Workbook

Sheet Teacher Salary - District
C2: CACTUS Database | E2: Teacher Benefits Survey (as Reported by LEA)
C3: Median School Administrator Salary | D3: Median Classroom Teacher Salary | E3: Social Security | F3: Retirement | G3: Health Insurance | H3: Dental Insurance | I3: Life Insurance | J3: Industrial Insurance | K3: Unemploy-ment Insurance | L3: Long-Term Disability Insurance | M3: Total Teacher Benefits | N3: Total Teacher Compensation
B4: ALPINE DISTRICT | C4: 84442.11 | D4: 43568.64 | E4: 3538 | F4: 8490 | G4: 13146 | H4: 0 | I4: 36 | J4: 162 | K4: 27 | L4: 132 | M4: 25531 | N4: =D4+M4 -> 69099.64
B5: BEAVER DISTRICT | C5: 72830 | D5: 50511 | E5: 3864 | F5: 9173 | G5: 13562 | H5: 918 | I5: 50 | J5: 303 | K5: 0 | L5: 109 | M5: 27979 | N5: =D5+M5 -> 78490
B6: BOX ELDER DISTRICT | C6: 75087 | D6: 45503 | E6: 3488 | F6: 7167 | G6: 10136 | H6: 0 | I6: 101 | J6: 145 | K6: 46 | L6: 0 | M6: 21083 | N6: =D6+M6 -> 66586
B7: CACHE DISTRICT | C7: 83658 | D7: 48551 | E7: 3678 | F7: 8827 | G7: 10145 | H7: 0 | I7: 26 | J7: 139 | K7: 48 | L7: 121 | M7: 22984 | N7: =D7+M7 -> 71535
B8: CANYONS DISTRICT | C8: 84547 | D8: 45164.7 | E8: 3513 | F8: 8431 | G8: 7012 | H8: 0 | I8: 54 | J8: 367 | K8: 46 | L8: 157 | M8: 19580 | N8: =D8+M8 -> 64744.7
B9: CARBON DISTRICT | C9: 67229.695 | D9: 47269 | E9: 3530 | F9: 8473 | G9: 17376 | H9: 0 | I9: 65 | J9: 370 | K9: 46 | L9: 0 | M9: 29861 | N9: =D9+M9 -> 77130
B10: DAGGETT DISTRICT | C10: 72249 | D10: 40570 | E10: 3318 | F10: 6817 | G10: 14760 | H10: 0 | I10: 59 | J10: 332 | K10: 43 | L10: 152 | M10: 25482 | N10: =D10+M10 -> 66052
B11: DAVIS DISTRICT | C11: 77700 | D11: 49051 | E11: 3731 | F11: 8955 | G11: 12595 | H11: 909 | I11: 59 | J11: 74 | K11: 51 | L11: 94 | M11: 26468 | N11: =D11+M11 -> 75519
B12: DUCHESNE DISTRICT | C12: 71474.22 | D12: 45521.14 | E12: 3390 | F12: 8136 | G12: 10056 | H12: 0 | I12: 69 | J12: 146 | K12: 27 | L12: 122 | M12: 21946 | N12: =D12+M12 -> 67467.14
B13: EMERY DISTRICT | C13: 82402 | D13: 51950 | E13: 3762 | F13: 7731 | G13: 16402 | H13: 756 | I13: 56 | J13: 340 | K13: 49 | L13: 94 | M13: 29190 | N13: =D13+M13 -> 81140
B14: GARFIELD DISTRICT | C14: 51537.5 | D14: 48429.005 | E14: 3672 | F14: 7545 | G14: 11675 | H14: 0 | I14: 121 | J14: 284 | K14: 48 | L14: 168 | M14: 23513 | N14: =D14+M14 -> 71942.005
B15: GRAND DISTRICT | C15: 76272 | D15: 45255 | E15: 3513 | F15: 7220 | G15: 6192 | H15: 0 | I15: 61 | J15: 271 | K15: 46 | L15: 221 | M15: 17525 | N15: =D15+M15 -> 62780
... B44: WEBER DISTRICT | C44: 75163 | D44: 44056 | E44: 3370 | F44: 6926 | G44: 10253 | H44: 0 | I44: 49 | J44: 127 | K44: 19 | L44: 74 | M44: 20818 | N44: =D44+M44 -> 64874
B45: District Median | C45: 79240 | D45: 46623 | E45: =MEDIAN(E4:E44) -> 3553 | F45: =MEDIAN(F4:F44) -> 8015 | G45: =MEDIAN(G4:G44) -> 11530 | H45: =MEDIAN(H4:H44) -> 0 | I45: =MEDIAN(I4:I44) -> 59 | J45: =MEDIAN(J4:J44) -> 195 | K45: =MEDIAN(K4:K44) -> 46 | L45: =MEDIAN(L4:L44) -> 128 | ... N45: =MEDIAN(N4:N44) -> 70882.5
B46: Charter Median | C46: 66658 | D46: 35500 | E46: ='Teacher Salary - Charter'!E84 -> 2718 | F46: ='Teacher Salary - Charter'!F84 -> 2082 | G46: ='Teacher Salary - Charter'!G84 -> 6454.5 | H46: ='Teacher Salary - Charter'!H84 -> 0 | I46: ='Teacher Salary - Charter'!I84 -> 0 | J46: ='Teacher Salary - Charter'!J84 -> 97 | K46: ='Teacher Salary - Charter'!K84 -> 134 | L46: ='Teacher Salary - Charter'!L84 -> 0 | ... N46: ='Teacher Salary - Charter'!N84 -> 48226.5
B47: Utah Schools for the Deaf and Blind | C47: 0 | D47: 55834 | E47: ='Teacher Salary - Charter'!E85 -> 0 | F47: ='Teacher Salary - Charter'!F85 -> 0 | G47: ='Teacher Salary - Charter'!G85 -> 0 | H47: ='Teacher Salary - Charter'!H85 -> 0 | I47: ='Teacher Salary - Charter'!I85 -> 0 | J47: ='Teacher Salary - Charter'!J85 -> 0 | K47: ='Teacher Salary - Charter'!K85 -> 0 | L47: ='Teacher Salary - Charter'!L85 -> 0 | ... N47: ='Teacher Salary - Charter'!N85 -> 0
B48: Grand Median | C48: 78656 | D48: 45432 | E48: ='Teacher Salary - Charter'!E86 -> 0 | F48: ='Teacher Salary - Charter'!F86 -> 0 | G48: ='Teacher Salary - Charter'!G86 -> 0 | H48: ='Teacher Salary - Charter'!H86 -> 0 | I48: ='Teacher Salary - Charter'!I86 -> 0 | J48: ='Teacher Salary - Charter'!J86 -> 0 | K48: ='Teacher Salary - Charter'!K86 -> 0 | L48: ='Teacher Salary - Charter'!L86 -> 0 | ... N48: ='Teacher Salary - Charter'!N86 -> 0
B49: Note: Benefits are based on the portion of the premium paid by the LEA for family coverage for an employee.

Sheet Teacher Salary - Charter
C2: CACTUS Database | E2: Teacher Benefits Survey (as Reported by LEA)
C3: Median School Administrator Salary | D3: Median Classroom Teacher Salary | E3: Social Security | F3: Retirement | G3: Health Insurance | H3: Dental Insurance | I3: Life Insurance | J3: Industrial Insurance | K3: Unemploy-ment Insurance | L3: Long-Term Disability Insurance | M3: Total Teacher Benefits | N3: Total Teacher Compensation
B4: ACADEMY FOR MATH, ENGINEERING & SCIENCE | C4: 90000 | D4: 46272.49 | E4: 3540 | F4: 8496 | G4: 12030 | H4: 480 | I4: 119 | J4: 185 | K4: 185 | L4: 278 | M4: 25312 | N4: =D4+M4 -> 71584.49
B5: ALIANZA ACADEMY | C5: 0 | D5: 32000 | E5: 2601 | F5: 5345 | G5: 6851 | H5: 703 | I5: 45 | J5: 0 | K5: 34 | L5: 45 | M5: 15625 | N5: =D5+M5 -> 47625
B6: AMERICAN LEADERSHIP ACADEMY | C6: 51665 | D6: 37903.42 | E6: 2907 | F6: 5973 | G6: 10971 | H6: 894 | I6: 0 | J6: 176 | K6: 38 | L6: 0 | M6: 20959 | N6: =D6+M6 -> 58862.42
B7: AMERICAN PREPARATORY ACADEMY | C7: 45000 | D7: 33055 | E7: 2529 | F7: 1027 | G7: 2424 | H7: 65 | I7: 26 | J7: 75 | K7: 581 | L7: 395 | M7: 7121 | N7: =D7+M7 -> 40176
B8: BAER CANYON HS FOR SPORTS & MEDICAL SCIENCES | C8: 60000 | D8: 0 | E8: 0 | F8: 0 | G8: 0 | H8: 0 | I8: 0 | J8: 0 | K8: 0 | L8: 0 | M8: 0 | N8: 0
B9: BEAR RIVER CHARTER SCHOOL | C9: 0 | D9: 35713.125 | E9: 2615 | F9: 5374 | G9: 6803 | H9: 926 | I9: 0 | J9: 144 | K9: 398 | L9: 0 | M9: 16260 | N9: =D9+M9 -> 51973.125
B10: BEEHIVE SCIENCE & TECHNOLOGY ACADEMY | C10: 0 | D10: 33102.495 | E10: 2532 | F10: 0 | G10: 3410 | H10: 0 | I10: 0 | J10: 109 | K10: 430 | L10: 0 | M10: 6482 | N10: =D10+M10 -> 39584.495
B11: CANYON RIM ACADEMY | C11: 85000 | D11: 38205 | E11: 2878 | F11: 739 | G11: 489 | H11: 50 | I11: 0 | J11: 558 | K11: 38 | L11: 0 | M11: 4752 | N11: =D11+M11 -> 42957
B12: CHANNING HALL | C12: 69720 | D12: 37104 | E12: 2838 | F12: 2559 | G12: 4218 | H12: 388 | I12: 60 | J12: 110 | K12: 125 | L12: 0 | M12: 10298 | N12: =D12+M12 -> 47402
B13: CITY ACADEMY | C13: 53298.89 | D13: 34634 | E13: 2650 | F13: 1559 | G13: 5195 | H13: 0 | I13: 0 | J13: 114 | K13: 35 | L13: 0 | M13: 9552 | N13: =D13+M13 -> 44186
B14: C.S. LEWIS ACADEMY | C14: 0 | D14: 31200 | E14: 2427 | F14: 0 | G14: 5612 | H14: 0 | I14: 0 | J14: 0 | K14: 412 | L14: 0 | M14: 8451 | N14: =D14+M14 -> 39651
B15: DAVINCI ACADEMY | C15: 82500 | D15: 40000 | E15: 3060 | F15: 2000 | G15: 6709 | H15: 857 | I15: 78 | J15: 242 | K15: 723 | L15: 0 | M15: 13669 | N15: =D15+M15 -> 53669
B16: DUAL IMMERSION ACADEMY | C16: 55000 | D16: 39750 | E16: 3041 | F16: 795 | G16: 4358 | H16: 103 | I16: 0 | J16: 182 | K16: 532 | L16: 0 | M16: 9011 | N16: =D16+M16 -> 48761
B17: EARLY LIGHT ACADEMY AT DAYBREAK | C17: 75000 | D17: 34955 | E17: 2749 | F17: 0 | G17: 7500 | H17: 0 | I17: 0 | J17: 93 | K17: 824 | L17: 0 | M17: 11167 | N17: =D17+M17 -> 46122
B18: EAST HOLLYWOOD HIGH | C18: 0 | D18: 32750 | E18: 2525 | F18: 5188 | G18: 4320 | H18: 242 | I18: 0 | J18: 225 | K18: 33 | L18: 0 | M18: 12533 | N18: =D18+M18 -> 45283
B19: EDITH BOWEN LABORATORY SCHOOL | C19: 73076.92 | D19: 47803.5 | E19: 3657 | F19: 7515 | G19: 6604 | H19: 761 | I19: 122 | J19: 288 | K19: 48 | L19: 131 | M19: 19126 | N19: =D19+M19 -> 66929.5
B20: ENDEAVOR HALL | C20: 56000 | D20: 34500 | E20: 2639 | F20: 3105 | G20: 4000 | H20: 240 | I20: 27 | J20: 38 | K20: 35 | L20: 58 | M20: 10142 | N20: =D20+M20 -> 44642
... B29: HAWTHORN ACADEMY | C29: 69702.4 | D29: 31788.95 | E29: 2432 | F29: 0 | G29: 7800 | H29: 0 | I29: 0 | J29: 83 | K29: 721 | L29: 0 | M29: 11036 | N29: =D29+M29 -> 42824.95
B30: HIGHMARK CHARTER SCHOOL | C30: 68000 | D30: 0 | E30: 0 | F30: 0 | G30: 0 | H30: 0 | I30: 0 | J30: 0 | K30: 0 | L30: 0 | M30: 0 | N30: 0
B31: INTECH COLLEGIATE HIGH SCHOOL | C31: 87482 | D31: 42785 | E31: 3090 | F31: 6349 | G31: 5371 | H31: 0 | I31: 0 | J31: 130 | K31: 470 | L31: 0 | M31: 15410 | N31: =D31+M31 -> 58195
B32: ITINERIS EARLY COLLEGE HIGH | C32: 87214 | D32: 42548.555 | E32: 3665 | F32: 7531 | G32: 9668 | H32: 0 | I32: 0 | J32: 109 | K32: 48 | L32: 162 | M32: 21182 | N32: =D32+M32 -> 63730.555
B33: JOHN HANCOCK CHARTER SCHOOL | C33: 71757 | D33: 38535 | E33: 3010 | F33: 6184 | G33: 14298 | H33: 774 | I33: 89 | J33: 86 | K33: 74 | L33: 123 | M33: 24637 | N33: =D33+M33 -> 63172
B34: KARL G. MAESER PREPARATORY ACADEMY | C34: 47000 | D34: 33692.54 | E34: 2486 | F34: 5109 | G34: 713 | H34: 0 | I34: 97 | J34: 80 | K34: 33 | L34: 0 | M34: 8518 | N34: =D34+M34 -> 42210.54
B35: LAKEVIEW ACADEMY | C35: 0 | D35: 36331 | E35: 2783 | F35: 2547 | G35: 8041 | H35: 0 | I35: 0 | J35: 124 | K35: 36 | L35: 0 | M35: 13532 | N35: =D35+M35 -> 49863
B36: LEGACY PREPARATORY ACADEMY | C36: 60000 | D36: 33368 | E36: 2573 | F36: 529 | G36: 6001 | H36: 171 | I36: 0 | J36: 0 | K36: 34 | L36: 0 | M36: 9307 | N36: =D36+M36 -> 42675
B37: LIBERTY ACADEMY | C37: 105913.5 | D37: 32726 | E37: 0 | F37: 0 | G37: 0 | H37: 0 | I37: 0 | J37: 0 | K37: 0 | L37: 0 | M37: 0 | N37: =D37+M37 -> 32726
B38: LINCOLN ACADEMY | C38: 66500 | D38: 34840 | E38: 2665 | F38: 523 | G38: 7332 | H38: 716 | I38: 42 | J38: 98 | K38: 310 | L38: 72 | M38: 11758 | N38: =D38+M38 -> 46598
B39: MARIA MONTESSORI ACADEMY | C39: 72500 | D39: 35103.29 | E39: 2678 | F39: 0 | G39: 7800 | H39: 0 | I39: 0 | J39: 91 | K39: 649 | L39: 0 | M39: 11218 | N39: =D39+M39 -> 46321.29
B40: MERIT COLLEGE PREPARATORY ACADEMY | C40: 45000 | D40: 33589 | E40: 2720 | F40: 1067 | G40: 5292 | H40: 1109 | I40: 119 | J40: 0 | K40: 708 | L40: 0 | M40: 11014 | N40: =D40+M40 -> 44603
B41: MOAB CHARTER SCHOOL | C41: 55000 | D41: 31500 | E41: 2410 | F41: 0 | G41: 4464 | H41: 0 | I41: 0 | J41: 0 | K41: 32 | L41: 0 | M41: 6905 | N41: =D41+M41 -> 38405
B42: MONTICELLO ACADEMY | C42: 0 | D42: 35750 | E42: 2705 | F42: 6634 | G42: 12348 | H42: 0 | I42: 0 | J42: 200 | K42: 35 | L42: 0 | M42: 21922 | N42: =D42+M42 -> 57672
... B50: OGDEN PREPARATORY ACADEMY | C50: 64648.9 | D50: 36720 | E50: 2875 | F50: 472 | G50: 8700 | H50: 0 | I50: 0 | J50: 98 | K50: 841 | L50: 0 | M50: 12985 | N50: =D50+M50 -> 49705
B51: OPEN CLASSROOM | C51: 76919 | D51: 47565.5 | E51: 0 | F51: 0 | G51: 0 | H51: 0 | I51: 0 | J51: 0 | K51: 0 | L51: 0 | M51: 0 | N51: 0
B52: OPEN HIGH SCHOOL OF UTAH | C52: 72450 | D52: 30000 | E52: 2372 | F52: 0 | G52: 8700 | H52: 0 | I52: 0 | J52: 81 | K52: 708 | L52: 0 | M52: 11860 | N52: =D52+M52 -> 41860
B53: OQUIRRH MOUNTAIN CHARTER SCHOOL | C53: 70000 | D53: 34000 | E53: 2601 | F53: 0 | G53: 7200 | H53: 0 | I53: 0 | J53: 88 | K53: 779 | L53: 0 | M53: 10669 | N53: =D53+M53 -> 44669
B54: PARADIGM HIGH SCHOOL | C54: 75000 | D54: 36980 | E54: 2831 | F54: 0 | G54: 7372 | H54: 1228 | I54: 240 | J54: 141 | K54: 0 | L54: 0 | M54: 11812 | N54: =D54+M54 -> 48792
B55: PINNACLE CANYON ACADEMY | C55: 62034.59 | D55: 30965.91 | E55: 2441 | F55: 5017 | G55: 18076 | H55: 1740 | I55: 414 | J55: 238 | K55: 32 | L55: 181 | M55: 28139 | N55: =D55+M55 -> 59104.91
B56: PROVIDENCE HALL | C56: 58417.5 | D56: 34034.48 | E56: 2655 | F56: 2430 | G56: 6000 | H56: 0 | I56: 0 | J56: 95 | K56: 165 | L56: 0 | M56: 11345 | N56: =D56+M56 -> 45379.48
...
