Workbook
Name Print_Area_MI: 'CPI-based on Jun14'!$A$3:$K$45
Name TitleRegion1.a1.g261.2: 'CPI-Jun2014'!$G$261
Name TitleRegion1.a3.r47.1: 'CPI-based on Jun14'!$R$47

Sheet CPI-based on Jun14
A1: Revised Referendum Cap Inflation Estimates | O1: n/a | P1: n/a | Q1: n/a | R1: n/a
A2: FY 2005 - FY 2023 | K2: n/a | L2: n/a | M2: n/a | N2: n/a | O2: n/a | P2: n/a | Q2: n/a | R2: n/a
A3: CPI - Urban Consumers | K3: n/a | L3: n/a | M3: n/a | N3: n/a | O3: n/a | P3: n/a | Q3: n/a | R3: n/a
A4: June 2014 Update | K4: n/a | L4: n/a | M4: n/a | N4: n/a | O4: n/a | P4: n/a | Q4: n/a | R4: n/a
A5: Source of CPI Data: DOF- John Peloquin | L5: n/a | M5: n/a | N5: n/a | O5: n/a | P5: n/a | Q5: n/a | R5: n/a
A6: Date: June 30, 2014
D10: CALENDAR | E10: CALENDAR | F10: CALENDAR | G10: CALENDAR | H10: FISCAL | I10: RATE OF | J10: CUMMULATIVE
D11: QUARTER | E11: QUARTER | F11: QUARTER | G11: QUARTER | H11: YEAR | I11: INCREASE | J11: RATE OF
D12: 1 | E12: 2 | F12: 3 | G12: 4 | H12: AVERAGE | J12: INCREASE
A14: n/a | B14: n/a | C14: n/a | D14: n/a | E14: n/a | F14: n/a | G14: n/a | H14: n/a | I14: n/a | J14: n/a | K14: n/a | L14: A | M14: B | N14: C | O14: D | P14: E | Q14: F | R14: G
A15: n/a | B15: n/a | C15: n/a | D15: n/a | E15: n/a | F15: n/a | G15: n/a | H15: n/a | I15: n/a | J15: n/a | K15: n/a | M15: Projected | O15: Projected | Q15: Std. Cap | R15: Projected
A16: n/a | B16: n/a | C16: n/a | D16: n/a | E16: n/a | F16: n/a | G16: n/a | H16: n/a | I16: n/a | J16: n/a | K16: n/a | L16: Annual | M16: Inflation | N16: Formula | O16: Inflation | P16: Projected | Q16: Increase | R16: Inflation
A17: Fiscal | C17: Calendar | D17: 1st | E17: 2nd | F17: 3rd | G17: 4th | J17: (CY % / BASE YR %) | K17: n/a | L17: Projected | M17: Ratio | N17: Allow Based | O17: Based | P17: Std. Cap | Q17: over | R17: Ratio
A18: Year | C18: Year | K18: n/a | L18: Inflation | M18: Std. Cap | N18: Std. Cap | O18: Std. Cap | P18: Gtr of C or D | Q18: FY 2004 or | R18: Alt. Cap*
A19: n/a | B19: n/a | C19: n/a | D19: n/a | E19: n/a | F19: n/a | G19: n/a | H19: n/a | I19: n/a | J19: n/a | K19: n/a | L19: n/a | M19: n/a | N19: n/a | O19: n/a | P19: n/a | Q19: FY 2015 | R19: n/a
A20: 2003 | C20: 2003 | D20: ='CPI-Jun2014'!C178 -> 1.833667 | E20: ='CPI-Jun2014'!C179 -> 1.830667 | F20: ='CPI-Jun2014'!C180 -> 1.844333 | G20: ='CPI-Jun2014'!C181 -> 1.851333 | H20: =(F19+G19+D20+E20)/4 -> 0.9160835
A21: =A20+1 -> 2004 | C21: 2004 | D21: ='CPI-Jun2014'!C182 -> 1.867 | E21: ='CPI-Jun2014'!C183 -> 1.881667 | F21: ='CPI-Jun2014'!C184 -> 1.893667 | G21: ='CPI-Jun2014'!C185 -> 1.914 | H21: =(F20+G20+D21+E21)/4 -> 1.8610833 | I21: =ROUND((H21/H20)-1,4) -> 1.0316
A22: =A21+1 -> 2005 | C22: 2005 | D22: ='CPI-Jun2014'!C186 -> 1.923667 | E22: ='CPI-Jun2014'!C187 -> 1.936667 | F22: ='CPI-Jun2014'!C188 -> 1.966 | G22: ='CPI-Jun2014'!C189 -> 1.984333 | H22: =(F21+G21+D22+E22)/4 -> 1.9170003 | I22: =(H22/H21)-1 -> 0.030045405 | J22: =(H22/$H$21)-1 -> 0.030045405 | L22: 0.0301 | M22: 1.0301 | N22: =ROUND(4601*0.186,2) -> 855.79 | O22: =M22*855.79 -> 881.54928 | P22: =IF(N22>O22,N22,O22) -> 881.54928 | Q22: =P22-855.79 -> 25.759279 | R22: =M22 -> 1.0301
A23: =A22+1 -> 2006 | C23: 2006 | D23: ='CPI-Jun2014'!C190 -> 1.994667 | E23: ='CPI-Jun2014'!C191 -> 2.012667 | F23: ='CPI-Jun2014'!C192 -> 2.031667 | G23: ='CPI-Jun2014'!C193 -> 2.023333 | H23: =(F22+G22+D23+E23)/4 -> 1.9894167 | I23: =(H23/H22)-1 -> 0.037775947 | J23: =(H23/$H$21)-1 -> 0.068956346 | L23: 0.0381 | M23: 1.0693 | N23: =ROUND(4783*0.186,2) -> 889.64 | O23: =M23*855.79 -> 915.09625 | P23: =IF(N23>O23,N23,O23) -> 915.09625 | Q23: =P23-855.79 -> 59.306247 | R23: =M23 -> 1.0693
A24: =A23+1 -> 2007 | C24: 2007 | D24: ='CPI-Jun2014'!C194 -> 2.04317 | E24: ='CPI-Jun2014'!C195 -> 2.06631 | F24: ='CPI-Jun2014'!C196 -> 2.07939 | G24: ='CPI-Jun2014'!C197 -> 2.104897 | H24: =(F23+G23+D24+E24)/4 -> 2.04112 | I24: =(H24/H23)-1 -> 0.02598915 | J24: =(H24/$H$21)-1 -> 0.096737612 | L24: 0.0261 | M24: 1.0973 | N24: =ROUND(4974*0.26,2) -> 1293.24 | O24: =M24*1294 -> 1419.9062 | P24: =IF(N24>O24,N24,O24) -> 1419.9062 | Q24: =P24-855.79 -> 564.1162 | R24: =M24 -> 1.0973
A25: =A24+1 -> 2008 | C25: 2008 | D25: ='CPI-Jun2014'!C198 -> 2.127697 | E25: ='CPI-Jun2014'!C199 -> 2.155377 | F25: ='CPI-Jun2014'!C200 -> 2.18861 | G25: ='CPI-Jun2014'!C201 -> 2.138487 | H25: =(F24+G24+D25+E25)/4 -> 2.1168402 | I25: =(H25/H24)-1 -> 0.037097402 | J25: =(H25/$H$21)-1 -> 0.13742373 | L25: 0.0367 | M25: 1.1376 | N25: =ROUND(5074*0.26,2) -> 1319.24 | O25: =M25*1294 -> 1472.0544 | P25: =IF(N25>O25,N25,O25) -> 1472.0544 | Q25: =P25-855.79 -> 616.2644 | R25: =M25 -> 1.1376
A26: =A25+1 -> 2009 | C26: =C25+1 -> 2009 | D26: ='CPI-Jun2014'!C202 -> 2.123777 | E26: ='CPI-Jun2014'!C203 -> 2.13507 | F26: ='CPI-Jun2014'!C204 -> 2.15344 | G26: ='CPI-Jun2014'!C205 -> 2.1703 | H26: =(F25+G25+D26+E26)/4 -> 2.146486 | I26: =(H26/H25)-1 -> 0.014004718 | J26: =(H26/$H$21)-1 -> 0.15335303 | L26: 0.0142 | M26: 1.1537 | N26: =ROUND(5124*0.26,2) -> 1332.24 | O26: =M26*1294 -> 1492.8878 | P26: =IF(N26>O26,N26,O26) -> 1492.8878 | Q26: =P26-855.79 -> 637.0978 | R26: =R$25+(0.25*(5124/5074-1)) -> 1.1400635
A27: =A26+1 -> 2010 | C27: =C26+1 -> 2010 | D27: ='CPI-Jun2014'!C206 -> 2.173407 | E27: ='CPI-Jun2014'!C207 -> 2.1732 | F27: ='CPI-Jun2014'!C208 -> 2.1799 | G27: ='CPI-Jun2014'!C209 -> 2.196683 | H27: =(F26+G26+D27+E27)/4 -> 2.1675867 | I27: =(H27/H26)-1 -> 0.0098303693 | J27: =(H27/$H$21)-1 -> 0.16469091 | L27: 0.0093 | M27: 1.1644 | N27: =ROUND(5124*0.26,2) -> 1332.24 | O27: =M27*1294 -> 1506.7336 | P27: =IF(N27>O27,N27,O27) -> 1506.7336 | Q27: =P27-855.79 -> 650.9436 | R27: =R26 -> 1.1400635
A28: =A27+1 -> 2011 | C28: =C27+1 -> 2011 | D28: ='CPI-Jun2014'!C210 -> 2.21951 | E28: ='CPI-Jun2014'!C211 -> 2.246547 | F28: ='CPI-Jun2014'!C212 -> 2.261253 | G28: ='CPI-Jun2014'!C213 -> 2.269967 | H28: =(F27+G27+D28+E28)/4 -> 2.21066 | I28: =(H28/H27)-1 -> 0.019871523 | J28: =(H28/$H$21)-1 -> 0.1878351 | L28: 0.0203 | M28: 1.1881 | N28: =ROUND(5124*0.26,2) -> 1332.24 | O28: =M28*1294 -> 1537.4014 | P28: =IF(N28>O28,N28,O28) -> 1537.4014 | Q28: =P28-855.79 -> 681.6114 | R28: =R27 -> 1.1400635
A29: =A28+1 -> 2012 | C29: =C28+1 -> 2012 | D29: ='CPI-Jun2014'!C214 -> 2.281787 | E29: ='CPI-Jun2014'!C215 -> 2.289643 | F29: ='CPI-Jun2014'!C216 -> 2.29939 | G29: ='CPI-Jun2014'!C217 -> 2.313137 | H29: =(F28+G28+D29+E29)/4 -> 2.2756625 | I29: =(H29/H28)-1 -> 0.029404115 | J29: =(H29/$H$21)-1 -> 0.22276233 | L29: 0.0294 | M29: 1.223 | N29: =ROUND(5174*0.26,2) -> 1345.24 | O29: =M29*1294 -> 1582.562 | P29: =IF(N29>O29,N29,O29) -> 1582.562 | Q29: =P29-855.79 -> 726.772 | R29: =R$25+(0.25*(5174/5074-1)) -> 1.1425271
A30: =A29+1 -> 2013 | C30: =C29+1 -> 2013 | D30: ='CPI-Jun2014'!C218 -> 2.319983 | E30: ='CPI-Jun2014'!C219 -> 2.322303 | F30: ='CPI-Jun2014'!C220 -> 2.33476 | G30: ='CPI-Jun2014'!C221 -> 2.341363 | H30: =(F29+G29+D30+E30)/4 -> 2.3137033 | I30: =(H30/H29)-1 -> 0.016716341 | J30: =(H30/$H$21)-1 -> 0.24320245 | L30: =ROUND(I30,4) -> 0.0167 | M30: =ROUND(H30/H$21,4) -> 1.2432 | N30: =ROUND(5224*0.26,2) -> 1358.24 | O30: =M30*1294 -> 1608.7008 | P30: =IF(N30>O30,N30,O30) -> 1608.7008 | Q30: =P30-855.79 -> 752.9108 | R30: =R$25+(0.25*(5224/5074-1)) -> 1.1449906
A31: 2014 | B31: e | C31: 2014 | D31: ='CPI-Jun2014'!C222 -> 2.352473 | E31: ='CPI-Jun2014'!C223 -> 2.367656 | F31: ='CPI-Jun2014'!C224 -> 2.379144 | G31: ='CPI-Jun2014'!C225 -> 2.39264 | H31: =(F30+G30+D31+E31)/4 -> 2.349063 | I31: =(H31/H30)-1 -> 0.015282751 | J31: =(H31/$H$21)-1 -> 0.262202 | L31: =ROUND(I31,4) -> 0.0153 | M31: =ROUND(H31/H$21,4) -> 1.2622 | N31: =ROUND(5302*0.26,2) -> 1378.52 | O31: =M31*1294 -> 1633.2868 | P31: =IF(N31>O31,N31,O31) -> 1633.2868 | Q31: =P31-855.79 -> 777.4968 | R31: =R$25+(0.25*(5302/5074-1)) -> 1.1488337
A32: New Law Formula for FY 2015 and Out | M32: n/a | N32: n/a | O32: n/a | P32: n/a | Q32: n/a | R32: n/a
A33: 2015 | B33: e | C33: 2015 | D33: ='CPI-Jun2014'!C226 -> 2.402175 | E33: ='CPI-Jun2014'!C227 -> 2.407847 | F33: ='CPI-Jun2014'!C228 -> 2.416604 | G33: ='CPI-Jun2014'!C229 -> 2.421435 | H33: =(F31+G31+D33+E33)/4 -> 2.3954515 | I33: =(H33/H31)-1 -> 0.019747661 | J33: =(H33/$H$21)-1 -> 0.28712754 | L33: =ROUND(I33,4) -> 0.0197 | M33: =ROUND(H33/H$33,4) -> 1 | N33: na | O33: =M33*1845 -> 1845 | P33: =O33 -> 1845 | Q33: =P33-1845 -> 0 | R33: 1
A34: 2016 | B34: e | C34: 2016 | D34: ='CPI-Jun2014'!C230 -> 2.432095 | E34: ='CPI-Jun2014'!C231 -> 2.441396 | F34: ='CPI-Jun2014'!C232 -> 2.452038 | G34: ='CPI-Jun2014'!C233 -> 2.464456 | H34: =(F33+G33+D34+E34)/4 -> 2.4278825 | I34: =(H34/H33)-1 -> 0.013538575 | J34: =(H34/$H$21)-1 -> 0.30455341 | L34: =ROUND(I34,4) -> 0.0135 | M34: =ROUND(H34/H$33,4) -> 1.0135 | N34: na | O34: =M34*1845 -> 1869.9075 | P34: =O34 -> 1869.9075 | Q34: =P34-1845 -> 24.9075 | R34: =R$33+(0.25*(5831/5831-1)) -> 1
A35: 2017 | B35: e | C35: 2017 | D35: ='CPI-Jun2014'!C234 -> 2.475091 | E35: ='CPI-Jun2014'!C235 -> 2.486846 | F35: ='CPI-Jun2014'!C236 -> 2.499427 | G35: ='CPI-Jun2014'!C237 -> 2.511317 | H35: =(F34+G34+D35+E35)/4 -> 2.4696077 | I35: =(H35/H34)-1 -> 0.017185861 | J35: =(H35/$H$21)-1 -> 0.32697328 | L35: =ROUND(I35,4) -> 0.0172 | M35: =ROUND(H35/H$33,4) -> 1.031 | N35: na | O35: =M35*1845 -> 1902.195 | P35: =O35 -> 1902.195 | Q35: =P35-1845 -> 57.195 | R35: =R34 -> 1
A36: 2018 | B36: e | C36: 2018 | D36: ='CPI-Jun2014'!C238 -> 2.524419 | E36: ='CPI-Jun2014'!C239 -> 2.53595 | F36: ='CPI-Jun2014'!C240 -> 2.548261 | G36: ='CPI-Jun2014'!C241 -> 2.56 | H36: =(F35+G35+D36+E36)/4 -> 2.5177783 | I36: =(H36/H35)-1 -> 0.019505324 | J36: =(H36/$H$21)-1 -> 0.35285633 | L36: =ROUND(I36,4) -> 0.0195 | M36: =ROUND(H36/H$33,4) -> 1.0511 | N36: na | O36: =M36*1845 -> 1939.2795 | P36: =O36 -> 1939.2795 | Q36: =P36-1845 -> 94.2795 | R36: =R35 -> 1
A37: 2019 | B37: e | C37: 2019 | D37: ='CPI-Jun2014'!C242 -> 2.572897 | E37: ='CPI-Jun2014'!C243 -> 2.583349 | F37: ='CPI-Jun2014'!C244 -> 2.59495 | G37: ='CPI-Jun2014'!C245 -> 2.607184 | H37: =(F36+G36+D37+E37)/4 -> 2.5661268 | I37: =(H37/H36)-1 -> 0.019202843 | J37: =(H37/$H$21)-1 -> 0.37883501 | L37: =ROUND(I37,4) -> 0.0192 | M37: =ROUND(H37/H$33,4) -> 1.0712 | N37: na | O37: =M37*1845 -> 1976.364 | P37: =O37 -> 1976.364 | Q37: =P37-1845 -> 131.364 | R37: =R36 -> 1
A38: 2020 | B38: e | C38: 2020 | D38: ='CPI-Jun2014'!C246 -> 2.622024 | E38: ='CPI-Jun2014'!C247 -> 2.634597 | F38: ='CPI-Jun2014'!C248 -> 2.647675 | G38: ='CPI-Jun2014'!C249 -> 2.660681 | H38: =(F37+G37+D38+E38)/4 -> 2.6146888 | I38: =(H38/H37)-1 -> 0.018924241 | J38: =(H38/$H$21)-1 -> 0.40492842 | L38: =ROUND(I38,4) -> 0.0189 | M38: =ROUND(H38/H$33,4) -> 1.0915 | N38: na | O38: =M38*1845 -> 2013.8175 | P38: =O38 -> 2013.8175 | Q38: =P38-1845 -> 168.8175 | R38: =R37 -> 1
A39: 2021 | B39: e | C39: 2021 | D39: ='CPI-Jun2014'!C250 -> 2.675387 | E39: ='CPI-Jun2014'!C251 -> 2.689257 | F39: ='CPI-Jun2014'!C252 -> 2.7036 | G39: ='CPI-Jun2014'!C253 -> 2.717428 | H39: =(F38+G38+D39+E39)/4 -> 2.66825 | I39: =(H39/H38)-1 -> 0.020484752 | J39: =(H39/$H$21)-1 -> 0.43370803 | L39: =ROUND(I39,4) -> 0.0205 | M39: =ROUND(H39/H$33,4) -> 1.1139 | N39: na | O39: =M39*1845 -> 2055.1455 | P39: =O39 -> 2055.1455 | Q39: =P39-1845 -> 210.1455 | R39: =R38 -> 1
A40: 2022 | B40: e | C40: 2022 | D40: ='CPI-Jun2014'!C254 -> 2.731723 | E40: ='CPI-Jun2014'!C255 -> 2.745572 | F40: ='CPI-Jun2014'!C256 -> 2.760068 | G40: ='CPI-Jun2014'!C257 -> 2.7744 | H40: =(F39+G39+D40+E40)/4 -> 2.7245808 | I40: =(H40/H39)-1 -> 0.021111496 | J40: =(H40/$H$21)-1 -> 0.46397575 | L40: =ROUND(I40,4) -> 0.0211 | M40: =ROUND(H40/H$33,4) -> 1.1374 | N40: na | O40: =M40*1845 -> 2098.503 | P40: =O40 -> 2098.503 | Q40: =P40-1845 -> 253.503 | R40: =R39 -> 1
A41: 2023 | B41: e | C41: 2023 | D41: ='CPI-Jun2014'!C258 -> 2.789296 | E41: ='CPI-Jun2014'!C259 -> 2.803686 | F41: ='CPI-Jun2014'!C260 -> 2.81873 | G41: ='CPI-Jun2014'!C261 -> 2.83441 | H41: =(F40+G40+D41+E41)/4 -> 2.7818625 | I41: =(H41/H40)-1 -> 0.02102406 | J41: =(H41/$H$21)-1 -> 0.49475447 | L41: =ROUND(I41,4) -> 0.021 | M41: =ROUND(H41/H$33,4) -> 1.1613 | N41: na | O41: =M41*1845 -> 2142.5985 | P41: =O41 -> 2142.5985 | Q41: =P41-1845 -> 297.5985 | R41: =R40 -> 1
A42: Old Law Formula Calculation for FY 2015 | M42: n/a | N42: n/a | O42: n/a | P42: n/a | Q42: n/a | R42: n/a
A43: 2015 | B43: e | C43: 2015 | D43: =+'CPI-Jun2014'!C226 -> 2.402175 | E43: =+'CPI-Jun2014'!C227 -> 2.407847 | F43: =+'CPI-Jun2014'!C228 -> 2.416604 | G43: =+'CPI-Jun2014'!C229 -> 2.421435 | H43: =(F31+G31+D43+E43)/4 -> 2.3954515 | I43: =(H43/H31)-1 -> 0.019747661 | J43: =(H43/$H$21)-1 -> 0.28712754 | L43: =ROUND(I43,4) -> 0.0197 | M43: =ROUND(H43/H$21,4) -> 1.2871 | N43: =ROUND(5224*0.26,2) -> 1358.24 | O43: =M43*1294 -> 1665.5074 | P43: =IF(N43>O43,N43,O43) -> 1665.5074 | Q43: =P43-855.79 -> 809.7174 | R43: =R$25+(0.25*(5224/5074-1)) -> 1.1449906
A44: Notes: | B44: n/a | C44: n/a | D44: n/a | E44: n/a | F44: n/a | G44: n/a | H44: n/a | I44: n/a | J44: n/a | K44: n/a | L44: n/a | M44: n/a | N44: n/a | O44: n/a | P44: n/a | Q44: n/a | R44: n/a
...

Sheet CPI-Jun2014
A1: obs | B1: obs | C1: CPI | D1: previous | E1: diff | F1: df-current | G1: df-previous | H1: n/a | I1: n/a
A2: 81.625694 | B2: 1959Q1 | C2: 0.289933 | D2: 0.289933 | E2: =C2-D2 -> 0 | H2: n/a | I2: n/a
A3: 81.626389 | B3: 1959Q2 | C3: 0.290433 | D3: 0.290433 | E3: =C3-D3 -> 0 | F3: =C3-C2 -> 0.0005 | G3: =D3-D2 -> 0.0005 | H3: n/a | I3: n/a
A4: 81.627083 | B4: 1959Q3 | C4: 0.291933 | D4: 0.291933 | E4: =C4-D4 -> 0 | F4: =C4-C3 -> 0.0015 | G4: =D4-D3 -> 0.0015 | H4: n/a | I4: n/a
A5: 81.627778 | B5: 1959Q4 | C5: 0.2937 | D5: 0.2937 | E5: =C5-D5 -> 0 | F5: =C5-C4 -> 0.001767 | G5: =D5-D4 -> 0.001767 | H5: n/a | I5: n/a
A6: 81.667361 | B6: 1960Q1 | C6: 0.293967 | D6: 0.293967 | E6: =C6-D6 -> 0 | F6: =C6-C5 -> 0.000267 | G6: =D6-D5 -> 0.000267 | H6: n/a | I6: n/a
A7: 81.668056 | B7: 1960Q2 | C7: 0.295733 | D7: 0.295733 | E7: =C7-D7 -> 0 | F7: =C7-C6 -> 0.001766 | G7: =D7-D6 -> 0.001766 | H7: n/a | I7: n/a
A8: 81.66875 | B8: 1960Q3 | C8: 0.2959 | D8: 0.2959 | E8: =C8-D8 -> 0 | F8: =C8-C7 -> 0.000167 | G8: =D8-D7 -> 0.000167 | H8: n/a | I8: n/a
A9: 81.669444 | B9: 1960Q4 | C9: 0.2978 | D9: 0.2978 | E9: =C9-D9 -> 0 | F9: =C9-C8 -> 0.0019 | G9: =D9-D8 -> 0.0019 | H9: n/a | I9: n/a
A10: 81.709028 | B10: 1961Q1 | C10: 0.2984 | D10: 0.2984 | E10: =C10-D10 -> 0 | F10: =C10-C9 -> 0.0006 | G10: =D10-D9 -> 0.0006 | H10: n/a | I10: n/a
A11: 81.709722 | B11: 1961Q2 | C11: 0.2983 | D11: 0.2983 | E11: =C11-D11 -> 0 | F11: =C11-C10 -> -0.0001 | G11: =D11-D10 -> -0.0001 | H11: n/a | I11: n/a
A12: 81.710417 | B12: 1961Q3 | C12: 0.299467 | D12: 0.299467 | E12: =C12-D12 -> 0 | F12: =C12-C11 -> 0.001167 | G12: =D12-D11 -> 0.001167 | H12: n/a | I12: n/a
A13: 81.711111 | B13: 1961Q4 | C13: 0.2999 | D13: 0.2999 | E13: =C13-D13 -> 0 | F13: =C13-C12 -> 0.000433 | G13: =D13-D12 -> 0.000433 | H13: n/a | I13: n/a
A14: 81.750694 | B14: 1962Q1 | C14: 0.301067 | D14: 0.301067 | E14: =C14-D14 -> 0 | F14: =C14-C13 -> 0.001167 | G14: =D14-D13 -> 0.001167 | H14: n/a | I14: n/a
... A198: 83.667361 | B198: 2008Q1 | C198: 2.127697 | D198: 2.127697 | E198: =C198-D198 -> 0 | F198: =C198-C197 -> 0.0228 | G198: =D198-D197 -> 0.0228 | H198: n/a | I198: n/a
A199: 83.668056 | B199: 2008Q2 | C199: 2.155377 | D199: 2.155377 | E199: =C199-D199 -> 0 | F199: =C199-C198 -> 0.02768 | G199: =D199-D198 -> 0.02768 | H199: =(SUM(C196:C199))/4 -> 2.1168402 | I199: =(SUM(D196:D199))/4 -> 2.1168402
A200: 83.66875 | B200: 2008Q3 | C200: 2.18861 | D200: 2.18861 | E200: =C200-D200 -> 0 | F200: =C200-C199 -> 0.033233 | G200: =D200-D199 -> 0.033233 | H200: n/a | I200: n/a
A201: 83.669444 | B201: 2008Q4 | C201: 2.138487 | D201: 2.138487 | E201: =C201-D201 -> 0 | F201: =C201-C200 -> -0.050123 | G201: =D201-D200 -> -0.050123 | H201: n/a | I201: n/a
A202: 83.709028 | B202: 2009Q1 | C202: 2.123777 | D202: 2.124327 | E202: =C202-D202 -> -0.00055 | F202: =C202-C201 -> -0.01471 | G202: =D202-D201 -> -0.01416 | H202: n/a | I202: n/a
A203: 83.709722 | B203: 2009Q2 | C203: 2.13507 | D203: 2.13482 | E203: =C203-D203 -> 0.00025 | F203: =C203-C202 -> 0.011293 | G203: =D203-D202 -> 0.010493 | H203: =(SUM(C200:C203))/4 -> 2.146486 | I203: =(SUM(D200:D203))/4 -> 2.146561
A204: 83.710417 | B204: 2009Q3 | C204: 2.15344 | D204: 2.153473 | E204: =C204-D204 -> -3.3e-05 | F204: =C204-C203 -> 0.01837 | G204: =D204-D203 -> 0.018653 | H204: n/a | I204: n/a
A205: 83.711111 | B205: 2009Q4 | C205: 2.1703 | D205: 2.17004 | E205: =C205-D205 -> 0.00026 | F205: =C205-C204 -> 0.01686 | G205: =D205-D204 -> 0.016567 | H205: n/a | I205: n/a
A206: 83.750694 | B206: 2010Q1 | C206: 2.173407 | D206: 2.174047 | E206: =C206-D206 -> -0.00064 | F206: =C206-C205 -> 0.003107 | G206: =D206-D205 -> 0.004007 | H206: n/a | I206: n/a
A207: 83.751389 | B207: 2010Q2 | C207: 2.1732 | D207: 2.1728 | E207: =C207-D207 -> 0.0004 | F207: =C207-C206 -> -0.000207 | G207: =D207-D206 -> -0.001247 | H207: =(SUM(C204:C207))/4 -> 2.1675867 | I207: =(SUM(D204:D207))/4 -> 2.16759
A208: 83.752083 | B208: 2010Q3 | C208: 2.1799 | D208: 2.180097 | E208: =C208-D208 -> -0.000197 | F208: =C208-C207 -> 0.0067 | G208: =D208-D207 -> 0.007297 | H208: n/a | I208: n/a
A209: 83.752778 | B209: 2010Q4 | C209: 2.196683 | D209: 2.19645 | E209: =C209-D209 -> 0.000233 | F209: =C209-C208 -> 0.016783 | G209: =D209-D208 -> 0.016353 | H209: n/a | I209: n/a
A210: 83.792361 | B210: 2011Q1 | C210: 2.21951 | D210: 2.22027 | E210: =C210-D210 -> -0.00076 | F210: =C210-C209 -> 0.022827 | G210: =D210-D209 -> 0.02382 | H210: n/a | I210: n/a
A211: 83.793056 | B211: 2011Q2 | C211: 2.246547 | D211: 2.245653 | E211: =C211-D211 -> 0.000894 | F211: =C211-C210 -> 0.027037 | G211: =D211-D210 -> 0.025383 | H211: =(SUM(C208:C211))/4 -> 2.21066 | I211: =(SUM(D208:D211))/4 -> 2.2106175
A212: 83.79375 | B212: 2011Q3 | C212: 2.261253 | D212: 2.26178 | E212: =C212-D212 -> -0.000527 | F212: =C212-C211 -> 0.014706 | G212: =D212-D211 -> 0.016127 | H212: n/a | I212: n/a
A213: 83.794444 | B213: 2011Q4 | C213: 2.269967 | D213: 2.269713 | E213: =C213-D213 -> 0.000254 | F213: =C213-C212 -> 0.008714 | G213: =D213-D212 -> 0.007933 | H213: n/a | I213: n/a
A214: 83.834028 | B214: 2012Q1 | C214: 2.281787 | D214: 2.282693 | E214: =C214-D214 -> -0.000906 | F214: =C214-C213 -> 0.01182 | G214: =D214-D213 -> 0.01298 | H214: n/a | I214: n/a
A215: 83.834722 | B215: 2012Q2 | C215: 2.289643 | D215: 2.28841 | E215: =C215-D215 -> 0.001233 | F215: =C215-C214 -> 0.007856 | G215: =D215-D214 -> 0.005717 | H215: n/a | I215: n/a
A216: 83.835417 | B216: 2012Q3 | C216: 2.29939 | D216: 2.300297 | E216: =C216-D216 -> -0.000907 | F216: =C216-C215 -> 0.009747 | G216: =D216-D215 -> 0.011887 | H216: n/a | I216: n/a
A217: 83.836111 | B217: 2012Q4 | C217: 2.313137 | D217: 2.31277 | E217: =C217-D217 -> 0.000367 | F217: =C217-C216 -> 0.013747 | G217: =D217-D216 -> 0.012473 | H217: n/a | I217: n/a
A218: 83.875694 | B218: 2013Q1 | C218: 2.319983 | D218: 2.321027 | E218: =C218-D218 -> -0.001044 | F218: =C218-C217 -> 0.006846 | G218: =D218-D217 -> 0.008257 | H218: n/a | I218: n/a
A219: 83.876389 | B219: 2013Q2 | C219: 2.322303 | D219: 2.318318 | E219: =C219-D219 -> 0.003985 | F219: =C219-C218 -> 0.00232 | G219: =D219-D218 -> -0.002709 | H219: n/a | I219: n/a
A220: 83.877083 | B220: 2013Q3 | C220: 2.33476 | D220: 2.327656 | E220: =C220-D220 -> 0.007104 | F220: =C220-C219 -> 0.012457 | G220: =D220-D219 -> 0.009338 | H220: n/a | I220: n/a
A221: 83.877778 | B221: 2013Q4 | C221: 2.341363 | D221: 2.335111 | E221: =C221-D221 -> 0.006252 | F221: =C221-C220 -> 0.006603 | G221: =D221-D220 -> 0.007455 | H221: n/a | I221: n/a
A222: 83.917361 | B222: 2014Q1 | C222: 2.352473 | D222: 2.345591 | E222: =C222-D222 -> 0.006882 | F222: =C222-C221 -> 0.01111 | G222: =D222-D221 -> 0.01048 | H222: n/a | I222: n/a
A223: 83.918056 | B223: 2014Q2 | C223: 2.367656 | D223: 2.356616 | E223: =C223-D223 -> 0.01104 | F223: =C223-C222 -> 0.015183 | G223: =D223-D222 -> 0.011025 | H223: n/a | I223: n/a
...
