Workbook
Name TitleRegion1.a2.d25.1: 'FY2014 SUMMARY'!$A$1
Name TitleRegion1.a2.o24.2: 'District by Cluster'!$D$24
Name TitleRegion10.a257.o266.2: 'District by Cluster'!$A$227
Name TitleRegion11.a268.o296.2: 'District by Cluster'!$A$268
Name TitleRegion12.a298.o310.2: 'District by Cluster'!$A$298
Name TitleRegion13.a312.o316.2: 'District by Cluster'!$A$298
Name TitleRegion14.a318.o327.2: 'District by Cluster'!$A$298
Name TitleRegion15.a329.o337.2: 'District by Cluster'!$A$298
Name TitleRegion16.a339.o349.2: 'District by Cluster'!$A$339
Name TitleRegion2.a26.o36.2: 'District by Cluster'!$D$24
Name TitleRegion2.f1.i4.1: 'FY2014 SUMMARY'!$G$7
Name TitleRegion3.a38.0101.2: 'District by Cluster'!$C$101
Name TitleRegion4.a103.o124.2: 'District by Cluster'!$A$103
Name TitleRegion5.a126.o169.2: 'District by Cluster'!$A$126
Name TitleRegion6.a171.o188.2: 'District by Cluster'!$A$171
Name TitleRegion7.a190.o225.2: 'District by Cluster'!$A$190
Name TitleRegion8.a227.o242.2: 'District by Cluster'!$A$227
Name TitleRegion9.a244.o255.2: 'District by Cluster'!$A$227

Sheet FY2014 SUMMARY
A1: FY2014 Telecomm Equity Aid | B1: n/a | C1: n/a | D1: n/a | F1: PAYMENTS TO INDIVIDUAL SCHOOLS | H1: n/a | I1: n/a
A2: Based on FY2013 Actual Costs | B2: n/a | C2: n/a | D2: n/a | F2: n/a | G2: n/a | H2: Eligible | I2: Prorated
A3: Proration Rate | B3: 0.43512324 | C3: n/a | D3: n/a | F3: n/a | G3: n/a | H3: Aid Amount | I3: Aid Amount
A4: PAYMENTS TO TELECOM ACCESS CLUSTERS | C4: n/a | D4: n/a | F4: 297-01 | G4: SPRING GROVE SCHOOL DISTRICT | H4: 773.07 | I4: =H4*$B$3 -> 336.38072
A5: n/a | B5: Org # | C5: Eligible | D5: Prorated | F5: rest of column left blank | G5: rest of column left blank | H5: rest of column left blank | I5: rest of column left blank
A6: Cluster | B6: Org Type | C6: Aid Amount | D6: Aid Amount
A7: REGION 3-CENTRAL | B7: 0867-82 | C7: ='District by Cluster'!N25 -> 463943.98 | D7: ='District by Cluster'!O25 -> 201872.81
A8: REGION 2 - ARCC | B8: 0868-82 | C8: ='District by Cluster'!N37 -> 85674.13 | D8: ='District by Cluster'!O37 -> 37278.805
A9: NW LINKS (REGION I) | B9: 0869-82 | C9: ='District by Cluster'!N102 -> 1044903.4 | D9: ='District by Cluster'!O102 -> 453603.17
A10: REGION 10 - SOUTHEAST SERVICE COOP | B10: 0921-83 | C10: ='District by Cluster'!N125 -> 336031.94 | D10: ='District by Cluster'!O125 -> 146215.31
A11: REGION 7-TIES | B11: 0925-82 | C11: ='District by Cluster'!N170 -> 2595093 | D11: ='District by Cluster'!O170 -> 1129185.3
A12: REGION 3-NORTHEAST SERVICE COOP | B12: 0927-83 | C12: ='District by Cluster'!N189 -> 429389.33 | D12: ='District by Cluster'!O189 -> 186837.28
A13: REGION 6 & 8-SW/WC SERVICE COOP | B13: 0991-83 | C13: ='District by Cluster'!N226 -> 715241.31 | D13: ='District by Cluster'!O226 -> 311218.12
A14: EAST CENTRAL MN ED | B14: 6003-50 | C14: ='District by Cluster'!N243 -> 584226.93 | D14: ='District by Cluster'!O243 -> 254210.71
A15: FRESHWATER ED. DIST. | B15: 6004-61 | C15: ='District by Cluster'!N256 -> 176915.71 | D15: ='District by Cluster'!O256 -> 76980.137
A16: MN RIVER VALLEY | B16: 6018-61 | C16: ='District by Cluster'!N267 -> 134056.07 | D16: ='District by Cluster'!O267 -> 58330.912
A17: SOCRATES | B17: 6036-50 | C17: ='District by Cluster'!N297 -> 1033952.4 | D17: ='District by Cluster'!O297 -> 449896.73
A18: LITTLE CROW TELE-MEDIA NETWORK | B18: 6040-50 | C18: ='District by Cluster'!N311 -> 430561 | D18: ='District by Cluster'!O311 -> 187347.1
A19: WASIOJA ED. TECH. COOP | B19: 6048-50 | C19: ='District by Cluster'!N317 -> 98400 | D19: ='District by Cluster'!O317 -> 42816.127
A20: CENTRAL MN ED TECH | B20: 6054-50 | C20: ='District by Cluster'!N328 -> 256664.57 | D20: ='District by Cluster'!O328 -> 111680.72
A21: ITASCA AREA | B21: 6070-50 | C21: ='District by Cluster'!N338 -> 98860.7 | D21: ='District by Cluster'!O338 -> 43016.588
A22: MID STATE ED. DISTRICT | B22: 6979-61 | C22: ='District by Cluster'!N350 -> 152992.44 | D22: ='District by Cluster'!O350 -> 59173.837
A23: Total for Cluster Members | B23: n/a | C23: =SUM(C7:C22) -> 8636906.9 | D23: =SUM(D7:D22) -> 3749663.6
A24: District no Cluster | B24: n/a | C24: =H4 -> 773.07 | D24: =I4 -> 336.38072
A25: TOTAL | B25: n/a | C25: =C23+C24 -> 8637680 | D25: =D23+D24 -> 3750000
A26: end of worksheet

Sheet District by Cluster
A1: REGION 3-CENTRAL 0867-82 | C1: =N25 -> 463943.98 | D1: n/a | E1: n/a | F1: n/a | G1: n/a | H1: n/a | I1: n/a | J1: n/a | K1: n/a | L1: n/a | M1: n/a | N1: Aid Eligible Costs | O1: Prorated
A2: Dist Num | B2: District Or School Name | C2: Dist Type | D2: Cluster Name | E2: Cluster Num | F2: Line Lease Before Erate | G2: Line Lease After Erate | H2: Install Before E Rate | I2: Install After E Rate | J2: COOP Costs | K2: Maint Costs | L2: Total Before E Rate | M2: Total E Rate Discount | N2: Total After E Rate | O2: Aid
A3: 1 | B3: AITKIN PUBLIC SCHOOL DISTRICT | C3: 1 | D3: REGION 3 - CENTRAL | E3: 868 | F3: 18224.36 | G3: 5394.57 | H3: 0 | I3: 0 | J3: 2779.78 | K3: 0 | L3: 21004.14 | M3: 12829.79 | N3: 8174.35 | O3: =N3*'FY2014 SUMMARY'!$B$3 -> 3556.8497
A4: 0001 | B4: MINNEAPOLIS PUBLIC SCHOOL | C4: 3 | D4: REGION 3 - CENTRAL | E4: 867 | L4: 790202.54 | M4: 609042.84 | N4: 181159.7 | O4: =N4*'FY2014 SUMMARY'!$B$3 -> 78826.796
A5: 51 | B5: FOLEY PUBLIC SCHOOL DISTRICT | C5: 1 | D5: REGION 3 - CENTRAL | E5: 867 | F5: 35288.94 | G5: 16448.91 | H5: 0 | I5: 0 | J5: 0 | K5: 0 | L5: 35288.94 | M5: 18840.03 | N5: 16448.91 | O5: =N5*'FY2014 SUMMARY'!$B$3 -> 7157.303
A6: 181 | B6: BRAINERD PUBLIC SCHOOL DISTRICT | C6: 1 | D6: REGION 3 - CENTRAL | E6: 867 | F6: 15039.06 | G6: 4361.33 | H6: 0 | I6: 0 | J6: 0 | K6: 0 | L6: =F6 -> 15039.06 | M6: =F6-G6 -> 10677.73 | N6: =F6-M6 -> 4361.33 | O6: =N6*'FY2014 SUMMARY'!$B$3 -> 1897.716
A7: 182 | B7: CROSBY-IRONTON PUBLIC SCHOOL DIST. | C7: 1 | D7: REGION 3 - CENTRAL | E7: 867 | F7: 23026.64 | G7: 5712.71 | H7: 0 | I7: 0 | J7: 0 | K7: 0 | L7: 23026.64 | M7: 17313.93 | N7: 5712.71 | O7: =N7*'FY2014 SUMMARY'!$B$3 -> 2485.7329
A8: 186 | B8: PEQUOT LAKES PUBLIC SCHOOLS | C8: 1 | D8: REGION 3 - CENTRAL | E8: 867 | F8: 22218.48 | G8: 8887.39 | H8: 0 | I8: 0 | J8: 0 | K8: 0 | L8: 22218.48 | M8: 13331.09 | N8: 8887.39 | O8: =N8*'FY2014 SUMMARY'!$B$3 -> 3867.1099
A9: 463 | B9: EDEN VALLEY-WATKINS SCHOOL DISTRICT | C9: 1 | D9: REGION 3 - CENTRAL | E9: 867 | F9: 38224.09 | G9: 11467.23 | H9: 0 | I9: 0 | J9: 0 | K9: 0 | L9: 38224.09 | M9: 26756.86 | N9: 11467.23 | O9: =N9*'FY2014 SUMMARY'!$B$3 -> 4989.6583
A10: 465 | B10: LITCHFIELD PUBLIC SCHOOL DISTRICT | C10: 1 | D10: REGION 3 - CENTRAL | E10: 867 | F10: 48694.84 | G10: 16069.3 | H10: 0 | I10: 0 | J10: 0 | K10: 0 | L10: 48694.84 | M10: 32625.54 | N10: 16069.3 | O10: =N10*'FY2014 SUMMARY'!$B$3 -> 6992.1259
A11: 466 | B11: DASSEL-COKATO PUBLIC SCHOOL DIST. | C11: 1 | D11: REGION 3 - CENTRAL | E11: 867 | F11: 22218.48 | G11: 7776.47 | H11: 0 | I11: 0 | J11: 0 | K11: 0 | L11: 22218.48 | M11: 14442.01 | N11: 7776.47 | O11: =N11*'FY2014 SUMMARY'!$B$3 -> 3383.7228
A12: 726 | B12: BECKER PUBLIC SCHOOL DISTRICT | C12: 1 | D12: REGION 3 - CENTRAL | E12: 867 | F12: 16276.53 | G12: 8952.09 | H12: 0 | I12: 0 | J12: 0 | K12: 0 | L12: 16276.53 | M12: 7324.44 | N12: 8952.09 | O12: =N12*'FY2014 SUMMARY'!$B$3 -> 3895.2624
A13: 727 | B13: BIG LAKE PUBLIC SCHOOL DISTRICT | C13: 1 | D13: REGION 3 - CENTRAL | E13: 867 | F13: 19847.49 | G13: 9923.74 | H13: 0 | I13: 0 | J13: 0 | K13: 0 | L13: 19847.49 | M13: 9923.75 | N13: 9923.74 | O13: =N13*'FY2014 SUMMARY'!$B$3 -> 4318.0499
A14: 739 | B14: KIMBALL PUBLIC SCHOOL DISTRICT | C14: 1 | D14: REGION 3 - CENTRAL | E14: 867 | F14: 19165.2 | G14: 8624.34 | H14: 0 | I14: 0 | J14: 0 | K14: 0 | L14: 19165.2 | M14: 10540.86 | N14: 8624.34 | O14: =N14*'FY2014 SUMMARY'!$B$3 -> 3752.6508
A15: 741 | B15: PAYNESVILLE PUBLIC SCHOOL DISTRICT | C15: 1 | D15: REGION 3 - CENTRAL | E15: 867 | F15: 16290.79 | G15: 4887.24 | H15: 0 | I15: 0 | J15: 0 | K15: 0 | L15: 16290.79 | M15: 11403.55 | N15: 4887.24 | O15: =N15*'FY2014 SUMMARY'!$B$3 -> 2126.5517
A16: 742 | B16: ST. CLOUD PUBLIC SCHOOL DISTRICT | C16: 1 | D16: REGION 3 - CENTRAL | E16: 867 | F16: 64740 | G16: 21502.8 | H16: 0 | I16: 0 | J16: 0 | K16: 0 | L16: 64740 | M16: 43237.2 | N16: 21502.8 | O16: =N16*'FY2014 SUMMARY'!$B$3 -> 9356.368
A17: 748 | B17: SARTELL-ST. STEPHEN SCHOOL DISTRICT | C17: 1 | D17: REGION 3 - CENTRAL | E17: 867 | F17: 21032.94 | G17: 12619.76 | H17: 0 | I17: 0 | J17: 5524.79 | K17: 0 | L17: 26557.73 | M17: 8413.18 | N17: 18144.55 | O17: =N17*'FY2014 SUMMARY'!$B$3 -> 7895.1154
A18: 750 | B18: ROCORI PUBLIC SCHOOL DISTRICT | C18: 1 | D18: REGION 3 - CENTRAL | E18: 867 | F18: 45512.37 | G18: 22501.56 | H18: 0 | I18: 0 | J18: 0 | K18: 0 | L18: 45512.37 | M18: 23010.81 | N18: 22501.56 | O18: =N18*'FY2014 SUMMARY'!$B$3 -> 9790.9517
A19: 879 | B19: DELANO PUBLIC SCHOOL DISTRICT | C19: 1 | D19: REGION 3 - CENTRAL | E19: 867 | F19: 39289.47 | G19: 23573.68 | H19: 0 | I19: 0 | J19: 0 | K19: 0 | L19: 39289.47 | M19: 15715.79 | N19: 23573.68 | O19: =N19*'FY2014 SUMMARY'!$B$3 -> 10257.456
A20: 881 | B20: MAPLE LAKE PUBLIC SCHOOL DISTRICT | C20: 1 | D20: REGION 3 - CENTRAL | E20: 867 | F20: 17464.05 | G20: 8732.02 | H20: 0 | I20: 0 | J20: 0 | K20: 0 | L20: 17464.05 | M20: 8732.03 | N20: 8732.02 | O20: =N20*'FY2014 SUMMARY'!$B$3 -> 3799.5048
A21: 882 | B21: MONTICELLO PUBLIC SCHOOL DISTRICT | C21: 1 | D21: REGION 3 - CENTRAL | E21: 867 | F21: 23449.95 | G21: 12921.98 | H21: 0 | I21: 0 | J21: 7328 | K21: 0 | L21: 30777.95 | M21: 10527.97 | N21: 20249.98 | O21: =N21*'FY2014 SUMMARY'!$B$3 -> 8811.2369
A22: 883 | B22: ROCKFORD PUBLIC SCHOOL DISTRICT | C22: 1 | D22: REGION 3 - CENTRAL | E22: 867 | F22: 16290.99 | G22: 8145.49 | H22: 0 | I22: 0 | J22: 0 | K22: 0 | L22: 16290.99 | M22: 8145.5 | N22: 8145.49 | O22: =N22*'FY2014 SUMMARY'!$B$3 -> 3544.292
A23: 2174 | B23: PINE RIVER-BACKUS SCHOOL DISTRICT | C23: 1 | D23: REGION 3 - CENTRAL | E23: 867 | F23: 19132.53 | G23: 4001.27 | H23: 0 | I23: 0 | J23: 0 | K23: 0 | L23: 19132.53 | M23: 15131.26 | N23: 4001.27 | O23: =N23*'FY2014 SUMMARY'!$B$3 -> 1741.0456
A24: 2687 | B24: HOWARD LAKE-WAVERLY-WINSTED | C24: 1 | D24: REGION 3 - CENTRAL | E24: 867 | F24: 99217.4 | G24: 44647.83 | H24: 0 | I24: 0 | J24: 0 | K24: 0 | L24: 99217.4 | M24: 54569.57 | N24: 44647.83 | O24: =N24*'FY2014 SUMMARY'!$B$3 -> 19427.308
A25: line left blank intentionally | N25: =SUM(N3:N24) -> 463943.98 | O25: =SUM(O3:O24) -> 201872.81
A26: REGION 2-ARCC 0868-82 | C26: =N37 -> 85674.13
A27: Dist Num | B27: District Or School Name | C27: Dist Type | D27: Cluster Name | E27: Cluster Num | F27: Line Lease Before Erate | G27: Line Lease After Erate | H27: Install Before E Rate | I27: Install After E Rate | J27: COOP Costs | K27: Maint Costs | L27: Total Before E Rate | M27: Total E Rate Discount | N27: Total After E Rate
A28: 4 | B28: MCGREGOR PUBLIC SCHOOL DISTRICT | C28: 1 | D28: REGION 2 - ARCC | E28: 868 | F28: 13471.49 | G28: 2020.72 | H28: 0 | I28: 0 | J28: 847.65 | K28: 0 | L28: 14319.14 | M28: 11450.77 | N28: 2868.37 | O28: =N28*'FY2014 SUMMARY'!$B$3 -> 1248.0944
A29: 91 | B29: BARNUM PUBLIC SCHOOL DISTRICT | C29: 1 | D29: REGION 2 - ARCC | E29: 868 | F29: 9058.27 | G29: 3079.81 | H29: 0 | I29: 0 | J29: 1680.17 | K29: 0 | L29: 10738.44 | M29: 5978.46 | N29: 4759.98 | O29: =N29*'FY2014 SUMMARY'!$B$3 -> 2071.1779
A30: 94 | B30: CLOQUET PUBLIC SCHOOL DISTRICT | C30: 1 | D30: REGION 2 - ARCC | E30: 868 | F30: 39624 | G30: 13076 | H30: 0 | I30: 0 | J30: 5829.42 | K30: 0 | L30: 45453.42 | M30: 26548 | N30: 18905.42 | O30: =N30*'FY2014 SUMMARY'!$B$3 -> 8226.1876
A31: 95 | B31: CROMWELL-WRIGHT PUBLIC SCHOOLS | C31: 1 | D31: REGION 2 - ARCC | E31: 868 | F31: 19882.84 | G31: 6022.84 | H31: 0 | I31: 0 | J31: 673.64 | K31: 0 | L31: 20556.48 | M31: 13860 | N31: 6696.48 | O31: =N31*'FY2014 SUMMARY'!$B$3 -> 2913.7941
A32: 99 | B32: ESKO PUBLIC SCHOOL DISTRICT | C32: 1 | D32: REGION 2 - ARCC | E32: 868 | F32: 11400 | G32: 5700 | H32: 0 | I32: 0 | J32: 2668.11 | K32: 0 | L32: 14068.11 | M32: 5700 | N32: 8368.11 | O32: =N32*'FY2014 SUMMARY'!$B$3 -> 3641.1591
A33: 362 | B33: LITTLEFORK-BIG FALLS SCHOOL DIST. | C33: 1 | D33: REGION 2 - ARCC | E33: 868 | F33: 13098 | G33: 3929 | H33: 0 | I33: 0 | J33: 636.87 | K33: 0 | L33: 13734.87 | M33: 9169 | N33: 4565.87 | O33: =N33*'FY2014 SUMMARY'!$B$3 -> 1986.7161
A34: 577 | B34: WILLOW RIVER PUBLIC SCHOOL DISTRICT | C34: 1 | D34: REGION 2 - ARCC | E34: 868 | F34: 20026.38 | G34: 8482.38 | H34: 0 | I34: 0 | J34: 948.21 | K34: 0 | L34: 20974.59 | M34: 11544 | N34: 9430.59 | O34: =N34*'FY2014 SUMMARY'!$B$3 -> 4103.4689
A35: 696 | B35: ELY PUBLIC SCHOOL DISTRICT | C35: 1 | D35: REGION 2 - ARCC | E35: 868 | F35: 23250 | G35: 7290 | H35: 0 | I35: 0 | J35: 2374.98 | K35: 0 | L35: 25624.98 | M35: 15960 | N35: 9664.98 | O35: =N35*'FY2014 SUMMARY'!$B$3 -> 4205.4574
A36: 700 | B36: HERMANTOWN PUBLIC SCHOOL DISTRICT | C36: 1 | D36: REGION 2 - ARCC | E36: 868 | F36: 7800 | G36: 4680 | H36: 18500 | I36: 11100 | J36: 4634.33 | K36: 0 | L36: 30934.33 | M36: 10520 | N36: 20414.33 | O36: =N36*'FY2014 SUMMARY'!$B$3 -> 8882.7494
A37: line left blank intentionally | N37: =SUM(N28:N36) -> 85674.13 | O37: =SUM(O28:O36) -> 37278.805
A38: REGION 1-NWLINKS 0869-82 | C38: =N102 -> 1044903.4
A39: Dist Num | B39: District Or School Name | C39: Dist Type | D39: Cluster Name | E39: Cluster Num | F39: Line Lease Before Erate | G39: Line Lease After Erate | H39: Install Before E Rate | I39: Install After E Rate | J39: COOP Costs | K39: Maint Costs | L39: Total Before E Rate | M39: Total E Rate Discount | N39: Total After E Rate
A40: 23 | B40: FRAZEE-VERGAS PUBLIC SCHOOL DIST. | C40: 1 | D40: REGION 1 - NWLinks | E40: 0869 | F40: 56337.64 | G40: 16901.29 | H40: 0 | I40: 0 | J40: 750 | K40: 0 | L40: 57087.64 | M40: 39436.35 | N40: =L40-M40 -> 17651.29 | O40: =N40*'FY2014 SUMMARY'!$B$3 -> 7680.4865
...
