Workbook
Name Form: ENGLISH!$A$1:$E$34
Name Reporting_Procedures: ENGLISH!$A$35:$E$94
Name Terms: ENGLISH!$A$35:$E$94

Sheet EXTRACT
A1: CODE | B1: PER | C1: PAXCDOM | D1: PAXCEUR | E1: PAXCUE | F1: PAXCNAM | G1: PAXCLAC | H1: PAXCMEA | I1: PAXCASP | J1: PAXCAFR | K1: PAXCTOT | L1: TFRTDOM | M1: TFRTEUR | N1: TFRTUE | O1: TFRTNAM | P1: TFRTLAC | Q1: TFRTMEA | R1: TFRTASP | S1: TFRTAFR | T1: TFRTTOT | U1: ATMCDOM | V1: ATMCEUR | W1: ATMCUE | X1: ATMCNAM | Y1: ATMCLAC | Z1: ATMCMEA | AA1: ATMCASP | AB1: ATMCAFR | AC1: ATMCTOT | AD1: MAIL | AE1: PO&DDEF | AF1: FO&DDEF | AG1: MO&DDEF | AH1: INTLPAX | AI1: INTLFRT | AJ1: INTLATM
A2: =ENGLISH!$D$3 -> 0 | B2: =RIGHT(ENGLISH!$E$3,4) -> 2012 | C2: =ENGLISH!$B$6 -> 0 | D2: =ENGLISH!$B$7 -> 0 | E2: =ENGLISH!$B$8 -> 0 | F2: =ENGLISH!$B$9 -> 0 | G2: =ENGLISH!$B$10 -> 0 | H2: =ENGLISH!$B$11 -> 0 | I2: =ENGLISH!$B$12 -> 0 | J2: =ENGLISH!$B$13 -> 0 | K2: =ENGLISH!$B$14 -> 0 | L2: =ENGLISH!$C$6 -> 0 | M2: =ENGLISH!$C$7 -> 0 | N2: =ENGLISH!$C$8 -> 0 | O2: =ENGLISH!$C$9 -> 0 | P2: =ENGLISH!$C$10 -> 0 | Q2: =ENGLISH!$C$11 -> 0 | R2: =ENGLISH!$C$12 -> 0 | S2: =ENGLISH!$C$13 -> 0 | T2: =ENGLISH!$C$14 -> 0 | U2: =ENGLISH!$D$6 -> 0 | V2: =ENGLISH!$D$7 -> 0 | W2: =ENGLISH!$D$8 -> 0 | X2: =ENGLISH!$D$9 -> 0 | Y2: =ENGLISH!$D$10 -> 0 | Z2: =ENGLISH!$D$11 -> 0 | AA2: =ENGLISH!$D$12 -> 0 | AB2: =ENGLISH!$D$13 -> 0 | AC2: =ENGLISH!$D$14 -> 0 | AD2: =ENGLISH!$E$14 -> 0 | AH2: =ENGLISH!B7+ENGLISH!B9+ENGLISH!B10+ENGLISH!B11+ENGLISH!B12+ENGLISH!B13 -> 0 | AI2: =ENGLISH!C7+ENGLISH!C9+ENGLISH!C10+ENGLISH!C11+ENGLISH!C12+ENGLISH!C13 -> 0 | AJ2: =ENGLISH!D7+ENGLISH!D9+ENGLISH!D10+ENGLISH!D11+ENGLISH!D12+ENGLISH!D13 -> 0

Sheet FRANÇAIS
A1: Ventilation annuelle du trafic aéroportuaire
A2: par région d'origine et de destination
A3: AEROPORT/VILLE : | C3: CODE IATA 3-LTR : | E3: ANNEE : 2012
A5: REGIONS | B5: TOTAL PASSAGERS AEROGARE | C5: TOTAL FRET (en tonnes) | D5: TOTAL MOUVEMENTS COMMERCIAUX | E5: TOTAL POSTE
A6: INTERIEUR
A7: EUROPE
A8: DONT L' U.E.
A9: AMERIQUE DU NORD
A10: AMERIQUE LATINE/CARAIBES
A11: MOYEN-ORIENT
A12: ASIE/PACIFIQUE
A13: AFRIQUE
A14: TOTAL*
A17: Origine et destination :
A18: (Veuillez vous référer aux définitions des termes et cocher la case appropriée)
B19: PASSAGERS AEROGARE | C19: FRET | D19: MOUVEMENTS COMMERCIAUX
A20: Lieu d'embarquement/débarquement (passagers)
A21: Lieu de chargement/déchargement (fret)
A23: Origine initiale et destination finale du vol
A25: Dernière provenance et prochaine destination du vol
A27: Formulaire rempli par : | C27: Télécopie/Téléphone/E-mail :
E34: Voir définitions des termes page suivante ...
A35: N.B.
A36: 1 Les données se rapportent à une année civile
A37: 2 Veuillez remplir la case de la personne à contacter (nom, téléphone, télécopie, e-mail)
A38: 3 A retourner au Siège mondial de l'ACI, à l'attention de Patrick Lucas
A39: Case postale PO Box 302, 800 Rue du Square Victoria, Montreal, Quebec H4Z 1G8, Canada
A40: Télécopie : +1 514 373 1201
A41: E-mail : stats@aci.aero
A43: Définitions des termes
A45: Origine et destination
A46: Passagers
A47: Lieux d'embarquement et de débarquement des passagers ainsi qu'ils apparaissent sur le coupon du vol, pour
A48: autant qu'ils concernent le même numéro de vol. Si les données ne sont pas fournies sur la base du coupon de
... A53: Passager détenteur d'un ticket comportant les trois coupons suivants :
A54: Naples - Rome | B54: Route AZ 119
A55: Rome - Paris | B55: Route AZ 320
A56: Paris - New York | B56: Route AZ 011
A58: Dans le cas de l'aéroport de Rome, l'origine de ce passager étant Naples et sa destination Paris, il sera classé
A59: de la manière suivante :
...

Sheet ENGLISH
A1: Annual Airport Traffic by Region of Origin and Destination
A3: AIRPORT/CITY: | C3: 3-LTR IATA CODE: | E3: YEAR: 2012
A5: REGIONS | B5: TOTAL TERMINAL PASSENGERS | C5: TOTAL FREIGHT (in tonnes) | D5: TOTAL AIR TRANSPORT MOVEMENTS | E5: TOTAL MAIL
A6: DOMESTIC
A7: EUROPE
A8: of which E.U.
A9: NORTH AMERICA
A10: LATIN AMERICA/CARIBBEAN
A11: MIDDLE EAST
A12: ASIA/PACIFIC
A13: AFRICA
A14: TOTAL*
A17: Origin and Destination defined as:
A18: (Please refer to Definition of Terms and tick box where applicable)
B19: TERMINAL PASSENGERS | C19: FREIGHT | D19: AIR TRANSPORT MOVEMENTS
A20: Point of Embarkation/Disembarkation (Passengers)
A21: Point of Loading/Unloading (Freight)
A23: First Origin and Last Destination of Flight
A25: Last Origin and First Destination of Flight
A27: Prepared by: | C27: FAX/Phone/E-mail:
E34: Definition of Terms next page please ...
A35: Reporting Procedures:
A36: 1 Data is for calendar year
A37: 2 Please fill-in the box for the contact person and how he/she may be reached
A38: 3 Please return to ACI World Headquarters, attention Patrick Lucas
A39: by post: PO Box 302, 800 Rue du Square Victoria, Montreal, Quebec H4Z 1G8, Canada
A40: by fax: +1 514 373 1201
A41: by e-mail: stats@aci.aero
A43: Definition of Terms:
A45: Origin and Destination
A46: Passengers
A47: The passengers' embarkation points and disembarkation points as they appear on the flight coupon as far as it concerns
A48: the same flight number. If data is not available on a flight coupon basis, please indicate the basis upon which the
... A53: Passengers holding a ticket including the following three coupons:
A54: Naples - Rome | B54: Route AZ 119
A55: Rome - Paris | B55: Route AZ 320
A56: Paris - New York | B56: Route AZ 011
A58: In the case of Rome airport, this passenger's origin is Naples and his destination is Paris, he will be classified:
A59: - on arrival under "Domestic"
A60: - on departure, under "Europe"
...

Sheet QUAERO
A1: YEAR | B1: EUR | C1: 20080328 | D1: PAXCDOM | E1: PAXCEUR | F1: PAXCUE | G1: PAXCNAM | H1: PAXCLAC | I1: PAXCMEA | J1: PAXCASP | K1: PAXCAFR | L1: PAXCTOT | M1: TFRTDOM | N1: TFRTEUR | O1: TFRTUE | P1: TFRTNAM | Q1: TFRTLAC | R1: TFRTMEA | S1: TFRTASP | T1: TFRTAFR | U1: TFRTTOT | V1: ATMCDOM | W1: ATMCEUR | X1: ATMCUE | Y1: ATMCNAM | Z1: ATMCLAC | AA1: ATMCMEA | AB1: ATMCASP | AC1: ATMCAFR | AD1: ATMCTOT | AE1: MAIL | AF1: PO&DDEF | AG1: FO&DDEF | AH1: MO&DDEF | AI1: INTLPAX | AJ1: INTLFRT | AK1: INTLATM
A2: IATA | B2: YEAR | C2: MONTH | D2: C72 | E2: C73 | F2: C74 | G2: C75 | H2: C76 | I2: C77 | J2: C78 | K2: C79 | L2: C71 | M2: C82 | N2: C83 | O2: C84 | P2: C85 | Q2: C86 | R2: C87 | S2: C88 | T2: C89 | U2: C81 | V2: C92 | W2: C93 | X2: C94 | Y2: C95 | Z2: C96 | AA2: C97 | AB2: C98 | AC2: C99 | AD2: C91 | AE2: C101 | AI2: C80 | AJ2: C90 | AK2: C100 | AL2: END
A3: =IF(EXTRACT!A2=0,"",EXTRACT!A2) | B3: =IF(EXTRACT!B2=0,"",EXTRACT!B2) -> 2012 | D3: =IF(EXTRACT!C2=0,"",EXTRACT!C2) | E3: =IF(EXTRACT!D2=0,"",EXTRACT!D2) | F3: =IF(EXTRACT!E2=0,"",EXTRACT!E2) | G3: =IF(EXTRACT!F2=0,"",EXTRACT!F2) | H3: =IF(EXTRACT!G2=0,"",EXTRACT!G2) | I3: =IF(EXTRACT!H2=0,"",EXTRACT!H2) | J3: =IF(EXTRACT!I2=0,"",EXTRACT!I2) | K3: =IF(EXTRACT!J2=0,"",EXTRACT!J2) | ... AK3: =IF(EXTRACT!AJ2=0,"",EXTRACT!AJ2)
A4: =IF(EXTRACT!A3=0,"",EXTRACT!A3) | B4: =IF(EXTRACT!B3=0,"",EXTRACT!B3) | D4: =IF(EXTRACT!C3=0,"",EXTRACT!C3) | E4: =IF(EXTRACT!D3=0,"",EXTRACT!D3) | F4: =IF(EXTRACT!E3=0,"",EXTRACT!E3) | G4: =IF(EXTRACT!F3=0,"",EXTRACT!F3) | H4: =IF(EXTRACT!G3=0,"",EXTRACT!G3) | I4: =IF(EXTRACT!H3=0,"",EXTRACT!H3) | J4: =IF(EXTRACT!I3=0,"",EXTRACT!I3) | K4: =IF(EXTRACT!J3=0,"",EXTRACT!J3) | ... AK4: =IF(EXTRACT!AJ3=0,"",EXTRACT!AJ3)
A5: =IF(EXTRACT!A4=0,"",EXTRACT!A4) | B5: =IF(EXTRACT!B4=0,"",EXTRACT!B4) | D5: =IF(EXTRACT!C4=0,"",EXTRACT!C4) | E5: =IF(EXTRACT!D4=0,"",EXTRACT!D4) | F5: =IF(EXTRACT!E4=0,"",EXTRACT!E4) | G5: =IF(EXTRACT!F4=0,"",EXTRACT!F4) | H5: =IF(EXTRACT!G4=0,"",EXTRACT!G4) | I5: =IF(EXTRACT!H4=0,"",EXTRACT!H4) | J5: =IF(EXTRACT!I4=0,"",EXTRACT!I4) | K5: =IF(EXTRACT!J4=0,"",EXTRACT!J4) | ... AK5: =IF(EXTRACT!AJ4=0,"",EXTRACT!AJ4)
A6: =IF(EXTRACT!A5=0,"",EXTRACT!A5) | B6: =IF(EXTRACT!B5=0,"",EXTRACT!B5) | D6: =IF(EXTRACT!C5=0,"",EXTRACT!C5) | E6: =IF(EXTRACT!D5=0,"",EXTRACT!D5) | F6: =IF(EXTRACT!E5=0,"",EXTRACT!E5) | G6: =IF(EXTRACT!F5=0,"",EXTRACT!F5) | H6: =IF(EXTRACT!G5=0,"",EXTRACT!G5) | I6: =IF(EXTRACT!H5=0,"",EXTRACT!H5) | J6: =IF(EXTRACT!I5=0,"",EXTRACT!I5) | K6: =IF(EXTRACT!J5=0,"",EXTRACT!J5) | ... AK6: =IF(EXTRACT!AJ5=0,"",EXTRACT!AJ5)
A7: =IF(EXTRACT!A6=0,"",EXTRACT!A6) | B7: =IF(EXTRACT!B6=0,"",EXTRACT!B6) | D7: =IF(EXTRACT!C6=0,"",EXTRACT!C6) | E7: =IF(EXTRACT!D6=0,"",EXTRACT!D6) | F7: =IF(EXTRACT!E6=0,"",EXTRACT!E6) | G7: =IF(EXTRACT!F6=0,"",EXTRACT!F6) | H7: =IF(EXTRACT!G6=0,"",EXTRACT!G6) | I7: =IF(EXTRACT!H6=0,"",EXTRACT!H6) | J7: =IF(EXTRACT!I6=0,"",EXTRACT!I6) | K7: =IF(EXTRACT!J6=0,"",EXTRACT!J6) | ... AK7: =IF(EXTRACT!AJ6=0,"",EXTRACT!AJ6)
A8: =IF(EXTRACT!A7=0,"",EXTRACT!A7) | B8: =IF(EXTRACT!B7=0,"",EXTRACT!B7) | D8: =IF(EXTRACT!C7=0,"",EXTRACT!C7) | E8: =IF(EXTRACT!D7=0,"",EXTRACT!D7) | F8: =IF(EXTRACT!E7=0,"",EXTRACT!E7) | G8: =IF(EXTRACT!F7=0,"",EXTRACT!F7) | H8: =IF(EXTRACT!G7=0,"",EXTRACT!G7) | I8: =IF(EXTRACT!H7=0,"",EXTRACT!H7) | J8: =IF(EXTRACT!I7=0,"",EXTRACT!I7) | K8: =IF(EXTRACT!J7=0,"",EXTRACT!J7) | ... AK8: =IF(EXTRACT!AJ7=0,"",EXTRACT!AJ7)
A9: =IF(EXTRACT!A8=0,"",EXTRACT!A8) | B9: =IF(EXTRACT!B8=0,"",EXTRACT!B8) | D9: =IF(EXTRACT!C8=0,"",EXTRACT!C8) | E9: =IF(EXTRACT!D8=0,"",EXTRACT!D8) | F9: =IF(EXTRACT!E8=0,"",EXTRACT!E8) | G9: =IF(EXTRACT!F8=0,"",EXTRACT!F8) | H9: =IF(EXTRACT!G8=0,"",EXTRACT!G8) | I9: =IF(EXTRACT!H8=0,"",EXTRACT!H8) | J9: =IF(EXTRACT!I8=0,"",EXTRACT!I8) | K9: =IF(EXTRACT!J8=0,"",EXTRACT!J8) | ... AK9: =IF(EXTRACT!AJ8=0,"",EXTRACT!AJ8)
A10: =IF(EXTRACT!A9=0,"",EXTRACT!A9) | B10: =IF(EXTRACT!B9=0,"",EXTRACT!B9) | D10: =IF(EXTRACT!C9=0,"",EXTRACT!C9) | E10: =IF(EXTRACT!D9=0,"",EXTRACT!D9) | F10: =IF(EXTRACT!E9=0,"",EXTRACT!E9) | G10: =IF(EXTRACT!F9=0,"",EXTRACT!F9) | H10: =IF(EXTRACT!G9=0,"",EXTRACT!G9) | I10: =IF(EXTRACT!H9=0,"",EXTRACT!H9) | J10: =IF(EXTRACT!I9=0,"",EXTRACT!I9) | K10: =IF(EXTRACT!J9=0,"",EXTRACT!J9) | ... AK10: =IF(EXTRACT!AJ9=0,"",EXTRACT!AJ9)
A11: =IF(EXTRACT!A10=0,"",EXTRACT!A10) | B11: =IF(EXTRACT!B10=0,"",EXTRACT!B10) | D11: =IF(EXTRACT!C10=0,"",EXTRACT!C10) | E11: =IF(EXTRACT!D10=0,"",EXTRACT!D10) | F11: =IF(EXTRACT!E10=0,"",EXTRACT!E10) | G11: =IF(EXTRACT!F10=0,"",EXTRACT!F10) | H11: =IF(EXTRACT!G10=0,"",EXTRACT!G10) | I11: =IF(EXTRACT!H10=0,"",EXTRACT!H10) | J11: =IF(EXTRACT!I10=0,"",EXTRACT!I10) | K11: =IF(EXTRACT!J10=0,"",EXTRACT!J10) | ... AK11: =IF(EXTRACT!AJ10=0,"",EXTRACT!AJ10)
A12: =IF(EXTRACT!A11=0,"",EXTRACT!A11) | B12: =IF(EXTRACT!B11=0,"",EXTRACT!B11) | D12: =IF(EXTRACT!C11=0,"",EXTRACT!C11) | E12: =IF(EXTRACT!D11=0,"",EXTRACT!D11) | F12: =IF(EXTRACT!E11=0,"",EXTRACT!E11) | G12: =IF(EXTRACT!F11=0,"",EXTRACT!F11) | H12: =IF(EXTRACT!G11=0,"",EXTRACT!G11) | I12: =IF(EXTRACT!H11=0,"",EXTRACT!H11) | J12: =IF(EXTRACT!I11=0,"",EXTRACT!I11) | K12: =IF(EXTRACT!J11=0,"",EXTRACT!J11) | ... AK12: =IF(EXTRACT!AJ11=0,"",EXTRACT!AJ11)
A13: =IF(EXTRACT!A12=0,"",EXTRACT!A12) | B13: =IF(EXTRACT!B12=0,"",EXTRACT!B12) | D13: =IF(EXTRACT!C12=0,"",EXTRACT!C12) | E13: =IF(EXTRACT!D12=0,"",EXTRACT!D12) | F13: =IF(EXTRACT!E12=0,"",EXTRACT!E12) | G13: =IF(EXTRACT!F12=0,"",EXTRACT!F12) | H13: =IF(EXTRACT!G12=0,"",EXTRACT!G12) | I13: =IF(EXTRACT!H12=0,"",EXTRACT!H12) | J13: =IF(EXTRACT!I12=0,"",EXTRACT!I12) | K13: =IF(EXTRACT!J12=0,"",EXTRACT!J12) | ... AK13: =IF(EXTRACT!AJ12=0,"",EXTRACT!AJ12)
A14: =IF(EXTRACT!A13=0,"",EXTRACT!A13) | B14: =IF(EXTRACT!B13=0,"",EXTRACT!B13) | D14: =IF(EXTRACT!C13=0,"",EXTRACT!C13) | E14: =IF(EXTRACT!D13=0,"",EXTRACT!D13) | F14: =IF(EXTRACT!E13=0,"",EXTRACT!E13) | G14: =IF(EXTRACT!F13=0,"",EXTRACT!F13) | H14: =IF(EXTRACT!G13=0,"",EXTRACT!G13) | I14: =IF(EXTRACT!H13=0,"",EXTRACT!H13) | J14: =IF(EXTRACT!I13=0,"",EXTRACT!I13) | K14: =IF(EXTRACT!J13=0,"",EXTRACT!J13) | ... AK14: =IF(EXTRACT!AJ13=0,"",EXTRACT!AJ13)
... A504: =IF(EXTRACT!A503=0,"",EXTRACT!A503) | B504: =IF(EXTRACT!B503=0,"",EXTRACT!B503) | D504: =IF(EXTRACT!C503=0,"",EXTRACT!C503) | E504: =IF(EXTRACT!D503=0,"",EXTRACT!D503) | F504: =IF(EXTRACT!E503=0,"",EXTRACT!E503) | G504: =IF(EXTRACT!F503=0,"",EXTRACT!F503) | H504: =IF(EXTRACT!G503=0,"",EXTRACT!G503) | I504: =IF(EXTRACT!H503=0,"",EXTRACT!H503) | J504: =IF(EXTRACT!I503=0,"",EXTRACT!I503) | K504: =IF(EXTRACT!J503=0,"",EXTRACT!J503) | ... AK504: =IF(EXTRACT!AJ503=0,"",EXTRACT!AJ503)
