Workbook
Name randdata: [1]Sheet1!$D$2:$D$2001
Name test4data: '[1]TEST 4 (FINAL)'!$J$13:$J$75

Sheet OVERVIEW
L1: T1 | M1: T2 | N1: T3 | O1: T4 | P1: T4-Extension
B2: NOTE: All samples were tested using 2ml of deionised H2O | J2: Relative Standard Deviation | L2: =STDEV(C9:C32)/AVERAGE(F9:F32) -> 0.013183908 | M2: =STDEV(E9:E32)/AVERAGE(G9:G32) -> 0.46400771 | N2: =STDEV(G9:G32)/AVERAGE(H9:H32) -> 0.006864422 | O2: =STDEV(I9:I32)/AVERAGE(I9:I32) -> 0.3179143 | P2: =STDEV(I33:I71)/AVERAGE(I33:I71) -> 0.42956751
J3: RSD% | L3: =STDEV(C9:C32)/AVERAGE(F10:F33)*100 -> 1.3183908 | M3: =STDEV(E9:E32)/AVERAGE(G10:G33)*100 -> 44.467406 | N3: =STDEV(G9:G32)/AVERAGE(H10:H33)*100 -> 0.6864422 | O3: =STDEV(I10:I33)/AVERAGE(I10:I33)*100 -> 31.796942 | P3: =STDEV(I33:I71)/AVERAGE(I33:I71)*100 -> 42.956751
A7: Sample | B7: TEST 1 | D7: TEST 2 | F7: TEST 3 | H7: TEST 4
A8: id. | B8: v (ul) | C8: ='[1]TEST 1 (T1)'!I4 -> 260/280 | D8: v (ul) | E8: ='[1]TEST 2 (T2)'!I7 -> 260/280 | F8: v (ul) | G8: ='[1]TEST 3 (T3)'!I5 -> 260/280 | H8: v (ul) | I8: ='[1]TEST 4 (FINAL)'!J11 -> 260/280 | K8: Blood storage | L8: Date | M8: Time
A9: 1 | B9: 50 | C9: ='[1]TEST 1 (T1)'!I5 -> 1.1891892 | D9: 150 | E9: ='[1]TEST 2 (T2)'!I8 -> 1.0465116 | F9: 50 | G9: ='[1]TEST 3 (T3)'!Q20 -> 0 | H9: 50 | I9: ='[1]TEST 4 (FINAL)'!J13 -> 1.25
A10: 2 | B10: 50 | C10: ='[1]TEST 1 (T1)'!I6 -> 1.1666667 | D10: 150 | E10: ='[1]TEST 2 (T2)'!I9 -> 1.1071429 | F10: 50 | G10: ='[1]TEST 3 (T3)'!Q21 -> 1.3809524 | H10: 50 | I10: ='[1]TEST 4 (FINAL)'!J14 -> 1.2222222 | K10: Collection (on wet ice) | L10: 41018
A11: 3 | B11: 50 | C11: ='[1]TEST 1 (T1)'!I7 -> 1.25 | D11: 150 | E11: ='[1]TEST 2 (T2)'!I10 -> 1.2307692 | F11: 50 | G11: ='[1]TEST 3 (T3)'!Q22 -> 1.1538462 | H11: 50 | I11: ='[1]TEST 4 (FINAL)'!J15 -> 1.4375 | K11: Refrigerated (at 4 d C) | L11: 41018
A12: 4 | B12: 50 | C12: ='[1]TEST 1 (T1)'!I8 -> 1.4 | D12: 150 | E12: ='[1]TEST 2 (T2)'!I11 -> 1.1 | F12: 50 | G12: ='[1]TEST 3 (T3)'!Q23 -> 1.5454545 | H12: 50 | I12: ='[1]TEST 4 (FINAL)'!J16 -> 1.4444444 | K12: Frozen (-20 d C frost freeze) | L12: 41023
A13: 5 | B13: 50 | C13: ='[1]TEST 1 (T1)'!I9 -> 0.5 | D13: 150 | E13: ='[1]TEST 2 (T2)'!I12 -> 0.875 | F13: 50 | G13: ='[1]TEST 3 (T3)'!I10 -> 1.2 | H13: 50 | I13: ='[1]TEST 4 (FINAL)'!J17 -> 0 | K13: Thawed (at 4 d C) | L13: 41150 | M13: 0.5
A14: 6 | B14: 50 | C14: ='[1]TEST 1 (T1)'!I10 -> 1.2 | D14: 150 | E14: ='[1]TEST 2 (T2)'!I13 -> 0.87096774 | F14: 50 | G14: ='[1]TEST 3 (T3)'!I11 -> 1.4285714 | H14: 50 | I14: ='[1]TEST 4 (FINAL)'!J18 -> 1.3333333
A15: 7 | B15: 50 | C15: ='[1]TEST 1 (T1)'!I11 -> 1.25 | D15: 150 | E15: ='[1]TEST 2 (T2)'!I14 -> 0.89285714 | F15: 50 | G15: ='[1]TEST 3 (T3)'!I12 -> 1.5 | H15: 50 | I15: ='[1]TEST 4 (FINAL)'!J19 -> 1 | K15: t-Test: Two-Sample Assuming Equal Variances | O15: t-Test: Two-Sample Assuming Equal Variances | S15: t-Test: Two-Sample Assuming Equal Variances
A16: 8 | B16: 50 | C16: ='[1]TEST 1 (T1)'!I12 -> 1.3333333 | D16: 150 | E16: ='[1]TEST 2 (T2)'!I15 -> 0.95238095 | F16: 50 | G16: ='[1]TEST 3 (T3)'!I13 -> 1.3846154 | H16: 50 | I16: ='[1]TEST 4 (FINAL)'!J20 -> 1.4166667 | K16: (Compare Test 1 & 2) | O16: (Compare Test 2 & 4 extension) | S16: (Compare Test 3 & 4)
A17: 9 | B17: 50 | C17: ='[1]TEST 1 (T1)'!I13 -> 1.4666667 | D17: 150 | E17: ='[1]TEST 2 (T2)'!I16 -> 0.64285714 | F17: 50 | G17: ='[1]TEST 3 (T3)'!I14 -> 1.5 | H17: 50 | I17: ='[1]TEST 4 (FINAL)'!J21 -> 0.75 | L17: Variable 1 | M17: Variable 2 | P17: Variable 1 | Q17: Variable 2 | T17: Variable 1 | U17: Variable 2
A18: 10 | B18: 50 | C18: ='[1]TEST 1 (T1)'!I14 -> 2 | D18: 150 | E18: ='[1]TEST 2 (T2)'!I17 -> 0.25 | F18: 50 | G18: ='[1]TEST 3 (T3)'!I15 -> 1.4 | H18: 50 | I18: ='[1]TEST 4 (FINAL)'!J22 -> 1.3333333 | K18: Mean | L18: 1.0959705 | M18: 0.94638471 | O18: Mean | P18: 0.94638471 | Q18: 1.049243 | S18: Mean | T18: 1.3620879 | U18: 1.1271712
A19: 11 | B19: 50 | C19: ='[1]TEST 1 (T1)'!I15 -> 0 | D19: 150 | E19: ='[1]TEST 2 (T2)'!I18 -> 0.66666667 | F19: 50 | G19: ='[1]TEST 3 (T3)'!I16 -> 1.4444444 | H19: 50 | I19: ='[1]TEST 4 (FINAL)'!J23 -> 1.0909091 | K19: Variance | L19: 0.4345386 | M19: 0.39944839 | O19: Variance | P19: 0.39944839 | Q19: 0.20314915 | S19: Variance | T19: 0.11780072 | U19: 0.12841032
A20: 12 | B20: 50 | C20: ='[1]TEST 1 (T1)'!I16 -> 0 | D20: 150 | E20: ='[1]TEST 2 (T2)'!I19 -> 2.75 | F20: 50 | G20: ='[1]TEST 3 (T3)'!I17 -> 1.5 | H20: 50 | I20: ='[1]TEST 4 (FINAL)'!J24 -> 1.4117647 | K20: Observations | L20: 24 | M20: 24 | O20: Observations | P20: 24 | Q20: 39 | S20: Observations | T20: 24 | U20: 24
A21: 13 | B21: 50 | C21: ='[1]TEST 1 (T1)'!I17 -> 1 | D21: 150 | E21: ='[1]TEST 2 (T2)'!I20 -> 0.88888889 | F21: 50 | G21: ='[1]TEST 3 (T3)'!I18 -> 1.4 | H21: 50 | I21: ='[1]TEST 4 (FINAL)'!J25 -> 1.4 | K21: Pooled Variance | L21: 0.4169935 | O21: Pooled Variance | P21: 0.27716362 | S21: Pooled Variance | T21: 0.12310552
A22: 14 | B22: 50 | C22: ='[1]TEST 1 (T1)'!I18 -> 1.3333333 | D22: 150 | E22: ='[1]TEST 2 (T2)'!I21 -> 0.71428571 | F22: 50 | G22: ='[1]TEST 3 (T3)'!Q24 -> 1.3636364 | H22: 50 | I22: ='[1]TEST 4 (FINAL)'!J26 -> 1.1818182 | K22: Hypothesized Mean Difference | L22: 0 | O22: Hypothesized Mean Difference | P22: 0 | S22: Hypothesized Mean Difference | T22: 0
A23: 15 | B23: 50 | C23: ='[1]TEST 1 (T1)'!I19 -> 1.3333333 | D23: 150 | E23: ='[1]TEST 2 (T2)'!I22 -> 0.4 | F23: 50 | G23: ='[1]TEST 3 (T3)'!I20 -> 1.5555556 | H23: 50 | I23: ='[1]TEST 4 (FINAL)'!J27 -> 1.5 | K23: df | L23: 46 | O23: df | P23: 61 | S23: df | T23: 46
A24: 16 | B24: 50 | C24: ='[1]TEST 1 (T1)'!I20 -> 2 | D24: 150 | E24: ='[1]TEST 2 (T2)'!I23 -> 2.6666667 | F24: 50 | G24: ='[1]TEST 3 (T3)'!Q25 -> 1.4897959 | H24: 50 | I24: ='[1]TEST 4 (FINAL)'!J28 -> 1.3333333 | K24: t Stat | L24: 0.80244689 | O24: t Stat | P24: -0.75307592 | S24: t Stat | T24: 2.3193468
A25: 17 | B25: 50 | C25: ='[1]TEST 1 (T1)'!I21 -> 1.2307692 | D25: 150 | E25: ='[1]TEST 2 (T2)'!I24 -> 1.25 | F25: 50 | G25: ='[1]TEST 3 (T3)'!I22 -> 1.4705882 | H25: 50 | I25: ='[1]TEST 4 (FINAL)'!J29 -> 1.2727273 | K25: P(T<=t) one-tail | L25: 0.2132105 | O25: P(T<=t) one-tail | P25: 0.22715049 | S25: P(T<=t) one-tail | T25: 0.012435108
A26: 18 | B26: 50 | C26: ='[1]TEST 1 (T1)'!I22 -> 0 | D26: 150 | E26: ='[1]TEST 2 (T2)'!I25 -> 0.90322581 | F26: 50 | G26: ='[1]TEST 3 (T3)'!I23 -> 1.5 | H26: 50 | I26: ='[1]TEST 4 (FINAL)'!J30 -> 1.173913 | K26: t Critical one-tail | L26: 1.6786604 | O26: t Critical one-tail | P26: 1.6702195 | S26: t Critical one-tail | T26: 1.6786604
A27: 19 | B27: 50 | C27: ='[1]TEST 1 (T1)'!I23 -> 1.75 | D27: 150 | E27: ='[1]TEST 2 (T2)'!I26 -> 0.92857143 | F27: 50 | G27: ='[1]TEST 3 (T3)'!I24 -> 1.4444444 | H27: 50 | I27: ='[1]TEST 4 (FINAL)'!J31 -> 1.2222222 | K27: P(T<=t) two-tail | L27: 0.426421 | O27: P(T<=t) two-tail | P27: 0.45430099 | S27: P(T<=t) two-tail | T27: 0.024870215
A28: 20 | B28: 50 | C28: ='[1]TEST 1 (T1)'!I24 -> 1.5 | D28: 150 | E28: ='[1]TEST 2 (T2)'!I27 -> 0.052631579 | F28: 50 | G28: ='[1]TEST 3 (T3)'!I25 -> 1.4615385 | H28: 50 | I28: ='[1]TEST 4 (FINAL)'!J32 -> 0.86666667 | K28: t Critical two-tail | L28: 2.0128956 | O28: t Critical two-tail | P28: 1.9996236 | S28: t Critical two-tail | T28: 2.0128956
A29: 21 | B29: 50 | C29: ='[1]TEST 1 (T1)'!I25 -> 0 | D29: 150 | E29: ='[1]TEST 2 (T2)'!I28 -> 0.14285714 | F29: 50 | G29: ='[1]TEST 3 (T3)'!I26 -> 1.4 | H29: 50 | I29: ='[1]TEST 4 (FINAL)'!J33 -> 0.36363636
A30: 22 | B30: 50 | C30: ='[1]TEST 1 (T1)'!I26 -> 0 | D30: 150 | E30: ='[1]TEST 2 (T2)'!I29 -> 0.52380952 | F30: 50 | G30: ='[1]TEST 3 (T3)'!I27 -> 2 | H30: 50 | I30: ='[1]TEST 4 (FINAL)'!J34 -> 0.83333333 | K30: t-Test: Two-Sample Assuming Equal Variances | O30: t-Test: Two-Sample Assuming Equal Variances
A31: 23 | B31: 50 | C31: ='[1]TEST 1 (T1)'!I27 -> 1.4 | D31: 150 | E31: ='[1]TEST 2 (T2)'!I30 -> 0.71428571 | F31: 50 | G31: ='[1]TEST 3 (T3)'!Q26 -> 1.1666667 | H31: 50 | I31: ='[1]TEST 4 (FINAL)'!J35 -> 1.2142857 | K31: (Compare test 2 & 3) | O31: (Compare Test 1 & 3)
A32: 24 | B32: 50 | C32: ='[1]TEST 1 (T1)'!I28 -> 2 | D32: 150 | E32: ='[1]TEST 2 (T2)'!I31 -> 1.1428571 | F32: 50 | G32: ='[1]TEST 3 (T3)'!Q27 -> 1 | H32: 50 | I32: ='[1]TEST 4 (FINAL)'!J36 -> 1 | L32: Variable 1 | M32: Variable 2 | P32: Variable 1 | Q32: Variable 2
A33: 25 | H33: 50 | I33: ='[1]TEST 4 (FINAL)'!J37 -> 1.2 | K33: Mean | L33: 0.94638471 | M33: 1.3620879 | O33: Mean | P33: 1.0959705 | Q33: 1.3620879
A34: 26 | H34: 50 | I34: ='[1]TEST 4 (FINAL)'!J38 -> 1 | K34: Variance | L34: 0.39944839 | M34: 0.11780072 | O34: Variance | P34: 0.4345386 | Q34: 0.11780072
A35: 27 | H35: 50 | I35: ='[1]TEST 4 (FINAL)'!J39 -> 1.2 | K35: Observations | L35: 24 | M35: 24 | O35: Observations | P35: 24 | Q35: 24
A36: 28 | H36: 50 | I36: ='[1]TEST 4 (FINAL)'!J40 -> 1.25 | K36: Pooled Variance | L36: 0.25862456 | O36: Pooled Variance | P36: 0.27616966
A37: 29 | H37: 50 | I37: ='[1]TEST 4 (FINAL)'!J41 -> 0.42857143 | K37: Hypothesized Mean Difference | L37: 0 | O37: Hypothesized Mean Difference | P37: 0
A38: 30 | H38: 50 | I38: ='[1]TEST 4 (FINAL)'!J42 -> 1 | K38: df | L38: 46 | O38: df | P38: 46
A39: 31 | H39: 50 | I39: ='[1]TEST 4 (FINAL)'!J43 -> 1.1666667 | K39: t Stat | L39: -2.8316471 | O39: t Stat | P39: -1.7541873
A40: 32 | H40: 50 | I40: ='[1]TEST 4 (FINAL)'!J44 -> 1.3333333 | K40: P(T<=t) one-tail | L40: 0.0034239047 | O40: P(T<=t) one-tail | P40: 0.043029305
A41: 33 | H41: 50 | I41: ='[1]TEST 4 (FINAL)'!J45 -> 0.9 | K41: t Critical one-tail | L41: 1.6786604 | O41: t Critical one-tail | P41: 1.6786604
A42: 34 | H42: 50 | I42: ='[1]TEST 4 (FINAL)'!J46 -> 1.1 | K42: P(T<=t) two-tail | L42: 0.0068478095 | O42: P(T<=t) two-tail | P42: 0.086058611
A43: 35 | H43: 50 | I43: ='[1]TEST 4 (FINAL)'!J47 -> 0.85714286 | K43: t Critical two-tail | L43: 2.0128956 | O43: t Critical two-tail | P43: 2.0128956
...

Sheet TEST 1 (T1)
A2: TEST 1
B3: Table 1a: Test 1 using 50 ul of sample and an additional analysis to determine FG3 affectiveness | N3: Table 1b: Test 1 repeats using 50 ul of sample.
B4: FG3 experiment | C4: Sample id. | D4: v (ul) | E4: 230 | F4: 260 | G4: 270 | H4: 280 | I4: 260/280 | N4: NLIS tag | O4: v (ul) | P4: 230 | Q4: 260 | R4: 270 | S4: 280 | T4: 260/280
C5: 1 | D5: 50 | E5: 0.079 | F5: 0.044 | G5: 0.041 | H5: 0.037 | I5: =F5/H5 -> 1.1891892 | M5: Repeat | N5: 5 | O5: 50 | P5: 0.002 | Q5: 0.001 | R5: 0 | S5: 0
C6: 2 | D6: 50 | E6: 0.019 | F6: 0.021 | G6: 0.018 | H6: 0.018 | I6: =F6/H6 -> 1.1666667 | M6: Repeat | N6: 11 | O6: 50 | P6: 0.023 | Q6: 0.005 | R6: 0.005 | S6: 0.005 | T6: =Q6/S6 -> 1
C7: 3 | D7: 50 | E7: 0.025 | F7: 0.01 | G7: 0.01 | H7: 0.008 | I7: =F7/H7 -> 1.25 | M7: Repeat | N7: 21 | O7: 50 | P7: 0.01 | Q7: 0 | R7: 0 | S7: 0
C8: 4 | D8: 50 | E8: 0.015 | F8: 0.007 | G8: 0.006 | H8: 0.005 | I8: =F8/H8 -> 1.4 | M8: Repeat | N8: 22 | O8: 50 | P8: 0.011 | Q8: 0 | R8: 0 | S8: 0
B9: Fresh 400 | C9: 5 | D9: 50 | E9: 0 | F9: -0.001 | G9: -0.002 | H9: -0.002 | I9: =F9/H9 -> 0.5 | N9: Median | P9: =MEDIAN(P5:P8) -> 0.0105 | Q9: =MEDIAN(Q5:Q8) -> 0.0005 | R9: =MEDIAN(R5:R8) -> 0 | S9: =MEDIAN(S5:S8) -> 0 | T9: =MEDIAN(T5:T8) -> 1
C10: 6 | D10: 50 | E10: 0.033 | F10: 0.012 | G10: 0.012 | H10: 0.01 | I10: =F10/H10 -> 1.2 | N10: STDEV | P10: =STDEVA(P5:P8) -> 0.008660254 | Q10: =STDEVA(Q5:Q8) -> 0.0023804761 | R10: =STDEVA(R5:R8) -> 0.0025 | S10: =STDEVA(S5:S8) -> 0.0025 | T10: =STDEVA(T5:T8) -> #DIV/0!
B11: Fresh 500 | C11: 7 | D11: 50 | E11: 0.008 | F11: 0.005 | G11: 0.004 | H11: 0.004 | I11: =F11/H11 -> 1.25 | N11: AV | P11: =AVERAGE(P5:P8) -> 0.0115 | Q11: =AVERAGE(Q5:Q8) -> 0.0015 | R11: =AVERAGE(R5:R8) -> 0.00125 | S11: =AVERAGE(S5:S8) -> 0.00125 | T11: =AVERAGE(T5:T8) -> 1
C12: 8 | D12: 50 | E12: 0.033 | F12: 0.016 | G12: 0.015 | H12: 0.012 | I12: =F12/H12 -> 1.3333333
A13: Red mark | C13: 9 | D13: 50 | E13: 0.037 | F13: 0.022 | G13: 0.019 | H13: 0.015 | I13: =F13/H13 -> 1.4666667 | N13: Table 1c: Test 1 displaying detailed data relating to increasing/replacing FG3 level
B14: Fresh 1000 V | C14: 10 | D14: 50 | E14: 0.003 | F14: 0.002 | G14: 0.001 | H14: 0.001 | I14: =F14/H14 -> 2 | N14: ANALYSE THIS BY T-TEST | Q14: TEST 1
C15: 11 | D15: 50 | E15: 0.01 | F15: 0 | G15: 0.003 | H15: 0.004 | I15: =F15/H15 -> 0 | O15: Additional FG3 incorporated into samples | T15: FG3 replaced with fresh FG3 (total)
B16: Add. 1000 V | C16: 12 | D16: 50 | E16: 0.013 | F16: 0.004 | G16: 0.005 | H16: 0 | I16: 0 | O16: FG3 (ul) | P16: Sample id. | Q16: FG3 (ul) | R16: Sample id. | T16: FG3 (ul) | U16: Sample id. | V16: FG3 (ul) | W16: Sample id.
B17: Add. 1000 V | C17: 13 | D17: 50 | E17: 0.015 | F17: 0.005 | G17: 0.005 | H17: 0.005 | I17: =F17/H17 -> 1 | N17: Non-vortexed | O17: 400 | P17: 15 | Q17: 500 | R17: 22 | T17: 400 | U17: 5 | V17: 500 | W17: 7
C18: 14 | D18: 50 | E18: 0.01 | F18: 0.004 | G18: 0.004 | H18: 0.003 | I18: =F18/H18 -> 1.3333333 | N18: Vortexed* | O18: 400 | P18: 12 | Q18: 500 | R18: 13 | T18: 400 | U18: 20 | V18: 500 | W18: 10
B19: Add. 400 | C19: 15 | D19: 50 | E19: 0.014 | F19: 0.004 | G19: 0.004 | H19: 0.003 | I19: =F19/H19 -> 1.3333333 | N19: Additional FG3 | O19: 100 | Q19: 100 | T19: 100 | V19: 100
C20: 16 | D20: 50 | E20: 0.051 | F20: 0.008 | G20: 0.007 | H20: 0.004 | I20: =F20/H20 -> 2 | N20: " | O20: 500 | Q20: 400 | T20: 500 | V20: 400
C21: 17 | D21: 50 | E21: 0.046 | F21: 0.016 | G21: 0.016 | H21: 0.013 | I21: =F21/H21 -> 1.2307692 | N21: NOTE: Cross reference sample id. In the table opposite (left)
C22: 18 | D22: 50 | E22: 0.01 | F22: 0 | G22: 0 | H22: 0 | I22: 0 | N22: *Vortexing speed was at maximum rate for at least 50 secs.
C23: 19 | D23: 50 | E23: 0.01 | F23: 0.007 | G23: 0.006 | H23: 0.004 | I23: =F23/H23 -> 1.75
B24: Fresh 1000 V | C24: 20 | D24: 50 | E24: 0.004 | F24: 0.003 | G24: 0.002 | H24: 0.002 | I24: =F24/H24 -> 1.5
C25: 21 | D25: 50 | E25: 0.01 | F25: 0 | G25: 0 | H25: 0 | I25: 0
B26: Add. 500 | C26: 22 | D26: 50 | E26: 0.011 | F26: 0 | G26: 0 | H26: 0.001 | I26: =F26/H26 -> 0
C27: 23 | D27: 50 | E27: 0.022 | F27: 0.007 | G27: 0.006 | H27: 0.005 | I27: =F27/H27 -> 1.4
A28: Red mark | C28: 24 | D28: 50 | E28: 0.018 | F28: 0.018 | G28: 0.011 | H28: 0.009 | I28: =F28/H28 -> 2
C29: Median | E29: =MEDIAN(E5:E28) -> 0.0145 | F29: =MEDIAN(F5:F28) -> 0.006 | G29: =MEDIAN(G5:G28) -> 0.0055 | H29: =MEDIAN(H5:H28) -> 0.004 | I29: =MEDIAN(I5:I28) -> 1.25
C30: STDEV | E30: =STDEVA(E5:E28) -> 0.018145946 | F30: =STDEVA(F5:F28) -> 0.010120649 | G30: =STDEVA(G5:G28) -> 0.0091674242 | H30: =STDEVA(H5:H28) -> 0.0082434647 | I30: =STDEVA(I5:I28) -> 0.65919542
C31: AV | E31: =AVERAGE(E5:E28) -> 0.020666667 | F31: =AVERAGE(F5:F28) -> 0.0089166667 | G31: =AVERAGE(G5:G28) -> 0.0080416667 | H31: =AVERAGE(H5:H28) -> 0.0067083333 | I31: =AVERAGE(I5:I28) -> 1.0959705

Sheet TEST 2 (T2)
D2: TEST 2 (volume used in this UV spectrophotometer was doubled as the samples contained greater liquid content than tests 1, 3 and 4)
D3: Table 2a: Test occurred using 100 ul of sample.
D4: Sample id. | E4: v (ul) | F4: 230 | G4: 260 | H4: 270 | I4: 280 | J4: 260/280 | M4: NOTE: 'Red mark' indicates sample with DNA pellet which was particularly difficult to breakup by vortexing.
B5: Lower volume | D5: 1 | E5: 100 | F5: 0.058 | G5: 0.018 | H5: 0.019 | I5: 0.017 | J5: =G5/I5 -> 1.0588235
D7: Table 2b: Test using 150 ul of sample | M7: Table 2c: Repeat tests using 150 ul of sample
C8: Solid DNA pellet | D8: Sample id. | E8: v (ul) | F8: 230 | G8: 260 | H8: 270 | I8: 280 | J8: 260/280 | M8: NLIS tag | N8: v | O8: 230 | P8: 260 | Q8: 270 | R8: 280 | S8: 260/280
C9: * | D9: 1 | E9: 150 | F9: 0.1 | G9: 0.045 | H9: 0.046 | I9: 0.043 | J9: =G9/I9 -> 1.0465116 | L9: Repeat | M9: 1 | N9: 150 | O9: 0.1 | P9: 0.037 | Q9: 0.035 | R9: 0.031 | S9: =P9/R9 -> 1.1935484
D10: 2 | E10: 150 | F10: 0.01 | G10: 0.031 | H10: 0.031 | I10: 0.028 | J10: =G10/I10 -> 1.1071429 | L10: Repeat | M10: 3 | N10: 150 | O10: 0.077 | P10: 0.025 | Q10: 0.027 | R10: 0.026 | S10: =P10/R10 -> 0.96153846
C11: * | D11: 3 | E11: 150 | F11: 0.155 | G11: 0.048 | H11: 0.044 | I11: 0.039 | J11: =G11/I11 -> 1.2307692 | M11: Median | O11: =MEDIAN(O9:O10) -> 0.0885 | P11: =MEDIAN(P9:P10) -> 0.031 | Q11: =MEDIAN(Q9:Q10) -> 0.031 | R11: =MEDIAN(R9:R10) -> 0.0285 | S11: =MEDIAN(S9:S10) -> 1.0775434
D12: 4 | E12: 150 | F12: 0.065 | G12: 0.011 | H12: 0.012 | I12: 0.01 | J12: =G12/I12 -> 1.1 | M12: STDEV | O12: =STDEVA(O9:O10) -> 0.016263456 | P12: =STDEVA(P9:P10) -> 0.0084852814 | Q12: =STDEVA(Q9:Q10) -> 0.0056568542 | R12: =STDEVA(R9:R10) -> 0.0035355339 | S12: =STDEVA(S9:S10) -> 0.16405579
D13: 5 | E13: 150 | F13: 0.138 | G13: 0.028 | H13: 0.033 | I13: 0.032 | J13: =G13/I13 -> 0.875 | M13: AV | O13: =AVERAGE(O9:O10) -> 0.0885 | P13: =AVERAGE(P9:P10) -> 0.031 | Q13: =AVERAGE(Q9:Q10) -> 0.031 | R13: =AVERAGE(R9:R10) -> 0.0285 | S13: =AVERAGE(S9:S10) -> 1.0775434
D14: 6 | E14: 150 | F14: 0.142 | G14: 0.027 | H14: 0.033 | I14: 0.031 | J14: =G14/I14 -> 0.87096774
D15: 7 | E15: 150 | F15: 0.122 | G15: 0.025 | H15: 0.029 | I15: 0.028 | J15: =G15/I15 -> 0.89285714
D16: 8 | E16: 150 | F16: 0.083 | G16: 0.02 | H16: 0.023 | I16: 0.021 | J16: =G16/I16 -> 0.95238095 | M16: IMPORTANT: TEST 2 samples were placed in rotating incubator for 1000 mins @ 64 d C at speed 6 on 10/09/2012
D17: 9 | E17: 150 | F17: 0.084 | G17: 0.009 | H17: 0.014 | I17: 0.014 | J17: =G17/I17 -> 0.64285714
D18: 10 | E18: 150 | F18: 0.057 | G18: 0.002 | H18: 0.007 | I18: 0.008 | J18: =G18/I18 -> 0.25
D19: 11 | E19: 150 | F19: 0.071 | G19: 0.012 | H19: 0.017 | I19: 0.018 | J19: =G19/I19 -> 0.66666667
C20: * | D20: 12 | E20: 150 | F20: 0.008 | G20: -0.011 | H20: -0.007 | I20: -0.004 | J20: =G20/I20 -> 2.75
D21: 13 | E21: 150 | F21: 0.078 | G21: 0.016 | H21: 0.019 | I21: 0.018 | J21: =G21/I21 -> 0.88888889
B22: Red mark | D22: 14 | E22: 150 | F22: 0.087 | G22: 0.01 | H22: 0.014 | I22: 0.014 | J22: =G22/I22 -> 0.71428571
D23: 15 | E23: 150 | F23: 0.068 | G23: 0.004 | H23: 0.008 | I23: 0.01 | J23: =G23/I23 -> 0.4
B24: Red mark | D24: 16 | E24: 150 | F24: 0.04 | G24: -0.008 | H24: -0.003 | I24: -0.003 | J24: =G24/I24 -> 2.6666667
D25: 17 | E25: 150 | F25: 0.126 | G25: 0.035 | H25: 0.036 | I25: 0.028 | J25: =G25/I25 -> 1.25
C26: * | D26: 18 | E26: 150 | F26: 0.114 | G26: 0.028 | H26: 0.033 | I26: 0.031 | J26: =G26/I26 -> 0.90322581
D27: 19 | E27: 150 | F27: 0.06 | G27: 0.013 | H27: 0.018 | I27: 0.014 | J27: =G27/I27 -> 0.92857143
D28: 20 | E28: 150 | F28: 0.051 | G28: 0.001 | H28: 0.014 | I28: 0.019 | J28: =G28/I28 -> 0.052631579
B29: 600 ul FG3 | C29: * | D29: 21 | E29: 150 | F29: 0.063 | G29: 0.001 | H29: 0.004 | I29: 0.007 | J29: =G29/I29 -> 0.14285714
C30: * | D30: 22 | E30: 150 | F30: 0.102 | G30: 0.011 | H30: 0.018 | I30: 0.021 | J30: =G30/I30 -> 0.52380952
C31: * | D31: 23 | E31: 150 | F31: 0.059 | G31: 0.01 | H31: 0.015 | I31: 0.014 | J31: =G31/I31 -> 0.71428571
C32: * | D32: 24 | E32: 150 | F32: 0.062 | G32: 0.008 | H32: 0.01 | I32: 0.007 | J32: =G32/I32 -> 1.1428571
D33: Median | F33: =MEDIAN(F9:F32) -> 0.0745 | G33: =MEDIAN(G9:G32) -> 0.0115 | H33: =MEDIAN(H9:H32) -> 0.0175 | I33: =MEDIAN(I9:I32) -> 0.018 | J33: =MEDIAN(J9:J32) -> 0.89087302
D34: STDEV | F34: =STDEVA(F9:F32) -> 0.038313897 | G34: =STDEVA(G9:G32) -> 0.015193439 | H34: =STDEVA(H9:H32) -> 0.013771426 | I34: =STDEVA(I9:I32) -> 0.012099826 | J34: =STDEVA(J9:J32) -> 0.6320193
D35: AV | F35: =AVERAGE(F9:F32) -> 0.081041667 | G35: =AVERAGE(G9:G32) -> 0.015666667 | H35: =AVERAGE(H9:H32) -> 0.0195 | I35: =AVERAGE(I9:I32) -> 0.018666667 | J35: =AVERAGE(J9:J32) -> 0.94638471

Sheet TEST 3 (T3)
D2: TEST 3
D4: TABLE 3a: Increased volume of test 3 (50ul/2ml H2O) in quartz cell
D5: Sample id. | E5: v (ul) | F5: 230 | G5: 260 | H5: 270 | I5: 280 | J5: 260/280 | M5: TABLE 3b: Lower volume of test 3 (i.e. 20ul/2ml H2O) added to quartz cell
B6: Not enough volume | D6: 1 | E6: 50 | M6: Sample id. | N6: v (ul) | O6: 230 | P6: 260 | Q6: 270 | R6: 280 | S6: 260/280 | V6: t-Test: Two-Sample Assuming Equal Variances
D7: 2 | E7: 50 | F7: 0.04 | G7: 0.029 | H7: 0.026 | I7: 0.021 | J7: =G7/I7 -> 1.3809524 | M7: 1 | N7: 20 | O7: 0.014 | P7: 0.009 | Q7: 0.008 | R7: 0.007 | S7: =P7/R7 -> 1.2857143 | V7: (Comparison between 20 and 50 ul i.e. table 3b and table 3c)
D8: 3 | E8: 50 | F8: 0.029 | G8: 0.015 | H8: 0.014 | I8: 0.013 | J8: =G8/I8 -> 1.1538462 | M8: 2 | N8: 20 | O8: 0.014 | P8: 0.01 | Q8: 0.009 | R8: 0.007 | S8: =P8/R8 -> 1.4285714 | W8: Variable 1 | X8: Variable 2
D9: 4 | E9: 50 | F9: 0.039 | G9: 0.017 | H9: 0.016 | I9: 0.011 | J9: =G9/I9 -> 1.5454545 | M9: 3 | N9: 20 | O9: 0.007 | P9: 0.002 | Q9: 0.002 | R9: 0.002 | S9: =P9/R9 -> 1 | V9: Mean | W9: 0.023 | X9: 0.006625
D10: 5 | E10: 50 | F10: 0.026 | G10: 0.018 | H10: 0.017 | I10: 0.015 | J10: =G10/I10 -> 1.2 | M10: 4 | N10: 20 | O10: 0.008 | P10: 0.005 | Q10: 0.004 | R10: 0.003 | S10: =P10/R10 -> 1.6666667 | V10: Variance | W10: 0.00056766667 | X10: 9.9821429e-06
D11: 6 | E11: 50 | F11: 0.019 | G11: 0.01 | H11: 0.009 | I11: 0.007 | J11: =G11/I11 -> 1.4285714 | M11: 14 | N11: 20 | O11: 0.011 | P11: 0.007 | Q11: 0.006 | R11: 0.005 | S11: =P11/R11 -> 1.4 | V11: Observations | W11: 7 | X11: 8
D12: 7 | E12: 50 | F12: 0.023 | G12: 0.012 | H12: 0.011 | I12: 0.008 | J12: =G12/I12 -> 1.5 | M12: 16 | N12: 20 | O12: 0.018 | P12: 0.011 | Q12: 0.01 | R12: 0.008 | S12: =P12/R12 -> 1.375 | V12: Pooled Variance | W12: 0.000267375
D13: 8 | E13: 50 | F13: 0.03 | G13: 0.018 | H13: 0.016 | I13: 0.013 | J13: =G13/I13 -> 1.3846154 | M13: 23 | N13: 20 | O13: 0.012 | P13: 0.005 | Q13: 0.005 | R13: 0.004 | S13: =P13/R13 -> 1.25 | V13: Hypothesized Mean Difference | W13: 0
D14: 9 | E14: 50 | F14: 0.022 | G14: 0.012 | H14: 0.011 | I14: 0.008 | J14: =G14/I14 -> 1.5 | M14: 24 | N14: 20 | O14: 0.01 | P14: 0.004 | Q14: 0.004 | R14: 0.003 | S14: =P14/R14 -> 1.3333333 | V14: df | W14: 13
D15: 10 | E15: 50 | F15: 0.025 | G15: 0.014 | H15: 0.013 | I15: 0.01 | J15: =G15/I15 -> 1.4 | M15: Median | O15: =MEDIAN(O7:O14) -> 0.0115 | P15: =MEDIAN(P7:P14) -> 0.006 | Q15: =MEDIAN(Q7:Q14) -> 0.0055 | R15: =MEDIAN(R7:R14) -> 0.0045 | S15: =MEDIAN(S7:S14) -> 1.3541667 | V15: t Stat | W15: 1.934948
D16: 11 | E16: 50 | F16: 0.02 | G16: 0.013 | H16: 0.012 | I16: 0.009 | J16: =G16/I16 -> 1.4444444 | M16: STDEV | O16: =STDEVA(O7:O14) -> 0.0035757117 | P16: =STDEVA(P7:P14) -> 0.0031594529 | Q16: =STDEVA(Q7:Q14) -> 0.0027774603 | R16: =STDEVA(R7:R14) -> 0.0022320714 | S16: =STDEVA(S7:S14) -> 0.18747415 | V16: P(T<=t) one-tail | W16: 0.037528108
D17: 12 | E17: 50 | F17: 0.025 | G17: 0.018 | H17: 0.016 | I17: 0.012 | J17: =G17/I17 -> 1.5 | M17: AV | O17: =AVERAGE(O7:O14) -> 0.01175 | P17: =AVERAGE(P7:P14) -> 0.006625 | Q17: =AVERAGE(Q7:Q14) -> 0.006 | R17: =AVERAGE(R7:R14) -> 0.004875 | S17: =AVERAGE(S7:S14) -> 1.3424107 | V17: t Critical one-tail | W17: 1.7709334
D18: 13 | E18: 50 | F18: 0.016 | G18: 0.007 | H18: 0.007 | I18: 0.005 | J18: =G18/I18 -> 1.4 | V18: P(T<=t) two-tail | W18: 0.075056215
D19: 14 | E19: 50 | F19: 0.028 | G19: 0.015 | H19: 0.015 | I19: 0.011 | J19: =G19/I19 -> 1.3636364 | M19: Table 3c: These are samples (below) which are from table 3a for t-test comparison with table 3b. | V19: t Critical two-tail | W19: 2.1603687
D20: 15 | E20: 50 | F20: 0.02 | G20: 0.014 | H20: 0.012 | I20: 0.009 | J20: =G20/I20 -> 1.5555556 | M20: Sample id. | N20: v (ul) | O20: 230 | P20: 260 | Q20: 270 | R20: 280 | S20: 260/280
B21: No repeat capable | D21: 16 | E21: 50 | F21: 0.108 | G21: 0.073 | H21: 0.052 | I21: 0.049 | J21: =G21/I21 -> 1.4897959 | M21: 1 | N21: 50
D22: 17 | E22: 50 | F22: 0.029 | G22: 0.025 | H22: 0.026 | I22: 0.017 | J22: =G22/I22 -> 1.4705882 | M22: 2 | N22: 50 | O22: 0.04 | P22: 0.029 | Q22: 0.026 | R22: 0.021 | S22: =P22/R22 -> 1.3809524
D23: 18 | E23: 50 | F23: 0.019 | G23: 0.012 | H23: 0.012 | I23: 0.008 | J23: =G23/I23 -> 1.5 | M23: 3 | N23: 50 | O23: 0.029 | P23: 0.015 | Q23: 0.014 | R23: 0.013 | S23: =P23/R23 -> 1.1538462
D24: 19 | E24: 50 | F24: 0.021 | G24: 0.013 | H24: 0.011 | I24: 0.009 | J24: =G24/I24 -> 1.4444444 | M24: 4 | N24: 50 | O24: 0.039 | P24: 0.017 | Q24: 0.016 | R24: 0.011 | S24: =P24/R24 -> 1.5454545
D25: 20 | E25: 50 | F25: 0.031 | G25: 0.019 | H25: 0.017 | I25: 0.013 | J25: =G25/I25 -> 1.4615385 | M25: 14 | N25: 50 | O25: 0.028 | P25: 0.015 | Q25: 0.015 | R25: 0.011 | S25: =P25/R25 -> 1.3636364
D26: 21 | E26: 50 | F26: 0.026 | G26: 0.014 | H26: 0.013 | I26: 0.01 | J26: =G26/I26 -> 1.4 | M26: 16 | N26: 50 | O26: 0.108 | P26: 0.073 | Q26: 0.052 | R26: 0.049 | S26: =P26/R26 -> 1.4897959
D27: 22 | E27: 50 | F27: 0.019 | G27: 0.02 | H27: 0.014 | I27: 0.01 | J27: =G27/I27 -> 2 | M27: 23 | N27: 50 | O27: 0.034 | P27: 0.014 | Q27: 0.013 | R27: 0.012 | S27: =P27/R27 -> 1.1666667
D28: 23 | E28: 50 | F28: 0.034 | G28: 0.014 | H28: 0.013 | I28: 0.012 | J28: =G28/I28 -> 1.1666667 | M28: 24 | N28: 50 | O28: -0.002 | P28: -0.002 | Q28: -0.002 | R28: -0.002 | S28: =P28/R28 -> 1
B29: No repeat capable | D29: 24 | E29: 50 | F29: -0.002 | G29: -0.002 | H29: -0.002 | I29: -0.002 | J29: =G29/I29 -> 1 | M29: Median | O29: =MEDIAN(O21:O28) -> 0.034 | P29: =MEDIAN(P21:P28) -> 0.015 | Q29: =MEDIAN(Q21:Q28) -> 0.015 | R29: =MEDIAN(R21:R28) -> 0.012 | S29: =MEDIAN(S21:S28) -> 1.3636364
D30: Median | F30: =MEDIAN(F6:F29) -> 0.025 | G30: =MEDIAN(G6:G29) -> 0.014 | H30: =MEDIAN(H6:H29) -> 0.013 | I30: =MEDIAN(I6:I29) -> 0.01 | J30: =MEDIAN(J6:J29) -> 1.4444444 | M30: STDEV | O30: =STDEVA(O21:O28) -> 0.033385911 | P30: =STDEVA(P21:P28) -> 0.023825756 | Q30: =STDEVA(Q21:Q28) -> 0.016657617 | R30: =STDEVA(R21:R28) -> 0.015873008 | S30: =STDEVA(S21:S28) -> 0.19833138
D31: STDEV | F31: =STDEVA(F6:F29) -> 0.019384399 | G31: =STDEVA(G6:G29) -> 0.013513425 | H31: =STDEVA(H6:H29) -> 0.0097664425 | I31: =STDEVA(I6:I29) -> 0.009159759 | J31: =STDEVA(J6:J29) -> 0.18750377 | M31: AV | O31: =AVERAGE(O21:O28) -> 0.039428571 | P31: =AVERAGE(P21:P28) -> 0.023 | Q31: =AVERAGE(Q21:Q28) -> 0.019142857 | R31: =AVERAGE(R21:R28) -> 0.016428571 | S31: =AVERAGE(S21:S28) -> 1.3000503
D32: AV | F32: =AVERAGE(F6:F29) -> 0.028130435 | G32: =AVERAGE(G6:G29) -> 0.017391304 | H32: =AVERAGE(H6:H29) -> 0.01526087 | I32: =AVERAGE(I6:I29) -> 0.012086957 | J32: =AVERAGE(J6:J29) -> 1.4213091
D33: * Highlight red to visually indicate odd readings.

Sheet TEST 4 (FINAL)
X1: t-Test: Two-Sample Assuming Equal Variances
C2: NOTE: | D2: TEST 4 UV spectrometer will be conducted on 24th Sept., as DNA was still present following 48 hrs heat treatment @ 55 d C, | X2: Compare 260 (Column F v's P)
D3: which requires further time to push beyond an expected threshold for dissolving the DNA pellets. The samples were | Y3: Variable 1 | Z3: Variable 2
D4: placed into the refrigerator over the weekend. It is important to note that FG3 buffer was not increased, as the protocol advices further incubation if low buffer. | X4: Mean | Y4: 0.014272727 | Z4: 0.012083333
X5: Variance | Y5: 4.5618182e-05 | Z5: 9.3901515e-05
X6: Observations | Y6: 11 | Z6: 12
E7: Denotes samples used in tests 1 - 4 | X7: Pooled Variance | Y7: 7.0909452e-05
X8: Hypothesized Mean Difference | Y8: 0
X9: df | Y9: 21
D10: Table 4a: Normal protease mix | P10: Table 4b: Double protease mix | X10: t Stat | Y10: 0.62286639
D11: v (ul) | E11: 230 | F11: 260 | G11: 270 | H11: 280 | I11: 260/280 | M11: Sample id. | N11: v (ul) | O11: 230 | P11: 260 | Q11: 270 | R11: 280 | S11: 260/280 | U11: P(T<=t) one-tail | V11: 0.27003909
C12: Sample id. | U12: t Critical one-tail | V12: 1.7207429
C13: 1 | D13: 50 | E13: 0.045 | F13: 0.015 | G13: 0.015 | H13: 0.012 | I13: =F13/H13 -> 1.25 | M13: 1 | N13: 50 | O13: 0.052 | P13: 0.011 | Q13: 0.013 | R13: 0.011 | S13: =P13/R13 -> 1 | U13: P(T<=t) two-tail | V13: 0.54007818
C14: 2 | D14: 50 | E14: 0.063 | F14: 0.022 | G14: 0.022 | H14: 0.018 | I14: =F14/H14 -> 1.2222222 | M14: 2 | N14: 50 | O14: 0.061 | P14: 0.019 | Q14: 0.02 | R14: 0.018 | S14: =P14/R14 -> 1.0555556 | U14: t Critical two-tail | V14: 2.0796138
C15: 3 | D15: 50 | E15: 0.047 | F15: 0.023 | G15: 0.022 | H15: 0.016 | I15: =F15/H15 -> 1.4375 | M15: 3 | N15: 50 | O15: 0.07 | P15: 0.027 | Q15: 0.028 | R15: 0.024 | S15: =P15/R15 -> 1.125
C16: 4 | D16: 50 | E16: 0.035 | F16: 0.013 | G16: 0.012 | H16: 0.009 | I16: =F16/H16 -> 1.4444444 | M16: 4 | N16: 50 | O16: 0.031 | P16: 0.007 | Q16: 0.009 | R16: 0.008 | S16: =P16/R16 -> 0.875 | U16: t-Test: Two-Sample Assuming Equal Variances
C17: 5 | D17: 50 | M17: 5 | N17: 50 | O17: 0.035 | P17: 0.006 | Q17: 0.008 | R17: 0.008 | S17: =P17/R17 -> 0.75 | U17: Compare 280 (Column H v's R)
C18: 6 | D18: 50 | E18: 0.039 | F18: 0.012 | G18: 0.012 | H18: 0.009 | I18: =F18/H18 -> 1.3333333 | M18: 6 | N18: 50 | O18: 0.037 | P18: 0.009 | Q18: 0.011 | R18: 0.01 | S18: =P18/R18 -> 0.9 | V18: Variable 1 | W18: Variable 2
C19: 7 | D19: 50 | E19: 0.035 | F19: 0.008 | G19: 0.009 | H19: 0.008 | I19: =F19/H19 -> 1 | M19: 7 | N19: 50 | O19: 0.034 | P19: 0.014 | Q19: 0.014 | R19: 0.012 | S19: =P19/R19 -> 1.1666667 | U19: Mean | V19: 0.011090909 | W19: 0.012333333
C20: 8 | D20: 50 | E20: 0.039 | F20: 0.017 | G20: 0.016 | H20: 0.012 | I20: =F20/H20 -> 1.4166667 | M20: 8 | N20: 50 | O20: 0.037 | P20: 0.003 | Q20: 0.005 | R20: 0.006 | S20: =P20/R20 -> 0.5 | U20: Variance | V20: 2.0290909e-05 | W20: 5.0606061e-05
C21: 9 | D21: 50 | E21: 0.034 | F21: 0.003 | G21: 0.005 | H21: 0.004 | I21: =F21/H21 -> 0.75 | M21: 9 | N21: 50 | O21: 0.032 | P21: -0.001 | Q21: 0.003 | R21: 0.004 | S21: =P21/R21 -> -0.25 | U21: Observations | V21: 11 | W21: 12
C22: 10 | D22: 50 | E22: 0.031 | F22: 0.008 | G22: 0.008 | H22: 0.006 | I22: =F22/H22 -> 1.3333333 | M22: 10 | N22: 50 | O22: 0.03 | P22: 0.004 | Q22: 0.006 | R22: 0.006 | S22: =P22/R22 -> 0.66666667 | U22: Pooled Variance | V22: 3.6170274e-05
C23: 11 | D23: 50 | E23: 0.046 | F23: 0.012 | G23: 0.013 | H23: 0.011 | I23: =F23/H23 -> 1.0909091 | M23: 11 | N23: 50 | O23: 0.051 | P23: 0.015 | Q23: 0.016 | R23: 0.015 | S23: =P23/R23 -> 1 | U23: Hypothesized Mean Difference | V23: 0
C24: 12 | D24: 50 | E24: 0.042 | F24: 0.024 | G24: 0.023 | H24: 0.017 | I24: =F24/H24 -> 1.4117647 | M24: 12 | N24: 50 | O24: 0.064 | P24: 0.031 | Q24: 0.03 | R24: 0.026 | S24: =P24/R24 -> 1.1923077 | U24: df | V24: 21
C25: 13 | D25: 50 | E25: 0.028 | F25: 0.007 | G25: 0.007 | H25: 0.005 | I25: =F25/H25 -> 1.4 | M25: Median | O25: =MEDIAN(O13:O24) -> 0.037 | P25: =MEDIAN(P13:P24) -> 0.01 | Q25: =MEDIAN(Q13:Q24) -> 0.012 | R25: =MEDIAN(R13:R24) -> 0.0105 | S25: =MEDIAN(S13:S24) -> 0.95 | U25: t Stat | V25: -0.49489956
C26: 14 | D26: 50 | E26: 0.049 | F26: 0.013 | G26: 0.014 | H26: 0.011 | I26: =F26/H26 -> 1.1818182 | M26: STDEV | O26: =STDEVA(O13:O24) -> 0.014343196 | P26: =STDEVA(P13:P24) -> 0.0096902794 | Q26: =STDEVA(Q13:Q24) -> 0.0086703081 | R26: =STDEVA(R13:R24) -> 0.0071137937 | S26: =STDEVA(S13:S24) -> 0.39949706 | U26: P(T<=t) one-tail | V26: 0.31290464
C27: 15 | D27: 50 | E27: 0.03 | F27: 0.009 | G27: 0.009 | H27: 0.006 | I27: =F27/H27 -> 1.5 | M27: AV | O27: =AVERAGE(O13:O24) -> 0.0445 | P27: =AVERAGE(P13:P24) -> 0.012083333 | Q27: =AVERAGE(Q13:Q24) -> 0.013583333 | R27: =AVERAGE(R13:R24) -> 0.012333333 | S27: =AVERAGE(S13:S24) -> 0.83176638 | U27: t Critical one-tail | V27: 1.7207429
C28: 16 | D28: 50 | E28: 0.042 | F28: 0.016 | G28: 0.015 | H28: 0.012 | I28: =F28/H28 -> 1.3333333 | U28: P(T<=t) two-tail | V28: 0.62580929
C29: 17 | D29: 50 | E29: 0.036 | F29: 0.014 | G29: 0.014 | H29: 0.011 | I29: =F29/H29 -> 1.2727273 | U29: t Critical two-tail | V29: 2.0796138
C30: 18 | D30: 50 | E30: 0.058 | F30: 0.027 | G30: 0.027 | H30: 0.023 | I30: =F30/H30 -> 1.173913
C31: 19 | D31: 50 | E31: 0.038 | F31: 0.011 | G31: 0.013 | H31: 0.009 | I31: =F31/H31 -> 1.2222222 | U31: t-Test: Two-Sample Assuming Equal Variances
C32: 20 | D32: 50 | E32: 0.05 | F32: 0.013 | G32: 0.015 | H32: 0.015 | I32: =F32/H32 -> 0.86666667 | U32: (260/280 comparison i.e. J v's S. Only samples 5 - 62)
C33: 21 | D33: 50 | E33: 0.082 | F33: 0.004 | G33: 0.008 | H33: 0.011 | I33: =F33/H33 -> 0.36363636 | V33: Variable 1 | W33: Variable 2
C34: 22 | D34: 50 | E34: 0.034 | F34: 0.01 | G34: 0.011 | H34: 0.012 | I34: =F34/H34 -> 0.83333333 | U34: Mean | V34: 1.2009144 | W34: 0.83176638
C35: 23 | D35: 50 | E35: 0.037 | F35: 0.017 | G35: 0.016 | H35: 0.014 | I35: =F35/H35 -> 1.2142857 | U35: Variance | V35: 0.048091427 | W35: 0.1595979
C36: 24 | D36: 50 | E36: 0.013 | F36: 0.003 | G36: 0.004 | H36: 0.003 | I36: =F36/H36 -> 1 | U36: Observations | V36: 9 | W36: 12
C37: 25 | D37: 50 | E37: 0.042 | F37: 0.018 | G37: 0.018 | H37: 0.015 | I37: =F37/H37 -> 1.2 | U37: Pooled Variance | V37: 0.11264781
C38: 26 | D38: 50 | E38: 0.019 | F38: 0.007 | G38: 0.008 | H38: 0.007 | I38: =F38/H38 -> 1 | U38: Hypothesized Mean Difference | V38: 0
C39: 27 | D39: 50 | E39: 0.036 | F39: 0.018 | G39: 0.018 | H39: 0.015 | I39: =F39/H39 -> 1.2 | U39: df | V39: 19
C40: 28 | D40: 50 | E40: 0.025 | F40: 0.01 | G40: 0.011 | H40: 0.008 | I40: =F40/H40 -> 1.25 | U40: t Stat | V40: 2.4942579
...

Sheet Master mix data
A1: Master mix
B4: # of samples
B6: N + 1ul
B7: 1 | C7: 10 | F7: [DNA] = VDNA/Vcuvette x 50 x A260
A8: Polymerase | B8: 25 | C8: 250
A9: Primer F | B9: 1 | C9: 25 | E9: Example: | F9: [DNA] = 20/2000 x 50 x 0.1
A10: Primer R | B10: 1 | C10: 25 | F10: =1/100 x 50 x 0.1
A11: Water | B11: 22 | C11: 220 | F11: =0.5 x 0.1
A12: Template | B12: 1 | F12: =0.05 ug/ul | J12: CONVERSION WEBSITE
A13: TOTAL | B13: =SUM(B8:B12) -> 50 | C13: =SUM(C8:C12) -> 520 | F13: =50 ng/ul | J13: http://www.endmemo.com/sconvert/ug_ulng_ul.php
A14: *Vortex master mix

Sheet Master mix calculations
D2: Base calculation | F2: =20/2000*50
B3: Table 5a: UV absorbance readings for 260 nanometres. | J3: Table 5b: Calculations based on master mix data.
B4: =OVERVIEW!A7 -> Sample | C4: =OVERVIEW!B7 -> TEST 1 | D4: =OVERVIEW!D7 -> TEST 2 | E4: =OVERVIEW!F7 -> TEST 3 | F4: =OVERVIEW!H7 -> TEST 4 | J4: Sample | K4: Test 1 | L4: Test 2 | M4: Test 3 | N4: Test 4
B5: =OVERVIEW!A8 -> id. | C5: 260 (nm) | D5: 260 (nm) | E5: 260 (nm) | F5: 260 (nm) | J5: id.
B6: =OVERVIEW!A9 -> 1 | C6: 0.044 | D6: 0.045 | F6: 0.015 | J6: 1 | K6: =0.5*C6 -> 0.022 | L6: =0.5*D6 -> 0.0225 | M6: =0.5*E6 -> 0 | N6: =0.5*F6 -> 0.0075
B7: =OVERVIEW!A10 -> 2 | C7: 0.021 | D7: 0.031 | E7: 0.029 | F7: 0.022 | J7: 2 | K7: =0.5*C7 -> 0.0105 | L7: =0.5*D7 -> 0.0155 | M7: =0.5*E7 -> 0.0145 | N7: =0.5*F7 -> 0.011
B8: =OVERVIEW!A11 -> 3 | C8: 0.01 | D8: 0.048 | E8: 0.015 | F8: 0.023 | J8: 3 | K8: =0.5*C8 -> 0.005 | L8: =0.5*D8 -> 0.024 | M8: =0.5*E8 -> 0.0075 | N8: =0.5*F8 -> 0.0115
B9: =OVERVIEW!A12 -> 4 | C9: 0.007 | D9: 0.011 | E9: 0.017 | F9: 0.013 | J9: 4 | K9: =0.5*C9 -> 0.0035 | L9: =0.5*D9 -> 0.0055 | M9: =0.5*E9 -> 0.0085 | N9: =0.5*F9 -> 0.0065
B10: =OVERVIEW!A13 -> 5 | C10: -0.001 | D10: 0.028 | E10: 0.018 | J10: 5 | K10: =0.5*C10 -> -0.0005 | L10: =0.5*D10 -> 0.014 | M10: =0.5*E10 -> 0.009 | N10: =0.5*F10 -> 0
B11: =OVERVIEW!A14 -> 6 | C11: 0.012 | D11: 0.027 | E11: 0.01 | F11: 0.012 | J11: 6 | K11: =0.5*C11 -> 0.006 | L11: =0.5*D11 -> 0.0135 | M11: =0.5*E11 -> 0.005 | N11: =0.5*F11 -> 0.006
B12: =OVERVIEW!A15 -> 7 | C12: 0.005 | D12: 0.025 | E12: 0.012 | F12: 0.008 | J12: 7 | K12: =0.5*C12 -> 0.0025 | L12: =0.5*D12 -> 0.0125 | M12: =0.5*E12 -> 0.006 | N12: =0.5*F12 -> 0.004
B13: =OVERVIEW!A16 -> 8 | C13: 0.016 | D13: 0.02 | E13: 0.018 | F13: 0.017 | J13: 8 | K13: =0.5*C13 -> 0.008 | L13: =0.5*D13 -> 0.01 | M13: =0.5*E13 -> 0.009 | N13: =0.5*F13 -> 0.0085
B14: =OVERVIEW!A17 -> 9 | C14: 0.022 | D14: 0.009 | E14: 0.012 | F14: 0.003 | J14: 9 | K14: =0.5*C14 -> 0.011 | L14: =0.5*D14 -> 0.0045 | M14: =0.5*E14 -> 0.006 | N14: =0.5*F14 -> 0.0015
B15: =OVERVIEW!A18 -> 10 | C15: 0.002 | D15: 0.002 | E15: 0.014 | F15: 0.008 | J15: 10 | K15: =0.5*C15 -> 0.001 | L15: =0.5*D15 -> 0.001 | M15: =0.5*E15 -> 0.007 | N15: =0.5*F15 -> 0.004
B16: =OVERVIEW!A19 -> 11 | C16: 0 | D16: 0.012 | E16: 0.013 | F16: 0.012 | J16: 11 | K16: =0.5*C16 -> 0 | L16: =0.5*D16 -> 0.006 | M16: =0.5*E16 -> 0.0065 | N16: =0.5*F16 -> 0.006
B17: =OVERVIEW!A20 -> 12 | C17: 0.004 | D17: -0.011 | E17: 0.018 | F17: 0.024 | J17: 12 | K17: =0.5*C17 -> 0.002 | L17: =0.5*D17 -> -0.0055 | M17: =0.5*E17 -> 0.009 | N17: =0.5*F17 -> 0.012
B18: =OVERVIEW!A21 -> 13 | C18: 0.005 | D18: 0.016 | E18: 0.007 | F18: 0.007 | J18: 13 | K18: =0.5*C18 -> 0.0025 | L18: =0.5*D18 -> 0.008 | M18: =0.5*E18 -> 0.0035 | N18: =0.5*F18 -> 0.0035
B19: =OVERVIEW!A22 -> 14 | C19: 0.004 | D19: 0.01 | E19: 0.015 | F19: 0.013 | J19: 14 | K19: =0.5*C19 -> 0.002 | L19: =0.5*D19 -> 0.005 | M19: =0.5*E19 -> 0.0075 | N19: =0.5*F19 -> 0.0065
B20: =OVERVIEW!A23 -> 15 | C20: 0.004 | D20: 0.004 | E20: 0.014 | F20: 0.009 | J20: 15 | K20: =0.5*C20 -> 0.002 | L20: =0.5*D20 -> 0.002 | M20: =0.5*E20 -> 0.007 | N20: =0.5*F20 -> 0.0045
B21: =OVERVIEW!A24 -> 16 | C21: 0.008 | D21: -0.008 | E21: 0.073 | F21: 0.016 | J21: 16 | K21: =0.5*C21 -> 0.004 | L21: =0.5*D21 -> -0.004 | M21: =0.5*E21 -> 0.0365 | N21: =0.5*F21 -> 0.008
B22: =OVERVIEW!A25 -> 17 | C22: 0.016 | D22: 0.035 | E22: 0.025 | F22: 0.014 | J22: 17 | K22: =0.5*C22 -> 0.008 | L22: =0.5*D22 -> 0.0175 | M22: =0.5*E22 -> 0.0125 | N22: =0.5*F22 -> 0.007
... B29: =OVERVIEW!A32 -> 24 | C29: 0.018 | D29: 0.008 | E29: -0.002 | F29: 0.003 | J29: 24 | K29: =0.5*C29 -> 0.009 | L29: =0.5*D29 -> 0.004 | M29: =0.5*E29 -> -0.001 | N29: =0.5*F29 -> 0.0015
B51: Sample | C51: TEST 1 | D51: TEST 2 | E51: TEST 3 | F51: TEST 4 | J51: Sample | K51: Test 1 | L51: Test 2 | M51: Test 3 | N51: Test 4
B52: id. | C52: 260 (nm) | D52: 260 (nm) | E52: 260 (nm) | F52: 260 (nm) | J52: id.
B53: =OVERVIEW!A33 -> 25 | C53: N/A | F53: 0.018 | J53: 25 | N53: =0.5*F53 -> 0.009
B54: =OVERVIEW!A34 -> 26 | F54: 0.007 | J54: 26 | N54: =0.5*F54 -> 0.0035
B55: =OVERVIEW!A35 -> 27 | F55: 0.018 | J55: 27 | N55: =0.5*F55 -> 0.009
B56: =OVERVIEW!A36 -> 28 | F56: 0.01 | J56: 28 | N56: =0.5*F56 -> 0.005
B57: =OVERVIEW!A37 -> 29 | F57: 0.003 | J57: 29 | N57: =0.5*F57 -> 0.0015
B58: =OVERVIEW!A38 -> 30 | F58: 0.004 | J58: 30 | N58: =0.5*F58 -> 0.002
B59: =OVERVIEW!A39 -> 31 | F59: 0.014 | J59: 31 | N59: =0.5*F59 -> 0.007
B60: =OVERVIEW!A40 -> 32 | F60: 0.012 | J60: 32 | N60: =0.5*F60 -> 0.006
B61: =OVERVIEW!A41 -> 33 | F61: 0.009 | J61: 33 | N61: =0.5*F61 -> 0.0045
B62: =OVERVIEW!A42 -> 34 | F62: 0.011 | J62: 34 | N62: =0.5*F62 -> 0.0055
B63: =OVERVIEW!A43 -> 35 | F63: 0.012 | J63: 35 | N63: =0.5*F63 -> 0.006
B64: =OVERVIEW!A44 -> 36 | F64: 0.009 | J64: 36 | N64: =0.5*F64 -> 0.0045
B65: =OVERVIEW!A45 -> 37 | F65: 0.005 | J65: 37 | N65: =0.5*F65 -> 0.0025
... B91: =OVERVIEW!A71 -> 63 | F91: 0.004 | J91: 63 | N91: =0.5*F91 -> 0.002
C93: N/A - No data recorded for samples 25 - 63 in Test 1-3
