Workbook
Name mainbody: SOA!$M$8
Name Y: Redirection!$B$19

Sheet SOA
B1: District Statement of Accounts
B2: School District:
B3: Reviewer:
B4: Date:
B6: IDEA Part B School Age
M8: IDEA Part B School Age
B9: Allocation:
F12: CCIP Budget | J12: Findet to date | M12: Code | N12: Salaries | O12: Retirement Fringe Benefits | P12: Purchased Services | Q12: Supplies | R12: Capital Outlay | S12: Other | T12: Total
I13: LEA Support | J13: Difference | K13: % | N13: 100 | O13: 200 | P13: 400 | Q13: 500 | R13: 600 | S13: 800
F14: Budgeted | G14: % | I14: Documentation | J14: Amount | K14: Difference | M14: Instruction
B15: Expenditures | M15: Support Services
B16: 100 | C16: Salaries | G16: =F16/F27 -> #DIV/0! | J16: =F16-I16 -> 0 | K16: =I16/F16-1 -> #DIV/0! | M16: Governance/Admin
M17: Prof Development
B18: 200 | C18: Fringe Benefits | G18: =F18/F27 -> #DIV/0! | J18: =F18-I18 -> 0 | K18: =I18/F18-1 -> #DIV/0! | M18: Family/Community
M19: Safety
B20: 400 | C20: Purchased Services | G20: =F20/F27 -> #DIV/0! | J20: =F20-I20 -> 0 | K20: =I20/F20-1 -> #DIV/0! | M20: Facilities
M21: Transportation
B22: 500 | C22: Supplies | G22: =F22/F27 -> #DIV/0! | J22: =F22-I22 -> 0 | K22: =I22/F22-1 -> #DIV/0! | M22: Nonpublic
M23: Indirect Cost
B24: 600 | C24: Capital Outlay | G24: =F24/F27 -> #DIV/0! | J24: =F24-I24 -> 0 | K24: =I24/F24-1 -> #DIV/0! | M24: TOTAL | N24: =SUM(N14:N23) -> 0 | O24: =SUM(O14:O23) -> 0 | P24: =SUM(P14:P23) -> 0 | Q24: =SUM(Q14:Q23) -> 0 | R24: =SUM(R14:R23) -> 0 | S24: =SUM(S14:S23) -> 0
R25: Adjusted Allocation
B26: 800 | C26: Other | G26: =F26/F27 -> #DIV/0! | J26: =F26-I26 -> 0 | K26: =I26/F26-1 -> #DIV/0! | R26: Remaining
C27: Total | F27: =SUM(F16+F18+F20+F22+F24+F26) -> 0 | G27: =SUM(G16:G26) -> #DIV/0! | I27: =SUM(I16+I18+I20+I22+I24+I26) -> 0 | J27: =F27-I27 -> 0 | K27: =I27/F27-1 -> #DIV/0!
B32: Pre-School Age
M36: Pre-School Age
B38: Allocation:
M40: Code | N40: Salaries | O40: Retirement Fringe Benefits | P40: Purchased Services | Q40: Supplies | R40: Capital Outlay | S40: Other | T40: Total
F41: CCIP Budget | J41: Findet to date | N41: 100 | O41: 200 | P41: 400 | Q41: 500 | R41: 600 | S41: 800
I42: LEA Support | J42: Difference | K42: % | M42: Instruction
F43: Budgeted | G43: % | I43: Documentation | J43: Amount | K43: Difference | M43: Support Services
B44: Expenditures | M44: Governance/Admin
B45: 100 | C45: Salaries | G45: =F45/F56 -> #DIV/0! | J45: =F45-I45 -> 0 | K45: =I45/F45-1 -> #DIV/0! | M45: Prof Development
M46: Family/Community
B47: 200 | C47: Fringe Benefits | G47: =F47/F56 -> #DIV/0! | J47: =F47-I47 -> 0 | K47: =I47/F47-1 -> #DIV/0! | M47: Safety
M48: Facilities
B49: 400 | C49: Purchased Services | G49: =F49/F56 -> #DIV/0! | J49: =F49-I49 -> 0 | K49: =I49/F49-1 -> #DIV/0! | M49: Transportation
M50: Nonpublic
B51: 500 | C51: Supplies | G51: =F51/F56 -> #DIV/0! | J51: =F51-I51 -> 0 | K51: =I51/F51-1 -> #DIV/0! | M51: Indirect Cost
M52: TOTAL | N52: =SUM(N42:N51) -> 0 | O52: =SUM(O42:O51) -> 0 | P52: =SUM(P42:P51) -> 0 | Q52: =SUM(Q42:Q51) -> 0 | R52: =SUM(R42:R51) -> 0 | S52: =SUM(S42:S51) -> 0
B53: 600 | C53: Capital Outlay | G53: =F53/F56 -> #DIV/0! | J53: =F53-I53 -> 0 | K53: =I53/F53-1 -> #DIV/0! | R53: Adjusted Allocation
...

Sheet Payroll Exp
B1: Payroll Expenditure Test
B2: School District: | C2: =SOA!C2 -> 0
B3: Reviewer: | C3: =SOA!C3 -> 0
B4: Date: | C4: =SOA!C4 -> 0
B6: Purpose: To detemine if the subgrantee,
C7: - properly documented the payroll expenditure via Time and Effort Log or Semi-Annual Certification
C8: - properly accounted for the payroll expense. This test will look to ensure the LEA properly coded the
C9: expense to the correct function and object.
B10: Instructions: The reviewer shall review all employees funded with Part B funds to ensure the federal funds were expended for an appropriate purpose based upon the fedral guidelines.
B11: Review the district's answer to question #5 on the NS-3 Consultation Guide. If the services are provided, ensure the teacher providing services to non-public students has the proper certifications.
B13: Utilize the Districts ACCRPT and FER for this tab
B14: Review certificate for all teachers providing services to students with disabilities
B15: * if urban district, select 10% (not less than 10) of employee records to review.
G16: Attributes | N16: Comments
B17: Name | C17: Title | D17: Fund | E17: Function | F17: Object | G17: A | H17: B | I17: C | J17: D | K17: E | L17: F | M17: G
A19: School Age
G33: Attributes | N33: Comments
B34: Name | C34: Title | D34: Fund | E34: Function | F34: Object | G34: A | H34: B | J34: C | K34: D | L34: E | M34: F
A37: Pre-School Age
B46: Legend
B47: Y | C47: Attribute Satisfied
B48: N | C48: Attribute Not Satisfied
B49: N/A | C49: Attribut Not Applicable
B50: Attributes
B51: A | C51: Review of position description for all positions funded through IDEA funds
B52: B | C52: Review of certification and/or licensure of IDEA funded staff - this includes those providing services to non-public schools. Is the License appropriate given position held?
B53: C | C53: The district maintains documentation for all certified teachers and para-professionals paid with Part B funds to assure that they meet the qualifications and requirements to be considered a Highly Qualified Teacher.
B54: D | C54: Time and effort documentation was maintained (Split purpose employees require Log or Timesheet) Personal Activity Report (PAR)
B55: E | C55: Semi-annual Certification documentation was maintained for Single Funded or single purpose employees
B56: F | C56: The Payroll expense was charged to the proper fund.
B57: G | C57: The Payroll expense was charged to the proper function.

Sheet Non-Payroll Exp
B1: Non-Payroll Expenditure Test
B2: School District: | C2: =SOA!C2 -> 0
B3: Reviewer: | C3: =SOA!C3 -> 0
B4: Date: | C4: =SOA!C4 -> 0
B6: Purpose: To determine if the subgrantee,
C7: - federal funds are used for proper and intended purpose
C8: - properly accounted for the non-payroll expense. This test will look to ensure the LEA properly coded the expense to the proper function and object.
C9: - test 10% of expenditures not less than 10 transactions, completed across the program year
C10: - properly documented expenditures, for example; invoices, contracts, cancelled checks.
B13: Instruction: | C13: The reviewer should select a sample, test 10 % of expenditures not less than 10 transactions through the program year.
C14: Review Expenditures for evidence of payments related to services to Non-Public Schools stated in item #2 of the NS-3 Consultation Guide.
C15: Utilize the FINDET report to determine with vouchers to review. Review vouchers pulled by the district's treasurers office.
C16: Vendor | E16: Voucher/Check# | F16: Function | G16: Object | H16: Amount | I16: Date | J16: Attributes
B17: # | D17: Item | J17: A | K17: B | L17: C | M17: D | N17: E | O17: F | P17: Comments
A18: School Age Current fiscal year 516 | B18: 1
B19: 2
B20: 3
B21: 4
B22: 5
B23: 6
B24: 7
B25: 8
B26: 9
B27: 10
B28: 11
B29: 12
B30: 13
... B37: 20
C38: Vendor | E38: Voucher/Check# | F38: Function | G38: Object | H38: Amount | I38: Date | J38: Attributes
B39: # | D39: Item | J39: A | K39: B | L39: C | M39: D | N39: E | O39: F | P39: Comments
A40: Pre-School Age 587 | B40: 1
B41: 2
B42: 3
B43: 4
B44: 5
B45: 6
B46: 7
B47: 8
B48: 9
B49: 10
...

Sheet equipment_Cap.outlay
B1: Equipment - Capital Outlay Test
B2: School District: | C2: =SOA!C2 -> 0
B3: Reviewer: | C3: =SOA!C3 -> 0
B4: Date: | C4: =SOA!C4 -> 0
B6: Purpose: Equipment may be purchased with IDEA Part B funds.
B7: Has the district established and implemented procurement procedures?
B8: Review Expenditures (FINDET) for evidence of payments related to services to Non-Public Schools stated in item #2 of the NS-3 Consultation Guide.
B9: - From the entity's master listing of equipment purchased with project funds, select a representative number of equipment items and trace them to locations noted in the district. This applies to all funding years, not just the current year's purchases.
C11: Inventory list | K11: Comments/dispostion data inclusing date of disposal and the sale price for the item
B12: Item Description | C12: serial number/ID | D12: Name of Holder | E12: Acquistion cost | F12: Location | G12: Acquistion Date | H12: proper intendend use | I12: condition of the item | J12: percent of Part B funds included in the cost of the item
A13: School Age
C21: Inventory list | K21: Comments/dispostion data inclusing date of disposal and the sale price for the item
B22: Item Description | C22: serial number/ID | D22: Name of Holder | E22: Acquistion cost | F22: Location | G22: Acquistion Date | H22: proper intendend use | I22: condition of the item | J22: percent of Part B funds included in the cost of the item
A23: Pre-School Age
B30: Legend
B31: Y | C31: Attribute Satisfied
B32: N | C32: Attribute Not Satisfied
B33: N/A | C33: Attribut Not Applicable
B34: Attributes
B35: Expenditures
G36: Indicate Y/N/NA
B38: A | C38: Does the district have procurement policy?
B39: B | C39: Is the district's procurement policy followed regarding purchases with IDEA funds?
B40: C | C40: Did the district provide an equipment inventory list for review?
B41: D | C41: Is the district properly identifying equipment purchased per its policy?
B42: E | C42: Is there an equipment inventory removal procedure in place and being followed?
B43: F | C43: Item traced to location noted on the master listing
A44: - Using the entity's list of equipment disposed during the review period, regardless of year purchased, select a sample of disposals and determine that:
B45: G | C45: The entity disposed of the equipment in accordance with local policies
B46: H | C46: For items with fair market value of greater than $5,000 determine if the entity requested
C47: disposition instruction from ODE before disposing of the asset
B48: I | C48: For all items purchased with grant funds, determine that the proceeds from the sale were
C49: deposited in the original grant funding source and used to support the grant activities from
C50: the original funding source

Sheet NP Child Find
B1: Non-Public Child Find
B2: School District: | C2: =SOA!C2 -> 0
B3: Reviewer: | C3: =SOA!C3 -> 0
B4: Date: | C4: =SOA!C4 -> 0
B6: Purpose:
B7: - LEAs are required to do child find with non publics in their boundaries (not paid with proportionate share amount)
B8: - Each LEA must maintain in its records ;
B9: 1.) | C9: the number of children evaluated
B10: 2.) | C10: the number of children determined to be children with disabilities
B11: 3.) | C11: the number of children served
B12: 4) | C12: the district is able to document its timely consultation with non-public schools
B13: ATTRIBUTES
B14: A | C14: B | D14: C | E14: D | F14: COMMENTS
A15: Participating NP
B17: Legend
B18: Y | C18: Attribute Satisfied
B19: N | C19: Attribute Not Satisfied
B20: N/A | C20: Attribute Not Applicable
B22: Attributes
B23: A | C23: The LEA maintains in its records the number of children evaluated.
B24: B | C24: The LEA maintains in its records the number of children determined to be SWD
B25: C | C25: The LEA maintains in its records the number of children served
B26: D | C26: The LEA held timely consultation with NP as noted in the NS3 documentation

Sheet Public Notification
B1: Public Participation 300.165
B2: =SOA!B2 -> School District: | C2: =SOA!C2 -> 0
B3: =SOA!B3 -> Reviewer: | C3: =SOA!C3 -> 0
B4: =SOA!B4 -> Date: | C4: =SOA!C4 -> 0
B5: Purpose: To ensure that,
C6: - there are public hearings
C7: - adequate notice of the hearings (not less than one week prior to date or public hearing)
C8: - an opportunity for comment available to the general public, including individuals with disabilities and parents of children with disabilites.
B10: Instruction: Have the district present a copy of the public notice and other relevant documentation.
B13: ATTRIBUTES
B14: A | C14: B | D14: C | E14: COMMENTS
B17: Legend
B18: Y | C18: Attribute Satisfied
B19: N | C19: Attribute Not Satisfied
B20: N/A | C20: Attribut Not Applicable
B22: Attributes
B23: A | C23: Invitation to public meeting
B24: B | C24: Adequate notice of the hearings (not less than one week)
B25: C | C25: Agenda, sign in sheet or something equivalent to prove the meeting was held

Sheet Redirection
C1: CCIP Redirection page 300.226
B2: =SOA!B2 -> School District: | C2: =SOA!C2 -> 0
B3: =SOA!B3 -> Reviewer: | C3: =SOA!C3 -> 0
B4: =SOA!B4 -> Date: | C4: =SOA!C4 -> 0
B6: Purpose: | C6: Districts are able to allocate funds to various projects and purposes which must be reported on the Redirection Page.
B8: Instructions: | C8: Review CCIP redirection page
C9: Review documents which support expenditures related to budget for PD or service for CEIS
B11: Attributes for replacement of local funds.
B12: Review prior year expenditures for which the current year IDEA funds were used to legally replace those local expenditures.
B13: Ensure the amount replaced is noted in the CCIP redirection page.
B17: ATTRIBUTES
B18: A | C18: B | D18: C | E18: D | F18: E | G18: F | H18: G | I18: H | J18: I | K18: COMMENTS
B19: N/A | C19: N/A | D19: N/A | E19: N/A | F19: N/A | G19: N/A | H19: N/A | I19: N/A | J19: N/A | K19: They reported MFS but no other data.
B23: Legend
B24: Y | C24: Attribute Satisfied
B25: N | C25: Attribute Not Satisfied
B26: N/A | C26: Attribut Not Applicable
B28: Attributes
B29: A | C29: Review district budget for CEIS. Did district opt to redirect up to 15 % of funds for CEIS? Indicate in the comments section how funds for CEIS were budgeted.
B30: B | C30: Professional development expenditures which align with CEIS?
B31: C | C31: Providing educational and behavioral evaluations, services, and supports, including scientifically based literacy instruction?
B32: D | C32: Is the district verifying the count of students who received early interevening services?
B33: E | C33: Is the district verifying the count of students who subsequetly received SP ED / related services?
B34: F | C34: Was district eligible to replace local funds?
B35: G | C35: Did they replace local funds?
B36: H | C36: Are they tracking funds?
B37: I | C37: Did they report in the redirection page?
B41: PLEASE NOTE: Funds used to provide early intervening services under section 613(f)(1)-(5) count towards the maximum amount of local expenditures that a district may reduce.
