Workbook
Name _ftn1: 'CE Curriculum'!$O$43
Name _ftn1: 'CE Curriculum BUS minor'!$O$52
Name _ftn1: 'CE Curriculum CO-OP'!$O$52
Name _ftn1: 'CE Curriculum double major'!$O$52
Name _ftn1: 'CE Curriculum ESS Minor'!$O$43
Name _ftnref1: 'CE Curriculum'!#REF!
Name _ftnref1: 'CE Curriculum BUS minor'!#REF!
Name _ftnref1: 'CE Curriculum CO-OP'!#REF!
Name _ftnref1: 'CE Curriculum double major'!#REF!
Name _ftnref1: 'CE Curriculum ESS Minor'!#REF!
Name flow_chart_print: Flowchart!$A$1:$P$32
Name Table_5_1_Curriculum: 'DOUBLE MAJ CHECKLIST'!$V$36
Name Table_5_1_Curriculum: 'ABET Summary'!$V$36
Name Workloads: #REF!

Sheet CE Curriculum
E1: MERRIMACK COLLEGE
E2: CIVIL ENGINEERING CURRICULUM | CO2: ECO 1201 Introduction to Economics
CO3: ECO 1202 Topics in Introductory Economics
A4: Name | B4: ENTER NAME HERE | C4: ID # | D4: ID HERE | F4: Class year: | G4: CLASS YEAR HERE | I4: ADVISOR: | J4: ADVISOR HERE | CO4: ECO 3305 Ecological Economics
B6: FALL | I6: SPRING | BC6: Workloads
F7: FRESHMAN YEAR | BC7: Fall | BE7: Spring | CA7: Arts and Literature | CD7: Ethics | CI7: Historical Studies | CN7: Social Science
A8: GEN 1001 | B8: Intro. to Eng. | C8: 4 | H8: MTH 1505 | I8: Applied Statistics | J8: 4 | BC8: =A8 -> GEN 1001 | BD8: =C8 -> 4 | BE8: =H16 -> GEN2012 | BF8: =J16 -> 4 | CB8: Arts and Literature (AL) | CE8: Ethics | CJ8: Historical Studies | CO8: Social Science | CS8: Science Elective
A9: MTH 1217 | B9: Calculus I | C9: 4 | H9: MTH 1218 | I9: Calculus II | J9: 4 | O9: Pre-requisites or co-requisites not met | BC9: =A16 -> GEN2010 | BD9: =C16 -> 4 | BE9: =H18 -> GEN 3040 | BF9: =J18 -> 4 | CA9: ='[1]LS Core'!C5 -> Communication Arts and Sciences | CB9: ='[1]LS Core'!D5 -> WRT 2790 Public and Private Writing from the Civil War Era | CD9: ='[1]LS Core'!E5 -> Management | CE9: ='[1]LS Core'!F5 -> MGT 3325 Ethics and Social Responsibility | CI9: ='[1]LS Core'!I5 -> Economics | CJ9: ='[1]LS Core'!J5 -> ECO 3314 U.S. Economic History | CN9: ='[1]LS Core'!K5 -> Communication Arts and Sciences | CO9: ='[1]LS Core'!L5 -> COM 2201 Introduction to Interpersonal Communication | CS9: AST 1101 Introduction to Astronomy
A10: PHL 1000 | B10: Intro to Philosophy | C10: 4 | H10: PHY 2211 | I10: Physics I | J10: 4 | O10: Pre-requisite for another course | BC10: =A19 -> CEN 2001 | BD10: =C19 -> 4 | BE10: =H25 -> CEN3030 | BF10: =J25 -> 4 | CA10: ='[1]LS Core'!C6 -> Communication Arts and Sciences | CB10: ='[1]LS Core'!D6 -> WRT 3060 Writing the Personal Memoir | CD10: ='[1]LS Core'!E6 -> Philosophy | CE10: ='[1]LS Core'!F6 -> PHL 2020W Perspectives on the Good Life | CI10: ='[1]LS Core'!I6 -> Economics | CJ10: ='[1]LS Core'!J6 -> ECO 3312 The History of Economic Thought | CN10: ='[1]LS Core'!K6 -> Communication Arts and Sciences | CO10: ='[1]LS Core'!L6 -> COM 2301 Introduction to Organizational Communication | CS10: BIO 1027 Principles of Biology I
A11: FYW 1050 | B11: College Writing | C11: 4 | H11: Arts & Lit (AL) | I11: Elective (course here) | J11: 4 | O11: Co-requisite for another course | BC11: =A25 -> CEN3010 | BD11: =C25 -> 4 | BE11: =H26 -> CEN3050 | BF11: =J26 -> 4 | CA11: ='[1]LS Core'!C7 -> English | CB11: ='[1]LS Core'!D7 -> ENG 1060 Horror Fiction | CD11: ='[1]LS Core'!E7 -> Philosophy | CE11: ='[1]LS Core'!F7 -> PHL 2030 Contemporary Moral Problems | CI11: ='[1]LS Core'!I7 -> History | CJ11: ='[1]LS Core'!J7 -> HIS 1106 History of American Civilization, 1600-1877 | CN11: ='[1]LS Core'!K7 -> Communication Arts and Sciences | CO11: ='[1]LS Core'!L7 -> COM 2401 Introduction to Mass Communication | CS11: BIO 3009 Environment, Ecology and Society
BC12: =A26 -> CEN3020 | BD12: =C26 -> 4 | BE12: =H27 -> CEN3090 | BF12: =J27 -> 1 | CA12: ='[1]LS Core'!C8 -> English | CB12: ='[1]LS Core'!D8 -> ENG 1500 Major British and World Authors | CD12: ='[1]LS Core'!E8 -> Philosophy | CE12: ='[1]LS Core'!F8 -> PHL 2040 Introduction to Political Philosophy | CI12: ='[1]LS Core'!I8 -> History | CJ12: ='[1]LS Core'!J8 -> HIS 1107 History of American Civilization, 1877-2000 | CN12: ='[1]LS Core'!K8 -> Communication Arts and Sciences | CO12: ='[1]LS Core'!L8 -> COM 3231 Intercultural Communication (D) | CS12: BIO 3090 – 3099 Global Field Studies Program Courses
C13: =SUM(C8:C12) -> 16 | J13: =SUM(J8:J12) -> 16 | BC13: =B34 -> Elective (course here) | BD13: =C34 -> 4 | BE13: =H34 -> CEN 4901 | BF13: =J34 -> 4 | CA13: ='[1]LS Core'!C9 -> English | CB13: ='[1]LS Core'!D9 -> ENG 1550 Major American Authors | CD13: ='[1]LS Core'!E9 -> Philosophy | CE13: ='[1]LS Core'!F9 -> PHL 2050 Ethics in the Professions | CI13: ='[1]LS Core'!I9 -> History | CJ13: ='[1]LS Core'!J9 -> HIS 1119 History of Western Civilization I | CN13: ='[1]LS Core'!K9 -> Economics | CO13: ='[1]LS Core'!L9 -> ECO 1201 Introduction to Economics | CS13: CEN 4060 Geology
CA14: ='[1]LS Core'!C10 -> English | CB14: ='[1]LS Core'!D10 -> ENG 2050W Introduction to Literary Studies | CD14: ='[1]LS Core'!E10 -> Philosophy | CE14: ='[1]LS Core'!F10 -> PHL 2060 Biomedical Ethics | CI14: ='[1]LS Core'!I10 -> History | CJ14: ='[1]LS Core'!J10 -> HIS 1120 History of Western Civilization II | CN14: ='[1]LS Core'!K10 -> Economics | CO14: ='[1]LS Core'!L10 -> ECO 1202 Topics in Introductory Economics | CS14: CSC 1610 Computer Science I
F15: SOPHOMORE YEAR | O15: INSTRUCTIONS FOR USE | BC15: =B35 -> Elective (course here) | BD15: =C35 -> 4 | BE15: =I35 -> Elective (course here) | BF15: =J35 -> 4 | CA15: ='[1]LS Core'!C11 -> English | CB15: ='[1]LS Core'!D11 -> ENG 2200 Introduction to Poetry | CD15: ='[1]LS Core'!E11 -> Philosophy | CE15: ='[1]LS Core'!F11 -> PHL 2070 Environmental Ethics | CI15: ='[1]LS Core'!I11 -> History | CJ15: ='[1]LS Core'!J11 -> HIS 2329 American Social History | CN15: ='[1]LS Core'!K11 -> Economics | CO15: ='[1]LS Core'!L11 -> ECO 1203 Principles of Economics – Micro | CS15: HSC 1104 Introduction to Human Disease
A16: GEN2010 | B16: Mechanics I | C16: 4 | H16: GEN2012 | I16: Mechanics II | J16: 4 | O16: 1. Enter a 1 into the boxes outlined in green beside courses that you have completed successfully | BE16: =I36 -> Elective (course here) | BF16: =J36 -> 4 | CA16: ='[1]LS Core'!C12 -> English | CB16: ='[1]LS Core'!D12 -> ENG 2300 Detective Fiction | CD16: ='[1]LS Core'!E12 -> Philosophy | CE16: ='[1]LS Core'!F12 -> PHL 2080 Approaches to Ethics | CI16: ='[1]LS Core'!I12 -> History | CJ16: ='[1]LS Core'!J12 -> HIS 2340 History of Latin America (D) | CN16: ='[1]LS Core'!K12 -> Economics | CO16: ='[1]LS Core'!L12 -> ECO 1204 Principles of Economics – Macro | CS16: HSC 1106 Human Biology
A17: PHY 2212 | B17: Physics II | C17: 4 | H17: MTH 2220 | I17: Diff. Equations | J17: 4 | BE17: =H37 -> CEN 4900 | BF17: =J37 -> 1 | CA17: ='[1]LS Core'!C13 -> English | CB17: ='[1]LS Core'!D13 -> ENG 2740 Politics in Literature | CD17: ='[1]LS Core'!E13 -> Philosophy | CE17: ='[1]LS Core'!F13 -> PHL 2090 Values in a Technological Culture | CI17: ='[1]LS Core'!I13 -> History | CJ17: ='[1]LS Core'!J13 -> HIS 3350 Ancient History | CN17: ='[1]LS Core'!K13 -> Economics | CO17: ='[1]LS Core'!L13 -> ECO 1225 Economics of Gender (D) | CS17: HSC 1122 Anatomy and Physiology I
A18: MTH 2219 | B18: Calculus III | C18: 4 | H18: GEN 3040 | I18: Fluid Mech. | J18: 4 | O18: 2. Now you're ready to begin planning the upcoming semester. Enter a 1 into the green boxes beside courses in which you would like to enroll next semester. | CA18: ='[1]LS Core'!C14 -> English | CB18: ='[1]LS Core'!D14 -> ENG 2750 Adapting the Graphic Novel to Film | CD18: ='[1]LS Core'!E14 -> Philosophy | CE18: ='[1]LS Core'!F14 -> PHL 2100 Women, Ethics and Society (D) | CI18: ='[1]LS Core'!I14 -> History | CJ18: ='[1]LS Core'!J14 -> HIS 3360 Medieval Civilization | CN18: ='[1]LS Core'!K14 -> Economics | CO18: ='[1]LS Core'!L14 -> ECO 2201 Intermediate Micro-Economics | CS18: HSC 2300 Nutrition, Diet and Health
A19: CEN 2001 | B19: CE Site Design | C19: 4 | H19: CHM 1180 | I19: Engineering Chemistry | J19: 4 | CA19: ='[1]LS Core'!C15 -> English | CB19: ='[1]LS Core'!D15 -> ENG 2770 Literature and Film | CD19: ='[1]LS Core'!E15 -> Philosophy | CE19: ='[1]LS Core'!F15 -> PHL 2310 Socrates and the Examined Life | CI19: ='[1]LS Core'!I15 -> History | CJ19: ='[1]LS Core'!J15 -> HIS 3370 Renaissance and Reformation | CN19: ='[1]LS Core'!K15 -> Economics | CO19: ='[1]LS Core'!L15 -> ECO 2202 Intermediate Macro-Economics | CS19: HSC 3302 Community Public Health
O20: 3. The cell will turn red if you are missing any co or pre-requisites, which are shown in teal and pink, respectively. | CA20: ='[1]LS Core'!C16 -> English | CB20: ='[1]LS Core'!D16 -> ENG 3020 A History of the English Language | CD20: ='[1]LS Core'!E16 -> Philosophy | CE20: ='[1]LS Core'!F16 -> PHL 2500 Theories of Justice | CI20: ='[1]LS Core'!I16 -> History | CJ20: ='[1]LS Core'!J16 -> HIS 3376 Era of the French Revolution | CN20: ='[1]LS Core'!K16 -> Economics | CO20: ='[1]LS Core'!L16 -> ECO 3303 Economic Development
CA21: ='[1]LS Core'!C17 -> English | CB21: ='[1]LS Core'!D17 -> ENG 3100 Beowulf and Old English Literature | CD21: ='[1]LS Core'!E17 -> Philosophy | CE21: ='[1]LS Core'!F17 -> PHL 3020 Philosophy of Law | CI21: ='[1]LS Core'!I17 -> History | CJ21: ='[1]LS Core'!J17 -> HIS 3378 History of Modern Britain | CN21: ='[1]LS Core'!K17 -> Economics | CO21: ='[1]LS Core'!L17 -> ECO 3304 Economics of Education
C22: =SUM(C16:C21) -> 16 | J22: =SUM(J16:J20) -> 16 | O22: 4. You may keep track of your progress through the curriculum by clicking on the Flowchart sheet. All completed courses will be outlined in yellow. | CA22: ='[1]LS Core'!C18 -> English | CB22: ='[1]LS Core'!D18 -> ENG 3140 Chaucer and Middle English Literature | CD22: ='[1]LS Core'!E18 -> Philosophy | CE22: ='[1]LS Core'!F18 -> PHL 3030 Global Justice | CI22: ='[1]LS Core'!I18 -> History | CJ22: ='[1]LS Core'!J18 -> HIS 3380 History of Modern Technology | CN22: ='[1]LS Core'!K18 -> Economics | CO22: ='[1]LS Core'!L18 -> ECO 3305 Ecological Economics
CA23: ='[1]LS Core'!C19 -> English | CB23: ='[1]LS Core'!D19 -> ENG 3200 Renaissance Literature | CD23: ='[1]LS Core'!E19 -> Philosophy | CE23: ='[1]LS Core'!F19 -> PHL 3180 Existentialism | CI23: ='[1]LS Core'!I19 -> History | CJ23: ='[1]LS Core'!J19 -> HIS 3390 Modern European Social History | CN23: ='[1]LS Core'!K19 -> Economics | CO23: ='[1]LS Core'!L19 -> ECO 3306 International Economics
F24: JUNIOR YEAR | CA24: ='[1]LS Core'!C20 -> English | CB24: ='[1]LS Core'!D20 -> ENG 3220 Renaissance Drama | CD24: ='[1]LS Core'!E20 -> Religious and Theological Studies | CE24: ='[1]LS Core'!F20 -> RTS 2800 Christian Social Ethics (D) | CI24: ='[1]LS Core'!I20 -> History | CJ24: ='[1]LS Core'!J20 -> HIS 3391 Women in Modern European History (D) | CN24: ='[1]LS Core'!K20 -> Economics | CO24: ='[1]LS Core'!L20 -> ECO 3307 Labor Economics
A25: CEN3010 | B25: Structures | C25: 4 | H25: CEN3030 | I25: Transportation | J25: 4 | BC25: Marc | CA25: ='[1]LS Core'!C21 -> English | CB25: ='[1]LS Core'!D21 -> ENG 3250 Shakespearean Drama | CD25: ='[1]LS Core'!E21 -> Religious and Theological Studies | CE25: ='[1]LS Core'!F21 -> RTS 2900 Holocaust: Theology, Reality and Aftermath (D) | CI25: ='[1]LS Core'!I21 -> History | CJ25: ='[1]LS Core'!J21 -> HIS 3320 The American City | CN25: ='[1]LS Core'!K21 -> Economics | CO25: ='[1]LS Core'!L21 -> ECO 3308 Managerial Economics
A26: CEN3020 | B26: Geotech Engr | C26: 4 | H26: CEN3050 | I26: Enviro. Engr. | J26: 4 | BC26: =BC9 -> GEN2010 | BD26: =BD9 -> 4 | BE26: =BE8 -> GEN2012 | BF26: =BF8+2+3 -> 9 | CA26: ='[1]LS Core'!C22 -> English | CB26: ='[1]LS Core'!D22 -> ENG 3280 Angels and Demons: Milton and the Culture of Revolution | CD26: ='[1]LS Core'!E22 -> Religious and Theological Studies | CE26: ='[1]LS Core'!F22 -> RTS 2950 Ethics in the Abrahamic Traditions | CI26: ='[1]LS Core'!I22 -> History | CJ26: ='[1]LS Core'!J22 -> HIS 3326 History of American Architecture | CN26: ='[1]LS Core'!K22 -> Economics | CO26: ='[1]LS Core'!L22 -> ECO 3309 Marxian Economics
A27: PHY 2213 | B27: Thermodynamics | C27: 2 | H27: CEN3090 | I27: Professionalism & Ethics | J27: 1 | BC27: =BC11 -> CEN3010 | BD27: =BD11 -> 4 | CA27: ='[1]LS Core'!C23 -> English | CB27: ='[1]LS Core'!D23 -> ENG 3300 Restoration and Eighteenth-Century Literature | CD27: ='[1]LS Core'!E23 -> Religious and Theological Studies | CE27: ='[1]LS Core'!F23 -> RTS 3700 African-American Theology (D) | CI27: ='[1]LS Core'!I23 -> History | CJ27: ='[1]LS Core'!J23 -> HIS 3401 Topics in Nineteenth-Century Europe | CN27: ='[1]LS Core'!K23 -> Economics | CO27: ='[1]LS Core'!L23 -> ECO 3310 Money and Finance
A28: RTS 1100 | B28: Christianity in Context | C28: 4 | H28: Ethics (E) | I28: Elective (course here) | J28: 4 | BC28: =BC13 -> Elective (course here) | BD28: =BD13 -> 4 | CA28: ='[1]LS Core'!C24 -> English | CB28: ='[1]LS Core'!D24 -> ENG 3320 Eighteenth-Century Novel | CD28: ='[1]LS Core'!E24 -> Religious and Theological Studies | CE28: ='[1]LS Core'!F24 -> RTS 3710 Feminist Theology (D) | CI28: ='[1]LS Core'!I24 -> History | CJ28: ='[1]LS Core'!J24 -> HIS 3410 Twentieth-Century Europe | CN28: ='[1]LS Core'!K24 -> Economics | CO28: ='[1]LS Core'!L24 -> ECO 3311 Public Finance
A29: Hist. Studies (H) | B29: Elective (course here) | C29: 4 | H29: Science* | I29: Elective (course here) | J29: 4 | CA29: ='[1]LS Core'!C25 -> English | CB29: ='[1]LS Core'!D25 -> ENG 3350 Sex, Race, and Empire: 1660-1814 | CD29: ='[1]LS Core'!E25 -> Religious and Theological Studies | CE29: ='[1]LS Core'!F25 -> RTS 3800 The Catholic Thing: Merton and Day | CI29: ='[1]LS Core'!I25 -> History | CJ29: ='[1]LS Core'!J25 -> HIS 3425 Contemporary United States History | CN29: ='[1]LS Core'!K25 -> Economics | CO29: ='[1]LS Core'!L25 -> ECO 3312 The History of Economic Thought
CA30: ='[1]LS Core'!C26 -> English | CB30: ='[1]LS Core'!D26 -> ENG 3400 British Romanticism | CD30: ='[1]LS Core'!E26 -> Religious and Theological Studies | CE30: ='[1]LS Core'!F26 -> RTS 3850 War and Peace: Religious Perspectives | CI30: ='[1]LS Core'!I26 -> History | CJ30: ='[1]LS Core'!J26 -> HIS 3434 Age of the American Revolution, 1763-1800 | CN30: ='[1]LS Core'!K26 -> Economics | CO30: ='[1]LS Core'!L26 -> ECO 3313 Topics in Quantitative Economics
C31: =C25+C26+C27+C28+C29 -> 18 | J31: =SUM(J25:J29) -> 17 | CA31: ='[1]LS Core'!C27 -> English | CB31: ='[1]LS Core'!D27 -> ENG 3420 American Romanticism | CI31: ='[1]LS Core'!I27 -> History | CJ31: ='[1]LS Core'!J27 -> HIS 3435 American Colonial History | CN31: ='[1]LS Core'!K27 -> Economics | CO31: ='[1]LS Core'!L27 -> ECO 3314 U.S. Economic History
CA32: ='[1]LS Core'!C28 -> English | CB32: ='[1]LS Core'!D28 -> ENG 3440 Victorian Literature | CI32: ='[1]LS Core'!I28 -> History | CJ32: ='[1]LS Core'!J28 -> HIS 3437 Civil War and Reconstruction | CN32: ='[1]LS Core'!K28 -> Economics | CO32: ='[1]LS Core'!L28 -> ECO 3315 Urban and Regional Economics
F33: SENIOR YEAR | BC33: Aaron | CA33: ='[1]LS Core'!C29 -> English | CB33: ='[1]LS Core'!D29 -> ENG 3470 Realism and Naturalism in America | CI33: ='[1]LS Core'!I29 -> History | CJ33: ='[1]LS Core'!J29 -> HIS 3439 Slavery and Race in the Early Modern Atlantic World, 1400-1800 (D) | CN33: ='[1]LS Core'!K29 -> History | CO33: ='[1]LS Core'!L29 -> HIS 3376 Era of the French Revolution
A34: Structures | B34: Elective (course here) | C34: 4 | H34: CEN 4901 | I34: Des. Project | J34: 4 | BC34: =BC12 -> CEN3020 | BD34: =BD12+2+3 -> 9 | BE34: =BE9 -> GEN 3040 | BF34: =BF9+2+3 -> 9 | CA34: ='[1]LS Core'!C30 -> English | CB34: ='[1]LS Core'!D30 -> ENG 3500 Modern British Literature | CI34: ='[1]LS Core'!I30 -> History | CJ34: ='[1]LS Core'!J30 -> HIS 3470 History of Imperial Russia | CN34: ='[1]LS Core'!K30 -> History | CO34: ='[1]LS Core'!L30 -> HIS 3380 History of Modern Technology
A35: Geotechnical | B35: Elective (course here) | C35: 4 | H35: Transportation | I35: Elective (course here) | J35: 4 | BC35: =BC15 -> Elective (course here) | BD35: =BD15 -> 4 | CA35: ='[1]LS Core'!C31 -> English | CB35: ='[1]LS Core'!D31 -> ENG 3520 Modern Irish Literature | CI35: ='[1]LS Core'!I31 -> History | CJ35: ='[1]LS Core'!J31 -> HIS 3471 History of Twentieth-Century Russia | CN35: ='[1]LS Core'!K31 -> History | CO35: ='[1]LS Core'!L31 -> HIS 3390 Modern European Social History
A36: Technical | B36: Elective (course here) | C36: 4 | E36: Work with your advisor here. | H36: Environmental | I36: Elective (course here) | J36: 4 | CA36: ='[1]LS Core'!C32 -> English | CB36: ='[1]LS Core'!D32 -> ENG 3550 Modern American Literature | CI36: ='[1]LS Core'!I32 -> History | CJ36: ='[1]LS Core'!J32 -> HIS 3525 Environmental History of North America | CN36: ='[1]LS Core'!K32 -> History | CO36: ='[1]LS Core'!L32 -> HIS 3391 Women in Modern European History
A37: Soc. Science (SS) | B37: Elective (course here) | C37: 4 | H37: CEN 4900 | I37: Senior Seminar | J37: 1 | BC37: Dave | CA37: ='[1]LS Core'!C33 -> English | CB37: ='[1]LS Core'!D33 -> ENG 3620 Contemporary American Literature | CI37: ='[1]LS Core'!I33 -> Political Science | CJ37: ='[1]LS Core'!J33 -> POL 2581 Political Thought: Plato to Machiavelli | CN37: ='[1]LS Core'!K33 -> Political Science | CO37: ='[1]LS Core'!L33 -> POL 1000 Current Issues in Politics and Government
H38: Soc. Science (SS) | I38: Elective (course here) | J38: 4 | BC38: =BC10 -> CEN 2001 | BD38: =BD10+2+3 -> 9 | BE38: =BE11 -> CEN3050 | BF38: =BF11+2+3 -> 9 | CA38: ='[1]LS Core'!C34 -> English | CB38: ='[1]LS Core'!D34 -> ENG 3650 Contemporary American Drama | CI38: ='[1]LS Core'!I34 -> Political Science | CJ38: ='[1]LS Core'!J34 -> POL 2582 Political Thought: Machiavelli to Marx | CN38: ='[1]LS Core'!K34 -> Political Science | CO38: ='[1]LS Core'!L34 -> POL 1100 Politics of the United States
BE39: =BE12 -> CEN3090 | BF39: =BF12 -> 1 | CA39: ='[1]LS Core'!C35 -> English | CB39: ='[1]LS Core'!D35 -> ENG 3680 World Drama | CI39: ='[1]LS Core'!I35 -> Religious and Theological Studies | CJ39: ='[1]LS Core'!J35 -> RTS 2450 History of Christian Thought | CN39: ='[1]LS Core'!K35 -> Political Science | CO39: ='[1]LS Core'!L35 -> POL 1500 Comparative Politics
A40: Overall GPA | B40: =IFERROR('ABET Summary'!D17," ") | F40: TOOK FE EXAM | BE40: =BE16 -> Elective (course here) | BF40: =BF16 -> 4 | CA40: ='[1]LS Core'!C36 -> English | CB40: ='[1]LS Core'!D36 -> ENG 3685 The Graphic Novel | CI40: ='[1]LS Core'!I36 -> Religious and Theological Studies | CJ40: ='[1]LS Core'!J36 -> RTS 3400 American Catholicism | CN40: ='[1]LS Core'!K36 -> Political Science | CO40: ='[1]LS Core'!L36 -> POL 2000W Political Science Methods (Q)
A41: Major GPA | B41: =IFERROR('ABET Summary'!D16," ") | F41: DIVERSITY CRS. | I41: Course used? | CA41: ='[1]LS Core'!C37 -> English | CB41: ='[1]LS Core'!D37 -> ENG 3700 Self and Society: The Victorian Novel | CI41: ='[1]LS Core'!I37 -> Visual and Performing Arts | CJ41: ='[1]LS Core'!J37 -> FAA 1610 Art History I | CN41: ='[1]LS Core'!K37 -> Political Science | CO41: ='[1]LS Core'!L37 -> POL 2111 State and Local Politics
...

Sheet CE Curriculum CO-OP
E1: MERRIMACK COLLEGE
E2: DEPARTMENT OF CIVIL ENGINEERING CURRICULUM
A4: Name | B4: ENTER NAME HERE | C4: ID # | D4: ID HERE | F4: Class year: | G4: CLASS YEAR HERE | I4: ADVISOR: | J4: ADVISOR HERE
B6: FALL | I6: SPRING | BC6: Workloads
F7: FRESHMAN YEAR | BC7: Fall | BE7: Spring
A8: GEN 1001 | B8: Intro. to Eng. | C8: 4 | H8: MTH 1505 | I8: Applied Statistics | J8: 4 | BC8: =A8 -> GEN 1001 | BD8: =C8 -> 4 | BE8: =H16 -> GEN2012 | BF8: =J16 -> 4
A9: MTH 1217 | B9: Calculus I | C9: 4 | H9: MTH 1218 | I9: Calculus II | J9: 4 | O9: Pre-requisites or co-requisites not met | BC9: =A16 -> GEN2010 | BD9: =C16 -> 4 | BE9: =H18 -> GEN 3040 | BF9: =J18 -> 4
A10: PHL 1000 | B10: Intro to Philosophy | C10: 4 | H10: PHY 2211 | I10: Physics I | J10: 4 | O10: Pre-requisite for another course | BC10: =A19 -> CEN 2001 | BD10: =C19 -> 4 | BE10: =H25 -> CEN3030 | BF10: =J25 -> 4
A11: FYW 1050 | B11: College Writing | C11: 4 | H11: Arts & Lit (AL) | I11: Elective (course here) | J11: 4 | O11: Co-requisite for another course | BC11: =A34 -> CEN3010 | BD11: =C34 -> 4 | BE11: =H26 -> CEN3050 | BF11: =J26 -> 4
BC12: =A35 -> CEN3020 | BD12: =C35 -> 4 | BE12: =H27 -> CEN3090 | BF12: =J27 -> 1
C13: =SUM(C8:C12) -> 16 | J13: =SUM(J8:J12) -> 16 | BC13: =B43 -> Elective (course here) | BD13: =C43 -> 4 | BE13: =H43 -> CEN 4901 | BF13: =J43 -> 4
F15: SOPHOMORE YEAR | O15: INSTRUCTIONS FOR USE | BC15: =B44 -> Elective (course here) | BD15: =C44 -> 4 | BE15: =I44 -> Elective (course here) | BF15: =J44 -> 4
A16: GEN2010 | B16: Mechanics I | C16: 4 | H16: GEN2012 | I16: Mechanics II | J16: 4 | O16: 1. Enter a 1 into the boxes outlined in green beside courses that you have completed successfully | BE16: =I45 -> Elective (course here) | BF16: =J45 -> 4
A17: PHY 2212 | B17: Physics II | C17: 4 | H17: MTH 2220 | I17: Diff. Equations | J17: 4 | BE17: =H46 -> CEN 4900 | BF17: =J46 -> 1
A18: MTH 2219 | B18: Calculus III | C18: 4 | H18: GEN 3040 | I18: Fluid Mech. | J18: 4 | O18: 2. Now you're ready to begin planning the upcoming semester. Enter a 1 into the green boxes beside courses in which you would like to enroll next semester.
A19: CEN 2001 | B19: CE Site Design | C19: 4 | H19: CHM 1180 | I19: Engineering Chemistry | J19: 4
O20: 3. The cell will turn red if you are missing any co or pre-requisites, which are shown in teal and pink, respectively.
C22: =SUM(C16:C21) -> 16 | J22: =SUM(J16:J20) -> 16 | O22: 4. You may keep track of your progress through the curriculum by clicking on the Flowchart sheet. All completed courses will be outlined in yellow.
F23: WORK IN SUMMER
F24: JUNIOR YEAR 1
H25: CEN3030 | I25: Transportation | J25: 4
H26: CEN3050 | I26: Enviro. Engr. | J26: 4
B27: WORK DURING FALL | H27: CEN3090 | I27: Professionalism & Ethics | J27: 1
H28: Ethics (E) | I28: Elective (course here) | J28: 4
H29: Science* | I29: Elective (course here) | J29: 4
J31: =SUM(J25:J29) -> 17
F32: WORK IN SUMMER
F33: JUNIOR YEAR 2
A34: CEN3010 | B34: Structures | C34: 4 | BC34: Marc
A35: CEN3020 | B35: Geotech Engr | C35: 4 | BC35: =BC9 -> GEN2010 | BD35: =BD9 -> 4 | BE35: =BE8 -> GEN2012 | BF35: =BF8+2+3 -> 9
A36: PHY 2213 | B36: Thermodynamics | C36: 2 | I36: WORK DURING SPRING | BC36: =BC11 -> CEN3010 | BD36: =BD11 -> 4
A37: RTS 1100 | B37: Christianity in Context | C37: 4 | BC37: =BC13 -> Elective (course here) | BD37: =BD13 -> 4
A38: Hist. Studies (H) | B38: Elective (course here) | C38: 4
C40: =C34+C35+C36+C37+C38 -> 18
F41: WORK IN SUMMER
F42: SENIOR YEAR | BC42: Aaron
A43: Structures | B43: Elective (course here) | C43: 4 | H43: CEN 4901 | I43: Des. Project | J43: 4 | BC43: =BC12 -> CEN3020 | BD43: =BD12+2+3 -> 9 | BE43: =BE9 -> GEN 3040 | BF43: =BF9+2+3 -> 9
A44: Geotechnical | B44: Elective (course here) | C44: 4 | H44: Transportation | I44: Elective (course here) | J44: 4 | BC44: =BC15 -> Elective (course here) | BD44: =BD15 -> 4
A45: Technical | B45: Elective (course here) | C45: 4 | E45: Work with your advisor here. | H45: Environmental | I45: Elective (course here) | J45: 4
A46: Soc. Science (SS) | B46: Elective (course here) | C46: 4 | H46: CEN 4900 | I46: Senior Seminar | J46: 1 | BC46: Dave
...

Sheet CE Curriculum BUS minor
E1: MERRIMACK COLLEGE
E2: DEPARTMENT OF CIVIL ENGINEERING CURRICULUM
A4: Name | B4: ENTER NAME HERE | C4: ID # | D4: ID HERE | F4: Class year: | G4: CLASS YEAR HERE | I4: ADVISOR: | J4: ADVISOR HERE
B6: FALL | I6: SPRING | BC6: Workloads
F7: FRESHMAN YEAR | BC7: Fall | BE7: Spring
A8: GEN 1001 | B8: Intro. to Eng. | C8: 4 | H8: MTH 1505 | I8: Applied Statistics | J8: 4 | BC8: =A8 -> GEN 1001 | BD8: =C8 -> 4 | BE8: =H16 -> GEN2012 | BF8: =J16 -> 4
A9: MTH 1217 | B9: Calculus I | C9: 4 | H9: MTH 1218 | I9: Calculus II | J9: 4 | O9: Pre-requisites or co-requisites not met | BC9: =A16 -> GEN2010 | BD9: =C16 -> 4 | BE9: =H18 -> GEN 3040 | BF9: =J18 -> 4
A10: PHL 1000 | B10: Intro to Philosophy | C10: 4 | H10: PHY 2211 | I10: Physics I | J10: 4 | O10: Pre-requisite for another course | BC10: =A19 -> BUS 1100 | BD10: =C19 -> 4 | BE10: =H25 -> CEN3030 | BF10: =J25 -> 4
A11: FYW1050 | B11: College Writing | C11: 4 | H11: Arts & Lit (AL) | I11: Elective (course here) | J11: 4 | O11: Co-requisite for another course | BC11: =A34 -> CEN3010 | BD11: =C34 -> 4 | BE11: =H26 -> CEN3050 | BF11: =J26 -> 4
BC12: =A35 -> CEN3020 | BD12: =C35 -> 4 | BE12: =H27 -> CEN3090 | BF12: =J27 -> 1
C13: =SUM(C8:C12) -> 16 | J13: =SUM(J8:J12) -> 16 | BC13: =B43 -> Structures elective | BD13: =C43 -> 4 | BE13: =H43 -> CEN 4901 | BF13: =J43 -> 4
F15: SOPHOMORE YEAR | O15: INSTRUCTIONS FOR USE | BC15: =B44 -> Geotechnical elective | BD15: =C44 -> 4 | BE15: =I44 -> Management Info. Systems | BF15: =J44 -> 4
A16: GEN2010 | B16: Mechanics I | C16: 4 | H16: GEN2012 | I16: Mechanics II | J16: 4 | O16: 1. Enter a 1 into the boxes outlined in green beside courses that you have completed successfully | BE16: =I45 -> Operations Management | BF16: =J45 -> 4
A17: PHY 2212 | B17: Physics II | C17: 4 | H17: MTH 2220 | I17: Diff. Equations | J17: 4 | BE17: =H46 -> CEN 4900 | BF17: =J46 -> 1
A18: MTH 2219 | B18: Calculus III | C18: 4 | H18: GEN 3040 | I18: Fluid Mech. | J18: 4 | O18: 2. Now you're ready to begin planning the upcoming semester. Enter a 1 into the green boxes beside courses in which you would like to enroll next semester.
A19: BUS 1100 | B19: Essentials of Bus. Analysis | C19: 4 | H19: CHM 1180 | I19: Engineering Chemistry | J19: 4
O20: 3. The cell will turn red if you are missing any co or pre-requisites, which are shown in teal and pink, respectively.
C22: =SUM(C16:C21) -> 16 | J22: =SUM(J16:J20) -> 16 | O22: 4. You may keep track of your progress through the curriculum by clicking on the Flowchart sheet. All completed courses will be outlined in yellow.
F23: WORK IN SUMMER
F24: JUNIOR YEAR 1
A25: BUS 2203 | B25: Accounting for Business | C25: 4 | H25: CEN3030 | I25: Transportation | J25: 4
A26: BUS 2205 | B26: Principles of Marketing | C26: 4 | H26: CEN3050 | I26: Enviro. Engr. | J26: 4
A27: CEN 2001 | B27: CE Site Design | C27: 4 | H27: CEN3090 | I27: Professionalism & Ethics | J27: 1
A28: RTS 1100 | B28: Christianity in Context | C28: 4 | H28: Ethics (E) | I28: Elective (course here) | J28: 4
H29: Science* | I29: Elective (course here) | J29: 4
J31: =SUM(J25:J29) -> 17
F32: WORK IN SUMMER
F33: JUNIOR YEAR 2
A34: CEN3010 | B34: Structures | C34: 4 | BC34: Marc
A35: CEN3020 | B35: Geotech Engr | C35: 4 | BC35: =BC9 -> GEN2010 | BD35: =BD9 -> 4 | BE35: =BE8 -> GEN2012 | BF35: =BF8+2+3 -> 9
A36: PHY 2213 | B36: Thermodynamics | C36: 2 | I36: WORK DURING SPRING | BC36: =BC11 -> CEN3010 | BD36: =BD11 -> 4
A37: RTS 1001 | B37: Intro to Religious Studies | C37: 4 | BC37: =BC13 -> Structures elective | BD37: =BD13 -> 4
A38: Hist. Studies (H) | B38: Elective (course here) | C38: 4
C40: =C34+C35+C36+C37+C38 -> 18
F41: WORK IN SUMMER
F42: SENIOR YEAR | BC42: Aaron
A43: CEN | B43: Structures elective | C43: 4 | H43: CEN 4901 | I43: Des. Project | J43: 4 | BC43: =BC12 -> CEN3020 | BD43: =BD12+2+3 -> 9 | BE43: =BE9 -> GEN 3040 | BF43: =BF9+2+3 -> 9
A44: CEN | B44: Geotechnical elective | C44: 4 | H44: BUS 2210 | I44: Management Info. Systems | J44: 4 | BC44: =BC15 -> Geotechnical elective | BD44: =BD15 -> 4
A45: CEN | B45: Environmental elective | C45: 4 | E45: Work with your advisor here. | H45: BUS 2220 | I45: Operations Management | J45: 4
A46: Soc. Science (SS) | B46: Elective (course here) | C46: 4 | H46: CEN 4900 | I46: Senior Seminar | J46: 1 | BC46: Dave
...

Sheet CE Curriculum double major
E1: MERRIMACK COLLEGE
E2: DEPARTMENT OF CIVIL ENGINEERING CURRICULUM
F3: CE and WLC Double Major Proposal
A4: Name | B4: ENTER NAME HERE | C4: ID # | D4: ID HERE | F4: Class year: | G4: CLASS YEAR HERE | I4: ADVISOR: | J4: ADVISOR HERE
B6: FALL | I6: SPRING | BC6: Workloads
F7: FRESHMAN YEAR | BC7: Fall | BE7: Spring
A8: GEN 1001 | B8: Intro. to Eng. | C8: 4 | H8: MTH 1505 | I8: Applied Statistics | J8: 4 | BC8: =A8 -> GEN 1001 | BD8: =C8 -> 4 | BE8: =H16 -> GEN2012 | BF8: =J16 -> 4
A9: MTH 1217 | B9: Calculus I | C9: 4 | H9: MTH 1218 | I9: Calculus II | J9: 4 | O9: Pre-requisites or co-requisites not met | BC9: =A16 -> GEN2010 | BD9: =C16 -> 4 | BE9: =H18 -> GEN 3040 | BF9: =J18 -> 4
A10: WLC | B10: Major Course | C10: 4 | H10: PHY 2211 | I10: Physics I | J10: 4 | O10: Pre-requisite for another course | BC10: =A19 -> WLC | BD10: =C19 -> 4 | BE10: =H25 -> CEN3030 | BF10: =J25 -> 4
A11: FYW 1050 | B11: College Writing | C11: 4 | H11: Arts & Lit (AL) | I11: choose WLC major course | J11: 4 | O11: Co-requisite for another course | BC11: =A34 -> MTH 2220 | BD11: =C34 -> 4 | BE11: =H26 -> CEN3050 | BF11: =J26 -> 4
BC12: =A35 -> PHL 1000 | BD12: =C35 -> 4 | BE12: =H27 -> CEN3090 | BF12: =J27 -> 1
C13: =SUM(C8:C12) -> 16 | J13: =SUM(J8:J12) -> 16 | BC13: =B43 -> Elective (course here) | BD13: =C43 -> 4 | BE13: =H43 -> CEN 4901 | BF13: =J43 -> 4
F15: SOPHOMORE YEAR | O15: INSTRUCTIONS FOR USE | BC15: =B44 -> Elective (course here) | BD15: =C44 -> 4 | BE15: =I44 -> Elective (course here) | BF15: =J44 -> 4
A16: GEN2010 | B16: Mechanics I | C16: 4 | H16: GEN2012 | I16: Mechanics II | J16: 4 | O16: 1. Enter a 1 into the boxes outlined in green beside courses that you have completed successfully | BE16: =I45 -> Elective (course here) | BF16: =J45 -> 4
A17: PHY 2212 | B17: Physics II | C17: 4 | H17: WLC | I17: Major course | J17: 3 | BE17: =H46 -> CEN 4900 | BF17: =J46 -> 1
A18: MTH 2219 | B18: Calculus III | C18: 4 | H18: GEN 3040 | I18: Fluid Mech. | J18: 4 | O18: 2. Now you're ready to begin planning the upcoming semester. Enter a 1 into the green boxes beside courses in which you would like to enroll next semester.
A19: WLC | B19: Major course | C19: 4 | H19: CHM 1180 | I19: Engineering Chemistry | J19: 4
O20: 3. The cell will turn red if you are missing any co or pre-requisites, which are shown in teal and pink, respectively.
C22: =SUM(C16:C21) -> 16 | J22: =SUM(J16:J20) -> 15 | O22: 4. You may keep track of your progress through the curriculum by clicking on the Flowchart sheet. All completed courses will be outlined in yellow.
F23: WORK IN SUMMER
F24: JUNIOR YEAR 1
A25: CEN 2001 | B25: CE Site Design | C25: 4 | H25: CEN3030 | I25: Transportation | J25: 4
A26: CEN3010 | B26: Structures | C26: 4 | H26: CEN3050 | I26: Enviro. Engr. | J26: 4
A27: CEN3020 | B27: Geotech Engr | C27: 4 | H27: CEN3090 | I27: Professionalism & Ethics | J27: 1
A28: WLC | B28: Major course | C28: 4 | H28: Ethics (E) | I28: Elective (course here) | J28: 4
H29: WLC | I29: Major course | J29: 3
J31: =SUM(J25:J29) -> 16
F32: WORK IN SUMMER
F33: JUNIOR YEAR 2
A34: MTH 2220 | B34: Diff. Equations | C34: 4 | H34: STUDY ABROAD SEMESTER | BC34: Marc
A35: PHL 1000 | B35: Intro to Philosophy | C35: 4 | H35: WLC | I35: Major course | J35: 3 | BC35: =BC9 -> GEN2010 | BD35: =BD9 -> 4 | BE35: =BE8 -> GEN2012 | BF35: =BF8+2+3 -> 9
A36: PHY 2213 | B36: Thermodynamics | C36: 2 | H36: Science* | I36: Elective (course here) | J36: 3 | BC36: =BC11 -> MTH 2220 | BD36: =BD11 -> 4
A37: RTS 1100 | B37: Christianity in Context | C37: 4 | H37: Soc. Science (SS) | I37: Elective (course here) | J37: 3 | BC37: =BC13 -> Elective (course here) | BD37: =BD13 -> 4
A38: WLC | B38: Major Course | C38: 4 | H38: Hist. Studies (H) | I38: Elective (course here) | J38: 3
C40: =C34+C35+C36+C37+C38 -> 18
F41: WORK IN SUMMER
F42: SENIOR YEAR | BC42: Aaron
A43: Structures | B43: Elective (course here) | C43: 4 | H43: CEN 4901 | I43: Des. Project | J43: 4 | BC43: =BC12 -> PHL 1000 | BD43: =BD12+2+3 -> 9 | BE43: =BE9 -> GEN 3040 | BF43: =BF9+2+3 -> 9
A44: Geotechnical | B44: Elective (course here) | C44: 4 | H44: Transportation | I44: Elective (course here) | J44: 4 | BC44: =BC15 -> Elective (course here) | BD44: =BD15 -> 4
A45: Soc. Science (SS) | B45: Elective (course here) | C45: 4 | E45: Work with your advisor here. | H45: Environmental | I45: Elective (course here) | J45: 4
...

Sheet CE Curriculum ESS Minor
E1: MERRIMACK COLLEGE
E2: DEPARTMENT OF CIVIL ENGINEERING CURRICULUM
A4: Name | B4: ENTER NAME HERE | C4: ID # | D4: ID HERE | F4: Class year: | G4: CLASS YEAR HERE | I4: ADVISOR: | J4: ADVISOR HERE
B6: FALL | I6: SPRING | BC6: Workloads
F7: FRESHMAN YEAR | BC7: Fall | BE7: Spring
A8: GEN 1001 | B8: Intro. to Eng. | C8: 4 | H8: MTH 1505* | I8: Applied Statistics | J8: 4 | BC8: =A8 -> GEN 1001 | BD8: =C8 -> 4 | BE8: =H16 -> GEN2012 | BF8: =J16 -> 4
A9: MTH 1217 | B9: Calculus I | C9: 4 | H9: MTH 1218 | I9: Calculus II | J9: 4 | O9: Pre-requisites or co-requisites not met | BC9: =A16 -> GEN2010 | BD9: =C16 -> 4 | BE9: =H18 -> GEN 3040 | BF9: =J18 -> 4
A10: PHL 1000 | B10: Intro to Philosophy | C10: 4 | H10: PHY 2211 | I10: Physics I | J10: 4 | O10: Pre-requisite for another course | BC10: =A19 -> CEN 2001 | BD10: =C19 -> 4 | BE10: =H25 -> CEN3030 | BF10: =J25 -> 4
A11: FYW 1050 | B11: College Writing | C11: 4 | H11: Arts & Lit (AL) | I11: Elective (course here) | J11: 4 | O11: Co-requisite for another course | BC11: =A25 -> CEN3010 | BD11: =C25 -> 4 | BE11: =H26 -> CEN3050 | BF11: =J26 -> 4
H12: * replaces MTH 1111 | BC12: =A26 -> CEN3020 | BD12: =C26 -> 4 | BE12: =H27 -> CEN3090 | BF12: =J27 -> 1
C13: 16 | J13: 16 | BC13: =B34 -> Elective (course here) | BD13: =C34 -> 4 | BE13: =H34 -> CEN 4901 | BF13: =J34 -> 4
F15: SOPHOMORE YEAR | O15: INSTRUCTIONS FOR USE | BC15: =B35 -> Elective (course here) | BD15: =C35 -> 4 | BE15: =I35 -> Elective (course here) | BF15: =J35 -> 4
A16: GEN2010 | B16: Mechanics I | C16: 4 | H16: GEN2012 | I16: Mechanics II | J16: 4 | O16: 1. Enter a 1 into the boxes outlined in green beside courses that you have completed successfully | BE16: =I36 -> Elective (course here) | BF16: =J36 -> 4
A17: PHY 2212 | B17: Physics II | C17: 4 | H17: MTH 2220 | I17: Diff. Equations | J17: 4 | BE17: =H37 -> CEN 4900 | BF17: =J37 -> 1
A18: MTH 2219 | B18: Calculus III | C18: 4 | H18: GEN 3040 | I18: Fluid Mech. | J18: 4 | O18: 2. Now you're ready to begin planning the upcoming semester. Enter a 1 into the green boxes beside courses in which you would like to enroll next semester.
A19: CEN 2001 | B19: CE Site Design | C19: 4 | H19: CHM 1180 | I19: Engineering Chemistry | J19: 4
O20: 3. The cell will turn red if you are missing any co or pre-requisites, which are shown in teal and pink, respectively.
C22: 16 | J22: 16 | O22: 4. You may keep track of your progress through the curriculum by clicking on the Flowchart sheet. All completed courses will be outlined in yellow.
F24: JUNIOR YEAR
A25: CEN3010 | B25: Structures | C25: 4 | H25: CEN3030 | I25: Transportation | J25: 4 | BC25: Marc
A26: CEN3020 | B26: Geotech Engr | C26: 4 | H26: CEN3050 | I26: Enviro. Engr. | J26: 4 | BC26: =BC9 -> GEN2010 | BD26: =BD9 -> 4 | BE26: =BE8 -> GEN2012 | BF26: =BF8+2+3 -> 9
A27: PHY 2213 | B27: Thermodynamics | C27: 2 | H27: CEN3090 | I27: Professionalism & Ethics | J27: 1 | BC27: =BC11 -> CEN3010 | BD27: =BD11 -> 4
A28: RTS 1100 | B28: Christianity in Context | C28: 4 | H28: PHL 2070 | I28: Enviro Ethis | J28: 4 | BC28: =BC13 -> Elective (course here) | BD28: =BD13 -> 4
A29: HIS 3525 | B29: Environmental History of North America | C29: 4 | H29: ESS 1050 | I29: Enviro Studies Gateway | J29: 4
C31: 18 | J31: 17
F33: SENIOR YEAR | BC33: Aaron
A34: Structures | B34: Elective (course here) | C34: 4 | H34: CEN 4901 | I34: Des. Project | J34: 4 | BC34: =BC12 -> CEN3020 | BD34: =BD12+2+3 -> 9 | BE34: =BE9 -> GEN 3040 | BF34: =BF9+2+3 -> 9
A35: Geotechnical | B35: Elective (course here) | C35: 4 | H35: Transportation | I35: Elective (course here) | J35: 4 | BC35: =BC15 -> Elective (course here) | BD35: =BD15 -> 4
A36: ESS 4850 | B36: Community internship | C36: 4 | E36: Work with your advisor here. | H36: Environmental | I36: Elective (course here) | J36: 4
A37: ECO | B37: 1201 or 1202 or 3305 | C37: 4 | H37: CEN 4900 | I37: Senior Seminar | J37: 1 | BC37: Dave
H38: Soc. Science (SS) | I38: Elective (course here) | J38: 4 | BC38: =BC10 -> CEN 2001 | BD38: =BD10+2+3 -> 9 | BE38: =BE11 -> CEN3050 | BF38: =BF11+2+3 -> 9
BE39: =BE12 -> CEN3090 | BF39: =BF12 -> 1
A40: Overall GPA | F40: TOOK FE EXAM | BE40: =BE16 -> Elective (course here) | BF40: =BF16 -> 4
A41: Major GPA | F41: DIVERSITY CRS. | I41: Enter course used here
C42: 16 | J42: 17
A43: NOTES | H43: List of CE Senior Electives
G44: Environmental Engineering | J44: # cr | BC44: Gary
H45: CEN 4030 Enviro Design | J45: 4 | BC45: =BC8 -> GEN 1001 | BD45: =BD8+2+3 -> 9 | BE45: =BE10 -> CEN3030 | BF45: =BF10+2 -> 6
H46: CEN 4032 Applied Hydrology | J46: 4 | BE46: =BE17 -> CEN 4900 | BF46: =BF17 -> 1
A47: Must take one additional ESS elective approved by the ESS Director
...

Sheet Flowchart
H3: =CONCATENATE("BS in Civil Engineering",CHAR(10),"Class of 2012 Flowchart") -> BS in Civil Engineering Class of 2012 Flowchart | AA3: ='CE Curriculum'!A8 -> GEN 1001 | AB3: ='CE Curriculum'!B8 -> Intro. to Eng. | AC3: ='CE Curriculum'!C8 -> 4 | AD3: ='CE Curriculum'!D8 -> 0 | AH3: ='CE Curriculum'!H8 -> MTH 1505 | AI3: ='CE Curriculum'!I8 -> Applied Statistics | AJ3: ='CE Curriculum'!J8 -> 4 | AK3: ='CE Curriculum'!K8 -> 0
N4: Student Name: | O4: ='CE Curriculum'!B4 -> ENTER NAME HERE | AA4: ='CE Curriculum'!A9 -> MTH 1217 | AB4: ='CE Curriculum'!B9 -> Calculus I | AC4: ='CE Curriculum'!C9 -> 4 | AD4: ='CE Curriculum'!D9 -> 0 | AH4: ='CE Curriculum'!H9 -> MTH 1218 | AI4: ='CE Curriculum'!I9 -> Calculus II | AJ4: ='CE Curriculum'!J9 -> 4 | AK4: ='CE Curriculum'!K9 -> 0
N5: Student Number: | O5: ='CE Curriculum'!D4 -> ID HERE | AA5: ='CE Curriculum'!A10 -> PHL 1000 | AB5: ='CE Curriculum'!B10 -> Intro to Philosophy | AC5: ='CE Curriculum'!C10 -> 4 | AD5: ='CE Curriculum'!D10 -> 0 | AH5: ='CE Curriculum'!H10 -> PHY 2211 | AI5: ='CE Curriculum'!I10 -> Physics I | AJ5: ='CE Curriculum'!J10 -> 4 | AK5: ='CE Curriculum'!K10 -> 0
B6: =CONCATENATE('CE Curriculum'!A8,CHAR(10),'CE Curriculum'!B8) -> GEN 1001 Intro. to Eng. | D6: =CONCATENATE('CE Curriculum'!A19,CHAR(10),'CE Curriculum'!B19) -> CEN 2001 CE Site Design | N6: Class year: | O6: ='CE Curriculum'!G4 -> CLASS YEAR HERE | AA6: ='CE Curriculum'!A11 -> FYW 1050 | AB6: ='CE Curriculum'!B11 -> College Writing | AC6: ='CE Curriculum'!C11 -> 4 | AD6: ='CE Curriculum'!D11 -> 0 | AH6: ='CE Curriculum'!H11 -> Arts & Lit (AL) | AI6: ='CE Curriculum'!I11 -> Elective (course here) | AJ6: ='CE Curriculum'!J11 -> 4 | AK6: ='CE Curriculum'!K11 -> 0
N7: Advisor: | O7: ='CE Curriculum'!J4 -> ADVISOR HERE
D8: =CONCATENATE('CE Curriculum'!H8,CHAR(10),'CE Curriculum'!I8) -> MTH 1505 Applied Statistics | J8: =CONCATENATE('CE Curriculum'!H25,CHAR(10),'CE Curriculum'!I25) -> CEN3030 Transportation | L8: =CONCATENATE('CE Curriculum'!H35," ",'CE Curriculum'!I35) -> Transportation Elective (course here)
H10: =CONCATENATE('CE Curriculum'!H17,CHAR(10),'CE Curriculum'!I17) -> MTH 2220 Diff. Equations | J10: =CONCATENATE('CE Curriculum'!A26,CHAR(13),'CE Curriculum'!B26) -> CEN3020_x000D_Geotech Engr | L10: =CONCATENATE('CE Curriculum'!A35," ",'CE Curriculum'!B35) -> Geotechnical Elective (course here)
S11: mag factor
B12: =CONCATENATE('CE Curriculum'!A9,CHAR(10),'CE Curriculum'!B9) -> MTH 1217 Calculus I | D12: =CONCATENATE('CE Curriculum'!H9,CHAR(10),'CE Curriculum'!I9) -> MTH 1218 Calculus II | F12: =CONCATENATE('CE Curriculum'!A18,CHAR(10),'CE Curriculum'!B18) -> MTH 2219 Calculus III | J12: =CONCATENATE('CE Curriculum'!H18,CHAR(10),'CE Curriculum'!I18) -> GEN 3040 Fluid Mech. | S12: 1.63 | T12: Want | AF12: ='CE Curriculum'!F15 -> SOPHOMORE YEAR
R13: 19.79 | S13: =R13*S12 -> 32.2577 | T13: 36 | AA13: ='CE Curriculum'!A16 -> GEN2010 | AB13: ='CE Curriculum'!B16 -> Mechanics I | AC13: ='CE Curriculum'!C16 -> 4 | AD13: ='CE Curriculum'!D16 -> 0 | AH13: ='CE Curriculum'!H16 -> GEN2012 | AI13: ='CE Curriculum'!I16 -> Mechanics II | AJ13: ='CE Curriculum'!J16 -> 4 | AK13: ='CE Curriculum'!K16 -> 0
B14: =CONCATENATE('CE Curriculum'!H19,CHAR(10),'CE Curriculum'!I19) -> CHM 1180 Engineering Chemistry | D14: =CONCATENATE('CE Curriculum'!H29," ",'CE Curriculum'!I29) -> Science* Elective (course here) | J14: =CONCATENATE('CE Curriculum'!H26,CHAR(10),'CE Curriculum'!I26) -> CEN3050 Enviro. Engr. | L14: =CONCATENATE('CE Curriculum'!H36," ",'CE Curriculum'!I36) -> Environmental Elective (course here) | R14: 14.75 | S14: =R14*S12 -> 24.0425 | T14: 24 | AA14: ='CE Curriculum'!A17 -> PHY 2212 | AB14: ='CE Curriculum'!B17 -> Physics II | AC14: ='CE Curriculum'!C17 -> 4 | AD14: ='CE Curriculum'!D17 -> 0 | AH14: ='CE Curriculum'!H17 -> MTH 2220 | AI14: ='CE Curriculum'!I17 -> Diff. Equations | AJ14: ='CE Curriculum'!J17 -> 4 | AK14: ='CE Curriculum'!K17 -> 0
AA15: ='CE Curriculum'!A18 -> MTH 2219 | AB15: ='CE Curriculum'!B18 -> Calculus III | AC15: ='CE Curriculum'!C18 -> 4 | AD15: ='CE Curriculum'!D18 -> 0 | AH15: ='CE Curriculum'!H18 -> GEN 3040 | AI15: ='CE Curriculum'!I18 -> Fluid Mech. | AJ15: ='CE Curriculum'!J18 -> 4 | AK15: ='CE Curriculum'!K18 -> 0
B16: Pre-calculus | D16: =CONCATENATE('CE Curriculum'!H10,CHAR(10),'CE Curriculum'!I10) -> PHY 2211 Physics I | F16: =CONCATENATE('CE Curriculum'!A17,CHAR(10),'CE Curriculum'!B17) -> PHY 2212 Physics II | H16: =CONCATENATE('CE Curriculum'!H16,CHAR(10),'CE Curriculum'!I16) -> GEN2012 Mechanics II | J16: =CONCATENATE('CE Curriculum'!A25,CHAR(10),'CE Curriculum'!B25) -> CEN3010 Structures | L16: =CONCATENATE('CE Curriculum'!A34," ",'CE Curriculum'!B34) -> Structures Elective (course here) | AA16: ='CE Curriculum'!A19 -> CEN 2001 | AB16: ='CE Curriculum'!B19 -> CE Site Design | AC16: ='CE Curriculum'!C19 -> 4 | AD16: ='CE Curriculum'!D19 -> 0 | AH16: ='CE Curriculum'!H19 -> CHM 1180 | AI16: ='CE Curriculum'!I19 -> Engineering Chemistry | AJ16: ='CE Curriculum'!J19 -> 4 | AK16: ='CE Curriculum'!K19 -> 0
B18: =CONCATENATE('CE Curriculum'!A11,CHAR(10),'CE Curriculum'!B11) -> FYW 1050 College Writing | F18: =CONCATENATE('CE Curriculum'!A16,CHAR(10),'CE Curriculum'!B16) -> GEN2010 Mechanics I | J18: Permission of academic advisor | L18: =CONCATENATE('CE Curriculum'!A36," ",'CE Curriculum'!B36) -> Technical Elective (course here)
B20: =CONCATENATE('CE Curriculum'!A28," ",'CE Curriculum'!B28) -> RTS 1100 Christianity in Context | D20: =CONCATENATE('CE Curriculum'!H28," ",'CE Curriculum'!I28) -> Ethics (E) Elective (course here) | F20: =CONCATENATE('CE Curriculum'!A27,CHAR(10),'CE Curriculum'!B27) -> PHY 2213 Thermodynamics | J20: Senior standing | L20: =CONCATENATE('CE Curriculum'!H37,CHAR(10),'CE Curriculum'!I37) -> CEN 4900 Senior Seminar
O21: *Suggested Science Electives: | AF21: ='CE Curriculum'!F24 -> JUNIOR YEAR
B22: =CONCATENATE('CE Curriculum'!A10," ",'CE Curriculum'!B10) -> PHL 1000 Intro to Philosophy | J22: =CONCATENATE('CE Curriculum'!H27,CHAR(10),'CE Curriculum'!I27) -> CEN3090 Professionalism & Ethics | L22: =CONCATENATE('CE Curriculum'!H34,CHAR(10),'CE Curriculum'!I34) -> CEN 4901 Des. Project | O22: AST 1101 Introduction to Astronomy | AA22: ='CE Curriculum'!A25 -> CEN3010 | AB22: ='CE Curriculum'!B25 -> Structures | AC22: ='CE Curriculum'!C25 -> 4 | AD22: ='CE Curriculum'!D25 -> 0 | AH22: ='CE Curriculum'!H25 -> CEN3030 | AI22: ='CE Curriculum'!I25 -> Transportation | AJ22: ='CE Curriculum'!J25 -> 4 | AK22: ='CE Curriculum'!K25 -> 0
O23: BIO 1027 Principles of Biology I | AA23: ='CE Curriculum'!A26 -> CEN3020 | AB23: ='CE Curriculum'!B26 -> Geotech Engr | AC23: ='CE Curriculum'!C26 -> 4 | AD23: ='CE Curriculum'!D26 -> 0 | AH23: ='CE Curriculum'!H26 -> CEN3050 | AI23: ='CE Curriculum'!I26 -> Enviro. Engr. | AJ23: ='CE Curriculum'!J26 -> 4 | AK23: ='CE Curriculum'!K26 -> 0
B24: =CONCATENATE('CE Curriculum'!A37," ",'CE Curriculum'!B37) -> Soc. Science (SS) Elective (course here) | I24: CEN 3010, 3020,3030, 3040, 3050 (one senior CEN elective may be substituted for one of these jr courses) and at least 1 sr CEN elective | O24: BIO 3090 Environmental Ecology | AA24: ='CE Curriculum'!A27 -> PHY 2213 | AB24: ='CE Curriculum'!B27 -> Thermodynamics | AC24: ='CE Curriculum'!C27 -> 2 | AD24: ='CE Curriculum'!D27 -> 0 | AH24: ='CE Curriculum'!H27 -> CEN3090 | AI24: ='CE Curriculum'!I27 -> Professionalism & Ethics | AJ24: ='CE Curriculum'!J27 -> 1 | AK24: ='CE Curriculum'!K27 -> 0
F25: Steps to your goal: | O25: CEN 4060 Geology | AA25: ='CE Curriculum'!A28 -> RTS 1100 | AB25: ='CE Curriculum'!B28 -> Christianity in Context | AC25: ='CE Curriculum'!C28 -> 4 | AD25: ='CE Curriculum'!D28 -> 0 | AH25: ='CE Curriculum'!H28 -> Ethics (E) | AI25: ='CE Curriculum'!I28 -> Elective (course here) | AJ25: ='CE Curriculum'!J28 -> 4 | AK25: ='CE Curriculum'!K28 -> 0
B26: =CONCATENATE('CE Curriculum'!H11," ",'CE Curriculum'!I11) -> Arts & Lit (AL) Elective (course here) | F26: =CONCATENATE("BSCE",CHAR(10),"Pass FE Exam",CHAR(10),"Pass PE Exam") -> BSCE Pass FE Exam Pass PE Exam | J26: Key | O26: CSC 1610 Computer Science I | AA26: ='CE Curriculum'!A29 -> Hist. Studies (H) | AB26: ='CE Curriculum'!B29 -> Elective (course here) | AC26: ='CE Curriculum'!C29 -> 4 | AD26: ='CE Curriculum'!D29 -> 0 | AH26: ='CE Curriculum'!H29 -> Science* | AI26: ='CE Curriculum'!I29 -> Elective (course here) | AJ26: ='CE Curriculum'!J29 -> 4 | AK26: ='CE Curriculum'!K29 -> 0
J27: Pre-requisite: | O27: HSC 3302 Community Public Health
B28: =CONCATENATE('CE Curriculum'!H38," ",'CE Curriculum'!I38) -> Soc. Science (SS) Elective (course here) | H28: ='CE Curriculum'!F40 -> TOOK FE EXAM | J28: Co-requisite
H29: ='CE Curriculum'!F41 -> DIVERSITY CRS.
B30: =CONCATENATE('CE Curriculum'!A29," ",'CE Curriculum'!B29) -> Hist. Studies (H) Elective (course here) | AF30: ='CE Curriculum'!F33 -> SENIOR YEAR
H31: Our mission is to prepare exceptional civil engineers! | AA31: ='CE Curriculum'!A34 -> Structures | AB31: ='CE Curriculum'!B34 -> Elective (course here) | AC31: ='CE Curriculum'!C34 -> 4 | AD31: ='CE Curriculum'!D34 -> 0 | AH31: ='CE Curriculum'!H34 -> CEN 4901 | AI31: ='CE Curriculum'!I34 -> Des. Project | AJ31: ='CE Curriculum'!J34 -> 4 | AK31: ='CE Curriculum'!K34 -> 0
AA32: ='CE Curriculum'!A35 -> Geotechnical | AB32: ='CE Curriculum'!B35 -> Elective (course here) | AC32: ='CE Curriculum'!C35 -> 4 | AD32: ='CE Curriculum'!D35 -> 0 | AH32: ='CE Curriculum'!H35 -> Transportation | AI32: ='CE Curriculum'!I35 -> Elective (course here) | AJ32: ='CE Curriculum'!J35 -> 4 | AK32: ='CE Curriculum'!K35 -> 0
AA33: ='CE Curriculum'!A36 -> Technical | AB33: ='CE Curriculum'!B36 -> Elective (course here) | AC33: ='CE Curriculum'!C36 -> 4 | AD33: ='CE Curriculum'!D36 -> 0 | AH33: ='CE Curriculum'!H36 -> Environmental | AI33: ='CE Curriculum'!I36 -> Elective (course here) | AJ33: ='CE Curriculum'!J36 -> 4 | AK33: ='CE Curriculum'!K36 -> 0
AA34: ='CE Curriculum'!A37 -> Soc. Science (SS) | AB34: ='CE Curriculum'!B37 -> Elective (course here) | AC34: ='CE Curriculum'!C37 -> 4 | AD34: ='CE Curriculum'!D37 -> 0 | AH34: ='CE Curriculum'!H37 -> CEN 4900 | AI34: ='CE Curriculum'!I37 -> Senior Seminar | AJ34: ='CE Curriculum'!J37 -> 1 | AK34: ='CE Curriculum'!K37 -> 0
AA35: ='CE Curriculum'!A38 -> 0 | AB35: ='CE Curriculum'!B38 -> 0 | AC35: ='CE Curriculum'!C38 -> 0 | AD35: ='CE Curriculum'!D38 -> 0 | AH35: ='CE Curriculum'!H38 -> Soc. Science (SS) | AI35: ='CE Curriculum'!I38 -> Elective (course here) | AJ35: ='CE Curriculum'!J38 -> 4 | AK35: ='CE Curriculum'!K38 -> 0
AF37: ='CE Curriculum'!F40 -> TOOK FE EXAM | AG37: ='CE Curriculum'!H40 -> 0
AF38: ='CE Curriculum'!F41 -> DIVERSITY CRS. | AG38: ='CE Curriculum'!H41 -> 0

Sheet General Education
A2: Foundations | F2: Required
A3: Requirement | B3: Y | C3: N | D3: Course(s) taken | E3: Credits | F3: Credits
A4: =CONCATENATE("1. ",'CE Curriculum'!A11) -> 1. FYW 1050 | B4: =IF('CE Curriculum'!D11=1,"x"," ") | C4: =IF(B4=" ","x","") -> x | E4: =IF(B4="x",'CE Curriculum'!C11,0) -> 0 | F4: 4
A5: =CONCATENATE("2. ",'CE Curriculum'!A10) -> 2. PHL 1000 | B5: =IF('CE Curriculum'!D10=1,"x"," ") | C5: =IF(B5=" ","x","") -> x | E5: =IF(B5="x",'CE Curriculum'!C10,0) -> 0 | F5: 4
A6: 3. Quantitative Reasoning (Q) | B6: =IF('CE Curriculum'!D9=1,"x"," ") | C6: =IF(B6=" ","x","") -> x | D6: =IF(B6="x",'CE Curriculum'!B9,"") | E6: =IF(B6="x",'CE Curriculum'!C9,0) -> 0 | G6: Uses MTH 1217
A7: =CONCATENATE("4. ",'CE Curriculum'!H28) -> 4. Ethics (E) | B7: =IF('CE Curriculum'!K28=1,"x"," ") | C7: =IF(B7=" ","x","") -> x | D7: =IF(B7="x",'CE Curriculum'!I28,"") | E7: =IF(B7="x",'CE Curriculum'!J28,0) -> 0 | F7: 4
A9: Explorations | F9: Required
A10: Requirement | B10: Y | C10: N | D10: Course(s) taken | E10: Credits | F10: Credits
A11: =CONCATENATE("5. ",'CE Curriculum'!A28) -> 5. RTS 1100 | B11: =IF('CE Curriculum'!D28=1,"x"," ") | C11: =IF(B11=" ","x","") -> x | E11: =IF(B11="x",'CE Curriculum'!C28,0) -> 0 | F11: 4
A12: =CONCATENATE("6. ",'CE Curriculum'!H11) -> 6. Arts & Lit (AL) | B12: =IF('CE Curriculum'!K11=1,"x"," ") | C12: =IF(B12=" ","x","") -> x | D12: =IF(B12="x",'CE Curriculum'!I11,"") | E12: =IF(B12="x",'CE Curriculum'!J11,0) -> 0 | F12: 4
A13: 7. Foreign language* | B13: =IF('CE Curriculum'!K9=1,"x"," ") | C13: =IF(B13=" ","x","") -> x | D13: =IF(B13="x",'CE Curriculum'!I9,"") | E13: =IF(B13="x",'CE Curriculum'!J9,0) -> 0 | F13: 4 | G13: Uses MTH 1218
A14: =CONCATENATE("8. ",'CE Curriculum'!A29) -> 8. Hist. Studies (H) | B14: =IF('CE Curriculum'!D29=1,"x"," ") | C14: =IF(B14=" ","x","") -> x | D14: =IF(B14="x",'CE Curriculum'!B29,"") | E14: =IF(B14="x",'CE Curriculum'!C29,0) -> 0 | F14: 4
A15: =CONCATENATE("9. ",'CE Curriculum'!A37) -> 9. Soc. Science (SS) | B15: =IF('CE Curriculum'!D37=1,"x"," ") | C15: =IF(B15=" ","x","") -> x | D15: =IF(B15="x",'CE Curriculum'!B37,"") | E15: =IF(B15="x",'CE Curriculum'!C37,0) -> 0 | F15: 4
A16: =CONCATENATE("9. ",'CE Curriculum'!H38) -> 9. Soc. Science (SS) | B16: =IF('CE Curriculum'!K38=1,"x"," ") | C16: =IF(B16=" ","x","") -> x | D16: =IF(B16="x",'CE Curriculum'!I38,"") | E16: =IF(B16="x",'CE Curriculum'!J38,0) -> 0 | F16: 4
A17: 10. STEM | B17: =IF('CE Curriculum'!D9=1,"x"," ") | C17: =IF(B17=" ","x","") -> x | D17: =IF(B17="x",'CE Curriculum'!B9,"") | E17: =IF('CE Curriculum'!C9=1,"x"," ") | F17: 4 | G17: Uses MTH 1217
A18: 10. STEM | B18: =IF('CE Curriculum'!K10=1,"x"," ") | C18: =IF(B18=" ","x","") -> x | D18: =IF(B18="x",'CE Curriculum'!I10,"") | E18: =IF('CE Curriculum'!J10=1,"x"," ") | F18: 4 | G18: Uses PHY 2217
A19: 11. Cultural Diversity (D) | B19: =IF('CE Curriculum'!H41=1,"x"," ") | C19: =IF(B19=" ","x","") -> x | D19: =IF('CE Curriculum'!I41=1,"x"," ")
A21: Connections
A22: Writing intensive (W)** | B22: =IF('CE Curriculum'!D8=1,"x"," ") | C22: =IF(B22=" ","x","") -> x | D22: =IF(B22="x",'CE Curriculum'!B8,"") | G22: Uses GEN 1001
A23: Experiential (X)*** | B23: =IF('CE Curriculum'!K34=1,"x"," ") | C23: =IF(B23=" ","x","") -> x | D23: =IF(B23="x",'CE Curriculum'!I34,"") | G23: Uses CEN 4901
A25: FE Exam taken | B25: =IF('CE Curriculum'!H40=1,"x"," ") | C25: =IF(B25=" ","x","") -> x
A27: * Uses Calculus II as replacement for this requirement
D29: TOTALS | E29: =SUM(E5:E8,E13:E20) -> 0 | F29: =SUM(F4:F8,F11:F20) -> 44

Sheet ABET Summary
B2: Curriculum Analysis
B3: Curricular | C3: Number of Credits*
B4: Category | C4: Criteria | D4: Table I-1
C5: Requirement | D5: of Self-Study | E5: Actuals | F5: taken
B6: College-level Mathematics and Basic Science | C6: 1 yr (30-32 cr) | D6: 32 | E6: =H56 -> 38 | F6: =I56 -> 0
B7: Engineering Topics | C7: 1.5 yr (45-48 cr) | D7: =32*1.5 -> 48 | E7: =H75 -> 58 | F7: =I75 -> 0
B8: General Education | C8: Inst. Reqmt=44 | D8: 44 | E8: =H94 -> 44 | F8: =I94 -> 0 | G8: CEN 1001 counts for 4 more if taken F08 or later
B9: Please List Below Any Applicable Program Criteria Requirements:
B16: CIVIL ENGINEERING | C16: {=SUMPRODUCT(I59:I74,J59:J74)/I75} -> #DIV/0! | D16: =VLOOKUP(C16,L32:M43,2) -> #DIV/0!
B17: OVERALL | C17: {=(SUMPRODUCT(I44:I54,J44:J54)+SUMPRODUCT(I59:I74,J59:J74)+SUMPRODUCT(I78:I86,J78:J86)+SUMPRODUCT(I85:I107,J85:J107)+I97*J97)/(I56+I75+I94+I97)} -> #DIV/0! | D17: =VLOOKUP(C17,L33:M44,2) -> #DIV/0!
B18: MATH AND SCIENCE | C18: {=(SUMPRODUCT(I44:I48,J44:J48)+SUMPRODUCT(I50:I54,J50:J54))/I56} -> #DIV/0! | D18: =VLOOKUP(C18,L34:M45,2) -> #DIV/0! | K18: A | L18: 4
B19: GENERAL EDUCATION | C19: {=(SUMPRODUCT(I78:I86,J78:J86)+SUMPRODUCT(I85:I107,J85:J107))/I94} -> #DIV/0! | D19: =VLOOKUP(C19,L35:M46,2) -> #DIV/0! | K19: A- | L19: 3.7
K20: B | L20: 3
K21: B- | L21: 2.7 | O21: 0
K22: B+ | L22: 3.3 | O22: 16
K23: C | L23: 2 | O23: 0
K24: C- | L24: 1.7 | O24: 0
K25: C+ | L25: 2.3
K26: D | L26: 1
K27: D- | L27: 0.7
K28: D+ | L28: 1.3
K29: F | L29: 0 | N29: =CONCATENATE('CE Curriculum'!H20," ",'CE Curriculum'!I20) | O29: ='CE Curriculum'!J20 -> 0
N30: =CONCATENATE('CE Curriculum'!H21," ",'CE Curriculum'!I21) | O30: ='CE Curriculum'!J21 -> 0
N31: =CONCATENATE('CE Curriculum'!H22," ",'CE Curriculum'!I22) | O31: ='CE Curriculum'!J22 -> 16
L32: 0 | M32: F | O32: ='CE Curriculum'!J23 -> 0
L33: 1.3 | M33: D+ | O33: ='CE Curriculum'!J24 -> 0
L34: 0.7 | M34: D-
L35: 1 | M35: D
L36: 2.3 | M36: C+ | V36: Table 5-1 Curriculum
L37: 1.7 | M37: C-
L38: 2 | M38: C | V38: Year; | Y38: Category (Credit Hours)
L39: 3.3 | M39: B+ | O39: ='CE Curriculum'!J30 -> 0 | V39: Semester or | Y39: Math & Basic Sciences | Z39: Engineering Topics Check if Contains Significant Design (√) | AA39: General Education | AB39: Other
L40: 2.7 | M40: B- | O40: ='CE Curriculum'!J31 -> 17 | V40: Quarter | W40: Course
G41: Reference for Table I-1 | L41: 3 | M41: B | O41: ='CE Curriculum'!J32 -> 0 | W41: (Department, Number, Title)
H42: Credits | I42: Credits | L42: 3.7 | M42: A- | O42: ='CE Curriculum'!J33 -> 0 | V42: Freshman; Fall | W42: =G59 -> GEN 1001 Intro. to Eng. | Z42: =H59 -> 4
G43: Science and Math Topics | H43: Required | I43: Taken | J43: Grade | L43: 4 | M43: A | V43: Freshman; Fall | W43: =G44 -> MTH 1217 Calculus I | Y43: =H44 -> 4
G44: =CONCATENATE('CE Curriculum'!A9," ",'CE Curriculum'!B9) -> MTH 1217 Calculus I | H44: ='CE Curriculum'!C9 -> 4 | I44: =IF('CE Curriculum'!D9=1,H44,0) -> 0 | J44: =IFERROR(VLOOKUP('CE Curriculum'!E9,K18:L29,2),0.001) -> 0.001 | V44: Freshman; Fall | W44: =G50 -> Science* Elective (course here) | Y44: =H50 -> 4
G45: =CONCATENATE('CE Curriculum'!H9," ",'CE Curriculum'!I9) -> MTH 1218 Calculus II | H45: ='CE Curriculum'!J9 -> 4 | I45: =IF('CE Curriculum'!K9=1,H45,0) -> 0 | J45: =IFERROR(VLOOKUP('CE Curriculum'!L9,K18:L29,2),0.001) -> 0.001 | V45: Freshman; Fall | W45: =G78 -> FYW 1050 College Writing | AA45: =H78 -> 4
G46: =CONCATENATE('CE Curriculum'!A18," ",'CE Curriculum'!B18) -> MTH 2219 Calculus III | H46: ='CE Curriculum'!C18 -> 4 | I46: =IF('CE Curriculum'!D18=1,H46,0) -> 0 | J46: =IFERROR(VLOOKUP('CE Curriculum'!E18,K18:L29,2),0.001) -> 0.001 | V46: Freshman; Spring | W46: =G48 -> MTH 1505 Applied Statistics | Y46: =H48 -> 4
G47: =CONCATENATE('CE Curriculum'!H17," ",'CE Curriculum'!I17) -> MTH 2220 Diff. Equations | H47: ='CE Curriculum'!J17 -> 4 | I47: =IF('CE Curriculum'!K17=1,H47,0) -> 0 | J47: =IFERROR(VLOOKUP('CE Curriculum'!L17,K18:L29,2),0.001) -> 0.001 | V47: Freshman; Spring | W47: =G45 -> MTH 1218 Calculus II | Y47: =H45 -> 4
...

Sheet DOUBLE MAJ CHECKLIST
B2: Curriculum Analysis
B3: Curricular | C3: Number of Credits*
B4: Category | C4: Criteria | D4: Table I-1
C5: Requirement | D5: of Self-Study | E5: Actuals | F5: taken
B6: College-level Mathematics and Basic Science | C6: 1 yr (30-32 cr) | D6: 32 | E6: =H56 -> 38 | F6: =I56 -> 0
B7: Engineering Topics | C7: 1.5 yr (45-48 cr) | D7: =32*1.5 -> 48 | E7: =H75 -> 58 | F7: =I75 -> 0
B8: General Education | C8: Inst. Reqmt=44 | D8: 44 | E8: =H91 -> 42 | F8: =I91 -> 0 | G8: CEN 1001 counts for 4 more if taken F08 or later
B9: Please List Below Any Applicable Program Criteria Requirements:
B16: CIVIL ENGINEERING | C16: {=SUMPRODUCT(I59:I74,J59:J74)/I75} -> #DIV/0! | D16: =VLOOKUP(C16,L32:M43,2) -> #DIV/0!
B17: OVERALL | C17: {=(SUMPRODUCT(I44:I54,J44:J54)+SUMPRODUCT(I59:I74,J59:J74)+SUMPRODUCT(I78:I81,J78:J81)+SUMPRODUCT(I85:I88,J85:J88)+I106*J106)/(I56+I75+I91+I106)} -> #DIV/0! | D17: =VLOOKUP(C17,L33:M44,2) -> #DIV/0!
B18: MATH AND SCIENCE | C18: {=(SUMPRODUCT(I44:I48,J44:J48)+SUMPRODUCT(I50:I54,J50:J54))/I56} -> #DIV/0! | D18: =VLOOKUP(C18,L34:M45,2) -> #DIV/0! | K18: A | L18: 4
B19: GENERAL EDUCATION | C19: {=(SUMPRODUCT(I78:I81,J78:J81)+SUMPRODUCT(I85:I88,J85:J88))/I91} -> #DIV/0! | D19: =VLOOKUP(C19,L35:M46,2) -> #DIV/0! | K19: A- | L19: 3.7
K20: B | L20: 3
K21: B- | L21: 2.7 | O21: 0
K22: B+ | L22: 3.3 | O22: 16
K23: C | L23: 2 | O23: 0
K24: C- | L24: 1.7 | O24: 0
K25: C+ | L25: 2.3
K26: D | L26: 1
K27: D- | L27: 0.7
K28: D+ | L28: 1.3
K29: F | L29: 0 | N29: =CONCATENATE('CE Curriculum'!H20," ",'CE Curriculum'!I20) | O29: ='CE Curriculum'!J20 -> 0
N30: =CONCATENATE('CE Curriculum'!H21," ",'CE Curriculum'!I21) | O30: ='CE Curriculum'!J21 -> 0
N31: =CONCATENATE('CE Curriculum'!H22," ",'CE Curriculum'!I22) | O31: ='CE Curriculum'!J22 -> 16
L32: 0 | M32: F | O32: ='CE Curriculum'!J23 -> 0
L33: 1.3 | M33: D+ | O33: ='CE Curriculum'!J24 -> 0
L34: 0.7 | M34: D-
L35: 1 | M35: D
L36: 2.3 | M36: C+ | V36: Table 5-1 Curriculum
L37: 1.7 | M37: C-
L38: 2 | M38: C | V38: Year; | Y38: Category (Credit Hours)
L39: 3.3 | M39: B+ | O39: ='CE Curriculum'!J30 -> 0 | V39: Semester or | Y39: Math & Basic Sciences | Z39: Engineering Topics Check if Contains Significant Design (√) | AA39: General Education | AB39: Other
L40: 2.7 | M40: B- | O40: ='CE Curriculum'!J31 -> 17 | V40: Quarter | W40: Course
G41: Reference for Table I-1 | L41: 3 | M41: B | O41: ='CE Curriculum'!J32 -> 0 | W41: (Department, Number, Title)
H42: Credits | L42: 3.7 | M42: A- | O42: ='CE Curriculum'!J33 -> 0 | V42: Freshman; Fall | W42: =G59 -> GEN 1001 Intro. to Eng. | Z42: =H59 -> 4
G43: Science and Math Topics | H43: Required | L43: 4 | M43: A | V43: Freshman; Fall | W43: =G44 -> MTH 1217 Calculus I | Y43: =H44 -> 4
G44: =CONCATENATE('CE Curriculum'!A9," ",'CE Curriculum'!B9) -> MTH 1217 Calculus I | H44: ='CE Curriculum'!C9 -> 4 | V44: Freshman; Fall | W44: =G50 -> Science* Elective (course here) | Y44: =H50 -> 4
G45: =CONCATENATE('CE Curriculum'!H9," ",'CE Curriculum'!I9) -> MTH 1218 Calculus II | H45: ='CE Curriculum'!J9 -> 4 | V45: Freshman; Fall | W45: =G78 -> FYW 1050 College Writing | AA45: =H78 -> 4
G46: =CONCATENATE('CE Curriculum'!A18," ",'CE Curriculum'!B18) -> MTH 2219 Calculus III | H46: ='CE Curriculum'!C18 -> 4 | V46: Freshman; Spring | W46: =G48 -> MTH 1505 Applied Statistics | Y46: =H48 -> 4
G47: =CONCATENATE('CE Curriculum'!H17," ",'CE Curriculum'!I17) -> MTH 2220 Diff. Equations | H47: ='CE Curriculum'!J17 -> 4 | V47: Freshman; Spring | W47: =G45 -> MTH 1218 Calculus II | Y47: =H45 -> 4
...
