Workbook
Name Currency_of_reported_figures: [1]ENGLISH!$G$127

Sheet Cover letter

Sheet ENGLISH
E2: ACI Airport Economics Survey 2013
F6: Please submit the completed questionnaire before August 30th 2013 to: | N6: econ@aci.aero
F7: Tel: +1 514 373 1229 | I7: Fax: +1 514 373 1201
F9: INSTRUCTIONS:
F10: The following convention should be used in reporting values in this questionnaire:
F11: — | G11: Please report actual values only (no abridged values);
F12: — | G12: When actual observed values are not available, produce estimated values in italics;
F13: — | G13: When the actual reported value is nil (zero), include the value "0" in the relevant cell;
F14: — | G14: Only when the actual value or an estimate is not available, treat the data item as missing and leave the cell blank.
F16: Note: Certain questionnaire items require respondents to use check boxes and drop down lists. To respond to these items, please click on the appropriate option.
F17: The items with these features include the corresponding drop lists of unit measures to the right of the reported figures in Section 3.1, check boxes in Section 5
F18: and drop lists with predefined options in Sections 2, 4 and 10
F20: ********Please do not alter this questionnaire form by adding columns, rows and/or deleting items.********
C24: Part 1 - Contact Information
L25: 3-letter IATA Airport Code - If the reported figures pertain to more than
C26: Airport Name (Please complete one separate form for EACH airport being reported) | L26: one airport, please list each airport separated by "/" (e.g. XXX/YYY/ZZZ)
C28: Contact person | L28: Telephone Number
C30: Title | L30: Email Address
C35: Part 2 - General Information
C37: ="Total Traffic for Calendar year 2012"&" "&"("&L27&")" -> Total Traffic for Calendar year 2012 ()
C39: 2.1 | D39: Passengers: | J39: 2.5 | K39: Financial Year (please select):
C41: 2.2 | D41: Cargo (metric tons): | J41: 2.6 | K41: Financial figures submitted in:
C43: 2.3 | D43: Movements | J43: 2.7 | K43: Reporting Currency (please select):
C45: 2.4 | D45: WLU: | F45: =IF(AND(ISNUMBER(F39), ISNUMBER(F41)), (F39+10*F41), "") | J45: 2.8 | K45: Suggested exchange rate: 1 USD = | Q45: =IF(ISTEXT(O43), O43, "")
D46: Work Load Unit is equal to 1 passenger or 100 kg of cargo
C50: Part 3.1 - Infrastructure Size (Area) | M50: Unit of measure
M51: (please select)
C52: 3.1.1 | D52: Total Airport Site Area
D53: of which:
C54: 3.1.1.1 | D54: Airside Area
C55: 3.1.1.2 | D55: Landside area
C57: 3.1.2 | D57: Passenger Terminal(s) Building(s) Area
D58: of which:
C59: 3.1.2.1 | D59: Airside Area
C60: 3.1.2.2 | D60: Landside area
C62: 3.1.3 | D62: Cargo Terminal(s) Building(s) Area
C64: 3.1.4 | D64: Commercial Activity Area
D65: (inside and outside the terminal building(s))
D66: of which:
C67: 3.1.4.1 | D67: Food & beverage
...

Sheet FRANÇAIS
E2: ACI Enquête sur l'Économie des Aéroports 2013
F6: Nous vous prions de soumettre le questionnaire dûment rempli avant le 30 Août 2013 à l'adresse de: | P6: econ@aci.aero
F7: Tél: +1 514 373 1229 | I7: Fax: +1 514 373 1201
F9: INSTRUCTIONS:
F10: La convention suivante doit être utilisée pour le rapport de valeurs dans ce questionnaire:
F11: — | G11: Signaler les valeurs réelles seulement (pas de valeurs abrégées);
F12: — | G12: Si les valeurs réelles sont pas disponibles, prière d'indiquer des valeurs estimées en italique;
F13: — | G13: Lorsque la valeur réelle est nulle (zéro), indiquer la valeur;
F14: — | G14: Une cellule doit rester vide seulement au cas où la valeur réelle ou une estimation n'est pas disponible
F16: Remarque: Certains éléments du questionnaire exigent à cocher des cases d'option et à faire des choix des listes déroulantes.
F17: Pour répondre à ces articles, s'il vous plaît choisir l'option appropriée. Les articles avec ces caractéristiques comprennent les listes déroulantes des unités de
F18: mesure vers la droite dans la Section 3.1, des cases à cocher dans la Section 5, des listes déroulantes dans les Sections 2, 4 et 10.
F20: ********Prière de ne pas modifier cette questionnaire en ajoutant ou supprimant des colonnes, des lignes et/ou des éléments********
C24: Partie 1 - Informations de Contact
L25: Le code AITA (3 lettres) - Nous vous prions de séparer chaque aéroport par un "/"
C26: Nom de l'Aéroport (Veuillez compléter un formulaire pour chaque aéroport): | L26: au cas où les chiffres indiqués représentent plusieurs aéroports (ex. XXX/YYY/ZZZ)
C28: Personne à contacter | L28: Numéro de Téléphone
C30: Titre | L30: Adresse courriel
C35: Partie 2 - Informations Générales
C37: ="Trafic total pour l'année 2012"&" "&"("&L27&")" -> Trafic total pour l'année 2012 ()
C39: 2.1 | D39: Passagers: | J39: 2.5 | K39: Année Budgétaire (choisir une option):
C41: 2.2 | D41: Cargo (en tonnes): | J41: 2.6 | K41: Les chiffres financiers soumis en:
C43: 2.3 | D43: Mouvements | J43: 2.7 | K43: La monnaie de présentation (choisir):
C45: 2.4 | D45: L'unité WLU: | F45: =IF(AND(ISNUMBER(F39), ISNUMBER(F41)), (F39+10*F41), "") | J45: 2.8 | K45: Taux de change suggéré: | N45: 1 USD = | Q45: =IF(ISTEXT(O43), O43, "")
D46: Work Load Unit (WLU) est une unité qui correspond à un passager ou 0,1 tonne de fret
C50: Partie 3.1 - Infrastructure (Superficie) | M50: Unité de mesure
M51: (sélectionner)
C52: 3.1.1 | D52: Superficie totale du site de l'aéroport
D53: dont:
C54: 3.1.1.1 | D54: Zone aérienne (ex: côté piste)
C55: 3.1.1.2 | D55: Zone terrestre (ex: côté ville)
C57: 3.1.2 | D57: Superficie totale des terminaux de passagers
D58: dont:
C59: 3.1.2.1 | D59: Zone aérienne
C60: 3.1.2.2 | D60: Zone terrestre
C62: 3.1.3 | D62: Superficie totale des terminaux de frets
C64: 3.1.4 | D64: Zone d'activité commerciale
D65: (à l'intérieur et à l'extérieur des bâtiments du terminal)
D66: dont:
C67: 3.1.4.1 | D67: Aliments & boissons
...

Sheet ESPAÑOL
E2: ACI Encuesta Económica 2013
F6: Por favor, envíe el cuestionario completo antes del 30 de agosto de 2013 a: | O6: econ@aci.aero
F7: Tel: +1 514 373 1229 | I7: Fax: +1 514 373 1201
F9: INSTRUCCIONES:
F10: Las siguientes convenciones deben utilizarse para reportar los valores en este cuestionario:
F11: — | G11: Por favor reporte los valores reales (no valores abreviados);
F12: — | G12: Cuando los valores reales no estén disponibles, indique los valores estimados en cursiva;
F13: — | G13: Cuando el valor real es cero, incluya el valor "0" en la celda correspondiente;
F14: — | G14: Solamente cuando el valor real or el estimado no esté disponible, trate el dato como no-disponible y deje la celda en blanco.
F16: Nota: Algunas preguntas de este cuestionario se responden marcando la casilla o seleccionando la opción correcta del menú desplegable. Por favor, responda según sea el caso.
F19: ********Por favor no altere este cuestionario añadiendo columnas, filas y/o eliminando preguntas********
C24: Parte 1 - Información de contacto
L25: Código IATA de 3 letras - Si los datos corresponden a más de un aeropuerto,
C26: Nombre del aeropuerto (Por favor llene un formulario/cuestionario por CADA aeropuerto) | L26: liste cada aeropuerto separados con "/" (e.g. XXX/YYY/ZZZ)
C28: Persona de contacto | L28: Número de teléfono
C30: Título | L30: Dirección de E-mail
C35: Parte 2 - Información General
C37: ="El tráfico total para el año calendario 2012"&" "&"("&L27&")" -> El tráfico total para el año calendario 2012 ()
C39: 2.1 | D39: Pasajeros: | J39: 2.5 | K39: Año económico (por favor, seleccione):
C41: 2.2 | D41: Carga (toneladas): | J41: 2.6 | K41: Las cifras financieras presentadas:
C43: 2.3 | D43: Movimientos: | J43: 2.7 | K43: Moneda de Referencia (seleccione):
C45: 2.4 | D45: WLU: | F45: =IF(AND(ISNUMBER(F39), ISNUMBER(F41)), (F39+10*F41), "") | J45: 2.8 | K45: Tipo de cambio sugerido: | N45: 1 USD = | Q45: =IF(ISTEXT(O43), O43, "")
D46: WLU es igual a 1 pasajero o 100 kg de carga
C50: Parte 3.1 - Tamaño de la Infraestructura (Área) | M50: Unidad de medida
M51: (seleccione)
C52: 3.1.1 | D52: Área Total del Aeropuerto
D53: de las cuales:
C54: 3.1.1.1 | D54: Lado aire
C55: 3.1.1.2 | D55: Lado tierra
C57: 3.1.2 | D57: Área total de las terminales de pasajeros
D58: de las cuales:
C59: 3.1.2.1 | D59: Lado aire
C60: 3.1.2.2 | D60: Lado tierra
C62: 3.1.3 | D62: Área total de las terminales de carga
C64: 3.1.4 | D64: Área dedicada a las actividades comerciales
D65: (dentro y fuera de los edificios terminales)
D66: de las cuales:
C67: 3.1.4.1 | D67: Zona de restauración (F&B)
C68: 3.1.4.2 | D68: Área de venta al por menor
D69: de las cuales:
...

Sheet glossary
B1: Available in English only
B3: Aircraft Movement – An aircraft take-off or landing at an airport. For
B4: airport traffic purposes one arrival and one departure are counted as
B5: two movements, measured over the course of a year.
B7: Capital Expenditure - (CAPEX) – Funds used by a airport operator to acquire
B8: or upgrade physical assets such as property, industrial buildings or equipment.
B9: This type of outlay is made by companies to maintain or increase the scope of their
B10: operations and allocated for specific time period. These expenditures can include
B11: everything from repairing a roof to building a new terminal building or runway.
B13: Cash – In accounting contexts, cash on hand (e.g., petty cash and cash not yet
B14: deposited to the bank) and demand deposits held in banks and similar accounts
B15: that can be used in payment of obligations.In accounting contexts, cash on hand
... B144: Terminal - the part of an aerodrome used for embarking or disembarking passengers or cargo.
C145: Domestic: terminal used primarily for domestic flights
C146: (i.e. having exclusively domestic stages).
C147: International: terminal used primarily for international flights
C148: (i.e. flights that contain one or more international flight stages).
B150: Total Operating Revenue – The sum of Aeronautical and Nonaeronautical
B151: operating revenue.
B153: Weighted-average cost of capital – A weighted average of the after-tax required rates of
B154: return on a company’s common stock, preferred stock, and long-term debt, where the weights
B155: are the fraction of each source of financing in the company’s target capital structure.

Sheet for internal use
A1: 1 | B1: 1 | C1: 1 | D1: 1 | E1: 1 | F1: 1 | G1: 1 | H1: 1 | I1: 1 | J1: 1 | K1: 1 | L1: 1 | M1: 2 | N1: 2 | O1: 2 | P1: 2 | Q1: 2 | R1: 2 | S1: 2 | T1: 2 | U1: 3.1 | W1: 3.1 | Y1: 3.1 | AA1: 3.1 | AC1: 3.1 | AE1: 3.1 | AG1: 3.1 | AI1: 3.1 | AK1: 3.1 | AM1: 3.1 | AO1: 3.1 | AQ1: 3.2 | AR1: 3.2 | AS1: 3.2 | AT1: 3.2 | AU1: 3.2 | AV1: 3.2 | AW1: 3.2 | AX1: 3.2 | AY1: 3.2 | AZ1: 3.2 | BA1: 3.2 | BB1: 4 | BC1: 4 | BD1: 4 | BE1: 4 | BF1: 4 | BG1: 4 | BH1: 5 | BI1: 5 | BJ1: 5 | BK1: 5 | BL1: 5 | BM1: 5 | BN1: 5 | BO1: 5 | BP1: 5 | BQ1: 5 | BR1: 5 | BS1: 5 | BT1: 5 | BU1: 5 | BV1: 5 | BW1: 5 | BY1: 5 | BZ1: 5 | CA1: 5 | CB1: 5 | CC1: 5 | CD1: 5 | CE1: 5 | CF1: 5 | CG1: 5 | CH1: 5 | CI1: 5 | CJ1: 5 | CK1: 5 | CL1: 5 | CM1: 5 | CN1: 5 | CO1: 5 | CP1: 5 | CQ1: 5 | CR1: 5 | CS1: 5 | CT1: 5 | CU1: 5 | CV1: 5 | CW1: 5 | CX1: 5 | CY1: 5 | CZ1: 5 | DA1: 5 | DB1: 5 | DC1: 5 | DD1: 5 | DE1: 5 | DF1: 5 | DG1: 5 | DH1: 5 | DI1: 5 | DJ1: 5 | DK1: 5 | DL1: 5 | DM1: 5 | DN1: 5 | DO1: 5 | DP1: 5 | DQ1: 5 | DR1: 5 | DS1: 6 | DT1: 6 | DU1: 6 | DV1: 6 | DW1: 6 | DX1: 6 | DY1: 6 | DZ1: 6 | EA1: 6 | EB1: 6 | EC1: 6 | ED1: 6 | EE1: 6 | EF1: 6 | EG1: 6 | EH1: 6 | EI1: 6 | EJ1: 6 | EK1: 6 | EL1: 6 | EM1: 6 | EN1: 6 | EO1: 6 | EP1: 6 | EQ1: 6 | ER1: 6 | ES1: 6 | ET1: 6 | EU1: 6 | EV1: 6 | EW1: 6 | EX1: 6 | EY1: 6 | EZ1: 6 | FA1: 6 | FB1: 6 | FC1: 6 | FD1: 7 | FE1: 7 | FF1: 7 | FG1: 7 | FH1: 7 | FI1: 7 | FJ1: 7 | FK1: 7 | FL1: 7 | FM1: 7 | FN1: 7 | FO1: 7 | FP1: 8 | FQ1: 8 | FR1: 8 | FS1: 8 | FT1: 8 | FU1: 8 | FV1: 8 | FW1: 8 | FX1: 8 | FY1: 8 | FZ1: 8 | GA1: 8 | GB1: 8 | GC1: 8 | GD1: 9 | GE1: 9 | GF1: 9 | GG1: 9 | GH1: 9 | GI1: 9 | GJ1: 9 | GK1: 9 | GL1: 9 | GM1: 9 | GN1: 9 | GO1: 9 | GP1: 10 | GQ1: 10 | GR1: 10 | GS1: 10 | GT1: 10 | GU1: 11 | GV1: 11 | GW1: 11 | GX1: 11 | GY1: 11 | GZ1: 11 | HA1: 11 | HB1: 11 | HC1: 12 | HD1: 12 | HE1: 13 | HF1: 13 | HG1: 13 | HH1: 13 | HI1: 13 | HJ1: 13 | HK1: 13 | HL1: 14 | HM1: 14 | HQ1: 6 (2011) | HR1: 6 (2011) | HS1: 6 (2011) | HT1: 6 (2011) | HU1: 6 (2011) | HV1: 6 (2011) | HW1: 6 (2011) | HX1: 6 (2011) | HY1: 6 (2011) | HZ1: 6 (2011) | IA1: 6 (2011) | IB1: 6 (2011) | IC1: 6 (2011) | ID1: 6 (2011) | IE1: 6 (2011) | IF1: 6 (2011) | IG1: 6 (2011) | IH1: 6 (2011) | II1: 6 (2011) | IJ1: 6 (2011) | IK1: 6 (2011) | IL1: 6 (2011) | IM1: 6 (2011) | IN1: 6 (2011) | IO1: 6 (2011) | IP1: 6 (2011) | IQ1: 6 (2011) | IR1: 6 (2011) | IS1: 6 (2011) | IT1: 6 (2011) | IU1: 6 (2011) | IV1: 6 (2011) | IW1: 6 (2011) | IX1: 6 (2011) | IY1: 6 (2011) | IZ1: 6 (2011) | JA1: 6 (2011) | JB1: 7 (2011) | JC1: 7 (2011) | JD1: 7 (2011) | JE1: 7 (2011) | JF1: 7 (2011) | JG1: 7 (2011) | JH1: 7 (2011) | JI1: 7 (2011) | JJ1: 7 (2011) | JK1: 7 (2011) | JL1: 7 (2011) | JM1: 7 (2011) | JN1: 8 (2011) | JO1: 8 (2011) | JP1: 8 (2011) | JQ1: 8 (2011) | JR1: 8 (2011) | JS1: 8 (2011) | JT1: 8 (2011) | JU1: 8 (2011) | JV1: 8 (2011) | JW1: 8 (2011) | JX1: 8 (2011) | JY1: 8 (2011) | JZ1: 8 (2011) | KA1: 8 (2011) | KB1: 9 (2011) | KC1: 9 (2011) | KD1: 9 (2011) | KE1: 9 (2011) | KF1: 9 (2011) | KG1: 9 (2011) | KH1: 9 (2011) | KI1: 9 (2011) | KJ1: 9 (2011) | KK1: 9 (2011) | KL1: 9 (2011) | KM1: 9 (2011) | KN1: 10 (2011) | KO1: 11 (2011) | KP1: 11 (2011) | KQ1: 11 (2011) | KR1: 11 (2011) | KS1: 11 (2011) | KT1: 11 (2011) | KU1: 11 (2011) | KV1: 11 (2011) | KW1: 12 (2011) | KX1: 12 (2011) | KY1: 13 (2011) | KZ1: 13 (2011) | LA1: 13 (2011) | LB1: 13 (2011) | LC1: 13 (2011) | LD1: 13 (2011) | LE1: 13 (2011) | LF1: 14 (2011) | LG1: 14 (2011)
A2: Region | B2: City | C2: Country | D2: Operator | E2: Size Category | F2: Code | G2: Count | H2: Airport Name | I2: Contact person | J2: Title | K2: Tel. Number | L2: Email Address | M2: 2.1 Passengers: | N2: 2.2 Cargo (metric tons): | O2: 2.3 Movements | P2: 2.4 WLU: | Q2: 2.5 Financial Year (please select): | R2: 2.6 Financial figures submitted in: | S2: 2.7 Reporting Currency (please select): | T2: 2.8 Suggested exchange rate: | U2: 3.1.1 Total Airport Site Area | W2: 3.1.1.1 Airside Area | Y2: 3.1.1.2 Landside area | AA2: 3.1.2 Passenger Terminal(s) Building(s) Area | AC2: 3.1.2.1 Airside Area | AE2: 3.1.2.2 Landside area | AG2: 3.1.3 Cargo Terminal(s) Building(s) Area | AI2: 3.1.4 Commercial Activity Area | AK2: 3.1.4.1 Food & beverage | AM2: 3.1.4.2 Retail Activity Area | AO2: 3.1.4.2.1 Duty Free Area | AQ2: 3.2.1 Runways (paved landing strips) | AR2: 3.2.2 Contact gates with air bridge (jet bridge) | AS2: 3.2.3 Remote stands (B737-800 or equivalent) | AT2: 3.2.4 Passenger terminals | AU2: 3.2.5 Cargo terminals | AV2: 3.2.6 Passenger check-in desks/counters | AW2: 3.2.7 Self service kiosks operated by airport | AX2: 3.2.8 Individual car parking spaces | AY2: 3.2.9 Retail stores / shops / boutiques | AZ2: 3.2.9.1 Duty-Free shops | BA2: 3.2.10 Restaurants / cafés and other F&B outlets | BB2: 4.1 Pricing regulation | BC2: 4.2 Economic Oversigght | BD2: 4.3 Ownership Structure | BE2: 4.4 Private participation | BF2: 4.5 WACC | BG2: 4.6 Incentive scheme | BH2: 5.1 Total personnel employed by airport operator | Headcount | BI2: 5.1 Total personnel employed by airport operator | FTE | BJ2: 5.1.1 Management | Insourced | BK2: 5.1.2 Ground handling services: | Insourced | BL2: 5.1.2.1 Passenger handling services | Insourced | BM2: 5.1.2.2 Ramp handling services | Insourced | BN2: 5.1.2.3 Cargo handling services | Insourced | BO2: 5.1.3 Rescue and fire service | Insourced | BP2: 5.1.4 Car parking services | Insourced | BQ2: 5.1.5 Cleaning services | Insourced | BR2: 5.1.6 Maintenance services | Insourced | BS2: 5.1.7 Air traffic control services | Insourced | BT2: 5.1.8 Passenger security services | Insourced | BU2: 5.1.8.1 Other security (e.g. perimeter and cargo security) | Insourced | BV2: 5.1.10 Concession services (shops, F&B, etc.) | Insourced | BW2: 5.1.11 Runway, taxiway, apron operations |Insourced | BX2: 5.1.12 Other |Insourced | BY2: 5.1.1 Management | Outsourced | BZ2: 5.1.2 Ground handling services: | Outsourced | CA2: 5.1.2.1 Passenger handling services | Outsourced | CB2: 5.1.2.2 Ramp handling services | Outsourced | CC2: 5.1.2.3 Cargo handling services | Outsourced | CD2: 5.1.3 Rescue and fire service | Outsourced | CE2: 5.1.4 Car parking services | Outsourced | CF2: 5.1.5 Cleaning services | Outsourced | CG2: 5.1.6 Maintenance services | Outsourced | CH2: 5.1.7 Air traffic control services | Outsourced | CI2: 5.1.8 Passenger security services | Outsourced | CJ2: 5.1.8.1 Other security (e.g. perimeter and cargo security) | Outsourced | CK2: 5.1.10 Concession services (shops, F&B, etc.) | Outsourced | CL2: 5.1.11 Runway, taxiway, apron operations | Outsourced | CM2: 5.1.12 Other | Outsorced | CN2: 5.1.1 Management | Headcount | CO2: 5.1.2 Ground handling services: | Headcount | CP2: 5.1.2.1 Passenger handling services | Headcount | CQ2: 5.1.2.2 Ramp handling services | Headcount | CR2: 5.1.2.3 Cargo handling services | Headcount | CS2: 5.1.3 Rescue and fire service | Headcount | CT2: 5.1.4 Car parking services | Headcount | CU2: 5.1.5 Cleaning services | Headcount | CV2: 5.1.6 Maintenance services | Headcount | CW2: 5.1.7 Air traffic control services | Headcount | CX2: 5.1.8 Passenger security services | Headcount | CY2: 5.1.8.1 Other security (e.g. perimeter and cargo security) | Headcount | CZ2: 5.1.10 Concession services (shops, F&B, etc.) | Headcount | DA2: 5.1.11 Runway, taxiway, apron operations | Headcount | DB2: 5.1.12 Other | Headcount | DC2: 5.1.1 Management | FTE | DD2: 5.1.2 Ground handling services: | FTE | DE2: 5.1.2.1 Passenger handling services | FTE | DF2: 5.1.2.2 Ramp handling services | FTE | DG2: 5.1.2.3 Cargo handling services | FTE | DH2: 5.1.3 Rescue and fire service | FTE | DI2: 5.1.4 Car parking services | FTE | DJ2: 5.1.5 Cleaning services | FTE | DK2: 5.1.6 Maintenance services | FTE | DL2: 5.1.7 Air traffic control services | FTE | DM2: 5.1.8 Passenger security services | FTE | DN2: 5.1.8.1 Other security (e.g. perimeter and cargo security) | FTE | DO2: 5.1.10 Concession services (shops, F&B, etc.) | FTE | DP2: 5.1.11 Runway, taxiway, apron operations | FTE | DQ2: 5.1.12 Other | FTE | DR2: 5.2 Total number of people working at the airport | DS2: 6.1 Total Airport Revenue (Sum 6.1.1, 6.1.2, 6.1.3) | DT2: 6.1.1 Operating Aeronautical Revenue (sum 6.1.1.1 -6.1.1.12, 6.1.1.13-6.1.1.16) | DU2: 6.1.1.1 Landing charges | DV2: 6.1.1.2 Lighting surcharges | DW2: 6.1.1.3 Noise & other environmental charges | DX2: 6.1.1.4 Navaid charges | DY2: 6.1.1.5 Parking charges | DZ2: 6.1.1.6 Boarding bridge charges | EA2: 6.1.1.7 Passenger charges (excluding AIF or similar) | EB2: 6.1.1.8 Transfer / transit charges | EC2: 6.1.1.9 Security charges | ED2: 6.1.1.10 Cargo (or freight) charges | EE2: 6.1.1.11 Fueling charges | EF2: 6.1.1.12 Ground handling services (excluding fuel charges) | EG2: 6.1.1.12.1 Ground handling infrastructure (if additional to 6.1.1.4) | EH2: 6.1.1.13 Airport improvement fees - AIF (or Passenger facility charge) | EI2: 6.1.1.14 Utility recharges (e.g. water, electricity, etc.) | EJ2: 6.1.1.15 Terminal rentals paid by airlines for space utilization | EK2: 6.1.1.16 Other (please specify in text box below any item >3% of total income) | EL2: 6.1.1.16 Other TEXT | EM2: 6.1.2 Operating Non-Aeronautical Revenue (sum 6.1.2.1 - 6.1.2.7) | EN2: 6.1.2.1 Retail concessions | EO2: 6.1.2.1.1Duty Free concessions | EP2: 6.1.2.2 Food & Beverage | EQ2: 6.1.2.3 Car parking | ER2: 6.1.2.4 Rental car concessions | ES2: 6.1.2.5 Property & real estate income or rent | ET2: 6.1.2.6 Advertising | EU2: 6.1.2.7 Other (please specify in the text box below any item >3%) | EV2: 6.1.2.7 Other TEXT | EW2: 6.1.3 Non-Operating Revenue (sum 6.1.3.1-6.1.3.4) | EX2: 6.1.3.1 Interest income | EY2: 6.1.3.2 Subsidies / Grants | EZ2: 6.1.3.3 Asset Divestments | FA2: 6.1.3.4 Other (please specify in text box any item >3%) | FB2: 6.1.3.4 Other TEXT | FC2: 6.1.4 Comments (please type in the box below): | FD2: 7.1 Total Operating Expenses (sum 7.1.1 - 7.1.9) | FE2: 7.1.1 Personnel expenses (salaries and benefits) | FF2: 7.1.2 Contracted services (cost of services paid to third parties) | FG2: 7.1.3 Materials, equipment, supplies (excluding maintenance/contracted serv.) | FH2: 7.1.4 Communications, utilities, energy & waste | FI2: 7.1.5 Insurance, claims, settlements | FJ2: 7.1.6 Maintenance (excluding contracted services) | FK2: 7.1.7 Lease, rent, concession fee payments | FL2: 7.1.8 General and administrative expenses (excluding personnel) | FM2: 7.1.9 Other - (please specify in text box any item >3% of total expenses): | FN2: 7.1.9 Other TEXT | FO2: 7.2 Comments (please type in the box below): | FP2: 8.1 Total Airport Income | FQ2: 8.1.1 Operating Aeronautical Income | FR2: 8.1.2 Operating Non-Aeronautical Income | FS2: 8.1.3 Non-Operating Income | FT2: 8.2 Total Operating Expenses | FU2: 8.3 Operating Surplus/Deficit (EBITDA) | FV2: 8.4 Capital Costs | FW2: 8.4.1 Interest and dividends paid to third parties | FX2: 8.4.2 Depreciation or/and amortization of property, plant & equipment | FY2: 8.4.3 Other capital costs (please specify below) | FZ2: 8.4.3 Other capital costs TEXT | GA2: 8.5 Taxes & Other Fees | GB2: 8.6 Net Profit / Loss | GC2: 8.7 Comments (please type in the box below): | GD2: 9.1 Total Assets | GE2: 9.1.1 Current Assets | GF2: 9.1.1.1 Cash and equivalent | GG2: 9.1.1.2 Other | GH2: 9.1.2 Non Current Assets | GI2: 9.1.2.1 Fixed assets | GJ2: 9.1.2.2 Other | GK2: 9.2 Total Liabilities | GL2: 9.2.1 Current liabilities | GM2: 9.2.1 Non-current liabilities | GN2: 9.3 Net Assets (9.1 - 9.2) | GO2: 9.4 Accumulated depreciation of fixed assets (9.1.2.1) | GP2: 10.1 Debt outstanding | GQ2: 10.2 What is the credit rating of financial instruments issued by the airport company? Moody's: | GR2: 10.2 What is the credit rating of financial instruments issued by the airport company? S&P: | GS2: 10.2 What is the credit rating of financial instruments issued by the airport company? Fitch: | GT2: 10.2 What is the credit rating of financial instruments issued by the airport company? In words: | GU2: 11.1 Total Operating Expenses (Total corresponds to 7.1) | GV2: 11.1.1 Security | GW2: 11.1.2 Airfield Operations & Maintenance (including firefighting & winter services) | GX2: 11.1.3 Terminal, Landside Operations & Maintenance (including commercial operations) | GY2: 11.1.4 Administration | GZ2: 11.1.5 Sales & Marketing | HA2: 11.1.6 Other - (please specify in text box any item >5% of total operating expenses) | HB2: 11.1.6 Other - TEXT | HC2: 12.1 Taxes levied on passengers | HD2: 12.2 Taxed levied on airlines | HE2: 13.1 Airport Capital Expenditure (CAPEX) | HF2: 13.1.1 Purchase of property, plant & equipment | HG2: 13.1.2 Construction expenses | HH2: 13.1.3 Purchase of other goods & services | HI2: 13.1.4 Other capital expenditure items (please specify below) | HJ2: 13.1.4 Other capital expenditure items TEXT | HK2: 13.2 Comments (please type in the box below): | HL2: 14.1 Return On Invested Capital (ROIC) (%) | HM2: 14.2 Return on Capital Employed (ROCE) (%) | HQ2: 6.1 Total Airport Revenue (Sum 6.1.1, 6.1.2, 6.1.3) | HR2: 6.1.1 Operating Aeronautical Revenue (sum 6.1.1.1 -6.1.1.12, 6.1.1.13-6.1.1.16) | HS2: 6.1.1.1 Landing charges | HT2: 6.1.1.2 Lighting surcharges | HU2: 6.1.1.3 Noise & other environmental charges | HV2: 6.1.1.4 Navaid charges | HW2: 6.1.1.5 Parking charges | HX2: 6.1.1.6 Boarding bridge charges | HY2: 6.1.1.7 Passenger charges (excluding AIF or similar) | HZ2: 6.1.1.8 Transfer / transit charges | IA2: 6.1.1.9 Security charges | IB2: 6.1.1.10 Cargo (or freight) charges | IC2: 6.1.1.11 Fueling charges | ID2: 6.1.1.12 Ground handling services (excluding fuel charges) | IE2: 6.1.1.12.1 Ground handling infrastructure (if additional to 6.1.1.4) | IF2: 6.1.1.13 Airport improvement fees - AIF (or Passenger facility charge) | IG2: 6.1.1.14 Utility recharges (e.g. water, electricity, etc.) | IH2: 6.1.1.15 Terminal rentals paid by airlines for space utilization | II2: 6.1.1.16 Other (please specify in text box below any item >3% of total income) | IJ2: 6.1.1.16 Other TEXT | IK2: 6.1.2 Operating Non-Aeronautical Revenue (sum 6.1.2.1 - 6.1.2.7) | IL2: 6.1.2.1 Retail concessions | IM2: 6.1.2.1.1 of which: Duty Free concessions | IN2: 6.1.2.2 Food & Beverage | IO2: 6.1.2.3 Car parking | IP2: 6.1.2.4 Rental car concessions | IQ2: 6.1.2.5 Property & real estate income or rent | IR2: 6.1.2.6 Advertising | IS2: 6.1.2.7 Other (please specify in the text box below any item >3%) | IT2: 6.1.2.7 Other TEXT | IU2: 6.1.3 Non-Operating Revenue (sum 6.1.3.1-6.1.3.4) | IV2: 6.1.3.1 Interest income | IW2: 6.1.3.2 Subsidies / Grants | IX2: 6.1.3.3 Asset Divestments | IY2: 6.1.3.4 Other (please specify in text box any item >3%) | IZ2: 6.1.3.4 Other TEXT | JA2: 6.1.4 Comments (please type in the box below): | JB2: 7.1 Total Operating Expenses (sum 7.1.1 - 7.1.9) | JC2: 7.1.1 Personnel expenses (salaries and benefits) | JD2: 7.1.2 Contracted services (cost of services paid to third parties) | JE2: 7.1.3 Materials, equipment, supplies (excluding maintenance/contracted serv.) | JF2: 7.1.4 Communications, utilities, energy & waste | JG2: 7.1.5 Insurance, claims, settlements | JH2: 7.1.6 Maintenance (excluding contracted services) | JI2: 7.1.7 Lease, rent, concession fee payments | JJ2: 7.1.8 General and administrative expenses (excluding personnel) | JK2: 7.1.9 Other - (please specify in text box any item >3% of total expenses): | JL2: 7.1.9 Other TEXT | JM2: 7.2 Comments (please type in the box below): | JN2: 8.1 Total Airport Income | JO2: 8.1.1 Operating Aeronautical Income | JP2: 8.1.2 Operating Non-Aeronautical Income | JQ2: 8.1.3 Non-Operating Income | JR2: 8.2 Total Operating Expenses | JS2: 8.3 Operating Surplus/Deficit (EBITDA) | JT2: 8.4 Capital Costs | JU2: 8.4.1 Interest and dividends paid to third parties | JV2: 8.4.2 Depreciation or/and amortization of property, plant & equipment | JW2: 8.4.3 Other capital costs (please specify below) | JX2: 8.4.3 Other capital costs TEXT | JY2: 8.5 Taxes & Other Fees | JZ2: 8.6 Net Profit / Loss | KA2: 8.7 Comments (please type in the box below): | KB2: 9.1 Total Assets | KC2: 9.1.1 Current Assets | KD2: 9.1.1.1 Cash and equivalent | KE2: 9.1.1.2 Other | KF2: 9.1.2 Non Current Assets | KG2: 9.1.2.1 Fixed assets | KH2: 9.1.2.2 Other | KI2: 9.2 Total Liabilities | KJ2: 9.2.1 Current liabilities | KK2: 9.2.1 Non-current liabilities | KL2: 9.3 Net Assets (9.1 - 9.2) | KM2: 9.4 Accumulated depreciation of fixed assets (9.1.2.1) | KN2: 10.1 Debt outstanding | KO2: 11.1 Total Operating Expenses (Total corresponds to 7.1) | KP2: 11.1.1 Security | KQ2: 11.1.2 Airfield Operations & Maintenance (including firefighting & winter services) | KR2: 11.1.3 Terminal, Landside Operations & Maintenance (including commercial operations) | KS2: 11.1.4 Administration | KT2: 11.1.5 Sales & Marketing | KU2: 11.1.6 Other - (please specify in text box any item >5% of total operating expenses) | KV2: 11.1.6 Other - TEXT | KW2: 12.1 Taxes levied on passengers | KX2: 12.2 Taxed levied on airlines | KY2: 13.1 Airport Capital Expenditure (CAPEX) | KZ2: 13.1.1 Purchase of property, plant & equipment | LA2: 13.1.2 Construction expenses | LB2: 13.1.3 Purchase of other goods & services | LC2: 13.1.4 Other capital expenditure items (please specify below) | LD2: 13.1.4 Other capital expenditure items TEXT | LE2: 13.2 Comments (please type in the box below): | LF2: 14.1 Return On Invested Capital (ROIC) (%) | LG2: 14.2 Return on Capital Employed (ROCE) (%)
F3: =IF(ISBLANK(ENGLISH!L27), "", ENGLISH!L27) | G3: =IF(LEN(F3)=3, "1", "") | H3: =IF(ISBLANK(ENGLISH!C27), "", ENGLISH!C27) | I3: =IF(ISBLANK(ENGLISH!C29), "", ENGLISH!C29) | J3: =IF(ISBLANK(ENGLISH!C31), "", ENGLISH!C31) | K3: =IF(ISBLANK(ENGLISH!L29), "", ENGLISH!L29) | L3: =IF(ISBLANK(ENGLISH!L31), "", ENGLISH!L31) | M3: =IF(ISBLANK(ENGLISH!F39), "", ENGLISH!F39) | N3: =IF(ISBLANK(ENGLISH!F41), "", ENGLISH!F41) | O3: =IF(ISBLANK(ENGLISH!F43), "", ENGLISH!F43) | P3: =IF(ISBLANK(ENGLISH!F45), "", ENGLISH!F45) | Q3: =IF(ISBLANK(ENGLISH!O39), "", ENGLISH!O39) | R3: =IF(ISBLANK(ENGLISH!O41), "", ENGLISH!O41) | S3: =IF(ISBLANK(ENGLISH!O43), "", ENGLISH!O43) | T3: =IF(ISBLANK(ENGLISH!O45), "", ENGLISH!O45) | U3: =IF(ISBLANK(ENGLISH!J52), "", ENGLISH!J52) | V3: =IF(ISBLANK(ENGLISH!M52), "", ENGLISH!M52) | W3: =IF(ISBLANK(ENGLISH!J54), "", ENGLISH!J54) | X3: =IF(ISBLANK(ENGLISH!M54), "", ENGLISH!M54) | Y3: =IF(ISBLANK(ENGLISH!J55), "", ENGLISH!J55) | Z3: =IF(ISBLANK(ENGLISH!M55), "", ENGLISH!M55) | AA3: =IF(ISBLANK(ENGLISH!J57), "", ENGLISH!J57) | AB3: =IF(ISBLANK(ENGLISH!M57), "", ENGLISH!M57) | AC3: =IF(ISBLANK(ENGLISH!J59), "", ENGLISH!J59) | AD3: =IF(ISBLANK(ENGLISH!M59), "", ENGLISH!M59) | AE3: =IF(ISBLANK(ENGLISH!J60), "", ENGLISH!J60) | AF3: =IF(ISBLANK(ENGLISH!M60), "", ENGLISH!M60) | AG3: =IF(ISBLANK(ENGLISH!J62), "", ENGLISH!J62) | AH3: =IF(ISBLANK(ENGLISH!M62), "", ENGLISH!M62) | AI3: =IF(ISBLANK(ENGLISH!J64), "", ENGLISH!J64) | AJ3: =IF(ISBLANK(ENGLISH!M64), "", ENGLISH!M64) | AK3: =IF(ISBLANK(ENGLISH!J67), "", ENGLISH!J67) | AL3: =IF(ISBLANK(ENGLISH!M67), "", ENGLISH!M67) | AM3: =IF(ISBLANK(ENGLISH!J68), "", ENGLISH!J68) | AN3: =IF(ISBLANK(ENGLISH!M68), "", ENGLISH!M68) | AO3: =IF(ISBLANK(ENGLISH!J70), "", ENGLISH!J70) | AP3: =IF(ISBLANK(ENGLISH!M70), "", ENGLISH!M70) | AQ3: =IF(ISBLANK(ENGLISH!J77), "", ENGLISH!J77) | AR3: =IF(ISBLANK(ENGLISH!J78), "", ENGLISH!J78) | AS3: =IF(ISBLANK(ENGLISH!J79), "", ENGLISH!J79) | AT3: =IF(ISBLANK(ENGLISH!J80), "", ENGLISH!J80) | AU3: =IF(ISBLANK(ENGLISH!J81), "", ENGLISH!J81) | AV3: =IF(ISBLANK(ENGLISH!J82), "", ENGLISH!J82) | AW3: =IF(ISBLANK(ENGLISH!J83), "", ENGLISH!J83) | AX3: =IF(ISBLANK(ENGLISH!J84), "", ENGLISH!J84) | AY3: =IF(ISBLANK(ENGLISH!J85), "", ENGLISH!J85) | AZ3: =IF(ISBLANK(ENGLISH!J87), "", ENGLISH!J87) | BA3: =IF(ISBLANK(ENGLISH!J88), "", ENGLISH!J88) | BB3: =IF(ISBLANK(ENGLISH!M94), "", ENGLISH!M94) | BC3: =IF(ISBLANK(ENGLISH!M96), "", ENGLISH!M96) | BD3: =IF(ISBLANK(ENGLISH!M98), "", ENGLISH!M98) | BE3: =IF(ISBLANK(ENGLISH!M100), "", ENGLISH!M100) | BF3: =IF(ISBLANK(ENGLISH!M102), "", ENGLISH!M102) | BG3: =IF(ISBLANK(ENGLISH!M104), "", ENGLISH!M104) | BH3: =IF(ISBLANK(ENGLISH!K115), "", ENGLISH!K115) | BI3: =IF(ISBLANK(ENGLISH!O115), "", ENGLISH!O115) | BJ3: FALSE | BK3: FALSE | BL3: FALSE | BM3: FALSE | BN3: FALSE | BO3: FALSE | BP3: FALSE | BQ3: FALSE | BR3: FALSE | BS3: FALSE | BT3: FALSE | BU3: FALSE | BV3: FALSE | BW3: FALSE | BX3: FALSE | BY3: FALSE | BZ3: FALSE | CA3: FALSE | CB3: FALSE | CC3: FALSE | CD3: FALSE | CE3: FALSE | CF3: FALSE | CG3: FALSE | CH3: FALSE | CI3: FALSE | CJ3: FALSE | CK3: FALSE | CL3: FALSE | CM3: FALSE | CN3: =IF(ISBLANK(ENGLISH!K119), "", ENGLISH!K119) | CO3: =IF(ISBLANK(ENGLISH!K120), "", ENGLISH!K120) | CP3: =IF(ISBLANK(ENGLISH!K122), "", ENGLISH!K122) | CQ3: =IF(ISBLANK(ENGLISH!K123), "", ENGLISH!K123) | CR3: =IF(ISBLANK(ENGLISH!K124), "", ENGLISH!K124) | CS3: =IF(ISBLANK(ENGLISH!K125), "", ENGLISH!K125) | CT3: =IF(ISBLANK(ENGLISH!K126), "", ENGLISH!K126) | CU3: =IF(ISBLANK(ENGLISH!K127), "", ENGLISH!K127) | CV3: =IF(ISBLANK(ENGLISH!K128), "", ENGLISH!K128) | CW3: =IF(ISBLANK(ENGLISH!K129), "", ENGLISH!K129) | CX3: =IF(ISBLANK(ENGLISH!K130), "", ENGLISH!K130) | CY3: =IF(ISBLANK(ENGLISH!K132), "", ENGLISH!K132) | CZ3: =IF(ISBLANK(ENGLISH!K133), "", ENGLISH!K133) | DA3: =IF(ISBLANK(ENGLISH!K134), "", ENGLISH!K134) | DB3: =IF(ISBLANK(ENGLISH!K135), "", ENGLISH!K135) | DC3: =IF(ISBLANK(ENGLISH!O119), "", ENGLISH!O119) | DD3: =IF(ISBLANK(ENGLISH!O120), "", ENGLISH!O120) | DE3: =IF(ISBLANK(ENGLISH!O122), "", ENGLISH!O122) | DF3: =IF(ISBLANK(ENGLISH!O123), "", ENGLISH!O123) | DG3: =IF(ISBLANK(ENGLISH!O124), "", ENGLISH!O124) | DH3: =IF(ISBLANK(ENGLISH!O125), "", ENGLISH!O125) | DI3: =IF(ISBLANK(ENGLISH!O126), "", ENGLISH!O126) | DJ3: =IF(ISBLANK(ENGLISH!O127), "", ENGLISH!O127) | DK3: =IF(ISBLANK(ENGLISH!O128), "", ENGLISH!O128) | DL3: =IF(ISBLANK(ENGLISH!O129), "", ENGLISH!O129) | DM3: =IF(ISBLANK(ENGLISH!O130), "", ENGLISH!O130) | DN3: =IF(ISBLANK(ENGLISH!O132), "", ENGLISH!O132) | DO3: =IF(ISBLANK(ENGLISH!O133), "", ENGLISH!O133) | DP3: =IF(ISBLANK(ENGLISH!O134), "", ENGLISH!O134) | DQ3: =IF(ISBLANK(ENGLISH!O135), "", ENGLISH!O135) | DR3: =IF(ISBLANK(ENGLISH!K138), "", ENGLISH!K138) | DS3: =IF(ISBLANK(ENGLISH!K146), "", ENGLISH!K146) -> 0 | DT3: =IF(ISBLANK(ENGLISH!K148), "", ENGLISH!K148) -> 0 | DU3: =IF(ISBLANK(ENGLISH!K150), "", ENGLISH!K150) | DV3: =IF(ISBLANK(ENGLISH!K151), "", ENGLISH!K151) | DW3: =IF(ISBLANK(ENGLISH!K152), "", ENGLISH!K152) | DX3: =IF(ISBLANK(ENGLISH!K153), "", ENGLISH!K153) | DY3: =IF(ISBLANK(ENGLISH!K154), "", ENGLISH!K154) | DZ3: =IF(ISBLANK(ENGLISH!K155), "", ENGLISH!K155) | EA3: =IF(ISBLANK(ENGLISH!K156), "", ENGLISH!K156) | EB3: =IF(ISBLANK(ENGLISH!K157), "", ENGLISH!K157) | EC3: =IF(ISBLANK(ENGLISH!K158), "", ENGLISH!K158) | ED3: =IF(ISBLANK(ENGLISH!K159), "", ENGLISH!K159) | EE3: =IF(ISBLANK(ENGLISH!K160), "", ENGLISH!K160) | EF3: =IF(ISBLANK(ENGLISH!K161), "", ENGLISH!K161) | EG3: =IF(ISBLANK(ENGLISH!K162), "", ENGLISH!K162) | EH3: =IF(ISBLANK(ENGLISH!K163), "", ENGLISH!K163) | EI3: =IF(ISBLANK(ENGLISH!K164), "", ENGLISH!K164) | EJ3: =IF(ISBLANK(ENGLISH!K165), "", ENGLISH!K165) | EK3: =IF(ISBLANK(ENGLISH!K167), "", ENGLISH!K167) | EL3: =IF(ISBLANK(ENGLISH!D167), "", ENGLISH!D167) | EM3: =IF(ISBLANK(ENGLISH!K169), "", ENGLISH!K169) -> 0 | EN3: =IF(ISBLANK(ENGLISH!K171), "", ENGLISH!K171) | EO3: =IF(ISBLANK(ENGLISH!K172), "", ENGLISH!K172) | EP3: =IF(ISBLANK(ENGLISH!K173), "", ENGLISH!K173) | EQ3: =IF(ISBLANK(ENGLISH!K174), "", ENGLISH!K174) | ER3: =IF(ISBLANK(ENGLISH!K175), "", ENGLISH!K175) | ES3: =IF(ISBLANK(ENGLISH!K176), "", ENGLISH!K176) | ET3: =IF(ISBLANK(ENGLISH!K177), "", ENGLISH!K177) | EU3: =IF(ISBLANK(ENGLISH!K179), "", ENGLISH!K179) | EV3: =IF(ISBLANK(ENGLISH!D179), "", ENGLISH!D179) | EW3: =IF(ISBLANK(ENGLISH!K181), "", ENGLISH!K181) -> 0 | EX3: =IF(ISBLANK(ENGLISH!K183), "", ENGLISH!K183) | EY3: =IF(ISBLANK(ENGLISH!K184), "", ENGLISH!K184) | EZ3: =IF(ISBLANK(ENGLISH!K185), "", ENGLISH!K185) | FA3: =IF(ISBLANK(ENGLISH!K187), "", ENGLISH!K187) | FB3: =IF(ISBLANK(ENGLISH!D187), "", ENGLISH!D187) | FC3: =IF(ISBLANK(ENGLISH!D191), "", ENGLISH!D191) | FD3: =IF(ISBLANK(ENGLISH!K199), "", ENGLISH!K199) -> 0 | FE3: =IF(ISBLANK(ENGLISH!K201), "", ENGLISH!K201) | FF3: =IF(ISBLANK(ENGLISH!K202), "", ENGLISH!K202) | FG3: =IF(ISBLANK(ENGLISH!K203), "", ENGLISH!K203) | FH3: =IF(ISBLANK(ENGLISH!K204), "", ENGLISH!K204) | FI3: =IF(ISBLANK(ENGLISH!K205), "", ENGLISH!K205) | FJ3: =IF(ISBLANK(ENGLISH!K206), "", ENGLISH!K206) | FK3: =IF(ISBLANK(ENGLISH!K207), "", ENGLISH!K207) | FL3: =IF(ISBLANK(ENGLISH!K208), "", ENGLISH!K208) | FM3: =IF(ISBLANK(ENGLISH!K210), "", ENGLISH!K210) | FN3: =IF(ISBLANK(ENGLISH!D210), "", ENGLISH!D210) | FO3: =IF(ISBLANK(ENGLISH!D214), "", ENGLISH!D214) | FP3: =IF(ISBLANK(ENGLISH!K222), "", ENGLISH!K222) -> 0 | FQ3: =IF(ISBLANK(ENGLISH!K224), "", ENGLISH!K224) -> 0 | FR3: =IF(ISBLANK(ENGLISH!K225), "", ENGLISH!K225) -> 0 | FS3: =IF(ISBLANK(ENGLISH!K226), "", ENGLISH!K226) -> 0 | FT3: =IF(ISBLANK(ENGLISH!K228), "", ENGLISH!K228) -> 0 | FU3: =IF(ISBLANK(ENGLISH!K230), "", ENGLISH!K230) -> 0 | FV3: =IF(ISBLANK(ENGLISH!K233), "", ENGLISH!K233) -> 0 | FW3: =IF(ISBLANK(ENGLISH!K235), "", ENGLISH!K235) | FX3: =IF(ISBLANK(ENGLISH!K236), "", ENGLISH!K236) | FY3: =IF(ISBLANK(ENGLISH!K238), "", ENGLISH!K238) | FZ3: =IF(ISBLANK(ENGLISH!D238), "", ENGLISH!D238) | GA3: =IF(ISBLANK(ENGLISH!K240), "", ENGLISH!K240) | GB3: =IF(ISBLANK(ENGLISH!K242), "", ENGLISH!K242) -> 0 | GC3: =IF(ISBLANK(ENGLISH!D247), "", ENGLISH!D247) | GD3: =IF(ISBLANK(ENGLISH!K255), "", ENGLISH!K255) -> 0 | GE3: =IF(ISBLANK(ENGLISH!K257), "", ENGLISH!K257) -> 0 | GF3: =IF(ISBLANK(ENGLISH!K258), "", ENGLISH!K258) | GG3: =IF(ISBLANK(ENGLISH!K259), "", ENGLISH!K259) | GH3: =IF(ISBLANK(ENGLISH!K261), "", ENGLISH!K261) -> 0 | GI3: =IF(ISBLANK(ENGLISH!K262), "", ENGLISH!K262) | GJ3: =IF(ISBLANK(ENGLISH!K264),"", ENGLISH!K264) | GK3: =IF(ISBLANK(ENGLISH!K266), "", ENGLISH!K266) -> 0 | GL3: =IF(ISBLANK(ENGLISH!K267), "", ENGLISH!K267) | GM3: =IF(ISBLANK(ENGLISH!K268), "", ENGLISH!K268) | GN3: =IF(ISBLANK(ENGLISH!K270), "", ENGLISH!K270) -> 0 | GO3: =IF(ISBLANK(ENGLISH!K263), "", ENGLISH!K263) | GP3: =IF(ISBLANK(ENGLISH!K276), "", ENGLISH!K276) | GQ3: =IF(ISBLANK(ENGLISH!K279), "", ENGLISH!K279) | GR3: =IF(ISBLANK(ENGLISH!M279), "", ENGLISH!M279) | GS3: =IF(ISBLANK(ENGLISH!O279), "", ENGLISH!O279) | GT3: =IF(ISBLANK(ENGLISH!Q279), "", ENGLISH!Q279) | GU3: =IF(ISBLANK(ENGLISH!K285), "", ENGLISH!K285) -> 0 | GV3: =IF(ISBLANK(ENGLISH!K287),"",ENGLISH!K287) | GW3: =IF(ISBLANK(ENGLISH!K288),"",ENGLISH!K288) | GX3: =IF(ISBLANK(ENGLISH!K289),"",ENGLISH!K289) | GY3: =IF(ISBLANK(ENGLISH!K290),"",ENGLISH!K290) | GZ3: =IF(ISBLANK(ENGLISH!K291),"",ENGLISH!K291) | HA3: =IF(ISBLANK(ENGLISH!K293),"",ENGLISH!K293) | HB3: =IF(ISBLANK(ENGLISH!D293), "", ENGLISH!D293) | HC3: =IF(ISBLANK(ENGLISH!K299), "", ENGLISH!K299) | HD3: =IF(ISBLANK(ENGLISH!K300), "", ENGLISH!K300) | HE3: =IF(ISBLANK(ENGLISH!K306), "", ENGLISH!K306) -> 0 | HF3: =IF(ISBLANK(ENGLISH!K308), "", ENGLISH!K308) | HG3: =IF(ISBLANK(ENGLISH!K309), "", ENGLISH!K309) | HH3: =IF(ISBLANK(ENGLISH!K310), "", ENGLISH!K31) | HI3: =IF(ISBLANK(ENGLISH!K312), "", ENGLISH!K312) | HJ3: =IF(ISBLANK(ENGLISH!D312), "", ENGLISH!D312) | HK3: =IF(ISBLANK(ENGLISH!D316), "", ENGLISH!D316) | HL3: =IF(ISBLANK(ENGLISH!K324), "", ENGLISH!K324) | HM3: =IF(ISBLANK(ENGLISH!K325), "", ENGLISH!K325) | HQ3: =IF(ISBLANK(ENGLISH!O146), "", ENGLISH!O146) -> 0 | HR3: =IF(ISBLANK(ENGLISH!O148), "", ENGLISH!O148) -> 0 | HS3: =IF(ISBLANK(ENGLISH!O150), "", ENGLISH!O150) | HT3: =IF(ISBLANK(ENGLISH!O151), "", ENGLISH!O151) | HU3: =IF(ISBLANK(ENGLISH!O152), "", ENGLISH!O152) | HV3: =IF(ISBLANK(ENGLISH!O153), "", ENGLISH!O153) | HW3: =IF(ISBLANK(ENGLISH!O154), "", ENGLISH!O154) | HX3: =IF(ISBLANK(ENGLISH!O155), "", ENGLISH!O155) | HY3: =IF(ISBLANK(ENGLISH!O156), "", ENGLISH!O156) | HZ3: =IF(ISBLANK(ENGLISH!O157), "", ENGLISH!O157) | IA3: =IF(ISBLANK(ENGLISH!O158), "", ENGLISH!O158) | IB3: =IF(ISBLANK(ENGLISH!O159), "", ENGLISH!O159) | IC3: =IF(ISBLANK(ENGLISH!O160), "", ENGLISH!O160) | ID3: =IF(ISBLANK(ENGLISH!O161), "", ENGLISH!O161) | IE3: =IF(ISBLANK(ENGLISH!O162), "", ENGLISH!O162) | IF3: =IF(ISBLANK(ENGLISH!O163), "", ENGLISH!O163) | IG3: =IF(ISBLANK(ENGLISH!O164), "", ENGLISH!O164) | IH3: =IF(ISBLANK(ENGLISH!O165), "", ENGLISH!O165) | II3: =IF(ISBLANK(ENGLISH!O167), "", ENGLISH!O167) | IJ3: =IF(ISBLANK(ENGLISH!D167), "", ENGLISH!D167) | IK3: =IF(ISBLANK(ENGLISH!O169), "", ENGLISH!O169) -> 0 | IL3: =IF(ISBLANK(ENGLISH!O171), "", ENGLISH!O171) | IM3: =IF(ISBLANK(ENGLISH!O172), "", ENGLISH!O172) | IN3: =IF(ISBLANK(ENGLISH!O173), "", ENGLISH!O173) | IO3: =IF(ISBLANK(ENGLISH!O174), "", ENGLISH!O174) | IP3: =IF(ISBLANK(ENGLISH!O175), "", ENGLISH!O175) | IQ3: =IF(ISBLANK(ENGLISH!O176), "", ENGLISH!O176) | IR3: =IF(ISBLANK(ENGLISH!O177), "", ENGLISH!O177) | IS3: =IF(ISBLANK(ENGLISH!O179), "", ENGLISH!O179) | IT3: =IF(ISBLANK(ENGLISH!D179), "", ENGLISH!D179) | IU3: =IF(ISBLANK(ENGLISH!O181), "", ENGLISH!O181) -> 0 | IV3: =IF(ISBLANK(ENGLISH!O183), "", ENGLISH!O183) | IW3: =IF(ISBLANK(ENGLISH!O184), "", ENGLISH!O184) | IX3: =IF(ISBLANK(ENGLISH!O185), "", ENGLISH!O185) | IY3: =IF(ISBLANK(ENGLISH!O187), "", ENGLISH!O187) | IZ3: =IF(ISBLANK(ENGLISH!DB187), "", ENGLISH!DB187) | JA3: =IF(ISBLANK(ENGLISH!D191), "", ENGLISH!D191) | JB3: =IF(ISBLANK(ENGLISH!O199), "", ENGLISH!O199) -> 0 | JC3: =IF(ISBLANK(ENGLISH!O201), "", ENGLISH!O201) | JD3: =IF(ISBLANK(ENGLISH!O202), "", ENGLISH!O202) | JE3: =IF(ISBLANK(ENGLISH!O203), "", ENGLISH!O203) | JF3: =IF(ISBLANK(ENGLISH!O204), "", ENGLISH!O204) | JG3: =IF(ISBLANK(ENGLISH!O205), "", ENGLISH!O205) | JH3: =IF(ISBLANK(ENGLISH!O206), "", ENGLISH!O206) | JI3: =IF(ISBLANK(ENGLISH!O207), "", ENGLISH!O207) | JJ3: =IF(ISBLANK(ENGLISH!O208), "", ENGLISH!O208) | JK3: =IF(ISBLANK(ENGLISH!O210), "", ENGLISH!O210) | JL3: =IF(ISBLANK(ENGLISH!D210), "", ENGLISH!D210) | JM3: =IF(ISBLANK(ENGLISH!D214), "", ENGLISH!D214) | JN3: =IF(ISBLANK(ENGLISH!O222), "", ENGLISH!O222) -> 0 | JO3: =IF(ISBLANK(ENGLISH!O224), "", ENGLISH!O224) -> 0 | JP3: =IF(ISBLANK(ENGLISH!O225), "", ENGLISH!O225) -> 0 | JQ3: =IF(ISBLANK(ENGLISH!O226), "", ENGLISH!O226) -> 0 | JR3: =IF(ISBLANK(ENGLISH!O228), "", ENGLISH!O228) -> 0 | JS3: =IF(ISBLANK(ENGLISH!O230), "", ENGLISH!O230) -> 0 | JT3: =IF(ISBLANK(ENGLISH!O233), "", ENGLISH!O233) -> 0 | JU3: =IF(ISBLANK(ENGLISH!O235), "", ENGLISH!O235) | JV3: =IF(ISBLANK(ENGLISH!O236), "", ENGLISH!O236) | JW3: =IF(ISBLANK(ENGLISH!O238), "", ENGLISH!O238) | JX3: =IF(ISBLANK(ENGLISH!D238), "", ENGLISH!D238) | JY3: =IF(ISBLANK(ENGLISH!O240), "", ENGLISH!O240) | JZ3: =IF(ISBLANK(ENGLISH!O242), "", ENGLISH!O242) -> 0 | KA3: =IF(ISBLANK(ENGLISH!D247), "", ENGLISH!D247) | KB3: =IF(ISBLANK(ENGLISH!O255), "", ENGLISH!O255) -> 0 | KC3: =IF(ISBLANK(ENGLISH!O257), "", ENGLISH!O257) -> 0 | KD3: =IF(ISBLANK(ENGLISH!O258), "", ENGLISH!O258) | KE3: =IF(ISBLANK(ENGLISH!O259), "", ENGLISH!O259) | KF3: =IF(ISBLANK(ENGLISH!O261), "", ENGLISH!O261) -> 0 | KG3: =IF(ISBLANK(ENGLISH!O262), "", ENGLISH!O262) | KH3: =IF(ISBLANK(ENGLISH!O264),"", ENGLISH!O264) | KI3: =IF(ISBLANK(ENGLISH!O266), "", ENGLISH!O266) -> 0 | KJ3: =IF(ISBLANK(ENGLISH!O267), "", ENGLISH!O267) | KK3: =IF(ISBLANK(ENGLISH!O268), "", ENGLISH!O268) | KL3: =IF(ISBLANK(ENGLISH!O270), "", ENGLISH!O270) -> 0 | KM3: =IF(ISBLANK(ENGLISH!O263), "", ENGLISH!O263) | KN3: =IF(ISBLANK(ENGLISH!O276), "", ENGLISH!O276) | KO3: =IF(ISBLANK(ENGLISH!O285), "", ENGLISH!O285) -> 0 | KP3: =IF(ISBLANK(ENGLISH!O287),"",ENGLISH!O287) | KQ3: =IF(ISBLANK(ENGLISH!O288),"",ENGLISH!O288) | KR3: =IF(ISBLANK(ENGLISH!O289),"",ENGLISH!O289) | KS3: =IF(ISBLANK(ENGLISH!O290),"",ENGLISH!O290) | KT3: =IF(ISBLANK(ENGLISH!O291),"",ENGLISH!O291) | KU3: =IF(ISBLANK(ENGLISH!O293),"",ENGLISH!O293) | KV3: =IF(ISBLANK(ENGLISH!D293), "", ENGLISH!D293) | KW3: =IF(ISBLANK(ENGLISH!O299), "", ENGLISH!O299) | KX3: =IF(ISBLANK(ENGLISH!O300), "", ENGLISH!O300) | KY3: =IF(ISBLANK(ENGLISH!O306), "", ENGLISH!O306) -> 0 | KZ3: =IF(ISBLANK(ENGLISH!O308), "", ENGLISH!O308) | LA3: =IF(ISBLANK(ENGLISH!O309), "", ENGLISH!O309) | LB3: =IF(ISBLANK(ENGLISH!O310), "", ENGLISH!O31) | LC3: =IF(ISBLANK(ENGLISH!O312), "", ENGLISH!O312) | LD3: =IF(ISBLANK(ENGLISH!D312), "", ENGLISH!D312) | LE3: =IF(ISBLANK(ENGLISH!D316), "", ENGLISH!D316) | LF3: =IF(ISBLANK(ENGLISH!O324), "", ENGLISH!O324) | LG3: =IF(ISBLANK(ENGLISH!O325), "", ENGLISH!O325)

Sheet for internal use (FRENCH)
A1: 1 | B1: 1 | C1: 1 | D1: 1 | E1: 1 | F1: 1 | G1: 1 | H1: 1 | I1: 1 | J1: 1 | K1: 1 | L1: 1 | M1: 2 | N1: 2 | O1: 2 | P1: 2 | Q1: 2 | R1: 2 | S1: 2 | T1: 2 | U1: 3.1 | W1: 3.1 | Y1: 3.1 | AA1: 3.1 | AC1: 3.1 | AE1: 3.1 | AG1: 3.1 | AI1: 3.1 | AK1: 3.1 | AM1: 3.1 | AO1: 3.1 | AQ1: 3.2 | AR1: 3.2 | AS1: 3.2 | AT1: 3.2 | AU1: 3.2 | AV1: 3.2 | AW1: 3.2 | AX1: 3.2 | AY1: 3.2 | AZ1: 3.2 | BA1: 3.2 | BB1: 4 | BC1: 4 | BD1: 4 | BE1: 4 | BF1: 4 | BG1: 4 | BH1: 5 | BI1: 5 | BJ1: 5 | BK1: 5 | BL1: 5 | BM1: 5 | BN1: 5 | BO1: 5 | BP1: 5 | BQ1: 5 | BR1: 5 | BS1: 5 | BT1: 5 | BU1: 5 | BV1: 5 | BW1: 5 | BY1: 5 | BZ1: 5 | CA1: 5 | CB1: 5 | CC1: 5 | CD1: 5 | CE1: 5 | CF1: 5 | CG1: 5 | CH1: 5 | CI1: 5 | CJ1: 5 | CK1: 5 | CL1: 5 | CM1: 5 | CN1: 5 | CO1: 5 | CP1: 5 | CQ1: 5 | CR1: 5 | CS1: 5 | CT1: 5 | CU1: 5 | CV1: 5 | CW1: 5 | CX1: 5 | CY1: 5 | CZ1: 5 | DA1: 5 | DB1: 5 | DC1: 5 | DD1: 5 | DE1: 5 | DF1: 5 | DG1: 5 | DH1: 5 | DI1: 5 | DJ1: 5 | DK1: 5 | DL1: 5 | DM1: 5 | DN1: 5 | DO1: 5 | DP1: 5 | DQ1: 5 | DR1: 5 | DS1: 6 | DT1: 6 | DU1: 6 | DV1: 6 | DW1: 6 | DX1: 6 | DY1: 6 | DZ1: 6 | EA1: 6 | EB1: 6 | EC1: 6 | ED1: 6 | EE1: 6 | EF1: 6 | EG1: 6 | EH1: 6 | EI1: 6 | EJ1: 6 | EK1: 6 | EL1: 6 | EM1: 6 | EN1: 6 | EO1: 6 | EP1: 6 | EQ1: 6 | ER1: 6 | ES1: 6 | ET1: 6 | EU1: 6 | EV1: 6 | EW1: 6 | EX1: 6 | EY1: 6 | EZ1: 6 | FA1: 6 | FB1: 6 | FC1: 6 | FD1: 7 | FE1: 7 | FF1: 7 | FG1: 7 | FH1: 7 | FI1: 7 | FJ1: 7 | FK1: 7 | FL1: 7 | FM1: 7 | FN1: 7 | FO1: 7 | FP1: 8 | FQ1: 8 | FR1: 8 | FS1: 8 | FT1: 8 | FU1: 8 | FV1: 8 | FW1: 8 | FX1: 8 | FY1: 8 | FZ1: 8 | GA1: 8 | GB1: 8 | GC1: 8 | GD1: 9 | GE1: 9 | GF1: 9 | GG1: 9 | GH1: 9 | GI1: 9 | GJ1: 9 | GK1: 9 | GL1: 9 | GM1: 9 | GN1: 9 | GO1: 9 | GP1: 10 | GQ1: 10 | GR1: 10 | GS1: 10 | GT1: 10 | GU1: 11 | GV1: 11 | GW1: 11 | GX1: 11 | GY1: 11 | GZ1: 11 | HA1: 11 | HB1: 11 | HC1: 12 | HD1: 12 | HE1: 13 | HF1: 13 | HG1: 13 | HH1: 13 | HI1: 13 | HJ1: 13 | HK1: 13 | HL1: 14 | HM1: 14 | HQ1: 6 (2011) | HR1: 6 (2011) | HS1: 6 (2011) | HT1: 6 (2011) | HU1: 6 (2011) | HV1: 6 (2011) | HW1: 6 (2011) | HX1: 6 (2011) | HY1: 6 (2011) | HZ1: 6 (2011) | IA1: 6 (2011) | IB1: 6 (2011) | IC1: 6 (2011) | ID1: 6 (2011) | IE1: 6 (2011) | IF1: 6 (2011) | IG1: 6 (2011) | IH1: 6 (2011) | II1: 6 (2011) | IJ1: 6 (2011) | IK1: 6 (2011) | IL1: 6 (2011) | IM1: 6 (2011) | IN1: 6 (2011) | IO1: 6 (2011) | IP1: 6 (2011) | IQ1: 6 (2011) | IR1: 6 (2011) | IS1: 6 (2011) | IT1: 6 (2011) | IU1: 6 (2011) | IV1: 6 (2011) | IW1: 6 (2011) | IX1: 6 (2011) | IY1: 6 (2011) | IZ1: 6 (2011) | JA1: 6 (2011) | JB1: 7 (2011) | JC1: 7 (2011) | JD1: 7 (2011) | JE1: 7 (2011) | JF1: 7 (2011) | JG1: 7 (2011) | JH1: 7 (2011) | JI1: 7 (2011) | JJ1: 7 (2011) | JK1: 7 (2011) | JL1: 7 (2011) | JM1: 7 (2011) | JN1: 8 (2011) | JO1: 8 (2011) | JP1: 8 (2011) | JQ1: 8 (2011) | JR1: 8 (2011) | JS1: 8 (2011) | JT1: 8 (2011) | JU1: 8 (2011) | JV1: 8 (2011) | JW1: 8 (2011) | JX1: 8 (2011) | JY1: 8 (2011) | JZ1: 8 (2011) | KA1: 8 (2011) | KB1: 9 (2011) | KC1: 9 (2011) | KD1: 9 (2011) | KE1: 9 (2011) | KF1: 9 (2011) | KG1: 9 (2011) | KH1: 9 (2011) | KI1: 9 (2011) | KJ1: 9 (2011) | KK1: 9 (2011) | KL1: 9 (2011) | KM1: 9 (2011) | KN1: 10 (2011) | KO1: 11 (2011) | KP1: 11 (2011) | KQ1: 11 (2011) | KR1: 11 (2011) | KS1: 11 (2011) | KT1: 11 (2011) | KU1: 11 (2011) | KV1: 11 (2011) | KW1: 12 (2011) | KX1: 12 (2011) | KY1: 13 (2011) | KZ1: 13 (2011) | LA1: 13 (2011) | LB1: 13 (2011) | LC1: 13 (2011) | LD1: 13 (2011) | LE1: 13 (2011) | LF1: 14 (2011) | LG1: 14 (2011)
