Workbook

Sheet DIRECTIONS
A1: Directions for completing the Straight A Grant Financial Impact Report
A4: Each applicant for a Straight A Fund grant must complete a Straight A Grant Financial Impact Table. The instructions for completing the file can be found below. This file is used for all applicants. If you have multiple applicants, you will need multiple tabs (discussed below). Use the appropriate tab based on your organization type. City, local, exempted village or joint vocational school districts will use the Traditional tab. Educational Service Centers will use the ESC tab. All other applicants will use the Non-Traditional tab.
A7: Instructions for the Traditional Tab
A8: 1. Enter the district's 6-digit IRN in cell B2 of the Traditional tab. Column C of the form will be populated with the October, FY14 five-year forecast figures as submitted to EMIS for the entered district. 2. Enter into Columns D through H (FY16-FY20) the anticipated sustaining costs and cost reductions for each expenditure type impacted by Straight A funds in the years following the grant year (FY15). These numbers are to be based on the anticipated grant award. The purpose of the financial impact table is to show the impact of the grant award. 3. Enter into Column I text explaination regarding the anticipated costs and cost reductions.
A10: Instructions for the Non-Traditional and ESC Tabs
A11: 1. Enter the school or organization name in cell B1 and the IRN (if applicable) in cell B2 of the Non-Traditional or ESC tab. 2. If the applicant is a community school that has submitted a five-year forecast, enter into Column C the data from the five-year forecast as submitted to ODE for the current fiscal year (October, FY14). If the applicant is an organization that has not submitted a five-year forecast to ODE, enter into Column C the current budget information. 3. Enter into Columns D through H (FY16-FY20) the anticipated sustaining costs and cost reductions for each expenditure type impacted by Straight A funds in the years following the grant year (FY15). These numbers are to be based on the anticipated grant award. The purpose of the financial impact table is to show the impact of the grant award. 4. Enter into Column I text explaination regarding the anticipated costs and cost reductions.
A17: Individual Applicants:
A18: A submitted Financial Impact Table for an individual applicant should contain only one tab. 1. After completing the appropriate tab as detailed above, delete the unused tabs from the workbook. 1.a. Right click on the unused tab. 1.b. Select Delete. 2. Save the file with the file name of 'Financial Impact XXXXXX' where XXXXXX is your school's IRN (if applicable) or organization name. 3. Upload the completed file to the CCIP.
A20: Consortium Applicants:
A21: A submitted Financial Impact Table for a consortium should contain one tab for each member of the consortium. 1. Copy the appropriate tab for each member of the consortium based on the organization type. 1.a. Right click on the appropriate tab to be copied (Traditional, ESC or Non-Traditional). Select Move or Copy. 1.b. Select (move to the end) and the Create a copy checkbox. 1.c. Click on OK. A new tab will be created. 1.d. Double-click on the tab title to rename it to the consortium member's IRN (if applicable) or organization name. 2. The first tab after the DIRECTIONS should be the tab for the Lead Applicant. If the Lead Applicant tab is not the first one, click and drag to rearrange the tabs. 3. Enter the appropriate budget and forecast information on each consortium member's tab based on the instructions above. 4. Save the file with the file name of 'Financial Impact XXXXXX' where XXXXXX is the name of the consortium. 5. Upload the completed file to the CCIP.

Sheet Traditional
A1: IRN (6 digits): | I1: APPLICANT:
A2: APPLICANT: | B2: =VLOOKUP(B1,'FYF DATA'!$A$1:$BR$670,2,FALSE) -> #N/A | I2: =B2 -> #N/A
C3: FY14 | D3: FY16 | E3: FY17 | F3: FY18 | G3: FY19 | H3: FY20 | I3: EXPLAINATION
A4: Do not alter any of the shaded cells. | C4: Financial Baseline from the Current Five-Year Forecast | D4: Since FY15 is the grant year, its expenditures are not required in this table. In the FY16-FY20 columns, ADD only the SUSTAINING COSTS to the appropriate line items (refer to Question 15), and SUBTRACT only the SUSTAINING COST REDUCTIONS to the appropriate line items (refer to Questions 16 & 17). | I4: Explaination Provide detailed notes regarding the financial impact on each line affected by the grant funds. These notes are critical to the evaluation of the financial sustainability.
A5: EXPENDITURES - OPERATIONAL | C5: FY14 | D5: FY16 | E5: FY17 | F5: FY18 | G5: FY19 | H5: FY20
A6: 3.010 | B6: Personal Services (Salaries & Wages) | C6: =VLOOKUP(B1,'FYF DATA'!$A$1:$BR$670,20,FALSE) -> #N/A
A7: 3.020 | B7: Fringe Benefits | C7: =VLOOKUP(B1,'FYF DATA'!$A$1:$BR$670,21,FALSE) -> #N/A
A8: 3.030 | B8: Purchased Services | C8: =VLOOKUP(B1,'FYF DATA'!$A$1:$BR$670,22,FALSE) -> #N/A
A9: 3.040 | B9: Supplies and Materials | C9: =VLOOKUP(B1,'FYF DATA'!$A$1:$BR$670,23,FALSE) -> #N/A
A10: 3.050 | B10: Capital Outlay | C10: =VLOOKUP(B1,'FYF DATA'!$A$1:$BR$670,24,FALSE) -> #N/A
A11: 3.060 | B11: Intergovernmental | C11: =VLOOKUP(B1,'FYF DATA'!$A$1:$BR$670,25,FALSE) -> #N/A
B12: Total Expenditures - Operational | C12: =SUM(C6:C11) -> #N/A | D12: =SUM(D6:D11) -> 0 | E12: =SUM(E6:E11) -> 0 | F12: =SUM(F6:F11) -> 0 | G12: =SUM(G6:G11) -> 0 | H12: =SUM(H6:H11) -> 0
A13: EXPENDITURES - DEBT SERVICE | C13: FY14 | D13: FY16 | E13: FY17 | F13: FY18 | G13: FY19 | H13: FY20
A14: 4.010 | B14: Debt Service-Principal-All (Historical Only) | C14: =VLOOKUP(B1,'FYF DATA'!$A$1:$BR$670,26,FALSE) -> #N/A
A15: 4.020 | B15: Debt Service-Principal-Notes | C15: =VLOOKUP($B$1,'FYF DATA'!$A$1:$BR$670,27,FALSE) -> #N/A
A16: 4.030 | B16: Debt Service-Principal-State Loans | C16: =VLOOKUP($B$1,'FYF DATA'!$A$1:$BR$670,28,FALSE) -> #N/A
A17: 4.040 | B17: Debt Service-Principal-State Advances | C17: =VLOOKUP($B$1,'FYF DATA'!$A$1:$BR$670,29,FALSE) -> #N/A
A18: 4.050 | B18: Debt Service-Principal-HB264 Loans | C18: =VLOOKUP($B$1,'FYF DATA'!$A$1:$BR$670,30,FALSE) -> #N/A
A19: 4.055 | B19: Debt Service-Principal-Other | C19: =VLOOKUP($B$1,'FYF DATA'!$A$1:$BR$670,31,FALSE) -> #N/A
A20: 4.060 | B20: Debt Service-Interest and Fiscal Charges | C20: =VLOOKUP($B$1,'FYF DATA'!$A$1:$BR$670,32,FALSE) -> #N/A
A21: 4.300 | B21: Debt Service-Other Objects | C21: =VLOOKUP($B$1,'FYF DATA'!$A$1:$BR$670,33,FALSE) -> #N/A
B22: Total Expenditures - Debt Service | C22: =SUM(C14:C21) -> #N/A | D22: =SUM(D14:D21) -> 0 | E22: =SUM(E14:E21) -> 0 | F22: =SUM(F14:F21) -> 0 | G22: =SUM(G14:G21) -> 0 | H22: =SUM(H14:H21) -> 0
A23: EXPENDITURES - NON-OPERATIONAL | C23: FY14 | D23: FY16 | E23: FY17 | F23: FY18 | G23: FY19 | H23: FY20
A24: 5.010 | B24: Operating Transfers-Out | C24: =VLOOKUP($B$1,'FYF DATA'!$A$1:$BR$670,35,FALSE) -> #N/A
A25: 5.020 | B25: Advances-Out | C25: =VLOOKUP($B$1,'FYF DATA'!$A$1:$BR$670,36,FALSE) -> #N/A
A26: 5.030 | B26: All Other Financing Uses | C26: =VLOOKUP($B$1,'FYF DATA'!$A$1:$BR$670,37,FALSE) -> #N/A
B27: Total Expenditures - Non-operational | C27: =SUM(C24:C26) -> #N/A | D27: =SUM(D24:D26) -> 0 | E27: =SUM(E24:E26) -> 0 | F27: =SUM(F24:F26) -> 0 | G27: =SUM(G24:G26) -> 0 | H27: =SUM(H24:H26) -> 0
A28: SUSTAINABILITY | C28: FY14 | D28: FY16 | E28: FY17 | F28: FY18 | G28: FY19 | H28: FY20
B29: TOTAL EXPENDITURES For FY16-20, total expenditures must be cost neutral (e.g. $0 or less) to prove sustainability. | C29: =(C12+C22+C27) -> #N/A | D29: =(D12+D22+D27) -> 0 | E29: =(E12+E22+E27) -> 0 | F29: =(F12+F22+F27) -> 0 | G29: =(G12+G22+G27) -> 0 | H29: =(H12+H22+H27) -> 0

Sheet Non-Traditional
A1: IRN (if applicable): | I1: APPLICANT:
A2: APPLICANT: | I2: =B2 -> 0
C3: FY14 | D3: FY16 | E3: FY17 | F3: FY18 | G3: FY19 | H3: FY20 | I3: EXPLAINATION
A4: Do not alter any of the shaded cells. | C4: Financial Baseline from the Current Fiscal Year | D4: Since FY15 is the grant year, its expenditures are not required in this table. In the FY16-FY20 columns, ADD only the SUSTAINING COSTS to the appropriate line items (refer to Question 15), and SUBTRACT only the SUSTAINING COST REDUCTIONS to the appropriate line items (refer to Questions 16 & 17). | I4: Explaination Provide detailed notes regarding the financial impact on each line affected by the grant funds. These notes are critical to the evaluation of the financial sustainability.
A5: EXPENDITURES | C5: FY14 | D5: FY16 | E5: FY17 | F5: FY18 | G5: FY19 | H5: FY20
A6: 100 | B6: Salaries and Wages
A7: 200 | B7: Employee Retirement and Insurance Benefits
A8: 400 | B8: Purchased Services
A9: 500 | B9: Supplies and Materials
A10: 600 | B10: Capital Outlay - New
A11: 700 | B11: Capital Outlay - Replacement
A12: 800 | B12: Other Operating Disbursements
A13: SUSTAINABILITY | C13: FY14 | D13: FY16 | E13: FY17 | F13: FY18 | G13: FY19 | H13: FY20
B14: TOTAL EXPENDITURES For FY16-20, total expenditures must be cost neutral (e.g. $0 or less) to prove sustainability. | C14: =SUM(C6:C12) -> 0 | D14: =SUM(D6:D12) -> 0 | E14: =SUM(E6:E12) -> 0 | F14: =SUM(F6:F12) -> 0 | G14: =SUM(G6:G12) -> 0 | H14: =SUM(H6:H12) -> 0

Sheet ESC
A1: IRN (if applicable): | I1: APPLICANT:
A2: APPLICANT: | I2: =B2 -> 0
C3: FY14 | D3: FY16 | E3: FY17 | F3: FY18 | G3: FY19 | H3: FY20 | I3: EXPLAINATION
A4: Do not alter any of the shaded cells. | C4: Financial Baseline from the Current Fiscal Year | D4: Since FY15 is the grant year, its expenditures are not required in this table. In the FY16-FY20 columns, ADD only the SUSTAINING COSTS to the appropriate line items (refer to Question 15), and SUBTRACT only the SUSTAINING COST REDUCTIONS to the appropriate line items (refer to Questions 16 & 17). | I4: Explaination Provide detailed notes regarding the financial impact on each line affected by the grant funds. These notes are critical to the evaluation of the financial sustainability.
A5: EXPENDITURES - OPERATIONAL | C5: FY14 | D5: FY16 | E5: FY17 | F5: FY18 | G5: FY19 | H5: FY20
A6: 3.010 | B6: Personal Services (Salaries & Wages)
A7: 3.020 | B7: Fringe Benefits
A8: 3.030 | B8: Purchased Services
A9: 3.040 | B9: Supplies and Materials
A10: 3.050 | B10: Capital Outlay
A11: 3.060 | B11: Intergovernmental
B12: Total Expenditures - Operational | C12: =SUM(C6:C11) -> 0 | D12: =SUM(D6:D11) -> 0 | E12: =SUM(E6:E11) -> 0 | F12: =SUM(F6:F11) -> 0 | G12: =SUM(G6:G11) -> 0 | H12: =SUM(H6:H11) -> 0
A13: EXPENDITURES - DEBT SERVICE | C13: FY14 | D13: FY16 | E13: FY17 | F13: FY18 | G13: FY19 | H13: FY20
A14: 4.010 | B14: Debt Service-Principal-All (Historical Only)
A15: 4.020 | B15: Debt Service-Principal-Notes
A16: 4.030 | B16: Debt Service-Principal-State Loans
A17: 4.040 | B17: Debt Service-Principal-State Advances
A18: 4.050 | B18: Debt Service-Principal-HB264 Loans
A19: 4.055 | B19: Debt Service-Principal-Other
A20: 4.060 | B20: Debt Service-Interest and Fiscal Charges
A21: 4.300 | B21: Debt Service-Other Objects
B22: Total Expenditures - Debt Service | C22: =SUM(C14:C21) -> 0 | D22: =SUM(D14:D21) -> 0 | E22: =SUM(E14:E21) -> 0 | F22: =SUM(F14:F21) -> 0 | G22: =SUM(G14:G21) -> 0 | H22: =SUM(H14:H21) -> 0
A23: EXPENDITURES - NON-OPERATIONAL | C23: FY14 | D23: FY16 | E23: FY17 | F23: FY18 | G23: FY19 | H23: FY20
A24: 5.010 | B24: Operating Transfers-Out
A25: 5.020 | B25: Advances-Out
A26: 5.030 | B26: All Other Financing Uses
B27: Total Expenditures - Non-operational | C27: =SUM(C24:C26) -> 0 | D27: =SUM(D24:D26) -> 0 | E27: =SUM(E24:E26) -> 0 | F27: =SUM(F24:F26) -> 0 | G27: =SUM(G24:G26) -> 0 | H27: =SUM(H24:H26) -> 0
A28: SUSTAINABILITY | C28: FY14 | D28: FY16 | E28: FY17 | F28: FY18 | G28: FY19 | H28: FY20
B29: TOTAL EXPENDITURES For FY16-20, total expenditures must be cost neutral (e.g. $0 or less) to prove sustainability. | C29: =(C12+C22+C27) -> 0 | D29: =(D12+D22+D27) -> 0 | E29: =(E12+E22+E27) -> 0 | F29: =(F12+F22+F27) -> 0 | G29: =(G12+G22+G27) -> 0 | H29: =(H12+H22+H27) -> 0

Sheet FYF DATA
A1: IRN | B1: DISTRICT | C1: County | D1: 1.01 | E1: 1.02 | F1: 1.03 | G1: 1.035 | H1: 1.04 | I1: 1.045 | J1: 1.05 | K1: 1.06 | L1: 1.07 | M1: 2.01 | N1: 2.02 | O1: 2.04 | P1: 2.05 | Q1: 2.06 | R1: 2.07 | S1: 2.08 | T1: 3.01 | U1: 3.02 | V1: 3.03 | W1: 3.04 | X1: 3.05 | Y1: 3.06 | Z1: 4.01 | AA1: 4.02 | AB1: 4.03 | AC1: 4.04 | AD1: 4.05 | AE1: 4.055 | AF1: 4.06 | AG1: 4.3 | AH1: 4.5 | AI1: 5.01 | AJ1: 5.02 | AK1: 5.03 | AL1: 5.04 | AM1: 5.05 | AN1: 6.01 | AO1: 7.01 | AP1: 7.02 | AQ1: 8.01 | AR1: 9.01 | AS1: 9.02 | AT1: 9.03 | AU1: 9.04 | AV1: 9.045 | AW1: 9.05 | AX1: 9.06 | AY1: 9.07 | AZ1: 9.08 | BA1: 10.01 | BB1: 11.01 | BC1: 11.02 | BD1: 11.3 | BE1: 12.01 | BF1: 13.01 | BG1: 13.02 | BH1: 13.03 | BI1: 14.01 | BJ1: 15.01 | BK1: 20.01 | BL1: 20.015 | BM1: 21.01 | BN1: 21.02 | BO1: 21.03 | BP1: 21.04 | BQ1: 21.05 | BR1: 21.06 | BS1: Grand Total
A2: 000442 | B2: Manchester Local SD | C2: Adams | D2: 2016765 | E2: 5048235 | F2: 0 | G2: 1563539 | H2: 28 | I2: 0 | J2: 2637787 | K2: 747032 | L2: 12013386 | M2: 0 | N2: 0 | O2: 0 | P2: 0 | Q2: 6436 | R2: 6436 | S2: 12019822 | T2: 4735233 | U2: 2157523 | V2: 2323141 | W2: 442627 | X2: 256968 | Y2: 0 | Z2: 0 | AA2: 0 | AB2: 0 | AC2: 0 | AD2: 30000 | AE2: 35793 | AF2: 21805 | AG2: 374534 | AH2: 10377624 | AI2: 2015739 | AJ2: 0 | AK2: 0 | AL2: 2015739 | AM2: 12393363 | AN2: -373541 | AO2: 5166670 | AP2: 4793129 | AQ2: 120000 | AR2: 0 | AS2: 0 | AT2: 0 | AU2: 0 | AV2: 0 | AW2: 0 | AX2: 0 | AY2: 0 | AZ2: 0 | BA2: 4673129 | BB2: 0 | BC2: 0 | BD2: 0 | BE2: 4673129 | BF2: 0 | BG2: 0 | BH2: 0 | BI2: 0 | BJ2: 4673129 | BK2: 0 | BL2: 0 | BM2: 0 | BN2: 0 | BO2: 0 | BP2: 0 | BQ2: 0 | BR2: 0 | BS2: 12393363
A3: 043489 | B3: Akron City SD | C3: Summit | D3: 103384602 | E3: 7465642 | F3: 0 | G3: 160156899 | H3: 3431385 | J3: 20488265 | K3: 11263678 | L3: 306190471 | M3: 0 | N3: 0 | O3: 32000 | R3: 32000 | S3: 306222471 | T3: 146483981 | U3: 64772763 | V3: 72432792 | W3: 9257816 | X3: 5807069 | Z3: 0 | AA3: 0 | AB3: 0 | AC3: 0 | AD3: 0 | AE3: 0 | AF3: 0 | AG3: 3450937 | AH3: 302205358 | AI3: 123500 | AK3: 0 | AM3: 302328858 | AO3: 13609028 | AP3: 17502641 | AQ3: 0 | AT3: 0 | AW3: 0 | AX3: 0 | AY3: 0 | BA3: 17502641 | BB3: 0 | BC3: 0 | BD3: 0 | BE3: 17502641 | BF3: 0 | BI3: 0 | BJ3: 17502641 | BK3: 2310 | BL3: 25009 | BS3: 306222471
A4: 043497 | B4: Alliance City SD | C4: Stark | D4: 6276000 | E4: 0 | F4: 0 | G4: 19330913 | H4: 184975 | I4: 0 | J4: 1072572 | K4: 1000000 | L4: 27864460 | M4: 0 | N4: 0 | O4: 0 | P4: 0 | Q4: 64433 | R4: 64433 | S4: 27928893 | T4: 15700000 | U4: 5700000 | V4: 5024592 | W4: 800000 | X4: 260000 | Y4: 0 | Z4: 165600 | AA4: 0 | AB4: 0 | AC4: 0 | AD4: 0 | AE4: 0 | AF4: 21970 | AG4: 304615 | AH4: 27976777 | AI4: 0 | AJ4: 0 | AK4: 0 | AL4: 0 | AM4: 27976777 | AN4: -47884 | AO4: 4735578 | AP4: 4687694 | AQ4: 0 | AR4: 0 | AS4: 0 | AT4: 0 | AU4: 0 | AV4: 0 | AW4: 0 | AX4: 0 | AY4: 0 | AZ4: 0 | BA4: 4687694 | BB4: 0 | BC4: 0 | BD4: 0 | BE4: 4687694 | BF4: 0 | BG4: 0 | BH4: 0 | BI4: 0 | BJ4: 4687694 | BK4: 238 | BL4: 2646 | BM4: 0 | BN4: 0 | BO4: 0 | BP4: 0 | BQ4: 0 | BR4: 0 | BS4: 27976777
A5: 043505 | B5: Ashland City SD | C5: Ashland | D5: 12974978 | E5: 1009592 | F5: 0 | G5: 10870284 | H5: 155831 | I5: 0 | J5: 3754952 | K5: 953026 | L5: 29718663 | M5: 0 | N5: 0 | O5: 0 | P5: 67423 | Q5: 0 | R5: 67423 | S5: 29786086 | T5: 15918018 | U5: 6856889 | V5: 5058002 | W5: 926966 | X5: 155143 | Y5: 0 | Z5: 0 | AA5: 0 | AB5: 0 | AC5: 0 | AD5: 250000 | AE5: 0 | AF5: 54590 | AG5: 426621 | AH5: 29646229 | AI5: 0 | AJ5: 67423 | AK5: 0 | AL5: 67423 | AM5: 29713652 | AN5: 72434 | AO5: 4539988 | AP5: 4612422 | AQ5: 195000 | AR5: 0 | AS5: 0 | AT5: 0 | AU5: 0 | AV5: 0 | AW5: 0 | AX5: 0 | AY5: 0 | AZ5: 0 | BA5: 4417422 | BB5: 0 | BC5: 0 | BD5: 0 | BE5: 4417422 | BF5: 0 | BG5: 0 | BH5: 0 | BI5: 0 | BJ5: 4417422 | BM5: 0 | BN5: 0 | BO5: 0 | BP5: 0 | BQ5: 0 | BR5: 0 | BS5: 29786086
A6: 043513 | B6: Ashtabula Area City SD | C6: Ashtabula | D6: 7841869 | E6: 1193945 | F6: 0 | G6: 23559062 | H6: 40414 | I6: 0 | J6: 1253343 | K6: 791865 | L6: 34680498 | M6: 0 | N6: 0 | O6: 0 | P6: 48812 | Q6: 25000 | R6: 73812 | S6: 34754310 | T6: 16754138 | U6: 7524351 | V6: 8779688 | W6: 639845 | X6: 8384 | Y6: 0 | Z6: 0 | AA6: 0 | AB6: 0 | AC6: 0 | AD6: 0 | AE6: 0 | AF6: 0 | AG6: 485518 | AH6: 34191924 | AI6: 28000 | AJ6: 350000 | AK6: 0 | AL6: 378000 | AM6: 34569924 | AN6: 184386 | AO6: 1696227 | AP6: 1880613 | AQ6: 250000 | AR6: 0 | AS6: 0 | AT6: 0 | AU6: 0 | AV6: 0 | AW6: 0 | AX6: 0 | AY6: 0 | AZ6: 0 | BA6: 1630613 | BB6: 0 | BC6: 0 | BD6: 0 | BE6: 1630613 | BF6: 0 | BG6: 0 | BH6: 0 | BI6: 0 | BJ6: 1630613 | BM6: 0 | BN6: 0 | BO6: 0 | BP6: 0 | BQ6: 0 | BR6: 0 | BS6: 34754310
A7: 043521 | B7: Athens City SD | C7: Athens | D7: 12044555 | E7: 1586424 | F7: 3598377 | G7: 7964397 | H7: 50034 | I7: 0 | J7: 1487710 | K7: 2901725 | L7: 29633222 | M7: 0 | N7: 0 | O7: 0 | P7: 0 | Q7: 93701 | R7: 93701 | S7: 29726923 | T7: 17491784 | U7: 7711897 | V7: 3463939 | W7: 663286 | X7: 10609 | Y7: 0 | Z7: 0 | AA7: 0 | AB7: 0 | AC7: 0 | AD7: 0 | AE7: 0 | AF7: 0 | AG7: 504631 | AH7: 29846146 | AI7: 10000 | AJ7: 50000 | AK7: 300000 | AL7: 360000 | AM7: 30206146 | AN7: -479223 | AO7: 7653620 | AP7: 7174397 | AQ7: 0 | AR7: 0 | AS7: 0 | AT7: 0 | AU7: 0 | AV7: 0 | AW7: 0 | AX7: 0 | AY7: 0 | AZ7: 0 | BA7: 7174397 | BB7: 0 | BC7: 0 | BD7: 0 | BE7: 7174397 | BF7: 0 | BG7: 0 | BH7: 0 | BI7: 0 | BJ7: 7174397 | BM7: 0 | BN7: 0 | BO7: 0 | BP7: 0 | BQ7: 0 | BR7: 0 | BS7: 30206146
A8: 043539 | B8: Barberton City SD | C8: Summit | D8: 11008889 | E8: 560748 | F8: 0 | G8: 22105032 | H8: 448607 | I8: 0 | J8: 2285107 | K8: 2621538 | L8: 39029921 | M8: 0 | N8: 0 | O8: 0 | P8: 0 | Q8: 250000 | R8: 250000 | S8: 39279921 | T8: 20067331 | U8: 8313788 | V8: 8261402 | W8: 749294 | X8: 56417 | Y8: 0 | Z8: 0 | AA8: 0 | AB8: 0 | AC8: 0 | AD8: 0 | AE8: 0 | AF8: 0 | AG8: 368133 | AH8: 37816365 | AI8: 0 | AJ8: 0 | AK8: 0 | AL8: 0 | AM8: 37816365 | AN8: 1463556 | AO8: 4754414 | AP8: 6217970 | AQ8: 500000 | AR8: 0 | AS8: 0 | AT8: 0 | AU8: 0 | AV8: 0 | AW8: 0 | AX8: 0 | AY8: 0 | AZ8: 0 | BA8: 5717970 | BB8: 0 | BC8: 0 | BD8: 0 | BE8: 5717970 | BF8: 0 | BG8: 0 | BH8: 0 | BI8: 0 | BJ8: 5717970 | BM8: 0 | BN8: 0 | BO8: 0 | BP8: 0 | BQ8: 0 | BR8: 0 | BS8: 39279921
A9: 043547 | B9: Bay Village City SD | C9: Cuyahoga | D9: 21427917 | E9: 819124 | F9: 0 | G9: 4052122 | H9: 139519 | I9: 0 | J9: 3465154 | K9: 357992 | L9: 30261828 | M9: 0 | N9: 0 | O9: 50000 | P9: 0 | Q9: 0 | R9: 50000 | S9: 30311828 | T9: 18744506 | U9: 6421399 | V9: 3094942 | W9: 1062787 | X9: 532354 | Y9: 0 | Z9: 0 | AA9: 159500 | AB9: 0 | AC9: 0 | AD9: 0 | AE9: 0 | AF9: 88162 | AG9: 433292 | AH9: 30536942 | AI9: 0 | AJ9: 0 | AK9: 250000 | AL9: 250000 | AM9: 30786942 | AN9: -475114 | AO9: 9217454 | AP9: 8742340 | AQ9: 200000 | AR9: 0 | AS9: 0 | AT9: 0 | AU9: 0 | AV9: 0 | AW9: 0 | AX9: 0 | AY9: 0 | AZ9: 0 | BA9: 8542340 | BB9: 0 | BC9: 0 | BD9: 0 | BE9: 8542340 | BF9: 0 | BG9: 0 | BH9: 0 | BI9: 0 | BJ9: 8542340 | BM9: 0 | BN9: 0 | BO9: 0 | BP9: 0 | BQ9: 0 | BR9: 0 | BS9: 30786942
A10: 043554 | B10: Beachwood City SD | C10: Cuyahoga | D10: 24715866 | E10: 3846 | F10: 0 | G10: 1037797 | H10: 100000 | I10: 0 | J10: 4248645 | K10: 3113844 | L10: 33219999 | M10: 0 | N10: 0 | O10: 0 | P10: 0 | Q10: 2500 | R10: 2500 | S10: 33222499 | T10: 18353780 | U10: 6299606 | V10: 4730740 | W10: 1078878 | X10: 972741 | Y10: 0 | Z10: 0 | AA10: 0 | AB10: 0 | AC10: 0 | AD10: 0 | AE10: 0 | AF10: 0 | AG10: 546116 | AH10: 31981860 | AI10: 801566 | AJ10: 0 | AK10: 0 | AL10: 801566 | AM10: 32783426 | AN10: 439072 | AO10: 18918953 | AP10: 19358025 | AQ10: 300000 | AR10: 0 | AS10: 0 | AT10: 134873 | AU10: 0 | AW10: 0 | AX10: 0 | AY10: 0 | AZ10: 134873 | BA10: 18923152 | BB10: 0 | BC10: 0 | BD10: 0 | BE10: 18923152 | BF10: 0 | BG10: 0 | BH10: 0 | BI10: 0 | BJ10: 18923152 | BK10: 85 | BL10: 1536 | BS10: 33222499
A11: 043562 | B11: Bedford City SD | C11: Cuyahoga | D11: 24500915 | E11: 2576436 | F11: 0 | G11: 6548130 | H11: 126491 | I11: 0 | J11: 8647318 | K11: 1882156 | L11: 44281446 | M11: 0 | N11: 0 | O11: 0 | P11: 1500000 | Q11: 100000 | R11: 1600000 | S11: 45881446 | T11: 25528989 | U11: 9337008 | V11: 8120005 | W11: 1553994 | X11: 963125 | Y11: 0 | Z11: 0 | AA11: 68644 | AB11: 0 | AC11: 0 | AD11: 230515 | AE11: 102807 | AF11: 96069 | AG11: 792730 | AH11: 46793886 | AI11: 422700 | AJ11: 1000000 | AK11: 0 | AL11: 1422700 | AM11: 48216586 | AN11: -2335140 | AO11: 16019872 | AP11: 13684732 | AQ11: 750000 | AR11: 0 | AS11: 0 | AT11: 0 | AU11: 0 | AV11: 0 | AW11: 0 | AX11: 0 | AY11: 0 | AZ11: 0 | BA11: 12934732 | BB11: 0 | BC11: 0 | BD11: 0 | BE11: 12934732 | BF11: 0 | BG11: 0 | BH11: 0 | BI11: 0 | BJ11: 12934732 | BM11: 0 | BN11: 0 | BO11: 0 | BP11: 0 | BQ11: 0 | BR11: 0 | BS11: 48216586
A12: 043570 | B12: Bellaire Local SD | C12: Belmont | D12: 2110000 | E12: 0 | F12: 0 | G12: 9207000 | H12: 26000 | I12: 0 | J12: 351000 | K12: 1010000 | L12: 12704000 | M12: 0 | N12: 0 | O12: 0 | P12: 0 | Q12: 0 | R12: 0 | S12: 12704000 | T12: 5150000 | U12: 2712000 | V12: 2250000 | W12: 435000 | X12: 300000 | Y12: 0 | Z12: 0 | AA12: 0 | AB12: 0 | AC12: 887500 | AD12: 0 | AE12: 0 | AF12: 0 | AG12: 236640 | AH12: 11971140 | AI12: 0 | AJ12: 0 | AK12: 0 | AL12: 0 | AM12: 11971140 | AN12: 732860 | AO12: 381000 | AP12: 1113860 | AQ12: 150000 | AR12: 0 | AS12: 0 | AT12: 0 | AU12: 0 | AV12: 0 | AW12: 0 | AX12: 0 | AY12: 0 | AZ12: 0 | BA12: 963860 | BB12: 0 | BC12: 0 | BD12: 0 | BE12: 963860 | BF12: 0 | BG12: 0 | BH12: 0 | BI12: 0 | BJ12: 963860 | BK12: 0 | BL12: 0 | BM12: 0 | BN12: 0 | BO12: 0 | BP12: 0 | BQ12: 0 | BR12: 0 | BS12: 12704000
A13: 043588 | B13: Bellefontaine City SD | C13: Logan | D13: 6696000 | E13: 0 | F13: 0 | G13: 13022169 | H13: 42900 | I13: 0 | J13: 1205392 | K13: 1249000 | L13: 22215461 | M13: 0 | N13: 0 | O13: 0 | P13: 0 | Q13: 0 | R13: 0 | S13: 22215461 | T13: 12595348 | U13: 5059216 | V13: 3377355 | W13: 489721 | X13: 123235 | Y13: 0 | Z13: 0 | AA13: 0 | AB13: 0 | AC13: 0 | AD13: 0 | AE13: 0 | AF13: 0 | AG13: 356472 | AH13: 22001347 | AI13: 50000 | AJ13: 0 | AK13: 0 | AL13: 50000 | AM13: 22051347 | AN13: 164114 | AO13: 7422784 | AP13: 7586898 | AQ13: 42000 | AR13: 225904 | AS13: 0 | AT13: 198858 | AU13: 0 | AV13: 0 | AW13: 0 | AX13: 0 | AY13: 0 | AZ13: 424762 | BA13: 7120136 | BB13: 0 | BC13: 0 | BD13: 0 | BE13: 7120136 | BF13: 0 | BG13: 0 | BH13: 0 | BI13: 0 | BJ13: 7120136 | BK13: 213 | BL13: 2430 | BM13: 0 | BN13: 0 | BO13: 0 | BP13: 0 | BQ13: 0 | BR13: 0 | BS13: 22215461
A14: 043596 | B14: Bellevue City SD | C14: Huron | D14: 6475000 | E14: 0 | F14: 1287000 | G14: 9274984 | H14: 110000 | I14: 0 | J14: 1265857 | K14: 609400 | L14: 19022241 | M14: 0 | N14: 0 | O14: 0 | P14: 204241 | Q14: 69355 | R14: 273596 | S14: 19295837 | T14: 10642833 | U14: 3916225 | V14: 3636585 | W14: 812993 | X14: 91340 | Y14: 0 | Z14: 0 | AA14: 0 | AB14: 0 | AC14: 0 | AD14: 69116 | AE14: 0 | AF14: 4090 | AG14: 285255 | AH14: 19458437 | AI14: 10794 | AJ14: 200000 | AK14: 12000 | AL14: 222794 | AM14: 19681231 | AN14: -385394 | AO14: 5406471 | AP14: 5021077 | AQ14: 0 | AR14: 0 | AS14: 0 | AT14: 0 | AU14: 0 | AV14: 0 | AW14: 0 | AX14: 0 | AY14: 0 | AZ14: 0 | BA14: 5021077 | BB14: 0 | BC14: 0 | BD14: 0 | BE14: 5021077 | BF14: 0 | BG14: 0 | BH14: 0 | BI14: 0 | BJ14: 5021077 | BK14: 164 | BL14: 1871 | BM14: 0 | BN14: 0 | BO14: 0 | BP14: 0 | BQ14: 0 | BR14: 0 | BS14: 19681231
A15: 043604 | B15: Belpre City SD | C15: Washington | D15: 3099927 | E15: 244927 | F15: 0 | G15: 2680478 | H15: 1149 | I15: 0 | J15: 2696763 | K15: 650578 | L15: 9373822 | M15: 0 | N15: 0 | O15: 0 | P15: 93266 | Q15: 10000 | R15: 103266 | S15: 9477088 | T15: 4709580 | U15: 2221070 | V15: 2129356 | W15: 389726 | X15: 252448 | Y15: 0 | Z15: 0 | AA15: 0 | AB15: 0 | AC15: 0 | AD15: 0 | AE15: 0 | AF15: 11924 | AG15: 172306 | AH15: 9886410 | AI15: 10000 | AJ15: 3000 | AK15: 0 | AL15: 13000 | AM15: 9899410 | AN15: -422322 | AO15: 1387376 | AP15: 965054 | AQ15: 125000 | AR15: 0 | AS15: 0 | AT15: 299082 | AU15: 0 | AV15: 0 | AW15: 0 | AX15: 0 | AY15: 5944 | AZ15: 305026 | BA15: 535028 | BB15: 0 | BC15: 0 | BD15: 0 | BE15: 535028 | BF15: 0 | BG15: 0 | BH15: 0 | BI15: 0 | BJ15: 535028 | BM15: 0 | BN15: 0 | BO15: 0 | BP15: 0 | BQ15: 0 | BR15: 0 | BS15: 9899410
A16: 043612 | B16: Berea City SD | C16: Cuyahoga | D16: 50974997 | E16: 2395966 | F16: 0 | G16: 8150147 | H16: 141039 | I16: 0 | J16: 14951352 | K16: 4219051 | L16: 80832552 | M16: 0 | N16: 0 | O16: 0 | P16: 160004 | Q16: 0 | R16: 160004 | S16: 80992556 | T16: 44394291 | U16: 22816619 | V16: 9801372 | W16: 2039769 | X16: 276715 | Y16: 0 | Z16: 0 | AA16: 0 | AB16: 0 | AC16: 0 | AD16: 0 | AE16: 525000 | AF16: 1171995 | AG16: 609358 | AH16: 81635119 | AI16: 200000 | AJ16: 160000 | AK16: 0 | AL16: 360000 | AM16: 81995119 | AN16: -1002564 | AO16: 2221730 | AP16: 1219166 | AQ16: 0 | AR16: 0 | AS16: 0 | AT16: 0 | AU16: 0 | AV16: 0 | AW16: 0 | AX16: 0 | AY16: 0 | AZ16: 0 | BA16: 1219166 | BB16: 0 | BC16: 0 | BD16: 0 | BE16: 1219166 | BF16: 0 | BG16: 0 | BH16: 0 | BI16: 0 | BJ16: 1219166 | BM16: 0 | BN16: 0 | BO16: 0 | BP16: 0 | BQ16: 0 | BR16: 0 | BS16: 81995119
A17: 043620 | B17: Bexley City SD | C17: Franklin | D17: 19933000 | E17: 0 | F17: 6300000 | G17: 3950000 | I17: 0 | J17: 2760000 | K17: 280000 | L17: 33223000 | M17: 0 | P17: 38456 | Q17: 20000 | R17: 58456 | T17: 18340000 | U17: 7030000 | V17: 4520000 | W17: 1364000 | X17: 676000 | AG17: 570000 | AH17: 32500000 | AI17: 362921 | AJ17: 50000 | AL17: 414721 | AM17: 32914721 | AN17: 366735 | AO17: 21029924 | AP17: 21396659 | AQ17: 1000000 | AX17: 1900000 | AZ17: 1900000 | BA17: 18496659 | BE17: 18496659 | BJ17: 18496659 | BK17: 163 | BL17: 1992 | BO17: 0 | BP17: 0 | BQ17: 0 | BR17: 0 | BS17: 33223000
A18: 043638 | B18: Bowling Green City SD | C18: Wood | D18: 15469104 | E18: 0 | F18: 2958531 | G18: 6882599 | H18: 167011 | I18: 0 | J18: 3207838 | K18: 443000 | L18: 29128083 | M18: 0 | N18: 0 | O18: 0 | P18: 0 | Q18: 0 | R18: 0 | S18: 29128083 | T18: 16854639 | U18: 6737199 | V18: 3879400 | W18: 1307800 | X18: 210000 | Y18: 0 | Z18: 0 | AA18: 0 | AB18: 0 | AC18: 0 | AD18: 0 | AE18: 0 | AF18: 0 | AG18: 1260450 | AH18: 30249488 | AI18: 301000 | AJ18: 0 | AK18: 0 | AL18: 301000 | AM18: 30550488 | AN18: -1422405 | AO18: 5320157 | AP18: 3897752 | AQ18: 55000 | AR18: 0 | AS18: 0 | AT18: 500000 | AU18: 0 | AV18: 0 | AW18: 0 | AX18: 0 | AY18: 0 | AZ18: 500000 | BA18: 3342752 | BB18: 0 | BC18: 0 | BD18: 0 | BE18: 3342752 | BF18: 0 | BG18: 0 | BH18: 0 | BI18: 0 | BJ18: 3342752 | BM18: 11240 | BN18: 3406 | BO18: 0 | BP18: 0 | BQ18: 0 | BR18: 14646 | BS18: 30550488
A19: 043646 | B19: Brecksville-Broadview Heights City SD | C19: Cuyahoga | D19: 30394054 | E19: 1802360 | F19: 0 | G19: 5223756 | H19: 105262 | I19: 0 | J19: 5751285 | K19: 1577134 | L19: 44853851 | M19: 0 | N19: 0 | O19: 0 | P19: 110000 | Q19: 95521 | R19: 205521 | S19: 45059372 | T19: 29985681 | U19: 9305318 | V19: 4406144 | W19: 1186851 | X19: 257334 | Y19: 0 | Z19: 0 | AA19: 0 | AB19: 0 | AC19: 0 | AD19: 323005 | AE19: 0 | AF19: 3230 | AG19: 815223 | AH19: 46282786 | AI19: 75960 | AJ19: 110000 | AK19: 0 | AL19: 185960 | AM19: 46468746 | AN19: -1409374 | AO19: 10256825 | AP19: 8847451 | AQ19: 272371 | AR19: 0 | AS19: 0 | AT19: 0 | AU19: 0 | AV19: 0 | AW19: 0 | AX19: 0 | AY19: 0 | AZ19: 0 | BA19: 8575080 | BB19: 0 | BC19: 0 | BD19: 0 | BE19: 8575080 | BF19: 0 | BG19: 0 | BH19: 0 | BI19: 0 | BJ19: 8575080 | BM19: 0 | BN19: 0 | BO19: 0 | BP19: 0 | BQ19: 0 | BR19: 0 | BS19: 46468746
A20: 043653 | B20: Brooklyn City SD | C20: Cuyahoga | D20: 9284567 | E20: 900808 | F20: 0 | G20: 760000 | H20: 0 | I20: 0 | J20: 2101607 | K20: 575000 | L20: 13621982 | M20: 0 | N20: 0 | O20: 0 | P20: 351740 | Q20: 0 | R20: 351740 | S20: 13973722 | T20: 9040181 | U20: 2983260 | V20: 2644216 | W20: 245245 | X20: 50000 | Y20: 0 | Z20: 0 | AA20: 0 | AB20: 0 | AC20: 0 | AD20: 0 | AE20: 0 | AF20: 0 | AG20: 400000 | AH20: 15362902 | AI20: 0 | AJ20: 0 | AK20: 0 | AL20: 0 | AM20: 15362902 | AN20: -1389180 | AO20: 2569336 | AP20: 1180156 | AQ20: 0 | AR20: 0 | AS20: 0 | AT20: 0 | AU20: 0 | AV20: 0 | AW20: 0 | AX20: 0 | AY20: 0 | AZ20: 0 | BA20: 1180156 | BB20: 0 | BC20: 1127000 | BD20: 1127000 | BE20: 2307156 | BF20: 0 | BG20: 0 | BH20: 0 | BI20: 0 | BJ20: 2307156 | BM20: 0 | BN20: 0 | BO20: 0 | BP20: 0 | BQ20: 0 | BR20: 0 | BS20: 15362902
A21: 043661 | B21: Brunswick City SD | C21: Medina | D21: 32169823 | E21: 992411 | F21: 0 | G21: 22129000 | H21: 72000 | I21: 102000 | J21: 4928693 | K21: 1212500 | L21: 61606427 | M21: 0 | N21: 0 | O21: 0 | P21: 900000 | Q21: 0 | R21: 900000 | S21: 62506427 | T21: 39600000 | U21: 15648000 | V21: 6036198 | W21: 2732160 | X21: 245270 | Y21: 0 | Z21: 0 | AA21: 0 | AB21: 0 | AC21: 0 | AD21: 0 | AE21: 60865 | AF21: 16263 | AG21: 1098391 | AH21: 65437147 | AI21: 0 | AJ21: 0 | AK21: 0 | AL21: 0 | AM21: 65437146 | AN21: -2930719 | AO21: 4080689 | AP21: 1149970 | AQ21: 922226 | AR21: 0 | AS21: 0 | AT21: 0 | AU21: 0 | AW21: 0 | AX21: 0 | AY21: 0 | AZ21: 0 | BA21: 227744 | BB21: 0 | BC21: 0 | BD21: 0 | BE21: 227744 | BF21: 0 | BG21: 2478000 | BH21: 2478000 | BI21: 0 | BJ21: 2705744 | BS21: 65437147
A22: 043679 | B22: Bryan City SD | C22: Williams | D22: 6400000 | E22: 0 | F22: 2825000 | G22: 5609000 | H22: 38500 | I22: 0 | J22: 2338000 | K22: 1263800 | L22: 18474300 | M22: 0 | N22: 0 | O22: 0 | P22: 0 | Q22: 2000 | R22: 2000 | S22: 18476300 | T22: 11391255 | U22: 4257453 | V22: 2392776 | W22: 500619 | X22: 0 | Y22: 0 | Z22: 0 | AA22: 0 | AB22: 0 | AC22: 0 | AD22: 0 | AE22: 0 | AF22: 0 | AG22: 256465 | AH22: 18798568 | AI22: 157185 | AJ22: 0 | AK22: 0 | AL22: 157185 | AM22: 18955753 | AN22: -479453 | AO22: 9689298 | AP22: 9209845 | AQ22: 100000 | AR22: 0 | AS22: 0 | AT22: 0 | AU22: 0 | AV22: 0 | AW22: 0 | AX22: 0 | AY22: 0 | AZ22: 0 | BA22: 9109845 | BB22: 0 | BC22: 0 | BD22: 0 | BE22: 9109845 | BF22: 0 | BG22: 0 | BH22: 0 | BI22: 0 | BJ22: 9109845 | BK22: 180 | BL22: 1820 | BM22: 0 | BN22: 0 | BO22: 0 | BP22: 0 | BQ22: 0 | BR22: 0 | BS22: 18955753
A23: 043687 | B23: Bucyrus City SD | C23: Crawford | D23: 3441014 | E23: 367687 | F23: 0 | G23: 8941326 | H23: 44074 | I23: 0 | J23: 808315 | K23: 741147 | L23: 14343563 | M23: 0 | N23: 0 | O23: 0 | P23: 0 | Q23: 9700 | R23: 9700 | S23: 14353263 | T23: 7108167 | U23: 3104105 | V23: 3848256 | W23: 218874 | X23: 13430 | Y23: 0 | Z23: 0 | AA23: 0 | AB23: 0 | AC23: 0 | AD23: 0 | AE23: 0 | AF23: 0 | AG23: 224406 | AH23: 14517238 | AI23: 25000 | AJ23: 0 | AK23: 0 | AL23: 25000 | AM23: 14542238 | AN23: -188975 | AO23: 4372247 | AP23: 4183272 | AQ23: 100000 | AR23: 0 | AS23: 0 | AT23: 0 | AU23: 0 | AV23: 0 | AW23: 0 | AX23: 0 | AY23: 0 | AZ23: 0 | BA23: 4083272 | BB23: 0 | BC23: 0 | BD23: 0 | BE23: 4083272 | BF23: 0 | BG23: 0 | BH23: 0 | BI23: 0 | BJ23: 4083272 | BS23: 14542238
A24: 043695 | B24: Cambridge City SD | C24: Guernsey | D24: 4778699 | E24: 738456 | F24: 0 | G24: 13297382 | H24: 24856 | I24: 0 | J24: 841480 | K24: 1026516 | L24: 20707389 | M24: 0 | N24: 0 | O24: 0 | P24: 0 | Q24: 51484 | R24: 51484 | S24: 20758873 | T24: 10565722 | U24: 5141650 | V24: 3921407 | W24: 677263 | X24: 125333 | Y24: 0 | Z24: 0 | AA24: 0 | AB24: 0 | AC24: 0 | AD24: 0 | AE24: 0 | AF24: 0 | AG24: 446520 | AH24: 20877895 | AI24: 0 | AJ24: 0 | AK24: 0 | AL24: 0 | AM24: 20877895 | AN24: -119022 | AO24: 1327072 | AP24: 1208050 | AQ24: 500000 | AR24: 0 | AS24: 0 | AT24: 0 | AU24: 0 | AV24: 0 | AW24: 0 | AX24: 0 | AY24: 0 | AZ24: 0 | BA24: 708050 | BB24: 0 | BC24: 0 | BD24: 0 | BE24: 708050 | BF24: 0 | BG24: 0 | BH24: 0 | BI24: 0 | BJ24: 708050 | BM24: 0 | BN24: 0 | BO24: 0 | BP24: 0 | BQ24: 0 | BR24: 0 | BS24: 20877895
A25: 043703 | B25: Campbell City SD | C25: Mahoning | D25: 1846781 | E25: 0 | F25: 0 | G25: 10706030 | H25: 84256 | I25: 0 | J25: 504346 | K25: 300000 | L25: 13441413 | M25: 0 | N25: 0 | O25: 0 | P25: 39984 | Q25: 0 | R25: 39984 | S25: 13481397 | T25: 7416222 | U25: 2644403 | V25: 2783064 | W25: 303556 | X25: 0 | Y25: 0 | Z25: 0 | AA25: 0 | AB25: 0 | AC25: 0 | AD25: 0 | AE25: 144000 | AF25: 92711 | AG25: 79857 | AH25: 13463813 | AI25: 0 | AJ25: 30000 | AK25: 0 | AL25: 30000 | AM25: 13493813 | AN25: -12416 | AO25: 308684 | AP25: 296268 | AQ25: 20000 | AR25: 0 | AS25: 0 | AT25: 0 | AU25: 0 | AV25: 0 | AW25: 0 | AX25: 0 | AY25: 0 | AZ25: 0 | BA25: 276268 | BB25: 0 | BC25: 0 | BD25: 0 | BE25: 276268 | BF25: 0 | BG25: 0 | BH25: 0 | BI25: 0 | BJ25: 276268 | BK25: 106 | BL25: 1138 | BM25: 0 | BN25: 0 | BO25: 0 | BP25: 0 | BQ25: 0 | BR25: 0 | BS25: 13493813
A26: 043711 | B26: Canton City SD | C26: Stark | D26: 20500000 | E26: 3098350 | F26: 0 | G26: 70844928 | H26: 1067166 | I26: 0 | J26: 6336410 | K26: 1800000 | L26: 103646854 | M26: 0 | N26: 0 | O26: 0 | P26: 0 | Q26: 400000 | R26: 400000 | S26: 104046854 | T26: 59498881 | U26: 22751165 | V26: 22000000 | W26: 3000000 | X26: 1200000 | Y26: 0 | Z26: 0 | AA26: 0 | AB26: 0 | AC26: 0 | AD26: 0 | AE26: 0 | AF26: 0 | AG26: 750000 | AH26: 109200046 | AI26: 1350000 | AJ26: 0 | AK26: 20000 | AL26: 1370000 | AM26: 110570046 | AN26: -6523192 | AO26: 14142407 | AP26: 7619215 | AQ26: 2700000 | AR26: 0 | AS26: 0 | AT26: 0 | AU26: 0 | AV26: 0 | AW26: 0 | AX26: 0 | AY26: 0 | AZ26: 0 | BA26: 4919215 | BB26: 0 | BC26: 0 | BD26: 0 | BE26: 4919215 | BF26: 0 | BG26: 0 | BH26: 0 | BI26: 0 | BJ26: 4919215 | BK26: 0 | BL26: 0 | BM26: 0 | BN26: 0 | BO26: 0 | BP26: 0 | BQ26: 0 | BR26: 0 | BS26: 110570046
A27: 043729 | B27: Celina City SD | C27: Mercer | D27: 10577176 | E27: 302221 | F27: 2296746 | G27: 10313686 | H27: 126075 | I27: 0 | J27: 1629575 | K27: 1645569 | L27: 26891048 | M27: 0 | N27: 0 | O27: 0 | P27: 771500 | Q27: 50000 | R27: 821500 | S27: 27712548 | T27: 14877336 | U27: 7162534 | V27: 3988241 | W27: 940640 | X27: 304806 | Y27: 0 | Z27: 0 | AA27: 0 | AB27: 0 | AC27: 0 | AD27: 0 | AE27: 0 | AF27: 0 | AG27: 452284 | AH27: 27725841 | AI27: 25000 | AJ27: 400000 | AK27: 25000 | AL27: 450000 | AM27: 28175841 | AN27: -463293 | AO27: 6838984 | AP27: 6375691 | AQ27: 0 | AR27: 0 | AS27: 0 | AT27: 0 | AU27: 0 | AV27: 0 | AW27: 0 | AX27: 0 | AY27: 0 | AZ27: 0 | BA27: 6375691 | BB27: 0 | BC27: 0 | BD27: 0 | BE27: 6375691 | BF27: 0 | BG27: 0 | BH27: 0 | BI27: 0 | BJ27: 6375691 | BK27: 196 | BL27: 2469 | BM27: 0 | BN27: 0 | BO27: 0 | BP27: 0 | BQ27: 0 | BR27: 0 | BS27: 28175841
A28: 043737 | B28: Centerville City SD | C28: Montgomery | D28: 55500000 | E28: 2100000 | F28: 0 | G28: 11213500 | H28: 186500 | I28: 261184 | J28: 8000000 | K28: 3400000 | L28: 80661184 | M28: 0 | N28: 0 | O28: 0 | P28: 0 | Q28: 0 | R28: 0 | S28: 80661184 | T28: 52988332 | U28: 24982713 | V28: 4938643 | W28: 2157189 | X28: 66500 | Y28: 0 | Z28: 0 | AA28: 0 | AB28: 0 | AC28: 0 | AD28: 0 | AE28: 0 | AF28: 0 | AG28: 800000 | AH28: 85933377 | AI28: 0 | AJ28: 0 | AK28: 0 | AL28: 0 | AM28: 85933377 | AN28: -5272193 | AO28: 15903864 | AP28: 10631671 | AQ28: 400000 | AR28: 0 | AS28: 0 | AT28: 0 | AU28: 0 | AV28: 0 | AW28: 0 | AX28: 0 | AY28: 0 | AZ28: 0 | BA28: 10231671 | BB28: 0 | BC28: 4631750 | BD28: 4631750 | BE28: 14863421 | BF28: 0 | BG28: 0 | BH28: 0 | BI28: 0 | BJ28: 14863421 | BK28: 0 | BL28: 0 | BM28: 0 | BN28: 0 | BO28: 0 | BP28: 0 | BQ28: 0 | BR28: 0 | BS28: 85933377
A29: 043745 | B29: Chillicothe City SD | C29: Ross | D29: 9851977 | E29: 1100124 | F29: 0 | G29: 11616217 | H29: 0 | I29: 0 | J29: 3824076 | K29: 1533984 | L29: 27926378 | M29: 0 | N29: 0 | O29: 0 | P29: 606 | Q29: 95299 | R29: 95905 | S29: 28022283 | T29: 13014047 | U29: 5820896 | V29: 6373321 | W29: 426348 | X29: 0 | Y29: 0 | Z29: 0 | AA29: 0 | AB29: 0 | AC29: 0 | AD29: 0 | AE29: 0 | AF29: 0 | AG29: 521399 | AH29: 26156011 | AI29: 2000000 | AJ29: 0 | AK29: 0 | AL29: 2000000 | AM29: 28156011 | AN29: -133728 | AO29: 2525688 | AP29: 2391960 | AQ29: 150000 | AR29: 0 | AS29: 0 | AT29: 0 | AU29: 0 | AV29: 0 | AW29: 0 | AX29: 0 | AY29: 0 | AZ29: 0 | BA29: 2241960 | BB29: 0 | BC29: 0 | BD29: 0 | BE29: 2241960 | BF29: 0 | BG29: 0 | BH29: 0 | BI29: 0 | BJ29: 2241960 | BK29: 230 | BL29: 2616 | BM29: 0 | BN29: 0 | BO29: 0 | BP29: 0 | BQ29: 0 | BR29: 0 | BS29: 28156011
A30: 043752 | B30: Cincinnati City SD | C30: Hamilton | D30: 224722049 | E30: 22221945 | F30: 0 | G30: 155346931 | H30: 1082347 | I30: 0 | J30: 35698761 | K30: 10744412 | L30: 449816445 | M30: 0 | N30: 0 | O30: 0 | P30: 24346567 | Q30: 3500000 | R30: 27846567 | S30: 477663012 | T30: 192380454 | U30: 75504424 | V30: 167981228 | W30: 7422292 | X30: 3804847 | Y30: 0 | Z30: 0 | AA30: 0 | AB30: 0 | AC30: 0 | AD30: 2183072 | AE30: 4455000 | AF30: 5435236 | AG30: 6057690 | AH30: 465224243 | AI30: 18085480 | AJ30: 12500000 | AK30: 0 | AL30: 30585480 | AM30: 495809723 | AN30: -18146711 | AO30: 56898627 | AP30: 38751916 | AQ30: 12500000 | AR30: 0 | AS30: 0 | AT30: 0 | AU30: 0 | AV30: 0 | AW30: 0 | AX30: 0 | AY30: 0 | AZ30: 0 | BA30: 26251916 | BB30: 0 | BC30: 0 | BD30: 0 | BE30: 26251916 | BF30: 0 | BG30: 0 | BH30: 0 | BI30: 0 | BJ30: 26251916 | BS30: 495809723
A31: 043760 | B31: Circleville City SD | C31: Pickaway | D31: 7150000 | E31: 615000 | F31: 1575000 | G31: 9475000 | H31: 0 | I31: 0 | J31: 1435000 | K31: 970000 | L31: 21220000 | M31: 0 | N31: 0 | O31: 0 | P31: 449370 | Q31: 107165 | R31: 556535 | S31: 21776535 | T31: 12750000 | U31: 5100000 | V31: 2300000 | W31: 620000 | X31: 2500000 | Y31: 0 | Z31: 0 | AA31: 0 | AB31: 0 | AC31: 0 | AD31: 21000 | AE31: 0 | AF31: 11054 | AG31: 582840 | AH31: 23884894 | AI31: 130000 | AJ31: 250000 | AK31: 120000 | AL31: 500000 | AM31: 24384894 | AN31: -2608359 | AO31: 15265224 | AP31: 12656865 | AQ31: 0 | AR31: 0 | AS31: 0 | AT31: 0 | AU31: 0 | AV31: 0 | AW31: 0 | AX31: 0 | AY31: 0 | AZ31: 0 | BA31: 12656865 | BB31: 0 | BC31: 0 | BD31: 0 | BE31: 12656865 | BF31: 0 | BG31: 0 | BH31: 0 | BI31: 0 | BJ31: 12656865 | BK31: 170 | BL31: 1904 | BM31: 0 | BN31: 0 | BO31: 0 | BP31: 0 | BQ31: 0 | BR31: 0 | BS31: 24384894
A32: 043778 | B32: Claymont City SD | C32: Tuscarawas | D32: 2777660 | E32: 315797 | F32: 0 | G32: 13578260 | H32: 61189 | I32: 0 | J32: 507709 | K32: 1285138 | L32: 18525753 | M32: 0 | N32: 0 | O32: 0 | P32: 10000 | Q32: 0 | R32: 10000 | S32: 18535753 | T32: 10168598 | U32: 4768669 | V32: 2535609 | W32: 530672 | X32: 220296 | Y32: 0 | Z32: 0 | AA32: 0 | AB32: 0 | AC32: 0 | AD32: 0 | AE32: 0 | AF32: 0 | AG32: 138880 | AH32: 18362724 | AI32: 0 | AJ32: 10000 | AK32: 0 | AL32: 10000 | AM32: 18372724 | AN32: 163029 | AO32: 3114120 | AP32: 3277149 | AQ32: 100000 | AR32: 0 | AS32: 0 | AT32: 0 | AU32: 0 | AV32: 0 | AW32: 0 | AX32: 0 | AY32: 0 | AZ32: 0 | BA32: 3177149 | BB32: 0 | BC32: 0 | BD32: 0 | BE32: 3177149 | BF32: 0 | BG32: 0 | BH32: 0 | BI32: 0 | BJ32: 3177149 | BK32: 131 | BL32: 1925 | BM32: 0 | BN32: 0 | BO32: 0 | BP32: 0 | BQ32: 0 | BR32: 0 | BS32: 18535753
A33: 043786 | B33: Cleveland Municipal SD | C33: Cuyahoga | D33: 199907447 | E33: 57169 | F33: 0 | G33: 425495955 | H33: 2877105 | I33: 0 | J33: 32078830 | K33: 33061609 | L33: 693478115 | M33: 0 | N33: 0 | O33: 0 | P33: 9690000 | Q33: 0 | R33: 9690000 | S33: 703168115 | T33: 307476059 | U33: 124535995 | V33: 237681608 | W33: 12330728 | X33: 1540287 | Y33: 0 | Z33: 0 | AA33: 0 | AB33: 0 | AC33: 0 | AD33: 964162 | AE33: 0 | AF33: 272840 | AG33: 6900454 | AH33: 691702133 | AI33: 944394 | AJ33: 0 | AK33: 0 | AL33: 944394 | AM33: 692646527 | AN33: 10521588 | AO33: 69349024 | AP33: 79870613 | AQ33: 12000000 | AR33: 0 | AS33: 0 | AT33: 0 | AU33: 0 | AV33: 0 | AW33: 0 | AX33: 0 | AY33: 0 | AZ33: 0 | BA33: 67870613 | BB33: 0 | BC33: 0 | BD33: 0 | BE33: 67870613 | BF33: 0 | BG33: 0 | BH33: 0 | BI33: 0 | BJ33: 67870613 | BS33: 703168115
A34: 043794 | B34: Cleve. Hts.-Univ. Hts. City SD | C34: Cuyahoga | D34: 68600000 | E34: 0 | F34: 0 | G34: 19000000 | H34: 0 | I34: 0 | J34: 9435000 | K34: 4865000 | L34: 101900000 | M34: 0 | N34: 0 | O34: 0 | P34: 9135000 | Q34: 0 | R34: 9135000 | S34: 111035000 | T34: 55198013 | U34: 22897763 | V34: 15227747 | W34: 2585872 | X34: 2062765 | Y34: 0 | Z34: 0 | AA34: 0 | AB34: 0 | AC34: 0 | AD34: 0 | AE34: 0 | AF34: 0 | AG34: 2175000 | AH34: 100147160 | AI34: 750000 | AJ34: 0 | AK34: 0 | AL34: 750000 | AM34: 100897160 | AN34: 10137840 | AO34: 21711469 | AP34: 31849309 | AQ34: 3295575 | AR34: 0 | AS34: 0 | AT34: 0 | AU34: 0 | AV34: 0 | AW34: 0 | AX34: 0 | AY34: 0 | AZ34: 0 | BA34: 28553734 | BB34: 0 | BC34: 0 | BD34: 0 | BE34: 28553734 | BF34: 0 | BG34: 0 | BH34: 0 | BI34: 0 | BJ34: 28553734 | BM34: 0 | BN34: 0 | BO34: 0 | BP34: 0 | BQ34: 0 | BR34: 0 | BS34: 111035000
A35: 043802 | B35: Columbus City SD | C35: Franklin | D35: 398244352 | E35: 238334 | F35: 0 | G35: 254479868 | H35: 2415583 | I35: 707899 | J35: 61843258 | K35: 15634244 | L35: 733563538 | M35: 0 | N35: 0 | O35: 1515961 | P35: 30000000 | Q35: 150000 | R35: 31665961 | S35: 765229499 | T35: 383141102 | U35: 155896988 | V35: 183389964 | W35: 19267061 | X35: 2332877 | Y35: 0 | Z35: 0 | AA35: 0 | AB35: 0 | AC35: 0 | AD35: 965000 | AE35: 637935 | AF35: 1284977 | AG35: 14417054 | AH35: 761332958 | AI35: 3777141 | AJ35: 30000000 | AK35: 0 | AL35: 33777141 | AM35: 795110099 | AN35: -29880600 | AO35: 120605461 | AP35: 90724861 | AQ35: 8000000 | AR35: 0 | AS35: 0 | AT35: 0 | AU35: 0 | AV35: 0 | AW35: 0 | AX35: 0 | AY35: 0 | AZ35: 0 | BA35: 82724861 | BB35: 0 | BC35: 0 | BD35: 0 | BE35: 82724861 | BF35: 0 | BG35: 0 | BH35: 0 | BI35: 0 | BJ35: 82724861 | BS35: 795110099
A36: 043810 | B36: Conneaut Area City SD | C36: Ashtabula | D36: 3756096 | E36: 222851 | F36: 0 | G36: 11261451 | H36: 38590 | I36: 0 | J36: 577212 | K36: 431698 | L36: 16287898 | M36: 0 | N36: 0 | O36: 0 | P36: 25000 | Q36: 119744 | R36: 144744 | S36: 16432642 | T36: 9223423 | U36: 4191440 | V36: 2733800 | W36: 329605 | X36: 160217 | Y36: 0 | Z36: 0 | AA36: 0 | AB36: 0 | AC36: 0 | AD36: 110000 | AE36: 0 | AF36: 4019 | AG36: 335635 | AH36: 17088139 | AI36: 10000 | AJ36: 25000 | AK36: 0 | AL36: 35000 | AM36: 17123139 | AN36: -690497 | AO36: 2937988 | AP36: 2247491 | AQ36: 150000 | AR36: 0 | AS36: 0 | AT36: 0 | AU36: 0 | AV36: 0 | AW36: 0 | AX36: 0 | AY36: 0 | AZ36: 0 | BA36: 2097491 | BB36: 0 | BC36: 0 | BD36: 0 | BE36: 2097491 | BF36: 0 | BG36: 0 | BH36: 0 | BI36: 0 | BJ36: 2097491 | BK36: 0 | BL36: 0 | BM36: 0 | BN36: 0 | BO36: 0 | BP36: 0 | BQ36: 0 | BR36: 0 | BS36: 17123139
A37: 043828 | B37: Coshocton City SD | C37: Coshocton | D37: 4506394 | E37: 405532 | F37: 0 | G37: 8774161 | H37: 39074 | I37: 0 | J37: 919649 | K37: 1034870 | L37: 15679680 | M37: 0 | N37: 0 | O37: 0 | P37: 0 | Q37: 0 | R37: 0 | S37: 15679680 | T37: 8701337 | U37: 3477100 | V37: 2550675 | W37: 626373 | X37: 88000 | Y37: 0 | Z37: 0 | AA37: 0 | AB37: 0 | AC37: 0 | AD37: 23691 | AE37: 0 | AF37: 12974 | AG37: 256576 | AH37: 15736726 | AI37: 0 | AJ37: 35000 | AK37: 0 | AL37: 35000 | AM37: 15771726 | AN37: -92046 | AO37: 2075025 | AP37: 1982979 | AQ37: 275000 | AR37: 0 | AS37: 0 | AT37: 0 | AU37: 0 | AV37: 0 | AW37: 0 | AX37: 0 | AY37: 0 | AZ37: 0 | BA37: 1707979 | BB37: 0 | BC37: 0 | BD37: 0 | BE37: 1707979 | BF37: 0 | BG37: 0 | BH37: 0 | BI37: 0 | BJ37: 1707979 | BK37: 135 | BL37: 1692 | BM37: 0 | BN37: 0 | BO37: 0 | BP37: 0 | BQ37: 0 | BR37: 0 | BS37: 15771726
A38: 043836 | B38: Cuyahoga Falls City SD | C38: Summit | D38: 27026553 | E38: 253306 | F38: 0 | G38: 12272896 | H38: 546191 | I38: 0 | J38: 4567577 | K38: 3550183 | L38: 48216706 | M38: 0 | N38: 0 | O38: 0 | P38: 0 | Q38: 150493 | R38: 150493 | S38: 48367199 | T38: 26900322 | U38: 10883265 | V38: 7758391 | W38: 740798 | X38: 588641 | Y38: 0 | Z38: 0 | AA38: 0 | AB38: 0 | AC38: 0 | AD38: 0 | AE38: 0 | AF38: 0 | AG38: 786877 | AH38: 47658294 | AI38: 0 | AJ38: 0 | AK38: 150000 | AL38: 150000 | AM38: 47808294 | AN38: 558905 | AO38: 4486602 | AP38: 5045507 | AQ38: 90000 | AR38: 0 | AS38: 0 | AT38: 0 | AU38: 0 | AV38: 0 | AW38: 0 | AX38: 0 | AY38: 0 | AZ38: 0 | BA38: 4955507 | BB38: 0 | BC38: 0 | BD38: 0 | BE38: 4955507 | BF38: 0 | BG38: 0 | BH38: 0 | BI38: 0 | BJ38: 4955507 | BM38: 0 | BN38: 0 | BO38: 0 | BP38: 0 | BQ38: 0 | BR38: 0 | BS38: 48367199
A39: 043844 | B39: Dayton City SD | C39: Montgomery | D39: 50360740 | E39: 5639034 | F39: 0 | G39: 143399691 | H39: 1523125 | I39: 0 | J39: 12742345 | K39: 4301456 | L39: 217966391 | M39: 0 | N39: 0 | O39: 0 | P39: 4483510 | Q39: 75000 | R39: 4558510 | S39: 222524901 | T39: 94872984 | U39: 41733902 | V39: 80627048 | W39: 4963449 | X39: 539472 | Y39: 0 | Z39: 0 | AA39: 0 | AB39: 0 | AC39: 0 | AD39: 0 | AE39: 0 | AF39: 0 | AG39: 2286675 | AH39: 225023530 | AI39: 250000 | AJ39: 2500000 | AK39: 0 | AL39: 2750000 | AM39: 227773530 | AN39: -5248629 | AO39: 11242816 | AP39: 5994187 | AQ39: 0 | AR39: 0 | AS39: 0 | AT39: 0 | AU39: 0 | AV39: 0 | AW39: 0 | AX39: 0 | AY39: 0 | AZ39: 0 | BA39: 5994187 | BB39: 0 | BC39: 0 | BD39: 0 | BE39: 5994187 | BF39: 0 | BG39: 0 | BH39: 0 | BI39: 0 | BJ39: 5994187 | BM39: 0 | BN39: 0 | BO39: 0 | BP39: 0 | BQ39: 0 | BR39: 0 | BS39: 227773530
A40: 043851 | B40: Deer Park Community City SD | C40: Hamilton | D40: 7257844 | E40: 714830 | F40: 0 | G40: 3135407 | H40: 12500 | I40: 0 | J40: 1241494 | K40: 749681 | L40: 13111756 | M40: 0 | N40: 0 | O40: 0 | P40: 128515 | Q40: 31798 | R40: 160313 | S40: 13272069 | T40: 6570014 | U40: 2211871 | V40: 3373467 | W40: 651592 | X40: 39892 | Y40: 0 | Z40: 0 | AA40: 0 | AB40: 0 | AC40: 0 | AD40: 0 | AE40: 0 | AF40: 0 | AG40: 334059 | AH40: 13180895 | AI40: 1406892 | AJ40: 0 | AK40: 0 | AL40: 1406892 | AM40: 14587787 | AN40: -1315718 | AO40: 4853346 | AP40: 3537628 | AQ40: 218067 | AR40: 0 | AS40: 0 | AT40: 0 | AU40: 0 | AV40: 0 | AW40: 0 | AX40: 0 | AY40: 0 | AZ40: 0 | BA40: 3319561 | BB40: 0 | BC40: 0 | BD40: 0 | BE40: 3319561 | BF40: 0 | BG40: 0 | BH40: 0 | BI40: 0 | BJ40: 3319561 | BK40: 0 | BL40: 0 | BM40: 0 | BN40: 0 | BO40: 0 | BP40: 0 | BQ40: 0 | BR40: 0 | BS40: 14587787
...
