Workbook

Sheet Summary
B3: Actual 2012 | C3: Projected 2012/13 | F3: 0.92307692
A4: BUDGET DIVISION | B4: BUDGET | C4: SALARIES | D4: ADMIN & SUPPORT | E4: OPERATING | F4: Formula Allocation | G4: 10/11 Expenditure | H4: +/- last year
A6: President | B6: =GETPIVOTDATA("BEGINNING BUDGET",'fy12 budget (2)'!$A$3,"Division","1") -> 1715950 | C6: =Calculations!N8 -> 1015869 | D6: =INDIRECT(ADDRESS(MATCH(A6,Calculations!B:B,0),15,1,1,"Calculations")) -> 0 | E6: =INDIRECT(ADDRESS(MATCH(A6,Calculations!B:B,0),16,1,1,"Calculations")) -> 276744.4 | F6: =INDIRECT(ADDRESS(MATCH(A6,Calculations!B:B,0),17,1,1,"Calculations")) -> 1292613.4 | G6: =GETPIVOTDATA("TOTAL EXPENSE",'FY11 expense (2)'!$A$4,"Division","1") -> 1767758.3 | H6: =F6-B6 -> -423336.6
A7: Provost | B7: =GETPIVOTDATA("BEGINNING BUDGET",'fy12 budget (2)'!$A$3,"Division","2")-(SUM(B12:B33)) -> 4998016 | C7: =Calculations!N9 -> 3900785 | D7: =INDIRECT(ADDRESS(MATCH(A7,Calculations!B:B,0),15,1,1,"Calculations")) -> 0 | E7: =INDIRECT(ADDRESS(MATCH(A7,Calculations!B:B,0),16,1,1,"Calculations")) -> 1062657.1 | F7: =INDIRECT(ADDRESS(MATCH(A7,Calculations!B:B,0),17,1,1,"Calculations")) -> 4963442.1 | G7: =GETPIVOTDATA("TOTAL EXPENSE",'FY11 expense (2)'!$A$4,"Division","2")-(SUM(G12:G33)) -> 6538746.9 | H7: =F7-B7 -> -34573.904
A8: Finance & Aministration | B8: =GETPIVOTDATA("BEGINNING BUDGET",'fy12 budget (2)'!$A$3,"Division","3") -> 11834075 | C8: =Calculations!N10 -> 3762774 | D8: =INDIRECT(ADDRESS(MATCH(A8,Calculations!B:B,0),15,1,1,"Calculations")) -> 0 | E8: =INDIRECT(ADDRESS(MATCH(A8,Calculations!B:B,0),16,1,1,"Calculations")) -> 1025060 | F8: =INDIRECT(ADDRESS(MATCH(A8,Calculations!B:B,0),17,1,1,"Calculations")) -> 4787834 | G8: =GETPIVOTDATA("TOTAL EXPENSE",'FY11 expense (2)'!$A$4,"Division","3") -> 13064220 | H8: =F8-B8 -> -7046241
A9: Strategy, Planning & Policy | B9: =GETPIVOTDATA("BEGINNING BUDGET",'fy12 budget (2)'!$A$3,"Division","4") -> 272144 | C9: =Calculations!N11 -> 0 | D9: =INDIRECT(ADDRESS(MATCH(A9,Calculations!B:B,0),15,1,1,"Calculations")) -> 0 | E9: =INDIRECT(ADDRESS(MATCH(A9,Calculations!B:B,0),16,1,1,"Calculations")) -> 0 | F9: =INDIRECT(ADDRESS(MATCH(A9,Calculations!B:B,0),17,1,1,"Calculations")) -> 0 | G9: =GETPIVOTDATA("TOTAL EXPENSE",'FY11 expense (2)'!$A$4,"Division","4") -> 244753.55 | H9: =F9-B9 -> -272144
A10: Student Services & Enrollment Management | B10: =GETPIVOTDATA("BEGINNING BUDGET",'fy12 budget (2)'!$A$3,"Division","5") -> 2658064 | C10: =Calculations!N12 -> 1895281 | D10: =INDIRECT(ADDRESS(MATCH(A10,Calculations!B:B,0),15,1,1,"Calculations")) -> 84925 | E10: =INDIRECT(ADDRESS(MATCH(A10,Calculations!B:B,0),16,1,1,"Calculations")) -> 516315 | F10: =INDIRECT(ADDRESS(MATCH(A10,Calculations!B:B,0),17,1,1,"Calculations")) -> 2496521 | G10: =GETPIVOTDATA("TOTAL EXPENSE",'FY11 expense (2)'!$A$4,"Division","5") -> 2649386.4 | H10: =F10-B10 -> -161543
A11: Development | B11: =GETPIVOTDATA("BEGINNING BUDGET",'fy12 budget (2)'!$A$3,"Division","6") -> 449832 | C11: =Calculations!N13 -> 427804 | D11: =INDIRECT(ADDRESS(MATCH(A11,Calculations!B:B,0),15,1,1,"Calculations")) -> 0 | E11: =INDIRECT(ADDRESS(MATCH(A11,Calculations!B:B,0),16,1,1,"Calculations")) -> 116542.94 | F11: =INDIRECT(ADDRESS(MATCH(A11,Calculations!B:B,0),17,1,1,"Calculations"))-95000 -> 449346.94 | G11: =GETPIVOTDATA("TOTAL EXPENSE",'FY11 expense (2)'!$A$4,"Division","6") -> 279189.07 | H11: =F11-B11 -> -485.05892
A12: Agriculture | B12: =GETPIVOTDATA("BEGINNING BUDGET",'fy12 budget'!$A$6,"DEPARTMENT","Agriculture") -> 591449 | C12: =INDIRECT(ADDRESS(MATCH(A12,Calculations!B:B,0),14,1,1,"Calculations")) -> 520790.48 | D12: =INDIRECT(ADDRESS(MATCH(A12,Calculations!B:B,0),15,1,1,"Calculations")) -> 92923.575 | E12: =INDIRECT(ADDRESS(MATCH(A12,Calculations!B:B,0),16,1,1,"Calculations")) -> 59116.727 | F12: =INDIRECT(ADDRESS(MATCH(A12,Calculations!B:B,0),17,1,1,"Calculations")) -> 672830.78 | G12: =GETPIVOTDATA("TOTAL EXPENSE",'FY11 expense'!$A$6,"DEPARTMENT","Agriculture") -> 599585.43 | H12: =F12-B12 -> 81381.784
A13: Art & Music | B13: =GETPIVOTDATA("BEGINNING BUDGET",'fy12 budget'!$A$6,"DEPARTMENT","Art and Music") -> 1229055 | C13: =INDIRECT(ADDRESS(MATCH(A13,Calculations!B:B,0),14,1,1,"Calculations")) -> 643983.85 | D13: =INDIRECT(ADDRESS(MATCH(A13,Calculations!B:B,0),15,1,1,"Calculations")) -> 97091.326 | E13: =INDIRECT(ADDRESS(MATCH(A13,Calculations!B:B,0),16,1,1,"Calculations")) -> 89920.186 | F13: =INDIRECT(ADDRESS(MATCH(A13,Calculations!B:B,0),17,1,1,"Calculations")) -> 830995.36 | G13: =GETPIVOTDATA("TOTAL EXPENSE",'FY11 expense'!$A$6,"DEPARTMENT","Art and Music") -> 1225927.7 | H13: =F13-B13 -> -398059.64
A14: Biology | B14: =GETPIVOTDATA("BEGINNING BUDGET",'fy12 budget'!$A$6,"DEPARTMENT","Biology") -> 1108636 | C14: =INDIRECT(ADDRESS(MATCH(A14,Calculations!B:B,0),14,1,1,"Calculations")) -> 953090.97 | D14: =INDIRECT(ADDRESS(MATCH(A14,Calculations!B:B,0),15,1,1,"Calculations")) -> 101174.16 | E14: =INDIRECT(ADDRESS(MATCH(A14,Calculations!B:B,0),16,1,1,"Calculations")) -> 120096.04 | F14: =INDIRECT(ADDRESS(MATCH(A14,Calculations!B:B,0),17,1,1,"Calculations")) -> 1174361.2 | G14: =GETPIVOTDATA("TOTAL EXPENSE",'FY11 expense'!$A$6,"DEPARTMENT","Biology") -> 1165519.6 | H14: =F14-B14 -> 65725.168
A15: Chemistry & Biochemistry | B15: =GETPIVOTDATA("BEGINNING BUDGET",'fy12 budget'!$A$6,"DEPARTMENT","Chemistry and Biochemistry") -> 531545 | C15: =INDIRECT(ADDRESS(MATCH(A15,Calculations!B:B,0),14,1,1,"Calculations")) -> 419992.86 | D15: =INDIRECT(ADDRESS(MATCH(A15,Calculations!B:B,0),15,1,1,"Calculations")) -> 92831.811 | E15: =INDIRECT(ADDRESS(MATCH(A15,Calculations!B:B,0),16,1,1,"Calculations")) -> 58438.505 | F15: =INDIRECT(ADDRESS(MATCH(A15,Calculations!B:B,0),17,1,1,"Calculations")) -> 571263.18 | G15: =GETPIVOTDATA("TOTAL EXPENSE",'FY11 expense'!$A$6,"DEPARTMENT","Chemistry and Biochemistry") -> 595096.85 | H15: =F15-B15 -> 39718.179
A16: Communication, Mass Media, & Theatre | B16: =GETPIVOTDATA("BEGINNING BUDGET",'fy12 budget'!$A$6,"DEPARTMENT","Communication, Mass Media & Theatre") -> 989795 | C16: =INDIRECT(ADDRESS(MATCH(A16,Calculations!B:B,0),14,1,1,"Calculations")) -> 892534.33 | D16: =INDIRECT(ADDRESS(MATCH(A16,Calculations!B:B,0),15,1,1,"Calculations")) -> 99937.394 | E16: =INDIRECT(ADDRESS(MATCH(A16,Calculations!B:B,0),16,1,1,"Calculations")) -> 110955.21 | F16: =INDIRECT(ADDRESS(MATCH(A16,Calculations!B:B,0),17,1,1,"Calculations")) -> 1103426.9 | G16: =GETPIVOTDATA("TOTAL EXPENSE",'FY11 expense'!$A$6,"DEPARTMENT","Communication, Mass Media & Theatre") -> 1256290.9 | H16: =F16-B16 -> 113631.94
A17: English & Modern Langagues | B17: =GETPIVOTDATA("BEGINNING BUDGET",'fy12 budget'!$A$6,"DEPARTMENT","English and Modern Languages") -> 1663079 | C17: =INDIRECT(ADDRESS(MATCH(A17,Calculations!B:B,0),14,1,1,"Calculations")) -> 1370462.8 | D17: =INDIRECT(ADDRESS(MATCH(A17,Calculations!B:B,0),15,1,1,"Calculations")) -> 109647.99 | E17: =INDIRECT(ADDRESS(MATCH(A17,Calculations!B:B,0),16,1,1,"Calculations")) -> 182725.35 | F17: =INDIRECT(ADDRESS(MATCH(A17,Calculations!B:B,0),17,1,1,"Calculations")) -> 1662836.2 | G17: =GETPIVOTDATA("TOTAL EXPENSE",'FY11 expense'!$A$6,"DEPARTMENT","English and Modern languages") -> 1561489.3 | H17: =F17-B17 -> -242.83926
A18: Pol Science | B18: =GETPIVOTDATA("BEGINNING BUDGET",'fy12 budget'!$A$6,"DEPARTMENT","Political Science") -> 462519 | C18: =INDIRECT(ADDRESS(MATCH(A18,Calculations!B:B,0),14,1,1,"Calculations")) -> 329746.23 | D18: =INDIRECT(ADDRESS(MATCH(A18,Calculations!B:B,0),15,1,1,"Calculations")) -> 91112.939 | E18: =INDIRECT(ADDRESS(MATCH(A18,Calculations!B:B,0),16,1,1,"Calculations")) -> 45734.482 | F18: =INDIRECT(ADDRESS(MATCH(A18,Calculations!B:B,0),17,1,1,"Calculations")) -> 466593.65 | G18: =GETPIVOTDATA("TOTAL EXPENSE",'FY11 expense'!$A$6,"DEPARTMENT","Political Science") -> 813960.94 | H18: =F18-B18 -> 4074.6532
A19: History | B19: =GETPIVOTDATA("BEGINNING BUDGET",'fy12 budget'!$A$6,"DEPARTMENT","History") -> 762149 | C19: =INDIRECT(ADDRESS(MATCH(A19,Calculations!B:B,0),14,1,1,"Calculations")) -> 990543.63 | D19: =INDIRECT(ADDRESS(MATCH(A19,Calculations!B:B,0),15,1,1,"Calculations")) -> 103151.89 | E19: =INDIRECT(ADDRESS(MATCH(A19,Calculations!B:B,0),16,1,1,"Calculations")) -> 134713.25 | F19: =INDIRECT(ADDRESS(MATCH(A19,Calculations!B:B,0),17,1,1,"Calculations")) -> 1228408.8 | G19: =GETPIVOTDATA("TOTAL EXPENSE",'FY11 expense'!$A$6,"DEPARTMENT","History") -> 747361.15 | H19: =F19-B19 -> 466259.77
A20: Mathematics & Computer Science | B20: =GETPIVOTDATA("BEGINNING BUDGET",'fy12 budget'!$A$6,"DEPARTMENT","Mathematics and Computer Science") -> 1259999 | C20: =INDIRECT(ADDRESS(MATCH(A20,Calculations!B:B,0),14,1,1,"Calculations")) -> 1061559.7 | D20: =INDIRECT(ADDRESS(MATCH(A20,Calculations!B:B,0),15,1,1,"Calculations")) -> 104980.29 | E20: =INDIRECT(ADDRESS(MATCH(A20,Calculations!B:B,0),16,1,1,"Calculations")) -> 148226.77 | F20: =INDIRECT(ADDRESS(MATCH(A20,Calculations!B:B,0),17,1,1,"Calculations")) -> 1314766.8 | G20: =GETPIVOTDATA("TOTAL EXPENSE",'FY11 expense'!$A$6,"DEPARTMENT","Mathematics and Computer Science") -> 34069.77 | H20: =F20-B20 -> 54767.758
A21: Physics | B21: =GETPIVOTDATA("BEGINNING BUDGET",'fy12 budget'!$A$6,"DEPARTMENT","Physics") -> 810053 | C21: =INDIRECT(ADDRESS(MATCH(A21,Calculations!B:B,0),14,1,1,"Calculations")) -> 593961.47 | D21: =INDIRECT(ADDRESS(MATCH(A21,Calculations!B:B,0),15,1,1,"Calculations")) -> 96146.289 | E21: =INDIRECT(ADDRESS(MATCH(A21,Calculations!B:B,0),16,1,1,"Calculations")) -> 82935.505 | F21: =INDIRECT(ADDRESS(MATCH(A21,Calculations!B:B,0),17,1,1,"Calculations")) -> 773043.26 | G21: =GETPIVOTDATA("TOTAL EXPENSE",'FY11 expense'!$A$6,"DEPARTMENT","Physics") -> 699416.54 | H21: =F21-B21 -> -37009.741
A22: Accounting, Economics, & Finance | B22: =GETPIVOTDATA("BEGINNING BUDGET",'fy12 budget'!$A$6,"DEPARTMENT","Accounting, Economics, and Finance") -> 1066854 | C22: =INDIRECT(ADDRESS(MATCH(A22,Calculations!B:B,0),14,1,1,"Calculations")) -> 748618.19 | D22: =INDIRECT(ADDRESS(MATCH(A22,Calculations!B:B,0),15,1,1,"Calculations")) -> 96931.081 | E22: =INDIRECT(ADDRESS(MATCH(A22,Calculations!B:B,0),16,1,1,"Calculations")) -> 88735.827 | F22: =INDIRECT(ADDRESS(MATCH(A22,Calculations!B:B,0),17,1,1,"Calculations")) -> 934285.1 | G22: =GETPIVOTDATA("TOTAL EXPENSE",'FY11 expense'!$A$6,"DEPARTMENT","Accounting, Economics, and Finance") -> 1233545 | H22: =F22-B22 -> -132568.9
A23: Aerospace Studies | B23: =GETPIVOTDATA("BEGINNING BUDGET",'fy12 budget'!$A$6,"DEPARTMENT","Aerospace Studies") -> 44068 | C23: =INDIRECT(ADDRESS(MATCH(A23,Calculations!B:B,0),14,1,1,"Calculations")) -> 40090.405 | D23: =INDIRECT(ADDRESS(MATCH(A23,Calculations!B:B,0),15,1,1,"Calculations")) -> 85682.399 | E23: =INDIRECT(ADDRESS(MATCH(A23,Calculations!B:B,0),16,1,1,"Calculations")) -> 5597.8682 | F23: =INDIRECT(ADDRESS(MATCH(A23,Calculations!B:B,0),17,1,1,"Calculations")) -> 131370.67 | G23: =GETPIVOTDATA("TOTAL EXPENSE",'FY11 expense'!$A$6,"DEPARTMENT","Aerospace Studies") -> 50559.72 | H23: =F23-B23 -> 87302.673
A24: Management & Marketing | B24: =GETPIVOTDATA("BEGINNING BUDGET",'fy12 budget'!$A$6,"DEPARTMENT","Management and Marketing") -> 1102526 | C24: =INDIRECT(ADDRESS(MATCH(A24,Calculations!B:B,0),14,1,1,"Calculations")) -> 757858.67 | D24: =INDIRECT(ADDRESS(MATCH(A24,Calculations!B:B,0),15,1,1,"Calculations")) -> 95617.616 | E24: =INDIRECT(ADDRESS(MATCH(A24,Calculations!B:B,0),16,1,1,"Calculations")) -> 79028.132 | F24: =INDIRECT(ADDRESS(MATCH(A24,Calculations!B:B,0),17,1,1,"Calculations")) -> 932504.42 | G24: =GETPIVOTDATA("TOTAL EXPENSE",'FY11 expense'!$A$6,"DEPARTMENT","Management and Marketing") -> 1356228.3 | H24: =F24-B24 -> -170021.58
A25: Security Studies & Criminal Justice | B25: =GETPIVOTDATA("BEGINNING BUDGET",'fy12 budget'!$A$6,"DEPARTMENT","Security Studies Criminal Justice") -> 193510 | C25: =INDIRECT(ADDRESS(MATCH(A25,Calculations!B:B,0),14,1,1,"Calculations")) -> 0 | D25: =INDIRECT(ADDRESS(MATCH(A25,Calculations!B:B,0),15,1,1,"Calculations")) -> 84925 | E25: =INDIRECT(ADDRESS(MATCH(A25,Calculations!B:B,0),16,1,1,"Calculations")) -> 0 | F25: =INDIRECT(ADDRESS(MATCH(A25,Calculations!B:B,0),17,1,1,"Calculations")) -> 84925 | H25: =F25-B25 -> -108585
A26: Teacher Education | B26: =GETPIVOTDATA("BEGINNING BUDGET",'fy12 budget'!$A$6,"DEPARTMENT","Teacher Education") -> 763138 | C26: =INDIRECT(ADDRESS(MATCH(A26,Calculations!B:B,0),14,1,1,"Calculations")) -> 714215.95 | D26: =INDIRECT(ADDRESS(MATCH(A26,Calculations!B:B,0),15,1,1,"Calculations")) -> 94913.632 | E26: =INDIRECT(ADDRESS(MATCH(A26,Calculations!B:B,0),16,1,1,"Calculations")) -> 73825.05 | F26: =INDIRECT(ADDRESS(MATCH(A26,Calculations!B:B,0),17,1,1,"Calculations")) -> 882954.63 | G26: =GETPIVOTDATA("TOTAL EXPENSE",'FY11 expense'!$A$6,"DEPARTMENT","Teacher Education") -> 869748.16 | H26: =F26-B26 -> 119816.63
A27: Curriculum & Instruction | B27: =GETPIVOTDATA("BEGINNING BUDGET",'fy12 budget'!$A$6,"DEPARTMENT","Curriculum and Instruction") -> 459814 | C27: =INDIRECT(ADDRESS(MATCH(A27,Calculations!B:B,0),14,1,1,"Calculations")) -> 1598591.7 | D27: =INDIRECT(ADDRESS(MATCH(A27,Calculations!B:B,0),15,1,1,"Calculations")) -> 87131.456 | E27: =INDIRECT(ADDRESS(MATCH(A27,Calculations!B:B,0),16,1,1,"Calculations")) -> 16307.714 | F27: =INDIRECT(ADDRESS(MATCH(A27,Calculations!B:B,0),17,1,1,"Calculations")) -> 1702030.8 | G27: =GETPIVOTDATA("TOTAL EXPENSE",'FY11 expense'!$A$6,"DEPARTMENT","Curriculum and Instruction") -> 927480.14 | H27: =F27-B27 -> 1242216.8
A28: Kinesiology | B28: =GETPIVOTDATA("BEGINNING BUDGET",'fy12 budget'!$A$6,"DEPARTMENT","Kinesiology") -> 538599 | C28: =INDIRECT(ADDRESS(MATCH(A28,Calculations!B:B,0),14,1,1,"Calculations")) -> 580605.43 | D28: =INDIRECT(ADDRESS(MATCH(A28,Calculations!B:B,0),15,1,1,"Calculations")) -> 92931.793 | E28: =INDIRECT(ADDRESS(MATCH(A28,Calculations!B:B,0),16,1,1,"Calculations")) -> 59177.464 | F28: =INDIRECT(ADDRESS(MATCH(A28,Calculations!B:B,0),17,1,1,"Calculations")) -> 732714.69 | G28: =GETPIVOTDATA("TOTAL EXPENSE",'FY11 expense'!$A$6,"DEPARTMENT","Kinesiology") -> 835180.02 | H28: =F28-B28 -> 194115.69
A29: Nursing | B29: =GETPIVOTDATA("BEGINNING BUDGET",'fy12 budget'!$A$6,"DEPARTMENT","Nursing and Rehabilitation Sciences") -> 1951761 | C29: =INDIRECT(ADDRESS(MATCH(A29,Calculations!B:B,0),14,1,1,"Calculations")) -> 1636512.8 | D29: =INDIRECT(ADDRESS(MATCH(A29,Calculations!B:B,0),15,1,1,"Calculations")) -> 101249.49 | E29: =INDIRECT(ADDRESS(MATCH(A29,Calculations!B:B,0),16,1,1,"Calculations")) -> 120652.79 | F29: =INDIRECT(ADDRESS(MATCH(A29,Calculations!B:B,0),17,1,1,"Calculations")) -> 1858415 | G29: =GETPIVOTDATA("TOTAL EXPENSE",'FY11 expense'!$A$6,"DEPARTMENT","Nursing and Rehabilitation Sciences") -> 2186809.8 | H29: =F29-B29 -> -93345.962
A30: Athletic Training | B30: 0 | C30: =INDIRECT(ADDRESS(MATCH(A30,Calculations!B:B,0),14,1,1,"Calculations")) -> 0 | D30: =INDIRECT(ADDRESS(MATCH(A30,Calculations!B:B,0),15,1,1,"Calculations")) -> 84925 | E30: =INDIRECT(ADDRESS(MATCH(A30,Calculations!B:B,0),16,1,1,"Calculations")) -> 0 | F30: =INDIRECT(ADDRESS(MATCH(A30,Calculations!B:B,0),17,1,1,"Calculations")) -> 84925 | G30: 0 | H30: =F30-B30 -> 84925
A31: Physical Therapy | B31: =GETPIVOTDATA("BEGINNING BUDGET",'fy12 budget'!$A$6,"DEPARTMENT","Physical Therapy") -> 980425 | C31: =INDIRECT(ADDRESS(MATCH(A31,Calculations!B:B,0),14,1,1,"Calculations")) -> 143787.87 | D31: =INDIRECT(ADDRESS(MATCH(A31,Calculations!B:B,0),15,1,1,"Calculations")) -> 84925 | E31: =INDIRECT(ADDRESS(MATCH(A31,Calculations!B:B,0),16,1,1,"Calculations")) -> 39170.885 | F31: =INDIRECT(ADDRESS(MATCH(A31,Calculations!B:B,0),17,1,1,"Calculations")) -> 267883.76 | G31: =GETPIVOTDATA("TOTAL EXPENSE",'FY11 expense'!$A$6,"DEPARTMENT","Physical Therapy") -> 1025417.9 | H31: =F31-B31 -> -712541.24
A32: Psychology, Sociology & Social Work | B32: =GETPIVOTDATA("BEGINNING BUDGET",'fy12 budget'!$A$6,"DEPARTMENT","Psychology, Sociology, Social Work") -> 1064457 | C32: =INDIRECT(ADDRESS(MATCH(A32,Calculations!B:B,0),14,1,1,"Calculations")) -> 1355266.5 | D32: =INDIRECT(ADDRESS(MATCH(A32,Calculations!B:B,0),15,1,1,"Calculations")) -> 103269.68 | E32: =INDIRECT(ADDRESS(MATCH(A32,Calculations!B:B,0),16,1,1,"Calculations")) -> 135583.81 | F32: =INDIRECT(ADDRESS(MATCH(A32,Calculations!B:B,0),17,1,1,"Calculations")) -> 1594120 | G32: =GETPIVOTDATA("TOTAL EXPENSE",'FY11 expense'!$A$6,"DEPARTMENT","Psychology, Sociology, Social Work") -> 1228952.8 | H32: =F32-B32 -> 529662.98
A33: Academic Affairs | B33: 1653792 | C33: =INDIRECT(ADDRESS(MATCH(A33,Calculations!B:B,0),14,1,1,"Calculations")) -> 120198.72 | D33: =INDIRECT(ADDRESS(MATCH(A33,Calculations!B:B,0),15,1,1,"Calculations")) -> 87195.828 | E33: =INDIRECT(ADDRESS(MATCH(A33,Calculations!B:B,0),16,1,1,"Calculations")) -> 16783.482 | F33: =INDIRECT(ADDRESS(MATCH(A33,Calculations!B:B,0),17,1,1,"Calculations")) -> 224178.03 | H33: =F33-B33 -> -1429614 | I33: =SUM(H12:H33) -> 1610.1968
A34: Facilities | B34: =GETPIVOTDATA("BEGINNING BUDGET",'fy12 budget (2)'!$A$4,"Division","F") -> 5531857 | C34: =INDIRECT(ADDRESS(MATCH(A34,Calculations!B:B,0),10,1,1,"Calculations")) -> 0 | D34: =INDIRECT(ADDRESS(MATCH(A34,Calculations!B:B,0),15,1,1,"Calculations")) -> 0 | E34: =INDIRECT(ADDRESS(MATCH(A34,Calculations!B:B,0),16,1,1,"Calculations")) -> 0 | F34: =B62*B61 -> 2832527.2 | G34: =GETPIVOTDATA("TOTAL EXPENSE",'FY11 expense (2)'!$A$4,"Division","F") -> 5883187.3 | H34: =F34-B34 -> -2699329.8
A36: Totals | B36: =SUM(B6:B35) -> 46687161 | C36: =SUM(C6:C35) -> 26474926 | D36: =SUM(D6:D35) -> 2173620.6 | E36: =SUM(E6:E35) -> 4665044.4 | F36: =SUM(F6:F35) -> 36051118 | G36: =SUM(G6:G35) -> 48839881
E38: University Expenses | F38: ='University Cost'!D73 -> 10398251
E39: Budget Requirements | F39: =+F36+F38 -> 46449369
E40: Revenue | F40: =Revenue!J62 -> 47056603
E41: Strategic Iniatives | F41: =+F40-F39 -> 607234.18
A43: Variables
A44: Faculty (full time) | B44: 0.85
A45: Faculty (adjunct) | B45: 0.15
A46: Academic Operating | B46: 6750
...

Sheet Calculations
C5: 2012 | D5: 2012 | G5: Required | H5: Required | I5: Required | J5: Required | K5: Total | L5: 2011/12 UG | M5: 2011/12 Grad | N5: 2011/12 Projected | O5: HeadCount Driven | P5: 2011/12
B6: BUDGET DIVISION | C6: UG SCH | D6: G SCH | E6: UG Lab (HC) | F6: G Lab (HC) | G6: UG Fac. FTE | H6: G Fac. FTE | I6: UG Lab Fac | J6: G Lab Fac | K6: Faculty | L6: Faculty Salaries | M6: Faculty Salaries | N6: SALARIES | O6: ADMIN & SUPPORT | P6: OPERATING | Q6: TOTAL ALLOCATION | R6: HOLD HARMLESS | S6: DIFFERENCE
B8: President | N8: =GETPIVOTDATA("Distribution Budget",'position by div'!$A$3,"Div","1") -> 1015869 | P8: =IF(ISERROR(IF(K8>0,(K8*Summary!$B$46)+((Calculations!C8+D8)/500*Summary!$B$64),Calculations!N8/Summary!$B$59*Summary!$B$54)),"",IF(G8>0,(G8*Summary!$B$46)+(Calculations!C8/500*Summary!$B$64),Calculations!N8/Summary!$B$59*Summary!$B$54)) -> 276744.4 | Q8: =SUM(N8:P8) -> 1292613.4
B9: Provost | N9: =GETPIVOTDATA("Distribution Budget",'position by div'!$A$3,"Div","2") -> 3900785 | P9: =IF(ISERROR(IF(K9>0,(K9*Summary!$B$46)+((Calculations!C9+D9)/500*Summary!$B$64),Calculations!N9/Summary!$B$59*Summary!$B$54)),"",IF(G9>0,(G9*Summary!$B$46)+(Calculations!C9/500*Summary!$B$64),Calculations!N9/Summary!$B$59*Summary!$B$54)) -> 1062657.1 | Q9: =SUM(N9:P9) -> 4963442.1
B10: Finance & Aministration | N10: =GETPIVOTDATA("Distribution Budget",'position by div'!$A$3,"Div","3") -> 3762774 | P10: =IF(ISERROR(IF(K10>0,(K10*Summary!$B$46)+((Calculations!C10+D10)/500*Summary!$B$64),Calculations!N10/Summary!$B$59*Summary!$B$54)),"",IF(G10>0,(G10*Summary!$B$46)+(Calculations!C10/500*Summary!$B$64),Calculations!N10/Summary!$B$59*Summary!$B$54)) -> 1025060 | Q10: =SUM(N10:P10) -> 4787834
B11: Strategy, Planning & Policy | P11: =IF(ISERROR(IF(K11>0,(K11*Summary!$B$46)+((Calculations!C11+D11)/500*Summary!$B$64),Calculations!N11/Summary!$B$59*Summary!$B$54)),"",IF(G11>0,(G11*Summary!$B$46)+(Calculations!C11/500*Summary!$B$64),Calculations!N11/Summary!$B$59*Summary!$B$54)) -> 0 | Q11: =SUM(N11:P11) -> 0
B12: Student Services & Enrollment Management | N12: =GETPIVOTDATA("Distribution Budget",'position by div'!$A$3,"Div","5") -> 1895281 | O12: =IF(ISERROR(Summary!$B$59+Summary!$B$60+((Calculations!C12/30)/Summary!$B$53*Summary!$B$60)),"",Summary!$B$59+Summary!$B$60+((Calculations!C12/30)/Summary!$B$53*Summary!$B$60)) -> 84925 | P12: =IF(ISERROR(IF(K12>0,(K12*Summary!$B$46)+((Calculations!C12+D12)/500*Summary!$B$64),Calculations!N12/Summary!$B$59*Summary!$B$54)),"",IF(G12>0,(G12*Summary!$B$46)+(Calculations!C12/500*Summary!$B$64),Calculations!N12/Summary!$B$59*Summary!$B$54)) -> 516315 | Q12: =SUM(N12:P12) -> 2496521
B13: Development | N13: =GETPIVOTDATA("Distribution Budget",'position by div'!$A$3,"Div","6") -> 427804 | P13: =IF(ISERROR(IF(K13>0,(K13*Summary!$B$46)+((Calculations!C13+D13)/500*Summary!$B$64),Calculations!N13/Summary!$B$59*Summary!$B$54)),"",IF(G13>0,(G13*Summary!$B$46)+(Calculations!C13/500*Summary!$B$64),Calculations!N13/Summary!$B$59*Summary!$B$54)) -> 116542.94 | Q13: =SUM(N13:P13) -> 544346.94
B14: Agriculture | C14: =IF(ISERROR(INDIRECT(ADDRESS(MATCH(B14,Data!B:B,0),5,1,1,"Data"))*INDIRECT(ADDRESS(MATCH(B14,'Cost Factor'!B:B,0),21,1,1,"Cost Factor"))),"",INDIRECT(ADDRESS(MATCH(B14,Data!B:B,0),5,1,1,"Data"))*INDIRECT(ADDRESS(MATCH(B14,'Cost Factor'!B:B,0),21,1,1,"Cost Factor"))) -> 5840 | D14: =IF(ISERROR(INDIRECT(ADDRESS(MATCH(B14,Data!B:B,0),6,1,1,"Data"))*INDIRECT(ADDRESS(MATCH(B14,'Cost Factor'!B:B,0),21,1,1,"Cost Factor"))),"",INDIRECT(ADDRESS(MATCH(B14,Data!B:B,0),6,1,1,"Data"))*INDIRECT(ADDRESS(MATCH(B14,'Cost Factor'!B:B,0),21,1,1,"Cost Factor"))) -> 397 | E14: =IF(ISERROR(INDIRECT(ADDRESS(MATCH(B14,Data!B:B,0),8,1,1,"Data"))*INDIRECT(ADDRESS(MATCH(B14,'Cost Factor'!B:B,0),21,1,1,"Cost Factor"))),"",INDIRECT(ADDRESS(MATCH(B14,Data!B:B,0),8,1,1,"Data"))*INDIRECT(ADDRESS(MATCH(B14,'Cost Factor'!B:B,0),21,1,1,"Cost Factor"))) -> 0 | F14: =IF(ISERROR(INDIRECT(ADDRESS(MATCH(B14,Data!B:B,0),9,1,1,"Data"))*INDIRECT(ADDRESS(MATCH(B14,'Cost Factor'!B:B,0),21,1,1,"Cost Factor"))),"",INDIRECT(ADDRESS(MATCH(B14,Data!B:B,0),9,1,1,"Data"))*INDIRECT(ADDRESS(MATCH(B14,'Cost Factor'!B:B,0),21,1,1,"Cost Factor"))) -> 0 | G14: =IF(ISERROR(C14/(Summary!$B$47*Summary!$B$49)),"",C14/(Summary!$B$47*Summary!$B$49)) -> 7.3737374 | H14: =IF(ISERROR(D14/(Summary!$B$48*Summary!$B$50)),"",D14/(Summary!$B$48*Summary!$B$50)) -> 1.6965812 | I14: =E14/(Summary!$B$51*Summary!$B$49*0.67) -> 0 | J14: =F14/(Summary!$B$50*Summary!$B$52*0.67) -> 0 | K14: =H14+G14+I14+J14 -> 9.0703186 | L14: =IF(ISERROR(((G14+I14)*Summary!$B$44*Summary!$B$57)+((Calculations!G14+I14)*Summary!$B$45*Summary!$B$58)),"",((G14+I14)*Summary!$B$44*Summary!$B$57)+((Calculations!G14+I14)*Summary!$B$45*Summary!$B$58)) -> 423377.88 | M14: =IF(ISERROR(((H14+J14)*Summary!$B$44*Summary!$B$57)+((H14+J14)*Summary!$B$45*Summary!$B$58)),"",((H14+J14)*Summary!$B$44*Summary!$B$57)+((H14+J14)*Summary!$B$45*Summary!$B$58)) -> 97412.603 | N14: =L14+M14 -> 520790.48 | O14: =IF(ISERROR(Summary!$B$59+Summary!$B$60+((Calculations!C14/30)/Summary!$B$53*Summary!$B$60)),"",Summary!$B$59+Summary!$B$60+((Calculations!C14/30)/Summary!$B$53*Summary!$B$60)) -> 92923.575 | P14: =IF(ISERROR(IF(K14>0,(K14*Summary!$B$46)+((Calculations!C14+D14)/500*Summary!$B$64),Calculations!N14/Summary!$B$59*Summary!$B$54)),"",IF(G14>0,(G14*Summary!$B$46)+(Calculations!C14/500*Summary!$B$64),Calculations!N14/Summary!$B$59*Summary!$B$54)) -> 59116.727 | Q14: =SUM(N14:P14) -> 672830.78
B15: Art & Music | C15: =IF(ISERROR(INDIRECT(ADDRESS(MATCH(B15,Data!B:B,0),5,1,1,"Data"))*INDIRECT(ADDRESS(MATCH(B15,'Cost Factor'!B:B,0),21,1,1,"Cost Factor"))),"",INDIRECT(ADDRESS(MATCH(B15,Data!B:B,0),5,1,1,"Data"))*INDIRECT(ADDRESS(MATCH(B15,'Cost Factor'!B:B,0),21,1,1,"Cost Factor"))) -> 8883 | D15: =IF(ISERROR(INDIRECT(ADDRESS(MATCH(B15,Data!B:B,0),6,1,1,"Data"))*INDIRECT(ADDRESS(MATCH(B15,'Cost Factor'!B:B,0),21,1,1,"Cost Factor"))),"",INDIRECT(ADDRESS(MATCH(B15,Data!B:B,0),6,1,1,"Data"))*INDIRECT(ADDRESS(MATCH(B15,'Cost Factor'!B:B,0),21,1,1,"Cost Factor"))) -> 0 | E15: =IF(ISERROR(INDIRECT(ADDRESS(MATCH(B15,Data!B:B,0),8,1,1,"Data"))*INDIRECT(ADDRESS(MATCH(B15,'Cost Factor'!B:B,0),21,1,1,"Cost Factor"))),"",INDIRECT(ADDRESS(MATCH(B15,Data!B:B,0),8,1,1,"Data"))*INDIRECT(ADDRESS(MATCH(B15,'Cost Factor'!B:B,0),21,1,1,"Cost Factor"))) -> 0 | F15: =IF(ISERROR(INDIRECT(ADDRESS(MATCH(B15,Data!B:B,0),9,1,1,"Data"))*INDIRECT(ADDRESS(MATCH(B15,'Cost Factor'!B:B,0),21,1,1,"Cost Factor"))),"",INDIRECT(ADDRESS(MATCH(B15,Data!B:B,0),9,1,1,"Data"))*INDIRECT(ADDRESS(MATCH(B15,'Cost Factor'!B:B,0),21,1,1,"Cost Factor"))) -> 0 | G15: =IF(ISERROR(C15/(Summary!$B$47*Summary!$B$49)),"",C15/(Summary!$B$47*Summary!$B$49)) -> 11.215909 | H15: =IF(ISERROR(D15/(Summary!$B$48*Summary!$B$50)),"",D15/(Summary!$B$48*Summary!$B$50)) -> 0 | I15: =E15/(Summary!$B$51*Summary!$B$49*0.67) -> 0 | J15: =F15/(Summary!$B$50*Summary!$B$52*0.67) -> 0 | K15: =H15+G15+I15+J15 -> 11.215909 | L15: =IF(ISERROR(((G15+I15)*Summary!$B$44*Summary!$B$57)+((Calculations!G15+I15)*Summary!$B$45*Summary!$B$58)),"",((G15+I15)*Summary!$B$44*Summary!$B$57)+((Calculations!G15+I15)*Summary!$B$45*Summary!$B$58)) -> 643983.85 | M15: =IF(ISERROR(((H15+J15)*Summary!$B$44*Summary!$B$57)+((H15+J15)*Summary!$B$45*Summary!$B$58)),"",((H15+J15)*Summary!$B$44*Summary!$B$57)+((H15+J15)*Summary!$B$45*Summary!$B$58)) -> 0 | N15: =L15+M15 -> 643983.85 | O15: =IF(ISERROR(Summary!$B$59+Summary!$B$60+((Calculations!C15/30)/Summary!$B$53*Summary!$B$60)),"",Summary!$B$59+Summary!$B$60+((Calculations!C15/30)/Summary!$B$53*Summary!$B$60)) -> 97091.326 | P15: =IF(ISERROR(IF(K15>0,(K15*Summary!$B$46)+((Calculations!C15+D15)/500*Summary!$B$64),Calculations!N15/Summary!$B$59*Summary!$B$54)),"",IF(G15>0,(G15*Summary!$B$46)+(Calculations!C15/500*Summary!$B$64),Calculations!N15/Summary!$B$59*Summary!$B$54)) -> 89920.186 | Q15: =SUM(N15:P15) -> 830995.36
B16: Biology | C16: =IF(ISERROR(INDIRECT(ADDRESS(MATCH(B16,Data!B:B,0),5,1,1,"Data"))*INDIRECT(ADDRESS(MATCH(B16,'Cost Factor'!B:B,0),21,1,1,"Cost Factor"))),"",INDIRECT(ADDRESS(MATCH(B16,Data!B:B,0),5,1,1,"Data"))*INDIRECT(ADDRESS(MATCH(B16,'Cost Factor'!B:B,0),21,1,1,"Cost Factor"))) -> 11864 | D16: =IF(ISERROR(INDIRECT(ADDRESS(MATCH(B16,Data!B:B,0),6,1,1,"Data"))*INDIRECT(ADDRESS(MATCH(B16,'Cost Factor'!B:B,0),21,1,1,"Cost Factor"))),"",INDIRECT(ADDRESS(MATCH(B16,Data!B:B,0),6,1,1,"Data"))*INDIRECT(ADDRESS(MATCH(B16,'Cost Factor'!B:B,0),21,1,1,"Cost Factor"))) -> 379 | E16: =IF(ISERROR(INDIRECT(ADDRESS(MATCH(B16,Data!B:B,0),8,1,1,"Data"))*INDIRECT(ADDRESS(MATCH(B16,'Cost Factor'!B:B,0),21,1,1,"Cost Factor"))),"",INDIRECT(ADDRESS(MATCH(B16,Data!B:B,0),8,1,1,"Data"))*INDIRECT(ADDRESS(MATCH(B16,'Cost Factor'!B:B,0),21,1,1,"Cost Factor"))) -> 0 | F16: =IF(ISERROR(INDIRECT(ADDRESS(MATCH(B16,Data!B:B,0),9,1,1,"Data"))*INDIRECT(ADDRESS(MATCH(B16,'Cost Factor'!B:B,0),21,1,1,"Cost Factor"))),"",INDIRECT(ADDRESS(MATCH(B16,Data!B:B,0),9,1,1,"Data"))*INDIRECT(ADDRESS(MATCH(B16,'Cost Factor'!B:B,0),21,1,1,"Cost Factor"))) -> 0 | G16: =IF(ISERROR(C16/(Summary!$B$47*Summary!$B$49)),"",C16/(Summary!$B$47*Summary!$B$49)) -> 14.979798 | H16: =IF(ISERROR(D16/(Summary!$B$48*Summary!$B$50)),"",D16/(Summary!$B$48*Summary!$B$50)) -> 1.6196581 | I16: =E16/(Summary!$B$51*Summary!$B$49*0.67) -> 0 | J16: =F16/(Summary!$B$50*Summary!$B$52*0.67) -> 0 | K16: =H16+G16+I16+J16 -> 16.599456 | L16: =IF(ISERROR(((G16+I16)*Summary!$B$44*Summary!$B$57)+((Calculations!G16+I16)*Summary!$B$45*Summary!$B$58)),"",((G16+I16)*Summary!$B$44*Summary!$B$57)+((Calculations!G16+I16)*Summary!$B$45*Summary!$B$58)) -> 860095.06 | M16: =IF(ISERROR(((H16+J16)*Summary!$B$44*Summary!$B$57)+((H16+J16)*Summary!$B$45*Summary!$B$58)),"",((H16+J16)*Summary!$B$44*Summary!$B$57)+((H16+J16)*Summary!$B$45*Summary!$B$58)) -> 92995.91 | N16: =L16+M16 -> 953090.97 | O16: =IF(ISERROR(Summary!$B$59+Summary!$B$60+((Calculations!C16/30)/Summary!$B$53*Summary!$B$60)),"",Summary!$B$59+Summary!$B$60+((Calculations!C16/30)/Summary!$B$53*Summary!$B$60)) -> 101174.16 | P16: =IF(ISERROR(IF(K16>0,(K16*Summary!$B$46)+((Calculations!C16+D16)/500*Summary!$B$64),Calculations!N16/Summary!$B$59*Summary!$B$54)),"",IF(G16>0,(G16*Summary!$B$46)+(Calculations!C16/500*Summary!$B$64),Calculations!N16/Summary!$B$59*Summary!$B$54)) -> 120096.04 | Q16: =SUM(N16:P16) -> 1174361.2
B17: Chemistry & Biochemistry | C17: =IF(ISERROR(INDIRECT(ADDRESS(MATCH(B17,Data!B:B,0),5,1,1,"Data"))*INDIRECT(ADDRESS(MATCH(B17,'Cost Factor'!B:B,0),21,1,1,"Cost Factor"))),"",INDIRECT(ADDRESS(MATCH(B17,Data!B:B,0),5,1,1,"Data"))*INDIRECT(ADDRESS(MATCH(B17,'Cost Factor'!B:B,0),21,1,1,"Cost Factor"))) -> 5773 | D17: =IF(ISERROR(INDIRECT(ADDRESS(MATCH(B17,Data!B:B,0),6,1,1,"Data"))*INDIRECT(ADDRESS(MATCH(B17,'Cost Factor'!B:B,0),21,1,1,"Cost Factor"))),"",INDIRECT(ADDRESS(MATCH(B17,Data!B:B,0),6,1,1,"Data"))*INDIRECT(ADDRESS(MATCH(B17,'Cost Factor'!B:B,0),21,1,1,"Cost Factor"))) -> 6 | E17: =IF(ISERROR(INDIRECT(ADDRESS(MATCH(B17,Data!B:B,0),8,1,1,"Data"))*INDIRECT(ADDRESS(MATCH(B17,'Cost Factor'!B:B,0),21,1,1,"Cost Factor"))),"",INDIRECT(ADDRESS(MATCH(B17,Data!B:B,0),8,1,1,"Data"))*INDIRECT(ADDRESS(MATCH(B17,'Cost Factor'!B:B,0),21,1,1,"Cost Factor"))) -> 0 | F17: =IF(ISERROR(INDIRECT(ADDRESS(MATCH(B17,Data!B:B,0),9,1,1,"Data"))*INDIRECT(ADDRESS(MATCH(B17,'Cost Factor'!B:B,0),21,1,1,"Cost Factor"))),"",INDIRECT(ADDRESS(MATCH(B17,Data!B:B,0),9,1,1,"Data"))*INDIRECT(ADDRESS(MATCH(B17,'Cost Factor'!B:B,0),21,1,1,"Cost Factor"))) -> 0 | G17: =IF(ISERROR(C17/(Summary!$B$47*Summary!$B$49)),"",C17/(Summary!$B$47*Summary!$B$49)) -> 7.2891414 | H17: =IF(ISERROR(D17/(Summary!$B$48*Summary!$B$50)),"",D17/(Summary!$B$48*Summary!$B$50)) -> 0.025641026 | I17: =E17/(Summary!$B$51*Summary!$B$49*0.67) -> 0 | J17: =F17/(Summary!$B$50*Summary!$B$52*0.67) -> 0 | K17: =H17+G17+I17+J17 -> 7.3147824 | L17: =IF(ISERROR(((G17+I17)*Summary!$B$44*Summary!$B$57)+((Calculations!G17+I17)*Summary!$B$45*Summary!$B$58)),"",((G17+I17)*Summary!$B$44*Summary!$B$57)+((Calculations!G17+I17)*Summary!$B$45*Summary!$B$58)) -> 418520.63 | M17: =IF(ISERROR(((H17+J17)*Summary!$B$44*Summary!$B$57)+((H17+J17)*Summary!$B$45*Summary!$B$58)),"",((H17+J17)*Summary!$B$44*Summary!$B$57)+((H17+J17)*Summary!$B$45*Summary!$B$58)) -> 1472.2308 | N17: =L17+M17 -> 419992.86 | O17: =IF(ISERROR(Summary!$B$59+Summary!$B$60+((Calculations!C17/30)/Summary!$B$53*Summary!$B$60)),"",Summary!$B$59+Summary!$B$60+((Calculations!C17/30)/Summary!$B$53*Summary!$B$60)) -> 92831.811 | P17: =IF(ISERROR(IF(K17>0,(K17*Summary!$B$46)+((Calculations!C17+D17)/500*Summary!$B$64),Calculations!N17/Summary!$B$59*Summary!$B$54)),"",IF(G17>0,(G17*Summary!$B$46)+(Calculations!C17/500*Summary!$B$64),Calculations!N17/Summary!$B$59*Summary!$B$54)) -> 58438.505 | Q17: =SUM(N17:P17) -> 571263.18
B18: Communication, Mass Media, & Theatre | C18: =IF(ISERROR(INDIRECT(ADDRESS(MATCH(B18,Data!B:B,0),5,1,1,"Data"))*INDIRECT(ADDRESS(MATCH(B18,'Cost Factor'!B:B,0),21,1,1,"Cost Factor"))),"",INDIRECT(ADDRESS(MATCH(B18,Data!B:B,0),5,1,1,"Data"))*INDIRECT(ADDRESS(MATCH(B18,'Cost Factor'!B:B,0),21,1,1,"Cost Factor"))) -> 10961 | D18: =IF(ISERROR(INDIRECT(ADDRESS(MATCH(B18,Data!B:B,0),6,1,1,"Data"))*INDIRECT(ADDRESS(MATCH(B18,'Cost Factor'!B:B,0),21,1,1,"Cost Factor"))),"",INDIRECT(ADDRESS(MATCH(B18,Data!B:B,0),6,1,1,"Data"))*INDIRECT(ADDRESS(MATCH(B18,'Cost Factor'!B:B,0),21,1,1,"Cost Factor"))) -> 399 | E18: =IF(ISERROR(INDIRECT(ADDRESS(MATCH(B18,Data!B:B,0),8,1,1,"Data"))*INDIRECT(ADDRESS(MATCH(B18,'Cost Factor'!B:B,0),21,1,1,"Cost Factor"))),"",INDIRECT(ADDRESS(MATCH(B18,Data!B:B,0),8,1,1,"Data"))*INDIRECT(ADDRESS(MATCH(B18,'Cost Factor'!B:B,0),21,1,1,"Cost Factor"))) -> 0 | F18: =IF(ISERROR(INDIRECT(ADDRESS(MATCH(B18,Data!B:B,0),9,1,1,"Data"))*INDIRECT(ADDRESS(MATCH(B18,'Cost Factor'!B:B,0),21,1,1,"Cost Factor"))),"",INDIRECT(ADDRESS(MATCH(B18,Data!B:B,0),9,1,1,"Data"))*INDIRECT(ADDRESS(MATCH(B18,'Cost Factor'!B:B,0),21,1,1,"Cost Factor"))) -> 0 | G18: =IF(ISERROR(C18/(Summary!$B$47*Summary!$B$49)),"",C18/(Summary!$B$47*Summary!$B$49)) -> 13.839646 | H18: =IF(ISERROR(D18/(Summary!$B$48*Summary!$B$50)),"",D18/(Summary!$B$48*Summary!$B$50)) -> 1.7051282 | I18: =E18/(Summary!$B$51*Summary!$B$49*0.67) -> 0 | J18: =F18/(Summary!$B$50*Summary!$B$52*0.67) -> 0 | K18: =H18+G18+I18+J18 -> 15.544775 | L18: =IF(ISERROR(((G18+I18)*Summary!$B$44*Summary!$B$57)+((Calculations!G18+I18)*Summary!$B$45*Summary!$B$58)),"",((G18+I18)*Summary!$B$44*Summary!$B$57)+((Calculations!G18+I18)*Summary!$B$45*Summary!$B$58)) -> 794630.98 | M18: =IF(ISERROR(((H18+J18)*Summary!$B$44*Summary!$B$57)+((H18+J18)*Summary!$B$45*Summary!$B$58)),"",((H18+J18)*Summary!$B$44*Summary!$B$57)+((H18+J18)*Summary!$B$45*Summary!$B$58)) -> 97903.346 | N18: =L18+M18 -> 892534.33 | O18: =IF(ISERROR(Summary!$B$59+Summary!$B$60+((Calculations!C18/30)/Summary!$B$53*Summary!$B$60)),"",Summary!$B$59+Summary!$B$60+((Calculations!C18/30)/Summary!$B$53*Summary!$B$60)) -> 99937.394 | P18: =IF(ISERROR(IF(K18>0,(K18*Summary!$B$46)+((Calculations!C18+D18)/500*Summary!$B$64),Calculations!N18/Summary!$B$59*Summary!$B$54)),"",IF(G18>0,(G18*Summary!$B$46)+(Calculations!C18/500*Summary!$B$64),Calculations!N18/Summary!$B$59*Summary!$B$54)) -> 110955.21 | Q18: =SUM(N18:P18) -> 1103426.9
B19: English & Modern Langagues | C19: =IF(ISERROR(INDIRECT(ADDRESS(MATCH(B19,Data!B:B,0),5,1,1,"Data"))*INDIRECT(ADDRESS(MATCH(B19,'Cost Factor'!B:B,0),21,1,1,"Cost Factor"))),"",INDIRECT(ADDRESS(MATCH(B19,Data!B:B,0),5,1,1,"Data"))*INDIRECT(ADDRESS(MATCH(B19,'Cost Factor'!B:B,0),21,1,1,"Cost Factor"))) -> 18051 | D19: =IF(ISERROR(INDIRECT(ADDRESS(MATCH(B19,Data!B:B,0),6,1,1,"Data"))*INDIRECT(ADDRESS(MATCH(B19,'Cost Factor'!B:B,0),21,1,1,"Cost Factor"))),"",INDIRECT(ADDRESS(MATCH(B19,Data!B:B,0),6,1,1,"Data"))*INDIRECT(ADDRESS(MATCH(B19,'Cost Factor'!B:B,0),21,1,1,"Cost Factor"))) -> 252 | E19: =IF(ISERROR(INDIRECT(ADDRESS(MATCH(B19,Data!B:B,0),8,1,1,"Data"))*INDIRECT(ADDRESS(MATCH(B19,'Cost Factor'!B:B,0),21,1,1,"Cost Factor"))),"",INDIRECT(ADDRESS(MATCH(B19,Data!B:B,0),8,1,1,"Data"))*INDIRECT(ADDRESS(MATCH(B19,'Cost Factor'!B:B,0),21,1,1,"Cost Factor"))) -> 0 | F19: =IF(ISERROR(INDIRECT(ADDRESS(MATCH(B19,Data!B:B,0),9,1,1,"Data"))*INDIRECT(ADDRESS(MATCH(B19,'Cost Factor'!B:B,0),21,1,1,"Cost Factor"))),"",INDIRECT(ADDRESS(MATCH(B19,Data!B:B,0),9,1,1,"Data"))*INDIRECT(ADDRESS(MATCH(B19,'Cost Factor'!B:B,0),21,1,1,"Cost Factor"))) -> 0 | G19: =IF(ISERROR(C19/(Summary!$B$47*Summary!$B$49)),"",C19/(Summary!$B$47*Summary!$B$49)) -> 22.791667 | H19: =IF(ISERROR(D19/(Summary!$B$48*Summary!$B$50)),"",D19/(Summary!$B$48*Summary!$B$50)) -> 1.0769231 | I19: =E19/(Summary!$B$51*Summary!$B$49*0.67) -> 0 | J19: =F19/(Summary!$B$50*Summary!$B$52*0.67) -> 0 | K19: =H19+G19+I19+J19 -> 23.86859 | L19: =IF(ISERROR(((G19+I19)*Summary!$B$44*Summary!$B$57)+((Calculations!G19+I19)*Summary!$B$45*Summary!$B$58)),"",((G19+I19)*Summary!$B$44*Summary!$B$57)+((Calculations!G19+I19)*Summary!$B$45*Summary!$B$58)) -> 1308629.1 | M19: =IF(ISERROR(((H19+J19)*Summary!$B$44*Summary!$B$57)+((H19+J19)*Summary!$B$45*Summary!$B$58)),"",((H19+J19)*Summary!$B$44*Summary!$B$57)+((H19+J19)*Summary!$B$45*Summary!$B$58)) -> 61833.692 | N19: =L19+M19 -> 1370462.8 | O19: =IF(ISERROR(Summary!$B$59+Summary!$B$60+((Calculations!C19/30)/Summary!$B$53*Summary!$B$60)),"",Summary!$B$59+Summary!$B$60+((Calculations!C19/30)/Summary!$B$53*Summary!$B$60)) -> 109647.99 | P19: =IF(ISERROR(IF(K19>0,(K19*Summary!$B$46)+((Calculations!C19+D19)/500*Summary!$B$64),Calculations!N19/Summary!$B$59*Summary!$B$54)),"",IF(G19>0,(G19*Summary!$B$46)+(Calculations!C19/500*Summary!$B$64),Calculations!N19/Summary!$B$59*Summary!$B$54)) -> 182725.35 | Q19: =SUM(N19:P19) -> 1662836.2
B20: Pol Science | C20: =IF(ISERROR(INDIRECT(ADDRESS(MATCH(B20,Data!B:B,0),5,1,1,"Data"))*INDIRECT(ADDRESS(MATCH(B20,'Cost Factor'!B:B,0),21,1,1,"Cost Factor"))),"",INDIRECT(ADDRESS(MATCH(B20,Data!B:B,0),5,1,1,"Data"))*INDIRECT(ADDRESS(MATCH(B20,'Cost Factor'!B:B,0),21,1,1,"Cost Factor"))) -> 4518 | D20: =IF(ISERROR(INDIRECT(ADDRESS(MATCH(B20,Data!B:B,0),6,1,1,"Data"))*INDIRECT(ADDRESS(MATCH(B20,'Cost Factor'!B:B,0),21,1,1,"Cost Factor"))),"",INDIRECT(ADDRESS(MATCH(B20,Data!B:B,0),6,1,1,"Data"))*INDIRECT(ADDRESS(MATCH(B20,'Cost Factor'!B:B,0),21,1,1,"Cost Factor"))) -> 9 | E20: =IF(ISERROR(INDIRECT(ADDRESS(MATCH(B20,Data!B:B,0),8,1,1,"Data"))*INDIRECT(ADDRESS(MATCH(B20,'Cost Factor'!B:B,0),21,1,1,"Cost Factor"))),"",INDIRECT(ADDRESS(MATCH(B20,Data!B:B,0),8,1,1,"Data"))*INDIRECT(ADDRESS(MATCH(B20,'Cost Factor'!B:B,0),21,1,1,"Cost Factor"))) -> 0 | F20: =IF(ISERROR(INDIRECT(ADDRESS(MATCH(B20,Data!B:B,0),9,1,1,"Data"))*INDIRECT(ADDRESS(MATCH(B20,'Cost Factor'!B:B,0),21,1,1,"Cost Factor"))),"",INDIRECT(ADDRESS(MATCH(B20,Data!B:B,0),9,1,1,"Data"))*INDIRECT(ADDRESS(MATCH(B20,'Cost Factor'!B:B,0),21,1,1,"Cost Factor"))) -> 0 | G20: =IF(ISERROR(C20/(Summary!$B$47*Summary!$B$49)),"",C20/(Summary!$B$47*Summary!$B$49)) -> 5.7045455 | H20: =IF(ISERROR(D20/(Summary!$B$48*Summary!$B$50)),"",D20/(Summary!$B$48*Summary!$B$50)) -> 0.038461538 | I20: =E20/(Summary!$B$51*Summary!$B$49*0.67) -> 0 | J20: =F20/(Summary!$B$50*Summary!$B$52*0.67) -> 0 | K20: =H20+G20+I20+J20 -> 5.743007 | L20: =IF(ISERROR(((G20+I20)*Summary!$B$44*Summary!$B$57)+((Calculations!G20+I20)*Summary!$B$45*Summary!$B$58)),"",((G20+I20)*Summary!$B$44*Summary!$B$57)+((Calculations!G20+I20)*Summary!$B$45*Summary!$B$58)) -> 327537.89 | M20: =IF(ISERROR(((H20+J20)*Summary!$B$44*Summary!$B$57)+((H20+J20)*Summary!$B$45*Summary!$B$58)),"",((H20+J20)*Summary!$B$44*Summary!$B$57)+((H20+J20)*Summary!$B$45*Summary!$B$58)) -> 2208.3462 | N20: =L20+M20 -> 329746.23 | O20: =IF(ISERROR(Summary!$B$59+Summary!$B$60+((Calculations!C20/30)/Summary!$B$53*Summary!$B$60)),"",Summary!$B$59+Summary!$B$60+((Calculations!C20/30)/Summary!$B$53*Summary!$B$60)) -> 91112.939 | P20: =IF(ISERROR(IF(K20>0,(K20*Summary!$B$46)+((Calculations!C20+D20)/500*Summary!$B$64),Calculations!N20/Summary!$B$59*Summary!$B$54)),"",IF(G20>0,(G20*Summary!$B$46)+(Calculations!C20/500*Summary!$B$64),Calculations!N20/Summary!$B$59*Summary!$B$54)) -> 45734.482 | Q20: =SUM(N20:P20) -> 466593.65
B21: History | C21: =IF(ISERROR(INDIRECT(ADDRESS(MATCH(B21,Data!B:B,0),5,1,1,"Data"))*INDIRECT(ADDRESS(MATCH(B21,'Cost Factor'!B:B,0),21,1,1,"Cost Factor"))),"",INDIRECT(ADDRESS(MATCH(B21,Data!B:B,0),5,1,1,"Data"))*INDIRECT(ADDRESS(MATCH(B21,'Cost Factor'!B:B,0),21,1,1,"Cost Factor"))) -> 13308 | D21: =IF(ISERROR(INDIRECT(ADDRESS(MATCH(B21,Data!B:B,0),6,1,1,"Data"))*INDIRECT(ADDRESS(MATCH(B21,'Cost Factor'!B:B,0),21,1,1,"Cost Factor"))),"",INDIRECT(ADDRESS(MATCH(B21,Data!B:B,0),6,1,1,"Data"))*INDIRECT(ADDRESS(MATCH(B21,'Cost Factor'!B:B,0),21,1,1,"Cost Factor"))) -> 105 | E21: =IF(ISERROR(INDIRECT(ADDRESS(MATCH(B21,Data!B:B,0),8,1,1,"Data"))*INDIRECT(ADDRESS(MATCH(B21,'Cost Factor'!B:B,0),21,1,1,"Cost Factor"))),"",INDIRECT(ADDRESS(MATCH(B21,Data!B:B,0),8,1,1,"Data"))*INDIRECT(ADDRESS(MATCH(B21,'Cost Factor'!B:B,0),21,1,1,"Cost Factor"))) -> 0 | F21: =IF(ISERROR(INDIRECT(ADDRESS(MATCH(B21,Data!B:B,0),9,1,1,"Data"))*INDIRECT(ADDRESS(MATCH(B21,'Cost Factor'!B:B,0),21,1,1,"Cost Factor"))),"",INDIRECT(ADDRESS(MATCH(B21,Data!B:B,0),9,1,1,"Data"))*INDIRECT(ADDRESS(MATCH(B21,'Cost Factor'!B:B,0),21,1,1,"Cost Factor"))) -> 0 | G21: =IF(ISERROR(C21/(Summary!$B$47*Summary!$B$49)),"",C21/(Summary!$B$47*Summary!$B$49)) -> 16.80303 | H21: =IF(ISERROR(D21/(Summary!$B$48*Summary!$B$50)),"",D21/(Summary!$B$48*Summary!$B$50)) -> 0.44871795 | I21: =E21/(Summary!$B$51*Summary!$B$49*0.67) -> 0 | J21: =F21/(Summary!$B$50*Summary!$B$52*0.67) -> 0 | K21: =H21+G21+I21+J21 -> 17.251748 | L21: =IF(ISERROR(((G21+I21)*Summary!$B$44*Summary!$B$57)+((Calculations!G21+I21)*Summary!$B$45*Summary!$B$58)),"",((G21+I21)*Summary!$B$44*Summary!$B$57)+((Calculations!G21+I21)*Summary!$B$45*Summary!$B$58)) -> 964779.59 | M21: =IF(ISERROR(((H21+J21)*Summary!$B$44*Summary!$B$57)+((H21+J21)*Summary!$B$45*Summary!$B$58)),"",((H21+J21)*Summary!$B$44*Summary!$B$57)+((H21+J21)*Summary!$B$45*Summary!$B$58)) -> 25764.038 | N21: =L21+M21 -> 990543.63 | O21: =IF(ISERROR(Summary!$B$59+Summary!$B$60+((Calculations!C21/30)/Summary!$B$53*Summary!$B$60)),"",Summary!$B$59+Summary!$B$60+((Calculations!C21/30)/Summary!$B$53*Summary!$B$60)) -> 103151.89 | P21: =IF(ISERROR(IF(K21>0,(K21*Summary!$B$46)+((Calculations!C21+D21)/500*Summary!$B$64),Calculations!N21/Summary!$B$59*Summary!$B$54)),"",IF(G21>0,(G21*Summary!$B$46)+(Calculations!C21/500*Summary!$B$64),Calculations!N21/Summary!$B$59*Summary!$B$54)) -> 134713.25 | Q21: =SUM(N21:P21) -> 1228408.8
B22: Mathematics & Computer Science | C22: =IF(ISERROR(INDIRECT(ADDRESS(MATCH(B22,Data!B:B,0),5,1,1,"Data"))*INDIRECT(ADDRESS(MATCH(B22,'Cost Factor'!B:B,0),21,1,1,"Cost Factor"))),"",INDIRECT(ADDRESS(MATCH(B22,Data!B:B,0),5,1,1,"Data"))*INDIRECT(ADDRESS(MATCH(B22,'Cost Factor'!B:B,0),21,1,1,"Cost Factor"))) -> 14642.968 | D22: =IF(ISERROR(INDIRECT(ADDRESS(MATCH(B22,Data!B:B,0),6,1,1,"Data"))*INDIRECT(ADDRESS(MATCH(B22,'Cost Factor'!B:B,0),21,1,1,"Cost Factor"))),"",INDIRECT(ADDRESS(MATCH(B22,Data!B:B,0),6,1,1,"Data"))*INDIRECT(ADDRESS(MATCH(B22,'Cost Factor'!B:B,0),21,1,1,"Cost Factor"))) -> 0 | E22: =IF(ISERROR(INDIRECT(ADDRESS(MATCH(B22,Data!B:B,0),8,1,1,"Data"))*INDIRECT(ADDRESS(MATCH(B22,'Cost Factor'!B:B,0),21,1,1,"Cost Factor"))),"",INDIRECT(ADDRESS(MATCH(B22,Data!B:B,0),8,1,1,"Data"))*INDIRECT(ADDRESS(MATCH(B22,'Cost Factor'!B:B,0),21,1,1,"Cost Factor"))) -> 0 | F22: =IF(ISERROR(INDIRECT(ADDRESS(MATCH(B22,Data!B:B,0),9,1,1,"Data"))*INDIRECT(ADDRESS(MATCH(B22,'Cost Factor'!B:B,0),21,1,1,"Cost Factor"))),"",INDIRECT(ADDRESS(MATCH(B22,Data!B:B,0),9,1,1,"Data"))*INDIRECT(ADDRESS(MATCH(B22,'Cost Factor'!B:B,0),21,1,1,"Cost Factor"))) -> 0 | G22: =IF(ISERROR(C22/(Summary!$B$47*Summary!$B$49)),"",C22/(Summary!$B$47*Summary!$B$49)) -> 18.488596 | H22: =IF(ISERROR(D22/(Summary!$B$48*Summary!$B$50)),"",D22/(Summary!$B$48*Summary!$B$50)) -> 0 | I22: =E22/(Summary!$B$51*Summary!$B$49*0.67) -> 0 | J22: =F22/(Summary!$B$50*Summary!$B$52*0.67) -> 0 | K22: =H22+G22+I22+J22 -> 18.488596 | L22: =IF(ISERROR(((G22+I22)*Summary!$B$44*Summary!$B$57)+((Calculations!G22+I22)*Summary!$B$45*Summary!$B$58)),"",((G22+I22)*Summary!$B$44*Summary!$B$57)+((Calculations!G22+I22)*Summary!$B$45*Summary!$B$58)) -> 1061559.7 | M22: =IF(ISERROR(((H22+J22)*Summary!$B$44*Summary!$B$57)+((H22+J22)*Summary!$B$45*Summary!$B$58)),"",((H22+J22)*Summary!$B$44*Summary!$B$57)+((H22+J22)*Summary!$B$45*Summary!$B$58)) -> 0 | N22: =L22+M22 -> 1061559.7 | O22: =IF(ISERROR(Summary!$B$59+Summary!$B$60+((Calculations!C22/30)/Summary!$B$53*Summary!$B$60)),"",Summary!$B$59+Summary!$B$60+((Calculations!C22/30)/Summary!$B$53*Summary!$B$60)) -> 104980.29 | P22: =IF(ISERROR(IF(K22>0,(K22*Summary!$B$46)+((Calculations!C22+D22)/500*Summary!$B$64),Calculations!N22/Summary!$B$59*Summary!$B$54)),"",IF(G22>0,(G22*Summary!$B$46)+(Calculations!C22/500*Summary!$B$64),Calculations!N22/Summary!$B$59*Summary!$B$54)) -> 148226.77 | Q22: =SUM(N22:P22) -> 1314766.8
B23: Physics | C23: =IF(ISERROR(INDIRECT(ADDRESS(MATCH(B23,Data!B:B,0),5,1,1,"Data"))*INDIRECT(ADDRESS(MATCH(B23,'Cost Factor'!B:B,0),21,1,1,"Cost Factor"))),"",INDIRECT(ADDRESS(MATCH(B23,Data!B:B,0),5,1,1,"Data"))*INDIRECT(ADDRESS(MATCH(B23,'Cost Factor'!B:B,0),21,1,1,"Cost Factor"))) -> 8193 | D23: =IF(ISERROR(INDIRECT(ADDRESS(MATCH(B23,Data!B:B,0),6,1,1,"Data"))*INDIRECT(ADDRESS(MATCH(B23,'Cost Factor'!B:B,0),21,1,1,"Cost Factor"))),"",INDIRECT(ADDRESS(MATCH(B23,Data!B:B,0),6,1,1,"Data"))*INDIRECT(ADDRESS(MATCH(B23,'Cost Factor'!B:B,0),21,1,1,"Cost Factor"))) -> 0 | E23: =IF(ISERROR(INDIRECT(ADDRESS(MATCH(B23,Data!B:B,0),8,1,1,"Data"))*INDIRECT(ADDRESS(MATCH(B23,'Cost Factor'!B:B,0),21,1,1,"Cost Factor"))),"",INDIRECT(ADDRESS(MATCH(B23,Data!B:B,0),8,1,1,"Data"))*INDIRECT(ADDRESS(MATCH(B23,'Cost Factor'!B:B,0),21,1,1,"Cost Factor"))) -> 0 | F23: =IF(ISERROR(INDIRECT(ADDRESS(MATCH(B23,Data!B:B,0),9,1,1,"Data"))*INDIRECT(ADDRESS(MATCH(B23,'Cost Factor'!B:B,0),21,1,1,"Cost Factor"))),"",INDIRECT(ADDRESS(MATCH(B23,Data!B:B,0),9,1,1,"Data"))*INDIRECT(ADDRESS(MATCH(B23,'Cost Factor'!B:B,0),21,1,1,"Cost Factor"))) -> 0 | G23: =IF(ISERROR(C23/(Summary!$B$47*Summary!$B$49)),"",C23/(Summary!$B$47*Summary!$B$49)) -> 10.344697 | H23: =IF(ISERROR(D23/(Summary!$B$48*Summary!$B$50)),"",D23/(Summary!$B$48*Summary!$B$50)) -> 0 | I23: =E23/(Summary!$B$51*Summary!$B$49*0.67) -> 0 | J23: =F23/(Summary!$B$50*Summary!$B$52*0.67) -> 0 | K23: =H23+G23+I23+J23 -> 10.344697 | L23: =IF(ISERROR(((G23+I23)*Summary!$B$44*Summary!$B$57)+((Calculations!G23+I23)*Summary!$B$45*Summary!$B$58)),"",((G23+I23)*Summary!$B$44*Summary!$B$57)+((Calculations!G23+I23)*Summary!$B$45*Summary!$B$58)) -> 593961.47 | M23: =IF(ISERROR(((H23+J23)*Summary!$B$44*Summary!$B$57)+((H23+J23)*Summary!$B$45*Summary!$B$58)),"",((H23+J23)*Summary!$B$44*Summary!$B$57)+((H23+J23)*Summary!$B$45*Summary!$B$58)) -> 0 | N23: =L23+M23 -> 593961.47 | O23: =IF(ISERROR(Summary!$B$59+Summary!$B$60+((Calculations!C23/30)/Summary!$B$53*Summary!$B$60)),"",Summary!$B$59+Summary!$B$60+((Calculations!C23/30)/Summary!$B$53*Summary!$B$60)) -> 96146.289 | P23: =IF(ISERROR(IF(K23>0,(K23*Summary!$B$46)+((Calculations!C23+D23)/500*Summary!$B$64),Calculations!N23/Summary!$B$59*Summary!$B$54)),"",IF(G23>0,(G23*Summary!$B$46)+(Calculations!C23/500*Summary!$B$64),Calculations!N23/Summary!$B$59*Summary!$B$54)) -> 82935.505 | Q23: =SUM(N23:P23) -> 773043.26
B24: Accounting, Economics, & Finance | C24: =IF(ISERROR(INDIRECT(ADDRESS(MATCH(B24,Data!B:B,0),5,1,1,"Data"))*INDIRECT(ADDRESS(MATCH(B24,'Cost Factor'!B:B,0),21,1,1,"Cost Factor"))),"",INDIRECT(ADDRESS(MATCH(B24,Data!B:B,0),5,1,1,"Data"))*INDIRECT(ADDRESS(MATCH(B24,'Cost Factor'!B:B,0),21,1,1,"Cost Factor"))) -> 8766 | D24: =IF(ISERROR(INDIRECT(ADDRESS(MATCH(B24,Data!B:B,0),6,1,1,"Data"))*INDIRECT(ADDRESS(MATCH(B24,'Cost Factor'!B:B,0),21,1,1,"Cost Factor"))),"",INDIRECT(ADDRESS(MATCH(B24,Data!B:B,0),6,1,1,"Data"))*INDIRECT(ADDRESS(MATCH(B24,'Cost Factor'!B:B,0),21,1,1,"Cost Factor"))) -> 461 | E24: =IF(ISERROR(INDIRECT(ADDRESS(MATCH(B24,Data!B:B,0),8,1,1,"Data"))*INDIRECT(ADDRESS(MATCH(B24,'Cost Factor'!B:B,0),21,1,1,"Cost Factor"))),"",INDIRECT(ADDRESS(MATCH(B24,Data!B:B,0),8,1,1,"Data"))*INDIRECT(ADDRESS(MATCH(B24,'Cost Factor'!B:B,0),21,1,1,"Cost Factor"))) -> 0 | F24: =IF(ISERROR(INDIRECT(ADDRESS(MATCH(B24,Data!B:B,0),9,1,1,"Data"))*INDIRECT(ADDRESS(MATCH(B24,'Cost Factor'!B:B,0),21,1,1,"Cost Factor"))),"",INDIRECT(ADDRESS(MATCH(B24,Data!B:B,0),9,1,1,"Data"))*INDIRECT(ADDRESS(MATCH(B24,'Cost Factor'!B:B,0),21,1,1,"Cost Factor"))) -> 0 | G24: =IF(ISERROR(C24/(Summary!$B$47*Summary!$B$49)),"",C24/(Summary!$B$47*Summary!$B$49)) -> 11.068182 | H24: =IF(ISERROR(D24/(Summary!$B$48*Summary!$B$50)),"",D24/(Summary!$B$48*Summary!$B$50)) -> 1.9700855 | I24: =E24/(Summary!$B$51*Summary!$B$49*0.67) -> 0 | J24: =F24/(Summary!$B$50*Summary!$B$52*0.67) -> 0 | K24: =H24+G24+I24+J24 -> 13.038267 | L24: =IF(ISERROR(((G24+I24)*Summary!$B$44*Summary!$B$57)+((Calculations!G24+I24)*Summary!$B$45*Summary!$B$58)),"",((G24+I24)*Summary!$B$44*Summary!$B$57)+((Calculations!G24+I24)*Summary!$B$45*Summary!$B$58)) -> 635501.8 | M24: =IF(ISERROR(((H24+J24)*Summary!$B$44*Summary!$B$57)+((H24+J24)*Summary!$B$45*Summary!$B$58)),"",((H24+J24)*Summary!$B$44*Summary!$B$57)+((H24+J24)*Summary!$B$45*Summary!$B$58)) -> 113116.4 | N24: =L24+M24 -> 748618.19 | O24: =IF(ISERROR(Summary!$B$59+Summary!$B$60+((Calculations!C24/30)/Summary!$B$53*Summary!$B$60)),"",Summary!$B$59+Summary!$B$60+((Calculations!C24/30)/Summary!$B$53*Summary!$B$60)) -> 96931.081 | P24: =IF(ISERROR(IF(K24>0,(K24*Summary!$B$46)+((Calculations!C24+D24)/500*Summary!$B$64),Calculations!N24/Summary!$B$59*Summary!$B$54)),"",IF(G24>0,(G24*Summary!$B$46)+(Calculations!C24/500*Summary!$B$64),Calculations!N24/Summary!$B$59*Summary!$B$54)) -> 88735.827 | Q24: =SUM(N24:P24) -> 934285.1
B25: Aerospace Studies | C25: =IF(ISERROR(INDIRECT(ADDRESS(MATCH(B25,Data!B:B,0),5,1,1,"Data"))*INDIRECT(ADDRESS(MATCH(B25,'Cost Factor'!B:B,0),21,1,1,"Cost Factor"))),"",INDIRECT(ADDRESS(MATCH(B25,Data!B:B,0),5,1,1,"Data"))*INDIRECT(ADDRESS(MATCH(B25,'Cost Factor'!B:B,0),21,1,1,"Cost Factor"))) -> 553 | D25: =IF(ISERROR(INDIRECT(ADDRESS(MATCH(B25,Data!B:B,0),6,1,1,"Data"))*INDIRECT(ADDRESS(MATCH(B25,'Cost Factor'!B:B,0),21,1,1,"Cost Factor"))),"",INDIRECT(ADDRESS(MATCH(B25,Data!B:B,0),6,1,1,"Data"))*INDIRECT(ADDRESS(MATCH(B25,'Cost Factor'!B:B,0),21,1,1,"Cost Factor"))) -> 0 | E25: =IF(ISERROR(INDIRECT(ADDRESS(MATCH(B25,Data!B:B,0),8,1,1,"Data"))*INDIRECT(ADDRESS(MATCH(B25,'Cost Factor'!B:B,0),21,1,1,"Cost Factor"))),"",INDIRECT(ADDRESS(MATCH(B25,Data!B:B,0),8,1,1,"Data"))*INDIRECT(ADDRESS(MATCH(B25,'Cost Factor'!B:B,0),21,1,1,"Cost Factor"))) -> 0 | F25: =IF(ISERROR(INDIRECT(ADDRESS(MATCH(B25,Data!B:B,0),9,1,1,"Data"))*INDIRECT(ADDRESS(MATCH(B25,'Cost Factor'!B:B,0),21,1,1,"Cost Factor"))),"",INDIRECT(ADDRESS(MATCH(B25,Data!B:B,0),9,1,1,"Data"))*INDIRECT(ADDRESS(MATCH(B25,'Cost Factor'!B:B,0),21,1,1,"Cost Factor"))) -> 0 | G25: =IF(ISERROR(C25/(Summary!$B$47*Summary!$B$49)),"",C25/(Summary!$B$47*Summary!$B$49)) -> 0.69823232 | H25: =IF(ISERROR(D25/(Summary!$B$48*Summary!$B$50)),"",D25/(Summary!$B$48*Summary!$B$50)) -> 0 | I25: =E25/(Summary!$B$51*Summary!$B$49*0.67) -> 0 | J25: =F25/(Summary!$B$50*Summary!$B$52*0.67) -> 0 | K25: =H25+G25+I25+J25 -> 0.69823232 | L25: =IF(ISERROR(((G25+I25)*Summary!$B$44*Summary!$B$57)+((Calculations!G25+I25)*Summary!$B$45*Summary!$B$58)),"",((G25+I25)*Summary!$B$44*Summary!$B$57)+((Calculations!G25+I25)*Summary!$B$45*Summary!$B$58)) -> 40090.405 | M25: =IF(ISERROR(((H25+J25)*Summary!$B$44*Summary!$B$57)+((H25+J25)*Summary!$B$45*Summary!$B$58)),"",((H25+J25)*Summary!$B$44*Summary!$B$57)+((H25+J25)*Summary!$B$45*Summary!$B$58)) -> 0 | N25: =L25+M25 -> 40090.405 | O25: =IF(ISERROR(Summary!$B$59+Summary!$B$60+((Calculations!C25/30)/Summary!$B$53*Summary!$B$60)),"",Summary!$B$59+Summary!$B$60+((Calculations!C25/30)/Summary!$B$53*Summary!$B$60)) -> 85682.399 | P25: =IF(ISERROR(IF(K25>0,(K25*Summary!$B$46)+((Calculations!C25+D25)/500*Summary!$B$64),Calculations!N25/Summary!$B$59*Summary!$B$54)),"",IF(G25>0,(G25*Summary!$B$46)+(Calculations!C25/500*Summary!$B$64),Calculations!N25/Summary!$B$59*Summary!$B$54)) -> 5597.8682 | Q25: =SUM(N25:P25) -> 131370.67
... B35: Academic Affairs | C35: =IF(ISERROR(INDIRECT(ADDRESS(MATCH(B35,Data!B:B,0),5,1,1,"Data"))*INDIRECT(ADDRESS(MATCH(B35,'Cost Factor'!B:B,0),21,1,1,"Cost Factor"))),"",INDIRECT(ADDRESS(MATCH(B35,Data!B:B,0),5,1,1,"Data"))*INDIRECT(ADDRESS(MATCH(B35,'Cost Factor'!B:B,0),21,1,1,"Cost Factor"))) -> 1658 | D35: =IF(ISERROR(INDIRECT(ADDRESS(MATCH(B35,Data!B:B,0),6,1,1,"Data"))*INDIRECT(ADDRESS(MATCH(B35,'Cost Factor'!B:B,0),21,1,1,"Cost Factor"))),"",INDIRECT(ADDRESS(MATCH(B35,Data!B:B,0),6,1,1,"Data"))*INDIRECT(ADDRESS(MATCH(B35,'Cost Factor'!B:B,0),21,1,1,"Cost Factor"))) -> 0 | E35: =IF(ISERROR(INDIRECT(ADDRESS(MATCH(B35,Data!B:B,0),8,1,1,"Data"))*INDIRECT(ADDRESS(MATCH(B35,'Cost Factor'!B:B,0),21,1,1,"Cost Factor"))),"",INDIRECT(ADDRESS(MATCH(B35,Data!B:B,0),8,1,1,"Data"))*INDIRECT(ADDRESS(MATCH(B35,'Cost Factor'!B:B,0),21,1,1,"Cost Factor"))) -> 0 | F35: =IF(ISERROR(INDIRECT(ADDRESS(MATCH(B35,Data!B:B,0),9,1,1,"Data"))*INDIRECT(ADDRESS(MATCH(B35,'Cost Factor'!B:B,0),21,1,1,"Cost Factor"))),"",INDIRECT(ADDRESS(MATCH(B35,Data!B:B,0),9,1,1,"Data"))*INDIRECT(ADDRESS(MATCH(B35,'Cost Factor'!B:B,0),21,1,1,"Cost Factor"))) -> 0 | G35: =IF(ISERROR(C35/(Summary!$B$47*Summary!$B$49)),"",C35/(Summary!$B$47*Summary!$B$49)) -> 2.0934343 | H35: =IF(ISERROR(D35/(Summary!$B$48*Summary!$B$50)),"",D35/(Summary!$B$48*Summary!$B$50)) -> 0 | I35: =E35/(Summary!$B$51*Summary!$B$49*0.67) -> 0 | J35: =F35/(Summary!$B$50*Summary!$B$52*0.67) -> 0 | K35: =H35+G35+I35+J35 -> 2.0934343 | L35: =IF(ISERROR(((G35+I35)*Summary!$B$44*Summary!$B$57)+((Calculations!G35+I35)*Summary!$B$45*Summary!$B$58)),"",((G35+I35)*Summary!$B$44*Summary!$B$57)+((Calculations!G35+I35)*Summary!$B$45*Summary!$B$58)) -> 120198.72 | M35: =IF(ISERROR(((H35+J35)*Summary!$B$44*Summary!$B$57)+((H35+J35)*Summary!$B$45*Summary!$B$58)),"",((H35+J35)*Summary!$B$44*Summary!$B$57)+((H35+J35)*Summary!$B$45*Summary!$B$58)) -> 0 | N35: =L35+M35 -> 120198.72 | O35: =IF(ISERROR(Summary!$B$59+Summary!$B$60+((Calculations!C35/30)/Summary!$B$53*Summary!$B$60)),"",Summary!$B$59+Summary!$B$60+((Calculations!C35/30)/Summary!$B$53*Summary!$B$60)) -> 87195.828 | P35: =IF(ISERROR(IF(K35>0,(K35*Summary!$B$46)+((Calculations!C35+D35)/500*Summary!$B$64),Calculations!N35/Summary!$B$59*Summary!$B$54)),"",IF(G35>0,(G35*Summary!$B$46)+(Calculations!C35/500*Summary!$B$64),Calculations!N35/Summary!$B$59*Summary!$B$54)) -> 16783.482 | Q35: =SUM(N35:P35) -> 224178.03
B36: Facilities

Sheet Cost Factor
C1: 2010/11
B2: Total Adjusted Revenues | C2: =Revenue!J62 -> 47056603
B3: Administrative $
B4: Facility $ (prior yr facilities allocation) | C4: 4206660
B5: Instructional Funding | C5: =C33 -> 18412640
B6: Inst. Overhead Factor | C6: =(C2-C4-C5)/C5 -> 1.3272026
I7: Not Needed
C9: 2010/11 Expenditures | D9: 2010/11 Instructional Compensation | E9: 2011/12 Total Credits | F9: Instructional Cost per Credit | G9: Departmental Cost per Credit | H9: Institutional Cost per Credit | I9: Departmental Overhead % | J9: Calculated Faculty FTE | K9: Actual Faculty FTE | L9: Faculty Instructional Hours | M9: IH_Cost | N9: Department IH_Cost | O9: Institutional IH_Cost | P9: Revenue per Credit Hour | Q9: Instructional Break-Even Class Size | R9: Departmental Break-Even Class Size | S9: Institutional Break-Even Class Size | T9: Restricted Class Size | U9: Cost Factor
B10: Agriculture | C10: =INDIRECT(ADDRESS(MATCH(B10,Summary!A:A,0),7,1,1,"Summary")) -> 599585.43 | D10: 404624.43 | E10: =INDIRECT(ADDRESS(MATCH(B10,Data!B:B,0),7,1,1,"Data")) -> 6237 | F10: =IF(ISERROR(D10/E10),"",D10/E10) -> 64.874848 | G10: =IF(ISERROR((C10)/E10),"",(C10)/E10) -> 96.133627 | H10: =IF(ISERROR(G10*(1+$C$6)),"",G10*(1+$C$6)) -> 223.72242 | I10: =IF(ISERROR((G10/F10)-1),"",(G10/F10)-1) -> 0.481832 | J10: =INDIRECT(ADDRESS(MATCH(B10,Calculations!B:B,0),11,1,1,"Calculations")) -> 9.0703186 | K10: 8.9672954 | L10: =IF(ISERROR(K10*Summary!$B$49),"",K10*Summary!$B$49) -> 215.21509 | M10: =IF(ISERROR(D10/L10),"",D10/L10) -> 1880.0932 | N10: =IF(ISERROR((C10+D10)/L10),"",(C10+D10)/L10) -> 4666.0755 | O10: =IF(ISERROR(N10*(1+$C$6)),"",N10*(1+$C$6)) -> 10858.903 | P10: =((2425.05+135)/15)+64.99 -> 235.66 | Q10: =IF(ISERROR(M10/P10),"",M10/P10) -> 7.9779904 | R10: =IF(ISERROR(N10/P10),"",N10/P10) -> 19.800032 | S10: =IF(ISERROR(O10/P10),"",O10/P10) -> 46.078685 | U10: =IF(T10>0,Summary!$B$47/T10,IF(S10<Summary!$B$47,'Cost Factor'!S10/Summary!$B$47,1)) -> 1
B11: Art & Music | C11: =INDIRECT(ADDRESS(MATCH(B11,Summary!A:A,0),7,1,1,"Summary")) -> 1225927.7 | D11: 1124676.9 | E11: =INDIRECT(ADDRESS(MATCH(B11,Data!B:B,0),7,1,1,"Data")) -> 8883 | F11: =IF(ISERROR(D11/E11),"",D11/E11) -> 126.61003 | G11: =IF(ISERROR((C11)/E11),"",(C11)/E11) -> 138.0083 | H11: =IF(ISERROR(G11*(1+$C$6)),"",G11*(1+$C$6)) -> 321.17326 | I11: =IF(ISERROR((G11/F11)-1),"",(G11/F11)-1) -> 0.090026538 | J11: =INDIRECT(ADDRESS(MATCH(B11,Calculations!B:B,0),11,1,1,"Calculations")) -> 11.215909 | K11: 12.75708 | L11: =IF(ISERROR(K11*Summary!$B$49),"",K11*Summary!$B$49) -> 306.16991 | M11: =IF(ISERROR(D11/L11),"",D11/L11) -> 3673.3751 | N11: =IF(ISERROR((C11+D11)/L11),"",(C11+D11)/L11) -> 7677.4514 | O11: =IF(ISERROR(N11*(1+$C$6)),"",N11*(1+$C$6)) -> 17866.985 | P11: =((2425.05+135)/15)+64.99 -> 235.66 | Q11: =IF(ISERROR(M11/P11),"",M11/P11) -> 15.587605 | R11: =IF(ISERROR(N11/P11),"",N11/P11) -> 32.578509 | S11: =IF(ISERROR(O11/P11),"",O11/P11) -> 75.816789 | U11: =IF(T11>0,Summary!$B$47/T11,IF(S11<Summary!$B$47,'Cost Factor'!S11/Summary!$B$47,1)) -> 1
B12: Biology | C12: =INDIRECT(ADDRESS(MATCH(B12,Summary!A:A,0),7,1,1,"Summary")) -> 1165519.6 | D12: 996802.07 | E12: =INDIRECT(ADDRESS(MATCH(B12,Data!B:B,0),7,1,1,"Data")) -> 12243 | F12: =IF(ISERROR(D12/E12),"",D12/E12) -> 81.418122 | G12: =IF(ISERROR((C12)/E12),"",(C12)/E12) -> 95.19886 | H12: =IF(ISERROR(G12*(1+$C$6)),"",G12*(1+$C$6)) -> 221.54703 | I12: =IF(ISERROR((G12/F12)-1),"",(G12/F12)-1) -> 0.16925885 | J12: =INDIRECT(ADDRESS(MATCH(B12,Calculations!B:B,0),11,1,1,"Calculations")) -> 16.599456 | K12: 15.933371 | L12: =IF(ISERROR(K12*Summary!$B$49),"",K12*Summary!$B$49) -> 382.40091 | M12: =IF(ISERROR(D12/L12),"",D12/L12) -> 2606.6938 | N12: =IF(ISERROR((C12+D12)/L12),"",(C12+D12)/L12) -> 5654.5936 | O12: =IF(ISERROR(N12*(1+$C$6)),"",N12*(1+$C$6)) -> 13159.385 | P12: =((2425.05+135)/15)+64.99 -> 235.66 | Q12: =IF(ISERROR(M12/P12),"",M12/P12) -> 11.061248 | R12: =IF(ISERROR(N12/P12),"",N12/P12) -> 23.994711 | S12: =IF(ISERROR(O12/P12),"",O12/P12) -> 55.840553 | U12: =IF(T12>0,Summary!$B$47/T12,IF(S12<Summary!$B$47,'Cost Factor'!S12/Summary!$B$47,1)) -> 1
B13: Chemistry & Biochemistry | C13: =INDIRECT(ADDRESS(MATCH(B13,Summary!A:A,0),7,1,1,"Summary")) -> 595096.85 | D13: 514254.34 | E13: =INDIRECT(ADDRESS(MATCH(B13,Data!B:B,0),7,1,1,"Data")) -> 5779 | F13: =IF(ISERROR(D13/E13),"",D13/E13) -> 88.986735 | G13: =IF(ISERROR((C13)/E13),"",(C13)/E13) -> 102.97575 | H13: =IF(ISERROR(G13*(1+$C$6)),"",G13*(1+$C$6)) -> 239.64542 | I13: =IF(ISERROR((G13/F13)-1),"",(G13/F13)-1) -> 0.15720336 | J13: =INDIRECT(ADDRESS(MATCH(B13,Calculations!B:B,0),11,1,1,"Calculations")) -> 7.3147824 | K13: 7.98464 | L13: =IF(ISERROR(K13*Summary!$B$49),"",K13*Summary!$B$49) -> 191.63136 | M13: =IF(ISERROR(D13/L13),"",D13/L13) -> 2683.5605 | N13: =IF(ISERROR((C13+D13)/L13),"",(C13+D13)/L13) -> 5788.9856 | O13: =IF(ISERROR(N13*(1+$C$6)),"",N13*(1+$C$6)) -> 13472.142 | P13: =((2425.05+135)/15)+64.99 -> 235.66 | Q13: =IF(ISERROR(M13/P13),"",M13/P13) -> 11.387424 | R13: =IF(ISERROR(N13/P13),"",N13/P13) -> 24.56499 | S13: =IF(ISERROR(O13/P13),"",O13/P13) -> 57.167708 | U13: =IF(T13>0,Summary!$B$47/T13,IF(S13<Summary!$B$47,'Cost Factor'!S13/Summary!$B$47,1)) -> 1
B14: Communication, Mass Media, & Theatre | C14: =INDIRECT(ADDRESS(MATCH(B14,Summary!A:A,0),7,1,1,"Summary")) -> 1256290.9 | D14: 981628.61 | E14: =INDIRECT(ADDRESS(MATCH(B14,Data!B:B,0),7,1,1,"Data")) -> 11360 | F14: =IF(ISERROR(D14/E14),"",D14/E14) -> 86.410969 | G14: =IF(ISERROR((C14)/E14),"",(C14)/E14) -> 110.58899 | H14: =IF(ISERROR(G14*(1+$C$6)),"",G14*(1+$C$6)) -> 257.36298 | I14: =IF(ISERROR((G14/F14)-1),"",(G14/F14)-1) -> 0.27980267 | J14: =INDIRECT(ADDRESS(MATCH(B14,Calculations!B:B,0),11,1,1,"Calculations")) -> 15.544775 | K14: 14.181245 | L14: =IF(ISERROR(K14*Summary!$B$49),"",K14*Summary!$B$49) -> 340.34988 | M14: =IF(ISERROR(D14/L14),"",D14/L14) -> 2884.175 | N14: =IF(ISERROR((C14+D14)/L14),"",(C14+D14)/L14) -> 6575.3499 | O14: =IF(ISERROR(N14*(1+$C$6)),"",N14*(1+$C$6)) -> 15302.171 | P14: =((2425.05+135)/15)+64.99 -> 235.66 | Q14: =IF(ISERROR(M14/P14),"",M14/P14) -> 12.238713 | R14: =IF(ISERROR(N14/P14),"",N14/P14) -> 27.90185 | S14: =IF(ISERROR(O14/P14),"",O14/P14) -> 64.933256 | U14: =IF(T14>0,Summary!$B$47/T14,IF(S14<Summary!$B$47,'Cost Factor'!S14/Summary!$B$47,1)) -> 1
