Workbook

Sheet Legend
A2: Legend
D3: Local
D5: State
D7: Federal
D9: Other
D11: Indeterminate
D13: Bridgeport
D15: New Haven
A17: Source | B17: Connecticut State Department of Education
A19: All files are "read only" and based on data collections from the Connecticut State Department of Education.
A20: The conclusions reached in this document are those of the author(s) and do not necessarily represent those
A21: of Ball State University.

Sheet 2006-07 without school constr
A1: 2006-07 Strategic School Profiles data without school construction
A3: TOWN CODE | B3: NAME | C3: TOTAL EXPENDITURES | D3: STATE PORTION | E3: FEDERAL PORTION | F3: TUITION PORTION | G3: LOCAL PORTION | H3: LOCAL % | I3: FEDERAL % | J3: STATE % | K3: TUITION %
A4: 1 | B4: ANDOVER | C4: 3687550 | D4: 1114944 | E4: 113133 | F4: 0 | G4: 2459473 | H4: 66.7 | I4: 3.1 | J4: 30.2 | K4: 0
A5: 2 | B5: ANSONIA | C5: 27155249 | D5: 15521279 | E5: 1605250 | F5: 126610 | G5: 9902110 | H5: 36.5 | I5: 5.9 | J5: 57.2 | K5: 0.5
A6: 3 | B6: ASHFORD | C6: 6585903 | D6: 2943116 | E6: 263829 | F6: 26932 | G6: 3352026 | H6: 50.9 | I6: 4 | J6: 44.7 | K6: 0.4
A7: 4 | B7: AVON | C7: 37769527 | D7: 1569268 | E7: 613406 | F7: 294354 | G7: 35292499 | H7: 93.4 | I7: 1.6 | J7: 4.2 | K7: 0.8
A8: 5 | B8: BARKHAMSTED | C8: 3429220 | D8: 681571 | E8: 131976 | F8: 0 | G8: 2615673 | H8: 76.3 | I8: 3.8 | J8: 19.9 | K8: 0
A9: 7 | B9: BERLIN | C9: 36611965 | D9: 5553362 | E9: 662941 | F9: 73584 | G9: 30322078 | H9: 82.8 | I9: 1.8 | J9: 15.2 | K9: 0.2
A10: 8 | B10: BETHANY | C10: 5811191 | D10: 868188 | E10: 194483 | F10: 0 | G10: 4748520 | H10: 81.7 | I10: 3.3 | J10: 14.9 | K10: 0
A11: 9 | B11: BETHEL | C11: 38407232 | D11: 8474289 | E11: 478644 | F11: 23116 | G11: 29431183 | H11: 76.6 | I11: 1.2 | J11: 22.1 | K11: 0.1
A12: 11 | B12: BLOOMFIELD | C12: 38808360 | D12: 6115981 | E12: 1113173 | F12: 217431 | G12: 31361775 | H12: 80.8 | I12: 2.9 | J12: 15.8 | K12: 0.6
A13: 12 | B13: BOLTON | C13: 11606027 | D13: 3150847 | E13: 152825 | F13: 58280 | G13: 8244075 | H13: 71 | I13: 1.3 | J13: 27.1 | K13: 0.5
A14: 13 | B14: BOZRAH | C14: 4505180 | D14: 1189268 | E14: 138528 | F14: 3800 | G14: 3173584 | H14: 70.4 | I14: 3.1 | J14: 26.4 | K14: 0.1
A15: 14 | B15: BRANFORD | C15: 44324105 | D15: 2353294 | E15: 1096491 | F15: 25334 | G15: 40848986 | H15: 92.2 | I15: 2.5 | J15: 5.3 | K15: 0.1
... A185: 284 | B185: CROSS CULTURAL ACADE | C185: 568917 | D185: 403500 | E185: 118625 | F185: 46792 | G185: 0 | H185: 0 | I185: 20.9 | J185: 70.9 | K185: 8.2

Sheet 2006-07 St Dist w school constr
A1: 2006-07 Strategic School Profiles data with school construction
A3: TOWN CODE | B3: NAME | D3: TOTAL EXPENDITURES | E3: STATE PORTION | F3: FEDERAL PORTION | G3: TUITION PORTION | H3: LOCAL PORTION | I3: LOCAL % | J3: FEDERAL % | K3: STATE % | L3: TUITION %
A4: 1 | B4: ANDOVER | C4: 328 | D4: 5033625 | E4: 1325669 | F4: 113133 | G4: 0 | H4: 3594823 | I4: 71.4 | J4: 2.2 | K4: 26.3 | L4: 0
A5: 2 | B5: ANSONIA | C5: 2640 | D5: 30923338 | E5: 18311249 | F5: 1605250 | G5: 126610 | H5: 10880229 | I5: 35.2 | J5: 5.2 | K5: 59.2 | L5: 0.4
A6: 3 | B6: ASHFORD | C6: 486 | D6: 6710979 | E6: 3068193 | F6: 263829 | G6: 26932 | H6: 3352025 | I6: 49.9 | J6: 3.9 | K6: 45.7 | L6: 0.4
A7: 4 | B7: AVON | C7: 3458 | D7: 42554998 | E7: 2039867 | F7: 613406 | G7: 294354 | H7: 39607371 | I7: 93.1 | J7: 1.4 | K7: 4.8 | L7: 0.7
A8: 5 | B8: BARKHAMSTED | C8: 336 | D8: 3677020 | E8: 809224 | F8: 131976 | G8: 0 | H8: 2735820 | I8: 74.4 | J8: 3.6 | K8: 22 | L8: 0
A9: 7 | B9: BERLIN | C9: 3217 | D9: 37806653 | E9: 6147336 | F9: 662941 | G9: 73584 | H9: 30922792 | I9: 81.8 | J9: 1.8 | K9: 16.3 | L9: 0.2
A10: 8 | B10: BETHANY | C10: 537 | D10: 6346071 | E10: 1064447 | F10: 194483 | G10: 0 | H10: 5087141 | I10: 80.2 | J10: 3.1 | K10: 16.8 | L10: 0
A11: 9 | B11: BETHEL | C11: 3170 | D11: 40711740 | E11: 8955572 | F11: 478644 | G11: 23116 | H11: 31254408 | I11: 76.8 | J11: 1.2 | K11: 22 | L11: 0.1
A12: 11 | B12: BLOOMFIELD | C12: 2214 | D12: 42926057 | E12: 9320012 | F12: 1113173 | G12: 217431 | H12: 32275441 | I12: 75.2 | J12: 2.6 | K12: 21.7 | L12: 0.5
A13: 12 | B13: BOLTON | C13: 907 | D13: 12258286 | E13: 3519188 | F13: 152825 | G13: 58280 | H13: 8527993 | I13: 69.6 | J13: 1.2 | K13: 28.7 | L13: 0.5
A14: 13 | B14: BOZRAH | C14: 260 | D14: 4863685 | E14: 1386562 | F14: 138528 | G14: 3800 | H14: 3334795 | I14: 68.6 | J14: 2.8 | K14: 28.5 | L14: 0.1
A15: 14 | B15: BRANFORD | C15: 3517 | D15: 47372447 | E15: 3427346 | F15: 1096491 | G15: 25334 | H15: 42823276 | I15: 90.4 | J15: 2.3 | K15: 7.2 | L15: 0.1
... A169: 219 | B169: DISTRICT NO. 19 | C169: 1201 | D169: 19309584 | E169: 7558980 | F169: 260076 | G169: 619763 | H169: 10870765 | I169: 56.3 | J169: 1.3 | K169: 39.1 | L169: 3.2
B170: Subtotal | C170: =SUM(C4:C169) -> 536364 | D170: =SUM(D4:D169) -> 7980736808 | E170: =SUM(E4:E169) -> 2660597884 | F170: =SUM(F4:F169) -> 288401750 | G170: =SUM(G4:G169) -> 73855592 | H170: =SUM(H4:H169) -> 4957881582
D171: Less Adult | E171: ='2007 ST Fed Grants'!C165 -> 18167318 | F171: ='2007 ST Fed Grants'!C244 -> 2176308
D172: Less Adult Care Revenue | F172: 34548
D173: Less Preschool Care Revenue | F173: 1003815
D174: Less PreK | E174: ='2007 ST Fed Grants'!C343 -> 51928850 | F174: ='2007 ST Fed Grants'!C354 -> 615648
B175: Total | D175: =SUM(E175:H175) -> 7906810321 | E175: =E170-(E171+E174) -> 2590501716 | F175: =F170-(F171+F172+F173+F174) -> 284571431 | G175: =G170-(G171+G174) -> 73855592 | H175: =H170-(H171+H174) -> 4957881582
C176: enrollment less pk | D176: =C170 -> 536364 | E176: =E175/D176 -> 4829.7457 | F176: =F175/D176 -> 530.55655 | G176: =G175/D176 -> 137.69677 | H176: =H175/D176 -> 9243.5018
E177: =E175/D175 -> 0.32762917 | F177: =F175/D175 -> 0.035990674 | G177: =G175/D175 -> 0.0093407568 | H177: =H175/D175 -> 0.6270394
E178: State | F178: Federal | G178: Tuition | H178: Local
A180: Bridgeport
A181: 15 | B181: BRIDGEPORT | C181: 20682 | D181: 299448214 | E181: 218716259 | F181: 25310070 | G181: 1430348 | H181: 53991537 | I181: 18 | J181: 8.5 | K181: 73 | L181: 0.5
D182: Less Adult | E182: ='2007 ST Fed Grants'!C166 -> 1167363 | F182: ='2007 ST Fed Grants'!C245 -> 170000
D183: Less Adult Care Revenue
D184: Less Preschool Care Revenue
D185: Less PreK | E185: ='2007 ST Fed Grants'!C344 -> 7932087 | F185: ='2007 ST Fed Grants'!C355 -> 0
B186: Total | D186: =SUM(E186:H186) -> 290178764 | E186: =E181-(E182+E185) -> 209616809 | F186: =F181-(F182+F183+F184+F185) -> 25140070 | G186: =G181-(G182+G185) -> 1430348 | H186: =H181-(H182+H185) -> 53991537
C187: enrollment less pk | D187: =C181 -> 20682 | E187: =E186/D187 -> 10135.229 | F187: =F186/D187 -> 1215.5531 | G187: =G186/D187 -> 69.159076 | H187: =H186/D187 -> 2610.5569
E188: =E186/D186 -> 0.72237129 | F188: =F186/D186 -> 0.086636491 | G188: =G186/D186 -> 0.004929196 | H188: =H186/D186 -> 0.18606302
A189: New Haven
A190: 93 | B190: NEW HAVEN | C190: 18638 | D190: 422788415 | E190: 296750600 | F190: 35696779 | G190: 6091424 | H190: 84249612 | I190: 19.9 | J190: 8.4 | K190: 70.2 | L190: 1.4
D191: Less Adult | E191: ='2007 ST Fed Grants'!C167 -> 2380784 | F191: ='2007 ST Fed Grants'!C246 -> 120000
D192: Less Adult Care Revenue | F192: 0
D193: Less Preschool Care Revenue | F193: 297992
D194: Less PreK | E194: ='2007 ST Fed Grants'!C345 -> 6991926 | F194: ='2007 ST Fed Grants'!C356 -> 0
B195: Total | D195: =SUM(E195:H195) -> 412997713 | E195: =E190-(E191+E194) -> 287377890 | F195: =F190-(F191+F192+F193+F194) -> 35278787 | G195: =G190-(G191+G194) -> 6091424 | H195: =H190-(H191+H194) -> 84249612
...

Sheet FY07 Figures 1,2,4
A1: Figure 1 | K1: Figure 2
A2: Connecticut (2006-07) | B2: Statewide | D2: Statewide Weighted for Charter Enrollment | F2: Bridgeport | H2: New Haven | L2: District | M2: Charter | N2: Difference
A3: Per-Pupil Revenue | K3: State | L3: =B4 -> 14741.501 | M3: =B5 -> 12631.105 | N3: =B6 -> 2110.3955
A4: District | B4: =B14 -> 14741.501 | D4: 16476 | F4: =F14 -> 14030.498 | H4: =H14 -> 22158.907 | K4: Statewide Weighted | L4: =D4 -> 16476 | M4: =D5 -> 12631 | N4: =D6 -> 3845
A5: Charter | B5: =C14 -> 12631.105 | D5: 12631 | F5: =G14 -> 9920.2951 | H5: =I14 -> 12080.46 | K5: =F2 -> Bridgeport | L5: =F4 -> 14030.498 | M5: =F5 -> 9920.2951 | N5: =F6 -> 4110.2031
A6: Difference | B6: =B4-B5 -> 2110.3955 | D6: 3845 | F6: =F4-F5 -> 4110.2031 | H6: =H4-H5 -> 10078.447 | K6: =H2 -> New Haven | L6: =H4 -> 22158.907 | M6: =H5 -> 12080.46 | N6: =H6 -> 10078.447
B7: =B6/B4 -> 0.14316015 | D7: 0.233 | F7: =F6/F4 -> 0.29294777 | H7: =H6/H4 -> 0.454826
A8: Per-Pupil Revenue by Source | B8: District | C8: Charter | D8: District | E8: Charter | F8: District | G8: Charter | H8: District | I8: Charter | K8: Figure 2: Per Pupil Revenue for Connecticut District vs. Charter Schools, FY 2006-07
A9: Federal | B9: ='[1]2006-07 St Dist w school constr'!F176 -> 530.55655 | C9: ='[1]FY07 St Charter w Const'!F22 -> 927.67726 | D9: 930 | E9: =C9 -> 927.67726 | F9: ='[1]2006-07 St Dist w school constr'!F187 -> 1215.5531 | G9: ='[1]FY07 St Charter w Const'!F31 -> 751.37471 | H9: ='[1]2006-07 St Dist w school constr'!F196 -> 1892.8419 | I9: ='[1]FY07 St Charter w Const'!F41 -> 1122.7349
A10: State | B10: ='[1]2006-07 St Dist w school constr'!E176 -> 4829.7457 | C10: ='[1]FY07 St Charter w Const'!E22 -> 9592.2236 | D10: 7933 | E10: =C10 -> 9592.2236 | F10: ='[1]2006-07 St Dist w school constr'!E187 -> 10135.229 | G10: ='[1]FY07 St Charter w Const'!E31 -> 8187.8595 | H10: ='[1]2006-07 St Dist w school constr'!E196 -> 15418.923 | I10: ='[1]FY07 St Charter w Const'!E41 -> 8874.9606
A11: Local | B11: ='[1]2006-07 St Dist w school constr'!H176 -> 9243.5018 | C11: ='[1]FY07 St Charter w Const'!H22 -> 114.19359 | D11: 7437 | E11: =C11 -> 114.19359 | F11: ='[1]2006-07 St Dist w school constr'!H187 -> 2610.5569 | G11: ='[1]FY07 St Charter w Const'!H31 -> 49.248244 | H11: ='[1]2006-07 St Dist w school constr'!H196 -> 4520.314 | I11: ='[1]FY07 St Charter w Const'!H41 -> 0
A12: Other
A13: Indeterminate | B13: ='[1]2006-07 St Dist w school constr'!G176 -> 137.69677 | C13: ='[1]FY07 St Charter w Const'!G22 -> 1997.0108 | D13: 177 | E13: =C13 -> 1997.0108 | F13: ='[1]2006-07 St Dist w school constr'!G187 -> 69.159076 | G13: ='[1]FY07 St Charter w Const'!G31 -> 931.81265 | H13: ='[1]2006-07 St Dist w school constr'!G196 -> 326.8282 | I13: ='[1]FY07 St Charter w Const'!G41 -> 2082.7645
A14: Total | B14: =SUM(B9:B13) -> 14741.501 | C14: =SUM(C9:C13) -> 12631.105 | D14: =D4 -> 16476 | E14: =C14 -> 12631.105 | F14: =SUM(F9:F13) -> 14030.498 | G14: =SUM(G9:G13) -> 9920.2951 | H14: =SUM(H9:H13) -> 22158.907 | I14: =SUM(I9:I13) -> 12080.46
A15: Enrollment
A16: District | B16: ='[1]2006-07 St Dist w school constr'!C170 -> 536364 | D16: n/a | F16: ='[1]2006-07 St Dist w school constr'!C181 -> 20682 | H16: ='[1]2006-07 St Dist w school constr'!C190 -> 18638
B17: =B16/(B16+B18) -> 0.99364572 | D17: n/a | F17: =F16/(F16+F18) -> 0.97977166 | H17: =H16/(H16+H18) -> 0.95330162
A18: Charter | B18: ='[1]FY07 St Charter w Const'!C18 -> 3430 | D18: n/a | F18: ='[1]FY07 St Charter w Const'!C27 -> 427 | H18: ='[1]FY07 St Charter w Const'!C37 -> 913
B19: =B18/(B16+B18) -> 0.0063542759 | D19: n/a | F19: =F18/(F16+F18) -> 0.020228339 | H19: =H18/(H16+H18) -> 0.046698379
A20: Number of Charters | B20: 16 | D20: n/a | F20: 2 | H20: 3
A21: Total Revenue
A22: District | B22: ='[1]2006-07 St Dist w school constr'!D175 -> 7906810321 | D22: n/a | F22: ='[1]2006-07 St Dist w school constr'!D186 -> 290178764 | H22: ='[1]2006-07 St Dist w school constr'!D195 -> 412997713
B23: =B22/B26 -> 0.99455045 | D23: n/a | F23: =F22/F26 -> 0.98561225 | H23: =H22/H26 -> 0.97398879
A24: Charter | B24: ='[1]FY07 St Charter w Const'!I21 -> 43324691 | D24: n/a | F24: ='[1]FY07 St Charter w Const'!I30 -> 4235966 | H24: ='[1]FY07 St Charter w Const'!I40 -> 11029460
B25: =B24/B26 -> 0.0054495541 | D25: n/a | F25: =F24/F26 -> 0.014387752 | H25: =H24/H26 -> 0.02601121
A26: Total | B26: =B22+B24 -> 7950135012 | D26: n/a | F26: =F22+F24 -> 294414730 | H26: =H22+H24 -> 424027173
A27: Percentage of Revenue by Source | B27: District | C27: Charter | D27: District | E27: Charter | F27: District | G27: Charter | H27: District | I27: Charter | K27: Figure 4
A28: Federal | B28: =B9/B14 -> 0.035990674 | C28: =C9/C14 -> 0.073443871 | D28: =D9/D$14 -> 0.056445739 | E28: =C28 -> 0.073443871 | F28: =F9/F14 -> 0.086636491 | G28: =G9/G14 -> 0.075741165 | H28: =H9/H14 -> 0.085421265 | I28: =I9/I14 -> 0.092938095 | L28: Federal | M28: State | N28: Local | O28: Other | P28: Indeterminate
A29: State | B29: =B10/B14 -> 0.32762917 | C29: =C10/C14 -> 0.75941285 | D29: =D10/D$14 -> 0.48148823 | E29: =C29 -> 0.75941285 | F29: =F10/F14 -> 0.72237129 | G29: =G10/G14 -> 0.82536451 | H29: =H10/H14 -> 0.6958341 | I29: =I10/I14 -> 0.73465419 | K29: Statewide District | L29: =B9 -> 530.55655 | M29: =B10 -> 4829.7457 | N29: =B11 -> 9243.5018 | O29: =B12 -> 0 | P29: =B13 -> 137.69677
A30: Local | B30: =B11/B14 -> 0.6270394 | C30: =C11/C14 -> 0.0090406646 | D30: =D11/D$14 -> 0.45138383 | E30: =C30 -> 0.0090406646 | F30: =F11/F14 -> 0.18606302 | G30: =G11/G14 -> 0.004964393 | H30: =H11/H14 -> 0.20399535 | I30: =I11/I14 -> 0 | K30: Statewide Charter | L30: =C9 -> 927.67726 | M30: =C10 -> 9592.2236 | N30: =C11 -> 114.19359 | O30: =C12 -> 0 | P30: =C13 -> 1997.0108
A31: Other | K31: Statewide Weighted | L31: =D9 -> 930 | M31: =D10 -> 7933 | N31: =D11 -> 7437 | O31: =D12 -> 0 | P31: =D13 -> 177
A32: Indeterminate | B32: =B13/B14 -> 0.0093407568 | C32: =C13/C14 -> 0.15810262 | D32: =D13/D$14 -> 0.010742899 | E32: =C32 -> 0.15810262 | F32: =F13/F14 -> 0.004929196 | G32: =G13/G14 -> 0.093929932 | H32: =H13/H14 -> 0.014749292 | I32: =I13/I14 -> 0.17240772 | K32: Bridgeport District | L32: =F9 -> 1215.5531 | M32: =F10 -> 10135.229 | N32: =F11 -> 2610.5569 | O32: =F12 -> 0 | P32: =F13 -> 69.159076
A33: Change in district school funding if subjected to charter funding structure | K33: Bridgeport Charter | L33: =G9 -> 751.37471 | M33: =G10 -> 8187.8595 | N33: =G11 -> 49.248244 | O33: =G12 -> 0 | P33: =G13 -> 931.81265
B34: ($1.1 billion) | F34: ($85 million) | H34: ($187.8 million) | K34: New Haven District | L34: =H9 -> 1892.8419 | M34: =H10 -> 15418.923 | N34: =H11 -> 4520.314 | O34: =H12 -> 0 | P34: =H13 -> 326.8282
B35: =B6*B16 -> 1.1319402e+09 | F35: =F6*F16 -> 85007221 | H35: =H6*H16 -> 1.878421e+08 | K35: New Haven Charter | L35: =I9 -> 1122.7349 | M35: =I10 -> 8874.9606 | N35: =I11 -> 0 | O35: =I12 -> 0 | P35: =I13 -> 2082.7645
A36: Notes: Tuition contains a variety of revneue sources and includes non-resident student
A37: fees from CT districts as well as individuals. Also includes the costs of transportation
A38: for said students, Medicaid reimbursements, 3rd party insurance and private contributions
A39: the state cannot provide more detailed data, therefore, Tuition is an indeterminate
A40: revenue stream.
...

Sheet Figure 3
A1: State Charter School Policies
A2: Figure 3
A3: State Policies | B3: Yes | C3: No | D3: Partial
A4: Charter schools received their funding directly from the state | D4: 3
A5: Charter schools are eligible for local funding | D5: 2
A6: Cap on funding a charter school can receive | C6: X
A7: District public school receive differential funding (e.g. more funding for 9-12 vs. K-8 schools) | B7: X
A8: Charter schools receive differential funding | B8: 5
A9: State allows districts to withhold funding from charter schools for providing adminstrative services | C9: X
A10: State "holds harmless" ditrict funding for charter enrollment | C10: X
A11: School is considered LEA if authorized by non-district organization | B11: X
A12: School is considered LEA if authorized by district | C12: X
A13: Cap on number of charter schools | B13: 1
A14: Cap on number of charters schools authorized per year | C14: X
A15: Cap on number of students attending charter schools | B15: 4
A16: Charter schools have an open enrollment policy | B16: X
A18: 1. Connecticut law contains the following caps: 250 students per state board of education-authorized charter or 25 percent of the enrollment of the district in which the charter is located, whichever is less; 300 students per state board of education-authorized K-8 charter or 25 percent of the enrollment of the district in which the charter is located, whichever is less; and, for charters with a demonstrated record of achievement, 85 students per grade may be added.
A19: 2. Charter schools authorized by the state receive their funding directly from the state, and all charter schools in Connecticut are state authorized.
A20: 3. Charter schools authorized by the state receive their funding directly from the state, and all charter schools in Connecticut are state authorized.
A21: 4. State sponsored charter schools are limited to 250 students, 300 if a K-8 school. However, schools that have a demonstrated record of achievement can petition to enroll up to 85 students per grade.
A22: 5. State sponsored charter schools receive a flat rate per pupil to provide education services with additional funding available for special education pupils.

Sheet Figure 5
C2: Statewide District | D2: Statewide Charter
A3: Percentage of stuents eligible for free or reduced price lunch | C3: 0.271 | D3: 0.594
A4: Percentage of schools eligible for Title 1 | C4: 0.407 | D4: 0.875
A5: Percent of students by school type
B6: Primary (K-5) | C6: 0.479 | D6: 0.516
B7: Middle (6-8) | C7: 0.207 | D7: 0.316
B8: High (9-12) | C8: 0.307 | D8: 0.168
B9: Other (K-12,K-8, etc.) | C9: 0.008 | D9: 0

Sheet Figure 6
A1: Figure 6: State Scorecard
B2: Findings | C2: Connecticut | E2: Use the following options only
A3: Federal Funding | B3: Charters have access to federal funds according to state statutes (Yes = black, No = white)* | C3: Y | E3: Y
B4: Percentage of federal revenue equals percentage of total enrollment for charter schools (<, >, or =) | C4: > | E4: P
A5: State Funding | B5: Charters have access to state funds according to state statutes (Yes = black, No = white) | C5: Y | E5: N
B6: Percentage of state revenue equals percentage of total enrollment for charter schools (<, >, or =) | C6: >
A7: Local Funding | B7: Charters have access to local funds according to state statutes (Yes = black, No = white) | C7: P2
B8: Percentage of local revenue equals percentage of total enrollment for charter schools (<, >, or =) | C8: <
A9: Facilities Funding | B9: Charters have access to facilities funds according to state statutes (Yes = black, No = white) | C9: Y1
B10: Percentage of facilities revenue equals percentage of total enrollment for charter schools (<, >, or =) | C10: N/A
A11: Data Availability | B11: State provides detailed, public data on federal, state, local and other revenues for district schools (Yes = black, Partial = grey, No = white) | C11: Y
B12: State provides detailed, public data on federal, state, local and other revenues for charter schools (Yes = black, Partial = grey, No = white) | C12: Y
A13: Funding Formula | B13: Charters are treated as LEAs for funding purposes (Yes = black, Partial = grey, No = white) | C13: Y
B14: State funds student (black) or the LEA (grey) | C14: S | E14: S | F14: L | H14: Use these options for the query to the left only (B18)
B15: State funding formula is fair and equitable (Yes = black, No = white | C15: N
A17: * For this finding, No could indicate that the statue is silent or that it denies access.
A19: 1 For the fiscal years ending June 30, 2006, and June 30, 2007, the Commissioner of Education shall establish, within available bond authorizations, a grant program to assist state charter schools in financing (1) school building projects, as defined in section 10-282, (2) general improvements to school buildings, as defined in subsection (a) of section 10-265h, and (3) repayment of debt incurred prior to July 1, 2005, for school building projects. The governing authorities of such state charter schools may apply for such grants to the Department of Education at such time and in such manner as the commissioner prescribes. The commissioner shall give preference to applications that provide for matching funds from nonstate sources.
A20: 2 Charter schools authorized by a school district are eligible for local funds, but charter schools authorized by the state are not. Currently, there are no charter schools in Connecticut authorized by school districts.

Sheet FY07 St Charter w Const
D1: Total | E1: State | F1: Federal | G1: Tuition | H1: Local
A2: 261 | B2: JUMOKE ACADEMY | C2: 325 | D2: 3144658 | E2: 2586513 | F2: 421008 | G2: 137137 | H2: 0 | I2: 0 | J2: 13.4 | K2: 82.3 | L2: 4.4
A3: 263 | B3: ODYSSEY SCHOOL | C3: 174 | D3: 1518146 | E3: 1458903 | F3: 8318 | G3: 50925 | H3: 0 | I3: 0 | J3: 0.5 | K3: 96.1 | L3: 3.4
A4: 264 | B4: INTEGRATED DAY | C4: 286 | D4: 4717938 | E4: 3927235 | F4: 347229 | G4: 286625 | H4: 156849 | I4: 3.3 | J4: 7.4 | K4: 83.2 | L4: 6.1
A5: 265 | B5: INTERDIST SCH ART | C5: 181 | D5: 2770130 | E5: 2424709 | F5: 30889 | G5: 314532 | H5: 0 | I5: 0 | J5: 1.1 | K5: 87.5 | L5: 11.4
A6: 268 | B6: COMMON GROUND | C6: 145 | D6: 1639114 | E6: 1368771 | F6: 199017 | G6: 71326 | H6: 0 | I6: 0 | J6: 12.1 | K6: 83.5 | L6: 4.4
A7: 269 | B7: BRIDGE ACADEMY | C7: 251 | D7: 2722601 | E7: 2179390 | F7: 137046 | G7: 385136 | H7: 21029 | I7: 0.8 | J7: 5 | K7: 80 | L7: 14.1
A8: 270 | B8: SIDE BY SIDE | C8: 200 | D8: 2301792 | E8: 2133591 | F8: 40014 | G8: 128187 | H8: 0 | I8: 0 | J8: 1.7 | K8: 92.7 | L8: 5.6
A9: 272 | B9: EXPLORATIONS | C9: 83 | D9: 968965 | E9: 863374 | F9: 34922 | G9: 70669 | H9: 0 | I9: 0 | J9: 3.6 | K9: 89.1 | L9: 7.3
A10: 277 | B10: HIGHVILLE MUSTARD | C10: 217 | D10: 3107075 | E10: 2421139 | F10: 197545 | G10: 313817 | H10: 174574 | I10: 5.6 | J10: 6.4 | K10: 77.9 | L10: 10.1
A11: 278 | B11: TRAILBLAZERS | C11: 150 | D11: 2735867 | E11: 1215701 | F11: 108019 | G11: 1372915 | H11: 39232 | I11: 1.4 | J11: 3.9 | K11: 44.4 | L11: 50.2
A12: 279 | B12: AMISTAD | C12: 400 | D12: 5893887 | E12: 3757930 | F12: 439052 | G12: 1696905 | H12: 0 | I12: 0 | J12: 7.4 | K12: 63.8 | L12: 28.8
A13: 280 | B13: NEW BEGINNINGS | C13: 302 | D13: 3845573 | E13: 2877457 | F13: 338601 | G13: 629515 | H13: 0 | I13: 0 | J13: 8.8 | K13: 74.8 | L13: 16.4
... A17: 284 | B17: CROSS CULTURAL ACADE | C17: 50 | D17: 568917 | E17: 403500 | F17: 118625 | G17: 46792 | H17: 0 | I17: 0 | J17: 20.9 | K17: 70.9 | L17: 8.2
C18: =SUM(C2:C17) -> 3430 | E18: =SUM(E2:E17) -> 32901327 | F18: =SUM(F2:F17) -> 3181933 | G18: =SUM(G2:G17) -> 6849747 | H18: =SUM(H2:H17) -> 391684
B19: Less Adult Ed | E19: 0 | F19: 0 | G19: 0 | H19: 0
B20: Less Preschool/PreK | E20: 0 | F20: 0 | G20: 0 | H20: 0
E21: =E18-(E19+E20) -> 32901327 | F21: =F18-(F19+F20) -> 3181933 | G21: =G18-(G19+G20) -> 6849747 | H21: =H18-(H19+H20) -> 391684 | I21: =SUM(E21:H21) -> 43324691
E22: =E21/C18 -> 9592.2236 | F22: =F21/C18 -> 927.67726 | G22: =G21/C18 -> 1997.0108 | H22: =H21/C18 -> 114.19359
E23: =E21/I21 -> 0.75941285 | F23: =F21/I21 -> 0.073443871 | G23: =G21/I21 -> 0.15810262 | H23: =H21/I21 -> 0.0090406646
A24: Bridgeport Charters
A25: 269 | B25: BRIDGE ACADEMY | C25: 251 | D25: 2722601 | E25: 2179390 | F25: 137046 | G25: 385136 | H25: 21029 | I25: 0.8 | J25: 5 | K25: 80 | L25: 14.1
A26: 283 | B26: PARK CITY PREP | C26: 176 | D26: 1513365 | E26: 1316826 | F26: 183791 | G26: 12748 | H26: 0 | I26: 0 | J26: 12.1 | K26: 87 | L26: 0.8
C27: =SUM(C25:C26) -> 427 | E27: =SUM(E25:E26) -> 3496216 | F27: =SUM(F25:F26) -> 320837 | G27: =SUM(G25:G26) -> 397884 | H27: =SUM(H25:H26) -> 21029
B28: Less Adult Ed | E28: 0 | F28: 0 | G28: 0 | H28: 0
B29: Less Preschool/PreK | E29: 0 | F29: 0 | G29: 0 | H29: 0
E30: =E27-(E28+E29) -> 3496216 | F30: =F27-(F28+F29) -> 320837 | G30: =G27-(G28+G29) -> 397884 | H30: =H27-(H28+H29) -> 21029 | I30: =SUM(E30:H30) -> 4235966
E31: =E30/C27 -> 8187.8595 | F31: =F30/C27 -> 751.37471 | G31: =G30/C27 -> 931.81265 | H31: =H30/C27 -> 49.248244
E32: =E30/I30 -> 0.82536451 | F32: =F30/I30 -> 0.075741165 | G32: =G30/I30 -> 0.093929932 | H32: =H30/I30 -> 0.004964393
A33: New Haven Charters
A34: 268 | B34: COMMON GROUND | C34: 145 | D34: 1639114 | E34: 1368771 | F34: 199017 | G34: 71326 | H34: 0 | I34: 0 | J34: 12.1 | K34: 83.5 | L34: 4.4
A35: 279 | B35: AMISTAD | C35: 400 | D35: 5893887 | E35: 3757930 | F35: 439052 | G35: 1696905 | H35: 0 | I35: 0 | J35: 7.4 | K35: 63.8 | L35: 28.8
A36: 281 | B36: ELM CITY COLLEGE PRE | C36: 368 | D36: 3496459 | E36: 2976138 | F36: 386988 | G36: 133333 | H36: 0 | I36: 0 | J36: 11.1 | K36: 85.1 | L36: 3.8
C37: =SUM(C34:C36) -> 913 | E37: =SUM(E34:E36) -> 8102839 | F37: =SUM(F34:F36) -> 1025057 | G37: =SUM(G34:G36) -> 1901564 | H37: =SUM(H34:H36) -> 0
B38: Less Adult Ed | E38: 0 | F38: 0 | G38: 0 | H38: 0
B39: Less Preschool/PreK | E39: 0 | F39: 0 | G39: 0 | H39: 0
E40: =E37-(E38+E39) -> 8102839 | F40: =F37-(F38+F39) -> 1025057 | G40: =G37-(G38+G39) -> 1901564 | H40: =H37-(H38+H39) -> 0 | I40: =SUM(E40:H40) -> 11029460
E41: =E40/C37 -> 8874.9606 | F41: =F40/C37 -> 1122.7349 | G41: =G40/C37 -> 2082.7645 | H41: =H40/C37 -> 0
E42: =E40/I40 -> 0.73465419 | F42: =F40/I40 -> 0.092938095 | G42: =G40/I40 -> 0.17240772 | H42: =H40/I40 -> 0
A44: Do not have Cross Cultural Acad on state list. State list includes Achievement First Bridgeport Acad, where there is no data.
...

Sheet 2007 ST Fed Grants
A1: Vendor | B1: VName | C1: Payment | D1: CCode | E1: GrantName | F1: CCode_A
A2: 7 | B2: BERLIN | C2: 12347 | D2: 11000-17030-84002-2007-170013- | E2: ADULT EDUCATION - PROVIDER | F2: 11000-17030-84002-2007 | G2: Adult Education
A3: 11 | B3: BLOOMFIELD | C3: 21800 | D3: 11000-17030-84002-2007-170013- | E3: ADULT EDUCATION - PROVIDER | F3: 11000-17030-84002-2007 | G3: Adult Education
A4: 14 | B4: BRANFORD | C4: 23774 | D4: 11000-17030-84002-2007-170013- | E4: ADULT EDUCATION - PROVIDER | F4: 11000-17030-84002-2007 | G4: Adult Education
A5: 15 | B5: BRIDGEPORT | C5: 1113537 | D5: 11000-17030-84002-2007-170013- | E5: ADULT EDUCATION - PROVIDER | F5: 11000-17030-84002-2007 | G5: Adult Education
A6: 17 | B6: BRISTOL | C6: 293978 | D6: 11000-17030-84002-2007-170013- | E6: ADULT EDUCATION - PROVIDER | F6: 11000-17030-84002-2007 | G6: Adult Education
A7: 241 | B7: C R E C | D7: 11000-17030-84002-2007-170013- | E7: ADULT EDUCATION - PROVIDER | F7: 11000-17030-84002-2007 | G7: Adult Education
A8: 25 | B8: CHESHIRE | C8: 22009 | D8: 11000-17030-84002-2007-170013- | E8: ADULT EDUCATION - PROVIDER | F8: 11000-17030-84002-2007 | G8: Adult Education
A9: 34 | B9: DANBURY | C9: 182193 | D9: 11000-17030-84002-2007-170013- | E9: ADULT EDUCATION - PROVIDER | F9: 11000-17030-84002-2007 | G9: Adult Education
A10: 253 | B10: E A S T C O N N | D10: 11000-17030-84002-2007-170013- | E10: ADULT EDUCATION - PROVIDER | F10: 11000-17030-84002-2007 | G10: Adult Education
A11: 43 | B11: EAST HARTFORD | C11: 96940 | D11: 11000-17030-84002-2007-170013- | E11: ADULT EDUCATION - PROVIDER | F11: 11000-17030-84002-2007 | G11: Adult Education
A12: 44 | B12: EAST HAVEN | C12: 370857 | D12: 11000-17030-84002-2007-170013- | E12: ADULT EDUCATION - PROVIDER | F12: 11000-17030-84002-2007 | G12: Adult Education
A13: 242 | B13: EDUCATION CONNECTION | D13: 11000-17030-84002-2007-170013- | E13: ADULT EDUCATION - PROVIDER | F13: 11000-17030-84002-2007 | G13: Adult Education
A14: 49 | B14: ENFIELD | C14: 74332 | D14: 11000-17030-84002-2007-170013- | E14: ADULT EDUCATION - PROVIDER | F14: 11000-17030-84002-2007 | G14: Adult Education
A15: 51 | B15: FAIRFIELD | C15: 9286 | D15: 11000-17030-84002-2007-170013- | E15: ADULT EDUCATION - PROVIDER | F15: 11000-17030-84002-2007 | G15: Adult Education
A16: 52 | B16: FARMINGTON | C16: 3501 | D16: 11000-17030-84002-2007-170013- | E16: ADULT EDUCATION - PROVIDER | F16: 11000-17030-84002-2007 | G16: Adult Education
A17: 59 | B17: GROTON | C17: 26467 | D17: 11000-17030-84002-2007-170013- | E17: ADULT EDUCATION - PROVIDER | F17: 11000-17030-84002-2007 | G17: Adult Education
A18: 62 | B18: HAMDEN | C18: 180820 | D18: 11000-17030-84002-2007-170013- | E18: ADULT EDUCATION - PROVIDER | F18: 11000-17030-84002-2007 | G18: Adult Education
A19: 64 | B19: HARTFORD | C19: 3400389 | D19: 11000-17030-84002-2007-170013- | E19: ADULT EDUCATION - PROVIDER | F19: 11000-17030-84002-2007 | G19: Adult Education
A20: 80 | B20: MERIDEN | C20: 993379 | D20: 11000-17030-84002-2007-170013- | E20: ADULT EDUCATION - PROVIDER | F20: 11000-17030-84002-2007 | G20: Adult Education
A21: 83 | B21: MIDDLETOWN | C21: 1310292 | D21: 11000-17030-84002-2007-170013- | E21: ADULT EDUCATION - PROVIDER | F21: 11000-17030-84002-2007 | G21: Adult Education
A22: 84 | B22: MILFORD | C22: 29100 | D22: 11000-17030-84002-2007-170013- | E22: ADULT EDUCATION - PROVIDER | F22: 11000-17030-84002-2007 | G22: Adult Education
A23: 88 | B23: NAUGATUCK | C23: 200188 | D23: 11000-17030-84002-2007-170013- | E23: ADULT EDUCATION - PROVIDER | F23: 11000-17030-84002-2007 | G23: Adult Education
A24: 89 | B24: NEW BRITAIN | C24: 608819 | D24: 11000-17030-84002-2007-170013- | E24: ADULT EDUCATION - PROVIDER | F24: 11000-17030-84002-2007 | G24: Adult Education
A25: 93 | B25: NEW HAVEN | C25: 2327089 | D25: 11000-17030-84002-2007-170013- | E25: ADULT EDUCATION - PROVIDER | F25: 11000-17030-84002-2007 | G25: Adult Education
... A164: 151 | B164: WATERBURY | C164: 23860 | D164: 11000-17030-84004-2007-170013- | E164: ADULT EDUC.-COOPERATING ELIGIBLE ENTITY | F164: 11000-17030-84004-2007 | G164: Adult Education
B165: Statewide Total | C165: =SUM(C2:C164) -> 18167318
B166: Bridgeport Total | C166: =C5+C152 -> 1167363
B167: New Haven Total | C167: =C25+C160 -> 2380784
A169: 62 | B169: HAMDEN | C169: 0 | D169: 12060-20784-84002-2005-170016-SDE00005 | E169: ADULT EDUCATION | F169: 12060-20784-84002-2005 | G169: Adult Education
A170: 62 | B170: HAMDEN | C170: 31053 | D170: 12060-20784-84002-2005-170016-SDE00006 | E170: ADULT EDUCATION | F170: 12060-20784-84002-2005 | G170: Adult Education
A171: 15 | B171: BRIDGEPORT | C171: 100000 | D171: 12060-20784-84002-2006-170014-SDE00008 | E171: ADULT EDUCATION | F171: 12060-20784-84002-2006 | G171: Adult Education
A172: 135 | B172: STAMFORD | C172: 35000 | D172: 12060-20784-84002-2006-170014-SDE00008 | E172: ADULT EDUCATION | F172: 12060-20784-84002-2006 | G172: Adult Education
A173: 7 | B173: BERLIN | C173: 20000 | D173: 12060-20784-84002-2006-170015-SDE00008 | E173: ADULT EDUCATION | F173: 12060-20784-84002-2006 | G173: Adult Education
A174: 15 | B174: BRIDGEPORT | C174: 20000 | D174: 12060-20784-84002-2006-170015-SDE00008 | E174: ADULT EDUCATION | F174: 12060-20784-84002-2006 | G174: Adult Education
A175: 44 | B175: EAST HAVEN | C175: 10562 | D175: 12060-20784-84002-2006-170015-SDE00008 | E175: ADULT EDUCATION | F175: 12060-20784-84002-2006 | G175: Adult Education
A176: 62 | B176: HAMDEN | C176: 20000 | D176: 12060-20784-84002-2006-170015-SDE00008 | E176: ADULT EDUCATION | F176: 12060-20784-84002-2006 | G176: Adult Education
A177: 64 | B177: HARTFORD | C177: 19850 | D177: 12060-20784-84002-2006-170015-SDE00008 | E177: ADULT EDUCATION | F177: 12060-20784-84002-2006 | G177: Adult Education
A178: 83 | B178: MIDDLETOWN | C178: 20000 | D178: 12060-20784-84002-2006-170015-SDE00008 | E178: ADULT EDUCATION | F178: 12060-20784-84002-2006 | G178: Adult Education
A179: 95 | B179: NEW LONDON | C179: 20000 | D179: 12060-20784-84002-2006-170015-SDE00008 | E179: ADULT EDUCATION | F179: 12060-20784-84002-2006 | G179: Adult Education
...

Sheet FY03 Figures 1,2,4
A1: Figure 1 | I1: Figure 2
A2: Connecticut (2002-03) | B2: Statewide | D2: Bridgeport | F2: New Haven | J2: District | K2: Charter | L2: Difference
A3: Per-Pupil Revenue | I3: State | J3: =B4 -> 11551.265 | K3: =B5 -> 11282.617 | L3: =B6 -> 268.64763
A4: District | B4: =B14 -> 11551.265 | D4: =D14 -> 11005.991 | F4: =F14 -> 16963.091 | I4: =D2 -> Bridgeport | J4: =D4 -> 11005.991 | K4: =D5 -> 9459.1486 | L4: =D6 -> 1546.842
A5: Charter | B5: =C14 -> 11282.617 | D5: =E14 -> 9459.1486 | F5: =G14 -> 14354.18 | I5: =F2 -> New Haven | J5: =F4 -> 16963.091 | K5: =F5 -> 14354.18 | L5: =F6 -> 2608.9108
A6: Difference | B6: =B4-B5 -> 268.64763 | D6: =D4-D5 -> 1546.842 | F6: =F4-F5 -> 2608.9108
B7: =B6/B4 -> 0.023256988 | D7: =D6/D4 -> 0.14054546 | F7: =F6/F4 -> 0.15379926
A8: Per-Pupil Revenue by Source | B8: District | C8: Charter | D8: District | E8: Charter | F8: District | G8: Charter
A9: Federal | B9: ='FY03 Dist w school constr'!E174 -> 456.00394 | C9: ='FY03 Charter w school const'!E19 -> 1037.4362 | D9: ='FY03 Dist w school constr'!E181 -> 1115.6638 | E9: ='FY03 Charter w school const'!E28 -> 1393.8571 | F9: ='FY03 Dist w school constr'!E188 -> 2038.4386 | G9: ='FY03 Charter w school const'!E38 -> 1317.4294
A10: State | B10: ='FY03 Dist w school constr'!D174 -> 3796.3369 | C10: ='FY03 Charter w school const'!D19 -> 8167.3897 | D10: ='FY03 Dist w school constr'!D181 -> 7464.6145 | E10: ='FY03 Charter w school const'!D28 -> 7026.6629 | F10: ='FY03 Dist w school constr'!D188 -> 10965.344 | G10: ='FY03 Charter w school const'!D38 -> 8390.3213
A11: Local | B11: ='FY03 Dist w school constr'!G174 -> 7193.8918 | C11: ='FY03 Charter w school const'!G19 -> 148.28864 | D11: ='FY03 Dist w school constr'!G181 -> 2358.7306 | E11: ='FY03 Charter w school const'!G28 -> 166.40571 | F11: ='FY03 Dist w school constr'!G188 -> 3811.0307 | G11: ='FY03 Charter w school const'!G38 -> 0
A12: Other
A13: Indeterminate | B13: ='FY03 Dist w school constr'!F174 -> 105.03227 | C13: ='FY03 Charter w school const'!F19 -> 1929.5028 | D13: ='FY03 Dist w school constr'!F181 -> 66.981574 | E13: ='FY03 Charter w school const'!F28 -> 872.22286 | F13: ='FY03 Dist w school constr'!F188 -> 148.27812 | G13: ='FY03 Charter w school const'!F38 -> 4646.4294
A14: Total | B14: =SUM(B9:B13) -> 11551.265 | C14: =SUM(C9:C13) -> 11282.617 | D14: =SUM(D9:D13) -> 11005.991 | E14: =SUM(E9:E13) -> 9459.1486 | F14: =SUM(F9:F13) -> 16963.091 | G14: =SUM(G9:G13) -> 14354.18
A15: Enrollment
A16: District | B16: ='FY03 Dist w school constr'!C174 -> 544263 | D16: ='FY03 Dist w school constr'!C181 -> 21925 | F16: ='FY03 Dist w school constr'!C188 -> 19082
B17: =B16/(B16+B18) -> 0.99606889 | D17: =D16/(D16+D18) -> 0.99208145 | F17: =F16/(F16+F18) -> 0.98284831
A18: Charter | B18: ='FY03 Charter w school const'!C19 -> 2148 | D18: ='FY03 Charter w school const'!C28 -> 175 | F18: ='FY03 Charter w school const'!C38 -> 333
B19: =B18/(B16+B18) -> 0.0039311068 | D19: =D18/(D16+D18) -> 0.007918552 | F19: =F18/(F16+F18) -> 0.017151687
A20: Number of Charters | B20: 12 | D20: 1 | F20: 2
A21: Total Revenue
A22: District | B22: ='FY03 Dist w school constr'!H173 -> 6286926116 | D22: ='FY03 Dist w school constr'!H180 -> 241306343 | F22: ='FY03 Dist w school constr'!H187 -> 323689703
B23: =B22/B26 -> 0.99615997 | D23: =D22/D26 -> 0.99318678 | F23: =F22/F26 -> 0.98544784
A24: Charter | B24: ='FY03 Charter w school const'!H18 -> 24235062 | D24: ='FY03 Charter w school const'!H27 -> 1655351 | F24: ='FY03 Charter w school const'!H37 -> 4779942
B25: =B24/B26 -> 0.0038400322 | D25: =D24/D26 -> 0.0068132181 | F25: =F24/F26 -> 0.014552157
A26: Total | B26: =B22+B24 -> 6311161178 | D26: =D22+D24 -> 242961694 | F26: =F22+F24 -> 328469645 | I26: Figure 4
A27: Percentage of Revenue by Source | B27: District | C27: Charter | D27: District | E27: Charter | F27: District | G27: Charter | J27: Federal | K27: State | L27: Local | M27: Other | N27: Indeterminate
A28: Federal | B28: =B9/B14 -> 0.039476538 | C28: =C9/C14 -> 0.091949961 | D28: =D9/D14 -> 0.10136878 | E28: =E9/E14 -> 0.14735546 | F28: =F9/F14 -> 0.12016905 | G28: =G9/G14 -> 0.091780193 | I28: Statewide District | J28: =B9 -> 456.00394 | K28: =B10 -> 3796.3369 | L28: =B11 -> 7193.8918 | M28: =B12 -> 0 | N28: =B13 -> 105.03227
A29: State | B29: =B10/B14 -> 0.32865118 | C29: =C10/C14 -> 0.7238914 | D29: =D10/D14 -> 0.67823196 | E29: =E10/E14 -> 0.74284306 | F29: =F10/F14 -> 0.64642367 | G29: =G10/G14 -> 0.58452111 | I29: Statewide Charter | J29: =C9 -> 1037.4362 | K29: =C10 -> 8167.3897 | L29: =C11 -> 148.28864 | M29: =C12 -> 0 | N29: =C13 -> 1929.5028
A30: Local | B30: =B11/B14 -> 0.62277957 | C30: =C11/C14 -> 0.013143106 | D30: =D11/D14 -> 0.21431334 | E30: =E11/E14 -> 0.017592039 | F30: =F11/F14 -> 0.22466605 | G30: =G11/G14 -> 0 | I30: Bridgeport District | J30: =D9 -> 1115.6638 | K30: =D10 -> 7464.6145 | L30: =D11 -> 2358.7306 | M30: =D12 -> 0 | N30: =D13 -> 66.981574
A31: Other | I31: Bridgeport Charter | J31: =E9 -> 1393.8571 | K31: =E10 -> 7026.6629 | L31: =E11 -> 166.40571 | M31: =E12 -> 0 | N31: =E13 -> 872.22286
A32: Indeterminate | B32: =B13/B14 -> 0.0090927073 | C32: =C13/C14 -> 0.17101553 | D32: =D13/D14 -> 0.0060859196 | E32: =E13/E14 -> 0.092209447 | F32: =F13/F14 -> 0.0087412203 | G32: =G13/G14 -> 0.3236987 | I32: New Haven District | J32: =F9 -> 2038.4386 | K32: =F10 -> 10965.344 | L32: =F11 -> 3811.0307 | M32: =F12 -> 0 | N32: =F13 -> 148.27812
A33: Change in district school funding if subjected to charter funding structure | I33: New Haven Charter | J33: =G9 -> 1317.4294 | K33: =G10 -> 8390.3213 | L33: =G11 -> 0 | M33: =G12 -> 0 | N33: =G13 -> 4646.4294
B34: ($146.2 million) | D34: ($33.9 million) | F34: ($49.7 million)
B35: =B6*B16 -> 1.4621497e+08 | D35: =D6*D16 -> 33914511 | F35: =F6*F16 -> 49783237

Sheet FY03 Dist w school constr
A1: 2002-03 Strategic School Profiles data with school construction
A3: TOWN CODE | B3: NAME | C3: TOTAL EXPENDITURES | D3: STATE PORTION | E3: FEDERAL PORTION | F3: TUITION PORTION | G3: LOCAL PORTION | H3: LOCAL % | I3: FEDERAL % | J3: STATE % | K3: TUITION %
A4: 1 | B4: ANDOVER | C4: 3254085 | D4: 1085745 | E4: 65112 | F4: 10179 | G4: 2093049 | H4: 64.3 | I4: 2 | J4: 33.4 | K4: 0.3
A5: 2 | B5: ANSONIA | C5: 26616472 | D5: 15571785 | E5: 1050134 | F5: 63315 | G5: 9931238 | H5: 37.3 | I5: 3.9 | J5: 58.5 | K5: 0.2
A6: 3 | B6: ASHFORD | C6: 5530577 | D6: 2732733 | E6: 198305 | F6: 9717 | G6: 2589822 | H6: 46.8 | I6: 3.6 | J6: 49.4 | K6: 0.2
A7: 4 | B7: AVON | C7: 34665315 | D7: 2287643 | E7: 399944 | F7: 131279 | G7: 31846449 | H7: 91.9 | I7: 1.2 | J7: 6.6 | K7: 0.4
A8: 5 | B8: BARKHAMSTED | C8: 3523411 | D8: 900130 | E8: 179849 | F8: 450 | G8: 2442982 | H8: 69.3 | I8: 5.1 | J8: 25.5 | K8: 0
A9: 7 | B9: BERLIN | C9: 33027344 | D9: 5299155 | E9: 625336 | F9: 13252 | G9: 27089601 | H9: 82 | I9: 1.9 | J9: 16 | K9: 0
A10: 8 | B10: BETHANY | C10: 5382487 | D10: 1218887 | E10: 177035 | F10: 22200 | G10: 3964365 | H10: 73.7 | I10: 3.3 | J10: 22.6 | K10: 0.4
A11: 9 | B11: BETHEL | C11: 38604071 | D11: 12014224 | E11: 632099 | F11: 0 | G11: 25957748 | H11: 67.2 | I11: 1.6 | J11: 31.1 | K11: 0
A12: 11 | B12: BLOOMFIELD | C12: 31790507 | D12: 4135330 | E12: 812305 | F12: 258381 | G12: 26584491 | H12: 83.6 | I12: 2.6 | J12: 13 | K12: 0.8
A13: 12 | B13: BOLTON | C13: 10768951 | D13: 3849337 | E13: 191337 | F13: 28682 | G13: 6699595 | H13: 62.2 | I13: 1.8 | J13: 35.7 | K13: 0.3
A14: 13 | B14: BOZRAH | C14: 4546740 | D14: 1522407 | E14: 136735 | F14: 5615 | G14: 2881983 | H14: 63.4 | I14: 3 | J14: 33.5 | K14: 0.1
A15: 14 | B15: BRANFORD | C15: 40101168 | D15: 3043361 | E15: 915898 | F15: 0 | G15: 36141909 | H15: 90.1 | I15: 2.3 | J15: 7.6 | K15: 0
... A169: 219 | B169: DISTRICT NO. 19 | C169: 16188640 | D169: 7424797 | E169: 272741 | F169: 499402 | G169: 7991700 | H169: 49.4 | I169: 1.7 | J169: 45.9 | K169: 3.1
B170: Subtotal | D170: =SUM(D4:D169) -> 2145319330 | E170: =SUM(E4:E169) -> 260460171 | F170: =SUM(F4:F169) -> 57165179 | G170: =SUM(G4:G169) -> 3915369154
C171: Less Adult | D171: ='FY03 ST Fed Grants'!F182 -> 16068137 | E171: ='FY03 ST Fed Grants'!F30 -> 6041447
C172: Less PreK | D172: ='FY03 ST Fed Grants'!F426 -> 63045485 | E172: ='FY03 ST Fed Grants'!F341 -> 6232649
B173: Total | D173: =D170-(D171+D172) -> 2066205708 | E173: =E170-(E171+E172) -> 248186075 | F173: =F170-(F171+F172) -> 57165179 | G173: =G170-(G171+G172) -> 3915369154 | H173: =SUM(D173:G173) -> 6286926116
B174: Enrollment | C174: 544263 | D174: =D173/C174 -> 3796.3369 | E174: =E173/C174 -> 456.00394 | F174: =F173/C174 -> 105.03227 | G174: =G173/C174 -> 7193.8918
D175: =D173/H173 -> 0.32865118 | E175: =E173/H173 -> 0.039476538 | F175: =F173/H173 -> 0.0090927073 | G175: =G173/H173 -> 0.62277957
A177: 15 | B177: BRIDGEPORT | C177: 251008445 | D177: 172973178 | E177: 24851527 | F177: 1468571 | G177: 51715169 | H177: 20.6 | I177: 9.9 | J177: 68.9 | K177: 0.6
C178: Less Adult | D178: ='FY03 ST Fed Grants'!F183 -> 956003 | E178: ='FY03 ST Fed Grants'!F31 -> 95800
C179: Less PreK | D179: ='FY03 ST Fed Grants'!F427 -> 8355501 | E179: ='FY03 ST Fed Grants'!F342 -> 294798
B180: Total | D180: =D177-(D178+D179) -> 163661674 | E180: =E177-(E178+E179) -> 24460929 | F180: =F177-(F178+F179) -> 1468571 | G180: =G177-(G178+G179) -> 51715169 | H180: =SUM(D180:G180) -> 241306343
B181: Enrollment | C181: 21925 | D181: =D180/C181 -> 7464.6145 | E181: =E180/C181 -> 1115.6638 | F181: =F180/C181 -> 66.981574 | G181: =G180/C181 -> 2358.7306
D182: =D180/H180 -> 0.67823196 | E182: =E180/H180 -> 0.10136878 | F182: =F180/H180 -> 0.0060859196 | G182: =G180/H180 -> 0.21431334
A184: 93 | B184: NEW HAVEN | C184: 333224148 | D184: 218503424 | E184: 39169193 | F184: 2829443 | G184: 72722088 | H184: 21.8 | I184: 11.8 | J184: 65.6 | K184: 0.8
C185: Less Adult | D185: ='FY03 ST Fed Grants'!F184 -> 2167633 | E185: ='FY03 ST Fed Grants'!F32 -> 144686
C186: Less PreK | D186: ='FY03 ST Fed Grants'!F428 -> 7095104 | E186: ='FY03 ST Fed Grants'!F343 -> 127022
B187: Total | D187: =D184-(D185+D186) -> 209240687 | E187: =E184-(E185+E186) -> 38897485 | F187: =F184-(F185+F186) -> 2829443 | G187: =G184-(G185+G186) -> 72722088 | H187: =SUM(D187:G187) -> 323689703
B188: Enrollment | C188: 19082 | D188: =D187/C188 -> 10965.344 | E188: =E187/C188 -> 2038.4386 | F188: =F187/C188 -> 148.27812 | G188: =G187/C188 -> 3811.0307
D189: =D187/H187 -> 0.64642367 | E189: =E187/H187 -> 0.12016905 | F189: =F187/H187 -> 0.0087412203 | G189: =G187/H187 -> 0.22466605

Sheet FY03 Charter w school const
A1: TOWN CODE | B1: NAME | C1: TOTAL EXPENDITURES | D1: STATE PORTION | E1: FEDERAL PORTION | F1: TUITION PORTION | G1: LOCAL PORTION | H1: LOCAL % | I1: FEDERAL % | J1: STATE % | K1: TUITION %
A2: 261 | B2: JUMOKE ACADEMY | C2: 2682204 | D2: 2297719 | E2: 280516 | F2: 103969 | G2: 0 | H2: 0 | I2: 10.5 | J2: 85.7 | K2: 3.9
A3: 263 | B3: ODYSSEY SCHOOL | C3: 1493819 | D3: 1230489 | E3: 25457 | F3: 217203 | G3: 20670 | H3: 1.4 | I3: 1.7 | J3: 82.4 | K3: 14.5
A4: 264 | B4: INTEGRATED DAY | C4: 2823437 | D4: 2323844 | E4: 223963 | F4: 274362 | G4: 1268 | H4: 0 | I4: 7.9 | J4: 82.3 | K4: 9.7
A5: 265 | B5: INTERDIST SCH ART | C5: 1347043 | D5: 807703 | E5: 272419 | F5: 209970 | G5: 56951 | H5: 4.2 | I5: 20.2 | J5: 60 | K5: 15.6
A6: 268 | B6: COMMON GROUND | C6: 1551400 | D6: 1249575 | E6: 223947 | F6: 77878 | G6: 0 | H6: 0 | I6: 14.4 | J6: 80.5 | K6: 5
A7: 269 | B7: BRIDGE ACADEMY | C7: 1655351 | D7: 1229666 | E7: 243925 | F7: 152639 | G7: 29121 | H7: 1.8 | I7: 14.7 | J7: 74.3 | K7: 9.2
A8: 270 | B8: SIDE BY SIDE | C8: 2444363 | D8: 2090450 | E8: 60453 | F8: 169393 | G8: 124067 | H8: 5.1 | I8: 2.5 | J8: 85.5 | K8: 6.9
A9: 272 | B9: EXPLORATIONS | C9: 1032495 | D9: 897446 | E9: 28266 | F9: 82833 | G9: 23950 | H9: 2.3 | I9: 2.7 | J9: 86.9 | K9: 8
A10: 273 | B10: BROOKLAWN ACADEMY | C10: 0 | D10: 0 | E10: 0 | F10: 0 | G10: 0
A11: 277 | B11: HIGHVILLE MUSTARD | C11: 2378894 | D11: 2115519 | E11: 241185 | F11: 22190 | G11: 0 | H11: 0 | I11: 10.1 | J11: 88.9 | K11: 0.9
A12: 278 | B12: TRAILBLAZERS | C12: 1584899 | D12: 759421 | E12: 76937 | F12: 748541 | G12: 0 | H12: 0 | I12: 4.9 | J12: 47.9 | K12: 47.2
A13: 279 | B13: AMISTAD | C13: 3228542 | D13: 1544402 | E13: 214757 | F13: 1469383 | G13: 0 | H13: 0 | I13: 6.7 | J13: 47.8 | K13: 45.5
A14: 280 | B14: NEW BEGINNINGS | C14: 2012615 | D14: 997319 | E14: 336588 | F14: 616211 | G14: 62497 | H14: 3.1 | I14: 16.7 | J14: 49.6 | K14: 30.6
B15: Subtotal | D15: =SUM(D2:D14) -> 17543553 | E15: =SUM(E2:E14) -> 2228413 | F15: =SUM(F2:F14) -> 4144572 | G15: =SUM(G2:G14) -> 318524
B16: Less Adult Ed | D16: 0 | E16: 0 | F16: 0 | G16: 0
B17: Less Preschool/PreK | D17: 0 | E17: 0 | F17: 0 | G17: 0
B18: Total | D18: =D15-(D16+D17) -> 17543553 | E18: =E15-(E16+E17) -> 2228413 | F18: =F15-(F16+F17) -> 4144572 | G18: =G15-(G16+G17) -> 318524 | H18: =SUM(D18:G18) -> 24235062
B19: Enrollment | C19: 2148 | D19: =D18/$C$19 -> 8167.3897 | E19: =E18/$C$19 -> 1037.4362 | F19: =F18/$C$19 -> 1929.5028 | G19: =G18/$C$19 -> 148.28864
D20: =D18/H18 -> 0.7238914 | E20: =E18/H18 -> 0.091949961 | F20: =F18/H18 -> 0.17101553 | G20: =G18/H18 -> 0.013143106
B22: Bridgeport Charters
A23: 269 | B23: BRIDGE ACADEMY | C23: 1655351 | D23: 1229666 | E23: 243925 | F23: 152639 | G23: 29121 | H23: 1.8 | I23: 14.7 | J23: 74.3 | K23: 9.2
B24: Subtotal | D24: =D23 -> 1229666 | E24: =E23 -> 243925 | F24: =F23 -> 152639 | G24: =G23 -> 29121
B25: Less Adult Ed | D25: 0 | E25: 0 | F25: 0 | G25: 0
B26: Less Preschool/PreK | D26: 0 | E26: 0 | F26: 0 | G26: 0
B27: Total | D27: =D24-(D25+D26) -> 1229666 | E27: =E24-(E25+E26) -> 243925 | F27: =F24-(F25+F26) -> 152639 | G27: =G24-(G25+G26) -> 29121 | H27: =SUM(D27:G27) -> 1655351
B28: Enrollment | C28: 175 | D28: =D27/$C$28 -> 7026.6629 | E28: =E27/$C$28 -> 1393.8571 | F28: =F27/$C$28 -> 872.22286 | G28: =G27/$C$28 -> 166.40571
D29: =D27/H27 -> 0.74284306 | E29: =E27/H27 -> 0.14735546 | F29: =F27/H27 -> 0.092209447 | G29: =G27/H27 -> 0.017592039
B31: Hew Haven Charters
A32: 268 | B32: COMMON GROUND | C32: 1551400 | D32: 1249575 | E32: 223947 | F32: 77878 | G32: 0 | H32: 0 | I32: 14.4 | J32: 80.5 | K32: 5
A33: 279 | B33: AMISTAD | C33: 3228542 | D33: 1544402 | E33: 214757 | F33: 1469383 | G33: 0 | H33: 0 | I33: 6.7 | J33: 47.8 | K33: 45.5
B34: Subtotal | D34: =SUM(D32:D33) -> 2793977 | E34: =SUM(E32:E33) -> 438704 | F34: =SUM(F32:F33) -> 1547261 | G34: =SUM(G32:G33) -> 0
B35: Less Adult Ed | D35: 0 | E35: 0 | F35: 0 | G35: 0
B36: Less Preschool/PreK | D36: 0 | E36: 0 | F36: 0 | G36: 0
B37: Total | D37: =D34-(D35+D36) -> 2793977 | E37: =E34-(E35+E36) -> 438704 | F37: =F34-(F35+F36) -> 1547261 | G37: =G34-(G35+G36) -> 0 | H37: =SUM(D37:G37) -> 4779942
B38: Enrollment | C38: 333 | D38: =D37/$C$38 -> 8390.3213 | E38: =E37/$C$38 -> 1317.4294 | F38: =F37/$C$38 -> 4646.4294 | G38: =G37/$C$38 -> 0
D39: =D37/H37 -> 0.58452111 | E39: =E37/H37 -> 0.091780193 | F39: =F37/H37 -> 0.3236987 | G39: =G37/H37 -> 0

Sheet FY03 ST Fed Grants
A1: town | B1: name | C1: drg | D1: grant_name | E1: grant_type | F1: pay2003
A2: 7 | B2: Berlin | C2: D | D2: Adult Education | E2: Federal | F2: 10640 | G2: Adult Education
A3: 14 | B3: Branford | C3: D | D3: Adult Education | E3: Federal | F3: 97850 | G3: Adult Education
A4: 15 | B4: Bridgeport | C4: I | D4: Adult Education | E4: Federal | F4: 95800 | G4: Adult Education
A5: 17 | B5: Bristol | C5: G | D5: Adult Education | E5: Federal | F5: 72500 | G5: Adult Education
A6: 34 | B6: Danbury | C6: H | D6: Adult Education | E6: Federal | F6: 157700 | G6: Adult Education
A7: 44 | B7: East Haven | C7: G | D7: Adult Education | E7: Federal | F7: 11487 | G7: Adult Education
A8: 62 | B8: Hamden | C8: G | D8: Adult Education | E8: Federal | F8: 244564 | G8: Adult Education
A9: 64 | B9: Hartford | C9: I | D9: Adult Education | E9: Federal | F9: 99000 | G9: Adult Education
A10: 80 | B10: Meriden | C10: H | D10: Adult Education | E10: Federal | F10: 157882 | G10: Adult Education
A11: 83 | B11: Middletown | C11: G | D11: Adult Education | E11: Federal | F11: 392500 | G11: Adult Education
A12: 88 | B12: Naugatuck | C12: G | D12: Adult Education | E12: Federal | F12: 30746 | G12: Adult Education
A13: 89 | B13: New Britain | C13: I | D13: Adult Education | E13: Federal | F13: 145000 | G13: Adult Education
... A23: 155 | B23: West Hartford | C23: B | D23: Adult Education | E23: Federal | F23: 57172 | G23: Adult Education
A24: 241 | B24: C R E C | D24: Adult Education | E24: Federal | F24: 902214 | G24: Adult Education
A25: 242 | B25: Education Connection | D25: Adult Education | E25: Federal | F25: 174826 | G25: Adult Education
A26: 253 | B26: E A S T C O N N | D26: Adult Education | E26: Federal | F26: 195005 | G26: Adult Education
A27: 301 | B27: Voc. Tech. Schools | D27: Adult Education | E27: Federal | F27: 191359 | G27: Adult Education
A28: 336 | B28: Dept Of Corrections | D28: Adult Education | E28: Federal | F28: 165800 | G28: Adult Education
A29: 998 | B29: Towns Not Included | D29: Adult Education | E29: Federal | F29: 1269620 | G29: Adult Education
E30: Statewide Total | F30: =SUM(F2:F29) -> 6041447
E31: Bridgeport Total | F31: =F4 -> 95800
E32: New Haven Total | F32: =F14 -> 144686
A34: 2 | B34: Ansonia | C34: H | D34: Adult Education - Provider | E34: State | F34: 88308 | G34: Adult Education
A35: 4 | B35: Avon | C35: B | D35: Adult Education - Provider | E35: State | F35: 702 | G35: Adult Education
A36: 5 | B36: Barkhamsted | C36: C | D36: Adult Education - Provider | E36: State | F36: 1116 | G36: Adult Education
A37: 7 | B37: Berlin | C37: D | D37: Adult Education - Provider | E37: State | F37: 7833 | G37: Adult Education
A38: 9 | B38: Bethel | C38: D | D38: Adult Education - Provider | E38: State | F38: 5576 | G38: Adult Education
A39: 11 | B39: Bloomfield | C39: G | D39: Adult Education - Provider | E39: State | F39: 9987 | G39: Adult Education
A40: 12 | B40: Bolton | C40: C | D40: Adult Education - Provider | E40: State | F40: 2912 | G40: Adult Education
A41: 13 | B41: Bozrah | C41: E | D41: Adult Education - Provider | E41: State | F41: 3881 | G41: Adult Education
A42: 14 | B42: Branford | C42: D | D42: Adult Education - Provider | E42: State | F42: 17088 | G42: Adult Education
A43: 15 | B43: Bridgeport | C43: I | D43: Adult Education - Provider | E43: State | F43: 956003 | G43: Adult Education
A44: 17 | B44: Bristol | C44: G | D44: Adult Education - Provider | E44: State | F44: 206501 | G44: Adult Education
A45: 18 | B45: Brookfield | C45: B | D45: Adult Education - Provider | E45: State | F45: 1873 | G45: Adult Education
A46: 19 | B46: Brooklyn | C46: E | D46: Adult Education - Provider | E46: State | F46: 20047 | G46: Adult Education
A47: 241 | B47: C R E C | D47: Adult Education - Provider | E47: State | F47: 213103 | G47: Adult Education
A48: 22 | B48: Canterbury | C48: F | D48: Adult Education - Provider | E48: State | F48: 9455 | G48: Adult Education
A49: 23 | B49: Canton | C49: C | D49: Adult Education - Provider | E49: State | F49: 1345 | G49: Adult Education
A50: 24 | B50: Chaplin | C50: E | D50: Adult Education - Provider | E50: State | F50: 1749 | G50: Adult Education
...

Sheet 2002-03 without school constr 
A1: 2002-03 Strategic School Profiles data without school construction
A3: TOWN CODE | B3: NAME | C3: TOTAL EXPENDITURES | D3: STATE PORTION | E3: FEDERAL PORTION | F3: TUITION PORTION | G3: LOCAL PORTION | H3: LOCAL % | I3: FEDERAL % | J3: STATE % | K3: TUITION %
A4: 1 | B4: ANDOVER | C4: 3165184 | D4: 1085745 | E4: 65112 | F4: 10179 | G4: 2004148 | H4: 63.3 | I4: 2.1 | J4: 34.3 | K4: 0.3
A5: 2 | B5: ANSONIA | C5: 21950002 | D5: 12589024 | E5: 1050134 | F5: 63315 | G5: 8247529 | H5: 37.6 | I5: 4.8 | J5: 57.4 | K5: 0.3
A6: 3 | B6: ASHFORD | C6: 5283291 | D6: 2575765 | E6: 198305 | F6: 9717 | G6: 2499504 | H6: 47.3 | I6: 3.8 | J6: 48.8 | K6: 0.2
A7: 4 | B7: AVON | C7: 30115177 | D7: 965282 | E7: 399944 | F7: 131279 | G7: 28618672 | H7: 95 | I7: 1.3 | J7: 3.2 | K7: 0.4
A8: 5 | B8: BARKHAMSTED | C8: 3147772 | D8: 744944 | E8: 179849 | F8: 450 | G8: 2222529 | H8: 70.6 | I8: 5.7 | J8: 23.7 | K8: 0
A9: 7 | B9: BERLIN | C9: 30388846 | D9: 4506324 | E9: 625336 | F9: 13252 | G9: 25243934 | H9: 83.1 | I9: 2.1 | J9: 14.8 | K9: 0
A10: 8 | B10: BETHANY | C10: 4805718 | D10: 998730 | E10: 177035 | F10: 22200 | G10: 3607753 | H10: 75.1 | I10: 3.7 | J10: 20.8 | K10: 0.5
A11: 9 | B11: BETHEL | C11: 32488956 | D11: 7794675 | E11: 632099 | F11: 0 | G11: 24062182 | H11: 74.1 | I11: 1.9 | J11: 24 | K11: 0
A12: 11 | B12: BLOOMFIELD | C12: 31008515 | D12: 3958264 | E12: 812305 | F12: 258381 | G12: 25979565 | H12: 83.8 | I12: 2.6 | J12: 12.8 | K12: 0.8
A13: 12 | B13: BOLTON | C13: 10179970 | D13: 2836937 | E13: 191337 | F13: 28682 | G13: 7123014 | H13: 70 | I13: 1.9 | J13: 27.9 | K13: 0.3
A14: 13 | B14: BOZRAH | C14: 3956170 | D14: 1192391 | E14: 136735 | F14: 5615 | G14: 2621429 | H14: 66.3 | I14: 3.5 | J14: 30.1 | K14: 0.1
A15: 14 | B15: BRANFORD | C15: 36830531 | D15: 1968773 | E15: 915898 | F15: 0 | G15: 33945860 | H15: 92.2 | I15: 2.5 | J15: 5.3 | K15: 0
... A177: 272 | B177: EXPLORATIONS | C177: 602495 | D177: 467446 | E177: 28266 | F177: 82833 | G177: 23950 | H177: 4 | I177: 4.7 | J177: 77.6 | K177: 13.7
A178: 273 | B178: BROOKLAWN ACADEMY | C178: 0 | D178: 0 | E178: 0 | F178: 0 | G178: 0
A179: 277 | B179: HIGHVILLE MUSTARD | C179: 2378894 | D179: 2115519 | E179: 241185 | F179: 22190 | G179: 0 | H179: 0 | I179: 10.1 | J179: 88.9 | K179: 0.9
A180: 278 | B180: TRAILBLAZERS | C180: 1584899 | D180: 759421 | E180: 76937 | F180: 748541 | G180: 0 | H180: 0 | I180: 4.9 | J180: 47.9 | K180: 47.2
A181: 279 | B181: AMISTAD | C181: 2436679 | D181: 1544402 | E181: 214757 | F181: 677520 | G181: 0 | H181: 0 | I181: 8.8 | J181: 63.4 | K181: 27.8
A182: 280 | B182: NEW BEGINNINGS | C182: 2012615 | D182: 997319 | E182: 336588 | F182: 616211 | G182: 62497 | H182: 3.1 | I182: 16.7 | J182: 49.6 | K182: 30.6
