Workbook

Sheet NominalGDP-SIC
B1: HOVER FOR DETAIL ON SAVING DATA | U1: CURRENT DOLLARS (millions) OF GROSS DOMESTIC PRODUCT [SIC-derived]
A2: Location Codes | B2: Name of Geography | C2: Nominal Gross Domestic Product (millions) [SIC-derived] 1969 | D2: Nominal Gross Domestic Product (millions) [SIC-derived] 1970 | E2: Nominal Gross Domestic Product (millions) [SIC-derived] 1971 | F2: Nominal Gross Domestic Product (millions) [SIC-derived] 1972 | G2: Nominal Gross Domestic Product (millions) [SIC-derived] 1973 | H2: Nominal Gross Domestic Product (millions) [SIC-derived] 1974 | I2: Nominal Gross Domestic Product (millions) [SIC-derived] 1975 | J2: Nominal Gross Domestic Product (millions) [SIC-derived] 1976 | K2: Nominal Gross Domestic Product (millions) [SIC-derived] 1977 | L2: Nominal Gross Domestic Product (millions) [SIC-derived] 1978 | M2: Nominal Gross Domestic Product (millions) [SIC-derived] 1979 | N2: Nominal Gross Domestic Product (millions) [SIC-derived] 1980 | O2: Nominal Gross Domestic Product (millions) [SIC-derived] 1981 | P2: Nominal Gross Domestic Product (millions) [SIC-derived] 1982 | Q2: Nominal Gross Domestic Product (millions) [SIC-derived] 1983 | R2: Nominal Gross Domestic Product (millions) [SIC-derived] 1984 | S2: Nominal Gross Domestic Product (millions) [SIC-derived] 1985 | T2: Nominal Gross Domestic Product (millions) [SIC-derived] 1986 | U2: Nominal Gross Domestic Product (millions) [SIC-derived] 1987 | V2: Nominal Gross Domestic Product (millions) [SIC-derived] 1988 | W2: Nominal Gross Domestic Product (millions) [SIC-derived] 1989 | X2: Nominal Gross Domestic Product (millions) [SIC-derived] 1990 | Y2: Nominal Gross Domestic Product (millions) [SIC-derived] 1991 | Z2: Nominal Gross Domestic Product (millions) [SIC-derived] 1992 | AA2: Nominal Gross Domestic Product (millions) [SIC-derived] 1993 | AB2: Nominal Gross Domestic Product (millions) [SIC-derived] 1994 | AC2: Nominal Gross Domestic Product (millions) [SIC-derived] 1995 | AD2: Nominal Gross Domestic Product (millions) [SIC-derived] 1996 | AE2: Nominal Gross Domestic Product (millions) [SIC-derived] 1997
A3: CodedLocale | B3: Geo Name | C3: Raw GDP (mil$) [SIC] 1969 | D3: Raw GDP (mil$) [SIC] 1970 | E3: Raw GDP (mil$) [SIC] 1971 | F3: Raw GDP (mil$) [SIC] 1972 | G3: Raw GDP (mil$) [SIC] 1973 | H3: Raw GDP (mil$) [SIC] 1974 | I3: Raw GDP (mil$) [SIC] 1975 | J3: Raw GDP (mil$) [SIC] 1976 | K3: Raw GDP (mil$) [SIC] 1977 | L3: Raw GDP (mil$) [SIC] 1978 | M3: Raw GDP (mil$) [SIC] 1979 | N3: Raw GDP (mil$) [SIC] 1980 | O3: Raw GDP (mil$) [SIC] 1981 | P3: Raw GDP (mil$) [SIC] 1982 | Q3: Raw GDP (mil$) [SIC] 1983 | R3: Raw GDP (mil$) [SIC] 1984 | S3: Raw GDP (mil$) [SIC] 1985 | T3: Raw GDP (mil$) [SIC] 1986 | U3: Raw GDP (mil$) [SIC] 1987 | V3: Raw GDP (mil$) [SIC] 1988 | W3: Raw GDP (mil$) [SIC] 1989 | X3: Raw GDP (mil$) [SIC] 1990 | Y3: Raw GDP (mil$) [SIC] 1991 | Z3: Raw GDP (mil$) [SIC] 1992 | AA3: Raw GDP (mil$) [SIC] 1993 | AB3: Raw GDP (mil$) [SIC] 1994 | AC3: Raw GDP (mil$) [SIC] 1995 | AD3: Raw GDP (mil$) [SIC] 1996 | AE3: Raw GDP (mil$) [SIC] 1997
A4: fips_code | B4: geo_name | C4: raw-mil-dollars_gdp-sic_1969 | D4: raw-mil-dollars_gdp-sic_1970 | E4: raw-mil-dollars_gdp-sic_1971 | F4: raw-mil-dollars_gdp-sic_1972 | G4: raw-mil-dollars_gdp-sic_1973 | H4: raw-mil-dollars_gdp-sic_1974 | I4: raw-mil-dollars_gdp-sic_1975 | J4: raw-mil-dollars_gdp-sic_1976 | K4: raw-mil-dollars_gdp-sic_1977 | L4: raw-mil-dollars_gdp-sic_1978 | M4: raw-mil-dollars_gdp-sic_1979 | N4: raw-mil-dollars_gdp-sic_1980 | O4: raw-mil-dollars_gdp-sic_1981 | P4: raw-mil-dollars_gdp-sic_1982 | Q4: raw-mil-dollars_gdp-sic_1983 | R4: raw-mil-dollars_gdp-sic_1984 | S4: raw-mil-dollars_gdp-sic_1985 | T4: raw-mil-dollars_gdp-sic_1986 | U4: raw-mil-dollars_gdp-sic_1987 | V4: raw-mil-dollars_gdp-sic_1988 | W4: raw-mil-dollars_gdp-sic_1989 | X4: raw-mil-dollars_gdp-sic_1990 | Y4: raw-mil-dollars_gdp-sic_1991 | Z4: raw-mil-dollars_gdp-sic_1992 | AA4: raw-mil-dollars_gdp-sic_1993 | AB4: raw-mil-dollars_gdp-sic_1994 | AC4: raw-mil-dollars_gdp-sic_1995 | AD4: raw-mil-dollars_gdp-sic_1996 | AE4: raw-mil-dollars_gdp-sic_1997
A5: FIPS_CODE | B5: GEO_NAME | C5: 1969 | D5: 1970 | E5: 1971 | F5: 1972 | G5: 1973 | H5: 1974 | I5: 1975 | J5: 1976 | K5: 1977 | L5: 1978 | M5: 1979 | N5: 1980 | O5: 1981 | P5: 1982 | Q5: 1983 | R5: 1984 | S5: 1985 | T5: 1986 | U5: 1987 | V5: 1988 | W5: 1989 | X5: 1990 | Y5: 1991 | Z5: 1992 | AA5: 1993 | AB5: 1994 | AC5: 1995 | AD5: 1996 | AE5: 1997
A6: US | B6: United States | C6: 962902 | D6: 1012299 | E6: 1097173 | F6: 1210292 | G6: 1356500 | H6: 1472024 | I6: 1602228 | J6: 1780497 | K6: 1986408 | L6: 2243230 | M6: 2489416 | N6: 2713933 | O6: 3057318 | P6: 3211370 | Q6: 3445372 | R6: 3853668 | S6: 4126664 | T6: 4340813 | U6: 4649020 | V6: 5053003 | W6: 5366080 | X6: 5651747 | Y6: 5842665 | Z6: 6167644 | AA6: 6467698 | AB6: 6912844 | AC6: 7299372 | AD6: 7749965 | AE6: 8284432
A7: 004 | B7: Arizona | C7: 7563 | D7: 8569 | E7: 9649 | F7: 11292 | G7: 13330 | H7: 14611 | I7: 15284 | J7: 16970 | K7: 19609 | L7: 23279 | M7: 27495 | N7: 30764 | O7: 34269 | P7: 35794 | Q7: 39774 | R7: 46135 | S7: 50709 | T7: 55881 | U7: 60047 | V7: 64945 | W7: 67895 | X7: 70632 | Y7: 73358 | Z7: 82682 | AA7: 89300 | AB7: 100374 | AC7: 109906 | AD7: 119530 | AE7: 129279

Sheet NominalGDP-NAICS
B1: HOVER FOR DETAIL ON SAVING DATA | C1: CURRENT DOLLARS (millions) OF GROSS DOMESTIC PRODUCT [NAICS-derived]
A2: Location Codes | B2: Name of Geography | C2: Nominal Gross Domestic Product (millions) [NAICS-derived] 1997 | D2: Nominal Gross Domestic Product (millions) [NAICS-derived] 1998 | E2: Nominal Gross Domestic Product (millions) [NAICS-derived] 1999 | F2: Nominal Gross Domestic Product (millions) [NAICS-derived] 2000 | G2: Nominal Gross Domestic Product (millions) [NAICS-derived] 2001 | H2: Nominal Gross Domestic Product (millions) [NAICS-derived] 2002 | I2: Nominal Gross Domestic Product (millions) [NAICS-derived] 2003 | J2: Nominal Gross Domestic Product (millions) [NAICS-derived] 2004 | K2: Nominal Gross Domestic Product (millions) [NAICS-derived] 2005 | L2: Nominal Gross Domestic Product (millions) [NAICS-derived] 2006 | M2: Nominal Gross Domestic Product (millions) [NAICS-derived] 2007 | N2: Nominal Gross Domestic Product (millions) [NAICS-derived] 2008 | O2: Nominal Gross Domestic Product (millions) [NAICS-derived] 2009 | P2: Nominal Gross Domestic Product (millions) [NAICS-derived] 2010 | Q2: Nominal Gross Domestic Product (millions) [NAICS-derived] 2011 | R2: Nominal Gross Domestic Product (millions) [NAICS-derived] 2012
A3: CodedLocale | B3: Geo Name | C3: Raw GDP (mil$) [NAICS] 1997 | D3: Raw GDP (mil$) [NAICS] 1998 | E3: Raw GDP (mil$) [NAICS] 1999 | F3: Raw GDP (mil$) [NAICS] 2000 | G3: Raw GDP (mil$) [NAICS] 2001 | H3: Raw GDP (mil$) [NAICS] 2002 | I3: Raw GDP (mil$) [NAICS] 2003 | J3: Raw GDP (mil$) [NAICS] 2004 | K3: Raw GDP (mil$) [NAICS] 2005 | L3: Raw GDP (mil$) [NAICS] 2006 | M3: Raw GDP (mil$) [NAICS] 2007 | N3: Raw GDP (mil$) [NAICS] 2008 | O3: Raw GDP (mil$) [NAICS] 2009 | P3: Raw GDP (mil$) [NAICS] 2010 | Q3: Raw GDP (mil$) [NAICS] 2011 | R3: Raw GDP (mil$) [NAICS] 2012
A4: fips_code | B4: geo_name | C4: raw-mil-dollars_gdp-NAICS_1997 | D4: raw-mil-dollars_gdp-NAICS_1998 | E4: raw-mil-dollars_gdp-NAICS_1999 | F4: raw-mil-dollars_gdp-NAICS_2000 | G4: raw-mil-dollars_gdp-NAICS_2001 | H4: raw-mil-dollars_gdp-NAICS_2002 | I4: raw-mil-dollars_gdp-NAICS_2003 | J4: raw-mil-dollars_gdp-NAICS_2004 | K4: raw-mil-dollars_gdp-NAICS_2005 | L4: raw-mil-dollars_gdp-NAICS_2006 | M4: raw-mil-dollars_gdp-NAICS_2007 | N4: raw-mil-dollars_gdp-NAICS_2008 | O4: raw-mil-dollars_gdp-NAICS_2009 | P4: raw-mil-dollars_gdp-NAICS_2010 | Q4: raw-mil-dollars_gdp-NAICS_2011 | R4: raw-mil-dollars_gdp-NAICS_2012
A5: FIPS_CODE | B5: GEO_NAME | C5: 1997 | D5: 1998 | E5: 1999 | F5: 2000 | G5: 2001 | H5: 2002 | I5: 2003 | J5: 2004 | K5: 2005 | L5: 2006 | M5: 2007 | N5: 2008 | O5: 2009 | P5: 2010 | Q5: 2011 | R5: 2012
A6: NA | B6: U.S. Metros | C6: NA | D6: NA | E6: NA | F6: NA | G6: 9174721 | H6: 9495543 | I6: 9927853 | J6: 10558594 | K6: 11263078 | L6: 11949404 | M6: 12535529 | N6: 12754870 | O6: 12434965 | P6: 12950980 | Q6: 13445266
A7: US | B7: United States | C7: 8270462 | D7: 8727023 | E7: 9286858 | F7: 9884171 | G7: 10218019 | H7: 10572388 | I7: 11067829 | J7: 11774410 | K7: 12539116 | L7: 13289235 | M7: 13936199 | N7: 14193120 | O7: 13869678 | P7: 14388813 | Q7: 14959778 | R7: 15566077
A8: 004 | B8: Arizona | C8: 128026 | D8: 139276 | E8: 150876 | F8: 161792 | G8: 170008 | H8: 177068 | I8: 189060 | J8: 201006 | K8: 222569 | L8: 246099 | M8: 259157 | N8: 261128 | O8: 245216 | P8: 247329 | Q8: 255989 | R8: 266891
A9: 22380 | B9: Metro Flagstaff | C9: NA | D9: NA | E9: NA | F9: NA | G9: 2979 | H9: 3167 | I9: 3375 | J9: 3571 | K9: 3900 | L9: 4363 | M9: 4776 | N9: 4984 | O9: 4761 | P9: 4801 | Q9: 4890
A10: 29420 | B10: Metro Lake Havasu City | C10: NA | D10: NA | E10: NA | F10: NA | G10: 2432 | H10: 2621 | I10: 2855 | J10: 3025 | K10: 3408 | L10: 3908 | M10: 3977 | N10: 3933 | O10: 3579 | P10: 3570 | Q10: 3706
A11: 38060 | B11: Metro Phoenix | C11: NA | D11: NA | E11: NA | F11: NA | G11: 128231 | H11: 134076 | I11: 142985 | J11: 152071 | K11: 168571 | L11: 186580 | M11: 195763 | N11: 196360 | O11: 184014 | P11: 188332 | Q11: 194793
A12: 39140 | B12: Metro Prescott | C12: NA | D12: NA | E12: NA | F12: NA | G12: 2906 | H12: 3059 | I12: 3312 | J12: 3512 | K12: 4054 | L12: 4693 | M12: 4849 | N12: 4879 | O12: 4479 | P12: 4300 | Q12: 4402
A13: 46060 | B13: Metro Tucson | C13: NA | D13: NA | E13: NA | F13: NA | G13: 22621 | H13: 22801 | I13: 24564 | J13: 25737 | K13: 28165 | L13: 30612 | M13: 32704 | N13: 33259 | O13: 31675 | P13: 31529 | Q13: 32335
A14: 49740 | B14: Metro Yuma | C14: NA | D14: NA | E14: NA | F14: NA | G14: 3056 | H14: 3462 | I14: 3616 | J14: 4160 | K14: 4358 | L14: 4687 | M14: 5085 | N14: 5144 | O14: 5118 | P14: 5124 | Q14: 5322

Sheet RealGDP-SIC
B1: HOVER FOR DETAIL ON SAVING DATA | C1: INFLATION-ADJUSTED DOLLARS (millions) OF GROSS DOMESTIC PRODUCT [SIC-derived]
A2: Location Codes | B2: Name of Geography | C2: Nominal Gross Domestic Product (millions) [SIC-derived] 1987 | D2: Nominal Gross Domestic Product (millions) [SIC-derived] 1988 | E2: Nominal Gross Domestic Product (millions) [SIC-derived] 1989 | F2: Nominal Gross Domestic Product (millions) [SIC-derived] 1990 | G2: Nominal Gross Domestic Product (millions) [SIC-derived] 1991 | H2: Nominal Gross Domestic Product (millions) [SIC-derived] 1992 | I2: Nominal Gross Domestic Product (millions) [SIC-derived] 1993 | J2: Nominal Gross Domestic Product (millions) [SIC-derived] 1994 | K2: Nominal Gross Domestic Product (millions) [SIC-derived] 1995 | L2: Nominal Gross Domestic Product (millions) [SIC-derived] 1996 | M2: Nominal Gross Domestic Product (millions) [SIC-derived] 1997
A3: CodedLocale | B3: Geo Name | C3: Raw GDP (mil$) [SIC] 1987 | D3: Raw GDP (mil$) [SIC] 1988 | E3: Raw GDP (mil$) [SIC] 1989 | F3: Raw GDP (mil$) [SIC] 1990 | G3: Raw GDP (mil$) [SIC] 1991 | H3: Raw GDP (mil$) [SIC] 1992 | I3: Raw GDP (mil$) [SIC] 1993 | J3: Raw GDP (mil$) [SIC] 1994 | K3: Raw GDP (mil$) [SIC] 1995 | L3: Raw GDP (mil$) [SIC] 1996 | M3: Raw GDP (mil$) [SIC] 1997
A4: fips_code | B4: geo_name | C4: raw-mil-dollars_gdp-sic_1987 | D4: raw-mil-dollars_gdp-sic_1988 | E4: raw-mil-dollars_gdp-sic_1989 | F4: raw-mil-dollars_gdp-sic_1990 | G4: raw-mil-dollars_gdp-sic_1991 | H4: raw-mil-dollars_gdp-sic_1992 | I4: raw-mil-dollars_gdp-sic_1993 | J4: raw-mil-dollars_gdp-sic_1994 | K4: raw-mil-dollars_gdp-sic_1995 | L4: raw-mil-dollars_gdp-sic_1996 | M4: raw-mil-dollars_gdp-sic_1997
A5: FIPS_CODE | B5: GEO_NAME | C5: 1987 | D5: 1988 | E5: 1989 | F5: 1990 | G5: 1991 | H5: 1992 | I5: 1993 | J5: 1994 | K5: 1995 | L5: 1996 | M5: 1997
A6: US | B6: United States | C6: 6076695 | D6: 6398624 | E6: 6540047 | F6: 6638210 | G6: 6627809 | H6: 6828525 | I6: 6967716 | J6: 7288327 | K6: 7539096 | L6: 7871721 | M6: 8284432
A7: 004 | B7: Arizona | C7: 76600 | D7: 80258 | E7: 80971 | F7: 81606 | G7: 81946 | H7: 90282 | I7: 94916 | J7: 104104 | K7: 112019 | L7: 120869 | M7: 129279

Sheet RealGDP-NAICS
B1: HOVER FOR DETAIL ON SAVING DATA | G1: INFLATION-ADJUSTED DOLLARS (millions) OF GROSS DOMESTIC PRODUCT [NAICS-derived]
A2: Location Codes | B2: Name of Geography | C2: Nominal Gross Domestic Product (millions) [NAICS-derived] 1997 | D2: Nominal Gross Domestic Product (millions) [NAICS-derived] 1998 | E2: Nominal Gross Domestic Product (millions) [NAICS-derived] 1999 | F2: Nominal Gross Domestic Product (millions) [NAICS-derived] 2000 | G2: Nominal Gross Domestic Product (millions) [NAICS-derived] 2001 | H2: Nominal Gross Domestic Product (millions) [NAICS-derived] 2002 | I2: Nominal Gross Domestic Product (millions) [NAICS-derived] 2003 | J2: Nominal Gross Domestic Product (millions) [NAICS-derived] 2004 | K2: Nominal Gross Domestic Product (millions) [NAICS-derived] 2005 | L2: Nominal Gross Domestic Product (millions) [NAICS-derived] 2006 | M2: Nominal Gross Domestic Product (millions) [NAICS-derived] 2007 | N2: Nominal Gross Domestic Product (millions) [NAICS-derived] 2008 | O2: Nominal Gross Domestic Product (millions) [NAICS-derived] 2009 | P2: Nominal Gross Domestic Product (millions) [NAICS-derived] 2010 | Q2: Nominal Gross Domestic Product (millions) [NAICS-derived] 2011 | R2: Nominal Gross Domestic Product (millions) [NAICS-derived] 2012
A3: CodedLocale | B3: Geo Name | C3: Raw GDP (mil$) [NAICS] 1997 | D3: Raw GDP (mil$) [NAICS] 1998 | E3: Raw GDP (mil$) [NAICS] 1999 | F3: Raw GDP (mil$) [NAICS] 2000 | G3: Raw GDP (mil$) [NAICS] 2001 | H3: Raw GDP (mil$) [NAICS] 2002 | I3: Raw GDP (mil$) [NAICS] 2003 | J3: Raw GDP (mil$) [NAICS] 2004 | K3: Raw GDP (mil$) [NAICS] 2005 | L3: Raw GDP (mil$) [NAICS] 2006 | M3: Raw GDP (mil$) [NAICS] 2007 | N3: Raw GDP (mil$) [NAICS] 2008 | O3: Raw GDP (mil$) [NAICS] 2009 | P3: Raw GDP (mil$) [NAICS] 2010 | Q3: Raw GDP (mil$) [NAICS] 2011 | R3: Raw GDP (mil$) [NAICS] 2012
A4: fips_code | B4: geo_name | C4: raw-mil-dollars_gdp-NAICS_1997 | D4: raw-mil-dollars_gdp-NAICS_1998 | E4: raw-mil-dollars_gdp-NAICS_1999 | F4: raw-mil-dollars_gdp-NAICS_2000 | G4: raw-mil-dollars_gdp-NAICS_2001 | H4: raw-mil-dollars_gdp-NAICS_2002 | I4: raw-mil-dollars_gdp-NAICS_2003 | J4: raw-mil-dollars_gdp-NAICS_2004 | K4: raw-mil-dollars_gdp-NAICS_2005 | L4: raw-mil-dollars_gdp-NAICS_2006 | M4: raw-mil-dollars_gdp-NAICS_2007 | N4: raw-mil-dollars_gdp-NAICS_2008 | O4: raw-mil-dollars_gdp-NAICS_2009 | P4: raw-mil-dollars_gdp-NAICS_2010 | Q4: raw-mil-dollars_gdp-NAICS_2011 | R4: raw-mil-dollars_gdp-NAICS_2012
A5: FIPS_CODE | B5: GEO_NAME | C5: 1997 | D5: 1998 | E5: 1999 | F5: 2000 | G5: 2001 | H5: 2002 | I5: 2003 | J5: 2004 | K5: 2005 | L5: 2006 | M5: 2007 | N5: 2008 | O5: 2009 | P5: 2010 | Q5: 2011 | R5: 2012
A6: NA | B6: U.S. Metros | C6: NA | D6: NA | E6: NA | F6: NA | G6: 10191124 | H6: 10366268 | I6: 10582060 | J6: 10942701 | K6: 11263078 | L6: 11581176 | M6: 11801656 | N6: 11722676 | O6: 11273425 | P6: 11623332 | Q6: 11807572
A7: US | B7: United States | C7: 9856166 | D7: 10281034 | E7: 10771147 | F7: 11225406 | G7: 11365110 | H7: 11559801 | I7: 11809034 | J7: 12199532 | K7: 12539116 | L7: 12875816 | M7: 13103341 | N7: 13016791 | O7: 12592668 | P7: 12897088 | Q7: 13108318 | R7: 13430576
A8: 004 | B8: Arizona | C8: 141474 | D8: 154770 | E8: 167704 | F8: 178845 | G8: 185464 | H8: 189985 | I8: 199895 | J8: 207289 | K8: 222569 | L8: 238371 | M8: 243950 | N8: 241134 | O8: 221405 | P8: 221016 | Q8: 224787 | R8: 230641
A9: 22380 | B9: Metro Flagstaff | C9: NA | D9: NA | E9: NA | F9: NA | G9: 3382 | H9: 3499 | I9: 3624 | J9: 3703 | K9: 3900 | L9: 4213 | M9: 4459 | N9: 4535 | O9: 4210 | P9: 4235 | Q9: 4198
A10: 29420 | B10: Metro Lake Havasu City | C10: NA | D10: NA | E10: NA | F10: NA | G10: 2767 | H10: 2916 | I10: 3089 | J10: 3152 | K10: 3408 | L10: 3751 | M10: 3698 | N10: 3576 | O10: 3175 | P10: 3152 | Q10: 3180
A11: 38060 | B11: Metro Phoenix | C11: NA | D11: NA | E11: NA | F11: NA | G11: 138274 | H11: 142462 | I11: 150275 | J11: 156427 | K11: 168571 | L11: 181191 | M11: 185286 | N11: 182729 | O11: 166900 | P11: 169941 | Q11: 173026
A12: 39140 | B12: Metro Prescott | C12: NA | D12: NA | E12: NA | F12: NA | G12: 3353 | H12: 3449 | I12: 3636 | J12: 3698 | K12: 4054 | L12: 4485 | M12: 4454 | N12: 4348 | O12: 3909 | P12: 3734 | Q12: 3708
A13: 46060 | B13: Metro Tucson | C13: NA | D13: NA | E13: NA | F13: NA | G13: 25110 | H13: 24764 | I13: 26141 | J13: 26670 | K13: 28165 | L13: 29512 | M13: 30564 | N13: 30429 | O13: 28165 | P13: 27879 | Q13: 28060
A14: 49740 | B14: Metro Yuma | C14: NA | D14: NA | E14: NA | F14: NA | G14: 3426 | H14: 3849 | I14: 3855 | J14: 4207 | K14: 4358 | L14: 4559 | M14: 4666 | N14: 4604 | O14: 4580 | P14: 4477 | Q14: 4412

Sheet NominalGDPperEmp
B1: HOVER FOR DETAIL ON SAVING DATA | AI1: NOMINAL DOLLARS OF GDP PER EMPLOYEE
A2: Location Codes | B2: Name of Geography | C2: Nominal Gross Domestic Product Per Employee [SIC-derived] 1969 | D2: Nominal Gross Domestic Product Per Employee [SIC-derived] 1970 | E2: Nominal Gross Domestic Product Per Employee [SIC-derived] 1971 | F2: Nominal Gross Domestic Product Per Employee [SIC-derived] 1972 | G2: Nominal Gross Domestic Product Per Employee [SIC-derived] 1973 | H2: Nominal Gross Domestic Product Per Employee [SIC-derived] 1974 | I2: Nominal Gross Domestic Product Per Employee [SIC-derived] 1975 | J2: Nominal Gross Domestic Product Per Employee [SIC-derived] 1976 | K2: Nominal Gross Domestic Product Per Employee [SIC-derived] 1977 | L2: Nominal Gross Domestic Product Per Employee [SIC-derived] 1978 | M2: Nominal Gross Domestic Product Per Employee [SIC-derived] 1979 | N2: Nominal Gross Domestic Product Per Employee [SIC-derived] 1980 | O2: Nominal Gross Domestic Product Per Employee [SIC-derived] 1981 | P2: Nominal Gross Domestic Product Per Employee [SIC-derived] 1982 | Q2: Nominal Gross Domestic Product Per Employee [SIC-derived] 1983 | R2: Nominal Gross Domestic Product Per Employee [SIC-derived] 1984 | S2: Nominal Gross Domestic Product Per Employee [SIC-derived] 1985 | T2: Nominal Gross Domestic Product Per Employee [SIC-derived] 1986 | U2: Nominal Gross Domestic Product Per Employee [SIC-derived] 1987 | V2: Nominal Gross Domestic Product Per Employee [SIC-derived] 1988 | W2: Nominal Gross Domestic Product Per Employee [SIC-derived] 1989 | X2: Nominal Gross Domestic Product Per Employee [SIC-derived] 1990 | Y2: Nominal Gross Domestic Product Per Employee [SIC-derived] 1991 | Z2: Nominal Gross Domestic Product Per Employee [SIC-derived] 1992 | AA2: Nominal Gross Domestic Product Per Employee [SIC-derived] 1993 | AB2: Nominal Gross Domestic Product Per Employee [SIC-derived] 1994 | AC2: Nominal Gross Domestic Product Per Employee [SIC-derived] 1995 | AD2: Nominal Gross Domestic Product Per Employee [SIC-derived] 1996 | AE2: Nominal Gross Domestic Product Per Employee [SIC-derived] 1997 | AF2: Nominal Gross Domestic Product Per Employee [NAICS-derived] 1998 | AG2: Nominal Gross Domestic Product Per Employee [NAICS-derived] 1999 | AH2: Nominal Gross Domestic Product Per Employee [NAICS-derived] 2000 | AI2: Nominal Gross Domestic Product Per Employee [NAICS-derived] 2001 | AJ2: Nominal Gross Domestic Product Per Employee [NAICS-derived] 2002 | AK2: Nominal Gross Domestic Product Per Employee [NAICS-derived] 2003 | AL2: Nominal Gross Domestic Product Per Employee [NAICS-derived] 2004 | AM2: Nominal Gross Domestic Product Per Employee [NAICS-derived] 2005 | AN2: Nominal Gross Domestic Product Per Employee [NAICS-derived] 2006 | AO2: Nominal Gross Domestic Product Per Employee [NAICS-derived] 2007 | AP2: Nominal Gross Domestic Product Per Employee [NAICS-derived] 2008 | AQ2: Nominal Gross Domestic Product Per Employee [NAICS-derived] 2009 | AR2: Nominal Gross Domestic Product Per Employee [NAICS-derived] 2010 | AS2: Nominal Gross Domestic Product Per Employee [NAICS-derived] 2011
A3: CodedLocale | B3: Geo Name | C3: Raw GDP Per Emp [SIC] 1969 | D3: Raw GDP Per Emp [SIC] 1970 | E3: Raw GDP Per Emp [SIC] 1971 | F3: Raw GDP Per Emp [SIC] 1972 | G3: Raw GDP Per Emp [SIC] 1973 | H3: Raw GDP Per Emp [SIC] 1974 | I3: Raw GDP Per Emp [SIC] 1975 | J3: Raw GDP Per Emp [SIC] 1976 | K3: Raw GDP Per Emp [SIC] 1977 | L3: Raw GDP Per Emp [SIC] 1978 | M3: Raw GDP Per Emp [SIC] 1979 | N3: Raw GDP Per Emp [SIC] 1980 | O3: Raw GDP Per Emp [SIC] 1981 | P3: Raw GDP Per Emp [SIC] 1982 | Q3: Raw GDP Per Emp [SIC] 1983 | R3: Raw GDP Per Emp [SIC] 1984 | S3: Raw GDP Per Emp [SIC] 1985 | T3: Raw GDP Per Emp [SIC] 1986 | U3: Raw GDP Per Emp [SIC] 1987 | V3: Raw GDP Per Emp [SIC] 1988 | W3: Raw GDP Per Emp [SIC] 1989 | X3: Raw GDP Per Emp [SIC] 1990 | Y3: Raw GDP Per Emp [SIC] 1991 | Z3: Raw GDP Per Emp [SIC] 1992 | AA3: Raw GDP Per Emp [SIC] 1993 | AB3: Raw GDP Per Emp [SIC] 1994 | AC3: Raw GDP Per Emp [SIC] 1995 | AD3: Raw GDP Per Emp [SIC] 1996 | AE3: Raw GDP Per Emp [SIC] 1997 | AF3: Raw GDP Per Emp [NAICS] 1998 | AG3: Raw GDP Per Emp [NAICS] 1999 | AH3: Raw GDP Per Emp [NAICS] 2000 | AI3: Raw GDP Per Emp [NAICS] 2001 | AJ3: Raw GDP Per Emp [NAICS] 2002 | AK3: Raw GDP Per Emp [NAICS] 2003 | AL3: Raw GDP Per Emp [NAICS] 2004 | AM3: Raw GDP Per Emp [NAICS] 2005 | AN3: Raw GDP Per Emp [NAICS] 2006 | AO3: Raw GDP Per Emp [NAICS] 2007 | AP3: Raw GDP Per Emp [NAICS] 2008 | AQ3: Raw GDP Per Emp [NAICS] 2009 | AR3: Raw GDP Per Emp [NAICS] 2010 | AS3: Raw GDP Per Emp [NAICS] 2011
A4: fips_code | B4: geo_name | C4: raw-dollars_gdp-per-emp-sic_1969 | D4: raw-dollars_gdp-per-emp-sic_1970 | E4: raw-dollars_gdp-per-emp-sic_1971 | F4: raw-dollars_gdp-per-emp-sic_1972 | G4: raw-dollars_gdp-per-emp-sic_1973 | H4: raw-dollars_gdp-per-emp-sic_1974 | I4: raw-dollars_gdp-per-emp-sic_1975 | J4: raw-dollars_gdp-per-emp-sic_1976 | K4: raw-dollars_gdp-per-emp-sic_1977 | L4: raw-dollars_gdp-per-emp-sic_1978 | M4: raw-dollars_gdp-per-emp-sic_1979 | N4: raw-dollars_gdp-per-emp-sic_1980 | O4: raw-dollars_gdp-per-emp-sic_1981 | P4: raw-dollars_gdp-per-emp-sic_1982 | Q4: raw-dollars_gdp-per-emp-sic_1983 | R4: raw-dollars_gdp-per-emp-sic_1984 | S4: raw-dollars_gdp-per-emp-sic_1985 | T4: raw-dollars_gdp-per-emp-sic_1986 | U4: raw-dollars_gdp-per-emp-sic_1987 | V4: raw-dollars_gdp-per-emp-sic_1988 | W4: raw-dollars_gdp-per-emp-sic_1989 | X4: raw-dollars_gdp-per-emp-sic_1990 | Y4: raw-dollars_gdp-per-emp-sic_1991 | Z4: raw-dollars_gdp-per-emp-sic_1992 | AA4: raw-dollars_gdp-per-emp-sic_1993 | AB4: raw-dollars_gdp-per-emp-sic_1994 | AC4: raw-dollars_gdp-per-emp-sic_1995 | AD4: raw-dollars_gdp-per-emp-sic_1996 | AE4: raw-dollars_gdp-per-emp-sic_1997 | AF4: raw-dollars_gdp-per-emp-naics_1998 | AG4: raw-dollars_gdp-per-emp-naics_1999 | AH4: raw-dollars_gdp-per-emp-naics_2000 | AI4: raw-dollars_gdp-per-emp-naics_2001 | AJ4: raw-dollars_gdp-per-emp-naics_2002 | AK4: raw-dollars_gdp-per-emp-naics_2003 | AL4: raw-dollars_gdp-per-emp-naics_2004 | AM4: raw-dollars_gdp-per-emp-naics_2005 | AN4: raw-dollars_gdp-per-emp-naics_2006 | AO4: raw-dollars_gdp-per-emp-naics_2007 | AP4: raw-dollars_gdp-per-emp-naics_2008 | AQ4: raw-dollars_gdp-per-emp-naics_2009 | AR4: raw-dollars_gdp-per-emp-naics_2010 | AS4: raw-dollars_gdp-per-emp-naics_2011
A5: FIPS_CODE | B5: GEO_NAME | C5: 1969 | D5: 1970 | E5: 1971 | F5: 1972 | G5: 1973 | H5: 1974 | I5: 1975 | J5: 1976 | K5: 1977 | L5: 1978 | M5: 1979 | N5: 1980 | O5: 1981 | P5: 1982 | Q5: 1983 | R5: 1984 | S5: 1985 | T5: 1986 | U5: 1987 | V5: 1988 | W5: 1989 | X5: 1990 | Y5: 1991 | Z5: 1992 | AA5: 1993 | AB5: 1994 | AC5: 1995 | AD5: 1996 | AE5: 1997 | AF5: 1998 | AG5: 1999 | AH5: 2000 | AI5: 2001 | AJ5: 2002 | AK5: 2003 | AL5: 2004 | AM5: 2005 | AN5: 2006 | AO5: 2007 | AP5: 2008 | AQ5: 2009 | AR5: 2010 | AS5: 2011
A6: NA | B6: U.S. Metros | C6: NA | D6: NA | E6: NA | F6: NA | G6: NA | H6: NA | I6: NA | J6: NA | K6: NA | L6: NA | M6: NA | N6: NA | O6: NA | P6: NA | Q6: NA | R6: NA | S6: NA | T6: NA | U6: NA | V6: NA | W6: NA | X6: NA | Y6: NA | Z6: NA | AA6: NA | AB6: NA | AC6: NA | AD6: NA | AE6: NA | AF6: NA | AG6: NA | AH6: NA | AI6: =('NominalGDP-NAICS'!G6*1000000.0)/TotalEmployment!AI6 -> 65193.98 | AJ6: =('NominalGDP-NAICS'!H6*1000000.0)/TotalEmployment!AJ6 -> 67645.663 | AK6: =('NominalGDP-NAICS'!I6*1000000.0)/TotalEmployment!AK6 -> 70293.756 | AL6: =('NominalGDP-NAICS'!J6*1000000.0)/TotalEmployment!AL6 -> 73366.092 | AM6: =('NominalGDP-NAICS'!K6*1000000.0)/TotalEmployment!AM6 -> 76600.903 | AN6: =('NominalGDP-NAICS'!L6*1000000.0)/TotalEmployment!AN6 -> 79534.371 | AO6: =('NominalGDP-NAICS'!M6*1000000.0)/TotalEmployment!AO6 -> 81592.957 | AP6: =('NominalGDP-NAICS'!N6*1000000.0)/TotalEmployment!AP6 -> 83069.562 | ... AS6: =('NominalGDP-NAICS'!Q6*1000000.0)/TotalEmployment!AS6 -> 89383.503
A7: US | B7: United States | C7: =('NominalGDP-SIC'!C6*1000000.0)/TotalEmployment!C7 -> 10575.158 | D7: =('NominalGDP-SIC'!D6*1000000.0)/TotalEmployment!D7 -> 11090.333 | E7: =('NominalGDP-SIC'!E6*1000000.0)/TotalEmployment!E7 -> 11980.304 | F7: =('NominalGDP-SIC'!F6*1000000.0)/TotalEmployment!F7 -> 12832.825 | G7: =('NominalGDP-SIC'!G6*1000000.0)/TotalEmployment!G7 -> 13781.718 | H7: =('NominalGDP-SIC'!H6*1000000.0)/TotalEmployment!H7 -> 14703.801 | I7: =('NominalGDP-SIC'!I6*1000000.0)/TotalEmployment!I7 -> 16200.387 | J7: =('NominalGDP-SIC'!J6*1000000.0)/TotalEmployment!J7 -> 17526.095 | ... AE7: =('NominalGDP-SIC'!AE6*1000000.0)/TotalEmployment!AE7 -> 53606.624 | AF7: =('NominalGDP-NAICS'!D7*1000000.0)/TotalEmployment!AF7 -> 55066.614 | AG7: =('NominalGDP-NAICS'!E7*1000000.0)/TotalEmployment!AG7 -> 57492.622 | AH7: =('NominalGDP-NAICS'!F7*1000000.0)/TotalEmployment!AH7 -> 59769.748 | AI7: =('NominalGDP-NAICS'!G7*1000000.0)/TotalEmployment!AI7 -> 61736.491 | AJ7: =('NominalGDP-NAICS'!H7*1000000.0)/TotalEmployment!AJ7 -> 64050.584 | AK7: =('NominalGDP-NAICS'!I7*1000000.0)/TotalEmployment!AK7 -> 66665.837 | AL7: =('NominalGDP-NAICS'!J7*1000000.0)/TotalEmployment!AL7 -> 69660.06 | AM7: =('NominalGDP-NAICS'!K7*1000000.0)/TotalEmployment!AM7 -> 72668.874 | ... AS7: =('NominalGDP-NAICS'!Q7*1000000.0)/TotalEmployment!AS7 -> 85078.645
A8: 004 | B8: Arizona | C8: =('NominalGDP-SIC'!C7*1000000.0)/TotalEmployment!C8 -> 10631.987 | D8: =('NominalGDP-SIC'!D7*1000000.0)/TotalEmployment!D8 -> 11476.549 | E8: =('NominalGDP-SIC'!E7*1000000.0)/TotalEmployment!E8 -> 12280.284 | F8: =('NominalGDP-SIC'!F7*1000000.0)/TotalEmployment!F8 -> 13289.302 | G8: =('NominalGDP-SIC'!G7*1000000.0)/TotalEmployment!G8 -> 14412.525 | H8: =('NominalGDP-SIC'!H7*1000000.0)/TotalEmployment!H8 -> 15297.811 | I8: =('NominalGDP-SIC'!I7*1000000.0)/TotalEmployment!I8 -> 16345.3 | J8: =('NominalGDP-SIC'!J7*1000000.0)/TotalEmployment!J8 -> 17385.193 | ... AE8: =('NominalGDP-SIC'!AE7*1000000.0)/TotalEmployment!AE8 -> 51770.287 | AF8: =('NominalGDP-NAICS'!D8*1000000.0)/TotalEmployment!AF8 -> 53344.671 | AG8: =('NominalGDP-NAICS'!E8*1000000.0)/TotalEmployment!AG8 -> 55946.576 | AH8: =('NominalGDP-NAICS'!F8*1000000.0)/TotalEmployment!AH8 -> 57870.283 | AI8: =('NominalGDP-NAICS'!G8*1000000.0)/TotalEmployment!AI8 -> 60212.818 | AJ8: =('NominalGDP-NAICS'!H8*1000000.0)/TotalEmployment!AJ8 -> 62314.141 | AK8: =('NominalGDP-NAICS'!I8*1000000.0)/TotalEmployment!AK8 -> 64876.974 | AL8: =('NominalGDP-NAICS'!J8*1000000.0)/TotalEmployment!AL8 -> 66121.917 | AM8: =('NominalGDP-NAICS'!K8*1000000.0)/TotalEmployment!AM8 -> 69374.109 | ... AS8: =('NominalGDP-NAICS'!Q8*1000000.0)/TotalEmployment!AS8 -> 79314.95
A9: 22380 | B9: Metro Flagstaff | C9: NA | D9: NA | E9: NA | F9: NA | G9: NA | H9: NA | I9: NA | J9: NA | K9: NA | L9: NA | M9: NA | N9: NA | O9: NA | P9: NA | Q9: NA | R9: NA | S9: NA | T9: NA | U9: NA | V9: NA | W9: NA | X9: NA | Y9: NA | Z9: NA | AA9: NA | AB9: NA | AC9: NA | AD9: NA | AE9: NA | AF9: NA | AG9: NA | AH9: NA | AI9: =('NominalGDP-NAICS'!G9*1000000.0)/TotalEmployment!AI9 -> 42611.32 | AJ9: =('NominalGDP-NAICS'!H9*1000000.0)/TotalEmployment!AJ9 -> 44719.006 | AK9: =('NominalGDP-NAICS'!I9*1000000.0)/TotalEmployment!AK9 -> 46109.077 | AL9: =('NominalGDP-NAICS'!J9*1000000.0)/TotalEmployment!AL9 -> 46216.367 | AM9: =('NominalGDP-NAICS'!K9*1000000.0)/TotalEmployment!AM9 -> 49161.729 | AN9: =('NominalGDP-NAICS'!L9*1000000.0)/TotalEmployment!AN9 -> 53172.949 | AO9: =('NominalGDP-NAICS'!M9*1000000.0)/TotalEmployment!AO9 -> 55746.851 | AP9: =('NominalGDP-NAICS'!N9*1000000.0)/TotalEmployment!AP9 -> 58904.871 | ... AS9: =('NominalGDP-NAICS'!Q9*1000000.0)/TotalEmployment!AS9 -> 59770.452
A10: 29420 | B10: Metro Lake Havasu City | C10: NA | D10: NA | E10: NA | F10: NA | G10: NA | H10: NA | I10: NA | J10: NA | K10: NA | L10: NA | M10: NA | N10: NA | O10: NA | P10: NA | Q10: NA | R10: NA | S10: NA | T10: NA | U10: NA | V10: NA | W10: NA | X10: NA | Y10: NA | Z10: NA | AA10: NA | AB10: NA | AC10: NA | AD10: NA | AE10: NA | AF10: NA | AG10: NA | AH10: NA | AI10: =('NominalGDP-NAICS'!G10*1000000.0)/TotalEmployment!AI10 -> 43455.731 | AJ10: =('NominalGDP-NAICS'!H10*1000000.0)/TotalEmployment!AJ10 -> 45128.964 | AK10: =('NominalGDP-NAICS'!I10*1000000.0)/TotalEmployment!AK10 -> 46246.052 | AL10: =('NominalGDP-NAICS'!J10*1000000.0)/TotalEmployment!AL10 -> 45901.49 | AM10: =('NominalGDP-NAICS'!K10*1000000.0)/TotalEmployment!AM10 -> 48307.535 | AN10: =('NominalGDP-NAICS'!L10*1000000.0)/TotalEmployment!AN10 -> 52733.136 | AO10: =('NominalGDP-NAICS'!M10*1000000.0)/TotalEmployment!AO10 -> 53641.759 | AP10: =('NominalGDP-NAICS'!N10*1000000.0)/TotalEmployment!AP10 -> 56895.28 | ... AS10: =('NominalGDP-NAICS'!Q10*1000000.0)/TotalEmployment!AS10 -> 59471.083
A11: 38060 | B11: Metro Phoenix | C11: NA | D11: NA | E11: NA | F11: NA | G11: NA | H11: NA | I11: NA | J11: NA | K11: NA | L11: NA | M11: NA | N11: NA | O11: NA | P11: NA | Q11: NA | R11: NA | S11: NA | T11: NA | U11: NA | V11: NA | W11: NA | X11: NA | Y11: NA | Z11: NA | AA11: NA | AB11: NA | AC11: NA | AD11: NA | AE11: NA | AF11: NA | AG11: NA | AH11: NA | AI11: =('NominalGDP-NAICS'!G11*1000000.0)/TotalEmployment!AI11 -> 65822.981 | AJ11: =('NominalGDP-NAICS'!H11*1000000.0)/TotalEmployment!AJ11 -> 68385.118 | AK11: =('NominalGDP-NAICS'!I11*1000000.0)/TotalEmployment!AK11 -> 71161.563 | AL11: =('NominalGDP-NAICS'!J11*1000000.0)/TotalEmployment!AL11 -> 72560.159 | AM11: =('NominalGDP-NAICS'!K11*1000000.0)/TotalEmployment!AM11 -> 75625.781 | AN11: =('NominalGDP-NAICS'!L11*1000000.0)/TotalEmployment!AN11 -> 79504.243 | AO11: =('NominalGDP-NAICS'!M11*1000000.0)/TotalEmployment!AO11 -> 81277.418 | AP11: =('NominalGDP-NAICS'!N11*1000000.0)/TotalEmployment!AP11 -> 82573.973 | ... AS11: =('NominalGDP-NAICS'!Q11*1000000.0)/TotalEmployment!AS11 -> 86369.606
A12: 39140 | B12: Metro Prescott | C12: NA | D12: NA | E12: NA | F12: NA | G12: NA | H12: NA | I12: NA | J12: NA | K12: NA | L12: NA | M12: NA | N12: NA | O12: NA | P12: NA | Q12: NA | R12: NA | S12: NA | T12: NA | U12: NA | V12: NA | W12: NA | X12: NA | Y12: NA | Z12: NA | AA12: NA | AB12: NA | AC12: NA | AD12: NA | AE12: NA | AF12: NA | AG12: NA | AH12: NA | AI12: =('NominalGDP-NAICS'!G12*1000000.0)/TotalEmployment!AI12 -> 41016.231 | AJ12: =('NominalGDP-NAICS'!H12*1000000.0)/TotalEmployment!AJ12 -> 41942.605 | AK12: =('NominalGDP-NAICS'!I12*1000000.0)/TotalEmployment!AK12 -> 43971.217 | AL12: =('NominalGDP-NAICS'!J12*1000000.0)/TotalEmployment!AL12 -> 44212.249 | AM12: =('NominalGDP-NAICS'!K12*1000000.0)/TotalEmployment!AM12 -> 48012.696 | AN12: =('NominalGDP-NAICS'!L12*1000000.0)/TotalEmployment!AN12 -> 51911.42 | AO12: =('NominalGDP-NAICS'!M12*1000000.0)/TotalEmployment!AO12 -> 51781.214 | AP12: =('NominalGDP-NAICS'!N12*1000000.0)/TotalEmployment!AP12 -> 55399.114 | ... AS12: =('NominalGDP-NAICS'!Q12*1000000.0)/TotalEmployment!AS12 -> 55326.53
A13: 46060 | B13: Metro Tucson | C13: NA | D13: NA | E13: NA | F13: NA | G13: NA | H13: NA | I13: NA | J13: NA | K13: NA | L13: NA | M13: NA | N13: NA | O13: NA | P13: NA | Q13: NA | R13: NA | S13: NA | T13: NA | U13: NA | V13: NA | W13: NA | X13: NA | Y13: NA | Z13: NA | AA13: NA | AB13: NA | AC13: NA | AD13: NA | AE13: NA | AF13: NA | AG13: NA | AH13: NA | AI13: =('NominalGDP-NAICS'!G13*1000000.0)/TotalEmployment!AI13 -> 51435.328 | AJ13: =('NominalGDP-NAICS'!H13*1000000.0)/TotalEmployment!AJ13 -> 51890.625 | AK13: =('NominalGDP-NAICS'!I13*1000000.0)/TotalEmployment!AK13 -> 54954.618 | AL13: =('NominalGDP-NAICS'!J13*1000000.0)/TotalEmployment!AL13 -> 55269.939 | AM13: =('NominalGDP-NAICS'!K13*1000000.0)/TotalEmployment!AM13 -> 58630.179 | AN13: =('NominalGDP-NAICS'!L13*1000000.0)/TotalEmployment!AN13 -> 60951.911 | AO13: =('NominalGDP-NAICS'!M13*1000000.0)/TotalEmployment!AO13 -> 63035.714 | AP13: =('NominalGDP-NAICS'!N13*1000000.0)/TotalEmployment!AP13 -> 65553.705 | ... AS13: =('NominalGDP-NAICS'!Q13*1000000.0)/TotalEmployment!AS13 -> 67462.122
A14: 49740 | B14: Metro Yuma | C14: NA | D14: NA | E14: NA | F14: NA | G14: NA | H14: NA | I14: NA | J14: NA | K14: NA | L14: NA | M14: NA | N14: NA | O14: NA | P14: NA | Q14: NA | R14: NA | S14: NA | T14: NA | U14: NA | V14: NA | W14: NA | X14: NA | Y14: NA | Z14: NA | AA14: NA | AB14: NA | AC14: NA | AD14: NA | AE14: NA | AF14: NA | AG14: NA | AH14: NA | AI14: =('NominalGDP-NAICS'!G14*1000000.0)/TotalEmployment!AI14 -> 43631.587 | AJ14: =('NominalGDP-NAICS'!H14*1000000.0)/TotalEmployment!AJ14 -> 48117.417 | AK14: =('NominalGDP-NAICS'!I14*1000000.0)/TotalEmployment!AK14 -> 49054.454 | AL14: =('NominalGDP-NAICS'!J14*1000000.0)/TotalEmployment!AL14 -> 53828.138 | AM14: =('NominalGDP-NAICS'!K14*1000000.0)/TotalEmployment!AM14 -> 54876.283 | AN14: =('NominalGDP-NAICS'!L14*1000000.0)/TotalEmployment!AN14 -> 56885.901 | AO14: =('NominalGDP-NAICS'!M14*1000000.0)/TotalEmployment!AO14 -> 60743.979 | AP14: =('NominalGDP-NAICS'!N14*1000000.0)/TotalEmployment!AP14 -> 61890.152 | ... AS14: =('NominalGDP-NAICS'!Q14*1000000.0)/TotalEmployment!AS14 -> 66191.56

Sheet NominalGDPperCap
B1: HOVER FOR DETAIL ON SAVING DATA | AE1: CURRENT DOLLARS OF GDP PER CAPITA
A2: Location Codes | B2: Name of Geography | C2: Nominal Gross Domestic Product Per Capita [SIC-derived] 1969 | D2: Nominal Gross Domestic Product Per Capita [SIC-derived] 1970 | E2: Nominal Gross Domestic Product Per Capita [SIC-derived] 1971 | F2: Nominal Gross Domestic Product Per Capita [SIC-derived] 1972 | G2: Nominal Gross Domestic Product Per Capita [SIC-derived] 1973 | H2: Nominal Gross Domestic Product Per Capita [SIC-derived] 1974 | I2: Nominal Gross Domestic Product Per Capita [SIC-derived] 1975 | J2: Nominal Gross Domestic Product Per Capita [SIC-derived] 1976 | K2: Nominal Gross Domestic Product Per Capita [SIC-derived] 1977 | L2: Nominal Gross Domestic Product Per Capita [SIC-derived] 1978 | M2: Nominal Gross Domestic Product Per Capita [SIC-derived] 1979 | N2: Nominal Gross Domestic Product Per Capita [SIC-derived] 1980 | O2: Nominal Gross Domestic Product Per Capita [SIC-derived] 1981 | P2: Nominal Gross Domestic Product Per Capita [SIC-derived] 1982 | Q2: Nominal Gross Domestic Product Per Capita [SIC-derived] 1983 | R2: Nominal Gross Domestic Product Per Capita [SIC-derived] 1984 | S2: Nominal Gross Domestic Product Per Capita [SIC-derived] 1985 | T2: Nominal Gross Domestic Product Per Capita [SIC-derived] 1986 | U2: Nominal Gross Domestic Product Per Capita [SIC-derived] 1987 | V2: Nominal Gross Domestic Product Per Capita [SIC-derived] 1988 | W2: Nominal Gross Domestic Product Per Capita [SIC-derived] 1989 | X2: Nominal Gross Domestic Product Per Capita [SIC-derived] 1990 | Y2: Nominal Gross Domestic Product Per Capita [SIC-derived] 1991 | Z2: Nominal Gross Domestic Product Per Capita [SIC-derived] 1992 | AA2: Nominal Gross Domestic Product Per Capita [SIC-derived] 1993 | AB2: Nominal Gross Domestic Product Per Capita [SIC-derived] 1994 | AC2: Nominal Gross Domestic Product Per Capita [SIC-derived] 1995 | AD2: Nominal Gross Domestic Product Per Capita [SIC-derived] 1996 | AE2: Nominal Gross Domestic Product Per Capita [SIC-derived] 1997 | AF2: Nominal Gross Domestic Product Per Capita [NAICS-derived] 1998 | AG2: Nominal Gross Domestic Product Per Capita [NAICS-derived] 1999 | AH2: Nominal Gross Domestic Product Per Capita [NAICS-derived] 2000 | AI2: Nominal Gross Domestic Product Per Capita [NAICS-derived] 2001 | AJ2: Nominal Gross Domestic Product Per Capita [NAICS-derived] 2002 | AK2: Nominal Gross Domestic Product Per Capita [NAICS-derived] 2003 | AL2: Nominal Gross Domestic Product Per Capita [NAICS-derived] 2004 | AM2: Nominal Gross Domestic Product Per Capita [NAICS-derived] 2005 | AN2: Nominal Gross Domestic Product Per Capita [NAICS-derived] 2006 | AO2: Nominal Gross Domestic Product Per Capita [NAICS-derived] 2007 | AP2: Nominal Gross Domestic Product Per Capita [NAICS-derived] 2008 | AQ2: Nominal Gross Domestic Product Per Capita [NAICS-derived] 2009 | AR2: Nominal Gross Domestic Product Per Capita [NAICS-derived] 2010 | AS2: Nominal Gross Domestic Product Per Capita [NAICS-derived] 2011
A3: CodedLocale | B3: Geo Name | C3: Raw GDP Per Cap [SIC] 1969 | D3: Raw GDP Per Cap [SIC] 1970 | E3: Raw GDP Per Cap [SIC] 1971 | F3: Raw GDP Per Cap [SIC] 1972 | G3: Raw GDP Per Cap [SIC] 1973 | H3: Raw GDP Per Cap [SIC] 1974 | I3: Raw GDP Per Cap [SIC] 1975 | J3: Raw GDP Per Cap [SIC] 1976 | K3: Raw GDP Per Cap [SIC] 1977 | L3: Raw GDP Per Cap [SIC] 1978 | M3: Raw GDP Per Cap [SIC] 1979 | N3: Raw GDP Per Cap [SIC] 1980 | O3: Raw GDP Per Cap [SIC] 1981 | P3: Raw GDP Per Cap [SIC] 1982 | Q3: Raw GDP Per Cap [SIC] 1983 | R3: Raw GDP Per Cap [SIC] 1984 | S3: Raw GDP Per Cap [SIC] 1985 | T3: Raw GDP Per Cap [SIC] 1986 | U3: Raw GDP Per Cap [SIC] 1987 | V3: Raw GDP Per Cap [SIC] 1988 | W3: Raw GDP Per Cap [SIC] 1989 | X3: Raw GDP Per Cap [SIC] 1990 | Y3: Raw GDP Per Cap [SIC] 1991 | Z3: Raw GDP Per Cap [SIC] 1992 | AA3: Raw GDP Per Cap [SIC] 1993 | AB3: Raw GDP Per Cap [SIC] 1994 | AC3: Raw GDP Per Cap [SIC] 1995 | AD3: Raw GDP Per Cap [SIC] 1996 | AE3: Raw GDP Per Cap [SIC] 1997 | AF3: Raw GDP Per Cap [NAICS] 1998 | AG3: Raw GDP Per Cap [NAICS] 1999 | AH3: Raw GDP Per Cap [NAICS] 2000 | AI3: Raw GDP Per Cap [NAICS] 2001 | AJ3: Raw GDP Per Cap [NAICS] 2002 | AK3: Raw GDP Per Cap [NAICS] 2003 | AL3: Raw GDP Per Cap [NAICS] 2004 | AM3: Raw GDP Per Cap [NAICS] 2005 | AN3: Raw GDP Per Cap [NAICS] 2006 | AO3: Raw GDP Per Cap [NAICS] 2007 | AP3: Raw GDP Per Cap [NAICS] 2008 | AQ3: Raw GDP Per Cap [NAICS] 2009 | AR3: Raw GDP Per Cap [NAICS] 2010 | AS3: Raw GDP Per Cap [NAICS] 2011
A4: fips_code | B4: geo_name | C4: raw-dollars_gdp-per-cap-sic_1969 | D4: raw-dollars_gdp-per-cap-sic_1970 | E4: raw-dollars_gdp-per-cap-sic_1971 | F4: raw-dollars_gdp-per-cap-sic_1972 | G4: raw-dollars_gdp-per-cap-sic_1973 | H4: raw-dollars_gdp-per-cap-sic_1974 | I4: raw-dollars_gdp-per-cap-sic_1975 | J4: raw-dollars_gdp-per-cap-sic_1976 | K4: raw-dollars_gdp-per-cap-sic_1977 | L4: raw-dollars_gdp-per-cap-sic_1978 | M4: raw-dollars_gdp-per-cap-sic_1979 | N4: raw-dollars_gdp-per-cap-sic_1980 | O4: raw-dollars_gdp-per-cap-sic_1981 | P4: raw-dollars_gdp-per-cap-sic_1982 | Q4: raw-dollars_gdp-per-cap-sic_1983 | R4: raw-dollars_gdp-per-cap-sic_1984 | S4: raw-dollars_gdp-per-cap-sic_1985 | T4: raw-dollars_gdp-per-cap-sic_1986 | U4: raw-dollars_gdp-per-cap-sic_1987 | V4: raw-dollars_gdp-per-cap-sic_1988 | W4: raw-dollars_gdp-per-cap-sic_1989 | X4: raw-dollars_gdp-per-cap-sic_1990 | Y4: raw-dollars_gdp-per-cap-sic_1991 | Z4: raw-dollars_gdp-per-cap-sic_1992 | AA4: raw-dollars_gdp-per-cap-sic_1993 | AB4: raw-dollars_gdp-per-cap-sic_1994 | AC4: raw-dollars_gdp-per-cap-sic_1995 | AD4: raw-dollars_gdp-per-cap-sic_1996 | AE4: raw-dollars_gdp-per-cap-sic_1997 | AF4: raw-dollars_gdp-per-cap-naics_1998 | AG4: raw-dollars_gdp-per-cap-naics_1999 | AH4: raw-dollars_gdp-per-cap-naics_2000 | AI4: raw-dollars_gdp-per-cap-naics_2001 | AJ4: raw-dollars_gdp-per-cap-naics_2002 | AK4: raw-dollars_gdp-per-cap-naics_2003 | AL4: raw-dollars_gdp-per-cap-naics_2004 | AM4: raw-dollars_gdp-per-cap-naics_2005 | AN4: raw-dollars_gdp-per-cap-naics_2006 | AO4: raw-dollars_gdp-per-cap-naics_2007 | AP4: raw-dollars_gdp-per-cap-naics_2008 | AQ4: raw-dollars_gdp-per-cap-naics_2009 | AR4: raw-dollars_gdp-per-cap-naics_2010 | AS4: raw-dollars_gdp-per-cap-naics_2011
A5: FIPS_CODE | B5: GEO_NAME | C5: 1969 | D5: 1970 | E5: 1971 | F5: 1972 | G5: 1973 | H5: 1974 | I5: 1975 | J5: 1976 | K5: 1977 | L5: 1978 | M5: 1979 | N5: 1980 | O5: 1981 | P5: 1982 | Q5: 1983 | R5: 1984 | S5: 1985 | T5: 1986 | U5: 1987 | V5: 1988 | W5: 1989 | X5: 1990 | Y5: 1991 | Z5: 1992 | AA5: 1993 | AB5: 1994 | AC5: 1995 | AD5: 1996 | AE5: 1997 | AF5: 1998 | AG5: 1999 | AH5: 2000 | AI5: 2001 | AJ5: 2002 | AK5: 2003 | AL5: 2004 | AM5: 2005 | AN5: 2006 | AO5: 2007 | AP5: 2008 | AQ5: 2009 | AR5: 2010 | AS5: 2011
A6: NA | B6: U.S. Metros | C6: NA | D6: NA | E6: NA | F6: NA | G6: NA | H6: NA | I6: NA | J6: NA | K6: NA | L6: NA | M6: NA | N6: NA | O6: NA | P6: NA | Q6: NA | R6: NA | S6: NA | T6: NA | U6: NA | V6: NA | W6: NA | X6: NA | Y6: NA | Z6: NA | AA6: NA | AB6: NA | AC6: NA | AD6: NA | AE6: NA | AF6: NA | AG6: NA | AH6: NA | AI6: =('NominalGDP-NAICS'!G6*1000000.0)/TotalPopulation!AI6 -> 38793.015 | AJ6: =('NominalGDP-NAICS'!H6*1000000.0)/TotalPopulation!AJ6 -> 39731.745 | AK6: =('NominalGDP-NAICS'!I6*1000000.0)/TotalPopulation!AK6 -> 41148.384 | AL6: =('NominalGDP-NAICS'!J6*1000000.0)/TotalPopulation!AL6 -> 43321.063 | AM6: =('NominalGDP-NAICS'!K6*1000000.0)/TotalPopulation!AM6 -> 45750.176 | AN6: =('NominalGDP-NAICS'!L6*1000000.0)/TotalPopulation!AN6 -> 48047.303 | AO6: =('NominalGDP-NAICS'!M6*1000000.0)/TotalPopulation!AO6 -> 49884.17 | AP6: =('NominalGDP-NAICS'!N6*1000000.0)/TotalPopulation!AP6 -> 50229.719 | ... AS6: =('NominalGDP-NAICS'!Q6*1000000.0)/TotalPopulation!AS6 -> 51493.99
A7: US | B7: United States | C7: =('NominalGDP-SIC'!C6*1000000.0)/TotalPopulation!C7 -> 4783.4653 | D7: =('NominalGDP-SIC'!D6*1000000.0)/TotalPopulation!D7 -> 4967.1509 | E7: =('NominalGDP-SIC'!E6*1000000.0)/TotalPopulation!E7 -> 5305.0296 | F7: =('NominalGDP-SIC'!F6*1000000.0)/TotalPopulation!F7 -> 5783.2645 | G7: =('NominalGDP-SIC'!G6*1000000.0)/TotalPopulation!G7 -> 6418.2877 | H7: =('NominalGDP-SIC'!H6*1000000.0)/TotalPopulation!H7 -> 6900.1027 | I7: =('NominalGDP-SIC'!I6*1000000.0)/TotalPopulation!I7 -> 7436.4309 | J7: =('NominalGDP-SIC'!J6*1000000.0)/TotalPopulation!J7 -> 8184.1665 | ... AE7: =('NominalGDP-SIC'!AE6*1000000.0)/TotalPopulation!AE7 -> 30385.202 | AF7: =('NominalGDP-NAICS'!D7*1000000.0)/TotalPopulation!AF7 -> 31636.372 | AG7: =('NominalGDP-NAICS'!E7*1000000.0)/TotalPopulation!AG7 -> 33281.438 | AH7: =('NominalGDP-NAICS'!F7*1000000.0)/TotalPopulation!AH7 -> 35030.077 | AI7: =('NominalGDP-NAICS'!G7*1000000.0)/TotalPopulation!AI7 -> 35856.604 | AJ7: =('NominalGDP-NAICS'!H7*1000000.0)/TotalPopulation!AJ7 -> 36757.517 | AK7: =('NominalGDP-NAICS'!I7*1000000.0)/TotalPopulation!AK7 -> 38150.729 | AL7: =('NominalGDP-NAICS'!J7*1000000.0)/TotalPopulation!AL7 -> 40212.421 | AM7: =('NominalGDP-NAICS'!K7*1000000.0)/TotalPopulation!AM7 -> 42431.173 | ... AS7: =('NominalGDP-NAICS'!Q7*1000000.0)/TotalPopulation!AS7 -> 48010.803
A8: 004 | B8: Arizona | C8: =('NominalGDP-SIC'!C7*1000000.0)/TotalPopulation!C8 -> 4354.0587 | D8: =('NominalGDP-SIC'!D7*1000000.0)/TotalPopulation!D8 -> 4774.0502 | E8: =('NominalGDP-SIC'!E7*1000000.0)/TotalPopulation!E8 -> 5088.8452 | F8: =('NominalGDP-SIC'!F7*1000000.0)/TotalPopulation!F8 -> 5621.1349 | G8: =('NominalGDP-SIC'!G7*1000000.0)/TotalPopulation!G8 -> 6272.1118 | H8: =('NominalGDP-SIC'!H7*1000000.0)/TotalPopulation!H8 -> 6568.6841 | I8: =('NominalGDP-SIC'!I7*1000000.0)/TotalPopulation!I8 -> 6684.8966 | J8: =('NominalGDP-SIC'!J7*1000000.0)/TotalPopulation!J8 -> 7227.5015 | ... AE8: =('NominalGDP-SIC'!AE7*1000000.0)/TotalPopulation!AE8 -> 27291.381 | AF8: =('NominalGDP-NAICS'!D8*1000000.0)/TotalPopulation!AF8 -> 28520.632 | AG8: =('NominalGDP-NAICS'!E8*1000000.0)/TotalPopulation!AG8 -> 30032.109 | AH8: =('NominalGDP-NAICS'!F8*1000000.0)/TotalPopulation!AH8 -> 31351.478 | AI8: =('NominalGDP-NAICS'!G8*1000000.0)/TotalPopulation!AI8 -> 32238.313 | AJ8: =('NominalGDP-NAICS'!H8*1000000.0)/TotalPopulation!AJ8 -> 32813.127 | AK8: =('NominalGDP-NAICS'!I8*1000000.0)/TotalPopulation!AK8 -> 34309.893 | AL8: =('NominalGDP-NAICS'!J8*1000000.0)/TotalPopulation!AL8 -> 35561.152 | AM8: =('NominalGDP-NAICS'!K8*1000000.0)/TotalPopulation!AM8 -> 38117.154 | ... AS8: =('NominalGDP-NAICS'!Q8*1000000.0)/TotalPopulation!AS8 -> 39489.21
A9: 22380 | B9: Metro Flagstaff | C9: NA | D9: NA | E9: NA | F9: NA | G9: NA | H9: NA | I9: NA | J9: NA | K9: NA | L9: NA | M9: NA | N9: NA | O9: NA | P9: NA | Q9: NA | R9: NA | S9: NA | T9: NA | U9: NA | V9: NA | W9: NA | X9: NA | Y9: NA | Z9: NA | AA9: NA | AB9: NA | AC9: NA | AD9: NA | AE9: NA | AF9: NA | AG9: NA | AH9: NA | AI9: =('NominalGDP-NAICS'!G9*1000000.0)/TotalPopulation!AI9 -> 25185.361 | AJ9: =('NominalGDP-NAICS'!H9*1000000.0)/TotalPopulation!AJ9 -> 26107.099 | AK9: =('NominalGDP-NAICS'!I9*1000000.0)/TotalPopulation!AK9 -> 27465.373 | AL9: =('NominalGDP-NAICS'!J9*1000000.0)/TotalPopulation!AL9 -> 28541.285 | AM9: =('NominalGDP-NAICS'!K9*1000000.0)/TotalPopulation!AM9 -> 30702.618 | AN9: =('NominalGDP-NAICS'!L9*1000000.0)/TotalPopulation!AN9 -> 33901.861 | AO9: =('NominalGDP-NAICS'!M9*1000000.0)/TotalPopulation!AO9 -> 36613.974 | AP9: =('NominalGDP-NAICS'!N9*1000000.0)/TotalPopulation!AP9 -> 37799.671 | ... AS9: =('NominalGDP-NAICS'!Q9*1000000.0)/TotalPopulation!AS9 -> 36353.904
A10: 29420 | B10: Metro Lake Havasu City | C10: NA | D10: NA | E10: NA | F10: NA | G10: NA | H10: NA | I10: NA | J10: NA | K10: NA | L10: NA | M10: NA | N10: NA | O10: NA | P10: NA | Q10: NA | R10: NA | S10: NA | T10: NA | U10: NA | V10: NA | W10: NA | X10: NA | Y10: NA | Z10: NA | AA10: NA | AB10: NA | AC10: NA | AD10: NA | AE10: NA | AF10: NA | AG10: NA | AH10: NA | AI10: =('NominalGDP-NAICS'!G10*1000000.0)/TotalPopulation!AI10 -> 15170.418 | AJ10: =('NominalGDP-NAICS'!H10*1000000.0)/TotalPopulation!AJ10 -> 15774.427 | AK10: =('NominalGDP-NAICS'!I10*1000000.0)/TotalPopulation!AK10 -> 16537.974 | AL10: =('NominalGDP-NAICS'!J10*1000000.0)/TotalPopulation!AL10 -> 16757.053 | AM10: =('NominalGDP-NAICS'!K10*1000000.0)/TotalPopulation!AM10 -> 18053.429 | AN10: =('NominalGDP-NAICS'!L10*1000000.0)/TotalPopulation!AN10 -> 19921.7 | AO10: =('NominalGDP-NAICS'!M10*1000000.0)/TotalPopulation!AO10 -> 19908.891 | AP10: =('NominalGDP-NAICS'!N10*1000000.0)/TotalPopulation!AP10 -> 19657.334 | ... AS10: =('NominalGDP-NAICS'!Q10*1000000.0)/TotalPopulation!AS10 -> 18314.711
A11: 38060 | B11: Metro Phoenix | C11: NA | D11: NA | E11: NA | F11: NA | G11: NA | H11: NA | I11: NA | J11: NA | K11: NA | L11: NA | M11: NA | N11: NA | O11: NA | P11: NA | Q11: NA | R11: NA | S11: NA | T11: NA | U11: NA | V11: NA | W11: NA | X11: NA | Y11: NA | Z11: NA | AA11: NA | AB11: NA | AC11: NA | AD11: NA | AE11: NA | AF11: NA | AG11: NA | AH11: NA | AI11: =('NominalGDP-NAICS'!G11*1000000.0)/TotalPopulation!AI11 -> 38121.601 | AJ11: =('NominalGDP-NAICS'!H11*1000000.0)/TotalPopulation!AJ11 -> 38834.805 | AK11: =('NominalGDP-NAICS'!I11*1000000.0)/TotalPopulation!AK11 -> 40432.498 | AL11: =('NominalGDP-NAICS'!J11*1000000.0)/TotalPopulation!AL11 -> 41808.391 | AM11: =('NominalGDP-NAICS'!K11*1000000.0)/TotalPopulation!AM11 -> 44658.166 | AN11: =('NominalGDP-NAICS'!L11*1000000.0)/TotalPopulation!AN11 -> 47667.321 | AO11: =('NominalGDP-NAICS'!M11*1000000.0)/TotalPopulation!AO11 -> 48719.951 | AP11: =('NominalGDP-NAICS'!N11*1000000.0)/TotalPopulation!AP11 -> 47818.366 | ... AS11: =('NominalGDP-NAICS'!Q11*1000000.0)/TotalPopulation!AS11 -> 45691.348
A12: 39140 | B12: Metro Prescott | C12: NA | D12: NA | E12: NA | F12: NA | G12: NA | H12: NA | I12: NA | J12: NA | K12: NA | L12: NA | M12: NA | N12: NA | O12: NA | P12: NA | Q12: NA | R12: NA | S12: NA | T12: NA | U12: NA | V12: NA | W12: NA | X12: NA | Y12: NA | Z12: NA | AA12: NA | AB12: NA | AC12: NA | AD12: NA | AE12: NA | AF12: NA | AG12: NA | AH12: NA | AI12: =('NominalGDP-NAICS'!G12*1000000.0)/TotalPopulation!AI12 -> 16833.105 | AJ12: =('NominalGDP-NAICS'!H12*1000000.0)/TotalPopulation!AJ12 -> 17247.212 | AK12: =('NominalGDP-NAICS'!I12*1000000.0)/TotalPopulation!AK12 -> 18188.808 | AL12: =('NominalGDP-NAICS'!J12*1000000.0)/TotalPopulation!AL12 -> 18698.555 | AM12: =('NominalGDP-NAICS'!K12*1000000.0)/TotalPopulation!AM12 -> 20744.637 | AN12: =('NominalGDP-NAICS'!L12*1000000.0)/TotalPopulation!AN12 -> 22995.659 | AO12: =('NominalGDP-NAICS'!M12*1000000.0)/TotalPopulation!AO12 -> 23226.183 | AP12: =('NominalGDP-NAICS'!N12*1000000.0)/TotalPopulation!AP12 -> 23100.123 | ... AS12: =('NominalGDP-NAICS'!Q12*1000000.0)/TotalPopulation!AS12 -> 20775.126
A13: 46060 | B13: Metro Tucson | C13: NA | D13: NA | E13: NA | F13: NA | G13: NA | H13: NA | I13: NA | J13: NA | K13: NA | L13: NA | M13: NA | N13: NA | O13: NA | P13: NA | Q13: NA | R13: NA | S13: NA | T13: NA | U13: NA | V13: NA | W13: NA | X13: NA | Y13: NA | Z13: NA | AA13: NA | AB13: NA | AC13: NA | AD13: NA | AE13: NA | AF13: NA | AG13: NA | AH13: NA | AI13: =('NominalGDP-NAICS'!G13*1000000.0)/TotalPopulation!AI13 -> 26325.528 | AJ13: =('NominalGDP-NAICS'!H13*1000000.0)/TotalPopulation!AJ13 -> 26080.133 | AK13: =('NominalGDP-NAICS'!I13*1000000.0)/TotalPopulation!AK13 -> 27727.954 | AL13: =('NominalGDP-NAICS'!J13*1000000.0)/TotalPopulation!AL13 -> 28554.089 | AM13: =('NominalGDP-NAICS'!K13*1000000.0)/TotalPopulation!AM13 -> 30604.217 | AN13: =('NominalGDP-NAICS'!L13*1000000.0)/TotalPopulation!AN13 -> 32533.77 | AO13: =('NominalGDP-NAICS'!M13*1000000.0)/TotalPopulation!AO13 -> 34213.893 | AP13: =('NominalGDP-NAICS'!N13*1000000.0)/TotalPopulation!AP13 -> 34366.353 | ... AS13: =('NominalGDP-NAICS'!Q13*1000000.0)/TotalPopulation!AS13 -> 32675.842
A14: 49740 | B14: Metro Yuma | C14: NA | D14: NA | E14: NA | F14: NA | G14: NA | H14: NA | I14: NA | J14: NA | K14: NA | L14: NA | M14: NA | N14: NA | O14: NA | P14: NA | Q14: NA | R14: NA | S14: NA | T14: NA | U14: NA | V14: NA | W14: NA | X14: NA | Y14: NA | Z14: NA | AA14: NA | AB14: NA | AC14: NA | AD14: NA | AE14: NA | AF14: NA | AG14: NA | AH14: NA | AI14: =('NominalGDP-NAICS'!G14*1000000.0)/TotalPopulation!AI14 -> 18763.085 | AJ14: =('NominalGDP-NAICS'!H14*1000000.0)/TotalPopulation!AJ14 -> 20931.329 | AK14: =('NominalGDP-NAICS'!I14*1000000.0)/TotalPopulation!AK14 -> 21523.425 | AL14: =('NominalGDP-NAICS'!J14*1000000.0)/TotalPopulation!AL14 -> 24070.731 | AM14: =('NominalGDP-NAICS'!K14*1000000.0)/TotalPopulation!AM14 -> 24371.421 | AN14: =('NominalGDP-NAICS'!L14*1000000.0)/TotalPopulation!AN14 -> 25493.886 | AO14: =('NominalGDP-NAICS'!M14*1000000.0)/TotalPopulation!AO14 -> 27140.699 | AP14: =('NominalGDP-NAICS'!N14*1000000.0)/TotalPopulation!AP14 -> 26903.484 | ... AS14: =('NominalGDP-NAICS'!Q14*1000000.0)/TotalPopulation!AS14 -> 26494.748

Sheet PctChgRealGDP
B1: HOVER FOR DETAIL ON SAVING DATA | L1: PERCENT CHANGE IN INFLATION-ADJUSTED GROSS DOMESTIC PRODUCT
A2: Location Codes | B2: Name of Geography | C2: Inflation-Adjusted Percent Change in Gross Domestic Product 1988 | D2: Inflation-Adjusted Percent Change in Gross Domestic Product 1989 | E2: Inflation-Adjusted Percent Change in Gross Domestic Product 1990 | F2: Inflation-Adjusted Percent Change in Gross Domestic Product 1991 | G2: Inflation-Adjusted Percent Change in Gross Domestic Product 1992 | H2: Inflation-Adjusted Percent Change in Gross Domestic Product 1993 | I2: Inflation-Adjusted Percent Change in Gross Domestic Product 1994 | J2: Inflation-Adjusted Percent Change in Gross Domestic Product 1995 | K2: Inflation-Adjusted Percent Change in Gross Domestic Product 1996 | L2: Inflation-Adjusted Percent Change in Gross Domestic Product 1997 | M2: Inflation-Adjusted Percent Change in Gross Domestic Product 1998 | N2: Inflation-Adjusted Percent Change in Gross Domestic Product 1999 | O2: Inflation-Adjusted Percent Change in Gross Domestic Product 2000 | P2: Inflation-Adjusted Percent Change in Gross Domestic Product 2001 | Q2: Inflation-Adjusted Percent Change in Gross Domestic Product 2002 | R2: Inflation-Adjusted Percent Change in Gross Domestic Product 2003 | S2: Inflation-Adjusted Percent Change in Gross Domestic Product 2004 | T2: Inflation-Adjusted Percent Change in Gross Domestic Product 2005 | U2: Inflation-Adjusted Percent Change in Gross Domestic Product 2006 | V2: Inflation-Adjusted Percent Change in Gross Domestic Product 2007 | W2: Inflation-Adjusted Percent Change in Gross Domestic Product 2008 | X2: Inflation-Adjusted Percent Change in Gross Domestic Product 2009 | Y2: Inflation-Adjusted Percent Change in Gross Domestic Product 2010 | Z2: Inflation-Adjusted Percent Change in Gross Domestic Product 2011 | AA2: Inflation-Adjusted Percent Change in Gross Domestic Product 2012
A3: CodedLocale | B3: Geo Name | C3: Pct Chg Real GDP 1988 | D3: Pct Chg Real GDP 1989 | E3: Pct Chg Real GDP 1990 | F3: Pct Chg Real GDP 1991 | G3: Pct Chg Real GDP 1992 | H3: Pct Chg Real GDP 1993 | I3: Pct Chg Real GDP 1994 | J3: Pct Chg Real GDP 1995 | K3: Pct Chg Real GDP 1996 | L3: Pct Chg Real GDP 1997 | M3: Pct Chg Real GDP 1998 | N3: Pct Chg Real GDP 1999 | O3: Pct Chg Real GDP 2000 | P3: Pct Chg Real GDP 2001 | Q3: Pct Chg Real GDP 2002 | R3: Pct Chg Real GDP 2003 | S3: Pct Chg Real GDP 2004 | T3: Pct Chg Real GDP 2005 | U3: Pct Chg Real GDP 2006 | V3: Pct Chg Real GDP 2007 | W3: Pct Chg Real GDP 2008 | X3: Pct Chg Real GDP 2009 | Y3: Pct Chg Real GDP 2010 | Z3: Pct Chg Real GDP 2011 | AA3: Pct Chg Real GDP 2012
A4: fips_code | B4: geo_name | C4: pct-chg_real-gdp_1988 | D4: pct-chg_real-gdp_1989 | E4: pct-chg_real-gdp_1990 | F4: pct-chg_real-gdp_1991 | G4: pct-chg_real-gdp_1992 | H4: pct-chg_real-gdp_1993 | I4: pct-chg_real-gdp_1994 | J4: pct-chg_real-gdp_1995 | K4: pct-chg_real-gdp_1996 | L4: pct-chg_real-gdp_1997 | M4: pct-chg_real-gdp_1998 | N4: pct-chg_real-gdp_1999 | O4: pct-chg_real-gdp_2000 | P4: pct-chg_real-gdp_2001 | Q4: pct-chg_real-gdp_2002 | R4: pct-chg_real-gdp_2003 | S4: pct-chg_real-gdp_2004 | T4: pct-chg_real-gdp_2005 | U4: pct-chg_real-gdp_2006 | V4: pct-chg_real-gdp_2007 | W4: pct-chg_real-gdp_2008 | X4: pct-chg_real-gdp_2009 | Y4: pct-chg_real-gdp_2010 | Z4: pct-chg_real-gdp_2011 | AA4: pct-chg_real-gdp_2012
A5: FIPS_CODE | B5: GEO_NAME | C5: 1988 | D5: 1989 | E5: 1990 | F5: 1991 | G5: 1992 | H5: 1993 | I5: 1994 | J5: 1995 | K5: 1996 | L5: 1997 | M5: 1998 | N5: 1999 | O5: 2000 | P5: 2001 | Q5: 2002 | R5: 2003 | S5: 2004 | T5: 2005 | U5: 2006 | V5: 2007 | W5: 2008 | X5: 2009 | Y5: 2010 | Z5: 2011 | AA5: 2012
A6: US | B6: U.S. Metros | C6: NA | D6: NA | E6: NA | F6: NA | G6: NA | H6: NA | I6: NA | J6: NA | K6: NA | L6: NA | M6: NA | N6: NA | O6: NA | P6: NA | Q6: =('RealGDP-NAICS'!H6-'RealGDP-NAICS'!G6)/'RealGDP-NAICS'!G6 -> 0.017185936 | R6: =('RealGDP-NAICS'!I6-'RealGDP-NAICS'!H6)/'RealGDP-NAICS'!H6 -> 0.020816749 | S6: =('RealGDP-NAICS'!J6-'RealGDP-NAICS'!I6)/'RealGDP-NAICS'!I6 -> 0.034080415 | T6: =('RealGDP-NAICS'!K6-'RealGDP-NAICS'!J6)/'RealGDP-NAICS'!J6 -> 0.029277689 | U6: =('RealGDP-NAICS'!L6-'RealGDP-NAICS'!K6)/'RealGDP-NAICS'!K6 -> 0.028242546 | V6: =('RealGDP-NAICS'!M6-'RealGDP-NAICS'!L6)/'RealGDP-NAICS'!L6 -> 0.01903779 | W6: =('RealGDP-NAICS'!N6-'RealGDP-NAICS'!M6)/'RealGDP-NAICS'!M6 -> -0.0066922812 | X6: =('RealGDP-NAICS'!O6-'RealGDP-NAICS'!N6)/'RealGDP-NAICS'!N6 -> -0.038323246 | ... Z6: =('RealGDP-NAICS'!Q6-'RealGDP-NAICS'!P6)/'RealGDP-NAICS'!P6 -> 0.015850876
A7: 004 | B7: United States | C7: =('RealGDP-SIC'!D6-'RealGDP-SIC'!C6)/'RealGDP-SIC'!C6 -> 0.052977647 | D7: =('RealGDP-SIC'!E6-'RealGDP-SIC'!D6)/'RealGDP-SIC'!D6 -> 0.022102096 | E7: =('RealGDP-SIC'!F6-'RealGDP-SIC'!E6)/'RealGDP-SIC'!E6 -> 0.015009525 | F7: =('RealGDP-SIC'!G6-'RealGDP-SIC'!F6)/'RealGDP-SIC'!F6 -> -0.001566838 | G7: =('RealGDP-SIC'!H6-'RealGDP-SIC'!G6)/'RealGDP-SIC'!G6 -> 0.030283914 | H7: =('RealGDP-SIC'!I6-'RealGDP-SIC'!H6)/'RealGDP-SIC'!H6 -> 0.020383758 | I7: =('RealGDP-SIC'!J6-'RealGDP-SIC'!I6)/'RealGDP-SIC'!I6 -> 0.046013787 | J7: =('RealGDP-SIC'!K6-'RealGDP-SIC'!J6)/'RealGDP-SIC'!J6 -> 0.034406936 | ... L7: =('RealGDP-SIC'!M6-'RealGDP-SIC'!L6)/'RealGDP-SIC'!L6 -> 0.052429577 | M7: =('RealGDP-NAICS'!D7-'RealGDP-NAICS'!C7)/'RealGDP-NAICS'!C7 -> 0.043106823 | N7: =('RealGDP-NAICS'!E7-'RealGDP-NAICS'!D7)/'RealGDP-NAICS'!D7 -> 0.047671567 | O7: =('RealGDP-NAICS'!F7-'RealGDP-NAICS'!E7)/'RealGDP-NAICS'!E7 -> 0.042173689 | P7: =('RealGDP-NAICS'!G7-'RealGDP-NAICS'!F7)/'RealGDP-NAICS'!F7 -> 0.012445341 | Q7: =('RealGDP-NAICS'!H7-'RealGDP-NAICS'!G7)/'RealGDP-NAICS'!G7 -> 0.017130587 | R7: =('RealGDP-NAICS'!I7-'RealGDP-NAICS'!H7)/'RealGDP-NAICS'!H7 -> 0.021560319 | S7: =('RealGDP-NAICS'!J7-'RealGDP-NAICS'!I7)/'RealGDP-NAICS'!I7 -> 0.033067734 | T7: =('RealGDP-NAICS'!K7-'RealGDP-NAICS'!J7)/'RealGDP-NAICS'!J7 -> 0.027835822 | ... AA7: =('RealGDP-NAICS'!R7-'RealGDP-NAICS'!Q7)/'RealGDP-NAICS'!Q7 -> 0.024584237
A8: 22380 | B8: Arizona | C8: =('RealGDP-SIC'!D7-'RealGDP-SIC'!C7)/'RealGDP-SIC'!C7 -> 0.047754569 | D8: =('RealGDP-SIC'!E7-'RealGDP-SIC'!D7)/'RealGDP-SIC'!D7 -> 0.0088838496 | E8: =('RealGDP-SIC'!F7-'RealGDP-SIC'!E7)/'RealGDP-SIC'!E7 -> 0.0078423139 | F8: =('RealGDP-SIC'!G7-'RealGDP-SIC'!F7)/'RealGDP-SIC'!F7 -> 0.0041663603 | G8: =('RealGDP-SIC'!H7-'RealGDP-SIC'!G7)/'RealGDP-SIC'!G7 -> 0.10172553 | H8: =('RealGDP-SIC'!I7-'RealGDP-SIC'!H7)/'RealGDP-SIC'!H7 -> 0.051328061 | I8: =('RealGDP-SIC'!J7-'RealGDP-SIC'!I7)/'RealGDP-SIC'!I7 -> 0.096801382 | J8: =('RealGDP-SIC'!K7-'RealGDP-SIC'!J7)/'RealGDP-SIC'!J7 -> 0.076029739 | ... L8: =('RealGDP-SIC'!M7-'RealGDP-SIC'!L7)/'RealGDP-SIC'!L7 -> 0.069579462 | M8: =('RealGDP-NAICS'!D8-'RealGDP-NAICS'!C8)/'RealGDP-NAICS'!C8 -> 0.093981933 | N8: =('RealGDP-NAICS'!E8-'RealGDP-NAICS'!D8)/'RealGDP-NAICS'!D8 -> 0.083569167 | O8: =('RealGDP-NAICS'!F8-'RealGDP-NAICS'!E8)/'RealGDP-NAICS'!E8 -> 0.066432524 | P8: =('RealGDP-NAICS'!G8-'RealGDP-NAICS'!F8)/'RealGDP-NAICS'!F8 -> 0.037009701 | Q8: =('RealGDP-NAICS'!H8-'RealGDP-NAICS'!G8)/'RealGDP-NAICS'!G8 -> 0.024376698 | R8: =('RealGDP-NAICS'!I8-'RealGDP-NAICS'!H8)/'RealGDP-NAICS'!H8 -> 0.052162013 | S8: =('RealGDP-NAICS'!J8-'RealGDP-NAICS'!I8)/'RealGDP-NAICS'!I8 -> 0.036989419 | T8: =('RealGDP-NAICS'!K8-'RealGDP-NAICS'!J8)/'RealGDP-NAICS'!J8 -> 0.073713511 | ... AA8: =('RealGDP-NAICS'!R8-'RealGDP-NAICS'!Q8)/'RealGDP-NAICS'!Q8 -> 0.026042431
A9: 29420 | B9: Metro Flagstaff | C9: NA | D9: NA | E9: NA | F9: NA | G9: NA | H9: NA | I9: NA | J9: NA | K9: NA | L9: NA | M9: NA | N9: NA | O9: NA | P9: NA | Q9: =('RealGDP-NAICS'!H9-'RealGDP-NAICS'!G9)/'RealGDP-NAICS'!G9 -> 0.034594914 | R9: =('RealGDP-NAICS'!I9-'RealGDP-NAICS'!H9)/'RealGDP-NAICS'!H9 -> 0.035724493 | S9: =('RealGDP-NAICS'!J9-'RealGDP-NAICS'!I9)/'RealGDP-NAICS'!I9 -> 0.021799117 | T9: =('RealGDP-NAICS'!K9-'RealGDP-NAICS'!J9)/'RealGDP-NAICS'!J9 -> 0.053200108 | U9: =('RealGDP-NAICS'!L9-'RealGDP-NAICS'!K9)/'RealGDP-NAICS'!K9 -> 0.08025641 | V9: =('RealGDP-NAICS'!M9-'RealGDP-NAICS'!L9)/'RealGDP-NAICS'!L9 -> 0.058390695 | W9: =('RealGDP-NAICS'!N9-'RealGDP-NAICS'!M9)/'RealGDP-NAICS'!M9 -> 0.01704418 | X9: =('RealGDP-NAICS'!O9-'RealGDP-NAICS'!N9)/'RealGDP-NAICS'!N9 -> -0.071664829 | ... Z9: =('RealGDP-NAICS'!Q9-'RealGDP-NAICS'!P9)/'RealGDP-NAICS'!P9 -> -0.0087367178
A10: 38060 | B10: Metro Lake Havasu City | C10: NA | D10: NA | E10: NA | F10: NA | G10: NA | H10: NA | I10: NA | J10: NA | K10: NA | L10: NA | M10: NA | N10: NA | O10: NA | P10: NA | Q10: =('RealGDP-NAICS'!H10-'RealGDP-NAICS'!G10)/'RealGDP-NAICS'!G10 -> 0.053848934 | R10: =('RealGDP-NAICS'!I10-'RealGDP-NAICS'!H10)/'RealGDP-NAICS'!H10 -> 0.059327846 | S10: =('RealGDP-NAICS'!J10-'RealGDP-NAICS'!I10)/'RealGDP-NAICS'!I10 -> 0.02039495 | T10: =('RealGDP-NAICS'!K10-'RealGDP-NAICS'!J10)/'RealGDP-NAICS'!J10 -> 0.081218274 | U10: =('RealGDP-NAICS'!L10-'RealGDP-NAICS'!K10)/'RealGDP-NAICS'!K10 -> 0.10064554 | V10: =('RealGDP-NAICS'!M10-'RealGDP-NAICS'!L10)/'RealGDP-NAICS'!L10 -> -0.014129565 | W10: =('RealGDP-NAICS'!N10-'RealGDP-NAICS'!M10)/'RealGDP-NAICS'!M10 -> -0.032990806 | X10: =('RealGDP-NAICS'!O10-'RealGDP-NAICS'!N10)/'RealGDP-NAICS'!N10 -> -0.11213647 | ... Z10: =('RealGDP-NAICS'!Q10-'RealGDP-NAICS'!P10)/'RealGDP-NAICS'!P10 -> 0.0088832487
