Workbook

Sheet Main Analysis
A1: Northeastern University Libraries, November 2010
A2: Please see http://www.lib.neu.edu/ALADrupalPoster2011 if you have questions.
A4: The following survey was sent to three email lists (Drupal4Lib, Web4Lib, and Code4Lib)
A5: on 10/20/2010 and 11/01/2010.
A8: Type of Library
A10: Total # | B10: Special | C10: Public | D10: Academic
A12: =SUM(B12:D12) -> 29 | B12: =COUNTIF('Full Data'!B2:AD2,"special") -> 2 | C12: =COUNTIF('Full Data'!B2:AD2,"Public") -> 4 | D12: =COUNTIF('Full Data'!B2:AD2,"Academic") -> 23
A15: Size
A17: Academic* | D17: * Uses Carnegie Classification
A18: Very small (Under 1,000) | B18: =COUNTIF('Full Data'!B3:AD3,"Under 1,000") -> 1
A19: Small (1,000 - 2,999) | B19: =COUNTIF('Full Data'!B3:AD3,"1,000 - 2,999") -> 2
A20: Medium (3,000 - 9,999) | B20: =COUNTIF('Full Data'!B3:AD3,"3,000 - 9,999") -> 4
A21: Large (10,000 - 19,999) | B21: =COUNTIF('Full Data'!B3:AD3,"10,000 - 19,999") -> 11
A22: Very large (Over 20,000) | B22: 5 | C22: **One public library answered "over 20,000" using the academic classification rather than public;
B23: =SUM(B18:B22) -> 23 | C23: we categorized this as small, below.
A25: Public
A26: Very small (Under 10,000) | B26: =COUNTIF('Full Data'!B4:AD4,"Under 10,000") -> 0
A27: Small (10,000 - 24,999) | B27: 2 | C27: **One public library answered "over 20,000" using the academic classification rather than public;
A28: Medium (25,000 -99,999) | B28: =COUNTIF('Full Data'!B4:AD4,"25,000 -99,999") -> 1 | C28: we categorized this as small
A29: Large (100,000 - 499,999) | B29: =COUNTIF('Full Data'!B4:AD4,"100,000 - 499,999") -> 0
A30: Very large (500,000 and over) | B30: =COUNTIF('Full Data'!B4:AD4,"500,000 and over") -> 1
B32: =SUM(B26:B31) -> 4
A34: Special
A35: Very small (1-9) | B35: 0
A36: Small (10-49) | B36: 0
A37: Medium (50-99) | B37: 0
A38: Large (over 100) | B38: 2
B39: 2
A42: Customization level
A44: Minimal | B44: =COUNTIF('Full Data'!B6:AD6,"Minimally") -> 3 | C44: v. small | D44: small | E44: medium | F44: large | G44: v. large
A45: Academic | B45: 1 | F45: 1
A46: Public | B46: 1 | E46: 1
A47: Special | B47: 1 | F47: 1
A49: Moderate | B49: =COUNTIF('Full Data'!B6:AD6,"Moderately") -> 16 | C49: v. small | D49: small | E49: medium | F49: large | G49: v. large
A50: Academic | B50: 12 | D50: 2 | F50: 8 | G50: 2
A51: Public | B51: 3 | D51: 1 | E51: 1 | G51: 1
A52: Special | B52: 1 | F52: 1
A54: Heavy | B54: =COUNTIF('Full Data'!B6:AD6,"Heavily") -> 10 | C54: v. small | D54: small | E54: medium | F54: large | G54: v. large
A55: Academic | B55: 10 | C55: 1 | E55: 4 | F55: 2 | G55: 3
A56: Public
...

Sheet Full Data
A1: Drupal Survey Questions
A2: 1) Are you an academic, public, or special library? | B2: Academic | C2: Academic | D2: Academic | E2: Academic | F2: Academic | G2: Academic | H2: Academic | I2: Special | J2: Academic | K2: Special | L2: Public | M2: Academic | N2: Academic | O2: Academic | P2: Academic | Q2: Academic | R2: Academic | S2: Academic | T2: Academic | U2: Academic | V2: Public | W2: Academic | X2: Academic | Y2: Public | Z2: Academic | AA2: Academic | AB2: Academic | AC2: Academic | AD2: Public
A3: 1a) For academic libraries: what is your institution’s full-time equivalent (FTE)? | B3: 1,000 - 2,999 | C3: Over 20,000 | D3: 10,000 - 19,999 | E3: 3,000 - 9,999 | F3: 10,000 - 19,999 | G3: Over 20,000 | H3: Over 20,000 | J3: Under 1,000 | M3: 10,000 - 19,999 | N3: 10,000 - 19,999 | O3: 1,000 - 2,999 | P3: 3,000 - 9,999 | Q3: 10,000 - 19,999 | R3: 3,000 - 9,999 | S3: Over 20,000 | T3: 3,000 - 9,999 | U3: 10,000 - 19,999 | W3: 10,000 - 19,999 | X3: 10,000 - 19,999 | Y3: Over 20,000 | Z3: 10,000 - 19,999 | AA3: 10,000 - 19,999 | AB3: 10,000 - 19,999 | AC3: Over 20,000
A4: 1b) For public libraries: what is the population in your legal service area? | L4: 500,000 and over | V4: 25,000 -99,999 | AD4: 10,000 - 24,999
A5: 1c) For special libraries: how many people do you serve? | I5: 100 and over | K5: 100 and over
A6: 2) Is your Drupal website minimally, moderately, or heavily customized? | B6: Moderately | C6: Heavily | D6: Moderately | E6: Heavily | F6: Moderately | G6: Heavily | H6: Heavily | I6: Minimally | J6: Heavily | K6: Moderately | L6: Moderately | M6: Moderately | N6: Moderately | O6: Moderately | P6: Heavily | Q6: Moderately | R6: Heavily | S6: Moderately | T6: Heavily | U6: Heavily | V6: Moderately | W6: Moderately | X6: Moderately | Y6: Minimally | Z6: Moderately | AA6: Heavily | AB6: Minimally | AC6: Moderately | AD6: Moderately
A7: 2a) If your Drupal site is customized, do you do template customization and module development in-house? | B7: Yes | C7: Yes | D7: Yes | E7: Yes | F7: Yes | G7: Yes | H7: Yes | J7: Yes | K7: Yes | L7: No | M7: Yes | N7: Yes | O7: Yes | P7: Yes | Q7: Yes | R7: Yes | S7: Yes | T7: Yes | U7: Yes | V7: Yes | W7: Yes | X7: Yes | Y7: No | Z7: No | AA7: Yes | AB7: Yes | AC7: No | AD7: Yes
A8: 3) Do you feel that your current level of staffing is sufficient to support your current and planned Drupal projects? | B8: Yes | C8: No | D8: No | E8: No | F8: Yes | G8: Yes | H8: No | I8: No | J8: Yes | K8: No | L8: No | M8: No | N8: Yes | O8: No | P8: Yes | Q8: Yes | R8: Yes | S8: No | T8: No | U8: No | V8: Yes | W8: No | X8: No | Y8: No | Z8: No | AA8: Yes | AB8: No | AC8: Yes | AD8: Yes
A9: 4) Do you have permanent library staff with responsibilities in Drupal development and maintenance? If not, please go to question 8. | B9: No | C9: Yes | D9: Yes | E9: Yes | F9: Yes | G9: Yes | H9: Yes | I9: Yes | J9: Yes | K9: Yes | L9: Yes | M9: Yes | N9: Yes | O9: Yes | P9: Yes | Q9: Yes | R9: Yes | S9: Yes | T9: Yes | U9: Yes | V9: Yes | W9: Yes | X9: Yes | Y9: Yes | Z9: Yes | AA9: Yes | AB9: Yes | AC9: Yes | AD9: Yes
A10: 5) If you do have permanent library staff with responsibilities in Drupal development and maintenance, what skills do they have? | C10: PHP, CSS, HTML, Server Administration | D10: PHP, CSS, HTML, Graphic Design, Server Administration | E10: PHP, CSS, HTML, Graphic Design, Server Administration, database administration, usability testing | F10: PHP, CSS, HTML, Server Administration | G10: PHP, CSS, HTML, Graphic Design, Server Administration, javascript, java, ruby, etc | H10: PHP, CSS, HTML, Graphic Design | I10: CSS, HTML, Graphic Design | J10: PHP, CSS, HTML, Graphic Design | K10: PHP, CSS, HTML, Server Administration, Drupal skills | L10: PHP, CSS, HTML, Server Administration | M10: PHP, CSS, HTML, Graphic Design | N10: PHP, CSS, HTML, sql, ajax | O10: CSS, HTML | P10: PHP, CSS, HTML, Graphic Design, Server Administration | Q10: PHP, CSS, HTML, Server Administration | R10: PHP, CSS, HTML, Graphic Design, Server Administration, SQL, multimedia | S10: PHP, CSS, HTML, Server Administration | T10: PHP, CSS, HTML, Server Administration | U10: PHP, CSS, HTML | V10: PHP, CSS, HTML, Server Administration, perl, python, javascript | W10: PHP, CSS, HTML, Graphic Design, Server Administration | X10: PHP, CSS, HTML, Graphic Design, Server Administration | Y10: CSS, HTML, Server Administration | Z10: PHP, CSS, HTML, Server Administration | AA10: PHP, CSS, HTML, Graphic Design, Server Administration | AB10: PHP, CSS, HTML, Server Administration | AC10: PHP, CSS, HTML, Graphic Design, Server Administration, Accessibility training | AD10: PHP, CSS, HTML
A11: 6) If you do have permanent staff with responsibilities in Drupal development and maintenance, in which department do they reside? | C11: Our department is kinda a sibling to Library Systems and Technical Services | D11: Library Systems | E11: New Media | F11: Library Systems | G11: Library IT | H11: Library Web Systems | I11: unrelated to IT | J11: Library Systems | K11: Library Systems, Technical Services | L11: Library Systems | M11: Library Systems, Web Services | N11: Library Systems | O11: Reference | P11: Library Systems | Q11: Library Systems, Technical Services | R11: branch library | S11: Library Systems | T11: Library Systems | U11: Library Systems | V11: Technology | W11: Library Systems, Administration | X11: Library Systems | Y11: Library Systems | Z11: Library Systems | AA11: Web Services (library department) | AB11: Library Systems | AC11: Library Systems | AD11: Computer Services
A12: 7) If you do have permanent library staff with responsibilities in Drupal development and maintenance, do they have shared responsibilities, or are they solely devoted to Drupal development and maintenance? | C12: Shared responsibilities | D12: Shared responsibilities | E12: Shared responsibilities | F12: Shared responsibilities | G12: Shared responsibilities | H12: Shared responsibilities | I12: Shared responsibilities | J12: Shared responsibilities | K12: Shared responsibilities | L12: Shared responsibilities | M12: Shared responsibilities | N12: Shared responsibilities | O12: Shared responsibilities | P12: Shared responsibilities | Q12: Shared responsibilities | R12: Shared responsibilities | S12: Drupal only | T12: Shared responsibilities | U12: Shared responsibilities | V12: Shared responsibilities | W12: Shared responsibilities | X12: Shared responsibilities | Y12: Shared responsibilities | Z12: Shared responsibilities | AA12: Shared responsibilities | AB12: Shared responsibilities | AC12: Shared responsibilities | AD12: Shared responsibilities
A13: 7a) If they are solely devoted to Drupal development and maintenance, do they receive support from other departments in the library or organization? (For exanple, server administation is done by city or campus IT.) If yes, please tell us what type of support. | C13: Server administration is done by a separate sibling department in our org chart. | G13: We have about 17 Drupal sites with the entire library system. Most sites run on servers hosted by central IT dept but with Library IT support | H13: The answer to 7 is 'both'. I have one FTE devoted to Drupal and 2 additional FTE who work in Drupal, but do other non-drupal work, as well, including the proxy server, a Metalib install, and non-Drupal PHP applications. | O13: Server administration by campus IT. Since IT does not have any linux experience, we also have an off-campus paid linux consultant for occasional server maintenance. | S13: Server OS support, i.e., software patching, and maintaining our virtual server | AC13: No
A14: 7b) If they have shared responsibilities beyond Drupal development and maintenance, what are their other areas of focus? | C14: They maintain the library's ezproxy configuration, the Library's Ex Libris Metalib server, and legacy non-drupal php and perl code. | D14: Other web applications in the library. i.e., ContentDM | E14: Non-Drupal website/application development, database design and administration, scripting languages, help desk support | F14: other systems (wordpress, mrbs, etc.); ref desk, library & campus committees | G14: Java web applications, Ruby apps, system architecture development, external program support. I do a lot of work in the international information systems and some of my time is on a contract with [a large organization] | H14: The answer to 7 is 'both'. I have one FTE devoted to Drupal and 2 additional FTE who work in Drupal, but do other non-drupal work, as well, including the proxy server, a Metalib install, and non-Drupal PHP applications. | I14: instructional and elearning design, training, web conferencing, multimedia development | J14: Everything else dealing with our web presence, including static HTML/CSS, design, CONTENTdm, application development. | K14: content management | L14: Catalogue api usage; server maintenance; general scripting; | M14: On the Systems side, maintenance of staff computers; maintenance of the Voyager catalog, ILLIAD, eRes, and more systems; and more than I think of right now. On the Web Services side, overall maintenance of the web presence, including some content updates, graphic design, and support of digitization efforts. | N14: Other IT | O14: Reference and instruction | P14: Library ILS, ezproxy, SFX, server administration, digital library, contentdm | Q14: Internal library programming projects | R14: educational technology, user support | T14: Library instruction, reference services | U14: Technology Helpdesk every third week. | V14: helpdesk, ILS (Evergreen) enhancement, custom one-off web apps | W14: Web master: Building coordinator, merit staff coordinator, oversees student employment program Systems: database development projects for Metalib and Xerxes | X14: Supporting all Library web applications development (excluding applications referred to as enterprise systems) and server administration. | Y14: system management Reference E-resources marketing | Z14: We run about 10 different servers, 2 of which host drupal sites. We run a variety of Drupal sites, including our intranet, primary website, and an online community for our campus. We manage ILLiad, SFX, EZProxy, online Chat (just the technical side of this), LibAnswers, LibGuides. | AA14: Bibliographer: order books in one area and teach some library instruction sessions. Responsible for all library Web Services including ILLiad Web interface, CONTENTdm Web interface and all custom applications and web pages. | AB14: - overall maintenance of libraries' web presence, web services, - programming for other web services & internal databases - maintaining ILS - server administration for other library servers | AC14: Other dynamic content systems, web server account management | AD14: All areas of computer support
A15: 7c) If you have library staff with responsibility for Drupal, and they also have responsibilities in other areas, how many hours a week do they devote to the library website (including maintenance like server backup, account administration, software updates, etc.)? | B15: Less than 5 hours per week | C15: More than 20 hours per week | D15: Currently more than 20 because are still migrating | E15: More than 20 hours per week | F15: More than 20 hours per week | G15: 16-20 hours per week | H15: More than 20 hours per week | I15: highly variable depending on what's happening | J15: The question doesn't make sense for us. We have 3 people who work on Drupal. 100% of their time is spent on the library website. But the library website is not all Drupal. | K15: 6-10 hours per week | L15: More than 20 hours per week | M15: More than 20 hours per week | N15: Less than 5 hours per week | O15: 11-15 hours per week | P15: 16-20 hours per week | Q15: 16-20 hours per week | R15: 11-15 hours per week | S15: 16-20 hours per week | T15: 16-20 hours per week | U15: 11-15 hours per week | V15: 6-10 hours per week | W15: 6-10 hours per week | X15: 11-15 hours per week | Y15: Less than 5 hours per week | Z15: 11-15 hours per week | AA15: More than 20 hours per week | AB15: 16-20 hours per week | AC15: 16-20 hours per week | AD15: 6-10 hours per week
A16: 8) If you do NOT have permanent library staff with Drupal expertise, how do you support Drupal development and maintenance? | B16: Campus IT staff
A17: 9) Do you distribute website editing around the library, or does only your web manager make content changes to the website? | B17: Distributed around library. | C17: Distributed around library. | D17: Distribution is possible, but webmaster ends up making most changes | E17: Distributed around library. | F17: Distributed, but with understanding that web developer will fill in gaps if requested | G17: Distributed around library. | H17: Distributed around library. | I17: Distributed around library. | J17: Distributed around library. | K17: Distributed around library. | L17: Moving toward distributed editing | M17: simplete text editing is distrubted, but changes to navigation and search tools are done by web services. | N17: Distributed around library. | O17: Distributed around library. | P17: Distributed around library. | Q17: Distributed around library. | R17: Distributed around library. | S17: Distributed around library. | T17: Distributed around library. | U17: Distributed around library. | V17: Distributed around library. | W17: Distributed around library. | X17: Distributed around library. | Y17: Only webmaster makes changes. | Z17: Distributed around library. | AA17: Distributed around library. | AB17: Distributed around library. | AC17: mixed -- main pages done by webmaster, librarians manage own content | AD17: Distributed around library.
A18: 9a) If more than one person can make content changes to the website, what number of library staff have permission to maintain content on the site? | B18: anyone who has a need to do so | C18: Around 200. | D18: 15 | E18: 10 | F18: all librarians if they choose (mostly on their areas), and selected staff | G18: 40308 | H18: 150 | I18: 4 | J18: Drupal hasn't been 100% adopted yet. When it is, about 25 people will have permission. | K18: 40466 | L18: bloggers only; about 12. | M18: all professional staff have access to their own bio pages. Department heads have control over pages that are pertinient to them. | N18: 9 | O18: 8 | P18: 10 | Q18: 10+ | R18: 3 | S18: 12 | T18: All staff have limited access, different levels | U18: 30 | V18: 20+ | W18: 29 | X18: 30 | Z18: everyone has libguides permission. 8 people on the library website (this could grow according to need) | AA18: 20 | AB18: 6 | AC18: 4 (currently -- plans to expand) | AD18: 7
A19: 9b) If more than one person can make content changes to the website, do library staff have different levels of permissions (for example, some can only draft content while others can edit and publish?) | B19: No | C19: Yes | D19: Yes | E19: Yes | F19: Yes | G19: Yes | H19: Yes | I19: No | J19: Yes | K19: Yes | L19: Yes | M19: Yes | N19: Yes | O19: Yes | P19: Yes | Q19: Yes | R19: Yes | S19: Yes | T19: Yes | U19: Yes | V19: No | W19: Yes | X19: Yes | Z19: Yes | AA19: Yes | AB19: Yes | AC19: Yes | AD19: Yes
A20: 9c) In your opinion, is content updating more/less difficult than using Microsoft Word, or about the same? | B20: Less difficult | C20: Less difficult | D20: More difficult | E20: About the same | F20: About the same | G20: Less difficult | H20: About the same | I20: Do not know | J20: About the same | K20: About the same | L20: About the same | M20: Less difficult | N20: More difficult | O20: About the same | P20: More difficult | Q20: Less difficult | R20: Less difficult | S20: Less difficult | T20: About the same | U20: About the same | V20: About the same | W20: About the same | X20: About the same | Z20: More difficult | AA20: Less difficult | AB20: About the same | AC20: About the same | AD20: About the same
A21: 10) What other issues should we take into consideration when developing our staffing model? Please share any other comments you have here. | D21: Drupal is not easy to learn, and requires heavy development to get a quality site. However, it is easier than trying to create a 2.0 site in-house. | E21: Allow designers and developers freedom (work from home/coffee shops, flex time, etc). Avoid committee thinking, but include your web team on decision making processes that will affect your web presence. Do not pile unrelated work onto your web team due to staffing shortages in other areas. Outsourcing may seem attractive as far as budget is concerned, but you will be one of many clients to a contractor who cannot invest the time to understand your culture like full-time staff can. If you do decide to contract, don't ask for speculative work ("Design something for us and we'll pay you if we like it"). It's evil. Oh, and pay well. :) | F21: don't assume that just because librarians can make changes, that they all will want to. Some may want to leave it to others, which could/should be accomodated have other testing instances of drupal for the developers to play on, and also (another one) for the real keen non-systems staff training done once is not done once and for all, must be repeated and iterative | G21: You can outsource theme development, but having an in house person with a good understanding of PHP is important, even if you're not doing custom module development. | I21: Similar issues apply to all content management scenarios - pasting in crappy code, adding animated gifs, etc. Good procedures and policies from your previous scenario will help. Also - Drupal is more complicated even for the content editors, so expect that they'll need training and that you may need to do some work around permissions. | J21: That last question (9c) doesn't quite make sense. 99% of people who use Microsoft Word do it incorrectly, without regard to document well-formedness. These people will almost certainly be incapable of creating properly formed web pages in Drupal as well. It's not about *difficulty*; it's about understanding the nature of proper content creation. I would have a content expert create the initial Drupal site, and give training on creating well-formed web documents before setting general library staff loose on the website. | L21: The specific Drupal experience of a particular developer is the biggest factor in staffing. One experienced Drupalista equals about three or more newbies. | M21: It is critical to have PHP skills. We are stretched thin because we have only one person with real programming skills, and he has competing duties. Jquery is another useful skill that we are trying to develop in Web Services. | S21: I highly recommend this excellent presentation given by Emily Morton Owens at LITA National Forum a couple of weeks ago: http://connect.ala.org/files/79651/editorial_and_technological_workflow_tools_pdf_56609.pdf It has been very helpful to me in working out content management issues on our Drupal site, which we just launched in August. | T21: You can never have all the staff you really need, but there are a couple of areas that we miss in our organization they are: 1. Usability person: Someone with a little expertise in designing interfaces for better usability 2. Designer - someone to make things look nice 3. Liason to students/facutly: Somebody to set up a sustainable system for getting regular feedback and testing from our user community | U21: You need more than one person with the skills necessary to implement and customize Drupal. | W21: Time for developing and giving training is essential. Developing training guides and sessions is time consuming but very important to do. I haven't had as much time to focus on this as I would like. I'm mainly responsible for our site but ask for PHP work from our database person. He has assisted with creating custom templates and figuring out module patches. He may eventually create simple modules if we have a need. We have a network person who works with me on servers and maintains the server side of the Drupal installations. | X21: Staff users tend to find change frustrating. The idea of separating content from presentation is foreign to a lot of staff. Aim to use as few modules as possible (which tends to still be a large number but if you can avoid module overload, it is highly suggestible). Due to the very nature of drupal it supports gradual change and implementation, so I would suggest that you focus on the must haves, and then slowly bring in additional features. Even you have a large staff, this may not be as much of an issue but scope creep tends to make the initial rollout (and migration of old web content) potentially painful. | Y21: time to train, learn and make mistakes lots of free resources out there, training videos, podcasts, etc to take advantage of make time for creating and delivering in house training if you are going to have multiple authors/editors | Z21: There is a significant learning curve -- but a LOT of potential with Drupal. And it's worth it --- so much you can do once you get started! | AA21: Have someone who loves Drupal (and there are folks who are crazy about it) enough to really get into and waylay the naysayers. | AB21: we're in the initial stages of migrating our site onto Drupal, so there's a heavy focus on the system. We're also trying to do hiring, so our staff levels in support of Drupal aren't stable at this point. | AC21: We maintain our own servers. Depending on your level of customization, you're going to want to be able to work closely with the server administrator or webmaster so you can tweak rewrite rules, mysql performance, php configuration, etc, as well as do backups and restarte the server when necessary. | AD21: work across departments so people can handle their own content

Sheet Typical Academic Library
A1: NOTE: The survey generated enough data to make generalizations about a "typical" academic library only.
A2: See Special & Public Breakout (next tab) for individual library profiles in those categories.
A5: Typical academic staff situation: | C5: Not enough staff (although medium, heavy customizers were more satisfied)
C6: Have permanent staff with Drupal expertise
C7: Drupal staff in library dept. variously called Systems/IT/Web Systems/Web Services
C8: Drupal staff has other responsibilities (see breakdown on next tab)
C9: Spend over 16 hours a week on lib website, up to 20+ hours/week
C10: Allow distributed editing, almost all using range of permissions to control access
C11: Have the following skills, in order of commonality: CSS & HTML, PHP, Server Admin, Graphic Design and other
C12: (incl. database admin, usability testing, JavaScript, Java, Ruby, SQL, Ajax, multimedia, Perl, Python,
C13: accessibility training)
B17: Minimal | C17: Moderate | D17: Heavy | E17: Yes in-house cust'n templates/modules | F17: No in-house cust'n templates/modules | G17: Yes suff'nt staff | H17: No suff'nt staff | I17: Yes perm'nt Drupal | J17: No perm'nt Drupal
A18: Very small (Under 1,000) | D18: 1 | E18: 1 | G18: 1 | I18: 1
A19: Small (1,000 - 2,999) | C19: 2 | E19: 2 | G19: 1 | H19: 1 | I19: 1 | J19: 1
A20: Medium (3,000 - 9,999) | D20: 4 | E20: 4 | G20: 2 | H20: 2 | I20: 4
A21: Large (10,000 - 19,999) | B21: 1 | C21: 8 | D21: 2 | E21: 10 | F21: 1 | G21: 4 | H21: 7 | I21: 11
A22: Very large (Over 20,000) | C22: 2 | D22: 3 | E22: 4 | F22: 1 | G22: 2 | H22: 3 | I22: 5
A27: Very small (Under 1,000) | B27: 1 total | C27: Yes in-house | D27: No in-house | E27: Yes suff'nt staff | F27: No suff'nt staff | G27: Yes perm'nt Drupal | H27: No perm'nt Drupal
A28: Minimal
A29: Moderate
A30: Heavy | B30: 1 | C30: 1 | E30: 1 | G30: 1
A36: Small (1,000 - 2,999) | B36: 2 total | C36: Yes in-house | D36: No in-house | E36: Yes suff'nt staff | F36: No suff'nt staff | G36: Yes perm'nt Drupal | H36: No perm'nt Drupal
A37: Minimal
A38: Moderate | B38: 2 | C38: 2 | E38: 1 | F38: 1 | G38: 1 | H38: 1
A39: Heavy
A45: Medium (3,000 - 9,999) | B45: 4 total | C45: Yes in-house | D45: No in-house | E45: Yes suff'nt staff | F45: No suff'nt staff | G45: Yes perm'nt Drupal | H45: No perm'nt Drupal
A46: Minimal
A47: Moderate
A48: Heavy | B48: 4 | C48: 4 | E48: 2 | F48: 2 | G48: 4
A53: Large (10,000 - 19,999) | B53: 11 total | C53: Yes in-house | D53: No in-house | E53: Yes suff'nt staff | F53: No suff'nt staff | G53: Yes perm'nt Drupal | H53: No perm'nt Drupal
A54: Minimal | B54: 1 | C54: 1 | F54: 1 | G54: 1
A55: Moderate | B55: 8 | C55: 7 | D55: 1 | E55: 3 | F55: 5 | G55: 8
A56: Heavy | B56: 2 | C56: 2 | E56: 1 | F56: 1 | G56: 2
A61: Very large (Over 20,000) | B61: 5 total | C61: Yes in-house | D61: No in-house | E61: Yes suff'nt staff | F61: No suff'nt staff | G61: Yes perm'nt Drupal | H61: No perm'nt Drupal
A62: Minimal
A63: Moderate | B63: 2 | C63: 1 | D63: 1 | E63: 1 | F63: 1 | G63: 2
A64: Heavy | B64: 3 | C64: 3 | E64: 1 | F64: 2 | G64: 3

Sheet Special & Public Breakout
A3: Special
A4: (2 total) | B4: Size | C4: Large (over 100) | D4: Large (over 100)
B5: Level of customization | C5: Minimal customization | D5: Moderate customization
B6: In-house development of modules and templates? | C6: Not answered | D6: Yes
B7: Sufficiently staffed? | C7: No | D7: No
B8: Permanent lib staff who does Drupal? | C8: Yes | D8: Yes
B9: What kind of skills? | C9: CSS, HTML, Graphic Design | D9: PHP, CSS, HTML Server Admin
B10: Which dept? | C10: Non-IT Dept | D10: Lib Systems
B11: Shared/other duties? | C11: Yes | D11: Yes
B12: Types of other duties | C12: E-learning and instructional design | D12: Content management
B13: Time spent on website | C13: Highly variable | D13: 6-10 hours/week
B14: Distributed editing? | C14: Yes | D14: Yes
B15: Editors have differing Drupal permission levels? | C15: No | D15: Yes
A18: Public
A19: (4 total) | B19: Size | C19: Very Large (500,000 +) | D19: Medium (25,000 - 99,000) | E19: Small (Over 20,000)* | F19: Small (10,000 - 24,999)
B20: Level of customization | C20: Moderate | D20: Moderate | E20: Minimal | F20: Moderate
B21: In-house development of modules and templates? | C21: No | D21: Yes | E21: No | F21: Yes
B22: Sufficiently staffed? | C22: No | D22: Yes | E22: No | F22: Yes
B23: Permanent lib staff who does Drupal? | C23: Yes | D23: Yes | E23: Yes | F23: Yes
B24: What kind of skills? | C24: PHP, CSS, HTML, Server Admin | D24: PHP, CSS, HTML, Server Administration, perl, python, javascript | E24: CSS, HTML, Server Administration | F24: PHP, CSS, HTML
B25: Which dept? | C25: Library Systems | D25: Technology | E25: Library Systems | F25: Computer Services
B26: Shared/other duties? | C26: Yes | D26: Yes | E26: Yes | F26: Yes
B27: Types of other duties | C27: Catalog API, server maintenance, general scripting | D27: helpdesk, ILS enhancement, custom one-off web apps | E27: system management, Reference, E-resources, marketing | F27: All areas of computer support
B28: Time spent on website | C28: More than 20 hours/week | D28: 6-10 hours per week | E28: Less than 5 hours/week | F28: 6-10 hours per week
B29: Distributed editing? | C29: Moving towards this model | D29: Yes | E29: No | F29: Yes
B30: Editors have differing Drupal permission levels? | C30: Yes | D30: No | E30: N/A | F30: Yes
E32: *mis-match in numbers because respondent answered under academic classification rather than public; we categorized this as small

Sheet Share Responsibilities Coded
A1: Analysis of question 7b:
A2: If shared responsibilities, what other areas of focus?
A3: NOTE: This is just an initial attempt at coding responses; some responses were unclear, and discarded for that reason.
A5: Technical: P=Programming, S=Systems, W=Web-specific services and apps
A6: Public: SD = Service Desk/direct patron contact, I = Instruction
A8: They maintain the library's ezproxy configuration, the Library's Ex Libris Metalib server, and legacy non-drupal php and perl code.
A9: P, S
A11: Other web applications in the library. i.e., ContentDM
A12: S, W
A14: Non-Drupal website/application development, database design and administration, scripting languages, help desk support
A15: P, W | B15: SD
A17: other systems (wordpress, mrbs, etc.); ref desk, library & campus committees
A18: S | B18: SD
A20: Java web applications, Ruby apps, system architecture development, external program support. I do a lot of work in the international
A21: information systems andsome of my time is on a contract with [a large organization]
A22: P, S, W
A24: The answer to 7 is 'both'. I have one FTE devoted to Drupal and 2 additional FTE who work in Drupal, but do other non-drupal work, as well, including
A25: the proxy server, a Metalib install, and non-Drupal PHP applications.
A26: P, S
A28: instructional and elearning design, training, web conferencing, multimedia development
B29: I
A31: Everything else dealing with our web presence, including static HTML/CSS, design, CONTENTdm, application development.
A32: P, W
A34: content management
A35: W
A37: Catalogue api usage; server maintenance; general scripting;
A38: P, S
A41: On the Systems side, maintenance of staff computers; maintenance of the Voyager catalog, ILLIAD, eRes, and more systems; and more than I think
A42: of right now. On the Web Services side, overall maintenance of the web presence, including some content updates, graphic design, and support of
A43: digitization efforts.
A44: S, W
A46: Reference and instruction
B47: SD, I
A49: Library ILS, ezproxy, SFX, server administration, digital library, contentdm
A50: S
A52: Internal library programming projects
A53: P
A55: educational technology, user support
B56: SD, I
A58: Library instruction, reference services
...
