Workbook
Name Name1: Report!$A$359
Name Name2: Report!$A$7
Name Names: 'FY07 PU'!$I$5:$EX$7
Name Outputs: Report!$E$15:$I$15
Name Range1: Report!$A$361:$N$700
Name Range2: Report!$A$17:$N$356
Name Reset: Outputs!$A$6:$A$151
Name Snumber: Report!$A$1
Name Start: Outputs!$A$4

Sheet SUMMARY
A1: CHARTER SCHOOL REFERENDUM AID PER PUPIL UNIT, FY 2007 TO FY 2011
A2: THESE ESTIMATES REFLECT DECREASING AID PORTIONS AS TAX BASES GROW FASTER THAN PUPIL COUNTS,
A3: AND ASSUME THAN AUTHORITIES WILL BE REPLACED AS THEY EXPIRE BUT WILL NOT INCREASE.
D5: FY 2007 | E5: FY 2008 | F5: FY 2009 | G5: FY 2010 | H5: FY 2011
A7: 4000 | B7: 7 | C7: CITY ACADEMY | D7: 121.5 | E7: 93.13 | F7: 57.03 | G7: 23.85 | H7: 0
A8: 4001 | B8: 7 | C8: BLUFFVIEW MONTESSORI | D8: 93.56 | E8: 29.8 | F8: 6.73 | G8: 5.04 | H8: 3.25
A9: 4003 | B9: 7 | C9: NEW HEIGHTS SCHOOL, INC. | D9: 6.46 | E9: 4.13 | F9: 1.79 | G9: 0.54 | H9: 0
A10: 4004 | B10: 7 | C10: CEDAR RIVERSIDE COMMUNITY SCHO | D10: 0 | E10: 0 | F10: 0 | G10: 0 | H10: 0
A11: 4005 | B11: 7 | C11: METRO DEAF CHARTER SCHOOL | D11: 87.33 | E11: 55.44 | F11: 24.36 | G11: 10.19 | H11: 0
A12: 4006 | B12: 7 | C12: SKILLS FOR TOMORROW CHARTER SC | D12: 85.79 | E12: 65.33 | F12: 39.98 | G12: 16.72 | H12: 0
A13: 4007 | B13: 7 | C13: MINNESOTA NEW COUNTRY SCHOOL | D13: 176.05 | E13: 153.5 | F13: 119.7 | G13: 87.64 | H13: 51.04
A14: 4008 | B14: 7 | C14: PACT CHARTER SCHOOL | D14: 183.4 | E14: 153.42 | F14: 76.6 | G14: 15.14 | H14: 1.73
A15: 4011 | B15: 7 | C15: NEW VISIONS CHARTER SCHOOL | D15: 9.74 | E15: 6.53 | F15: 3.55 | G15: 1.1 | H15: 0.22
A16: 4012 | B16: 7 | C16: EMILY CHARTER SCHOOL | D16: 57.12 | E16: 17.13 | F16: 0.07 | G16: 0 | H16: 0
A17: 4015 | B17: 7 | C17: COMMUNITY OF PEACE ACADEMY | D17: 117.02 | E17: 89.7 | F17: 54.88 | G17: 23.06 | H17: 0.21
A18: 4016 | B18: 7 | C18: WORLD LEARNER CHARTER SCHOOL | D18: 59.63 | E18: 30.26 | F18: 0 | G18: 0 | H18: 0
... A137: 4163 | B137: 7 | C137: LEARNING FOR LEADERSHIP CHARTER | D137: 0 | E137: 0 | F137: 0 | G137: 0 | H137: 0

Sheet Report
A1: 4181 | B1: = Charter School Number | F1: INSTRUCTIONS: ENTER THE SCHOOL NUMBER IN CELL A1
F2: (THE YELLOW CELL), THEN READ IN THE SCHOOL'S INPUTS
F3: BY HOLDING DOWN THE CTRL KEY AND SIMULTANEOUSLY
F4: HITTING THE "A" KEY.
A6: ESTIMATED REFERENDUM AID PER PUPIL UNIT, FY 2007 TO FY 2011 | N6: CHART_REFAID_0711
A7: COMMUNITY SCHOOL OF EXCELLENCE #4181 | N7: 39482
D9: A | E9: B | F9: C | G9: D | H9: E | I9: F | J9: H | K9: I | L9: J | M9: K | N9: L
D11: FY 2007 | E11: FY 2007 | F11: FY 2008 | G11: FY 2009 | H11: FY 2010 | I11: FY 2011 | J11: FY 2007 | K11: FY 2008 | L11: FY 2009 | M11: FY 2010 | N11: FY 2011
D12: PUPIL | E12: AID | F12: AID | G12: AID | H12: AID | I12: AID | J12: PRODUCT | K12: PRODUCT | L12: PRODUCT | M12: PRODUCT | N12: PRODUCT
D13: UNITS | E13: PER PU | F13: PER PU | G13: PER PU | H13: PER PU | I13: PER PU | J13: =+"= "&+D9&" X "&+E9 -> = A X B | K13: =+"= "&+D9&" X "&+F9 -> = A X C | L13: =+"= "&+D9&" X "&+G9 -> = A X D | M13: =+"= "&+D9&" X "&+H9 -> = A X E | N13: =+"= "&+D9&" X "&+I9 -> = A X F
C15: TOTAL | D15: =SUM(D361:D700) -> 1 | E15: =IF(D15=1,"n/a",ROUND(IF($D15=0,0,J15/$D15),2)) -> n/a | F15: =ROUND(IF($D15=0,0,K15/$D15),2) -> 145.43 | G15: =ROUND(IF($D15=0,0,L15/$D15),2) -> 73.45 | H15: =ROUND(IF($D15=0,0,M15/$D15),2) -> 29.58 | I15: =ROUND(IF($D15=0,0,N15/$D15),2) -> 0 | J15: =SUM(J361:J700) -> 114.42 | K15: =SUM(K361:K700) -> 145.43 | L15: =SUM(L361:L700) -> 73.45 | M15: =SUM(M361:M700) -> 29.58 | N15: =SUM(N361:N700) -> 0
A17: 625 | B17: 1 | C17: ST. PAUL | D17: 1 | E17: 114.42 | F17: 145.43 | G17: 73.45 | H17: 29.58 | I17: 0 | J17: 114.42 | K17: 145.43 | L17: 73.45 | M17: 29.58 | N17: 0
A18: 1 | B18: 1 | C18: AITKIN | D18: 0 | E18: 0.02 | F18: 0.01 | G18: 0 | H18: 0 | I18: 0 | J18: 0 | K18: 0 | L18: 0 | M18: 0 | N18: 0
A19: 1.2 | B19: 3 | C19: MINNEAPOLIS | D19: 0 | E19: 0 | F19: 0 | G19: 0 | H19: 0 | I19: 0 | J19: 0 | K19: 0 | L19: 0 | M19: 0 | N19: 0
A20: 2 | B20: 1 | C20: HILL CITY | D20: 0 | E20: 0 | F20: 0 | G20: 0 | H20: 0 | I20: 0 | J20: 0 | K20: 0 | L20: 0 | M20: 0 | N20: 0
A21: 4 | B21: 1 | C21: MCGREGOR | D21: 0 | E21: 0.29 | F21: 0.1 | G21: 0 | H21: 0 | I21: 0 | J21: 0 | K21: 0 | L21: 0 | M21: 0 | N21: 0
A22: 6 | B22: 3 | C22: SOUTH ST. PAUL | D22: 0 | E22: 148.33 | F22: 101.24 | G22: 33.49 | H22: 42.11 | I22: 22.55 | J22: 0 | K22: 0 | L22: 0 | M22: 0 | N22: 0
A23: 11 | B23: 1 | C23: ANOKA-HENNEPIN | D23: 0 | E23: 201.32 | F23: 160.73 | G23: 94.43 | H23: 68.94 | I23: 35.3 | J23: 0 | K23: 0 | L23: 0 | M23: 0 | N23: 0
A24: 12 | B24: 1 | C24: CENTENNIAL | D24: 0 | E24: 236.53 | F24: 219.92 | G24: 159.5 | H24: 146.91 | I24: 124.23 | J24: 0 | K24: 0 | L24: 0 | M24: 0 | N24: 0
A25: 13 | B25: 1 | C25: COLUMBIA HEIGHTS | D25: 0 | E25: 84.33 | F25: 18.39 | G25: 0 | H25: 0 | I25: 0 | J25: 0 | K25: 0 | L25: 0 | M25: 0 | N25: 0
A26: 14 | B26: 1 | C26: FRIDLEY | D26: 0 | E26: 62.1 | F26: 0.95 | G26: 0 | H26: 0 | I26: 0 | J26: 0 | K26: 0 | L26: 0 | M26: 0 | N26: 0
A27: 15 | B27: 1 | C27: ST. FRANCIS | D27: 0 | E27: 154.67 | F27: 108.49 | G27: 65.38 | H27: 2.43 | I27: 0 | J27: 0 | K27: 0 | L27: 0 | M27: 0 | N27: 0
A28: 16 | B28: 1 | C28: SPRING LAKE PARK | D28: 0 | E28: 0 | F28: 0 | G28: 0 | H28: 0 | I28: 0 | J28: 0 | K28: 0 | L28: 0 | M28: 0 | N28: 0
... A356: 2902 | B356: 1 | C356: RUSSELL-TYLER-RUTHTON | D356: 0 | E356: 434.73 | F356: 435.52 | G356: 404.09 | H356: 380.59 | I356: 349.74 | J356: 0 | K356: 0 | L356: 0 | M356: 0 | N356: 0
A359: =HLOOKUP(Snumber,Names,3,FALSE)&" #"&FIXED(Snumber,0,TRUE) -> COMMUNITY SCHOOL OF EXCELLENCE #4181
A361: 1 | B361: 1 | C361: AITKIN | D361: ='FY07 PU'!D11 -> 0 | E361: 0.02 | F361: 0.01 | G361: 0 | H361: 0 | I361: 0 | J361: =$D361*E361 -> 0 | K361: =$D361*F361 -> 0 | L361: =$D361*G361 -> 0 | M361: =$D361*H361 -> 0 | N361: =$D361*I361 -> 0
A362: 1.2 | B362: 3 | C362: MINNEAPOLIS | D362: ='FY07 PU'!D12 -> 0 | E362: 0 | F362: 0 | G362: 0 | H362: 0 | I362: 0 | J362: =$D362*E362 -> 0 | K362: =$D362*F362 -> 0 | L362: =$D362*G362 -> 0 | M362: =$D362*H362 -> 0 | N362: =$D362*I362 -> 0
A363: 2 | B363: 1 | C363: HILL CITY | D363: ='FY07 PU'!D13 -> 0 | E363: 0 | F363: 0 | G363: 0 | H363: 0 | I363: 0 | J363: =$D363*E363 -> 0 | K363: =$D363*F363 -> 0 | L363: =$D363*G363 -> 0 | M363: =$D363*H363 -> 0 | N363: =$D363*I363 -> 0
A364: 4 | B364: 1 | C364: MCGREGOR | D364: ='FY07 PU'!D14 -> 0 | E364: 0.29 | F364: 0.1 | G364: 0 | H364: 0 | I364: 0 | J364: =$D364*E364 -> 0 | K364: =$D364*F364 -> 0 | L364: =$D364*G364 -> 0 | M364: =$D364*H364 -> 0 | N364: =$D364*I364 -> 0
A365: 6 | B365: 3 | C365: SOUTH ST. PAUL | D365: ='FY07 PU'!D15 -> 0 | E365: 148.33 | F365: 101.24 | G365: 33.49 | H365: 42.11 | I365: 22.55 | J365: =$D365*E365 -> 0 | K365: =$D365*F365 -> 0 | L365: =$D365*G365 -> 0 | M365: =$D365*H365 -> 0 | N365: =$D365*I365 -> 0
A366: 11 | B366: 1 | C366: ANOKA-HENNEPIN | D366: ='FY07 PU'!D16 -> 0 | E366: 201.32 | F366: 160.73 | G366: 94.43 | H366: 68.94 | I366: 35.3 | J366: =$D366*E366 -> 0 | K366: =$D366*F366 -> 0 | L366: =$D366*G366 -> 0 | M366: =$D366*H366 -> 0 | N366: =$D366*I366 -> 0
A367: 12 | B367: 1 | C367: CENTENNIAL | D367: ='FY07 PU'!D17 -> 0 | E367: 236.53 | F367: 219.92 | G367: 159.5 | H367: 146.91 | I367: 124.23 | J367: =$D367*E367 -> 0 | K367: =$D367*F367 -> 0 | L367: =$D367*G367 -> 0 | M367: =$D367*H367 -> 0 | N367: =$D367*I367 -> 0
A368: 13 | B368: 1 | C368: COLUMBIA HEIGHTS | D368: ='FY07 PU'!D18 -> 0 | E368: 84.33 | F368: 18.39 | G368: 0 | H368: 0 | I368: 0 | J368: =$D368*E368 -> 0 | K368: =$D368*F368 -> 0 | L368: =$D368*G368 -> 0 | M368: =$D368*H368 -> 0 | N368: =$D368*I368 -> 0
A369: 14 | B369: 1 | C369: FRIDLEY | D369: ='FY07 PU'!D19 -> 0 | E369: 62.1 | F369: 0.95 | G369: 0 | H369: 0 | I369: 0 | J369: =$D369*E369 -> 0 | K369: =$D369*F369 -> 0 | L369: =$D369*G369 -> 0 | M369: =$D369*H369 -> 0 | N369: =$D369*I369 -> 0
A370: 15 | B370: 1 | C370: ST. FRANCIS | D370: ='FY07 PU'!D20 -> 0 | E370: 154.67 | F370: 108.49 | G370: 65.38 | H370: 2.43 | I370: 0 | J370: =$D370*E370 -> 0 | K370: =$D370*F370 -> 0 | L370: =$D370*G370 -> 0 | M370: =$D370*H370 -> 0 | N370: =$D370*I370 -> 0
A371: 16 | B371: 1 | C371: SPRING LAKE PARK | D371: ='FY07 PU'!D21 -> 0 | E371: 0 | F371: 0 | G371: 0 | H371: 0 | I371: 0 | J371: =$D371*E371 -> 0 | K371: =$D371*F371 -> 0 | L371: =$D371*G371 -> 0 | M371: =$D371*H371 -> 0 | N371: =$D371*I371 -> 0
A372: 22 | B372: 1 | C372: DETROIT LAKES | D372: ='FY07 PU'!D22 -> 0 | E372: 117.1 | F372: 87.32 | G372: 44.46 | H372: 22.66 | I372: 15.15 | J372: =$D372*E372 -> 0 | K372: =$D372*F372 -> 0 | L372: =$D372*G372 -> 0 | M372: =$D372*H372 -> 0 | N372: =$D372*I372 -> 0
... A700: 2902 | B700: 1 | C700: RUSSELL-TYLER-RUTHTON | D700: ='FY07 PU'!D350 -> 0 | E700: 434.73 | F700: 435.52 | G700: 404.09 | H700: 380.59 | I700: 349.74 | J700: =$D700*E700 -> 0 | K700: =$D700*F700 -> 0 | L700: =$D700*G700 -> 0 | M700: =$D700*H700 -> 0 | N700: =$D700*I700 -> 0

Sheet Notes
A1: Notes
A3: 1. | B3: For charter schools, referendum revenue per pupil unit equals the weighted
B4: average of the referendum aids per pupil unit received by the charter school's
B5: students' school districts of residence.
A7: 2. | B7: It is assumed that the percentage distribution of each charter school's pupil
B8: units among resident school districts won't change after FY 2007. For
B9: example, if 60% of a school's FY 2007 pupil units came from Minneapolis,
B10: and 40% came from St. Paul, it is assumed that this 60-40 split will remain
B11: in effect for all future years.
A13: 3. | B13: The "Report" worksheet includes these instructions:
B15: INSTRUCTIONS: ENTER THE SCHOOL NUMBER IN CELL A1 (THE
B16: YELLOW CELL), THEN READ IN THE SCHOOL'S INPUTS BY HOLDING
B17: DOWN THE CTRL KEY AND SIMULTANEOUSLY HITTING THE "A" KEY.
B19: By following these instructions, you run the "School" macro.
B21: The macro sorts school districts in descending order of the number of pupil units
B22: generated for the charter school in FY 2007.
A24: 4. | B24: For charter schools that open in FY 2008, it is assumed that all pupil units
B25: reside in the district in which the charter school is located. To carry out this
B26: assumption, the spreadsheet assigns 1 pupil unit to the local district and
B27: zero pupil units to all other districts.
B29: For charter schools that open in FY 2009 or later, it may be easiest to do a
B30: manual calculation. If a school opens in FY 2009, with 60% of the pupil units
B31: living in Centennial #12 and 40% living in Columbia Heights #13, the
B32: estimated average FY 2009 referendum aid per pupil unit would be
B33: (0.60 x 169.89) + (0.40 x 0.00) = 101.93. The 169.89 and the 0.00
B34: can be found in the "Report" worksheet.
A36: 5. | B36: In the portion of the "Report" worksheet that relates to specific school districts,
B37: columns H through M are calculated from columns A through G.
B39: In the line that shows a school's overall average referendum aid per pupil unit,
B40: columns B through G are calculated from column A and columns H through M.
B42: For example, a school's average FY 2007 referendum aid per pupil unit is found
B43: by dividing its total FY 2007 referendum aid (see column H) divided by its
B44: total FY 2007 pupil units (see column A).
B46: This approach gives the weighted average referendum aid per pupil unit for
B47: all the districts where students live, with the weighting factor being the
B48: pupil units shown in column A.
A50: 6. | B50: The FY 2007 aids per pupil unit shown here may contain rounding discrepancies
B51: from actual values.
A53: 7. | B53: Charter schools' operating revenue per pupil unit tends to decrease over time.
B55: This is explained by the fact that charter schools receive only the aid portion of
...

Sheet FY07 PU
F3: FY 2007 CHARTER SCHOOL PUPIL UNITS BY RESIDENT DISTRICT
I5: 4000 | J5: 4001 | K5: 4003 | L5: 4004 | M5: 4005 | N5: 4006 | O5: 4007 | P5: 4008 | Q5: 4011 | R5: 4012 | S5: 4015 | T5: 4016 | U5: 4017 | V5: 4018 | W5: 4020 | X5: 4025 | Y5: 4026 | Z5: 4027 | AA5: 4028 | AB5: 4029 | AC5: 4030 | AD5: 4031 | AE5: 4032 | AF5: 4035 | AG5: 4036 | AH5: 4038 | AI5: 4039 | AJ5: 4042 | AK5: 4043 | AL5: 4044 | AM5: 4045 | AN5: 4046 | AO5: 4048 | AP5: 4049 | AQ5: 4050 | AR5: 4052 | AS5: 4053 | AT5: 4054 | AU5: 4055 | AV5: 4056 | AW5: 4057 | AX5: 4058 | AY5: 4059 | AZ5: 4061 | BA5: 4064 | BB5: 4066 | BC5: 4067 | BD5: 4068 | BE5: 4070 | BF5: 4072 | BG5: 4073 | BH5: 4074 | BI5: 4075 | BJ5: 4077 | BK5: 4078 | BL5: 4079 | BM5: 4080 | BN5: 4081 | BO5: 4082 | BP5: 4083 | BQ5: 4084 | BR5: 4085 | BS5: 4086 | BT5: 4087 | BU5: 4088 | BV5: 4089 | BW5: 4090 | BX5: 4091 | BY5: 4092 | BZ5: 4093 | CA5: 4095 | CB5: 4097 | CC5: 4098 | CD5: 4099 | CE5: 4100 | CF5: 4101 | CG5: 4102 | CH5: 4103 | CI5: 4104 | CJ5: 4105 | CK5: 4106 | CL5: 4107 | CM5: 4108 | CN5: 4109 | CO5: 4110 | CP5: 4111 | CQ5: 4112 | CR5: 4113 | CS5: 4114 | CT5: 4115 | CU5: 4116 | CV5: 4118 | CW5: 4119 | CX5: 4120 | CY5: 4121 | CZ5: 4122 | DA5: 4123 | DB5: 4124 | DC5: 4125 | DD5: 4126 | DE5: 4127 | DF5: 4131 | DG5: 4132 | DH5: 4133 | DI5: 4135 | DJ5: 4136 | DK5: 4137 | DL5: 4138 | DM5: 4139 | DN5: 4140 | DO5: 4141 | DP5: 4142 | DQ5: 4143 | DR5: 4144 | DS5: 4145 | DT5: 4146 | DU5: 4148 | DV5: 4149 | DW5: 4150 | DX5: 4151 | DY5: 4152 | DZ5: 4153 | EA5: 4154 | EB5: 4155 | EC5: 4157 | ED5: 4158 | EE5: 4159 | EF5: 4160 | EG5: 4161 | EH5: 4162 | EI5: 4163 | EJ5: 4165 | EK5: 4166 | EL5: 4167 | EM5: 4168 | EN5: 4169 | EO5: 4170 | EP5: 4171 | EQ5: 4172 | ER5: 4173 | ES5: 4174 | ET5: 4175 | EU5: 4177 | EV5: 4178 | EW5: 4180 | EX5: 4181
D6: RPU IN | I6: 7 | J6: 7 | K6: 7 | L6: 7 | M6: 7 | N6: 7 | O6: 7 | P6: 7 | Q6: 7 | R6: 7 | S6: 7 | T6: 7 | U6: 7 | V6: 7 | W6: 7 | X6: 7 | Y6: 7 | Z6: 7 | AA6: 7 | AB6: 7 | AC6: 7 | AD6: 7 | AE6: 7 | AF6: 7 | AG6: 7 | AH6: 7 | AI6: 7 | AJ6: 7 | AK6: 7 | AL6: 7 | AM6: 7 | AN6: 7 | AO6: 7 | AP6: 7 | AQ6: 7 | AR6: 7 | AS6: 7 | AT6: 7 | AU6: 7 | AV6: 7 | AW6: 7 | AX6: 7 | AY6: 7 | AZ6: 7 | BA6: 7 | BB6: 7 | BC6: 7 | BD6: 7 | BE6: 7 | BF6: 7 | BG6: 7 | BH6: 7 | BI6: 7 | BJ6: 7 | BK6: 7 | BL6: 7 | BM6: 7 | BN6: 7 | BO6: 7 | BP6: 7 | BQ6: 7 | BR6: 7 | BS6: 7 | BT6: 7 | BU6: 7 | BV6: 7 | BW6: 7 | BX6: 7 | BY6: 7 | BZ6: 7 | CA6: 7 | CB6: 7 | CC6: 7 | CD6: 7 | CE6: 7 | CF6: 7 | CG6: 7 | CH6: 7 | CI6: 7 | CJ6: 7 | CK6: 7 | CL6: 7 | CM6: 7 | CN6: 7 | CO6: 7 | CP6: 7 | CQ6: 7 | CR6: 7 | CS6: 7 | CT6: 7 | CU6: 7 | CV6: 7 | CW6: 7 | CX6: 7 | CY6: 7 | CZ6: 7 | DA6: 7 | DB6: 7 | DC6: 7 | DD6: 7 | DE6: 7 | DF6: 7 | DG6: 7 | DH6: 7 | DI6: 7 | DJ6: 7 | DK6: 7 | DL6: 7 | DM6: 7 | DN6: 7 | DO6: 7 | DP6: 7 | DQ6: 7 | DR6: 7 | DS6: 7 | DT6: 7 | DU6: 7 | DV6: 7 | DW6: 7 | DX6: 7 | DY6: 7 | DZ6: 7 | EA6: 7 | EB6: 7 | EC6: 7 | ED6: 7 | EE6: 7 | EF6: 7 | EG6: 7 | EH6: 7 | EI6: 7 | EJ6: 7 | EK6: 7 | EL6: 7 | EM6: 7 | EN6: 7 | EO6: 7 | EP6: 7 | EQ6: 7 | ER6: 7 | ES6: 7 | ET6: 7 | EU6: 7 | EV6: 7 | EW6: 7 | EX6: 7
D7: SCHOOL | I7: CITY ACADEMY | J7: BLUFFVIEW MONTESSORI | K7: NEW HEIGHTS SCHOOL, INC. | L7: CEDAR RIVERSIDE COMMUNITY SCHO | M7: METRO DEAF CHARTER SCHOOL | N7: SKILLS FOR TOMORROW CHARTER SC | O7: MINNESOTA NEW COUNTRY SCHOOL | P7: PACT CHARTER SCHOOL | Q7: NEW VISIONS CHARTER SCHOOL | R7: EMILY CHARTER SCHOOL | S7: COMMUNITY OF PEACE ACADEMY | T7: WORLD LEARNER CHARTER SCHOOL | U7: MINNESOTA TRANSITIONS CHARTER | V7: ACHIEVE LANGUAGE ACADEMY | W7: DULUTH PUBLIC SCHOOLS ACADEMY | X7: CYBER VILLAGE ACADEMY | Y7: E.C.H.O. CHARTER SCHOOL | Z7: HIGHER GROUND ACADEMY | AA7: ECI' NOMPA WOONSPE | AB7: NEW SPIRIT SCHOOLS | AC7: ODYSSEY CHARTER SCHOOL | AD7: JENNINGS EXPERIENTIAL HIGH SCH | AE7: HARVEST PREP SCHOOL/SEED ACADE | AF7: CONCORDIA CREATIVE LEARNING AC | AG7: FACE TO FACE ACADEMY | AH7: SOJOURNER TRUTH ACADEMY | AI7: HIGH SCHOOL FOR RECORDING ARTS | AJ7: TWIN CITIES ACADEMY | AK7: MATH & SCIENCE ACADEMY | AL7: HEART OF THE EARTH CHARTER | AM7: LAKES AREA CHARTER SCHOOL | AN7: LAKE SUPERIOR HIGH SCHOOL | AO7: GREAT RIVER EDUCATION CENTER | AP7: COON RAPIDS LEARNING CENTER | AQ7: LAFAYETTE PUBLIC CHARTER SCHOO | AR7: FOUR DIRECTIONS CHARTER SCHOOL | AS7: NORTH LAKES ACADEMY | AT7: LACRESCENT MONTESSORI ACADEMY | AU7: NERSTRAND CHARTER SCHOOL | AV7: ROCHESTER OFF-CAMPUS CHARTER H | AW7: EL COLEGIO CHARTER SCHOOL | AX7: SCHOOLCRAFT LEARNING COMMUNITY | AY7: CROSSLAKE COMMUNITY CHARTER SC | AZ7: STUDIO ACADEMY CHARTER SCHOOL | BA7: RIVERWAY LEARNING COMMUNITY CH | BB7: RIVERBEND ACADEMY | BC7: AURORA CHARTER SCHOOL | BD7: EXCELL ACADEMY CHARTER | BE7: HOPE COMMUNITY ACADEMY | BF7: YANKTON COUNTRY CHARTER SCHOOL | BG7: ACADEMIA CESAR CHAVEZ CHARTER | BH7: AGRICULTURAL FOOD SCIENCE ACAD | BI7: AVALON SCHOOL | BJ7: TWIN CITIES INTERNATIONAL ELEM | BK7: MN INTERNATIONAL MIDDLE CHARTE | BL7: FRIENDSHIP ACDMY OF FINE ARTS | BM7: PILLAGER AREA CHARTER SCHOOL | BN7: COVENANT ACADEMY OF MN. CHTR. | BO7: BLUESKY CHARTER SCHOOL | BP7: RIDGEWAY COMMUNITY SCHOOL | BQ7: NORTH SHORE COMMUNITY SCHOOL | BR7: HARBOR CITY INTERNATIONAL CHAR | BS7: WOODSON INSTITUTE FOR EXCELLEN | BT7: SAGE ACADEMY CHARTER SCHOOL | BU7: URBAN ACADEMY CHARTER SCHOOL | BV7: NEW CITY SCHOOL | BW7: PRAIRIE CREEK COMMUNITY SCHOOL | BX7: ARTECH | BY7: WATERSHED HIGH SCHOOL | BZ7: NEW CENTURY CHARTER SCHOOL | CA7: TRIO WOLF CREEK DISTANCE LEARN | CB7: PARTNERSHIP ACADEMY, INC. | CC7: NOVA CLASSICAL ACADEMY | CD7: TAREK IBN ZIYAD ACADEMY | CE7: GREAT EXPECTATIONS | CF7: MINNESOTA NORTH STAR ACADEMY | CG7: MINNESOTA INTERNSHIP CENTER | CH7: HMONG ACADEMY | CI7: LIBERTY HIGH SCHOOL | CJ7: GREAT RIVER SCHOOL | CK7: TREKNORTH HIGH SCHOOL | CL7: VOYAGEURS EXPEDITIONARY | CM7: GENERAL JOHN VESSEY JR LEADERS | CN7: SOBRIETY HIGH | CO7: MAIN STREET SCHOOL PERFORMING | CP7: AUGSBURG ACADEMY FOR HEALTH CA | CQ7: ST PAUL CONSERVATORY PERFORMIN | CR7: FRASER ACADEMY | CS7: ASCENSION ACADEMY CHARTER SCHO | CT7: MINNEAPOLIS ACADEMY CHARTER SC | CU7: LAKES INTERNATIONAL LANGUAGE A | CV7: KALEIDOSCOPE CHARTER SCHOOL | CW7: RIVER HEIGHTS CHARTER SCHOOL | CX7: ST. CROIX PREPARATORY ACADEMY | CY7: UBAH MEDICAL ACADEMY CHARTER S | CZ7: EAGLE RIDGE ACADEMY CHARTER SC | DA7: DAKOTA AREA COMMUNITY CHARTER | DB7: BEACON ACADEMY | DC7: WORTHINGTON AREA LANGUAGE ACAD | DD7: PRAIRIE SEEDS ACADEMY | DE7: TEAM ACADEMY | DF7: LIGHTHOUSE ACADEMY OF NATIONS | DG7: TWIN CITIES ACADEMY HIGH SCHOOL | DH7: BEACON PREPARATORY SCHOOL | DI7: ADAM ABDULLE ACADEMY | DJ7: SOUL ACADEMY CHARTER SCHOOL | DK7: SWAN RIVER MONTESSORI CHARTER | DL7: MILROY AREA CHARTER SCHOOL | DM7: LOVEWORKS ACADEMY FOR ARTS | DN7: YINGHUA ACADEMY | DO7: PAIDEIA ACADEMY CHARTER SCHOOL | DP7: STRIDE ACADEMY CHARTER SCHOOL | DQ7: NEW MILLENNIUM ACADEMY CHARTER | DR7: GREEN ISLE COMMUNITY SCHOOL | DS7: BIRCH GROVE COMMUNITY SCHOOL | DT7: NORTHERN LIGHTS COMMUNITY SCHO | DU7: ACADEMY OF BIOSCIENCES | DV7: CYGNUS ACADEMY | DW7: MINNESOTA ONLINE HIGH SCHOOL | DX7: EDVISIONS OFF CAMPUS SCHOOL | DY7: TWIN CITIES GERMAN IMMERSION C | DZ7: DUGSI ACADEMY | EA7: RECOVERY SCHOOL OF SOUTHERN MN | EB7: NAYTAUWAUSH COMMUNITY SCHOOL | EC7: NEW SALEM ACADEMY | ED7: DAKOTA ACADEMY | EE7: SEVEN HILLS CLASSICAL ACADEMY | EF7: SPECTRUM HIGH SCHOOL | EG7: NEW DISCOVERIES MONTESSORI ACADEMY | EH7: SOUTHSIDE FAMILY CHARTER SCHOOL | EI7: LEARNING FOR LEADERSHIP CHARTER | EJ7: ELOM INTERNATIONAL SCHOOL | EK7: EAST RANGE ACADEMY OF TECH &SCIENCE | EL7: INTERNATIONAL SPANISH LANGUAGE ACAD | EM7: GLACIAL HILLS ELEMENTARY | EN7: ELLIOT PARK COMMUNITY SCHOOL | EO7: HIAWATHA LEADERSHIP ACADEMY | EP7: NOBLE ACADEMY | EQ7: CLARKFIELD CHARTER SCHOOL | ER7: DUNWOODY ACADEMY | ES7: PINE GROVE LEADERSHIP ACADEMY | ET7: LONG TIENG ACADEMY | EU7: MINISINAAKWAANG LEADERSHIP ACADEMY | EV7: LINCOLN INTERNATIONAL SCHOOL | EW7: EMILY O. GOODRIDGE-GREY ACCELERATED | EX7: COMMUNITY SCHOOL OF EXCELLENCE
D9: =SUM(D11:D352) -> 1 | I9: =SUM(I11:I350) -> 149.39 | J9: =SUM(J11:J350) -> 210.21 | K9: =SUM(K11:K350) -> 145.99 | L9: =SUM(L11:L350) -> 111.52 | M9: =SUM(M11:M350) -> 8.71 | N9: =SUM(N11:N350) -> 104.79 | O9: =SUM(O11:O350) -> 133 | P9: =SUM(P11:P350) -> 624.51 | ... EX9: =SUM(EX11:EX350) -> 1
A11: 1 | B11: 1 | C11: AITKIN | D11: =SUMIF(I$5:EX$5,Snumber,I11:EX11) -> 0 | F11: 1 | G11: 1 | H11: AITKIN | I11: 0 | J11: 0 | K11: 0 | L11: 0 | M11: 0 | N11: 0 | O11: 0 | P11: 0 | Q11: 0 | R11: 0 | S11: 0 | T11: 0 | U11: 0 | V11: 0 | W11: 0 | X11: 0 | Y11: 0 | Z11: 0 | AA11: 0 | AB11: 0 | AC11: 0 | AD11: 0 | AE11: 0 | AF11: 0 | AG11: 0 | AH11: 0 | AI11: 0 | AJ11: 0 | AK11: 0 | AL11: 0 | AM11: 0 | AN11: 0 | AO11: 0 | AP11: 0 | AQ11: 0 | AR11: 0 | AS11: 0 | AT11: 0 | AU11: 0 | AV11: 0 | AW11: 0 | AX11: 0 | AY11: 0 | AZ11: 0 | BA11: 0 | BB11: 0 | BC11: 0 | BD11: 0 | BE11: 0 | BF11: 0 | BG11: 0 | BH11: 0 | BI11: 0 | BJ11: 0 | BK11: 0 | BL11: 0 | BM11: 0 | BN11: 0 | BO11: 0 | BP11: 0 | BQ11: 0 | BR11: 0 | BS11: 0 | BT11: 0 | BU11: 0 | BV11: 0 | BW11: 0 | BX11: 0 | BY11: 0 | BZ11: 0 | CA11: 0 | CB11: 0 | CC11: 0 | CD11: 0 | CE11: 0 | CF11: 0 | CG11: 0 | CH11: 0 | CI11: 0 | CJ11: 0 | CK11: 0 | CL11: 0 | CM11: 0 | CN11: 0 | CO11: 0 | CP11: 0 | CQ11: 0 | CR11: 0 | CS11: 0 | CT11: 0 | CU11: 0 | CV11: 0 | CW11: 0 | CX11: 0 | CY11: 0 | CZ11: 0 | DA11: 0 | DB11: 0 | DC11: 0 | DD11: 0 | DE11: 0 | DF11: 0 | DG11: 0 | DH11: 0 | DI11: 0 | DJ11: 0 | DK11: 0 | DL11: 0 | DM11: 0 | DN11: 0 | DO11: 0 | DP11: 0 | DQ11: 0 | DR11: 0 | DS11: 0 | DT11: 0 | DU11: 0 | DV11: 0 | DW11: 1.3 | DX11: 0 | DY11: 0 | DZ11: 0 | EA11: 0 | EB11: 0 | EC11: 0 | ED11: 0 | EE11: 0 | EF11: 0 | EG11: 0 | EH11: 0 | EI11: 0 | EJ11: 0 | EK11: 0 | EL11: 0 | EM11: 0 | EN11: 0 | EO11: 0 | EP11: 0 | EQ11: 0 | ER11: 0 | ES11: 0 | ET11: 0 | EU11: 0 | EV11: 0 | EW11: 0 | EX11: 0
A12: 1.2 | B12: 3 | C12: MINNEAPOLIS | D12: =SUMIF(I$5:EX$5,Snumber,I12:EX12) -> 0 | F12: 1.2 | G12: 3 | H12: MINNEAPOLIS | I12: 0 | J12: 0 | K12: 0.33 | L12: 111.52 | M12: 0 | N12: 22.38 | O12: 0 | P12: 0 | Q12: 213.26 | R12: 0 | S12: 0.04 | T12: 0 | U12: 772.87 | V12: 0 | W12: 0 | X12: 24.43 | Y12: 0 | Z12: 207.77 | AA12: 0 | AB12: 0 | AC12: 21.34 | AD12: 2.11 | AE12: 477.45 | AF12: 0 | AG12: 0 | AH12: 243.57 | AI12: 64.9 | AJ12: 30.48 | AK12: 0 | AL12: 223.14 | AM12: 0 | AN12: 0 | AO12: 0 | AP12: 1.83 | AQ12: 0 | AR12: 109.56 | AS12: 0 | AT12: 0 | AU12: 0 | AV12: 0 | AW12: 103.82 | AX12: 0 | AY12: 0 | AZ12: 0 | BA12: 0 | BB12: 0 | BC12: 212.48 | BD12: 79.28 | BE12: 0 | BF12: 0 | BG12: 0 | BH12: 29.21 | BI12: 29.31 | BJ12: 426.33 | BK12: 269.9 | BL12: 89.43 | BM12: 0 | BN12: 0 | BO12: 20.67 | BP12: 0 | BQ12: 0 | BR12: 0 | BS12: 186.43 | BT12: 3.94 | BU12: 0.41 | BV12: 123.27 | BW12: 0 | BX12: 0 | BY12: 94.42 | BZ12: 0 | CA12: 0.1 | CB12: 26.88 | CC12: 29.56 | CD12: 92.2 | CE12: 0 | CF12: 2.6 | CG12: 460.09 | CH12: 276.3 | CI12: 7.58 | CJ12: 45 | CK12: 0 | CL12: 0 | CM12: 0 | CN12: 8.75 | CO12: 39.26 | CP12: 46.45 | CQ12: 31.56 | CR12: 31.67 | CS12: 86.08 | CT12: 133.81 | CU12: 0 | CV12: 0 | CW12: 0 | CX12: 0 | CY12: 226.78 | CZ12: 16.95 | DA12: 0 | DB12: 11.55 | DC12: 0 | DD12: 272.51 | DE12: 0 | DF12: 124.58 | DG12: 7.27 | DH12: 1.06 | DI12: 0 | DJ12: 64.31 | DK12: 0 | DL12: 0 | DM12: 262.27 | DN12: 8.23 | DO12: 0 | DP12: 0 | DQ12: 221.31 | DR12: 0 | DS12: 0 | DT12: 0 | DU12: 65.14 | DV12: 4.73 | DW12: 1.21 | DX12: 7.66 | DY12: 20.02 | DZ12: 115.26 | EA12: 0 | EB12: 0 | EC12: 57.85 | ED12: 0 | EE12: 14.65 | EF12: 0 | EG12: 0 | EH12: 94.83 | EI12: 156.66 | EJ12: 0 | EK12: 0 | EL12: 0 | EM12: 0 | EN12: 1 | EO12: 1 | EP12: 0 | EQ12: 0 | ER12: 1 | ES12: 0 | ET12: 1 | EU12: 0 | EV12: 1 | EW12: 1 | EX12: 0
A13: 2 | B13: 1 | C13: HILL CITY | D13: =SUMIF(I$5:EX$5,Snumber,I13:EX13) -> 0 | F13: 2 | G13: 1 | H13: HILL CITY | I13: 0 | J13: 0 | K13: 0 | L13: 0 | M13: 0 | N13: 0 | O13: 0 | P13: 0 | Q13: 0 | R13: 0 | S13: 0 | T13: 0 | U13: 0 | V13: 0 | W13: 0 | X13: 0 | Y13: 0 | Z13: 0 | AA13: 0 | AB13: 0 | AC13: 0 | AD13: 0 | AE13: 0 | AF13: 0 | AG13: 0 | AH13: 0 | AI13: 0 | AJ13: 0 | AK13: 0 | AL13: 0 | AM13: 0 | AN13: 0 | AO13: 0 | AP13: 0 | AQ13: 0 | AR13: 0 | AS13: 0 | AT13: 0 | AU13: 0 | AV13: 0 | AW13: 0 | AX13: 0 | AY13: 0 | AZ13: 0 | BA13: 0 | BB13: 0 | BC13: 0 | BD13: 0 | BE13: 0 | BF13: 0 | BG13: 0 | BH13: 0 | BI13: 0 | BJ13: 0 | BK13: 0 | BL13: 0 | BM13: 0 | BN13: 0 | BO13: 0 | BP13: 0 | BQ13: 0 | BR13: 0 | BS13: 0 | BT13: 0 | BU13: 0 | BV13: 0 | BW13: 0 | BX13: 0 | BY13: 0 | BZ13: 0 | CA13: 0 | CB13: 0 | CC13: 0 | CD13: 0 | CE13: 0 | CF13: 0 | CG13: 0 | CH13: 0 | CI13: 0 | CJ13: 0 | CK13: 0 | CL13: 0 | CM13: 0 | CN13: 0 | CO13: 0 | CP13: 0 | CQ13: 0 | CR13: 0 | CS13: 0 | CT13: 0 | CU13: 0 | CV13: 0 | CW13: 0 | CX13: 0 | CY13: 0 | CZ13: 0 | DA13: 0 | DB13: 0 | DC13: 0 | DD13: 0 | DE13: 0 | DF13: 0 | DG13: 0 | DH13: 0 | DI13: 0 | DJ13: 0 | DK13: 0 | DL13: 0 | DM13: 0 | DN13: 0 | DO13: 0 | DP13: 0 | DQ13: 0 | DR13: 0 | DS13: 0 | DT13: 0 | DU13: 0 | DV13: 0 | DW13: 0 | DX13: 0 | DY13: 0 | DZ13: 0 | EA13: 0 | EB13: 0 | EC13: 0 | ED13: 0 | EE13: 0 | EF13: 0 | EG13: 0 | EH13: 0 | EI13: 0 | EJ13: 0 | EK13: 0 | EL13: 0 | EM13: 0 | EN13: 0 | EO13: 0 | EP13: 0 | EQ13: 0 | ER13: 0 | ES13: 0 | ET13: 0 | EU13: 0 | EV13: 0 | EW13: 0 | EX13: 0
A14: 4 | B14: 1 | C14: MCGREGOR | D14: =SUMIF(I$5:EX$5,Snumber,I14:EX14) -> 0 | F14: 4 | G14: 1 | H14: MCGREGOR | I14: 0 | J14: 0 | K14: 0 | L14: 0 | M14: 0 | N14: 0 | O14: 0 | P14: 0 | Q14: 0 | R14: 0 | S14: 0 | T14: 0 | U14: 2.8 | V14: 0 | W14: 0 | X14: 0 | Y14: 0 | Z14: 0 | AA14: 0 | AB14: 0 | AC14: 0 | AD14: 0 | AE14: 0 | AF14: 0 | AG14: 0 | AH14: 0 | AI14: 0 | AJ14: 0 | AK14: 0 | AL14: 0 | AM14: 0 | AN14: 0 | AO14: 0 | AP14: 0 | AQ14: 0 | AR14: 0 | AS14: 0 | AT14: 0 | AU14: 0 | AV14: 0 | AW14: 0 | AX14: 0 | AY14: 0 | AZ14: 0 | BA14: 0 | BB14: 0 | BC14: 0 | BD14: 0 | BE14: 0 | BF14: 0 | BG14: 0 | BH14: 0 | BI14: 0 | BJ14: 0 | BK14: 0 | BL14: 0 | BM14: 0 | BN14: 0 | BO14: 0 | BP14: 0 | BQ14: 0 | BR14: 0 | BS14: 0 | BT14: 0 | BU14: 0 | BV14: 0 | BW14: 0 | BX14: 0 | BY14: 0 | BZ14: 0 | CA14: 0 | CB14: 0 | CC14: 0 | CD14: 0 | CE14: 0 | CF14: 0 | CG14: 0 | CH14: 0 | CI14: 0 | CJ14: 0 | CK14: 0 | CL14: 0 | CM14: 0 | CN14: 0 | CO14: 0 | CP14: 0 | CQ14: 0 | CR14: 0 | CS14: 0 | CT14: 0 | CU14: 0 | CV14: 0 | CW14: 0 | CX14: 0 | CY14: 0 | CZ14: 0 | DA14: 0 | DB14: 0 | DC14: 0 | DD14: 0 | DE14: 0 | DF14: 0 | DG14: 0 | DH14: 0 | DI14: 0 | DJ14: 0 | DK14: 0 | DL14: 0 | DM14: 0 | DN14: 0 | DO14: 0 | DP14: 0 | DQ14: 0 | DR14: 0 | DS14: 0 | DT14: 0 | DU14: 0 | DV14: 0 | DW14: 1.3 | DX14: 0 | DY14: 0 | DZ14: 0 | EA14: 0 | EB14: 0 | EC14: 0 | ED14: 0 | EE14: 0 | EF14: 0 | EG14: 0 | EH14: 0 | EI14: 0 | EJ14: 0 | EK14: 0 | EL14: 0 | EM14: 0 | EN14: 0 | EO14: 0 | EP14: 0 | EQ14: 0 | ER14: 0 | ES14: 0 | ET14: 0 | EU14: 1 | EV14: 0 | EW14: 0 | EX14: 0
A15: 6 | B15: 3 | C15: SOUTH ST. PAUL | D15: =SUMIF(I$5:EX$5,Snumber,I15:EX15) -> 0 | F15: 6 | G15: 3 | H15: SOUTH ST. PAUL | I15: 0 | J15: 0 | K15: 0 | L15: 0 | M15: 0 | N15: 0 | O15: 0 | P15: 0 | Q15: 0 | R15: 0 | S15: 0 | T15: 0 | U15: 1.66 | V15: 0.12 | W15: 0 | X15: 2.12 | Y15: 0 | Z15: 2.47 | AA15: 0 | AB15: 0 | AC15: 0 | AD15: 1.38 | AE15: 0 | AF15: 0 | AG15: 0 | AH15: 0 | AI15: 0.12 | AJ15: 0 | AK15: 0 | AL15: 0 | AM15: 0 | AN15: 0 | AO15: 0 | AP15: 0 | AQ15: 0 | AR15: 0 | AS15: 0 | AT15: 0 | AU15: 0 | AV15: 0 | AW15: 0 | AX15: 0 | AY15: 0 | AZ15: 0 | BA15: 0 | BB15: 0 | BC15: 0 | BD15: 0 | BE15: 0 | BF15: 0 | BG15: 3.36 | BH15: 0 | BI15: 0.75 | BJ15: 0 | BK15: 0 | BL15: 0 | BM15: 0 | BN15: 0 | BO15: 4.69 | BP15: 0 | BQ15: 0 | BR15: 0 | BS15: 0 | BT15: 0 | BU15: 0 | BV15: 0 | BW15: 0 | BX15: 0 | BY15: 0 | BZ15: 0 | CA15: 0 | CB15: 0 | CC15: 1.3 | CD15: 2.38 | CE15: 0 | CF15: 0 | CG15: 0 | CH15: 0 | CI15: 0 | CJ15: 0 | CK15: 0 | CL15: 0 | CM15: 0 | CN15: 3.43 | CO15: 0 | CP15: 0 | CQ15: 2.59 | CR15: 0 | CS15: 0 | CT15: 0 | CU15: 0 | CV15: 0 | CW15: 17.01 | CX15: 0 | CY15: 0 | CZ15: 0 | DA15: 0 | DB15: 0 | DC15: 0 | DD15: 0 | DE15: 0 | DF15: 0 | DG15: 0 | DH15: 0 | DI15: 0 | DJ15: 0 | DK15: 0 | DL15: 0 | DM15: 0 | DN15: 1.12 | DO15: 0.25 | DP15: 0 | DQ15: 0 | DR15: 0 | DS15: 0 | DT15: 0 | DU15: 0 | DV15: 0 | DW15: 1.83 | DX15: 0.7 | DY15: 1.12 | DZ15: 0 | EA15: 0 | EB15: 0 | EC15: 0 | ED15: 0 | EE15: 0 | EF15: 0 | EG15: 0 | EH15: 0 | EI15: 0 | EJ15: 0 | EK15: 0 | EL15: 0 | EM15: 0 | EN15: 0 | EO15: 0 | EP15: 0 | EQ15: 0 | ER15: 0 | ES15: 0 | ET15: 0 | EU15: 0 | EV15: 0 | EW15: 0 | EX15: 0
A16: 11 | B16: 1 | C16: ANOKA-HENNEPIN | D16: =SUMIF(I$5:EX$5,Snumber,I16:EX16) -> 0 | F16: 11 | G16: 1 | H16: ANOKA-HENNEPIN | I16: 0 | J16: 0 | K16: 0 | L16: 0 | M16: 1.01 | N16: 0 | O16: 0 | P16: 477.24 | Q16: 2.36 | R16: 0 | S16: 2.42 | T16: 0 | U16: 40.69 | V16: 0 | W16: 0 | X16: 5.61 | Y16: 0 | Z16: 0 | AA16: 0 | AB16: 1.68 | AC16: 29.39 | AD16: 0 | AE16: 2.18 | AF16: 0 | AG16: 0 | AH16: 0.17 | AI16: 2.62 | AJ16: 0 | AK16: 0 | AL16: 0.31 | AM16: 0 | AN16: 0 | AO16: 0 | AP16: 165.05 | AQ16: 0 | AR16: 0 | AS16: 0 | AT16: 0 | AU16: 0 | AV16: 0 | AW16: 0 | AX16: 0 | AY16: 0 | AZ16: 0 | BA16: 0 | BB16: 0 | BC16: 2.18 | BD16: 23.79 | BE16: 0 | BF16: 0 | BG16: 0 | BH16: 3.9 | BI16: 0 | BJ16: 5.38 | BK16: 2.01 | BL16: 0 | BM16: 0 | BN16: 0 | BO16: 13.55 | BP16: 0 | BQ16: 0 | BR16: 0 | BS16: 8.43 | BT16: 19.59 | BU16: 0 | BV16: 3.53 | BW16: 0 | BX16: 0 | BY16: 0 | BZ16: 0 | CA16: 1.05 | CB16: 0 | CC16: 0.05 | CD16: 0 | CE16: 0 | CF16: 0 | CG16: 5.2 | CH16: 11.48 | CI16: 169.28 | CJ16: 0 | CK16: 0 | CL16: 0 | CM16: 0 | CN16: 35.72 | CO16: 0.16 | CP16: 6.11 | CQ16: 15.41 | CR16: 1.37 | CS16: 0 | CT16: 0 | CU16: 14.33 | CV16: 0 | CW16: 0 | CX16: 0 | CY16: 2.1 | CZ16: 0 | DA16: 0 | DB16: 7.17 | DC16: 0 | DD16: 0 | DE16: 0 | DF16: 0 | DG16: 0 | DH16: 1.04 | DI16: 0 | DJ16: 0 | DK16: 0 | DL16: 0 | DM16: 0 | DN16: 2.24 | DO16: 0 | DP16: 0 | DQ16: 13.15 | DR16: 0 | DS16: 0 | DT16: 0 | DU16: 4.58 | DV16: 91.38 | DW16: 9.55 | DX16: 0 | DY16: 1.12 | DZ16: 1.12 | EA16: 0 | EB16: 0 | EC16: 0.39 | ED16: 0 | EE16: 0 | EF16: 9.1 | EG16: 0 | EH16: 0 | EI16: 0.01 | EJ16: 0 | EK16: 0 | EL16: 0 | EM16: 0 | EN16: 0 | EO16: 0 | EP16: 0 | EQ16: 0 | ER16: 0 | ES16: 0 | ET16: 0 | EU16: 0 | EV16: 0 | EW16: 0 | EX16: 0
A17: 12 | B17: 1 | C17: CENTENNIAL | D17: =SUMIF(I$5:EX$5,Snumber,I17:EX17) -> 0 | F17: 12 | G17: 1 | H17: CENTENNIAL | I17: 0 | J17: 0 | K17: 0 | L17: 0 | M17: 0 | N17: 0 | O17: 0 | P17: 2.86 | Q17: 2.18 | R17: 0 | S17: 1.47 | T17: 0 | U17: 1.3 | V17: 0 | W17: 0 | X17: 4.72 | Y17: 0 | Z17: 0 | AA17: 0 | AB17: 0 | AC17: 0 | AD17: 0 | AE17: 0 | AF17: 2.18 | AG17: 0 | AH17: 0 | AI17: 1.2 | AJ17: 0 | AK17: 0 | AL17: 0 | AM17: 0 | AN17: 0 | AO17: 0 | AP17: 0 | AQ17: 0 | AR17: 0 | AS17: 0 | AT17: 0 | AU17: 0 | AV17: 0 | AW17: 0 | AX17: 0 | AY17: 0 | AZ17: 0 | BA17: 0 | BB17: 0 | BC17: 0 | BD17: 2.18 | BE17: 1.12 | BF17: 0 | BG17: 0 | BH17: 6.79 | BI17: 1.3 | BJ17: 0 | BK17: 0 | BL17: 0 | BM17: 0 | BN17: 0 | BO17: 1.17 | BP17: 0 | BQ17: 0 | BR17: 0 | BS17: 0 | BT17: 0 | BU17: 0 | BV17: 0 | BW17: 0 | BX17: 0 | BY17: 0 | BZ17: 0 | CA17: 0.61 | CB17: 0 | CC17: 1.12 | CD17: 0.53 | CE17: 0 | CF17: 0 | CG17: 0 | CH17: 0 | CI17: 1.3 | CJ17: 3.59 | CK17: 0 | CL17: 0 | CM17: 0 | CN17: 1.3 | CO17: 0 | CP17: 0 | CQ17: 1.3 | CR17: 0 | CS17: 0 | CT17: 0 | CU17: 15.34 | CV17: 0 | CW17: 0 | CX17: 0 | CY17: 0 | CZ17: 0 | DA17: 0 | DB17: 0 | DC17: 0 | DD17: 0 | DE17: 0 | DF17: 0 | DG17: 0 | DH17: 0 | DI17: 0 | DJ17: 0 | DK17: 0 | DL17: 0 | DM17: 0 | DN17: 0.27 | DO17: 0 | DP17: 0 | DQ17: 0.06 | DR17: 0 | DS17: 0 | DT17: 0 | DU17: 1.3 | DV17: 1.06 | DW17: 0 | DX17: 0 | DY17: 0 | DZ17: 0 | EA17: 0 | EB17: 0 | EC17: 0 | ED17: 0 | EE17: 0 | EF17: 0 | EG17: 0 | EH17: 0 | EI17: 0 | EJ17: 0 | EK17: 0 | EL17: 0 | EM17: 0 | EN17: 0 | EO17: 0 | EP17: 0 | EQ17: 0 | ER17: 0 | ES17: 0 | ET17: 0 | EU17: 0 | EV17: 0 | EW17: 0 | EX17: 0
A18: 13 | B18: 1 | C18: COLUMBIA HEIGHTS | D18: =SUMIF(I$5:EX$5,Snumber,I18:EX18) -> 0 | F18: 13 | G18: 1 | H18: COLUMBIA HEIGHTS | I18: 0 | J18: 0 | K18: 0 | L18: 0 | M18: 0 | N18: 0 | O18: 0 | P18: 0 | Q18: 6.73 | R18: 0 | S18: 0 | T18: 0 | U18: 6.28 | V18: 0 | W18: 0 | X18: 0 | Y18: 0 | Z18: 0.93 | AA18: 0 | AB18: 0 | AC18: 1.62 | AD18: 0.51 | AE18: 0 | AF18: 0 | AG18: 0 | AH18: 0 | AI18: 0 | AJ18: 0 | AK18: 0 | AL18: 4.43 | AM18: 0 | AN18: 0 | AO18: 0 | AP18: 0.39 | AQ18: 0 | AR18: 5.92 | AS18: 0 | AT18: 0 | AU18: 0 | AV18: 0 | AW18: 0 | AX18: 0 | AY18: 0 | AZ18: 0 | BA18: 0 | BB18: 0 | BC18: 1.06 | BD18: 2.18 | BE18: 0 | BF18: 0 | BG18: 0 | BH18: 6.5 | BI18: 0.59 | BJ18: 7.69 | BK18: 10.28 | BL18: 0 | BM18: 0 | BN18: 0 | BO18: 6.08 | BP18: 0 | BQ18: 0 | BR18: 0 | BS18: 2.18 | BT18: 0 | BU18: 0 | BV18: 1.68 | BW18: 0 | BX18: 0 | BY18: 0 | BZ18: 0 | CA18: 0 | CB18: 0.4 | CC18: 4.41 | CD18: 0 | CE18: 0 | CF18: 0 | CG18: 2.78 | CH18: 5.4 | CI18: 1.82 | CJ18: 0 | CK18: 0 | CL18: 0 | CM18: 0 | CN18: 1.48 | CO18: 0 | CP18: 7.48 | CQ18: 1.3 | CR18: 1.12 | CS18: 0 | CT18: 0 | CU18: 0 | CV18: 0 | CW18: 0 | CX18: 0 | CY18: 9.01 | CZ18: 0 | DA18: 0 | DB18: 0 | DC18: 0 | DD18: 0 | DE18: 0 | DF18: 1.46 | DG18: 0 | DH18: 0 | DI18: 0 | DJ18: 0 | DK18: 0 | DL18: 0 | DM18: 0 | DN18: 0 | DO18: 0 | DP18: 0 | DQ18: 0 | DR18: 0 | DS18: 0 | DT18: 0 | DU18: 39.99 | DV18: 0 | DW18: 0 | DX18: 0 | DY18: 0 | DZ18: 0 | EA18: 0 | EB18: 0 | EC18: 0 | ED18: 0 | EE18: 0 | EF18: 0 | EG18: 0 | EH18: 0 | EI18: 6.96 | EJ18: 0 | EK18: 0 | EL18: 0 | EM18: 0 | EN18: 0 | EO18: 0 | EP18: 0 | EQ18: 0 | ER18: 0 | ES18: 0 | ET18: 0 | EU18: 0 | EV18: 0 | EW18: 0 | EX18: 0
A19: 14 | B19: 1 | C19: FRIDLEY | D19: =SUMIF(I$5:EX$5,Snumber,I19:EX19) -> 0 | F19: 14 | G19: 1 | H19: FRIDLEY | I19: 0 | J19: 0 | K19: 0 | L19: 0 | M19: 0 | N19: 0 | O19: 0 | P19: 0 | Q19: 0 | R19: 0 | S19: 0 | T19: 0 | U19: 4.08 | V19: 0 | W19: 0 | X19: 3.66 | Y19: 0 | Z19: 0.81 | AA19: 0 | AB19: 0 | AC19: 0 | AD19: 0 | AE19: 0 | AF19: 0 | AG19: 0 | AH19: 0 | AI19: 0 | AJ19: 0 | AK19: 0 | AL19: 0 | AM19: 0 | AN19: 0 | AO19: 0 | AP19: 1 | AQ19: 0 | AR19: 0.17 | AS19: 0 | AT19: 0 | AU19: 0 | AV19: 0 | AW19: 0 | AX19: 0 | AY19: 0 | AZ19: 0 | BA19: 0 | BB19: 0 | BC19: 0 | BD19: 0 | BE19: 0 | BF19: 0 | BG19: 0 | BH19: 3.9 | BI19: 0 | BJ19: 3.93 | BK19: 2.37 | BL19: 0 | BM19: 0 | BN19: 0 | BO19: 0 | BP19: 0 | BQ19: 0 | BR19: 0 | BS19: 0 | BT19: 0 | BU19: 0 | BV19: 1.12 | BW19: 0 | BX19: 0 | BY19: 0 | BZ19: 0 | CA19: 0 | CB19: 0 | CC19: 0 | CD19: 0 | CE19: 0 | CF19: 0 | CG19: 1.27 | CH19: 2.77 | CI19: 5.69 | CJ19: 0 | CK19: 0 | CL19: 0 | CM19: 0 | CN19: 0.8 | CO19: 0 | CP19: 1.3 | CQ19: 1.3 | CR19: 0.48 | CS19: 3.04 | CT19: 0 | CU19: 0 | CV19: 0 | CW19: 0 | CX19: 0 | CY19: 1.51 | CZ19: 0 | DA19: 0 | DB19: 0 | DC19: 0 | DD19: 0 | DE19: 0 | DF19: 0 | DG19: 0 | DH19: 0 | DI19: 0 | DJ19: 0.82 | DK19: 0 | DL19: 0 | DM19: 0 | DN19: 1.12 | DO19: 0 | DP19: 0 | DQ19: 0 | DR19: 0 | DS19: 0 | DT19: 0 | DU19: 21.48 | DV19: 0 | DW19: 0 | DX19: 0 | DY19: 1.68 | DZ19: 0 | EA19: 0 | EB19: 0 | EC19: 0 | ED19: 0 | EE19: 0 | EF19: 0 | EG19: 0 | EH19: 0 | EI19: 2.36 | EJ19: 0 | EK19: 0 | EL19: 0 | EM19: 0 | EN19: 0 | EO19: 0 | EP19: 0 | EQ19: 0 | ER19: 0 | ES19: 0 | ET19: 0 | EU19: 0 | EV19: 0 | EW19: 0 | EX19: 0
A20: 15 | B20: 1 | C20: ST. FRANCIS | D20: =SUMIF(I$5:EX$5,Snumber,I20:EX20) -> 0 | F20: 15 | G20: 1 | H20: ST. FRANCIS | I20: 0 | J20: 0 | K20: 0 | L20: 0 | M20: 0 | N20: 0 | O20: 0 | P20: 56.13 | Q20: 0 | R20: 0 | S20: 0 | T20: 0 | U20: 2.11 | V20: 0 | W20: 0 | X20: 0 | Y20: 0 | Z20: 0 | AA20: 0 | AB20: 0 | AC20: 0 | AD20: 0 | AE20: 0 | AF20: 0 | AG20: 0 | AH20: 0 | AI20: 0 | AJ20: 0 | AK20: 0 | AL20: 0 | AM20: 0 | AN20: 0 | AO20: 0 | AP20: 2.73 | AQ20: 0 | AR20: 0 | AS20: 2.36 | AT20: 0 | AU20: 0 | AV20: 0 | AW20: 0 | AX20: 0 | AY20: 0 | AZ20: 0 | BA20: 0 | BB20: 0 | BC20: 0 | BD20: 0 | BE20: 0 | BF20: 0 | BG20: 0 | BH20: 2.6 | BI20: 0 | BJ20: 0 | BK20: 0 | BL20: 0 | BM20: 0 | BN20: 0 | BO20: 13.76 | BP20: 0 | BQ20: 0 | BR20: 0 | BS20: 0 | BT20: 0 | BU20: 0 | BV20: 0 | BW20: 0 | BX20: 0 | BY20: 0 | BZ20: 0 | CA20: 2.6 | CB20: 0 | CC20: 0.56 | CD20: 0 | CE20: 0 | CF20: 0 | CG20: 0 | CH20: 0 | CI20: 2.81 | CJ20: 0 | CK20: 0 | CL20: 0 | CM20: 0 | CN20: 0 | CO20: 0 | CP20: 0 | CQ20: 1.3 | CR20: 0 | CS20: 0 | CT20: 0 | CU20: 12.58 | CV20: 0 | CW20: 0 | CX20: 0 | CY20: 0 | CZ20: 0 | DA20: 0 | DB20: 0 | DC20: 0 | DD20: 0 | DE20: 0 | DF20: 0 | DG20: 0 | DH20: 0 | DI20: 0 | DJ20: 0 | DK20: 0 | DL20: 0 | DM20: 0 | DN20: 0 | DO20: 0 | DP20: 0 | DQ20: 0 | DR20: 0 | DS20: 0 | DT20: 0 | DU20: 2.36 | DV20: 2.36 | DW20: 1.92 | DX20: 0 | DY20: 0 | DZ20: 0 | EA20: 0 | EB20: 0 | EC20: 0 | ED20: 0 | EE20: 0 | EF20: 0 | EG20: 0 | EH20: 0 | EI20: 0 | EJ20: 0 | EK20: 0 | EL20: 0 | EM20: 0 | EN20: 0 | EO20: 0 | EP20: 0 | EQ20: 0 | ER20: 0 | ES20: 0 | ET20: 0 | EU20: 0 | EV20: 0 | EW20: 0 | EX20: 0
A21: 16 | B21: 1 | C21: SPRING LAKE PARK | D21: =SUMIF(I$5:EX$5,Snumber,I21:EX21) -> 0 | F21: 16 | G21: 1 | H21: SPRING LAKE PARK | I21: 0 | J21: 0 | K21: 0 | L21: 0 | M21: 0 | N21: 0 | O21: 0 | P21: 2.19 | Q21: 0.45 | R21: 0 | S21: 0 | T21: 0 | U21: 0.53 | V21: 0 | W21: 0 | X21: 0 | Y21: 0 | Z21: 0 | AA21: 0 | AB21: 0 | AC21: 0 | AD21: 0 | AE21: 0 | AF21: 0 | AG21: 0 | AH21: 0.92 | AI21: 1.18 | AJ21: 0 | AK21: 0 | AL21: 9.14 | AM21: 0 | AN21: 0 | AO21: 0 | AP21: 1.4 | AQ21: 0 | AR21: 0 | AS21: 0 | AT21: 0 | AU21: 0 | AV21: 0 | AW21: 0 | AX21: 0 | AY21: 0 | AZ21: 0 | BA21: 0 | BB21: 0 | BC21: 0 | BD21: 0 | BE21: 0 | BF21: 0 | BG21: 0 | BH21: 1.3 | BI21: 0 | BJ21: 0 | BK21: 0 | BL21: 0 | BM21: 0 | BN21: 0 | BO21: 0.77 | BP21: 0 | BQ21: 0 | BR21: 0 | BS21: 0 | BT21: 1.14 | BU21: 0 | BV21: 0 | BW21: 0 | BX21: 0 | BY21: 0 | BZ21: 0 | CA21: 0 | CB21: 0 | CC21: 0 | CD21: 0 | CE21: 0 | CF21: 0 | CG21: 0 | CH21: 0 | CI21: 5.51 | CJ21: 0 | CK21: 0 | CL21: 0 | CM21: 0 | CN21: 3.65 | CO21: 0 | CP21: 0 | CQ21: 0 | CR21: 0 | CS21: 0 | CT21: 0 | CU21: 1.62 | CV21: 0 | CW21: 0 | CX21: 0 | CY21: 0 | CZ21: 0 | DA21: 0 | DB21: 0.56 | DC21: 0 | DD21: 0 | DE21: 0 | DF21: 0 | DG21: 0 | DH21: 0 | DI21: 0 | DJ21: 0 | DK21: 0 | DL21: 0 | DM21: 0 | DN21: 0 | DO21: 0 | DP21: 0 | DQ21: 0 | DR21: 0 | DS21: 0 | DT21: 0 | DU21: 5.15 | DV21: 0 | DW21: 0 | DX21: 0 | DY21: 1.12 | DZ21: 0.5 | EA21: 0 | EB21: 0 | EC21: 0.86 | ED21: 0 | EE21: 0 | EF21: 0 | EG21: 0 | EH21: 0 | EI21: 0 | EJ21: 0 | EK21: 0 | EL21: 0 | EM21: 0 | EN21: 0 | EO21: 0 | EP21: 0 | EQ21: 0 | ER21: 0 | ES21: 0 | ET21: 0 | EU21: 0 | EV21: 0 | EW21: 0 | EX21: 0
A22: 22 | B22: 1 | C22: DETROIT LAKES | D22: =SUMIF(I$5:EX$5,Snumber,I22:EX22) -> 0 | F22: 22 | G22: 1 | H22: DETROIT LAKES | I22: 0 | J22: 0 | K22: 0 | L22: 0 | M22: 0 | N22: 0 | O22: 0 | P22: 0 | Q22: 0 | R22: 0 | S22: 0 | T22: 0 | U22: 0 | V22: 0 | W22: 0 | X22: 0 | Y22: 0 | Z22: 0 | AA22: 0 | AB22: 0 | AC22: 0 | AD22: 0 | AE22: 0 | AF22: 0 | AG22: 0 | AH22: 0 | AI22: 0 | AJ22: 0 | AK22: 0 | AL22: 0 | AM22: 0 | AN22: 0 | AO22: 0 | AP22: 0 | AQ22: 0 | AR22: 0 | AS22: 0 | AT22: 0 | AU22: 0 | AV22: 0 | AW22: 0 | AX22: 0 | AY22: 0 | AZ22: 0 | BA22: 0 | BB22: 0 | BC22: 0 | BD22: 0 | BE22: 0 | BF22: 0 | BG22: 0 | BH22: 0 | BI22: 0 | BJ22: 0 | BK22: 0 | BL22: 0 | BM22: 0 | BN22: 0 | BO22: 1.34 | BP22: 0 | BQ22: 0 | BR22: 0 | BS22: 0 | BT22: 0 | BU22: 0 | BV22: 0 | BW22: 0 | BX22: 0 | BY22: 0 | BZ22: 0 | CA22: 0 | CB22: 0 | CC22: 0 | CD22: 0 | CE22: 0 | CF22: 0 | CG22: 0 | CH22: 0 | CI22: 0 | CJ22: 0 | CK22: 0 | CL22: 0 | CM22: 0 | CN22: 0 | CO22: 0 | CP22: 0 | CQ22: 0 | CR22: 0 | CS22: 0 | CT22: 0 | CU22: 0 | CV22: 0 | CW22: 0 | CX22: 0 | CY22: 0 | CZ22: 0 | DA22: 0 | DB22: 0 | DC22: 0 | DD22: 0 | DE22: 0 | DF22: 0 | DG22: 0 | DH22: 0 | DI22: 0 | DJ22: 0 | DK22: 0 | DL22: 0 | DM22: 0 | DN22: 0 | DO22: 0 | DP22: 0 | DQ22: 0 | DR22: 0 | DS22: 0 | DT22: 0 | DU22: 0 | DV22: 0 | DW22: 0.35 | DX22: 0 | DY22: 0 | DZ22: 0 | EA22: 0 | EB22: 0 | EC22: 0 | ED22: 0 | EE22: 0 | EF22: 0 | EG22: 0 | EH22: 0 | EI22: 0 | EJ22: 0 | EK22: 0 | EL22: 0 | EM22: 0 | EN22: 0 | EO22: 0 | EP22: 0 | EQ22: 0 | ER22: 0 | ES22: 0 | ET22: 0 | EU22: 0 | EV22: 0 | EW22: 0 | EX22: 0
... A350: 2902 | B350: 1 | C350: RUSSELL-TYLER-RUTHTON | D350: =SUMIF(I$5:EX$5,Snumber,I350:EX350) -> 0 | F350: 2902 | G350: 1 | H350: RUSSELL-TYLER-RUTHTON | I350: 0 | J350: 0 | K350: 0 | L350: 0 | M350: 0 | N350: 0 | O350: 0 | P350: 0 | Q350: 0 | R350: 0 | S350: 0 | T350: 0 | U350: 0 | V350: 0 | W350: 0 | X350: 0 | Y350: 0 | Z350: 0 | AA350: 0 | AB350: 0 | AC350: 0 | AD350: 0 | AE350: 0 | AF350: 0 | AG350: 0 | AH350: 0 | AI350: 0 | AJ350: 0 | AK350: 0 | AL350: 0 | AM350: 0 | AN350: 0 | AO350: 0 | AP350: 0 | AQ350: 0 | AR350: 0 | AS350: 0 | AT350: 0 | AU350: 0 | AV350: 0 | AW350: 0 | AX350: 0 | AY350: 0 | AZ350: 0 | BA350: 0 | BB350: 0 | BC350: 0 | BD350: 0 | BE350: 0 | BF350: 1.14 | BG350: 0 | BH350: 0 | BI350: 0 | BJ350: 0 | BK350: 0 | BL350: 0 | BM350: 0 | BN350: 0 | BO350: 0 | BP350: 0 | BQ350: 0 | BR350: 0 | BS350: 0 | BT350: 0 | BU350: 0 | BV350: 0 | BW350: 0 | BX350: 0 | BY350: 0 | BZ350: 0 | CA350: 0 | CB350: 0 | CC350: 0 | CD350: 0 | CE350: 0 | CF350: 0 | CG350: 0 | CH350: 0 | CI350: 0 | CJ350: 0 | CK350: 0 | CL350: 0 | CM350: 0 | CN350: 0 | CO350: 0 | CP350: 0 | CQ350: 0 | CR350: 0 | CS350: 0 | CT350: 0 | CU350: 0 | CV350: 0 | CW350: 0 | CX350: 0 | CY350: 0 | CZ350: 0 | DA350: 0 | DB350: 0 | DC350: 0 | DD350: 0 | DE350: 0 | DF350: 0 | DG350: 0 | DH350: 0 | DI350: 0 | DJ350: 0 | DK350: 0 | DL350: 0 | DM350: 0 | DN350: 0 | DO350: 0 | DP350: 0 | DQ350: 0 | DR350: 0 | DS350: 0 | DT350: 0 | DU350: 0 | DV350: 0 | DW350: 0 | DX350: 0 | DY350: 0 | DZ350: 0 | EA350: 0 | EB350: 0 | EC350: 0 | ED350: 0 | EE350: 0 | EF350: 0 | EG350: 0 | EH350: 0 | EI350: 0 | EJ350: 0 | EK350: 0 | EL350: 0 | EM350: 0 | EN350: 0 | EO350: 0 | EP350: 0 | EQ350: 0 | ER350: 0 | ES350: 0 | ET350: 0 | EU350: 0 | EV350: 0 | EW350: 0 | EX350: 0

Sheet Outputs
A4: 1
A5: 1
A6: 1 | B6: 4000 | C6: 7 | D6: CITY ACADEMY | E6: 114.42 | F6: 145.43 | G6: 73.45 | H6: 29.58 | I6: 0
A7: 1 | B7: 4001 | C7: 7 | D7: BLUFFVIEW MONTESSORI | E7: 114.57 | F7: 51.97 | G7: 11.8 | H7: 10.85 | I7: 10.12
A8: 1 | B8: 4003 | C8: 7 | D8: NEW HEIGHTS SCHOOL, INC. | E8: 7.02 | F8: 6.66 | G8: 3.23 | H8: 1.71 | I8: 0.38
A9: 1 | B9: 4004 | C9: 7 | D9: CEDAR RIVERSIDE COMMUNITY SCHO | E9: 0 | F9: 0 | G9: 0 | H9: 0 | I9: 0
A10: 1 | B10: 4005 | C10: 7 | D10: METRO DEAF CHARTER SCHOOL | E10: 101.85 | F10: 93.01 | G10: 46.54 | H10: 22.33 | I10: 4.09
A11: 1 | B11: 4006 | C11: 7 | D11: SKILLS FOR TOMORROW CHARTER SC | E11: 79.44 | F11: 99.83 | G11: 50.23 | H11: 20.23 | I11: 0
A12: 1 | B12: 4007 | C12: 7 | D12: MINNESOTA NEW COUNTRY SCHOOL | E12: 173.86 | F12: 154.27 | G12: 135.5 | H12: 88.07 | I12: 75.68
A13: 1 | B13: 4008 | C13: 7 | D13: PACT CHARTER SCHOOL | E13: 188 | F13: 149.05 | G13: 87.17 | H13: 58.79 | I13: 31.48
A14: 1 | B14: 4011 | C14: 7 | D14: NEW VISIONS CHARTER SCHOOL | E14: 10.73 | F14: 7.06 | G14: 4.03 | H14: 3.35 | I14: 2.55
A15: 1 | B15: 4012 | C15: 7 | D15: EMILY CHARTER SCHOOL | E15: 50.9 | F15: 13.92 | G15: 0.48 | H15: 0.2 | I15: 0.28
A16: 1 | B16: 4015 | C16: 7 | D16: COMMUNITY OF PEACE ACADEMY | E16: 110.86 | F16: 138.46 | G16: 69.94 | H16: 28.58 | I16: 0.51
A17: 1 | B17: 4016 | C17: 7 | D17: WORLD LEARNER CHARTER SCHOOL | E17: 63.75 | F17: 20.06 | G17: 0.2 | H17: 0.15 | I17: 0.12
... A136: 1 | B136: 4163 | C136: 7 | D136: LEARNING FOR LEADERSHIP CHARTER | E136: 4.58 | F136: 0.83 | G136: 0.01 | H136: 0.01 | I136: 0
A137: 1 | B137: 4165 | C137: 7 | D137: ELOM INTERNATIONAL SCHOOL | E137: n/a | F137: 14.26 | G137: 0 | H137: 0 | I137: 0
A138: 1 | B138: 4166 | C138: 7 | D138: EAST RANGE ACADEMY OF TECH &SCIENCE | E138: n/a | F138: 213.42 | G138: 194.66 | H138: 165.52 | I138: 153.2
A139: 1 | B139: 4167 | C139: 7 | D139: INTERNATIONAL SPANISH LANGUAGE ACAD | E139: n/a | F139: 0 | G139: 0 | H139: 0 | I139: 0
A140: 1 | B140: 4168 | C140: 7 | D140: GLACIAL HILLS ELEMENTARY | E140: n/a | F140: 219.07 | G140: 142.62 | H140: 88.94 | I140: 40.59
A141: 1 | B141: 4169 | C141: 7 | D141: ELLIOT PARK COMMUNITY SCHOOL | E141: n/a | F141: 0 | G141: 0 | H141: 0 | I141: 0
A142: 1 | B142: 4170 | C142: 7 | D142: HIAWATHA LEADERSHIP ACADEMY | E142: n/a | F142: 0 | G142: 0 | H142: 0 | I142: 0
A143: 1 | B143: 4171 | C143: 7 | D143: NOBLE ACADEMY | E143: n/a | F143: 14.26 | G143: 0 | H143: 0 | I143: 0
A144: 1 | B144: 4172 | C144: 7 | D144: CLARKFIELD CHARTER SCHOOL | E144: n/a | F144: 559.35 | G144: 504.8 | H144: 511.98 | I144: 485.41
A145: 1 | B145: 4173 | C145: 7 | D145: DUNWOODY ACADEMY | E145: n/a | F145: 0 | G145: 0 | H145: 0 | I145: 0
A146: 1 | B146: 4174 | C146: 7 | D146: PINE GROVE LEADERSHIP ACADEMY | E146: n/a | F146: 43.11 | G146: 30.99 | H146: 55.57 | I146: 45.15
A147: 1 | B147: 4175 | C147: 7 | D147: LONG TIENG ACADEMY | E147: n/a | F147: 0 | G147: 0 | H147: 0 | I147: 0
A148: 1 | B148: 4177 | C148: 7 | D148: MINISINAAKWAANG LEADERSHIP ACADEMY | E148: n/a | F148: 0.1 | G148: 0 | H148: 0 | I148: 0
... A151: 1 | B151: 4181 | C151: 7 | D151: COMMUNITY SCHOOL OF EXCELLENCE | E151: n/a | F151: 145.43 | G151: 73.45 | H151: 29.58 | I151: 0
