Workbook

Sheet Excess Cost
A1: Excess Cost Worksheet
A2: ` | B2: District | D2: =IF(ISBLANK(C2),"-",VLOOKUP(C2,Data!B2:C307,2,FALSE)) -> - | H2: Year: | I2: 2011-2012
B3: Note: All requested data are from the prior school year (the 2010-2011 school year).
A4: Prior school year total expenditures from all sources less capital outlay and debt service.
E6: Secondary (9-12, NG) | H6: Elementary (PreK-8)
A7: Total Expenditures
B8: State & Local | H8: =IF(ISBLANK(E8),0,Totals!E6-'Excess Cost'!E8) -> 0
B9: Federal | H9: =IF(ISBLANK(E9),0,Totals!E7-'Excess Cost'!E9) -> 0
A10: Total Expenditures from all Sources | F10: =SUM(E8:E9) -> 0 | I10: =SUM(H8:H9) -> 0
A11: Less Capital Outlay & Debt Services
B12: Capital Outlay | H12: =IF(ISBLANK(E12),0,Totals!E10-'Excess Cost'!E12) -> 0
B13: Debt Services | H13: =IF(ISBLANK(E13),0,Totals!E11-'Excess Cost'!E13) -> 0
A14: Total Capital Outlay & Debt Services | F14: =SUM(E12:E13) -> 0 | I14: =SUM(H12:H13) -> 0
A15: Total Expenditures less Capital Outlay
A16: & Debt Services | F16: =F10-F14 -> 0 | I16: =I10-I14 -> 0
A19: Deduct prior Year's Special Education Expenditures.
E20: Secondary (9-12, NG) | H20: Elementary (PreK-8)
A21: Special Education Expenditures
B22: ESEA Title I, Part A | H22: =IF(ISBLANK(E22),0,Totals!E19-'Excess Cost'!E22) -> 0
B23: ESEA Title III, Parts A & B | H23: =IF(ISBLANK(E23),0,Totals!E20-'Excess Cost'!E23) -> 0
B24: State and Local special education funds | H24: =IF(ISBLANK(E24),0,Totals!E21-'Excess Cost'!E24) -> 0
B25: State and local funds for programs under
B26: ESEA Title I, Part A, and ESEA Title III, Parts A & B | H26: =IF(ISBLANK(E26),0,Totals!E23-'Excess Cost'!E26) -> 0
A27: Total special education deductions | F27: =SUM(E22:E26) -> 0 | I27: =SUM(H22:H26) -> 0
A28: Total Expenditures less
A29: Special Education Expenditures | F29: =F16-F27 -> 0 | I29: =I16-I27 -> 0
A31: School enrollments
E32: Secondary (9-12, NG) | H32: Elementary (PreK-8)
A33: Prior year's September 20 count | F33: =IF(ISBLANK(C2),"-",VLOOKUP(C2,Data!B2:Q307,15,FALSE)) -> - | I33: =IF(ISBLANK(C2),"-",Totals!F30-'Excess Cost'!F33) -> -
B37: Please return a copy of the completed Excel file to your Coop/Interlocal Special Education Director.
B38: Do not send a faxed or printed copy.

Sheet Totals
B2: District | C2: ='Excess Cost'!C2 -> 0 | D2: ='Excess Cost'!D2:E2 -> - | H2: Note: The data provided on this tab is informational only and is directly populated from the annual district budgets submitted to KSDE in July. No action is required by district officials on this tab.
E4: Total for District
A5: Total Expenditures
B6: State & Local | E6: =VLOOKUP(C2,Data!B2:P307,3,FALSE) -> #N/A
B7: Federal | E7: =VLOOKUP(C2,Data!B2:P307,4,FALSE) -> #N/A
A8: Total Expenditures from all Sources | F8: =SUM(E6:E7) -> #N/A
A9: Less Capital Outlay & Debt Services
B10: Capital Outlay | E10: =VLOOKUP(C2,Data!B2:P307,5,FALSE) -> #N/A
B11: Debt Services | E11: =VLOOKUP(C2,Data!B2:P307,6,FALSE) -> #N/A
A12: Total Capital Outlay & Debt Services | F12: =SUM(E10:E11) -> #N/A
A13: Total Expenditures less Capital Outlay
A14: & Debt Services | F14: =F8-F12 -> #N/A
E17: Total for District
A18: Special Education Expenditures
B19: ESEA Title I, Part A | E19: =VLOOKUP(C2,Data!B2:Q307,8,FALSE) -> #N/A
B20: ESEA Title III, Parts A & B | E20: =VLOOKUP(C2,Data!B2:Q307,9,FALSE) -> #N/A
B21: State and Local special education funds | E21: =VLOOKUP(C2,Data!B2:Q307,10,FALSE) -> #N/A
B22: State and local funds for programs under
B23: ESEA Title I, Part A, and ESEA Title III, Parts A & B | E23: =VLOOKUP(C2,Data!B2:Q307,13,FALSE) -> #N/A
A24: Total special education deductions | F24: =SUM(E19:E23) -> #N/A
A25: Total Expenditures less
A26: Special Education Expenditures | F26: =F14-F24 -> #N/A
E29: Total for District
A30: Prior year's September 20 count | F30: =VLOOKUP(C2,Data!B2:Q307,14,FALSE)+VLOOKUP(C2,Data!B2:Q307,15,FALSE) -> #N/A

Sheet Data
A1: Coop | B1: USD# | C1: USD_Name | D1: Ln1:Non-Fed Exp | E1: Ln2:Federal Exp (Code 7) | F1: Cap_Outlay | G1: Debt_Service | H1: IDEA_Draw | I1: TitleI_Draw | J1: TitleIII_Draw | K1: Sped Fund | L1: Coop Fund | M1: Sped_Expend | N1: Bil_Expend | O1: PK-8_Hdct | P1: 9-12,NG_Hdct
A2: D0603 | B2: 101 | C2: Erie-Galesburg | D2: 7893998 | E2: 229659 | F2: 1056129 | G2: 1263846 | H2: 0 | I2: 234359 | J2: 0 | K2: 116302 | L2: 0 | M2: 116302 | N2: 1969 | O2: 347 | P2: 197
A3: D0613 | B3: 102 | C3: Cimarron-Ensign | D3: 6346680 | E3: 334944 | F3: 764852 | G3: 395005 | H3: 0 | I3: 122312 | J3: 14377 | K3: 61997 | L3: 0 | M3: 61997 | N3: 259784 | O3: 502 | P3: 217
A4: D0602 | B4: 103 | C4: Cheylin | D4: 2052178 | E4: 129857 | F4: 178431 | G4: 0 | H4: 0 | I4: 50028 | J4: 0 | K4: 49637 | L4: 0 | M4: 49637 | N4: 30490 | O4: 89 | P4: 53
A5: D0602 | B5: 105 | C5: Rawlins County | D5: 3629528 | E5: 132283 | F5: 402826 | G5: 0 | H5: 0 | I5: 96668 | J5: 0 | K5: 170537 | L5: 0 | M5: 170537 | N5: 0 | O5: 200 | P5: 115
A6: D0613 | B6: 106 | C6: Western Plains | D6: 2097730 | E6: 71770 | F6: 50449 | G6: 59001 | H6: 0 | I6: 34098 | J6: 0 | K6: 1102 | L6: 0 | M6: 1102 | N6: 18183 | O6: 122 | P6: 48
A7: D0273 | B7: 107 | C7: Rock Hills | D7: 3703256 | E7: 117063 | F7: 350063 | G7: 52908 | H7: 0 | I7: 102952 | J7: 0 | K7: 20504 | L7: 0 | M7: 20504 | N7: 0 | O7: 171 | P7: 127
A8: D0333 | B8: 108 | C8: Washington Co. Schools | D8: 5711058 | E8: 142453 | F8: 1371943 | G8: 261765 | H8: 0 | I8: 94258 | J8: 0 | K8: 140153 | L8: 0 | M8: 140153 | N8: 0 | O8: 298 | P8: 118
A9: D0333 | B9: 109 | C9: Republic County | D9: 4703569 | E9: 218170 | F9: 221692 | G9: 67320 | H9: 0 | I9: 157312 | J9: 0 | K9: 53406 | L9: 0 | M9: 53406 | N9: 0 | O9: 346 | P9: 163
A10: D0636 | B10: 110 | C10: Thunder Ridge Schools | D10: 3227975 | E10: 105455 | F10: 299807 | G10: 0 | H10: 0 | I10: 54828 | J10: 0 | K10: 440 | L10: 0 | M10: 440 | N10: 0 | O10: 186 | P10: 83
A11: D0616 | B11: 111 | C11: Doniphan West Schools | D11: 5125166 | E11: 80958 | F11: 306258 | G11: 0 | H11: 0 | I11: 49912 | J11: 0 | K11: 6854 | L11: 0 | M11: 6854 | N11: 0 | O11: 236 | P11: 129
A12: D0305 | B12: 112 | C12: Central Plains | D12: 8059964 | E12: 133078 | F12: 516017 | G12: 708875 | H12: 0 | I12: 96897 | J12: 0 | K12: 40632 | L12: 0 | M12: 40632 | N12: 0 | O12: 365 | P12: 254
A13: D0336 | B13: 113 | C13: Prairie Hills | D13: 12575798 | E13: 191344 | F13: 643708 | G13: 561693 | H13: 0 | I13: 169542 | J13: 0 | K13: 282693 | L13: 0 | M13: 282693 | N13: 2000 | O13: 866 | P13: 392
... A16: D0611 | B16: 200 | C16: Greeley County Schools | D16: 2665109 | E16: 53407 | F16: 159854 | G16: 27753 | H16: 0 | I16: 55794 | J16: 0 | K16: 3682 | L16: 0 | M16: 3682 | N16: 59889 | O16: 138 | P16: 63
B17: 202 | C17: Turner-Kansas City | D17: 40618890 | E17: 1849607 | F17: 3767346 | G17: 3761905 | H17: 1129985 | I17: 1457336 | J17: 67046 | K17: 4109176 | L17: 0 | M17: 4109176 | N17: 456154 | O17: 2780 | P17: 1296
A18: D0500 | B18: 203 | C18: Piper-Kansas City | D18: 14975203 | E18: 126433 | F18: 977527 | G18: 1707443 | H18: 0 | I18: 92969 | J18: 0 | K18: 156606 | L18: 0 | M18: 156606 | N18: 0 | O18: 1194 | P18: 524
A19: D0500 | B19: 204 | C19: Bonner Springs | D19: 21118421 | E19: 517728 | F19: 754220 | G19: 3167774 | H19: 0 | I19: 411472 | J19: 22868 | K19: 384374 | L19: 0 | M19: 384374 | N19: 145683 | O19: 1800 | P19: 716
A20: D0490 | B20: 205 | C20: Bluestem | D20: 6504262 | E20: 149584 | F20: 429440 | G20: 608588 | H20: 0 | I20: 120657 | J20: 0 | K20: 32949 | L20: 0 | M20: 32949 | N20: 0 | O20: 323 | P20: 221
A21: D0490 | B21: 206 | C21: Remington-Whitewater | D21: 5410950 | E21: 104250 | F21: 242224 | G21: 436319 | H21: 0 | I21: 83473 | J21: 0 | K21: 80964 | L21: 0 | M21: 80964 | N21: 26284 | O21: 350 | P21: 203
A22: D0453 | B22: 207 | C22: Ft Leavenworth | D22: 16272024 | E22: 94400 | F22: 2254434 | G22: 0 | H22: 0 | I22: 67496 | J22: 0 | K22: 88699 | L22: 0 | M22: 88699 | N22: 174016 | O22: 1905 | P22: 91
A23: D0602 | B23: 208 | C23: Wakeeney | D23: 4551003 | E23: 150004 | F23: 357668 | G23: 207507 | H23: 0 | I23: 119170 | J23: 0 | K23: 504994 | L23: 0 | M23: 504994 | N23: 0 | O23: 270 | P23: 122
A24: D0611 | B24: 209 | C24: Moscow Public Schools | D24: 3059217 | E24: 258073 | F24: 680739 | G24: 0 | H24: 0 | I24: 37185 | J24: 0 | K24: 0 | L24: 0 | M24: 0 | N24: 81496 | O24: 117 | P24: 83
A25: D0611 | B25: 210 | C25: Hugoton Public Schools | D25: 12621278 | E25: 688037 | F25: 2094055 | G25: 1206610 | H25: 0 | I25: 247875 | J25: 23205 | K25: 28176 | L25: 0 | M25: 28176 | N25: 268897 | O25: 774 | P25: 340
A26: D0636 | B26: 211 | C26: Norton Community Schools | D26: 6721102 | E26: 177858 | F26: 539467 | G26: 0 | H26: 0 | I26: 151724 | J26: 0 | K26: 22021 | L26: 0 | M26: 22021 | N26: 0 | O26: 481 | P26: 280
A27: D0636 | B27: 212 | C27: Northern Valley | D27: 3000525 | E27: 56906 | F27: 609499 | G27: 0 | H27: 0 | I27: 58800 | J27: 0 | K27: 14261 | L27: 0 | M27: 14261 | N27: 0 | O27: 150 | P27: 62
A28: D0611 | B28: 214 | C28: Ulysses | D28: 14837976 | E28: 1018855 | F28: 640226 | G28: 1333206 | H28: 0 | I28: 347248 | J28: 43635 | K28: 9130 | L28: 0 | M28: 9130 | N28: 370087 | O28: 1224 | P28: 494
A29: D0611 | B29: 215 | C29: Lakin | D29: 7627396 | E29: 213356 | F29: 547329 | G29: 936175 | H29: 0 | I29: 178782 | J29: 0 | K29: 9462 | L29: 0 | M29: 9462 | N29: 218562 | O29: 464 | P29: 165
... A39: D0613 | B39: 227 | C39: Jetmore | D39: 4164420 | E39: 110532 | F39: 655153 | G39: 345365 | H39: 0 | I39: 61846 | J39: 0 | K39: 2149 | L39: 0 | M39: 2149 | N39: 3543 | O39: 231 | P39: 92
B40: 229 | C40: Blue Valley | D40: 247410819 | E40: 658833 | F40: 14269150 | G40: 41965928 | H40: 5216654 | I40: 340546 | J40: 30806 | K40: 29746139 | L40: 0 | M40: 29746139 | N40: 1505859 | O40: 14768 | P40: 6663
B41: 230 | C41: Spring Hill | D41: 28028186 | E41: 218215 | F41: 430068 | G41: 3810929 | H41: 757820 | I41: 183017 | J41: 0 | K41: 2125599 | L41: 0 | M41: 2125599 | N41: 26137 | O41: 1555 | P41: 2053
B42: 231 | C42: Gardner Edgerton | D42: 57050970 | E42: 1223108 | F42: 3747688 | G42: 11399195 | H42: 1243765 | I42: 412869 | J42: 0 | K42: 7033419 | L42: 0 | M42: 7033419 | N42: 270804 | O42: 3712 | P42: 1330
B43: 232 | C43: De Soto | D43: 70741971 | E43: 360742 | F43: 2210790 | G43: 16010332 | H43: 1620626 | I43: 148872 | J43: 17992 | K43: 6536322 | L43: 0 | M43: 6536322 | N43: 259117 | O43: 4926 | P43: 1742
B44: 233 | C44: Olathe | D44: 280212690 | E44: 4897040 | F44: 3475490 | G44: 42372540 | H44: 9165610 | I44: 2217996 | J44: 138591 | K44: 33953344 | L44: 0 | M44: 33953344 | N44: 2482521 | O44: 19530 | P44: 7835
B45: 234 | C45: Fort Scott | D45: 16714855 | E45: 963216 | F45: 537363 | G45: 1057041 | H45: 630903 | I45: 803285 | J45: 0 | K45: 1335376 | L45: 0 | M45: 1335376 | N45: 9645 | O45: 1406 | P45: 567
A46: D0637 | B46: 235 | C46: Uniontown | D46: 4824177 | E46: 156190 | F46: 446675 | G46: 154070 | H46: 0 | I46: 121343 | J46: 0 | K46: 36029 | L46: 0 | M46: 36029 | N46: 9458 | O46: 318 | P46: 157
A47: D0636 | B47: 237 | C47: Smith Center | D47: 5204512 | E47: 130488 | F47: 1045309 | G47: 0 | H47: 0 | I47: 118879 | J47: 0 | K47: 38745 | L47: 0 | M47: 38745 | N47: 0 | O47: 257 | P47: 172
A48: D0305 | B48: 239 | C48: North Ottawa County | D48: 6167547 | E48: 160941 | F48: 305501 | G48: 354015 | H48: 0 | I48: 95946 | J48: 0 | K48: 202686 | L48: 0 | M48: 202686 | N48: 0 | O48: 397 | P48: 230
A49: D0305 | B49: 240 | C49: Twin Valley | D49: 6524508 | E49: 142998 | F49: 216432 | G49: 522932 | H49: 0 | I49: 86385 | J49: 0 | K49: 98255 | L49: 0 | M49: 98255 | N49: 0 | O49: 427 | P49: 212
A50: D0602 | B50: 241 | C50: Wallace County Schools | D50: 2255334 | E50: 36690 | F50: 146123 | G50: 229218 | H50: 0 | I50: 52577 | J50: 0 | K50: 8 | L50: 0 | M50: 8 | N50: 0 | O50: 141 | P50: 58
A51: D0602 | B51: 242 | C51: Weskan | D51: 1349297 | E51: 53163 | F51: 61759 | G51: 0 | H51: 0 | I51: 29028 | J51: 0 | K51: 0 | L51: 0 | M51: 0 | N51: 20063 | O51: 69 | P51: 44
...
