Workbook

Sheet Legend
A2: Legend
D3: Local
D5: State
D7: Federal
D9: Other
A12: Source | B12: Indiana Department of Education
A14: All files are "read only" and based on data collections from the Indiana Department of Education.
A15: The conclusions reached in this document are those of the author(s) and do not necessarily represent those
A16: of Ball State University.

Sheet Figures 1,2,4
A1: Figure 1: District & Charter School Revenues & Enrollments | I1: Figure 2
A2: Indiana (2006-07) | B2: Statewide | F2: Indianapolis | J2: District | K2: Charter | L2: Difference
A3: Per-Pupil Revenue | I3: State | J3: =B4 -> 7046.6145 | K3: =B5 -> 9327.7446 | L3: =B6 -> -2281.13
A4: District | B4: =B14 -> 7046.6145 | F4: =F14 -> 11146.836 | I4: Statewide Weighted
A5: Charter | B5: =C14 -> 9327.7446 | F5: =G14 -> 9835.0698 | I5: Indianapolis | J5: =F4 -> 11146.836 | K5: =F5 -> 9835.0698 | L5: =F6 -> 1311.7665
A6: Difference | B6: =B4-B5 -> -2281.13 | F6: =F4-F5 -> 1311.7665
B7: =B6/B4 -> -0.32372 | F7: =F6/F4 -> 0.11768061
A8: Per-Pupil Revenue by Source | B8: District | C8: Charter | F8: District | G8: Charter
A9: Federal | B9: =Districts!E295/'Figures 1,2,4'!B16:C16 -> 701.31117 | C9: ='Charters State'!E39/'Charters State'!I39 -> 1113.7251 | F9: =Districts!E176/'Figures 1,2,4'!F16:G16 -> 1778.8812 | G9: ='Charters Indy'!E19/'Charters Indy'!I19 -> 995.17289
A10: State | B10: =Districts!D295/'Figures 1,2,4'!B16:C16 -> 3906.4345 | C10: ='Charters State'!D39/'Charters State'!I39 -> 4208.19 | F10: =Districts!D176/'Figures 1,2,4'!F16:G16 -> 5968.2584 | G10: ='Charters Indy'!D19/'Charters Indy'!I19 -> 4031.1984
A11: Local | B11: =Districts!C295/'Figures 1,2,4'!B16:C16 -> 1769.7759 | C11: ='Charters State'!C39/'Charters State'!I39 -> 2339.621 | F11: =Districts!C176/'Figures 1,2,4'!F16:G16 -> 1475.8358 | G11: ='Charters Indy'!C19/'Charters Indy'!I19 -> 2712.1513
A12: Other | B12: =Districts!F295/'Figures 1,2,4'!B16:C16 -> 669.09302 | C12: ='Charters State'!F39/'Charters State'!I39 -> 1666.2084 | F12: =Districts!F176/'Figures 1,2,4'!F16:G16 -> 1923.861 | G12: ='Charters Indy'!F19/'Charters Indy'!I19 -> 2096.5472
A13: Indeterminate
A14: Total | B14: =SUM(B9:B13) -> 7046.6145 | C14: =SUM(C9:C13) -> 9327.7446 | F14: =SUM(F9:F13) -> 11146.836 | G14: =SUM(G9:G13) -> 9835.0698
A15: Enrollment
A16: District | B16: =Districts!I297 -> 1024893 | F16: =Districts!I176 -> 37057
B17: =B16/(B16+B18) -> 0.99128257 | F17: =F16/(F16+F18) -> 0.89570241
A18: Charter | B18: ='Charters State'!I39 -> 9013 | F18: ='Charters Indy'!I19 -> 4315
B19: =B18/(B16+B18) -> 0.0087174269 | F19: =F18/(F16+F18) -> 0.10429759
A20: Number of Charters | B20: 37 | F20: 17
A21: Total Revenue
A22: District | B22: =SUM(Districts!C295:F295) -> 7.2220259e+09 | F22: =SUM(Districts!C176:F176) -> 4.1306831e+08
B23: =B22/B26 -> 0.98849304 | F23: =F22/F26 -> 0.90683269
A24: Charter | B24: =SUM('Charters State'!C39:F39) -> 84070962 | F24: =SUM('Charters Indy'!C19:F19) -> 42438326
B25: =B24/B26 -> 0.01150696 | F25: =F24/F26 -> 0.093167305
A26: Total | B26: =B22+B24 -> 7.3060969e+09 | F26: =F22+F24 -> 4.5550664e+08
A27: Percentage of Revenue by Source | B27: District | C27: Charter | F27: District | G27: Charter | I27: Figure 4
A28: Federal | B28: =B9/B14 -> 0.099524554 | C28: =C9/C14 -> 0.11939919 | F28: =F9/F14 -> 0.15958619 | G28: =G9/G14 -> 0.10118615 | J28: Federal | K28: State | L28: Local | M28: Other | N28: Indeterminate
A29: State | B29: =B10/B14 -> 0.5543704 | C29: =C10/C14 -> 0.45114765 | F29: =F10/F14 -> 0.53542173 | G29: =G10/G14 -> 0.40988 | I29: Statewide District | J29: =B9 -> 701.31117 | K29: =B10 -> 3906.4345 | L29: =B11 -> 1769.7759 | M29: =B12 -> 669.09302 | N29: =B13 -> 0
A30: Local | B30: =B11/B14 -> 0.25115264 | C30: =C11/C14 -> 0.25082387 | F30: =F11/F14 -> 0.13239952 | G30: =G11/G14 -> 0.2757633 | I30: Statewide Charter | J30: =C9 -> 1113.7251 | K30: =C10 -> 4208.19 | L30: =C11 -> 2339.621 | M30: =C12 -> 1666.2084 | N30: =C13 -> 0
A31: Other | B31: =B12/B14 -> 0.094952408 | C31: =C12/C14 -> 0.17862929 | F31: =F12/F14 -> 0.17259256 | G31: =G12/G14 -> 0.21317055 | I31: Statewide Weighted
A32: Change in district school funding if subjected to charter funding structure | I32: Indianapolis District | J32: =F9 -> 1778.8812 | K32: =F10 -> 5968.2584 | L32: =F11 -> 1475.8358 | M32: =F12 -> 1923.861 | N32: =F13 -> 0
B33: $2.2 billion | F33: (48.6 million) | I33: Indianapolis Charter | J33: =G9 -> 995.17289 | K33: =G10 -> 4031.1984 | L33: =G11 -> 2712.1513 | M33: =G12 -> 2096.5472 | N33: =G13 -> 0
B34: =B6*B16 -> -2.3379142e+09 | F34: =F6*F16 -> 48610132
A35: Monument Lighthouse charter school revenues excluded as the school does not list any students for FY07
A36: The following LEA have enrollments but no dollars. Therefore, excluded from analysis
A37: Indiana Department of Corrections
A38: Blue River Special Education Coop
A39: Northwest Indiana Special Education Coop
A40: The following LEA has dollars but no enrollments. Therefore, excluded from analysis
...

Sheet archive
A3: Corp | B3: Corporation Name | C3: L062 | D3: L071 | E3: Local Revenue | F3: S062 | G3: S071 | H3: State Revenue | I3: F062 | J3: F071 | K3: Federal Revenue | L3: O062 | M3: O071 | N3: Other Revenue | O3: District/charter
A4: 15 | B4: Adams Central Community Schools | C4: 1381696.7 | D4: 1298899.1 | E4: =SUM(C4:D4) -> 2680595.8 | F4: 2147938.9 | G4: 2008567.6 | H4: =SUM(F4:G4) -> 4156506.5 | I4: 243125.53 | J4: 343162.17 | K4: =SUM(I4:J4) -> 586287.7 | L4: 968547.97 | M4: 42228.66 | N4: =SUM(L4:M4) -> 1010776.6 | O4: District | P4: State
A5: 25 | B5: North Adams Community Schools | C5: 2897178 | D5: 2719609.1 | E5: =SUM(C5:D5) -> 5616787.1 | F5: 4488521.7 | G5: 4036028 | H5: =SUM(F5:G5) -> 8524549.7 | I5: 334800.78 | J5: 499910.74 | K5: =SUM(I5:J5) -> 834711.52 | L5: 43181.08 | M5: 15423.3 | N5: =SUM(L5:M5) -> 58604.38 | O5: District | P5: State
A6: 35 | B6: South Adams Schools | C6: 1510496.5 | D6: 1487835.1 | E6: =SUM(C6:D6) -> 2998331.6 | F6: 3009938.1 | G6: 2764103.9 | H6: =SUM(F6:G6) -> 5774042 | I6: 764214.66 | J6: 625324.17 | K6: =SUM(I6:J6) -> 1389538.8 | L6: 3371.84 | M6: 28019.28 | N6: =SUM(L6:M6) -> 31391.12 | O6: District | P6: State
A7: 125 | B7: M S D Southwest Allen County | C7: 12666607 | D7: 2950903.6 | E7: =SUM(C7:D7) -> 15617511 | F7: 6722083.3 | G7: 6513155.6 | H7: =SUM(F7:G7) -> 13235239 | I7: 1446367.7 | J7: 1516633.3 | K7: =SUM(I7:J7) -> 2963000.9 | L7: 2508013.1 | M7: 2681684.5 | N7: =SUM(L7:M7) -> 5189697.6 | O7: District | P7: State
A8: 225 | B8: Northwest Allen County Schools | C8: 7891483 | D8: 2134056.7 | E8: =SUM(C8:D8) -> 10025540 | F8: 8959306.6 | G8: 8707031.8 | H8: =SUM(F8:G8) -> 17666338 | I8: 429002.4 | J8: 703930.74 | K8: =SUM(I8:J8) -> 1132933.1 | L8: 172880.21 | M8: 66579.65 | N8: =SUM(L8:M8) -> 239459.86 | O8: District | P8: State
A9: 235 | B9: Fort Wayne Community Schools | C9: 32894431 | D9: 9346915.1 | E9: =SUM(C9:D9) -> 42241346 | F9: 69064590 | G9: 63381242 | H9: =SUM(F9:G9) -> 1.3244583e+08 | I9: 14621455 | J9: 16701880 | K9: =SUM(I9:J9) -> 31323336 | L9: 7058316.6 | M9: 1444702.4 | N9: =SUM(L9:M9) -> 8503019.1 | O9: District | P9: State
A10: 255 | B10: East Allen County Schools | C10: 10385601 | D10: 3025155.1 | E10: =SUM(C10:D10) -> 13410756 | F10: 21025558 | G10: 19382272 | H10: =SUM(F10:G10) -> 40407830 | I10: 3253281.9 | J10: 3299733.2 | K10: =SUM(I10:J10) -> 6553015.2 | L10: 5130400.8 | M10: 9046917.4 | N10: =SUM(L10:M10) -> 14177318 | O10: District | P10: State
A11: 365 | B11: Bartholomew Con School Corp | C11: 13448291 | D11: 5952725.1 | E11: =SUM(C11:D11) -> 19401016 | F11: 19130184 | G11: 17862844 | H11: =SUM(F11:G11) -> 36993028 | I11: 5402294.8 | J11: 5298950.2 | K11: =SUM(I11:J11) -> 10701245 | L11: 2110227.5 | M11: 661638.51 | N11: =SUM(L11:M11) -> 2771866 | O11: District | P11: State
A12: 370 | B12: Flat Rock-Hawcreek School Corp | C12: 666613.34 | D12: 183012.16 | E12: =SUM(C12:D12) -> 849625.5 | F12: 2858413.8 | G12: 2455916.3 | H12: =SUM(F12:G12) -> 5314330.1 | I12: 153112.74 | J12: 200413.46 | K12: =SUM(I12:J12) -> 353526.2 | L12: 4619.7 | M12: 22651.84 | N12: =SUM(L12:M12) -> 27271.54 | O12: District | P12: State
A13: 395 | B13: Benton Community School Corp | C13: 3786773.3 | D13: 1117333.8 | E13: =SUM(C13:D13) -> 4904107.1 | F13: 3752329 | G13: 3083276.4 | H13: =SUM(F13:G13) -> 6835605.4 | I13: 114947.71 | J13: 222926.1 | K13: =SUM(I13:J13) -> 337873.81 | L13: 146890.01 | M13: 17295 | N13: =SUM(L13:M13) -> 164185.01 | O13: District | P13: State
A14: 515 | B14: Blackford County Schools | C14: 1935470.9 | D14: 205087.81 | E14: =SUM(C14:D14) -> 2140558.7 | F14: 5389107.3 | G14: 4961684.5 | H14: =SUM(F14:G14) -> 10350792 | I14: 548751.14 | J14: 922084.37 | K14: =SUM(I14:J14) -> 1470835.5 | L14: 48699.09 | M14: 46603.44 | N14: =SUM(L14:M14) -> 95302.53 | O14: District | P14: State
A15: 615 | B15: Western Boone Co Com Sch Dist | C15: 1984149.3 | D15: 517199.45 | E15: =SUM(C15:D15) -> 2501348.8 | F15: 3640846.9 | G15: 3416824.3 | H15: =SUM(F15:G15) -> 7057671.2 | I15: 96683.56 | J15: 195559.25 | K15: =SUM(I15:J15) -> 292242.81 | L15: 9744.83 | M15: 13376.54 | N15: =SUM(L15:M15) -> 23121.37 | O15: District | P15: State
A16: 630 | B16: Zionsville Community Schools | C16: 7910192.3 | D16: 1283513.1 | E16: =SUM(C16:D16) -> 9193705.4 | F16: 7179033.2 | G16: 7006898.7 | H16: =SUM(F16:G16) -> 14185932 | I16: 199767.09 | J16: 188134.53 | K16: =SUM(I16:J16) -> 387901.62 | M16: 325 | N16: =SUM(L16:M16) -> 325 | O16: District | P16: State
A17: 665 | B17: Lebanon Community School Corp | C17: 3449018.9 | D17: 607543.48 | E17: =SUM(C17:D17) -> 4056562.3 | F17: 6093344.5 | G17: 6592757.7 | H17: =SUM(F17:G17) -> 12686102 | I17: 489854.5 | J17: 924894.17 | K17: =SUM(I17:J17) -> 1414748.7 | L17: 454682.25 | M17: 90261.64 | N17: =SUM(L17:M17) -> 544943.89 | O17: District | P17: State
A18: 670 | B18: Brown County School Corporation | C18: 6087341.3 | D18: 490934.53 | E18: =SUM(C18:D18) -> 6578275.9 | F18: 3973281.2 | G18: 3286436.1 | H18: =SUM(F18:G18) -> 7259717.3 | I18: 550260.36 | J18: 879947.09 | K18: =SUM(I18:J18) -> 1430207.4 | L18: 14031.5 | M18: 42161.79 | N18: =SUM(L18:M18) -> 56193.29 | O18: District | P18: State
A19: 750 | B19: Carroll Consolidated Sch Corp | C19: 1467057.7 | D19: 464230.28 | E19: =SUM(C19:D19) -> 1931288 | F19: 2030585.3 | G19: 1842649.4 | H19: =SUM(F19:G19) -> 3873234.6 | I19: 100903.17 | J19: 202262.74 | K19: =SUM(I19:J19) -> 303165.91 | L19: 750000 | M19: 1033173.5 | N19: =SUM(L19:M19) -> 1783173.5 | O19: District | P19: State
A20: 755 | B20: Delphi Community School Corp | C20: 1738957.3 | D20: 586765.74 | E20: =SUM(C20:D20) -> 2325723 | F20: 3432249.3 | G20: 3068378.1 | H20: =SUM(F20:G20) -> 6500627.5 | I20: 320289.89 | J20: 349278.06 | K20: =SUM(I20:J20) -> 669567.95 | L20: 22317.55 | M20: 2217.46 | N20: =SUM(L20:M20) -> 24535.01 | O20: District | P20: State
A21: 775 | B21: Pioneer Regional School Corp | C21: 984792.68 | D21: 334566.16 | E21: =SUM(C21:D21) -> 1319358.8 | F21: 1847121 | G21: 1921376.4 | H21: =SUM(F21:G21) -> 3768497.4 | I21: 119053.5 | J21: 195739.55 | K21: =SUM(I21:J21) -> 314793.05 | L21: 39940.02 | M21: 49124.07 | N21: =SUM(L21:M21) -> 89064.09 | O21: District | P21: State
A22: 815 | B22: Southeastern School Corp | C22: 1722905.5 | D22: 716729.2 | E22: =SUM(C22:D22) -> 2439634.7 | F22: 3361967.5 | G22: 3003140.1 | H22: =SUM(F22:G22) -> 6365107.6 | I22: 288400.05 | J22: 231710.82 | K22: =SUM(I22:J22) -> 520110.87 | L22: 9088.55 | M22: 6664.43 | N22: =SUM(L22:M22) -> 15752.98 | O22: District | P22: State
A23: 875 | B23: Logansport Community Sch Corp | C23: 2892856.1 | D23: 1429205.8 | E23: =SUM(C23:D23) -> 4322061.9 | F23: 10861784 | G23: 10267729 | H23: =SUM(F23:G23) -> 21129512 | I23: 2905086.2 | J23: 3585100.2 | K23: =SUM(I23:J23) -> 6490186.4 | L23: 3990911.5 | M23: 5330534.7 | N23: =SUM(L23:M23) -> 9321446.2 | O23: District | P23: State
A24: 940 | B24: West Clark Community Schools | C24: 5031031.6 | D24: 1523959.5 | E24: =SUM(C24:D24) -> 6554991 | F24: 6635654.1 | G24: 6388404.7 | H24: =SUM(F24:G24) -> 13024059 | I24: 299535.34 | J24: 491165.42 | K24: =SUM(I24:J24) -> 790700.76 | L24: 699446.14 | M24: 69575.09 | N24: =SUM(L24:M24) -> 769021.23 | O24: District | P24: State
A25: 1000 | B25: Clarksville Com School Corp | C25: 2633561.5 | D25: 811586.76 | E25: =SUM(C25:D25) -> 3445148.2 | F25: 3405887.6 | G25: 2931900.5 | H25: =SUM(F25:G25) -> 6337788 | I25: 384646.62 | J25: 378181.11 | K25: =SUM(I25:J25) -> 762827.73 | L25: 106960.16 | M25: 9500.3 | N25: =SUM(L25:M25) -> 116460.46 | O25: District | P25: State
A26: 1010 | B26: Greater Clark County Schools | C26: 13880175 | D26: 5252750.9 | E26: =SUM(C26:D26) -> 19132926 | F26: 24018514 | G26: 22055146 | H26: =SUM(F26:G26) -> 46073660 | I26: 5297135.6 | J26: 4699504.9 | K26: =SUM(I26:J26) -> 9996640.5 | L26: 840109.38 | M26: 1252886.4 | N26: =SUM(L26:M26) -> 2092995.8 | O26: District | P26: State
A27: 1125 | B27: Clay Community Schools | C27: 3763162.9 | D27: 630707.11 | E27: =SUM(C27:D27) -> 4393870 | F27: 10513718 | G27: 9677453.8 | H27: =SUM(F27:G27) -> 20191172 | I27: 1298894.3 | J27: 1646659.8 | K27: =SUM(I27:J27) -> 2945554.1 | L27: 92803.85 | M27: 43167.98 | N27: =SUM(L27:M27) -> 135971.83 | O27: District | P27: State
A28: 1150 | B28: Clinton Central School Corp | C28: 1208514.3 | D28: 420679.94 | E28: =SUM(C28:D28) -> 1629194.3 | F28: 2187142.5 | G28: 1940181.1 | H28: =SUM(F28:G28) -> 4127323.5 | I28: 278931.24 | J28: 255346.76 | K28: =SUM(I28:J28) -> 534278 | L28: 218257.95 | M28: 6112.9 | N28: =SUM(L28:M28) -> 224370.85 | O28: District | P28: State
... A32: 1300 | B32: Crawford Co Com School Corp | C32: 180405.87 | D32: 1298084.2 | E32: =SUM(C32:D32) -> 1478490 | F32: 4794821.7 | G32: 4502700.2 | H32: =SUM(F32:G32) -> 9297521.9 | I32: 721469.62 | J32: 739123.19 | K32: =SUM(I32:J32) -> 1460592.8 | L32: 230601.61 | M32: 107893.97 | N32: =SUM(L32:M32) -> 338495.58 | O32: District | P32: State
A33: 1315 | B33: Barr-Reeve Com Schools Inc | C33: 2340945.7 | D33: 2237871.2 | E33: =SUM(C33:D33) -> 4578817 | H33: =SUM(F33:G33) -> 0 | K33: =SUM(I33:J33) -> 0 | N33: =SUM(L33:M33) -> 0 | O33: District | P33: State
A34: 1375 | B34: North Daviess Com Schools | C34: 1185654.5 | D34: 1258990 | E34: =SUM(C34:D34) -> 2444644.5 | F34: 2375713.3 | G34: 2176942.5 | H34: =SUM(F34:G34) -> 4552655.8 | I34: 344087.99 | J34: 357039.8 | K34: =SUM(I34:J34) -> 701127.79 | L34: 9113.96 | M34: 9424.08 | N34: =SUM(L34:M34) -> 18538.04 | O34: District | P34: State
A35: 1405 | B35: Washington Com Schools Inc | C35: 1848953.3 | D35: 2071056.9 | E35: =SUM(C35:D35) -> 3920010.2 | F35: 5966230 | G35: 5562462 | H35: =SUM(F35:G35) -> 11528692 | I35: 536491 | J35: 639439.61 | K35: =SUM(I35:J35) -> 1175930.6 | L35: 2509313.7 | M35: 20453.83 | N35: =SUM(L35:M35) -> 2529767.6 | O35: District | P35: State
A36: 1560 | B36: Sunman-Dearborn Com Sch Corp | C36: 4723797.9 | D36: 2640034.1 | E36: =SUM(C36:D36) -> 7363832.1 | F36: 8678125.1 | G36: 8158629.9 | H36: =SUM(F36:G36) -> 16836755 | I36: 1551948.4 | J36: 1462156.5 | K36: =SUM(I36:J36) -> 3014104.9 | L36: 2763620.2 | M36: 2458534.1 | N36: =SUM(L36:M36) -> 5222154.3 | O36: District | P36: State
A37: 1600 | B37: South Dearborn Com School Corp | C37: 2710256.8 | D37: 1816592.9 | E37: =SUM(C37:D37) -> 4526849.7 | F37: 6630530.7 | G37: 6181101.4 | H37: =SUM(F37:G37) -> 12811632 | I37: 609089.6 | J37: 500782.32 | K37: =SUM(I37:J37) -> 1109871.9 | L37: 829349.35 | M37: 608138.64 | N37: =SUM(L37:M37) -> 1437488 | O37: District | P37: State
A38: 1620 | B38: Lawrenceburg Com School Corp | C38: 4503409.1 | D38: 2511269.9 | E38: =SUM(C38:D38) -> 7014679 | F38: 183294.12 | G38: 1026075.3 | H38: =SUM(F38:G38) -> 1209369.5 | I38: 306913.53 | J38: 266451.37 | K38: =SUM(I38:J38) -> 573364.9 | L38: 17863.37 | M38: 2635.6 | N38: =SUM(L38:M38) -> 20498.97 | O38: District | P38: State
A39: 1655 | B39: Decatur County Com Schools | C39: 171440.45 | D39: 2861219.8 | E39: =SUM(C39:D39) -> 3032660.3 | F39: 4334069.1 | G39: 4142217.6 | H39: =SUM(F39:G39) -> 8476286.7 | I39: 281833.65 | J39: 390790.2 | K39: =SUM(I39:J39) -> 672623.85 | L39: 22916.71 | M39: 7591.87 | N39: =SUM(L39:M39) -> 30508.58 | O39: District | P39: State
A40: 1730 | B40: Greensburg Community Schools | C40: 2577871.3 | D40: 960102.04 | E40: =SUM(C40:D40) -> 3537973.3 | F40: 4114464.1 | G40: 3771535.1 | H40: =SUM(F40:G40) -> 7885999.2 | I40: 741227.64 | J40: 690155.18 | K40: =SUM(I40:J40) -> 1431382.8 | L40: 249352.5 | M40: 16368.9 | N40: =SUM(L40:M40) -> 265721.4 | O40: District | P40: State
A41: 1805 | B41: DeKalb Co Eastern Com Sch Dist | C41: 2849328.5 | D41: 482114.5 | E41: =SUM(C41:D41) -> 3331443 | F41: 2981750 | G41: 2879892.2 | H41: =SUM(F41:G41) -> 5861642.1 | I41: 4078093 | J41: 963384.42 | K41: =SUM(I41:J41) -> 5041477.5 | L41: 2361486.6 | M41: 922211.16 | N41: =SUM(L41:M41) -> 3283697.8 | O41: District | P41: State
A42: 1820 | B42: Garrett-Keyser-Butler Com | C42: 2690185.8 | D42: 427405.11 | E42: =SUM(C42:D42) -> 3117590.9 | F42: 3556399.7 | G42: 3296367.6 | H42: =SUM(F42:G42) -> 6852767.3 | I42: 1124466.7 | J42: 1307437.9 | K42: =SUM(I42:J42) -> 2431904.5 | L42: 1430461.9 | M42: 725767.24 | N42: =SUM(L42:M42) -> 2156229.2 | O42: District | P42: State
A43: 1835 | B43: DeKalb Co Ctl United Sch Dist | C43: 7311741.9 | D43: 1192385.2 | E43: =SUM(C43:D43) -> 8504127.1 | F43: 7786309.2 | G43: 7121930.4 | H43: =SUM(F43:G43) -> 14908240 | I43: 594609.1 | J43: 787121.45 | K43: =SUM(I43:J43) -> 1381730.5 | L43: 180911.97 | M43: 279275.61 | N43: =SUM(L43:M43) -> 460187.58 | O43: District | P43: State
A44: 1875 | B44: Delaware Community School Corp | C44: 2402772.6 | D44: 614195.96 | E44: =SUM(C44:D44) -> 3016968.6 | F44: 6119270.9 | G44: 5709361.1 | H44: =SUM(F44:G44) -> 11828632 | I44: 645569.52 | J44: 645295 | K44: =SUM(I44:J44) -> 1290864.5 | L44: 23267.39 | M44: 20957.01 | N44: =SUM(L44:M44) -> 44224.4 | O44: District | P44: State
A45: 1885 | B45: Harrison-Wash Com School Corp | C45: 1007048.9 | D45: 243653.12 | E45: =SUM(C45:D45) -> 1250702 | F45: 1717137.5 | G45: 1532241.2 | H45: =SUM(F45:G45) -> 3249378.7 | I45: 158544.52 | J45: 165307 | K45: =SUM(I45:J45) -> 323851.52 | L45: 631524.84 | M45: 470233.38 | N45: =SUM(L45:M45) -> 1101758.2 | O45: District | P45: State
...

Sheet Sheet2
A1: 9300 | B1: 666.16
A2: 9315 | B2: 778.6
A3: 9315 | B3: 3689.42
A4: 9320 | B4: 74667.01
A5: 9325 | B5: 17088
A6: 9330 | B6: 48891
A7: 9330 | B7: 563375.4
A8: 9340 | B8: 38015
A9: 9340 | B9: 5685.57
A10: 9350 | B10: 500
A11: 9350 | B11: 3985.94
A12: 9360 | B12: 25
... A60: 9665 | B60: 152565

Sheet Figure 3
A1: State Charter School Policies
A2: Figure 3
A3: State Policies | B3: Yes | C3: No | D3: Partial
A4: Charter schools received their funding directly from the state | B4: X
A5: Charter schools are eligible for local funding | B5: X
A6: Cap on funding a charter school can receive | B6: X
A7: District public school receive differential funding (e.g. more funding for 9-12 vs. K-8 schools) | B7: X
A8: Charter schools receive differential funding | B8: X
A9: State allows districts to withhold funding from charter schools for providing adminstrative services | B9: X
A10: State "holds harmless" ditrict funding for charter enrollment | C10: X
A11: School is considered LEA if authorized by non-district organization | C11: X
A12: School is considered LEA if authorized by district | C12: X
A13: Cap on number of charter schools | B13: X1
A14: Cap on number of charters schools authorized per year | B14: X
A15: Cap on number of studens attending charter schools | C15: X
A16: Charter schools have an open enrollment policy | B16: X
A18: 1. Mayors of consolidated cities may sponsor no more than 20 charter schools as of calendar year 2007 and are limited to sponsoring five in

Sheet Figure 5
A1: Figure 5: School Characteristics
C2: Statewide District | D2: Statewide Charter
A3: Percentage of stuents eligible for free or reduced price lunch | C3: 0.374 | D3: 0.603
A4: Percentage of schools eligible for Title 1 | C4: 0.4 | D4: 0.649
A5: Percent of students by school type
B6: Primary (K-5) | C6: 0.473 | D6: 0.59
B7: Middle (6-8) | C7: 0.201 | D7: 0.033
B8: High (9-12) | C8: 0.305 | D8: 0.075
B9: Other (K-12,K-8, etc.) | C9: 0.022 | D9: 0.302

Sheet Figure 6
B2: Findings | C2: Indiana | E2: Use the following options only
A3: Federal Funding | B3: Charters have access to federal funds according to state statutes (Yes = black, No = white)* | C3: Y | E3: Y
B4: Percentage of federal revenue equals percentage of total enrollment for charter schools (Yes = black, No = white) | C4: > | E4: P
A5: State Funding | B5: Charters have access to state funds according to state statutes (Yes = black, No = white) | C5: Y | E5: N
B6: Percentage of state revenue equals percentage of total enrollment for charter schools (Yes = black, No = white) | C6: >
A7: Local Funding | B7: Charters have access to local funds according to state statutes (Yes = black, No = white) | C7: Y
B8: Percentage of local revenue equals percentage of total enrollment for charter schools (Yes = black, No = white) | C8: >
A9: Facilities Funding | B9: Charters have access to facilities funds according to state statutes (Yes = black, No = white) | C9: Y1
B10: Percentage of facilities revenue equals percentage of total enrollment for charter schools (Yes = black, No = white) | C10: N/A
A11: Data Availability | B11: State provides detailed, public data on federal, state, local and other revenues for district schools (Yes = black, Partial = grey, No = white) | C11: P
B12: State provides detailed, public data on federal, state, local and other revenues for charter schools (Yes = black, Partial = grey, No = white) | C12: P
A13: Funding Formula | B13: Charters are treated as LEAs for funding purposes (Yes = black, Partial = grey, No = white) | C13: P
B14: State funds student (black) or the LEA (grey) | C14: S | E14: S | F14: L | H14: Use these options for the query to the left only (B18)
B15: State funding formula is fair and equitable (Yes = black, No = white | C15: N
A17: * For this finding, No could indicate that the statue is silent or that it denies access.
A19: 1. HB1001, passed in 2005, provides that if the United States Department of Education approves a new competition for states to receive matching funds for charter school facilities, the State Department of Education shall pursue this federal funding; appropriates ten million dollars ($10,000,000) to the department from the common school fund interest balance in the state general fund to provide state matching funds for the federal funding for the benefit of charter schools, beginning July 1, 2005, and ending June 30, 2007.

Sheet Districts
A1: Corp | B1: Corporation Name | C1: Local Revenue | D1: State Revenue | E1: Federal Revenue | F1: Other Revenue | G1: District/charter | K1: CNAME | L1: CORP | M1: PE07PK | N1: PE07TOT | O1: Total Less Pre-K
A2: 15 | B2: Adams Central Community Schools | C2: 2680595.8 | D2: 4156506.5 | E2: 586287.7 | F2: 1010776.6 | G2: District | H2: State | K2: ="Adams Central Community Schools " -> Adams Central Community Schools | L2: ="0015" -> 0015 | M2: 0 | N2: 1163 | O2: =N2-M2 -> 1163
A3: 25 | B3: North Adams Community Schools | C3: 5616787.1 | D3: 8524549.7 | E3: 834711.52 | F3: 58604.38 | G3: District | H3: State | K3: ="North Adams Community Schools " -> North Adams Community Schools | L3: ="0025" -> 0025 | M3: 0 | N3: 2187 | O3: =N3-M3 -> 2187
A4: 35 | B4: South Adams Schools | C4: 2998331.6 | D4: 5774042 | E4: 1389538.8 | F4: 31391.12 | G4: District | H4: State | K4: ="South Adams Schools " -> South Adams Schools | L4: ="0035" -> 0035 | M4: 28 | N4: 1411 | O4: =N4-M4 -> 1383
A5: 125 | B5: M S D Southwest Allen County | C5: 15617511 | D5: 13235239 | E5: 2963000.9 | F5: 5189697.6 | G5: District | H5: State | K5: ="M S D Southwest Allen County " -> M S D Southwest Allen County | L5: ="0125" -> 0125 | M5: 0 | N5: 6612 | O5: =N5-M5 -> 6612
A6: 225 | B6: Northwest Allen County Schools | C6: 10025540 | D6: 17666338 | E6: 1132933.1 | F6: 239459.86 | G6: District | H6: State | K6: ="Northwest Allen County Schools " -> Northwest Allen County Schools | L6: ="0225" -> 0225 | M6: 0 | N6: 6035 | O6: =N6-M6 -> 6035
A7: 235 | B7: Fort Wayne Community Schools | C7: 42241346 | D7: 1.3244583e+08 | E7: 31323336 | F7: 8503019.1 | G7: District | H7: State | K7: ="Fort Wayne Community Schools " -> Fort Wayne Community Schools | L7: ="0235" -> 0235 | M7: 870 | N7: 31884 | O7: =N7-M7 -> 31014
A8: 255 | B8: East Allen County Schools | C8: 13410756 | D8: 40407830 | E8: 6553015.2 | F8: 14177318 | G8: District | H8: State | K8: ="East Allen County Schools " -> East Allen County Schools | L8: ="0255" -> 0255 | M8: 111 | N8: 10228 | O8: =N8-M8 -> 10117
A9: 365 | B9: Bartholomew Con School Corp | C9: 19401016 | D9: 36993028 | E9: 10701245 | F9: 2771866 | G9: District | H9: State | K9: ="Bartholomew Con School Corp " -> Bartholomew Con School Corp | L9: ="0365" -> 0365 | M9: 222 | N9: 11098 | O9: =N9-M9 -> 10876
A10: 370 | B10: Flat Rock-Hawcreek School Corp | C10: 849625.5 | D10: 5314330.1 | E10: 353526.2 | F10: 27271.54 | G10: District | H10: State | K10: ="Flat Rock-Hawcreek School Corp " -> Flat Rock-Hawcreek School Corp | L10: ="0370" -> 0370 | M10: 16 | N10: 1103 | O10: =N10-M10 -> 1087
A11: 395 | B11: Benton Community School Corp | C11: 4904107.1 | D11: 6835605.4 | E11: 337873.81 | F11: 164185.01 | G11: District | H11: State | K11: ="Benton Community School Corp " -> Benton Community School Corp | L11: ="0395" -> 0395 | M11: 0 | N11: 1948 | O11: =N11-M11 -> 1948
A12: 515 | B12: Blackford County Schools | C12: 2140558.7 | D12: 10350792 | E12: 1470835.5 | F12: 95302.53 | G12: District | H12: State | K12: ="Blackford County Schools " -> Blackford County Schools | L12: ="0515" -> 0515 | M12: 6 | N12: 2258 | O12: =N12-M12 -> 2252
A13: 615 | B13: Western Boone Co Com Sch Dist | C13: 2501348.8 | D13: 7057671.2 | E13: 292242.81 | F13: 23121.37 | G13: District | H13: State | K13: ="Western Boone Co Com Sch Dist " -> Western Boone Co Com Sch Dist | L13: ="0615" -> 0615 | M13: 88 | N13: 1916 | O13: =N13-M13 -> 1828
A14: 630 | B14: Zionsville Community Schools | C14: 9193705.4 | D14: 14185932 | E14: 387901.62 | F14: 325 | G14: District | H14: State | K14: ="Zionsville Community Schools " -> Zionsville Community Schools | L14: ="0630" -> 0630 | M14: 37 | N14: 4959 | O14: =N14-M14 -> 4922
A15: 665 | B15: Lebanon Community School Corp | C15: 4056562.3 | D15: 12686102 | E15: 1414748.7 | F15: 544943.89 | G15: District | H15: State | K15: ="Lebanon Community School Corp " -> Lebanon Community School Corp | L15: ="0665" -> 0665 | M15: 24 | N15: 3529 | O15: =N15-M15 -> 3505
A16: 670 | B16: Brown County School Corporation | C16: 6578275.9 | D16: 7259717.3 | E16: 1430207.4 | F16: 56193.29 | G16: District | H16: State | K16: ="Brown County School Corporation " -> Brown County School Corporation | L16: ="0670" -> 0670 | M16: 18 | N16: 2295 | O16: =N16-M16 -> 2277
A17: 750 | B17: Carroll Consolidated Sch Corp | C17: 1931288 | D17: 3873234.6 | E17: 303165.91 | F17: 1783173.5 | G17: District | H17: State | K17: ="Carroll Consolidated Sch Corp " -> Carroll Consolidated Sch Corp | L17: ="0750" -> 0750 | M17: 0 | N17: 1138 | O17: =N17-M17 -> 1138
A18: 755 | B18: Delphi Community School Corp | C18: 2325723 | D18: 6500627.5 | E18: 669567.95 | F18: 24535.01 | G18: District | H18: State | K18: ="Delphi Community School Corp " -> Delphi Community School Corp | L18: ="0755" -> 0755 | M18: 0 | N18: 1649 | O18: =N18-M18 -> 1649
A19: 775 | B19: Pioneer Regional School Corp | C19: 1319358.8 | D19: 3768497.4 | E19: 314793.05 | F19: 89064.09 | G19: District | H19: State | K19: ="Pioneer Regional School Corp " -> Pioneer Regional School Corp | L19: ="0775" -> 0775 | M19: 0 | N19: 1028 | O19: =N19-M19 -> 1028
A20: 815 | B20: Southeastern School Corp | C20: 2439634.7 | D20: 6365107.6 | E20: 520110.87 | F20: 15752.98 | G20: District | H20: State | K20: ="Southeastern School Corp " -> Southeastern School Corp | L20: ="0815" -> 0815 | M20: 0 | N20: 1607 | O20: =N20-M20 -> 1607
A21: 875 | B21: Logansport Community Sch Corp | C21: 4322061.9 | D21: 21129512 | E21: 6490186.4 | F21: 9321446.2 | G21: District | H21: State | K21: ="Logansport Community Sch Corp " -> Logansport Community Sch Corp | L21: ="0875" -> 0875 | M21: 19 | N21: 4310 | O21: =N21-M21 -> 4291
A22: 940 | B22: West Clark Community Schools | C22: 6554991 | D22: 13024059 | E22: 790700.76 | F22: 769021.23 | G22: District | H22: State | K22: ="West Clark Community Schools " -> West Clark Community Schools | L22: ="0940" -> 0940 | M22: 50 | N22: 3796 | O22: =N22-M22 -> 3746
A23: 1000 | B23: Clarksville Com School Corp | C23: 3445148.2 | D23: 6337788 | E23: 762827.73 | F23: 116460.46 | G23: District | H23: State | K23: ="Clarksville Com School Corp " -> Clarksville Com School Corp | L23: ="1000" -> 1000 | M23: 7 | N23: 1459 | O23: =N23-M23 -> 1452
A24: 1010 | B24: Greater Clark County Schools | C24: 19132926 | D24: 46073660 | E24: 9996640.5 | F24: 2092995.8 | G24: District | H24: State | K24: ="Greater Clark County Schools " -> Greater Clark County Schools | L24: ="1010" -> 1010 | M24: 0 | N24: 10768 | O24: =N24-M24 -> 10768
A25: 1125 | B25: Clay Community Schools | C25: 4393870 | D25: 20191172 | E25: 2945554.1 | F25: 135971.83 | G25: District | H25: State | K25: ="Clay Community Schools " -> Clay Community Schools | L25: ="1125" -> 1125 | M25: 0 | N25: 4661 | O25: =N25-M25 -> 4661
A26: 1150 | B26: Clinton Central School Corp | C26: 1629194.3 | D26: 4127323.5 | E26: 534278 | F26: 224370.85 | G26: District | H26: State | K26: ="Clinton Central School Corp " -> Clinton Central School Corp | L26: ="1150" -> 1150 | M26: 0 | N26: 1077 | O26: =N26-M26 -> 1077
A27: 1160 | B27: Clinton Prairie School Corp | C27: 1685131.9 | D27: 3418112.7 | E27: 379505.1 | F27: 274220.09 | G27: District | H27: State | K27: ="Clinton Prairie School Corp " -> Clinton Prairie School Corp | L27: ="1160" -> 1160 | M27: 0 | N27: 1012 | O27: =N27-M27 -> 1012
A28: 1170 | B28: Community Schools of Frankfort | C28: 3069582.3 | D28: 15191121 | E28: 5703189.6 | F28: 4239430.4 | G28: District | H28: State | K28: ="Community Schools of Frankfort " -> Community Schools of Frankfort | L28: ="1170" -> 1170 | M28: 63 | N28: 3320 | O28: =N28-M28 -> 3257
A29: 1180 | B29: Rossville Con School District | C29: 1349687.9 | D29: 3652632.6 | E29: 334237.01 | F29: 22315.77 | G29: District | H29: State | K29: ="Rossville Con School District " -> Rossville Con School District | L29: ="1180" -> 1180 | M29: 0 | N29: 1014 | O29: =N29-M29 -> 1014
A30: 1300 | B30: Crawford Co Com School Corp | C30: 1478490 | D30: 9297521.9 | E30: 1460592.8 | F30: 338495.58 | G30: District | H30: State | K30: ="Crawford Co Com School Corp " -> Crawford Co Com School Corp | L30: ="1300" -> 1300 | M30: 0 | N30: 1809 | O30: =N30-M30 -> 1809
A31: 1315 | B31: Barr-Reeve Com Schools Inc | C31: 4578817 | D31: 0 | E31: 0 | F31: 0 | G31: District | H31: State | K31: ="Barr-Reeve Com Schools Inc " -> Barr-Reeve Com Schools Inc | L31: ="1315" -> 1315 | M31: 0 | N31: 743 | O31: =N31-M31 -> 743
A32: 1375 | B32: North Daviess Com Schools | C32: 2444644.5 | D32: 4552655.8 | E32: 701127.79 | F32: 18538.04 | G32: District | H32: State | K32: ="North Daviess Com Schools " -> North Daviess Com Schools | L32: ="1375" -> 1375 | M32: 0 | N32: 1137 | O32: =N32-M32 -> 1137
A33: 1405 | B33: Washington Com Schools Inc | C33: 3920010.2 | D33: 11528692 | E33: 1175930.6 | F33: 2529767.6 | G33: District | H33: State | K33: ="Washington Com Schools " -> Washington Com Schools | L33: ="1405" -> 1405 | M33: 0 | N33: 2433 | O33: =N33-M33 -> 2433
A34: 1560 | B34: Sunman-Dearborn Com Sch Corp | C34: 7363832.1 | D34: 16836755 | E34: 3014104.9 | F34: 5222154.3 | G34: District | H34: State | K34: ="Sunman-Dearborn Com Sch Corp " -> Sunman-Dearborn Com Sch Corp | L34: ="1560" -> 1560 | M34: 19 | N34: 4422 | O34: =N34-M34 -> 4403
A35: 1600 | B35: South Dearborn Com School Corp | C35: 4526849.7 | D35: 12811632 | E35: 1109871.9 | F35: 1437488 | G35: District | H35: State | K35: ="South Dearborn Com School Corp " -> South Dearborn Com School Corp | L35: ="1600" -> 1600 | M35: 0 | N35: 2984 | O35: =N35-M35 -> 2984
A36: 1620 | B36: Lawrenceburg Com School Corp | C36: 7014679 | D36: 1209369.5 | E36: 573364.9 | F36: 20498.97 | G36: District | H36: State | K36: ="Lawrenceburg Com School Corp " -> Lawrenceburg Com School Corp | L36: ="1620" -> 1620 | M36: 15 | N36: 1628 | O36: =N36-M36 -> 1613
A37: 1655 | B37: Decatur County Com Schools | C37: 3032660.3 | D37: 8476286.7 | E37: 672623.85 | F37: 30508.58 | G37: District | H37: State | K37: ="Decatur County Com Schools " -> Decatur County Com Schools | L37: ="1655" -> 1655 | M37: 14 | N37: 2293 | O37: =N37-M37 -> 2279
A38: 1730 | B38: Greensburg Community Schools | C38: 3537973.3 | D38: 7885999.2 | E38: 1431382.8 | F38: 265721.4 | G38: District | H38: State | K38: ="Greensburg Community Schools " -> Greensburg Community Schools | L38: ="1730" -> 1730 | M38: 22 | N38: 2169 | O38: =N38-M38 -> 2147
A39: 1805 | B39: DeKalb Co Eastern Com Sch Dist | C39: 3331443 | D39: 5861642.1 | E39: 5041477.5 | F39: 3283697.8 | G39: District | H39: State | K39: ="DeKalb Co Eastern Com Sch Dist " -> DeKalb Co Eastern Com Sch Dist | L39: ="1805" -> 1805 | M39: 0 | N39: 1507 | O39: =N39-M39 -> 1507
A40: 1820 | B40: Garrett-Keyser-Butler Com | C40: 3117590.9 | D40: 6852767.3 | E40: 2431904.5 | F40: 2156229.2 | G40: District | H40: State | K40: ="Garrett-Keyser-Butler Com " -> Garrett-Keyser-Butler Com | L40: ="1820" -> 1820 | M40: 0 | N40: 1720 | O40: =N40-M40 -> 1720
...

Sheet Charters State
A1: Corp | B1: Corporation Name | C1: Local Revenue | D1: State Revenue | E1: Federal Revenue | F1: Other Revenue | G1: District/charter | H1: State/Indy | I1: Enrollment | J1: CNAME | K1: CORP | L1: PE07PK | M1: PE07TOT | N1: Total Less Pre-K
A2: 9300 | B2: Campagna Academy Charter School | C2: 326780.33 | D2: 807114.87 | E2: 101921.09 | F2: 666.16 | G2: Charter | H2: State | I2: 132 | J2: ="Campagna Academy Charter School " -> Campagna Academy Charter School | K2: ="9300" -> 9300 | L2: 0 | M2: 132 | N2: =M2-L2 -> 132
A3: 9310 | B3: Charter School of the Dunes | C3: 1342579.3 | D3: 2681037 | E3: 1028482 | F3: 0 | G3: Charter | H3: State | I3: 490 | J3: ="Charter School of the Dunes " -> Charter School of the Dunes | K3: ="9310" -> 9310 | L3: 0 | M3: 490 | N3: =M3-L3 -> 490
A4: 9315 | B4: Signature Learning Inc | C4: 644456.97 | D4: 1221566.3 | E4: 14193 | F4: 4468.02 | G4: Charter | H4: State | I4: 276 | J4: ="Signature School Inc " -> Signature School Inc | K4: ="9315" -> 9315 | L4: 0 | M4: 276 | N4: =M4-L4 -> 276
A5: 9320 | B5: Community Montessori Inc | C5: 1068842.2 | D5: 1022130.9 | E5: 0 | F5: 74667.01 | G5: Charter | H5: State | I5: 314 | J5: ="Community Montessori Inc " -> Community Montessori Inc | K5: ="9320" -> 9320 | L5: 2 | M5: 316 | N5: =M5-L5 -> 314
A6: 9325 | B6: Options Charter School - Carmel | C6: 225369.48 | D6: 882330.8 | E6: 2691.1 | F6: 17088 | G6: Charter | H6: State | I6: 131 | J6: ="Options Charter School - Carmel " -> Options Charter School - Carmel | K6: ="9325" -> 9325 | L6: 0 | M6: 131 | N6: =M6-L6 -> 131
A7: 9330 | B7: Irvington Community School | C7: 1235976.2 | D7: 1960846.6 | E7: 171365.85 | F7: 612266.4 | G7: Charter | H7: Indianapolis | I7: 460 | J7: ="Irvington Community School " -> Irvington Community School | K7: ="9330" -> 9330 | L7: 0 | M7: 460 | N7: =M7-L7 -> 460
A8: 9340 | B8: New Community School | C8: 203265.69 | D8: 312350.7 | E8: 0 | F8: 43700.57 | G8: Charter | H8: State | I8: 73 | J8: ="New Community School " -> New Community School | K8: ="9340" -> 9340 | L8: 0 | M8: 73 | N8: =M8-L8 -> 73
A9: 9350 | B9: Timothy L Johnson Academy | C9: 245493.83 | D9: 1003857.7 | E9: 294125.31 | F9: 4485.94 | G9: Charter | H9: State | I9: 224 | J9: ="Timothy L Johnson Academy " -> Timothy L Johnson Academy | K9: ="9350" -> 9350 | L9: 0 | M9: 224 | N9: =M9-L9 -> 224
A10: 9360 | B10: Veritas Academy | C10: 278144.53 | D10: 649584.44 | E10: 47855.29 | F10: 1585.26 | G10: Charter | H10: State | I10: 182 | J10: ="Veritas Academy " -> Veritas Academy | K10: ="9360" -> 9360 | L10: 0 | M10: 182 | N10: =M10-L10 -> 182
A11: 9370 | B11: Fall Creek Academy | C11: 711319.8 | D11: 1510339.7 | E11: 224613.1 | F11: 332 | G11: Charter | H11: Indianapolis | I11: 307 | J11: ="Fall Creek Academy " -> Fall Creek Academy | K11: ="9370" -> 9370 | L11: 0 | M11: 307 | N11: =M11-L11 -> 307
A12: 9380 | B12: Christel House Academy | C12: 1949162.6 | D12: 1927108.9 | E12: 522362.81 | F12: 19667.97 | G12: Charter | H12: Indianapolis | I12: 384 | J12: ="Christel House Academy " -> Christel House Academy | K12: ="9380" -> 9380 | L12: 0 | M12: 384 | N12: =M12-L12 -> 384
A13: 9390 | B13: Flanner House Elementary School | C13: 488614.88 | D13: 968099.89 | E13: 157918.97 | F13: 2690.48 | G13: Charter | H13: Indianapolis | I13: 227 | J13: ="Flanner House Elementary School " -> Flanner House Elementary School | K13: ="9390" -> 9390 | L13: 0 | M13: 227 | N13: =M13-L13 -> 227
A14: 9400 | B14: KIPP Indpls College Preparatory | C14: 582873.54 | D14: 917455.33 | E14: 267771.11 | F14: 453004.4 | G14: Charter | H14: Indianapolis | I14: 214 | J14: ="KIPP Indpls College Preparatory " -> KIPP Indpls College Preparatory | K14: ="9400" -> 9400 | L14: 0 | M14: 214 | N14: =M14-L14 -> 214
A15: 9445 | B15: Charles A Tindley Accelerated Sch | C15: 1021456.9 | D15: 1085716.7 | E15: 183916.7 | F15: 334292.08 | G15: Charter | H15: Indianapolis | I15: 245 | J15: ="Charles A Tindley Accelerated Schl" -> Charles A Tindley Accelerated Schl | K15: ="9445" -> 9445 | L15: 0 | M15: 245 | N15: =M15-L15 -> 245
A16: 9460 | B16: Thea Bowman Leadership Academy | C16: 1480101.4 | D16: 2896239.5 | E16: 665169.22 | F16: 0 | G16: Charter | H16: State | I16: 572 | J16: ="Thea Bowman Leadership Academy " -> Thea Bowman Leadership Academy | K16: ="9460" -> 9460 | L16: 0 | M16: 572 | N16: =M16-L16 -> 572
A17: 9465 | B17: Rural Community Schools Inc | C17: 189489.96 | D17: 441988.54 | E17: 43604.74 | F17: 168623.87 | G17: Charter | H17: State | I17: 123 | J17: ="Rural Community Schools Inc " -> Rural Community Schools Inc | K17: ="9465" -> 9465 | L17: 0 | M17: 123 | N17: =M17-L17 -> 123
A18: 9470 | B18: Goodwill Education Initiatives Inc | C18: 441615.17 | D18: 541937.94 | E18: 62221.65 | F18: 143309.69 | G18: Charter | H18: Indianapolis | I18: 122 | J18: Goodwill | K18: ="9470" -> 9470 | L18: 0 | M18: 122 | N18: =M18-L18 -> 122
A19: 9475 | B19: Goodwill Education Initiatives II | C19: 418757.25 | D19: 536218.84 | E19: 50701.99 | F19: 134015.94 | G19: Charter | H19: Indianapolis | I19: 125 | J19: Goodwill | K19: ="9475" -> 9475 | L19: 0 | M19: 125 | N19: =M19-L19 -> 125
A20: 9480 | B20: Fountain Square Academy | C20: 592986.79 | D20: 971940.14 | E20: 281787.1 | F20: 309609 | G20: Charter | H20: Indianapolis | I20: 210 | J20: ="Fountain Square Academy " -> Fountain Square Academy | K20: ="9480" -> 9480 | L20: 0 | M20: 210 | N20: =M20-L20 -> 210
A21: 9485 | B21: SE Neighborhood Sch of Excellence | C21: 396077.36 | D21: 925885.97 | E21: 246204.83 | F21: 214026.16 | G21: Charter | H21: Indianapolis | I21: 235 | J21: ="SE Neighborhood Sch of Excellence " -> SE Neighborhood Sch of Excellence | K21: ="9485" -> 9485 | L21: 0 | M21: 235 | N21: =M21-L21 -> 235
A22: 9495 | B22: Joshua Academy | C22: 570590.5 | D22: 859714.75 | E22: 330169.8 | F22: 51236.52 | G22: Charter | H22: State | I22: 228 | J22: ="Joshua Academy " -> Joshua Academy | K22: ="9495" -> 9495 | L22: 0 | M22: 228 | N22: =M22-L22 -> 228
A23: 9525 | B23: Decatur Discovery Academy Inc | C23: 589468.51 | D23: 516467.81 | E23: 14853 | F23: 549.5 | G23: Charter | H23: Indianapolis | I23: 127 | J23: ="Decatur Discovery Academy Inc " -> Decatur Discovery Academy Inc | K23: ="9525" -> 9525 | L23: 0 | M23: 127 | N23: =M23-L23 -> 127
A24: 9535 | B24: Gary Lighthouse Charter School | C24: 1038409.9 | D24: 2418239.2 | E24: 704490.85 | F24: 1544966.2 | G24: Charter | H24: State | I24: 516 | J24: ="Gary Lighthouse Charter School " -> Gary Lighthouse Charter School | K24: ="9535" -> 9535 | L24: 0 | M24: 516 | N24: =M24-L24 -> 516
A25: 9545 | B25: 21st Century Charter Sch of Gary | C25: 789156.14 | D25: 1727589.4 | E25: 339417.98 | F25: 359002.57 | G25: Charter | H25: State | I25: 304 | J25: ="21st Century Charter Sch of Gary " -> 21st Century Charter Sch of Gary | K25: ="9545" -> 9545 | L25: 0 | M25: 304 | N25: =M25-L25 -> 304
A26: 9555 | B26: East Chicago Urban Enterprise Acad | C26: 482871.96 | D26: 1120056.4 | E26: 386630.92 | F26: 370638 | G26: Charter | H26: State | I26: 284 | J26: ="East Chicago Urban Enterprise Acad" -> East Chicago Urban Enterprise Acad | K26: ="9555" -> 9555 | L26: 0 | M26: 284 | N26: =M26-L26 -> 284
A27: 9565 | B27: Galileo Charter School | C27: 304131.31 | D27: 722823.75 | E27: 286742.13 | F27: 124476 | G27: Charter | H27: State | I27: 179 | J27: ="Galileo Charter School " -> Galileo Charter School | K27: ="9565" -> 9565 | L27: 0 | M27: 179 | N27: =M27-L27 -> 179
A28: 9575 | B28: Indpls Lighthouse Charter School | C28: 553095.98 | D28: 1726107.7 | E28: 587394.15 | F28: 4821076.1 | G28: Charter | H28: Indianapolis | I28: 496 | J28: ="Indpls Lighthouse Charter School " -> Indpls Lighthouse Charter School | K28: ="9575" -> 9575 | L28: 13 | M28: 509 | N28: =M28-L28 -> 496
A29: 9585 | B29: West Gary Lighthouse Charter School | C29: 39946.89 | D29: 938733.64 | E29: 468182.88 | F29: 1853061 | G29: Charter | H29: State | I29: 340 | J29: ="West Gary Lighthouse Charter " -> West Gary Lighthouse Charter | K29: ="9585" -> 9585 | L29: 0 | M29: 340 | N29: =M29-L29 -> 340
A30: 9595 | B30: East Chicago Lighthouse Charter | C30: 17190.06 | D30: 243996.6 | E30: 243811.56 | F30: 428778.38 | G30: Charter | H30: State | I30: 115 | J30: ="East Chicago Lighthouse Charter " -> East Chicago Lighthouse Charter | K30: ="9595" -> 9595 | L30: 0 | M30: 115 | N30: =M30-L30 -> 115
A31: 9615 | B31: Andrew J Brown Academy | C31: 1444803.5 | D31: 2651463.2 | E31: 427758.15 | F31: 0 | G31: Charter | H31: Indianapolis | I31: 609 | J31: ="Andrew J Brown Academy " -> Andrew J Brown Academy | K31: ="9615" -> 9615 | L31: 0 | M31: 609 | N31: =M31-L31 -> 609
A32: 9635 | B32: KIPP Lead College Prep Charter | C32: 53436.8 | D32: 257469.88 | E32: 263633.93 | F32: 429384.7 | G32: Charter | H32: State | I32: 81 | J32: ="KIPP Lead College Prep Charter " -> KIPP Lead College Prep Charter | K32: ="9635" -> 9635 | L32: 0 | M32: 81 | N32: =M32-L32 -> 81
A33: 9640 | B33: Options Charter School - Noblesville | C33: 67836.55 | D33: 255192.61 | E33: 301711.8 | F33: 341541.92 | G33: Charter | H33: State | I33: 109 | J33: ="Options Charter Sch - Noblesville " -> Options Charter Sch - Noblesville | K33: ="9640" -> 9640 | L33: 0 | M33: 109 | N33: =M33-L33 -> 109
A34: 9645 | B34: Challenge Foundation Academy | C34: 440684.18 | D34: 571500.79 | E34: 328509.74 | F34: 921409.12 | G34: Charter | H34: Indianapolis | I34: 257 | J34: ="Challenge Foundation Academy " -> Challenge Foundation Academy | K34: ="9645" -> 9645 | L34: 0 | M34: 257 | N34: =M34-L34 -> 257
A35: 9650 | B35: Herron Charter | C35: 459592.69 | D35: 232176.24 | E35: 383820.84 | F35: 513197.92 | G35: Charter | H35: Indianapolis | I35: 98 | J35: ="Herron Charter " -> Herron Charter | K35: ="9650" -> 9650 | L35: 0 | M35: 98 | N35: =M35-L35 -> 98
A36: 9655 | B36: Hope Academy | C36: 56672.06 | D36: 55666.78 | E36: 269482.03 | F36: 86172.46 | G36: Charter | H36: Indianapolis | I36: 28 | J36: ="Hope Academy " -> Hope Academy | K36: ="9655" -> 9655 | L36: 0 | M36: 28 | N36: =M36-L36 -> 28
A37: 9660 | B37: Stonegate Early Clg HS for Sci/Tec | C37: 319775.4 | D37: 295688.65 | E37: 113489 | F37: 480982 | G37: Charter | H37: Indianapolis | I37: 158 | J37: ="Stonegate Early Clg HS for Sci/Tec" -> Stonegate Early Clg HS for Sci/Tec | K37: ="9660" -> 9660 | L37: 0 | M37: 158 | N37: =M37-L37 -> 158
A38: 9665 | B38: Geist Montessori Academy | C38: 15977.43 | D38: 71778.49 | E38: 221000 | F38: 152565 | G38: Charter | H38: State | I38: 38 | J38: ="Geist Montessori Academy " -> Geist Montessori Academy | K38: ="9665" -> 9665 | L38: 0 | M38: 38 | N38: =M38-L38 -> 38
C39: =SUM(C2:C38) -> 21087004 | D39: =SUM(D2:D38) -> 37928417 | E39: =SUM(E2:E38) -> 10038005 | F39: =SUM(F2:F38) -> 15017536 | I39: =SUM(I2:I38) -> 9013
C40: =C39/I39 -> 2339.621 | D40: =D39/I39 -> 4208.19 | E40: =E39/I39 -> 1113.7251 | F40: =F39/I39 -> 1666.2084 | J40: Not included in analysis as the school did not have enrollment in FY07
...

Sheet Charters Indy
A1: Corp | B1: Corporation Name | C1: Local Revenue | D1: State Revenue | E1: Federal Revenue | F1: Other Revenue | G1: District/charter | H1: State/Indy | I1: Enrollment
A2: 9330 | B2: Irvington Community School | C2: 1235976.2 | D2: 1960846.6 | E2: 171365.85 | F2: 612266.4 | G2: Charter | H2: Indianapolis | I2: 460
A3: 9370 | B3: Fall Creek Academy | C3: 711319.8 | D3: 1510339.7 | E3: 224613.1 | F3: 332 | G3: Charter | H3: Indianapolis | I3: 307
A4: 9380 | B4: Christel House Academy | C4: 1949162.6 | D4: 1927108.9 | E4: 522362.81 | F4: 19667.97 | G4: Charter | H4: Indianapolis | I4: 384
A5: 9390 | B5: Flanner House Elementary School | C5: 488614.88 | D5: 968099.89 | E5: 157918.97 | F5: 2690.48 | G5: Charter | H5: Indianapolis | I5: 227
A6: 9400 | B6: KIPP Indpls College Preparatory | C6: 582873.54 | D6: 917455.33 | E6: 267771.11 | F6: 453004.4 | G6: Charter | H6: Indianapolis | I6: 214
A7: 9445 | B7: Charles A Tindley Accelerated Sch | C7: 1021456.9 | D7: 1085716.7 | E7: 183916.7 | F7: 334292.08 | G7: Charter | H7: Indianapolis | I7: 245
A8: 9470 | B8: Goodwill Education Initiatives Inc | C8: 441615.17 | D8: 541937.94 | E8: 62221.65 | F8: 143309.69 | G8: Charter | H8: Indianapolis | I8: 122
A9: 9475 | B9: Goodwill Education Initiatives II | C9: 418757.25 | D9: 536218.84 | E9: 50701.99 | F9: 134015.94 | G9: Charter | H9: Indianapolis | I9: 125
A10: 9480 | B10: Fountain Square Academy | C10: 592986.79 | D10: 971940.14 | E10: 281787.1 | F10: 309609 | G10: Charter | H10: Indianapolis | I10: 210
A11: 9485 | B11: SE Neighborhood Sch of Excellence | C11: 396077.36 | D11: 925885.97 | E11: 246204.83 | F11: 214026.16 | G11: Charter | H11: Indianapolis | I11: 235
A12: 9525 | B12: Decatur Discovery Academy Inc | C12: 589468.51 | D12: 516467.81 | E12: 14853 | F12: 549.5 | G12: Charter | H12: Indianapolis | I12: 127
A13: 9575 | B13: Indpls Lighthouse Charter School | C13: 553095.98 | D13: 1726107.7 | E13: 587394.15 | F13: 4821076.1 | G13: Charter | H13: Indianapolis | I13: 509
... A18: 9660 | B18: Stonegate Early Clg HS for Sci/Tec | C18: 319775.4 | D18: 295688.65 | E18: 113489 | F18: 480982 | G18: Charter | H18: Indianapolis | I18: 158
C19: =SUM(C2:C18) -> 11702933 | D19: =SUM(D2:D18) -> 17394621 | E19: =SUM(E2:E18) -> 4294171 | F19: =SUM(F2:F18) -> 9046601.2 | I19: =SUM(I2:I18) -> 4315
