Workbook
Name QRY_FTETOTAL: #REF!

Sheet Resident FTE
A1: The Colorado Department of Higher Education
A2: FTE Student Enrollment Report
A4: Governing Board / Institutions | B4: Resident Student FTE
B5: FY 91-92 | C5: FY 92-93 | D5: FY 93-94 | E5: FY 94-95 | F5: FY 95-96 | G5: FY 96-97 | H5: FY 97-98 | I5: FY 98-99 | J5: FY 99-2000 | K5: FY 2000-01 | L5: FY 2001-02 | M5: FY 2002-03 | N5: FY 2003-04 | O5: FY 2004-05 | P5: FY 2005-06 | Q5: FY 2006-07 | R5: FY 2007-08 | S5: FY 2008-09 | T5: FY 2009-10
A6: Regents of the University of Colorado: | B6: =SUM(B7:B10) -> 27854.4 | C6: =SUM(C7:C10) -> 27362 | D6: =SUM(D7:D10) -> 27504 | E6: =SUM(E7:E10) -> 27237 | F6: =SUM(F7:F10) -> 27083.93 | G6: =SUM(G7:G10) -> 27312 | H6: =SUM(H7:H10) -> 28012.9 | I6: =SUM(I7:I10) -> 28491.3 | ... T6: =SUM(T7:T10) -> 39101.016
A7: University of Colorado-Boulder | B7: 15456 | C7: 14809 | D7: 15097 | E7: 14846 | F7: 14631.93 | G7: 14934 | H7: 15239 | I7: 15243 | J7: 15667 | K7: 15691.5 | L7: 16007 | M7: 16934.1 | N7: 17759 | O7: 18109 | P7: 18020 | Q7: 17805 | R7: 17785 | S7: 17744 | T7: 18168.89
A8: University of Colorado-Colorado Springs | B8: 3884 | C8: 3752 | D8: 3669 | E8: 3734 | F8: 3777 | G8: 3840 | H8: 4243.9 | I8: 4423 | J8: 4601.7 | K8: 4687.9 | L8: 4930.1 | M8: 5526.4 | N8: 5788.2 | O8: 5843.7 | P8: 5822 | Q8: 5815 | R8: 5836 | S8: 6118 | T8: 6534.7197
A9: University of Colorado Denver - Downtown Campus | B9: 6584.4 | C9: 6794 | D9: 6564 | E9: 6409 | F9: 6426 | G9: 6313 | H9: 6380 | I9: 6627.3 | J9: 6600.6 | K9: 6783 | L9: 7065.2 | M9: 7636.7 | N9: 7908.7 | O9: 8110.38 | P9: 8056.6 | Q9: 8206 | R9: 8484.4 | S9: 8734 | T9: 10455.288
A10: University of Colorado Denver - Anschutz Medical Campus | B10: 1930 | C10: 2007 | D10: 2174 | E10: 2248 | F10: 2249 | G10: 2225 | H10: 2150 | I10: 2198 | J10: 2102.19 | K10: 2095.85 | L10: 2161.72 | M10: 2248.74 | N10: 2409.93 | O10: 2508.27 | P10: 2943.8 | Q10: 2966.1 | R10: 3078.3 | S10: 3095 | T10: 3942.1187
A11: Board of Governors of Colorado State University System: | B11: =SUM(B12:B14) -> 18538.2 | C11: =SUM(C12:C14) -> 18663.9 | D11: =SUM(D12:D14) -> 18499.2 | E11: =SUM(E12:E14) -> 18534.5 | F11: =SUM(F12:F14) -> 18586.3 | G11: =SUM(G12:G14) -> 18683.4 | H11: =SUM(H12:H14) -> 18568.5 | I11: =SUM(I12:I14) -> 18907.4 | ... T11: =SUM(T12:T14) -> 22107.562
A12: Colorado State University-Education & General | B12: 14496.2 | C12: 14583.7 | D12: 14530.6 | E12: 14660.5 | F12: 14844 | G12: 15157 | H12: 15080 | I12: 15423.5 | J12: 15657.2 | K12: 15597.4 | L12: 16173.6 | M12: 16931.2 | N12: 17405.9 | O12: 17779 | P12: 17550.467 | Q12: 17328.067 | R12: 17270 | S12: 17479 | T12: 17912.429
A13: Colorado State University-Professional Veterinary Medicine | B13: 331 | C13: 326.7 | D13: 336.6 | E13: 325.5 | F13: 329.6 | G13: 327.4 | H13: 352.1 | I13: 379.9 | J13: 399.9 | K13: 422 | L13: 419.2 | M13: 432.3 | N13: 424 | O13: 434.6 | P13: 422.13333 | Q13: 423.66667 | R13: 419.8 | S13: 405 | T13: 426.53486
A14: Colorado State University - Pueblo | B14: 3711 | C14: 3753.5 | D14: 3632 | E14: 3548.5 | F14: 3412.7 | G14: 3199 | H14: 3136.4 | I14: 3104 | J14: 3107.56 | K14: 3086.3 | L14: 3045.1 | M14: 3029.7 | N14: 3158.4 | O14: 3266.2 | P14: 3161.9 | Q14: 3002.5 | R14: 3080 | S14: 3419 | T14: 3768.5981
A15: Trustees of Fort Lewis College:
A16: Fort Lewis College | B16: 2854 | C16: 2783 | D16: 2838 | E16: 2764 | F16: 2913 | G16: 2935 | H16: 2866 | I16: 2733 | J16: 2756 | K16: 2672 | L16: 2800 | M16: 2784 | N16: 2727 | O16: 2733 | P16: 2656 | Q16: 2644 | R16: 2621 | S16: 2426 | T16: 2395.9293
A17: Trustees of Colorado School of Mines:
A18: Colorado School of Mines | B18: 1743 | C18: 1910 | D18: 1983 | E18: 2043 | F18: 2122 | G18: 2160 | H18: 2168 | I18: 2281.2 | J18: 2343.6 | K18: 2250.8 | L18: ='[1]Resident Undergraduate'!L18+'[1]Resident Graduate'!L16 -> 2356.4 | M18: ='[1]Resident Undergraduate'!M18+'[1]Resident Graduate'!M16 -> 2452.2 | N18: ='[1]Resident Undergraduate'!N18+'[1]Resident Graduate'!N16 -> 2584.2 | O18: ='[1]Resident Undergraduate'!O18+'[1]Resident Graduate'!O16 -> 2845.1 | P18: ='[1]Resident Undergraduate'!P18+'[1]Resident Graduate'!P16 -> 2973.5 | Q18: ='[1]Resident Undergraduate'!Q18+'[1]Resident Graduate'!Q16 -> 3018.9 | R18: ='[1]Resident Undergraduate'!R18+'[1]Resident Graduate'!R16 -> 3044.9 | S18: ='[1]Resident Undergraduate'!S18+'[1]Resident Graduate'!S16 -> 3144 | T18: 3288.3218
A19: Board of Trustees University of Northern Colorado:
A20: University of Northern Colorado | B20: 8717 | C20: 8651 | D20: 8749 | E20: 8643 | F20: 8403 | G20: 8225 | H20: 8315 | I20: 8573.36 | J20: 8989.58 | K20: 9041.07 | L20: 9088.1 | M20: 9420.91 | N20: 9596.47 | O20: 9878.37 | P20: 9880.83 | Q20: 9657.93 | R20: 9361.78 | S20: 8658 | T20: 8918.4351
A21: Trustees of Adams State College:
A22: Adams State College | B22: 1928 | C22: 1931 | D22: 1748 | E22: 1820 | F22: 1833 | G22: 1869 | H22: 1798 | I22: 1898.15 | J22: 1893.7 | K22: 1809 | L22: 1919.7 | M22: 1965.9 | N22: 1993.2 | O22: 1893.92 | P22: 1933.07 | Q22: 1822.01 | R22: 1702.96 | S22: 1646 | T22: 1860.3332
A23: Trustees of Mesa State College:
A24: Mesa State College | B24: 3280 | C24: 3320 | D24: 3382 | E24: 3494 | F24: 3589 | G24: 3667 | H24: 3663 | I24: 3779 | J24: 3703.1 | K24: 3882.6 | L24: 4029.5 | M24: 4209.1 | N24: =4312.9+21.4 -> 4334.3 | O24: 4481 | P24: 4228.93 | Q24: 4411.2833 | R24: 4459.4 | S24: 4541 | T24: 5306.118
A25: Trustees of Metropolitan State College:
A26: Metropolitan State College of Denver | B26: 12343 | C26: 12162 | D26: 11996 | E26: 11923 | F26: 11767 | G26: 11988 | H26: 12166 | I26: 11909 | J26: 11942.73 | K26: 11845.77 | L26: 12760.5 | M26: 13720.1 | N26: 14178.47 | O26: 14626.67 | P26: 14685.53 | Q26: 14743.84 | R26: 15135 | S26: 15621 | T26: 16790.761
A27: Trustees of Western State College:
A28: Western State College | B28: 1584 | C28: 1602 | D28: 1393 | E28: 1417 | F28: 1460 | G28: 1525 | H28: 1478 | I28: 1501 | J28: 1498.9 | K28: 1431.8 | L28: 1499.23 | M28: 1549.9 | N28: 1617.6 | O28: 1545 | P28: 1521.66 | Q28: 1451.68 | R28: 1428.43 | S28: 1453 | T28: 1430.3615
A29: Community Colleges of Colorado: | B29: =SUM(B30:B42) -> 31436 | C29: =SUM(C30:C42) -> 33149 | D29: =SUM(D30:D42) -> 33090 | E29: =SUM(E30:E42) -> 32960 | F29: =SUM(F30:F42) -> 33129 | G29: =SUM(G30:G42) -> 33332 | H29: =SUM(H30:H42) -> 33810 | I29: =SUM(I30:I42) -> 34936.3 | ... T29: =SUM(T30:T42) -> 53454.045
A30: Arapahoe Community College | B30: 3880 | C30: 3849 | D30: 3832 | E30: 3744 | F30: 3832 | G30: 3821 | H30: 3785 | I30: 3832 | J30: 3814.8 | K30: 3799.7 | L30: 4079.77 | M30: 4500.23 | N30: 4657.23 | O30: 4570.57 | P30: 4209.17 | Q30: 4110.22 | R30: 4021.83 | S30: 4370 | T30: 5120.7086
A31: Colorado Northwestern Community College | B31: 782 | C31: 807 | D31: 750 | E31: 697 | F31: 704 | G31: 732 | H31: 768 | I31: 710 | J31: 651.21 | K31: 665.5 | L31: 796.27 | M31: 842.9 | N31: 907.1 | O31: 895.38 | P31: 698.93 | Q31: 623 | R31: 663.21 | S31: 686 | T31: 708.35943
A32: Community College of Aurora | B32: 2359 | C32: 2514 | D32: 2658 | E32: 2603 | F32: 2559 | G32: 2366 | H32: 2349 | I32: 2494 | J32: 2608.17 | K32: 2595.5 | L32: 2710.73 | M32: 3075.81 | N32: 3410.07 | O32: 3396.29 | P32: 3299.7 | Q32: 3058 | R32: 3076.6 | S32: 3338 | T32: 3923.9918
A33: Community College of Denver | B33: 3873 | C33: 4240 | D33: 4365 | E33: 4187 | F33: 3984 | G33: 3973 | H33: 3801 | I33: 3816 | J33: 3761.95 | K33: 3791.47 | L33: 3924.59 | M33: 4743.72 | N33: 5245.38 | O33: 5044.93 | P33: 4710.37 | Q33: 4890.14 | R33: 4654.94 | S33: 4933 | T33: 6900.6972
A34: Front Range Community College | B34: 5926 | C34: 6187 | D34: 6061 | E34: 5916 | F34: 6329 | G34: 6056 | H34: 6066 | I34: 6554 | J34: 6984.95 | K34: 7286.43 | L34: 7718.85 | M34: 8764.17 | N34: 9401.19 | O34: 9629.27 | P34: 9316.2 | Q34: 9055.5 | R34: 9312.8 | S34: 9945 | T34: 11863.86
A35: Lamar Community College | B35: 586 | C35: 612 | D35: 581 | E35: 557 | F35: 580 | G35: 621 | H35: 633 | I35: 649 | J35: 614.09 | K35: 630.43 | L35: 639.77 | M35: 707.21 | N35: 696.4 | O35: 637 | P35: 624.63 | Q35: 611.32 | R35: 662.49867 | S35: 674 | T35: 630.81198
A36: Morgan Community College | B36: 566 | C36: 712 | D36: 807 | E36: 696 | F36: 744 | G36: 802 | H36: 861 | I36: 911 | J36: 948.14 | K36: 949.03 | L36: 979.47 | M36: 922.17 | N36: 936.36 | O36: 961.72 | P36: 984.13 | Q36: 984.15 | R36: 973.57 | S36: 999 | T36: 1052.3702
A37: Northeastern Junior College | B37: 1695 | C37: 1724 | D37: 1570 | E37: 1559 | F37: 1515 | G37: 1579 | H37: 1457 | I37: 1500 | J37: 1463.85 | K37: 1545.8 | L37: 1512.5 | M37: 1556.57 | N37: 1446.77 | O37: 1403.32 | P37: 1203.91 | Q37: 1151 | R37: 1195.8 | S37: 1343 | T37: 1367.3083
A38: Otero Junior College | B38: 666 | C38: 677 | D38: 749 | E38: 761 | F38: 735 | G38: 773 | H38: 835 | I38: 887 | J38: 933.15 | K38: 954.58 | L38: 1072.25 | M38: 1108.7 | N38: 1215.8 | O38: 1236.63 | P38: 1221.33 | Q38: 1219.25 | R38: 1138.67 | S38: 1123 | T38: 1187.8184
A39: Pikes Peak Community College | B39: 4571 | C39: 4717 | D39: 4437 | E39: 4573 | F39: 4436 | G39: 4662 | H39: 4772 | I39: 4994 | J39: 5171.4 | K39: 5207.8 | L39: 5507.2 | M39: 6147.2 | N39: 6461.1 | O39: 6716.7 | P39: 6780.5 | Q39: 6412.9 | R39: 7102.39 | S39: 7624 | T39: 8824.5987
A40: Pueblo Community College | B40: 2472 | C40: 2696 | D40: 2623 | E40: 2690 | F40: 2747 | G40: 2831 | H40: 3045 | I40: 3053 | J40: 3175.34 | K40: 3159.03 | L40: 3492.31 | M40: 3782.45 | N40: 4170.87 | O40: 4095.57 | P40: 3809.38 | Q40: 3442 | R40: 3404.8 | S40: 3761 | T40: 4616.2549
A41: Red Rocks Community College | B41: 3037 | C41: 3365 | D41: 3598 | E41: 3627 | F41: 3666 | G41: 3720 | H41: 4035 | I41: 4228.3 | J41: 4033.99 | K41: 4064.23 | L41: 4031.5 | M41: 4323.24 | N41: 4581.39 | O41: 4522.55 | P41: 4249.33 | Q41: 4114.86 | R41: 4465.67 | S41: 4841 | T41: 5844.4292
...

Sheet % Change Resident FTE
A1: The Colorado Department of Higher Education
A2: Final FTE Student Enrollment Report
A4: Governing Board / Institutions | B4: Percentage Change in Resident Student FTE
B5: FY 92 to FY 93 | C5: FY 93 to FY 94 | D5: FY 94 to FY 95 | E5: FY 95 to FY 96 | F5: FY 96 to FY 97 | G5: FY 97 to FY 98 | H5: FY 98 to FY 99 | I5: FY 99 to FY 00 | J5: FY 00 to 01 | K5: FY 01 to 02 | L5: FY 02 to 03 | M5: FY 03 to 04 | N5: FY 04 to 05 | O5: FY 05 to 06 | P5: FY 06 to 07 | Q5: FY 07 to 08 | R5: FY 08 to 09 | S5: FY 09 to 10
A6: Regents of the University of Colorado: | B6: =('Resident FTE'!C6-'Resident FTE'!B6)/'Resident FTE'!B6 -> -0.017677638 | C6: =('Resident FTE'!D6-'Resident FTE'!C6)/'Resident FTE'!C6 -> 0.0051896791 | D6: =('Resident FTE'!E6-'Resident FTE'!D6)/'Resident FTE'!D6 -> -0.0097076789 | E6: =('Resident FTE'!F6-'Resident FTE'!E6)/'Resident FTE'!E6 -> -0.0056199288 | F6: =('Resident FTE'!G6-'Resident FTE'!F6)/'Resident FTE'!F6 -> 0.0084208606 | G6: =('Resident FTE'!H6-'Resident FTE'!G6)/'Resident FTE'!G6 -> 0.025662712 | H6: =('Resident FTE'!I6-'Resident FTE'!H6)/'Resident FTE'!H6 -> 0.017077846 | I6: =('Resident FTE'!J6-'Resident FTE'!I6)/'Resident FTE'!I6 -> 0.016853917 | ... S6: =('Resident FTE'!T6-'Resident FTE'!S6)/'Resident FTE'!S6 -> 0.095542729
A7: University of Colorado-Boulder | B7: =('Resident FTE'!C7-'Resident FTE'!B7)/'Resident FTE'!B7 -> -0.041860766 | C7: =('Resident FTE'!D7-'Resident FTE'!C7)/'Resident FTE'!C7 -> 0.019447633 | D7: =('Resident FTE'!E7-'Resident FTE'!D7)/'Resident FTE'!D7 -> -0.01662582 | E7: =('Resident FTE'!F7-'Resident FTE'!E7)/'Resident FTE'!E7 -> -0.014419372 | F7: =('Resident FTE'!G7-'Resident FTE'!F7)/'Resident FTE'!F7 -> 0.020644577 | G7: =('Resident FTE'!H7-'Resident FTE'!G7)/'Resident FTE'!G7 -> 0.020423195 | H7: =('Resident FTE'!I7-'Resident FTE'!H7)/'Resident FTE'!H7 -> 0.00026248441 | I7: =('Resident FTE'!J7-'Resident FTE'!I7)/'Resident FTE'!I7 -> 0.027816047 | ... S7: =('Resident FTE'!T7-'Resident FTE'!S7)/'Resident FTE'!S7 -> 0.023945532
A8: University of Colorado-Colorado Springs | B8: =('Resident FTE'!C8-'Resident FTE'!B8)/'Resident FTE'!B8 -> -0.033985582 | C8: =('Resident FTE'!D8-'Resident FTE'!C8)/'Resident FTE'!C8 -> -0.022121535 | D8: =('Resident FTE'!E8-'Resident FTE'!D8)/'Resident FTE'!D8 -> 0.017715999 | E8: =('Resident FTE'!F8-'Resident FTE'!E8)/'Resident FTE'!E8 -> 0.011515801 | F8: =('Resident FTE'!G8-'Resident FTE'!F8)/'Resident FTE'!F8 -> 0.016679905 | G8: =('Resident FTE'!H8-'Resident FTE'!G8)/'Resident FTE'!G8 -> 0.10518229 | H8: =('Resident FTE'!I8-'Resident FTE'!H8)/'Resident FTE'!H8 -> 0.042201748 | I8: =('Resident FTE'!J8-'Resident FTE'!I8)/'Resident FTE'!I8 -> 0.040402442 | ... S8: =('Resident FTE'!T8-'Resident FTE'!S8)/'Resident FTE'!S8 -> 0.068113715
A9: University of Colorado-Denver | B9: =('Resident FTE'!C9-'Resident FTE'!B9)/'Resident FTE'!B9 -> 0.031832817 | C9: =('Resident FTE'!D9-'Resident FTE'!C9)/'Resident FTE'!C9 -> -0.0338534 | D9: =('Resident FTE'!E9-'Resident FTE'!D9)/'Resident FTE'!D9 -> -0.02361365 | E9: =('Resident FTE'!F9-'Resident FTE'!E9)/'Resident FTE'!E9 -> 0.0026525199 | F9: =('Resident FTE'!G9-'Resident FTE'!F9)/'Resident FTE'!F9 -> -0.017584812 | G9: =('Resident FTE'!H9-'Resident FTE'!G9)/'Resident FTE'!G9 -> 0.010613021 | H9: =('Resident FTE'!I9-'Resident FTE'!H9)/'Resident FTE'!H9 -> 0.038761755 | I9: =('Resident FTE'!J9-'Resident FTE'!I9)/'Resident FTE'!I9 -> -0.00402879 | ... S9: =('Resident FTE'!T9-'Resident FTE'!S9)/'Resident FTE'!S9 -> 0.19707895
A10: University of Colorado-Health Sciences | B10: =('Resident FTE'!C10-'Resident FTE'!B10)/'Resident FTE'!B10 -> 0.039896373 | C10: =('Resident FTE'!D10-'Resident FTE'!C10)/'Resident FTE'!C10 -> 0.083208769 | D10: =('Resident FTE'!E10-'Resident FTE'!D10)/'Resident FTE'!D10 -> 0.034038638 | E10: =('Resident FTE'!F10-'Resident FTE'!E10)/'Resident FTE'!E10 -> 0.00044483986 | F10: =('Resident FTE'!G10-'Resident FTE'!F10)/'Resident FTE'!F10 -> -0.01067141 | G10: =('Resident FTE'!H10-'Resident FTE'!G10)/'Resident FTE'!G10 -> -0.033707865 | H10: =('Resident FTE'!I10-'Resident FTE'!H10)/'Resident FTE'!H10 -> 0.022325581 | I10: =('Resident FTE'!J10-'Resident FTE'!I10)/'Resident FTE'!I10 -> -0.043589627 | ... S10: =('Resident FTE'!T10-'Resident FTE'!S10)/'Resident FTE'!S10 -> 0.27370557
A11: Board of Governors of Colorado State University System: | B11: =('Resident FTE'!C11-'Resident FTE'!B11)/'Resident FTE'!B11 -> 0.0067805936 | C11: =('Resident FTE'!D11-'Resident FTE'!C11)/'Resident FTE'!C11 -> -0.0088245222 | D11: =('Resident FTE'!E11-'Resident FTE'!D11)/'Resident FTE'!D11 -> 0.0019081906 | E11: =('Resident FTE'!F11-'Resident FTE'!E11)/'Resident FTE'!E11 -> 0.0027947881 | F11: =('Resident FTE'!G11-'Resident FTE'!F11)/'Resident FTE'!F11 -> 0.0052242781 | G11: =('Resident FTE'!H11-'Resident FTE'!G11)/'Resident FTE'!G11 -> -0.0061498442 | H11: =('Resident FTE'!I11-'Resident FTE'!H11)/'Resident FTE'!H11 -> 0.01825134 | I11: =('Resident FTE'!J11-'Resident FTE'!I11)/'Resident FTE'!I11 -> 0.013606313 | ... S11: =('Resident FTE'!T11-'Resident FTE'!S11)/'Resident FTE'!S11 -> 0.037767553
A12: Colorado State University-Education & General | B12: =('Resident FTE'!C12-'Resident FTE'!B12)/'Resident FTE'!B12 -> 0.0060360646 | C12: =('Resident FTE'!D12-'Resident FTE'!C12)/'Resident FTE'!C12 -> -0.0036410513 | D12: =('Resident FTE'!E12-'Resident FTE'!D12)/'Resident FTE'!D12 -> 0.0089397547 | E12: =('Resident FTE'!F12-'Resident FTE'!E12)/'Resident FTE'!E12 -> 0.012516626 | F12: =('Resident FTE'!G12-'Resident FTE'!F12)/'Resident FTE'!F12 -> 0.021085961 | G12: =('Resident FTE'!H12-'Resident FTE'!G12)/'Resident FTE'!G12 -> -0.005080161 | H12: =('Resident FTE'!I12-'Resident FTE'!H12)/'Resident FTE'!H12 -> 0.022778515 | I12: =('Resident FTE'!J12-'Resident FTE'!I12)/'Resident FTE'!I12 -> 0.015152203 | ... S12: =('Resident FTE'!T12-'Resident FTE'!S12)/'Resident FTE'!S12 -> 0.024797143
A13: Colorado State University-Professional Veterinary Medicine | B13: =('Resident FTE'!C13-'Resident FTE'!B13)/'Resident FTE'!B13 -> -0.012990937 | C13: =('Resident FTE'!D13-'Resident FTE'!C13)/'Resident FTE'!C13 -> 0.03030303 | D13: =('Resident FTE'!E13-'Resident FTE'!D13)/'Resident FTE'!D13 -> -0.032976827 | E13: =('Resident FTE'!F13-'Resident FTE'!E13)/'Resident FTE'!E13 -> 0.012596006 | F13: =('Resident FTE'!G13-'Resident FTE'!F13)/'Resident FTE'!F13 -> -0.0066747573 | G13: =('Resident FTE'!H13-'Resident FTE'!G13)/'Resident FTE'!G13 -> 0.075442883 | H13: =('Resident FTE'!I13-'Resident FTE'!H13)/'Resident FTE'!H13 -> 0.078954842 | I13: =('Resident FTE'!J13-'Resident FTE'!I13)/'Resident FTE'!I13 -> 0.052645433 | ... S13: =('Resident FTE'!T13-'Resident FTE'!S13)/'Resident FTE'!S13 -> 0.053172486
A14: Colorado State University - Pueblo | B14: =('Resident FTE'!C14-'Resident FTE'!B14)/'Resident FTE'!B14 -> 0.011452439 | C14: =('Resident FTE'!D14-'Resident FTE'!C14)/'Resident FTE'!C14 -> -0.032369788 | D14: =('Resident FTE'!E14-'Resident FTE'!D14)/'Resident FTE'!D14 -> -0.022990088 | E14: =('Resident FTE'!F14-'Resident FTE'!E14)/'Resident FTE'!E14 -> -0.038269691 | F14: =('Resident FTE'!G14-'Resident FTE'!F14)/'Resident FTE'!F14 -> -0.062619041 | G14: =('Resident FTE'!H14-'Resident FTE'!G14)/'Resident FTE'!G14 -> -0.019568615 | H14: =('Resident FTE'!I14-'Resident FTE'!H14)/'Resident FTE'!H14 -> -0.010330315 | I14: =('Resident FTE'!J14-'Resident FTE'!I14)/'Resident FTE'!I14 -> 0.0011469072 | ... S14: =('Resident FTE'!T14-'Resident FTE'!S14)/'Resident FTE'!S14 -> 0.10225155
A15: Trustees of Fort Lewis College:
A16: Fort Lewis College | B16: =('Resident FTE'!C16-'Resident FTE'!B16)/'Resident FTE'!B16 -> -0.024877365 | C16: =('Resident FTE'!D16-'Resident FTE'!C16)/'Resident FTE'!C16 -> 0.019762846 | D16: =('Resident FTE'!E16-'Resident FTE'!D16)/'Resident FTE'!D16 -> -0.0260747 | E16: =('Resident FTE'!F16-'Resident FTE'!E16)/'Resident FTE'!E16 -> 0.053907381 | F16: =('Resident FTE'!G16-'Resident FTE'!F16)/'Resident FTE'!F16 -> 0.0075523515 | G16: =('Resident FTE'!H16-'Resident FTE'!G16)/'Resident FTE'!G16 -> -0.02350937 | H16: =('Resident FTE'!I16-'Resident FTE'!H16)/'Resident FTE'!H16 -> -0.046406141 | I16: =('Resident FTE'!J16-'Resident FTE'!I16)/'Resident FTE'!I16 -> 0.0084156604 | ... S16: =('Resident FTE'!T16-'Resident FTE'!S16)/'Resident FTE'!S16 -> -0.012395167
A17: Trustees of Colorado School of Mines:
A18: Colorado School of Mines | B18: =('Resident FTE'!C18-'Resident FTE'!B18)/'Resident FTE'!B18 -> 0.095811819 | C18: =('Resident FTE'!D18-'Resident FTE'!C18)/'Resident FTE'!C18 -> 0.038219895 | D18: =('Resident FTE'!E18-'Resident FTE'!D18)/'Resident FTE'!D18 -> 0.030257186 | E18: =('Resident FTE'!F18-'Resident FTE'!E18)/'Resident FTE'!E18 -> 0.038668625 | F18: =('Resident FTE'!G18-'Resident FTE'!F18)/'Resident FTE'!F18 -> 0.017907634 | G18: =('Resident FTE'!H18-'Resident FTE'!G18)/'Resident FTE'!G18 -> 0.0037037037 | H18: =('Resident FTE'!I18-'Resident FTE'!H18)/'Resident FTE'!H18 -> 0.052214022 | I18: =('Resident FTE'!J18-'Resident FTE'!I18)/'Resident FTE'!I18 -> 0.027354024 | ... S18: =('Resident FTE'!T18-'Resident FTE'!S18)/'Resident FTE'!S18 -> 0.045903887
A19: Board of Trustees University of Northern Colorado:
A20: University of Northern Colorado | B20: =('Resident FTE'!C20-'Resident FTE'!B20)/'Resident FTE'!B20 -> -0.0075714122 | C20: =('Resident FTE'!D20-'Resident FTE'!C20)/'Resident FTE'!C20 -> 0.01132817 | D20: =('Resident FTE'!E20-'Resident FTE'!D20)/'Resident FTE'!D20 -> -0.01211567 | E20: =('Resident FTE'!F20-'Resident FTE'!E20)/'Resident FTE'!E20 -> -0.027768136 | F20: =('Resident FTE'!G20-'Resident FTE'!F20)/'Resident FTE'!F20 -> -0.021182911 | G20: =('Resident FTE'!H20-'Resident FTE'!G20)/'Resident FTE'!G20 -> 0.010942249 | H20: =('Resident FTE'!I20-'Resident FTE'!H20)/'Resident FTE'!H20 -> 0.031071557 | I20: =('Resident FTE'!J20-'Resident FTE'!I20)/'Resident FTE'!I20 -> 0.048548061 | ... S20: =('Resident FTE'!T20-'Resident FTE'!S20)/'Resident FTE'!S20 -> 0.030080283
A21: Trustees of Adams State College:
A22: Adams State College | B22: =('Resident FTE'!C22-'Resident FTE'!B22)/'Resident FTE'!B22 -> 0.0015560166 | C22: =('Resident FTE'!D22-'Resident FTE'!C22)/'Resident FTE'!C22 -> -0.094769549 | D22: =('Resident FTE'!E22-'Resident FTE'!D22)/'Resident FTE'!D22 -> 0.041189931 | E22: =('Resident FTE'!F22-'Resident FTE'!E22)/'Resident FTE'!E22 -> 0.0071428571 | F22: =('Resident FTE'!G22-'Resident FTE'!F22)/'Resident FTE'!F22 -> 0.019639935 | G22: =('Resident FTE'!H22-'Resident FTE'!G22)/'Resident FTE'!G22 -> -0.037988229 | H22: =('Resident FTE'!I22-'Resident FTE'!H22)/'Resident FTE'!H22 -> 0.055700779 | I22: =('Resident FTE'!J22-'Resident FTE'!I22)/'Resident FTE'!I22 -> -0.002344388 | ... S22: =('Resident FTE'!T22-'Resident FTE'!S22)/'Resident FTE'!S22 -> 0.13021461
A23: Trustees of Mesa State College:
A24: Mesa State College | B24: =('Resident FTE'!C24-'Resident FTE'!B24)/'Resident FTE'!B24 -> 0.012195122 | C24: =('Resident FTE'!D24-'Resident FTE'!C24)/'Resident FTE'!C24 -> 0.018674699 | D24: =('Resident FTE'!E24-'Resident FTE'!D24)/'Resident FTE'!D24 -> 0.033116499 | E24: =('Resident FTE'!F24-'Resident FTE'!E24)/'Resident FTE'!E24 -> 0.027189468 | F24: =('Resident FTE'!G24-'Resident FTE'!F24)/'Resident FTE'!F24 -> 0.021733073 | G24: =('Resident FTE'!H24-'Resident FTE'!G24)/'Resident FTE'!G24 -> -0.0010908099 | H24: =('Resident FTE'!I24-'Resident FTE'!H24)/'Resident FTE'!H24 -> 0.031668032 | I24: =('Resident FTE'!J24-'Resident FTE'!I24)/'Resident FTE'!I24 -> -0.020084678 | ... S24: =('Resident FTE'!T24-'Resident FTE'!S24)/'Resident FTE'!S24 -> 0.16849109
A25: Trustees of Metropolitan State College:
A26: Metropolitan State College of Denver | B26: =('Resident FTE'!C26-'Resident FTE'!B26)/'Resident FTE'!B26 -> -0.014664182 | C26: =('Resident FTE'!D26-'Resident FTE'!C26)/'Resident FTE'!C26 -> -0.013649071 | D26: =('Resident FTE'!E26-'Resident FTE'!D26)/'Resident FTE'!D26 -> -0.0060853618 | E26: =('Resident FTE'!F26-'Resident FTE'!E26)/'Resident FTE'!E26 -> -0.013083955 | F26: =('Resident FTE'!G26-'Resident FTE'!F26)/'Resident FTE'!F26 -> 0.018781338 | G26: =('Resident FTE'!H26-'Resident FTE'!G26)/'Resident FTE'!G26 -> 0.014848182 | H26: =('Resident FTE'!I26-'Resident FTE'!H26)/'Resident FTE'!H26 -> -0.021124445 | I26: =('Resident FTE'!J26-'Resident FTE'!I26)/'Resident FTE'!I26 -> 0.0028323117 | ... S26: =('Resident FTE'!T26-'Resident FTE'!S26)/'Resident FTE'!S26 -> 0.074883903
A27: Trustees of Western State College:
A28: Western State College | B28: =('Resident FTE'!C28-'Resident FTE'!B28)/'Resident FTE'!B28 -> 0.011363636 | C28: =('Resident FTE'!D28-'Resident FTE'!C28)/'Resident FTE'!C28 -> -0.13046192 | D28: =('Resident FTE'!E28-'Resident FTE'!D28)/'Resident FTE'!D28 -> 0.017229002 | E28: =('Resident FTE'!F28-'Resident FTE'!E28)/'Resident FTE'!E28 -> 0.030345801 | F28: =('Resident FTE'!G28-'Resident FTE'!F28)/'Resident FTE'!F28 -> 0.044520548 | G28: =('Resident FTE'!H28-'Resident FTE'!G28)/'Resident FTE'!G28 -> -0.030819672 | H28: =('Resident FTE'!I28-'Resident FTE'!H28)/'Resident FTE'!H28 -> 0.01556157 | I28: =('Resident FTE'!J28-'Resident FTE'!I28)/'Resident FTE'!I28 -> -0.0013990673 | ... S28: =('Resident FTE'!T28-'Resident FTE'!S28)/'Resident FTE'!S28 -> -0.015580553
A29: Community Colleges of Colorado: | B29: =('Resident FTE'!C29-'Resident FTE'!B29)/'Resident FTE'!B29 -> 0.054491666 | C29: =('Resident FTE'!D29-'Resident FTE'!C29)/'Resident FTE'!C29 -> -0.0017798425 | D29: =('Resident FTE'!E29-'Resident FTE'!D29)/'Resident FTE'!D29 -> -0.0039286794 | E29: =('Resident FTE'!F29-'Resident FTE'!E29)/'Resident FTE'!E29 -> 0.0051274272 | F29: =('Resident FTE'!G29-'Resident FTE'!F29)/'Resident FTE'!F29 -> 0.006127562 | G29: =('Resident FTE'!H29-'Resident FTE'!G29)/'Resident FTE'!G29 -> 0.014340574 | H29: =('Resident FTE'!I29-'Resident FTE'!H29)/'Resident FTE'!H29 -> 0.033312629 | I29: =('Resident FTE'!J29-'Resident FTE'!I29)/'Resident FTE'!I29 -> 0.015432945 | ... S29: =('Resident FTE'!T29-'Resident FTE'!S29)/'Resident FTE'!S29 -> 0.18998319
A30: Arapahoe Community College | B30: =('Resident FTE'!C30-'Resident FTE'!B30)/'Resident FTE'!B30 -> -0.0079896907 | C30: =('Resident FTE'!D30-'Resident FTE'!C30)/'Resident FTE'!C30 -> -0.0044167316 | D30: =('Resident FTE'!E30-'Resident FTE'!D30)/'Resident FTE'!D30 -> -0.022964509 | E30: =('Resident FTE'!F30-'Resident FTE'!E30)/'Resident FTE'!E30 -> 0.023504274 | F30: =('Resident FTE'!G30-'Resident FTE'!F30)/'Resident FTE'!F30 -> -0.0028705637 | G30: =('Resident FTE'!H30-'Resident FTE'!G30)/'Resident FTE'!G30 -> -0.0094216174 | H30: =('Resident FTE'!I30-'Resident FTE'!H30)/'Resident FTE'!H30 -> 0.012417437 | I30: =('Resident FTE'!J30-'Resident FTE'!I30)/'Resident FTE'!I30 -> -0.0044885177 | ... S30: =('Resident FTE'!T30-'Resident FTE'!S30)/'Resident FTE'!S30 -> 0.17178687
A31: Colorado Northwestern Community College | B31: =('Resident FTE'!C31-'Resident FTE'!B31)/'Resident FTE'!B31 -> 0.031969309 | C31: =('Resident FTE'!D31-'Resident FTE'!C31)/'Resident FTE'!C31 -> -0.07063197 | D31: =('Resident FTE'!E31-'Resident FTE'!D31)/'Resident FTE'!D31 -> -0.070666667 | E31: =('Resident FTE'!F31-'Resident FTE'!E31)/'Resident FTE'!E31 -> 0.010043042 | F31: =('Resident FTE'!G31-'Resident FTE'!F31)/'Resident FTE'!F31 -> 0.039772727 | G31: =('Resident FTE'!H31-'Resident FTE'!G31)/'Resident FTE'!G31 -> 0.049180328 | H31: =('Resident FTE'!I31-'Resident FTE'!H31)/'Resident FTE'!H31 -> -0.075520833 | I31: =('Resident FTE'!J31-'Resident FTE'!I31)/'Resident FTE'!I31 -> -0.082802817 | ... S31: =('Resident FTE'!T31-'Resident FTE'!S31)/'Resident FTE'!S31 -> 0.032593927
A32: Community College of Aurora | B32: =('Resident FTE'!C32-'Resident FTE'!B32)/'Resident FTE'!B32 -> 0.065705808 | C32: =('Resident FTE'!D32-'Resident FTE'!C32)/'Resident FTE'!C32 -> 0.057279236 | D32: =('Resident FTE'!E32-'Resident FTE'!D32)/'Resident FTE'!D32 -> -0.02069225 | E32: =('Resident FTE'!F32-'Resident FTE'!E32)/'Resident FTE'!E32 -> -0.016903573 | F32: =('Resident FTE'!G32-'Resident FTE'!F32)/'Resident FTE'!F32 -> -0.075420086 | G32: =('Resident FTE'!H32-'Resident FTE'!G32)/'Resident FTE'!G32 -> -0.0071851226 | H32: =('Resident FTE'!I32-'Resident FTE'!H32)/'Resident FTE'!H32 -> 0.061728395 | I32: =('Resident FTE'!J32-'Resident FTE'!I32)/'Resident FTE'!I32 -> 0.045777867 | ... S32: =('Resident FTE'!T32-'Resident FTE'!S32)/'Resident FTE'!S32 -> 0.17555177
A33: Community College of Denver | B33: =('Resident FTE'!C33-'Resident FTE'!B33)/'Resident FTE'!B33 -> 0.094758585 | C33: =('Resident FTE'!D33-'Resident FTE'!C33)/'Resident FTE'!C33 -> 0.029481132 | D33: =('Resident FTE'!E33-'Resident FTE'!D33)/'Resident FTE'!D33 -> -0.040778923 | E33: =('Resident FTE'!F33-'Resident FTE'!E33)/'Resident FTE'!E33 -> -0.048483401 | F33: =('Resident FTE'!G33-'Resident FTE'!F33)/'Resident FTE'!F33 -> -0.0027610442 | G33: =('Resident FTE'!H33-'Resident FTE'!G33)/'Resident FTE'!G33 -> -0.043292223 | H33: =('Resident FTE'!I33-'Resident FTE'!H33)/'Resident FTE'!H33 -> 0.0039463299 | I33: =('Resident FTE'!J33-'Resident FTE'!I33)/'Resident FTE'!I33 -> -0.014164046 | ... S33: =('Resident FTE'!T33-'Resident FTE'!S33)/'Resident FTE'!S33 -> 0.39888448
A34: Front Range Community College | B34: =('Resident FTE'!C34-'Resident FTE'!B34)/'Resident FTE'!B34 -> 0.044043199 | C34: =('Resident FTE'!D34-'Resident FTE'!C34)/'Resident FTE'!C34 -> -0.020365282 | D34: =('Resident FTE'!E34-'Resident FTE'!D34)/'Resident FTE'!D34 -> -0.023923445 | E34: =('Resident FTE'!F34-'Resident FTE'!E34)/'Resident FTE'!E34 -> 0.069810683 | F34: =('Resident FTE'!G34-'Resident FTE'!F34)/'Resident FTE'!F34 -> -0.043134776 | G34: =('Resident FTE'!H34-'Resident FTE'!G34)/'Resident FTE'!G34 -> 0.001651255 | H34: =('Resident FTE'!I34-'Resident FTE'!H34)/'Resident FTE'!H34 -> 0.080448401 | I34: =('Resident FTE'!J34-'Resident FTE'!I34)/'Resident FTE'!I34 -> 0.065753738 | ... S34: =('Resident FTE'!T34-'Resident FTE'!S34)/'Resident FTE'!S34 -> 0.19294719
A35: Lamar Community College | B35: =('Resident FTE'!C35-'Resident FTE'!B35)/'Resident FTE'!B35 -> 0.044368601 | C35: =('Resident FTE'!D35-'Resident FTE'!C35)/'Resident FTE'!C35 -> -0.050653595 | D35: =('Resident FTE'!E35-'Resident FTE'!D35)/'Resident FTE'!D35 -> -0.04130809 | E35: =('Resident FTE'!F35-'Resident FTE'!E35)/'Resident FTE'!E35 -> 0.041292639 | F35: =('Resident FTE'!G35-'Resident FTE'!F35)/'Resident FTE'!F35 -> 0.070689655 | G35: =('Resident FTE'!H35-'Resident FTE'!G35)/'Resident FTE'!G35 -> 0.019323671 | H35: =('Resident FTE'!I35-'Resident FTE'!H35)/'Resident FTE'!H35 -> 0.025276461 | I35: =('Resident FTE'!J35-'Resident FTE'!I35)/'Resident FTE'!I35 -> -0.053790447 | ... S35: =('Resident FTE'!T35-'Resident FTE'!S35)/'Resident FTE'!S35 -> -0.06407718
A36: Morgan Community College | B36: =('Resident FTE'!C36-'Resident FTE'!B36)/'Resident FTE'!B36 -> 0.25795053 | C36: =('Resident FTE'!D36-'Resident FTE'!C36)/'Resident FTE'!C36 -> 0.13342697 | D36: =('Resident FTE'!E36-'Resident FTE'!D36)/'Resident FTE'!D36 -> -0.13754647 | E36: =('Resident FTE'!F36-'Resident FTE'!E36)/'Resident FTE'!E36 -> 0.068965517 | F36: =('Resident FTE'!G36-'Resident FTE'!F36)/'Resident FTE'!F36 -> 0.077956989 | G36: =('Resident FTE'!H36-'Resident FTE'!G36)/'Resident FTE'!G36 -> 0.073566085 | H36: =('Resident FTE'!I36-'Resident FTE'!H36)/'Resident FTE'!H36 -> 0.058072009 | I36: =('Resident FTE'!J36-'Resident FTE'!I36)/'Resident FTE'!I36 -> 0.040768386 | ... S36: =('Resident FTE'!T36-'Resident FTE'!S36)/'Resident FTE'!S36 -> 0.05342364
A37: Northeastern Junior College | B37: =('Resident FTE'!C37-'Resident FTE'!B37)/'Resident FTE'!B37 -> 0.017109145 | C37: =('Resident FTE'!D37-'Resident FTE'!C37)/'Resident FTE'!C37 -> -0.089327146 | D37: =('Resident FTE'!E37-'Resident FTE'!D37)/'Resident FTE'!D37 -> -0.0070063694 | E37: =('Resident FTE'!F37-'Resident FTE'!E37)/'Resident FTE'!E37 -> -0.02822322 | F37: =('Resident FTE'!G37-'Resident FTE'!F37)/'Resident FTE'!F37 -> 0.042244224 | G37: =('Resident FTE'!H37-'Resident FTE'!G37)/'Resident FTE'!G37 -> -0.077264091 | H37: =('Resident FTE'!I37-'Resident FTE'!H37)/'Resident FTE'!H37 -> 0.029512697 | I37: =('Resident FTE'!J37-'Resident FTE'!I37)/'Resident FTE'!I37 -> -0.0241 | ... S37: =('Resident FTE'!T37-'Resident FTE'!S37)/'Resident FTE'!S37 -> 0.0181
A38: Otero Junior College | B38: =('Resident FTE'!C38-'Resident FTE'!B38)/'Resident FTE'!B38 -> 0.016516517 | C38: =('Resident FTE'!D38-'Resident FTE'!C38)/'Resident FTE'!C38 -> 0.10635155 | D38: =('Resident FTE'!E38-'Resident FTE'!D38)/'Resident FTE'!D38 -> 0.016021362 | E38: =('Resident FTE'!F38-'Resident FTE'!E38)/'Resident FTE'!E38 -> -0.034165572 | F38: =('Resident FTE'!G38-'Resident FTE'!F38)/'Resident FTE'!F38 -> 0.05170068 | G38: =('Resident FTE'!H38-'Resident FTE'!G38)/'Resident FTE'!G38 -> 0.080206986 | H38: =('Resident FTE'!I38-'Resident FTE'!H38)/'Resident FTE'!H38 -> 0.062275449 | I38: =('Resident FTE'!J38-'Resident FTE'!I38)/'Resident FTE'!I38 -> 0.052029312 | ... S38: =('Resident FTE'!T38-'Resident FTE'!S38)/'Resident FTE'!S38 -> 0.057718947
A39: Pikes Peak Community College | B39: =('Resident FTE'!C39-'Resident FTE'!B39)/'Resident FTE'!B39 -> 0.031940494 | C39: =('Resident FTE'!D39-'Resident FTE'!C39)/'Resident FTE'!C39 -> -0.059359763 | D39: =('Resident FTE'!E39-'Resident FTE'!D39)/'Resident FTE'!D39 -> 0.030651341 | E39: =('Resident FTE'!F39-'Resident FTE'!E39)/'Resident FTE'!E39 -> -0.029958452 | F39: =('Resident FTE'!G39-'Resident FTE'!F39)/'Resident FTE'!F39 -> 0.050946799 | G39: =('Resident FTE'!H39-'Resident FTE'!G39)/'Resident FTE'!G39 -> 0.023595024 | H39: =('Resident FTE'!I39-'Resident FTE'!H39)/'Resident FTE'!H39 -> 0.046521375 | I39: =('Resident FTE'!J39-'Resident FTE'!I39)/'Resident FTE'!I39 -> 0.035522627 | ... S39: =('Resident FTE'!T39-'Resident FTE'!S39)/'Resident FTE'!S39 -> 0.15747622
... A48: Public Summary | B48: =('Resident FTE'!C48-'Resident FTE'!B48)/'Resident FTE'!B48 -> 0.01094421 | C48: =('Resident FTE'!D48-'Resident FTE'!C48)/'Resident FTE'!C48 -> -0.006139904 | D48: =('Resident FTE'!E48-'Resident FTE'!D48)/'Resident FTE'!D48 -> -0.0041460441 | E48: =('Resident FTE'!F48-'Resident FTE'!E48)/'Resident FTE'!E48 -> -0.0013852359 | F48: =('Resident FTE'!G48-'Resident FTE'!F48)/'Resident FTE'!F48 -> 0.0077805455 | G48: =('Resident FTE'!H48-'Resident FTE'!G48)/'Resident FTE'!G48 -> 0.0091101566 | H48: =('Resident FTE'!I48-'Resident FTE'!H48)/'Resident FTE'!H48 -> 0.017158999 | I48: =('Resident FTE'!J48-'Resident FTE'!I48)/'Resident FTE'!I48 -> 0.014071154 | ... S48: =('Resident FTE'!T48-'Resident FTE'!S48)/'Resident FTE'!S48 -> 0.11042485

Sheet Non-Resident FTE
A1: The Colorado Department of Higher Education
A2: Final FTE Student Enrollment Report
A4: Governing Board / Institutions | B4: Non-Resident Student FTE
B5: FY 91-92 | C5: FY 92-93 | D5: FY 93-94 | E5: FY 94-95 | F5: FY 95-96 | G5: FY 96-97 | H5: FY 97-98 | I5: FY 98-99 | J5: FY 99-2000 | K5: FY 2000-01 | L5: FY 2001-02 | M5: FY 2002-03 | N5: FY 2003-04 | O5: FY 2004-05 | P5: FY 2005-06 | Q5: FY 2006-07 | R5: FY 2007-08 | S5: FY 2008-09 | T5: FY 2009-10
A6: Regents of the University of Colorado: | B6: =SUM(B7:B10) -> 8246 | C6: =SUM(C7:C10) -> 8499 | D6: =SUM(D7:D10) -> 8205 | E6: =SUM(E7:E10) -> 7830 | F6: =SUM(F7:F10) -> 8028 | G6: =SUM(G7:G10) -> 7913 | H6: =SUM(H7:H10) -> 8187 | I6: =SUM(I7:I10) -> 8387 | ... T6: =SUM(T7:T10) -> 11632.527
A7: University of Colorado-Boulder | B7: 7374 | C7: 7547 | D7: 7175 | E7: 6787 | F7: 6895 | G7: 6749 | H7: 6957 | I7: 7203 | J7: 7215 | K7: 7521.4 | L7: 7914 | M7: 8320.3 | N7: 8615 | O7: 8399 | P7: 7958 | Q7: 8155 | R7: 8317 | S7: 9071 | T7: 9163.1047
A8: University of Colorado-Colorado Springs | B8: 205 | C8: 231 | D8: 247 | E8: 240 | F8: 232 | G8: 244 | H8: 315 | I8: 345 | J8: 366.4 | K8: 384.5 | L8: 393.6 | M8: 379.2 | N8: 357.7 | O8: 366.4 | P8: 380 | Q8: 325 | R8: 444 | S8: 488 | T8: 510.83946
A9: University of Colorado Denver - Downtown Campus | B9: 423 | C9: 460 | D9: 516 | E9: 546 | F9: 611 | G9: 656 | H9: 677 | I9: 602 | J9: 651.9 | K9: 788.2 | L9: 827.4 | M9: 770.2 | N9: 671.1 | O9: 676.1 | P9: 606 | Q9: 638.2 | R9: 788.4 | S9: 955 | T9: 1173.2569
A10: University of Colorado Denver - Anschutz Medical Campus | B10: 244 | C10: 261 | D10: 267 | E10: 257 | F10: 290 | G10: 264 | H10: 238 | I10: 237 | J10: 257.8 | K10: 233.68 | L10: 248.66 | M10: 270.75 | N10: 254.32 | O10: 266.23 | P10: 317.5 | Q10: 368.2 | R10: 412 | S10: 520 | T10: 785.32582
A11: Board of Governors of Colorado State University System: | B11: =SUM(B12:B14) -> 5089.5 | C11: =SUM(C12:C14) -> 5242.5 | D11: =SUM(D12:D14) -> 5447.3 | E11: =SUM(E12:E14) -> 5469.3 | F11: =SUM(F12:F14) -> 5578.1 | G11: =SUM(G12:G14) -> 5393.4 | H11: =SUM(H12:H14) -> 5360.2 | I11: =SUM(I12:I14) -> 5293.1 | ... T11: =SUM(T12:T14) -> 4915.5254
A12: Colorado State University-Education & General | B12: 4446 | C12: 4567 | D12: 4642 | E12: 4616 | F12: 4689 | G12: 4510 | H12: 4467 | I12: 4440 | J12: 4431.1 | K12: 4366.5 | L12: 4549.8 | M12: 4593.4 | N12: 4465.6 | O12: 4349.6 | P12: 4124.6667 | Q12: 4031.0333 | R12: 4142.7 | S12: 4096 | T12: 4113.3933
A13: Colorado State University-Professional Veterinary Medicine | B13: 370.5 | C13: 365.5 | D13: 397.3 | E13: 391.3 | F13: 393.1 | G13: 399.4 | H13: 376.2 | I13: 357.1 | J13: 332.7 | K13: 322.6 | L13: 325.3 | M13: 329.8 | N13: 329.7 | O13: 330.8 | P13: 340.8 | Q13: 343.96667 | R13: 346 | S13: 332 | T13: 359.83
A14: Colorado State University - Pueblo | B14: 273 | C14: 310 | D14: 408 | E14: 462 | F14: 496 | G14: 484 | H14: 517 | I14: 496 | J14: 521.27 | K14: 521 | L14: 469.8 | M14: 417.9 | N14: 375.7 | O14: 347.9 | P14: 356.1 | Q14: 384 | R14: 327.8 | S14: 387 | T14: 442.3021
A15: Trustees of Fort Lewis College:
A16: Fort Lewis College | B16: 939 | C16: 1084 | D16: 1193 | E16: 1182 | F16: 1215 | G16: 1255 | H16: 1301 | I16: 1295 | J16: 1382 | K16: 1347 | L16: 1369 | M16: 1296 | N16: 1214 | O16: 1127 | P16: 1056 | Q16: 1075 | R16: 1081 | S16: 1104 | T16: =[2]Sheet1!$F$11 -> 1091.2748
A17: Trustees of Colorado School of Mines:
A18: Colorado School of Mines | B18: 830 | C18: 948 | D18: 1023 | E18: 1051 | F18: 1067 | G18: 1082 | H18: 1043 | I18: 969 | J18: 932.8 | K18: 863.6 | L18: ='[1]Non-Resident Undergraduate'!L18+'[1]Non-Resident Graduate'!L16 -> 857.9 | M18: ='[1]Non-Resident Undergraduate'!M18+'[1]Non-Resident Graduate'!M16 -> 824.1 | N18: ='[1]Non-Resident Undergraduate'!N18+'[1]Non-Resident Graduate'!N16 -> 810.1 | O18: ='[1]Non-Resident Undergraduate'!O18+'[1]Non-Resident Graduate'!O16 -> 820 | P18: ='[1]Non-Resident Undergraduate'!P18+'[1]Non-Resident Graduate'!P16 -> 831.6 | Q18: ='[1]Non-Resident Undergraduate'!Q18+'[1]Non-Resident Graduate'!Q16 -> 900.3 | R18: ='[1]Non-Resident Undergraduate'!R18+'[1]Non-Resident Graduate'!R16 -> 1030.2 | S18: ='[1]Non-Resident Undergraduate'!S18+'[1]Non-Resident Graduate'!S16 -> 1181 | T18: =[2]Sheet1!$F$12 -> 1305.9433
A19: Board of Trustees University of Northern Colorado:
A20: University of Northern Colorado | B20: 1055 | C20: 1055 | D20: 1091 | E20: 1078 | F20: 1151 | G20: 1218 | H20: 1304 | I20: 1343 | J20: 1305.12 | K20: 1268.16 | L20: 1240.43 | M20: 1184.87 | N20: 1112.23 | O20: 1134.33 | P20: 1103.86 | Q20: 1136.6 | R20: 1058.23 | S20: 1033 | T20: =[2]Sheet1!$F$13 -> 1039.7477
A21: Trustees of Adams State College:
A22: Adams State College | B22: 450 | C22: 419 | D22: 416 | E22: 435 | F22: 441 | G22: 426 | H22: 379 | I22: 368 | J22: 368 | K22: 330.6 | L22: 373.7 | M22: 355.7 | N22: 320 | O22: 280.33 | P22: 245.76 | Q22: 228.4 | R22: 274.65 | S22: 273 | T22: =[2]Sheet1!$F$14 -> 309.04977
A23: Trustees of Mesa State College:
A24: Mesa State College | B24: 251 | C24: 313 | D24: 352 | E24: 399 | F24: 412 | G24: 406 | H24: 422 | I24: 410 | J24: 438.3 | K24: 428.1 | L24: 431.3 | M24: 441.8 | N24: =461.2+1.9 -> 463.1 | O24: 483.1 | P24: 457.2 | Q24: 437.91667 | R24: 507.6 | S24: 517 | T24: =[2]Sheet1!$F$15 -> 622.22331
A25: Trustees of Metropolitan State College:
A26: Metropolitan State College of Denver | B26: 343 | C26: 337 | D26: 311 | E26: 323 | F26: 320 | G26: 359 | H26: 390 | I26: 408 | J26: 426.5 | K26: 434.03 | L26: 466.37 | M26: 467.56 | N26: 449.61 | O26: 425.8 | P26: 401.53 | Q26: 431.54 | R26: 502.2 | S26: 544 | T26: =[2]Sheet1!$F$16 -> 542.40072
A27: Trustees of Western State College:
A28: Western State College | B28: 767 | C28: 840 | D28: 764 | E28: 744 | F28: 766 | G28: 755 | H28: 746 | I28: 697 | J28: 680.1 | K28: 640.25 | L28: 594.51 | M28: 591.35 | N28: 547.1 | O28: 513.35 | P28: 497.2 | Q28: 466.23 | R28: 447.92 | S28: 422 | T28: =[2]Sheet1!$F$17 -> 427.23367
A29: Community Colleges of Colorado: | B29: =SUM(B30:B42) -> 1659 | C29: =SUM(C30:C42) -> 2063 | D29: =SUM(D30:D42) -> 2075 | E29: =SUM(E30:E42) -> 2153 | F29: =SUM(F30:F42) -> 1957 | G29: =SUM(G30:G42) -> 1892 | H29: =SUM(H30:H42) -> 1906 | I29: =SUM(I30:I42) -> 2077 | ... T29: =SUM(T30:T42) -> 3978.5324
A30: Arapahoe Community College | B30: 248 | C30: 296 | D30: 278 | E30: 292 | F30: 240 | G30: 269 | H30: 301 | I30: 376 | J30: 324.9 | K30: 291.4 | L30: 238.25 | M30: 187.59 | N30: 196.53 | O30: 192.31 | P30: 188.9 | Q30: 245.75 | R30: 221.8 | S30: 186 | T30: 211.98125
A31: Colorado Northwestern Community College | B31: 79 | C31: 118 | D31: 126 | E31: 118 | F31: 116 | G31: 101 | H31: 98 | I31: 85 | J31: 79.08 | K31: 88.95 | L31: 76.03 | M31: 79.36 | N31: 101.35 | O31: 98.54 | P31: 83.97 | Q31: 95.55 | R31: 107.3 | S31: 125 | T31: 136.91664
A32: Community College of Aurora | B32: 49 | C32: 41 | D32: 44 | E32: 68 | F32: 60 | G32: 52 | H32: 55 | I32: 83 | J32: 84.42 | K32: 73.86 | L32: 103.23 | M32: 102.17 | N32: 73.74 | O32: 91.67 | P32: 101.4 | Q32: 170 | R32: 187.9 | S32: 211 | T32: 247.77897
A33: Community College of Denver | B33: 159 | C33: 246 | D33: 238 | E33: 253 | F33: 252 | G33: 254 | H33: 237 | I33: 255 | J33: 264.16 | K33: 235.22 | L33: 263.57 | M33: 298.02 | N33: 293.47 | O33: 296.97 | P33: 311.83 | Q33: 414.14 | R33: 481.96 | S33: 510 | T33: 718.44091
A34: Front Range Community College | B34: 308 | C34: 405 | D34: 422 | E34: 434 | F34: 408 | G34: 390 | H34: 434 | I34: 454 | J34: 481.59 | K34: 393.65 | L34: 406.35 | M34: 459.86 | N34: 547.51 | O34: 591.08 | P34: 567.8 | Q34: 671.3 | R34: 728 | S34: 749 | T34: 914.4377
A35: Lamar Community College | B35: 51 | C35: 63 | D35: 73 | E35: 73 | F35: 84 | G35: 77 | H35: 104 | I35: 96 | J35: 59.26 | K35: 43.862 | L35: 42.59 | M35: 54.94 | N35: 44.3 | O35: 59.99 | P35: 80.39 | Q35: 73.96 | R35: 97.889 | S35: 86 | T35: 103.06443
A36: Morgan Community College | B36: 18 | C36: 45 | D36: 39 | E36: 20 | F36: 25 | G36: 13 | H36: 18 | I36: 16 | J36: 11.29 | K36: 9.81 | L36: 8.3 | M36: 5.65 | N36: 4.75 | O36: 18.35 | P36: 36.1 | Q36: 38.48 | R36: 29.97 | S36: 33 | T36: 34.9603
A37: Northeastern Junior College | B37: 85 | C37: 101 | D37: 78 | E37: 74 | F37: 78 | G37: 134 | H37: 75 | I37: 79 | J37: 73.65 | K37: 58.58 | L37: 81.04 | M37: 84.11 | N37: 85.13 | O37: 74.64 | P37: 70.74 | Q37: 91.03 | R37: 101.66 | S37: 87 | T37: 89.846995
A38: Otero Junior College | B38: 60 | C38: 61 | D38: 50 | E38: 52 | F38: 40 | G38: 32 | H38: 19 | I38: 19 | J38: 25.37 | K38: 19.4 | L38: 19.84 | M38: 31.93 | N38: 31 | O38: 37.3 | P38: 40.6 | Q38: 82.4 | R38: 97.36 | S38: 111 | T38: 109.39266
A39: Pikes Peak Community College | B39: 131 | C39: 169 | D39: 149 | E39: 121 | F39: 124 | G39: 142 | H39: 147 | I39: 114 | J39: 118.4 | K39: 126.5 | L39: 172.4 | M39: 248.9 | N39: 245.5 | O39: 270 | P39: 348.3 | Q39: 346.84 | R39: 378.88 | S39: 524 | T39: 821.63494
A40: Pueblo Community College | B40: 45 | C40: 48 | D40: 52 | E40: 59 | F40: 74 | G40: 80 | H40: 101 | I40: 168 | J40: 156.93 | K40: 132.52 | L40: 117.99 | M40: 120.05 | N40: 115 | O40: 108.96 | P40: 95.56 | Q40: 80 | R40: 82.6 | S40: 95 | T40: 134.19595
A41: Red Rocks Community College | B41: 208 | C41: 278 | D41: 342 | E41: 406 | F41: 287 | G41: 177 | H41: 150 | I41: 170 | J41: 167.81 | K41: 169.13 | L41: 172.33 | M41: 148.06 | N41: 129.48 | O41: 134.12 | P41: 137.97 | Q41: 163.73 | R41: 214.65 | S41: 230 | T41: 285.6649
...

Sheet % Change Non-Resident FTE
A1: The Colorado Department of Higher Education
A2: Final FTE Student Enrollment Report
A4: Governing Board / Institutions | B4: Percentage Change in Non-Resident Student FTE
B5: FY 92 to FY 93 | C5: FY 93 to FY 94 | D5: FY 94 to FY 95 | E5: FY 95 to FY 96 | F5: FY 96 to FY 97 | G5: FY 97 to FY 98 | H5: FY 98 to FY 99 | I5: FY 99 to FY 00 | J5: FY 00 to 01 | K5: FY 01 to 02 | L5: FY 02 to 03 | M5: FY 03 to 04 | N5: FY 04 to 05 | O5: FY 05 to 06 | P5: FY 06 to 07 | Q5: FY 07 to 08 | R5: FY 08 to 09 | S5: FY 09 to 10
A6: Regents of the University of Colorado: | B6: =('Non-Resident FTE'!C6-'Non-Resident FTE'!B6)/'Non-Resident FTE'!B6 -> 0.030681543 | C6: =('Non-Resident FTE'!D6-'Non-Resident FTE'!C6)/'Non-Resident FTE'!C6 -> -0.034592305 | D6: =('Non-Resident FTE'!E6-'Non-Resident FTE'!D6)/'Non-Resident FTE'!D6 -> -0.045703839 | E6: =('Non-Resident FTE'!F6-'Non-Resident FTE'!E6)/'Non-Resident FTE'!E6 -> 0.025287356 | F6: =('Non-Resident FTE'!G6-'Non-Resident FTE'!F6)/'Non-Resident FTE'!F6 -> -0.014324863 | G6: =('Non-Resident FTE'!H6-'Non-Resident FTE'!G6)/'Non-Resident FTE'!G6 -> 0.034626564 | H6: =('Non-Resident FTE'!I6-'Non-Resident FTE'!H6)/'Non-Resident FTE'!H6 -> 0.024428973 | I6: =('Non-Resident FTE'!J6-'Non-Resident FTE'!I6)/'Non-Resident FTE'!I6 -> 0.012412066 | ... S6: =('Non-Resident FTE'!T6-'Non-Resident FTE'!S6)/'Non-Resident FTE'!S6 -> 0.054243874
A7: University of Colorado-Boulder | B7: =('Non-Resident FTE'!C7-'Non-Resident FTE'!B7)/'Non-Resident FTE'!B7 -> 0.023460808 | C7: =('Non-Resident FTE'!D7-'Non-Resident FTE'!C7)/'Non-Resident FTE'!C7 -> -0.049291109 | D7: =('Non-Resident FTE'!E7-'Non-Resident FTE'!D7)/'Non-Resident FTE'!D7 -> -0.054076655 | E7: =('Non-Resident FTE'!F7-'Non-Resident FTE'!E7)/'Non-Resident FTE'!E7 -> 0.015912774 | F7: =('Non-Resident FTE'!G7-'Non-Resident FTE'!F7)/'Non-Resident FTE'!F7 -> -0.021174764 | G7: =('Non-Resident FTE'!H7-'Non-Resident FTE'!G7)/'Non-Resident FTE'!G7 -> 0.030819381 | H7: =('Non-Resident FTE'!I7-'Non-Resident FTE'!H7)/'Non-Resident FTE'!H7 -> 0.035360069 | I7: =('Non-Resident FTE'!J7-'Non-Resident FTE'!I7)/'Non-Resident FTE'!I7 -> 0.0016659725 | ... S7: =('Non-Resident FTE'!T7-'Non-Resident FTE'!S7)/'Non-Resident FTE'!S7 -> 0.010153754
A8: University of Colorado-Colorado Springs | B8: =('Non-Resident FTE'!C8-'Non-Resident FTE'!B8)/'Non-Resident FTE'!B8 -> 0.12682927 | C8: =('Non-Resident FTE'!D8-'Non-Resident FTE'!C8)/'Non-Resident FTE'!C8 -> 0.069264069 | D8: =('Non-Resident FTE'!E8-'Non-Resident FTE'!D8)/'Non-Resident FTE'!D8 -> -0.028340081 | E8: =('Non-Resident FTE'!F8-'Non-Resident FTE'!E8)/'Non-Resident FTE'!E8 -> -0.033333333 | F8: =('Non-Resident FTE'!G8-'Non-Resident FTE'!F8)/'Non-Resident FTE'!F8 -> 0.051724138 | G8: =('Non-Resident FTE'!H8-'Non-Resident FTE'!G8)/'Non-Resident FTE'!G8 -> 0.29098361 | H8: =('Non-Resident FTE'!I8-'Non-Resident FTE'!H8)/'Non-Resident FTE'!H8 -> 0.095238095 | I8: =('Non-Resident FTE'!J8-'Non-Resident FTE'!I8)/'Non-Resident FTE'!I8 -> 0.062028986 | ... S8: =('Non-Resident FTE'!T8-'Non-Resident FTE'!S8)/'Non-Resident FTE'!S8 -> 0.046802182
A9: University of Colorado-Denver | B9: =('Non-Resident FTE'!C9-'Non-Resident FTE'!B9)/'Non-Resident FTE'!B9 -> 0.087470449 | C9: =('Non-Resident FTE'!D9-'Non-Resident FTE'!C9)/'Non-Resident FTE'!C9 -> 0.12173913 | D9: =('Non-Resident FTE'!E9-'Non-Resident FTE'!D9)/'Non-Resident FTE'!D9 -> 0.058139535 | E9: =('Non-Resident FTE'!F9-'Non-Resident FTE'!E9)/'Non-Resident FTE'!E9 -> 0.11904762 | F9: =('Non-Resident FTE'!G9-'Non-Resident FTE'!F9)/'Non-Resident FTE'!F9 -> 0.073649755 | G9: =('Non-Resident FTE'!H9-'Non-Resident FTE'!G9)/'Non-Resident FTE'!G9 -> 0.032012195 | H9: =('Non-Resident FTE'!I9-'Non-Resident FTE'!H9)/'Non-Resident FTE'!H9 -> -0.11078287 | I9: =('Non-Resident FTE'!J9-'Non-Resident FTE'!I9)/'Non-Resident FTE'!I9 -> 0.082890365 | ... S9: =('Non-Resident FTE'!T9-'Non-Resident FTE'!S9)/'Non-Resident FTE'!S9 -> 0.22854128
A10: University of Colorado-Health Sciences | B10: =('Non-Resident FTE'!C10-'Non-Resident FTE'!B10)/'Non-Resident FTE'!B10 -> 0.069672131 | C10: =('Non-Resident FTE'!D10-'Non-Resident FTE'!C10)/'Non-Resident FTE'!C10 -> 0.022988506 | D10: =('Non-Resident FTE'!E10-'Non-Resident FTE'!D10)/'Non-Resident FTE'!D10 -> -0.037453184 | E10: =('Non-Resident FTE'!F10-'Non-Resident FTE'!E10)/'Non-Resident FTE'!E10 -> 0.12840467 | F10: =('Non-Resident FTE'!G10-'Non-Resident FTE'!F10)/'Non-Resident FTE'!F10 -> -0.089655172 | G10: =('Non-Resident FTE'!H10-'Non-Resident FTE'!G10)/'Non-Resident FTE'!G10 -> -0.098484848 | H10: =('Non-Resident FTE'!I10-'Non-Resident FTE'!H10)/'Non-Resident FTE'!H10 -> -0.0042016807 | I10: =('Non-Resident FTE'!J10-'Non-Resident FTE'!I10)/'Non-Resident FTE'!I10 -> 0.087763713 | ... S10: =('Non-Resident FTE'!T10-'Non-Resident FTE'!S10)/'Non-Resident FTE'!S10 -> 0.51024197
A11: Board of Governors of Colorado State University System: | B11: =('Non-Resident FTE'!C11-'Non-Resident FTE'!B11)/'Non-Resident FTE'!B11 -> 0.030061892 | C11: =('Non-Resident FTE'!D11-'Non-Resident FTE'!C11)/'Non-Resident FTE'!C11 -> 0.039065331 | D11: =('Non-Resident FTE'!E11-'Non-Resident FTE'!D11)/'Non-Resident FTE'!D11 -> 0.0040386981 | E11: =('Non-Resident FTE'!F11-'Non-Resident FTE'!E11)/'Non-Resident FTE'!E11 -> 0.019892856 | F11: =('Non-Resident FTE'!G11-'Non-Resident FTE'!F11)/'Non-Resident FTE'!F11 -> -0.033111633 | G11: =('Non-Resident FTE'!H11-'Non-Resident FTE'!G11)/'Non-Resident FTE'!G11 -> -0.0061556717 | H11: =('Non-Resident FTE'!I11-'Non-Resident FTE'!H11)/'Non-Resident FTE'!H11 -> -0.01251819 | I11: =('Non-Resident FTE'!J11-'Non-Resident FTE'!I11)/'Non-Resident FTE'!I11 -> -0.0015170694 | ... S11: =('Non-Resident FTE'!T11-'Non-Resident FTE'!S11)/'Non-Resident FTE'!S11 -> 0.02087755
A12: Colorado State University-Education & General | B12: =('Non-Resident FTE'!C12-'Non-Resident FTE'!B12)/'Non-Resident FTE'!B12 -> 0.027215475 | C12: =('Non-Resident FTE'!D12-'Non-Resident FTE'!C12)/'Non-Resident FTE'!C12 -> 0.016422159 | D12: =('Non-Resident FTE'!E12-'Non-Resident FTE'!D12)/'Non-Resident FTE'!D12 -> -0.005601034 | E12: =('Non-Resident FTE'!F12-'Non-Resident FTE'!E12)/'Non-Resident FTE'!E12 -> 0.015814558 | F12: =('Non-Resident FTE'!G12-'Non-Resident FTE'!F12)/'Non-Resident FTE'!F12 -> -0.038174451 | G12: =('Non-Resident FTE'!H12-'Non-Resident FTE'!G12)/'Non-Resident FTE'!G12 -> -0.0095343681 | H12: =('Non-Resident FTE'!I12-'Non-Resident FTE'!H12)/'Non-Resident FTE'!H12 -> -0.0060443251 | I12: =('Non-Resident FTE'!J12-'Non-Resident FTE'!I12)/'Non-Resident FTE'!I12 -> -0.0020045045 | ... S12: =('Non-Resident FTE'!T12-'Non-Resident FTE'!S12)/'Non-Resident FTE'!S12 -> 0.0042464123
A13: Colorado State University-Professional Veterinary Medicine | B13: =('Non-Resident FTE'!C13-'Non-Resident FTE'!B13)/'Non-Resident FTE'!B13 -> -0.013495277 | C13: =('Non-Resident FTE'!D13-'Non-Resident FTE'!C13)/'Non-Resident FTE'!C13 -> 0.087004104 | D13: =('Non-Resident FTE'!E13-'Non-Resident FTE'!D13)/'Non-Resident FTE'!D13 -> -0.015101938 | E13: =('Non-Resident FTE'!F13-'Non-Resident FTE'!E13)/'Non-Resident FTE'!E13 -> 0.0046000511 | F13: =('Non-Resident FTE'!G13-'Non-Resident FTE'!F13)/'Non-Resident FTE'!F13 -> 0.016026456 | G13: =('Non-Resident FTE'!H13-'Non-Resident FTE'!G13)/'Non-Resident FTE'!G13 -> -0.058087131 | H13: =('Non-Resident FTE'!I13-'Non-Resident FTE'!H13)/'Non-Resident FTE'!H13 -> -0.050770867 | I13: =('Non-Resident FTE'!J13-'Non-Resident FTE'!I13)/'Non-Resident FTE'!I13 -> -0.068328199 | ... S13: =('Non-Resident FTE'!T13-'Non-Resident FTE'!S13)/'Non-Resident FTE'!S13 -> 0.083825301
A14: Colorado State University - Pueblo | B14: =('Non-Resident FTE'!C14-'Non-Resident FTE'!B14)/'Non-Resident FTE'!B14 -> 0.13553114 | C14: =('Non-Resident FTE'!D14-'Non-Resident FTE'!C14)/'Non-Resident FTE'!C14 -> 0.31612903 | D14: =('Non-Resident FTE'!E14-'Non-Resident FTE'!D14)/'Non-Resident FTE'!D14 -> 0.13235294 | E14: =('Non-Resident FTE'!F14-'Non-Resident FTE'!E14)/'Non-Resident FTE'!E14 -> 0.073593074 | F14: =('Non-Resident FTE'!G14-'Non-Resident FTE'!F14)/'Non-Resident FTE'!F14 -> -0.024193548 | G14: =('Non-Resident FTE'!H14-'Non-Resident FTE'!G14)/'Non-Resident FTE'!G14 -> 0.068181818 | H14: =('Non-Resident FTE'!I14-'Non-Resident FTE'!H14)/'Non-Resident FTE'!H14 -> -0.040618956 | I14: =('Non-Resident FTE'!J14-'Non-Resident FTE'!I14)/'Non-Resident FTE'!I14 -> 0.050947581 | ... S14: =('Non-Resident FTE'!T14-'Non-Resident FTE'!S14)/'Non-Resident FTE'!S14 -> 0.14289948
A15: Trustees of Fort Lewis College:
A16: Fort Lewis College | B16: =('Non-Resident FTE'!C16-'Non-Resident FTE'!B16)/'Non-Resident FTE'!B16 -> 0.1544196 | C16: =('Non-Resident FTE'!D16-'Non-Resident FTE'!C16)/'Non-Resident FTE'!C16 -> 0.10055351 | D16: =('Non-Resident FTE'!E16-'Non-Resident FTE'!D16)/'Non-Resident FTE'!D16 -> -0.0092204526 | E16: =('Non-Resident FTE'!F16-'Non-Resident FTE'!E16)/'Non-Resident FTE'!E16 -> 0.027918782 | F16: =('Non-Resident FTE'!G16-'Non-Resident FTE'!F16)/'Non-Resident FTE'!F16 -> 0.032921811 | G16: =('Non-Resident FTE'!H16-'Non-Resident FTE'!G16)/'Non-Resident FTE'!G16 -> 0.036653386 | H16: =('Non-Resident FTE'!I16-'Non-Resident FTE'!H16)/'Non-Resident FTE'!H16 -> -0.004611837 | I16: =('Non-Resident FTE'!J16-'Non-Resident FTE'!I16)/'Non-Resident FTE'!I16 -> 0.067181467 | ... S16: =('Non-Resident FTE'!T16-'Non-Resident FTE'!S16)/'Non-Resident FTE'!S16 -> -0.01152645
A17: Trustees of Colorado School of Mines:
A18: Colorado School of Mines | B18: =('Non-Resident FTE'!C18-'Non-Resident FTE'!B18)/'Non-Resident FTE'!B18 -> 0.14216867 | C18: =('Non-Resident FTE'!D18-'Non-Resident FTE'!C18)/'Non-Resident FTE'!C18 -> 0.079113924 | D18: =('Non-Resident FTE'!E18-'Non-Resident FTE'!D18)/'Non-Resident FTE'!D18 -> 0.027370479 | E18: =('Non-Resident FTE'!F18-'Non-Resident FTE'!E18)/'Non-Resident FTE'!E18 -> 0.015223597 | F18: =('Non-Resident FTE'!G18-'Non-Resident FTE'!F18)/'Non-Resident FTE'!F18 -> 0.014058107 | G18: =('Non-Resident FTE'!H18-'Non-Resident FTE'!G18)/'Non-Resident FTE'!G18 -> -0.036044362 | H18: =('Non-Resident FTE'!I18-'Non-Resident FTE'!H18)/'Non-Resident FTE'!H18 -> -0.070949185 | I18: =('Non-Resident FTE'!J18-'Non-Resident FTE'!I18)/'Non-Resident FTE'!I18 -> -0.037358101 | ... S18: =('Non-Resident FTE'!T18-'Non-Resident FTE'!S18)/'Non-Resident FTE'!S18 -> 0.10579447
A19: Board of Trustees University of Northern Colorado:
A20: University of Northern Colorado | B20: =('Non-Resident FTE'!C20-'Non-Resident FTE'!B20)/'Non-Resident FTE'!B20 -> 0 | C20: =('Non-Resident FTE'!D20-'Non-Resident FTE'!C20)/'Non-Resident FTE'!C20 -> 0.034123223 | D20: =('Non-Resident FTE'!E20-'Non-Resident FTE'!D20)/'Non-Resident FTE'!D20 -> -0.011915674 | E20: =('Non-Resident FTE'!F20-'Non-Resident FTE'!E20)/'Non-Resident FTE'!E20 -> 0.067717996 | F20: =('Non-Resident FTE'!G20-'Non-Resident FTE'!F20)/'Non-Resident FTE'!F20 -> 0.058210252 | G20: =('Non-Resident FTE'!H20-'Non-Resident FTE'!G20)/'Non-Resident FTE'!G20 -> 0.070607553 | H20: =('Non-Resident FTE'!I20-'Non-Resident FTE'!H20)/'Non-Resident FTE'!H20 -> 0.029907975 | I20: =('Non-Resident FTE'!J20-'Non-Resident FTE'!I20)/'Non-Resident FTE'!I20 -> -0.02820551 | ... S20: =('Non-Resident FTE'!T20-'Non-Resident FTE'!S20)/'Non-Resident FTE'!S20 -> 0.0065321173
A21: Trustees of Adams State College:
A22: Adams State College | B22: =('Non-Resident FTE'!C22-'Non-Resident FTE'!B22)/'Non-Resident FTE'!B22 -> -0.068888889 | C22: =('Non-Resident FTE'!D22-'Non-Resident FTE'!C22)/'Non-Resident FTE'!C22 -> -0.0071599045 | D22: =('Non-Resident FTE'!E22-'Non-Resident FTE'!D22)/'Non-Resident FTE'!D22 -> 0.045673077 | E22: =('Non-Resident FTE'!F22-'Non-Resident FTE'!E22)/'Non-Resident FTE'!E22 -> 0.013793103 | F22: =('Non-Resident FTE'!G22-'Non-Resident FTE'!F22)/'Non-Resident FTE'!F22 -> -0.034013605 | G22: =('Non-Resident FTE'!H22-'Non-Resident FTE'!G22)/'Non-Resident FTE'!G22 -> -0.11032864 | H22: =('Non-Resident FTE'!I22-'Non-Resident FTE'!H22)/'Non-Resident FTE'!H22 -> -0.029023747 | I22: =('Non-Resident FTE'!J22-'Non-Resident FTE'!I22)/'Non-Resident FTE'!I22 -> 0 | ... S22: =('Non-Resident FTE'!T22-'Non-Resident FTE'!S22)/'Non-Resident FTE'!S22 -> 0.13205045
A23: Trustees of Mesa State College:
A24: Mesa State College | B24: =('Non-Resident FTE'!C24-'Non-Resident FTE'!B24)/'Non-Resident FTE'!B24 -> 0.24701195 | C24: =('Non-Resident FTE'!D24-'Non-Resident FTE'!C24)/'Non-Resident FTE'!C24 -> 0.12460064 | D24: =('Non-Resident FTE'!E24-'Non-Resident FTE'!D24)/'Non-Resident FTE'!D24 -> 0.13352273 | E24: =('Non-Resident FTE'!F24-'Non-Resident FTE'!E24)/'Non-Resident FTE'!E24 -> 0.032581454 | F24: =('Non-Resident FTE'!G24-'Non-Resident FTE'!F24)/'Non-Resident FTE'!F24 -> -0.014563107 | G24: =('Non-Resident FTE'!H24-'Non-Resident FTE'!G24)/'Non-Resident FTE'!G24 -> 0.039408867 | H24: =('Non-Resident FTE'!I24-'Non-Resident FTE'!H24)/'Non-Resident FTE'!H24 -> -0.028436019 | I24: =('Non-Resident FTE'!J24-'Non-Resident FTE'!I24)/'Non-Resident FTE'!I24 -> 0.06902439 | ... S24: =('Non-Resident FTE'!T24-'Non-Resident FTE'!S24)/'Non-Resident FTE'!S24 -> 0.2035267
A25: Trustees of Metropolitan State College:
A26: Metropolitan State College of Denver | B26: =('Non-Resident FTE'!C26-'Non-Resident FTE'!B26)/'Non-Resident FTE'!B26 -> -0.017492711 | C26: =('Non-Resident FTE'!D26-'Non-Resident FTE'!C26)/'Non-Resident FTE'!C26 -> -0.077151335 | D26: =('Non-Resident FTE'!E26-'Non-Resident FTE'!D26)/'Non-Resident FTE'!D26 -> 0.038585209 | E26: =('Non-Resident FTE'!F26-'Non-Resident FTE'!E26)/'Non-Resident FTE'!E26 -> -0.0092879257 | F26: =('Non-Resident FTE'!G26-'Non-Resident FTE'!F26)/'Non-Resident FTE'!F26 -> 0.121875 | G26: =('Non-Resident FTE'!H26-'Non-Resident FTE'!G26)/'Non-Resident FTE'!G26 -> 0.086350975 | H26: =('Non-Resident FTE'!I26-'Non-Resident FTE'!H26)/'Non-Resident FTE'!H26 -> 0.046153846 | I26: =('Non-Resident FTE'!J26-'Non-Resident FTE'!I26)/'Non-Resident FTE'!I26 -> 0.045343137 | ... S26: =('Non-Resident FTE'!T26-'Non-Resident FTE'!S26)/'Non-Resident FTE'!S26 -> -0.0029398521
A27: Trustees of Western State College:
A28: Western State College | B28: =('Non-Resident FTE'!C28-'Non-Resident FTE'!B28)/'Non-Resident FTE'!B28 -> 0.09517601 | C28: =('Non-Resident FTE'!D28-'Non-Resident FTE'!C28)/'Non-Resident FTE'!C28 -> -0.09047619 | D28: =('Non-Resident FTE'!E28-'Non-Resident FTE'!D28)/'Non-Resident FTE'!D28 -> -0.02617801 | E28: =('Non-Resident FTE'!F28-'Non-Resident FTE'!E28)/'Non-Resident FTE'!E28 -> 0.029569892 | F28: =('Non-Resident FTE'!G28-'Non-Resident FTE'!F28)/'Non-Resident FTE'!F28 -> -0.014360313 | G28: =('Non-Resident FTE'!H28-'Non-Resident FTE'!G28)/'Non-Resident FTE'!G28 -> -0.01192053 | H28: =('Non-Resident FTE'!I28-'Non-Resident FTE'!H28)/'Non-Resident FTE'!H28 -> -0.065683646 | I28: =('Non-Resident FTE'!J28-'Non-Resident FTE'!I28)/'Non-Resident FTE'!I28 -> -0.024246772 | ... S28: =('Non-Resident FTE'!T28-'Non-Resident FTE'!S28)/'Non-Resident FTE'!S28 -> 0.012402057
A29: Community Colleges of Colorado: | B29: =('Non-Resident FTE'!C29-'Non-Resident FTE'!B29)/'Non-Resident FTE'!B29 -> 0.24352019 | C29: =('Non-Resident FTE'!D29-'Non-Resident FTE'!C29)/'Non-Resident FTE'!C29 -> 0.0058167717 | D29: =('Non-Resident FTE'!E29-'Non-Resident FTE'!D29)/'Non-Resident FTE'!D29 -> 0.037590361 | E29: =('Non-Resident FTE'!F29-'Non-Resident FTE'!E29)/'Non-Resident FTE'!E29 -> -0.091035764 | F29: =('Non-Resident FTE'!G29-'Non-Resident FTE'!F29)/'Non-Resident FTE'!F29 -> -0.033214103 | G29: =('Non-Resident FTE'!H29-'Non-Resident FTE'!G29)/'Non-Resident FTE'!G29 -> 0.0073995772 | H29: =('Non-Resident FTE'!I29-'Non-Resident FTE'!H29)/'Non-Resident FTE'!H29 -> 0.089716684 | I29: =('Non-Resident FTE'!J29-'Non-Resident FTE'!I29)/'Non-Resident FTE'!I29 -> -0.038825229 | ... S29: =('Non-Resident FTE'!T29-'Non-Resident FTE'!S29)/'Non-Resident FTE'!S29 -> 0.2900559
A30: Arapahoe Community College | B30: =('Non-Resident FTE'!C30-'Non-Resident FTE'!B30)/'Non-Resident FTE'!B30 -> 0.19354839 | C30: =('Non-Resident FTE'!D30-'Non-Resident FTE'!C30)/'Non-Resident FTE'!C30 -> -0.060810811 | D30: =('Non-Resident FTE'!E30-'Non-Resident FTE'!D30)/'Non-Resident FTE'!D30 -> 0.050359712 | E30: =('Non-Resident FTE'!F30-'Non-Resident FTE'!E30)/'Non-Resident FTE'!E30 -> -0.17808219 | F30: =('Non-Resident FTE'!G30-'Non-Resident FTE'!F30)/'Non-Resident FTE'!F30 -> 0.12083333 | G30: =('Non-Resident FTE'!H30-'Non-Resident FTE'!G30)/'Non-Resident FTE'!G30 -> 0.11895911 | H30: =('Non-Resident FTE'!I30-'Non-Resident FTE'!H30)/'Non-Resident FTE'!H30 -> 0.24916944 | I30: =('Non-Resident FTE'!J30-'Non-Resident FTE'!I30)/'Non-Resident FTE'!I30 -> -0.13590426 | ... S30: =('Non-Resident FTE'!T30-'Non-Resident FTE'!S30)/'Non-Resident FTE'!S30 -> 0.13968416
A31: Colorado Northwestern Community College | B31: =('Non-Resident FTE'!C31-'Non-Resident FTE'!B31)/'Non-Resident FTE'!B31 -> 0.49367089 | C31: =('Non-Resident FTE'!D31-'Non-Resident FTE'!C31)/'Non-Resident FTE'!C31 -> 0.06779661 | D31: =('Non-Resident FTE'!E31-'Non-Resident FTE'!D31)/'Non-Resident FTE'!D31 -> -0.063492063 | E31: =('Non-Resident FTE'!F31-'Non-Resident FTE'!E31)/'Non-Resident FTE'!E31 -> -0.016949153 | F31: =('Non-Resident FTE'!G31-'Non-Resident FTE'!F31)/'Non-Resident FTE'!F31 -> -0.12931034 | G31: =('Non-Resident FTE'!H31-'Non-Resident FTE'!G31)/'Non-Resident FTE'!G31 -> -0.02970297 | H31: =('Non-Resident FTE'!I31-'Non-Resident FTE'!H31)/'Non-Resident FTE'!H31 -> -0.13265306 | I31: =('Non-Resident FTE'!J31-'Non-Resident FTE'!I31)/'Non-Resident FTE'!I31 -> -0.069647059 | ... S31: =('Non-Resident FTE'!T31-'Non-Resident FTE'!S31)/'Non-Resident FTE'!S31 -> 0.095333129
