Workbook

Sheet Legend
A2: Legend
D3: Local
D5: State
D7: Federal
D9: Other
D11: Indeterminate
D13: Not Used
D15: Albany
D17: Buffalo
D19: New York City
D21: Focus District
A24: Source | B24: New York Department of Education
A26: All files are "read only" and based on data collections from the New York Department of Education.
A27: The conclusions reached in this document are those of the author(s) and do not necessarily represent those
A28: of Ball State University.

Sheet 1,2,4
A1: Figure 1 | M1: Figure 2
A2: New York (2006-07) | B2: Statewide | D2: Statewide Weighted for Charter Enrollment | F2: Albany | H2: Buffalo | J2: New York City | N2: District | O2: Charter | P2: Difference
A3: Per-Pupil Revenue | M3: State | N3: 19518.393 | O3: 12908.476 | P3: 6609.9172
A4: District | B4: =B14 -> 19518.393 | D4: 19782 | F4: =F14 -> 22761.061 | H4: =H14 -> 18665.733 | J4: =J14 -> 20021.23 | M4: Statewide Weighted | N4: 19782 | O4: 12908 | P4: 6874
A5: Charter | B5: =C14 -> 12908.476 | D5: 12908 | F5: =G14 -> 13261.85 | H5: =I14 -> 11647.269 | J5: =K14 -> 13468.238 | M5: Albany | N5: 22761.061 | O5: 13261.85 | P5: 9499.211
A6: Difference | B6: =B4-B5 -> 6609.9172 | D6: 6874 | F6: =F4-F5 -> 9499.211 | H6: =H4-H5 -> 7018.4643 | J6: =J4-J5 -> 6552.9928 | M6: Buffalo | N6: 18665.733 | O6: 11647.269 | P6: 7018.4643
B7: =B6/B4 -> 0.33865069 | D7: 0.347 | F7: =F6/F4 -> 0.41734483 | H7: =H6/H4 -> 0.37600796 | J7: =J6/J4 -> 0.3273022 | M7: New York City | N7: 20021.23 | O7: 13468.238 | P7: 6552.9928
A8: Per-Pupil Revenue by Source | B8: District | C8: Charter | D8: District | E8: Charter | F8: District | G8: Charter | H8: District | I8: Charter | J8: District | K8: Charter
A9: Federal | B9: ='Dist Work File'!G686 -> 760.54794 | C9: ='Charter Work File'!R98 -> 610.46117 | D9: 1265 | E9: 610.46117 | F9: ='Dist Work File'!G696 -> 1255.6053 | G9: ='Charter Work File'!R198 -> 2015.1528 | H9: ='Dist Work File'!G706 -> 1429.4794 | I9: ='Charter Work File'!R184 -> 551.92395 | J9: ='Dist Work File'!G716 -> 1582.4359 | K9: ='Charter Work File'!R164 -> 343.11588
A10: State | B10: ='Dist Work File'!F686 -> 8856.1444 | C10: ='Charter Work File'!O98 -> 6606.8741 | D10: 10028 | E10: 6606.8741 | F10: ='Dist Work File'!F696 -> 7214.5559 | G10: ='Charter Work File'!O198 -> 4652.9184 | H10: ='Dist Work File'!F706 -> 14085.529 | I10: ='Charter Work File'!O184 -> 8619.6264 | J10: ='Dist Work File'!F716 -> 9741.9882 | K10: ='Charter Work File'!O164 -> 5849.8606
A11: Local | B11: ='Dist Work File'!E686 -> 9756.2939 | C11: ='Charter Work File'!G98 -> 4007.016 | D11: 8401 | E11: 4007.016 | F11: ='Dist Work File'!E696 -> 14241.289 | G11: ='Charter Work File'!G198 -> 5326.9992 | H11: ='Dist Work File'!E706 -> 3031.9092 | I11: ='Charter Work File'!G184 -> 1607.792 | J11: ='Dist Work File'!E716 -> 8659.1841 | K11: ='Charter Work File'!G164 -> 4963.2727
A12: Other | B12: ='Dist Work File'!H686 -> 145.36293 | C12: ='Charter Work File'!Y98 -> 990.72316 | D12: 88 | E12: 990.72316 | F12: ='Dist Work File'!H696 -> 49.610717 | G12: ='Charter Work File'!Y198 -> 763.62924 | H12: ='Dist Work File'!H706 -> 118.81621 | I12: ='Charter Work File'!Y184 -> 294.70288 | J12: ='Dist Work File'!H716 -> 37.500861 | K12: ='Charter Work File'!Y164 -> 1416.0654
A13: Indeterminate | B13: ='Dist Work File'!I686 -> 0.043709732 | C13: ='Charter Work File'!AJ98 -> 693.40121 | D13: - | E13: 693.40121 | F13: ='Dist Work File'!I696 -> 0 | G13: ='Charter Work File'!AJ198 -> 503.15017 | H13: ='Dist Work File'!I706 -> 0 | I13: ='Charter Work File'!AJ184 -> 573.22373 | J13: ='Dist Work File'!I716 -> 0.12142192 | K13: ='Charter Work File'!AJ164 -> 895.92313
A14: Total | B14: =SUM(B9:B13) -> 19518.393 | C14: =SUM(C9:C13) -> 12908.476 | D14: 19782 | E14: 12908.476 | F14: =SUM(F9:F13) -> 22761.061 | G14: =SUM(G9:G13) -> 13261.85 | H14: =SUM(H9:H13) -> 18665.733 | I14: =SUM(I9:I13) -> 11647.269 | J14: =SUM(J9:J13) -> 20021.23 | K14: =SUM(K9:K13) -> 13468.238
A15: Enrollment
A16: District | B16: ='Dist Work File'!C685 -> 2714773 | D16: n/a | F16: ='Dist Work File'!C695 -> 8603 | H16: ='Dist Work File'!C705 -> 34589 | J16: ='Dist Work File'!C715 -> 977270
B17: =B16/(B16+B18) -> 0.99033838 | D17: n/a | F17: =F16/(F16+F18) -> 0.85110803 | H17: =H16/(H16+H18) -> 0.88465178 | J17: =J16/(J16+J18) -> 0.98490995
A18: Charter | B18: ='Charter Work File'!B97 -> 26485 | D18: n/a | F18: ='Charter Work File'!B197 -> 1505 | H18: ='Charter Work File'!B183 -> 4510 | J18: ='Charter Work File'!B163 -> 14973
B19: =B18/(B16+B18) -> 0.0096616225 | D19: n/a | F19: =F18/(F16+F18) -> 0.14889197 | H19: =H18/(H16+H18) -> 0.11534822 | J19: =J18/(J16+J18) -> 0.015090054
A20: Number of Charters | B20: 93 | D20: n/a | F20: 7 | H20: 13 | J20: 58
A21: Total Revenue
A22: District | B22: ='Dist Work File'!J685 -> 52988005852 | D22: n/a | F22: ='Dist Work File'!J695 -> 1.9581341e+08 | H22: ='Dist Work File'!J705 -> 6.4562905e+08 | J22: ='Dist Work File'!J715 -> 1.9566148e+10
B23: =B22/B26 -> 0.99358932 | D23: n/a | F23: =F22/F26 -> 0.9074994 | H23: =H22/H26 -> 0.92476035 | J23: =J22/J26 -> 0.98979857
A24: Charter | B24: ='Charter Work File'!AK97 -> 341880976 | D24: n/a | F24: ='Charter Work File'!AK197 -> 19959084 | H24: ='Charter Work File'!AK183 -> 52529183 | J24: ='Charter Work File'!AK163 -> 201659923
B25: =B24/B26 -> 0.0064106826 | D25: n/a | F25: =F24/F26 -> 0.092500596 | H25: =H24/H26 -> 0.075239653 | J25: =J24/J26 -> 0.010201431
A26: Total | B26: =B22+B24 -> 53329886828 | D26: n/a | F26: =F22+F24 -> 2.1577249e+08 | H26: =H22+H24 -> 6.9815823e+08 | J26: =J22+J24 -> 1.9767808e+10
A27: Percentage of Revenue by Source | B27: District | C27: Charter | D27: District | E27: Charter | F27: District | G27: Charter | H27: District | I27: Charter | J27: District | K27: Charter | M27: Figure 4
A28: Federal | B28: =B9/$B$14 -> 0.038965705 | C28: =C9/$C$14 -> 0.047291499 | D28: 0.063947023 | E28: 0.047291499 | F28: =F9/$F$14 -> 0.055164619 | G28: =G9/$G$14 -> 0.15195111 | H28: =H9/$H$14 -> 0.07658308 | I28: =I9/$I$14 -> 0.047386555 | J28: =J9/$J$14 -> 0.079037895 | K28: =K9/$K$14 -> 0.02547593 | N28: Federal | O28: State | P28: Local | Q28: Other | R28: Indeterminate
A29: State | B29: =B10/$B$14 -> 0.45373328 | C29: =C10/$C$14 -> 0.5118245 | D29: 0.50692549 | E29: 0.5118245 | F29: =F10/$F$14 -> 0.31696923 | G29: =G10/$G$14 -> 0.35084988 | H29: =H10/$H$14 -> 0.75461962 | I29: =I10/$I$14 -> 0.74005558 | J29: =J10/$J$14 -> 0.48658289 | K29: =K10/$K$14 -> 0.43434492 | M29: Statewide District | N29: 760.54794 | O29: 8856.1444 | P29: 9756.2939 | Q29: 145.36293 | R29: 0.043709732
A30: Local | B30: =B11/$B$14 -> 0.49985129 | C30: =C11/$C$14 -> 0.31041744 | D30: 0.424679 | E30: 0.31041744 | F30: =F11/$F$14 -> 0.62568652 | G30: =G11/$G$14 -> 0.40167844 | H30: =H11/$H$14 -> 0.16243183 | I30: =I11/$I$14 -> 0.13804026 | J30: =J11/$J$14 -> 0.4325001 | K30: =K11/$K$14 -> 0.36851686 | M30: Statewide Charter | N30: 610.46117 | O30: 6606.8741 | P30: 4007.016 | Q30: 990.72316 | R30: 693.40121
A31: Other | B31: =B12/$B$14 -> 0.0074474845 | C31: =C12/$C$14 -> 0.076749819 | D31: 0.0044484885 | E31: 0.076749819 | F31: =F12/$F$14 -> 0.0021796311 | G31: =G12/$G$14 -> 0.057580899 | H31: =H12/$H$14 -> 0.0063654726 | I31: =I12/$I$14 -> 0.025302316 | J31: =J12/$J$14 -> 0.0018730547 | K31: =K12/$K$14 -> 0.1051411 | M31: Statewide Weighted | N31: 1265 | O31: 10028 | P31: 8401 | Q31: 88 | R31: -
A32: Change in district school funding if subjected to charter funding structure | M32: Albany District | N32: 1255.6053 | O32: 7214.5559 | P32: 14241.289 | Q32: 49.610717 | R32: 0
B33: ($17.9 billion) | F33: ($81.7 million) | H33: ($242.7 million) | J33: ($6.6 billion) | M33: Albany Charter | N33: 2015.1528 | O33: 4652.9184 | P33: 5326.9992 | Q33: 763.62924 | R33: 503.15017
M34: Buffalo District | N34: 1429.4794 | O34: 14085.529 | P34: 3031.9092 | Q34: 118.81621 | R34: 0
B35: =B6*B16 -> 1.7944425e+10 | F35: =F6*F16 -> 81721713 | H35: =H6*H16 -> 2.4276166e+08 | J35: =J6*J16 -> 6.4040432e+09 | M35: Buffalo Charter | N35: 551.92395 | O35: 8619.6264 | P35: 1607.792 | Q35: 294.70288 | R35: 573.22373
M36: NYC District | N36: 1582.4359 | O36: 9741.9882 | P36: 8659.1841 | Q36: 37.500861 | R36: 0.12142192
M37: NYC Charter | N37: 343.11588 | O37: 5849.8606 | P37: 4963.2727 | Q37: 1416.0654 | R37: 895.92313

Sheet Figure 3
A1: State Charter School Policies
A2: Figure 3
A3: State Policies | B3: Yes | C3: No | D3: Partial
A4: Charter schools received their funding directly from the state | C4: X
A5: Charter schools are eligible for local funding | D5: X
A6: Cap on funding a charter school can receive | C6: X
A7: District public school receive differential funding (e.g. more funding for 9-12 vs. K-8 schools) | B7: X
A8: Charter schools receive differential funding | C8: X
A9: State allows districts to withhold funding from charter schools for providing adminstrative services | C9: X
A10: State "holds harmless" ditrict funding for charter enrollment | C10: X
A11: School is considered LEA if authorized by non-district organization | D11: X
A12: School is considered LEA if authorized by district | D12: X
A13: Cap on number of charter schools | B13: X1
A14: Cap on number of charters schools authorized per year | C14: X
A15: Cap on number of studens attending charter schools | C15: X
A16: Charter schools have an open enrollment policy | B16: X
A18: 1. The State University of New York may authorize 50 charter schools, and the state's Board of Regents may authorize 50. There is no limit on the number of existing district schools that may convert to charter schools. The legislature approved raising the cap to 200 charter schools effective July 1, 2007

Sheet Figure 5
C2: Statewide District | D2: Statewide Charter
A3: Percentage of stuents eligible for free or reduced price lunch | C3: 0.435 | D3: 0.733
A4: Percentage of schools eligible for Title 1 | C4: 0.68 | D4: 0.903
A5: Percent of students by school type
B6: Primary (K-5) | C6: 0.45 | D6: 0.688
B7: Middle (6-8) | C7: 0.195 | D7: 0.102
B8: High (9-12) | C8: 0.306 | D8: 0.029
B9: Other (K-12,K-8, etc.) | C9: 0.048 | D9: 0.18

Sheet Figure 6
A1: Figure 6: State Scorecard
B2: Findings | C2: New York | E2: Use the following options only
A3: Federal Funding | B3: Charters have access to federal funds according to state statutes (Yes = black, No = white) | C3: Y | E3: Y
B4: Percentage of federal revenue equals percentage of total enrollment for charter schools (<, >, or =) | C4: > | E4: P
A5: State Funding | B5: Charters have access to state funds according to state statutes (Yes = black, No = white) | C5: Y | E5: N
B6: Percentage of state revenue equals percentage of total enrollment for charter schools (<, >, or =) | C6: >
A7: Local Funding | B7: Charters have access to local funds according to state statutes (Yes = black, No = white) | C7: N
B8: Percentage of local revenue equals percentage of total enrollment for charter schools (<, >, or =) | C8: >
A9: Facilities Funding | B9: Charters have access to facilities funds according to state statutes (Yes = black, No = white) | C9: Y
B10: Percentage of facilities revenue equals percentage of total enrollment for charter schools (<, >, or =) | C10: NA
A11: Data Availability | B11: State provides detailed, public data on federal, state, local and other revenues for district schools (Yes = black, Partial = grey, No = white) | C11: P
B12: State provides detailed, public data on federal, state, local and other revenues for charter schools (Yes = black, Partial = grey, No = white) | C12: P
A13: Funding Formula | B13: Charters are treated as LEAs for funding purposes (Yes = black, Partial = grey, No = white) | C13: P
B14: State funds student (black) or the LEA (grey) | C14: S | E14: S | F14: L | H14: Use these options for the query to the left only (B18)
B15: State funding formula is fair and equitable (Yes = black, No = white | C15: N
A17: * For this finding, No could indicate that the statue is silent or that it denies access.

Sheet Charter Archive File
B1: New York Charter School Audits | M1: Is this the NY State Stimulus Facility Financing Grant?
B2: FY06-07 | D2: State | E2: Federal | F2: Local | G2: Other | H2: Other | I2: Discard | J2: Other | K2: Indeterminate | L2: Indeterminate | M2: State | N2: Other | O2: Other | P2: Other | Q2: Discard | R2: Local | S2: State | T2: State | U2: Indeterminate | V2: Indeterminate | W2: Other | X2: Indeterminate | Y2: Local | Z2: State | AA2: Federal | AB2: Other | AC2: Indeterminate | AD2: Indeterminate | AE2: State | AF2: Indeterminate | AG2: Indeterminate | AH2: State | AI2: Local | AJ2: Indetemrinate | AK2: Indeterminate | AL2: Federal | AM2: State
C3: District Location | D3: Other State Source | E3: Federal Sources | F3: Local Sources | G3: Private Sources | H3: Contributions | I3: In-Kind Contributions | J3: Other Income | K3: State & Local per pupil Operating | L3: Government Grants and Contracts | M3: Government Grant - Purchase of Land | N3: Benefit Event | O3: Interest Income | P3: Fundraising expenses | Q3: Public School District Revenue/State Aid/NYC Grant | R3: Local Portion Public School District Revenue | S3: State Portion Public School District Revenue | T3: Public School District Sped | U3: Net Assets Released from Restriction | V3: Grants and Other | W3: Revenue from School Operations | X3: Federal, State & Local Grants | Y3: Federal, State & Local Grants | Z3: Federal, State & Local Grants | AA3: Federal, State & Local Grants | AB3: Student Meal Fees | AC3: Various Grants & Honorarius | AD3: Proportionate Share Benefit Agreement | AE3: NYS Stimulus Facility financing grant | AF3: Public Support | AG3: State & City Grants | AH3: State & City Grants | AI3: State & City Grants | AJ3: Other revenue from public school districts | AK3: Federal & State Grants | AL3: Federal & State Grants | AM3: Federal & State Grants | AO3: Total
B4: Brooklyn Excelsior Charter School | C4: NYC | D4: 82544 | E4: 617358 | F4: 44352 | G4: 809841 | Q4: 6318578 | R4: 2964341.8 | S4: 3354236.2 | AO4: =SUM(D4:AN4) -> 14191251
B5: Brooklyn Charter School | C5: NYC | E5: 106924 | H5: 99818 | I5: 462000 | J5: 18475 | Q5: 2376282 | R5: 1114825.5 | S5: 1261456.5 | AO5: =SUM(D5:AN5) -> 5439781
B6: Bronx Preparatory Charter School | C6: NYC | H6: 1103043 | J6: 5988 | L6: 515807 | M6: 350000 | N6: 1250 | O6: 48533 | P6: -66197 | Q6: 5702690 | R6: 2675399.8 | S6: 3027290.2 | AO6: =SUM(D6:AN6) -> 13363804
B7: KIPP Sankofa Charter School | C7: Buffalo | H7: 5200 | J7: 13758 | O7: 68 | Q7: 2181466 | R7: 372538.11 | S7: 1808927.9 | T7: 105425 | U7: 174162 | AO7: =SUM(D7:AN7) -> 4661545
B8: Buffalo Academy of Science Charter School | C8: Buffalo | Q8: 3285894 | R8: 546361.16 | S8: 2739532.8 | V8: 310958 | AO8: =SUM(D8:AN8) -> 6882746
B9: Buffalo United Charter School | C9: Buffalo | D9: 166471 | E9: 620478 | F9: 19292 | Q9: 4445602 | R9: 779070.29 | S9: 3666531.7 | AO9: =SUM(D9:AN9) -> 9697445
B10: Achievement Academy | C10: Albany | D10: 1985 | E10: 169152 | J10: 40088 | Q10: 1318525 | R10: 763500.38 | S10: 555024.62 | T10: 131675 | U10: 157841 | V10: 87500 | AO10: =SUM(D10:AN10) -> 3225291
B11: Achievement First East New York Charter School | C11: NYC | H11: 4000 | J11: 17517 | L11: 398113 | Q11: 2532177 | R11: 1187963.2 | S11: 1344213.8 | AO11: =SUM(D11:AN11) -> 5483984
B12: Achievement First Crown Heights Charter | C12: NYC | H12: 26200 | J12: 40363 | L12: 510760 | Q12: 4291802 | R12: 2013486 | S12: 2278316 | W12: 116972 | AO12: =SUM(D12:AN12) -> 9277899
B13: Achievement First Endeavor Charter School | C13: NYC | H13: 295000 | J13: 650 | O13: 967 | Q13: 846982 | R13: 397359.05 | S13: 449622.95 | X13: 605579 | AB13: 5038 | AD13: brianna call february 12 | AE13: 718-622-4786 | AF13: 18533 ext | AO13: =SUM(D13:AN13) -> 2601198
B14: Westminster Community Charter School | C14: Buffalo | D14: 618210 | E14: 405429 | G14: 504815 | H14: 2133 | J14: 135661 | Q14: 4837511 | R14: 784501.25 | S14: 4053009.7 | T14: 34996 | AO14: =SUM(D14:AN14) -> 11376266
B15: Western New York Maritime Charter | C15: Buffalo | H15: 67084 | J15: 7572 | P15: 13525 | Q15: 2793512 | R15: 482017.54 | S15: 2311494.5 | T15: 450108 | U15: 273172 | AO15: =SUM(D15:AN15) -> 6398485
B16: Williamsburg Collegiate Charter | C16: NYC | H16: 185000 | J16: 17253 | L16: 482069 | Q16: 1431586 | R16: 671624.26 | S16: 759961.74 | AO16: =SUM(D16:AN16) -> 3547494
B17: The Renaissance Charter School | C17: NYC | E17: 279835 | J17: 3961 | Q17: 5291724 | R17: 2482596.4 | S17: 2809127.6 | T17: 415011 | AC17: 198575 | AD17: 9115 | AO17: =SUM(D17:AN17) -> 11489945
B18: Riverhead Charter School | C18: Statewide | L18: 410647 | O18: 898 | Q18: 3796932 | R18: 2148294.4 | S18: 1648637.6 | AO18: =SUM(D18:AN18) -> 8005409
B19: Roosevelt Children's Academy Charter | C19: Statewide | D19: 29466 | E19: 226444 | H19: 5340 | J19: 37672 | O19: 58124 | Q19: 7067201 | R19: 2839171.7 | S19: 4228029.3 | AB19: 176450 | AO19: =SUM(D19:AN19) -> 14667898
B20: Ross Global Academy Charter | C20: NYC | H20: 596250 | I20: 397664 | L20: 290713 | O20: 2930 | Q20: 1734688 | R20: 813823.65 | S20: 920864.35 | AO20: =SUM(D20:AN20) -> 4756933
B21: Sisulu-Walker Charter School of Harlem | C21: NYC | D21: 19246 | E21: 389928 | H21: 34012 | J21: 4891 | O21: 9139 | Q21: 2467850 | R21: 1157784.4 | S21: 1310065.6 | T21: 60209 | AB21: 78604 | AO21: =SUM(D21:AN21) -> 5531729
B22: South Bronx Charter Intl Cultures | C22: NYC | D22: 211167 | E22: 99273 | O22: 17574 | Q22: 2068463 | R22: 970413.18 | S22: 1098049.8 | T22: 7908 | X22: 29311 | AB22: 106761 | AC22: josh - a combination, can't tell off the top of my head. | AD22: 212-786-7900 | AE22: 250000 | AO22: =SUM(D22:AN22) -> 4858920
B23: South Bronx Classical Charter | C23: NYC | H23: 465030 | I23: 70895 | J23: 10993 | Q23: 1307094 | R23: 613219.21 | S23: 693874.79 | X23: 371495 | Y23: 136920 | Z23: 195056 | AA23: 39519 | AC23: Lena | AD23: (718) 860-4340 | AE23: lkonda@southbronxclassical.org Lena | AO23: =SUM(D23:AN23) -> 3904096
B24: South Buffalo Charter | C24: Buffalo | D24: 350000 | E24: 728747 | J24: 36357 | O24: 90737 | Q24: 5964594 | R24: 1056656.5 | S24: 4907937.5 | T24: 316280 | AO24: =SUM(D24:AN24) -> 13451309
B25: Our World Neighborhood Charter | C25: NYC | H25: 66875 | J25: 124624 | L25: 487524 | O25: 44994 | Q25: 7005755 | R25: 3286728.8 | S25: 3719026.2 | AB25: 96854 | AO25: =SUM(D25:AN25) -> 14832381
B26: Peninsula Preparatory Academy Charter | C26: NYC | D26: 19507 | E26: 116508 | H26: 327860 | J26: 23332 | Q26: 2546176 | R26: 1194530.8 | S26: 1351645.2 | T26: 51066 | AB26: 126056 | AO26: =SUM(D26:AN26) -> 5756681
B27: Pinnacle Charter School | C27: Buffalo | E27: 247174 | J27: 9750 | Q27: 3859552 | R27: 726012.01 | S27: 3133540 | T27: 497134 | U27: 6658 | AB27: 131124 | AO27: =SUM(D27:AN27) -> 8610944
B28: King Center Charter School | C28: Buffalo | H28: 1346 | J28: 2142 | O28: 7402 | Q28: 985491 | R28: 159817.5 | S28: 825673.5 | T28: 48646 | U28: 334151 | AO28: =SUM(D28:AN28) -> 2364669
B29: KIPP Academy Charter School | C29: NYC | H29: 2546857 | I29: 3570 | J29: 114929 | L29: 202325 | O29: 116224 | P29: -135463 | Q29: 2688070 | R29: 1261099.9 | S29: 1426970.1 | AO29: =SUM(D29:AN29) -> 8224582
B30: KIPP AMP Academy | C30: NYC | H30: 221632 | I30: 41683 | J30: 38696 | L30: 339570 | O30: 7242 | Q30: 1473829 | R30: 691442.43 | S30: 782386.57 | AO30: =SUM(D30:AN30) -> 3596481
B31: KIPP Infinity Charter | C31: NYC | H31: 220100 | I31: 40197 | J31: 44913 | L31: 302450 | O31: 15088 | Q31: 1687271 | R31: 791578.11 | S31: 895692.89 | AO31: =SUM(D31:AN31) -> 3997290
B32: Family Life Academy Charter | C32: NYC | D32: 267785 | E32: 235903 | I32: 45000 | J32: 22554 | O32: 17689 | Q32: 3156950 | R32: 1482201 | S32: 1674749 | AC32: (718) 410-8100 | AF32: 198029 | AG32: did not want to answer question | AO32: =SUM(D32:AN32) -> 7100860
B33: Ark Community Charter | C33: Statewide | D33: 50000 | E33: 326544 | H33: 7180 | J33: 7278 | O33: 11593 | Q33: 1895827 | R33: 672623.37 | S33: 1223203.6 | AO33: =SUM(D33:AN33) -> 4194249
B34: Carl C. Icahn Charter | C34: NYC | J34: 14116 | O34: 31205 | Q34: 2736898 | R34: 1284007.4 | S34: 1452890.6 | T34: 10815 | V34: 272913 | AO34: =SUM(D34:AN34) -> 5802845
B35: Charter School for Applied Technologies | C35: Statewide | D35: 29909 | E35: 1734293 | J35: 154644 | O35: 386682 | Q35: 13401259 | R35: 2697653.7 | S35: 10703605 | T35: 990404 | U35: 22237 | AO35: =SUM(D35:AN35) -> 30120687
B36: Charter School for Educational Excellence | C36: Statewide | D36: 152247 | E36: 156632 | H36: 5200 | O36: 819 | Q36: 2655696 | R36: 1091870.5 | S36: 1563825.5 | AB36: 86595 | AO36: =SUM(D36:AN36) -> 5712885
B37: New Covenant Charter School | C37: Albany | D37: 27283 | E37: 894921 | J37: 236577 | Q37: 6496868 | R37: 3448538.5 | S37: 3048329.5 | T37: 18394 | U37: 57233 | AO37: =SUM(D37:AN37) -> 14228144
B38: Child Development Center of the Hamptons | C38: Statewide | D38: 21382 | H38: 62667 | J38: 9871 | Q38: 1195807 | T38: 831695 | AO38: =SUM(D38:AN38) -> 2121422
B39: Community Charter School | C39: Buffalo | E39: 179143 | J39: 46040 | Q39: 2610708 | R39: 440496.14 | S39: 2170211.9 | T39: 141520 | AO39: =SUM(D39:AN39) -> 5588119
B40: Community Partnership Charter | C40: NYC | H40: 181687 | J40: 3792 | L40: 215179 | O40: 68381 | Q40: 2937694 | R40: 1378210.3 | S40: 1559483.7 | AO40: =SUM(D40:AN40) -> 6344427
...

Sheet Charter Work File
A1: New York Charter School Audits
A2: FY06-07 | B2: green = Preschool/PreK enrollment | D2: Local | E2: Local | F2: Local | G2: Local | H2: State | I2: State | J2: State | K2: State | L2: State | M2: State | N2: State | O2: State | P2: Federal | Q2: Federal | R2: Federal | S2: Other | T2: Other | U2: Other | V2: Other | W2: Other | X2: Other | Y2: Other | Z2: Indetemrinate | AA2: Indeterminate | AB2: Indeterminate | AC2: Indeterminate | AD2: Indeterminate | AE2: Indeterminate | AF2: Indeterminate | AG2: Indeterminate | AH2: Indeterminate | AI2: Indeterminate | AJ2: Indeterminate | AN2: Discard | AO2: Discard
B3: Enrollment | C3: District Location | D3: Local Sources | E3: Local Portion Public School District Revenue | F3: State & City Grants | G3: Federal, State & Local Grants | H3: Other State Source | I3: Government Grant - Purchase of Land | J3: State Portion Public School District Revenue | K3: Public School District Sped | L3: NYS Stimulus Facility financing grant | M3: State & City Grants | N3: Federal & State Grants | O3: Federal, State & Local Grants | P3: Federal Sources | Q3: Federal, State & Local Grants | R3: Federal & State Grants | S3: Private Sources | T3: Contributions | U3: Other Income | V3: Benefit Event | W3: Interest Income | X3: Revenue from School Operations | Y3: Student Meal Fees | Z3: Other revenue from public school districts | AA3: State & Local per pupil Operating | AB3: Government Grants and Contracts | AC3: Net Assets Released from Restriction | AD3: Grants and Other | AE3: Federal, State & Local Grants | AF3: Various Grants & Honorarius | AG3: Proportionate Share Benefit Agreement | AH3: Public Support | AI3: State & City Grants | AJ3: Federal & State Grants | AK3: Total | AN3: In-Kind Contributions | AO3: Fundraising expenses
A4: Riverhead Charter School | B4: 306 | C4: Statewide | E4: 2148294.4 | J4: 1648637.6 | W4: 898 | AB4: 410647 | AK4: =SUM(D4:AJ4) -> 4208477
A5: Roosevelt Children's Academy Charter | B5: 499 | C5: Statewide | E5: 2839171.7 | H5: 29466 | J5: 4228029.3 | P5: 226444 | T5: 5340 | U5: 37672 | W5: 58124 | Y5: 176450 | AK5: =SUM(D5:AJ5) -> 7600697 | AN5: 462000
A6: Ark Community Charter | B6: 179 | C6: Statewide | E6: 672623.37 | H6: 50000 | J6: 1223203.6 | P6: 326544 | T6: 7180 | U6: 7278 | W6: 11593 | AK6: =SUM(D6:AJ6) -> 2298422 | AO6: -66197
A7: Charter School for Applied Technologies | B7: 1402 | C7: Statewide | E7: 2697653.7 | H7: 29909 | J7: 10703605 | K7: 990404 | P7: 1734293 | U7: 154644 | W7: 386682 | AC7: 22237 | AK7: =SUM(D7:AJ7) -> 16719428
A8: Charter School for Educational Excellence | B8: 284 | C8: Statewide | E8: 1091870.5 | H8: 152247 | J8: 1563825.5 | P8: 156632 | T8: 5200 | W8: 819 | Y8: 86595 | AK8: =SUM(D8:AJ8) -> 3057189
A9: Child Development Center of the Hamptons | B9: 60 | C9: Statewide | H9: 21382 | K9: 831695 | T9: 62667 | U9: 9871 | AK9: =SUM(D9:AJ9) -> 925615
A10: Genesee Community Charter School | B10: 212 | C10: Statewide | E10: 572500.63 | J10: 1475043.4 | K10: 26756 | P10: 164547 | T10: 83500 | U10: 50479 | W10: 51505 | Y10: 50037 | AK10: =SUM(D10:AJ10) -> 2474368
A11: Global Concepts Charter School | B11: 381 | C11: Statewide | E11: 938733.73 | J11: 2695432.3 | K11: 93295 | P11: 520538 | T11: 6500 | U11: 55159 | AK11: =SUM(D11:AJ11) -> 4309658
A12: Eugenio Maria De Hostos Charter | B12: 290 | C12: Statewide | E12: 657375.75 | J12: 2069503.3 | K12: 80776 | R12: 896561 | U12: 4582 | W12: 29845 | Y12: 171176 | AK12: =SUM(D12:AJ12) -> 3909819
A13: Southside Academy Charter School | B13: 420 | C13: Statewide | D13: 13792 | E13: 815258.03 | H13: 41971 | J13: 2666287 | P13: 641876 | S13: 257097 | AK13: =SUM(D13:AJ13) -> 4436281
A14: Syracuse Academy of Science Charter | B14: 336 | C14: Statewide | E14: 694872.73 | H14: 3143 | J14: 2116764.3 | K14: 193844 | P14: 269634 | U14: 23392 | AK14: =SUM(D14:AJ14) -> 3301650
A15: True North Rochester Preparatory Charter | B15: 81 | C15: Statewide | E15: 168085.97 | J15: 574985.03 | T15: 288500 | U15: 4877 | AB15: 619158 | AK15: =SUM(D15:AJ15) -> 1655606 | AO15: 13525
A16: Niagara Charter School | B16: 245 | C16: Statewide | E16: 503021.18 | J16: 1775214.8 | K16: 144899 | T16: 947 | U16: 28005 | Z16: 23822 | AD16: 485722 | AK16: =SUM(D16:AJ16) -> 2961631
A17: Urban Choice Charter School | B17: 264 | C17: Statewide | E17: 576456.12 | J17: 1933342.9 | K17: 53436 | P17: 276513 | U17: 11665 | W17: 8873 | Y17: 119446 | AK17: =SUM(D17:AJ17) -> 2979732
A18: International Charter School of Schenectady | B18: 538 | C18: Statewide | E18: 2152750.7 | H18: 36804 | J18: 3886043.3 | K18: 175995 | P18: 295026 | U18: 301586 | AC18: 46008 | AK18: =SUM(D18:AJ18) -> 6894213
A19: Brooklyn Excelsior Charter School | B19: 653 | C19: NYC | D19: 44352 | E19: 2964341.8 | H19: 82544 | J19: 3354236.2 | P19: 617358 | S19: 809841 | AK19: =SUM(D19:AJ19) -> 7872673
A20: Brooklyn Charter School | B20: 227 | C20: NYC | E20: 1114825.5 | J20: 1261456.5 | P20: 106924 | T20: 99818 | U20: 18475 | AK20: =SUM(D20:AJ20) -> 2601499 | AN20: 397664
A21: Bronx Preparatory Charter School | B21: 525 | C21: NYC | E21: 2675399.8 | I21: 350000 | J21: 3027290.2 | T21: 1103043 | U21: 5988 | V21: 1250 | W21: 48533 | AB21: 515807 | AK21: =SUM(D21:AJ21) -> 7727311
A22: Achievement First East New York Charter School | B22: 250 | C22: NYC | E22: 1187963.2 | J22: 1344213.8 | T22: 4000 | U22: 17517 | AB22: 398113 | AK22: =SUM(D22:AJ22) -> 2951807
A23: Achievement First Crown Heights Charter | B23: 428 | C23: NYC | E23: 2013486 | J23: 2278316 | T23: 26200 | U23: 40363 | X23: 116972 | AB23: 510760 | AK23: =SUM(D23:AJ23) -> 4986097 | AN23: 70895
A24: Achievement First Endeavor Charter School | B24: 84 | C24: NYC | E24: 397359.05 | J24: 449622.95 | T24: 295000 | U24: 650 | W24: 967 | Y24: 5038 | AE24: 605579 | AK24: =SUM(D24:AJ24) -> 1754216
A25: Williamsburg Collegiate Charter | B25: 139 | C25: NYC | E25: 671624.26 | J25: 759961.74 | T25: 185000 | U25: 17253 | AB25: 482069 | AK25: =SUM(D25:AJ25) -> 2115908
A26: The Renaissance Charter School | B26: 524 | C26: NYC | E26: 2482596.4 | J26: 2809127.6 | K26: 415011 | P26: 279835 | U26: 3961 | AF26: 198575 | AG26: 9115 | AK26: =SUM(D26:AJ26) -> 6198221
A27: Ross Global Academy Charter | B27: 211 | C27: NYC | E27: 813823.65 | J27: 920864.35 | T27: 596250 | W27: 2930 | AB27: 290713 | AK27: =SUM(D27:AJ27) -> 2624581
A28: Sisulu-Walker Charter School of Harlem | B28: 245 | C28: NYC | E28: 1157784.4 | H28: 19246 | J28: 1310065.6 | K28: 60209 | P28: 389928 | T28: 34012 | U28: 4891 | W28: 9139 | Y28: 78604 | AK28: =SUM(D28:AJ28) -> 3063879
A29: South Bronx Charter Intl Cultures | B29: 206 | C29: NYC | E29: 970413.18 | H29: 211167 | J29: 1098049.8 | K29: 7908 | L29: 250000 | P29: 99273 | W29: 17574 | Y29: 106761 | AE29: 29311 | AK29: =SUM(D29:AJ29) -> 2790457 | AN29: 3570 | AO29: -135463
A30: South Bronx Classical Charter | B30: 128 | C30: NYC | E30: 613219.21 | G30: 136920 | J30: 693874.79 | O30: 195056 | Q30: 39519 | T30: 465030 | U30: 10993 | AK30: =SUM(D30:AJ30) -> 2154612 | AN30: 41683
A31: Our World Neighborhood Charter | B31: 677 | C31: NYC | E31: 3286728.8 | J31: 3719026.2 | T31: 66875 | U31: 124624 | W31: 44994 | Y31: 96854 | AB31: 487524 | AK31: =SUM(D31:AJ31) -> 7826626 | AN31: 40197
A32: Peninsula Preparatory Academy Charter | B32: 250 | C32: NYC | E32: 1194530.8 | H32: 19507 | J32: 1351645.2 | K32: 51066 | P32: 116508 | T32: 327860 | U32: 23332 | Y32: 126056 | AK32: =SUM(D32:AJ32) -> 3210505 | AN32: 45000
A33: KIPP Academy Charter School | B33: 248 | C33: NYC | E33: 1261099.9 | J33: 1426970.1 | T33: 2546857 | U33: 114929 | W33: 116224 | AB33: 202325 | AK33: =SUM(D33:AJ33) -> 5668405
A34: KIPP AMP Academy | B34: 136 | C34: NYC | E34: 691442.43 | J34: 782386.57 | T34: 221632 | U34: 38696 | W34: 7242 | AB34: 339570 | AK34: =SUM(D34:AJ34) -> 2080969
A35: KIPP Infinity Charter | B35: 154 | C35: NYC | E35: 791578.11 | J35: 895692.89 | T35: 220100 | U35: 44913 | W35: 15088 | AB35: 302450 | AK35: =SUM(D35:AJ35) -> 2269822
A36: Family Life Academy Charter | B36: 288 | C36: NYC | E36: 1482201 | H36: 267785 | J36: 1674749 | P36: 235903 | U36: 22554 | W36: 17689 | AH36: 198029 | AK36: =SUM(D36:AJ36) -> 3898910
A37: Carl C. Icahn Charter | B37: 278 | C37: NYC | E37: 1284007.4 | J37: 1452890.6 | K37: 10815 | U37: 14116 | W37: 31205 | AD37: 272913 | AK37: =SUM(D37:AJ37) -> 3065947
A38: Community Partnership Charter | B38: 288 | C38: NYC | E38: 1378210.3 | J38: 1559483.7 | T38: 181687 | U38: 3792 | W38: 68381 | AB38: 215179 | AK38: =SUM(D38:AJ38) -> 3406733
A39: Community Roots Charter School | B39: 100 | C39: NYC | E39: 478915.57 | F39: 139412 | J39: 541906.43 | M39: 47115 | P39: 217414 | T39: 417809 | W39: 9728 | AK39: =SUM(D39:AJ39) -> 1852300
A40: Bronx Charter School for Better Learning | B40: 229 | C40: NYC | E40: 1089674.1 | J40: 1232996.9 | T40: 120265 | U40: 125619 | AB40: 162446 | AK40: =SUM(D40:AJ40) -> 2731001
...

Sheet Sending District
A1: Table 6
A2: Formula for Distribution of FY07 Charter Sending District Revenue by Local and State Funds
B3: Sending District | C3: District BEDS | D3: # Pupils | E3: Sending District Funding Formula | F3: Total Sending District Local & State Revenue | G3: % State Revenue | H3: State Revenue | I3: % Local Revenue | J3: Local Revenue | K3: Sending District Total State & Local | L3: State % Total State & Local | M3: Local % Total State & Local | N3: % of pupils | O3: Charter Self Reported Basic Operating Revenues | P3: Local Portion Basic Operating Revenues | Q3: State Portion Basic Operating Revenues
A4: Achievement Academy
B5: Albany | C5: 010100 | D5: 146 | E5: 10176 | F5: 172866321 | G5: =H5/F5 -> 0.42094357 | H5: =F5-J5 -> 72766966 | I5: =J5/F5 -> 0.57905643 | J5: 100099355 | K5: =SUM(H5+J5) -> 172866321 | L5: =H5/K5 -> 0.42094357 | M5: =J5/K5 -> 0.57905643 | N5: =D5/$D$6 -> 1 | O5: 1318525 | P5: =O5*N5*M5 -> 763500.38 | Q5: =O5*N5*L5 -> 555024.62
A6: Total Achievement Academy | D6: =SUM(D5) -> 146 | P6: =SUM(P5) -> 763500.38 | Q6: =SUM(Q5) -> 555024.62
A7: Albany Community
B8: Albany | C8: 010100 | D8: 95 | E8: 10176 | F8: 172866321 | G8: =H8/F8 -> 0.42094357 | H8: =F8-J8 -> 72766966 | I8: =J8/F8 -> 0.57905643 | J8: 100099355 | K8: =SUM(H8+J8) -> 172866321 | L8: =H8/K8 -> 0.42094357 | M8: =J8/K8 -> 0.57905643 | N8: =D8/$D$14 -> 0.9223301 | O8: 1078927 | P8: =O8*N8*M8 -> 576234.6 | Q8: =O8*N8*L8 -> 418892.24
B9: Ravena-Coeymans-Selkirk | C9: 010402 | D9: 1 | E9: 10973 | F9: 39310578 | G9: =H9/F9 -> 0.47995763 | H9: =F9-J9 -> 18867412 | I9: =J9/F9 -> 0.52004237 | J9: 20443166 | K9: =SUM(H9+J9) -> 39310578 | L9: =H9/K9 -> 0.47995763 | M9: =J9/K9 -> 0.52004237 | N9: =D9/$D$14 -> 0.0097087379 | O9: 1078927 | P9: =O9*N9*M9 -> 5447.4539 | Q9: =O9*N9*L9 -> 5027.5655
B10: Watervliet | C10: 011200 | D10: 1 | E10: 8036 | F10: 18681136 | G10: =H10/F10 -> 0.69404532 | H10: =F10-J10 -> 12965555 | I10: =J10/F10 -> 0.30595468 | J10: 5715581 | K10: =SUM(H10+J10) -> 18681136 | L10: =H10/K10 -> 0.69404532 | M10: =J10/K10 -> 0.30595468 | N10: =D10/$D$14 -> 0.0097087379 | O10: 1078927 | P10: =O10*N10*M10 -> 3204.8812 | Q10: =O10*N10*L10 -> 7270.1382
B11: East Greenbush | C11: 490301 | D11: 1 | E11: 10374 | F11: 75113751 | G11: =H11/F11 -> 0.45169729 | H11: =F11-J11 -> 33928678 | I11: =J11/F11 -> 0.54830271 | J11: 41185073 | K11: =SUM(H11+J11) -> 75113751 | L11: =H11/K11 -> 0.45169729 | M11: =J11/K11 -> 0.54830271 | N11: =D11/$D$14 -> 0.0097087379 | O11: 1078927 | P11: =O11*N11*M11 -> 5743.4815 | Q11: =O11*N11*L11 -> 4731.5379
B12: Lansingburgh | C12: 490601 | D12: 1 | E12: 8243 | F12: 31403986 | G12: =H12/F12 -> 0.66721619 | H12: =F12-J12 -> 20953248 | I12: =J12/F12 -> 0.33278381 | J12: 10450738 | K12: =SUM(H12+J12) -> 31403986 | L12: =H12/K12 -> 0.66721619 | M12: =J12/K12 -> 0.33278381 | N12: =D12/$D$14 -> 0.0097087379 | O12: 1078927 | P12: =O12*N12*M12 -> 3485.9168 | Q12: =O12*N12*L12 -> 6989.1026
B13: Troy | C13: 491700 | D13: 4 | E13: 10954 | F13: 81553767 | G13: =H13/F13 -> 0.64283589 | H13: =F13-J13 -> 52425688 | I13: =J13/F13 -> 0.35716411 | J13: 29128079 | K13: =SUM(H13+J13) -> 81553767 | L13: =H13/K13 -> 0.64283589 | M13: =J13/K13 -> 0.35716411 | N13: =D13/$D$14 -> 0.038834951 | O13: 1078927 | P13: =O13*N13*M13 -> 14965.204 | Q13: =O13*N13*L13 -> 26934.874
A14: Total Albany Community | D14: =SUM(D8:D13) -> 103 | P14: =SUM(P8:P13) -> 609081.54 | Q14: =SUM(Q8:Q13) -> 469845.46
A15: Albany Prep
B16: Albany | C16: 010100 | D16: 109 | E16: 10176 | F16: 172866321 | G16: =H16/F16 -> 0.42094357 | H16: =F16-J16 -> 72766966 | I16: =J16/F16 -> 0.57905643 | J16: 100099355 | K16: =SUM(H16+J16) -> 172866321 | L16: =H16/K16 -> 0.42094357 | M16: =J16/K16 -> 0.57905643 | N16: =D16/$D$20 -> 0.96460177 | O16: 1073355 | P16: =O16*N16*M16 -> 599531.94 | Q16: =O16*N16*L16 -> 435828.19
B17: Watervliet | C17: 011200 | D17: 1 | E17: 8036 | F17: 18681136 | G17: =H17/F17 -> 0.69404532 | H17: =F17-J17 -> 12965555 | I17: =J17/F17 -> 0.30595468 | J17: 5715581 | K17: =SUM(H17+J17) -> 18681136 | L17: =H17/K17 -> 0.69404532 | M17: =J17/K17 -> 0.30595468 | N17: =D17/$D$20 -> 0.0088495575 | O17: 1073355 | P17: =O17*N17*M17 -> 2906.1769 | Q17: =O17*N17*L17 -> 6592.5399
B18: Troy | C18: 491700 | D18: 2 | E18: 10954 | F18: 81553767 | G18: =H18/F18 -> 0.64283589 | H18: =F18-J18 -> 52425688 | I18: =J18/F18 -> 0.35716411 | J18: 29128079 | K18: =SUM(H18+J18) -> 81553767 | L18: =H18/K18 -> 0.64283589 | M18: =J18/K18 -> 0.35716411 | N18: =D18/$D$20 -> 0.017699115 | O18: 1073355 | P18: =O18*N18*M18 -> 6785.2016 | Q18: =O18*N18*L18 -> 12212.232
B19: Scotia-Glenville | C19: 530202 | D19: 1 | E19: 9361 | F19: 41910477 | G19: =H19/F19 -> 0.51384605 | H19: =F19-J19 -> 21535533 | I19: =J19/F19 -> 0.48615395 | J19: 20374944 | K19: =SUM(H19+J19) -> 41910477 | L19: =H19/K19 -> 0.51384605 | M19: =J19/K19 -> 0.48615395 | N19: =D19/$D$20 -> 0.0088495575 | O19: 1073355 | P19: =O19*N19*M19 -> 4617.8387 | Q19: =O19*N19*L19 -> 4880.8781
A20: Total Albany Prep | D20: =SUM(D16:D19) -> 113 | P20: =SUM(P16:P19) -> 613841.16 | Q20: =SUM(Q16:Q19) -> 459513.84
A21: Brighter Choice Boys
B22: Albany | C22: 010100 | D22: 137 | E22: 10176 | F22: 172866321 | G22: =H22/F22 -> 0.42094357 | H22: =F22-J22 -> 72766966 | I22: =J22/F22 -> 0.57905643 | J22: 100099355 | K22: =SUM(H22+J22) -> 172866321 | L22: =H22/K22 -> 0.42094357 | M22: =J22/K22 -> 0.57905643 | N22: =D22/$D$27 -> 0.97163121 | O22: 1415113 | P22: =O22*N22*M22 -> 796184.04 | Q22: =O22*N22*L22 -> 578783.92
B23: Ravena-Coeymans-Selkirk | C23: 010402 | D23: 1 | E23: 10973 | F23: 39310578 | G23: =H23/F23 -> 0.47995763 | H23: =F23-J23 -> 18867412 | I23: =J23/F23 -> 0.52004237 | J23: 20443166 | K23: =SUM(H23+J23) -> 39310578 | L23: =H23/K23 -> 0.47995763 | M23: =J23/K23 -> 0.52004237 | N23: =D23/$D$27 -> 0.0070921986 | O23: 1415113 | P23: =O23*N23*M23 -> 5219.2817 | Q23: =O23*N23*L23 -> 4816.9808
B24: Lansingburgh | C24: 490601 | D24: 1 | E24: 8243 | F24: 31403986 | G24: =H24/F24 -> 0.66721619 | H24: =F24-J24 -> 20953248 | I24: =J24/F24 -> 0.33278381 | J24: 10450738 | K24: =SUM(H24+J24) -> 31403986 | L24: =H24/K24 -> 0.66721619 | M24: =J24/K24 -> 0.33278381 | N24: =D24/$D$27 -> 0.0070921986 | O24: 1415113 | P24: =O24*N24*M24 -> 3339.9056 | Q24: =O24*N24*L24 -> 6696.3568
B25: Troy | C25: 491700 | D25: 1 | E25: 10954 | F25: 81553767 | G25: =H25/F25 -> 0.64283589 | H25: =F25-J25 -> 52425688 | I25: =J25/F25 -> 0.35716411 | J25: 29128079 | K25: =SUM(H25+J25) -> 81553767 | L25: =H25/K25 -> 0.64283589 | M25: =J25/K25 -> 0.35716411 | N25: =D25/$D$27 -> 0.0070921986 | O25: 1415113 | P25: =O25*N25*M25 -> 3584.5928 | Q25: =O25*N25*L25 -> 6451.6696
B26: Schenectady | C26: 530600 | D26: 1 | E26: 9112 | F26: 129603734 | G26: =H26/F26 -> 0.64854502 | H26: =F26-J26 -> 84053856 | I26: =J26/F26 -> 0.35145498 | J26: 45549878 | K26: =SUM(H26+J26) -> 129603734 | L26: =H26/K26 -> 0.64854502 | M26: =J26/K26 -> 0.35145498 | N26: =D26/$D$27 -> 0.0070921986 | O26: 1415113 | P26: =O26*N26*M26 -> 3527.2944 | Q26: =O26*N26*L26 -> 6508.968
A27: Total Brighter Choice Boys | D27: =SUM(D22:D26) -> 141 | P27: =SUM(P22:P26) -> 811855.11 | Q27: =SUM(Q22:Q26) -> 603257.89
A28: Brighter Choice Girls
B29: Albany | C29: 010100 | D29: 143 | E29: 10176 | F29: 172866321 | G29: =H29/F29 -> 0.42094357 | H29: =F29-J29 -> 72766966 | I29: =J29/F29 -> 0.57905643 | J29: 100099355 | K29: =SUM(H29+J29) -> 172866321 | L29: =H29/K29 -> 0.42094357 | M29: =J29/K29 -> 0.57905643 | N29: =D29/$D$31 -> 0.99305556 | O29: 1514457 | P29: =O29*N29*M29 -> 870866.09 | Q29: =O29*N29*L29 -> 633073.84
B30: Troy | C30: 491700 | D30: 1 | E30: 10954 | F30: 81553767 | G30: =H30/F30 -> 0.64283589 | H30: =F30-J30 -> 52425688 | I30: =J30/F30 -> 0.35716411 | J30: 29128079 | K30: =SUM(H30+J30) -> 81553767 | L30: =H30/K30 -> 0.64283589 | M30: =J30/K30 -> 0.35716411 | N30: =D30/$D$31 -> 0.0069444444 | O30: 1514457 | P30: =O30*N30*M30 -> 3756.3173 | Q30: =O30*N30*L30 -> 6760.7452
A31: Total Brighter Choice Girls | D31: =SUM(D29:D30) -> 144 | P31: =SUM(P29:P30) -> 874622.41 | Q31: =SUM(Q29:Q30) -> 639834.59
A32: KIPP Tech Valley
B33: Albany | C33: 010100 | D33: 153 | E33: 10176 | F33: 172866321 | G33: =H33/F33 -> 0.42094357 | H33: =F33-J33 -> 72766966 | I33: =J33/F33 -> 0.57905643 | J33: 100099355 | K33: =SUM(H33+J33) -> 172866321 | L33: =H33/K33 -> 0.42094357 | M33: =J33/K33 -> 0.57905643 | N33: =D33/$D$41 -> 0.92168675 | O33: 1583116 | P33: =O33*N33*M33 -> 844922.69 | Q33: =O33*N33*L33 -> 614214.35
B34: Berne-Knox Westerlo | C34: 010201 | D34: 1 | E34: 10026 | F34: 18737733 | G34: =H34/F34 -> 0.53705056 | H34: =F34-J34 -> 10063110 | I34: =J34/F34 -> 0.46294944 | J34: 8674623 | K34: =SUM(H34+J34) -> 18737733 | L34: =H34/K34 -> 0.53705056 | M34: =J34/K34 -> 0.46294944 | N34: =D34/$D$41 -> 0.0060240964 | O34: 1583116 | P34: =O34*N34*M34 -> 4415.0763 | Q34: =O34*N34*L34 -> 5121.7671
B35: Menands | C35: 010615 | D35: 1 | E35: 15215 | F35: 6663188 | G35: =H35/F35 -> 0.12586408 | H35: =F35-J35 -> 838656 | I35: =J35/F35 -> 0.87413592 | J35: 5824532 | K35: =SUM(H35+J35) -> 6663188 | L35: =H35/K35 -> 0.12586408 | M35: =J35/K35 -> 0.87413592 | N35: =D35/$D$41 -> 0.0060240964 | O35: 1583116 | P35: =O35*N35*M35 -> 8336.4974 | Q35: =O35*N35*L35 -> 1200.346
B36: Watervliet | C36: 011200 | D36: 1 | E36: 8036 | F36: 18681136 | G36: =H36/F36 -> 0.69404532 | H36: =F36-J36 -> 12965555 | I36: =J36/F36 -> 0.30595468 | J36: 5715581 | K36: =SUM(H36+J36) -> 18681136 | L36: =H36/K36 -> 0.69404532 | M36: =J36/K36 -> 0.30595468 | N36: =D36/$D$41 -> 0.0060240964 | O36: 1583116 | P36: =O36*N36*M36 -> 2917.8419 | Q36: =O36*N36*L36 -> 6619.0015
B37: Rensselaer | C37: 491200 | D37: 1 | E37: 10992 | F37: 15992771 | G37: =H37/F37 -> 0.58393014 | H37: =F37-J37 -> 9338661 | I37: =J37/F37 -> 0.41606986 | J37: 6654110 | K37: =SUM(H37+J37) -> 15992771 | L37: =H37/K37 -> 0.58393014 | M37: =J37/K37 -> 0.41606986 | N37: =D37/$D$41 -> 0.0060240964 | O37: 1583116 | P37: =O37*N37*M37 -> 3967.9931 | Q37: =O37*N37*L37 -> 5568.8503
B38: Troy | C38: 491700 | D38: 6 | E38: 10954 | F38: 81553767 | G38: =H38/F38 -> 0.64283589 | H38: =F38-J38 -> 52425688 | I38: =J38/F38 -> 0.35716411 | J38: 29128079 | K38: =SUM(H38+J38) -> 81553767 | L38: =H38/K38 -> 0.64283589 | M38: =J38/K38 -> 0.35716411 | N38: =D38/$D$41 -> 0.036144578 | O38: 1583116 | P38: =O38*N38*M38 -> 20437.309 | Q38: =O38*N38*L38 -> 36783.751
B39: Rotterdam-Mohonasen | C39: 530515 | D39: 1 | E39: 7073 | F39: 39235095 | G39: =H39/F39 -> 0.58123445 | H39: =F39-J39 -> 22804789 | I39: =J39/F39 -> 0.41876555 | J39: 16430306 | K39: =SUM(H39+J39) -> 39235095 | L39: =H39/K39 -> 0.58123445 | M39: =J39/K39 -> 0.41876555 | N39: =D39/$D$41 -> 0.0060240964 | O39: 1583116 | P39: =O39*N39*M39 -> 3993.7014 | Q39: =O39*N39*L39 -> 5543.1419
B40: Schenectady | C40: 530600 | D40: 2 | E40: 9112 | F40: 129603734 | G40: =H40/F40 -> 0.64854502 | H40: =F40-J40 -> 84053856 | I40: =J40/F40 -> 0.35145498 | J40: 45549878 | K40: =SUM(H40+J40) -> 129603734 | L40: =H40/K40 -> 0.64854502 | M40: =J40/K40 -> 0.35145498 | N40: =D40/$D$41 -> 0.012048193 | O40: 1583116 | P40: =O40*N40*M40 -> 6703.5422 | Q40: =O40*N40*L40 -> 12370.145
...

Sheet District Archive File
A1: District | D1: Year | E1: UFB | F1: STaid | G1: STAR | H1: TOTSTAT | I1: LREV | J1: FEDREV | K1: TOTREV | L1: BDED0607 | M1: CADM0607 | N1: TSAL0607 | O1: PPS0607 | P1: CDS0607 | Q1: BOC0607 | R1: TUI10607 | S1: TUI20607 | T1: OIS0607 | U1: OIEXP0607 | V1: CSER0607 | W1: OPMT0607 | X1: TCHR0607 | Y1: HEAL0607 | Z1: OEB0607 | AA1: OUND0607 | AB1: OTH0607 | AC1: SUBTOT | AD1: TRANS0607 | AE1: DSP0607 | AF1: DSI0607 | AG1: TEXP0506 | AH1: DCAADM | AI1: REV/PUPIL | AJ1: EXP/PUPIL | AK1: AV/TWPU | AL1: INC/TWPU | AM1: CWR | AN1: IE1/TOTAL | AO1: INS FB% | AP1: IE2% | AQ1: IE3/ADJ EXP | AR1: LOC EFF RATE
A2: 010100 | B2: ALBANY | D2: 2006 | E2: 9391660 | F2: 61985001 | G2: 10781965 | H2: 72766966 | I2: 100099355 | J2: 14202125 | K2: 187068446 | L2: 337488 | M2: 1944400 | N2: 52770396 | O2: 5594128 | P2: 4652548 | Q2: 4070123 | R2: 237068 | S2: 6500274 | T2: 16672939 | U2: 22021702 | V2: 1082653 | W2: 11385459 | X2: 5062461 | Y2: 15253020 | Z2: 12100562 | AA2: 3859192 | AB2: 717000 | AC2: 164261413 | AD2: 5921905 | AE2: 7040756 | AF2: 6378739 | AG2: 183602813 | AH2: 10416 | AI2: 17960 | AJ2: 17627 | AK2: 264221 | AL2: 99659 | AM2: 0.754 | AN2: 0.61284016 | AO2: 0.162 | AP2: 0.77484016 | AQ2: 0.8669 | AR2: 24.51
A3: 010201 | B3: BERNE KNOX | D3: 2006 | E3: 1772806 | F3: 8510365 | G3: 1552745 | H3: 10063110 | I3: 8674623 | J3: 738334 | K3: 19476067 | L3: 67838 | M3: 471480 | N3: 5646243 | O3: 0 | P3: 297223 | Q3: 2034555 | R3: 1180 | S3: 350246 | T3: 863681 | U3: 663008 | V3: 0 | W3: 884054 | X3: 526995 | Y3: 2970694 | Z3: 973692 | AA3: 201620 | AB3: 247579 | AC3: 16200088 | AD3: 1606294 | AE3: 703943 | AF3: 250388 | AG3: 18760713 | AH3: 1152 | AI3: 16906 | AJ3: 16285 | AK3: 274364 | AL3: 94667 | AM3: 0.746 | AN3: 0.52536042 | AO3: 0.183 | AP3: 0.70836042 | AQ3: 0.8292 | AR3: 19.72
A4: 010306 | B4: BETHLEHEM | D4: 2006 | E4: 2790327 | F4: 23148376 | G4: 6750166 | H4: 29898542 | I4: 48092263 | J4: 1665041 | K4: 79655846 | L4: 310085 | M4: 903198 | N4: 23631833 | O4: 1731877 | P4: 1927349 | Q4: 2314073 | R4: 991025 | S4: 0 | T4: 6362930 | U4: 2700328 | V4: 0 | W4: 4338334 | X4: 2453424 | Y4: 7810180 | Z4: 4715379 | AA4: 997780 | AB4: 279961 | AC4: 61467756 | AD4: 5199804 | AE4: 4564985 | AF4: 4183369 | AG4: 75415914 | AH4: 4919 | AI4: 16194 | AJ4: 15332 | AK4: 323121 | AL4: 143970 | AM4: 1.013 | AN4: 0.52587594 | AO4: 0.164 | AP4: 0.68987594 | AQ4: 0.8436 | AR4: 19.71
A5: 010402 | B5: RAVENACOEYMAN | D5: 2006 | E5: 2174497 | F5: 15856148 | G5: 3011264 | H5: 18867412 | I5: 20443166 | J5: 1829530 | K5: 41140108 | L5: 205735 | M5: 805983 | N5: 13553561 | O5: 1076869 | P5: 576931 | Q5: 2875915 | R5: 35971 | S5: 964189 | T5: 1609005 | U5: 1617389 | V5: 0 | W5: 2625132 | X5: 1638392 | Y5: 2711402 | Z5: 2162510 | AA5: 602623 | AB5: 215205 | AC5: 33276812 | AD5: 2833969 | AE5: 2532169 | AF5: 1226870 | AG5: 39869820 | AH5: 2254 | AI5: 18252 | AJ5: 17688 | AK5: 298219 | AL5: 89687 | AM5: 0.758 | AN5: 0.55956686 | AO5: 0.134 | AP5: 0.69356686 | AQ5: 0.8358 | AR5: 20.36
A6: 010500 | B6: COHOES | D6: 2006 | E6: 1679645 | F6: 15970615 | G6: 2759513 | H6: 18730128 | I6: 11467144 | J6: 2284729 | K6: 32482001 | L6: 142228 | M6: 780674 | N6: 11284815 | O6: 694296 | P6: 812178 | Q6: 1481549 | R6: 498625 | S6: 76434 | T6: 2097326 | U6: 1412971 | V6: 0 | W6: 2395541 | X6: 1103517 | Y6: 3688568 | Z6: 1799876 | AA6: 599833 | AB6: 76357 | AC6: 28944788 | AD6: 809523 | AE6: 1778764 | AF6: 592341 | AG6: 32125416 | AH6: 2121 | AI6: 15314 | AJ6: 15146 | AK6: 145261 | AL6: 79495 | AM6: 0.516 | AN6: 0.57145389 | AO6: 0.184 | AP6: 0.75545389 | AQ6: 0.8378 | AR6: 24.13
A7: 010601 | B7: SOUTH COLONIE | D7: 2006 | E7: 3179174 | F7: 21034443 | G7: 6989127 | H7: 28023570 | I7: 52765846 | J7: 2204028 | K7: 82993444 | L7: 249073 | M7: 1081181 | N7: 31094392 | O7: 780126 | P7: 1352711 | Q7: 1967720 | R7: 124584 | S7: 1014992 | T7: 7065515 | U7: 4178347 | V7: 371937 | W7: 5021835 | X7: 2989513 | Y7: 7317822 | Z7: 5393145 | AA7: 1585837 | AB7: 0 | AC7: 71588730 | AD7: 3594911 | AE7: 3776865 | AF7: 1847996 | AG7: 80808502 | AH7: 5593 | AI7: 14839 | AJ7: 14448 | AK7: 419464 | AL7: 108496 | AM7: 0.993 | AN7: 0.58877947 | AO7: 0.167 | AP7: 0.75577947 | AQ7: 0.8529 | AR7: 16.42
A8: 010605 | B8: NORTH COLONIE | D8: 2006 | E8: 4139145 | F8: 13407553 | G8: 5153966 | H8: 18561519 | I8: 57007023 | J8: 1292895 | K8: 76861437 | L8: 350374 | M8: 1222494 | N8: 28171984 | O8: 1769369 | P8: 1477306 | Q8: 313800 | R8: 0 | S8: 206829 | T8: 6895235 | U8: 3657553 | V8: 0 | W8: 6212885 | X8: 2791581 | Y8: 5941737 | Z8: 4802011 | AA8: 1387737 | AB8: 1052000 | AC8: 66252895 | AD8: 4715716 | AE8: 3549470 | AF8: 1926284 | AG8: 76444365 | AH8: 5460 | AI8: 14077 | AJ8: 14001 | AK8: 517499 | AL8: 166985 | AM8: 1.362 | AN8: 0.55585622 | AO8: 0.149 | AP8: 0.70485622 | AQ8: 0.8262 | AR8: 15.42
A9: 010615 | B9: MENANDS | D9: 2006 | E9: 848529 | F9: 556367 | G9: 282289 | H9: 838656 | I9: 5824532 | J9: 83593 | K9: 6746781 | L9: 37703 | M9: 342676 | N9: 1638298 | O9: 68661 | P9: 447 | Q9: 356735 | R9: 1341006 | S9: 0 | T9: 99279 | U9: 253522 | V9: 500 | W9: 265946 | X9: 152288 | Y9: 486790 | Z9: 228119 | AA9: 59412 | AB9: 32000 | AC9: 5363382 | AD9: 628820 | AE9: 315000 | AF9: 158805 | AG9: 6466007 | AH9: 378 | AI9: 17849 | AJ9: 17106 | AK9: 730740 | AL9: 251553 | AM9: 1.987 | AN9: 0.58118527 | AO9: 0.108 | AP9: 0.68918527 | AQ9: 0.7742 | AR9: 17.63
A10: 010622 | B10: MAPLEWOOD | D10: 2006 | E10: 105557 | F10: 593116 | G10: 128993 | H10: 722109 | I10: 1732089 | J10: 64148 | K10: 2518346 | L10: 17756 | M10: 148580 | N10: 849340 | O10: 52150 | P10: 0 | Q10: 146480 | R10: 322395 | S10: 108587 | T10: 115466 | U10: 63904 | V10: 0 | W10: 146636 | X10: 87381 | Y10: 198830 | Z10: 112402 | AA10: 53866 | AB10: 0 | AC10: 2423773 | AD10: 73256 | AE10: 20000 | AF10: 11925 | AG10: 2528954 | AH10: 201 | AI10: 12529 | AJ10: 12582 | AK10: 464690 | AL10: 139753 | AM10: 1.18 | AN10: 0.65573435 | AO10: 0.133 | AP10: 0.78873435 | AQ10: 0.7954 | AR10: 28.72
A11: 010701 | B11: GREEN ISLAND | D11: 2006 | E11: 954765 | F11: 1953731 | G11: 412845 | H11: 2366576 | I11: 3153237 | J11: 177335 | K11: 5697148 | L11: 60113 | M11: 211033 | N11: 1577181 | O11: 152803 | P11: 126042 | Q11: 635366 | R11: 0 | S11: 44105 | T11: 259149 | U11: 208401 | V11: 1640 | W11: 339418 | X11: 173890 | Y11: 324573 | Z11: 231216 | AA11: 137663 | AB11: 0 | AC11: 4482593 | AD11: 308525 | AE11: 300741 | AF11: 462187 | AG11: 5554046 | AH11: 332 | AI11: 17160 | AJ11: 16729 | AK11: 176321 | AL11: 87360 | AM11: 0.588 | AN11: 0.54069538 | AO11: 0.112 | AP11: 0.65269538 | AQ11: 0.8081 | AR11: 37.01
A12: 010802 | B12: GUILDERLAND | D12: 2006 | E12: 6203058 | F12: 23250659 | G12: 6384197 | H12: 29634856 | I12: 50963291 | J12: 1460334 | K12: 82058481 | L12: 171747 | M12: 1064380 | N12: 25863701 | O12: 1590613 | P12: 2529249 | Q12: 3485764 | R12: 0 | S12: 1352894 | T12: 6614544 | U12: 2697995 | V12: 0 | W12: 5534844 | X12: 2825418 | Y12: 7687323 | Z12: 4378406 | AA12: 1153535 | AB12: 0 | AC12: 66950413 | AD12: 4238827 | AE12: 4780384 | AF12: 2317955 | AG12: 78287579 | AH12: 5371 | AI12: 15278 | AJ12: 14576 | AK12: 345787 | AL12: 141740 | AM12: 1.033 | AN12: 0.56375175 | AO12: 0.161 | AP12: 0.72475175 | AQ12: 0.8472 | AR12: 17.89
A13: 011003 | B13: VOORHEESVILLE | D13: 2006 | E13: 886657 | F13: 5764070 | G13: 1767447 | H13: 7531517 | I13: 12761920 | J13: 346222 | K13: 20639659 | L13: 165026 | M13: 495240 | N13: 6763106 | O13: 380024 | P13: 364393 | Q13: 1109905 | R13: 11099 | S13: 110638 | T13: 1215832 | U13: 670777 | V13: 28644 | W13: 1362636 | X13: 687917 | Y13: 2547082 | Z13: 1107760 | AA13: 325771 | AB13: 534851 | AC13: 17880701 | AD13: 894939 | AE13: 1343218 | AF13: 723026 | AG13: 20841884 | AH13: 1231 | AI13: 16767 | AJ13: 16931 | AK13: 359379 | AL13: 158232 | AM13: 1.119 | AN13: 0.5098279 | AO13: 0.175 | AP13: 0.6848279 | AQ13: 0.822 | AR13: 18.74
... A678: 680801 | B678: DUNDEE | D678: 2006 | E678: 1398007 | F678: 7234758 | G678: 909846 | H678: 8144604 | I678: 3704917 | J678: 1419336 | K678: 13268857 | L678: 59684 | M678: 342285 | N678: 4687275 | O678: 148534 | P678: 175706 | Q678: 720948 | R678: 12873 | S678: 200 | T678: 921766 | U678: 683970 | V678: 0 | W678: 795694 | X678: 358266 | Y678: 1120627 | Z678: 883663 | AA678: 207925 | AB678: 0 | AC678: 11119416 | AD678: 681800 | AE678: 760000 | AF678: 292257 | AG678: 12853473 | AH678: 945 | AI678: 14041 | AJ678: 13602 | AK678: 215306 | AL678: 57357 | AM678: 0.516 | AN678: 0.57192885 | AO678: 0.156 | AP678: 0.72792885 | AQ678: 0.8418 | AR678: 13.25
A679: 999999 | B679: STATE | D679: 2006 | E679: 1619994566 | F679: 18037704210 | G679: 3553529613 | H679: 21591233823 | I679: 24965812794 | J679: 2739671347 | K679: 49296717964 | L679: 160370576 | M679: 792673793 | N679: 17031940292 | O679: 611843369 | P679: 1118113354 | Q679: 1846045277 | R679: 518070232 | S679: 767917815 | T679: 2961786133 | U679: 3085149569 | V679: 98570011 | W679: 3113401466 | X679: 2506230028 | Y679: 4033668462 | Z679: 3345900549 | AA679: 1012618868 | AB679: 267206592 | AC679: 43271506386 | AD679: 2515971434 | AE679: 1583042758 | AF679: 1196065168 | AG679: 48566585746 | AH679: 2802441 | AI679: 17591 | AJ679: 17330 | AK679: 382200 | AL679: 121800 | AM679: 1 | AN679: 0.57531049 | AO679: 0.18 | AP679: 0.75531049 | AQ679: 0.8502 | AR679: 15.1

Sheet Dist Work File
A1: District | C1: Enrollment | D1: Year | E1: LREV | F1: TOTSTAT | G1: FEDREV | H1: Other | I1: Indeterminate | J1: TOTREV
A2: 010100 | B2: ALBANY | D2: 2006 | E2: 100099355 | F2: 72766966 | G2: 14202125 | J2: 187068446
A3: 010201 | B3: BERNE KNOX | D3: 2006 | E3: 8674623 | F3: 10063110 | G3: 738334 | J3: 19476067
A4: 010306 | B4: BETHLEHEM | D4: 2006 | E4: 48092263 | F4: 29898542 | G4: 1665041 | J4: 79655846
A5: 010402 | B5: RAVENACOEYMAN | D5: 2006 | E5: 20443166 | F5: 18867412 | G5: 1829530 | J5: 41140108
A6: 010500 | B6: COHOES | D6: 2006 | E6: 11467144 | F6: 18730128 | G6: 2284729 | J6: 32482001
A7: 010601 | B7: SOUTH COLONIE | D7: 2006 | E7: 52765846 | F7: 28023570 | G7: 2204028 | J7: 82993444
A8: 010605 | B8: NORTH COLONIE | D8: 2006 | E8: 57007023 | F8: 18561519 | G8: 1292895 | J8: 76861437
A9: 010615 | B9: MENANDS | D9: 2006 | E9: 5824532 | F9: 838656 | G9: 83593 | J9: 6746781
A10: 010622 | B10: MAPLEWOOD | D10: 2006 | E10: 1732089 | F10: 722109 | G10: 64148 | J10: 2518346
A11: 010701 | B11: GREEN ISLAND | D11: 2006 | E11: 3153237 | F11: 2366576 | G11: 177335 | J11: 5697148
A12: 010802 | B12: GUILDERLAND | D12: 2006 | E12: 50963291 | F12: 29634856 | G12: 1460334 | J12: 82058481
A13: 011003 | B13: VOORHEESVILLE | D13: 2006 | E13: 12761920 | F13: 7531517 | G13: 346222 | J13: 20639659
... A678: 680801 | B678: DUNDEE | D678: 2006 | E678: 3704917 | F678: 8144604 | G678: 1419336 | J678: 13268857
B679: State Subtotal | C679: 2714773 | D679: 2006 | E679: 24965812794 | F679: 21591233823 | G679: 2739671347 | J679: 49296717964
B680: Food Service & Capital Revenue | E680: ='Dist Food Sv & Capital'!R21 -> 1626068312 | F680: ='Dist Food Sv & Capital'!R39 -> 3127106016 | G680: ='Dist Food Sv & Capital'!R9 -> 74027060 | H680: ='Dist Food Sv & Capital'!R34 -> 394627352 | I680: ='Dist Food Sv & Capital'!R11 -> 118662 | L680: NIEER Preschool Revenue Data
B681: Total Statewide prior to deductions | E681: =SUM(E679:E680) -> 26591881106 | F681: =SUM(F679:F680) -> 24718339839 | G681: =SUM(G679:G680) -> 2813698407 | H681: =SUM(H679:H680) -> 394627352 | I681: =SUM(I679:I680) -> 118662 | M681: State Preschool | N681: Federal Preschool
B682: Less Preschool/PreK | C682: 40063 | F682: 504413929 | G682: 740979286 | M682: =F682 -> 504413929 | N682: =G682 -> 740979286
B683: Less Charter Passthroughs | E683: ='Charter Work File'!E97 -> 1.0575797e+08 | F683: ='Charter Work File'!K97 -> 1.7055021e+08 | L683: PPR | M683: =M682/C682 -> 12590.518 | N683: =N682/C682 -> 18495.352
B684: Less Adult | F684: =Adult!G24 -> 954009 | G684: =Adult!G59 -> 8004104
B685: Total Statewide After Deductions | C685: =C679 -> 2714773 | E685: =E681-(E682+E683+E684) -> 2.6486123e+10 | F685: =F681-(F682+F683+F684) -> 2.4042422e+10 | G685: =G681-(G682+G683+G684) -> 2064715017 | H685: =H681-(H682+H683+H684) -> 394627352 | I685: =I681-(I682+I683+I684) -> 118662 | J685: =SUM(E685:I685) -> 52988005852 | L685: Note: NIEER reports 84,660 preschool students.
E686: =E685/C685 -> 9756.2939 | F686: =F685/C685 -> 8856.1444 | G686: =G685/C685 -> 760.54794 | H686: =H685/C685 -> 145.36293 | I686: =I685/C685 -> 0.043709732 | L686: However, NIEER only has statewide numbers - none
E687: =E685/J685 -> 0.49985129 | F687: =F685/J685 -> 0.45373328 | G687: =G685/J685 -> 0.038965705 | H687: =H685/J685 -> 0.0074474845 | I687: =I685/J685 -> 2.2394124e-06 | L687: for districts. We used the NYSED report card stats
L688: for that reason as they provide district based numbers
A689: 010100 | B689: ALBANY | D689: 2006 | E689: 100099355 | F689: 72766966 | G689: 14202125 | L689: for pre-K. This results in a higher per pupil than using
B690: Food Service & Capital Revenue | E690: ='Dist Food Sv & Capital'!S21 -> 30435588 | F690: ='Dist Food Sv & Capital'!S39 -> 121389 | G690: ='Dist Food Sv & Capital'!S9 -> 2536855 | H690: ='Dist Food Sv & Capital'!S34 -> 426801 | I690: ='Dist Food Sv & Capital'!S11 -> 0 | L690: the NIEER enrollment but there was no other choice
B691: Total Albany prior to deducations | E691: =SUM(E689:E690) -> 130534943 | F691: =SUM(F689:F690) -> 72888355 | G691: =SUM(G689:G690) -> 16738980 | H691: =SUM(H689:H690) -> 426801 | I691: =SUM(I689:I690) -> 0 | L691: since they do not have district based enrollments.
B692: Less Preschool/PreK | C692: 321 | F692: =M683*C692 -> 4041556.3 | G692: =N683*C692 -> 5937008
B693: Less Charter Passthroughs | E693: ='Charter Work File'!E197 -> 8017133.8 | F693: ='Charter Work File'!K197 -> 6765834.2 | L693: Note: Food Service and Capital Revenue not reported in public documents by the NYSED.
B694: Less Adult | F694: =Adult!L3 -> 14140 | L694: Information provided through the raw data submission by districts to the NYSED except
B695: Total Albany After Deducations | C695: 8603 | E695: =E691-(E692+E693+E694) -> 1.2251781e+08 | F695: =F691-(F692+F693+F694) -> 62066824 | G695: =G691-(G692+G693+G694) -> 10801972 | H695: =H691-(H692+H693+H694) -> 426801 | I695: =I691-(I692+I693+I694) -> 0 | J695: =SUM(E695:I695) -> 1.9581341e+08 | L695: for New York City. NYC data derived from the FY07 audit of the New York City
E696: =E695/C695 -> 14241.289 | F696: =F695/C695 -> 7214.5559 | G696: =G695/C695 -> 1255.6053 | H696: =H695/C695 -> 49.610717 | I696: =I695/C695 -> 0 | L696: School Construction Authority
E697: =E695/J695 -> 0.62568652 | F697: =F695/J695 -> 0.31696923 | G697: =G695/J695 -> 0.055164619 | H697: =H695/J695 -> 0.0021796311 | I697: =I695/J695 -> 0
A699: 140600 | B699: BUFFALO | D699: 2006 | E699: 106159756 | F699: 548458716 | G699: 69637969
B700: Food Service & Capital Revenue | E700: ='Dist Food Sv & Capital'!T21 -> 5942800 | F700: ='Dist Food Sv & Capital'!T39 -> 756078 | G700: ='Dist Food Sv & Capital'!T9 -> 16193712 | H700: ='Dist Food Sv & Capital'!T34 -> 4109734 | I700: ='Dist Food Sv & Capital'!T11 -> 0
B701: Total Buffalo prior to deductions | E701: =SUM(E699:E700) -> 112102556 | F701: =SUM(F699:F700) -> 549214794 | G701: =SUM(G699:G700) -> 85831681 | H701: =SUM(H699:H700) -> 4109734 | I701: =SUM(I699:I700) -> 0
B702: Less Preschool/PreK | C702: 1951 | F702: =M683*C702 -> 24564101 | G702: =N683*C702 -> 36084432
B703: Less Charter Passthroughs | E703: ='Charter Work File'!E183 -> 7231849.9 | F703: ='Charter Work File'!K183 -> 37230455
B704: Less Adult | F704: =Adult!L7 -> 215890 | G704: =Adult!L12 -> 302988
B705: Total Buffalo After Deducations | C705: 34589 | E705: =E701-(E702+E703+E704) -> 1.0487071e+08 | F705: =F701-(F702+F703+F704) -> 4.8720435e+08 | G705: =G701-(G702+G703+G704) -> 49444261 | H705: =H701-(H702+H703+H704) -> 4109734 | I705: =I701-(I702+I703+I704) -> 0 | J705: =SUM(E705:I705) -> 6.4562905e+08
...

Sheet Dist Food Sv & Capital
A1: District Food Service and Capital Expenditures from the ST-3 Database Download for FY06
S2: 010100 | T2: 140600 | U2: 300000
F3: Downloads | S3: Albany | T3: Buffalo | U3: New York City
B4: ST-3 Revenue Type | C4: DP Code | D4: ST3- Row | E4: Funding Type | F4: ST3-010100-051301 | G4: ST3-051901-120501 | H4: ST3-120701-150901 | I4: ST3-151001-230301 | J4: ST3-230901-280214 | K4: ST3-280215-411603 | L4: ST3-411701-460102 | M4: ST3-460500-512101 | N4: ST3-512201-580211 | O4: ST3-580212-600801 | P4: ST3-600903-660301 | R4: Total
A5: Reimbursement of Medicare Part D Expends | B5: Food Service | C5: 58 | D5: 6 | E5: Federal | F5: 7851 | G5: 8515 | H5: 51310 | I5: 30117 | J5: 5788 | K5: 230945 | L5: 31256 | M5: 63297 | N5: 40565 | O5: 107872 | P5: 6831 | Q5: 26419 | R5: =SUM(F5:Q5) -> 610766
A6: Federal Reimbursement | B6: Food Service | C6: 58 | D6: 11 | E6: Federal | F6: 1624879 | G6: 1534558 | H6: 3351610 | I6: 1360418 | J6: 4260180 | K6: 22021197 | L6: 3259191 | M6: 2209894 | N6: 3718058 | O6: 3349830 | P6: 1382418 | Q6: 1479437 | R6: =SUM(F6:Q6) -> 49551670 | S6: 2449784 | T6: 14761848 | U6: 297023056
A7: Federal Reimbursement Surplus Food Only | B7: Food Service | C7: 58 | D7: 12 | E7: Federal | F7: 270794 | G7: 53619 | H7: 1243078 | I7: 206192 | J7: 376057 | K7: 16616413 | L7: 823220 | M7: 188135 | N7: 72916 | O7: 193806 | P7: 132571 | Q7: 388573 | R7: =SUM(F7:Q7) -> 20565374 | S7: 87071 | T7: 1431864 | U7: 20000000
A8: Federal Sources | B8: Capital | C8: 65 | D8: 6 | E8: Federal | G8: 0 | H8: 0 | I8: 0 | J8: 0 | K8: 0 | L8: 2977873 | M8: 321377 | N8: 0 | O8: 0 | P8: 0 | Q8: 0 | R8: =SUM(F8:Q8) -> 3299250
Q9: Federal | R9: =SUM(R5:R8) -> 74027060 | S9: =SUM(S5:S8) -> 2536855 | T9: =SUM(T5:T8) -> 16193712 | U9: =SUM(U5:U8) -> 317023056
A10: NYC Non-state Capital (manually added item) | B10: Capital | C10: 65 | E10: Indeterminate | K10: =U10 -> 118662 | R10: =SUM(F10:Q10) -> 118662 | U10: 118662
Q11: Indeterminate | R11: =SUM(R10) -> 118662 | S11: =SUM(S10) -> 0 | T11: =SUM(T10) -> 0 | U11: =SUM(U10) -> 118662
A12: Misc. Revenues from Local Sources | B12: Food Service | C12: 58 | D12: 9 | E12: Local | F12: 1913977 | G12: 1579159 | H12: 3925443 | I12: 1244935 | J12: 3781782 | K12: 13816143 | L12: 2668838 | M12: 2230694 | N12: 2447345 | O12: 1764073 | P12: 1883868 | Q12: 1664549 | R12: =SUM(F12:Q12) -> 38920806 | S12: 32588 | T12: 53800
A13: Proceeds Term Bonds | B13: Capital | C13: 65 | D13: 9 | E13: Local | G13: 0 | H13: 0 | I13: 1375000 | J13: 361000 | K13: 0 | L13: 326885 | M13: 0 | N13: 0 | O13: 0 | P13: 6840000 | Q13: 21937517 | R13: =SUM(F13:Q13) -> 30840402
