Workbook
Name BinDivisor: 'Overall Metrics'!$X$2
Name DynamicFilterColumnName: 'Overall Metrics'!#REF!
Name DynamicFilterForceCalculationRange: HistogramBins[[Dynamic Filter Bin]:[Dynamic Filter Frequency]]
Name DynamicFilterSourceColumnRange: 'Overall Metrics'!$X$4
Name DynamicFilterTableName: 'Overall Metrics'!#REF!
Name NoMetricMessage: 'Overall Metrics'!$X$3
Name NotAvailable: 'Overall Metrics'!$X$2
Name ValidBooleansDefaultFalse: Misc!$F$2:$F$5
Name ValidEdgeStyles: Misc!$B$2:$B$11
Name ValidEdgeVisibilities: Misc!$A$2:$A$7
Name ValidGroupShapes: Misc!$E$2:$E$19
Name ValidVertexLabelPositions: Misc!$G$2:$G$21
Name ValidVertexShapes: Misc!$D$2:$D$23
Name ValidVertexVisibilities: Misc!$C$2:$C$9

Sheet Edges
C1: Visual Properties | H1: Labels | K1: Graph Metrics | L1: Do Not Edit | N1: Other Columns
A2: Vertex 1 | B2: Vertex 2 | C2: Color | D2: Width | E2: Style | F2: Opacity | G2: Visibility | H2: Label | I2: Label Text Color | J2: Label Font Size | K2: Reciprocated? | L2: ID | M2: Dynamic Filter | N2: Add Your Own Columns Here
A3: Brazil | B3: South America | L3: 3 | M3: =IF(AND(TRUE), TRUE, FALSE) -> TRUE
A4: UK | B4: Europe | L4: 4 | M4: =IF(AND(TRUE), TRUE, FALSE) -> TRUE
A5: US | B5: North America | L5: 5 | M5: =IF(AND(TRUE), TRUE, FALSE) -> TRUE
A6: Europe | B6: #opendata | L6: 6 | M6: =IF(AND(TRUE), TRUE, FALSE) -> TRUE
A7: South America | B7: #opendata | L7: 7 | M7: =IF(AND(TRUE), TRUE, FALSE) -> TRUE
A8: North America | B8: #opendata | L8: 8 | M8: =IF(AND(TRUE), TRUE, FALSE) -> TRUE
A9: @worldbank | B9: #opendata | L9: 9 | M9: =IF(AND(TRUE), TRUE, FALSE) -> TRUE
A10: #da12 | B10: Europe | L10: 10 | M10: =IF(AND(TRUE), TRUE, FALSE) -> TRUE
A11: #dadosabertos | B11: Brazil | L11: 11 | M11: =IF(AND(TRUE), TRUE, FALSE) -> TRUE
A12: @dadosgovbr | B12: Brazil | L12: 12 | M12: =IF(AND(TRUE), TRUE, FALSE) -> TRUE
A13: @egovbr | B13: Brazil | L13: 13 | M13: =IF(AND(TRUE), TRUE, FALSE) -> TRUE
A14: #uktransparency | B14: UK | L14: 14 | M14: =IF(AND(TRUE), TRUE, FALSE) -> TRUE
... A89: @opengov | B89: US | L89: 89 | M89: =IF(AND(TRUE), TRUE, FALSE) -> TRUE
L90: 90 | M90: =IF(AND(TRUE), TRUE, FALSE) -> TRUE

Sheet Vertices
B1: Visual Properties | H1: Labels | L1: Layout | R1: Graph Metrics | Z1: Do Not Edit | AB1: Other Columns
A2: Vertex | B2: Color | C2: Shape | D2: Size | E2: Opacity | F2: Image File | G2: Visibility | H2: Label | I2: Label Fill Color | J2: Label Position | K2: Tooltip | L2: Layout Order | M2: X | N2: Y | O2: Locked? | P2: Polar R | Q2: Polar Angle | R2: Degree | S2: In-Degree | T2: Out-Degree | U2: Betweenness Centrality | V2: Closeness Centrality | W2: Eigenvector Centrality | X2: PageRank | Y2: Clustering Coefficient | Z2: ID | AA2: Dynamic Filter | AB2: Add Your Own Columns Here | AC2: Followers | AD2: Minutes to max tweets | AE2: Inverse of Min to Max Tweets | AF2: Size2 | AG2: Tags | AH2: Type
A3: #opendata | B3: 255, 191, 0 | C3: Label | D3: 7.075328 | H3: #opendata | Z3: 3 | AA3: =IF(AND(OR(NOT(ISNUMBER(Vertices[Size])), Vertices[Size] >= Misc!$N$2), OR(NOT(ISNUMBER(Vertices[Size])), Vertices[Size] <= Misc!$O$2),OR(NOT(ISNUMBER(Vertices[Inverse of Min to Max Tweets])), Vertices[Inverse of Min to Max Tweets] >= Misc!$N$3), OR(NOT(ISNUMBER(Vertices[Inverse of Min to Max Tweets])), Vertices[Inverse of Min to Max Tweets] <= Misc!$O$3),OR(NOT(ISNUMBER(Vertices[Size2])), Vertices[Size2] >= Misc!$N$4), OR(NOT(ISNUMBER(Vertices[Size2])), Vertices[Size2] <= Misc!$O$4),TRUE), TRUE, FALSE) -> TRUE | AD3: 60 | AE3: =10000000/Vertices[[#This Row],[Minutes to max tweets]] -> 166666.67 | AF3: =Vertices[[#This Row],[Followers]]+Vertices[[#This Row],[Inverse of Min to Max Tweets]] -> 166666.67 | AH3: Tag
A4: Brazil | C4: Label | D4: 5 | H4: Brazil | Z4: 4 | AA4: =IF(AND(OR(NOT(ISNUMBER(Vertices[Size])), Vertices[Size] >= Misc!$N$2), OR(NOT(ISNUMBER(Vertices[Size])), Vertices[Size] <= Misc!$O$2),OR(NOT(ISNUMBER(Vertices[Inverse of Min to Max Tweets])), Vertices[Inverse of Min to Max Tweets] >= Misc!$N$3), OR(NOT(ISNUMBER(Vertices[Inverse of Min to Max Tweets])), Vertices[Inverse of Min to Max Tweets] <= Misc!$O$3),OR(NOT(ISNUMBER(Vertices[Size2])), Vertices[Size2] >= Misc!$N$4), OR(NOT(ISNUMBER(Vertices[Size2])), Vertices[Size2] <= Misc!$O$4),TRUE), TRUE, FALSE) -> TRUE | AF4: =Vertices[[#This Row],[Followers]]+Vertices[[#This Row],[Inverse of Min to Max Tweets]] -> 0 | AH4: Geography
A5: UK | C5: Label | D5: 5 | H5: UK | Z5: 5 | AA5: =IF(AND(OR(NOT(ISNUMBER(Vertices[Size])), Vertices[Size] >= Misc!$N$2), OR(NOT(ISNUMBER(Vertices[Size])), Vertices[Size] <= Misc!$O$2),OR(NOT(ISNUMBER(Vertices[Inverse of Min to Max Tweets])), Vertices[Inverse of Min to Max Tweets] >= Misc!$N$3), OR(NOT(ISNUMBER(Vertices[Inverse of Min to Max Tweets])), Vertices[Inverse of Min to Max Tweets] <= Misc!$O$3),OR(NOT(ISNUMBER(Vertices[Size2])), Vertices[Size2] >= Misc!$N$4), OR(NOT(ISNUMBER(Vertices[Size2])), Vertices[Size2] <= Misc!$O$4),TRUE), TRUE, FALSE) -> TRUE | AF5: =Vertices[[#This Row],[Followers]]+Vertices[[#This Row],[Inverse of Min to Max Tweets]] -> 0 | AH5: Geography
A6: US | C6: Label | D6: 5 | H6: US | Z6: 6 | AA6: =IF(AND(OR(NOT(ISNUMBER(Vertices[Size])), Vertices[Size] >= Misc!$N$2), OR(NOT(ISNUMBER(Vertices[Size])), Vertices[Size] <= Misc!$O$2),OR(NOT(ISNUMBER(Vertices[Inverse of Min to Max Tweets])), Vertices[Inverse of Min to Max Tweets] >= Misc!$N$3), OR(NOT(ISNUMBER(Vertices[Inverse of Min to Max Tweets])), Vertices[Inverse of Min to Max Tweets] <= Misc!$O$3),OR(NOT(ISNUMBER(Vertices[Size2])), Vertices[Size2] >= Misc!$N$4), OR(NOT(ISNUMBER(Vertices[Size2])), Vertices[Size2] <= Misc!$O$4),TRUE), TRUE, FALSE) -> TRUE | AF6: =Vertices[[#This Row],[Followers]]+Vertices[[#This Row],[Inverse of Min to Max Tweets]] -> 0 | AH6: Geography
A7: Europe | C7: Label | D7: 5 | H7: Europe | Z7: 7 | AA7: =IF(AND(OR(NOT(ISNUMBER(Vertices[Size])), Vertices[Size] >= Misc!$N$2), OR(NOT(ISNUMBER(Vertices[Size])), Vertices[Size] <= Misc!$O$2),OR(NOT(ISNUMBER(Vertices[Inverse of Min to Max Tweets])), Vertices[Inverse of Min to Max Tweets] >= Misc!$N$3), OR(NOT(ISNUMBER(Vertices[Inverse of Min to Max Tweets])), Vertices[Inverse of Min to Max Tweets] <= Misc!$O$3),OR(NOT(ISNUMBER(Vertices[Size2])), Vertices[Size2] >= Misc!$N$4), OR(NOT(ISNUMBER(Vertices[Size2])), Vertices[Size2] <= Misc!$O$4),TRUE), TRUE, FALSE) -> TRUE | AF7: =Vertices[[#This Row],[Followers]]+Vertices[[#This Row],[Inverse of Min to Max Tweets]] -> 0 | AH7: Geography
A8: South America | C8: Label | D8: 5 | H8: South America | Z8: 8 | AA8: =IF(AND(OR(NOT(ISNUMBER(Vertices[Size])), Vertices[Size] >= Misc!$N$2), OR(NOT(ISNUMBER(Vertices[Size])), Vertices[Size] <= Misc!$O$2),OR(NOT(ISNUMBER(Vertices[Inverse of Min to Max Tweets])), Vertices[Inverse of Min to Max Tweets] >= Misc!$N$3), OR(NOT(ISNUMBER(Vertices[Inverse of Min to Max Tweets])), Vertices[Inverse of Min to Max Tweets] <= Misc!$O$3),OR(NOT(ISNUMBER(Vertices[Size2])), Vertices[Size2] >= Misc!$N$4), OR(NOT(ISNUMBER(Vertices[Size2])), Vertices[Size2] <= Misc!$O$4),TRUE), TRUE, FALSE) -> TRUE | AF8: =Vertices[[#This Row],[Followers]]+Vertices[[#This Row],[Inverse of Min to Max Tweets]] -> 0 | AH8: Geography
A9: North America | C9: Label | D9: 5 | H9: North America | Z9: 9 | AA9: =IF(AND(OR(NOT(ISNUMBER(Vertices[Size])), Vertices[Size] >= Misc!$N$2), OR(NOT(ISNUMBER(Vertices[Size])), Vertices[Size] <= Misc!$O$2),OR(NOT(ISNUMBER(Vertices[Inverse of Min to Max Tweets])), Vertices[Inverse of Min to Max Tweets] >= Misc!$N$3), OR(NOT(ISNUMBER(Vertices[Inverse of Min to Max Tweets])), Vertices[Inverse of Min to Max Tweets] <= Misc!$O$3),OR(NOT(ISNUMBER(Vertices[Size2])), Vertices[Size2] >= Misc!$N$4), OR(NOT(ISNUMBER(Vertices[Size2])), Vertices[Size2] <= Misc!$O$4),TRUE), TRUE, FALSE) -> TRUE | AF9: =Vertices[[#This Row],[Followers]]+Vertices[[#This Row],[Inverse of Min to Max Tweets]] -> 0 | AH9: Geography
A10: @worldbank | C10: Circle | D10: 6.9645594 | H10: @worldbank | Z10: 10 | AA10: =IF(AND(OR(NOT(ISNUMBER(Vertices[Size])), Vertices[Size] >= Misc!$N$2), OR(NOT(ISNUMBER(Vertices[Size])), Vertices[Size] <= Misc!$O$2),OR(NOT(ISNUMBER(Vertices[Inverse of Min to Max Tweets])), Vertices[Inverse of Min to Max Tweets] >= Misc!$N$3), OR(NOT(ISNUMBER(Vertices[Inverse of Min to Max Tweets])), Vertices[Inverse of Min to Max Tweets] <= Misc!$O$3),OR(NOT(ISNUMBER(Vertices[Size2])), Vertices[Size2] >= Misc!$N$4), OR(NOT(ISNUMBER(Vertices[Size2])), Vertices[Size2] <= Misc!$O$4),TRUE), TRUE, FALSE) -> TRUE | AC10: 147124 | AF10: =Vertices[[#This Row],[Followers]]+Vertices[[#This Row],[Inverse of Min to Max Tweets]] -> 147124 | AG10: International | AH10: Organization
A11: #da12 | B11: 255, 191, 0 | C11: Label | D11: 4.5082794 | H11: #da12 | Z11: 11 | AA11: =IF(AND(OR(NOT(ISNUMBER(Vertices[Size])), Vertices[Size] >= Misc!$N$2), OR(NOT(ISNUMBER(Vertices[Size])), Vertices[Size] <= Misc!$O$2),OR(NOT(ISNUMBER(Vertices[Inverse of Min to Max Tweets])), Vertices[Inverse of Min to Max Tweets] >= Misc!$N$3), OR(NOT(ISNUMBER(Vertices[Inverse of Min to Max Tweets])), Vertices[Inverse of Min to Max Tweets] <= Misc!$O$3),OR(NOT(ISNUMBER(Vertices[Size2])), Vertices[Size2] >= Misc!$N$4), OR(NOT(ISNUMBER(Vertices[Size2])), Vertices[Size2] <= Misc!$O$4),TRUE), TRUE, FALSE) -> TRUE | AD11: 1080 | AE11: =10000000/Vertices[[#This Row],[Minutes to max tweets]] -> 9259.2593 | AF11: =Vertices[[#This Row],[Followers]]+Vertices[[#This Row],[Inverse of Min to Max Tweets]] -> 9259.2593 | AH11: Tag
A12: #dadosabertos | B12: 255, 191, 0 | C12: Label | D12: 3.0215575 | H12: #dadosabertos | Z12: 12 | AA12: =IF(AND(OR(NOT(ISNUMBER(Vertices[Size])), Vertices[Size] >= Misc!$N$2), OR(NOT(ISNUMBER(Vertices[Size])), Vertices[Size] <= Misc!$O$2),OR(NOT(ISNUMBER(Vertices[Inverse of Min to Max Tweets])), Vertices[Inverse of Min to Max Tweets] >= Misc!$N$3), OR(NOT(ISNUMBER(Vertices[Inverse of Min to Max Tweets])), Vertices[Inverse of Min to Max Tweets] <= Misc!$O$3),OR(NOT(ISNUMBER(Vertices[Size2])), Vertices[Size2] >= Misc!$N$4), OR(NOT(ISNUMBER(Vertices[Size2])), Vertices[Size2] <= Misc!$O$4),TRUE), TRUE, FALSE) -> TRUE | AD12: 5760 | AE12: =10000000/Vertices[[#This Row],[Minutes to max tweets]] -> 1736.1111 | AF12: =Vertices[[#This Row],[Followers]]+Vertices[[#This Row],[Inverse of Min to Max Tweets]] -> 1736.1111 | AH12: Tag
A13: @dadosgovbr | C13: Circle | D13: 2.1282881 | H13: @dadosgovbr | Z13: 13 | AA13: =IF(AND(OR(NOT(ISNUMBER(Vertices[Size])), Vertices[Size] >= Misc!$N$2), OR(NOT(ISNUMBER(Vertices[Size])), Vertices[Size] <= Misc!$O$2),OR(NOT(ISNUMBER(Vertices[Inverse of Min to Max Tweets])), Vertices[Inverse of Min to Max Tweets] >= Misc!$N$3), OR(NOT(ISNUMBER(Vertices[Inverse of Min to Max Tweets])), Vertices[Inverse of Min to Max Tweets] <= Misc!$O$3),OR(NOT(ISNUMBER(Vertices[Size2])), Vertices[Size2] >= Misc!$N$4), OR(NOT(ISNUMBER(Vertices[Size2])), Vertices[Size2] <= Misc!$O$4),TRUE), TRUE, FALSE) -> TRUE | AC13: 635 | AF13: =Vertices[[#This Row],[Followers]]+Vertices[[#This Row],[Inverse of Min to Max Tweets]] -> 635 | AG13: Brazil | AH13: Government
A14: @egovbr | C14: Circle | D14: 4.8057443 | H14: @egovbr | Z14: 14 | AA14: =IF(AND(OR(NOT(ISNUMBER(Vertices[Size])), Vertices[Size] >= Misc!$N$2), OR(NOT(ISNUMBER(Vertices[Size])), Vertices[Size] <= Misc!$O$2),OR(NOT(ISNUMBER(Vertices[Inverse of Min to Max Tweets])), Vertices[Inverse of Min to Max Tweets] >= Misc!$N$3), OR(NOT(ISNUMBER(Vertices[Inverse of Min to Max Tweets])), Vertices[Inverse of Min to Max Tweets] <= Misc!$O$3),OR(NOT(ISNUMBER(Vertices[Size2])), Vertices[Size2] >= Misc!$N$4), OR(NOT(ISNUMBER(Vertices[Size2])), Vertices[Size2] <= Misc!$O$4),TRUE), TRUE, FALSE) -> TRUE | AC14: 12943 | AF14: =Vertices[[#This Row],[Followers]]+Vertices[[#This Row],[Inverse of Min to Max Tweets]] -> 12943 | AG14: Brazil | AH14: Government
A15: #uktransparency | B15: 255, 191, 0 | C15: Label | D15: 2.4059473 | H15: #uktransparency | Z15: 15 | AA15: =IF(AND(OR(NOT(ISNUMBER(Vertices[Size])), Vertices[Size] >= Misc!$N$2), OR(NOT(ISNUMBER(Vertices[Size])), Vertices[Size] <= Misc!$O$2),OR(NOT(ISNUMBER(Vertices[Inverse of Min to Max Tweets])), Vertices[Inverse of Min to Max Tweets] >= Misc!$N$3), OR(NOT(ISNUMBER(Vertices[Inverse of Min to Max Tweets])), Vertices[Inverse of Min to Max Tweets] <= Misc!$O$3),OR(NOT(ISNUMBER(Vertices[Size2])), Vertices[Size2] >= Misc!$N$4), OR(NOT(ISNUMBER(Vertices[Size2])), Vertices[Size2] <= Misc!$O$4),TRUE), TRUE, FALSE) -> TRUE | AD15: 11520 | AE15: =10000000/Vertices[[#This Row],[Minutes to max tweets]] -> 868.05556 | AF15: =Vertices[[#This Row],[Followers]]+Vertices[[#This Row],[Inverse of Min to Max Tweets]] -> 868.05556 | AH15: Tag
A16: #egov | B16: 255, 191, 0 | C16: Label | D16: 5.6459252 | H16: #egov | Z16: 16 | AA16: =IF(AND(OR(NOT(ISNUMBER(Vertices[Size])), Vertices[Size] >= Misc!$N$2), OR(NOT(ISNUMBER(Vertices[Size])), Vertices[Size] <= Misc!$O$2),OR(NOT(ISNUMBER(Vertices[Inverse of Min to Max Tweets])), Vertices[Inverse of Min to Max Tweets] >= Misc!$N$3), OR(NOT(ISNUMBER(Vertices[Inverse of Min to Max Tweets])), Vertices[Inverse of Min to Max Tweets] <= Misc!$O$3),OR(NOT(ISNUMBER(Vertices[Size2])), Vertices[Size2] >= Misc!$N$4), OR(NOT(ISNUMBER(Vertices[Size2])), Vertices[Size2] <= Misc!$O$4),TRUE), TRUE, FALSE) -> TRUE | AD16: 300 | AE16: =10000000/Vertices[[#This Row],[Minutes to max tweets]] -> 33333.333 | AF16: =Vertices[[#This Row],[Followers]]+Vertices[[#This Row],[Inverse of Min to Max Tweets]] -> 33333.333 | AH16: Tag
A17: @ictdev | C17: Circle | D17: 3.4371363 | H17: @ictdev | Z17: 17 | AA17: =IF(AND(OR(NOT(ISNUMBER(Vertices[Size])), Vertices[Size] >= Misc!$N$2), OR(NOT(ISNUMBER(Vertices[Size])), Vertices[Size] <= Misc!$O$2),OR(NOT(ISNUMBER(Vertices[Inverse of Min to Max Tweets])), Vertices[Inverse of Min to Max Tweets] >= Misc!$N$3), OR(NOT(ISNUMBER(Vertices[Inverse of Min to Max Tweets])), Vertices[Inverse of Min to Max Tweets] <= Misc!$O$3),OR(NOT(ISNUMBER(Vertices[Size2])), Vertices[Size2] >= Misc!$N$4), OR(NOT(ISNUMBER(Vertices[Size2])), Vertices[Size2] <= Misc!$O$4),TRUE), TRUE, FALSE) -> TRUE | AC17: 2772 | AF17: =Vertices[[#This Row],[Followers]]+Vertices[[#This Row],[Inverse of Min to Max Tweets]] -> 2772 | AH17: Media
A18: #ICT4d | B18: 255, 191, 0 | C18: Label | D18: 5.4839985 | H18: #ICT4d | Z18: 18 | AA18: =IF(AND(OR(NOT(ISNUMBER(Vertices[Size])), Vertices[Size] >= Misc!$N$2), OR(NOT(ISNUMBER(Vertices[Size])), Vertices[Size] <= Misc!$O$2),OR(NOT(ISNUMBER(Vertices[Inverse of Min to Max Tweets])), Vertices[Inverse of Min to Max Tweets] >= Misc!$N$3), OR(NOT(ISNUMBER(Vertices[Inverse of Min to Max Tweets])), Vertices[Inverse of Min to Max Tweets] <= Misc!$O$3),OR(NOT(ISNUMBER(Vertices[Size2])), Vertices[Size2] >= Misc!$N$4), OR(NOT(ISNUMBER(Vertices[Size2])), Vertices[Size2] <= Misc!$O$4),TRUE), TRUE, FALSE) -> TRUE | AD18: 360 | AE18: =10000000/Vertices[[#This Row],[Minutes to max tweets]] -> 27777.778 | AF18: =Vertices[[#This Row],[Followers]]+Vertices[[#This Row],[Inverse of Min to Max Tweets]] -> 27777.778 | AH18: Tag
A19: @glynmoody | C19: Circle | D19: 4.614023 | H19: @glynmoody | Z19: 19 | AA19: =IF(AND(OR(NOT(ISNUMBER(Vertices[Size])), Vertices[Size] >= Misc!$N$2), OR(NOT(ISNUMBER(Vertices[Size])), Vertices[Size] <= Misc!$O$2),OR(NOT(ISNUMBER(Vertices[Inverse of Min to Max Tweets])), Vertices[Inverse of Min to Max Tweets] >= Misc!$N$3), OR(NOT(ISNUMBER(Vertices[Inverse of Min to Max Tweets])), Vertices[Inverse of Min to Max Tweets] <= Misc!$O$3),OR(NOT(ISNUMBER(Vertices[Size2])), Vertices[Size2] >= Misc!$N$4), OR(NOT(ISNUMBER(Vertices[Size2])), Vertices[Size2] <= Misc!$O$4),TRUE), TRUE, FALSE) -> TRUE | AC19: 10430 | AF19: =Vertices[[#This Row],[Followers]]+Vertices[[#This Row],[Inverse of Min to Max Tweets]] -> 10430
A20: @Jay_Nath | C20: Circle | D20: 3.4639608 | H20: @Jay_Nath | Z20: 20 | AA20: =IF(AND(OR(NOT(ISNUMBER(Vertices[Size])), Vertices[Size] >= Misc!$N$2), OR(NOT(ISNUMBER(Vertices[Size])), Vertices[Size] <= Misc!$O$2),OR(NOT(ISNUMBER(Vertices[Inverse of Min to Max Tweets])), Vertices[Inverse of Min to Max Tweets] >= Misc!$N$3), OR(NOT(ISNUMBER(Vertices[Inverse of Min to Max Tweets])), Vertices[Inverse of Min to Max Tweets] <= Misc!$O$3),OR(NOT(ISNUMBER(Vertices[Size2])), Vertices[Size2] >= Misc!$N$4), OR(NOT(ISNUMBER(Vertices[Size2])), Vertices[Size2] <= Misc!$O$4),TRUE), TRUE, FALSE) -> TRUE | AC20: 2857 | AF20: =Vertices[[#This Row],[Followers]]+Vertices[[#This Row],[Inverse of Min to Max Tweets]] -> 2857 | AG20: SF, US | AH20: Officer
A21: #gov20 | B21: 255, 191, 0 | C21: Label | D21: 4.8683883 | H21: #gov20 | Z21: 21 | AA21: =IF(AND(OR(NOT(ISNUMBER(Vertices[Size])), Vertices[Size] >= Misc!$N$2), OR(NOT(ISNUMBER(Vertices[Size])), Vertices[Size] <= Misc!$O$2),OR(NOT(ISNUMBER(Vertices[Inverse of Min to Max Tweets])), Vertices[Inverse of Min to Max Tweets] >= Misc!$N$3), OR(NOT(ISNUMBER(Vertices[Inverse of Min to Max Tweets])), Vertices[Inverse of Min to Max Tweets] <= Misc!$O$3),OR(NOT(ISNUMBER(Vertices[Size2])), Vertices[Size2] >= Misc!$N$4), OR(NOT(ISNUMBER(Vertices[Size2])), Vertices[Size2] <= Misc!$O$4),TRUE), TRUE, FALSE) -> TRUE | AD21: 720 | AE21: =10000000/Vertices[[#This Row],[Minutes to max tweets]] -> 13888.889 | AF21: =Vertices[[#This Row],[Followers]]+Vertices[[#This Row],[Inverse of Min to Max Tweets]] -> 13888.889 | AH21: Tag
A22: @NeelieKroesEU | C22: Circle | D22: 5.9386734 | H22: @NeelieKroesEU | Z22: 22 | AA22: =IF(AND(OR(NOT(ISNUMBER(Vertices[Size])), Vertices[Size] >= Misc!$N$2), OR(NOT(ISNUMBER(Vertices[Size])), Vertices[Size] <= Misc!$O$2),OR(NOT(ISNUMBER(Vertices[Inverse of Min to Max Tweets])), Vertices[Inverse of Min to Max Tweets] >= Misc!$N$3), OR(NOT(ISNUMBER(Vertices[Inverse of Min to Max Tweets])), Vertices[Inverse of Min to Max Tweets] <= Misc!$O$3),OR(NOT(ISNUMBER(Vertices[Size2])), Vertices[Size2] >= Misc!$N$4), OR(NOT(ISNUMBER(Vertices[Size2])), Vertices[Size2] <= Misc!$O$4),TRUE), TRUE, FALSE) -> TRUE | AC22: 46348 | AF22: =Vertices[[#This Row],[Followers]]+Vertices[[#This Row],[Inverse of Min to Max Tweets]] -> 46348 | AG22: Europe, European Commission, #da12 | AH22: Officer
A23: SF | C23: Label | D23: 5 | H23: SF | Z23: 23 | AA23: =IF(AND(OR(NOT(ISNUMBER(Vertices[Size])), Vertices[Size] >= Misc!$N$2), OR(NOT(ISNUMBER(Vertices[Size])), Vertices[Size] <= Misc!$O$2),OR(NOT(ISNUMBER(Vertices[Inverse of Min to Max Tweets])), Vertices[Inverse of Min to Max Tweets] >= Misc!$N$3), OR(NOT(ISNUMBER(Vertices[Inverse of Min to Max Tweets])), Vertices[Inverse of Min to Max Tweets] <= Misc!$O$3),OR(NOT(ISNUMBER(Vertices[Size2])), Vertices[Size2] >= Misc!$N$4), OR(NOT(ISNUMBER(Vertices[Size2])), Vertices[Size2] <= Misc!$O$4),TRUE), TRUE, FALSE) -> TRUE | AF23: =Vertices[[#This Row],[Followers]]+Vertices[[#This Row],[Inverse of Min to Max Tweets]] -> 0 | AH23: Geography
A24: #IOGDC | B24: 255, 191, 0 | C24: Label | D24: 2.5245416 | H24: #IOGDC | Z24: 24 | AA24: =IF(AND(OR(NOT(ISNUMBER(Vertices[Size])), Vertices[Size] >= Misc!$N$2), OR(NOT(ISNUMBER(Vertices[Size])), Vertices[Size] <= Misc!$O$2),OR(NOT(ISNUMBER(Vertices[Inverse of Min to Max Tweets])), Vertices[Inverse of Min to Max Tweets] >= Misc!$N$3), OR(NOT(ISNUMBER(Vertices[Inverse of Min to Max Tweets])), Vertices[Inverse of Min to Max Tweets] <= Misc!$O$3),OR(NOT(ISNUMBER(Vertices[Size2])), Vertices[Size2] >= Misc!$N$4), OR(NOT(ISNUMBER(Vertices[Size2])), Vertices[Size2] <= Misc!$O$4),TRUE), TRUE, FALSE) -> TRUE | AD24: 10080 | AE24: =10000000/Vertices[[#This Row],[Minutes to max tweets]] -> 992.06349 | AF24: =Vertices[[#This Row],[Followers]]+Vertices[[#This Row],[Inverse of Min to Max Tweets]] -> 992.06349 | AG24: WorldBank, Conference | AH24: Tag
A25: @WorldBankData | C25: Circle | D25: 0 | H25: @WorldBankData | Z25: 25 | AA25: =IF(AND(OR(NOT(ISNUMBER(Vertices[Size])), Vertices[Size] >= Misc!$N$2), OR(NOT(ISNUMBER(Vertices[Size])), Vertices[Size] <= Misc!$O$2),OR(NOT(ISNUMBER(Vertices[Inverse of Min to Max Tweets])), Vertices[Inverse of Min to Max Tweets] >= Misc!$N$3), OR(NOT(ISNUMBER(Vertices[Inverse of Min to Max Tweets])), Vertices[Inverse of Min to Max Tweets] <= Misc!$O$3),OR(NOT(ISNUMBER(Vertices[Size2])), Vertices[Size2] >= Misc!$N$4), OR(NOT(ISNUMBER(Vertices[Size2])), Vertices[Size2] <= Misc!$O$4),TRUE), TRUE, FALSE) -> TRUE | AF25: =Vertices[[#This Row],[Followers]]+Vertices[[#This Row],[Inverse of Min to Max Tweets]] -> 0 | AG25: International | AH25: Organization
A26: #ogov | B26: 255, 191, 0 | C26: Label | D26: 4.8683883 | H26: #ogov | Z26: 26 | AA26: =IF(AND(OR(NOT(ISNUMBER(Vertices[Size])), Vertices[Size] >= Misc!$N$2), OR(NOT(ISNUMBER(Vertices[Size])), Vertices[Size] <= Misc!$O$2),OR(NOT(ISNUMBER(Vertices[Inverse of Min to Max Tweets])), Vertices[Inverse of Min to Max Tweets] >= Misc!$N$3), OR(NOT(ISNUMBER(Vertices[Inverse of Min to Max Tweets])), Vertices[Inverse of Min to Max Tweets] <= Misc!$O$3),OR(NOT(ISNUMBER(Vertices[Size2])), Vertices[Size2] >= Misc!$N$4), OR(NOT(ISNUMBER(Vertices[Size2])), Vertices[Size2] <= Misc!$O$4),TRUE), TRUE, FALSE) -> TRUE | AD26: 720 | AE26: =10000000/Vertices[[#This Row],[Minutes to max tweets]] -> 13888.889 | AF26: =Vertices[[#This Row],[Followers]]+Vertices[[#This Row],[Inverse of Min to Max Tweets]] -> 13888.889 | AH26: Tag
A27: @usdatagov | C27: Circle | D27: 3.4498605 | H27: @usdatagov | Z27: 27 | AA27: =IF(AND(OR(NOT(ISNUMBER(Vertices[Size])), Vertices[Size] >= Misc!$N$2), OR(NOT(ISNUMBER(Vertices[Size])), Vertices[Size] <= Misc!$O$2),OR(NOT(ISNUMBER(Vertices[Inverse of Min to Max Tweets])), Vertices[Inverse of Min to Max Tweets] >= Misc!$N$3), OR(NOT(ISNUMBER(Vertices[Inverse of Min to Max Tweets])), Vertices[Inverse of Min to Max Tweets] <= Misc!$O$3),OR(NOT(ISNUMBER(Vertices[Size2])), Vertices[Size2] >= Misc!$N$4), OR(NOT(ISNUMBER(Vertices[Size2])), Vertices[Size2] <= Misc!$O$4),TRUE), TRUE, FALSE) -> TRUE | AC27: 2812 | AF27: =Vertices[[#This Row],[Followers]]+Vertices[[#This Row],[Inverse of Min to Max Tweets]] -> 2812 | AG27: US, White House | AH27: Government
A28: @LiberationTech | C28: Circle | D28: 4.7339575 | H28: @LiberationTech | Z28: 28 | AA28: =IF(AND(OR(NOT(ISNUMBER(Vertices[Size])), Vertices[Size] >= Misc!$N$2), OR(NOT(ISNUMBER(Vertices[Size])), Vertices[Size] <= Misc!$O$2),OR(NOT(ISNUMBER(Vertices[Inverse of Min to Max Tweets])), Vertices[Inverse of Min to Max Tweets] >= Misc!$N$3), OR(NOT(ISNUMBER(Vertices[Inverse of Min to Max Tweets])), Vertices[Inverse of Min to Max Tweets] <= Misc!$O$3),OR(NOT(ISNUMBER(Vertices[Size2])), Vertices[Size2] >= Misc!$N$4), OR(NOT(ISNUMBER(Vertices[Size2])), Vertices[Size2] <= Misc!$O$4),TRUE), TRUE, FALSE) -> TRUE | AC28: 11938 | AF28: =Vertices[[#This Row],[Followers]]+Vertices[[#This Row],[Inverse of Min to Max Tweets]] -> 11938 | AG28: Stanford | AH28: Academic
A29: @SunFoundation | C29: Circle | D29: 5.032568 | H29: @SunFoundation | Z29: 29 | AA29: =IF(AND(OR(NOT(ISNUMBER(Vertices[Size])), Vertices[Size] >= Misc!$N$2), OR(NOT(ISNUMBER(Vertices[Size])), Vertices[Size] <= Misc!$O$2),OR(NOT(ISNUMBER(Vertices[Inverse of Min to Max Tweets])), Vertices[Inverse of Min to Max Tweets] >= Misc!$N$3), OR(NOT(ISNUMBER(Vertices[Inverse of Min to Max Tweets])), Vertices[Inverse of Min to Max Tweets] <= Misc!$O$3),OR(NOT(ISNUMBER(Vertices[Size2])), Vertices[Size2] >= Misc!$N$4), OR(NOT(ISNUMBER(Vertices[Size2])), Vertices[Size2] <= Misc!$O$4),TRUE), TRUE, FALSE) -> TRUE | AC29: 16709 | AF29: =Vertices[[#This Row],[Followers]]+Vertices[[#This Row],[Inverse of Min to Max Tweets]] -> 16709 | AH29: Foundation
A30: @EC_opendata | C30: Circle | D30: 3.0482098 | H30: @EC_opendata | Z30: 30 | AA30: =IF(AND(OR(NOT(ISNUMBER(Vertices[Size])), Vertices[Size] >= Misc!$N$2), OR(NOT(ISNUMBER(Vertices[Size])), Vertices[Size] <= Misc!$O$2),OR(NOT(ISNUMBER(Vertices[Inverse of Min to Max Tweets])), Vertices[Inverse of Min to Max Tweets] >= Misc!$N$3), OR(NOT(ISNUMBER(Vertices[Inverse of Min to Max Tweets])), Vertices[Inverse of Min to Max Tweets] <= Misc!$O$3),OR(NOT(ISNUMBER(Vertices[Size2])), Vertices[Size2] >= Misc!$N$4), OR(NOT(ISNUMBER(Vertices[Size2])), Vertices[Size2] <= Misc!$O$4),TRUE), TRUE, FALSE) -> TRUE | AC30: 1789 | AF30: =Vertices[[#This Row],[Followers]]+Vertices[[#This Row],[Inverse of Min to Max Tweets]] -> 1789 | AG30: Europe, European Commission | AH30: Government
A31: @OpenGov | C31: Circle | D31: 8 | H31: @OpenGov | Z31: 31 | AA31: =IF(AND(OR(NOT(ISNUMBER(Vertices[Size])), Vertices[Size] >= Misc!$N$2), OR(NOT(ISNUMBER(Vertices[Size])), Vertices[Size] <= Misc!$O$2),OR(NOT(ISNUMBER(Vertices[Inverse of Min to Max Tweets])), Vertices[Inverse of Min to Max Tweets] >= Misc!$N$3), OR(NOT(ISNUMBER(Vertices[Inverse of Min to Max Tweets])), Vertices[Inverse of Min to Max Tweets] <= Misc!$O$3),OR(NOT(ISNUMBER(Vertices[Size2])), Vertices[Size2] >= Misc!$N$4), OR(NOT(ISNUMBER(Vertices[Size2])), Vertices[Size2] <= Misc!$O$4),TRUE), TRUE, FALSE) -> TRUE | AC31: 472072 | AF31: =Vertices[[#This Row],[Followers]]+Vertices[[#This Row],[Inverse of Min to Max Tweets]] -> 472072 | AG31: US, White House | AH31: Government
A32: @opendataParis | C32: Circle | D32: 2.9339312 | H32: @opendataParis | Z32: 32 | AA32: =IF(AND(OR(NOT(ISNUMBER(Vertices[Size])), Vertices[Size] >= Misc!$N$2), OR(NOT(ISNUMBER(Vertices[Size])), Vertices[Size] <= Misc!$O$2),OR(NOT(ISNUMBER(Vertices[Inverse of Min to Max Tweets])), Vertices[Inverse of Min to Max Tweets] >= Misc!$N$3), OR(NOT(ISNUMBER(Vertices[Inverse of Min to Max Tweets])), Vertices[Inverse of Min to Max Tweets] <= Misc!$O$3),OR(NOT(ISNUMBER(Vertices[Size2])), Vertices[Size2] >= Misc!$N$4), OR(NOT(ISNUMBER(Vertices[Size2])), Vertices[Size2] <= Misc!$O$4),TRUE), TRUE, FALSE) -> TRUE | AC32: 1573 | AF32: =Vertices[[#This Row],[Followers]]+Vertices[[#This Row],[Inverse of Min to Max Tweets]] -> 1573 | AG32: Europe, France | AH32: Government
A33: @KnightFdn | C33: Circle | D33: 5.5103405 | H33: @KnightFdn | Z33: 33 | AA33: =IF(AND(OR(NOT(ISNUMBER(Vertices[Size])), Vertices[Size] >= Misc!$N$2), OR(NOT(ISNUMBER(Vertices[Size])), Vertices[Size] <= Misc!$O$2),OR(NOT(ISNUMBER(Vertices[Inverse of Min to Max Tweets])), Vertices[Inverse of Min to Max Tweets] >= Misc!$N$3), OR(NOT(ISNUMBER(Vertices[Inverse of Min to Max Tweets])), Vertices[Inverse of Min to Max Tweets] <= Misc!$O$3),OR(NOT(ISNUMBER(Vertices[Size2])), Vertices[Size2] >= Misc!$N$4), OR(NOT(ISNUMBER(Vertices[Size2])), Vertices[Size2] <= Misc!$O$4),TRUE), TRUE, FALSE) -> TRUE | AC33: 28614 | AF33: =Vertices[[#This Row],[Followers]]+Vertices[[#This Row],[Inverse of Min to Max Tweets]] -> 28614 | AG33: US, Arts | AH33: Foundation
A34: @OKFN | C34: Circle | D34: 3.8658662 | H34: @OKFN | Z34: 34 | AA34: =IF(AND(OR(NOT(ISNUMBER(Vertices[Size])), Vertices[Size] >= Misc!$N$2), OR(NOT(ISNUMBER(Vertices[Size])), Vertices[Size] <= Misc!$O$2),OR(NOT(ISNUMBER(Vertices[Inverse of Min to Max Tweets])), Vertices[Inverse of Min to Max Tweets] >= Misc!$N$3), OR(NOT(ISNUMBER(Vertices[Inverse of Min to Max Tweets])), Vertices[Inverse of Min to Max Tweets] <= Misc!$O$3),OR(NOT(ISNUMBER(Vertices[Size2])), Vertices[Size2] >= Misc!$N$4), OR(NOT(ISNUMBER(Vertices[Size2])), Vertices[Size2] <= Misc!$O$4),TRUE), TRUE, FALSE) -> TRUE | AC34: 4492 | AF34: =Vertices[[#This Row],[Followers]]+Vertices[[#This Row],[Inverse of Min to Max Tweets]] -> 4492 | AG34: Europe | AH34: Foundation
A35: @jwyg | C35: Circle | D35: 3.2881865 | H35: @jwyg | Z35: 35 | AA35: =IF(AND(OR(NOT(ISNUMBER(Vertices[Size])), Vertices[Size] >= Misc!$N$2), OR(NOT(ISNUMBER(Vertices[Size])), Vertices[Size] <= Misc!$O$2),OR(NOT(ISNUMBER(Vertices[Inverse of Min to Max Tweets])), Vertices[Inverse of Min to Max Tweets] >= Misc!$N$3), OR(NOT(ISNUMBER(Vertices[Inverse of Min to Max Tweets])), Vertices[Inverse of Min to Max Tweets] <= Misc!$O$3),OR(NOT(ISNUMBER(Vertices[Size2])), Vertices[Size2] >= Misc!$N$4), OR(NOT(ISNUMBER(Vertices[Size2])), Vertices[Size2] <= Misc!$O$4),TRUE), TRUE, FALSE) -> TRUE | AC35: 2344 | AF35: =Vertices[[#This Row],[Followers]]+Vertices[[#This Row],[Inverse of Min to Max Tweets]] -> 2344 | AG35: OKFN | AH35: Officer
A36: @civicdatachallenge | C36: Circle | D36: 0 | H36: @civicdatachallenge | Z36: 36 | AA36: =IF(AND(OR(NOT(ISNUMBER(Vertices[Size])), Vertices[Size] >= Misc!$N$2), OR(NOT(ISNUMBER(Vertices[Size])), Vertices[Size] <= Misc!$O$2),OR(NOT(ISNUMBER(Vertices[Inverse of Min to Max Tweets])), Vertices[Inverse of Min to Max Tweets] >= Misc!$N$3), OR(NOT(ISNUMBER(Vertices[Inverse of Min to Max Tweets])), Vertices[Inverse of Min to Max Tweets] <= Misc!$O$3),OR(NOT(ISNUMBER(Vertices[Size2])), Vertices[Size2] >= Misc!$N$4), OR(NOT(ISNUMBER(Vertices[Size2])), Vertices[Size2] <= Misc!$O$4),TRUE), TRUE, FALSE) -> TRUE | AF36: =Vertices[[#This Row],[Followers]]+Vertices[[#This Row],[Inverse of Min to Max Tweets]] -> 0 | AH36: Contest
A37: #civicdata | B37: 255, 191, 0 | C37: Label | D37: 2.5245416 | H37: #civicdata | Z37: 37 | AA37: =IF(AND(OR(NOT(ISNUMBER(Vertices[Size])), Vertices[Size] >= Misc!$N$2), OR(NOT(ISNUMBER(Vertices[Size])), Vertices[Size] <= Misc!$O$2),OR(NOT(ISNUMBER(Vertices[Inverse of Min to Max Tweets])), Vertices[Inverse of Min to Max Tweets] >= Misc!$N$3), OR(NOT(ISNUMBER(Vertices[Inverse of Min to Max Tweets])), Vertices[Inverse of Min to Max Tweets] <= Misc!$O$3),OR(NOT(ISNUMBER(Vertices[Size2])), Vertices[Size2] >= Misc!$N$4), OR(NOT(ISNUMBER(Vertices[Size2])), Vertices[Size2] <= Misc!$O$4),TRUE), TRUE, FALSE) -> TRUE | AD37: 10080 | AE37: =10000000/Vertices[[#This Row],[Minutes to max tweets]] -> 992.06349 | AF37: =Vertices[[#This Row],[Followers]]+Vertices[[#This Row],[Inverse of Min to Max Tweets]] -> 992.06349 | AH37: Tag
A38: @regardscityoens | C38: Circle | D38: 4.0839125 | H38: @regardscityoens | Z38: 38 | AA38: =IF(AND(OR(NOT(ISNUMBER(Vertices[Size])), Vertices[Size] >= Misc!$N$2), OR(NOT(ISNUMBER(Vertices[Size])), Vertices[Size] <= Misc!$O$2),OR(NOT(ISNUMBER(Vertices[Inverse of Min to Max Tweets])), Vertices[Inverse of Min to Max Tweets] >= Misc!$N$3), OR(NOT(ISNUMBER(Vertices[Inverse of Min to Max Tweets])), Vertices[Inverse of Min to Max Tweets] <= Misc!$O$3),OR(NOT(ISNUMBER(Vertices[Size2])), Vertices[Size2] >= Misc!$N$4), OR(NOT(ISNUMBER(Vertices[Size2])), Vertices[Size2] <= Misc!$O$4),TRUE), TRUE, FALSE) -> TRUE | AC38: 5742 | AF38: =Vertices[[#This Row],[Followers]]+Vertices[[#This Row],[Inverse of Min to Max Tweets]] -> 5742 | AG38: Europe, France | AH38: Citizens
A39: @TimDavies | C39: Circle | D39: 3.7071761 | H39: @TimDavies | Z39: 39 | AA39: =IF(AND(OR(NOT(ISNUMBER(Vertices[Size])), Vertices[Size] >= Misc!$N$2), OR(NOT(ISNUMBER(Vertices[Size])), Vertices[Size] <= Misc!$O$2),OR(NOT(ISNUMBER(Vertices[Inverse of Min to Max Tweets])), Vertices[Inverse of Min to Max Tweets] >= Misc!$N$3), OR(NOT(ISNUMBER(Vertices[Inverse of Min to Max Tweets])), Vertices[Inverse of Min to Max Tweets] <= Misc!$O$3),OR(NOT(ISNUMBER(Vertices[Size2])), Vertices[Size2] >= Misc!$N$4), OR(NOT(ISNUMBER(Vertices[Size2])), Vertices[Size2] <= Misc!$O$4),TRUE), TRUE, FALSE) -> TRUE | AC39: 3757 | AF39: =Vertices[[#This Row],[Followers]]+Vertices[[#This Row],[Inverse of Min to Max Tweets]] -> 3757 | AH39: Citizens
A40: @HadleyBeeman | C40: Circle | D40: 3.9310344 | H40: @HadleyBeeman | Z40: 40 | AA40: =IF(AND(OR(NOT(ISNUMBER(Vertices[Size])), Vertices[Size] >= Misc!$N$2), OR(NOT(ISNUMBER(Vertices[Size])), Vertices[Size] <= Misc!$O$2),OR(NOT(ISNUMBER(Vertices[Inverse of Min to Max Tweets])), Vertices[Inverse of Min to Max Tweets] >= Misc!$N$3), OR(NOT(ISNUMBER(Vertices[Inverse of Min to Max Tweets])), Vertices[Inverse of Min to Max Tweets] <= Misc!$O$3),OR(NOT(ISNUMBER(Vertices[Size2])), Vertices[Size2] >= Misc!$N$4), OR(NOT(ISNUMBER(Vertices[Size2])), Vertices[Size2] <= Misc!$O$4),TRUE), TRUE, FALSE) -> TRUE | AC40: 4834 | AF40: =Vertices[[#This Row],[Followers]]+Vertices[[#This Row],[Inverse of Min to Max Tweets]] -> 4834 | AG40: Europe, UK | AH40: Citizens
...

Sheet Do Not Delete
A1: This worksheet is no longer used but is retained to allow older versions of NodeXL to open workbooks created with NodeXL version 1.0.1.96 or later.
A3: Do not delete this worksheet.

Sheet Groups
B1: Visual Properties | E1: Labels | F1: Do Not Edit | H1: Graph Metrics
A2: Group | B2: Vertex Color | C2: Vertex Shape | D2: Collapsed? | E2: Label | F2: ID | G2: Collapsed Properties | H2: Vertices | I2: Unique Edges | J2: Edges With Duplicates | K2: Total Edges | L2: Self-Loops | M2: Connected Components | N2: Single-Vertex Connected Components | O2: Maximum Vertices in a Connected Component | P2: Maximum Edges in a Connected Component | Q2: Maximum Geodesic Distance (Diameter) | R2: Average Geodesic Distance | S2: Graph Density

Sheet Group Vertices
A1: Group | B1: Vertex | C1: Vertex ID

Sheet Overall Metrics
A1: Graph Metric | B1: Value | D1: Degree Bin | E1: Degree Frequency | F1: In-Degree Bin | G1: In-Degree Frequency | H1: Out-Degree Bin | I1: Out-Degree Frequency | J1: Betweenness Centrality Bin | K1: Betweenness Centrality Frequency | L1: Closeness Centrality Bin | M1: Closeness Centrality Frequency | N1: Eigenvector Centrality Bin | O1: Eigenvector Centrality Frequency | P1: PageRank Bin | Q1: PageRank Frequency | R1: Clustering Coefficient Bin | S1: Clustering Coefficient Frequency | T1: Dynamic Filter Bin | U1: Dynamic Filter Frequency | W1: Histogram Property | X1: Value
D2: =MIN(Vertices[Degree]) -> 0 | E2: =COUNTIF(Vertices[Degree], ">= " & D2) - COUNTIF(Vertices[Degree], ">=" & D3) -> 0 | F2: =MIN(Vertices[In-Degree]) -> 0 | G2: =COUNTIF(Vertices[In-Degree], ">= " & F2) - COUNTIF(Vertices[In-Degree], ">=" & F3) -> 0 | H2: =MIN(Vertices[Out-Degree]) -> 0 | I2: =COUNTIF(Vertices[Out-Degree], ">= " & H2) - COUNTIF(Vertices[Out-Degree], ">=" & H3) -> 0 | J2: =MIN(Vertices[Betweenness Centrality]) -> 0 | K2: =COUNTIF(Vertices[Betweenness Centrality], ">= " & J2) - COUNTIF(Vertices[Betweenness Centrality], ">=" & J3) -> 0 | L2: =MIN(Vertices[Closeness Centrality]) -> 0 | M2: =COUNTIF(Vertices[Closeness Centrality], ">= " & L2) - COUNTIF(Vertices[Closeness Centrality], ">=" & L3) -> 0 | N2: =MIN(Vertices[Eigenvector Centrality]) -> 0 | O2: =COUNTIF(Vertices[Eigenvector Centrality], ">= " & N2) - COUNTIF(Vertices[Eigenvector Centrality], ">=" & N3) -> 0 | P2: =MIN(Vertices[PageRank]) -> 0 | Q2: =COUNTIF(Vertices[PageRank], ">= " & P2) - COUNTIF(Vertices[PageRank], ">=" & P3) -> 0 | R2: =MIN(Vertices[Clustering Coefficient]) -> 0 | S2: =COUNTIF(Vertices[Clustering Coefficient], ">= " & R2) - COUNTIF(Vertices[Clustering Coefficient], ">=" & R3) -> 0 | T2: =MIN(INDIRECT(DynamicFilterSourceColumnRange)) -> 0 | U2: =COUNTIF(INDIRECT(DynamicFilterSourceColumnRange), ">= " & T2) - COUNTIF(INDIRECT(DynamicFilterSourceColumnRange), ">=" & T3) -> 45 | W2: Bin Divisor | X2: =ROWS(HistogramBins[Degree Bin]) - 1 -> 43
D3: =D2+($D$45-$D$2)/BinDivisor -> 0 | E3: =COUNTIF(Vertices[Degree], ">= " & D3) - COUNTIF(Vertices[Degree], ">=" & D4) -> 0 | F3: =F2+($F$45-$F$2)/BinDivisor -> 0 | G3: =COUNTIF(Vertices[In-Degree], ">= " & F3) - COUNTIF(Vertices[In-Degree], ">=" & F4) -> 0 | H3: =H2+($H$45-$H$2)/BinDivisor -> 0 | I3: =COUNTIF(Vertices[Out-Degree], ">= " & H3) - COUNTIF(Vertices[Out-Degree], ">=" & H4) -> 0 | J3: =J2+($J$45-$J$2)/BinDivisor -> 0 | K3: =COUNTIF(Vertices[Betweenness Centrality], ">= " & J3) - COUNTIF(Vertices[Betweenness Centrality], ">=" & J4) -> 0 | L3: =L2+($L$45-$L$2)/BinDivisor -> 0 | M3: =COUNTIF(Vertices[Closeness Centrality], ">= " & L3) - COUNTIF(Vertices[Closeness Centrality], ">=" & L4) -> 0 | N3: =N2+($N$45-$N$2)/BinDivisor -> 0 | O3: =COUNTIF(Vertices[Eigenvector Centrality], ">= " & N3) - COUNTIF(Vertices[Eigenvector Centrality], ">=" & N4) -> 0 | P3: =P2+($P$45-$P$2)/BinDivisor -> 0 | Q3: =COUNTIF(Vertices[PageRank], ">= " & P3) - COUNTIF(Vertices[PageRank], ">=" & P4) -> 0 | R3: =R2+($R$45-$R$2)/BinDivisor -> 0 | S3: =COUNTIF(Vertices[Clustering Coefficient], ">= " & R3) - COUNTIF(Vertices[Clustering Coefficient], ">=" & R4) -> 0 | T3: =T2+($T$45-$T$2)/BinDivisor -> 10978.419 | U3: =COUNTIF(INDIRECT(DynamicFilterSourceColumnRange), ">= " & T3) - COUNTIF(INDIRECT(DynamicFilterSourceColumnRange), ">=" & T4) -> 8 | W3: No Metric Message | X3: Not Available
D4: =D3+($D$45-$D$2)/BinDivisor -> 0 | E4: =COUNTIF(Vertices[Degree], ">= " & D4) - COUNTIF(Vertices[Degree], ">=" & D5) -> 0 | F4: =F3+($F$45-$F$2)/BinDivisor -> 0 | G4: =COUNTIF(Vertices[In-Degree], ">= " & F4) - COUNTIF(Vertices[In-Degree], ">=" & F5) -> 0 | H4: =H3+($H$45-$H$2)/BinDivisor -> 0 | I4: =COUNTIF(Vertices[Out-Degree], ">= " & H4) - COUNTIF(Vertices[Out-Degree], ">=" & H5) -> 0 | J4: =J3+($J$45-$J$2)/BinDivisor -> 0 | K4: =COUNTIF(Vertices[Betweenness Centrality], ">= " & J4) - COUNTIF(Vertices[Betweenness Centrality], ">=" & J5) -> 0 | L4: =L3+($L$45-$L$2)/BinDivisor -> 0 | M4: =COUNTIF(Vertices[Closeness Centrality], ">= " & L4) - COUNTIF(Vertices[Closeness Centrality], ">=" & L5) -> 0 | N4: =N3+($N$45-$N$2)/BinDivisor -> 0 | O4: =COUNTIF(Vertices[Eigenvector Centrality], ">= " & N4) - COUNTIF(Vertices[Eigenvector Centrality], ">=" & N5) -> 0 | P4: =P3+($P$45-$P$2)/BinDivisor -> 0 | Q4: =COUNTIF(Vertices[PageRank], ">= " & P4) - COUNTIF(Vertices[PageRank], ">=" & P5) -> 0 | R4: =R3+($R$45-$R$2)/BinDivisor -> 0 | S4: =COUNTIF(Vertices[Clustering Coefficient], ">= " & R4) - COUNTIF(Vertices[Clustering Coefficient], ">=" & R5) -> 0 | T4: =T3+($T$45-$T$2)/BinDivisor -> 21956.837 | U4: =COUNTIF(INDIRECT(DynamicFilterSourceColumnRange), ">= " & T4) - COUNTIF(INDIRECT(DynamicFilterSourceColumnRange), ">=" & T5) -> 3 | W4: Dynamic Filter Source Column Range | X4: Vertices[Size2]
D5: =D4+($D$45-$D$2)/BinDivisor -> 0 | E5: =COUNTIF(Vertices[Degree], ">= " & D5) - COUNTIF(Vertices[Degree], ">=" & D6) -> 0 | F5: =F4+($F$45-$F$2)/BinDivisor -> 0 | G5: =COUNTIF(Vertices[In-Degree], ">= " & F5) - COUNTIF(Vertices[In-Degree], ">=" & F6) -> 0 | H5: =H4+($H$45-$H$2)/BinDivisor -> 0 | I5: =COUNTIF(Vertices[Out-Degree], ">= " & H5) - COUNTIF(Vertices[Out-Degree], ">=" & H6) -> 0 | J5: =J4+($J$45-$J$2)/BinDivisor -> 0 | K5: =COUNTIF(Vertices[Betweenness Centrality], ">= " & J5) - COUNTIF(Vertices[Betweenness Centrality], ">=" & J6) -> 0 | L5: =L4+($L$45-$L$2)/BinDivisor -> 0 | M5: =COUNTIF(Vertices[Closeness Centrality], ">= " & L5) - COUNTIF(Vertices[Closeness Centrality], ">=" & L6) -> 0 | N5: =N4+($N$45-$N$2)/BinDivisor -> 0 | O5: =COUNTIF(Vertices[Eigenvector Centrality], ">= " & N5) - COUNTIF(Vertices[Eigenvector Centrality], ">=" & N6) -> 0 | P5: =P4+($P$45-$P$2)/BinDivisor -> 0 | Q5: =COUNTIF(Vertices[PageRank], ">= " & P5) - COUNTIF(Vertices[PageRank], ">=" & P6) -> 0 | R5: =R4+($R$45-$R$2)/BinDivisor -> 0 | S5: =COUNTIF(Vertices[Clustering Coefficient], ">= " & R5) - COUNTIF(Vertices[Clustering Coefficient], ">=" & R6) -> 0 | T5: =T4+($T$45-$T$2)/BinDivisor -> 32935.256 | U5: =COUNTIF(INDIRECT(DynamicFilterSourceColumnRange), ">= " & T5) - COUNTIF(INDIRECT(DynamicFilterSourceColumnRange), ">=" & T6) -> 1
D6: =D5+($D$45-$D$2)/BinDivisor -> 0 | E6: =COUNTIF(Vertices[Degree], ">= " & D6) - COUNTIF(Vertices[Degree], ">=" & D7) -> 0 | F6: =F5+($F$45-$F$2)/BinDivisor -> 0 | G6: =COUNTIF(Vertices[In-Degree], ">= " & F6) - COUNTIF(Vertices[In-Degree], ">=" & F7) -> 0 | H6: =H5+($H$45-$H$2)/BinDivisor -> 0 | I6: =COUNTIF(Vertices[Out-Degree], ">= " & H6) - COUNTIF(Vertices[Out-Degree], ">=" & H7) -> 0 | J6: =J5+($J$45-$J$2)/BinDivisor -> 0 | K6: =COUNTIF(Vertices[Betweenness Centrality], ">= " & J6) - COUNTIF(Vertices[Betweenness Centrality], ">=" & J7) -> 0 | L6: =L5+($L$45-$L$2)/BinDivisor -> 0 | M6: =COUNTIF(Vertices[Closeness Centrality], ">= " & L6) - COUNTIF(Vertices[Closeness Centrality], ">=" & L7) -> 0 | N6: =N5+($N$45-$N$2)/BinDivisor -> 0 | O6: =COUNTIF(Vertices[Eigenvector Centrality], ">= " & N6) - COUNTIF(Vertices[Eigenvector Centrality], ">=" & N7) -> 0 | P6: =P5+($P$45-$P$2)/BinDivisor -> 0 | Q6: =COUNTIF(Vertices[PageRank], ">= " & P6) - COUNTIF(Vertices[PageRank], ">=" & P7) -> 0 | R6: =R5+($R$45-$R$2)/BinDivisor -> 0 | S6: =COUNTIF(Vertices[Clustering Coefficient], ">= " & R6) - COUNTIF(Vertices[Clustering Coefficient], ">=" & R7) -> 0 | T6: =T5+($T$45-$T$2)/BinDivisor -> 43913.674 | U6: =COUNTIF(INDIRECT(DynamicFilterSourceColumnRange), ">= " & T6) - COUNTIF(INDIRECT(DynamicFilterSourceColumnRange), ">=" & T7) -> 1
D7: =D6+($D$45-$D$2)/BinDivisor -> 0 | E7: =COUNTIF(Vertices[Degree], ">= " & D7) - COUNTIF(Vertices[Degree], ">=" & D8) -> 0 | F7: =F6+($F$45-$F$2)/BinDivisor -> 0 | G7: =COUNTIF(Vertices[In-Degree], ">= " & F7) - COUNTIF(Vertices[In-Degree], ">=" & F8) -> 0 | H7: =H6+($H$45-$H$2)/BinDivisor -> 0 | I7: =COUNTIF(Vertices[Out-Degree], ">= " & H7) - COUNTIF(Vertices[Out-Degree], ">=" & H8) -> 0 | J7: =J6+($J$45-$J$2)/BinDivisor -> 0 | K7: =COUNTIF(Vertices[Betweenness Centrality], ">= " & J7) - COUNTIF(Vertices[Betweenness Centrality], ">=" & J8) -> 0 | L7: =L6+($L$45-$L$2)/BinDivisor -> 0 | M7: =COUNTIF(Vertices[Closeness Centrality], ">= " & L7) - COUNTIF(Vertices[Closeness Centrality], ">=" & L8) -> 0 | N7: =N6+($N$45-$N$2)/BinDivisor -> 0 | O7: =COUNTIF(Vertices[Eigenvector Centrality], ">= " & N7) - COUNTIF(Vertices[Eigenvector Centrality], ">=" & N8) -> 0 | P7: =P6+($P$45-$P$2)/BinDivisor -> 0 | Q7: =COUNTIF(Vertices[PageRank], ">= " & P7) - COUNTIF(Vertices[PageRank], ">=" & P8) -> 0 | R7: =R6+($R$45-$R$2)/BinDivisor -> 0 | S7: =COUNTIF(Vertices[Clustering Coefficient], ">= " & R7) - COUNTIF(Vertices[Clustering Coefficient], ">=" & R8) -> 0 | T7: =T6+($T$45-$T$2)/BinDivisor -> 54892.093 | U7: =COUNTIF(INDIRECT(DynamicFilterSourceColumnRange), ">= " & T7) - COUNTIF(INDIRECT(DynamicFilterSourceColumnRange), ">=" & T8) -> 0
D8: =D7+($D$45-$D$2)/BinDivisor -> 0 | E8: =COUNTIF(Vertices[Degree], ">= " & D8) - COUNTIF(Vertices[Degree], ">=" & D9) -> 0 | F8: =F7+($F$45-$F$2)/BinDivisor -> 0 | G8: =COUNTIF(Vertices[In-Degree], ">= " & F8) - COUNTIF(Vertices[In-Degree], ">=" & F9) -> 0 | H8: =H7+($H$45-$H$2)/BinDivisor -> 0 | I8: =COUNTIF(Vertices[Out-Degree], ">= " & H8) - COUNTIF(Vertices[Out-Degree], ">=" & H9) -> 0 | J8: =J7+($J$45-$J$2)/BinDivisor -> 0 | K8: =COUNTIF(Vertices[Betweenness Centrality], ">= " & J8) - COUNTIF(Vertices[Betweenness Centrality], ">=" & J9) -> 0 | L8: =L7+($L$45-$L$2)/BinDivisor -> 0 | M8: =COUNTIF(Vertices[Closeness Centrality], ">= " & L8) - COUNTIF(Vertices[Closeness Centrality], ">=" & L9) -> 0 | N8: =N7+($N$45-$N$2)/BinDivisor -> 0 | O8: =COUNTIF(Vertices[Eigenvector Centrality], ">= " & N8) - COUNTIF(Vertices[Eigenvector Centrality], ">=" & N9) -> 0 | P8: =P7+($P$45-$P$2)/BinDivisor -> 0 | Q8: =COUNTIF(Vertices[PageRank], ">= " & P8) - COUNTIF(Vertices[PageRank], ">=" & P9) -> 0 | R8: =R7+($R$45-$R$2)/BinDivisor -> 0 | S8: =COUNTIF(Vertices[Clustering Coefficient], ">= " & R8) - COUNTIF(Vertices[Clustering Coefficient], ">=" & R9) -> 0 | T8: =T7+($T$45-$T$2)/BinDivisor -> 65870.512 | U8: =COUNTIF(INDIRECT(DynamicFilterSourceColumnRange), ">= " & T8) - COUNTIF(INDIRECT(DynamicFilterSourceColumnRange), ">=" & T9) -> 1
D9: =D8+($D$45-$D$2)/BinDivisor -> 0 | E9: =COUNTIF(Vertices[Degree], ">= " & D9) - COUNTIF(Vertices[Degree], ">=" & D10) -> 0 | F9: =F8+($F$45-$F$2)/BinDivisor -> 0 | G9: =COUNTIF(Vertices[In-Degree], ">= " & F9) - COUNTIF(Vertices[In-Degree], ">=" & F10) -> 0 | H9: =H8+($H$45-$H$2)/BinDivisor -> 0 | I9: =COUNTIF(Vertices[Out-Degree], ">= " & H9) - COUNTIF(Vertices[Out-Degree], ">=" & H10) -> 0 | J9: =J8+($J$45-$J$2)/BinDivisor -> 0 | K9: =COUNTIF(Vertices[Betweenness Centrality], ">= " & J9) - COUNTIF(Vertices[Betweenness Centrality], ">=" & J10) -> 0 | L9: =L8+($L$45-$L$2)/BinDivisor -> 0 | M9: =COUNTIF(Vertices[Closeness Centrality], ">= " & L9) - COUNTIF(Vertices[Closeness Centrality], ">=" & L10) -> 0 | N9: =N8+($N$45-$N$2)/BinDivisor -> 0 | O9: =COUNTIF(Vertices[Eigenvector Centrality], ">= " & N9) - COUNTIF(Vertices[Eigenvector Centrality], ">=" & N10) -> 0 | P9: =P8+($P$45-$P$2)/BinDivisor -> 0 | Q9: =COUNTIF(Vertices[PageRank], ">= " & P9) - COUNTIF(Vertices[PageRank], ">=" & P10) -> 0 | R9: =R8+($R$45-$R$2)/BinDivisor -> 0 | S9: =COUNTIF(Vertices[Clustering Coefficient], ">= " & R9) - COUNTIF(Vertices[Clustering Coefficient], ">=" & R10) -> 0 | T9: =T8+($T$45-$T$2)/BinDivisor -> 76848.93 | U9: =COUNTIF(INDIRECT(DynamicFilterSourceColumnRange), ">= " & T9) - COUNTIF(INDIRECT(DynamicFilterSourceColumnRange), ">=" & T10) -> 2
D10: =D9+($D$45-$D$2)/BinDivisor -> 0 | E10: =COUNTIF(Vertices[Degree], ">= " & D10) - COUNTIF(Vertices[Degree], ">=" & D11) -> 0 | F10: =F9+($F$45-$F$2)/BinDivisor -> 0 | G10: =COUNTIF(Vertices[In-Degree], ">= " & F10) - COUNTIF(Vertices[In-Degree], ">=" & F11) -> 0 | H10: =H9+($H$45-$H$2)/BinDivisor -> 0 | I10: =COUNTIF(Vertices[Out-Degree], ">= " & H10) - COUNTIF(Vertices[Out-Degree], ">=" & H11) -> 0 | J10: =J9+($J$45-$J$2)/BinDivisor -> 0 | K10: =COUNTIF(Vertices[Betweenness Centrality], ">= " & J10) - COUNTIF(Vertices[Betweenness Centrality], ">=" & J11) -> 0 | L10: =L9+($L$45-$L$2)/BinDivisor -> 0 | M10: =COUNTIF(Vertices[Closeness Centrality], ">= " & L10) - COUNTIF(Vertices[Closeness Centrality], ">=" & L11) -> 0 | N10: =N9+($N$45-$N$2)/BinDivisor -> 0 | O10: =COUNTIF(Vertices[Eigenvector Centrality], ">= " & N10) - COUNTIF(Vertices[Eigenvector Centrality], ">=" & N11) -> 0 | P10: =P9+($P$45-$P$2)/BinDivisor -> 0 | Q10: =COUNTIF(Vertices[PageRank], ">= " & P10) - COUNTIF(Vertices[PageRank], ">=" & P11) -> 0 | R10: =R9+($R$45-$R$2)/BinDivisor -> 0 | S10: =COUNTIF(Vertices[Clustering Coefficient], ">= " & R10) - COUNTIF(Vertices[Clustering Coefficient], ">=" & R11) -> 0 | T10: =T9+($T$45-$T$2)/BinDivisor -> 87827.349 | U10: =COUNTIF(INDIRECT(DynamicFilterSourceColumnRange), ">= " & T10) - COUNTIF(INDIRECT(DynamicFilterSourceColumnRange), ">=" & T11) -> 0
D11: =D10+($D$45-$D$2)/BinDivisor -> 0 | E11: =COUNTIF(Vertices[Degree], ">= " & D11) - COUNTIF(Vertices[Degree], ">=" & D12) -> 0 | F11: =F10+($F$45-$F$2)/BinDivisor -> 0 | G11: =COUNTIF(Vertices[In-Degree], ">= " & F11) - COUNTIF(Vertices[In-Degree], ">=" & F12) -> 0 | H11: =H10+($H$45-$H$2)/BinDivisor -> 0 | I11: =COUNTIF(Vertices[Out-Degree], ">= " & H11) - COUNTIF(Vertices[Out-Degree], ">=" & H12) -> 0 | J11: =J10+($J$45-$J$2)/BinDivisor -> 0 | K11: =COUNTIF(Vertices[Betweenness Centrality], ">= " & J11) - COUNTIF(Vertices[Betweenness Centrality], ">=" & J12) -> 0 | L11: =L10+($L$45-$L$2)/BinDivisor -> 0 | M11: =COUNTIF(Vertices[Closeness Centrality], ">= " & L11) - COUNTIF(Vertices[Closeness Centrality], ">=" & L12) -> 0 | N11: =N10+($N$45-$N$2)/BinDivisor -> 0 | O11: =COUNTIF(Vertices[Eigenvector Centrality], ">= " & N11) - COUNTIF(Vertices[Eigenvector Centrality], ">=" & N12) -> 0 | P11: =P10+($P$45-$P$2)/BinDivisor -> 0 | Q11: =COUNTIF(Vertices[PageRank], ">= " & P11) - COUNTIF(Vertices[PageRank], ">=" & P12) -> 0 | R11: =R10+($R$45-$R$2)/BinDivisor -> 0 | S11: =COUNTIF(Vertices[Clustering Coefficient], ">= " & R11) - COUNTIF(Vertices[Clustering Coefficient], ">=" & R12) -> 0 | T11: =T10+($T$45-$T$2)/BinDivisor -> 98805.767 | U11: =COUNTIF(INDIRECT(DynamicFilterSourceColumnRange), ">= " & T11) - COUNTIF(INDIRECT(DynamicFilterSourceColumnRange), ">=" & T12) -> 0
D12: =D11+($D$45-$D$2)/BinDivisor -> 0 | E12: =COUNTIF(Vertices[Degree], ">= " & D12) - COUNTIF(Vertices[Degree], ">=" & D13) -> 0 | F12: =F11+($F$45-$F$2)/BinDivisor -> 0 | G12: =COUNTIF(Vertices[In-Degree], ">= " & F12) - COUNTIF(Vertices[In-Degree], ">=" & F13) -> 0 | H12: =H11+($H$45-$H$2)/BinDivisor -> 0 | I12: =COUNTIF(Vertices[Out-Degree], ">= " & H12) - COUNTIF(Vertices[Out-Degree], ">=" & H13) -> 0 | J12: =J11+($J$45-$J$2)/BinDivisor -> 0 | K12: =COUNTIF(Vertices[Betweenness Centrality], ">= " & J12) - COUNTIF(Vertices[Betweenness Centrality], ">=" & J13) -> 0 | L12: =L11+($L$45-$L$2)/BinDivisor -> 0 | M12: =COUNTIF(Vertices[Closeness Centrality], ">= " & L12) - COUNTIF(Vertices[Closeness Centrality], ">=" & L13) -> 0 | N12: =N11+($N$45-$N$2)/BinDivisor -> 0 | O12: =COUNTIF(Vertices[Eigenvector Centrality], ">= " & N12) - COUNTIF(Vertices[Eigenvector Centrality], ">=" & N13) -> 0 | P12: =P11+($P$45-$P$2)/BinDivisor -> 0 | Q12: =COUNTIF(Vertices[PageRank], ">= " & P12) - COUNTIF(Vertices[PageRank], ">=" & P13) -> 0 | R12: =R11+($R$45-$R$2)/BinDivisor -> 0 | S12: =COUNTIF(Vertices[Clustering Coefficient], ">= " & R12) - COUNTIF(Vertices[Clustering Coefficient], ">=" & R13) -> 0 | T12: =T11+($T$45-$T$2)/BinDivisor -> 109784.19 | U12: =COUNTIF(INDIRECT(DynamicFilterSourceColumnRange), ">= " & T12) - COUNTIF(INDIRECT(DynamicFilterSourceColumnRange), ">=" & T13) -> 0
D13: =D12+($D$45-$D$2)/BinDivisor -> 0 | E13: =COUNTIF(Vertices[Degree], ">= " & D13) - COUNTIF(Vertices[Degree], ">=" & D14) -> 0 | F13: =F12+($F$45-$F$2)/BinDivisor -> 0 | G13: =COUNTIF(Vertices[In-Degree], ">= " & F13) - COUNTIF(Vertices[In-Degree], ">=" & F14) -> 0 | H13: =H12+($H$45-$H$2)/BinDivisor -> 0 | I13: =COUNTIF(Vertices[Out-Degree], ">= " & H13) - COUNTIF(Vertices[Out-Degree], ">=" & H14) -> 0 | J13: =J12+($J$45-$J$2)/BinDivisor -> 0 | K13: =COUNTIF(Vertices[Betweenness Centrality], ">= " & J13) - COUNTIF(Vertices[Betweenness Centrality], ">=" & J14) -> 0 | L13: =L12+($L$45-$L$2)/BinDivisor -> 0 | M13: =COUNTIF(Vertices[Closeness Centrality], ">= " & L13) - COUNTIF(Vertices[Closeness Centrality], ">=" & L14) -> 0 | N13: =N12+($N$45-$N$2)/BinDivisor -> 0 | O13: =COUNTIF(Vertices[Eigenvector Centrality], ">= " & N13) - COUNTIF(Vertices[Eigenvector Centrality], ">=" & N14) -> 0 | P13: =P12+($P$45-$P$2)/BinDivisor -> 0 | Q13: =COUNTIF(Vertices[PageRank], ">= " & P13) - COUNTIF(Vertices[PageRank], ">=" & P14) -> 0 | R13: =R12+($R$45-$R$2)/BinDivisor -> 0 | S13: =COUNTIF(Vertices[Clustering Coefficient], ">= " & R13) - COUNTIF(Vertices[Clustering Coefficient], ">=" & R14) -> 0 | T13: =T12+($T$45-$T$2)/BinDivisor -> 120762.6 | U13: =COUNTIF(INDIRECT(DynamicFilterSourceColumnRange), ">= " & T13) - COUNTIF(INDIRECT(DynamicFilterSourceColumnRange), ">=" & T14) -> 0
D14: =D13+($D$45-$D$2)/BinDivisor -> 0 | E14: =COUNTIF(Vertices[Degree], ">= " & D14) - COUNTIF(Vertices[Degree], ">=" & D15) -> 0 | F14: =F13+($F$45-$F$2)/BinDivisor -> 0 | G14: =COUNTIF(Vertices[In-Degree], ">= " & F14) - COUNTIF(Vertices[In-Degree], ">=" & F15) -> 0 | H14: =H13+($H$45-$H$2)/BinDivisor -> 0 | I14: =COUNTIF(Vertices[Out-Degree], ">= " & H14) - COUNTIF(Vertices[Out-Degree], ">=" & H15) -> 0 | J14: =J13+($J$45-$J$2)/BinDivisor -> 0 | K14: =COUNTIF(Vertices[Betweenness Centrality], ">= " & J14) - COUNTIF(Vertices[Betweenness Centrality], ">=" & J15) -> 0 | L14: =L13+($L$45-$L$2)/BinDivisor -> 0 | M14: =COUNTIF(Vertices[Closeness Centrality], ">= " & L14) - COUNTIF(Vertices[Closeness Centrality], ">=" & L15) -> 0 | N14: =N13+($N$45-$N$2)/BinDivisor -> 0 | O14: =COUNTIF(Vertices[Eigenvector Centrality], ">= " & N14) - COUNTIF(Vertices[Eigenvector Centrality], ">=" & N15) -> 0 | P14: =P13+($P$45-$P$2)/BinDivisor -> 0 | Q14: =COUNTIF(Vertices[PageRank], ">= " & P14) - COUNTIF(Vertices[PageRank], ">=" & P15) -> 0 | R14: =R13+($R$45-$R$2)/BinDivisor -> 0 | S14: =COUNTIF(Vertices[Clustering Coefficient], ">= " & R14) - COUNTIF(Vertices[Clustering Coefficient], ">=" & R15) -> 0 | T14: =T13+($T$45-$T$2)/BinDivisor -> 131741.02 | U14: =COUNTIF(INDIRECT(DynamicFilterSourceColumnRange), ">= " & T14) - COUNTIF(INDIRECT(DynamicFilterSourceColumnRange), ">=" & T15) -> 0
D15: =D14+($D$45-$D$2)/BinDivisor -> 0 | E15: =COUNTIF(Vertices[Degree], ">= " & D15) - COUNTIF(Vertices[Degree], ">=" & D16) -> 0 | F15: =F14+($F$45-$F$2)/BinDivisor -> 0 | G15: =COUNTIF(Vertices[In-Degree], ">= " & F15) - COUNTIF(Vertices[In-Degree], ">=" & F16) -> 0 | H15: =H14+($H$45-$H$2)/BinDivisor -> 0 | I15: =COUNTIF(Vertices[Out-Degree], ">= " & H15) - COUNTIF(Vertices[Out-Degree], ">=" & H16) -> 0 | J15: =J14+($J$45-$J$2)/BinDivisor -> 0 | K15: =COUNTIF(Vertices[Betweenness Centrality], ">= " & J15) - COUNTIF(Vertices[Betweenness Centrality], ">=" & J16) -> 0 | L15: =L14+($L$45-$L$2)/BinDivisor -> 0 | M15: =COUNTIF(Vertices[Closeness Centrality], ">= " & L15) - COUNTIF(Vertices[Closeness Centrality], ">=" & L16) -> 0 | N15: =N14+($N$45-$N$2)/BinDivisor -> 0 | O15: =COUNTIF(Vertices[Eigenvector Centrality], ">= " & N15) - COUNTIF(Vertices[Eigenvector Centrality], ">=" & N16) -> 0 | P15: =P14+($P$45-$P$2)/BinDivisor -> 0 | Q15: =COUNTIF(Vertices[PageRank], ">= " & P15) - COUNTIF(Vertices[PageRank], ">=" & P16) -> 0 | R15: =R14+($R$45-$R$2)/BinDivisor -> 0 | S15: =COUNTIF(Vertices[Clustering Coefficient], ">= " & R15) - COUNTIF(Vertices[Clustering Coefficient], ">=" & R16) -> 0 | T15: =T14+($T$45-$T$2)/BinDivisor -> 142719.44 | U15: =COUNTIF(INDIRECT(DynamicFilterSourceColumnRange), ">= " & T15) - COUNTIF(INDIRECT(DynamicFilterSourceColumnRange), ">=" & T16) -> 1
D16: =D15+($D$45-$D$2)/BinDivisor -> 0 | E16: =COUNTIF(Vertices[Degree], ">= " & D16) - COUNTIF(Vertices[Degree], ">=" & D17) -> 0 | F16: =F15+($F$45-$F$2)/BinDivisor -> 0 | G16: =COUNTIF(Vertices[In-Degree], ">= " & F16) - COUNTIF(Vertices[In-Degree], ">=" & F17) -> 0 | H16: =H15+($H$45-$H$2)/BinDivisor -> 0 | I16: =COUNTIF(Vertices[Out-Degree], ">= " & H16) - COUNTIF(Vertices[Out-Degree], ">=" & H17) -> 0 | J16: =J15+($J$45-$J$2)/BinDivisor -> 0 | K16: =COUNTIF(Vertices[Betweenness Centrality], ">= " & J16) - COUNTIF(Vertices[Betweenness Centrality], ">=" & J17) -> 0 | L16: =L15+($L$45-$L$2)/BinDivisor -> 0 | M16: =COUNTIF(Vertices[Closeness Centrality], ">= " & L16) - COUNTIF(Vertices[Closeness Centrality], ">=" & L17) -> 0 | N16: =N15+($N$45-$N$2)/BinDivisor -> 0 | O16: =COUNTIF(Vertices[Eigenvector Centrality], ">= " & N16) - COUNTIF(Vertices[Eigenvector Centrality], ">=" & N17) -> 0 | P16: =P15+($P$45-$P$2)/BinDivisor -> 0 | Q16: =COUNTIF(Vertices[PageRank], ">= " & P16) - COUNTIF(Vertices[PageRank], ">=" & P17) -> 0 | R16: =R15+($R$45-$R$2)/BinDivisor -> 0 | S16: =COUNTIF(Vertices[Clustering Coefficient], ">= " & R16) - COUNTIF(Vertices[Clustering Coefficient], ">=" & R17) -> 0 | T16: =T15+($T$45-$T$2)/BinDivisor -> 153697.86 | U16: =COUNTIF(INDIRECT(DynamicFilterSourceColumnRange), ">= " & T16) - COUNTIF(INDIRECT(DynamicFilterSourceColumnRange), ">=" & T17) -> 0
... D25: =D24+($D$45-$D$2)/BinDivisor -> 0 | E25: =COUNTIF(Vertices[Degree], ">= " & D25) - COUNTIF(Vertices[Degree], ">=" & D26) -> 0 | F25: =F24+($F$45-$F$2)/BinDivisor -> 0 | G25: =COUNTIF(Vertices[In-Degree], ">= " & F25) - COUNTIF(Vertices[In-Degree], ">=" & F26) -> 0 | H25: =H24+($H$45-$H$2)/BinDivisor -> 0 | I25: =COUNTIF(Vertices[Out-Degree], ">= " & H25) - COUNTIF(Vertices[Out-Degree], ">=" & H26) -> 0 | J25: =J24+($J$45-$J$2)/BinDivisor -> 0 | K25: =COUNTIF(Vertices[Betweenness Centrality], ">= " & J25) - COUNTIF(Vertices[Betweenness Centrality], ">=" & J26) -> 0 | L25: =L24+($L$45-$L$2)/BinDivisor -> 0 | M25: =COUNTIF(Vertices[Closeness Centrality], ">= " & L25) - COUNTIF(Vertices[Closeness Centrality], ">=" & L26) -> 0 | N25: =N24+($N$45-$N$2)/BinDivisor -> 0 | O25: =COUNTIF(Vertices[Eigenvector Centrality], ">= " & N25) - COUNTIF(Vertices[Eigenvector Centrality], ">=" & N26) -> 0 | P25: =P24+($P$45-$P$2)/BinDivisor -> 0 | Q25: =COUNTIF(Vertices[PageRank], ">= " & P25) - COUNTIF(Vertices[PageRank], ">=" & P26) -> 0 | R25: =R24+($R$45-$R$2)/BinDivisor -> 0 | S25: =COUNTIF(Vertices[Clustering Coefficient], ">= " & R25) - COUNTIF(Vertices[Clustering Coefficient], ">=" & R26) -> 0 | T25: =T24+($T$45-$T$2)/BinDivisor -> 252503.63 | U25: =COUNTIF(INDIRECT(DynamicFilterSourceColumnRange), ">= " & T25) - COUNTIF(INDIRECT(DynamicFilterSourceColumnRange), ">=" & T26) -> 0
A26: Readability Metric | B26: Value | D26: =D25+($D$45-$D$2)/BinDivisor -> 0 | E26: =COUNTIF(Vertices[Degree], ">= " & D26) - COUNTIF(Vertices[Degree], ">=" & D27) -> 0 | F26: =F25+($F$45-$F$2)/BinDivisor -> 0 | G26: =COUNTIF(Vertices[In-Degree], ">= " & F26) - COUNTIF(Vertices[In-Degree], ">=" & F27) -> 0 | H26: =H25+($H$45-$H$2)/BinDivisor -> 0 | I26: =COUNTIF(Vertices[Out-Degree], ">= " & H26) - COUNTIF(Vertices[Out-Degree], ">=" & H27) -> 0 | J26: =J25+($J$45-$J$2)/BinDivisor -> 0 | K26: =COUNTIF(Vertices[Betweenness Centrality], ">= " & J26) - COUNTIF(Vertices[Betweenness Centrality], ">=" & J27) -> 0 | L26: =L25+($L$45-$L$2)/BinDivisor -> 0 | M26: =COUNTIF(Vertices[Closeness Centrality], ">= " & L26) - COUNTIF(Vertices[Closeness Centrality], ">=" & L27) -> 0 | N26: =N25+($N$45-$N$2)/BinDivisor -> 0 | O26: =COUNTIF(Vertices[Eigenvector Centrality], ">= " & N26) - COUNTIF(Vertices[Eigenvector Centrality], ">=" & N27) -> 0 | P26: =P25+($P$45-$P$2)/BinDivisor -> 0 | Q26: =COUNTIF(Vertices[PageRank], ">= " & P26) - COUNTIF(Vertices[PageRank], ">=" & P27) -> 0 | R26: =R25+($R$45-$R$2)/BinDivisor -> 0 | S26: =COUNTIF(Vertices[Clustering Coefficient], ">= " & R26) - COUNTIF(Vertices[Clustering Coefficient], ">=" & R27) -> 0 | T26: =T25+($T$45-$T$2)/BinDivisor -> 263482.05 | U26: =COUNTIF(INDIRECT(DynamicFilterSourceColumnRange), ">= " & T26) - COUNTIF(INDIRECT(DynamicFilterSourceColumnRange), ">=" & T27) -> 0
D27: =D26+($D$45-$D$2)/BinDivisor -> 0 | E27: =COUNTIF(Vertices[Degree], ">= " & D27) - COUNTIF(Vertices[Degree], ">=" & D28) -> 0 | F27: =F26+($F$45-$F$2)/BinDivisor -> 0 | G27: =COUNTIF(Vertices[In-Degree], ">= " & F27) - COUNTIF(Vertices[In-Degree], ">=" & F28) -> 0 | H27: =H26+($H$45-$H$2)/BinDivisor -> 0 | I27: =COUNTIF(Vertices[Out-Degree], ">= " & H27) - COUNTIF(Vertices[Out-Degree], ">=" & H28) -> 0 | J27: =J26+($J$45-$J$2)/BinDivisor -> 0 | K27: =COUNTIF(Vertices[Betweenness Centrality], ">= " & J27) - COUNTIF(Vertices[Betweenness Centrality], ">=" & J28) -> 0 | L27: =L26+($L$45-$L$2)/BinDivisor -> 0 | M27: =COUNTIF(Vertices[Closeness Centrality], ">= " & L27) - COUNTIF(Vertices[Closeness Centrality], ">=" & L28) -> 0 | N27: =N26+($N$45-$N$2)/BinDivisor -> 0 | O27: =COUNTIF(Vertices[Eigenvector Centrality], ">= " & N27) - COUNTIF(Vertices[Eigenvector Centrality], ">=" & N28) -> 0 | P27: =P26+($P$45-$P$2)/BinDivisor -> 0 | Q27: =COUNTIF(Vertices[PageRank], ">= " & P27) - COUNTIF(Vertices[PageRank], ">=" & P28) -> 0 | R27: =R26+($R$45-$R$2)/BinDivisor -> 0 | S27: =COUNTIF(Vertices[Clustering Coefficient], ">= " & R27) - COUNTIF(Vertices[Clustering Coefficient], ">=" & R28) -> 0 | T27: =T26+($T$45-$T$2)/BinDivisor -> 274460.47 | U27: =COUNTIF(INDIRECT(DynamicFilterSourceColumnRange), ">= " & T27) - COUNTIF(INDIRECT(DynamicFilterSourceColumnRange), ">=" & T28) -> 0
D28: =D27+($D$45-$D$2)/BinDivisor -> 0 | E28: =COUNTIF(Vertices[Degree], ">= " & D28) - COUNTIF(Vertices[Degree], ">=" & D29) -> 0 | F28: =F27+($F$45-$F$2)/BinDivisor -> 0 | G28: =COUNTIF(Vertices[In-Degree], ">= " & F28) - COUNTIF(Vertices[In-Degree], ">=" & F29) -> 0 | H28: =H27+($H$45-$H$2)/BinDivisor -> 0 | I28: =COUNTIF(Vertices[Out-Degree], ">= " & H28) - COUNTIF(Vertices[Out-Degree], ">=" & H29) -> 0 | J28: =J27+($J$45-$J$2)/BinDivisor -> 0 | K28: =COUNTIF(Vertices[Betweenness Centrality], ">= " & J28) - COUNTIF(Vertices[Betweenness Centrality], ">=" & J29) -> 0 | L28: =L27+($L$45-$L$2)/BinDivisor -> 0 | M28: =COUNTIF(Vertices[Closeness Centrality], ">= " & L28) - COUNTIF(Vertices[Closeness Centrality], ">=" & L29) -> 0 | N28: =N27+($N$45-$N$2)/BinDivisor -> 0 | O28: =COUNTIF(Vertices[Eigenvector Centrality], ">= " & N28) - COUNTIF(Vertices[Eigenvector Centrality], ">=" & N29) -> 0 | P28: =P27+($P$45-$P$2)/BinDivisor -> 0 | Q28: =COUNTIF(Vertices[PageRank], ">= " & P28) - COUNTIF(Vertices[PageRank], ">=" & P29) -> 0 | R28: =R27+($R$45-$R$2)/BinDivisor -> 0 | S28: =COUNTIF(Vertices[Clustering Coefficient], ">= " & R28) - COUNTIF(Vertices[Clustering Coefficient], ">=" & R29) -> 0 | T28: =T27+($T$45-$T$2)/BinDivisor -> 285438.88 | U28: =COUNTIF(INDIRECT(DynamicFilterSourceColumnRange), ">= " & T28) - COUNTIF(INDIRECT(DynamicFilterSourceColumnRange), ">=" & T29) -> 0
