Workbook

Sheet Data
A1: Railroad Fuel Surcharges
B3: Mileage-based ($/mile) | N3: As a percent of tariff
B4: (values prior to Apr 07 are estimates for all railraods except BNSF, for which values prior to Jan 06 are estimates) | N4: (all values after April 2007 are estimates)
B5: Starting Jan-09 CP is calculated using average of bi-weekly fuel surcharge
I6: N. Amer. | J6: Weighted | K6: 3-year Monthly | U6: N. Amer. | V6: Weighted | X6: KCS
A7: Month-Year | B7: BNSF | C7: CN | D7: CP | E7: CSXT | F7: KCS | G7: NS | H7: UP | I7: Average | J7: Average | K7: Average | N7: BNSF | O7: CN | P7: CP | Q7: CSXT | R7: KCS | S7: NS | T7: UP | U7: Average | V7: Average | X7: Mexico | Y7: FerroMex
A8: 36708 | M8: 36708 | S8: 0.02 | U8: =AVERAGE(N8:T8) -> 0.02
A9: 36739 | M9: 36739 | S9: 0.02 | U9: =AVERAGE(N9:T9) -> 0.02
A10: 36770 | M10: 36770 | S10: 0.02 | U10: =AVERAGE(N10:T10) -> 0.02
A11: 36800 | M11: 36800 | S11: 0.02 | U11: =AVERAGE(N11:T11) -> 0.02
A12: 36831 | M12: 36831 | Q12: 0.02 | S12: 0.02 | U12: =AVERAGE(N12:T12) -> 0.02
A13: 36861 | M13: 36861 | Q13: 0.02 | S13: 0.02 | U13: =AVERAGE(N13:T13) -> 0.02
A14: 36892 | B14: 0.1 | C14: 0.0793 | D14: 0 | E14: 0 | F14: 0 | G14: 0 | H14: 0 | I14: =AVERAGE(B14,C14,D14,E14,F14,G14,H14) -> 0.025614286 | M14: 36892 | Q14: 0.02 | S14: 0.02 | U14: =AVERAGE(N14:T14) -> 0.02 | V14: =SUM(N14*'Annual Avg.'!$M$9,O14*'Annual Avg.'!$N$9,P14*'Annual Avg.'!$O$9,Q14*'Annual Avg.'!$P$9,R14*'Annual Avg.'!$Q$9,S14*'Annual Avg.'!$R$9,T14*'Annual Avg.'!$S$9) -> 0
A15: 36923 | B15: 0.08 | C15: 0.0671 | D15: 0 | E15: 0 | F15: 0 | G15: 0 | H15: 0 | I15: =AVERAGE(B15,C15,D15,E15,F15,G15,H15) -> 0.021014286 | M15: 36923 | Q15: 0.02 | S15: 0.02 | U15: =AVERAGE(N15:T15) -> 0.02 | V15: =SUM(N15*'Annual Avg.'!$M$9,O15*'Annual Avg.'!$N$9,P15*'Annual Avg.'!$O$9,Q15*'Annual Avg.'!$P$9,R15*'Annual Avg.'!$Q$9,S15*'Annual Avg.'!$R$9,T15*'Annual Avg.'!$S$9) -> 0
A16: 36951 | B16: 0.07 | C16: 0.061 | D16: 0 | E16: 0 | F16: 0 | G16: 0 | H16: 0 | I16: =AVERAGE(B16,C16,D16,E16,F16,G16,H16) -> 0.018714286 | M16: 36951 | Q16: 0.02 | S16: 0.02 | U16: =AVERAGE(N16:T16) -> 0.02 | V16: =SUM(N16*'Annual Avg.'!$M$9,O16*'Annual Avg.'!$N$9,P16*'Annual Avg.'!$O$9,Q16*'Annual Avg.'!$P$9,R16*'Annual Avg.'!$Q$9,S16*'Annual Avg.'!$R$9,T16*'Annual Avg.'!$S$9) -> 0
A17: 36982 | B17: 0.07 | C17: 0.0549 | D17: 0 | E17: 0 | F17: 0 | G17: 0 | H17: 0 | I17: =AVERAGE(B17,C17,D17,E17,F17,G17,H17) -> 0.017842857 | M17: 36982 | Q17: 0.02 | S17: 0.02 | U17: =AVERAGE(N17:T17) -> 0.02 | V17: =SUM(N17*'Annual Avg.'!$M$9,O17*'Annual Avg.'!$N$9,P17*'Annual Avg.'!$O$9,Q17*'Annual Avg.'!$P$9,R17*'Annual Avg.'!$Q$9,S17*'Annual Avg.'!$R$9,T17*'Annual Avg.'!$S$9) -> 0
A18: 37012 | B18: 0.04 | C18: 0.0305 | D18: 0 | E18: 0 | F18: 0 | G18: 0 | H18: 0 | I18: =AVERAGE(B18,C18,D18,E18,F18,G18,H18) -> 0.010071429 | M18: 37012 | Q18: 0.02 | S18: 0.02 | U18: =AVERAGE(N18:T18) -> 0.02 | V18: =SUM(N18*'Annual Avg.'!$M$9,O18*'Annual Avg.'!$N$9,P18*'Annual Avg.'!$O$9,Q18*'Annual Avg.'!$P$9,R18*'Annual Avg.'!$Q$9,S18*'Annual Avg.'!$R$9,T18*'Annual Avg.'!$S$9) -> 0
A19: 37043 | B19: 0.05 | C19: 0.0366 | D19: 0 | E19: 0 | F19: 0 | G19: 0 | H19: 0 | I19: =AVERAGE(B19,C19,D19,E19,F19,G19,H19) -> 0.012371429 | M19: 37043 | Q19: 0.02 | S19: 0.02 | U19: =AVERAGE(N19:T19) -> 0.02 | V19: =SUM(N19*'Annual Avg.'!$M$9,O19*'Annual Avg.'!$N$9,P19*'Annual Avg.'!$O$9,Q19*'Annual Avg.'!$P$9,R19*'Annual Avg.'!$Q$9,S19*'Annual Avg.'!$R$9,T19*'Annual Avg.'!$S$9) -> 0
A20: 37073 | B20: 0.07 | C20: 0.0549 | D20: 0 | E20: 0 | F20: 0 | G20: 0 | H20: 0 | I20: =AVERAGE(B20,C20,D20,E20,F20,G20,H20) -> 0.017842857 | M20: 37073 | Q20: 0.02 | S20: 0.02 | U20: =AVERAGE(N20:T20) -> 0.02 | V20: =SUM(N20*'Annual Avg.'!$M$9,O20*'Annual Avg.'!$N$9,P20*'Annual Avg.'!$O$9,Q20*'Annual Avg.'!$P$9,R20*'Annual Avg.'!$Q$9,S20*'Annual Avg.'!$R$9,T20*'Annual Avg.'!$S$9) -> 0
A21: 37104 | B21: 0.06 | C21: 0.0488 | D21: 0 | E21: 0 | F21: 0 | G21: 0 | H21: 0 | I21: =AVERAGE(B21,C21,D21,E21,F21,G21,H21) -> 0.015542857 | M21: 37104 | Q21: 0.02 | S21: 0.02 | U21: =AVERAGE(N21:T21) -> 0.02 | V21: =SUM(N21*'Annual Avg.'!$M$9,O21*'Annual Avg.'!$N$9,P21*'Annual Avg.'!$O$9,Q21*'Annual Avg.'!$P$9,R21*'Annual Avg.'!$Q$9,S21*'Annual Avg.'!$R$9,T21*'Annual Avg.'!$S$9) -> 0
A22: 37135 | B22: 0.04 | C22: 0.0305 | D22: 0 | E22: 0 | F22: 0 | G22: 0 | H22: 0 | I22: =AVERAGE(B22,C22,D22,E22,F22,G22,H22) -> 0.010071429 | M22: 37135 | Q22: 0.02 | S22: 0.02 | U22: =AVERAGE(N22:T22) -> 0.02 | V22: =SUM(N22*'Annual Avg.'!$M$9,O22*'Annual Avg.'!$N$9,P22*'Annual Avg.'!$O$9,Q22*'Annual Avg.'!$P$9,R22*'Annual Avg.'!$Q$9,S22*'Annual Avg.'!$R$9,T22*'Annual Avg.'!$S$9) -> 0
A23: 37165 | B23: 0.04 | C23: 0.0305 | D23: 0 | E23: 0 | F23: 0 | G23: 0 | H23: 0 | I23: =AVERAGE(B23,C23,D23,E23,F23,G23,H23) -> 0.010071429 | J23: =SUM(B23*$B$186,C23*$C$186,D23*$D$186,E23*$E$186,F23*$F$186,G23*$G$186,H23*$H$186) -> 0.0149054 | M23: 37165 | O23: 0.02 | Q23: 0.02 | S23: 0.02 | U23: =AVERAGE(N23:T23) -> 0.02 | V23: =SUM(N23*'Annual Avg.'!$M$9,O23*'Annual Avg.'!$N$9,P23*'Annual Avg.'!$O$9,Q23*'Annual Avg.'!$P$9,R23*'Annual Avg.'!$Q$9,S23*'Annual Avg.'!$R$9,T23*'Annual Avg.'!$S$9) -> 0
A24: 37196 | B24: 0.07 | C24: 0.0549 | D24: 0 | E24: 0 | F24: 0 | G24: 0 | H24: 0 | I24: =AVERAGE(B24,C24,D24,E24,F24,G24,H24) -> 0.017842857 | J24: =SUM(B24*$B$186,C24*$C$186,D24*$D$186,E24*$E$186,F24*$F$186,G24*$G$186,H24*$H$186) -> 0.02628392 | M24: 37196 | O24: 0.02 | Q24: 0 | S24: 0 | U24: =AVERAGE(N24:T24) -> 0.0066666667 | V24: =SUM(N24*'Annual Avg.'!$M$9,O24*'Annual Avg.'!$N$9,P24*'Annual Avg.'!$O$9,Q24*'Annual Avg.'!$P$9,R24*'Annual Avg.'!$Q$9,S24*'Annual Avg.'!$R$9,T24*'Annual Avg.'!$S$9) -> 0
A25: 37226 | B25: 0.03 | C25: 0.0244 | D25: 0 | E25: 0 | F25: 0 | G25: 0 | H25: 0 | I25: =AVERAGE(B25,C25,D25,E25,F25,G25,H25) -> 0.0077714286 | J25: =SUM(B25*$B$186,C25*$C$186,D25*$D$186,E25*$E$186,F25*$F$186,G25*$G$186,H25*$H$186) -> 0.01137852 | M25: 37226 | O25: 0.02 | Q25: 0 | S25: 0 | U25: =AVERAGE(N25:T25) -> 0.0066666667 | V25: =SUM(N25*'Annual Avg.'!$M$9,O25*'Annual Avg.'!$N$9,P25*'Annual Avg.'!$O$9,Q25*'Annual Avg.'!$P$9,R25*'Annual Avg.'!$Q$9,S25*'Annual Avg.'!$R$9,T25*'Annual Avg.'!$S$9) -> 0
A26: 37257 | B26: 0.01 | C26: 0.0061 | D26: 0 | E26: 0 | F26: 0 | G26: 0 | H26: 0 | I26: =AVERAGE(B26,C26,D26,E26,F26,G26,H26) -> 0.0023 | J26: =SUM(B26*$B$186,C26*$C$186,D26*$D$186,E26*$E$186,F26*$F$186,G26*$G$186,H26*$H$186) -> 0.00352688 | M26: 37257 | N26: 0 | O26: 0 | P26: 0 | Q26: 0 | S26: 0 | U26: =AVERAGE(N26:T26) -> 0 | V26: =SUM(N26*'Annual Avg.'!$M$9,O26*'Annual Avg.'!$N$9,P26*'Annual Avg.'!$O$9,Q26*'Annual Avg.'!$P$9,R26*'Annual Avg.'!$Q$9,S26*'Annual Avg.'!$R$9,T26*'Annual Avg.'!$S$9) -> 0
A27: 37288 | B27: 0 | C27: 0 | D27: 0 | E27: 0 | F27: 0 | G27: 0 | H27: 0 | I27: =AVERAGE(B27,C27,D27,E27,F27,G27,H27) -> 0 | J27: =SUM(B27*$B$186,C27*$C$186,D27*$D$186,E27*$E$186,F27*$F$186,G27*$G$186,H27*$H$186) -> 0 | M27: 37288 | N27: 0 | O27: 0 | P27: 0 | Q27: 0 | S27: 0 | U27: =AVERAGE(N27:T27) -> 0 | V27: =SUM(N27*'Annual Avg.'!$M$9,O27*'Annual Avg.'!$N$9,P27*'Annual Avg.'!$O$9,Q27*'Annual Avg.'!$P$9,R27*'Annual Avg.'!$Q$9,S27*'Annual Avg.'!$R$9,T27*'Annual Avg.'!$S$9) -> 0
A28: 37316 | B28: 0 | C28: 0 | D28: 0 | E28: 0 | F28: 0 | G28: 0 | H28: 0 | I28: =AVERAGE(B28,C28,D28,E28,F28,G28,H28) -> 0 | J28: =SUM(B28*$B$186,C28*$C$186,D28*$D$186,E28*$E$186,F28*$F$186,G28*$G$186,H28*$H$186) -> 0 | M28: 37316 | N28: 0 | O28: 0 | P28: 0 | Q28: 0 | S28: 0 | U28: =AVERAGE(N28:T28) -> 0 | V28: =SUM(N28*'Annual Avg.'!$M$9,O28*'Annual Avg.'!$N$9,P28*'Annual Avg.'!$O$9,Q28*'Annual Avg.'!$P$9,R28*'Annual Avg.'!$Q$9,S28*'Annual Avg.'!$R$9,T28*'Annual Avg.'!$S$9) -> 0
A29: 37347 | B29: 0 | C29: 0 | D29: 0 | E29: 0 | F29: 0 | G29: 0 | H29: 0 | I29: =AVERAGE(B29,C29,D29,E29,F29,G29,H29) -> 0 | J29: =SUM(B29*$B$186,C29*$C$186,D29*$D$186,E29*$E$186,F29*$F$186,G29*$G$186,H29*$H$186) -> 0 | M29: 37347 | N29: 0 | O29: 0 | P29: 0 | Q29: 0 | S29: 0 | U29: =AVERAGE(N29:T29) -> 0 | V29: =SUM(N29*'Annual Avg.'!$M$9,O29*'Annual Avg.'!$N$9,P29*'Annual Avg.'!$O$9,Q29*'Annual Avg.'!$P$9,R29*'Annual Avg.'!$Q$9,S29*'Annual Avg.'!$R$9,T29*'Annual Avg.'!$S$9) -> 0
A30: 37377 | B30: 0 | C30: 0 | D30: 0 | E30: 0 | F30: 0 | G30: 0 | H30: 0 | I30: =AVERAGE(B30,C30,D30,E30,F30,G30,H30) -> 0 | J30: =SUM(B30*$B$186,C30*$C$186,D30*$D$186,E30*$E$186,F30*$F$186,G30*$G$186,H30*$H$186) -> 0 | M30: 37377 | N30: 0 | O30: 0 | P30: 0 | Q30: 0 | S30: 0 | U30: =AVERAGE(N30:T30) -> 0 | V30: =SUM(N30*'Annual Avg.'!$M$9,O30*'Annual Avg.'!$N$9,P30*'Annual Avg.'!$O$9,Q30*'Annual Avg.'!$P$9,R30*'Annual Avg.'!$Q$9,S30*'Annual Avg.'!$R$9,T30*'Annual Avg.'!$S$9) -> 0
A31: 37408 | B31: 0.02 | C31: 0.0122 | D31: 0 | E31: 0 | F31: 0 | G31: 0 | H31: 0 | I31: =AVERAGE(B31,C31,D31,E31,F31,G31,H31) -> 0.0046 | J31: =SUM(B31*$B$186,C31*$C$186,D31*$D$186,E31*$E$186,F31*$F$186,G31*$G$186,H31*$H$186) -> 0.00705376 | M31: 37408 | N31: 0.01 | O31: 0 | P31: 0 | Q31: 0 | S31: 0 | U31: =AVERAGE(N31:T31) -> 0.002 | V31: =SUM(N31*'Annual Avg.'!$M$9,O31*'Annual Avg.'!$N$9,P31*'Annual Avg.'!$O$9,Q31*'Annual Avg.'!$P$9,R31*'Annual Avg.'!$Q$9,S31*'Annual Avg.'!$R$9,T31*'Annual Avg.'!$S$9) -> 0
A32: 37438 | B32: 0.02 | C32: 0.0122 | D32: 0 | E32: 0 | F32: 0 | G32: 0 | H32: 0 | I32: =AVERAGE(B32,C32,D32,E32,F32,G32,H32) -> 0.0046 | J32: =SUM(B32*$B$186,C32*$C$186,D32*$D$186,E32*$E$186,F32*$F$186,G32*$G$186,H32*$H$186) -> 0.00705376 | M32: 37438 | N32: 0.01 | O32: 0.02 | P32: 0 | Q32: 0 | S32: 0 | U32: =AVERAGE(N32:T32) -> 0.006 | V32: =SUM(N32*'Annual Avg.'!$M$9,O32*'Annual Avg.'!$N$9,P32*'Annual Avg.'!$O$9,Q32*'Annual Avg.'!$P$9,R32*'Annual Avg.'!$Q$9,S32*'Annual Avg.'!$R$9,T32*'Annual Avg.'!$S$9) -> 0
A33: 37469 | B33: 0.01 | C33: 0.0122 | D33: 0 | E33: 0 | F33: 0 | G33: 0 | H33: 0 | I33: =AVERAGE(B33,C33,D33,E33,F33,G33,H33) -> 0.0031714286 | J33: =SUM(B33*$B$186,C33*$C$186,D33*$D$186,E33*$E$186,F33*$F$186,G33*$G$186,H33*$H$186) -> 0.00432476 | M33: 37469 | N33: 0 | O33: 0.02 | P33: 0 | Q33: 0 | S33: 0 | U33: =AVERAGE(N33:T33) -> 0.004 | V33: =SUM(N33*'Annual Avg.'!$M$9,O33*'Annual Avg.'!$N$9,P33*'Annual Avg.'!$O$9,Q33*'Annual Avg.'!$P$9,R33*'Annual Avg.'!$Q$9,S33*'Annual Avg.'!$R$9,T33*'Annual Avg.'!$S$9) -> 0
A34: 37500 | B34: 0.02 | C34: 0.0122 | D34: 0 | E34: 0 | F34: 0 | G34: 0 | H34: 0 | I34: =AVERAGE(B34,C34,D34,E34,F34,G34,H34) -> 0.0046 | J34: =SUM(B34*$B$186,C34*$C$186,D34*$D$186,E34*$E$186,F34*$F$186,G34*$G$186,H34*$H$186) -> 0.00705376 | M34: 37500 | N34: 0 | O34: 0.02 | P34: 0 | Q34: 0 | S34: 0 | U34: =AVERAGE(N34:T34) -> 0.004 | V34: =SUM(N34*'Annual Avg.'!$M$9,O34*'Annual Avg.'!$N$9,P34*'Annual Avg.'!$O$9,Q34*'Annual Avg.'!$P$9,R34*'Annual Avg.'!$Q$9,S34*'Annual Avg.'!$R$9,T34*'Annual Avg.'!$S$9) -> 0
A35: 37530 | B35: 0.02 | C35: 0.0183 | D35: 0 | E35: 0 | F35: 0 | G35: 0 | H35: 0 | I35: =AVERAGE(B35,C35,D35,E35,F35,G35,H35) -> 0.0054714286 | J35: =SUM(B35*$B$186,C35*$C$186,D35*$D$186,E35*$E$186,F35*$F$186,G35*$G$186,H35*$H$186) -> 0.00785164 | M35: 37530 | N35: 0.01 | O35: 0.04 | P35: 0 | Q35: 0.02 | S35: 0.02 | U35: =AVERAGE(N35:T35) -> 0.018 | V35: =SUM(N35*'Annual Avg.'!$M$9,O35*'Annual Avg.'!$N$9,P35*'Annual Avg.'!$O$9,Q35*'Annual Avg.'!$P$9,R35*'Annual Avg.'!$Q$9,S35*'Annual Avg.'!$R$9,T35*'Annual Avg.'!$S$9) -> 0
A36: 37561 | B36: 0.05 | C36: 0.0366 | D36: 0 | E36: 0 | F36: 0 | G36: 0 | H36: 0 | I36: =AVERAGE(B36,C36,D36,E36,F36,G36,H36) -> 0.012371429 | J36: =SUM(B36*$B$186,C36*$C$186,D36*$D$186,E36*$E$186,F36*$F$186,G36*$G$186,H36*$H$186) -> 0.01843228 | M36: 37561 | N36: 0.02 | O36: 0.04 | P36: 0 | Q36: 0.02 | S36: 0.02 | U36: =AVERAGE(N36:T36) -> 0.02 | V36: =SUM(N36*'Annual Avg.'!$M$9,O36*'Annual Avg.'!$N$9,P36*'Annual Avg.'!$O$9,Q36*'Annual Avg.'!$P$9,R36*'Annual Avg.'!$Q$9,S36*'Annual Avg.'!$R$9,T36*'Annual Avg.'!$S$9) -> 0
A37: 37591 | B37: 0.06 | C37: 0.0488 | D37: 0 | E37: 0 | F37: 0 | G37: 0 | H37: 0 | I37: =AVERAGE(B37,C37,D37,E37,F37,G37,H37) -> 0.015542857 | J37: =SUM(B37*$B$186,C37*$C$186,D37*$D$186,E37*$E$186,F37*$F$186,G37*$G$186,H37*$H$186) -> 0.02275704 | M37: 37591 | N37: 0.025 | O37: 0.04 | P37: 0 | Q37: 0 | S37: 0 | U37: =AVERAGE(N37:T37) -> 0.013 | V37: =SUM(N37*'Annual Avg.'!$M$9,O37*'Annual Avg.'!$N$9,P37*'Annual Avg.'!$O$9,Q37*'Annual Avg.'!$P$9,R37*'Annual Avg.'!$Q$9,S37*'Annual Avg.'!$R$9,T37*'Annual Avg.'!$S$9) -> 0
A38: 37622 | B38: 0.05 | C38: 0.0366 | D38: 0 | E38: 0 | F38: 0 | G38: 0 | H38: 0 | I38: =AVERAGE(B38,C38,D38,E38,F38,G38,H38) -> 0.012371429 | J38: =SUM(B38*$B$186,C38*$C$186,D38*$D$186,E38*$E$186,F38*$F$186,G38*$G$186,H38*$H$186) -> 0.01843228 | M38: 37622 | N38: 0.02 | O38: 0.04 | P38: 0 | Q38: 0 | S38: 0 | U38: =AVERAGE(N38:T38) -> 0.012 | V38: =SUM(N38*'Annual Avg.'!$M$9,O38*'Annual Avg.'!$N$9,P38*'Annual Avg.'!$O$9,Q38*'Annual Avg.'!$P$9,R38*'Annual Avg.'!$Q$9,S38*'Annual Avg.'!$R$9,T38*'Annual Avg.'!$S$9) -> 0
A39: 37653 | B39: 0.05 | C39: 0.0366 | D39: 0 | E39: 0 | F39: 0 | G39: 0 | H39: 0 | I39: =AVERAGE(B39,C39,D39,E39,F39,G39,H39) -> 0.012371429 | J39: =SUM(B39*$B$186,C39*$C$186,D39*$D$186,E39*$E$186,F39*$F$186,G39*$G$186,H39*$H$186) -> 0.01843228 | M39: 37653 | N39: 0.02 | O39: 0.04 | P39: 0 | Q39: 0.02 | S39: 0.02 | T39: 0.02 | U39: =AVERAGE(N39:T39) -> 0.02 | V39: =SUM(N39*'Annual Avg.'!$M$9,O39*'Annual Avg.'!$N$9,P39*'Annual Avg.'!$O$9,Q39*'Annual Avg.'!$P$9,R39*'Annual Avg.'!$Q$9,S39*'Annual Avg.'!$R$9,T39*'Annual Avg.'!$S$9) -> 0
A40: 37681 | B40: 0.06 | C40: 0.0488 | D40: 0 | E40: 0 | F40: 0 | G40: 0 | H40: 0 | I40: =AVERAGE(B40,C40,D40,E40,F40,G40,H40) -> 0.015542857 | J40: =SUM(B40*$B$186,C40*$C$186,D40*$D$186,E40*$E$186,F40*$F$186,G40*$G$186,H40*$H$186) -> 0.02275704 | M40: 37681 | N40: 0.025 | O40: 0.04 | P40: 0 | Q40: 0.02 | S40: 0.02 | T40: 0.02 | U40: =AVERAGE(N40:T40) -> 0.020833333 | V40: =SUM(N40*'Annual Avg.'!$M$9,O40*'Annual Avg.'!$N$9,P40*'Annual Avg.'!$O$9,Q40*'Annual Avg.'!$P$9,R40*'Annual Avg.'!$Q$9,S40*'Annual Avg.'!$R$9,T40*'Annual Avg.'!$S$9) -> 0
A41: 37712 | B41: 0.11 | C41: 0.0854 | D41: 0 | E41: 0 | F41: 0 | G41: 0 | H41: 0 | I41: =AVERAGE(B41,C41,D41,E41,F41,G41,H41) -> 0.027914286 | J41: =SUM(B41*$B$186,C41*$C$186,D41*$D$186,E41*$E$186,F41*$F$186,G41*$G$186,H41*$H$186) -> 0.04118932 | M41: 37712 | N41: 0.045 | O41: 0.06 | P41: 0 | Q41: 0.02 | R41: 0 | S41: 0.02 | T41: 0.02 | U41: =AVERAGE(N41:T41) -> 0.023571429 | V41: =SUM(N41*'Annual Avg.'!$M$9,O41*'Annual Avg.'!$N$9,P41*'Annual Avg.'!$O$9,Q41*'Annual Avg.'!$P$9,R41*'Annual Avg.'!$Q$9,S41*'Annual Avg.'!$R$9,T41*'Annual Avg.'!$S$9) -> 0
...

Sheet New Fig. 7 Mileage-based
A1: Figure 7
A2: Railroad Fuel Surcharges, North American Weighted Average1
A23: Sources: www.bnsf.com, www.cn.ca, www.cpr.ca, www.csx.com, www.kcsi.com, www.nscorp.com, www.uprr.com
G27: Previous | H27: Percent
G28: Value | H28: Change
E29: Last month | G29: =Data!J178 -> 0.3177606 | H29: =(Data!$J$179/G29)-1 -> -0.025445384
E30: Last year | G30: =Data!J167 -> 0.3286421 | H30: =(Data!$J$179/G30)-1 -> -0.057713359
E31: 3-year average | G31: =Data!K179 -> 0.33220811 | H31: =(Data!$J$179/G31)-1 -> -0.067828105

Sheet Annual Avg.
A1: Railroad Fuel Surcharges --Annual and Quarterly Averages
B2: Mileage-based ($/mile) | M2: As a percent of tariff
I3: N. Amer. | J3: Weighted | T3: N. Amer. | U3: Weighted
B4: BNSF | C4: CN | D4: CP | E4: CSXT | F4: KCS | G4: NS | H4: UP | I4: Average | J4: Average | M4: BNSF | N4: CN | O4: CP | P4: CSXT | Q4: KCS | R4: NS | S4: UP | T4: Average | U4: Average
A5: 2003 average | B5: =AVERAGE(Data!B38:B49) -> 0.0675 | C5: =AVERAGE(Data!C38:C49) -> 0.052866667 | D5: =AVERAGE(Data!D38:D49) -> 0 | E5: =AVERAGE(Data!E38:E49) -> 0 | F5: =AVERAGE(Data!F38:F49) -> 0 | G5: =AVERAGE(Data!G38:G49) -> 0 | H5: =AVERAGE(Data!H38:H49) -> 0 | I5: =AVERAGE(Data!I38:I49) -> 0.017195238 | J5: =AVERAGE(Data!J38:J49) -> 0.02533571 | L5: 2003 average | M5: =AVERAGE(Data!N38:N49) -> 0.025 | N5: =AVERAGE(Data!O38:O49) -> 0.045 | O5: =AVERAGE(Data!P38:P49) -> 0 | P5: =AVERAGE(Data!Q38:Q49) -> 0.023666667 | Q5: =AVERAGE(Data!R38:R49) -> 0.015555556 | R5: =AVERAGE(Data!S38:S49) -> 0.018333333 | S5: =AVERAGE(Data!T38:T49) -> 0.021818182 | T5: =AVERAGE(Data!U38:U49) -> 0.021295635 | U5: =AVERAGE(Data!V38:V49) -> 0
A6: 2004 average | B6: =AVERAGE(Data!B50:B61) -> 0.12083333 | C6: =AVERAGE(Data!C50:C61) -> 0.097091667 | D6: =AVERAGE(Data!D50:D61) -> 0 | E6: =AVERAGE(Data!E50:E61) -> 0.0033333333 | F6: =AVERAGE(Data!F50:F61) -> 0 | G6: =AVERAGE(Data!G50:G61) -> 0 | H6: =AVERAGE(Data!H50:H61) -> 0 | I6: =AVERAGE(Data!I50:I61) -> 0.031608333 | J6: =AVERAGE(Data!J50:J61) -> 0.04698194 | L6: 2004 average | M6: =AVERAGE(Data!N50:N61) -> 0.047916667 | N6: =AVERAGE(Data!O50:O61) -> 0.07 | O6: =AVERAGE(Data!P50:P61) -> 0.014166667 | P6: =AVERAGE(Data!Q50:Q61) -> 0.066333333 | Q6: =AVERAGE(Data!R50:R61) -> 0.05 | R6: =AVERAGE(Data!S50:S61) -> 0.063333333 | S6: =AVERAGE(Data!T50:T61) -> 0.047916667 | T6: =AVERAGE(Data!U50:U61) -> 0.051380952 | U6: =AVERAGE(Data!V50:V61) -> 0.0078404917
A7: 2005 average | B7: =AVERAGE(Data!B62:B73) -> 0.275 | C7: =AVERAGE(Data!C62:C73) -> 0.22163333 | D7: =AVERAGE(Data!D62:D73) -> 0.03375 | E7: =AVERAGE(Data!E62:E73) -> 0.0875 | F7: =AVERAGE(Data!F62:F73) -> 0.0475 | G7: =AVERAGE(Data!G62:G73) -> 0 | H7: =AVERAGE(Data!H62:H73) -> 0.041666667 | I7: =AVERAGE(Data!I62:I73) -> 0.10100714 | J7: =AVERAGE(Data!J62:J73) -> 0.13555042 | L7: 2005 average | M7: =AVERAGE(Data!N62:N73) -> 0.11 | N7: =AVERAGE(Data!O62:O73) -> 0.10216667 | O7: =AVERAGE(Data!P62:P73) -> 0.075 | P7: =AVERAGE(Data!Q62:Q73) -> 0.127 | Q7: =AVERAGE(Data!R62:R73) -> 0.12833333 | R7: =AVERAGE(Data!S62:S73) -> 0.127 | S7: =AVERAGE(Data!T62:T73) -> 0.11 | T7: =AVERAGE(Data!U62:U73) -> 0.11135714 | U7: =AVERAGE(Data!V62:V73) -> 0.10783595
A8: 2006 average | B8: =AVERAGE(Data!B74:B85) -> 0.36583333 | C8: =AVERAGE(Data!C74:C85) -> 0.29635833 | D8: =AVERAGE(Data!D74:D85) -> 0.095833333 | E8: =AVERAGE(Data!E74:E85) -> 0.17833333 | F8: =AVERAGE(Data!F74:F85) -> 0.1425 | G8: =AVERAGE(Data!G74:G85) -> 0 | H8: =AVERAGE(Data!H74:H85) -> 0.1225 | I8: =AVERAGE(Data!I74:I85) -> 0.17162262 | J8: =AVERAGE(Data!J74:J85) -> 0.21025894 | L8: 2006 average | M8: =AVERAGE(Data!N74:N85) -> 0.14625 | N8: =AVERAGE(Data!O74:O85) -> 0.11541667 | O8: =AVERAGE(Data!P74:P85) -> 0.10625 | P8: =AVERAGE(Data!Q74:Q85) -> 0.17266667 | Q8: =AVERAGE(Data!R74:R85) -> 0.17266667 | R8: =AVERAGE(Data!S74:S85) -> 0.17141667 | S8: =AVERAGE(Data!T74:T85) -> 0.14625 | T8: =AVERAGE(Data!U74:U85) -> 0.14727381 | U8: =AVERAGE(Data!V74:V85) -> 0.14204544
A9: 2007 average | B9: =AVERAGE(Data!B86:B97) -> 0.37916667 | C9: =AVERAGE(Data!C86:C97) -> 0.30805 | D9: =AVERAGE(Data!D86:D97) -> 0.11310833 | E9: =AVERAGE(Data!E86:E97) -> 0.19166667 | F9: =AVERAGE(Data!F86:F97) -> 0.15833333 | G9: =AVERAGE(Data!G86:G97) -> 0 | H9: =AVERAGE(Data!H86:H97) -> 0.135 | I9: =AVERAGE(Data!I86:I97) -> 0.18361786 | J9: =AVERAGE(Data!J86:J97) -> 0.22603214
A10: 2008 average | B10: =AVERAGE(Data!B98:B109) -> 0.67416667 | C10: =AVERAGE(Data!C98:C109) -> 0.38711667 | D10: =AVERAGE(Data!D98:D109) -> 0.35125 | E10: =AVERAGE(Data!E98:E109) -> 0.48583333 | F10: =AVERAGE(Data!F98:F109) -> 0.4525 | G10: =AVERAGE(Data!G98:G109) -> 0 | H10: =AVERAGE(Data!H98:H109) -> 0.37 | I10: =AVERAGE(Data!I98:I109) -> 0.38869524 | J10: =AVERAGE(Data!J98:J109) -> 0.44258422
A11: 2009 average | B11: =AVERAGE(Data!B110:B121) -> 0.30416667 | C11: =AVERAGE(Data!C110:C121) -> 0.037391667 | D11: =AVERAGE(Data!D110:D121) -> 0.047083333 | E11: =AVERAGE(Data!E110:E121) -> 0.11583333 | F11: =AVERAGE(Data!F110:F121) -> 0.073333333 | G11: =AVERAGE(Data!G110:G121) -> 0 | H11: =AVERAGE(Data!H110:H121) -> 0.0625 | I11: =AVERAGE(Data!I110:I121) -> 0.091472619 | J11: =AVERAGE(Data!J110:J121) -> 0.13806469
A12: 2010 average | B12: =AVERAGE(Data!B122:B133) -> 0.4225 | C12: =AVERAGE(Data!C122:C133) -> 0.12173333 | D12: =AVERAGE(Data!D122:D133) -> 0.14791667 | E12: =AVERAGE(Data!E122:E133) -> 0.23333333 | F12: =AVERAGE(Data!F122:F133) -> 0.20083333 | G12: =AVERAGE(Data!G122:G133) -> 0 | H12: =AVERAGE(Data!H122:H133) -> 0.16833333 | I12: =AVERAGE(Data!I122:I133) -> 0.18495 | J12: =AVERAGE(Data!J122:J133) -> 0.22899912
A13: 2011 average | B13: =AVERAGE(Data!B134:B145) -> 0.365 | C13: =AVERAGE(Data!C134:C145) -> 0.27650833 | D13: =AVERAGE(Data!D134:D145) -> 0.320625 | E13: =AVERAGE(Data!E134:E145) -> 0.43583333 | F13: =AVERAGE(Data!F134:F145) -> 0.40333333 | G13: =AVERAGE(Data!G134:G145) -> 0 | H13: =AVERAGE(Data!H134:H145) -> 0.32916667 | I13: =AVERAGE(Data!I134:I145) -> 0.30435238 | J13: =AVERAGE(Data!J134:J145) -> 0.3098255
A14: 2012 average | B14: =AVERAGE(Data!B146:B157) -> 0.37 | C14: =AVERAGE(Data!C146:C157) -> 0.32106667 | D14: =AVERAGE(Data!D146:D157) -> 0.35791667 | E14: =AVERAGE(Data!E146:E157) -> 0.495 | F14: =AVERAGE(Data!F146:F157) -> 0.46 | G14: =AVERAGE(Data!G146:G157) -> 0 | H14: =AVERAGE(Data!H146:H157) -> 0.3775 | I14: =AVERAGE(Data!I146:I157) -> 0.3402119 | J14: =AVERAGE(Data!J146:J157) -> 0.3378274
A15: 2013 average | B15: =AVERAGE(Data!B158:B169) -> 0.36666667 | C15: =AVERAGE(Data!C158:C169) -> 0.31771667 | D15: =AVERAGE(Data!D158:D169) -> 0.35291667 | E15: =AVERAGE(Data!E158:E169) -> 0.49166667 | F15: =AVERAGE(Data!F158:F169) -> 0.45666667 | G15: =AVERAGE(Data!G158:G169) -> 0 | H15: =AVERAGE(Data!H158:H169) -> 0.375 | I15: =AVERAGE(Data!I158:I169) -> 0.33723333 | J15: =AVERAGE(Data!J158:J169) -> 0.33183764
B18: Wt. Avg.
B19: Fuel Surcharge
B20: by Quarter
A21: 4Q01 | B21: =AVERAGE(Data!J23:J25) -> 0.017522613
A22: 1Q02 | B22: =AVERAGE(Data!J26:J28) -> 0.0011756267
A23: 2Q02 | B23: =AVERAGE(Data!J29:J31) -> 0.0023512533
A24: 3Q02 | B24: =AVERAGE(Data!J32:J34) -> 0.0061440933
A25: 4Q02 | B25: =AVERAGE(Data!J35:J37) -> 0.016346987
A26: 1Q03 | B26: =AVERAGE(Data!J38:J40) -> 0.019873867
A27: 2Q03 | B27: =AVERAGE(Data!J41:J43) -> 0.038838067
A28: 3Q03 | B28: =AVERAGE(Data!J44:J46) -> 0.019873867
A29: 4Q03 | B29: =AVERAGE(Data!J47:J49) -> 0.02275704
A30: 1Q04 | B30: =AVERAGE(Data!J50:J52) -> 0.027118747
A31: 2Q04 | B31: =AVERAGE(Data!J53:J55) -> 0.0396724
A32: 3Q04 | B32: =AVERAGE(Data!J56:J58) -> 0.048892
A33: 4Q04 | B33: =AVERAGE(Data!J59:J61) -> 0.072244613
A34: 1Q05 | B34: =AVERAGE(Data!J62:J64) -> 0.0843656
A35: 2Q05 | B35: =AVERAGE(Data!J65:J67) -> 0.10378125
A36: 3Q05 | B36: =AVERAGE(Data!J68:J70) -> 0.12319318
A37: 4Q05 | B37: =AVERAGE(Data!J71:J73) -> 0.23086166
A38: 1Q06 | B38: =AVERAGE(Data!J74:J76) -> 0.17080444
A39: 2Q06 | B39: =AVERAGE(Data!J77:J79) -> 0.18803015
A40: 3Q06 | B40: =AVERAGE(Data!J80:J82) -> 0.2541334
A41: 4Q06 | B41: =AVERAGE(Data!J83:J85) -> 0.22806778
A42: 1Q07 | B42: =AVERAGE(Data!J86:J88) -> 0.18482817
...

Sheet WTI vs. HDF
A1: Comparison of On-Highway Diesel Fuel Prices (HDF)
A2: with Oklahoma West Texas Intermediate Oil Prices (WTI)
A3: (average of daily WTI as published in the Wall Street Journal)
A4: The January fuel price determines the March surcharge--there is a 2-month lag.
F6: Fuel surcharge ($/railcar mile)
B8: HDF | C8: WTI
A9: Month--Year | B9: $/gal. | C9: $/bbl.
A10: 36526 | B10: 1.356 | C10: 27.26
A11: 36557 | B11: 1.461 | C11: 29.37
A12: 36586 | B12: 1.479 | C12: 29.84
A13: 36617 | B13: 1.422 | C13: 25.72
A14: 36647 | B14: 1.42 | C14: 28.79
A15: 36678 | B15: 1.421 | C15: 31.82
A16: 36708 | B16: 1.434 | C16: 29.7
A17: 36739 | B17: 1.466 | C17: 31.26
A18: 36770 | B18: 1.637 | C18: 33.88
A19: 36800 | B19: 1.637 | C19: 33.11
A20: 36831 | B20: 1.621 | C20: 34.42
A21: 36861 | B21: 1.565 | C21: 28.44
... A182: 41760 | B182: 3.943 | C182: 102
A183: 41791
A184: 41821
A185: 41852
A186: 41883
A187: 41913
A188: 41944
A189: 41974
