Workbook

Sheet Application
B3: IIE - LATIN AMERICA
B4: Intern Program Application
B5: Scholarship Division
B8: The Institute of International Education (IIE), office for Latin American in Mexico City, seeks candidates for an internship program in the scholarship division. This program is open to students from U.S. universities who have either recently graduated (with an undergraduate degree), or are enrolled in a graduate program.
B10: IIE administers scholarship programs funded by the Cargill, ExxonMobil, Rolex, and the Rockefeller Foundation, as well as with NYU Abu Dhabi. No specific field of study is required.
B12: Responsibilities include assistance in promotional activities, communication with universities, communication with Mexican students, responding to requests for information, management of on-line applications and CRM databases.
B14: IIE offers a stipend of US$500.00 per month to help defray living expenses. Interns should be prepared to complement this amount with other sources of funding. IIE will help complete paperwork necessary for students to earn academic credit for their internship, but it is the responsibility of each intern to fully investigate the institutional requirements for credit.
B16: For more information about the Institute of International Education, please visit: www.iie.org
B17: Period Requested
B19: Fall | F19: Year:
B20: Spring
B21: Summer | G21: Expected dates of internship: | N21: Closing date:
B23: Personal Information
B25: Name:
B27: Date of birth: | F27: Email: | M27: Telephone:
B29: College Address:
B31: Permanent Address:
B32: Emergency Contact Information
B34: Name:
B36: Relationship: | O36: Telephone:
B38: Address:
B39: Education
B41: Undergraduate:
B43: College/University:
B45: Current Grade Level:
B47: Expected graduated date:
B49: Cumulative Grade Point Average:
B51: Major:
B53: Minor:
B55: Graduate:
B57: College/University:
B59: Current Grade Level:
... B68: Spanish Language Ability
C70: Excellent | E70: Very good | H70: Fair | J70: Poor
B71: Reading
B73: Writing
B75: Speaking
B76: Work experience
B78: 1. Position Title | M78: Dates:
B80: Office/Institution
...

Sheet Data
A1: fall | B1: spring | C1: summer | D1: Year | E1: expected_date | F1: closing_date | G1: name | H1: birth | I1: emal | J1: telephone | K1: college_address | L1: permanent_address | M1: e_name | N1: e_relationship | O1: e_telephone | P1: e_address | Q1: u_college | R1: u_grade | S1: u_graduate | T1: u_gpa | U1: u_major | V1: u_minor | W1: g_college | X1: g_grade | Y1: g_graduate | Z1: g_gpa | AA1: g_major | AB1: g_minor | AC1: r_excellent | AD1: r_verygood | AE1: r_fair | AF1: r_poor | AG1: w_excellent | AH1: w_verygood | AI1: w_fair | AJ1: w_poor | AK1: s_excellent | AL1: s_verygood | AM1: s_fair | AN1: s_poor | AO1: w_1_position | AP1: w_1_date | AQ1: w_1_office | AR1: w_1_responsibilities | AS1: w_2_position | AT1: w_2_date | AU1: w_2_office | AV1: w_2_responsibilities | AW1: w_location_1 | AX1: w_date_1 | AY1: w_purpose_1 | AZ1: w_location_2 | BA1: w_date_2 | BB1: w_purpose_2 | BC1: w_location_3 | BD1: w_date_3 | BE1: w_purpose_3 | BF1: e_microsoft_windows | BG1: vg_microsoft_windows | BH1: f_microsoft_windows | BI1: p_microsoft_windows | BJ1: e_databases | BK1: vg_databases | BL1: f_databases | BM1: p_databases | BN1: e_web | BO1: vg_web | BP1: f_web | BQ1: p_web | BR1: e_culture | BS1: vg_culture | BT1: f_culture | BU1: p_culture | BV1: e_speaking | BW1: vg_speaking | BX1: f_speaking | BY1: p_speaking | BZ1: termns_name | CA1: termns_date
A2: =Application!C19 -> 0 | B2: =Application!C20 -> 0 | C2: =Application!C21 -> 0 | D2: =Application!H19 -> 0 | E2: =Application!H21 -> 0 | F2: =Application!O21 -> 0 | G2: =Application!C25 -> 0 | H2: =Application!C27 -> 0 | I2: =Application!G27 -> 0 | J2: =Application!Q27 -> 0 | K2: =Application!R29 -> 0 | L2: =Application!C31 -> 0 | M2: =Application!C34 -> 0 | N2: =Application!C36 -> 0 | O2: =Application!P36 -> 0 | P2: =Application!C38 -> 0 | Q2: =Application!C43 -> 0 | R2: =Application!C45 -> 0 | S2: =Application!C47 -> 0 | T2: =Application!C49 -> 0 | U2: =Application!C51 -> 0 | V2: =Application!C53 -> 0 | W2: =Application!C57 -> 0 | X2: =Application!C59 -> 0 | Y2: =Application!C61 -> 0 | Z2: =Application!C63 -> 0 | AA2: =Application!C65 -> 0 | AB2: =Application!C67 -> 0 | AC2: =Application!C71 -> 0 | AD2: =Application!E71 -> 0 | AE2: =Application!H71 -> 0 | AF2: =Application!J71 -> 0 | AG2: =Application!C73 -> 0 | AH2: =Application!E73 -> 0 | AI2: =Application!H73 -> 0 | AJ2: =Application!J73 -> 0 | AK2: =Application!C75 -> 0 | AL2: =Application!E75 -> 0 | AM2: =Application!H75 -> 0 | AN2: =Application!J75 -> 0 | AO2: =Application!C78 -> 0 | AP2: =Application!O78 -> 0 | AQ2: =Application!C80 -> 0 | AR2: =Application!C82 -> 0 | AS2: =Application!C84 -> 0 | AT2: =Application!O84 -> 0 | AU2: =Application!C86 -> 0 | AV2: =Application!C88 -> 0 | AW2: =Application!C93 -> 0 | AX2: =Application!H93 -> 0 | AY2: =Application!J93 -> 0 | AZ2: =Application!C95 -> 0 | BA2: =Application!H95 -> 0 | BB2: =Application!J95 -> 0 | BC2: =Application!C97 -> 0 | BD2: =Application!H97 -> 0 | BE2: =Application!J97 -> 0 | BF2: =Application!H101 -> 0 | BG2: =Application!J101 -> 0 | BH2: =Application!L101 -> 0 | BI2: =Application!O101 -> 0 | BJ2: =Application!H103 -> 0 | BK2: =Application!J103 -> 0 | BL2: =Application!L103 -> 0 | BM2: =Application!O103 -> 0 | BN2: =Application!H105 -> 0 | BO2: =Application!J105 -> 0 | BP2: =Application!L105 -> 0 | BQ2: =Application!O105 -> 0 | BR2: =Application!H107 -> 0 | BS2: =Application!J107 -> 0 | BT2: =Application!L107 -> 0 | BU2: =Application!O107 -> 0 | BV2: =Application!H109 -> 0 | BW2: =Application!J109 -> 0 | BX2: =Application!L109 -> 0 | BY2: =Application!O109 -> 0 | BZ2: =Application!C131 -> 0 | CA2: =Application!Q131 -> 0
