Workbook
Name _ftn1: Instructions!$A$43
Name _ftnref1: Instructions!$A$5
Name OLE_LINK1: Instructions!#REF!
Name OLE_LINK2: Instructions!#REF!
Name Query_from_DATABRIDGE_1: 'OLD 2010 DATA - queries'!#REF!
Name Query_from_DATABRIDGE_2: 'OLD 2010 DATA - queries'!#REF!
Name Query_from_DATABRIDGE_3: 'OLD 2010 DATA - queries'!#REF!
Name Query_from_DATABRIDGE_4: 'OLD 2010 DATA - queries'!#REF!

Sheet Instructions
A1: Instructions to the User: Detailed instructions for completing the School Readiness Budget Planner are found below in a Word Document embedded in this spreadsheet. To open and view the "Guide to Using the School Readiness Budget Planner" in Word, right-click once inside the text box below, and select "Document Object," then "Open."

Sheet Budget Planner
A1: First enter the district number, then enter revenue and expenditure data in yellow-shaded cells only.
D2: Column A | F2: Column B | H2: Column C | J2: Column D
A3: District Number: (Mpls = 9999; State = 1000) | C3: 2 | D3: FY 2012 (School Year 2011-2012) | F3: FY 2013 (School Year 2012-2013) | H3: FY 2014 (School Year 2013-2014) | J3: FY 2015 (School Year 2014-2015)
A4: =VLOOKUP($C$3,'lookup name'!A2:B340,2,FALSE) -> HILL CITY PUBLIC SCHOOL DISTRICT
A5: vlookup( | F5: =VLOOKUP($C$3,'OLD DATA -lookup3_UFARS expends'!#REF!,3,FALSE) -> #REF! | H5: 0 | J5: 0
B6: fy 2010 home visiting levy limit, hidden row | H6: =VLOOKUP($C$3,'OLD DATA -lookup3_UFARS expends'!A$3:D$342,4,FALSE) -> 3545.32
A7: Revenue
A8: 1 | B8: School Readiness State Aid Entitlement | D8: =VLOOKUP($C$3,lookup1_aid_otherev_fundbal!A2:B337,2,FALSE) -> 3731.63 | E8: =+D8/D$10 -> 0.96884436 | F8: =VLOOKUP($C$3,lookup1_aid_otherev_fundbal!A2:D337,3,FALSE) -> 3247.74 | G8: =+F8/F$10 -> 1 | H8: =VLOOKUP($C$3,lookup1_aid_otherev_fundbal!A2:D337,4,FALSE) -> 5140.26 | I8: =IF(H$10>0,+H8/H$10,"0%") -> 1 | J8: =+H8 -> 5140.26 | K8: =IF(J$10>0,+J8/J$10,"0%") -> 1
A9: 2 | B9: Other Government Grants, Fees, Other Local Revenue (FY 2011 Data Source: UFARS) | D9: =VLOOKUP($C$3,lookup1_aid_otherev_fundbal!A2:G337,5,FALSE) -> 120 | E9: =+D9/D$10 -> 0.031155641 | G9: =+F9/F$10 -> 0 | I9: =IF(H$10>0,+H9/H$10,"0%") -> 0 | K9: =IF(J$10>0,+J9/J$10,"0%") -> 0
A10: 3 | B10: Total Revenue | D10: =SUM(D7:D9) -> 3851.63 | E10: =+D10/D$10 -> 1 | F10: =SUM(F7:F9) -> 3247.74 | G10: =+F10/F$10 -> 1 | H10: =SUM(H7:H9) -> 5140.26 | I10: =IF(H$10>0,+H10/H$10,"0%") -> 1 | J10: =SUM(J7:J9) -> 5140.26 | K10: =IF(J$10>0,+J10/J$10,"0%") -> 1
A11: 4 | B11: Total Expenditures (FY 2011 Data Source: UFARS) | D11: =VLOOKUP($C$3,lookup2_expenditures!A2:G339,2,FALSE) -> 5315.13
A12: 5 | B12: Difference, Revenue - Expenditures | D12: =+D10-D11 -> -1463.5 | F12: =+F10-F11 -> 3247.74 | H12: =+H10-H11 -> 5140.26 | J12: =+J10-J11 -> 5140.26
A13: 6 | B13: Beginning Fund Balance | D13: =VLOOKUP($C$3,lookup1_aid_otherev_fundbal!A2:G339,6,FALSE) -> 4058.41 | F13: =+D14 -> 1459.97 | H13: =+F14 -> 4707.71 | J13: =+H14 -> 9847.97
A14: 7 | B14: Closing Fund Balance | D14: =VLOOKUP($C$3,lookup1_aid_otherev_fundbal!A2:G340,7,FALSE) -> 1459.97 | F14: =+F12+F13 -> 4707.71 | H14: =+H12+H13 -> 9847.97 | J14: =+J12+J13 -> 14988.23

Sheet Expenditure Planning Worksheet
A2: Expenditure Planning Worksheet | C2: Budget Planner - Column B | E2: Budget Planner - Column C | G2: Budget Planner - Column D
C3: FY 2013 (School Year 2012-2013) | E3: FY 2014 (School Year 2013-2014) | G3: FY 2015 (School Year 2014-2015)
A5: Expenditures by UFARS Object Code | D5: % of Total | F5: % of Total | H5: % of Total
A6: 100 Series - Salary
A7: 110 | B7: Administration (Limit = 5% of Total Revenue) | D7: =IF(C$27>0,C7/C$27,"0%") -> 0% | F7: =IF(E$27>0,E7/E$27,"0%") -> 0% | H7: =IF(G$27>0,G7/G$27,"0%") -> 0%
A8: 120 | B8: Program Coordinator | D8: =IF(C$27>0,C8/C$27,"0%") -> 0% | F8: =IF(E$27>0,E8/E$27,"0%") -> 0% | H8: =IF(G$27>0,G8/G$27,"0%") -> 0%
A9: 140 | B9: Licensed Instruction | D9: =IF(C$27>0,C9/C$27,"0%") -> 0% | F9: =IF(E$27>0,E9/E$27,"0%") -> 0% | H9: =IF(G$27>0,G9/G$27,"0%") -> 0%
A10: 141 | B10: Non-Licensed Instruction - Paraprofessionals | D10: =IF(C$27>0,C10/C$27,"0%") -> 0% | F10: =IF(E$27>0,E10/E$27,"0%") -> 0% | H10: =IF(G$27>0,G10/G$27,"0%") -> 0%
A11: 170 | B11: Non-Instructional | D11: =IF(C$27>0,C11/C$27,"0%") -> 0% | F11: =IF(E$27>0,E11/E$27,"0%") -> 0% | H11: =IF(G$27>0,G11/G$27,"0%") -> 0%
A12: All Other Salary | D12: =IF(C$27>0,C12/C$27,"0%") -> 0% | F12: =IF(E$27>0,E12/E$27,"0%") -> 0% | H12: =IF(G$27>0,G12/G$27,"0%") -> 0%
A13: Subtotal 100 Series | C13: =SUM(C7:C12) -> 0 | D13: =IF(C$27>0,C13/C$27,"0%") -> 0% | E13: =SUM(E7:E12) -> 0 | F13: =IF(E$27>0,E13/E$27,"0%") -> 0% | G13: =SUM(G7:G12) -> 0 | H13: =IF(G$27>0,G13/G$27,"0%") -> 0%
A14: 200 Series - Benefits | D14: =IF(C$27>0,C14/C$27,"0%") -> 0% | F14: =IF(E$27>0,E14/E$27,"0%") -> 0% | H14: =IF(G$27>0,G14/G$27,"0%") -> 0%
A15: 300 Series - Purchased Services
A16: 305 | B16: Contractual/Consultant Services | D16: =IF(C$27>0,C16/C$27,"0%") -> 0% | F16: =IF(E$27>0,E16/E$27,"0%") -> 0% | H16: =IF(G$27>0,G16/G$27,"0%") -> 0%
A17: 320 | B17: Telephone | D17: =IF(C$27>0,C17/C$27,"0%") -> 0% | F17: =IF(E$27>0,E17/E$27,"0%") -> 0% | H17: =IF(G$27>0,G17/G$27,"0%") -> 0%
A18: 329 | B18: Postage | D18: =IF(C$27>0,C18/C$27,"0%") -> 0% | F18: =IF(E$27>0,E18/E$27,"0%") -> 0% | H18: =IF(G$27>0,G18/G$27,"0%") -> 0%
A19: 360, 365 | B19: Transportation - Field Trips | D19: =IF(C$27>0,C19/C$27,"0%") -> 0% | F19: =IF(E$27>0,E19/E$27,"0%") -> 0% | H19: =IF(G$27>0,G19/G$27,"0%") -> 0%
A20: 366 | B20: In-state Travel Staff/Training | D20: =IF(C$27>0,C20/C$27,"0%") -> 0% | F20: =IF(E$27>0,E20/E$27,"0%") -> 0% | H20: =IF(G$27>0,G20/G$27,"0%") -> 0%
A21: 370 | B21: Equipment Leases | D21: =IF(C$27>0,C21/C$27,"0%") -> 0% | F21: =IF(E$27>0,E21/E$27,"0%") -> 0% | H21: =IF(G$27>0,G21/G$27,"0%") -> 0%
A22: All Other 300 | D22: =IF(C$27>0,C22/C$27,"0%") -> 0% | F22: =IF(E$27>0,E22/E$27,"0%") -> 0% | H22: =IF(G$27>0,G22/G$27,"0%") -> 0%
A23: Subtotal 300 Series | C23: =SUM(C16:C22) -> 0 | D23: =IF(C$27>0,C23/C$27,"0%") -> 0% | E23: =SUM(E16:E22) -> 0 | F23: =IF(E$27>0,E23/E$27,"0%") -> 0% | G23: =SUM(G16:G22) -> 0 | H23: =IF(G$27>0,G23/G$27,"0%") -> 0%
A24: 400 Series - Supplies & Materials | D24: =IF(C$27>0,C24/C$27,"0%") -> 0% | F24: =IF(E$27>0,E24/E$27,"0%") -> 0% | H24: =IF(G$27>0,G24/G$27,"0%") -> 0%
A25: 500 Series - Equipment | D25: =IF(C$27>0,C25/C$27,"0%") -> 0% | F25: =IF(E$27>0,E25/E$27,"0%") -> 0% | H25: =IF(G$27>0,G25/G$27,"0%") -> 0%
A26: 820 - Dues, Membership, Licenses & Fees | D26: =IF(C$27>0,C26/C$27,"0%") -> 0% | F26: =IF(E$27>0,E26/E$27,"0%") -> 0% | H26: =IF(G$27>0,G26/G$27,"0%") -> 0%
A27: Total Expenditures | C27: =+SUM(C13:C14)+SUM(C23:C26) -> 0 | D27: =IF(C$27>0,C27/C$27,"0%") -> 0% | E27: =+SUM(E13:E14)+SUM(E23:E26) -> 0 | F27: =IF(E$27>0,E27/E$27,"0%") -> 0% | G27: =+SUM(G13:G14)+SUM(G23:G26) -> 0 | H27: =IF(G$27>0,G27/G$27,"0%") -> 0%

Sheet Allowable Expenditures
A8: 344 | B8: SCHOOL (LEARNING) READINESS | C8: 04 | D8: 001-999 | E8: 581 Prekindergarten Programs; 582 School Readiness | F8: 110-305, 320-330, 350-366, 370, 390-391, 394-395, 398-430, 470, 490, 520-530, 555, 820

Sheet lookup name
A1: 1 | B1: 2 | M1: 13 | N1: 14 | O1: 15 | P1: 16 | Q1: 17 | R1: 18 | S1: 19 | T1: 20
A2: 1 | B2: AITKIN PUBLIC SCHOOL DISTRICT
A3: 9999 | B3: MINNEAPOLIS PUBLIC SCHOOL DIST.
A4: 2 | B4: HILL CITY PUBLIC SCHOOL DISTRICT
A5: 4 | B5: MCGREGOR PUBLIC SCHOOL DISTRICT
A6: 6 | B6: SOUTH ST. PAUL PUBLIC SCHOOL DIST.
A7: 11 | B7: ANOKA-HENNEPIN PUBLIC SCHOOL DIST.
A8: 12 | B8: CENTENNIAL PUBLIC SCHOOL DISTRICT
A9: 13 | B9: COLUMBIA HEIGHTS PUBLIC SCHOOL DIST
A10: 14 | B10: FRIDLEY PUBLIC SCHOOL DISTRICT
A11: 15 | B11: ST. FRANCIS PUBLIC SCHOOL DISTRICT
A12: 16 | B12: SPRING LAKE PARK PUBLIC SCHOOLS
A13: 22 | B13: DETROIT LAKES PUBLIC SCHOOL DIST.
... A340: 1000 | B340: STATE TOTAL

Sheet lookup1_aid_otherev_fundbal
A1: 1 | B1: 2 | C1: 3 | D1: 4 | E1: 5 | F1: 6 | G1: 7 | H1: 8 | I1: 9 | J1: 10 | K1: 11 | L1: 12 | M1: 13 | N1: 14 | O1: 15 | P1: 16 | Q1: 17 | R1: 18 | S1: 19 | T1: 20 | U1: 21 | V1: 22 | W1: 23 | X1: 24 | Y1: 25 | Z1: 26 | AA1: 27 | AB1: 28 | AC1: 29 | AD1: 30 | AE1: 31 | AF1: 32 | AG1: 33 | AH1: 34 | AI1: 35 | AJ1: 36 | AK1: 37 | AL1: 38 | AM1: 39 | AN1: 40 | AO1: 41 | AP1: 42 | AQ1: 43 | AR1: 44 | AS1: 45 | AT1: 46 | AU1: 47 | AV1: 48 | AW1: 49 | AX1: 50 | AY1: 51 | AZ1: 52 | BA1: 53 | BB1: 54 | BC1: 55 | BD1: 56 | BE1: 57 | BF1: 58 | BG1: 59 | BH1: 60 | BI1: 61 | BJ1: 62 | BK1: 63 | BL1: 64 | BM1: 65 | BN1: 66 | BO1: 67 | BP1: 68 | BQ1: 69 | BR1: =+BQ1+1 -> 70 | BS1: 71 | BT1: 72 | BU1: 73 | BV1: 74 | BW1: 75 | BX1: 76 | BY1: 77 | BZ1: 78
A2: 1 | B2: 13046.14 | C2: 15057.75 | D2: 16606.85 | E2: 48185.24 | F2: 24001.08 | G2: 21548.7 | J2: col B - #2 | K2: fy 12 entitlement adjusted for excess fund balance
A3: 9999 | B3: 769806.08 | C3: 754515.66 | D3: 769806.08 | E3: 65222.93 | F3: 23897.64 | G3: 174010.8 | J3: col C - #3 | K3: fy 13 entitlement adjusted for excess fund balance
A4: 2 | B4: 3731.63 | C4: 3247.74 | D4: 5140.26 | E4: 120 | F4: 4058.41 | G4: 1459.97 | J4: col D - #4 | K4: fy 13 entitlement, prior to adjustment for excess fund balance
A5: 4 | B5: 6191.44 | C5: 7169.38 | D5: 6191.44 | E5: 35469.3 | F5: -25143.08 | G5: -6370.4 | J5: col E - #5 | K5: fy12 other revenue from Aid Calculation Report/UFARS
A6: 6 | B6: 43366.15 | C6: 45156.39 | D6: 43366.15 | E6: 33941.71 | F6: 4732.38 | G6: 0 | J6: col F - #6 | K6: fy11 closing fund balance from Aid Calculation Report/UFARS
A7: 11 | B7: 417875.98 | C7: 420409.29 | D7: 417875.98 | E7: 710123.33 | F7: 57550.94 | G7: 191884.74 | J7: col G - #7 | K7: fy12 closing fund balance from Aid Calculation Report/UFARS
A8: 12 | B8: 50870.25 | C8: 50668.67 | D8: 50870.25 | E8: 23279.62 | F8: -740.87 | G8: 4976.03
A9: 13 | B9: 61851.25 | C9: 63846.52 | D9: 61851.25 | E9: 83368.65 | F9: 4344.17 | G9: 16863.12
A10: 14 | B10: 42503.64 | C10: 39828.29 | D10: 42503.64 | E10: 18346.5 | F10: 20183.99 | G10: 21910.67
A11: 15 | B11: 59011.04 | C11: 59346.83 | D11: 59011.04 | E11: 0 | F11: 10534.28 | G11: 6292.4
A12: 16 | B12: 66518.97 | C12: 69129.74 | D12: 66518.97 | E12: 5977.24 | F12: 1699.26 | G12: 1143.64
A13: 22 | B13: 36847.07 | C13: 33211.75 | D13: 36847.07 | E13: 44489 | F13: 8725.6 | G13: 7813.86
A14: 23 | B14: 12094.15 | C14: 13263.55 | D14: 13808.45 | E14: 19427.5 | F14: 6913.38 | G14: 4467.84
A15: 25 | B15: 2185.41 | C15: 1977.01 | D15: 2185.41 | E15: 0 | F15: 0 | G15: 0
A16: 31 | B16: 69261.58 | C16: 86444.72 | D16: 87096.85 | E16: 0 | F16: 54738.32 | G16: 25034.3
A17: 32 | B17: 7271.89 | C17: 4912.24 | D17: 10682.84 | E17: 0 | F17: 10396.05 | G17: 12038.05
A18: 36 | B18: 3931.13 | C18: 4128 | D18: 3931.13 | E18: 0 | F18: 242.84 | G18: 243.57
A19: 38 | B19: 35127.18 | C19: 32875.24 | D19: 35127.18 | E19: 0 | F19: -0.01 | G19: -0.01
... A338: 1000 | B338: 9958393.1 | C338: 9966123.4 | D338: 10095000 | E338: 13031454 | F338: 1345804.3 | G338: 1038325.3
B340: =COUNTIF(B2:B337,">0") -> 330 | C340: =COUNTIF(C2:C337,">0") -> 326 | D340: =COUNTIF(D2:D337,">0") -> 333

Sheet lookup2_expenditures
A1: 1 | B1: 2 | C1: 3 | E1: col B - #2 | F1: FY 2012 School Readiness Expenditures: Program 582 and any Finance code except 321, 325, 218; Finance 344 and any Program code except 582.
A2: 1 | B2: 63683.33
A3: 9999 | B3: 684754.88
A4: 2 | B4: 5315.13
A5: 4 | B5: 22886.84
A6: 6 | B6: 82118.93
A7: 11 | B7: 993658.64
A8: 12 | B8: 68433.45
A9: 13 | B9: 132697.83
A10: 14 | B10: 59612.56
A11: 15 | B11: 63252.99
A12: 16 | B12: 73048.28
A13: 22 | B13: 82252.94
... A338: 1000 | B338: 23545271

Sheet Combined District Planner
A1: Enter the combined total amounts of revenue, expenditures and fund balance for all reporting districts in the yellow-shaded cells.
A2: Districts Submitting Combined Report: | D2: Column A | E2: Column B | F2: Column C | G2: Column D
A3: 1000-Cityville, 2000-Countryland, 3001-Waterplace | D3: FY 2012 (School Year 2011-2012) | E3: FY 2013 (School Year 2012-2013) | F3: FY 2014 (School Year 2013-2014) | G3: FY 2015 (School Year 2014-2015)
E5: =VLOOKUP($C$3,'OLD DATA -lookup3_UFARS expends'!#REF!,3,FALSE) -> #REF! | F5: 0 | G5: 0
B6: fy 2010 home visiting levy limit, hidden row | F6: =VLOOKUP($C$3,'OLD DATA -lookup3_UFARS expends'!A$3:D$342,4,FALSE) -> #N/A
A7: Line No.
B8: Revenue
A9: 1 | B9: School Readiness State Aid Entitlement | D9: 0 | E9: 0 | F9: 0 | G9: 0
A10: 2 | B10: Other Government Grants, Fees, Other Local Revenue | D10: 0 | E10: 0 | F10: 0 | G10: 0
A11: 3 | B11: Total Revenue = 1 + 2 | D11: =SUM(D7:D10) -> 0 | E11: =SUM(E7:E10) -> 0 | F11: =SUM(F7:F10) -> 0 | G11: =SUM(G7:G10) -> 0
A12: 4 | B12: Expenditures | D12: 0 | E12: 0 | F12: 0 | G12: 0
A13: 5 | B13: Difference, Revenue - Expenditures = 3 - 4 | D13: =+D11-D12 -> 0 | E13: =+E11-E12 -> 0 | F13: =+F11-F12 -> 0 | G13: =+G11-G12 -> 0
A14: 6 | B14: Beginning Fund Balance | D14: 0 | E14: 0 | F14: 0 | G14: 0
A15: 7 | B15: Closing Fund Balance = 5 + 6 | D15: =+D13+D14 -> 0 | E15: =+E13+E14 -> 0 | F15: =+F13+F14 -> 0 | G15: =+G13+G14 -> 0

Sheet OLD 2010 DATA - queries
A1: dat_yer | B1: dst_num | C1: dst_tye | D1: ent_bef_xfb_adj | E1: ent_adj_xfb | F1: dat_yer | G1: dst_num | H1: dst_tye | I1: ent_bef_xfb_adj | J1: ent_adj_xfb | L1: dat_yer | M1: dst_num | N1: dst_tye | O1: fun_num | P1: prg_num | Q1: fna_num | R1: obj_num | S1: tot_amt | U1: dat_yer | V1: dst_num | W1: dst_tye | X1: fun_num | Y1: prg_num | Z1: fna_num | AA1: gen_lgr_num | AB1: src_num | AC1: tot_amt | AE1: dat_yer | AF1: dst_num | AG1: dst_tye | AH1: py3_aud_clo_fub | AI1: py2_aud_clo_fub | AJ1: pyr_aud_clo_fub | AL1: dat_yer | AM1: uni_maj | AN1: uni_tye | AO1: uni_imd | AP1: uni_nam | AQ1: atv_sts
A2: 08-09 | B2: 1 | C2: 1 | D2: 19114.41 | E2: 19114.41 | F2: 09-10 | G2: 1 | H2: 1 | I2: 18839.94 | J2: 18839.94 | L2: 08-09 | M2: 139 | N2: 1 | O2: 4 | P2: 582 | Q2: 321 | R2: 899 | S2: 25 | U2: 08-09 | V2: 378 | W2: 1 | X2: 4 | Y2: 0 | Z2: 344 | AA2: 5.19 | AB2: 649 | AC2: 446.75 | AE2: 09-10 | AF2: 1 | AG2: 1 | AH2: -1999.92 | AI2: 6266.02 | AJ2: 10325.66 | AL2: 09-10 | AM2: 1 | AN2: 1 | AO2: 0 | AP2: AITKIN PUBLIC SCHOOL DISTRICT | AQ2: A
A3: 08-09 | B3: 1 | C3: 3 | D3: 815697.41 | E3: 815697.41 | F3: 09-10 | G3: 1 | H3: 3 | I3: 797880.43 | J3: 797880.43 | L3: 08-09 | M3: 282 | N3: 1 | O3: 4 | P3: 582 | Q3: 321 | R3: 899 | S3: 4033.4 | U3: 08-09 | V3: 726 | W3: 1 | X3: 4 | Y3: 0 | Z3: 344 | AA3: 5.19 | AB3: 649 | AC3: 18625.61 | AE3: 09-10 | AF3: 1 | AG3: 3 | AH3: 319151.58 | AI3: 357430.58 | AJ3: 173292.49 | AL3: 09-10 | AM3: 1 | AN3: 3 | AO3: 0 | AP3: MINNEAPOLIS PUBLIC SCHOOL DIST. | AQ3: A
A4: 08-09 | B4: 2 | C4: 1 | D4: 4653.6 | E4: 4653.6 | F4: 09-10 | G4: 2 | H4: 1 | I4: 5501.6 | J4: 5501.6 | L4: 08-09 | M4: 813 | N4: 1 | O4: 4 | P4: 582 | Q4: 321 | R4: 898 | S4: 4450 | U4: 08-09 | V4: 820 | W4: 1 | X4: 4 | Y4: 0 | Z4: 344 | AA4: 5.19 | AB4: 649 | AC4: 10366.35 | AE4: 09-10 | AF4: 2 | AG4: 1 | AH4: 999.64 | AI4: 1505.71 | AJ4: 1412.92 | AL4: 09-10 | AM4: 2 | AN4: 1 | AO4: 0 | AP4: HILL CITY PUBLIC SCHOOL DISTRICT | AQ4: A
A5: 08-09 | B5: 4 | C5: 1 | D5: 7250.74 | E5: 7250.74 | F5: 09-10 | G5: 4 | H5: 1 | I5: 7248.85 | J5: 7248.85 | L5: 08-09 | M5: 1 | N5: 3 | O5: 4 | P5: 582 | Q5: 599 | R5: 895 | S5: 2885.38 | U5: 08-09 | V5: 914 | W5: 1 | X5: 4 | Y5: 0 | Z5: 344 | AA5: 5.19 | AB5: 649 | AC5: 3306 | AE5: 09-10 | AF5: 4 | AG5: 1 | AH5: -361.05 | AI5: -8770.7 | AJ5: -18451.43 | AL5: 09-10 | AM5: 4 | AN5: 1 | AO5: 0 | AP5: MCGREGOR PUBLIC SCHOOL DISTRICT | AQ5: A
A6: 08-09 | B6: 6 | C6: 3 | D6: 42830.95 | E6: 42830.95 | F6: 09-10 | G6: 6 | H6: 3 | I6: 43445.31 | J6: 43445.31 | L6: 08-09 | M6: 625 | N6: 1 | O6: 4 | P6: 582 | Q6: 599 | R6: 895 | S6: 27438.88 | U6: 08-09 | V6: 2165 | W6: 1 | X6: 4 | Y6: 0 | Z6: 344 | AA6: 5.05 | AB6: 649 | AC6: 30797.83 | AE6: 09-10 | AF6: 6 | AG6: 3 | AH6: -12719.37 | AI6: -2944.54 | AJ6: 6056.87 | AL6: 09-10 | AM6: 6 | AN6: 3 | AO6: 0 | AP6: SOUTH ST. PAUL PUBLIC SCHOOL DIST. | AQ6: A
A7: 08-09 | B7: 11 | C7: 1 | D7: 422702.88 | E7: 422702.88 | F7: 09-10 | G7: 11 | H7: 1 | I7: 418671.54 | J7: 418671.54 | L7: 08-09 | M7: 1 | N7: 3 | O7: 4 | P7: 582 | Q7: 0 | R7: 895 | S7: 1327.76 | U7: 08-09 | V7: 2172 | W7: 1 | X7: 4 | Y7: 0 | Z7: 344 | AA7: 5.19 | AB7: 649 | AC7: 20771.58 | AE7: 09-10 | AF7: 11 | AG7: 1 | AH7: 123106.65 | AI7: 179128.25 | AJ7: 177680.78 | AL7: 09-10 | AM7: 11 | AN7: 1 | AO7: 0 | AP7: ANOKA-HENNEPIN PUBLIC SCHOOL DIST. | AQ7: A
A8: 08-09 | B8: 12 | C8: 1 | D8: 50579.32 | E8: 50579.32 | F8: 09-10 | G8: 12 | H8: 1 | I8: 49509.17 | J8: 49509.17 | L8: 08-09 | M8: 4 | N8: 1 | O8: 4 | P8: 582 | Q8: 344 | R8: 820 | S8: 105 | U8: 08-09 | V8: 62 | W8: 1 | X8: 4 | Y8: 582 | Z8: 344 | AA8: 5.19 | AB8: 649 | AC8: 6898 | AE8: 09-10 | AF8: 12 | AG8: 1 | AH8: 3783.26 | AI8: 27709.69 | AJ8: 21904.54 | AL8: 09-10 | AM8: 12 | AN8: 1 | AO8: 0 | AP8: CENTENNIAL PUBLIC SCHOOL DISTRICT | AQ8: A
A9: 08-09 | B9: 13 | C9: 1 | D9: 59011.91 | E9: 59011.91 | F9: 09-10 | G9: 13 | H9: 1 | I9: 60006.04 | J9: 60006.04 | L9: 08-09 | M9: 6 | N9: 3 | O9: 4 | P9: 582 | Q9: 344 | R9: 820 | S9: 47.5 | U9: 08-09 | V9: 84 | W9: 1 | X9: 4 | Y9: 582 | Z9: 344 | AA9: 5.19 | AB9: 649 | AC9: 16902.17 | AE9: 09-10 | AF9: 13 | AG9: 1 | AH9: 7792.64 | AI9: 22377.82 | AJ9: 23924.96 | AL9: 09-10 | AM9: 13 | AN9: 1 | AO9: 0 | AP9: COLUMBIA HEIGHTS PUBLIC SCHOOL DIST | AQ9: A
A10: 08-09 | B10: 14 | C10: 1 | D10: 39647.39 | E10: 39647.39 | F10: 09-10 | G10: 14 | H10: 1 | I10: 41669.95 | J10: 41669.95 | L10: 08-09 | M10: 11 | N10: 1 | O10: 4 | P10: 582 | Q10: 344 | R10: 820 | S10: 316.67 | U10: 08-09 | V10: 95 | W10: 1 | X10: 4 | Y10: 582 | Z10: 344 | AA10: 5.19 | AB10: 649 | AC10: 18563.48 | AE10: 09-10 | AF10: 14 | AG10: 1 | AH10: 8674.32 | AI10: 6898 | AJ10: 8619.51 | AL10: 09-10 | AM10: 14 | AN10: 1 | AO10: 0 | AP10: FRIDLEY PUBLIC SCHOOL DISTRICT | AQ10: A
A11: 08-09 | B11: 15 | C11: 1 | D11: 59047.8 | E11: 59047.8 | F11: 09-10 | G11: 15 | H11: 1 | I11: 60370.89 | J11: 60370.89 | L11: 08-09 | M11: 14 | N11: 1 | O11: 4 | P11: 582 | Q11: 344 | R11: 820 | S11: 47.5 | U11: 08-09 | V11: 272 | W11: 1 | X11: 4 | Y11: 582 | Z11: 344 | AA11: 5.19 | AB11: 649 | AC11: 162840.86 | AE11: 09-10 | AF11: 15 | AG11: 1 | AH11: 11161.95 | AI11: 10580.5 | AJ11: 10468.91 | AL11: 09-10 | AM11: 15 | AN11: 1 | AO11: 0 | AP11: ST. FRANCIS PUBLIC SCHOOL DISTRICT | AQ11: A
A12: 08-09 | B12: 16 | C12: 1 | D12: 63728.86 | E12: 63728.86 | F12: 09-10 | G12: 16 | H12: 1 | I12: 62806.33 | J12: 62806.33 | L12: 08-09 | M12: 129 | N12: 1 | O12: 4 | P12: 582 | Q12: 344 | R12: 820 | S12: 12690 | U12: 08-09 | V12: 362 | W12: 1 | X12: 4 | Y12: 582 | Z12: 344 | AA12: 5.19 | AB12: 649 | AC12: 56782.16 | AE12: 09-10 | AF12: 16 | AG12: 1 | AH12: 6247.34 | AI12: 7374.98 | AJ12: 9437.64 | AL12: 09-10 | AM12: 16 | AN12: 1 | AO12: 0 | AP12: SPRING LAKE PARK PUBLIC SCHOOLS | AQ12: A
A13: 08-09 | B13: 22 | C13: 1 | D13: 35584.37 | E13: 35584.37 | F13: 09-10 | G13: 22 | H13: 1 | I13: 34865.56 | J13: 34865.56 | L13: 08-09 | M13: 241 | N13: 1 | O13: 4 | P13: 582 | Q13: 344 | R13: 820 | S13: 298.31 | U13: 08-09 | V13: 363 | W13: 1 | X13: 4 | Y13: 582 | Z13: 344 | AA13: 5.19 | AB13: 649 | AC13: 61905.15 | AE13: 09-10 | AF13: 22 | AG13: 1 | AH13: 12286.85 | AI13: 6550.15 | AJ13: 5427.59 | AL13: 09-10 | AM13: 22 | AN13: 1 | AO13: 0 | AP13: DETROIT LAKES PUBLIC SCHOOL DIST. | AQ13: A
... A336: 08-09 | B336: 2897 | C336: 1 | D336: 18152.54 | E336: 18152.54 | F336: 09-10 | G336: 2904 | H336: 1 | I336: 13119.87 | J336: 13119.87 | L336: 08-09 | M336: 11 | N336: 1 | O336: 4 | P336: 582 | Q336: 344 | R336: 401 | S336: 50152.6 | U336: 08-09 | V336: 2190 | W336: 1 | X336: 4 | Y336: 582 | Z336: 344 | AA336: 5.05 | AB336: 300 | AC336: 14240.22 | AE336: 09-10 | AF336: 2904 | AG336: 1 | AH336: -21787.19 | AI336: -41794.57 | AJ336: -62928.95 | AL336: 09-10 | AM336: 2902 | AN336: 1 | AO336: 0 | AP336: RTR PUBLIC SCHOOLS | AQ336: A
A337: 08-09 | B337: 2898 | C337: 1 | D337: 8493.36 | E337: 8493.36 | I337: =SUBTOTAL(109,I2:I336) -> 10095000 | J337: =SUBTOTAL(109,J2:J336) -> 10014781 | L337: 08-09 | M337: 12 | N337: 1 | O337: 4 | P337: 582 | Q337: 344 | R337: 401 | S337: 45.02 | U337: 08-09 | V337: 2198 | W337: 1 | X337: 4 | Y337: 582 | Z337: 344 | AA337: 5.19 | AB337: 300 | AC337: 7317.54 | AL337: 09-10 | AM337: 2903 | AN337: 1 | AO337: 0 | AP337: ORTONVILLE PUBLIC SCHOOLS | AQ337: A
A338: 08-09 | B338: 2899 | C338: 1 | D338: 12908.02 | E338: 12908.02 | L338: 08-09 | M338: 13 | N338: 1 | O338: 4 | P338: 582 | Q338: 344 | R338: 401 | S338: 504.46 | U338: 08-09 | V338: 2215 | W338: 1 | X338: 4 | Y338: 582 | Z338: 344 | AA338: 5.19 | AB338: 300 | AC338: 5071.86 | AL338: 09-10 | AM338: 2904 | AN338: 1 | AO338: 0 | AP338: TRACY AREA PUBLIC SCHOOL DISTRICT | AQ338: A
A339: 08-09 | B339: 2902 | C339: 1 | D339: 6309.34 | E339: 6309.34 | L339: 08-09 | M339: 16 | N339: 1 | O339: 4 | P339: 582 | Q339: 344 | R339: 401 | S339: 144.85 | U339: 08-09 | V339: 2310 | W339: 1 | X339: 4 | Y339: 582 | Z339: 344 | AA339: 5.19 | AB339: 300 | AC339: 18674.72
D340: =SUBTOTAL(109,D2:D339) -> 10095000 | E340: =SUBTOTAL(109,E2:E339) -> 10028275 | L340: 08-09 | M340: 84 | N340: 1 | O340: 4 | P340: 582 | Q340: 344 | R340: 401 | S340: 585.16 | U340: 08-09 | V340: 2311 | W340: 1 | X340: 4 | Y340: 582 | Z340: 344 | AA340: 5.19 | AB340: 300 | AC340: 7570.83
L341: 08-09 | M341: 93 | N341: 1 | O341: 4 | P341: 582 | Q341: 344 | R341: 401 | S341: 796.07 | U341: 08-09 | V341: 2342 | W341: 1 | X341: 4 | Y341: 582 | Z341: 344 | AA341: 5.19 | AB341: 300 | AC341: 11385.5
D342: ent_bef_xfb_adj | E342: ent_adj_xfb | L342: 08-09 | M342: 94 | N342: 1 | O342: 4 | P342: 582 | Q342: 344 | R342: 401 | S342: 1580.18 | U342: 08-09 | V342: 2358 | W342: 1 | X342: 4 | Y342: 582 | Z342: 344 | AA342: 5.19 | AB342: 300 | AC342: 3364.28
B343: 2903 | D343: 7139.46 | E343: 6433.32 | L343: 08-09 | M343: 95 | N343: 1 | O343: 4 | P343: 582 | Q343: 344 | R343: 401 | S343: 341.61 | U343: 08-09 | V343: 2364 | W343: 1 | X343: 4 | Y343: 582 | Z343: 344 | AA343: 5.05 | AB343: 300 | AC343: 9800.55
B344: 2904 | D344: 12044.06 | E344: 12044.06 | L344: 08-09 | M344: 110 | N344: 1 | O344: 4 | P344: 582 | Q344: 344 | R344: 401 | S344: 472.95 | U344: 08-09 | V344: 2365 | W344: 1 | X344: 4 | Y344: 582 | Z344: 344 | AA344: 5.19 | AB344: 300 | AC344: 12519.18
D345: ent_bef_xfb_adj | I345: ent_adj_xfb | L345: 08-09 | M345: 112 | N345: 1 | O345: 4 | P345: 582 | Q345: 344 | R345: 401 | S345: 984.62 | U345: 08-09 | V345: 2396 | W345: 1 | X345: 4 | Y345: 582 | Z345: 344 | AA345: 5.19 | AB345: 300 | AC345: 12547.83
D346: w/ 2887 | E346: w/o 2887 | F346: 2887 alloc | H346: pct alloc | I346: 2887 alloc | J346: w/o 2887 | K346: w/ 2887 | L346: 08-09 | M346: 113 | N346: 1 | O346: 4 | P346: 582 | Q346: 344 | R346: 401 | S346: 2252.69 | U346: 08-09 | V346: 2397 | W346: 1 | X346: 4 | Y346: 582 | Z346: 344 | AA346: 5.19 | AB346: 300 | AC346: -1769
B347: 2159 | D347: 8544.86 | E347: 7136.9 | F347: =+D347-E347 -> 1407.96 | H347: =+F347/$F$350 -> 0.33465726 | I347: =+ROUND(H347*$I$350,2) -> 541.46 | J347: 7136.9 | K347: =+I347+J347 -> 7678.36 | L347: 08-09 | M347: 138 | N347: 1 | O347: 4 | P347: 582 | Q347: 344 | R347: 401 | S347: 832.89 | U347: 08-09 | V347: 2448 | W347: 1 | X347: 4 | Y347: 582 | Z347: 344 | AA347: 5.19 | AB347: 300 | AC347: 8580.01
B348: 2365 | D348: 13053.42 | E348: 12519.18 | F348: =+D348-E348 -> 534.24 | H348: =+F348/$F$350 -> 0.12698322 | I348: =+ROUND(H348*$I$350,2) -> 205.45 | J348: 12519.18 | K348: =+I348+J348 -> 12724.63 | L348: 08-09 | M348: 162 | N348: 1 | O348: 4 | P348: 582 | Q348: 344 | R348: 401 | S348: 889.04 | U348: 08-09 | V348: 2527 | W348: 1 | X348: 4 | Y348: 582 | Z348: 344 | AA348: 5.19 | AB348: 300 | AC348: 3396.54
B349: 2859 | D349: 26777.97 | E349: 24513 | F349: =+D349-E349 -> 2264.97 | H349: =+F349/$F$350 -> 0.53835951 | I349: =+ROUND(H349*$I$350,2) -> 871.04 | J349: 22983.65 | K349: =+I349+J349 -> 23854.69 | L349: 08-09 | M349: 166 | N349: 1 | O349: 4 | P349: 582 | Q349: 344 | R349: 401 | S349: 37.81 | U349: 08-09 | V349: 2534 | W349: 1 | X349: 4 | Y349: 582 | Z349: 344 | AA349: 5.19 | AB349: 300 | AC349: 10086.12
F350: =SUM(F347:F349) -> 4207.17 | H350: =+F350/$F$350 -> 1 | I350: 1617.95 | J350: =SUM(J347:J349) -> 42639.73 | K350: =SUM(K347:K349) -> 44257.68 | L350: 08-09 | M350: 181 | N350: 1 | O350: 4 | P350: 582 | Q350: 344 | R350: 401 | S350: 298.43 | U350: 08-09 | V350: 2536 | W350: 1 | X350: 4 | Y350: 582 | Z350: 344 | AA350: 5.19 | AB350: 300 | AC350: 360.99
L351: 08-09 | M351: 186 | N351: 1 | O351: 4 | P351: 582 | Q351: 344 | R351: 401 | S351: 74.63 | U351: 08-09 | V351: 2609 | W351: 1 | X351: 4 | Y351: 582 | Z351: 344 | AA351: 5.19 | AB351: 300 | AC351: 7799.14
J352: =+J350+I350 -> 44257.68 | L352: 08-09 | M352: 191 | N352: 1 | O352: 4 | P352: 582 | Q352: 344 | R352: 401 | S352: 1187.89 | U352: 08-09 | V352: 2689 | W352: 1 | X352: 4 | Y352: 582 | Z352: 344 | AA352: 5.19 | AB352: 300 | AC352: 14661.04
L353: 08-09 | M353: 192 | N353: 1 | O353: 4 | P353: 582 | Q353: 344 | R353: 401 | S353: 67.47 | U353: 08-09 | V353: 2711 | W353: 1 | X353: 4 | Y353: 582 | Z353: 344 | AA353: 5.19 | AB353: 300 | AC353: 12424.57
L354: 08-09 | M354: 194 | N354: 1 | O354: 4 | P354: 582 | Q354: 344 | R354: 401 | S354: 4000 | U354: 08-09 | V354: 2752 | W354: 1 | X354: 4 | Y354: 582 | Z354: 344 | AA354: 5.19 | AB354: 300 | AC354: 23872.57
L355: 08-09 | M355: 196 | N355: 1 | O355: 4 | P355: 582 | Q355: 344 | R355: 401 | S355: 196.02 | U355: 08-09 | V355: 2754 | W355: 1 | X355: 4 | Y355: 582 | Z355: 344 | AA355: 5.19 | AB355: 300 | AC355: 5782.99
L356: 08-09 | M356: 199 | N356: 1 | O356: 4 | P356: 582 | Q356: 344 | R356: 401 | S356: 582.92 | U356: 08-09 | V356: 2805 | W356: 1 | X356: 4 | Y356: 582 | Z356: 344 | AA356: 5.19 | AB356: 300 | AC356: 10877.39
L357: 08-09 | M357: 200 | N357: 1 | O357: 4 | P357: 582 | Q357: 344 | R357: 401 | S357: 1540.89 | U357: 08-09 | V357: 2853 | W357: 1 | X357: 4 | Y357: 582 | Z357: 344 | AA357: 5.19 | AB357: 300 | AC357: 11703.49
L358: 08-09 | M358: 204 | N358: 1 | O358: 4 | P358: 582 | Q358: 344 | R358: 401 | S358: 3848.7 | U358: 08-09 | V358: 2854 | W358: 1 | X358: 4 | Y358: 582 | Z358: 344 | AA358: 5.19 | AB358: 300 | AC358: 6591.07
L359: 08-09 | M359: 206 | N359: 1 | O359: 4 | P359: 582 | Q359: 344 | R359: 401 | S359: 1430 | U359: 08-09 | V359: 2856 | W359: 1 | X359: 4 | Y359: 582 | Z359: 344 | AA359: 5.19 | AB359: 300 | AC359: 4702.5
L360: 08-09 | M360: 207 | N360: 1 | O360: 4 | P360: 582 | Q360: 344 | R360: 401 | S360: 1848.85 | U360: 08-09 | V360: 2859 | W360: 1 | X360: 4 | Y360: 582 | Z360: 344 | AA360: 5.19 | AB360: 300 | AC360: 25533.23
L361: 08-09 | M361: 227 | N361: 1 | O361: 4 | P361: 582 | Q361: 344 | R361: 401 | S361: 1134.15 | U361: 08-09 | V361: 2884 | W361: 1 | X361: 4 | Y361: 582 | Z361: 344 | AA361: 5.19 | AB361: 300 | AC361: 7970.22
L362: 08-09 | M362: 229 | N362: 1 | O362: 4 | P362: 582 | Q362: 344 | R362: 401 | S362: 338.4 | U362: 08-09 | V362: 2887 | W362: 1 | X362: 4 | Y362: 582 | Z362: 344 | AA362: 5.19 | AB362: 300 | AC362: 1766.45
...

Sheet OLD DATA -lookup2_UFARS revenue
A1: 1 | B1: 2 | C1: 3 | D1: 4 | E1: 5 | F1: 6 | G1: 7 | H1: 8 | I1: 9 | J1: 10 | K1: 11 | L1: 12 | M1: 13 | N1: 14 | O1: 15 | P1: 16 | Q1: 17 | R1: 18 | S1: 19 | T1: 20 | U1: 21 | V1: 22 | W1: 23 | X1: 24 | Y1: 25 | Z1: 26 | AA1: 27 | AB1: 28 | AC1: 29 | AD1: 30 | AE1: 31 | AF1: 32 | AG1: 33 | AH1: 34 | AI1: 35 | AJ1: 36 | AK1: 37 | AL1: 38 | AM1: 39 | AN1: 40 | AO1: 41 | AP1: 42 | AQ1: 43 | AR1: 44 | AS1: 45 | AT1: 46 | AU1: 47 | AV1: 48 | AW1: 49 | AX1: 50 | AY1: 51 | AZ1: 52 | BA1: 53 | BB1: 54 | BC1: 55 | BD1: 56 | BE1: 57 | BF1: 58 | BG1: 59 | BH1: 60 | BI1: 61 | BJ1: 62 | BK1: 63 | BL1: 64 | BM1: 65 | BN1: 66 | BO1: 67 | BP1: 68 | BQ1: 69 | BR1: =+BQ1+1 -> 70 | BS1: 71 | BT1: 72 | BU1: 73 | BV1: 74 | BW1: 75 | BX1: 76 | BY1: 77 | BZ1: 78
A2: 1 | B2: 92433.95 | C2: 0 | D2: 0 | E2: 0
A3: 2 | B3: 617 | C3: 0 | D3: 0 | E3: 0
A4: 4 | B4: 3960 | C4: 0 | D4: 0 | E4: 0
A5: 6 | B5: 40926.96 | C5: 0 | D5: 0 | E5: 0
A6: 11 | B6: 713576.11 | C6: 0 | D6: 0 | E6: 0
A7: 12 | B7: 24263.5 | C7: 0 | D7: 0 | E7: 0
A8: 13 | B8: 14158.07 | C8: 0 | D8: 0 | E8: 0
A9: 14 | B9: 15894.5 | C9: 0 | D9: 0 | E9: 0
A10: 15 | B10: 0 | C10: 0 | D10: 0 | E10: 0
A11: 16 | B11: 12071 | C11: 0 | D11: 0 | E11: 0
A12: 22 | B12: 34358.69 | C12: 0 | D12: 0 | E12: 0
A13: 23 | B13: 17672.3 | C13: 0 | D13: 0 | E13: 0
... A338: 1000 | B338: 10071010 | C338: 85665.55 | D338: 1214811.9 | E338: 570888.66

Sheet OLD DATA -lookup3_UFARS expends
A1: 1 | B1: 2 | C1: 3 | D1: 4 | E1: 5 | F1: 6 | G1: 7 | H1: 8 | I1: 9 | J1: 10 | K1: 11 | L1: 12 | M1: 13 | N1: 14 | O1: 15 | P1: 16 | Q1: 17 | R1: 18 | BO1: 143 | BP1: 144 | BQ1: 145 | BR1: 146 | BS1: 185 | BT1: 195 | BU1: 199 | BW1: 210 | BX1: 214 | BY1: 218 | BZ1: 220 | CA1: 230 | CB1: 235 | CC1: 240 | CD1: 250 | CE1: 251 | CF1: 252 | CG1: 270 | CH1: 280 | CI1: 290 | CJ1: 291 | CK1: 295 | CL1: 299 | CQ1: 360 | CR1: 365 | CV1: 303 | CW1: 304 | CX1: 330 | CY1: 350 | CZ1: 368 | DA1: 390 | DB1: 391 | DC1: 394 | DD1: 395 | DE1: 398
A2: OBJ_NUM | B2: 110 | C2: 120 | D2: 140 | E2: 141 | F2: 170 | G2: sum_143-199 | H2: sum_200s | I2: 305 | J2: 320 | K2: 329 | L2: sum_360-365 | M2: 366 | N2: 370 | O2: sum_allother300s | P2: sum_400s | Q2: sum_500s | R2: sum_800s | BQ2: 825.52 | BR2: 246.5 | BT2: -572 | BW2: 2603.44 | BX2: 287.83 | BY2: 1612.79 | BZ2: 1529 | CA2: 134.41 | CD2: 81.2 | CG2: 224.96 | CR2: 63.95
A3: 1 | D3: 32253.36 | F3: 4282.2 | G3: 500.02 | H3: 6473.63 | L3: 63.95 | M3: 530 | O3: 0 | P3: 164.24 | Q3: 0 | R3: 0 | BW3: 332.89 | BX3: 61.51 | BY3: 195.08
A4: 2 | D4: 3545.32 | E4: 925.92 | G4: 0 | H4: 589.48 | L4: 0 | O4: 0 | P4: 302.67 | Q4: 0 | R4: 0 | BR4: 208.25 | BW4: 1142.25 | BX4: 314.42 | BY4: 637.79 | BZ4: 1406.13 | CB4: 14.88 | CC4: 37.1 | CG4: 55.1
A5: 4 | D5: 11595.18 | E5: 4628.25 | F5: 195.84 | G5: 208.25 | H5: 3607.67 | L5: 0 | M5: 118.17 | O5: 0 | P5: 433.11 | Q5: 0 | R5: 105 | BW5: 3312.53 | BX5: 2916.48 | BY5: 14.73 | BZ5: 6375.42 | CA5: 70.98 | CB5: 176.45 | CC5: 227.27 | CD5: 834.64 | CG5: 291.59 | CQ5: 182.74 | DB5: 14675.15 | DC5: 94.83 | DE5: 3.55
A6: 6 | C6: 29418.26 | E6: 11019.27 | F6: 3818.39 | G6: 0 | H6: 14220.09 | I6: 98.67 | K6: 49.83 | L6: 182.74 | M6: 134.72 | O6: 14773.53 | P6: 993.58 | Q6: 0 | R6: 47.5 | BU6: 705.29 | BW6: 61941.46 | BX6: 48259.92 | BY6: 4151.99 | CD6: 4083.16 | CL6: 40040.22 | CR6: 7825.73 | CX6: 10381.66 | CY6: 782.07 | DE6: 45724.92
A7: 11 | B7: 8685.02 | C7: 130300.91 | D7: 396584.24 | E7: 232104.56 | F7: 42592.01 | G7: 705.29 | H7: 158476.75 | I7: 29494.14 | J7: 5842.56 | K7: 5970.86 | L7: 7825.73 | M7: 1716.22 | N7: 1748.02 | O7: 56888.65 | P7: 50546.35 | Q7: 7928.48 | R7: 316.67 | BW7: 4342.84 | BX7: 948.35 | BY7: 2332.27 | CA7: 74.72 | CB7: 793 | CC7: 128.16 | CD7: 23.98
A8: 12 | C8: 15067.25 | D8: 42976.8 | E8: 2990.96 | F8: 10844.44 | G8: 0 | H8: 8643.32 | I8: 80 | L8: 0 | O8: 0 | P8: 45.02 | Q8: 0 | R8: 0 | CK8: 14406.23
A9: 13 | C9: 1000 | D9: 40242.95 | E9: 12435.32 | F9: 746.23 | G9: 0 | H9: 14406.23 | I9: 1574.33 | K9: 351.5 | L9: 0 | M9: 246.27 | O9: 0 | P9: 619.33 | Q9: 0 | R9: 0 | BW9: 2944.14 | BX9: 1476.6 | BY9: 854.58 | BZ9: 7236.6 | CD9: 503.92 | CG9: 272.68
A10: 14 | C10: 16849.15 | D10: 15536.7 | E10: 7713.51 | G10: 0 | H10: 13288.52 | K10: 21.9 | L10: 0 | M10: 80 | O10: 0 | P10: 283.1 | Q10: 0 | R10: 47.5 | BS10: 8043.35 | BW10: 1255.38 | BX10: 897.78 | BY10: 236.91 | BZ10: 1961.73 | CA10: 42.35 | CB10: 178.77 | CC10: 30.59 | CD10: 100 | CE10: 100 | CR10: 19001.1
A11: 15 | C11: 4561.46 | F11: 5510.39 | G11: 8043.35 | H11: 4803.51 | I11: 17240 | L11: 19001.1 | O11: 0 | P11: 0 | Q11: 0 | R11: 0 | BW11: 4330.24 | BX11: 1970.23 | BY11: 1547.98 | BZ11: 2230.96 | CA11: 30.42 | CB11: 211.12 | CC11: 15.31 | CD11: 190.06 | CE11: 570.03
A12: 16 | D12: 13846.11 | E12: 18176.29 | F12: 26700.1 | G12: 0 | H12: 11096.35 | I12: 3493.5 | L12: 0 | M12: 280 | O12: 0 | P12: 144.85 | Q12: 0 | R12: 0 | BT12: 1589.18 | BW12: 3966.01 | BX12: 952.82 | BY12: 2097.12 | BZ12: 1222.75 | CA12: 12.08 | CD12: 28.5 | CE12: 55.71 | CG12: 238.19 | CK12: 610.16 | DE12: 6659.44
A13: 22 | B13: 1700.79 | D13: 35393.75 | E13: 11955.45 | F13: 3884.26 | G13: 1589.18 | H13: 9183.34 | K13: 47.89 | L13: 0 | M13: 314.18 | O13: 6659.44 | P13: 337.34 | Q13: 0 | R13: 0 | BW13: 1750.52 | BX13: 540.11 | BY13: 818.64 | CA13: 5.22 | CC13: 2.47 | CD13: 8.76
A14: 23 | B14: 528.6 | D14: 14356 | F14: 8141.4 | G14: 0 | H14: 3125.72 | L14: 0 | M14: 307.34 | O14: 0 | P14: 0 | Q14: 0 | R14: 0 | BW14: 125.28 | BY14: 90 | BZ14: 189.64 | CA14: 6 | CB14: 2.64 | CC14: 9.12
A15: 25 | D15: 1637.28 | G15: 0 | H15: 422.68 | L15: 0 | O15: 0 | P15: 0 | Q15: 0 | R15: 0 | BW15: 3097.18 | BX15: 244 | BY15: 2565.12 | BZ15: 6387.12 | CB15: 1188 | CD15: 1600.08 | CG15: 505
A16: 31 | B16: 3305 | D16: 46639 | G16: 0 | H16: 15586.5 | I16: 1830.87 | L16: 0 | O16: 0 | P16: 0 | Q16: 0 | R16: 0 | BW16: 496.82 | BY16: 299.28 | CD16: 148.08
A17: 32 | D17: 6491.99 | G17: 0 | H17: 944.18 | L17: 0 | O17: 0 | P17: 55.14 | Q17: 0 | R17: 0 | BW17: 298.56 | BY17: 214.56 | BZ17: 317.23
A18: 36 | D18: 3615.4 | G18: 0 | H18: 830.35 | L18: 0 | O18: 0 | P18: 0 | Q18: 0 | R18: 0 | BT18: -229.18 | BW18: 1940.9 | BX18: 596.77 | BY18: 900.96 | BZ18: 6290 | CA18: 162.37 | CB18: 276.64 | CC18: 97.91 | CD18: 493
A19: 38 | D19: 16379.53 | E19: 8990.99 | G19: -229.18 | H19: 10758.55 | L19: 0 | M19: 122.55 | O19: 0 | P19: 562.25 | Q19: 0 | R19: 0 | BP19: 14027.27 | BQ19: 5886.72 | BW19: 5936.57 | BX19: 1287.8 | BY19: 3331.95 | BZ19: 1000 | CA19: 32.45 | CC19: 44.59 | CD19: 942.62 | CE19: 4394.52 | CK19: 573.48
A20: 47 | C20: 3500 | D20: 50619.33 | F20: 6000 | G20: 19913.99 | H20: 17543.98 | I20: 770.45 | J20: 250 | K20: 268.99 | L20: 0 | M20: 90.09 | O20: 0 | P20: 1448.26 | Q20: 0 | R20: 0 | BW20: 1216.03 | BY20: 905.84 | BZ20: 3036.3 | CA20: 52.64 | CB20: 160.79 | CC20: 70.76 | CD20: 134.88
A21: 51 | D21: 16568.16 | G21: 0 | H21: 5577.24 | L21: 0 | O21: 0 | P21: 0 | Q21: 0 | R21: 0 | BW21: 299.18 | BX21: 11.06 | BY21: 191.42 | BZ21: 84.99 | CC21: 7.17 | CD21: 2.85
A22: 75 | C22: 250 | D22: 3174.88 | E22: 653.97 | G22: 0 | H22: 596.67 | L22: 0 | O22: 0 | P22: 1070 | Q22: 0 | R22: 0 | BW22: 6566.61 | BX22: 3181.15 | BY22: 2048.49 | CD22: 354.01 | CK22: 429.19 | CQ22: 37686
A23: 77 | D23: 38406.29 | E23: 45559.09 | F23: 1871.68 | G23: 0 | H23: 12579.45 | I23: 150 | L23: 37686 | M23: 1063.15 | O23: 0 | P23: 12652.08 | Q23: 160.2 | R23: 0 | BW23: 210.8 | BY23: 142.12 | BZ23: 638.94
A24: 81 | D24: 2584.69 | F24: 178.1 | G24: 0 | H24: 991.86 | L24: 0 | O24: 0 | P24: 266.6 | Q24: 0 | R24: 0 | BW24: 2520.2 | BX24: 581.73 | BY24: 1330.79 | CA24: 2.95 | CC24: 47.22 | CD24: 11.94 | CK24: 81.61 | CQ24: 4937.88
A25: 84 | B25: 900 | D25: 23267.32 | E25: 8778.5 | G25: 0 | H25: 4576.44 | I25: 460 | L25: 4937.88 | O25: 0 | P25: 846.19 | Q25: 0 | R25: 0 | BW25: 316.6 | BY25: 20.79 | BZ25: 64.16 | CA25: 0.28 | CD25: 3.4
A26: 85 | D26: 4163.25 | G26: 0 | H26: 405.23 | L26: 0 | O26: 0 | P26: 0 | Q26: 0 | R26: 0 | BW26: 2644.13 | BX26: 891.15 | BY26: 1163.77 | CG26: 212 | CQ26: 6528.54
A27: 88 | D27: 21159.06 | E27: 13404.24 | G27: 0 | H27: 4911.05 | I27: 90 | L27: 6528.54 | M27: 326.23 | O27: 0 | P27: 2861.46 | Q27: 0 | R27: 0 | BQ27: 154 | BW27: 1650.73 | BX27: 470.8 | BY27: 789.28 | CG27: 150 | DE27: -2139
A28: 91 | C28: 2500.04 | D28: 11695.5 | E28: 7228.13 | G28: 154 | H28: 3060.81 | K28: 50 | L28: 0 | O28: -2139 | P28: 624.79 | Q28: 0 | R28: 0 | BW28: 2093.57 | BX28: 468.54 | BY28: 1102.56 | DC28: 225
A29: 93 | C29: 3794.8 | D29: 15893.2 | E29: 7320.77 | G29: 0 | H29: 3664.67 | L29: 0 | M29: 1277.97 | O29: 225 | P29: 796.07 | Q29: 0 | R29: 0 | BW29: 2590.4 | BX29: 1831.39 | BY29: 349.21 | CQ29: 561.63
A30: 94 | C30: 770.58 | D30: 5578.62 | E30: 26151.98 | F30: 1360.54 | G30: 0 | H30: 4771 | L30: 561.63 | M30: 82 | N30: 3368.64 | O30: 0 | P30: 1580.18 | Q30: 0 | R30: 0 | BW30: 1587.03 | BX30: 479.18 | BY30: 745.18 | CA30: 76.96
A31: 95 | D31: 12588.24 | F31: 7198.39 | G31: 0 | H31: 2888.35 | L31: 0 | O31: 0 | P31: 341.61 | Q31: 0 | R31: 0 | BQ31: 45 | BR31: 157.5 | BT31: 26.51 | BW31: 1527.3 | BX31: 336.85 | BY31: 832.77 | CA31: 80.19 | CB31: 125.76 | CC31: 46.8 | CK31: 8.41 | DE31: 10.25
A32: 97 | C32: 1020 | D32: 14516.44 | E32: 5093.76 | G32: 229.01 | H32: 2958.08 | L32: 0 | O32: 10.25 | P32: 0 | Q32: 0 | R32: 0 | BT32: 400 | BW32: 2586.02 | BX32: 590.18 | BY32: 1368.16 | CA32: 15.66
A33: 99 | C33: 3303.68 | D33: 21741 | E33: 8725.19 | F33: 34.64 | G33: 400 | H33: 4560.02 | L33: 0 | O33: 0 | P33: 1265.29 | Q33: 0 | R33: 0 | BW33: 313.19 | BX33: 81.75 | BY33: 172.08 | CR33: 12.81
A34: 100 | D34: 3128.55 | E34: 1219.08 | G34: 0 | H34: 567.02 | L34: 12.81 | O34: 0 | P34: 344.3 | Q34: 0 | R34: 0 | BW34: 226.6 | BX34: 15.63 | BY34: 156.26 | BZ34: 359.75 | CQ34: 3090.97
A35: 108 | D35: 3289.36 | F35: 240.51 | G35: 0 | H35: 758.24 | I35: 35 | K35: 168 | L35: 3090.97 | M35: 323.2 | O35: 0 | P35: 931.63 | Q35: 0 | R35: 0 | BW35: 2202.8 | BX35: 754.34 | BY35: 999.72 | BZ35: 854.73 | CA35: 10.65 | CB35: 1275.69 | CC35: 15.78 | CQ35: 566.84 | CR35: 196
A36: 110 | D36: 17896.73 | E36: 9209.57 | F36: 2454.48 | G36: 0 | H36: 6113.71 | L36: 762.84 | O36: 0 | P36: 494.63 | Q36: 0 | R36: 0 | BT36: -1110 | BW36: 772.93 | BY36: 718.85 | BZ36: 1628.95 | CA36: 51.6 | CB36: 259.08 | CC36: 43.62 | CD36: 202.79
A37: 111 | D37: 13070.38 | G37: -1110 | H37: 3677.82 | I37: 2610 | L37: 0 | O37: 0 | P37: 0 | Q37: 0 | R37: 0 | BQ37: 238.02 | BR37: 715.95 | BS37: 146.31 | BU37: 872.92 | BW37: 5942.95 | BX37: 2297.94 | BY37: 2245.15 | BZ37: 9485.36 | CA37: 53.2 | CB37: 121.44 | CC37: 20.43 | CD37: 2106.01 | CG37: 88.07 | CQ37: 22742.34 | DE37: -3950.1
A38: 112 | C38: 8627.71 | D38: 31595.04 | E38: 24459.16 | F38: 10455.5 | G38: 1973.2 | H38: 22360.55 | I38: 1166.51 | K38: 754.57 | L38: 22742.34 | M38: 100.95 | O38: -3950.1 | P38: 14744.36 | Q38: 509.64 | R38: 0 | BS38: 841.5 | BW38: 752.72 | BY38: 619.78 | CR38: 380
A39: 113 | C39: 923 | D39: 9504 | E39: 35.63 | G39: 841.5 | H39: 1372.5 | L39: 380 | O39: 0 | P39: 2252.69 | Q39: 698.24 | R39: 0 | BW39: 2013.34 | BY39: 1740.45 | BZ39: 6032.56 | CD39: 318.42 | DE39: 233.2
A40: 115 | D40: 31646.64 | G40: 0 | H40: 10104.77 | L40: 0 | O40: 233.2 | P40: 46 | Q40: 0 | R40: 0 | BQ40: 250 | BW40: 1986.8 | BX40: 123.5 | BY40: 1351.54 | BZ40: 3140.97 | CB40: 179.49
...

Sheet OLD 2010 DATA - lookup4_GNL
A1: 1 | B1: 2 | C1: 3 | D1: 4 | E1: 5 | F1: 6 | G1: 7
A2: dst_num | B2: py2_aud_clo_fub | C2: pyr_aud_clo_fub
A3: 1 | B3: 6266.02 | C3: 10325.66
A4: 9999 | B4: 357430.58 | C4: 173292.49
A5: 2 | B5: 1505.71 | C5: 1412.92
A6: 4 | B6: -8770.7 | C6: -18451.43
A7: 6 | B7: -2944.54 | C7: 6056.87
A8: 11 | B8: 179128.25 | C8: 177680.78
A9: 12 | B9: 27709.69 | C9: 21904.54
A10: 13 | B10: 22377.82 | C10: 23924.96
A11: 14 | B11: 6898 | C11: 8619.51
A12: 15 | B12: 10580.5 | C12: 10468.91
A13: 16 | B13: 7374.98 | C13: 9437.64
A14: 22 | B14: 6550.15 | C14: 5427.59
... A337: 2904 | B337: -41794.57 | C337: -62928.95
A338: 1000 | B338: =SUM(B3:B337) -> 1470000 | C338: =SUM(C3:C337) -> 1816010.4

Sheet Sheet1
