Workbook
Name BlanksRange: 'Data {DO NOT EDIT}'!$A$3:$A$27
Name ChangeOrders: 'Data {DO NOT EDIT}'!$C$2:$C$13
Name CountyList: 'Data {DO NOT EDIT}'!$F$2:$F$101
Name Eligibility: 'Data {DO NOT EDIT}'!$C$25:$C$26
Name LabCodes: 'Data {DO NOT EDIT}'!$K$2:$K$88
Name NoBlanksRange: tblTask!$D:$D
Name ReimbTypeName: 'Data {DO NOT EDIT}'!$C$8:$C$11
Name RPType: 'Data {DO NOT EDIT}'!$C$17:$C$19
Name TaskList: 'Data {DO NOT EDIT}'!$I$2:$I$152

Sheet Instructions
A1: NORTH CAROLINA DEPARTMENT OF ENVIRONMENT & NATURAL RESOURCES
A2: LEAKING PETROLEUM UNDERGROUND STORAGE TANK CLEANUP FUNDS
A4: INSTRUCTIONS FOR COMPLETING AN ePATA (ELECTRONIC PREAPPROVAL) FORM
A6: Preapproval Requirement
C8: Written preapproval of both tasks and associated costs must be received from the appropriate regional office before work is performed in order to receive reimbursement from the Cleanup Funds [N.C.G.S. 143-215.94E(e2) and 15A NCAC 2P.0402(b)(9)]. Preapproval must be obtained even if Fund eligibility has not been determined where later reimbursement will be sought. Except where otherwise noted, work performed during emergency response actions (such as vapor/explosion hazards, initial abatement actions for a new release, and immediate free product recovery responses, etc.) and the risk assessment phase (Limited Site Assessment) do not require preapproval.
B10: Tasks or phases of work requiring preapproval include:
B11:  | C11: Any work not defined by the Department as an Emergency Response (typically immediate surface water cleanup actions, initial free product recovery events in response to the discovery of free-phase hydrocarbons, vapor/explosion hazard investigations, the Initial Abatement Action done within 90 days of the release discovery, etc.) or part of the site's initial Risk Assessment (typically the LSA).
B12:  | C12: All work performed after a Risk, Rank and Abatement determination is made for the site (typically, but not always, following completion of a Limited Site Assessment) including any corrective action excavations done as following a tank closure event performed after the RRA score is assigned.
B13:  | C13: All aggressive fluid-vapor recovery events after completion of the first emergency response event.
B14:  | C14: Any task in the Reasonable Rate Document that is defined as requiring preapproval.
B15:  | C15: Note that any Initial Abatement Action or Limited Site Assessment activity that varies from or exceeds the scopes of work defined in the STIRA (tank closure) or ACA (assessment) guidelines, and/or the Reasonable Rate Document, (excepting only those variations specifically allowed in the aforementioned documents) should be approved in writing by the Incident Manager. Formal 'Preapproval' is not required, but may be used as documentation of the work as reasonable and necessary.
A17: Preapproval Procedures
B18: 1 | C18: Complete the Electronic Preapproval Task Authorization Form (ePATA) excel worksheet included in this file. DO NOT MODIFY the form or alter the other worksheets in the file, as this will impact the ability to have the information uploaded into the State Trust Fund Preapproval database in a timely manner. If additional room is needed, break the requested scope into related task groupings and submit a separate ePATA file for each group.
B19: 2 | C19: The Preapproval form must be completed in full, with the exception of those portions explicitly reserved for UST Section personnel (designated as 'Incident Manager', 'RO', 'CO', and 'UST Section'). This includes the completion of the required text in the form header, as well as the 'Task/Lab', 'Unit/Type', and 'Rate/Price' columns.
B20: 3 | C20: Complete the TA by first selecting the merged cell with the TA title in it (Cells A1-J2) then picking the applicable Preappoval type in the dropdown menu (Directed, NonDirected, Free Product Program). [Note that a NonDirected preapproval request will require that a scanned copy of the NonDirected Certification (notarized statement from the RP acknowledging the delayed reimbursement schedule for NonDirected work) be attached to the submittal, with the original subsequently submitted by mail to the Regional Office.]
C21: If you receive an error message when entering data, it likely means that the cell you are using either has a specific format type (like dates) or has a preset list available via dropdown menu (text can still be entered manually for these, but it must match the style/options in the dropdown.) Please follow the instructions on the error message to match the appropriate data validation rules.
B22: 4 | C22: Next, enter in all of the associated Site, Responsble Party, and Consultant Information at the top of the TA. Do not enter any information in the "Reserved for Incident Manager" box. Where known, the RP and Consultant ID numbers may be entered at this time as well. Though not required, these ID numbers may be obtained by contacting Jared Edwards at jared.edwards@ncdenr.gov or by referencing previous ePATA's for this or other sites where this information was already provided (the ID #'s are consistent for each RP and Consultant across multiple sites.)
B23: 5 | C23: Enter in the requested 'Tasks', 'Units' and unit 'Type' (e.g., ft, hrs, mw, 6200b, etc.), then the 'Rate' per unit or lump 'Price' (if bidded) in the appropriate columns, and, if applicable, designate the task as being a Third Party Deductible/Damages Task in the far left column with a 'Y'. If not a Third Party Damages cost, leave the leftmost column blank. [Note that that the "Total Applied as Third Party Deductible/Damages Costs" relates to a separate deductible for costs associated with bodily injury or property damage, including loss of normal use of their property, for neighboring property owners (or a new non-RP site owner) impacted by the release (NCGS 143-215.94B(b)(5) and 143-215.94D(b1)(2)). It is not for costs related to 'Third-Party' vendors or service providers (which are not tracked separately.)]
B24: 6 | C24: Confirm that the Proposed Task Subtotal is accurate, that the summed Requested Totals are accurate, and enter a submittal date at the bottom of the form. Then save a copy of the submittal as < incident#-TA# Site Name yyyy-mm-dd > (e.g., "123456-78 John Doe Residence 2012-01-31" and email a copy of the finalized TA Excel file to the appropriate Regional Office Incident Manager, along with a copy of the workplan/proposal justifying the work included within the TA and any necessary maps or tables. [A submittal PM signature should not be included at this time. See #7 below.]
B25: 7 | C25: Once preapproval is authorized by both Branches, the Regional Office will send a copy of the finalized Preapproval form directly to the Main Consultant/Contractor. Upon receipt, the PM should also sign and date the final hard copy in the space provided. After receiving the finalized Preapproval form, the approved activities may be initiated. Any costs incurred prior to the final UST Section authorization date on the Preapproval may not be claimed as a "preapproved" cost under that form.
B26: 8 | C26: If the Main Consultant/Contractor discovers that unexpected tasks must be performed and/or costs will be incurred that exceed the preapproved amount, a 'supplementary' ePATA change order must be submitted (using the same file, but designated as such where applicable in the form header.) List all previous PATA numbers associated with this revised request and include scans/copies of the earlier approved PATA form(s) along with a written justification to the Regional Office. This form must be approved by all applicable UST Section staff prior to conducting the additional work. The supplementary Preapproval form should include only the additional requested tasks and costs, and should not carry forward any previously-approved costs from an earlier PATA.
B27: 9 | C27: If verbal preapproval is authorized over the telephone or by email, it is the responsibility of the consultant to prepare a formal ePATA submittal as outlined above and ensure that this file is submitted to the Regional Office within one week of the verbal authorization. Failure to acquire this document will result in non-payment of the costs.
A29: Claim Procedures
B30: 1 | C30: After the work has been completed, the finalized Preapproval form will serve as the cover to the Main Consultant/Contractor invoices submitted with the reimbursement claim. Please note that multiple PATA's may be submitted with a single reimbursement claim. Once claimed, however, each Preapproval Task Authorization (including associated PATA supplements/change orders, whether claimed or not) is closed and no other costs may be claimed under that preapproval. Additionally, except where a claim exceeds $20,000, only one claim may be submitted for a given site during a 90-day period.
B31: 2 | C31: Complete the "Final Reimbursement" section of all Preapproval forms included with a reimbursement claim. Designate the applicable date(s) of work specific to each task and the amount claimed for these dates under each Preapproval. This portion of the Preapproval form must be completed for the reimbursement request to be properly reviewed. Any failure to properly document the required information will result in the return of any filed claim, unprocessed.
B32: 3 | C32: Ensure that the aforementioned dates and subtotals correspond correctly to any information on the invoices, Primary Forms, and Secondary Forms submitted with the reimbursement claim. Inconsistencies within the provided documentation will result in reimbursement reductions or denials.

Sheet Preapproval ePATA
A1: CLICK HERE FIRST TO USE DROPDOWN -> | K1: ELECTRONIC PREAPPROVAL TASK AUTHORIZATION FORM
K2: Dept of Environment & Natural Resources - Division of Waste Management
B4: Site Name | M4: City / County | P4: / | S4: Incident #
B5: RP STF ID/Name (F/L) | F5: / | M5: Incident Mgr | S5: Region | T5: =VLOOKUP(Q4,'Data {DO NOT EDIT}'!F2:G101,2) -> #N/A
B6: RP Type (Owner/Operator / Landowner / Attny-in-fact) | M6: TA Supplement / Change Order? | S6: Prev. TA #
B8: Consult. ID/Co.Name | F8: / | M8: (Reserved for Incident Manager)
B9: Phone / Fax Number | I9: / | M9: Task Authorization Number: | S9: ChangeOrd:
B10: Email / PM Name (F/L) | I10: / | M10: Site Risk / Rank / Abatement: | S10: RRA Date:
B11: Proposal# / Scope Dates | I11: / | M11: % Commercial (C=100%, NC=0%, Both=1%-99%)
B12: Has STF Eligibility Been Determined? (T/F) | M12: Site Status (Active or NFA Date) | Q12: Active
B14: Note: This Electronic Preapproval Task Authorization Form should be used to receive preapproval from the UST Section. A proposal must be attached to elaborate on the costs for the tasks listed below that describes the scope of work and the rationale for the proposed activities. If, following completion of this ePATA, you discover that unexpected tasks must be performed, incurring costs or for tasks not originally included with this form, you must complete and submit a separate preapproval request designated as a "TA Supplement / Change Order" in the provided space above. Include a copy of the prior preapproval form for confirmation. Please attach this form to the cover of the corresponding claim when requesting reimbursement. IMPORTANT: Only one claim may be submitted during a quarter or 3-month period. All preapprovals submitted within a claim are closed with that claim, and may not be re-used in a separate submittal, even for costs or tasks that were not originally claimed Final reimbursement of costs associated with the Total Claimed amount below may vary depending on the eligibility status of the site (i.e., deductibles, apportionment, etc.), and the documentary validation of incurred costs as reasonable and necessary expenses per 15A NCAC 2P .0402 and .0404.
B15: With Claim: | D15: [ ] All Main Consultant/Contractor invoices attached? | M15: [ ] Proof of payment attached directly to the front of each invoice?
B16: w Important: The date of reimbursement is dependent on the Trust Fund balance. There may be a delay in the reimbursement of claims for work under this ePATA.
B18: PREAPPROVAL / TASK AUTHORIZATION | Q18: FINAL REIMBURSEMENT
B19: (See Instructions / RRD for Tasks requiring Preapproval / Task Authorization) | Q19: (Must Complete with Claim Submittal)
B20: 3rd Pty Ded? | C20: Task # | D20: Lab / SubCode | E20: Proposed Units / Type (Consultant) | H20: RO Auth | J20: Proposed Rate/Price (Consultant) | K20: CO Auth | M20: Proposed Task Subtotal (Consultant) | O20: Preapproved Subtotal (UST Section) | Q20: Dates of Work1 (Consultant) Started / Completed | T20: Claimed Amount2 (Consultant)
M21: =IF(E21="","",E21*J21) | O21: =IF(K21="","",IF(K21="y",IF(H21="y",E21*J21,H21*J21),IF(H21="y",E21*K21,H21*K21))) | R21: /
M22: =IF(E22="","",E22*J22) | O22: =IF(K22="","",IF(K22="y",IF(H22="y",E22*J22,H22*J22),IF(H22="y",E22*K22,H22*K22))) | R22: /
M23: =IF(E23="","",E23*J23) | O23: =IF(K23="","",IF(K23="y",IF(H23="y",E23*J23,H23*J23),IF(H23="y",E23*K23,H23*K23))) | R23: /
M24: =IF(E24="","",E24*J24) | O24: =IF(K24="","",IF(K24="y",IF(H24="y",E24*J24,H24*J24),IF(H24="y",E24*K24,H24*K24))) | R24: /
M25: =IF(E25="","",E25*J25) | O25: =IF(K25="","",IF(K25="y",IF(H25="y",E25*J25,H25*J25),IF(H25="y",E25*K25,H25*K25))) | R25: /
M26: =IF(E26="","",E26*J26) | O26: =IF(K26="","",IF(K26="y",IF(H26="y",E26*J26,H26*J26),IF(H26="y",E26*K26,H26*K26))) | R26: /
M27: =IF(E27="","",E27*J27) | O27: =IF(K27="","",IF(K27="y",IF(H27="y",E27*J27,H27*J27),IF(H27="y",E27*K27,H27*K27))) | R27: /
M28: =IF(E28="","",E28*J28) | O28: =IF(K28="","",IF(K28="y",IF(H28="y",E28*J28,H28*J28),IF(H28="y",E28*K28,H28*K28))) | R28: /
M29: =IF(E29="","",E29*J29) | O29: =IF(K29="","",IF(K29="y",IF(H29="y",E29*J29,H29*J29),IF(H29="y",E29*K29,H29*K29))) | R29: /
M30: =IF(E30="","",E30*J30) | O30: =IF(K30="","",IF(K30="y",IF(H30="y",E30*J30,H30*J30),IF(H30="y",E30*K30,H30*K30))) | R30: /
M31: =IF(E31="","",E31*J31) | O31: =IF(K31="","",IF(K31="y",IF(H31="y",E31*J31,H31*J31),IF(H31="y",E31*K31,H31*K31))) | R31: /
M32: =IF(E32="","",E32*J32) | O32: =IF(K32="","",IF(K32="y",IF(H32="y",E32*J32,H32*J32),IF(H32="y",E32*K32,H32*K32))) | R32: /
... M45: =IF(E45="","",E45*J45) | O45: =IF(K45="","",IF(K45="y",IF(H45="y",E45*J45,H45*J45),IF(H45="y",E45*K45,H45*K45))) | R45: /
M46: Requested | O46: Preapproved | T46: Claimed2
K47: TOTAL: | M47: =SUM(M21:M45) -> 0 | O47: =SUM(O21:O45) -> 0 | S47: TOTAL:
K48: Total Standard Costs (Not Third Party) | M48: =SUMIF($B$21:$B$45,"",M21:M45) -> 0 | O48: =SUMIF($B$21:$B$45,"",O21:O45) -> 0 | S48: Total Standard Costs
K49: Total applied as Third Party Deductible/Damage Costs | M49: =SUMIF($B$21:$B$45,"y",M21:M45) -> 0 | O49: =SUMIF($B$21:$B$45,"y",O21:O45) -> 0 | S49: Total Third Pty Costs
B50: Process Tracking | D50: (Date) | F50: (Initials)
C51: TA Submittal: | E51: by: | H51: (PM) | J51: (Reserved for RO)
C53: RO Review: | E53: by: | H53: (IM) | M53: Final Joint UST Preapproval Confirmed By: | S53: Date1
C55: CO Review: | E55: by: | H55: (STF) | M55: Consultant Receipt Confirmation Signature: | S55: Date 3
B57: 1 - If no work has been started, the ePATA expires one year from the Joint UST Preapproval date. Note: Tasks must also be claimed within one year of completion.
C58: This one-year activity deadline from the authorization date does not supercede other regulatory deadlines (e.g., NORR's, NOV's, Enforcements, Remissions, etc.)
B59: 2 - Only Tasks included on this PATA form may be claimed. Do not include other Tasks or claimed costs (i.e., Claim preparation) that were not preapproved.
...

Sheet Non-Directed Certification
A1: NON-DIRECTED CERTIFICATION | J1: ELECTRONIC PREAPPROVAL TASK AUTHORIZATION FORM
J2: Dept of Environment & Natural Resources - Div of Waste Management
A4: Site Name | C4: =IF('Preapproval ePATA'!D4<>0,'Preapproval ePATA'!D4,"") | L4: City / County | M4: =IF('Preapproval ePATA'!N4<>0,'Preapproval ePATA'!N4,"") | O4: / | R4: Incident # | S4: =IF('Preapproval ePATA'!T4<>0,'Preapproval ePATA'!T4,"")
A5: Responsible Party Name | E5: =IF('Preapproval ePATA'!G5<>0,'Preapproval ePATA'!G5,"") | I5: =IF('Preapproval ePATA'!J5<>0,'Preapproval ePATA'!J5,"") | L5: Incident Mgr | M5: =IF('Preapproval ePATA'!N5<>0,'Preapproval ePATA'!N5,"") | R5: Region | S5: =VLOOKUP(P4,'Data {DO NOT EDIT}'!F2:G101,2) -> #N/A
A6: RP Type (Owner/Operator / Landowner / Attny-in-fact) | H6: =IF('Preapproval ePATA'!I6<>0,'Preapproval ePATA'!I6,"") | L6: TA Supplement/C. Order? | O6: =IF('Preapproval ePATA'!Q6<>0,'Preapproval ePATA'!Q6,"") | R6: Prev. TA # | S6: =IF('Preapproval ePATA'!T6<>0,'Preapproval ePATA'!T6,"")
A7: Consultant Name | D7: =IF('Preapproval ePATA'!G8<>0,'Preapproval ePATA'!G8,"") | L7: Proposal# / Scope Dates | O7: =IF('Preapproval ePATA'!E11<>0,'Preapproval ePATA'!E11,"") | Q7: / | R7: =IF('Preapproval ePATA'!J11<>0,'Preapproval ePATA'!J11,"")
A10: Note: An original, notarized version of this form should be submitted to the Regional Office by mail to be filed with a hard copy of the finalized Non-Directed Electronic Preapproval Task Authorization request. The associated Non-Directed ePATA cannot be approved without receipt of this certification document. If, following receipt of the completed ePATA, you discover that other, unexpected tasks must be performed, incurring costs or using tasks not preapproved in this authorization, you must complete and submit a separate ePATA request with its own, separate Non-Directed Certification. Additionally, a copy of this form should be attached to the hard copy of the ePATA form that is submitted with the formal claim when requesting reimbursement. IMPORTANT: Only one claim may be submitted during a quarter or 3-month period. All preapprovals submitted within a claim are closed with that claim, and may not be reused for a separate claim, even for any remaining, 'unclaimed' tasks from the earlier submittal. Final reimbursement of costs associated with the total preapproved amount may vary depending on the eligibility status of the site (i.e., deductibles, apportionment, etc.), and the documentary validation of incurred costs as reasonable and necessary expenses per 15A NCAC 2P .0402 and .0404.
L12: Requested Amount (as shown on the ePATA)
J14: TOTAL NONDIRECTED REQUEST: | L14: ='Preapproval ePATA'!M47 -> 0
J15: Total Standard Costs (Not Third Party Damages) | L15: ='Preapproval ePATA'!M48 -> 0
J16: Total applied as Third Party Deductible/Damage Costs | L16: ='Preapproval ePATA'!M49 -> 0
A18: I, ______________________________________ (tank owner/operator/landowner), understand and agree that reimbursement of claims submitted to the Department for costs incurred as a result of properly completing the tasks preapproved herein will not be paid until after the Department has paid all claims for tasks that the Department directs.
E19: Signature | N19: Date
A21: County of | I21: State of
A22: I certify that the following person(s) personally appeared before me this day: __________________________________________,
A23: each acknowledging to me that he or she signed the foregoing document: ____________________________________________.
L24: (Describe if signed individually or in representative capacity)
A25: WITNESS my hand and official seal, this ______ day of ______________ A.D. ________
A27: Notary Public: | N27: My Commission expires:
A38: DWM/UST NonDir Cert V.03/19/2013

Sheet Data {DO NOT EDIT}
A1: Discrete Tasks | B1: (calculated from entry) | F1: County List | G1: RO | I1: 2010 Task List | K1: Lab Codes | N1: Code LU
F2: Alamance | G2: WS | I2: 1.01 | K2: #210 | N2: 1.01
A3: =IF(COUNTIF('Preapproval ePATA'!$C$21:C21,'Preapproval ePATA'!C21)=1,'Preapproval ePATA'!C21,"") | F3: Alexander | G3: MOR | I3: 1.02 | K3: #220 | N3: 1.02
A4: =IF(COUNTIF('Preapproval ePATA'!$C$21:C22,'Preapproval ePATA'!C22)=1,'Preapproval ePATA'!C22,"") | F4: Alleghany | G4: WS | I4: 1.025 | K4: #230 | N4: 1.025
A5: =IF(COUNTIF('Preapproval ePATA'!$C$21:C23,'Preapproval ePATA'!C23)=1,'Preapproval ePATA'!C23,"") | F5: Anson | G5: FAY | I5: 1.04 | K5: #240 | N5: 1.04
A6: =IF(COUNTIF('Preapproval ePATA'!$C$21:C24,'Preapproval ePATA'!C24)=1,'Preapproval ePATA'!C24,"") | F6: Ashe | G6: WS | I6: 1.05 | K6: #271 | N6: 1.05
A7: =IF(COUNTIF('Preapproval ePATA'!$C$21:C25,'Preapproval ePATA'!C25)=1,'Preapproval ePATA'!C25,"") | C7: ReimbType Name | D7: Type Value | F7: Avery | G7: ASH | I7: 1.061 | K7: #272 | N7: 1.061
A8: =IF(COUNTIF('Preapproval ePATA'!$C$21:C26,'Preapproval ePATA'!C26)=1,'Preapproval ePATA'!C26,"") | C8: CLICK HERE FIRST TO USE DROPDOWN -> | D8: 0 | F8: Beaufort | G8: WAS | I8: 2.071 | K8: #280 | N8: 2.071
A9: =IF(COUNTIF('Preapproval ePATA'!$C$21:C27,'Preapproval ePATA'!C27)=1,'Preapproval ePATA'!C27,"") | C9: DIRECTED COSTS | D9: 1 | F9: Bertie | G9: WAS | I9: 2.072 | K9: #290 | N9: 2.072
A10: =IF(COUNTIF('Preapproval ePATA'!$C$21:C28,'Preapproval ePATA'!C28)=1,'Preapproval ePATA'!C28,"") | C10: NON-DIRECTED | D10: 2 | F10: Bladen | G10: FAY | I10: 2.073 | K10: #300 | N10: 2.073
A11: =IF(COUNTIF('Preapproval ePATA'!$C$21:C29,'Preapproval ePATA'!C29)=1,'Preapproval ePATA'!C29,"") | C11: FREE PRODUCT | D11: 3 | F11: Brunswick | G11: WIL | I11: 2.074 | K11: #301 | N11: 2.074
A12: =IF(COUNTIF('Preapproval ePATA'!$C$21:C30,'Preapproval ePATA'!C30)=1,'Preapproval ePATA'!C30,"") | F12: Buncombe | G12: ASH | I12: 2.082 | K12: #310 | N12: 2.082
A13: =IF(COUNTIF('Preapproval ePATA'!$C$21:C31,'Preapproval ePATA'!C31)=1,'Preapproval ePATA'!C31,"") | F13: Burke | G13: ASH | I13: 2.084 | K13: #320 | N13: 2.084
A14: =IF(COUNTIF('Preapproval ePATA'!$C$21:C32,'Preapproval ePATA'!C32)=1,'Preapproval ePATA'!C32,"") | F14: Cabarrus | G14: MOR | I14: 2.085 | K14: #321 | N14: 2.085
A15: =IF(COUNTIF('Preapproval ePATA'!$C$21:C33,'Preapproval ePATA'!C33)=1,'Preapproval ePATA'!C33,"") | F15: Caldwell | G15: ASH | I15: 2.086 | K15: #330 | N15: 2.086
A16: =IF(COUNTIF('Preapproval ePATA'!$C$21:C34,'Preapproval ePATA'!C34)=1,'Preapproval ePATA'!C34,"") | C16: RP Type | F16: Camden | G16: WAS | I16: 2.087 | K16: #331 | N16: 2.087
A17: =IF(COUNTIF('Preapproval ePATA'!$C$21:C35,'Preapproval ePATA'!C35)=1,'Preapproval ePATA'!C35,"") | C17: Owner/Operator | F17: Carteret | G17: WIL | I17: 2.09 | K17: #340 | N17: 2.09
A18: =IF(COUNTIF('Preapproval ePATA'!$C$21:C36,'Preapproval ePATA'!C36)=1,'Preapproval ePATA'!C36,"") | C18: Landowner | F18: Caswell | G18: WS | I18: 2.1 | K18: #341 | N18: 2.1
A19: =IF(COUNTIF('Preapproval ePATA'!$C$21:C37,'Preapproval ePATA'!C37)=1,'Preapproval ePATA'!C37,"") | C19: Attorney-In-Fact | F19: Catawba | G19: MOR | I19: 2.121 | K19: #342 | N19: 2.121
A20: =IF(COUNTIF('Preapproval ePATA'!$C$21:C38,'Preapproval ePATA'!C38)=1,'Preapproval ePATA'!C38,"") | F20: Chatham | G20: RAL | I20: 2.13 | K20: #350 | N20: 2.13
A21: =IF(COUNTIF('Preapproval ePATA'!$C$21:C39,'Preapproval ePATA'!C39)=1,'Preapproval ePATA'!C39,"") | F21: Cherokee | G21: ASH | I21: 2.141 | K21: #360 | N21: 2.141
A22: =IF(COUNTIF('Preapproval ePATA'!$C$21:C40,'Preapproval ePATA'!C40)=1,'Preapproval ePATA'!C40,"") | F22: Chowan | G22: WAS | I22: 2.15 | K22: #370 | N22: 2.15
A23: =IF(COUNTIF('Preapproval ePATA'!$C$21:C41,'Preapproval ePATA'!C41)=1,'Preapproval ePATA'!C41,"") | F23: Clay | G23: ASH | I23: 2.17 | K23: #380 | N23: 2.17
A24: =IF(COUNTIF('Preapproval ePATA'!$C$21:C42,'Preapproval ePATA'!C42)=1,'Preapproval ePATA'!C42,"") | C24: Eligibility | F24: Cleveland | G24: ASH | I24: 2.2 | K24: #390 | N24: 2.2
A25: =IF(COUNTIF('Preapproval ePATA'!$C$21:C43,'Preapproval ePATA'!C43)=1,'Preapproval ePATA'!C43,"") | C25: TRUE | F25: Columbus | G25: WIL | I25: 2.281 | K25: #408 | N25: 2.281
A26: =IF(COUNTIF('Preapproval ePATA'!$C$21:C44,'Preapproval ePATA'!C44)=1,'Preapproval ePATA'!C44,"") | C26: FALSE | F26: Craven | G26: WAS | I26: 2.29 | K26: #409 | N26: 2.29
A27: =IF(COUNTIF('Preapproval ePATA'!$C$21:C45,'Preapproval ePATA'!C45)=1,'Preapproval ePATA'!C45,"") | F27: Cumberland | G27: FAY | I27: 2.3 | K27: #410 | N27: 2.3
F28: Currituck | G28: WAS | I28: 2.381 | K28: #411 | N28: 2.381
F29: Dare | G29: WAS | I29: 2.4 | K29: #412 | N29: 2.4
F30: Davidson | G30: WS | I30: 2.41 | K30: #414 | N30: 2.41
F31: Davie | G31: WS | I31: 2.413 | K31: #415 | N31: 2.413
F32: Duplin | G32: WIL | I32: 2.415 | K32: #416 | N32: 2.415
F33: Durham | G33: RAL | I33: 2.5 | K33: #417 | N33: 2.5
F34: Edgecombe | G34: RAL | I34: 2.51 | K34: #420 | N34: 2.51
F35: Forsyth | G35: WS | I35: 2.52 | K35: #421 | N35: 2.52
F36: Franklin | G36: RAL | I36: 2.6 | K36: #422 | N36: 2.6
F37: Gaston | G37: MOR | I37: 2.61 | K37: #424 | N37: 2.61
F38: Gates | G38: WAS | I38: 2.62 | K38: #430 | N38: 2.62
F39: Graham | G39: ASH | I39: 3.025 | K39: #440 | N39: 3.025
... F88: Swain | G88: ASH | I88: 6.1 | K88: 2P | N88: 6.1
...

Sheet tblSite
A1: IncidentNum | B1: SiteName | C1: SiteAddress | D1: SiteCounty | E1: SiteCity | F1: SiteNote | G1: Eligible | H1: FacID | I1: DedAmt | J1: FndCompct | K1: Ded3RD | L1: Sum3RD | M1: DedCode | N1: PriRank
A2: ='Preapproval ePATA'!T4 -> 0 | B2: ='Preapproval ePATA'!D4 -> 0 | D2: ='Preapproval ePATA'!Q4 -> 0 | E2: ='Preapproval ePATA'!N4 -> 0 | G2: ='Preapproval ePATA'!H12 -> 0 | J2: ='Preapproval ePATA'!T11 -> 0 | N2: =PATA!P10

Sheet tblClaim
A1: SiteID | B1: ClaimID | C1: ApplID | D1: ClmNote | E1: ReimType | F1: CleanUpPze | G1: P50AmtCom | H1: P50ChkCom | I1: FnlAmtCom | J1: FnlChkCom | K1: P50AmtNon | L1: P50ChkNon | M1: FnlAmtNon | N1: FnlChkNon | O1: DateStrt | P1: DateEnd | Q1: OwnID | R1: ConsID | S1: Directed | T1: Claimed | U1: ClaimDate | V1: ClaimNote
A2: =tblTask!$A$4 | B2: =tblTask!$B$4 | C2: =tblTask!$C$4 | D2: ePATA Test2 | E2: =VLOOKUP('Preapproval ePATA'!$A$1,'Data {DO NOT EDIT}'!C8:D11,2,FALSE) -> 0 | F2: 0 | G2: 0 | H2: 0 | I2: 0 | J2: 0 | K2: 0 | L2: 0 | M2: 0 | N2: 0 | O2: ='Preapproval ePATA'!D51 -> 0 | P2: ='Preapproval ePATA'!D53 -> 0 | Q2: ='Preapproval ePATA'!E5 -> 0 | R2: ='Preapproval ePATA'!E8 -> 0 | S2: =VLOOKUP('Preapproval ePATA'!$A$1,'Data {DO NOT EDIT}'!C8:D11,2,FALSE) -> 0 | T2: 0 | U2: 0

Sheet tblTask
A1: SiteID | B1: ClaimID | C1: ApplID | D1: TaskID | E1: ReqAmttsk | F1: AppdAmttsk | G1: RedNote
A2: ='Preapproval ePATA'!$T$4 -> 0 | B2: ='Preapproval ePATA'!$Q$9 -> 0 | C2: ='Preapproval ePATA'!$T$9 -> 0 | D2: -1 | E2: =IF($D2="","",SUMIF('Preapproval ePATA'!$C$21:$C$45,tblTask!D2,'Preapproval ePATA'!$M$21:$M$45)) -> 0 | F2: =IF(D2="","",SUMIF('Preapproval ePATA'!$C$21:$C$45,D2,'Preapproval ePATA'!$O$21:$O$45)) -> 0
A3: =IF($D3="","",A2) -> 0 | B3: =IF($D3="","",B2) -> 0 | C3: =IF($D3="","",C2) -> 0 | D3: 0 | E3: =IF($D3="","",SUMIF('Preapproval ePATA'!$C$21:$C$45,tblTask!D3,'Preapproval ePATA'!$M$21:$M$45)) -> 0 | F3: =IF(D3="","",SUMIF('Preapproval ePATA'!$C$21:$C$45,D3,'Preapproval ePATA'!$O$21:$O$45)) -> 0
A4: =IF($D4="","",A3) | B4: =IF($D4="","",B3) | C4: =IF($D4="","",C3) | D4: =IFERROR(INDEX([0]!BlanksRange,SMALL((IF(LEN([0]!BlanksRange),ROW(INDIRECT("1:"&ROWS([0]!BlanksRange))))),ROW(D1)),1),"") | E4: =IF($D4="","",SUMIF('Preapproval ePATA'!$C$21:$C$45,tblTask!D4,'Preapproval ePATA'!$M$21:$M$45)) | F4: =IF(D4="","",SUMIF('Preapproval ePATA'!$C$21:$C$45,D4,'Preapproval ePATA'!$O$21:$O$45))
A5: =IF($D5="","",A4) | B5: =IF($D5="","",B4) | C5: =IF($D5="","",C4) | D5: {=IFERROR(INDEX([0]!BlanksRange,SMALL((IF(LEN([0]!BlanksRange),ROW(INDIRECT("1:"&ROWS([0]!BlanksRange))))),ROW(D2)),1),"")} | E5: =IF($D5="","",SUMIF('Preapproval ePATA'!$C$21:$C$45,tblTask!D5,'Preapproval ePATA'!$M$21:$M$45)) | F5: =IF(D5="","",SUMIF('Preapproval ePATA'!$C$21:$C$45,D5,'Preapproval ePATA'!$O$21:$O$45))
A6: =IF($D6="","",A5) | B6: =IF($D6="","",B5) | C6: =IF($D6="","",C5) | D6: {=IFERROR(INDEX([0]!BlanksRange,SMALL((IF(LEN([0]!BlanksRange),ROW(INDIRECT("1:"&ROWS([0]!BlanksRange))))),ROW(D3)),1),"")} | E6: =IF($D6="","",SUMIF('Preapproval ePATA'!$C$21:$C$45,tblTask!D6,'Preapproval ePATA'!$M$21:$M$45)) | F6: =IF(D6="","",SUMIF('Preapproval ePATA'!$C$21:$C$45,D6,'Preapproval ePATA'!$O$21:$O$45))
A7: =IF($D7="","",A6) | B7: =IF($D7="","",B6) | C7: =IF($D7="","",C6) | D7: {=IFERROR(INDEX([0]!BlanksRange,SMALL((IF(LEN([0]!BlanksRange),ROW(INDIRECT("1:"&ROWS([0]!BlanksRange))))),ROW(D4)),1),"")} | E7: =IF($D7="","",SUMIF('Preapproval ePATA'!$C$21:$C$45,tblTask!D7,'Preapproval ePATA'!$M$21:$M$45)) | F7: =IF(D7="","",SUMIF('Preapproval ePATA'!$C$21:$C$45,D7,'Preapproval ePATA'!$O$21:$O$45))
A8: =IF($D8="","",A7) | B8: =IF($D8="","",B7) | C8: =IF($D8="","",C7) | D8: {=IFERROR(INDEX([0]!BlanksRange,SMALL((IF(LEN([0]!BlanksRange),ROW(INDIRECT("1:"&ROWS([0]!BlanksRange))))),ROW(D5)),1),"")} | E8: =IF($D8="","",SUMIF('Preapproval ePATA'!$C$21:$C$45,tblTask!D8,'Preapproval ePATA'!$M$21:$M$45)) | F8: =IF(D8="","",SUMIF('Preapproval ePATA'!$C$21:$C$45,D8,'Preapproval ePATA'!$O$21:$O$45))
A9: =IF($D9="","",A8) | B9: =IF($D9="","",B8) | C9: =IF($D9="","",C8) | D9: {=IFERROR(INDEX([0]!BlanksRange,SMALL((IF(LEN([0]!BlanksRange),ROW(INDIRECT("1:"&ROWS([0]!BlanksRange))))),ROW(D6)),1),"")} | E9: =IF($D9="","",SUMIF('Preapproval ePATA'!$C$21:$C$45,tblTask!D9,'Preapproval ePATA'!$M$21:$M$45)) | F9: =IF(D9="","",SUMIF('Preapproval ePATA'!$C$21:$C$45,D9,'Preapproval ePATA'!$O$21:$O$45))
A10: =IF($D10="","",A9) | B10: =IF($D10="","",B9) | C10: =IF($D10="","",C9) | D10: {=IFERROR(INDEX([0]!BlanksRange,SMALL((IF(LEN([0]!BlanksRange),ROW(INDIRECT("1:"&ROWS([0]!BlanksRange))))),ROW(D7)),1),"")} | E10: =IF($D10="","",SUMIF('Preapproval ePATA'!$C$21:$C$45,tblTask!D10,'Preapproval ePATA'!$M$21:$M$45)) | F10: =IF(D10="","",SUMIF('Preapproval ePATA'!$C$21:$C$45,D10,'Preapproval ePATA'!$O$21:$O$45))
A11: =IF($D11="","",A10) | B11: =IF($D11="","",B10) | C11: =IF($D11="","",C10) | D11: {=IFERROR(INDEX([0]!BlanksRange,SMALL((IF(LEN([0]!BlanksRange),ROW(INDIRECT("1:"&ROWS([0]!BlanksRange))))),ROW(D8)),1),"")} | E11: =IF($D11="","",SUMIF('Preapproval ePATA'!$C$21:$C$45,tblTask!D11,'Preapproval ePATA'!$M$21:$M$45)) | F11: =IF(D11="","",SUMIF('Preapproval ePATA'!$C$21:$C$45,D11,'Preapproval ePATA'!$O$21:$O$45))
A12: =IF($D12="","",A11) | B12: =IF($D12="","",B11) | C12: =IF($D12="","",C11) | D12: {=IFERROR(INDEX([0]!BlanksRange,SMALL((IF(LEN([0]!BlanksRange),ROW(INDIRECT("1:"&ROWS([0]!BlanksRange))))),ROW(D9)),1),"")} | E12: =IF($D12="","",SUMIF('Preapproval ePATA'!$C$21:$C$45,tblTask!D12,'Preapproval ePATA'!$M$21:$M$45)) | F12: =IF(D12="","",SUMIF('Preapproval ePATA'!$C$21:$C$45,D12,'Preapproval ePATA'!$O$21:$O$45))
A13: =IF($D13="","",A12) | B13: =IF($D13="","",B12) | C13: =IF($D13="","",C12) | D13: {=IFERROR(INDEX([0]!BlanksRange,SMALL((IF(LEN([0]!BlanksRange),ROW(INDIRECT("1:"&ROWS([0]!BlanksRange))))),ROW(D10)),1),"")} | E13: =IF($D13="","",SUMIF('Preapproval ePATA'!$C$21:$C$45,tblTask!D13,'Preapproval ePATA'!$M$21:$M$45)) | F13: =IF(D13="","",SUMIF('Preapproval ePATA'!$C$21:$C$45,D13,'Preapproval ePATA'!$O$21:$O$45))
A14: =IF($D14="","",A13) | B14: =IF($D14="","",B13) | C14: =IF($D14="","",C13) | D14: {=IFERROR(INDEX([0]!BlanksRange,SMALL((IF(LEN([0]!BlanksRange),ROW(INDIRECT("1:"&ROWS([0]!BlanksRange))))),ROW(D11)),1),"")} | E14: =IF($D14="","",SUMIF('Preapproval ePATA'!$C$21:$C$45,tblTask!D14,'Preapproval ePATA'!$M$21:$M$45)) | F14: =IF(D14="","",SUMIF('Preapproval ePATA'!$C$21:$C$45,D14,'Preapproval ePATA'!$O$21:$O$45))
A15: =IF($D15="","",A14) | B15: =IF($D15="","",B14) | C15: =IF($D15="","",C14) | D15: {=IFERROR(INDEX([0]!BlanksRange,SMALL((IF(LEN([0]!BlanksRange),ROW(INDIRECT("1:"&ROWS([0]!BlanksRange))))),ROW(D12)),1),"")} | E15: =IF($D15="","",SUMIF('Preapproval ePATA'!$C$21:$C$45,tblTask!D15,'Preapproval ePATA'!$M$21:$M$45)) | F15: =IF(D15="","",SUMIF('Preapproval ePATA'!$C$21:$C$45,D15,'Preapproval ePATA'!$O$21:$O$45))
A16: =IF($D16="","",A15) | B16: =IF($D16="","",B15) | C16: =IF($D16="","",C15) | D16: {=IFERROR(INDEX([0]!BlanksRange,SMALL((IF(LEN([0]!BlanksRange),ROW(INDIRECT("1:"&ROWS([0]!BlanksRange))))),ROW(D13)),1),"")} | E16: =IF($D16="","",SUMIF('Preapproval ePATA'!$C$21:$C$45,tblTask!D16,'Preapproval ePATA'!$M$21:$M$45)) | F16: =IF(D16="","",SUMIF('Preapproval ePATA'!$C$21:$C$45,D16,'Preapproval ePATA'!$O$21:$O$45))
... A32: =IF($D32="","",A31) | B32: =IF($D32="","",B31) | C32: =IF($D32="","",C31) | D32: {=IFERROR(INDEX([0]!BlanksRange,SMALL((IF(LEN([0]!BlanksRange),ROW(INDIRECT("1:"&ROWS([0]!BlanksRange))))),ROW(D29)),1),"")} | E32: =IF($D32="","",SUMIF('Preapproval ePATA'!$C$21:$C$45,tblTask!D32,'Preapproval ePATA'!$M$21:$M$45)) | F32: =IF(D32="","",SUMIF('Preapproval ePATA'!$C$21:$C$45,D32,'Preapproval ePATA'!$O$21:$O$45))
