Workbook

Sheet Calculations
A1: Effects of Replacement Strategies on Sap Yield and Net Profit
A3: Yrs | C3: Nothing | D3: Spouts | E3: CV | F3: D1 | G3: D2 | H3: D3 | I3: D4 | J3: D5 | K3: Clean | L3: Clean+Spout
A4: 1 | B4: 100 | C4: 100 | D4: 100 | E4: =F4 -> 100 | F4: 100 | G4: 100 | H4: 100 | I4: =D4 -> 100 | J4: =I4 -> 100 | K4: 100 | L4: 100
A5: 2 | B5: 100 | C5: 85.5 | D5: 92.5 | E5: 96 | F5: 99 | G5: =J5 -> 92.5 | H5: 92.5 | I5: =D5 -> 92.5 | J5: =I5 -> 92.5 | K5: 91 | L5: 94
A6: 3 | B6: 100 | C6: 78 | D6: 86.5 | E6: 94 | F6: 98 | G6: =F6 -> 98 | H6: 86.5 | I6: =D6 -> 86.5 | J6: =I6 -> 86.5 | K6: 85 | L6: 89
A7: 4 | B7: 100 | C7: 72 | D7: =C7*1.125 -> 81 | E7: 92 | F7: 97 | G7: =G6*0.925 -> 90.65 | H7: 97 | I7: =D7 -> 81 | J7: =I7 -> 81 | K7: 79.5 | L7: 84.5
A8: 5 | B8: 100 | C8: 68 | D8: =C8*1.125 -> 76.5 | E8: 90 | F8: 96 | G8: =F8 -> 96 | H8: =H7*0.925 -> 89.725 | I8: =F8 -> 96 | J8: =D8 -> 76.5 | K8: 74.5 | L8: 80
A9: 6 | B9: 100 | C9: 64.5 | D9: =C9*1.125 -> 72.5625 | E9: 88 | F9: 95 | G9: =G8*0.925 -> 88.8 | H9: =(H7*0.865) -> 83.905 | I9: =(I8*0.925) -> 88.8 | J9: =F9 -> 95 | K9: 70 | L9: 76
A11: Baseline Gal sap
A12: =Model!M33 -> 20 | C12: Nothing | D12: Spouts | E12: CV | F12: D1 | G12: D2 | H12: D3 | I12: D4 | J12: D5 | K12: Clean | L12: Clean+Spout
A13: 1 | B13: =$A$12*(B4/100) -> 20 | C13: =$A$12*(C4/100) -> 20 | D13: =$A$12*(D4/100) -> 20 | E13: =$A$12*(E4/100) -> 20 | F13: =$A$12*(F4/100) -> 20 | G13: =$A$12*(G4/100) -> 20 | H13: =$A$12*(H4/100) -> 20 | I13: =$A$12*(I4/100) -> 20 | ... L13: =$A$12*(L4/100) -> 20
A14: 2 | B14: =$A$12*(B5/100) -> 20 | C14: =$A$12*(C5/100) -> 17.1 | D14: =$A$12*(D5/100) -> 18.5 | E14: =$A$12*(E5/100) -> 19.2 | F14: =$A$12*(F5/100) -> 19.8 | G14: =$A$12*(G5/100) -> 18.5 | H14: =$A$12*(H5/100) -> 18.5 | I14: =$A$12*(I5/100) -> 18.5 | ... L14: =$A$12*(L5/100) -> 18.8
A15: 3 | B15: =$A$12*(B6/100) -> 20 | C15: =$A$12*(C6/100) -> 15.6 | D15: =$A$12*(D6/100) -> 17.3 | E15: =$A$12*(E6/100) -> 18.8 | F15: =$A$12*(F6/100) -> 19.6 | G15: =$A$12*(G6/100) -> 19.6 | H15: =$A$12*(H6/100) -> 17.3 | I15: =$A$12*(I6/100) -> 17.3 | ... L15: =$A$12*(L6/100) -> 17.8
A16: 4 | B16: =$A$12*(B7/100) -> 20 | C16: =$A$12*(C7/100) -> 14.4 | D16: =$A$12*(D7/100) -> 16.2 | E16: =$A$12*(E7/100) -> 18.4 | F16: =$A$12*(F7/100) -> 19.4 | G16: =$A$12*(G7/100) -> 18.13 | H16: =$A$12*(H7/100) -> 19.4 | I16: =$A$12*(I7/100) -> 16.2 | ... L16: =$A$12*(L7/100) -> 16.9
A17: 5 | B17: =$A$12*(B8/100) -> 20 | C17: =$A$12*(C8/100) -> 13.6 | D17: =$A$12*(D8/100) -> 15.3 | E17: =$A$12*(E8/100) -> 18 | F17: =$A$12*(F8/100) -> 19.2 | G17: =$A$12*(G8/100) -> 19.2 | H17: =$A$12*(H8/100) -> 17.945 | I17: =$A$12*(I8/100) -> 19.2 | ... L17: =$A$12*(L8/100) -> 16
A18: 6 | B18: =$A$12*(B9/100) -> 20 | C18: =$A$12*(C9/100) -> 12.9 | D18: =$A$12*(D9/100) -> 14.5125 | E18: =$A$12*(E9/100) -> 17.6 | F18: =$A$12*(F9/100) -> 19 | G18: =$A$12*(G9/100) -> 17.76 | H18: =$A$12*(H9/100) -> 16.781 | I18: =$A$12*(I9/100) -> 17.76 | ... L18: =$A$12*(L9/100) -> 15.2
A21: $ sap value produced per tap
A22: =Model!M34 -> 0.3 | C22: Nothing | D22: Spouts | E22: CV | F22: D1 | G22: D2 | H22: D3 | I22: D4 | J22: D5 | K22: Clean | L22: Clean+Spout
A23: 1 | B23: =B13*0.5 -> 10 | C23: =C13*$A$22 -> 6 | D23: =D13*$A$22 -> 6 | E23: =E13*$A$22 -> 6 | F23: =F13*$A$22 -> 6 | G23: =G13*$A$22 -> 6 | H23: =H13*$A$22 -> 6 | I23: =I13*$A$22 -> 6 | J23: =J13*$A$22 -> 6 | ... L23: =L13*$A$22 -> 6
A24: 2 | B24: =B14*0.5 -> 10 | C24: =C14*$A$22 -> 5.13 | D24: =D14*$A$22 -> 5.55 | E24: =E14*$A$22 -> 5.76 | F24: =F14*$A$22 -> 5.94 | G24: =G14*$A$22 -> 5.55 | H24: =H14*$A$22 -> 5.55 | I24: =I14*$A$22 -> 5.55 | J24: =J14*$A$22 -> 5.55 | ... L24: =L14*$A$22 -> 5.64
A25: 3 | B25: =B15*0.5 -> 10 | C25: =C15*$A$22 -> 4.68 | D25: =D15*$A$22 -> 5.19 | E25: =E15*$A$22 -> 5.64 | F25: =F15*$A$22 -> 5.88 | G25: =G15*$A$22 -> 5.88 | H25: =H15*$A$22 -> 5.19 | I25: =I15*$A$22 -> 5.19 | J25: =J15*$A$22 -> 5.19 | ... L25: =L15*$A$22 -> 5.34
A26: 4 | B26: =B16*0.5 -> 10 | C26: =C16*$A$22 -> 4.32 | D26: =D16*$A$22 -> 4.86 | E26: =E16*$A$22 -> 5.52 | F26: =F16*$A$22 -> 5.82 | G26: =G16*$A$22 -> 5.439 | H26: =H16*$A$22 -> 5.82 | I26: =I16*$A$22 -> 4.86 | J26: =J16*$A$22 -> 4.86 | ... L26: =L16*$A$22 -> 5.07
A27: 5 | B27: =B17*0.5 -> 10 | C27: =C17*$A$22 -> 4.08 | D27: =D17*$A$22 -> 4.59 | E27: =E17*$A$22 -> 5.4 | F27: =F17*$A$22 -> 5.76 | G27: =G17*$A$22 -> 5.76 | H27: =H17*$A$22 -> 5.3835 | I27: =I17*$A$22 -> 5.76 | J27: =J17*$A$22 -> 4.59 | ... L27: =L17*$A$22 -> 4.8
A28: 6 | B28: =B18*0.5 -> 10 | C28: =C18*$A$22 -> 3.87 | D28: =D18*$A$22 -> 4.35375 | E28: =E18*$A$22 -> 5.28 | F28: =F18*$A$22 -> 5.7 | G28: =G18*$A$22 -> 5.328 | H28: =H18*$A$22 -> 5.0343 | I28: =I18*$A$22 -> 5.328 | J28: =J18*$A$22 -> 5.7 | ... L28: =L18*$A$22 -> 4.56
A31: $ per tap gained | D31: =Model!M27 -> 0.18 | E31: =Model!M28 -> 0.36 | F31: =Model!M29 -> 1.4666667 | G31: =Model!M27 -> 0.18 | H31: =Model!M27 -> 0.18 | I31: =Model!M27 -> 0.18 | J31: =Model!M27 -> 0.18 | K31: =Model!M30 -> 0.26666667 | L31: =Model!M31 -> 0.44666667 | M31: Costs
C32: Nothing | D32: Spouts | E32: CV | F32: D1 | G32: D2 | H32: D3 | I32: D4 | J32: D5 | K32: Clean | L32: Clean+Spout
A33: 1 | D33: =D23-$C23 -> 0 | E33: =E23-$C23 -> 0 | F33: =F23-$C23 -> 0 | G33: =G23-$C23 -> 0 | H33: =H23-$C23 -> 0 | I33: =I23-$C23 -> 0 | J33: =J23-$C23 -> 0 | K33: =K23-$C23 -> 0 | L33: =L23-$C23 -> 0
A34: 2 | D34: =D24-$C24 -> 0.42 | E34: =E24-$C24 -> 0.63 | F34: =F24-$C24 -> 0.81 | G34: =G24-$C24 -> 0.42 | H34: =H24-$C24 -> 0.42 | I34: =I24-$C24 -> 0.42 | J34: =J24-$C24 -> 0.42 | K34: =K24-$C24 -> 0.33 | L34: =L24-$C24 -> 0.51
A35: 3 | D35: =D25-$C25 -> 0.51 | E35: =E25-$C25 -> 0.96 | F35: =F25-$C25 -> 1.2 | G35: =G25-$C25 -> 1.2 | H35: =H25-$C25 -> 0.51 | I35: =I25-$C25 -> 0.51 | J35: =J25-$C25 -> 0.51 | K35: =K25-$C25 -> 0.42 | L35: =L25-$C25 -> 0.66
A36: 4 | D36: =D26-$C26 -> 0.54 | E36: =E26-$C26 -> 1.2 | F36: =F26-$C26 -> 1.5 | G36: =G26-$C26 -> 1.119 | H36: =H26-$C26 -> 1.5 | I36: =I26-$C26 -> 0.54 | J36: =J26-$C26 -> 0.54 | K36: =K26-$C26 -> 0.45 | L36: =L26-$C26 -> 0.75
A37: 5 | D37: =D27-$C27 -> 0.51 | E37: =E27-$C27 -> 1.32 | F37: =F27-$C27 -> 1.68 | G37: =G27-$C27 -> 1.68 | H37: =H27-$C27 -> 1.3035 | I37: =I27-$C27 -> 1.68 | J37: =J27-$C27 -> 0.51 | K37: =K27-$C27 -> 0.39 | L37: =L27-$C27 -> 0.72
A38: 6 | D38: =D28-$C28 -> 0.48375 | E38: =E28-$C28 -> 1.41 | F38: =F28-$C28 -> 1.83 | G38: =G28-$C28 -> 1.458 | H38: =H28-$C28 -> 1.1643 | I38: =I28-$C28 -> 1.458 | J38: =J28-$C28 -> 1.83 | K38: =K28-$C28 -> 0.33 | L38: =L28-$C28 -> 0.69
A41: Net Profit ($)
C42: Nothing | D42: Spouts | E42: CV | F42: D1 | G42: D2 | H42: D3 | I42: D4 | J42: D5 | K42: Clean | L42: Clean+Spout
A43: 1 | D43: 0 | E43: 0 | F43: 0 | G43: 2 Yr | H43: 3 Yr | I43: 4 Yr | J43: 5 Yr | K43: 0 | L43: 0
A44: 2 | D44: =D34-D$31 -> 0.24 | E44: =E34-E$31 -> 0.27 | F44: =F34-F$31 -> -0.65666667 | G44: =G34-G$31 -> 0.24 | H44: =H34-H$31 -> 0.24 | I44: =I34-I$31 -> 0.24 | J44: =J34-J$31 -> 0.24 | K44: =K34-K$31 -> 0.063333333 | L44: =L34-L$31 -> 0.063333333
A45: 3 | D45: =D35-D$31 -> 0.33 | E45: =E35-E$31 -> 0.6 | F45: =F35-F$31 -> -0.26666667 | G45: =G35-Model!$M$29 -> -0.26666667 | H45: =H35-H$31 -> 0.33 | I45: =I35-I$31 -> 0.33 | J45: =J35-J$31 -> 0.33 | K45: =K35-K$31 -> 0.15333333 | L45: =L35-L$31 -> 0.21333333
A46: 4 | D46: =D36-D$31 -> 0.36 | E46: =E36-E$31 -> 0.84 | F46: =F36-F$31 -> 0.033333333 | G46: =G36-G$31 -> 0.939 | H46: =H36-Model!$M$29 -> 0.033333333 | I46: =I36-I$31 -> 0.36 | J46: =J36-J$31 -> 0.36 | K46: =K36-K$31 -> 0.18333333 | L46: =L36-L$31 -> 0.30333333
A47: 5 | D47: =D37-D$31 -> 0.33 | E47: =E37-E$31 -> 0.96 | F47: =F37-F$31 -> 0.21333333 | G47: =G37-Model!$M$29 -> 0.21333333 | H47: =H37-H$31 -> 1.1235 | I47: =I37-Model!$M$29 -> 0.21333333 | J47: =J37-J$31 -> 0.33 | K47: =K37-K$31 -> 0.12333333 | L47: =L37-L$31 -> 0.27333333
A48: 6 | D48: =D38-D$31 -> 0.30375 | E48: =E38-E$31 -> 1.05 | F48: =F38-F$31 -> 0.36333333 | G48: =G38-G$31 -> 1.278 | H48: =H38-H$31 -> 0.9843 | I48: =I38-I$31 -> 1.278 | J48: =J38-Model!$M$29 -> 0.36333333 | K48: =K38-K$31 -> 0.063333333 | L48: =L38-L$31 -> 0.24333333
...

Sheet Model
B1: Effects of Spout and Drop Sanitation Strategy on Sap Yield and Net Profit
B2: Hover here for description of Fig. 1. | V2: Hover here for description of Fig. 3.
X4: LABOR CALCULATIONS
X5: Drop Assembly Labor Calculations
X6: Pay rate/hr | Y6: 10
X7: Number drops made/hr | Y7: 60
X8: Number drops made/min | Y8: =Y7/60 -> 1
X9: Assembly cost per drop | Y9: =Y6/Y7 -> 0.16666667
X11: Drop Installation Labor Calculations
X12: Pay rate/hr | Y12: 10
X13: Number drops installed/hr | Y13: 20
X14: Number drops installed/min | Y14: =Y13/60 -> 0.33333333
X15: Installation cost per tap | Y15: =Y12/Y13 -> 0.5
X17: Cleaning Labor Calculations
X18: Pay rate/hr | Y18: 10
B19: Hover here for description of Fig. 2. | X19: Number drops cleaned/hr | Y19: 60
X20: Number drops cleaned/min | Y20: =Y19/60 -> 1
X21: Cost per tap | Y21: =Y18/Y19 -> 0.16666667
K24: Model Input Variables | P24: <--------------- Materials -------------------------> | S24: <------- Labor -------> | V24: Hover here for description. | X24: LEGEND
S25: (use calculators on right)
K26: STRATEGY COST/TAP | M26: TOTAL COST | O26: Tubing | P26: Tee | Q26: Spout | R26: Sanitizer | S26: Assemble | T26: Install or Clean | X26: S = replace spouts each year
K27: Spout | M27: =SUM(O27:T27) -> 0.18 | N27: = | Q27: 0.18 | X27: CV = use and replace CV spouts each year
K28: CV | M28: =SUM(O28:T28) -> 0.36 | N28: = | Q28: 0.36 | X28: D x 1 = replace drops each year
K29: Drop & Spout | M29: =SUM(O29:T29) -> 1.4666667 | N29: = | O29: 0.3 | P29: 0.32 | Q29: 0.18 | S29: =Y9 -> 0.16666667 | T29: =Y15 -> 0.5 | X29: D x 2 = replace drops every second year
K30: Clean Spouts+Drops | M30: =SUM(O30:T30) -> 0.26666667 | N30: = | R30: 0.1 | T30: =Y21 -> 0.16666667 | X30: D x 3 = replace drops every third year
K31: Clean & Replace | M31: =SUM(O31:T31) -> 0.44666667 | N31: = | Q31: =M27 -> 0.18 | R31: 0.1 | T31: =Y21 -> 0.16666667 | X31: D x 4 = replace drops every fourth year
X32: D x 5 = replace drops every fifth year
K33: Baseline Sap/Tap (gal) | M33: 20 | N33: gal (estimated or actual production of sap first year after re-tubing) | X33: Cln = clean spouts and tubing each year
K34: Value of Sap/Gal ($) | M34: 0.3 | N34: (price per gallon you value your sap) | X34: Cln + S = clean drops & replace spouts each yr
X35: Timothy.Perkins@uvm.edu
