Workbook

Sheet Instructions
A1: Service Center Billing Rate Proposal Worksheet
A2: University of Idaho
A3: FY2014
A5: General Instructions
A6: 1) Fill in only the yellow highlighted areas. Do not enter data in non-highlighted areas
A7: 2) Use this worksheet for one fund only (there may be multiple budgets associated with the fund or only one)
A9: The following worksheets (see worksheet tabs below) are designed to assist in the calculation of the Service Center Billing Rates. Detailed explanations are included as comments in the worksheets. Please do them in order.
A11: The proposal contains the following worksheets with named tabs. Please fill them out in order.
A13: 1. General Info - provides contact and service center application information
A14: 2. Budget Info - provides budget information about the service center
A15: 3. Salaries - provides a calculation of the salaries & benefits included in the proposal.
A16: 4. Operating Costs - lists the non-salary and non-depreciation costs included in the proposal.
... A23: 11. SCC Notes - this is for the use of the Service Center Committee to track status of request

Sheet General Info
A1: General Information - Service Center Application | I1: =Instructions!A3 -> FY2014
A3: Instructions
A4: Fill in the yellow highlighted areas
A7: New Application
A8: Renewal
B9: (Indicate one of the above)
A11: College/Division
A12: Department
A13: Service Center Name
A15: Contact Information (Worksheet preparer)
A16: Name
A17: Email
A18: Phone #
A20: College Fiscal Contact
A21: Name
A22: Email
A23: Phone #
A25: Financially Responsible Person for the Service Center
... A37: No
A38: Yes | C38: If Yes, what percent?
A40: Description of the product(s) or service(s) to be provided
A43: Do competitors exist outside of the UI?
A44: No
A45: Yes
A46: If yes, briefly describe how the service center rates compare to market rates
A49: Does the service center provide services to certain users at discounted rates or free of charge?
A50: Same fee charged to everyone
A51: Different fees to differnent users
A52: If different fees, please elaborate
A55: Source of start-up (seed) money. (Complete this field if reporting a new service center. Include budget numbers and dollar amounts.
A56: Budget
A57: Amount
... A60: Budget

Sheet Budget Info
A1: Budget and Fund Information | I1: =Instructions!A3 -> FY2014
A3: Instructions
B4: Fill in the yellow highlighted areas
B5: Service Name (short) - A short name of the service. For example: copier chgs, field tests, etc.
C7: Service Center Name | D7: ='General Info'!B13
C8: Fund #*
A11: Describe the service(s) for each rate offered
E12: Current Rate (if applicable) | H12: Proposed New Rate
C13: Service Name (short) | D13: Brief description of the service | E13: FY2013 | F13: Unit* | G13: Estmated # of annual units | H13: FY2014
B14: 1)
B15: 2)
F16: *Unit is how the rate is charged such as per hour, each, etc.
E20: Most Recent Complete Fiscal Year Information (Statement of Changes - FWRDSTR)
A21: List all budgets associated with the fund number above | H21: Most recent fiscal year used | I21: FY2013
B23: Budget Number | C23: Budget Name | E23: Previous FY Carryover | F23: Revenue | G23: Expenditures | H23: Transfers | I23: Ending Balance
A24: Operating budget
A25: Budget | E25: 0 | F25: 0 | G25: 0 | H25: 0 | I25: =E25+F25-G25-H25 -> 0
A26: Budget | E26: 0 | F26: 0 | G26: 0 | H26: 0 | I26: =E26+F26-G26-H26 -> 0
A27: Budget | E27: 0 | H27: 0 | I27: =E27+F27-G27-H27 -> 0
A28: Budget | E28: 0 | H28: 0 | I28: =E28+F28-G28-H28 -> 0
A29: Budget | E29: 0 | H29: 0 | I29: =E29+F29-G29-H29 -> 0
A30: Budget | H30: 0 | I30: =E30+F30-G30-H30 -> 0
B31: TOTAL OPERATING BUDGET | E31: =SUM(E25:E30) -> 0 | F31: =SUM(F25:F30) -> 0 | G31: =SUM(G25:G30) -> 0 | H31: =SUM(H25:H30) -> 0 | I31: =SUM(I25:I30) -> 0
A32: Equipment replacement reserves*
A33: Budget | E33: 0 | H33: 0 | I33: =E33+F33-G33-H33 -> 0
B34: FUND TOTAL | E34: =E33+E31 -> 0 | F34: =F33+F31 -> 0 | G34: =G33+G31 -> 0 | H34: =H33+H31 -> 0 | I34: =I33+I31 -> 0
A37: *Total amount in equipment reserves can not be greater than the carryover or the allowed equipment inventory total, whichever is less

Sheet Salaries
A1: Service Center Calculations | D1: ='Budget Info'!D8 | K1: =Instructions!A3 -> FY2014
A3: Salaries & Benefits Expenditures
A4: Purpose: To list personnel paid on the service center and allocate personnel costs to each service.
A6: Sheet Instructions
A7: 1) Only fill in the areas shaded in yellow
A8: 2) Fill in the name of the person(s) that is providing the service (board apptd only)
A9: 3) For TH employee costs you may put in a lump sum total for the estimated expenditures.
A10: 4) Fill in that person's PCN
A11: 5) Enter in the employee type | C11: *<<Type is EX for exempt, CL for classified, TH for temporary help, or GA for graduate assistant>>
A12: 6) Enter in the employee's annual salary
A13: 7) Enter in the employee's annual FTE (0.5, 1, 0.75, etc.)
A14: 8) Enter in the FTE % of this employee's time associated with the service and this budget
H16: SERVICE 1 | J16: SERVICE 2
H17: ='Budget Info'!C14 | J17: ='Budget Info'!C15
A18: NAME | B18: PCN | C18: TYPE* | D18: ANNUAL SALARY | E18: FTE | F18: FRINGES | G18: TOTAL COST | H18: FTE % | I18: Amount | J18: FTE % | K18: Amount
D19: 0 | E19: 0 | F19: =IF(D19=0,0,IF(C19="ex",E19*Salaries!$B$40+Salaries!$B$39*Salaries!D19,IF(C19="cl",E19*Salaries!$B$40+Salaries!$B$39*D19,IF(C19="GA",Salaries!$B$42*D19,IF(C19="TH",Salaries!$B$41*D19,"Need TYPE"))))) -> 0 | G19: =F19+D19 -> 0 | H19: 0 | I19: =H19*G19 -> 0 | J19: 0 | K19: =J19*G19 -> 0
D20: 0 | E20: 0 | F20: =IF(D20=0,0,IF(C20="ex",E20*Salaries!$B$40+Salaries!$B$39*Salaries!D20,IF(C20="cl",E20*Salaries!$B$40+Salaries!$B$39*D20,IF(C20="GA",Salaries!$B$42*D20,IF(C20="TH",Salaries!$B$41*D20,"Need TYPE"))))) -> 0 | G20: =F20+D20 -> 0 | H20: 0 | I20: =H20*G20 -> 0 | J20: 0 | K20: =J20*G20 -> 0
D21: 0 | E21: 0 | F21: =IF(D21=0,0,IF(C21="ex",E21*Salaries!$B$40+Salaries!$B$39*Salaries!D21,IF(C21="cl",E21*Salaries!$B$40+Salaries!$B$39*D21,IF(C21="GA",Salaries!$B$42*D21,IF(C21="TH",Salaries!$B$41*D21,"Need TYPE"))))) -> 0 | G21: =F21+D21 -> 0 | H21: 0 | I21: =H21*G21 -> 0 | J21: 0 | K21: =J21*G21 -> 0
D22: 0 | E22: 0 | F22: =IF(D22=0,0,IF(C22="ex",E22*Salaries!$B$40+Salaries!$B$39*Salaries!D22,IF(C22="cl",E22*Salaries!$B$40+Salaries!$B$39*D22,IF(C22="GA",Salaries!$B$42*D22,IF(C22="TH",Salaries!$B$41*D22,"Need TYPE"))))) -> 0 | G22: =F22+D22 -> 0 | H22: 0 | I22: =H22*G22 -> 0 | J22: 0 | K22: =J22*G22 -> 0
D23: 0 | E23: 0 | F23: =IF(D23=0,0,IF(C23="ex",E23*Salaries!$B$40+Salaries!$B$39*Salaries!D23,IF(C23="cl",E23*Salaries!$B$40+Salaries!$B$39*D23,IF(C23="GA",Salaries!$B$42*D23,IF(C23="TH",Salaries!$B$41*D23,"Need TYPE"))))) -> 0 | G23: =F23+D23 -> 0 | H23: 0 | I23: =H23*G23 -> 0 | J23: 0 | K23: =J23*G23 -> 0
D24: 0 | E24: 0 | F24: =IF(D24=0,0,IF(C24="ex",E24*Salaries!$B$40+Salaries!$B$39*Salaries!D24,IF(C24="cl",E24*Salaries!$B$40+Salaries!$B$39*D24,IF(C24="GA",Salaries!$B$42*D24,IF(C24="TH",Salaries!$B$41*D24,"Need TYPE"))))) -> 0 | G24: =F24+D24 -> 0 | H24: 0 | I24: =H24*G24 -> 0 | J24: 0 | K24: =J24*G24 -> 0
D25: 0 | E25: 0 | F25: =IF(D25=0,0,IF(C25="ex",E25*Salaries!$B$40+Salaries!$B$39*Salaries!D25,IF(C25="cl",E25*Salaries!$B$40+Salaries!$B$39*D25,IF(C25="GA",Salaries!$B$42*D25,IF(C25="TH",Salaries!$B$41*D25,"Need TYPE"))))) -> 0 | G25: =F25+D25 -> 0 | H25: 0 | I25: =H25*G25 -> 0 | J25: 0 | K25: =J25*G25 -> 0
D26: 0 | E26: 0 | F26: =IF(D26=0,0,IF(C26="ex",E26*Salaries!$B$40+Salaries!$B$39*Salaries!D26,IF(C26="cl",E26*Salaries!$B$40+Salaries!$B$39*D26,IF(C26="GA",Salaries!$B$42*D26,IF(C26="TH",Salaries!$B$41*D26,"Need TYPE"))))) -> 0 | G26: =F26+D26 -> 0 | H26: 0 | I26: =H26*G26 -> 0 | J26: 0 | K26: =J26*G26 -> 0
D27: 0 | E27: 0 | F27: =IF(D27=0,0,IF(C27="ex",E27*Salaries!$B$40+Salaries!$B$39*Salaries!D27,IF(C27="cl",E27*Salaries!$B$40+Salaries!$B$39*D27,IF(C27="GA",Salaries!$B$42*D27,IF(C27="TH",Salaries!$B$41*D27,"Need TYPE"))))) -> 0 | G27: =F27+D27 -> 0 | H27: 0 | I27: =H27*G27 -> 0 | J27: 0 | K27: =J27*G27 -> 0
D28: 0 | E28: 0 | F28: =IF(D28=0,0,IF(C28="ex",E28*Salaries!$B$40+Salaries!$B$39*Salaries!D28,IF(C28="cl",E28*Salaries!$B$40+Salaries!$B$39*D28,IF(C28="GA",Salaries!$B$42*D28,IF(C28="TH",Salaries!$B$41*D28,"Need TYPE"))))) -> 0 | G28: =F28+D28 -> 0 | H28: 0 | I28: =H28*G28 -> 0 | J28: 0 | K28: =J28*G28 -> 0
D29: 0 | E29: 0 | F29: =IF(D29=0,0,IF(C29="ex",E29*Salaries!$B$40+Salaries!$B$39*Salaries!D29,IF(C29="cl",E29*Salaries!$B$40+Salaries!$B$39*D29,IF(C29="GA",Salaries!$B$42*D29,IF(C29="TH",Salaries!$B$41*D29,"Need TYPE"))))) -> 0 | G29: =F29+D29 -> 0 | H29: 0 | I29: =H29*G29 -> 0 | J29: 0 | K29: =J29*G29 -> 0
D30: 0 | E30: 0 | F30: =IF(D30=0,0,IF(C30="ex",E30*Salaries!$B$40+Salaries!$B$39*Salaries!D30,IF(C30="cl",E30*Salaries!$B$40+Salaries!$B$39*D30,IF(C30="GA",Salaries!$B$42*D30,IF(C30="TH",Salaries!$B$41*D30,"Need TYPE"))))) -> 0 | G30: =F30+D30 -> 0 | H30: 0 | I30: =H30*G30 -> 0 | J30: 0 | K30: =J30*G30 -> 0
A32: TOTAL SALARIES | D32: =SUM(D19:D31) -> 0 | F32: =SUM(F19:F31) -> 0 | G32: =SUM(G19:G31) -> 0 | I32: =SUM(I19:I31) -> 0 | K32: =SUM(K19:K29) -> 0
A34: SUBSIDY - AMOUNT THAT WILL NOT BE CHARGED TO CUSTOMERS | G34: 0 | H34: 0 | I34: =H34*G34 -> 0 | J34: 0 | K34: =J34*G34 -> 0
A36: TOTAL SALARY COSTS CHARGED TO CUSTOMERS | G36: =G32-G34 -> 0 | I36: =I32-I34 -> 0 | K36: =K32-K34 -> 0
A38: Fringe Benefits* | B38: Rate
A39: Variable | B39: 0.245
A40: Fixed (Health) | B40: 9100
A41: TH | B41: 0.0821
A42: GA | B42: 0.0038
A44: *The FB rates can be modified if needed in this rate box

Sheet Operating Costs
A1: Service Center Calculations | B1: ='Budget Info'!D8 | F1: =Instructions!A3 -> FY2014
A3: ANNUAL BUDGETED OPERATING COSTS
A4: Purpose: To detail non-salary and non-equipment costs associated with the service center services
A6: Sheet Instructions
A7: Fill in only the yellow highlighted areas
A8: You may insert additional lines as necessary.
C9: SERVICE 1 | E9: SERVICE 2
A10: Travel | C10: ='Budget Info'!$C$14 | E10: ='Budget Info'!$C$15
A11: Description | B11: Annual Amt | C11: % | D11: Amount | E11: % | F11: Amount
B12: 0 | C12: 0 | D12: =$B12*C12 -> 0 | E12: 0 | F12: =$B12*E12 -> 0
B13: 0 | C13: 0 | D13: =$B13*C13 -> 0 | E13: 0 | F13: =$B13*E13 -> 0
B14: 0 | C14: 0 | D14: =$B14*C14 -> 0 | E14: 0 | F14: =$B14*E14 -> 0
B15: 0 | C15: 0 | D15: =$B15*C15 -> 0 | E15: 0 | F15: =$B15*E15 -> 0
A17: SUBTOTAL TRAVEL | B17: =SUM(B12:B16) -> 0 | D17: =SUM(D12:D15) -> 0 | F17: =SUM(F12:F15) -> 0
A19: SUBSIDY - AMOUNT THAT WILL NOT BE CHARGED TO CUSTOMERS | B19: 0 | C19: 0 | D19: =C19*B19 -> 0 | E19: 0 | F19: =E19*B19 -> 0
A21: TOTAL TRAVEL | B21: =B17-B19 -> 0 | D21: =D17-D19 -> 0 | F21: =F17-F19 -> 0
C24: SERVICE 1 | E24: SERVICE 2
A25: Operating Expenses | C25: ='Budget Info'!$C$14 | E25: ='Budget Info'!$C$15
A26: Description | B26: Annual Amt | C26: % | D26: Amount | E26: % | F26: Amount
A27: 0 | B27: 0 | C27: 0 | D27: =$B27*C27 -> 0 | E27: 0 | F27: =$B27*E27 -> 0
A28: 0 | B28: 0 | C28: 0 | D28: =$B28*C28 -> 0 | E28: 0 | F28: =$B28*E28 -> 0
A29: 0 | B29: 0 | C29: 0 | D29: =$B29*C29 -> 0 | E29: 0 | F29: =$B29*E29 -> 0
C30: 0 | D30: =$B30*C30 -> 0 | E30: 0 | F30: =$B30*E30 -> 0
C31: 0 | D31: =$B31*C31 -> 0 | E31: 0 | F31: =$B31*E31 -> 0
A33: SUBTOTAL OPERATING EXPENSES | B33: =SUM(B27:B32) -> 0 | D33: =SUM(D28:D31) -> 0 | F33: =SUM(F28:F31) -> 0
A35: SUBSIDY - AMOUNT THAT WILL NOT BE CHARGED TO CUSTOMERS | B35: 0 | C35: 0 | D35: =C35*B35 -> 0 | E35: 0 | F35: =E35*B35 -> 0
A37: SUBTOTAL OPERATING EXPENSES | B37: =B33-B35 -> 0 | D37: =D33-D35 -> 0 | F37: =F33-F35 -> 0
C40: SERVICE 1 | E40: SERVICE 2
A41: Equipment < $5,000* | C41: ='Budget Info'!$C$14 | E41: ='Budget Info'!$C$15
A42: Description | B42: Annual Amt | C42: % | D42: Amount | E42: % | F42: Amount
A43: Equipment - non R&R | B43: 0 | C43: 0 | D43: =$B43*C43 -> 0 | E43: 0 | F43: =$B43*E43 -> 0
B44: 0 | C44: 0 | D44: =$B44*C44 -> 0 | E44: 0 | F44: =$B44*E44 -> 0
B45: 0 | C45: 0 | D45: =$B45*C45 -> 0 | E45: 0 | F45: =$B45*E45 -> 0
B46: 0 | C46: 0 | D46: =$B46*C46 -> 0 | E46: 0 | F46: =$B46*E46 -> 0
B47: 0 | C47: 0 | D47: =$B47*C47 -> 0 | E47: 0 | F47: =$B47*E47 -> 0
B48: 0 | C48: 0 | D48: =$B48*C48 -> 0 | E48: 0 | F48: =$B48*E48 -> 0
B49: 0 | C49: 0 | D49: =$B49*C49 -> 0 | E49: 0 | F49: =$B49*E49 -> 0
A51: SUBTOTAL EQUIPMENT <$5,000 | B51: =SUM(B43:B50) -> 0 | D51: =SUM(D43:D50) -> 0 | F51: =SUM(F43:F50) -> 0
A53: SUBSIDY - AMOUNT THAT WILL NOT BE CHARGED TO CUSTOMERS | B53: 0 | C53: 0 | D53: =$B53*C53 -> 0 | E53: 0 | F53: =E53*B53 -> 0
A55: SUBTOTAL EQUIPMENT <$5,000> | B55: =B51-B53 -> 0 | D55: =D51-D53 -> 0 | F55: =F51-F53 -> 0
...

Sheet Capital Equip Depreciation
A1: Service Center Calculations | D1: ='Budget Info'!D8 | M1: =Instructions!A3 -> FY2014
A3: DEPRECIATION OF EQUIPMENT > $5,000
A4: The purpose of this sheet is to track depreciation costs of capitalized equipment used to provide the service(s)
A5: If you have any questions about the accounting for equipment >$5,000 for this service center, please contact the Controller's Office
A8: Sheet instructions
A9: Fill in only yellow highlighted areas in both sections as applicable
A10: Column J - Identify the % of use of the equipment for each service
A11: Add additional lines as needed
A14: SERVICE CENTER EQUIPMENT INFORMATION
J16: SERVICE 1 | L16: SERVICE 2
A17: Depreciation Schedule - List existing allowable equipment only* | J17: ='Budget Info'!C14 | L17: ='Budget Info'!C15
A18: Desc/Type of Equipment | B18: UI Property Tag# | C18: Acquisition Budget No. | D18: Acquistion Date | E18: Depr Start Date | F18: Depr End Date | G18: Acquisition Cost | H18: Useful Life (years) | I18: Annual depreciation | J18: % | K18: Amount | L18: % | M18: Amount
G19: 0 | H19: 0 | I19: =IF(G19=0,0,G19/H19) -> 0 | J19: 0 | K19: =I19*J19 -> 0 | L19: 0 | M19: =L19*I19 -> 0
G20: 0 | H20: 0 | I20: =IF(G20=0,0,G20/H20) -> 0 | J20: 0 | K20: =I20*J20 -> 0 | L20: 0 | M20: =L20*I20 -> 0
G21: 0 | H21: 0 | I21: =IF(G21=0,0,G21/H21) -> 0 | J21: 0 | K21: =I21*J21 -> 0 | L21: 0 | M21: =L21*I21 -> 0
G22: 0 | H22: 0 | I22: =IF(G22=0,0,G22/H22) -> 0 | J22: 0 | K22: =I22*J22 -> 0 | L22: 0 | M22: =L22*I22 -> 0
G23: 0 | H23: 0 | I23: =IF(G23=0,0,G23/H23) -> 0 | J23: 0 | K23: =I23*J23 -> 0 | L23: 0 | M23: =L23*I23 -> 0
G24: 0 | H24: 0 | I24: =IF(G24=0,0,G24/H24) -> 0 | J24: 0 | K24: =I24*J24 -> 0 | L24: 0 | M24: =L24*I24 -> 0
G25: 0 | H25: 0 | I25: =IF(G25=0,0,G25/H25) -> 0 | J25: 0 | K25: =I25*J25 -> 0 | L25: 0 | M25: =L25*I25 -> 0
I26: =IF(G26=0,0,G26/H26) -> 0 | J26: 0 | K26: =I26*J26 -> 0 | L26: 0 | M26: =L26*I26 -> 0
A28: TOTAL ALLOWED DEPRECIATION | G28: =SUM(G19:G27) -> 0 | I28: =SUM(I19:I27) -> 0 | K28: =SUM(K19:K27) -> 0 | M28: =SUM(M19:M27) -> 0
A30: SUBSIDY - AMOUNT THAT WILL NOT BE INCLUDED IN RATE CALCULATIONS | I30: 0 | J30: 0 | K30: =J30*I30 -> 0 | L30: 0 | M30: =L30*I30 -> 0
A32: TOTAL DEPRECIATION TO BE INCLUDED IN SERVICE CENTER COSTS | I32: =I28-I30 -> 0 | K32: =K28-K30 -> 0 | M32: =M28-M30 -> 0
A34: *Unallowable equipment replacements include equipment originally purchased on a grant or purchases of new equipment not previously in use by the service center.
F37: Percentage of Use
F38: SERVICE 1 | G38: SERVICE 2
A39: Other Equipment Used to Provide Service But Not Included in the Costs | F39: ='Budget Info'!C14 | G39: ='Budget Info'!C15
A40: Desc/Type of Equipment | B40: U of I Tag Number | C40: Acquisition Budget No. | D40: Acquistion Date | E40: Acquisition Cost | F40: % | G40: %
E41: 0 | F41: 0 | G41: 0
E42: 0 | F42: 0 | G42: 0
E43: 0 | F43: 0 | G43: 0
E44: 0 | F44: 0 | G44: 0
E45: 0 | F45: 0 | G45: 0
E46: 0 | F46: 0 | G46: 0
E47: 0 | F47: 0 | G47: 0
E48: 0 | F48: 0 | G48: 0

Sheet Capital Equip Replacement
A1: Service Center Calculations | H1: ='Budget Info'!D8 | M1: =Instructions!A3 -> FY2014
A3: PURCHASES FOR THE REPLACEMENT OF ALLOWABLE EQUIPMENT >$5,000
A4: PURPOSE: This sheet is used to record the equipment that will be purchased in the upcoming fiscal year, that
B5: 1) are replacements for existing service center equipment
B6: 2) and have allowable depreciation
A8: Sheet instructions
A9: Fill in only yellow highlighted areas in both sections as applicable
A10: Insert additional lines as needed
A12: NEW EQUIPMENT PURCHASES FOR THIS NEXT FISCAL YEAR (PURCHASES OF EQUIPMENT TO REPLACE CURRENT ALLOWABLE EQUIPMENT)*
E15: SERVICE 1 | G15: SERVICE 2
A16: Equipment purchases > $5,000 | E16: ='Budget Info'!C14 | G16: ='Budget Info'!C15
A17: Tag # of existing equipment being replaced | B17: Description of equipment being replaced | C17: General description of the new equipment to be purchased in the coming fiscal year | D17: Estimated cost of new equpment | E17: % | F17: Amount | G17: % | H17: Amount
D18: 0 | E18: 0 | F18: =D18*E18 -> 0 | G18: 0 | H18: =D18*G18 -> 0
D19: 0 | E19: 0 | F19: =D19*E19 -> 0 | G19: 0 | H19: =D19*G19 -> 0
D20: 0 | E20: 0 | F20: =D20*E20 -> 0 | G20: 0 | H20: =D20*G20 -> 0
D21: 0 | E21: 0 | F21: =D21*E21 -> 0 | G21: 0 | H21: =D21*G21 -> 0
E22: 0 | F22: =D22*E22 -> 0 | G22: 0 | H22: =D22*G22 -> 0
E23: 0 | F23: =D23*E23 -> 0 | G23: 0 | H23: =D23*G23 -> 0
E24: 0 | F24: =D24*E24 -> 0 | G24: 0 | H24: =D24*G24 -> 0
E25: 0 | F25: =D25*E25 -> 0 | G25: 0 | H25: =D25*G25 -> 0
A27: SUBTOTAL | D27: =SUM(D18:D26) -> 0 | F27: =SUM(F18:F25) -> 0 | H27: =SUM(H18:H25) -> 0
A29: SUBSIDY | D29: 0 | E29: 0 | F29: =D29*E29 -> 0 | G29: 0 | H29: =D29*G29 -> 0
A31: TOTAL PURCHASES OF EQUIPMENT >$5,000 EACH | D31: =D27-D29 -> 0 | F31: =F27-F29 -> 0 | H31: =H27-H29 -> 0
A33: *See APM20.20 for a description of allowable equipment
A36: Amount of carryover kept on reserve for >$5,000 equipment purchases
C37: Equipment replacement reserve budget (from Budget info)
C39: Equipment reserves | E39: SERVICE 1 | G39: SERVICE 2
E40: ='Budget Info'!C14 | G40: ='Budget Info'!C15
D41: Total | E41: % | F41: Amount | G41: % | H41: Amount
C42: Amount in equipment replacement reserve | D42: ='Budget Info'!I33 -> 0 | F42: =D42*E42 -> 0 | H42: =D42*G42 -> 0
C43: (Can not exceed inventory total (see Capital Equip Depreciation sheet) or carryover total, whichever is less)
A45: **If a service center is building an equipment replacement reserve, that reserve ideally should be in a separate budget within the same fund -- contact the Controller's Office for further help or information

Sheet Add'l Costs
A1: Additional Cost Worksheet | C1: =Instructions!A3 -> FY2014
A2: Purpose: Used to identify other costs that support the service but are paid by other budgets
A4: Sheet Instructions
A5: 1) Fill in only yellow highlighted areas
A6: 2) Additional lines may be inserted as necessary
A8: Description of Cost | B8: Budget Number | C8: Amount
C9: 0
C33: =SUM(C9:C32) -> 0

Sheet Notes
A1: Notes and Comments | E1: =Instructions!A3 -> FY2014
A2: Purpose: To include comments that will help clarify how this rate sheet was developed or provide additional notes about the service center
A4: Sheet Instructions
A5: 1) Fill in only yellow highlighted areas
A6: 2) Additional lines may be inserted as necessary

Sheet Rate Summary
A1: ='General Info'!B13
A2: ='Budget Info'!D8
A3: =Instructions!A3 -> FY2014
A4: Service Center Rate Summary Sheet - Operating Budget
B6: ='Budget Info'!D8 | D6: TOTAL
B7: Service 1 | C7: Service 2
B8: ='Budget Info'!C14 | C8: ='Budget Info'!C15
A9: Prior Year Fund Balance (if applicable) | B9: ='Budget Info'!I31*B20 -> 0 | C9: ='Budget Info'!J31*C20 -> 0 | D9: =SUM(B9:C9) -> 0
A11: ANNUAL COSTS
A12: Salaries and Fringe Benefits | B12: =Salaries!I36 -> 0 | C12: =Salaries!K36 -> 0 | D12: =SUM(B12:C12) -> 0
A13: Travel | B13: ='Operating Costs'!D21 -> 0 | C13: ='Operating Costs'!F21 -> 0 | D13: =SUM(B13:C13) -> 0
A14: Operating Costs | B14: ='Operating Costs'!D37 -> 0 | C14: ='Operating Costs'!F37 -> 0 | D14: =SUM(B14:C14) -> 0
A15: Equipment < $5,000 | B15: ='Operating Costs'!D55 -> 0 | C15: ='Operating Costs'!F55 -> 0 | D15: =SUM(B15:C15) -> 0
A16: Capital equipment depreciation | B16: ='Capital Equip Depreciation'!K32 -> 0 | C16: ='Capital Equip Depreciation'!M32 -> 0 | D16: =SUM(B16:C16) -> 0
A18: TOTAL ANNUAL SERVICE COSTS W/ SUBSIDIES | B18: =SUM(B12:B17) -> 0 | C18: =SUM(C12:C17) -> 0 | D18: =SUM(B18:C18) -> 0
A20: % of Total Costs | B20: =IF(B18=0,0,B18/SUM(B18:C18)) -> 0 | C20: =IF(C18=0,0,C18/SUM(B18:C18)) -> 0 | D20: =SUM(B20:C20) -> 0
A22: Revised Prior Year Balance (Add Deficit, Subtract Surplus) | B22: =-1*B9 -> 0 | C22: =-1*C9 -> 0 | D22: =SUM(B22:C22) -> 0
A23: Estimated 2 months working capital | B23: =B22*0.16 -> 0 | C23: =C22*0.16 -> 0 | D23: =SUM(B23:C23) -> 0
A25: TOTAL REVISED COSTS | B25: =B18+SUM(B22:B23) -> 0 | C25: =C18+SUM(C22:C23) -> 0 | D25: =SUM(B25:C25) -> 0
A27: # of Annual Units | B27: ='Budget Info'!G14 | C27: ='Budget Info'!G15
A28: Unit Base | B28: ='Budget Info'!F14 | C28: ='Budget Info'!F15
A30: CALCULATED RATE PER SERVICE PER UNIT W/ SUBSIDIES | B30: =IF(B27<>0,B25/B27,0) -> #VALUE! | C30: =IF(C27<>0,C25/C27,0) -> #VALUE! | D30: =SUM(B30:C30) -> #VALUE!
A32: UNIT RATE THAT WILL BE CHARGED TO UI DEPARTMENTS | B32: 0 | C32: 0
A35: Current year rates | B35: =B8 | C35: =C8
B36: ='Budget Info'!E14 | C36: ='Budget Info'!E15 | D36: =SUM(B36:C36) -> 0
A39: SUBSIDIES | D39: TOTAL
A40: Salaries | B40: =Salaries!I34 -> 0 | C40: =Salaries!K32 -> 0 | D40: =SUM(B40:C40) -> 0
A41: Travel | B41: ='Operating Costs'!D19 -> 0 | C41: ='Operating Costs'!F19 -> 0 | D41: =SUM(B41:C41) -> 0
A42: Operating Expense | B42: ='Operating Costs'!D35 -> 0 | C42: ='Operating Costs'!F35 -> 0 | D42: =SUM(B42:C42) -> 0
A43: Equipment <$5,000 | B43: ='Operating Costs'!D53 -> 0 | C43: ='Operating Costs'!F53 -> 0 | D43: =SUM(B43:C43) -> 0
A44: Depreciation | B44: ='Capital Equip Depreciation'!K30 -> 0 | C44: ='Capital Equip Depreciation'!M30 -> 0 | D44: =SUM(B44:C44) -> 0
A45: TOTAL SUBSIDIES | B45: =SUM(B40:B44) -> 0 | C45: =SUM(C40:C44) -> 0 | D45: =SUM(B45:C45) -> 0
A47: TOTAL SERVICE COSTS | B47: =B45+B18 -> 0 | C47: =C45+C18 -> 0 | D47: =SUM(B47:C47) -> 0
A49: FULLY COSTED RATES | B49: =B47/B27 -> #VALUE! | C49: =C47/C27 -> #VALUE!

Sheet Budget Summary
A1: Budget Summary
A4: Operating Budget | F4: Capital Budget
A6: Revenue | F6: Revenue
B7: ='Budget Info'!C14 | C7: ='Rate Summary'!B32*'Rate Summary'!B27 -> #VALUE! | G7: Transfer from operating budget | H7: ='Budget Info'!H33*-1 -> 0
B8: ='Budget Info'!C15 | C8: ='Rate Summary'!C32*'Rate Summary'!C27 -> #VALUE! | G8: Carryover | H8: ='Budget Info'!E33 -> 0
B10: Total Revenue | C10: =SUM(C7:C9) -> #VALUE! | H10: =SUM(H7:H9) -> 0
A12: Expenditures | F12: Expenditures
B13: Salaries, Fringes, TH | C13: =SUM('Rate Summary'!B12:C12) -> 0 | G13: Capital Outlay > $5,000 | H13: ='Capital Equip Replacement'!D31 -> 0
B14: Travel | C14: =SUM('Rate Summary'!B13:C13) -> 0
B15: Operating Expenses | C15: =SUM('Rate Summary'!B14:C14) -> 0
B16: Capital Outlay <$5,000 | C16: =SUM('Rate Summary'!B15:C15) -> 0
B17: Transfer to capital budget | C17: =SUM('Rate Summary'!B16:C16) -> 0
B19: Total Expenditures | C19: =SUM(C13:C18) -> 0 | F19: Total Expenditures | H19: =SUM(H13:H18) -> 0
A21: Net | C21: =C10-C19 -> #VALUE! | F21: Net | H21: =H10-H19 -> 0

Sheet SCC Notes
A1: Service Center Committee Notes
A3: Date
A4: Reviewer
B8: Fund | C8: ='Budget Info'!D8
B10: Fund Balance | C10: FYcurrent | D10: FY-1 | E10: FY-2
B11: Beginning Balance
B12: Revenues
B13: Expenditures
B14: Encumbrances
B15: Transfers Out
B17: Ending Balance | C17: =C11+C12-C13-C14-C15 -> 0 | D17: =D11+D12-D13-D14-D15 -> 0 | E17: =E11+E12-E13-E14-E15 -> 0
C20: Recommend approval | D20: Deny
A21: Reviewer recommendation
A24: Date | B24: Comments
