Workbook
Name Text156: 'Cost Share'!#REF!
Name Text157: 'Cost Share'!#REF!
Name Text158: 'Cost Share'!#REF!

Sheet Instructions and Summary
A1: Detailed Budget Justification | G1: OMB Number: 1910-5162
G2: Expiration Date: 01/31/2015
A3: Instructions and Summary
A4: Award Number: | D4: Date of Submission:
A5: Award Recipient: | D5: Form submitted by:
G6: (May be award recipient or sub-recipient)
A7: Please read the instructions on each page (worksheet) before starting. If you have any questions, please ask your DOE contact. It will save you time!
A8: On this form, provide detailed support for the estimated project costs identified for each Category line item within each worksheet (budget items under different tabs). ● The dollar amounts on this page must match the amounts on the associated application. ● The award recipient and each sub-recipient with estimated costs of $100,000 or more must complete this form and ensure it matches the application. ● The total budget presented on this form and on the application must include both Federal (DOE), and Non-Federal (cost share) portions, thereby reflecting TOTAL PROJECT COSTS proposed. ● For costs in each Object Class Category, complete the corresponding worksheet on this form (tab at the bottom of the page). Include a brief narrative explanation of the costs in the "Additional Explanations/Comments" section to justify the costs. ● All costs incurred by the preparer's sub-recipients, vendors, contractors, consultants and Federal Research and Development Centers (FFRDCs), should be entered only in section f. Contractual. All other sections are for the costs of the preparer only. BURDEN DISCLOSURE STATEMENT Public reporting burden for this collection of information is estimated to average 3 hours per response, including the time for reviewing instructions, searching existing data sources, gathering and maintaining the data needed, and completing and reviewing the collection of information. Send comments regarding this burden estimate or any other aspect of this collection of information, including suggestions for reducing this burden, to Office of Information Resources Management Policy, Plans, and Oversight, AD-241-2 - GTN, Paperwork Reduction Project (1910-5162), U.S. Department of Energy 1000 Independence Avenue, S.W., Washington, DC 20585; and to the Office of Management and Budget, Paperwork Reduction Project (1910-5162), Washington, DC 20503.
A10: SUMMARY OF BUDGET CATEGORY COSTS PROPOSED (Note: The values in this summary table are from entries made in each budget category sheet.)
A11: CATEGORY | B11: Budget Period 1 Costs | C11: Budget Period 2 Costs | D11: Budget Period 3 Costs | E11: Total Costs | F11: Project Costs % | G11: Comments (Add comments as needed)
A12: a. Personnel | B12: ='a. Personnel'!E65 -> 0 | C12: ='a. Personnel'!H65 -> 0 | D12: ='a. Personnel'!K65 -> 0 | E12: =SUM(B12:D12) -> 0 | F12: =E12/$E$26 -> #DIV/0!
A13: b. Fringe Benefits | B13: ='b. Fringe'!D10 -> 0 | C13: ='b. Fringe'!G10 -> 0 | D13: ='b. Fringe'!J10 -> 0 | E13: =SUM(B13:D13) -> 0 | F13: =E13/$E$26 -> #DIV/0!
A14: c. Travel | B14: ='c. Travel'!G24 -> 0 | C14: ='c. Travel'!G41 -> 0 | D14: ='c. Travel'!G58 -> 0 | E14: =SUM(B14:D14) -> 0 | F14: =E14/$E$26 -> #DIV/0!
A15: d. Equipment | B15: ='d. Equipment'!D17 -> 0 | C15: ='d. Equipment'!D28 -> 0 | D15: ='d. Equipment'!D41 -> 0 | E15: =SUM(B15:D15) -> 0 | F15: =E15/$E$26 -> #DIV/0!
A16: e. Supplies | B16: ='e. Supplies'!D18 -> 0 | C16: ='e. Supplies'!D31 -> 0 | D16: ='e. Supplies'!D44 -> 0 | E16: =SUM(B16:D16) -> 0 | F16: =E16/$E$26 -> #DIV/0!
A17: f. Contractual
A18: Sub-recipient | B18: ='f. Contractual'!C17 -> 0 | C18: ='f. Contractual'!D17 -> 0 | D18: ='f. Contractual'!E17 -> 0 | E18: =SUM(B18:D18) -> 0 | F18: =E18/$E$26 -> #DIV/0!
A19: Vendor | B19: ='f. Contractual'!C28 -> 0 | C19: ='f. Contractual'!D28 -> 0 | D19: ='f. Contractual'!E28 -> 0 | E19: =SUM(B19:D19) -> 0 | F19: =E19/$E$26 -> #DIV/0!
A20: FFRDC | B20: ='f. Contractual'!C34 -> 0 | C20: ='f. Contractual'!D34 -> 0 | D20: ='f. Contractual'!E34 -> 0 | E20: =SUM(B20:D20) -> 0 | F20: =E20/$E$26 -> #DIV/0!
A21: Total Contractual | B21: =SUM(B18:B20) -> 0 | C21: =SUM(C18:C20) -> 0 | D21: =SUM(D18:D20) -> 0 | E21: =SUM(B21:D21) -> 0 | F21: =E21/$E$26 -> #DIV/0!
A22: g. Construction | B22: ='g. Construction'!B16 -> 0 | C22: ='g. Construction'!B23 -> 0 | D22: ='g. Construction'!B30 -> 0 | E22: =SUM(B22:D22) -> 0 | F22: =E22/$E$26 -> #DIV/0!
A23: h. Other Direct Costs | B23: ='h. Other'!B14 -> 0 | C23: ='h. Other'!B22 -> 0 | D23: ='h. Other'!B30 -> 0 | E23: =SUM(B23:D23) -> 0 | F23: =E23/$E$26 -> #DIV/0!
A24: Total Direct Costs | B24: =B12+B13+B14+B15+B16+B21+B22+B23 -> 0 | C24: =C12+C13+C14+C15+C16+C21+C22+C23 -> 0 | D24: =D12+D13+D14+D15+D16+D21+D22+D23 -> 0 | E24: =E12+E13+E14+E15+E16+E21+E22+E23 -> 0 | F24: =F12+F13+F14+F15+F16+F21+F22+F23 -> #DIV/0!
A25: i. Indirect Charges | B25: ='i. Indirect'!B16 -> 0 | C25: ='i. Indirect'!C16 -> 0 | D25: ='i. Indirect'!D16 -> 0 | E25: =SUM(B25:D25) -> 0 | F25: =E25/$E$26 -> #DIV/0!
A26: Total Project Costs | B26: =B24+B25 -> 0 | C26: =C24+C25 -> 0 | D26: =D24+D25 -> 0 | E26: =E24+E25 -> 0 | F26: =F24+F25 -> #DIV/0!
A28: Additional Explanations/Comments (as necessary)

Sheet a. Personnel
A1: Detailed Budget Justification | L1: ='Instructions and Summary'!G5 -> 0
A2: a. Personnel
A3: PLEASE READ!!! List costs solely for employees of the entity completing this form (award prime recipient or sub-recipient with costs over $100,000). All other personnel costs (for prime's subrecipients or other contractual efforts of the entity preparing this budget) must be included under f. Contractual. This includes all consultants and FFRDCs. Identify positions to be supported. Key personnel should be identified by title. All other personnel should be identified either by title or a group category. State the amounts of time (e.g., hours or % of time) to be expended, the base pay rate (or composite base pay rate for group category), total direct personnel compensation, and identify the rate basis (e.g., actual salary, labor distribution report, technical estimate, state civil service rates, etc.). Add rows as needed. Formulas/calculations will need to be entered by the preparer of this form. Please enter formulas as shown in the example. Include a brief narrative explanation of the costs in the "Additional Explanations/Comments" section to justify the costs.
A6: Task # and Title | B6: Position Title | C6: Budget Period 1 | F6: Budget Period 2 | I6: Budget Period 3 | L6: Project Total Hours | M6: Project Total Dollars | N6: Rate Basis
C7: Time (Hours) | D7: Pay Rate ($/Hr) | E7: Total Budget Period 1 | F7: Time (Hours) | G7: Pay Rate ($/Hr) | H7: Total Budget Period 2 | I7: Time (Hours) | J7: Pay Rate ($/Hr) | K7: Total Budget Period 3
A8: 1. Generation 2A Receiver Design | C8: =SUM(C9:C11) -> 10000 | E8: =SUM(E9:E11) -> 423000 | F8: =SUM(F9:F11) -> 600 | H8: =SUM(H9:H11) -> 24000 | I8: =SUM(I9:I11) -> 800 | K8: =SUM(K9:K11) -> 31000 | L8: =C8+F8+I8 -> 11400 | M8: =E8+H8+K8 -> 478000 | N8: Actual Salary
A9: EXAMPLE | B9: Sr. Engineer | C9: 2000 | D9: 85 | E9: =C9*D9 -> 170000 | F9: 200 | G9: 50 | H9: =F9*G9 -> 10000 | I9: 200 | J9: 50 | K9: =I9*J9 -> 10000 | L9: =C9+F9+I9 -> 2400 | M9: =E9+H9+K9 -> 190000 | N9: Actual Salary
A10: ONLY!!! | B10: Electrical engineers | C10: 6200 | D10: 35 | E10: =C10*D10 -> 217000 | F10: 400 | G10: 35 | H10: =F10*G10 -> 14000 | I10: 600 | J10: 35 | K10: =I10*J10 -> 21000 | L10: =C10+F10+I10 -> 7200 | M10: =E10+H10+K10 -> 252000 | N10: Actual Salary
B11: Technician | C11: 1800 | D11: 20 | E11: =C11*D11 -> 36000 | F11: 0 | G11: 0 | H11: =F11*G11 -> 0 | I11: 0 | J11: 0 | K11: =I11*J11 -> 0 | L11: =C11+F11+I11 -> 1800 | M11: =E11+H11+K11 -> 36000 | N11: Actual Salary
A12: 1. (Task 1 Title) | E12: =C12*D12 -> 0 | H12: =F12*G12 -> 0 | K12: =I12*J12 -> 0 | L12: =SUM(C12+F12+I12) -> 0 | M12: =SUM(E12+H12+K12) -> 0
E13: =C13*D13 -> 0 | H13: =F13*G13 -> 0 | K13: =I13*J13 -> 0 | L13: =SUM(C13+F13+I13) -> 0 | M13: =SUM(E13+H13+K13) -> 0
E14: =C14*D14 -> 0 | H14: =F14*G14 -> 0 | K14: =I14*J14 -> 0 | L14: =SUM(C14+F14+I14) -> 0 | M14: =SUM(E14+H14+K14) -> 0
E15: =C15*D15 -> 0 | H15: =F15*G15 -> 0 | K15: =I15*J15 -> 0 | L15: =SUM(C15+F15+I15) -> 0 | M15: =SUM(E15+H15+K15) -> 0
E16: =C16*D16 -> 0 | H16: =F16*G16 -> 0 | K16: =I16*J16 -> 0 | L16: =SUM(C16+F16+I16) -> 0 | M16: =SUM(E16+H16+K16) -> 0
A17: 2. (Task 2 Title)
E18: =C18*D18 -> 0 | H18: =F18*G18 -> 0 | K18: =I18*J18 -> 0 | L18: =SUM(C18+F18+I18) -> 0 | M18: =SUM(E18+H18+K18) -> 0
E19: =C19*D19 -> 0 | H19: =F19*G19 -> 0 | K19: =I19*J19 -> 0 | L19: =SUM(C19+F19+I19) -> 0 | M19: =SUM(E19+H19+K19) -> 0
A20: 3. (Task 3 Title)
A21: etc. | E21: =C21*D21 -> 0 | H21: =F21*G21 -> 0 | K21: =I21*J21 -> 0 | L21: =SUM(C21+F21+I21) -> 0 | M21: =SUM(E21+H21+K21) -> 0
B65: Total Personnel Costs | C65: =SUM(C12:C64) -> 0 | E65: =SUM(E12:E64) -> 0 | F65: =SUM(F12:F64) -> 0 | H65: =SUM(H12:H64) -> 0 | I65: =SUM(I12:I64) -> 0 | K65: =SUM(K12:K64) -> 0 | L65: =J65+G65+D65 -> 0 | M65: =K65+H65+E65 -> 0
A67: Additional Explanations/Comments (as necessary)

Sheet b. Fringe
A1: Detailed Budget Justification | K1: ='Instructions and Summary'!$G$5 -> 0 | N1: ='Instructions and Summary'!G5 -> 0
A2: b. Fringe Benefits
A3: Please Read!!! Fill out the table below by labor type (add additional rows if necessary). If all employees receive the same fringe benefits, you can show "Total Personnel" in the Labor Type column instead of listing out all personnel separately. If necessary, you can use the box below to provide additional explanation regarding your fringe rate calculation. The rates and how they are applied should not be averaged to get one fringe cost percentage. The fringe benefit rate should be applied to both the Federal Share and Recipient Cost Share. Add rows as needed. If rows are added, formulas/calculations may need to be adjusted by the preparer. Please enter formulas as shown in the example.
A4: Labor Type | B4: Budget Period 1 | E4: Budget Period 2 | H4: Budget Period 3 | K4: Total Project Fringe Benefit Costs
B5: Personnel Costs | C5: Rate | D5: Total | E5: Personnel Costs | F5: Rate | G5: Total | H5: Personnel Costs | I5: Rate | J5: Total
A6: EXAMPLE ONLY: Sr. Engineer | B6: 170000 | C6: 0.2 | D6: =B6*C6 -> 34000 | E6: 10000 | F6: 0.2 | G6: =E6*F6 -> 2000 | H6: 10000 | I6: 0.2 | J6: =H6*I6 -> 2000 | K6: =D6+G6+J6 -> 38000
A7: Total Personnel | D7: =C7*B7 -> 0 | G7: =E7*F7 -> 0 | J7: =H7*I7 -> 0 | K7: =SUM(D7+G7+J7) -> 0
D8: =C8*B8 -> 0 | G8: =E8*F8 -> 0 | J8: =H8*I8 -> 0 | K8: =SUM(D8+G8+J8) -> 0
D9: =C9*B9 -> 0 | G9: =E9*F9 -> 0 | J9: =H9*I9 -> 0 | K9: =SUM(D9+G9+J9) -> 0
A10: Total: | B10: =SUM(B7:B9) -> 0 | D10: =SUM(D7:D9) -> 0 | E10: =SUM(E7:E9) -> 0 | G10: =SUM(G7:G9) -> 0 | H10: =SUM(H7:H9) -> 0 | J10: =SUM(J7:J9) -> 0 | K10: =SUM(D10+G10+J10) -> 0
A13: A federally approved fringe benefit rate agreement, or a proposed rate supported and agreed upon by DOE for estimating purposes is required if reimbursement for fringe benefits is requested. Please check (X) one of the options below and provide the requested information. Calculate the fringe rate and the Total should calculate automatically (if adding rows, ensure the formulas are updated).
A15: ______ A fringe benefit rate has been negotiated with, or approved by, a federal government agency. A copy of the latest rate agreement is included with this application, and will be provided electronically to the Contracting Officer for this project. ______ There is not a current, federally approved rate agreement negotiated and available*. *When this option is checked, the entity preparing this form shall submit a rate proposal in the format provided at the following website, or a format that provides the same level of information; and the rate proposal must support the rates being proposed for use in performance of the proposed project. Go to https://www.eere-pmc.energy.gov/forms.aspx and select Sample Rate Proposal.
A22: Additional Explanation/Comments (as necessary)
A23: Please use this box (or an attachment) to further explain how your total fringe benefits costs were calculated. Your calculations should identify all rates used, along with the base they were applied to (and how the base was derived), and a total for each (along with grand total).

Sheet c. Travel
A1: Detailed Budget Justification | H1: ='Instructions and Summary'!G5 -> 0
A2: c. Travel
A3: PLEASE READ!!! Provide travel detail as requested below, identifying total Foreign and Domestic Travel as separate items. Purpose of travel are items such as professional conference, DOE sponsored meeting, project management meeting, etc. The Basis for Estimating Costs are items such as past trips, current quotations, Federal Travel Regulations, etc. All listed travel must be necessary for performance of the Statement of Project Objectives. Add rows as needed. If rows are added, formulas/calculations may need to be adjusted by the preparer.
A5: Purpose of travel | B5: Depart From | C5: Destination | D5: No. of Days | E5: No. of Travelers | F5: Cost per Traveler | G5: Cost per Trip | H5: Basis for Estimating Costs
A6: Budget Period 1
A7: Domestic Travel
A8: EXAMPLE ONLY!!! Visit to PV cell mfr. to set up vendor agreement | D8: 2 | E8: 2 | F8: 650 | G8: =F8*E8 -> 1300 | H8: Internet prices
G9: =F9*E9 -> 0
G10: =F10*E10 -> 0
G11: =F11*E11 -> 0
G12: =F12*E12 -> 0
G13: =F13*E13 -> 0
G14: =F14*E14 -> 0
G15: =F15*E15 -> 0
G16: =F16*E16 -> 0
A17: Domestic Travel subtotal | G17: =SUM(G9:G16) -> 0
A18: International Travel
G19: =F19*E19 -> 0
G20: =F20*E20 -> 0
G21: =F21*E21 -> 0
G22: =F22*E22 -> 0
A23: International Travel subtotal | G23: =SUM(G19:G22) -> 0
A24: Budget Period 1 Total | G24: =G17+G23 -> 0
A25: Budget Period 2
A26: Domestic Travel
G27: =F27*E27 -> 0
G28: =F28*E28 -> 0
G29: =F29*E29 -> 0
G30: =F30*E30 -> 0
G31: =F31*E31 -> 0
G32: =F32*E32 -> 0
G33: =F33*E33 -> 0
A34: Domestic Travel subtotal | G34: =SUM(G27:G33) -> 0
A35: International Travel
G36: =F36*E36 -> 0
G37: =F37*E37 -> 0
G38: =F38*E38 -> 0
G39: =F39*E39 -> 0
A40: International Travel subtotal | G40: =SUM(G36:G39) -> 0
A41: Budget Period 2 Total | G41: =G34+G40 -> 0
...

Sheet d. Equipment
A1: Detailed Budget Justification | F1: ='Instructions and Summary'!G5 -> 0
A2: d. Equipment
A3: PLEASE READ!!! Equipment is generally defined as an item with an acquisition cost greater than $5,000 and a useful life expectancy of more than one year. Further definitions can be found at 10 CFR 600 found on the PMC Recipient Resources Forms page at https://www.eere-pmc.energy.gov/Forms.aspx#regs . List all proposed equipment below, providing a basis of cost such as vendor quotes, catalog prices, prior invoices, etc.; and briefly justify its need as it applies to the Statement of Project Objectives. If it is existing equipment, and the value of its contribution to the project budget is being shown as cost share, provide logical support for the estimated value shown. If it is new equipment which will retain a useful life upon completion of the project, provide logical support for the estimated value shown. For equipment over $50,000 in price, also include a copy of the associated vendor quote or catalog price list. Add rows as needed. If rows are added, formulas/calculations may need to be adjusted by the preparer.
A5: Equipment Item | B5: Qty | C5: Unit Cost | D5: Total Cost | E5: Basis of Cost | F5: Justification of need
A6: Budget Period 1
A7: EXAMPLE ONLY!!! Thermal shock chamber | B7: 2 | C7: 20000 | D7: =B7*C7 -> 40000 | E7: Vendor Quote | F7: Reliability testing of PV modules- Task 4.3
D8: =B8*C8 -> 0
D9: =B9*C9 -> 0
D10: =B10*C10 -> 0
D11: =B11*C11 -> 0
D12: =B12*C12 -> 0
D13: =B13*C13 -> 0
D14: =B14*C14 -> 0
D15: =B15*C15 -> 0
D16: =B16*C16 -> 0
A17: Budget Period 1 Total | D17: =SUM(D8:D16) -> 0
A18: Budget Period 2
D19: =B19*C19 -> 0
D20: =B20*C20 -> 0
D21: =B21*C21 -> 0
D22: =B22*C22 -> 0
D23: =B23*C23 -> 0
D24: =B24*C24 -> 0
D25: =B25*C25 -> 0
D26: =B26*C26 -> 0
D27: =B27*C27 -> 0
A28: Budget Period 2 Total | D28: =SUM(D19:D27) -> 0
A29: Budget Period 3
D30: =B30*C30 -> 0
D31: =B31*C31 -> 0
D32: =B32*C32 -> 0
D33: =B33*C33 -> 0
D34: =B34*C34 -> 0
D35: =B35*C35 -> 0
D36: =B36*C36 -> 0
D37: =B37*C37 -> 0
D38: =B38*C38 -> 0
D39: =B39*C39 -> 0
D40: =B40*C40 -> 0
A41: Budget Period 3 Total | D41: =SUM(D30:D40) -> 0
...

Sheet e. Supplies
A1: Detailed Budget Justification | F1: ='Instructions and Summary'!G5 -> 0
A2: e. Supplies
A3: PLEASE READ!!! Supplies are generally defined as an item with an acquisition cost of $5,000 or less and a useful life expectancy of less than one year. Supplies are generally consumed during the project performance. Further definitions can be found at 10 CFR 600 found on the PMC Recipient Resources Forms page at https://www.eere-pmc.energy.gov/Forms.aspx#regs. List all proposed supplies below, providing a bases of costs such as vendor quotes, catalog prices, prior invoices, etc.; and briefly justify the need for the Supplies as they apply to the Statement of Project Objectives. Note that Supply items must be direct costs to the project at this budget category, and not duplicative of supply costs included in the indirect pool that is the basis of the indirect rate applied for this project. Add rows as needed. If rows are added, formulas/calculations may need to be adjusted by the preparer.
A5: General Category of Supplies | B5: Qty | C5: Unit Cost | D5: Total Cost | E5: Basis of Cost | F5: Justification of need
A6: Budget Period 1
A7: EXAMPLE ONLY!!! Wireless DAS components | B7: 10 | C7: 360 | D7: 3600 | E7: Catalog price | F7: For Alpha prototype - Task 2.4
D8: =B8*C8 -> 0
D9: =B9*C9 -> 0
D10: =B10*C10 -> 0
D11: =B11*C11 -> 0
D12: =B12*C12 -> 0
D13: =B13*C13 -> 0
D14: =B14*C14 -> 0
D15: =B15*C15 -> 0
D16: =B16*C16 -> 0
D17: =B17*C17 -> 0
A18: Budget Period 1 Total | D18: =SUM(D8:D17) -> 0
A19: Budget Period 2
D20: =B20*C20 -> 0
D21: =B21*C21 -> 0
D22: =B22*C22 -> 0
D23: =B23*C23 -> 0
D24: =B24*C24 -> 0
D25: =B25*C25 -> 0
D26: =B26*C26 -> 0
D27: =B27*C27 -> 0
D28: =B28*C28 -> 0
D29: =B29*C29 -> 0
D30: =B30*C30 -> 0
A31: Budget Period 2 Total | D31: =SUM(D20:D30) -> 0
A32: Budget Period 3
D33: =B33*C33 -> 0
D34: =B34*C34 -> 0
D35: =B35*C35 -> 0
D36: =B36*C36 -> 0
D37: =B37*C37 -> 0
D38: =B38*C38 -> 0
D39: =B39*C39 -> 0
D40: =B40*C40 -> 0
D41: =B41*C41 -> 0
...

Sheet f. Contractual
A1: Detailed Budget Justification | D1: ='Instructions and Summary'!G5 -> 0
A2: f. Contractual
A3: PLEASE READ!!! The entity completing this form must provide all costs related to sub-recipients, vendors, contractors, consultants and FFRDC partners in the applicable boxes below. Sub-recipients (partners, sub-awardees): For each sub-recipient with total project costs of $100,000 or more, a separate budget form and justification must be submitted. These sub-recipient forms may be completed by either the sub-recipients themselves or by the preparer of this form. The budget totals on the sub-recipient's forms must match the sub-recipeint entries below. The preparer of this form need only provide further support of the completed sub-recipient budget forms as they deem necessary. The support to justify the budgets of sub-recipients with estimated costs less than $100,000 may be in any format, and at a minimum should provide what Statement of Project Objectives task(s) are being performed, the purpose/need for the effort, and a basis of the estimated costs that is considered sufficient for DOE evaluation.
A4: Vendors (includes contractors and consultants): List all vendors, contractors and consultants supplying commercial supplies or services used to support the project. The support to justify vendor costs (in any amount) should provide the purpose for the products or services and a basis of the estimated costs that is considered sufficient for DOE evaluation. Federal Research and Development Centers (FFRDCs): For FFRDC partners, the award recipient will provide a Field Work Proposal (if not already provided with the original application), along with the FFRDC labor mix and hours, by category and FFRDC major purchases greater than $25,000, including Quantity, Unit Cost, Basis of Cost, and Justification. The award recipient may allow the FFRDC to provide this information directly to DOE. Add rows as needed. If rows are added, formulas/calculations may need to be adjusted by the preparer.
A7: Sub-Recipient Name/Organization | B7: Purpose/Tasks in SOPO | C7: Budget Period 1 Costs | D7: Budget Period 2 Costs | E7: Budget Period 3 Costs | F7: Project Total
A8: EXAMPLE ONLY!!! XYZ Corp. | B8: Partner to develop optimal fresnel lens for Gen 2 product - Task 2.4 | C8: 48000 | D8: 32000 | E8: 16000 | F8: =SUM(C8:E8) -> 96000 | G8: =IF(F8>100000,"Separate budget forms required for this sub-recipient!", " ")
F9: =SUM(C9:E9) -> 0 | G9: =IF(F9>=100000,"Separate budget forms required for this sub-recipient!", " ")
F10: =SUM(C10:E10) -> 0 | G10: =IF(F10>100000,"Separate budget forms required for this sub-recipient!", " ")
F11: =SUM(C11:E11) -> 0 | G11: =IF(F11>100000,"Separate budget forms required for this sub-recipient!", " ")
F12: =SUM(C12:E12) -> 0 | G12: =IF(F12>100000,"Separate budget forms required for this sub-recipient!", " ")
F13: =SUM(C13:E13) -> 0 | G13: =IF(F13>100000,"Separate budget forms required for this sub-recipient!", " ")
F14: =SUM(C14:E14) -> 0 | G14: =IF(F14>100000,"Separate budget forms required for this sub-recipient!", " ")
F15: =SUM(C15:E15) -> 0 | G15: =IF(F15>100000,"Separate budget forms required for this sub-recipient!", " ")
F16: =SUM(C16:E16) -> 0 | G16: =IF(F16>100000,"Separate budget forms required for this sub-recipient!", " ")
B17: Sub-total | C17: =SUM(C9:C16) -> 0 | D17: =SUM(D9:D16) -> 0 | E17: =SUM(E9:E15) -> 0 | F17: =SUM(F9:F16) -> 0
A19: Vendor Name/Organization | B19: Product or Service, Purpose/Need and Basis of Cost (Provide additional support at bottom of page as needed) | C19: Budget Period 1 Costs | D19: Budget Period 2 Costs | E19: Budget Period 3 Costs | F19: Project Total
A20: EXAMPLE ONLY!!! ABC Corp. | B20: Vendor for developing custom robotics to perform lens inspection, alignment, and placement (Task 4 ). Required for expanding CPV module mfg. capacity. Cost is from competitive quotes. | C20: 32900 | D20: 86500 | F20: =SUM(C20:E20) -> 119400
F21: =SUM(C21:E21) -> 0
F22: =SUM(C22:E22) -> 0
F23: =SUM(C23:E23) -> 0
F24: =SUM(C24:E24) -> 0
F25: =SUM(C25:E25) -> 0
F26: =SUM(C26:E26) -> 0
F27: =SUM(C27:E27) -> 0
B28: Sub-total | C28: =SUM(C21:C27) -> 0 | D28: =SUM(D21:D27) -> 0 | E28: =SUM(E21:E27) -> 0 | F28: =SUM(F21:F27) -> 0
A30: FFRDC Name/Organization | B30: Purpose | C30: Budget Period 1 Costs | D30: Budget Period 2 Costs | E30: Budget Period 3 Costs | F30: Project Total
F31: =SUM(C31:E31) -> 0
F32: =SUM(C32:E32) -> 0
F33: =SUM(C33:E33) -> 0
B34: Sub-total | C34: =SUM(C31:C33) -> 0 | D34: =SUM(D31:D33) -> 0 | E34: =SUM(E31:E33) -> 0 | F34: =SUM(C34:E34) -> 0
A36: Total Contractual | C36: =C28+C34+C17 -> 0 | D36: =D28+D34+D17 -> 0 | E36: =E28+E34+E17 -> 0 | F36: =F28+F34+F17 -> 0
A38: AdditionalExplanations/Comments (as necessary)

Sheet g. Construction
A1: Detailed Budget Justification | D1: ='Instructions and Summary'!G5 -> 0
A2: g. Construction
A3: PLEASE READ!!! Construction, for the purpose of budgeting, is defined as all types of work done on a particular building, including erecting, altering, or remodeling. Construction conducted by the award recipient is entered on this page. Any construction work that is performed by a vendor or subrecipient to the award recipient should be entered under f. Contractual. List all proposed construction below, providing a basis of cost such as engineering estimates, prior construction, etc., and briefly justify its need as it applies to the Statement of Project Objectives. Add rows as needed. If rows are added, formulas/calculations may need to be adjusted by the preparer.
A5: Overall description of construction actiivities:
A6: Example Only!!! - Build wind turbine platform
A8: General Description | B8: Cost | C8: Basis of Cost | D8: Justification of need
A9: Budget Period 1
A10: Three days of excavation for platform site EXAMPLE ONLY!!! | B10: 28000 | C10: Engineering estimate | D10: Site must be prepared for construction of platform.
A16: Budget Period 1 Total | B16: =SUM(B11:B15) -> 0
A17: Budget Period 2
A23: Budget Period 2 Total | B23: =SUM(B18:B22) -> 0
A24: Budget Period 3
A30: Budget Period 3 Total | B30: =SUM(B25:B29) -> 0
A31: PROJECT TOTAL | B31: =-B30+B23+B16 -> 0
A33: Additional Explanations/Comments (as necessary)

Sheet h. Other
A1: Detailed Budget Justification | D1: ='Instructions and Summary'!G5 -> 0
A2: h. Other Direct Costs
A3: PLEASE READ!!! Other direct costs are direct cost items required for the project which do not fit clearly into other categories. These direct costs must not be included in the indirect costs (for which the indirect rate is being applied for this project). Examples are: equipment costs less than $5000, meetings within the scope of work, printing costs, etc. which can be directly charged to the project and are not duplicated in indirect costs (overhead costs). Basis of cost are items such as vendor quotes, prior purchases of similar or like items, published price list, etc. Add rows as needed. If rows are added, formulas/calculations may need to be adjusted by the preparer.
A5: General description | B5: Cost | C5: Basis of Cost | D5: Justification of need
A6: Budget Period 1
A7: EXAMPLE ONLY!!! Grad student tuition | B7: 16000 | C7: Established UCD costs | D7: Support of graduate students working on project
A14: Budget Period 1 Total | B14: =SUM(B8:B13) -> 0
A15: Budget Period 2
A22: Budget Period 2 Total | B22: =SUM(B16:B21) -> 0
A23: Budget Period 3
A30: Budget Period 3 Total | B30: =SUM(B24:B29) -> 0
A31: PROJECT TOTAL | B31: =B30+B22+B14 -> 0
A33: Additional Explanations/Comments (as necessary)

Sheet i. Indirect
A1: Detailed Budget Justification | F1: ='Instructions and Summary'!$G$5 -> 0
C2: i. Indirect Costs
A3: Please Read!!! Fill out the table below to indicate how your indirect costs are calculated. If necessary, you can use the box below to provide additional explanation regarding your indirect rate calculation. The rates and how they are applied should not be averaged to get one indirect cost percentage. The indirect rate should be applied to both the Federal Share and Recipient Cost Share. Add rows as needed. If rows are added, formulas/calculations may need to be adjusted by the preparer. Please enter formulas as shown in the example.
B5: Budget Period 1 | C5: Budget Period 2 | D5: Budget Period 3 | E5: Total | F5: Explanation of BASE
A6: Provide ONLY Applicable Rates:
A7: Overhead Rate | B7: 0 | C7: 0 | D7: 0
A8: General & Administrative (G&A) | B8: 0 | C8: 0 | D8: 0
A9: FCCM Rate, if applicable | B9: 0 | C9: 0 | D9: 0
A10: OTHER Indirect Rate | B10: 0 | C10: 0 | D10: 0
A11: Indirect Costs (As Applicable):
A12: Overhead Costs | B12: 0 | C12: 0 | D12: 0 | E12: =SUM(B12:D12) -> 0
A13: G&A Costs | B13: 0 | C13: =0*C8 -> 0 | D13: 0 | E13: =SUM(B13:D13) -> 0
A14: FCCM Costs, if applicable | B14: 0 | C14: 0 | D14: =0*D9 -> 0 | E14: =SUM(B14:D14) -> 0
A15: OTHER Indirect Costs | B15: 0 | C15: =0*C10 -> 0 | D15: =0*D10 -> 0 | E15: =SUM(B15:D15) -> 0
A16: Total indirect costs requested: | B16: =SUM(B12:B15) -> 0 | C16: =SUM(C12:C15) -> 0 | D16: =SUM(D12:D15) -> 0 | E16: =SUM(E12:E15) -> 0
A18: A federally approved indirect rate agreement, or rate proposed (supported and agreed upon by DOE for estimating purposes) is required if reimbursement of indirect costs is requested. Please check (X) one of the options below and provide the requested information if it has not already been provided as requested, or has changed. Calculate the indirect rate dollars and the totals should calculate automatically.
A19: ______ An indirect rate has been approved or negotiated with a federal government agency. A copy of the latest rate agreement is included with this application, and will be provided electronically to the Contracting Officer for this project. ______ There is not a current, federally approved rate agreement negotiated and available*. *When this option is checked, the entity preparing this form shall submit an indirect rate proposal in the format provided at the following website, or a format that provides the same level of information and which will support the rates being proposed for use in performance of the proposed project. Go to https://www.eere-pmc.energy.gov/forms.aspx and select Sample Rate Proposal.
A26: Additional Explanations/Comments (as necessary)
A27: *IMPORTANT: Please use this box (or an attachment) to further explain how your total indirect costs were calculated. If the total indirect costs are a cumulative amount of more than one calculation or rate application, the explanation and calculations should identify all rates used, along with the base they were applied to (and how the base was derived), and a total for each (along with grand total).

Sheet Cost Share
A1: Detailed Budget Justification | E1: ='Instructions and Summary'!G5 -> 0
A2: Cost Share
A3: PLEASE READ!!! A detailed presentation of the cash or cash value of all cost share proposed for the project must be provided in the table below. Identify the source & amount of each item of cost share proposed by the award recipient and each sub-recipient or vendor. Letters of commitment must be submitted for all third party cost share (other than award recipient). Note that “cost-share" is not limited to cash investment. Other items that may be assigned value in a budget if incurred as part of the project budget and are necessary to the performance of the project. Items that may be considered as cost share include: contribution of services or property; donated, purchased or existing equipment; donated, purchased or existing supplies; and/or unrecovered personnel, fringe benefits and indirect costs, etc. For each cost share contribution identified as other than cash, identify the item and describe how the value of the cost share contribution was calculated.
A4: Funds from other Federal sources MAY NOT be counted as cost share. This prohibition includes FFRDC sub-recipients. Non-Federal sources include private, state or local Government, or any source not originally derived from Federal funds. Documentation of cost sharing commitments must be provided, if not already provided with the original application and they have not changed since its submission. Fee or profit will not be paid to the award recipients or subrecipients of financial assistance awards. Additionally, foregone fee or profit by the applicant shall not be considered cost sharing under any resulting award. Reimbursement of actual costs will only include those costs that are allowable and allocable to the project as determined in accordance with the applicable cost principles prescribed in 10 CFR 600.127, 10 CFR 600.222 or 10 CFR 600.317. Also see 10 CFR 600.318 relative to profit or fee. Add rows as needed. If rows are added, formulas/calculations may need to be adjusted by the preparer.
A6: Organization/Source | B6: Type (cash or other) | C6: Cost Share Item | D6: Budget Period 1 Cost Share | E6: Budget Period 2 Cost Share | F6: Budget Period 3 Cost Share | G6: Total Project Cost Share
A7: ABC Company EXAMPLE ONLY!!! | B7: Cash | C7: Project partner ABC Company will provide 40 PV modules for product development at 50% off the of the retail price of $680 | D7: 13600 | G7: =SUM(D7:F7) -> 13600
G8: =SUM(D8:F8) -> 0
G9: =SUM(D9:F9) -> 0
G10: =SUM(D10:F10) -> 0
G11: =SUM(D11:F11) -> 0
G12: =SUM(D12:F12) -> 0
G13: =SUM(D13:F13) -> 0
G14: =SUM(D14:F14) -> 0
G15: =SUM(D15:F15) -> 0
G16: =SUM(D16:F16) -> 0
G17: =SUM(D17:F17) -> 0
C18: Totals | D18: =SUM(D8:D17) -> 0 | E18: =SUM(E7:E17) -> 0 | F18: =SUM(F7:F17) -> 0 | G18: =SUM(G8:G17) -> 0
A20: Total Project Cost: | C20: ='Instructions and Summary'!E26 -> 0 | D20: Cost Share Percent of Award: | G20: =G18/C20 -> #DIV/0!
A22: Additional Explanations/Comments (as necessary)

Sheet SF-424A
A1: Applicant Name: | E1: Award Number:
A2: Budget Information - Non Construction Programs
A3: OMB Approval No. 0348-0044
A4: Section A - Budget Summary
B5: Grant Program Function or Activity | C5: Catalog of Federal Domestic Assistance Number | D5: Estimated Unobligated Funds | F5: New or Revised Budget
D6: Federal | E6: Non-Federal | F6: Federal | G6: Non-Federal | H6: Total
B7: (a) | C7: (b) | D7: (c ) | E7: (d) | F7: (e) | G7: (f) | H7: (g)
A8: 1. | B8: Budget period 1 | F8: =D26-G8 -> 0 | G8: ='Cost Share'!D18 -> 0 | H8: =SUM(D8:G8) -> 0
A9: 2. | B9: Budget period 2 | F9: =E26-G9 -> 0 | G9: ='Cost Share'!E18 -> 0 | H9: =SUM(D9:G9) -> 0
A10: 3. | B10: Budget period 3 | F10: =F26-'Cost Share'!F18 -> 0 | G10: ='Cost Share'!F18 -> 0 | H10: =SUM(D10:G10) -> 0
A11: 4. | H11: =SUM(D11:G11) -> 0
A12: 5. | B12: Totals | D12: =SUM(D8:D11) -> 0 | E12: =SUM(E8:E11) -> 0 | F12: =SUM(F8:F11) -> 0 | G12: =SUM(G8:G11) -> 0 | H12: =SUM(H8:H11) -> 0
A13: Section B - Budget Categories
A14: 6. | B14: Object Class Categories | D14: Grant Program, Function or Activity | H14: Total (5)
D15: Budget period 1 | E15: Budget period 2 | F15: Budget period 3 | G15: (4)
B16: a. Personnel | D16: ='Instructions and Summary'!B12 -> 0 | E16: ='Instructions and Summary'!C12 -> 0 | F16: ='Instructions and Summary'!D12 -> 0 | H16: =SUM(D16:G16) -> 0
B17: b. Fringe Benefits | D17: ='Instructions and Summary'!B13 -> 0 | E17: ='Instructions and Summary'!C13 -> 0 | F17: ='Instructions and Summary'!D13 -> 0 | H17: =SUM(D17:G17) -> 0
B18: c. Travel | D18: ='Instructions and Summary'!B14 -> 0 | E18: ='Instructions and Summary'!C14 -> 0 | F18: ='Instructions and Summary'!D14 -> 0 | H18: =SUM(D18:G18) -> 0
B19: d. Equipment | D19: ='Instructions and Summary'!B15 -> 0 | E19: ='Instructions and Summary'!C15 -> 0 | F19: ='Instructions and Summary'!D15 -> 0 | H19: =SUM(D19:G19) -> 0
B20: e. Supplies | D20: ='Instructions and Summary'!B16 -> 0 | E20: ='Instructions and Summary'!C16 -> 0 | F20: ='Instructions and Summary'!D16 -> 0 | H20: =SUM(D20:G20) -> 0
B21: f. Contractual | D21: ='Instructions and Summary'!B21 -> 0 | E21: ='Instructions and Summary'!C21 -> 0 | F21: ='Instructions and Summary'!D21 -> 0 | H21: =SUM(D21:G21) -> 0
B22: g. Construction | D22: ='Instructions and Summary'!B22 -> 0 | E22: ='Instructions and Summary'!C22 -> 0 | F22: ='Instructions and Summary'!D22 -> 0 | H22: =SUM(D22:G22) -> 0
B23: h. Other | D23: ='Instructions and Summary'!B23 -> 0 | E23: ='Instructions and Summary'!C23 -> 0 | F23: ='Instructions and Summary'!D23 -> 0 | H23: =SUM(D23:G23) -> 0
B24: i. Total Direct Charges (sum of 6a-6h) | D24: =SUM(D16:D23) -> 0 | E24: =SUM(E16:E23) -> 0 | F24: =SUM(F16:F23) -> 0 | G24: =SUM(G16:G23) -> 0 | H24: =SUM(D24:G24) -> 0
B25: j. Indirect Charges | D25: ='Instructions and Summary'!B25 -> 0 | E25: ='Instructions and Summary'!C25 -> 0 | F25: ='Instructions and Summary'!D25 -> 0 | H25: =SUM(D25:G25) -> 0
B26: k. Totals (sum of 6i-6j) | D26: =SUM(D24:D25) -> 0 | E26: =SUM(E24:E25) -> 0 | F26: =SUM(F24:F25) -> 0 | G26: =SUM(G24:G25) -> 0 | H26: =SUM(H24:H25) -> 0
A28: 7. | B28: Program Income | H28: =SUM(D28:G28) -> 0
H30: SF-424A (Rev. 4-92)
A31: Previous Edition Usable | G31: Prescribed by OMB Circular A-102
A32: Authorized for Local Reproduction
A34: Section C - Non-Federal Resources
B35: (a) Grant Program | E35: (b) Applicant | F35: (c ) State | G35: (d) Other Sources | H35: (e) Totals
A36: 8. | B36: Budget period 1 | H36: =SUM(E36:G36) -> 0
A37: 9. | B37: Budget period 2 | H37: =SUM(E37:G37) -> 0
A38: 10. | B38: Budget period 3 | H38: =SUM(E38:G38) -> 0
A39: 11. | H39: =SUM(E39:G39) -> 0
A40: 12. | B40: Total (sum of lines 8 - 11) | E40: =SUM(E36:E39) -> 0 | F40: =SUM(F36:F39) -> 0 | G40: =SUM(G36:G39) -> 0 | H40: =SUM(H36:H39) -> 0
A41: Section D - Forecasted Cash Needs
D42: Total for 1st Year | E42: 1st Quarter | F42: 2nd Quarter | G42: 3rd Quarter | H42: 4th quarter
A43: 13. | B43: Federal | D43: =SUM(E43:H43) -> 0
...
