Workbook

Sheet Data
B1: YEAR | C1: PROGRAM | D1: Program Completers | E1: Respondents | F1: Respondents Employed, Related To Training | G1: Median Hourly Wage | H1: Respondents Employed, Unrelated To Training | I1: Total Employed | J1: Unemployed, Seeking Employment | K1: Unemployed, Not Seeking Employment | L1: Military Full-time | M1: Military Part-Time | N1: Total in Military | O1: Continuing Education (Secondary or Post-Secondary) | P1: Apprenticeship related to FRCC taining*(The 2008 survey question is different) | Q1: Apprenticeship unrelated to FRCC taining | R1: Total in Apprenticeships | S1: Took State Licensing Exam | T1: Passed State Licensing Exam | U1: Instructional Program Met Educational Goals
A2: =C2=C37 -> TRUE | B2: 2013 | C2: Total | D2: 2196 | E2: 1239 | F2: 598 | G2: 14.85 | H2: 342 | I2: 940 | J2: 144 | K2: 149 | L2: 9 | M2: 7 | N2: 16 | O2: 629 | P2: 168 | Q2: 76 | R2: 244 | S2: 620 | T2: 601 | U2: 1150 | W2: =S2-E2 -> -619 | X2: =-T2-S2 -> -1221
A3: =C3=C38 -> TRUE | B3: 2013 | C3: Accounting | D3: 62 | E3: 34 | F3: 11 | G3: 15 | H3: 11 | I3: 22 | J3: 5 | K3: 7 | L3: 0 | M3: 0 | N3: 0 | O3: 18 | P3: 4 | Q3: 1 | R3: 5 | S3: 2 | T3: 2 | U3: 31 | W3: =S3-E3 -> -32 | X3: =-T3-S3 -> -4
A4: =C4=C39 -> TRUE | B4: 2013 | C4: Animal Laboratory Technology | D4: 1 | E4: 0 | W4: =S4-E4 -> 0 | X4: =-T4-S4 -> 0
A5: =C5=C40 -> TRUE | B5: 2013 | C5: Applied Technology | D5: 1 | E5: 1 | W5: =S5-E5 -> -1 | X5: =-T5-S5 -> 0
A6: =C6=C41 -> TRUE | B6: 2013 | C6: Architectural Engineering Technology | D6: 16 | E6: 8 | F6: 5 | G6: 15 | H6: 1 | I6: 6 | J6: 1 | K6: 1 | L6: 0 | M6: 0 | N6: 0 | O6: 2 | P6: 0 | Q6: 0 | R6: 0 | S6: 0 | T6: 0 | U6: 7 | W6: =S6-E6 -> -8 | X6: =-T6-S6 -> 0
A7: =C7=C42 -> TRUE | B7: 2013 | C7: Automotive Technology | D7: 114 | E7: 45 | F7: 19 | G7: 12 | H7: 14 | I7: 33 | J7: 6 | K7: 5 | L7: 1 | M7: 0 | N7: 1 | O7: 22 | P7: 3 | Q7: 1 | R7: 4 | S7: 10 | T7: 10 | U7: 44 | W7: =S7-E7 -> -35 | X7: =-T7-S7 -> -20
A8: =C8=C43 -> TRUE | B8: 2013 | C8: Business | D8: 108 | E8: 61 | F8: 32 | G8: 14.13 | H8: 16 | I8: 48 | J8: 8 | K8: 4 | L8: 0 | M8: 1 | N8: 1 | O8: 37 | P8: 7 | Q8: 3 | R8: 10 | S8: 8 | T8: 8 | U8: 57 | W8: =S8-E8 -> -53 | X8: =-T8-S8 -> -16
A9: =C9=C44 -> TRUE | B9: 2013 | C9: CISCO Network Associate | D9: 10 | E9: 6 | F9: 3 | H9: 2 | I9: 5 | J9: 1 | K9: 0 | L9: 0 | M9: 0 | N9: 0 | O9: 1 | P9: 0 | Q9: 1 | R9: 1 | S9: 1 | T9: 1 | U9: 5 | W9: =S9-E9 -> -5 | X9: =-T9-S9 -> -2
A10: =C10=C45 -> TRUE | B10: 2013 | C10: Computer Aided Drafting and Design | D10: 17 | E10: 14 | F10: 5 | G10: 16.25 | H10: 7 | I10: 12 | J10: 2 | K10: 0 | L10: 0 | M10: 0 | N10: 0 | O10: 3 | P10: 1 | Q10: 0 | R10: 1 | S10: 0 | T10: 0 | U10: 12 | W10: =S10-E10 -> -14 | X10: =-T10-S10 -> 0
A11: =C11=C46 -> TRUE | B11: 2013 | C11: Computer Information Systems | D11: 169 | E11: 112 | F11: 39 | G11: 18 | H11: 30 | I11: 69 | J11: 25 | K11: 18 | L11: 0 | M11: 0 | N11: 0 | O11: 61 | P11: 8 | Q11: 4 | R11: 12 | S11: 23 | T11: 20 | U11: 96 | W11: =S11-E11 -> -89 | X11: =-T11-S11 -> -43
A12: =C12=C47 -> TRUE | B12: 2013 | C12: Dental Assisting | D12: 28 | E12: 23 | F12: 15 | G12: 14 | H12: 4 | I12: 19 | J12: 2 | K12: 2 | L12: 0 | M12: 0 | N12: 0 | O12: 11 | P12: 2 | Q12: 1 | R12: 3 | S12: 0 | T12: 0 | U12: 22 | W12: =S12-E12 -> -23 | X12: =-T12-S12 -> 0
A13: =C13=C48 -> TRUE | B13: 2013 | C13: Early Childhood Education | D13: 52 | E13: 28 | F13: 23 | G13: 12.5 | H13: 1 | I13: 24 | J13: 1 | K13: 3 | L13: 0 | M13: 0 | N13: 0 | O13: 9 | P13: 4 | Q13: 0 | R13: 4 | S13: 4 | T13: 4 | U13: 28 | W13: =S13-E13 -> -24 | X13: =-T13-S13 -> -8
A14: =C14=C49 -> TRUE | B14: 2013 | C14: Emergency Medical Services | D14: 325 | E14: 152 | F14: 56 | G14: 12.25 | H14: 59 | I14: 115 | J14: 18 | K14: 18 | L14: 3 | M14: 2 | N14: 5 | O14: 88 | P14: 44 | Q14: 10 | R14: 54 | S14: 129 | T14: 122 | U14: 149 | W14: =S14-E14 -> -23 | X14: =-T14-S14 -> -251
A15: =C15=C50 -> TRUE | B15: 2013 | C15: Energy Technology | D15: 35 | E15: 31 | F15: 14 | G15: 18 | H15: 10 | I15: 24 | J15: 7 | K15: 0 | L15: 0 | M15: 0 | N15: 0 | O15: 10 | P15: 4 | Q15: 0 | R15: 4 | S15: 5 | T15: 5 | U15: 26 | W15: =S15-E15 -> -26 | X15: =-T15-S15 -> -10
A16: =C16=C51 -> TRUE | B16: 2013 | C16: Forestry-Wildlife & Natural Resources | D16: 63 | E16: 27 | F16: 3 | H16: 12 | I16: 15 | J16: 5 | K16: 7 | L16: 0 | M16: 1 | N16: 1 | O16: 18 | P16: 8 | Q16: 1 | R16: 9 | S16: 1 | T16: 1 | U16: 26 | W16: =S16-E16 -> -26 | X16: =-T16-S16 -> -2
A17: =C17=C52 -> TRUE | B17: 2013 | C17: Geographic Information System | D17: 62 | E17: 37 | F17: 15 | G17: 17.15 | H17: 13 | I17: 28 | J17: 6 | K17: 3 | L17: 0 | M17: 0 | N17: 0 | O17: 11 | P17: 3 | Q17: 1 | R17: 4 | S17: 0 | T17: 0 | U17: 32 | W17: =S17-E17 -> -37 | X17: =-T17-S17 -> 0
A18: =C18=C53 -> TRUE | B18: 2013 | C18: Health Information Technologies | D18: 9 | E18: 4
A19: =C19=C54 -> TRUE | B19: 2013 | C19: Heating, Ventilation & Air Cond | D19: 17 | E19: 16 | F19: 13 | G19: 20.5 | H19: 0 | I19: 13 | J19: 2 | K19: 1 | L19: 0 | M19: 0 | N19: 0 | O19: 2 | P19: 7 | Q19: 0 | R19: 7 | S19: 13 | T19: 13 | U19: 15 | W19: =S19-E19 -> -3 | X19: =-T19-S19 -> -26
A20: =C20=C55 -> TRUE | B20: 2013 | C20: Holistic Health | D20: 37 | E20: 25 | F20: 6 | H20: 5 | I20: 11 | J20: 1 | K20: 13 | L20: 0 | M20: 0 | N20: 0 | O20: 17 | P20: 5 | Q20: 4 | R20: 9 | S20: 6 | T20: 6 | U20: 24 | W20: =S20-E20 -> -19 | X20: =-T20-S20 -> -12
A21: =C21=C56 -> TRUE | B21: 2013 | C21: Horticulture & Landscape Tech | D21: 18 | E21: 15 | F21: 14 | G21: 14.35 | H21: 0 | I21: 14 | J21: 0 | K21: 1 | L21: 0 | M21: 0 | N21: 0 | O21: 2 | P21: 3 | Q21: 0 | R21: 3 | S21: 1 | T21: 1 | U21: 15 | W21: =S21-E21 -> -14 | X21: =-T21-S21 -> -2
A22: =C22=C57 -> TRUE | B22: 2013 | C22: Hospitality/ Food Management | D22: 17 | E22: 7 | F22: 5 | H22: 2 | I22: 7 | J22: 0 | K22: 0 | L22: 0 | M22: 0 | N22: 0 | O22: 2 | P22: 0 | Q22: 1 | R22: 1 | S22: 1 | T22: 1 | U22: 5 | W22: =S22-E22 -> -6 | X22: =-T22-S22 -> -2
A23: =C23=C58 -> TRUE | B23: 2013 | C23: Interior Design | D23: 12 | E23: 10 | F23: 7 | G23: 17 | H23: 2 | I23: 9 | J23: 0 | K23: 1 | L23: 0 | M23: 0 | N23: 0 | O23: 0 | P23: 1 | Q23: 2 | R23: 3 | S23: 3 | T23: 3 | U23: 10 | W23: =S23-E23 -> -7 | X23: =-T23-S23 -> -6
A24: =C24=C59 -> TRUE | B24: 2013 | C24: Interpreter Preparation | D24: 14 | E24: 4 | W24: =S24-E24 -> -4 | X24: =-T24-S24 -> 0
A25: =C25=C60 -> TRUE | B25: 2013 | C25: Legal Assistant / Paralegal | D25: 34 | E25: 24 | F25: 9 | G25: 15.25 | H25: 8 | I25: 17 | J25: 5 | K25: 2 | L25: 0 | M25: 0 | N25: 0 | O25: 11 | P25: 4 | Q25: 0 | R25: 4 | S25: 1 | T25: 1 | U25: 19 | W25: =S25-E25 -> -23 | X25: =-T25-S25 -> -2
A26: =C26=C61 -> TRUE | B26: 2013 | C26: Machining Technology | W26: =S26-E26 -> 0 | X26: =-T26-S26 -> 0
A27: =C27=C62 -> TRUE | B27: 2013 | C27: Medical Office Technology | D27: 45 | E27: 27 | F27: 14 | G27: 12.465 | H27: 6 | I27: 20 | J27: 5 | K27: 2 | L27: 0 | M27: 0 | N27: 0 | O27: 10 | P27: 3 | Q27: 3 | R27: 6 | S27: 14 | T27: 14 | U27: 24 | W27: =S27-E27 -> -13 | X27: =-T27-S27 -> -28
A28: =C28=C63 -> TRUE | B28: 2013 | C28: Multimedia Graphic Design | D28: 56 | E28: 26 | F28: 11 | G28: 15.5 | H28: 7 | I28: 18 | J28: 4 | K28: 4 | L28: 0 | M28: 0 | N28: 0 | O28: 9 | P28: 4 | Q28: 1 | R28: 5 | S28: 0 | T28: 0 | U28: 20 | W28: =S28-E28 -> -26 | X28: =-T28-S28 -> 0
A29: =C29=C64 -> TRUE | B29: 2013 | C29: Nurse Aide | D29: 422 | E29: 232 | F29: 98 | G29: 11.5 | H29: 78 | I29: 176 | J29: 22 | K29: 32 | L29: 0 | M29: 2 | N29: 2 | O29: 158 | P29: 17 | Q29: 27 | R29: 44 | S29: 191 | T29: 189 | U29: 223 | W29: =S29-E29 -> -41 | X29: =-T29-S29 -> -380
A30: =C30=C65 -> TRUE | B30: 2013 | C30: Pharmacy Technician | D30: 54 | E30: 31 | F30: 10 | G30: 13.75 | H30: 13 | I30: 23 | J30: 5 | K30: 3 | L30: 1 | M30: 0 | N30: 1 | O30: 8 | P30: 1 | Q30: 1 | R30: 2 | S30: 25 | T30: 23 | U30: 25 | W30: =S30-E30 -> -6 | X30: =-T30-S30 -> -48
A31: =C31=C66 -> TRUE | B31: 2013 | C31: Phlebotomy | D31: 55 | E31: 32 | F31: 15 | G31: 13 | H31: 9 | I31: 24 | J31: 2 | K31: 6 | L31: 2 | M31: 0 | N31: 2 | O31: 15 | P31: 6 | Q31: 3 | R31: 9 | S31: 6 | T31: 6 | U31: 30 | W31: =S31-E31 -> -26 | X31: =-T31-S31 -> -12
A32: =C32=C67 -> TRUE | B32: 2013 | C32: Practical Nursing | D32: 47 | E32: 24 | F32: 18 | G32: 21 | H32: 4 | I32: 22 | J32: 1 | K32: 0 | L32: 0 | M32: 0 | N32: 0 | O32: 13 | P32: 0 | Q32: 1 | R32: 1 | S32: 22 | T32: 22 | U32: 21 | W32: =S32-E32 -> -2 | X32: =-T32-S32 -> -44
A33: =C33=C68 -> TRUE | B33: 2013 | C33: Registered Nursing | D33: 167 | E33: 109 | F33: 94 | G33: 25 | H33: 8 | I33: 102 | J33: 2 | K33: 5 | L33: 0 | M33: 0 | N33: 0 | O33: 45 | P33: 16 | Q33: 6 | R33: 22 | S33: 109 | T33: 107 | U33: 107 | W33: =S33-E33 -> 0 | X33: =-T33-S33 -> -216
A34: =C34=C69 -> TRUE | B34: 2013 | C34: Teaching English as a Second Language | D34: 7 | E34: 5 | F34: 0 | H34: 3 | I34: 3 | J34: 0 | K34: 2 | L34: 0 | M34: 0 | N34: 0 | O34: 2 | P34: 4 | Q34: 0 | R34: 4 | S34: 0 | T34: 0 | U34: 4 | W34: =S34-E34 -> -5 | X34: =-T34-S34 -> 0
A35: =C35=C70 -> TRUE | B35: 2013 | C35: Veterinary Technology | D35: 57 | E35: 22 | F35: 12 | G35: 13 | H35: 4 | I35: 16 | J35: 1 | K35: 5 | L35: 0 | M35: 0 | N35: 0 | O35: 8 | P35: 3 | Q35: 1 | R35: 4 | S35: 17 | T35: 16 | U35: 22 | W35: =S35-E35 -> -5 | X35: =-T35-S35 -> -33
A36: =C36=C71 -> TRUE | B36: 2013 | C36: Welding Technology | D36: 65 | E36: 47 | F36: 25 | G36: 16 | H36: 12 | I36: 37 | J36: 6 | K36: 4 | L36: 2 | M36: 1 | N36: 3 | O36: 32 | P36: 2 | Q36: 1 | R36: 3 | S36: 23 | T36: 21 | U36: 42 | W36: =S36-E36 -> -24 | X36: =-T36-S36 -> -44
A37: =C37=C72 -> TRUE | B37: 2012 | C37: TOTAL | D37: 2257 | E37: 1515 | F37: 720 | G37: 14 | H37: 477 | I37: 1197 | J37: 150 | K37: 160 | L37: 4 | M37: 16 | N37: 20 | O37: 729 | P37: 229 | Q37: 57 | R37: 286 | S37: 906 | T37: 872 | U37: 1417 | W37: =S37-E37 -> -609 | X37: =-T37-S37 -> -1778
A38: =C38=C73 -> TRUE | B38: 2012 | C38: Accounting | D38: 88 | E38: 67 | F38: 28 | G38: 17.13 | H38: 23 | I38: 51 | J38: 10 | K38: 6 | N38: 0 | O38: 26 | P38: 3 | Q38: 1 | R38: 4 | S38: 8 | T38: 8 | U38: 61 | W38: =S38-E38 -> -59 | X38: =-T38-S38 -> -16
A39: =C39=C74 -> TRUE | B39: 2012 | C39: Animal Laboratory Technology | D39: 1 | E39: 1 | W39: =S39-E39 -> -1 | X39: =-T39-S39 -> 0
A40: =C40=C75 -> TRUE | B40: 2012 | C40: Applied Technology | D40: 2 | E40: 2 | W40: =S40-E40 -> -2 | X40: =-T40-S40 -> 0
...

Sheet Pivot Data
B3: Values
A4: Row Labels | B4: Sum of Program Completers | C4: Sum of Respondents | D4: Sum of Total Employed | E4: Sum of Median Hourly Wage | F4: Sum of Total in Military | G4: Sum of Continuing Education (Secondary or Post-Secondary) | H4: Sum of Total in Apprenticeships | I4: Sum of Took State Licensing Exam | J4: Sum of Passed State Licensing Exam | K4: Sum of Instructional Program Met Educational Goals
A5: Total | B5: 13974 | C5: 8317 | D5: 6515 | E5: 105.12 | F5: 126 | G5: 4017 | H5: 1465 | I5: 4507 | J5: 4382 | K5: 7748
A6: 2013 | B6: 2196 | C6: 1239 | D6: 940 | E6: 14.85 | F6: 16 | G6: 629 | H6: 244 | I6: 620 | J6: 601 | K6: 1150
A7: 2012 | B7: 2257 | C7: 1515 | D7: 1197 | E7: 14 | F7: 20 | G7: 729 | H7: 286 | I7: 906 | J7: 872 | K7: 1417
A8: 2011 | B8: 2169 | C8: 1205 | D8: 913 | E8: 14.2 | F8: 17 | G8: 538 | H8: 243 | I8: 765 | J8: 747 | K8: 1079
A9: 2010 | B9: 2072 | C9: 1173 | D9: 880 | E9: 14.7 | F9: 23 | G9: 650 | H9: 263 | I9: 731 | J9: 731 | K9: 1096
A10: 2009 | B10: 1879 | C10: 1119 | D10: 862 | E10: 14.17 | F10: 27 | G10: 575 | H10: 231 | I10: 741 | J10: 709 | K10: 1045
A11: 2008 | B11: 1736 | C11: 1196 | D11: 1013 | E11: 16.86 | F11: 13 | G11: 508 | H11: 198 | I11: 744 | J11: 722 | K11: 1125
A12: 2007 | B12: 1665 | C12: 870 | D12: 710 | E12: 16.34 | F12: 10 | G12: 388 | K12: 836
A13: Accounting | B13: 406 | C13: 286 | D13: 207 | E13: 106.03275 | F13: 2 | G13: 105 | H13: 15 | I13: 22 | J13: 21 | K13: 261
A14: 2013 | B14: 62 | C14: 34 | D14: 22 | E14: 15 | F14: 0 | G14: 18 | H14: 5 | I14: 2 | J14: 2 | K14: 31
A15: 2012 | B15: 88 | C15: 67 | D15: 51 | E15: 17.13 | F15: 0 | G15: 26 | H15: 4 | I15: 8 | J15: 8 | K15: 61
A16: 2011 | B16: 66 | C16: 49 | D16: 32 | E16: 13 | F16: 1 | G16: 14 | H16: 2 | I16: 2 | J16: 1 | K16: 44
A17: 2010 | B17: 46 | C17: 37 | D17: 28 | E17: 12.25 | F17: 1 | G17: 21 | H17: 1 | I17: 7 | J17: 7 | K17: 33
A18: 2009 | B18: 46 | C18: 34 | D18: 21 | E18: 15 | G18: 12 | I18: 1 | J18: 1 | K18: 31
A19: 2008 | B19: 56 | C19: 43 | D19: 35 | E19: 16.93875 | F19: 0 | G19: 10 | H19: 3 | I19: 2 | J19: 2 | K19: 40
A20: 2007 | B20: 42 | C20: 22 | D20: 18 | E20: 16.714 | F20: 0 | G20: 4 | K20: 21
A21: Animal Laboratory Technology | B21: 2 | C21: 1
A22: 2013 | B22: 1 | C22: 0
A23: 2012 | B23: 1 | C23: 1
A24: 2011
A25: 2010
A26: 2009
A27: 2008
A28: 2007
A29: Applied Technology | B29: 9 | C29: 5
A30: 2013 | B30: 1 | C30: 1
A31: 2012 | B31: 2 | C31: 2
A32: 2011 | B32: 3 | C32: 0
A33: 2010 | B33: 2 | C33: 1
A34: 2009 | B34: 1 | C34: 1
A35: 2008
A36: 2007
A37: Architectural Engineering Technology | B37: 110 | C37: 75 | D37: 59 | E37: 70.15 | F37: 0 | G37: 26 | H37: 2 | I37: 6 | J37: 5 | K37: 71
A38: 2013 | B38: 16 | C38: 8 | D38: 6 | E38: 15 | F38: 0 | G38: 2 | H38: 0 | I38: 0 | J38: 0 | K38: 7
A39: 2012 | B39: 17 | C39: 17 | D39: 14 | E39: 18.03 | F39: 0 | G39: 7 | H39: 0 | I39: 2 | J39: 2 | K39: 17
A40: 2011 | B40: 15 | C40: 9 | D40: 7 | F40: 0 | G40: 1 | H40: 0 | I40: 1 | J40: 0 | K40: 8
A41: 2010 | B41: 12 | C41: 8 | D41: 5 | F41: 0 | G41: 2 | H41: 1 | I41: 1 | J41: 1 | K41: 7
A42: 2009 | B42: 20 | C42: 10 | D42: 9 | G42: 6 | I42: 2 | J42: 2 | K42: 10
...

Sheet Chart Titles
D1: =Options!D6 -> TOTAL
D2: TITLE BOX
B5: COMPLETES CHART TITLE
B6: ="Program Completers & Respondents" -> Program Completers & Respondents
B9: RESPONSE RATES CHART TITLE
B10: ="Response Rates" -> Response Rates
B13: TOTAL EMPLOYED CHART TITLE
B14: ="Total Employed %" -> Total Employed %
B17: MEDIAN HOURLY WAGE CHART TITLE
B18: ="Average Hourly Wage" -> Average Hourly Wage
B21: TOTAL IN MILITARY CHART TITLE
B22: ="Total in Military" -> Total in Military
B25: CONTINUING EDUCATION CHART TITLE
B26: ="Students Continuing their Education %" -> Students Continuing their Education %
B29: TOTAL APPRENTICESHIPS CHART TITLE
B30: ="Total Apprenticeships %" -> Total Apprenticeships %
B33: STATE LICENSING EXAM CHART TITLE (TOOK AND PASSED IN ONE CHART)
B34: ="State Licensing Exam" -> State Licensing Exam
B36: INSTRUCTIONAL GOALS MET CHART TITLE
B37: ="Program Met Students Instructional Goals %" -> Program Met Students Instructional Goals %
B39: RESPONSE RATES WITH PROGRAM COMPLETES CHART TITLE
B40: ="Program Completers & Response Rate %" -> Program Completers & Response Rate %

Sheet Options
L3: CHART DATA
C4: AVAILABLE PROGRAMS | D4: SELECTED PROGRAM | F4: AVAILABLE YEARS | G4: SELECTED YEAR | L4: COMPLETES | M4: RESPONDENTS | N4: RESPONSE RATE | O4: TOTAL EMPLOYED | P4: TOTAL EMPLOYED % | Q4: MEDIAN SALARY | R4: TOTAL IN MILITARY | S4: TOTAL IN MILITARY % | T4: TOTAL IN CONTINUING ED | U4: TOTAL CONTIN ED % | V4: TOTAL APPRENTICESHIPS | W4: TOTAL APPRENTICESHIP % | X4: TOOK STATE LICENSING EXAM | Y4: TOOK EXAM % | Z4: PASSED LICENSING EXAM | AA4: PASSED EXAM % | AB4: INSTRUCTIONAL GOALS MET | AC4: GOALS MET %
C5: TOTAL | D5: 1 | F5: 2007 | G5: 1 | I5: =$F5 -> 2007 | L5: =GETPIVOTDATA("Sum of Program Completers",'Pivot Data'!$A$3,"YEAR",$I5,"PROGRAM",$D$6) -> 1665 | M5: =GETPIVOTDATA("Sum of Respondents",'Pivot Data'!$A$3,"YEAR",$I5,"PROGRAM",$D$6) -> 870 | N5: =IF($L5>4,$M5/$L5,"") -> 0.52252252 | O5: =GETPIVOTDATA("Sum of Total Employed",'Pivot Data'!$A$3,"YEAR",$I5,"PROGRAM",$D$6) -> 710 | P5: =IF($M5>4,$O5/$M5, " ") -> 0.81609195 | Q5: =GETPIVOTDATA("Sum of Median Hourly Wage ",'Pivot Data'!$A$3,"YEAR",$I5,"PROGRAM",$D$6) -> 16.34 | R5: =GETPIVOTDATA("Sum of Total in Military",'Pivot Data'!$A$3,"YEAR",$I5,"PROGRAM",$D$6) -> 10 | S5: =IF($M5>4, $R5/$M5, " ") -> 0.011494253 | T5: =GETPIVOTDATA("Sum of Continuing Education (Secondary or Post-Secondary)",'Pivot Data'!$A$3,"YEAR",$I5,"PROGRAM",$D$6) -> 388 | U5: =IF($M5>4, $T5/$M5, " ") -> 0.44597701 | V5: =GETPIVOTDATA("Sum of Total in Apprenticeships",'Pivot Data'!$A$3,"YEAR",$I5,"PROGRAM",$D$6) -> 0 | W5: =IF($M5>4,$V5/$M5,"") -> 0 | X5: =GETPIVOTDATA("Sum of Took State Licensing Exam",'Pivot Data'!$A$3,"YEAR",$I5,"PROGRAM",$D$6) -> 0 | Y5: =IF($M5>4,$X5/$M5, "") -> 0 | Z5: =GETPIVOTDATA("Sum of Passed State Licensing Exam",'Pivot Data'!$A$3,"YEAR",$I5,"PROGRAM",$D$6) -> 0 | AA5: =IF($X5>4, $Z5/$X5, "") | AB5: =GETPIVOTDATA("Sum of Instructional Program Met Educational Goals",'Pivot Data'!$A$3,"YEAR",$I5,"PROGRAM",$D$6) -> 836 | AC5: =IF($M5>4,$AB5/$M5,"") -> 0.96091954
C6: Accounting | D6: =INDEX(C5:C41,D5) -> TOTAL | F6: 2008 | G6: =INDEX(F5:F11,G5) -> 2007 | I6: =$F6 -> 2008 | L6: =GETPIVOTDATA("Sum of Program Completers",'Pivot Data'!$A$3,"YEAR",$I6,"PROGRAM",$D$6) -> 1736 | M6: =GETPIVOTDATA("Sum of Respondents",'Pivot Data'!$A$3,"YEAR",$I6,"PROGRAM",$D$6) -> 1196 | N6: =IF($L6>4,$M6/$L6,"") -> 0.68894009 | O6: =GETPIVOTDATA("Sum of Total Employed",'Pivot Data'!$A$3,"YEAR",$I6,"PROGRAM",$D$6) -> 1013 | P6: =IF($M6>4,$O6/$M6, " ") -> 0.84698997 | Q6: =GETPIVOTDATA("Sum of Median Hourly Wage ",'Pivot Data'!$A$3,"YEAR",$I6,"PROGRAM",$D$6) -> 16.86 | R6: =GETPIVOTDATA("Sum of Total in Military",'Pivot Data'!$A$3,"YEAR",$I6,"PROGRAM",$D$6) -> 13 | S6: =IF($M6>4, $R6/$M6, " ") -> 0.010869565 | T6: =GETPIVOTDATA("Sum of Continuing Education (Secondary or Post-Secondary)",'Pivot Data'!$A$3,"YEAR",$I6,"PROGRAM",$D$6) -> 508 | U6: =IF($M6>4, $T6/$M6, " ") -> 0.42474916 | V6: =GETPIVOTDATA("Sum of Total in Apprenticeships",'Pivot Data'!$A$3,"YEAR",$I6,"PROGRAM",$D$6) -> 198 | W6: =IF($M6>4,$V6/$M6,"") -> 0.16555184 | X6: =GETPIVOTDATA("Sum of Took State Licensing Exam",'Pivot Data'!$A$3,"YEAR",$I6,"PROGRAM",$D$6) -> 744 | Y6: =IF($M6>4,$X6/$M6, "") -> 0.62207358 | Z6: =GETPIVOTDATA("Sum of Passed State Licensing Exam",'Pivot Data'!$A$3,"YEAR",$I6,"PROGRAM",$D$6) -> 722 | AA6: =IF($X6>4, $Z6/$X6, "") -> 0.97043011 | AB6: =GETPIVOTDATA("Sum of Instructional Program Met Educational Goals",'Pivot Data'!$A$3,"YEAR",$I6,"PROGRAM",$D$6) -> 1125 | AC6: =IF($M6>4,$AB6/$M6,"") -> 0.94063545
C7: Animal Laboratory Technology | F7: 2009 | I7: =$F7 -> 2009 | L7: =GETPIVOTDATA("Sum of Program Completers",'Pivot Data'!$A$3,"YEAR",$I7,"PROGRAM",$D$6) -> 1879 | M7: =GETPIVOTDATA("Sum of Respondents",'Pivot Data'!$A$3,"YEAR",$I7,"PROGRAM",$D$6) -> 1119 | N7: =IF($L7>4,$M7/$L7,"") -> 0.59552954 | O7: =GETPIVOTDATA("Sum of Total Employed",'Pivot Data'!$A$3,"YEAR",$I7,"PROGRAM",$D$6) -> 862 | P7: =IF($M7>4,$O7/$M7, " ") -> 0.77033065 | Q7: =GETPIVOTDATA("Sum of Median Hourly Wage ",'Pivot Data'!$A$3,"YEAR",$I7,"PROGRAM",$D$6) -> 14.17 | R7: =GETPIVOTDATA("Sum of Total in Military",'Pivot Data'!$A$3,"YEAR",$I7,"PROGRAM",$D$6) -> 27 | S7: =IF($M7>4, $R7/$M7, " ") -> 0.024128686 | T7: =GETPIVOTDATA("Sum of Continuing Education (Secondary or Post-Secondary)",'Pivot Data'!$A$3,"YEAR",$I7,"PROGRAM",$D$6) -> 575 | U7: =IF($M7>4, $T7/$M7, " ") -> 0.51385165 | V7: =GETPIVOTDATA("Sum of Total in Apprenticeships",'Pivot Data'!$A$3,"YEAR",$I7,"PROGRAM",$D$6) -> 231 | W7: =IF($M7>4,$V7/$M7,"") -> 0.20643432 | X7: =GETPIVOTDATA("Sum of Took State Licensing Exam",'Pivot Data'!$A$3,"YEAR",$I7,"PROGRAM",$D$6) -> 741 | Y7: =IF($M7>4,$X7/$M7, "") -> 0.66219839 | Z7: =GETPIVOTDATA("Sum of Passed State Licensing Exam",'Pivot Data'!$A$3,"YEAR",$I7,"PROGRAM",$D$6) -> 709 | AA7: =IF($X7>4, $Z7/$X7, "") -> 0.95681511 | AB7: =GETPIVOTDATA("Sum of Instructional Program Met Educational Goals",'Pivot Data'!$A$3,"YEAR",$I7,"PROGRAM",$D$6) -> 1045 | AC7: =IF($M7>4,$AB7/$M7,"") -> 0.93386953
C8: Applied Technology | F8: 2010 | I8: =$F8 -> 2010 | L8: =GETPIVOTDATA("Sum of Program Completers",'Pivot Data'!$A$3,"YEAR",$I8,"PROGRAM",$D$6) -> 2072 | M8: =GETPIVOTDATA("Sum of Respondents",'Pivot Data'!$A$3,"YEAR",$I8,"PROGRAM",$D$6) -> 1173 | N8: =IF($L8>4,$M8/$L8,"") -> 0.56611969 | O8: =GETPIVOTDATA("Sum of Total Employed",'Pivot Data'!$A$3,"YEAR",$I8,"PROGRAM",$D$6) -> 880 | P8: =IF($M8>4,$O8/$M8, " ") -> 0.75021313 | Q8: =GETPIVOTDATA("Sum of Median Hourly Wage ",'Pivot Data'!$A$3,"YEAR",$I8,"PROGRAM",$D$6) -> 14.7 | R8: =GETPIVOTDATA("Sum of Total in Military",'Pivot Data'!$A$3,"YEAR",$I8,"PROGRAM",$D$6) -> 23 | S8: =IF($M8>4, $R8/$M8, " ") -> 0.019607843 | T8: =GETPIVOTDATA("Sum of Continuing Education (Secondary or Post-Secondary)",'Pivot Data'!$A$3,"YEAR",$I8,"PROGRAM",$D$6) -> 650 | U8: =IF($M8>4, $T8/$M8, " ") -> 0.5541347 | V8: =GETPIVOTDATA("Sum of Total in Apprenticeships",'Pivot Data'!$A$3,"YEAR",$I8,"PROGRAM",$D$6) -> 263 | W8: =IF($M8>4,$V8/$M8,"") -> 0.22421142 | X8: =GETPIVOTDATA("Sum of Took State Licensing Exam",'Pivot Data'!$A$3,"YEAR",$I8,"PROGRAM",$D$6) -> 731 | Y8: =IF($M8>4,$X8/$M8, "") -> 0.62318841 | Z8: =GETPIVOTDATA("Sum of Passed State Licensing Exam",'Pivot Data'!$A$3,"YEAR",$I8,"PROGRAM",$D$6) -> 731 | AA8: =IF($X8>4, $Z8/$X8, "") -> 1 | AB8: =GETPIVOTDATA("Sum of Instructional Program Met Educational Goals",'Pivot Data'!$A$3,"YEAR",$I8,"PROGRAM",$D$6) -> 1096 | AC8: =IF($M8>4,$AB8/$M8,"") -> 0.93435635
C9: Architectural Engineering Technology | F9: 2011 | I9: =$F9 -> 2011 | L9: =GETPIVOTDATA("Sum of Program Completers",'Pivot Data'!$A$3,"YEAR",$I9,"PROGRAM",$D$6) -> 2169 | M9: =GETPIVOTDATA("Sum of Respondents",'Pivot Data'!$A$3,"YEAR",$I9,"PROGRAM",$D$6) -> 1205 | N9: =IF($L9>4,$M9/$L9,"") -> 0.55555556 | O9: =GETPIVOTDATA("Sum of Total Employed",'Pivot Data'!$A$3,"YEAR",$I9,"PROGRAM",$D$6) -> 913 | P9: =IF($M9>4,$O9/$M9, " ") -> 0.75767635 | Q9: =GETPIVOTDATA("Sum of Median Hourly Wage ",'Pivot Data'!$A$3,"YEAR",$I9,"PROGRAM",$D$6) -> 14.2 | R9: =GETPIVOTDATA("Sum of Total in Military",'Pivot Data'!$A$3,"YEAR",$I9,"PROGRAM",$D$6) -> 17 | S9: =IF($M9>4, $R9/$M9, " ") -> 0.014107884 | T9: =GETPIVOTDATA("Sum of Continuing Education (Secondary or Post-Secondary)",'Pivot Data'!$A$3,"YEAR",$I9,"PROGRAM",$D$6) -> 538 | U9: =IF($M9>4, $T9/$M9, " ") -> 0.44647303 | V9: =GETPIVOTDATA("Sum of Total in Apprenticeships",'Pivot Data'!$A$3,"YEAR",$I9,"PROGRAM",$D$6) -> 243 | W9: =IF($M9>4,$V9/$M9,"") -> 0.20165975 | X9: =GETPIVOTDATA("Sum of Took State Licensing Exam",'Pivot Data'!$A$3,"YEAR",$I9,"PROGRAM",$D$6) -> 765 | Y9: =IF($M9>4,$X9/$M9, "") -> 0.63485477 | Z9: =GETPIVOTDATA("Sum of Passed State Licensing Exam",'Pivot Data'!$A$3,"YEAR",$I9,"PROGRAM",$D$6) -> 747 | AA9: =IF($X9>4, $Z9/$X9, "") -> 0.97647059 | AB9: =GETPIVOTDATA("Sum of Instructional Program Met Educational Goals",'Pivot Data'!$A$3,"YEAR",$I9,"PROGRAM",$D$6) -> 1079 | AC9: =IF($M9>4,$AB9/$M9,"") -> 0.89543568
C10: Automotive Technology | F10: 2012 | I10: =$F10 -> 2012 | L10: =GETPIVOTDATA("Sum of Program Completers",'Pivot Data'!$A$3,"YEAR",$I10,"PROGRAM",$D$6) -> 2257 | M10: =GETPIVOTDATA("Sum of Respondents",'Pivot Data'!$A$3,"YEAR",$I10,"PROGRAM",$D$6) -> 1515 | N10: =IF($L10>4,$M10/$L10,"") -> 0.67124502 | O10: =GETPIVOTDATA("Sum of Total Employed",'Pivot Data'!$A$3,"YEAR",$I10,"PROGRAM",$D$6) -> 1197 | P10: =IF($M10>4,$O10/$M10, " ") -> 0.79009901 | Q10: =GETPIVOTDATA("Sum of Median Hourly Wage ",'Pivot Data'!$A$3,"YEAR",$I10,"PROGRAM",$D$6) -> 14 | R10: =GETPIVOTDATA("Sum of Total in Military",'Pivot Data'!$A$3,"YEAR",$I10,"PROGRAM",$D$6) -> 20 | S10: =IF($M10>4, $R10/$M10, " ") -> 0.01320132 | T10: =GETPIVOTDATA("Sum of Continuing Education (Secondary or Post-Secondary)",'Pivot Data'!$A$3,"YEAR",$I10,"PROGRAM",$D$6) -> 729 | U10: =IF($M10>4, $T10/$M10, " ") -> 0.48118812 | V10: =GETPIVOTDATA("Sum of Total in Apprenticeships",'Pivot Data'!$A$3,"YEAR",$I10,"PROGRAM",$D$6) -> 286 | W10: =IF($M10>4,$V10/$M10,"") -> 0.18877888 | X10: =GETPIVOTDATA("Sum of Took State Licensing Exam",'Pivot Data'!$A$3,"YEAR",$I10,"PROGRAM",$D$6) -> 906 | Y10: =IF($M10>4,$X10/$M10, "") -> 0.5980198 | Z10: =GETPIVOTDATA("Sum of Passed State Licensing Exam",'Pivot Data'!$A$3,"YEAR",$I10,"PROGRAM",$D$6) -> 872 | AA10: =IF($X10>4, $Z10/$X10, "") -> 0.96247241 | AB10: =GETPIVOTDATA("Sum of Instructional Program Met Educational Goals",'Pivot Data'!$A$3,"YEAR",$I10,"PROGRAM",$D$6) -> 1417 | AC10: =IF($M10>4,$AB10/$M10,"") -> 0.93531353
C11: Business | F11: 2013 | I11: =$F11 -> 2013 | L11: =GETPIVOTDATA("Sum of Program Completers",'Pivot Data'!$A$3,"YEAR",$I11,"PROGRAM",$D$6) -> 2196 | M11: =GETPIVOTDATA("Sum of Respondents",'Pivot Data'!$A$3,"YEAR",$I11,"PROGRAM",$D$6) -> 1239 | N11: =IF($L11>4,$M11/$L11,"") -> 0.56420765 | O11: =GETPIVOTDATA("Sum of Total Employed",'Pivot Data'!$A$3,"YEAR",$I11,"PROGRAM",$D$6) -> 940 | P11: =IF($M11>4,$O11/$M11, " ") -> 0.75867635 | Q11: =GETPIVOTDATA("Sum of Median Hourly Wage ",'Pivot Data'!$A$3,"YEAR",$I11,"PROGRAM",$D$6) -> 14.85 | R11: =GETPIVOTDATA("Sum of Total in Military",'Pivot Data'!$A$3,"YEAR",$I11,"PROGRAM",$D$6) -> 16 | S11: =IF($M11>4, $R11/$M11, " ") -> 0.01291364 | T11: =GETPIVOTDATA("Sum of Continuing Education (Secondary or Post-Secondary)",'Pivot Data'!$A$3,"YEAR",$I11,"PROGRAM",$D$6) -> 629 | U11: =IF($M11>4, $T11/$M11, " ") -> 0.50766747 | V11: =GETPIVOTDATA("Sum of Total in Apprenticeships",'Pivot Data'!$A$3,"YEAR",$I11,"PROGRAM",$D$6) -> 244 | W11: =IF($M11>4,$V11/$M11,"") -> 0.19693301 | X11: =GETPIVOTDATA("Sum of Took State Licensing Exam",'Pivot Data'!$A$3,"YEAR",$I11,"PROGRAM",$D$6) -> 620 | Y11: =IF($M11>4,$X11/$M11, "") -> 0.50040355 | Z11: =GETPIVOTDATA("Sum of Passed State Licensing Exam",'Pivot Data'!$A$3,"YEAR",$I11,"PROGRAM",$D$6) -> 601 | AA11: =IF($X11>4, $Z11/$X11, "") -> 0.96935484 | AB11: =GETPIVOTDATA("Sum of Instructional Program Met Educational Goals",'Pivot Data'!$A$3,"YEAR",$I11,"PROGRAM",$D$6) -> 1150 | AC11: =IF($M11>4,$AB11/$M11,"") -> 0.92816788
C12: CISCO Network Associate
C13: Computer Aided Drafting and Design
C14: Computer Information Systems
C15: Dental Assisting
C16: Dietetic Technology
C17: Early Childhood Education
C18: Emergency Medical Services
C19: Energy Technology
C20: Forestry-Wildlife & Natural Resources
C21: Geographic Information System
C22: Heating, Ventilation & Air Cond
C23: Holistic Health
... C39: Welding Technology

Sheet Introduction
B1: Introduction to the VE-135 Interactive Dashboard: by Program
B18: 1. At any time between October 1st and December 31st of (the preceding year) were you:
B19: Employed in an occupation related to your FRCC training
B20: Employed in an occupation NOT related to your FRCC training
B21: Unemployed and actively seeking employment
B22: Unemployed and NOT actively seeking employment
B24: 2. In order to help future students interested in your program know what they
B25: might expect, what is your hourly wage? (You will not be identified with this
B26: Information!)
B28: 3. Since completing your program last year (or as part of your graduation
B29: requirements), have you taken a state licensing test or an industry certification
B30: test related to your program
... B46: Not currently continuing your education

Sheet Main
D1: ='Chart Titles'!D1 -> TOTAL
D32: If less than five respondents, no data reported.

Sheet Success
D1: ='Chart Titles'!D1 -> TOTAL
D32: If less than five respondents, no data reported.
