Workbook

Sheet Pivot
A1: SCC Student Funded Programs
A2: for the period ending June 30, 2013
A4: Account Title | B4: Budget | C4: (Rev)/Exp | D4: Encumbered | E4: Balance
A5: 2221 - SPEC.BLDG FUND-SCC
A6: Carryforward | B6: 0 | C6: -652524.89 | D6: 0 | E6: 652524.89
A7: Revenue | B7: 0 | C7: -304696.93 | D7: 0 | E7: 304696.93
A8: Rev-Fund Transfers - In | B8: 0 | C8: 0 | D8: 0 | E8: 0
A9: Rev-Fund Transfers - Out | B9: 0 | C9: 0 | D9: 0 | E9: 0
A10: Exp-Goods & Services | B10: 0 | C10: 2787.91 | D10: 0 | E10: -2787.91
A11: Exp-Travel | B11: 0 | C11: 0 | D11: 0 | E11: 0
A12: Exp-Equipment | B12: 0 | C12: 0 | D12: 0 | E12: 0
A13: Exp-Computer Equipment | B13: 0 | C13: 0 | D13: 0 | E13: 0
A14: 2221 - SPEC.BLDG FUND-SCC Total | B14: 0 | C14: -954433.91 | D14: 0 | E14: 954433.91
A15: 2222 - SBF-SCC-LAIR FURNISH
A16: Carryforward | B16: 0 | C16: -3339.12 | D16: 0 | E16: 3339.12
A17: 2222 - SBF-SCC-LAIR FURNISH Total | B17: 0 | C17: -3339.12 | D17: 0 | E17: 3339.12
A18: 2309 - IRP CLUB ADVISORS
A19: Exp-Salaries & Wages | B19: 48333 | C19: 48353.89 | D19: 0 | E19: -20.89
A20: Exp-Benefits | B20: 9667 | C20: 8351.01 | D20: 0 | E20: 1315.99
A21: Exp-Goods & Services | B21: 0 | C21: 884.55 | D21: 0 | E21: -884.55
A22: 2309 - IRP CLUB ADVISORS Total | B22: 58000 | C22: 57589.45 | D22: 0 | E22: 410.55
A23: 2310 - IRP-GENERAL FUND
A24: Carryforward | B24: 0 | C24: 179090.33 | D24: 0 | E24: -179090.33
A25: Rev-Intra-Fund Transfer | B25: 0 | C25: -384041.9 | D25: 0 | E25: 384041.9
A26: Exp-Goods & Services | B26: 13893 | C26: 5901.6 | D26: 0 | E26: 7991.4
A27: Exp-Travel | B27: 0 | C27: 148.54 | D27: 0 | E27: -148.54
A28: 2310 - IRP-GENERAL FUND Total | B28: 13893 | C28: -198901.43 | D28: 0 | E28: 212794.43
A29: 2311 - PRES SPEAKER SERIES
A30: Exp-Salaries & Wages | B30: 0 | C30: 0 | D30: 0 | E30: 0
A31: Exp-Benefits | B31: 0 | C31: -0.09 | D31: 0 | E31: 0.09
A32: Exp-Goods & Services | B32: 0 | C32: 0 | D32: 0 | E32: 0
A33: 2311 - PRES SPEAKER SERIES Total | B33: 0 | C33: -0.09 | D33: 0 | E33: 0.09
A34: 2312 - ADA ACCESSIBILITY
A35: Exp-Salaries & Wages | B35: 909 | C35: 636.23 | D35: 0 | E35: 272.77
A36: Exp-Benefits | B36: 91 | C36: 71.57 | D36: 0 | E36: 19.43
A37: Exp-Goods & Services | B37: 0 | C37: 0 | D37: 0 | E37: 0
A38: 2312 - ADA ACCESSIBILITY Total | B38: 1000 | C38: 707.8 | D38: 0 | E38: 292.2
A39: 2313 - HLTH INFO MANAGEMNT
A40: Revenue | B40: 0 | C40: 0 | D40: 0 | E40: 0
A41: Exp-Goods & Services | B41: 2060 | C41: 0 | D41: 0 | E41: 2060
...

Sheet BSPRGORG-T
A1: FYR | B1: Appr | C1: Prg | D1: Org | E1: Title | F1: Sobj | G1: SSObj | H1: Src | I1: SSrc | J1: Category | K1: Budget | L1: Exp/Rev | M1: Encumbered | N1: Balance | O1: Current | P1: Org Title
A2: 1213 | B2: 522 | C2: 264 | D2: 2221 | E2: =D2&" - "&P2 -> 2221 - SPEC.BLDG FUND-SCC | H2: 0401 | J2: =IF(H2="",VLOOKUP(LEFT(F2,1),'Exp-Rev Categories'!A:B,2,FALSE),IF(ISNA(VLOOKUP(H2,'Exp-Rev Categories'!A:B,2,FALSE)),"Revenue",VLOOKUP(H2,'Exp-Rev Categories'!A:B,2,FALSE))) -> Revenue | K2: 0 | L2: -5473.54 | M2: 0 | N2: 5473.54 | O2: -1964.34 | P2: SPEC.BLDG FUND-SCC
A3: 1213 | B3: 522 | C3: 264 | D3: 2221 | E3: =D3&" - "&P3 -> 2221 - SPEC.BLDG FUND-SCC | H3: 0424 | I3: #A | J3: =IF(H3="",VLOOKUP(LEFT(F3,1),'Exp-Rev Categories'!A:B,2,FALSE),IF(ISNA(VLOOKUP(H3,'Exp-Rev Categories'!A:B,2,FALSE)),"Revenue",VLOOKUP(H3,'Exp-Rev Categories'!A:B,2,FALSE))) -> Revenue | K3: 0 | L3: -566.75 | M3: 0 | N3: 566.75 | O3: 0 | P3: SPEC.BLDG FUND-SCC
A4: 1213 | B4: 522 | C4: 264 | D4: 2221 | E4: =D4&" - "&P4 -> 2221 - SPEC.BLDG FUND-SCC | H4: 0424 | I4: #B | J4: =IF(H4="",VLOOKUP(LEFT(F4,1),'Exp-Rev Categories'!A:B,2,FALSE),IF(ISNA(VLOOKUP(H4,'Exp-Rev Categories'!A:B,2,FALSE)),"Revenue",VLOOKUP(H4,'Exp-Rev Categories'!A:B,2,FALSE))) -> Revenue | K4: 0 | L4: -71.91 | M4: 0 | N4: 71.91 | O4: 0 | P4: SPEC.BLDG FUND-SCC
A5: 1213 | B5: 522 | C5: 264 | D5: 2221 | E5: =D5&" - "&P5 -> 2221 - SPEC.BLDG FUND-SCC | H5: 0424 | I5: #G | J5: =IF(H5="",VLOOKUP(LEFT(F5,1),'Exp-Rev Categories'!A:B,2,FALSE),IF(ISNA(VLOOKUP(H5,'Exp-Rev Categories'!A:B,2,FALSE)),"Revenue",VLOOKUP(H5,'Exp-Rev Categories'!A:B,2,FALSE))) -> Revenue | K5: 0 | L5: -1052.07 | M5: 0 | N5: 1052.07 | O5: 0 | P5: SPEC.BLDG FUND-SCC
A6: 1213 | B6: 522 | C6: 264 | D6: 2221 | E6: =D6&" - "&P6 -> 2221 - SPEC.BLDG FUND-SCC | H6: 0424 | I6: #P | J6: =IF(H6="",VLOOKUP(LEFT(F6,1),'Exp-Rev Categories'!A:B,2,FALSE),IF(ISNA(VLOOKUP(H6,'Exp-Rev Categories'!A:B,2,FALSE)),"Revenue",VLOOKUP(H6,'Exp-Rev Categories'!A:B,2,FALSE))) -> Revenue | K6: 0 | L6: -437.51 | M6: 0 | N6: 437.51 | O6: 0 | P6: SPEC.BLDG FUND-SCC
A7: 1213 | B7: 522 | C7: 264 | D7: 2221 | E7: =D7&" - "&P7 -> 2221 - SPEC.BLDG FUND-SCC | H7: 0424 | I7: +1 | J7: =IF(H7="",VLOOKUP(LEFT(F7,1),'Exp-Rev Categories'!A:B,2,FALSE),IF(ISNA(VLOOKUP(H7,'Exp-Rev Categories'!A:B,2,FALSE)),"Revenue",VLOOKUP(H7,'Exp-Rev Categories'!A:B,2,FALSE))) -> Revenue | K7: 0 | L7: -92.92 | M7: 0 | N7: 92.92 | O7: 0 | P7: SPEC.BLDG FUND-SCC
A8: 1213 | B8: 522 | C8: 264 | D8: 2221 | E8: =D8&" - "&P8 -> 2221 - SPEC.BLDG FUND-SCC | H8: 0424 | I8: +2 | J8: =IF(H8="",VLOOKUP(LEFT(F8,1),'Exp-Rev Categories'!A:B,2,FALSE),IF(ISNA(VLOOKUP(H8,'Exp-Rev Categories'!A:B,2,FALSE)),"Revenue",VLOOKUP(H8,'Exp-Rev Categories'!A:B,2,FALSE))) -> Revenue | K8: 0 | L8: -6.21 | M8: 0 | N8: 6.21 | O8: 0 | P8: SPEC.BLDG FUND-SCC
A9: 1213 | B9: 522 | C9: 264 | D9: 2221 | E9: =D9&" - "&P9 -> 2221 - SPEC.BLDG FUND-SCC | H9: 0424 | I9: +A | J9: =IF(H9="",VLOOKUP(LEFT(F9,1),'Exp-Rev Categories'!A:B,2,FALSE),IF(ISNA(VLOOKUP(H9,'Exp-Rev Categories'!A:B,2,FALSE)),"Revenue",VLOOKUP(H9,'Exp-Rev Categories'!A:B,2,FALSE))) -> Revenue | K9: 0 | L9: -19100.76 | M9: 0 | N9: 19100.76 | O9: 0 | P9: SPEC.BLDG FUND-SCC
A10: 1213 | B10: 522 | C10: 264 | D10: 2221 | E10: =D10&" - "&P10 -> 2221 - SPEC.BLDG FUND-SCC | H10: 0424 | I10: +G | J10: =IF(H10="",VLOOKUP(LEFT(F10,1),'Exp-Rev Categories'!A:B,2,FALSE),IF(ISNA(VLOOKUP(H10,'Exp-Rev Categories'!A:B,2,FALSE)),"Revenue",VLOOKUP(H10,'Exp-Rev Categories'!A:B,2,FALSE))) -> Revenue | K10: 0 | L10: -33899.59 | M10: 0 | N10: 33899.59 | O10: 0 | P10: SPEC.BLDG FUND-SCC
A11: 1213 | B11: 522 | C11: 264 | D11: 2221 | E11: =D11&" - "&P11 -> 2221 - SPEC.BLDG FUND-SCC | H11: 0424 | I11: +H | J11: =IF(H11="",VLOOKUP(LEFT(F11,1),'Exp-Rev Categories'!A:B,2,FALSE),IF(ISNA(VLOOKUP(H11,'Exp-Rev Categories'!A:B,2,FALSE)),"Revenue",VLOOKUP(H11,'Exp-Rev Categories'!A:B,2,FALSE))) -> Revenue | K11: 0 | L11: -324.28 | M11: 0 | N11: 324.28 | O11: 0 | P11: SPEC.BLDG FUND-SCC
A12: 1213 | B12: 522 | C12: 264 | D12: 2221 | E12: =D12&" - "&P12 -> 2221 - SPEC.BLDG FUND-SCC | H12: 0424 | I12: +M | J12: =IF(H12="",VLOOKUP(LEFT(F12,1),'Exp-Rev Categories'!A:B,2,FALSE),IF(ISNA(VLOOKUP(H12,'Exp-Rev Categories'!A:B,2,FALSE)),"Revenue",VLOOKUP(H12,'Exp-Rev Categories'!A:B,2,FALSE))) -> Revenue | K12: 0 | L12: -3146.61 | M12: 0 | N12: 3146.61 | O12: 0 | P12: SPEC.BLDG FUND-SCC
A13: 1213 | B13: 522 | C13: 264 | D13: 2221 | E13: =D13&" - "&P13 -> 2221 - SPEC.BLDG FUND-SCC | H13: 0424 | I13: TN | J13: =IF(H13="",VLOOKUP(LEFT(F13,1),'Exp-Rev Categories'!A:B,2,FALSE),IF(ISNA(VLOOKUP(H13,'Exp-Rev Categories'!A:B,2,FALSE)),"Revenue",VLOOKUP(H13,'Exp-Rev Categories'!A:B,2,FALSE))) -> Revenue | K13: 0 | L13: -1736.51 | M13: 0 | N13: 1736.51 | O13: 0 | P13: SPEC.BLDG FUND-SCC
A14: 1213 | B14: 522 | C14: 264 | D14: 2221 | E14: =D14&" - "&P14 -> 2221 - SPEC.BLDG FUND-SCC | H14: 0424 | I14: TR | J14: =IF(H14="",VLOOKUP(LEFT(F14,1),'Exp-Rev Categories'!A:B,2,FALSE),IF(ISNA(VLOOKUP(H14,'Exp-Rev Categories'!A:B,2,FALSE)),"Revenue",VLOOKUP(H14,'Exp-Rev Categories'!A:B,2,FALSE))) -> Revenue | K14: 0 | L14: -238788.27 | M14: 0 | N14: 238788.27 | O14: 0 | P14: SPEC.BLDG FUND-SCC
A15: 1213 | B15: 522 | C15: 264 | D15: 2221 | E15: =D15&" - "&P15 -> 2221 - SPEC.BLDG FUND-SCC | H15: 0621 | J15: =IF(H15="",VLOOKUP(LEFT(F15,1),'Exp-Rev Categories'!A:B,2,FALSE),IF(ISNA(VLOOKUP(H15,'Exp-Rev Categories'!A:B,2,FALSE)),"Revenue",VLOOKUP(H15,'Exp-Rev Categories'!A:B,2,FALSE))) -> Rev-Fund Transfers - In | K15: 0 | L15: 0 | M15: 0 | N15: 0 | O15: 0 | P15: SPEC.BLDG FUND-SCC
A16: 1213 | B16: 522 | C16: 264 | D16: 2221 | E16: =D16&" - "&P16 -> 2221 - SPEC.BLDG FUND-SCC | H16: 0622 | J16: =IF(H16="",VLOOKUP(LEFT(F16,1),'Exp-Rev Categories'!A:B,2,FALSE),IF(ISNA(VLOOKUP(H16,'Exp-Rev Categories'!A:B,2,FALSE)),"Revenue",VLOOKUP(H16,'Exp-Rev Categories'!A:B,2,FALSE))) -> Rev-Fund Transfers - Out | K16: 0 | L16: 0 | M16: 0 | N16: 0 | O16: 0 | P16: SPEC.BLDG FUND-SCC
A17: 1213 | B17: 522 | C17: 264 | D17: 2221 | E17: =D17&" - "&P17 -> 2221 - SPEC.BLDG FUND-SCC | H17: 0999 | J17: =IF(H17="",VLOOKUP(LEFT(F17,1),'Exp-Rev Categories'!A:B,2,FALSE),IF(ISNA(VLOOKUP(H17,'Exp-Rev Categories'!A:B,2,FALSE)),"Revenue",VLOOKUP(H17,'Exp-Rev Categories'!A:B,2,FALSE))) -> Carryforward | K17: 0 | L17: -652524.89 | M17: 0 | N17: 652524.89 | O17: 0 | P17: SPEC.BLDG FUND-SCC
A18: 1213 | B18: 522 | C18: 264 | D18: 2221 | E18: =D18&" - "&P18 -> 2221 - SPEC.BLDG FUND-SCC | F18: E | J18: =IF(H18="",VLOOKUP(LEFT(F18,1),'Exp-Rev Categories'!A:B,2,FALSE),IF(ISNA(VLOOKUP(H18,'Exp-Rev Categories'!A:B,2,FALSE)),"Revenue",VLOOKUP(H18,'Exp-Rev Categories'!A:B,2,FALSE))) -> Exp-Goods & Services | K18: 0 | L18: 0 | M18: 0 | N18: 0 | O18: 0 | P18: SPEC.BLDG FUND-SCC
A19: 1213 | B19: 522 | C19: 264 | D19: 2221 | E19: =D19&" - "&P19 -> 2221 - SPEC.BLDG FUND-SCC | F19: EA | G19: 00 | J19: =IF(H19="",VLOOKUP(LEFT(F19,1),'Exp-Rev Categories'!A:B,2,FALSE),IF(ISNA(VLOOKUP(H19,'Exp-Rev Categories'!A:B,2,FALSE)),"Revenue",VLOOKUP(H19,'Exp-Rev Categories'!A:B,2,FALSE))) -> Exp-Goods & Services | K19: 0 | L19: 2787.91 | M19: 0 | N19: -2787.91 | O19: 0 | P19: SPEC.BLDG FUND-SCC
A20: 1213 | B20: 522 | C20: 264 | D20: 2221 | E20: =D20&" - "&P20 -> 2221 - SPEC.BLDG FUND-SCC | F20: G | J20: =IF(H20="",VLOOKUP(LEFT(F20,1),'Exp-Rev Categories'!A:B,2,FALSE),IF(ISNA(VLOOKUP(H20,'Exp-Rev Categories'!A:B,2,FALSE)),"Revenue",VLOOKUP(H20,'Exp-Rev Categories'!A:B,2,FALSE))) -> Exp-Travel | K20: 0 | L20: 0 | M20: 0 | N20: 0 | O20: 0 | P20: SPEC.BLDG FUND-SCC
A21: 1213 | B21: 522 | C21: 264 | D21: 2221 | E21: =D21&" - "&P21 -> 2221 - SPEC.BLDG FUND-SCC | F21: J | J21: =IF(H21="",VLOOKUP(LEFT(F21,1),'Exp-Rev Categories'!A:B,2,FALSE),IF(ISNA(VLOOKUP(H21,'Exp-Rev Categories'!A:B,2,FALSE)),"Revenue",VLOOKUP(H21,'Exp-Rev Categories'!A:B,2,FALSE))) -> Exp-Equipment | K21: 0 | L21: 0 | M21: 0 | N21: 0 | O21: 0 | P21: SPEC.BLDG FUND-SCC
A22: 1213 | B22: 522 | C22: 264 | D22: 2221 | E22: =D22&" - "&P22 -> 2221 - SPEC.BLDG FUND-SCC | F22: KA | J22: =IF(H22="",VLOOKUP(LEFT(F22,1),'Exp-Rev Categories'!A:B,2,FALSE),IF(ISNA(VLOOKUP(H22,'Exp-Rev Categories'!A:B,2,FALSE)),"Revenue",VLOOKUP(H22,'Exp-Rev Categories'!A:B,2,FALSE))) -> Exp-Computer Equipment | K22: 0 | L22: 0 | M22: 0 | N22: 0 | O22: 0 | P22: SPEC.BLDG FUND-SCC
A23: 1213 | B23: 522 | C23: 264 | D23: 2221 | E23: =D23&" - "&P23 -> 2221 - SPEC.BLDG FUND-SCC | F23: KC | J23: =IF(H23="",VLOOKUP(LEFT(F23,1),'Exp-Rev Categories'!A:B,2,FALSE),IF(ISNA(VLOOKUP(H23,'Exp-Rev Categories'!A:B,2,FALSE)),"Revenue",VLOOKUP(H23,'Exp-Rev Categories'!A:B,2,FALSE))) -> Exp-Computer Equipment | K23: 0 | L23: 0 | M23: 0 | N23: 0 | O23: 0 | P23: SPEC.BLDG FUND-SCC
A24: 1213 | B24: 522 | C24: 264 | D24: 2222 | E24: =D24&" - "&P24 -> 2222 - SBF-SCC-LAIR FURNISH | H24: 0999 | J24: =IF(H24="",VLOOKUP(LEFT(F24,1),'Exp-Rev Categories'!A:B,2,FALSE),IF(ISNA(VLOOKUP(H24,'Exp-Rev Categories'!A:B,2,FALSE)),"Revenue",VLOOKUP(H24,'Exp-Rev Categories'!A:B,2,FALSE))) -> Carryforward | K24: 0 | L24: -3339.12 | M24: 0 | N24: 3339.12 | O24: 0 | P24: SBF-SCC-LAIR FURNISH
A25: 1213 | B25: 522 | C25: 264 | D25: 2309 | E25: =D25&" - "&P25 -> 2309 - IRP CLUB ADVISORS | F25: AC | G25: CA | J25: =IF(H25="",VLOOKUP(LEFT(F25,1),'Exp-Rev Categories'!A:B,2,FALSE),IF(ISNA(VLOOKUP(H25,'Exp-Rev Categories'!A:B,2,FALSE)),"Revenue",VLOOKUP(H25,'Exp-Rev Categories'!A:B,2,FALSE))) -> Exp-Salaries & Wages | K25: 0 | L25: 963 | M25: 0 | N25: -963 | O25: 0 | P25: IRP CLUB ADVISORS
A26: 1213 | B26: 522 | C26: 264 | D26: 2309 | E26: =D26&" - "&P26 -> 2309 - IRP CLUB ADVISORS | F26: AE | G26: CA | J26: =IF(H26="",VLOOKUP(LEFT(F26,1),'Exp-Rev Categories'!A:B,2,FALSE),IF(ISNA(VLOOKUP(H26,'Exp-Rev Categories'!A:B,2,FALSE)),"Revenue",VLOOKUP(H26,'Exp-Rev Categories'!A:B,2,FALSE))) -> Exp-Salaries & Wages | K26: 48333 | L26: 45421.5 | M26: 0 | N26: 2911.5 | O26: 0 | P26: IRP CLUB ADVISORS
A27: 1213 | B27: 522 | C27: 264 | D27: 2309 | E27: =D27&" - "&P27 -> 2309 - IRP CLUB ADVISORS | F27: AE | G27: CP | J27: =IF(H27="",VLOOKUP(LEFT(F27,1),'Exp-Rev Categories'!A:B,2,FALSE),IF(ISNA(VLOOKUP(H27,'Exp-Rev Categories'!A:B,2,FALSE)),"Revenue",VLOOKUP(H27,'Exp-Rev Categories'!A:B,2,FALSE))) -> Exp-Salaries & Wages | K27: 0 | L27: 1765.5 | M27: 0 | N27: -1765.5 | O27: 0 | P27: IRP CLUB ADVISORS
A28: 1213 | B28: 522 | C28: 264 | D28: 2309 | E28: =D28&" - "&P28 -> 2309 - IRP CLUB ADVISORS | F28: AU | G28: 01 | J28: =IF(H28="",VLOOKUP(LEFT(F28,1),'Exp-Rev Categories'!A:B,2,FALSE),IF(ISNA(VLOOKUP(H28,'Exp-Rev Categories'!A:B,2,FALSE)),"Revenue",VLOOKUP(H28,'Exp-Rev Categories'!A:B,2,FALSE))) -> Exp-Salaries & Wages | K28: 0 | L28: 203.89 | M28: 0 | N28: -203.89 | O28: 0 | P28: IRP CLUB ADVISORS
A29: 1213 | B29: 522 | C29: 264 | D29: 2309 | E29: =D29&" - "&P29 -> 2309 - IRP CLUB ADVISORS | F29: B | J29: =IF(H29="",VLOOKUP(LEFT(F29,1),'Exp-Rev Categories'!A:B,2,FALSE),IF(ISNA(VLOOKUP(H29,'Exp-Rev Categories'!A:B,2,FALSE)),"Revenue",VLOOKUP(H29,'Exp-Rev Categories'!A:B,2,FALSE))) -> Exp-Benefits | K29: 9667 | L29: 0 | M29: 0 | N29: 9667 | O29: 0 | P29: IRP CLUB ADVISORS
A30: 1213 | B30: 522 | C30: 264 | D30: 2309 | E30: =D30&" - "&P30 -> 2309 - IRP CLUB ADVISORS | F30: BA | J30: =IF(H30="",VLOOKUP(LEFT(F30,1),'Exp-Rev Categories'!A:B,2,FALSE),IF(ISNA(VLOOKUP(H30,'Exp-Rev Categories'!A:B,2,FALSE)),"Revenue",VLOOKUP(H30,'Exp-Rev Categories'!A:B,2,FALSE))) -> Exp-Benefits | K30: 0 | L30: 3655.48 | M30: 0 | N30: -3655.48 | O30: 0 | P30: IRP CLUB ADVISORS
A31: 1213 | B31: 522 | C31: 264 | D31: 2309 | E31: =D31&" - "&P31 -> 2309 - IRP CLUB ADVISORS | F31: BB | J31: =IF(H31="",VLOOKUP(LEFT(F31,1),'Exp-Rev Categories'!A:B,2,FALSE),IF(ISNA(VLOOKUP(H31,'Exp-Rev Categories'!A:B,2,FALSE)),"Revenue",VLOOKUP(H31,'Exp-Rev Categories'!A:B,2,FALSE))) -> Exp-Benefits | K31: 0 | L31: 4306.86 | M31: 0 | N31: -4306.86 | O31: 0 | P31: IRP CLUB ADVISORS
A32: 1213 | B32: 522 | C32: 264 | D32: 2309 | E32: =D32&" - "&P32 -> 2309 - IRP CLUB ADVISORS | F32: BC | J32: =IF(H32="",VLOOKUP(LEFT(F32,1),'Exp-Rev Categories'!A:B,2,FALSE),IF(ISNA(VLOOKUP(H32,'Exp-Rev Categories'!A:B,2,FALSE)),"Revenue",VLOOKUP(H32,'Exp-Rev Categories'!A:B,2,FALSE))) -> Exp-Benefits | K32: 0 | L32: 2.92 | M32: 0 | N32: -2.92 | O32: 0 | P32: IRP CLUB ADVISORS
A33: 1213 | B33: 522 | C33: 264 | D33: 2309 | E33: =D33&" - "&P33 -> 2309 - IRP CLUB ADVISORS | F33: BD | J33: =IF(H33="",VLOOKUP(LEFT(F33,1),'Exp-Rev Categories'!A:B,2,FALSE),IF(ISNA(VLOOKUP(H33,'Exp-Rev Categories'!A:B,2,FALSE)),"Revenue",VLOOKUP(H33,'Exp-Rev Categories'!A:B,2,FALSE))) -> Exp-Benefits | K33: 0 | L33: 37.6 | M33: 0 | N33: -37.6 | O33: 0 | P33: IRP CLUB ADVISORS
A34: 1213 | B34: 522 | C34: 264 | D34: 2309 | E34: =D34&" - "&P34 -> 2309 - IRP CLUB ADVISORS | F34: BF | J34: =IF(H34="",VLOOKUP(LEFT(F34,1),'Exp-Rev Categories'!A:B,2,FALSE),IF(ISNA(VLOOKUP(H34,'Exp-Rev Categories'!A:B,2,FALSE)),"Revenue",VLOOKUP(H34,'Exp-Rev Categories'!A:B,2,FALSE))) -> Exp-Benefits | K34: 0 | L34: 348.15 | M34: 0 | N34: -348.15 | O34: 0 | P34: IRP CLUB ADVISORS
A35: 1213 | B35: 522 | C35: 264 | D35: 2309 | E35: =D35&" - "&P35 -> 2309 - IRP CLUB ADVISORS | F35: E | J35: =IF(H35="",VLOOKUP(LEFT(F35,1),'Exp-Rev Categories'!A:B,2,FALSE),IF(ISNA(VLOOKUP(H35,'Exp-Rev Categories'!A:B,2,FALSE)),"Revenue",VLOOKUP(H35,'Exp-Rev Categories'!A:B,2,FALSE))) -> Exp-Goods & Services | K35: 0 | L35: 0 | M35: 0 | N35: 0 | O35: 0 | P35: IRP CLUB ADVISORS
A36: 1213 | B36: 522 | C36: 264 | D36: 2309 | E36: =D36&" - "&P36 -> 2309 - IRP CLUB ADVISORS | F36: EN | G36: 06 | J36: =IF(H36="",VLOOKUP(LEFT(F36,1),'Exp-Rev Categories'!A:B,2,FALSE),IF(ISNA(VLOOKUP(H36,'Exp-Rev Categories'!A:B,2,FALSE)),"Revenue",VLOOKUP(H36,'Exp-Rev Categories'!A:B,2,FALSE))) -> Exp-Goods & Services | K36: 0 | L36: 9.67 | M36: 0 | N36: -9.67 | O36: 0 | P36: IRP CLUB ADVISORS
A37: 1213 | B37: 522 | C37: 264 | D37: 2309 | E37: =D37&" - "&P37 -> 2309 - IRP CLUB ADVISORS | F37: EN | G37: 07 | J37: =IF(H37="",VLOOKUP(LEFT(F37,1),'Exp-Rev Categories'!A:B,2,FALSE),IF(ISNA(VLOOKUP(H37,'Exp-Rev Categories'!A:B,2,FALSE)),"Revenue",VLOOKUP(H37,'Exp-Rev Categories'!A:B,2,FALSE))) -> Exp-Goods & Services | K37: 0 | L37: 0.03 | M37: 0 | N37: -0.03 | O37: 0 | P37: IRP CLUB ADVISORS
A38: 1213 | B38: 522 | C38: 264 | D38: 2309 | E38: =D38&" - "&P38 -> 2309 - IRP CLUB ADVISORS | F38: EZ | G38: 30 | J38: =IF(H38="",VLOOKUP(LEFT(F38,1),'Exp-Rev Categories'!A:B,2,FALSE),IF(ISNA(VLOOKUP(H38,'Exp-Rev Categories'!A:B,2,FALSE)),"Revenue",VLOOKUP(H38,'Exp-Rev Categories'!A:B,2,FALSE))) -> Exp-Goods & Services | K38: 0 | L38: 874.85 | M38: 0 | N38: -874.85 | O38: 0 | P38: IRP CLUB ADVISORS
A39: 1213 | B39: 522 | C39: 264 | D39: 2310 | E39: =D39&" - "&P39 -> 2310 - IRP-GENERAL FUND | H39: 0782 | J39: =IF(H39="",VLOOKUP(LEFT(F39,1),'Exp-Rev Categories'!A:B,2,FALSE),IF(ISNA(VLOOKUP(H39,'Exp-Rev Categories'!A:B,2,FALSE)),"Revenue",VLOOKUP(H39,'Exp-Rev Categories'!A:B,2,FALSE))) -> Rev-Intra-Fund Transfer | K39: 0 | L39: -384041.9 | M39: 0 | N39: 384041.9 | O39: -162237 | P39: IRP-GENERAL FUND
A40: 1213 | B40: 522 | C40: 264 | D40: 2310 | E40: =D40&" - "&P40 -> 2310 - IRP-GENERAL FUND | H40: 0999 | J40: =IF(H40="",VLOOKUP(LEFT(F40,1),'Exp-Rev Categories'!A:B,2,FALSE),IF(ISNA(VLOOKUP(H40,'Exp-Rev Categories'!A:B,2,FALSE)),"Revenue",VLOOKUP(H40,'Exp-Rev Categories'!A:B,2,FALSE))) -> Carryforward | K40: 0 | L40: 179090.33 | M40: 0 | N40: -179090.33 | O40: 0 | P40: IRP-GENERAL FUND
...

Sheet Exp-Rev Categories
A1: Obj/Src | B1: Title | C1: Line
A2: 0999 | B2: Carryforward | C2: 1
B3: Revenue | C3: 2
A4: 0782 | B4: Rev-Intra-Fund Transfer | C4: 3
A5: 0621 | B5: Rev-Fund Transfers - In | C5: 4
A6: 0622 | B6: Rev-Fund Transfers - Out | C6: 5
A7: A | B7: Exp-Salaries & Wages | C7: 6
A8: B | B8: Exp-Benefits | C8: 7
A9: C | B9: Exp-Personal Service Contracts | C9: 8
A10: E | B10: Exp-Goods & Services | C10: 9
A11: G | B11: Exp-Travel | C11: 10
A12: J | B12: Exp-Equipment | C12: 11
A13: K | B13: Exp-Computer Equipment | C13: 12
A14: N | B14: Exp-Grants/Scholarships | C14: 13
A15: T | B15: Exp-Transfer | C15: 14
