Workbook
Name am: List!#REF!
Name AMPM: List!$N$2:$N$3
Name FREQ: List!$C$2:$C$6
Name list: List!$B$2:$B$13
Name pm: List!#REF!
Name time: List!$L$2:$L$26

Sheet Instructions

Sheet Provider Order Form
B2: Ordering Frequency | C2: Ordering Month
B3: Monthly | C3: January
B4: PROVIDER REQUEST FOR CHILDHOOD VACCINES
B5: Public Health Seattle & King County
B6: 401 Fifth Avenue, 9th floor
B7: Seattle WA 98104
B8: Provider PIN #: | E8: Telephone: (206) 296-4774 | K8: Fax: (206) 205-5780
B9: CLINIC NAME: | N9: DATE ORDERED: | T9: TRUE
B10: SHIPPING ADDRESS: | N10: =IF(U10=TRUE,"!!!NEW ADDRESS!!!","Check if New Address") -> Check if New Address | T10: TRUE | U10: FALSE
B11: CITY: | H11: ZIP: | T11: TRUE
B12: CONTACT: | I12: Email: | T12: TRUE
B13: TELEPHONE: | K13: FAX: | T13: TRUE
B14: DELIVERY TIMES: Please specify all days and hours you may receive vaccine. (e.g., 9AM- 3PM) | D14: Monday | G14: Tuesday | J14: Wednesday | M14: Thursday | P14: Friday
D15: AM | F15: to | G15: AM | I15: to | J15: AM | L15: to | M15: AM | O15: to | P15: AM | R15: to
D16: PM | G16: PM | J16: PM | M16: PM | P16: PM
B17: Special Shipping Instructions: (e.g., Closed 12-1 Lunch)
B18: Vaccine | C18: Description | K18: Doses used Last Month | M18: Doses On Hand | O18: Recommended Order | Q18: Doses Ordered
B19: DT | C19: Diphtheria & Tetanus | O19: {=INDEX(Table!$C$4:$C$31,MATCH(1,(Table!$A$4:$A$31='Provider Order Form'!$B$3)*(Table!$B$4:$B$31='Provider Order Form'!$C$3),0))} -> 0
B20: DTaP | C20: Diphtheria & tetanus toxoids & acellular pertussis vaccine (Daptacel / Infanrix) | O20: {=INDEX(Table!$D$4:$D$31,MATCH(1,(Table!$A$4:$A$31='Provider Order Form'!$B$3)*(Table!$B$4:$B$31='Provider Order Form'!$C$3),0))} -> 0
B21: DTaP-HEP B-IPV | C21: Pediarix: Diphtheria & tetanus toxoids and acellular pertussis, Hepatitis B, and IPV combination vaccine | O21: {=INDEX(Table!$E$4:$E$31,MATCH(1,(Table!$A$4:$A$31='Provider Order Form'!$B$3)*(Table!$B$4:$B$31='Provider Order Form'!$C$3),0))} -> 0
B22: DTaP - IPV - Hib | C22: Pentacel: Diphtheria & tetanus toxoids and acellular pertussis, IPV, and Haemophilus influenzae type b Conjugate combination vaccine | O22: {=INDEX(Table!$F$4:$F$31,MATCH(1,(Table!$A$4:$A$31='Provider Order Form'!$B$3)*(Table!$B$4:$B$31='Provider Order Form'!$C$3),0))} -> 0
B23: DTaP - IPV | C23: Kinrix: Diphtheria & tetanus toxoids and acellular pertussis and IPV combination vaccine | O23: {=INDEX(Table!$T$4:$T$31,MATCH(1,(Table!$A$4:$A$31='Provider Order Form'!$B$3)*(Table!$B$4:$B$31='Provider Order Form'!$C$3),0))} -> 0
B24: Hep A | C24: Hepatitis A Pediatric/Adolescent (Havrix / VAQTA) | O24: {=INDEX(Table!$H$4:$H$31,MATCH(1,(Table!$A$4:$A$31='Provider Order Form'!$B$3)*(Table!$B$4:$B$31='Provider Order Form'!$C$3),0))} -> 0
B25: Hep B | C25: Hepatitis B Pediatric/Adolescent (Engerix B / Recombivax) | O25: {=INDEX(Table!$I$4:$I$31,MATCH(1,(Table!$A$4:$A$31='Provider Order Form'!$B$3)*(Table!$B$4:$B$31='Provider Order Form'!$C$3),0))} -> 0
B26: Hep B - Hib | C26: Comvax: Hepatitis B Pediatric/Adolescent and Haemophilus influenzae type b Conjugate combination vaccine | O26: {=INDEX(Table!$U$4:$U$31,MATCH(1,(Table!$A$4:$A$31='Provider Order Form'!$B$3)*(Table!$B$4:$B$31='Provider Order Form'!$C$3),0))} -> 0
B27: Hib | C27: Haemophilus influenzae type b Conjugate (ActHIB / PedvaxHIB) | O27: {=INDEX(Table!$J$4:$J$31,MATCH(1,(Table!$A$4:$A$31='Provider Order Form'!$B$3)*(Table!$B$4:$B$31='Provider Order Form'!$C$3),0))} -> 0
B28: HPV | C28: Human Papillomavirus vaccine (Cervarix / Gardasil) | O28: {=INDEX(Table!$K$4:$K$31,MATCH(1,(Table!$A$4:$A$31='Provider Order Form'!$B$3)*(Table!$B$4:$B$31='Provider Order Form'!$C$3),0))} -> 0
B29: IPV | C29: Inactivated Poliovirus vaccine (IPOL) | O29: {=INDEX(Table!$G$4:$G$31,MATCH(1,(Table!$A$4:$A$31='Provider Order Form'!$B$3)*(Table!$B$4:$B$31='Provider Order Form'!$C$3),0))} -> 0
B30: MCV | C30: Meningococcal (Groups A, C, Y & W-135) Conjugate vaccine (Menactra / Menveo) | O30: {=INDEX(Table!$L$4:$L$31,MATCH(1,(Table!$A$4:$A$31='Provider Order Form'!$B$3)*(Table!$B$4:$B$31='Provider Order Form'!$C$3),0))} -> 0
B31: MMR | C31: Measles, Mumps, and Rubella combination vaccine (MMRII) | O31: {=INDEX(Table!$M$4:$M$31,MATCH(1,(Table!$A$4:$A$31='Provider Order Form'!$B$3)*(Table!$B$4:$B$31='Provider Order Form'!$C$3),0))} -> 0
B32: PCV | C32: Pneumococcal Conjugate 13-valent (Prevnar 13) | O32: {=INDEX(Table!$O$4:$O$31,MATCH(1,(Table!$A$4:$A$31='Provider Order Form'!$B$3)*(Table!$B$4:$B$31='Provider Order Form'!$C$3),0))} -> 0
B33: PPSV | C33: Pneumococcal polysaccharide vaccine (Special Circumstances Only) (Pneumovax 23) | O33: {=INDEX(Table!$N$4:$N$31,MATCH(1,(Table!$A$4:$A$31='Provider Order Form'!$B$3)*(Table!$B$4:$B$31='Provider Order Form'!$C$3),0))} -> 0
B34: Rota | C34: Rotavirus (Rotarix / RotaTeq) | O34: {=INDEX(Table!$P$4:$P$31,MATCH(1,(Table!$A$4:$A$31='Provider Order Form'!$B$3)*(Table!$B$4:$B$31='Provider Order Form'!$C$3),0))} -> 0
B35: Td | C35: Tetanus & diphtheria toxoids adsorbed (Decavac / Td) | O35: {=INDEX(Table!$Q$4:$Q$31,MATCH(1,(Table!$A$4:$A$31='Provider Order Form'!$B$3)*(Table!$B$4:$B$31='Provider Order Form'!$C$3),0))} -> 0
B36: Tdap | C36: Tetanus & diphtheria toxoids and acellular pertussis vaccine (Adacel / Boostrix) | O36: {=INDEX(Table!$R$4:$R$31,MATCH(1,(Table!$A$4:$A$31='Provider Order Form'!$B$3)*(Table!$B$4:$B$31='Provider Order Form'!$C$3),0))} -> 0
B37: Varicella | C37: Varicella vaccine (Freezer Storage Only) (Varivax) | O37: {=INDEX(Table!$S$4:$S$31,MATCH(1,(Table!$A$4:$A$31='Provider Order Form'!$B$3)*(Table!$B$4:$B$31='Provider Order Form'!$C$3),0))} -> 0
B38: MMRV | C38: MMR & Varicella combination vaccine (Freezer Storage Only) (ProQuad) | O38: {=INDEX(Table!$V$4:$V$31,MATCH(1,(Table!$A$4:$A$31='Provider Order Form'!$B$3)*(Table!$B$4:$B$31='Provider Order Form'!$C$3),0))} -> 0
B39: Immunization Guidelines For the Use of State-Supplied Vaccine
B40: Provider/LHJ Use - Online Vaccine Order | K40: DOH Use
B41: Order Number: | C41: Entered By: | D41: Order Entry Date: | G41: Approved By:
...

Sheet Table
C1: DT | D1: DTaP | E1: DTaP-Hep B-IPV | F1: DTaP-IPV-Hib | G1: e-IPV | H1: Hep A | I1: Hep B | J1: Hib | K1: HPV | L1: MCV | M1: MMR | N1: PPSV | O1: PCV | P1: Rotavirus | Q1: Td | R1: Tdap | S1: Varicella | T1: DTaP-IPV | U1: Hep B-Hib | V1: MMRV
B2: last | C2: ='Provider Order Form'!$K$19 -> 0 | D2: ='Provider Order Form'!$K$20 -> 0 | E2: ='Provider Order Form'!$K$21 -> 0 | F2: ='Provider Order Form'!$K$22 -> 0 | G2: ='Provider Order Form'!$K$29 -> 0 | H2: ='Provider Order Form'!$K$24 -> 0 | I2: ='Provider Order Form'!$K$25 -> 0 | J2: ='Provider Order Form'!$K$27 -> 0 | K2: ='Provider Order Form'!$K$28 -> 0 | L2: ='Provider Order Form'!$K$30 -> 0 | M2: ='Provider Order Form'!$K$31 -> 0 | N2: ='Provider Order Form'!$K$33 -> 0 | O2: ='Provider Order Form'!$K$32 -> 0 | P2: ='Provider Order Form'!$K$34 -> 0 | Q2: ='Provider Order Form'!$K$35 -> 0 | R2: ='Provider Order Form'!$K$36 -> 0 | S2: ='Provider Order Form'!$K$37 -> 0 | T2: ='Provider Order Form'!$K$23 -> 0 | U2: ='Provider Order Form'!$K$26 -> 0 | V2: ='Provider Order Form'!$K$38 -> 0
B3: oh | C3: ='Provider Order Form'!$M$19 -> 0 | D3: ='Provider Order Form'!$M$20 -> 0 | E3: ='Provider Order Form'!$M$21 -> 0 | F3: ='Provider Order Form'!$M$22 -> 0 | G3: ='Provider Order Form'!$M$29 -> 0 | H3: ='Provider Order Form'!$M$24 -> 0 | I3: ='Provider Order Form'!$M$25 -> 0 | J3: ='Provider Order Form'!$M$27 -> 0 | K3: ='Provider Order Form'!$M$28 -> 0 | L3: ='Provider Order Form'!$M$30 -> 0 | M3: ='Provider Order Form'!$M$31 -> 0 | N3: ='Provider Order Form'!$M$33 -> 0 | O3: ='Provider Order Form'!$M$32 -> 0 | P3: ='Provider Order Form'!$M$34 -> 0 | Q3: ='Provider Order Form'!$M$35 -> 0 | R3: ='Provider Order Form'!$M$36 -> 0 | S3: ='Provider Order Form'!$M$37 -> 0 | T3: ='Provider Order Form'!$M$23 -> 0 | U3: ='Provider Order Form'!$M$26 -> 0 | V3: ='Provider Order Form'!$M$38 -> 0
A4: Monthly | B4: =List!F2 -> January | C4: =IF(AND(C2<5,C3<5,(C2*2)>C3,(ROUND((IF((((C$2/C18)*C7)+((C2/C18)*C8)-C3)>0,(((C$2/C18)*C7)+((C2/C18)*C8)-C3),0)),-1))=0),10,(ROUNDUP((IF((((C$2/C18)*C7)+((C2/C18)*C8)-C3)>0,(((C$2/C18)*C7)+((C2/C18)*C8)-C3),0)),-1))) -> 0 | D4: =IF(AND(D2<5,D3<5,(D2*2)>D3,(ROUND((IF((((D$2/D18)*D7)+((D2/D18)*D8)-D3)>0,(((D$2/D18)*D7)+((D2/D18)*D8)-D3),0)),-1))=0),10,(ROUNDUP((IF((((D$2/D18)*D7)+((D2/D18)*D8)-D3)>0,(((D$2/D18)*D7)+((D2/D18)*D8)-D3),0)),-1))) -> 0 | E4: =IF(AND(E2<5,E3<5,(E2*2)>E3,(ROUND((IF((((E$2/E18)*E7)+((E2/E18)*E8)-E3)>0,(((E$2/E18)*E7)+((E2/E18)*E8)-E3),0)),-1))=0),10,(ROUNDUP((IF((((E$2/E18)*E7)+((E2/E18)*E8)-E3)>0,(((E$2/E18)*E7)+((E2/E18)*E8)-E3),0)),-1))) -> 0 | F4: =IF(AND(F2<5,F3<5,(F2*2)>F3,(MROUND((IF((((F$2/F18)*F7)+((F2/F18)*F8)-F3)>0,(((F$2/F18)*F7)+((F2/F18)*F8)-F3),0)),5))=0),5,(MROUND((IF((((F$2/F18)*F7)+((F2/F18)*F8)-F3)>0,((((F$2/F18)*F7)+((F2/F18)*F8)-F3)+2.25),0)),5))) -> 0 | G4: =IF(AND(G2<5,G3<5,(G2*2)>G3,(ROUND((IF((((G$2/G18)*G7)+((G2/G18)*G8)-G3)>0,(((G$2/G18)*G7)+((G2/G18)*G8)-G3),0)),-1))=0),10,(ROUNDUP((IF((((G$2/G18)*G7)+((G2/G18)*G8)-G3)>0,(((G$2/G18)*G7)+((G2/G18)*G8)-G3),0)),-1))) -> 0 | H4: =IF(AND(H2<5,H3<5,(H2*2)>H3,(ROUND((IF((((H$2/H18)*H7)+((H2/H18)*H8)-H3)>0,(((H$2/H18)*H7)+((H2/H18)*H8)-H3),0)),-1))=0),10,(ROUNDUP((IF((((H$2/H18)*H7)+((H2/H18)*H8)-H3)>0,(((H$2/H18)*H7)+((H2/H18)*H8)-H3),0)),-1))) -> 0 | I4: =IF(AND(I2<5,I3<5,(I2*2)>I3,(ROUND((IF((((I$2/I18)*I7)+((I2/I18)*I8)-I3)>0,(((I$2/I18)*I7)+((I2/I18)*I8)-I3),0)),-1))=0),10,(ROUNDUP((IF((((I$2/I18)*I7)+((I2/I18)*I8)-I3)>0,(((I$2/I18)*I7)+((I2/I18)*I8)-I3),0)),-1))) -> 0 | J4: =IF(AND(J2<5,J3<5,(J2*2)>J3,(MROUND((IF((((J$2/J18)*J7)+((J2/J18)*J8)-J3)>0,(((J$2/J18)*J7)+((J2/J18)*J8)-J3),0)),5))=0),5,(MROUND((IF((((J$2/J18)*J7)+((J2/J18)*J8)-J3)>0,((((J$2/J18)*J7)+((J2/J18)*J8)-J3)+2.25),0)),5))) -> 0 | K4: =IF(AND(K2<5,K3<5,(K2*2)>K3,(ROUND((IF((((K$2/K18)*K7)+((K2/K18)*K8)-K3)>0,(((K$2/K18)*K7)+((K2/K18)*K8)-K3),0)),-1))=0),10,(ROUNDUP((IF((((K$2/K18)*K7)+((K2/K18)*K8)-K3)>0,(((K$2/K18)*K7)+((K2/K18)*K8)-K3),0)),-1))) -> 0 | L4: =IF(AND(L2<5,L3<5,(L2*2)>L3,(MROUND((IF((((L$2/L18)*L7)+((L2/L18)*L8)-L3)>0,(((L$2/L18)*L7)+((L2/L18)*L8)-L3),0)),5))=0),5,(MROUND((IF((((L$2/L18)*L7)+((L2/L18)*L8)-L3)>0,((((L$2/L18)*L7)+((L2/L18)*L8)-L3)+2.25),0)),5))) -> 0 | M4: =IF(AND(M2<5,M3<5,(M2*2)>M3,(ROUND((IF((((M$2/M18)*M7)+((M2/M18)*M8)-M3)>0,(((M$2/M18)*M7)+((M2/M18)*M8)-M3),0)),-1))=0),10,(ROUNDUP((IF((((M$2/M18)*M7)+((M2/M18)*M8)-M3)>0,(((M$2/M18)*M7)+((M2/M18)*M8)-M3),0)),-1))) -> 0 | N4: =IF(AND(N2<5,N3<5,(N2*2)>N3,(ROUND((IF((((N$2/N18)*N7)+((N2/N18)*N8)-N3)>0,(((N$2/N18)*N7)+((N2/N18)*N8)-N3),0)),-1))=0),10,(ROUNDUP((IF((((N$2/N18)*N7)+((N2/N18)*N8)-N3)>0,(((N$2/N18)*N7)+((N2/N18)*N8)-N3),0)),-1))) -> 0 | O4: =IF(AND(O2<5,O3<5,(O2*2)>O3,(ROUND((IF((((O$2/O18)*O7)+((O2/O18)*O8)-O3)>0,(((O$2/O18)*O7)+((O2/O18)*O8)-O3),0)),-1))=0),10,(ROUNDUP((IF((((O$2/O18)*O7)+((O2/O18)*O8)-O3)>0,(((O$2/O18)*O7)+((O2/O18)*O8)-O3),0)),-1))) -> 0 | P4: =IF(AND(P2<5,P3<5,(P2*2)>P3,(ROUND((IF((((P$2/P18)*P7)+((P2/P18)*P8)-P3)>0,(((P$2/P18)*P7)+((P2/P18)*P8)-P3),0)),-1))=0),10,(ROUNDUP((IF((((P$2/P18)*P7)+((P2/P18)*P8)-P3)>0,(((P$2/P18)*P7)+((P2/P18)*P8)-P3),0)),-1))) -> 0 | Q4: =IF(AND(Q2<5,Q3<5,(Q2*2)>Q3,(ROUND((IF((((Q$2/Q18)*Q7)+((Q2/Q18)*Q8)-Q3)>0,(((Q$2/Q18)*Q7)+((Q2/Q18)*Q8)-Q3),0)),-1))=0),10,(ROUNDUP((IF((((Q$2/Q18)*Q7)+((Q2/Q18)*Q8)-Q3)>0,(((Q$2/Q18)*Q7)+((Q2/Q18)*Q8)-Q3),0)),-1))) -> 0 | R4: =IF(AND(R2<5,R3<5,(R2*2)>R3,(ROUND((IF((((R$2/R18)*R7)+((R2/R18)*R8)-R3)>0,(((R$2/R18)*R7)+((R2/R18)*R8)-R3),0)),-1))=0),10,(ROUNDUP((IF((((R$2/R18)*R7)+((R2/R18)*R8)-R3)>0,(((R$2/R18)*R7)+((R2/R18)*R8)-R3),0)),-1))) -> 0 | S4: =IF(AND(S2<5,S3<5,(S2*2)>S3,(ROUND((IF((((S$2/S18)*S7)+((S2/S18)*S8)-S3)>0,(((S$2/S18)*S7)+((S2/S18)*S8)-S3),0)),-1))=0),10,(ROUNDUP((IF((((S$2/S18)*S7)+((S2/S18)*S8)-S3)>0,(((S$2/S18)*S7)+((S2/S18)*S8)-S3),0)),-1))) -> 0 | T4: =IF(AND(T2<5,T3<5,(T2*2)>T3,(ROUND((IF((((T$2/T18)*T7)+((T2/T18)*T8)-T3)>0,(((T$2/T18)*T7)+((T2/T18)*T8)-T3),0)),-1))=0),10,(ROUNDUP((IF((((T$2/T18)*T7)+((T2/T18)*T8)-T3)>0,(((T$2/T18)*T7)+((T2/T18)*T8)-T3),0)),-1))) -> 0 | ... V4: =IF(AND(V2<5,V3<5,(V2*2)>V3,(ROUND((IF((((V$2/V18)*V7)+((V2/V18)*V8)-V3)>0,(((V$2/V18)*V7)+((V2/V18)*V8)-V3),0)),-1))=0),10,(ROUNDUP((IF((((V$2/V18)*V7)+((V2/V18)*V8)-V3)>0,(((V$2/V18)*V7)+((V2/V18)*V8)-V3),0)),-1))) -> 0
C6: DT | D6: DTaP | E6: DTaP-Hep B-IPV | F6: DTaP-IPV-Hib | G6: e-IPV | H6: Hep A | I6: Hep B | J6: Hib | K6: HPV | L6: MCV | M6: MMR | N6: PPSV | O6: PCV | P6: Rotavirus | Q6: Td | R6: Tdap | S6: Varicella | T6: DTaP-IPV | U6: Hep B-Hib | V6: Varicella
A7: Seasonality | B7: =List!F2 -> January | C7: =SUMIF(Seasonality!$A$17:$A$28,Table!$B7,Seasonality!B$17:B$28) -> 0.083333333 | D7: =SUMIF(Seasonality!$A$17:$A$28,Table!$B7,Seasonality!C$17:C$28) -> 0.069969601 | E7: =SUMIF(Seasonality!$A$17:$A$28,Table!$B7,Seasonality!D$17:D$28) -> 0.073262758 | F7: =SUMIF(Seasonality!$A$17:$A$28,Table!$B7,Seasonality!E$17:E$28) -> 0.069075372 | G7: =SUMIF(Seasonality!$A$17:$A$28,Table!$B7,Seasonality!F$17:F$28) -> 0.071272423 | H7: =SUMIF(Seasonality!$A$17:$A$28,Table!$B7,Seasonality!G$17:G$28) -> 0.057922227 | I7: =SUMIF(Seasonality!$A$17:$A$28,Table!$B7,Seasonality!H$17:H$28) -> 0.083741525 | J7: =SUMIF(Seasonality!$A$17:$A$28,Table!$B7,Seasonality!I$17:I$28) -> 0.073772438 | ... V7: =SUMIF(Seasonality!$A$17:$A$28,Table!$B7,Seasonality!U$17:U$28) -> 0.040326642
A8: Seasonality | B8: =List!F3 -> February | C8: =SUMIF(Seasonality!$A$17:$A$28,Table!$B8,Seasonality!B$17:B$28) -> 0.083333333 | D8: =SUMIF(Seasonality!$A$17:$A$28,Table!$B8,Seasonality!C$17:C$28) -> 0.076738957 | E8: =SUMIF(Seasonality!$A$17:$A$28,Table!$B8,Seasonality!D$17:D$28) -> 0.07784791 | F8: =SUMIF(Seasonality!$A$17:$A$28,Table!$B8,Seasonality!E$17:E$28) -> 0.075670723 | G8: =SUMIF(Seasonality!$A$17:$A$28,Table!$B8,Seasonality!F$17:F$28) -> 0.074285163 | H8: =SUMIF(Seasonality!$A$17:$A$28,Table!$B8,Seasonality!G$17:G$28) -> 0.07130059 | I8: =SUMIF(Seasonality!$A$17:$A$28,Table!$B8,Seasonality!H$17:H$28) -> 0.082085761 | J8: =SUMIF(Seasonality!$A$17:$A$28,Table!$B8,Seasonality!I$17:I$28) -> 0.077116816 | ... V8: =SUMIF(Seasonality!$A$17:$A$28,Table!$B8,Seasonality!U$17:U$28) -> 0.054908027
A9: Seasonality | B9: =List!F4 -> March | C9: =SUMIF(Seasonality!$A$17:$A$28,Table!$B9,Seasonality!B$17:B$28) -> 0.083333333 | D9: =SUMIF(Seasonality!$A$17:$A$28,Table!$B9,Seasonality!C$17:C$28) -> 0.071089992 | E9: =SUMIF(Seasonality!$A$17:$A$28,Table!$B9,Seasonality!D$17:D$28) -> 0.075959906 | F9: =SUMIF(Seasonality!$A$17:$A$28,Table!$B9,Seasonality!E$17:E$28) -> 0.07473576 | G9: =SUMIF(Seasonality!$A$17:$A$28,Table!$B9,Seasonality!F$17:F$28) -> 0.069490498 | H9: =SUMIF(Seasonality!$A$17:$A$28,Table!$B9,Seasonality!G$17:G$28) -> 0.0758071 | I9: =SUMIF(Seasonality!$A$17:$A$28,Table!$B9,Seasonality!H$17:H$28) -> 0.075450161 | J9: =SUMIF(Seasonality!$A$17:$A$28,Table!$B9,Seasonality!I$17:I$28) -> 0.073168592 | ... V9: =SUMIF(Seasonality!$A$17:$A$28,Table!$B9,Seasonality!U$17:U$28) -> 0.061155479
A10: Seasonality | B10: =List!F5 -> April | C10: =SUMIF(Seasonality!$A$17:$A$28,Table!$B10,Seasonality!B$17:B$28) -> 0.083333333 | D10: =SUMIF(Seasonality!$A$17:$A$28,Table!$B10,Seasonality!C$17:C$28) -> 0.085482708 | E10: =SUMIF(Seasonality!$A$17:$A$28,Table!$B10,Seasonality!D$17:D$28) -> 0.089196455 | F10: =SUMIF(Seasonality!$A$17:$A$28,Table!$B10,Seasonality!E$17:E$28) -> 0.085856756 | G10: =SUMIF(Seasonality!$A$17:$A$28,Table!$B10,Seasonality!F$17:F$28) -> 0.083314198 | H10: =SUMIF(Seasonality!$A$17:$A$28,Table!$B10,Seasonality!G$17:G$28) -> 0.085873449 | I10: =SUMIF(Seasonality!$A$17:$A$28,Table!$B10,Seasonality!H$17:H$28) -> 0.085930395 | J10: =SUMIF(Seasonality!$A$17:$A$28,Table!$B10,Seasonality!I$17:I$28) -> 0.080037986 | ... V10: =SUMIF(Seasonality!$A$17:$A$28,Table!$B10,Seasonality!U$17:U$28) -> 0.080737223
A11: Seasonality | B11: =List!F6 -> May | C11: =SUMIF(Seasonality!$A$17:$A$28,Table!$B11,Seasonality!B$17:B$28) -> 0.083333333 | D11: =SUMIF(Seasonality!$A$17:$A$28,Table!$B11,Seasonality!C$17:C$28) -> 0.084178197 | E11: =SUMIF(Seasonality!$A$17:$A$28,Table!$B11,Seasonality!D$17:D$28) -> 0.088302292 | F11: =SUMIF(Seasonality!$A$17:$A$28,Table!$B11,Seasonality!E$17:E$28) -> 0.084277175 | G11: =SUMIF(Seasonality!$A$17:$A$28,Table!$B11,Seasonality!F$17:F$28) -> 0.08152768 | H11: =SUMIF(Seasonality!$A$17:$A$28,Table!$B11,Seasonality!G$17:G$28) -> 0.08609063 | I11: =SUMIF(Seasonality!$A$17:$A$28,Table!$B11,Seasonality!H$17:H$28) -> 0.083490652 | J11: =SUMIF(Seasonality!$A$17:$A$28,Table!$B11,Seasonality!I$17:I$28) -> 0.076543936 | ... V11: =SUMIF(Seasonality!$A$17:$A$28,Table!$B11,Seasonality!U$17:U$28) -> 0.093208144
A12: Seasonality | B12: =List!F7 -> June | C12: =SUMIF(Seasonality!$A$17:$A$28,Table!$B12,Seasonality!B$17:B$28) -> 0.083333333 | D12: =SUMIF(Seasonality!$A$17:$A$28,Table!$B12,Seasonality!C$17:C$28) -> 0.081964837 | E12: =SUMIF(Seasonality!$A$17:$A$28,Table!$B12,Seasonality!D$17:D$28) -> 0.089161275 | F12: =SUMIF(Seasonality!$A$17:$A$28,Table!$B12,Seasonality!E$17:E$28) -> 0.084817909 | G12: =SUMIF(Seasonality!$A$17:$A$28,Table!$B12,Seasonality!F$17:F$28) -> 0.081302643 | H12: =SUMIF(Seasonality!$A$17:$A$28,Table!$B12,Seasonality!G$17:G$28) -> 0.082431126 | I12: =SUMIF(Seasonality!$A$17:$A$28,Table!$B12,Seasonality!H$17:H$28) -> 0.085353386 | J12: =SUMIF(Seasonality!$A$17:$A$28,Table!$B12,Seasonality!I$17:I$28) -> 0.077612279 | ... V12: =SUMIF(Seasonality!$A$17:$A$28,Table!$B12,Seasonality!U$17:U$28) -> 0.092296808
A13: Seasonality | B13: =List!F8 -> July | C13: =SUMIF(Seasonality!$A$17:$A$28,Table!$B13,Seasonality!B$17:B$28) -> 0.083333333 | D13: =SUMIF(Seasonality!$A$17:$A$28,Table!$B13,Seasonality!C$17:C$28) -> 0.095342934 | E13: =SUMIF(Seasonality!$A$17:$A$28,Table!$B13,Seasonality!D$17:D$28) -> 0.095045163 | F13: =SUMIF(Seasonality!$A$17:$A$28,Table!$B13,Seasonality!E$17:E$28) -> 0.096748673 | G13: =SUMIF(Seasonality!$A$17:$A$28,Table!$B13,Seasonality!F$17:F$28) -> 0.093707231 | H13: =SUMIF(Seasonality!$A$17:$A$28,Table!$B13,Seasonality!G$17:G$28) -> 0.090694871 | I13: =SUMIF(Seasonality!$A$17:$A$28,Table!$B13,Seasonality!H$17:H$28) -> 0.091405706 | J13: =SUMIF(Seasonality!$A$17:$A$28,Table!$B13,Seasonality!I$17:I$28) -> 0.095350902 | ... V13: =SUMIF(Seasonality!$A$17:$A$28,Table!$B13,Seasonality!U$17:U$28) -> 0.09627791
A14: Seasonality | B14: =List!F9 -> August | C14: =SUMIF(Seasonality!$A$17:$A$28,Table!$B14,Seasonality!B$17:B$28) -> 0.083333333 | D14: =SUMIF(Seasonality!$A$17:$A$28,Table!$B14,Seasonality!C$17:C$28) -> 0.097658148 | E14: =SUMIF(Seasonality!$A$17:$A$28,Table!$B14,Seasonality!D$17:D$28) -> 0.099671358 | F14: =SUMIF(Seasonality!$A$17:$A$28,Table!$B14,Seasonality!E$17:E$28) -> 0.093967758 | G14: =SUMIF(Seasonality!$A$17:$A$28,Table!$B14,Seasonality!F$17:F$28) -> 0.099948563 | H14: =SUMIF(Seasonality!$A$17:$A$28,Table!$B14,Seasonality!G$17:G$28) -> 0.1078739 | I14: =SUMIF(Seasonality!$A$17:$A$28,Table!$B14,Seasonality!H$17:H$28) -> 0.094127682 | J14: =SUMIF(Seasonality!$A$17:$A$28,Table!$B14,Seasonality!I$17:I$28) -> 0.084058465 | ... V14: =SUMIF(Seasonality!$A$17:$A$28,Table!$B14,Seasonality!U$17:U$28) -> 0.11918124
A15: Seasonality | B15: =List!F10 -> September | C15: =SUMIF(Seasonality!$A$17:$A$28,Table!$B15,Seasonality!B$17:B$28) -> 0.083333333 | D15: =SUMIF(Seasonality!$A$17:$A$28,Table!$B15,Seasonality!C$17:C$28) -> 0.09545654 | E15: =SUMIF(Seasonality!$A$17:$A$28,Table!$B15,Seasonality!D$17:D$28) -> 0.099002935 | F15: =SUMIF(Seasonality!$A$17:$A$28,Table!$B15,Seasonality!E$17:E$28) -> 0.09587764 | G15: =SUMIF(Seasonality!$A$17:$A$28,Table!$B15,Seasonality!F$17:F$28) -> 0.10019656 | H15: =SUMIF(Seasonality!$A$17:$A$28,Table!$B15,Seasonality!G$17:G$28) -> 0.1299178 | I15: =SUMIF(Seasonality!$A$17:$A$28,Table!$B15,Seasonality!H$17:H$28) -> 0.084569407 | J15: =SUMIF(Seasonality!$A$17:$A$28,Table!$B15,Seasonality!I$17:I$28) -> 0.081070201 | ... V15: =SUMIF(Seasonality!$A$17:$A$28,Table!$B15,Seasonality!U$17:U$28) -> 0.14840396
A16: Seasonality | B16: =List!F11 -> October | C16: =SUMIF(Seasonality!$A$17:$A$28,Table!$B16,Seasonality!B$17:B$28) -> 0.083333333 | D16: =SUMIF(Seasonality!$A$17:$A$28,Table!$B16,Seasonality!C$17:C$28) -> 0.090144476 | E16: =SUMIF(Seasonality!$A$17:$A$28,Table!$B16,Seasonality!D$17:D$28) -> 0.082075397 | F16: =SUMIF(Seasonality!$A$17:$A$28,Table!$B16,Seasonality!E$17:E$28) -> 0.087529567 | G16: =SUMIF(Seasonality!$A$17:$A$28,Table!$B16,Seasonality!F$17:F$28) -> 0.09047864 | H16: =SUMIF(Seasonality!$A$17:$A$28,Table!$B16,Seasonality!G$17:G$28) -> 0.082691744 | I16: =SUMIF(Seasonality!$A$17:$A$28,Table!$B16,Seasonality!H$17:H$28) -> 0.084055117 | J16: =SUMIF(Seasonality!$A$17:$A$28,Table!$B16,Seasonality!I$17:I$28) -> 0.094272237 | ... V16: =SUMIF(Seasonality!$A$17:$A$28,Table!$B16,Seasonality!U$17:U$28) -> 0.087644195
A17: Seasonality | B17: =List!F12 -> November | C17: =SUMIF(Seasonality!$A$17:$A$28,Table!$B17,Seasonality!B$17:B$28) -> 0.083333333 | D17: =SUMIF(Seasonality!$A$17:$A$28,Table!$B17,Seasonality!C$17:C$28) -> 0.07948509 | E17: =SUMIF(Seasonality!$A$17:$A$28,Table!$B17,Seasonality!D$17:D$28) -> 0.069346029 | F17: =SUMIF(Seasonality!$A$17:$A$28,Table!$B17,Seasonality!E$17:E$28) -> 0.081842543 | G17: =SUMIF(Seasonality!$A$17:$A$28,Table!$B17,Seasonality!F$17:F$28) -> 0.080636717 | H17: =SUMIF(Seasonality!$A$17:$A$28,Table!$B17,Seasonality!G$17:G$28) -> 0.071832684 | I17: =SUMIF(Seasonality!$A$17:$A$28,Table!$B17,Seasonality!H$17:H$28) -> 0.076855052 | J17: =SUMIF(Seasonality!$A$17:$A$28,Table!$B17,Seasonality!I$17:I$28) -> 0.099737817 | ... V17: =SUMIF(Seasonality!$A$17:$A$28,Table!$B17,Seasonality!U$17:U$28) -> 0.077643476
A18: Seasonality | B18: =List!F13 -> December | C18: =SUMIF(Seasonality!$A$17:$A$28,Table!$B18,Seasonality!B$17:B$28) -> 0.083333333 | D18: =SUMIF(Seasonality!$A$17:$A$28,Table!$B18,Seasonality!C$17:C$28) -> 0.072488522 | E18: =SUMIF(Seasonality!$A$17:$A$28,Table!$B18,Seasonality!D$17:D$28) -> 0.061128522 | F18: =SUMIF(Seasonality!$A$17:$A$28,Table!$B18,Seasonality!E$17:E$28) -> 0.069600124 | G18: =SUMIF(Seasonality!$A$17:$A$28,Table!$B18,Seasonality!F$17:F$28) -> 0.073839682 | H18: =SUMIF(Seasonality!$A$17:$A$28,Table!$B18,Seasonality!G$17:G$28) -> 0.057563878 | I18: =SUMIF(Seasonality!$A$17:$A$28,Table!$B18,Seasonality!H$17:H$28) -> 0.072935156 | J18: =SUMIF(Seasonality!$A$17:$A$28,Table!$B18,Seasonality!I$17:I$28) -> 0.087258333 | ... V18: =SUMIF(Seasonality!$A$17:$A$28,Table!$B18,Seasonality!U$17:U$28) -> 0.048216898
C20: DT | D20: DTaP | E20: DTaP-Hep B-IPV | F20: DTaP-IPV-Hib | G20: e-IPV | H20: Hep A | I20: Hep B | J20: Hib | K20: HPV | L20: MCV | M20: MMR | N20: PPSV | O20: PCV | P20: Rotavirus | Q20: Td | R20: Tdap | S20: Varicella | T20: DTaP-IPV | U20: Hep B-Hib | V20: Varicella
A21: Quarterly | B21: =List!G2 -> January | C21: =IF(AND(C2<5,C3<5,(C2*4)>C3,(ROUND((IF((((C$2/C18)*C7)+((C2/C18)*C8)+((C2/C18)*C9)+((C2/C18)*C10)-C3)>0,(((C$2/C18)*C7)+((C2/C18)*C8)+((C2/C18)*C9)+((C2/C18)*C10)-C3),0)),-1))=0),10,(ROUNDUP((IF((((C$2/C18)*C7)+((C2/C18)*C8)+((C2/C18)*C9)+((C2/C18)*C10)-C3)>0,(((C$2/C18)*C7)+((C2/C18)*C8)+((C2/C18)*C9)+((C2/C18)*C10)-C3),0)),-1))) -> 0 | D21: =IF(AND(D2<5,D3<5,(D2*4)>D3,(ROUND((IF((((D$2/D18)*D7)+((D2/D18)*D8)+((D2/D18)*D9)+((D2/D18)*D10)-D3)>0,(((D$2/D18)*D7)+((D2/D18)*D8)+((D2/D18)*D9)+((D2/D18)*D10)-D3),0)),-1))=0),10,(ROUNDUP((IF((((D$2/D18)*D7)+((D2/D18)*D8)+((D2/D18)*D9)+((D2/D18)*D10)-D3)>0,(((D$2/D18)*D7)+((D2/D18)*D8)+((D2/D18)*D9)+((D2/D18)*D10)-D3),0)),-1))) -> 0 | E21: =IF(AND(E2<5,E3<5,(E2*4)>E3,(ROUND((IF((((E$2/E18)*E7)+((E2/E18)*E8)+((E2/E18)*E9)+((E2/E18)*E10)-E3)>0,(((E$2/E18)*E7)+((E2/E18)*E8)+((E2/E18)*E9)+((E2/E18)*E10)-E3),0)),-1))=0),10,(ROUNDUP((IF((((E$2/E18)*E7)+((E2/E18)*E8)+((E2/E18)*E9)+((E2/E18)*E10)-E3)>0,(((E$2/E18)*E7)+((E2/E18)*E8)+((E2/E18)*E9)+((E2/E18)*E10)-E3),0)),-1))) -> 0 | F21: =IF(AND(F2<5,F3<5,(F2*4)>F3,(MROUND((IF((((F$2/F18)*F7)+((F2/F18)*F8)+((F2/F18)*F9)+((F2/F18)*F10)-F3)>0,(((F$2/F18)*F7)+((F2/F18)*F8)+((F2/F18)*F9)+((F2/F18)*F10)-F3),0)),5))=0),5,(MROUND((IF((((F$2/F18)*F7)+((F2/F18)*F8)+((F2/F18)*F9)+((F2/F18)*F10)-F3)>0,((((F$2/F18)*F7)+((F2/F18)*F8)+((F2/F18)*F9)+((F2/F18)*F10)-F3)+2.25),0)),5))) -> 0 | G21: =IF(AND(G2<5,G3<5,(G2*4)>G3,(ROUND((IF((((G$2/G18)*G7)+((G2/G18)*G8)+((G2/G18)*G9)+((G2/G18)*G10)-G3)>0,(((G$2/G18)*G7)+((G2/G18)*G8)+((G2/G18)*G9)+((G2/G18)*G10)-G3),0)),-1))=0),10,(ROUNDUP((IF((((G$2/G18)*G7)+((G2/G18)*G8)+((G2/G18)*G9)+((G2/G18)*G10)-G3)>0,(((G$2/G18)*G7)+((G2/G18)*G8)+((G2/G18)*G9)+((G2/G18)*G10)-G3),0)),-1))) -> 0 | H21: =IF(AND(H2<5,H3<5,(H2*4)>H3,(ROUND((IF((((H$2/H18)*H7)+((H2/H18)*H8)+((H2/H18)*H9)+((H2/H18)*H10)-H3)>0,(((H$2/H18)*H7)+((H2/H18)*H8)+((H2/H18)*H9)+((H2/H18)*H10)-H3),0)),-1))=0),10,(ROUNDUP((IF((((H$2/H18)*H7)+((H2/H18)*H8)+((H2/H18)*H9)+((H2/H18)*H10)-H3)>0,(((H$2/H18)*H7)+((H2/H18)*H8)+((H2/H18)*H9)+((H2/H18)*H10)-H3),0)),-1))) -> 0 | I21: =IF(AND(I2<5,I3<5,(I2*4)>I3,(ROUND((IF((((I$2/I18)*I7)+((I2/I18)*I8)+((I2/I18)*I9)+((I2/I18)*I10)-I3)>0,(((I$2/I18)*I7)+((I2/I18)*I8)+((I2/I18)*I9)+((I2/I18)*I10)-I3),0)),-1))=0),10,(ROUNDUP((IF((((I$2/I18)*I7)+((I2/I18)*I8)+((I2/I18)*I9)+((I2/I18)*I10)-I3)>0,(((I$2/I18)*I7)+((I2/I18)*I8)+((I2/I18)*I9)+((I2/I18)*I10)-I3),0)),-1))) -> 0 | J21: =IF(AND(J2<5,J3<5,(J2*4)>J3,(ROUND((IF((((J$2/J18)*J7)+((J2/J18)*J8)+((J2/J18)*J9)+((J2/J18)*J10)-J3)>0,(((J$2/J18)*J7)+((J2/J18)*J8)+((J2/J18)*J9)+((J2/J18)*J10)-J3),0)),-1))=0),10,(ROUNDUP((IF((((J$2/J18)*J7)+((J2/J18)*J8)+((J2/J18)*J9)+((J2/J18)*J10)-J3)>0,(((J$2/J18)*J7)+((J2/J18)*J8)+((J2/J18)*J9)+((J2/J18)*J10)-J3),0)),-1))) -> 0 | K21: =IF(AND(K2<5,K3<5,(K2*4)>K3,(ROUND((IF((((K$2/K18)*K7)+((K2/K18)*K8)+((K2/K18)*K9)+((K2/K18)*K10)-K3)>0,(((K$2/K18)*K7)+((K2/K18)*K8)+((K2/K18)*K9)+((K2/K18)*K10)-K3),0)),-1))=0),10,(ROUNDUP((IF((((K$2/K18)*K7)+((K2/K18)*K8)+((K2/K18)*K9)+((K2/K18)*K10)-K3)>0,(((K$2/K18)*K7)+((K2/K18)*K8)+((K2/K18)*K9)+((K2/K18)*K10)-K3),0)),-1))) -> 0 | L21: =IF(AND(L2<5,L3<5,(L2*4)>L3,(MROUND((IF((((L$2/L18)*L7)+((L2/L18)*L8)+((L2/L18)*L9)+((L2/L18)*L10)-L3)>0,(((L$2/L18)*L7)+((L2/L18)*L8)+((L2/L18)*L9)+((L2/L18)*L10)-L3),0)),5))=0),5,(MROUND((IF((((L$2/L18)*L7)+((L2/L18)*L8)+((L2/L18)*L9)+((L2/L18)*L10)-L3)>0,((((L$2/L18)*L7)+((L2/L18)*L8)+((L2/L18)*L9)+((L2/L18)*L10)-L3)+2.25),0)),5))) -> 0 | M21: =IF(AND(M2<5,M3<5,(M2*4)>M3,(ROUND((IF((((M$2/M18)*M7)+((M2/M18)*M8)+((M2/M18)*M9)+((M2/M18)*M10)-M3)>0,(((M$2/M18)*M7)+((M2/M18)*M8)+((M2/M18)*M9)+((M2/M18)*M10)-M3),0)),-1))=0),10,(ROUNDUP((IF((((M$2/M18)*M7)+((M2/M18)*M8)+((M2/M18)*M9)+((M2/M18)*M10)-M3)>0,(((M$2/M18)*M7)+((M2/M18)*M8)+((M2/M18)*M9)+((M2/M18)*M10)-M3),0)),-1))) -> 0 | N21: =IF(AND(N2<5,N3<5,(N2*4)>N3,(ROUND((IF((((N$2/N18)*N7)+((N2/N18)*N8)+((N2/N18)*N9)+((N2/N18)*N10)-N3)>0,(((N$2/N18)*N7)+((N2/N18)*N8)+((N2/N18)*N9)+((N2/N18)*N10)-N3),0)),-1))=0),10,(ROUNDUP((IF((((N$2/N18)*N7)+((N2/N18)*N8)+((N2/N18)*N9)+((N2/N18)*N10)-N3)>0,(((N$2/N18)*N7)+((N2/N18)*N8)+((N2/N18)*N9)+((N2/N18)*N10)-N3),0)),-1))) -> 0 | O21: =IF(AND(O2<5,O3<5,(O2*4)>O3,(ROUND((IF((((O$2/O18)*O7)+((O2/O18)*O8)+((O2/O18)*O9)+((O2/O18)*O10)-O3)>0,(((O$2/O18)*O7)+((O2/O18)*O8)+((O2/O18)*O9)+((O2/O18)*O10)-O3),0)),-1))=0),10,(ROUNDUP((IF((((O$2/O18)*O7)+((O2/O18)*O8)+((O2/O18)*O9)+((O2/O18)*O10)-O3)>0,(((O$2/O18)*O7)+((O2/O18)*O8)+((O2/O18)*O9)+((O2/O18)*O10)-O3),0)),-1))) -> 0 | P21: =IF(AND(P2<5,P3<5,(P2*4)>P3,(ROUND((IF((((P$2/P18)*P7)+((P2/P18)*P8)+((P2/P18)*P9)+((P2/P18)*P10)-P3)>0,(((P$2/P18)*P7)+((P2/P18)*P8)+((P2/P18)*P9)+((P2/P18)*P10)-P3),0)),-1))=0),10,(ROUNDUP((IF((((P$2/P18)*P7)+((P2/P18)*P8)+((P2/P18)*P9)+((P2/P18)*P10)-P3)>0,(((P$2/P18)*P7)+((P2/P18)*P8)+((P2/P18)*P9)+((P2/P18)*P10)-P3),0)),-1))) -> 0 | Q21: =IF(AND(Q2<5,Q3<5,(Q2*4)>Q3,(ROUND((IF((((Q$2/Q18)*Q7)+((Q2/Q18)*Q8)+((Q2/Q18)*Q9)+((Q2/Q18)*Q10)-Q3)>0,(((Q$2/Q18)*Q7)+((Q2/Q18)*Q8)+((Q2/Q18)*Q9)+((Q2/Q18)*Q10)-Q3),0)),-1))=0),10,(ROUNDUP((IF((((Q$2/Q18)*Q7)+((Q2/Q18)*Q8)+((Q2/Q18)*Q9)+((Q2/Q18)*Q10)-Q3)>0,(((Q$2/Q18)*Q7)+((Q2/Q18)*Q8)+((Q2/Q18)*Q9)+((Q2/Q18)*Q10)-Q3),0)),-1))) -> 0 | R21: =IF(AND(R2<5,R3<5,(R2*4)>R3,(ROUND((IF((((R$2/R18)*R7)+((R2/R18)*R8)+((R2/R18)*R9)+((R2/R18)*R10)-R3)>0,(((R$2/R18)*R7)+((R2/R18)*R8)+((R2/R18)*R9)+((R2/R18)*R10)-R3),0)),-1))=0),10,(ROUNDUP((IF((((R$2/R18)*R7)+((R2/R18)*R8)+((R2/R18)*R9)+((R2/R18)*R10)-R3)>0,(((R$2/R18)*R7)+((R2/R18)*R8)+((R2/R18)*R9)+((R2/R18)*R10)-R3),0)),-1))) -> 0 | S21: =IF(AND(S2<5,S3<5,(S2*4)>S3,(ROUND((IF((((S$2/S18)*S7)+((S2/S18)*S8)+((S2/S18)*S9)+((S2/S18)*S10)-S3)>0,(((S$2/S18)*S7)+((S2/S18)*S8)+((S2/S18)*S9)+((S2/S18)*S10)-S3),0)),-1))=0),10,(ROUNDUP((IF((((S$2/S18)*S7)+((S2/S18)*S8)+((S2/S18)*S9)+((S2/S18)*S10)-S3)>0,(((S$2/S18)*S7)+((S2/S18)*S8)+((S2/S18)*S9)+((S2/S18)*S10)-S3),0)),-1))) -> 0 | T21: =IF(AND(T2<5,T3<5,(T2*4)>T3,(ROUND((IF((((T$2/T18)*T7)+((T2/T18)*T8)+((T2/T18)*T9)+((T2/T18)*T10)-T3)>0,(((T$2/T18)*T7)+((T2/T18)*T8)+((T2/T18)*T9)+((T2/T18)*T10)-T3),0)),-1))=0),10,(ROUNDUP((IF((((T$2/T18)*T7)+((T2/T18)*T8)+((T2/T18)*T9)+((T2/T18)*T10)-T3)>0,(((T$2/T18)*T7)+((T2/T18)*T8)+((T2/T18)*T9)+((T2/T18)*T10)-T3),0)),-1))) -> 0 | ... V21: =IF(AND(V2<5,V3<5,(V2*4)>V3,(ROUND((IF((((V$2/V18)*V7)+((V2/V18)*V8)+((V2/V18)*V9)+((V2/V18)*V10)-V3)>0,(((V$2/V18)*V7)+((V2/V18)*V8)+((V2/V18)*V9)+((V2/V18)*V10)-V3),0)),-1))=0),10,(ROUNDUP((IF((((V$2/V18)*V7)+((V2/V18)*V8)+((V2/V18)*V9)+((V2/V18)*V10)-V3)>0,(((V$2/V18)*V7)+((V2/V18)*V8)+((V2/V18)*V9)+((V2/V18)*V10)-V3),0)),-1))) -> 0
C23: DT | D23: DTaP | E23: DTaP-Hep B-IPV | F23: DTaP-IPV-Hib | G23: e-IPV | H23: Hep A | I23: Hep B | J23: Hib | K23: HPV | L23: MCV | M23: MMR | N23: PPSV | O23: PCV | P23: Rotavirus | Q23: Td | R23: Tdap | S23: Varicella | T23: DTaP-IPV | U23: Hep B-Hib | V23: Varicella
A24: Every 2 Months | B24: =List!H2 -> January | C24: =IF(AND(C2<5,C3<5,(C2*3)>C3,(ROUND((IF((((C$2/C$18)*C7)+((C$2/C$18)*C8)+((C$2/C$18)*C9)-C3)>0,(((C$2/C$18)*C7)+((C$2/C$18)*C8)+((C$2/C$18)*C9)-C3),0)),-1))=0),10,(ROUNDUP((IF((((C$2/C$18)*C7)+((C$2/C$18)*C8)+((C$2/C$18)*C9)-C3)>0,(((C$2/C$18)*C7)+((C$2/C$18)*C8)+((C$2/C$18)*C9)-C3),0)),-1))) -> 0 | D24: =IF(AND(D2<5,D3<5,(D2*3)>D3,(ROUND((IF((((D$2/D$18)*D7)+((D$2/D$18)*D8)+((D$2/D$18)*D9)-D3)>0,(((D$2/D$18)*D7)+((D$2/D$18)*D8)+((D$2/D$18)*D9)-D3),0)),-1))=0),10,(ROUNDUP((IF((((D$2/D$18)*D7)+((D$2/D$18)*D8)+((D$2/D$18)*D9)-D3)>0,(((D$2/D$18)*D7)+((D$2/D$18)*D8)+((D$2/D$18)*D9)-D3),0)),-1))) -> 0 | E24: =IF(AND(E2<5,E3<5,(E2*3)>E3,(ROUND((IF((((E$2/E$18)*E7)+((E$2/E$18)*E8)+((E$2/E$18)*E9)-E3)>0,(((E$2/E$18)*E7)+((E$2/E$18)*E8)+((E$2/E$18)*E9)-E3),0)),-1))=0),10,(ROUNDUP((IF((((E$2/E$18)*E7)+((E$2/E$18)*E8)+((E$2/E$18)*E9)-E3)>0,(((E$2/E$18)*E7)+((E$2/E$18)*E8)+((E$2/E$18)*E9)-E3),0)),-1))) -> 0 | F24: =IF(AND(F2<5,F3<5,(F2*3)>F3,(MROUND((IF((((F$2/F$18)*F7)+((F$2/F$18)*F8)+((F$2/F$18)*F9)-F3)>0,(((F$2/F$18)*F7)+((F$2/F$18)*F8)+((F$2/F$18)*F9)-F3),0)),5))=0),5,(MROUND((IF((((F$2/F$18)*F7)+((F$2/F$18)*F8)+((F$2/F$18)*F9)-F3)>0,((((F$2/F$18)*F7)+((F$2/F$18)*F8)+((F$2/F$18)*F9)-F3)+2.25),0)),5))) -> 0 | G24: =IF(AND(G2<5,G3<5,(G2*3)>G3,(ROUND((IF((((G$2/G$18)*G7)+((G$2/G$18)*G8)+((G$2/G$18)*G9)-G3)>0,(((G$2/G$18)*G7)+((G$2/G$18)*G8)+((G$2/G$18)*G9)-G3),0)),-1))=0),10,(ROUNDUP((IF((((G$2/G$18)*G7)+((G$2/G$18)*G8)+((G$2/G$18)*G9)-G3)>0,(((G$2/G$18)*G7)+((G$2/G$18)*G8)+((G$2/G$18)*G9)-G3),0)),-1))) -> 0 | H24: =IF(AND(H2<5,H3<5,(H2*3)>H3,(ROUND((IF((((H$2/H$18)*H7)+((H$2/H$18)*H8)+((H$2/H$18)*H9)-H3)>0,(((H$2/H$18)*H7)+((H$2/H$18)*H8)+((H$2/H$18)*H9)-H3),0)),-1))=0),10,(ROUNDUP((IF((((H$2/H$18)*H7)+((H$2/H$18)*H8)+((H$2/H$18)*H9)-H3)>0,(((H$2/H$18)*H7)+((H$2/H$18)*H8)+((H$2/H$18)*H9)-H3),0)),-1))) -> 0 | I24: =IF(AND(I2<5,I3<5,(I2*3)>I3,(ROUND((IF((((I$2/I$18)*I7)+((I$2/I$18)*I8)+((I$2/I$18)*I9)-I3)>0,(((I$2/I$18)*I7)+((I$2/I$18)*I8)+((I$2/I$18)*I9)-I3),0)),-1))=0),10,(ROUNDUP((IF((((I$2/I$18)*I7)+((I$2/I$18)*I8)+((I$2/I$18)*I9)-I3)>0,(((I$2/I$18)*I7)+((I$2/I$18)*I8)+((I$2/I$18)*I9)-I3),0)),-1))) -> 0 | J24: =IF(AND(J2<5,J3<5,(J2*3)>J3,(ROUND((IF((((J$2/J$18)*J7)+((J$2/J$18)*J8)+((J$2/J$18)*J9)-J3)>0,(((J$2/J$18)*J7)+((J$2/J$18)*J8)+((J$2/J$18)*J9)-J3),0)),-1))=0),10,(ROUNDUP((IF((((J$2/J$18)*J7)+((J$2/J$18)*J8)+((J$2/J$18)*J9)-J3)>0,(((J$2/J$18)*J7)+((J$2/J$18)*J8)+((J$2/J$18)*J9)-J3),0)),-1))) -> 0 | K24: =IF(AND(K2<5,K3<5,(K2*3)>K3,(ROUND((IF((((K$2/K$18)*K7)+((K$2/K$18)*K8)+((K$2/K$18)*K9)-K3)>0,(((K$2/K$18)*K7)+((K$2/K$18)*K8)+((K$2/K$18)*K9)-K3),0)),-1))=0),10,(ROUNDUP((IF((((K$2/K$18)*K7)+((K$2/K$18)*K8)+((K$2/K$18)*K9)-K3)>0,(((K$2/K$18)*K7)+((K$2/K$18)*K8)+((K$2/K$18)*K9)-K3),0)),-1))) -> 0 | L24: =IF(AND(L2<5,L3<5,(L2*3)>L3,(MROUND((IF((((L$2/L$18)*L7)+((L$2/L$18)*L8)+((L$2/L$18)*L9)-L3)>0,(((L$2/L$18)*L7)+((L$2/L$18)*L8)+((L$2/L$18)*L9)-L3),0)),5))=0),5,(MROUND((IF((((L$2/L$18)*L7)+((L$2/L$18)*L8)+((L$2/L$18)*L9)-L3)>0,((((L$2/L$18)*L7)+((L$2/L$18)*L8)+((L$2/L$18)*L9)-L3)+2.25),0)),5))) -> 0 | M24: =IF(AND(M2<5,M3<5,(M2*3)>M3,(ROUND((IF((((M$2/M$18)*M7)+((M$2/M$18)*M8)+((M$2/M$18)*M9)-M3)>0,(((M$2/M$18)*M7)+((M$2/M$18)*M8)+((M$2/M$18)*M9)-M3),0)),-1))=0),10,(ROUNDUP((IF((((M$2/M$18)*M7)+((M$2/M$18)*M8)+((M$2/M$18)*M9)-M3)>0,(((M$2/M$18)*M7)+((M$2/M$18)*M8)+((M$2/M$18)*M9)-M3),0)),-1))) -> 0 | N24: =IF(AND(N2<5,N3<5,(N2*3)>N3,(ROUND((IF((((N$2/N$18)*N7)+((N$2/N$18)*N8)+((N$2/N$18)*N9)-N3)>0,(((N$2/N$18)*N7)+((N$2/N$18)*N8)+((N$2/N$18)*N9)-N3),0)),-1))=0),10,(ROUNDUP((IF((((N$2/N$18)*N7)+((N$2/N$18)*N8)+((N$2/N$18)*N9)-N3)>0,(((N$2/N$18)*N7)+((N$2/N$18)*N8)+((N$2/N$18)*N9)-N3),0)),-1))) -> 0 | O24: =IF(AND(O2<5,O3<5,(O2*3)>O3,(ROUND((IF((((O$2/O$18)*O7)+((O$2/O$18)*O8)+((O$2/O$18)*O9)-O3)>0,(((O$2/O$18)*O7)+((O$2/O$18)*O8)+((O$2/O$18)*O9)-O3),0)),-1))=0),10,(ROUNDUP((IF((((O$2/O$18)*O7)+((O$2/O$18)*O8)+((O$2/O$18)*O9)-O3)>0,(((O$2/O$18)*O7)+((O$2/O$18)*O8)+((O$2/O$18)*O9)-O3),0)),-1))) -> 0 | P24: =IF(AND(P2<5,P3<5,(P2*3)>P3,(ROUND((IF((((P$2/P$18)*P7)+((P$2/P$18)*P8)+((P$2/P$18)*P9)-P3)>0,(((P$2/P$18)*P7)+((P$2/P$18)*P8)+((P$2/P$18)*P9)-P3),0)),-1))=0),10,(ROUNDUP((IF((((P$2/P$18)*P7)+((P$2/P$18)*P8)+((P$2/P$18)*P9)-P3)>0,(((P$2/P$18)*P7)+((P$2/P$18)*P8)+((P$2/P$18)*P9)-P3),0)),-1))) -> 0 | Q24: =IF(AND(Q2<5,Q3<5,(Q2*3)>Q3,(ROUND((IF((((Q$2/Q$18)*Q7)+((Q$2/Q$18)*Q8)+((Q$2/Q$18)*Q9)-Q3)>0,(((Q$2/Q$18)*Q7)+((Q$2/Q$18)*Q8)+((Q$2/Q$18)*Q9)-Q3),0)),-1))=0),10,(ROUNDUP((IF((((Q$2/Q$18)*Q7)+((Q$2/Q$18)*Q8)+((Q$2/Q$18)*Q9)-Q3)>0,(((Q$2/Q$18)*Q7)+((Q$2/Q$18)*Q8)+((Q$2/Q$18)*Q9)-Q3),0)),-1))) -> 0 | R24: =IF(AND(R2<5,R3<5,(R2*3)>R3,(ROUND((IF((((R$2/R$18)*R7)+((R$2/R$18)*R8)+((R$2/R$18)*R9)-R3)>0,(((R$2/R$18)*R7)+((R$2/R$18)*R8)+((R$2/R$18)*R9)-R3),0)),-1))=0),10,(ROUNDUP((IF((((R$2/R$18)*R7)+((R$2/R$18)*R8)+((R$2/R$18)*R9)-R3)>0,(((R$2/R$18)*R7)+((R$2/R$18)*R8)+((R$2/R$18)*R9)-R3),0)),-1))) -> 0 | S24: =IF(AND(S2<5,S3<5,(S2*3)>S3,(ROUND((IF((((S$2/S$18)*S7)+((S$2/S$18)*S8)+((S$2/S$18)*S9)-S3)>0,(((S$2/S$18)*S7)+((S$2/S$18)*S8)+((S$2/S$18)*S9)-S3),0)),-1))=0),10,(ROUNDUP((IF((((S$2/S$18)*S7)+((S$2/S$18)*S8)+((S$2/S$18)*S9)-S3)>0,(((S$2/S$18)*S7)+((S$2/S$18)*S8)+((S$2/S$18)*S9)-S3),0)),-1))) -> 0 | T24: =IF(AND(T2<5,T3<5,(T2*3)>T3,(ROUND((IF((((T$2/T$18)*T7)+((T$2/T$18)*T8)+((T$2/T$18)*T9)-T3)>0,(((T$2/T$18)*T7)+((T$2/T$18)*T8)+((T$2/T$18)*T9)-T3),0)),-1))=0),10,(ROUNDUP((IF((((T$2/T$18)*T7)+((T$2/T$18)*T8)+((T$2/T$18)*T9)-T3)>0,(((T$2/T$18)*T7)+((T$2/T$18)*T8)+((T$2/T$18)*T9)-T3),0)),-1))) -> 0 | ... V24: =IF(AND(V2<5,V3<5,(V2*3)>V3,(ROUND((IF((((V$2/V$18)*V7)+((V$2/V$18)*V8)+((V$2/V$18)*V9)-V3)>0,(((V$2/V$18)*V7)+((V$2/V$18)*V8)+((V$2/V$18)*V9)-V3),0)),-1))=0),10,(ROUNDUP((IF((((V$2/V$18)*V7)+((V$2/V$18)*V8)+((V$2/V$18)*V9)-V3)>0,(((V$2/V$18)*V7)+((V$2/V$18)*V8)+((V$2/V$18)*V9)-V3),0)),-1))) -> 0
C26: DT | D26: DTaP | E26: DTaP-Hep B-IPV | F26: DTaP-IPV-Hib | G26: e-IPV | H26: Hep A | I26: Hep B | J26: Hib | K26: HPV | L26: MCV | M26: MMR | N26: PPSV | O26: PCV | P26: Rotavirus | Q26: Td | R26: Tdap | S26: Varicella | T26: DTaP-IPV | U26: Hep B-Hib | V26: Varicella
A27: Every 6 Months | B27: =List!I2 -> January | C27: =IF(AND(C2<5,C3<5,(C2*7)>C3,(ROUND((IF((((C$2/C$18)*C7)+((C$2/C$18)*C8)+((C$2/C$18)*C9)+((C$2/C$18)*C10)+((C$2/C$18)*C11)+((C$2/C$18)*C12)+((C$2/C$18)*C13)-C3)>0,(((C$2/C$18)*C7)+((C$2/C$18)*C8)+((C$2/C$18)*C9)+((C$2/C$18)*C10)+((C$2/C$18)*C11)+((C$2/C$18)*C12)+((C$2/C$18)*C13)-C3),0)),-1))=0),10,(ROUNDUP((IF((((C$2/C$18)*C7)+((C$2/C$18)*C8)+((C$2/C$18)*C9)+((C$2/C$18)*C10)+((C$2/C$18)*C11)+((C$2/C$18)*C12)+((C$2/C$18)*C13)-C3)>0,(((C$2/C$18)*C7)+((C$2/C$18)*C8)+((C$2/C$18)*C9)+((C$2/C$18)*C10)+((C$2/C$18)*C11)+((C$2/C$18)*C12)+((C$2/C$18)*C13)-C3),0)),-1))) -> 0 | D27: =IF(AND(D2<5,D3<5,(D2*7)>D3,(ROUND((IF((((D$2/D$18)*D7)+((D$2/D$18)*D8)+((D$2/D$18)*D9)+((D$2/D$18)*D10)+((D$2/D$18)*D11)+((D$2/D$18)*D12)+((D$2/D$18)*D13)-D3)>0,(((D$2/D$18)*D7)+((D$2/D$18)*D8)+((D$2/D$18)*D9)+((D$2/D$18)*D10)+((D$2/D$18)*D11)+((D$2/D$18)*D12)+((D$2/D$18)*D13)-D3),0)),-1))=0),10,(ROUNDUP((IF((((D$2/D$18)*D7)+((D$2/D$18)*D8)+((D$2/D$18)*D9)+((D$2/D$18)*D10)+((D$2/D$18)*D11)+((D$2/D$18)*D12)+((D$2/D$18)*D13)-D3)>0,(((D$2/D$18)*D7)+((D$2/D$18)*D8)+((D$2/D$18)*D9)+((D$2/D$18)*D10)+((D$2/D$18)*D11)+((D$2/D$18)*D12)+((D$2/D$18)*D13)-D3),0)),-1))) -> 0 | E27: =IF(AND(E2<5,E3<5,(E2*7)>E3,(ROUND((IF((((E$2/E$18)*E7)+((E$2/E$18)*E8)+((E$2/E$18)*E9)+((E$2/E$18)*E10)+((E$2/E$18)*E11)+((E$2/E$18)*E12)+((E$2/E$18)*E13)-E3)>0,(((E$2/E$18)*E7)+((E$2/E$18)*E8)+((E$2/E$18)*E9)+((E$2/E$18)*E10)+((E$2/E$18)*E11)+((E$2/E$18)*E12)+((E$2/E$18)*E13)-E3),0)),-1))=0),10,(ROUNDUP((IF((((E$2/E$18)*E7)+((E$2/E$18)*E8)+((E$2/E$18)*E9)+((E$2/E$18)*E10)+((E$2/E$18)*E11)+((E$2/E$18)*E12)+((E$2/E$18)*E13)-E3)>0,(((E$2/E$18)*E7)+((E$2/E$18)*E8)+((E$2/E$18)*E9)+((E$2/E$18)*E10)+((E$2/E$18)*E11)+((E$2/E$18)*E12)+((E$2/E$18)*E13)-E3),0)),-1))) -> 0 | F27: =IF(AND(F2<5,F3<5,(F2*7)>F3,(MROUND((IF((((F$2/F$18)*F7)+((F$2/F$18)*F8)+((F$2/F$18)*F9)+((F$2/F$18)*F10)+((F$2/F$18)*F11)+((F$2/F$18)*F12)+((F$2/F$18)*F13)-F3)>0,(((F$2/F$18)*F7)+((F$2/F$18)*F8)+((F$2/F$18)*F9)+((F$2/F$18)*F10)+((F$2/F$18)*F11)+((F$2/F$18)*F12)+((F$2/F$18)*F13)-F3),0)),5))=0),5,(MROUND((IF((((F$2/F$18)*F7)+((F$2/F$18)*F8)+((F$2/F$18)*F9)+((F$2/F$18)*F10)+((F$2/F$18)*F11)+((F$2/F$18)*F12)+((F$2/F$18)*F13)-F3)>0,((((F$2/F$18)*F7)+((F$2/F$18)*F8)+((F$2/F$18)*F9)+((F$2/F$18)*F10)+((F$2/F$18)*F11)+((F$2/F$18)*F12)+((F$2/F$18)*F13)-F3)+2.25),0)),5))) -> 0 | G27: =IF(AND(G2<5,G3<5,(G2*7)>G3,(ROUND((IF((((G$2/G$18)*G7)+((G$2/G$18)*G8)+((G$2/G$18)*G9)+((G$2/G$18)*G10)+((G$2/G$18)*G11)+((G$2/G$18)*G12)+((G$2/G$18)*G13)-G3)>0,(((G$2/G$18)*G7)+((G$2/G$18)*G8)+((G$2/G$18)*G9)+((G$2/G$18)*G10)+((G$2/G$18)*G11)+((G$2/G$18)*G12)+((G$2/G$18)*G13)-G3),0)),-1))=0),10,(ROUNDUP((IF((((G$2/G$18)*G7)+((G$2/G$18)*G8)+((G$2/G$18)*G9)+((G$2/G$18)*G10)+((G$2/G$18)*G11)+((G$2/G$18)*G12)+((G$2/G$18)*G13)-G3)>0,(((G$2/G$18)*G7)+((G$2/G$18)*G8)+((G$2/G$18)*G9)+((G$2/G$18)*G10)+((G$2/G$18)*G11)+((G$2/G$18)*G12)+((G$2/G$18)*G13)-G3),0)),-1))) -> 0 | H27: =IF(AND(H2<5,H3<5,(H2*7)>H3,(ROUND((IF((((H$2/H$18)*H7)+((H$2/H$18)*H8)+((H$2/H$18)*H9)+((H$2/H$18)*H10)+((H$2/H$18)*H11)+((H$2/H$18)*H12)+((H$2/H$18)*H13)-H3)>0,(((H$2/H$18)*H7)+((H$2/H$18)*H8)+((H$2/H$18)*H9)+((H$2/H$18)*H10)+((H$2/H$18)*H11)+((H$2/H$18)*H12)+((H$2/H$18)*H13)-H3),0)),-1))=0),10,(ROUNDUP((IF((((H$2/H$18)*H7)+((H$2/H$18)*H8)+((H$2/H$18)*H9)+((H$2/H$18)*H10)+((H$2/H$18)*H11)+((H$2/H$18)*H12)+((H$2/H$18)*H13)-H3)>0,(((H$2/H$18)*H7)+((H$2/H$18)*H8)+((H$2/H$18)*H9)+((H$2/H$18)*H10)+((H$2/H$18)*H11)+((H$2/H$18)*H12)+((H$2/H$18)*H13)-H3),0)),-1))) -> 0 | I27: =IF(AND(I2<5,I3<5,(I2*7)>I3,(ROUND((IF((((I$2/I$18)*I7)+((I$2/I$18)*I8)+((I$2/I$18)*I9)+((I$2/I$18)*I10)+((I$2/I$18)*I11)+((I$2/I$18)*I12)+((I$2/I$18)*I13)-I3)>0,(((I$2/I$18)*I7)+((I$2/I$18)*I8)+((I$2/I$18)*I9)+((I$2/I$18)*I10)+((I$2/I$18)*I11)+((I$2/I$18)*I12)+((I$2/I$18)*I13)-I3),0)),-1))=0),10,(ROUNDUP((IF((((I$2/I$18)*I7)+((I$2/I$18)*I8)+((I$2/I$18)*I9)+((I$2/I$18)*I10)+((I$2/I$18)*I11)+((I$2/I$18)*I12)+((I$2/I$18)*I13)-I3)>0,(((I$2/I$18)*I7)+((I$2/I$18)*I8)+((I$2/I$18)*I9)+((I$2/I$18)*I10)+((I$2/I$18)*I11)+((I$2/I$18)*I12)+((I$2/I$18)*I13)-I3),0)),-1))) -> 0 | J27: =IF(AND(J2<5,J3<5,(J2*7)>J3,(ROUND((IF((((J$2/J$18)*J7)+((J$2/J$18)*J8)+((J$2/J$18)*J9)+((J$2/J$18)*J10)+((J$2/J$18)*J11)+((J$2/J$18)*J12)+((J$2/J$18)*J13)-J3)>0,(((J$2/J$18)*J7)+((J$2/J$18)*J8)+((J$2/J$18)*J9)+((J$2/J$18)*J10)+((J$2/J$18)*J11)+((J$2/J$18)*J12)+((J$2/J$18)*J13)-J3),0)),-1))=0),10,(ROUNDUP((IF((((J$2/J$18)*J7)+((J$2/J$18)*J8)+((J$2/J$18)*J9)+((J$2/J$18)*J10)+((J$2/J$18)*J11)+((J$2/J$18)*J12)+((J$2/J$18)*J13)-J3)>0,(((J$2/J$18)*J7)+((J$2/J$18)*J8)+((J$2/J$18)*J9)+((J$2/J$18)*J10)+((J$2/J$18)*J11)+((J$2/J$18)*J12)+((J$2/J$18)*J13)-J3),0)),-1))) -> 0 | K27: =IF(AND(K2<5,K3<5,(K2*7)>K3,(ROUND((IF((((K$2/K$18)*K7)+((K$2/K$18)*K8)+((K$2/K$18)*K9)+((K$2/K$18)*K10)+((K$2/K$18)*K11)+((K$2/K$18)*K12)+((K$2/K$18)*K13)-K3)>0,(((K$2/K$18)*K7)+((K$2/K$18)*K8)+((K$2/K$18)*K9)+((K$2/K$18)*K10)+((K$2/K$18)*K11)+((K$2/K$18)*K12)+((K$2/K$18)*K13)-K3),0)),-1))=0),10,(ROUNDUP((IF((((K$2/K$18)*K7)+((K$2/K$18)*K8)+((K$2/K$18)*K9)+((K$2/K$18)*K10)+((K$2/K$18)*K11)+((K$2/K$18)*K12)+((K$2/K$18)*K13)-K3)>0,(((K$2/K$18)*K7)+((K$2/K$18)*K8)+((K$2/K$18)*K9)+((K$2/K$18)*K10)+((K$2/K$18)*K11)+((K$2/K$18)*K12)+((K$2/K$18)*K13)-K3),0)),-1))) -> 0 | L27: =IF(AND(L2<5,L3<5,(L2*7)>L3,(MROUND((IF((((L$2/L$18)*L7)+((L$2/L$18)*L8)+((L$2/L$18)*L9)+((L$2/L$18)*L10)+((L$2/L$18)*L11)+((L$2/L$18)*L12)+((L$2/L$18)*L13)-L3)>0,(((L$2/L$18)*L7)+((L$2/L$18)*L8)+((L$2/L$18)*L9)+((L$2/L$18)*L10)+((L$2/L$18)*L11)+((L$2/L$18)*L12)+((L$2/L$18)*L13)-L3),0)),5))=0),5,(MROUND((IF((((L$2/L$18)*L7)+((L$2/L$18)*L8)+((L$2/L$18)*L9)+((L$2/L$18)*L10)+((L$2/L$18)*L11)+((L$2/L$18)*L12)+((L$2/L$18)*L13)-L3)>0,((((L$2/L$18)*L7)+((L$2/L$18)*L8)+((L$2/L$18)*L9)+((L$2/L$18)*L10)+((L$2/L$18)*L11)+((L$2/L$18)*L12)+((L$2/L$18)*L13)-L3)+2.25),0)),5))) -> 0 | M27: =IF(AND(M2<5,M3<5,(M2*7)>M3,(ROUND((IF((((M$2/M$18)*M7)+((M$2/M$18)*M8)+((M$2/M$18)*M9)+((M$2/M$18)*M10)+((M$2/M$18)*M11)+((M$2/M$18)*M12)+((M$2/M$18)*M13)-M3)>0,(((M$2/M$18)*M7)+((M$2/M$18)*M8)+((M$2/M$18)*M9)+((M$2/M$18)*M10)+((M$2/M$18)*M11)+((M$2/M$18)*M12)+((M$2/M$18)*M13)-M3),0)),-1))=0),10,(ROUNDUP((IF((((M$2/M$18)*M7)+((M$2/M$18)*M8)+((M$2/M$18)*M9)+((M$2/M$18)*M10)+((M$2/M$18)*M11)+((M$2/M$18)*M12)+((M$2/M$18)*M13)-M3)>0,(((M$2/M$18)*M7)+((M$2/M$18)*M8)+((M$2/M$18)*M9)+((M$2/M$18)*M10)+((M$2/M$18)*M11)+((M$2/M$18)*M12)+((M$2/M$18)*M13)-M3),0)),-1))) -> 0 | N27: =IF(AND(N2<5,N3<5,(N2*7)>N3,(ROUND((IF((((N$2/N$18)*N7)+((N$2/N$18)*N8)+((N$2/N$18)*N9)+((N$2/N$18)*N10)+((N$2/N$18)*N11)+((N$2/N$18)*N12)+((N$2/N$18)*N13)-N3)>0,(((N$2/N$18)*N7)+((N$2/N$18)*N8)+((N$2/N$18)*N9)+((N$2/N$18)*N10)+((N$2/N$18)*N11)+((N$2/N$18)*N12)+((N$2/N$18)*N13)-N3),0)),-1))=0),10,(ROUNDUP((IF((((N$2/N$18)*N7)+((N$2/N$18)*N8)+((N$2/N$18)*N9)+((N$2/N$18)*N10)+((N$2/N$18)*N11)+((N$2/N$18)*N12)+((N$2/N$18)*N13)-N3)>0,(((N$2/N$18)*N7)+((N$2/N$18)*N8)+((N$2/N$18)*N9)+((N$2/N$18)*N10)+((N$2/N$18)*N11)+((N$2/N$18)*N12)+((N$2/N$18)*N13)-N3),0)),-1))) -> 0 | O27: =IF(AND(O2<5,O3<5,(O2*7)>O3,(ROUND((IF((((O$2/O$18)*O7)+((O$2/O$18)*O8)+((O$2/O$18)*O9)+((O$2/O$18)*O10)+((O$2/O$18)*O11)+((O$2/O$18)*O12)+((O$2/O$18)*O13)-O3)>0,(((O$2/O$18)*O7)+((O$2/O$18)*O8)+((O$2/O$18)*O9)+((O$2/O$18)*O10)+((O$2/O$18)*O11)+((O$2/O$18)*O12)+((O$2/O$18)*O13)-O3),0)),-1))=0),10,(ROUNDUP((IF((((O$2/O$18)*O7)+((O$2/O$18)*O8)+((O$2/O$18)*O9)+((O$2/O$18)*O10)+((O$2/O$18)*O11)+((O$2/O$18)*O12)+((O$2/O$18)*O13)-O3)>0,(((O$2/O$18)*O7)+((O$2/O$18)*O8)+((O$2/O$18)*O9)+((O$2/O$18)*O10)+((O$2/O$18)*O11)+((O$2/O$18)*O12)+((O$2/O$18)*O13)-O3),0)),-1))) -> 0 | P27: =IF(AND(P2<5,P3<5,(P2*7)>P3,(ROUND((IF((((P$2/P$18)*P7)+((P$2/P$18)*P8)+((P$2/P$18)*P9)+((P$2/P$18)*P10)+((P$2/P$18)*P11)+((P$2/P$18)*P12)+((P$2/P$18)*P13)-P3)>0,(((P$2/P$18)*P7)+((P$2/P$18)*P8)+((P$2/P$18)*P9)+((P$2/P$18)*P10)+((P$2/P$18)*P11)+((P$2/P$18)*P12)+((P$2/P$18)*P13)-P3),0)),-1))=0),10,(ROUNDUP((IF((((P$2/P$18)*P7)+((P$2/P$18)*P8)+((P$2/P$18)*P9)+((P$2/P$18)*P10)+((P$2/P$18)*P11)+((P$2/P$18)*P12)+((P$2/P$18)*P13)-P3)>0,(((P$2/P$18)*P7)+((P$2/P$18)*P8)+((P$2/P$18)*P9)+((P$2/P$18)*P10)+((P$2/P$18)*P11)+((P$2/P$18)*P12)+((P$2/P$18)*P13)-P3),0)),-1))) -> 0 | Q27: =IF(AND(Q2<5,Q3<5,(Q2*7)>Q3,(ROUND((IF((((Q$2/Q$18)*Q7)+((Q$2/Q$18)*Q8)+((Q$2/Q$18)*Q9)+((Q$2/Q$18)*Q10)+((Q$2/Q$18)*Q11)+((Q$2/Q$18)*Q12)+((Q$2/Q$18)*Q13)-Q3)>0,(((Q$2/Q$18)*Q7)+((Q$2/Q$18)*Q8)+((Q$2/Q$18)*Q9)+((Q$2/Q$18)*Q10)+((Q$2/Q$18)*Q11)+((Q$2/Q$18)*Q12)+((Q$2/Q$18)*Q13)-Q3),0)),-1))=0),10,(ROUNDUP((IF((((Q$2/Q$18)*Q7)+((Q$2/Q$18)*Q8)+((Q$2/Q$18)*Q9)+((Q$2/Q$18)*Q10)+((Q$2/Q$18)*Q11)+((Q$2/Q$18)*Q12)+((Q$2/Q$18)*Q13)-Q3)>0,(((Q$2/Q$18)*Q7)+((Q$2/Q$18)*Q8)+((Q$2/Q$18)*Q9)+((Q$2/Q$18)*Q10)+((Q$2/Q$18)*Q11)+((Q$2/Q$18)*Q12)+((Q$2/Q$18)*Q13)-Q3),0)),-1))) -> 0 | R27: =IF(AND(R2<5,R3<5,(R2*7)>R3,(ROUND((IF((((R$2/R$18)*R7)+((R$2/R$18)*R8)+((R$2/R$18)*R9)+((R$2/R$18)*R10)+((R$2/R$18)*R11)+((R$2/R$18)*R12)+((R$2/R$18)*R13)-R3)>0,(((R$2/R$18)*R7)+((R$2/R$18)*R8)+((R$2/R$18)*R9)+((R$2/R$18)*R10)+((R$2/R$18)*R11)+((R$2/R$18)*R12)+((R$2/R$18)*R13)-R3),0)),-1))=0),10,(ROUNDUP((IF((((R$2/R$18)*R7)+((R$2/R$18)*R8)+((R$2/R$18)*R9)+((R$2/R$18)*R10)+((R$2/R$18)*R11)+((R$2/R$18)*R12)+((R$2/R$18)*R13)-R3)>0,(((R$2/R$18)*R7)+((R$2/R$18)*R8)+((R$2/R$18)*R9)+((R$2/R$18)*R10)+((R$2/R$18)*R11)+((R$2/R$18)*R12)+((R$2/R$18)*R13)-R3),0)),-1))) -> 0 | S27: =IF(AND(S2<5,S3<5,(S2*7)>S3,(ROUND((IF((((S$2/S$18)*S7)+((S$2/S$18)*S8)+((S$2/S$18)*S9)+((S$2/S$18)*S10)+((S$2/S$18)*S11)+((S$2/S$18)*S12)+((S$2/S$18)*S13)-S3)>0,(((S$2/S$18)*S7)+((S$2/S$18)*S8)+((S$2/S$18)*S9)+((S$2/S$18)*S10)+((S$2/S$18)*S11)+((S$2/S$18)*S12)+((S$2/S$18)*S13)-S3),0)),-1))=0),10,(ROUNDUP((IF((((S$2/S$18)*S7)+((S$2/S$18)*S8)+((S$2/S$18)*S9)+((S$2/S$18)*S10)+((S$2/S$18)*S11)+((S$2/S$18)*S12)+((S$2/S$18)*S13)-S3)>0,(((S$2/S$18)*S7)+((S$2/S$18)*S8)+((S$2/S$18)*S9)+((S$2/S$18)*S10)+((S$2/S$18)*S11)+((S$2/S$18)*S12)+((S$2/S$18)*S13)-S3),0)),-1))) -> 0 | T27: =IF(AND(T2<5,T3<5,(T2*7)>T3,(ROUND((IF((((T$2/T$18)*T7)+((T$2/T$18)*T8)+((T$2/T$18)*T9)+((T$2/T$18)*T10)+((T$2/T$18)*T11)+((T$2/T$18)*T12)+((T$2/T$18)*T13)-T3)>0,(((T$2/T$18)*T7)+((T$2/T$18)*T8)+((T$2/T$18)*T9)+((T$2/T$18)*T10)+((T$2/T$18)*T11)+((T$2/T$18)*T12)+((T$2/T$18)*T13)-T3),0)),-1))=0),10,(ROUNDUP((IF((((T$2/T$18)*T7)+((T$2/T$18)*T8)+((T$2/T$18)*T9)+((T$2/T$18)*T10)+((T$2/T$18)*T11)+((T$2/T$18)*T12)+((T$2/T$18)*T13)-T3)>0,(((T$2/T$18)*T7)+((T$2/T$18)*T8)+((T$2/T$18)*T9)+((T$2/T$18)*T10)+((T$2/T$18)*T11)+((T$2/T$18)*T12)+((T$2/T$18)*T13)-T3),0)),-1))) -> 0 | ... V27: =IF(AND(V2<5,V3<5,(V2*7)>V3,(ROUND((IF((((V$2/V$18)*V7)+((V$2/V$18)*V8)+((V$2/V$18)*V9)+((V$2/V$18)*V10)+((V$2/V$18)*V11)+((V$2/V$18)*V12)+((V$2/V$18)*V13)-V3)>0,(((V$2/V$18)*V7)+((V$2/V$18)*V8)+((V$2/V$18)*V9)+((V$2/V$18)*V10)+((V$2/V$18)*V11)+((V$2/V$18)*V12)+((V$2/V$18)*V13)-V3),0)),-1))=0),10,(ROUNDUP((IF((((V$2/V$18)*V7)+((V$2/V$18)*V8)+((V$2/V$18)*V9)+((V$2/V$18)*V10)+((V$2/V$18)*V11)+((V$2/V$18)*V12)+((V$2/V$18)*V13)-V3)>0,(((V$2/V$18)*V7)+((V$2/V$18)*V8)+((V$2/V$18)*V9)+((V$2/V$18)*V10)+((V$2/V$18)*V11)+((V$2/V$18)*V12)+((V$2/V$18)*V13)-V3),0)),-1))) -> 0
C29: DT | D29: DTaP | E29: DTaP-Hep B-IPV | F29: DTaP-IPV-Hib | G29: e-IPV | H29: Hep A | I29: Hep B | J29: Hib | K29: HPV | L29: MCV | M29: MMR | N29: PPSV | O29: PCV | P29: Rotavirus | Q29: Td | R29: Tdap | S29: Varicella | T29: DTaP-IPV | U29: Hep B-Hib | V29: Varicella
A30: Twice a Month | B30: =List!J2 -> January | C30: =ROUNDUP((C4/2),-1) -> 0 | D30: =ROUNDUP((D4/2),-1) -> 0 | E30: =MROUND(((E4/2)+2.25),5) -> 0 | F30: =MROUND(((F4/2)+2.25),5) -> 0 | G30: =ROUNDUP((G4/2),-1) -> 0 | H30: =ROUNDUP((H4/2),-1) -> 0 | I30: =ROUNDUP((I4/2),-1) -> 0 | J30: =ROUNDUP((J4/2),-1) -> 0 | K30: =ROUNDUP((K4/2),-1) -> 0 | L30: =MROUND(((L4/2)+2.25),5) -> 0 | M30: =ROUNDUP((M4/2),-1) -> 0 | N30: =ROUNDUP((N4/2),-1) -> 0 | O30: =ROUNDUP((O4/2),-1) -> 0 | P30: =ROUNDUP((P4/2),-1) -> 0 | Q30: =ROUNDUP((Q4/2),-1) -> 0 | R30: =ROUNDUP((R4/2),-1) -> 0 | S30: =ROUNDUP((S4/2),-1) -> 0 | T30: =ROUNDUP((T4/2),-1) -> 0 | ... V30: =ROUNDUP((V4/2),-1) -> 0
A31: Twice a Month | B31: =List!J3 -> January | C31: =C4-C30 -> 0 | D31: =D4-D30 -> 0 | E31: =E4-E30 -> 0 | F31: =F4-F30 -> 0 | G31: =G4-G30 -> 0 | H31: =H4-H30 -> 0 | I31: =I4-I30 -> 0 | J31: =J4-J30 -> 0 | ... V31: =V4-V30 -> 0
C33: DT | D33: DTaP | E33: DTaP-Hep B-IPV | F33: DTaP-IPV-Hib | G33: e-IPV | H33: Hep A | I33: Hep B | J33: Hib | K33: HPV | L33: MCV | M33: MMR | N33: PPSV | O33: PCV | P33: Rotavirus | Q33: Td | R33: Tdap | S33: Varicella | T33: DTaP-IPV | U33: Hep B-Hib | V33: Varicella
B34: =List!F2 -> January | C34: 0.083333333 | D34: 0.083333333 | E34: 0.083333333 | F34: 0.083333333 | G34: 0.083333333 | H34: 0.083333333 | I34: 0.083333333 | J34: 0.083333333 | K34: 0.083333333 | L34: 0.083333333 | M34: 0.083333333 | N34: 0.083333333 | O34: 0.083333333 | P34: 0.083333333 | Q34: 0.083333333 | R34: 0.083333333 | S34: 0.083333333 | T34: 0.083333333 | U34: 0.083333333 | V34: 0.083333333
B35: =List!F3 -> February | C35: 0.083333333 | D35: 0.083333333 | E35: 0.083333333 | F35: 0.083333333 | G35: 0.083333333 | H35: 0.083333333 | I35: 0.083333333 | J35: 0.083333333 | K35: 0.083333333 | L35: 0.083333333 | M35: 0.083333333 | N35: 0.083333333 | O35: 0.083333333 | P35: 0.083333333 | Q35: 0.083333333 | R35: 0.083333333 | S35: 0.083333333 | T35: 0.083333333 | U35: 0.083333333 | V35: 0.083333333
B36: =List!F4 -> March | C36: 0.083333333 | D36: 0.083333333 | E36: 0.083333333 | F36: 0.083333333 | G36: 0.083333333 | H36: 0.083333333 | I36: 0.083333333 | J36: 0.083333333 | K36: 0.083333333 | L36: 0.083333333 | M36: 0.083333333 | N36: 0.083333333 | O36: 0.083333333 | P36: 0.083333333 | Q36: 0.083333333 | R36: 0.083333333 | S36: 0.083333333 | T36: 0.083333333 | U36: 0.083333333 | V36: 0.083333333
B37: =List!F5 -> April | C37: 0.083333333 | D37: 0.083333333 | E37: 0.083333333 | F37: 0.083333333 | G37: 0.083333333 | H37: 0.083333333 | I37: 0.083333333 | J37: 0.083333333 | K37: 0.083333333 | L37: 0.083333333 | M37: 0.083333333 | N37: 0.083333333 | O37: 0.083333333 | P37: 0.083333333 | Q37: 0.083333333 | R37: 0.083333333 | S37: 0.083333333 | T37: 0.083333333 | U37: 0.083333333 | V37: 0.083333333
B38: =List!F6 -> May | C38: 0.083333333 | D38: 0.083333333 | E38: 0.083333333 | F38: 0.083333333 | G38: 0.083333333 | H38: 0.083333333 | I38: 0.083333333 | J38: 0.083333333 | K38: 0.083333333 | L38: 0.083333333 | M38: 0.083333333 | N38: 0.083333333 | O38: 0.083333333 | P38: 0.083333333 | Q38: 0.083333333 | R38: 0.083333333 | S38: 0.083333333 | T38: 0.083333333 | U38: 0.083333333 | V38: 0.083333333
B39: =List!F7 -> June | C39: 0.083333333 | D39: 0.083333333 | E39: 0.083333333 | F39: 0.083333333 | G39: 0.083333333 | H39: 0.083333333 | I39: 0.083333333 | J39: 0.083333333 | K39: 0.083333333 | L39: 0.083333333 | M39: 0.083333333 | N39: 0.083333333 | O39: 0.083333333 | P39: 0.083333333 | Q39: 0.083333333 | R39: 0.083333333 | S39: 0.083333333 | T39: 0.083333333 | U39: 0.083333333 | V39: 0.083333333
B40: =List!F8 -> July | C40: 0.083333333 | D40: 0.083333333 | E40: 0.083333333 | F40: 0.083333333 | G40: 0.083333333 | H40: 0.083333333 | I40: 0.083333333 | J40: 0.083333333 | K40: 0.083333333 | L40: 0.083333333 | M40: 0.083333333 | N40: 0.083333333 | O40: 0.083333333 | P40: 0.083333333 | Q40: 0.083333333 | R40: 0.083333333 | S40: 0.083333333 | T40: 0.083333333 | U40: 0.083333333 | V40: 0.083333333
B41: =List!F9 -> August | C41: 0.083333333 | D41: 0.083333333 | E41: 0.083333333 | F41: 0.083333333 | G41: 0.083333333 | H41: 0.083333333 | I41: 0.083333333 | J41: 0.083333333 | K41: 0.083333333 | L41: 0.083333333 | M41: 0.083333333 | N41: 0.083333333 | O41: 0.083333333 | P41: 0.083333333 | Q41: 0.083333333 | R41: 0.083333333 | S41: 0.083333333 | T41: 0.083333333 | U41: 0.083333333 | V41: 0.083333333
B42: =List!F10 -> September | C42: 0.083333333 | D42: 0.083333333 | E42: 0.083333333 | F42: 0.083333333 | G42: 0.083333333 | H42: 0.083333333 | I42: 0.083333333 | J42: 0.083333333 | K42: 0.083333333 | L42: 0.083333333 | M42: 0.083333333 | N42: 0.083333333 | O42: 0.083333333 | P42: 0.083333333 | Q42: 0.083333333 | R42: 0.083333333 | S42: 0.083333333 | T42: 0.083333333 | U42: 0.083333333 | V42: 0.083333333
B43: =List!F11 -> October | C43: 0.083333333 | D43: 0.083333333 | E43: 0.083333333 | F43: 0.083333333 | G43: 0.083333333 | H43: 0.083333333 | I43: 0.083333333 | J43: 0.083333333 | K43: 0.083333333 | L43: 0.083333333 | M43: 0.083333333 | N43: 0.083333333 | O43: 0.083333333 | P43: 0.083333333 | Q43: 0.083333333 | R43: 0.083333333 | S43: 0.083333333 | T43: 0.083333333 | U43: 0.083333333 | V43: 0.083333333
B44: =List!F12 -> November | C44: 0.083333333 | D44: 0.083333333 | E44: 0.083333333 | F44: 0.083333333 | G44: 0.083333333 | H44: 0.083333333 | I44: 0.083333333 | J44: 0.083333333 | K44: 0.083333333 | L44: 0.083333333 | M44: 0.083333333 | N44: 0.083333333 | O44: 0.083333333 | P44: 0.083333333 | Q44: 0.083333333 | R44: 0.083333333 | S44: 0.083333333 | T44: 0.083333333 | U44: 0.083333333 | V44: 0.083333333
B45: =List!F13 -> December | C45: 0.083333333 | D45: 0.083333333 | E45: 0.083333333 | F45: 0.083333333 | G45: 0.083333333 | H45: 0.083333333 | I45: 0.083333333 | J45: 0.083333333 | K45: 0.083333333 | L45: 0.083333333 | M45: 0.083333333 | N45: 0.083333333 | O45: 0.083333333 | P45: 0.083333333 | Q45: 0.083333333 | R45: 0.083333333 | S45: 0.083333333 | T45: 0.083333333 | U45: 0.083333333 | V45: 0.083333333
C48: =IF(AND(C2<5,C3<5,(C2*4)>C3,(ROUND((IF((((C$2/C45)*C34)+((C2/C45)*C35)+((C2/C45)*C36)+((C2/C45)*C37)-C3)>0,(((C$2/C45)*C34)+((C2/C45)*C35)+((C2/C45)*C36)+((C2/C45)*C37)-C3),0)),-1))=0),10,(ROUNDUP((IF((((C$2/C45)*C34)+((C2/C45)*C35)+((C2/C45)*C36)+((C2/C45)*C37)-C3)>0,(((C$2/C45)*C34)+((C2/C45)*C35)+((C2/C45)*C36)+((C2/C45)*C37)-C3),0)),-1))) -> 0 | D48: =IF(AND(D2<5,D3<5,(D2*4)>D3,(ROUND((IF((((D$2/D45)*D34)+((D2/D45)*D35)+((D2/D45)*D36)+((D2/D45)*D37)-D3)>0,(((D$2/D45)*D34)+((D2/D45)*D35)+((D2/D45)*D36)+((D2/D45)*D37)-D3),0)),-1))=0),10,(ROUNDUP((IF((((D$2/D45)*D34)+((D2/D45)*D35)+((D2/D45)*D36)+((D2/D45)*D37)-D3)>0,(((D$2/D45)*D34)+((D2/D45)*D35)+((D2/D45)*D36)+((D2/D45)*D37)-D3),0)),-1))) -> 0 | E48: =IF(AND(E2<5,E3<5,(E2*4)>E3,(ROUND((IF((((E$2/E45)*E34)+((E2/E45)*E35)+((E2/E45)*E36)+((E2/E45)*E37)-E3)>0,(((E$2/E45)*E34)+((E2/E45)*E35)+((E2/E45)*E36)+((E2/E45)*E37)-E3),0)),-1))=0),10,(ROUNDUP((IF((((E$2/E45)*E34)+((E2/E45)*E35)+((E2/E45)*E36)+((E2/E45)*E37)-E3)>0,(((E$2/E45)*E34)+((E2/E45)*E35)+((E2/E45)*E36)+((E2/E45)*E37)-E3),0)),-1))) -> 0 | F48: =IF(AND(F2<5,F3<5,(F2*4)>F3,(MROUND((IF((((F$2/F45)*F34)+((F2/F45)*F35)+((F2/F45)*F36)+((F2/F45)*F37)-F3)>0,(((F$2/F45)*F34)+((F2/F45)*F35)+((F2/F45)*F36)+((F2/F45)*F37)-F3),0)),5))=0),5,(MROUND((IF((((F$2/F45)*F34)+((F2/F45)*F35)+((F2/F45)*F36)+((F2/F45)*F37)-F3)>0,((((F$2/F45)*F34)+((F2/F45)*F35)+((F2/F45)*F36)+((F2/F45)*F37)-F3)+2.25),0)),5))) -> 0 | G48: =IF(AND(G2<5,G3<5,(G2*4)>G3,(ROUND((IF((((G$2/G45)*G34)+((G2/G45)*G35)+((G2/G45)*G36)+((G2/G45)*G37)-G3)>0,(((G$2/G45)*G34)+((G2/G45)*G35)+((G2/G45)*G36)+((G2/G45)*G37)-G3),0)),-1))=0),10,(ROUNDUP((IF((((G$2/G45)*G34)+((G2/G45)*G35)+((G2/G45)*G36)+((G2/G45)*G37)-G3)>0,(((G$2/G45)*G34)+((G2/G45)*G35)+((G2/G45)*G36)+((G2/G45)*G37)-G3),0)),-1))) -> 0 | H48: =IF(AND(H2<5,H3<5,(H2*4)>H3,(ROUND((IF((((H$2/H45)*H34)+((H2/H45)*H35)+((H2/H45)*H36)+((H2/H45)*H37)-H3)>0,(((H$2/H45)*H34)+((H2/H45)*H35)+((H2/H45)*H36)+((H2/H45)*H37)-H3),0)),-1))=0),10,(ROUNDUP((IF((((H$2/H45)*H34)+((H2/H45)*H35)+((H2/H45)*H36)+((H2/H45)*H37)-H3)>0,(((H$2/H45)*H34)+((H2/H45)*H35)+((H2/H45)*H36)+((H2/H45)*H37)-H3),0)),-1))) -> 0 | I48: =IF(AND(I2<5,I3<5,(I2*4)>I3,(ROUND((IF((((I$2/I45)*I34)+((I2/I45)*I35)+((I2/I45)*I36)+((I2/I45)*I37)-I3)>0,(((I$2/I45)*I34)+((I2/I45)*I35)+((I2/I45)*I36)+((I2/I45)*I37)-I3),0)),-1))=0),10,(ROUNDUP((IF((((I$2/I45)*I34)+((I2/I45)*I35)+((I2/I45)*I36)+((I2/I45)*I37)-I3)>0,(((I$2/I45)*I34)+((I2/I45)*I35)+((I2/I45)*I36)+((I2/I45)*I37)-I3),0)),-1))) -> 0 | J48: =IF(AND(J2<5,J3<5,(J2*4)>J3,(MROUND((IF((((J$2/J45)*J34)+((J2/J45)*J35)+((J2/J45)*J36)+((J2/J45)*J37)-J3)>0,(((J$2/J45)*J34)+((J2/J45)*J35)+((J2/J45)*J36)+((J2/J45)*J37)-J3),0)),5))=0),5,(MROUND((IF((((J$2/J45)*J34)+((J2/J45)*J35)+((J2/J45)*J36)+((J2/J45)*J37)-J3)>0,((((J$2/J45)*J34)+((J2/J45)*J35)+((J2/J45)*J36)+((J2/J45)*J37)-J3)+2.25),0)),5))) -> 0 | K48: =IF(AND(K2<5,K3<5,(K2*4)>K3,(ROUND((IF((((K$2/K45)*K34)+((K2/K45)*K35)+((K2/K45)*K36)+((K2/K45)*K37)-K3)>0,(((K$2/K45)*K34)+((K2/K45)*K35)+((K2/K45)*K36)+((K2/K45)*K37)-K3),0)),-1))=0),10,(ROUNDUP((IF((((K$2/K45)*K34)+((K2/K45)*K35)+((K2/K45)*K36)+((K2/K45)*K37)-K3)>0,(((K$2/K45)*K34)+((K2/K45)*K35)+((K2/K45)*K36)+((K2/K45)*K37)-K3),0)),-1))) -> 0 | L48: =IF(AND(L2<5,L3<5,(L2*4)>L3,(MROUND((IF((((L$2/L45)*L34)+((L2/L45)*L35)+((L2/L45)*L36)+((L2/L45)*L37)-L3)>0,(((L$2/L45)*L34)+((L2/L45)*L35)+((L2/L45)*L36)+((L2/L45)*L37)-L3),0)),5))=0),5,(MROUND((IF((((L$2/L45)*L34)+((L2/L45)*L35)+((L2/L45)*L36)+((L2/L45)*L37)-L3)>0,((((L$2/L45)*L34)+((L2/L45)*L35)+((L2/L45)*L36)+((L2/L45)*L37)-L3)+2.25),0)),5))) -> 0 | M48: =IF(AND(M2<5,M3<5,(M2*4)>M3,(ROUND((IF((((M$2/M45)*M34)+((M2/M45)*M35)+((M2/M45)*M36)+((M2/M45)*M37)-M3)>0,(((M$2/M45)*M34)+((M2/M45)*M35)+((M2/M45)*M36)+((M2/M45)*M37)-M3),0)),-1))=0),10,(ROUNDUP((IF((((M$2/M45)*M34)+((M2/M45)*M35)+((M2/M45)*M36)+((M2/M45)*M37)-M3)>0,(((M$2/M45)*M34)+((M2/M45)*M35)+((M2/M45)*M36)+((M2/M45)*M37)-M3),0)),-1))) -> 0 | N48: =IF(AND(N2<5,N3<5,(N2*4)>N3,(ROUND((IF((((N$2/N45)*N34)+((N2/N45)*N35)+((N2/N45)*N36)+((N2/N45)*N37)-N3)>0,(((N$2/N45)*N34)+((N2/N45)*N35)+((N2/N45)*N36)+((N2/N45)*N37)-N3),0)),-1))=0),10,(ROUNDUP((IF((((N$2/N45)*N34)+((N2/N45)*N35)+((N2/N45)*N36)+((N2/N45)*N37)-N3)>0,(((N$2/N45)*N34)+((N2/N45)*N35)+((N2/N45)*N36)+((N2/N45)*N37)-N3),0)),-1))) -> 0 | O48: =IF(AND(O2<5,O3<5,(O2*4)>O3,(ROUND((IF((((O$2/O45)*O34)+((O2/O45)*O35)+((O2/O45)*O36)+((O2/O45)*O37)-O3)>0,(((O$2/O45)*O34)+((O2/O45)*O35)+((O2/O45)*O36)+((O2/O45)*O37)-O3),0)),-1))=0),10,(ROUNDUP((IF((((O$2/O45)*O34)+((O2/O45)*O35)+((O2/O45)*O36)+((O2/O45)*O37)-O3)>0,(((O$2/O45)*O34)+((O2/O45)*O35)+((O2/O45)*O36)+((O2/O45)*O37)-O3),0)),-1))) -> 0 | P48: =IF(AND(P2<5,P3<5,(P2*4)>P3,(ROUND((IF((((P$2/P45)*P34)+((P2/P45)*P35)+((P2/P45)*P36)+((P2/P45)*P37)-P3)>0,(((P$2/P45)*P34)+((P2/P45)*P35)+((P2/P45)*P36)+((P2/P45)*P37)-P3),0)),-1))=0),10,(ROUNDUP((IF((((P$2/P45)*P34)+((P2/P45)*P35)+((P2/P45)*P36)+((P2/P45)*P37)-P3)>0,(((P$2/P45)*P34)+((P2/P45)*P35)+((P2/P45)*P36)+((P2/P45)*P37)-P3),0)),-1))) -> 0 | Q48: =IF(AND(Q2<5,Q3<5,(Q2*4)>Q3,(ROUND((IF((((Q$2/Q45)*Q34)+((Q2/Q45)*Q35)+((Q2/Q45)*Q36)+((Q2/Q45)*Q37)-Q3)>0,(((Q$2/Q45)*Q34)+((Q2/Q45)*Q35)+((Q2/Q45)*Q36)+((Q2/Q45)*Q37)-Q3),0)),-1))=0),10,(ROUNDUP((IF((((Q$2/Q45)*Q34)+((Q2/Q45)*Q35)+((Q2/Q45)*Q36)+((Q2/Q45)*Q37)-Q3)>0,(((Q$2/Q45)*Q34)+((Q2/Q45)*Q35)+((Q2/Q45)*Q36)+((Q2/Q45)*Q37)-Q3),0)),-1))) -> 0 | R48: =IF(AND(R2<5,R3<5,(R2*4)>R3,(ROUND((IF((((R$2/R45)*R34)+((R2/R45)*R35)+((R2/R45)*R36)+((R2/R45)*R37)-R3)>0,(((R$2/R45)*R34)+((R2/R45)*R35)+((R2/R45)*R36)+((R2/R45)*R37)-R3),0)),-1))=0),10,(ROUNDUP((IF((((R$2/R45)*R34)+((R2/R45)*R35)+((R2/R45)*R36)+((R2/R45)*R37)-R3)>0,(((R$2/R45)*R34)+((R2/R45)*R35)+((R2/R45)*R36)+((R2/R45)*R37)-R3),0)),-1))) -> 0 | S48: =IF(AND(S2<5,S3<5,(S2*4)>S3,(ROUND((IF((((S$2/S45)*S34)+((S2/S45)*S35)+((S2/S45)*S36)+((S2/S45)*S37)-S3)>0,(((S$2/S45)*S34)+((S2/S45)*S35)+((S2/S45)*S36)+((S2/S45)*S37)-S3),0)),-1))=0),10,(ROUNDUP((IF((((S$2/S45)*S34)+((S2/S45)*S35)+((S2/S45)*S36)+((S2/S45)*S37)-S3)>0,(((S$2/S45)*S34)+((S2/S45)*S35)+((S2/S45)*S36)+((S2/S45)*S37)-S3),0)),-1))) -> 0 | V48: =IF(AND(V2<5,V3<5,(V2*4)>V3,(ROUND((IF((((V$2/V45)*V34)+((V2/V45)*V35)+((V2/V45)*V36)+((V2/V45)*V37)-V3)>0,(((V$2/V45)*V34)+((V2/V45)*V35)+((V2/V45)*V36)+((V2/V45)*V37)-V3),0)),-1))=0),10,(ROUNDUP((IF((((V$2/V45)*V34)+((V2/V45)*V35)+((V2/V45)*V36)+((V2/V45)*V37)-V3)>0,(((V$2/V45)*V34)+((V2/V45)*V35)+((V2/V45)*V36)+((V2/V45)*V37)-V3),0)),-1))) -> 0
...

Sheet List
F1: Yearly | G1: Quarterly | H1: Every 2 Months | I1: Twice Yearly | J1: Twice Monthly
A2: 1 | B2: January | C2: Twice a Month | D2: April | E2: 4 | F2: ='Provider Order Form'!C3 -> January | G2: ='Provider Order Form'!C3 -> January | H2: ='Provider Order Form'!C3 -> January | I2: ='Provider Order Form'!C3 -> January | J2: ='Provider Order Form'!C3 -> January | L2: 6:00 | N2: AM
