Workbook

Sheet Summary
A1: Database Statistics Summary
A2: 2006-2007
A5: Database Name | B5: Vendor | C5: Sessions | D5: Searches | E5: Turnaways | F5: Successful full-text article requests | G5: 2006/07 Price | H5: Cost per Search
A6: ABI/INFORM Global | B6: ProQuest | C6: N/A | D6: =ProQuest!N6 -> 32354 | E6: 0 | F6: Not avail. | G6: =ProQuest!O6 -> 17940 | H6: =ProQuest!P6 -> 0.55449094
A7: ABI/INFORM Trade & Industry | B7: ProQuest | C7: N/A | D7: =ProQuest!N11 -> 15174 | E7: 0 | F7: Not avail. | G7: 0 | H7: N/A
A8: ABC-CLIO databases (all) | B8: ABC-CLIO | C8: 2710 | D8: 3223 | E8: 0 | F8: N/A | G8: 13440 | H8: 4.17
A9: Abstracts in Anthropology | B9: MetaPress | C9: Not avail. | D9: Not avail. | E9: Not avail. | F9: N/A | G9: =MetaPress!O7 -> 653 | H9: N/A
A10: Academic Search Premier | B10: EBSCOhost | C10: =EBSCOhost!N7 -> 91426 | D10: =EBSCOhost!N8 -> 289711 | E10: 0 | F10: Not avail. | G10: =EBSCOhost!O8 -> 19175 | H10: =EBSCOhost!P8 -> 0.066186648
A11: Alternative Press Index | B11: FirstSearch | C11: N/A | D11: =FirstSearch!N7 -> 53 | E11: 0 | F11: N/A | G11: 53 | H11: 1
A12: Alternative Press Index Archive | B12: FirstSearch | C12: N/A | D12: =FirstSearch!N12 -> 27 | E12: 0 | F12: N/A | G12: 27 | H12: 1
A13: America History & Life | B13: ABC-CLIO | C13: 1732 | D13: 2270 | E13: 0 | F13: N/A | G13: 6720 | H13: 2.96
A14: Art Abstracts | B14: WilsonWeb | C14: =WilsonWeb!N7 -> 979 | D14: =WilsonWeb!N8 -> 3129 | E14: =WilsonWeb!N9 -> 0 | F14: N/A | G14: =WilsonWeb!O8 -> 5535 | H14: =WilsonWeb!P8 -> 1.7689358
A15: ArticleFirst* | B15: FirstSearch | C15: =FirstSearch!N17 -> 2534 | D15: =FirstSearch!N18 -> 8651 | E15: =FirstSearch!N20 -> 151 | F15: N/A | G15: 0 | H15: N/A
A16: ASFA: Aquatic Science & Fisheries Abstracts | B16: CSA | C16: N/A | D16: 16246 | E16: 0 | F16: N/A | G16: 7335 | H16: 0.45
A17: ASFA 1 | B17: CSA | C17: N/A | D17: 3274 | E17: 0 | F17: N/A | G17: 0 | H17: N/A
A18: ASFA 2 | B18: CSA | C18: N/A | D18: 603 | E18: 0 | F18: N/A | G18: 0 | H18: N/A
A19: ASFA 3 | B19: CSA | C19: N/A | D19: 1916 | E19: 0 | F19: N/A | G19: 0 | H19: N/A
A20: ASFA Aquaculture Abstracts | C20: N/A | D20: 1901 | E20: 0 | F20: N/A | G20: 0 | H20: N/A
A21: ASFA Marine Biotechnology Abstracts | B21: CSA | C21: N/A | D21: 1670 | E21: 0 | F21: N/A | G21: 0 | H21: N/A
A22: Bibliography & Index of Micropaleontology | B22: Micropress | C22: Not avail. | D22: Not avail. | E22: Not avail. | F22: Not avail. | G22: 142.26 | H22: Not avail.
A23: Biological Abstracts / BIOSIS | B23: Ovid WEBSPIRS | C23: =WebSpirs!N7 -> 1845 | D23: =WebSpirs!N8 -> 6477 | E23: =WebSpirs!N9 -> 0 | F23: N/A | G23: =WebSpirs!O8 -> 23244 | H23: =WebSpirs!P8 -> 3.5886985
A24: Biological & Agricultural Index Plus* | B24: WilsonWeb | C24: =WilsonWeb!N12 -> 536 | D24: =WilsonWeb!N13 -> 1209 | E24: =WilsonWeb!N14 -> 48 | F24: N/A | G24: =WilsonWeb!O13 -> 3213 | H24: =WilsonWeb!P13 -> 2.6575682
A25: BIOSIS Previews | B25: OVID | C25: =OVID!N7 -> 24 | D25: =OVID!N8 -> 79 | E25: 0 | F25: N/A | G25: 0 | H25: N/A
A26: Book Index with Reviews | B26: EBSCOhost | C26: =EBSCOhost!N13 -> 196 | D26: =EBSCOhost!N14 -> 672 | E26: 0 | F26: N/A | G26: 0 | H26: N/A
A27: ChoiceReviews.online | B27: Choice | C27: Not avail. | D27: Not avail. | E27: Not avail. | F27: Not avail. | G27: 632.83 | H27: Not avail.
A28: CIAO | B28: CIAO | C28: 1002 | D28: Not avail. | E28: 0 | F28: Not avail. | G28: 896 | H28: 0.89
A29: CINAHL | B29: EBSCOhost | C29: =EBSCOhost!N61 -> 10449 | D29: =EBSCOhost!N62 -> 43486 | E29: 0 | F29: Not avail. | G29: =EBSCOhost!O62 -> 5372 | H29: =EBSCOhost!P62 -> 0.12353401
A30: Clase and Periodica* | B30: FirstSearch | C30: =FirstSearch!N25 -> 141 | D30: =FirstSearch!N26 -> 117 | E30: =FirstSearch!N28 -> 2 | F30: N/A | G30: 0 | H30: N/A
A31: Classification Web* | B31: Library of Congress | C31: 87 | D31: 118342 | E31: Not avail. | F31: N/A | G31: 613 | H31: 0.01
A32: Cochrane Library | B32: Wiley InterScience | C32: =Cochrane!N7 -> 1005 | D32: =Cochrane!N8 -> 357 | E32: 0 | F32: =Cochrane!N9 -> 1138 | G32: 2633.02 | H32: =Cochrane!P8 -> 7.3754062
A33: CollegeSource | B33: CollegeSource | C33: N/A | D33: 398 | E33: 0 | F33: N/A | G33: 1334 | H33: 3.35
A34: Communication Abstracts | B34: CSA | C34: N/A | D34: 9944 | E34: 0 | F34: N/A | G34: 2685 | H34: 0.27
A35: Compendex | B35: EI | C35: 1807 | D35: 6789 | E35: 0 | F35: N/A | G35: 14510 | H35: 2.14
A36: CSA (all databases) | B36: CSA | C36: 31175 | D36: 87709 | E36: 0 | F36: N/A | G36: 27294 | H36: 0.31
A37: Doody's Core Titles in the Health Sciences | B37: Doody's | C37: Not avail. | D37: Not avail. | E37: Not avail. | F37: Not avail. | G37: 149.5 | H37: N/A
A38: EBSCO Animals | B38: EBSCOhost | C38: =EBSCOhost!N19 -> 907 | D38: =EBSCOhost!N20 -> 2666 | E38: 0 | F38: N/A | G38: 0 | H38: N/A
A39: EBSCOhost (all databases) | B39: EBSCOhost | C39: =EBSCOhost!N91 -> 112004 | D39: =EBSCOhost!N92 -> 369355 | E39: 0 | F39: =EBSCOhost!N93 -> 205851 | G39: =EBSCOhost!O93 -> 55833 | H39: =EBSCOhost!P92 -> 0.15116351
A40: EconLit | B40: CSA | C40: N/A | D40: 6989 | E40: 0 | F40: N/A | G40: 4163 | H40: 0.6
A41: Electronic Books* | B41: FirstSearch | C41: =FirstSearch!N41 -> 108 | D41: =FirstSearch!N42 -> 122 | E41: =FirstSearch!N44 -> 0 | F41: N/A | G41: 0 | H41: N/A
A42: Electronic Collections Online* | B42: FirstSearch | C42: =FirstSearch!N49 -> 467 | D42: =FirstSearch!N50 -> 753 | E42: =FirstSearch!N52 -> 1 | F42: URI does not subscribe to full text | G42: 0 | H42: N/A
...

Sheet ABC-CLIO
A1: ABC-CLIO
A2: 2006-2007
B5: 38899 | C5: 38930 | D5: 38961 | E5: 38991 | F5: 39022 | G5: 39052 | H5: 39083 | I5: 39114 | J5: 39142 | K5: 39173 | L5: 39203 | M5: 39234 | N5: Total | O5: 2006-2007 Price | P5: Price per search
A6: AHL Database
A7: Sessions | B7: 53 | C7: 18 | D7: 149 | E7: 312 | F7: 280 | G7: 105 | H7: 55 | I7: 136 | J7: 221 | K7: 316 | L7: 44 | M7: 43 | N7: =SUM(B7:M7) -> 1732
A8: Searches | B8: 61 | C8: 13 | D8: 241 | E8: 359 | F8: 318 | G8: 102 | H8: 65 | I8: 157 | J8: 343 | K8: 509 | L8: 42 | M8: 60 | N8: =SUM(B8:M8) -> 2270 | O8: 6720 | P8: =O8/N8 -> 2.9603524
B11: 38899 | C11: 38930 | D11: 38961 | E11: 38991 | F11: 39022 | G11: 39052 | H11: 39083 | I11: 39114 | J11: 39142 | K11: 39173 | L11: 39203 | M11: 39234 | N11: Total | O11: 2006-2007 Price | P11: Price per search
A12: HA Database
A13: Sessions | B13: 23 | C13: 6 | D13: 18 | E13: 65 | F13: 120 | G13: 69 | H13: 10 | I13: 71 | J13: 111 | K13: 115 | L13: 33 | M13: 20 | N13: =SUM(B13:M13) -> 661
A14: Searches | B14: 27 | C14: 2 | D14: 8 | E14: 58 | F14: 121 | G14: 87 | H14: 10 | I14: 79 | J14: 98 | K14: 126 | L14: 40 | M14: 30 | N14: =SUM(B14:M14) -> 686 | O14: 6720 | P14: =O14/N14 -> 9.7959184
B17: 38899 | C17: 38930 | D17: 38961 | E17: 38991 | F17: 39022 | G17: 39052 | H17: 39083 | I17: 39114 | J17: 39142 | K17: 39173 | L17: 39203 | M17: 39234 | N17: Total | O17: 2006-2007 Price | P17: Price per search
A18: XDB (XDB = Combined AHL and HA Database Activity)
A19: Sessions | B19: 12 | C19: 9 | D19: 7 | E19: 97 | F19: 56 | G19: 14 | H19: 7 | I19: 25 | J19: 37 | K19: 39 | L19: 3 | M19: 11 | N19: =SUM(B18:M19) -> 317
A20: Searches | B20: 16 | C20: 18 | D20: N/A | E20: 30 | F20: 42 | G20: 14 | H20: 6 | I20: 12 | J20: 47 | K20: 71 | L20: 4 | M20: 7 | N20: =SUM(B20:M20) -> 267 | O20: N/A | P20: N/A
B23: 38899 | C23: 38930 | D23: 38961 | E23: 38991 | F23: 39022 | G23: 39052 | H23: 39083 | I23: 39114 | J23: 39142 | K23: 39173 | L23: 39203 | M23: 39234 | N23: Total | O23: 2006-2007 Price | P23: Price per unit
A24: ABC-CLIO databases (all)
A25: Sessions | B25: =B7+B13+B19 -> 88 | C25: =C7+C13+C19 -> 33 | D25: =D7+D13+D19 -> 174 | E25: =E7+E13+E19 -> 474 | F25: =F7+F13+F19 -> 456 | G25: =G7+G13+G19 -> 188 | H25: =H7+H13+H19 -> 72 | I25: =I7+I13+I19 -> 232 | ... M25: =M7+M13+M19 -> 74 | N25: =SUM(B24:M25) -> 2710
A26: Searches | B26: =B8+B14+B20 -> 104 | C26: =C8+C14+C20 -> 33 | D26: =D8+D14 -> 249 | E26: =E8+E14+E20 -> 447 | F26: =F8+F14+F20 -> 481 | G26: =G8+G14+G20 -> 203 | H26: =H8+H14+H20 -> 81 | I26: =I8+I14+I20 -> 248 | J26: =J8+J14+J20 -> 488 | K26: =K8+K14+K20 -> 706 | L26: =L8+L14+L20 -> 86 | M26: =M8+M14+M20 -> 97 | N26: =SUM(B26:M26) -> 3223 | O26: =O8+O14 -> 13440 | P26: =O26/N26 -> 4.1700279
A29: COUNTER-Compliant?: | B29: No

Sheet CIAO
A1: CIAO
A2: 2006-2007
B5: 38899 | C5: 38930 | D5: 38961 | E5: 38991 | F5: 39022 | G5: 39052 | H5: 39083 | I5: 39114 | J5: 39142 | K5: 39173 | L5: 39203 | M5: 39234 | N5: Total | O5: 2006-2007 price | P5: Price per unit
A6: TOTAL
A7: Unique Visitors | B7: N/A | C7: N/A | D7: N/A | E7: N/A | F7: N/A | G7: 0 | H7: 6 | I7: 13 | J7: 10 | K7: 18 | L7: 4 | M7: 7 | N7: =SUM(B7:M7) -> 58
A8: No of Visits | B8: N/A | C8: N/A | D8: N/A | E8: N/A | F8: N/A | G8: 0 | H8: 15 | I8: 15 | J8: 10 | K8: 24 | L8: 4 | M8: 7 | N8: =SUM(B8:M8) -> 75
A9: No of Views | B9: N/A | C9: N/A | D9: N/A | E9: N/A | F9: N/A | G9: 0 | H9: 44 | I9: 37 | J9: 45 | K9: 40 | L9: 7 | M9: 25 | N9: =SUM(B9:M9) -> 198
A10: No of Searches | B10: N/A | C10: N/A | D10: N/A | E10: N/A | F10: N/A | G10: 0 | H10: 0 | I10: 0 | J10: 0 | K10: 0 | L10: 0 | M10: 0 | N10: =SUM(B10:M10) -> 0
A11: Articles Viewed | B11: N/A | C11: N/A | D11: N/A | E11: N/A | F11: N/A | G11: 0 | H11: 25 | I11: 17 | J11: 32 | K11: 3 | L11: 18 | M11: 11 | N11: =SUM(B11:M11) -> 106
A12: Average Visit Duration | B12: N/A | C12: N/A | D12: N/A | E12: N/A | F12: N/A | G12: 0 | H12: 00:07:18 | I12: 00:02:44 | J12: 00:02:26 | K12: 00:02:01 | L12: 00:01:09 | M12: 00:02:38 | N12: —
A13: Unique Visitors | B13: 107 | C13: 14 | D13: 142 | E13: 297 | F13: 365 | G13: 19 | H13: 24 | I13: 21 | J13: 17 | K13: 25 | L13: 6 | M13: N/A | N13: =SUM(B13:L13) -> 1037
A14: Active Sessions | B14: 126 | C14: 14 | D14: 181 | E14: 356 | F14: 455 | G14: 19 | H14: 28 | I14: 21 | J14: 17 | K14: 27 | L14: 6 | M14: N/A | N14: =SUM(B14:L14) -> 1250
A15: Page Views | B15: 296 | C15: 61 | D15: 570 | E15: 1059 | F15: 1248 | G15: 34 | H15: 43 | I15: 37 | J15: 45 | K15: 37 | L15: 7 | M15: N/A | N15: =SUM(B15:L15) -> 3437
A17: COUNTER-Compliant?: | B17: No
A18: Note: Methods of gathering statistics changed mid-year with no explanation.
A20: Unique Visitors (compilation) | B20: 107 | C20: 14 | D20: 142 | E20: 297 | F20: 365 | G20: 19 | H20: 6 | I20: 13 | J20: 10 | K20: 18 | L20: 4 | M20: 7 | N20: =SUM(B20:M20) -> 1002 | O20: 896 | P20: =O20/N20 -> 0.89421158

Sheet ClassificationWeb
A1: ClassificationWeb
A2: 2006-2007
B5: 38899 | C5: 38930 | D5: 38961 | E5: 38991 | F5: 39022 | G5: 39052 | H5: 39083 | I5: 39114 | J5: 39142 | K5: 39173 | L5: 39203 | M5: 39234 | N5: Total | O5: 2006-2007 Price | P5: Price per unit
A6: ClassificationWeb
A7: Sessions (no. days used) | B7: 0 | C7: 3 | D7: 11 | E7: 16 | F7: 15 | G7: 9 | H7: 0 | I7: 6 | J7: 2 | K7: 18 | L7: 3 | M7: 4 | N7: =SUM(B7:M7) -> 87 | O7: 613 | P7: =O7/N7 -> 7.045977
A8: Maximum users | B8: 0 | C8: 1 | D8: 4 | E8: 4 | F8: 2 | G8: 3 | H8: 0 | I8: 4 | J8: 1 | K8: 3 | L8: 1 | M8: 3
A9: Total records | B9: 0 | C9: =50+29+53 -> 132 | D9: =51+222+1938+780+2669+4680+6798+5857+898 -> 23893 | E9: =75+2306+3957+1157+274+189+313+454+2676+125+185+400+147+120+110+1461 -> 13949 | F9: =712+4535+634+375+5289+3337+383+3754+735+527+2231+2363+525 -> 25400 | G9: =1044+2590+136+1148+101+1536+663+25 -> 7243 | H9: 0 | I9: =156+101+299+178+2825 -> 3559 | J9: 26 | K9: =108+1790+2529+6719+3071+5755+63+6191+726+6258+3241+2673+1198+720+113+1451+225+707 -> 43538 | L9: =550+52 -> 602 | M9: 0 | N9: =SUM(B9:M9) -> 118342 | O9: 613 | P9: =O9/N9 -> 0.0051799023
A10: Next/prev records | B10: 0 | C10: N/A | D10: =130+457+50+447+594+226+250 -> 2154 | E10: =25+25+50+1059 -> 1159 | F10: =1352+44+25+2207+508+588+555+137+320+29 -> 5765 | G10: =265+294+341+246+458 -> 1604 | H10: 0 | I10: 0 | J10: 0 | K10: =26+1+25+2310+670+846+654+51+4597+548+749+131+23+537+52 -> 11220 | L10: 170 | M10: 0 | N10: =SUM(B10:M10) -> 22072
A12: COUNTER-Compliant?: | B12: No

Sheet Cochrane
A1: Cochrane Library
A2: 2006-2007
B5: 38899 | C5: 38930 | D5: 38961 | E5: 38991 | F5: 39022 | G5: 39052 | H5: 39083 | I5: 39114 | J5: 39142 | K5: 39173 | L5: 39203 | M5: 39234 | N5: Total | O5: 2006-2007 price | P5: Price per unit
A6: Cochrane Library
A7: Sessions | B7: 31 | C7: 19 | D7: 94 | E7: 122 | F7: 129 | G7: 42 | H7: 44 | I7: 146 | J7: 146 | K7: 107 | L7: 65 | M7: 60 | N7: =SUM(B7:M7) -> 1005
A8: Searches | B8: 13 | C8: 7 | D8: 50 | E8: 32 | F8: 25 | G8: 21 | H8: 13 | I8: 51 | J8: 95 | K8: 25 | L8: 11 | M8: 14 | N8: =SUM(B8:M8) -> 357 | O8: 2633.02 | P8: =O8/N8 -> 7.3754062
A9: Full-Text Articles Downloaded | B9: 39 | C9: 80 | D9: 76 | E9: 108 | F9: 97 | G9: 35 | H9: 87 | I9: 199 | J9: 118 | K9: 91 | L9: 128 | M9: 80 | N9: =SUM(B9:M9) -> 1138 | O9: 2633.02 | P9: =O9/N9 -> 2.3137258
A10: Turnaways | B10: 0 | C10: 0 | D10: 0 | E10: 0 | F10: 0 | G10: 0 | H10: 0 | I10: 0 | J10: 0 | K10: 0 | L10: 0 | M10: 0
A13: COUNTER-Compliant?: | B13: Yes

Sheet CollegeSource
A1: CollegeSource
A2: 2006-2007
B5: 38899 | C5: 38930 | D5: 38961 | E5: 38991 | F5: 39022 | G5: 39052 | H5: 39083 | I5: 39114 | J5: 39142 | K5: 39173 | L5: 39203 | M5: 39234 | N5: Total | O5: 2006-2007 price | P5: Price per search
A6: College Source
A7: Searches | B7: 9 | C7: 86 | D7: 37 | E7: 18 | F7: 21 | G7: 25 | H7: 23 | I7: 23 | J7: 34 | K7: 28 | L7: 42 | M7: 52 | N7: =SUM(B7:M7) -> 398 | O7: 1334 | P7: =O7/N7 -> 3.3517588
A9: Service Errors | B9: 2 | C9: 89 | D9: 47 | E9: 34 | F9: 11 | G9: 39 | H9: 79 | I9: 24 | J9: 62 | K9: 90 | L9: 183 | M9: 370 | N9: =SUM(B9:M9) -> 1030
A10: Turnaways | B10: 0 | C10: 0 | D10: 0 | E10: 0 | F10: 0 | G10: 0 | H10: 0 | I10: 0 | J10: 0 | K10: 0 | L10: 0 | M10: 0 | N10: =SUM(B10:M10) -> 0
A13: COUNTER-Compliant?: | B13: No

Sheet Compendex(EI)
A1: Compendex (Engineering Index)
A2: 2006-2007
B5: 38899 | C5: 38930 | D5: 38961 | E5: 38991 | F5: 39022 | G5: 39052 | H5: 39083 | I5: 39114 | J5: 39142 | K5: 39173 | L5: 39203 | M5: 39234 | N5: Total | O5: 2006-2007 Price | P5: Price per search
A6: Compendex
A7: Sessions | B7: 69 | C7: 57 | D7: 242 | E7: 329 | F7: 236 | G7: 229 | H7: 51 | I7: 106 | J7: 144 | K7: 116 | L7: 116 | M7: 112 | N7: =SUM(B7:M7) -> 1807
A8: Searches | B8: 184 | C8: 171 | D8: 1043 | E8: 1411 | F8: 732 | G8: 614 | H8: 314 | I8: 459 | J8: 552 | K8: 378 | L8: 397 | M8: 534 | N8: =SUM(B8:M8) -> 6789 | O8: 14510 | P8: =O8/N8 -> 2.1372809
A11: COUNTER-Compliant?: | B11: No

Sheet CSA
A1: CSA Databases
A2: 2006-2007
A5: Metric | B5: 38899 | C5: 38930 | D5: 38961 | E5: 38991 | F5: 39022 | G5: 39052 | H5: 39083 | I5: 39114 | J5: 39142 | K5: 39173 | L5: 39203 | M5: 39234 | N5: Total | O5: 2006-2007 Price | P5: Price per search
A6: ASFA (all)
A7: Searches | B7: =1+585+215 -> 801 | C7: =1+403+271 -> 675 | D7: =925+836 -> 1761 | E7: =667+1037 -> 1704 | F7: =829+1053 -> 1882 | G7: =1597+617 -> 2214 | H7: =607+305 -> 912 | I7: =675+1449 -> 2124 | J7: =609+879 -> 1488 | K7: =632+734 -> 1366 | L7: =154+421 -> 575 | M7: =434+310 -> 744 | N7: =SUM(B7:M7) -> 16246 | O7: 7335 | P7: =O7/N7 -> 0.45149575
A10: Metric | B10: 38899 | C10: 38930 | D10: 38961 | E10: 38991 | F10: 39022 | G10: 39052 | H10: 39083 | I10: 39114 | J10: 39142 | K10: 39173 | L10: 39203 | M10: 39234 | N10: Total | O10: 2006-2007 Price | P10: Price per search
A11: ASFA 1 (Biosciences...)
A12: Searches | B12: =0+0 -> 0 | C12: 24 | D12: 239 | E12: 375 | F12: =60+411 -> 471 | G12: =101+205 -> 306 | H12: =62+33 -> 95 | I12: =274+124 -> 398 | J12: =402+59 -> 461 | K12: =98+443 -> 541 | L12: =117+49 -> 166 | M12: =167+31 -> 198 | N12: =SUM(B12:M12) -> 3274 | O12: 0 | P12: N/A
A15: Metric | B15: 38899 | C15: 38930 | D15: 38961 | E15: 38991 | F15: 39022 | G15: 39052 | H15: 39083 | I15: 39114 | J15: 39142 | K15: 39173 | L15: 39203 | M15: 39234 | N15: Total | O15: 2006-2007 Price | P15: Price per search
A16: ASFA 2 (Ocean Technology…)
A17: Searches | B17: =0+0 -> 0 | C17: 14 | D17: 66 | E17: 66 | F17: 96 | G17: 39 | H17: =23+0 -> 23 | I17: =75+2 -> 77 | J17: =67+0 -> 67 | K17: =0+107 -> 107 | L17: 36 | M17: 12 | N17: =SUM(B17:M17) -> 603 | O17: 0 | P17: N/A
A20: Metric | B20: 38899 | C20: 38930 | D20: 38961 | E20: 38991 | F20: 39022 | G20: 39052 | H20: 39083 | I20: 39114 | J20: 39142 | K20: 39173 | L20: 39203 | M20: 39234 | N20: Total | O20: 2006-2007 Price | P20: Price per search
A21: ASFA 3 (Aquatic Pollution…)
A22: Searches | B22: 0 | C22: 18 | D22: 95 | E22: 173 | F22: =60+261 -> 321 | G22: =101+89 -> 190 | H22: =35+33 -> 68 | I22: =120+124 -> 244 | J22: =247+59 -> 306 | K22: =98+169 -> 267 | L22: =47+49 -> 96 | M22: =109+29 -> 138 | N22: =SUM(B22:M22) -> 1916 | O22: 0 | P22: N/A
A25: Metric | B25: 38899 | C25: 38930 | D25: 38961 | E25: 38991 | F25: 39022 | G25: 39052 | H25: 39083 | I25: 39114 | J25: 39142 | K25: 39173 | L25: 39203 | M25: 39234 | N25: Total | O25: 2006-2007 Price | P25: Price per search
A26: ASFA Aquaculture Abstracts
A27: Searches | B27: 0 | C27: 28 | D27: 91 | E27: 105 | F27: =60+254 -> 314 | G27: =101+150 -> 251 | H27: =41+33 -> 74 | I27: =129+124 -> 253 | J27: =234+59 -> 293 | K27: =98+155 -> 253 | L27: =44+49 -> 93 | M27: =117+29 -> 146 | N27: =SUM(B27:M27) -> 1901 | O27: 0 | P27: N/A
A30: Metric | B30: 38899 | C30: 38930 | D30: 38961 | E30: 38991 | F30: 39022 | G30: 39052 | H30: 39083 | I30: 39114 | J30: 39142 | K30: 39173 | L30: 39203 | M30: 39234 | N30: Total | O30: 2006-2007 Price | P30: Price per search
A31: ASFA Marine Biotechnology Abstracts
A32: Searches | B32: 0 | C32: 16 | D32: 75 | E32: 85 | F32: =60+181 -> 241 | G32: =101+79 -> 180 | H32: =33+33 -> 66 | I32: =108+126 -> 234 | J32: =244+59 -> 303 | K32: =98+153 -> 251 | L32: =47+49 -> 96 | M32: =94+29 -> 123 | N32: =SUM(B32:M32) -> 1670 | O32: 0 | P32: N/A
A35: Metric | B35: 38899 | C35: 38930 | D35: 38961 | E35: 38991 | F35: 39022 | G35: 39052 | H35: 39083 | I35: 39114 | J35: 39142 | K35: 39173 | L35: 39203 | M35: 39234 | N35: Total | O35: 2006-2007 Price | P35: Price per search
A36: Communication Abstracts
A37: Searches | B37: 476 | C37: 113 | D37: =1+567 -> 568 | E37: 962 | F37: 2299 | G37: 684 | H37: 192 | I37: =751+4 -> 755 | J37: =864+0 -> 864 | K37: =8+2415 -> 2423 | L37: =353+0 -> 353 | M37: 255 | N37: =SUM(B37:M37) -> 9944 | O37: 2685 | P37: =O37/N37 -> 0.27001207
A40: Metric | B40: 38899 | C40: 38930 | D40: 38961 | E40: 38991 | F40: 39022 | G40: 39052 | H40: 39083 | I40: 39114 | J40: 39142 | K40: 39173 | L40: 39203 | M40: 39234 | N40: Total | O40: 2006-2007 Price | P40: Price per search
A41: EconLit
A42: Searches | B42: 322 | C42: 232 | D42: =1+536 -> 537 | E42: 1027 | F42: 994 | G42: 422 | H42: 405 | I42: =816+4 -> 820 | J42: =720+0 -> 720 | K42: =8+954 -> 962 | L42: =324+0 -> 324 | M42: 224 | N42: =SUM(B42:M42) -> 6989 | O42: 4163 | P42: =O42/N42 -> 0.59565031
A45: Metric | B45: 38899 | C45: 38930 | D45: 38961 | E45: 38991 | F45: 39022 | G45: 39052 | H45: 39083 | I45: 39114 | J45: 39142 | K45: 39173 | L45: 39203 | M45: 39234 | N45: Total | O45: 2006-2007 Price | P45: Price per search
A46: ERIC
A47: Searches | B47: 444 | C47: 116 | D47: =1+846 -> 847 | E47: 1474 | F47: 1338 | G47: 459 | H47: 212 | I47: =866+4 -> 870 | J47: =1015 -> 1015 | K47: =8+1050 -> 1058 | L47: 319 | M47: 411 | N47: =SUM(B47:M47) -> 8563 | O47: 0 | P47: N/A
A50: Metric | B50: 38899 | C50: 38930 | D50: 38961 | E50: 38991 | F50: 39022 | G50: 39052 | H50: 39083 | I50: 39114 | J50: 39142 | K50: 39173 | L50: 39203 | M50: 39234 | N50: Total | O50: 2006-2007 Price | P50: Price per search
A51: GeoRef
A52: Searches | B52: 5 | C52: =1+28 -> 29 | D52: 161 | E52: 170 | F52: =40+222 -> 262 | G52: =101+94 -> 195 | H52: =54+69 -> 123 | I52: =109+187 -> 296 | J52: =326+90 -> 416 | K52: =125+224 -> 349 | L52: =56+67 -> 123 | M52: =73+71 -> 144 | N52: =SUM(B52:M52) -> 2273 | O52: 2925 | P52: =O52/N52 -> 1.2868456
A55: Metric | B55: 38899 | C55: 38930 | D55: 38961 | E55: 38991 | F55: 39022 | G55: 39052 | H55: 39083 | I55: 39114 | J55: 39142 | K55: 39173 | L55: 39203 | M55: 39234 | N55: Total | O55: 2006-2007 Price | P55: Price per search
A56: GeoRef in Process
A57: Searches | B57: 5 | C57: =1+20 -> 21 | D57: 141 | E57: 149 | F57: =40+192 -> 232 | G57: =101+71 -> 172 | H57: =34+33 -> 67 | I57: =98+129 -> 227 | J57: =243+62 -> 305 | K57: =98+153 -> 251 | L57: =45+49 -> 94 | M57: =70+29 -> 99 | N57: =SUM(B57:M57) -> 1763 | O57: 0 | P57: N/A
A60: Metric | B60: 38899 | C60: 38930 | D60: 38961 | E60: 38991 | F60: 39022 | G60: 39052 | H60: 39083 | I60: 39114 | J60: 39142 | K60: 39173 | L60: 39203 | M60: 39234 | N60: Total | O60: 2006-2007 Price | P60: Price per search
A61: International Pharmaceutical Abstracts
A62: Searches | B62: =30+14+68 -> 112 | C62: =25+5+24 -> 54 | D62: =33+218 -> 251 | E62: =26+243 -> 269 | F62: =62+282 -> 344 | G62: =101+103 -> 204 | H62: =43+33 -> 76 | I62: =147+124 -> 271 | J62: =321+59 -> 380 | K62: =98+211 -> 309 | L62: =82+49 -> 131 | M62: =166+29 -> 195 | N62: =SUM(B62:M62) -> 2596 | O62: 3444 | P62: =O62/N62 -> 1.3266564
A65: Metric | B65: 38899 | C65: 38930 | D65: 38961 | E65: 38991 | F65: 39022 | G65: 39052 | H65: 39083 | I65: 39114 | J65: 39142 | K65: 39173 | L65: 39203 | M65: 39234 | N65: Total | O65: 2006-2007 Price | P65: Price per search
A66: MLA International Bibliography
...

Sheet EBSCOhost
A1: EBSCOhost Databases
A2: 2006-2007
B5: 38899 | C5: 38930 | D5: 38961 | E5: 38991 | F5: 39022 | G5: 39052 | H5: 39083 | I5: 39114 | J5: 39142 | K5: 39173 | L5: 39203 | M5: 39234 | N5: Total | O5: 2006-2007 Price | P5: Price per search
A6: Academic Search Premier
A7: Sessions | B7: 5613 | C7: 1141 | D7: 5003 | E7: 14683 | F7: 14524 | G7: 6797 | H7: 2511 | I7: 9745 | J7: 12163 | K7: 12975 | L7: 3255 | M7: 3016 | N7: =SUM(B7:M7) -> 91426
A8: Searches | B8: 22341 | C8: 2157 | D8: 13297 | E8: 48738 | F8: 44971 | G8: 19789 | H8: 6102 | I8: 30569 | J8: 38956 | K8: 42059 | L8: 10721 | M8: 10011 | N8: =SUM(B8:M8) -> 289711 | O8: 19175 | P8: =O8/N8 -> 0.066186648
B11: 38899 | C11: 38930 | D11: 38961 | E11: 38991 | F11: 39022 | G11: 39052 | H11: 39083 | I11: 39114 | J11: 39142 | K11: 39173 | L11: 39203 | M11: 39234 | N11: Total | O11: 2006-2007 Price | P11: Price per search
A12: Book Index with Reviews
A13: Sessions | B13: 0 | C13: 4 | D13: 26 | E13: 25 | F13: 32 | G13: 17 | H13: 6 | I13: 19 | J13: 15 | K13: 21 | L13: 20 | M13: 11 | N13: =SUM(B13:M13) -> 196
A14: Searches | B14: 0 | C14: 15 | D14: 111 | E14: 64 | F14: 133 | G14: 64 | H14: 22 | I14: 64 | J14: 70 | K14: 50 | L14: 44 | M14: 35 | N14: =SUM(B14:M14) -> 672 | O14: 0 | P14: N/A
B17: 38899 | C17: 38930 | D17: 38961 | E17: 38991 | F17: 39022 | G17: 39052 | H17: 39083 | I17: 39114 | J17: 39142 | K17: 39173 | L17: 39203 | M17: 39234 | N17: Total | O17: 2006-2007 Price | P17: Price per search
A18: EBSCO Animals
A19: Sessions | B19: 37 | C19: 5 | D19: 45 | E19: 150 | F19: 137 | G19: 48 | H19: 17 | I19: 125 | J19: 123 | K19: 167 | L19: 19 | M19: 34 | N19: =SUM(B19:M19) -> 907
A20: Searches | B20: 136 | C20: 17 | D20: 120 | E20: 457 | F20: 451 | G20: 130 | H20: 31 | I20: 355 | J20: 351 | K20: 457 | L20: 62 | M20: 99 | N20: =SUM(B20:M20) -> 2666 | O20: 0 | P20: N/A
B23: 38899 | C23: 38930 | D23: 38961 | E23: 38991 | F23: 39022 | G23: 39052 | H23: 39083 | I23: 39114 | J23: 39142 | K23: 39173 | L23: 39203 | M23: 39234 | N23: Total | O23: 2006-2007 Price | P23: Price per search
A24: Film & Television Literature Index
A25: Sessions | B25: 0 | C25: 11 | D25: 39 | E25: 109 | F25: 96 | G25: 54 | H25: 6 | I25: 55 | J25: 92 | K25: 97 | L25: 34 | M25: 41 | N25: =SUM(B25:M25) -> 634
A26: Searches | B26: 0 | C26: 26 | D26: 128 | E26: 332 | F26: 422 | G26: 164 | H26: 35 | I26: 185 | J26: 375 | K26: 276 | L26: 110 | M26: 151 | N26: =SUM(B26:M26) -> 2204 | O26: 0 | P26: N/A
B29: 38899 | C29: 38930 | D29: 38961 | E29: 38991 | F29: 39022 | G29: 39052 | H29: 39083 | I29: 39114 | J29: 39142 | K29: 39173 | L29: 39203 | M29: 39234 | N29: Total | O29: 2006-2007 Price | P29: Price per search
A30: Funk & Wagnall's New World Encyclopedia
A31: Sessions | B31: 24 | C31: 2 | D31: 19 | E31: 72 | F31: 54 | G31: 37 | H31: 13 | I31: 55 | J31: 57 | K31: 61 | L31: 23 | M31: 37 | N31: =SUM(B31:M31) -> 454
A32: Searches | B32: 119 | C32: 8 | D32: 70 | E32: 187 | F32: 237 | G32: 75 | H32: 37 | I32: 177 | J32: 179 | K32: 173 | L32: 79 | M32: 138 | N32: =SUM(B32:M32) -> 1479 | O32: 0 | P32: N/A
B35: 38899 | C35: 38930 | D35: 38961 | E35: 38991 | F35: 39022 | G35: 39052 | H35: 39083 | I35: 39114 | J35: 39142 | K35: 39173 | L35: 39203 | M35: 39234 | N35: Total | O35: 2006-2007 Price | P35: Price per search
A36: INSPEC
A37: Sessions | B37: 21 | C37: 5 | D37: 31 | E37: 63 | F37: 54 | G37: 38 | H37: 10 | I37: 87 | J37: 53 | K37: 67 | L37: 34 | M37: 33 | N37: =SUM(B37:M37) -> 496
A38: Searches | B38: 61 | C38: 6 | D38: 147 | E38: 190 | F38: 269 | G38: 87 | H38: 23 | I38: 304 | J38: 222 | K38: 213 | L38: 132 | M38: 92 | N38: =SUM(B38:M38) -> 1746 | O38: 25764 | P38: =O38/N38 -> 14.756014
B41: 38899 | C41: 38930 | D41: 38961 | E41: 38991 | F41: 39022 | G41: 39052 | H41: 39083 | I41: 39114 | J41: 39142 | K41: 39173 | L41: 39203 | M41: 39234 | N41: Total | O41: 2006-2007 Price | P41: Price per search
A42: MAS Ultra - School Edition
A43: Sessions | B43: 49 | C43: 13 | D43: 59 | E43: 132 | F43: 103 | G43: 59 | H43: 25 | I43: 93 | J43: 96 | K43: 103 | L43: 44 | M43: 69 | N43: =SUM(B43:M43) -> 845
A44: Searches | B44: 154 | C44: 21 | D44: 142 | E44: 316 | F44: 280 | G44: 70 | H44: 46 | I44: 377 | J44: 328 | K44: 250 | L44: 145 | M44: 222 | N44: =SUM(B44:M44) -> 2351 | O44: 0 | P44: N/A
B47: 38899 | C47: 38930 | D47: 38961 | E47: 38991 | F47: 39022 | G47: 39052 | H47: 39083 | I47: 39114 | J47: 39142 | K47: 39173 | L47: 39203 | M47: 39234 | N47: Total | O47: 2006-2007 Price | P47: Price per search
A48: Military & Government Collection
A49: Sessions | B49: 39 | C49: 15 | D49: 39 | E49: 113 | F49: 100 | G49: 46 | H49: 11 | I49: 70 | J49: 84 | K49: 127 | L49: 25 | M49: 36 | N49: =SUM(B49:M49) -> 705
A50: Searches | B50: 128 | C50: 33 | D50: 75 | E50: 310 | F50: 315 | G50: 89 | H50: 35 | I50: 189 | J50: 285 | K50: 329 | L50: 60 | M50: 108 | N50: =SUM(B50:M50) -> 1956 | O50: 0 | P50: N/A
B53: 38899 | C53: 38930 | D53: 38961 | E53: 38991 | F53: 39022 | G53: 39052 | H53: 39083 | I53: 39114 | J53: 39142 | K53: 39173 | L53: 39203 | M53: 39234 | N53: Total | O53: 2006-2007 Price | P53: Price per search
A54: Primary Search
A55: Sessions | B55: 67 | C55: 9 | D55: 54 | E55: 135 | F55: 101 | G55: 36 | H55: 16 | I55: 119 | J55: 111 | K55: 89 | L55: 31 | M55: 60 | N55: =SUM(B55:M55) -> 828
A56: Searches | B56: 293 | C56: 36 | D56: 227 | E56: 399 | F56: 348 | G56: 86 | H56: 35 | I56: 436 | J56: 435 | K56: 366 | L56: 108 | M56: 222 | N56: =SUM(B56:M56) -> 2991 | O56: 0 | P56: N/A
B59: 38899 | C59: 38930 | D59: 38961 | E59: 38991 | F59: 39022 | G59: 39052 | H59: 39083 | I59: 39114 | J59: 39142 | K59: 39173 | L59: 39203 | M59: 39234 | N59: Total | O59: 2006-2007 Price | P59: Price per search
A60: CINAHL
...

Sheet Elsevier
A1: Elsevier
A2: 2006-2007
B5: 38899 | C5: 38930 | D5: 38961 | E5: 38991 | F5: 39022 | G5: 39052 | H5: 39083 | I5: 39114 | J5: 39142 | K5: 39173 | L5: 39203 | M5: 39234 | N5: Total | O5: 2006-2007 Price | P5: Price per unit
A6: EMBASE.com
A7: Sessions | B7: 6 | C7: 18 | D7: 44 | E7: 50 | F7: 76 | G7: 31 | H7: 31 | I7: 71 | J7: 100 | K7: 112 | L7: 72 | M7: 63 | N7: =SUM(B7:M7) -> 674
A8: Searches | B8: 37 | C8: 60 | D8: 185 | E8: 151 | F8: 236 | G8: 121 | H8: 107 | I8: 243 | J8: 327 | K8: 364 | L8: 176 | M8: 233 | N8: =SUM(B8:M8) -> 2240 | O8: 9045 | P8: =O8/N8 -> 4.0379464
A10: Encyclopedia of Ocean Science
A11: Requests for full text chapters | B11: 0 | C11: 6 | D11: 3 | E11: 19 | F11: 97 | G11: 418 | H11: 1 | I11: 12 | J11: 7 | K11: 3 | L11: 25 | M11: 37 | N11: =SUM(B11:M11) -> 628 | O11: 615 | P11: =O11/N11 -> 0.97929936
A14: COUNTER-Compliant?: | B14: No

Sheet FirstSearch
A1: FirstSearch
A2: 2006-2007
B5: 38899 | C5: 38930 | D5: 38961 | E5: 38991 | F5: 39022 | G5: 39052 | H5: 39083 | I5: 39114 | J5: 39142 | K5: 39173 | L5: 39203 | M5: 39234 | N5: Total | O5: 2006-2007 Price | P5: Price per search
A6: Alternative Press Index
A7: Searches | B7: 0 | C7: 0 | D7: 20 | E7: 27 | F7: 0 | G7: 3 | H7: 0 | I7: 0 | J7: 0 | K7: 0 | L7: 0 | M7: 3 | N7: =SUM(B7:M7) -> 53 | O7: =P7*N7 -> 53 | P7: 1
B10: 38899 | C10: 38930 | D10: 38961 | E10: 38991 | F10: 39022 | G10: 39052 | H10: 39083 | I10: 39114 | J10: 39142 | K10: 39173 | L10: 39203 | M10: 39234 | N10: Total | O10: 2006-2007 Price | P10: Price per search
A11: Alternative Press Index Archive
A12: Searches | B12: 0 | C12: 0 | D12: 12 | E12: 11 | F12: 0 | G12: 0 | H12: 0 | I12: 0 | J12: 4 | K12: 0 | L12: 0 | M12: 0 | N12: =SUM(B12:M12) -> 27 | O12: =P12*N12 -> 27 | P12: 1
B15: 38899 | C15: 38930 | D15: 38961 | E15: 38991 | F15: 39022 | G15: 39052 | H15: 39083 | I15: 39114 | J15: 39142 | K15: 39173 | L15: 39203 | M15: 39234 | N15: Total | O15: 2006-2007 Price | P15: Price per search
A16: ArticleFirst
A17: Sessions | B17: 160 | C17: 63 | D17: 194 | E17: 391 | F17: 400 | G17: 193 | H17: 118 | I17: 225 | J17: 301 | K17: 297 | L17: 91 | M17: 101 | N17: =SUM(B17:M17) -> 2534
A18: Searches | B18: 662 | C18: 298 | D18: 436 | E18: 738 | F18: 895 | G18: 1163 | H18: 771 | I18: 608 | J18: 931 | K18: 674 | L18: 645 | M18: 830 | N18: =SUM(B18:M18) -> 8651 | O18: 0 | P18: N/A
A19: User Limit | B19: 2 | C19: 2 | D19: 2 | E19: 2 | F19: 2 | G19: 2 | H19: 2 | I19: 2 | J19: 2 | K19: 2 | L19: 2 | M19: 2
A20: Turnaways | B20: 6 | C20: 0 | D20: 9 | E20: 44 | F20: 30 | G20: 3 | H20: 3 | I20: 4 | J20: 33 | K20: 19 | L20: 0 | M20: 0 | N20: =SUM(B20:M20) -> 151
B23: 38899 | C23: 38930 | D23: 38961 | E23: 38991 | F23: 39022 | G23: 39052 | H23: 39083 | I23: 39114 | J23: 39142 | K23: 39173 | L23: 39203 | M23: 39234 | N23: Total | O23: 2006-2007 Price | P23: Price per search
A24: Clase and Periodica
A25: Sessions | B25: 0 | C25: 2 | D25: 9 | E25: 25 | F25: 27 | G25: 21 | H25: 3 | I25: 21 | J25: 12 | K25: 14 | L25: 2 | M25: 5 | N25: =SUM(B25:M25) -> 141
A26: Searches | B26: 0 | C26: 2 | D26: 6 | E26: 16 | F26: 24 | G26: 41 | H26: 3 | I26: 9 | J26: 1 | K26: 9 | L26: 1 | M26: 5 | N26: =SUM(B26:M26) -> 117 | O26: 0 | P26: N/A
A27: User Limit | B27: 0 | C27: 2 | D27: 2 | E27: 2 | F27: 2 | G27: 2 | H27: 2 | I27: 2 | J27: 2 | K27: 2 | L27: 2 | M27: 2
A28: Turnaways | B28: 0 | C28: 0 | D28: 0 | E28: 0 | F28: 2 | G28: 0 | H28: 0 | I28: 0 | J28: 0 | K28: 0 | L28: 0 | M28: 0 | N28: =SUM(B28:M28) -> 2
B31: 38899 | C31: 38930 | D31: 38961 | E31: 38991 | F31: 39022 | G31: 39052 | H31: 39083 | I31: 39114 | J31: 39142 | K31: 39173 | L31: 39203 | M31: 39234 | N31: Total | O31: 2006-2007 Price | P31: Price per search
A32: ERIC
A33: Sessions | B33: 98 | C33: 26 | D33: 100 | E33: 356 | F33: 291 | G33: 121 | H33: 63 | I33: 206 | J33: 213 | K33: 154 | L33: 32 | M33: 93 | N33: =SUM(B33:M33) -> 1753
A34: Searches | B34: 236 | C34: 52 | D34: 221 | E34: 761 | F34: 698 | G34: 218 | H34: 140 | I34: 452 | J34: 534 | K34: 318 | L34: 70 | M34: 245 | N34: =SUM(B34:M34) -> 3945 | O34: 0 | P34: N/A
A35: User Limit | B35: 2 | C35: 2 | D35: 2 | E35: 2 | F35: 2 | G35: 2 | H35: 2 | I35: 2 | J35: 2 | K35: 2 | L35: 2 | M35: 2
A36: Turnaways | B36: 3 | C36: 0 | D36: 3 | E36: 37 | F36: 73 | G36: 6 | H36: 2 | I36: 15 | J36: 17 | K36: 9 | L36: 37 | M36: 8 | N36: =SUM(B36:M36) -> 210
B39: 38899 | C39: 38930 | D39: 38961 | E39: 38991 | F39: 39022 | G39: 39052 | H39: 39083 | I39: 39114 | J39: 39142 | K39: 39173 | L39: 39203 | M39: 39234 | N39: Total | O39: 2006-2007 Price | P39: Price per search
A40: Electronic Books
A41: Sessions | B41: 2 | C41: 1 | D41: 7 | E41: 14 | F41: 16 | G41: 11 | H41: 9 | I41: 18 | J41: 6 | K41: 12 | L41: 12 | M41: 0 | N41: =SUM(B41:M41) -> 108
A42: Searches | B42: 7 | C42: 1 | D42: 3 | E42: 25 | F42: 16 | G42: 9 | H42: 12 | I42: 14 | J42: 7 | K42: 17 | L42: 11 | M42: 0 | N42: =SUM(B42:M42) -> 122 | O42: 0 | P42: N/A
A43: User Limit | B43: 2 | C43: 2 | D43: 2 | E43: 2 | F43: 2 | G43: 2 | H43: 2 | I43: 2 | J43: 2 | K43: 2 | L43: 2 | M43: 0
A44: Turnaways | B44: 0 | C44: 0 | D44: 0 | E44: 0 | F44: 0 | G44: 0 | H44: 0 | I44: 0 | J44: 0 | K44: 0 | L44: 0 | M44: 0 | N44: =SUM(B44:M44) -> 0
B47: 38899 | C47: 38930 | D47: 38961 | E47: 38991 | F47: 39022 | G47: 39052 | H47: 39083 | I47: 39114 | J47: 39142 | K47: 39173 | L47: 39203 | M47: 39234 | N47: Total | O47: 2006-2007 Price | P47: Price per search
A48: Electronic Collections Online
A49: Sessions | B49: 20 | C49: 4 | D49: 46 | E49: 81 | F49: 74 | G49: 16 | H49: 34 | I49: 53 | J49: 50 | K49: 43 | L49: 21 | M49: 25 | N49: =SUM(B49:M49) -> 467
A50: Searches | B50: 19 | C50: 4 | D50: 124 | E50: 153 | F50: 104 | G50: 23 | H50: 61 | I50: 75 | J50: 64 | K50: 58 | L50: 25 | M50: 43 | N50: =SUM(B50:M50) -> 753 | O50: 0 | P50: N/A
A51: User Limit | B51: 2 | C51: 2 | D51: 2 | E51: 2 | F51: 2 | G51: 2 | H51: 2 | I51: 2 | J51: 2 | K51: 2 | L51: 2 | M51: 2
A52: Turnaways | B52: 0 | C52: 0 | D52: 0 | E52: 0 | F52: 0 | G52: 0 | H52: 1 | I52: 0 | J52: 0 | K52: 0 | L52: 0 | M52: 0 | N52: =SUM(B52:M52) -> 1
B55: 38899 | C55: 38930 | D55: 38961 | E55: 38991 | F55: 39022 | G55: 39052 | H55: 39083 | I55: 39114 | J55: 39142 | K55: 39173 | L55: 39203 | M55: 39234 | N55: Total | O55: 2006-2007 Price | P55: Price per search
A56: GEOBASE
...

Sheet InfoTrac
A1: InfoTRAC
A2: 2006-2007
B5: 38899 | C5: 38930 | D5: 38961 | E5: 38991 | F5: 39022 | G5: 39052 | H5: 39083 | I5: 39114 | J5: 39142 | K5: 39173 | L5: 39203 | M5: 39234 | N5: Total | O5: Price for 2006-2007 | P5: Price per unit
A6: Literature Resource Center
A7: Sessions | B7: 263 | C7: 22 | D7: 147 | E7: 544 | F7: 741 | G7: 413 | H7: 86 | I7: 249 | J7: 362 | K7: 389 | L7: 218 | M7: 118 | N7: =SUM(B7:M7) -> 3552
A8: Searches | B8: 1886 | C8: 124 | D8: 864 | E8: 3068 | F8: 3553 | G8: 2073 | H8: 506 | I8: 1220 | J8: 1259 | K8: 1690 | L8: 919 | M8: 251 | N8: =SUM(B8:M8) -> 17413 | O8: 4678 | P8: =O8/N8 -> 0.26864986
A9: Turnaways | B9: 0 | C9: 0 | D9: 0 | E9: 0 | F9: 0 | G9: 0 | H9: 0 | I9: 0 | J9: 0 | K9: 0 | L9: 0 | M9: 0 | N9: =SUM(B9:M9) -> 0
A10: Successful Full-Text Article Requests | B10: 439 | C10: 12 | D10: 201 | E10: 708 | F10: 966 | G10: 597 | H10: 141 | I10: 269 | J10: 422 | K10: 574 | L10: 300 | M10: 55 | N10: =SUM(B10:M10) -> 4684 | O10: 4678 | P10: =O10/N10 -> 0.99871904
A13: COUNTER-Compliant?: | B13: Yes

Sheet LexisNexis
A1: LexisNexis
A2: 2006-2007
B5: 38899 | C5: 38930 | D5: 38961 | E5: 38991 | F5: 39022 | G5: 39052 | H5: 39083 | I5: 39114 | J5: 39142 | K5: 39173 | L5: 39203 | M5: 39234 | N5: Total | O5: 2006-2007 Price | P5: Price per unit
A6: Academic
A7: Searches | B7: 2595 | C7: 1788 | D7: 3196 | E7: 7736 | F7: 7367 | G7: 4266 | H7: 2724 | I7: 5750 | J7: 6526 | K7: 7270 | L7: 1925 | M7: 1988 | N7: =SUM(B7:M7) -> 53131 | O7: 21720 | P7: =O7/N7 -> 0.40880089
A8: Documents Retrieved | B8: 3708 | C8: 2888 | D8: 3791 | E8: 7817 | F8: 8730 | G8: 5660 | H8: 3990 | I8: 6881 | J8: 7087 | K8: 9194 | L8: 2638 | M8: 2543 | N8: =SUM(B8:M8) -> 64927 | O8: 21720 | P8: =O8/N8 -> 0.33452955
A10: Congressional
A11: Searches | B11: 63 | C11: 20 | D11: 302 | E11: 312 | F11: 283 | G11: 68 | H11: 36 | I11: 118 | J11: 172 | K11: 130 | L11: 77 | M11: 133 | N11: =SUM(B11:M11) -> 1714 | O11: =6889.86+1025 -> 7914.86 | P11: =O11/N11 -> 4.6177713
A12: Documents Retrieved | B12: 37 | C12: 11 | D12: 239 | E12: 224 | F12: 412 | G12: 27 | H12: 63 | I12: 67 | J12: 195 | K12: 115 | L12: 54 | M12: 357 | N12: =SUM(B12:M12) -> 1801 | O12: =O11 -> 7914.86 | P12: =O12/N12 -> 4.3947029
A14: Environmental
A15: Searches | B15: 0 | C15: 9 | D15: 135 | E15: 299 | F15: 445 | G15: 222 | H15: 32 | I15: 172 | J15: 506 | K15: 329 | L15: 44 | M15: 46 | N15: =SUM(B15:M15) -> 2239 | O15: 4200 | P15: =O15/N15 -> 1.8758374
A16: Documents Retrieved | B16: 0 | C16: 5 | D16: 93 | E16: 273 | F16: 457 | G16: 202 | H16: 4 | I16: 311 | J16: 579 | K16: 261 | L16: 62 | M16: 42 | N16: =SUM(B16:M16) -> 2289 | O16: 4200 | P16: =O16/N16 -> 1.8348624
A19: COUNTER-Compliant?: | B19: No

Sheet MathSciNet
A1: MathSciNet
A2: 2006-2007
B5: 38899 | C5: 38930 | D5: 38961 | E5: 38991 | F5: 39022 | G5: 39052 | H5: 39083 | I5: 39114 | J5: 39142 | K5: 39173 | L5: 39203 | M5: 39234 | N5: Total | O5: 2006-2007 price | P5: Price per search
A6: MathSciNet
A7: Sessions | B7: 127 | C7: 125 | D7: 596 | E7: 571 | F7: 831 | G7: 681 | H7: 946 | I7: 696 | J7: 1409 | K7: 933 | L7: 631 | M7: 458 | N7: =SUM(B7:M7) -> 8004
A8: Searches | B8: 274 | C8: 300 | D8: 792 | E8: 854 | F8: 1080 | G8: 811 | H8: 1097 | I8: 851 | J8: 1616 | K8: 1207 | L8: 727 | M8: 571 | N8: =SUM(B8:M8) -> 10180 | O8: 6856 | P8: =O8/N8 -> 0.67347741
A11: COUNTER-Compliant?: | B11: No

Sheet Mergent
A1: Mergent
A2: 2006-2007
B5: 38899 | C5: 38930 | D5: 38961 | E5: 38991 | F5: 39022 | G5: 39052 | H5: 39083 | I5: 39114 | J5: 39142 | K5: 39173 | L5: 39203 | M5: 39234 | N5: Total | O5: 2006-2007 price | P5: Price per unit
A6: MergentOnline
A7: Logins | B7: 15 | C7: 18 | D7: 21 | E7: 44 | F7: 58 | G7: 52 | H7: 27 | I7: 11 | J7: 8 | K7: 33 | L7: 6 | M7: 9 | N7: =SUM(B7:M7) -> 302
A8: Searches | B8: 31 | C8: 39 | D8: 17 | E8: 78 | F8: 65 | G8: 61 | H8: 56 | I8: 20 | J8: 17 | K8: 55 | L8: 3 | M8: 14 | N8: =SUM(B8:M8) -> 456 | O8: 11000 | P8: =O8/N8 -> 24.122807
A9: Companies Viewed | B9: 20 | C9: 14 | D9: 15 | E9: 39 | F9: 27 | G9: 49 | H9: 27 | I9: 6 | J9: 4 | K9: 35 | L9: 3 | M9: 3 | N9: =SUM(B9:M9) -> 242 | O9: 11000 | P9: =O9/N9 -> 45.454545
A12: COUNTER-Compliant?: | B12: No

Sheet MetaPress
A1: MetaPress
A2: 2006-2007
B5: 38899 | C5: 38930 | D5: 38961 | E5: 38991 | F5: 39022 | G5: 39052 | H5: 39083 | I5: 39114 | J5: 39142 | K5: 39173 | L5: 39203 | M5: 39234 | N5: Total | O5: 2006-2007 price | P5: Price per search
A6: Abstracts in Anthropology
A7: Number of Successful Article Requests | B7: 0 | C7: 0 | D7: 0 | E7: 0 | F7: 0 | G7: 0 | H7: 0 | I7: 0 | J7: 0 | K7: 0 | L7: 0 | M7: 0 | N7: =SUM(B7:M7) -> 0 | O7: 653 | P7: N/A
A9: Note: This subscription allows users to search a database, yet MetaPress usage statistics only measure "article requests," not searches.
A10: Thus these numbers mean nothing. They do NOT mean that the resource was not used.
A12: COUNTER-Compliant?: | B12: Yes

Sheet MINABS
A1: MINABS
A2: 2006-2007
B5: 38899 | C5: 38930 | D5: 38961 | E5: 38991 | F5: 39022 | G5: 39052 | H5: 39083 | I5: 39114 | J5: 39142 | K5: 39173 | L5: 39203 | M5: 39234 | N5: Total | O5: 2006-2007 price | P5: Price per search
A6: MinABS
A7: Sessions | B7: 0 | C7: 0 | D7: 1 | E7: 0 | F7: 0 | G7: 0 | H7: 0 | I7: 0 | J7: 0 | K7: 0 | L7: 0 | M7: 7 | N7: =SUM(B7:M7) -> 8 | O7: 531.94 | P7: =O7/N7 -> 66.4925
A10: COUNTER-Compliant?: | B10: No

Sheet MusicIndex
A1: Music Index
A2: 2006-2007
B5: 38899 | C5: 38930 | D5: 38961 | E5: 38991 | F5: 39022 | G5: 39052 | H5: 39083 | I5: 39114 | J5: 39142 | K5: 39173 | L5: 39203 | M5: 39234 | N5: Total | O5: 2006-2007 Price | P5: Price per search
A6: Music Index
A7: Sessions | B7: N/A | C7: N/A | D7: N/A | E7: N/A | F7: N/A | G7: N/A | H7: N/A | I7: N/A | J7: N/A | K7: N/A | L7: N/A | M7: N/A | N7: N/A
A8: Searches | B8: 137 | C8: 2 | D8: 8 | E8: 79 | F8: 208 | G8: 60 | H8: 13 | I8: 65 | J8: 420 | K8: 73 | L8: 13 | M8: 1 | N8: =SUM(B8:M8) -> 1079 | O8: 2000 | P8: =O8/N8 -> 1.8535681
A11: COUNTER-Compliant?: | B11: No

Sheet netLibrary
A1: NetLibrary
A2: 2006-2007
B5: 38899 | C5: 38930 | D5: 38961 | E5: 38991 | F5: 39022 | G5: 39052 | H5: 39083 | I5: 39114 | J5: 39142 | K5: 39173 | L5: 39203 | M5: 39234 | N5: Total | O5: Price for 2006-2007 | P5: Price per access
A6: NetLibrary
A7: Accesses | B7: 43 | C7: 33 | D7: 74 | E7: 183 | F7: 209 | G7: 96 | H7: 46 | I7: 111 | J7: 137 | K7: 133 | L7: 57 | M7: 51 | N7: =SUM(B7:M7) -> 1173 | O7: 0 | P7: N/A
A8: Turnaways | B8: 6 | C8: 0 | D8: 0 | E8: 18 | F8: 34 | G8: 26 | H8: 19 | I8: 17 | J8: 10 | K8: 31 | L8: 20 | M8: 23 | N8: =SUM(B8:M8) -> 204
A11: Note: We have 4,478 shared titles
A12: COUNTER-Compliant?: | B12: No

Sheet OVID
A1: Ovid
A2: 2006-2007
B5: 38899 | C5: 38930 | D5: 38961 | E5: 38991 | F5: 39022 | G5: 39052 | H5: 39083 | I5: 39114 | J5: 39142 | K5: 39173 | L5: 39203 | M5: 39234 | N5: Total | O5: 2006-2007 Price | P5: Price per search
A6: BIOSIS Previews
A7: Sessions | B7: 0 | C7: 1 | D7: 4 | E7: 0 | F7: 0 | G7: 2 | H7: 4 | I7: 0 | J7: 7 | K7: 2 | L7: 2 | M7: 2 | N7: =SUM(B7:M7) -> 24
A8: Searches | B8: 0 | C8: 1 | D8: 38 | E8: 0 | F8: 0 | G8: 6 | H8: 4 | I8: 0 | J8: 21 | K8: 2 | L8: 2 | M8: 5 | N8: =SUM(B8:M8) -> 79 | O8: 0 | P8: N/A
A9: Turnaways | B9: 0 | C9: 0 | D9: 0 | E9: 0 | F9: 0 | G9: 0 | H9: 0 | I9: 0 | J9: 0 | K9: 0 | L9: 0 | M9: 0 | N9: =SUM(B9:M9) -> 0
B12: 38899 | C12: 38930 | D12: 38961 | E12: 38991 | F12: 39022 | G12: 39052 | H12: 39083 | I12: 39114 | J12: 39142 | K12: 39173 | L12: 39203 | M12: 39234 | N12: Total | O12: 2006-2007 Price | P12: Price per search
A13: Ovid MEDLINE
A14: Sessions | B14: 3 | C14: 8 | D14: 106 | E14: 155 | F14: 179 | G14: 76 | H14: 54 | I14: 180 | J14: 274 | K14: 237 | L14: 117 | M14: 59 | N14: =SUM(B14:M14) -> 1448
A15: Searches | B15: 0 | C15: 54 | D15: 187 | E15: 405 | F15: 631 | G15: 332 | H15: 414 | I15: 517 | J15: 850 | K15: 638 | L15: 897 | M15: 583 | N15: =SUM(B15:M15) -> 5508 | O15: 0 | P15: N/A
A16: Turnaways | B16: 0 | C16: 0 | D16: 0 | E16: 0 | F16: 0 | G16: 0 | H16: 0 | I16: 0 | J16: 0 | K16: 0 | L16: 0 | M16: 0 | N16: =SUM(B16:M16) -> 0
B19: 38899 | C19: 38930 | D19: 38961 | E19: 38991 | F19: 39022 | G19: 39052 | H19: 39083 | I19: 39114 | J19: 39142 | K19: 39173 | L19: 39203 | M19: 39234 | N19: Total | O19: 2006-2007 Price | P19: Price per search
A20: Ovid MEDLINE In-Process
A21: Sessions | B21: 0 | C21: 8 | D21: 102 | E21: 153 | F21: 177 | G21: 76 | H21: 54 | I21: 181 | J21: 259 | K21: 222 | L21: 102 | M21: 58 | N21: =SUM(B21:M21) -> 1392
A22: Searches | B22: 0 | C22: 54 | D22: 180 | E22: 405 | F22: 629 | G22: 332 | H22: 414 | I22: 519 | J22: 825 | K22: 609 | L22: 283 | M22: 194 | N22: =SUM(B22:M22) -> 4444 | O22: 0 | P22: N/A
A23: Turnaways | B23: 0 | C23: 0 | D23: 0 | E23: 0 | F23: 0 | G23: 0 | H23: 0 | I23: 0 | J23: 0 | K23: 0 | L23: 0 | M23: 0 | N23: =SUM(B23:M23) -> 0
B26: 38899 | C26: 38930 | D26: 38961 | E26: 38991 | F26: 39022 | G26: 39052 | H26: 39083 | I26: 39114 | J26: 39142 | K26: 39173 | L26: 39203 | M26: 39234 | N26: Total | O26: 2006-2007 Price | P26: Price per search
A27: Ovid OLDMEDLINE
A28: Sessions | B28: 0 | C28: 9 | D28: 102 | E28: 152 | F28: 177 | G28: 76 | H28: 14 | I28: 0 | J28: 0 | K28: 0 | L28: 0 | M28: 0 | N28: =SUM(B28:M28) -> 530
A29: Searches | B29: 0 | C29: 54 | D29: 180 | E29: 399 | F29: 629 | G29: 332 | H29: 272 | I29: 0 | J29: 0 | K29: 0 | L29: 0 | M29: 0 | N29: =SUM(B29:M29) -> 1866 | O29: 0 | P29: N/A
A30: Turnaways | B30: 0 | C30: 0 | D30: 0 | E30: 0 | F30: 0 | G30: 0 | H30: 0 | I30: 0 | J30: 0 | K30: 0 | L30: 0 | M30: 0 | N30: =SUM(B30:M30) -> 0
B33: 38899 | C33: 38930 | D33: 38961 | E33: 38991 | F33: 39022 | G33: 39052 | H33: 39083 | I33: 39114 | J33: 39142 | K33: 39173 | L33: 39203 | M33: 39234 | N33: Total | O33: 2006-2007 Price | P33: Price per search
A34: Journals@Ovid Full Text
A35: Sessions | B35: 230 | C35: 166 | D35: 428 | E35: 698 | F35: 830 | G35: 339 | H35: 337 | I35: 748 | J35: 891 | K35: 905 | L35: 259 | M35: 301 | N35: =SUM(B35:M35) -> 6132
A36: Searches | B36: 133 | C36: 71 | D36: 203 | E36: 355 | F36: 385 | G36: 201 | H36: 165 | I36: 343 | J36: 452 | K36: 407 | L36: 178 | M36: 211 | N36: =SUM(B36:M36) -> 3104 | O36: 10226 | P36: =O36/N36 -> 3.2944588
A37: Turnaways | B37: 0 | C37: 0 | D37: 0 | E37: 0 | F37: 0 | G37: 0 | H37: 0 | I37: 0 | J37: 0 | K37: 0 | L37: 0 | M37: 0 | N37: =SUM(B37:M37) -> 0
B41: 38899 | C41: 38930 | D41: 38961 | E41: 38991 | F41: 39022 | G41: 39052 | H41: 39083 | I41: 39114 | J41: 39142 | K41: 39173 | L41: 39203 | M41: 39234 | N41: Total | O41: 2006-2007 Price | P41: Price per search
A42: All OVID Databases
A43: Sessions | B43: =B7+B14+B21+B28+B35 -> 233 | C43: =C7+C14+C21+C28+C35 -> 192 | D43: =D7+D14+D21+D28+D35 -> 742 | E43: =E7+E14+E21+E28+E35 -> 1158 | F43: =F7+F14+F21+F28+F35 -> 1363 | G43: =G7+G14+G21+G28+G35 -> 569 | H43: =H7+H14+H21+H28+H35 -> 463 | I43: =I7+I14+I21+I28+I35 -> 1109 | ... M43: =M7+M14+M21+M28+M35 -> 420 | N43: =SUM(B43:M43) -> 9526
A44: Searches | B44: =B8+B15+B22+B29+B36 -> 133 | C44: =C8+C15+C22+C29+C36 -> 234 | D44: =D8+D15+D22+D29+D36 -> 788 | E44: =E8+E15+E22+E29+E36 -> 1564 | F44: =F8+F15+F22+F29+F36 -> 2274 | G44: =G8+G15+G22+G29+G36 -> 1203 | H44: =H8+H15+H22+H29+H36 -> 1269 | I44: =I8+I15+I22+I29+I36 -> 1379 | ... M44: =M8+M15+M22+M29+M36 -> 993 | N44: =SUM(B44:M44) -> 15001 | O44: =SUM(O7:O37) -> 10226 | P44: =O44/N44 -> 0.68168789
A45: Turnaways | B45: 0 | C45: 0 | D45: 0 | E45: 0 | F45: 0 | G45: 0 | H45: 0 | I45: 0 | J45: 0 | K45: 0 | L45: 0 | M45: 0 | N45: =SUM(B45:M45) -> 0
A48: COUNTER-Compliant?: | B48: Yes

Sheet Oxford
A1: Oxford
A2: 2006-2007
B5: 38899 | C5: 38930 | D5: 38961 | E5: 38991 | F5: 39022 | G5: 39052 | H5: 39083 | I5: 39114 | J5: 39142 | K5: 39173 | L5: 39203 | M5: 39234 | N5: Total | O5: 2006-2007 Price | P5: Price per unit
A6: Grove Music Online
A7: Sessions | B7: 15 | C7: 17 | D7: 67 | E7: 60 | F7: 62 | G7: 38 | H7: 18 | I7: 28 | J7: 29 | K7: 62 | L7: 22 | M7: 12 | N7: =SUM(B7:M7) -> 430
A8: Searches | B8: 38 | C8: 49 | D8: 120 | E8: 114 | F8: 105 | G8: 64 | H8: 46 | I8: 56 | J8: 56 | K8: 143 | L8: 35 | M8: 24 | N8: =SUM(B8:M8) -> 850 | O8: 1437 | P8: =O8/N8 -> 1.6905882
A9: Turnaways | B9: 0 | C9: 0 | D9: 0 | E9: 4 | F9: 0 | G9: 0 | H9: 0 | I9: 0 | J9: 0 | K9: 0 | L9: 0 | M9: 0 | N9: =SUM(B9:M9) -> 4
A11: Oxford English Dictionary
A12: Sessions | B12: 135 | C12: 95 | D12: 478 | E12: 547 | F12: 592 | G12: 291 | H12: 463 | I12: 642 | J12: 402 | K12: 366 | L12: 267 | M12: 71 | N12: =SUM(B12:M12) -> 4349
A13: Searches | B13: 626 | C13: 295 | D13: 1648 | E13: 1489 | F13: 1197 | G13: 856 | H13: 1066 | I13: 2835 | J13: 1196 | K13: 1471 | L13: 899 | M13: 296 | N13: =SUM(B13:M13) -> 13874 | O13: 2364 | P13: =O13/N13 -> 0.17039066
A14: Turnaways | B14: 0 | C14: 0 | D14: 0 | E14: 0 | F14: 0 | G14: 0 | H14: 0 | I14: 0 | J14: 0 | K14: 0 | L14: 0 | M14: 0 | N14: =SUM(B14:M14) -> 0
A16: Treaties & International Agreements Online (Oceana)
A17: Sessions | B17: 0 | C17: 1 | D17: 4 | E17: 9 | F17: 1 | G17: 1 | H17: 0 | I17: 1 | J17: 3 | K17: 4 | L17: 1 | M17: 0 | N17: =SUM(B17:M17) -> 25 | O17: 1325 | P17: =O17/N17 -> 53
A18: Minutes | B18: 0 | C18: 14 | D18: 11 | E18: 83 | F18: 3 | G18: 1 | H18: 0 | I18: 1 | J18: 6 | K18: 4 | L18: 3 | M18: 0 | N18: =SUM(B18:M18) -> 126 | O18: 1325 | P18: =O18/N18 -> 10.515873
A19: Turnaways | B19: 0 | C19: 0 | D19: 0 | E19: 0 | F19: 0 | G19: 0 | H19: 0 | I19: 0 | J19: 0 | K19: 0 | L19: 0 | M19: 0 | N19: =SUM(B19:M19) -> 0
A23: COUNTER-Compliant?: | B23: No

Sheet ProQuest
A1: ProQuest databases
A2: 2006-2007
B4: 38899 | C4: 38930 | D4: 38961 | E4: 38991 | F4: 39022 | G4: 39052 | H4: 39083 | I4: 39114 | J4: 39142 | K4: 39173 | L4: 39203 | M4: 39234 | N4: Total | O4: 2006-2007 Price | P4: Price per search
A5: ABI/INFORM Global
A6: Searches | B6: 1935 | C6: 1231 | D6: 2407 | E6: 5291 | F6: 4571 | G6: 3165 | H6: 1844 | I6: 1661 | J6: 3415 | K6: 4113 | L6: 1593 | M6: 1128 | N6: =SUM(B6:M6) -> 32354 | O6: 17940 | P6: =O6/N6 -> 0.55449094
B9: 38899 | C9: 38930 | D9: 38961 | E9: 38991 | F9: 39022 | G9: 39052 | H9: 39083 | I9: 39114 | J9: 39142 | K9: 39173 | L9: 39203 | M9: 39234 | N9: Total | O9: 2006-2007 Price | P9: Price per search
A10: ABI/INFORM Trade & Industry
A11: Searches | B11: 1059 | C11: 617 | D11: 1102 | E11: 2503 | F11: 2245 | G11: 1751 | H11: 568 | I11: 736 | J11: 1621 | K11: 1729 | L11: 729 | M11: 514 | N11: =SUM(B11:M11) -> 15174 | O11: 0 | P11: N/A
B14: 38899 | C14: 38930 | D14: 38961 | E14: 38991 | F14: 39022 | G14: 39052 | H14: 39083 | I14: 39114 | J14: 39142 | K14: 39173 | L14: 39203 | M14: 39234 | N14: Total | O14: 2006-2007 Price | P14: Price per search
A15: ProQuest Dissertations & Theses
A16: Searches | B16: 999 | C16: 578 | D16: 874 | E16: 2212 | F16: 1817 | G16: 1690 | H16: 633 | I16: 961 | J16: 1828 | K16: 1719 | L16: 724 | M16: 580 | N16: =SUM(B16:M16) -> 14615 | O16: 5475 | P16: =O16/N16 -> 0.37461512
B19: 38899 | C19: 38930 | D19: 38961 | E19: 38991 | F19: 39022 | G19: 39052 | H19: 39083 | I19: 39114 | J19: 39142 | K19: 39173 | L19: 39203 | M19: 39234 | N19: Total | O19: 2006-2007 Price | P19: Price per search
A20: National Newspapers (5)
A21: Searches | B21: 1175 | C21: 630 | D21: 984 | E21: 2361 | F21: 2485 | G21: 1842 | H21: 583 | I21: 966 | J21: 1822 | K21: 2080 | L21: 704 | M21: 529 | N21: =SUM(B21:M21) -> 16161 | O21: 3071 | P21: =O21/N21 -> 0.19002537
B24: 38899 | C24: 38930 | D24: 38961 | E24: 38991 | F24: 39022 | G24: 39052 | H24: 39083 | I24: 39114 | J24: 39142 | K24: 39173 | L24: 39203 | M24: 39234 | N24: Total | O24: 2006-2007 Price | P24: Price per search
A25: Los Angeles Times
A26: Searches | B26: 980 | C26: 602 | D26: 907 | E26: 2047 | F26: 2176 | G26: 1654 | H26: 535 | I26: 964 | J26: 1486 | K26: 1555 | L26: 600 | M26: 453 | N26: =SUM(B26:M26) -> 13959 | O26: 0 | P26: N/A
B29: 38899 | C29: 38930 | D29: 38961 | E29: 38991 | F29: 39022 | G29: 39052 | H29: 39083 | I29: 39114 | J29: 39142 | K29: 39173 | L29: 39203 | M29: 39234 | N29: Total | O29: 2006-2007 Price | P29: Price per search
A30: Providence Journal-Bulletin
A31: Searches | B31: 1294 | C31: 653 | D31: 1027 | E31: 2253 | F31: 2446 | G31: 1878 | H31: 643 | I31: 832 | J31: 1671 | K31: 1774 | L31: 713 | M31: 580 | N31: =SUM(B31:M31) -> 15764 | O31: 1820 | P31: =O31/N31 -> 0.11545293
B34: 38899 | C34: 38930 | D34: 38961 | E34: 38991 | F34: 39022 | G34: 39052 | H34: 39083 | I34: 39114 | J34: 39142 | K34: 39173 | L34: 39203 | M34: 39234 | N34: Total | O34: 2006-2007 Price | P34: Price per search
A35: Wall Street Journal
A36: Searches | B36: 1020 | C36: 602 | D36: 925 | E36: 2050 | F36: 2185 | G36: 1665 | H36: 535 | I36: 694 | J36: 1491 | K36: 1564 | L36: 600 | M36: 459 | N36: =SUM(B36:M36) -> 13790 | O36: 0 | P36: N/A
B39: 38899 | C39: 38930 | D39: 38961 | E39: 38991 | F39: 39022 | G39: 39052 | H39: 39083 | I39: 39114 | J39: 39142 | K39: 39173 | L39: 39203 | M39: 39234 | N39: Total | O39: 2006-2007 Price | P39: Price per search
A40: ProQuest Historical Newspapers The New York Times (1851-2002)
A41: Searches | B41: 57 | C41: 7 | D41: 134 | E41: 237 | F41: 182 | G41: 54 | H41: 131 | I41: 88 | J41: 156 | K41: 438 | L41: 111 | M41: 8 | N41: =SUM(B41:M41) -> 1603 | O41: 0 | P41: N/A
B45: 38899 | C45: 38930 | D45: 38961 | E45: 38991 | F45: 39022 | G45: 39052 | H45: 39083 | I45: 39114 | J45: 39142 | K45: 39173 | L45: 39203 | M45: 39234 | N45: Total | O45: 2006-2007 Price | P45: Price per unit
A46: ProQuest (all databases)
A47: Sessions | B47: 854 | C47: 443 | D47: 1180 | E47: 2570 | F47: 2565 | G47: 1687 | H47: 818 | I47: 1927 | J47: 2371 | K47: 2708 | L47: 976 | M47: 738 | N47: =SUM(B47:M47) -> 18837
A48: Searches | B48: 2654 | C48: 1324 | D48: 3165 | E48: 6851 | F48: 6454 | G48: 4064 | H48: 2147 | I48: 4829 | J48: 5210 | K48: 5980 | L48: 2211 | M48: 1535 | N48: =SUM(B48:M48) -> 46424 | O48: =SUM(O6:O41) -> 28306 | P48: =O48/N48 -> 0.60972773
A49: Successful full-text downloads | B49: 2616 | C49: 1333 | D49: 2874 | E49: 5529 | F49: 5387 | G49: 3436 | H49: 2223 | I49: 3980 | J49: 4472 | K49: 6309 | L49: 2135 | M49: 1583 | N49: =SUM(B49:M49) -> 41877 | O49: =O48 -> 28306 | P49: =O49/N49 -> 0.6759319
A52: COUNTER-Compliant?: | B52: Yes

Sheet ReferenceUSA
A1: ReferenceUSA
A2: 2006-2007
B5: 38899 | C5: 38930 | D5: 38961 | E5: 38991 | F5: 39022 | G5: 39052 | H5: 39083 | I5: 39114 | J5: 39142 | K5: 39173 | L5: 39203 | M5: 39234 | N5: Total | O5: 2006-2007 Price | P5: Price per search
A6: Sessions | B6: 72 | C6: 55 | D6: 188 | E6: 176 | F6: 225 | G6: 95 | H6: 217 | I6: 209 | J6: 121 | K6: 112 | L6: 58 | M6: 80 | N6: =SUM(B6:M6) -> 1608
A7: Searches | B7: 361 | C7: 85 | D7: 361 | E7: 289 | F7: 692 | G7: 383 | H7: 673 | I7: 417 | J7: 157 | K7: 196 | L7: 180 | M7: 335 | N7: =SUM(B7:M7) -> 4129 | O7: 6120 | P7: =O7/N7 -> 1.4821991
A8: Residential Searches | B8: 21 | C8: 22 | D8: 45 | E8: 87 | F8: 269 | G8: 117 | H8: 59 | I8: 65 | J8: 15 | K8: 19 | L8: 11 | M8: 44 | N8: =SUM(B8:M8) -> 774
A9: Business Searches | B9: 340 | C9: 63 | D9: =312+4 -> 316 | E9: 202 | F9: 423 | G9: 266 | H9: 614 | I9: 352 | J9: 142 | K9: 177 | L9: 169 | M9: 291 | N9: =SUM(B9:M9) -> 3355
A12: COUNTER-Compliant?: | B12: No

Sheet RefWorks
A1: RefWorks (CSA)
A2: 2006-2007
B5: 38899 | C5: 38930 | D5: 38961 | E5: 38991 | F5: 39022 | G5: 39052 | H5: 39083 | I5: 39114 | J5: 39142 | K5: 39173 | L5: 39203 | M5: 39234 | N5: Total | O5: 2006-2007 Price | P5: Price per unit
A6: New Users | B6: 3 | C6: 7 | D6: 21 | E6: 16 | F6: 16 | G6: 7 | H6: 3 | I6: 98 | J6: 9 | K6: 21 | L6: 5 | M6: 6 | N6: =SUM(B6:M6) -> 212 | O6: 11025 | P6: =O6/N6 -> 52.004717
A7: Repeat Users | B7: 12 | C7: 4 | D7: 14 | E7: 25 | F7: 37 | G7: 27 | H7: 18 | I7: 33 | J7: 77 | K7: 69 | L7: 49 | M7: 16 | N7: =SUM(B7:M7) -> 381 | O7: 11025 | P7: =O7/N7 -> 28.937008
A8: Total Monthly Users | B8: 15 | C8: 11 | D8: 35 | E8: 41 | F8: 53 | G8: 34 | H8: 21 | I8: 131 | J8: 86 | K8: 90 | L8: 54 | M8: 22 | N8: =SUM(B8:M8) -> 593 | O8: 11025 | P8: =O8/N8 -> 18.591906 | Q8: per user
A9: Total Sessions per month | B9: 79 | C9: 25 | D9: 87 | E9: 161 | F9: 236 | G9: 187 | H9: 98 | I9: 351 | J9: 484 | K9: 589 | L9: 192 | M9: 128 | N9: =SUM(B9:M9) -> 2617 | O9: 11025 | P9: =O9/N9 -> 4.2128391 | Q9: per session
A10: Average Sessions Per User | B10: 5.27 | C10: 2.27 | D10: 2.49 | E10: 3.93 | F10: 4.45 | G10: 5.5 | H10: 4.67 | I10: 2.68 | J10: 5.63 | K10: 6.54 | L10: 3.56 | M10: 5.82 | N10: =SUM(B10:M10) -> 52.81 | O10: 11025 | P10: =O10/N10 -> 208.76728
A11: Total Subscriber References added | B11: 728 | C11: 136 | D11: 144 | E11: 740 | F11: 3492 | G11: 592 | H11: 174 | I11: 617 | J11: 1202 | K11: 1186 | L11: 581 | M11: 464 | N11: =SUM(B11:M11) -> 10056 | O11: 11025 | P11: =O11/N11 -> 1.0963604 | Q11: per reference added
A12: Average References added per user | B12: 48.53 | C12: 12.36 | D12: 4.11 | E12: 18.05 | F12: 65.89 | G12: 17.41 | H12: 8.29 | I12: 4.71 | J12: 13.98 | K12: 13.18 | L12: 10.76 | M12: 21.09 | N12: =SUM(B12:M12) -> 238.36 | O12: 11025 | P12: =O12/N12 -> 46.253566
A16: COUNTER-Compliant?: | B16: No

Sheet SciFinderScholar
A1: SciFinder Scholar
A2: 2006-2007
B5: 38899 | C5: 38930 | D5: 38961 | E5: 38991 | F5: 39022 | G5: 39052 | H5: 39083 | I5: 39114 | J5: 39142 | K5: 39173 | L5: 39203 | M5: 39234 | N5: Total | O5: 2006-2007 Price | P5: Price per search
A6: Sessions | B6: 242 | C6: 190 | D6: 241 | E6: 203 | F6: 185 | G6: 147 | H6: 186 | I6: 203 | J6: 229 | K6: 194 | L6: 181 | M6: 240 | N6: =SUM(B6:M6) -> 2441
A7: Searches | B7: 1029 | C7: 771 | D7: 783 | E7: 671 | F7: 917 | G7: 488 | H7: 586 | I7: 898 | J7: 764 | K7: 732 | L7: 753 | M7: 798 | N7: =SUM(B7:M7) -> 9190 | O7: 29485 | P7: =O7/N7 -> 3.2083787
A8: Turnaways | B8: 257 | C8: 124 | D8: 105 | E8: 56 | F8: 123 | G8: 52 | H8: 50 | I8: 148 | J8: 77 | K8: 124 | L8: 122 | M8: 126 | N8: =SUM(B8:M8) -> 1364
A9: Simultaneous users | B9: 1 | C9: 1 | D9: 1 | E9: 1 | F9: 1 | G9: 1 | H9: 1 | I9: 1 | J9: 1 | K9: 1 | L9: 1 | M9: 1
A12: COUNTER-Compliant?: | B12: No

Sheet Turfgrass InfoCtr
A1: Turfgrass Information Center
A2: 2006-2007
B5: 38899 | C5: 38930 | D5: 38961 | E5: 38991 | F5: 39022 | G5: 39052 | H5: 39083 | I5: 39114 | J5: 39142 | K5: 39173 | L5: 39203 | M5: 39234 | N5: Total | O5: 2006-2007 Price | P5: Price per search
A6: Displayed result sets (i.e. searches?) | B6: 0 | C6: 15 | D6: 25 | E6: 24 | F6: 58 | G6: 0 | H6: 4 | I6: 77 | J6: 32 | K6: 18 | L6: 12 | M6: 12 | N6: =SUM(B6:M6) -> 277 | O6: 0 | P6: N/A
A9: COUNTER-Compliant?: | B9: No

Sheet WebofScience
A1: Web of Science
A2: 2006-2007
B5: 38899 | C5: 38930 | D5: 38961 | E5: 38991 | F5: 39022 | G5: 39052 | H5: 39083 | I5: 39114 | J5: 39142 | K5: 39173 | L5: 39203 | M5: 39234 | N5: Total | O5: 2006-2007 Price | P5: Price per search
A6: Sessions | B6: 326 | C6: 266 | D6: 514 | E6: 670 | F6: 721 | G6: 510 | H6: 326 | I6: 500 | J6: 566 | K6: 579 | L6: 427 | M6: 487 | N6: =SUM(B6:M6) -> 5892
A7: Queries | B7: 949 | C7: 994 | D7: 1540 | E7: 2044 | F7: 2223 | G7: 1618 | H7: 1135 | I7: 2045 | J7: 2015 | K7: 2298 | L7: 1565 | M7: 2291 | N7: =SUM(B7:M7) -> 20717 | O7: 92892 | P7: =O7/N7 -> 4.4838538
A8: Maximum Contractual Users | B8: 5 | C8: 5 | D8: 5 | E8: 5 | F8: 5 | G8: 5 | H8: 5 | I8: 5 | J8: 5 | K8: 5 | L8: 5 | M8: 5
A9: Turnaways | B9: 0 | C9: 0 | D9: 34 | E9: 21 | F9: 6 | G9: 9 | H9: 0 | I9: 0 | J9: 0 | K9: 0 | L9: 0 | M9: 0 | N9: =SUM(B9:M9) -> 70
A12: COUNTER-Compliant?: | B12: No

Sheet WebSpirs
A1: WebSPIRS (OVID)
A2: 2006-2007
B5: 38899 | C5: 38930 | D5: 38961 | E5: 38991 | F5: 39022 | G5: 39052 | H5: 39083 | I5: 39114 | J5: 39142 | K5: 39173 | L5: 39203 | M5: 39234 | N5: Total | O5: 2006-2007 Price | P5: Price per unit
A6: Biological Abstracts
A7: Sessions | B7: 43 | C7: 58 | D7: 148 | E7: 269 | F7: 259 | G7: 85 | H7: 81 | I7: 252 | J7: 282 | K7: 251 | L7: 89 | M7: 28 | N7: =SUM(B7:M7) -> 1845
A8: Searches | B8: 229 | C8: 384 | D8: 556 | E8: 716 | F8: 836 | G8: 234 | H8: 313 | I8: 859 | J8: 1033 | K8: 742 | L8: 383 | M8: 192 | N8: =SUM(B8:M8) -> 6477 | O8: 23244 | P8: =O8/N8 -> 3.5886985
A9: Turnaways | B9: 0 | C9: 0 | D9: 0 | E9: 0 | F9: 0 | G9: 0 | H9: 0 | I9: 0 | J9: 0 | K9: 0 | L9: 0 | M9: 0 | N9: =SUM(B9:M9) -> 0
A12: COUNTER-Compliant?: | B12: Yes

Sheet WilsonWeb
A1: WilsonWeb
A2: 2006-2007
B5: 38899 | C5: 38930 | D5: 38961 | E5: 38991 | F5: 39022 | G5: 39052 | H5: 39083 | I5: 39114 | J5: 39142 | K5: 39173 | L5: 39203 | M5: 39234 | N5: Total | O5: 2006-2007 price | P5: Price per search
A6: Art Abstracts
A7: Sessions | B7: 34 | C7: 11 | D7: 52 | E7: 122 | F7: 150 | G7: 68 | H7: 34 | I7: 156 | J7: 195 | K7: 112 | L7: 16 | M7: 29 | N7: =SUM(B7:M7) -> 979 | O7: 5535
A8: Searches | B8: 144 | C8: 43 | D8: 159 | E8: 468 | F8: 629 | G8: 223 | H8: 127 | I8: 409 | J8: 420 | K8: 395 | L8: 24 | M8: 88 | N8: =SUM(B8:M8) -> 3129 | O8: 5535 | P8: =O8/N8 -> 1.7689358
A9: Turnaways | B9: 0 | C9: 0 | D9: 0 | E9: 0 | F9: 0 | G9: 0 | H9: 0 | I9: 0 | J9: 0 | K9: 0 | L9: 0 | M9: 0 | N9: =SUM(B9:M9) -> 0
A11: Biological & Agricultural Index Plus
A12: Sessions | B12: 31 | C12: 14 | D12: 48 | E12: 76 | F12: 71 | G12: 75 | H12: 6 | I12: 48 | J12: 82 | K12: 63 | L12: 6 | M12: 16 | N12: =SUM(B12:M12) -> 536 | O12: 3213
A13: Searches | B13: 122 | C13: 43 | D13: 141 | E13: 151 | F13: 144 | G13: 22 | H13: 16 | I13: 114 | J13: 208 | K13: 195 | L13: 14 | M13: 39 | N13: =SUM(B13:M13) -> 1209 | O13: 3213 | P13: =O13/N13 -> 2.6575682
A14: Turnaways | B14: 0 | C14: 0 | D14: 16 | E14: 7 | F14: 25 | G14: 0 | H14: 0 | I14: 0 | J14: 0 | K14: 0 | L14: 0 | M14: 0 | N14: =SUM(B14:M14) -> 48
A16: Readers Guide Retrospective
A17: Sessions | B17: 18 | C17: 5 | D17: 18 | E17: 84 | F17: 54 | G17: 18 | H17: 4 | I17: 56 | J17: 78 | K17: 17 | L17: 4 | M17: 20 | N17: =SUM(B17:M17) -> 376 | O17: 326
A18: Searches | B18: 81 | C18: 27 | D18: 96 | E18: 334 | F18: 179 | G18: 59 | H18: 6 | I18: 141 | J18: 112 | K18: 44 | L18: 7 | M18: 39 | N18: =SUM(B18:M18) -> 1125 | O18: 326 | P18: =O18/N18 -> 0.28977778
A19: Turnaways | B19: 0 | C19: 0 | D19: 0 | E19: 0 | F19: 0 | G19: 0 | H19: 0 | I19: 0 | J19: 0 | K19: 0 | L19: 0 | M19: 0 | N19: =SUM(B19:M19) -> 0
A23: COUNTER-Compliant?: | B23: Yes
