Workbook

Sheet Legend
A2: Legend
D3: Local
D5: State
D7: Federal
D9: Other
D11: Indeterminate
A14: Source | B14: Ohio Department of Education
A16: All files are "read only" and based on data collections from the Ohio Department of Education.
A17: The conclusions reached in this document are those of the author(s) and do not necessarily represent those
A18: of Ball State University.

Sheet Figure 1,2,4
A1: Figure 1 | K1: Figure 2
A2: Ohio (2006-07) | B2: Statewide | D2: Statewide Weighted for Charter Enrollment | F2: Cleveland | H2: Dayton | L2: District | M2: Charter | N2: Difference
A3: Per-Pupil Revenue | K3: State | L3: =B4 -> 9778.6384 | M3: =B5 -> 8190.0097 | N3: =B6 -> 1588.6287
A4: District | B4: =B14 -> 9778.6384 | D4: 10421 | F4: =F14 -> 13016.3 | H4: =H14 -> 13120.806 | K4: Statewide Weighted | L4: =D4 -> 10421 | M4: =D5 -> 8190 | N4: =D6 -> 2231
A5: Charter | B5: =C14 -> 8190.0097 | D5: 8190 | F5: =G14 -> 8931.2491 | H5: =I14 -> 8585.2898 | K5: =F2 -> Cleveland | L5: =F4 -> 13016.3 | M5: =F5 -> 8931.2491 | N5: =F6 -> 4085.0504
A6: Difference | B6: =B4-B5 -> 1588.6287 | D6: 2231 | F6: =F4-F5 -> 4085.0504 | H6: =H4-H5 -> 4535.5164 | K6: =H2 -> Dayton | L6: =H4 -> 13120.806 | M6: =H5 -> 8585.2898 | N6: =H6 -> 4535.5164
B7: =B6/B4 -> 0.16245909 | D7: 0.214 | F7: =F6/F4 -> 0.31384115 | H7: =H6/H4 -> 0.34567361
A8: Per-Pupil Revenue by Source | B8: District | C8: Charter | D8: District | E8: Charter | F8: District | G8: Charter | H8: District | I8: Charter
A9: Federal | B9: ='District Work'!I621/'Figure 1,2,4'!B16:C16 -> 760.30396 | C9: ='Charter Work'!O305 -> 923.29365 | D9: 1046 | E9: =C9 -> 923.29365 | F9: ='District Work'!G37/'Figure 1,2,4'!F16:G16 -> 2290.4939 | G9: ='Charter Work'!O43 -> 1206.8672 | H9: ='District Work'!G43/'Figure 1,2,4'!H16:I16 -> 2128.5719 | I9: ='Charter Work'!O72 -> 812.49115
A10: State | B10: ='District Work'!I1859/'Figure 1,2,4'!B16:C16 -> 4096.8848 | C10: ='Charter Work'!O911 -> 6991.1826 | D10: 4531 | E10: =C10 -> 6991.1826 | F10: ='District Work'!G1275/'Figure 1,2,4'!F16:G16 -> 6686.7822 | G10: ='Charter Work'!O649 -> 7463.7203 | H10: ='District Work'!G1281/'Figure 1,2,4'!H16:I16 -> 5811.1328 | I10: ='Charter Work'!O678 -> 7237.395
A11: Local | B11: ='District Work'!I1240/'Figure 1,2,4'!B16:C16 -> 4921.4497 | C11: 0 | D11: 4843 | E11: =C11 -> 0 | F11: ='District Work'!G656/'Figure 1,2,4'!F16:G16 -> 4039.0234 | G11: 0 | H11: ='District Work'!G662/'Figure 1,2,4'!H16:I16 -> 5181.1015 | I11: 0
A12: Other | B12: 0 | C12: ='Charter Work'!P608 -> 275.5334 | D12: - | E12: =C12 -> 275.5334 | F12: 0 | G12: ='Charter Work'!P346 -> 260.66165 | H12: 0 | I12: ='Charter Work'!P375 -> 535.40364
A13: Indeterminate | B13: 0 | C13: 0 | D13: - | E13: =C13 -> 0 | F13: 0 | G13: 0 | H13: 0 | I13: 0
A14: Total | B14: =SUM(B9:B13) -> 9778.6384 | C14: =SUM(C9:C13) -> 8190.0097 | D14: =D4 -> 10421 | E14: =C14 -> 8190.0097 | F14: =SUM(F9:F13) -> 13016.3 | G14: =SUM(G9:G13) -> 8931.2491 | H14: =SUM(H9:H13) -> 13120.806 | I14: =SUM(I9:I13) -> 8585.2898
A15: Enrollment
A16: District | B16: 1726715 | D16: n/a | F16: 54617 | H16: 15887
B17: =B16/(B16+B18) -> 0.9580986 | D17: n/a | F17: =F16/(F16+F18) -> 0.83953824 | H17: =H16/(H16+H18) -> 0.69952886
A18: Charter | B18: ='Charter Work'!N911 -> 75516 | D18: n/a | F18: ='Charter Work'!O346 -> 10439 | H18: ='Charter Work'!O375 -> 6824
B19: =B18/(B16+B18) -> 0.041901399 | D19: n/a | F19: =F18/(F16+F18) -> 0.16046176 | H19: =H18/(H16+H18) -> 0.30047114
A20: Number of Charters | B20: 303 | D20: n/a | F20: 41 | H20: 29
A21: Total Revenue
A22: District | B22: ='District Work'!I621+'District Work'!I1240+'District Work'!I1859 -> 1.6884922e+10 | D22: n/a | F22: ='District Work'!G37+'District Work'!G656+'District Work'!G1275 -> 7.1091123e+08 | H22: ='District Work'!G1281+'District Work'!G662+'District Work'!G43 -> 2.0845025e+08
B23: =B22/B26 -> 0.96466533 | D23: n/a | F23: =F22/F26 -> 0.88405902 | H23: =H22/H26 -> 0.78060651
A24: Charter | B24: ='Charter Work'!M305+'Charter Work'!N608+'Charter Work'!M911 -> 6.1847677e+08 | D24: n/a | F24: ='Charter Work'!M43+'Charter Work'!N346+'Charter Work'!M649 -> 93233310 | H24: ='Charter Work'!M678+'Charter Work'!N375+'Charter Work'!M72 -> 58586018
B25: =B24/B26 -> 0.035334668 | D25: n/a | F25: =F24/F26 -> 0.11594098 | H25: =H24/H26 -> 0.21939349
A26: Total | B26: =B22+B24 -> 1.7503398e+10 | D26: n/a | F26: =F22+F24 -> 8.0414454e+08 | H26: =H22+H24 -> 2.6703627e+08
A27: Percentage of Revenue by Source | B27: District | C27: Charter | D27: District | E27: Charter | F27: District | G27: Charter | H27: District | I27: Charter | K27: Figure 4
A28: Federal | B28: =B9/B14 -> 0.077751515 | C28: =C9/C14 -> 0.11273413 | D28: =D9/D$14 -> 0.10037424 | E28: =C28 -> 0.11273413 | F28: =F9/F14 -> 0.17597121 | G28: =G9/G14 -> 0.1351286 | H28: =H9/H14 -> 0.16222875 | I28: =I9/I14 -> 0.094637592 | L28: Federal | M28: State | N28: Local | O28: Other | P28: Indeterminate
A29: State | B29: =B10/B14 -> 0.41896271 | C29: =C10/C14 -> 0.85362324 | D29: =D10/D$14 -> 0.43479513 | E29: =C29 -> 0.85362324 | F29: =F10/F14 -> 0.51372375 | G29: =G10/G14 -> 0.83568604 | H29: =H10/H14 -> 0.44289449 | I29: =I10/I14 -> 0.8429995 | K29: Statewide District | L29: =B9 -> 760.30396 | M29: =B10 -> 4096.8848 | N29: =B11 -> 4921.4497 | O29: =B12 -> 0 | P29: =B13 -> 0
A30: Local | B30: =B11/B14 -> 0.50328578 | C30: =C11/C14 -> 0 | D30: =D11/D$14 -> 0.46473467 | E30: =C30 -> 0 | F30: =F11/F14 -> 0.31030504 | G30: =G11/G14 -> 0 | H30: =H11/H14 -> 0.39487677 | I30: =I11/I14 -> 0 | K30: Statewide Charter | L30: =C9 -> 923.29365 | M30: =C10 -> 6991.1826 | N30: =C11 -> 0 | O30: =C12 -> 275.5334 | P30: =C13 -> 0
A31: Other | B31: =B12/B14 -> 0 | C31: =C12/C14 -> 0.033642622 | D31: 0 | E31: =C31 -> 0.033642622 | F31: =F12/F14 -> 0 | G31: =G12/G14 -> 0.029185352 | H31: =H12/H14 -> 0 | I31: =I12/I14 -> 0.062362909 | K31: Statewide Weighted | L31: =D9 -> 1046 | M31: =D10 -> 4531 | N31: =D11 -> 4843 | O31: =D12 -> - | P31: =D13 -> -
A32: Change in district school funding if subjected to charter funding structure | K32: Cleveland District | L32: =F9 -> 2290.4939 | M32: =F10 -> 6686.7822 | N32: =F11 -> 4039.0234 | O32: =F12 -> 0 | P32: =F13 -> 0
B33: ($2.5 billion) | F33: ($214.9 million) | H33: ($64.3 million) | K33: Cleveland Charter | L33: =G9 -> 1206.8672 | M33: =G10 -> 7463.7203 | N33: =G11 -> 0 | O33: =G12 -> 260.66165 | P33: =G13 -> 0
B34: =B6*B16 -> 2.7431091e+09 | F34: =F6*F16 -> 2.231132e+08 | H34: =H6*H16 -> 72055750 | K34: Dayton District | L34: =H9 -> 2128.5719 | M34: =H10 -> 5811.1328 | N34: =H11 -> 5181.1015 | O34: =H12 -> 0 | P34: =H13 -> 0
A35: Removed Promise Academy from the analysis - dollars but no pupils | K35: Dayton Charter | L35: =I9 -> 812.49115 | M35: =I10 -> 7237.395 | N35: =I11 -> 0 | O35: =I12 -> 535.40364 | P35: =I13 -> 0
A36: Conversion charters included in analysis include state funds only

Sheet Figure 3
A1: State Charter School Policies
A2: Figure 3
A3: State Policies | B3: Yes | C3: No | D3: Partial
A4: Charter schools received their funding directly from the state | B4: X
A5: Charter schools are eligible for local funding | C5: X
A6: Cap on funding a charter school can receive | D6: 1
A7: District public school receive differential funding (e.g. more funding for 9-12 vs. K-8 schools) | B7: 2
A8: Charter schools receive differential funding | B8: 3
A9: State allows districts to withhold funding from charter schools for providing adminstrative services | B9: 4
A10: State "holds harmless" ditrict funding for charter enrollment | C10: X
A11: School is considered LEA if authorized by non-district organization | B11: X
A12: School is considered LEA if authorized by district | B12: X
A13: Cap on number of charter schools | B13: 5
A14: Cap on number of charters schools authorized per year | C14: X
A15: Cap on number of studens attending charter schools | C15: X
A16: Charter schools have an open enrollment policy | B16: 6
A19: 1. Internet- or computer-based Community Schools receive only the formula amount and the special education weighted amount
A20: 2. The amount of state funds available to a school is based on a number of variables, including a cost-of-doing business factor for a community, six special education factors, and a Disadvantaged Pupil Impact Aid (DPIA) adjustment factor. Schools receive one-half the funding for kindergarten students.
A21: 3. See two above
A22: 4. The state allows sponsors to charge up to a 3 percent admnistrative fee (of per-pupil funding) to provide sponsorship. Sponsors may also sell additional services to schools.
A23: 5. Ohio law allows 30 start-up charters authorized by non-district entities and 30 start-up charters authorized by districts above the number open as of May 5, 2005. Operators of charter schools with a track record of success are not subject to these restrictions, though. Ohio law also has a moratorium in place on new virtual schools.
A24: 6, There are three open enrollment policies in Ohio. Two are concerned with intradistrict transfers which allow students in low-performing schools to attend different schools within the school district. The third is an interdistrict (voluntary) policy which requires districts to determine whether they will admint nonresident students. "E-schools" are a good example of schools operating under the state's open enrollment policies.

Sheet Figure 5
A1: Figure 5: School Characteristics
C2: Statewide District | D2: Statewide Charter
A3: Percentage of stuents eligible for free or reduced price lunch | C3: 0.334 | D3: 0.432
A4: Percentage of schools eligible for Title 1 | C4: 0.683 | D4: 0.795
A5: Percent of students by school type
B6: Primary (K-5) | C6: 0.45 | D6: 0.426
B7: Middle (6-8) | C7: 0.2 | D7: 0.03
B8: High (9-12) | C8: 0.311 | D8: 0.152
B9: Other (K-12,K-8, etc.) | C9: 0.039 | D9: 0.392

Sheet Figure 6
A1: Figure 6: State Scorecard
B2: Findings | C2: Ohio | E2: Use the following options only
A3: Federal Funding | B3: Charters have access to federal funds according to state statutes (Yes = black, No = white)* | C3: Y | E3: Y
B4: Charters have full access to federal funds in practice (Yes = black, Partial = grey, No = white) | C4: P | E4: P
B5: Percentage of federal revenue equals percentage of total enrollment for charter schools (Yes = black, No = white) | C5: < | E5: N
A6: State Funding | B6: Charters have access to state funds according to state statutes (Yes = black, No = white) | C6: Y
B7: Charters have full access to state funds in practice (Yes = black, Partial = grey, No = white) | C7: Y
B8: Percentage of state revenue equals percentage of total enrollment for charter schools (Yes = black, No = white) | C8: >
A9: Local Funding | B9: Charters have access to local funds according to state statutes (Yes = black, No = white) | C9: N
B10: Charters have full access to local funds in practice (Yes = black, Partial = grey, No = white) | C10: N
B11: Percentage of local revenue equals percentage of total enrollment for charter schools (Yes = black, No = white) | C11: N
A12: Facilities Funding | B12: Charters have access to facilities funds according to state statutes (Yes = black, No = white) | C12: N
B13: Charters have full access to facilities funds in practice (Yes = black, Partial = grey, No = white) | C13: N
B14: Percentage of facilities revenue equals percentage of total enrollment for charter schools (Yes = black, No = white) | C14: N
A15: Data Availability | B15: State provides detailed, public data on federal, state, local and other revenues for district schools (Yes = black, Partial = grey, No = white) | C15: Y
B16: State provides detailed, public data on federal, state, local and other revenues for charter schools (Yes = black, Partial = grey, No = white) | C16: Y
A17: Funding Formula | B17: Charters are treated as LEAs for funding purposes (Yes = black, Partial = grey, No = white) | C17: Y
B18: State funds student (black) or the LEA (grey) | C18: S | E18: S | F18: L | H18: Use these options for the query to the left only (B18)
B19: State funding formula is fair and equitable (Yes = black, No = white | C19: N
A21: * For this finding, No could indicate that the statue is silent or that it denies access.

Sheet District Work
D1: School Year | H1: Charter | K1: County | L1: City | M1: Enrollment
A2: District | C2: Revenue Source | G2: Note: charter revenues are separate and distinct from district revenues. Do not need to back out charter financial eata from the district files as previously told.
A3: 000442 | B3: Manchester Local | C3: Federal Revenue | E3: 13272749 | F3: 0.080527445 | G3: 1068820.6 | H3: District
A4: 000777 | B4: Educational Academy at Linden | C4: Federal Revenue | E4: 204904.7 | F4: 0.73204763 | G4: 150000 | H4: District
A5: 000779 | B5: Educational Academy for Boys & Girls | C5: Federal Revenue | E5: 205403.19 | F5: 0.73027103 | G5: 150000 | H5: District
A6: 000780 | B6: Midnimo Cross Cultural Community School | C6: Federal Revenue | E6: 204907.09 | F6: 0.73203909 | G6: 150000 | H6: District
A7: 043489 | B7: Akron City | C7: Federal Revenue | E7: 3.0791105e+08 | F7: 0.10622273 | G7: 32707152 | H7: District
A8: 043497 | B8: Alliance City | C8: Federal Revenue | E8: 30321614 | F8: 0.13201312 | G8: 4002850.9 | H8: District
A9: 043505 | B9: Ashland City | C9: Federal Revenue | E9: 32742400 | F9: 0.06537838 | G9: 2140645.1 | H9: District
A10: 043513 | B10: Ashtabula Area City | C10: Federal Revenue | E10: 40237485 | F10: 0.1186019 | G10: 4772242.3 | H10: District
A11: 043521 | B11: Athens City | C11: Federal Revenue | E11: 29275566 | F11: 0.076152325 | G11: 2229402.4 | H11: District
A12: 043539 | B12: Barberton City | C12: Federal Revenue | E12: 42958716 | F12: 0.12623936 | G12: 5423080.8 | H12: District
A13: 043547 | B13: Bay Village City | C13: Federal Revenue | E13: 26540939 | F13: 0.037347591 | G13: 991240.16 | H13: District
A14: 043554 | B14: Beachwood City | C14: Federal Revenue | E14: 32237839 | F14: 0.017102645 | G14: 551352.32 | H14: District
... A36: 043778 | B36: Claymont City | C36: Federal Revenue | E36: 18569454 | F36: 0.093773747 | G36: 1741327.3 | H36: District
A37: 043786 | B37: Cleveland Metropolitan City | C37: Federal Revenue | E37: 7.1149149e+08 | F37: 0.17582769 | G37: 1.2509991e+08 | H37: District | L37: Cleveland
A38: 043794 | B38: Cleveland Heights-University Heights City | C38: Federal Revenue | E38: 98409787 | F38: 0.059000842 | G38: 5806260.3 | H38: District
A39: 043802 | B39: Columbus City | C39: Federal Revenue | E39: 6.9664072e+08 | F39: 0.13690076 | G39: 95370641 | H39: District
A40: 043810 | B40: Conneaut Area City | C40: Federal Revenue | E40: 19640706 | F40: 0.1399862 | G40: 2749427.8 | H40: District
A41: 043828 | B41: Coshocton City | C41: Federal Revenue | E41: 16690162 | F41: 0.090898725 | G41: 1517114.4 | H41: District
A42: 043836 | B42: Cuyahoga Falls City | C42: Federal Revenue | E42: 46276612 | F42: 0.023525594 | G42: 1088684.8 | H42: District
A43: 043844 | B43: Dayton City | C43: Federal Revenue | E43: 2.0902574e+08 | F43: 0.16178209 | G43: 33816622 | H43: District | L43: Dayton
A44: 043851 | B44: Deer Park Community City | C44: Federal Revenue | E44: 14444274 | F44: 0.036445204 | G44: 526424.51 | H44: District
A45: 043869 | B45: Defiance City | C45: Federal Revenue | E45: 22578645 | F45: 0.073589053 | G45: 1661541.1 | H45: District
A46: 043877 | B46: Delaware City | C46: Federal Revenue | E46: 40689417 | F46: 0.059497552 | G46: 2420920.7 | H46: District
A47: 043885 | B47: Delphos City | C47: Federal Revenue | E47: 9189823.3 | F47: 0.071652724 | G47: 658475.87 | H47: District
A48: 043893 | B48: Dover City | C48: Federal Revenue | E48: 20473084 | F48: 0.064359535 | G48: 1317638.2 | H48: District
A49: 043901 | B49: East Cleveland City | C49: Federal Revenue | E49: 57785809 | F49: 0.1613687 | G49: 9324821 | H49: District
A50: 043919 | B50: East Liverpool City | C50: Federal Revenue | E50: 25065119 | F50: 0.12549031 | G50: 3145429.6 | H50: District
A51: 043927 | B51: East Palestine City | C51: Federal Revenue | E51: 10582409 | F51: 0.092790759 | G51: 981949.75 | H51: District
A52: 043935 | B52: Eaton Community City | C52: Federal Revenue | E52: 19925241 | F52: 0.054123953 | G52: 1078432.8 | H52: District
A53: 043943 | B53: Elyria City | C53: Federal Revenue | E53: 76055634 | F53: 0.097685357 | G53: 7429521.8 | H53: District
A54: 043950 | B54: Euclid City | C54: Federal Revenue | E54: 75583917 | F54: 0.071132661 | G54: 5376485.2 | H54: District
A55: 043968 | B55: Fairborn City | C55: Federal Revenue | E55: 40189558 | F55: 0.11816503 | G55: 4749000.3 | H55: District
... A619: 069682 | B619: East Guernsey Local | C619: Federal Revenue | E619: 10656779 | F619: 0.10113438 | G619: 1077766.8 | H619: District
A620: 091397 | B620: Tri-County North Local | C620: Federal Revenue | E620: 9036139.3 | F620: 0.053997937 | G620: 487932.88 | H620: District | I620: Total Statewide Federal
A621: 139303 | B621: Monroe Local | C621: Federal Revenue | E621: 15517674 | F621: 0.046199512 | G621: 716908.97 | H621: District | I621: =SUM(G3:G621) -> 1.3128282e+09
A622: 000442 | B622: Manchester Local | C622: Local Revenue | E622: 13272749 | F622: 0.46772579 | G622: 6208007.2 | H622: District
A623: 000777 | B623: Educational Academy at Linden | C623: Local Revenue | E623: 204904.7 | F623: 0 | G623: 0 | H623: District
A624: 000779 | B624: Educational Academy for Boys & Girls | C624: Local Revenue | E624: 205403.19 | F624: 0 | G624: 0 | H624: District
...

Sheet Charter Work
D1: School Year | H1: Charter | K1: County | L1: City | M1: Enrollment
D2: Metrics | E2: Total Revenue Amount | F2: Revenue Source Pct of Total | G2: Use This Amount | H2: Charter | I2: Conversion | J2: Conversion District | K2: County | L2: City
A3: 000195 | B3: Hope Academy East Campus | C3: Federal Revenue | E3: 3429982.1 | F3: 0.12923064 | G3: 443258.8 | H3: C | K3: Cuyahoga | L3: Cleveland
A4: 000316 | B4: Westpark Community Middle School | C4: Federal Revenue | E4: 865196.41 | F4: 0.27563059 | G4: 238474.6 | H4: C | K4: Cuyahoga | L4: Cleveland
A5: 000319 | B5: Madison Community School | C5: Federal Revenue | E5: 1490755.8 | F5: 0.25866492 | G5: 385606.23 | H5: C | K5: Cuyahoga | L5: Cleveland
A6: 000321 | B6: Old Brooklyn Community Middle School | C6: Federal Revenue | E6: 802536.76 | F6: 0.24571617 | G6: 197196.26 | H6: C | K6: Cuyahoga | L6: Cleveland
A7: 000418 | B7: Greater Heights Academy | C7: Federal Revenue | E7: 7954976.9 | F7: 0.099349158 | G7: 790320.26 | H7: C | K7: Cuyahoga | L7: Cleveland
A8: 000527 | B8: Cleveland Academy for Scholarship Technology and Leadership | C8: Federal Revenue | E8: 2445648.9 | F8: 0.14109789 | G8: 345075.9 | H8: C | K8: Cuyahoga | L8: Cleveland
A9: 000534 | B9: Puritas Community Middle School | C9: Federal Revenue | E9: 479588.19 | F9: 0.47182254 | G9: 226280.52 | H9: C | K9: Cuyahoga | L9: Cleveland
A10: 000541 | B10: Outreach Academy for Children with Disabilities | C10: Federal Revenue | E10: 1689005 | F10: 0.17761937 | G10: 300000 | H10: C | K10: Cuyahoga | L10: Cleveland
A11: 000564 | B11: Virtual Schoolhouse, Inc. | C11: Federal Revenue | E11: 8436970.5 | F11: 0.0521787 | G11: 440230.15 | H11: C | K11: Cuyahoga | L11: Cleveland
A12: 000575 | B12: Hope Academy Northwest Campus | C12: Federal Revenue | E12: 3233072.7 | F12: 0.23784172 | G12: 768959.57 | H12: C | K12: Cuyahoga | L12: Cleveland
A13: 000736 | B13: Phoenix Village Academy Primary 2 | C13: Federal Revenue | E13: 492036.1 | F13: 0.55779653 | G13: 274456.03 | H13: C | K13: Cuyahoga | L13: Cleveland
A14: 000738 | B14: Phoenix Village Academy: Secondary I | C14: Federal Revenue | E14: 393282.73 | F14: 0.57372918 | G14: 225637.78 | H14: C | K14: Cuyahoga | L14: Cleveland
... A39: 143313 | B39: Hope Academy Cuyahoga Campus | C39: Federal Revenue | E39: 4017568.6 | F39: 0.11595871 | G39: 465872.06 | H39: C | K39: Cuyahoga | L39: Cleveland
A40: 143446 | B40: Greater Achievement Community School | C40: Federal Revenue | E40: 0 | F40: -- | G40: 0 | H40: C | K40: Cuyahoga | L40: Cleveland
A41: 143479 | B41: Puritas Community School | C41: Federal Revenue | E41: 1458765.4 | F41: 0.097114022 | G41: 141666.58 | H41: C | K41: Cuyahoga | L41: Cleveland
A42: 151183 | B42: Life Skills Ctr Of Lake Erie | C42: Federal Revenue | E42: 3568958.2 | F42: 0.082010822 | G42: 292693.2 | H42: C | K42: Cuyahoga | L42: Cleveland | M42: Cleveland Charter Totals - Federal
A43: 151209 | B43: Life Skills Of Northeast Ohio | C43: Federal Revenue | E43: 2709131.3 | F43: 0.050943626 | G43: 138012.97 | H43: C | K43: Cuyahoga | L43: Cleveland | M43: =SUM(G3:G43) -> 12598487 | N43: =SUM(M306:M346) -> 10439 | O43: =M43/N43 -> 1206.8672
A44: 000138 | B44: Pathway School of Discovery | C44: Federal Revenue | E44: 0 | F44: -- | H44: C | K44: Montgomery | L44: Dayton
A45: 000297 | B45: Summit Academy Dayton | C45: Federal Revenue | E45: 1407836.6 | F45: 0.059684456 | G45: 84025.96 | H45: C | K45: Montgomery | L45: Dayton
A46: 000427 | B46: Arise Academy | C46: Federal Revenue | E46: 1470515.3 | F46: 0.12967294 | G46: 190686.04 | H46: C | K46: Montgomery | L46: Dayton
A47: 000445 | B47: General Chappie James Leadership Academy | C47: Federal Revenue | E47: 833238.87 | F47: 0.33702075 | G47: 280818.79 | H47: C | K47: Montgomery | L47: Dayton
A48: 000496 | B48: Peterson Entrepreneurial Training Enterprise | C48: Federal Revenue | E48: 1451418.6 | F48: 0.15931945 | G48: 231239.22 | H48: C | K48: Montgomery | L48: Dayton
A49: 000577 | B49: Emerson Academy | C49: Federal Revenue | E49: 0 | F49: -- | G49: 0 | H49: C | K49: Montgomery | L49: Dayton
A50: 000700 | B50: New City School | C50: Federal Revenue | E50: 892186 | F50: 0.41266642 | G50: 368175.2 | H50: C | K50: Montgomery | L50: Dayton
A51: 000808 | B51: Horizon Science Academy-Dayton | C51: Federal Revenue | E51: 1443280.7 | F51: 0.16938231 | G51: 244466.21 | H51: C | K51: Montgomery | L51: Dayton
A52: 000813 | B52: Life Skills Center of Dayton | C52: Federal Revenue | E52: 2707072 | F52: 0.1170392 | G52: 316833.55 | H52: C | K52: Montgomery | L52: Dayton
A53: 000922 | B53: Nu Bethel Center of Excellence | C53: Federal Revenue | E53: 377292.94 | F53: 0.085992253 | G53: 32444.27 | H53: C | K53: Montgomery | L53: Dayton
A54: 008283 | B54: Dayton Technology Design High School | C54: Federal Revenue | E54: 853109.34 | F54: 0.0066539771 | G54: 5676.57 | H54: C | I54: Yes | J54: Dayton | K54: Montgomery | L54: Dayton
A55: 132738 | B55: Colin Powell Leadership Acad | C55: Federal Revenue | E55: 2171897.7 | F55: 0.22343486 | G55: 485277.67 | H55: C | K55: Montgomery | L55: Dayton
A56: 132944 | B56: Miami Valley Academies | C56: Federal Revenue | E56: 1320416 | F56: 0.1027145 | G56: 135625.86 | H56: c | K56: Montgomery | L56: Dayton
A57: 133348 | B57: Richard Allen Preparatory | C57: Federal Revenue | E57: 673623.24 | F57: 0.10794035 | G57: 72711.13 | H57: C | K57: Montgomery | L57: Dayton
A58: 133371 | B58: Omega School Of Excellence | C58: Federal Revenue | E58: 924919.7 | F58: 0.18841253 | G58: 174266.46 | H58: C | K58: Montgomery | L58: Dayton
A59: 133454 | B59: Dayton View Academy | C59: Federal Revenue | E59: 4930062 | F59: 0.11867513 | G59: 585075.72 | H59: C | K59: Montgomery | L59: Dayton
A60: 133736 | B60: Richard Allen Academy | C60: Federal Revenue | E60: 1404805.4 | F60: 0.084365023 | G60: 118516.44 | H60: C | K60: Montgomery | L60: Dayton
A61: 133744 | B61: The ISUS Institute of Construction Technology | C61: Federal Revenue | E61: 4376265 | F61: 0.066322867 | G61: 290246.44 | H61: c | K61: Montgomery | L61: Dayton
A62: 133769 | B62: New Choices Community School | C62: Federal Revenue | E62: 2165529.9 | F62: 0 | G62: 0 | H62: C | K62: Montgomery | L62: Dayton
A63: 133959 | B63: Dayton Academy, The | C63: Federal Revenue | E63: 5661783.1 | F63: 0.10417008 | G63: 589788.41 | H63: C | K63: Montgomery | L63: Dayton
A64: 134247 | B64: City Day Community School | C64: Federal Revenue | E64: 1221188.5 | F64: 0.082518224 | G64: 100770.31 | H64: C | K64: Montgomery | L64: Dayton
...

Sheet Charter Master
A1: 133355 | B1: A.B. Miree Fundamental Academy | C1: Local Revenue | E1: 2719630.4 | F1: 0.010789095 | G1: 29342.35 | H1: C | K1: 376
A2: 000556 | B2: A+ Arts Academy | C2: Local Revenue | E2: 1450154.8 | F2: 0.0043871041 | G2: 6361.98 | H2: C | K2: 161
A3: 000912 | B3: Academic Acceleration Academy | C3: Local Revenue | E3: 730744.86 | F3: 0.0086639953 | G3: 6331.17 | H3: C | K3: 82
A4: 007982 | B4: Academy of Arts and Humanities | C4: Local Revenue | E4: 277522.47 | F4: 9.8190247e-05 | G4: 27.25 | H4: C | K4: 128
A5: 008064 | B5: Academy of Arts and Sciences | C5: Local Revenue | E5: 1344443.6 | F5: 0 | G5: 0 | H5: C | K5: 216
A6: 134262 | B6: Academy Of Business & Tech | C6: Local Revenue | E6: 1750555.6 | F6: 0.00052156014 | G6: 913.02 | H6: C | K6: 309
A7: 133900 | B7: Academy of Cleveland | C7: Local Revenue | E7: 1059945.3 | F7: 0.0002142186 | G7: 227.06 | H7: C | I7: Cuyahoga | J7: Cleveland | K7: 147
A8: 000784 | B8: Academy of Columbus | C8: Local Revenue | E8: 2727062.2 | F8: 0 | G8: 0 | H8: C | K8: 473
A9: 133918 | B9: Academy Of Dayton | C9: Local Revenue | E9: 746521.86 | F9: 0.0010595001 | G9: 790.94 | H9: C | I9: Montgomery | K9: 120
A10: 149054 | B10: Akron Digital Academy | C10: Local Revenue | E10: 4063576.7 | F10: 0.021877212 | G10: 88899.73 | H10: C | K10: 539
A11: 000139 | B11: Alliance Academy of Cincinnati | C11: Local Revenue | E11: 0 | F11: -- | H11: C
A12: 143396 | B12: Alternative Education Academy | C12: Local Revenue | E12: 17351899 | F12: 0.060497628 | G12: 1049748.7 | H12: C | K12: 2125
A13: 000560 | B13: Apex Academy | C13: Local Revenue | E13: 0 | F13: -- | H13: C | I13: Cuyahoga | K13: 616
A14: 000427 | B14: Arise Academy | C14: Local Revenue | E14: 1470515.3 | F14: 0 | G14: 0 | H14: C | I14: Montgomery | J14: Dayton | K14: 178
A15: 143610 | B15: Arts & College Preparatory Academy | C15: Local Revenue | E15: 1588994.8 | F15: 0.00026705562 | G15: 424.35 | H15: C | K15: 208
A16: 008068 | B16: Arts Academy West, The | C16: Local Revenue | E16: 657459.05 | F16: 0.0047800087 | G16: 3142.66 | H16: C | I16: Cuyahoga | J16: Cleveland | K16: 74
A17: 000574 | B17: Arts Academy, The | C17: Local Revenue | E17: 1974056.5 | F17: 0.01129149 | G17: 22290.04 | H17: C | K17: 272
A18: 007992 | B18: Arts and Science Academy | C18: Local Revenue | E18: 622949.76 | F18: 6.0197471e-05 | G18: 37.5 | H18: C | K18: 158
A19: 008061 | B19: Arts and Science Preparatory Academy | C19: Local Revenue | E19: 161469.61 | F19: 0 | G19: 0 | H19: C | I19: Cuyahoga | K19: 26
A20: 000288 | B20: Auglaize County Educational Academy | C20: Local Revenue | E20: 705727.13 | F20: 0.016722469 | G20: 11801.5 | H20: C | K20: 56
A21: 000287 | B21: Auglaize County Special Needs School | C21: Local Revenue | E21: 1082082.8 | F21: 0.0098995201 | G21: 10712.1 | H21: C | K21: 35
A22: 134148 | B22: Aurora Academy | C22: Local Revenue | E22: 1380421.7 | F22: 0.010913165 | G22: 15064.77 | H22: C | K22: 159
A23: 000843 | B23: Bennett Venture Academy | C23: Local Revenue | E23: 0 | F23: -- | H23: C | K23: 519
A24: 000417 | B24: Buckeye On-Line School for Success | C24: Local Revenue | E24: 7399000.7 | F24: 0.00097174339 | G24: 7189.93 | H24: C | K24: 1012
A25: 000502 | B25: Canton Academy, The | C25: Local Revenue | E25: 879618.34 | F25: 0.0012297606 | G25: 1081.72 | H25: C | K25: 50
A26: 000859 | B26: Canton Arts Academy | C26: Local Revenue | E26: 1222466.8 | F26: 0.0066802879 | G26: 8166.43 | H26: C | K26: 122
A27: 000420 | B27: Capitol City Academy | C27: Local Revenue | E27: 1323872.1 | F27: 0.038754658 | G27: 51306.21 | H27: C | K27: 159
A28: 000343 | B28: Chase Academy for Communication Arts | C28: Local Revenue | E28: 1829347 | F28: 0.0036094847 | G28: 6603 | H28: C | K28: 221
A29: 133512 | B29: Cincinnati College Preparatory Academy | C29: Local Revenue | E29: 4463813.7 | F29: 0.001022574 | G29: 4564.58 | H29: C | K29: 544
A30: 000953 | B30: Cincinnati Preparatory and Fitness Academy | C30: Local Revenue | E30: 835934 | F30: 0.0011472198 | G30: 959 | H30: C | K30: 79
A31: 000781 | B31: Cincinnati Speech & Reading Intervention Center | C31: Local Revenue | E31: 1357867 | F31: 7.5449214e-05 | G31: 102.45 | H31: C | K31: 180
A32: 133520 | B32: Citizens Academy | C32: Local Revenue | E32: 3812632.9 | F32: 0.085243732 | G32: 325003.06 | H32: C | I32: Cuyahoga | J32: Cleveland | K32: 380
A33: 134247 | B33: City Day Community School | C33: Local Revenue | E33: 1221188.5 | F33: 0.013922404 | G33: 17001.88 | H33: C | I33: Montgomery | J33: Dayton | K33: 169
A34: 000527 | B34: Cleveland Academy for Scholarship Technology and Leadership | C34: Local Revenue | E34: 2445648.9 | F34: 0 | G34: 0 | H34: C | I34: Cuyahoga | J34: Cleveland | K34: 160
A35: 007995 | B35: Cleveland Arts and Social Sciences Academy | C35: Local Revenue | E35: 1189815.7 | F35: 0.00047435076 | G35: 564.39 | H35: C | I35: Cuyahoga | J35: Cleveland | K35: 131
A36: 000930 | B36: Cleveland Entreprenuership Preparatory School | C36: Local Revenue | E36: 1607032.7 | F36: 0.43075697 | G36: 692240.54 | H36: C | I36: Cuyahoga | J36: Cleveland | K36: 123
A37: 000946 | B37: Cleveland Lighthouse Community School | C37: Local Revenue | E37: 2239223.5 | F37: 0.3055538 | G37: 684203.25 | H37: C | I37: Cuyahoga | J37: Cleveland | K37: 166
A38: 132738 | B38: Colin Powell Leadership Acad | C38: Local Revenue | E38: 2171897.7 | F38: 0 | G38: 0 | H38: C | I38: Montgomery | J38: Dayton | K38: 219
A39: 000557 | B39: Columbus Arts & Technology Academy | C39: Local Revenue | E39: 4484235.7 | F39: 0.00050200305 | G39: 2251.1 | H39: C | K39: 598
A40: 000553 | B40: Columbus Humanities, Arts and Technology Academy | C40: Local Revenue | E40: 2476348.7 | F40: 0.0011386159 | G40: 2819.61 | H40: C | K40: 325
...

Sheet Master
D1: School Year | H1: Charter | K1: County | L1: City | M1: Enrollment
D2: Metrics | E2: Total Revenue Amount | F2: Revenue Source Pct of Total | G2: Use This Amount | H2: Charter | I2: Conversion | J2: Conversion District | K2: County | L2: City
A3: District | C3: Revenue Source | G3: Note: charter revenues are separate and distinct from district revenues. Do not need to back out charter financial eata from the district files as previously told.
A4: 000125 | B4: Polly Fox Academy Community School | C4: Local Revenue | E4: 1252639.2 | F4: 0.019529359 | G4: =F4*E4 -> 24463.24 | H4: C | M4: 131
A5: 000125 | B5: Polly Fox Academy Community School | C5: State Revenue | E5: 1252639.2 | F5: 0.76300448 | G5: =F5*E5 -> 955769.31 | H5: C
A6: 000125 | B6: Polly Fox Academy Community School | C6: Federal Revenue | E6: 1252639.2 | F6: 0.21746616 | G6: =F6*E6 -> 272406.64 | H6: C
A7: 000130 | B7: Phoenix Academy Community School | C7: Local Revenue | E7: 7379049.3 | F7: 0.21479738 | G7: =F7*E7 -> 1585000.5 | H7: C | M7: 708
A8: 000130 | B8: Phoenix Academy Community School | C8: State Revenue | E8: 7379049.3 | F8: 0.77968003 | G8: =F8*E8 -> 5753297.3 | H8: C
A9: 000130 | B9: Phoenix Academy Community School | C9: Federal Revenue | E9: 7379049.3 | F9: 0.0055225868 | G9: =F9*E9 -> 40751.44 | H9: C
A10: 000131 | B10: Glass City Academy | C10: Local Revenue | E10: 1296747.6 | F10: 0.087188241 | G10: =F10*E10 -> 113061.14 | H10: C | M10: 180
A11: 000131 | B11: Glass City Academy | C11: State Revenue | E11: 1296747.6 | F11: 0.91281176 | G11: =F11*E11 -> 1183686.4 | H11: C
A12: 000131 | B12: Glass City Academy | C12: Federal Revenue | E12: 1296747.6 | F12: 0 | G12: =F12*E12 -> 0 | H12: C
A13: 000138 | B13: Pathway School of Discovery | C13: Local Revenue | E13: 0 | F13: -- | H13: C | K13: Montgomery | L13: Dayton | M13: 679
A14: 000138 | B14: Pathway School of Discovery | C14: State Revenue | E14: 4188670.2 | F14: -- | G14: 4188670.2 | H14: C | K14: Montgomery | L14: Dayton
A15: 000138 | B15: Pathway School of Discovery | C15: Federal Revenue | E15: 0 | F15: -- | H15: C | K15: Montgomery | L15: Dayton
A16: 000139 | B16: Alliance Academy of Cincinnati | C16: Local Revenue | E16: 0 | F16: -- | H16: C | M16: 505
A17: 000139 | B17: Alliance Academy of Cincinnati | C17: State Revenue | E17: 3161899.6 | F17: -- | G17: 3161899.6 | H17: C
A18: 000139 | B18: Alliance Academy of Cincinnati | C18: Federal Revenue | E18: 0 | F18: -- | H18: C
A19: 000140 | B19: Victory Academy of Toledo | C19: Local Revenue | E19: 1136684 | F19: 0.00050960512 | G19: =F19*E19 -> 579.26 | H19: C | M19: 112
A20: 000140 | B20: Victory Academy of Toledo | C20: State Revenue | E20: 1136684 | F20: 0.69867387 | G20: =F20*E20 -> 794171.43 | H20: C
A21: 000140 | B21: Victory Academy of Toledo | C21: Federal Revenue | E21: 1136684 | F21: 0.30081653 | G21: =F21*E21 -> 341933.34 | H21: C
A22: 000143 | B22: George A. Phillips Academy | C22: Local Revenue | E22: 1674388.4 | F22: 0.0020729777 | G22: =F22*E22 -> 3470.97 | H22: C | M22: 216
A23: 000143 | B23: George A. Phillips Academy | C23: State Revenue | E23: 1674388.4 | F23: 0.83561365 | G23: =F23*E23 -> 1399141.9 | H23: C
A24: 000143 | B24: George A. Phillips Academy | C24: Federal Revenue | E24: 1674388.4 | F24: 0.16231337 | G24: =F24*E24 -> 271775.63 | H24: C
A25: 000195 | B25: Hope Academy East Campus | C25: Local Revenue | E25: 3429982.1 | F25: 0.0034535982 | G25: =F25*E25 -> 11845.78 | H25: C | K25: Cuyahoga | L25: Cleveland | M25: 440
A26: 000195 | B26: Hope Academy East Campus | C26: State Revenue | E26: 3429982.1 | F26: 0.86731576 | G26: =F26*E26 -> 2974877.5 | H26: C | K26: Cuyahoga | L26: Cleveland
A27: 000195 | B27: Hope Academy East Campus | C27: Federal Revenue | E27: 3429982.1 | F27: 0.12923064 | G27: =F27*E27 -> 443258.8 | H27: C | K27: Cuyahoga | L27: Cleveland
A28: 000197 | B28: Hamilton Local Digital Academy | C28: Local Revenue | E28: 603347.98 | F28: 0.82928566 | G28: =F28*E28 -> 500347.83 | H28: c | M28: 65
A29: 000197 | B29: Hamilton Local Digital Academy | C29: State Revenue | E29: 603347.98 | F29: 0.004972255 | G29: =F29*E29 -> 3000 | H29: c
A30: 000197 | B30: Hamilton Local Digital Academy | C30: Federal Revenue | E30: 603347.98 | F30: 0.16574208 | G30: =F30*E30 -> 100000.15 | H30: c
A31: 000222 | B31: Wildwood Environmental Academy | C31: Local Revenue | E31: 1853701.4 | F31: 0.001248939 | G31: =F31*E31 -> 2315.16 | H31: C | M31: 190
A32: 000222 | B32: Wildwood Environmental Academy | C32: State Revenue | E32: 1853701.4 | F32: 0.82349874 | G32: =F32*E32 -> 1526520.8 | H32: C
A33: 000222 | B33: Wildwood Environmental Academy | C33: Federal Revenue | E33: 1853701.4 | F33: 0.17525233 | G33: =F33*E33 -> 324865.49 | H33: C
A34: 000235 | B34: International College Preparatory Academy | C34: Local Revenue | E34: 4926715.6 | F34: 0.013378422 | G34: =F34*E34 -> 65911.68 | H34: C | M34: 639
A35: 000235 | B35: International College Preparatory Academy | C35: State Revenue | E35: 4926715.6 | F35: 0.82697827 | G35: =F35*E35 -> 4074286.7 | H35: C
A36: 000235 | B36: International College Preparatory Academy | C36: Federal Revenue | E36: 4926715.6 | F36: 0.15964331 | G36: =F36*E36 -> 786517.18 | H36: C
A37: 000236 | B37: Ohio Connections Academy, Inc | C37: Local Revenue | E37: 7076666.7 | F37: 0.0051544225 | G37: =F37*E37 -> 36476.13 | H37: C | M37: 912
A38: 000236 | B38: Ohio Connections Academy, Inc | C38: State Revenue | E38: 7076666.7 | F38: 0.89244895 | G38: =F38*E38 -> 6315563.8 | H38: C
A39: 000236 | B39: Ohio Connections Academy, Inc | C39: Federal Revenue | E39: 7076666.7 | F39: 0.10239663 | G39: =F39*E39 -> 724626.8 | H39: C
A40: 000277 | B40: Scholarts Preparatory and Career Center for Children | C40: Local Revenue | E40: 842358.61 | F40: 0.00011871428 | G40: =F40*E40 -> 100 | H40: C | M40: 96
...
