Workbook
Name Rents: 'LIHTCRents 12'!$A$19:$AP$54

Sheet Sources
A1: SOURCES OF FUNDING
A3: Project Name: | E3: Date: | F3: 40909
A5: If mixed use project, see comment | B5: RESIDENTIAL | G5: COMMERCIAL
A6: Funding Source | B6: HOME Match (check) | C6: Committed | D6: Conditional | E6: Tentative | F6: Anticipated or Firm Commitment Date | G6: Commercial | H6: Anticipated or Firm Commitment Date
A8: OHCS GRANTS & EQUITY
A9: LIHTC Equity | E9: ='LIHTC Calculation'!F62 -> 0
A10: Trust Fund
A11: Preservation
A12: LI Weatherization Program
A13: HELP
A14: OTHER ____________________
A15: Total OHCS Grants & Equity | C15: =SUM(C9:C14) -> 0 | D15: =SUM(D9:D14) -> 0 | E15: =SUM(E9:E14) -> 0
A17: OHCS LOANS
A18: Tax Exempt Bonds
A19: Trust Fund
A20: Preservation
A21: ORR
A22: HELP
A23: OTHER ____________________
A24: Total OHCS Loans | C24: =SUM(C18:C23) -> 0 | D24: =SUM(D18:D23) -> 0 | E24: =SUM(E18:E23) -> 0
A26: PHB SOURCES
A27: Tax Increment Financing
A28: HOME
A29: SDC Waivers
A30: Tax Exemptions
A31: OTHER ____________________
A32: Total PHB | C32: =SUM(C27:C31) -> 0 | D32: =SUM(D27:D31) -> 0 | E32: =SUM(E27:E31) -> 0
A34: OTHER LOANS
A35: Permanent Loan (bank name)
A40: Total OTHER Loans | C40: =SUM(C35:C39) -> 0 | D40: =SUM(D35:D39) -> 0 | E40: =SUM(E35:E39) -> 0
A42: OTHER GRANTS
A48: Total OTHER Grants | C48: =SUM(C43:C47) -> 0 | D48: =SUM(D43:D47) -> 0 | E48: =SUM(E43:E47) -> 0
A50: APPLICANT CONTRIBUTIONS
A51: Cash
A52: Deferred Development Fee
A55: Total Applicant Contribution | C55: =SUM(C51:C54) -> 0 | D55: =SUM(D51:D54) -> 0 | E55: =SUM(E51:E54) -> 0
A57: OTHER:
A58: Cashflow During Rehab
A61: Total Other Funds | C61: =SUM(C58:C60) -> 0 | D61: =SUM(D58:D60) -> 0 | E61: =SUM(E58:E60) -> 0
G62: =SUM(G9:G61) -> 0
...

Sheet Uses of Funds
A1: USES OF FUNDING
A2: Project Name: | C2: =Sources!$B$3 -> 0 | H2: Date: | I2: =Sources!F3 -> 40909
A4: Acq/Rehab
A5: IRS Setaside
A6: Number of Units:
A7: Gross Residential Square Footage:
A8: Net Residential Square Footage (for info only, not used in calcs)
A9: Common Areas: | T9: These two columns are for
A10: Commercial/other | T10: LIHTC APPLICANTS ONLY
A11: Total Square Footage: | C11: =SUM(C7:C10)-C8 -> 0
B13: If mixed use project, see comment | D13: COMMERCIAL | E13: RESIDENTIAL
C14: Total | D14: Commercial | E14: (A) Original Application | F14: Cost per Unit | G14: Cost per Square Foot | H14: Cost as % of Total | I14: (B) Carryover Application | J14: % Diff (B/A) | K14: Cost per Unit | L14: Cost per Square Foot | M14: Cost as % of Total | N14: (C) Final Application | O14: % Diff (C/B) | P14: Cost per Unit | Q14: Cost per Square Foot | R14: Cost as % of Total | S14: Funding Source | T14: Reasonably Expected Basis | U14: Estimated Gross Expended by Carryover Date
A16: Acquisition Costs
B17: Purchase Price:
B18: Land | C18: =D18+E18 -> 0 | F18: =E18/$C$6 -> #DIV/0! | G18: =E18/($C$7+$C$9) -> #DIV/0! | H18: =E18/$E$130 -> #DIV/0! | J18: =(I18/E18)-1 -> #DIV/0! | K18: =I18/$C$6 -> #DIV/0! | L18: =I18/($C$7+$C$9) -> #DIV/0! | M18: =I18/$I$130 -> #DIV/0! | O18: =(N18/I18)-1 -> #DIV/0! | P18: =N18/$C$6 -> #DIV/0! | Q18: =N18/($C$7+$C$9) -> #DIV/0! | R18: =N18/$N$130 -> #DIV/0!
B19: Improvements | C19: =D19+E19 -> 0 | F19: =E19/$C$6 -> #DIV/0! | G19: =E19/($C$7+$C$9) -> #DIV/0! | H19: =E19/$E$130 -> #DIV/0! | J19: =(I19/E19)-1 -> #DIV/0! | K19: =I19/$C$6 -> #DIV/0! | L19: =I19/($C$7+$C$9) -> #DIV/0! | M19: =I19/$I$130 -> #DIV/0! | O19: =(N19/I19)-1 -> #DIV/0! | P19: =N19/$C$6 -> #DIV/0! | Q19: =N19/($C$7+$C$9) -> #DIV/0! | R19: =N19/$N$130 -> #DIV/0! | T19: =E19 -> 0
B20: Liens and Other Taxes | C20: =D20+E20 -> 0 | F20: =E20/$C$6 -> #DIV/0! | G20: =E20/($C$7+$C$9) -> #DIV/0! | H20: =E20/$E$130 -> #DIV/0! | J20: =(I20/E20)-1 -> #DIV/0! | K20: =I20/$C$6 -> #DIV/0! | L20: =I20/($C$7+$C$9) -> #DIV/0! | M20: =I20/$I$130 -> #DIV/0! | O20: =(N20/I20)-1 -> #DIV/0! | P20: =N20/$C$6 -> #DIV/0! | Q20: =N20/($C$7+$C$9) -> #DIV/0! | R20: =N20/$N$130 -> #DIV/0! | T20: =E20 -> 0
B21: Closing/Recording | C21: =D21+E21 -> 0 | F21: =E21/$C$6 -> #DIV/0! | G21: =E21/($C$7+$C$9) -> #DIV/0! | H21: =E21/$E$130 -> #DIV/0! | J21: =(I21/E21)-1 -> #DIV/0! | K21: =I21/$C$6 -> #DIV/0! | L21: =I21/($C$7+$C$9) -> #DIV/0! | M21: =I21/$I$130 -> #DIV/0! | O21: =(N21/I21)-1 -> #DIV/0! | P21: =N21/$C$6 -> #DIV/0! | Q21: =N21/($C$7+$C$9) -> #DIV/0! | R21: =N21/$N$130 -> #DIV/0! | T21: =E21 -> 0
B22: Extension Fees | C22: =D22+E22 -> 0 | F22: =E22/$C$6 -> #DIV/0! | G22: =E22/($C$7+$C$9) -> #DIV/0! | H22: =E22/$E$130 -> #DIV/0! | J22: =(I22/E22)-1 -> #DIV/0! | K22: =I22/$C$6 -> #DIV/0! | L22: =I22/($C$7+$C$9) -> #DIV/0! | M22: =I22/$I$130 -> #DIV/0! | O22: =(N22/I22)-1 -> #DIV/0! | P22: =N22/$C$6 -> #DIV/0! | Q22: =N22/($C$7+$C$9) -> #DIV/0! | R22: =N22/$N$130 -> #DIV/0! | T22: =E22 -> 0
B23: Other: | C23: =D23+E23 -> 0 | F23: =E23/$C$6 -> #DIV/0! | G23: =E23/($C$7+$C$9) -> #DIV/0! | H23: =E23/$E$130 -> #DIV/0! | J23: =(I23/E23)-1 -> #DIV/0! | K23: =I23/$C$6 -> #DIV/0! | L23: =I23/($C$7+$C$9) -> #DIV/0! | M23: =I23/$I$130 -> #DIV/0! | O23: =(N23/I23)-1 -> #DIV/0! | P23: =N23/$C$6 -> #DIV/0! | Q23: =N23/($C$7+$C$9) -> #DIV/0! | R23: =N23/$N$130 -> #DIV/0! | T23: =E23 -> 0
B25: Acquisition Costs Subtotal: | C25: =SUM(C17:C24) -> 0 | D25: =SUM(D17:D24) -> 0 | E25: =SUM(E18:E23) -> 0 | F25: =E25/$C$6 -> #DIV/0! | G25: =E25/($C$7+$C$9) -> #DIV/0! | H25: =E25/$E$130 -> #DIV/0! | I25: =SUM(I18:I24) -> 0 | J25: =(I25/E25)-1 -> #DIV/0! | K25: =I25/$C$6 -> #DIV/0! | L25: =I25/($C$7+$C$9) -> #DIV/0! | M25: =I25/$I$130 -> #DIV/0! | N25: =SUM(N18:N24) -> 0 | O25: =(N25/I25)-1 -> #DIV/0! | P25: =N25/$C$6 -> #DIV/0! | Q25: =N25/($C$7+$C$9) -> #DIV/0! | R25: =N25/$N$130 -> #DIV/0! | T25: =SUM(T18:T23) -> 0 | U25: =SUM(U18:U23) -> 0
A27: Construction Costs
B28: Off-site Work | C28: =D28+E28 -> 0 | F28: =E28/$C$6 -> #DIV/0! | G28: =E28/($C$7+$C$9) -> #DIV/0! | H28: =E28/$E$130 -> #DIV/0! | J28: =(I28/E28)-1 -> #DIV/0! | K28: =I28/$C$6 -> #DIV/0! | L28: =I28/($C$7+$C$9) -> #DIV/0! | M28: =I28/$I$130 -> #DIV/0! | O28: =(N28/I28)-1 -> #DIV/0! | P28: =N28/$C$6 -> #DIV/0! | Q28: =N28/($C$7+$C$9) -> #DIV/0! | R28: =N28/$N$130 -> #DIV/0!
B29: On-site Work | C29: =D29+E29 -> 0 | F29: =E29/$C$6 -> #DIV/0! | G29: =E29/($C$7+$C$9) -> #DIV/0! | H29: =E29/$E$130 -> #DIV/0! | J29: =(I29/E29)-1 -> #DIV/0! | K29: =I29/$C$6 -> #DIV/0! | L29: =I29/($C$7+$C$9) -> #DIV/0! | M29: =I29/$I$130 -> #DIV/0! | O29: =(N29/I29)-1 -> #DIV/0! | P29: =N29/$C$6 -> #DIV/0! | Q29: =N29/($C$7+$C$9) -> #DIV/0! | R29: =N29/$N$130 -> #DIV/0! | T29: =E29 -> 0
B30: Hazardous Materials Abatement | C30: =D30+E30 -> 0 | F30: =E30/$C$6 -> #DIV/0! | G30: =E30/($C$7+$C$9) -> #DIV/0! | H30: =E30/$E$130 -> #DIV/0! | J30: =(I30/E30)-1 -> #DIV/0! | K30: =I30/$C$6 -> #DIV/0! | L30: =I30/($C$7+$C$9) -> #DIV/0! | M30: =I30/$I$130 -> #DIV/0! | O30: =(N30/I30)-1 -> #DIV/0! | P30: =N30/$C$6 -> #DIV/0! | Q30: =N30/($C$7+$C$9) -> #DIV/0! | R30: =N30/$N$130 -> #DIV/0! | T30: =E30 -> 0
B31: Demolition | C31: =D31+E31 -> 0 | F31: =E31/$C$6 -> #DIV/0! | G31: =E31/($C$7+$C$9) -> #DIV/0! | H31: =E31/$E$130 -> #DIV/0! | J31: =(I31/E31)-1 -> #DIV/0! | K31: =I31/$C$6 -> #DIV/0! | L31: =I31/($C$7+$C$9) -> #DIV/0! | M31: =I31/$I$130 -> #DIV/0! | O31: =(N31/I31)-1 -> #DIV/0! | P31: =N31/$C$6 -> #DIV/0! | Q31: =N31/($C$7+$C$9) -> #DIV/0! | R31: =N31/$N$130 -> #DIV/0! | T31: =E31 -> 0
B32: Residential Building | C32: =D32+E32 -> 0 | F32: =E32/$C$6 -> #DIV/0! | G32: =E32/($C$7+$C$9) -> #DIV/0! | H32: =E32/$E$130 -> #DIV/0! | J32: =(I32/E32)-1 -> #DIV/0! | K32: =I32/$C$6 -> #DIV/0! | L32: =I32/($C$7+$C$9) -> #DIV/0! | M32: =I32/$I$130 -> #DIV/0! | O32: =(N32/I32)-1 -> #DIV/0! | P32: =N32/$C$6 -> #DIV/0! | Q32: =N32/($C$7+$C$9) -> #DIV/0! | R32: =N32/$N$130 -> #DIV/0! | T32: =E32 -> 0
B33: Commercial Space/Building | C33: =D33+E33 -> 0 | F33: =E33/$C$6 -> #DIV/0! | G33: =E33/($C$7+$C$9) -> #DIV/0! | H33: =E33/$E$130 -> #DIV/0! | J33: =(I33/E33)-1 -> #DIV/0! | K33: =I33/$C$6 -> #DIV/0! | L33: =I33/($C$7+$C$9) -> #DIV/0! | M33: =I33/$I$130 -> #DIV/0! | O33: =(N33/I33)-1 -> #DIV/0! | P33: =N33/$C$6 -> #DIV/0! | Q33: =N33/($C$7+$C$9) -> #DIV/0! | R33: =N33/$N$130 -> #DIV/0!
B34: Common Use Facilities | C34: =D34+E34 -> 0 | F34: =E34/$C$6 -> #DIV/0! | G34: =E34/($C$7+$C$9) -> #DIV/0! | H34: =E34/$E$130 -> #DIV/0! | J34: =(I34/E34)-1 -> #DIV/0! | K34: =I34/$C$6 -> #DIV/0! | L34: =I34/($C$7+$C$9) -> #DIV/0! | M34: =I34/$I$130 -> #DIV/0! | O34: =(N34/I34)-1 -> #DIV/0! | P34: =N34/$C$6 -> #DIV/0! | Q34: =N34/($C$7+$C$9) -> #DIV/0! | R34: =N34/$N$130 -> #DIV/0! | T34: =E34 -> 0
B35: Elevator | C35: =D35+E35 -> 0 | F35: =E35/$C$6 -> #DIV/0! | G35: =E35/($C$7+$C$9) -> #DIV/0! | H35: =E35/$E$130 -> #DIV/0! | J35: =(I35/E35)-1 -> #DIV/0! | K35: =I35/$C$6 -> #DIV/0! | L35: =I35/($C$7+$C$9) -> #DIV/0! | M35: =I35/$I$130 -> #DIV/0! | O35: =(N35/I35)-1 -> #DIV/0! | P35: =N35/$C$6 -> #DIV/0! | Q35: =N35/($C$7+$C$9) -> #DIV/0! | R35: =N35/$N$130 -> #DIV/0! | T35: =E35 -> 0
B36: Laundry Facilities | C36: =D36+E36 -> 0 | F36: =E36/$C$6 -> #DIV/0! | G36: =E36/($C$7+$C$9) -> #DIV/0! | H36: =E36/$E$130 -> #DIV/0! | J36: =(I36/E36)-1 -> #DIV/0! | K36: =I36/$C$6 -> #DIV/0! | L36: =I36/($C$7+$C$9) -> #DIV/0! | M36: =I36/$I$130 -> #DIV/0! | O36: =(N36/I36)-1 -> #DIV/0! | P36: =N36/$C$6 -> #DIV/0! | Q36: =N36/($C$7+$C$9) -> #DIV/0! | R36: =N36/$N$130 -> #DIV/0! | T36: =E36 -> 0
B37: Storage/Garages | C37: =D37+E37 -> 0 | F37: =E37/$C$6 -> #DIV/0! | G37: =E37/($C$7+$C$9) -> #DIV/0! | H37: =E37/$E$130 -> #DIV/0! | J37: =(I37/E37)-1 -> #DIV/0! | K37: =I37/$C$6 -> #DIV/0! | L37: =I37/($C$7+$C$9) -> #DIV/0! | M37: =I37/$I$130 -> #DIV/0! | O37: =(N37/I37)-1 -> #DIV/0! | P37: =N37/$C$6 -> #DIV/0! | Q37: =N37/($C$7+$C$9) -> #DIV/0! | R37: =N37/$N$130 -> #DIV/0! | T37: =E37 -> 0
B38: Landscaping | C38: =D38+E38 -> 0 | F38: =E38/$C$6 -> #DIV/0! | G38: =E38/($C$7+$C$9) -> #DIV/0! | H38: =E38/$E$130 -> #DIV/0! | J38: =(I38/E38)-1 -> #DIV/0! | K38: =I38/$C$6 -> #DIV/0! | L38: =I38/($C$7+$C$9) -> #DIV/0! | M38: =I38/$I$130 -> #DIV/0! | O38: =(N38/I38)-1 -> #DIV/0! | P38: =N38/$C$6 -> #DIV/0! | Q38: =N38/($C$7+$C$9) -> #DIV/0! | R38: =N38/$N$130 -> #DIV/0! | T38: =E38 -> 0
B39: General Conditions | C39: =D39+E39 -> 0 | F39: =E39/$C$6 -> #DIV/0! | G39: =E39/($C$7+$C$9) -> #DIV/0! | H39: =E39/$E$130 -> #DIV/0! | J39: =(I39/E39)-1 -> #DIV/0! | K39: =I39/$C$6 -> #DIV/0! | L39: =I39/($C$7+$C$9) -> #DIV/0! | M39: =I39/$I$130 -> #DIV/0! | O39: =(N39/I39)-1 -> #DIV/0! | P39: =N39/$C$6 -> #DIV/0! | Q39: =N39/($C$7+$C$9) -> #DIV/0! | R39: =N39/$N$130 -> #DIV/0! | T39: =E39 -> 0
B40: Builder's Risk Insurance | C40: =D40+E40 -> 0 | F40: =E40/$C$6 -> #DIV/0! | G40: =E40/($C$7+$C$9) -> #DIV/0! | H40: =E40/$E$130 -> #DIV/0! | J40: =(I40/E40)-1 -> #DIV/0! | K40: =I40/$C$6 -> #DIV/0! | L40: =I40/($C$7+$C$9) -> #DIV/0! | M40: =I40/$I$130 -> #DIV/0! | O40: =(N40/I40)-1 -> #DIV/0! | P40: =N40/$C$6 -> #DIV/0! | Q40: =N40/($C$7+$C$9) -> #DIV/0! | R40: =N40/$N$130 -> #DIV/0! | T40: =E40 -> 0
B41: Contractor Overhead | C41: =D41+E41 -> 0 | F41: =E41/$C$6 -> #DIV/0! | G41: =E41/($C$7+$C$9) -> #DIV/0! | H41: =E41/$E$130 -> #DIV/0! | J41: =(I41/E41)-1 -> #DIV/0! | K41: =I41/$C$6 -> #DIV/0! | L41: =I41/($C$7+$C$9) -> #DIV/0! | M41: =I41/$I$130 -> #DIV/0! | O41: =(N41/I41)-1 -> #DIV/0! | P41: =N41/$C$6 -> #DIV/0! | Q41: =N41/($C$7+$C$9) -> #DIV/0! | R41: =N41/$N$130 -> #DIV/0! | T41: =E41 -> 0
B42: Contractor Profit | C42: =D42+E42 -> 0 | F42: =E42/$C$6 -> #DIV/0! | G42: =E42/($C$7+$C$9) -> #DIV/0! | H42: =E42/$E$130 -> #DIV/0! | J42: =(I42/E42)-1 -> #DIV/0! | K42: =I42/$C$6 -> #DIV/0! | L42: =I42/($C$7+$C$9) -> #DIV/0! | M42: =I42/$I$130 -> #DIV/0! | O42: =(N42/I42)-1 -> #DIV/0! | P42: =N42/$C$6 -> #DIV/0! | Q42: =N42/($C$7+$C$9) -> #DIV/0! | R42: =N42/$N$130 -> #DIV/0! | T42: =E42 -> 0
B43: Contingency | C43: =D43+E43 -> 0 | F43: =E43/$C$6 -> #DIV/0! | G43: =E43/($C$7+$C$9) -> #DIV/0! | H43: =E43/$E$130 -> #DIV/0! | J43: =(I43/E43)-1 -> #DIV/0! | K43: =I43/$C$6 -> #DIV/0! | L43: =I43/($C$7+$C$9) -> #DIV/0! | M43: =I43/$I$130 -> #DIV/0! | O43: =(N43/I43)-1 -> #DIV/0! | P43: =N43/$C$6 -> #DIV/0! | Q43: =N43/($C$7+$C$9) -> #DIV/0! | R43: =N43/$N$130 -> #DIV/0! | T43: =E43 -> 0
B44: FF&E (Common Area Furnishings) | C44: =D44+E44 -> 0 | F44: =E44/$C$6 -> #DIV/0! | G44: =E44/($C$7+$C$9) -> #DIV/0! | H44: =E44/$E$130 -> #DIV/0! | J44: =(I44/E44)-1 -> #DIV/0! | K44: =I44/$C$6 -> #DIV/0! | L44: =I44/($C$7+$C$9) -> #DIV/0! | M44: =I44/$I$130 -> #DIV/0! | O44: =(N44/I44)-1 -> #DIV/0! | P44: =N44/$C$6 -> #DIV/0! | Q44: =N44/($C$7+$C$9) -> #DIV/0! | R44: =N44/$N$130 -> #DIV/0! | T44: =E44 -> 0
B45: Internet Wiring & Equipment | C45: =D45+E45 -> 0 | F45: =E45/$C$6 -> #DIV/0! | G45: =E45/($C$7+$C$9) -> #DIV/0! | H45: =E45/$E$130 -> #DIV/0! | J45: =(I45/E45)-1 -> #DIV/0! | K45: =I45/$C$6 -> #DIV/0! | L45: =I45/($C$7+$C$9) -> #DIV/0! | M45: =I45/$I$130 -> #DIV/0! | O45: =(N45/I45)-1 -> #DIV/0! | P45: =N45/$C$6 -> #DIV/0! | Q45: =N45/($C$7+$C$9) -> #DIV/0! | R45: =N45/$N$130 -> #DIV/0! | T45: =E45 -> 0
...

Sheet Income
A1: COMBINED HOUSING/COMMERCIAL OPERATING BUDGET - INCOME
B3: Project Name: | E3: =Sources!$B$3 -> 0
D4: Date: | F4: =Sources!F3 -> 40909
D5: County:
A6: ANNUAL Residential Income: | I6: Annual Inflation Rate Factor: | M6: 0.02
A7: Rents based on:
A8: Unit Size | B8: Unit Type | C8: # of Baths | D8: Square Feet | E8: Median Income % | F8: Gross Monthly Rent Per Unit | H8: Tenant Paid Utility Allow | J8: Net Monthly Rent Per Unit | L8: Number of Units | N8: 1 | O8: 2 | P8: 3 | Q8: 4 | R8: 5 | S8: 6 | T8: 7 | U8: 8 | V8: 9 | W8: 10 | X8: 11 | Y8: 12 | Z8: 13 | AA8: 14 | AB8: 15 | AC8: 16 | AD8: 17 | AE8: 18 | AF8: 19 | AG8: 20 | AH8: 21 | AI8: 22 | AJ8: 23 | AK8: 24 | AL8: 25 | AM8: 26 | AN8: 27 | AO8: 28 | AP8: 29 | AQ8: 30
B10: Bdr | E10: =ROUNDUP(IF(OR(A10="sro",A10=0),+F10/(VLOOKUP($F$5,Rents,26)*2),IF(A10=1,+F10/(VLOOKUP($F$5,Rents,27)*2),IF(A10=2,+F10/(VLOOKUP($F$5,Rents,28)*2),IF(A10=3,+F10/(VLOOKUP($F$5,Rents,29)*2),IF(A10=4,+F10/(VLOOKUP($F$5,Rents,30)*2),IF(A10=5,+F10/(VLOOKUP($F$5,Rents,31)*2),0)))))),3)*100 -> #N/A | G10: - | I10: = | J10: =F10-H10 -> 0 | K10: X 12 | M10: = | N10: =J10*L10*12 -> 0 | O10: =(+N10*$M$6)+N10 -> 0 | P10: =(+O10*$M$6)+O10 -> 0 | Q10: =(+P10*$M$6)+P10 -> 0 | R10: =(+Q10*$M$6)+Q10 -> 0 | S10: =(+R10*$M$6)+R10 -> 0 | T10: =(+S10*$M$6)+S10 -> 0 | U10: =(+T10*$M$6)+T10 -> 0 | V10: =(+U10*$M$6)+U10 -> 0 | ... AQ10: =(+AP10*$M$6)+AP10 -> 0
B11: Bdr | E11: =ROUNDUP(IF(OR(A11="sro",A11=0),+F11/(VLOOKUP($F$5,Rents,26)*2),IF(A11=1,+F11/(VLOOKUP($F$5,Rents,27)*2),IF(A11=2,+F11/(VLOOKUP($F$5,Rents,28)*2),IF(A11=3,+F11/(VLOOKUP($F$5,Rents,29)*2),IF(A11=4,+F11/(VLOOKUP($F$5,Rents,30)*2),IF(A11=5,+F11/(VLOOKUP($F$5,Rents,31)*2),0)))))),3)*100 -> #N/A | G11: - | I11: = | J11: =F11-H11 -> 0 | K11: X 12 | M11: = | N11: =J11*L11*12 -> 0 | O11: =(+N11*$M$6)+N11 -> 0 | P11: =(+O11*$M$6)+O11 -> 0 | Q11: =(+P11*$M$6)+P11 -> 0 | R11: =(+Q11*$M$6)+Q11 -> 0 | S11: =(+R11*$M$6)+R11 -> 0 | T11: =(+S11*$M$6)+S11 -> 0 | U11: =(+T11*$M$6)+T11 -> 0 | V11: =(+U11*$M$6)+U11 -> 0 | ... AQ11: =(+AP11*$M$6)+AP11 -> 0
B12: Bdr | E12: =ROUNDUP(IF(OR(A12="sro",A12=0),+F12/(VLOOKUP($F$5,Rents,26)*2),IF(A12=1,+F12/(VLOOKUP($F$5,Rents,27)*2),IF(A12=2,+F12/(VLOOKUP($F$5,Rents,28)*2),IF(A12=3,+F12/(VLOOKUP($F$5,Rents,29)*2),IF(A12=4,+F12/(VLOOKUP($F$5,Rents,30)*2),IF(A12=5,+F12/(VLOOKUP($F$5,Rents,31)*2),0)))))),3)*100 -> #N/A | G12: - | I12: = | J12: =F12-H12 -> 0 | K12: X 12 | M12: = | N12: =J12*L12*12 -> 0 | O12: =(+N12*$M$6)+N12 -> 0 | P12: =(+O12*$M$6)+O12 -> 0 | Q12: =(+P12*$M$6)+P12 -> 0 | R12: =(+Q12*$M$6)+Q12 -> 0 | S12: =(+R12*$M$6)+R12 -> 0 | T12: =(+S12*$M$6)+S12 -> 0 | U12: =(+T12*$M$6)+T12 -> 0 | V12: =(+U12*$M$6)+U12 -> 0 | ... AQ12: =(+AP12*$M$6)+AP12 -> 0
B13: Bdr | E13: =ROUNDUP(IF(OR(A13="sro",A13=0),+F13/(VLOOKUP($F$5,Rents,26)*2),IF(A13=1,+F13/(VLOOKUP($F$5,Rents,27)*2),IF(A13=2,+F13/(VLOOKUP($F$5,Rents,28)*2),IF(A13=3,+F13/(VLOOKUP($F$5,Rents,29)*2),IF(A13=4,+F13/(VLOOKUP($F$5,Rents,30)*2),IF(A13=5,+F13/(VLOOKUP($F$5,Rents,31)*2),0)))))),3)*100 -> #N/A | G13: - | I13: = | J13: =F13-H13 -> 0 | K13: X 12 | M13: = | N13: =J13*L13*12 -> 0 | O13: =(+N13*$M$6)+N13 -> 0 | P13: =(+O13*$M$6)+O13 -> 0 | Q13: =(+P13*$M$6)+P13 -> 0 | R13: =(+Q13*$M$6)+Q13 -> 0 | S13: =(+R13*$M$6)+R13 -> 0 | T13: =(+S13*$M$6)+S13 -> 0 | U13: =(+T13*$M$6)+T13 -> 0 | V13: =(+U13*$M$6)+U13 -> 0 | ... AQ13: =(+AP13*$M$6)+AP13 -> 0
B14: Bdr | E14: =ROUNDUP(IF(OR(A14="sro",A14=0),+F14/(VLOOKUP($F$5,Rents,26)*2),IF(A14=1,+F14/(VLOOKUP($F$5,Rents,27)*2),IF(A14=2,+F14/(VLOOKUP($F$5,Rents,28)*2),IF(A14=3,+F14/(VLOOKUP($F$5,Rents,29)*2),IF(A14=4,+F14/(VLOOKUP($F$5,Rents,30)*2),IF(A14=5,+F14/(VLOOKUP($F$5,Rents,31)*2),0)))))),3)*100 -> #N/A | G14: - | I14: = | J14: =F14-H14 -> 0 | K14: X 12 | M14: = | N14: =J14*L14*12 -> 0 | O14: =(+N14*$M$6)+N14 -> 0 | P14: =(+O14*$M$6)+O14 -> 0 | Q14: =(+P14*$M$6)+P14 -> 0 | R14: =(+Q14*$M$6)+Q14 -> 0 | S14: =(+R14*$M$6)+R14 -> 0 | T14: =(+S14*$M$6)+S14 -> 0 | U14: =(+T14*$M$6)+T14 -> 0 | V14: =(+U14*$M$6)+U14 -> 0 | ... AQ14: =(+AP14*$M$6)+AP14 -> 0
B15: Bdr | E15: =ROUNDUP(IF(OR(A15="sro",A15=0),+F15/(VLOOKUP($F$5,Rents,26)*2),IF(A15=1,+F15/(VLOOKUP($F$5,Rents,27)*2),IF(A15=2,+F15/(VLOOKUP($F$5,Rents,28)*2),IF(A15=3,+F15/(VLOOKUP($F$5,Rents,29)*2),IF(A15=4,+F15/(VLOOKUP($F$5,Rents,30)*2),IF(A15=5,+F15/(VLOOKUP($F$5,Rents,31)*2),0)))))),3)*100 -> #N/A | G15: - | I15: = | J15: =F15-H15 -> 0 | K15: X 12 | M15: = | N15: =J15*L15*12 -> 0 | O15: =(+N15*$M$6)+N15 -> 0 | P15: =(+O15*$M$6)+O15 -> 0 | Q15: =(+P15*$M$6)+P15 -> 0 | R15: =(+Q15*$M$6)+Q15 -> 0 | S15: =(+R15*$M$6)+R15 -> 0 | T15: =(+S15*$M$6)+S15 -> 0 | U15: =(+T15*$M$6)+T15 -> 0 | V15: =(+U15*$M$6)+U15 -> 0 | ... AQ15: =(+AP15*$M$6)+AP15 -> 0
B16: Bdr | E16: =ROUNDUP(IF(OR(A16="sro",A16=0),+F16/(VLOOKUP($F$5,Rents,26)*2),IF(A16=1,+F16/(VLOOKUP($F$5,Rents,27)*2),IF(A16=2,+F16/(VLOOKUP($F$5,Rents,28)*2),IF(A16=3,+F16/(VLOOKUP($F$5,Rents,29)*2),IF(A16=4,+F16/(VLOOKUP($F$5,Rents,30)*2),IF(A16=5,+F16/(VLOOKUP($F$5,Rents,31)*2),0)))))),3)*100 -> #N/A | G16: - | I16: = | J16: =F16-H16 -> 0 | K16: X 12 | M16: = | N16: =J16*L16*12 -> 0 | O16: =(+N16*$M$6)+N16 -> 0 | P16: =(+O16*$M$6)+O16 -> 0 | Q16: =(+P16*$M$6)+P16 -> 0 | R16: =(+Q16*$M$6)+Q16 -> 0 | S16: =(+R16*$M$6)+R16 -> 0 | T16: =(+S16*$M$6)+S16 -> 0 | U16: =(+T16*$M$6)+T16 -> 0 | V16: =(+U16*$M$6)+U16 -> 0 | ... AQ16: =(+AP16*$M$6)+AP16 -> 0
B17: Bdr | E17: =ROUNDUP(IF(OR(A17="sro",A17=0),+F17/(VLOOKUP($F$5,Rents,26)*2),IF(A17=1,+F17/(VLOOKUP($F$5,Rents,27)*2),IF(A17=2,+F17/(VLOOKUP($F$5,Rents,28)*2),IF(A17=3,+F17/(VLOOKUP($F$5,Rents,29)*2),IF(A17=4,+F17/(VLOOKUP($F$5,Rents,30)*2),IF(A17=5,+F17/(VLOOKUP($F$5,Rents,31)*2),0)))))),3)*100 -> #N/A | G17: - | I17: = | J17: =F17-H17 -> 0 | K17: X 12 | M17: = | N17: =J17*L17*12 -> 0 | O17: =(+N17*$M$6)+N17 -> 0 | P17: =(+O17*$M$6)+O17 -> 0 | Q17: =(+P17*$M$6)+P17 -> 0 | R17: =(+Q17*$M$6)+Q17 -> 0 | S17: =(+R17*$M$6)+R17 -> 0 | T17: =(+S17*$M$6)+S17 -> 0 | U17: =(+T17*$M$6)+T17 -> 0 | V17: =(+U17*$M$6)+U17 -> 0 | ... AQ17: =(+AP17*$M$6)+AP17 -> 0
B18: Bdr | E18: =ROUNDUP(IF(OR(A18="sro",A18=0),+F18/(VLOOKUP($F$5,Rents,26)*2),IF(A18=1,+F18/(VLOOKUP($F$5,Rents,27)*2),IF(A18=2,+F18/(VLOOKUP($F$5,Rents,28)*2),IF(A18=3,+F18/(VLOOKUP($F$5,Rents,29)*2),IF(A18=4,+F18/(VLOOKUP($F$5,Rents,30)*2),IF(A18=5,+F18/(VLOOKUP($F$5,Rents,31)*2),0)))))),3)*100 -> #N/A | G18: - | I18: = | J18: =F18-H18 -> 0 | K18: X 12 | M18: = | N18: =J18*L18*12 -> 0 | O18: =(+N18*$M$6)+N18 -> 0 | P18: =(+O18*$M$6)+O18 -> 0 | Q18: =(+P18*$M$6)+P18 -> 0 | R18: =(+Q18*$M$6)+Q18 -> 0 | S18: =(+R18*$M$6)+R18 -> 0 | T18: =(+S18*$M$6)+S18 -> 0 | U18: =(+T18*$M$6)+T18 -> 0 | V18: =(+U18*$M$6)+U18 -> 0 | ... AQ18: =(+AP18*$M$6)+AP18 -> 0
B19: Bdr | E19: =ROUNDUP(IF(OR(A19="sro",A19=0),+F19/(VLOOKUP($F$5,Rents,26)*2),IF(A19=1,+F19/(VLOOKUP($F$5,Rents,27)*2),IF(A19=2,+F19/(VLOOKUP($F$5,Rents,28)*2),IF(A19=3,+F19/(VLOOKUP($F$5,Rents,29)*2),IF(A19=4,+F19/(VLOOKUP($F$5,Rents,30)*2),IF(A19=5,+F19/(VLOOKUP($F$5,Rents,31)*2),0)))))),3)*100 -> #N/A | G19: - | I19: = | J19: =F19-H19 -> 0 | K19: X 12 | M19: = | N19: =J19*L19*12 -> 0 | O19: =(+N19*$M$6)+N19 -> 0 | P19: =(+O19*$M$6)+O19 -> 0 | Q19: =(+P19*$M$6)+P19 -> 0 | R19: =(+Q19*$M$6)+Q19 -> 0 | S19: =(+R19*$M$6)+R19 -> 0 | T19: =(+S19*$M$6)+S19 -> 0 | U19: =(+T19*$M$6)+T19 -> 0 | V19: =(+U19*$M$6)+U19 -> 0 | ... AQ19: =(+AP19*$M$6)+AP19 -> 0
B20: Bdr | E20: =ROUNDUP(IF(OR(A20="sro",A20=0),+F20/(VLOOKUP($F$5,Rents,26)*2),IF(A20=1,+F20/(VLOOKUP($F$5,Rents,27)*2),IF(A20=2,+F20/(VLOOKUP($F$5,Rents,28)*2),IF(A20=3,+F20/(VLOOKUP($F$5,Rents,29)*2),IF(A20=4,+F20/(VLOOKUP($F$5,Rents,30)*2),IF(A20=5,+F20/(VLOOKUP($F$5,Rents,31)*2),0)))))),3)*100 -> #N/A | G20: - | I20: = | J20: =F20-H20 -> 0 | K20: X 12 | M20: = | N20: =J20*L20*12 -> 0 | O20: =(+N20*$M$6)+N20 -> 0 | P20: =(+O20*$M$6)+O20 -> 0 | Q20: =(+P20*$M$6)+P20 -> 0 | R20: =(+Q20*$M$6)+Q20 -> 0 | S20: =(+R20*$M$6)+R20 -> 0 | T20: =(+S20*$M$6)+S20 -> 0 | U20: =(+T20*$M$6)+T20 -> 0 | V20: =(+U20*$M$6)+U20 -> 0 | ... AQ20: =(+AP20*$M$6)+AP20 -> 0
B21: Bdr | E21: =ROUNDUP(IF(OR(A21="sro",A21=0),+F21/(VLOOKUP($F$5,Rents,26)*2),IF(A21=1,+F21/(VLOOKUP($F$5,Rents,27)*2),IF(A21=2,+F21/(VLOOKUP($F$5,Rents,28)*2),IF(A21=3,+F21/(VLOOKUP($F$5,Rents,29)*2),IF(A21=4,+F21/(VLOOKUP($F$5,Rents,30)*2),IF(A21=5,+F21/(VLOOKUP($F$5,Rents,31)*2),0)))))),3)*100 -> #N/A | G21: - | I21: = | J21: =F21-H21 -> 0 | K21: X 12 | M21: = | N21: =J21*L21*12 -> 0 | O21: =(+N21*$M$6)+N21 -> 0 | P21: =(+O21*$M$6)+O21 -> 0 | Q21: =(+P21*$M$6)+P21 -> 0 | R21: =(+Q21*$M$6)+Q21 -> 0 | S21: =(+R21*$M$6)+R21 -> 0 | T21: =(+S21*$M$6)+S21 -> 0 | U21: =(+T21*$M$6)+T21 -> 0 | V21: =(+U21*$M$6)+U21 -> 0 | ... AQ21: =(+AP21*$M$6)+AP21 -> 0
... B23: Bdr | E23: =ROUNDUP(IF(OR(A23="sro",A23=0),+F23/(VLOOKUP($F$5,Rents,26)*2),IF(A23=1,+F23/(VLOOKUP($F$5,Rents,27)*2),IF(A23=2,+F23/(VLOOKUP($F$5,Rents,28)*2),IF(A23=3,+F23/(VLOOKUP($F$5,Rents,29)*2),IF(A23=4,+F23/(VLOOKUP($F$5,Rents,30)*2),IF(A23=5,+F23/(VLOOKUP($F$5,Rents,31)*2),0)))))),3)*100 -> #N/A | G23: - | I23: = | J23: =F23-H23 -> 0 | K23: X 12 | M23: = | N23: =J23*L23*12 -> 0 | O23: =(+N23*$M$6)+N23 -> 0 | P23: =(+O23*$M$6)+O23 -> 0 | Q23: =(+P23*$M$6)+P23 -> 0 | R23: =(+Q23*$M$6)+Q23 -> 0 | S23: =(+R23*$M$6)+R23 -> 0 | T23: =(+S23*$M$6)+S23 -> 0 | U23: =(+T23*$M$6)+T23 -> 0 | V23: =(+U23*$M$6)+U23 -> 0 | ... AQ23: =(+AP23*$M$6)+AP23 -> 0
A25: SUB-TOTALS | L25: =SUM(L10:L24) -> 0 | M25: = | N25: =SUM(N10:N24) -> 0 | O25: =SUM(O10:O24) -> 0 | P25: =SUM(P10:P24) -> 0 | Q25: =SUM(Q10:Q24) -> 0 | R25: =SUM(R10:R24) -> 0 | S25: =SUM(S10:S24) -> 0 | T25: =SUM(T10:T24) -> 0 | U25: =SUM(U10:U24) -> 0 | ... AQ25: =SUM(AQ10:AQ24) -> 0
A27: Other Revenue:
A29: Laundry | O29: =(+N29*$M$6)+N29 -> 0 | P29: =(+O29*$M$6)+O29 -> 0 | Q29: =(+P29*$M$6)+P29 -> 0 | R29: =(+Q29*$M$6)+Q29 -> 0 | S29: =(+R29*$M$6)+R29 -> 0 | T29: =(+S29*$M$6)+S29 -> 0 | U29: =(+T29*$M$6)+T29 -> 0 | V29: =(+U29*$M$6)+U29 -> 0 | ... AQ29: =(+AP29*$M$6)+AP29 -> 0
A30: Parking | O30: =(+N30*$M$6)+N30 -> 0 | P30: =(+O30*$M$6)+O30 -> 0 | Q30: =(+P30*$M$6)+P30 -> 0 | R30: =(+Q30*$M$6)+Q30 -> 0 | S30: =(+R30*$M$6)+R30 -> 0 | T30: =(+S30*$M$6)+S30 -> 0 | U30: =(+T30*$M$6)+T30 -> 0 | V30: =(+U30*$M$6)+U30 -> 0 | ... AQ30: =(+AP30*$M$6)+AP30 -> 0
A31: Utility Reimbursements | O31: =(+N31*$M$6)+N31 -> 0 | P31: =(+O31*$M$6)+O31 -> 0 | Q31: =(+P31*$M$6)+P31 -> 0 | R31: =(+Q31*$M$6)+Q31 -> 0 | S31: =(+R31*$M$6)+R31 -> 0 | T31: =(+S31*$M$6)+S31 -> 0 | U31: =(+T31*$M$6)+T31 -> 0 | V31: =(+U31*$M$6)+U31 -> 0 | ... AQ31: =(+AP31*$M$6)+AP31 -> 0
A32: Miscellaneous Fees | O32: =(+N32*$M$6)+N32 -> 0 | P32: =(+O32*$M$6)+O32 -> 0 | Q32: =(+P32*$M$6)+P32 -> 0 | R32: =(+Q32*$M$6)+Q32 -> 0 | S32: =(+R32*$M$6)+R32 -> 0 | T32: =(+S32*$M$6)+S32 -> 0 | U32: =(+T32*$M$6)+T32 -> 0 | V32: =(+U32*$M$6)+U32 -> 0 | ... AQ32: =(+AP32*$M$6)+AP32 -> 0
A33: Service Income | O33: =(+N33*$M$6)+N33 -> 0 | P33: =(+O33*$M$6)+O33 -> 0 | Q33: =(+P33*$M$6)+P33 -> 0 | R33: =(+Q33*$M$6)+Q33 -> 0 | S33: =(+R33*$M$6)+R33 -> 0 | T33: =(+S33*$M$6)+S33 -> 0 | U33: =(+T33*$M$6)+T33 -> 0 | V33: =(+U33*$M$6)+U33 -> 0 | ... AQ33: =(+AP33*$M$6)+AP33 -> 0
A34: Other Income | O34: =(+N34*$M$6)+N34 -> 0 | P34: =(+O34*$M$6)+O34 -> 0 | Q34: =(+P34*$M$6)+P34 -> 0 | R34: =(+Q34*$M$6)+Q34 -> 0 | S34: =(+R34*$M$6)+R34 -> 0 | T34: =(+S34*$M$6)+S34 -> 0 | U34: =(+T34*$M$6)+T34 -> 0 | V34: =(+U34*$M$6)+U34 -> 0 | ... AQ34: =(+AP34*$M$6)+AP34 -> 0
A36: SUB-TOTAL OTHER REVENUE | N36: =SUM(N26:N35) -> 0 | O36: =SUM(O26:O35) -> 0 | P36: =SUM(P26:P35) -> 0 | Q36: =SUM(Q26:Q35) -> 0 | R36: =SUM(R26:R35) -> 0 | S36: =SUM(S26:S35) -> 0 | T36: =SUM(T26:T35) -> 0 | U36: =SUM(U26:U35) -> 0 | ... AQ36: =SUM(AQ26:AQ35) -> 0
A38: Gross Income: | N38: =N25+N36 -> 0 | O38: =O25+O36 -> 0 | P38: =P25+P36 -> 0 | Q38: =Q25+Q36 -> 0 | R38: =R25+R36 -> 0 | S38: =S25+S36 -> 0 | T38: =T25+T36 -> 0 | U38: =U25+U36 -> 0 | ... AQ38: =AQ25+AQ36 -> 0
A40: Less Vacancy Rate | E40: 0.05 | N40: =-N38*$E$40 -> 0 | O40: =-O38*$E$40 -> 0 | P40: =-P38*$E$40 -> 0 | Q40: =-Q38*$E$40 -> 0 | R40: =-R38*$E$40 -> 0 | S40: =-S38*$E$40 -> 0 | T40: =-T38*$E$40 -> 0 | U40: =-U38*$E$40 -> 0 | ... AQ40: =-AQ38*$E$40 -> 0
A42: Effective Gross Income (Residential): | N42: =N38+N40 -> 0 | O42: =O38+O40 -> 0 | P42: =P38+P40 -> 0 | Q42: =Q38+Q40 -> 0 | R42: =R38+R40 -> 0 | S42: =S38+S40 -> 0 | T42: =T38+T40 -> 0 | U42: =U38+U40 -> 0 | ... AQ42: =AQ38+AQ40 -> 0
N44: =-N42*$E$44 -> 0 | O44: =-O42*$E$44 -> 0 | P44: =-P42*$E$44 -> 0 | Q44: =-Q42*$E$44 -> 0 | R44: =-R42*$E$44 -> 0 | S44: =-S42*$E$44 -> 0 | T44: =-T42*$E$44 -> 0 | U44: =-U42*$E$44 -> 0 | ... AQ44: =-AQ42*$E$44 -> 0
A45: Commercial:
A46: ANNUAL Commercial Income (Enter on Comm Income Tab, uses escalator on this tab):
A48: Commercial Income: | N48: ='Comm Income'!H11 -> 0 | O48: =(+N48*$M$6)+N48 -> 0 | P48: =(+O48*$M$6)+O48 -> 0 | Q48: =(+P48*$M$6)+P48 -> 0 | R48: =(+Q48*$M$6)+Q48 -> 0 | S48: =(+R48*$M$6)+R48 -> 0 | T48: =(+S48*$M$6)+S48 -> 0 | U48: =(+T48*$M$6)+T48 -> 0 | V48: =(+U48*$M$6)+U48 -> 0 | ... AQ48: =(+AP48*$M$6)+AP48 -> 0
A49: ='Comm Income'!A12 -> Other: | N49: ='Comm Income'!H12 -> 0 | O49: =(+N49*$M$6)+N49 -> 0 | P49: =(+O49*$M$6)+O49 -> 0 | Q49: =(+P49*$M$6)+P49 -> 0 | R49: =(+Q49*$M$6)+Q49 -> 0 | S49: =(+R49*$M$6)+R49 -> 0 | T49: =(+S49*$M$6)+S49 -> 0 | U49: =(+T49*$M$6)+T49 -> 0 | V49: =(+U49*$M$6)+U49 -> 0 | ... AQ49: =(+AP49*$M$6)+AP49 -> 0
A50: ='Comm Income'!A13 -> Other: | N50: ='Comm Income'!H13 -> 0 | O50: =(+N50*$M$6)+N50 -> 0 | P50: =(+O50*$M$6)+O50 -> 0 | Q50: =(+P50*$M$6)+P50 -> 0 | R50: =(+Q50*$M$6)+Q50 -> 0 | S50: =(+R50*$M$6)+R50 -> 0 | T50: =(+S50*$M$6)+S50 -> 0 | U50: =(+T50*$M$6)+T50 -> 0 | V50: =(+U50*$M$6)+U50 -> 0 | ... AQ50: =(+AP50*$M$6)+AP50 -> 0
A51: ='Comm Income'!A14 -> Other: | N51: ='Comm Income'!H14 -> 0 | O51: =(+N51*$M$6)+N51 -> 0 | P51: =(+O51*$M$6)+O51 -> 0 | Q51: =(+P51*$M$6)+P51 -> 0 | R51: =(+Q51*$M$6)+Q51 -> 0 | S51: =(+R51*$M$6)+R51 -> 0 | T51: =(+S51*$M$6)+S51 -> 0 | U51: =(+T51*$M$6)+T51 -> 0 | V51: =(+U51*$M$6)+U51 -> 0 | ... AQ51: =(+AP51*$M$6)+AP51 -> 0
A52: ='Comm Income'!A15 -> Other: | N52: ='Comm Income'!H15 -> 0 | O52: =(+N52*$M$6)+N52 -> 0 | P52: =(+O52*$M$6)+O52 -> 0 | Q52: =(+P52*$M$6)+P52 -> 0 | R52: =(+Q52*$M$6)+Q52 -> 0 | S52: =(+R52*$M$6)+R52 -> 0 | T52: =(+S52*$M$6)+S52 -> 0 | U52: =(+T52*$M$6)+T52 -> 0 | V52: =(+U52*$M$6)+U52 -> 0 | ... AQ52: =(+AP52*$M$6)+AP52 -> 0
...

Sheet Expenses
B2: use purple line items for streamlined compliance reporting only
A3: HOUSING OPERATING BUDGET - EXPENSES
B5: Project Name: | C5: =Sources!$B$3 -> 0
B7: Date: | C7: =Sources!F3 -> 40909 | F7: Annual Inflation Rate Factor: | G7: 0.03
A9: Annual Operating Expenses | D9: Annual per Unit | E9: 1 | F9: 2 | G9: 3 | H9: 4 | I9: 5 | J9: 6 | K9: 7 | L9: 8 | M9: 9 | N9: 10 | O9: 11 | P9: 12 | Q9: 13 | R9: 14 | S9: 15 | T9: 16 | U9: 17 | V9: 18 | W9: 19 | X9: 20 | Y9: 21 | Z9: 22 | AA9: 23 | AB9: 24 | AC9: 25 | AD9: 26 | AE9: 27 | AF9: 28 | AG9: 29 | AH9: 30
A11: Property Management:
B12: On-site | D12: =E12/Income!$L$25 -> #DIV/0! | F12: =(+E12*$G$7)+E12 -> 0 | G12: =(+F12*$G$7)+F12 -> 0 | H12: =(+G12*$G$7)+G12 -> 0 | I12: =(+H12*$G$7)+H12 -> 0 | J12: =(+I12*$G$7)+I12 -> 0 | K12: =(+J12*$G$7)+J12 -> 0 | L12: =(+K12*$G$7)+K12 -> 0 | M12: =(+L12*$G$7)+L12 -> 0 | ... AH12: =(+AG12*$G$7)+AG12 -> 0
B13: On-site (resident mgr/other adm unit) | D13: =E13/Income!$L$25 -> #DIV/0! | F13: =(+E13*$G$7)+E13 -> 0 | G13: =(+F13*$G$7)+F13 -> 0 | H13: =(+G13*$G$7)+G13 -> 0 | I13: =(+H13*$G$7)+H13 -> 0 | J13: =(+I13*$G$7)+I13 -> 0 | K13: =(+J13*$G$7)+J13 -> 0 | L13: =(+K13*$G$7)+K13 -> 0 | M13: =(+L13*$G$7)+L13 -> 0 | ... AH13: =(+AG13*$G$7)+AG13 -> 0
B14: Contracted (Off-Site) | D14: =E14/Income!$L$25 -> #DIV/0! | F14: =(+E14*$G$7)+E14 -> 0 | G14: =(+F14*$G$7)+F14 -> 0 | H14: =(+G14*$G$7)+G14 -> 0 | I14: =(+H14*$G$7)+H14 -> 0 | J14: =(+I14*$G$7)+I14 -> 0 | K14: =(+J14*$G$7)+J14 -> 0 | L14: =(+K14*$G$7)+K14 -> 0 | M14: =(+L14*$G$7)+L14 -> 0 | ... AH14: =(+AG14*$G$7)+AG14 -> 0
A16: Professional Services - Legal/Audit/Accounting | D16: =E16/Income!$L$25 -> #DIV/0! | F16: =(+E16*$G$7)+E16 -> 0 | G16: =(+F16*$G$7)+F16 -> 0 | H16: =(+G16*$G$7)+G16 -> 0 | I16: =(+H16*$G$7)+H16 -> 0 | J16: =(+I16*$G$7)+I16 -> 0 | K16: =(+J16*$G$7)+J16 -> 0 | L16: =(+K16*$G$7)+K16 -> 0 | M16: =(+L16*$G$7)+L16 -> 0 | ... AH16: =(+AG16*$G$7)+AG16 -> 0
A18: Office & Administration | D18: =E18/Income!$L$25 -> #DIV/0! | F18: =(+E18*$G$7)+E18 -> 0 | G18: =(+F18*$G$7)+F18 -> 0 | H18: =(+G18*$G$7)+G18 -> 0 | I18: =(+H18*$G$7)+H18 -> 0 | J18: =(+I18*$G$7)+I18 -> 0 | K18: =(+J18*$G$7)+J18 -> 0 | L18: =(+K18*$G$7)+K18 -> 0 | M18: =(+L18*$G$7)+L18 -> 0 | ... AH18: =(+AG18*$G$7)+AG18 -> 0
A20: Advertising/Marketing & Promotion | D20: =E20/Income!$L$25 -> #DIV/0! | F20: =(+E20*$G$7)+E20 -> 0 | G20: =(+F20*$G$7)+F20 -> 0 | H20: =(+G20*$G$7)+G20 -> 0 | I20: =(+H20*$G$7)+H20 -> 0 | J20: =(+I20*$G$7)+I20 -> 0 | K20: =(+J20*$G$7)+J20 -> 0 | L20: =(+K20*$G$7)+K20 -> 0 | M20: =(+L20*$G$7)+L20 -> 0 | ... AH20: =(+AG20*$G$7)+AG20 -> 0
A22: Residential Bad Debt | D22: =E22/Income!$L$25 -> #DIV/0! | F22: =(+E22*$G$7)+E22 -> 0 | G22: =(+F22*$G$7)+F22 -> 0 | H22: =(+G22*$G$7)+G22 -> 0 | I22: =(+H22*$G$7)+H22 -> 0 | J22: =(+I22*$G$7)+I22 -> 0 | K22: =(+J22*$G$7)+J22 -> 0 | L22: =(+K22*$G$7)+K22 -> 0 | M22: =(+L22*$G$7)+L22 -> 0 | ... AH22: =(+AG22*$G$7)+AG22 -> 0
A24: Commercial Bad Debt | D24: =E24/Income!$L$25 -> #DIV/0! | F24: =(+E24*$G$7)+E24 -> 0 | G24: =(+F24*$G$7)+F24 -> 0 | H24: =(+G24*$G$7)+G24 -> 0 | I24: =(+H24*$G$7)+H24 -> 0 | J24: =(+I24*$G$7)+I24 -> 0 | K24: =(+J24*$G$7)+J24 -> 0 | L24: =(+K24*$G$7)+K24 -> 0 | M24: =(+L24*$G$7)+L24 -> 0 | ... AH24: =(+AG24*$G$7)+AG24 -> 0
A26: Security | D26: =E26/Income!$L$25 -> #DIV/0! | F26: =(+E26*$G$7)+E26 -> 0 | G26: =(+F26*$G$7)+F26 -> 0 | H26: =(+G26*$G$7)+G26 -> 0 | I26: =(+H26*$G$7)+H26 -> 0 | J26: =(+I26*$G$7)+I26 -> 0 | K26: =(+J26*$G$7)+J26 -> 0 | L26: =(+K26*$G$7)+K26 -> 0 | M26: =(+L26*$G$7)+L26 -> 0 | ... AH26: =(+AG26*$G$7)+AG26 -> 0
A28: Repairs:
B29: Repairs & Maint performed under contract | D29: =E29/Income!$L$25 -> #DIV/0! | F29: =(+E29*$G$7)+E29 -> 0 | G29: =(+F29*$G$7)+F29 -> 0 | H29: =(+G29*$G$7)+G29 -> 0 | I29: =(+H29*$G$7)+H29 -> 0 | J29: =(+I29*$G$7)+I29 -> 0 | K29: =(+J29*$G$7)+J29 -> 0 | L29: =(+K29*$G$7)+K29 -> 0 | M29: =(+L29*$G$7)+L29 -> 0 | ... AH29: =(+AG29*$G$7)+AG29 -> 0
B30: Repairs & Maint performed by property mgmt staff | D30: =E30/Income!$L$25 -> #DIV/0! | F30: =(+E30*$G$7)+E30 -> 0 | G30: =(+F30*$G$7)+F30 -> 0 | H30: =(+G30*$G$7)+G30 -> 0 | I30: =(+H30*$G$7)+H30 -> 0 | J30: =(+I30*$G$7)+I30 -> 0 | K30: =(+J30*$G$7)+J30 -> 0 | L30: =(+K30*$G$7)+K30 -> 0 | M30: =(+L30*$G$7)+L30 -> 0 | ... AH30: =(+AG30*$G$7)+AG30 -> 0
A32: Unit Turnover:
B33: Turnover performed under contract | D33: =E33/Income!$L$25 -> #DIV/0! | F33: =(+E33*$G$7)+E33 -> 0 | G33: =(+F33*$G$7)+F33 -> 0 | H33: =(+G33*$G$7)+G33 -> 0 | I33: =(+H33*$G$7)+H33 -> 0 | J33: =(+I33*$G$7)+I33 -> 0 | K33: =(+J33*$G$7)+J33 -> 0 | L33: =(+K33*$G$7)+K33 -> 0 | M33: =(+L33*$G$7)+L33 -> 0 | ... AH33: =(+AG33*$G$7)+AG33 -> 0
B34: Turnover performed by property mgmt staff | D34: =E34/Income!$L$25 -> #DIV/0! | F34: =(+E34*$G$7)+E34 -> 0 | G34: =(+F34*$G$7)+F34 -> 0 | H34: =(+G34*$G$7)+G34 -> 0 | I34: =(+H34*$G$7)+H34 -> 0 | J34: =(+I34*$G$7)+I34 -> 0 | K34: =(+J34*$G$7)+J34 -> 0 | L34: =(+K34*$G$7)+K34 -> 0 | M34: =(+L34*$G$7)+L34 -> 0 | ... AH34: =(+AG34*$G$7)+AG34 -> 0
A36: Elevator | D36: =E36/Income!$L$25 -> #DIV/0! | F36: =(+E36*$G$7)+E36 -> 0 | G36: =(+F36*$G$7)+F36 -> 0 | H36: =(+G36*$G$7)+G36 -> 0 | I36: =(+H36*$G$7)+H36 -> 0 | J36: =(+I36*$G$7)+I36 -> 0 | K36: =(+J36*$G$7)+J36 -> 0 | L36: =(+K36*$G$7)+K36 -> 0 | M36: =(+L36*$G$7)+L36 -> 0 | ... AH36: =(+AG36*$G$7)+AG36 -> 0
A38: Landscaping | D38: =E38/Income!$L$25 -> #DIV/0! | F38: =(+E38*$G$7)+E38 -> 0 | G38: =(+F38*$G$7)+F38 -> 0 | H38: =(+G38*$G$7)+G38 -> 0 | I38: =(+H38*$G$7)+H38 -> 0 | J38: =(+I38*$G$7)+I38 -> 0 | K38: =(+J38*$G$7)+J38 -> 0 | L38: =(+K38*$G$7)+K38 -> 0 | M38: =(+L38*$G$7)+L38 -> 0 | ... AH38: =(+AG38*$G$7)+AG38 -> 0
A40: Utilities:
B41: Electric | D41: =E41/Income!$L$25 -> #DIV/0! | F41: =(+E41*$G$7)+E41 -> 0 | G41: =(+F41*$G$7)+F41 -> 0 | H41: =(+G41*$G$7)+G41 -> 0 | I41: =(+H41*$G$7)+H41 -> 0 | J41: =(+I41*$G$7)+I41 -> 0 | K41: =(+J41*$G$7)+J41 -> 0 | L41: =(+K41*$G$7)+K41 -> 0 | M41: =(+L41*$G$7)+L41 -> 0 | ... AH41: =(+AG41*$G$7)+AG41 -> 0
B42: Natural Gas | D42: =E42/Income!$L$25 -> #DIV/0! | F42: =(+E42*$G$7)+E42 -> 0 | G42: =(+F42*$G$7)+F42 -> 0 | H42: =(+G42*$G$7)+G42 -> 0 | I42: =(+H42*$G$7)+H42 -> 0 | J42: =(+I42*$G$7)+I42 -> 0 | K42: =(+J42*$G$7)+J42 -> 0 | L42: =(+K42*$G$7)+K42 -> 0 | M42: =(+L42*$G$7)+L42 -> 0 | ... AH42: =(+AG42*$G$7)+AG42 -> 0
B43: Water & Sewer | D43: =E43/Income!$L$25 -> #DIV/0! | F43: =(+E43*$G$7)+E43 -> 0 | G43: =(+F43*$G$7)+F43 -> 0 | H43: =(+G43*$G$7)+G43 -> 0 | I43: =(+H43*$G$7)+H43 -> 0 | J43: =(+I43*$G$7)+I43 -> 0 | K43: =(+J43*$G$7)+J43 -> 0 | L43: =(+K43*$G$7)+K43 -> 0 | M43: =(+L43*$G$7)+L43 -> 0 | ... AH43: =(+AG43*$G$7)+AG43 -> 0
B44: Garbage Removal | D44: =E44/Income!$L$25 -> #DIV/0! | F44: =(+E44*$G$7)+E44 -> 0 | G44: =(+F44*$G$7)+F44 -> 0 | H44: =(+G44*$G$7)+G44 -> 0 | I44: =(+H44*$G$7)+H44 -> 0 | J44: =(+I44*$G$7)+I44 -> 0 | K44: =(+J44*$G$7)+J44 -> 0 | L44: =(+K44*$G$7)+K44 -> 0 | M44: =(+L44*$G$7)+L44 -> 0 | ... AH44: =(+AG44*$G$7)+AG44 -> 0
B45: Other Utilities: | D45: =E45/Income!$L$25 -> #DIV/0! | F45: =(+E45*$G$7)+E45 -> 0 | G45: =(+F45*$G$7)+F45 -> 0 | H45: =(+G45*$G$7)+G45 -> 0 | I45: =(+H45*$G$7)+H45 -> 0 | J45: =(+I45*$G$7)+I45 -> 0 | K45: =(+J45*$G$7)+J45 -> 0 | L45: =(+K45*$G$7)+K45 -> 0 | M45: =(+L45*$G$7)+L45 -> 0 | ... AH45: =(+AG45*$G$7)+AG45 -> 0
A47: Real Estate Taxes | D47: =E47/Income!$L$25 -> #DIV/0! | F47: =(+E47*$G$7)+E47 -> 0 | G47: =(+F47*$G$7)+F47 -> 0 | H47: =(+G47*$G$7)+G47 -> 0 | I47: =(+H47*$G$7)+H47 -> 0 | J47: =(+I47*$G$7)+I47 -> 0 | K47: =(+J47*$G$7)+J47 -> 0 | L47: =(+K47*$G$7)+K47 -> 0 | M47: =(+L47*$G$7)+L47 -> 0 | ... AH47: =(+AG47*$G$7)+AG47 -> 0
A49: Insurance | D49: =E49/Income!$L$25 -> #DIV/0! | F49: =(+E49*$G$7)+E49 -> 0 | G49: =(+F49*$G$7)+F49 -> 0 | H49: =(+G49*$G$7)+G49 -> 0 | I49: =(+H49*$G$7)+H49 -> 0 | J49: =(+I49*$G$7)+I49 -> 0 | K49: =(+J49*$G$7)+J49 -> 0 | L49: =(+K49*$G$7)+K49 -> 0 | M49: =(+L49*$G$7)+L49 -> 0 | ... AH49: =(+AG49*$G$7)+AG49 -> 0
A51: Compliance Monitoring Fees | D51: =E51/Income!$L$25 -> #DIV/0! | F51: =(+E51*$G$7)+E51 -> 0 | G51: =(+F51*$G$7)+F51 -> 0 | H51: =(+G51*$G$7)+G51 -> 0 | I51: =(+H51*$G$7)+H51 -> 0 | J51: =(+I51*$G$7)+I51 -> 0 | K51: =(+J51*$G$7)+J51 -> 0 | L51: =(+K51*$G$7)+K51 -> 0 | M51: =(+L51*$G$7)+L51 -> 0 | ... AH51: =(+AG51*$G$7)+AG51 -> 0
A53: Asset Management Fees | D53: =E53/Income!$L$25 -> #DIV/0! | F53: =(+E53*$G$7)+E53 -> 0 | G53: =(+F53*$G$7)+F53 -> 0 | H53: =(+G53*$G$7)+G53 -> 0 | I53: =(+H53*$G$7)+H53 -> 0 | J53: =(+I53*$G$7)+I53 -> 0 | K53: =(+J53*$G$7)+J53 -> 0 | L53: =(+K53*$G$7)+K53 -> 0 | M53: =(+L53*$G$7)+L53 -> 0 | ... AH53: =(+AG53*$G$7)+AG53 -> 0
A55: Resident Services | D55: =E55/Income!$L$25 -> #DIV/0! | F55: =(+E55*$G$7)+E55 -> 0 | G55: =(+F55*$G$7)+F55 -> 0 | H55: =(+G55*$G$7)+G55 -> 0 | I55: =(+H55*$G$7)+H55 -> 0 | J55: =(+I55*$G$7)+I55 -> 0 | K55: =(+J55*$G$7)+J55 -> 0 | L55: =(+K55*$G$7)+K55 -> 0 | M55: =(+L55*$G$7)+L55 -> 0 | ... AH55: =(+AG55*$G$7)+AG55 -> 0
A57: Gross Replacement Reserve Deposits | D57: =E57/Income!$L$25 -> #DIV/0! | F57: =(+E57*$G$7)+E57 -> 0 | G57: =(+F57*$G$7)+F57 -> 0 | H57: =(+G57*$G$7)+G57 -> 0 | I57: =(+H57*$G$7)+H57 -> 0 | J57: =(+I57*$G$7)+I57 -> 0 | K57: =(+J57*$G$7)+J57 -> 0 | L57: =(+K57*$G$7)+K57 -> 0 | M57: =(+L57*$G$7)+L57 -> 0 | ... AH57: =(+AG57*$G$7)+AG57 -> 0
A59: Commercial Expense (See Comment): | D59: 0 | F59: =(+E59*$G$7)+E59 -> 0 | G59: =(+F59*$G$7)+F59 -> 0 | H59: =(+G59*$G$7)+G59 -> 0 | I59: =(+H59*$G$7)+H59 -> 0 | J59: =(+I59*$G$7)+I59 -> 0 | K59: =(+J59*$G$7)+J59 -> 0 | L59: =(+K59*$G$7)+K59 -> 0 | M59: =(+L59*$G$7)+L59 -> 0 | ... AH59: =(+AG59*$G$7)+AG59 -> 0
A61: Other: | D61: =E61/Income!$L$25 -> #DIV/0! | F61: =(+E61*$G$7)+E61 -> 0 | G61: =(+F61*$G$7)+F61 -> 0 | H61: =(+G61*$G$7)+G61 -> 0 | I61: =(+H61*$G$7)+H61 -> 0 | J61: =(+I61*$G$7)+I61 -> 0 | K61: =(+J61*$G$7)+J61 -> 0 | L61: =(+K61*$G$7)+K61 -> 0 | M61: =(+L61*$G$7)+L61 -> 0 | ... AH61: =(+AG61*$G$7)+AG61 -> 0
A64: Total Annual Operating Expenses: | D64: =SUM(D45:D63) -> #DIV/0! | E64: =SUM(E45:E63) -> 0 | F64: =SUM(F45:F63) -> 0 | G64: =SUM(G45:G63) -> 0 | H64: =SUM(H45:H63) -> 0 | I64: =SUM(I45:I63) -> 0 | J64: =SUM(J45:J63) -> 0 | K64: =SUM(K45:K63) -> 0 | ... AH64: =SUM(AH45:AH63) -> 0
A66: Less Debt Service:
A68: Must Pay Debt (Complete for Annual Reporting): | C68: Lender:
...

Sheet Utility Allowance
A1: UTILITY ALLOWANCE INFORMATION
B3: Project Name: | C3: =Sources!$B$3 -> 0 | E3: Date: | F3: =Sources!F3 -> 40909
A5: UTILITIES | B5: TYPE OF UTILITY (Gas, elec., Oil,etc.) | C5: OWNER PAYS | D5: TENANT PAYS | E5: 0 BDRM | F5: 1 BDRM | G5: 2 BDRM | H5: 3 BDRM | I5: 4 BDRM
A7: Heating
A8: Lighting
A9: Air Conditioning
A10: Cooking
A11: Hot Water
A12: Water
A13: Sewer
A14: Trash Removal
A16: TOTAL UTILITY ALLOWANCE | E16: =SUM(E7:E15) -> 0 | F16: =SUM(F7:F15) -> 0 | G16: =SUM(G7:G15) -> 0 | H16: =SUM(H7:H15) -> 0 | I16: =SUM(I7:I15) -> 0
A19: Source of Utility Allowance Calculation: (Attach a Copy)
B21: Local Housing Authority
B22: Utility Company
B23: Other
A25: If allowances are calculated by other methods, attach the appropriate schedule and include
A26: unit rents, number of bedrooms, and allowances

Sheet Comm Income
A1: COMMERCIAL OPERATING BUDGET - INCOME
B3: Project Name: | E3: =Sources!$B$3 -> 0
D4: Date: | E4: =Sources!F3 -> 40909
D6: Annual Inflation Rate Factor: | E6: 0.02
A8: ANNUAL Commercial Income:
H9: 1 | I9: 2 | J9: 3 | K9: 4 | L9: 5 | M9: 6 | N9: 7 | O9: 8 | P9: 9 | Q9: 10 | R9: 11 | S9: 12 | T9: 13 | U9: 14 | V9: 15 | W9: 16 | X9: 17 | Y9: 18 | Z9: 19 | AA9: 20 | AB9: 21 | AC9: 22 | AD9: 23 | AE9: 24 | AF9: 25 | AG9: 26 | AH9: 27 | AI9: 28 | AJ9: 29 | AK9: 30
A11: Commercial Income: | I11: =(+H11*$E$6)+H11 -> 0 | J11: =(+I11*$E$6)+I11 -> 0 | K11: =(+J11*$E$6)+J11 -> 0 | L11: =(+K11*$E$6)+K11 -> 0 | M11: =(+L11*$E$6)+L11 -> 0 | N11: =(+M11*$E$6)+M11 -> 0 | O11: =(+N11*$E$6)+N11 -> 0 | P11: =(+O11*$E$6)+O11 -> 0 | ... AK11: =(+AJ11*$E$6)+AJ11 -> 0
A12: Other: | I12: =(+H12*$E$6)+H12 -> 0 | J12: =(+I12*$E$6)+I12 -> 0 | K12: =(+J12*$E$6)+J12 -> 0 | L12: =(+K12*$E$6)+K12 -> 0 | M12: =(+L12*$E$6)+L12 -> 0 | N12: =(+M12*$E$6)+M12 -> 0 | O12: =(+N12*$E$6)+N12 -> 0 | P12: =(+O12*$E$6)+O12 -> 0 | ... AK12: =(+AJ12*$E$6)+AJ12 -> 0
A13: Other: | I13: =(+H13*$E$6)+H13 -> 0 | J13: =(+I13*$E$6)+I13 -> 0 | K13: =(+J13*$E$6)+J13 -> 0 | L13: =(+K13*$E$6)+K13 -> 0 | M13: =(+L13*$E$6)+L13 -> 0 | N13: =(+M13*$E$6)+M13 -> 0 | O13: =(+N13*$E$6)+N13 -> 0 | P13: =(+O13*$E$6)+O13 -> 0 | ... AK13: =(+AJ13*$E$6)+AJ13 -> 0
A14: Other: | I14: =(+H14*$E$6)+H14 -> 0 | J14: =(+I14*$E$6)+I14 -> 0 | K14: =(+J14*$E$6)+J14 -> 0 | L14: =(+K14*$E$6)+K14 -> 0 | M14: =(+L14*$E$6)+L14 -> 0 | N14: =(+M14*$E$6)+M14 -> 0 | O14: =(+N14*$E$6)+N14 -> 0 | P14: =(+O14*$E$6)+O14 -> 0 | ... AK14: =(+AJ14*$E$6)+AJ14 -> 0
A15: Other: | I15: =(+H15*$E$6)+H15 -> 0 | J15: =(+I15*$E$6)+I15 -> 0 | K15: =(+J15*$E$6)+J15 -> 0 | L15: =(+K15*$E$6)+K15 -> 0 | M15: =(+L15*$E$6)+L15 -> 0 | N15: =(+M15*$E$6)+M15 -> 0 | O15: =(+N15*$E$6)+N15 -> 0 | P15: =(+O15*$E$6)+O15 -> 0 | ... AK15: =(+AJ15*$E$6)+AJ15 -> 0
A16: Other: | I16: =(+H16*$E$6)+H16 -> 0 | J16: =(+I16*$E$6)+I16 -> 0 | K16: =(+J16*$E$6)+J16 -> 0 | L16: =(+K16*$E$6)+K16 -> 0 | M16: =(+L16*$E$6)+L16 -> 0 | N16: =(+M16*$E$6)+M16 -> 0 | O16: =(+N16*$E$6)+N16 -> 0 | P16: =(+O16*$E$6)+O16 -> 0 | ... AK16: =(+AJ16*$E$6)+AJ16 -> 0
A17: Other: | I17: =(+H17*$E$6)+H17 -> 0 | J17: =(+I17*$E$6)+I17 -> 0 | K17: =(+J17*$E$6)+J17 -> 0 | L17: =(+K17*$E$6)+K17 -> 0 | M17: =(+L17*$E$6)+L17 -> 0 | N17: =(+M17*$E$6)+M17 -> 0 | O17: =(+N17*$E$6)+N17 -> 0 | P17: =(+O17*$E$6)+O17 -> 0 | ... AK17: =(+AJ17*$E$6)+AJ17 -> 0
A19: TOTAL COMMERCIAL REVENUE | H19: =SUM(H11:H18) -> 0 | I19: =SUM(I11:I18) -> 0 | J19: =SUM(J11:J18) -> 0 | K19: =SUM(K11:K18) -> 0 | L19: =SUM(L11:L18) -> 0 | M19: =SUM(M11:M18) -> 0 | N19: =SUM(N11:N18) -> 0 | O19: =SUM(O11:O18) -> 0 | ... AK19: =SUM(AK11:AK18) -> 0
A21: Less Vacancy Rate | E21: 0.1 | H21: =H19*$E$21 -> 0 | I21: =I19*$E$21 -> 0 | J21: =J19*$E$21 -> 0 | K21: =K19*$E$21 -> 0 | L21: =L19*$E$21 -> 0 | M21: =M19*$E$21 -> 0 | N21: =N19*$E$21 -> 0 | O21: =O19*$E$21 -> 0 | ... AK21: =AK19*$E$21 -> 0
A23: Effective Gross Income: | H23: =H19-H21 -> 0 | I23: =I19-I21 -> 0 | J23: =J19-J21 -> 0 | K23: =K19-K21 -> 0 | L23: =L19-L21 -> 0 | M23: =M19-M21 -> 0 | N23: =N19-N21 -> 0 | O23: =O19-O21 -> 0 | ... AK23: =AK19-AK21 -> 0

Sheet Com Expense
A3: COMMERCIAL OPERATING BUDGET - EXPENSES
B5: Project Name: | C5: =Sources!$B$3 -> 0
B7: Date: | C7: =Sources!F3 -> 40909 | E7: Annual Inflation Rate Factor: | F7: 0.03
A9: ANNUAL Operating Expenses | D9: 1 | E9: 2 | F9: 3 | G9: 4 | H9: 5 | I9: 6 | J9: 7 | K9: 8 | L9: 9 | M9: 10 | N9: 11 | O9: 12 | P9: 13 | Q9: 14 | R9: 15 | S9: 16 | T9: 17 | U9: 18 | V9: 19 | W9: 20 | X9: 21 | Y9: 22 | Z9: 23 | AA9: 24 | AB9: 25 | AC9: 26 | AD9: 27 | AE9: 28 | AF9: 29 | AG9: 30
A11: Insurance | E11: =(+D11*$F$7)+D11 -> 0 | F11: =(+E11*$F$7)+E11 -> 0 | G11: =(+F11*$F$7)+F11 -> 0 | H11: =(+G11*$F$7)+G11 -> 0 | I11: =(+H11*$F$7)+H11 -> 0 | J11: =(+I11*$F$7)+I11 -> 0 | K11: =(+J11*$F$7)+J11 -> 0 | L11: =(+K11*$F$7)+K11 -> 0 | ... AG11: =(+AF11*$F$7)+AF11 -> 0
A13: Utilities:(common areas)
B14: Gas/Oil | E14: =(+D14*$F$7)+D14 -> 0 | F14: =(+E14*$F$7)+E14 -> 0 | G14: =(+F14*$F$7)+F14 -> 0 | H14: =(+G14*$F$7)+G14 -> 0 | I14: =(+H14*$F$7)+H14 -> 0 | J14: =(+I14*$F$7)+I14 -> 0 | K14: =(+J14*$F$7)+J14 -> 0 | L14: =(+K14*$F$7)+K14 -> 0 | ... AG14: =(+AF14*$F$7)+AF14 -> 0
B15: Electric | E15: =(+D15*$F$7)+D15 -> 0 | F15: =(+E15*$F$7)+E15 -> 0 | G15: =(+F15*$F$7)+F15 -> 0 | H15: =(+G15*$F$7)+G15 -> 0 | I15: =(+H15*$F$7)+H15 -> 0 | J15: =(+I15*$F$7)+I15 -> 0 | K15: =(+J15*$F$7)+J15 -> 0 | L15: =(+K15*$F$7)+K15 -> 0 | ... AG15: =(+AF15*$F$7)+AF15 -> 0
B16: Water & Sewer | E16: =(+D16*$F$7)+D16 -> 0 | F16: =(+E16*$F$7)+E16 -> 0 | G16: =(+F16*$F$7)+F16 -> 0 | H16: =(+G16*$F$7)+G16 -> 0 | I16: =(+H16*$F$7)+H16 -> 0 | J16: =(+I16*$F$7)+I16 -> 0 | K16: =(+J16*$F$7)+J16 -> 0 | L16: =(+K16*$F$7)+K16 -> 0 | ... AG16: =(+AF16*$F$7)+AF16 -> 0
B17: Garbage Removal | E17: =(+D17*$F$7)+D17 -> 0 | F17: =(+E17*$F$7)+E17 -> 0 | G17: =(+F17*$F$7)+F17 -> 0 | H17: =(+G17*$F$7)+G17 -> 0 | I17: =(+H17*$F$7)+H17 -> 0 | J17: =(+I17*$F$7)+I17 -> 0 | K17: =(+J17*$F$7)+J17 -> 0 | L17: =(+K17*$F$7)+K17 -> 0 | ... AG17: =(+AF17*$F$7)+AF17 -> 0
A19: Repairs | E19: =(+D19*$F$7)+D19 -> 0 | F19: =(+E19*$F$7)+E19 -> 0 | G19: =(+F19*$F$7)+F19 -> 0 | H19: =(+G19*$F$7)+G19 -> 0 | I19: =(+H19*$F$7)+H19 -> 0 | J19: =(+I19*$F$7)+I19 -> 0 | K19: =(+J19*$F$7)+J19 -> 0 | L19: =(+K19*$F$7)+K19 -> 0 | ... AG19: =(+AF19*$F$7)+AF19 -> 0
A20: General Maintenance | E20: =(+D20*$F$7)+D20 -> 0 | F20: =(+E20*$F$7)+E20 -> 0 | G20: =(+F20*$F$7)+F20 -> 0 | H20: =(+G20*$F$7)+G20 -> 0 | I20: =(+H20*$F$7)+H20 -> 0 | J20: =(+I20*$F$7)+I20 -> 0 | K20: =(+J20*$F$7)+J20 -> 0 | L20: =(+K20*$F$7)+K20 -> 0 | ... AG20: =(+AF20*$F$7)+AF20 -> 0
A21: Landscape Maintenance | E21: =(+D21*$F$7)+D21 -> 0 | F21: =(+E21*$F$7)+E21 -> 0 | G21: =(+F21*$F$7)+F21 -> 0 | H21: =(+G21*$F$7)+G21 -> 0 | I21: =(+H21*$F$7)+H21 -> 0 | J21: =(+I21*$F$7)+I21 -> 0 | K21: =(+J21*$F$7)+J21 -> 0 | L21: =(+K21*$F$7)+K21 -> 0 | ... AG21: =(+AF21*$F$7)+AF21 -> 0
A22: Replacement Reserve | E22: =(+D22*$F$7)+D22 -> 0 | F22: =(+E22*$F$7)+E22 -> 0 | G22: =(+F22*$F$7)+F22 -> 0 | H22: =(+G22*$F$7)+G22 -> 0 | I22: =(+H22*$F$7)+H22 -> 0 | J22: =(+I22*$F$7)+I22 -> 0 | K22: =(+J22*$F$7)+J22 -> 0 | L22: =(+K22*$F$7)+K22 -> 0 | ... AG22: =(+AF22*$F$7)+AF22 -> 0
A24: Property Management:
B25: On-site | E25: =(+D25*$F$7)+D25 -> 0 | F25: =(+E25*$F$7)+E25 -> 0 | G25: =(+F25*$F$7)+F25 -> 0 | H25: =(+G25*$F$7)+G25 -> 0 | I25: =(+H25*$F$7)+H25 -> 0 | J25: =(+I25*$F$7)+I25 -> 0 | K25: =(+J25*$F$7)+J25 -> 0 | L25: =(+K25*$F$7)+K25 -> 0 | ... AG25: =(+AF25*$F$7)+AF25 -> 0
B26: Contracted (Off-Site) | E26: =(+D26*$F$7)+D26 -> 0 | F26: =(+E26*$F$7)+E26 -> 0 | G26: =(+F26*$F$7)+F26 -> 0 | H26: =(+G26*$F$7)+G26 -> 0 | I26: =(+H26*$F$7)+H26 -> 0 | J26: =(+I26*$F$7)+I26 -> 0 | K26: =(+J26*$F$7)+J26 -> 0 | L26: =(+K26*$F$7)+K26 -> 0 | ... AG26: =(+AF26*$F$7)+AF26 -> 0
A28: Professional Services:
B29: Legal | E29: =(+D29*$F$7)+D29 -> 0 | F29: =(+E29*$F$7)+E29 -> 0 | G29: =(+F29*$F$7)+F29 -> 0 | H29: =(+G29*$F$7)+G29 -> 0 | I29: =(+H29*$F$7)+H29 -> 0 | J29: =(+I29*$F$7)+I29 -> 0 | K29: =(+J29*$F$7)+J29 -> 0 | L29: =(+K29*$F$7)+K29 -> 0 | ... AG29: =(+AF29*$F$7)+AF29 -> 0
B30: Accounting | E30: =(+D30*$F$7)+D30 -> 0 | F30: =(+E30*$F$7)+E30 -> 0 | G30: =(+F30*$F$7)+F30 -> 0 | H30: =(+G30*$F$7)+G30 -> 0 | I30: =(+H30*$F$7)+H30 -> 0 | J30: =(+I30*$F$7)+I30 -> 0 | K30: =(+J30*$F$7)+J30 -> 0 | L30: =(+K30*$F$7)+K30 -> 0 | ... AG30: =(+AF30*$F$7)+AF30 -> 0
A32: Office & Administration | E32: =(+D32*$F$7)+D32 -> 0 | F32: =(+E32*$F$7)+E32 -> 0 | G32: =(+F32*$F$7)+F32 -> 0 | H32: =(+G32*$F$7)+G32 -> 0 | I32: =(+H32*$F$7)+H32 -> 0 | J32: =(+I32*$F$7)+I32 -> 0 | K32: =(+J32*$F$7)+J32 -> 0 | L32: =(+K32*$F$7)+K32 -> 0 | ... AG32: =(+AF32*$F$7)+AF32 -> 0
A33: Advertising/Marketing & Promotion | E33: =(+D33*$F$7)+D33 -> 0 | F33: =(+E33*$F$7)+E33 -> 0 | G33: =(+F33*$F$7)+F33 -> 0 | H33: =(+G33*$F$7)+G33 -> 0 | I33: =(+H33*$F$7)+H33 -> 0 | J33: =(+I33*$F$7)+I33 -> 0 | K33: =(+J33*$F$7)+J33 -> 0 | L33: =(+K33*$F$7)+K33 -> 0 | ... AG33: =(+AF33*$F$7)+AF33 -> 0
A34: Turnover | E34: =(+D34*$F$7)+D34 -> 0 | F34: =(+E34*$F$7)+E34 -> 0 | G34: =(+F34*$F$7)+F34 -> 0 | H34: =(+G34*$F$7)+G34 -> 0 | I34: =(+H34*$F$7)+H34 -> 0 | J34: =(+I34*$F$7)+I34 -> 0 | K34: =(+J34*$F$7)+J34 -> 0 | L34: =(+K34*$F$7)+K34 -> 0 | ... AG34: =(+AF34*$F$7)+AF34 -> 0
A35: Taxes(non-real estate) | E35: =(+D35*$F$7)+D35 -> 0 | F35: =(+E35*$F$7)+E35 -> 0 | G35: =(+F35*$F$7)+F35 -> 0 | H35: =(+G35*$F$7)+G35 -> 0 | I35: =(+H35*$F$7)+H35 -> 0 | J35: =(+I35*$F$7)+I35 -> 0 | K35: =(+J35*$F$7)+J35 -> 0 | L35: =(+K35*$F$7)+K35 -> 0 | ... AG35: =(+AF35*$F$7)+AF35 -> 0
A36: Real Estate Taxes | E36: =(+D36*$F$7)+D36 -> 0 | F36: =(+E36*$F$7)+E36 -> 0 | G36: =(+F36*$F$7)+F36 -> 0 | H36: =(+G36*$F$7)+G36 -> 0 | I36: =(+H36*$F$7)+H36 -> 0 | J36: =(+I36*$F$7)+I36 -> 0 | K36: =(+J36*$F$7)+J36 -> 0 | L36: =(+K36*$F$7)+K36 -> 0 | ... AG36: =(+AF36*$F$7)+AF36 -> 0
A37: Payroll Taxes | E37: =(+D37*$F$7)+D37 -> 0 | F37: =(+E37*$F$7)+E37 -> 0 | G37: =(+F37*$F$7)+F37 -> 0 | H37: =(+G37*$F$7)+G37 -> 0 | I37: =(+H37*$F$7)+H37 -> 0 | J37: =(+I37*$F$7)+I37 -> 0 | K37: =(+J37*$F$7)+J37 -> 0 | L37: =(+K37*$F$7)+K37 -> 0 | ... AG37: =(+AF37*$F$7)+AF37 -> 0
A38: Other: | E38: =(+D38*$F$7)+D38 -> 0 | F38: =(+E38*$F$7)+E38 -> 0 | G38: =(+F38*$F$7)+F38 -> 0 | H38: =(+G38*$F$7)+G38 -> 0 | I38: =(+H38*$F$7)+H38 -> 0 | J38: =(+I38*$F$7)+I38 -> 0 | K38: =(+J38*$F$7)+J38 -> 0 | L38: =(+K38*$F$7)+K38 -> 0 | ... AG38: =(+AF38*$F$7)+AF38 -> 0
A39: Other: | E39: =(+D39*$F$7)+D39 -> 0 | F39: =(+E39*$F$7)+E39 -> 0 | G39: =(+F39*$F$7)+F39 -> 0 | H39: =(+G39*$F$7)+G39 -> 0 | I39: =(+H39*$F$7)+H39 -> 0 | J39: =(+I39*$F$7)+I39 -> 0 | K39: =(+J39*$F$7)+J39 -> 0 | L39: =(+K39*$F$7)+K39 -> 0 | ... AG39: =(+AF39*$F$7)+AF39 -> 0
A41: Total Annual Operating Expenses: | D41: =SUM(D11:D40) -> 0 | E41: =SUM(E11:E40) -> 0 | F41: =SUM(F11:F40) -> 0 | G41: =SUM(G11:G40) -> 0 | H41: =SUM(H11:H40) -> 0 | I41: =SUM(I11:I40) -> 0 | J41: =SUM(J11:J40) -> 0 | K41: =SUM(K11:K40) -> 0 | ... AG41: =SUM(AG11:AG40) -> 0
A43: Less Debt Service:
A45: Permanent loan
A46: Rate | B46: Term (Years) | C46: Loan Amount
B47: 1 | D47: =IF($B$47>=D9,PMT($A$47/12,$B$47*12,-$C$47,0,0)*12,0) -> 0 | E47: =IF($B$47>=E9,PMT($A$47/12,$B$47*12,-$C$47,0,0)*12,0) -> 0 | F47: =IF($B$47>=F9,PMT($A$47/12,$B$47*12,-$C$47,0,0)*12,0) -> 0 | G47: =IF($B$47>=G9,PMT($A$47/12,$B$47*12,-$C$47,0,0)*12,0) -> 0 | H47: =IF($B$47>=H9,PMT($A$47/12,$B$47*12,-$C$47,0,0)*12,0) -> 0 | I47: =IF($B$47>=I9,PMT($A$47/12,$B$47*12,-$C$47,0,0)*12,0) -> 0 | J47: =IF($B$47>=J9,PMT($A$47/12,$B$47*12,-$C$47,0,0)*12,0) -> 0 | K47: =IF($B$47>=K9,PMT($A$47/12,$B$47*12,-$C$47,0,0)*12,0) -> 0 | ... AG47: =IF($B$47>=AG9,PMT($A$47/12,$B$47*12,-$C$47,0,0)*12,0) -> 0
A48: Deferred Developer Fee
A49: Rate | B49: Term (Years) | C49: Loan Amount
B50: 1 | D50: =IF($B$50>=D9,PMT($A$50/12,$B$50*12,-$C$50,0,0)*12,0) -> 0 | E50: =IF($B$50>=E9,PMT($A$50/12,$B$50*12,-$C$50,0,0)*12,0) -> 0 | F50: =IF($B$50>=F9,PMT($A$50/12,$B$50*12,-$C$50,0,0)*12,0) -> 0 | G50: =IF($B$50>=G9,PMT($A$50/12,$B$50*12,-$C$50,0,0)*12,0) -> 0 | H50: =IF($B$50>=H9,PMT($A$50/12,$B$50*12,-$C$50,0,0)*12,0) -> 0 | I50: =IF($B$50>=I9,PMT($A$50/12,$B$50*12,-$C$50,0,0)*12,0) -> 0 | J50: =IF($B$50>=J9,PMT($A$50/12,$B$50*12,-$C$50,0,0)*12,0) -> 0 | K50: =IF($B$50>=K9,PMT($A$50/12,$B$50*12,-$C$50,0,0)*12,0) -> 0 | ... AG50: =IF($B$50>=AG9,PMT($A$50/12,$B$50*12,-$C$50,0,0)*12,0) -> 0
A51: Amortized Debt (HOME Loan, , Partnership Loans,etc.) & Cashflow Loans
A53: Rate | B53: Term (Years) | C53: Loan Amount
B54: 1 | D54: =IF($B$54>=D9,PMT($A$54/12,$B$54*12,-$C$54,0,0)*12,0) -> 0 | E54: =IF($B$54>=E9,PMT($A$54/12,$B$54*12,-$C$54,0,0)*12,0) -> 0 | F54: =IF($B$54>=F9,PMT($A$54/12,$B$54*12,-$C$54,0,0)*12,0) -> 0 | G54: =IF($B$54>=G9,PMT($A$54/12,$B$54*12,-$C$54,0,0)*12,0) -> 0 | H54: =IF($B$54>=H9,PMT($A$54/12,$B$54*12,-$C$54,0,0)*12,0) -> 0 | I54: =IF($B$54>=I9,PMT($A$54/12,$B$54*12,-$C$54,0,0)*12,0) -> 0 | J54: =IF($B$54>=J9,PMT($A$54/12,$B$54*12,-$C$54,0,0)*12,0) -> 0 | K54: =IF($B$54>=K9,PMT($A$54/12,$B$54*12,-$C$54,0,0)*12,0) -> 0 | ... AG54: =IF($B$54>=AG9,PMT($A$54/12,$B$54*12,-$C$54,0,0)*12,0) -> 0
B55: 1 | D55: =IF($B$55>=D9,PMT($A$55/12,$B$55*12,-$C$55,0,0)*12,0) -> 0 | E55: =IF($B$55>=E9,PMT($A$55/12,$B$55*12,-$C$55,0,0)*12,0) -> 0 | F55: =IF($B$55>=F9,PMT($A$55/12,$B$55*12,-$C$55,0,0)*12,0) -> 0 | G55: =IF($B$55>=G9,PMT($A$55/12,$B$55*12,-$C$55,0,0)*12,0) -> 0 | H55: =IF($B$55>=H9,PMT($A$55/12,$B$55*12,-$C$55,0,0)*12,0) -> 0 | I55: =IF($B$55>=I9,PMT($A$55/12,$B$55*12,-$C$55,0,0)*12,0) -> 0 | J55: =IF($B$55>=J9,PMT($A$55/12,$B$55*12,-$C$55,0,0)*12,0) -> 0 | K55: =IF($B$55>=K9,PMT($A$55/12,$B$55*12,-$C$55,0,0)*12,0) -> 0 | ... AG55: =IF($B$55>=AG9,PMT($A$55/12,$B$55*12,-$C$55,0,0)*12,0) -> 0
...

Sheet Pro forma Summary
A1: Pro Forma Summary
A3: Project Name: | B3: =Sources!B3 -> 0 | D3: Date: | E3: =Sources!F3 -> 40909
A5: Number of Units: | B5: ='Uses of Funds'!C6 -> 0
A6: Square Footage: | C6: % of Total Sq. Foot
A7: Residential: | B7: ='Uses of Funds'!C7 -> 0 | C7: =B7/$B$10 -> #DIV/0!
A8: Common Areas: | B8: ='Uses of Funds'!C9 -> 0 | C8: =B8/$B$10 -> #DIV/0!
A9: Commercial/Other: | B9: ='Uses of Funds'!C10 -> 0 | C9: =B9/$B$10 -> #DIV/0!
A10: Total Square Footage: | B10: ='Uses of Funds'!C11 -> 0 | C10: =B10/$B$10 -> #DIV/0!
A12: Total Residential Project Cost:
B13: Total in Dollars | C13: Percent of Total Project Costs | D13: Total Cost Per Unit | E13: Total Cost Per Sq. Foot
A14: Acquisition Costs: | B14: ='Uses of Funds'!E25 -> 0 | C14: =B14/$B$17 -> #DIV/0! | D14: =B14/$B$5 -> #DIV/0! | E14: =B14/($B$7+$B$8) -> #DIV/0!
A15: Construction Costs: | B15: ='Uses of Funds'!E50 -> 0 | C15: =B15/$B$17 -> #DIV/0! | D15: =B15/$B$5 -> #DIV/0! | E15: =B15/($B$7+$B$8) -> #DIV/0!
A16: Development Costs: | B16: ='Uses of Funds'!E128 -> 0 | C16: =B16/$B$17 -> #DIV/0! | D16: =B16/$B$5 -> #DIV/0! | E16: =B16/($B$7+$B$8) -> #DIV/0!
A17: Total Project Costs : | B17: ='Uses of Funds'!E130 -> 0 | C17: =B17/$B$17 -> #DIV/0! | D17: =B17/$B$5 -> #DIV/0! | E17: =B17/($B$7+$B$8) -> #DIV/0!
A18: Construction:
C19: Percent of Construction | D19: Per Unit | E19: Per Sq. Foot
A20: Builder General Conditions | B20: ='Uses of Funds'!E39 -> 0 | C20: =B20/($B$15-$B$20) -> #DIV/0! | D20: =B20/$B$5 -> #DIV/0! | E20: =B20/($B$7+$B$8) -> #DIV/0!
A21: Builder Overhead | B21: ='Uses of Funds'!E41 -> 0 | C21: =B21/($B$15-$B$21) -> #DIV/0! | D21: =B21/$B$5 -> #DIV/0! | E21: =B21/($B$7+$B$8) -> #DIV/0!
A22: Builder Profit | B22: ='Uses of Funds'!E42 -> 0 | C22: =B22/($B$15-$B$22) -> #DIV/0! | D22: =B22/$B$5 -> #DIV/0! | E22: =B22/($B$7+$B$8) -> #DIV/0!
A23: Total Builder GC/O/P | B23: =SUM(B20:B22) -> 0 | C23: =B23/($B$15-$B$23) -> #DIV/0! | D23: =B23/$B$5 -> #DIV/0! | E23: =B23/($B$7+$B$8) -> #DIV/0!
A25: Construction Contingency | B25: ='Uses of Funds'!E43 -> 0 | C25: =B25/($B$15-$B$25) -> #DIV/0! | D25: =B25/$B$5 -> #DIV/0! | E25: =B25/($B$7+$B$8) -> #DIV/0!
A27: Architect's Fee | B27: ='Uses of Funds'!E69 -> 0 | C27: =B27/($B$15-$B$27) -> #DIV/0!
A28: Development Cost:
C29: Percent of Development | D29: Per Unit | E29: Per Sq. Foot
A30: Development Contingency | B30: ='Uses of Funds'!E121 -> 0 | C30: =B30/($B$16-$B$30) -> #DIV/0! | D30: =B30/$B$5 -> #DIV/0! | E30: =B30/($B$7+$B$8) -> #DIV/0!
B32: Total in Dollars | C32: Percent of Total Project Costs
A33: 5 % Max for Acquisition: | B33: =IF('Uses of Funds'!C4="x",('Uses of Funds'!E18+'Uses of Funds'!E19)*0.05, ) -> 0 | C33: =B33/(($B$17+(B33-$B$40)-B33)-'Uses of Funds'!E119-'Uses of Funds'!E120-'Uses of Funds'!E123) -> #DIV/0! | D33: =B33/$B$5 -> #DIV/0! | E33: =B33/($B$7+$B$8) -> #DIV/0!
A34: Max New Const/Rehab: | B34: =B35-B33 -> 0 | C34: =B34/(($B$17+(B34-$B$40)-B34-'Uses of Funds'!E119-'Uses of Funds'!E120-'Uses of Funds'!E123)) -> #DIV/0! | D34: =B34/$B$5 -> #DIV/0! | E34: =B34/($B$7+$B$8) -> #DIV/0!
A35: 15% Max Developer Fee: | B35: =('Uses of Funds'!E130-'Pro forma Summary'!B40-'Uses of Funds'!E76-'Uses of Funds'!E77-'Uses of Funds'!E119-'Uses of Funds'!E120-'Uses of Funds'!E123)*0.15 -> 0 | C35: =B35/(($B$17+(B35-$B$40)-B35-'Uses of Funds'!E119-'Uses of Funds'!E120-'Uses of Funds'!E123)) -> #DIV/0!
A37: Developer Fee: | B37: ='Uses of Funds'!E76 -> 0 | C37: =B37/($B$17-$B$40-'Uses of Funds'!E119-'Uses of Funds'!E120-'Uses of Funds'!E123) -> #DIV/0! | D37: =B37/$B$5 -> #DIV/0! | E37: =B37/($B$7+$B$8) -> #DIV/0!
A38: Consultant Fee | B38: ='Uses of Funds'!E77 -> 0 | C38: =B38/($B$17-$B$40-'Uses of Funds'!E119-'Uses of Funds'!E120-'Uses of Funds'!E123) -> #DIV/0! | D38: =B38/$B$5 -> #DIV/0! | E38: =B38/($B$7+$B$8) -> #DIV/0!
A39: Minimum Required Non-Profit Share of Developer Fee: (If Applicable) | B39: =B40*0.25 -> 0 | C39: =B39/($B$17-$B$40-'Uses of Funds'!E119-'Uses of Funds'!E120-'Uses of Funds'!E123) -> #DIV/0! | D39: =B39/$B$5 -> #DIV/0! | E39: =B39/($B$7+$B$8) -> #DIV/0!
A40: Total Developer Fee | B40: =B37+B38 -> 0 | C40: =B40/($B$17-$B$40-'Uses of Funds'!E119-'Uses of Funds'!E120-'Uses of Funds'!E123) -> #DIV/0! | D40: =B40/$B$5 -> #DIV/0! | E40: =B40/($B$7+$B$8) -> #DIV/0!
A41: Total Deferred Fee | B41: =Sources!$C$52+Sources!$D$52+Sources!$E$52 -> 0 | C41: =B41/($B$17-B40-'Uses of Funds'!E119-'Uses of Funds'!E120-'Uses of Funds'!E123) -> #DIV/0! | D41: =B41/$B$5 -> #DIV/0! | E41: =B41/($B$7+$B$8) -> #DIV/0!
A42: Total Cash Developer Fee: | B42: =B40-B41 -> 0 | C42: =B42/($B$17-$B$40-'Uses of Funds'!E119-'Uses of Funds'!E120-'Uses of Funds'!E123) -> #DIV/0! | D42: =B42/$B$5 -> #DIV/0! | E42: =B42/($B$7+$B$8) -> #DIV/0!
A44: Operating Income & Expense:
A45: Income: | C45: Percent of EGI | D45: Per Unit | E45: Per Sq. Foot
A46: EGI without OAHTC | B46: =Income!N42 -> 0 | D46: =B46/$B$5 -> #DIV/0! | E46: =B46/($B$7+$B$8) -> #DIV/0!
A47: EGI with OAHTC | B47: ='Income with OAHTC'!N50 -> 0 | D47: =B47/$B$5 -> #DIV/0! | E47: =B47/($B$7+$B$8) -> #DIV/0!
A49: Cash Flow without OAHTC | B49: =Expenses!E112 -> 0 | C49: =B49/B46 -> #DIV/0! | D49: =B49/$B$5 -> #DIV/0! | E49: =B49/($B$7+$B$8) -> #DIV/0!
...

Sheet Project Summary
A1: PROJECT SUMMARY
A3: Project Name: | B3: =Sources!B3 -> 0
A5: Date: | B5: =Sources!F3 -> 40909
A6: County | B6: =Income!F5 -> 0
A8: SOURCES
A10: OHCS Grants & Equity | B10: =Sources!C15+Sources!D15+Sources!E15 -> 0
A11: OHCS Loans | B11: =Sources!C24+Sources!D24+Sources!E24 -> 0
A12: PHB Sources | B12: =Sources!C32+Sources!D32+Sources!E32 -> 0
A13: Other Loans | B13: =Sources!C40+Sources!D40+Sources!E40 -> 0
A14: Other Grants | B14: =Sources!C48+Sources!D48+Sources!E48 -> 0
A15: Applicant Contributions | B15: =Sources!C55+Sources!D55+Sources!E55 -> 0
A16: Other Funds | B16: =Sources!C61+Sources!D61+Sources!E61 -> 0
A18: TOTAL FUNDING SOURCE | B18: =B16+B15+B14+B13+B12+B11+B10 -> 0
A19: =IF(Sources!C64+Sources!D64+Sources!E64>0,Sources!A64," ")
A20: USES
A22: Acquisition | B22: ='Uses of Funds'!E25 -> 0
A23: Construction/Rehab | B23: ='Uses of Funds'!E50 -> 0
A24: Development Costs | B24: ='Uses of Funds'!E128 -> 0
A26: Total | B26: ='Uses of Funds'!E130 -> 0
A28: FIRST YEAR INCOME & EXPENSES
B30: Without OAHTC | C30: With OAHTC
A32: Rental Income | B32: =Income!N25 -> 0 | C32: ='Income with OAHTC'!N25 -> 0
A33: Other Income | B33: =Income!N40 -> 0 | C33: ='Income with OAHTC'!N44 -> 0
A34: Gross Potential Income | B34: =Income!N42 -> 0 | C34: ='Income with OAHTC'!N46 -> 0
A35: Less Vacancy | B35: =Income!N44 -> 0 | C35: ='Income with OAHTC'!N48 -> 0
A36: Effective Gross Income | B36: =Income!N42 -> 0 | C36: ='Income with OAHTC'!N50 -> 0
A37: Annual Operating Expenses | B37: =Expenses!E64 -> 0 | C37: =Expenses!E118 -> 0
A38: Net Operating Income | B38: =Expenses!E109 -> 0 | C38: =Expenses!E119 -> 0
A39: Annual Debt Service | B39: =Expenses!E110 -> 0 | C39: =Expenses!E120 -> 0
A40: Primary Debt Coverage | B40: =Expenses!E113 -> #DIV/0! | C40: =Expenses!E123 -> #DIV/0!

Sheet LIHTC Calculation
A2: CALCULATION OF TAX CREDIT
B4: Project Name: | C4: =Sources!$B$3 -> 0
B5: Date: | C5: =Sources!F3 -> 40909
A7: Tax credits are calculated on an annual basis. The total tax credit receive is equal to 10 times the annual credit
D9: Yes | E9: No
A11: Qualified Census Tract (QCT) or Difficult to Develop Area (DDA) ?
B13: Enter QCT number
B14: Enter DDA area
A17: Indicate whether your project is qualified for:
A19: 30% Net Present Value | C19: (Place X under "Yes" if applicable)
A20: 70% Net Present Value | C20: (Place X under "Yes" if applicable)
A21: Both 30% & 70% | C21: (Place X under "Yes" if applicable)
D23: 0.3 | E23: 0.7 | F23: Total
A25: Total Project Costs | C25: Use applicable column (30%, 70% or both) for data entry | D25: ='Uses of Funds'!E130 -> 0 | E25: ='Uses of Funds'!E130 -> 0
B27: Less land; amortized and other ineligible costs * | D27: ='Uses of Funds'!$E$130-'Uses of Funds'!$T$130 -> 0 | E27: ='Uses of Funds'!$E$130-'Uses of Funds'!$T$130 -> 0
A29: Eligible Basis
B31: Less portion of federal grant used to finance qualifying developments
B32: Less amounts of nonqualified nonrecourse financing
B33: Less nonqualifying costs or units of higher quality
B34: Less Section 48 Rehabilitation Tax Credit
B35: Less Historic Tax Credit (Rresidential Portion Only)
A38: Total Eligible Basis | D38: =D25-D27-D31-D32-D33-D34-D35-D36 -> 0 | E38: =E25-E27-E31-E32-E33-E34-E35-E36 -> 0
B40: (Change to 130% if high cost or qualified census tract) | D40: 1 | E40: 1
A42: Adjusted Eligible Basis | D42: =D40*D38 -> 0 | E42: =E40*E38 -> 0
B44: Multiplied by the applicable fraction | D44: 1 | E44: 1
