Workbook

Sheet TS
A2: Date | B2: Reactor | C2: Initial Wt (g) | D2: Final Wt (g) | E2: Beaker Wt (g) | F2: ∆ Wt (g) | G2: Solids Wt (g) | H2: Solids Wt (mg) | I2: Vol (L) | J2: [TS] mg/L
A3: 38621 | B3: R1 | C3: 110.2 | D3: 49.5 | E3: 48.7 | F3: =C3-D3 -> 60.7 | G3: =D3-E3 -> 0.8 | H3: =G3*1000 -> 800 | I3: =F3/1000 -> 0.0607 | J3: =H3/I3 -> 13179.572
B4: R2 | C4: 131.5 | D4: 51.8 | E4: 51.1 | F4: =C4-D4 -> 79.7 | G4: =D4-E4 -> 0.7 | H4: =G4*1000 -> 700 | I4: =F4/1000 -> 0.0797 | J4: =H4/I4 -> 8782.936
A5: 38622 | B5: R1 | C5: 154.9 | D5: 73.3 | E5: 72.5 | F5: =C5-D5 -> 81.6 | G5: =D5-E5 -> 0.8 | H5: =G5*1000 -> 800 | I5: =F5/1000 -> 0.0816 | J5: =H5/I5 -> 9803.9216
B6: R2 | C6: 152.4 | D6: 61.2 | E6: 60.4 | F6: =C6-D6 -> 91.2 | G6: =D6-E6 -> 0.8 | H6: =G6*1000 -> 800 | I6: =F6/1000 -> 0.0912 | J6: =H6/I6 -> 8771.9298
A7: 38625 | B7: R1 | C7: 125.3 | D7: 50.3 | E7: 49.8 | F7: =C7-D7 -> 75 | G7: =D7-E7 -> 0.5 | H7: =G7*1000 -> 500 | I7: =F7/1000 -> 0.075 | J7: =H7/I7 -> 6666.6667
B8: R2 | C8: 146.4 | D8: 61.1 | E8: 60.3 | F8: =C8-D8 -> 85.3 | G8: =D8-E8 -> 0.8 | H8: =G8*1000 -> 800 | I8: =F8/1000 -> 0.0853 | J8: =H8/I8 -> 9378.6635
A9: 38626 | B9: R1 | C9: 104.6 | D9: 79.9 | E9: 79.6 | F9: =C9-D9 -> 24.7 | G9: =D9-E9 -> 0.3 | H9: =G9*1000 -> 300 | I9: =F9/1000 -> 0.0247 | J9: =H9/I9 -> 12145.749
B10: R2 | C10: 109.2 | D10: 82.6 | E10: 82.4 | F10: =C10-D10 -> 26.6 | G10: =D10-E10 -> 0.2 | H10: =G10*1000 -> 200 | I10: =F10/1000 -> 0.0266 | J10: =H10/I10 -> 7518.797
A11: 38627 | B11: R1 | C11: 105.7 | D11: 50.2 | E11: 49.8 | F11: =C11-D11 -> 55.5 | G11: =D11-E11 -> 0.4 | H11: =G11*1000 -> 400 | I11: =F11/1000 -> 0.0555 | J11: =H11/I11 -> 7207.2072
B12: R2 | C12: 113.8 | D12: 60.1 | E12: 59.8 | F12: =C12-D12 -> 53.7 | G12: =D12-E12 -> 0.3 | H12: =G12*1000 -> 300 | I12: =F12/1000 -> 0.0537 | J12: =H12/I12 -> 5586.5922
A13: 38629 | B13: R1 | C13: 158.4 | D13: 82.8 | E13: 82.4 | F13: =C13-D13 -> 75.6 | G13: =D13-E13 -> 0.4 | H13: =G13*1000 -> 400 | I13: =F13/1000 -> 0.0756 | J13: =H13/I13 -> 5291.0053
B14: R2 | C14: 162.2 | D14: 80.1 | E14: 79.6 | F14: =C14-D14 -> 82.1 | G14: =D14-E14 -> 0.5 | H14: =G14*1000 -> 500 | I14: =F14/1000 -> 0.0821 | J14: =H14/I14 -> 6090.134
A15: 38637 | B15: R1 | C15: 160.2 | D15: 73.3 | E15: 73 | F15: =C15-D15 -> 86.9 | G15: =D15-E15 -> 0.3 | H15: =G15*1000 -> 300 | I15: =F15/1000 -> 0.0869 | J15: =H15/I15 -> 3452.244
A16: 38640 | B16: R1 | C16: 125 | D16: 51.3 | E16: 50.1 | F16: =C16-D16 -> 73.7 | G16: =D16-E16 -> 1.2 | H16: =G16*1000 -> 1200 | I16: =F16/1000 -> 0.0737 | J16: =H16/I16 -> 16282.225
B17: R2 | C17: 118.7 | D17: 51.5 | E17: 50.8 | F17: =C17-D17 -> 67.2 | G17: =D17-E17 -> 0.7 | H17: =G17*1000 -> 700 | I17: =F17/1000 -> 0.0672 | J17: =H17/I17 -> 10416.667
A18: 38643 | B18: R1 | C18: 118.8 | D18: 50.7 | E18: 49.6 | F18: =C18-D18 -> 68.1 | G18: =D18-E18 -> 1.1 | H18: =G18*1000 -> 1100 | I18: =F18/1000 -> 0.0681 | J18: =H18/I18 -> 16152.717
B19: R2 | C19: 106.2 | D19: 50.4 | E19: 49.8 | F19: =C19-D19 -> 55.8 | G19: =D19-E19 -> 0.6 | H19: =G19*1000 -> 600 | I19: =F19/1000 -> 0.0558 | J19: =H19/I19 -> 10752.688
A20: 38645 | B20: R1 | C20: 120.1 | D20: 51.7 | E20: 50.6 | F20: =C20-D20 -> 68.4 | G20: =D20-E20 -> 1.1 | H20: =G20*1000 -> 1100 | I20: =F20/1000 -> 0.0684 | J20: =H20/I20 -> 16081.871
B21: R2 | C21: 140.4 | D21: 51.8 | E21: 50.8 | F21: =C21-D21 -> 88.6 | G21: =D21-E21 -> 1 | H21: =G21*1000 -> 1000 | I21: =F21/1000 -> 0.0886 | J21: =H21/I21 -> 11286.682
A22: 38647 | B22: R1 | C22: 112.6 | D22: 62.4 | E22: 61.6 | F22: =C22-D22 -> 50.2 | G22: =D22-E22 -> 0.8 | H22: =G22*1000 -> 800 | I22: =F22/1000 -> 0.0502 | J22: =H22/I22 -> 15936.255
B23: R2 | C23: 152.3 | D23: 68.5 | E23: 67.6 | F23: =C23-D23 -> 83.8 | G23: =D23-E23 -> 0.9 | H23: =G23*1000 -> 900 | I23: =F23/1000 -> 0.0838 | J23: =H23/I23 -> 10739.857
A24: 38649 | B24: R1 | C24: 130.9 | D24: 51.4 | E24: 50.1 | F24: =C24-D24 -> 79.5 | G24: =D24-E24 -> 1.3 | H24: =G24*1000 -> 1300 | I24: =F24/1000 -> 0.0795 | J24: =H24/I24 -> 16352.201
B25: R2 | C25: 147.2 | D25: 52.1 | E25: 51 | F25: =C25-D25 -> 95.1 | G25: =D25-E25 -> 1.1 | H25: =G25*1000 -> 1100 | I25: =F25/1000 -> 0.0951 | J25: =H25/I25 -> 11566.772
A26: Introduced culture from anaerobic digester and a third digester R3 as a control | K26: R3 container broke so was never considered
A27: 38651 | B27: R1 | C27: 297 | D27: 106.4 | E27: 103.9 | F27: =C27-D27 -> 190.6 | G27: =D27-E27 -> 2.5 | H27: =G27*1000 -> 2500 | I27: =F27/1000 -> 0.1906 | J27: =H27/I27 -> 13116.474
B28: R2 | C28: 314.9 | D28: 107.4 | E28: 105.2 | F28: =C28-D28 -> 207.5 | G28: =D28-E28 -> 2.2 | H28: =G28*1000 -> 2200 | I28: =F28/1000 -> 0.2075 | J28: =H28/I28 -> 10602.41
B29: R3 | C29: 293.2 | D29: 107.9 | E29: 106.8 | F29: =C29-D29 -> 185.3 | G29: =D29-E29 -> 1.1 | H29: =G29*1000 -> 1100 | I29: =F29/1000 -> 0.1853 | J29: =H29/I29 -> 5936.3195
A30: 38652 | B30: R1 | C30: 197.6 | D30: 67.3 | E30: 64.7 | F30: =C30-D30 -> 130.3 | G30: =D30-E30 -> 2.6 | H30: =G30*1000 -> 2600 | I30: =F30/1000 -> 0.1303 | J30: =H30/I30 -> 19953.952
B31: R2 | C31: 209.5 | D31: 69 | E31: 67.6 | F31: =C31-D31 -> 140.5 | G31: =D31-E31 -> 1.4 | H31: =G31*1000 -> 1400 | I31: =F31/1000 -> 0.1405 | J31: =H31/I31 -> 9964.4128
B32: R3 | C32: 198.9 | D32: 69.3 | E32: 68.9 | F32: =C32-D32 -> 129.6 | G32: =D32-E32 -> 0.4 | H32: =G32*1000 -> 400 | I32: =F32/1000 -> 0.1296 | J32: =H32/I32 -> 3086.4198
A33: 38654 | B33: R1 | C33: 126.9 | D33: 51.3 | E33: 50.5 | F33: =C33-D33 -> 75.6 | G33: =D33-E33 -> 0.8 | H33: =G33*1000 -> 800 | I33: =F33/1000 -> 0.0756 | J33: =H33/I33 -> 10582.011
B34: R2 | C34: 126.5 | D34: 51.2 | E34: 50.6 | F34: =C34-D34 -> 75.3 | G34: =D34-E34 -> 0.6 | H34: =G34*1000 -> 600 | I34: =F34/1000 -> 0.0753 | J34: =H34/I34 -> 7968.1275
B35: R3 | C35: 125.6 | D35: 49.1 | E35: 48.7 | F35: =C35-D35 -> 76.5 | G35: =D35-E35 -> 0.4 | H35: =G35*1000 -> 400 | I35: =F35/1000 -> 0.0765 | J35: =H35/I35 -> 5228.7582
A36: 38657 | B36: R1 | C36: 127.4 | D36: 50.8 | E36: 50 | F36: =C36-D36 -> 76.6 | G36: =D36-E36 -> 0.8 | H36: =G36*1000 -> 800 | I36: =F36/1000 -> 0.0766 | J36: =H36/I36 -> 10443.864
B37: R2 | C37: 132.9 | D37: 48.4 | E37: 47.7 | F37: =C37-D37 -> 84.5 | G37: =D37-E37 -> 0.7 | H37: =G37*1000 -> 700 | I37: =F37/1000 -> 0.0845 | J37: =H37/I37 -> 8284.0237
B38: R3 | C38: 136.6 | D38: 50.4 | E38: 49.9 | F38: =C38-D38 -> 86.2 | G38: =D38-E38 -> 0.5 | H38: =G38*1000 -> 500 | I38: =F38/1000 -> 0.0862 | J38: =H38/I38 -> 5800.464
A39: 38659 | B39: R1 | C39: 106.9 | D39: 50.2 | E39: 49.7 | F39: =C39-D39 -> 56.7 | G39: =D39-E39 -> 0.5 | H39: =G39*1000 -> 500 | I39: =F39/1000 -> 0.0567 | J39: =H39/I39 -> 8818.3422
B40: R2 | C40: 115.6 | D40: 50.3 | E40: 49.8 | F40: =C40-D40 -> 65.3 | G40: =D40-E40 -> 0.5 | H40: =G40*1000 -> 500 | I40: =F40/1000 -> 0.0653 | J40: =H40/I40 -> 7656.9678
B41: R3 | C41: 116.4 | D41: 50.3 | E41: 49.9 | F41: =C41-D41 -> 66.1 | G41: =D41-E41 -> 0.4 | H41: =G41*1000 -> 400 | I41: =F41/1000 -> 0.0661 | J41: =H41/I41 -> 6051.4372
...

Sheet VS
A1: Results for Votal solids for fresh fed (R1) and dry fed (R2) digesters, Sep 2009 - Nov 2010
A2: date | B2: reactor | C2: vol (ml) | D2: initial wt | E2: Final wt | F2: ∆Wt (g) | G2: solids wt (mg) | H2: vol(L) | I2: VS(mg/L)
A3: 38621 | B3: R1 | C3: =TS!F3 -> 60.7 | D3: 49.5 | E3: 48.8 | F3: =D3-E3 -> 0.7 | G3: =F3*1000 -> 700 | H3: =C3/1000 -> 0.0607 | I3: =G3/H3 -> 11532.125
B4: R2 | C4: =TS!F4 -> 79.7 | D4: 51.8 | E4: 51.2 | F4: =D4-E4 -> 0.6 | G4: =F4*1000 -> 600 | H4: =C4/1000 -> 0.0797 | I4: =G4/H4 -> 7528.2309
A5: 38622 | B5: R1 | C5: =TS!F5 -> 81.6 | D5: 73.3 | E5: 72.7 | F5: =D5-E5 -> 0.6 | G5: =F5*1000 -> 600 | H5: =C5/1000 -> 0.0816 | I5: =G5/H5 -> 7352.9412
B6: R2 | C6: =TS!F6 -> 91.2 | D6: 61.2 | E6: 60.6 | F6: =D6-E6 -> 0.6 | G6: =F6*1000 -> 600 | H6: =C6/1000 -> 0.0912 | I6: =G6/H6 -> 6578.9474
A7: 38625 | B7: R1 | C7: =TS!F7 -> 75 | D7: 50.3 | E7: 49.9 | F7: =D7-E7 -> 0.4 | G7: =F7*1000 -> 400 | H7: =C7/1000 -> 0.075 | I7: =G7/H7 -> 5333.3333
B8: R2 | C8: =TS!F8 -> 85.3 | D8: 61.1 | E8: 60.5 | F8: =D8-E8 -> 0.6 | G8: =F8*1000 -> 600 | H8: =C8/1000 -> 0.0853 | I8: =G8/H8 -> 7033.9977
A9: 38626 | B9: R1 | C9: =TS!F9 -> 24.7 | D9: 79.9 | E9: 79.7 | F9: =D9-E9 -> 0.2 | G9: =F9*1000 -> 200 | H9: =C9/1000 -> 0.0247 | I9: =G9/H9 -> 8097.166
B10: R2 | C10: =TS!F10 -> 26.6 | D10: 82.6 | E10: 82.4 | F10: =D10-E10 -> 0.2 | G10: =F10*1000 -> 200 | H10: =C10/1000 -> 0.0266 | I10: =G10/H10 -> 7518.797
A11: 38627 | B11: R1 | C11: =TS!F11 -> 55.5 | D11: 50.2 | E11: 49.9 | F11: =D11-E11 -> 0.3 | G11: =F11*1000 -> 300 | H11: =C11/1000 -> 0.0555 | I11: =G11/H11 -> 5405.4054
B12: R2 | C12: =TS!F12 -> 53.7 | D12: 60.1 | E12: 59.9 | F12: =D12-E12 -> 0.2 | G12: =F12*1000 -> 200 | H12: =C12/1000 -> 0.0537 | I12: =G12/H12 -> 3724.3948
A13: 38629 | B13: R1 | C13: =TS!F13 -> 75.6 | D13: 82.8 | E13: 82.5 | F13: =D13-E13 -> 0.3 | G13: =F13*1000 -> 300 | H13: =C13/1000 -> 0.0756 | I13: =G13/H13 -> 3968.254
B14: R2 | C14: =TS!F14 -> 82.1 | D14: 80.1 | E14: 79.8 | F14: =D14-E14 -> 0.3 | G14: =F14*1000 -> 300 | H14: =C14/1000 -> 0.0821 | I14: =G14/H14 -> 3654.0804
A15: 38637 | B15: R1 | C15: 86.9 | D15: 73.3 | E15: 73.1 | F15: =D15-E15 -> 0.2 | G15: =F15*1000 -> 200 | H15: =C15/1000 -> 0.0869 | I15: =(G15)/(H15) -> 2301.496
A16: 38640 | B16: R1 | C16: =TS!F16 -> 73.7 | D16: 51.3 | E16: 50.6 | F16: =D16-E16 -> 0.7 | G16: =F16*1000 -> 700 | H16: =C16/1000 -> 0.0737 | I16: =(G16)/(H16) -> 9497.9647
B17: R2 | C17: =TS!F17 -> 67.2 | D17: 51.5 | E17: 51.1 | F17: =D17-E17 -> 0.4 | G17: =F17*1000 -> 400 | H17: =C17/1000 -> 0.0672 | I17: =(G17)/(H17) -> 5952.381
A18: 38643 | B18: R1 | C18: =TS!F18 -> 68.1 | D18: 50.7 | E18: 50 | F18: =D18-E18 -> 0.7 | G18: =F18*1000 -> 700 | H18: =C18/1000 -> 0.0681 | I18: =(G18)/(H18) -> 10279.001
B19: R2 | C19: =TS!F19 -> 55.8 | D19: 50.4 | E19: 50.1 | F19: =D19-E19 -> 0.3 | G19: =F19*1000 -> 300 | H19: =C19/1000 -> 0.0558 | I19: =(G19)/(H19) -> 5376.3441
A20: 38645 | B20: R1 | C20: =TS!F20 -> 68.4 | D20: 51.7 | E20: 50.9 | F20: =D20-E20 -> 0.8 | G20: =F20*1000 -> 800 | H20: =C20/1000 -> 0.0684 | I20: =(G20)/(H20) -> 11695.906
B21: R2 | C21: =TS!F21 -> 88.6 | D21: 51.8 | E21: 51.1 | F21: =D21-E21 -> 0.7 | G21: =F21*1000 -> 700 | H21: =C21/1000 -> 0.0886 | I21: =(G21)/(H21) -> 7900.6772
A22: 38647 | B22: R1 | C22: =TS!F22 -> 50.2 | D22: 62.4 | E22: 61.8 | F22: =D22-E22 -> 0.6 | G22: =F22*1000 -> 600 | H22: =C22/1000 -> 0.0502 | I22: =(G22)/(H22) -> 11952.191
B23: R2 | C23: =TS!F23 -> 83.8 | D23: 68.5 | E23: 67.9 | F23: =D23-E23 -> 0.6 | G23: =F23*1000 -> 600 | H23: =C23/1000 -> 0.0838 | I23: =(G23)/(H23) -> 7159.9045
A24: 38649 | B24: R1 | C24: =TS!F24 -> 79.5 | D24: 51.4 | E24: 50.6 | F24: =D24-E24 -> 0.8 | G24: =F24*1000 -> 800 | H24: =C24/1000 -> 0.0795 | I24: =(G24)/(H24) -> 10062.893
B25: R2 | C25: =TS!F25 -> 95.1 | D25: 52.1 | E25: 51.4 | F25: =D25-E25 -> 0.7 | G25: =F25*1000 -> 700 | H25: =C25/1000 -> 0.0951 | I25: =(G25)/(H25) -> 7360.673
A26: Introduced culture from anaerobic digester and a third digester R3 as a control | J26: R3 container broke so was never considered
A27: 38651 | B27: R1 | C27: =TS!F27 -> 190.6 | D27: 52 | E27: 50.5 | F27: =D27-E27 -> 1.5 | G27: =F27*1000 -> 1500 | H27: =C27/1000 -> 0.1906 | I27: =(G27)/(H27) -> 7869.8846
B28: R2 | C28: =TS!F28 -> 207.5 | D28: 51.6 | E28: 50.3 | F28: =D28-E28 -> 1.3 | G28: =F28*1000 -> 1300 | H28: =C28/1000 -> 0.2075 | I28: =(G28)/(H28) -> 6265.0602
B29: R3 | C29: =TS!F29 -> 185.3 | D29: 52 | E29: 51.3 | F29: =D29-E29 -> 0.7 | G29: =F29*1000 -> 700 | H29: =C29/1000 -> 0.1853 | I29: =(G29)/(H29) -> 3777.6579
A30: 38652 | B30: R1 | C30: =TS!F30 -> 130.3 | D30: 67.3 | E30: 65.4 | F30: =D30-E30 -> 1.9 | G30: =F30*1000 -> 1900 | H30: =C30/1000 -> 0.1303 | I30: =(G30)/(H30) -> 14581.734
B31: R2 | C31: =TS!F31 -> 140.5 | D31: 69 | E31: 68.1 | F31: =D31-E31 -> 0.9 | G31: =F31*1000 -> 900 | H31: =C31/1000 -> 0.1405 | I31: =(G31)/(H31) -> 6405.694
B32: R3 | C32: =TS!F32 -> 129.6 | D32: 69.3 | E32: 69.1 | F32: =D32-E32 -> 0.2 | G32: =F32*1000 -> 200 | H32: =C32/1000 -> 0.1296 | I32: =(G32)/(H32) -> 1543.2099
A33: 38654 | B33: R1 | C33: =TS!F33 -> 75.6 | D33: 51.3 | E33: 50.8 | F33: =D33-E33 -> 0.5 | G33: =F33*1000 -> 500 | H33: =C33/1000 -> 0.0756 | I33: =(G33)/(H33) -> 6613.7566
B34: R2 | C34: =TS!F34 -> 75.3 | D34: 51.2 | E34: 50.9 | F34: =D34-E34 -> 0.3 | G34: =F34*1000 -> 300 | H34: =C34/1000 -> 0.0753 | I34: =(G34)/(H34) -> 3984.0637
B35: R3 | C35: =TS!F35 -> 76.5 | D35: 49.1 | E35: 48.8 | F35: =D35-E35 -> 0.3 | G35: =F35*1000 -> 300 | H35: =C35/1000 -> 0.0765 | I35: =(G35)/(H35) -> 3921.5686
A36: 38657 | B36: R1 | C36: =TS!F36 -> 76.6 | D36: 50.8 | E36: 50.4 | F36: =D36-E36 -> 0.4 | G36: =F36*1000 -> 400 | H36: =C36/1000 -> 0.0766 | I36: =(G36)/(H36) -> 5221.9321
B37: R2 | C37: =TS!F37 -> 84.5 | D37: 48.4 | E37: 48 | F37: =D37-E37 -> 0.4 | G37: =F37*1000 -> 400 | H37: =C37/1000 -> 0.0845 | I37: =(G37)/(H37) -> 4733.7278
B38: R3 | C38: =TS!F38 -> 86.2 | D38: 50.4 | E38: 50.1 | F38: =D38-E38 -> 0.3 | G38: =F38*1000 -> 300 | H38: =C38/1000 -> 0.0862 | I38: =(G38)/(H38) -> 3480.2784
A39: 38659 | B39: R1 | C39: =TS!F39 -> 56.7 | D39: 50.2 | E39: 49.8 | F39: =D39-E39 -> 0.4 | G39: =F39*1000 -> 400 | H39: =C39/1000 -> 0.0567 | I39: =(G39)/(H39) -> 7054.6737
B40: R2 | C40: =TS!F40 -> 65.3 | D40: 50.3 | E40: 50.1 | F40: =D40-E40 -> 0.2 | G40: =F40*1000 -> 200 | H40: =C40/1000 -> 0.0653 | I40: =(G40)/(H40) -> 3062.7871
...

Sheet gas
A1: Results for gas volume and composition for fresh fed (R1) and dry fed (R2) digesters, Sep 2009 - Nov 2010
A2: date | B2: reactor | C2: pH | D2: temp, oC | E2: pressure, mmHg | F2: total gas yeild, ml | G2: gas yield at stp | H2: CH4 (ml) | I2: CO2 (ml) | J2: O2 (ml) | K2: %CH4 | L2: %O2 | M2: %CO2
A3: 38621 | B3: A1 | C3: 6.75 | D3: 35 | E3: 648.8 | F3: 300 | G3: =(E3*F3*273.15)/((D3+273.15)*760) -> 227.01656 | H3: =K3/100*G3 -> 0 | I3: =(M3*G3)/100 -> 0 | J3: =(L3*G3)/100 -> 0
B4: A2 | C4: 6.76 | D4: 35 | E4: 648.8 | F4: 200 | G4: =(E4*F4*273.15)/((D4+273.15)*760) -> 151.34437 | H4: =K4/100*G4 -> 0 | I4: =(M4*G4)/100 -> 0 | J4: =(L4*G4)/100 -> 0
A5: 38622 | B5: A1 | C5: 6.35 | D5: 35 | E5: 646.7 | F5: 200 | G5: =(E5*F5*273.15)/((D5+273.15)*760) -> 150.85451 | H5: =K5/100*G5 -> 0 | I5: =(M5*G5)/100 -> 0 | J5: =(L5*G5)/100 -> 0
B6: A2 | C6: 6.38 | D6: 35 | E6: 646.7 | F6: 200 | G6: =(E6*F6*273.15)/((D6+273.15)*760) -> 150.85451 | H6: =K6/100*G6 -> 0 | I6: =(M6*G6)/100 -> 0 | J6: =(L6*G6)/100 -> 0
A7: 38624 | B7: A1 | C7: 6.04 | D7: 35 | E7: 648.7 | F7: 200 | G7: =(E7*F7*273.15)/((D7+273.15)*760) -> 151.32105 | H7: =K7/100*G7 -> 0 | I7: =(M7*G7)/100 -> 0 | J7: =(L7*G7)/100 -> 0
B8: A1 | C8: 5.34 | D8: 35 | E8: 648.7 | F8: 200 | G8: =(E8*F8*273.15)/((D8+273.15)*760) -> 151.32105 | H8: =K8/100*G8 -> 0 | I8: =(M8*G8)/100 -> 0 | J8: =(L8*G8)/100 -> 0
A9: 38625 | B9: A1 | C9: 6.01 | D9: 35 | E9: 650.6 | F9: 200 | G9: =(E9*F9*273.15)/((D9+273.15)*760) -> 151.76426 | H9: =K9/100*G9 -> 0 | I9: =(M9*G9)/100 -> 0 | J9: =(L9*G9)/100 -> 0
B10: A2 | C10: 5.61 | D10: 35 | E10: 650.6 | F10: 50 | G10: =(E10*F10*273.15)/((D10+273.15)*760) -> 37.941064 | H10: =K10/100*G10 -> 0 | I10: =(M10*G10)/100 -> 0 | J10: =(L10*G10)/100 -> 0
A11: 38626 | B11: A1 | C11: 6.29 | D11: 35 | E11: 658.6 | F11: 100 | G11: =(E11*F11*273.15)/((D11+273.15)*760) -> 76.8152 | H11: =K11/100*G11 -> 6.2297127 | I11: =(M11*G11)/100 -> 0 | J11: =(L11*G11)/100 -> 0 | K11: 8.11
B12: A2 | C12: 6.04 | D12: 35 | E12: 658.6 | F12: 0 | G12: =(E12*F12*273.15)/((D12+273.15)*760) -> 0 | H12: =K12/100*G12 -> 0 | I12: =(M12*G12)/100 -> 0 | J12: =(L12*G12)/100 -> 0 | K12: 3.2
A13: 38627 | B13: A1 | C13: 6.01 | D13: 35 | E13: 640 | F13: 500 | G13: =(E13*F13*273.15)/((D13+273.15)*760) -> 373.22903 | H13: =K13/100*G13 -> 0 | I13: =(M13*G13)/100 -> 0 | J13: =(L13*G13)/100 -> 0
B14: A2 | C14: 5.76 | D14: 35 | E14: 640 | F14: 1000 | G14: =(E14*F14*273.15)/((D14+273.15)*760) -> 746.45806 | H14: =K14/100*G14 -> 0 | I14: =(M14*G14)/100 -> 0 | J14: =(L14*G14)/100 -> 0
A15: 38629 | B15: A1 | C15: 6.06 | D15: 35 | E15: 642.8 | F15: 100 | G15: =(E15*F15*273.15)/((D15+273.15)*760) -> 74.972382 | H15: =K15/100*G15 -> 14.537145 | I15: =(M15*G15)/100 -> 0 | J15: =(L15*G15)/100 -> 0 | K15: 19.39
B16: A2 | C16: 6.06 | D16: 35 | E16: 642.8 | F16: 0 | G16: =(E16*F16*273.15)/((D16+273.15)*760) -> 0 | H16: =K16/100*G16 -> 0 | I16: =(M16*G16)/100 -> 0 | J16: =(L16*G16)/100 -> 0 | K16: 3.64
A17: 38631 | B17: A1 | C17: 5.99 | D17: 35 | E17: 645.5 | F17: 200 | G17: =(E17*F17*273.15)/((D17+273.15)*760) -> 150.57459 | H17: =K17/100*G17 -> 33.367329 | I17: =(M17*G17)/100 -> 0 | J17: =(L17*G17)/100 -> 0 | K17: 22.16
B18: A2 | C18: 5.73 | D18: 35 | E18: 645.5 | F18: 300 | G18: =(E18*F18*273.15)/((D18+273.15)*760) -> 225.86188 | H18: =K18/100*G18 -> 4.8786166 | I18: =(M18*G18)/100 -> 0 | J18: =(L18*G18)/100 -> 0 | K18: 2.16
A19: 38633 | B19: A1 | C19: 5.79 | D19: 35 | E19: 646 | F19: 300 | G19: =(E19*F19*273.15)/((D19+273.15)*760) -> 226.03683 | H19: =K19/100*G19 -> 57.435959 | I19: =(M19*G19)/100 -> 0 | J19: =(L19*G19)/100 -> 0 | K19: 25.41
B20: A2 | C20: 5.49 | D20: 35 | E20: 646 | F20: 200 | G20: =(E20*F20*273.15)/((D20+273.15)*760) -> 150.69122 | H20: =K20/100*G20 -> 1.6274652 | I20: =(M20*G20)/100 -> 0 | J20: =(L20*G20)/100 -> 0 | K20: 1.08
A21: 38634 | B21: A1 | C21: 5.3 | D21: 35 | F21: 200 | G21: =(E21*F21*273.15)/((D21+273.15)*760) -> 0 | H21: =K21/100*G21 -> 0 | I21: =(M21*G21)/100 -> 0 | J21: =(L21*G21)/100 -> 0
B22: A2 | C22: 4.39 | D22: 35 | F22: 100 | G22: =(E22*F22*273.15)/((D22+273.15)*760) -> 0 | H22: =K22/100*G22 -> 0 | I22: =(M22*G22)/100 -> 0 | J22: =(L22*G22)/100 -> 0
A23: 38636 | B23: A1 | C23: 5.59 | D23: 35 | F23: 400 | G23: =(E23*F23*273.15)/((D23+273.15)*760) -> 0 | H23: =K23/100*G23 -> 0 | I23: =(M23*G23)/100 -> 0 | J23: =(L23*G23)/100 -> 0
B24: A2 | C24: 5.59 | D24: 35 | F24: 200 | G24: =(E24*F24*273.15)/((D24+273.15)*760) -> 0 | H24: =K24/100*G24 -> 0 | I24: =(M24*G24)/100 -> 0 | J24: =(L24*G24)/100 -> 0
A25: 38641 | B25: A1 | C25: 6.95 | D25: 35 | E25: 649.2 | F25: 600 | G25: =(E25*F25*273.15)/((D25+273.15)*760) -> 454.31304 | H25: =K25/100*G25 -> 18.626835 | I25: =(M25*G25)/100 -> 0 | J25: =(L25*G25)/100 -> 0 | K25: 4.1
B26: A2 | C26: 6.98 | D26: 35 | E26: 649.2 | F26: 450 | G26: =(E26*F26*273.15)/((D26+273.15)*760) -> 340.73478 | H26: =K26/100*G26 -> 8.1776347 | I26: =(M26*G26)/100 -> 0 | J26: =(L26*G26)/100 -> 0 | K26: 2.4
A27: 38643 | B27: A1 | C27: 6.6 | D27: 35 | F27: 400 | G27: =(E27*F27*273.15)/((D27+273.15)*760) -> 0 | H27: =K27/100*G27 -> 0 | I27: =(M27*G27)/100 -> 0 | J27: =(L27*G27)/100 -> 0 | K27: 7.3
B28: A2 | C28: 6.8 | D28: 35 | F28: 200 | G28: =(E28*F28*273.15)/((D28+273.15)*760) -> 0 | H28: =K28/100*G28 -> 0 | I28: =(M28*G28)/100 -> 0 | J28: =(L28*G28)/100 -> 0 | K28: 3.4
A29: 38645 | B29: A1 | C29: 6.47 | D29: 35 | E29: 646.6 | F29: 400 | G29: =(E29*F29*273.15)/((D29+273.15)*760) -> 301.66237 | H29: =K29/100*G29 -> 38.31112 | I29: =(M29*G29)/100 -> 0 | J29: =(L29*G29)/100 -> 0 | K29: 12.7
B30: A2 | C30: 6.46 | D30: 35 | E30: 646.6 | F30: 300 | G30: =(E30*F30*273.15)/((D30+273.15)*760) -> 226.24677 | H30: =K30/100*G30 -> 13.34856 | I30: =(M30*G30)/100 -> 0 | J30: =(L30*G30)/100 -> 0 | K30: 5.9
A31: 38647 | B31: A1 | C31: 6.71 | D31: 35 | E31: 648.8 | F31: 600 | G31: =(E31*F31*273.15)/((D31+273.15)*760) -> 454.03312 | H31: =K31/100*G31 -> 237.91335 | I31: =(M31*G31)/100 -> 0 | J31: =(L31*G31)/100 -> 0 | K31: 52.4
B32: A2 | C32: 6.55 | D32: 35 | E32: 648.8 | F32: 300 | G32: =(E32*F32*273.15)/((D32+273.15)*760) -> 227.01656 | H32: =K32/100*G32 -> 61.294471 | I32: =(M32*G32)/100 -> 0 | J32: =(L32*G32)/100 -> 0 | K32: 27
A33: 38648 | B33: A1 | C33: 6.78 | D33: 35 | E33: 645.6 | F33: 500 | G33: =(E33*F33*273.15)/((D33+273.15)*760) -> 376.49479 | H33: =K33/100*G33 -> 188.81214 | I33: =(M33*G33)/100 -> 135.16163 | J33: =(L33*G33)/100 -> 19.50243 | K33: 50.15 | L33: 5.18 | M33: 35.9
B34: A2 | C34: 6.66 | D34: 35 | E34: 645.6 | F34: 200 | G34: =(E34*F34*273.15)/((D34+273.15)*760) -> 150.59791 | H34: =K34/100*G34 -> 59.93797 | I34: =(M34*G34)/100 -> 65.058299 | J34: =(L34*G34)/100 -> 25.601645 | K34: 39.8 | L34: 17 | M34: 43.2
A35: 38649 | B35: A1 | D35: 35 | E35: 650.24 | F35: 650 | G35: =(E35*F35*273.15)/((D35+273.15)*760) -> 492.96091 | H35: =K35/100*G35 -> 319.43867 | I35: =(M35*G35)/100 -> 172.04336 | J35: =(L35*G35)/100 -> 11.831062 | K35: 64.8 | L35: 2.4 | M35: 34.9
B36: A2 | D36: 35 | E36: 650.24 | F36: 450 | G36: =(E36*F36*273.15)/((D36+273.15)*760) -> 341.28063 | H36: =K36/100*G36 -> 108.18596 | I36: =(M36*G36)/100 -> 83.955034 | J36: =(L36*G36)/100 -> 29.691415 | K36: 31.7 | L36: 8.7 | M36: 24.6
B37: A3 | D37: 35 | E37: 650.24 | F37: 300 | G37: =(E37*F37*273.15)/((D37+273.15)*760) -> 227.52042 | H37: =K37/100*G37 -> 109.89236 | I37: =(M37*G37)/100 -> 48.91689 | J37: =(L37*G37)/100 -> 14.561307 | K37: 48.3 | L37: 6.4 | M37: 21.5
A38: 38650 | B38: A1 | C38: 7.06 | D38: 35 | E38: 649.8 | F38: 600 | G38: =(E38*F38*273.15)/((D38+273.15)*760) -> 454.73292 | H38: =K38/100*G38 -> 282.84388 | I38: =(M38*G38)/100 -> 134.60094 | J38: =(L38*G38)/100 -> 10.458857 | K38: 62.2 | L38: 2.3 | M38: 29.6
B39: A2 | C39: 6.7 | D39: 35 | E39: 649.8 | F39: 200 | G39: =(E39*F39*273.15)/((D39+273.15)*760) -> 151.57764 | H39: =K39/100*G39 -> 77.001442 | I39: =(M39*G39)/100 -> 62.449988 | J39: =(L39*G39)/100 -> 12.277789 | K39: 50.8 | L39: 8.1 | M39: 41.2
B40: A3 | C40: 7.08 | D40: 35 | E40: 649.8 | F40: 400 | G40: =(E40*F40*273.15)/((D40+273.15)*760) -> 303.15528 | H40: =K40/100*G40 -> 180.9837 | I40: =(M40*G40)/100 -> 93.674982 | J40: =(L40*G40)/100 -> 28.496596 | K40: 59.7 | L40: 9.4 | M40: 30.9
...

Sheet MassBVs (R1)
A1: Date | B1: Reactor | C1: TS fed in (g) | D1: VS fed in (g) | E1: Vsin (mg) | F1: Vsin, mg/L | G1: Vsout (mg/L) | H1: Vsout, mg | I1: Vsleft in rxter (mg) | J1: Volatile solids in reactor,mg | K1: End of day VS, mg | L1: ∆VS | M1: sum VS, mg | N1: CH4 | O1: CH4, L | P1: sum CH4, ml | Q1: ml/gVS | R1: ft3/lb vs
A2: 38647 | B2: R1 | C2: 1 | D2: =C2*0.7 -> 0.7 | E2: =D2*1000 -> 700 | F2: =E2*1000/200 -> 3500 | G2: =VS!I22 -> 11952.191 | H2: =G2*0.2 -> 2390.4382 | I2: =G2*1.8 -> 21513.944 | J2: =I2+E2 -> 22213.944 | K2: =G2*2 -> 23904.382 | N2: =gas!H31 -> 237.91335 | P2: 0
A3: 38649 | B3: R1 | C3: 1 | D3: =C3*0.7 -> 0.7 | E3: =D3*1000 -> 700 | F3: =E3*1000/200 -> 3500 | G3: =VS!I24 -> 10062.893 | H3: =G3*0.2 -> 2012.5786 | I3: =G3*1.8 -> 18113.208 | J3: =I3+E3 -> 18813.208 | K3: =G3*2 -> 20125.786 | L3: =J2-K3 -> 2088.1581 | M3: =L3 -> 2088.1581 | N3: =gas!H35 -> 319.43867 | O3: =N3/1000 -> 0.31943867 | P3: =N3 -> 319.43867 | Q3: =P3/(M3/1000) -> 152.97629 | R3: =Q3/62.4 -> 2.4515431
A4: 38651 | B4: R1 | C4: 1 | D4: =C4*0.7 -> 0.7 | E4: =D4*1000 -> 700 | F4: =E4*1000/200 -> 3500 | G4: =VS!I27 -> 7869.8846 | H4: =G4*0.2 -> 1573.9769 | I4: =G4*1.8 -> 14165.792 | J4: =I4+E4 -> 14865.792 | K4: =G4*2 -> 15739.769 | L4: =J3-K4 -> 3073.4384 | M4: =M3+L4 -> 5161.5965 | N4: =gas!H38 -> 282.84388 | O4: =N4/1000 -> 0.28284388 | P4: =P3+N4 -> 602.28254 | Q4: =P4/(M4/1000) -> 116.68532 | R4: =Q4/62.4 -> 1.8699571
A5: 38657 | B5: R1 | C5: 1 | D5: =C5*0.7 -> 0.7 | E5: =D5*1000 -> 700 | F5: =E5*1000/200 -> 3500 | G5: =VS!I36 -> 5221.9321 | H5: =G5*0.2 -> 1044.3864 | I5: =G5*1.8 -> 9399.4778 | J5: =I5+E5 -> 10099.478 | K5: =G5*2 -> 10443.864 | L5: =J4-K5 -> 4421.928 | M5: =M4+L5 -> 9583.5245 | N5: =gas!H50 -> 604.32321 | O5: =N5/1000 -> 0.60432321 | P5: =P4+N5 -> 1206.6058 | Q5: =P5/(M5/1000) -> 125.90418 | R5: =Q5/62.4 -> 2.0176951
A6: 38659 | B6: R1 | C6: 1 | D6: =C6*0.7 -> 0.7 | E6: =D6*1000 -> 700 | F6: =E6*1000/200 -> 3500 | G6: =VS!I39 -> 7054.6737 | H6: =G6*0.2 -> 1410.9347 | I6: =G6*1.8 -> 12698.413 | J6: =I6+E6 -> 13398.413 | K6: =G6*2 -> 14109.347 | L6: =J5-K6 -> -4009.8696 | M6: =M5+L6 -> 5573.6548 | N6: =gas!H53 -> 639.87419 | O6: =N6/1000 -> 0.63987419 | P6: =P5+N6 -> 1846.4799 | Q6: =P6/(M6/1000) -> 331.2871 | R6: =Q6/62.4 -> 5.3090881
A7: 38661 | B7: R1 | C7: 1 | D7: =C7*0.7 -> 0.7 | E7: =D7*1000 -> 700 | F7: =E7*1000/200 -> 3500 | G7: =VS!I42 -> 5228.7582 | H7: =G7*0.2 -> 1045.7516 | I7: =G7*1.8 -> 9411.7647 | J7: =I7+E7 -> 10111.765 | K7: =G7*2 -> 10457.516 | L7: =J6-K7 -> 2940.8964 | M7: =M6+L7 -> 8514.5512 | N7: =gas!H56 -> 547.44126 | O7: =N7/1000 -> 0.54744126 | P7: =P6+N7 -> 2393.9212 | Q7: =P7/(M7/1000) -> 281.15648 | R7: =Q7/62.4 -> 4.5057128
A8: 38668 | B8: R1 | C8: 1 | D8: =C8*0.7 -> 0.7 | E8: =D8*1000 -> 700 | F8: =E8*1000/200 -> 3500 | G8: =VS!I48 -> 3787.8788 | H8: =G8*0.2 -> 757.57576 | I8: =G8*1.8 -> 6818.1818 | J8: =I8+E8 -> 7518.1818 | K8: =G8*2 -> 7575.7576 | L8: =J7-K8 -> 2536.0071 | M8: =M7+L8 -> 11050.558 | N8: =gas!H65 -> 147.06711 | O8: =N8/1000 -> 0.14706711 | P8: =P7+N8 -> 2540.9883 | Q8: =P8/(M8/1000) -> 229.94208 | R8: =Q8/62.4 -> 3.6849692
A9: 38671 | B9: R1 | C9: 1 | D9: =C9*0.7 -> 0.7 | E9: =D9*1000 -> 700 | F9: =E9*1000/200 -> 3500 | G9: =VS!I51 -> 7407.4074 | H9: =G9*0.2 -> 1481.4815 | I9: =G9*1.8 -> 13333.333 | J9: =I9+E9 -> 14033.333 | K9: =G9*2 -> 14814.815 | L9: =J8-K9 -> -7296.633 | M9: =M8+L9 -> 3753.9253 | N9: =gas!H68 -> 254.61498 | O9: =N9/1000 -> 0.25461498 | P9: =P8+N9 -> 2795.6033 | Q9: =P9/(M9/1000) -> 744.71468 | R9: =Q9/62.4 -> 11.93453
A10: 38673 | B10: R1 | C10: 1 | D10: =C10*0.7 -> 0.7 | E10: =D10*1000 -> 700 | F10: =E10*1000/200 -> 3500 | G10: =VS!I54 -> 4184.1004 | H10: =G10*0.2 -> 836.82008 | I10: =G10*1.8 -> 7531.3808 | J10: =I10+E10 -> 8231.3808 | K10: =G10*2 -> 8368.2008 | L10: =J9-K10 -> 5665.1325 | M10: =M9+L10 -> 9419.0578 | N10: =gas!H71 -> 403.85414 | O10: =N10/1000 -> 0.40385414 | P10: =P9+N10 -> 3199.4574 | Q10: =P10/(M10/1000) -> 339.67914 | R10: =Q10/62.4 -> 5.4435759
A11: 38675 | B11: R1 | C11: 1 | D11: =C11*0.7 -> 0.7 | E11: =D11*1000 -> 700 | F11: =E11*1000/200 -> 3500 | G11: =VS!I57 -> 5228.7582 | H11: =G11*0.2 -> 1045.7516 | I11: =G11*1.8 -> 9411.7647 | J11: =I11+E11 -> 10111.765 | K11: =G11*2 -> 10457.516 | L11: =J10-K11 -> -2226.1356 | M11: =M10+L11 -> 7192.9222 | N11: =gas!H74 -> 110.72123 | O11: =N11/1000 -> 0.11072123 | P11: =P10+N11 -> 3310.1787 | Q11: =P11/(M11/1000) -> 460.19942 | R11: =Q11/62.4 -> 7.3749908
A12: 38687 | B12: R1 | C12: 1 | D12: =C12*0.7 -> 0.7 | E12: =D12*1000 -> 700 | F12: =E12*1000/200 -> 3500 | G12: =VS!I60 -> 3865.9794 | H12: =G12*0.2 -> 773.19588 | I12: =G12*1.8 -> 6958.7629 | J12: =I12+E12 -> 7658.7629 | K12: =G12*2 -> 7731.9588 | L12: =J11-K12 -> 2379.8059 | M12: =M11+L12 -> 9572.7282 | N12: =gas!H86 -> 152.87648 | O12: =N12/1000 -> 0.15287648 | P12: =P11+N12 -> 3463.0551 | Q12: =P12/(M12/1000) -> 361.76261 | R12: =Q12/62.4 -> 5.7974778
A13: 38689 | B13: R1 | C13: 1 | D13: =C13*0.7 -> 0.7 | E13: =D13*1000 -> 700 | F13: =E13*1000/200 -> 3500 | G13: =VS!I63 -> 5056.89 | H13: =G13*0.2 -> 1011.378 | I13: =G13*1.8 -> 9102.402 | J13: =I13+E13 -> 9802.402 | K13: =G13*2 -> 10113.78 | L13: =J12-K13 -> -2455.0171 | M13: =M12+L13 -> 7117.711 | N13: =gas!H89 -> 245.01102 | O13: =N13/1000 -> 0.24501102 | P13: =P12+N13 -> 3708.0662 | Q13: =P13/(M13/1000) -> 520.96329 | R13: =Q13/62.4 -> 8.3487707
A14: 38692 | B14: R1 | C14: 2 | D14: =C14*0.7 -> 1.4 | E14: =D14*1000 -> 1400 | F14: =E14*1000/200 -> 7000 | G14: =VS!I66 -> 4418.2622 | H14: =G14*0.2 -> 883.65243 | I14: =G14*1.8 -> 7952.8719 | J14: =I14+E14 -> 9352.8719 | K14: =G14*2 -> 8836.5243 | L14: =J13-K14 -> 965.87772 | M14: =M13+L14 -> 8083.5888 | N14: =gas!H92 -> 148.87497 | O14: =N14/1000 -> 0.14887497 | P14: =P13+N14 -> 3856.9411 | Q14: =P14/(M14/1000) -> 477.13228 | R14: =Q14/62.4 -> 7.6463506
A15: 38696 | B15: R1 | C15: 1 | D15: =C15*0.7 -> 0.7 | E15: =D15*1000 -> 700 | F15: =E15*1000/200 -> 3500 | G15: =VS!I69 -> 4748.3381 | H15: =G15*0.2 -> 949.66762 | I15: =G15*1.8 -> 8547.0085 | J15: =I15+E15 -> 9247.0085 | K15: =G15*2 -> 9496.6762 | L15: =J14-K15 -> -143.80429 | M15: =M14+L15 -> 7939.7845 | N15: =gas!H95 -> 181.13085 | O15: =N15/1000 -> 0.18113085 | P15: =P14+N15 -> 4038.072 | Q15: =P15/(M15/1000) -> 508.5871 | R15: =Q15/62.4 -> 8.1504344
A16: 38699 | B16: R1 | C16: 1 | D16: =C16*0.7 -> 0.7 | E16: =D16*1000 -> 700 | F16: =E16*1000/200 -> 3500 | G16: =VS!I72 -> 4580.1527 | H16: =G16*0.2 -> 916.03053 | I16: =G16*1.8 -> 8244.2748 | J16: =I16+E16 -> 8944.2748 | K16: =G16*2 -> 9160.3053 | L16: =J15-K16 -> 86.703203 | M16: =M15+L16 -> 8026.4877 | N16: =gas!H98 -> 127.57393 | O16: =N16/1000 -> 0.12757393 | P16: =P15+N16 -> 4165.6459 | Q16: =P16/(M16/1000) -> 518.98739 | R16: =Q16/62.4 -> 8.3171057
A17: 38701 | B17: R1 | C17: 1 | D17: =C17*0.7 -> 0.7 | E17: =D17*1000 -> 700 | F17: =E17*1000/200 -> 3500 | G17: =VS!I78 -> 4815.4093 | H17: =G17*0.2 -> 963.08186 | I17: =G17*1.8 -> 8667.7368 | J17: =I17+E17 -> 9367.7368 | K17: =G17*2 -> 9630.8186 | L17: =J16-K17 -> -686.54381 | M17: =M16+L17 -> 7339.9439 | N17: =gas!H104 -> 121.94057 | O17: =N17/1000 -> 0.12194057 | P17: =P16+N17 -> 4287.5865 | Q17: =P17/(M17/1000) -> 584.14432 | R17: =Q17/62.4 -> 9.3612871
A18: 38720 | B18: R1 | C18: 4 | D18: =C18*0.7 -> 2.8 | E18: =D18*1000 -> 2800 | F18: =E18*1000/200 -> 14000 | G18: =VS!I81 -> 3508.7719 | H18: =G18*0.2 -> 701.75439 | I18: =G18*1.8 -> 6315.7895 | J18: =I18+E18 -> 9115.7895 | K18: =G18*2 -> 7017.5439 | L18: =J17-K18 -> 2350.1929 | M18: =M17+L18 -> 9690.1368 | N18: =gas!H113 -> 120.95607 | O18: =N18/1000 -> 0.12095607 | P18: =P17+N18 -> 4408.5426 | Q18: =P18/(M18/1000) -> 454.95153 | R18: =Q18/62.4 -> 7.2908899
A19: 38722 | B19: R1 | C19: 1 | D19: =C19*0.7 -> 0.7 | E19: =D19*1000 -> 700 | F19: =E19*1000/200 -> 3500 | G19: =VS!I84 -> 2257.3363 | H19: =G19*0.2 -> 451.46727 | I19: =G19*1.8 -> 4063.2054 | J19: =I19+E19 -> 4763.2054 | K19: =G19*2 -> 4514.6727 | L19: =J18-K19 -> 4601.1168 | M19: =M18+L19 -> 14291.254 | N19: =gas!H116 -> 112.74907 | O19: =N19/1000 -> 0.11274907 | P19: =P18+N19 -> 4521.2916 | Q19: =P19/(M19/1000) -> 316.36774 | R19: =Q19/62.4 -> 5.0699959
A20: 38724 | B20: R1 | C20: 1 | D20: =C20*0.7 -> 0.7 | E20: =D20*1000 -> 700 | F20: =E20*1000/200 -> 3500 | G20: =VS!I88 -> 2525.2525 | H20: =G20*0.2 -> 505.05051 | I20: =G20*1.8 -> 4545.4545 | J20: =I20+E20 -> 5245.4545 | K20: =G20*2 -> 5050.5051 | L20: =J19-K20 -> -287.29963 | M20: =M19+L20 -> 14003.954 | N20: =gas!H119 -> 92.84588 | O20: =N20/1000 -> 0.09284588 | P20: =P19+N20 -> 4614.1375 | Q20: =P20/(M20/1000) -> 329.4882 | R20: =Q20/62.4 -> 5.2802595
A21: 38727 | B21: R1 | C21: 1 | D21: =C21*0.7 -> 0.7 | E21: =D21*1000 -> 700 | F21: =E21*1000/200 -> 3500 | G21: =VS!I92 -> 4264.3923 | H21: =G21*0.2 -> 852.87846 | I21: =G21*1.8 -> 7675.9062 | J21: =I21+E21 -> 8375.9062 | K21: =G21*2 -> 8528.7846 | L21: =J20-K21 -> -3283.3301 | M21: =M20+L21 -> 10720.624 | N21: =gas!H122 -> 129.86452 | O21: =N21/1000 -> 0.12986452 | P21: =P20+N21 -> 4744.002 | Q21: =P21/(M21/1000) -> 442.51175 | R21: =Q21/62.4 -> 7.0915345
A22: 38729 | B22: R1 | C22: 1 | D22: =C22*0.7 -> 0.7 | E22: =D22*1000 -> 700 | F22: =E22*1000/200 -> 3500 | G22: =VS!I95 -> 4484.3049 | H22: =G22*0.2 -> 896.86099 | I22: =G22*1.8 -> 8071.7489 | J22: =I22+E22 -> 8771.7489 | K22: =G22*2 -> 8968.6099 | L22: =J21-K22 -> -592.70368 | M22: =M21+L22 -> 10127.92 | N22: =gas!H125 -> 113.61895 | O22: =N22/1000 -> 0.11361895 | P22: =P21+N22 -> 4857.621 | Q22: =P22/(M22/1000) -> 479.62671 | R22: =Q22/62.4 -> 7.6863254
A23: 38731 | B23: R1 | C23: 1 | D23: =C23*0.7 -> 0.7 | E23: =D23*1000 -> 700 | F23: =E23*1000/200 -> 3500 | G23: =VS!I98 -> 4373.1778 | H23: =G23*0.2 -> 874.63557 | I23: =G23*1.8 -> 7871.7201 | J23: =I23+E23 -> 8571.7201 | K23: =G23*2 -> 8746.3557 | L23: =J22-K23 -> 25.393194 | M23: =M22+L23 -> 10153.313 | N23: =gas!H128 -> 145.38394 | O23: =N23/1000 -> 0.14538394 | P23: =P22+N23 -> 5003.0049 | Q23: =P23/(M23/1000) -> 492.74604 | R23: =Q23/62.4 -> 7.8965711
A24: 38734 | B24: R1 | C24: 1 | D24: =C24*0.7 -> 0.7 | E24: =D24*1000 -> 700 | F24: =E24*1000/200 -> 3500 | G24: =VS!I101 -> 3929.2731 | H24: =G24*0.2 -> 785.85462 | I24: =G24*1.8 -> 7072.6916 | J24: =I24+E24 -> 7772.6916 | K24: =G24*2 -> 7858.5462 | L24: =J23-K24 -> 713.17395 | M24: =M23+L24 -> 10866.487 | N24: =gas!H131 -> 164.49256 | O24: =N24/1000 -> 0.16449256 | P24: =P23+N24 -> 5167.4975 | Q24: =P24/(M24/1000) -> 475.54443 | R24: =Q24/62.4 -> 7.6209043
A25: 38736 | B25: R1 | C25: 1 | D25: =C25*0.7 -> 0.7 | E25: =D25*1000 -> 700 | F25: =E25*1000/200 -> 3500 | G25: =VS!I104 -> 3154.5741 | H25: =G25*0.2 -> 630.91483 | I25: =G25*1.8 -> 5678.2334 | J25: =I25+E25 -> 6378.2334 | K25: =G25*2 -> 6309.1483 | L25: =J24-K25 -> 1463.5433 | M25: =M24+L25 -> 12330.031 | N25: =gas!H134 -> 138.10221 | O25: =N25/1000 -> 0.13810221 | P25: =P24+N25 -> 5305.5997 | Q25: =P25/(M25/1000) -> 430.29899 | R25: =Q25/62.4 -> 6.8958171
A26: 38738 | B26: R1 | C26: 1 | D26: =C26*0.7 -> 0.7 | E26: =D26*1000 -> 700 | F26: =E26*1000/200 -> 3500 | G26: =VS!I107 -> 3205.1282 | H26: =G26*0.2 -> 641.02564 | I26: =G26*1.8 -> 5769.2308 | J26: =I26+E26 -> 6469.2308 | K26: =G26*2 -> 6410.2564 | L26: =J25-K26 -> -32.022972 | M26: =M25+L26 -> 12298.008 | N26: =gas!H137 -> 151.18612 | O26: =N26/1000 -> 0.15118612 | P26: =P25+N26 -> 5456.7858 | Q26: =P26/(M26/1000) -> 443.713 | R26: =Q26/62.4 -> 7.1107852
A27: 38741 | B27: R1 | C27: 1 | D27: =C27*0.7 -> 0.7 | E27: =D27*1000 -> 700 | F27: =E27*1000/200 -> 3500 | G27: =VS!I110 -> 3027.2452 | H27: =G27*0.2 -> 605.44904 | I27: =G27*1.8 -> 5449.0414 | J27: =I27+E27 -> 6149.0414 | K27: =G27*2 -> 6054.4904 | L27: =J26-K27 -> 414.74036 | M27: =M26+L27 -> 12712.748 | N27: =gas!H140 -> 123.32944 | O27: =N27/1000 -> 0.12332944 | P27: =P26+N27 -> 5580.1152 | Q27: =P27/(M27/1000) -> 438.93856 | R27: =Q27/62.4 -> 7.0342718
A28: 38743 | B28: R1 | C28: 1 | D28: =C28*0.7 -> 0.7 | E28: =D28*1000 -> 700 | F28: =E28*1000/200 -> 3500 | G28: =VS!I113 -> 2127.6596 | H28: =G28*0.2 -> 425.53191 | I28: =G28*1.8 -> 3829.7872 | J28: =I28+E28 -> 4529.7872 | K28: =G28*2 -> 4255.3191 | L28: =J27-K28 -> 1893.7222 | M28: =M27+L28 -> 14606.47 | N28: =gas!H143 -> 145.82093 | O28: =N28/1000 -> 0.14582093 | P28: =P27+N28 -> 5725.9362 | Q28: =P28/(M28/1000) -> 392.01368 | R28: =Q28/62.4 -> 6.2822706
A29: 38745 | B29: R1 | C29: 1 | D29: =C29*0.7 -> 0.7 | E29: =D29*1000 -> 700 | F29: =E29*1000/200 -> 3500 | G29: =VS!I116 -> 2285.7143 | H29: =G29*0.2 -> 457.14286 | I29: =G29*1.8 -> 4114.2857 | J29: =I29+E29 -> 4814.2857 | K29: =G29*2 -> 4571.4286 | L29: =J28-K29 -> -41.641337 | M29: =M28+L29 -> 14564.829 | N29: =gas!H146 -> 125.48715 | O29: =N29/1000 -> 0.12548715 | P29: =P28+N29 -> 5851.4233 | Q29: =P29/(M29/1000) -> 401.75023 | R29: =Q29/62.4 -> 6.438305
A30: 38748 | B30: R1 | C30: 1 | D30: =C30*0.7 -> 0.7 | E30: =D30*1000 -> 700 | F30: =E30*1000/200 -> 3500 | G30: 2875.5265 | H30: =G30*0.2 -> 575.1053 | I30: =G30*1.8 -> 5175.9477 | J30: =I30+E30 -> 5875.9477 | K30: =G30*2 -> 5751.053 | L30: =J29-K30 -> -936.76724 | M30: =M29+L30 -> 13628.062 | N30: =gas!H148 -> 77.972754 | O30: =N30/1000 -> 0.077972754 | P30: =P29+N30 -> 5929.3961 | Q30: =P30/(M30/1000) -> 435.08727 | R30: =Q30/62.4 -> 6.9725524
A31: 38750 | B31: R1 | C31: 1 | D31: =C31*0.7 -> 0.7 | E31: =D31*1000 -> 700 | F31: =E31*1000/200 -> 3500 | G31: 2859.4979 | H31: =G31*0.2 -> 571.89958 | I31: =G31*1.8 -> 5147.0962 | J31: =I31+E31 -> 5847.0962 | K31: =G31*2 -> 5718.9958 | L31: =J30-K31 -> 156.95186 | M31: =M30+L31 -> 13785.013 | N31: =gas!H150 -> 82.928918 | O31: =N31/1000 -> 0.082928918 | P31: =P30+N31 -> 6012.325 | Q31: =P31/(M31/1000) -> 436.14937 | R31: =Q31/62.4 -> 6.9895733
A32: 38752 | B32: R1 | C32: 1 | D32: =C32*0.7 -> 0.7 | E32: =D32*1000 -> 700 | F32: =E32*1000/200 -> 3500 | G32: 3429.1038 | H32: =G32*0.2 -> 685.82075 | I32: =G32*1.8 -> 6172.3868 | J32: =I32+E32 -> 6872.3868 | K32: =G32*2 -> 6858.2075 | L32: =J31-K32 -> -1011.1113 | M32: =M31+L32 -> 12773.902 | N32: =gas!H152 -> 54.607046 | O32: =N32/1000 -> 0.054607046 | P32: =P31+N32 -> 6066.932 | Q32: =P32/(M32/1000) -> 474.94743 | R32: =Q32/62.4 -> 7.6113371
A33: 38755 | B33: R1 | C33: 1 | D33: =C33*0.7 -> 0.7 | E33: =D33*1000 -> 700 | F33: =E33*1000/200 -> 3500 | G33: 3418.1365 | H33: =G33*0.2 -> 683.6273 | I33: =G33*1.8 -> 6152.6457 | J33: =I33+E33 -> 6852.6457 | K33: =G33*2 -> 6836.273 | L33: =J32-K33 -> 36.113812 | M33: =M32+L33 -> 12810.016 | N33: =gas!H154 -> 113.27216 | O33: =N33/1000 -> 0.11327216 | P33: =P32+N33 -> 6180.2042 | Q33: =P33/(M33/1000) -> 482.45094 | R33: =Q33/62.4 -> 7.7315855
A34: 38757 | B34: R1 | C34: 1 | D34: =C34*0.7 -> 0.7 | E34: =D34*1000 -> 700 | F34: =E34*1000/200 -> 3500 | G34: 2490.9873 | H34: =G34*0.2 -> 498.19746 | I34: =G34*1.8 -> 4483.7771 | J34: =I34+E34 -> 5183.7771 | K34: =G34*2 -> 4981.9746 | L34: =J33-K34 -> 1870.6711 | M34: =M33+L34 -> 14680.687 | N34: =gas!H156 -> 85.86361 | O34: =N34/1000 -> 0.08586361 | P34: =P33+N34 -> 6266.0678 | Q34: =P34/(M34/1000) -> 426.82388 | R34: =Q34/62.4 -> 6.8401263
A35: 38759 | B35: R1 | C35: 1 | D35: =C35*0.7 -> 0.7 | E35: =D35*1000 -> 700 | F35: =E35*1000/200 -> 3500 | G35: 3185.8228 | H35: =G35*0.2 -> 637.16455 | I35: =G35*1.8 -> 5734.481 | J35: =I35+E35 -> 6434.481 | K35: =G35*2 -> 6371.6455 | L35: =J34-K35 -> -1187.8684 | M35: =M34+L35 -> 13492.819 | N35: =gas!H158 -> 83.703331 | O35: =N35/1000 -> 0.083703331 | P35: =P34+N35 -> 6349.7711 | Q35: =P35/(M35/1000) -> 470.60376 | R35: =Q35/62.4 -> 7.5417269
A36: 38762 | B36: R1 | C36: 1 | D36: =C36*0.7 -> 0.7 | E36: =D36*1000 -> 700 | F36: =E36*1000/200 -> 3500 | G36: =VS!I130 -> 3367.0034 | H36: =G36*0.2 -> 673.40067 | I36: =G36*1.8 -> 6060.6061 | J36: =I36+E36 -> 6760.6061 | K36: =G36*2 -> 6734.0067 | L36: =J35-K36 -> -299.52577 | M36: =M35+L36 -> 13193.293 | N36: =gas!H160 -> 101.80634 | O36: =N36/1000 -> 0.10180634 | P36: =P35+N36 -> 6451.5775 | Q36: =P36/(M36/1000) -> 489.00434 | R36: =Q36/62.4 -> 7.836608
A37: 38764 | B37: R1 | C37: 1 | D37: =C37*0.7 -> 0.7 | E37: =D37*1000 -> 700 | F37: =E37*1000/200 -> 3500 | G37: =VS!I132 -> 3257.329 | H37: =G37*0.2 -> 651.4658 | I37: =G37*1.8 -> 5863.1922 | J37: =I37+E37 -> 6563.1922 | K37: =G37*2 -> 6514.658 | L37: =J36-K37 -> 245.94808 | M37: =M36+L37 -> 13439.241 | N37: =gas!H162 -> 90.46648 | O37: =N37/1000 -> 0.09046648 | P37: =P36+N37 -> 6542.044 | Q37: =P37/(M37/1000) -> 486.78672 | R37: =Q37/62.4 -> 7.8010692
A38: 38766 | B38: R1 | C38: 1 | D38: =C38*0.7 -> 0.7 | E38: =D38*1000 -> 700 | F38: =E38*1000/200 -> 3500 | G38: =VS!I134 -> 2961.5005 | H38: =G38*0.2 -> 592.3001 | I38: =G38*1.8 -> 5330.7009 | J38: =I38+E38 -> 6030.7009 | K38: =G38*2 -> 5923.001 | L38: =J37-K38 -> 640.1912 | M38: =M37+L38 -> 14079.432 | N38: =gas!H164 -> 64.541966 | O38: =N38/1000 -> 0.064541966 | P38: =P37+N38 -> 6606.5859 | Q38: =P38/(M38/1000) -> 469.23667 | R38: =Q38/62.4 -> 7.5198185
A39: 38771 | B39: R1 | C39: 1 | D39: =C39*0.7 -> 0.7 | E39: =D39*1000 -> 700 | F39: =E39*1000/200 -> 3500 | G39: =VS!I136 -> 2406.7389 | H39: =G39*0.2 -> 481.34777 | I39: =G39*1.8 -> 4332.13 | J39: =I39+E39 -> 5032.13 | K39: =G39*2 -> 4813.4777 | L39: =J38-K39 -> 1217.2232 | M39: =M38+L39 -> 15296.655 | N39: =gas!H166 -> 82.62497 | O39: =N39/1000 -> 0.08262497 | P39: =P38+N39 -> 6689.2109 | Q39: =P39/(M39/1000) -> 437.29892 | R39: =Q39/62.4 -> 7.0079956
A40: 38773 | B40: R1 | C40: 1 | D40: =C40*0.7 -> 0.7 | E40: =D40*1000 -> 700 | F40: =E40*1000/200 -> 3500 | G40: =VS!I138 -> 2336.4486 | H40: =G40*0.2 -> 467.28972 | I40: =G40*1.8 -> 4205.6075 | J40: =I40+E40 -> 4905.6075 | K40: =G40*2 -> 4672.8972 | L40: =J39-K40 -> 359.23277 | M40: =M39+L40 -> 15655.888 | N40: =gas!H168 -> 89.674512 | O40: =N40/1000 -> 0.089674512 | P40: =P39+N40 -> 6778.8854 | Q40: =P40/(M40/1000) -> 432.99271 | R40: =Q40/62.4 -> 6.9389857
...

Sheet MassBVs (R2)
A1: Date | B1: Reactor | C1: TS fed in (g) | D1: VS fed in (g) | F1: Vsin (mg) | G1: Vsout (mg) | H1: Vsout (mg/L) | I1: Vleft in rxtor (mg) | J1: Volatile solids in reactor,mg | K1: end of dayVs | L1: ∆VS | M1: sum VS, mg | N1: CH4 | O1: Ch4, L | P1: sum CH4, ml | Q1: ml/gVs | R1: ft3/lb
A2: 38645 | B2: R2 | C2: 0.9 | D2: =C2*0.7 -> 0.63 | E2: =F2/0.2 -> 3150 | F2: =D2*1000 -> 630
A3: 38647 | B3: R2 | C3: 0.9 | D3: =C3*0.7 -> 0.63 | E3: =F3/0.2 -> 3150 | F3: =D3*1000 -> 630 | G3: =H3*0.2 -> 1431.9809 | H3: =VS!I23 -> 7159.9045 | I3: =H3*1.8 -> 12887.828 | J3: =I3+F3 -> 13517.828 | K3: =H3*2 -> 14319.809 | M3: =L3 -> 0 | N3: =gas!H32 -> 61.294471 | O3: =N3/1000 -> 0.061294471 | P3: 0
A4: 38649 | B4: R2 | C4: 0.9 | D4: =C4*0.7 -> 0.63 | E4: =F4/0.2 -> 3150 | F4: =D4*1000 -> 630 | G4: =H4*0.2 -> 1472.1346 | H4: =VS!I25 -> 7360.673 | I4: =H4*1.8 -> 13249.211 | J4: =I4+F4 -> 13879.211 | K4: =H4*2 -> 14721.346 | L4: =J3-K4 -> -1203.5178 | M4: =M3+L4 -> -1203.5178 | N4: =gas!H36 -> 108.18596 | O4: =N4/1000 -> 0.10818596 | P4: =N4 -> 108.18596 | Q4: =P4/(M4/1000) -> -89.89145 | R4: =Q4/62.4 -> -1.4405681
A5: 38651 | B5: R2 | C5: 0.9 | D5: =C5*0.7 -> 0.63 | E5: =F5/0.2 -> 3150 | F5: =D5*1000 -> 630 | G5: =H5*0.2 -> 1253.012 | H5: =VS!I28 -> 6265.0602 | I5: =H5*1.8 -> 11277.108 | J5: =I5+F5 -> 11907.108 | K5: =H5*2 -> 12530.12 | L5: =J4-K5 -> 1349.0909 | M5: =M4+L5 -> 145.57309 | N5: =gas!H39 -> 77.001442 | O5: =N5/1000 -> 0.077001442 | P5: =P4+N5 -> 185.1874 | Q5: =P5/(M5/1000) -> 1272.1266 | R5: =Q5/62.4 -> 20.386645
A6: 38657 | B6: R2 | C6: 0.9 | D6: =C6*0.7 -> 0.63 | E6: =F6/0.2 -> 3150 | F6: =D6*1000 -> 630 | G6: =H6*0.2 -> 946.74556 | H6: =VS!I37 -> 4733.7278 | I6: =H6*1.8 -> 8520.7101 | J6: =I6+F6 -> 9150.7101 | K6: =H6*2 -> 9467.4556 | L6: =J5-K6 -> 2439.6528 | M6: =M5+L6 -> 2585.2259 | N6: =gas!H51 -> 549.38474 | O6: =N6/1000 -> 0.54938474 | P6: =P5+N6 -> 734.57214 | Q6: =P6/(M6/1000) -> 284.14234 | R6: =Q6/62.4 -> 4.5535632
A7: 38659 | B7: R2 | C7: 0.9 | D7: =C7*0.7 -> 0.63 | E7: =F7/0.2 -> 3150 | F7: =D7*1000 -> 630 | G7: =H7*0.2 -> 612.55743 | H7: =VS!I40 -> 3062.7871 | I7: =H7*1.8 -> 5513.0168 | J7: =I7+F7 -> 6143.0168 | K7: =H7*2 -> 6125.5743 | L7: =J6-K7 -> 3025.1358 | M7: =M6+L7 -> 5610.3617 | N7: =gas!H54 -> 527.63421 | O7: =N7/1000 -> 0.52763421 | P7: =P6+N7 -> 1262.2063 | Q7: =P7/(M7/1000) -> 224.97771 | R7: =Q7/62.4 -> 3.6054121
A8: 38661 | B8: R2 | C8: 0.9 | D8: =C8*0.7 -> 0.63 | E8: =F8/0.2 -> 3150 | F8: =D8*1000 -> 630 | G8: =H8*0.2 -> 997.50623 | H8: =VS!I43 -> 4987.5312 | I8: =H8*1.8 -> 8977.5561 | J8: =I8+F8 -> 9607.5561 | K8: =H8*2 -> 9975.0623 | L8: =J7-K8 -> -3832.0455 | M8: =M7+L8 -> 1778.3162 | N8: =gas!H55 -> 175.57431 | O8: =N8/1000 -> 0.17557431 | P8: =P7+N8 -> 1437.7807 | Q8: =P8/(M8/1000) -> 808.50676 | R8: =Q8/62.4 -> 12.956839
A9: 38668 | B9: R2 | C9: 0.9 | D9: =C9*0.7 -> 0.63 | E9: =F9/0.2 -> 3150 | F9: =D9*1000 -> 630 | G9: =H9*0.2 -> 1379.3103 | H9: =VS!I49 -> 6896.5517 | I9: =H9*1.8 -> 12413.793 | J9: =I9+F9 -> 13043.793 | K9: =H9*2 -> 13793.103 | L9: =J8-K9 -> -4185.5473 | M9: =M8+L9 -> -2407.2312 | N9: =gas!H66 -> 217.87721 | O9: =N9/1000 -> 0.21787721 | P9: =P8+N9 -> 1655.6579 | Q9: =P9/(M9/1000) -> -687.78516 | R9: =Q9/62.4 -> -11.022198
A10: 38671 | B10: R2 | C10: 0.9 | D10: =C10*0.7 -> 0.63 | E10: =F10/0.2 -> 3150 | F10: =D10*1000 -> 630 | G10: =H10*0.2 -> 995.02488 | H10: =VS!I52 -> 4975.1244 | I10: =H10*1.8 -> 8955.2239 | J10: =I10+F10 -> 9585.2239 | K10: =H10*2 -> 9950.2488 | L10: =J9-K10 -> 3093.5443 | M10: =M9+L10 -> 686.31319 | N10: =gas!H69 -> 179.06904 | O10: =N10/1000 -> 0.17906904 | P10: =P9+N10 -> 1834.7269 | Q10: =P10/(M10/1000) -> 2673.3085 | R10: =Q10/62.4 -> 42.841482
A11: 38673 | B11: R2 | C11: 0.9 | D11: =C11*0.7 -> 0.63 | E11: =F11/0.2 -> 3150 | F11: =D11*1000 -> 630 | G11: =H11*0.2 -> 860.83214 | H11: =VS!I55 -> 4304.1607 | I11: =H11*1.8 -> 7747.4892 | J11: =I11+F11 -> 8377.4892 | K11: =H11*2 -> 8608.3214 | L11: =J10-K11 -> 976.9025 | M11: =M10+L11 -> 1663.2157 | N11: =gas!H72 -> 57.55909 | O11: =N11/1000 -> 0.05755909 | P11: =P10+N11 -> 1892.286 | Q11: =P11/(M11/1000) -> 1137.7274 | R11: =Q11/62.4 -> 18.23281
A12: 38675 | B12: R2 | C12: 0.9 | D12: =C12*0.7 -> 0.63 | E12: =F12/0.2 -> 3150 | F12: =D12*1000 -> 630 | G12: =H12*0.2 -> 1032.2581 | H12: =VS!I58 -> 5161.2903 | I12: =H12*1.8 -> 9290.3226 | J12: =I12+F12 -> 9920.3226 | K12: =H12*2 -> 10322.581 | L12: =J11-K12 -> -1945.0914 | M12: =M11+L12 -> -281.87571 | N12: =gas!H75 -> 52.316344 | O12: =N12/1000 -> 0.052316344 | P12: =P11+N12 -> 1944.6023 | Q12: =P12/(M12/1000) -> -6898.7936 | R12: =Q12/62.4 -> -110.55759
A13: 38687 | B13: R2 | C13: 0.9 | D13: =C13*0.7 -> 0.63 | E13: =F13/0.2 -> 3150 | F13: =D13*1000 -> 630 | G13: =H13*0.2 -> 883.9779 | H13: =VS!I61 -> 4419.8895 | I13: =H13*1.8 -> 7955.8011 | J13: =I13+F13 -> 8585.8011 | K13: =H13*2 -> 8839.779 | L13: =J12-K13 -> 1080.5436 | M13: =M12+L13 -> 798.66787 | N13: =gas!H87 -> 187.25834 | O13: =N13/1000 -> 0.18725834 | P13: =P12+N13 -> 2131.8607 | Q13: =P13/(M13/1000) -> 2669.2706 | R13: =Q13/62.4 -> 42.776773
A14: 38689 | B14: R2 | C14: 0.9 | D14: =C14*0.7 -> 0.63 | E14: =F14/0.2 -> 3150 | F14: =D14*1000 -> 630 | G14: =H14*0.2 -> 1041.6667 | H14: =VS!I64 -> 5208.3333 | I14: =H14*1.8 -> 9375 | J14: =I14+F14 -> 10005 | K14: =H14*2 -> 10416.667 | L14: =J13-K14 -> -1830.8656 | M14: =M13+L14 -> -1032.1977 | N14: =gas!H90 -> 133.82765 | O14: =N14/1000 -> 0.13382765 | P14: =P13+N14 -> 2265.6883 | Q14: =P14/(M14/1000) -> -2195.0139 | R14: =Q14/62.4 -> -35.176505
A15: 38692 | B15: R2 | C15: 1.9 | D15: =C15*0.7 -> 1.33 | E15: =F15/0.2 -> 6650 | F15: =D15*1000 -> 1330 | G15: =H15*0.2 -> 914.63415 | H15: =VS!I67 -> 4573.1707 | I15: =H15*1.8 -> 8231.7073 | J15: =I15+F15 -> 9561.7073 | K15: =H15*2 -> 9146.3415 | L15: =J14-K15 -> 858.65854 | M15: =M14+L15 -> -173.53916 | N15: =gas!H93 -> 89.740999 | O15: =N15/1000 -> 0.089740999 | P15: =P14+N15 -> 2355.4293 | Q15: =P15/(M15/1000) -> -13572.898 | R15: =Q15/62.4 -> -217.51439
A16: 38696 | B16: R2 | C16: 0.9 | D16: =C16*0.7 -> 0.63 | E16: =F16/0.2 -> 3150 | F16: =D16*1000 -> 630 | G16: =H16*0.2 -> 1117.3184 | H16: =VS!I70 -> 5586.5922 | I16: =H16*1.8 -> 10055.866 | J16: =I16+F16 -> 10685.866 | K16: =H16*2 -> 11173.184 | L16: =J15-K16 -> -1611.477 | M16: =M15+L16 -> -1785.0162 | N16: =gas!H96 -> 136.75228 | O16: =N16/1000 -> 0.13675228 | P16: =P15+N16 -> 2492.1816 | Q16: =P16/(M16/1000) -> -1396.1675 | R16: =Q16/62.4 -> -22.374479
A17: 38699 | B17: R2 | C17: 0.9 | D17: =C17*0.7 -> 0.63 | E17: =F17/0.2 -> 3150 | F17: =D17*1000 -> 630 | G17: =H17*0.2 -> 813.00813 | H17: =VS!I73 -> 4065.0407 | I17: =H17*1.8 -> 7317.0732 | J17: =I17+F17 -> 7947.0732 | K17: =H17*2 -> 8130.0813 | L17: =J16-K17 -> 2555.7846 | M17: =M16+L17 -> 770.76842 | N17: =gas!H99 -> 90.185477 | O17: =N17/1000 -> 0.090185477 | P17: =P16+N17 -> 2582.3671 | Q17: =P17/(M17/1000) -> 3350.38 | R17: =Q17/62.4 -> 53.691987
A18: 38701 | B18: R2 | C18: 0.9 | D18: =C18*0.7 -> 0.63 | E18: =F18/0.2 -> 3150 | F18: =D18*1000 -> 630 | G18: =H18*0.2 -> 598.8024 | H18: =VS!I79 -> 2994.012 | I18: =H18*1.8 -> 5389.2216 | J18: =I18+F18 -> 6019.2216 | K18: =H18*2 -> 5988.024 | L18: =J17-K18 -> 1959.0492 | M18: =M17+L18 -> 2729.8176 | N18: =gas!G105 -> 75.975435 | O18: =N18/1000 -> 0.075975435 | P18: =P17+N18 -> 2658.3425 | Q18: =P18/(M18/1000) -> 973.81689 | R18: =Q18/62.4 -> 15.60604
A19: 38720 | B19: R2 | C19: 3.6 | D19: =C19*0.7 -> 2.52 | E19: =F19/0.2 -> 12600 | F19: =D19*1000 -> 2520 | G19: =H19*0.2 -> 840.33613 | H19: =VS!I82 -> 4201.6807 | I19: =H19*1.8 -> 7563.0252 | J19: =I19+F19 -> 10083.025 | K19: =H19*2 -> 8403.3613 | L19: =J18-K19 -> -2384.1398 | M19: =M18+L19 -> 345.67785 | N19: =gas!H114 -> 88.284424 | O19: =N19/1000 -> 0.088284424 | P19: =P18+N19 -> 2746.6269 | Q19: =P19/(M19/1000) -> 7945.626 | R19: =Q19/62.4 -> 127.33375
A20: 38722 | B20: R2 | C20: 0.9 | D20: =C20*0.7 -> 0.63 | E20: =F20/0.2 -> 3150 | F20: =D20*1000 -> 630 | G20: =H20*0.2 -> 1092.8962 | H20: =VS!I85 -> 5464.4809 | I20: =H20*1.8 -> 9836.0656 | J20: =I20+F20 -> 10466.066 | K20: =H20*2 -> 10928.962 | L20: =J19-K20 -> -845.93654 | M20: =M19+L20 -> -500.25869 | N20: =gas!H117 -> 109.62388 | O20: =N20/1000 -> 0.10962388 | P20: =P19+N20 -> 2856.2508 | Q20: =P20/(M20/1000) -> -5709.5477 | R20: =Q20/62.4 -> -91.499161
A21: 38724 | B21: R2 | C21: 0.9 | D21: =C21*0.7 -> 0.63 | E21: =F21/0.2 -> 3150 | F21: =D21*1000 -> 630 | G21: =H21*0.2 -> 469.48357 | H21: =VS!I89 -> 2347.4178 | I21: =H21*1.8 -> 4225.3521 | J21: =I21+F21 -> 4855.3521 | K21: =H21*2 -> 4694.8357 | L21: =J20-K21 -> 5771.2299 | M21: =M20+L21 -> 5270.9712 | N21: =gas!H120 -> 88.223418 | O21: =N21/1000 -> 0.088223418 | P21: =P20+N21 -> 2944.4742 | Q21: =P21/(M21/1000) -> 558.62081 | R21: =Q21/62.4 -> 8.9522566
A22: 38727 | B22: R2 | C22: 0.9 | D22: =C22*0.7 -> 0.63 | E22: =F22/0.2 -> 3150 | F22: =D22*1000 -> 630 | G22: =H22*0.2 -> 478.4689 | H22: =VS!I93 -> 2392.3445 | I22: =H22*1.8 -> 4306.2201 | J22: =I22+F22 -> 4936.2201 | K22: =H22*2 -> 4784.689 | L22: =J21-K22 -> 70.663117 | M22: =M21+L22 -> 5341.6343 | N22: =gas!H123 -> 130.27613 | O22: =N22/1000 -> 0.13027613 | P22: =P21+N22 -> 3074.7504 | Q22: =P22/(M22/1000) -> 575.61978 | R22: =Q22/62.4 -> 9.2246759
A23: 38729 | B23: R2 | C23: 0.9 | D23: =C23*0.7 -> 0.63 | E23: =F23/0.2 -> 3150 | F23: =D23*1000 -> 630 | G23: =H23*0.2 -> 911.16173 | H23: =VS!I96 -> 4555.8087 | I23: =H23*1.8 -> 8200.4556 | J23: =I23+F23 -> 8830.4556 | K23: =H23*2 -> 9111.6173 | L23: =J22-K23 -> -4175.3972 | M23: =M22+L23 -> 1166.2371 | N23: =gas!H126 -> 66.522619 | O23: =N23/1000 -> 0.066522619 | P23: =P22+N23 -> 3141.273 | Q23: =P23/(M23/1000) -> 2693.5114 | R23: =Q23/62.4 -> 43.165247
A24: 38731 | B24: R2 | C24: 0.9 | D24: =C24*0.7 -> 0.63 | E24: =F24/0.2 -> 3150 | F24: =D24*1000 -> 630 | G24: =H24*0.2 -> 1071.4286 | H24: =VS!I99 -> 5357.1429 | I24: =H24*1.8 -> 9642.8571 | J24: =I24+F24 -> 10272.857 | K24: =H24*2 -> 10714.286 | L24: =J23-K24 -> -1883.8301 | M24: =M23+L24 -> -717.59302 | N24: =gas!H129 -> 81.060622 | O24: =N24/1000 -> 0.081060622 | P24: =P23+N24 -> 3222.3336 | Q24: =P24/(M24/1000) -> -4490.4751 | R24: =Q24/62.4 -> -71.962742
A25: 38734 | B25: R2 | C25: 0.9 | D25: =C25*0.7 -> 0.63 | E25: =F25/0.2 -> 3150 | F25: =D25*1000 -> 630 | G25: =H25*0.2 -> 388.34951 | H25: =VS!I102 -> 1941.7476 | I25: =H25*1.8 -> 3495.1456 | J25: =I25+F25 -> 4125.1456 | K25: =H25*2 -> 3883.4951 | L25: =J24-K25 -> 6389.362 | M25: =M24+L25 -> 5671.769 | N25: =gas!H132 -> 90.561976 | O25: =N25/1000 -> 0.090561976 | P25: =P24+N25 -> 3312.8956 | Q25: =P25/(M25/1000) -> 584.1027 | R25: =Q25/62.4 -> 9.3606202
A26: 38736 | B26: R2 | C26: 0.9 | D26: =C26*0.7 -> 0.63 | E26: =F26/0.2 -> 3150 | F26: =D26*1000 -> 630 | G26: =H26*0.2 -> 638.97764 | H26: =VS!I105 -> 3194.8882 | I26: =H26*1.8 -> 5750.7987 | J26: =I26+F26 -> 6380.7987 | K26: =H26*2 -> 6389.7764 | L26: =J25-K26 -> -2264.6307 | M26: =M25+L26 -> 3407.1382 | N26: =gas!H135 -> 100.69213 | O26: =N26/1000 -> 0.10069213 | P26: =P25+N26 -> 3413.5877 | Q26: =P26/(M26/1000) -> 1001.8929 | R26: =Q26/62.4 -> 16.055976
A27: 38738 | B27: R2 | C27: 0.9 | D27: =C27*0.7 -> 0.63 | E27: =F27/0.2 -> 3150 | F27: =D27*1000 -> 630 | G27: =H27*0.2 -> 608.51927 | H27: =VS!I108 -> 3042.5963 | I27: =H27*1.8 -> 5476.6734 | J27: =I27+F27 -> 6106.6734 | K27: =H27*2 -> 6085.1927 | L27: =J26-K27 -> 295.60602 | M27: =M26+L27 -> 3702.7443 | N27: =gas!H138 -> 92.953121 | O27: =N27/1000 -> 0.092953121 | P27: =P26+N27 -> 3506.5408 | Q27: =P27/(M27/1000) -> 947.01135 | R27: =Q27/62.4 -> 15.176464
A28: 38741 | B28: R2 | C28: 0.9 | D28: =C28*0.7 -> 0.63 | E28: =F28/0.2 -> 3150 | F28: =D28*1000 -> 630 | G28: =H28*0.2 -> 442.96788 | H28: =VS!I111 -> 2214.8394 | I28: =H28*1.8 -> 3986.711 | J28: =I28+F28 -> 4616.711 | K28: =H28*2 -> 4429.6788 | L28: =J27-K28 -> 1676.9946 | M28: =M27+L28 -> 5379.7388 | N28: =gas!H141 -> 91.908505 | O28: =N28/1000 -> 0.091908505 | P28: =P27+N28 -> 3598.4493 | Q28: =P28/(M28/1000) -> 668.88922 | R28: =Q28/62.4 -> 10.719379
A29: 38743 | B29: R2 | C29: 0.9 | D29: =C29*0.7 -> 0.63 | E29: =F29/0.2 -> 3150 | F29: =D29*1000 -> 630 | G29: =H29*0.2 -> 468.38407 | H29: =VS!I114 -> 2341.9204 | I29: =H29*1.8 -> 4215.4567 | J29: =I29+F29 -> 4845.4567 | K29: =H29*2 -> 4683.8407 | L29: =J28-K29 -> -67.129786 | M29: =M28+L29 -> 5312.6091 | N29: =gas!H144 -> 92.83934 | O29: =N29/1000 -> 0.09283934 | P29: =P28+N29 -> 3691.2887 | Q29: =P29/(M29/1000) -> 694.81655 | R29: =Q29/62.4 -> 11.134881
A30: 38745 | B30: R2 | C30: 0.9 | D30: =C30*0.7 -> 0.63 | E30: =F30/0.2 -> 3150 | F30: =D30*1000 -> 630 | G30: =H30*0.2 -> 645.85576 | H30: =VS!I117 -> 3229.2788 | I30: =H30*1.8 -> 5812.7018 | J30: =I30+F30 -> 6442.7018 | K30: =H30*2 -> 6458.5576 | L30: =J29-K30 -> -1613.1009 | M30: =M29+L30 -> 3699.5081 | N30: =gas!H147 -> 95.019263 | O30: =N30/1000 -> 0.095019263 | P30: =P29+N30 -> 3786.3079 | Q30: =P30/(M30/1000) -> 1023.4625 | R30: =Q30/62.4 -> 16.401643
A31: 38748 | B31: R2 | C31: 0.9 | D31: =C31*0.7 -> 0.63 | E31: =F31/0.2 -> 3150 | F31: =D31*1000 -> 630 | G31: =H31*0.2 -> 578.34715 | H31: 2891.7358 | I31: =H31*1.8 -> 5205.1244 | J31: =I31+F31 -> 5835.1244 | K31: =H31*2 -> 5783.4715 | L31: =J30-K31 -> 659.23031 | M31: =M30+L31 -> 4358.7385 | N31: =gas!H149 -> 90.496563 | O31: =N31/1000 -> 0.090496563 | P31: =P30+N31 -> 3876.8045 | Q31: =P31/(M31/1000) -> 889.4327 | R31: =Q31/62.4 -> 14.253729
A32: 38750 | B32: R2 | C32: 0.9 | D32: =C32*0.7 -> 0.63 | E32: =F32/0.2 -> 3150 | F32: =D32*1000 -> 630 | G32: =H32*0.2 -> 522.92959 | H32: 2614.6479 | I32: =H32*1.8 -> 4706.3663 | J32: =I32+F32 -> 5336.3663 | K32: =H32*2 -> 5229.2959 | L32: =J31-K32 -> 605.82851 | M32: =M31+L32 -> 4964.567 | N32: =gas!H151 -> 89.305762 | O32: =N32/1000 -> 0.089305762 | P32: =P31+N32 -> 3966.1103 | Q32: =P32/(M32/1000) -> 798.88343 | R32: =Q32/62.4 -> 12.802619
A33: 38752 | B33: R2 | C33: 0.9 | D33: =C33*0.7 -> 0.63 | E33: =F33/0.2 -> 3150 | F33: =D33*1000 -> 630 | G33: =H33*0.2 -> 546.90184 | H33: 2734.5092 | I33: =H33*1.8 -> 4922.1165 | J33: =I33+F33 -> 5552.1165 | K33: =H33*2 -> 5469.0184 | L33: =J32-K33 -> -132.6521 | M33: =M32+L33 -> 4831.9149 | N33: =gas!H153 -> 116.71735 | O33: =N33/1000 -> 0.11671735 | P33: =P32+N33 -> 4082.8276 | Q33: =P33/(M33/1000) -> 844.97093 | R33: =Q33/62.4 -> 13.541201
A34: 38755 | B34: R2 | C34: 0.9 | D34: =C34*0.7 -> 0.63 | E34: =F34/0.2 -> 3150 | F34: =D34*1000 -> 630 | G34: =H34*0.2 -> 505.41273 | H34: 2527.0637 | I34: =H34*1.8 -> 4548.7146 | J34: =I34+F34 -> 5178.7146 | K34: =H34*2 -> 5054.1273 | L34: =J33-K34 -> 497.98921 | M34: =M33+L34 -> 5329.9041 | N34: =gas!H155 -> 129.4931 | O34: =N34/1000 -> 0.1294931 | P34: =P33+N34 -> 4212.3207 | Q34: =P34/(M34/1000) -> 790.3183 | R34: =Q34/62.4 -> 12.665357
A35: 38757 | B35: R2 | C35: 0.9 | D35: =C35*0.7 -> 0.63 | E35: =F35/0.2 -> 3150 | F35: =D35*1000 -> 630 | G35: =H35*0.2 -> 285.25018 | H35: 1426.2509 | I35: =H35*1.8 -> 2567.2516 | J35: =I35+F35 -> 3197.2516 | K35: =H35*2 -> 2852.5018 | L35: =J34-K35 -> 2326.2128 | M35: =M34+L35 -> 7656.1169 | N35: =gas!H157 -> 150.28387 | O35: =N35/1000 -> 0.15028387 | P35: =P34+N35 -> 4362.6046 | Q35: =P35/(M35/1000) -> 569.81949 | R35: =Q35/62.4 -> 9.1317225
A36: 38759 | B36: R2 | C36: 0.9 | D36: =C36*0.7 -> 0.63 | E36: =F36/0.2 -> 3150 | F36: =D36*1000 -> 630 | G36: =H36*0.2 -> 552.79518 | H36: 2763.9759 | I36: =H36*1.8 -> 4975.1566 | J36: =I36+F36 -> 5605.1566 | K36: =H36*2 -> 5527.9518 | L36: =J35-K36 -> -2330.7001 | M36: =M35+L36 -> 5325.4167 | N36: =gas!H159 -> 72.193934 | O36: =N36/1000 -> 0.072193934 | P36: =P35+N36 -> 4434.7985 | Q36: =P36/(M36/1000) -> 832.76084 | R36: =Q36/62.4 -> 13.345526
A37: 38762 | B37: R2 | C37: 0.9 | D37: =C37*0.7 -> 0.63 | E37: =F37/0.2 -> 3150 | F37: =D37*1000 -> 630 | G37: =H37*0.2 -> 198.60973 | H37: =VS!I131 -> 993.04866 | I37: =H37*1.8 -> 1787.4876 | J37: =I37+F37 -> 2417.4876 | K37: =H37*2 -> 1986.0973 | L37: =J36-K37 -> 3619.0593 | M37: =M36+L37 -> 8944.476 | N37: =gas!H161 -> 125.33534 | O37: =N37/1000 -> 0.12533534 | P37: =P36+N37 -> 4560.1339 | Q37: =P37/(M37/1000) -> 509.82683 | R37: =Q37/62.4 -> 8.1703018
A38: 38764 | B38: R2 | C38: 1 | D38: =C38*0.7 -> 0.7 | E38: =F38/0.2 -> 3500 | F38: =D38*1000 -> 700 | G38: =H38*0.2 -> 392.92731 | H38: =VS!I133 -> 1964.6365 | I38: =H38*1.8 -> 3536.3458 | J38: =I38+F38 -> 4236.3458 | K38: =H38*2 -> 3929.2731 | L38: =J37-K38 -> -1511.7855 | M38: =M37+L38 -> 7432.6905 | N38: =gas!H163 -> 80.295424 | O38: =N38/1000 -> 0.080295424 | P38: =P37+N38 -> 4640.4293 | Q38: =P38/(M38/1000) -> 624.32699 | R38: =Q38/62.4 -> 10.00524
A39: 38766 | B39: R2 | C39: 1 | D39: =C39*0.7 -> 0.7 | E39: =F39/0.2 -> 3500 | F39: =D39*1000 -> 700 | G39: =H39*0.2 -> 419.72718 | H39: =VS!I135 -> 2098.6359 | I39: =H39*1.8 -> 3777.5446 | J39: =I39+F39 -> 4477.5446 | K39: =H39*2 -> 4197.2718 | L39: =J38-K39 -> 39.074003 | M39: =M38+L39 -> 7471.7645 | N39: =gas!H165 -> 77.988365 | O39: =N39/1000 -> 0.077988365 | P39: =P38+N39 -> 4718.4176 | Q39: =P39/(M39/1000) -> 631.49978 | R39: =Q39/62.4 -> 10.120189
A40: 38771 | B40: R2 | C40: 1 | D40: =C40*0.7 -> 0.7 | E40: =F40/0.2 -> 3500 | F40: =D40*1000 -> 700 | G40: =H40*0.2 -> 424.17815 | H40: =VS!I137 -> 2120.8908 | I40: =H40*1.8 -> 3817.6034 | J40: =I40+F40 -> 4517.6034 | K40: =H40*2 -> 4241.7815 | L40: =J39-K40 -> 235.76305 | M40: =M39+L40 -> 7707.5275 | N40: =gas!H167 -> 148.39384 | O40: =N40/1000 -> 0.14839384 | P40: =P39+N40 -> 4866.8115 | Q40: =P40/(M40/1000) -> 631.43615 | R40: =Q40/62.4 -> 10.119169
...

Sheet Moisture
A1: moisture content
B2: wet wt + dish | C2: dry wt +dish | D2: dish | F2: dry wt | G2: wet wt | H2: solids | I2: % solids | J2: %moisture
A3: batch 1 | B3: =49.9+25 -> 74.9 | C3: 51 | D3: 49.9 | F3: =C3-D3 -> 1.1 | G3: =B3-D3 -> 25 | H3: =F3/G3 -> 0.044 | I3: =H3 -> 0.044 | J3: =1-I3 -> 0.956
A4: batch 1 | B4: =50.1+25 -> 75.1 | C4: 51.2 | D4: 50.1 | F4: =C4-D4 -> 1.1 | G4: =B4-D4 -> 25 | H4: =F4/G4 -> 0.044 | I4: =H4 -> 0.044 | J4: =1-I4 -> 0.956
A5: batch 2 | B5: =24+49.9 -> 73.9 | C5: 51.1 | D5: 49.9 | F5: =C5-D5 -> 1.2 | G5: =B5-D5 -> 24 | H5: =F5/G5 -> 0.05 | I5: =H5 -> 0.05 | J5: =1-I5 -> 0.95
A6: batch 2 | B6: =24+49.9 -> 73.9 | C6: 51.1 | D6: 49.9 | F6: =C6-D6 -> 1.2 | G6: =B6-D6 -> 24 | H6: =F6/G6 -> 0.05 | I6: =H6 -> 0.05 | J6: =1-I6 -> 0.95
A7: batch 3 | B7: =23+49.9 -> 72.9 | C7: 51.2 | D7: 49.9 | F7: =C7-D7 -> 1.3 | G7: =B7-D7 -> 23 | H7: =F7/G7 -> 0.056521739 | I7: =H7 -> 0.056521739 | J7: =1-I7 -> 0.94347826 | K7: =AVERAGE(J3:J18) -> 0.94898301
A8: batch 4 | B8: 73.9 | C8: 48.8 | D8: 47.7 | F8: =C8-D8 -> 1.1 | G8: =B8-D8 -> 26.2 | H8: =F8/G8 -> 0.041984733 | I8: =H8 -> 0.041984733 | J8: =1-I8 -> 0.95801527
A9: batch 5 | B9: =47.7+23 -> 70.7 | C9: 49.1 | D9: 47.7 | F9: =C9-D9 -> 1.4 | G9: =B9-D9 -> 23 | H9: =F9/G9 -> 0.060869565 | I9: =H9 -> 0.060869565 | J9: =1-I9 -> 0.93913043
A10: 40340
A11: batch 6 | B11: =40.01+50.82 -> 90.83 | C11: 52.5619 | D11: 50.82 | F11: =C11-D11 -> 1.7419 | G11: =B11-D11 -> 40.01 | H11: =F11/G11 -> 0.043536616 | I11: =H11 -> 0.043536616 | J11: =1-I11 -> 0.95646338
A15: starch test | F15: 0.6 | G15: 10 | H15: =F15/G15 -> 0.06 | I15: =H15 -> 0.06 | J15: =1-I15 -> 0.94 | L15: mon
B16: 59.4 | C16: 43 | D16: 42 | F16: =C16-D16 -> 1 | G16: =B16-D16 -> 17.4 | H16: =F16/G16 -> 0.057471264 | I16: =H16 -> 0.057471264 | J16: =1-I16 -> 0.94252874 | L16: fri
B17: 73.9 | C17: 48.8 | D17: 47.7 | F17: =C17-D17 -> 1.1 | G17: =B17-D17 -> 26.2 | H17: =F17/G17 -> 0.041984733 | I17: =H17 -> 0.041984733 | J17: =1-I17 -> 0.95801527
B18: =4.8516+1.3 -> 6.1516 | C18: 1.6 | D18: 1.3 | F18: =C18-D18 -> 0.3 | G18: =B18-D18 -> 4.8516 | H18: =F18/G18 -> 0.061835271 | I18: =H18 -> 0.061835271 | J18: =1-I18 -> 0.93816473
A23: Confirmation of moisture content for Starch
A24: DAY 6 results
A25: wet samples
B26: =1.29+0.2 -> 1.49 | C26: 1.31 | D26: 1.29 | F26: =C26-D26 -> 0.02 | G26: =B26-D26 -> 0.2 | H26: =F26/G26 -> 0.1 | I26: =H26 -> 0.1 | J26: =1-I26 -> 0.9
B27: =1.29+0.2 -> 1.49 | C27: 1.32 | D27: 1.29 | F27: =C27-D27 -> 0.03 | G27: =B27-D27 -> 0.2 | H27: =F27/G27 -> 0.15 | I27: =H27 -> 0.15 | J27: =1-I27 -> 0.85 | K27: =AVERAGE(J26:J28) -> 0.85
B28: =1.29+0.2 -> 1.49 | C28: 1.33 | D28: 1.29 | F28: =C28-D28 -> 0.04 | G28: =B28-D28 -> 0.2 | H28: =F28/G28 -> 0.2 | I28: =H28 -> 0.2 | J28: =1-I28 -> 0.8
A29: dry samples
B30: =1.29+0.2 -> 1.49 | C30: 1.48 | D30: 1.29 | F30: =C30-D30 -> 0.19 | G30: =B30-D30 -> 0.2 | H30: =F30/G30 -> 0.95 | I30: =H30 -> 0.95 | J30: =1-I30 -> 0.05
B31: =1.29+0.2 -> 1.49 | C31: 1.48 | D31: 1.29 | F31: =C31-D31 -> 0.19 | G31: =B31-D31 -> 0.2 | H31: =F31/G31 -> 0.95 | I31: =H31 -> 0.95 | J31: =1-I31 -> 0.05 | K31: =AVERAGE(J30:J32) -> 0.066666667
