Workbook
Name AnnualCostHomeTelework: '[1]DROPDOWN MENU SOURCE'!$H$7:$H$14
Name AnnualCostHomeTelework: '[2]DROPDOWN MENU SOURCE'!$H$7:$H$14
Name AnnualTelecomCost: '[1]DROPDOWN MENU SOURCE'!$G$7:$G$23
Name AnnualTelecomCost: '[2]DROPDOWN MENU SOURCE'!$G$7:$G$23
Name ITCostperWorkstation: '[1]DROPDOWN MENU SOURCE'!$F$7:$F$14
Name ITCostperWorkstation: '[2]DROPDOWN MENU SOURCE'!$F$7:$F$14
Name Value_Menu1: '[1]DROPDOWN MENU SOURCE'!$F$24
Name Value_Menu1: '[2]DROPDOWN MENU SOURCE'!$F$24
Name Value_Menu2: '[1]DROPDOWN MENU SOURCE'!$G$24
Name Value_Menu2: '[2]DROPDOWN MENU SOURCE'!$G$24
Name Value_Menu3: '[1]DROPDOWN MENU SOURCE'!$H$24
Name Value_Menu3: '[2]DROPDOWN MENU SOURCE'!$H$24

Sheet INTRODUCTION
B1: COST PER PERSON MODEL 2.0
B2: INTRODUCTION
B3: I. Introduction
B4: The Cost Per Person Model 2.0 (CPPM) is an Excel-based tool designed to compute and benchmark the cost per person for workspace, information technology (IT), and telecommunications scenarios. The CPPM also calculates potential cost savings resulting from the use of alternative work environments, such as hoteling, or desk sharing.
B6: II. Overview of CPPM Worksheet
B7: The CPPM has tabs on the bottom of each screen which take the user to any of the model's sections:
B8: CPPM | C8: Allows users to input data and generate results.
B9: GRAPHS | C9: Illustrates cost per person results graphically.
B10: CALCULATIONS | C10: Provides explanation of total office workplace cost for organization, as well as cost per person.
B11: SCENARIOS | C11: Calculates potential net savings resulting from the use of alternate work environments.
B12: SCENARIO GRAPHS | C12: Illustrates scenario results graphically.
B13: DEFINITIONS | C13: Defines data inputs for CPPM.
B17: III. Getting Started: Enabling Macros
B18: Depending on your current computer setting, you may see a message regarding macros (Figure1) or a similar message. You will need to enable the spreadsheet macros by changing the macro security setting in the Trust Center (Figure 2). | C18: Figure 1 - Enabling Macros
B19: Click the Microsoft Office Button , then click Excel Options. In the Trust Center category, click Trust Center Settings, and then click the Macro Settings category. Under Macro Setting, Enable All Macros. Close Excel file and reopen Cost Per Person Model. | C19: Figure 2 - Trust Center
B22: IV. Completing the CPPM Worksheets
B23: Input data in only the un-shaded spreadsheet cells. Work through each component and use suggested values where applicable, or refer to the DEFINITIONS tab for more information.
B25: Complete the CPPM worksheet from top to bottom, since some calculations depend on prior inputs. The CPPM displays a Cumulative Cost Per Person at the top of each spreadsheet. This number shows the impact of a single model component on the total cost per person. Click on the CPPM CALCULATIONS tab at any time for details of each calculation in the model.
B27: To save the results under a new file name, click "Save As" on the Excel toolbar. A dialog box will ask you for a new file name. Once you enter the new file name, click "Close" to overwrite the existing file.
B30: V. Contact Us
B31: If you have questions or comments regarding the Cost Per Person Model 2.0, please contact Ray Wynter, GSA's Office of Governmentwide Policy, at 202-501-3802 or ray.wynter@gsa.gov.

Sheet CPPM
H2: Current Cost per Person
H3: =I71
G5: CURRENT COST PER PERSON
B7: People
C9: Number of employees
C11: Number of teleworkers
B14: A. | C14: Real Estate
C16: Total square footage of office space (rentable) | L16: Including shared spaces such as restrooms and hallways, should be available on leasing agreement.
C18: Number of workspaces | L18: Number of shared workspaces available | P18: =IF(I18<>"",IFERROR(I18+I11-I9,0),"")
L19: Hoteling or desk sharing (unassigned workspaces)
D20: Square feet/person | I20: =IFERROR(ROUND(I16/(I9),2),"") | L20: Ratio of teleworkers to shared workspace | P20: =IF($I$11=0,"",IFERROR($I$11/$P$18,""))
C23: Full service lease rate/square foot | L23: Including utilities, trash removal, janitorial services, furniture and fixtures, etc.
D25: Estimated fully serviced workspace cost | I25: =IFERROR(I23*I20,"")
C27: REAL ESTATE SUBTOTAL (A) | I27: =IFERROR(I16*I23,"") -> 0
B30: B. | C30: Telecommunications
C32: Select Telecommunications Service
D33: Digital | F33: IP Phone
C36: Estimated annual Telcom cost per user profile | I36: 497
C38: Number of profiles | I38: =I9 -> 0
C40: TELECOMMUNICATIONS SUBTOTAL (B) | I40: =I36*I38 -> 0
B43: C. | C43: Individual Information Technology (IT) and Mobility Devices
C46: Estimated annual IT cost per user profile | I46: 5000
C48: Individual IT Subtotal | I48: =I9*I46 -> 0
C52: MOBILITY DEVICES | I52: QUANTITY | L52: ANNUAL COST PER UNIT
C53: Second Computer (laptop) | K53: 700 | N53: Suggested range: $400-$500 per year (assumes a 3-year lifecycle) | T53: 0
C55: Smartphone | N55: Suggested range: $600-$700 per year | T55: 0
C57: Other (optional description) | N57: e.g., Tablet Computer (assumes a 1-year lifecycle and a range of $500 - $600 per year) | T57: 0
C60: Mobility Devices Subtotal | I60: =(L53*I53)+(I55*L55)+(I57*L57) -> 0
C63: Individual IT and Mobility Devices Subtotal (C) | I63: =I48+I60 -> 0
B66: TOTALS (A+B+C)
B67: (All costs are annualized)
C69: TOTAL COST FOR ORGANIZATION | I69: =IFERROR(I63+I40+I27,"") -> 0
C71: TOTAL COST PER PERSON | I71: =IFERROR(I69/I9,"")
H88: http://www.gsa.gov/portal/content/103583
G101: =CPPM!I9-CPPM!I18 -> 0 | H101: Unassigned workers

Sheet GRAPHS
E1: CPPM Graphs

Sheet CALCULATIONS
B2: CPPM CALCULATIONS
B3: A. Real Estate
D4: REAL ESTATE SUBTOTAL (A) | F4: = | G4: number of square feet | I4: fully serviced rentable sq. ft.
E5: =G5*I5 -> 0 | F5: = | G5: =CPPM!I16 -> 0 | H5: * | I5: =CPPM!I23 -> 0
B7: B. Telecommunications
B8: TELECOMMUNICATIONS SUBTOTAL (B) | F8: = | G8: number of employees | H8: * | I8: annual telecom cost per workstation
E9: =G9*I9 -> 0 | F9: = | G9: =CPPM!$I$9 -> 0 | H9: * | I9: =CPPM!I36 -> 497
B11: C. Individual Information Technology (IT) and Mobility Devices
B12: WORKSTATION IT
B13: WORKSTATION IT SUBTOTAL | F13: = | G13: number of employees | H13: * | I13: annual IT cost per IT profile
E14: =G14*I14 -> 0 | F14: = | G14: =CPPM!$I$9 -> 0 | H14: * | I14: =CPPM!$I$46 -> 5000
B15: MOBILITY DEVICES
B16: LAPTOP COST | F16: = | G16: number of laptops | H16: * | I16: annual cost per laptop
E17: =G17*I17 -> 0 | F17: = | G17: =CPPM!I53 -> 0 | H17: * | I17: =CPPM!L53 -> 0
B18: CELL PHONE COST | F18: = | G18: number of cell phones | H18: * | I18: annual cost per cell phone
E19: =G19*I19 -> 0 | F19: = | G19: =CPPM!I55 -> 0 | H19: * | I19: =CPPM!L55 -> 0
B20: OTHER ADD. DEVICE COST | F20: = | G20: number of items | H20: * | I20: annual cost of item
E21: =G21*I21 -> 0 | F21: = | G21: =CPPM!I57 -> 0 | H21: * | I21: =CPPM!L57 -> 0
B22: INDIVIDUAL IT AND MOBILITY DEVICES SUBTOTAL (C)
B23: INDIVIDUAL IT AND MOBILITY DEVICES SUBTOTAL | F23: = | G23: =B13 -> WORKSTATION IT SUBTOTAL | H23: + | I23: ADDITIONAL DEVICES SUBTOTAL
E24: =G24+I24 -> 0 | F24: = | G24: =E14 -> 0 | H24: + | I24: =E17+E19+E21 -> 0
B26: TOTALS (A+B+C)
B27: TOTAL COST FOR ORGANIZATION | F27: = | G27: REAL ESTATE SUBTOTAL | H27: + | I27: TELECOM SUBTOTAL | J27: + | K27: WORKSTATION IT SUBTOTAL
E28: =G28+I28+K28 -> 0 | F28: = | G28: =E5 -> 0 | H28: + | I28: =E9 -> 0 | J28: + | K28: =E24 -> 0
B30: TOTAL COST PER PERSON | F30: = | G30: TOTAL COST FOR ORGANIZATION | H30: ¸ | I30: NUMBER OF EMPLOYEES
E31: =G31/I31 -> #DIV/0! | F31: = | G31: =E28 -> 0 | H31: ¸ | I31: =CPPM!I9 -> 0

Sheet SCENARIOS
F1: Scenario Tool
B2: Current Baseline | G2: Adjusted Outcomes | L2: Potential Savings
B4: Number of employees | D4: =CPPM!$I$9 -> 0 | G4: Number of employees | H4: =D4 -> 0 | L4: Change in Cost
L5: =IFERROR($H$53-$D$53,0) -> 0
B6: Total number of teleworkers | D6: =CPPM!$I$11 -> 0 | G6: Total number of teleworkers | H6: 0
L7: Change in Cost Per Person
B8: Real Estate | G8: Real Estate | L8: =IFERROR($H$55-$D$55,0) -> 0
B10: Total square footage of office space | D10: =CPPM!$I$16 -> 0 | G10: Total square footage of office space | H10: 0 | L10: Change in Teleworkers
L11: =IFERROR($H$6-$D$6,0) -> 0
B12: Total number of workspaces | D12: =CPPM!$I$18 -> 0 | G12: Total number of workspaces | H12: 0
L13: Change in Sq. Ft.
B14: Square feet/person | D14: =IFERROR(ROUND($D$10/($D$4),2),"") | G14: Square feet/person | H14: =IFERROR(ROUND(H10/H4,2),0) -> 0 | L14: =IFERROR($H$10-$D$10,0) -> 0
B15: Cost per square foot | D15: =CPPM!$I$23 -> 0 | G15: Cost per square foot | H15: =$D$15 -> 0
B17: Cost per workspace | D17: =IFERROR($D$15*$D$14,"") | G17: Cost per workspace | H17: =IFERROR(ROUND(($H$10/$H$12)*$H$15,2),"")
B19: Real Estate Subtotal | D19: =IFERROR($D$10*$D$15,"") -> 0 | G19: Real Estate Subtotal | H19: =$H$10*$H$15 -> 0
B21: Teleworkers | G21: Teleworkers
B23: Ratio of teleworkers to shared workspace | D23: =IFERROR($D$6/$D$24,"") | G23: Ratio of teleworkers to shared workspace | H23: =IFERROR(ROUND(H6/H24,3),0) -> 0
B24: Shared Workspaces | D24: =CPPM!$P$18 | G24: Shared Workspaces | H24: =IFERROR(H12+H6-H4,0) -> 0
B25: Shared Square Feet | D25: =IFERROR(CPPM!$P$18*CPPM!$I$20,"") | G25: Shared Square Feet | H25: =H14*H24 -> 0
B26: Shared Space Costs | D26: =CPPM!$P$21 -> 0 | G26: Shared Space Costs | H26: =IFERROR($H$25*$H$15,0) -> 0
B28: Telecommunications | G28: Telecommunications
B30: Estimated annual cost per profile | D30: =CPPM!$I$36 -> 497 | G30: Estimated annual cost per profile | H30: =$D$30 -> 497
B32: Number of profiles | D32: =CPPM!$I$38 -> 0 | G32: Number of profiles | H32: =$D$32 -> 0
B34: Telecom Subtotal | D34: =$D$30*$D$32 -> 0 | G34: Telecom Subtotal | H34: =$D$34 -> 0
B36: Individual Information Technology (IT) | G36: Individual Information Technology (IT)
B39: Estimated annual IT cost per profile | D39: 5000 | G39: Estimated annual IT cost per profile | H39: =$D$39 -> 5000
B41: Individual IT Subtotal | D41: =$D$32*$D$39 -> 0 | G41: Individual IT Subtotal | H41: =$D$41 -> 0
B43: Mobility Devices | G43: Mobility Devices
B44: Laptop | D44: =IFERROR(CPPM!$I$53*CPPM!$L$53,0) -> 0 | G44: Laptop | H44: =$D$44 -> 0
B45: Smartphone | D45: =IFERROR(CPPM!$I$55*CPPM!$L$55,0) -> 0 | G45: Smartphone | H45: =$D$45 -> 0
B46: Other | D46: =IFERROR(CPPM!$I$57*CPPM!$L$57,0) -> 0 | G46: Other | H46: =$D$46 -> 0
B48: Mobility Devices Subtotal | D48: =($D$44)+($D$45)+($D$46) -> 0 | G48: Mobility Devices Subtotal | H48: =$D$48 -> 0 | N48: 0
B49: Individual IT/Devices Subtotal | D49: =CPPM!$I$63 -> 0 | G49: Individual IT/Devices Subtotal | H49: =$D$49 -> 0
B51: Total Costs | G51: Total Costs
B53: Total Cost | D53: =CPPM!I69 -> 0 | G53: Total Cost | H53: =$H$49+$H$34+$H$19 -> 0
B55: Total Cost Per Person | D55: =CPPM!I71 | G55: Total Cost Per Person | H55: =IFERROR($H$53/$H$4,"")

Sheet SCENARIO GRAPHS
E1: Scenario Graphs

Sheet DATA
A1: DIGITAL/ANALOG | B1: TELECOM | C1: IT | E1: ENHANCEMENTS | F1: Checked? | G1: SUGGESTED RANGES | H1: ALTERNATIVE WORK
A2: 1 | B2: 2 | C2: 1 | E2: 0 | G2: Suggested range: $600-$850 per year* | H2: #REF! | I2: 2
A3: Picklist Results: Do not Edit | C3: =IF(C2=2, 1.3, 1) -> 1 | E3: 0 | G3: Suggested range: $600-$800 per year
C4: =IF(C2=0,0,1) -> 1 | E4: 0 | G4: Examples: Blackberry, home internet access*
A6: User Estimated Fully serviced rental rate | B6: 31.5
A7: User Estimated Daily telework center cost | B7: 0
E9: =117*6445 -> 754065
E10: =833*6445 -> 5368685
A11: CPP GRAPHS | B11: TOTALS | C11: PER PERSON | E11: =950*6445 -> 6122750
A12: Real Estate | B12: =CPPM!I27 -> 0 | C12: =IF(CPPM!$I$9>0,B12/CPPM!$I$9,0) -> 0 | F12: =12*34*2*52 -> 42432
A13: Telecom | B13: =CPPM!I40 -> 0 | C13: =IF(CPPM!$I$9>0,B13/CPPM!$I$9,0) -> 0
A14: Individual IT | B14: =CPPM!I48 -> 0 | C14: =IF(CPPM!$I$9>0,B14/CPPM!$I$9,0) -> 0 | E14: Intoduction
A15: Moblity Devices | B15: =CPPM!I60 -> 0 | C15: =IFERROR(B15/CPPM!$I$9,0) -> 0 | E15: Intorduction
A17: SCENARIO TOOL GRAPHS | B17: BASELINE | C17: ADJUSTED | D17: SAVINGS | E17: Introductions
A18: Real Estate | B18: =SCENARIOS!$D$19 -> 0 | C18: =SCENARIOS!$H$19 -> 0 | D18: =B18-C18 -> 0
A19: Telecom | B19: =SCENARIOS!$D$34 -> 0 | C19: =SCENARIOS!$H$34 -> 0 | D19: =B19-C19 -> 0
A20: Individual IT | B20: =SCENARIOS!$D$49 -> 0 | C20: =SCENARIOS!$H$49 -> 0 | D20: =B20-C20 -> 0
A23: Real Estate Comparison | B23: BASELINE | C23: ADJUSTED | D23: SAVINGS | F23: costs | G23: savings
A24: Teleworkers | B24: =SCENARIOS!#REF! -> #REF! | C24: =SCENARIOS!#REF! -> #REF! | E24: =A45 -> Real Estate | F24: =IF(B45>0,0,B45) -> #VALUE! | G24: =IF(B45<0,0,B45) -> #VALUE!
A25: Total Workspaces | B25: =SCENARIOS!$D$12 -> 0 | C25: =SCENARIOS!$H$12 -> 0 | D25: =B25-C25 -> 0 | E25: =A46 -> Telecom | F25: =IF(B46>0,0,B46) -> #VALUE! | G25: =IF(B46<0,0,B46) -> #VALUE!
A26: Shared Workspaces | B26: =SCENARIOS!$D$24 | C26: =SCENARIOS!$H$24 -> 0
A27: Assigned Workspaces | B27: =B25-B26 -> #VALUE! | C27: =C25-C26 -> 0 | E27: =A47 -> Workstation IT | F27: =IF(B47>0,0,B47) -> #VALUE! | G27: =IF(B47<0,0,B47) -> #VALUE!
A28: Rentable Square Feet (*1,000) | B28: =SCENARIOS!$D$10/1000 -> 0 | C28: =SCENARIOS!$H$10/1000 -> 0 | D28: =(B28-C28) -> 0 | E28: =A48 -> Mobility Devices | F28: =IF(B48>0,0,B48) -> #VALUE!
E29: =A49 -> Alternative Work Environments | F29: =IF(B49>0,0,B49) -> #VALUE! | G29: =IF(B49<0,0,B49) -> #VALUE!
A35: Baseline IT | B35: 5000
A36: Cloud IT | B36: 3200 | D36: 1 | E36: Teleworkers (%)
A37: IP Phone | B37: 497 | D37: 2 | E37: Teleworkers (#)
A38: Digital Phone | B38: 1000 | D38: 3 | E38: Square Feet (%)
D39: 4 | E39: Square Feet (#)
A44: SUBTRACTION OF SCENARIO TOOL GRAPHS FROM CPP GRAPHS
A45: Real Estate | B45: #VALUE! | C45: #VALUE!
A46: Telecom | B46: #VALUE! | C46: #VALUE!
A47: Workstation IT | B47: #VALUE! | C47: #VALUE!
A48: Mobility Devices | B48: #VALUE! | C48: #VALUE!
A49: Alternative Work Environments | B49: #VALUE! | C49: #VALUE!
A50: NET SAVINGS | B50: =SUM(B45:B49) -> #VALUE! | C50: =SUM(C45:C49) -> #VALUE!
A58: Telecommunications | F58: Results | J58: Telecommunications
A60: Estimated annual cost per profile | C60: =CPPM!#REF! -> #REF! | F60: Change in Cost | J60: Estimated annual cost per profile | K60: =C60 -> #REF!
F61: =IFERROR($L$55-$D$55,0) -> 0
A62: Number of profiles | C62: =CPPM!#REF! -> #REF! | J62: Number of profiles | K62: =C62 -> #REF!
...

Sheet DEFINITIONS
B2: DEFINITIONS
B3: Field Name | C3: Description
B4: People
B5: Number of employees | C5: Total number of employees, including full-time, part-time, interns, and contractors, in terms of full-time equivalents (FTE).
B6: Total number of teleworkers | C6: Number of employees who perform work at least one entire work day a week at a location other than their official duty station.
B7: REAL ESTATE
B8: Total square footage of office space (rentable) | C8: Tenant total square footage of rentable office space, except for the elevator shaft and fire-escape stairwell. Rentable space includes restrooms, electrical and mechanical rooms, janitorial rooms, elevator lobbies and public corridors. Cost data should be available in leasing agreement.
B9: Total number of workspaces | C9: Total number of on-site workstations
B10: Square feet per person | C10: Total square feet of rentable office space divided by the total number of employees (FTE).
B11: Fully serviced rental rate | C11: Rental rate for the area, building class, and type. Including utilities, trash removal, janitorial services, furniture, fixtures, and equipment, etc.
B13: TELECOMMUNICATIONS
B14: Annual cost per workstation | C14: Annual cost of digital system or IP Phone (Voice Over Internet Protocal) for each workstation. This includes the instrument cost plus the cost of local service.
B16: INDIVIDUAL INFORMATION TECHNOLOGY (IT) AND MOBILITY DEVICES
B17: Annual IT cost per individual profile | C17: Cost of workstation IT system and local area network (LAN) interface for each employee. Cost of a personal computer and a phone for each workstation based on economies of scales for a large organization. Cost includes a more powerful (megahertz) PC with a large disk space. It also includes more options in the software IT configuration and in-house staff support (i.e. Help Desk).
B18: Laptop | C18: Cost for laptop computers used by employees for travel, teleworking, etc. Suggested cost range is $400-$500 per year, assuming 3-year life cycle.
B19: Smartphone | C19: Includes cost of Voice and Domestic Data Bundle Plan. For devices, zero or nominal cost. Suggested cost range is $600-$700 per year.
B20: Tablet Computer | C20: For devices, zero or nominal cost. Suggested cost range is $500-$600 per year.
