Workbook

Sheet Instructions
A1: Colorado Department of Education
A2: Maintenance of Effort Workbook
A3: as required under IDEA (34 CFR §300.203)
A4: Instructions for Completing MOE Workbook
A5: 2012-13
A7: Purpose
B8: This workbook can be used as a tool to calculate if an AU will meet MOE by entering the AU's projected expenditures into the Data Needed section. In this scenario, the AU will enter the information into the Data Needed section of the MOE Input Sheet and submission to CDE is not required.
B10: This workbook must be used if the AU appears to have failed Maintenance of Effort and must document the allowable exceptions to show that MOE was maintained with exceptions. In this scenario, CDE will have entered the actual data used to measure Maintenance of Effort into the Data Needed section of the MOE Input Sheet and the AU must submit the completed workbook with the completed Signature Page to CDE.
B12: Printing of these instructions is recommended for reference while working through the different tabs of the workbook.
A14: 1. Signature Page
B16: The signature page must be completed emailed in pdf format to CDE to document that the exceptions provided in 4. Exceptions have been certified by the Superintendent, Director of Special Education and Business Manager/CFO.
A20: 2. MOE Input Sheet
B22: The MOE Input Sheet is where all data should be input to determine the next steps for determining whether an Administrative Unit meets the MOE requirements
B25: Data Needed Section:
C27: Select your Administrative Unit name from the drop down list. The Administrative Unit code will automatically populate based on the name you select.
C30: Select whether your Administrative Unit, 'Meets Requirements' based on the determination made by the ESSU.
C33: Input the amounts for the current year and prior year allocation for IDEA Part B
C35: Input any supplemental award under the FY in which the funds can be used. For example: supplements made to AUs from 11/12 funds, are available for use in 12/13, and they would be entered under the 12/13 column.
C37: Include the amounts expended and obligated for Early Intervening Services.
C39: Input State and Local Expenditures for both periods.
C41: Input the December 1 Funded Pupil Count.
C43: Input the December 1 Total Served Special Education Count
B45: Maintenance of Fiscal Effort (MOE) Comparisons Section:
C47: Review the information in the Maintenance of Fiscal Effort (MOE) Comparisons section of the MOE_Input_Sheet. If any line in this section has "Pass" under the Result of Comparison, the Administrative Unit has met effort and no further action is required.
C50: If the three cells under the Results of Comparison say "Continue" it will be necessary for the Administrative Unit to provide additional information to justify the decrease in MOE.
C54: The Maintenance of Fiscal Effort (MOE) Comparisons section will provide the optimal (best case) MOE comparison for each scenario:
C57: -- | D57: Total Expenditures
C58: -- | D58: Per Capita - December 1 - Funded Pupil Count, or
C59: -- | D59: Per Capita - December 1 - Total Served Special Education Count
C61: Note: The Per Capita amounts provided in the MOE Comparisons section are aggregated for comparison purposes. For example, if the per capita amount is $150 per pupil, the MOE Comparisons section multiplies $150 by the number of pupils in the current year to determine the smallest reporting year comparisons in aggregate. That is, the per capita must be aggregated at this point to determine the total amount of effort that has not been maintained.
C68: The smallest number of the three is the amount that must be explained on the Exceptions sheet:
A71: 3. Calculations Sheet
B73: This sheet is locked and input is not necessary. It is performing the calculations necessary to
B74: determine Maintenance of Effort as reported on sheet 2. MOE_Input_Sheet under comparisons.
A76: 4. Exceptions
B78: This sheet is locked and input is not necessary. The Exceptions page totals the amounts input into sheets 5 - 7 to determine the amount of effort that may be reduced due to the mitigating circumstances documented in these pages. Calculations are made automatically and cell E45 indicates if the total exceptions explain the total shortfall and allow the AU to Pass the MOE requirement (Cell E45 will indicate Pass/Fail).
A82: 5. Staff Departures
B84: The voluntary departure, by retirement or otherwise, or departure for just cause of special education
B85: or related services personnel (34 CFR §300.204(a)) is an allowable exception to Maintenance of
B86: Effort.
...

Sheet 1. Signature_Page
A1: Colorado Department of Education
A2: Maintenance of Effort Workbook
A3: as required under IDEA (34 CFR §300.203)
A4: Signature Page and Certification
A5: ='2. MOE_Input_Sheet'!I18 -> 2012-13
A10: Admin. Unit Code: | C10: ='2. MOE_Input_Sheet'!C7
A12: Admin. Unit Name | C12: ='2. MOE_Input_Sheet'!C10:G10 -> None
B17: We (the administrative unit) understand that all Federal requirements for providing a free appropriate public education (FAPE) to children with disabilities under §300.101 of the Individuals with Disabilities Education Act still apply and that these requirements are not diminished in any manner with these exceptions to the MOE calculation as provided. We certify, that to the best of our knowledge, all information contained in this workbook true and accurate.
A25: Superintendent: | H25: Date:
A28: Director of Special Education: | H28: Date:
A31: Chief Financial Officer/Business Manager | H31: Date:

Sheet 2. MOE_Input_Sheet
A1: Colorado Department of Education
A2: Maintenance of Effort Workbook
A3: as required under IDEA (34 CFR §300.203)
A4: =I18 -> 2012-13
P5: Yes
P6: No
A7: Admin. Unit Code: | C7: =IF(C10<>"None",VLOOKUP(C10,AC18:AD74,2,FALSE),"")
A9: Select
A10: Admin. Unit Name | C10: None
A13: Did Admin. Unit Meet Requirements Reporting Year?
G16: Preceding | I16: Current
G17: Reporting Year | I17: Reporting Year
A18: Data Needed: | G18: 2011-12 | I18: 2012-13 | AC18: None
AC19: EXAMPLE | AD19: 99999
A20: IDEA Part B - Flowthrough Allocation | AC20: ADAMS 1 MAPLETON | AD20: 01010
A21: IDEA Part B - Supplemental Allocation - Enter into the year in which the funds can be used | AC21: ADAMS 12 NORTHGLENN | AD21: 01020
A22: Total Allocation | G22: =SUM(G20:G21) -> 0 | I22: =SUM(I20:I21) -> 0 | AC22: ADAMS 14 COMMERCE CITY | AD22: 01030
AC23: ADAMS 27J BRIGHTON | AD23: 01040
A24: Coordinated Early Intervening Services | G24: 0 | I24: 0 | AC24: ADAMS 50 WESTMINSTER | AD24: 01070
AC25: ARAPAHOE 1 ENGLEWOOD | AD25: 03010
A26: State and Local Special Education Expenditures (ADE Codes 3130/3131) | AC26: ARAPAHOE 2 SHERIDAN | AD26: 03020
AC27: ARAPAHOE 5 CHERRY CREEK | AD27: 03030
A28: December 1 Funded Special Ed Student Count | AC28: ARAPAHOE 6 LITTLETON | AD28: 03040
G29: Dec 1, 2011 | I29: Dec 1, 2012 | AC29: ADAMS-ARAP 28J AURORA | AD29: 03060
A30: December 1 Total Served Special Ed Count | AC30: BOULDER RE-1J ST VRAIN | AD30: 07010
AC31: BOULDER RE-2 BOULDER | AD31: 07020
AC32: DELTA 50J | AD32: 15010
AC33: DENVER 1 | AD33: 16010
AC34: DOUGLAS RE-1 | AD34: 18010
AC35: EL PASO 2 HARRISON | AD35: 21020
A36: Maintenance of Fiscal Effort (MOE) Comparisons | G36: Reporting Year | I36: Results of Comparison | AC36: EL PASO 3 WIDEFIELD | AD36: 21030
A37: Only the optimal comparison is shown. | E37: No. | G37: Comparisons | I37: (Pass or Fail, Fail=Continue) | AC37: EL PASO 8 FOUNTAIN | AD37: 21040
AC38: EL PASO 11 COLO SPRINGS | AD38: 21050
A39: State and Local Expenditures (ADE Codes 3130/3131) | E39: =IF(G39='3. Calculations_Sheet'!L25,'3. Calculations_Sheet'!A25,IF(G39='3. Calculations_Sheet'!L28,'3. Calculations_Sheet'!A28,"")) -> 1 | G39: =MAX('3. Calculations_Sheet'!L25:L28) -> 0 | I39: =IF(G39>=0,"Pass","Continue") -> Pass | AC39: EL PASO 12 CHEYENNE MOUNTAIN | AD39: 21060
AC40: EL PASO 20 ACADEMY | AD40: 21080
A41: December 1 Total Special Ed Funded Pupil Count | E41: =IF(G41='3. Calculations_Sheet'!P33,'3. Calculations_Sheet'!A33,IF(G41='3. Calculations_Sheet'!P37,'3. Calculations_Sheet'!A37,"")) | G41: =MAX('3. Calculations_Sheet'!P33:P37) -> 0 | I41: =IF(G41>=0,"Pass","Continue") -> Pass | AC41: EL PASO 38, LEWIS PALMER | AD41: 21085
AC42: EL PASO 49 FALCON | AD42: 21090
A43: December 1 Head Count - Per Capita -- Total Served | E43: =IF(G43='3. Calculations_Sheet'!P41,'3. Calculations_Sheet'!A41,IF(G43='3. Calculations_Sheet'!P45,'3. Calculations_Sheet'!A45,"")) | G43: =MAX('3. Calculations_Sheet'!P41:P45) -> 0 | I43: =IF(G43>=0,"Pass","Continue") -> Pass | AC43: FORT LUPTON/KEENESBURG | AD43: 21490
AC44: FREMONT RE-1 CANON CITY | AD44: 22010
AC45: GUNNISON RE-1J | AD45: 26011
...

Sheet 3. Calculations_Sheet
B3: Current Reporting Year | C3: ='2. MOE_Input_Sheet'!I18 -> 2012-13
B5: Admin Unit Code | C5: ='2. MOE_Input_Sheet'!C7
B7: Admin Unit Name | C7: ='2. MOE_Input_Sheet'!C10 -> None
H8: Preceding | J8: Current
H9: Reporting Year | J9: Reporting Year
H10: ='2. MOE_Input_Sheet'!G18 -> 2011-12 | J10: ='2. MOE_Input_Sheet'!I18 -> 2012-13
B11: Data Input Section - Input positive numbers
L12: 50% Limit | N12: 50% Flexibility
B13: Total IDEA Part B | H13: ='2. MOE_Input_Sheet'!G22 -> 0 | J13: ='2. MOE_Input_Sheet'!I22 -> 0 | L13: =IF('2. MOE_Input_Sheet'!E13="Yes",IF('3. Calculations_Sheet'!J13-'3. Calculations_Sheet'!H13>0,('3. Calculations_Sheet'!J13-'3. Calculations_Sheet'!H13)*0.5,"N/A"),"N/A") -> N/A | N13: =IF(L13="N/A",0,IF(J15>=(J13*0.15),0,IF(L13>=0,IF(L13-J15>=0,IF(J15=0,(L13-J15),IF(L13-J15>L17,L17,L13-J15)),0)))) -> 0
B15: ='2. MOE_Input_Sheet'!A24 -> Coordinated Early Intervening Services | H15: ='2. MOE_Input_Sheet'!G24 -> 0 | J15: ='2. MOE_Input_Sheet'!I24 -> 0 | L15: =J13*0.15 -> 0 | M15: Max | N15: Available
B17: ADE Expenditures Reported for State Grant Codes 3130/3131 | H17: ='2. MOE_Input_Sheet'!G26 -> 0 | J17: ='2. MOE_Input_Sheet'!I26 -> 0 | L17: =IF((J13*0.15)-J15>L13,L13-J15,IF((L13-J15)<0,0,(J13*0.15)-J15)) -> #VALUE! | N17: EIS Limit to 50% Rule
B19: December 1 Funded Special Ed Student Count | H19: ='2. MOE_Input_Sheet'!G28 -> 0 | J19: ='2. MOE_Input_Sheet'!I28 -> 0 | L19: =IF(OR(H19=0,J19=0),"Not Valid",(J19/H19)-1) -> Not Valid | N19: Percent
N20: Change
B21: December 1 Total Special Ed Count | H21: ='2. MOE_Input_Sheet'!G30 -> 0 | J21: ='2. MOE_Input_Sheet'!I30 -> 0 | L21: =IF(OR(H21=0,J21=0),"Not Valid",(J21/H21)-1) -> Not Valid
P22: Total
A23: No. | B23: Maintenance of Effort (MOE) - Comparisons | H23: Prior Year | J23: Current Year | L23: Increase/(Decrease) | P23: Surplus/(Shortfall)
A25: 1 | B25: Comparison Prior Year to Current Year Special Ed Expenditures | H25: =SUM(H17:H18) -> 0 | J25: =SUM(J17:J18) -> 0 | L25: =J17-H17 -> 0 | N25: =IF(L25>=0,"Pass","Continue") -> Pass | P25: =L25 -> 0
A28: 2 | B28: 50% Flexibility, if Meets Requirements | H28: =H17 -> 0 | J28: =J17+N13 -> 0 | L28: =(J17+N13)-H17 -> 0 | N28: =IF(L28>=0,"Pass","Continue") -> Pass | P28: =L28 -> 0
P29: Total
B30: Per Capita Calculations | H30: Prior Year | J30: Current Year | L30: Increase/(Decrease) | P30: Surplus/(Shortfall)
A33: 3 | B33: Per Capita - December 1 Headcount (Funded) | H33: =IF(OR(H19=0,J19=0),"Not Valid",H25/H19) -> Not Valid | J33: =IF(OR(H19=0,J19=0),"Not Valid",J25/J19) -> Not Valid | L33: =IF(OR(H19=0,J19=0),-0.001,J33-H33) -> -0.001 | N33: =IF(L33>=0,"Pass","Continue") -> Continue | P33: =IF(OR(H$19=0,J$19=0),"",IF(J$19=0,"",L33*J$19))
A37: 4 | B37: Per Capita - Dec.1 Headcount (Funded) - 50% Flex | H37: =IF(OR(H19=0,J19=0),"Not Valid",H28/H19) -> Not Valid | J37: =IF(OR(H19=0,J19=0),"Not Valid",J28/J19) -> Not Valid | L37: =IF(OR(H19=0,J19=0),-0.001,J37-H37) -> -0.001 | N37: =IF(L37>=0,"Pass","Continue") -> Continue | P37: =IF(OR(H$19=0,J$19=0),"",IF(J$19=0,"",L37*J$19))
A41: 5 | B41: Per Capita - December 1 Total Head Count (Served) | H41: =IF(OR(H21=0,J21=0),"Not Valid",H25/H21) -> Not Valid | J41: =IF(OR(H21=0,J21=0),"Not Valid",J25/J21) -> Not Valid | L41: =IF(OR(H21=0,J21=0),-0.001,J41-H41) -> -0.001 | N41: =IF(L41>=0,"Pass","Continue") -> Continue | P41: =IF(OR(H$21=0,J$21=0),"",IF(J$21=0,"",L41*J$21))
A45: 6 | B45: Per Capita - December 1 Total Head Count (Served) - 50% Flex | H45: =IF(OR(H21=0,J21=0),"Not Valid",H28/H21) -> Not Valid | J45: =IF(OR(H21=0,J21=0),"Not Valid",J28/J21) -> Not Valid | L45: =IF(OR(H21=0,J21=0),-0.001,J45-H45) -> -0.001 | N45: =IF(L45>=0,"Pass","Continue") -> Continue | P45: =IF(OR(H$21=0,J$21=0),"",IF(J$21=0,"",L45*J$21))
B48: Maintenance of Effort - (Shortfall)/ Surplus | L48: =IF(MAX(P25:P45)>0,0,MAX(P25:P45)) -> 0 | N48: =IF(L48>=0,"Pass","Continue") -> Pass | P48: =MAX(P24:P47) -> 0 | Q48: Maximum
P49: =IF(L25>=0,0,IF(L28>=0,0,IF(P48<=0,N13,IF(N13-P48<=0,0,N13-P48)))) -> 0 | Q49: 50% Flexibility
E50: Date | G50: =+TODAY() -> 41806 | Q50: Used
E51: Shortfall without 50% Flexibility | L51: =L48-P49 -> 0

Sheet 4. Exceptions
A1: Colorado Department of Education
A2: Maintenance of Effort Workbook
A3: as required under IDEA (34 CFR §300.203)
A4: Exception Totals Worksheet
A6: Instructions: No Input is necessary on this sheet. Calculations are made automatically from data input on the Staff_Departures, HighCost_Students and Termination_of_Exps tabs of this workbook. See Cell E45 to see Pass/Fail results after entering exceptions.
A9: Reporting Year | C9: ='2. MOE_Input_Sheet'!I18 -> 2012-13
A11: Administrative Unit Code | C11: ='2. MOE_Input_Sheet'!C7
A13: Administrative Unit Name | C13: ='2. MOE_Input_Sheet'!C10 -> None
A16: Maintenance of Effort Shortfall from MOE_Input_Sheet | D16: -0.35 | E16: =IF('2. MOE_Input_Sheet'!I48="Pass","Pass",'2. MOE_Input_Sheet'!G48) -> Pass
A19: Exceptions to Maintenance of Effort (see Federal IDEA Regulations 34 CFR §300.204):
A20: Justify only to the amount of fiscal effort not maintained as noted on the Maintenance of Fiscal Effort Worksheet. If the total justifications equal/exceed this amount then fiscal effort has been maintained for the reporting year.
A23: Exception: | C23: Amount(s)
A25: 34 CFR §300.204(a)
A26: Voluntary Departure, by retirement or otherwise, or departure for just cause. ('Departures' worksheet) | B26: 1. | C26: ='5. Staff_Departures'!H115 -> 0
A30: 34 CFR §300.204(c)
A31: High Cost special education student moves, reaches maximum age, or no longer needs services. ('High Cost' worksheet) | B31: 2. | C31: ='6. HighCost_Students'!F114 -> 0
A35: 34 CFR §300.204(d)
A36: Termination of costly expenditures for Long-Term Purchases ('Termination_of_Exps' worksheet) | B36: 3. | C36: ='7. Termination_of_Exps'!G47 -> 0
A39: Allowable Federal Exceptions to Maintenance of Effort | C39: =SUM(C26:C36) -> 0
A44: Maintenance of Effort Surplus/(Shortfall) | E44: =IF($E16="Pass",0,E16+C39) -> 0
E45: =IF(E44>=0,"Pass","Fail") -> Pass

Sheet 5. Staff_Departures
A1: Colorado Department of Education
A2: Maintenance of Effort Workbook
A3: 34 CFR §300.204(a)
A4: Worksheet to Document Departures of Staff
A5: ='2. MOE_Input_Sheet'!I18 -> 2012-13
A7: Instructions: Provide the requested information in the appropriate columns. The allowable exception amount will calculate automatically. If the position could not be filled with a qualified applicant enter N/A for the Name and $0 for the Amount of the incoming employee. Provide the total position cost funded by State and Local funds for these staff. Only the difference between the higher paid departing staff and the lower paid incoming staff is an allowable exception. See the Instructions tab under Staff Departures for more detailed instructions, and information on unallowable staff exceptions. For monitoring purposes, maintain your records regarding these staff and the calculations of salary and benefit costs, but do not submit to CDE with this document, unless requested.
G9: Salary & Benefits
D10: Salary & | G10: Amount for
D11: Benefits Amount | F11: Name of | G11: Incoming Employee | H11: Allowable
B12: Name of | D12: For Departing | F12: Incoming Employee | G12: (Enter $0 if not | H12: Exception
A13: No. | B13: Departing Employee | C13: Position | D13: Employee | E13: Reason for Departure | F13: (Enter N/A if not replaced) | G13: replaced) | H13: Amount
A14: 1 | H14: =D14-G14 -> 0
A15: 2 | H15: =D15-G15 -> 0
A16: 3 | H16: =D16-G16 -> 0
A17: 4 | H17: =D17-G17 -> 0
A18: 5 | H18: =D18-G18 -> 0
A19: 6 | H19: =D19-G19 -> 0
A20: 7 | H20: =D20-G20 -> 0
A21: 8 | H21: =D21-G21 -> 0
A22: 9 | H22: =D22-G22 -> 0
A23: 10 | H23: =D23-G23 -> 0
A24: 11 | H24: =D24-G24 -> 0
A25: 12 | H25: =D25-G25 -> 0
... A113: 100 | H113: =D113-G113 -> 0
F115: Total: | H115: =SUM(H14:H113) -> 0

Sheet 6. HighCost_Students
A1: Colorado Department of Education
A2: Maintenance of Effort Workbook
A3: 34 CFR §300.204(c)
A4: Worksheet to Document Departure of High Cost Students
A5: ='2. MOE_Input_Sheet'!I18 -> 2012-13
A7: Instructions: The first 100 are prepopulated with the State Threshold and the Amount formula. Numbers after 30 are hidden. Unhide to get numbers 31 -100. Add additional rows as needed and copy the threshold amount in column E and the formula in column F down into the appropriate columns of the additional rows, or you can contact Grants Fiscal to add rows for you. Do not report the same student on multiple lines. See the Instructions tab under High Cost Students for more detailed instructions and allowable reasons for departure of high cost students. For monitoring purposes, maintain your calculations of student costs and back up for reasons for leaving, but do not submit to CDE with this document, unless requested.
D9: Total | E9: State
D10: State & Local | E10: Threshold | F10: Allowable
D11: Program | E11: for MOE High | F11: Exception
A12: No. | B12: SASID | C12: Reason for Decrease in Cost | D12: Amount | E12: Cost Program | F12: Amount
A13: 1 | E13: 7250 | F13: =IF(D13-E13>0,D13-E13,"")
A14: 2 | E14: 7250 | F14: =IF(D14-E14>0,D14-E14,"")
A15: 3 | E15: 7250 | F15: =IF(D15-E15>0,D15-E15,"")
A16: 4 | E16: 7250 | F16: =IF(D16-E16>0,D16-E16,"")
A17: 5 | E17: 7250 | F17: =IF(D17-E17>0,D17-E17,"")
A18: 6 | E18: 7250 | F18: =IF(D18-E18>0,D18-E18,"")
A19: 7 | E19: 7250 | F19: =IF(D19-E19>0,D19-E19,"")
A20: 8 | E20: 7250 | F20: =IF(D20-E20>0,D20-E20,"")
A21: 9 | E21: 7250 | F21: =IF(D21-E21>0,D21-E21,"")
A22: 10 | E22: 7250 | F22: =IF(D22-E22>0,D22-E22,"")
A23: 11 | E23: 7250 | F23: =IF(D23-E23>0,D23-E23,"")
A24: 12 | E24: 7250 | F24: =IF(D24-E24>0,D24-E24,"")
... A112: 100 | E112: 7250 | F112: =IF(D112-E112>0,D112-E112,"")
D114: Total: | F114: =SUM(F13:F113) -> 0

Sheet 7. Termination_of_Exps
A1: Colorado Department of Education
A2: Maintenance of Effort Workbook
A3: 34 CFR §300.204(d)
A4: Worksheet for the Termination of Costly Expenditures for Long Term (Multi-Year) Purchases
A5: ='2. MOE_Input_Sheet'!I18 -> 2012-13
A7: Instructions: For each expenditure start by answering the first 2 questions about fiscal year expenditures. These questions will determine if the expenditure is an allowable exception. To be allowable, the answer to the question in column B must be Yes and the answer to the question in column C must be No. If the expense is allowable, enter the requested information in the appropriate column. Under type of expenditure enter a brief description such as capital outlay equipment, or bus fleet refurbishing, etc., enter the amount expensed in FY 2010/11, this is the amount of your allowable exception. See the Instructions tab under Termination of Expenditures for more detailed instructions and information on allowable exceptions for the termination of costly long term expenditures. For monitoring purposes, maintain contract documentation and expenditure back up, but do not submit to CDE with this document, unless requested.
B9: Are there
B10: Expenditures | C10: Are there
B11: for this | C11: Expenditures | G11: Amount
B12: Contract in | C12: for this | G12: Expensed in FY
B13: at least FY | C13: Contract in | F13: Contract Start | G13: 2011-12
B14: 10/11 & FY | C14: FY 2012/13? | F14: and End | G14: (Allowable
A15: No. | B15: 11/12? (Y/N) | C15: (Y/N) | D15: Type of Expenditure | E15: Contract # | F15: Dates | G15: Exception)
A16: 1
A17: 2
A18: 3
A19: 4
A20: 5
A21: 6
A22: 7
A23: 8
A24: 9
A25: 10
A26: 11
A27: 12
... A45: 30
F47: Total: | G47: =SUM(G46:G46) -> 0
