Workbook
Name _ftn1: 'EE Curriculum'!$O$40
Name _ftn1: 'EE CurriculumCO-OP'!$O$50
Name _ftnref1: 'EE Curriculum'!#REF!
Name _ftnref1: 'EE CurriculumCO-OP'!#REF!
Name flow_chart_print: Flowchart!$A$1:$P$32
Name Workloads: #REF!
Name Workloads: #REF!
Name Workloads: #REF!

Sheet EE Curriculum
E1: MERRIMACK COLLEGE
E2: ELECTRICAL ENGINEERING CURRICULUM | I2: (as of Fall 2013) | CO2: ECO 1201 Introduction to Economics
CO3: ECO 1202 Topics in Introductory Economics
A4: Name | C4: ID # | F4: Class year: | I4: ADVISOR: | CO4: ECO 3305 Ecological Economics
B6: FALL | I6: SPRING | BC6: Workloads | CA6: Arts and Literature | CD6: Ethics
F7: FRESHMAN YEAR | BC7: Fall | BE7: Spring | CI7: Historical Studies | CN7: Social Science | CS7: Science Elective
A8: GEN 1001 | B8: Intro. to Eng. | C8: 4 | H8: EEN 1200 | I8: Digital Fundamentals | J8: 4 | BC8: =A8 -> GEN 1001 | BD8: =C8 -> 4 | BE8: =H16 -> EEN 2140 | BF8: =J16 -> 4
A9: MTH 1217 | B9: Calculus I | C9: 4 | H9: MTH 1218 | I9: Calculus II | J9: 4 | BC9: =A16 -> EEN 2130 | BD9: =C16 -> 4 | BE9: =H18 -> EEN 2270 | BF9: =J18 -> 4 | CA9: Communication Arts and Sciences | CB9: WRT 2790 Public and Private Writing from the Civil War Era | CD9: Management | CE9: MGT 3325 Ethics and Social Responsibility | CI9: Economics | CJ9: ECO 3314 U.S. Economic History | CN9: Communication Arts and Sciences | CO9: COM 2201 Introduction to Interpersonal Communication | CS9: AST 1101 Introduction to Astronomy
A10: PHL 1000 | B10: Intro to Philosophy | C10: 4 | H10: CHM 1180 | I10: Engineering Chemistry | J10: 4 | BC10: =A19 -> EEN 2250 | BD10: =C19 -> 2 | BE10: =A25 -> EEN 3270 | BF10: =C25 -> 4 | CA10: Communication Arts and Sciences | CB10: WRT 3060 Writing the Personal Memoir | CD10: Philosophy | CE10: PHL 2020W Perspectives on the Good Life | CI10: Economics | CJ10: ECO 3312 The History of Economic Thought | CN10: Communication Arts and Sciences | CO10: COM 2301 Introduction to Organizational Communication | CS10: BIO 1027 Principles of Biology I
A11: CSC 1610 | B11: Computer Science I | C11: 4 | H11: ENG 1050 | I11: College Writing | J11: 4 | BC11: =H25 -> EEN 3430 | BD11: =J25 -> 4 | BE11: =A36 -> EEN 3130 | BF11: =C36 -> 4 | CA11: English | CB11: ENG 1060 Horror Fiction | CD11: Philosophy | CE11: PHL 2030 Contemporary Moral Problems | CI11: History | CJ11: HIS 1106 History of American Civilization, 1600-1877 | CN11: Communication Arts and Sciences | CO11: COM 2401 Introduction to Mass Communication | CS11: BIO 3009 Environment, Ecology and Society
A12: EEN 1100 | B12: Analog Fundamentals | C12: 2 | BC12: =A26 -> MTH 2220 | BD12: =C26 -> 4 | BE12: =H26 -> EEN 3220 | BF12: =J26 -> 4 | CA12: English | CB12: ENG 1500 Major British and World Authors | CD12: Philosophy | CE12: PHL 2040 Introduction to Political Philosophy | CI12: History | CJ12: HIS 1107 History of American Civilization, 1877-2000 | CN12: Communication Arts and Sciences | CO12: COM 3231 Intercultural Communication | CS12: BIO 3090 – 3099 Global Field Studies Program Courses
C13: =SUM(C8:C12) -> 18 | J13: =SUM(J8:J12) -> 16 | BC13: =#REF! -> #REF! | BD13: =#REF! -> #REF! | BE13: =H34 -> MTH 1505 | BF13: =J34 -> 4 | CA13: English | CB13: ENG 1550 Major American Authors | CD13: Philosophy | CE13: PHL 2050 Ethics in the Professions | CI13: History | CJ13: HIS 1119 History of Western Civilization I | CN13: Economics | CO13: ECO 1201 Introduction to Economics | CS13: CEN 4060 Geology
CA14: English | CB14: ENG 2050W Introduction to Literary Studies | CD14: Philosophy | CE14: PHL 2060 Biomedical Ethics | CI14: History | CJ14: HIS 1120 History of Western Civilization II | CN14: Economics | CO14: ECO 1202 Topics in Introductory Economics | CS14: CSC 1610 Computer Science I
F15: SOPHOMORE YEAR | O15: INSTRUCTIONS FOR USE | BC15: =B34 -> VLSI Design | BD15: =C34 -> 4 | BE15: =I35 -> Feedback Circuits | BF15: =J35 -> 4 | CA15: English | CB15: ENG 2200 Introduction to Poetry | CD15: Philosophy | CE15: PHL 2070 Environmental Ethics | CI15: History | CJ15: HIS 2329 American Social History | CN15: Economics | CO15: ECO 1203 Principles of Economics – Micro | CS15: HSC 1104 Introduction to Human Disease
A16: EEN 2130 | B16: Circuit Theory I | C16: 4 | H16: EEN 2140 | I16: Circuit Theory II | J16: 4 | O16: 1. Enter a 1 into the boxes outlined in green beside courses that you have completed successfully | BE16: =#REF! -> #REF! | BF16: =#REF! -> #REF! | CA16: English | CB16: ENG 2300 Detective Fiction | CD16: Philosophy | CE16: PHL 2080 Approaches to Ethics | CI16: History | CJ16: HIS 2340 History of Latin America (D) | CN16: Economics | CO16: ECO 1204 Principles of Economics – Macro | CS16: HSC 1106 Human Biology
A17: PHY 2211 | B17: Physics I | C17: 4 | H17: PHY 2212 | I17: Physics II | J17: 4 | BE17: =H37 -> EEN 4970 | BF17: =J37 -> 2 | CA17: English | CB17: ENG 2740 Politics in Literature | CD17: Philosophy | CE17: PHL 2090 Values in a Technological Culture | CI17: History | CJ17: HIS 3350 Ancient History | CN17: Economics | CO17: ECO 1225 Economics of Gender | CS17: HSC 1122 Anatomy and Physiology I
A18: MTH 2219 | B18: Calculus III | C18: 4 | H18: EEN 2270 | I18: Embedded Microprocessors | J18: 4 | O18: 2. Now you're ready to begin planning the upcoming semester. Enter a 1 into the green boxes beside courses in which you would like to enroll next semester. | CA18: English | CB18: ENG 2750 Adapting the Graphic Novel to Film | CD18: Philosophy | CE18: PHL 2100 Women, Ethics and Society (D) | CI18: History | CJ18: HIS 3360 Medieval Civilization | CN18: Economics | CO18: ECO 2201 Intermediate Micro-Economics | CS18: HSC 2300 Nutrition, Diet and Health
A19: EEN 2250 | B19: Assembly for EEN | C19: 2 | H19: Ethics (E) | I19: Elective (course here) | J19: 4 | CA19: English | CB19: ENG 2770 Literature and Film | CD19: Philosophy | CE19: PHL 2310 Socrates and the Examined Life | CI19: History | CJ19: HIS 3370 Renaissance and Reformation | CN19: Economics | CO19: ECO 2202 Intermediate Macro-Economics | CS19: HSC 3302 Community Public Health
A20: Arts & Lit (AL) | B20: Elective (course here) | C20: 4 | O20: 3. Use the attached Flowchart to find co and pre-requisite courses | CA20: English | CB20: ENG 3020 A History of the English Language | CD20: Philosophy | CE20: PHL 2500 Theories of Justice | CI20: History | CJ20: HIS 3376 Era of the French Revolution | CN20: Economics | CO20: ECO 3303 Economic Development
CA21: English | CB21: ENG 3100 Beowulf and Old English Literature | CD21: Philosophy | CE21: PHL 3020 Philosophy of Law | CI21: History | CJ21: HIS 3378 History of Modern Britain | CN21: Economics | CO21: ECO 3304 Economics of Education
C22: =SUM(C16:C21) -> 18 | J22: =SUM(J16:J20) -> 16 | CA22: English | CB22: ENG 3140 Chaucer and Middle English Literature | CD22: Philosophy | CE22: PHL 3030 Global Justice | CI22: History | CJ22: HIS 3380 History of Modern Technology | CN22: Economics | CO22: ECO 3305 Ecological Economics
CA23: English | CB23: ENG 3200 Renaissance Literature | CD23: Philosophy | CE23: PHL 3180 Existentialism | CI23: History | CJ23: HIS 3390 Modern European Social History | CN23: Economics | CO23: ECO 3306 International Economics
F24: JUNIOR YEAR | CA24: English | CB24: ENG 3220 Renaissance Drama | CD24: Religious and Theological Studies | CE24: RTS 2800 Christian Social Ethics (D) | CI24: History | CJ24: HIS 3391 Women in Modern European History (D) | CN24: Economics | CO24: ECO 3307 Labor Economics
A25: EEN 3270 | B25: Energy Gen., Cons., and Tech | C25: 4 | H25: EEN 3430 | I25: Eng. Electromagnetics I | J25: 4 | BC25: Marc | CA25: English | CB25: ENG 3250 Shakespearean Drama | CD25: Religious and Theological Studies | CE25: RTS 2900 Holocaust: Theology, Reality and Aftermath (D) | CI25: History | CJ25: HIS 3320 The American City | CN25: Economics | CO25: ECO 3308 Managerial Economics
A26: MTH 2220 | B26: Differential Equations | C26: 4 | H26: EEN 3220 | I26: Electronics II | J26: 4 | BC26: =BC9 -> EEN 2130 | BD26: =BD9 -> 4 | BE26: =BE8 -> EEN 2140 | BF26: =BF8+2+3 -> 9 | CA26: English | CB26: ENG 3280 Angels and Demons: Milton and the Culture of Revolution | CD26: Religious and Theological Studies | CE26: RTS 2950 Ethics in the Abrahamic Traditions | CI26: History | CJ26: HIS 3326 History of American Architecture | CN26: Economics | CO26: ECO 3309 Marxian Economics
A27: EEN 3210 | B27: Electronics I | C27: 4 | H27: Hist. Studies (H) | I27: Elective (course here) | J27: 4 | BC27: =BC11 -> EEN 3430 | BD27: =BD11 -> 4 | CA27: English | CB27: ENG 3300 Restoration and Eighteenth-Century Literature | CD27: Religious and Theological Studies | CE27: RTS 3700 African-American Theology (D) | CI27: History | CJ27: HIS 3401 Topics in Nineteenth-Century Europe | CN27: Economics | CO27: ECO 3310 Money and Finance
A28: RTS 1001 | B28: Christianity in Context | C28: 4 | H28: Open elective | J28: 4 | BC28: =BC13 -> #REF! | BD28: =BD13 -> #REF! | CA28: English | CB28: ENG 3320 Eighteenth-Century Novel | CD28: Religious and Theological Studies | CE28: RTS 3710 Feminist Theology (D) | CI28: History | CJ28: HIS 3410 Twentieth-Century Europe | CN28: Economics | CO28: ECO 3311 Public Finance
CA29: English | CB29: ENG 3350 Sex, Race, and Empire: 1660-1814 | CD29: Religious and Theological Studies | CE29: RTS 3800 The Catholic Thing: Merton and Day | CI29: History | CJ29: HIS 3425 Contemporary United States History | CN29: Economics | CO29: ECO 3312 The History of Economic Thought
CA30: English | CB30: ENG 3400 British Romanticism | CD30: Religious and Theological Studies | CE30: RTS 3850 War and Peace: Religious Perspectives | CI30: History | CJ30: HIS 3434 Age of the American Revolution, 1763-1800 | CN30: Economics | CO30: ECO 3313 Topics in Quantitative Economics
C31: =J25+C26+C27+C28 -> 16 | J31: =SUM(J25:J28) -> 16 | CA31: English | CB31: ENG 3420 American Romanticism | CI31: History | CJ31: HIS 3435 American Colonial History | CN31: Economics | CO31: ECO 3314 U.S. Economic History
CA32: English | CB32: ENG 3440 Victorian Literature | CI32: History | CJ32: HIS 3437 Civil War and Reconstruction | CN32: Economics | CO32: ECO 3315 Urban and Regional Economics
F33: SENIOR YEAR | BC33: Aaron | CA33: English | CB33: ENG 3470 Realism and Naturalism in America | CI33: History | CJ33: HIS 3439 Slavery and Race in the Early Modern Atlantic World, 1400-1800 | CN33: History | CO33: HIS 3376 Era of the French Revolution
A34: EEN 4750 | B34: VLSI Design | C34: 4 | H34: MTH 1505 | I34: Engineering Statistics | J34: 4 | O34: =C13+J13+C22+J22+C31+J31+C40+J40 -> 136 | BC34: =BC12 -> MTH 2220 | BD34: =BD12+2+3 -> 9 | BE34: =BE9 -> EEN 2270 | BF34: =BF9+2+3 -> 9 | CA34: English | CB34: ENG 3500 Modern British Literature | CI34: History | CJ34: HIS 3470 History of Imperial Russia | CN34: History | CO34: HIS 3380 History of Modern Technology
A35: EEN | B35: Elective (course here) | C35: 4 | H35: EEN 4270 | I35: Feedback Circuits | J35: 4 | BC35: =BC15 -> VLSI Design | BD35: =BD15 -> 4 | CA35: English | CB35: ENG 3520 Modern Irish Literature | CI35: History | CJ35: HIS 3471 History of Twentieth-Century Russia | CN35: History | CO35: HIS 3390 Modern European Social History
A36: EEN 3130 | B36: Linear Signals and Systems | C36: 4 | H36: EEN | I36: Elective (course here) | J36: 4 | CA36: English | CB36: ENG 3550 Modern American Literature | CI36: History | CJ36: HIS 3525 Environmental History of North America | CN36: History | CO36: HIS 3391 Women in Modern European History
A37: EEN 4960 | B37: Design Project I | C37: 2 | E37: Work with your advisor here. | H37: EEN 4970 | I37: Design Project II | J37: 2 | BC37: Dave | CA37: English | CB37: ENG 3620 Contemporary American Literature | CI37: Political Science | CJ37: POL 2581 Political Thought: Plato to Machiavelli | CN37: Political Science | CO37: POL 1000 Current Issues in Politics and Government
A38: Soc. Science (SS) | B38: PSY 1000 Introduction to Psychology | C38: 4 | H38: Soc. Science (SS) | I38: POL 1000 Current Issues in Politics and Government | J38: 4 | BC38: =BC10 -> EEN 2250 | BD38: =BD10+2+3 -> 7 | BE38: =BE11 -> EEN 3130 | BF38: =BF11+2+3 -> 9 | CA38: English | CB38: ENG 3650 Contemporary American Drama | CI38: Political Science | CJ38: POL 2582 Political Thought: Machiavelli to Marx | CN38: Political Science | CO38: POL 1100 Politics of the United States
BE39: =BE12 -> EEN 3220 | BF39: =BF12 -> 4 | CA39: English | CB39: ENG 3680 World Drama | CI39: Religious and Theological Studies | CJ39: RTS 2450 History of Christian Thought | CN39: Political Science | CO39: POL 1500 Comparative Politics
C40: =SUM(C34:C38) -> 18 | J40: =SUM(J34:J39) -> 18 | CA40: English | CB40: ENG 3730 Modern American Poetry | CI40: Visual and Performing Arts | CJ40: FAA 2520 Theater History I | CN40: Political Science | CO40: POL 2121 Public Administration and Public Policy
A41: NOTES | H41: List of EEN Electives | BC41: Gary | CA41: English | CB41: ENG 3740 American Women’s Fiction | CI41: Visual and Performing Arts | CJ41: FAA 2530 Theater History II | CN41: Political Science | CO41: POL 2181 American Political Thought
...

Sheet EE CurriculumCO-OP
E1: MERRIMACK COLLEGE
E2: ELECTRICAL ENGINEERING CURRICULUM | CO2: ECO 1201 Introduction to Economics
CO3: ECO 1202 Topics in Introductory Economics
A4: Name | B4: ENTER NAME HERE | C4: ID # | D4: ID HERE | F4: Class year: | G4: CLASS YEAR HERE | I4: ADVISOR: | J4: ADVISOR HERE | CO4: ECO 3305 Ecological Economics
B6: FALL | I6: SPRING | BC6: Workloads | CA6: Arts and Literature | CD6: Ethics
F7: FRESHMAN YEAR | BC7: Fall | BE7: Spring | CI7: Historical Studies | CN7: Social Science | CS7: Science Elective
A8: GEN 1001 | B8: Intro. to Eng. | C8: 4 | H8: EEN 1200 | I8: Digital Fundamentals | J8: 4 | BC8: =A8 -> GEN 1001 | BD8: =C8 -> 4 | BE8: =H16 -> EEN 2140 | BF8: =J16 -> 4
A9: MTH 1217 | B9: Calculus I | C9: 4 | H9: MTH 1218 | I9: Calculus II | J9: 4 | BC9: =A16 -> EEN 2130 | BD9: =C16 -> 4 | BE9: =H18 -> EEN 2270 | BF9: =J18 -> 4 | CA9: Communication Arts and Sciences | CB9: WRT 2790 Public and Private Writing from the Civil War Era | CD9: Management | CE9: MGT 3325 Ethics and Social Responsibility | CI9: Economics | CJ9: ECO 3314 U.S. Economic History | CN9: Communication Arts and Sciences | CO9: COM 2201 Introduction to Interpersonal Communication | CS9: AST 1101 Introduction to Astronomy
A10: PHL 1000 | B10: Intro to Philosophy | C10: 4 | H10: CHM 1180 | I10: Engineering Chemistry | J10: 4 | BC10: =A19 -> EEN 2250 | BD10: =C19 -> 2 | BE10: =H42 -> MTH 1505 | BF10: =J42 -> 4 | CA10: Communication Arts and Sciences | CB10: WRT 3060 Writing the Personal Memoir | CD10: Philosophy | CE10: PHL 2020W Perspectives on the Good Life | CI10: Economics | CJ10: ECO 3312 The History of Economic Thought | CN10: Communication Arts and Sciences | CO10: COM 2301 Introduction to Organizational Communication | CS10: BIO 1027 Principles of Biology I
A11: CSC 1610 | B11: Computer Science I | C11: 4 | H11: ENG 1050 | I11: College Writing | J11: 4 | BC11: =#REF! -> #REF! | BD11: =#REF! -> #REF! | BE11: =H43 -> EEN 4270 | BF11: =J43 -> 4 | CA11: English | CB11: ENG 1060 Horror Fiction | CD11: Philosophy | CE11: PHL 2030 Contemporary Moral Problems | CI11: History | CJ11: HIS 1106 History of American Civilization, 1600-1877 | CN11: Communication Arts and Sciences | CO11: COM 2401 Introduction to Mass Communication | CS11: BIO 3009 Environment, Ecology and Society
A12: EEN 110 | B12: Analog Fundamentals | C12: 2 | BC12: =#REF! -> #REF! | BD12: =#REF! -> #REF! | BE12: =H44 -> EEN | BF12: =J44 -> 4 | CA12: English | CB12: ENG 1500 Major British and World Authors | CD12: Philosophy | CE12: PHL 2040 Introduction to Political Philosophy | CI12: History | CJ12: HIS 1107 History of American Civilization, 1877-2000 | CN12: Communication Arts and Sciences | CO12: COM 3231 Intercultural Communication | CS12: BIO 3090 – 3099 Global Field Studies Program Courses
C13: =SUM(C8:C12) -> 18 | J13: =SUM(J8:J12) -> 16 | BC13: =#REF! -> #REF! | BD13: =#REF! -> #REF! | BE13: =H33 -> EEN 3220 | BF13: =J33 -> 4 | CA13: English | CB13: ENG 1550 Major American Authors | CD13: Philosophy | CE13: PHL 2050 Ethics in the Professions | CI13: History | CJ13: HIS 1119 History of Western Civilization I | CN13: Economics | CO13: ECO 1201 Introduction to Economics | CS13: CEN 4060 Geology
CA14: English | CB14: ENG 2050W Introduction to Literary Studies | CD14: Philosophy | CE14: PHL 2060 Biomedical Ethics | CI14: History | CJ14: HIS 1120 History of Western Civilization II | CN14: Economics | CO14: ECO 1202 Topics in Introductory Economics | CS14: CSC 1610 Computer Science I
F15: SOPHOMORE YEAR | O15: INSTRUCTIONS FOR USE | BC15: =B33 -> VLSI Design | BD15: =C33 -> 4 | BE15: =I34 -> Linear Signals and Systems | BF15: =J34 -> 4 | CA15: English | CB15: ENG 2200 Introduction to Poetry | CD15: Philosophy | CE15: PHL 2070 Environmental Ethics | CI15: History | CJ15: HIS 2329 American Social History | CN15: Economics | CO15: ECO 1203 Principles of Economics – Micro | CS15: HSC 1104 Introduction to Human Disease
A16: EEN 2130 | B16: Circuit Theory I | C16: 4 | H16: EEN 2140 | I16: Circuit Theory II | J16: 4 | O16: 1. Enter a 1 into the boxes outlined in green beside courses that you have completed successfully | BE16: =I35 -> Eng. Electromagnetics II | BF16: =J35 -> 2 | CA16: English | CB16: ENG 2300 Detective Fiction | CD16: Philosophy | CE16: PHL 2080 Approaches to Ethics | CI16: History | CJ16: HIS 2340 History of Latin America (D) | CN16: Economics | CO16: ECO 1204 Principles of Economics – Macro | CS16: HSC 1106 Human Biology
A17: PHY 2211 | B17: Physics I | C17: 4 | H17: PHY 2212 | I17: Physics II | J17: 4 | BE17: =H36 -> EEN 4970 | BF17: =J36 -> 2 | CA17: English | CB17: ENG 2740 Politics in Literature | CD17: Philosophy | CE17: PHL 2090 Values in a Technological Culture | CI17: History | CJ17: HIS 3350 Ancient History | CN17: Economics | CO17: ECO 1225 Economics of Gender | CS17: HSC 1122 Anatomy and Physiology I
A18: MTH 2219 | B18: Calculus III | C18: 4 | H18: EEN 2270 | I18: Embedded Microprocessors | J18: 4 | O18: 2. Now you're ready to begin planning the upcoming semester. Enter a 1 into the green boxes beside courses in which you would like to enroll next semester. | CA18: English | CB18: ENG 2750 Adapting the Graphic Novel to Film | CD18: Philosophy | CE18: PHL 2100 Women, Ethics and Society (D) | CI18: History | CJ18: HIS 3360 Medieval Civilization | CN18: Economics | CO18: ECO 2201 Intermediate Micro-Economics | CS18: HSC 2300 Nutrition, Diet and Health
A19: EEN 2250 | B19: Assembly for EEN | C19: 2 | H19: Ethics (E) | I19: Elective (course here) | J19: 4 | CA19: English | CB19: ENG 2770 Literature and Film | CD19: Philosophy | CE19: PHL 2310 Socrates and the Examined Life | CI19: History | CJ19: HIS 3370 Renaissance and Reformation | CN19: Economics | CO19: ECO 2202 Intermediate Macro-Economics | CS19: HSC 3302 Community Public Health
A20: Arts & Lit (AL) | B20: Elective (course here) | C20: 4 | CA20: English | CB20: ENG 3020 A History of the English Language | CD20: Philosophy | CE20: PHL 2500 Theories of Justice | CI20: History | CJ20: HIS 3376 Era of the French Revolution | CN20: Economics | CO20: ECO 3303 Economic Development
CA21: English | CB21: ENG 3100 Beowulf and Old English Literature | CD21: Philosophy | CE21: PHL 3020 Philosophy of Law | CI21: History | CJ21: HIS 3378 History of Modern Britain | CN21: Economics | CO21: ECO 3304 Economics of Education
C22: =SUM(C16:C21) -> 18 | J22: =SUM(J16:J20) -> 16 | CA22: English | CB22: ENG 3140 Chaucer and Middle English Literature | CD22: Philosophy | CE22: PHL 3030 Global Justice | CI22: History | CJ22: HIS 3380 History of Modern Technology | CN22: Economics | CO22: ECO 3305 Ecological Economics
CA23: English | CB23: ENG 3200 Renaissance Literature | CD23: Philosophy | CE23: PHL 3180 Existentialism | CI23: History | CJ23: HIS 3390 Modern European Social History | CN23: Economics | CO23: ECO 3306 International Economics
F24: JUNIOR YEAR
A25: EEN 3430 | B25: Eng. Electromagnetics I | C25: 4
A26: MTH 2220 | B26: Differential Equations | C26: 4 | I26: CO-OP Semester | O26: THIS REFLECTS CURRICULUM FROM AY 2012.
A27: EEN 3210 | B27: Electronics I | C27: 4 | O27: EE FACULTY MUST DETERMINE NEW CO-OP SCHEDULE WITH THE REVISED CURRICULUM
A28: RTS 1001 | B28: Intro to Religious Studies | C28: 4
C30: =C25+C26+C27+C28+J29 -> 16
F32: JUNIOR YEAR | CA32: English | CB32: ENG 3220 Renaissance Drama | CD32: Religious and Theological Studies | CE32: RTS 2800 Christian Social Ethics (D) | CI32: History | CJ32: HIS 3391 Women in Modern European History (D) | CN32: Economics | CO32: ECO 3307 Labor Economics
A33: EEN 4750 | B33: VLSI Design | C33: 4 | H33: EEN 3220 | I33: Electronics II | J33: 4 | BC33: Marc | CA33: English | CB33: ENG 3250 Shakespearean Drama | CD33: Religious and Theological Studies | CE33: RTS 2900 Holocaust: Theology, Reality and Aftermath (D) | CI33: History | CJ33: HIS 3320 The American City | CN33: Economics | CO33: ECO 3308 Managerial Economics
A34: EEN | B34: Elective (course here) | C34: 4 | H34: EEN 3130 | I34: Linear Signals and Systems | J34: 4 | BC34: =BC9 -> EEN 2130 | BD34: =BD9 -> 4 | BE34: =BE8 -> EEN 2140 | BF34: =BF8+2+3 -> 9 | CA34: English | CB34: ENG 3280 Angels and Demons: Milton and the Culture of Revolution | CD34: Religious and Theological Studies | CE34: RTS 2950 Ethics in the Abrahamic Traditions | CI34: History | CJ34: HIS 3326 History of American Architecture | CN34: Economics | CO34: ECO 3309 Marxian Economics
A35: EEN | B35: Elective (course here) | C35: 4 | E35: Work with your advisor here. | H35: EEN 3440 | I35: Eng. Electromagnetics II | J35: 2 | BC35: =BC11 -> #REF! | BD35: =BD11 -> #REF! | CA35: English | CB35: ENG 3300 Restoration and Eighteenth-Century Literature | CD35: Religious and Theological Studies | CE35: RTS 3700 African-American Theology (D) | CI35: History | CJ35: HIS 3401 Topics in Nineteenth-Century Europe | CN35: Economics | CO35: ECO 3310 Money and Finance
A36: EEN 4960 | B36: Design Project I | C36: 2 | H36: EEN 4970 | I36: Design Project II | J36: 2 | BC36: =BC13 -> #REF! | BD36: =BD13 -> #REF! | CA36: English | CB36: ENG 3320 Eighteenth-Century Novel | CD36: Religious and Theological Studies | CE36: RTS 3710 Feminist Theology (D) | CI36: History | CJ36: HIS 3410 Twentieth-Century Europe | CN36: Economics | CO36: ECO 3311 Public Finance
A37: Soc. Science (SS) | B37: Elective (course here) | C37: 4 | H37: EEN 4370 | I37: Disruptive technologies | J37: 2 | CA37: English | CB37: ENG 3350 Sex, Race, and Empire: 1660-1814 | CD37: Religious and Theological Studies | CE37: RTS 3800 The Catholic Thing: Merton and Day | CI37: History | CJ37: HIS 3425 Contemporary United States History | CN37: Economics | CO37: ECO 3312 The History of Economic Thought
H38: Soc. Science (SS) | I38: Elective (course here) | J38: 4 | CA38: English | CB38: ENG 3400 British Romanticism | CD38: Religious and Theological Studies | CE38: RTS 3850 War and Peace: Religious Perspectives | CI38: History | CJ38: HIS 3434 Age of the American Revolution, 1763-1800 | CN38: Economics | CO38: ECO 3313 Topics in Quantitative Economics
C39: =C33+C34+C35+C36+C37 -> 18 | J39: =J38+J37+J36+J35+J34+J33 -> 18 | CA39: English | CB39: ENG 3420 American Romanticism | CI39: History | CJ39: HIS 3435 American Colonial History | CN39: Economics | CO39: ECO 3314 U.S. Economic History
CA40: English | CB40: ENG 3440 Victorian Literature | CI40: History | CJ40: HIS 3437 Civil War and Reconstruction | CN40: Economics | CO40: ECO 3315 Urban and Regional Economics
F41: SENIOR YEAR | BC41: Aaron | CA41: English | CB41: ENG 3470 Realism and Naturalism in America | CI41: History | CJ41: HIS 3439 Slavery and Race in the Early Modern Atlantic World, 1400-1800 | CN41: History | CO41: HIS 3376 Era of the French Revolution
H42: MTH 1505 | I42: Engineering Statistics | J42: 4 | BC42: =BC12 -> #REF! | BD42: =BD12+2+3 -> #REF! | BE42: =BE9 -> EEN 2270 | BF42: =BF9+2+3 -> 9 | CA42: English | CB42: ENG 3500 Modern British Literature | CI42: History | CJ42: HIS 3470 History of Imperial Russia | CN42: History | CO42: HIS 3380 History of Modern Technology
H43: EEN 4270 | I43: Feedback Circuits | J43: 4 | BC43: =BC15 -> VLSI Design | BD43: =BD15 -> 4 | CA43: English | CB43: ENG 3520 Modern Irish Literature | CI43: History | CJ43: HIS 3471 History of Twentieth-Century Russia | CN43: History | CO43: HIS 3390 Modern European Social History
...

Sheet Flowchart
H3: =CONCATENATE("BS in Civil Engineering",CHAR(10),"Class of 2012 Flowchart") -> BS in Civil Engineering Class of 2012 Flowchart | AA3: ='EE Curriculum'!A8 -> GEN 1001 | AB3: ='EE Curriculum'!B8 -> Intro. to Eng. | AC3: ='EE Curriculum'!C8 -> 4 | AD3: ='EE Curriculum'!D8 | AH3: ='EE Curriculum'!H8 -> EEN 1200 | AI3: ='EE Curriculum'!I8 -> Digital Fundamentals | AJ3: ='EE Curriculum'!J8 -> 4 | AK3: ='EE Curriculum'!K8
N4: Student Name: | O4: ='EE Curriculum'!B4 | AA4: ='EE Curriculum'!A9 -> MTH 1217 | AB4: ='EE Curriculum'!B9 -> Calculus I | AC4: ='EE Curriculum'!C9 -> 4 | AD4: ='EE Curriculum'!D9 | AH4: ='EE Curriculum'!H9 -> MTH 1218 | AI4: ='EE Curriculum'!I9 -> Calculus II | AJ4: ='EE Curriculum'!J9 -> 4 | AK4: ='EE Curriculum'!K9
AA5: ='EE Curriculum'!A10 -> PHL 1000 | AB5: ='EE Curriculum'!B10 -> Intro to Philosophy | AC5: ='EE Curriculum'!C10 -> 4 | AD5: ='EE Curriculum'!D10 -> 0 | AH5: ='EE Curriculum'!H10 -> CHM 1180 | AI5: ='EE Curriculum'!I10 -> Engineering Chemistry | AJ5: ='EE Curriculum'!J10 -> 4 | AK5: ='EE Curriculum'!K10
B6: =CONCATENATE('[1]CE Curriculum'!A8,CHAR(10),'[1]CE Curriculum'!B8) -> GEN 1001 Intro. to Eng. | D6: =CONCATENATE(AH5," ",AI5) -> CHM 1180 Engineering Chemistry | L6: =CONCATENATE(AA29," ",AB29) -> EEN 4750 VLSI Design | AA6: ='EE Curriculum'!A11 -> CSC 1610 | AB6: ='EE Curriculum'!B11 -> Computer Science I | AC6: ='EE Curriculum'!C11 -> 4 | AD6: ='EE Curriculum'!D11 | AH6: ='EE Curriculum'!H11 -> ENG 1050 | AI6: ='EE Curriculum'!I11 -> College Writing | AJ6: ='EE Curriculum'!J11 -> 4 | AK6: ='EE Curriculum'!K11
AA7: ='EE Curriculum'!A12 -> EEN 1100 | AB7: ='EE Curriculum'!B12 -> Analog Fundamentals | AC7: ='EE Curriculum'!C12 -> 2 | AD7: ='EE Curriculum'!D12
B8: =CONCATENATE(AA7," ",AB7) -> EEN 1100 Analog Fundamentals | D8: =CONCATENATE(AH3," ",AI3) -> EEN 1200 Digital Fundamentals | F8: =CONCATENATE(AA11," ",AB11) -> EEN 2130 Circuit Theory I | H8: =CONCATENATE(AH11," ",AI11) -> EEN 2140 Circuit Theory II | J8: =CONCATENATE(AA22," ",AB22) -> EEN 3210 Electronics I | L8: =CONCATENATE(AH22," ",AI22) -> EEN 3220 Electronics II
B10: =CONCATENATE(AA6," ",AB6) -> CSC 1610 Computer Science I | F10: =CONCATENATE(AA14," ",AB14) -> EEN 2250 Assembly for EEN | H10: =CONCATENATE(AH13," ",AI13,"*") -> EEN 2270 Embedded Microprocessors* | J10: =CONCATENATE(AH21," ",AI21) -> EEN 3130 Linear Signals and Systems | L10: =CONCATENATE(AH30," ",AI30) -> EEN 4270 Feedback Circuits | AF10: ='[1]CE Curriculum'!F15 -> SOPHOMORE YEAR
H11: *pre-requisites may be replaced with CSC 3720 | S11: mag factor | AA11: ='EE Curriculum'!A16 -> EEN 2130 | AB11: ='EE Curriculum'!B16 -> Circuit Theory I | AC11: ='EE Curriculum'!C16 -> 4 | AD11: ='EE Curriculum'!D16 | AH11: ='EE Curriculum'!H16 -> EEN 2140 | AI11: ='EE Curriculum'!I16 -> Circuit Theory II | AJ11: ='EE Curriculum'!J16 -> 4 | AK11: ='EE Curriculum'!K16
B12: =CONCATENATE(AA4,CHAR(10),AB4) -> MTH 1217 Calculus I | D12: =CONCATENATE(AH4,CHAR(10),AI4) -> MTH 1218 Calculus II | F12: =CONCATENATE(AA13,CHAR(10),AB13) -> MTH 2219 Calculus III | H12: =CONCATENATE(AA21,CHAR(13),AB21) -> MTH 2220_x000D_Differential Equations | J12: =CONCATENATE(AA32," ",AB32) -> EEN 4960 Design Project I | L12: =CONCATENATE(AH32," ",AI32) -> EEN 4970 Design Project II | S12: 1.63 | T12: Want | AA12: ='EE Curriculum'!A17 -> PHY 2211 | AB12: ='EE Curriculum'!B17 -> Physics I | AC12: ='EE Curriculum'!C17 -> 4 | AD12: ='EE Curriculum'!D17 | AH12: ='EE Curriculum'!H17 -> PHY 2212 | AI12: ='EE Curriculum'!I17 -> Physics II | AJ12: ='EE Curriculum'!J17 -> 4 | AK12: ='EE Curriculum'!K17
R13: 19.79 | S13: =R13*S12 -> 32.2577 | T13: 36 | AA13: ='EE Curriculum'!A18 -> MTH 2219 | AB13: ='EE Curriculum'!B18 -> Calculus III | AC13: ='EE Curriculum'!C18 -> 4 | AD13: ='EE Curriculum'!D18 | AH13: ='EE Curriculum'!H18 -> EEN 2270 | AI13: ='EE Curriculum'!I18 -> Embedded Microprocessors | AJ13: ='EE Curriculum'!J18 -> 4 | AK13: ='EE Curriculum'!K18
H14: =CONCATENATE(AA20," ",AB20) -> EEN 3430 Eng. Electromagnetics I | J14: =CONCATENATE(AH20," ",AI20) -> EEN 3270 Energy Gen., Cons., and Tech | K14: Jr. Standing | R14: 14.75 | S14: =R14*S12 -> 24.0425 | T14: 24 | AA14: ='EE Curriculum'!A19 -> EEN 2250 | AB14: ='EE Curriculum'!B19 -> Assembly for EEN | AC14: ='EE Curriculum'!C19 -> 2 | AD14: ='EE Curriculum'!D19 | AH14: ='EE Curriculum'!H19 -> Ethics (E) | AI14: ='EE Curriculum'!I19 -> Elective (course here) | AJ14: ='EE Curriculum'!J19 -> 4 | AK14: ='EE Curriculum'!K19 -> 0
AA15: ='EE Curriculum'!A20 -> Arts & Lit (AL) | AB15: ='EE Curriculum'!B20 -> Elective (course here) | AC15: ='EE Curriculum'!C20 -> 4 | AD15: ='EE Curriculum'!D20 -> 0
F16: =CONCATENATE(AA12,CHAR(10),AB12) -> PHY 2211 Physics I | H16: =CONCATENATE(AH12,CHAR(10),AI12) -> PHY 2212 Physics II | J16: =CONCATENATE(AA30," ",AB30) -> EEN Elective (course here) | K16: see prerequisites | L16: =CONCATENATE(AH31," ",AI31) -> EEN Elective (course here)
B18: =CONCATENATE(AH6," ",AI6) -> ENG 1050 College Writing | J18: =CONCATENATE(AA31," ",AB31) -> #REF! | K18: see prerequisites
AF19: ='[1]CE Curriculum'!F24 -> JUNIOR YEAR
B20: =CONCATENATE(AA23," ",AB23) -> RTS 1001 Christianity in Context | D20: =CONCATENATE(AH14," ",AI14) -> Ethics (E) Elective (course here) | AA20: ='EE Curriculum'!H25 -> EEN 3430 | AB20: ='EE Curriculum'!I25 -> Eng. Electromagnetics I | AC20: ='EE Curriculum'!J25 -> 4 | AD20: ='EE Curriculum'!K25 | AH20: ='EE Curriculum'!A25 -> EEN 3270 | AI20: ='EE Curriculum'!B25 -> Energy Gen., Cons., and Tech | AJ20: ='EE Curriculum'!C25 -> 4 | AK20: ='EE Curriculum'!D25 -> 0
AA21: ='EE Curriculum'!A26 -> MTH 2220 | AB21: ='EE Curriculum'!B26 -> Differential Equations | AC21: ='EE Curriculum'!C26 -> 4 | AD21: ='EE Curriculum'!D26 | AH21: ='EE Curriculum'!A36 -> EEN 3130 | AI21: ='EE Curriculum'!B36 -> Linear Signals and Systems | AJ21: ='EE Curriculum'!C36 -> 4 | AK21: ='EE Curriculum'!D36 -> 0
B22: =CONCATENATE(AA5," ",AB5) -> PHL 1000 Intro to Philosophy | AA22: ='EE Curriculum'!A27 -> EEN 3210 | AB22: ='EE Curriculum'!B27 -> Electronics I | AC22: ='EE Curriculum'!C27 -> 4 | AD22: ='EE Curriculum'!D27 | AH22: ='EE Curriculum'!H26 -> EEN 3220 | AI22: ='EE Curriculum'!I26 -> Electronics II | AJ22: ='EE Curriculum'!J26 -> 4 | AK22: ='EE Curriculum'!K26 -> 0
AA23: ='EE Curriculum'!A28 -> RTS 1001 | AB23: ='EE Curriculum'!B28 -> Christianity in Context | AC23: ='EE Curriculum'!C28 -> 4 | AD23: ='EE Curriculum'!D28 | AH23: ='EE Curriculum'!H27 -> Hist. Studies (H) | AI23: ='EE Curriculum'!I27 -> Elective (course here) | AJ23: ='EE Curriculum'!J27 -> 4 | AK23: ='EE Curriculum'!K27 -> 0
B24: =CONCATENATE(AA33," ",AB33) -> Soc. Science (SS) PSY 1000 Introduction to Psychology
B26: =CONCATENATE(AA15," ",AB15) -> Arts & Lit (AL) Elective (course here) | J26: Key
J27: Pre-requisite:
B28: =CONCATENATE(AH33," ",AI33) -> Soc. Science (SS) POL 1000 Current Issues in Politics and Government | J28: Co-requisite | AF28: ='[1]CE Curriculum'!F33 -> SENIOR YEAR
AA29: ='EE Curriculum'!A34 -> EEN 4750 | AB29: ='EE Curriculum'!B34 -> VLSI Design | AC29: ='EE Curriculum'!C34 -> 4 | AD29: ='EE Curriculum'!D34 -> 0 | AH29: ='EE Curriculum'!H34 -> MTH 1505 | AI29: ='EE Curriculum'!I34 -> Engineering Statistics | AJ29: ='EE Curriculum'!J34 -> 4 | AK29: ='EE Curriculum'!K34 -> 0
B30: =CONCATENATE(AH23," ",AI23) -> Hist. Studies (H) Elective (course here) | AA30: ='EE Curriculum'!A35 -> EEN | AB30: ='EE Curriculum'!B35 -> Elective (course here) | AC30: ='EE Curriculum'!C35 -> 4 | AD30: ='EE Curriculum'!D35 -> 0 | AH30: ='EE Curriculum'!H35 -> EEN 4270 | AI30: ='EE Curriculum'!I35 -> Feedback Circuits | AJ30: ='EE Curriculum'!J35 -> 4 | AK30: ='EE Curriculum'!K35 -> 0
H31: Our mission is to prepare outstanding electrical engineers! | AA31: ='EE Curriculum'!#REF! -> #REF! | AB31: ='EE Curriculum'!#REF! -> #REF! | AC31: ='EE Curriculum'!#REF! -> #REF! | AD31: ='EE Curriculum'!#REF! -> #REF! | AH31: ='EE Curriculum'!H36 -> EEN | AI31: ='EE Curriculum'!I36 -> Elective (course here) | AJ31: ='EE Curriculum'!J36 -> 4 | AK31: ='EE Curriculum'!K36 -> 0
AA32: ='EE Curriculum'!A37 -> EEN 4960 | AB32: ='EE Curriculum'!B37 -> Design Project I | AC32: ='EE Curriculum'!C37 -> 2 | AD32: ='EE Curriculum'!D37 -> 0 | AH32: ='EE Curriculum'!H37 -> EEN 4970 | AI32: ='EE Curriculum'!I37 -> Design Project II | AJ32: ='EE Curriculum'!J37 -> 2 | AK32: ='EE Curriculum'!K37 -> 0
AA33: ='EE Curriculum'!A38 -> Soc. Science (SS) | AB33: ='EE Curriculum'!B38 -> PSY 1000 Introduction to Psychology | AC33: ='EE Curriculum'!C38 -> 4 | AD33: ='EE Curriculum'!D38 | AH33: ='EE Curriculum'!H38 -> Soc. Science (SS) | AI33: ='EE Curriculum'!I38 -> POL 1000 Current Issues in Politics and Government | AJ33: ='EE Curriculum'!J38 -> 4 | AK33: ='EE Curriculum'!K38

Sheet Summary Checklist
E3: Credits | F3: Credits
D4: Science and Math Topics | E4: Required | F4: Taken
D5: ='EE Curriculum'!A9 -> MTH 1217 | E5: ='EE Curriculum'!C9 -> 4 | F5: ='EE Curriculum'!D9*E5 -> #VALUE!
D6: ='EE Curriculum'!H9 -> MTH 1218 | E6: ='EE Curriculum'!J9 -> 4 | F6: ='EE Curriculum'!K9*E6 -> #VALUE!
D7: ='EE Curriculum'!A18 -> MTH 2219 | E7: ='EE Curriculum'!C18 -> 4 | F7: ='EE Curriculum'!D18*E7 -> #VALUE!
D8: ='EE Curriculum'!A26 -> MTH 2220 | E8: ='EE Curriculum'!C26 -> 4 | F8: ='EE Curriculum'!D26*E8 -> #VALUE!
D9: ='EE Curriculum'!H34 -> MTH 1505 | E9: ='EE Curriculum'!J34 -> 4 | F9: ='EE Curriculum'!K34*E9 -> 0
D10: TOTAL MATH | E10: =SUM(E5:E9) -> 20 | F10: =SUM(F5:F9) -> #VALUE!
D11: ='EE Curriculum'!A11 -> CSC 1610 | E11: ='EE Curriculum'!C11 -> 4 | F11: ='EE Curriculum'!D11*E11 -> #VALUE!
D12: ='EE Curriculum'!H10 -> CHM 1180 | E12: ='EE Curriculum'!J10 -> 4 | F12: ='EE Curriculum'!K10*E12 -> #VALUE!
D13: ='EE Curriculum'!A17 -> PHY 2211 | E13: ='EE Curriculum'!C17 -> 4 | F13: ='EE Curriculum'!D17*E13 -> #VALUE!
D14: ='EE Curriculum'!H17 -> PHY 2212 | E14: ='EE Curriculum'!J17 -> 4 | F14: ='EE Curriculum'!K17*E14 -> #VALUE!
D16: TOTAL SCIENCE | E16: =SUM(E11:E14) -> 16 | F16: =SUM(F11:F14) -> #VALUE!
D17: TOTAL MATH and SCIENCE | E17: =E10+E16 -> 36 | F17: =F10+F16 -> #VALUE!
D19: Engineering Topics
D20: ='EE Curriculum'!A8 -> GEN 1001 | E20: ='EE Curriculum'!C8 -> 4 | F20: ='EE Curriculum'!D8*E20 -> #VALUE!
D21: ='EE Curriculum'!A12 -> EEN 1100 | E21: ='EE Curriculum'!C12 -> 2 | F21: ='EE Curriculum'!D12*E21 -> #VALUE!
D22: ='EE Curriculum'!H8 -> EEN 1200 | E22: ='EE Curriculum'!J8 -> 4 | F22: ='EE Curriculum'!K8*E22 -> #VALUE!
D23: ='EE Curriculum'!A16 -> EEN 2130 | E23: ='EE Curriculum'!C16 -> 4 | F23: ='EE Curriculum'!D16*E23 -> #VALUE!
D24: ='EE Curriculum'!A19 -> EEN 2250 | E24: ='EE Curriculum'!C19 -> 2 | F24: ='EE Curriculum'!D19*E24 -> #VALUE!
D25: ='EE Curriculum'!H16 -> EEN 2140 | E25: ='EE Curriculum'!J16 -> 4 | F25: ='EE Curriculum'!K16*E25 -> #VALUE!
D26: ='EE Curriculum'!H18 -> EEN 2270 | E26: ='EE Curriculum'!J18 -> 4 | F26: ='EE Curriculum'!K18*E26 -> #VALUE!
D27: ='EE Curriculum'!H25 -> EEN 3430 | E27: ='EE Curriculum'!J25 -> 4 | F27: ='EE Curriculum'!K25*E27 -> #VALUE!
D28: ='EE Curriculum'!A27 -> EEN 3210 | E28: ='EE Curriculum'!C27 -> 4 | F28: ='EE Curriculum'!D27*E28 -> #VALUE!
D29: ='EE Curriculum'!A25 -> EEN 3270 | E29: ='EE Curriculum'!C25 -> 4 | F29: ='EE Curriculum'!D25*E29 -> 0
D30: ='EE Curriculum'!A36 -> EEN 3130 | E30: ='EE Curriculum'!C36 -> 4 | F30: ='EE Curriculum'!D36*E30 -> 0
D31: ='EE Curriculum'!H26 -> EEN 3220 | E31: ='EE Curriculum'!J26 -> 4 | F31: ='EE Curriculum'!K26*E31 -> 0
D32: =CONCATENATE('EE Curriculum'!A35," ",'EE Curriculum'!B35) -> EEN Elective (course here) | E32: ='EE Curriculum'!C35 -> 4 | F32: ='EE Curriculum'!D35*E32 -> 0
D34: =CONCATENATE('EE Curriculum'!H36," ",'EE Curriculum'!I36) -> EEN Elective (course here) | E34: ='EE Curriculum'!J36 -> 4 | F34: ='EE Curriculum'!K36*E34 -> 0
D35: ='EE Curriculum'!A34 -> EEN 4750 | E35: ='EE Curriculum'!C34 -> 4 | F35: ='EE Curriculum'!D34*E35 -> 0
D36: ='EE Curriculum'!H35 -> EEN 4270 | E36: ='EE Curriculum'!J35 -> 4 | F36: ='EE Curriculum'!K35*E36 -> 0
D37: ='EE Curriculum'!A37 -> EEN 4960 | E37: ='EE Curriculum'!C37 -> 2 | F37: ='EE Curriculum'!D37*E37 -> 0
D38: ='EE Curriculum'!H37 -> EEN 4970 | E38: ='EE Curriculum'!J37 -> 2 | F38: ='EE Curriculum'!K37*E38 -> 0
D39: TOTAL ENGINEERING | E39: =SUM(E20:E38) -> 64 | F39: =SUM(F20:F38) -> #VALUE!
D41: LS CORE
D42: Foundations
D43: 1. ENG 1050 | E43: 4 | F43: ='EE Curriculum'!K11*E43 -> #VALUE!
D44: 2. PHL 1000 | E44: 4 | F44: ='EE Curriculum'!D10*E44 -> 0
D45: 3. Quantitative Reasoning (Q) | F45: MTH 1217
D46: 4. Ethics (E) | E46: 4 | F46: ='EE Curriculum'!K19*E46 -> 0
...
