Workbook

Sheet Worksheet Instructions
B2: Charter School Funding -- Inequity Persists
B3: May 2010
B5: Supporting Excel Spreadsheet
B6: Worksheet Legend and Instructions
B7: South Carolina
B9: Data Source:
B10: District revenue data (inclusive of inseparable charter school revenue data) was downloaded from the South Carolina Department of Education (SCDE) FTP site – the download file name: “07-distrev.xls.” This file contains sufficient revenue account coding to identify sources of revenues. Charter school revenue data was not available from SCDE. Charter school revenue data was obtained from audited Annual Financial Reports, which were downloaded from school district web sites (these are also available in paper at SCDE). Charter revenue data were subtracted from the “district” revenue data to arrive at comparable revenue data for district schools and charter schools. A “district” enrollment file was also downloaded – this file included inseparable district school and charter school enrollment. SCDE also provided an enrollment file just for charter schools. The charter school enrollments were subtracted from the “district” enrollment file in order to obtain separate district and charter school enrollment counts. Charter school revenue data could not be obtained for some charter schools, representing 24.8 percent of the total population of charter school students. An estimate was made of total statewide charter school revenues by taking the actual per pupil revenue amount from charter schools representing 76.2 percent of charter students, and applying that per pupil amount to the 24.8 percent of students with no associated revenue data, then adding the actual and extrapolated amounts together. The Meyer Center for Special Children, a Greenville charter school, was eliminated from the Greenville and statewide presentation of this analysis because it would distort the analysis. The Meyer Center, established in 1954, receives 83.4 percent of its funding through private contributions and donations, and has a per pupil revenue amount of $410,250.
B12: Disclaimer:
B13: This is a "read only" file containing data collections from the South Carolina Department of Education. The conclusions reached in this document are those of the author(s) and do not necessarily represent those of Ball State University.
B15: File Management:
B16: This is a "Final (Read-Only)" Excel file. This means you will not be able to edit this file, but you can copy whole worksheets, paste them into a new file (workbook), and then save that file under a different name. No "Protection" has been set for this file.
B18: Cautions:
B19: This spreadsheet was designed for use by the author/researcher, not for third-party use. Some of the data in this spreadsheet may be useful to third-parties, but any interpretations or additional analysis by third-parties is done so at their own risk.

Sheet Template
A1: Figure 1 | I1: Figure 2 | S1: TEMPLATE
A2: South Carolina 2006-2007 | B2: Statewide | D2: Greenville | F2: N/A
A3: Per-Pupil Revenue
A4: District | B4: =B22/B16 -> 10164.628 | D4: =D22/D16 -> 9331.7805
A5: Charter | B5: =C24/B18 -> 8396.0204 | D5: =D24/D18 -> 7464.5999
A6: Difference | B6: =B4-B5 -> 1768.6078 | D6: =D4-D5 -> 1867.1805
B7: =B6/B4 -> 0.17399631 | D7: =D6/D4 -> 0.20008835
A8: Per-Pupil Revenue by Source | B8: District | C8: Charter | D8: District | E8: Charter (3) | R8: PROOF
A9: Federal | B9: ='4-Districts Less Charters'!DI229/B16 -> 1014.4325 | C9: N/A (1) | D9: ='4-Districts Less Charters'!AY232/D16 -> 796.18153 | E9: ='5-Charters'!H101/D18 -> 918.71353 | R9: =SUM(B9:G9) -> 2729.3275
A10: State | B10: ='4-Districts Less Charters'!DI187/B16 -> 4295.0403 | C10: N/A (1) | D10: ='4-Districts Less Charters'!AY190/D16 -> 4078.1773 | E10: ='5-Charters'!H100/D18 -> 6025.4518 | R10: =SUM(B10:G10) -> 14398.669
A11: Local | B11: ='4-Districts Less Charters'!DI16/B16 -> 3922.8877 | C11: N/A (1) | D11: ='4-Districts Less Charters'!AY19/D16 -> 3430.5143 | E11: ='5-Charters'!H99/D18 -> 0 | R11: =SUM(B11:G11) -> 7353.4021
A12: Other | B12: ='4-Districts Less Charters'!DI58/B16 -> 932.26766 | C12: N/A (1) | D12: ='4-Districts Less Charters'!AY61/D16 -> 1026.9073 | E12: ='5-Charters'!H102/D18 -> 520.43464 | R12: =SUM(B12:G12) -> 2479.6096
A13: Indeterminate | B13: 0 | C13: N/A (1) | D13: ='4-Districts Less Charters'!AY235/D16 -> 0 | E13: 0 | R13: =SUM(B13:G13) -> 0
A14: Total | B14: =SUM(B9:B13) -> 10164.628 | C14: Est'd.(2) $8,396 | D14: =SUM(D9:D13) -> 9331.7805 | E14: =SUM(E9:E13) -> 7464.5999
A15: Enrollment
A16: District | B16: ='6-Enrollment'!P104 -> 676773.43 | D16: ='6-Enrollment'!R47 -> 65411.5
B17: =B16/(B16+B18) -> 0.99266054 | D17: =D16/(D16+D18) -> 0.98770851 | J17: District | K17: Charter | L17: Difference
A18: Charter | B18: ='5-Charters'!M34 -> 5003.88 | D18: ='5-Charters'!B98 -> 814.01 | I18: South Carolina | J18: =B4 -> 10164.628 | K18: =B5 -> 8396.0204 | L18: =B6 -> 1768.6078
B19: =B18/(B16+B18) -> 0.007339464 | D19: =D18/(D16+D18) -> 0.012291487 | I19: Greenville | J19: =D4 -> 9331.7805 | K19: =D5 -> 7464.5999 | L19: =D6 -> 1867.1805
A20: Number of Charters | B20: ='5-Charters'!L34 -> 28 | D20: 6
A21: Total Revenue
A22: District | B22: ='4-Districts Less Charters'!DI237 -> 6.8791503e+09 | D22: ='4-Districts Less Charters'!AY240 -> 610405757
B23: =B22/B26 -> 0.99392982 | D23: =D22/D26 -> 0.99014366
A24: Charter | B24: Est'd.(2) | C24: ='5-Charters'!Q34 -> 42012678 | D24: ='5-Charters'!I104 -> 6076259
B25: =C24/B26 -> 0.0060701762 | D25: =D24/D26 -> 0.0098563443
A26: Total | B26: =C24+B22 -> 6921162935 | D26: =D24+D22 -> 616482016
A27: Percentage of Revenue by Source | B27: District | C27: Charter | D27: District | E27: Charter | I27: Figure 4
A28: Federal | B28: =B9/B$14 -> 0.099800253 | C28: N/A (1) | D28: =D9/D$14 -> 0.085319359 | E28: =E9/E$14 -> 0.12307606
A29: State | B29: =B10/B$14 -> 0.4225477 | C29: N/A (1) | D29: =D10/D$14 -> 0.43702028 | E29: =E10/E$14 -> 0.80720358
A30: Local | B30: =B11/B$14 -> 0.38593519 | C30: N/A (1) | D30: =D11/D$14 -> 0.36761627 | E30: =E11/E$14 -> 0
A31: Other | B31: =B12/B$14 -> 0.091716848 | C31: N/A (1) | D31: =D12/D$14 -> 0.11004409 | E31: =E12/E$14 -> 0.069720366
A32: Indeterminate | B32: =B13/B$14 -> 0 | C32: N/A (1) | D32: =D13/D$14 -> 0 | E32: =E13/E$14 -> 0
A33: Change in district school funding if subjected to charter funding structure
B34: =B6*B16 -> 1.1969468e+09 | D34: =D6*D16 -> 1.2213508e+08
A36: PROOF | B36: =SUM(B28:B32) -> 1 | C36: =SUM(C28:C32) -> 0 | D36: =SUM(D28:D32) -> 1 | E36: =SUM(E28:E32) -> 1 | F36: =SUM(F28:F32) -> 0 | G36: =SUM(G28:G32) -> 0
A38: See other NOTES on tab #5-Charters.
J56: Federal | K56: State | L56: Local | M56: Other | N56: Indeterminate | R56: PROOF
I57: Statewide-District | J57: =B9 -> 1014.4325 | K57: =B10 -> 4295.0403 | L57: =B11 -> 3922.8877 | M57: =B12 -> 932.26766 | N57: =B13 -> 0 | R57: =SUM(J57:O57) -> 10164.628
I58: Statewide-Charter | J58: =C9 -> N/A (1) | K58: =C10 -> N/A (1) | L58: =C11 -> N/A (1) | M58: =C12 -> N/A (1) | N58: =C13 -> N/A (1) | R58: =SUM(J58:O58) -> 0
I59: Greenville District | J59: =D9 -> 796.18153 | K59: =D10 -> 4078.1773 | L59: =D11 -> 3430.5143 | M59: =D12 -> 1026.9073 | N59: =D13 -> 0 | R59: =SUM(J59:O59) -> 9331.7805
...

Sheet Figures 1,2,4-Weighted
A1: Figure 1 | K1: Figure 2 | U1: TEMPLATE
A2: South Carolina 2006-2007 | B2: Statewide | D2: Statewide Weighted for Charter Enrollment | F2: Greenville | H2: N/A
A3: Per-Pupil Revenue
A4: District | B4: =B22/B16 -> 10164.628 | D4: 10104 | F4: =F22/F16 -> 9331.7805
A5: Charter | B5: =42012678.339/B18 -> 8396.0204 | D5: 8396 | F5: =F24/F18 -> 7464.5999
A6: Difference | B6: =B4-B5 -> 1768.6078 | D6: 1708 | F6: =F4-F5 -> 1867.1805
B7: =B6/B4 -> 0.17399631 | D7: 0.169 | F7: =F6/F4 -> 0.20008835
A8: Per-Pupil Revenue by Source | B8: District | C8: Charter | D8: District | E8: Charter | F8: District | G8: Charter (3) | T8: PROOF
A9: Federal | B9: ='[2]4-Districts Less Charters'!DI229/B16 -> 1014.4325 | C9: * | D9: 998 | E9: =C9 -> * | F9: ='[2]4-Districts Less Charters'!AY232/F16 -> 796.18153 | G9: ='[2]5-Charters'!H101/F18 -> 918.71353 | T9: =SUM(B9:I9) -> 3727.3275
A10: State | B10: ='[2]4-Districts Less Charters'!DI187/B16 -> 4295.0403 | C10: * | D10: 4279 | E10: =C10 -> * | F10: ='[2]4-Districts Less Charters'!AY190/F16 -> 4078.1773 | G10: ='[2]5-Charters'!H100/F18 -> 6025.4518 | T10: =SUM(B10:I10) -> 18677.669
A11: Local | B11: ='[2]4-Districts Less Charters'!DI16/B16 -> 3922.8877 | C11: * | D11: 3887 | E11: =C11 -> * | F11: ='[2]4-Districts Less Charters'!AY19/F16 -> 3430.5143 | G11: ='[2]5-Charters'!H99/F18 -> 0 | T11: =SUM(B11:I11) -> 11240.402
A12: Other | B12: ='[2]4-Districts Less Charters'!DI58/B16 -> 932.26766 | C12: * | D12: 939 | E12: =C12 -> * | F12: ='[2]4-Districts Less Charters'!AY61/F16 -> 1026.9073 | G12: ='[2]5-Charters'!H102/F18 -> 520.43464 | T12: =SUM(B12:I12) -> 3418.6096
A13: Indeterminate | B13: 0 | C13: * | D13: 0 | E13: =C13 -> * | F13: ='[2]4-Districts Less Charters'!AY235/F16 -> 0 | G13: 0 | T13: =SUM(B13:I13) -> 0
A14: Total | B14: =SUM(B9:B13) -> 10164.628 | C14: $8,396** | D14: =D4 -> 10104 | E14: =C14 -> $8,396** | F14: =SUM(F9:F13) -> 9331.7805 | G14: =SUM(G9:G13) -> 7464.5999
A15: Enrollment
A16: District | B16: ='[2]6-Enrollment'!P104 -> 676773.43 | D16: n/a | F16: ='[2]6-Enrollment'!R47 -> 65411.5
B17: =B16/(B16+B18) -> 0.99266054 | D17: n/a | F17: =F16/(F16+F18) -> 0.98770851 | L17: District | M17: Charter | N17: Difference
A18: Charter | B18: ='[2]5-Charters'!M34 -> 5003.88 | D18: n/a | F18: ='[2]5-Charters'!B98 -> 814.01 | K18: South Carolina | L18: =B4 -> 10164.628 | M18: =B5 -> 8396.0204 | N18: =B6 -> 1768.6078
B19: =B18/(B16+B18) -> 0.007339464 | D19: n/a | F19: =F18/(F16+F18) -> 0.012291487 | K19: South Carolina Weighted | L19: =D4 -> 10104 | M19: =D5 -> 8396 | N19: =D6 -> 1708
A20: Number of Charters | B20: ='[2]5-Charters'!L34 -> 28 | D20: n/a | F20: 6 | K20: Greenville | L20: =F4 -> 9331.7805 | M20: =F5 -> 7464.5999 | N20: =F6 -> 1867.1805
A21: Total Revenue
A22: District | B22: ='[2]4-Districts Less Charters'!DI237 -> 6.8791503e+09 | D22: n/a | F22: ='[2]4-Districts Less Charters'!AY240 -> 610405757
B23: =B22/B26 -> 0.99392982 | D23: n/a | F23: =F22/F26 -> 0.99014366
A24: Charter | B24: $ | C24: 42,012,678** | D24: n/a | F24: ='[2]5-Charters'!I104 -> 6076259
B25: =42012678.339/B26 -> 0.0060701762 | D25: n/a | F25: =F24/F26 -> 0.0098563443
A26: Total | B26: 6921162935 | D26: n/a | F26: =F24+F22 -> 616482016
A27: Percentage of Revenue by Source | B27: District | C27: Charter | D27: District | E27: Charter | F27: District | G27: Charter | K27: Figure 4
A28: Federal | B28: =B9/B$14 -> 0.099800253 | C28: * | D28: =D9/$D$14 -> 0.098772763 | E28: =C28 -> * | F28: =F9/F$14 -> 0.085319359 | G28: =G9/G$14 -> 0.12307606
A29: State | B29: =B10/B$14 -> 0.4225477 | C29: * | D29: =D10/$D$14 -> 0.42349565 | E29: =C29 -> * | F29: =F10/F$14 -> 0.43702028 | G29: =G10/G$14 -> 0.80720358
A30: Local | B30: =B11/B$14 -> 0.38593519 | C30: * | D30: =D11/$D$14 -> 0.38469913 | E30: =C30 -> * | F30: =F11/F$14 -> 0.36761627 | G30: =G11/G$14 -> 0
A31: Other | B31: =B12/B$14 -> 0.091716848 | C31: * | D31: =D12/$D$14 -> 0.092933492 | E31: =C31 -> * | F31: =F12/F$14 -> 0.11004409 | G31: =G12/G$14 -> 0.069720366
A32: Indeterminate | B32: =B13/B$14 -> 0 | C32: * | D32: =D13/$D$14 -> 0 | E32: =C32 -> * | F32: =F13/F$14 -> 0 | G32: =G13/G$14 -> 0
A33: Change in district school funding if subjected to charter funding structure
B34: ($1.2 billion) | F34: ($122.1 million)
A36: 42012678 | B36: =(B$16*B$5)-B$22 -> -1.1969468e+09 | F36: =(F$16*F$5)-F$22 -> -1.2213508e+08 | H36: =SUM(H28:H32) -> 0 | I36: =SUM(I28:I32) -> 0
A37: PROOF | B37: =SUM(B28:B32) -> 1 | C37: =SUM(C28:C32) -> 0 | F37: =SUM(F28:F32) -> 1 | G37: =SUM(G28:G32) -> 1
A38: See other NOTES on tab #5-Charters.
L60: Federal | M60: State | N60: Local | O60: Other | P60: Indeterminate | T60: PROOF
K61: Statewide District | L61: =B9 -> 1014.4325 | M61: =B10 -> 4295.0403 | N61: =B11 -> 3922.8877 | O61: =B12 -> 932.26766 | P61: =B13 -> 0 | T61: =SUM(L61:Q61) -> 10164.628
K62: Statewide Weighted | L62: =D9 -> 998 | M62: =D10 -> 4279 | N62: =D11 -> 3887 | O62: =D12 -> 939 | P62: =D13 -> 0
...

Sheet Report Figures 1,3,5,6
B3: Figure 1
B4: South Carolina (2006-07) | C4: Statewide | E4: Statewide Weighted for Charter Enrollment | G4: Greenville
B5: Per-Pupil Revenue
B6: District | C6: 10164.628 | E6: 10104 | G6: 9331.7805
B7: Charter | C7: est. $8,396 | E7: est. $8,396 | G7: 7464.5999
B8: Difference | C8: est. ($1,769) | E8: est. ($1,708) | G8: -1867.1805
C9: est. (17.4%) | E9: est. (16.9%) | G9: (20.0%)
B10: Per-Pupil Revenue by Source | C10: District | D10: Charter | E10: District | F10: Charter | G10: District | H10: Charter
B11: Federal | C11: 1014.4325 | D11: N/A | E11: 998 | F11: N/A | G11: 796.18153 | H11: 918.71353
B12: State | C12: 4295.0403 | D12: N/A | E12: 4279 | F12: N/A | G12: 4078.1773 | H12: 6025.4518
B13: Local | C13: 3922.8877 | D13: N/A | E13: 3887 | F13: N/A | G13: 3430.5143 | H13: 0
B14: Other | C14: 932.26766 | D14: N/A | E14: 939 | F14: N/A | G14: 1026.9073 | H14: 520.43464
B15: Indeterminate | C15: 0 | D15: N/A | E15: 0 | F15: N/A | G15: 0 | H15: 0
B16: Total | C16: 10164.628 | D16: est. $8,396 | E16: 10104 | F16: est. $8,396 | G16: 9331.7805 | H16: 7464.5999
B17: Enrollment
B18: District | C18: 676773.43 | E18: N/A | G18: 65411.5
C19: 0.99266054 | E19: N/A | G19: 0.98770851
B20: Charter | C20: 5003.88 | E20: N/A | G20: 814.01
C21: 0.007339464 | E21: N/A | G21: 0.012291487
B22: Number of Charters | C22: 28 | E22: N/A | G22: 6
B23: Total Revenue
B24: District | C24: 6.8791503e+09 | E24: N/A | G24: 610405757
C25: 0.99392982 | E25: N/A | G25: 0.99014366
B26: Charter | C26: est. $42,012,678 | E26: N/A | G26: 6076259
C27: 0.0060701762 | E27: N/A | G27: 0.0098563443
B28: Total | C28: est. $6,921,162,935 | E28: N/A | G28: 616482016
B29: Percentage of Revenue by Source | C29: District | D29: Charter | E29: District | F29: Charter | G29: District | H29: Charter
B30: Federal | C30: 0.099800253 | D30: N/A | E30: 0.098772763 | F30: N/A | G30: 0.085319359 | H30: 0.12307606
B31: State | C31: 0.4225477 | D31: N/A | E31: 0.42349565 | F31: N/A | G31: 0.43702028 | H31: 0.80720358
B32: Local | C32: 0.38593519 | D32: N/A | E32: 0.38469913 | F32: N/A | G32: 0.36761627 | H32: 0
B33: Other | C33: 0.091716848 | D33: N/A | E33: 0.092933492 | F33: N/A | G33: 0.11004409 | H33: 0.069720366
B34: Indeterminate | C34: 0 | D34: N/A | E34: 0 | F34: N/A | G34: 0 | H34: 0
B35: Change in district school funding if subjected to charter funding structure
C36: ($1.2 billion) | G36: ($122.1 million)
J39: Figure 3
J40: State Policies | K40: Yes | L40: No | M40: Partial
J41: Charter schools receive their funding directly from the state | L41: X3
J42: Charter schools are eligible for local funding | K42: X4
J43: Cap on funding a charter school can receive | L43: X
J44: District public schools receive differential funding (e.g. more funding for 9-12 vs. K-8 schools) | K44: X
...

Sheet 1-Download
A1: File Name: "07-distrev.xls" -- Download of Excel 2006/2007 Revenue File
A2: SOURCE: SC DOE Web Site; Confirmed as to Content by Mellanie Jinnette, Financial Systems Manager, SC Department of Education (DOE) | O2: See other NOTES on tab #5-Charters.
A3: Notes: Includes revenue for traditional district schools and charter schools by district; all revenues sources (some non-study revenue items to be deleted)
C5: | | D5: ABBEVILLE | E5: | | F5: AIKEN | G5: | | H5: ALLENDALE | I5: | | J5: ANDERSON CTY BD | K5: | | L5: ANDERSON 01 | M5: | | N5: ANDERSON 02 | O5: | | P5: ANDERSON 03 | Q5: | | R5: ANDERSON 04 | S5: | | T5: ANDERSON 05 | U5: | | V5: ANDERSON ALT SCHOOL | W5: | | X5: ANDERSON 1&2 CC | Y5: | | Z5: BAMBERG 01 | AA5: | | AB5: BAMBERG 02 | AC5: | | AD5: BARNWELL 19 | AE5: | | AF5: BARNWELL 29 | AG5: | | AH5: BARNWELL 45 | AI5: | | AJ5: BARNWELL VOC CEN | AK5: | | AL5: BEAUFORT | AM5: | | AN5: BEAUFORT-JASPER CEC | AO5: | | AP5: BERKELEY | AQ5: | | AR5: CALHOUN | AS5: | | AT5: CHARLESTON | AU5: | | AV5: CHEROKEE | AW5: | | AX5: CHESTER | AY5: | | AZ5: CHESTERFIELD | BA5: | | BB5: CLARENDON 01 | BC5: | | BD5: CLARENDON 02 | BE5: | | BF5: CLARENDON 03 | BG5: | | BH5: F.E. DUBOSE CC | BI5: | | BJ5: COLLETON | BK5: | | BL5: DARLINGTON | BM5: | | BN5: DILLON CTY BD | BO5: | | BP5: DILLON 01 | BQ5: | | BR5: DILLON 02 | BS5: | | BT5: DILLON 03 | BU5: | | BV5: DILLON ATC | BW5: | | BX5: DORCHESTER 02 | BY5: | | BZ5: DORCHESTER 04 | CA5: | | CB5: DORCHESTER CAR SCH | CC5: | | CD5: EDGEFIELD | CE5: | | CF5: FAIRFIELD | CG5: | | CH5: FLORENCE 01 | CI5: | | CJ5: FLORENCE 02 | CK5: | | CL5: FLORENCE 03 | CM5: | | CN5: FLORENCE 04 | CO5: | | CP5: FLORENCE 05 | CQ5: | | CR5: GEORGETOWN | CS5: | | CT5: GREENVILLE | CU5: | | CV5: GREENWOOD 50 | CW5: | | CX5: GREENWOOD 51 | CY5: | | CZ5: GREENWOOD 52 | DA5: | | DB5: GREENWOOD VOC FAC | DC5: | | DD5: HAMPTON 01 | DE5: | | DF5: HAMPTON 02 | DG5: | | DH5: HORRY | DI5: | | DJ5: JASPER | DK5: | | DL5: KERSHAW | DM5: | | DN5: LANCASTER | DO5: | | DP5: LAURENS 55 | DQ5: | | DR5: LAURENS 56 | DS5: | | DT5: LEE | DU5: | | DV5: LEXINGTON 01 | DW5: | | DX5: LEXINGTON 02 | DY5: | | DZ5: LEXINGTON 03 | EA5: | | EB5: LEXINGTON 04 | EC5: | | ED5: LEXINGTON 05 | EE5: | | EF5: MCCORMICK | EG5: | | EH5: MARION CTY BD | EI5: | | EJ5: MARION 01 | EK5: | | EL5: MARION 02 | EM5: | | EN5: MARION 07 | EO5: | | EP5: MARION VOC CTR | EQ5: | | ER5: MARLBORO | ES5: | | ET5: NEWBERRY | EU5: | | EV5: OCONEE | EW5: | | EX5: ORANGEBURG CTY BD | EY5: | | EZ5: ORANGEBURG 03 | FA5: | | FB5: ORANGEBURG 04 | FC5: | | FD5: ORANGEBURG 05 | FE5: | | FF5: COPE AVC | FG5: | | FH5: PICKENS | FI5: | | FJ5: RICHLAND 01 | FK5: | | FL5: RICHLAND 02 | FM5: | | FN5: SALUDA | FO5: | | FP5: SPARTANBURG 01 | FQ5: | | FR5: SPARTANBURG 02 | FS5: | | FT5: SPARTANBURG 03 | FU5: | | FV5: SPARTANBURG 04 | FW5: | | FX5: SPARTANBURG 05 | FY5: | | FZ5: SPARTANBURG 06 | GA5: | | GB5: SPARTANBURG 07 | GC5: | | GD5: DAN MORGAN VOC CEN | GE5: | | GF5: R.D. ANDERSON ATC | GG5: | | GH5: H.B. SWOFFORD CC | GI5: | | GJ5: SUMTER 02 | GK5: | | GL5: SUMTER 17 | GM5: | | GN5: SUMTER CC | GO5: | | GP5: UNION | GQ5: | | GR5: WILLIAMSBURG | GS5: | | GT5: YORK 01 | GU5: | | GV5: YORK 02 | GW5: | | GX5: YORK 03 | GY5: | | GZ5: YORK 04 | HA5: | | HB5: JUVENILE JUSTICE | HC5: | | HD5: PALMETTO UNIFIED | HE5: | | HF5: REGULAR DIST.TOTALS | HG5: | | HH5: SPECIAL DIST.TOTALS | HI5: | | HJ5: STATE TOTALS | HK5: |
C6: | | E6: | | G6: | | I6: | | K6: | | M6: | | O6: | | Q6: | | S6: | | U6: | | W6: | | Y6: | | AA6: | | AC6: | | AE6: | | AG6: | | AI6: | | AK6: | | AM6: | | AO6: | | AQ6: | | AS6: | | AU6: | | AW6: | | AY6: | | BA6: | | BC6: | | BE6: | | BG6: | | BI6: | | BK6: | | BM6: | | BO6: | | BQ6: | | BS6: | | BU6: | | BW6: | | BY6: | | CA6: | | CC6: | | CE6: | | CG6: | | CI6: | | CK6: | | CM6: | | CO6: | | CQ6: | | CS6: | | CU6: | | CW6: | | CY6: | | DA6: | | DC6: | | DE6: | | DG6: | | DI6: | | DK6: | | DM6: | | DO6: | | DQ6: | | DS6: | | DU6: | | DW6: | | DY6: | | EA6: | | EC6: | | EE6: | | EG6: | | EI6: | | EK6: | | EM6: | | EO6: | | EQ6: | | ES6: | | EU6: | | EW6: | | EY6: | | FA6: | | FC6: | | FE6: | | FG6: | | FI6: | | FK6: | | FM6: | | FO6: | | FQ6: | | FS6: | | FU6: | | FW6: | | FY6: | | GA6: | | GC6: | | GE6: | | GG6: | | GI6: | | GK6: | | GM6: | | GO6: | | GQ6: | | GS6: | | GU6: | | GW6: | | GY6: | | HA6: | | HC6: | | HE6: | | HG6: | | HI6: | | HK6: |
A7: 1000 | B7: REVENUE FROM LOCAL SOURCES: | C7: | | E7: | | G7: | | I7: | | K7: | | M7: | | O7: | | Q7: | | S7: | | U7: | | W7: | | Y7: | | AA7: | | AC7: | | AE7: | | AG7: | | AI7: | | AK7: | | AM7: | | AO7: | | AQ7: | | AS7: | | AU7: | | AW7: | | AY7: | | BA7: | | BC7: | | BE7: | | BG7: | | BI7: | | BK7: | | BM7: | | BO7: | | BQ7: | | BS7: | | BU7: | | BW7: | | BY7: | | CA7: | | CC7: | | CE7: | | CG7: | | CI7: | | CK7: | | CM7: | | CO7: | | CQ7: | | CS7: | | CU7: | | CW7: | | CY7: | | DA7: | | DC7: | | DE7: | | DG7: | | DI7: | | DK7: | | DM7: | | DO7: | | DQ7: | | DS7: | | DU7: | | DW7: | | DY7: | | EA7: | | EC7: | | EE7: | | EG7: | | EI7: | | EK7: | | EM7: | | EO7: | | EQ7: | | ES7: | | EU7: | | EW7: | | EY7: | | FA7: | | FC7: | | FE7: | | FG7: | | FI7: | | FK7: | | FM7: | | FO7: | | FQ7: | | FS7: | | FU7: | | FW7: | | FY7: | | GA7: | | GC7: | | GE7: | | GG7: | | GI7: | | GK7: | | GM7: | | GO7: | | GQ7: | | GS7: | | GU7: | | GW7: | | GY7: | | HA7: | | HC7: | | HE7: | | HG7: | | HI7: | | HK7: |
A8: 1100 | B8: TAXES ASSESSED/LEVIED BY LEA: | C8: | | E8: | | G8: | | I8: | | K8: | | M8: | | O8: | | Q8: | | S8: | | U8: | | W8: | | Y8: | | AA8: | | AC8: | | AE8: | | AG8: | | AI8: | | AK8: | | AM8: | | AO8: | | AQ8: | | AS8: | | AU8: | | AW8: | | AY8: | | BA8: | | BC8: | | BE8: | | BG8: | | BI8: | | BK8: | | BM8: | | BO8: | | BQ8: | | BS8: | | BU8: | | BW8: | | BY8: | | CA8: | | CC8: | | CE8: | | CG8: | | CI8: | | CK8: | | CM8: | | CO8: | | CQ8: | | CS8: | | CU8: | | CW8: | | CY8: | | DA8: | | DC8: | | DE8: | | DG8: | | DI8: | | DK8: | | DM8: | | DO8: | | DQ8: | | DS8: | | DU8: | | DW8: | | DY8: | | EA8: | | EC8: | | EE8: | | EG8: | | EI8: | | EK8: | | EM8: | | EO8: | | EQ8: | | ES8: | | EU8: | | EW8: | | EY8: | | FA8: | | FC8: | | FE8: | | FG8: | | FI8: | | FK8: | | FM8: | | FO8: | | FQ8: | | FS8: | | FU8: | | FW8: | | FY8: | | GA8: | | GC8: | | GE8: | | GG8: | | GI8: | | GK8: | | GM8: | | GO8: | | GQ8: | | GS8: | | GU8: | | GW8: | | GY8: | | HA8: | | HC8: | | HE8: | | HG8: | | HI8: | | HK8: |
A9: 1110 | B9: AD VALOREM TAXES (FISC INDEPEN) | C9: | | D9: 1520764 | E9: | | F9: 60312472 | G9: | | H9: 4709102 | I9: | | K9: | | M9: | | O9: | | Q9: | | S9: | | U9: | | W9: | | Y9: | | Z9: 3518785 | AA9: | | AC9: | | AD9: 1608309 | AE9: | | AF9: 1694415 | AG9: | | AH9: 4983807 | AI9: | | AK9: | | AM9: | | AO9: | | AP9: 81057233 | AQ9: | | AS9: | | AT9: 237617163 | AU9: | | AV9: 20857424 | AW9: | | AX9: 15774043 | AY9: | | AZ9: 13611432 | BA9: | | BC9: | | BE9: | | BG9: | | BI9: | | BJ9: 3633589 | BK9: | | BL9: 31643785 | BM9: | | BN9: 1164045 | BO9: | | BQ9: | | BS9: | | BT9: 1669444 | BU9: | | BV9: 773207 | BW9: | | BX9: 47974404 | BY9: | | BZ9: 9991137 | CA9: | | CC9: | | CD9: 9211573 | CE9: | | CG9: | | CI9: | | CK9: | | CL9: 6118718 | CM9: | | CN9: 2340676 | CO9: | | CQ9: | | CR9: 53912753 | CS9: | | CT9: 209875704 | CU9: | | CW9: | | CY9: | | DA9: | | DC9: | | DE9: | | DG9: | | DH9: 189882593 | DI9: | | DK9: | | DM9: | | DN9: 27833046 | DO9: | | DP9: 12598542 | DQ9: | | DR9: 4931133 | DS9: | | DU9: | | DV9: 54022433 | DW9: | | DX9: 28570445 | DY9: | | DZ9: 8785696 | EA9: | | EB9: 6370433 | EC9: | | ED9: 75156901 | EE9: | | EG9: | | EH9: 1031638 | EI9: | | EK9: | | EM9: | | EO9: | | EP9: 829221 | EQ9: | | ER9: 7589855 | ES9: | | ET9: 21368223 | EU9: | | EW9: | | EY9: | | EZ9: 8411421 | FA9: | | FB9: 9864404 | FC9: | | FD9: 22697920 | FE9: | | FG9: | | FH9: 41771782 | FI9: | | FK9: | | FM9: | | FO9: | | FP9: 15002986 | FQ9: | | FR9: 19399837 | FS9: | | FT9: 10606763 | FU9: | | FV9: 6064849 | FW9: | | FX9: 27007132 | FY9: | | FZ9: 34914489 | GA9: | | GB9: 35418636 | GC9: | | GD9: 1220480 | GE9: | | GF9: 1790126 | GG9: | | GI9: | | GK9: | | GM9: | | GO9: | | GP9: 7548390 | GQ9: | | GR9: 6863244 | GS9: | | GT9: 8885582 | GU9: | | GV9: 37156040 | GW9: | | GX9: 51613941 | GY9: | | GZ9: 34135864 | HA9: | | HC9: | | HE9: | | HF9: 1644918029 | HG9: | | HI9: | | HJ9: 1644918029 | HK9: |
A10: 1140 | B10: PENALTY/INT ON TAX (FISC INDEP) | C10: | | D10: 132769 | E10: | | F10: 2319640 | G10: | | H10: 10538 | I10: | | K10: | | M10: | | O10: | | Q10: | | S10: | | U10: | | W10: | | Y10: | | AA10: | | AC10: | | AD10: 22174 | AE10: | | AF10: 315835 | AG10: | | AI10: | | AK10: | | AM10: | | AO10: | | AP10: 283069 | AQ10: | | AS10: | | AT10: 7206803 | AU10: | | AW10: | | AY10: | | AZ10: 69856 | BA10: | | BC10: | | BE10: | | BG10: | | BI10: | | BK10: | | BL10: 149802 | BM10: | | BO10: | | BQ10: | | BS10: | | BT10: 16783 | BU10: | | BV10: 7569 | BW10: | | BY10: | | CA10: | | CC10: | | CD10: 63329 | CE10: | | CG10: | | CI10: | | CK10: | | CL10: 24835 | CM10: | | CN10: 7929 | CO10: | | CQ10: | | CR10: 338274 | CS10: | | CU10: | | CW10: | | CY10: | | DA10: | | DC10: | | DE10: | | DG10: | | DH10: 1847104 | DI10: | | DK10: | | DM10: | | DN10: 306014 | DO10: | | DP10: 39250 | DQ10: | | DR10: 352047 | DS10: | | DU10: | | DV10: 2948414 | DW10: | | DX10: 168908 | DY10: | | DZ10: 123038 | EA10: | | EB10: 60715 | EC10: | | ED10: 401443 | EE10: | | EG10: | | EH10: 13774 | EI10: | | EK10: | | EM10: | | EO10: | | EP10: 11472 | EQ10: | | ER10: 98476 | ES10: | | ET10: 382847 | EU10: | | EW10: | | EY10: | | EZ10: 158859 | FA10: | | FB10: 92320 | FC10: | | FD10: 302645 | FE10: | | FG10: | | FH10: 356908 | FI10: | | FK10: | | FM10: | | FO10: | | FQ10: | | FS10: | | FU10: | | FW10: | | FY10: | | FZ10: 53219 | GA10: | | GC10: | | GE10: | | GF10: 118918 | GG10: | | GI10: | | GK10: | | GM10: | | GO10: | | GP10: 623388 | GQ10: | | GS10: | | GT10: 436515 | GU10: | | GV10: 765865 | GW10: | | GX10: 436456 | GY10: | | GZ10: 117338 | HA10: | | HC10: | | HE10: | | HF10: 21185138 | HG10: | | HI10: | | HJ10: 21185138 | HK10: |
A11: 1190 | B11: OTHER TAXES (FISCALLY INDEPEN) | C11: | | E11: | | G11: | | I11: | | K11: | | M11: | | O11: | | Q11: | | S11: | | U11: | | W11: | | Y11: | | AA11: | | AC11: | | AE11: | | AG11: | | AI11: | | AK11: | | AM11: | | AO11: | | AQ11: | | AS11: | | AU11: | | AV11: 5051631 | AW11: | | AY11: | | BA11: | | BC11: | | BE11: | | BG11: | | BI11: | | BK11: | | BM11: | | BN11: 62076 | BO11: | | BQ11: | | BS11: | | BT11: 347531 | BU11: | | BV11: 162535 | BW11: | | BY11: | | CA11: | | CC11: | | CE11: | | CG11: | | CI11: | | CK11: | | CM11: | | CO11: | | CQ11: | | CS11: | | CU11: | | CW11: | | CY11: | | DA11: | | DC11: | | DE11: | | DG11: | | DI11: | | DK11: | | DM11: | | DO11: | | DQ11: | | DS11: | | DU11: | | DV11: 25525556 | DW11: | | DY11: | | EA11: | | EC11: | | EE11: | | EG11: | | EI11: | | EK11: | | EM11: | | EO11: | | EQ11: | | ER11: 8497 | ES11: | | EU11: | | EW11: | | EY11: | | FA11: | | FC11: | | FE11: | | FG11: | | FH11: 5595 | FI11: | | FK11: | | FM11: | | FO11: | | FQ11: | | FS11: | | FU11: | | FW11: | | FX11: 1781081 | FY11: | | GA11: | | GC11: | | GE11: | | GG11: | | GI11: | | GK11: | | GM11: | | GO11: | | GQ11: | | GS11: | | GU11: | | GW11: | | GY11: | | HA11: | | HC11: | | HE11: | | HF11: 32944502 | HG11: | | HI11: | | HJ11: 32944502 | HK11: |
A12: 1200 | B12: REV FR LOC GOV UNIT OTH THAN LEA: | C12: | | E12: | | G12: | | I12: | | K12: | | M12: | | O12: | | Q12: | | S12: | | U12: | | W12: | | Y12: | | AA12: | | AC12: | | AE12: | | AG12: | | AI12: | | AK12: | | AM12: | | AO12: | | AQ12: | | AS12: | | AU12: | | AW12: | | AY12: | | BA12: | | BC12: | | BE12: | | BG12: | | BI12: | | BK12: | | BM12: | | BO12: | | BQ12: | | BS12: | | BU12: | | BW12: | | BY12: | | CA12: | | CC12: | | CE12: | | CG12: | | CI12: | | CK12: | | CM12: | | CO12: | | CQ12: | | CS12: | | CU12: | | CW12: | | CY12: | | DA12: | | DC12: | | DE12: | | DG12: | | DI12: | | DK12: | | DM12: | | DO12: | | DQ12: | | DS12: | | DU12: | | DW12: | | DY12: | | EA12: | | EC12: | | EE12: | | EG12: | | EI12: | | EK12: | | EM12: | | EO12: | | EQ12: | | ES12: | | EU12: | | EW12: | | EY12: | | FA12: | | FC12: | | FE12: | | FG12: | | FI12: | | FK12: | | FM12: | | FO12: | | FQ12: | | FS12: | | FU12: | | FW12: | | FY12: | | GA12: | | GC12: | | GE12: | | GG12: | | GI12: | | GK12: | | GM12: | | GO12: | | GQ12: | | GS12: | | GU12: | | GW12: | | GY12: | | HA12: | | HC12: | | HE12: | | HG12: | | HI12: | | HK12: |
A13: 1210 | B13: AD VALOREM TAX (FISC DEPENDENT) | C13: | | D13: 6245819 | E13: | | G13: | | I13: | | J13: 433216 | K13: | | L13: 16421598 | M13: | | N13: 7017799 | O13: | | P13: 5213455 | Q13: | | R13: 12347769 | S13: | | T13: 33664427 | U13: | | V13: 868614 | W13: | | X13: 2138478 | Y13: | | AA13: | | AB13: 2593235 | AC13: | | AE13: | | AG13: | | AI13: | | AJ13: 1111614 | AK13: | | AL13: 153402920 | AM13: | | AO13: | | AQ13: | | AR13: 5828627 | AS13: | | AU13: | | AW13: | | AY13: | | BA13: | | BB13: 3254202 | BC13: | | BD13: 3919418 | BE13: | | BF13: 1414172 | BG13: | | BH13: 195242 | BI13: | | BJ13: 13693942 | BK13: | | BM13: | | BO13: | | BP13: 797062 | BQ13: | | BR13: 3812551 | BS13: | | BU13: | | BW13: | | BY13: | | CA13: | | CB13: 2977217 | CC13: | | CD13: 1735984 | CE13: | | CF13: 21351124 | CG13: | | CH13: 46691201 | CI13: | | CJ13: 2458856 | CK13: | | CM13: | | CO13: | | CP13: 2852068 | CQ13: | | CS13: | | CU13: | | CV13: 30220203 | CW13: | | CX13: 2691050 | CY13: | | CZ13: 7425961 | DA13: | | DB13: 1147565 | DC13: | | DD13: 5106272 | DE13: | | DF13: 3216142 | DG13: | | DI13: | | DJ13: 9192444 | DK13: | | DL13: 24813543 | DM13: | | DO13: | | DQ13: | | DR13: 976985 | DS13: | | DT13: 4809755 | DU13: | | DW13: | | DY13: | | EA13: | | EC13: | | EE13: | | EF13: 4962701 | EG13: | | EI13: | | EJ13: 3857014 | EK13: | | EL13: 2488097 | EM13: | | EN13: 1333045 | EO13: | | EQ13: | | ES13: | | EU13: | | EV13: 54253011 | EW13: | | EY13: | | EZ13: 1874414 | FA13: | | FB13: 604807 | FC13: | | FD13: 3222083 | FE13: | | FG13: | | FI13: | | FJ13: 158166933 | FK13: | | FL13: 97862726 | FM13: | | FN13: 5417651 | FO13: | | FQ13: | | FS13: | | FU13: | | FW13: | | FY13: | | GA13: | | GC13: | | GE13: | | GG13: | | GH13: 1742817 | GI13: | | GJ13: 18310585 | GK13: | | GL13: 18715981 | GM13: | | GO13: | | GQ13: | | GS13: | | GT13: 5888294 | GU13: | | GV13: 3131088 | GW13: | | GX13: 9576458 | GY13: | | HA13: | | HC13: | | HE13: | | HF13: 833448235 | HG13: | | HI13: | | HJ13: 833448235 | HK13: |
A14: 1240 | B14: PENALTY/INT ON TAX (FISC DEPEN) | C14: | | D14: 597511 | E14: | | G14: | | I14: | | K14: | | L14: 880175 | M14: | | N14: 621538 | O14: | | Q14: | | S14: | | T14: 1894677 | U14: | | W14: | | X14: 154664 | Y14: | | AA14: | | AB14: 263749 | AC14: | | AE14: | | AG14: | | AI14: | | AJ14: 7827 | AK14: | | AL14: 1108823 | AM14: | | AO14: | | AQ14: | | AR14: 314398 | AS14: | | AU14: | | AW14: | | AY14: | | BA14: | | BB14: 20715 | BC14: | | BD14: 58335 | BE14: | | BF14: 14132 | BG14: | | BI14: | | BK14: | | BM14: | | BO14: | | BP14: 10867 | BQ14: | | BR14: 45178 | BS14: | | BU14: | | BW14: | | BY14: | | CA14: | | CC14: | | CE14: | | CF14: 128917 | CG14: | | CH14: 94545 | CI14: | | CJ14: 8145 | CK14: | | CM14: | | CO14: | | CP14: 8204 | CQ14: | | CS14: | | CU14: | | CV14: 3144240 | CW14: | | CX14: 28733 | CY14: | | CZ14: 20006 | DA14: | | DB14: 101865 | DC14: | | DD14: 36588 | DE14: | | DF14: 44176 | DG14: | | DI14: | | DJ14: 147877 | DK14: | | DL14: 381137 | DM14: | | DO14: | | DQ14: | | DS14: | | DT14: 41064 | DU14: | | DW14: | | DY14: | | EA14: | | EC14: | | EE14: | | EG14: | | EI14: | | EJ14: 56050 | EK14: | | EL14: 36677 | EM14: | | EN14: 121914 | EO14: | | EQ14: | | ES14: | | EU14: | | EV14: 172869 | EW14: | | EY14: | | FA14: | | FC14: | | FE14: | | FG14: | | FI14: | | FJ14: 1748 | FK14: | | FL14: 1202011 | FM14: | | FO14: | | FQ14: | | FS14: | | FU14: | | FW14: | | FY14: | | GA14: | | GC14: | | GE14: | | GG14: | | GI14: | | GK14: | | GM14: | | GO14: | | GQ14: | | GS14: | | GT14: 233092 | GU14: | | GV14: 89758 | GW14: | | GY14: | | HA14: | | HC14: | | HE14: | | HF14: 12092205 | HG14: | | HI14: | | HJ14: 12092205 | HK14: |
A15: 1280 | B15: REV IN LIEU OF TAX (INDEP & DEP) | C15: | | D15: 248250 | E15: | | F15: 3228180 | G15: | | H15: 30934 | I15: | | J15: 16195 | K15: | | L15: 281920 | M15: | | N15: 110149 | O15: | | P15: 663826 | Q15: | | R15: 987719 | S15: | | T15: 705878 | U15: | | V15: 32380 | W15: | | X15: 37121 | Y15: | | AA15: | | AB15: 58802 | AC15: | | AD15: 337725 | AE15: | | AG15: | | AI15: | | AK15: | | AL15: 72555 | AM15: | | AO15: | | AP15: 11717128 | AQ15: | | AR15: 1501169 | AS15: | | AU15: | | AV15: 3487340 | AW15: | | AX15: 1808893 | AY15: | | AZ15: 1012904 | BA15: | | BC15: | | BE15: | | BG15: | | BI15: | | BK15: | | BL15: 2270051 | BM15: | | BO15: | | BQ15: | | BS15: | | BU15: | | BW15: | | BX15: 2558555 | BY15: | | BZ15: 136438 | CA15: | | CC15: | | CE15: | | CF15: 81935 | CG15: | | CH15: 1352744 | CI15: | | CJ15: 18213 | CK15: | | CL15: 512915 | CM15: | | CN15: 778498 | CO15: | | CP15: 75913 | CQ15: | | CR15: 260827 | CS15: | | CT15: 14519384 | CU15: | | CW15: | | CX15: 239598 | CY15: | | DA15: | | DC15: | | DD15: 175 | DE15: | | DG15: | | DH15: 3339957 | DI15: | | DJ15: 424974 | DK15: | | DL15: 2160178 | DM15: | | DN15: 1429643 | DO15: | | DP15: 262951 | DQ15: | | DR15: 635032 | DS15: | | DT15: 151497 | DU15: | | DV15: 3660322 | DW15: | | DX15: 1228103 | DY15: | | DZ15: 9708 | EA15: | | EB15: 449301 | EC15: | | ED15: 78278 | EE15: | | EF15: 138537 | EG15: | | EI15: | | EJ15: 107735 | EK15: | | EL15: 66565 | EM15: | | EO15: | | EQ15: | | ER15: 2473128 | ES15: | | ET15: 1173323 | EU15: | | EV15: 1913859 | EW15: | | EY15: | | EZ15: 983273 | FA15: | | FB15: 164336 | FC15: | | FD15: 1488642 | FE15: | | FG15: | | FH15: 57293 | FI15: | | FJ15: 6147665 | FK15: | | FL15: 955039 | FM15: | | FO15: | | FQ15: | | FR15: 66554 | FS15: | | FT15: 1296281 | FU15: | | FV15: 126483 | FW15: | | FX15: 4902610 | FY15: | | FZ15: 1833006 | GA15: | | GB15: 42550 | GC15: | | GD15: 2821 | GE15: | | GF15: 11374 | GG15: | | GI15: | | GJ15: 286707 | GK15: | | GM15: | | GO15: | | GQ15: | | GR15: 3398472 | GS15: | | GU15: | | GV15: 194008 | GW15: | | GY15: | | GZ15: 2423424 | HA15: | | HC15: | | HE15: | | HF15: 93227943 | HG15: | | HI15: | | HJ15: 93227943 | HK15: |
A16: 1290 | B16: OTHER TAXES (FISCALLY DEPENDENT) | C16: | | D16: -185981 | E16: | | G16: | | I16: | | K16: | | L16: 2529411 | M16: | | N16: 1058039 | O16: | | Q16: | | S16: | | T16: 3578859 | U16: | | W16: | | Y16: | | AA16: | | AC16: | | AE16: | | AG16: | | AI16: | | AK16: | | AM16: | | AO16: | | AQ16: | | AS16: | | AU16: | | AW16: | | AY16: | | AZ16: 2678003 | BA16: | | BB16: 498106 | BC16: | | BE16: | | BF16: 592984 | BG16: | | BI16: | | BK16: | | BM16: | | BO16: | | BP16: 191741 | BQ16: | | BR16: 693689 | BS16: | | BU16: | | BW16: | | BY16: | | CA16: | | CC16: | | CE16: | | CG16: | | CI16: | | CK16: | | CM16: | | CO16: | | CQ16: | | CS16: | | CU16: | | CW16: | | CY16: | | DA16: | | DC16: | | DE16: | | DG16: | | DI16: | | DK16: | | DM16: | | DO16: | | DQ16: | | DS16: | | DT16: 162622 | DU16: | | DW16: | | DY16: | | EA16: | | EC16: | | EE16: | | EG16: | | EI16: | | EK16: | | EM16: | | EO16: | | EQ16: | | ES16: | | EU16: | | EW16: | | EY16: | | FA16: | | FB16: 2395955 | FC16: | | FE16: | | FG16: | | FI16: | | FK16: | | FM16: | | FO16: | | FQ16: | | FR16: 2896709 | FS16: | | FU16: | | FW16: | | FY16: | | GA16: | | GC16: | | GE16: | | GG16: | | GI16: | | GK16: | | GM16: | | GO16: | | GQ16: | | GS16: | | GU16: | | GW16: | | GY16: | | HA16: | | HC16: | | HE16: | | HF16: 17090137 | HG16: | | HI16: | | HJ16: 17090137 | HK16: |
A17: 1300 | B17: TUITION: | C17: | | E17: | | G17: | | I17: | | K17: | | M17: | | O17: | | Q17: | | S17: | | U17: | | W17: | | Y17: | | AA17: | | AC17: | | AE17: | | AG17: | | AI17: | | AK17: | | AM17: | | AO17: | | AQ17: | | AS17: | | AU17: | | AW17: | | AY17: | | BA17: | | BC17: | | BE17: | | BG17: | | BI17: | | BK17: | | BM17: | | BO17: | | BQ17: | | BS17: | | BU17: | | BW17: | | BY17: | | CA17: | | CC17: | | CE17: | | CG17: | | CI17: | | CK17: | | CM17: | | CO17: | | CQ17: | | CS17: | | CU17: | | CW17: | | CY17: | | DA17: | | DC17: | | DE17: | | DG17: | | DI17: | | DK17: | | DM17: | | DO17: | | DQ17: | | DS17: | | DU17: | | DW17: | | DY17: | | EA17: | | EC17: | | EE17: | | EG17: | | EI17: | | EK17: | | EM17: | | EO17: | | EQ17: | | ES17: | | EU17: | | EW17: | | EY17: | | FA17: | | FC17: | | FE17: | | FG17: | | FI17: | | FK17: | | FM17: | | FO17: | | FQ17: | | FS17: | | FU17: | | FW17: | | FY17: | | GA17: | | GC17: | | GE17: | | GG17: | | GI17: | | GK17: | | GM17: | | GO17: | | GQ17: | | GS17: | | GU17: | | GW17: | | GY17: | | HA17: | | HC17: | | HE17: | | HG17: | | HI17: | | HK17: |
A18: 1310 | B18: REGULAR DAY SCHOOL FRM PATRONS | C18: | | D18: 4600 | E18: | | F18: 19069 | G18: | | I18: | | K18: | | L18: 29796 | M18: | | N18: 13270 | O18: | | P18: 6586 | Q18: | | R18: 9507 | S18: | | U18: | | W18: | | Y18: | | Z18: 44039 | AA18: | | AC18: | | AE18: | | AG18: | | AI18: | | AK18: | | AL18: 40379 | AM18: | | AO18: | | AP18: 2424119 | AQ18: | | AS18: | | AT18: 29275 | AU18: | | AW18: | | AX18: 1517 | AY18: | | AZ18: 61794 | BA18: | | BC18: | | BD18: 6214 | BE18: | | BF18: 100565 | BG18: | | BH18: 4201 | BI18: | | BK18: | | BM18: | | BO18: | | BQ18: | | BS18: | | BU18: | | BW18: | | BY18: | | CA18: | | CB18: 7752 | CC18: | | CD18: 11617 | CE18: | | CF18: 1068 | CG18: | | CH18: 102253 | CI18: | | CK18: | | CL18: 7970 | CM18: | | CO18: | | CP18: 55215 | CQ18: | | CR18: 25358 | CS18: | | CT18: 495128 | CU18: | | CV18: 5400 | CW18: | | CX18: 7750 | CY18: | | CZ18: 9080 | DA18: | | DC18: | | DD18: 28003 | DE18: | | DG18: | | DH18: 59417 | DI18: | | DK18: | | DM18: | | DN18: 37589 | DO18: | | DQ18: | | DR18: 4776 | DS18: | | DU18: | | DV18: 33968 | DW18: | | DX18: 33500 | DY18: | | DZ18: 83297 | EA18: | | EB18: 36675 | EC18: | | ED18: 287505 | EE18: | | EG18: | | EI18: | | EK18: | | EL18: 16296 | EM18: | | EO18: | | EP18: 35090 | EQ18: | | ES18: | | ET18: 1700 | EU18: | | EV18: 103074 | EW18: | | EY18: | | FA18: | | FB18: 25225 | FC18: | | FD18: 77335 | FE18: | | FG18: | | FH18: 240398 | FI18: | | FJ18: 72550 | FK18: | | FL18: 90318 | FM18: | | FO18: | | FP18: 5112 | FQ18: | | FR18: 6335 | FS18: | | FT18: 42214 | FU18: | | FV18: 3550 | FW18: | | FX18: 3815 | FY18: | | FZ18: 29962 | GA18: | | GB18: 47447 | GC18: | | GE18: | | GG18: | | GI18: | | GJ18: 1139 | GK18: | | GL18: 551267 | GM18: | | GO18: | | GQ18: | | GS18: | | GU18: | | GV18: 6218 | GW18: | | GX18: 280631 | GY18: | | GZ18: 139833 | HA18: | | HC18: | | HE18: | | HF18: 5907761 | HG18: | | HI18: | | HJ18: 5907761 | HK18: |
A19: 1320 | B19: REG DAY SCHL FROM OTHER LEA'S | C19: | | E19: | | F19: 12820 | G19: | | H19: 47341 | I19: | | K19: | | L19: 17317 | M19: | | O19: | | Q19: | | S19: | | T19: 76940 | U19: | | W19: | | X19: 1221292 | Y19: | | AA19: | | AC19: | | AE19: | | AG19: | | AH19: 90802 | AI19: | | AJ19: 181167 | AK19: | | AM19: | | AN19: 2431388 | AO19: | | AP19: 56192 | AQ19: | | AS19: | | AU19: | | AW19: | | AX19: 50000 | AY19: | | AZ19: 16318 | BA19: | | BC19: | | BE19: | | BG19: | | BH19: 750617 | BI19: | | BJ19: 11183 | BK19: | | BM19: | | BO19: | | BQ19: | | BS19: | | BU19: | | BW19: | | BY19: | | BZ19: 14134 | CA19: | | CC19: | | CE19: | | CG19: | | CH19: 78083 | CI19: | | CK19: | | CL19: 11617 | CM19: | | CN19: 3122 | CO19: | | CQ19: | | CS19: | | CU19: | | CW19: | | CY19: | | DA19: | | DC19: | | DE19: | | DG19: | | DI19: | | DK19: | | DL19: 24318 | DM19: | | DN19: 21353 | DO19: | | DQ19: | | DR19: 5787 | DS19: | | DU19: | | DV19: 197914 | DW19: | | DX19: 668225 | DY19: | | EA19: | | EC19: | | EE19: | | EG19: | | EH19: 375077 | EI19: | | EK19: | | EM19: | | EO19: | | EP19: 329502 | EQ19: | | ES19: | | ET19: 13989 | EU19: | | EV19: 21750 | EW19: | | EY19: | | FA19: | | FB19: 6195 | FC19: | | FD19: 24622 | FE19: | | FF19: 759620 | FG19: | | FH19: 63211 | FI19: | | FJ19: 396184 | FK19: | | FL19: 882 | FM19: | | FO19: | | FQ19: | | FR19: 81313 | FS19: | | FU19: | | FW19: | | FY19: | | FZ19: 31574 | GA19: | | GB19: 663166 | GC19: | | GD19: 407619 | GE19: | | GF19: 619986 | GG19: | | GH19: 544539 | GI19: | | GJ19: 995368 | GK19: | | GM19: | | GO19: | | GQ19: | | GR19: 22786 | GS19: | | GU19: | | GW19: | | GX19: 15962 | GY19: | | HA19: | | HC19: | | HE19: | | HF19: 11361275 | HG19: | | HI19: | | HJ19: 11361275 | HK19: |
A20: 1330 | B20: ADULT/CONT ED FROM PATRONS | C20: | | E20: | | F20: 12354 | G20: | | I20: | | K20: | | M20: | | O20: | | Q20: | | S20: | | U20: | | W20: | | X20: 29659 | Y20: | | AA20: | | AC20: | | AD20: 1267 | AE20: | | AG20: | | AI20: | | AK20: | | AM20: | | AO20: | | AQ20: | | AR20: 12856 | AS20: | | AU20: | | AV20: 11021 | AW20: | | AY20: | | AZ20: 18550 | BA20: | | BC20: | | BE20: | | BG20: | | BH20: 15692 | BI20: | | BK20: | | BM20: | | BO20: | | BQ20: | | BR20: 3490 | BS20: | | BU20: | | BW20: | | BX20: 105071 | BY20: | | CA20: | | CC20: | | CE20: | | CF20: 141 | CG20: | | CH20: 146348 | CI20: | | CK20: | | CM20: | | CO20: | | CQ20: | | CS20: | | CT20: 509383 | CU20: | | CV20: 20362 | CW20: | | CY20: | | DA20: | | DC20: | | DE20: | | DG20: | | DH20: 15248 | DI20: | | DK20: | | DM20: | | DN20: 20604 | DO20: | | DQ20: | | DS20: | | DU20: | | DW20: | | DX20: 100 | DY20: | | EA20: | | EC20: | | EE20: | | EG20: | | EI20: | | EK20: | | EM20: | | EO20: | | EP20: 520 | EQ20: | | ES20: | | EU20: | | EV20: 6002 | EW20: | | EY20: | | FA20: | | FC20: | | FE20: | | FG20: | | FI20: | | FJ20: 66956 | FK20: | | FM20: | | FO20: | | FQ20: | | FS20: | | FU20: | | FW20: | | FY20: | | GA20: | | GB20: 13313 | GC20: | | GE20: | | GG20: | | GI20: | | GK20: | | GL20: 7190 | GM20: | | GO20: | | GQ20: | | GR20: 41319 | GS20: | | GU20: | | GW20: | | GY20: | | HA20: | | HC20: | | HE20: | | HF20: 1057446 | HG20: | | HI20: | | HJ20: 1057446 | HK20: |
A21: 1340 | B21: ADULT/CONT ED FROM OTHER LEA'S | C21: | | E21: | | G21: | | I21: | | K21: | | M21: | | O21: | | Q21: | | S21: | | U21: | | W21: | | Y21: | | AA21: | | AC21: | | AE21: | | AG21: | | AI21: | | AK21: | | AM21: | | AO21: | | AQ21: | | AS21: | | AU21: | | AW21: | | AY21: | | BA21: | | BC21: | | BE21: | | BG21: | | BH21: 12000 | BI21: | | BK21: | | BM21: | | BO21: | | BQ21: | | BS21: | | BU21: | | BW21: | | BY21: | | CA21: | | CC21: | | CE21: | | CG21: | | CI21: | | CK21: | | CM21: | | CO21: | | CQ21: | | CS21: | | CU21: | | CW21: | | CY21: | | DA21: | | DC21: | | DE21: | | DG21: | | DI21: | | DK21: | | DM21: | | DO21: | | DQ21: | | DS21: | | DU21: | | DW21: | | DY21: | | EA21: | | EC21: | | EE21: | | EG21: | | EI21: | | EK21: | | EM21: | | EO21: | | EQ21: | | ES21: | | EU21: | | EV21: 3960 | EW21: | | EY21: | | FA21: | | FC21: | | FE21: | | FG21: | | FI21: | | FK21: | | FM21: | | FO21: | | FQ21: | | FS21: | | FU21: | | FW21: | | FY21: | | GA21: | | GC21: | | GE21: | | GG21: | | GI21: | | GK21: | | GM21: | | GO21: | | GQ21: | | GS21: | | GU21: | | GW21: | | GY21: | | HA21: | | HC21: | | HE21: | | HF21: 15960 | HG21: | | HI21: | | HJ21: 15960 | HK21: |
A22: 1350 | B22: SUMMER SCHOOL FROM PATRONS | C22: | | D22: 2400 | E22: | | G22: | | I22: | | K22: | | L22: 52183 | M22: | | N22: 16242 | O22: | | P22: 7992 | Q22: | | S22: | | U22: | | W22: | | Y22: | | AA22: | | AB22: 250 | AC22: | | AE22: | | AG22: | | AH22: 29544 | AI22: | | AK22: | | AM22: | | AN22: 780636 | AO22: | | AQ22: | | AS22: | | AU22: | | AV22: 22803 | AW22: | | AY22: | | AZ22: 18050 | BA22: | | BC22: | | BE22: | | BG22: | | BI22: | | BK22: | | BM22: | | BO22: | | BP22: 900 | BQ22: | | BR22: 5150 | BS22: | | BU22: | | BW22: | | BX22: 184486 | BY22: | | BZ22: 12995 | CA22: | | CB22: 2925 | CC22: | | CE22: | | CG22: | | CI22: | | CK22: | | CM22: | | CN22: 460 | CO22: | | CQ22: | | CR22: 20638 | CS22: | | CT22: 278417 | CU22: | | CW22: | | CX22: 7390 | CY22: | | CZ22: 200 | DA22: | | DC22: | | DE22: | | DG22: | | DH22: 147814 | DI22: | | DJ22: 8294 | DK22: | | DM22: | | DN22: 11420 | DO22: | | DQ22: | | DS22: | | DT22: 11980 | DU22: | | DW22: | | DX22: 38629 | DY22: | | EA22: | | EC22: | | ED22: 75910 | EE22: | | EG22: | | EI22: | | EJ22: 15033 | EK22: | | EL22: 3040 | EM22: | | EO22: | | EQ22: | | ES22: | | ET22: 6250 | EU22: | | EV22: 75695 | EW22: | | EY22: | | EZ22: 74383 | FA22: | | FB22: 33386 | FC22: | | FD22: 16724 | FE22: | | FG22: | | FH22: 45210 | FI22: | | FJ22: 61125 | FK22: | | FL22: 90223 | FM22: | | FO22: | | FP22: 3400 | FQ22: | | FR22: 3050 | FS22: | | FU22: | | FW22: | | FX22: 3575 | FY22: | | FZ22: 1000 | GA22: | | GB22: 22365 | GC22: | | GE22: | | GG22: | | GI22: | | GJ22: 6942 | GK22: | | GL22: 11978 | GM22: | | GO22: | | GQ22: | | GS22: | | GU22: | | GW22: | | GX22: 123250 | GY22: | | GZ22: 20749 | HA22: | | HC22: | | HE22: | | HF22: 2355086 | HG22: | | HI22: | | HJ22: 2355086 | HK22: |
A23: 1360 | B23: SUMMER SCHOOL FROM OTHER LEA'S | C23: | | E23: | | G23: | | I23: | | K23: | | M23: | | O23: | | Q23: | | S23: | | U23: | | W23: | | Y23: | | AA23: | | AC23: | | AE23: | | AG23: | | AI23: | | AK23: | | AM23: | | AO23: | | AQ23: | | AS23: | | AU23: | | AW23: | | AY23: | | BA23: | | BC23: | | BE23: | | BG23: | | BI23: | | BK23: | | BM23: | | BO23: | | BQ23: | | BS23: | | BU23: | | BW23: | | BY23: | | CA23: | | CC23: | | CE23: | | CG23: | | CI23: | | CK23: | | CM23: | | CO23: | | CQ23: | | CS23: | | CU23: | | CW23: | | CY23: | | DA23: | | DC23: | | DE23: | | DG23: | | DH23: 400 | DI23: | | DK23: | | DM23: | | DO23: | | DQ23: | | DS23: | | DU23: | | DW23: | | DY23: | | EA23: | | EC23: | | EE23: | | EG23: | | EI23: | | EK23: | | EM23: | | EO23: | | EQ23: | | ES23: | | EU23: | | EW23: | | EY23: | | FA23: | | FC23: | | FE23: | | FG23: | | FI23: | | FK23: | | FL23: 104200 | FM23: | | FO23: | | FQ23: | | FS23: | | FU23: | | FW23: | | FY23: | | GA23: | | GC23: | | GE23: | | GG23: | | GI23: | | GK23: | | GM23: | | GO23: | | GQ23: | | GS23: | | GU23: | | GW23: | | GY23: | | HA23: | | HC23: | | HE23: | | HF23: 104600 | HG23: | | HI23: | | HJ23: 104600 | HK23: |
A24: 1400 | B24: TRANSPORTATION FEES: | C24: | | E24: | | G24: | | I24: | | K24: | | M24: | | O24: | | Q24: | | S24: | | U24: | | W24: | | Y24: | | AA24: | | AC24: | | AE24: | | AG24: | | AI24: | | AK24: | | AM24: | | AO24: | | AQ24: | | AS24: | | AU24: | | AW24: | | AY24: | | BA24: | | BC24: | | BE24: | | BG24: | | BI24: | | BK24: | | BM24: | | BO24: | | BQ24: | | BS24: | | BU24: | | BW24: | | BY24: | | CA24: | | CC24: | | CE24: | | CG24: | | CI24: | | CK24: | | CM24: | | CO24: | | CQ24: | | CS24: | | CU24: | | CW24: | | CY24: | | DA24: | | DC24: | | DE24: | | DG24: | | DI24: | | DK24: | | DM24: | | DO24: | | DQ24: | | DS24: | | DU24: | | DW24: | | DY24: | | EA24: | | EC24: | | EE24: | | EG24: | | EI24: | | EK24: | | EM24: | | EO24: | | EQ24: | | ES24: | | EU24: | | EW24: | | EY24: | | FA24: | | FC24: | | FE24: | | FG24: | | FI24: | | FK24: | | FM24: | | FO24: | | FQ24: | | FS24: | | FU24: | | FW24: | | FY24: | | GA24: | | GC24: | | GE24: | | GG24: | | GI24: | | GK24: | | GM24: | | GO24: | | GQ24: | | GS24: | | GU24: | | GW24: | | GY24: | | HA24: | | HC24: | | HE24: | | HG24: | | HI24: | | HK24: |
A25: 1410 | B25: REGULAR DAY SCHOOL FRM PATRONS | C25: | | E25: | | G25: | | I25: | | K25: | | L25: 107802 | M25: | | O25: | | Q25: | | S25: | | U25: | | W25: | | Y25: | | AA25: | | AC25: | | AE25: | | AG25: | | AI25: | | AK25: | | AM25: | | AO25: | | AQ25: | | AS25: | | AU25: | | AW25: | | AY25: | | BA25: | | BC25: | | BE25: | | BG25: | | BI25: | | BK25: | | BM25: | | BO25: | | BQ25: | | BS25: | | BU25: | | BW25: | | BY25: | | CA25: | | CC25: | | CE25: | | CG25: | | CI25: | | CK25: | | CM25: | | CO25: | | CQ25: | | CS25: | | CU25: | | CW25: | | CY25: | | DA25: | | DC25: | | DE25: | | DG25: | | DI25: | | DK25: | | DM25: | | DO25: | | DP25: 40077 | DQ25: | | DS25: | | DU25: | | DW25: | | DY25: | | EA25: | | EC25: | | EE25: | | EG25: | | EI25: | | EK25: | | EM25: | | EN25: 3750 | EO25: | | EQ25: | | ES25: | | EU25: | | EV25: 157696 | EW25: | | EY25: | | FA25: | | FC25: | | FE25: | | FG25: | | FI25: | | FJ25: 85349 | FK25: | | FM25: | | FO25: | | FQ25: | | FS25: | | FU25: | | FW25: | | FY25: | | FZ25: 105 | GA25: | | GC25: | | GE25: | | GG25: | | GI25: | | GK25: | | GM25: | | GO25: | | GQ25: | | GS25: | | GU25: | | GW25: | | GY25: | | HA25: | | HC25: | | HE25: | | HF25: 394779 | HG25: | | HI25: | | HJ25: 394779 | HK25: |
A26: 1415 | B26: REGULAR DAY SCHL FRM OTH LEA'S | C26: | | E26: | | G26: | | I26: | | K26: | | L26: 28632 | M26: | | O26: | | Q26: | | S26: | | U26: | | W26: | | Y26: | | AA26: | | AC26: | | AE26: | | AG26: | | AH26: 14420 | AI26: | | AK26: | | AM26: | | AO26: | | AQ26: | | AS26: | | AU26: | | AW26: | | AY26: | | BA26: | | BC26: | | BE26: | | BG26: | | BI26: | | BK26: | | BM26: | | BO26: | | BQ26: | | BS26: | | BU26: | | BW26: | | BY26: | | CA26: | | CC26: | | CE26: | | CG26: | | CI26: | | CK26: | | CM26: | | CO26: | | CQ26: | | CS26: | | CU26: | | CW26: | | CY26: | | DA26: | | DC26: | | DE26: | | DG26: | | DI26: | | DK26: | | DM26: | | DO26: | | DQ26: | | DS26: | | DU26: | | DW26: | | DY26: | | EA26: | | EC26: | | EE26: | | EG26: | | EI26: | | EK26: | | EM26: | | EO26: | | EQ26: | | ES26: | | EU26: | | EW26: | | EY26: | | FA26: | | FC26: | | FE26: | | FG26: | | FI26: | | FK26: | | FM26: | | FO26: | | FQ26: | | FS26: | | FU26: | | FW26: | | FY26: | | GA26: | | GC26: | | GE26: | | GG26: | | GI26: | | GK26: | | GM26: | | GO26: | | GQ26: | | GS26: | | GU26: | | GW26: | | GY26: | | HA26: | | HC26: | | HE26: | | HF26: 43052 | HG26: | | HI26: | | HJ26: 43052 | HK26: |
A27: 1420 | B27: SUMMER SCHOOL FRM PATRONS | C27: | | E27: | | G27: | | I27: | | K27: | | M27: | | O27: | | Q27: | | S27: | | U27: | | W27: | | Y27: | | AA27: | | AC27: | | AE27: | | AG27: | | AI27: | | AK27: | | AM27: | | AO27: | | AQ27: | | AS27: | | AU27: | | AW27: | | AY27: | | BA27: | | BC27: | | BE27: | | BG27: | | BI27: | | BK27: | | BM27: | | BO27: | | BQ27: | | BS27: | | BU27: | | BW27: | | BY27: | | CA27: | | CC27: | | CE27: | | CG27: | | CI27: | | CK27: | | CM27: | | CO27: | | CQ27: | | CS27: | | CU27: | | CW27: | | CY27: | | DA27: | | DC27: | | DE27: | | DG27: | | DI27: | | DK27: | | DM27: | | DO27: | | DQ27: | | DS27: | | DU27: | | DW27: | | DY27: | | EA27: | | EC27: | | EE27: | | EG27: | | EI27: | | EK27: | | EM27: | | EO27: | | EQ27: | | ES27: | | EU27: | | EW27: | | EY27: | | FA27: | | FC27: | | FE27: | | FG27: | | FI27: | | FK27: | | FM27: | | FO27: | | FQ27: | | FS27: | | FU27: | | FW27: | | FY27: | | GA27: | | GC27: | | GE27: | | GG27: | | GI27: | | GK27: | | GM27: | | GO27: | | GQ27: | | GS27: | | GU27: | | GW27: | | GY27: | | HA27: | | HC27: | | HE27: | | HG27: | | HI27: | | HK27: |
A28: 1425 | B28: SUMMER SCHOOL FROM OTHER LEA'S | C28: | | E28: | | G28: | | I28: | | K28: | | M28: | | O28: | | Q28: | | S28: | | U28: | | W28: | | Y28: | | AA28: | | AC28: | | AE28: | | AG28: | | AI28: | | AK28: | | AM28: | | AO28: | | AQ28: | | AS28: | | AU28: | | AW28: | | AY28: | | BA28: | | BC28: | | BE28: | | BG28: | | BI28: | | BK28: | | BM28: | | BO28: | | BQ28: | | BS28: | | BU28: | | BW28: | | BY28: | | CA28: | | CC28: | | CE28: | | CG28: | | CI28: | | CK28: | | CM28: | | CO28: | | CQ28: | | CS28: | | CU28: | | CW28: | | CY28: | | DA28: | | DC28: | | DE28: | | DG28: | | DI28: | | DK28: | | DM28: | | DO28: | | DQ28: | | DS28: | | DU28: | | DW28: | | DY28: | | EA28: | | EC28: | | EE28: | | EG28: | | EI28: | | EK28: | | EM28: | | EO28: | | EQ28: | | ES28: | | EU28: | | EW28: | | EY28: | | FA28: | | FC28: | | FE28: | | FG28: | | FI28: | | FK28: | | FM28: | | FO28: | | FQ28: | | FS28: | | FU28: | | FW28: | | FY28: | | GA28: | | GC28: | | GE28: | | GG28: | | GI28: | | GK28: | | GM28: | | GO28: | | GQ28: | | GS28: | | GU28: | | GW28: | | GY28: | | HA28: | | HC28: | | HE28: | | HG28: | | HI28: | | HK28: |
A29: 1500 | B29: EARNINGS ON INVESTMENTS: | C29: | | E29: | | G29: | | I29: | | K29: | | M29: | | O29: | | Q29: | | S29: | | U29: | | W29: | | Y29: | | AA29: | | AC29: | | AE29: | | AG29: | | AI29: | | AK29: | | AM29: | | AO29: | | AQ29: | | AS29: | | AU29: | | AW29: | | AY29: | | BA29: | | BC29: | | BE29: | | BG29: | | BI29: | | BK29: | | BM29: | | BO29: | | BQ29: | | BS29: | | BU29: | | BW29: | | BY29: | | CA29: | | CC29: | | CE29: | | CG29: | | CI29: | | CK29: | | CM29: | | CO29: | | CQ29: | | CS29: | | CU29: | | CW29: | | CY29: | | DA29: | | DC29: | | DE29: | | DG29: | | DI29: | | DK29: | | DM29: | | DO29: | | DQ29: | | DS29: | | DU29: | | DW29: | | DY29: | | EA29: | | EC29: | | EE29: | | EG29: | | EI29: | | EK29: | | EM29: | | EO29: | | EQ29: | | ES29: | | EU29: | | EW29: | | EY29: | | FA29: | | FC29: | | FE29: | | FG29: | | FI29: | | FK29: | | FM29: | | FO29: | | FQ29: | | FS29: | | FU29: | | FW29: | | FY29: | | GA29: | | GC29: | | GE29: | | GG29: | | GI29: | | GK29: | | GM29: | | GO29: | | GQ29: | | GS29: | | GU29: | | GW29: | | GY29: | | HA29: | | HC29: | | HE29: | | HG29: | | HI29: | | HK29: |
A30: 1510 | B30: INTEREST ON INVESTMENTS | C30: | | D30: 134656 | E30: | | F30: 1019518 | G30: | | H30: 26508 | I30: | | J30: 14227 | K30: | | L30: 382520 | M30: | | N30: 175851 | O30: | | P30: 593746 | Q30: | | R30: 1393711 | S30: | | T30: 995816 | U30: | | V30: 24583 | W30: | | X30: 101910 | Y30: | | Z30: 86610 | AA30: | | AB30: 31703 | AC30: | | AD30: 33738 | AE30: | | AF30: 51617 | AG30: | | AH30: 283442 | AI30: | | AJ30: 3750 | AK30: | | AL30: 6091855 | AM30: | | AN30: 17315 | AO30: | | AP30: 9966532 | AQ30: | | AR30: 1039571 | AS30: | | AT30: 31663984 | AU30: | | AV30: 2551948 | AW30: | | AX30: 657255 | AY30: | | AZ30: 775806 | BA30: | | BB30: 480114 | BC30: | | BD30: 157046 | BE30: | | BF30: 95143 | BG30: | | BH30: 77 | BI30: | | BJ30: 2944533 | BK30: | | BL30: 2511589 | BM30: | | BN30: 61978 | BO30: | | BP30: 25012 | BQ30: | | BR30: 213591 | BS30: | | BT30: 146640 | BU30: | | BV30: 10776 | BW30: | | BX30: 6061613 | BY30: | | BZ30: 328116 | CA30: | | CB30: 70250 | CC30: | | CD30: 263705 | CE30: | | CF30: 455917 | CG30: | | CH30: 2392922 | CI30: | | CJ30: 22739 | CK30: | | CL30: 447808 | CM30: | | CN30: 65072 | CO30: | | CP30: 173768 | CQ30: | | CR30: 1222449 | CS30: | | CT30: 26367262 | CU30: | | CV30: 3868814 | CW30: | | CX30: 140798 | CY30: | | CZ30: 148978 | DA30: | | DB30: 15150 | DC30: | | DD30: 78885 | DE30: | | DF30: 99706 | DG30: | | DH30: 9414516 | DI30: | | DJ30: 858451 | DK30: | | DL30: 6396413 | DM30: | | DN30: 2710836 | DO30: | | DP30: 891984 | DQ30: | | DR30: 1098339 | DS30: | | DT30: 256399 | DU30: | | DV30: 8581616 | DW30: | | DX30: 1636238 | DY30: | | DZ30: 159922 | EA30: | | EB30: 414131 | EC30: | | ED30: 1932695 | EE30: | | EF30: 121817 | EG30: | | EH30: 88904 | EI30: | | EJ30: 317612 | EK30: | | EL30: 295666 | EM30: | | EN30: 93279 | EO30: | | EP30: 50194 | EQ30: | | ER30: 125350 | ES30: | | ET30: 3580991 | EU30: | | EV30: 1454347 | EW30: | | EY30: | | EZ30: 412277 | FA30: | | FB30: 386574 | FC30: | | FD30: 1137980 | FE30: | | FF30: 2297 | FG30: | | FH30: 9208926 | FI30: | | FJ30: 7846289 | FK30: | | FL30: 5121247 | FM30: | | FN30: 159958 | FO30: | | FP30: 1053150 | FQ30: | | FR30: 1413118 | FS30: | | FT30: 802732 | FU30: | | FV30: 520570 | FW30: | | FX30: 3698436 | FY30: | | FZ30: 1076282 | GA30: | | GB30: 1152244 | GC30: | | GD30: 3680 | GE30: | | GF30: 21482 | GG30: | | GH30: 19850 | GI30: | | GJ30: 2016865 | GK30: | | GL30: 1476955 | GM30: | | GO30: | | GP30: 1460897 | GQ30: | | GR30: 721203 | GS30: | | GT30: 760084 | GU30: | | GV30: 1333915 | GW30: | | GX30: 3715398 | GY30: | | GZ30: 3658618 | HA30: | | HC30: | | HE30: | | HF30: 196649350 | HG30: | | HI30: | | HJ30: 196649350 | HK30: |
A31: 1520 | B31: DIVIDENDS ON INVESTMENTS | C31: | | E31: | | F31: 156526 | G31: | | I31: | | K31: | | M31: | | O31: | | Q31: | | S31: | | U31: | | W31: | | Y31: | | AA31: | | AC31: | | AE31: | | AG31: | | AI31: | | AK31: | | AM31: | | AO31: | | AQ31: | | AS31: | | AU31: | | AW31: | | AY31: | | BA31: | | BC31: | | BE31: | | BG31: | | BI31: | | BK31: | | BM31: | | BO31: | | BQ31: | | BS31: | | BU31: | | BW31: | | BY31: | | CA31: | | CC31: | | CE31: | | CG31: | | CI31: | | CK31: | | CM31: | | CO31: | | CQ31: | | CS31: | | CU31: | | CW31: | | CY31: | | DA31: | | DC31: | | DE31: | | DG31: | | DI31: | | DK31: | | DM31: | | DO31: | | DQ31: | | DS31: | | DU31: | | DW31: | | DY31: | | EA31: | | EC31: | | EE31: | | EG31: | | EI31: | | EK31: | | EM31: | | EO31: | | EQ31: | | ES31: | | EU31: | | EW31: | | EY31: | | FA31: | | FC31: | | FE31: | | FG31: | | FI31: | | FK31: | | FM31: | | FO31: | | FQ31: | | FS31: | | FU31: | | FW31: | | FY31: | | GA31: | | GC31: | | GE31: | | GG31: | | GI31: | | GK31: | | GM31: | | GO31: | | GQ31: | | GS31: | | GU31: | | GW31: | | GY31: | | HA31: | | HC31: | | HE31: | | HF31: 156526 | HG31: | | HI31: | | HJ31: 156526 | HK31: |
A32: 1530 | B32: GAIN/LOSS ON SALE OF INVEST | C32: | | E32: | | G32: | | I32: | | K32: | | M32: | | O32: | | Q32: | | S32: | | U32: | | W32: | | Y32: | | AA32: | | AC32: | | AE32: | | AG32: | | AI32: | | AK32: | | AM32: | | AO32: | | AQ32: | | AS32: | | AU32: | | AV32: 22159 | AW32: | | AY32: | | BA32: | | BC32: | | BE32: | | BG32: | | BI32: | | BK32: | | BM32: | | BO32: | | BQ32: | | BS32: | | BU32: | | BW32: | | BY32: | | CA32: | | CC32: | | CE32: | | CG32: | | CI32: | | CK32: | | CM32: | | CO32: | | CQ32: | | CS32: | | CT32: 123830 | CU32: | | CW32: | | CY32: | | DA32: | | DC32: | | DE32: | | DG32: | | DI32: | | DK32: | | DM32: | | DO32: | | DQ32: | | DS32: | | DU32: | | DW32: | | DY32: | | EA32: | | EC32: | | EE32: | | EG32: | | EI32: | | EK32: | | EM32: | | EO32: | | EQ32: | | ES32: | | EU32: | | EW32: | | EY32: | | FA32: | | FC32: | | FE32: | | FG32: | | FI32: | | FJ32: 31128 | FK32: | | FM32: | | FO32: | | FQ32: | | FS32: | | FU32: | | FW32: | | FY32: | | GA32: | | GC32: | | GE32: | | GG32: | | GI32: | | GK32: | | GM32: | | GO32: | | GQ32: | | GS32: | | GU32: | | GW32: | | GY32: | | HA32: | | HC32: | | HE32: | | HF32: 177117 | HG32: | | HI32: | | HJ32: 177117 | HK32: |
A33: 1600 | B33: FOOD SERVICE: | C33: | | E33: | | G33: | | I33: | | K33: | | M33: | | O33: | | Q33: | | S33: | | U33: | | W33: | | Y33: | | AA33: | | AC33: | | AE33: | | AG33: | | AI33: | | AK33: | | AM33: | | AO33: | | AQ33: | | AS33: | | AU33: | | AW33: | | AY33: | | BA33: | | BC33: | | BE33: | | BG33: | | BI33: | | BK33: | | BM33: | | BO33: | | BQ33: | | BS33: | | BU33: | | BW33: | | BY33: | | CA33: | | CC33: | | CE33: | | CG33: | | CI33: | | CK33: | | CM33: | | CO33: | | CQ33: | | CS33: | | CU33: | | CW33: | | CY33: | | DA33: | | DC33: | | DE33: | | DG33: | | DI33: | | DK33: | | DM33: | | DO33: | | DQ33: | | DS33: | | DU33: | | DW33: | | DY33: | | EA33: | | EC33: | | EE33: | | EG33: | | EI33: | | EK33: | | EM33: | | EO33: | | EQ33: | | ES33: | | EU33: | | EW33: | | EY33: | | FA33: | | FC33: | | FE33: | | FG33: | | FI33: | | FK33: | | FM33: | | FO33: | | FQ33: | | FS33: | | FU33: | | FW33: | | FY33: | | GA33: | | GC33: | | GE33: | | GG33: | | GI33: | | GK33: | | GM33: | | GO33: | | GQ33: | | GS33: | | GU33: | | GW33: | | GY33: | | HA33: | | HC33: | | HE33: | | HG33: | | HI33: | | HK33: |
