Workbook
Name Active_Inactive: Other!$B$2:$B$3
Name bdg_fmp: '2a - Budget Detail'!$J$8:$J$500
Name bdgCost: '2a - Budget Detail'!$E$8:$E$500
Name bdgObj: '2a - Budget Detail'!$K$8:$K$500
Name bdgProg: '2a - Budget Detail'!$I$8:$I$500
Name cderange: '1-Cover Page'!$B$24:$C$24
Name coverpage: '1-Cover Page'!#REF!
Name eqpAdmin: #REF!
Name eqpAdmin: #REF!
Name eqpCapitilized: #REF!
Name eqpCapitilized: #REF!
Name eqpCost: #REF!
Name eqpCost: #REF!
Name Federal_Match_ProgramIncome: Other!$B$29:$B$31
Name funding: Other!#REF!
Name funding: Other!#REF!
Name funding2: [1]Other!#REF!
Name funding2: [1]Other!#REF!
Name fundingequipment: Other!#REF!
Name fundingequipment: Other!#REF!
Name gotoB: Other!#REF!
Name gotoB: Other!#REF!
Name incCost: #REF!
Name incCost: #REF!
Name incObj: #REF!
Name incObj: #REF!
Name incProg: #REF!
Name incProg: #REF!
Name line1_6a: '4a - Budget Summary'!$A$6
Name line1_6a: 'Corrections % Summary'!$A$6
Name look1: #REF!
Name look1: #REF!
Name look2: Other!$B$85:$C$89
Name matCost: #REF!
Name matObj: #REF!
Name matProg: #REF!
Name object: Other!$B$47:$B$51
Name program: Other!$B$38:$B$40
Name program2: Other!#REF!
Name program2: Other!#REF!
Name report: Other!$B$56:$B$57
Name signover: #REF!
Name signover: #REF!
Name signovercol1: #REF!
Name signovercol1: #REF!
Name source1: Other!$B$9:$B$15
Name source1single: Other!#REF!
Name source1single: Other!#REF!
Name staff_fmp: '3a - Staff Detail'!$L$7:$L$500
Name staffCostIA: '3a - Staff Detail'!$H$7:$H$500
Name staffobj: '3a - Staff Detail'!$M$7:$M$500
Name staffprog: '3a - Staff Detail'!$N$7:$N$500
Name title1req: Other!#REF!
Name title1req: Other!#REF!
Name transfers: Other!$B$84:$B$88
Name Yes_No: Other!$B$9:$B$10
Name YesNo: Other!#REF!
Name YesNo: Other!#REF!
Name yesnocap: Other!$B$73:$B$74

Sheet Federal Guidance
A1: The Adult Education and Family Literacy Act, Title II of the Workforce Investment Act of 1998 (P.L. 105-220) with Title V Provisions
A2: FEDERAL REGULATIONS
A3: School Districts
A4: OMB A-87-Cost Principles for State, Local and Indian Tribal Governments http://www.whitehouse.gov/omb/circulars_a087_2004
A5: Appendix B of this Circular provides - Selected Items of Costs
A6: Education Department General Administrative Regulations (EDGAR) Part 80 Uniform Administrative Requirements for Grants and Cooperative Agreements to State and Local Governments
A7: Institutions of Higher Education
A8: OMB A-21-Cost Principles for Educational Institutions http://www.whitehouse.gov/omb/circulars_a021_2004
A9: Education Department General Administrative Regulations (EDGAR) Part 74 Administration of Grants and Agreements with Institutions of Higher Education, Hospital and other Non-Profit Organizations
A10: Non-Profit Organizations
A11: OMB A-122-Cost Principles for Non-Profit Organizations http://www.whitehouse.gov/omb/circulars_a122_2004
A12: Education Department General Administrative Regulations (EDGAR) Part 74 Administration of Grants and Agreements with Institutions of Higher Education, Hospital and other Non-Profit Organizations
... A19: This grant does not allow indirect costs to be charged to the grant. A maximum of 5% of the total amount being requested can be directed to Administrative costs; however, a higher rate may be negotiated with CDE. See instructions for Sheet 6a-Comments on Instruction Tab.

Sheet Instructions
B1: Colorado Department of Education/Grants Fiscal Management
B2: Adult Education and Family Literacy Budget Instructions
B3: FY2014-15
B4: ADULT EDUCATION & FAMILY LITERACY GRANT REQUIREMENTS
B5: General Budget Comments:
B6: The budget document must contain language within the description that provide a direct tie to the application/narrative. (EXAMPLE: On 2a Budget, $2,000 is budgeted for Purchased Professional Services. The description would include the section of the application where this activity is described. For example this cost may be part of the Section G: Instructional Staff Qualification and/or Section H Professional Development.
B7: Enter dollar amounts as whole dollars. Do not enter cent amounts.
B8: Enter data in white cells only.
B10: If a cell background turns red, it means something is wrong or incomplete - either the cell itself or an associated cell. Do not submit this file if it contains any cells with a red background; call Office of Grants Fiscal for assistance. Contact information on the Cover Page
A13: Line | B13: 1-Cover Page sheet
A14: 1 | B14: Enter the legal name of the agency submitting grant. Do not use a program name.
A15: 2 | B15: Enter the agency's Dun and Bradstreet Number (DUNS) - REQUIRED FIELD | C15: http://fedgov.dnb.com/webform
A16: 3 | B16: Enter the agency's current status (ACTIVE/INACTIVE) with the System for Award Management (SAM) - REQUIRED FIELD | C16: https://www.sam.gov/portal/public/SAM/#1
A17: 4 | B17: Select Original or Revised from the dropdown.
A18: 5 | B18: If revisions are submitted, revision number is required.
A19: 6 | B19: Enter the date the budget is completed. This field must be updated when revisions are submitted.
A20: 7 | B20: Enter the name of the person completing the form along with the fiscal contact.
A21: 8 | B21: Enter the phone number for both individuals.
A22: 9 | B22: Enter the e-mail for both individuals.
B24: 2a-Budget Detail
B25: All non-salary expenditures for AEFLA, Match and Program Income funds will be entered on this sheet. A drop-down has been added to this worksheet for:
B26: AEFLA Federal Grant-Required
B27: Match-Required
B28: Program Income-Required if generated under the proposed AEFLA Program
B29: The entries made on this sheet subtotal on the 4a-Budget Summary.
B30: REMINDER: Enter the non-salary expenditures only.
A32: 1 | B32: Enter the % of the expenditure that will benefit corrections education/community corrections/institutionalized students
A34: 2 | B34: Select Instructional Program ABE/ESL, Instructional Program ASE or Administration from the dropdown.
A36: 3 | B36: Select Federal/Match/Program Income from the dropdown. This is the designation of the funds being budgeted.
B37: ●Federal: Expenditures to be paid with the AEFLA grant funds
B38: ●Match: Those non-federal expenditures that have been identified to meet the 40% match requirement
B39: ●Program Income: Those expenditures that will be covered by any program income collected by the AEFLA funded program. ALL program income must be used before the AEFLA federal funds.
A41: 4 | B41: Select the Budget Object from the dropdown. Reminder: Do not enter salaries on this page.
A43: 5 | B43: Enter the amount budgeted. Reminder: Use whole dollars.
A45: 6 | B45: Detailed information is to be entered to support each expense. Example: Employee benefits-not sufficient vs. Employee benefits for 4 teachers and 2 support staff-sufficient.
A47: 7 | B47: REQUIRED IF MATCH IS BEING BUDGETED: If "Match" is chosen in column 3 you must add the source of match. Reminder - Federal Funds can't be used for match. Example: Grant from ABC Company
A49: 8 | B49: REQUIRED IF MATCH IS BEING BUDGETED: Confirm that the match funds described in column 7 are not federal funds.
B51: 3a-Staff Detail
B52: This sheet is to identify salary expenses as they relate to this budget. The entries made on this sheet subtotal on the 4a-Budget Summary.
A54: 1 | B54: Enter the % of the expenditure that will benefit corrections education/community corrections/institutionalized students
...

Sheet 1-Cover Page
B1: 1-Cover Page
B2: Colorado Department of Education/Office of Grants Fiscal
B4: =C24 -> 14-15v9 | C4: CFDA #: 84.002 GRANT CODE: 5002
B5: Program | C5: Adult Education and Literacy Budget Form
A6: 1 | B6: AGENCY NAME: | D6: Do not enter a program name.
A7: 2 | B7: 9- DIGIT DUNS #:
A8: 3 | B8: REGISTERED WITH SYSTEM OF AWARD MANAGEMENT (SAM):
A9: 4 | B9: select Original or Revised Budget Report:
A10: 5 | B10: Revision number:
A11: 6 | B11: Date:
B13: Person completing this information | C13: Program Manager/Program Name | D13: Fiscal Manager
A14: 7 | B14: Name: | G14: 5
A15: 8 | B15: Phone No.: | G15: 6
A16: 9 | B16: E-mail: | G16: 7
A18: 10 | B18: Electronic file to this e-mail address: | C18: Electronic_budget@cde.state.co.us
B20: Grants Fiscal Staff Contact | C20: Phone No. E-mail Address
B21: Ron Mosness | C21: 303-866-6905 mosness_r@cde.state.co.us
B24: Version: | C24: 14-15v9

Sheet 2a - Budget Detail
A1: 2a-AEFLA BUDGET DETAIL
A2: ='1-Cover Page'!C5 -> Adult Education and Literacy Budget Form
B3: ='1-Cover Page'!$C$6 -> 0
B4: ='1-Cover Page'!$C$24 -> 14-15v9
A5: 1 | B5: 2 | C5: 3 | D5: 4 | E5: 5 | F5: 6 | G5: 7 | H5: 8
A6: Percentage Directed to Corrections Education/Community Corrections/Institutionalized Students | B6: Program | C6: Federal/Match/Program Income | D6: Budget Object | E6: Amount | F6: Description | G6: Source of MATCH OR Source of PROGRAM INCOME | H6: Is the source of MATCH funds from Federal grant | L6: Percentage Directed to Corrections Education/Community Corrections/Institutionalized Students
E7: =SUM(E8:E500) -> 0
I8: =RIGHT($B8,3) | J8: =LEFT($C8,2) | K8: =RIGHT($D8,6) | L8: =E8*A8 -> 0
I9: =RIGHT($B9,3) | J9: =LEFT($C9,2) | K9: =RIGHT($D9,6) | L9: =E9*A9 -> 0
I10: =RIGHT($B10,3) | J10: =LEFT($C10,2) | K10: =RIGHT($D10,6) | L10: =E10*A10 -> 0
I11: =RIGHT($B11,3) | J11: =LEFT($C11,2) | K11: =RIGHT($D11,6) | L11: =E11*A11 -> 0
I12: =RIGHT($B12,3) | J12: =LEFT($C12,2) | K12: =RIGHT($D12,6) | L12: =E12*A12 -> 0
I13: =RIGHT($B13,3) | J13: =LEFT($C13,2) | K13: =RIGHT($D13,6) | L13: =E13*A13 -> 0
I14: =RIGHT($B14,3) | J14: =LEFT($C14,2) | K14: =RIGHT($D14,6) | L14: =E14*A14 -> 0
I15: =RIGHT($B15,3) | J15: =LEFT($C15,2) | K15: =RIGHT($D15,6) | L15: =E15*A15 -> 0
I16: =RIGHT($B16,3) | J16: =LEFT($C16,2) | K16: =RIGHT($D16,6) | L16: =E16*A16 -> 0
I17: =RIGHT($B17,3) | J17: =LEFT($C17,2) | K17: =RIGHT($D17,6) | L17: =E17*A17 -> 0
I18: =RIGHT($B18,3) | J18: =LEFT($C18,2) | K18: =RIGHT($D18,6) | L18: =E18*A18 -> 0
I19: =RIGHT($B19,3) | J19: =LEFT($C19,2) | K19: =RIGHT($D19,6) | L19: =E19*A19 -> 0
... I500: =RIGHT($B500,3) | J500: =LEFT($C500,2) | K500: =RIGHT($D500,6) | L500: =E500*A500 -> 0

Sheet 3a - Staff Detail
C1: ='1-Cover Page'!$C$9&" "&TEXT('1-Cover Page'!$C$11,"mm/dd/yy") | E1: 3a-AEFLA STAFF DETAIL
C2: ='1-Cover Page'!$C$6 -> 0 | E2: ='1-Cover Page'!C5 -> Adult Education and Literacy Budget Form
C3: ='1-Cover Page'!$C$24 -> 14-15v9
A4: 1 | B4: 2 | C4: 3 | D4: 4 | E4: 5 | F4: 6 | G4: 7 | H4: 8 | I4: 9 | J4: 10 | K4: 11
A5: Percentage Directed to Corrections Education/Community Corrections/Institutionalized Students | B5: Federal/Match/Program Income | C5: Name of Staff | D5: Position/ Title | E5: Site | F5: Program-Instructional-ABE/ESL, Instructional-ASE, Administration | G5: FTE | H5: Amount | I5: Description | J5: Source of MATCH OR PROGRAM INCOME | K5: Is the source of Match funds from Federal grant | O5: Percentage Directed to Corrections Education/Community Corrections/Institutionalized Students
C6: Total | G6: =SUM(G7:G500) -> 0 | H6: =SUM(H7:H500) -> 0
L7: =LEFT(B7,2) | M7: (0100) | N7: =RIGHT(F7,3) | O7: =H7*A7 -> 0
L8: =LEFT(B8,2) | M8: (0100) | N8: =RIGHT(F8,3) | O8: =H8*A8 -> 0
L9: =LEFT(B9,2) | M9: (0100) | N9: =RIGHT(F9,3) | O9: =H9*A9 -> 0
L10: =LEFT(B10,2) | M10: (0100) | N10: =RIGHT(F10,3) | O10: =H10*A10 -> 0
L11: =LEFT(B11,2) | M11: (0100) | N11: =RIGHT(F11,3) | O11: =H11*A11 -> 0
L12: =LEFT(B12,2) | M12: (0100) | N12: =RIGHT(F12,3) | O12: =H12*A12 -> 0
L13: =LEFT(B13,2) | M13: (0100) | N13: =RIGHT(F13,3) | O13: =H13*A13 -> 0
L14: =LEFT(B14,2) | M14: (0100) | N14: =RIGHT(F14,3) | O14: =H14*A14 -> 0
L15: =LEFT(B15,2) | M15: (0100) | N15: =RIGHT(F15,3) | O15: =H15*A15 -> 0
L16: =LEFT(B16,2) | M16: (0100) | N16: =RIGHT(F16,3) | O16: =H16*A16 -> 0
L17: =LEFT(B17,2) | M17: (0100) | N17: =RIGHT(F17,3) | O17: =H17*A17 -> 0
L18: =LEFT(B18,2) | M18: (0100) | N18: =RIGHT(F18,3) | O18: =H18*A18 -> 0
... L500: =LEFT(B500,2) | M500: (0100) | N500: =RIGHT(F500,3) | O500: =H500*A500 -> 0
O501: =SUM(O7:O500) -> 0

Sheet 4a - Budget Summary
A1: ='1-Cover Page'!$C$24 -> 14-15v9 | B1: 4a -Budget Summary
B2: ='1-Cover Page'!C5 -> Adult Education and Literacy Budget Form
A3: ='1-Cover Page'!$C$6 -> 0
A4: ='1-Cover Page'!$C$9&" "&TEXT('1-Cover Page'!$C$11,"mm/dd/yy")
A5: Line | B5: =IF(LEFT('5a-Error Checking'!I9,3)<>"not","Description","ERROR!! Check Error Sheet") -> Description | D5: AEFLA Federal | E5: AEFLA Match | F5: AEFLA Program Income
A6: 1 | B6: Current Year Allocation/Match/Anticipated Program Income | D6: 0 | E6: 0 | F6: 0
A7: INSTRUCTIONAL SERVICES MUST BE GREATER THAN OR = 95% OF TOTAL BUDGET REQUEST
A8: Instructional Program (0010 – 2000) - ABE/ESL
A9: 2 | B9: Salaries (0100) | C9: (0100) | D9: =SUMIFS(staffCostIA,staff_fmp,"Fe",staffprog,"ESL") -> 0 | E9: =SUMIFS(staffCostIA,staff_fmp,"Ma",staffprog,"ESL") -> 0 | F9: =SUMIFS(staffCostIA,staff_fmp,"Pr",staffprog,"ESL") -> 0
A10: 3 | B10: Employee Benefits (0200) | C10: (0200) | D10: =SUMIFS(bdgCost,bdgProg,"ESL",bdg_fmp,"Fe",bdgObj,$C10) -> 0 | E10: =SUMIFS(bdgCost,bdgProg,"ESL",bdg_fmp,"Ma",bdgObj,$C10) -> 0 | F10: =SUMIFS(bdgCost,bdgProg,"ESL",bdg_fmp,"pr",bdgObj,$C10) -> 0
A11: 4 | B11: Purchased Professional & Technical Services (0300) | C11: (0300) | D11: =SUMIFS(bdgCost,bdgProg,"ESL",bdg_fmp,"Fe",bdgObj,$C11) -> 0 | E11: =SUMIFS(bdgCost,bdgProg,"ESL",bdg_fmp,"Ma",bdgObj,$C11) -> 0 | F11: =SUMIFS(bdgCost,bdgProg,"ESL",bdg_fmp,"pr",bdgObj,$C11) -> 0
A12: 5 | B12: Other Purchased Services (0500) | C12: (0500) | D12: =SUMIFS(bdgCost,bdgProg,"ESL",bdg_fmp,"Fe",bdgObj,$C12) -> 0 | E12: =SUMIFS(bdgCost,bdgProg,"ESL",bdg_fmp,"Ma",bdgObj,$C12) -> 0 | F12: =SUMIFS(bdgCost,bdgProg,"ESL",bdg_fmp,"pr",bdgObj,$C12) -> 0
A13: 6 | B13: Supplies (0600) | C13: (0600) | D13: =SUMIFS(bdgCost,bdgProg,"ESL",bdg_fmp,"Fe",bdgObj,$C13) -> 0 | E13: =SUMIFS(bdgCost,bdgProg,"ESL",bdg_fmp,"Ma",bdgObj,$C13) -> 0 | F13: =SUMIFS(bdgCost,bdgProg,"ESL",bdg_fmp,"pr",bdgObj,$C13) -> 0
A14: 7 | B14: Equipment (0730) | C14: (0730) | D14: =SUMIFS(bdgCost,bdgProg,"ESL",bdg_fmp,"Fe",bdgObj,$C14) -> 0 | E14: =SUMIFS(bdgCost,bdgProg,"ESL",bdg_fmp,"Ma",bdgObj,$C14) -> 0 | F14: =SUMIFS(bdgCost,bdgProg,"ESL",bdg_fmp,"pr",bdgObj,$C14) -> 0
A15: 8 | B15: Subtotal Instructional Program ABE/ESL | D15: =SUM(D9:D14) -> 0 | E15: =SUM(E9:E14) -> 0 | F15: =SUM(F9:F14) -> 0
A16: Instructional Program (0010-2000) ASE
A17: 9 | B17: Salaries (0100) | C17: (0100) | D17: =SUMIFS(staffCostIA,staff_fmp,"Fe",staffprog,"ASE") -> 0 | E17: =SUMIFS(staffCostIA,staff_fmp,"Ma",staffprog,"ASE") -> 0 | F17: =SUMIFS(staffCostIA,staff_fmp,"Pr",staffprog,"ASE") -> 0
A18: 10 | B18: Employee Benefits (0200) | C18: (0200) | D18: =SUMIFS(bdgCost,bdgProg,"ASE",bdg_fmp,"Fe",bdgObj,$C18) -> 0 | E18: =SUMIFS(bdgCost,bdgProg,"ASE",bdg_fmp,"Ma",bdgObj,$C18) -> 0 | F18: =SUMIFS(bdgCost,bdgProg,"ASE",bdg_fmp,"pr",bdgObj,$C18) -> 0
A19: 11 | B19: Purchased Professional & Technical Services (0300) | C19: (0300) | D19: =SUMIFS(bdgCost,bdgProg,"ASE",bdg_fmp,"Fe",bdgObj,$C19) -> 0 | E19: =SUMIFS(bdgCost,bdgProg,"ASE",bdg_fmp,"Ma",bdgObj,$C19) -> 0 | F19: =SUMIFS(bdgCost,bdgProg,"ASE",bdg_fmp,"pr",bdgObj,$C19) -> 0
A20: 12 | B20: Other Purchased Services (0500) | C20: (0500) | D20: =SUMIFS(bdgCost,bdgProg,"ASE",bdg_fmp,"Fe",bdgObj,$C20) -> 0 | E20: =SUMIFS(bdgCost,bdgProg,"ASE",bdg_fmp,"Ma",bdgObj,$C20) -> 0 | F20: =SUMIFS(bdgCost,bdgProg,"ASE",bdg_fmp,"pr",bdgObj,$C20) -> 0
A21: 13 | B21: Supplies (0600) | C21: (0600) | D21: =SUMIFS(bdgCost,bdgProg,"ASE",bdg_fmp,"Fe",bdgObj,$C21) -> 0 | E21: =SUMIFS(bdgCost,bdgProg,"ASE",bdg_fmp,"Ma",bdgObj,$C21) -> 0 | F21: =SUMIFS(bdgCost,bdgProg,"ASE",bdg_fmp,"pr",bdgObj,$C21) -> 0
A22: 14 | B22: Equipment (0730) | C22: (0730) | D22: =SUMIFS(bdgCost,bdgProg,"ASE",bdg_fmp,"Fe",bdgObj,$C22) -> 0 | E22: =SUMIFS(bdgCost,bdgProg,"ASE",bdg_fmp,"Ma",bdgObj,$C22) -> 0 | F22: =SUMIFS(bdgCost,bdgProg,"ASE",bdg_fmp,"pr",bdgObj,$C22) -> 0
A23: 15 | B23: Subtotal Instructional Program ASE | D23: =SUM(D17:D22) -> 0 | E23: =SUM(E17:E22) -> 0 | F23: =SUM(F17:F22) -> 0
A24: Administration (2300, 2400, and 2500) MAXIMUM ADMINISTRATIVE COSTS = 5%, with waiver requirement for additional amount
A25: 16 | B25: Salaries (0100) | C25: (0100) | D25: =SUMIFS(staffCostIA,staff_fmp,"Fe",staffprog,"ion") -> 0 | E25: =SUMIFS(staffCostIA,staff_fmp,"Ma",staffprog,"ion") -> 0 | F25: =SUMIFS(staffCostIA,staff_fmp,"Pr",staffprog,"ion") -> 0
A26: 17 | B26: Employee Benefits (0200) | C26: (0200) | D26: =SUMIFS(bdgCost,bdgProg,"ion",bdg_fmp,"Fe",bdgObj,$C26) -> 0 | E26: =SUMIFS(bdgCost,bdgProg,"ion",bdg_fmp,"Ma",bdgObj,$C26) -> 0 | F26: =SUMIFS(bdgCost,bdgProg,"ion",bdg_fmp,"pr",bdgObj,$C26) -> 0
A27: 18 | B27: Purchased Professional & Technical Services (0300) | C27: (0300) | D27: =SUMIFS(bdgCost,bdgProg,"ion",bdg_fmp,"Fe",bdgObj,$C27) -> 0 | E27: =SUMIFS(bdgCost,bdgProg,"ion",bdg_fmp,"Ma",bdgObj,$C27) -> 0 | F27: =SUMIFS(bdgCost,bdgProg,"ion",bdg_fmp,"pr",bdgObj,$C27) -> 0
A28: 19 | B28: Other Purchased Services (0500) | C28: (0500) | D28: =SUMIFS(bdgCost,bdgProg,"ion",bdg_fmp,"Fe",bdgObj,$C28) -> 0 | E28: =SUMIFS(bdgCost,bdgProg,"ion",bdg_fmp,"Ma",bdgObj,$C28) -> 0 | F28: =SUMIFS(bdgCost,bdgProg,"ion",bdg_fmp,"pr",bdgObj,$C28) -> 0
A29: 20 | B29: Supplies (0600) | C29: (0600) | D29: =SUMIFS(bdgCost,bdgProg,"ion",bdg_fmp,"Fe",bdgObj,$C29) -> 0 | E29: =SUMIFS(bdgCost,bdgProg,"ion",bdg_fmp,"Ma",bdgObj,$C29) -> 0 | F29: =SUMIFS(bdgCost,bdgProg,"ion",bdg_fmp,"pr",bdgObj,$C29) -> 0
A30: 21 | B30: Equipment (0730) | C30: (0730) | D30: =SUMIFS(bdgCost,bdgProg,"ion",bdg_fmp,"Fe",bdgObj,$C30) -> 0 | E30: =SUMIFS(bdgCost,bdgProg,"ion",bdg_fmp,"Ma",bdgObj,$C30) -> 0 | F30: =SUMIFS(bdgCost,bdgProg,"ion",bdg_fmp,"pr",bdgObj,$C30) -> 0
A31: 22 | B31: Subtotal Administration | D31: =SUM(D25:D30) -> 0 | E31: =SUM(E25:E30) -> 0 | F31: =SUM(F25:F30) -> 0
A33: 23 | B33: Total Budget | D33: =SUM(D15+D23+D31) -> 0 | E33: =SUM(E15+E23+E31) -> 0 | F33: =SUM(F15+F23+F31) -> 0
A35: 1 | B35: Total Funds Available (repeated from above) | D35: =D6 -> 0 | E35: =E6 -> 0 | F35: =F6 -> 0
B37: Difference - Line 1 less line 24-must be zero | D37: =D35-D33 -> 0 | E37: =E35-E33 -> 0 | F37: =F35-F33 -> 0
D79: Verification
D80: Instructional Services >/= 95% | F80: =IF(D33=0,"",(D15+D23)/D33)
D81: Match >/= 40% | F81: =IF(D33=0,"",E33/D33)

Sheet Corrections % Summary
A1: ='1-Cover Page'!$C$24 -> 14-15v9 | B1: Corrections Summary
B2: ='1-Cover Page'!C5 -> Adult Education and Literacy Budget Form
A4: ='1-Cover Page'!$C$9&" "&TEXT('1-Cover Page'!$C$11,"mm/dd/yy")
A5: Line | B5: =IF(LEFT('5a-Error Checking'!I9,3)<>"not","Description","ERROR!! Check Error Sheet") -> Description | D5: Percentage Directed to Corrections Education/Community Corrections/Institutionalized Students
A6: 1 | B6: Current Year Allocation/Match/Anticipated Program Income | D6: 0
A7: INSTRUCTIONAL SERVICES MUST BE GREATER THAN OR = 95% OF TOTAL BUDGET REQUEST
A8: Instructional Program (0010 – 2000) - ABE/ESL
A9: 2 | B9: Salaries (0100) | C9: (0100) | D9: =SUMIFS('3a - Staff Detail'!$O$7:$O$499,'3a - Staff Detail'!L7:L499,"Fe",'3a - Staff Detail'!N7:N499,"ESL") -> 0
A10: 3 | B10: Employee Benefits (0200) | C10: (0200) | D10: =SUMIFS(#REF!,#REF!,"ESL",#REF!,"Fe",#REF!,$C10) -> #REF!
A11: 4 | B11: Purchased Professional & Technical Services (0300) | C11: (0300) | D11: =SUMIFS(#REF!,#REF!,"ESL",#REF!,"Fe",#REF!,$C11) -> #REF!
A12: 5 | B12: Other Purchased Services (0500) | C12: (0500) | D12: =SUMIFS(#REF!,#REF!,"ESL",#REF!,"Fe",#REF!,$C12) -> #REF!
A13: 6 | B13: Supplies (0600) | C13: (0600) | D13: =SUMIFS(#REF!,#REF!,"ESL",#REF!,"Fe",#REF!,$C13) -> #REF!
A14: 7 | B14: Equipment (0730) | C14: (0730) | D14: =SUMIFS(#REF!,#REF!,"ESL",#REF!,"Fe",#REF!,$C14) -> #REF!
A15: 8 | B15: Subtotal Instructional Program ABE/ESL | D15: =SUM(D9:D14) -> #REF!
A16: Instructional Program (0010-2000) ASE
A17: 9 | B17: Salaries (0100) | C17: (0100) | D17: =SUMIFS('3a - Staff Detail'!$O$7:$O$499,'3a - Staff Detail'!$L$7:$L$499,"Fe",'3a - Staff Detail'!$N$7:$N$499,"ASE") -> 0
A18: 10 | B18: Employee Benefits (0200) | C18: (0200) | D18: =SUMIFS(#REF!,#REF!,"ASE",#REF!,"Fe",#REF!,$C18) -> #REF!
A19: 11 | B19: Purchased Professional & Technical Services (0300) | C19: (0300) | D19: =SUMIFS(#REF!,#REF!,"ASE",#REF!,"Fe",#REF!,$C19) -> #REF!
A20: 12 | B20: Other Purchased Services (0500) | C20: (0500) | D20: =SUMIFS(#REF!,#REF!,"ASE",#REF!,"Fe",#REF!,$C20) -> #REF!
A21: 13 | B21: Supplies (0600) | C21: (0600) | D21: =SUMIFS(#REF!,#REF!,"ASE",#REF!,"Fe",#REF!,$C21) -> #REF!
A22: 14 | B22: Equipment (0730) | C22: (0730) | D22: =SUMIFS(#REF!,#REF!,"ASE",#REF!,"Fe",#REF!,$C22) -> #REF!
A23: 15 | B23: Subtotal Instructional Program ASE | D23: =SUM(D17:D22) -> #REF!
A24: Administration (2300, 2400, and 2500) MAXIMUM ADMINISTRATIVE COSTS = 5%, with waiver requirement for additional amount
A25: 16 | B25: Salaries (0100) | C25: (0100) | D25: =SUMIFS('3a - Staff Detail'!$O$7:$O$499,'3a - Staff Detail'!$L$7:$L$499,"Fe",'3a - Staff Detail'!$N$7:$N$499,"ION") -> 0
A26: 17 | B26: Employee Benefits (0200) | C26: (0200) | D26: =SUMIFS(#REF!,#REF!,"ION",#REF!,"Fe",#REF!,$C26) -> #REF!
A27: 18 | B27: Purchased Professional & Technical Services (0300) | C27: (0300) | D27: =SUMIFS(#REF!,#REF!,"ION",#REF!,"Fe",#REF!,$C27) -> #REF!
A28: 19 | B28: Other Purchased Services (0500) | C28: (0500) | D28: =SUMIFS(#REF!,#REF!,"ION",#REF!,"Fe",#REF!,$C28) -> #REF!
A29: 20 | B29: Supplies (0600) | C29: (0600) | D29: =SUMIFS(#REF!,#REF!,"ION",#REF!,"Fe",#REF!,$C29) -> #REF!
A30: 21 | B30: Equipment (0730) | C30: (0730) | D30: =SUMIFS(#REF!,#REF!,"ION",#REF!,"Fe",#REF!,$C30) -> #REF!
A31: 22 | B31: Subtotal Administration | D31: =SUM(D25:D30) -> #REF!
A33: 23 | B33: Total Budget | D33: =SUM(D15+D23+D31) -> #REF!
A35: 1 | B35: Total Funds Available (repeated from above) | D35: =D6 -> 0

Sheet 5a-Error Checking
D1: =IF(OR(I9<>"equal"),"ERROR!","") | F1: 5-Error Checking | I1: ='1-Cover Page'!$C$9&" "&TEXT('1-Cover Page'!$C$11,"mm/dd/yy")
F2: ='1-Cover Page'!C5 -> Adult Education and Literacy Budget Form
B3: ='1-Cover Page'!$C$6 -> 0
B4: ='1-Cover Page'!$C$24 -> 14-15v9
D6: Detail Sheets 2a, 3a | G6: 4a Budget Summary | I6: Equal?
C9: Total | E9: =+'2a - Budget Detail'!E7+'3a - Staff Detail'!H6 -> 0 | F9: =IF(E9=G9,"=","") -> = | G9: ='4a - Budget Summary'!D33+'4a - Budget Summary'!E33+'4a - Budget Summary'!F33 -> 0 | I9: =IF(E9=G9,"equal","not equal!") -> equal
E12: If the amounts do not equal each other, the most likely problem is on a
E13: detail sheet. All required entries may not have been entered.

Sheet 6a-Comments
B2: ='1-Cover Page'!C5 -> Adult Education and Literacy Budget Form
A4: ='1-Cover Page'!$C$6 -> 0
A5: ='1-Cover Page'!$B$4 -> 14-15v9
A6: Date | B6: Comments | C6: Initials

Sheet Other
A2: vr1 | B2: Active
B3: Inactive
A4: vr2
B9: Yes
B10: No
B29: Federal
B30: Match
B31: Program Income
B38: Instructional Program- ABE/ESL
B39: Instructional Program - ASE
B40: Administration
B42: Instructional Program - ABE/ESL
B43: Instructional Program - ASE
B44: Administration
B47: Employee Benefits (0200)
... B74: No (0735)
C78: 0500, 0800
C79: 0300, 0500
C80: 0100, '0200, 0300, 0500, 0600
C81: 0300, 0500, 0600
B84: No Transfers
B85: REAP | C85: No Transfers
B86: Non-improvement | C86: 1
B87: Improvement | C87: 0.5
B88: BOCES | C88: 0.3
C89: BOCES - see below
