Workbook

Sheet instruction-districts
B1: Full-Time Equivalents (FTEs) by Position
B2: Licensed and Classified Personnel
B3: FY 2011
B4: Local Education Agencies | C4: INSTRUCTION | K4: SUPPORT
C5: CLASSROOM TEACHERS | I5: Instructional Aides | J5: Instructional Coordinators and Supervisors | K5: Elementary Guidance Counselors | L5: Secondary Guidance Counselors | M5: Librarians and Media Specialists | N5: Library and Media Support Staff
C6: Pre-Kindergarten | E6: Kindergarten | F6: Elementary | G6: Secondary | H6: Special Education
C7: Regular | D7: Special
C8: CACTUS Database | D8: CACTUS Database | E8: CACTUS Database | F8: CACTUS Database | G8: CACTUS Database | H8: CACTUS Database | I8: Classified Personnel Report | J8: CACTUS Database | K8: CACTUS Database | L8: CACTUS Database | M8: CACTUS Database | N8: Classified Personnel Report
B9: DISTRICT
A10: 1 | B10: Alpine | C10: ='Licensed FTEs'!C7 -> 10.14 | D10: ='Licensed FTEs'!D7 -> 22.5 | E10: ='Licensed FTEs'!E7 -> 124.04 | F10: ='Licensed FTEs'!F7 -> 1342.61 | G10: ='Licensed FTEs'!G7 -> 1031.49 | H10: ='Licensed FTEs'!H7 -> 264.68 | I10: ='Classified FTEs'!C7 -> 830.99 | J10: ='Licensed FTEs'!I7+'Licensed FTEs'!J7 -> 127.09 | K10: ='Licensed FTEs'!K7 -> 0 | L10: ='Licensed FTEs'!L7 -> 82.92 | M10: ='Licensed FTEs'!M7 -> 22.64 | N10: ='Classified FTEs'!G7 -> 69
A11: 2 | B11: Beaver | C11: ='Licensed FTEs'!C8 -> 0.5 | D11: ='Licensed FTEs'!D8 -> 0 | E11: ='Licensed FTEs'!E8 -> 3.44 | F11: ='Licensed FTEs'!F8 -> 34.94 | G11: ='Licensed FTEs'!G8 -> 31.33 | H11: ='Licensed FTEs'!H8 -> 7.35 | I11: ='Classified FTEs'!C8 -> 34 | J11: ='Licensed FTEs'!I8+'Licensed FTEs'!J8 -> 0.41 | K11: ='Licensed FTEs'!K8 -> 0 | L11: ='Licensed FTEs'!L8 -> 1.53 | M11: ='Licensed FTEs'!M8 -> 0 | N11: ='Classified FTEs'!G8 -> 3
A12: 3 | B12: Box Elder | C12: ='Licensed FTEs'!C9 -> 1 | D12: ='Licensed FTEs'!D9 -> 8 | E12: ='Licensed FTEs'!E9 -> 24.81 | F12: ='Licensed FTEs'!F9 -> 186.87 | G12: ='Licensed FTEs'!G9 -> 216.79 | H12: ='Licensed FTEs'!H9 -> 50.72 | I12: ='Classified FTEs'!C9 -> 409 | J12: ='Licensed FTEs'!I9+'Licensed FTEs'!J9 -> 17.83 | K12: ='Licensed FTEs'!K9 -> 1.5 | L12: ='Licensed FTEs'!L9 -> 13.84 | M12: ='Licensed FTEs'!M9 -> 5 | N12: ='Classified FTEs'!G9 -> 10
A13: 4 | B13: Cache | C13: ='Licensed FTEs'!C10 -> 0 | D13: ='Licensed FTEs'!D10 -> 6.84 | E13: ='Licensed FTEs'!E10 -> 28.99 | F13: ='Licensed FTEs'!F10 -> 257.86 | G13: ='Licensed FTEs'!G10 -> 281.23 | H13: ='Licensed FTEs'!H10 -> 55.23 | I13: ='Classified FTEs'!C10 -> 357.78 | J13: ='Licensed FTEs'!I10+'Licensed FTEs'!J10 -> 41.27 | K13: ='Licensed FTEs'!K10 -> 0 | L13: ='Licensed FTEs'!L10 -> 18.76 | M13: ='Licensed FTEs'!M10 -> 21 | N13: ='Classified FTEs'!G10 -> 0
A14: 42 | B14: Canyons | C14: ='Licensed FTEs'!C11 -> 0 | D14: ='Licensed FTEs'!D11 -> 14 | E14: ='Licensed FTEs'!E11 -> 64.11 | F14: ='Licensed FTEs'!F11 -> 632.32 | G14: ='Licensed FTEs'!G11 -> 590.71 | H14: ='Licensed FTEs'!H11 -> 145.68 | I14: ='Classified FTEs'!C11 -> 130.38 | J14: ='Licensed FTEs'!I11+'Licensed FTEs'!J11 -> 110.16 | K14: ='Licensed FTEs'!K11 -> 0.5 | L14: ='Licensed FTEs'!L11 -> 40 | M14: ='Licensed FTEs'!M11 -> 10.99 | N14: ='Classified FTEs'!G11 -> 30.31
A15: 5 | B15: Carbon | C15: ='Licensed FTEs'!C12 -> 0 | D15: ='Licensed FTEs'!D12 -> 2 | E15: ='Licensed FTEs'!E12 -> 13 | F15: ='Licensed FTEs'!F12 -> 76.8 | G15: ='Licensed FTEs'!G12 -> 65.02 | H15: ='Licensed FTEs'!H12 -> 20.12 | I15: ='Classified FTEs'!C12 -> 82.17 | J15: ='Licensed FTEs'!I12+'Licensed FTEs'!J12 -> 12.75 | K15: ='Licensed FTEs'!K12 -> 2.6 | L15: ='Licensed FTEs'!L12 -> 4.37 | M15: ='Licensed FTEs'!M12 -> 0.86 | N15: ='Classified FTEs'!G12 -> 0
A16: 6 | B16: Daggett | C16: ='Licensed FTEs'!C13 -> 0 | D16: ='Licensed FTEs'!D13 -> 0 | E16: ='Licensed FTEs'!E13 -> 0.84 | F16: ='Licensed FTEs'!F13 -> 4.67 | G16: ='Licensed FTEs'!G13 -> 7.97 | H16: ='Licensed FTEs'!H13 -> 0.86 | I16: ='Classified FTEs'!C13 -> 7.86 | J16: ='Licensed FTEs'!I13+'Licensed FTEs'!J13 -> 2.44 | K16: ='Licensed FTEs'!K13 -> 0 | L16: ='Licensed FTEs'!L13 -> 0 | M16: ='Licensed FTEs'!M13 -> 0.03 | N16: ='Classified FTEs'!G13 -> 0
A17: 7 | B17: Davis | C17: ='Licensed FTEs'!C14 -> 1.67 | D17: ='Licensed FTEs'!D14 -> 24.33 | E17: ='Licensed FTEs'!E14 -> 134.77 | F17: ='Licensed FTEs'!F14 -> 1288.78 | G17: ='Licensed FTEs'!G14 -> 1063.95 | H17: ='Licensed FTEs'!H14 -> 300.76 | I17: ='Classified FTEs'!C14 -> 995.82 | J17: ='Licensed FTEs'!I14+'Licensed FTEs'!J14 -> 154.52 | K17: ='Licensed FTEs'!K14 -> 34 | L17: ='Licensed FTEs'!L14 -> 77.3 | M17: ='Licensed FTEs'!M14 -> 20.5 | N17: ='Classified FTEs'!G14 -> 53.25
A18: 8 | B18: Duchesne | C18: ='Licensed FTEs'!C15 -> 0 | D18: ='Licensed FTEs'!D15 -> 3 | E18: ='Licensed FTEs'!E15 -> 11.5 | F18: ='Licensed FTEs'!F15 -> 95.92 | G18: ='Licensed FTEs'!G15 -> 85.3 | H18: ='Licensed FTEs'!H15 -> 28.84 | I18: ='Classified FTEs'!C15 -> 87.1 | J18: ='Licensed FTEs'!I15+'Licensed FTEs'!J15 -> 5.69 | K18: ='Licensed FTEs'!K15 -> 0 | L18: ='Licensed FTEs'!L15 -> 5.65 | M18: ='Licensed FTEs'!M15 -> 6.34 | N18: ='Classified FTEs'!G15 -> 4.4
A19: 9 | B19: Emery | C19: ='Licensed FTEs'!C16 -> 0 | D19: ='Licensed FTEs'!D16 -> 1 | E19: ='Licensed FTEs'!E16 -> 7.5 | F19: ='Licensed FTEs'!F16 -> 54.26 | G19: ='Licensed FTEs'!G16 -> 50.09 | H19: ='Licensed FTEs'!H16 -> 13.33 | I19: ='Classified FTEs'!C16 -> 40.26 | J19: ='Licensed FTEs'!I16+'Licensed FTEs'!J16 -> 0.67 | K19: ='Licensed FTEs'!K16 -> 0 | L19: ='Licensed FTEs'!L16 -> 2 | M19: ='Licensed FTEs'!M16 -> 1.2 | N19: ='Classified FTEs'!G16 -> 8.5
A20: 10 | B20: Garfield | C20: ='Licensed FTEs'!C17 -> 0.5 | D20: ='Licensed FTEs'!D17 -> 0 | E20: ='Licensed FTEs'!E17 -> 2.74 | F20: ='Licensed FTEs'!F17 -> 24.12 | G20: ='Licensed FTEs'!G17 -> 28.5 | H20: ='Licensed FTEs'!H17 -> 5.4 | I20: ='Classified FTEs'!C17 -> 26.5 | J20: ='Licensed FTEs'!I17+'Licensed FTEs'!J17 -> 0.67 | K20: ='Licensed FTEs'!K17 -> 0.65 | L20: ='Licensed FTEs'!L17 -> 1.73 | M20: ='Licensed FTEs'!M17 -> 0 | N20: ='Classified FTEs'!G17 -> 1.5
A21: 11 | B21: Grand | C21: ='Licensed FTEs'!C18 -> 0 | D21: ='Licensed FTEs'!D18 -> 1 | E21: ='Licensed FTEs'!E18 -> 2 | F21: ='Licensed FTEs'!F18 -> 30 | G21: ='Licensed FTEs'!G18 -> 35.81 | H21: ='Licensed FTEs'!H18 -> 10 | I21: ='Classified FTEs'!C18 -> 24.06 | J21: ='Licensed FTEs'!I18+'Licensed FTEs'!J18 -> 1.25 | K21: ='Licensed FTEs'!K18 -> 0 | L21: ='Licensed FTEs'!L18 -> 2 | M21: ='Licensed FTEs'!M18 -> 1 | N21: ='Classified FTEs'!G18 -> 2.63
... A50: 35 | B50: Weber | C50: ='Licensed FTEs'!C47 -> 0 | D50: ='Licensed FTEs'!D47 -> 10 | E50: ='Licensed FTEs'!E47 -> 62.03 | F50: ='Licensed FTEs'!F47 -> 564.7 | G50: ='Licensed FTEs'!G47 -> 519.45 | H50: ='Licensed FTEs'!H47 -> 166.78 | I50: ='Classified FTEs'!C47 -> 383.9 | J50: ='Licensed FTEs'!I47+'Licensed FTEs'!J47 -> 84.97 | K50: ='Licensed FTEs'!K47 -> 18.86 | L50: ='Licensed FTEs'!L47 -> 37.28 | M50: ='Licensed FTEs'!M47 -> 13.83 | N50: ='Classified FTEs'!G47 -> 27.7
B51: DISTRICT TOTAL | C51: =SUM(C10:C50) -> 28.56 | D51: =SUM(D10:D50) -> 224.4 | E51: =SUM(E10:E50) -> 1183.56 | F51: =SUM(F10:F50) -> 10453.19 | G51: =SUM(G10:G50) -> 9433.26 | H51: =SUM(H10:H50) -> 2547.49 | I51: =SUM(I10:I50) -> 7649.45 | J51: =SUM(J10:J50) -> 1629.31 | ... N51: =SUM(N10:N50) -> 449.84
B52: CHARTER TOTAL | C52: ='instruction-charters'!C86 -> 0 | D52: ='instruction-charters'!D86 -> 0 | E52: ='instruction-charters'!E86 -> 93.02 | F52: ='instruction-charters'!F86 -> 876.12 | G52: ='instruction-charters'!G86 -> 698.7 | H52: ='instruction-charters'!H86 -> 138.41 | I52: ='instruction-charters'!I86 -> 564.55 | J52: ='instruction-charters'!J86 -> 69.76 | ... N52: ='instruction-charters'!N86 -> 7.81
B53: GRAND TOTAL | C53: =SUM(C51:C52) -> 28.56 | D53: =SUM(D51:D52) -> 224.4 | E53: =SUM(E51:E52) -> 1276.58 | F53: =SUM(F51:F52) -> 11329.31 | G53: =SUM(G51:G52) -> 10131.96 | H53: =SUM(H51:H52) -> 2685.9 | I53: =SUM(I51:I52) -> 8214 | J53: =SUM(J51:J52) -> 1699.07 | ... N53: =SUM(N51:N52) -> 457.65

Sheet instruction-charters
B1: Full-Time Equivalents (FTEs) by Position
B2: Licensed and Classified Personnel
B3: FY 2011
B4: Local Education Agencies | C4: INSTRUCTION | K4: SUPPORT
C5: CLASSROOM TEACHERS | I5: Instructional Aides | J5: Instructional Coordinators and Supervisors | K5: Elementary Guidance Counselors | L5: Secondary Guidance Counselors | M5: Librarians and Media Specialists | N5: Library and Media Support Staff
C6: Pre-Kindergarten | E6: Kindergarten | F6: Elementary | G6: Secondary | H6: Special Education
C7: Regular | D7: Special
C8: CACTUS Database | D8: CACTUS Database | E8: CACTUS Database | F8: CACTUS Database | G8: CACTUS Database | H8: CACTUS Database | I8: Classified Personnel Report | J8: CACTUS Database | K8: CACTUS Database | L8: CACTUS Database | M8: CACTUS Database | N8: Classified Personnel Report
B9: CHARTER SCHOOL
A10: 83 | B10: ACADEMY FOR MATH ENGINEERING & SCIENCE (AMES) | C10: ='Licensed FTEs'!C49 -> 0 | D10: ='Licensed FTEs'!D49 -> 0 | E10: ='Licensed FTEs'!E49 -> 0 | F10: ='Licensed FTEs'!F49 -> 0 | G10: ='Licensed FTEs'!G49 -> 19.59 | H10: ='Licensed FTEs'!H49 -> 1 | I10: ='Classified FTEs'!C49 -> 2.45 | J10: ='Licensed FTEs'!I49+'Licensed FTEs'!J49 -> 0.17 | K10: ='Licensed FTEs'!K49 -> 0 | L10: ='Licensed FTEs'!L49 -> 3 | M10: ='Licensed FTEs'!M49 -> 0 | N10: ='Classified FTEs'!G49 -> 0
A11: 8B | B11: AMERICAN LEADERSHIP ACADEMY | C11: ='Licensed FTEs'!C50 -> 0 | D11: ='Licensed FTEs'!D50 -> 0 | E11: ='Licensed FTEs'!E50 -> 3 | F11: ='Licensed FTEs'!F50 -> 25.61 | G11: ='Licensed FTEs'!G50 -> 33.18 | H11: ='Licensed FTEs'!H50 -> 6 | I11: ='Classified FTEs'!C50 -> 0 | J11: ='Licensed FTEs'!I50+'Licensed FTEs'!J50 -> 4.92 | K11: ='Licensed FTEs'!K50 -> 0.25 | L11: ='Licensed FTEs'!L50 -> 2 | M11: ='Licensed FTEs'!M50 -> 0.6 | N11: ='Classified FTEs'!G50 -> 0
A12: 74 | B12: AMERICAN PREPARATORY ACADEMY | C12: ='Licensed FTEs'!C51 -> 0 | D12: ='Licensed FTEs'!D51 -> 0 | E12: ='Licensed FTEs'!E51 -> 3 | F12: ='Licensed FTEs'!F51 -> 27.01 | G12: ='Licensed FTEs'!G51 -> 16.96 | H12: ='Licensed FTEs'!H51 -> 1 | I12: ='Classified FTEs'!C51 -> 12.88 | J12: ='Licensed FTEs'!I51+'Licensed FTEs'!J51 -> 2.69 | K12: ='Licensed FTEs'!K51 -> 0.35 | L12: ='Licensed FTEs'!L51 -> 0.35 | M12: ='Licensed FTEs'!M51 -> 0 | N12: ='Classified FTEs'!G51 -> 0
A13: 3G | B13: BEAR RIVER CHARTER SCHOOL | C13: ='Licensed FTEs'!C52 -> 0 | D13: ='Licensed FTEs'!D52 -> 0 | E13: ='Licensed FTEs'!E52 -> 0.5 | F13: ='Licensed FTEs'!F52 -> 5.9 | G13: ='Licensed FTEs'!G52 -> 3.73 | H13: ='Licensed FTEs'!H52 -> 0.5 | I13: ='Classified FTEs'!C52 -> 2.5 | J13: ='Licensed FTEs'!I52+'Licensed FTEs'!J52 -> 0.67 | K13: ='Licensed FTEs'!K52 -> 0 | L13: ='Licensed FTEs'!L52 -> 0 | M13: ='Licensed FTEs'!M52 -> 0 | N13: ='Classified FTEs'!G52 -> 0
A14: 3B | B14: BEEHIVE SCIENCE & TECHNOLOGY ACADEMY (BSTA) | C14: ='Licensed FTEs'!C53 -> 0 | D14: ='Licensed FTEs'!D53 -> 0 | E14: ='Licensed FTEs'!E53 -> 0 | F14: ='Licensed FTEs'!F53 -> 0 | G14: ='Licensed FTEs'!G53 -> 13.6 | H14: ='Licensed FTEs'!H53 -> 1.08 | I14: ='Classified FTEs'!C53 -> 0 | J14: ='Licensed FTEs'!I53+'Licensed FTEs'!J53 -> 0 | K14: ='Licensed FTEs'!K53 -> 0 | L14: ='Licensed FTEs'!L53 -> 0 | M14: ='Licensed FTEs'!M53 -> 0 | N14: ='Classified FTEs'!G53 -> 0
A15: 9D | B15: CANYON RIM ACADEMY | C15: ='Licensed FTEs'!C54 -> 0 | D15: ='Licensed FTEs'!D54 -> 0 | E15: ='Licensed FTEs'!E54 -> 2 | F15: ='Licensed FTEs'!F54 -> 18 | G15: ='Licensed FTEs'!G54 -> 0 | H15: ='Licensed FTEs'!H54 -> 1 | I15: ='Classified FTEs'!C54 -> 0 | J15: ='Licensed FTEs'!I54+'Licensed FTEs'!J54 -> 0.33 | K15: ='Licensed FTEs'!K54 -> 0 | L15: ='Licensed FTEs'!L54 -> 0 | M15: ='Licensed FTEs'!M54 -> 0 | N15: ='Classified FTEs'!G54 -> 0
A16: 2D | B16: CHANNING HALL | C16: ='Licensed FTEs'!C55 -> 0 | D16: ='Licensed FTEs'!D55 -> 0 | E16: ='Licensed FTEs'!E55 -> 2 | F16: ='Licensed FTEs'!F55 -> 18 | G16: ='Licensed FTEs'!G55 -> 9.5 | H16: ='Licensed FTEs'!H55 -> 2.51 | I16: ='Classified FTEs'!C55 -> 11.7 | J16: ='Licensed FTEs'!I55+'Licensed FTEs'!J55 -> 0.5 | K16: ='Licensed FTEs'!K55 -> 0 | L16: ='Licensed FTEs'!L55 -> 0 | M16: ='Licensed FTEs'!M55 -> 0 | N16: ='Classified FTEs'!G55 -> 1.5
A17: 87 | B17: CITY ACADEMY | C17: ='Licensed FTEs'!C56 -> 0 | D17: ='Licensed FTEs'!D56 -> 0 | E17: ='Licensed FTEs'!E56 -> 0 | F17: ='Licensed FTEs'!F56 -> 0 | G17: ='Licensed FTEs'!G56 -> 15.73 | H17: ='Licensed FTEs'!H56 -> 0 | I17: ='Classified FTEs'!C56 -> 6.4 | J17: ='Licensed FTEs'!I56+'Licensed FTEs'!J56 -> 1.72 | K17: ='Licensed FTEs'!K56 -> 0 | L17: ='Licensed FTEs'!L56 -> 1 | M17: ='Licensed FTEs'!M56 -> 0 | N17: ='Classified FTEs'!G56 -> 0.81
A18: 3E | B18: CS LEWIS ACADEMY | C18: ='Licensed FTEs'!C57 -> 0 | D18: ='Licensed FTEs'!D57 -> 0 | E18: ='Licensed FTEs'!E57 -> 2.28 | F18: ='Licensed FTEs'!F57 -> 11 | G18: ='Licensed FTEs'!G57 -> 1.5 | H18: ='Licensed FTEs'!H57 -> 1 | I18: ='Classified FTEs'!C57 -> 1.83 | J18: ='Licensed FTEs'!I57+'Licensed FTEs'!J57 -> 0 | K18: ='Licensed FTEs'!K57 -> 0 | L18: ='Licensed FTEs'!L57 -> 0 | M18: ='Licensed FTEs'!M57 -> 0 | N18: ='Classified FTEs'!G57 -> 0
A19: A3 | B19: DAVINCI ACADEMY | C19: ='Licensed FTEs'!C58 -> 0 | D19: ='Licensed FTEs'!D58 -> 0 | E19: ='Licensed FTEs'!E58 -> 0 | F19: ='Licensed FTEs'!F58 -> 0 | G19: ='Licensed FTEs'!G58 -> 18.34 | H19: ='Licensed FTEs'!H58 -> 2 | I19: ='Classified FTEs'!C58 -> 0 | J19: ='Licensed FTEs'!I58+'Licensed FTEs'!J58 -> 0 | K19: ='Licensed FTEs'!K58 -> 0 | L19: ='Licensed FTEs'!L58 -> 1 | M19: ='Licensed FTEs'!M58 -> 0.33 | N19: ='Classified FTEs'!G58 -> 0.5
A20: 4E | B20: DUAL IMMERSION ACADEMY | C20: ='Licensed FTEs'!C59 -> 0 | D20: ='Licensed FTEs'!D59 -> 0 | E20: ='Licensed FTEs'!E59 -> 4 | F20: ='Licensed FTEs'!F59 -> 11.75 | G20: ='Licensed FTEs'!G59 -> 2.8 | H20: ='Licensed FTEs'!H59 -> 2 | I20: ='Classified FTEs'!C59 -> 3 | J20: ='Licensed FTEs'!I59+'Licensed FTEs'!J59 -> 0.17 | K20: ='Licensed FTEs'!K59 -> 0 | L20: ='Licensed FTEs'!L59 -> 0 | M20: ='Licensed FTEs'!M59 -> 1 | N20: ='Classified FTEs'!G59 -> 0.5
A21: 6F | B21: EARLY LIGHT ACADEMY AT DAYBREAK | C21: ='Licensed FTEs'!C60 -> 0 | D21: ='Licensed FTEs'!D60 -> 0 | E21: ='Licensed FTEs'!E60 -> 1.5 | F21: ='Licensed FTEs'!F60 -> 17.92 | G21: ='Licensed FTEs'!G60 -> 10.41 | H21: ='Licensed FTEs'!H60 -> 2.14 | I21: ='Classified FTEs'!C60 -> 12.68 | J21: ='Licensed FTEs'!I60+'Licensed FTEs'!J60 -> 1 | K21: ='Licensed FTEs'!K60 -> 0.04 | L21: ='Licensed FTEs'!L60 -> 0.06 | M21: ='Licensed FTEs'!M60 -> 1 | N21: ='Classified FTEs'!G60 -> 0
A22: A8 | B22: EAST HOLLYWOOD HIGH | C22: ='Licensed FTEs'!C61 -> 0 | D22: ='Licensed FTEs'!D61 -> 0 | E22: ='Licensed FTEs'!E61 -> 0 | F22: ='Licensed FTEs'!F61 -> 0 | G22: ='Licensed FTEs'!G61 -> 16.48 | H22: ='Licensed FTEs'!H61 -> 2 | I22: ='Classified FTEs'!C61 -> 2 | J22: ='Licensed FTEs'!I61+'Licensed FTEs'!J61 -> 0.75 | K22: ='Licensed FTEs'!K61 -> 0 | L22: ='Licensed FTEs'!L61 -> 1 | M22: ='Licensed FTEs'!M61 -> 0.1 | N22: ='Classified FTEs'!G61 -> 0
A23: 5E | B23: EDITH BOWEN LABORATORY SCHOOL | C23: ='Licensed FTEs'!C62 -> 0 | D23: ='Licensed FTEs'!D62 -> 0 | E23: ='Licensed FTEs'!E62 -> 1.03 | F23: ='Licensed FTEs'!F62 -> 13.14 | G23: ='Licensed FTEs'!G62 -> 0 | H23: ='Licensed FTEs'!H62 -> 1.03 | I23: ='Classified FTEs'!C62 -> 0 | J23: ='Licensed FTEs'!I62+'Licensed FTEs'!J62 -> 0 | K23: ='Licensed FTEs'!K62 -> 0.77 | L23: ='Licensed FTEs'!L62 -> 0 | M23: ='Licensed FTEs'!M62 -> 2.6 | N23: ='Classified FTEs'!G62 -> 0
A24: 3C | B24: ENTHEOS ACADEMY | C24: ='Licensed FTEs'!C63 -> 0 | D24: ='Licensed FTEs'!D63 -> 0 | E24: ='Licensed FTEs'!E63 -> 1.08 | F24: ='Licensed FTEs'!F63 -> 16.16 | G24: ='Licensed FTEs'!G63 -> 8.43 | H24: ='Licensed FTEs'!H63 -> 2.32 | I24: ='Classified FTEs'!C63 -> 13.5 | J24: ='Licensed FTEs'!I63+'Licensed FTEs'!J63 -> 0.36 | K24: ='Licensed FTEs'!K63 -> 0 | L24: ='Licensed FTEs'!L63 -> 0 | M24: ='Licensed FTEs'!M63 -> 0 | N24: ='Classified FTEs'!G63 -> 0.75
A25: 7F | B25: EXCELSIOR ACADEMY | C25: ='Licensed FTEs'!C64 -> 0 | D25: ='Licensed FTEs'!D64 -> 0 | E25: ='Licensed FTEs'!E64 -> 1.5 | F25: ='Licensed FTEs'!F64 -> 19.27 | G25: ='Licensed FTEs'!G64 -> 6.8 | H25: ='Licensed FTEs'!H64 -> 0 | I25: ='Classified FTEs'!C64 -> 19 | J25: ='Licensed FTEs'!I64+'Licensed FTEs'!J64 -> 1.84 | K25: ='Licensed FTEs'!K64 -> 0 | L25: ='Licensed FTEs'!L64 -> 0 | M25: ='Licensed FTEs'!M64 -> 0 | N25: ='Classified FTEs'!G64 -> 0
A26: 98 | B26: FAST FORWARD HIGH | C26: ='Licensed FTEs'!C65 -> 0 | D26: ='Licensed FTEs'!D65 -> 0 | E26: ='Licensed FTEs'!E65 -> 0 | F26: ='Licensed FTEs'!F65 -> 0 | G26: ='Licensed FTEs'!G65 -> 12.19 | H26: ='Licensed FTEs'!H65 -> 0.28 | I26: ='Classified FTEs'!C65 -> 3 | J26: ='Licensed FTEs'!I65+'Licensed FTEs'!J65 -> 1.14 | K26: ='Licensed FTEs'!K65 -> 0 | L26: ='Licensed FTEs'!L65 -> 1.33 | M26: ='Licensed FTEs'!M65 -> 0 | N26: ='Classified FTEs'!G65 -> 0
A27: 82 | B27: FREEDOM ACADEMY | C27: ='Licensed FTEs'!C66 -> 0 | D27: ='Licensed FTEs'!D66 -> 0 | E27: ='Licensed FTEs'!E66 -> 2 | F27: ='Licensed FTEs'!F66 -> 19.1 | G27: ='Licensed FTEs'!G66 -> 6.57 | H27: ='Licensed FTEs'!H66 -> 2 | I27: ='Classified FTEs'!C66 -> 3.14 | J27: ='Licensed FTEs'!I66+'Licensed FTEs'!J66 -> 1.05 | K27: ='Licensed FTEs'!K66 -> 0 | L27: ='Licensed FTEs'!L66 -> 0 | M27: ='Licensed FTEs'!M66 -> 0 | N27: ='Classified FTEs'!G66 -> 0
A28: 7E | B28: GATEWAY PREPARATORY ACADEMY | C28: ='Licensed FTEs'!C67 -> 0 | D28: ='Licensed FTEs'!D67 -> 0 | E28: ='Licensed FTEs'!E67 -> 2 | F28: ='Licensed FTEs'!F67 -> 13.54 | G28: ='Licensed FTEs'!G67 -> 6.71 | H28: ='Licensed FTEs'!H67 -> 2 | I28: ='Classified FTEs'!C67 -> 20 | J28: ='Licensed FTEs'!I67+'Licensed FTEs'!J67 -> 0 | K28: ='Licensed FTEs'!K67 -> 0 | L28: ='Licensed FTEs'!L67 -> 0 | M28: ='Licensed FTEs'!M67 -> 0 | N28: ='Classified FTEs'!G67 -> 0
A29: 5D | B29: GEORGE WASHINGTON ACADEMY | C29: ='Licensed FTEs'!C68 -> 0 | D29: ='Licensed FTEs'!D68 -> 0 | E29: ='Licensed FTEs'!E68 -> 5 | F29: ='Licensed FTEs'!F68 -> 28.57 | G29: ='Licensed FTEs'!G68 -> 0.43 | H29: ='Licensed FTEs'!H68 -> 1.38 | I29: ='Classified FTEs'!C68 -> 7.84 | J29: ='Licensed FTEs'!I68+'Licensed FTEs'!J68 -> 1.2 | K29: ='Licensed FTEs'!K68 -> 0 | L29: ='Licensed FTEs'!L68 -> 0 | M29: ='Licensed FTEs'!M68 -> 0 | N29: ='Classified FTEs'!G68 -> 0
A30: 8G | B30: GOOD FOUNDATIONS ACADEMY | C30: ='Licensed FTEs'!C69 -> 0 | D30: ='Licensed FTEs'!D69 -> 0 | E30: ='Licensed FTEs'!E69 -> 2 | F30: ='Licensed FTEs'!F69 -> 16 | G30: ='Licensed FTEs'!G69 -> 0 | H30: ='Licensed FTEs'!H69 -> 0.64 | I30: ='Classified FTEs'!C69 -> 2.5 | J30: ='Licensed FTEs'!I69+'Licensed FTEs'!J69 -> 0 | K30: ='Licensed FTEs'!K69 -> 0 | L30: ='Licensed FTEs'!L69 -> 0 | M30: ='Licensed FTEs'!M69 -> 0 | N30: ='Classified FTEs'!G69 -> 0
A31: 1E | B31: GUADALUPE SCHOOL | C31: ='Licensed FTEs'!C70 -> 0 | D31: ='Licensed FTEs'!D70 -> 0 | E31: ='Licensed FTEs'!E70 -> 0.8 | F31: ='Licensed FTEs'!F70 -> 4 | G31: ='Licensed FTEs'!G70 -> 0 | H31: ='Licensed FTEs'!H70 -> 0.5 | I31: ='Classified FTEs'!C70 -> 5.75 | J31: ='Licensed FTEs'!I70+'Licensed FTEs'!J70 -> 0.5 | K31: ='Licensed FTEs'!K70 -> 0 | L31: ='Licensed FTEs'!L70 -> 0 | M31: ='Licensed FTEs'!M70 -> 0 | N31: ='Classified FTEs'!G70 -> 0.5
A32: 8F | B32: HAWTHORN ACADEMY | C32: ='Licensed FTEs'!C71 -> 0 | D32: ='Licensed FTEs'!D71 -> 0 | E32: ='Licensed FTEs'!E71 -> 2 | F32: ='Licensed FTEs'!F71 -> 19.5 | G32: ='Licensed FTEs'!G71 -> 9.16 | H32: ='Licensed FTEs'!H71 -> 1.1 | I32: ='Classified FTEs'!C71 -> 8.26 | J32: ='Licensed FTEs'!I71+'Licensed FTEs'!J71 -> 0.17 | K32: ='Licensed FTEs'!K71 -> 0 | L32: ='Licensed FTEs'!L71 -> 0.9 | M32: ='Licensed FTEs'!M71 -> 0.45 | N32: ='Classified FTEs'!G71 -> 0
A33: 2C | B33: INTECH COLLEGIATE HIGH SCHOOL | C33: ='Licensed FTEs'!C72 -> 0 | D33: ='Licensed FTEs'!D72 -> 0 | E33: ='Licensed FTEs'!E72 -> 0 | F33: ='Licensed FTEs'!F72 -> 0 | G33: ='Licensed FTEs'!G72 -> 7.09 | H33: ='Licensed FTEs'!H72 -> 0.13 | I33: ='Classified FTEs'!C72 -> 0.81 | J33: ='Licensed FTEs'!I72+'Licensed FTEs'!J72 -> 0.65 | K33: ='Licensed FTEs'!K72 -> 0 | L33: ='Licensed FTEs'!L72 -> 0.5 | M33: ='Licensed FTEs'!M72 -> 0 | N33: ='Classified FTEs'!G72 -> 0
A34: A5 | B34: ITINERIS EARLY COLLEGE HIGH | C34: ='Licensed FTEs'!C73 -> 0 | D34: ='Licensed FTEs'!D73 -> 0 | E34: ='Licensed FTEs'!E73 -> 0 | F34: ='Licensed FTEs'!F73 -> 0 | G34: ='Licensed FTEs'!G73 -> 11.58 | H34: ='Licensed FTEs'!H73 -> 0 | I34: ='Classified FTEs'!C73 -> 0.5 | J34: ='Licensed FTEs'!I73+'Licensed FTEs'!J73 -> 0 | K34: ='Licensed FTEs'!K73 -> 0 | L34: ='Licensed FTEs'!L73 -> 2 | M34: ='Licensed FTEs'!M73 -> 0 | N34: ='Classified FTEs'!G73 -> 0
A35: 93 | B35: JOHN HANCOCK CHARTER SCHOOL | C35: ='Licensed FTEs'!C74 -> 0 | D35: ='Licensed FTEs'!D74 -> 0 | E35: ='Licensed FTEs'!E74 -> 0.72 | F35: ='Licensed FTEs'!F74 -> 8.24 | G35: ='Licensed FTEs'!G74 -> 1.33 | H35: ='Licensed FTEs'!H74 -> 1 | I35: ='Classified FTEs'!C74 -> 4.29 | J35: ='Licensed FTEs'!I74+'Licensed FTEs'!J74 -> 0 | K35: ='Licensed FTEs'!K74 -> 0 | L35: ='Licensed FTEs'!L74 -> 0 | M35: ='Licensed FTEs'!M74 -> 0 | N35: ='Classified FTEs'!G74 -> 0
A36: 2E | B36: KARL G MAESER PREPARATORY ACADEMY | C36: ='Licensed FTEs'!C75 -> 0 | D36: ='Licensed FTEs'!D75 -> 0 | E36: ='Licensed FTEs'!E75 -> 0 | F36: ='Licensed FTEs'!F75 -> 0 | G36: ='Licensed FTEs'!G75 -> 26.67 | H36: ='Licensed FTEs'!H75 -> 0.5 | I36: ='Classified FTEs'!C75 -> 1 | J36: ='Licensed FTEs'!I75+'Licensed FTEs'!J75 -> 1.84 | K36: ='Licensed FTEs'!K75 -> 0 | L36: ='Licensed FTEs'!L75 -> 0 | M36: ='Licensed FTEs'!M75 -> 0.75 | N36: ='Classified FTEs'!G75 -> 0
A37: 4C | B37: LAKEVIEW ACADEMY | C37: ='Licensed FTEs'!C76 -> 0 | D37: ='Licensed FTEs'!D76 -> 0 | E37: ='Licensed FTEs'!E76 -> 2 | F37: ='Licensed FTEs'!F76 -> 22.36 | G37: ='Licensed FTEs'!G76 -> 7.5 | H37: ='Licensed FTEs'!H76 -> 2 | I37: ='Classified FTEs'!C76 -> 16.19 | J37: ='Licensed FTEs'!I76+'Licensed FTEs'!J76 -> 1.3 | K37: ='Licensed FTEs'!K76 -> 0 | L37: ='Licensed FTEs'!L76 -> 0 | M37: ='Licensed FTEs'!M76 -> 1 | N37: ='Classified FTEs'!G76 -> 0
A38: 5C | B38: LEGACY PREPARATORY ACADEMY | C38: ='Licensed FTEs'!C77 -> 0 | D38: ='Licensed FTEs'!D77 -> 0 | E38: ='Licensed FTEs'!E77 -> 1.5 | F38: ='Licensed FTEs'!F77 -> 17 | G38: ='Licensed FTEs'!G77 -> 24.71 | H38: ='Licensed FTEs'!H77 -> 2 | I38: ='Classified FTEs'!C77 -> 0 | J38: ='Licensed FTEs'!I77+'Licensed FTEs'!J77 -> 3.62 | K38: ='Licensed FTEs'!K77 -> 0.17 | L38: ='Licensed FTEs'!L77 -> 0.83 | M38: ='Licensed FTEs'!M77 -> 0 | N38: ='Classified FTEs'!G77 -> 0
A39: 6C | B39: LIBERTY ACADEMY | C39: ='Licensed FTEs'!C78 -> 0 | D39: ='Licensed FTEs'!D78 -> 0 | E39: ='Licensed FTEs'!E78 -> 1 | F39: ='Licensed FTEs'!F78 -> 9.05 | G39: ='Licensed FTEs'!G78 -> 4.7 | H39: ='Licensed FTEs'!H78 -> 2 | I39: ='Classified FTEs'!C78 -> 7 | J39: ='Licensed FTEs'!I78+'Licensed FTEs'!J78 -> 0.36 | K39: ='Licensed FTEs'!K78 -> 0 | L39: ='Licensed FTEs'!L78 -> 0 | M39: ='Licensed FTEs'!M78 -> 0 | N39: ='Classified FTEs'!G78 -> 0
A40: 2B | B40: LINCOLN ACADEMY | C40: ='Licensed FTEs'!C79 -> 0 | D40: ='Licensed FTEs'!D79 -> 0 | E40: ='Licensed FTEs'!E79 -> 1 | F40: ='Licensed FTEs'!F79 -> 14.21 | G40: ='Licensed FTEs'!G79 -> 12 | H40: ='Licensed FTEs'!H79 -> 4.02 | I40: ='Classified FTEs'!C79 -> 23.25 | J40: ='Licensed FTEs'!I79+'Licensed FTEs'!J79 -> 0.03 | K40: ='Licensed FTEs'!K79 -> 0 | L40: ='Licensed FTEs'!L79 -> 0.53 | M40: ='Licensed FTEs'!M79 -> 0 | N40: ='Classified FTEs'!G79 -> 0.75
...

Sheet support-districts
B1: Full-Time Equivalents (FTEs) by Position
B2: Licensed and Classified Personnel
B3: FY 2011
B4: Local Education Agencies | C4: SUPPORT | M4: TOTAL FTEs
C5: LEA Administrators | E5: LEA Administrative Support Staff | F5: School Administrators | G5: School Administrative Support Staff | H5: Student Support Services Staff | L5: Other Support Staff
H7: Student Support Services | I7: Student Transportation Supervisors | J7: School Food Services Supervisors | K7: School Nurses
C8: CACTUS Database | D8: Classified Personnel Report | E8: Classified Personnel Report | F8: CACTUS Database | G8: Classified Personnel Report | H8: CACTUS Database | I8: Classified Personnel Report | J8: Classified Personnel Report | K8: Classified Personnel Report | L8: Classified Personnel Report
B9: DISTRICT
A10: 1 | B10: Alpine | C10: ='Licensed FTEs'!N7 -> 22 | D10: ='Classified FTEs'!H7+'Classified FTEs'!K7 -> 1 | E10: ='Classified FTEs'!I7+'Classified FTEs'!L7+'Classified FTEs'!M7+'Classified FTEs'!N7+'Classified FTEs'!O7 -> 98.21 | F10: ='Licensed FTEs'!O7 -> 113.8 | G10: ='Classified FTEs'!E7+'Classified FTEs'!F7+'Classified FTEs'!J7 -> 274.71 | H10: ='Licensed FTEs'!P7 -> 95.11 | I10: ='Classified FTEs'!V7 -> 4 | J10: ='Classified FTEs'!AD7 -> 5 | K10: ='Classified FTEs'!D7 -> 0 | L10: ='Classified FTEs'!T7+'Classified FTEs'!U7+'Classified FTEs'!W7+'Classified FTEs'!X7+'Classified FTEs'!Y7+'Classified FTEs'!AC7+'Classified FTEs'!AE7+'Classified FTEs'!AF7+'Classified FTEs'!AL7 -> 1005.94 | M10: =SUM(C10:L10)+SUM('instruction-districts'!C10:N10) -> 5547.87
A11: 2 | B11: Beaver | C11: ='Licensed FTEs'!N8 -> 3.25 | D11: ='Classified FTEs'!H8+'Classified FTEs'!K8 -> 0 | E11: ='Classified FTEs'!I8+'Classified FTEs'!L8+'Classified FTEs'!M8+'Classified FTEs'!N8+'Classified FTEs'!O8 -> 1.75 | F11: ='Licensed FTEs'!O8 -> 3.75 | G11: ='Classified FTEs'!E8+'Classified FTEs'!F8+'Classified FTEs'!J8 -> 6.3 | H11: ='Licensed FTEs'!P8 -> 1 | I11: ='Classified FTEs'!V8 -> 0 | J11: ='Classified FTEs'!AD8 -> 0 | K11: ='Classified FTEs'!D8 -> 0.2 | L11: ='Classified FTEs'!T8+'Classified FTEs'!U8+'Classified FTEs'!W8+'Classified FTEs'!X8+'Classified FTEs'!Y8+'Classified FTEs'!AC8+'Classified FTEs'!AE8+'Classified FTEs'!AF8+'Classified FTEs'!AL8 -> 24.72 | M11: =SUM(C11:L11)+SUM('instruction-districts'!C11:N11) -> 157.47
A12: 3 | B12: Box Elder | C12: ='Licensed FTEs'!N9 -> 5 | D12: ='Classified FTEs'!H9+'Classified FTEs'!K9 -> 2 | E12: ='Classified FTEs'!I9+'Classified FTEs'!L9+'Classified FTEs'!M9+'Classified FTEs'!N9+'Classified FTEs'!O9 -> 14 | F12: ='Licensed FTEs'!O9 -> 25.3 | G12: ='Classified FTEs'!E9+'Classified FTEs'!F9+'Classified FTEs'!J9 -> 50 | H12: ='Licensed FTEs'!P9 -> 23.4 | I12: ='Classified FTEs'!V9 -> 1 | J12: ='Classified FTEs'!AD9 -> 1 | K12: ='Classified FTEs'!D9 -> 5 | L12: ='Classified FTEs'!T9+'Classified FTEs'!U9+'Classified FTEs'!W9+'Classified FTEs'!X9+'Classified FTEs'!Y9+'Classified FTEs'!AC9+'Classified FTEs'!AE9+'Classified FTEs'!AF9+'Classified FTEs'!AL9 -> 372 | M12: =SUM(C12:L12)+SUM('instruction-districts'!C12:N12) -> 1444.06
A13: 4 | B13: Cache | C13: ='Licensed FTEs'!N10 -> 3 | D13: ='Classified FTEs'!H10+'Classified FTEs'!K10 -> 1 | E13: ='Classified FTEs'!I10+'Classified FTEs'!L10+'Classified FTEs'!M10+'Classified FTEs'!N10+'Classified FTEs'!O10 -> 16.93 | F13: ='Licensed FTEs'!O10 -> 30.75 | G13: ='Classified FTEs'!E10+'Classified FTEs'!F10+'Classified FTEs'!J10 -> 42.74 | H13: ='Licensed FTEs'!P10 -> 37.03 | I13: ='Classified FTEs'!V10 -> 3.66 | J13: ='Classified FTEs'!AD10 -> 25 | K13: ='Classified FTEs'!D10 -> 2.5 | L13: ='Classified FTEs'!T10+'Classified FTEs'!U10+'Classified FTEs'!W10+'Classified FTEs'!X10+'Classified FTEs'!Y10+'Classified FTEs'!AC10+'Classified FTEs'!AE10+'Classified FTEs'!AF10+'Classified FTEs'!AL10 -> 260.12 | M13: =SUM(C13:L13)+SUM('instruction-districts'!C13:N13) -> 1491.69
A14: 42 | B14: Canyons | C14: ='Licensed FTEs'!N11 -> 21 | D14: ='Classified FTEs'!H11+'Classified FTEs'!K11 -> 6 | E14: ='Classified FTEs'!I11+'Classified FTEs'!L11+'Classified FTEs'!M11+'Classified FTEs'!N11+'Classified FTEs'!O11 -> 64 | F14: ='Licensed FTEs'!O11 -> 83 | G14: ='Classified FTEs'!E11+'Classified FTEs'!F11+'Classified FTEs'!J11 -> 107.5 | H14: ='Licensed FTEs'!P11 -> 79.53 | I14: ='Classified FTEs'!V11 -> 1 | J14: ='Classified FTEs'!AD11 -> 1 | K14: ='Classified FTEs'!D11 -> 18.4 | L14: ='Classified FTEs'!T11+'Classified FTEs'!U11+'Classified FTEs'!W11+'Classified FTEs'!X11+'Classified FTEs'!Y11+'Classified FTEs'!AC11+'Classified FTEs'!AE11+'Classified FTEs'!AF11+'Classified FTEs'!AL11 -> 476.32 | M14: =SUM(C14:L14)+SUM('instruction-districts'!C14:N14) -> 2626.91
A15: 5 | B15: Carbon | C15: ='Licensed FTEs'!N12 -> 5.48 | D15: ='Classified FTEs'!H12+'Classified FTEs'!K12 -> 1 | E15: ='Classified FTEs'!I12+'Classified FTEs'!L12+'Classified FTEs'!M12+'Classified FTEs'!N12+'Classified FTEs'!O12 -> 5.29 | F15: ='Licensed FTEs'!O12 -> 10.41 | G15: ='Classified FTEs'!E12+'Classified FTEs'!F12+'Classified FTEs'!J12 -> 18.51 | H15: ='Licensed FTEs'!P12 -> 3.8 | I15: ='Classified FTEs'!V12 -> 0 | J15: ='Classified FTEs'!AD12 -> 0.5 | K15: ='Classified FTEs'!D12 -> 0 | L15: ='Classified FTEs'!T12+'Classified FTEs'!U12+'Classified FTEs'!W12+'Classified FTEs'!X12+'Classified FTEs'!Y12+'Classified FTEs'!AC12+'Classified FTEs'!AE12+'Classified FTEs'!AF12+'Classified FTEs'!AL12 -> 79.3 | M15: =SUM(C15:L15)+SUM('instruction-districts'!C15:N15) -> 403.98
A16: 6 | B16: Daggett | C16: ='Licensed FTEs'!N13 -> 0.8 | D16: ='Classified FTEs'!H13+'Classified FTEs'!K13 -> 0.85 | E16: ='Classified FTEs'!I13+'Classified FTEs'!L13+'Classified FTEs'!M13+'Classified FTEs'!N13+'Classified FTEs'!O13 -> 1 | F16: ='Licensed FTEs'!O13 -> 0.86 | G16: ='Classified FTEs'!E13+'Classified FTEs'!F13+'Classified FTEs'!J13 -> 1.5 | H16: ='Licensed FTEs'!P13 -> 0 | I16: ='Classified FTEs'!V13 -> 0 | J16: ='Classified FTEs'!AD13 -> 0.13 | K16: ='Classified FTEs'!D13 -> 0 | L16: ='Classified FTEs'!T13+'Classified FTEs'!U13+'Classified FTEs'!W13+'Classified FTEs'!X13+'Classified FTEs'!Y13+'Classified FTEs'!AC13+'Classified FTEs'!AE13+'Classified FTEs'!AF13+'Classified FTEs'!AL13 -> 8.67 | M16: =SUM(C16:L16)+SUM('instruction-districts'!C16:N16) -> 38.48
A17: 7 | B17: Davis | C17: ='Licensed FTEs'!N14 -> 20 | D17: ='Classified FTEs'!H14+'Classified FTEs'!K14 -> 13 | E17: ='Classified FTEs'!I14+'Classified FTEs'!L14+'Classified FTEs'!M14+'Classified FTEs'!N14+'Classified FTEs'!O14 -> 70.11 | F17: ='Licensed FTEs'!O14 -> 166.7 | G17: ='Classified FTEs'!E14+'Classified FTEs'!F14+'Classified FTEs'!J14 -> 224.63 | H17: ='Licensed FTEs'!P14 -> 114.16 | I17: ='Classified FTEs'!V14 -> 1 | J17: ='Classified FTEs'!AD14 -> 4 | K17: ='Classified FTEs'!D14 -> 14.93 | L17: ='Classified FTEs'!T14+'Classified FTEs'!U14+'Classified FTEs'!W14+'Classified FTEs'!X14+'Classified FTEs'!Y14+'Classified FTEs'!AC14+'Classified FTEs'!AE14+'Classified FTEs'!AF14+'Classified FTEs'!AL14 -> 1031.51 | M17: =SUM(C17:L17)+SUM('instruction-districts'!C17:N17) -> 5809.69
A18: 8 | B18: Duchesne | C18: ='Licensed FTEs'!N15 -> 2 | D18: ='Classified FTEs'!H15+'Classified FTEs'!K15 -> 1 | E18: ='Classified FTEs'!I15+'Classified FTEs'!L15+'Classified FTEs'!M15+'Classified FTEs'!N15+'Classified FTEs'!O15 -> 10 | F18: ='Licensed FTEs'!O15 -> 13.85 | G18: ='Classified FTEs'!E15+'Classified FTEs'!F15+'Classified FTEs'!J15 -> 20.73 | H18: ='Licensed FTEs'!P15 -> 2.5 | I18: ='Classified FTEs'!V15 -> 1 | J18: ='Classified FTEs'!AD15 -> 1 | K18: ='Classified FTEs'!D15 -> 0.5 | L18: ='Classified FTEs'!T15+'Classified FTEs'!U15+'Classified FTEs'!W15+'Classified FTEs'!X15+'Classified FTEs'!Y15+'Classified FTEs'!AC15+'Classified FTEs'!AE15+'Classified FTEs'!AF15+'Classified FTEs'!AL15 -> 89.12 | M18: =SUM(C18:L18)+SUM('instruction-districts'!C18:N18) -> 475.44
A19: 9 | B19: Emery | C19: ='Licensed FTEs'!N16 -> 4 | D19: ='Classified FTEs'!H16+'Classified FTEs'!K16 -> 1 | E19: ='Classified FTEs'!I16+'Classified FTEs'!L16+'Classified FTEs'!M16+'Classified FTEs'!N16+'Classified FTEs'!O16 -> 3 | F19: ='Licensed FTEs'!O16 -> 9.35 | G19: ='Classified FTEs'!E16+'Classified FTEs'!F16+'Classified FTEs'!J16 -> 11 | H19: ='Licensed FTEs'!P16 -> 2 | I19: ='Classified FTEs'!V16 -> 1 | J19: ='Classified FTEs'!AD16 -> 1 | K19: ='Classified FTEs'!D16 -> 0 | L19: ='Classified FTEs'!T16+'Classified FTEs'!U16+'Classified FTEs'!W16+'Classified FTEs'!X16+'Classified FTEs'!Y16+'Classified FTEs'!AC16+'Classified FTEs'!AE16+'Classified FTEs'!AF16+'Classified FTEs'!AL16 -> 53.67 | M19: =SUM(C19:L19)+SUM('instruction-districts'!C19:N19) -> 264.83
A20: 10 | B20: Garfield | C20: ='Licensed FTEs'!N17 -> 0.54 | D20: ='Classified FTEs'!H17+'Classified FTEs'!K17 -> 1 | E20: ='Classified FTEs'!I17+'Classified FTEs'!L17+'Classified FTEs'!M17+'Classified FTEs'!N17+'Classified FTEs'!O17 -> 4.5 | F20: ='Licensed FTEs'!O17 -> 5.04 | G20: ='Classified FTEs'!E17+'Classified FTEs'!F17+'Classified FTEs'!J17 -> 5.7 | H20: ='Licensed FTEs'!P17 -> 1 | I20: ='Classified FTEs'!V17 -> 0 | J20: ='Classified FTEs'!AD17 -> 0 | K20: ='Classified FTEs'!D17 -> 0 | L20: ='Classified FTEs'!T17+'Classified FTEs'!U17+'Classified FTEs'!W17+'Classified FTEs'!X17+'Classified FTEs'!Y17+'Classified FTEs'!AC17+'Classified FTEs'!AE17+'Classified FTEs'!AF17+'Classified FTEs'!AL17 -> 19.6 | M20: =SUM(C20:L20)+SUM('instruction-districts'!C20:N20) -> 129.69
A21: 11 | B21: Grand | C21: ='Licensed FTEs'!N18 -> 2 | D21: ='Classified FTEs'!H18+'Classified FTEs'!K18 -> 0.25 | E21: ='Classified FTEs'!I18+'Classified FTEs'!L18+'Classified FTEs'!M18+'Classified FTEs'!N18+'Classified FTEs'!O18 -> 4.25 | F21: ='Licensed FTEs'!O18 -> 6 | G21: ='Classified FTEs'!E18+'Classified FTEs'!F18+'Classified FTEs'!J18 -> 10 | H21: ='Licensed FTEs'!P18 -> 2 | I21: ='Classified FTEs'!V18 -> 1 | J21: ='Classified FTEs'!AD18 -> 1 | K21: ='Classified FTEs'!D18 -> 0 | L21: ='Classified FTEs'!T18+'Classified FTEs'!U18+'Classified FTEs'!W18+'Classified FTEs'!X18+'Classified FTEs'!Y18+'Classified FTEs'!AC18+'Classified FTEs'!AE18+'Classified FTEs'!AF18+'Classified FTEs'!AL18 -> 45.38 | M21: =SUM(C21:L21)+SUM('instruction-districts'!C21:N21) -> 181.63
... A50: 35 | B50: Weber | C50: ='Licensed FTEs'!N47 -> 18 | D50: ='Classified FTEs'!H47+'Classified FTEs'!K47 -> 2.33 | E50: ='Classified FTEs'!I47+'Classified FTEs'!L47+'Classified FTEs'!M47+'Classified FTEs'!N47+'Classified FTEs'!O47 -> 21.86 | F50: ='Licensed FTEs'!O47 -> 63 | G50: ='Classified FTEs'!E47+'Classified FTEs'!F47+'Classified FTEs'!J47 -> 85.28 | H50: ='Licensed FTEs'!P47 -> 47.23 | I50: ='Classified FTEs'!V47 -> 2 | J50: ='Classified FTEs'!AD47 -> 3 | K50: ='Classified FTEs'!D47 -> 12.7 | L50: ='Classified FTEs'!T47+'Classified FTEs'!U47+'Classified FTEs'!W47+'Classified FTEs'!X47+'Classified FTEs'!Y47+'Classified FTEs'!AC47+'Classified FTEs'!AE47+'Classified FTEs'!AF47+'Classified FTEs'!AL47 -> 431.48 | M50: =SUM(C50:L50)+SUM('instruction-districts'!C50:N50) -> 2576.38
B51: DISTRICT TOTAL | C51: =SUM(C10:C50) -> 274.47 | D51: =SUM(D10:D50) -> 64.05 | E51: =SUM(E10:E50) -> 700.2 | F51: =SUM(F10:F50) -> 1200.11 | G51: =SUM(G10:G50) -> 2099.92 | H51: =SUM(H10:H50) -> 947.52 | I51: =SUM(I10:I50) -> 37.45 | J51: =SUM(J10:J50) -> 71.46 | ... L51: =SUM(L10:L50) -> 8881.05 | M51: =SUM(C51:L51)+SUM('instruction-districts'!C51:N51) -> 49033.75
B52: CHARTER TOTAL | C52: ='support-charters'!C86 -> 22.36 | D52: ='support-charters'!D86 -> 28.97 | E52: ='support-charters'!E86 -> 30.95 | F52: ='support-charters'!F86 -> 100.33 | G52: ='support-charters'!G86 -> 160.27 | H52: ='support-charters'!H86 -> 16.88 | I52: ='support-charters'!I86 -> 0 | J52: ='support-charters'!J86 -> 14.18 | ... L52: ='support-charters'!L86 -> 162.73 | M52: =SUM(C52:L52)+SUM('instruction-districts'!C52:N52) -> 3043.87
B53: GRAND TOTAL | C53: =C51+C52 -> 296.83 | D53: =D51+D52 -> 93.02 | E53: =E51+E52 -> 731.15 | F53: =F51+F52 -> 1300.44 | G53: =G51+G52 -> 2260.19 | H53: =H51+H52 -> 964.4 | I53: =I51+I52 -> 37.45 | J53: =J51+J52 -> 85.64 | ... M53: =M51+M52 -> 52077.62

Sheet support-charters
B1: Full-Time Equivalents (FTEs) by Position
B2: Licensed and Classified Personnel
B3: FY 2011
B4: Local Education Agencies | C4: SUPPORT | M4: TOTAL FTEs
C5: LEA Administrators | E5: LEA Administrative Support Staff | F5: School Administrators | G5: School Administrative Support Staff | H5: Student Support Services Staff | L5: Other Support Staff
H7: Student Support Services | I7: Student Transportation Supervisors | J7: School Food Services Supervisors | K7: School Nurses
C8: CACTUS Database | D8: Classified Personnel Report | E8: Classified Personnel Report | F8: CACTUS Database | G8: Classified Personnel Report | H8: CACTUS Database | I8: Classified Personnel Report | J8: Classified Personnel Report | K8: Classified Personnel Report | L8: Classified Personnel Report
B9: CHARTER SCHOOL
A10: 83 | B10: ACADEMY FOR MATH ENGINEERING & SCIENCE (AMES) | C10: ='Licensed FTEs'!N49 -> 0 | D10: ='Classified FTEs'!H49+'Classified FTEs'!K49 -> 1 | E10: ='Classified FTEs'!I49+'Classified FTEs'!L49+'Classified FTEs'!M49+'Classified FTEs'!N49+'Classified FTEs'!O49 -> 1.62 | F10: ='Licensed FTEs'!O49 -> 1 | G10: ='Classified FTEs'!E49+'Classified FTEs'!F49+'Classified FTEs'!J49 -> 0.84 | H10: ='Licensed FTEs'!P49 -> 0 | I10: ='Classified FTEs'!V49 -> 0 | J10: ='Classified FTEs'!AD49 -> 0 | K10: ='Classified FTEs'!D49 -> 0 | L10: ='Classified FTEs'!T49+'Classified FTEs'!U49+'Classified FTEs'!W49+'Classified FTEs'!X49+'Classified FTEs'!Y49+'Classified FTEs'!AC49+'Classified FTEs'!AE49+'Classified FTEs'!AF49+'Classified FTEs'!AL49 -> 0 | M10: =SUM(C10:L10)+SUM('instruction-charters'!C10:N10) -> 30.67
A11: 8B | B11: AMERICAN LEADERSHIP ACADEMY | C11: ='Licensed FTEs'!N50 -> 1 | D11: ='Classified FTEs'!H50+'Classified FTEs'!K50 -> 2 | E11: ='Classified FTEs'!I50+'Classified FTEs'!L50+'Classified FTEs'!M50+'Classified FTEs'!N50+'Classified FTEs'!O50 -> 3 | F11: ='Licensed FTEs'!O50 -> 1.5 | G11: ='Classified FTEs'!E50+'Classified FTEs'!F50+'Classified FTEs'!J50 -> 6 | H11: ='Licensed FTEs'!P50 -> 0 | I11: ='Classified FTEs'!V50 -> 0 | J11: ='Classified FTEs'!AD50 -> 0 | K11: ='Classified FTEs'!D50 -> 0 | L11: ='Classified FTEs'!T50+'Classified FTEs'!U50+'Classified FTEs'!W50+'Classified FTEs'!X50+'Classified FTEs'!Y50+'Classified FTEs'!AC50+'Classified FTEs'!AE50+'Classified FTEs'!AF50+'Classified FTEs'!AL50 -> 3 | M11: =SUM(C11:L11)+SUM('instruction-charters'!C11:N11) -> 92.06
A12: 74 | B12: AMERICAN PREPARATORY ACADEMY | C12: ='Licensed FTEs'!N51 -> 2.1 | D12: ='Classified FTEs'!H51+'Classified FTEs'!K51 -> 0 | E12: ='Classified FTEs'!I51+'Classified FTEs'!L51+'Classified FTEs'!M51+'Classified FTEs'!N51+'Classified FTEs'!O51 -> 0 | F12: ='Licensed FTEs'!O51 -> 4 | G12: ='Classified FTEs'!E51+'Classified FTEs'!F51+'Classified FTEs'!J51 -> 9.89 | H12: ='Licensed FTEs'!P51 -> 1.86 | I12: ='Classified FTEs'!V51 -> 0 | J12: ='Classified FTEs'!AD51 -> 0 | K12: ='Classified FTEs'!D51 -> 0 | L12: ='Classified FTEs'!T51+'Classified FTEs'!U51+'Classified FTEs'!W51+'Classified FTEs'!X51+'Classified FTEs'!Y51+'Classified FTEs'!AC51+'Classified FTEs'!AE51+'Classified FTEs'!AF51+'Classified FTEs'!AL51 -> 11.98 | M12: =SUM(C12:L12)+SUM('instruction-charters'!C12:N12) -> 94.07
A13: 3G | B13: BEAR RIVER CHARTER SCHOOL | C13: ='Licensed FTEs'!N52 -> 0 | D13: ='Classified FTEs'!H52+'Classified FTEs'!K52 -> 0 | E13: ='Classified FTEs'!I52+'Classified FTEs'!L52+'Classified FTEs'!M52+'Classified FTEs'!N52+'Classified FTEs'!O52 -> 0 | F13: ='Licensed FTEs'!O52 -> 0 | G13: ='Classified FTEs'!E52+'Classified FTEs'!F52+'Classified FTEs'!J52 -> 1 | H13: ='Licensed FTEs'!P52 -> 0 | I13: ='Classified FTEs'!V52 -> 0 | J13: ='Classified FTEs'!AD52 -> 0 | K13: ='Classified FTEs'!D52 -> 0 | L13: ='Classified FTEs'!T52+'Classified FTEs'!U52+'Classified FTEs'!W52+'Classified FTEs'!X52+'Classified FTEs'!Y52+'Classified FTEs'!AC52+'Classified FTEs'!AE52+'Classified FTEs'!AF52+'Classified FTEs'!AL52 -> 1.5 | M13: =SUM(C13:L13)+SUM('instruction-charters'!C13:N13) -> 16.3
A14: 3B | B14: BEEHIVE SCIENCE & TECHNOLOGY ACADEMY (BSTA) | C14: ='Licensed FTEs'!N53 -> 2.25 | D14: ='Classified FTEs'!H53+'Classified FTEs'!K53 -> 0.35 | E14: ='Classified FTEs'!I53+'Classified FTEs'!L53+'Classified FTEs'!M53+'Classified FTEs'!N53+'Classified FTEs'!O53 -> 0 | F14: ='Licensed FTEs'!O53 -> 0 | G14: ='Classified FTEs'!E53+'Classified FTEs'!F53+'Classified FTEs'!J53 -> 2 | H14: ='Licensed FTEs'!P53 -> 0 | I14: ='Classified FTEs'!V53 -> 0 | J14: ='Classified FTEs'!AD53 -> 0 | K14: ='Classified FTEs'!D53 -> 0 | L14: ='Classified FTEs'!T53+'Classified FTEs'!U53+'Classified FTEs'!W53+'Classified FTEs'!X53+'Classified FTEs'!Y53+'Classified FTEs'!AC53+'Classified FTEs'!AE53+'Classified FTEs'!AF53+'Classified FTEs'!AL53 -> 0 | M14: =SUM(C14:L14)+SUM('instruction-charters'!C14:N14) -> 19.28
A15: 9D | B15: CANYON RIM ACADEMY | C15: ='Licensed FTEs'!N54 -> 0.67 | D15: ='Classified FTEs'!H54+'Classified FTEs'!K54 -> 0 | E15: ='Classified FTEs'!I54+'Classified FTEs'!L54+'Classified FTEs'!M54+'Classified FTEs'!N54+'Classified FTEs'!O54 -> 0 | F15: ='Licensed FTEs'!O54 -> 1 | G15: ='Classified FTEs'!E54+'Classified FTEs'!F54+'Classified FTEs'!J54 -> 0 | H15: ='Licensed FTEs'!P54 -> 0.53 | I15: ='Classified FTEs'!V54 -> 0 | J15: ='Classified FTEs'!AD54 -> 0 | K15: ='Classified FTEs'!D54 -> 0 | L15: ='Classified FTEs'!T54+'Classified FTEs'!U54+'Classified FTEs'!W54+'Classified FTEs'!X54+'Classified FTEs'!Y54+'Classified FTEs'!AC54+'Classified FTEs'!AE54+'Classified FTEs'!AF54+'Classified FTEs'!AL54 -> 0 | M15: =SUM(C15:L15)+SUM('instruction-charters'!C15:N15) -> 23.53
A16: 2D | B16: CHANNING HALL | C16: ='Licensed FTEs'!N55 -> 0 | D16: ='Classified FTEs'!H55+'Classified FTEs'!K55 -> 1 | E16: ='Classified FTEs'!I55+'Classified FTEs'!L55+'Classified FTEs'!M55+'Classified FTEs'!N55+'Classified FTEs'!O55 -> 0.45 | F16: ='Licensed FTEs'!O55 -> 2.25 | G16: ='Classified FTEs'!E55+'Classified FTEs'!F55+'Classified FTEs'!J55 -> 2 | H16: ='Licensed FTEs'!P55 -> 2 | I16: ='Classified FTEs'!V55 -> 0 | J16: ='Classified FTEs'!AD55 -> 1 | K16: ='Classified FTEs'!D55 -> 0 | L16: ='Classified FTEs'!T55+'Classified FTEs'!U55+'Classified FTEs'!W55+'Classified FTEs'!X55+'Classified FTEs'!Y55+'Classified FTEs'!AC55+'Classified FTEs'!AE55+'Classified FTEs'!AF55+'Classified FTEs'!AL55 -> 3.95 | M16: =SUM(C16:L16)+SUM('instruction-charters'!C16:N16) -> 58.36
A17: 87 | B17: CITY ACADEMY | C17: ='Licensed FTEs'!N56 -> 1 | D17: ='Classified FTEs'!H56+'Classified FTEs'!K56 -> 1 | E17: ='Classified FTEs'!I56+'Classified FTEs'!L56+'Classified FTEs'!M56+'Classified FTEs'!N56+'Classified FTEs'!O56 -> 0 | F17: ='Licensed FTEs'!O56 -> 0.9 | G17: ='Classified FTEs'!E56+'Classified FTEs'!F56+'Classified FTEs'!J56 -> 1.17 | H17: ='Licensed FTEs'!P56 -> 0 | I17: ='Classified FTEs'!V56 -> 0 | J17: ='Classified FTEs'!AD56 -> 0 | K17: ='Classified FTEs'!D56 -> 0 | L17: ='Classified FTEs'!T56+'Classified FTEs'!U56+'Classified FTEs'!W56+'Classified FTEs'!X56+'Classified FTEs'!Y56+'Classified FTEs'!AC56+'Classified FTEs'!AE56+'Classified FTEs'!AF56+'Classified FTEs'!AL56 -> 1.59 | M17: =SUM(C17:L17)+SUM('instruction-charters'!C17:N17) -> 31.32
A18: 3E | B18: CS LEWIS ACADEMY | C18: ='Licensed FTEs'!N57 -> 1 | D18: ='Classified FTEs'!H57+'Classified FTEs'!K57 -> 3 | E18: ='Classified FTEs'!I57+'Classified FTEs'!L57+'Classified FTEs'!M57+'Classified FTEs'!N57+'Classified FTEs'!O57 -> 0 | F18: ='Licensed FTEs'!O57 -> 0 | G18: ='Classified FTEs'!E57+'Classified FTEs'!F57+'Classified FTEs'!J57 -> 1.28 | H18: ='Licensed FTEs'!P57 -> 0.6 | I18: ='Classified FTEs'!V57 -> 0 | J18: ='Classified FTEs'!AD57 -> 0 | K18: ='Classified FTEs'!D57 -> 0 | L18: ='Classified FTEs'!T57+'Classified FTEs'!U57+'Classified FTEs'!W57+'Classified FTEs'!X57+'Classified FTEs'!Y57+'Classified FTEs'!AC57+'Classified FTEs'!AE57+'Classified FTEs'!AF57+'Classified FTEs'!AL57 -> 2.32 | M18: =SUM(C18:L18)+SUM('instruction-charters'!C18:N18) -> 25.81
A19: A3 | B19: DAVINCI ACADEMY | C19: ='Licensed FTEs'!N58 -> 0 | D19: ='Classified FTEs'!H58+'Classified FTEs'!K58 -> 0 | E19: ='Classified FTEs'!I58+'Classified FTEs'!L58+'Classified FTEs'!M58+'Classified FTEs'!N58+'Classified FTEs'!O58 -> 0.6 | F19: ='Licensed FTEs'!O58 -> 2 | G19: ='Classified FTEs'!E58+'Classified FTEs'!F58+'Classified FTEs'!J58 -> 1.6 | H19: ='Licensed FTEs'!P58 -> 0 | I19: ='Classified FTEs'!V58 -> 0 | J19: ='Classified FTEs'!AD58 -> 0 | K19: ='Classified FTEs'!D58 -> 0 | L19: ='Classified FTEs'!T58+'Classified FTEs'!U58+'Classified FTEs'!W58+'Classified FTEs'!X58+'Classified FTEs'!Y58+'Classified FTEs'!AC58+'Classified FTEs'!AE58+'Classified FTEs'!AF58+'Classified FTEs'!AL58 -> 3.8 | M19: =SUM(C19:L19)+SUM('instruction-charters'!C19:N19) -> 30.17
A20: 4E | B20: DUAL IMMERSION ACADEMY | C20: ='Licensed FTEs'!N59 -> 0 | D20: ='Classified FTEs'!H59+'Classified FTEs'!K59 -> 0 | E20: ='Classified FTEs'!I59+'Classified FTEs'!L59+'Classified FTEs'!M59+'Classified FTEs'!N59+'Classified FTEs'!O59 -> 1.1 | F20: ='Licensed FTEs'!O59 -> 1.17 | G20: ='Classified FTEs'!E59+'Classified FTEs'!F59+'Classified FTEs'!J59 -> 1.6 | H20: ='Licensed FTEs'!P59 -> 0 | I20: ='Classified FTEs'!V59 -> 0 | J20: ='Classified FTEs'!AD59 -> 0 | K20: ='Classified FTEs'!D59 -> 0 | L20: ='Classified FTEs'!T59+'Classified FTEs'!U59+'Classified FTEs'!W59+'Classified FTEs'!X59+'Classified FTEs'!Y59+'Classified FTEs'!AC59+'Classified FTEs'!AE59+'Classified FTEs'!AF59+'Classified FTEs'!AL59 -> 6 | M20: =SUM(C20:L20)+SUM('instruction-charters'!C20:N20) -> 35.09
A21: 6F | B21: EARLY LIGHT ACADEMY AT DAYBREAK | C21: ='Licensed FTEs'!N60 -> 0 | D21: ='Classified FTEs'!H60+'Classified FTEs'!K60 -> 0 | E21: ='Classified FTEs'!I60+'Classified FTEs'!L60+'Classified FTEs'!M60+'Classified FTEs'!N60+'Classified FTEs'!O60 -> 0 | F21: ='Licensed FTEs'!O60 -> 1.61 | G21: ='Classified FTEs'!E60+'Classified FTEs'!F60+'Classified FTEs'!J60 -> 2.45 | H21: ='Licensed FTEs'!P60 -> 0 | I21: ='Classified FTEs'!V60 -> 0 | J21: ='Classified FTEs'!AD60 -> 0 | K21: ='Classified FTEs'!D60 -> 0 | L21: ='Classified FTEs'!T60+'Classified FTEs'!U60+'Classified FTEs'!W60+'Classified FTEs'!X60+'Classified FTEs'!Y60+'Classified FTEs'!AC60+'Classified FTEs'!AE60+'Classified FTEs'!AF60+'Classified FTEs'!AL60 -> 0 | M21: =SUM(C21:L21)+SUM('instruction-charters'!C21:N21) -> 50.81
A22: A8 | B22: EAST HOLLYWOOD HIGH | C22: ='Licensed FTEs'!N61 -> 0 | D22: ='Classified FTEs'!H61+'Classified FTEs'!K61 -> 0.7 | E22: ='Classified FTEs'!I61+'Classified FTEs'!L61+'Classified FTEs'!M61+'Classified FTEs'!N61+'Classified FTEs'!O61 -> 0.6 | F22: ='Licensed FTEs'!O61 -> 0 | G22: ='Classified FTEs'!E61+'Classified FTEs'!F61+'Classified FTEs'!J61 -> 2 | H22: ='Licensed FTEs'!P61 -> 0 | I22: ='Classified FTEs'!V61 -> 0 | J22: ='Classified FTEs'!AD61 -> 0 | K22: ='Classified FTEs'!D61 -> 0 | L22: ='Classified FTEs'!T61+'Classified FTEs'!U61+'Classified FTEs'!W61+'Classified FTEs'!X61+'Classified FTEs'!Y61+'Classified FTEs'!AC61+'Classified FTEs'!AE61+'Classified FTEs'!AF61+'Classified FTEs'!AL61 -> 1.3 | M22: =SUM(C22:L22)+SUM('instruction-charters'!C22:N22) -> 26.93
A23: 5E | B23: EDITH BOWEN LABORATORY SCHOOL | C23: ='Licensed FTEs'!N62 -> 0 | D23: ='Classified FTEs'!H62+'Classified FTEs'!K62 -> 0 | E23: ='Classified FTEs'!I62+'Classified FTEs'!L62+'Classified FTEs'!M62+'Classified FTEs'!N62+'Classified FTEs'!O62 -> 0 | F23: ='Licensed FTEs'!O62 -> 1.3 | G23: ='Classified FTEs'!E62+'Classified FTEs'!F62+'Classified FTEs'!J62 -> 0 | H23: ='Licensed FTEs'!P62 -> 0.51 | I23: ='Classified FTEs'!V62 -> 0 | J23: ='Classified FTEs'!AD62 -> 0 | K23: ='Classified FTEs'!D62 -> 0 | L23: ='Classified FTEs'!T62+'Classified FTEs'!U62+'Classified FTEs'!W62+'Classified FTEs'!X62+'Classified FTEs'!Y62+'Classified FTEs'!AC62+'Classified FTEs'!AE62+'Classified FTEs'!AF62+'Classified FTEs'!AL62 -> 0 | M23: =SUM(C23:L23)+SUM('instruction-charters'!C23:N23) -> 20.38
A24: 3C | B24: ENTHEOS ACADEMY | C24: ='Licensed FTEs'!N63 -> 0 | D24: ='Classified FTEs'!H63+'Classified FTEs'!K63 -> 1 | E24: ='Classified FTEs'!I63+'Classified FTEs'!L63+'Classified FTEs'!M63+'Classified FTEs'!N63+'Classified FTEs'!O63 -> 0 | F24: ='Licensed FTEs'!O63 -> 0 | G24: ='Classified FTEs'!E63+'Classified FTEs'!F63+'Classified FTEs'!J63 -> 3.5 | H24: ='Licensed FTEs'!P63 -> 0.21 | I24: ='Classified FTEs'!V63 -> 0 | J24: ='Classified FTEs'!AD63 -> 1 | K24: ='Classified FTEs'!D63 -> 0 | L24: ='Classified FTEs'!T63+'Classified FTEs'!U63+'Classified FTEs'!W63+'Classified FTEs'!X63+'Classified FTEs'!Y63+'Classified FTEs'!AC63+'Classified FTEs'!AE63+'Classified FTEs'!AF63+'Classified FTEs'!AL63 -> 3.1 | M24: =SUM(C24:L24)+SUM('instruction-charters'!C24:N24) -> 51.41
A25: 7F | B25: EXCELSIOR ACADEMY | C25: ='Licensed FTEs'!N64 -> 0.86 | D25: ='Classified FTEs'!H64+'Classified FTEs'!K64 -> 0 | E25: ='Classified FTEs'!I64+'Classified FTEs'!L64+'Classified FTEs'!M64+'Classified FTEs'!N64+'Classified FTEs'!O64 -> 1 | F25: ='Licensed FTEs'!O64 -> 1 | G25: ='Classified FTEs'!E64+'Classified FTEs'!F64+'Classified FTEs'!J64 -> 4 | H25: ='Licensed FTEs'!P64 -> 0 | I25: ='Classified FTEs'!V64 -> 0 | J25: ='Classified FTEs'!AD64 -> 0 | K25: ='Classified FTEs'!D64 -> 0 | L25: ='Classified FTEs'!T64+'Classified FTEs'!U64+'Classified FTEs'!W64+'Classified FTEs'!X64+'Classified FTEs'!Y64+'Classified FTEs'!AC64+'Classified FTEs'!AE64+'Classified FTEs'!AF64+'Classified FTEs'!AL64 -> 3 | M25: =SUM(C25:L25)+SUM('instruction-charters'!C25:N25) -> 58.27
A26: 98 | B26: FAST FORWARD HIGH | C26: ='Licensed FTEs'!N65 -> 0 | D26: ='Classified FTEs'!H65+'Classified FTEs'!K65 -> 0.8 | E26: ='Classified FTEs'!I65+'Classified FTEs'!L65+'Classified FTEs'!M65+'Classified FTEs'!N65+'Classified FTEs'!O65 -> 0.5 | F26: ='Licensed FTEs'!O65 -> 1.17 | G26: ='Classified FTEs'!E65+'Classified FTEs'!F65+'Classified FTEs'!J65 -> 2 | H26: ='Licensed FTEs'!P65 -> 0 | I26: ='Classified FTEs'!V65 -> 0 | J26: ='Classified FTEs'!AD65 -> 0 | K26: ='Classified FTEs'!D65 -> 0 | L26: ='Classified FTEs'!T65+'Classified FTEs'!U65+'Classified FTEs'!W65+'Classified FTEs'!X65+'Classified FTEs'!Y65+'Classified FTEs'!AC65+'Classified FTEs'!AE65+'Classified FTEs'!AF65+'Classified FTEs'!AL65 -> 1 | M26: =SUM(C26:L26)+SUM('instruction-charters'!C26:N26) -> 23.41
A27: 82 | B27: FREEDOM ACADEMY | C27: ='Licensed FTEs'!N66 -> 0 | D27: ='Classified FTEs'!H66+'Classified FTEs'!K66 -> 0.3 | E27: ='Classified FTEs'!I66+'Classified FTEs'!L66+'Classified FTEs'!M66+'Classified FTEs'!N66+'Classified FTEs'!O66 -> 1 | F27: ='Licensed FTEs'!O66 -> 1.18 | G27: ='Classified FTEs'!E66+'Classified FTEs'!F66+'Classified FTEs'!J66 -> 2.1 | H27: ='Licensed FTEs'!P66 -> 0.25 | I27: ='Classified FTEs'!V66 -> 0 | J27: ='Classified FTEs'!AD66 -> 0.5 | K27: ='Classified FTEs'!D66 -> 0 | L27: ='Classified FTEs'!T66+'Classified FTEs'!U66+'Classified FTEs'!W66+'Classified FTEs'!X66+'Classified FTEs'!Y66+'Classified FTEs'!AC66+'Classified FTEs'!AE66+'Classified FTEs'!AF66+'Classified FTEs'!AL66 -> 4.8 | M27: =SUM(C27:L27)+SUM('instruction-charters'!C27:N27) -> 43.99
A28: 7E | B28: GATEWAY PREPARATORY ACADEMY | C28: ='Licensed FTEs'!N67 -> 0 | D28: ='Classified FTEs'!H67+'Classified FTEs'!K67 -> 0 | E28: ='Classified FTEs'!I67+'Classified FTEs'!L67+'Classified FTEs'!M67+'Classified FTEs'!N67+'Classified FTEs'!O67 -> 1 | F28: ='Licensed FTEs'!O67 -> 1 | G28: ='Classified FTEs'!E67+'Classified FTEs'!F67+'Classified FTEs'!J67 -> 0 | H28: ='Licensed FTEs'!P67 -> 1 | I28: ='Classified FTEs'!V67 -> 0 | J28: ='Classified FTEs'!AD67 -> 0 | K28: ='Classified FTEs'!D67 -> 1 | L28: ='Classified FTEs'!T67+'Classified FTEs'!U67+'Classified FTEs'!W67+'Classified FTEs'!X67+'Classified FTEs'!Y67+'Classified FTEs'!AC67+'Classified FTEs'!AE67+'Classified FTEs'!AF67+'Classified FTEs'!AL67 -> 2 | M28: =SUM(C28:L28)+SUM('instruction-charters'!C28:N28) -> 50.25
A29: 5D | B29: GEORGE WASHINGTON ACADEMY | C29: ='Licensed FTEs'!N68 -> 0 | D29: ='Classified FTEs'!H68+'Classified FTEs'!K68 -> 0 | E29: ='Classified FTEs'!I68+'Classified FTEs'!L68+'Classified FTEs'!M68+'Classified FTEs'!N68+'Classified FTEs'!O68 -> 0 | F29: ='Licensed FTEs'!O68 -> 1.82 | G29: ='Classified FTEs'!E68+'Classified FTEs'!F68+'Classified FTEs'!J68 -> 4.66 | H29: ='Licensed FTEs'!P68 -> 0 | I29: ='Classified FTEs'!V68 -> 0 | J29: ='Classified FTEs'!AD68 -> 0 | K29: ='Classified FTEs'!D68 -> 0 | L29: ='Classified FTEs'!T68+'Classified FTEs'!U68+'Classified FTEs'!W68+'Classified FTEs'!X68+'Classified FTEs'!Y68+'Classified FTEs'!AC68+'Classified FTEs'!AE68+'Classified FTEs'!AF68+'Classified FTEs'!AL68 -> 1.8 | M29: =SUM(C29:L29)+SUM('instruction-charters'!C29:N29) -> 52.7
A30: 8G | B30: GOOD FOUNDATIONS ACADEMY | C30: ='Licensed FTEs'!N69 -> 0 | D30: ='Classified FTEs'!H69+'Classified FTEs'!K69 -> 0 | E30: ='Classified FTEs'!I69+'Classified FTEs'!L69+'Classified FTEs'!M69+'Classified FTEs'!N69+'Classified FTEs'!O69 -> 0.1 | F30: ='Licensed FTEs'!O69 -> 1 | G30: ='Classified FTEs'!E69+'Classified FTEs'!F69+'Classified FTEs'!J69 -> 1.5 | H30: ='Licensed FTEs'!P69 -> 0 | I30: ='Classified FTEs'!V69 -> 0 | J30: ='Classified FTEs'!AD69 -> 0 | K30: ='Classified FTEs'!D69 -> 0 | L30: ='Classified FTEs'!T69+'Classified FTEs'!U69+'Classified FTEs'!W69+'Classified FTEs'!X69+'Classified FTEs'!Y69+'Classified FTEs'!AC69+'Classified FTEs'!AE69+'Classified FTEs'!AF69+'Classified FTEs'!AL69 -> 1.2 | M30: =SUM(C30:L30)+SUM('instruction-charters'!C30:N30) -> 24.94
A31: 1E | B31: GUADALUPE SCHOOL | C31: ='Licensed FTEs'!N70 -> 0 | D31: ='Classified FTEs'!H70+'Classified FTEs'!K70 -> 1.05 | E31: ='Classified FTEs'!I70+'Classified FTEs'!L70+'Classified FTEs'!M70+'Classified FTEs'!N70+'Classified FTEs'!O70 -> 0.75 | F31: ='Licensed FTEs'!O70 -> 1 | G31: ='Classified FTEs'!E70+'Classified FTEs'!F70+'Classified FTEs'!J70 -> 1.2 | H31: ='Licensed FTEs'!P70 -> 0 | I31: ='Classified FTEs'!V70 -> 0 | J31: ='Classified FTEs'!AD70 -> 0 | K31: ='Classified FTEs'!D70 -> 0 | L31: ='Classified FTEs'!T70+'Classified FTEs'!U70+'Classified FTEs'!W70+'Classified FTEs'!X70+'Classified FTEs'!Y70+'Classified FTEs'!AC70+'Classified FTEs'!AE70+'Classified FTEs'!AF70+'Classified FTEs'!AL70 -> 3.48 | M31: =SUM(C31:L31)+SUM('instruction-charters'!C31:N31) -> 19.53
A32: 8F | B32: HAWTHORN ACADEMY | C32: ='Licensed FTEs'!N71 -> 0 | D32: ='Classified FTEs'!H71+'Classified FTEs'!K71 -> 0 | E32: ='Classified FTEs'!I71+'Classified FTEs'!L71+'Classified FTEs'!M71+'Classified FTEs'!N71+'Classified FTEs'!O71 -> 0 | F32: ='Licensed FTEs'!O71 -> 2.6 | G32: ='Classified FTEs'!E71+'Classified FTEs'!F71+'Classified FTEs'!J71 -> 1.78 | H32: ='Licensed FTEs'!P71 -> 0 | I32: ='Classified FTEs'!V71 -> 0 | J32: ='Classified FTEs'!AD71 -> 0 | K32: ='Classified FTEs'!D71 -> 0 | L32: ='Classified FTEs'!T71+'Classified FTEs'!U71+'Classified FTEs'!W71+'Classified FTEs'!X71+'Classified FTEs'!Y71+'Classified FTEs'!AC71+'Classified FTEs'!AE71+'Classified FTEs'!AF71+'Classified FTEs'!AL71 -> 2.03 | M32: =SUM(C32:L32)+SUM('instruction-charters'!C32:N32) -> 47.95
A33: 2C | B33: INTECH COLLEGIATE HIGH SCHOOL | C33: ='Licensed FTEs'!N72 -> 0 | D33: ='Classified FTEs'!H72+'Classified FTEs'!K72 -> 0 | E33: ='Classified FTEs'!I72+'Classified FTEs'!L72+'Classified FTEs'!M72+'Classified FTEs'!N72+'Classified FTEs'!O72 -> 0 | F33: ='Licensed FTEs'!O72 -> 1 | G33: ='Classified FTEs'!E72+'Classified FTEs'!F72+'Classified FTEs'!J72 -> 0.88 | H33: ='Licensed FTEs'!P72 -> 0 | I33: ='Classified FTEs'!V72 -> 0 | J33: ='Classified FTEs'!AD72 -> 0 | K33: ='Classified FTEs'!D72 -> 0 | L33: ='Classified FTEs'!T72+'Classified FTEs'!U72+'Classified FTEs'!W72+'Classified FTEs'!X72+'Classified FTEs'!Y72+'Classified FTEs'!AC72+'Classified FTEs'!AE72+'Classified FTEs'!AF72+'Classified FTEs'!AL72 -> 0.31 | M33: =SUM(C33:L33)+SUM('instruction-charters'!C33:N33) -> 11.37
A34: A5 | B34: ITINERIS EARLY COLLEGE HIGH | C34: ='Licensed FTEs'!N73 -> 0 | D34: ='Classified FTEs'!H73+'Classified FTEs'!K73 -> 0 | E34: ='Classified FTEs'!I73+'Classified FTEs'!L73+'Classified FTEs'!M73+'Classified FTEs'!N73+'Classified FTEs'!O73 -> 0 | F34: ='Licensed FTEs'!O73 -> 0.95 | G34: ='Classified FTEs'!E73+'Classified FTEs'!F73+'Classified FTEs'!J73 -> 2.5 | H34: ='Licensed FTEs'!P73 -> 0 | I34: ='Classified FTEs'!V73 -> 0 | J34: ='Classified FTEs'!AD73 -> 0 | K34: ='Classified FTEs'!D73 -> 0 | L34: ='Classified FTEs'!T73+'Classified FTEs'!U73+'Classified FTEs'!W73+'Classified FTEs'!X73+'Classified FTEs'!Y73+'Classified FTEs'!AC73+'Classified FTEs'!AE73+'Classified FTEs'!AF73+'Classified FTEs'!AL73 -> 0 | M34: =SUM(C34:L34)+SUM('instruction-charters'!C34:N34) -> 17.53
A35: 93 | B35: JOHN HANCOCK CHARTER SCHOOL | C35: ='Licensed FTEs'!N74 -> 0 | D35: ='Classified FTEs'!H74+'Classified FTEs'!K74 -> 1 | E35: ='Classified FTEs'!I74+'Classified FTEs'!L74+'Classified FTEs'!M74+'Classified FTEs'!N74+'Classified FTEs'!O74 -> 0 | F35: ='Licensed FTEs'!O74 -> 1 | G35: ='Classified FTEs'!E74+'Classified FTEs'!F74+'Classified FTEs'!J74 -> 1 | H35: ='Licensed FTEs'!P74 -> 0 | I35: ='Classified FTEs'!V74 -> 0 | J35: ='Classified FTEs'!AD74 -> 0 | K35: ='Classified FTEs'!D74 -> 0 | L35: ='Classified FTEs'!T74+'Classified FTEs'!U74+'Classified FTEs'!W74+'Classified FTEs'!X74+'Classified FTEs'!Y74+'Classified FTEs'!AC74+'Classified FTEs'!AE74+'Classified FTEs'!AF74+'Classified FTEs'!AL74 -> 0 | M35: =SUM(C35:L35)+SUM('instruction-charters'!C35:N35) -> 18.58
A36: 2E | B36: KARL G MAESER PREPARATORY ACADEMY | C36: ='Licensed FTEs'!N75 -> 0 | D36: ='Classified FTEs'!H75+'Classified FTEs'!K75 -> 0.1 | E36: ='Classified FTEs'!I75+'Classified FTEs'!L75+'Classified FTEs'!M75+'Classified FTEs'!N75+'Classified FTEs'!O75 -> 2 | F36: ='Licensed FTEs'!O75 -> 2.4 | G36: ='Classified FTEs'!E75+'Classified FTEs'!F75+'Classified FTEs'!J75 -> 2 | H36: ='Licensed FTEs'!P75 -> 0 | I36: ='Classified FTEs'!V75 -> 0 | J36: ='Classified FTEs'!AD75 -> 0 | K36: ='Classified FTEs'!D75 -> 0 | L36: ='Classified FTEs'!T75+'Classified FTEs'!U75+'Classified FTEs'!W75+'Classified FTEs'!X75+'Classified FTEs'!Y75+'Classified FTEs'!AC75+'Classified FTEs'!AE75+'Classified FTEs'!AF75+'Classified FTEs'!AL75 -> 0 | M36: =SUM(C36:L36)+SUM('instruction-charters'!C36:N36) -> 37.26
A37: 4C | B37: LAKEVIEW ACADEMY | C37: ='Licensed FTEs'!N76 -> 1 | D37: ='Classified FTEs'!H76+'Classified FTEs'!K76 -> 0 | E37: ='Classified FTEs'!I76+'Classified FTEs'!L76+'Classified FTEs'!M76+'Classified FTEs'!N76+'Classified FTEs'!O76 -> 0 | F37: ='Licensed FTEs'!O76 -> 2 | G37: ='Classified FTEs'!E76+'Classified FTEs'!F76+'Classified FTEs'!J76 -> 3.15 | H37: ='Licensed FTEs'!P76 -> 0 | I37: ='Classified FTEs'!V76 -> 0 | J37: ='Classified FTEs'!AD76 -> 1 | K37: ='Classified FTEs'!D76 -> 0 | L37: ='Classified FTEs'!T76+'Classified FTEs'!U76+'Classified FTEs'!W76+'Classified FTEs'!X76+'Classified FTEs'!Y76+'Classified FTEs'!AC76+'Classified FTEs'!AE76+'Classified FTEs'!AF76+'Classified FTEs'!AL76 -> 4.78 | M37: =SUM(C37:L37)+SUM('instruction-charters'!C37:N37) -> 64.28
A38: 5C | B38: LEGACY PREPARATORY ACADEMY | C38: ='Licensed FTEs'!N77 -> 1 | D38: ='Classified FTEs'!H77+'Classified FTEs'!K77 -> 0 | E38: ='Classified FTEs'!I77+'Classified FTEs'!L77+'Classified FTEs'!M77+'Classified FTEs'!N77+'Classified FTEs'!O77 -> 0 | F38: ='Licensed FTEs'!O77 -> 2 | G38: ='Classified FTEs'!E77+'Classified FTEs'!F77+'Classified FTEs'!J77 -> 0 | H38: ='Licensed FTEs'!P77 -> 0 | I38: ='Classified FTEs'!V77 -> 0 | J38: ='Classified FTEs'!AD77 -> 0 | K38: ='Classified FTEs'!D77 -> 0 | L38: ='Classified FTEs'!T77+'Classified FTEs'!U77+'Classified FTEs'!W77+'Classified FTEs'!X77+'Classified FTEs'!Y77+'Classified FTEs'!AC77+'Classified FTEs'!AE77+'Classified FTEs'!AF77+'Classified FTEs'!AL77 -> 0 | M38: =SUM(C38:L38)+SUM('instruction-charters'!C38:N38) -> 52.83
