Workbook

Sheet Holds
A29: 41548 | C29: Mental Holds (I.C. 66-326) by Ordering County
C30: =A29 -> 41548 | I30: SFY2014 -YTD
C31: 24 Hour-MD Hold | D31: 24 Hour-Police Hold | E31: Field Petition | F31: Administrative Hold | G31: County Total | H31: Regional Total | I31: 24 Hour-MD Hold | J31: 24 Hour-Police Hold | K31: Field Petition | L31: Administrative Hold | M31: County Total | N31: Regional Total
A33: Region 1 | B33: Benewah | C33: 2 | D33: 3 | G33: =SUM(C33:F33) -> 5 | H33: =SUM(C33:F37) -> 55 | I33: 3 | J33: 4 | M33: =SUM(I33:L33) -> 7 | N33: =SUM(I33:L37) -> 253
B34: Bonner | C34: 1 | D34: 2 | G34: =SUM(C34:F34) -> 3 | I34: 1 | J34: 20 | M34: =SUM(I34:L34) -> 21
B35: Boundary | G35: =SUM(C35:F35) -> 0 | M35: =SUM(I35:L35) -> 0
B36: Kootenai | C36: 9 | D36: 33 | F36: 5 | G36: =SUM(C36:F36) -> 47 | I36: 49 | J36: 142 | L36: 25 | M36: =SUM(I36:L36) -> 216
B37: Shoshone | G37: =SUM(C37:F37) -> 0 | I37: 1 | J37: 8 | M37: =SUM(I37:L37) -> 9
A38: Region 2 | B38: Clearwater | C38: 1 | F38: 1 | G38: =SUM(C38:F38) -> 2 | H38: =SUM(C38:F42) -> 20 | I38: 3 | J38: 1 | K38: 1 | L38: 2 | M38: =SUM(I38:L38) -> 7 | N38: =SUM(I38:L42) -> 86
B39: Idaho | C39: 1 | G39: =SUM(C39:F39) -> 1 | I39: 3 | J39: 2 | K39: 1 | M39: =SUM(I39:L39) -> 6
B40: Latah | C40: 5 | D40: 1 | G40: =SUM(C40:F40) -> 6 | I40: 10 | J40: 11 | K40: 2 | M40: =SUM(I40:L40) -> 23
B41: Lewis | G41: =SUM(C41:F41) -> 0 | K41: 2 | M41: =SUM(I41:L41) -> 2
B42: Nez Perce | C42: 6 | D42: 5 | G42: =SUM(C42:F42) -> 11 | I42: 32 | J42: 16 | M42: =SUM(I42:L42) -> 48
A43: Region 3 | B43: Adams | D43: 1 | G43: =SUM(C43:F43) -> 1 | H43: =SUM(C43:F48) -> 89 | I43: 3 | J43: 4 | M43: =SUM(I43:L43) -> 7 | N43: =SUM(I43:L48) -> 382
B44: Canyon | C44: 46 | D44: 29 | F44: 3 | G44: =SUM(C44:F44) -> 78 | I44: 172 | J44: 156 | L44: 7 | M44: =SUM(I44:L44) -> 335
B45: Gem | C45: 4 | D45: 3 | G45: =SUM(C45:F45) -> 7 | I45: 7 | J45: 12 | M45: =SUM(I45:L45) -> 19
B46: Owyhee | G46: =SUM(C46:F46) -> 0 | M46: =SUM(I46:L46) -> 0
B47: Payette | G47: =SUM(C47:F47) -> 0 | I47: 2 | J47: 7 | M47: =SUM(I47:L47) -> 9
B48: Washington | D48: 3 | G48: =SUM(C48:F48) -> 3 | I48: 5 | J48: 7 | M48: =SUM(I48:L48) -> 12
A49: Region 4 | B49: Ada | C49: 88 | D49: 67 | E49: 17 | F49: 1 | G49: =SUM(C49:F49) -> 173 | H49: =SUM(C49:F52) -> 180 | I49: 328 | J49: 253 | K49: 53 | L49: 1 | M49: =SUM(I49:L49) -> 635 | N49: =SUM(I49:L52) -> 652
B50: Boise | D50: 1 | G50: =SUM(C50:F50) -> 1 | J50: 3 | M50: =SUM(I50:L50) -> 3
B51: Elmore | C51: 3 | D51: 3 | G51: =SUM(C51:F51) -> 6 | I51: 5 | J51: 8 | K51: 1 | M51: =SUM(I51:L51) -> 14
B52: Valley | G52: =SUM(C52:F52) -> 0 | M52: =SUM(I52:L52) -> 0
A53: Region 5 | B53: Blaine | C53: 1 | D53: 2 | G53: =SUM(C53:F53) -> 3 | H53: =SUM(C53:F60) -> 39 | I53: 4 | J53: 7 | K53: 1 | M53: =SUM(I53:L53) -> 12 | N53: =SUM(I53:L60) -> 174
B54: Camas | G54: =SUM(C54:F54) -> 0 | I54: 1 | J54: 1 | L54: 1 | M54: =SUM(I54:L54) -> 3
B55: Cassia | C55: 4 | G55: =SUM(C55:F55) -> 4 | I55: 15 | M55: =SUM(I55:L55) -> 15
B56: Gooding | C56: 1 | G56: =SUM(C56:F56) -> 1 | I56: 9 | M56: =SUM(I56:L56) -> 9
B57: Jerome | C57: 1 | G57: =SUM(C57:F57) -> 1 | I57: 6 | J57: 2 | L57: 4 | M57: =SUM(I57:L57) -> 12
B58: Lincoln | C58: 1 | D58: 1 | G58: =SUM(C58:F58) -> 2 | I58: 3 | J58: 2 | M58: =SUM(I58:L58) -> 5
B59: Minidoka | C59: 1 | G59: =SUM(C59:F59) -> 1 | I59: 6 | J59: 5 | L59: 3 | M59: =SUM(I59:L59) -> 14
B60: Twin Falls | C60: 18 | D60: 9 | G60: =SUM(C60:F60) -> 27 | I60: 78 | J60: 24 | L60: 2 | M60: =SUM(I60:L60) -> 104
A61: Region 6 | B61: Bannock | C61: 15 | D61: 3 | F61: 1 | G61: =SUM(C61:F61) -> 19 | H61: =SUM(C61:F66) -> 21 | I61: 78 | J61: 6 | K61: 1 | L61: 7 | M61: =SUM(I61:L61) -> 92 | N61: =SUM(I61:L66) -> 104
B62: Bear Lake | G62: =SUM(C62:F62) -> 0 | I62: 1 | J62: 1 | M62: =SUM(I62:L62) -> 2
B63: Caribou | G63: =SUM(C63:F63) -> 0 | I63: 1 | M63: =SUM(I63:L63) -> 1
B64: Franklin | C64: 1 | G64: =SUM(C64:F64) -> 1 | I64: 2 | J64: 3 | M64: =SUM(I64:L64) -> 5
B65: Oneida | G65: =SUM(C65:F65) -> 0 | I65: 1 | M65: =SUM(I65:L65) -> 1
B66: Power | C66: 1 | G66: =SUM(C66:F66) -> 1 | I66: 3 | M66: =SUM(I66:L66) -> 3
A67: Region 7 | B67: Bingham | C67: 6 | D67: 1 | F67: 1 | G67: =SUM(C67:F67) -> 8 | H67: =SUM(C67:F76) -> 33 | I67: 10 | J67: 4 | L67: 32 | M67: =SUM(I67:L67) -> 46 | N67: =SUM(I67:L76) -> 145
B68: Bonneville | C68: 2 | D68: 5 | F68: 11 | G68: =SUM(C68:F68) -> 18 | I68: 4 | J68: 15 | L68: 52 | M68: =SUM(I68:L68) -> 71
B69: Butte | G69: =SUM(C69:F69) -> 0 | M69: =SUM(I69:L69) -> 0
...

Sheet Intakes, Admins, Discharges
A22: =Holds!A29 -> 41548 | C22: Intakes by County of Residence | N22: Admissions/Discharges
C23: Children's Mental Health | H23: Adult Mental Health | N23: Children's Mental Health | S23: Adult Mental Health
C24: =A22 -> 41548 | E24: SFY2014 | H24: =A22 -> 41548 | J24: SFY2014 | N24: =A22 -> 41548 | P24: SFY2014 | S24: =A22 -> 41548 | U24: SFY2014
C25: County Total | D25: Regional Total | E25: County Total | F25: Regional Total | H25: County Total | I25: Regional Total | J25: County Total | K25: Regional Total | N25: Admin | O25: Disch | P25: Admin | Q25: Disch | S25: Admin | T25: Disch | U25: Admin | V25: Disch
A26: Region 1 | B26: Benewah | D26: =SUM(C26:C30) -> 9 | E26: 5 | F26: =SUM(E26:E30) -> 114 | I26: =SUM(H26:H30) -> 44 | J26: 12 | K26: =SUM(J26:J30) -> 405 | N26: ='Admissions Tracking'!Q2 -> 5 | O26: 7 | P26: 26 | Q26: 30 | S26: 23 | T26: 22 | U26: 73 | V26: 81
B27: Bonner | E27: 10 | H27: 1 | J27: 40
B28: Boundary | J28: 1
B29: Kootenai | C29: 9 | E29: 92 | H29: 40 | J29: 325
B30: Shoshone | E30: 7 | H30: 3 | J30: 27
A31: Region 2 | B31: Clearwater | D31: =SUM(C31:C35) -> 6 | E31: 3 | F31: =SUM(E31:E35) -> 42 | H31: 3 | I31: =SUM(H31:H35) -> 20 | J31: 13 | K31: =SUM(J31:J35) -> 166 | O31: 2 | P31: 11 | Q31: 11 | S31: 13 | T31: 8 | U31: 40 | V31: 43
B32: Idaho | E32: 1 | J32: 13
B33: Latah | C33: 1 | E33: 14 | H33: 2 | J33: 49
B34: Lewis | J34: 4
B35: Nez Perce | C35: 5 | E35: 24 | H35: 15 | J35: 87
A36: Region 3 | B36: Adams | D36: =SUM(C36:C41) -> 19 | E36: 2 | F36: =SUM(E36:E41) -> 210 | I36: =SUM(H36:H41) -> 59 | J36: 8 | K36: =SUM(J36:J41) -> 762 | N36: 6 | O36: 4 | P36: 35 | Q36: 30 | S36: 24 | T36: 51 | U36: 72 | V36: 99
B37: Canyon | C37: 17 | E37: 172 | H37: 50 | J37: 634
B38: Gem | E38: 13 | H38: 3 | J38: 35
B39: Owyhee | E39: 5 | J39: 13
B40: Payette | C40: 1 | E40: 8 | H40: 1 | J40: 44
B41: Washington | C41: 1 | E41: 10 | H41: 5 | J41: 28
A42: Region 4 | B42: Ada | C42: 24 | D42: =SUM(C42:C45) -> 26 | E42: 269 | F42: =SUM(E42:E45) -> 277 | H42: 86 | I42: =SUM(H42:H45) -> 96 | J42: 1052 | K42: =SUM(J42:J45) -> 1085 | N42: 17 | O42: 17 | P42: 54 | Q42: 64 | S42: 23 | T42: 13 | U42: 76 | V42: 81
B43: Boise | E43: 1 | H43: 1 | J43: 6
B44: Elmore | C44: 1 | E44: 5 | H44: 5 | J44: 20
B45: Valley | C45: 1 | E45: 2 | H45: 4 | J45: 7
A46: Region 5 | B46: Blaine | D46: =SUM(C46:C53) -> 10 | E46: 3 | F46: =SUM(E46:E53) -> 98 | I46: =SUM(H46:H53) -> 55 | J46: 17 | K46: =SUM(J46:J53) -> 436 | N46: 8 | O46: 12 | P46: 35 | Q46: 34 | S46: 14 | T46: 15 | U46: 47 | V46: 47
B47: Camas | E47: 1 | J47: 5
B48: Cassia | C48: 1 | E48: 8 | H48: 5 | J48: 41
B49: Gooding | C49: 2 | E49: 5 | H49: 4 | J49: 20
B50: Jerome | E50: 3 | H50: 14 | J50: 21
B51: Lincoln | E51: 1 | H51: 2 | J51: 4
B52: Minidoka | C52: 1 | E52: 5 | H52: 2 | J52: 30
B53: Twin Falls | C53: 6 | E53: 72 | H53: 28 | J53: 298
A54: Region 6 | B54: Bannock | C54: 22 | D54: =SUM(C54:C59) -> 23 | E54: 53 | F54: =SUM(E54:E59) -> 60 | H54: 33 | I54: =SUM(H54:H59) -> 40 | J54: 208 | K54: =SUM(J54:J59) -> 245 | N54: 9 | O54: 11 | P54: 19 | Q54: 30 | S54: 10 | T54: 11 | U54: 45 | V54: 56
B55: Bear Lake | E55: 1 | H55: 4 | J55: 6
B56: Caribou | H56: 1 | J56: 3
B57: Franklin | E57: 3 | J57: 16
B58: Oneida | C58: 1 | H58: 2 | J58: 4
B59: Power | E59: 3 | J59: 8
A60: Region 7 | B60: Bingham | D60: =SUM(C60:C69) -> 18 | E60: 15 | F60: =SUM(E60:E69) -> 105 | H60: 13 | I60: =SUM(H60:H69) -> 91 | J60: 88 | K60: =SUM(J60:J69) -> 423 | N60: 9 | O60: 18 | P60: 47 | Q60: 73 | S60: 43 | T60: 46 | U60: 150 | V60: 153
B61: Bonneville | C61: 11 | E61: 69 | H61: 54 | J61: 267
...

Sheet AMH CMH Patients Served
A26: =Holds!A29 -> 41548 | C26: Children's Mental Health | F26: Adult Mental Health
C27: Number of children served this Month | D27: Number of children served SFY2014 | F27: Number of adults served this Month | G27: Number of adults served SFY2014
A30: Region 1 | B30: Benewah | C30: 79 | D30: 123 | F30: 379 | G30: 630
B31: Bonner
B32: Boundary
B33: Kootenai
B34: Shoshone
A35: Region 2 | B35: Clearwater | C35: 75 | D35: 94 | F35: 195 | G35: 330
B36: Idaho
B37: Latah
B38: Lewis
B39: Nez Perce
A40: Region 3 | B40: Adams | C40: 86 | D40: 129 | F40: 676 | G40: 1249
B41: Canyon
B42: Gem
B43: Owyhee
B44: Payette
B45: Washington
A46: Region 4 | B46: Ada | C46: 162 | D46: 247 | F46: 676 | G46: 1564
B47: Boise
B48: Elmore
B49: Valley
A50: Region 5 | B50: Blaine | C50: 91 | D50: 123 | F50: 262 | G50: 540
B51: Camas
B52: Cassia
B53: Gooding
B54: Jerome
B55: Lincoln
B56: Minidoka
B57: Twin Falls
A58: Region 6 | B58: Bannock | C58: 60 | D58: 91 | F58: 270 | G58: 500
B59: Bear Lake
B60: Caribou
B61: Franklin
B62: Oneida
B63: Power
A64: Region 7 | B64: Bingham | C64: 164 | D64: 287 | F64: 583 | G64: 965
B65: Bonneville
B66: Butte
B67: Clark
...

Sheet Invsigtns, Exams, and Commits
A24: =Holds!A29 -> 41548 | C24: Pre-Sentence Investigation Reports (I.C. 19-2524) | F24: Designated Examinations by Ordering County | K24: Civil Commitments (I.C. 66-329) by Ordering County
C25: Monthly | D25: SFY2014 | F25: Monthly County Total | G25: Monthly Regional Total | H25: SFY2014 County Total | I25: SFY2014 Regional Total | K25: Monthly County Total | L25: Monthly Regional Total | M25: SFY2014 County Total | N25: SFY2014 Regional Total
A28: Region 1 | B28: Benewah | C28: 5 | D28: 10 | F28: 5 | G28: =SUM(F28:F32) -> 55 | H28: 7 | I28: =SUM(H28:H32) -> 252 | L28: =SUM(K28:K32) -> 7 | N28: =SUM(M28:M32) -> 36
B29: Bonner | F29: 3 | H29: 21 | K29: 1 | M29: 8
B30: Boundary
B31: Kootenai | F31: 47 | H31: 215 | K31: 6 | M31: 27
B32: Shoshone | H32: 9 | M32: 1
A33: Region 2 | B33: Clearwater | C33: 2 | D33: 7 | F33: 2 | G33: =SUM(F33:F37) -> 20 | H33: 7 | I33: =SUM(H33:H37) -> 86 | K33: 1 | L33: =SUM(K33:K37) -> 2 | M33: 3 | N33: =SUM(M33:M37) -> 18
B34: Idaho | F34: 1 | H34: 6 | M34: 2
B35: Latah | F35: 6 | H35: 23 | M35: 8
B36: Lewis | H36: 2
B37: Nez Perce | F37: 11 | H37: 48 | K37: 1 | M37: 5
A38: Region 3 | B38: Adams | C38: 19 | D38: 47 | F38: 1 | G38: =SUM(F38:F43) -> 86 | H38: 5 | I38: =SUM(H38:H43) -> 354 | K38: 1 | L38: =SUM(K38:K43) -> 10 | M38: 1 | N38: =SUM(M38:M43) -> 53
B39: Canyon | F39: 75 | H39: 312 | K39: 9 | M39: 49
B40: Gem | F40: 7 | H40: 18 | M40: 1
B41: Owyhee
B42: Payette | H42: 8
B43: Washington | F43: 3 | H43: 11 | M43: 2
A44: Region 4 | B44: Ada | C44: 1 | D44: 17 | F44: 159 | G44: =SUM(F44:F47) -> 166 | H44: 585 | I44: =SUM(H44:H47) -> 601 | K44: 26 | L44: =SUM(K44:K47) -> 27 | M44: 140 | N44: =SUM(M44:M47) -> 144
B45: Boise | F45: 1 | H45: 2
B46: Elmore | F46: 6 | H46: 14 | K46: 1 | M46: 4
B47: Valley
A48: Region 5 | B48: Blaine | C48: 7 | D48: 27 | F48: 3 | G48: =SUM(F48:F55) -> 39 | H48: 12 | I48: =SUM(H48:H55) -> 174 | L48: =SUM(K48:K55) -> 4 | M48: 1 | N48: =SUM(M48:M55) -> 22
B49: Camas | H49: 3
B50: Cassia | F50: 4 | H50: 15 | K50: 1 | M50: 5
B51: Gooding | F51: 1 | H51: 9 | M51: 3
B52: Jerome | F52: 1 | H52: 12 | K52: 1 | M52: 1
B53: Lincoln | F53: 2 | H53: 5
B54: Minidoka | F54: 1 | H54: 14 | M54: 3
B55: Twin Falls | F55: 27 | H55: 104 | K55: 2 | M55: 9
A56: Region 6 | B56: Bannock | C56: 2 | D56: 21 | F56: 19 | G56: =SUM(F56:F61) -> 21 | H56: 91 | I56: =SUM(H56:H61) -> 103 | K56: 6 | L56: =SUM(K56:K61) -> 6 | M56: 39 | N56: =SUM(M56:M61) -> 44
B57: Bear Lake | H57: 2 | M57: 2
B58: Caribou | H58: 1
B59: Franklin | F59: 1 | H59: 5 | M59: 1
B60: Oneida | H60: 1
B61: Power | F61: 1 | H61: 3 | M61: 2
A62: Region 7 | B62: Bingham | C62: 8 | D62: 27 | F62: 7 | G62: =SUM(F62:F71) -> 32 | H62: 43 | I62: =SUM(H62:H71) -> 141 | K62: 2 | L62: =SUM(K62:K71) -> 11 | M62: 21 | N62: =SUM(M62:M71) -> 57
B63: Bonneville | F63: 18 | H63: 70 | K63: 7 | M63: 29
B64: Butte
B65: Clark
...

Sheet Hold Tracking
A1: MH Holds | B1: 41153 | C1: 41183 | D1: 41214 | E1: 41244 | F1: 41275 | G1: 41306 | H1: 41334 | I1: 41365 | J1: 41395 | K1: 41426 | L1: 41456 | M1: 41487 | N1: 41518 | O1: 41548
A2: Region 1 | B2: 44 | C2: 47 | D2: 56 | E2: 39 | F2: 48 | G2: 55 | H2: 46 | I2: =Holds!H33 -> 55 | J2: 65 | K2: 56 | L2: 80 | M2: 69 | N2: 50 | O2: 55
A3: Region 2 | B3: 27 | C3: 13 | D3: 17 | E3: 10 | F3: 19 | G3: 16 | H3: 20 | I3: =Holds!H38 -> 20 | J3: 24 | K3: 14 | L3: 28 | M3: 21 | N3: 17 | O3: 20
A4: Region 3 | B4: 91 | C4: 85 | D4: 64 | E4: 106 | F4: 91 | G4: 81 | H4: 79 | I4: =Holds!H43 -> 89 | J4: 94 | K4: 82 | L4: 112 | M4: 94 | N4: 82 | O4: 88
A5: Region 4 | B5: 167 | C5: 148 | D5: 146 | E5: 179 | F5: 163 | G5: 155 | H5: 156 | I5: =Holds!H49 -> 180 | J5: 174 | K5: 175 | L5: 156 | M5: 161 | N5: 154 | O5: 181
A6: Region 5 | B6: 44 | C6: 38 | D6: 53 | E6: 38 | F6: 40 | G6: 44 | H6: 42 | I6: =Holds!H53 -> 39 | J6: 45 | K6: 62 | L6: 48 | M6: 50 | N6: 39 | O6: 39
A7: Region 6 | B7: 29 | C7: 13 | D7: 12 | E7: 24 | F7: 20 | G7: 11 | H7: 20 | I7: =Holds!H61 -> 21 | J7: 12 | K7: 24 | L7: 27 | M7: 26 | N7: 28 | O7: 21
A8: Region 7 | B8: 29 | C8: 37 | D8: 28 | E8: 31 | F8: 36 | G8: 35 | H8: 26 | I8: =Holds!H67 -> 33 | J8: 36 | K8: 36 | L8: 37 | M8: 34 | N8: 42 | O8: 33
A9: Statewide Total | B9: 431 | C9: 381 | D9: 376 | E9: 427 | F9: 417 | G9: 397 | H9: 389 | I9: =Holds!H78 -> 437 | J9: 450 | K9: =SUM(K2:K8) -> 449 | L9: 488 | M9: 455 | N9: 412 | O9: 437

Sheet Served Tracking
A2: CMH Clients Served | B2: 41091 | C2: 41122 | D2: 41153 | E2: 41183 | F2: 41214 | G2: 41244 | H2: 41275 | I2: 41306 | J2: 41334 | K2: 41365 | L2: 41395 | M2: 41426 | N2: 41456 | O2: 41487 | P2: 41518 | Q2: 41548
A3: Region 1 | B3: 68 | C3: 65 | D3: 55 | E3: 63 | F3: 57 | G3: 63 | H3: 69 | I3: 68 | J3: 70 | K3: 76 | L3: 68 | M3: 61 | N3: 66 | O3: 74 | P3: 79 | Q3: 79
A4: Region 2 | B4: 67 | C4: 70 | D4: 69 | E4: 73 | F4: 71 | G4: 80 | H4: 84 | I4: 69 | J4: 85 | K4: 80 | L4: 81 | M4: 74 | N4: 72 | O4: 60 | P4: 68 | Q4: 75
A5: Region 3 | B5: 70 | C5: 76 | D5: 67 | E5: 67 | F5: 81 | G5: 72 | H5: 77 | I5: 79 | J5: 81 | K5: 82 | L5: 86 | M5: 83 | N5: 89 | O5: 80 | P5: 80 | Q5: 86
A6: Region 4 | B6: 132 | C6: 130 | D6: 126 | E6: 153 | F6: 152 | G6: 158 | H6: 175 | I6: 161 | J6: 181 | K6: 187 | L6: 169 | M6: 166 | N6: 170 | O6: 158 | P6: 165 | Q6: 162
A7: Region 5 | B7: 72 | C7: 67 | D7: 69 | E7: 87 | F7: 75 | G7: 77 | H7: 85 | I7: 86 | J7: 95 | K7: 96 | L7: 99 | M7: 90 | N7: 85 | O7: 89 | P7: 82 | Q7: 91
A8: Region 6 | B8: 54 | C8: 48 | D8: 53 | E8: 58 | F8: 55 | G8: 51 | H8: 58 | I8: 61 | J8: 69 | K8: 65 | L8: 68 | M8: 59 | N8: 51 | O8: 47 | P8: 49 | Q8: 60
A9: Region 7 | B9: 167 | C9: 188 | D9: 185 | E9: 180 | F9: 172 | G9: 157 | H9: 170 | I9: 172 | J9: 189 | K9: 180 | L9: 189 | M9: 206 | N9: 203 | O9: 179 | P9: 167 | Q9: 164
A10: CMH Clients Served | B10: =SUM(B3:B9) -> 630 | C10: =SUM(C3:C9) -> 644 | D10: =SUM(D3:D9) -> 624 | E10: =SUM(E3:E9) -> 681 | F10: =SUM(F3:F9) -> 663 | G10: =SUM(G3:G9) -> 658 | H10: =SUM(H3:H9) -> 718 | I10: =SUM(I3:I9) -> 696 | J10: =SUM(J3:J9) -> 770 | K10: 766 | L10: 760 | M10: =SUM(M3:M9) -> 739 | N10: 736 | O10: 687 | P10: 690 | Q10: 717
A13: AMH Clients Served | B13: 41091 | C13: 41122 | D13: 41153 | E13: 41183 | F13: 41214 | G13: 41244 | H13: 41275 | I13: 41306 | J13: 41334 | K13: 41365 | L13: 41395 | M13: 41426 | N13: 41456 | O13: 41487 | P13: 41518 | Q13: 41548
A14: Region 1 | B14: 324 | C14: 336 | D14: 305 | E14: 342 | F14: 349 | G14: 348 | H14: 323 | I14: 302 | J14: 329 | K14: 337 | L14: 334 | M14: 333 | N14: 361 | O14: 348 | P14: 343 | Q14: 379
A15: Region 2 | B15: 220 | C15: 221 | D15: 230 | E15: 251 | F15: 221 | G15: 223 | H15: 227 | I15: 205 | J15: 226 | K15: 225 | L15: 200 | M15: 197 | N15: 213 | O15: 189 | P15: 182 | Q15: 195
A16: Region 3 | B16: 438 | C16: 430 | D16: 426 | E16: 475 | F16: 484 | G16: 584 | H16: 615 | I16: 580 | J16: 571 | K16: 615 | L16: 623 | M16: 578 | N16: 638 | O16: 653 | P16: 631 | Q16: 676
A17: Region 4 | B17: 608 | C17: 644 | D17: 627 | E17: 648 | F17: 572 | G17: 602 | H17: 649 | I17: 647 | J17: 625 | K17: 652 | L17: 683 | M17: 662 | N17: 688 | O17: 710 | P17: 713 | Q17: 676
A18: Region 5 | B18: 302 | C18: 245 | D18: 221 | E18: 248 | F18: 243 | G18: 234 | H18: 250 | I18: 240 | J18: 239 | K18: 231 | L18: 247 | M18: 258 | N18: 265 | O18: 271 | P18: 258 | Q18: 262
A19: Region 6 | B19: 269 | C19: 249 | D19: 220 | E19: 225 | F19: 231 | G19: 228 | H19: 244 | I19: 219 | J19: 256 | K19: 268 | L19: 261 | M19: 255 | N19: 242 | O19: 275 | P19: 249 | Q19: 270
A20: Region 7 | B20: 478 | C20: 545 | D20: 449 | E20: 486 | F20: 462 | G20: 488 | H20: 477 | I20: 459 | J20: 495 | K20: 518 | L20: 480 | M20: 530 | N20: 539 | O20: 555 | P20: 538 | Q20: 583
A21: AMH Clients Served | B21: =SUM(B14:B20) -> 2639 | C21: =SUM(C14:C20) -> 2670 | D21: =SUM(D14:D20) -> 2478 | E21: =SUM(E14:E20) -> 2675 | F21: =SUM(F14:F20) -> 2562 | G21: =SUM(G14:G20) -> 2707 | H21: =SUM(H14:H20) -> 2785 | I21: =SUM(I14:I20) -> 2652 | J21: =SUM(J14:J20) -> 2741 | K21: 2846 | L21: 2828 | M21: =SUM(M14:M20) -> 2813 | N21: 2946 | O21: 3001 | P21: 2914 | Q21: 3041

Sheet Intake Tracking
A1: CMH Intakes | B1: 41153 | C1: 41183 | D1: 41214 | E1: 41244 | F1: 41275 | G1: 41306 | H1: 41334 | I1: 41365 | J1: 41395 | K1: 41426 | L1: 41456 | M1: 41487 | N1: 41518 | O1: 41548
A2: Region 1 | B2: 8 | C2: 12 | D2: 15 | E2: 12 | F2: 8 | G2: 13 | H2: 10 | I2: 16 | J2: 17 | K2: 4 | L2: 9 | M2: 11 | N2: 15 | O2: 9
A3: Region 2 | B3: 5 | C3: 9 | D3: 4 | E3: 10 | F3: 11 | G3: 4 | H3: 8 | I3: 7 | J3: 7 | K3: 8 | L3: 2 | M3: 2 | N3: 9 | O3: 5
A4: Region 3 | B4: 8 | C4: 19 | D4: 15 | E4: 16 | F4: 14 | G4: 15 | H4: 25 | I4: 14 | J4: 15 | K4: 19 | L4: 20 | M4: 12 | N4: 8 | O4: 19
A5: Region 4 | B5: 21 | C5: 33 | D5: 27 | E5: 20 | F5: 28 | G5: 20 | H5: 29 | I5: 40 | J5: 21 | K5: 21 | L5: 24 | M5: 16 | N5: 30 | O5: 26
A6: Region 5 | B6: 22 | C6: 18 | D6: 21 | E6: 20 | F6: 16 | G6: 14 | H6: 21 | I6: 18 | J6: 18 | K6: 13 | L6: 18 | M6: 12 | N6: 15 | O6: 11
A7: Region 6 | B7: 11 | C7: 18 | D7: 7 | E7: 6 | F7: 11 | G7: 11 | H7: 22 | I7: 7 | J7: 11 | K7: 9 | L7: 5 | M7: 6 | N7: 8 | O7: 23
A8: Region 7 | B8: 29 | C8: 35 | D8: 36 | E8: 23 | F8: 24 | G8: 29 | H8: 28 | I8: 42 | J8: 29 | K8: 44 | L8: 25 | M8: 22 | N8: 25 | O8: 18
A9: CMH Intakes | B9: 104 | C9: 144 | D9: 125 | E9: 107 | F9: 112 | G9: 106 | H9: 143 | I9: 144 | J9: 118 | K9: =SUM(K2:K8) -> 118 | L9: 103 | M9: 81 | N9: 110 | O9: 111
A12: AMH Intakes | B12: 41153 | C12: 41183 | D12: 41214 | E12: 41244 | F12: 41275 | G12: 41306 | H12: 41334 | I12: 41365 | J12: 41395 | K12: 41426 | L12: 41456 | M12: 41487 | N12: 41518 | O12: 41548
A13: Region 1 | B13: 59 | C13: 83 | D13: 80 | E13: 67 | F13: 66 | G13: 70 | H13: 81 | I13: 79 | J13: 92 | K13: 73 | L13: 103 | M13: 94 | N13: 97 | O13: 114
A14: Region 2 | B14: 40 | C14: 52 | D14: 46 | E14: 36 | F14: 46 | G14: 42 | H14: 32 | I14: 34 | J14: 40 | K14: 30 | L14: 50 | M14: 43 | N14: 33 | O14: 42
A15: Region 3 | B15: 117 | C15: 122 | D15: 105 | E15: 159 | F15: 175 | G15: 116 | H15: 125 | I15: 139 | J15: 174 | K15: 139 | L15: 180 | M15: 190 | N15: 183 | O15: 198
A16: Region 4 | B16: 203 | C16: 194 | D16: 191 | E16: 210 | F16: 214 | G16: 221 | H16: 223 | I16: 246 | J16: 311 | K16: 264 | L16: 280 | M16: 302 | N16: 244 | O16: 293
A17: Region 5 | B17: 79 | C17: 75 | D17: 80 | E17: 67 | F17: 75 | G17: 79 | H17: 79 | I17: 85 | J17: 106 | K17: 117 | L17: 118 | M17: 117 | N17: 99 | O17: 98
A18: Region 6 | B18: 54 | C18: 40 | D18: 50 | E18: 53 | F18: 48 | G18: 46 | H18: 53 | I18: 75 | J18: 52 | K18: 56 | L18: 42 | M18: 93 | N18: 54 | O18: 60
A19: Region 7 | B19: 72 | C19: 87 | D19: 91 | E19: 82 | F19: 81 | G19: 82 | H19: 85 | I19: 80 | J19: 80 | K19: 63 | L19: 99 | M19: 105 | N19: 113 | O19: 118
A20: AMH Intakes | B20: 624 | C20: 653 | D20: 643 | E20: 674 | F20: 705 | G20: 656 | H20: 678 | I20: 738 | J20: 855 | K20: =SUM(K13:K19) -> 742 | L20: 872 | M20: 960 | N20: 823 | O20: 923

Sheet Admissions Tracking
A1: CMH Admissions | B1: 41091 | C1: 41122 | D1: 41153 | E1: 41183 | F1: 41214 | G1: 41244 | H1: 41275 | I1: 41306 | J1: 41334 | K1: 41365 | L1: 41395 | M1: 41426 | N1: 41456 | O1: 41487 | P1: 41518 | Q1: 41548
A2: Region 1 | B2: 8 | C2: 5 | D2: 4 | E2: 6 | F2: 12 | G2: 6 | H2: 7 | I2: 9 | J2: 5 | K2: 6 | L2: 11 | M2: 7 | O2: 5 | P2: 9 | Q2: 5
A3: Region 2 | B3: 1 | C3: 1 | D3: 3 | E3: 4 | F3: 4 | G3: 7 | H3: 4 | I3: 4 | J3: 6 | K3: 5 | L3: 2 | M3: 3 | N3: 3 | O3: 2 | P3: 5
A4: Region 3 | B4: 7 | C4: 3 | D4: 6 | E4: 5 | F4: 10 | G4: 8 | H4: 9 | I4: 10 | J4: 10 | K4: 5 | L4: 8 | M4: 5 | N4: 19 | O4: 5 | P4: 5 | Q4: 6
A5: Region 4 | B5: 13 | C5: 14 | D5: 11 | E5: 17 | F5: 22 | G5: 15 | H5: 25 | I5: 15 | J5: 17 | K5: 19 | L5: 21 | M5: 15 | N5: 14 | O5: 8 | P5: 11 | Q5: 17
A6: Region 5 | B6: 3 | C6: 7 | D6: 9 | E6: 13 | F6: 13 | G6: 8 | H6: 12 | I6: 14 | J6: 12 | K6: 11 | L6: 8 | M6: 9 | N6: 10 | O6: 8 | P6: 7 | Q6: 8
A7: Region 6 | B7: 3 | C7: 8 | D7: 5 | E7: 8 | F7: 9 | G7: 3 | H7: 4 | I7: 8 | J7: 9 | K7: 6 | L7: 4 | M7: 5 | N7: 4 | O7: 7 | P7: 1 | Q7: 9
A8: Region 7 | B8: 11 | C8: 20 | D8: 9 | E8: 20 | F8: 14 | G8: 13 | H8: 15 | I8: 7 | J8: 12 | K8: 9 | L8: 15 | M8: 6 | N8: 16 | O8: 12 | P8: 8 | Q8: 9
A9: CMH Admissions | B9: 46 | C9: 58 | D9: 47 | E9: 73 | F9: 84 | G9: 60 | H9: 76 | I9: 67 | J9: 71 | K9: 61 | L9: 69 | M9: 50 | N9: 66 | O9: 47 | P9: 46 | Q9: 54
A12: AMH Admissions | B12: 41091 | C12: 41122 | D12: 41153 | E12: 41183 | F12: 41214 | G12: 41244 | H12: 41275 | I12: 41306 | J12: 41334 | K12: 41365 | L12: 41395 | M12: 41426 | N12: 41456 | O12: 41487 | P12: 41518 | Q12: 41548
A13: Region 1 | B13: 23 | C13: 22 | D13: 15 | E13: 29 | F13: 17 | G13: 13 | H13: 17 | I13: 13 | J13: 18 | K13: 15 | L13: 15 | M13: 14 | N13: 20 | O13: 9 | P13: 16 | Q13: 23
A14: Region 2 | B14: 9 | C14: 5 | D14: 13 | E14: 14 | F14: 19 | G14: 15 | H14: 16 | I14: 20 | J14: 10 | K14: 6 | L14: 6 | M14: 11 | N14: 7 | O14: 9 | P14: 7 | Q14: 13
A15: Region 3 | B15: 19 | C15: 11 | D15: 12 | E15: 21 | F15: 23 | G15: 9 | H15: 15 | I15: 17 | J15: 17 | K15: 19 | L15: 22 | M15: 14 | N15: 17 | O15: 14 | P15: 16 | Q15: 24
A16: Region 4 | B16: 18 | C16: 23 | D16: 22 | E16: 15 | F16: 14 | G16: 19 | H16: 19 | I16: 23 | J16: 13 | K16: 18 | L16: 17 | M16: 10 | N16: 15 | O16: 13 | P16: 20 | Q16: 23
A17: Region 5 | B17: 9 | C17: 19 | D17: 12 | E17: 19 | F17: 15 | G17: 8 | H17: 13 | I17: 7 | J17: 12 | K17: 15 | L17: 6 | M17: 11 | N17: 10 | O17: 11 | P17: 8 | Q17: 14
... A20: AMH Admissions | B20: 117 | C20: 131 | D20: 123 | E20: 142 | F20: 141 | G20: 94 | H20: 118 | I20: 127 | J20: 124 | K20: 125 | L20: 109 | M20: 90 | N20: 117 | O20: 103 | P20: 109 | Q20: 150

Sheet Discharge Tracking
A1: CMH Discharges | B1: 41091 | C1: 41122 | D1: 41153 | E1: 41183 | F1: 41214 | G1: 41244 | H1: 41275 | I1: 41306 | J1: 41334 | K1: 41365 | L1: 41395 | M1: 41426 | N1: 41456 | O1: 41487 | P1: 41518 | Q1: 41548
A2: Region 1 | B2: 7 | C2: 9 | D2: 12 | E2: 9 | F2: 5 | G2: 2 | H2: 6 | I2: 8 | J2: 6 | K2: 9 | L2: 5 | M2: 7 | N2: 4 | O2: 8 | P2: 8 | Q2: 7
A3: Region 2 | B3: 2 | C3: 3 | D3: 4 | E3: 4 | F3: 1 | G3: 4 | H3: 6 | I3: 1 | J3: 7 | K3: 2 | L3: 4 | M3: 5 | N3: 7 | O3: 1 | P3: 1 | Q3: 2
A4: Region 3 | B4: 2 | C4: 11 | D4: 8 | E4: 5 | F4: 9 | G4: 8 | H4: 6 | I4: 13 | J4: 3 | K4: 3 | L4: 10 | M4: 8 | N4: 10 | O4: 6 | P4: 10 | Q4: 4
A5: Region 4 | B5: 15 | C5: 5 | D5: 15 | E5: 11 | F5: 14 | G5: 12 | H5: 18 | I5: 11 | J5: 24 | K5: 25 | L5: 21 | M5: 15 | N5: 18 | O5: 14 | P5: 14 | Q5: 17
A6: Region 5 | B6: 9 | C6: 7 | D6: 7 | E6: 11 | F6: 11 | G6: 7 | H6: 12 | I6: 8 | J6: 6 | K6: 5 | L6: 11 | M6: 14 | N6: 2 | O6: 12 | P6: 4 | Q6: 12
A7: Region 6 | B7: 9 | C7: 6 | D7: 4 | E7: 4 | F7: 6 | G7: 4 | H7: 3 | I7: 9 | J7: 6 | K7: 3 | L7: 7 | M7: 10 | N7: 9 | O7: 5 | P7: 5 | Q7: 11
A8: Region 7 | B8: 13 | C8: 14 | D8: 8 | E8: 15 | F8: 15 | G8: 19 | H8: 13 | I8: 15 | J8: 14 | K8: 9 | L8: 5 | M8: 11 | N8: 22 | O8: 20 | P8: 17 | Q8: 18
A9: CMH Discharges | B9: =SUM(B2:B8) -> 57 | C9: =SUM(C2:C8) -> 55 | D9: =SUM(D2:D8) -> 58 | E9: =SUM(E2:E8) -> 59 | F9: =SUM(F2:F8) -> 61 | G9: =SUM(G2:G8) -> 56 | H9: =SUM(H2:H8) -> 64 | I9: =SUM(I2:I8) -> 65 | J9: =SUM(J2:J8) -> 66 | K9: 56 | L9: 63 | M9: 70 | N9: 72 | O9: 66 | P9: 59 | Q9: 71
A12: AMH Discharges | B12: 41091 | C12: 41122 | D12: 41153 | E12: 41183 | F12: 41214 | G12: 41244 | H12: 41275 | I12: 41306 | J12: 41334 | K12: 41365 | L12: 41395 | M12: 41426 | N12: 41456 | O12: 41487 | P12: 41518 | Q12: 41548
A13: Region 1 | B13: 35 | C13: 26 | D13: 17 | E13: 32 | F13: 23 | G13: 12 | H13: 20 | I13: 11 | J13: 14 | K13: 13 | L13: 19 | M13: 12 | N13: 18 | O13: 17 | P13: 24 | Q13: 22
A14: Region 2 | B14: 20 | C14: 17 | D14: 9 | E14: 24 | F14: 15 | G14: 20 | H14: 28 | I14: 18 | J14: 13 | K14: 16 | L14: 23 | M14: 13 | N14: 16 | O14: 5 | P14: 12 | Q14: 8
A15: Region 3 | B15: 15 | C15: 24 | D15: 10 | E15: 16 | F15: 20 | G15: 14 | H15: 13 | I15: 16 | J15: 15 | K15: 18 | L15: 20 | M15: 18 | N15: 13 | O15: 18 | P15: 17 | Q15: 51
A16: Region 4 | B16: 18 | C16: 29 | D16: 15 | E16: 21 | F16: 29 | G16: 8 | H16: 20 | I16: 23 | J16: 16 | K16: 19 | L16: 20 | M16: 19 | N16: 18 | O16: 13 | P16: 36 | Q16: 13
A17: Region 5 | B17: 18 | C17: 20 | D17: 14 | E17: 19 | F17: 21 | G17: 7 | H17: 14 | I17: 10 | J17: 13 | K17: 14 | L17: 11 | M17: 13 | N17: 9 | O17: 10 | P17: 11 | Q17: 15
A18: Region 6 | B18: 16 | C18: 15 | D18: 11 | E18: 11 | F18: 15 | G18: 8 | H18: 10 | I18: 10 | J18: 13 | K18: 15 | L18: 11 | M18: 9 | N18: 13 | O18: 11 | P18: 21 | Q18: 11
A19: Region 7 | B19: 32 | C19: 54 | D19: 41 | E19: 28 | F19: 28 | G19: 23 | H19: 18 | I19: 21 | J19: 36 | K19: 34 | L19: 18 | M19: 48 | N19: 41 | O19: 43 | P19: 22 | Q19: 46
A20: AMH Discharges | B20: =SUM(B13:B19) -> 154 | C20: =SUM(C13:C19) -> 185 | D20: =SUM(D13:D19) -> 117 | E20: =SUM(E13:E19) -> 151 | F20: =SUM(F13:F19) -> 151 | G20: =SUM(G13:G19) -> 92 | H20: =SUM(H13:H19) -> 123 | I20: =SUM(I13:I19) -> 109 | J20: =SUM(J13:J19) -> 120 | K20: 129 | L20: 122 | M20: 132 | N20: 128 | O20: 117 | P20: 143 | Q20: 166

Sheet TDC
B1: 41091 | C1: 41122 | D1: 41153 | E1: 41183 | F1: 41214 | G1: 41244 | H1: 41275 | I1: 41306 | J1: 41334 | K1: 41365 | L1: 41395 | M1: 41426 | N1: 41456 | O1: 41487 | P1: 41518 | Q1: 41548
A2: Pre-Sentence Investigation Reports (I.C. 19-2524) | B2: 85 | C2: 100 | D2: 87 | E2: 105 | F2: 104 | G2: 83 | H2: 102 | I2: 93 | J2: 110 | K2: =K15 -> 137 | L2: 63 | M2: =M15 -> 58 | N2: 25 | O2: 36 | P2: =P15 -> 38 | Q2: 47
A3: Designated Examinations | B3: 437 | C3: 434 | D3: 420 | E3: 368 | F3: 364 | G3: 413 | H3: 399 | I3: 387 | J3: 378 | K3: =K26 -> 360 | L3: 437 | M3: =M26 -> 432 | N3: 457 | O3: 439 | P3: =P26 -> 396 | Q3: 419
A4: Civil Commitments (I.C. 66-329) | B4: 89 | C4: 115 | D4: 77 | E4: 85 | F4: 88 | G4: 70 | H4: 88 | I4: 68 | J4: 61 | K4: =K37 -> 71 | L4: 94 | M4: =M37 -> 91 | N4: 105 | O4: 92 | P4: =P37 -> 89 | Q4: 82
A7: 192524 | B7: 41091 | C7: 41122 | D7: 41153 | E7: 41183 | F7: 41214 | G7: 41244 | H7: 41275 | I7: 41306 | J7: 41334 | K7: 41365 | L7: 41395 | M7: 41426 | N7: 41456 | O7: 41487 | P7: 41518 | Q7: 41548
A8: Region 1 | B8: 4 | C8: 12 | D8: 7 | E8: 6 | F8: 8 | G8: 9 | H8: 7 | I8: 4 | J8: 9 | K8: 8 | L8: 11 | M8: 10 | N8: 2 | O8: 2 | Q8: 5
A9: Region 2 | B9: 1 | C9: 2 | D9: 5 | E9: 8 | F9: 6 | G9: 5 | H9: 2 | I9: 2 | J9: 3 | K9: 4 | L9: 2 | M9: 3 | N9: 1 | O9: 2 | P9: 2 | Q9: 2
A10: Region 3 | B10: 20 | C10: 20 | D10: 17 | E10: 19 | F10: 16 | G10: 15 | H10: 19 | I10: 15 | J10: 18 | K10: 18 | L10: 10 | M10: 3 | N10: 1 | O10: 6 | P10: 9 | Q10: 19
A11: Region 4 | B11: 24 | C11: 27 | D11: 19 | E11: 29 | F11: 30 | G11: 16 | H11: 28 | I11: 35 | J11: 33 | K11: 49 | L11: 12 | M11: 8 | N11: 4 | O11: 7 | P11: 5 | Q11: 1
A12: Region 5 | B12: 10 | C12: 8 | D12: 9 | E12: 9 | F12: 9 | G12: 13 | H12: 19 | I12: 15 | J12: 14 | K12: 15 | L12: 5 | M12: 7 | O12: 9 | P12: 11 | Q12: 7
A13: Region 6 | B13: 11 | C13: 12 | D13: 14 | E13: 12 | F13: 10 | G13: 12 | H13: 14 | I13: 11 | J13: 13 | K13: 15 | L13: 11 | M13: 14 | N13: 8 | O13: 4 | P13: 7 | Q13: 2
A14: Region 7 | B14: 15 | C14: 19 | D14: 16 | E14: 22 | F14: 25 | G14: 13 | H14: 13 | I14: 11 | J14: 20 | K14: 28 | L14: 12 | M14: 13 | N14: 9 | O14: 6 | P14: 4 | Q14: 8
A15: Statewide Total | B15: 85 | C15: 100 | D15: 87 | E15: 105 | F15: 104 | G15: 83 | H15: 102 | I15: 93 | J15: 110 | K15: 137 | L15: 63 | M15: =SUM(M8:M14) -> 58 | N15: 25 | O15: 36 | P15: 38 | Q15: 44
A18: DE's | B18: 41091 | C18: 41122 | D18: 41153 | E18: 41183 | F18: 41214 | G18: 41244 | H18: 41275 | I18: 41306 | J18: 41334 | K18: 41365 | L18: 41395 | M18: 41426 | N18: 41456 | O18: 41487 | P18: 41518 | Q18: 41548
A19: Region 1 | B19: 45 | C19: 60 | D19: 44 | E19: 47 | F19: 56 | G19: 39 | H19: 46 | I19: 55 | J19: 49 | K19: 61 | L19: 65 | M19: 56 | N19: 79 | O19: 69 | P19: 50 | Q19: 55
A20: Region 2 | B20: 21 | C20: 15 | D20: 27 | E20: 12 | F20: 17 | G20: 10 | H20: 19 | I20: 15 | J20: 20 | K20: 19 | L20: 24 | M20: 14 | N20: 28 | O20: 21 | P20: 17 | Q20: 20
A21: Region 3 | B21: 90 | C21: 80 | D21: 88 | E21: 80 | F21: 57 | G21: 101 | H21: 84 | I21: 78 | J21: 74 | K21: 85 | L21: 90 | M21: 80 | N21: 99 | O21: 90 | P21: 75 | Q21: 85
A22: Region 4 | B22: 166 | C22: 163 | D22: 159 | E22: 142 | F22: 142 | G22: 171 | H22: 154 | I22: 152 | J22: 143 | K22: 114 | L22: 166 | M22: 162 | N22: 139 | O22: 150 | P22: 146 | Q22: 167
A23: Region 5 | B23: 49 | C23: 48 | D23: 44 | E23: 38 | F23: 53 | G23: 38 | H23: 40 | I23: 44 | J23: 47 | K23: 43 | L23: 45 | M23: 62 | N23: 48 | O23: 50 | P23: 39 | Q23: 39
A24: Region 6 | B24: 30 | C24: 26 | D24: 29 | E24: 13 | F24: 12 | G24: 24 | H24: 20 | I24: 11 | J24: 20 | K24: 20 | L24: 12 | M24: 24 | N24: 27 | O24: 26 | P24: 28 | Q24: 21
A25: Region 7 | B25: 36 | C25: 42 | D25: 29 | E25: 36 | F25: 27 | G25: 30 | H25: 36 | I25: 32 | J25: 25 | K25: 18 | L25: 35 | M25: 34 | N25: 37 | O25: 33 | P25: 41 | Q25: 32
A26: Statewide Total | B26: 437 | C26: 434 | D26: 420 | E26: 368 | F26: 364 | G26: 413 | H26: 399 | I26: 387 | J26: 378 | K26: 360 | L26: 437 | M26: =SUM(M19:M25) -> 432 | N26: 457 | O26: 439 | P26: 396 | Q26: 419
A29: 66-326/329 Pri 2 | B29: July | C29: August | D29: September | E29: October | F29: November | G29: December | H29: January | I29: February | J29: March | K29: 41365 | L29: 41395 | M29: 41426 | N29: 41456 | O29: 41487 | P29: 41518 | Q29: 41548
A30: Region 1 | B30: 15 | C30: 10 | D30: 11 | E30: 10 | F30: 11 | G30: 5 | H30: 12 | I30: 9 | J30: 4 | K30: 10 | L30: 10 | M30: 11 | N30: 9 | O30: 7 | P30: 9 | Q30: 12
A31: Region 2 | B31: 8 | C31: 6 | D31: 7 | E31: 3 | F31: 7 | G31: 4 | H31: 3 | I31: 3 | J31: 5 | K31: 6 | L31: 7 | M31: 5 | N31: 2 | O31: 5 | P31: 6 | Q31: 2
A32: Region 3 | B32: 11 | C32: 17 | D32: 12 | E32: 16 | F32: 13 | G32: 11 | H32: 11 | I32: 13 | J32: 10 | K32: 14 | L32: 21 | M32: 12 | N32: 19 | O32: 11 | P32: 10 | Q32: 11
A33: Region 4 | B33: 29 | C33: 48 | D33: 21 | E33: 28 | F33: 39 | G33: 26 | H33: 38 | I33: 21 | J33: 17 | K33: 24 | L33: 32 | M33: 37 | N33: 38 | O33: 37 | P33: 34 | Q33: 34
A34: Region 5 | B34: 5 | C34: 7 | D34: 3 | E34: 5 | F34: 3 | G34: 5 | H34: 4 | I34: 3 | J34: 5 | K34: 6 | L34: 5 | M34: 9 | N34: 6 | O34: 12 | P34: 4 | Q34: 3
A35: Region 6 | B35: 11 | C35: 10 | D35: 14 | E35: 9 | F35: 4 | G35: 8 | H35: 8 | I35: 4 | J35: 9 | K35: 6 | L35: 2 | M35: 6 | N35: 15 | O35: 8 | P35: 10 | Q35: 8
A36: Region 7 | B36: 10 | C36: 17 | D36: 9 | E36: 14 | F36: 11 | G36: 11 | H36: 12 | I36: 15 | J36: 11 | K36: 5 | L36: 17 | M36: 11 | N36: 16 | O36: 12 | P36: 16 | Q36: 12
A37: Statewide Total | B37: 89 | C37: 115 | D37: 77 | E37: 85 | F37: 88 | G37: 70 | H37: 88 | I37: 68 | J37: 61 | K37: 71 | L37: 94 | M37: =SUM(M30:M36) -> 91 | N37: 105 | O37: 92 | P37: 89 | Q37: 82
