Workbook

Sheet Extract
A1: CODE | B1: PER | C1: ENPLANED DOM | D1: ENPLANED INT | E1: ENPLANED COM | F1: ENPLANED TOT | G1: TOTAL PAX | H1: TOTAL INTL | I1: TRANSIT PAX | J1: NON-REV PAX | K1: ENPLANED FRT | L1: DEPLANED FRT | M1: TOT FREIGHT | N1: ENPLANED ML | O1: DEPLANED ML | P1: TOT FRT/ML | Q1: INTL FRT | R1: DOM PAX A/C | S1: DOM ALL CGO | T1: INT PAX A/C | U1: INT ALL CGO | V1: COMMUTER | W1: GA | X1: MILITARY | Y1: TOT A/C OPS | Z1: EnpDom-1 | AA1: EnpInt-1 | AB1: EnpCom-1 | AC1: EnpTot-1 | AD1: TotPax-1 | AE1: TotInt-1 | AF1: Transit-1 | AG1: NonRev-1 | AH1: EnpFrt-1 | AI1: DepFrt-1 | AJ1: TotFrt-1 | AK1: EnpMail-1 | AL1: DepMail-1 | AM1: TotF/M-1 | AN1: INTLFRT-1 | AO1: DomPaxAC-1 | AP1: DomAll-1 | AQ1: IntPax-1 | AR1: IntAll-1 | AS1: Commuter-1 | AT1: GA-1 | AU1: Mili-1 | AV1: TotA/COps-1 | AW1: STATE | AX1: INTLML | AY1: INTLML-1 | AZ1: ENTRYDATE | BA1: DATEMODIFIED
A2: =NAMFORM2!D4 -> 0 | B2: =NAMFORM2!C5 -> 0 | C2: =NAMFORM2!C8 -> 0 | D2: =NAMFORM2!C9 -> 0 | E2: =NAMFORM2!C10 -> 0 | F2: =NAMFORM2!C11 -> 0 | G2: =NAMFORM2!C12 -> 0 | H2: =NAMFORM2!C13 -> 0 | I2: =NAMFORM2!C15 -> 0 | J2: =NAMFORM2!C14 -> 0 | K2: =NAMFORM2!C17 -> 0 | L2: =NAMFORM2!C18 -> 0 | M2: =K2+L2 -> 0 | N2: =NAMFORM2!C19 -> 0 | O2: =NAMFORM2!C20 -> 0 | P2: =NAMFORM2!C21 -> 0 | Q2: =NAMFORM2!C23 -> 0 | R2: =NAMFORM2!C27 -> 0 | S2: =NAMFORM2!C28 -> 0 | T2: =NAMFORM2!C30 -> 0 | U2: =NAMFORM2!C31 -> 0 | V2: =NAMFORM2!C32 -> 0 | W2: =NAMFORM2!C33 -> 0 | X2: =NAMFORM2!C34 -> 0 | Y2: =NAMFORM2!C35 -> 0 | Z2: =NAMFORM2!D8 -> 0 | AA2: =NAMFORM2!D9 -> 0 | AB2: =NAMFORM2!D10 -> 0 | AC2: =NAMFORM2!D11 -> 0 | AD2: =NAMFORM2!D12 -> 0 | AE2: =NAMFORM2!D13 -> 0 | AF2: =NAMFORM2!D15 -> 0 | AG2: =NAMFORM2!D14 -> 0 | AH2: =NAMFORM2!D17 -> 0 | AI2: =NAMFORM2!D18 -> 0 | AJ2: =AH2+AI2 -> 0 | AK2: =NAMFORM2!D19 -> 0 | AL2: =NAMFORM2!D20 -> 0 | AM2: =NAMFORM2!D21 -> 0 | AN2: =NAMFORM2!D23 -> 0 | AO2: =NAMFORM2!D27 -> 0 | AP2: =NAMFORM2!D28 -> 0 | AQ2: =NAMFORM2!D30 -> 0 | AR2: =NAMFORM2!D31 -> 0 | AS2: =NAMFORM2!D32 -> 0 | AT2: =NAMFORM2!D33 -> 0 | AU2: =NAMFORM2!D34 -> 0 | AV2: =NAMFORM2!D35 -> 0 | AX2: =NAMFORM2!C24 -> 0 | AY2: =NAMFORM2!D24 -> 0 | AZ2: =NOW() -> 41647.426 | BA2: =NOW() -> 41647.426
A3: CHECK | F3: =F2-(C2+D2+E2) -> 0 | G3: =F2/G2*100 -> #DIV/0! | H3: =H2<G2 -> FALSE | M3: =K2+L2-M2 -> 0 | P3: =M2+N2+O2-P2 -> 0 | Y3: =Y2-(R2+S2+T2+U2+V2+W2+X2) -> 0 | AC3: =AC2-(Z2+AA2+AB2) -> 0 | AD3: =AC2/AD2*100 -> #DIV/0! | AE3: =AE2<AD2 -> FALSE | AJ3: =AH2+AI2-AJ2 -> 0 | AM3: =AJ2+AK2+AL2-AM2 -> 0 | AV3: =AV2-(AO2+AP2+AQ2+AR2+AS2+AT2+AU2) -> 0

Sheet NAMFORM2
E1: AIRPORTS COUNCIL INTERNATIONAL
A2: STATE/PROVINCE: | C2: CONTACT NAME
A3: CITY: | C3: FAX/E-MAIL/TEL
A4: AIRPORT: | C4: 3-LTR CODE
A5: 12-MONTH REPORTING PERIOD ENDING:
C6: CALENDAR YEAR 2013 | D6: CALENDAR YEAR 2012 | E6: % Change
A7: PART 1. COMMERCIAL PASSENGERS
A8: A. | B8: ENPLANED DOMESTIC (excluding commuter) | E8: =IF(OR(C8="",D8=""),"-",(C8-D8)/D8) -> -
A9: B. | B9: ENPLANED INTERNATIONAL (excluding commuter) | E9: =IF(OR(C9="",D9=""),"-",(C9-D9)/D9) -> -
A10: C. | B10: ENPLANED COMMUTER | E10: =IF(OR(C10="",D10=""),"-",(C10-D10)/D10) -> -
A11: D. | B11: ENPLANED TOTAL (D=A+B+C) | E11: =IF(OR(C11="",D11=""),"-",(C11-D11)/D11) -> -
A12: E. | B12: TOTAL PASSENGERS (enplaned and deplaned) | E12: =IF(OR(C12="",D12=""),"-",(C12-D12)/D12) -> -
A13: E1. | B13: TOTAL INTERNATIONAL PASSENGERS (enplaned and deplaned) | E13: =IF(OR(C13="",D13=""),"-",(C13-D13)/D13) -> -
A14: E2. | B14: NON-REVENUE PASSENGERS | E14: =IF(OR(C14="",D14=""),"-",(C14-D14)/D14) -> -
A15: F. | B15: DIRECT TRANSIT PASSENGERS | E15: =IF(OR(C15="",D15=""),"-",(C15-D15)/D15) -> -
A16: PART 2. FREIGHT/MAIL (metric tonnes) | C16: 1 metric tonne = U.S. ton (2000 lbs) x .907
A17: A. | B17: ENPLANED FREIGHT (including express) | E17: =IF(OR(C17="",D17=""),"-",(C17-D17)/D17) -> -
A18: B. | B18: DEPLANED FREIGHT (including express) | E18: =IF(OR(C18="",D18=""),"-",(C18-D18)/D18) -> -
A19: C. | B19: ENPLANED MAIL | E19: =IF(OR(C19="",D19=""),"-",(C19-D19)/D19) -> -
A20: D. | B20: DEPLANED MAIL | E20: =IF(OR(C20="",D20=""),"-",(C20-D20)/D20) -> -
A21: E. | B21: TOTAL FREIGHT/MAIL (E=A+B+C+D) | E21: =IF(OR(C21="",D21=""),"-",(C21-D21)/D21) -> -
A22: F. | B22: TOTAL INTERNATIONAL FREIGHT/MAIL | E22: =IF(OR(C22="",D22=""),"-",(C22-D22)/D22) -> -
A23: E1. | B23: INTERNATIONAL FREIGHT | E23: =IF(OR(C23="",D23=""),"-",(C23-D23)/D23) -> -
A24: E2. | B24: INTERNATIONAL MAIL | E24: =IF(OR(C24="",D24=""),"-",(C24-D24)/D24) -> -
A25: PART 3. AIRCRAFT OPERATIONS
A26: A. | B26: DOMESTIC COMMERCIAL (excluding commuter)
A27: A1. | B27: PASSENGER AIRCRAFT | E27: =IF(OR(C27="",D27=""),"-",(C27-D27)/D27) -> -
A28: A2. | B28: ALL-CARGO AIRCRAFT | E28: =IF(OR(C28="",D28=""),"-",(C28-D28)/D28) -> -
A29: B. | B29: INTERNATIONAL COMMERCIAL (excluding commuter)
A30: B1. | B30: PASSENGER AIRCRAFT | E30: =IF(OR(C30="",D30=""),"-",(C30-D30)/D30) -> -
A31: B2. | B31: ALL-CARGO AIRCRAFT | E31: =IF(OR(C31="",D31=""),"-",(C31-D31)/D31) -> -
A32: C. | B32: COMMUTER (excluding non-sched on-demand air taxi ops) | E32: =IF(OR(C32="",D32=""),"-",(C32-D32)/D32) -> -
A33: D. | B33: GENERAL AVIATION (including non-sched on-demand air taxi ops) | E33: =IF(OR(C33="",D33=""),"-",(C33-D33)/D33) -> -
A34: E. | B34: MILITARY | E34: =IF(OR(C34="",D34=""),"-",(C34-D34)/D34) -> -
A35: F. | B35: TOTAL AIRCRAFT OPERATIONS (F=A+B+C+D+E) | E35: =IF(OR(C35="",D35=""),"-",(C35-D35)/D35) -> -
E36: ENGANLNA
A38: Event(s) affecting traffic for the period reported:
A43: SUBMIT COMPLETED FORMS BY 20 FEBRUARY 2014 TO ACI, MONTREAL.
A44: Mailing address: PO Box 302, 800 Rue du Square Victoria, Montreal, Quebec H4Z 1G8, Canada
A45: Fax: +1 514 373 1201
...

Sheet QUAERO
A1: YEAR | B1: EUR | C1: 20080328 | D1: ENPLANED DOM | E1: ENPLANED INT | F1: ENPLANED COM | G1: ENPLANED TOT | H1: TOTAL PAX | I1: TOTAL INTL | J1: TRANSIT PAX | K1: NON-REV PAX | L1: ENPLANED FRT | M1: DEPLANED FRT | N1: TOT FREIGHT | O1: ENPLANED ML | P1: DEPLANED ML | Q1: TOT FRT/ML | R1: INTL FRT | S1: DOM PAX A/C | T1: DOM ALL CGO | U1: INT PAX A/C | V1: INT ALL CGO | W1: COMMUTER | X1: GA | Y1: MILITARY | Z1: TOT A/C OPS | AA1: EnpDom-1 | AB1: EnpInt-1 | AC1: EnpCom-1 | AD1: EnpTot-1 | AE1: TotPax-1 | AF1: TotInt-1 | AG1: Transit-1 | AH1: NonRev-1 | AI1: EnpFrt-1 | AJ1: DepFrt-1 | AK1: TotFrt-1 | AL1: EnpMail-1 | AM1: DepMail-1 | AN1: TotF/M-1 | AO1: INTLFRT-1 | AP1: DomPaxAC-1 | AQ1: DomAll-1 | AR1: IntPax-1 | AS1: IntAll-1 | AT1: Commuter-1 | AU1: GA-1 | AV1: Mili-1 | AW1: TotA/COps-1 | AX1: STATE | AY1: INTLML | AZ1: INTLML-1 | BA1: ENTRYDATE | BB1: DATEMODIFIED
A2: IATA | B2: YEAR | C2: MONTH | D2: C37 | E2: C38 | F2: C39 | G2: C36 | H2: C27 | I2: C41 | J2: C45 | K2: C44 | L2: C57 | M2: C58 | N2: C46 | O2: C69 | P2: C70 | Q2: C48 | R2: C60 | S2: C3 | T2: C19 | U2: C4 | V2: C20 | W2: C22 | X2: C24 | Y2: C25 | Z2: C1 | AA2: L37 | AB2: L38 | AC2: L39 | AD2: L36 | AE2: L27 | AF2: L41 | AG2: L45 | AH2: L44 | AI2: L57 | AJ2: L58 | AK2: L46 | AL2: L69 | AM2: L70 | AN2: L48 | AO2: L60 | AP2: L3 | AQ2: L19 | AR2: L4 | AS2: L20 | AT2: L22 | AU2: L24 | AV2: L25 | AW2: L1 | AY2: C67 | AZ2: L67 | BA2: END
A3: =IF(OR(Extract!A2=0, Extract!A2="CHECK"),"",Extract!A2) | B3: =IF(Extract!B2=0,"",Extract!B2) | D3: =IF(Extract!C2=0,"",Extract!C2) | E3: =IF(Extract!D2=0,"",Extract!D2) | F3: =IF(Extract!E2=0,"",Extract!E2) | G3: =IF(Extract!F2=0,"",Extract!F2) | H3: =IF(Extract!G2=0,"",Extract!G2) | I3: =IF(Extract!H2=0,"",Extract!H2) | J3: =IF(Extract!I2=0,"",Extract!I2) | K3: =IF(Extract!J2=0,"",Extract!J2) | ... BB3: =IF(Extract!BA2=0,"",Extract!BA2) -> 41647.426
A4: =IF(OR(Extract!A3=0, Extract!A3="CHECK"),"",Extract!A3) | B4: =IF(Extract!B3=0,"",Extract!B3) | D4: =IF(Extract!C3=0,"",Extract!C3) | E4: =IF(Extract!D3=0,"",Extract!D3) | F4: =IF(Extract!E3=0,"",Extract!E3) | G4: =IF(Extract!F3=0,"",Extract!F3) | H4: =IF(Extract!G3=0,"",Extract!G3) -> #DIV/0! | I4: =IF(Extract!H3=0,"",Extract!H3) -> FALSE | J4: =IF(Extract!I3=0,"",Extract!I3) | K4: =IF(Extract!J3=0,"",Extract!J3) | ... BB4: =IF(Extract!BA3=0,"",Extract!BA3)
A5: =IF(OR(Extract!A4=0, Extract!A4="CHECK"),"",Extract!A4) | B5: =IF(Extract!B4=0,"",Extract!B4) | D5: =IF(Extract!C4=0,"",Extract!C4) | E5: =IF(Extract!D4=0,"",Extract!D4) | F5: =IF(Extract!E4=0,"",Extract!E4) | G5: =IF(Extract!F4=0,"",Extract!F4) | H5: =IF(Extract!G4=0,"",Extract!G4) | I5: =IF(Extract!H4=0,"",Extract!H4) | J5: =IF(Extract!I4=0,"",Extract!I4) | K5: =IF(Extract!J4=0,"",Extract!J4) | ... BB5: =IF(Extract!BA4=0,"",Extract!BA4)
A6: =IF(Extract!A5=0,"",Extract!A5) | B6: =IF(Extract!B5=0,"",Extract!B5) | D6: =IF(Extract!C5=0,"",Extract!C5) | E6: =IF(Extract!D5=0,"",Extract!D5) | F6: =IF(Extract!E5=0,"",Extract!E5) | G6: =IF(Extract!F5=0,"",Extract!F5) | H6: =IF(Extract!G5=0,"",Extract!G5) | I6: =IF(Extract!H5=0,"",Extract!H5) | J6: =IF(Extract!I5=0,"",Extract!I5) | K6: =IF(Extract!J5=0,"",Extract!J5) | ... BB6: =IF(Extract!BA5=0,"",Extract!BA5)
A7: =IF(Extract!A6=0,"",Extract!A6) | B7: =IF(Extract!B6=0,"",Extract!B6) | D7: =IF(Extract!C6=0,"",Extract!C6) | E7: =IF(Extract!D6=0,"",Extract!D6) | F7: =IF(Extract!E6=0,"",Extract!E6) | G7: =IF(Extract!F6=0,"",Extract!F6) | H7: =IF(Extract!G6=0,"",Extract!G6) | I7: =IF(Extract!H6=0,"",Extract!H6) | J7: =IF(Extract!I6=0,"",Extract!I6) | K7: =IF(Extract!J6=0,"",Extract!J6) | ... BB7: =IF(Extract!BA6=0,"",Extract!BA6)
A8: =IF(Extract!A7=0,"",Extract!A7) | B8: =IF(Extract!B7=0,"",Extract!B7) | D8: =IF(Extract!C7=0,"",Extract!C7) | E8: =IF(Extract!D7=0,"",Extract!D7) | F8: =IF(Extract!E7=0,"",Extract!E7) | G8: =IF(Extract!F7=0,"",Extract!F7) | H8: =IF(Extract!G7=0,"",Extract!G7) | I8: =IF(Extract!H7=0,"",Extract!H7) | J8: =IF(Extract!I7=0,"",Extract!I7) | K8: =IF(Extract!J7=0,"",Extract!J7) | ... BB8: =IF(Extract!BA7=0,"",Extract!BA7)
A9: =IF(Extract!A8=0,"",Extract!A8) | B9: =IF(Extract!B8=0,"",Extract!B8) | D9: =IF(Extract!C8=0,"",Extract!C8) | E9: =IF(Extract!D8=0,"",Extract!D8) | F9: =IF(Extract!E8=0,"",Extract!E8) | G9: =IF(Extract!F8=0,"",Extract!F8) | H9: =IF(Extract!G8=0,"",Extract!G8) | I9: =IF(Extract!H8=0,"",Extract!H8) | J9: =IF(Extract!I8=0,"",Extract!I8) | K9: =IF(Extract!J8=0,"",Extract!J8) | ... BB9: =IF(Extract!BA8=0,"",Extract!BA8)
A10: =IF(Extract!A9=0,"",Extract!A9) | B10: =IF(Extract!B9=0,"",Extract!B9) | D10: =IF(Extract!C9=0,"",Extract!C9) | E10: =IF(Extract!D9=0,"",Extract!D9) | F10: =IF(Extract!E9=0,"",Extract!E9) | G10: =IF(Extract!F9=0,"",Extract!F9) | H10: =IF(Extract!G9=0,"",Extract!G9) | I10: =IF(Extract!H9=0,"",Extract!H9) | J10: =IF(Extract!I9=0,"",Extract!I9) | K10: =IF(Extract!J9=0,"",Extract!J9) | ... BB10: =IF(Extract!BA9=0,"",Extract!BA9)
A11: =IF(Extract!A10=0,"",Extract!A10) | B11: =IF(Extract!B10=0,"",Extract!B10) | D11: =IF(Extract!C10=0,"",Extract!C10) | E11: =IF(Extract!D10=0,"",Extract!D10) | F11: =IF(Extract!E10=0,"",Extract!E10) | G11: =IF(Extract!F10=0,"",Extract!F10) | H11: =IF(Extract!G10=0,"",Extract!G10) | I11: =IF(Extract!H10=0,"",Extract!H10) | J11: =IF(Extract!I10=0,"",Extract!I10) | K11: =IF(Extract!J10=0,"",Extract!J10) | ... BB11: =IF(Extract!BA10=0,"",Extract!BA10)
A12: =IF(Extract!A11=0,"",Extract!A11) | B12: =IF(Extract!B11=0,"",Extract!B11) | D12: =IF(Extract!C11=0,"",Extract!C11) | E12: =IF(Extract!D11=0,"",Extract!D11) | F12: =IF(Extract!E11=0,"",Extract!E11) | G12: =IF(Extract!F11=0,"",Extract!F11) | H12: =IF(Extract!G11=0,"",Extract!G11) | I12: =IF(Extract!H11=0,"",Extract!H11) | J12: =IF(Extract!I11=0,"",Extract!I11) | K12: =IF(Extract!J11=0,"",Extract!J11) | ... BB12: =IF(Extract!BA11=0,"",Extract!BA11)
A13: =IF(Extract!A12=0,"",Extract!A12) | B13: =IF(Extract!B12=0,"",Extract!B12) | D13: =IF(Extract!C12=0,"",Extract!C12) | E13: =IF(Extract!D12=0,"",Extract!D12) | F13: =IF(Extract!E12=0,"",Extract!E12) | G13: =IF(Extract!F12=0,"",Extract!F12) | H13: =IF(Extract!G12=0,"",Extract!G12) | I13: =IF(Extract!H12=0,"",Extract!H12) | J13: =IF(Extract!I12=0,"",Extract!I12) | K13: =IF(Extract!J12=0,"",Extract!J12) | ... BB13: =IF(Extract!BA12=0,"",Extract!BA12)
A14: =IF(Extract!A13=0,"",Extract!A13) | B14: =IF(Extract!B13=0,"",Extract!B13) | D14: =IF(Extract!C13=0,"",Extract!C13) | E14: =IF(Extract!D13=0,"",Extract!D13) | F14: =IF(Extract!E13=0,"",Extract!E13) | G14: =IF(Extract!F13=0,"",Extract!F13) | H14: =IF(Extract!G13=0,"",Extract!G13) | I14: =IF(Extract!H13=0,"",Extract!H13) | J14: =IF(Extract!I13=0,"",Extract!I13) | K14: =IF(Extract!J13=0,"",Extract!J13) | ... BB14: =IF(Extract!BA13=0,"",Extract!BA13)
A15: =IF(Extract!A14=0,"",Extract!A14) | B15: =IF(Extract!B14=0,"",Extract!B14) | D15: =IF(Extract!C14=0,"",Extract!C14) | E15: =IF(Extract!D14=0,"",Extract!D14) | F15: =IF(Extract!E14=0,"",Extract!E14) | G15: =IF(Extract!F14=0,"",Extract!F14) | H15: =IF(Extract!G14=0,"",Extract!G14) | I15: =IF(Extract!H14=0,"",Extract!H14) | J15: =IF(Extract!I14=0,"",Extract!I14) | K15: =IF(Extract!J14=0,"",Extract!J14) | ... BB15: =IF(Extract!BA14=0,"",Extract!BA14)
A16: =IF(Extract!A15=0,"",Extract!A15) | B16: =IF(Extract!B15=0,"",Extract!B15) | D16: =IF(Extract!C15=0,"",Extract!C15) | E16: =IF(Extract!D15=0,"",Extract!D15) | F16: =IF(Extract!E15=0,"",Extract!E15) | G16: =IF(Extract!F15=0,"",Extract!F15) | H16: =IF(Extract!G15=0,"",Extract!G15) | I16: =IF(Extract!H15=0,"",Extract!H15) | J16: =IF(Extract!I15=0,"",Extract!I15) | K16: =IF(Extract!J15=0,"",Extract!J15) | ... BB16: =IF(Extract!BA15=0,"",Extract!BA15)
A17: =IF(Extract!A16=0,"",Extract!A16) | B17: =IF(Extract!B16=0,"",Extract!B16) | D17: =IF(Extract!C16=0,"",Extract!C16) | E17: =IF(Extract!D16=0,"",Extract!D16) | F17: =IF(Extract!E16=0,"",Extract!E16) | G17: =IF(Extract!F16=0,"",Extract!F16) | H17: =IF(Extract!G16=0,"",Extract!G16) | I17: =IF(Extract!H16=0,"",Extract!H16) | J17: =IF(Extract!I16=0,"",Extract!I16) | K17: =IF(Extract!J16=0,"",Extract!J16) | ... BB17: =IF(Extract!BA16=0,"",Extract!BA16)
... A504: =IF(Extract!A503=0,"",Extract!A503) | B504: =IF(Extract!B503=0,"",Extract!B503) | D504: =IF(Extract!C503=0,"",Extract!C503) | E504: =IF(Extract!D503=0,"",Extract!D503) | F504: =IF(Extract!E503=0,"",Extract!E503) | G504: =IF(Extract!F503=0,"",Extract!F503) | H504: =IF(Extract!G503=0,"",Extract!G503) | I504: =IF(Extract!H503=0,"",Extract!H503) | J504: =IF(Extract!I503=0,"",Extract!I503) | K504: =IF(Extract!J503=0,"",Extract!J503) | ... BB504: =IF(Extract!BA503=0,"",Extract!BA503)
