Workbook
Name _GoBack: PETITION!$D$32
Name YNList: HIDE!$A$1:$A$2

Sheet Intro
B1: Scouting's Journey to Excellence
B2: Order of the Arrow Chapter Performance Recognition Program
B4: Chapter Journey to Excellence Interactive Guide
A6: Chapters may use this template to track their progress on their Journey to Excellence. The information will assist in both completing the Journey to Excellence petition and developing the Annual Report in Item 17 of the Chapter JTE.
A10: How to Use this Guide: Each of the chapter JTE's seventeen "items" are represented as "tabs" in this Excel spreadsheet. Each chapter should use this interactive guide in different ways throughout the year: At the beginning of the year. Every chapter should become intimately familiar with this guide at the beginning of the year, and use it to set and document the chapter's goals. The guide highlights the information the chapter must track, and identifies the goals the chapter sets for itself. Throughout the year. As the year progresses, each chapter should update the guide to track the chapter's progress. The guide will update in real-time to inform the chapter how the chapter in performing on its Journey to Excellence. Toward the end of the year. At the end of the year, chapters can consult this guide to help create the annual report in item 17, as well as to facilitate submitting an accurate JTE petition. The guide uses embedded formulas to calculate all of the necessary information, meaning the chapter can focus on inputting accurate data, and not on the math.
A30: If you have questions, or need to report errors in this guide, please contact the Chapter JTE Coordinator at:
A32: jte@oa-bsa.org

Sheet Worksheet
A1: Answer the questions on this page to begin the Chapter JTE Workbook. The values entered here will automatically populate in other tabs.
A2: Chapter Information
A3: Chapter Name
A5: Lodge Name
A7: Council Name
A9: Chapter Chief
A11: Chapter Adviser
A13: Chapter Staff Adviser
A15: Date of Chapter JTE Petition
A17: Membership Figures
A18: ="How many chapter members were registered on December 31, "&HIDE!B35&"?" -> How many chapter members were registered on December 31, 2012?
A20: ="How many chapter members were registered on December 31, "&HIDE!B34&"?" -> How many chapter members were registered on December 31, 2013?
A22: ="How many chapter members were registered on December 31, "&HIDE!B33&"?" -> How many chapter members were registered on December 31, 2014?
A24: Ordeal Membership
A25: ="How many chapter members were candidates for the Ordeal induction in "&HIDE!B34+'3 Ordeal Completion'!B34&"?" -> How many chapter members were candidates for the Ordeal induction in 2013?
A27: ="How many chapter members were inducted in "&HIDE!B34+'3 Ordeal Completion'!B34&"?" -> How many chapter members were inducted in 2013?
A29: ="How many chapter members were candidates for the Ordeal induction in "&HIDE!B33&"?" -> How many chapter members were candidates for the Ordeal induction in 2014?
A31: ="How many chapter members were inducted in "&HIDE!B33&"?" -> How many chapter members were inducted in 2014?
A33: Brotherhood Membership
A34: ="How many Ordeal members were eligible to go through the Brotherhood ceremony in "&HIDE!B34&"?" -> How many Ordeal members were eligible to go through the Brotherhood ceremony in 2013?
A36: ="How many Ordeal members went through the Brotherhood ceremony in "&HIDE!B34&"?" -> How many Ordeal members went through the Brotherhood ceremony in 2013?
A38: ="How many Ordeal members were eligible to go through the Brotherhood ceremony in "&HIDE!B33&"?" -> How many Ordeal members were eligible to go through the Brotherhood ceremony in 2014?
A40: ="How many Ordeal members went through the Brotherhood ceremony in "&HIDE!B33&"?" -> How many Ordeal members went through the Brotherhood ceremony in 2014?
A42: Unit Information
A43: ="How many troops and teams were in the district (or in the chapter's territory if different from the district) as of December 31, "&HIDE!B34&"?" -> How many troops and teams were in the district (or in the chapter's territory if different from the district) as of December 31, 2013?
A45: ="How many troops and teams were in the district (or in the chapter's territory if different from the district) as of December 31, "&HIDE!B33&"?" -> How many troops and teams were in the district (or in the chapter's territory if different from the district) as of December 31, 2014?

Sheet 1 Fiscal
A1: 1 | B1: Fiscal Management: Manage chapter revenue and expense according to council-lodge established procedures and leadership.
C3: Establish financial target(s) for the chapter | F3: Bronze | G3: 75
C5: Meet the chapter’s financial target(s) | F5: Silver | G5: 100
C7: Exceed the chapter’s financial target(s) | F7: Gold | G7: 200
B9: Depending on lodge/council procedures, chapters may or may not have funds or develop annual budgets. The key factor is: Does your chapter follow your lodge’s and/or council’s budgeting and accounting procedures in establishing its budget or financial targets? A financial target could be having and executing a budget for a specific chapter program/event, or it could be having and executing an annual chapter budget. Award points based on the chapter’s success at following lodge/council policies and in setting and/or achieving the established financial target.
C15: What specific financial target(s) will the chapter meet? | H15: Date Goal Made
B16: Set the Goal
C22: What steps must the chapter take before this item is accomplished?
B23: Plan Acheivement
C29: What steps did the chapter take to meet the chapter's financial target(s)? | H29: Date Goal Met
B30: Meet the Goal
C36: What specifically contributed to the chapter exceeding its financial target(s)? | H36: Date Goal Exceeded
B37: Exceed the Goal
C43: What specific financial target(s) should the chapter aim for next year?
B44: Plan for Next Year | C44: asdf

Sheet 2 Membership Impact
A1: 2 | B1: Membership Impact: Experience positive growth in membership in the chapter over the previous year. [REQUIRED]
C3: Grow membership by at least 1 | F3: Bronze | G3: 75
C5: Grow membership by at least 1% | F5: Silver | G5: 100
C7: Grow membership by at least 13% | F7: Gold | G7: 200
B9: Identify the Benchmark | C9: ="How many chapter members were registered on December 31 of "& HIDE!B34&"?" -> How many chapter members were registered on December 31 of 2013? | H9: =Worksheet!B20 -> 0
C15: What specific steps will the chapter take to grow membership in the chapter?
B16: Plan Acheivement
B22: Evaluate Success | C22: ="How many chapter members are registered on December 31 of "&HIDE!B33+'2 Membership Impact'!B33&"?" -> How many chapter members are registered on December 31 of 2014? | H22: =Worksheet!B22 -> 0
C28: Benchmark: | E28: =H9 -> 0
C29: This year: | E29: =H22 -> 0
D30: Growth (members): | E30: =E29-E28 -> 0
D31: Growth Percentage: | E31: =IF(E28<>0, E30/E28, "-") -> -
E32: =IF(E31="-", "-", IF((E31*100)>=13, "GOLD", IF((E31*100)>=1, "SILVER", IF(E30>=1, "BRONZE", "Not JTE Eligible")))) -> -
C35: What actions were successful or unsuccessful in achieving growth?
B36: Reflect on Achievement
C42: What should the chapter change next year to achieve maximum growth?
B43: Plan for Next Year

Sheet 3 Ordeal Completion
A1: 3 | B1: Ordeal completion: Complete induction of elected Ordeal candidates.
C3: Complete induction of at least 64% of Ordeal candidates or 5% increase | F3: Bronze | G3: 25
C6: Complete induction of at least 77% of Ordeal candidates or 5% increase over 64% | F6: Silver | G6: 50
C9: Complete induction of at least 98% of Ordeal candidates or 5% increase over 77% | F9: Gold | G9: 100
B12: Ordeal candidates from either lodge- or chapter-run inductions and ceremonies, as determined by the lodge and/or council, should be counted.
B15: Identify the Benchmark | C15: ="How many chapter members were candidates for the Ordeal induction in "&HIDE!B34+'3 Ordeal Completion'!B34&"?" -> How many chapter members were candidates for the Ordeal induction in 2013? | H15: =Worksheet!B25 -> 0
C18: ="How many chapter members were inducted in "&HIDE!B34+'3 Ordeal Completion'!B34&"?" -> How many chapter members were inducted in 2013? | H18: =Worksheet!B27 -> 0
C20: Percentage of candidates inducted last year: | E20: =IF(H15<>0, H18/H15, "-") -> -
C22: What specific steps can the chapter take to ensure as many candidates as possible are inducted this year?
B24: Plan Achievement
B30: Evaluate Success | C30: ="How many chapter members were candidates for the Ordeal induction in "&HIDE!B33&"?" -> How many chapter members were candidates for the Ordeal induction in 2014? | H30: =Worksheet!B29 -> 0
C33: ="How many chapter members were inducted in "&HIDE!B33&"?" -> How many chapter members were inducted in 2014? | H33: =Worksheet!B31 -> 0
C35: Percentage of candidates inducted this year: | E35: =IF(H30<>0, H33/H30, "-") -> -
E36: =IF(OR(E35="-", E20="-"), "-", IF(OR(E35*100>=98, AND((E35*100)-(E20*100)>=5, E20*100>=77)),"GOLD",IF(OR(E35*100>=77, AND(E35*100-E20*100>=5, E20*100>=64)), "SILVER", IF(OR(E35*100>=64, E35*100-E20*100>=5), "BRONZE", "NONE")))) -> -
C38: What caused candidates not to go through the Ordeal? How do you know?
B39: Reflect on Acheivement
C44: How can the chapter improve its induction percentage next year?
B45: Plan for Next Year

Sheet 4 Brotherhood Conversion
A1: 4 | B1: Brotherhood conversion: Convert eligible Ordeal members to Brotherhood [REQUIRED]
C4: Convert at least 25% or 5% increase over prior year | F4: Bronze | G4: 75
C6: Convert at least 32% or 3% increase over 25% | F6: Silver | G6: 100
C8: Convert at least 47% or 3% increase over 32% | F8: Gold | G8: 200
B10: Brotherhood candidates from either lodge or chapter run ceremonies, as determined by the lodge and/or council, should be counted.
B13: Identify the Benchmark | C13: ="How many Ordeal members were eligible to go through the Brotherhood ceremony in "&HIDE!B34&"?" -> How many Ordeal members were eligible to go through the Brotherhood ceremony in 2013? | H13: =Worksheet!B34 -> 0
C16: ="How many Ordeal members went through the Brotherhood ceremony in "&HIDE!B34&"?" -> How many Ordeal members went through the Brotherhood ceremony in 2013? | H16: =Worksheet!B36 -> 0
C19: ="Percentage of Ordeal members who sealed their membership in "&HIDE!B34&":" -> Percentage of Ordeal members who sealed their membership in 2013: | E19: =IF(H13<>0, H16/H13, "-") -> -
C22: What specific steps can the chapter take to ensure as many Ordeal members as possible seal their membership this year?
B24: Plan Achievement
B30: Evaluate Success | C30: ="How many Ordeal members were eligible to go through the Brotherhood ceremony in "&HIDE!B33&"?" -> How many Ordeal members were eligible to go through the Brotherhood ceremony in 2014? | H30: =Worksheet!B38 -> 0
C33: ="How many Ordeal members went through the Brotherhood ceremony in "&HIDE!B33&"?" -> How many Ordeal members went through the Brotherhood ceremony in 2014? | H33: =Worksheet!B40 -> 0
C36: ="Percentage of Ordeal members who sealed their membership in "&HIDE!B33&":" -> Percentage of Ordeal members who sealed their membership in 2014: | E36: =IF(H30<>0, H33/H30, "-") -> -
E38: =IF(OR(E36="-", E19="-"), "-", IF(OR(E36*100>=47, AND((E36*100)-(E19*100)>=3, E19*100>=32)),"GOLD",IF(OR(E36*100>=32, AND(E36*100-E19*100>=3, E19*100>=25)), "SILVER", IF(OR(E36*100>=25, E36*100-E19*100>=5), "BRONZE", "NONE")))) -> -
C40: What caused Ordeal members not to go through the Brotherhood ceremony? How do you know?
B42: Reflect on Acheivement
C47: How can the chapter improve its Brotherhood conversion next year?
B48: Plan for Next Year

Sheet 5 Membership Retention
A1: 5 | B1: Membership retention: Improve retention rate of chapter members.
C3: Achieve 69% or a 4% increase over prior year | F3: Bronze | G3: 75
C5: Achieve 77% or a 4% increase over 69% | F5: Silver | G5: 100
C7: Achieve 88% or a 5% increase over 77% | F7: Gold | G7: 200
B9: ="To determine chapter retention, take current year total membership less current year Ordeal inductions times 100 and then divide by prior year total membership. For example, ("&HIDE!B33&" total membership less "&HIDE!B33&" Ordeal inductions) * 100) ÷ ("&HIDE!B34&" total membership). All chapter numbers are to be taken from the same database source from which the lodge’s reported numbers on its charter renewal application were based." -> To determine chapter retention, take current year total membership less current year Ordeal inductions times 100 and then divide by prior year total membership. For example, (2014 total membership less 2014 Ordeal inductions) * 100) ÷ (2013 total membership). All chapter numbers are to be taken from the same database source from which the lodge’s reported numbers on its charter renewal application were based.
B15: Last year's achievement | C15: ="What was the chapter's total membership in "&HIDE!B35&"?" -> What was the chapter's total membership in 2012? | H15: =Worksheet!B18 -> 0
C17: ="What is the chapter's total membership at the end of "&HIDE!B34&"?" -> What is the chapter's total membership at the end of 2013? | H17: =Worksheet!B20 -> 0
C19: ="How many Ordeal candidates were inducted into the chapter in "&HIDE!B34&"?" -> How many Ordeal candidates were inducted into the chapter in 2013? | H19: =Worksheet!B27 -> 0
D21: ="Chapter retention for "&HIDE!B34&":" -> Chapter retention for 2013: | F21: =IF(H15<>0, (H17-H19)/H15, "-") -> -
C23: What specific steps can the chapter take to ensure as many of last year's members remain paid, active members?
B25: Plan Achievement
B31: Evaluate Success | C31: ="What is the chapter's total membership at the end of "&HIDE!B33&"?" -> What is the chapter's total membership at the end of 2014? | H31: =Worksheet!B22 -> 0
C33: ="How many Ordeal candidates were inducted into the chapter in "&HIDE!B33&"?" -> How many Ordeal candidates were inducted into the chapter in 2014? | H33: =Worksheet!B31 -> 0
D35: ="Chapter retention for "&HIDE!B33&":" -> Chapter retention for 2014: | F35: =IF(H17<>0, (H31-H33)/H17, "-") -> -
F36: =IF(OR(F35="-",F21="-"),"-",IF(OR(F35*100>=88,AND((F35*100)-(F21*100)>=5,F21*100>=77)),"GOLD",IF(OR(F35*100>=77,AND(F35*100-F21*100>=4,F21*100>=69)),"SILVER",IF(OR(F35*100>=69,F35*100-F21*100>=4),"BRONZE","NONE")))) -> -
C38: What caused last year's members not to return as paid, active members this year?
B40: Reflect on Acheivement
C45: How can the chapter improve its membership retention next year?
B46: Plan for Next Year

Sheet 6 Unit Elections
A1: 6 | B1: Unit elections: Conduct unit elections in district troops and teams desiring them.
C3: Complete elections for at least 90% of requesting units | F3: Bronze | G3: 25
C5: Complete elections for at least 95% of requesting units | F5: Silver | G5: 50
C7: Complete elections for 100% of requesting units | F7: Gold | G7: 100
B9: All troops and teams must have been contacted and given the opportunity to request an election. Election teams must be trained, all team members in proper uniform during each unit election, and team members must be from units other than the one for which the election is being held.
C13: ="How many troops and teams are in the district on December 31, "&HIDE!B33&"?" -> How many troops and teams are in the district on December 31, 2014? | H13: =Worksheet!B45 -> 0
C15: What is the chapter's plan to contract every troop and team in the district? | H15: Goal date to contact each unit
B16: Plan Acheivement
C22: Describe the plan to conduct an election in each unit requesting one.
B23: Plan Acheivement
B29: Evaluate Success | C29: ="How may troops and teams did the chapter contact in "&HIDE!B33&" for elections?" -> How may troops and teams did the chapter contact in 2014 for elections?
C31: ="How many troops and teams in the district requested an election in "&HIDE!B33&"?" -> How many troops and teams in the district requested an election in 2014?
C33: ="For how many troops and teams in the district did the chapter conduct an election in "&HIDE!B33&"?" -> For how many troops and teams in the district did the chapter conduct an election in 2014?
D35: Unit Election Percentage: | E35: =IF(H13-H29>0, "No points; not all units contacted", IF(H31<>0, H33/H31, "-")) -> -
E36: =IF(E35="-", "-", IF(E35*100>=100, "GOLD", IF(E35*100>=95, "SILVER", IF(E35*100>=90, "BRONZE", "No Points")))) -> -
C38: Analyze the effectiveness of the chapter's efforts.
B39: Evaluate Success
C45: How can the chapter achieve success more efficiently next year?
B46: Plan for Next Year

Sheet 7 Attendance
A1: 7 | B1: Lodge, section and national OA event attendance: Attend lodge, section and national OA events.
C3: Set and achieve a chapter attendance goal for OA events | F3: Bronze | H3: 25
C6: Exceed the chapter attendance goal by 10% | F6: Silver | H6: 50
C8: Exceed the chapter attendance goal by 20% | F8: Gold | H8: 100
B10: Chapters should support lodge events. Chapter member representation at section and national events or an OA High Adventure program is not required, but counts toward goal achievement when it occurs. The intent of this criterion is to encourage the chapter to set and meet a goal for participation in lodge events, and for chapters to support the lodge in reaching its goals for these events.
B16: Identify the Benchmark | C16: ="What was the chapter's total membership at the end of "&HIDE!B34&"?" -> What was the chapter's total membership at the end of 2013? | H16: =Worksheet!B20 -> 0
C20: List the lodge, section and national OA events at which the chapter will be represented. | D20: ="Attendance in "&HIDE!B34 -> Attendance in 2013 | E20: ="Goal for "&HIDE!B33 -> Goal for 2014 | F20: ="Actual Attendance in "&HIDE!B33 -> Actual Attendance in 2014 | H20: Goal Set? | I20: Goal Met? Goal Exceeded?
A21: Lodge Events | B21: 1. | H21: =IF(AND(C21="",E21<>""),"Insert Event Name",IF(AND(C21<>"",OR(E21=0,E21="")),"NEEDS GOAL",IF(AND(C21="",E21=""),"","Goal Set."))) | I21: =IF(AND(C21<>"",E21>0,F21>0,F21=E21),"Goal Met.",IF(AND(C21<>"",E21>0,F21>0,F21<E21),"Goal Not Met.",IF(AND(C21<>"",E21>0,F21>0,F21>=E21),"Goal Exceeded by "&ROUND(((((F21-E21)/E21))*100), 2)&"%.",IF(AND(C21<>"",E21>0),"NEEDS RESULT",""))))
B22: 2. | H22: =IF(AND(C22="",E22<>""),"Insert Event Name",IF(AND(C22<>"",OR(E22=0,E22="")),"NEEDS GOAL",IF(AND(C22="",E22=""),"","Goal Set."))) | I22: =IF(AND(C22<>"",E22>0,F22>0,F22=E22),"Goal Met.",IF(AND(C22<>"",E22>0,F22>0,F22<E22),"Goal Not Met.",IF(AND(C22<>"",E22>0,F22>0,F22>E22),"Goal Exceeded by "&ROUND(((((F22-E22)/E22))*100), 2)&"%.",IF(AND(C22<>"",E22>0),"NEEDS RESULT",""))))
B23: 3. | H23: =IF(AND(C23="",E23<>""),"Insert Event Name",IF(AND(C23<>"",OR(E23=0,E23="")),"NEEDS GOAL",IF(AND(C23="",E23=""),"","Goal Set."))) | I23: =IF(AND(C23<>"",E23>0,F23>0,F23=E23),"Goal Met.",IF(AND(C23<>"",E23>0,F23>0,F23<E23),"Goal Not Met.",IF(AND(C23<>"",E23>0,F23>0,F23>E23),"Goal Exceeded by "&ROUND(((((F23-E23)/E23))*100), 2)&"%.",IF(AND(C23<>"",E23>0),"NEEDS RESULT",""))))
B24: 4. | H24: =IF(AND(C24="",E24<>""),"Insert Event Name",IF(AND(C24<>"",OR(E24=0,E24="")),"NEEDS GOAL",IF(AND(C24="",E24=""),"","Goal Set."))) | I24: =IF(AND(C24<>"",E24>0,F24>0,F24=E24),"Goal Met.",IF(AND(C24<>"",E24>0,F24>0,F24<E24),"Goal Not Met.",IF(AND(C24<>"",E24>0,F24>0,F24>E24),"Goal Exceeded by "&ROUND(((((F24-E24)/E24))*100), 2)&"%.",IF(AND(C24<>"",E24>0),"NEEDS RESULT",""))))
B25: 5. | H25: =IF(AND(C25="",E25<>""),"Insert Event Name",IF(AND(C25<>"",OR(E25=0,E25="")),"NEEDS GOAL",IF(AND(C25="",E25=""),"","Goal Set."))) | I25: =IF(AND(C25<>"",E25>0,F25>0,F25=E25),"Goal Met.",IF(AND(C25<>"",E25>0,F25>0,F25<E25),"Goal Not Met.",IF(AND(C25<>"",E25>0,F25>0,F25>E25),"Goal Exceeded by "&ROUND(((((F25-E25)/E25))*100), 2)&"%.",IF(AND(C25<>"",E25>0),"NEEDS RESULT",""))))
H26: =IF(AND(C26="",E26<>""),"Insert Event Name",IF(AND(C26<>"",OR(E26=0,E26="")),"NEEDS GOAL",IF(AND(C26="",E26=""),"","Goal Set."))) | I26: =IF(AND(C26<>"",E26>0,F26>0,F26=E26),"Goal Met.",IF(AND(C26<>"",E26>0,F26>0,F26<E26),"Goal Not Met.",IF(AND(C26<>"",E26>0,F26>0,F26>E26),"Goal Exceeded by "&ROUND(((((F26-E26)/E26))*100), 2)&"%.",IF(AND(C26<>"",E26>0),"NEEDS RESULT",""))))
A27: Section Events | B27: 1. | H27: =IF(AND(C27="",E27<>""),"Insert Event Name",IF(AND(C27<>"",OR(E27=0,E27="")),"NEEDS GOAL",IF(AND(C27="",E27=""),"","Goal Set."))) | I27: =IF(AND(C27<>"",E27>0,F27>0,F27=E27),"Goal Met.",IF(AND(C27<>"",E27>0,F27>0,F27<E27),"Goal Not Met.",IF(AND(C27<>"",E27>0,F27>0,F27>E27),"Goal Exceeded by "&ROUND(((((F27-E27)/E27))*100), 2)&"%.",IF(AND(C27<>"",E27>0),"NEEDS RESULT",""))))
B28: 2. | H28: =IF(AND(C28="",E28<>""),"Insert Event Name",IF(AND(C28<>"",OR(E28=0,E28="")),"NEEDS GOAL",IF(AND(C28="",E28=""),"","Goal Set."))) | I28: =IF(AND(C28<>"",E28>0,F28>0,F28=E28),"Goal Met.",IF(AND(C28<>"",E28>0,F28>0,F28<E28),"Goal Not Met.",IF(AND(C28<>"",E28>0,F28>0,F28>E28),"Goal Exceeded by "&ROUND(((((F28-E28)/E28))*100), 2)&"%.",IF(AND(C28<>"",E28>0),"NEEDS RESULT",""))))
H29: =IF(AND(C29="",E29<>""),"Insert Event Name",IF(AND(C29<>"",OR(E29=0,E29="")),"NEEDS GOAL",IF(AND(C29="",E29=""),"","Goal Set."))) | I29: =IF(AND(C29<>"",E29>0,F29>0,F29=E29),"Goal Met.",IF(AND(C29<>"",E29>0,F29>0,F29<E29),"Goal Not Met.",IF(AND(C29<>"",E29>0,F29>0,F29>E29),"Goal Exceeded by "&ROUND(((((F29-E29)/E29))*100), 2)&"%.",IF(AND(C29<>"",E29>0),"NEEDS RESULT",""))))
A30: National Events | B30: 1. | H30: =IF(AND(C30="",E30<>""),"Insert Event Name",IF(AND(C30<>"",OR(E30=0,E30="")),"NEEDS GOAL",IF(AND(C30="",E30=""),"","Goal Set."))) | I30: =IF(AND(C30<>"",E30>0,F30>0,F30=E30),"Goal Met.",IF(AND(C30<>"",E30>0,F30>0,F30<E30),"Goal Not Met.",IF(AND(C30<>"",E30>0,F30>0,F30>E30),"Goal Exceeded by "&ROUND(((((F30-E30)/E30))*100), 2)&"%.",IF(AND(C30<>"",E30>0),"NEEDS RESULT",""))))
B31: 2. | H31: =IF(AND(C31="",E31<>""),"Insert Event Name",IF(AND(C31<>"",OR(E31=0,E31="")),"NEEDS GOAL",IF(AND(C31="",E31=""),"","Goal Set."))) | I31: =IF(AND(C31<>"",E31>0,F31>0,F31=E31),"Goal Met.",IF(AND(C31<>"",E31>0,F31>0,F31<E31),"Goal Not Met.",IF(AND(C31<>"",E31>0,F31>0,F31>E31),"Goal Exceeded by "&ROUND(((((F31-E31)/E31))*100), 2)&"%.",IF(AND(C31<>"",E31>0),"NEEDS RESULT",""))))
C33: AVERAGES: | D33: =IF(SUM(D21:D31)>0,ROUND(AVERAGE(D21:D31),2),"-") -> - | E33: =IF(SUM(E21:E31)>0,ROUND(AVERAGE(E21:E31),2),"-") -> - | F33: =IF(SUM(F21:F31)>0,ROUND(AVERAGE(F21:F31),2),"-") -> - | H33: =IF(COUNTIF(H21:H31,"NEEDS GOAL")>=1,"Goal Needed",IF(COUNTIF(H21:H31,"Goal Set.")>=1,"Goals Set.","-")) -> - | I33: =IF(H33="-","-",IF(COUNTIF(I21:I31,"Needs Result")>=1,"Result Needed.",IF(H33="Goal Needed","Goal Needed",IF(AND(H33="Goals Set.",AVERAGE(HIDE!G21:G31)=0),"Goals Met.",IF(AND(H33="Goals Set.",AVERAGE(HIDE!G21:G31)>0),"Goal Exceeded by "&ROUND(AVERAGE(HIDE!G21:G31),2)&"%.","-"))))) -> -
H34: JTE Level: | I34: =IF(H33="-","-",IF(H33="Goal Needed","NONE - Goal Needed",IF(I33="Result Needed.","NONE - Result Needed",IF(I33="Did Not Meet Goal","-",IF(AVERAGE(HIDE!G21:G31)>=20,"GOLD",IF(AVERAGE(HIDE!G21:G31)>=10,"SILVER",IF(AVERAGE(HIDE!G21:G31)>=0,"BRONZE","None"))))))) -> -
C35: How can the chapter improve attendance next year?
B36: Plan for Next Year

Sheet 8 Communications
A1: 8 | B1: Chapter communications: Maintain active communications within the chapter.
C3: Have and follow a written chapter communication plan | F3: Bronze | G3: 25
C5: Communicate regularly with unit OA representatives | F5: Silver | G5: 50
C7: Contribute to the lodge and/or council newsletter or website | F7: Gold | G7: 100
C10: Provide a brief overview of the chapter's written communication plan. Include how the chapter will communicate regularly with the unit OA representatives. Provide a plan for contributing to the lodge and/or council newsletter or website. Attach the actual plan to the annual lodge report.
B14: Describe the Plan
C20: How will the chapter remain accountable for following its communication plan?
B21: Plan for Success
B27: Evaluate Achievement | C27: Did the chapter maintain a communication plan?
C29: Did the chapter follow the communication plan?
C31: Did the chapter regularly communicate with unit OA representatives?
C33: Did the chapter contribute to the lodge and/or council newsletter or website?
C35: What obstacles did the chapter face when trying to follow its communication plan?
B37: Reflect on Difficulties
C43: What should the chapter do differently next year? What additional support is needed?
B45: Plan for Next Year

Sheet 9 Participation
A1: 9 | B1: Chapter meetings and event participation: Improve chapter membership participation at chapter meetings and events.
B3: Set and achieve a chapter attendance goal for OA events | G3: Bronze | H3: 25
B6: Exceed the chapter attendance goal by 20% | G6: Silver | H6: 50
B8: Exceed the chapter attendance goal by 30% | G8: Gold | H8: 100
C10: Identify the Benchmark | D10: ="What was the chapter's total membership at the end of "&HIDE!B34&"?" -> What was the chapter's total membership at the end of 2013? | H10: =Worksheet!B20 -> 0
B15: List the chapter meetings and events where all chapter members are invited to attend. | D15: ="Attendance in "&HIDE!B34 -> Attendance in 2013 | E15: ="Goal for "&HIDE!B33 -> Goal for 2014 | F15: ="Actual Attendance in "&HIDE!B33 -> Actual Attendance in 2014 | G15: Goal Set? | H15: Goal Achievement | I15: Percentage of chapter membership in attendance
A16: 1. | G16: =IF(AND(B16="",E16<>""),"Insert Event Name",IF(AND(B16<>"",OR(E16=0,E16="")),"NEEDS GOAL",IF(AND(B16="",E16=""),"","Done"))) | H16: =IF(AND(B16<>"", E16>0, F16>=0), ROUND(((F16-E16)/E16), 2), "") | I16: =IF(AND(B16<>"", $H$10>0), F16/$H$10, "")
A17: 2. | G17: =IF(AND(B17="",E17<>""),"Insert Event Name",IF(AND(B17<>"",OR(E17=0,E17="")),"NEEDS GOAL",IF(AND(B17="",E17=""),"","Done"))) | H17: =IF(AND(B17<>"", E17>0, F17>=0), ROUND(((F17-E17)/E17), 2), "") | I17: =IF(AND(B17<>"", $H$10>0), F17/$H$10, "")
A18: 3. | G18: =IF(AND(B18="",E18<>""),"Insert Event Name",IF(AND(B18<>"",OR(E18=0,E18="")),"NEEDS GOAL",IF(AND(B18="",E18=""),"","Done"))) | H18: =IF(AND(B18<>"", E18>0, F18>=0), ROUND(((F18-E18)/E18), 2), "") | I18: =IF(AND(B18<>"", $H$10>0), F18/$H$10, "")
A19: 4. | G19: =IF(AND(B19="",E19<>""),"Insert Event Name",IF(AND(B19<>"",OR(E19=0,E19="")),"NEEDS GOAL",IF(AND(B19="",E19=""),"","Done"))) | H19: =IF(AND(B19<>"", E19>0, F19>=0), ROUND(((F19-E19)/E19), 2), "") | I19: =IF(AND(B19<>"", $H$10>0), F19/$H$10, "")
A20: 5. | G20: =IF(AND(B20="",E20<>""),"Insert Event Name",IF(AND(B20<>"",OR(E20=0,E20="")),"NEEDS GOAL",IF(AND(B20="",E20=""),"","Done"))) | H20: =IF(AND(B20<>"", E20>0, F20>=0), ROUND(((F20-E20)/E20), 2), "") | I20: =IF(AND(B20<>"", $H$10>0), F20/$H$10, "")
A21: 6. | G21: =IF(AND(B21="",E21<>""),"Insert Event Name",IF(AND(B21<>"",OR(E21=0,E21="")),"NEEDS GOAL",IF(AND(B21="",E21=""),"","Done"))) | H21: =IF(AND(B21<>"", E21>0, F21>=0), ROUND(((F21-E21)/E21), 2), "") | I21: =IF(AND(B21<>"", $H$10>0), F21/$H$10, "")
A22: 7. | G22: =IF(AND(B22="",E22<>""),"Insert Event Name",IF(AND(B22<>"",OR(E22=0,E22="")),"NEEDS GOAL",IF(AND(B22="",E22=""),"","Done"))) | H22: =IF(AND(B22<>"", E22>0, F22>=0), ROUND(((F22-E22)/E22), 2), "") | I22: =IF(AND(B22<>"", $H$10>0), F22/$H$10, "")
A23: 8. | G23: =IF(AND(B23="",E23<>""),"Insert Event Name",IF(AND(B23<>"",OR(E23=0,E23="")),"NEEDS GOAL",IF(AND(B23="",E23=""),"","Done"))) | H23: =IF(AND(B23<>"", E23>0, F23>=0), ROUND(((F23-E23)/E23), 2), "") | I23: =IF(AND(B23<>"", $H$10>0), F23/$H$10, "")
A24: 9. | G24: =IF(AND(B24="",E24<>""),"Insert Event Name",IF(AND(B24<>"",OR(E24=0,E24="")),"NEEDS GOAL",IF(AND(B24="",E24=""),"","Done"))) | H24: =IF(AND(B24<>"", E24>0, F24>=0), ROUND(((F24-E24)/E24), 2), "") | I24: =IF(AND(B24<>"", $H$10>0), F24/$H$10, "")
A25: 10. | G25: =IF(AND(B25="",E25<>""),"Insert Event Name",IF(AND(B25<>"",OR(E25=0,E25="")),"NEEDS GOAL",IF(AND(B25="",E25=""),"","Done"))) | H25: =IF(AND(B25<>"", E25>0, F25>=0), ROUND(((F25-E25)/E25), 2), "") | I25: =IF(AND(B25<>"", $H$10>0), F25/$H$10, "")
A26: 11. | G26: =IF(AND(B26="",E26<>""),"Insert Event Name",IF(AND(B26<>"",OR(E26=0,E26="")),"NEEDS GOAL",IF(AND(B26="",E26=""),"","Done"))) | H26: =IF(AND(B26<>"", E26>0, F26>=0), ROUND(((F26-E26)/E26), 2), "") | I26: =IF(AND(B26<>"", $H$10>0), F26/$H$10, "")
A27: 12. | G27: =IF(AND(B27="",E27<>""),"Insert Event Name",IF(AND(B27<>"",OR(E27=0,E27="")),"NEEDS GOAL",IF(AND(B27="",E27=""),"","Done"))) | H27: =IF(AND(B27<>"", E27>0, F27>=0), ROUND(((F27-E27)/E27), 2), "") | I27: =IF(AND(B27<>"", $H$10>0), F27/$H$10, "")
H28: =IF(COUNTBLANK(H16:H27)>=12,"-", AVERAGE(H16:H27)) -> -
A29: Evaluate Success | B29: Average Attendance Goal | E29: =IF(COUNTA($B16:$B27)*$H10<>0, SUM(E16:E27)/(COUNTA($B16:$B27)*$H10), "-") -> -
B30: Actual Average Attendance Percentage | E30: =IF((COUNTA($B16:$B27)*$H10)<>0, (SUM(F16:F27)/(COUNTA($B16:$B27)*$H10)), "-") -> -
B32: =IF(G32="Goal Needed", "Chapter did not set goals for all meetings listed.", IF(OR(E30="-",E29="-"), "-", IF(E30>E29,"Chapter exceeded its attendance goal by "&ROUND((E30-E29)*100, 2)&"% of its members and "&ROUND((AVERAGE(H16:H27))*100, 2)&"% of its target goal.",IF(AND(E30<E29, E30>0),"Chapter failed to meet its attendance goal by "&ROUND((E30-E29)*100, 2)&"% of its members and "&ROUND((AVERAGE(H16:H27))*100, 2)&"% of its target goal.", IF(SUM(E16:E27)=SUM(F16:F27), "Chapter met its goal.", "-"))))) -> - | G32: =IF(COUNTIF(G16:G27,"NEEDS GOAL")>=1, "Goal Needed", IF(H28="-", "-", IF(H28*100>=30, "GOLD", IF(H28*100>=20, "SILVER", IF(H28*100>=0, "BRONZE", "None"))))) -> -

Sheet 10 Planning
A1: 10 | B1: Chapter planning: Maintain an active planning process that guides chapter program and supports the lodge’s plans.
C4: Have a written annual plan approved by the lodge executive committee; submit approved plan to district committee and/or executive. | F4: Bronze | G4: 25
C8: Conduct an annual review and update of your plan, in conjunction with your lodge’s plan | F8: Silver | G8: 50
C11: Meet with the district committee and/or executive to review/update your plan | F11: Gold | G11: 100
B14: Evaluate Achievement | C14: Did the chapter create a written annual plan?
C16: Did the lodge executive committee approve the chapter's written annual plan?
D18: On what date?
C20: Did the chapter submit the approved plan to the district committee and/or district executive?
D23: On what date?
C25: Did the chapter conduct an annual review and update of the plan?
D27: On what date?
C29: Did the chapter chief and adviser meet with the district committee and/or district executive to review/update the plan?
D31: On what date?
C33: What benefits did the chapter realize from maintaining a written annual plan?
B34: Analyze the Past
C40: How can the chapter achieve this goal more efficiently next year?
B41: Plan for Next Year

Sheet 11 Lodge Support
A1: 11 | B1: Lodge designated support: Complete lodge executive committee designated programs or projects.
C4: Complete one program or project | F4: Bronze | G4: 75
C6: Complete two programs or projects | F6: Silver | G6: 100
C8: Complete three programs or projects | F8: Gold | G8: 200
B10: Lodge executive committee and/or lodge leadership designated programs or projects are to be developed in conjunction with the lodge leadership and in support of the lodge’s work. Here are some examples of lodge executive committee designated programs or projects:
B13: • | C13: The chapter holds a training session for OA Troop/Team Representative positions and communicates with those representatives regularly.
B15: • | C15: The chapter leadership attends at least 50% of lodge executive committee meetings and presents reports of chapter activities.
B17: • | C17: The chapter will provide at least two members to serve on lodge committees.
B18: • | C18: The chapter holds at least three meetings a year and focuses on FUN and FELLOWSHIP for at least half of each chapter meeting.
B21: List the programs or projects the lodge executive committee designated to the chapter
B22: 1.
C24: When did the LEC designate this program or project?
C26: When did the chapter complete the program or project?
B29: 2.
C31: When did the LEC designate this program or project?
C33: When did the chapter complete the program or project?
B36: 3.
C38: When did the LEC designate this program or project?
C40: When did the chapter complete the program or project?
C42: What benefit did these projects have? What should the chapter focus on next year?
B44: Plan for Next Year

Sheet 12 Service Projects
A1: 12 | B1: District/Council service projects: Complete district executive/Scout Executive approved service project(s) on Council property or in the community.
C4: Complete project(s) equal to at least 3.5 hours of service per chapter member | F4: Bronze | G4: 75
C7: Complete project(s) equal to at least 6 hours of service per chapter member | F7: Silver | G7: 100
C10: Complete project(s) equal to at least 15 hours of service per chapter member | F10: Gold | G10: 200
B13: At least one district/council service project and one community service project must be conducted and a written report of each project included in the chapter’s annual report.
E15: Date Completed | F15: # of Participants | G15: Man-Hours | H15: Report Attached?
A16: 1. | B16: List the required district/council service project.
A19: 2. | B19: List the required community service project.
A22: 3. | B22: List additional project.
A25: 4. | B25: List additional project.
A28: 5. | B28: List additional project.
A31: 6. | B31: List additional project.
G33: =SUM(G16:G32) -> 0
B35: ="Number of registered chapter members at end of "&HIDE!B33&"." -> Number of registered chapter members at end of 2014. | F35: =Worksheet!B22 -> 0
B37: Number of service hours performed per chapter member. | F37: =IF(F35>0, G33/F35,"")
F38: =IF(F37="", "-", IF(AND(G16>0, G19>0, F37>=15), "GOLD", IF(AND(G16>0, G19>0, F37>=6), "SILVER", IF(AND(G16>0, G19>0, F37>=3.5), "BRONZE", "None")))) -> -
C40: Reflect on how meaningful these projects were. What should the chapter do differently next year? Could the chapter have an even larger influence?
B41: Plan for Next Year

Sheet 13 Camping Support
A1: 13 | B1: District/council camping support: Conduct camp promotion contacts to district troops and teams.
C3: Complete contacts to at least 75% of units or 3% increase | F3: Bronze | G3: 75
C5: Complete contacts to at least 80% of units or 3% increase over 75% | F5: Silver | G5: 100
C8: Complete contacts to at least 85% of units or 3% increase over 80% | F8: Gold | G8: 200
B11: What constitutes an acceptable contact under this category is determined by the Scout Executive or the council’s camping committee if delegated by the Scout Executive.
B14: Set the Goal | C14: Who determined "acceptable contact"? The Scout Executive or the council's camping committee?
C17: When was the determination made?
C19: How does the Scout Executive or council's camping committee define "acceptable contact" for purposes of this item?
B27: Identify Benchmark | C27: ="Number of units in the district in "&HIDE!B34&"." -> Number of units in the district in 2013. | F27: =Worksheet!B43 -> 0
C29: ="Number of units contacted in district in "&HIDE!B34&"." -> Number of units contacted in district in 2013.
C31: ="Percentage of units contacted in "&HIDE!B34&"." -> Percentage of units contacted in 2013. | F31: =IF(F27<>0, F29/F27, "-") -> -
B33: Evaluate Success | C33: ="Number of units in the district in "&HIDE!B33&"." -> Number of units in the district in 2014. | F33: =Worksheet!B45 -> 0
C35: ="Number of units contacted in district in "&HIDE!B33&"." -> Number of units contacted in district in 2014.
C37: ="Percentage of units contacted in "&HIDE!B33&"." -> Percentage of units contacted in 2014. | F37: =IF(F33<>0, F35/F33, "-") -> -
F38: =IF(OR(F37="-",F31="-"),"-",IF(OR(F37*100>=85,AND((F37*100)-(F31*100)>=3,F31*100>=80)),"GOLD",IF(OR(F37*100>=80,AND((F37*100)-(F31*100)>=3,F31*100>=75)),"SILVER",IF(OR(F37*100>=75,(F37*100)-(F31*100)>=3),"BRONZE","NONE")))) -> -
C40: How can the chapter better serve the district in promoting camping next year?
B41: Plan for Next Year

Sheet 14 Program Support
A1: 14 | B1: District/council program support: Provide OA member staff support for district and/or council program events.
C4: Support two district and/or council events | F4: Bronze | G4: 75
C6: Support three district and/or council events | F6: Silver | G6: 100
C8: Support five district and/or council events | F8: Gold | G8: 200
B10: List the district and/or council program events for which the chapter provided support.
B13: 1. | F13: Date | G13: =IF(COUNTA(C13,F14)=2, "X", "-") -> -
B18: 2. | F18: Date | G18: =IF(COUNTA(C18,F19)=2, "X", "-") -> -
B23: 3. | F23: Date | G23: =IF(COUNTA(C23,F24)=2, "X", "-") -> -
B28: 4. | F28: Date | G28: =IF(COUNTA(C28,F29)=2, "X", "-") -> -
B33: 5. | F33: Date | G33: =IF(COUNTA(C33,F34)=2, "X", "-") -> -
F38: =IF(COUNTIF(F13:G33,"X")>=5,"GOLD",IF(COUNTIF(F13:G33,"X")>=3,"SILVER",IF(COUNTIF(F13:G33,"X")>=2,"BRONZE","-"))) -> -
C40: What specific benefits did the chapter provide to the district?
B41: Analyze Impact
C46: How can the chapter provide an even broader impact in the district or chapter next year?
B48: Plan for Next Year

Sheet 15 BSA Designated Support
A1: 15 | B1: District/council designated support: Complete district executive and/or Scout Executive designated program support projects.
C4: Complete one project | F4: Bronze | G4: 75
C6: Complete two projects | F6: Silver | G6: 100
C8: Complete three projects | F8: Gold | G8: 200
B10: District executive/Scout Executive designated program support projects are to be developed during a meeting with the lodge and/or chapter Key 3 with consideration for both the current local council and national Order of the Arrow strategic plans. Here are some examples of district executive/Scout Executive designated programs or projects:
B13: • | C13: The chapter is to hold its chapter meetings on the same night and at the same location as the district roundtable for Scoutmasters.
B15: • | C15: The chapter Key 3 is to meet at least quarterly to discuss progress in the chapter.
B17: • | C17: The chapter holds a chapter meeting or gathering at a district event such as a camporee.
B19: • | C19: The chapter is to provide manpower, resources, and/or program assistance in support of the district Cub Scout outdoor program or conducts at least two Cub Scout/Webelos Arrow of Light crossover ceremonies for Cub Scout packs requesting them.
B23: • | C23: The chapter is to conduct a call out ceremony during the campfire at the district camporee.
B26: List the programs or projects the district/Scout Executive designated to the chapter
B27: 1.
C29: When did the executive designate this program or project?
C31: When did the chapter complete the program or project?
B33: 2.
C35: When did the executive designate this program or project?
C37: When did the chapter complete the program or project?
B39: 3.
C41: When did the executive designate this program or project?
C43: When did the chapter complete the program or project?
C45: What benefit did these projects have? What should the chapter focus on next year?
B47: Plan for Next Year

Sheet 16 Chapter Leadership
A1: 16 | B1: Chapter leadership: Participate in and/or conduct at least one LLD during the year with qualified instructors using current material.
C3: Achieve at least 66% of chapter leadership trained or 3% increase | F3: Bronze | G3: 25
C6: Achieve at least 83% of chapter leadership trained or 3% over 66% | F6: Silver | G6: 50
C9: Achieve at least 100% of chapter leadership trained or 3% over 83% | F9: Gold | G9: 100
B12: LLD courses must be conducted at either the lodge or chapter level, with qualified instructors and using current LLD materials (see www.oa-bsa.org), to train chapter officers, committee chairmen and their advisers. Eligible participants include elected and appointed youth members of the LEC and their advisers.
B17: Identify Benchmark | C17: ="Number of eligible participants in "&HIDE!B34 -> Number of eligible participants in 2013
C19: ="Number of eligible participants that participated in LLD course in "&HIDE!B34 -> Number of eligible participants that participated in LLD course in 2013
C21: ="Percentage of eligible participants that participated in LLD course in "&HIDE!B34 -> Percentage of eligible participants that participated in LLD course in 2013 | F21: =IF(F17<>0, F19/F17, "-") -> -
C23: Number and dates of LLDs conducted during this year with qualified instructors and current material
C25: 1.
C26: 2.
C27: 3.
C28: 4.
B30: Evaluate Success | C30: ="Number of eligible participants in "&HIDE!B33 -> Number of eligible participants in 2014
C32: ="Number of eligible participants that participated in LLD course in "&HIDE!B33 -> Number of eligible participants that participated in LLD course in 2014
C34: ="Percentage of eligible participants that participated in LLD course in "&HIDE!B33 -> Percentage of eligible participants that participated in LLD course in 2014 | F34: =IF(F30<>0, F32/F30, "-") -> -
F35: =IF(OR(F34="-",F21="-"),"-",IF(OR(F34*100>=100,AND((F34*100)-(F21*100)>=3,F21*100>=83)),"GOLD",IF(OR(F34*100>=83,AND((F34*100)-(F21*100)>=3,F21*100>=66)),"SILVER",IF(OR(F34*100>=66,(F34*100)-(F21*100)>=3),"BRONZE","NONE")))) -> -
C37: What is the number one area of training most needed in the chapter?
B38: Plan for Next Year

Sheet 17 Annual Report
A1: 17 | B1: Annual report: Submit a written annual report of chapter accomplishments to the lodge executive committee and/or district committee.
C4: Written report submitted to the lodge executive committee and district committee and/or executive | F4: Bronze | G4: 25
C8: Written and verbal report given to Scoutmasters at roundtable by the chapter chief | F8: Silver | G8: 50
C11: Written and verbal report given to the lodge executive committee and district committee and/or executive by the chapter chief | F11: Gold | G11: 100
B15: Chapters should present and submit a written report of their accomplishments to the lodge executive committee and/or district committee. This Southern Region Annual Report Template should provide the chapter with a method of organizing concepts for the annual report. Use this template to help form the annual report, identify the chapter's strengths and weaknesses, and plan for the next year.
C21: What is the chapter's goal regarding when the written report is completed? | H21: Date Goal Made
B22: Set the Goal
C26: List the steps, in back-dater format, to submitting the written report by the goal stated above.
B28: Plan Acheivement
F34: By Chapter Chief?
E35: Y/N | F35: Y/N | H35: Date
B36: Written report submitted to LEC
B38: Verbal report given to LEC
B40: Written report submitted to district committee and/or district executive
B43: Verbal report given to district committee and/or district executive
B46: Written report submitted to Scoutmasters at roundtable
B49: Verbal report given to Scoutmasters at roundtable
F51: =IF(AND(F36="Yes",F38="Yes",F40="Yes",F43="Yes",F46="Yes",F49="Yes"),"GOLD",IF(AND(F46="Yes",F49="Yes",E36="Yes",E40="Yes"),"SILVER",IF(AND(E36="Yes",E40="Yes"),"BRONZE","None"))) -> None

Sheet PETITION
A1: Scouting's Journey to Excellence
A2: =HIDE!B33&" OA Chapter Performance Recognition Program" -> 2014 OA Chapter Performance Recognition Program
A4: Chapter | C4: =IF(ISBLANK(Worksheet!B3), "", Worksheet!B3) | D4: Lodge | E4: =IF(ISBLANK(Worksheet!B5), "", Worksheet!B5) | F4: Council | G4: =IF(ISBLANK(Worksheet!B7), "", Worksheet!B7)
A6: Chapter Chief | C6: =IF(ISBLANK(Worksheet!B9), "", Worksheet!B9) | D6: Chapter Adviser | E6: =IF(ISBLANK(Worksheet!B11), "", Worksheet!B11) | F6: Staff Adviser | G6: =IF(ISBLANK(Worksheet!B13), "", Worksheet!B13)
A8: Date | C8: =IF(ISBLANK(Worksheet!B15), "", Worksheet!B15)
D9: No
A10: To qualify for recognition, chapters must complete this paperwork on time, and be in compliance with the current editions of the OA Handbook, Guide for Officers and Advisers, Chapter Operations Guide, Guide to Inductions, and ceremony books. In addition, the chapter must operate according to lodge and/or council established procedures for OA chapters. The assessment of the OA Chapter Performance Recognition Program is managed by the lodge that authorizes and oversees the chapter’s work. It also needs to be coordinated with the chapter staff adviser and district committee and/or district executive. Follow your lodge’s submission deadlines and procedures.
A11: Item # | B11: Objective | D11: Bronze level | E11: Silver level | F11: Gold level | G11: Bronze points | H11: Silver points | I11: Gold points
B12: Finance
A13: 1 | B13: Fiscal Management: Manage chapter revenue and expense according to council/lodge established procedures and leadership. | D13: Establish financial target(s) for the chapter | E13: Meet the chapter's financial target(s) | F13: Exceed the chapter's financial target(s) | G13: =IF(AND(D14="Complete.", E14="Incomplete.", F14="Incomplete."), 75, 0) -> 0 | H13: =IF(AND(D14="Complete.", E14="Complete.", F14="Incomplete."), 100, 0) -> 0 | I13: =IF(AND(D14="Complete.", E14="Complete.", F14="Complete."), 200, 0) -> 0
D14: =IF(COUNTA('1 Fiscal'!H17)=1, "Complete.", "Incomplete.") -> Incomplete. | E14: =IF(COUNTA('1 Fiscal'!H31:H34)=1, "Complete.", "Incomplete.") -> Incomplete. | F14: =IF(COUNTA('1 Fiscal'!H38:H41)=1, "Complete.", "Incomplete.") -> Incomplete.
B15: Membership
A16: 2 | B16: Membership impact: Experience positive growth in membership in the chapter over the previous year. [REQUIRED] | D16: Grow membership by at least 1 | E16: Grow membership by at least 1% | F16: Grow membership by at least 13% | G16: =IF('2 Membership Impact'!E32="BRONZE", 75, 0) -> 0 | H16: =IF('2 Membership Impact'!E32="Silver", 100, 0) -> 0 | I16: =IF('2 Membership Impact'!E32="Gold", 200, 0) -> 0
A17: 3 | B17: Ordeal completion: Complete induction of elected Ordeal candidates. | D17: Complete induction of at least 64% of Ordeal candidates or 5% increase over prior year | E17: Complete induction of at least 77% of Ordeal candidates or 5% increase over 64% | F17: Complete induction of at least 98% of Ordeal candidates or 5% increase over 77% | G17: =IF('3 Ordeal Completion'!E36="BRONZE", 25, 0) -> 0 | H17: =IF('3 Ordeal Completion'!E36="Silver", 50, 0) -> 0 | I17: =IF('3 Ordeal Completion'!E36="Gold", 100, 0) -> 0
A18: 4 | B18: Brotherhood completion: Convert eligible Ordeal members to Brotherhood. [REQUIRED] | D18: Convert at least 25% or 5% increase over prior year | E18: Convert at least 32% or 3% increase over 25% | F18: Convert at least 47% or 3% increase over 32% | G18: =IF('4 Brotherhood Conversion'!E38="BRONZE", 75, 0) -> 0 | H18: =IF('4 Brotherhood Conversion'!E38="Silver", 100, 0) -> 0 | I18: =IF('4 Brotherhood Conversion'!E38="Gold", 200, 0) -> 0
A19: 5 | B19: Membership retention: Improve retention rate of chapter members. | D19: Achieve 69% or a 4% increase over prior year | E19: Achieve 77% or a 4% increase over 69% | F19: Achieve 88% or a 5% increase over 77% | G19: =IF('5 Membership Retention'!F36="BRONZE", 75, 0) -> 0 | H19: =IF('5 Membership Retention'!F36="Silver", 100, 0) -> 0 | I19: =IF('5 Membership Retention'!F36="Gold", 200, 0) -> 0
B20: Program
A21: 6 | B21: Unit elections: Conduct unit elections in district troops and teams desiring them. | D21: Complete elections for at least 90% of requesting units | E21: Complete elections for at least 95% of requesting units | F21: Complete elections for 100% of requesting units | G21: =IF('6 Unit Elections'!E36="BRONZE", 25, 0) -> 0 | H21: =IF('6 Unit Elections'!E36="Silver", 50, 0) -> 0 | I21: =IF('6 Unit Elections'!E36="Gold", 100, 0) -> 0
A22: 7 | B22: Lodge, section, and national OA event attendance: Attend lodge, section, and national OA events. | D22: Set and achieve a chapter attendance goal for OA events | E22: Exceed the chapter attendance goal by 10% | F22: Exceed the chapter attendance goal by 20% | G22: =IF('7 Attendance'!I34="BRONZE", 25, 0) -> 0 | H22: =IF('7 Attendance'!I34="SILVER", 50, 0) -> 0 | I22: =IF('7 Attendance'!I34="GOLD", 100, 0) -> 0
A23: 8 | B23: Chapter communications: Maintain active communications within the chapter. | D23: Have and follow a written chapter communication plan | E23: Communicate regularly with unit OA troop representatives | F23: Contribute to the lodge and/or council newsletter or website | G23: =IF(AND(D24="Yes.", E24="-"), 25, 0) -> 0 | H23: =IF(AND(D24="Yes.", E24="Yes.", F24="-"), 50, 0) -> 0 | I23: =IF(AND(D24="Yes.", E24="Yes.", F24="Yes."), 100, 0) -> 0
D24: =IF(AND('8 Communications'!H27="Yes", '8 Communications'!H29="Yes"), "Yes.", "-") -> - | E24: =IF('8 Communications'!H31="Yes", "Yes.", "-") -> - | F24: =IF('8 Communications'!H33="Yes", "Yes.", "-") -> -
A25: 9 | B25: Chapter meetings and event participation: Improve chapter membership participation at chapter meetings and events. | D25: Set and achieve a chapter attendance goal for chapter meetings or events | E25: Exceed the chapter attendance goal by 10%. | F25: Exceed the chapter attendance goal by 20% | G25: =IF('9 Participation'!G32="BRONZE", 25, 0) -> 0 | H25: =IF('9 Participation'!G32="SILVER", 50, 0) -> 0 | I25: =IF('9 Participation'!G32="GOLD", 100, 0) -> 0
A26: 10 | B26: Chapter planning: Maintain an active planning process that guides chapter program and supports the lodge’s plans. | D26: Have a written annual plan approved by the lodge executive committee; submit approved plan to district committee and/or executive | E26: Conduct an annual review and update of your plan, in conjunction with your lodge’s plan | F26: Meet with the district committee and/or executive to review/ update your plan | G26: =IF(AND(D27="Yes.", E27="-"), 25, 0) -> 0 | H26: =IF(AND(D27="Yes.", E27="Yes.", F27="-"), 50, 0) -> 0 | I26: =IF(AND(D27="Yes.", E27="Yes.", F27="Yes."), 100, 0) -> 0
D27: =IF(AND('10 Planning'!H14="Yes", '10 Planning'!H16="Yes", '10 Planning'!H20="Yes"), "Yes.", "-") -> - | E27: =IF('10 Planning'!H25="Yes", "Yes.", "-") -> - | F27: =IF('10 Planning'!H29="Yes", "Yes.", "-") -> -
A28: 11 | B28: Lodge designated support: Complete lodge executive committee designated programs or projects. | D28: Complete one program or project | E28: Complete two programs or projects | F28: Complete three programs or projects | G28: =IF(COUNTA('11 Lodge Support'!F26,'11 Lodge Support'!F33,'11 Lodge Support'!F40)=1,75,0) -> 0 | H28: =IF(COUNTA('11 Lodge Support'!F26,'11 Lodge Support'!F33,'11 Lodge Support'!F40)=2,100,0) -> 0 | I28: =IF(COUNTA('11 Lodge Support'!F26,'11 Lodge Support'!F33,'11 Lodge Support'!F40)=3,200,0) -> 0
B29: District and Council service
A30: 12 | B30: District/council service projects: Complete district executive/Scout Executive approved service project(s) on council property or in the community. | D30: Complete project(s) equal to at least 3.5 hours of service per chapter member | E30: Complete project(s) equal to at least 6 hours of service per chapter member | F30: Complete project(s) equal to at least 15 hours of service per chapter member | G30: =IF('12 Service Projects'!F38="BRONZE", 75, 0) -> 0 | H30: =IF('12 Service Projects'!F38="Silver", 100, 0) -> 0 | I30: =IF('12 Service Projects'!F38="Gold", 200, 0) -> 0
A31: 13 | B31: District/council camping support: Conduct camp promotion contacts to district troops and teams. | D31: Complete contacts to at least 75% of units or 3% increase | E31: Complete contacts to at least 80% of units or 3% increase over 75% | F31: Complete contacts to at least 85% of units or 3% increase over 80% | G31: =IF('13 Camping Support'!F38="BRONZE", 75, 0) -> 0 | H31: =IF('13 Camping Support'!F38="Silver", 100, 0) -> 0 | I31: =IF('13 Camping Support'!F38="Gold", 200, 0) -> 0
A32: 14 | B32: District/council program support: Provide OA member staff support for district and/or council program events. | D32: Support two district and/or council events | E32: Support three district and/or council events | F32: Support five district and/or council events | G32: =IF('14 Program Support'!F38="BRONZE", 75, 0) -> 0 | H32: =IF('14 Program Support'!F38="Silver", 100, 0) -> 0 | I32: =IF('14 Program Support'!F38="Gold", 200, 0) -> 0
A33: 15 | B33: District/council designated support: Complete district executive and/or Scout Executive designated program support projects. | D33: Complete one project | E33: Complete two projects | F33: Complete three projects | G33: =IF(COUNTA('15 BSA Designated Support'!F31,'15 BSA Designated Support'!F37,'15 BSA Designated Support'!F43)=1, 75, 0) -> 0 | H33: =IF(COUNTA('15 BSA Designated Support'!F31,'15 BSA Designated Support'!F37,'15 BSA Designated Support'!F43)=2, 100, 0) -> 0 | I33: =IF(COUNTA('15 BSA Designated Support'!F31,'15 BSA Designated Support'!F37,'15 BSA Designated Support'!F43)=3, 200, 0) -> 0
B34: Leadership and governance
A35: 16 | B35: Chapter leadership: Participate in and/or conduct at least one LLD during the year with qualified instructors using current material. | D35: Achieve at least 66% of chapter leadership trained or 3% increase | E35: Achieve at least 83% of chapter leadership trained or 3% over 66% | F35: Achieve at least 100% of chapter leadership trained or 3% over 83% | G35: =IF('16 Chapter Leadership'!F35="BRONZE", 25, 0) -> 0 | H35: =IF('16 Chapter Leadership'!F35="Silver", 50, 0) -> 0 | I35: =IF('16 Chapter Leadership'!F35="Gold", 100, 0) -> 0
A36: 17 | B36: Annual report: Submit a written annual report of chapter accomplishments to the lodge executive committee and/or district committee. | D36: Written report submitted to the lodge executive committee and district committee and/or executive | E36: Written and verbal report given to Scoutmasters at roundtable by the chapter chief | F36: Written and verbal report given to the lodge executive committee and district committee and/or executive by the chapter chief | G36: =IF('17 Annual Report'!F51="BRONZE", 25, 0) -> 0 | H36: =IF('17 Annual Report'!F51="Silver", 50, 0) -> 0 | I36: =IF('17 Annual Report'!F51="Gold", 100, 0) -> 0
F37: Total achieved | G37: =SUM(G13:G36) -> 0 | H37: =SUM(H13:H36) -> 0 | I37: =SUM(I13:I36) -> 0
B38: Award level: | D38: =IF(AND(I38>=1400,SUM(G16:I16)>0,SUM(G18:I18)>0,COUNTIF(G13:I36,0)<=36),"Gold",IF(AND(I38>=1100,SUM(G16:I16)>0,SUM(G18:I18)>0,COUNTIF(G13:I36,0)<=39),"Silver",IF(AND(I38>=800,SUM(G16:I16)>0,SUM(G18:I18)>0,COUNTIF(G13:I36,0)<=41),"Bronze","None"))) -> None | H38: Grand total | I38: =SUM(G37:I37) -> 0
A40: Below is specific information to help you understand the criteria and exactly what data will be used to determine the three levels of performance. In planning your strategy, use actual numbers from the previous year to guide your performance improvement goal-planning.
A42: Scoring the chapter's performance
A43: ● | B43: To qualify for silver or gold points within an individual criterion, the chapter must have completed the lower level criterion (e.g., to qualify for silver level in item number 1, the chapter must have completed the bronze level in that item)
A44: ● | B44: To determine the chapter’s overall performance level, the chapter will use the above matrix to determine the points earned in each of the 17 individual criteria, circle the criteria completed, add the scores in each column to determine the points earned at each award level, then add the three column scores to obtain the grand total points earned.
A45: ● | B45: Overall award levels are determined as follows using the grand total points earned:
...

Sheet HIDE
A1: Yes
A2: No
C20: List the lodge, section and national OA events at which the chapter will be represented. | D20: Previous Year's Attendance | E20: This Year's Goal | F20: This Year's Actual Attendance
A21: Lodge Events | B21: 1. | C21: ='7 Attendance'!C21 -> 0 | D21: ='7 Attendance'!D21 -> 0 | E21: ='7 Attendance'!E21 -> 0 | F21: ='7 Attendance'!F21 -> 0 | G21: =IF(AND(C21<>"",E21>0,F21>0,F21=E21),0,IF(AND(C21<>"",E21>0,F21>0,F21<E21),"Goal Not Met.",IF(AND(C21<>"",E21>0,F21>0,F21>E21),((((F21-E21)/E21))*100),IF(AND(C21<>"",E21>0),"NEEDS RESULT",""))))
B22: 2. | C22: ='7 Attendance'!C22 -> 0 | D22: ='7 Attendance'!D22 -> 0 | E22: ='7 Attendance'!E22 -> 0 | F22: ='7 Attendance'!F22 -> 0 | G22: =IF(AND(C22<>"",E22>0,F22>0,F22=E22),0,IF(AND(C22<>"",E22>0,F22>0,F22<E22),"Goal Not Met.",IF(AND(C22<>"",E22>0,F22>0,F22>E22),((((F22-E22)/E22))*100),IF(AND(C22<>"",E22>0),"NEEDS RESULT",""))))
B23: 3. | C23: ='7 Attendance'!C23 -> 0 | D23: ='7 Attendance'!D23 -> 0 | E23: ='7 Attendance'!E23 -> 0 | F23: ='7 Attendance'!F23 -> 0 | G23: =IF(AND(C23<>"",E23>0,F23>0,F23=E23),0,IF(AND(C23<>"",E23>0,F23>0,F23<E23),"Goal Not Met.",IF(AND(C23<>"",E23>0,F23>0,F23>E23),((((F23-E23)/E23))*100),IF(AND(C23<>"",E23>0),"NEEDS RESULT",""))))
B24: 4. | C24: ='7 Attendance'!C24 -> 0 | D24: ='7 Attendance'!D24 -> 0 | E24: ='7 Attendance'!E24 -> 0 | F24: ='7 Attendance'!F24 -> 0 | G24: =IF(AND(C24<>"",E24>0,F24>0,F24=E24),0,IF(AND(C24<>"",E24>0,F24>0,F24<E24),"Goal Not Met.",IF(AND(C24<>"",E24>0,F24>0,F24>E24),((((F24-E24)/E24))*100),IF(AND(C24<>"",E24>0),"NEEDS RESULT",""))))
B25: 5. | C25: ='7 Attendance'!C25 -> 0 | D25: ='7 Attendance'!D25 -> 0 | E25: ='7 Attendance'!E25 -> 0 | F25: ='7 Attendance'!F25 -> 0 | G25: =IF(AND(C25<>"",E25>0,F25>0,F25=E25),0,IF(AND(C25<>"",E25>0,F25>0,F25<E25),"Goal Not Met.",IF(AND(C25<>"",E25>0,F25>0,F25>E25),((((F25-E25)/E25))*100),IF(AND(C25<>"",E25>0),"NEEDS RESULT",""))))
G26: =IF(AND(C26<>"",E26>0,F26>0,F26=E26),0,IF(AND(C26<>"",E26>0,F26>0,F26<E26),"Goal Not Met.",IF(AND(C26<>"",E26>0,F26>0,F26>E26),((((F26-E26)/E26))*100),IF(AND(C26<>"",E26>0),"NEEDS RESULT",""))))
A27: Section Events | B27: 1. | C27: ='7 Attendance'!C27 -> 0 | D27: ='7 Attendance'!D27 -> 0 | E27: ='7 Attendance'!E27 -> 0 | F27: ='7 Attendance'!F27 -> 0 | G27: =IF(AND(C27<>"",E27>0,F27>0,F27=E27),0,IF(AND(C27<>"",E27>0,F27>0,F27<E27),"Goal Not Met.",IF(AND(C27<>"",E27>0,F27>0,F27>E27),((((F27-E27)/E27))*100),IF(AND(C27<>"",E27>0),"NEEDS RESULT",""))))
B28: 2. | C28: ='7 Attendance'!C28 -> 0 | D28: ='7 Attendance'!D28 -> 0 | E28: ='7 Attendance'!E28 -> 0 | F28: ='7 Attendance'!F28 -> 0 | G28: =IF(AND(C28<>"",E28>0,F28>0,F28=E28),0,IF(AND(C28<>"",E28>0,F28>0,F28<E28),"Goal Not Met.",IF(AND(C28<>"",E28>0,F28>0,F28>E28),((((F28-E28)/E28))*100),IF(AND(C28<>"",E28>0),"NEEDS RESULT",""))))
G29: =IF(AND(C29<>"",E29>0,F29>0,F29=E29),0,IF(AND(C29<>"",E29>0,F29>0,F29<E29),"Goal Not Met.",IF(AND(C29<>"",E29>0,F29>0,F29>E29),((((F29-E29)/E29))*100),IF(AND(C29<>"",E29>0),"NEEDS RESULT",""))))
A30: National Events | B30: 1. | C30: ='7 Attendance'!C30 -> 0 | D30: ='7 Attendance'!D30 -> 0 | E30: ='7 Attendance'!E30 -> 0 | F30: ='7 Attendance'!F30 -> 0 | G30: =IF(AND(C30<>"",E30>0,F30>0,F30=E30),0,IF(AND(C30<>"",E30>0,F30>0,F30<E30),"Goal Not Met.",IF(AND(C30<>"",E30>0,F30>0,F30>E30),((((F30-E30)/E30))*100),IF(AND(C30<>"",E30>0),"NEEDS RESULT",""))))
B31: 2. | C31: ='7 Attendance'!C31 -> 0 | D31: ='7 Attendance'!D31 -> 0 | E31: ='7 Attendance'!E31 -> 0 | F31: ='7 Attendance'!F31 -> 0 | G31: =IF(AND(C31<>"",E31>0,F31>0,F31=E31),0,IF(AND(C31<>"",E31>0,F31>0,F31<E31),"Goal Not Met.",IF(AND(C31<>"",E31>0,F31>0,F31>E31),((((F31-E31)/E31))*100),IF(AND(C31<>"",E31>0),"NEEDS RESULT",""))))
A33: This year: | B33: 2014
A34: Last year: | B34: 2013
A35: Year before last: | B35: 2012
