Workbook
Name _Rev07: Master!$A$1:$EJ$666

Sheet Legend
A2: Legend
D3: Local
D5: State
D7: Federal
D9: Other
D11: Indeterminate
D13: Pre K Enrollments
D15: Not Used
A18: Source | B18: New Jersey Department of Education
A20: All files are "read only" and based on data collections from the New Jersey Department of Education.
A21: The conclusions reached in this document are those of the author(s) and do not necessarily represent those
A22: of Ball State University.

Sheet Figures 1,2,4
A1: Figure 1 | M1: Figure 2
A2: New Jersey (2006-07) | B2: Statewide | D2: Statewide Weighted for Charter Enrollment | F2: Jersey City | H2: Newark | J2: Trenton | N2: District | O2: Charter | P2: Difference | R2: Trenton charter numbers reflect a significant drop from the FY03 analysis.
A3: Per-Pupil Revenue | M3: State | N3: 17110.216 | O3: 12441.618 | P3: 4668.5987 | R3: Compared the files. It appears that Granville Charter School did not operate in FY07 -
A4: District | B4: ='[1]State Dist'!$CL$618 -> 17110.216 | D4: 19837 | F4: ='[1]State Dist'!$CL$625 -> 21951.563 | H4: ='[1]State Dist'!$CL$632 -> 23594.054 | J4: ='[1]State Dist'!$CL$639 -> 23655.25 | M4: Statewide Weighted | N4: 19837 | O4: 12442 | P4: 7395
A5: Charter | B5: ='[1]State Chart'!$CL$58 -> 12441.618 | D5: 12442 | F5: ='[1]State Chart'!$CL$69 -> 11886.06 | H5: ='[1]State Chart'!$CL$83 -> 11677.314 | J5: ='[1]State Chart'!$CL$90 -> 12648.808 | M5: Jersey City | N5: 21951.563 | O5: 11886.06 | P5: 10065.503 | R5: - it was by far the largest charter school in the city with 1188 pupils in FY03.
A6: Difference | B6: =B4-B5 -> 4668.5987 | D6: 7395 | F6: =F4-F5 -> 10065.503 | H6: =H4-H5 -> 11916.741 | J6: =J4-J5 -> 11006.442 | M6: Newark | N6: 23594.054 | O6: 11677.314 | P6: 11916.741 | R6: The closing of that school would affect significantly the numbers presented in FY07.
B7: =B6/B4 -> 0.27285445 | D7: 0.373 | F7: =F6/F4 -> 0.45853241 | H7: =H6/H4 -> 0.50507388 | J7: =J6/J4 -> 0.46528536 | M7: Trenton | N7: 23655.25 | O7: 12648.808 | P7: 11006.442 | R7: Confirmed on SDE website that Granville is not operational in FY07
A8: Per-Pupil Revenue by Source | B8: District | C8: Charter | D8: District | E8: Charter | F8: District | G8: Charter | H8: District | I8: Charter | J8: District | K8: Charter | M8: Figure 2: Per Pupil Revenue for New Jersey District & Charter Schools, FY 2006-07
A9: Federal | B9: ='[1]State Dist'!$BF$618 -> 549.52683 | C9: ='[1]State Chart'!$BF$58 -> 1140.7799 | D9: 963 | E9: 1140.7799 | F9: ='[1]State Dist'!$BF$625 -> 1314.3847 | G9: ='[1]State Chart'!$BF$69 -> 1139.3091 | H9: ='[1]State Dist'!$BF$632 -> 1625.7832 | I9: ='[1]State Chart'!$BF$83 -> 1217.9403 | J9: ='[1]State Dist'!$BF$639 -> 1251.6225 | K9: ='[1]State Chart'!$BF$90 -> 1239.0861
A10: State | B10: ='[1]State Dist'!$AV$618 -> 6503.1246 | C10: ='[1]State Chart'!$AV$58 -> 8911.6816 | D10: 11898 | E10: 8911.6816 | F10: ='[1]State Dist'!$AV$625 -> 17347.826 | G10: ='[1]State Chart'!$AV$69 -> 8585.1296 | H10: ='[1]State Dist'!$AV$632 -> 17448.688 | I10: ='[1]State Chart'!$AV$83 -> 9114.2904 | J10: ='[1]State Dist'!$AV$639 -> 21332.867 | K10: ='[1]State Chart'!$AV$90 -> 9491.2024
A11: Local | B11: ='[1]State Dist'!$O$618 -> 9080.4845 | C11: ='[1]State Chart'!$N$58 -> 2314.9006 | D11: 5959 | E11: 2314.9006 | F11: ='[1]State Dist'!$O$625 -> 3152.3881 | G11: ='[1]State Chart'!$N$69 -> 2083.2195 | H11: ='[1]State Dist'!$O$632 -> 2254.5849 | I11: ='[1]State Chart'!$N$83 -> 1332.5719 | J11: ='[1]State Dist'!$O$639 -> 956.70679 | K11: ='[1]State Chart'!$N$90 -> 1918.5199
A12: Other | B12: ='[1]State Dist'!$CC$618 -> 541.00187 | C12: ='[1]State Chart'!$CC$58 -> 63.305208 | D12: 781 | E12: 63.305208 | F12: ='[1]State Dist'!$CC$625 -> 136.96403 | G12: ='[1]State Chart'!$CC$69 -> 78.401425 | H12: ='[1]State Dist'!$CC$632 -> 2252.0969 | I12: ='[1]State Chart'!$CC$83 -> 12.511356 | J12: ='[1]State Dist'!$CC$639 -> 114.05395 | K12: ='[1]State Chart'!$CC$90 -> 0
A13: Indeterminate | B13: ='[1]State Dist'!$CK$618 -> 436.07851 | C13: ='[1]State Chart'!$CK$58 -> 10.950263 | D13: 236 | E13: 10.950263 | F13: ='[1]State Dist'!$CK$625 -> 0 | G13: ='[1]State Chart'!$CK$69 -> 0 | H13: ='[1]State Dist'!$CK$632 -> 12.901808 | I13: ='[1]State Chart'!$CK$83 -> 0 | J13: ='[1]State Dist'!$CK$639 -> 0 | K13: ='[1]State Chart'!$CK$90 -> 0
A14: Total | B14: =SUM(B9:B13) -> 17110.216 | C14: =SUM(C9:C13) -> 12441.618 | D14: 19837 | E14: 12441.618 | F14: =SUM(F9:F13) -> 21951.563 | G14: =SUM(G9:G13) -> 11886.06 | H14: =SUM(H9:H13) -> 23594.054 | I14: =SUM(I9:I13) -> 11677.314 | J14: =SUM(J9:J13) -> 23655.25 | K14: =SUM(K9:K13) -> 12648.808
A15: Enrollment
A16: District | B16: ='[1]State Dist'!$F$617 -> 1331638 | D16: n/a | F16: ='[1]State Dist'!$F$622 -> 28910 | H16: ='[1]State Dist'!$F$629 -> 41266 | J16: ='[1]State Dist'!$F$636 -> 12047.5
B17: =B16/(B16+B18) -> 0.98831893 | D17: n/a | F17: =F16/(F16+F18) -> 0.90749286 | H17: =H16/(H16+H18) -> 0.92271641 | J17: =J16/(J16+J18) -> 0.89439495
A18: Charter | B18: ='[1]State Chart'!$F$57 -> 15738.8 | D18: n/a | F18: ='[1]State Chart'!$F$68 -> 2947 | H18: ='[1]State Chart'!$F$82 -> 3456.3 | J18: ='[1]State Chart'!$F$89 -> 1422.5
B19: =B18/(B16+B18) -> 0.011681068 | D19: n/a | F19: =F18/(F16+F18) -> 0.092507141 | H19: =H18/(H16+H18) -> 0.077283592 | J19: =J18/(J16+J18) -> 0.10560505
A20: Number of Charters | B20: 53 | D20: n/a | F20: 8 | H20: 11 | J20: 4
A21: Total Revenue
A22: District | B22: ='[1]State Dist'!$CL$617 -> 22784614225 | D22: n/a | F22: ='[1]State Dist'!$CL$624 -> 634619678 | H22: ='[1]State Dist'!$CL$631 -> 973632249 | J22: ='[1]State Dist'!$CL$638 -> 284986624
B23: =B22/B26 -> 0.99147901 | D23: n/a | F23: =F22/F26 -> 0.94769159 | H23: =H22/H26 -> 0.96019665 | J23: =J22/J26 -> 0.94061339
A24: Charter | B24: ='[1]State Chart'!$CL$57 -> 1.9581613e+08 | D24: n/a | F24: ='[1]State Chart'!$CL$68 -> 35028218 | H24: ='[1]State Chart'!$CL$82 -> 40360300 | J24: ='[1]State Chart'!$CL$89 -> 17992930
B25: =B24/B26 -> 0.008520995 | D25: n/a | F25: =F24/F26 -> 0.052308412 | H25: =H24/H26 -> 0.03980335 | J25: =J24/J26 -> 0.059386615
A26: Total | B26: =B22+B24 -> 2.298043e+10 | D26: n/a | F26: =F22+F24 -> 669647896 | H26: =H22+H24 -> 1013992549 | J26: =J22+J24 -> 302979554
A27: Percentage of Revenue by Source | B27: District | C27: Charter | D27: District | E27: Charter | F27: District | G27: Charter | H27: District | I27: Charter | J27: District | K27: Charter | M27: Figure 4
A28: Federal | B28: =B9/$B$14 -> 0.032116884 | C28: =C9/$C$14 -> 0.091690643 | D28: 0.048545647 | E28: 0.091690643 | F28: =F9/$F$14 -> 0.059876588 | G28: =G9/$G$14 -> 0.09585255 | H28: =H9/$H$14 -> 0.068906479 | I28: =I9/$I$14 -> 0.1042997 | J28: =J9/$J$14 -> 0.052910982 | K28: =K9/$K$14 -> 0.097960699 | N28: Federal | O28: State | P28: Local | Q28: Other | R28: Indeterminate
A29: State | B29: =B10/$B$14 -> 0.38007261 | C29: =C10/$C$14 -> 0.71627998 | D29: 0.59978827 | E29: 0.71627998 | F29: =F10/$F$14 -> 0.79027749 | G29: =G10/$G$14 -> 0.72228559 | H29: =H10/$H$14 -> 0.73953748 | I29: =I10/$I$14 -> 0.78051258 | J29: =J10/$J$14 -> 0.90182377 | K29: =K10/$K$14 -> 0.75036336 | M29: Statewide District | N29: 549.52683 | O29: 6503.1246 | P29: 9080.4845 | Q29: 541.00187 | R29: 436.07851
A30: Local | B30: =B11/$B$14 -> 0.53070542 | C30: =C11/$C$14 -> 0.18606106 | D30: 0.30039825 | E30: 0.18606106 | F30: =F11/$F$14 -> 0.14360654 | G30: =G11/$G$14 -> 0.17526578 | H30: =H11/$H$14 -> 0.095557331 | I30: =I11/$I$14 -> 0.1141163 | J30: =J11/$J$14 -> 0.04044374 | K30: =K11/$K$14 -> 0.15167594 | M30: Statewide Charter | N30: 1140.7799 | O30: 8911.6816 | P30: 2314.9006 | Q30: 63.305208 | R30: 10.950263
A31: Other | B31: =B12/$B$14 -> 0.031618646 | C31: =C12/$C$14 -> 0.0050881814 | D31: 0.039370873 | E31: 0.0050881814 | F31: =F12/$F$14 -> 0.0062393748 | G31: =G12/$G$14 -> 0.0065960821 | H31: =H12/$H$14 -> 0.095451883 | I31: =I12/$I$14 -> 0.0010714241 | J31: =J12/$J$14 -> 0.004821507 | K31: =K12/$K$14 -> 0 | M31: Statewide Weighted | N31: 963 | O31: 11898 | P31: 5959 | Q31: 781 | R31: 236
A32: Change in district school funding if subjected to charter funding structure | M32: Jersey City District | N32: 1314.3847 | O32: 17347.826 | P32: 3152.3881 | Q32: 136.96403 | R32: 0
B33: ($5.9 billion) | F33: ($360 million) | H33: ($614 million) | J33: ($168 million) | M33: Jersey City Charter | N33: 1139.3091 | O33: 8585.1296 | P33: 2083.2195 | Q33: 78.401425 | R33: 0
M34: Newark District | N34: 1625.7832 | O34: 17448.688 | P34: 2254.5849 | Q34: 2252.0969 | R34: 12.901808
M35: Newark Charter | N35: 1217.9403 | O35: 9114.2904 | P35: 1332.5719 | Q35: 12.511356 | R35: 0
M36: Trenton District | N36: 1251.6225 | O36: 21332.867 | P36: 956.70679 | Q36: 114.05395 | R36: 0
M37: Trenton Charter | N37: 1239.0861 | O37: 9491.2024 | P37: 1918.5199 | Q37: 0 | R37: 0

Sheet Figure 3 Policies
A1: State Charter School Policies
A2: Figure 3
A3: State Policies | B3: Yes | C3: No | D3: Partial
A4: Charter schools received their funding directly from the state | D4: X₁
A5: Charter schools are eligible for local funding | B5: X
A6: Cap on funding a charter school can receive | C6: X
A7: District public school receive differential funding (e.g. more funding for 9-12 vs. K-8 schools) | B7: X
A8: Charter schools receive differential funding | B8: X
A9: State allows districts to withhold funding from charter schools for providing adminstrative services | B9: X₂
A10: State "holds harmless" district funding for charter enrollment | C10: X
A11: School is considered LEA if authorized by non-district organization | B11: X
A12: School is considered LEA if authorized by district | C12: X
A13: Cap on number of charter schools | C13: X
A14: Cap on number of charters schools authorized per year | C14: X
A15: Cap on number of students attending charter schools | C15: X
A16: Charter schools have an open enrollment policy | B16: X
A19: 1. State funding generally flows from the school district to the charter school for any revenue related to
A20: core funding. However, charters do receive some revenue directly from the state, such as the Abbott
A21: Kindergarten funding provided to charters within Abbott districts that run kindergarten programs.
A22: 2. Districts must provide charters 90 percent of the state mandated per pupil minimum.
A24: Note for chapter: the state passed funding reform legislation in 2008 to provide more equitable distribution of funds to charter schools - the School Funding Reform Act of 2008

Sheet Figure 5 Characteristics
A1: Figure 5: School Characteristics
C2: Statewide District | D2: Statewide Charter
A3: Percentage of students eligible for free or reduced price lunch | C3: 0.269 | D3: 0.653
A4: Percentage of schools eligible for Title 1 | C4: 0.507 | D4: 0.906
A5: Percent of students by school type
B6: Primary (K-5) | C6: 0.477 | D6: 0.634
B7: Middle (6-8) | C7: 0.204 | D7: 0.113
B8: High (9-12) | C8: 0.303 | D8: 0.112
B9: Other (K-12,K-8, etc.) | C9: 0.016 | D9: 0.141

Sheet Figure 6 Findings
A1: Figure 6: State Scorecard
B2: Findings | C2: New Jersey | E2: Use the following options only
A3: Federal Funding | B3: Charters have access to federal funds according to state statutes (Yes = black, No = white)* | C3: Y | E3: Y
B4: Percentage of federal revenue equals percentage of total enrollment for charter schools (<, >, or =) | C4: > | E4: P
A5: State Funding | B5: Charters have access to state funds according to state statutes (Yes = black, No = white) | C5: N | E5: N
B6: Percentage of state revenue equals percentage of total enrollment for charter schools (<, >, or =) | C6: >
A7: Local Funding | B7: Charters have access to local funds according to state statutes (Yes = black, No = white) | C7: Y
B8: Percentage of local revenue equals percentage of total enrollment for charter schools (<, >, or =) | C8: >
A9: Facilities Funding | B9: Charters have access to facilities funds according to state statutes (Yes = black, No = white) | C9: N
B10: Percentage of facilities revenue equals percentage of total enrollment for charter schools (<, >, or =) | C10: N
A11: Data Availability | B11: State provides detailed, public data on federal, state, local and other revenues for district schools (Yes = black, Partial = grey, No = white) | C11: Y
B12: State provides detailed, public data on federal, state, local and other revenues for charter schools (Yes = black, Partial = grey, No = white) | C12: Y
A13: Funding Formula | B13: Charters are treated as LEAs for funding purposes (Yes = black, Partial = grey, No = white) | C13: Y
B14: State funds student (black) or the LEA (grey) | C14: S | E14: S | F14: L | H14: Use these options for the query to the left only (B18)
B15: State funding formula is fair and equitable (Yes = black, No = white | C15: N
A17: * For this finding, No one could indicate that the statue is silent or that it denies access.

Sheet enr send dist
A1: Table 6 | B1: Students Originating from Districts that Receive a Higher Percentage of State Funding in their Aid Formula
A2: Formula for Distribution of FY07 New Jersey Charter State and Local Revenue Sending District
A3: Sending District by Charter School | B3: Charter Location | C3: BEDS | D3: # Pupils | E3: Sending District Funding Formula | F3: Total Sending District Local & State Revenue | G3: % state | H3: State Revenue | I3: % Local Revenue | J3: Local Revenue | K3: Sending District Total State & Local | L3: State % Total State & Local | M3: Local % Total State & Local | N3: % of pupils | O3: Charter Self Reported Local Revenues | P3: Local Portion Local Revenues | Q3: State Portion Local Revenues
A4: Academy Charter High
A5: Asbury Park City | D5: 162.7 | F5: =H5+J5 -> 33272858 | G5: =H5/F5 -> 0.825037 | H5: ='rev send dist only'!O359 -> 27451339 | I5: =J5/F5 -> 0.174963 | J5: ='rev send dist only'!J359 -> 5821519 | K5: =SUM(H5+J5) -> 33272858 | L5: =H5/K5 -> 0.825037 | M5: =J5/K5 -> 0.174963 | N5: =D5/$D$11 -> 0.83265097 | O5: 2330133 | P5: =O5*N5*M5 -> 339461.02 | Q5: =O5*N5*L5 -> 1600726.5
A6: Bradley Beach Boro | D6: 6 | F6: =H6+J6 -> 5083808 | G6: =H6/F6 -> 0 | H6: ='rev send dist only'!O364 -> 0 | I6: =J6/F6 -> 1 | J6: ='rev send dist only'!J364 -> 5083808 | K6: =SUM(H6+J6) -> 5083808 | L6: =H6/K6 -> 0 | M6: =J6/K6 -> 1 | N6: =D6/$D$11 -> 0.030706244 | O6: 2330133 | P6: =O6*N6*M6 -> 71549.632 | Q6: =O6*N6*L6 -> 0
A7: Neptune Twp | D7: 23.7 | F7: =H7+J7 -> 38370256 | G7: =H7/F7 -> 0.22188721 | H7: ='rev send dist only'!O394 -> 8513869 | I7: =J7/F7 -> 0.77811279 | J7: ='rev send dist only'!J394 -> 29856387 | K7: =SUM(H7+J7) -> 38370256 | L7: =H7/K7 -> 0.22188721 | M7: =J7/K7 -> 0.77811279 | N7: =D7/$D$11 -> 0.12128966 | O7: 2330133 | P7: =O7*N7*M7 -> 219911.05 | Q7: =O7*N7*L7 -> 62709.995
A8: Ocean Twp | D8: 1 | F8: =H8+J8 -> 53077484 | G8: =H8/F8 -> 0.093194489 | H8: ='rev send dist only'!O395 -> 4946529 | I8: =J8/F8 -> 0.90680551 | J8: ='rev send dist only'!J395 -> 48130955 | K8: =SUM(H8+J8) -> 53077484 | L8: =H8/K8 -> 0.093194489 | M8: =J8/K8 -> 0.90680551 | N8: =D8/$D$11 -> 0.0051177073 | O8: 2330133 | P8: =O8*N8*M8 -> 10813.6 | Q8: =O8*N8*L8 -> 1111.3386
A9: Lake Como | D9: 1 | F9: =H9+J9 -> 2785974 | G9: =H9/F9 -> 0.11371714 | H9: ='rev send dist only'!O405 -> 316813 | I9: =J9/F9 -> 0.88628286 | J9: ='rev send dist only'!J405 -> 2469161 | K9: =SUM(H9+J9) -> 2785974 | L9: =H9/K9 -> 0.11371714 | M9: =J9/K9 -> 0.88628286 | N9: =D9/$D$11 -> 0.0051177073 | O9: 2330133 | P9: =O9*N9*M9 -> 10568.869 | Q9: =O9*N9*L9 -> 1356.0699
A10: Wall Twp | D10: 1 | F10: =H10+J10 -> 49984614 | G10: =H10/F10 -> 0.013914002 | H10: ='rev send dist only'!O411 -> 695486 | I10: =J10/F10 -> 0.986086 | J10: ='rev send dist only'!J411 -> 49289128 | K10: =SUM(H10+J10) -> 49984614 | L10: =H10/K10 -> 0.013914002 | M10: =J10/K10 -> 0.986086 | N10: =D10/$D$11 -> 0.0051177073 | O10: 2330133 | P10: =O10*N10*M10 -> 11759.015 | Q10: =O10*N10*L10 -> 165.92361
A11: Benchmark Charter | D11: =SUM(D5:D10) -> 195.4 | P11: =SUM(P5:P10) -> 664063.19 | Q11: =SUM(Q5:Q10) -> 1666069.8
A12: Absecon City | D12: 0.8 | F12: =H12+J12 -> 8588416 | G12: =H12/F12 -> 0.040100177 | H12: ='rev send dist only'!O4 -> 344397 | I12: =J12/F12 -> 0.95989982 | J12: ='rev send dist only'!J4 -> 8244019 | K12: =SUM(H12+J12) -> 8588416 | L12: =H12/K12 -> 0.040100177 | M12: =J12/K12 -> 0.95989982 | N12: =D12/$D$26 -> 0.049382716 | P12: =O12*N12*M12 -> 0 | Q12: =O12*N12*L12 -> 0
A13: Atlantic City | D13: 0.8 | F13: =H13+J13 -> 95516913 | G13: =H13/F13 -> 0 | H13: ='rev send dist only'!O5 -> 0 | I13: =J13/F13 -> 1 | J13: ='rev send dist only'!J5 -> 95516913 | K13: =SUM(H13+J13) -> 95516913 | L13: =H13/K13 -> 0 | M13: =J13/K13 -> 1 | N13: =D13/$D$26 -> 0.049382716 | P13: =O13*N13*M13 -> 0 | Q13: =O13*N13*L13 -> 0
A14: Buena Regional | D14: 0.4 | F14: =H14+J14 -> 20836651 | G14: =H14/F14 -> 0.45071264 | H14: ='rev send dist only'!O9 -> 9391342 | I14: =J14/F14 -> 0.54928736 | J14: ='rev send dist only'!J9 -> 11445309 | K14: =SUM(H14+J14) -> 20836651 | L14: =H14/K14 -> 0.45071264 | M14: =J14/K14 -> 0.54928736 | N14: =D14/$D$26 -> 0.024691358 | P14: =O14*N14*M14 -> 0 | Q14: =O14*N14*L14 -> 0
A15: Corbin City | D15: 0.2 | F15: =H15+J15 -> 1186799 | G15: =H15/F15 -> 0.35255422 | H15: ='rev send dist only'!O10 -> 418411 | I15: =J15/F15 -> 0.64744578 | J15: ='rev send dist only'!J10 -> 768388 | K15: =SUM(H15+J15) -> 1186799 | L15: =H15/K15 -> 0.35255422 | M15: =J15/K15 -> 0.64744578 | N15: =D15/$D$26 -> 0.012345679 | P15: =O15*N15*M15 -> 0 | Q15: =O15*N15*L15 -> 0
A16: Egg Harbor Twp | D16: 0.6 | F16: =H16+J16 -> 72401641 | G16: =H16/F16 -> 0.28095243 | H16: ='rev send dist only'!O12 -> 20341417 | I16: =J16/F16 -> 0.71904757 | J16: ='rev send dist only'!J12 -> 52060224 | K16: =SUM(H16+J16) -> 72401641 | L16: =H16/K16 -> 0.28095243 | M16: =J16/K16 -> 0.71904757 | N16: =D16/$D$26 -> 0.037037037 | P16: =O16*N16*M16 -> 0 | Q16: =O16*N16*L16 -> 0
A17: Estell Manor City | D17: 0.8 | F17: =H17+J17 -> 3443757 | G17: =H17/F17 -> 0.43170816 | H17: ='rev send dist only'!O13 -> 1486698 | I17: =J17/F17 -> 0.56829184 | J17: ='rev send dist only'!J13 -> 1957059 | K17: =SUM(H17+J17) -> 3443757 | L17: =H17/K17 -> 0.43170816 | M17: =J17/K17 -> 0.56829184 | N17: =D17/$D$26 -> 0.049382716 | P17: =O17*N17*M17 -> 0 | Q17: =O17*N17*L17 -> 0
A18: Greater Egg Harbor Reg | D18: 1.7 | F18: =H18+J18 -> 44291276 | G18: =H18/F18 -> 0.40463217 | H18: ='rev send dist only'!O16 -> 17921675 | I18: =J18/F18 -> 0.59536783 | J18: ='rev send dist only'!J16 -> 26369601 | K18: =SUM(H18+J18) -> 44291276 | L18: =H18/K18 -> 0.40463217 | M18: =J18/K18 -> 0.59536783 | N18: =D18/$D$26 -> 0.10493827 | P18: =O18*N18*M18 -> 0 | Q18: =O18*N18*L18 -> 0
A19: Pleasantville City | D19: 7.5 | F19: =H19+J19 -> 34151238 | G19: =H19/F19 -> 0.80709888 | H19: ='rev send dist only'!O25 -> 27563426 | I19: =J19/F19 -> 0.19290112 | J19: ='rev send dist only'!J25 -> 6587812 | K19: =SUM(H19+J19) -> 34151238 | L19: =H19/K19 -> 0.80709888 | M19: =J19/K19 -> 0.19290112 | N19: =D19/$D$26 -> 0.46296296 | P19: =O19*N19*M19 -> 0 | Q19: =O19*N19*L19 -> 0
A20: Ventnor City | D20: 0.2 | F20: =H20+J20 -> 15801226 | G20: =H20/F20 -> 0.0063286229 | H20: ='rev send dist only'!O28 -> 100000 | I20: =J20/F20 -> 0.99367138 | J20: ='rev send dist only'!J28 -> 15701226 | K20: =SUM(H20+J20) -> 15801226 | L20: =H20/K20 -> 0.0063286229 | M20: =J20/K20 -> 0.99367138 | N20: =D20/$D$26 -> 0.012345679 | P20: =O20*N20*M20 -> 0 | Q20: =O20*N20*L20 -> 0
A21: Weymouth Twp | D21: 0.6 | F21: =H21+J21 -> 3202984 | G21: =H21/F21 -> 0.49066277 | H21: ='rev send dist only'!O29 -> 1571585 | I21: =J21/F21 -> 0.50933723 | J21: ='rev send dist only'!J29 -> 1631399 | K21: =SUM(H21+J21) -> 3202984 | L21: =H21/K21 -> 0.49066277 | M21: =J21/K21 -> 0.50933723 | N21: =D21/$D$26 -> 0.037037037 | P21: =O21*N21*M21 -> 0 | Q21: =O21*N21*L21 -> 0
A22: Dennis Twp | D22: 0.8 | F22: =H22+J22 -> 11557417 | G22: =H22/F22 -> 0.38452909 | H22: ='rev send dist only'!O195 -> 4444163 | I22: =J22/F22 -> 0.61547091 | J22: ='rev send dist only'!J195 -> 7113254 | K22: =SUM(H22+J22) -> 11557417 | L22: =H22/K22 -> 0.38452909 | M22: =J22/K22 -> 0.61547091 | N22: =D22/$D$26 -> 0.049382716 | P22: =O22*N22*M22 -> 0 | Q22: =O22*N22*L22 -> 0
A23: Upper Twp | D23: 1.2 | F23: =H23+J23 -> 26859440 | G23: =H23/F23 -> 0.25367204 | H23: ='rev send dist only'!O203 -> 6813489 | I23: =J23/F23 -> 0.74632796 | J23: ='rev send dist only'!J203 -> 20045951 | K23: =SUM(H23+J23) -> 26859440 | L23: =H23/K23 -> 0.25367204 | M23: =J23/K23 -> 0.74632796 | N23: =D23/$D$26 -> 0.074074074 | P23: =O23*N23*M23 -> 0 | Q23: =O23*N23*L23 -> 0
A24: Woodbine Boro | D24: 0.4 | F24: =H24+J24 -> 3007432 | G24: =H24/F24 -> 0.65751179 | H24: ='rev send dist only'!O208 -> 1977422 | I24: =J24/F24 -> 0.34248821 | J24: ='rev send dist only'!J208 -> 1030010 | K24: =SUM(H24+J24) -> 3007432 | L24: =H24/K24 -> 0.65751179 | M24: =J24/K24 -> 0.34248821 | N24: =D24/$D$26 -> 0.024691358 | P24: =O24*N24*M24 -> 0 | Q24: =O24*N24*L24 -> 0
A25: Commercial Twp | D25: 0.2 | F25: =H25+J25 -> 7519706 | G25: =H25/F25 -> 0.75021484 | H25: ='rev send dist only'!O210 -> 5641395 | I25: =J25/F25 -> 0.24978516 | J25: ='rev send dist only'!J210 -> 1878311 | K25: =SUM(H25+J25) -> 7519706 | L25: =H25/K25 -> 0.75021484 | M25: =J25/K25 -> 0.24978516 | N25: =D25/$D$26 -> 0.012345679 | P25: =O25*N25*M25 -> 0 | Q25: =O25*N25*L25 -> 0
A26: Central Jersey Prep | D26: =SUM(D12:D25) -> 16.2 | P26: =SUM(P12:P13) -> 0 | Q26: =SUM(Q12:Q13) -> 0
A27: Hamilton Twp | B27: Albany | C27: 010100 | D27: 1 | F27: =H27+J27 -> 125290913 | G27: =H27/F27 -> 0.25425071 | H27: ='rev send dist only'!O323 -> 31855304 | I27: =J27/F27 -> 0.74574929 | J27: ='rev send dist only'!J323 -> 93435609 | K27: =SUM(H27+J27) -> 125290913 | L27: =H27/K27 -> 0.25425071 | M27: =J27/K27 -> 0.74574929 | N27: =D27/$D$38 -> 0.006097561 | O27: 954474 | P27: =O27*N27*M27 -> 4340.2336 | Q27: =O27*N27*L27 -> 1479.7298
A28: Highland Park Boro | D28: 1 | F28: =H28+J28 -> 18671955 | G28: =H28/F28 -> 0.047495402 | H28: ='rev send dist only'!O338 -> 886832 | I28: =J28/F28 -> 0.9525046 | J28: ='rev send dist only'!J338 -> 17785123 | K28: =SUM(H28+J28) -> 18671955 | L28: =H28/K28 -> 0.047495402 | M28: =J28/K28 -> 0.9525046 | N28: =D28/$D$38 -> 0.006097561 | O28: 954474 | P28: =O28*N28*M28 -> 5543.5419 | Q28: =O28*N28*L28 -> 276.4215
A29: New Brunswick City | D29: 71.1 | F29: =H29+J29 -> 57383607 | G29: =H29/F29 -> 0.52198012 | H29: ='rev send dist only'!O346 -> 29953102 | I29: =J29/F29 -> 0.47801988 | J29: ='rev send dist only'!J346 -> 27430505 | K29: =SUM(H29+J29) -> 57383607 | L29: =H29/K29 -> 0.52198012 | M29: =J29/K29 -> 0.47801988 | N29: =D29/$D$38 -> 0.43353659 | O29: 954474 | P29: =O29*N29*M29 -> 197804.34 | Q29: =O29*N29*L29 -> 215995.06
A30: North Brunswick Twp | D30: 13.7 | F30: =H30+J30 -> 63170430 | G30: =H30/F30 -> 0.033034064 | H30: ='rev send dist only'!O347 -> 2086776 | I30: =J30/F30 -> 0.96696594 | J30: ='rev send dist only'!J347 -> 61083654 | K30: =SUM(H30+J30) -> 63170430 | L30: =H30/K30 -> 0.033034064 | M30: =J30/K30 -> 0.96696594 | N30: =D30/$D$38 -> 0.083536585 | O30: 954474 | P30: =O30*N30*M30 -> 77099.577 | Q30: =O30*N30*L30 -> 2633.9215
A31: Piscataway Twp | D31: 1 | F31: =H31+J31 -> 74430231 | G31: =H31/F31 -> 0.050648976 | H31: ='rev send dist only'!O350 -> 3769815 | I31: =J31/F31 -> 0.94935102 | J31: ='rev send dist only'!J350 -> 70660416 | K31: =SUM(H31+J31) -> 74430231 | L31: =H31/K31 -> 0.050648976 | M31: =J31/K31 -> 0.94935102 | N31: =D31/$D$38 -> 0.006097561 | O31: 954474 | P31: =O31*N31*M31 -> 5525.1882 | Q31: =O31*N31*L31 -> 294.77519
A32: South Brunswick Twp | D32: 1 | F32: =H32+J32 -> 101877504 | G32: =H32/F32 -> 0.10543046 | H32: ='rev send dist only'!O353 -> 10740992 | I32: =J32/F32 -> 0.89456954 | J32: ='rev send dist only'!J353 -> 91136512 | K32: =SUM(H32+J32) -> 101877504 | L32: =H32/K32 -> 0.10543046 | M32: =J32/K32 -> 0.89456954 | N32: =D32/$D$38 -> 0.006097561 | O32: 954474 | P32: =O32*N32*M32 -> 5206.362 | Q32: =O32*N32*L32 -> 613.60141
A33: South River Boro | D33: 1 | F33: =H33+J33 -> 17187343 | G33: =H33/F33 -> 0.31843107 | H33: ='rev send dist only'!O355 -> 5472984 | I33: =J33/F33 -> 0.68156893 | J33: ='rev send dist only'!J355 -> 11714359 | K33: =SUM(H33+J33) -> 17187343 | L33: =H33/K33 -> 0.31843107 | M33: =J33/K33 -> 0.68156893 | N33: =D33/$D$38 -> 0.006097561 | O33: 954474 | P33: =O33*N33*M33 -> 3966.7062 | Q33: =O33*N33*L33 -> 1853.2572
A34: Bound Brook Boro | D34: 2.5 | F34: =H34+J34 -> 14987214 | G34: =H34/F34 -> 0.15880697 | H34: ='rev send dist only'!O522 -> 2380074 | I34: =J34/F34 -> 0.84119303 | J34: ='rev send dist only'!J522 -> 12607140 | K34: =SUM(H34+J34) -> 14987214 | L34: =H34/K34 -> 0.15880697 | M34: =J34/K34 -> 0.84119303 | N34: =D34/$D$38 -> 0.015243902 | O34: 954474 | P34: =O34*N34*M34 -> 12239.282 | Q34: =O34*N34*L34 -> 2310.6268
A35: Franklin Twp | D35: 62.3 | F35: =H35+J35 -> 97929722 | G35: =H35/F35 -> 0 | H35: ='rev send dist only'!O525 -> 0 | I35: =J35/F35 -> 1 | J35: ='rev send dist only'!J525 -> 97929722 | K35: =SUM(H35+J35) -> 97929722 | L35: =H35/K35 -> 0 | M35: =J35/K35 -> 1 | N35: =D35/$D$38 -> 0.37987805 | O35: 954474 | P35: =O35*N35*M35 -> 362583.72 | Q35: =O35*N35*L35 -> 0
A36: Somerville Boro | D36: 1 | F36: =H36+J36 -> 19801225 | G36: =H36/F36 -> 0.096690836 | H36: ='rev send dist only'!O536 -> 1914597 | I36: =J36/F36 -> 0.90330916 | J36: ='rev send dist only'!J536 -> 17886628 | K36: =SUM(H36+J36) -> 19801225 | L36: =H36/K36 -> 0.096690836 | M36: =J36/K36 -> 0.90330916 | N36: =D36/$D$38 -> 0.006097561 | O36: 954474 | P36: =O36*N36*M36 -> 5257.2263 | Q36: =O36*N36*L36 -> 562.73713
A37: Plainfield City | D37: 8.4 | F37: =H37+J37 -> 62723780 | G37: =H37/F37 -> 0.71806696 | H37: ='rev send dist only'!O579 -> 45039874 | I37: =J37/F37 -> 0.28193304 | J37: ='rev send dist only'!J579 -> 17683906 | K37: =SUM(H37+J37) -> 62723780 | L37: =H37/K37 -> 0.71806696 | M37: =J37/K37 -> 0.28193304 | N37: =D37/$D$38 -> 0.051219512 | O37: 954474 | P37: =O37*N37*M37 -> 13783.056 | Q37: =O37*N37*L37 -> 35104.637
A38: Camden Academy Charter | D38: =SUM(D27:D37) -> 164 | P38: =SUM(P27:P37) -> 693349.23 | Q38: =SUM(Q27:Q37) -> 261124.77
A39: Camden City | B39: Albany | C39: 010100 | D39: 399 | F39: =H39+J39 -> 142607869 | G39: =H39/F39 -> 0.93287844 | H39: ='rev send dist only'!O158 -> 133035807 | I39: =J39/F39 -> 0.067121556 | J39: ='rev send dist only'!J158 -> 9572062 | K39: =SUM(H39+J39) -> 142607869 | L39: =H39/K39 -> 0.93287844 | M39: =J39/K39 -> 0.067121556 | N39: =D39/$D$41 -> 0.99007444 | O39: 615928 | P39: =O39*N39*M39 -> 40931.703 | Q39: =O39*N39*L39 -> 568882.87
A40: Pennsauken Twp | D40: 4 | F40: =H40+J40 -> 55109391 | G40: =H40/F40 -> 0.37803192 | H40: ='rev send dist only'!O180 -> 20833109 | I40: =J40/F40 -> 0.62196808 | J40: ='rev send dist only'!J180 -> 34276282 | K40: =SUM(H40+J40) -> 55109391 | L40: =H40/K40 -> 0.37803192 | M40: =J40/K40 -> 0.62196808 | N40: =D40/$D$41 -> 0.0099255583 | O40: 615928 | P40: =O40*N40*M40 -> 3802.3579 | Q40: =O40*N40*L40 -> 2311.0714
...

Sheet State Chart
G1: Local | H1: Local | I1: Local | J1: Local | K1: Local | L1: Local | M1: Local | O1: State | P1: State | Q1: State | R1: State | S1: State | T1: State | U1: State | V1: State | W1: State | X1: State | Y1: State | Z1: State | AA1: State | AB1: State | AC1: State | AD1: State | AE1: State | AF1: State | AG1: State | AH1: State | AI1: State | AJ1: State | AK1: State | AL1: State | AM1: State | AN1: State | AO1: State | AP1: State | AQ1: State | AR1: State | AS1: State | AT1: State | AU1: State Revenue - Special Revenue Funds | AW1: Federal | AX1: Federal | AY1: Federal | AZ1: Federal | BA1: Federal | BB1: Federal | BC1: Federal Revenue | BD1: Federal Revenue | BE1: Federal Revenue | BG1: Other | BH1: Other | BI1: Other | BJ1: Other | BK1: Other | BL1: Other | BM1: Other | BN1: Other | BO1: Other | BP1: Other | BR1: Other | BS1: Other | BT1: Other | BU1: Other | BV1: Other | BW1: Other | BX1: Other | BY1: Other | BZ1: Other | CA1: Other | CB1: Other | CD1: Indeterminate | CE1: Indeterminate | CF1: Indeterminate | CG1: Indeterminate | CI1: Intermediate | CJ1: Intermediate | CM1: Capital Projects Fund | CN1: Capital Projects | CO1: State | CP1: State | CQ1: State | CR1: Federal | CS1: Federal | CT1: State | CU1: State | CV1: Indeterminate
A2: CO | B2: DIST | C2: CONAME | D2: DISTNAME | F2: Enrollment | G2: Local Tax Levy & Unrestricted Misc Revenues | H2: County Tax Levy | I2: Other Local Govt Units - Unrestricted | J2: Other Local Govt Units - Restricted | K2: Other Revenue from Local Sources | L2: Local Tax Levy | M2: Municipal Surplus | N2: Total Local | O2: Core Curriculum Standards Aid | P2: Supplemental Core Curriculum Standards Aid | Q2: Local Tax Levy & Unrestricted Misc Revenues | R2: School Choice Aid | S2: Education Opportunity Aid | T2: Discretionary Education Opportunity Aid | U2: Abbott-bordered district aid | V2: Transportation Aid | W2: Special Education Aid | X2: Bilingual Education | Y2: Stabilization Aid | Z2: Supplemental Stabilization Aid | AA2: County Vocational Education Program Aid | AB2: Academic Achievement Reward Program | AC2: Extraordinary Aid | AD2: Consolidated Aid | AE2: Additional Formula Aid | AF2: Other State Aids - Out of Cap | AG2: TPAF Pension (On Behalf) | AH2: TPAF Social Security (Reimbursed) | AI2: Other State Aids | AJ2: Demonstrably Effective Program Aid - Prior Year Carryover | AK2: Distance Learning Network Aid - Prior Year Carryover | AL2: Instructional Supplement Ad - Prior Yr Carryover | AM2: Demontrably Effective Program Aid | AN2: Distance Learning Network Aid | AO2: Instructional Supplemental Aid | AP2: Debt Service Aid Type II | AQ2: Addtl State School Bldg Aid - Chap 177 | AR2: Addtl State School Bldg Aid - Chap 10 | AS2: Addt State School Building Aid-Chapter 74 | AT2: Addtl State School Building Aid - EDA Grant | AU2: Other Restricted Entitlements | AW2: Medicaid Reimbursement | AX2: Title VI | AY2: Schoolwide Programs | AZ2: JTPA | BA2: PL 81.874 (Impact) | BB2: Vocational Education | BC2: Title I | BD2: IDEA | BE2: Other Federal | BG2: Other Financing Sources - Capital Leases | BH2: Other Financing Sources | BI2: Tuition from Individuals | BJ2: Tuition from Other Sources | BK2: Tuition from Summer School | BL2: Non-Resident Fees | BM2: Transportation Fees from Individuals | BN2: Transportation Fees Other LEAs | BO2: Interest Earned on Capital Reserve Funds | BP2: Other Restricted Misc | BR2: Rents & Royalties | BS2: Sale of Property | BT2: Fines and Forfeits | BU2: Private Contributions | BV2: Tetbook Sales & Rentals | BW2: Interest on Investments | BX2: Other Financing Sources | BY2: Interest on Investments | BZ2: Other Misc | CA2: Earnings on Investments | CB2: Other Financing Sources | CD2: Tuition Other LEAs in State | CE2: Tuition from Other LEAs Outside the State | CF2: Tuition from LEAs | CG2: Other Tuition | CI2: Restricted Rev from Intermediate Sources | CJ2: Unrestricted Rev from Intermediate Sources | CM2: Bond Principal | CN2: Bond Premium | CO2: Aid for Adult & Post Graduate Programs | CP2: Post-Secondary Vocational Program Aid | CQ2: Early Childhood Program Aid - Prior Year Carryover | CR2: Adult Basic Ed | CS2: Interest earnd on Early Childhood Cap. Res. Fund | CT2: Early Childhood Program | CU2: Preschool Expansion Aid | CV2: Total Special Revenue
G3: L150/L253 | H3: L160 | I3: L191 | J3: L192 | K3: L419 | L3: L550 | M3: L642 | O3: L280 | P3: L281 | Q3: L150/L253 | R3: L285 | S3: L286 | T3: L287 | U3: L288 | V3: L300 | W3: L310 | X3: L320 | Y3: L340 | Z3: L341 | AA3: L350 | AB3: L353 | AC3: L354 | AD3: L355 | AE3: L356 | AF3: L360 | AG3: L361 | AH3: L362 | AI3: L365 | AJ3: L422 | AK3: L423 | AL3: L424 | AM3: L426 | AN3: L427 | AO3: L428 | AP3: L580 | AQ3: L600 | AR3: L610 | AS3: L620 | AT3: L641 | AU3: L430 | AV3: Total State | AW3: L390 | AX3: L450 | AY3: L455 | AZ3: L490 | BA3: L380 | BB3: L470 | BC3: L440 | BD3: L460 | BE3: L500 | BF3: Total Federal | BG3: L141 | BH3: L142 | BI3: L195 | BJ3: L198 | BK3: L199 | BL3: L230 | BM3: L241 | BN3: L242 | BO3: L251 | BP3: L252 | BR3: L254 | BS3: L255 | BT3: L256 | BU3: L257 | BV3: L258 | BW3: L418 | BX3: L541 | BY3: L551 | BZ3: L552 | CA3: L643 | CB3: L647 | CC3: Total Other | CD3: L196 | CE3: L197 | CF3: L210 | CG3: L220 | CI3: L271 | CJ3: L272 | CK3: Total Indeterminate | CM3: L644 | CN3: L645 | CO3: L351 | CP3: L352 | CQ3: L421 | CR3: L480 | CS3: L512 | CT3: L425 | CU3: L429 | CV3: L520
A4: 80 | B4: 6010 | C4: Lake Como | D4: Academy Charter High School | F4: 202 | G4: 664063.19 | N4: =SUM(G4:M4) -> 664063.19 | P4: 55117 | Q4: 1666069.8 | W4: 112833 | X4: 1400 | AH4: 82076 | AV4: =SUM(O4:AU4) -> 1917495.8 | AX4: 40755 | BC4: 97563 | BF4: =SUM(AW4:BE4) -> 138318 | CC4: =SUM(BG4:CB4) -> 0 | CK4: =SUM(CD4:CJ4) -> 0 | CV4: 138318
A5: 80 | B5: 6018 | C5: SOMERSET | D5: Central Jersey College Prep | F5: 164 | G5: 693349.23 | N5: =SUM(G5:M5) -> 693349.23 | Q5: 261124.77 | W5: 78081 | AF5: 684744 | AH5: 52147 | AU5: 3000 | AV5: =SUM(O5:AU5) -> 1079096.8 | BC5: 27840 | BE5: 319041 | BF5: =SUM(AW5:BE5) -> 346881 | BU5: 61045 | CC5: =SUM(BG5:CB5) -> 61045 | CK5: =SUM(CD5:CJ5) -> 0 | CV5: 349881
A6: 80 | B6: 6212 | C6: Camden | D6: Camden Academy Charter High School | F6: 406 | G6: 44734.06 | N6: =SUM(G6:M6) -> 44734.06 | O6: 3079797 | Q6: 571193.94 | R6: 183466 | W6: 173091 | AG6: 127894 | AH6: 144787 | AI6: 353634 | AU6: 251 | AV6: =SUM(O6:AU6) -> 4634113.9 | BC6: 414688 | BD6: 92081 | BE6: 42244 | BF6: =SUM(AW6:BE6) -> 549013 | CC6: =SUM(BG6:CB6) -> 0 | CK6: =SUM(CD6:CJ6) -> 0 | CV6: 549264
A7: 80 | B7: 6215 | C7: Camden | D7: Camden's Promise Charter | F7: 391 | G7: 138050.71 | N7: =SUM(G7:M7) -> 138050.71 | O7: 2793192 | Q7: 1567881.3 | W7: 225245 | AG7: 115668 | AH7: 157364 | AV7: =SUM(O7:AU7) -> 4859350.3 | BC7: 361407 | BD7: 82539 | BE7: 616263 | BF7: =SUM(AW7:BE7) -> 1060209 | CC7: =SUM(BG7:CB7) -> 0 | CJ7: 172344 | CK7: =SUM(CD7:CJ7) -> 172344 | CV7: 1060209
A8: 80 | B8: 6217 | C8: Plainfield | D8: Central Jersey Arts | F8: 222 | G8: 135691.71 | N8: =SUM(G8:M8) -> 135691.71 | Q8: 302047.29 | W8: 34375 | AH8: 58427 | AI8: 1728752 | AU8: 565634 | AV8: =SUM(O8:AU8) -> 2689235.3 | BC8: 22427 | BE8: 650 | BF8: =SUM(AW8:BE8) -> 23077 | CC8: =SUM(BG8:CB8) -> 0 | CK8: =SUM(CD8:CJ8) -> 0 | CV8: 588711
A9: 80 | B9: 6220 | C9: Jersey City | D9: CREATE | F9: 518 | G9: 350113.88 | I9: 2299440 | N9: =SUM(G9:M9) -> 2649553.9 | Q9: 765719.12 | W9: 401004 | AH9: 136909 | AM9: 130654 | AN9: 112475 | AU9: 359020 | AV9: =SUM(O9:AU9) -> 1905781.1 | BC9: 264127 | BD9: 89487 | BE9: 175429 | BF9: =SUM(AW9:BE9) -> 529043 | BR9: 101343 | CC9: =SUM(BG9:CB9) -> 101343 | CK9: =SUM(CD9:CJ9) -> 0 | CV9: 1131192
A10: 80 | B10: 6230 | C10: Clifton | D10: Classical Academy Charter | F10: 104 | G10: 820085.02 | K10: 6053 | N10: =SUM(G10:M10) -> 826138.02 | Q10: 65457.982 | AF10: 66314 | AH10: 29116 | AU10: 4000 | AV10: =SUM(O10:AU10) -> 164887.98 | BC10: 2418 | BD10: 2025 | BE10: 3859 | BF10: =SUM(AW10:BE10) -> 8302 | CC10: =SUM(BG10:CB10) -> 0 | CK10: =SUM(CD10:CJ10) -> 0 | CV10: 18355
A11: 80 | B11: 6232 | C11: Camden | D11: Environment Community Opportunity Charter School (ECO Charter School) | F11: 198 | G11: 23379.343 | N11: =SUM(G11:M11) -> 23379.343 | O11: 1157758 | Q11: 275004.66 | W11: 21623 | AF11: 259401 | AH11: 52275 | AM11: 80195 | AV11: =SUM(O11:AU11) -> 1846256.7 | AX11: 4384 | BC11: 200514 | BD11: 10593 | BE11: 206552 | BF11: =SUM(AW11:BE11) -> 422043 | CC11: =SUM(BG11:CB11) -> 0 | CK11: =SUM(CD11:CJ11) -> 0 | CT11: 141128 | CV11: 643366
A12: 80 | B12: 6235 | C12: Jersey City | D12: Liberty Academy Charter School | F12: 337 | G12: 273261.16 | N12: =SUM(G12:M12) -> 273261.16 | Q12: 584910.84 | W12: 153008 | X12: 5840 | AF12: 2484819 | AH12: 76818 | AV12: =SUM(O12:AU12) -> 3305395.8 | BC12: 297746 | BD12: 49919 | BE12: 53825 | BF12: =SUM(AW12:BE12) -> 401490 | CC12: =SUM(BG12:CB12) -> 0 | CK12: =SUM(CD12:CJ12) -> 0 | CV12: 401490
A13: 80 | B13: 6240 | C13: Camden | D13: Freedom Academy Charter School | F13: 215 | G13: 23011.255 | K13: 132750 | N13: =SUM(G13:M13) -> 155761.26 | O13: 1595913 | Q13: 289004.74 | W13: 160308 | AF13: 235387 | AH13: 34566 | AV13: =SUM(O13:AU13) -> 2315178.7 | BC13: 198674 | BE13: 43101 | BF13: =SUM(AW13:BE13) -> 241775 | BU13: 28933 | CC13: =SUM(BG13:CB13) -> 28933 | CK13: =SUM(CD13:CJ13) -> 0 | CV13: 374525
A14: 80 | B14: 6320 | C14: Newark | D14: Discovery Charter | F14: 75 | G14: 33429.267 | K14: 53000 | N14: =SUM(G14:M14) -> 86429.267 | Q14: 104372.73 | W14: 53080 | AF14: 563805 | AH14: 21326 | AV14: =SUM(O14:AU14) -> 742583.73 | BC14: 43088 | BD14: 10660 | BE14: 287792 | BF14: =SUM(AW14:BE14) -> 341540 | CC14: =SUM(BG14:CB14) -> 0 | CK14: =SUM(CD14:CJ14) -> 0 | CV14: 394540
A15: 80 | B15: 6325 | C15: Camden | D15: D.U.E. Season Charter | F15: 329 | G15: 36511.854 | N15: =SUM(G15:M15) -> 36511.854 | Q15: 435153.15 | W15: 78128 | AF15: 2900896 | AH15: 82597 | AU15: 223254 | AV15: =SUM(O15:AU15) -> 3720028.1 | BC15: 166396 | BD15: 34813 | BE15: 6736 | BF15: =SUM(AW15:BE15) -> 207945 | CC15: =SUM(BG15:CB15) -> 0 | CK15: =SUM(CD15:CJ15) -> 0 | CV15: 431199
A16: 80 | B16: 6410 | C16: East Orange | D16: East Orange Community Charter | F16: 501 | G16: 191481.34 | N16: =SUM(G16:M16) -> 191481.34 | O16: 2787424 | Q16: 717627.66 | W16: 103880 | AF16: 1255101 | AH16: 118791 | AV16: =SUM(O16:AU16) -> 4982823.7 | BC16: 425588 | BD16: 105509 | BE16: 256157 | BF16: =SUM(AW16:BE16) -> 787254 | CC16: =SUM(BG16:CB16) -> 0 | CK16: =SUM(CD16:CJ16) -> 0 | CV16: 787254
A17: 80 | B17: 6420 | C17: Hoboken | D17: Elysian Charter | F17: 279 | G17: 709741.84 | I17: 2248197 | N17: =SUM(G17:M17) -> 2957938.8 | Q17: 320838.16 | W17: 189487 | AF17: 160769 | AG17: 111623 | AV17: =SUM(O17:AU17) -> 782717.16 | BC17: 64068 | BD17: 39671 | BE17: 13350 | BF17: =SUM(AW17:BE17) -> 117089 | CC17: =SUM(BG17:CB17) -> 0 | CK17: =SUM(CD17:CJ17) -> 0 | CV17: 117089
A18: 80 | B18: 6425 | C18: Trenton | D18: Emily Fisher Charter | F18: 352 | G18: 111698.87 | N18: =SUM(G18:M18) -> 111698.87 | Q18: 512356.13 | W18: 1462240 | X18: 7290 | AF18: 2873003 | AH18: 99491 | AV18: =SUM(O18:AU18) -> 4954380.1 | BC18: 321978 | BD18: 63559 | BE18: 48003 | BF18: =SUM(AW18:BE18) -> 433540 | CC18: =SUM(BG18:CB18) -> 0 | CK18: =SUM(CD18:CJ18) -> 0 | CV18: 433540
A19: 80 | B19: 6430 | C19: Englewood | D19: Englewood on the Palisades Charter School | F19: 182 | G19: 1396669.3 | N19: =SUM(G19:M19) -> 1396669.3 | O19: 722193 | Q19: 43903.683 | W19: 55463 | X19: 294 | AF19: 325 | AH19: 70378 | AM19: 68279 | AO19: 1297 | AV19: =SUM(O19:AU19) -> 962132.68 | AX19: 14483 | BA19: 475 | BC19: 121191 | BD19: 27351 | BE19: 2900 | BF19: =SUM(AW19:BE19) -> 166400 | CC19: =SUM(BG19:CB19) -> 0 | CK19: =SUM(CD19:CJ19) -> 0 | CT19: 118130 | CV19: 353631
A20: 80 | B20: 6612 | C20: Galloway Township | D20: Galloway Community Charter School | F20: 270 | G20: 1220410.9 | N20: =SUM(G20:M20) -> 1220410.9 | Q20: 888874.15 | W20: 44841 | AF20: 219768 | AH20: 104580 | AU20: 191677 | AV20: =SUM(O20:AU20) -> 1449740.1 | BC20: 103503 | BD20: 56606 | BE20: 7843 | BF20: =SUM(AW20:BE20) -> 167952 | BX20: 237370 | CC20: =SUM(BG20:CB20) -> 237370 | CK20: =SUM(CD20:CJ20) -> 0 | CV20: 359629
A21: 80 | B21: 6635 | C21: New Brunswick | D21: Greater Brunswick Charter School | F21: 219 | G21: 556779.22 | N21: =SUM(G21:M21) -> 556779.22 | O21: 587519 | Q21: 398661.78 | W21: 92829 | X21: 32704 | AF21: 437901 | AG21: 13925 | AH21: 69545 | AU21: 132180 | AV21: =SUM(O21:AU21) -> 1765264.8 | AY21: 32186 | BC21: 90866 | BE21: 1575 | BF21: =SUM(AW21:BE21) -> 124627 | CC21: =SUM(BG21:CB21) -> 0 | CK21: =SUM(CD21:CJ21) -> 0 | CV21: 256807
A22: 80 | B22: 6665 | C22: Newark | D22: Gray Charter School | F22: 306 | G22: 140740.99 | N22: =SUM(G22:M22) -> 140740.99 | Q22: 439421.01 | AF22: 2443362 | AH22: 74931 | AU22: 4000 | AV22: =SUM(O22:AU22) -> 2961714 | BC22: 234750 | BE22: 30398 | BF22: =SUM(AW22:BE22) -> 265148 | CC22: =SUM(BG22:CB22) -> 0 | CK22: =SUM(CD22:CJ22) -> 0 | CL22: =SUM(N22+AV22+BF22+CC23+CK23) -> 3367603 | CV22: 269148
A23: 80 | B23: 6720 | C23: Hoboken | D23: Hoboken Charter School | F23: 251 | G23: 1482388 | K23: 40291 | N23: =SUM(G23:M23) -> 1522679 | O23: 1401520 | Q23: 617445.01 | W23: 228146 | AF23: 204519 | AH23: 115239 | AV23: =SUM(O23:AU23) -> 2566869 | BC23: 64795 | BD23: 42401 | BE23: 18238 | BF23: =SUM(AW23:BE23) -> 125434 | CC23: =SUM(BG23:CB23) -> 0 | CK23: =SUM(CD23:CJ23) -> 0 | CV23: 165725
A24: 80 | B24: 6740 | C24: Asbury Park | D24: Hope Academy Charter School | F24: 135 | G24: 76802.086 | N24: =SUM(G24:M24) -> 76802.086 | Q24: 239338.91 | AF24: 1296566 | AH24: 69043 | AV24: =SUM(O24:AU24) -> 1604947.9 | BC24: 110972 | BD24: 34603 | BE24: 11178 | BF24: =SUM(AW24:BE24) -> 156753 | CC24: =SUM(BG24:CB24) -> 0 | CK24: =SUM(CD24:CJ24) -> 0 | CV24: 156753
A25: 80 | B25: 6810 | C25: Trenton | D25: International Charter School of Trenton | F25: 94.5 | G25: 29309.455 | N25: =SUM(G25:M25) -> 29309.455 | Q25: 134735.55 | W25: 50525 | AF25: 753481 | AH25: 35679 | AU25: 1638 | AV25: =SUM(O25:AU25) -> 976058.55 | BC25: 72658 | BD25: 26141 | BE25: 26029 | BF25: =SUM(AW25:BE25) -> 124828 | CC25: =SUM(BG25:CB25) -> 0 | CK25: =SUM(CD25:CJ25) -> 0 | CL25: =SUM(N25+AV25+BF25+CC26+CK26) -> 1259902 | CV25: 126466
A26: 80 | B26: 6910 | C26: Jersey City | D26: Jersey City Community Charter School | F26: 505 | G26: 348970.78 | N26: =SUM(G26:M26) -> 348970.78 | O26: 2276775 | Q26: 743587.22 | W26: 60091 | AF26: 1305249 | AH26: 132000 | AV26: =SUM(O26:AU26) -> 4517702.2 | BC26: 670116 | BD26: 85170 | BE26: 48289 | BF26: =SUM(AW26:BE26) -> 803575 | BO26: 65022 | BP26: 64684 | CC26: =SUM(BG26:CB26) -> 129706 | CK26: =SUM(CD26:CJ26) -> 0 | CV26: 803575
A27: 80 | B27: 6915 | C27: Jersey City | D27: Jersey City Golden Door Charter School | F27: 494 | G27: 368589.86 | N27: =SUM(G27:M27) -> 368589.86 | Q27: 806127.14 | W27: 132810 | AF27: 3753870 | AH27: 161209 | AU27: 1892 | AV27: =SUM(O27:AU27) -> 4855908.1 | BC27: 300676 | BD27: 96131 | BE27: 70581 | BF27: =SUM(AW27:BE27) -> 467388 | CC27: =SUM(BG27:CB27) -> 0 | CK27: =SUM(CD27:CJ27) -> 0 | CV27: 469280
A28: 80 | B28: 7100 | C28: Newark | D28: Lady Liberty Academy Charter School | F28: 443 | G28: 185215.1 | N28: =SUM(G28:M28) -> 185215.1 | Q28: 577992.9 | AF28: 3620192 | AH28: 161510 | AV28: =SUM(O28:AU28) -> 4359694.9 | BC28: 325286 | BD28: 96705 | BE28: 44518 | BF28: =SUM(AW28:BE28) -> 466509 | CC28: =SUM(BG28:CB28) -> 0 | CK28: =SUM(CD28:CJ28) -> 0 | CV28: 466509
A29: 80 | B29: 7109 | C29: Camden | D29: LEAP Academy University Charter School | F29: 774 | G29: 264692.66 | N29: =SUM(G29:M29) -> 264692.66 | O29: 5075202 | Q29: 1540066.3 | W29: 167020 | X29: 20907 | AF29: 554157 | AG29: 215266 | AH29: 260176 | AM29: 327061 | AV29: =SUM(O29:AU29) -> 8159855.3 | BC29: 577652 | BD29: 151589 | BE29: 496172 | BF29: =SUM(AW29:BE29) -> 1225413 | BH29: 362413 | CC29: =SUM(BG29:CB29) -> 362413 | CK29: =SUM(CD29:CJ29) -> 0 | CT29: 582624 | CV29: 2135098
A30: 80 | B30: 7115 | C30: Jersey City | D30: Learning Community Charter School | F30: 322 | G30: 266399.35 | I30: 1613923 | K30: 88637 | N30: =SUM(G30:M30) -> 1968959.4 | Q30: 582630.65 | U30: 122868 | W30: 150221 | X30: 2336 | AF30: 562084 | AG30: 118066 | AV30: =SUM(O30:AU30) -> 1538205.6 | BC30: 125760 | BD30: 48427 | BF30: =SUM(AW30:BE30) -> 174187 | CC30: =SUM(BG30:CB30) -> 0 | CK30: =SUM(CD30:CJ30) -> 0 | CV30: 262824
A31: 80 | B31: 7210 | C31: Newark | D31: Marion P. Thomas Charter School | F31: 359 | G31: 153396.63 | N31: =SUM(G31:M31) -> 153396.63 | Q31: 478934.37 | AF31: 2939449 | AH31: 20004 | AV31: =SUM(O31:AU31) -> 3438387.4 | BC31: 350177 | BE31: 100700 | BF31: =SUM(AW31:BE31) -> 450877 | BU31: 27893 | CC31: =SUM(BG31:CB31) -> 27893 | CK31: =SUM(CD31:CJ31) -> 0 | CV31: 450877
A32: 80 | B32: 7280 | C32: Newark | D32: Greater Newark Charter School (formerly Newark, Greater Newark Academy Charter School | F32: 171.3 | G32: 83509.124 | K32: 10000 | N32: =SUM(G32:M32) -> 93509.124 | O32: 1056725 | Q32: 260731.88 | W32: 49386 | AD32: 162776 | AF32: 79312 | AH32: 61517 | AV32: =SUM(O32:AU32) -> 1670447.9 | AZ32: 11663 | BC32: 139803 | BD32: 29249 | BF32: =SUM(AW32:BE32) -> 180715 | BU32: 11176 | CC32: =SUM(BG32:CB32) -> 11176 | CK32: =SUM(CD32:CJ32) -> 0 | CV32: 190715
A33: 80 | B33: 7290 | C33: Newark | D33: New Horizons Community Charter School | F33: 508 | G33: 181243.19 | N33: =SUM(G33:M33) -> 181243.19 | Q33: 565876.81 | AF33: 3775494 | AH33: 144177 | AV33: =SUM(O33:AU33) -> 4485547.8 | BC33: 540738 | BD33: 80906 | BE33: 103550 | BF33: =SUM(AW33:BE33) -> 725194 | BH33: 4174 | CC33: =SUM(BG33:CB33) -> 4174 | CK33: =SUM(CD33:CJ33) -> 0 | CV33: 725194
A34: 80 | B34: 7320 | C34: Newark | D34: North Star Academy Charter School of Newark | F34: 451 | G34: 267018.1 | N34: =SUM(G34:M34) -> 267018.1 | Q34: 833682.9 | AF34: 3761939 | AH34: 212193 | AU34: 90688 | AV34: =SUM(O34:AU34) -> 4898502.9 | BC34: 402521 | BD34: 65204 | BE34: 239596 | BF34: =SUM(AW34:BE34) -> 707321 | CC34: =SUM(BG34:CB34) -> 0 | CK34: =SUM(CD34:CJ34) -> 0 | CV34: 798009
A35: 80 | B35: 7325 | C35: Newark | D35: TEAM Academy Charter School | F35: 467 | G35: 274966.61 | I35: 2699210 | K35: 192750 | N35: =SUM(G35:M35) -> 3166926.6 | Q35: 860282.39 | W35: 129781 | AF35: 634003 | AH35: 124814 | AV35: =SUM(O35:AU35) -> 1748880.4 | BC35: 317673 | BD35: 70308 | BE35: 22954 | BF35: =SUM(AW35:BE35) -> 410935 | CC35: =SUM(BG35:CB35) -> 0 | CK35: =SUM(CD35:CJ35) -> 0 | CV35: 603685
A36: 80 | B36: 7410 | C36: Somers Point | D36: Charter Tech High School | F36: 251 | G36: 1178176.4 | N36: =SUM(G36:M36) -> 1178176.4 | O36: 701118 | Q36: 500183.59 | W36: 159612 | AF36: 194093 | AH36: 92893 | AM36: 46794 | AV36: =SUM(O36:AU36) -> 1694693.6 | AX36: 1000 | BB36: 36052 | BC36: 82902 | BD36: 34529 | BE36: 2585 | BF36: =SUM(AW36:BE36) -> 157068 | CC36: =SUM(BG36:CB36) -> 0 | CK36: =SUM(CD36:CJ36) -> 0 | CV36: 203862
A37: 80 | B37: 7420 | C37: Atlantic City | D37: Oceanside Charter School | F37: 354 | G37: 2605924.2 | N37: =SUM(G37:M37) -> 2605924.2 | Q37: 127850.8 | W37: 195844 | AF37: 1367428 | AG37: 153924 | AH37: 146793 | AV37: =SUM(O37:AU37) -> 1991839.8 | BC37: 282375 | BD37: 76095 | BE37: 43969 | BF37: =SUM(AW37:BE37) -> 402439 | CC37: =SUM(BG37:CB37) -> 0 | CK37: =SUM(CD37:CJ37) -> 0 | CV37: 402439
A38: 80 | B38: 7500 | C38: Hamilton Township | D38: PACE Charter School of Hamilton | F38: 106 | G38: 59449.551 | N38: =SUM(G38:M38) -> 59449.551 | Q38: 172862.45 | AF38: 759274 | AH38: 30272 | AV38: =SUM(O38:AU38) -> 962408.45 | BF38: =SUM(AW38:BE38) -> 0 | CC38: =SUM(BG38:CB38) -> 0 | CK38: =SUM(CD38:CJ38) -> 0
A39: 80 | B39: 7503 | C39: Paterson | D39: Paterson Charter School for Science and Technology | F39: 397 | G39: 197178.29 | N39: =SUM(G39:M39) -> 197178.29 | Q39: 617858.71 | X39: 21258 | AH39: 109658 | AI39: 3238838 | AU39: 2125 | AV39: =SUM(O39:AU39) -> 3989737.7 | BC39: 171638 | BD39: 51728 | BE39: 80825 | BF39: =SUM(AW39:BE39) -> 304191 | CC39: =SUM(BG39:CB39) -> 0 | CK39: =SUM(CD39:CJ39) -> 0 | CV39: 306316
A40: 80 | B40: 7520 | C40: Pleasantville | D40: PleasanTech Academy Charter School | F40: 555 | G40: 623956.68 | N40: =SUM(G40:M40) -> 623956.68 | Q40: 1075634.3 | W40: 171189 | AF40: 3877698 | AH40: 173391 | AU40: 3993 | AV40: =SUM(O40:AU40) -> 5301905.3 | BC40: 274711 | BD40: 156027 | BE40: 154934 | BF40: =SUM(AW40:BE40) -> 585672 | CC40: =SUM(BG40:CB40) -> 0 | CK40: =SUM(CD40:CJ40) -> 0 | CV40: 589665
...

Sheet rev send dist only
G1: Revenue Local | H1: Local | I1: Revenue Local | J1: Total Local Revenues for Charter Distribution Calculation | L1: Revenue State | M1: State | N1: State | O1: Total State Revenue for Charter Distribution Calculation only
A2: CO | B2: DIST | C2: CONAME | D2: DISTNAME | F2: Enrollment | G2: Local Tax Levy | H2: County Tax Levy | I2: Unrestricted Misc Revenues | L2: Core Curriculum Standards Aid | M2: Supplemental Core Curriculum Standards Aid | N2: Stabilization Aid
G3: L150 | H3: L160 | I3: L253 | J3: L273 | L3: L280 | M3: L281 | N3: L340
A4: 1 | B4: 10 | C4: ATLANTIC | D4: ABSECON CITY | E4: 0010-ABSECON CITY | F4: 847 | G4: 8172525 | I4: 71494 | J4: =SUM(G4:I4) -> 8244019 | L4: 344397 | O4: =SUM(L4:N4) -> 344397
A5: 1 | B5: 110 | C5: ATLANTIC | D5: ATLANTIC CITY | E5: 0110-ATLANTIC CITY | F5: 6974 | G5: 93056124 | I5: 2460789 | J5: =SUM(G5:I5) -> 95516913 | O5: =SUM(L5:N5) -> 0
A6: 1 | B6: 120 | C6: ATLANTIC | D6: ATLANTIC CO VOCATIONAL | E6: 0120-ATLANTIC CO VOCATIONAL | F6: 532.5 | H6: 3624000 | I6: 339613 | J6: =SUM(G6:I6) -> 3963613 | L6: 1094318 | N6: 1928 | O6: =SUM(L6:N6) -> 1096246
A7: 1 | B7: 125 | C7: ATLANTIC | D7: ATLANTIC CO SPECIAL SERV | E7: 0125-ATLANTIC CO SPECIAL SERV | F7: 464 | H7: 1854000 | I7: 217626 | J7: =SUM(G7:I7) -> 2071626 | O7: =SUM(L7:N7) -> 0
A8: 1 | B8: 570 | C8: ATLANTIC | D8: BRIGANTINE CITY | E8: 0570-BRIGANTINE CITY | F8: 885 | G8: 13665336 | I8: 189857 | J8: =SUM(G8:I8) -> 13855193 | O8: =SUM(L8:N8) -> 0
A9: 1 | B9: 590 | C9: ATLANTIC | D9: BUENA REGIONAL | E9: 0590-BUENA REGIONAL | F9: 2594 | G9: 11204236 | I9: 241073 | J9: =SUM(G9:I9) -> 11445309 | L9: 9091917 | N9: 299425 | O9: =SUM(L9:N9) -> 9391342
A10: 1 | B10: 960 | C10: ATLANTIC | D10: CORBIN CITY | G10: 763006 | I10: 5382 | J10: =SUM(G10:I10) -> 768388 | L10: 418411 | O10: =SUM(L10:N10) -> 418411
A11: 1 | B11: 1300 | C11: ATLANTIC | D11: EGG HARBOR CITY | E11: 1300-EGG HARBOR CITY | F11: 520 | G11: 1810936 | I11: 72013 | J11: =SUM(G11:I11) -> 1882949 | L11: 2389741 | M11: 394444 | N11: 161942 | O11: =SUM(L11:N11) -> 2946127
A12: 1 | B12: 1310 | C12: ATLANTIC | D12: EGG HARBOR TWP | E12: 1310-EGG HARBOR TWP | F12: 7484 | G12: 50843214 | I12: 1217010 | J12: =SUM(G12:I12) -> 52060224 | L12: 20341417 | O12: =SUM(L12:N12) -> 20341417
A13: 1 | B13: 1410 | C13: ATLANTIC | D13: ESTELL MANOR CITY | E13: 1410-ESTELL MANOR CITY | F13: 218 | G13: 1934320 | I13: 22739 | J13: =SUM(G13:I13) -> 1957059 | L13: 1486698 | O13: =SUM(L13:N13) -> 1486698
A14: 1 | B14: 1540 | C14: ATLANTIC | D14: FOLSOM BORO | E14: 1540-FOLSOM BORO | F14: 392 | G14: 1258908 | I14: 109391 | J14: =SUM(G14:I14) -> 1368299 | L14: 1033381 | N14: 396365 | O14: =SUM(L14:N14) -> 1429746
A15: 1 | B15: 1690 | C15: ATLANTIC | D15: GALLOWAY TWP | E15: 1690-GALLOWAY TWP | F15: 3791 | G15: 26335007 | I15: 354991 | J15: =SUM(G15:I15) -> 26689998 | L15: 13410623 | N15: 446658 | O15: =SUM(L15:N15) -> 13857281
A16: 1 | B16: 1790 | C16: ATLANTIC | D16: GREATER EGG HARBOR REG | E16: 1790-GREATER EGG HARBOR REG | F16: 3913.5 | G16: 25657864 | I16: 711737 | J16: =SUM(G16:I16) -> 26369601 | L16: 17921675 | O16: =SUM(L16:N16) -> 17921675
A17: 1 | B17: 1940 | C17: ATLANTIC | D17: HAMILTON TWP | E17: 1940-HAMILTON TWP | F17: 3225 | G17: 15007035 | I17: 431583 | J17: =SUM(G17:I17) -> 15438618 | L17: 9647111 | O17: =SUM(L17:N17) -> 9647111
A18: 1 | B18: 1960 | C18: ATLANTIC | D18: HAMMONTON TOWN | E18: 1960-HAMMONTON TOWN | F18: 3325.5 | G18: 14521766 | J18: =SUM(G18:I18) -> 14521766 | L18: 4337255 | O18: =SUM(L18:N18) -> 4337255
A19: 1 | B19: 2680 | C19: ATLANTIC | D19: LINWOOD CITY | E19: 2680-LINWOOD CITY | F19: 998 | G19: 9157885 | I19: 143739 | J19: =SUM(G19:I19) -> 9301624 | L19: 969200 | O19: =SUM(L19:N19) -> 969200
A20: 1 | B20: 2780 | C20: ATLANTIC | D20: LONGPORT | G20: 968994 | J20: =SUM(G20:I20) -> 968994 | N20: 71301 | O20: =SUM(L20:N20) -> 71301
A21: 1 | B21: 2910 | C21: ATLANTIC | D21: MAINLAND REGIONAL | E21: 2910-MAINLAND REGIONAL | F21: 1621.5 | G21: 13953238 | I21: 351148 | J21: =SUM(G21:I21) -> 14304386 | L21: 4640595 | O21: =SUM(L21:N21) -> 4640595
A22: 1 | B22: 3020 | C22: ATLANTIC | D22: MARGATE CITY | E22: 3020-MARGATE CITY | F22: 593 | G22: 10173118 | I22: 242872 | J22: =SUM(G22:I22) -> 10415990 | O22: =SUM(L22:N22) -> 0
A23: 1 | B23: 3480 | C23: ATLANTIC | D23: MULLICA TWP | E23: 3480-MULLICA TWP | F23: 744 | G23: 3085814 | I23: 34891 | J23: =SUM(G23:I23) -> 3120705 | L23: 3250225 | O23: =SUM(L23:N23) -> 3250225
A24: 1 | B24: 3720 | C24: ATLANTIC | D24: NORTHFIELD CITY | E24: 3720-NORTHFIELD CITY | F24: 1078 | G24: 7194807 | I24: 89378 | J24: =SUM(G24:I24) -> 7284185 | L24: 1852131 | O24: =SUM(L24:N24) -> 1852131
A25: 1 | B25: 4180 | C25: ATLANTIC | D25: PLEASANTVILLE CITY | E25: 4180-PLEASANTVILLE CITY | F25: 3423 | G25: 6220639 | I25: 367173 | J25: =SUM(G25:I25) -> 6587812 | L25: 25501280 | M25: 2062146 | O25: =SUM(L25:N25) -> 27563426
A26: 1 | B26: 4240 | C26: ATLANTIC | D26: PORT REPUBLIC CITY | E26: 4240-PORT REPUBLIC CITY | F26: 134 | G26: 1229445 | J26: =SUM(G26:I26) -> 1229445 | N26: 771685 | O26: =SUM(L26:N26) -> 771685
A27: 1 | B27: 4800 | C27: ATLANTIC | D27: SOMERS POINT CITY | E27: 4800-SOMERS POINT CITY | F27: 1124 | G27: 7861264 | I27: 126375 | J27: =SUM(G27:I27) -> 7987639 | L27: 1865875 | N27: 495568 | O27: =SUM(L27:N27) -> 2361443
A28: 1 | B28: 5350 | C28: ATLANTIC | D28: VENTNOR CITY | E28: 5350-VENTNOR CITY | F28: 947 | G28: 15597115 | I28: 104111 | J28: =SUM(G28:I28) -> 15701226 | N28: 100000 | O28: =SUM(L28:N28) -> 100000
A29: 1 | B29: 5760 | C29: ATLANTIC | D29: WEYMOUTH TWP | E29: 5760-WEYMOUTH TWP | F29: 258 | G29: 1631399 | J29: =SUM(G29:I29) -> 1631399 | L29: 1422519 | N29: 149066 | O29: =SUM(L29:N29) -> 1571585
A30: 3 | B30: 40 | C30: BERGEN | D30: ALLENDALE BORO | E30: 0040-ALLENDALE BORO | F30: 1032 | G30: 12025265 | J30: =SUM(G30:I30) -> 12025265 | O30: =SUM(L30:N30) -> 0
A31: 3 | B31: 80 | C31: BERGEN | D31: ALPINE BORO | E31: 0080-ALPINE BORO | F31: 136 | G31: 4660644 | I31: 155383 | J31: =SUM(G31:I31) -> 4816027 | O31: =SUM(L31:N31) -> 0
A32: 3 | B32: 285 | C32: BERGEN | D32: BERGEN CO SPECIAL SERVICE | E32: 0285-BERGEN CO SPECIAL SERVICE | F32: 1025 | H32: 5766582 | I32: 928679 | J32: =SUM(G32:I32) -> 6695261 | O32: =SUM(L32:N32) -> 0
A33: 3 | B33: 290 | C33: BERGEN | D33: BERGEN COUNTY VOCATIONAL | E33: 0290-BERGEN COUNTY VOCATIONAL | F33: 2089 | H33: 22567423 | I33: 658561 | J33: =SUM(G33:I33) -> 23225984 | O33: =SUM(L33:N33) -> 0
A34: 3 | B34: 300 | C34: BERGEN | D34: BERGENFIELD BORO | E34: 0300-BERGENFIELD BORO | F34: 3619 | G34: 39876425 | I34: 160847 | J34: =SUM(G34:I34) -> 40037272 | L34: 4868281 | O34: =SUM(L34:N34) -> 4868281
A35: 3 | B35: 440 | C35: BERGEN | D35: BOGOTA BORO | E35: 0440-BOGOTA BORO | F35: 1182 | G35: 10238743 | I35: 15478 | J35: =SUM(G35:I35) -> 10254221 | L35: 2138184 | N35: 848968 | O35: =SUM(L35:N35) -> 2987152
A36: 3 | B36: 740 | C36: BERGEN | D36: CARLSTADT BORO | E36: 0740-CARLSTADT BORO | F36: 549.5 | G36: 7349150 | I36: 51799 | J36: =SUM(G36:I36) -> 7400949 | O36: =SUM(L36:N36) -> 0
A37: 3 | B37: 745 | C37: BERGEN | D37: CARLSTADT-EAST RUTHERFORD | E37: 0745-CARLSTADT-EAST RUTHERFORD | F37: 522.5 | G37: 9850324 | I37: 208302 | J37: =SUM(G37:I37) -> 10058626 | N37: 130865 | O37: =SUM(L37:N37) -> 130865
A38: 3 | B38: 890 | C38: BERGEN | D38: CLIFFSIDE PARK BORO | E38: 0890-CLIFFSIDE PARK BORO | F38: 2617 | G38: 23525325 | J38: =SUM(G38:I38) -> 23525325 | O38: =SUM(L38:N38) -> 0
A39: 3 | B39: 930 | C39: BERGEN | D39: CLOSTER BORO | E39: 0930-CLOSTER BORO | F39: 1183 | G39: 13720585 | I39: 99983 | J39: =SUM(G39:I39) -> 13820568 | O39: =SUM(L39:N39) -> 0
A40: 3 | B40: 990 | C40: BERGEN | D40: CRESSKILL BORO | E40: 0990-CRESSKILL BORO | F40: 1741 | G40: 18521666 | I40: 127890 | J40: =SUM(G40:I40) -> 18649556 | O40: =SUM(L40:N40) -> 0
...

Sheet Master
A1: CO | B1: DIST | C1: CONAME | D1: DISTNAME | E1: L16 | F1: L20 | G1: L24 | H1: L25 | I1: L50 | J1: L60 | K1: L70 | L1: L75 | M1: L80 | N1: L90 | O1: L100 | P1: L140 | Q1: L150 | R1: L196 | S1: L200 | T1: L242 | U1: L251 | V1: L253 | W1: L260 | X1: L280 | Y1: L300 | Z1: L310 | AA1: L320 | AB1: L354 | AC1: L355 | AD1: L361 | AE1: L362 | AF1: L365 | AG1: L370 | AH1: L410 | AI1: L428 | AJ1: L430 | AK1: L431 | AL1: L440 | AM1: L460 | AN1: L500 | AO1: L510 | AP1: L520 | AQ1: L550 | AR1: L551 | AS1: L560 | AT1: L570 | AU1: L580 | AV1: L590 | AW1: L640 | AX1: L643 | AY1: L646 | AZ1: L661 | BA1: L10 | BB1: L45 | BC1: L195 | BD1: L351 | BE1: L356 | BF1: L360 | BG1: L380 | BH1: L400 | BI1: L425 | BJ1: L426 | BK1: L470 | BL1: L540 | BM1: L541 | BN1: L160 | BO1: L210 | BP1: L220 | BQ1: L252 | BR1: L340 | BS1: L350 | BT1: L352 | BU1: L419 | BV1: L420 | BW1: L480 | BX1: L644 | BY1: L648 | BZ1: L230 | CA1: L390 | CB1: L198 | CC1: L647 | CD1: L15 | CE1: L254 | CF1: L281 | CG1: L141 | CH1: L285 | CI1: L641 | CJ1: L121 | CK1: L132 | CL1: L30 | CM1: L353 | CN1: L21 | CO1: L286 | CP1: L429 | CQ1: L511 | CR1: L620 | CS1: L630 | CT1: L427 | CU1: L422 | CV1: L40 | CW1: L421 | CX1: L142 | CY1: L192 | CZ1: L241 | DA1: L17 | DB1: L122 | DC1: L552 | DD1: L287 | DE1: L450 | DF1: L645 | DG1: L490 | DH1: L642 | DI1: L199 | DJ1: L256 | DK1: L258 | DL1: L130 | DM1: L418 | DN1: L191 | DO1: L341 | DP1: L423 | DQ1: L424 | DR1: L22 | DS1: L197 | DT1: L255 | DU1: L271 | DV1: L273 | DW1: L288 | DX1: L135 | DY1: L610 | DZ1: L257 | EA1: L545 | EB1: L123 | EC1: L600 | ED1: L272 | EE1: L455 | EF1: L131 | EG1: L133 | EH1: L134 | EI1: L512 | EJ1: L513
A2: 1 | B2: 10 | C2: ATLANTIC | D2: ABSECON CITY | E2: 35200 | F2: 800 | G2: 22986 | H2: 145750 | I2: 515706 | J2: 720442 | K2: 186685 | L2: 32594 | M2: 38022 | N2: 841 | O2: 258142 | P2: 341 | Q2: 8172525 | R2: 52188 | S2: 52188 | T2: 5834 | U2: 25895 | V2: 71494 | W2: 8327936 | X2: 344397 | Y2: 139638 | Z2: 656131 | AA2: 54842 | AB2: 9607 | AC2: 147092 | AD2: 860745 | AE2: 371687 | AF2: 5397 | AG2: 2589536 | AH2: 10917813 | AI2: 35811 | AJ2: 406322 | AK2: 442133 | AL2: 144655 | AM2: 244547 | AN2: 59446 | AO2: 448648 | AP2: 890781 | AQ2: 1134135 | AR2: 1817 | AS2: 1817 | AT2: 1135952 | AU2: 91394 | AV2: 1227346 | AW2: 1227346 | AX2: 341 | AY2: -341 | AZ2: 14014524
A3: 1 | B3: 110 | C3: ATLANTIC | D3: ATLANTIC CITY | F3: 3780064 | G3: 5258723 | H3: 3595885 | I3: 505000 | J3: 14840068 | K3: 2682970 | M3: 737864 | N3: 30041 | O3: 3450875 | Q3: 93056124 | S3: 11635011 | V3: 2460789 | W3: 107151924 | Y3: 1042992 | Z3: 5304073 | AA3: 910558 | AB3: 202806 | AC3: 749710 | AD3: 6726159 | AE3: 3691269 | AG3: 19698097 | AH3: 126878654 | AJ3: 229570 | AK3: 9461606 | AL3: 3730927 | AM3: 2312622 | AN3: 3125142 | AO3: 9266420 | AP3: 18728026 | AQ3: 11534220 | AT3: 11534220 | AU3: 1034431 | AV3: 12581503 | AW3: 12581503 | AZ3: 176479126 | BA3: 1643557 | BB3: 56839 | BC3: 11635011 | BD3: 34678 | BE3: 525813 | BF3: 510039 | BG3: 28633 | BH3: 28633 | BI3: 5952147 | BJ3: 3279889 | BK3: 97729 | BL3: 3080 | BM3: 9772
A4: 1 | B4: 120 | C4: ATLANTIC | D4: ATLANTIC CO VOCATIONAL | F4: 467596 | G4: 261575 | H4: 477914 | J4: 1207085 | K4: 520694 | L4: 149811 | O4: 670505 | V4: 339613 | W4: 6514876 | X4: 1094318 | Z4: 469855 | AC4: 20527 | AD4: 513045 | AE4: 280300 | AG4: 3750845 | AH4: 10265721 | AJ4: 99216 | AK4: 494426 | AL4: 123727 | AN4: 104821 | AO4: 564317 | AP4: 1282453 | AZ4: 14986022 | BD4: 208499 | BE4: 97652 | BJ4: 395210 | BK4: 260628 | BN4: 3624000 | BO4: 1907500 | BP4: 497926 | BQ4: 145837 | BR4: 1928 | BS4: 878471 | BT4: 186250 | BU4: 223710 | BV4: 223710 | BW4: 75141 | BX4: 1560258 | BY4: 1560258
A5: 1 | B5: 125 | C5: ATLANTIC | D5: ATLANTIC CO SPECIAL SERV | F5: 35722 | I5: 28418 | J5: 64140 | K5: 2413589 | L5: 675000 | M5: 216792 | O5: 3305381 | V5: 217626 | W5: 18544306 | AD5: 776303 | AE5: 559221 | AG5: 1335524 | AH5: 20016499 | AJ5: 201282 | AK5: 201282 | AM5: 27450 | AO5: 27450 | AP5: 267387 | AZ5: 23653407 | BH5: 136669 | BN5: 1854000 | BO5: 15458793 | BP5: 861740 | BU5: 38655 | BV5: 38655 | BZ5: 152147 | CA5: 136669
A6: 1 | B6: 570 | C6: ATLANTIC | D6: BRIGANTINE CITY | G6: 1412365 | H6: 1040602 | I6: 1 | J6: 2452968 | K6: 300627 | O6: 300627 | Q6: 13665336 | V6: 189857 | W6: 13855193 | Y6: 570923 | Z6: 1168580 | AA6: 39048 | AC6: 152382 | AD6: 808384 | AE6: 455929 | AF6: 928 | AG6: 3253000 | AH6: 17108193 | AJ6: 2440 | AK6: 1054983 | AL6: 264884 | AM6: 289968 | AN6: 81077 | AO6: 635929 | AP6: 1703941 | AZ6: 21576929 | BE6: 56826 | BI6: 605498 | BJ6: 447045 | BU6: 13029 | BV6: 13029 | BX6: 11200 | BY6: 11200
