Workbook

Sheet Facility Data
A1: (
A2: SCHOOL: | B2: Staff | C2: Students | D2: Total # of Recyclers | X2: (Original Staff Report)
A3: BALLENGER CREEK ELEMENTARY | B3: 85 | C3: 653 | D3: =B3+C3 -> 738 | H3: 738 | X3: 68
A4: BALLENGER CREEK MIDDLE | B4: 90 | C4: 707 | D4: =B4+C4 -> 797 | H4: 797 | X4: 84
A5: BRUNSWICK ELEMENTARY | B5: 80 | C5: 611 | D5: =B5+C5 -> 691 | H5: 691 | X5: 86
A6: BRUNSWICK HIGH | B6: 90 | C6: 717 | D6: =B6+C6 -> 807 | H6: 807 | X6: 96
A7: BRUNSWICK MIDDLE | B7: 75 | C7: 529 | D7: =B7+C7 -> 604 | H7: 604 | X7: 82
A8: CARROLL MANOR ELEMENTARY | B8: 92 | C8: 552 | D8: =B8+C8 -> 644 | H8: 644 | X8: 97
A9: CATOCTIN HIGH | B9: 100 | C9: 974 | D9: =B9+C9 -> 1074 | H9: 1074 | X9: 120
A10: CENTERVILLE ELEMENTARY | B10: 102 | C10: 926 | D10: =B10+C10 -> 1028 | H10: 1028 | X10: 100
A11: CRESTWOOD MIDDLE | B11: 60 | C11: 513 | D11: =B11+C11 -> 573 | H11: 573 | X11: 75
A12: DEER CROSSING ELEMENTARY | B12: 72 | C12: 668 | D12: =B12+C12 -> 740 | H12: 740 | X12: 78
A13: EMMITSBURG ELEMENTARY | B13: 50 | C13: 292 | D13: =B13+C13 -> 342 | H13: 342 | X13: 53
A14: FREDERICK HIGH | B14: 160 | C14: 1340 | D14: =B14+C14 -> 1500 | H14: 1500 | X14: 158
... A64: YELLOW SPRINGS ELEMENTARY | B64: 51 | C64: 463 | D64: =B64+C64 -> 514 | H64: 514 | X64: 57

Sheet SEPT (REVISED)
A1: Data in the yellow columns shows the pounds of material collected from each facility's RECYCLING dumpster and the date material was picked up.
A3: SEPTEMBER | B3: MON | C3: TUE | D3: WED | E3: THU | F3: FRI | H3: MON | I3: TUE | J3: WED | K3: THU | L3: FRI | N3: MON | O3: TUE | P3: WED | Q3: THU | R3: FRI | T3: MON | U3: TUE | V3: WED | W3: THU | X3: FRI
A4: Date of Recycling Collection | B4: 3 | C4: 4 | D4: 5 | E4: 6 | F4: 7 | H4: 10 | I4: 11 | J4: 12 | K4: 13 | L4: 14 | N4: 17 | O4: 18 | P4: 19 | Q4: 20 | R4: 21 | T4: 24 | U4: 25 | V4: 26 | W4: 27 | X4: 28 | Z4: TOTAL POUNDS COLLECTED | AA4: # of Recyclers | AB4: Pounds Recycled Per Capita
A5: SCHOOL:
A6: ROCK CREEK SCHOOL | C6: 400 | I6: 280 | L6: 1340 | U6: 60 | X6: 220 | Z6: =SUM(B6:Y6) -> 2300 | AA6: 177 | AB6: =Z6/AA6 -> 12.99435
A7: HEATHER RIDGE SCHOOL | C7: 80 | E7: 60 | I7: 140 | K7: 200 | U7: 140 | W7: 140 | Z7: =SUM(B7:Y7) -> 760 | AA7: 121 | AB7: =Z7/AA7 -> 6.2809917
A8: ORCHARD GROVE ELEMENTARY | C8: 200 | F8: 360 | L8: 1900 | N8: 340 | T8: 140 | X8: 280 | Z8: =SUM(B8:Y8) -> 3220 | AA8: 695 | AB8: =Z8/AA8 -> 4.6330935
A9: YELLOW SPRINGS ELEMENTARY | C9: 1140 | N9: 380 | T9: 440 | Z9: =SUM(B9:Y9) -> 1960 | AA9: 514 | AB9: =Z9/AA9 -> 3.8132296
A10: MONOCACY ELEMENTARY | C10: 80 | I10: 260 | O10: 1920 | U10: 120 | Z10: =SUM(B10:Y10) -> 2380 | AA10: 702 | AB10: =Z10/AA10 -> 3.3903134
A11: THOMAS JOHNSON HIGH | C11: 340 | E11: 1520 | F11: 420 | I11: 460 | L11: 340 | N11: 920 | U11: 300 | W11: 820 | X11: 260 | Z11: =SUM(B11:Y11) -> 5380 | AA11: 1632 | AB11: =Z11/AA11 -> 3.2965686
A12: WOODSBORO ELEMENTARY | E12: 340 | K12: 200 | W12: 140 | Z12: =SUM(B12:Y12) -> 680 | AA12: 213 | AB12: =Z12/AA12 -> 3.1924883
A13: MIDDLETOWN MIDDLE | C13: 40 | E13: 1740 | K13: 280 | N13: 300 | T13: 280 | W13: 140 | Z13: =SUM(B13:Y13) -> 2780 | AA13: 914 | AB13: =Z13/AA13 -> 3.0415755
A14: WOLFSVILLE ELEMENTARY | E14: 120 | K14: 160 | W14: 300 | Z14: =SUM(B14:Y14) -> 580 | AA14: 209 | AB14: =Z14/AA14 -> 2.7751196
A15: NEW MIDWAY ELEMENTARY | E15: 200 | K15: 140 | W15: 120 | Z15: =SUM(B15:Y15) -> 460 | AA15: 166 | AB15: =Z15/AA15 -> 2.7710843
A16: CENTERVILLE ELEMENTARY | C16: 60 | F16: 120 | I16: 200 | L16: 1900 | O16: 180 | U16: 20 | X16: 360 | Z16: =SUM(B16:Y16) -> 2840 | AA16: 1028 | AB16: =Z16/AA16 -> 2.7626459
A17: SABILLASVILLE ELEMENTARY | E17: 40 | K17: 240 | W17: 120 | Z17: =SUM(B17:Y17) -> 400 | AA17: 157 | AB17: =Z17/AA17 -> 2.5477707
A18: N FREDERICK ELEMENTARY | C18: 680 | I18: 380 | U18: 640 | Z18: =SUM(B18:Y18) -> 1700 | AA18: 693 | AB18: =Z18/AA18 -> 2.4531025
A19: WAVERLY ELEMENTARY | F19: 400 | I19: 320 | L19: 360 | U19: 260 | X19: 160 | Z19: =SUM(B19:Y19) -> 1500 | AA19: 637 | AB19: =Z19/AA19 -> 2.3547881
A20: FREDERICK HIGH | C20: 720 | E20: 80 | F20: 60 | J20: 40 | L20: 120 | N20: 200 | P20: 380 | T20: 20 | V20: 80 | X20: 1720 | Z20: =SUM(B20:Y20) -> 3420 | AA20: 1500 | AB20: =Z20/AA20 -> 2.28
A21: NEW MARKET MIDDLE | C21: 200 | F21: 420 | I21: 40 | L21: 160 | O21: 180 | U21: 200 | X21: 100 | Z21: =SUM(B21:Y21) -> 1300 | AA21: 581 | AB21: =Z21/AA21 -> 2.2375215
A22: LIBERTY ELEMENTARY | E22: 280 | K22: 140 | W22: 320 | Z22: =SUM(B22:Y22) -> 740 | AA22: 334 | AB22: =Z22/AA22 -> 2.2155689
A23: KEMPTOWN ELEMENTARY | F23: 180 | L23: 420 | X23: 320 | Z23: =SUM(B23:Y23) -> 920 | AA23: 442 | AB23: =Z23/AA23 -> 2.081448
A24: MONOCACY MIDDLE | C24: 180 | F24: 480 | I24: 300 | L24: 260 | U24: 100 | X24: 220 | Z24: =SUM(B24:Y24) -> 1540 | AA24: 816 | AB24: =Z24/AA24 -> 1.8872549
A25: GREEN VALLEY ELEMENTARY | F25: 300 | L25: 320 | X25: 260 | Z25: =SUM(B25:Y25) -> 880 | AA25: 469 | AB25: =Z25/AA25 -> 1.8763326
A26: URBANA HIGH | C26: 300 | E26: 220 | F26: 140 | J26: 180 | L26: 540 | N26: 280 | P26: 420 | T26: 240 | V26: 220 | X26: 460 | Z26: =SUM(B26:Y26) -> 3000 | AA26: 1609 | AB26: =Z26/AA26 -> 1.8645121
A27: CATOCTIN HIGH | C27: 640 | E27: 140 | K27: 360 | N27: 220 | T27: 180 | W27: 460 | Z27: =SUM(B27:Y27) -> 2000 | AA27: 1074 | AB27: =Z27/AA27 -> 1.8621974
A28: BALLENGER CREEK ELEMENTARY | C28: 280 | E28: 140 | K28: 480 | N28: 300 | T28: 60 | W28: 100 | Z28: =SUM(B28:Y28) -> 1360 | AA28: 738 | AB28: =Z28/AA28 -> 1.8428184
A29: OAKDALE MIDDLE | C29: 400 | F29: 220 | I29: 320 | L29: 180 | O29: 160 | U29: 0 | Z29: =SUM(B29:Y29) -> 1280 | AA29: 697 | AB29: =Z29/AA29 -> 1.8364419
A30: EMMITSBURG ELEMENTARY | E30: 320 | K30: 180 | W30: 120 | Z30: =SUM(B30:Y30) -> 620 | AA30: 342 | AB30: =Z30/AA30 -> 1.8128655
A31: MIDDLETOWN HIGH | C31: 700 | E31: 240 | K31: 420 | N31: 480 | T31: 360 | W31: 180 | Z31: =SUM(B31:Y31) -> 2380 | AA31: 1325 | AB31: =Z31/AA31 -> 1.7962264
A32: MIDDLETOWN ELEMENTARY | C32: 200 | N32: 100 | T32: 660 | Z32: =SUM(B32:Y32) -> 960 | AA32: 537 | AB32: =Z32/AA32 -> 1.7877095
A33: WHITTIER ELEMENTARY | C33: 660 | N33: 420 | T33: 460 | Z33: =SUM(B33:Y33) -> 1540 | AA33: 865 | AB33: =Z33/AA33 -> 1.7803468
A34: THOMAS JOHNSON MIDDLE | C34: 500 | F34: 100 | L34: 240 | N34: 40 | T34: 80 | X34: 80 | Z34: =SUM(B34:Y34) -> 1040 | AA34: 630 | AB34: =Z34/AA34 -> 1.6507937
A35: PARKWAY ELEMENTARY | C35: 80 | N35: 240 | T35: 160 | Z35: =SUM(B35:Y35) -> 480 | AA35: 302 | AB35: =Z35/AA35 -> 1.589404
A36: THURMONT PRIMARY | E36: 520 | K36: 120 | W36: 60 | Z36: =SUM(B36:Y36) -> 700 | AA36: 442 | AB36: =Z36/AA36 -> 1.5837104
A37: WINDSOR KNOLLS MIDDLE | F37: 100 | I37: 200 | L37: 160 | O37: 100 | U37: 660 | X37: 280 | Z37: =SUM(B37:Y37) -> 1500 | AA37: 954 | AB37: =Z37/AA37 -> 1.572327
A38: CRESTWOOD MIDDLE | E38: 360 | K38: 280 | W38: 240 | Z38: =SUM(B38:Y38) -> 880 | AA38: 573 | AB38: =Z38/AA38 -> 1.5357766
A39: HILLCREST ELEMENTARY | C39: 180 | F39: 200 | I39: 280 | L39: 300 | U39: 260 | X39: 280 | Z39: =SUM(B39:Y39) -> 1500 | AA39: 998 | AB39: =Z39/AA39 -> 1.503006
A40: THURMONT ELEMENTARY | E40: 280 | K40: 160 | W40: 120 | Z40: =SUM(B40:Y40) -> 560 | AA40: 381 | AB40: =Z40/AA40 -> 1.4698163
A41: TUSCARORA HIGH | C41: 380 | E41: 340 | K41: 320 | N41: 460 | T41: 280 | W41: 600 | Z41: =SUM(B41:Y41) -> 2380 | AA41: 1669 | AB41: =Z41/AA41 -> 1.4260036
...

Sheet OCT 12
A1: Data in the yellow columns shows the pounds of material collected from each facility's RECYCLING dumpster and the date material was picked up.
A3: OCTOBER | B3: MON | C3: TUE | D3: WED | E3: THU | F3: FRI | H3: MON | I3: TUE | J3: WED | K3: THU | L3: FRI | N3: MON | O3: TUE | P3: WED | Q3: THU | R3: FRI | T3: MON | U3: TUE | V3: WED | W3: THU | X3: FRI | Z3: MON | AA3: TUE | AB3: WED
A4: Date of Collection | B4: 1 | C4: 2 | D4: 3 | E4: 4 | F4: 5 | H4: 8 | I4: 9 | J4: 10 | K4: 11 | L4: 12 | N4: 15 | O4: 16 | P4: 17 | Q4: 18 | R4: 19 | T4: 22 | U4: 23 | V4: 24 | W4: 25 | X4: 26 | Z4: 29 | AA4: 30 | AB4: 31 | AD4: TOTAL COLLECTED | AE4: # of Recyclers | AF4: Pounds Recycled Per Capita
A5: SCHOOL:
A6: EMMITSBURG ELEMENTARY | E6: 520 | K6: 1080 | Q6: 40 | W6: 1240 | AD6: =SUM(B6:AC6) -> 2880 | AE6: 342 | AF6: =AD6/AE6 -> 8.4210526
A7: WOODSBORO ELEMENTARY | E7: 1040 | K7: 220 | Q7: 160 | W7: 160 | AD7: =SUM(B7:AC7) -> 1580 | AE7: 213 | AF7: =AD7/AE7 -> 7.4178404
A8: URBANA ELEMENTARY | B8: 2280 | H8: 160 | N8: 320 | T8: 420 | Z8: 1900 | AD8: =SUM(B8:AC8) -> 5080 | AE8: 820 | AF8: =AD8/AE8 -> 6.195122
A9: CARROLL MANOR ELEMENTARY | E9: 1680 | K9: 400 | Q9: 1500 | W9: 280 | AD9: =SUM(B9:AC9) -> 3860 | AE9: 644 | AF9: =AD9/AE9 -> 5.9937888
A10: MONOCACY ELEMENTARY | C10: 320 | X10: 1980 | AB10: 1900 | AD10: =SUM(B10:AC10) -> 4200 | AE10: 702 | AF10: =AD10/AE10 -> 5.982906
A11: ORCHARD GROVE ELEMENTARY | B11: 40 | F11: 1900 | H11: 420 | K11: 400 | N11: 220 | Q11: 320 | T11: 120 | W11: 340 | Z11: 260 | AD11: =SUM(B11:AC11) -> 4020 | AE11: 695 | AF11: =AD11/AE11 -> 5.7841727
A12: THURMONT PRIMARY | E12: 1660 | K12: 360 | Q12: 260 | W12: 220 | AD12: =SUM(B12:AC12) -> 2500 | AE12: 442 | AF12: =AD12/AE12 -> 5.6561086
A13: BALLENGER CREEK ELEMENTARY | B13: 60 | E13: 480 | H13: 140 | K13: 520 | N13: 160 | Q13: 380 | T13: 1640 | W13: 200 | Z13: 260 | AD13: =SUM(B13:AC13) -> 3840 | AE13: 738 | AF13: =AD13/AE13 -> 5.203252
A14: URBANA MIDDLE | C14: 160 | F14: 120 | L14: 80 | O14: 1820 | R14: 60 | U14: 20 | X14: 1720 | Z14: 200 | AD14: =SUM(B14:AC14) -> 4180 | AE14: 830 | AF14: =AD14/AE14 -> 5.0361446
A15: THOMAS JOHNSON HIGH | B15: 1220 | C15: 260 | E15: 1180 | F15: 480 | H15: 1340 | L15: 500 | N15: 60 | O15: 400 | Q15: 740 | R15: 440 | U15: 100 | W15: 520 | X15: 140 | Z15: 60 | AB15: 700 | AD15: =SUM(B15:AC15) -> 8140 | AE15: 1632 | AF15: =AD15/AE15 -> 4.9877451
A16: NEW MIDWAY ELEMENTARY | E16: 280 | K16: 140 | Q16: 20 | U16: 220 | W16: 160 | AD16: =SUM(B16:AC16) -> 820 | AE16: 166 | AF16: =AD16/AE16 -> 4.939759
A17: KEMPTOWN ELEMENTARY | F17: 260 | L17: 180 | R17: 380 | X17: 1360 | AD17: =SUM(B17:AC17) -> 2180 | AE17: 442 | AF17: =AD17/AE17 -> 4.9321267
A18: ROCK CREEK SCHOOL | C18: 40 | F18: 240 | L18: 260 | R18: 20 | U18: 20 | X18: 140 | AB18: 80 | AD18: =SUM(B18:AC18) -> 800 | AE18: 177 | AF18: =AD18/AE18 -> 4.519774
A19: LINCOLN ELEMENTARY | B19: 260 | H19: 340 | N19: 340 | T19: 220 | Z19: 1340 | AD19: =SUM(B19:AC19) -> 2500 | AE19: 586 | AF19: =AD19/AE19 -> 4.2662116
A20: OAKDALE ELEMENTARY | C20: 320 | O20: 500 | U20: 1700 | AB20: 280 | AD20: =SUM(B20:AC20) -> 2800 | AE20: 707 | AF20: =AD20/AE20 -> 3.960396
A21: N FREDERICK ELEMENTARY | C21: 540 | O21: 480 | U21: 500 | AB21: 1180 | AD21: =SUM(B21:AC21) -> 2700 | AE21: 693 | AF21: =AD21/AE21 -> 3.8961039
A22: HEATHER RIDGE SCHOOL | C22: 80 | E22: 0 | K22: 60 | Q22: 20 | U22: 40 | W22: 140 | AB22: 120 | AD22: =SUM(B22:AC22) -> 460 | AE22: 121 | AF22: =AD22/AE22 -> 3.8016529
A23: THURMONT MIDDLE | B23: 20 | E23: 20 | H23: 1540 | K23: 160 | N23: 140 | Q23: 100 | T23: 80 | W23: 200 | Z23: 340 | AD23: =SUM(B23:AC23) -> 2600 | AE23: 693 | AF23: =AD23/AE23 -> 3.7518038
A24: MIDDLETOWN HIGH | B24: 300 | E24: 320 | H24: 300 | K24: 320 | N24: 380 | Q24: 1580 | T24: 660 | W24: 300 | Z24: 620 | AD24: =SUM(B24:AC24) -> 4780 | AE24: 1325 | AF24: =AD24/AE24 -> 3.6075472
A25: SPRING RIDGE ELEMENTARY | E25: 80 | H25: 120 | K25: 100 | N25: 1300 | Q25: 180 | T25: 20 | W25: 180 | AD25: =SUM(B25:AC25) -> 1980 | AE25: 563 | AF25: =AD25/AE25 -> 3.5168739
A26: WHITTIER ELEMENTARY | B26: 660 | H26: 620 | N26: 320 | T26: 560 | Z26: 740 | AD26: =SUM(B26:AC26) -> 2900 | AE26: 865 | AF26: =AD26/AE26 -> 3.3526012
A27: CATOCTIN HIGH | B27: 380 | E27: 340 | H27: 540 | K27: 700 | N27: 300 | Q27: 440 | T27: 220 | W27: 420 | Z27: 180 | AD27: =SUM(B27:AC27) -> 3520 | AE27: 1074 | AF27: =AD27/AE27 -> 3.2774674
A28: W FREDERIC MIDDLE | B28: 120 | F28: 1820 | H28: 40 | L28: 260 | N28: 100 | R28: 220 | T28: 120 | X28: 160 | Z28: 60 | AD28: =SUM(B28:AC28) -> 2900 | AE28: 900 | AF28: =AD28/AE28 -> 3.2222222
A29: PARKWAY ELEMENTARY | B29: 240 | H29: 180 | N29: 280 | T29: 200 | Z29: 60 | AD29: =SUM(B29:AC29) -> 960 | AE29: 302 | AF29: =AD29/AE29 -> 3.1788079
A30: NEW MARKET MIDDLE | C30: 80 | F30: 160 | L30: 240 | O30: 280 | R30: 400 | U30: 100 | X30: 240 | AB30: 320 | AD30: =SUM(B30:AC30) -> 1820 | AE30: 581 | AF30: =AD30/AE30 -> 3.1325301
A31: WINDSOR KNOLLS MIDDLE | C31: 1760 | F31: 140 | L31: 160 | O31: 100 | R31: 360 | U31: 40 | X31: 140 | Z31: 280 | AD31: =SUM(B31:AC31) -> 2980 | AE31: 954 | AF31: =AD31/AE31 -> 3.1236897
A32: TUSCARORA ELEMENTARY | B32: 180 | E32: 420 | H32: 400 | K32: 300 | N32: 200 | Q32: 380 | T32: 180 | W32: 40 | Z32: 400 | AD32: =SUM(B32:AC32) -> 2500 | AE32: 839 | AF32: =AD32/AE32 -> 2.9797378
A33: WAVERLY ELEMENTARY | C33: 220 | F33: 420 | L33: 80 | R33: 280 | U33: 40 | X33: 400 | AB33: 400 | AD33: =SUM(B33:AC33) -> 1840 | AE33: 637 | AF33: =AD33/AE33 -> 2.88854
A34: HILLCREST ELEMENTARY | C34: 140 | F34: 1560 | L34: 300 | R34: 340 | U34: 160 | X34: 240 | AB34: 140 | AD34: =SUM(B34:AC34) -> 2880 | AE34: 998 | AF34: =AD34/AE34 -> 2.8857715
A35: WALKERSVILLE HIGH | B35: 1660 | E35: 120 | H35: 480 | K35: 160 | N35: 260 | Q35: 280 | T35: 220 | W35: 40 | Z35: 260 | AD35: =SUM(B35:AC35) -> 3480 | AE35: 1227 | AF35: =AD35/AE35 -> 2.8361858
A36: YELLOW SPRINGS ELEMENTARY | B36: 360 | H36: 300 | N36: 60 | T36: 240 | Z36: 420 | AD36: =SUM(B36:AC36) -> 1380 | AE36: 514 | AF36: =AD36/AE36 -> 2.6848249
A37: VALLEY ELEMENTARY | B37: 220 | H37: 360 | N37: 260 | T37: 140 | Z37: 300 | AD37: =SUM(B37:AC37) -> 1280 | AE37: 488 | AF37: =AD37/AE37 -> 2.6229508
A38: MIDDLETOWN ELEMENTARY | B38: 420 | H38: 120 | N38: 260 | T38: 280 | Z38: 280 | AD38: =SUM(B38:AC38) -> 1360 | AE38: 537 | AF38: =AD38/AE38 -> 2.5325885
A39: MYERSVILLE ELEMENTARY | E39: 400 | K39: 320 | Q39: 140 | W39: 160 | AD39: =SUM(B39:AC39) -> 1020 | AE39: 419 | AF39: =AD39/AE39 -> 2.4343675
A40: SABILLASVILLE ELEMENTARY | E40: 60 | K40: 20 | Q40: 80 | W40: 220 | AD40: =SUM(B40:AC40) -> 380 | AE40: 157 | AF40: =AD40/AE40 -> 2.4203822
A41: LIBERTY ELEMENTARY | E41: 280 | K41: 160 | Q41: 200 | W41: 160 | AD41: =SUM(B41:AC41) -> 800 | AE41: 334 | AF41: =AD41/AE41 -> 2.3952096
...

Sheet NOV 12
A1: Data in the yellow columns shows the pounds of material collected from each facility's RECYCLING dumpster and the date material was picked up.
A3: NOVEMBER | B3: MON | C3: TUE | D3: WED | E3: THU | F3: FRI | H3: MON | I3: TUE | J3: WED | K3: THU | L3: FRI | N3: MON | O3: TUE | P3: WED | Q3: THU | R3: FRI | T3: MON | U3: TUE | V3: WED | W3: THU | X3: FRI | Z3: MON | AA3: TUE | AB3: WED | AC3: THU | AD3: FRI
A4: Date of Collection | E4: 1 | F4: 2 | H4: 5 | I4: 6 | J4: 7 | K4: 8 | L4: 9 | N4: 12 | O4: 13 | P4: 14 | Q4: 15 | R4: 16 | T4: 19 | U4: 20 | V4: 21 | W4: 22 | X4: 23 | Z4: 26 | AA4: 27 | AB4: 28 | AC4: 29 | AD4: 30 | AF4: TOTAL COLLECTED | AG4: # of Recyclers | AH4: Pounds Recycled Per Capita
A5: SCHOOL:
A6: EMMITSBURG ELEMENTARY | E6: 1660 | K6: 220 | Q6: 240 | X6: 280 | AC6: 1240 | AF6: =SUM(E6:AE6) -> 3640 | AG6: 342 | AH6: =AF6/AG6 -> 10.643275
A7: HEATHER RIDGE SCHOOL | E7: 60 | I7: 220 | K7: 60 | Q7: 40 | U7: 0 | X7: 180 | AA7: 40 | AC7: 140 | AF7: =SUM(E7:AE7) -> 740 | AG7: 121 | AH7: =AF7/AG7 -> 6.1157025
A8: LIBERTY ELEMENTARY | E8: 1280 | K8: 120 | Q8: 260 | X8: 140 | AC8: 160 | AF8: =SUM(E8:AE8) -> 1960 | AG8: 334 | AH8: =AF8/AG8 -> 5.8682635
A9: MONOCACY ELEMENTARY | I9: 100 | U9: 560 | AA9: 1120 | AD9: 1980 | AF9: =SUM(E9:AE9) -> 3760 | AG9: 702 | AH9: =AF9/AG9 -> 5.3561254
A10: ROCK CREEK SCHOOL | F10: 160 | I10: 160 | L10: 140 | R10: 120 | U10: 100 | AA10: 20 | AD10: 140 | AF10: =SUM(E10:AE10) -> 840 | AG10: 177 | AH10: =AF10/AG10 -> 4.7457627
A11: URBANA MIDDLE | F11: 340 | I11: 20 | L11: 100 | R11: 20 | U11: 1660 | AA11: 20 | AD11: 1720 | AF11: =SUM(E11:AE11) -> 3880 | AG11: 830 | AH11: =AF11/AG11 -> 4.6746988
A12: KEMPTOWN ELEMENTARY | F12: 320 | L12: 100 | R12: 260 | AD12: 1360 | AF12: =SUM(E12:AE12) -> 2040 | AG12: 442 | AH12: =AF12/AG12 -> 4.6153846
A13: GREEN VALLEY ELEMENTARY | F13: 240 | L13: 1420 | R13: 200 | AD13: 240 | AF13: =SUM(E13:AE13) -> 2100 | AG13: 469 | AH13: =AF13/AG13 -> 4.4776119
A14: BALLENGER CREEK ELEMENTARY | E14: 720 | H14: 40 | K14: 1620 | Q14: 220 | T14: 260 | X14: 180 | AC14: 200 | AF14: =SUM(E14:AE14) -> 3240 | AG14: 738 | AH14: =AF14/AG14 -> 4.3902439
A15: MIDDLETOWN PRIMARY | E15: 360 | K15: 1500 | Q15: 300 | X15: 120 | AC15: 60 | AF15: =SUM(E15:AE15) -> 2340 | AG15: 541 | AH15: =AF15/AG15 -> 4.3253235
A16: SABILLASVILLE ELEMENTARY | E16: 200 | K16: 40 | Q16: 80 | X16: 100 | AC16: 220 | AF16: =SUM(E16:AE16) -> 640 | AG16: 157 | AH16: =AF16/AG16 -> 4.0764331
A17: MYERSVILLE ELEMENTARY | E17: 560 | K17: 220 | Q17: 300 | X17: 400 | AC17: 160 | AF17: =SUM(E17:AE17) -> 1640 | AG17: 419 | AH17: =AF17/AG17 -> 3.9140811
A18: WAVERLY ELEMENTARY | F18: 160 | I18: 1300 | L18: 200 | R18: 60 | U18: 220 | AA18: 40 | AD18: 400 | AF18: =SUM(E18:AE18) -> 2380 | AG18: 637 | AH18: =AF18/AG18 -> 3.7362637
A19: NEW MIDWAY ELEMENTARY | E19: 60 | K19: 120 | Q19: 180 | X19: 180 | AC19: 80 | AF19: =SUM(E19:AE19) -> 620 | AG19: 166 | AH19: =AF19/AG19 -> 3.7349398
A20: URBANA HIGH | F20: 280 | H20: 520 | J20: 280 | L20: 420 | P20: 860 | R20: 380 | T20: 2120 | V20: 480 | AB20: 220 | AD20: 320 | AF20: =SUM(E20:AE20) -> 5880 | AG20: 1609 | AH20: =AF20/AG20 -> 3.6544438
A21: ORCHARD GROVE ELEMENTARY | E21: 460 | H21: 400 | K21: 220 | Q21: 320 | T21: 360 | X21: 240 | Z21: 120 | AC21: 340 | AF21: =SUM(E21:AE21) -> 2460 | AG21: 695 | AH21: =AF21/AG21 -> 3.5395683
A22: WHITTIER ELEMENTARY | H22: 700 | T22: 1740 | Z22: 560 | AF22: =SUM(E22:AE22) -> 3000 | AG22: 865 | AH22: =AF22/AG22 -> 3.4682081
A23: THURMONT PRIMARY | E23: 240 | K23: 300 | Q23: 480 | X23: 260 | AC23: 220 | AF23: =SUM(E23:AE23) -> 1500 | AG23: 442 | AH23: =AF23/AG23 -> 3.3936652
A24: THOMAS JOHNSON MIDDLE | E24: 460 | H24: 140 | K24: 80 | Q24: 980 | T24: 0 | X24: 100 | Z24: 160 | AC24: 180 | AF24: =SUM(E24:AE24) -> 2100 | AG24: 630 | AH24: =AF24/AG24 -> 3.3333333
A25: CRESTWOOD MIDDLE | E25: 580 | K25: 320 | Q25: 460 | X25: 360 | AC25: 140 | AF25: =SUM(E25:AE25) -> 1860 | AG25: 573 | AH25: =AF25/AG25 -> 3.2460733
A26: TWIN RIDGE ELEMENTARY | F26: 540 | L26: 20 | R26: 1220 | AD26: 140 | AF26: =SUM(E26:AE26) -> 1920 | AG26: 598 | AH26: =AF26/AG26 -> 3.2107023
A27: MONOCACY MIDDLE | F27: 180 | I27: 340 | L27: 1200 | R27: 280 | U27: 140 | AA27: 180 | AD27: 200 | AF27: =SUM(E27:AE27) -> 2520 | AG27: 816 | AH27: =AF27/AG27 -> 3.0882353
A28: CATOCTIN HIGH | E28: 340 | H28: 340 | K28: 700 | Q28: 600 | T28: 360 | X28: 320 | Z28: 220 | AC28: 420 | AF28: =SUM(E28:AE28) -> 3300 | AG28: 1074 | AH28: =AF28/AG28 -> 3.0726257
A29: WOODSBORO ELEMENTARY | E29: 220 | K29: 60 | Q29: 80 | X29: 120 | AC29: 160 | AF29: =SUM(E29:AE29) -> 640 | AG29: 213 | AH29: =AF29/AG29 -> 3.0046948
A30: OAKDALE ELEMENTARY | I30: 100 | U30: 280 | AA30: 1700 | AF30: =SUM(E30:AE30) -> 2080 | AG30: 707 | AH30: =AF30/AG30 -> 2.9420085
A31: THURMONT ELEMENTARY | E31: 260 | K31: 160 | Q31: 80 | X31: 320 | AC31: 220 | AF31: =SUM(E31:AE31) -> 1040 | AG31: 381 | AH31: =AF31/AG31 -> 2.7296588
A32: THOMAS JOHNSON HIGH | E32: 820 | F32: 280 | H32: 320 | I32: 400 | L32: 380 | Q32: 60 | R32: 200 | T32: 740 | U32: 300 | X32: 60 | Z32: 80 | AA32: 100 | AC32: 520 | AD32: 140 | AF32: =SUM(E32:AE32) -> 4400 | AG32: 1632 | AH32: =AF32/AG32 -> 2.6960784
A33: PARKWAY ELEMENTARY | H33: 300 | T33: 300 | Z33: 200 | AF33: =SUM(E33:AE33) -> 800 | AG33: 302 | AH33: =AF33/AG33 -> 2.6490066
A34: NEW MARKET MIDDLE | F34: 320 | I34: 200 | L34: 260 | R34: 180 | U34: 180 | AA34: 100 | AD34: 240 | AF34: =SUM(E34:AE34) -> 1480 | AG34: 581 | AH34: =AF34/AG34 -> 2.5473322
A35: LEWISTOWN ELEMENTARY | E35: 140 | K35: 20 | Q35: 160 | X35: 160 | AC35: 160 | AF35: =SUM(E35:AE35) -> 640 | AG35: 274 | AH35: =AF35/AG35 -> 2.3357664
A36: WOLFSVILLE ELEMENTARY | E36: 80 | K36: 140 | Q36: 80 | X36: 40 | AC36: 140 | AF36: =SUM(E36:AE36) -> 480 | AG36: 209 | AH36: =AF36/AG36 -> 2.2966507
A37: BRUNSWICK HIGH | E37: 800 | H37: 240 | T37: 280 | Z37: 420 | AF37: =SUM(E37:AE37) -> 1740 | AG37: 807 | AH37: =AF37/AG37 -> 2.1561338
A38: MIDDLETOWN HIGH | E38: 320 | H38: 360 | K38: 40 | Q38: 260 | T38: 520 | X38: 240 | Z38: 660 | AC38: 300 | AF38: =SUM(E38:AE38) -> 2700 | AG38: 1325 | AH38: =AF38/AG38 -> 2.0377358
A39: CENTERVILLE ELEMENTARY | F39: 420 | I39: 240 | L39: 160 | R39: 400 | U39: 620 | AA39: 180 | AD39: 20 | AF39: =SUM(E39:AE39) -> 2040 | AG39: 1028 | AH39: =AF39/AG39 -> 1.9844358
A40: TUSCARORA ELEMENTARY | E40: 360 | H40: 300 | K40: 140 | Q40: 200 | T40: 280 | X40: 320 | AC40: 40 | AF40: =SUM(E40:AE40) -> 1640 | AG40: 839 | AH40: =AF40/AG40 -> 1.954708
A41: N FREDERICK ELEMENTARY | I41: 340 | U41: 480 | AA41: 500 | AF41: =SUM(E41:AE41) -> 1320 | AG41: 693 | AH41: =AF41/AG41 -> 1.9047619
...

Sheet DEC 12
A1: Data in the yellow columns shows the pounds of material collected from each facility's RECYCLING dumpster and the date material was picked up.
A3: DECEMBER | B3: MON | C3: TUE | D3: WED | E3: THU | F3: FRI | H3: MON | I3: TUE | J3: WED | K3: THU | L3: FRI | N3: MON | O3: TUE | P3: WED | Q3: THU | R3: FRI | T3: MON | U3: TUE | V3: WED | W3: THU | X3: FRI | Z3: MON
A4: Date of Collection | B4: 3 | C4: 4 | D4: 5 | E4: 6 | F4: 7 | H4: 10 | I4: 11 | J4: 12 | K4: 13 | L4: 14 | N4: 17 | O4: 18 | P4: 19 | Q4: 20 | R4: 21 | T4: 24 | U4: 25 | V4: 26 | W4: 27 | X4: 28 | Z4: 31 | AB4: TOTAL COLLECTED | AC4: # of Recyclers | AD4: Pounds Recycled Per Capita
A5: SCHOOL:
A6: ROCK CREEK SCHOOL | C6: 160 | F6: 140 | I6: 160 | L6: 260 | R6: 220 | X6: 260 | AB6: =SUM(B6:AA6) -> 1200 | AC6: 177 | AD6: =AB6/AC6 -> 6.779661
A7: WOODSBORO ELEMENTARY | E7: 60 | K7: 220 | Q7: 880 | W7: 100 | AB7: =SUM(B7:AA7) -> 1260 | AC7: 213 | AD7: =AB7/AC7 -> 5.915493
A8: LIBERTY ELEMENTARY | E8: 120 | K8: 160 | Q8: 1320 | W8: 120 | AB8: =SUM(B8:AA8) -> 1720 | AC8: 334 | AD8: =AB8/AC8 -> 5.1497006
A9: HEATHER RIDGE SCHOOL | C9: 220 | E9: 60 | I9: 40 | K9: 60 | Q9: 120 | T9: 100 | W9: 20 | AB9: =SUM(B9:AA9) -> 620 | AC9: 121 | AD9: =AB9/AC9 -> 5.1239669
A10: EMMITSBURG ELEMENTARY | E10: 220 | K10: 1080 | Q10: 120 | W10: 320 | AB10: =SUM(B10:AA10) -> 1740 | AC10: 342 | AD10: =AB10/AC10 -> 5.0877193
A11: BALLENGER CREEK ELEMENTARY | B11: 40 | E11: 1620 | H11: 160 | K11: 520 | N11: 160 | Q11: 560 | T11: 260 | W11: 200 | Z11: 20 | AB11: =SUM(B11:AA11) -> 3540 | AC11: 738 | AD11: =AB11/AC11 -> 4.796748
A12: SPRING RIDGE ELEMENTARY | B12: 180 | E12: 140 | H12: 180 | K12: 100 | N12: 1300 | Q12: 140 | T12: 260 | W12: 80 | Z12: 260 | AB12: =SUM(B12:AA12) -> 2640 | AC12: 563 | AD12: =AB12/AC12 -> 4.6891652
A13: THOMAS JOHNSON HIGH | B13: 320 | C13: 400 | E13: 380 | F13: 380 | H13: 60 | I13: 320 | K13: 940 | L13: 500 | N13: 60 | O13: 400 | Q13: 680 | R13: 680 | T13: 100 | U13: 380 | W13: 640 | X13: 480 | Z13: 60 | AB13: =SUM(B13:AA13) -> 6780 | AC13: 1632 | AD13: =AB13/AC13 -> 4.1544118
A14: GREEN VALLEY ELEMENTARY | F14: 1420 | L14: 260 | R14: 0 | X14: 140 | AB14: =SUM(B14:AA14) -> 1820 | AC14: 469 | AD14: =AB14/AC14 -> 3.880597
A15: NEW MARKET MIDDLE | C15: 200 | F15: 260 | I15: 180 | L15: 240 | O15: 280 | R15: 520 | U15: 260 | X15: 160 | AB15: =SUM(B15:AA15) -> 2100 | AC15: 581 | AD15: =AB15/AC15 -> 3.6144578
A16: NEW MIDWAY ELEMENTARY | E16: 120 | K16: 140 | Q16: 180 | W16: 140 | AB16: =SUM(B16:AA16) -> 580 | AC16: 166 | AD16: =AB16/AC16 -> 3.4939759
A17: ORCHARD GROVE ELEMENTARY | B17: 400 | E17: 220 | H17: 260 | K17: 400 | N17: 220 | Q17: 280 | T17: 200 | W17: 380 | Z17: 40 | AB17: =SUM(B17:AA17) -> 2400 | AC17: 695 | AD17: =AB17/AC17 -> 3.4532374
A18: WAVERLY ELEMENTARY | C18: 1300 | F18: 200 | I18: 200 | L18: 80 | R18: 300 | X18: 60 | AB18: =SUM(B18:AA18) -> 2140 | AC18: 637 | AD18: =AB18/AC18 -> 3.3594976
A19: MIDDLETOWN PRIMARY | E19: 1500 | K19: 60 | Q19: 20 | W19: 180 | AB19: =SUM(B19:AA19) -> 1760 | AC19: 541 | AD19: =AB19/AC19 -> 3.2532348
A20: PARKWAY ELEMENTARY | B20: 300 | H20: 120 | N20: 280 | T20: 260 | Z20: 20 | AB20: =SUM(B20:AA20) -> 980 | AC20: 302 | AD20: =AB20/AC20 -> 3.2450331
A21: URBANA MIDDLE | C21: 20 | F21: 100 | I21: 80 | L21: 80 | O21: 1820 | R21: 260 | U21: 120 | X21: 60 | AB21: =SUM(B21:AA21) -> 2540 | AC21: 830 | AD21: =AB21/AC21 -> 3.060241
A22: CATOCTIN HIGH | B22: 340 | E22: 700 | H22: 480 | K22: 700 | N22: 300 | Q22: 240 | T22: 160 | W22: 180 | Z22: 120 | AB22: =SUM(B22:AA22) -> 3220 | AC22: 1074 | AD22: =AB22/AC22 -> 2.9981378
A23: MONOCACY MIDDLE | C23: 340 | F23: 1200 | I23: 80 | L23: 220 | R23: 220 | X23: 240 | AB23: =SUM(B23:AA23) -> 2300 | AC23: 816 | AD23: =AB23/AC23 -> 2.8186275
A24: THURMONT ELEMENTARY | E24: 160 | K24: 340 | Q24: 240 | W24: 320 | AB24: =SUM(B24:AA24) -> 1060 | AC24: 381 | AD24: =AB24/AC24 -> 2.7821522
A25: WOLFSVILLE ELEMENTARY | E25: 140 | K25: 140 | Q25: 140 | W25: 160 | AB25: =SUM(B25:AA25) -> 580 | AC25: 209 | AD25: =AB25/AC25 -> 2.7751196
A26: THURMONT PRIMARY | E26: 300 | K26: 360 | Q26: 200 | W26: 340 | AB26: =SUM(B26:AA26) -> 1200 | AC26: 442 | AD26: =AB26/AC26 -> 2.7149321
A27: N FREDERICK ELEMENTARY | C27: 340 | I27: 300 | O27: 480 | Q27: 440 | U27: 300 | AB27: =SUM(B27:AA27) -> 1860 | AC27: 693 | AD27: =AB27/AC27 -> 2.6839827
A28: THOMAS JOHNSON MIDDLE | B28: 140 | H28: 180 | K28: 140 | N28: 140 | Q28: 200 | T28: 120 | W28: 160 | Z28: 560 | AB28: =SUM(B28:AA28) -> 1640 | AC28: 630 | AD28: =AB28/AC28 -> 2.6031746
A29: TUSCARORA ELEMENTARY | B29: 300 | E29: 140 | H29: 340 | K29: 300 | N29: 200 | Q29: 260 | T29: 220 | W29: 280 | Z29: 40 | AB29: =SUM(B29:AA29) -> 2080 | AC29: 839 | AD29: =AB29/AC29 -> 2.4791418
A30: CRESTWOOD MIDDLE | E30: 320 | K30: 200 | Q30: 520 | W30: 320 | AB30: =SUM(B30:AA30) -> 1360 | AC30: 573 | AD30: =AB30/AC30 -> 2.3734729
A31: URBANA HIGH | B31: 520 | D31: 280 | F31: 420 | H31: 280 | J31: 240 | L31: 400 | N31: 200 | P31: 180 | R31: 260 | T31: 180 | X31: 240 | Z31: 480 | AB31: =SUM(B31:AA31) -> 3680 | AC31: 1609 | AD31: =AB31/AC31 -> 2.2871349
A32: THURMONT MIDDLE | B32: 20 | E32: 60 | H32: 240 | K32: 160 | N32: 140 | Q32: 240 | T32: 120 | W32: 180 | Z32: 380 | AB32: =SUM(B32:AA32) -> 1540 | AC32: 693 | AD32: =AB32/AC32 -> 2.2222222
A33: WHITTIER ELEMENTARY | B33: 700 | H33: 520 | N33: 320 | T33: 320 | Z33: 40 | AB33: =SUM(B33:AA33) -> 1900 | AC33: 865 | AD33: =AB33/AC33 -> 2.1965318
A34: MIDDLETOWN ELEMENTARY | B34: 400 | H34: 260 | N34: 260 | T34: 220 | Z34: 0 | AB34: =SUM(B34:AA34) -> 1140 | AC34: 537 | AD34: =AB34/AC34 -> 2.122905
A35: BRUNSWICK MIDDLE | B35: 160 | E35: 80 | H35: 80 | K35: 80 | N35: 80 | Q35: 200 | T35: 240 | W35: 60 | Z35: 280 | AB35: =SUM(B35:AA35) -> 1260 | AC35: 604 | AD35: =AB35/AC35 -> 2.0860927
A36: MIDDLETOWN HIGH | B36: 360 | E36: 40 | H36: 420 | K36: 320 | N36: 380 | Q36: 500 | T36: 360 | W36: 180 | Z36: 120 | AB36: =SUM(B36:AA36) -> 2680 | AC36: 1325 | AD36: =AB36/AC36 -> 2.0226415
A37: CARROLL MANOR ELEMENTARY | E37: 280 | K37: 400 | Q37: 280 | W37: 320 | AB37: =SUM(B37:AA37) -> 1280 | AC37: 644 | AD37: =AB37/AC37 -> 1.9875776
A38: CENTERVILLE ELEMENTARY | C38: 240 | F38: 160 | I38: 420 | L38: 400 | O38: 300 | R38: 200 | V38: 220 | X38: 40 | AB38: =SUM(B38:AA38) -> 1980 | AC38: 1028 | AD38: =AB38/AC38 -> 1.92607
A39: OAKDALE HIGH | B39: 180 | H39: 160 | K39: 220 | N39: 620 | Q39: 300 | T39: 580 | W39: 200 | Z39: 120 | AB39: =SUM(B39:AA39) -> 2380 | AC39: 1274 | AD39: =AB39/AC39 -> 1.8681319
A40: FREDERICK HIGH | B40: 100 | D40: 160 | F40: 180 | H40: 280 | J40: 180 | L40: 320 | N40: 620 | P40: 220 | R40: 200 | T40: 160 | V40: 20 | X40: 120 | Z40: 120 | AB40: =SUM(B40:AA40) -> 2680 | AC40: 1500 | AD40: =AB40/AC40 -> 1.7866667
A41: MYERSVILLE ELEMENTARY | E41: 220 | K41: 320 | Q41: 20 | W41: 160 | AB41: =SUM(B41:AA41) -> 720 | AC41: 419 | AD41: =AB41/AC41 -> 1.7183771
...

Sheet JAN 13
A1: Data in the yellow columns shows the pounds of material collected from each facility's RECYCLING dumpster and the date material was picked up.
A3: JANUARY | B3: MON | C3: TUE | D3: WED | E3: THU | F3: FRI | H3: MON | I3: TUE | J3: WED | K3: THU | L3: FRI | N3: MON | O3: TUE | P3: WED | Q3: THU | R3: FRI | T3: MON | U3: TUE | V3: WED | W3: THU | X3: FRI | Z3: MON | AA3: TUE | AB3: WED | AC3: THU
A4: Date of Collection | C4: 1 | D4: 2 | E4: 3 | F4: 4 | H4: 7 | I4: 8 | J4: 9 | K4: 10 | L4: 11 | N4: 14 | O4: 15 | P4: 16 | Q4: 17 | R4: 18 | T4: 21 | U4: 22 | V4: 23 | W4: 24 | X4: 25 | Z4: 28 | AA4: 29 | AB4: 30 | AC4: 31 | AE4: TOTAL COLLECTED | AF4: # of Recyclers | AG4: Pounds Recycled Per Capita
A5: SCHOOL:
A6: HEATHER RIDGE SCHOOL | C6: 40 | E6: 60 | I6: 200 | K6: 40 | O6: 80 | Q6: 20 | U6: 140 | X6: 60 | AA6: 20 | AC6: 200 | AE6: =SUM(B6:AD6) -> 860 | AF6: 121 | AG6: =AE6/AF6 -> 7.107438
A7: EMMITSBURG ELEMENTARY | E7: 360 | K7: 1120 | Q7: 40 | X7: 420 | AC7: 460 | AE7: =SUM(B7:AD7) -> 2400 | AF7: 342 | AG7: =AE7/AF7 -> 7.0175439
A8: WOLFSVILLE ELEMENTARY | E8: 780 | K8: 80 | Q8: 180 | X8: 60 | AC8: 140 | AE8: =SUM(B8:AD8) -> 1240 | AF8: 209 | AG8: =AE8/AF8 -> 5.9330144
A9: BALLENGER CREEK ELEMENTARY | C9: 120 | E9: 360 | H9: 1420 | K9: 460 | N9: 300 | Q9: 380 | T9: 400 | X9: 220 | Z9: 120 | AC9: 440 | AE9: =SUM(B9:AD9) -> 4220 | AF9: 738 | AG9: =AE9/AF9 -> 5.7181572
A10: THURMONT PRIMARY | E10: 60 | K10: 1720 | Q10: 260 | X10: 180 | AC10: 200 | AE10: =SUM(B10:AD10) -> 2420 | AF10: 442 | AG10: =AE10/AF10 -> 5.4751131
A11: URBANA MIDDLE | C11: 360 | F11: 160 | I11: 80 | L11: 240 | O11: 1820 | R11: 60 | U11: 40 | X11: 60 | AA11: 1720 | AE11: =SUM(B11:AD11) -> 4540 | AF11: 830 | AG11: =AE11/AF11 -> 5.4698795
A12: CRESTWOOD MIDDLE | E12: 20 | K12: 2080 | Q12: 260 | X12: 420 | AC12: 300 | AE12: =SUM(B12:AD12) -> 3080 | AF12: 573 | AG12: =AE12/AF12 -> 5.3752182
A13: WAVERLY ELEMENTARY | C13: 100 | F13: 300 | I13: 260 | L13: 180 | O13: 320 | R13: 280 | U13: 260 | X13: 180 | AA13: 760 | AB13: 760 | AE13: =SUM(B13:AD13) -> 3400 | AF13: 637 | AG13: =AE13/AF13 -> 5.3375196
A14: N FREDERICK ELEMENTARY | C14: 60 | E14: 160 | I14: 280 | K14: 360 | O14: 480 | Q14: 320 | U14: 640 | X14: 460 | AA14: 200 | AC14: 560 | AE14: =SUM(B14:AD14) -> 3520 | AF14: 693 | AG14: =AE14/AF14 -> 5.0793651
A15: ROCK CREEK SCHOOL | C15: 80 | F15: 140 | I15: 140 | L15: 80 | O15: 100 | R15: 20 | U15: 60 | X15: 100 | AA15: 80 | AE15: =SUM(B15:AD15) -> 800 | AF15: 177 | AG15: =AE15/AF15 -> 4.519774
A16: CARROLL MANOR ELEMENTARY | E16: 120 | K16: 420 | Q16: 1500 | X16: 520 | AC16: 280 | AE16: =SUM(B16:AD16) -> 2840 | AF16: 644 | AG16: =AE16/AF16 -> 4.4099379
A17: TUSCARORA ELEMENTARY | E17: 220 | H17: 280 | K17: 260 | N17: 240 | Q17: 380 | T17: 700 | X17: 500 | Z17: 120 | AC17: 820 | AE17: =SUM(B17:AD17) -> 3520 | AF17: 839 | AG17: =AE17/AF17 -> 4.1954708
A18: THOMAS JOHNSON MIDDLE | E18: 120 | H18: 300 | K18: 20 | N18: 860 | Q18: 260 | T18: 200 | X18: 160 | Z18: 20 | AB18: 300 | AC18: 300 | AE18: =SUM(B18:AD18) -> 2540 | AF18: 630 | AG18: =AE18/AF18 -> 4.031746
A19: THURMONT ELEMENTARY | E19: 200 | K19: 360 | Q19: 280 | X19: 220 | AC19: 400 | AE19: =SUM(B19:AD19) -> 1460 | AF19: 381 | AG19: =AE19/AF19 -> 3.832021
A20: MIDDLETOWN HIGH | E20: 60 | H20: 60 | K20: 400 | N20: 260 | Q20: 1580 | T20: 960 | X20: 600 | Z20: 440 | AC20: 380 | AE20: =SUM(B20:AD20) -> 4740 | AF20: 1325 | AG20: =AE20/AF20 -> 3.5773585
A21: LIBERTY ELEMENTARY | E21: 360 | K21: 220 | Q21: 200 | X21: 180 | AC21: 220 | AE21: =SUM(B21:AD21) -> 1180 | AF21: 334 | AG21: =AE21/AF21 -> 3.5329341
A22: NEW MARKET MIDDLE | C22: 120 | F22: 20 | I22: 60 | L22: 320 | O22: 280 | R22: 400 | U22: 200 | X22: 320 | AA22: 300 | AE22: =SUM(B22:AD22) -> 2020 | AF22: 581 | AG22: =AE22/AF22 -> 3.4767642
A23: OAKDALE ELEMENTARY | C23: 80 | I23: 40 | O23: 500 | U23: 180 | AA23: 1580 | AE23: =SUM(B23:AD23) -> 2380 | AF23: 707 | AG23: =AE23/AF23 -> 3.3663366
A24: BRUNSWICK HIGH | H24: 360 | N24: 260 | T24: 120 | Z24: 1940 | AE24: =SUM(B24:AD24) -> 2680 | AF24: 807 | AG24: =AE24/AF24 -> 3.3209418
A25: WOODSBORO ELEMENTARY | E25: 20 | K25: 160 | Q25: 160 | X25: 180 | AC25: 180 | AE25: =SUM(B25:AD25) -> 700 | AF25: 213 | AG25: =AE25/AF25 -> 3.286385
A26: PARKWAY ELEMENTARY | C26: 120 | H26: 280 | N26: 240 | T26: 120 | Z26: 200 | AE26: =SUM(B26:AD26) -> 960 | AF26: 302 | AG26: =AE26/AF26 -> 3.1788079
A27: LEWISTOWN ELEMENTARY | E27: 120 | K27: 88 | Q27: 180 | X27: 140 | AC27: 340 | AE27: =SUM(B27:AD27) -> 868 | AF27: 274 | AG27: =AE27/AF27 -> 3.1678832
A28: ORCHARD GROVE ELEMENTARY | E28: 120 | H28: 320 | K28: 280 | N28: 260 | Q28: 320 | T28: 40 | X28: 280 | Z28: 100 | AC28: 360 | AE28: =SUM(B28:AD28) -> 2080 | AF28: 695 | AG28: =AE28/AF28 -> 2.9928058
A29: MIDDLETOWN PRIMARY | E29: 400 | K29: 300 | Q29: 300 | X29: 260 | AC29: 320 | AE29: =SUM(B29:AD29) -> 1580 | AF29: 541 | AG29: =AE29/AF29 -> 2.9205176
A30: WALKERSVILLE MIDDLE | E30: 500 | H30: 320 | K30: 100 | N30: 140 | Q30: 180 | T30: 160 | X30: 160 | Z30: 800 | AC30: 120 | AE30: =SUM(B30:AD30) -> 2480 | AF30: 859 | AG30: =AE30/AF30 -> 2.887078
A31: URBANA HIGH | D31: 220 | F31: 140 | H31: 400 | J31: 320 | L31: 240 | N31: 340 | P31: 280 | R31: 140 | T31: 260 | V31: 220 | X31: 120 | Z31: 100 | AB31: 1740 | AE31: =SUM(B31:AD31) -> 4520 | AF31: 1609 | AG31: =AE31/AF31 -> 2.8091983
A32: SPRING RIDGE ELEMENTARY | E32: 180 | H32: 280 | K32: 180 | N32: 200 | Q32: 180 | T32: 60 | X32: 100 | Z32: 160 | AC32: 80 | AE32: =SUM(B32:AD32) -> 1420 | AF32: 563 | AG32: =AE32/AF32 -> 2.5222025
A33: BRUNSWICK MIDDLE | E33: 120 | H33: 180 | K33: 140 | N33: 100 | Q33: 160 | T33: 380 | X33: 80 | Z33: 140 | AC33: 220 | AE33: =SUM(B33:AD33) -> 1520 | AF33: 604 | AG33: =AE33/AF33 -> 2.5165563
A34: WALKERSVILLE HIGH | E34: 120 | H34: 80 | K34: 280 | N34: 380 | Q34: 280 | T34: 980 | X34: 580 | Z34: 40 | AC34: 320 | AE34: =SUM(B34:AD34) -> 3060 | AF34: 1227 | AG34: =AE34/AF34 -> 2.4938875
A35: SABILLASVILLE ELEMENTARY | E35: 80 | K35: 80 | Q35: 80 | W35: 100 | AC35: 40 | AE35: =SUM(B35:AD35) -> 380 | AF35: 157 | AG35: =AE35/AF35 -> 2.4203822
A36: MYERSVILLE ELEMENTARY | E36: 60 | K36: 220 | Q36: 140 | U36: 120 | AC36: 460 | AE36: =SUM(B36:AD36) -> 1000 | AF36: 419 | AG36: =AE36/AF36 -> 2.3866348
A37: BALLENGER CREEK MIDDLE | E37: 200 | H37: 560 | K37: 320 | N37: 120 | Q37: 60 | T37: 60 | X37: 60 | Z37: 160 | AC37: 340 | AE37: =SUM(B37:AD37) -> 1880 | AF37: 797 | AG37: =AE37/AF37 -> 2.3588457
A38: MIDDLETOWN ELEMENTARY | H38: 300 | N38: 320 | T38: 400 | Z38: 240 | AE38: =SUM(B38:AD38) -> 1260 | AF38: 537 | AG38: =AE38/AF38 -> 2.3463687
A39: GREEN VALLEY ELEMENTARY | F39: 240 | L39: 320 | R39: 360 | X39: 180 | AE39: =SUM(B39:AD39) -> 1100 | AF39: 469 | AG39: =AE39/AF39 -> 2.3454158
A40: WINDSOR KNOLLS MIDDLE | C40: 200 | F40: 140 | I40: 180 | L40: 160 | O40: 100 | R40: 360 | U40: 660 | X40: 280 | AA40: 120 | AE40: =SUM(B40:AD40) -> 2200 | AF40: 954 | AG40: =AE40/AF40 -> 2.3060797
A41: OAKDALE HIGH | E41: 120 | H41: 240 | K41: 240 | N41: 220 | Q41: 200 | T41: 1160 | X41: 280 | Z41: 80 | AC41: 380 | AE41: =SUM(B41:AD41) -> 2920 | AF41: 1274 | AG41: =AE41/AF41 -> 2.2919937
...

Sheet FEB 13
A1: Data in the yellow columns shows the pounds of material collected from each facility's RECYCLING dumpster and the date material was picked up.
A3: FEBRUARY | B3: MON | C3: TUE | D3: WED | E3: THU | F3: FRI | H3: MON | I3: TUE | J3: WED | K3: THU | L3: FRI | N3: MON | O3: TUE | P3: WED | Q3: THU | R3: FRI | T3: MON | U3: TUE | V3: WED | W3: THU | X3: FRI | Z3: MON | AA3: TUE | AB3: WED | AC3: THU
A4: Date of Collection | F4: 1 | H4: 4 | I4: 5 | J4: 6 | K4: 7 | L4: 8 | N4: 11 | O4: 12 | P4: 13 | Q4: 14 | R4: 15 | T4: 18 | U4: 19 | V4: 20 | W4: 21 | X4: 22 | Z4: 25 | AA4: 26 | AB4: 27 | AC4: 28 | AE4: TOTAL COLLECTED | AF4: # of Recyclers | AG4: Pounds Recycled Per Capita
A5: SCHOOL:
A6: WOODSBORO ELEMENTARY | K6: 180 | Q6: 1120 | W6: 680 | AC6: 840 | AE6: =SUM(B6:AD6) -> 2820 | AF6: ='Facility Data'!D63 -> 213 | AG6: =AE6/AF6 -> 13.239437
A7: HEATHER RIDGE SCHOOL | I7: 240 | K7: 20 | O7: 80 | Q7: 120 | U7: 20 | W7: 40 | AA7: 320 | AC7: 100 | AE7: =SUM(B7:AD7) -> 940 | AF7: ='Facility Data'!D17 -> 121 | AG7: =AE7/AF7 -> 7.768595
A8: WOLFSVILLE ELEMENTARY | K8: 120 | Q8: 140 | W8: 800 | AC8: 280 | AE8: =SUM(B8:AD8) -> 1340 | AF8: ='Facility Data'!D62 -> 209 | AG8: =AE8/AF8 -> 6.4114833
A9: EMMITSBURG ELEMENTARY | K9: 220 | Q9: 280 | W9: 200 | AC9: 1140 | AE9: =SUM(B9:AD9) -> 1840 | AF9: ='Facility Data'!D13 -> 342 | AG9: =AE9/AF9 -> 5.380117
A10: THURMONT PRIMARY | K10: 180 | Q10: 320 | W10: 1540 | AC10: 60 | AE10: =SUM(B10:AD10) -> 2100 | AF10: ='Facility Data'!D47 -> 442 | AG10: =AE10/AF10 -> 4.7511312
A11: SPRING RIDGE ELEMENTARY | H11: 1560 | K11: 440 | N11: 160 | Q11: 140 | T11: 180 | W11: 20 | Z11: 100 | AC11: 40 | AE11: =SUM(B11:AD11) -> 2640 | AF11: ='Facility Data'!D42 -> 563 | AG11: =AE11/AF11 -> 4.6891652
A12: VALLEY ELEMENTARY | H12: 260 | N12: 1280 | T12: 280 | Z12: 280 | AE12: =SUM(B12:AD12) -> 2100 | AF12: ='Facility Data'!D54 -> 488 | AG12: =AE12/AF12 -> 4.3032787
A13: ROCK CREEK SCHOOL | F13: 60 | I13: 120 | L13: 80 | O13: 40 | R13: 20 | U13: 160 | X13: 40 | AA13: 240 | AE13: =SUM(B13:AD13) -> 760 | AF13: ='Facility Data'!D40 -> 177 | AG13: =AE13/AF13 -> 4.2937853
A14: TWIN RIDGE ELEMENTARY | F14: 1260 | L14: 60 | R14: 40 | X14: 1120 | AE14: =SUM(B14:AD14) -> 2480 | AF14: ='Facility Data'!D50 -> 598 | AG14: =AE14/AF14 -> 4.1471572
A15: MIDDLETOWN ELEMENTARY | H15: 20 | N15: 1740 | T15: 300 | Z15: 160 | AE15: =SUM(B15:AD15) -> 2220 | AF15: ='Facility Data'!D24 -> 537 | AG15: =AE15/AF15 -> 4.1340782
A16: WALKERSVILLE MIDDLE | F16: 1180 | I16: 220 | L16: 260 | O16: 40 | R16: 180 | U16: 140 | X16: 1340 | AA16: 180 | AE16: =SUM(B16:AD16) -> 3540 | AF16: ='Facility Data'!D58 -> 859 | AG16: =AE16/AF16 -> 4.121071
A17: BALLENGER CREEK ELEMENTARY | H17: 280 | K17: 280 | N17: 320 | Q17: 420 | T17: 640 | W17: 380 | Z17: 160 | AC17: 160 | AE17: =SUM(B17:AD17) -> 2640 | AF17: ='Facility Data'!D3 -> 738 | AG17: =AE17/AF17 -> 3.5772358
A18: LEWISTOWN ELEMENTARY | K18: 180 | Q18: 280 | W18: 220 | AC18: 220 | AE18: =SUM(B18:AD18) -> 900 | AF18: ='Facility Data'!D20 -> 274 | AG18: =AE18/AF18 -> 3.2846715
A19: THURMONT ELEMENTARY | K19: 300 | Q19: 360 | W19: 320 | AC19: 240 | AE19: =SUM(B19:AD19) -> 1220 | AF19: ='Facility Data'!D45 -> 381 | AG19: =AE19/AF19 -> 3.2020997
A20: WAVERLY ELEMENTARY | F20: 600 | H20: 140 | L20: 80 | N20: 100 | R20: 120 | T20: 20 | X20: 720 | Z20: 220 | AE20: =SUM(B20:AD20) -> 2000 | AF20: ='Facility Data'!D59 -> 637 | AG20: =AE20/AF20 -> 3.1397174
A21: NEW MARKET MIDDLE | F21: 260 | I21: 420 | L21: 320 | O21: 180 | R21: 220 | U21: 160 | X21: 80 | AA21: 120 | AE21: =SUM(B21:AD21) -> 1760 | AF21: ='Facility Data'!D33 -> 581 | AG21: =AE21/AF21 -> 3.0292599
A22: TUSCARORA ELEMENTARY | H22: 380 | K22: 540 | N22: 320 | Q22: 160 | T22: 280 | W22: 280 | Z22: 220 | AC22: 340 | AE22: =SUM(B22:AD22) -> 2520 | AF22: ='Facility Data'!D48 -> 839 | AG22: =AE22/AF22 -> 3.0035757
A23: PARKWAY ELEMENTARY | H23: 120 | N23: 520 | T23: 180 | Z23: 80 | AE23: =SUM(B23:AD23) -> 900 | AF23: ='Facility Data'!D39 -> 302 | AG23: =AE23/AF23 -> 2.9801325
A24: BRUNSWICK HIGH | H24: 420 | N24: 1640 | T24: 80 | Z24: 180 | AE24: =SUM(B24:AD24) -> 2320 | AF24: ='Facility Data'!D6 -> 807 | AG24: =AE24/AF24 -> 2.8748451
A25: OAKDALE HIGH | H25: 180 | K25: 420 | N25: 20 | Q25: 280 | T25: 200 | W25: 120 | Z25: 440 | AC25: 1680 | AE25: =SUM(B25:AD25) -> 3340 | AF25: ='Facility Data'!D36 -> 1274 | AG25: =AE25/AF25 -> 2.6216641
A26: ORCHARD GROVE ELEMENTARY | H26: 240 | K26: 160 | N26: 0 | Q26: 240 | T26: 400 | W26: 240 | Z26: 120 | AC26: 400 | AE26: =SUM(B26:AD26) -> 1800 | AF26: ='Facility Data'!D38 -> 695 | AG26: =AE26/AF26 -> 2.5899281
A27: WHITTIER ELEMENTARY | H27: 520 | N27: 680 | T27: 540 | Z27: 500 | AE27: =SUM(B27:AD27) -> 2240 | AF27: ='Facility Data'!D60 -> 865 | AG27: =AE27/AF27 -> 2.5895954
A28: N FREDERICK ELEMENTARY | I28: 140 | K28: 160 | O28: 520 | Q28: 100 | U28: 60 | W28: 100 | AA28: 320 | AC28: 240 | AE28: =SUM(B28:AD28) -> 1640 | AF28: ='Facility Data'!D31 -> 693 | AG28: =AE28/AF28 -> 2.3665224
A29: W FREDERIC MIDDLE | K29: 340 | Q29: 720 | W29: 300 | AC29: 760 | AE29: =SUM(B29:AD29) -> 2120 | AF29: ='Facility Data'!D55 -> 900 | AG29: =AE29/AF29 -> 2.3555556
A30: WALKERSVILLE ELEMENTARY | H30: 280 | K30: 160 | N30: 400 | Q30: 120 | T30: 280 | W30: 20 | Z30: 340 | AC30: 140 | AE30: =SUM(B30:AD30) -> 1740 | AF30: ='Facility Data'!D56 -> 762 | AG30: =AE30/AF30 -> 2.2834646
A31: SABILLASVILLE ELEMENTARY | K31: 100 | Q31: 100 | W31: 80 | AC31: 60 | AE31: =SUM(B31:AD31) -> 340 | AF31: ='Facility Data'!D41 -> 157 | AG31: =AE31/AF31 -> 2.1656051
A32: NEW MIDWAY ELEMENTARY | K32: 20 | Q32: 60 | W32: 60 | AC32: 200 | AE32: =SUM(B32:AD32) -> 340 | AF32: ='Facility Data'!D34 -> 166 | AG32: =AE32/AF32 -> 2.0481928
A33: FREDERICK HIGH | F33: 260 | H33: 660 | J33: 160 | L33: 140 | N33: 400 | P33: 160 | R33: 200 | T33: 360 | V33: 120 | X33: 80 | Z33: 360 | AB33: 120 | AE33: =SUM(B33:AD33) -> 3020 | AF33: ='Facility Data'!D14 -> 1500 | AG33: =AE33/AF33 -> 2.0133333
A34: WALKERSVILLE HIGH | H34: 300 | K34: 140 | N34: 80 | Q34: 180 | T34: 1240 | W34: 60 | Z34: 320 | AC34: 140 | AE34: =SUM(B34:AD34) -> 2460 | AF34: ='Facility Data'!D57 -> 1227 | AG34: =AE34/AF34 -> 2.00489
A35: MONOCACY ELEMENTARY | I35: 300 | O35: 480 | U35: 280 | AA35: 280 | AE35: =SUM(B35:AD35) -> 1340 | AF35: ='Facility Data'!D28 -> 702 | AG35: =AE35/AF35 -> 1.9088319
A36: GREEN VALLEY ELEMENTARY | F36: 280 | L36: 360 | R36: 80 | X36: 160 | AE36: =SUM(B36:AD36) -> 880 | AF36: ='Facility Data'!D16 -> 469 | AG36: =AE36/AF36 -> 1.8763326
A37: YELLOW SPRINGS ELEMENTARY | H37: 160 | N37: 520 | T37: 200 | Z37: 80 | AE37: =SUM(B37:AD37) -> 960 | AF37: ='Facility Data'!D64 -> 514 | AG37: =AE37/AF37 -> 1.8677043
A38: THURMONT MIDDLE | H38: 80 | K38: 240 | N38: 160 | Q38: 270 | T38: 140 | W38: 60 | Z38: 180 | AC38: 160 | AE38: =SUM(B38:AD38) -> 1290 | AF38: ='Facility Data'!D46 -> 693 | AG38: =AE38/AF38 -> 1.8614719
A39: KEMPTOWN ELEMENTARY | F39: 260 | L39: 420 | R39: 120 | X39: 20 | AE39: =SUM(B39:AD39) -> 820 | AF39: ='Facility Data'!D19 -> 442 | AG39: =AE39/AF39 -> 1.8552036
A40: MYERSVILLE ELEMENTARY | K40: 60 | Q40: 240 | W40: 200 | AC40: 240 | AE40: =SUM(B40:AD40) -> 740 | AF40: ='Facility Data'!D30 -> 419 | AG40: =AE40/AF40 -> 1.7661098
A41: MIDDLETOWN HIGH | H41: 540 | K41: 280 | N41: 100 | Q41: 480 | T41: 200 | W41: 100 | Z41: 400 | AC41: 220 | AE41: =SUM(B41:AD41) -> 2320 | AF41: ='Facility Data'!D25 -> 1325 | AG41: =AE41/AF41 -> 1.7509434
...

Sheet MAR 13
A1: Data in the yellow columns shows the pounds of material collected from each facility's RECYCLING dumpster and the date material was picked up.
A3: MARCH | B3: MON | C3: TUE | D3: WED | E3: THU | F3: FRI | H3: MON | I3: TUE | J3: WED | K3: THU | L3: FRI | N3: MON | O3: TUE | P3: WED | Q3: THU | R3: FRI | T3: MON | U3: TUE | V3: WED | W3: THU | X3: FRI | Z3: MON | AA3: TUE | AB3: WED | AC3: THU | AD3: FRI
A4: Date of Collection | F4: 1 | H4: 4 | I4: 5 | J4: 6 | K4: 7 | L4: 8 | N4: 11 | O4: 12 | P4: 13 | Q4: 14 | R4: 15 | T4: 18 | U4: 19 | V4: 20 | W4: 21 | X4: 22 | Z4: 25 | AA4: 26 | AB4: 27 | AC4: 28 | AD4: 29 | AF4: TOTAL COLLECTED | AG4: # of Recyclers | AH4: Pounds Recycled Per Capita
A5: SCHOOL:
A6: HEATHER RIDGE SCHOOL | I6: 240 | K6: 280 | O6: 100 | Q6: 160 | U6: 60 | W6: 320 | AA6: 160 | AC6: 80 | AF6: =SUM(B6:AE6) -> 1400 | AG6: ='Facility Data'!D17 -> 121 | AH6: =AF6/AG6 -> 11.570248
A7: ROCK CREEK SCHOOL | F7: 320 | I7: 200 | L7: 120 | O7: 80 | R7: 120 | U7: 160 | X7: 80 | AA7: 40 | AD7: 160 | AF7: =SUM(B7:AE7) -> 1280 | AG7: ='Facility Data'!D40 -> 177 | AH7: =AF7/AG7 -> 7.2316384
A8: WOODSBORO ELEMENTARY | K8: 260 | Q8: 360 | W8: 420 | AC8: 280 | AF8: =SUM(B8:AE8) -> 1320 | AG8: ='Facility Data'!D63 -> 213 | AH8: =AF8/AG8 -> 6.1971831
A9: WAVERLY ELEMENTARY | F9: 860 | I9: 320 | L9: 340 | O9: 480 | R9: 280 | U9: 320 | X9: 420 | AA9: 180 | AD9: 260 | AF9: =SUM(B9:AE9) -> 3460 | AG9: ='Facility Data'!D59 -> 637 | AH9: =AF9/AG9 -> 5.4317111
A10: SPRING RIDGE ELEMENTARY | H10: 320 | K10: 420 | N10: 180 | Q10: 520 | T10: 340 | W10: 260 | Z10: 240 | AC10: 460 | AF10: =SUM(B10:AE10) -> 2740 | AG10: ='Facility Data'!D42 -> 563 | AH10: =AF10/AG10 -> 4.8667851
A11: PARKWAY ELEMENTARY | H11: 460 | N11: 380 | T11: 280 | Z11: 340 | AF11: =SUM(B11:AE11) -> 1460 | AG11: ='Facility Data'!D39 -> 302 | AH11: =AF11/AG11 -> 4.8344371
A12: WOLFSVILLE ELEMENTARY | K12: 180 | Q12: 220 | W12: 160 | AC12: 340 | AF12: =SUM(B12:AE12) -> 900 | AG12: ='Facility Data'!D62 -> 209 | AH12: =AF12/AG12 -> 4.3062201
A13: THURMONT ELEMENTARY | K13: 480 | Q13: 520 | W13: 320 | AC13: 220 | AF13: =SUM(B13:AE13) -> 1540 | AG13: ='Facility Data'!D45 -> 381 | AH13: =AF13/AG13 -> 4.0419948
A14: THURMONT PRIMARY | K14: 480 | Q14: 620 | W14: 220 | AC14: 400 | AF14: =SUM(B14:AE14) -> 1720 | AG14: ='Facility Data'!D47 -> 442 | AH14: =AF14/AG14 -> 3.8914027
A15: NEW MARKET MIDDLE | F15: 260 | I15: 420 | L15: 180 | O15: 280 | R15: 300 | U15: 180 | X15: 80 | AA15: 240 | AD15: 100 | AF15: =SUM(B15:AE15) -> 2040 | AG15: ='Facility Data'!D33 -> 581 | AH15: =AF15/AG15 -> 3.5111876
A16: EMMITSBURG ELEMENTARY | K16: 160 | Q16: 240 | W16: 180 | AC16: 620 | AF16: =SUM(B16:AE16) -> 1200 | AG16: ='Facility Data'!D13 -> 342 | AH16: =AF16/AG16 -> 3.5087719
A17: TWIN RIDGE ELEMENTARY | F17: 380 | L17: 620 | R17: 280 | X17: 400 | AD17: 320 | AF17: =SUM(B17:AE17) -> 2000 | AG17: ='Facility Data'!D50 -> 598 | AH17: =AF17/AG17 -> 3.3444816
A18: VALLEY ELEMENTARY | H18: 320 | N18: 460 | T18: 320 | Z18: 400 | AF18: =SUM(B18:AE18) -> 1500 | AG18: ='Facility Data'!D54 -> 488 | AH18: =AF18/AG18 -> 3.0737705
A19: SABILLASVILLE ELEMENTARY | K19: 80 | Q19: 180 | W19: 60 | AC19: 120 | AF19: =SUM(B19:AE19) -> 440 | AG19: ='Facility Data'!D41 -> 157 | AH19: =AF19/AG19 -> 2.8025478
A20: LEWISTOWN ELEMENTARY | K20: 200 | Q20: 220 | W20: 140 | AC20: 160 | AF20: =SUM(B20:AE20) -> 720 | AG20: ='Facility Data'!D20 -> 274 | AH20: =AF20/AG20 -> 2.6277372
A21: THURMONT MIDDLE | H21: 160 | K21: 140 | N21: 320 | Q21: 220 | T21: 240 | W21: 200 | Z21: 240 | AC21: 260 | AF21: =SUM(B21:AE21) -> 1780 | AG21: ='Facility Data'!D46 -> 693 | AH21: =AF21/AG21 -> 2.5685426
A22: YELLOW SPRINGS ELEMENTARY | H22: 460 | N22: 300 | T22: 260 | Z22: 280 | AF22: =SUM(B22:AE22) -> 1300 | AG22: ='Facility Data'!D64 -> 514 | AH22: =AF22/AG22 -> 2.5291829
A23: BRUNSWICK HIGH | H23: 520 | N23: 680 | T23: 340 | Z23: 480 | AF23: =SUM(B23:AE23) -> 2020 | AG23: ='Facility Data'!D6 -> 807 | AH23: =AF23/AG23 -> 2.5030979
A24: MIDDLETOWN ELEMENTARY | H24: 520 | N24: 340 | T24: 160 | Z24: 320 | AF24: =SUM(B24:AE24) -> 1340 | AG24: ='Facility Data'!D24 -> 537 | AH24: =AF24/AG24 -> 2.4953445
A25: WHITTIER ELEMENTARY | H25: 560 | N25: 680 | T25: 420 | Z25: 320 | AF25: =SUM(B25:AE25) -> 1980 | AG25: ='Facility Data'!D60 -> 865 | AH25: =AF25/AG25 -> 2.2890173
A26: NEW MIDWAY ELEMENTARY | K26: 60 | Q26: 100 | W26: 80 | AC26: 120 | AF26: =SUM(B26:AE26) -> 360 | AG26: ='Facility Data'!D34 -> 166 | AH26: =AF26/AG26 -> 2.1686747
A27: ORCHARD GROVE ELEMENTARY | H27: 320 | K27: 240 | N27: 160 | Q27: 200 | T27: 80 | W27: 180 | Z27: 260 | AC27: 60 | AF27: =SUM(B27:AE27) -> 1500 | AG27: ='Facility Data'!D38 -> 695 | AH27: =AF27/AG27 -> 2.1582734
A28: THOMAS JOHNSON MIDDLE | H28: 80 | K28: 100 | N28: 140 | Q28: 200 | T28: 160 | W28: 40 | Z28: 240 | AC28: 380 | AF28: =SUM(B28:AE28) -> 1340 | AG28: ='Facility Data'!D44 -> 630 | AH28: =AF28/AG28 -> 2.1269841
A29: CRESTWOOD MIDDLE | K29: 280 | Q29: 340 | W29: 180 | AC29: 340 | AF29: =SUM(B29:AE29) -> 1140 | AG29: ='Facility Data'!D11 -> 573 | AH29: =AF29/AG29 -> 1.9895288
A30: GREEN VALLEY ELEMENTARY | F30: 300 | L30: 260 | R30: 160 | X30: 80 | AD30: 120 | AF30: =SUM(B30:AE30) -> 920 | AG30: ='Facility Data'!D16 -> 469 | AH30: =AF30/AG30 -> 1.9616205
A31: WALKERSVILLE ELEMENTARY | K31: 400 | Q31: 380 | W31: 420 | AC31: 260 | AF31: =SUM(B31:AE31) -> 1460 | AG31: ='Facility Data'!D56 -> 762 | AH31: =AF31/AG31 -> 1.9160105
A32: CATOCTIN HIGH | H32: 260 | K32: 240 | N32: 180 | Q32: 360 | T32: 180 | W32: 80 | Z32: 420 | AC32: 320 | AF32: =SUM(B32:AE32) -> 2040 | AG32: ='Facility Data'!D9 -> 1074 | AH32: =AF32/AG32 -> 1.8994413
A33: WALKERSVILLE HIGH | H33: 300 | K33: 260 | N33: 320 | Q33: 360 | T33: 240 | W33: 200 | Z33: 480 | AC33: 160 | AF33: =SUM(B33:AE33) -> 2320 | AG33: ='Facility Data'!D57 -> 1227 | AH33: =AF33/AG33 -> 1.8907905
A34: BALLENGER CREEK ELEMENTARY | H34: 380 | K34: 260 | N34: 100 | Q34: 120 | T34: 80 | W34: 160 | Z34: 220 | AC34: 60 | AF34: =SUM(B34:AE34) -> 1380 | AG34: ='Facility Data'!D3 -> 738 | AH34: =AF34/AG34 -> 1.8699187
A35: TUSCARORA ELEMENTARY | H35: 280 | K35: 160 | N35: 200 | Q35: 240 | T35: 60 | W35: 300 | Z35: 180 | AC35: 140 | AF35: =SUM(B35:AE35) -> 1560 | AG35: ='Facility Data'!D48 -> 839 | AH35: =AF35/AG35 -> 1.8593564
A36: BALLENGER CREEK MIDDLE | H36: 220 | K36: 60 | N36: 180 | Q36: 120 | T36: 60 | W36: 240 | Z36: 280 | AC36: 260 | AF36: =SUM(B36:AE36) -> 1420 | AG36: ='Facility Data'!D4 -> 797 | AH36: =AF36/AG36 -> 1.7816813
A37: MONOCACY ELEMENTARY | I37: 320 | O37: 420 | U37: 260 | AA37: 220 | AF37: =SUM(B37:AE37) -> 1220 | AG37: ='Facility Data'!D28 -> 702 | AH37: =AF37/AG37 -> 1.7378917
A38: LIBERTY ELEMENTARY | K38: 160 | Q38: 200 | W38: 140 | AC38: 80 | AF38: =SUM(B38:AE38) -> 580 | AG38: ='Facility Data'!D21 -> 334 | AH38: =AF38/AG38 -> 1.7365269
A39: OAKDALE MIDDLE | F39: 200 | I39: 40 | L39: 120 | O39: 160 | R39: 180 | U39: 220 | X39: 60 | AA39: 120 | AD39: 100 | AF39: =SUM(B39:AE39) -> 1200 | AG39: ='Facility Data'!D37 -> 697 | AH39: =AF39/AG39 -> 1.7216643
A40: BRUNSWICK ELEMENTARY | H40: 360 | N40: 340 | T40: 220 | Z40: 260 | AF40: =SUM(B40:AE40) -> 1180 | AG40: ='Facility Data'!D5 -> 691 | AH40: =AF40/AG40 -> 1.70767
A41: URBANA HIGH | F41: 180 | H41: 360 | J41: 120 | L41: 140 | N41: 220 | P41: 80 | R41: 200 | T41: 120 | V41: 480 | X41: 220 | Z41: 240 | AB41: 260 | AD41: 120 | AF41: =SUM(B41:AE41) -> 2740 | AG41: ='Facility Data'!D52 -> 1609 | AH41: =AF41/AG41 -> 1.7029211
...

Sheet APR 13
A1: Data in the yellow columns shows the pounds of material collected from each facility's RECYCLING dumpster and the date material was picked up.
A3: APRIL | B3: MON | C3: TUE | D3: WED | E3: THU | F3: FRI | H3: MON | I3: TUE | J3: WED | K3: THU | L3: FRI | N3: MON | O3: TUE | P3: WED | Q3: THU | R3: FRI | T3: MON | U3: TUE | V3: WED | W3: THU | X3: FRI | Z3: MON | AA3: TUE | AB3: WED | AC3: THU | AD3: FRI
A4: Date of Collection | B4: 1 | C4: 2 | D4: 3 | E4: 4 | F4: 5 | H4: 8 | I4: 9 | J4: 10 | K4: 11 | L4: 12 | N4: 15 | O4: 16 | P4: 17 | Q4: 18 | R4: 15 | T4: 22 | U4: 23 | V4: 24 | W4: 25 | X4: 26 | Z4: 29 | AA4: 30 | AF4: TOTAL COLLECTED | AG4: # of Recyclers | AH4: Pounds Recycled Per Capita
A5: SCHOOL:
A6: HEATHER RIDGE SCHOOL | C6: 160 | E6: 180 | I6: 120 | K6: 240 | O6: 120 | Q6: 180 | U6: 240 | W6: 160 | AA6: 80 | AF6: =SUM(B6:AE6) -> 1480 | AG6: ='Facility Data'!D17 -> 121 | AH6: =AF6/AG6 -> 12.231405
A7: ROCK CREEK SCHOOL | C7: 80 | F7: 100 | I7: 160 | L7: 180 | O7: 180 | R7: 200 | U7: 80 | X7: 300 | AA7: 140 | AF7: =SUM(B7:AE7) -> 1420 | AG7: ='Facility Data'!D40 -> 177 | AH7: =AF7/AG7 -> 8.0225989
A8: BRUNSWICK HIGH | B8: 480 | H8: 560 | N8: 1720 | T8: 500 | Z8: 1760 | AF8: =SUM(B8:AE8) -> 5020 | AG8: ='Facility Data'!D6 -> 807 | AH8: =AF8/AG8 -> 6.22057
A9: URBANA HIGH | B9: 600 | D9: 1120 | F9: 380 | H9: 1360 | J9: 460 | L9: 1540 | N9: 240 | P9: 420 | R9: 280 | T9: 620 | V9: 380 | X9: 240 | Z9: 680 | AF9: =SUM(B9:AE9) -> 8320 | AG9: ='Facility Data'!D52 -> 1609 | AH9: =AF9/AG9 -> 5.1709136
A10: WOODSBORO ELEMENTARY | E10: 280 | K10: 320 | Q10: 260 | W10: 180 | AF10: =SUM(B10:AE10) -> 1040 | AG10: ='Facility Data'!D63 -> 213 | AH10: =AF10/AG10 -> 4.8826291
A11: MONOCACY ELEMENTARY | C11: 260 | I11: 340 | O11: 300 | U11: 300 | AA11: 1860 | AF11: =SUM(B11:AE11) -> 3060 | AG11: ='Facility Data'!D28 -> 702 | AH11: =AF11/AG11 -> 4.3589744
A12: WOLFSVILLE ELEMENTARY | E12: 200 | K12: 230 | Q12: 180 | W12: 300 | AF12: =SUM(B12:AE12) -> 910 | AG12: ='Facility Data'!D62 -> 209 | AH12: =AF12/AG12 -> 4.354067
A13: WALKERSVILLE ELEMENTARY | B13: 460 | E13: 320 | H13: 540 | K13: 420 | N13: 220 | Q13: 360 | T13: 300 | W13: 400 | Z13: 120 | AF13: =SUM(B13:AE13) -> 3140 | AG13: ='Facility Data'!D56 -> 762 | AH13: =AF13/AG13 -> 4.1207349
A14: NEW MIDWAY ELEMENTARY | E14: 160 | K14: 200 | Q14: 160 | W14: 140 | AF14: =SUM(B14:AE14) -> 660 | AG14: ='Facility Data'!D34 -> 166 | AH14: =AF14/AG14 -> 3.9759036
A15: TUSCARORA ELEMENTARY | B15: 340 | E15: 180 | H15: 300 | K15: 420 | N15: 660 | Q15: 360 | T15: 200 | W15: 340 | Z15: 320 | AF15: =SUM(B15:AE15) -> 3120 | AG15: ='Facility Data'!D48 -> 839 | AH15: =AF15/AG15 -> 3.7187128
A16: KEMPTOWN ELEMENTARY | F16: 300 | L16: 620 | R16: 420 | X16: 260 | AF16: =SUM(B16:AE16) -> 1600 | AG16: ='Facility Data'!D19 -> 442 | AH16: =AF16/AG16 -> 3.6199095
A17: THOMAS JOHNSON MIDDLE | B17: 80 | E17: 140 | H17: 140 | K17: 16 | N17: 140 | Q17: 80 | T17: 60 | W17: 120 | Z17: 160 | AA17: 1260 | AF17: =SUM(B17:AE17) -> 2196 | AG17: ='Facility Data'!D44 -> 630 | AH17: =AF17/AG17 -> 3.4857143
A18: NEW MARKET MIDDLE | C18: 120 | F18: 80 | I18: 360 | L18: 320 | O18: 160 | R18: 160 | U18: 360 | X18: 180 | AA18: 220 | AF18: =SUM(B18:AE18) -> 1960 | AG18: ='Facility Data'!D33 -> 581 | AH18: =AF18/AG18 -> 3.373494
A19: THOMAS JOHNSON HIGH | C19: 600 | F19: 420 | I19: 360 | L19: 1080 | O19: 120 | R19: 640 | U19: 640 | X19: 260 | AA19: 1260 | AF19: =SUM(C19:AE19) -> 5380 | AG19: ='Facility Data'!D43 -> 1632 | AH19: =AF19/AG19 -> 3.2965686
A20: SABILLASVILLE ELEMENTARY | E20: 120 | K20: 80 | Q20: 160 | W20: 140 | AF20: =SUM(B20:AE20) -> 500 | AG20: ='Facility Data'!D41 -> 157 | AH20: =AF20/AG20 -> 3.1847134
A21: MONOCACY MIDDLE | C21: 240 | F21: 260 | I21: 180 | L21: 320 | O21: 80 | R21: 500 | U21: 220 | X21: 340 | AA21: 280 | AF21: =SUM(B21:AE21) -> 2420 | AG21: ='Facility Data'!D29 -> 816 | AH21: =AF21/AG21 -> 2.9656863
A22: GREEN VALLEY ELEMENTARY | F22: 320 | L22: 400 | R22: 380 | X22: 240 | AF22: =SUM(B22:AE22) -> 1340 | AG22: ='Facility Data'!D16 -> 469 | AH22: =AF22/AG22 -> 2.8571429
A23: PARKWAY ELEMENTARY | B23: 300 | H23: 60 | N23: 280 | T23: 100 | Z23: 120 | AF23: =SUM(B23:AE23) -> 860 | AG23: ='Facility Data'!D39 -> 302 | AH23: =AF23/AG23 -> 2.8476821
A24: EMMITSBURG ELEMENTARY | E24: 240 | K24: 160 | Q24: 380 | W24: 180 | AF24: =SUM(B24:AE24) -> 960 | AG24: ='Facility Data'!D13 -> 342 | AH24: =AF24/AG24 -> 2.8070175
A25: FREDERICK HIGH | B25: 460 | D25: 380 | F25: 120 | H25: 520 | J25: 400 | L25: 520 | N25: 260 | P25: 80 | R25: 80 | T25: 480 | V25: 160 | X25: 100 | Z25: 560 | AF25: =SUM(B25:AE25) -> 4120 | AG25: ='Facility Data'!D14 -> 1500 | AH25: =AF25/AG25 -> 2.7466667
A26: CRESTWOOD MIDDLE | E26: 420 | K26: 260 | Q26: 500 | W26: 380 | AF26: =SUM(B26:AE26) -> 1560 | AG26: ='Facility Data'!D11 -> 573 | AH26: =AF26/AG26 -> 2.7225131
A27: BALLENGER CREEK ELEMENTARY | B27: 100 | E27: 80 | H27: 340 | K27: 160 | N27: 520 | Q27: 220 | T27: 180 | W27: 200 | Z27: 120 | AF27: =SUM(B27:AE27) -> 1920 | AG27: ='Facility Data'!D3 -> 738 | AH27: =AF27/AG27 -> 2.601626
A28: VALLEY ELEMENTARY | B28: 300 | H28: 320 | N28: 300 | T28: 80 | Z28: 220 | AF28: =SUM(B28:AE28) -> 1220 | AG28: ='Facility Data'!D54 -> 488 | AH28: =AF28/AG28 -> 2.5
A29: MIDDLETOWN MIDDLE | B29: 360 | E29: 280 | H29: 80 | K29: 240 | N29: 400 | Q29: 220 | T29: 320 | W29: 140 | Z29: 200 | AF29: =SUM(B29:AE29) -> 2240 | AG29: ='Facility Data'!D26 -> 914 | AH29: =AF29/AG29 -> 2.4507659
A30: THURMONT MIDDLE | B30: 220 | E30: 200 | H30: 180 | K30: 140 | N30: 60 | Q30: 240 | T30: 160 | W30: 220 | Z30: 260 | AF30: =SUM(B30:AE30) -> 1680 | AG30: ='Facility Data'!D46 -> 693 | AH30: =AF30/AG30 -> 2.4242424
A31: CATOCTIN HIGH | B31: 200 | E31: 160 | H31: 180 | K31: 240 | N31: 360 | Q31: 300 | T31: 520 | W31: 280 | Z31: 340 | AF31: =SUM(B31:AE31) -> 2580 | AG31: ='Facility Data'!D9 -> 1074 | AH31: =AF31/AG31 -> 2.4022346
A32: WALKERSVILLE MIDDLE | C32: 160 | F32: 280 | I32: 60 | L32: 260 | O32: 220 | R32: 240 | U32: 220 | X32: 400 | AA32: 140 | AF32: =SUM(B32:AE32) -> 1980 | AG32: ='Facility Data'!D58 -> 859 | AH32: =AF32/AG32 -> 2.3050058
A33: CENTERVILLE ELEMENTARY | C33: 200 | F33: 180 | I33: 140 | L33: 440 | O33: 200 | R33: 420 | U33: 200 | X33: 360 | AA33: 220 | AF33: =SUM(B33:AE33) -> 2360 | AG33: ='Facility Data'!D10 -> 1028 | AH33: =AF33/AG33 -> 2.2957198
A34: WAVERLY ELEMENTARY | B34: 100 | F34: 320 | H34: 60 | L34: 180 | N34: 340 | R34: 220 | T34: 160 | X34: 20 | Z34: 40 | AF34: =SUM(B34:AE34) -> 1440 | AG34: ='Facility Data'!D59 -> 637 | AH34: =AF34/AG34 -> 2.2605965
A35: MIDDLETOWN ELEMENTARY | B35: 220 | H35: 240 | N35: 340 | T35: 260 | Z35: 100 | AF35: =SUM(B35:AE35) -> 1160 | AG35: ='Facility Data'!D24 -> 537 | AH35: =AF35/AG35 -> 2.160149
A36: HILLCREST ELEMENTARY | C36: 140 | F36: 140 | I36: 260 | L36: 400 | O36: 120 | R36: 280 | U36: 260 | X36: 280 | AA36: 260 | AF36: =SUM(B36:AE36) -> 2140 | AG36: ='Facility Data'!D18 -> 998 | AH36: =AF36/AG36 -> 2.1442886
A37: OAKDALE HIGH | B37: 180 | E37: 240 | H37: 400 | K37: 320 | N37: 260 | Q37: 160 | T37: 460 | W37: 220 | Z37: 440 | AF37: =SUM(B37:AE37) -> 2680 | AG37: ='Facility Data'!D36 -> 1274 | AH37: =AF37/AG37 -> 2.1036107
A38: TUSCARORA HIGH | B38: 480 | E38: 320 | H38: 620 | K38: 280 | N38: 460 | Q38: 260 | T38: 320 | W38: 440 | Z38: 300 | AF38: =SUM(B38:AE38) -> 3480 | AG38: ='Facility Data'!D49 -> 1669 | AH38: =AF38/AG38 -> 2.0850809
A39: MIDDLETOWN HIGH | B39: 220 | E39: 240 | H39: 80 | K39: 260 | N39: 520 | Q39: 240 | T39: 480 | W39: 300 | Z39: 380 | AF39: =SUM(B39:AE39) -> 2720 | AG39: ='Facility Data'!D25 -> 1325 | AH39: =AF39/AG39 -> 2.0528302
A40: SPRING RIDGE ELEMENTARY | B40: 180 | E40: 80 | H40: 160 | K40: 60 | N40: 140 | Q40: 180 | T40: 120 | W40: 80 | Z40: 120 | AF40: =SUM(B40:AE40) -> 1120 | AG40: ='Facility Data'!D42 -> 563 | AH40: =AF40/AG40 -> 1.9893428
A41: YELLOW SPRINGS ELEMENTARY | B41: 220 | H41: 80 | N41: 340 | T41: 100 | Z41: 280 | AF41: =SUM(B41:AE41) -> 1020 | AG41: ='Facility Data'!D64 -> 514 | AH41: =AF41/AG41 -> 1.9844358
...

Sheet Monthly "Top Ten" Comparisons
B1: "Top Ten" Monthly Comparisons
B3: September | C3: pounds per capita | E3: October | F3: pounds per capita | H3: November | I3: pounds per capita
A4: 1 | B4: ROCK CREEK SCHOOL | C4: 12.99435 | E4: ROCK CREEK SCHOOL | F4: 12.99435 | H4: EMMITSBURG ELEMENTARY | I4: 10.643275
A5: 2 | B5: HEATHER RIDGE SCHOOL | C5: 6.2809917 | E5: HEATHER RIDGE SCHOOL | F5: 6.2809917 | H5: HEATHER RIDGE SCHOOL | I5: 6.1157025
A6: 3 | B6: ORCHARD GROVE ELEMENTARY | C6: 4.6330935 | E6: ORCHARD GROVE ELEMENTARY | F6: 4.6330935 | H6: LIBERTY ELEMENTARY | I6: 5.8682635
A7: 4 | B7: YELLOW SPRINGS ELEMENTARY | C7: 3.8132296 | E7: YELLOW SPRINGS ELEMENTARY | F7: 3.8132296 | H7: MONOCACY ELEMENTARY | I7: 5.3561254
A8: 5 | B8: MONOCACY ELEMENTARY | C8: 3.3903134 | E8: MONOCACY ELEMENTARY | F8: 3.3903134 | H8: ROCK CREEK SCHOOL | I8: 4.7457627
A9: 6 | B9: THOMAS JOHNSON HIGH | C9: 3.2965686 | E9: THOMAS JOHNSON HIGH | F9: 3.2965686 | H9: URBANA MIDDLE | I9: 4.6746988
A10: 7 | B10: WOODSBORO ELEMENTARY | C10: 3.1924883 | E10: WOODSBORO ELEMENTARY | F10: 3.1924883 | H10: KEMPTOWN ELEMENTARY | I10: 4.6153846
A11: 8 | B11: MIDDLETOWN MIDDLE | C11: 3.0415755 | E11: MIDDLETOWN MIDDLE | F11: 3.0415755 | H11: GREEN VALLEY ELEMENTARY | I11: 4.4776119
A12: 9 | B12: WOLFSVILLE ELEMENTARY | C12: 2.7751196 | E12: WOLFSVILLE ELEMENTARY | F12: 2.7751196 | H12: BALLENGER CREEK ELEMENTARY | I12: 4.3902439
A13: 10 | B13: NEW MIDWAY ELEMENTARY | C13: 2.7710843 | E13: NEW MIDWAY ELEMENTARY | F13: 2.7710843 | H13: MIDDLETOWN PRIMARY | I13: 4.3253235
B15: December | C15: pounds per capita | E15: January | F15: pounds per capita | H15: February | I15: pounds per capita
A16: 1 | B16: ROCK CREEK SCHOOL | C16: 6.779661 | E16: HEATHER RIDGE SCHOOL | F16: 7.107438 | H16: WOODSBORO ELEMENTARY | I16: 13.239437
A17: 2 | B17: WOODSBORO ELEMENTARY | C17: 5.915493 | E17: EMMITSBURG ELEMENTARY | F17: 7.0175439 | H17: HEATHER RIDGE SCHOOL | I17: 7.768595
A18: 3 | B18: LIBERTY ELEMENTARY | C18: 5.1497006 | E18: WOLFSVILLE ELEMENTARY | F18: 5.9330144 | H18: WOLFSVILLE ELEMENTARY | I18: 6.4114833
