Workbook
Name Inputall: Districts!$A$18:$T$355

Sheet Districts
A1: FY 2012 PENSION REDUCTIONS BASED ON PAID SALARIES
A4: 1 | B4: =A4+1 -> 2 | C4: =B4+1 -> 3 | D4: =C4+1 -> 4 | E4: =D4+1 -> 5 | F4: =E4+1 -> 6 | G4: =F4+1 -> 7 | H4: =G4+1 -> 8 | I4: =H4+1 -> 9 | ... R4: =Q4+1 -> 18
D6: A | E6: B | F6: C | G6: D | H6: E | I6: F | J6: G | K6: H | L6: I | M6: J | N6: K | O6: L | P6: M | Q6: N | R6: O | S6: P | T6: Q | U6: R | V6: S | W6: T
Q8: FY 2012 | R8: FY 2012
D9: ACTUAL | E9: ACTUAL | F9: ACTUAL | G9: ACTUAL | H9: ACTUAL | I9: ACTUAL | J9: ACTUAL | K9: ACTUAL | L9: ACTUAL | M9: ACTUAL | Q9: PENSION | R9: PENSION
D10: FY 1997 | E10: FY 2004 | F10: FY 2005 | G10: FY 2006 | H10: FY 2007 | I10: FY 2008 | J10: FY 2009 | K10: FY 2010 | L10: FY 2011 | M10: FY 2012 | Q10: REDUCT | R10: REDUCT
D11: TRA | E11: TRA | F11: TRA | G11: TRA | H11: TRA | I11: TRA | J11: TRA | K11: TRA | L11: TRA | M11: TRA | Q11: INITIAL | R11: REVISED
D12: SALARIES | E12: SALARIES | F12: SALARIES | G12: SALARIES | H12: SALARIES | I12: SALARIES | J12: SALARIES | K12: SALARIES | L12: SALARIES | M12: SALARIES | O12: FY 1997 | P12: OLD LAW | Q12: = .0234
D13: BASIC | E13: BASIC | F13: BASIC | G13: BASIC | H13: BASIC | I13: BASIC | J13: BASIC | K13: BASIC | L13: BASIC | M13: BASIC | N13: = MIN OF | O13: PERA | P13: PERA | Q13: =+"X "&+N6 -> X K | R13: =+"= "&+Q6 -> = N | W13: Adjustment
D14: +COORD | E14: +COORD | F14: +COORD | G14: +COORD | H14: +COORD | I14: +COORD | J14: +COORD | K14: +COORD | L14: +COORD | M14: +COORD | N14: =+D6&" TO "&+M6 -> A TO J | O14: SALARIES | P14: ADJUST | Q14: =+"-.007*"&+$O6&"-"&+$P6 -> -.007*L-M | R14: =+"- .005 X "&+H6 -> - .005 X E | S14: =+"= .0234 X "&+N6 -> = .0234 X K | T14: =+"= .007 X "&+O6 -> = .007 X L | U14: =+"= "&+P6 -> = M | V14: =+"= .005 X "&+H6 -> = .005 X E | W14: =+"= "&+S6&"-"&+T6&"-"&+U6&"-"&+V6 -> = P-Q-R-S
C16: TOTAL, TYPES 1,2,3 | D16: =SUM(D18:D356) -> 2.0622264e+09 | E16: =SUM(E18:E356) -> 2.7052684e+09 | F16: =SUM(F18:F356) -> 2.7901219e+09 | G16: =SUM(G18:G356) -> 2.8606904e+09 | H16: =SUM(H18:H356) -> 3.1943642e+09 | I16: =SUM(I18:I356) -> 3.2585138e+09 | J16: =SUM(J18:J356) -> 3.4115901e+09 | K16: =SUM(K18:K356) -> 3.4456945e+09 | ... W16: =SUM(W18:W356) -> 29484217
A18: 1 | B18: 1 | C18: AITKIN | D18: 3647845.6 | E18: 4885983.7 | F18: 4798162.7 | G18: 4807053.8 | H18: 4599241.5 | I18: 4619045.8 | J18: 4742971.7 | K18: 4816898.9 | L18: 4528039.4 | M18: 4501522.7 | N18: =MIN(D18:M18) -> 3647845.6 | O18: 1166307 | P18: -6434.05 | Q18: =ROUND(0.0234*N18,2)-ROUND(0.007*O18,2)-P18 -> 83629.49 | R18: =ROUND(Q18-0.005*H18,2) -> 60633.28 | S18: =0.0234*N18 -> 85359.587 | T18: =0.007*O18 -> 8164.149 | U18: =P18 -> -6434.05 | V18: =0.005*H18 -> 22996.207 | W18: =S18-T18-U18-V18 -> 60633.281
A19: 1.2 | B19: 3 | C19: MINNEAPOLIS | D19: 0 | E19: 0 | F19: 0 | G19: 0 | H19: 197593500 | I19: 1.7607689e+08 | J19: 2.151053e+08 | K19: 2.1889332e+08 | L19: 2.2448269e+08 | M19: 2.29695e+08 | N19: =MIN(D19:M19) -> 0 | O19: 65485910 | P19: -105933.19 | Q19: =ROUND(0.0234*N19,2)-ROUND(0.007*O19,2)-P19 -> -352468.18 | R19: =ROUND(Q19-0.005*H19,2) -> -1340435.7 | S19: =0.0234*N19 -> 0 | T19: =0.007*O19 -> 458401.37 | U19: =P19 -> -105933.19 | V19: =0.005*H19 -> 987967.5 | W19: =S19-T19-U19-V19 -> -1340435.7
A20: 2 | B20: 1 | C20: HILL CITY | D20: 1223765.8 | E20: 1627340.5 | F20: 1609375.7 | G20: 1572961.8 | H20: 1606309.1 | I20: 1673129.2 | J20: 1780829.1 | K20: 1789667.6 | L20: 1695388 | M20: 1669105.8 | N20: =MIN(D20:M20) -> 1223765.8 | O20: 248322 | P20: -1400.81 | Q20: =ROUND(0.0234*N20,2)-ROUND(0.007*O20,2)-P20 -> 28298.68 | R20: =ROUND(Q20-0.005*H20,2) -> 20267.13 | S20: =0.0234*N20 -> 28636.119 | T20: =0.007*O20 -> 1738.254 | U20: =P20 -> -1400.81 | V20: =0.005*H20 -> 8031.5457 | W20: =S20-T20-U20-V20 -> 20267.129
A21: 4 | B21: 1 | C21: MCGREGOR | D21: 1846090.4 | E21: 2456679.5 | F21: 2432200.8 | G21: 2302948.5 | H21: 2240887.7 | I21: 2004998.7 | J21: 1948443.4 | K21: 1952577.7 | L21: 2035336.2 | M21: 1912764.3 | N21: =MIN(D21:M21) -> 1846090.4 | O21: 621370 | P21: -4027.95 | Q21: =ROUND(0.0234*N21,2)-ROUND(0.007*O21,2)-P21 -> 42876.88 | R21: =ROUND(Q21-0.005*H21,2) -> 31672.44 | S21: =0.0234*N21 -> 43198.516 | T21: =0.007*O21 -> 4349.59 | U21: =P21 -> -4027.95 | V21: =0.005*H21 -> 11204.438 | W21: =S21-T21-U21-V21 -> 31672.438
A22: 6 | B22: 3 | C22: SOUTH ST. PAUL | D22: 9238989.8 | E22: 11110590 | F22: 12230695 | G22: 13210125 | H22: 14633928 | I22: 15690590 | J22: 14327012 | K22: 15816431 | L22: 16370856 | M22: 16269960 | N22: =MIN(D22:M22) -> 9238989.8 | O22: 3949823 | P22: -14381.23 | Q22: =ROUND(0.0234*N22,2)-ROUND(0.007*O22,2)-P22 -> 202924.83 | R22: =ROUND(Q22-0.005*H22,2) -> 129755.19 | S22: =0.0234*N22 -> 216192.36 | T22: =0.007*O22 -> 27648.761 | U22: =P22 -> -14381.23 | V22: =0.005*H22 -> 73169.638 | W22: =S22-T22-U22-V22 -> 129755.19
A23: 11 | B23: 1 | C23: ANOKA-HENNEPIN | D23: 1.1368176e+08 | E23: 1.614175e+08 | F23: 1.6833668e+08 | G23: 1.7973083e+08 | H23: 1.863098e+08 | I23: 1.9055513e+08 | J23: 1.9806326e+08 | K23: 1.9485844e+08 | L23: 1.8850242e+08 | M23: 1.896328e+08 | N23: =MIN(D23:M23) -> 1.1368176e+08 | O23: 33786411 | P23: -124260.58 | Q23: =ROUND(0.0234*N23,2)-ROUND(0.007*O23,2)-P23 -> 2547908.9 | R23: =ROUND(Q23-0.005*H23,2) -> 1616359.9 | S23: =0.0234*N23 -> 2660153.2 | T23: =0.007*O23 -> 236504.88 | U23: =P23 -> -124260.58 | V23: =0.005*H23 -> 931549.02 | W23: =S23-T23-U23-V23 -> 1616359.9
A24: 12 | B24: 1 | C24: CENTENNIAL | D24: 17493477 | E24: 24105375 | F24: 23716422 | G24: 24262660 | H24: 27065663 | I24: 28721694 | J24: 29561008 | K24: 30192261 | L24: 28665360 | M24: 27148643 | N24: =MIN(D24:M24) -> 17493477 | O24: 4365753 | P24: -10737.83 | Q24: =ROUND(0.0234*N24,2)-ROUND(0.007*O24,2)-P24 -> 389524.93 | R24: =ROUND(Q24-0.005*H24,2) -> 254196.62 | S24: =0.0234*N24 -> 409347.37 | T24: =0.007*O24 -> 30560.271 | U24: =P24 -> -10737.83 | V24: =0.005*H24 -> 135328.31 | W24: =S24-T24-U24-V24 -> 254196.61
A25: 13 | B25: 1 | C25: COLUMBIA HEIGHTS | D25: 9519853.8 | E25: 10239105 | F25: 10758697 | G25: 11396854 | H25: 12611327 | I25: 13636045 | J25: 14076939 | K25: 12373432 | L25: 14056602 | M25: 15832980 | N25: =MIN(D25:M25) -> 9519853.8 | O25: 3579846 | P25: -13109.75 | Q25: =ROUND(0.0234*N25,2)-ROUND(0.007*O25,2)-P25 -> 210815.41 | R25: =ROUND(Q25-0.005*H25,2) -> 147758.78 | S25: =0.0234*N25 -> 222764.58 | T25: =0.007*O25 -> 25058.922 | U25: =P25 -> -13109.75 | V25: =0.005*H25 -> 63056.633 | W25: =S25-T25-U25-V25 -> 147758.77
A26: 14 | B26: 1 | C26: FRIDLEY | D26: 9244265.7 | E26: 10639739 | F26: 10433025 | G26: 11736805 | H26: 11875701 | I26: 12693423 | J26: 13904463 | K26: 13907139 | L26: 14166647 | M26: 14744056 | N26: =MIN(D26:M26) -> 9244265.7 | O26: 2793718 | P26: -9074.54 | Q26: =ROUND(0.0234*N26,2)-ROUND(0.007*O26,2)-P26 -> 205834.33 | R26: =ROUND(Q26-0.005*H26,2) -> 146455.82 | S26: =0.0234*N26 -> 216315.82 | T26: =0.007*O26 -> 19556.026 | U26: =P26 -> -9074.54 | V26: =0.005*H26 -> 59378.506 | W26: =S26-T26-U26-V26 -> 146455.83
A27: 15 | B27: 1 | C27: ST. FRANCIS | D27: 15225185 | E27: 20289693 | F27: 20951666 | G27: 22286379 | H27: 24417098 | I27: 26021613 | J27: 25689420 | K27: 25063660 | L27: 24948637 | M27: 23951524 | N27: =MIN(D27:M27) -> 15225185 | O27: 6145390 | P27: -19213.53 | Q27: =ROUND(0.0234*N27,2)-ROUND(0.007*O27,2)-P27 -> 332465.12 | R27: =ROUND(Q27-0.005*H27,2) -> 210379.63 | S27: =0.0234*N27 -> 356269.32 | T27: =0.007*O27 -> 43017.73 | U27: =P27 -> -19213.53 | V27: =0.005*H27 -> 122085.49 | W27: =S27-T27-U27-V27 -> 210379.63
A28: 16 | B28: 1 | C28: SPRING LAKE PARK | D28: 11770914 | E28: 14553558 | F28: 15685826 | G28: 17136862 | H28: 18133714 | I28: 19271200 | J28: 20036070 | K28: 20324370 | L28: 20549943 | M28: 20562135 | N28: =MIN(D28:M28) -> 11770914 | O28: 4276269 | P28: -17891.84 | Q28: =ROUND(0.0234*N28,2)-ROUND(0.007*O28,2)-P28 -> 263397.35 | R28: =ROUND(Q28-0.005*H28,2) -> 172728.78 | S28: =0.0234*N28 -> 275439.39 | T28: =0.007*O28 -> 29933.883 | U28: =P28 -> -17891.84 | V28: =0.005*H28 -> 90668.571 | W28: =S28-T28-U28-V28 -> 172728.77
A29: 22 | B29: 1 | C29: DETROIT LAKES | D29: 9183161.5 | E29: 11394483 | F29: 11294661 | G29: 11008753 | H29: 11546778 | I29: 11807378 | J29: 12626711 | K29: 12980365 | L29: 13132844 | M29: 13674265 | N29: =MIN(D29:M29) -> 9183161.5 | O29: 2157218 | P29: -9224.11 | Q29: =ROUND(0.0234*N29,2)-ROUND(0.007*O29,2)-P29 -> 209009.56 | R29: =ROUND(Q29-0.005*H29,2) -> 151275.67 | S29: =0.0234*N29 -> 214885.98 | T29: =0.007*O29 -> 15100.526 | U29: =P29 -> -9224.11 | V29: =0.005*H29 -> 57733.892 | W29: =S29-T29-U29-V29 -> 151275.67
... A297: 2155 | B297: 1 | C297: WADENA-DEER CREEK | D297: 4734630.1 | E297: 5083435.9 | F297: 5129373.6 | G297: 5155451.1 | H297: 5031920 | I297: 4735492.4 | J297: 4752346 | K297: 4536880.5 | L297: 4576635 | M297: 4503669.2 | N297: =MIN(D297:M297) -> 4503669.2 | O297: 1206576 | P297: -3679.64 | Q297: =ROUND(0.0234*N297,2)-ROUND(0.007*O297,2)-P297 -> 100619.47 | R297: =ROUND(Q297-0.005*H297,2) -> 75459.87 | S297: =0.0234*N297 -> 105385.86 | T297: =0.007*O297 -> 8446.032 | U297: =P297 -> -3679.64 | V297: =0.005*H297 -> 25159.6 | W297: =S297-T297-U297-V297 -> 75459.866
A298: 2159 | B298: 1 | C298: BUFFALO LAKE-HECTOR | D298: ='Consolidate 2887'!D30 -> 1661401 | E298: 2763773.5 | F298: 2731661.2 | G298: 2775715.6 | H298: ='Consolidate 2887'!D33 -> 2449272.4 | I298: 2824581.5 | J298: 2875401.4 | K298: 2655495.7 | L298: 2766600.3 | M298: 2790408.5 | N298: =MIN(D298:M298) -> 1661401 | O298: ='Consolidate 2887'!D49 -> 412779.5 | P298: ='Consolidate 2887'!D50 -> -3254.7 | Q298: =ROUND(0.0234*N298,2)-ROUND(0.007*O298,2)-P298 -> 39242.02 | R298: =ROUND(Q298-0.005*H298,2) -> 26995.66 | S298: =0.0234*N298 -> 38876.784 | T298: =0.007*O298 -> 2889.4565 | U298: =P298 -> -3254.7 | V298: =0.005*H298 -> 12246.362 | W298: =S298-T298-U298-V298 -> 26995.665
A299: 2164 | B299: 1 | C299: DILWORTH-GLYNDON | D299: 3696577.1 | E299: 4791515.4 | F299: 4925796.3 | G299: 5093598.5 | H299: 5205367.4 | I299: 5236509.9 | J299: 5591672.5 | K299: 5875671.1 | L299: 5964517.5 | M299: 6451032.8 | N299: =MIN(D299:M299) -> 3696577.1 | O299: 787894 | P299: -4045.52 | Q299: =ROUND(0.0234*N299,2)-ROUND(0.007*O299,2)-P299 -> 85030.16 | R299: =ROUND(Q299-0.005*H299,2) -> 59003.32 | S299: =0.0234*N299 -> 86499.904 | T299: =0.007*O299 -> 5515.258 | U299: =P299 -> -4045.52 | V299: =0.005*H299 -> 26026.837 | W299: =S299-T299-U299-V299 -> 59003.329
A300: 2165 | B300: 1 | C300: HINCKLEY-FINLAYS | D300: 3066155.2 | E300: 4054669.5 | F300: 3859697.8 | G300: 3890690.3 | H300: 3973107.6 | I300: 4167053.1 | J300: 4462394.1 | K300: 4491916.3 | L300: 4530856.7 | M300: 4602876.5 | N300: =MIN(D300:M300) -> 3066155.2 | O300: 871954 | P300: -4364.84 | Q300: =ROUND(0.0234*N300,2)-ROUND(0.007*O300,2)-P300 -> 70009.19 | R300: =ROUND(Q300-0.005*H300,2) -> 50143.65 | S300: =0.0234*N300 -> 71748.032 | T300: =0.007*O300 -> 6103.678 | U300: =P300 -> -4364.84 | V300: =0.005*H300 -> 19865.538 | W300: =S300-T300-U300-V300 -> 50143.656
A301: 2167 | B301: 1 | C301: LAKEVIEW | D301: 1580208.4 | E301: 1830494.7 | F301: 1688394.4 | G301: 1950499.8 | H301: 2103956.7 | I301: 2157781.7 | J301: 2355849.1 | K301: 2389448.4 | L301: 2410490.7 | M301: 2482156.3 | N301: =MIN(D301:M301) -> 1580208.4 | O301: 459054 | P301: -2053.77 | Q301: =ROUND(0.0234*N301,2)-ROUND(0.007*O301,2)-P301 -> 35817.27 | R301: =ROUND(Q301-0.005*H301,2) -> 25297.49 | S301: =0.0234*N301 -> 36976.877 | T301: =0.007*O301 -> 3213.378 | U301: =P301 -> -2053.77 | V301: =0.005*H301 -> 10519.784 | W301: =S301-T301-U301-V301 -> 25297.486
A302: 2168 | B302: 1 | C302: NRHEG | D302: 2857396.2 | E302: 3652135.1 | F302: 3821658.2 | G302: 3691134.2 | H302: 3774534 | I302: 3741887.9 | J302: 3805591.6 | K302: 3615081.1 | L302: 3567491.8 | M302: 3730994.8 | N302: =MIN(D302:M302) -> 2857396.2 | O302: 549739 | P302: -3324.78 | Q302: =ROUND(0.0234*N302,2)-ROUND(0.007*O302,2)-P302 -> 66339.68 | R302: =ROUND(Q302-0.005*H302,2) -> 47467.01 | S302: =0.0234*N302 -> 66863.072 | T302: =0.007*O302 -> 3848.173 | U302: =P302 -> -3324.78 | V302: =0.005*H302 -> 18872.67 | W302: =S302-T302-U302-V302 -> 47467.009
A303: 2169 | B303: 1 | C303: MURRAY COUNTY | D303: 2515898.4 | E303: 2778986.8 | F303: 2847871.5 | G303: 2827302.3 | H303: 2878468.6 | I303: 3057957.1 | J303: 3215053.6 | K303: 3275740.7 | L303: 3079717 | M303: 3030710.4 | N303: =MIN(D303:M303) -> 2515898.4 | O303: 795522 | P303: -4528.91 | Q303: =ROUND(0.0234*N303,2)-ROUND(0.007*O303,2)-P303 -> 57832.28 | R303: =ROUND(Q303-0.005*H303,2) -> 43439.94 | S303: =0.0234*N303 -> 58872.022 | T303: =0.007*O303 -> 5568.654 | U303: =P303 -> -4528.91 | V303: =0.005*H303 -> 14392.343 | W303: =S303-T303-U303-V303 -> 43439.935
A304: 2170 | B304: 1 | C304: STAPLES-MOTLEY | D304: 4770417.4 | E304: 5292621.4 | F304: 5657821.3 | G304: 5651066.7 | H304: 5354156.7 | I304: 4956433.3 | J304: 5113479.2 | K304: 5199491.4 | L304: 5046033.9 | M304: 5206702 | N304: =MIN(D304:M304) -> 4770417.4 | O304: 1906241 | P304: -9898.14 | Q304: =ROUND(0.0234*N304,2)-ROUND(0.007*O304,2)-P304 -> 108182.22 | R304: =ROUND(Q304-0.005*H304,2) -> 81411.44 | S304: =0.0234*N304 -> 111627.77 | T304: =0.007*O304 -> 13343.687 | U304: =P304 -> -9898.14 | V304: =0.005*H304 -> 26770.783 | W304: =S304-T304-U304-V304 -> 81411.438
A305: 2171 | B305: 1 | C305: KITTSON CENTRAL | D305: 1585722.9 | E305: 1772621.4 | F305: 1879726.2 | G305: 1802848.4 | H305: 1732942.4 | I305: 1480382.5 | J305: 1728984 | K305: 1717112.9 | L305: 1552904.5 | M305: 1588826.4 | N305: =MIN(D305:M305) -> 1480382.5 | O305: 411428 | P305: -3251.28 | Q305: =ROUND(0.0234*N305,2)-ROUND(0.007*O305,2)-P305 -> 35012.23 | R305: =ROUND(Q305-0.005*H305,2) -> 26347.52 | S305: =0.0234*N305 -> 34640.95 | T305: =0.007*O305 -> 2879.996 | U305: =P305 -> -3251.28 | V305: =0.005*H305 -> 8664.7118 | W305: =S305-T305-U305-V305 -> 26347.523
A306: 2172 | B306: 1 | C306: KENYON-WANAMINGO | D306: 2384412 | E306: 2860169.6 | F306: 2815783.9 | G306: 2544619.5 | H306: 2707427.2 | I306: 2730159.9 | J306: 2891382.1 | K306: 2773652 | L306: 2757163 | M306: 2859411.5 | N306: =MIN(D306:M306) -> 2384412 | O306: 469598 | P306: -2737.63 | Q306: =ROUND(0.0234*N306,2)-ROUND(0.007*O306,2)-P306 -> 55245.68 | R306: =ROUND(Q306-0.005*H306,2) -> 41708.54 | S306: =0.0234*N306 -> 55795.241 | T306: =0.007*O306 -> 3287.186 | U306: =P306 -> -2737.63 | V306: =0.005*H306 -> 13537.136 | W306: =S306-T306-U306-V306 -> 41708.549
A307: 2174 | B307: 1 | C307: PINE RIVER-BACKU | D307: 3015240.8 | E307: 4698963.4 | F307: 4561147.9 | G307: 4655637.5 | H307: 4652260.1 | I307: 4575523 | J307: 4616822.3 | K307: 4414633.7 | L307: 4044980.9 | M307: 4083033.4 | N307: =MIN(D307:M307) -> 3015240.8 | O307: 1079776 | P307: -4545.3 | Q307: =ROUND(0.0234*N307,2)-ROUND(0.007*O307,2)-P307 -> 67543.51 | R307: =ROUND(Q307-0.005*H307,2) -> 44282.21 | S307: =0.0234*N307 -> 70556.635 | T307: =0.007*O307 -> 7558.432 | U307: =P307 -> -4545.3 | V307: =0.005*H307 -> 23261.3 | W307: =S307-T307-U307-V307 -> 44282.203
A308: 2176 | B308: 1 | C308: WARREN-ALVARADO- | D308: 2368487.9 | E308: 2600748.9 | F308: 2421786.9 | G308: 2370034.8 | H308: 2464717.8 | I308: 2449729.7 | J308: 2482018.1 | K308: 2425462.6 | L308: 2505531.8 | M308: 2335471 | N308: =MIN(D308:M308) -> 2335471 | O308: 515143 | P308: -4057.97 | Q308: =ROUND(0.0234*N308,2)-ROUND(0.007*O308,2)-P308 -> 55101.99 | R308: =ROUND(Q308-0.005*H308,2) -> 42778.4 | S308: =0.0234*N308 -> 54650.022 | T308: =0.007*O308 -> 3606.001 | U308: =P308 -> -4057.97 | V308: =0.005*H308 -> 12323.589 | W308: =S308-T308-U308-V308 -> 42778.402
A309: 2180 | B309: 1 | C309: MACCRAY | D309: 2948794.5 | E309: 3386544.8 | F309: 3477853.2 | G309: 3578128.4 | H309: 3427662.1 | I309: 3370186 | J309: 3301924.3 | K309: 3305042.5 | L309: 3280601.6 | M309: 3206115.6 | N309: =MIN(D309:M309) -> 2948794.5 | O309: 872043 | P309: -4030.87 | Q309: =ROUND(0.0234*N309,2)-ROUND(0.007*O309,2)-P309 -> 66928.36 | R309: =ROUND(Q309-0.005*H309,2) -> 49790.05 | S309: =0.0234*N309 -> 69001.791 | T309: =0.007*O309 -> 6104.301 | U309: =P309 -> -4030.87 | V309: =0.005*H309 -> 17138.311 | W309: =S309-T309-U309-V309 -> 49790.05
A310: 2184 | B310: 1 | C310: LUVERNE | D310: 4036957.3 | E310: 4935966 | F310: 4826126.1 | G310: 4876595.7 | H310: 5048786.8 | I310: 5283621.1 | J310: 5532696.1 | K310: 5556198.6 | L310: 5605682.7 | M310: 5686141.8 | N310: =MIN(D310:M310) -> 4036957.3 | O310: 1069935 | P310: -5556.67 | Q310: =ROUND(0.0234*N310,2)-ROUND(0.007*O310,2)-P310 -> 92531.92 | R310: =ROUND(Q310-0.005*H310,2) -> 67287.99 | S310: =0.0234*N310 -> 94464.801 | T310: =0.007*O310 -> 7489.545 | U310: =P310 -> -5556.67 | V310: =0.005*H310 -> 25243.934 | W310: =S310-T310-U310-V310 -> 67287.992
... A318: 2364 | B318: 1 | C318: BELGRADE-BROOTEN-ELR | D318: 2586157.3 | E318: 3036965.7 | F318: 3102285 | G318: 3076074.3 | H318: 3017321 | I318: 2892359.8 | J318: 2879170.8 | K318: 2900880.9 | L318: 2822416.8 | M318: 2831630.6 | N318: =MIN(D318:M318) -> 2586157.3 | O318: 704988 | P318: -3815.5 | Q318: =ROUND(0.0234*N318,2)-ROUND(0.007*O318,2)-P318 -> 59396.66 | R318: =ROUND(Q318-0.005*H318,2) -> 44310.06 | S318: =0.0234*N318 -> 60516.081 | T318: =0.007*O318 -> 4934.916 | U318: =P318 -> -3815.5 | V318: =0.005*H318 -> 15086.605 | W318: =S318-T318-U318-V318 -> 44310.06
A319: 2365 | B319: 1 | C319: G.F.W. | D319: ='Consolidate 2887'!E30 -> 2951898.3 | E319: 3359494.2 | F319: 3370013.5 | G319: 3190546.1 | H319: ='Consolidate 2887'!E33 -> 3527785.5 | I319: 3291327.2 | J319: 3206053.4 | K319: 3277582.6 | L319: 3274991.8 | M319: 3284205.2 | N319: =MIN(D319:M319) -> 2951898.3 | O319: ='Consolidate 2887'!E49 -> 1015312.5 | P319: ='Consolidate 2887'!E50 -> -3569.25 | Q319: =ROUND(0.0234*N319,2)-ROUND(0.007*O319,2)-P319 -> 65536.48 | R319: =ROUND(Q319-0.005*H319,2) -> 47897.55 | S319: =0.0234*N319 -> 69074.42 | T319: =0.007*O319 -> 7107.1875 | U319: =P319 -> -3569.25 | V319: =0.005*H319 -> 17638.927 | W319: =S319-T319-U319-V319 -> 47897.555
A320: 2396 | B320: 1 | C320: A.C.G.C. | D320: 2566913.4 | E320: 3600804.1 | F320: 3698708.8 | G320: 3478063.7 | H320: 3386321.1 | I320: 3174009.3 | J320: 3411064.1 | K320: 3411188 | L320: 3350648.8 | M320: 3428403.1 | N320: =MIN(D320:M320) -> 2566913.4 | O320: 879033 | P320: -4080.73 | Q320: =ROUND(0.0234*N320,2)-ROUND(0.007*O320,2)-P320 -> 57993.27 | R320: =ROUND(Q320-0.005*H320,2) -> 41061.66 | S320: =0.0234*N320 -> 60065.774 | T320: =0.007*O320 -> 6153.231 | U320: =P320 -> -4080.73 | V320: =0.005*H320 -> 16931.606 | W320: =S320-T320-U320-V320 -> 41061.668
...

Sheet Report
A1: 2159
A3: FY 2011 Pension Adjustment | E3: Notes
A4: =VLOOKUP($A$1,Inputall,3)&" #"&FIXED(A1,0,TRUE) -> BUFFALO LAKE-HECTOR #2159
A6: 1 | B6: Actual TRA salaries, basic + coordinated, FY 1997 | C6: =VLOOKUP($A$1,Inputall,I6,FALSE) -> 1661401 | I6: 4
A7: =A6+1 -> 2 | B7: Actual TRA salaries, basic + coordinated, FY 2004 | C7: =VLOOKUP($A$1,Inputall,I7,FALSE) -> 2763773.5 | I7: 5
A8: =A7+1 -> 3 | B8: Actual TRA salaries, basic + coordinated, FY 2005 | C8: =VLOOKUP($A$1,Inputall,I8,FALSE) -> 2731661.2 | I8: 6
A9: =A8+1 -> 4 | B9: Actual TRA salaries, basic + coordinated, FY 2006 | C9: =VLOOKUP($A$1,Inputall,I9,FALSE) -> 2775715.6 | I9: 7
A10: =A9+1 -> 5 | B10: Actual TRA salaries, basic + coordinated, FY 2007 | C10: =VLOOKUP($A$1,Inputall,I10,FALSE) -> 2449272.4 | I10: 8
A11: =A10+1 -> 6 | B11: Actual TRA salaries, basic + coordinated, FY 2008 | C11: =VLOOKUP($A$1,Inputall,I11,FALSE) -> 2824581.5 | I11: 9
A12: =A11+1 -> 7 | B12: Actual TRA salaries, basic + coordinated, FY 2009 | C12: =VLOOKUP($A$1,Inputall,I12,FALSE) -> 2875401.4 | I12: 10
A13: =A12+1 -> 8 | B13: Actual TRA salaries, basic + coordinated, FY 2010 | C13: =VLOOKUP($A$1,Inputall,I13,FALSE) -> 2655495.7 | I13: 11
A14: =A13+1 -> 9 | B14: =+"Basis for clause 3 adjustment = minimum of ("&FIXED(A6,0)&") to ("&FIXED(A13,0)&") =" -> Basis for clause 3 adjustment = minimum of (1) to (8) = | C14: =MIN(C6:C13) -> 1661401
A16: =A14+1 -> 10 | B16: PERA salaries, FY 1997 | C16: =VLOOKUP($A$1,Inputall,I16,FALSE) -> 412779.5 | I16: 15
A17: =A16+1 -> 11 | B17: Old law PERA adjustment | C17: =VLOOKUP($A$1,Inputall,I17,FALSE) -> -3254.7 | I17: 16
A19: =A17+1 -> 12 | B19: =+"Clause 1 adjustment = ("&FIXED(A17,0)&") =" -> Clause 1 adjustment = (11) = | C19: =C17 -> -3254.7
A20: =A19+1 -> 13 | B20: =+"Clause 2 adjustment = .007 x ("&FIXED(A16,0)&") =" -> Clause 2 adjustment = .007 x (10) = | C20: =ROUND(0.007*C16,2) -> 2889.46
A21: =A20+1 -> 14 | B21: =+"Clause 3 adjustment = - .0234 x ("&FIXED(A14,0)&") =" -> Clause 3 adjustment = - .0234 x (9) = | C21: =ROUND(-0.0234*C14,2) -> -38876.78
A22: =A21+1 -> 15 | B22: =+"Clause 4 adjustment = .005 x ("&FIXED(A10,0)&") =" -> Clause 4 adjustment = .005 x (5) = | C22: =ROUND(0.005*C10,2) -> 12246.36
A24: =A22+1 -> 16 | B24: =+"Total adjustment = ("&FIXED(A19,0)&")+("&FIXED(A20,0)&")+("&FIXED(A21,0)&")+("&FIXED(A22,0)&") =" -> Total adjustment = (12)+(13)+(14)+(15) = | C24: =C19+C20+C21+C22 -> -26995.66

Sheet Consolidate 2903 2904
C1: 62 | D1: 371 | E1: 2903
C2: 1 | D2: 1 | E2: 1
C3: ORTONVILLE | D3: BELLINGHAM | E3: ORTONVILLE | G3: Notes
A5: 1 | B5: PERA salaries, FY 1997 | C5: 709929 | D5: 146336 | E5: =C5+D5 -> 856265 | G5: sum of separate districts
A6: =A5+1 -> 2 | B6: PERA adjustment, old law | C6: -4605.15 | D6: -1231.9 | E6: =C6+D6 -> -5837.05 | G6: sum of separate districts
A8: =A6+1 -> 3 | B8: TRA basic + coordinated salaries, FY 1997 | C8: 1958078.8 | D8: 392486.56 | E8: =C8+D8 -> 2350565.4 | G8: sum of separate districts
A9: =A8+1 -> 4 | B9: TRA basic + coordinated salaries, FY 2004 | C9: 2395980 | D9: 419699.35 | E9: =C9+D9 -> 2815679.3 | G9: sum of separate districts
A10: =A9+1 -> 5 | B10: TRA basic + coordinated salaries, FY 2005 | C10: 2469370.7 | D10: 349493.78 | E10: =C10+D10 -> 2818864.5 | G10: sum of separate districts
A11: =A10+1 -> 6 | B11: TRA basic + coordinated salaries, FY 2006 | C11: 2296845.4 | D11: 332433.46 | E11: =C11+D11 -> 2629278.9 | G11: sum of separate districts
A12: =A11+1 -> 7 | B12: TRA basic + coordinated salaries, FY 2007 | C12: 2267926 | D12: 356373.85 | E12: =C12+D12 -> 2624299.9 | G12: sum of separate districts
A13: =A12+1 -> 8 | B13: TRA basic + coordinated salaries, FY 2008 | C13: 2348979.1 | D13: 364217.52 | E13: =C13+D13 -> 2713196.6 | G13: sum of separate districts
A14: =A13+1 -> 9 | B14: TRA basic + coordinated salaries, FY 2009 | C14: 2706703.5 | D14: 472638.17 | E14: =C14+D14 -> 3179341.7 | G14: sum of separate districts
A15: =A14+1 -> 10 | B15: TRA basic + coordinated salaries, FY 2010 | C15: n/a | D15: n/a | E15: 2323451.6 | G15: total for new district
A17: =A15+1 -> 11 | B17: =+"Minimum of ("&FIXED(A8,0)&") to ("&FIXED(A14,0)&") =" -> Minimum of (3) to (9) = | C17: =MIN(C8:C14) -> 1958078.8 | D17: =MIN(D8:D14) -> 332433.46 | E17: n/a
A18: =A17+1 -> 12 | B18: =+"Minimum of ("&FIXED(A8,0)&") to ("&FIXED(A15,0)&") =" -> Minimum of (3) to (10) = | C18: n/a | D18: n/a | E18: =MIN(E8:E15) -> 2323451.6
A20: =A18+1 -> 13 | B20: ="FY 2009 salary total for Ortonville as separate district based on ("&FIXED(A17,0)&"):" -> FY 2009 salary total for Ortonville as separate district based on (11): | E20: =C17 -> 1958078.8 | G20: The salary basis should not
A21: =A20+1 -> 14 | B21: ="FY 2009 salary total for Bellingham as separate district based on ("&FIXED(A17,0)&"):" -> FY 2009 salary total for Bellingham as separate district based on (11): | E21: =D17 -> 332433.46 | G21: be more for the new districts
A22: =A21+1 -> 15 | B22: =+"FY 2009 salary total, combined = ("&FIXED(A20,0)&")+("&FIXED(A21,0)&") =" -> FY 2009 salary total, combined = (13)+(14) = | E22: =E20+E21 -> 2290512.3 | G22: than it was in total for
G23: for old districts.
A24: =A22+1 -> 16 | B24: =+"FY 2010 salary total based on ("&FIXED(A18,0)&") =" -> FY 2010 salary total based on (12) = | E24: =E18 -> 2323451.6
A26: =A24+1 -> 17 | B26: =+"FY 2010 salary total, revised = lesser of ("&FIXED(A22,0)&") or ("&FIXED(A24,0)&") =" -> FY 2010 salary total, revised = lesser of (15) or (16) = | E26: =MIN(E22,E24) -> 2290512.3
C29: 411 | D29: 417 | E29: 2904
C30: 1 | D30: 1 | E30: 1
C31: BALATON | D31: TRACY | E31: TRACY-BALATON | G31: Notes
A33: =A26+1 -> 18 | B33: PERA salaries, FY 1997 | C33: 189196 | D33: 795109 | E33: =C33+D33 -> 984305 | G33: sum of separate districts
A34: =A33+1 -> 19 | B34: PERA adjustment, old law | C34: -1273.33 | D34: -4033.11 | E34: =C34+D34 -> -5306.44 | G34: sum of separate districts
A36: =A34+1 -> 20 | B36: TRA basic + coordinated salaries, FY 1997 | C36: 664750.83 | D36: 2359775.4 | E36: =C36+D36 -> 3024526.2 | G36: sum of separate districts
A37: =A36+1 -> 21 | B37: TRA basic + coordinated salaries, FY 2004 | C37: 369579.01 | D37: 2734119.7 | E37: =C37+D37 -> 3103698.7 | G37: sum of separate districts
A38: =A37+1 -> 22 | B38: TRA basic + coordinated salaries, FY 2005 | C38: 338185.38 | D38: 2936947 | E38: =C38+D38 -> 3275132.4 | G38: sum of separate districts
A39: =A38+1 -> 23 | B39: TRA basic + coordinated salaries, FY 2006 | C39: 375891.23 | D39: 3008825.4 | E39: =C39+D39 -> 3384716.6 | G39: sum of separate districts
A40: =A39+1 -> 24 | B40: TRA basic + coordinated salaries, FY 2007 | C40: 383349.25 | D40: 3070068.6 | E40: =C40+D40 -> 3453417.9 | G40: sum of separate districts
A41: =A40+1 -> 25 | B41: TRA basic + coordinated salaries, FY 2008 | C41: 301076.34 | D41: 3099311 | E41: =C41+D41 -> 3400387.3 | G41: sum of separate districts
A42: =A41+1 -> 26 | B42: TRA basic + coordinated salaries, FY 2009 | C42: 336746.71 | D42: 3380592 | E42: =C42+D42 -> 3717338.7 | G42: sum of separate districts
A43: =A42+1 -> 27 | B43: TRA basic + coordinated salaries, FY 2010 | C43: n/a | D43: n/a | E43: 3644332.1 | G43: total for new district
A45: =A43+1 -> 28 | B45: =+"Minimum of ("&FIXED(A36,0)&") to ("&FIXED(A42,0)&") =" -> Minimum of (20) to (26) = | C45: =MIN(C36:C42) -> 301076.34 | D45: =MIN(D36:D42) -> 2359775.4 | E45: n/a
A46: =A45+1 -> 29 | B46: =+"Minimum of ("&FIXED(A36,0)&") to ("&FIXED(A43,0)&") =" -> Minimum of (20) to (27) = | C46: n/a | D46: n/a | E46: =MIN(E36:E43) -> 3024526.2
A48: =A46+1 -> 30 | B48: ="FY 2009 salary total for Ortonville as separate district based on ("&FIXED(A45,0)&"):" -> FY 2009 salary total for Ortonville as separate district based on (28): | E48: =C45 -> 301076.34 | G48: The salary basis should not
A49: =A48+1 -> 31 | B49: ="FY 2009 salary total for Bellingham as separate district based on ("&FIXED(A45,0)&"):" -> FY 2009 salary total for Bellingham as separate district based on (28): | E49: =D45 -> 2359775.4 | G49: be more for the new districts
A50: =A49+1 -> 32 | B50: =+"FY 2009 salary total, combined = ("&FIXED(A48,0)&")+("&FIXED(A49,0)&") =" -> FY 2009 salary total, combined = (30)+(31) = | E50: =E48+E49 -> 2660851.7 | G50: than it was in total for
G51: for old districts.
...

Sheet Consolidate 2887
A1: Consolidation: Districts Affected by McLeod West 2887
C3: A | D3: B | E3: C | F3: D | G3: E
C6: 2887 | D6: 2159 | E6: 2365 | F6: 2859
C7: 1 | D7: 1 | E7: 1 | F7: 1
C8: MCLEOD WEST | D8: BUFFALO LAKE | E8: G.F.W. | F8: GLENCOE-S LAKE | G8: =+"= "&+C3&"+"&+D3&"+"&+E3&"+"&+F3 -> = A+B+C+D
A10: 1 | B10: Portions for distributing Mcleod West values
B11: based on FY 2009 AMCPU: | C11: 0 | D11: 0.15 | E11: 0.29 | F11: 0.56 | G11: =SUM(C11:F11) -> 1
B13: Salary totals before adjusting for consolidation:
A15: =A10+1 -> 2 | B15: TRA basic + coordinated salaries, FY 1997 | C15: 1487616.7 | D15: 1499008 | E15: 2637938.5 | F15: 4201427.6 | G15: =C15+D15+E15+F15 -> 9825990.8
A16: =A15+1 -> 3 | B16: TRA basic + coordinated salaries, FY 2004 | C16: 1553595.1 | D16: 2265962.6 | E16: 3188988.9 | F16: 5881443.3 | G16: =C16+D16+E16+F16 -> 12889990
A17: =A16+1 -> 4 | B17: TRA basic + coordinated salaries, FY 2005 | C17: 1607578.7 | D17: 2216552.6 | E17: 3193583.6 | F17: 6095824.9 | G17: =C17+D17+E17+F17 -> 13113540
A18: =A17+1 -> 5 | B18: TRA basic + coordinated salaries, FY 2006 | C18: 1637985.1 | D18: 2250864.1 | E18: 3010779.1 | F18: 5741888.8 | G18: =C18+D18+E18+F18 -> 12641517
A19: =A18+1 -> 6 | B19: TRA basic + coordinated salaries, FY 2007 | C19: 1568852.8 | D19: 2213944.5 | E19: 3072818.2 | F19: 5387615.3 | G19: =C19+D19+E19+F19 -> 12243231
A20: =A19+1 -> 7 | B20: TRA basic + coordinated salaries, FY 2008 | C20: 1436341.4 | D20: 2364341.6 | E20: 3133690.4 | F20: 5421286.5 | G20: =C20+D20+E20+F20 -> 12355660
A21: =A20+1 -> 8 | B21: TRA basic + coordinated salaries, FY 2009 | C21: 1082620 | D21: 2528502.8 | E21: 3087237.1 | F21: 5841122.2 | G21: =C21+D21+E21+F21 -> 12539482
A22: =A21+1 -> 9 | B22: TRA basic + coordinated salaries, FY 2010 | C22: 0 | D22: 2655495.7 | E22: 3277582.6 | F22: 6501234.8 | G22: =D22+E22+F22 -> 12434313
B24: FY 1997 salary totals adjusted for consolidation:
A26: =A22+1 -> 10 | B26: =+"Minimum of ("&FIXED(A15,0)&") to ("&FIXED(A21,0)&") =" -> Minimum of (2) to (8) = | C26: =MIN(C15:C21) -> 1082620 | D26: n/a | E26: n/a | F26: n/a | G26: =C26 -> 1082620
A27: =A26+1 -> 11 | B27: =+"Proportionate share of ("&FIXED(A26,0)&") =" -> Proportionate share of (10) = | C27: 0 | D27: =ROUND(C26*D11,2) -> 162393.01 | E27: =ROUND(C26*E11,2) -> 313959.81 | F27: =C26-D27-E27 -> 606267.22 | G27: =C27+D27+E27+F27 -> 1082620
A29: =A27+1 -> 12 | B29: =+"Minimum of ("&FIXED(A15,0)&") to ("&FIXED(A22,0)&") =" -> Minimum of (2) to (9) = | C29: n/a | D29: =MIN(D15:D22) -> 1499008 | E29: =MIN(E15:E22) -> 2637938.5 | F29: =MIN(F15:F22) -> 4201427.6 | G29: =SUM(D29:F29) -> 8338374.1
A30: =A29+1 -> 13 | B30: =+"Adjusted FY 1997 salary = ("&FIXED(A27,0)&")+("&FIXED(A29,0)&") =" -> Adjusted FY 1997 salary = (11)+(12) = | C30: n/a | D30: =D27+D29 -> 1661401 | E30: =E27+E29 -> 2951898.3 | F30: =F27+F29 -> 4807694.8 | G30: =D30+E30+F30 -> 9420994.1
A32: =A30+1 -> 14 | B32: Share of #2887's FY 2007 salaries | C32: n/a | D32: =ROUND($C19*D11,2) -> 235327.92 | E32: =ROUND($C19*E11,2) -> 454967.31 | F32: =ROUND($C19*F11,2) -> 878557.56 | G32: =SUM(D32:F32) -> 1568852.8
A33: =A32+1 -> 15 | B33: =+"Adjusted FY 2007 salary = ("&+A19&")+("&+A32&") =" -> Adjusted FY 2007 salary = (6)+(14) = | C33: n/a | D33: =D19+D32 -> 2449272.4 | E33: =E19+E32 -> 3527785.5 | F33: =F19+F32 -> 6266172.9 | G33: =SUM(D33:F33) -> 12243231
B35: PERA:
B37: Not adjusted for consolidation:
A39: =A33+1 -> 16 | B39: PERA salaries, FY 1997 | C39: 377150 | D39: 356207 | E39: 905939 | F39: 1619524 | G39: =C39+D39+E39+F39 -> 3258820
A40: =A39+1 -> 17 | B40: PERA adjustment, old law | C40: -2307.75 | D40: -2908.54 | E40: -2900 | F40: -6870.24 | G40: =C40+D40+E40+F40 -> -14986.53
B42: Distributing the McLeod West values:
A44: =A40+1 -> 18 | B44: PERA salaries, FY 1997 | C44: n/a | D44: =ROUND(C39*D11,2) -> 56572.5 | E44: =ROUND(C39*E11,2) -> 109373.5 | F44: =C39-D44-E44 -> 211204 | G44: =SUM(D44:F44) -> 377150
A45: =A44+1 -> 19 | B45: PERA adjustment, old law | C45: n/a | D45: =ROUND(C40*D11,2) -> -346.16 | E45: =ROUND(C40*E11,2) -> -669.25 | F45: =C40-D45-E45 -> -1292.34 | G45: =SUM(D45:F45) -> -2307.75
B47: Adjusted for consolidation:
A49: =A45+1 -> 20 | B49: =+"PERA salaries, FY 1997 = ("&FIXED(A39,0)&")+("&FIXED(A44,0)&") =" -> PERA salaries, FY 1997 = (16)+(18) = | C49: n/a | D49: =D39+D44 -> 412779.5 | E49: =E39+E44 -> 1015312.5 | F49: =F39+F44 -> 1830728 | G49: =SUM(D49:F49) -> 3258820
A50: =A49+1 -> 21 | B50: =+"PERA adjustment, old law = ("&FIXED(A40,0)&")+("&FIXED(A45,0)&") =" -> PERA adjustment, old law = (17)+(19) = | C50: n/a | D50: =D40+D45 -> -3254.7 | E50: =E40+E45 -> -3569.25 | F50: =F40+F45 -> -8162.58 | G50: =SUM(D50:F50) -> -14986.53

Sheet Email
A1: SENT BY KAREN WILLIAMSON OF TRA
A2: (Karen.Williamson@state.mn.us or 651-296-4539) ON JULY 25, 2006
A4: Bob -
A6: Attached is an Excel spreadsheet for the school districts' salary totals for the 2004-05 school
A7: year. We are providing two lists: one by paid, which means the salary amount that was actually
A8: paid to our members in those school districts during the time period of July 1, 2004 through
A9: June 30, 2005 and the second by 'earned,' which means the salary that was earned by the
A10: teachers during the time period July 1, 2004 through June 30, 2005, salary could have been paid
A11: during July, August and early September, 2005 for the prior school year.
A13: The salary totals reported for 1996-97 and for 2003-04 were on a 'paid' basis. When the salary
A14: totals are available for the 2005-06 school year, we will forward information to you. If you wish just
A15: the paid total salary amounts, please advise. These amounts will be available much sooner than the
... A32: Karen.Williamson@state.mn.us

Sheet ConsolidateFY07
A1: CALCULATIONS FOR DISTRICTS OPENING IN FY 2007: | R1: PENSION0508_20070514
R2: 39216
A3: RESOLUTION: WE ARE CALCULATION THE ADJUSTMENT FOR NEWLY CONSOLIDATED DISTRICTS AS IF THEY HAD ALWAYS BEEN SINGLE ENTITIES.
A4: THIS IS BASED ON A CONVERSATION WITH TOM MELCHER THAT TOOK PLACE ON OCTOBER 24, 2007.
A7: For FY 2007, the primary salary basis is the least salary total from the years FY 1997, FY 2004, FY 2005, FY 2006, and FY 2007.
A9: Districts #2899 and #2902 both opened in FY 2007. For these new districts, the "least of" salary basis may apply to
A10: one or more of the previous districts, but not for the new districts when dealt with as single entities.
A12: We don't want to punish districts for consolidating. Therefore, we will ensure new districts of their former "least of" benefit
A13: by basing their "least of" salary totals on their prior district structures.
A15: Here are the details:
D17: A | E17: B | F17: C | G17: D | H17: E | I17: F | J17: G | K17: H | L17: I | M17: J | N17: K | O17: L | P17: M | Q17: N | R17: O
D19: ACTUAL | E19: ACTUAL | F19: ACTUAL | G19: ACTUAL | H19: ACTUAL | O19: FY 2005 | P19: FY 2006 | Q19: FY 2007 | R19: FY 2008
D20: FY 1997 | E20: FY 2004 | F20: FY 2005 | G20: FY 2006 | H20: FY 2007 | O20: PENSION | P20: PENSION | Q20: PENSION | R20: PENSION
D21: TRA | E21: TRA | F21: TRA | G21: TRA | H21: TRA | O21: REDUCT | P21: REDUCT | Q21: REDUCT | R21: REDUCT
D22: SALARIES | E22: SALARIES | F22: SALARIES | G22: SALARIES | H22: SALARIES | M22: FY 1997 | N22: OLD LAW | O22: = .0234 | P22: = .0234 | Q22: = .0234 | R22: =+"= "&+Q17 -> = N
D23: BASIC | E23: BASIC | F23: BASIC | G23: BASIC | H23: BASIC | I23: = MIN OF | J23: = MIN OF | K23: = MIN OF | L23: = MIN OF | M23: PERA | N23: PERA | O23: =+"X "&+I17 -> X F | P23: =+"X "&+K17 -> X H | Q23: =+"X "&+L17 -> X I | R23: =+"- "&+H17&" X" -> - E X
D24: +COORD | E24: +COORD | F24: +COORD | G24: +COORD | H24: +COORD | I24: =+D17&" TO "&+E17 -> A TO B | J24: =+D17&" TO "&+F17 -> A TO C | K24: =+D17&" TO "&+G17 -> A TO D | L24: =+D17&" TO "&+H17 -> A TO E | M24: SALARIES | N24: ADJUST | O24: =+"-.007*"&+$M17&"-"&+$N17 -> -.007*J-K | P24: =+"-.007*"&+$M17&"-"&+$N17 -> -.007*J-K | Q24: =+"-.007*"&+$M17&"-"&+$N17 -> -.007*J-K | R24: 0.005
A26: 2899 | B26: 1 | C26: PLAINVIEW-ELGIN-MILLVILLE
A28: 806 | B28: 1 | C28: ELGIN-MILLVILLE | D28: 1687490.6 | E28: 1799998.7 | F28: 1789832.5 | G28: 1617313 | H28: N/A | I28: =MIN(D28:E28) -> 1687490.6 | J28: =MIN(D28:F28) -> 1687490.6 | K28: =MIN(D28:G28) -> 1617313 | L28: =MIN(D28:H28) -> 1617313 | M28: 375106 | N28: -992.4 | O28: =ROUND(0.0234*I28,2)-ROUND(0.007*M28,2)-N28 -> 37853.94 | P28: =ROUND(0.0234*K28,2)-ROUND(0.007*M28,2)-N28 -> 36211.78 | Q28: =ROUND(0.0234*L28,2)-ROUND(0.007*M28,2)-N28 -> 36211.78 | R28: N/A
A29: 810 | B29: 1 | C29: PLAINVIEW | D29: 3126391.3 | E29: 4387846.5 | F29: 4218954.4 | G29: 3993852.2 | H29: N/A | I29: =MIN(D29:E29) -> 3126391.3 | J29: =MIN(D29:F29) -> 3126391.3 | K29: =MIN(D29:G29) -> 3126391.3 | L29: =MIN(D29:H29) -> 3126391.3 | M29: 499627 | N29: -1124.01 | O29: =ROUND(0.0234*I29,2)-ROUND(0.007*M29,2)-N29 -> 70784.18 | P29: =ROUND(0.0234*K29,2)-ROUND(0.007*M29,2)-N29 -> 70784.18 | Q29: =ROUND(0.0234*L29,2)-ROUND(0.007*M29,2)-N29 -> 70784.18 | R29: N/A
C30: SUM OF SEPARATE | D30: =D28+D29 -> 4813881.9 | E30: =E28+E29 -> 6187845.2 | F30: =F28+F29 -> 6008786.9 | G30: =G28+G29 -> 5611165.2 | H30: N/A | I30: =I28+I29 -> 4813881.9 | J30: =J28+J29 -> 4813881.9 | K30: =K28+K29 -> 4743704.3 | L30: =L28+L29 -> 4743704.3 | M30: =M28+M29 -> 874733 | N30: =N28+N29 -> -2116.41 | O30: =O28+O29 -> 108638.12 | P30: =P28+P29 -> 106995.96 | Q30: =Q28+Q29 -> 106995.96 | R30: N/A
C31: AS SINGLE DISTRICT | D31: =D30 -> 4813881.9 | E31: =E30 -> 6187845.2 | F31: =F30 -> 6008786.9 | G31: =G30 -> 5611165.2 | H31: 5950720.9 | I31: =MIN(D31:E31) -> 4813881.9 | J31: =MIN(D31:F31) -> 4813881.9 | K31: =MIN(D31:G31) -> 4813881.9 | L31: =MIN(D31:H31) -> 4813881.9 | M31: =M30 -> 874733 | N31: =N30 -> -2116.41 | O31: =ROUND(0.0234*I31,2)-ROUND(0.007*M31,2)-N31 -> 108638.12 | P31: =ROUND(0.0234*K31,2)-ROUND(0.007*M31,2)-N31 -> 108638.12 | Q31: =ROUND(0.0234*L31,2)-ROUND(0.007*M31,2)-N31 -> 108638.12 | R31: =ROUND(Q31-0.005*H31,2) -> 78884.52
C32: DIFFERENCE | D32: N/A | E32: N/A | F32: N/A | G32: N/A | H32: N/A | I32: N/A | J32: N/A | K32: N/A | L32: N/A | M32: N/A | N32: N/A | O32: =O30-O31 -> 0 | P32: =P30-P31 -> -1642.16 | Q32: =Q30-Q31 -> -1642.16 | R32: N/A
A35: 2902 | B35: 1 | C35: RUSSELL-TYLER-RUTHTON
A37: 409 | B37: 1 | C37: TYLER | D37: 1021122.4 | E37: 1010946.1 | F37: 999475.3 | G37: 912894.51 | H37: N/A | I37: =MIN(D37:E37) -> 1010946.1 | J37: =MIN(D37:F37) -> 999475.3 | K37: =MIN(D37:G37) -> 912894.51 | L37: =MIN(D37:H37) -> 912894.51 | M37: 144194 | N37: -1033.45 | O37: =ROUND(0.0234*I37,2)-ROUND(0.007*M37,2)-N37 -> 23680.23 | P37: =ROUND(0.0234*K37,2)-ROUND(0.007*M37,2)-N37 -> 21385.82 | Q37: =ROUND(0.0234*L37,2)-ROUND(0.007*M37,2)-N37 -> 21385.82 | R37: N/A
A38: 418 | B38: 1 | C38: RUSSELL | D38: 580764.39 | E38: 467380.33 | F38: 481322.47 | G38: 412099.79 | H38: N/A | I38: =MIN(D38:E38) -> 467380.33 | J38: =MIN(D38:F38) -> 467380.33 | K38: =MIN(D38:G38) -> 412099.79 | L38: =MIN(D38:H38) -> 412099.79 | M38: 126548 | N38: -580.15 | O38: =ROUND(0.0234*I38,2)-ROUND(0.007*M38,2)-N38 -> 10631.01 | P38: =ROUND(0.0234*K38,2)-ROUND(0.007*M38,2)-N38 -> 9337.45 | Q38: =ROUND(0.0234*L38,2)-ROUND(0.007*M38,2)-N38 -> 9337.45 | R38: N/A
A39: 584 | B39: 1 | C39: RUTHTON | D39: 645735.32 | E39: 690955.66 | F39: 728755.19 | G39: 710471.8 | H39: N/A | I39: =MIN(D39:E39) -> 645735.32 | J39: =MIN(D39:F39) -> 645735.32 | K39: =MIN(D39:G39) -> 645735.32 | L39: =MIN(D39:H39) -> 645735.32 | M39: 144537 | N39: -894.1 | O39: =ROUND(0.0234*I39,2)-ROUND(0.007*M39,2)-N39 -> 14992.55 | P39: =ROUND(0.0234*K39,2)-ROUND(0.007*M39,2)-N39 -> 14992.55 | Q39: =ROUND(0.0234*L39,2)-ROUND(0.007*M39,2)-N39 -> 14992.55 | R39: N/A
C40: SUM OF SEPARATE | D40: =SUM(D37:D39) -> 2247622.1 | E40: =SUM(E37:E39) -> 2169282.1 | F40: =SUM(F37:F39) -> 2209553 | G40: =SUM(G37:G39) -> 2035466.1 | H40: N/A | I40: =SUM(I37:I39) -> 2124061.7 | J40: =SUM(J37:J39) -> 2112591 | K40: =SUM(K37:K39) -> 1970729.6 | L40: =SUM(L37:L39) -> 1970729.6 | M40: =SUM(M37:M39) -> 415279 | N40: =SUM(N37:N39) -> -2507.7 | O40: =SUM(O37:O39) -> 49303.79 | P40: =SUM(P37:P39) -> 45715.82 | Q40: =SUM(Q37:Q39) -> 45715.82 | R40: N/A
C41: AS SINGLE DISTRICT | D41: =D40 -> 2247622.1 | E41: =E40 -> 2169282.1 | F41: =F40 -> 2209553 | G41: =G40 -> 2035466.1 | H41: 1786518.6 | I41: =MIN(D41:E41) -> 2169282.1 | J41: =MIN(D41:F41) -> 2169282.1 | K41: =MIN(D41:G41) -> 2035466.1 | L41: =MIN(D41:H41) -> 1786518.6 | M41: =M40 -> 415279 | N41: =N40 -> -2507.7 | O41: =ROUND(0.0234*I41,2)-ROUND(0.007*M41,2)-N41 -> 50361.95 | P41: =ROUND(0.0234*K41,2)-ROUND(0.007*M41,2)-N41 -> 47230.66 | Q41: =ROUND(0.0234*L41,2)-ROUND(0.007*M41,2)-N41 -> 41405.29 | R41: =ROUND(Q41-0.005*H41,2) -> 32472.7
C42: DIFFERENCE | D42: N/A | E42: N/A | F42: N/A | G42: N/A | H42: N/A | I42: N/A | J42: N/A | K42: N/A | L42: N/A | M42: N/A | N42: N/A | O42: =O40-O41 -> -1058.16 | P42: =P40-P41 -> -1514.84 | Q42: =Q40-Q41 -> 4310.53 | R42: N/A
A44: Values in the yellow cells are used in the "Districts" worksheet.

Sheet Law
A1: 127A.50, Minnesota Statutes 2006
A3: Copyright © 2006 by the Office of Revisor of Statutes, State of Minnesota.
A5: 127A.50 AID ADJUSTMENTS DUE TO CHANGES IN EMPLOYER RETIREMENT
A6: CONTRIBUTION RATES.
A7: Subdivision 1. Aid adjustment. Beginning in fiscal year 1998 and each year thereafter,
A8: the commissioner of education shall adjust state aid payments to school operating funds for
A9: Independent School District No. 625 and Independent School District No. 709 by the net amount
A10: of clauses (1) and (2), for Special School District No. 1 by the net amount of clauses (1), (2), and
A11: (4), and for all other districts, including charter schools, but excluding any education organizations
A12: that are prohibited from receiving direct state aids under section 123A.26 or 125A.75, subdivision
A13: 7 , by the net amount of clauses (1), (2), (3), and (4):
A14: (1) a decrease equal to each district's share of the fiscal year 1997 adjustment effected under
... A32: by the executive director of the Teachers Retirement Association. For any school district where
A33: the newly certified Teachers Retirement Association payroll is significantly lower than the fiscal | B33: Note that this applies only to the FY 1997
A34: 1997 amount as determined by the commissioner, the commissioner shall recalculate the lower | B34: base salary total, and not to the FY 2007
A35: reduction under subdivision 1, clause (3), and shall permanently reduce the adjustment amount | B35: salary total.
A36: in subsequent years.
A37: Subd. 4. Effect of reorganizations. The commissioner of education shall reapportion the aid
A38: adjustments to school districts under this section to account for significant changes in boundaries
A39: or consolidations, as determined by the commissioner. If a school district is dissolved, or a school
A40: district function thereof is assumed by either the state or a nonpublic organization, adjustments for
A41: all or the appropriate fraction of the total payroll under this section must terminate.
A42: Subd. 5. Adjustment termination. All adjustments under this section terminate on June
A43: 30, 2020.
A44: History: 1997 c 233 art 1 s 14; 1998 c 397 art 4 s 51; art 11 s 3; 1Sp2001 c 6 art 1 s 40;
A45: 2003 c 130 s 12; 2006 c 277 art 3 s 1
A46: NOTE: The amendment to subdivision 1 by Laws 2006, chapter 277, article 3, section 1,
A47: is effective for revenue for fiscal year 2008. Laws 2006, chapter 277, article 3, section 1, the
... A93: History: 1997 c 233 art 1 s 15; 1999 c 222 art 2 s 3

Sheet Minneapolis
A1: From: Marjorie Rolland [mailto:Marjorie.Rolland@mpls.k12.mn.us]
A2: Sent: Wednesday, February 06, 2008 4:04 PM
A3: To: Bob.Porter@state.mn.us
A4: Subject: Salary Exp
A6: Bob –
A8: Actual salary expense for 2007 (TRA eligible) $197,593,500. Yes, I know it
A9: is lower than the 2005 figure but not sure where the 2005 figure came from.
A11: Marjorie Rolland
A12: Finance Department
A13: Minneapolis Public Schools
A14: 612-668-0411

Sheet TRA
A1: FY 2010 Salaries for Pension Adjustment from Karen Williamson of TRA
A2: Received October 13, 2010
D4: Salary | E4: Deduction | F4: Contribution
C6: TOTAL | D6: =SUM(D12:D603) -> 3.8974394e+09 | E6: =SUM(E12:E603) -> 2.1237228e+08 | F6: =SUM(F12:F603) -> 2.2036746e+08
C8: DISTRICTS | D8: =SUM(D12:D348) -> 3.4467109e+09 | E8: =SUM(E12:E348) -> 1.8776764e+08 | F8: =SUM(F12:F348) -> 1.9575965e+08
C9: CHARTERS | D9: =SUM(D350:D512) -> 1.2014971e+08 | E9: =SUM(E350:E512) -> 6534025.7 | F9: =SUM(F350:F512) -> 6533895.9
C10: OTHERS | D10: =SUM(D514:D603) -> 3.3057878e+08 | E10: =SUM(E514:E603) -> 18070611 | F10: =SUM(F514:F603) -> 18073921
A12: 1 | B12: 1 | C12: AITKIN PUBLIC SCHOOL DISTRICT | D12: 4816898.9 | E12: 260714.06 | F12: 260713.26
A13: 1.2 | B13: 3 | C13: MINNEAPOLIS PUBLIC SCHOOL DIST. | D13: 2.1889332e+08 | E13: 12235991 | F13: 20231859
A14: 2 | B14: 1 | C14: HILL CITY PUBLIC SCHOOL DISTRICT | D14: 1789667.6 | E14: 98184.05 | F14: 98184.45
A15: 4 | B15: 1 | C15: MCGREGOR PUBLIC SCHOOL DISTRICT | D15: 1952577.7 | E15: 105878.39 | F15: 105877.44
A16: 6 | B16: 3 | C16: SOUTH ST. PAUL PUBLIC SCHOOL DIST. | D16: 15816431 | E16: 864257.72 | F16: 864250.99
A17: 11 | B17: 1 | C17: ANOKA-HENNEPIN PUBLIC SCHOOL DIST. | D17: 1.9485844e+08 | E17: 10598851 | F17: 10598751
A18: 12 | B18: 1 | C18: CENTENNIAL PUBLIC SCHOOL DISTRICT | D18: 30192261 | E18: 1653127.1 | F18: 1653118.4
A19: 13 | B19: 1 | C19: COLUMBIA HEIGHTS PUBLIC SCHOOL DIST | D19: 12373432 | E19: 680499.9 | F19: 680495.53
A20: 14 | B20: 1 | C20: FRIDLEY PUBLIC SCHOOL DISTRICT | D20: 13907139 | E20: 756234.45 | F20: 756233.2
A21: 15 | B21: 1 | C21: ST. FRANCIS PUBLIC SCHOOL DISTRICT | D21: 25063660 | E21: 1370426.5 | F21: 1370428.9
A22: 16 | B22: 1 | C22: SPRING LAKE PARK PUBLIC SCHOOLS | D22: 20324370 | E22: 1117778.8 | F22: 1117775.6
A23: 22 | B23: 1 | C23: DETROIT LAKES PUBLIC SCHOOL DIST. | D23: 12980365 | E23: 699183.07 | F23: 699179.29
... A603: 10100051 | B603: 0 | C603: MN State Comm and Tech College 101-51 | D603: 7348583.4 | E603: 404172.47 | F603: 404174.65

Sheet Changes
A1: ChAnges From FY 2009 to FY 2010
D4: A | E4: B | F4: C | G4: D | H4: E | I4: F | J4: G | K4: H | L4: I | M4: J | N4: K | O4: L | P4: M
O6: FY 2010 | P6: FY 2010
D7: ACTUAL | E7: ACTUAL | F7: ACTUAL | G7: ACTUAL | H7: ACTUAL | I7: ACTUAL | J7: ACTUAL | K7: ACTUAL | O7: PENSION | P7: PENSION
D8: FY 1997 | E8: FY 2004 | F8: FY 2005 | G8: FY 2006 | H8: FY 2007 | I8: FY 2008 | J8: FY 2009 | K8: FY 2010 | O8: REDUCT | P8: REDUCT
D9: TRA | E9: TRA | F9: TRA | G9: TRA | H9: TRA | I9: TRA | J9: TRA | K9: TRA | O9: INITIAL | P9: REVISED | Q9: FY 2009
D10: SALARIES | E10: SALARIES | F10: SALARIES | G10: SALARIES | H10: SALARIES | I10: SALARIES | J10: SALARIES | K10: SALARIES | M10: FY 1997 | N10: OLD LAW | O10: = .0234 | Q10: PENSION
D11: BASIC | E11: BASIC | F11: BASIC | G11: BASIC | H11: BASIC | I11: BASIC | J11: BASIC | K11: BASIC | L11: = MIN OF | M11: PERA | N11: PERA | O11: =+"X "&+L4 -> X I | P11: =+"= "&+O4 -> = L | Q11: REDUCT
D12: +COORD | E12: +COORD | F12: +COORD | G12: +COORD | H12: +COORD | I12: +COORD | J12: +COORD | K12: +COORD | L12: =+D4&" TO "&+K4 -> A TO H | M12: SALARIES | N12: ADJUST | O12: =+"-.007*"&+$M4&"-"&+$N4 -> -.007*J-K | P12: =+"- .005 X "&+H4 -> - .005 X E | Q12: REVISED | R12: CHANGE
A14: 297 | B14: 1 | C14: SPRING GROVE | D14: 1311719.7 | E14: 1487655.5 | F14: 1482958.1 | G14: 1540632.8 | H14: 1560257.7 | I14: 1570034.8 | J14: 1562879 | K14: 1244058.7 | L14: =MIN(D14:K14) -> 1244058.7 | M14: 280473 | N14: -1441.27 | O14: =ROUND(0.0234*L14,2)-ROUND(0.007*M14,2)-N14 -> 28588.93 | P14: =ROUND(O14-0.005*H14,2) -> 20787.64 | Q14: 22370.91 | R14: =P14-Q14 -> -1583.27
A15: 316 | B15: 1 | C15: GREENWAY | D15: 5044104.8 | E15: 4920652.3 | F15: 5001465.3 | G15: 5078651.9 | H15: 4420992.6 | I15: 4385443.2 | J15: 4577652.2 | K15: 4169649.3 | L15: =MIN(D15:K15) -> 4169649.3 | M15: 1687703 | N15: -8305.8 | O15: =ROUND(0.0234*L15,2)-ROUND(0.007*M15,2)-N15 -> 94061.67 | P15: =ROUND(O15-0.005*H15,2) -> 71956.71 | Q15: 77006.29 | R15: =P15-Q15 -> -5049.58
A16: 404 | B16: 1 | C16: LAKE BENTON | D16: 816057.04 | E16: 709110.87 | F16: 706180.28 | G16: 1052429 | H16: 788515.84 | I16: 682913.97 | J16: 563489.85 | K16: 523045.88 | L16: =MIN(D16:K16) -> 523045.88 | M16: 154184 | N16: -747 | O16: =ROUND(0.0234*L16,2)-ROUND(0.007*M16,2)-N16 -> 11906.98 | P16: =ROUND(O16-0.005*H16,2) -> 7964.4 | Q16: 8910.79 | R16: =P16-Q16 -> -946.39
A17: 595 | B17: 1 | C17: EAST GRAND FORKS | D17: 6800932 | E17: 6787665.9 | F17: 7041486.3 | G17: 6996820.2 | H17: 6888964.1 | I17: 6685299.7 | J17: 6908993.4 | K17: 6660364.4 | L17: =MIN(D17:K17) -> 6660364.4 | M17: 1543797 | N17: -4913.5 | O17: =ROUND(0.0234*L17,2)-ROUND(0.007*M17,2)-N17 -> 149959.45 | P17: =ROUND(O17-0.005*H17,2) -> 115514.63 | Q17: 116098.11 | R17: =P17-Q17 -> -583.48
A18: 852 | B18: 1 | C18: CAMPBELL-TINTAH | D18: 687077.62 | E18: 739388.56 | F18: 696255.84 | G18: 742083.65 | H18: 724247.6 | I18: 785773.84 | J18: 855188.36 | K18: 661144.75 | L18: =MIN(D18:K18) -> 661144.75 | M18: 194350 | N18: -1413.67 | O18: =ROUND(0.0234*L18,2)-ROUND(0.007*M18,2)-N18 -> 15524.01 | P18: =ROUND(O18-0.005*H18,2) -> 11902.77 | Q18: 12509.6 | R18: =P18-Q18 -> -606.83
A19: 2134 | B19: 1 | C19: UNITED SOUTH CENTRAL | D19: 3896654.9 | E19: 4102696.8 | F19: 4207547.7 | G19: 4262284.7 | H19: 4329092.6 | I19: 4129245.1 | J19: 3702441.1 | K19: 3582896.6 | L19: =MIN(D19:K19) -> 3582896.6 | M19: 1027991 | N19: -3816.81 | O19: =ROUND(0.0234*L19,2)-ROUND(0.007*M19,2)-N19 -> 80460.65 | P19: =ROUND(O19-0.005*H19,2) -> 58815.19 | Q19: 61612.53 | R19: =P19-Q19 -> -2797.34
A20: 2137 | B20: 1 | C20: KINGSLAND | D20: 3070926.4 | E20: 3457817.2 | F20: 3093183.7 | G20: 3116369.3 | H20: 3059413.9 | I20: 3026219.8 | J20: 2902457.8 | K20: 2718498.7 | L20: =MIN(D20:K20) -> 2718498.7 | M20: 794210 | N20: -5057.78 | O20: =ROUND(0.0234*L20,2)-ROUND(0.007*M20,2)-N20 -> 63111.18 | P20: =ROUND(O20-0.005*H20,2) -> 47814.11 | Q20: 52118.75 | R20: =P20-Q20 -> -4304.64
A21: 2142 | B21: 1 | C21: ST. LOUIS COUNTY | D21: 10020139 | E21: 10502525 | F21: 11622008 | G21: 10562754 | H21: 10260958 | I21: 9462307.2 | J21: 10208085 | K21: 9380368.1 | L21: =MIN(D21:K21) -> 9380368.1 | M21: 2270472 | N21: -20340.97 | O21: =ROUND(0.0234*L21,2)-ROUND(0.007*M21,2)-N21 -> 223948.28 | P21: =ROUND(O21-0.005*H21,2) -> 172643.49 | Q21: 174560.87 | R21: =P21-Q21 -> -1917.38
A22: 2155 | B22: 1 | C22: WADENA-DEER CREEK | D22: 4734630.1 | E22: 5083435.9 | F22: 5129373.6 | G22: 5155451.1 | H22: 5031920 | I22: 4735492.4 | J22: 4752346 | K22: 4536880.5 | L22: =MIN(D22:K22) -> 4536880.5 | M22: 1206576 | N22: -3679.64 | O22: =ROUND(0.0234*L22,2)-ROUND(0.007*M22,2)-N22 -> 101396.61 | P22: =ROUND(O22-0.005*H22,2) -> 76237.01 | Q22: 80864.35 | R22: =P22-Q22 -> -4627.34
A23: 2198 | B23: 1 | C23: FILMORE CENTRAL | D23: 2514159.4 | E23: 2622098 | F23: 2598396 | G23: 2564966.4 | H23: 2500111.9 | I23: 2696721.5 | J23: 2608912.9 | K23: 2252415 | L23: =MIN(D23:K23) -> 2252415 | M23: 613333 | N23: -3117.36 | O23: =ROUND(0.0234*L23,2)-ROUND(0.007*M23,2)-N23 -> 51530.54 | P23: =ROUND(O23-0.005*H23,2) -> 39029.98 | Q23: 44826.09 | R23: =P23-Q23 -> -5796.11
A24: 2527 | B24: 1 | C24: HALSTAD-HENDRUM | D24: 1341555.3 | E24: 1534879.9 | F24: 1437154.2 | G24: 1374610.5 | H24: 1415961.8 | I24: 1342404.8 | J24: 1353238.7 | K24: 1304956.5 | L24: =MIN(D24:K24) -> 1304956.5 | M24: 429905 | N24: -2247.8 | O24: =ROUND(0.0234*L24,2)-ROUND(0.007*M24,2)-N24 -> 29774.44 | P24: =ROUND(O24-0.005*H24,2) -> 22694.63 | Q24: 23551.04 | R24: =P24-Q24 -> -856.41
A26: 2159 | B26: 1 | C26: BUFFALO LAKE-HECTOR | D26: 1722150.5 | E26: 2499001.9 | F26: 2457689.5 | G26: 2496561.8 | H26: 2449272.4 | I26: 2579792.8 | J26: 2690895.8 | K26: ='Consolidate 2887'!#REF! -> #REF! | L26: =MIN(D26:K26) -> #REF! | M26: ='Consolidate 2887'!I10 -> 0 | N26: ='Consolidate 2887'!I11 -> 0 | O26: =ROUND(0.0234*L26,2)-ROUND(0.007*M26,2)-N26 -> #REF! | P26: =ROUND(O26-0.005*H26,2) -> #REF! | Q26: 24422.16 | R26: =P26-Q26 -> #REF!
A27: 2365 | B27: 1 | C27: G.F.W. | D27: 3069347.3 | E27: 3639531.5 | F27: 3659781.4 | G27: 3485794.7 | H27: 3527785.5 | I27: 3550229.4 | J27: 3401196.9 | K27: ='Consolidate 2887'!J60 -> 0 | L27: =MIN(D27:K27) -> 0 | M27: ='Consolidate 2887'!J10 -> 0 | N27: ='Consolidate 2887'!J11 -> 0 | O27: =ROUND(0.0234*L27,2)-ROUND(0.007*M27,2)-N27 -> 0 | P27: =ROUND(O27-0.005*H27,2) -> -17638.93 | Q27: 42922.1 | R27: =P27-Q27 -> -60561.03
A28: 2859 | B28: 1 | C28: GLENCOE-SILVER LAKE | D28: 5034493 | E28: 6751456.5 | F28: 6996069 | G28: 6659160.5 | H28: 6266172.9 | I28: 6225637.7 | J28: 6447389.4 | K28: ='Consolidate 2887'!K60 -> 0 | L28: =MIN(D28:K28) -> 0 | M28: ='Consolidate 2887'!K10 -> 0 | N28: ='Consolidate 2887'!K11 -> 0 | O28: =ROUND(0.0234*L28,2)-ROUND(0.007*M28,2)-N28 -> 0 | P28: =ROUND(O28-0.005*H28,2) -> -31330.86 | Q28: 66908.9 | R28: =P28-Q28 -> -98239.76
A30: 2903 | B30: 1 | C30: ORTONVILLE | D30: 2350565.4 | E30: 2815679.3 | F30: 2818864.5 | G30: 2629278.9 | H30: 2624299.9 | I30: 2713196.6 | J30: 3179341.7 | K30: ='Consolidate 2903 2904'!E26 -> 2290512.3 | L30: =MIN(D30:K30) -> 2290512.3 | M30: ='Consolidate 2903 2904'!E5 -> 856265 | N30: ='Consolidate 2903 2904'!E6 -> -5837.05 | O30: =ROUND(0.0234*L30,2)-ROUND(0.007*M30,2)-N30 -> 53441.18 | P30: =ROUND(O30-0.005*H30,2) -> 40319.68 | Q30: n/a | R30: n/a
A31: 2904 | B31: 1 | C31: TRACY-BALATON | D31: 3024526.2 | E31: 3103698.7 | F31: 3275132.4 | G31: 3384716.6 | H31: 3453417.9 | I31: 3400387.3 | J31: 3717338.7 | K31: ='Consolidate 2903 2904'!E54 -> 2660851.7 | L31: =MIN(D31:K31) -> 2660851.7 | M31: ='Consolidate 2903 2904'!E33 -> 984305 | N31: ='Consolidate 2903 2904'!E34 -> -5306.44 | O31: =ROUND(0.0234*L31,2)-ROUND(0.007*M31,2)-N31 -> 60680.23 | P31: =ROUND(O31-0.005*H31,2) -> 43413.14 | Q31: n/a | R31: n/a

Sheet Salaries 2011
A1: TRA Org ID | B1: Name | C1: Salary | D1: Deduction | E1: Contribution
A3: 1 | B3: Aitkin - ISD #1 | C3: 4528039.4 | D3: 249042.85 | E3: 249042.13
A4: 2 | B4: Hill City - ISD #2 | C4: 1695388 | D4: 93246.6 | E4: 93245.95
A5: 4 | B5: McGregor - ISD #4 | C5: 2035336.2 | D5: 111943.9 | E5: 111942.64
A6: 6 | B6: South St Paul Special School Dist #6 | C6: 16370856 | D6: 900401.02 | E6: 900392.79
A7: 11 | B7: Anoka-Hennepin - ISD #11 | C7: 1.8850242e+08 | D7: 10367714 | E7: 10367612
A8: 12 | B8: Centennial - ISD #12 | C8: 28665360 | D8: 1576607.5 | E8: 1576599.8
A9: 13 | B9: Columbia Heights - ISD #13 | C9: 14056602 | D9: 773117.29 | E9: 773114.24
A10: 14 | B10: Fridley - ISD #14 | C10: 14166647 | D10: 779168.79 | E10: 779165.7
A11: 15 | B11: St Francis - ISD #15 | C11: 24948637 | D11: 1372167 | E11: 1372171.9
A12: 16 | B12: Spring Lake Park - ISD #16 | C12: 20549943 | D12: 1130251.7 | E12: 1130247
A13: 22 | B13: Detroit Lakes - ISD #22 | C13: 13132844 | D13: 722305.82 | E13: 722300.07
A14: 23 | B14: Frazee-Vergas Public Schools | C14: 3830419 | D14: 210673.39 | E14: 210672.75
... A578: 10100051 | B578: MN State Comm and Tech College 101-51 | C578: 6661617.9 | D578: 366564.1 | E578: 366583.73
A579: S0001 | B579: Minneapolis - Special School Dist #1 | C579: 2.2448269e+08 | D579: 12495511 | E579: 20687038
A580: Total | C580: =SUM(C3:C579) -> 3.8981407e+09 | D580: =SUM(D3:D579) -> 2.1454702e+08 | E580: =SUM(E3:E579) -> 2.2273749e+08
