Workbook
Name access_distances: Stat!$B$54:$B$59
Name Canada: Calc2!$K$136:$K$148
Name Country: EF!$A$3:$A$157
Name distance_train: Stat!$B$61:$B$67
Name N_A: Calc2!$K$149

Sheet Intro
A1: ACERT v1.0 INTRODUCTION and INSTRUCTIONS
A2: Do-It-Yourself Airport Greenhouse Gas Emissions Inventory Tool
A37: Key to inputs | C37: Data input required - text, number, percentage or select from pull down menu
C38: (Some cells already have sample data. Modify or use this data as default)
C39: Information feedback (no input required)
C40: Notes to help explain data input
C42: Banner indicating Airport Owned and Controlled Sources
C43: Banner indicating Non-Airport, Tenant, or Airline Sources

Sheet Input
A1: Airport Carbon and Emissions Reporting Tool ACERT v1.0 | J1: =C5 -> XYZ | K1: =J6 -> 2011
A2: STEP 1 - GENERAL AIRPORT INFORMATION
B4: Airport Name: | G4: Airport Operator:
B5: IATA Identifier: | C5: XYZ | D5: (3 letters) | E5: ICAO Identifier: | F5: WXYZ | G5: (4 letters) | I5: Date of Report (DD/MM/YYYY): | J5: 41153 | O5: January
I6: Year of Inventory: | J6: 2011 | O6: February
B7: City: | I7: First month of year: | J7: January | O7: March
B8: Country: | C8: Albania | E8: ACI Region: | F8: Select One | O8: April
B9: Province: | C9: n/a | D9: (Canada only, otherwise select n/a) | I9: Aircraft movements in inventory year | J9: 100 | K9: movements | O9: May
I10: Passengers Movements in Inventory year | J10: 100 | K10: movements | O10: June
B11: Inventory compiled by: | C11: name | I11: Cargo in inventory year | J11: 10 | K11: tonnes | O11: July
B12: Position: | H12: Note: 1 landing and 1 take-off (LTO) = 2 movements | O12: August
B13: email: | O13: September
O14: October
D15: Permission: This data is made available to ACI | E15: unconditionally | I15: Unit System: | J15: Metric (e.g. metres, litres, kg) | O15: November
D16: Have you ever conducted a more detailed GHG inventory? | E16: No | O16: December
D17: If yes, will you submit it to ACI with this inventory? | E17: No | F17: Most recent year | I17: Reminder:Save file under a new name eg LHR2012
B18: Note: - Make sure you can see Columns A through K
A20: STEP 2 - AIRSIDE VEHICLES, MACHINERY, GSE, FIRE TRAINING, GLYCOL
B22: Fuel used in vehicles, including airside transport, machinery, ground service equipment
C23: Total Fuel used in Vehicles | D23: Airport Owned Vehicles | E23: Non-Airport, Tenant, or Airline Vehicles | F23: Unit | H23: Tenants include all airlines, government bureaus, concessionaires, freight companies, maintenance, contractors, and other companies based at the airport
C24: Gasoline | D24: 5 | F24: litre
C25: Diesel | F25: litre
C26: Natural Gas | F26: kg
C27: Propane | F27: litre
B29: Fuel used for fire training
C30: Fuel | D30: Airport Owned Fire Services | E30: Non-Airport Owned Fire Services | F30: Unit
C31: Kerosene | F31: litre
C32: Butane | F32: litre
C33: Propane | F33: kg
C34: Jet A | F34: litre
C35: Jet B | F35: litre
C36: Wood | F36: kg
I37: Reminder: Save your data. Menu "File"-> "Save"
B38: Fuel used for Stationary Emergency Power Generation Units
C39: Fuel | D39: Airport Owned Equipment | E39: Tenant Owned Equipment | F39: Unit
C40: Diesel or Jet A | F40: litre
B42: Glycol usage for surface and aircraft de-icing
C43: Glycol usage | D43: Airport Operation | E43: Non-Airport, Contactor or Airline Operation | F43: Unit
C44: Movement Surfaces | F44: litre
C45: Other/Aircraft | F45: litre | G45: Note: Calculation is based on 50-50 dilluted glycol
...

Sheet Output
B1: Airport Carbon and Emissions Reporting Tool ACERT v1.0 | G1: =+Calc1!C6 -> XYZ | H1: =Calc1!J8 -> 2011
B2: Airport: | C2: =Calc1!C4 -> 0 | G2: Country: | H2: =+Calc1!C10 -> Albania | K2: Aircraft mvmts: | L2: =+Calc1!J10 -> 100
B3: Report Date: | C3: =Calc1!J6 -> 41153 | G3: Default Ems Factor: | H3: =+Calc1!F95 -> 34.4395 | I3: g CO2/kWh | K3: Passengers: | L3: =+Calc1!J11 -> 100
B4: Operator: | C4: =+Calc1!H4 -> 0 | G4: EF Used: | H4: =+Calc2!E143 -> 34.4395 | I4: g CO2/kWh | K4: Traffic units: | L4: =Calc1!J11+(Calc1!J12*10) -> 200
G5: Greenhouse Gases (t)
B6: Entity | C6: Source | F6: Scope | G6: CO2 | H6: CH4 | I6: N2O | J6: CO2e | K6: CO2e %
B7: Airport Operator | C7: Airport | D7: Airside Vehicles | F7: 1 | G7: =Calc2!E41 -> 0.011445 | H7: =Calc2!F41 -> 2.51e-06 | I7: =Calc2!G41 -> 1e-06 | J7: =G7+H7*21+I7*310 -> 0.01180771 | K7: =J7/$J$33 -> 2.1727371e-06
C8: Airport | D8: Buildings (gas/oil/coal) | F8: 1 | G8: =+Calc2!C80 -> 0.018677934 | H8: =+Calc2!D80 -> 3.3294e-07 | I8: =+Calc2!E80 -> 3.3294e-08 | J8: =G8+H8*21+I8*310 -> 0.018695247 | K8: =J8/$J$33 -> 3.4401129e-06
C9: Airport | D9: Fire Training | F9: 1 | G9: =Calc2!E99 -> 0 | H9: =Calc2!F99 -> 0 | I9: =Calc2!G99 -> 0 | J9: =G9+H9*21+I9*310 -> 0 | K9: =J9/$J$33 -> 0
C10: Airport | D10: Emergency Generator | F10: 1 | G10: =Calc2!D117 -> 0 | H10: =Calc2!E117 -> 0 | I10: =Calc2!F117 -> 0 | J10: =G10+H10*21+I10*310 -> 0 | K10: =J10/$J$33 -> 0
C11: Airport | D11: Glycol | F11: 1 | G11: =Calc2!D129 -> 0 | J11: =G11+H11*21+I11*310 -> 0 | K11: =J11/$J$33 -> 0
C12: Airport | D12: Electricity Purchase | F12: 2 | G12: =Calc2!C142 -> 0.0001721975 | J12: =G12+H12*21+I12*310 -> 0.0001721975 | K12: =G12/$J$33 -> 3.1686067e-08 | L12: =+IF(Input!F71>Input!F69,"Error Step 4","")
C13: Airport | D13: Heat Purchase | F13: 2 | G13: =Calc2!C173 -> 0 | H13: =Calc2!D173 -> 0 | I13: =Calc2!E173 -> 0 | J13: =G13+H13*21+I13*310 -> 0 | K13: =J13/$J$33 -> 0 | L13: =+IF(Input!F84>Input!F82,"Error Step 5","")
I14: Airport Operator Sub-total | J14: =+SUM(J7:J13) -> 0.030675154 | K14: =J14/$J$33 -> 5.644536e-06
B15: Tenants (including airlines, government, shops etc.) and Employees | C15: Tenant | D15: Aircraft (LTO & taxi) | F15: 3 | G15: =Calc2!O324 -> 297.97173 | H15: =Calc2!G334 -> 0.0093648258 | I15: =Calc2!G335 -> 0.026959347 | J15: =G15+H15*21+I15*310 -> 306.52579 | K15: =J15/$J$33 -> 0.056403819
C16: Tenant | D16: Aircraft APU | F16: 3 | G16: =+Calc2!W324 -> 28.35 | H16: =+Calc2!G345 -> 0.000891 | I16: =+Calc2!G346 -> 0.002565 | J16: =G16+H16*21+I16*310 -> 29.163861 | K16: =J16/$J$33 -> 0.0053664429
C17: Tenant | D17: Aircraft Engine Run-ups | F17: 3 | G17: =Calc2!C513 -> 0.00471 | H17: =Calc2!D513 -> 4.437e-06 | I17: =Calc2!E513 -> 4.1325e-07 | J17: =G17+H17*21+I17*310 -> 0.0049312845 | K17: =J17/$J$33 -> 9.074058e-07
C18: Tenant | D18: Aircraft De-icing | F18: 3 | G18: =Calc2!D526 -> 0 | J18: =G18+H18*21+I18*310 -> 0 | K18: =J18/$J$33 -> 0
C19: Tenant | D19: Airside Vehicles | F19: 3 | G19: =Calc2!E384 -> 0 | H19: =Calc2!F384 -> 0 | I19: =Calc2!G384 -> 0 | J19: =G19+H19*21+I19*310 -> 0 | K19: =J19/$J$33 -> 0
C20: Tenant | D20: Buildings (gas/oil/coal) | F20: 3 | G20: =+Calc2!C430 -> 0 | H20: =+Calc2!D430 -> 0 | I20: =+Calc2!E430 -> 0 | J20: =G20+H20*21+I20*310 -> 0 | K20: =J20/$J$33 -> 0
C21: Tenant | D21: Electricity Purchase | F21: 3 | G21: =Calc2!C435 -> 0 | J21: =G21+H21*21+I21*310 -> 0 | K21: =J21/$J$33 -> 0
C22: Tenant | D22: Heat Purchase | F22: 3 | G22: =Calc2!C460 -> 0 | H22: =Calc2!D460 -> 0 | I22: =Calc2!E460 -> 0 | J22: =G22+H22*21+I22*310 -> 0 | K22: =J22/$J$33 -> 0
C23: Tenant | D23: Fire Training | F23: 3 | G23: =Calc2!E478 -> 0 | H23: =Calc2!F478 -> 0 | I23: =Calc2!G478 -> 0 | J23: =G23+H23*21+I23*310 -> 0 | K23: =J23/$J$33 -> 0
C24: Tenant | D24: Emergency Generator | F24: 3 | G24: =Calc2!D495 -> 0 | H24: =Calc2!E495 -> 0 | I24: =Calc2!F495 -> 0 | J24: =G24+H24*21+I24*310 -> 0 | K24: =J24/$J$33 -> 0
C25: Tenant | D25: Landside Vehicles | F25: 3 | G25: =Calc2!C922 -> 4467.6149 | H25: =Calc2!D922 -> 0.91997033 | I25: =Calc2!E922 -> 0.38634493 | J25: =G25+H25*21+I25*310 -> 4606.7012 | K25: =J25/$J$33 -> 0.84767922
C26: Airport | D26: Employee Vehicles | F26: 3 | G26: =Calc2!C908 -> 436.60656 | H26: =Calc2!D908 -> 0.090361954 | I26: =Calc2!E908 -> 0.037370466 | J26: =G26+H26*21+I26*310 -> 450.08901 | K26: =J26/$J$33 -> 0.082820891
I27: Tenant Sub-total | J27: =SUM(J15:J26) -> 5392.4848 | K27: =J27/$J$33 -> 0.99227128
B28: Public (including Passengers) | C28: Ground Access Vehicles | D28: Cars, taxi | F28: 3 | G28: =Calc2!C928 -> 0.4298587 | H28: =Calc2!D928 -> 8.0237082e-05 | I28: =Calc2!E928 -> 3.6823126e-05 | J28: =G28+H28*21+I28*310 -> 0.44295885 | K28: =J28/$J$33 -> 8.1508871e-05
D29: Bus, shuttles | F29: 3 | G29: =Calc2!C929 -> 38.317444 | H29: =Calc2!D929 -> 0.0012092152 | I29: =Calc2!E929 -> 0.0030314 | J29: =G29+H29*21+I29*310 -> 39.282571 | K29: =J29/$J$33 -> 0.0072283871
D30: Rail | F30: 3 | G30: =Calc2!C930 -> 2.2453959 | H30: =Calc2!D930 -> 0 | I30: =Calc2!E930 -> 0 | J30: =G30+H30*21+I30*310 -> 2.2453959 | K30: =J30/$J$33 -> 0.00041317536
I31: Public Sub-total | J31: =SUM(J28:J30) -> 41.970926 | K31: =J31/$J$33 -> 0.0077230713
B32: TOTAL | C32: Total emissions (tonne) | G32: =SUM(G7:G31) -> 5271.5709 | H32: =SUM(H7:H31) -> 1.0218848 | I32: =SUM(I7:I31) -> 0.45630941 | J32: =G32+H32*21+I32*310 -> 5434.4864
B33: Summary | C33: t CO2e | D33: CO2e % | H33: Total CO2e Emissions (t) | J33: =J14+J27+J31 -> 5434.4864 | K33: =K14+K27+K31 -> 1
B34: Airport Scope 1 | C34: =+SUM(J7:J11) -> 0.030502957 | D34: =+SUM(K7:K11) -> 5.61285e-06 | I34: The aircraft emissions calculations were | J34: =IF(Input!H95=0,"not included in this calculation.",+IF(Input!H95=1, "based on generic aircraft data.", "based on detailed aircraft data.")) -> based on generic aircraft data.
B35: Airport Scope 2 | C35: =+SUM(J12:J13) -> 0.0001721975 | D35: =+SUM(K12:K13) -> 3.1686067e-08 | I35: The landside traffic calculations were | J35: =IF(Calc1!E279="None","not included in this calculation.",+IF(Calc1!E279="No.", "based on estimated traffic data.", "based on a detailed traffic survey.")) -> based on estimated traffic data.
B36: Airport Scope 3 | C36: =+J27+J31 -> 5434.4557 | D36: =+K27+K31 -> 0.99999436 | J36: A more detailed separate GHG inventory is also available for Year: | K36: =+IF(AND(Calc1!E19="Yes",Calc1!E18="Yes"),Calc1!G19,"N/A") -> N/A
B70: Check List for Review of Input
A72: 1 | B72: Check Total Fuel dispensed to airside vehicles should not be zero | G72: Airport | H72: =+SUM(Calc1!C28:C31) -> 5 | I72: litres or kg
G73: Tenants | H73: =+SUM(Calc1!C179:C182) -> 0 | I73: litres or kg
A75: 2 | B75: Check Total Fuel (airport and tenants) for electricity or heat | G75: Nat Gas | H75: =+Input!C56+Input!C65 -> 10 | I75: =+Input!D52 -> m3
...

Sheet Acronyms
A1: Acronyms & Abbreviations
A2: ACERT | B2: Airport Carbon and Emissions Reporting Tool
A3: ACU | B3: Air Conditioning Unit
A4: AMO | B4: Aircraft Maintenance Organization
A5: AO | B5: Airport Operators
A6: APU | B6: Auxiliary Power Unit
A7: CAC | B7: Common Air Contaminants
A8: CH4 | B8: Methane
A9: CNG | B9: Compressed Natural Gas
A10: CO | B10: Carbon Monoxide
A11: CO2 | B11: Carbon Dioxide
A12: CO2e | B12: Carbon Dioxide Equivalent
A13: DA | B13: Double Aisle
... A43: WRI | B43: World Reporting Institute

Sheet EF
A1: CO2 Emission Factors for Electricity for Countries and US States
A2: Country | B2: Emissions factor | C2: (spot checks) | D2: Unit | F2: Emissions Factors for US States | H2: g CO2/kWh
A3: (Select One) | F3: NY, CT, RI, MA, VT, NH, ME | H3: 466
A4: Albania | B4: 34.4395 | D4: g CO2/kWh | F4: NJ, DE, PA, ML, WV,OH, IN, MI | H4: 782
A5: Algeria | B5: 670.9448 | D5: g CO2/kWh | F5: IL, WI | H5: 638
A6: Angola | B6: 342.7467 | D6: g CO2/kWh | F6: MO, KY, VI, AR, TN, NC, SC, LA, MI, AL, GA | H6: 690
A7: Argentina | B7: 306.4495 | D7: g CO2/kWh | F7: FA | H7: 678
A8: Armenia | B8: 138.329 | D8: g CO2/kWh | F8: TX | H8: 730
A9: Australia | B9: 873.31 | C9: 924 | D9: g CO2/kWh | F9: OK, KN | H9: 867
A10: Austria | B10: 224.87 | D10: g CO2/kWh | F10: ND, SD, NB, MN, IO | H10: 875
A11: Azerbaijan | B11: 504.8522 | D11: g CO2/kWh | F11: CO, UT, NV, WY, MT | H11: 909
A12: Bahrain | B12: 890.1022 | D12: g CO2/kWh | F12: NM, AZ | H12: 658
A13: Bangladesh | B13: 556.8777 | D13: g CO2/kWh | F13: OR, WA, ID | H13: 147
A14: Belarus | B14: 298.834 | D14: g CO2/kWh | F14: CA | H14: 350
A15: Belgium | B15: 267.959 | D15: g CO2/kWh | F15: HA | H15: 858
A16: Benin | B16: 709.9346 | D16: g CO2/kWh | F16: AL | H16: 749
A17: Bolivia | B17: 481.352 | D17: g CO2/kWh | F17: US TERRITORIES | H17: 858
A18: Bosnia-Herzegovina | B18: 618.6506 | D18: g CO2/kWh | F18: US AVERAGE | H18: 676
A19: Botswana | B19: 1847.6941 | D19: g CO2/kWh
A20: Brazil | B20: 84.2192 | C20: 93 | D20: g CO2/kWh | F20: Source Dept of Energy For EIA-1605 (2007)
A21: Brunei Darussalam | B21: 788.8284 | D21: g CO2/kWh | F21: For period 1999-2002
A22: Bulgaria | B22: 448.0035 | D22: g CO2/kWh
A23: Cambodia | B23: 1205.9307 | D23: g CO2/kWh
A24: Cameroon | B24: 39.0982 | C24: 16 | D24: g CO2/kWh
A25: Canada | B25: 198.664 | C25: 223 | D25: g CO2/kWh
A26: Chile | B26: 357.4757 | D26: g CO2/kWh
A27: People's Republic of China | B27: 787.8678 | D27: g CO2/kWh
A28: China (including Hong Kong) | B28: 788.1334 | D28: g CO2/kWh
A29: Chinese Taipei | B29: 631.6822 | D29: g CO2/kWh
A30: Colombia | B30: 163.1909 | D30: g CO2/kWh
A31: Congo | B31: 643 | C31: 683 | D31: g CO2/kWh
A32: Democratic Republic of Congo | B32: 2.9579 | C32: 4 | D32: g CO2/kWh
A33: Costa Rica | B33: 26.8938 | C33: 15 | D33: g CO2/kWh
A34: Côte d'Ivoire | B34: 518.1223 | D34: g CO2/kWh
A35: Croatia | B35: 311.3264 | D35: g CO2/kWh
A36: Cuba | B36: 987.4434 | D36: g CO2/kWh
A37: Cyprus | B37: 792.3237 | D37: g CO2/kWh
A38: Czech Republic | B38: 515.573 | D38: g CO2/kWh
A39: Denmark | B39: 283.582 | D39: g CO2/kWh
A40: Dominican Republic | B40: 573.9929 | D40: g CO2/kWh
...

Sheet LAQ
A1: Airport Carbon and Emissions Reporting Tool ACERT v1.0 - Approximate LAQ Emissions data | G1: =+Calc1!C6 -> XYZ | H1: =Calc1!J8 -> 2011
B2: Airport: | C2: =Calc1!C4 -> 0 | F2: Country: | G2: =+Calc1!C10 -> Albania | I2: Aircraft mvmts: | J2: =+Calc1!I153 -> 100
B3: Date: | C3: =Calc1!J6 -> 41153 | I3: Passengers: | J3: =+Calc1!J11 -> 100
B4: Operator: | C4: =+Calc1!H4 -> 0 | I4: Traffic units: | J4: =Calc1!J11+(Calc1!J12*10) -> 200
F5: Local Air Quality Pollutants (t)
B6: Entity | C6: Source | F6: NOx | G6: VOC | H6: CO | I6: PM | J6: SOx
B7: Airport Operator | C7: Airport | D7: Airside Vehicles | F7: =Calc2!H41 -> 5.986e-05 | G7: =Calc2!I41 -> 5.11e-05 | H7: =Calc2!J41 -> 0.00049859 | I7: =Calc2!K41 -> 1.2994e-07 | J7: =Calc2!L41 -> 1.46e-07
C8: Airport | D8: Buildings (gas/oil/coal) | F8: =+Calc2!F80 -> 2.33058e-05 | G8: =+Calc2!G80 -> 9.9882e-07 | H8: =+Calc2!H80 -> 9.9882e-06 | I8: =+Calc2!I80 -> 1.6647e-07 | J8: =+Calc2!J80 -> 1.6647e-07
C9: Airport | D9: Fire Training | F9: =Calc2!H99 -> 0 | G9: =Calc2!I99 -> 0 | H9: =Calc2!J99 -> 0 | I9: =Calc2!K99 -> 0 | J9: =Calc2!L99 -> 0
C10: Airport | D10: Emergency Generator | F10: =Calc2!G117 -> 0 | G10: =Calc2!H117 -> 0 | H10: =Calc2!I117 -> 0 | I10: =Calc2!J117 -> 0 | J10: =Calc2!K117 -> 0
C11: Airport | D11: Glycol | G11: =Calc2!H129 -> 0
C12: Airport | D12: Electricity Purchase | K12: LAQ not calculated
C13: Airport | D13: Heat Purchase | F13: =Calc2!F173 -> 0 | G13: =Calc2!G173 -> 0 | H13: =Calc2!H173 -> 0 | I13: =Calc2!I173 -> 0 | J13: =Calc2!J173 -> 0
B14: Airport Operator Sub-total | F14: =SUM(F7:F13) -> 8.31658e-05 | G14: =SUM(G7:G13) -> 5.209882e-05 | H14: =SUM(H7:H13) -> 0.0005085782 | I14: =SUM(I7:I13) -> 2.9641e-07 | J14: =SUM(J7:J13) -> 3.1247e-07
B15: Tenants (incl. airlines, governm't shops etc.) | C15: Tenant | D15: Aircraft (LTO & taxi) | F15: =Calc2!E324 -> 1.3223156 | G15: =Calc2!G324 -> 0.047620365 | H15: =Calc2!I324 -> 0.65646467 | I15: =Calc2!K324 -> 0.0041718604 | J15: =Calc2!M324 -> 0.0472971
C16: Tenant | D16: Aircraft APU | F16: =+Calc2!R324 -> 0.072 | G16: =Calc2!S324 -> 0.0048 | H16: =+Calc2!T324 -> 0.0063 | I16: =+Calc2!U324 -> 0.0012 | J16: =+Calc2!V324 -> 0.0045
C17: Tenant | D17: Aircraft Engine Run-ups | F17: =Calc2!F513 -> 1.5e-06 | G17: =Calc2!G513 -> 6.84e-05 | H17: =Calc2!H513 -> 0.0015 | I17: =Calc2!I513 -> 7.5e-08 | J17: =Calc2!J513 -> 7.5e-07
C18: Tenant | D18: Aircraft De-icing | G18: =Calc2!H526 -> 0
C19: Tenant | D19: Airside Vehicles | F19: =Calc2!H384 -> 0 | G19: =Calc2!I384 -> 0 | H19: =Calc2!J384 -> 0 | I19: =Calc2!K384 -> 0 | J19: =Calc2!L384 -> 0
C20: Tenant | D20: Buildings (gas/oil/coal) | F20: =+Calc2!F430 -> 0 | G20: =+Calc2!G430 -> 0 | H20: =+Calc2!H430 -> 0 | I20: =+Calc2!I430 -> 0 | J20: =+Calc2!J430 -> 0
C21: Tenant | D21: Electricity Purchase | K21: LAQ not calculated
C22: Tenant | D22: Heat Purchase | F22: =Calc2!F460 -> 0 | G22: =Calc2!G460 -> 0 | H22: =Calc2!H460 -> 0 | I22: =Calc2!I460 -> 0 | J22: =Calc2!J460 -> 0
C23: Tenant | D23: Fire Training | F23: =Calc2!H478 -> 0 | G23: =Calc2!I478 -> 0 | H23: =Calc2!J478 -> 0 | I23: =Calc2!K478 -> 0 | J23: =Calc2!L478 -> 0
C24: Tenant | D24: Emergency Generator | F24: =Calc2!G495 -> 0 | G24: =Calc2!H495 -> 0 | H24: =Calc2!I495 -> 0 | I24: =Calc2!J495 -> 0 | J24: =Calc2!K495 -> 0
C25: Tenant | D25: Landside Vehicles | F25: =Calc2!F922 -> 20.266524 | G25: =Calc2!G922 -> 18.100459 | H25: =Calc2!H922 -> 170.0067 | I25: =Calc2!I922 -> 0.30962479 | J25: =Calc2!J922 -> 0.05236512
C26: Airport | D26: Employee Vehicles | F26: =Calc2!F908 -> 1.951164 | G26: =Calc2!G908 -> 1.7700912 | H26: =Calc2!H908 -> 16.621646 | I26: =Calc2!I908 -> 0.024961752 | J26: =Calc2!J908 -> 0.005115456
B27: Tenant Sub-total | F27: =SUM(F15:F26) -> 23.612005 | G27: =SUM(G15:G26) -> 19.923039 | H27: =SUM(H15:H26) -> 187.29261 | I27: =SUM(I15:I26) -> 0.33995848 | J27: =SUM(J15:J26) -> 0.10927843
B28: Public | C28: Ground Access Vehicles | D28: Cars, taxi | F28: =Calc2!F928 -> 0.0019813626 | G28: =Calc2!G928 -> 0.0016208321 | H28: =Calc2!H928 -> 0.015243828 | I28: =Calc2!I928 -> 5.6526263e-05 | J28: =Calc2!J928 -> 4.7187168e-06
D29: Bus, shuttles | F29: =Calc2!F929 -> 0.3873672 | G29: =Calc2!G929 -> 0.05586836 | H29: =Calc2!H929 -> 0.5344038 | I29: =Calc2!I929 -> 0.01099891 | J29: =Calc2!J929 -> 0.0001893328
D30: Rail | F30: =Calc2!F930 -> 0 | G30: =Calc2!G930 -> 0 | H30: =Calc2!H930 -> 0 | I30: =Calc2!I930 -> 0 | J30: =Calc2!J930 -> 0
B31: Public Sub-total | F31: =SUM(F28:F30) -> 0.38934856 | G31: =SUM(G28:G30) -> 0.057489192 | H31: =SUM(H28:H30) -> 0.54964763 | I31: =SUM(I28:I30) -> 0.011055436 | J31: =SUM(J28:J30) -> 0.00019405152
B33: APPROXIMATE LAQ EMISSIONS | F33: =+F14+F27+F31 -> 24.001437 | G33: =+G14+G27+G31 -> 19.98058 | H33: =+H14+H27+H31 -> 187.84277 | I33: =+I14+I27+I31 -> 0.35101421 | J33: =+J14+J27+J31 -> 0.10947279 | K33: tonnes
E35: The landside traffic calculations for this inventory were based on: | J35: =IF(Calc1!E279="No.", "estimated traffic data", "a detailed traffic survey") -> estimated traffic data

Sheet xfer
A1: Notes: This page is for tranfer of the main data to an ACI database. | AU1: Onsite Elect generation? | BS1: Infrastructure for alternative fuel | CE1: Terminal Gates APU replacement | CU1: Outputs (tonnes per year)
CU2: Airport CO2e | DB2: Tenant/Staff CO2e | DW2: Airport LAQ | EB2: Tenant LAQ | EG2: GAV LAQ
A3: Airport code | B3: Airport Name: | C3: City: | D3: Airport Operator: | E3: ICAO Identifier: | F3: Country: | G3: Contact | H3: Position: | I3: email: | J3: date | K3: inventory yr | L3: AC mvt | M3: PAX | N3: Cargo | O3: Permission | P3: Prev GHG inventory | Q3: Send to ACI | R3: Other year | S3: Electricity Purchase | T3: El onsold | U3: Nat EF gCO2/kWh | V3: Actual EF | W3: Heat purch | X3: Heat purchase unit | Y3: Heat source | Z3: Heat onsold | AA3: Annual movements declared | AB3: Average Taxi Time | AC3: APU sm-med | AD3: APU Large aircraft | AE3: Traff study? | AF3: trip distance | AG3: Tirp distance method | AH3: % PAX connecting | AI3: % pax on Public Transport: | AJ3: Train # of service | AK3: distance | AL3: Subway # services | AM3: distance | AN3: # Apt emplees | AO3: #Tenant emplees | AP3: #Tenant visitors/day | AQ3: Equiv full time env staff | AR3: Environmental Report | AU3: Solar/PV | AV3: kW | AW3: MWh/yr | AX3: Comment | AY3: Solar hot water | AZ3: kW | BA3: MWh/yr | BB3: Comment | BC3: Wind turbine | BD3: kW | BE3: MWh/yr | BF3: Comment | BG3: Geothermal | BH3: kW | BI3: MWh/yr | BJ3: Comment | BK3: Hydroelectricity | BL3: kW | BM3: MWh/yr | BN3: Comment | BO3: Other | BP3: kW | BQ3: MWh/yr | BR3: Comment | BS3: CNG for vehicles | BU3: LPG for vehicles | BW3: Biofuels | BY3: Liquid Hydrogen | CA3: Electric veh recharge station | CC3: Other | CE3: # of bridges or contact gates | CG3: # with FEGP | CI3: # with PCA | CK3: # remote stands | CM3: # with FEGP | CO3: # with PCA | CQ3: # GPU available | CS3: # ACU available | CU3: Apt Veh airside | CV3: bldgs | CW3: fire training | CX3: em gens | CY3: glycol | CZ3: el purchase | DA3: heat purch | DB3: Ten LTO | DC3: APU | DD3: Eng runup | DE3: AC deice | DF3: Aside veh | DG3: Ten blds | DH3: El purch | DI3: heat purch | DJ3: fire tenant | DK3: em gen | DL3: landside veh | DM3: apt empl veh | DN3: GAV Cars | DO3: GAV Buses | DP3: GAV Trains | DQ3: GAV | DR3: Total Co2e | DS3: Apt sc1 | DT3: Apt sc2 | DU3: Apt sc3 | DV3: kg CO2e/traffic unit/year | DW3: Apt NOx | DX3: VOC | DY3: CO | DZ3: PM | EA3: SOx | EB3: Tenant NOx | EC3: VOC | ED3: CO | EE3: PM | EF3: SOx | EG3: GAV NOx | EH3: VOC | EI3: CO | EJ3: PM | EK3: SOx
A4: =Calc1!C6 -> XYZ | B4: =Calc1!C4 -> 0 | C4: =Calc1!C8 -> 0 | D4: =Calc1!H4 -> 0 | E4: =Calc1!F6 -> WXYZ | F4: =Calc1!C10 -> Albania | G4: =Calc1!C13 -> name | H4: =Calc1!C14 -> 0 | I4: =Calc1!C15 -> 0 | J4: =Calc1!J6 -> 41153 | K4: =Calc1!J8 -> 2011 | L4: =Calc1!J10 -> 100 | M4: =Calc1!J11 -> 100 | N4: =Calc1!J12 -> 10 | O4: =Calc1!E17 -> unconditionally | P4: =Calc1!E18 -> No | Q4: =Calc1!E19 -> No | R4: =Calc1!G19 -> 0 | S4: =Calc1!F91 -> 5 | T4: =Calc1!F93 -> 0 | U4: =Calc1!F95 -> 34.4395 | V4: =Calc1!W6 -> 0 | W4: =+Calc1!F101 -> 0 | X4: =+Calc1!G101 -> kWh | Y4: =+Calc1!F103 -> Natural Gas | Z4: =+Calc1!F105 -> not used | AA4: =Calc1!I153 -> 100 | AB4: =Calc1!C168 -> 26 | AC4: =Calc1!C172 -> 15 | AD4: =Calc1!C173 -> 45 | AE4: =+Calc1!E279 -> No. | AF4: =Calc1!G285 -> 30 | AG4: =+Calc1!G288 -> How I chose the vehicle travel distance? | AH4: =Calc1!F292 -> 0.3 | AI4: =Calc1!E296 -> 0.2 | AJ4: =+Calc1!F345 -> 1 | AK4: =+Calc1!G345 -> 5 | AL4: =+Calc1!F346 -> 1 | AM4: =+Calc1!G346 -> 5 | AN4: =+Calc1!E361 -> 100 | AO4: =+Calc1!E380 -> 1000 | AP4: =+Calc1!I400 -> 40 | AQ4: =+Calc1!D468 -> 1 | AR4: =+Calc1!D472 -> no | AS4: =+Calc1!E472 -> 2000 | AT4: =+Calc1!I472 -> 0 | AU4: =+Calc1!D517 -> yes | AV4: =+Calc1!I517 -> 0 | AW4: 0 | AX4: =+Calc1!I517 -> 0 | AY4: =+Calc1!D518 -> no | AZ4: =+Calc1!E518 -> 0 | BA4: 0 | BB4: =+Calc1!I518 -> 0 | BC4: =+Calc1!D519 -> no | BD4: =+Calc1!E519 -> 0 | BE4: 0 | BF4: =+Calc1!I519 -> 0 | BG4: =+Calc1!D520 -> no | BH4: =+Calc1!E520 -> 0 | BI4: 0 | BJ4: =+Calc1!I520 -> 0 | BK4: =+Calc1!D521 -> no | BL4: =+Calc1!E521 -> 0 | BM4: 0 | BN4: =+Calc1!I521 -> 0 | BO4: =+Calc1!D522 -> no | BP4: =+Calc1!E522 -> 0 | BQ4: 0 | BR4: =+Calc1!I522 -> 0 | BS4: =+Calc1!D539 -> no | BT4: =+Calc1!I539 -> 0 | BU4: =+Calc1!D540 -> no | BV4: =+Calc1!I540 -> 0 | BW4: =+Calc1!D541 -> no | BX4: =+Calc1!I541 -> 0 | BY4: =+Calc1!D542 -> no | BZ4: =+Calc1!I542 -> 0 | CA4: =+Calc1!D543 -> no | CB4: =+Calc1!I543 -> 0 | CC4: =+Calc1!D544 -> no | CD4: =+Calc1!I544 -> 0 | CE4: =+Calc1!D547 -> 99 | CF4: =+Calc1!I547 -> 0 | CG4: =+Calc1!D548 -> 99 | CH4: =+Calc1!I548 -> 0 | CI4: =+Calc1!D549 -> 99 | CJ4: =+Calc1!I549 -> 0 | CK4: =+Calc1!D551 -> 99 | CL4: =+Calc1!I551 -> 0 | CM4: =+Calc1!D552 -> 99 | CN4: =+Calc1!I552 -> 0 | CO4: =+Calc1!D553 -> 99 | CP4: =+Calc1!I553 -> 0 | CQ4: =+Calc1!D554 -> 99 | CR4: =+Calc1!I554 -> 0 | CS4: =+Calc1!D555 -> 99 | CT4: =+Calc1!I555 -> 0 | CU4: =+Output!J7 -> 0.01180771 | CV4: =+Output!J8 -> 0.018695247 | CW4: =+Output!J9 -> 0 | CX4: =+Output!J10 -> 0 | CY4: =+Output!J11 -> 0 | CZ4: =+Output!J12 -> 0.0001721975 | DA4: =+Output!J13 -> 0 | DB4: =+Output!J15 -> 306.52579 | DC4: =+Output!J16 -> 29.163861 | DD4: =+Output!J17 -> 0.0049312845 | DE4: =+Output!J18 -> 0 | DF4: =+Output!J19 -> 0 | DG4: =+Output!J20 -> 0 | DH4: =+Output!J21 -> 0 | DI4: =+Output!J22 -> 0 | DJ4: =+Output!J23 -> 0 | DK4: =+Output!J24 -> 0 | DL4: =+Output!J25 -> 4606.7012 | DM4: =+Output!J26 -> 450.08901 | DN4: =+Output!J25 -> 4606.7012 | DO4: =+Output!J26 -> 450.08901 | DP4: =+Output!J27 -> 5392.4848 | DQ4: =+Output!J28 -> 0.44295885 | DR4: =+Output!J32 -> 5434.4864 | DS4: =+Output!C34 -> 0.030502957 | DT4: =+Output!C35 -> 0.0001721975 | DU4: =+Output!C36 -> 5434.4557 | DV4: =+Output!J38 -> 0 | DW4: =+LAQ!F14 -> 8.31658e-05 | DX4: =+LAQ!G14 -> 5.209882e-05 | DY4: =+LAQ!H14 -> 0.0005085782 | DZ4: =+LAQ!I14 -> 2.9641e-07 | EA4: =+LAQ!J14 -> 3.1247e-07 | EB4: =+LAQ!F27 -> 23.612005 | EC4: =+LAQ!G27 -> 19.923039 | ED4: =+LAQ!H27 -> 187.29261 | EE4: =+LAQ!I27 -> 0.33995848 | EF4: =+LAQ!J27 -> 0.10927843 | EG4: =+LAQ!F31 -> 0.38934856 | EH4: =+LAQ!G31 -> 0.057489192 | EI4: =+LAQ!H31 -> 0.54964763 | EJ4: =+LAQ!I31 -> 0.011055436 | EK4: =+LAQ!J31 -> 0.00019405152
A7: Short Summary
B8: Airport Name: | C8: =+L3 -> AC mvt | D8: Pax | E8: Traff units | F8: =+K3 -> inventory yr | G8: Scope 1 | H8: Scope 2 | I8: Scope 3 | J8: Total | K8: Total/TU | L8: Sc1&2/TU | M8: Nat'l EF | N8: EF Used
A9: =+A4 -> XYZ | B9: =+B4 -> 0 | C9: =+Output!L2 -> 100 | D9: =+Output!L3 -> 100 | E9: =+Output!L4 -> 200 | F9: =+K4 -> 2011 | G9: =+Output!C34 -> 0.030502957 | H9: =+Output!C35 -> 0.0001721975 | I9: =+Output!C36 -> 5434.4557 | J9: =+Output!J33 -> 5434.4864 | K9: =+J9/E9*1000 -> 27172.432 | L9: =+(G9+H9)/E9*1000 -> 0.15337577 | M9: =+Output!H3 -> 34.4395 | N9: =+Output!H4 -> 34.4395

Sheet Calc1
A1: Calc 1 - Data processing page. | J1: =C4 -> 0 | K1: =J8 -> 2011
A2: GENERAL AIRPORT INFORMATION
A4: Mirror | B4: Airport Name: | C4: =+Input!C4 -> 0 | G4: Airport Operator: | H4: =+Input!H4 -> 0
A5: Input
A6: Page | B6: IATA Identifier: | C6: =+Input!C5 -> XYZ | D6: (3 letters) | E6: ICAO Identifier: | F6: =+Input!F5 -> WXYZ | G6: (4 letters) | I6: Date of Report (DD/MM/YYYY): | J6: =+Input!J5 -> 41153
B8: City: | C8: =+Input!C7 -> 0 | D8: =+Input!D7 -> 0 | E8: =+Input!E7 -> 0 | F8: =+Input!F7 -> 0 | I8: Calendar Year of Inventory: | J8: =+Input!J6 -> 2011
B10: Country: | C10: =+Input!C8 -> Albania | E10: ACI Region: | F10: =+Input!F8 -> Select One | I10: Aircraft movements in inventory year | J10: =+Input!J9 -> 100 | K10: movements
B11: Province: | C11: =+Input!C9 -> n/a | D11: (Canada only, otherwise select n/a) | I11: Passengers Movements in Inventory year | J11: =+Input!J10 -> 100 | K11: movements
I12: Cargo in inventory year | J12: =+Input!J11 -> 10 | K12: tonnes
B13: Inventory compiled by: | C13: =+Input!C11 -> name
B14: Position: | C14: =+Input!C12 -> 0
B15: email: | C15: =+Input!C13 -> 0
D17: Permission: This data is made available to ACI | E17: =+Input!E15 -> unconditionally | I17: Unit System: | J17: Metric (e.g. metres, litres, kg)
D18: Have you ever conducted a more detailed GHG inventory? | E18: =+Input!E16 -> No
D19: If yes, will you submit it to ACI with this inventory? | E19: =+Input!E17 -> No | F19: Most recent year? | G19: =+Input!G17 -> 0 | I19: Reminder: Save file under a new name eg LHR2012
B20: Note: - Make sure you can see Columns A through K
A22: SCOPE 1 - DIRECT EMISSIONS FROM SOURCES THAT ARE OWNED AND CONTROLLED BY THE AIRPORT OPERATOR
A24: Step 1-1: Input information for AIRPORT OPERATOR FLEET VEHICLES (vehicles, machinery and GSE)
A26: Mirror | B26: 1) Input total annual fuel usage for Airport Fleet | K26: Beta version - You can type comments here>>>>
A27: Input | B27: Fuel | C27: Volume | D27: Unit | E27: Note: Do not include ACU or GPU fuel. This is below.
A28: Page | B28: Gasoline | C28: =Input!D24 -> 5 | D28: litre | E28: Note: Include only fuel for airport owned vehicles.
B29: Diesel | C29: =Input!D25 -> 0 | D29: litre
B30: Natural Gas | C30: =Input!D26 -> 0 | D30: kg
B31: Propane | C31: =Input!D27 -> 0 | D31: litre
F32: Note: This table requires estimating the proportions of the fuel going into vehicles of different sizes.
B33: 1a) Input approximate percentages of fuel use in different vehicles | F33: Note: This data is for the Local Air Quality calculations, not for CO2
D34: Gasoline | E34: Diesel | F34: Note: Leave default values if estimates cannot be made. | J34: Gasoline (litre) | K34: Diesel (litre)
A35: Not on | B35: Passenger cars | D35: 0.8 | E35: 0.1 | F35: - cars and vehicles <2 tonnes | J35: =$C$28*D35 -> 4 | K35: =$C$29*E35 -> 0
A36: Input page | B36: Light-duty vehicles | D36: 0.2 | E36: 0.4 | F36: - vans and small buses typically <20 seats or 2-3.5 tonnes | J36: =$C$28*D36 -> 1 | K36: =$C$29*E36 -> 0
B37: Heavy-duty vehicles | D37: 0 | E37: 0.5 | F37: - buses, trucks, machinery > 20 seats or >3.5 tonnes | J37: =$C$28*D37 -> 0 | K37: =$C$29*E37 -> 0
D38: =+SUM(D35:D37) -> 1 | E38: =+SUM(E35:E37) -> 1
D39: =IF(SUM(D35:D37)>1, "> 100%, revise!", IF(SUM(D35:D37)<1, "< 100%, revise!", "Total % is OK.")) -> Total % is OK. | E39: =IF(SUM(E35:E37)>1, "> 100%, revise!", IF(SUM(E35:E37)<1, "< 100%, revise!", "Total % is OK.")) -> Total % is OK. | F39: Note: Percentages must add to 100%. Use whole numbers, no decimals.
B41: 2) Input total annual fuel usage for mobile equipment - Airport owned
E42: Gasoline | F42: Diesel | G42: Unit
B43: Mobile Air Conditioning Units (ACU) - Airport owned | E43: 0 | G43: litre | H43: This is included above
B44: Ground Power Units (GPU) - Airport owned | E44: 0 | G44: litre
A46: Step 1-2: Input information for AIRPORT OWNED AND OPERATED buildings (e.g. Power/electricity generation, heating/cooling plant, ATB, maintenance garage, etc.)
B48: 1) For buildings with metered fuel usage, input annual total usage: | F48: Note: Do not include Electricity - See Step 2
B49: Building Name | C49: Natural Gas | D49: Unit (Choose kg, m3 or GJ) | E49: Fuel Oil | F49: Unit | G49: Coal | H49: Unit
A50: Mirror | B50: =+Input!B52 -> eg Heating plant | C50: =+Input!C52 -> 10 | D50: =+Input!D52 -> m3 | E50: =+Input!E52 -> 0 | F50: litre | G50: =+Input!G52 -> 0 | H50: kg
...

Sheet Calc2
A1: Calculation Page 2
B4: =Calc1!A22 -> SCOPE 1 - DIRECT EMISSIONS FROM SOURCES THAT ARE OWNED AND CONTROLLED BY THE AIRPORT OPERATOR
A6: Step 1-1 | B6: Airside Vehicle Emission Calculation (Ton):
B8: Vehicle Type | C8: Volume (Liter) | E8: CO2 | F8: CH4 | G8: N2O | H8: NOx | I8: VOC | J8: CO | K8: PM | L8: SOx | M8: co2
B9: Light Gas Vehicle | C9: =Calc1!J35 -> 4 | D9: Gas EF (kg/L) | E9: 2.289 | F9: 0.00052 | G9: 0.0002 | H9: =14.5*730/1000/1000 -> 0.010585 | I9: =14*730/1000/1000 -> 0.01022 | J9: =132*730/1000/1000 -> 0.09636 | K9: =0.037*730/1000/1000 -> 2.701e-05 | L9: =0.04*730/1000/1000 -> 2.92e-05 | M9: =3180*730/1000/1000 -> 2.3214
B10: Light Gas Truck | C10: =Calc1!J36 -> 1 | D10: Gas EF (kg/L) | E10: 2.289 | F10: 0.00043 | G10: 0.0002 | H10: =24*730/1000/1000 -> 0.01752 | I10: =14*730/1000/1000 -> 0.01022 | J10: =155*730/1000/1000 -> 0.11315 | K10: =0.03*730/1000/1000 -> 2.19e-05 | L10: =0.04*730/1000/1000 -> 2.92e-05 | M10: =3180*730/1000/1000 -> 2.3214
B11: Heavy Gas Vehicle | C11: =Calc1!J37 -> 0 | D11: Gas EF (kg/L) | E11: 2.289 | F11: 0.00068 | G11: 0.0002 | H11: =Stat!H21*730/1000/1000 -> 0.027220339 | I11: =Stat!I21*730/1000/1000 -> 0.021652542 | J11: =Stat!J21*730/1000/1000 -> 0.24539548 | K11: =Stat!K21*730/1000/1000 -> 0 | L11: =Stat!M21*730/1000/1000 -> 2.92e-05
B13: Light Diesel Vehicle | C13: =Calc1!K35 -> 0 | D13: Diesel EF (kg/L) | E13: 2.663 | F13: 6.8e-05 | G13: 0.00021 | H13: =11*840/1000/1000 -> 0.00924 | I13: =1.1*840/1000/1000 -> 0.000924 | J13: =4.7*840/1000/1000 -> 0.003948 | K13: =1.7*840/1000/1000 -> 0.001428 | L13: =0.008*840/1000/1000 -> 6.72e-06 | M13: =3140*840/1000/1000 -> 2.6376
B14: Light Diesel Truck | C14: =Calc1!K36 -> 0 | D14: Diesel EF (kg/L) | E14: 2.663 | F14: 6.8e-05 | G14: 0.00021 | H14: =15*840/1000/1000 -> 0.0126 | I14: =1.75*840/1000/1000 -> 0.00147 | J14: =11*840/1000/1000 -> 0.00924 | K14: =2.8*840/1000/1000 -> 0.002352 | L14: =0.008*840/1000/1000 -> 6.72e-06
B15: Heavy Diesel Vehicle | C15: =Calc1!K37 -> 0 | D15: Diesel EF (kg/L) | E15: 2.663 | F15: 0.00014 | G15: 8.2e-05 | H15: =37*840/1000/1000 -> 0.03108 | I15: =1.6*840/1000/1000 -> 0.001344 | J15: =8*840/1000/1000 -> 0.00672 | K15: =1.2*840/1000/1000 -> 0.001008 | L15: =0.008*840/1000/1000 -> 6.72e-06
N16: co2e | O16: check - i.e. should = output total for both fuel types next sheet
D17: Gas Em | E17: =SUMPRODUCT($C$9:$C$11,E9:E11)/1000 -> 0.011445 | F17: =SUMPRODUCT($C$9:$C$11,F9:F11)/1000 -> 2.51e-06 | G17: =SUMPRODUCT($C$9:$C$11,G9:G11)/1000 -> 1e-06 | H17: =SUMPRODUCT($C$9:$C$11,H9:H11)/1000 -> 5.986e-05 | I17: =SUMPRODUCT($C$9:$C$11,I9:I11)/1000 -> 5.11e-05 | J17: =SUMPRODUCT($C$9:$C$11,J9:J11)/1000 -> 0.00049859 | K17: =SUMPRODUCT($C$9:$C$11,K9:K11)/1000 -> 1.2994e-07 | L17: =SUMPRODUCT($C$9:$C$11,L9:L11)/1000 -> 1.46e-07 | N17: =E17+F17*21+G17*310 -> 0.01180771
D18: Diesel Em | E18: =SUMPRODUCT($C$13:$C$15,E13:E15)/1000 -> 0 | F18: =SUMPRODUCT($C$13:$C$15,F13:F15)/1000 -> 0 | G18: =SUMPRODUCT($C$13:$C$15,G13:G15)/1000 -> 0 | H18: =SUMPRODUCT($C$13:$C$15,H13:H15)/1000 -> 0 | I18: =SUMPRODUCT($C$13:$C$15,I13:I15)/1000 -> 0 | J18: =SUMPRODUCT($C$13:$C$15,J13:J15)/1000 -> 0 | K18: =SUMPRODUCT($C$13:$C$15,K13:K15)/1000 -> 0 | L18: =SUMPRODUCT($C$13:$C$15,L13:L15)/1000 -> 0 | N18: =E18+F18*21+G18*310 -> 0 | O18: =SUM(N17:N18) -> 0.01180771
D20: Subtotal (t) | E20: =SUM(E17:E18) -> 0.011445 | F20: =SUM(F17:F18) -> 2.51e-06 | G20: =SUM(G17:G18) -> 1e-06 | H20: =SUM(H17:H18) -> 5.986e-05 | I20: =SUM(I17:I18) -> 5.11e-05 | J20: =SUM(J17:J18) -> 0.00049859 | K20: =SUM(K17:K18) -> 1.2994e-07 | L20: =SUM(L17:L18) -> 1.46e-07
B22: Vehicle Type | C22: units | E22: CO2 | F22: CH4 | G22: N2O | H22: NOx | I22: VOC | J22: CO | K22: PM | L22: SOx
B23: Natural Gas Vehicle | C23: =Calc1!C30/1000 -> 0 | D23: CNG EF | E23: 148 | F23: =1000*0.000009 -> 0.009 | G23: =1000*0.00000006 -> 6e-05 | H23: 0.056 | I23: 0.015 | J23: 0.395 | K23: 0.002 | L23: 0
B24: Propane Vehicle | C24: =Calc1!C31/1000 -> 0 | D24: Propane EF (kg/m3) | E24: =1000*1.51 -> 1510 | F24: =1000*0.00064 -> 0.64 | G24: =1000*0.000028 -> 0.028 | H24: =15.5*510/1000 -> 7.905 | I24: =10*510/1000 -> 5.1 | J24: =68*510/1000 -> 34.68 | K24: 0 | L24: 0
D26: CNG Em (tonne) | E26: =$C$23*1000/50*E23/1000/1000 -> 0 | F26: =$C$23/0.714*F23/1000 -> 0 | G26: =$C$23/0.714*G23/1000 -> 0 | H26: =$C$23*1000/50*H23/1000/1000 -> 0 | I26: =$C$23*1000/50*I23/1000/1000 -> 0 | J26: =$C$23*1000/50*J23/1000/1000 -> 0 | K26: =$C$23*1000/50*K23/1000/1000 -> 0 | L26: =$C$23*1000/50*L23/1000/1000 -> 0
D27: Propane em (tonne) | E27: =$C$24*E24/1000 -> 0 | F27: =$C$24*F24/1000 -> 0 | G27: =$C$24*G24/1000 -> 0 | H27: =$C$24*H24/1000 -> 0 | I27: =$C$24*I24/1000 -> 0 | J27: =$C$24*J24/1000 -> 0 | K27: =$C$24*K24/1000 -> 0 | L27: =$C$24*L24/1000 -> 0
D29: Subtotal | E29: =SUM(E26:E27) -> 0 | F29: =SUM(F26:F27) -> 0 | G29: =SUM(G26:G27) -> 0 | H29: =SUM(H26:H27) -> 0 | I29: =SUM(I26:I27) -> 0 | J29: =SUM(J26:J27) -> 0 | K29: =SUM(K26:K27) -> 0 | L29: =SUM(L26:L27) -> 0
B31: ACU | C31: Volume (L) | E31: CO2 | F31: CH4 | G31: N2O | H31: NOx | I31: VOC | J31: CO | K31: PM | L31: SOx
B32: Gasoline | C32: =Calc1!E43 -> 0 | D32: Gas EF (kg/L) | E32: 2.289 | F32: 0.00052 | G32: 0.0002 | H32: =14.5*730/1000/1000 -> 0.010585 | I32: =14*730/1000/1000 -> 0.01022 | J32: =132*730/1000/1000 -> 0.09636 | K32: =0.037*730/1000/1000 -> 2.701e-05 | L32: =0.04*730/1000/1000 -> 2.92e-05
B33: Diesel | C33: =Calc1!F43 -> 0 | D33: Diesel EF (kg/L) | E33: 2.663 | F33: 6.8e-05 | G33: 0.00021 | H33: =11*840/1000/1000 -> 0.00924 | I33: =1.1*840/1000/1000 -> 0.000924 | J33: =4.7*840/1000/1000 -> 0.003948 | K33: =1.7*840/1000/1000 -> 0.001428 | L33: =0.008*840/1000/1000 -> 6.72e-06
D34: Subtotal | E34: =SUMPRODUCT($C$32:$C$33,E32:E33)/1000 -> 0 | F34: =SUMPRODUCT($C$32:$C$33,F32:F33)/1000 -> 0 | G34: =SUMPRODUCT($C$32:$C$33,G32:G33)/1000 -> 0 | H34: =SUMPRODUCT($C$32:$C$33,H32:H33)/1000 -> 0 | I34: =SUMPRODUCT($C$32:$C$33,I32:I33)/1000 -> 0 | J34: =SUMPRODUCT($C$32:$C$33,J32:J33)/1000 -> 0 | K34: =SUMPRODUCT($C$32:$C$33,K32:K33)/1000 -> 0 | L34: =SUMPRODUCT($C$32:$C$33,L32:L33)/1000 -> 0
B36: GPU | E36: CO2 | F36: CH4 | G36: N2O | H36: NOx | I36: VOC | J36: CO | K36: PM | L36: SOx
B37: Gasoline | C37: =Calc1!E44 -> 0 | D37: Gas EF (kg/L) | E37: 2.289 | F37: 0.00052 | G37: 0.0002 | H37: =14.5*730/1000/1000 -> 0.010585 | I37: =14*730/1000/1000 -> 0.01022 | J37: =132*730/1000/1000 -> 0.09636 | K37: =0.037*730/1000/1000 -> 2.701e-05 | L37: =0.04*730/1000/1000 -> 2.92e-05
B38: Diesel | C38: =Calc1!F44 -> 0 | D38: Diesel EF (kg/L) | E38: 2.663 | F38: 6.8e-05 | G38: 0.00021 | H38: =11*840/1000/1000 -> 0.00924 | I38: =1.1*840/1000/1000 -> 0.000924 | J38: =4.7*840/1000/1000 -> 0.003948 | K38: =1.7*840/1000/1000 -> 0.001428 | L38: =0.008*840/1000/1000 -> 6.72e-06
D39: Subtotal | E39: =SUMPRODUCT($C$37:$C$38,E37:E38)/1000 -> 0 | F39: =SUMPRODUCT($C$37:$C$38,F37:F38)/1000 -> 0 | G39: =SUMPRODUCT($C$37:$C$38,G37:G38)/1000 -> 0 | H39: =SUMPRODUCT($C$37:$C$38,H37:H38)/1000 -> 0 | I39: =SUMPRODUCT($C$37:$C$38,I37:I38)/1000 -> 0 | J39: =SUMPRODUCT($C$37:$C$38,J37:J38)/1000 -> 0 | K39: =SUMPRODUCT($C$37:$C$38,K37:K38)/1000 -> 0 | L39: =SUMPRODUCT($C$37:$C$38,L37:L38)/1000 -> 0
D41: Airside Vehicle Subtotal | E41: =E20+E29+E34+E39 -> 0.011445 | F41: =F20+F29+F34+F39 -> 2.51e-06 | G41: =G20+G29+G34+G39 -> 1e-06 | H41: =H20+H29+H34+H39 -> 5.986e-05 | I41: =I20+I29+I34+I39 -> 5.11e-05 | J41: =J20+J29+J34+J39 -> 0.00049859 | K41: =K20+K29+K34+K39 -> 1.2994e-07 | L41: =L20+L29+L34+L39 -> 1.46e-07
B43: Note:
B44: Source: Environment Canada, "National Inventory Report 1990 - 2006", Annex 12 Table 12-7: Emission Factors for Energy Combustion Sources.
B45: Gasoline Vehicles: Light vehicle-Oxidation Catalyst; light truck-Oxidation Catalyst; heavy vehicle-three way catalyst.
B46: Diesel Vehicles: Moderate Control.
A48: Step 1-2 | B48: Building Emission Calculation (Ton)
B49: 1) Natural Gas
B50: Building | C50: Square Meter | D50: GJ/Annum | E50: Estimated NG (GJ)
F52: =SUM(E51:E52) -> 0
E53: =SUM(E51:E52) -> 0 | F53: GJ
E54: qty & unit as input
B55: Known NG total | E55: =Calc1!C59 -> 10 | F55: =Calc1!D59 -> m3
...

Sheet Acraft
A1: Data: Emission Factors for Aircraft
A2: Aircraft type | B2: #/Eng | C2: Typical engine | D2: Data | E2: Fuel (kg/LTO*) | F2: NOx (kg/ LTO*) | G2: HC (kg/ LTO*) | H2: CO (kg/ LTO*) | I2: PM (kg/ LTO*) | J2: SOx (kg/ LTO*) | K2: CO2 (kg/ LTO*) | L2: Fuel (g/min taxi) | M2: NOx (g/min taxi) | N2: HC (g/min taxi) | O2: CO (g/min taxi) | P2: PM (g/min taxi) | Q2: SOx (g/min taxi) | R2: CO2 (g/min taxi) | S2: FB (kg/min) | T2: Nox (g/min) | U2: HC (g/min) | V2: CO (g/min) | W2: PM (g/min) | X2: Sox (g/min) | Y2: CO2 (g/min)
A3: A109 | B3: 2H | C3: PW206C | D3: LSZH-H650 | E3: 69.888 | F3: 0.3214536 | G3: 1.3146354 | H3: 2.3507406 | I3: 0.00451832 | J3: 0.034944 | K3: 220.1472
A4: A119 | B4: 2H | C4: PT6B-37A | D4: LSZH-H900 | E4: 114.66 | F4: 0.8468148 | G4: 1.0201152 | H4: 1.3058838 | I4: 0.00738252 | J4: 0.05733 | K4: 361.179
A5: Airbus 300 | B5: 2J | C5: CF6-50A | D5: ICAO-3GE069 | E5: 973.44 | F5: 18.908528 | G5: 0.23956752 | H5: 2.0846969 | I5: 0.056265003 | J5: 0.48672 | K5: 3066.336 | L5: 19560 | M5: 66.504 | N5: 53.2032 | O5: 470.2224 | P5: 1.4568535 | Q5: 9.78 | R5: 61614 | S5: 4 | T5: 32 | U5: 2.1333333 | V5: 2.8 | W5: 0.53333333 | X5: 2 | Y5: 12600
A6: Airbus 310 | B6: 2J | C6: CF6-80A | D6: ICAO-1GE010 | E6: 967.26 | F6: 20.602452 | G6: 0.4416414 | H6: 2.124168 | I6: 0.060675899 | J6: 0.48363 | K6: 3046.869 | L6: 18000 | M6: 61.2 | N6: 113.22 | O6: 507.6 | P6: 1.8241209 | Q6: 9 | R6: 56700 | S6: 4 | T6: 32 | U6: 2.1333333 | V6: 2.8 | W6: 0.53333333 | X6: 2 | Y6: 12600
A7: Airbus 319 | B7: 2J | C7: CFM56-5B5P | D7: ICAO-3CM027 | E7: 406.812 | F7: 6.3916356 | G7: 0.2114424 | H7: 1.0259676 | I7: 0.017344058 | J7: 0.203406 | K7: 1281.4578 | L7: 11280 | M7: 42.864 | N7: 69.936 | O7: 338.4 | P7: 1.1018015 | Q7: 5.64 | R7: 35532 | S7: 1.7777778 | T7: 15.555556 | U7: 0.66666667 | V7: 6.8888889 | W7: 0.55555556 | X7: 0.88888889 | Y7: 5600
A8: Airbus 320 | B8: 2J | C8: CFM56-5B4P | D8: ICAO-3CM026 | E8: 504.168 | F8: 9.940416 | G8: 0.2006736 | H8: 0.9442152 | I8: 0.02194725 | J8: 0.252084 | K8: 1588.1292 | L8: 12480 | M8: 53.664 | N8: 57.408 | O8: 292.032 | P8: 1.0958119 | Q8: 6.24 | R8: 39312 | S8: 1.7777778 | T8: 15.555556 | U8: 0.66666667 | V8: 6.8888889 | W8: 0.55555556 | X8: 0.88888889 | Y8: 5600
A9: Airbus 321 | B9: 2J | C9: CFM56-5B1P | D9: ICAO-3CM023 | E9: 566.892 | F9: 12.739034 | G9: 0.1983804 | H9: 0.9418428 | I9: 0.023201222 | J9: 0.283446 | K9: 1785.7098 | L9: 13200 | M9: 59.4 | N9: 48.84 | O9: 261.36 | P9: 1.0857322 | Q9: 6.6 | R9: 41580 | S9: 1.7777778 | T9: 15.555556 | U9: 0.66666667 | V9: 6.8888889 | W9: 0.55555556 | X9: 0.88888889 | Y9: 5600
A10: Airbus 330 | B10: 2J | C10: PW4168 | D10: ICAO-9PW094 | E10: 1302.66 | F10: 26.543941 | G10: 0.04836 | H10: 1.0975669 | I10: 0.045550932 | J10: 0.65133 | K10: 4103.379 | L10: 30240 | M10: 123.3792 | N10: 28.728 | O10: 446.9472 | P10: 1.6578022 | Q10: 15.12 | R10: 95256 | S10: 4 | T10: 32 | U10: 2.1333333 | V10: 2.8 | W10: 0.53333333 | X10: 2 | Y10: 12600
A11: Airbus 340 | B11: 4J | C11: CFM56-5C4/1P | D11: ICAO-7CM047 | E11: 1220.664 | F11: 27.734873 | G11: 0.138 | H11: 2.0504208 | I11: 0.062235344 | J11: 0.610332 | K11: 3845.0916 | L11: 27600 | M11: 113.16 | N11: 138 | O11: 872.16 | P11: 2.9808 | Q11: 13.8 | R11: 86940 | S11: 4 | T11: 32 | U11: 2.1333333 | V11: 2.8 | W11: 0.53333333 | X11: 2 | Y11: 12600
A12: Airbus 380 | B12: 4J | C12: RR Trent 970 | D12: ICAO-8RR048 | E12: 2342.4 | F12: 58.07952 | G12: 0.0144 | H12: 2.43504 | I12: 0.075429778 | J12: 1.1712 | K12: 7378.56 | L12: 72000 | M12: 367.2 | N12: 14.4 | O12: 1087.2 | P12: 3.8814635 | Q12: 36 | R12: 226800 | S12: 4 | T12: 32 | U12: 2.1333333 | V12: 2.8 | W12: 0.53333333 | X12: 2 | Y12: 12600
A13: An-128 | B13: 4J | C13: D18T | D13: FOCA-J357 | E13: 2176.092 | F13: 45.257227 | G13: 1.1717208 | H13: 4.4182584 | I13: 0.10752268 | J13: 1.088046 | K13: 6854.6898 | L13: 56880 | M13: 170.64 | N13: 682.56 | O13: 3014.64 | P13: 7.9628987 | Q13: 28.44 | R13: 179172 | S13: 4 | T13: 32 | U13: 2.1333333 | V13: 2.8 | W13: 0.53333333 | X13: 2 | Y13: 12600
A14: An-70 | B14: 4T | C14: ZMKB D27 | D14: FAEED135 | E14: 375.612 | F14: 3.0774257 | G14: 0.78690708 | H14: 2.0163804 | I14: 0.027777304 | J14: 0.187806 | K14: 1183.1778 | L14: 18456 | M14: 64.96512 | N14: 325.01016 | O14: 804.6816 | P14: 3.6912 | Q14: 9.228 | R14: 58136.4 | S14: 4 | T14: 32 | U14: 2.1333333 | V14: 2.8 | W14: 0.53333333 | X14: 2 | Y14: 12600
A15: AN-72/74 | B15: 2J | C15: D-36 | D15: ICAO-1ZM001 | E15: 307.248 | F15: 5.45784 | G15: 0.0648 | H15: 0.6047688 | I15: 0.016527997 | J15: 0.153624 | K15: 967.8312 | L15: 12000 | M15: 66 | N15: 64.8 | O15: 248.4 | P15: 1.4230332 | Q15: 6 | R15: 37800 | S15: 1.7777778 | T15: 15.555556 | U15: 0.66666667 | V15: 6.8888889 | W15: 0.55555556 | X15: 0.88888889 | Y15: 5600
A16: ATR-42-300 | B16: 2T | C16: PW127E | D16: AIA-127B | E16: 103.5 | F16: 1.352706 | G16: 0 | H16: 0.311436 | I16: 0.00706652 | J16: 0.05175 | K16: 326.025 | L16: 6120 | M16: 42.228 | N16: 0 | O16: 56.304 | P16: 1.224 | Q16: 3.06 | R16: 19278
A17: ATR-72-200 | B17: 2T | C17: PW127F | D17: AIA-127B | E17: 103.5 | F17: 1.352706 | G17: 0 | H17: 0.311436 | I17: 0.00706652 | J17: 0.05175 | K17: 326.025 | L17: 6120 | M17: 42.228 | N17: 0 | O17: 56.304 | P17: 1.224 | Q17: 3.06 | R17: 19278
A18: BAe 146-300 | B18: 4J | C18: LF507 | D18: ICAO-1TL004 | E18: 331.2912 | F18: 3.4520351 | G18: 0.065956512 | H18: 0.93079032 | I18: 0.015178097 | J18: 0.1656456 | K18: 1043.5673 | L18: 10872 | M18: 35.66016 | N18: 51.31584 | O18: 411.28776 | P18: 1.516884 | Q18: 5.436 | R18: 34246.8 | S18: 1.7777778 | T18: 15.555556 | U18: 0.66666667 | V18: 6.8888889 | W18: 0.55555556 | X18: 0.88888889 | Y18: 5600
A19: BAe ATP | B19: 2T | C19: PW124 | D19: AIA-127B | E19: 103.5 | F19: 1.352706 | G19: 0 | H19: 0.311436 | I19: 0.00706652 | J19: 0.05175 | K19: 326.025 | L19: 6120 | M19: 42.228 | N19: 0 | O19: 56.304 | P19: 1.224 | Q19: 3.06 | R19: 19278
A20: BAe Jetstream 41 | B20: 2T | C20: TPE331-14GR | D20: FAEED136 | E20: 37.614 | F20: 0.39960564 | G20: 0.14743884 | H20: 0.2413476 | I20: 0.00263352 | J20: 0.018807 | K20: 11.84841 | L20: 1692 | M20: 4.83912 | N20: 133.85412 | O20: 104.058 | P20: 0.3384 | Q20: 0.846 | R20: 532.98
A21: Beech 1900D | B21: 2T | C21: PT6A-67D | D21: AIA-67D | E21: 47.76 | F21: 0.290748 | G21: 0.07623 | H21: 0.593394 | I21: 0.00349332 | J21: 0.02388 | K21: 150.444 | L21: 1800 | M21: 5.58 | N21: 31.68 | O21: 102.24 | P21: 0.36 | Q21: 0.9 | R21: 5670
A22: Beech 300 | B22: 2J | C22: FJ44-2A | D22: LSZH-FJ442A | E22: 27.996 | F22: 0.3215868 | G22: 0.023133 | H22: 0.1810812 | I22: 0.0038255017 | J22: 0.013998 | K22: 88.1874 | L22: 2520 | M22: 6.048 | N22: 5.7456 | O22: 80.892 | P22: 0.16212035 | Q22: 1.26 | R22: 7938 | S22: 1.7777778 | T22: 15.555556 | U22: 0.66666667 | V22: 6.8888889 | W22: 0.55555556 | X22: 0.88888889 | Y22: 5600
A23: Beech Super King 200B | B23: 2T | C23: PT6A-42 | D23: AIA-42 | E23: 45.516 | F23: 0.305871 | G23: 0.032184 | H23: 0.2539674 | I23: 0.003223572 | J23: 0.022758 | K23: 143.3754 | L23: 2160 | M23: 6.912 | N23: 32.184 | O23: 83.592 | P23: 0.432 | Q23: 1.08 | R23: 6804
A24: Beech Super King 350 | B24: 2T | C24: PT6A-60A | D24: AIA-67D | E24: 47.76 | F24: 0.290748 | G24: 0.07623 | H24: 0.593394 | I24: 0.00349332 | J24: 0.02388 | K24: 150.444 | L24: 1800 | M24: 5.58 | N24: 31.68 | O24: 102.24 | P24: 0.36 | Q24: 0.9 | R24: 5670
A25: Beech T-6A Texan | B25: 1T | C25: PT6A-68 | D25: AIA-67D | E25: 47.76 | F25: 0.290748 | G25: 0.07623 | H25: 0.593394 | I25: 0.00349332 | J25: 0.02388 | K25: 150.444 | L25: 1800 | M25: 5.58 | N25: 31.68 | O25: 102.24 | P25: 0.36 | Q25: 0.9 | R25: 5670
A26: Bell 206B | B26: 1H | C26: Allison 250-C20J | D26: LSZH-H650 | E26: 34.95 | F26: 0.1427598 | G26: 0.6153204 | H26: 1.0930386 | I26: 0.00227226 | J26: 0.017475 | K26: 110.0925
A27: Bell 230 | B27: 2H | C27: Allison 250-C30G2 | D27: LSZH-H650 | E27: 69.9 | F27: 0.2855196 | G27: 1.2306408 | H27: 2.1860772 | I27: 0.00454452 | J27: 0.03495 | K27: 220.185
A28: Bell 407/MDD 600N | B28: 1H | C28: Allison 250-C47 | D28: LSZH-H650 | E28: 34.95 | F28: 0.1427598 | G28: 0.6153204 | H28: 1.0930386 | I28: 0.00227226 | J28: 0.017475 | K28: 110.0925
A29: Bell 430 | B29: 2H | C29: Allison 250-C40B | D29: LSZH-H650 | E29: 69.9 | F29: 0.2855196 | G29: 1.2306408 | H29: 2.1860772 | I29: 0.00454452 | J29: 0.03495 | K29: 220.185
A30: Bell AB119 | B30: 2H | C30: PT6C-67C | D30: LSZH-H900 | E30: 114.66 | F30: 0.8468148 | G30: 1.0201152 | H30: 1.3058838 | I30: 0.00738252 | J30: 0.05733 | K30: 361.179
A31: Boeing 717 | B31: 2J | C31: BR715 | D31: ICAO-4BR002 | E31: 381.504 | F31: 6.4583597 | G31: 0.0072384 | H31: 0.82100112 | I31: 0.010983716 | J31: 0.190752 | K31: 1201.7376 | L31: 11520 | M31: 61.8624 | N31: 2.4192 | O31: 187.4304 | P31: 0.63810761 | Q31: 5.76 | R31: 36288 | S31: 1.7777778 | T31: 15.555556 | U31: 0.66666667 | V31: 6.8888889 | W31: 0.55555556 | X31: 0.88888889 | Y31: 5600
A32: Boeing 737 (300-500) | B32: 2J | C32: CFM56-3B1 | D32: ICAO-1CM004 | E32: 441.432 | F32: 5.8560888 | G32: 0.05595936 | H32: 1.2697032 | I32: 0.013520494 | J32: 0.220716 | K32: 1390.5108 | L32: 13680 | M32: 53.352 | N32: 31.1904 | O32: 470.592 | P32: 1.0710359 | Q32: 6.84 | R32: 43092 | S32: 1.7777778 | T32: 15.555556 | U32: 0.66666667 | V32: 6.8888889 | W32: 0.55555556 | X32: 0.88888889 | Y32: 5600
A33: Boeing 737 (600-900) | B33: 2J | C33: CFM56-7B24 | D33: ICAO-3CM032 | E33: 497.652 | F33: 8.8585356 | G33: 0.0824652 | H33: 0.8026608 | I33: 0.027860512 | J33: 0.248826 | K33: 1567.6038 | L33: 13080 | M33: 57.552 | N33: 34.008 | O33: 287.76 | P33: 1.2395989 | Q33: 6.54 | R33: 41202 | S33: 1.7777778 | T33: 15.555556 | U33: 0.66666667 | V33: 6.8888889 | W33: 0.55555556 | X33: 0.88888889 | Y33: 5600
A34: Boeing 747 (400) | B34: 4J | C34: CF6-80C2B4 | D34: ICAO-2GE043 | E34: 2105.832 | F34: 39.258727 | G34: 0.2226564 | H34: 2.319522 | I34: 0.08070063 | J34: 1.052916 | K34: 6633.3708 | L34: 48240 | M34: 225.7632 | N34: 76.7016 | O34: 953.2224 | P34: 2.8350793 | Q34: 24.12 | R34: 151956 | S34: 4 | T34: 32 | U34: 2.1333333 | V34: 2.8 | W34: 0.53333333 | X34: 2 | Y34: 12600
A35: Boeing 757 | B35: 2J | C35: RB211-535C | D35: ICAO-1RR012 | E35: 822.48 | F35: 16.489927 | G35: 0.2407392 | H35: 0.7859976 | I35: 0.040035543 | J35: 0.41124 | K35: 2590.812 | L35: 24000 | M35: 82.56 | N35: 34.56 | O35: 450.96 | P35: 1.7961481 | Q35: 12 | R35: 75600 | S35: 1.7777778 | T35: 15.555556 | U35: 0.66666667 | V35: 6.8888889 | W35: 0.55555556 | X35: 0.88888889 | Y35: 5600
A36: Boeing 767-300 | B36: 2J | C36: CF6-80C2 | D36: ICAO-2GE036 | E36: 1067.748 | F36: 20.205902 | G36: 0.1124058 | H36: 1.1485016 | I36: 0.041364598 | J36: 0.533874 | K36: 3363.4062 | L36: 24120 | M36: 112.8816 | N36: 38.3508 | O36: 476.6112 | P36: 1.4175396 | Q36: 12.06 | R36: 75978 | S36: 4 | T36: 32 | U36: 2.1333333 | V36: 2.8 | W36: 0.53333333 | X36: 2 | Y36: 12600
A37: Boeing 777 | B37: 2J | C37: RR Trent 892 | D37: ICAO-2RR027 | E37: 1662.84 | F37: 48.012708 | G37: 0.02861424 | H37: 0.9997632 | I37: 0.058148729 | J37: 0.83142 | K37: 5237.946 | L37: 36000 | M37: 191.88 | N37: 25.2 | O37: 470.52 | P37: 2.2861386 | Q37: 18 | R37: 113400 | S37: 4 | T37: 32 | U37: 2.1333333 | V37: 2.8 | W37: 0.53333333 | X37: 2 | Y37: 12600
A38: Boeing 787 | B38: 2J | C38: RR Trent 1000 | D38: ICAO | S38: 4 | T38: 32 | U38: 2.1333333 | V38: 2.8 | W38: 0.53333333 | X38: 2 | Y38: 12600
A39: C-130 Hercules | B39: 4T | C39: Allison AE2100 | D39: FOCA-T201 | E39: 282.984 | F39: 2.6284016 | G39: 0.027784728 | H39: 1.0931473 | I39: 0.021129944 | J39: 0.141492 | K39: 891.3996 | L39: 12504 | M39: 30.147144 | N39: 14.217048 | O39: 215.79403 | P39: 2.5008 | Q39: 6.252 | R39: 39387.6
A40: C-27 Spartan | B40: 2T | C40: Allison AE2100 | D40: FOCA-T201 | E40: 141.492 | F40: 1.3142008 | G40: 0.013892364 | H40: 0.54657367 | I40: 0.010564972 | J40: 0.070746 | K40: 445.6998 | L40: 6252 | M40: 15.073572 | N40: 7.108524 | O40: 107.89702 | P40: 1.2504 | Q40: 3.126 | R40: 19693.8
...

Sheet Stat
A1: Data: Emission Factors for Stationary Sources and Others
A2: Emission source | B2: Carburant | C2: Data Source/Reference | D2: Input metric | E2: Conversion unit | F2: Conversion value | G2: EI units | H2: EI NOx | I2: EI VOC | J2: EI CO | K2: EI PM | L2: EI CO2 | M2: EI SOx | N2: Extra comment
A3: Stationary sources
A4: Building Heating (50kW-1MW) | B4: Coal | C4: CORINAIR, 2009, 1.A.4.a.i | D4: kg coal | E4: MJ/kg carburant | F4: 28.1 | G4: g/GJ | H4: 160 | I4: 200 | J4: 2000 | K4: 190 | L4: 94000 | M4: 900
A5: Building Heating (50kW-1MW) | B5: Natural Gas | C5: CORINAIR, 2009, 1.A.4.a.i | D5: kg natural gas | E5: MJ/kg carburant | F5: 46.5 | G5: g/GJ | H5: 70 | I5: 3 | J5: 30 | K5: 0.5 | L5: 55000 | M5: 0.5
A6: Building Heating | B6: Light Oil | C6: CORINAIR, 2009, 1.A.4.a.i | D6: kg light/gas oil | E6: MJ/kg carburant | F6: 42.6 | G6: g/GJ | H6: 398 | I6: 0.19 | J6: 1.49 | K6: 3 | L6: 73700 | M6: 46.1
A7: Emergency Generator | B7: Diesel | C7: CORINAIR, 1990 | D7: kg diesel | E7: MJ/kg carburant | F7: 42.7 | G7: g/GJ | H7: 1400 | I7: 70 | J7: 210 | K7: 30 | L7: 73000 | M7: 65
A8: Fire training | B8: Kerosene | C8: US FAA (EDMS 4.2, App. H) | D8: kg kerosene | G8: g/kg | H8: 5.04 | I8: 20.22 | J8: 672.08 | K8: 151.88 | L8: 3150 | M8: 1.02
A9: Fire training | B9: Propane | C9: US FAA (EDMS 4.2, App. H) | D9: kg propane | G9: g/kg | H9: 1.32 | I9: 6.57 | J9: 7.19 | K9: 24.21 | L9: 3030 | M9: 0
A10: Fire training | B10: Wood | C10: http://www.atmos-chem-phys-discuss.net/10/27523/2010/acpd-10-27523-2010-print.pdf | D10: kg wood | G10: g/kg | H10: 1.72 | I10: 4.98 | J10: 104 | K10: 18.8 | L10: 1598 | M10: 0
A12: Vehicles landside
A13: Passenger Cars | B13: Gasoline | C13: CORINAIR, 2009, 1.A.3.b | D13: km estimate | E13: g fuel/km | F13: 70 | G13: g/kg | H13: 14.5 | I13: 14 | J13: 132 | K13: 0.037 | L13: 3180 | M13: 0.04
A14: Passenger Cars | B14: Diesel | C14: CORINAIR, 2009, 1.A.3.b | D14: km estimate | E14: g fuel/km | F14: 60 | G14: g/kg | H14: 11 | I14: 1.1 | J14: 4.7 | K14: 1.7 | L14: 3140 | M14: 0.008
A15: Passenger Cars | B15: LPG | C15: CORINAIR, 2009, 1.A.3.b | D15: km estimate | E15: g fuel/km | F15: 57.5 | G15: g/kg | H15: 15.5 | I15: 10 | J15: 68 | K15: 0 | L15: 3017 | M15: 0
A16: LDV | B16: Gasoline | C16: CORINAIR, 2009, 1.A.3.b | D16: km estimate | E16: g fuel/km | F16: 100 | G16: g/kg | H16: 24 | I16: 14 | J16: 155 | K16: 0.03 | L16: 3180 | M16: 0.04
A17: LDV | B17: Diesel | C17: CORINAIR, 2009, 1.A.3.b | D17: km estimate | E17: g fuel/km | F17: 80 | G17: g/kg | H17: 15 | I17: 1.75 | J17: 11 | K17: 2.8 | L17: 3140 | M17: 0.008
A18: HDV | B18: Diesel | C18: CORINAIR, 2009, 1.A.3.b | D18: km estimate | E18: g fuel/km | F18: 240 | G18: g/kg | H18: 37 | I18: 1.6 | J18: 8 | K18: 1.2 | L18: 3140 | M18: 0.008
A19: HDV | B19: CNG | C19: CORINAIR, 2009, 1.A.3.b | D19: km estimate | E19: g fuel/km | F19: 500 | G19: g/kg | H19: 13 | I19: 0.26 | J19: 5.7 | K19: 0.02 | L19: 2750 | M19: 0.008
A20: Motorbikes | B20: Gasoline | C20: CORINAIR, 2009, 1.A.3.b | D20: km estimate | E20: g fuel/km | F20: 35 | G20: g/kg | H20: 9.5 | I20: 114 | J20: 490 | K20: 2.7 | L20: 3180 | M20: 0.04
A21: HDV | B21: Gasoline | C21: CORINAIR, 2009, 1.A.3.b | D21: km estimate | E21: g fuel/km | F21: 177 | G21: g/kg | H21: =6.6/($F$21/1000) -> 37.288136 | I21: =5.25/($F$21/1000) -> 29.661017 | J21: =59.5/($F$21/1000) -> 336.15819 | K21: =0/($F$21/1000) -> 0 | L21: 3180 | M21: 0.04 | N21: NOX, VOC, CO, PM: Table3-19, 20
A23: Passenger Cars | B23: CNG | C23: Swiss EPA, 2010 (Nr.102, table 22) | D23: km estimate | G23: g/km | H23: 0.056 | I23: 0.015 | J23: 0.395 | K23: 0.002 | L23: 148 | M23: 0
A25: Vehicles/machinery airside
A26: Offroad machinery | B26: Diesel | C26: Swiss Offroad Database, 2000 | D26: kg diesel | G26: g/kg | H26: 36.71 | I26: 21.24 | J26: 151.37 | K26: 3.1 | L26: 3150 | M26: 0.54
A29: Older or alternative emission factors
A30: Building Heating | B30: Coke | C30: CORINAIR, 1990 | D30: kg coke | E30: MJ/kg carburant | F30: 28.05 | G30: g/GJ | H30: 200 | I30: 18 | J30: 178 | K30: 64 | L30: 98000 | M30: 500
A31: Building Heating | B31: Light Oil | C31: CORINAIR, 1990 | D31: kg light oil | E31: MJ/kg carburant | F31: 41 | G31: g/GJ | H31: 133 | I31: 8 | J31: 15 | K31: 24 | L31: 76000 | M31: 440
A32: Fire training | B32: Wood | C32: CORINAIR | D32: kg wood | E32: MJ/kg carburant | F32: 14.5 | G32: g/GJ | H32: 140 | I32: 28 | J32: 650 | K32: 80 | L32: 0 | M32: 0
A33: Fire training | B33: Wood | C33: AP-42, 2.5 | D33: kg forest residues | G33: g/kg | H33: 2000 | I33: 11.8 | J33: 70 | K33: 8 | L33: 0 | M33: 0
A34: Fire training | B34: Wood | C34: USDA-FS, 2003 | D34: kg pine pile | G34: g/kg | H34: 0.1 | I34: 11.8 | J34: 86.2 | K34: 12.7 | L34: 1634 | M34: 0
A36: Airside circulating cars | B36: All types | C36: HBEFA 2.1 (Swiss EPA), 2010 | D36: km estimate | G36: g/km | H36: 0.188 | I36: 0.046 | J36: 0.659 | K36: 0.005 | M36: 0.001 | N36: Swiss average, all fuel types, low speed
A37: Airside circulating light duty vehicles | B37: All types | C37: HBEFA 2.1 (Swiss EPA), 2010 | D37: km estimate | G37: g/km | H37: 0.642 | I37: 0.123 | J37: 1.218 | K37: 0.039 | M37: 0.001 | N37: Swiss average, all fuel types, low speed
A38: Airside circulating heavy duty vehicles | B38: All types | C38: HBEFA 2.1 (Swiss EPA), 2010 | D38: km estimate | G38: g/km | H38: 10.195 | I38: 1.09 | J38: 2.93 | K38: 0.288 | M38: 0.007 | N38: Swiss average, all fuel types, low speed
A42: Engine Runups
A43: Aircraft with aviation gasoline | B43: AVGAS | C43: 10min-idle-C182 | G43: kg/runup | H43: 0.0015 | I43: 0.0684 | J43: 1.5 | K43: 7.5e-05 | L43: 4.71 | M43: 0.00075
A44: Single-aisle aircraft with kerosene | B44: Jet-A1 | C44: 30min-idle-B737 | G44: kg/runup | H44: 4.3 | I44: 1.02024 | J44: 7 | K44: 0.037187967 | L44: 1236.06 | M44: 0.1962
A45: Double-aisle aircraft with kerosene | B45: Jet-A1 | C45: 30min-idle-A330 | G45: kg/runup | H45: 6.8 | I45: 0.73584 | J45: 9.04176 | K45: 0.038468934 | L45: 1575 | M45: 0.25
A47: Train emission factors | H47: EI MJ | I47: EI kWh/km
A48: Energy use per light rail wagon | B48: Electricity | C48: Murdoch Univ, Murdoch, WA, AU, 1995 | D48: km | E48: kWh/MJ | F48: 0.2778 | G48: MJ/km | H48: 15.3 | I48: =F48*H48 -> 4.25034
A49: Energy use per suburban rail wagon | B49: Electricity | C49: Murdoch Univ, Murdoch, WA, AU, 1995 | D49: km | E49: kWh/MJ | F49: 0.2778 | G49: MJ/km | H49: 49 | I49: =F49*H49 -> 13.6122
A50: Energy user per light rail pass.-km | B50: Electricity | C50: Murdoch Univ, Murdoch, WA, AU, 1995 | E50: kWh/MJ | F50: 0.2778 | G50: MJ/pkm | H50: 0.5
...
