Workbook

Sheet Summary
A1: Database Statistics Summary
A2: 2005-2006
A4: Database Name | B4: Vendor | C4: Sessions | D4: Searches | E4: Turnaways | F4: Successful full-text article requests | G4: Price | H4: Cost per Search
A5: ABI/INFORM Global | B5: ProQuest | C5: N/A | D5: =ProQuest!N7 -> 32702 | E5: 0 | F5: Not available | G5: =ProQuest!O7 -> 17940 | H5: =ProQuest!P7 -> 0.5485903
A6: ABI/INFORM Trade & Industry | B6: ProQuest | C6: N/A | D6: =ProQuest!N12 -> 14416 | E6: 0 | F6: Not available | G6: 0 | H6: N/A
A7: Academic Search Premier | B7: EBSCOhost | C7: =EBSCOhost!N7 -> 97878 | D7: =EBSCOhost!N8 -> 340317 | E7: 0 | F7: =EBSCOhost!N9 -> 228798 | G7: =EBSCOhost!O8 -> 18613 | H7: =EBSCOhost!P8 -> 0.054693124
A8: Alternative Press Index | B8: FirstSearch | C8: N/A | D8: =FirstSearch!N7 -> 27 | E8: 0 | F8: N/A | G8: 27 | H8: 1
A9: Alternative Press Index Archive | B9: FirstSearch | C9: N/A | D9: =FirstSearch!N12 -> 11 | E9: 0 | F9: N/A | G9: 11 | H9: 1
A10: America History & Life | B10: ABC-CLIO | C10: ='ABC-CLIO'!N7 -> 2365 | D10: ='ABC-CLIO'!N8 -> 3829 | E10: 0 | F10: N/A | G10: ='ABC-CLIO'!O8/2 -> 6124 | H10: =G10/D10 -> 1.5993732
A11: Applied Science & Technology Abstracts | B11: WilsonWeb | C11: =WilsonWeb!N12 -> 617 | D11: =WilsonWeb!N13 -> 2188 | E11: =WilsonWeb!N14 -> 0 | F11: N/A | G11: =WilsonWeb!O13 -> 5562 | H11: =WilsonWeb!P13 -> 2.5420475
A12: Art Abstracts | B12: WilsonWeb | C12: =WilsonWeb!N7 -> 995 | D12: =WilsonWeb!N8 -> 4280 | E12: =WilsonWeb!N9 -> 0 | F12: N/A | G12: =WilsonWeb!O8 -> 4977 | H12: =WilsonWeb!P8 -> 1.1628505
A13: ArticleFirst* | B13: FirstSearch | C13: =FirstSearch!N17 -> 4666 | D13: =FirstSearch!N18 -> 11414 | E13: =FirstSearch!N20 -> 507 | F13: N/A | G13: 0 | H13: N/A
A14: ASFA: Aquatic Science & Fisheries Abstracts | B14: CSA | C14: N/A | D14: =CSA!N7 -> 32527 | E14: 0 | F14: N/A | G14: =CSA!O7 -> 6908 | H14: =CSA!P7 -> 0.21237741
A15: Bibliography & Index of Micropaleontology | B15: — | C15: Not avail. | D15: Not avail. | E15: Not avail. | F15: N/A | G15: 141.21 | H15: N/A
A16: Biological Abstracts / BIOSIS | B16: Ovid WEBSPIRS | C16: =WebSpirs!N7 -> 2051 | D16: =WebSpirs!N8 -> 7022 | E16: =WebSpirs!N9 -> 0 | F16: N/A | G16: =WebSpirs!O8 -> 22306 | H16: =WebSpirs!P8 -> 3.1765879
A17: Biological & Agricultural Index Plus* | B17: WilsonWeb | C17: =WilsonWeb!N17 -> 560 | D17: =WilsonWeb!N18 -> 2000 | E17: =WilsonWeb!N19 -> 79 | F17: N/A | G17: =WilsonWeb!O18 -> 3291.75 | H17: =WilsonWeb!P18 -> 1.645875
A18: BIOSIS Previews | B18: OVID | C18: =OVID!N7 -> 6 | D18: =OVID!N8 -> 9 | E18: 0 | F18: N/A | G18: 0 | H18: N/A
A19: ChoiceReviews.online | B19: Choice | C19: Not avail. | D19: Not avail. | E19: Not avail. | F19: N/A | G19: 617.14 | H19: N/A
A20: CIAO | B20: CIAO | C20: =CIAO!N7 -> 1128 | D20: =CIAO!N8 -> 3055 | E20: 0 | F20: N/A | G20: =CIAO!O8 -> 898 | H20: =CIAO!P8 -> 0.29394435
A21: CINAHL | B21: EBSCOhost | C21: =EBSCOhost!N49 -> 9000 | D21: =EBSCOhost!N50 -> 40121 | E21: 0 | F21: Not available | G21: =EBSCOhost!O50 -> 5165 | H21: =EBSCOhost!P50 -> 0.12873557
A22: Clase and Periodica* | B22: FirstSearch | C22: =FirstSearch!N25 -> 24 | D22: =FirstSearch!N26 -> 14 | E22: =FirstSearch!N28 -> 0 | F22: N/A | G22: 0 | H22: N/A
A23: Cochrane Library | B23: Wiley InterScience | C23: =Cochrane!N7 -> 811 | D23: =Cochrane!N8 -> 246 | E23: 0 | F23: =Cochrane!N9 -> 676 | G23: 645 | H23: =Cochrane!P8 -> 9.4593496
A24: CollegeSource | B24: CollegeSource | C24: N/A | D24: =CollegeSource!N7 -> 446 | E24: 0 | F24: N/A | G24: =CollegeSource!O7 -> 1310.64 | H24: =CollegeSource!P7 -> 2.9386547
A25: Communication Abstracts | B25: CSA | C25: N/A | D25: =CSA!N12 -> 10262 | E25: 0 | F25: N/A | G25: =CSA!O12 -> 2530 | H25: =CSA!P12 -> 0.24654064
A26: Compendex | B26: EI | C26: ='Compendex(EI)'!N7 -> 1538 | D26: ='Compendex(EI)'!N8 -> 5585 | E26: 0 | F26: N/A | G26: ='Compendex(EI)'!O8 -> 13625 | H26: ='Compendex(EI)'!P8 -> 2.4395703
A27: CSA (all databases) | B27: CSA | C27: =CSA!N77 -> 23492 | D27: =CSA!N78 -> 70160 | E27: 0 | F27: N/A | G27: =CSA!O78 -> 27776.6 | H27: =CSA!P78 -> 0.39590365
A28: EBSCO Animals | B28: EBSCOhost | C28: =EBSCOhost!N14 -> 1022 | D28: =EBSCOhost!N15 -> 3185 | E28: 0 | F28: N/A | G28: 0 | H28: N/A
A29: EBSCOhost (all databases) | B29: EBSCOhost | C29: =EBSCOhost!N84 -> 129592 | D29: =EBSCOhost!N85 -> 397195 | E29: 0 | F29: =EBSCOhost!N86 -> 235489 | G29: =EBSCOhost!O85 -> 52416 | H29: =EBSCOhost!P85 -> 0.13196541
A30: EconLit | B30: CSA | C30: N/A | D30: =CSA!N17 -> 6045 | E30: 0 | F30: N/A | G30: =CSA!O17 -> 3990 | H30: =CSA!P17 -> 0.66004963
A31: Electronic Books* | B31: FirstSearch | C31: =FirstSearch!N41 -> 135 | D31: =FirstSearch!N42 -> 161 | E31: =FirstSearch!N44 -> 0 | F31: N/A | G31: 0 | H31: N/A
A32: Electronic Collections Online* | B32: FirstSearch | C32: =FirstSearch!N49 -> 892 | D32: =FirstSearch!N50 -> 1326 | E32: =FirstSearch!N52 -> 9 | F32: URI does not subscribe to full text | G32: 0 | H32: N/A
A33: ERIC | B33: CSA | C33: N/A | D33: =CSA!N22 -> 7061 | E33: 0 | F33: N/A | G33: 0 | H33: N/A
A34: ERIC* | B34: FirstSearch | C34: =FirstSearch!N33 -> 2154 | D34: =FirstSearch!N34 -> 5312 | E34: =FirstSearch!N36 -> 474 | F34: N/A | G34: 0 | H34: N/A
A35: FirstSearch (all databases) | B35: FirstSearch | C35: =FirstSearch!N126 -> 20189 | D35: =FirstSearch!N127 -> 52742 | E35: =FirstSearch!N129 -> 3614 | F35: N/A | G35: =FirstSearch!O127 -> 14661.25 | H35: =FirstSearch!P127 -> 0.27798055
A36: FirstSearch (“per-search” block searches) | B36: FirstSearch | C36: N/A | D36: =FirstSearch!N134 -> 247 | E36: 0 | F36: N/A | G36: 247 | H36: 1
A37: Funk & Wagnall's New World Encyclopedia | B37: EBSCOhost | C37: =EBSCOhost!N21 -> 359 | D37: =EBSCOhost!N22 -> 1083 | E37: 0 | F37: N/A | G37: 0 | H37: N/A
A38: GEOBASE | B38: FirstSearch | C38: N/A | D38: =FirstSearch!N57 -> 207 | E38: 0 | F38: N/A | G38: 207 | H38: 1
A39: GeoRef | B39: Community of Science | C39: Not avail. | D39: Not avail. | E39: Not avail. | F39: N/A | G39: 6100 | H39: N/A
A40: GPO Monthly Catalog* | B40: FirstSearch | C40: =FirstSearch!N62 -> 277 | D40: =FirstSearch!N63 -> 437 | E40: =FirstSearch!N65 -> 2 | F40: N/A | G40: 0 | H40: N/A
A41: Grove Music | B41: Oxford | C41: =GroveMusic!N7 -> 434 | D41: =GroveMusic!N8 -> 748 | E41: 0 | F41: N/A | G41: =GroveMusic!O8 -> 1483 | H41: =GroveMusic!P8 -> 1.9826203
...

Sheet ABC-CLIO
A1: ABC-CLIO
A2: 2005-2006
B5: 38534 | C5: 38565 | D5: 38596 | E5: 38626 | F5: 38657 | G5: 38687 | H5: 38718 | I5: 38749 | J5: 38777 | K5: 38808 | L5: 38838 | M5: 38869 | N5: Total | O5: 2005-2006 Price | P5: Price per search
A6: AHL Database
A7: Sessions | B7: 104 | C7: 22 | D7: 274 | E7: 478 | F7: 415 | G7: 127 | H7: 73 | I7: 259 | J7: 259 | K7: 234 | L7: 70 | M7: 50 | N7: =SUM(B7:M7) -> 2365
A8: Searches | B8: 182 | C8: 43 | D8: 639 | E8: 662 | F8: 649 | G8: 132 | H8: 128 | I8: 559 | J8: 373 | K8: 289 | L8: 131 | M8: 42 | N8: =SUM(B8:M8) -> 3829 | O8: 12248 | P8: =O8/N8 -> 3.1987464
B11: 38534 | C11: 38565 | D11: 38596 | E11: 38626 | F11: 38657 | G11: 38687 | H11: 38718 | I11: 38749 | J11: 38777 | K11: 38808 | L11: 38838 | M11: 38869 | N11: Total | O11: 2005-2006 Price | P11: Price per search
A12: HA Database
A13: Sessions | B13: 26 | C13: 4 | D13: 53 | E13: 230 | F13: 279 | G13: 83 | H13: 29 | I13: 85 | J13: 201 | K13: 165 | L13: 41 | M13: 30 | N13: =SUM(B13:M13) -> 1226
A14: Searches | B14: 26 | C14: 5 | D14: 74 | E14: 300 | F14: 381 | G14: 100 | H14: 30 | I14: 94 | J14: 214 | K14: 163 | L14: 44 | M14: 41 | N14: =SUM(B14:M14) -> 1472 | O14: 0 | P14: N/A
P15: For both:
P16: =O8/(N8+N14) -> 2.3105075

Sheet CIAO
A1: CIAO
A2: 2005-2006
B5: 38534 | C5: 38565 | D5: 38596 | E5: 38626 | F5: 38657 | G5: 38687 | H5: 38718 | I5: 38749 | J5: 38777 | K5: 38808 | L5: 38838 | M5: 38869 | N5: Total | O5: 2005-2006 price | P5: Price per search
A6: CIAO
A7: Sessions | B7: 40 | C7: 9 | D7: 56 | E7: 120 | F7: 198 | G7: 92 | H7: 20 | I7: 83 | J7: 128 | K7: 289 | L7: 47 | M7: 46 | N7: =SUM(B7:M7) -> 1128
A8: Searches | B8: 96 | C8: 15 | D8: 136 | E8: 284 | F8: 886 | G8: 271 | H8: 17 | I8: 142 | J8: 264 | K8: 763 | L8: 92 | M8: 89 | N8: =SUM(B8:M8) -> 3055 | O8: 898 | P8: =O8/N8 -> 0.29394435

Sheet Cochrane
A1: Cochrane Library
A2: 2005-2006
B5: 38534 | C5: 38565 | D5: 38596 | E5: 38626 | F5: 38657 | G5: 38687 | H5: 38718 | I5: 38749 | J5: 38777 | K5: 38808 | L5: 38838 | M5: 38869 | N5: Total | O5: 2005-2006 price | P5: Price per unit
A6: Cochrane Library
A7: Sessions | B7: 51 | C7: 10 | D7: 76 | E7: 89 | F7: 103 | G7: 31 | H7: 26 | I7: 79 | J7: 133 | K7: 130 | L7: 30 | M7: 53 | N7: =SUM(B7:M7) -> 811
A8: Searches | B8: 14 | C8: 2 | D8: 22 | E8: 8 | F8: 40 | G8: 2 | H8: 2 | I8: 25 | J8: 60 | K8: 42 | L8: 21 | M8: 8 | N8: =SUM(B8:M8) -> 246 | O8: 2327 | P8: =O8/N8 -> 9.4593496
A9: Full-Text Articles Downloaded | B9: 60 | C9: 11 | D9: 50 | E9: 62 | F9: 87 | G9: 30 | H9: 1 | I9: 45 | J9: 130 | K9: 133 | L9: 23 | M9: 44 | N9: =SUM(B9:M9) -> 676 | O9: 2327 | P9: =O9/N9 -> 3.4423077
A10: Turnaways | B10: 0 | C10: 0 | D10: 0 | E10: 0 | F10: 0 | G10: 0 | H10: 0 | I10: 0 | J10: 0 | K10: 0 | L10: 0 | M10: 0
A13: COUNTER-Compliant?: | B13: Yes

Sheet CollegeSource
A1: CollegeSource
A2: 2005-2006
B5: 38534 | C5: 38565 | D5: 38596 | E5: 38626 | F5: 38657 | G5: 38687 | H5: 38718 | I5: 38749 | J5: 38777 | K5: 38808 | L5: 38838 | M5: 38869 | N5: Total | O5: 2005-2006 price | P5: Price per search
A6: CollegeSource
A7: Searches | B7: 87 | C7: 4 | D7: 77 | E7: 74 | F7: 72 | G7: 21 | H7: 5 | I7: 33 | J7: 25 | K7: 22 | L7: 19 | M7: 7 | N7: =SUM(B7:M7) -> 446 | O7: 1310.64 | P7: =O7/N7 -> 2.9386547
A8: Service Errors | B8: 37 | C8: 2 | D8: 27 | E8: 25 | F8: 17 | G8: 7 | H8: 13 | I8: 3 | J8: 63 | K8: 19 | L8: 23 | M8: 8 | N8: =SUM(B8:M8) -> 244
A9: Turnaways | B9: 0 | C9: 0 | D9: 0 | E9: 0 | F9: 0 | G9: 0 | H9: 0 | I9: 0 | J9: 0 | K9: 0 | L9: 0 | M9: 0 | N9: =SUM(B9:M9) -> 0

Sheet Compendex(EI)
A1: Compendex (Engineering Index)
A2: 2005-2006
B5: 38534 | C5: 38565 | D5: 38596 | E5: 38626 | F5: 38657 | G5: 38687 | H5: 38718 | I5: 38749 | J5: 38777 | K5: 38808 | L5: 38838 | M5: 38869 | N5: Total | O5: 2005-2006 Price | P5: Price per search
A6: Compendex
A7: Sessions | B7: 65 | C7: 86 | D7: 134 | E7: 370 | F7: 174 | G7: 81 | H7: 80 | I7: 114 | J7: 150 | K7: 131 | L7: 91 | M7: 62 | N7: =SUM(B7:M7) -> 1538
A8: Searches | B8: 155 | C8: 219 | D8: 392 | E8: 2023 | F8: 589 | G8: 261 | H8: 272 | I8: 329 | J8: 528 | K8: 372 | L8: 262 | M8: 183 | N8: =SUM(B8:M8) -> 5585 | O8: 13625 | P8: =O8/N8 -> 2.4395703

Sheet CSA
A1: CSA Databases
A2: 2005-2006
B5: 38534 | C5: 38565 | D5: 38596 | E5: 38626 | F5: 38657 | G5: 38687 | H5: 38718 | I5: 38749 | J5: 38777 | K5: 38808 | L5: 38838 | M5: 38869 | N5: Total | O5: 2005-2006 Price | P5: Price per search
A6: ASFA
A7: Searches | B7: 977 | C7: 1095 | D7: 3321 | E7: 6146 | F7: 4440 | G7: 3738 | H7: 2734 | I7: 3204 | J7: 2544 | K7: 1528 | L7: 1903 | M7: 897 | N7: =SUM(B7:M7) -> 32527 | O7: 6908 | P7: =O7/N7 -> 0.21237741
B10: 38534 | C10: 38565 | D10: 38596 | E10: 38626 | F10: 38657 | G10: 38687 | H10: 38718 | I10: 38749 | J10: 38777 | K10: 38808 | L10: 38838 | M10: 38869 | N10: Total | O10: 2005-2006 Price | P10: Price per search
A11: Communication Abstracts
A12: Searches | B12: 273 | C12: 70 | D12: 347 | E12: 1409 | F12: 2156 | G12: 1089 | H12: 131 | I12: 632 | J12: 922 | K12: 2764 | L12: 287 | M12: 182 | N12: =SUM(B12:M12) -> 10262 | O12: 2530 | P12: =O12/N12 -> 0.24654064
B15: 38534 | C15: 38565 | D15: 38596 | E15: 38626 | F15: 38657 | G15: 38687 | H15: 38718 | I15: 38749 | J15: 38777 | K15: 38808 | L15: 38838 | M15: 38869 | N15: Total | O15: 2005-2006 Price | P15: Price per search
A16: EconLit
A17: Searches | B17: 411 | C17: 163 | D17: 387 | E17: 919 | F17: 1024 | G17: 412 | H17: 206 | I17: 639 | J17: 515 | K17: 978 | L17: 282 | M17: 109 | N17: =SUM(B17:M17) -> 6045 | O17: 3990 | P17: =O17/N17 -> 0.66004963
B20: 38534 | C20: 38565 | D20: 38596 | E20: 38626 | F20: 38657 | G20: 38687 | H20: 38718 | I20: 38749 | J20: 38777 | K20: 38808 | L20: 38838 | M20: 38869 | N20: Total | O20: 2005-2006 Price | P20: Price per search
A21: ERIC
A22: Searches | B22: 204 | C22: 61 | D22: 231 | E22: 1328 | F22: 1266 | G22: 483 | H22: 150 | I22: 951 | J22: 772 | K22: 1145 | L22: 278 | M22: 192 | N22: =SUM(B22:M22) -> 7061 | O22: 0 | P22: N/A
B25: 38534 | C25: 38565 | D25: 38596 | E25: 38626 | F25: 38657 | G25: 38687 | H25: 38718 | I25: 38749 | J25: 38777 | K25: 38808 | L25: 38838 | M25: 38869 | N25: Total | O25: 2005-2006 Price | P25: Price per search
A26: International Pharmaceutical Abstracts
A27: Searches | B27: 144 | C27: 99 | D27: 191 | E27: 302 | F27: 268 | G27: 228 | H27: 124 | I27: 258 | J27: 495 | K27: 273 | L27: 296 | M27: 140 | N27: =SUM(B27:M27) -> 2818 | O27: 3280 | P27: =O27/N27 -> 1.1639461
B30: 38534 | C30: 38565 | D30: 38596 | E30: 38626 | F30: 38657 | G30: 38687 | H30: 38718 | I30: 38749 | J30: 38777 | K30: 38808 | L30: 38838 | M30: 38869 | N30: Total | O30: 2005-2006 Price | P30: Price per search
A31: Meteorological & Geoastrophysical Abstracts
A32: Searches | B32: 415 | C32: 458 | D32: 611 | E32: 995 | F32: 953 | G32: 914 | H32: 651 | I32: 897 | J32: 1022 | K32: 795 | L32: 1456 | M32: 565 | N32: =SUM(B32:M32) -> 9732 | O32: 3681 | P32: =O32/N32 -> 0.37823674
B35: 38534 | C35: 38565 | D35: 38596 | E35: 38626 | F35: 38657 | G35: 38687 | H35: 38718 | I35: 38749 | J35: 38777 | K35: 38808 | L35: 38838 | M35: 38869 | N35: Total | O35: 2005-2006 Price | P35: Price per search
A36: Oceanic Abstracts
A37: Searches | B37: 450 | C37: 481 | D37: 655 | E37: 1117 | F37: 1191 | G37: 1025 | H37: 684 | I37: 942 | J37: 1254 | K37: 936 | L37: 1496 | M37: 589 | N37: =SUM(B37:M37) -> 10820 | O37: 0 | P37: N/A
O38: included with ASFA
B40: 38534 | C40: 38565 | D40: 38596 | E40: 38626 | F40: 38657 | G40: 38687 | H40: 38718 | I40: 38749 | J40: 38777 | K40: 38808 | L40: 38838 | M40: 38869 | N40: Total | O40: 2005-2006 Price | P40: Price per search
A41: PAIS International
A42: Searches | B42: 225 | C42: 51 | D42: 439 | E42: 1070 | F42: 1571 | G42: 542 | H42: 119 | I42: 494 | J42: 548 | K42: 1165 | L42: 222 | M42: 267 | N42: =SUM(B42:M42) -> 6713 | O42: 4920 | P42: =O42/N42 -> 0.7329063
B45: 38534 | C45: 38565 | D45: 38596 | E45: 38626 | F45: 38657 | G45: 38687 | H45: 38718 | I45: 38749 | J45: 38777 | K45: 38808 | L45: 38838 | M45: 38869 | N45: Total | O45: 2005-2006 Price | P45: Price per search
A46: Philosopher's Index
A47: Searches | B47: 45 | C47: 6 | D47: 41 | E47: 150 | F47: 307 | G47: 185 | H47: 22 | I47: 101 | J47: 197 | K47: 308 | L47: 102 | M47: 67 | N47: =SUM(B47:M47) -> 1531 | O47: 2550 | P47: =O47/N47 -> 1.6655781
B50: 38534 | C50: 38565 | D50: 38596 | E50: 38626 | F50: 38657 | G50: 38687 | H50: 38718 | I50: 38749 | J50: 38777 | K50: 38808 | L50: 38838 | M50: 38869 | N50: Total | O50: 2005-2006 Price | P50: Price per search
A51: Physical Education Index
A52: Searches | B52: 185 | C52: 122 | D52: 258 | E52: 1073 | F52: 993 | G52: 507 | H52: 167 | I52: 541 | J52: 592 | K52: 949 | L52: 418 | M52: 109 | N52: =SUM(B52:M52) -> 5914 | O52: 975 | P52: =O52/N52 -> 0.16486304
B55: 38534 | C55: 38565 | D55: 38596 | E55: 38626 | F55: 38657 | G55: 38687 | H55: 38718 | I55: 38749 | J55: 38777 | K55: 38808 | L55: 38838 | M55: 38869 | N55: Total | O55: 2005-2006 Price | P55: Price per search
A56: Pollution Abstracts
A57: Searches | B57: 17 | C57: 9 | D57: 67 | E57: 126 | F57: 123 | G57: 96 | H57: 11 | I57: 97 | J57: 161 | K57: 166 | L57: 41 | M57: 11 | N57: =SUM(B57:M57) -> 925 | O57: 1673.6 | P57: =O57/N57 -> 1.8092973
M58: Note: Price is print. Online comes free with print.
B60: 38534 | C60: 38565 | D60: 38596 | E60: 38626 | F60: 38657 | G60: 38687 | H60: 38718 | I60: 38749 | J60: 38777 | K60: 38808 | L60: 38838 | M60: 38869 | N60: Total | O60: 2005-2006 Price | P60: Price per search
A61: PsycINFO
A62: Searches | B62: 1075 | C62: 575 | D62: 1466 | E62: 4254 | F62: 5701 | G62: 2951 | H62: 1166 | I62: 3580 | J62: 3477 | K62: 4551 | L62: 1584 | M62: 946 | N62: =SUM(B62:M62) -> 31326 | O62: 13720 | P62: =O62/N62 -> 0.43797485
...

Sheet EBSCOhost
A1: EBSCOhost Databases
A2: 2005-2006
B5: 38534 | C5: 38565 | D5: 38596 | E5: 38626 | F5: 38657 | G5: 38687 | H5: 38718 | I5: 38749 | J5: 38777 | K5: 38808 | L5: 38838 | M5: 38869 | N5: Total | O5: 2005-2006 Price | P5: Price per unit
A6: Academic Search Premier
A7: Sessions | B7: 4062 | C7: 1089 | D7: 5297 | E7: 14508 | F7: 17275 | G7: 7973 | H7: 2545 | I7: 9748 | J7: 12381 | K7: 15774 | L7: 3755 | M7: 3471 | N7: =SUM(B7:M7) -> 97878
A8: Searches | B8: 14867 | C8: 3172 | D8: 16104 | E8: 52328 | F8: 55624 | G8: 26389 | H8: 6564 | I8: 37772 | J8: 47307 | K8: 55480 | L8: 12634 | M8: 12076 | N8: =SUM(B8:M8) -> 340317 | O8: 18613 | P8: =O8/N8 -> 0.054693124
A9: Successful full-text downloads | B9: 11065 | C9: 1971 | D9: 11453 | E9: 32693 | F9: 44699 | G9: 21084 | H9: 5964 | I9: 25078 | J9: 28835 | K9: 32412 | L9: 7104 | M9: 6440 | N9: =SUM(B9:M9) -> 228798 | O9: 18613 | P9: =O9/N9 -> 0.081351236
B12: 38534 | C12: 38565 | D12: 38596 | E12: 38626 | F12: 38657 | G12: 38687 | H12: 38718 | I12: 38749 | J12: 38777 | K12: 38808 | L12: 38838 | M12: 38869 | N12: Total | O12: 2005-2006 Price | P12: Price per unit
A13: EBSCO Animals
A14: Sessions | B14: 29 | C14: 9 | D14: 68 | E14: 172 | F14: 168 | G14: 69 | H14: 24 | I14: 114 | J14: 116 | K14: 193 | L14: 30 | M14: 30 | N14: =SUM(B14:M14) -> 1022
A15: Searches | B15: 59 | C15: 17 | D15: 248 | E15: 524 | F15: 506 | G15: 310 | H15: 59 | I15: 372 | J15: 368 | K15: 530 | L15: 109 | M15: 83 | N15: =SUM(B15:M15) -> 3185 | O15: 0 | P15: N/A
A16: Successful full-text downloads | B16: N/A | C16: N/A | D16: N/A | E16: N/A | F16: N/A | G16: N/A | H16: N/A | I16: N/A | J16: N/A | K16: N/A | L16: N/A | M16: N/A | N16: N/A | O16: 0 | P16: N/A
B19: 38534 | C19: 38565 | D19: 38596 | E19: 38626 | F19: 38657 | G19: 38687 | H19: 38718 | I19: 38749 | J19: 38777 | K19: 38808 | L19: 38838 | M19: 38869 | N19: Total | O19: 2005-2006 Price | P19: Price per unit
A20: Funk & Wagnall's New World Encyclopedia
A21: Sessions | B21: 21 | C21: 2 | D21: 9 | E21: 28 | F21: 63 | G21: 18 | H21: 7 | I21: 29 | J21: 47 | K21: 60 | L21: 25 | M21: 50 | N21: =SUM(B21:M21) -> 359
A22: Searches | B22: 52 | C22: 6 | D22: 23 | E22: 71 | F22: 235 | G22: 46 | H22: 19 | I22: 73 | J22: 136 | K22: 160 | L22: 75 | M22: 187 | N22: =SUM(B22:M22) -> 1083 | O22: 0 | P22: N/A
A23: Successful full-text downloads | B23: N/A | C23: N/A | D23: N/A | E23: N/A | F23: N/A | G23: N/A | H23: N/A | I23: N/A | J23: N/A | K23: N/A | L23: N/A | M23: N/A | N23: N/A | O23: 0 | P23: N/A
B26: 38534 | C26: 38565 | D26: 38596 | E26: 38626 | F26: 38657 | G26: 38687 | H26: 38718 | I26: 38749 | J26: 38777 | K26: 38808 | L26: 38838 | M26: 38869 | N26: Total | O26: 2005-2006 Price | P26: Price per unit
A27: MAS Ultra - School Edition
A28: Sessions | B28: 30 | C28: 17 | D28: 34 | E28: 90 | F28: 114 | G28: 45 | H28: 15 | I28: 69 | J28: 120 | K28: 145 | L28: 37 | M28: 29 | N28: =SUM(B28:M28) -> 745
A29: Searches | B29: 157 | C29: 33 | D29: 82 | E29: 264 | F29: 322 | G29: 129 | H29: 26 | I29: 203 | J29: 183 | K29: 215 | L29: 100 | M29: 91 | N29: =SUM(B29:M29) -> 1805 | O29: 0 | P29: N/A
A30: Successful full-text downloads | B30: 56 | C30: 11 | D30: 71 | E30: 150 | F30: 215 | G30: 171 | H30: 8 | I30: 208 | J30: 89 | K30: 186 | L30: 62 | M30: 30 | N30: =SUM(B30:M30) -> 1257 | O30: 0 | P30: N/A
B33: 38534 | C33: 38565 | D33: 38596 | E33: 38626 | F33: 38657 | G33: 38687 | H33: 38718 | I33: 38749 | J33: 38777 | K33: 38808 | L33: 38838 | M33: 38869 | N33: Total | O33: 2005-2006 Price | P33: Price per unit
A34: Military & Government Collection
A35: Sessions | B35: 21 | C35: 6 | D35: 37 | E35: 63 | F35: 128 | G35: 71 | H35: 12 | I35: 45 | J35: 55 | K35: 129 | L35: 23 | M35: 24 | N35: =SUM(B35:M35) -> 614
A36: Searches | B36: 58 | C36: 13 | D36: 77 | E36: 161 | F36: 366 | G36: 188 | H36: 17 | I36: 188 | J36: 179 | K36: 520 | L36: 77 | M36: 123 | N36: =SUM(B36:M36) -> 1967 | O36: 0 | P36: N/A
A37: Successful full-text downloads | B37: 44 | C37: 2 | D37: 58 | E37: 97 | F37: 297 | G37: 166 | H37: 14 | I37: 85 | J37: 125 | K37: 296 | L37: 31 | M37: 35 | N37: =SUM(B37:M37) -> 1250 | O37: 0 | P37: N/A
B40: 38534 | C40: 38565 | D40: 38596 | E40: 38626 | F40: 38657 | G40: 38687 | H40: 38718 | I40: 38749 | J40: 38777 | K40: 38808 | L40: 38838 | M40: 38869 | N40: Total | O40: 2005-2006 Price | P40: Price per unit
A41: Primary Search
A42: Sessions | B42: 21 | C42: 2 | D42: 24 | E42: 78 | F42: 82 | G42: 40 | H42: 15 | I42: 52 | J42: 85 | K42: 101 | L42: 34 | M42: 35 | N42: =SUM(B42:M42) -> 569
A43: Searches | B43: 121 | C43: 3 | D43: 118 | E43: 312 | F43: 309 | G43: 144 | H43: 31 | I43: 220 | J43: 319 | K43: 368 | L43: 138 | M43: 142 | N43: =SUM(B43:M43) -> 2225 | O43: 0 | P43: N/A
A44: Successful full-text downloads | B44: 27 | C44: 1 | D44: 44 | E44: 75 | F44: 72 | G44: 43 | H44: 0 | I44: 15 | J44: 29 | K44: 52 | L44: 14 | M44: 15 | N44: =SUM(B44:M44) -> 387 | O44: 0 | P44: N/A
B47: 38534 | C47: 38565 | D47: 38596 | E47: 38626 | F47: 38657 | G47: 38687 | H47: 38718 | I47: 38749 | J47: 38777 | K47: 38808 | L47: 38838 | M47: 38869 | N47: Total | O47: 2005-2006 Price | P47: Price per unit
A48: CINAHL
A49: Sessions | B49: 13 | C49: 48 | D49: 755 | E49: 1253 | F49: 1505 | G49: 442 | H49: 314 | I49: 924 | J49: 1165 | K49: 1786 | L49: 338 | M49: 457 | N49: =SUM(B49:M49) -> 9000
A50: Searches | B50: 44 | C50: 161 | D50: 3147 | E50: 5184 | F50: 6271 | G50: 1541 | H50: 1433 | I50: 4296 | J50: 5610 | K50: 8579 | L50: 1421 | M50: 2434 | N50: =SUM(B50:M50) -> 40121 | O50: 5165 | P50: =O50/N50 -> 0.12873557
A51: Successful full-text downloads | B51: 1 | C51: 2 | D51: 21 | E51: 43 | F51: 35 | G51: 12 | H51: 9 | I51: 23 | J51: 187 | K51: 360 | L51: 33 | M51: 100 | N51: =SUM(B51:M51) -> 826 | O51: 5165 | P51: =O51/N51 -> 6.2530266
B54: 38534 | C54: 38565 | D54: 38596 | E54: 38626 | F54: 38657 | G54: 38687 | H54: 38718 | I54: 38749 | J54: 38777 | K54: 38808 | L54: 38838 | M54: 38869 | N54: Total | O54: 2005-2006 Price | P54: Price per unit
A55: Pre-CINAHL
A56: Sessions | B56: 6 | C56: 4 | D56: 25 | E56: 46 | F56: 59 | G56: 23 | H56: 14 | I56: 50 | J56: 76 | K56: 73 | L56: 8 | M56: 17 | N56: =SUM(B56:M56) -> 401
...

Sheet FirstSearch
A1: FirstSearch
A2: 2005-2006
B5: 38534 | C5: 38565 | D5: 38596 | E5: 38626 | F5: 38657 | G5: 38687 | H5: 38718 | I5: 38749 | J5: 38777 | K5: 38808 | L5: 38838 | M5: 38869 | N5: Total | O5: 2005-2006 Price | P5: Price per search
A6: Alternative Press Index
A7: Searches | B7: 1 | C7: 0 | D7: 3 | E7: 11 | F7: 0 | G7: 0 | H7: 2 | I7: 0 | J7: 0 | K7: 2 | L7: 8 | M7: 0 | N7: =SUM(B7:M7) -> 27 | O7: 27 | P7: 1
B10: 38534 | C10: 38565 | D10: 38596 | E10: 38626 | F10: 38657 | G10: 38687 | H10: 38718 | I10: 38749 | J10: 38777 | K10: 38808 | L10: 38838 | M10: 38869 | N10: Total | O10: 2005-2006 Price | P10: Price per search
A11: Alternative Press Index Archive
A12: Searches | B12: 0 | C12: 0 | D12: 7 | E12: 3 | F12: 1 | G12: 0 | H12: 0 | I12: 0 | J12: 0 | K12: 0 | L12: 0 | M12: 0 | N12: =SUM(B12:M12) -> 11 | O12: 11 | P12: 1
B15: 38534 | C15: 38565 | D15: 38596 | E15: 38626 | F15: 38657 | G15: 38687 | H15: 38718 | I15: 38749 | J15: 38777 | K15: 38808 | L15: 38838 | M15: 38869 | N15: Total | O15: 2005-2006 Price | P15: Price per search
A16: ArticleFirst
A17: Sessions | B17: 242 | C17: 86 | D17: 367 | E17: 643 | F17: 722 | G17: 388 | H17: 170 | I17: 554 | J17: 500 | K17: 642 | L17: 185 | M17: 167 | N17: =SUM(B17:M17) -> 4666
A18: Searches | B18: 916 | C18: 129 | D18: 771 | E18: 1743 | F18: 1197 | G18: 1206 | H18: 479 | I18: 1324 | J18: 1262 | K18: 1541 | L18: 537 | M18: 309 | N18: =SUM(B18:M18) -> 11414 | O18: 0 | P18: N/A
A19: User Limit | B19: 2 | C19: 2 | D19: 2 | E19: 2 | F19: 2 | G19: 2 | H19: 2 | I19: 2 | J19: 2 | K19: 2 | L19: 2 | M19: 2
A20: Turnaways | B20: 77 | C20: 0 | D20: 21 | E20: 63 | F20: 140 | G20: 27 | H20: 7 | I20: 62 | J20: 46 | K20: 58 | L20: 2 | M20: 4 | N20: =SUM(B20:M20) -> 507
B23: 38534 | C23: 38565 | D23: 38596 | E23: 38626 | F23: 38657 | G23: 38687 | H23: 38718 | I23: 38749 | J23: 38777 | K23: 38808 | L23: 38838 | M23: 38869 | N23: Total | O23: 2005-2006 Price | P23: Price per search
A24: Clase and Periodica
A25: Sessions | B25: 2 | C25: 0 | D25: 3 | E25: 6 | F25: 8 | G25: 1 | H25: 0 | I25: 0 | J25: 0 | K25: 3 | L25: 0 | M25: 1 | N25: =SUM(B25:M25) -> 24
A26: Searches | B26: 2 | C26: 0 | D26: 1 | E26: 2 | F26: 5 | G26: 1 | H26: 0 | I26: 0 | J26: 0 | K26: 2 | L26: 0 | M26: 1 | N26: =SUM(B26:M26) -> 14 | O26: 0 | P26: N/A
A27: User Limit | B27: 2 | C27: 0 | D27: 2 | E27: 2 | F27: 2 | G27: 2 | H27: 2 | I27: 2 | J27: 0 | K27: 2 | L27: 0 | M27: 2
A28: Turnaways | B28: 0 | C28: 0 | D28: 0 | E28: 0 | F28: 0 | G28: 0 | H28: 0 | I28: 0 | J28: 0 | K28: 0 | L28: 0 | M28: 0 | N28: =SUM(B28:M28) -> 0
B31: 38534 | C31: 38565 | D31: 38596 | E31: 38626 | F31: 38657 | G31: 38687 | H31: 38718 | I31: 38749 | J31: 38777 | K31: 38808 | L31: 38838 | M31: 38869 | N31: Total | O31: 2005-2006 Price | P31: Price per search
A32: ERIC
A33: Sessions | B33: 70 | C33: 36 | D33: 173 | E33: 409 | F33: 316 | G33: 154 | H33: 65 | I33: 286 | J33: 189 | K33: 222 | L33: 104 | M33: 130 | N33: =SUM(B33:M33) -> 2154
A34: Searches | B34: 168 | C34: 31 | D34: 505 | E34: 986 | F34: 793 | G34: 344 | H34: 159 | I34: 826 | J34: 468 | K34: 531 | L34: 237 | M34: 264 | N34: =SUM(B34:M34) -> 5312 | O34: 0 | P34: N/A
A35: User Limit | B35: 2 | C35: 2 | D35: 2 | E35: 2 | F35: 2 | G35: 2 | H35: 2 | I35: 2 | J35: 2 | K35: 2 | L35: 2 | M35: 2
A36: Turnaways | B36: 34 | C36: 5 | D36: 64 | E36: 102 | F36: 50 | G36: 11 | H36: 10 | I36: 106 | J36: 37 | K36: 12 | L36: 42 | M36: 1 | N36: =SUM(B36:M36) -> 474
B39: 38534 | C39: 38565 | D39: 38596 | E39: 38626 | F39: 38657 | G39: 38687 | H39: 38718 | I39: 38749 | J39: 38777 | K39: 38808 | L39: 38838 | M39: 38869 | N39: Total | O39: 2005-2006 Price | P39: Price per search
A40: Electronic Books
A41: Sessions | B41: 3 | C41: 3 | D41: 16 | E41: 14 | F41: 35 | G41: 10 | H41: 5 | I41: 13 | J41: 11 | K41: 15 | L41: 2 | M41: 8 | N41: =SUM(B41:M41) -> 135
A42: Searches | B42: 3 | C42: 2 | D42: 44 | E42: 21 | F42: 31 | G42: 9 | H42: 7 | I42: 9 | J42: 9 | K42: 19 | L42: 2 | M42: 5 | N42: =SUM(B42:M42) -> 161 | O42: 0 | P42: N/A
A43: User Limit | B43: 2 | C43: 2 | D43: 2 | E43: 2 | F43: 2 | G43: 2 | H43: 2 | I43: 2 | J43: 2 | K43: 2 | L43: 2 | M43: 2
A44: Turnaways | B44: 0 | C44: 0 | D44: 0 | E44: 0 | F44: 0 | G44: 0 | H44: 0 | I44: 0 | J44: 0 | K44: 0 | L44: 0 | M44: 0 | N44: =SUM(B44:M44) -> 0
B47: 38534 | C47: 38565 | D47: 38596 | E47: 38626 | F47: 38657 | G47: 38687 | H47: 38718 | I47: 38749 | J47: 38777 | K47: 38808 | L47: 38838 | M47: 38869 | N47: Total | O47: 2005-2006 Price | P47: Price per search
A48: Electronic Collections Online
A49: Sessions | B49: 29 | C49: 21 | D49: 74 | E49: 170 | F49: 129 | G49: 66 | H49: 13 | I49: 90 | J49: 91 | K49: 149 | L49: 30 | M49: 30 | N49: =SUM(B49:M49) -> 892
A50: Searches | B50: 41 | C50: 29 | D50: 91 | E50: 240 | F50: 205 | G50: 76 | H50: 12 | I50: 140 | J50: 151 | K50: 221 | L50: 94 | M50: 26 | N50: =SUM(B50:M50) -> 1326 | O50: 0 | P50: N/A
A51: User Limit | B51: 2 | C51: 2 | D51: 2 | E51: 2 | F51: 2 | G51: 2 | H51: 2 | I51: 2 | J51: 2 | K51: 2 | L51: 2 | M51: 2
A52: Turnaways | B52: 3 | C52: 0 | D52: 0 | E52: 0 | F52: 0 | G52: 0 | H52: 0 | I52: 3 | J52: 2 | K52: 1 | L52: 0 | M52: 0 | N52: =SUM(B52:M52) -> 9
B55: 38534 | C55: 38565 | D55: 38596 | E55: 38626 | F55: 38657 | G55: 38687 | H55: 38718 | I55: 38749 | J55: 38777 | K55: 38808 | L55: 38838 | M55: 38869 | N55: Total | O55: 2005-2006 Price | P55: Price per search
A56: GEOBASE
...

Sheet GroveMusic
A1: Grove Music
A2: 2005-2006
B5: 38534 | C5: 38565 | D5: 38596 | E5: 38626 | F5: 38657 | G5: 38687 | H5: 38718 | I5: 38749 | J5: 38777 | K5: 38808 | L5: 38838 | M5: 38869 | N5: Total | O5: 2005-2006 Price | P5: Price per search
A6: GroveMusic
A7: Sessions | B7: 17 | C7: 10 | D7: 27 | E7: 93 | F7: 91 | G7: 32 | H7: 14 | I7: 29 | J7: 44 | K7: 37 | L7: 24 | M7: 16 | N7: =SUM(B7:M7) -> 434
A8: Searches | B8: 32 | C8: 21 | D8: 30 | E8: 136 | F8: 177 | G8: 50 | H8: 38 | I8: 39 | J8: 95 | K8: 52 | L8: 54 | M8: 24 | N8: =SUM(B8:M8) -> 748 | O8: 1483 | P8: =O8/N8 -> 1.9826203

Sheet InfoTrac
A1: InfoTRAC
A2: 2005-2006
B5: 38534 | C5: 38565 | D5: 38596 | E5: 38626 | F5: 38657 | G5: 38687 | H5: 38718 | I5: 38749 | J5: 38777 | K5: 38808 | L5: 38838 | M5: 38869 | N5: Total | O5: Price for 2005-2006 | P5: Price per unit
A6: Literature Resource Center
A7: Sessions | B7: 172 | C7: 20 | D7: 234 | E7: 432 | F7: 400 | G7: 368 | H7: 77 | I7: 360 | J7: 400 | K7: 413 | L7: 156 | M7: 128 | N7: =SUM(B7:M7) -> 3160
A8: Searches | B8: 1174 | C8: 107 | D8: 1060 | E8: 2542 | F8: 2518 | G8: 1737 | H8: 537 | I8: 2186 | J8: 2154 | K8: 2289 | L8: 840 | M8: 731 | N8: =SUM(B8:M8) -> 17875 | O8: 4678 | P8: =O8/N8 -> 0.26170629
A9: Turnaways | B9: 0 | C9: 0 | D9: 0 | E9: 0 | F9: 0 | G9: 0 | H9: 0 | I9: 0 | J9: 0 | K9: 0 | L9: 0 | M9: 0 | N9: =SUM(B9:M9) -> 0
A10: Successful Full-Text Article Requests | B10: 124 | C10: 11 | D10: 222 | E10: 473 | F10: 591 | G10: 495 | H10: 103 | I10: 677 | J10: 764 | K10: 671 | L10: 208 | M10: 213 | N10: =SUM(B10:M10) -> 4552 | O10: 4678 | P10: =O10/N10 -> 1.0276801

Sheet LexisNexis
A1: LexisNexis
A2: 2005-2006
B5: 38534 | C5: 38565 | D5: 38596 | E5: 38626 | F5: 38657 | G5: 38687 | H5: 38718 | I5: 38749 | J5: 38777 | K5: 38808 | L5: 38838 | M5: 38869 | N5: Total | O5: 2005-2006 Price | P5: Price per unit
A7: Academic
A8: Searches | B8: 2825 | C8: 1510 | D8: 5667 | E8: 7388 | F8: 8701 | G8: 6443 | H8: 3446 | I8: 8364 | J8: 8891 | K8: 10028 | L8: 3447 | M8: 2224 | N8: =SUM(B8:M8) -> 68934 | O8: 22584 | P8: =O8/N8 -> 0.32761772
A9: Documents Retrieved | B9: 3707 | C9: 2089 | D9: 5746 | E9: 8856 | F9: 10376 | G9: 7911 | H9: 4164 | I9: 10172 | J9: 11345 | K9: 13472 | L9: 4796 | M9: 3572 | N9: =SUM(B9:M9) -> 86206 | O9: 22584 | P9: =O9/N9 -> 0.26197712
A11: Congressional
A12: Searches | B12: 40 | C12: 18 | D12: 198 | E12: 435 | F12: 258 | G12: 116 | H12: 21 | I12: 69 | J12: 204 | K12: 217 | L12: 86 | M12: 21 | N12: =SUM(B12:M12) -> 1683 | O12: =6889.86+1013+75+250 -> 8227.86 | P12: =O12/N12 -> 4.8888057
A13: Documents Retrieved | B13: 15 | C13: 413 | D13: 196 | E13: 603 | F13: 342 | G13: 77 | H13: 34 | I13: 51 | J13: 173 | K13: 131 | L13: 48 | M13: 12 | N13: =SUM(B13:M13) -> 2095 | O13: =6889.86+1013+75+250 -> 8227.86 | P13: =O13/N13 -> 3.9273795

Sheet MathSciNet
A1: MathSciNet
A2: 2005-2006
B5: 38534 | C5: 38565 | D5: 38596 | E5: 38626 | F5: 38657 | G5: 38687 | H5: 38718 | I5: 38749 | J5: 38777 | K5: 38808 | L5: 38838 | M5: 38869 | N5: Total | O5: 2005-2006 price | P5: Price per search
A6: MathSciNet
A7: Sessions | B7: 136 | C7: 35 | D7: 213 | E7: 220 | F7: 189 | G7: 182 | H7: 229 | I7: 316 | J7: 582 | K7: 328 | L7: 702 | M7: 129 | N7: =SUM(B7:M7) -> 3261
A8: Searches | B8: 299 | C8: 193 | D8: 501 | E8: 445 | F8: 369 | G8: 388 | H8: 491 | I8: 634 | J8: 844 | K8: 648 | L8: 947 | M8: 304 | N8: =SUM(B8:M8) -> 6063 | O8: 6856 | P8: =O8/N8 -> 1.1307933

Sheet Mergent
A1: Mergent
A2: 2005-2006
B5: 38534 | C5: 38565 | D5: 38596 | E5: 38626 | F5: 38657 | G5: 38687 | H5: 38718 | I5: 38749 | J5: 38777 | K5: 38808 | L5: 38838 | M5: 38869 | N5: Total | O5: 2005-2006 Price | P5: Price per unit
A6: Mergent Online
A7: Logins | B7: 24 | C7: 70 | D7: 42 | E7: 92 | F7: 50 | G7: 31 | H7: 13 | I7: 14 | J7: 8 | K7: 8 | L7: 22 | M7: 4 | N7: =SUM(B7:M7) -> 378
A8: Searches | B8: 59 | C8: 3766 | D8: 209 | E8: 108 | F8: 133 | G8: 35 | H8: 11 | I8: 94 | J8: 17 | K8: 24 | L8: 59 | M8: 4 | N8: =SUM(B8:M8) -> 4519 | O8: 10400 | P8: =O8/N8 -> 2.3013941
A9: Companies Viewed | B9: 28 | C9: 4519 | D9: 225 | E9: 64 | F9: 82 | G9: 30 | H9: 15 | I9: 72 | J9: 4 | K9: 4 | L9: 26 | M9: 4 | N9: =SUM(B9:M9) -> 5073 | O9: 10400 | P9: =O9/N9 -> 2.050069

Sheet MINABS
A1: MINABS
A2: 2005-2006
B5: 38534 | C5: 38565 | D5: 38596 | E5: 38626 | F5: 38657 | G5: 38687 | H5: 38718 | I5: 38749 | J5: 38777 | K5: 38808 | L5: 38838 | M5: 38869 | N5: Total | O5: 2005-2006 Price | P5: Price per session
A6: MINABS
A7: Sessions | B7: 0 | C7: 0 | D7: 1 | E7: 0 | F7: 0 | G7: 0 | H7: 0 | I7: 2 | J7: 0 | K7: 1 | L7: 0 | M7: 0 | N7: =SUM(B7:M7) -> 4 | O7: 555.48 | P7: =O7/N7 -> 138.87

Sheet MusicIndex
A1: Music Index
A2: 2005-2006
B5: 38534 | C5: 38565 | D5: 38596 | E5: 38626 | F5: 38657 | G5: 38687 | H5: 38718 | I5: 38749 | J5: 38777 | K5: 38808 | L5: 38838 | M5: 38869 | N5: Total | O5: 2005-2006 Price | P5: Price per search
A6: Music Index
A7: Sessions | B7: N/A | C7: N/A | D7: N/A | E7: N/A | F7: N/A | G7: N/A | H7: N/A | I7: N/A | J7: N/A | K7: N/A | L7: N/A | M7: N/A
A8: Searches | B8: 532 | C8: 0 | D8: 210 | E8: 122 | F8: 186 | G8: 240 | H8: 5 | I8: 99 | J8: 132 | K8: 142 | L8: 28 | M8: 14 | N8: =SUM(B8:M8) -> 1710 | O8: 1850 | P8: =O8/N8 -> 1.0818713

Sheet netLibrary
A1: NetLibrary
A2: 2005-2006
B5: 38534 | C5: 38565 | D5: 38596 | E5: 38626 | F5: 38657 | G5: 38687 | H5: 38718 | I5: 38749 | J5: 38777 | K5: 38808 | L5: 38838 | M5: 38869 | N5: Total | O5: Price for 2005-2006 | P5: Price per search
A6: NetLibrary
A7: Accesses | B7: 25 | C7: 15 | D7: 85 | E7: 116 | F7: 172 | G7: 97 | H7: 58 | I7: 116 | J7: 121 | K7: 134 | L7: 76 | M7: 74 | N7: =SUM(B7:M7) -> 1089 | O7: 0 | P7: N/A
A8: Turnaways | B8: 7 | C8: 15 | D8: 140 | E8: 8 | F8: 52 | G8: 22 | H8: 4 | I8: 31 | J8: 10 | K8: 3 | L8: 8 | M8: 2 | N8: =SUM(B8:M8) -> 302
A11: Note: We have 4,478 shared titles

Sheet OVID
A1: Ovid
A2: 2005-2006
B5: 38534 | C5: 38565 | D5: 38596 | E5: 38626 | F5: 38657 | G5: 38687 | H5: 38718 | I5: 38749 | J5: 38777 | K5: 38808 | L5: 38838 | M5: 38869 | N5: Total
A6: BIOSIS Previews
A7: Sessions | B7: N/A | C7: N/A | D7: N/A | E7: N/A | F7: N/A | G7: N/A | H7: 0 | I7: 5 | J7: 0 | K7: 1 | L7: 0 | M7: 0 | N7: =SUM(B7:M7) -> 6
A8: Searches | B8: N/A | C8: N/A | D8: N/A | E8: N/A | F8: N/A | G8: N/A | H8: 0 | I8: 6 | J8: 0 | K8: 3 | L8: 0 | M8: 0 | N8: =SUM(B8:M8) -> 9
A9: Turnaways | B9: 0 | C9: 0 | D9: 0 | E9: 0 | F9: 0 | G9: 0 | H9: 0 | I9: 0 | J9: 0 | K9: 0 | L9: 0 | M9: 0 | N9: =SUM(B9:M9) -> 0
B12: 38534 | C12: 38565 | D12: 38596 | E12: 38626 | F12: 38657 | G12: 38687 | H12: 38718 | I12: 38749 | J12: 38777 | K12: 38808 | L12: 38838 | M12: 38869 | N12: Total
A13: Ovid MEDLINE
A14: Sessions | B14: N/A | C14: N/A | D14: N/A | E14: N/A | F14: N/A | G14: N/A | H14: 0 | I14: 1 | J14: 0 | K14: 4 | L14: 0 | M14: 1 | N14: =SUM(B14:M14) -> 6
A15: Searches | B15: N/A | C15: N/A | D15: N/A | E15: N/A | F15: N/A | G15: N/A | H15: 0 | I15: 2 | J15: 0 | K15: 4 | L15: 0 | M15: 0 | N15: =SUM(B15:M15) -> 6
A16: Turnaways | B16: 0 | C16: 0 | D16: 0 | E16: 0 | F16: 0 | G16: 0 | H16: 0 | I16: 0 | J16: 0 | K16: 0 | L16: 0 | M16: 0 | N16: =SUM(B16:M16) -> 0
B19: 38534 | C19: 38565 | D19: 38596 | E19: 38626 | F19: 38657 | G19: 38687 | H19: 38718 | I19: 38749 | J19: 38777 | K19: 38808 | L19: 38838 | M19: 38869 | N19: Total
A20: Ovid MEDLINE In-Process
A21: Sessions | B21: N/A | C21: N/A | D21: N/A | E21: N/A | F21: N/A | G21: N/A | H21: 0 | I21: 0 | J21: 0 | K21: 0 | L21: 0 | M21: 0 | N21: =SUM(B21:M21) -> 0
A22: Searches | B22: N/A | C22: N/A | D22: N/A | E22: N/A | F22: N/A | G22: N/A | H22: 0 | I22: 0 | J22: 0 | K22: 0 | L22: 0 | M22: 0 | N22: =SUM(B22:M22) -> 0
A23: Turnaways | B23: 0 | C23: 0 | D23: 0 | E23: 0 | F23: 0 | G23: 0 | H23: 0 | I23: 0 | J23: 0 | K23: 0 | L23: 0 | M23: 0 | N23: =SUM(B23:M23) -> 0
B26: 38534 | C26: 38565 | D26: 38596 | E26: 38626 | F26: 38657 | G26: 38687 | H26: 38718 | I26: 38749 | J26: 38777 | K26: 38808 | L26: 38838 | M26: 38869 | N26: Total
A27: Ovid OLDMEDLINE
A28: Sessions | B28: N/A | C28: N/A | D28: N/A | E28: N/A | F28: N/A | G28: N/A | H28: 0 | I28: 0 | J28: 0 | K28: 0 | L28: 0 | M28: 0 | N28: =SUM(B28:M28) -> 0
A29: Searches | B29: N/A | C29: N/A | D29: N/A | E29: N/A | F29: N/A | G29: N/A | H29: 0 | I29: 0 | J29: 0 | K29: 0 | L29: 0 | M29: 0 | N29: =SUM(B29:M29) -> 0
A30: Turnaways | B30: 0 | C30: 0 | D30: 0 | E30: 0 | F30: 0 | G30: 0 | H30: 0 | I30: 0 | J30: 0 | K30: 0 | L30: 0 | M30: 0 | N30: =SUM(B30:M30) -> 0
B33: 38534 | C33: 38565 | D33: 38596 | E33: 38626 | F33: 38657 | G33: 38687 | H33: 38718 | I33: 38749 | J33: 38777 | K33: 38808 | L33: 38838 | M33: 38869 | N33: Total
A34: Journals@Ovid Full Text
A35: Sessions | B35: N/A | C35: N/A | D35: N/A | E35: N/A | F35: N/A | G35: N/A | H35: 249 | I35: 636 | J35: 682 | K35: 877 | L35: 285 | M35: 308 | N35: =SUM(B35:M35) -> 3037
A36: Searches | B36: N/A | C36: N/A | D36: N/A | E36: N/A | F36: N/A | G36: N/A | H36: 112 | I36: 280 | J36: 403 | K36: 528 | L36: 119 | M36: 142 | N36: =SUM(B36:M36) -> 1584
A37: Turnaways | B37: 0 | C37: 0 | D37: 0 | E37: 0 | F37: 0 | G37: 0 | H37: 0 | I37: 0 | J37: 0 | K37: 0 | L37: 0 | M37: 0 | N37: =SUM(B37:M37) -> 0
B41: 38534 | C41: 38565 | D41: 38596 | E41: 38626 | F41: 38657 | G41: 38687 | H41: 38718 | I41: 38749 | J41: 38777 | K41: 38808 | L41: 38838 | M41: 38869 | N41: Total
A42: All OVID Databases
A43: Sessions | B43: 193 | C43: 22 | D43: 56 | E43: 18 | F43: 19 | G43: 35 | H43: 249 | I43: 642 | J43: 682 | K43: 882 | L43: 285 | M43: 309 | N43: =SUM(B43:M43) -> 3392
A44: Searches | B44: 1165 | C44: 22 | D44: 60 | E44: 19 | F44: 26 | G44: 27 | H44: 112 | I44: 288 | J44: 403 | K44: 535 | L44: 119 | M44: 142 | N44: =SUM(B44:M44) -> 2918
A45: Turnaways | B45: 0 | C45: 0 | D45: 0 | E45: 0 | F45: 0 | G45: 0 | H45: 0 | I45: 0 | J45: 0 | K45: 0 | L45: 0 | M45: 0 | N45: =SUM(B45:M45) -> 0

Sheet ProQuest
A1: ProQuest databases
A2: 2005-2006
B5: 38534 | C5: 38565 | D5: 38596 | E5: 38626 | F5: 38657 | G5: 38687 | H5: 38718 | I5: 38749 | J5: 38777 | K5: 38808 | L5: 38838 | M5: 38869 | N5: Total | O5: 2005-2006 Price | P5: Price per search
A6: ABI/INFORM Global
A7: Searches | B7: 1593 | C7: 639 | D7: 1820 | E7: 4454 | F7: 4424 | G7: 2221 | H7: 1761 | I7: 3389 | J7: 3744 | K7: 4181 | L7: 2525 | M7: 1951 | N7: =SUM(B7:M7) -> 32702 | O7: 17940 | P7: =O7/N7 -> 0.5485903
B10: 38534 | C10: 38565 | D10: 38596 | E10: 38626 | F10: 38657 | G10: 38687 | H10: 38718 | I10: 38749 | J10: 38777 | K10: 38808 | L10: 38838 | M10: 38869 | N10: Total | O10: 2005-2006 Price | P10: Price per search
A11: ABI/INFORM Trade & Industry
A12: Searches | B12: 658 | C12: 211 | D12: 471 | E12: 1862 | F12: 2179 | G12: 1169 | H12: 492 | I12: 1714 | J12: 1799 | K12: 1908 | L12: 810 | M12: 1143 | N12: =SUM(B12:M12) -> 14416 | O12: 0 | P12: N/A
B15: 38534 | C15: 38565 | D15: 38596 | E15: 38626 | F15: 38657 | G15: 38687 | H15: 38718 | I15: 38749 | J15: 38777 | K15: 38808 | L15: 38838 | M15: 38869 | N15: Total | O15: 2005-2006 Price | P15: Price per search
A16: ProQuest Dissertations & Theses
A17: Searches | B17: 534 | C17: 195 | D17: 371 | E17: 1235 | F17: 1570 | G17: 807 | H17: 394 | I17: 1271 | J17: 1469 | K17: 1576 | L17: 644 | M17: 887 | N17: =SUM(B17:M17) -> 10953 | O17: 5475 | P17: =O17/N17 -> 0.49986305
B20: 38534 | C20: 38565 | D20: 38596 | E20: 38626 | F20: 38657 | G20: 38687 | H20: 38718 | I20: 38749 | J20: 38777 | K20: 38808 | L20: 38838 | M20: 38869 | N20: Total | O20: 2005-2006 Price | P20: Price per search
A21: National Newspapers (5)
A22: Searches | B22: 987 | C22: 278 | D22: 631 | E22: 1677 | F22: 1962 | G22: 1170 | H22: 574 | I22: 1660 | J22: 2264 | K22: 2211 | L22: 863 | M22: 1227 | N22: =SUM(B22:M22) -> 15504 | O22: 3071 | P22: =O22/N22 -> 0.19807792
B25: 38534 | C25: 38565 | D25: 38596 | E25: 38626 | F25: 38657 | G25: 38687 | H25: 38718 | I25: 38749 | J25: 38777 | K25: 38808 | L25: 38838 | M25: 38869 | N25: Total | O25: 2005-2006 Price | P25: Price per search
A26: Los Angeles Times
A27: Searches | B27: 624 | C27: 254 | D27: 473 | E27: 1402 | F27: 1711 | G27: 880 | H27: 482 | I27: 1403 | J27: 1633 | K27: 1721 | L27: 723 | M27: 1035 | N27: =SUM(B27:M27) -> 12341 | O27: 0 | P27: N/A
B30: 38534 | C30: 38565 | D30: 38596 | E30: 38626 | F30: 38657 | G30: 38687 | H30: 38718 | I30: 38749 | J30: 38777 | K30: 38808 | L30: 38838 | M30: 38869 | N30: Total | O30: 2005-2006 Price | P30: Price per search
A31: Providence Journal-Bulletin
A32: Searches | B32: 909 | C32: 520 | D32: 551 | E32: 1608 | F32: 2014 | G32: 1133 | H32: 755 | I32: 1567 | J32: 1857 | K32: 1912 | L32: 907 | M32: 1220 | N32: =SUM(B32:M32) -> 14953 | O32: 1820 | P32: =O32/N32 -> 0.12171471
B35: 38534 | C35: 38565 | D35: 38596 | E35: 38626 | F35: 38657 | G35: 38687 | H35: 38718 | I35: 38749 | J35: 38777 | K35: 38808 | L35: 38838 | M35: 38869 | N35: Total | O35: 2005-2006 Price | P35: Price per search
A36: Wall Street Journal
A37: Searches | B37: 627 | C37: 261 | D37: 497 | E37: 1417 | F37: 1740 | G37: 914 | H37: 486 | I37: 1410 | J37: 1634 | K37: 1730 | L37: 738 | M37: 1072 | N37: =SUM(B37:M37) -> 12526 | O37: 0 | P37: N/A
B40: 38534 | C40: 38565 | D40: 38596 | E40: 38626 | F40: 38657 | G40: 38687 | H40: 38718 | I40: 38749 | J40: 38777 | K40: 38808 | L40: 38838 | M40: 38869 | N40: Total | O40: 2005-2006 Price | P40: Price per search
A41: ProQuest Historical Newspapers The New York Times (1851-2002)
A42: Searches | B42: 103 | C42: 65 | D42: 9 | E42: 231 | F42: 99 | G42: 69 | H42: 74 | I42: 188 | J42: 264 | K42: 445 | L42: 140 | M42: 68 | N42: =SUM(B42:M42) -> 1755 | O42: 0 | P42: N/A
B45: 38534 | C45: 38565 | D45: 38596 | E45: 38626 | F45: 38657 | G45: 38687 | H45: 38718 | I45: 38749 | J45: 38777 | K45: 38808 | L45: 38838 | M45: 38869 | N45: Total | O45: 2005-2006 Price | P45: Price per unit
A46: ProQuest (all databases)
A47: Sessions | B47: 1040 | C47: 446 | D47: 1397 | E47: 2347 | F47: 2606 | G47: 1389 | H47: 841 | I47: 1959 | J47: 2380 | K47: 2423 | L47: 1043 | M47: 935 | N47: =SUM(B47:M47) -> 18806
A48: Searches | B48: 2517 | C48: 1055 | D48: 2395 | E48: 5687 | F48: 5630 | G48: 3262 | H48: 2121 | I48: 4858 | J48: 5875 | K48: 5685 | L48: 3320 | M48: 2758 | N48: =SUM(B48:M48) -> 45163 | O48: =SUM(O7:O46) -> 28306 | P48: =O48/N48 -> 0.62675199
A49: Successful full-text downloads | B49: 1982 | C49: 1808 | D49: 2298 | E49: 5834 | F49: 5588 | G49: 3542 | H49: 2490 | I49: 4698 | J49: 5214 | K49: 5929 | L49: 2962 | M49: 3139 | N49: =SUM(B49:M49) -> 45484 | O49: =O48 -> 28306 | P49: =O49/N49 -> 0.62232873

Sheet ReferenceUSA
A1: ReferenceUSA
A2: 2005-2006
B5: 38534 | C5: 38565 | D5: 38596 | E5: 38626 | F5: 38657 | G5: 38687 | H5: 38718 | I5: 38749 | J5: 38777 | K5: 38808 | L5: 38838 | M5: 38869 | N5: Total | O5: 2005-2006 Price | P5: Price per search
A6: ReferenceUSA
A7: Sessions | B7: 122 | C7: 119 | D7: 109 | E7: 102 | F7: 127 | G7: 101 | H7: 107 | I7: 227 | J7: 254 | K7: 253 | L7: 89 | M7: 79 | N7: =SUM(B7:M7) -> 1689
A8: Searches | B8: 241 | C8: 325 | D8: 278 | E8: 271 | F8: 250 | G8: 321 | H8: 316 | I8: 490 | J8: 850 | K8: 626 | L8: 319 | M8: 196 | N8: =SUM(B8:M8) -> 4483 | O8: 4792 | P8: =O8/N8 -> 1.0689271
A9: Residential Searches | B9: 35 | C9: =11+2 -> 13 | D9: 45 | E9: 55 | F9: 41 | G9: 77 | H9: =21+1 -> 22 | I9: 79 | J9: 88 | K9: 112 | L9: 62 | M9: 43 | N9: =SUM(B9:M9) -> 672
A10: Business Searches | B10: 206 | C10: =181+131 -> 312 | D10: =232+1 -> 233 | E10: =212+4 -> 216 | F10: 209 | G10: 244 | H10: =290+4 -> 294 | I10: 411 | J10: 762 | K10: 514 | L10: 257 | M10: 153 | N10: =SUM(B10:M10) -> 3811

Sheet RefWorks
A1: RefWorks (CSA)
A2: 2005-2006
B5: 38534 | C5: 38565 | D5: 38596 | E5: 38626 | F5: 38657 | G5: 38687 | H5: 38718 | I5: 38749 | J5: 38777 | K5: 38808 | L5: 38838 | M5: 38869 | N5: Total | O5: 2005-2006 Price | P5: Cost per unit
A6: RefWorks
A7: New Users | B7: 1 | C7: N/A | D7: 21 | E7: 27 | F7: 54 | G7: 3 | H7: 6 | I7: 24 | J7: 13 | K7: 19 | L7: 6 | M7: 4 | N7: =SUM(B7:M7) -> 178 | O7: 10500 | P7: =O7/N7 -> 58.988764
A8: Repeat Users | B8: 5 | C8: N/A | D8: 3 | E8: 14 | F8: 20 | G8: 21 | H8: 16 | I8: 27 | J8: 19 | K8: 24 | L8: 18 | M8: 11 | N8: =SUM(B8:M8) -> 178 | O8: 10500 | P8: =O8/N8 -> 58.988764
A9: Total Monthly Users | B9: 6 | C9: 4 | D9: 24 | E9: 41 | F9: 74 | G9: 24 | H9: 22 | I9: 51 | J9: 32 | K9: 43 | L9: 24 | M9: 15 | N9: =SUM(B9:M9) -> 360 | O9: 10500 | P9: =O9/N9 -> 29.166667 | Q9: per user
A10: Total Sessions per month | B10: 18 | C10: 4 | D10: 50 | E10: 156 | F10: 318 | G10: 120 | H10: 111 | I10: 198 | J10: 199 | K10: 199 | L10: 97 | M10: 59 | N10: =SUM(B10:M10) -> 1529 | O10: 10500 | P10: =O10/N10 -> 6.8672335 | Q10: per session
A11: Average Sessions Per User | B11: 3 | C11: 1 | D11: 2.08 | E11: 3.8 | F11: 4.3 | G11: 5 | H11: 5.05 | I11: 3.88 | J11: 6.22 | K11: 4.63 | L11: 4.04 | M11: 3.93 | N11: =SUM(B11:M11) -> 46.93 | O11: 10500 | P11: =O11/N11 -> 223.73748
A12: Total Subscriber References added | B12: 27 | C12: 0 | D12: 38 | E12: 1856 | F12: 1084 | G12: 567 | H12: 169 | I12: 386 | J12: 423 | K12: 293 | L12: 333 | M12: 480 | N12: =SUM(B12:M12) -> 5656 | O12: 10500 | P12: =O12/N12 -> 1.8564356 | Q12: per reference added
A13: Average References added per user | B13: 4.5 | C13: 0 | D13: 1.58 | E13: 45.27 | F13: 14.65 | G13: 23.63 | H13: 7.68 | I13: 7.57 | J13: 13.22 | K13: 6.81 | L13: 13.88 | M13: 32 | N13: =SUM(B13:M13) -> 170.79 | O13: 10500 | P13: =O13/N13 -> 61.479009
A18: User Type and Focus Area Summary (as of 9/5/06)
A19: User Type | B19: Focus Area | D19: User Count
A20: N/A** | B20: N/A** | D20: 1
A21: Etudiant deuxième cycle | B21: College of Business Administration | D21: 1
A22: Faculty Member | B22: Business | D22: 1
A23: Faculty Member | B23: College of Arts and Sciences | D23: 2
A24: Faculty Member | B24: College of Human Science and Services | D24: 2
A25: Faculty Member | B25: College of Nursing | D25: 3
A26: Faculty Member | B26: Humanities | D26: 7
A27: Faculty Member | B27: Medicine | D27: 6
A28: Faculty Member | B28: Nursing | D28: 2
A29: Faculty Member | B29: Other | D29: 12
A30: Faculty Member | B30: Science & Technology | D30: 11
A31: Faculty Member | B31: Social Sciences | D31: 19
... A68: Undergraduate Student | B68: Social Sciences | D68: 47

Sheet SciFinderScholar
A1: SciFinder Scholar
A2: 2005-2006
B5: 38534 | C5: 38565 | D5: 38596 | E5: 38626 | F5: 38657 | G5: 38687 | H5: 38718 | I5: 38749 | J5: 38777 | K5: 38808 | L5: 38838 | M5: 38869 | N5: Total | O5: 2005-2006 Price | P5: Price per search
A6: SciFinder Scholar
A7: Sessions | B7: 218 | C7: 218 | D7: 277 | E7: 279 | F7: 253 | G7: 210 | H7: 190 | I7: 230 | J7: 193 | K7: 195 | L7: 248 | M7: 253 | N7: =SUM(B7:M7) -> 2764
A8: Searches | B8: 837 | C8: 599 | D8: 730 | E8: 813 | F8: 898 | G8: 740 | H8: 592 | I8: 623 | J8: 660 | K8: 775 | L8: 984 | M8: 1012 | N8: =SUM(B8:M8) -> 9263 | O8: 29030 | P8: =O8/N8 -> 3.1339739
A9: Turnaways | B9: 133 | C9: 57 | D9: 102 | E9: 93 | F9: 143 | G9: 96 | H9: 49 | I9: 95 | J9: 66 | K9: 96 | L9: 177 | M9: 253 | N9: =SUM(B9:M9) -> 1360
A10: Simultaneous users | B10: 1 | C10: 1 | D10: 1 | E10: 1 | F10: 1 | G10: 1 | H10: 1 | I10: 1 | J10: 1 | K10: 1 | L10: 1 | M10: 1

Sheet WebofScience
A1: Web of Science
A2: 2005-2006
B5: 38534 | C5: 38565 | D5: 38596 | E5: 38626 | F5: 38657 | G5: 38687 | H5: 38718 | I5: 38749 | J5: 38777 | K5: 38808 | L5: 38838 | M5: 38869 | N5: Total | O5: 2005-2006 Price | P5: Price per search
A6: Web of Science
A7: Sessions | B7: 280 | C7: 437 | D7: 508 | E7: 1034 | F7: 834 | G7: 477 | H7: 404 | I7: 506 | J7: 534 | K7: 677 | L7: 455 | M7: 376 | N7: =SUM(B7:M7) -> 6522
A8: Queries | B8: 1138 | C8: 1220 | D8: 1907 | E8: 2645 | F8: 3056 | G8: 1835 | H8: 1408 | I8: 1963 | J8: 1933 | K8: 2192 | L8: 1245 | M8: 1036 | N8: =SUM(B8:M8) -> 21578 | O8: 90186 | P8: =O8/N8 -> 4.1795347
A9: Maximum Contractual Users | B9: 5 | C9: 5 | D9: 5 | E9: 5 | F9: 5 | G9: 5 | H9: 5 | I9: 5 | J9: 5 | K9: 5 | L9: 5 | M9: 5 | N9: =SUM(B9:M9) -> 60
A10: Turnaways | B10: 1 | C10: 24 | D10: 19 | E10: 4895 | F10: 377 | G10: 132 | H10: 138 | I10: 122 | J10: 5 | K10: 1522 | L10: 866 | M10: 715 | N10: =SUM(B10:M10) -> 8816

Sheet WebSpirs
A1: WebSPIRS (OVID)
A2: 2005-2006
B5: 38534 | C5: 38565 | D5: 38596 | E5: 38626 | F5: 38657 | G5: 38687 | H5: 38718 | I5: 38749 | J5: 38777 | K5: 38808 | L5: 38838 | M5: 38869 | N5: Total | O5: 2005-2006 Price | P5: Price per search
A6: Biological Abstracts
A7: Sessions | B7: 44 | C7: 61 | D7: 178 | E7: 315 | F7: 297 | G7: 114 | H7: 148 | I7: 132 | J7: 246 | K7: 336 | L7: 89 | M7: 91 | N7: =SUM(B7:M7) -> 2051
A8: Searches | B8: 144 | C8: 155 | D8: 518 | E8: 1110 | F8: 983 | G8: 400 | H8: 614 | I8: 420 | J8: 866 | K8: 1181 | L8: 347 | M8: 284 | N8: =SUM(B8:M8) -> 7022 | O8: 22306 | P8: =O8/N8 -> 3.1765879
A9: Turnaways | B9: 0 | C9: 0 | D9: 0 | E9: 0 | F9: 0 | G9: 0 | H9: 0 | I9: 0 | J9: 0 | K9: 0 | L9: 0 | M9: 0 | N9: =SUM(B9:M9) -> 0

Sheet WilsonWeb
A1: WilsonWeb
A2: 2005-2006
B5: 38534 | C5: 38565 | D5: 38596 | E5: 38626 | F5: 38657 | G5: 38687 | H5: 38718 | I5: 38749 | J5: 38777 | K5: 38808 | L5: 38838 | M5: 38869 | N5: Total | O5: 2005-2006 price | P5: Price per search
A6: Art Abstracts
A7: Sessions | B7: 14 | C7: 7 | D7: 83 | E7: 143 | F7: 182 | G7: 79 | H7: 39 | I7: 197 | J7: 99 | K7: 107 | L7: 27 | M7: 18 | N7: =SUM(B7:M7) -> 995
A8: Searches | B8: 42 | C8: 19 | D8: 290 | E8: 592 | F8: 872 | G8: 319 | H8: 169 | I8: 1086 | J8: 364 | K8: 397 | L8: 90 | M8: 40 | N8: =SUM(B8:M8) -> 4280 | O8: 4977 | P8: =O8/N8 -> 1.1628505
A9: Turnaways | B9: 0 | C9: 0 | D9: 0 | E9: 0 | F9: 0 | G9: 0 | H9: 0 | I9: 0 | J9: 0 | K9: 0 | L9: 0 | M9: 0 | N9: =SUM(B9:M9) -> 0
A11: Applied Science & Technology Abstracts
A12: Sessions | B12: 29 | C12: 13 | D12: 34 | E12: 62 | F12: 129 | G12: 34 | H12: 28 | I12: 48 | J12: 75 | K12: 92 | L12: 29 | M12: 44 | N12: =SUM(B12:M12) -> 617
A13: Searches | B13: 126 | C13: 35 | D13: 108 | E13: 156 | F13: 548 | G13: 152 | H13: 130 | I13: 158 | J13: 257 | K13: 243 | L13: 70 | M13: 205 | N13: =SUM(B13:M13) -> 2188 | O13: 5562 | P13: =O13/N13 -> 2.5420475
A14: Turnaways | B14: 0 | C14: 0 | D14: 0 | E14: 0 | F14: 0 | G14: 0 | H14: 0 | I14: 0 | J14: 0 | K14: 0 | L14: 0 | M14: 0 | N14: =SUM(B14:M14) -> 0
A16: Biological & Agricultural Index Plus
A17: Sessions | B17: 22 | C17: 12 | D17: 45 | E17: 67 | F17: 57 | G17: 22 | H17: 68 | I17: 70 | J17: 74 | K17: 80 | L17: 22 | M17: 21 | N17: =SUM(B17:M17) -> 560
A18: Searches | B18: 145 | C18: 25 | D18: 129 | E18: 202 | F18: 211 | G18: 108 | H18: 248 | I18: 206 | J18: 272 | K18: 287 | L18: 64 | M18: 103 | N18: =SUM(B18:M18) -> 2000 | O18: 3291.75 | P18: =O18/N18 -> 1.645875
A19: Turnaways | B19: 0 | C19: 0 | D19: 20 | E19: 0 | F19: 0 | G19: 0 | H19: 53 | I19: 0 | J19: 6 | K19: 0 | L19: 0 | M19: 0 | N19: =SUM(B19:M19) -> 79
A21: Readers Guide Retrospective
A22: Sessions | B22: 45 | C22: 1 | D22: 16 | E22: 57 | F22: 23 | G22: 12 | H22: 10 | I22: 30 | J22: 38 | K22: 41 | L22: 8 | M22: 11 | N22: =SUM(B22:M22) -> 292
A23: Searches | B23: 146 | C23: 1 | D23: 30 | E23: 238 | F23: 89 | G23: 56 | H23: 28 | I23: 76 | J23: 152 | K23: 165 | L23: 35 | M23: 34 | N23: =SUM(B23:M23) -> 1050 | O23: 326 | P23: =O23/N23 -> 0.31047619
A24: Turnaways | B24: 0 | C24: 0 | D24: 0 | E24: 0 | F24: 0 | G24: 0 | H24: 0 | I24: 0 | J24: 0 | K24: 0 | L24: 0 | M24: 0 | N24: =SUM(B24:M24) -> 0
