Workbook
Name Aid: 'Aid Adjust'!$A$10:$H$346
Name Ideas: Credits!$A$8:$C$344
Name Ideas: Levy!$A$8:$C$344
Name Ideas: Ideas!$A$9:$H$345
Name Query_from_Databridge: Query1!$A$3:$F$146
Name Query_from_Databridge: Query4!$A$3:$F$138
Name Shift05: Receipts!$A$8:$K$344
Name ShiftCY: Shift11!$A$8:$O$344
Name ShiftPY: Shift10!$A$8:$O$344

Sheet Instructions
A1: PROPERTY TAX SHIFT | M1: =Report!I1 -> 41115 | O1: 2012 | P1: Pay 2012 | Q1: 11 Pay 12 | R1: FY 2013
P2: Pay 2011 | Q2: 10 Pay 11 | R2: FY 2012 | S2: 06/30/12 | T2: 07/01/2011 to 06/30/2012
P3: Pay 2010 | R3: FY 2011 | S3: 06/30/11 | T3: 07/01/2011 to 04/30/2012
P4: Pay 2009 | T4: 05/01/2012 to 06/30/2012
A5: ="The property tax shift is an accounting entry that takes a portion of the school district's property tax revenue and moves it forward one fiscal year, i.e., taxes that would otherwise be revenue for fiscal year "&RIGHT(R1,4)&" are shifted into fiscal year "&RIGHT(R2,4)&". The property tax shift requirement is in Minnesota Statutes, section 123B.75, subdivision 5." -> The property tax shift is an accounting entry that takes a portion of the school district's property tax revenue and moves it forward one fiscal year, i.e., taxes that would otherwise be revenue for fiscal year 2013 are shifted into fiscal year 2012. The property tax shift requirement is in Minnesota Statutes, section 123B.75, subdivision 5. | P5: Pay 2008
P6: Pay 2007
P7: Pay 2006
A8: Notes: | P8: Pay 2005
A10: ="For the June 30, "&RIGHT(R2,4)&", tax shift this spreadsheet is using the payable "&RIGHT(P1,4)&" final certified levies plus/minus county auditor adjustments." -> For the June 30, 2012, tax shift this spreadsheet is using the payable 2012 final certified levies plus/minus county auditor adjustments.
A13: ="Preliminary payable "&RIGHT(P1,4)&" credits are used in this spreadsheet. The spreadsheet will be updated to use final payable "&RIGHT(P1,4)&" credits when that data is available." -> Preliminary payable 2012 credits are used in this spreadsheet. The spreadsheet will be updated to use final payable 2012 credits when that data is available.
A15: ="Tax receipts for May-July "&RIGHT(R2,4)&" for the general fund and community service fund have been estimated on the Receipts tab. Preliminary payable "&RIGHT(P1,4)&" credits from the Department of Revenue are used in computing estimated tax receipts. These estimates are carried over to cells E89 and F89 of the Report tab. Districts should override these estimates when actual tax receipts are determined." -> Tax receipts for May-July 2012 for the general fund and community service fund have been estimated on the Receipts tab. Preliminary payable 2012 credits from the Department of Revenue are used in computing estimated tax receipts. These estimates are carried over to cells E89 and F89 of the Report tab. Districts should override these estimates when actual tax receipts are determined.
A19: Early Recognition Levies
A20: Certain levies have been--and will continue to be--shifted 100% with no aid reduction. Recognizing these levies early gets the revenue into the same fiscal year as the related expenditures. There is no state aid adjustment for this portion of the shift.
A23: Other Levies
A24: Starting in fiscal year 2004, the shift was expanded to include all other general and community service fund levies, net of tax credits. There is a corresponding state aid adjustment for this portion of the property tax shift, making this portion of the shift revenue neutral to school districts each year. If the shift at the end of the current year is larger than the shift at the end of the previous year, state aid for the current year is reduced for the net increase in the shift. If the shift at the end of the current year is less than the shift at the end of the previous year, state aid for the current year is increased for the net decrease in the shift.
A29: Starting in fiscal year 2006, the shift percentage for other levies was set to zero percent.
A30: Starting in fiscal year 2011, the shift percentage for other levies was set to 48.6 percent, and based on gross levies (before subtraction of credits).
A33: The "Reports" tab shows the property tax shift report for a selected school district.
B34: To select a specific district, type the district number in cell A3 (use 1.2 for Minneapolis) and press enter. Information for the selected district will then appear in the report. Running a macro is not required.
B37: The first section shows the property tax shift report for the school district, with a definition for each tax shift category.
C38: ="Column 1 is the amount of payable "&RIGHT(P1,4)&" levy to be recognized in fiscal year "&RIGHT(R2,4)&"." -> Column 1 is the amount of payable 2012 levy to be recognized in fiscal year 2012.
C39: ="Column 2 is the amount of payable "&RIGHT(P2,4)&" levy that was recognized in fiscal year "&RIGHT(R3,4)&"." -> Column 2 is the amount of payable 2011 levy that was recognized in fiscal year 2011.
C40: Column 3 is the revenue change to be recognized as a result of the levies shifted with with no aid reduction (net of column 1 and column 2 for these categories).
C41: Column 4 is the net shift amount to be recognized as a result of levies shifted with an aid reduction. A negative amount in this column represents a debit balance in source 020 and related crebit balance in source 299.
C43: Column 5 is the state aid payment (reduction) that is being made in the current year for the property tax shift.
C44: Column 6 represents the state aid payment (reduction) that will be made next year, for this year's tax shift. Column 4 plus column 5 plus column 6 should equal zero.
B47: The second section discusses the assumptions that have been made in generating the entries to record the tax shift. Also review the Accounts tab and Entries tab.
B49: ="In the third section, estimated tax receipts for May, June and July "&RIGHT(R2,4)&" have been computed. See blue highlighted area. Override these estimates with actual tax settlement receipts for May, June and July "&RIGHT(R2,4)&" when this data is available. If the gross shift amount is greater than May, June and July tax receipts, the district will recognize fiscal year "&RIGHT(R1,4)&" general education aid early in an amount equal to the difference between tax receipts and the gross shift." -> In the third section, estimated tax receipts for May, June and July 2012 have been computed. See blue highlighted area. Override these estimates with actual tax settlement receipts for May, June and July 2012 when this data is available. If the gross shift amount is greater than May, June and July tax receipts, the district will recognize fiscal year 2013 general education aid early in an amount equal to the difference between tax receipts and the gross shift.
B53: ="The fourth section provides information to make the year-end accounting entries for the fiscal year "&RIGHT(R2,4)&" property tax shift. The entry will include any general education aid to be recognized early if tax settlement receipts entered in section three are less than the gross shift amount." -> The fourth section provides information to make the year-end accounting entries for the fiscal year 2012 property tax shift. The entry will include any general education aid to be recognized early if tax settlement receipts entered in section three are less than the gross shift amount.
A56: Enter data on the Funds tab if you want to use the reconciliation feature in the Accounts tab.
B57: ="Enter certified levy by fund for payable "&RIGHT(P8,4)&" through "&RIGHT(P1,4)&" in the yellow highlighted section. Verify total certified levy. This data is used in the Accounts tab to automatically enter the certifed levy and to allocate abatements and adjustments." -> Enter certified levy by fund for payable 2005 through 2012 in the yellow highlighted section. Verify total certified levy. This data is used in the Accounts tab to automatically enter the certifed levy and to allocate abatements and adjustments.
B60: ="Enter tax settlements received during fiscal year "&RIGHT(R2,4)&" in the green highlighted section. The green outlined section below will then show each settlement allocated by fund. This data carries over as settlements received in the Accounts tab." -> Enter tax settlements received during fiscal year 2012 in the green highlighted section. The green outlined section below will then show each settlement allocated by fund. This data carries over as settlements received in the Accounts tab.
A63: The Accounts tab provides a year-end reconciliation for each tax-related account.
B64: This section shows how to determine the balance to be reflected in each account at year-end after all tax entries (including the property tax shift entries) have been made. Balance sheet accounts are listed first and then revenue source codes. Also shown is the source document where the data for each step of the reconcilation can be obtained.
B68: This tab can serve as a year-end reconcilation tool. Enter data in the highlighted fields on this tab and in the Funds tab. All other fields in this tab will automatically be computed.
A71: The Entries tab shows standard accounting entries for recording property taxes.
B72: The entries start with the levy being certified by the school board and work through a full year of accounting entries.
A74: The other tabs in this spreadsheet provide the data that is used to create the tax shift report shown in the Reports tab.
A76: If you have questions about the property tax shift or about using this spreadsheet, contact Terri Yetter by phone at 651-582-8868 or by e-mail at terri.yetter@state.mn.us.

Sheet Report
D1: PROPERTY TAX SHIFT YEAR-END RECONCILIATION | I1: 41115
D2: =Instructions!S2 -> 06/30/12
A3: 1.2 | B3: Enter District Number
B5: =VLOOKUP(A3,ShiftCY,3) -> MINNEAPOLIS
C6: 1 | D6: 2 | E6: 3 | F6: 4 | H6: 5 | I6: 6
C7: ="Gross Shift Amount "&Instructions!Q1 -> Gross Shift Amount 11 Pay 12 | D7: ="Replacement for "&Instructions!Q2&" Shift" -> Replacement for 10 Pay 11 Shift | E7: =Instructions!R2&" Revenue Adjust Src Code 001" -> FY 2012 Revenue Adjust Src Code 001 | F7: =Instructions!R2&" Net Shift Amount Src Code 020" -> FY 2012 Net Shift Amount Src Code 020 | H7: State Aid Adjustment Src Code 299 | I7: Revenue Adjustment Src Code 299
A9: A | B9: General - Shift & Adjust Aid | C9: =VLOOKUP($A$3,ShiftCY,4,FALSE) -> 11569510 | D9: =VLOOKUP($A$3,ShiftPY,4,FALSE) -> 14582222 | F9: =C9-D9 -> -3012712.2
A10: B | B10: General - Operating Referendum (with aid adjust) | C10: =VLOOKUP($A$3,ShiftCY,5,FALSE) -> 22730186 | D10: =VLOOKUP($A$3,ShiftPY,5,FALSE) -> 21821402 | F10: =C10-D10 -> 908784.28
A11: C | B11: General - Operating Referendum (no aid adjust) | C11: =VLOOKUP($A$3,ShiftCY,6,FALSE) -> 10049626 | D11: =VLOOKUP($A$3,ShiftPY,6,FALSE) -> 10049626 | E11: =C11-D11 -> 0
A12: D | B12: General - Addl Referendum Shift | C12: =VLOOKUP($A$3,ShiftCY,7,FALSE) -> 1205612.7 | D12: =VLOOKUP($A$3,ShiftPY,7,FALSE) -> 1205612.7 | E12: =C12-D12 -> 0
A13: E | B13: General - Career Technical | C13: =VLOOKUP($A$3,ShiftCY,8,FALSE) -> 551214.14 | D13: =VLOOKUP($A$3,ShiftPY,8,FALSE) -> 529738.02 | E13: =C13-D13 -> 21476.12
A14: F | B14: General - 100% Shift, No Adjust | C14: =VLOOKUP($A$3,ShiftCY,9,FALSE) -> 8657778.7 | D14: =VLOOKUP($A$3,ShiftPY,9,FALSE) -> 8867688.3 | E14: =C14-D14 -> -209909.61
A15: G | B15: General - Reemploy Ins (Reserved) | C15: =VLOOKUP($A$3,ShiftCY,10,FALSE) -> 0 | D15: =VLOOKUP($A$3,ShiftPY,10,FALSE) -> 0 | E15: =C15-D15 -> 0
A16: H | B16: General - Reemploy Ins (Unreserved) | C16: =VLOOKUP($A$3,ShiftCY,11,FALSE) -> 1774703.8 | D16: =VLOOKUP($A$3,ShiftPY,11,FALSE) -> 1757181.6 | E16: =C16-D16 -> 17522.16
A17: I | B17: General - Legislative Changes | C17: =VLOOKUP($A$3,ShiftCY,12,FALSE) -> 0 | D17: =VLOOKUP($A$3,ShiftPY,12,FALSE) -> 0 | E17: =C17-D17 -> 0
A18: J | B18: General Fund Total | C18: =SUM(C9:C17) -> 56538632 | D18: =SUM(D9:D17) -> 58813471 | E18: =SUM(E9:E17) -> -170911.33 | F18: =SUM(F9:F17) -> -2103927.9 | H18: =VLOOKUP($A$3,Ideas,4) -> 1703911.3 | I18: =-F18-H18 -> 400016.66
A20: K | B20: Comm Serv - Shift & Adjust Aid | C20: =VLOOKUP($A$3,ShiftCY,13,FALSE) -> 2395202 | D20: =VLOOKUP($A$3,ShiftPY,13,FALSE) -> 1994567.9 | F20: =C20-D20 -> 400634.03
A21: L | B21: Comm Serv - 100% Shift, No Adjust | C21: 0 | D21: 0 | E21: =C21-D21 -> 0
A22: M | B22: Comm Serv - Legislative Change | C22: =VLOOKUP($A$3,ShiftCY,14,FALSE) -> 0 | D22: =VLOOKUP($A$3,ShiftPY,14,FALSE) -> 0 | E22: =C22-D22 -> 0
A23: N | B23: Comm Serv Fund Total | C23: =SUM(C20:C22) -> 2395202 | D23: =SUM(D20:D22) -> 1994567.9 | E23: =SUM(E20:E22) -> 0 | F23: =SUM(F20:F22) -> 400634.03 | H23: =VLOOKUP($A$3,Ideas,5) -> 0 | I23: =-F23-H23 -> -400634.03
A26: O | B26: Total | C26: =C18+C23 -> 58933834 | D26: =D18+D23 -> 60808039 | E26: =E18+E23 -> -170911.33 | F26: =F18+F23 -> -1703293.9 | H26: =H18+H23 -> 1703911.3 | I26: =I18+I23 -> -617.37
A31: Definitions of levy categories within funds
A32: The following categories are mutually exclusive, that is, each levy appears in one category only.
B33: Shift & Adjust Aid | C33: ="For "&Instructions!P1&" this category includes all levies not identified below, shifted at 48.6%." -> For Pay 2012 this category includes all levies not identified below, shifted at 48.6%.
C34: ="For "&Instructions!P2&" this category includes all levies not identified below, shifted at 48.6%." -> For Pay 2011 this category includes all levies not identified below, shifted at 48.6%.
B35: Operating referendum (with aid adjust) | C35: ="For "&Instructions!P1&" this category is the greater of zero, or the "&Instructions!P1&" referendum levy shifted at 48.6% minus" -> For Pay 2012 this category is the greater of zero, or the Pay 2012 referendum levy shifted at 48.6% minus
C36: ="the Pay 2001 referendum shifted at 31%." -> the Pay 2001 referendum shifted at 31%.
B37: Operating referendum (no aid adjust) | C37: This category is the Pay 2001 referendum levy shifted at 31%. This amount will be constant from year to year.
B38: Addl referendum shift | C38: This is an additional revenue shift for districts that had a decrease in Pay 1994 referendum levy
C39: due to the net of changes in the allocation of HACA and the increase in referendum equalization aid.
C40: This amount will be constant from year to year.
B41: Career Technical | C41: Career technical levy and adjustment shifted at 100% with no aid adjustment.
B42: 100% shift, no adjust | C42: Includes levies that are shifted at 100% and for which there is no reduction to state aid. This category
C43: includes integration for first class districts, additional retirement, health benefits, and related adjustments.
B44: Reemploy Ins (reserved) | C44: Includes reemployment insurance levy adjustments for FY 2003 shifted at 100% with no aid adjustment.
B45: Reemploy Ins (unreserved) | C45: Includes reemployment insurance levy and adjustments for FY 2004 and later shifted at 100% with no aid adjustment.
B46: Legislative changes | C46: Includes selected levies that have been adjusted based on legislation that changes a levy authority after the levy has
C47: been certified (See Minnesota Statutes, section 126C.48, subdivision 6). The revenue shift is at 100% and there is
C48: ="no adjustment to state aids. For "&Instructions!P2&" and "&Instructions!P1&" this category is zero." -> no adjustment to state aids. For Pay 2011 and Pay 2012 this category is zero.
A52: =$A$3 -> 1.2 | B52: =VLOOKUP($A$3,ShiftCY,3) -> MINNEAPOLIS | I52: =Instructions!$M$1 -> 41115
...

Sheet Funds
A1: Enter certified levies for each year below | K1: =Report!I1 -> 41115
A2: This data is used to report certified levies on Accounts tab
A3: Also used to allocate adjustments and abatements on Accounts tab
D6: Certified Levy
D7: =Instructions!P1 -> Pay 2012 | E7: =Instructions!P2 -> Pay 2011 | F7: =Instructions!P3 -> Pay 2010 | G7: =Instructions!P4 -> Pay 2009 | H7: =Instructions!P5 -> Pay 2008 | I7: =Instructions!P6 -> Pay 2007 | J7: =Instructions!P7 -> Pay 2006 | K7: =Instructions!P8 -> Pay 2005
B9: General | D9: 0 | E9: 0 | F9: 0 | G9: 0 | H9: 0 | I9: 0 | J9: 0 | K9: 0
B10: Community Serv | D10: 0 | E10: 0 | F10: 0 | G10: 0 | H10: 0 | I10: 0 | J10: 0 | K10: 0
B11: Debt Service | D11: 0 | E11: 0 | F11: 0 | G11: 0 | H11: 0 | I11: 0 | J11: 0 | K11: 0
B12: OPEB | D12: 0 | E12: 0 | F12: 0 | G12: 0 | H12: 0 | I12: 0 | J12: 0 | K12: 0
B14: Total Certified Levy | D14: =SUM(D9:D13) -> 0 | E14: =SUM(E9:E13) -> 0 | F14: =SUM(F9:F13) -> 0 | G14: =SUM(G9:G13) -> 0 | H14: =SUM(H9:H13) -> 0 | I14: =SUM(I9:I13) -> 0 | J14: =SUM(J9:J13) -> 0 | K14: =SUM(K9:K13) -> 0
A20: ="Enter each tax settlement received July 1, "&RIGHT(Instructions!P2,4)&" through June 30, "&RIGHT(Instructions!P1,4) -> Enter each tax settlement received July 1, 2011 through June 30, 2012
A21: Enter data in green highlighted cells
A22: If more columns are needed, insert between column M and S
A23: Amounts will be allocated to funds based upon certified levies above
A24: Settlements will be totaled by year and fund for carryover to Accounts tab
A26: If settlement sheet from the county already shows settlements by fund:
A27: Unprotect this tab and enter settlement data directly into cells E56 through S145, orange outlined section below
A28: Caution: You will be overriding the formulas in these cells
E32: County | F32: County | G32: County | H32: County | I32: County | J32: County | K32: County | L32: County | M32: County | N32: County | O32: County | P32: County | Q32: County | R32: County | S32: County
D33: Total | E33: Date | F33: Date | G33: Date | H33: Date | I33: Date | J33: Date | K33: Date | L33: Date | M33: Date | N33: Date | O33: Date | P33: Date | Q33: Date | R33: Date | S33: Date
A35: Taxes receivable | C35: =Instructions!P1 -> Pay 2012 | D35: =SUM(E35:S35) -> 0 | E35: 0 | F35: 0 | G35: 0 | H35: 0 | I35: 0 | J35: 0 | K35: 0 | L35: 0 | M35: 0 | N35: 0 | O35: 0 | P35: 0 | Q35: 0 | R35: 0 | S35: 0
C36: =Instructions!P2 -> Pay 2011 | D36: =SUM(E36:S36) -> 0 | E36: 0 | F36: 0 | G36: 0 | H36: 0 | I36: 0 | J36: 0 | K36: 0 | L36: 0 | M36: 0 | N36: 0 | O36: 0 | P36: 0 | Q36: 0 | R36: 0 | S36: 0
C37: =Instructions!P3 -> Pay 2010 | D37: =SUM(E37:S37) -> 0 | E37: 0 | F37: 0 | G37: 0 | H37: 0 | I37: 0 | J37: 0 | K37: 0 | L37: 0 | M37: 0 | N37: 0 | O37: 0 | P37: 0 | Q37: 0 | R37: 0 | S37: 0
C38: =Instructions!P4 -> Pay 2009 | D38: =SUM(E38:S38) -> 0 | E38: 0 | F38: 0 | G38: 0 | H38: 0 | I38: 0 | J38: 0 | K38: 0 | L38: 0 | M38: 0 | N38: 0 | O38: 0 | P38: 0 | Q38: 0 | R38: 0 | S38: 0
C39: =Instructions!P5 -> Pay 2008 | D39: =SUM(E39:S39) -> 0 | E39: 0 | F39: 0 | G39: 0 | H39: 0 | I39: 0 | J39: 0 | K39: 0 | L39: 0 | M39: 0 | N39: 0 | O39: 0 | P39: 0 | Q39: 0 | R39: 0 | S39: 0
C40: =Instructions!P6 -> Pay 2007 | D40: =SUM(E40:S40) -> 0 | E40: 0 | F40: 0 | G40: 0 | H40: 0 | I40: 0 | J40: 0 | K40: 0 | L40: 0 | M40: 0 | N40: 0 | O40: 0 | P40: 0 | Q40: 0 | R40: 0 | S40: 0
C41: =Instructions!P7 -> Pay 2006 | D41: =SUM(E41:S41) -> 0 | E41: 0 | F41: 0 | G41: 0 | H41: 0 | I41: 0 | J41: 0 | K41: 0 | L41: 0 | M41: 0 | N41: 0 | O41: 0 | P41: 0 | Q41: 0 | R41: 0 | S41: 0
C42: =Instructions!P8 -> Pay 2005 | D42: =SUM(E42:S42) -> 0 | E42: 0 | F42: 0 | G42: 0 | H42: 0 | I42: 0 | J42: 0 | K42: 0 | L42: 0 | M42: 0 | N42: 0 | O42: 0 | P42: 0 | Q42: 0 | R42: 0 | S42: 0
A43: Fiscal disparities | C43: =Instructions!P1 -> Pay 2012 | D43: =SUM(E43:S43) -> 0 | E43: 0 | F43: 0 | G43: 0 | H43: 0 | I43: 0 | J43: 0 | K43: 0 | L43: 0 | M43: 0 | N43: 0 | O43: 0 | P43: 0 | Q43: 0 | R43: 0 | S43: 0
C44: =Instructions!P2 -> Pay 2011 | D44: =SUM(E44:S44) -> 0 | E44: 0 | F44: 0 | G44: 0 | H44: 0 | I44: 0 | J44: 0 | K44: 0 | L44: 0 | M44: 0 | N44: 0 | O44: 0 | P44: 0 | Q44: 0 | R44: 0 | S44: 0
A45: Taconite homestead | C45: =Instructions!P1 -> Pay 2012 | D45: =SUM(E45:S45) -> 0 | E45: 0 | F45: 0 | G45: 0 | H45: 0 | I45: 0 | J45: 0 | K45: 0 | L45: 0 | M45: 0 | N45: 0 | O45: 0 | P45: 0 | Q45: 0 | R45: 0 | S45: 0
C46: =Instructions!P2 -> Pay 2011 | D46: =SUM(E46:S46) -> 0 | E46: 0 | F46: 0 | G46: 0 | H46: 0 | I46: 0 | J46: 0 | K46: 0 | L46: 0 | M46: 0 | N46: 0 | O46: 0 | P46: 0 | Q46: 0 | R46: 0 | S46: 0
A47: Miscellaneous taxes | E47: 0 | F47: 0 | G47: 0 | H47: 0 | I47: 0 | J47: 0 | K47: 0 | L47: 0 | M47: 0 | N47: 0 | O47: 0 | P47: 0 | Q47: 0 | R47: 0 | S47: 0
B49: Total settlement | D49: =SUM(D35:D48) -> 0 | E49: =SUM(E35:E48) -> 0 | F49: =SUM(F35:F48) -> 0 | G49: =SUM(G35:G48) -> 0 | H49: =SUM(H35:H48) -> 0 | I49: =SUM(I35:I48) -> 0 | J49: =SUM(J35:J48) -> 0 | K49: =SUM(K35:K48) -> 0 | ... S49: =SUM(S35:S48) -> 0
A55: Current Taxes receivable
B56: =Instructions!P1 -> Pay 2012 | C56: General | D56: =SUM(E56:S56) -> 0 | E56: =ROUND(IF($D$14=0,0,E$35/$D$14*$D9),2) -> 0 | F56: =ROUND(IF($D$14=0,0,F$35/$D$14*$D9),2) -> 0 | G56: =ROUND(IF($D$14=0,0,G$35/$D$14*$D9),2) -> 0 | H56: =ROUND(IF($D$14=0,0,H$35/$D$14*$D9),2) -> 0 | I56: =ROUND(IF($D$14=0,0,I$35/$D$14*$D9),2) -> 0 | J56: =ROUND(IF($D$14=0,0,J$35/$D$14*$D9),2) -> 0 | K56: =ROUND(IF($D$14=0,0,K$35/$D$14*$D9),2) -> 0 | L56: =ROUND(IF($D$14=0,0,L$35/$D$14*$D9),2) -> 0 | ... S56: =ROUND(IF($D$14=0,0,S$35/$D$14*$D9),2) -> 0
B57: =Instructions!P1 -> Pay 2012 | C57: Comm Serv | D57: =SUM(E57:S57) -> 0 | E57: =ROUND(IF($D$14=0,0,E$35/$D$14*$D10),2) -> 0 | F57: =ROUND(IF($D$14=0,0,F$35/$D$14*$D10),2) -> 0 | G57: =ROUND(IF($D$14=0,0,G$35/$D$14*$D10),2) -> 0 | H57: =ROUND(IF($D$14=0,0,H$35/$D$14*$D10),2) -> 0 | I57: =ROUND(IF($D$14=0,0,I$35/$D$14*$D10),2) -> 0 | J57: =ROUND(IF($D$14=0,0,J$35/$D$14*$D10),2) -> 0 | K57: =ROUND(IF($D$14=0,0,K$35/$D$14*$D10),2) -> 0 | L57: =ROUND(IF($D$14=0,0,L$35/$D$14*$D10),2) -> 0 | ... S57: =ROUND(IF($D$14=0,0,S$35/$D$14*$D10),2) -> 0
B58: =Instructions!P1 -> Pay 2012 | C58: Debt Serv | D58: =SUM(E58:S58) -> 0 | E58: =ROUND(IF($D$14=0,0,E$35/$D$14*$D11),2) -> 0 | F58: =ROUND(IF($D$14=0,0,F$35/$D$14*$D11),2) -> 0 | G58: =ROUND(IF($D$14=0,0,G$35/$D$14*$D11),2) -> 0 | H58: =ROUND(IF($D$14=0,0,H$35/$D$14*$D11),2) -> 0 | I58: =ROUND(IF($D$14=0,0,I$35/$D$14*$D11),2) -> 0 | J58: =ROUND(IF($D$14=0,0,J$35/$D$14*$D11),2) -> 0 | K58: =ROUND(IF($D$14=0,0,K$35/$D$14*$D11),2) -> 0 | L58: =ROUND(IF($D$14=0,0,L$35/$D$14*$D11),2) -> 0 | ... S58: =ROUND(IF($D$14=0,0,S$35/$D$14*$D11),2) -> 0
B59: =Instructions!P1 -> Pay 2012 | C59: OPEB | D59: =SUM(E59:S59) -> 0 | E59: =ROUND(IF($D$14=0,0,E$35/$D$14*$D12),2) -> 0 | F59: =ROUND(IF($D$14=0,0,F$35/$D$14*$D12),2) -> 0 | G59: =ROUND(IF($D$14=0,0,G$35/$D$14*$D12),2) -> 0 | H59: =ROUND(IF($D$14=0,0,H$35/$D$14*$D12),2) -> 0 | I59: =ROUND(IF($D$14=0,0,I$35/$D$14*$D12),2) -> 0 | J59: =ROUND(IF($D$14=0,0,J$35/$D$14*$D12),2) -> 0 | K59: =ROUND(IF($D$14=0,0,K$35/$D$14*$D12),2) -> 0 | L59: =ROUND(IF($D$14=0,0,L$35/$D$14*$D12),2) -> 0 | ... S59: =ROUND(IF($D$14=0,0,S$35/$D$14*$D12),2) -> 0
C61: Subtotal | D61: =SUM(D56:D60) -> 0 | E61: =SUM(E56:E60) -> 0 | F61: =SUM(F56:F60) -> 0 | G61: =SUM(G56:G60) -> 0 | H61: =SUM(H56:H60) -> 0 | I61: =SUM(I56:I60) -> 0 | J61: =SUM(J56:J60) -> 0 | K61: =SUM(K56:K60) -> 0 | ... S61: =SUM(S56:S60) -> 0
...

Sheet Accounts
A1: Reconciation of Property Tax Accounts | I1: =Report!A3 -> 1.2 | J1: =Report!B5 -> MINNEAPOLIS | L1: =Report!I1 -> 41115 | N1: Note:
N2: Account balances are indicated as debit or (credit) balance
A3: On Reports tab enter your district # in cell A3 so correct tax shift amounts carryover | N3: Asset and expenditure accounts would normally have a debit balance
A4: Data entered on Funds tab will carryover and be used to allocate adjustments and abatements | N4: Liability and revenue accounts would normally have a credit balance
A5: On this tab enter data in highlighted fields only--from source indicated | N5: See comments by accounts GNL 214 and SRC 020 and 299
A6: All other fields will compute, including those that come from the Tax Shift spreadsheet
A7: Enter debits as positive and credits as negative, as indicated in column H | I7: General | J7: Comm Serv | K7: Debt | L7: Debt | M7: Total
I8: Debit (Credit) | J8: Debit (Credit) | K8: Debit (Credit) | L8: Debit (Credit) | M8: Debit (Credit)
A10: Balance Sheet Acccounts:
A12: =Instructions!P1&" Certified Levy" -> Pay 2012 Certified Levy | H12: Debit | I12: =Funds!D9 -> 0 | J12: =Funds!D10 -> 0 | K12: =Funds!D11 -> 0 | L12: =Funds!D12 -> 0 | M12: =SUM(I12:L12) -> 0 | N12: Levy Limitation & Certification Report
A13: ="Tax settlements "&Instructions!T4&" for "&Instructions!P1&" levy" -> Tax settlements 05/01/2012 to 06/30/2012 for Pay 2012 levy | H13: (Credit) | I13: =-Funds!D56 -> 0 | J13: =-Funds!D57 -> 0 | K13: =-Funds!D58 -> 0 | L13: =-Funds!D59 -> 0 | M13: =SUM(I13:L13) -> 0 | N13: ="Tax Settlement Reports (Form 52) "&Instructions!T2 -> Tax Settlement Reports (Form 52) 07/01/2011 to 06/30/2012
A14: ="Tax settlements Fiscal disparities "&Instructions!T4&" for "&Instructions!P1&" levy" -> Tax settlements Fiscal disparities 05/01/2012 to 06/30/2012 for Pay 2012 levy | H14: (Credit) | I14: =-Funds!D110 -> 0 | J14: =-Funds!D111 -> 0 | K14: =-Funds!D112 -> 0 | L14: =-Funds!D113 -> 0 | M14: =SUM(I14:L14) -> 0 | N14: ="Tax Settlement Reports (Form 52) "&Instructions!T2 -> Tax Settlement Reports (Form 52) 07/01/2011 to 06/30/2012
A15: ="Tax settlements Taconite homestead credit "&Instructions!T4&" for "&Instructions!P1&" levy" -> Tax settlements Taconite homestead credit 05/01/2012 to 06/30/2012 for Pay 2012 levy | H15: (Credit) | I15: =-Funds!D128 -> 0 | J15: =-Funds!D129 -> 0 | K15: =-Funds!D130 -> 0 | L15: =-Funds!D131 -> 0 | M15: =SUM(I15:L15) -> 0 | N15: ="Tax Settlement Reports (Form 52) "&Instructions!T2 -> Tax Settlement Reports (Form 52) 07/01/2011 to 06/30/2012
A16: (Do not include any July payments)
B18: ="10 Taxes Receivable--Current "&Instructions!S2 -> 10 Taxes Receivable--Current 06/30/12 | I18: =SUM(I12:I16) -> 0 | J18: =SUM(J12:J16) -> 0 | K18: =SUM(K12:K16) -> 0 | L18: =SUM(L12:L16) -> 0
A22: ="Delinquent Taxes Receivable "&Instructions!S3 -> Delinquent Taxes Receivable 06/30/11 | H22: Debit | I22: 0 | J22: 0 | K22: 0 | L22: 0 | M22: =SUM(I22:L22) -> 0 | N22: ="General Ledger "&Instructions!S3 -> General Ledger 06/30/11
A23: ="Current Taxes Receivable "&Instructions!S3 -> Current Taxes Receivable 06/30/11 | H23: Debit | I23: 0 | J23: 0 | K23: 0 | L23: 0 | M23: =SUM(I23:L23) -> 0 | N23: ="General Ledger "&Instructions!S3 -> General Ledger 06/30/11
A24: ="Increase (decrease) to "&Instructions!P2&" levy by county" -> Increase (decrease) to Pay 2011 levy by county | H24: Debit (Credit) | I24: =ROUND(IF(M24=0,0,Funds!E9/Funds!E14*M24),2) -> 0 | J24: =ROUND(IF(M24=0,0,Funds!E10/Funds!E14*M24),2) -> 0 | K24: =ROUND(IF(M24=0,0,Funds!E11/Funds!E14*M24),2) -> 0 | L24: =ROUND(IF(M24=0,0,Funds!E12/Funds!E14*M24),2) -> 0 | M24: 0 | N24: Taxes Receivable Report (Form 51)
A25: ="Increase (decrease) to "&Instructions!P3&" levy by county" -> Increase (decrease) to Pay 2010 levy by county | H25: Debit (Credit) | I25: =ROUND(IF($M$25=0,0,Funds!F9/Funds!$F$14*$M$25),2) -> 0 | J25: =ROUND(IF($M$25=0,0,Funds!F10/Funds!$F$14*$M$25),2) -> 0 | K25: =ROUND(IF($M$25=0,0,Funds!F11/Funds!$F$14*$M$25),2) -> 0 | L25: =ROUND(IF($M$25=0,0,Funds!F12/Funds!$F$14*$M$25),2) -> 0 | M25: 0 | N25: Taxes Receivable Report (Form 51)
A26: ="Education Homestead Market Value Credit for "&Instructions!R2 -> Education Homestead Market Value Credit for FY 2012 | H26: (Credit) | I26: 0 | J26: 0 | K26: 0 | L26: 0 | M26: =SUM(I26:L26) -> 0 | N26: Report of Credits from Dept of Revenue
A27: ="Agricultural Educ Homestead Market Value Credit for "&Instructions!R2 -> Agricultural Educ Homestead Market Value Credit for FY 2012 | H27: (Credit) | I27: 0 | J27: 0 | K27: 0 | L27: 0 | M27: =SUM(I27:L27) -> 0 | N27: Report of Credits from Dept of Revenue
A28: ="Other credits for "&Instructions!R2 -> Other credits for FY 2012 | H28: (Credit) | I28: 0 | J28: 0 | K28: 0 | L28: 0 | M28: =SUM(I28:L28) -> 0 | N28: Report of Credits from Dept of Revenue
A29: ="Disparity Aid adjustments for "&Instructions!R2 -> Disparity Aid adjustments for FY 2012 | H29: (Credit) | I29: 0 | J29: 0 | K29: 0 | L29: 0 | M29: =SUM(I29:L29) -> 0 | N29: Report of Credits from Dept of Revenue
A30: ="Decrease (increase) to credits by county" -> Decrease (increase) to credits by county | H30: Debit (Credit) | I30: =ROUND(IF(Funds!$E$14=0,0,Funds!E9/Funds!$E$14*$M$30),2) -> 0 | J30: =ROUND(IF(Funds!$E$14=0,0,Funds!E10/Funds!$E$14*$M$30),2) -> 0 | K30: =ROUND(IF(Funds!$E$14=0,0,Funds!E11/Funds!$E$14*$M$30),2) -> 0 | L30: =ROUND(IF(Funds!$E$14=0,0,Funds!E12/Funds!$E$14*$M$30),2) -> 0 | M30: 0 | N30: Credits on Taxes receivable minus credits from Revenue
A31: ="Abatements "&Instructions!T2&" for "&Instructions!P2&" levy" -> Abatements 07/01/2011 to 06/30/2012 for Pay 2011 levy | H31: (Credit) | I31: =ROUND(IF(Funds!$E$14=0,0,Funds!E9/Funds!$E$14*$M$31),2) -> 0 | J31: =ROUND(IF(Funds!$E$14=0,0,Funds!E10/Funds!$E$14*$M$31),2) -> 0 | K31: =ROUND(IF(Funds!$E$14=0,0,Funds!E11/Funds!$E$14*$M$31),2) -> 0 | L31: =ROUND(IF(Funds!$E$14=0,0,Funds!E12/Funds!$E$14*$M$31),2) -> 0 | M31: 0 | N31: Taxes Receivable Report (Form 51)
A32: ="Abatements "&Instructions!T2&" for "&Instructions!P3&" levy" -> Abatements 07/01/2011 to 06/30/2012 for Pay 2010 levy | H32: (Credit) | I32: =ROUND(IF(Funds!$F$14=0,0,Funds!F9/Funds!$F$14*$M$32),2) -> 0 | J32: =ROUND(IF(Funds!$F$14=0,0,Funds!F10/Funds!$F$14*$M$32),2) -> 0 | K32: =ROUND(IF(Funds!$F$14=0,0,Funds!F11/Funds!$F$14*$M$32),2) -> 0 | L32: =ROUND(IF(Funds!$F$14=0,0,Funds!F12/Funds!$F$14*$M$32),2) -> 0 | M32: 0 | N32: Taxes Receivable Report (Form 51)
A33: ="Abatements "&Instructions!T2&" for "&Instructions!P4&" levy" -> Abatements 07/01/2011 to 06/30/2012 for Pay 2009 levy | H33: (Credit) | I33: =ROUND(IF(Funds!$G$14=0,0,Funds!G9/Funds!$G$14*$M$33),2) -> 0 | J33: =ROUND(IF(Funds!$G$14=0,0,Funds!G10/Funds!$G$14*$M$33),2) -> 0 | K33: =ROUND(IF(Funds!$G$14=0,0,Funds!G11/Funds!$G$14*$M$33),2) -> 0 | L33: =ROUND(IF(Funds!$G$14=0,0,Funds!G12/Funds!$G$14*$M$33),2) -> 0 | M33: 0 | N33: Taxes Receivable Report (Form 51)
A34: ="Abatements "&Instructions!T2&" for "&Instructions!P5&" levy" -> Abatements 07/01/2011 to 06/30/2012 for Pay 2008 levy | H34: (Credit) | I34: =ROUND(IF(Funds!$H$14=0,0,Funds!H9/Funds!$H$14*$M$34),2) -> 0 | J34: =ROUND(IF(Funds!$H$14=0,0,Funds!H10/Funds!$H$14*$M$34),2) -> 0 | K34: =ROUND(IF(Funds!$H$14=0,0,Funds!H11/Funds!$H$14*$M$34),2) -> 0 | L34: =ROUND(IF(Funds!$H$14=0,0,Funds!H12/Funds!$H$14*$M$34),2) -> 0 | M34: 0 | N34: Taxes Receivable Report (Form 51)
A35: ="Abatements "&Instructions!T2&" for "&Instructions!P6&" levy" -> Abatements 07/01/2011 to 06/30/2012 for Pay 2007 levy | H35: (Credit) | I35: =ROUND(IF(Funds!$I$14=0,0,Funds!I9/Funds!$I$14*$M$35),2) -> 0 | J35: =ROUND(IF(Funds!$I$14=0,0,Funds!I10/Funds!$I$14*$M$35),2) -> 0 | K35: =ROUND(IF(Funds!$I$14=0,0,Funds!I11/Funds!$I$14*$M$35),2) -> 0 | L35: =ROUND(IF(Funds!$I$14=0,0,Funds!I12/Funds!$I$14*$M$35),2) -> 0 | M35: 0 | N35: Taxes Receivable Report (Form 51)
A36: ="Abatements "&Instructions!T2&" for "&Instructions!P7&" levy" -> Abatements 07/01/2011 to 06/30/2012 for Pay 2006 levy | H36: (Credit) | I36: =ROUND(IF(Funds!$J$14=0,0,Funds!J9/Funds!$J$14*$M$36),2) -> 0 | J36: =ROUND(IF(Funds!$J$14=0,0,Funds!J10/Funds!$J$14*$M$36),2) -> 0 | K36: =ROUND(IF(Funds!$J$14=0,0,Funds!J11/Funds!$J$14*$M$36),2) -> 0 | L36: =ROUND(IF(Funds!$J$14=0,0,Funds!J12/Funds!$J$14*$M$36),2) -> 0 | M36: 0 | N36: Taxes Receivable Report (Form 51)
A37: ="Abatements "&Instructions!T2&" for "&Instructions!P8&" levy" -> Abatements 07/01/2011 to 06/30/2012 for Pay 2005 levy | H37: (Credit) | I37: =ROUND(IF(Funds!$K$14=0,0,Funds!K9/Funds!$K$14*$M$37),2) -> 0 | J37: =ROUND(IF(Funds!$K$14=0,0,Funds!K10/Funds!$K$14*$M$37),2) -> 0 | K37: =ROUND(IF(Funds!$K$14=0,0,Funds!K11/Funds!$K$14*$M$37),2) -> 0 | L37: =ROUND(IF(Funds!$K$14=0,0,Funds!K12/Funds!$K$14*$M$37),2) -> 0 | M37: 0 | N37: Taxes Receivable Report (Form 51)
A38: ="Write off "&Instructions!P8&" delinquent taxes negative (positive) balance due" -> Write off Pay 2005 delinquent taxes negative (positive) balance due | H38: Debit (Credit) | I38: =ROUND(IF(Funds!$K$14=0,0,Funds!K9/Funds!$K$14*$M$38),2) -> 0 | J38: =ROUND(IF(Funds!$K$14=0,0,Funds!K10/Funds!$K$14*$M$38),2) -> 0 | K38: =ROUND(IF(Funds!$K$14=0,0,Funds!K11/Funds!$K$14*$M$38),2) -> 0 | L38: =ROUND(IF(Funds!$K$14=0,0,Funds!K12/Funds!$K$14*$M$38),2) -> 0 | M38: 0 | N38: Taxes Receivable Report (Form 51)
A39: ="Tax settlements "&Instructions!T2&" for "&Instructions!P2&" and prior levies" -> Tax settlements 07/01/2011 to 06/30/2012 for Pay 2011 and prior levies | H39: (Credit) | I39: =-Funds!D73 -> 0 | J39: =-Funds!D84 -> 0 | K39: =-Funds!D95 -> 0 | L39: =-Funds!D106 -> 0 | M39: =SUM(I39:L39) -> 0 | N39: ="Tax Settlement Reports (Form 52) "&Instructions!T2 -> Tax Settlement Reports (Form 52) 07/01/2011 to 06/30/2012
A40: ="Tax settlements Fiscal Disparities "&Instructions!T3&" for "&Instructions!P2 -> Tax settlements Fiscal Disparities 07/01/2011 to 04/30/2012 for Pay 2011 | H40: (Credit) | I40: =-Funds!D119 -> 0 | J40: =-Funds!D120 -> 0 | K40: =-Funds!D121 -> 0 | L40: =-Funds!D122 -> 0 | M40: =SUM(I40:L40) -> 0 | N40: ="Tax Settlement Reports (Form 52) "&Instructions!T2 -> Tax Settlement Reports (Form 52) 07/01/2011 to 06/30/2012
A41: ="Tax settlements Taconite homestead credit "&Instructions!T3&" for "&Instructions!P2 -> Tax settlements Taconite homestead credit 07/01/2011 to 04/30/2012 for Pay 2011 | H41: (Credit) | I41: =-Funds!D137 -> 0 | J41: =-Funds!D138 -> 0 | K41: =-Funds!D139 -> 0 | L41: =-Funds!D140 -> 0 | M41: =SUM(I41:L41) -> 0 | N41: ="Tax Settlement Reports (Form 52) "&Instructions!T2 -> Tax Settlement Reports (Form 52) 07/01/2011 to 06/30/2012
B43: ="111 Delinquent Taxes Receivable "&Instructions!S2 -> 111 Delinquent Taxes Receivable 06/30/12 | I43: =SUM(I22:I41) -> 0 | J43: =SUM(J22:J41) -> 0 | K43: =SUM(K22:K41) -> 0 | L43: =SUM(L22:L41) -> 0
A47: Year end receivable (payable) adjustment for property tax shift | H47: (Credit) | I47: =Report!I18 -> 400016.66 | J47: =Report!I23 -> -400634.03 | M47: =SUM(I47:L47) -> -617.37 | N47: Tax Shift Report (column 6)
B49: ="213 Property Tax Shift Adjustment "&Instructions!S2 -> 213 Property Tax Shift Adjustment 06/30/12 | I49: =I47 -> 400016.66 | J49: =J47 -> -400634.03
A53: Amount by which tax shift exceeds property tax receipts | H53: Debit | I53: =Report!E108 -> 4917530 | J53: =Report!E110 -> 0 | M53: =SUM(I53:L53) -> 4917530 | N53: Tax Shift Entry
B55: ="214 Advance of Unearned General Education Aid "&Instructions!S2 -> 214 Advance of Unearned General Education Aid 06/30/12 | I55: =SUM(I53:I54) -> 4917530 | J55: =SUM(J53:J54) -> 0
...

Sheet Entries
A1: Entries to record property taxes | I1: =Report!I1 -> 41115
A4: Jan 1 | B4: Debit | C4: GL 110 | D4: Current Taxes Receivable
B5: Credit | C5: GL 235 | D5: Deferred Revenue
C7: To record current year levy as taxes receivable
A10: Jan 1 | B10: Debit | C10: GL 111 | D10: Delinquent Taxes Receivable
B11: Credit | C11: GL 110 | D11: Current Taxes Receivable
C13: To transfer current taxes receivable to delinquent taxes
A16: Jan - July | B16: Debit | C16: GL 101 | D16: Cash
B17: Credit | C17: GL 110 | D17: Current Taxes Receivable
B18: Credit | C18: GL 111 | D18: Delinquent Taxes Receivable
B19: Credit | C19: SRC 009 | D19: Fiscal Disparities
B20: Credit | C20: SRC 014 | D20: Taconite Homestead Credit
B21: Credit | C21: SRC 019 | D21: Miscellaneous tax revenue
C23: To record first half tax settlements received from counties
A26: June 30 | B26: Debit | C26: GL 235 | D26: Deferred Revenue
B27: Debit | C27: GL 214 | D27: Advance of Unearned Gened
B28: Credit | C28: SRC 001 | D28: Tax Revenue
B29: Credit | C29: SRC 211 | D29: Tax Revenue (Portions with Finance Codes)
C31: To record current year tax shift
B34: Note: Property tax shift entry shown on "Report" tab combines the June 30th entry to record the current year tax shift (entry just above this note) with the prior July 1st entry to reverse the prior year tax shift (entry similar to entry below, but for the previous July 1st).
A39: July 1 | B39: Debit | C39: SRC 001 | D39: Tax Revenue
B40: Debit | C40: SRC 211 | D40: Tax Revenue (Portions with Finance Codes)
B41: Credit | C41: GL 235 | D41: Deferred Revenue
B42: Debit | C42: GL 214 | D42: Advance of Unearned Gened
C44: To reverse prior year tax shift
A47: July 1 | B47: Debit | C47: GL 235 | D47: Deferred Revenue
B48: Credit | C48: SRC 001 | D48: Tax Revenue
B49: Credit | C49: SRC 001 | D49: Tax Revenue (Portions with Finance Codes)
C51: To record levy revenue for current year
A54: July 1 | B54: Debit | C54: SRC 001 | D54: Tax Revenue
B55: Credit | C55: GL 110 | D55: Current Taxes Receivable
C57: To reduce taxes receivable for amount to be paid by state credits
A60: July 1 | B60: Debit | C60: SRC 001 | D60: Tax Revenue
B61: Credit | C61: GL 110 | D61: Current Taxes Receivable
C63: To reduce taxes receivable for amount to be paid by fiscal disparities
A66: July 1 | B66: Debit | C66: SRC 001 | D66: Tax Revenue
B67: Credit | C67: GL 110 | D67: Current Taxes Receivable
C69: To reduce taxes receivable for amount to be paid by taconite homestead credit
A72: July 1 | B72: Debit/Credit | C72: SRC 001 | D72: Tax Revenue
B73: Credit/Debit | C73: GL 110 | D73: Current Taxes Receivable
...

Sheet Aid Adjust
A1: =Instructions!R2&" Aid Payment (Reduction)" -> FY 2012 Aid Payment (Reduction) | H1: =Report!I1 -> 41115
A2: Positve amount indicates state aid payment
A3: Negative amount indicates reduction to state aid payments
A4: File created from LEVY run under S:\common\TAXSHIFT
D6: General Shift Aid Adjust | E6: Refer Aid Adjust | F6: Total General Aid Adjust | G6: Comm Serv Aid Adjust | H6: Total Aid Adjust
D7: -2.4734801e+08 | E7: -2.455034e+08 | F7: -4.9285142e+08 | G7: -35601749 | H7: -5.2845317e+08
C8: State Total | D8: =SUM(D10:D346) -> 5693766.1 | E8: =SUM(E10:E346) -> -14304632 | F8: =SUM(F10:F346) -> -8610866.3 | G8: =SUM(G10:G346) -> -204065.21 | H8: =SUM(H10:H346) -> -8814931.5
A10: 1 | B10: 1 | C10: AITKIN | D10: =Shift10!D8-Shift11!D8 -> 16354.58 | E10: =Shift10!E8-Shift11!E8 -> 0 | F10: =D10+E10 -> 16354.58 | G10: =Shift10!M8-Shift11!M8 -> 1607.39 | H10: =SUM(F10:G10) -> 17961.97
A11: 1.2 | B11: 3 | C11: MINNEAPOLIS | D11: =Shift10!D9-Shift11!D9 -> 3012712.2 | E11: =Shift10!E9-Shift11!E9 -> -908784.28 | F11: =D11+E11 -> 2103927.9 | G11: =Shift10!M9-Shift11!M9 -> -400634.03 | H11: =SUM(F11:G11) -> 1703293.9
A12: 2 | B12: 1 | C12: HILL CITY | D12: =Shift10!D10-Shift11!D10 -> -13585.7 | E12: =Shift10!E10-Shift11!E10 -> 0 | F12: =D12+E12 -> -13585.7 | G12: =Shift10!M10-Shift11!M10 -> -513.56 | H12: =SUM(F12:G12) -> -14099.26
A13: 4 | B13: 1 | C13: MCGREGOR | D13: =Shift10!D11-Shift11!D11 -> 87838.48 | E13: =Shift10!E11-Shift11!E11 -> 0 | F13: =D13+E13 -> 87838.48 | G13: =Shift10!M11-Shift11!M11 -> -2248.69 | H13: =SUM(F13:G13) -> 85589.79
A14: 6 | B14: 3 | C14: SOUTH ST. PAUL | D14: =Shift10!D12-Shift11!D12 -> -41697.78 | E14: =Shift10!E12-Shift11!E12 -> 103641.93 | F14: =D14+E14 -> 61944.15 | G14: =Shift10!M12-Shift11!M12 -> 999.22 | H14: =SUM(F14:G14) -> 62943.37
A15: 11 | B15: 1 | C15: ANOKA-HENNEPIN | D15: =Shift10!D13-Shift11!D13 -> 2199107.6 | E15: =Shift10!E13-Shift11!E13 -> -308768.4 | F15: =D15+E15 -> 1890339.2 | G15: =Shift10!M13-Shift11!M13 -> 74704.46 | H15: =SUM(F15:G15) -> 1965043.6
A16: 12 | B16: 1 | C16: CENTENNIAL | D16: =Shift10!D14-Shift11!D14 -> -59835.09 | E16: =Shift10!E14-Shift11!E14 -> -681947.78 | F16: =D16+E16 -> -741782.87 | G16: =Shift10!M14-Shift11!M14 -> 13600.76 | H16: =SUM(F16:G16) -> -728182.11
A17: 13 | B17: 1 | C17: COLUMBIA HEIGHTS | D17: =Shift10!D15-Shift11!D15 -> -79953.98 | E17: =Shift10!E15-Shift11!E15 -> -61572.5 | F17: =D17+E17 -> -141526.48 | G17: =Shift10!M15-Shift11!M15 -> -15058.14 | H17: =SUM(F17:G17) -> -156584.62
A18: 14 | B18: 1 | C18: FRIDLEY | D18: =Shift10!D16-Shift11!D16 -> 131811.61 | E18: =Shift10!E16-Shift11!E16 -> 165458.17 | F18: =D18+E18 -> 297269.78 | G18: =Shift10!M16-Shift11!M16 -> -7198.51 | H18: =SUM(F18:G18) -> 290071.27
A19: 15 | B19: 1 | C19: ST. FRANCIS | D19: =Shift10!D17-Shift11!D17 -> 319097.01 | E19: =Shift10!E17-Shift11!E17 -> 121970.06 | F19: =D19+E19 -> 441067.07 | G19: =Shift10!M17-Shift11!M17 -> 24860.94 | H19: =SUM(F19:G19) -> 465928.01
A20: 16 | B20: 1 | C20: SPRING LAKE PARK | D20: =Shift10!D18-Shift11!D18 -> -135051.3 | E20: =Shift10!E18-Shift11!E18 -> -265551.43 | F20: =D20+E20 -> -400602.73 | G20: =Shift10!M18-Shift11!M18 -> -19103.36 | H20: =SUM(F20:G20) -> -419706.09
A21: 22 | B21: 1 | C21: DETROIT LAKES | D21: =Shift10!D19-Shift11!D19 -> 2216.84 | E21: =Shift10!E19-Shift11!E19 -> 7814.34 | F21: =D21+E21 -> 10031.18 | G21: =Shift10!M19-Shift11!M19 -> -5945.62 | H21: =SUM(F21:G21) -> 4085.56
... A346: 2904 | B346: 1 | C346: TRACY AREA | D346: =Shift10!D344-Shift11!D344 -> 23030.14 | E346: =Shift10!E344-Shift11!E344 -> -14354.01 | F346: =D346+E346 -> 8676.13 | G346: =Shift10!M344-Shift11!M344 -> 1736.97 | H346: =SUM(F346:G346) -> 10413.1

Sheet Shift11
A1: =Instructions!P1&" Gross Shift" -> Pay 2012 Gross Shift | Q1: =Report!I1 -> 41115
A3: Shift at | B3: 0.486
D4: Genl with Aid Adjust | E4: Refer with Aid Adjust | F4: Refer No Aid Adjust | G4: Addl Refer Shift | H4: Career Technical | I4: 100% Shift | J4: Reemploy Resv | K4: Reemploy Unrsv | L4: Leg Changes Genl Fund | M4: Comm Serv at Shift % | N4: Leg Changes Comm Serv | O4: Total Gross Shift | P4: Total General Fund Shift | Q4: Total Comm Serv Fund Shift
C6: State Total | D6: =SUM(D8:D344) -> 2.4165425e+08 | E6: =SUM(E8:E344) -> 2.5980804e+08 | F6: =SUM(F8:F344) -> 1.1422854e+08 | G6: =SUM(G8:G344) -> 4282529.2 | H6: =SUM(H8:H344) -> 17147576 | I6: =SUM(I8:I344) -> 28857584 | J6: =SUM(J8:J344) -> -139906.18 | K6: =SUM(K8:K344) -> 19088375 | ... Q6: =SUM(Q8:Q344) -> 35805814
A8: 1 | B8: 1 | C8: AITKIN | D8: =ROUND(Data!AA8*$B$3,2) -> 400273.22 | E8: =MAX(0,Data!AD8-Data!Y8) -> 0 | F8: =Data!Y8 -> 141143.88 | G8: =Data!X8 -> 0 | H8: =Data!K8+Data!R8 -> 29961.63 | I8: =Data!I8+Data!L8+Data!M8+Data!N8+Data!O8+Data!S8 -> 0 | J8: =Data!Q8 -> 0 | K8: =Data!J8+Data!P8 -> 1882.81 | L8: =Data!T8 -> 0 | M8: =ROUND(Data!AB8*$B$3,2) -> 897.18 | N8: =Data!U8 -> 0 | O8: =SUM(D8:N8) -> 574158.72 | P8: =SUM(D8:L8) -> 573261.54 | Q8: =SUM(M8:N8) -> 897.18
A9: 1.2 | B9: 3 | C9: MINNEAPOLIS | D9: =ROUND(Data!AA9*$B$3,2) -> 11569510 | E9: =MAX(0,Data!AD9-Data!Y9) -> 22730186 | F9: =Data!Y9 -> 10049626 | G9: =Data!X9 -> 1205612.7 | H9: =Data!K9+Data!R9 -> 551214.14 | I9: =Data!I9+Data!L9+Data!M9+Data!N9+Data!O9+Data!S9 -> 8657778.7 | J9: =Data!Q9 -> 0 | K9: =Data!J9+Data!P9 -> 1774703.8 | L9: =Data!T9 -> 0 | M9: =ROUND(Data!AB9*$B$3,2) -> 2395202 | N9: =Data!U9 -> 0 | O9: =SUM(D9:N9) -> 58933834 | P9: =SUM(D9:L9) -> 56538632 | Q9: =SUM(M9:N9) -> 2395202
A10: 2 | B10: 1 | C10: HILL CITY | D10: =ROUND(Data!AA10*$B$3,2) -> 60705.45 | E10: =MAX(0,Data!AD10-Data!Y10) -> 0 | F10: =Data!Y10 -> 0 | G10: =Data!X10 -> 0 | H10: =Data!K10+Data!R10 -> 10000 | I10: =Data!I10+Data!L10+Data!M10+Data!N10+Data!O10+Data!S10 -> 0 | J10: =Data!Q10 -> 0 | K10: =Data!J10+Data!P10 -> 16031.66 | L10: =Data!T10 -> 0 | M10: =ROUND(Data!AB10*$B$3,2) -> 9705.42 | N10: =Data!U10 -> 0 | O10: =SUM(D10:N10) -> 96442.53 | P10: =SUM(D10:L10) -> 86737.11 | Q10: =SUM(M10:N10) -> 9705.42
A11: 4 | B11: 1 | C11: MCGREGOR | D11: =ROUND(Data!AA11*$B$3,2) -> 84723.02 | E11: =MAX(0,Data!AD11-Data!Y11) -> 0 | F11: =Data!Y11 -> 51784.65 | G11: =Data!X11 -> 0 | H11: =Data!K11+Data!R11 -> 11665.08 | I11: =Data!I11+Data!L11+Data!M11+Data!N11+Data!O11+Data!S11 -> 0 | J11: =Data!Q11 -> 0 | K11: =Data!J11+Data!P11 -> -12981.29 | L11: =Data!T11 -> 0 | M11: =ROUND(Data!AB11*$B$3,2) -> 27577.1 | N11: =Data!U11 -> 0 | O11: =SUM(D11:N11) -> 162768.56 | P11: =SUM(D11:L11) -> 135191.46 | Q11: =SUM(M11:N11) -> 27577.1
A12: 6 | B12: 3 | C12: SOUTH ST. PAUL | D12: =ROUND(Data!AA12*$B$3,2) -> 1342633.1 | E12: =MAX(0,Data!AD12-Data!Y12) -> 1092426.5 | F12: =Data!Y12 -> 360711.07 | G12: =Data!X12 -> 0 | H12: =Data!K12+Data!R12 -> 70749.16 | I12: =Data!I12+Data!L12+Data!M12+Data!N12+Data!O12+Data!S12 -> 0 | J12: =Data!Q12 -> 0 | K12: =Data!J12+Data!P12 -> 60297.28 | L12: =Data!T12 -> 0 | M12: =ROUND(Data!AB12*$B$3,2) -> 145894.77 | N12: =Data!U12 -> 0 | O12: =SUM(D12:N12) -> 3072711.9 | P12: =SUM(D12:L12) -> 2926817.1 | Q12: =SUM(M12:N12) -> 145894.77
A13: 11 | B13: 1 | C13: ANOKA-HENNEPIN | D13: =ROUND(Data!AA13*$B$3,2) -> 9693090.9 | E13: =MAX(0,Data!AD13-Data!Y13) -> 21313952 | F13: =Data!Y13 -> 3515884.7 | G13: =Data!X13 -> 197692.1 | H13: =Data!K13+Data!R13 -> 939930.34 | I13: =Data!I13+Data!L13+Data!M13+Data!N13+Data!O13+Data!S13 -> 0 | J13: =Data!Q13 -> 0 | K13: =Data!J13+Data!P13 -> 805350.9 | L13: =Data!T13 -> 0 | M13: =ROUND(Data!AB13*$B$3,2) -> 1509866.1 | N13: =Data!U13 -> 0 | O13: =SUM(D13:N13) -> 37975767 | P13: =SUM(D13:L13) -> 36465901 | Q13: =SUM(M13:N13) -> 1509866.1
A14: 12 | B14: 1 | C14: CENTENNIAL | D14: =ROUND(Data!AA14*$B$3,2) -> 1629289.2 | E14: =MAX(0,Data!AD14-Data!Y14) -> 2426127.1 | F14: =Data!Y14 -> 320094.52 | G14: =Data!X14 -> 16533.75 | H14: =Data!K14+Data!R14 -> 115112.6 | I14: =Data!I14+Data!L14+Data!M14+Data!N14+Data!O14+Data!S14 -> 0 | J14: =Data!Q14 -> 0 | K14: =Data!J14+Data!P14 -> 121208.84 | L14: =Data!T14 -> 0 | M14: =ROUND(Data!AB14*$B$3,2) -> 211746.12 | N14: =Data!U14 -> 0 | O14: =SUM(D14:N14) -> 4840112.1 | P14: =SUM(D14:L14) -> 4628366 | Q14: =SUM(M14:N14) -> 211746.12
A15: 13 | B15: 1 | C15: COLUMBIA HEIGHTS | D15: =ROUND(Data!AA15*$B$3,2) -> 1036557.9 | E15: =MAX(0,Data!AD15-Data!Y15) -> 810891.79 | F15: =Data!Y15 -> 848958.71 | G15: =Data!X15 -> 0 | H15: =Data!K15+Data!R15 -> 63473.1 | I15: =Data!I15+Data!L15+Data!M15+Data!N15+Data!O15+Data!S15 -> 0 | J15: =Data!Q15 -> 0 | K15: =Data!J15+Data!P15 -> 32224.07 | L15: =Data!T15 -> 0 | M15: =ROUND(Data!AB15*$B$3,2) -> 154587.27 | N15: =Data!U15 -> 0 | O15: =SUM(D15:N15) -> 2946692.9 | P15: =SUM(D15:L15) -> 2792105.6 | Q15: =SUM(M15:N15) -> 154587.27
A16: 14 | B16: 1 | C16: FRIDLEY | D16: =ROUND(Data!AA16*$B$3,2) -> 1100248.8 | E16: =MAX(0,Data!AD16-Data!Y16) -> 752276.98 | F16: =Data!Y16 -> 468605.33 | G16: =Data!X16 -> 0 | H16: =Data!K16+Data!R16 -> 68582.56 | I16: =Data!I16+Data!L16+Data!M16+Data!N16+Data!O16+Data!S16 -> 0 | J16: =Data!Q16 -> 0 | K16: =Data!J16+Data!P16 -> 106303.92 | L16: =Data!T16 -> 0 | M16: =ROUND(Data!AB16*$B$3,2) -> 226560.16 | N16: =Data!U16 -> 0 | O16: =SUM(D16:N16) -> 2722577.7 | P16: =SUM(D16:L16) -> 2496017.5 | Q16: =SUM(M16:N16) -> 226560.16
A17: 15 | B17: 1 | C17: ST. FRANCIS | D17: =ROUND(Data!AA17*$B$3,2) -> 1089099.9 | E17: =MAX(0,Data!AD17-Data!Y17) -> 596767.85 | F17: =Data!Y17 -> 288492.79 | G17: =Data!X17 -> 0 | H17: =Data!K17+Data!R17 -> 125814.1 | I17: =Data!I17+Data!L17+Data!M17+Data!N17+Data!O17+Data!S17 -> 0 | J17: =Data!Q17 -> 0 | K17: =Data!J17+Data!P17 -> 323183.08 | L17: =Data!T17 -> 0 | M17: =ROUND(Data!AB17*$B$3,2) -> 170083.7 | N17: =Data!U17 -> 0 | O17: =SUM(D17:N17) -> 2593441.4 | P17: =SUM(D17:L17) -> 2423357.7 | Q17: =SUM(M17:N17) -> 170083.7
A18: 16 | B18: 1 | C18: SPRING LAKE PARK | D18: =ROUND(Data!AA18*$B$3,2) -> 2060036.8 | E18: =MAX(0,Data!AD18-Data!Y18) -> 1682306.2 | F18: =Data!Y18 -> 804793.86 | G18: =Data!X18 -> 73286.44 | H18: =Data!K18+Data!R18 -> 81433.57 | I18: =Data!I18+Data!L18+Data!M18+Data!N18+Data!O18+Data!S18 -> 0 | J18: =Data!Q18 -> 0 | K18: =Data!J18+Data!P18 -> 83924.13 | L18: =Data!T18 -> 0 | M18: =ROUND(Data!AB18*$B$3,2) -> 225326.21 | N18: =Data!U18 -> 0 | O18: =SUM(D18:N18) -> 5011107.2 | P18: =SUM(D18:L18) -> 4785781 | Q18: =SUM(M18:N18) -> 225326.21
A19: 22 | B19: 1 | C19: DETROIT LAKES | D19: =ROUND(Data!AA19*$B$3,2) -> 697179.97 | E19: =MAX(0,Data!AD19-Data!Y19) -> 516047.57 | F19: =Data!Y19 -> 133298.49 | G19: =Data!X19 -> 0 | H19: =Data!K19+Data!R19 -> 56261.09 | I19: =Data!I19+Data!L19+Data!M19+Data!N19+Data!O19+Data!S19 -> 0 | J19: =Data!Q19 -> 0 | K19: =Data!J19+Data!P19 -> 40886.23 | L19: =Data!T19 -> 0 | M19: =ROUND(Data!AB19*$B$3,2) -> 102490.6 | N19: =Data!U19 -> 0 | O19: =SUM(D19:N19) -> 1546164 | P19: =SUM(D19:L19) -> 1443673.4 | Q19: =SUM(M19:N19) -> 102490.6
... A344: 2904 | B344: 1 | C344: TRACY AREA | D344: =ROUND(Data!AA344*$B$3,2) -> 180455 | E344: =MAX(0,Data!AD344-Data!Y344) -> 173663.18 | F344: =Data!Y344 -> 99195.2 | G344: =Data!X344 -> 4004.21 | H344: =Data!K344+Data!R344 -> 20309.01 | I344: =Data!I344+Data!L344+Data!M344+Data!N344+Data!O344+Data!S344 -> 0 | J344: =Data!Q344 -> 0 | K344: =Data!J344+Data!P344 -> -6973.8 | L344: =Data!T344 -> 0 | M344: =ROUND(Data!AB344*$B$3,2) -> 34228.49 | N344: =Data!U344 -> 0 | O344: =SUM(D344:N344) -> 504881.29 | P344: =SUM(D344:L344) -> 470652.8 | Q344: =SUM(M344:N344) -> 34228.49

Sheet Data
A1: =Levy!A3 -> Pay 2012 Levy | AD1: =Report!I1 -> 41115
I3: From Certified Levy Summaries
D4: Genl RMV Voter | E4: Genl RMV Other | F4: Genl NTC Voter | G4: Genl NTC Other | H4: Comm Service | I4: Integ--1st Class | J4: Reemploy | K4: Career Technical | L4: Hea Ben | M4: Addl Retire | N4: Int Adj PY--1st Class | O4: Int Adj 2YP--1st Class | P4: Reemploy Adjust Unreserved | Q4: Reemploy Adjust Reserved | R4: Career Tech Adjust | S4: Hea Ben Adjust | T4: Legislative Changes Genl Fund | U4: Legislative Changes Comm Serv | V4: Prinsburg Exclusion RMV Voter | W4: Prinsburg Exclusion NTC Voter | X4: Add'l Referendum | Y4: Pay 2001 Refer Shift | Z4: 100% Shift Total | AA4: Shiftable Oth Gen (E+F+G-U-X-Y-AA) | AB4: Shiftable Comm Serv (H-T-V) | AC4: =Instructions!P1&" Refer at Shift Percent" -> Pay 2012 Refer at Shift Percent | AD4: ="Refer (GTR of "&Instructions!P1&" or Pay 2001)" -> Refer (GTR of Pay 2012 or Pay 2001)
AA5: 5.0894653e+08 | AB5: 73254628
C6: State Total | D6: =SUM(D8:D344) -> 7.6354564e+08 | E6: =SUM(E8:E344) -> 91927344 | F6: =SUM(F8:F344) -> 47134874 | G6: =SUM(G8:G344) -> 4.2705476e+08 | H6: =SUM(H8:H344) -> 73674515 | I6: =SUM(I8:I344) -> 12677369 | J6: =SUM(J8:J344) -> 12942173 | K6: =SUM(K8:K344) -> 17615396 | ... AD6: =SUM(AD8:AD344) -> 3.7403658e+08
A8: 1 | B8: 1 | C8: AITKIN | D8: =Levy!F8 -> 81.54 | E8: =Levy!G8 -> 352047.5 | F8: =Levy!H8 -> 0 | G8: =Levy!I8 -> 503404.39 | H8: =Levy!J8 -> 1846.04 | I8: 0 | J8: 5964 | K8: 30312.4 | L8: 0 | M8: 0 | N8: 0 | O8: 0 | P8: -4081.19 | Q8: 0 | R8: -350.77 | S8: 0 | T8: 0 | U8: 0 | V8: 0 | W8: 0 | X8: 0 | Y8: 141143.88 | Z8: =SUM(I8:T8) -> 31844.44 | AA8: =ROUND(MAX(E8+F8+G8-W8-X8-Z8,0),2) -> 823607.45 | AB8: =ROUND(MAX(H8-U8,0),2) -> 1846.04 | AC8: =ROUND(MAX(0,(D8-V8)*Shift11!$B$3),2) -> 39.63 | AD8: =MAX(AC8,Y8) -> 141143.88
A9: 1.2 | B9: 3 | C9: MINNEAPOLIS | D9: =Levy!F9 -> 67448174 | E9: =Levy!G9 -> 8500163.8 | F9: =Levy!H9 -> 0 | G9: =Levy!I9 -> 27494722 | H9: =Levy!J9 -> 4928399.1 | I9: 6300349.8 | J9: 1428745 | K9: 553068.44 | L9: 0 | M9: 2250000 | N9: 70370.65 | O9: 37058.2 | P9: 345958.81 | Q9: 0 | R9: -1854.3 | S9: 0 | T9: 0 | U9: 0 | V9: 0 | W9: 0 | X9: 1205612.7 | Y9: 10049626 | Z9: =SUM(I9:T9) -> 10983697 | AA9: =ROUND(MAX(E9+F9+G9-W9-X9-Z9,0),2) -> 23805577 | AB9: =ROUND(MAX(H9-U9,0),2) -> 4928399.1 | AC9: =ROUND(MAX(0,(D9-V9)*Shift11!$B$3),2) -> 32779812 | AD9: =MAX(AC9,Y9) -> 32779812
A10: 2 | B10: 1 | C10: HILL CITY | D10: =Levy!F10 -> 0 | E10: =Levy!G10 -> 33615 | F10: =Levy!H10 -> 0 | G10: =Levy!I10 -> 117325 | H10: =Levy!J10 -> 19970 | I10: 0 | J10: 15688.59 | K10: 10000 | L10: 0 | M10: 0 | N10: 0 | O10: 0 | P10: 343.07 | Q10: 0 | R10: 0 | S10: 0 | T10: 0 | U10: 0 | V10: 0 | W10: 0 | X10: 0 | Y10: 0 | Z10: =SUM(I10:T10) -> 26031.66 | AA10: =ROUND(MAX(E10+F10+G10-W10-X10-Z10,0),2) -> 124908.34 | AB10: =ROUND(MAX(H10-U10,0),2) -> 19970 | AC10: =ROUND(MAX(0,(D10-V10)*Shift11!$B$3),2) -> 0 | AD10: =MAX(AC10,Y10) -> 0
A11: 4 | B11: 1 | C11: MCGREGOR | D11: =Levy!F11 -> 0 | E11: =Levy!G11 -> 66483 | F11: =Levy!H11 -> 0 | G11: =Levy!I11 -> 106528 | H11: =Levy!J11 -> 56743 | I11: 0 | J11: 247.02 | K11: 11665.08 | L11: 0 | M11: 0 | N11: 0 | O11: 0 | P11: -13228.31 | Q11: 0 | R11: 0 | S11: 0 | T11: 0 | U11: 0 | V11: 0 | W11: 0 | X11: 0 | Y11: 51784.65 | Z11: =SUM(I11:T11) -> -1316.21 | AA11: =ROUND(MAX(E11+F11+G11-W11-X11-Z11,0),2) -> 174327.21 | AB11: =ROUND(MAX(H11-U11,0),2) -> 56743 | AC11: =ROUND(MAX(0,(D11-V11)*Shift11!$B$3),2) -> 0 | AD11: =MAX(AC11,Y11) -> 51784.65
A12: 6 | B12: 3 | C12: SOUTH ST. PAUL | D12: =Levy!F12 -> 2989995 | E12: =Levy!G12 -> 380899 | F12: =Levy!H12 -> 591403 | G12: =Levy!I12 -> 1921364 | H12: =Levy!J12 -> 300195 | I12: 0 | J12: 40000 | K12: 72643.56 | L12: 0 | M12: 0 | N12: 0 | O12: 0 | P12: 20297.28 | Q12: 0 | R12: -1894.4 | S12: 0 | T12: 0 | U12: 0 | V12: 0 | W12: 0 | X12: 0 | Y12: 360711.07 | Z12: =SUM(I12:T12) -> 131046.44 | AA12: =ROUND(MAX(E12+F12+G12-W12-X12-Z12,0),2) -> 2762619.6 | AB12: =ROUND(MAX(H12-U12,0),2) -> 300195 | AC12: =ROUND(MAX(0,(D12-V12)*Shift11!$B$3),2) -> 1453137.6 | AD12: =MAX(AC12,Y12) -> 1453137.6
A13: 11 | B13: 1 | C13: ANOKA-HENNEPIN | D13: =Levy!F13 -> 51090199 | E13: =Levy!G13 -> 3820592.4 | F13: =Levy!H13 -> 3000000 | G13: =Levy!I13 -> 15067013 | H13: =Levy!J13 -> 3106720.4 | I13: 0 | J13: 500000 | K13: 953759.94 | L13: 0 | M13: 0 | N13: 0 | O13: 0 | P13: 305350.9 | Q13: 0 | R13: -13829.6 | S13: 0 | T13: 0 | U13: 0 | V13: 0 | W13: 0 | X13: 197692.1 | Y13: 3515884.7 | Z13: =SUM(I13:T13) -> 1745281.2 | AA13: =ROUND(MAX(E13+F13+G13-W13-X13-Z13,0),2) -> 19944632 | AB13: =ROUND(MAX(H13-U13,0),2) -> 3106720.4 | AC13: =ROUND(MAX(0,(D13-V13)*Shift11!$B$3),2) -> 24829837 | AD13: =MAX(AC13,Y13) -> 24829837
A14: 12 | B14: 1 | C14: CENTENNIAL | D14: =Levy!F14 -> 5650661.7 | E14: =Levy!G14 -> 764942.25 | F14: =Levy!H14 -> 0 | G14: =Levy!I14 -> 2840359.9 | H14: =Levy!J14 -> 435691.6 | I14: 0 | J14: 75000 | K14: 115112.6 | L14: 0 | M14: 0 | N14: 0 | O14: 0 | P14: 46208.84 | Q14: 0 | R14: 0 | S14: 0 | T14: 0 | U14: 0 | V14: 0 | W14: 0 | X14: 16533.75 | Y14: 320094.52 | Z14: =SUM(I14:T14) -> 236321.44 | AA14: =ROUND(MAX(E14+F14+G14-W14-X14-Z14,0),2) -> 3352447 | AB14: =ROUND(MAX(H14-U14,0),2) -> 435691.6 | AC14: =ROUND(MAX(0,(D14-V14)*Shift11!$B$3),2) -> 2746221.6 | AD14: =MAX(AC14,Y14) -> 2746221.6
A15: 13 | B15: 1 | C15: COLUMBIA HEIGHTS | D15: =Levy!F15 -> 3415330.2 | E15: =Levy!G15 -> 399163.32 | F15: =Levy!H15 -> 0 | G15: =Levy!I15 -> 1829369.1 | H15: =Levy!J15 -> 318080.81 | I15: 0 | J15: 20000 | K15: 62336.3 | L15: 0 | M15: 0 | N15: 0 | O15: 0 | P15: 12224.07 | Q15: 0 | R15: 1136.8 | S15: 0 | T15: 0 | U15: 0 | V15: 0 | W15: 0 | X15: 0 | Y15: 848958.71 | Z15: =SUM(I15:T15) -> 95697.17 | AA15: =ROUND(MAX(E15+F15+G15-W15-X15-Z15,0),2) -> 2132835.3 | AB15: =ROUND(MAX(H15-U15,0),2) -> 318080.81 | AC15: =ROUND(MAX(0,(D15-V15)*Shift11!$B$3),2) -> 1659850.5 | AD15: =MAX(AC15,Y15) -> 1659850.5
A16: 14 | B16: 1 | C16: FRIDLEY | D16: =Levy!F16 -> 2512103.5 | E16: =Levy!G16 -> 336673.52 | F16: =Levy!H16 -> 741000 | G16: =Levy!I16 -> 1361099.3 | H16: =Levy!J16 -> 466173.16 | I16: 0 | J16: 94000 | K16: 68582.56 | L16: 0 | M16: 0 | N16: 0 | O16: 0 | P16: 12303.92 | Q16: 0 | R16: 0 | S16: 0 | T16: 0 | U16: 0 | V16: 0 | W16: 0 | X16: 0 | Y16: 468605.33 | Z16: =SUM(I16:T16) -> 174886.48 | AA16: =ROUND(MAX(E16+F16+G16-W16-X16-Z16,0),2) -> 2263886.3 | AB16: =ROUND(MAX(H16-U16,0),2) -> 466173.16 | AC16: =ROUND(MAX(0,(D16-V16)*Shift11!$B$3),2) -> 1220882.3 | AD16: =MAX(AC16,Y16) -> 1220882.3
A17: 15 | B17: 1 | C17: ST. FRANCIS | D17: =Levy!F17 -> 1821524 | E17: =Levy!G17 -> 578387.61 | F17: =Levy!H17 -> 0 | G17: =Levy!I17 -> 2111555.8 | H17: =Levy!J17 -> 349966.46 | I17: 0 | J17: 150000 | K17: 136178.1 | L17: 0 | M17: 0 | N17: 0 | O17: 0 | P17: 173183.08 | Q17: 0 | R17: -10364 | S17: 0 | T17: 0 | U17: 0 | V17: 0 | W17: 0 | X17: 0 | Y17: 288492.79 | Z17: =SUM(I17:T17) -> 448997.18 | AA17: =ROUND(MAX(E17+F17+G17-W17-X17-Z17,0),2) -> 2240946.2 | AB17: =ROUND(MAX(H17-U17,0),2) -> 349966.46 | AC17: =ROUND(MAX(0,(D17-V17)*Shift11!$B$3),2) -> 885260.64 | AD17: =MAX(AC17,Y17) -> 885260.64
A18: 16 | B18: 1 | C18: SPRING LAKE PARK | D18: =Levy!F18 -> 5117489.9 | E18: =Levy!G18 -> 876015 | F18: =Levy!H18 -> 1065985 | G18: =Levy!I18 -> 2535402.9 | H18: =Levy!J18 -> 463634.17 | I18: 0 | J18: 75000 | K18: 90781.02 | L18: 0 | M18: 0 | N18: 0 | O18: 0 | P18: 8924.13 | Q18: 0 | R18: -9347.45 | S18: 0 | T18: 0 | U18: 0 | V18: 0 | W18: 0 | X18: 73286.44 | Y18: 804793.86 | Z18: =SUM(I18:T18) -> 165357.7 | AA18: =ROUND(MAX(E18+F18+G18-W18-X18-Z18,0),2) -> 4238758.8 | AB18: =ROUND(MAX(H18-U18,0),2) -> 463634.17 | AC18: =ROUND(MAX(0,(D18-V18)*Shift11!$B$3),2) -> 2487100.1 | AD18: =MAX(AC18,Y18) -> 2487100.1
A19: 22 | B19: 1 | C19: DETROIT LAKES | D19: =Levy!F19 -> 1336103 | E19: =Levy!G19 -> 382290 | F19: =Levy!H19 -> 0 | G19: =Levy!I19 -> 1149384 | H19: =Levy!J19 -> 210886 | I19: 0 | J19: 15000 | K19: 56261.09 | L19: 0 | M19: 0 | N19: 0 | O19: 0 | P19: 25886.23 | Q19: 0 | R19: 0 | S19: 0 | T19: 0 | U19: 0 | V19: 0 | W19: 0 | X19: 0 | Y19: 133298.49 | Z19: =SUM(I19:T19) -> 97147.32 | AA19: =ROUND(MAX(E19+F19+G19-W19-X19-Z19,0),2) -> 1434526.7 | AB19: =ROUND(MAX(H19-U19,0),2) -> 210886 | AC19: =ROUND(MAX(0,(D19-V19)*Shift11!$B$3),2) -> 649346.06 | AD19: =MAX(AC19,Y19) -> 649346.06
... A287: 2155 | B287: 1 | C287: WADENA-DEER CREE | D287: =Levy!F287 -> 573218 | E287: =Levy!G287 -> 64669 | F287: =Levy!H287 -> 0 | G287: =Levy!I287 -> 249637 | H287: =Levy!J287 -> 68530 | I287: 0 | J287: 20000 | K287: 34784.42 | L287: 0 | M287: 0 | N287: 0 | O287: 0 | P287: -1405.99 | Q287: 0 | R287: 0 | S287: 0 | T287: 0 | U287: 0 | V287: 0 | W287: 0 | X287: 0 | Y287: 38157.32 | Z287: =SUM(I287:T287) -> 53378.43 | AA287: =ROUND(MAX(E287+F287+G287-W287-X287-Z287,0),2) -> 260927.57 | AB287: =ROUND(MAX(H287-U287,0),2) -> 68530 | AC287: =ROUND(MAX(0,(D287-V287)*Shift11!$B$3),2) -> 278583.95 | AD287: =MAX(AC287,Y287) -> 278583.95
A288: 2159 | B288: 1 | C288: BUFFALO LAKE-HEC | D288: =Levy!F288 -> 501124.39 | E288: =Levy!G288 -> 53588.49 | F288: =Levy!H288 -> 0 | G288: =Levy!I288 -> 290062.04 | H288: =Levy!J288 -> 45624.79 | I288: 0 | J288: 15000 | K288: 13904.77 | L288: 0 | M288: 0 | N288: 0 | O288: 0 | P288: 9915.73 | Q288: 0 | R288: -107.2 | S288: 0 | T288: 0 | U288: 0 | V288: 0 | W288: 0 | X288: =22933.81+919.38 -> 23853.19 | Y288: =98779.38+3741.29 -> 102520.67 | Z288: =SUM(I288:T288) -> 38713.3 | AA288: =ROUND(MAX(E288+F288+G288-W288-X288-Z288,0),2) -> 281084.04 | AB288: =ROUND(MAX(H288-U288,0),2) -> 45624.79 | AC288: =ROUND(MAX(0,(D288-V288)*Shift11!$B$3),2) -> 243546.45 | AD288: =MAX(AC288,Y288) -> 243546.45
A289: 2164 | B289: 1 | C289: DILWORTH-GLYNDON | D289: =Levy!F289 -> 321243.8 | E289: =Levy!G289 -> 114871.4 | F289: =Levy!H289 -> 0 | G289: =Levy!I289 -> 148291.22 | H289: =Levy!J289 -> 75618.63 | I289: 0 | J289: 3700 | K289: 22306.11 | L289: 0 | M289: 0 | N289: 0 | O289: 0 | P289: -1538.69 | Q289: 0 | R289: -5794.94 | S289: 0 | T289: 0 | U289: 0 | V289: 0 | W289: 0 | X289: 0 | Y289: 55510.33 | Z289: =SUM(I289:T289) -> 18672.48 | AA289: =ROUND(MAX(E289+F289+G289-W289-X289-Z289,0),2) -> 244490.14 | AB289: =ROUND(MAX(H289-U289,0),2) -> 75618.63 | AC289: =ROUND(MAX(0,(D289-V289)*Shift11!$B$3),2) -> 156124.49 | AD289: =MAX(AC289,Y289) -> 156124.49
A290: 2165 | B290: 1 | C290: HINCKLEY-FINLAYS | D290: =Levy!F290 -> 273077.14 | E290: =Levy!G290 -> 102425.44 | F290: =Levy!H290 -> 0 | G290: =Levy!I290 -> 304183.13 | H290: =Levy!J290 -> 74225.44 | I290: 0 | J290: 6590.96 | K290: 7886.34 | L290: 0 | M290: 0 | N290: 0 | O290: 0 | P290: 0 | Q290: 0 | R290: 4967.08 | S290: 0 | T290: 0 | U290: 0 | V290: 0 | W290: 0 | X290: 0 | Y290: 51707.97 | Z290: =SUM(I290:T290) -> 19444.38 | AA290: =ROUND(MAX(E290+F290+G290-W290-X290-Z290,0),2) -> 387164.19 | AB290: =ROUND(MAX(H290-U290,0),2) -> 74225.44 | AC290: =ROUND(MAX(0,(D290-V290)*Shift11!$B$3),2) -> 132715.49 | AD290: =MAX(AC290,Y290) -> 132715.49
