Workbook

Sheet all
A1: Survey of all Currently enrolled students Fall 2012 -- All questions by Primary Campus
A3: Primary Campus | B3: Total | D3: Respondent | F3: % of campus
A4: Boulder County | B4: 2638 | C4: =B4/B10 -> 0.13999894 | D4: 487 | E4: =D4/D10 -> 0.16083223 | F4: =D4/B4 -> 0.18460955
A5: Brighton | B5: 184 | C5: =B5/B10 -> 0.0097648994 | D5: 38 | E5: =D5/D10 -> 0.012549538 | F5: =D5/B5 -> 0.20652174
A6: CCC Online | B6: 1500 | C6: =B6/B10 -> 0.079605158 | D6: 201 | E6: =D6/D10 -> 0.066380449 | F6: =D6/B6 -> 0.134
A7: Larimer | B7: 5884 | C7: =B7/B10 -> 0.3122645 | D7: 899 | E7: =D7/D10 -> 0.29689564 | F7: =D7/B7 -> 0.15278722
A8: FRCC Online | B8: 2667 | C8: =B8/B10 -> 0.14153797 | D8: 424 | E8: =D8/D10 -> 0.14002642 | F8: =D8/B8 -> 0.15898013
A9: Westminster | B9: 5970 | C9: =B9/B10 -> 0.31682853 | D9: 979 | E9: =D9/D10 -> 0.32331572 | F9: =D9/B9 -> 0.1639866
A10: Total | B10: =SUM(B4:B9) -> 18843 | C10: =SUM(C4:C9) -> 1 | D10: =SUM(D4:D9) -> 3028 | E10: =SUM(E4:E9) -> 1 | F10: =D10/B10 -> 0.16069628
A12: Degree | B12: Total | D12: Respondent | F12: % | G12: Boulder Cty | I12: Brighton | K12: CCCS Online | M12: Larimer | O12: FRCC Online | Q12: Westminster
A13: AA | B13: 5794 | C13: =B13/B19 -> 0.30748819 | D13: =G13+I13+K13+M13+O13+Q13 -> 902 | E13: =D13/D19 -> 0.29788639 | F13: =D13/B13 -> 0.15567829 | G13: 145 | H13: =G13/G19 -> 0.29774127 | I13: 9 | J13: =I13/I19 -> 0.23684211 | K13: 46 | L13: =K13/K19 -> 0.22885572 | M13: 299 | N13: =M13/M19 -> 0.33259177 | O13: 127 | P13: =O13/O19 -> 0.2995283 | Q13: 276 | R13: =Q13/Q19 -> 0.28192033
A14: AAS | B14: 5407 | C14: =B14/B19 -> 0.28695006 | D14: =G14+I14+K14+M14+O14+Q14 -> 944 | E14: =D14/D19 -> 0.31175694 | F14: =D14/B14 -> 0.1745885 | G14: 116 | H14: =G14/G19 -> 0.23819302 | I14: 13 | J14: =I14/I19 -> 0.34210526 | K14: 68 | L14: =K14/K19 -> 0.33830846 | M14: 280 | N14: =M14/M19 -> 0.31145717 | O14: 143 | P14: =O14/O19 -> 0.33726415 | Q14: 324 | R14: =Q14/Q19 -> 0.33094995
A15: AGS | B15: 1423 | C15: =B15/B19 -> 0.07551876 | D15: =G15+I15+K15+M15+O15+Q15 -> 201 | E15: =D15/D19 -> 0.066380449 | F15: =D15/B15 -> 0.14125088 | G15: 25 | H15: =G15/G19 -> 0.051334702 | I15: 2 | J15: =I15/I19 -> 0.052631579 | K15: 13 | L15: =K15/K19 -> 0.064676617 | M15: 55 | N15: =M15/M19 -> 0.061179088 | O15: 29 | P15: =O15/O19 -> 0.068396226 | Q15: 77 | R15: =Q15/Q19 -> 0.078651685
A16: AS | B16: 3365 | C16: =B16/B19 -> 0.17858091 | D16: =G16+I16+K16+M16+O16+Q16 -> 540 | E16: =D16/D19 -> 0.17833554 | F16: =D16/B16 -> 0.16047548 | G16: 84 | H16: =G16/G19 -> 0.1724846 | I16: 11 | J16: =I16/I19 -> 0.28947368 | K16: 40 | L16: =K16/K19 -> 0.19900498 | M16: 167 | N16: =M16/M19 -> 0.18576196 | O16: 50 | P16: =O16/O19 -> 0.11792453 | Q16: 188 | R16: =Q16/Q19 -> 0.19203269
A17: CER | B17: 1445 | C17: =B17/B19 -> 0.076686303 | D17: =G17+I17+K17+M17+O17+Q17 -> 248 | E17: =D17/D19 -> 0.081902246 | F17: =D17/B17 -> 0.1716263 | G17: 79 | H17: =G17/G19 -> 0.16221766 | I17: 1 | J17: =I17/I19 -> 0.026315789 | K17: 18 | L17: =K17/K19 -> 0.089552239 | M17: 52 | N17: =M17/M19 -> 0.057842047 | O17: 40 | P17: =O17/O19 -> 0.094339623 | Q17: 58 | R17: =Q17/Q19 -> 0.059244127
A18: UND | B18: 1409 | C18: =B18/B19 -> 0.074775779 | D18: =G18+I18+K18+M18+O18+Q18 -> 193 | E18: =D18/D19 -> 0.063738441 | F18: =D18/B18 -> 0.13697658 | G18: 38 | H18: =G18/G19 -> 0.078028747 | I18: 2 | J18: =I18/I19 -> 0.052631579 | K18: 16 | L18: =K18/K19 -> 0.07960199 | M18: 46 | N18: =M18/M19 -> 0.051167964 | O18: 35 | P18: =O18/O19 -> 0.08254717 | Q18: 56 | R18: =Q18/Q19 -> 0.057201226
A19: Total | B19: =SUM(B13:B18) -> 18843 | C19: =SUM(C13:C18) -> 1 | D19: =SUM(D13:D18) -> 3028 | E19: =SUM(E13:E18) -> 1 | F19: =D19/B19 -> 0.16069628 | G19: =SUM(G13:G18) -> 487 | H19: =SUM(H13:H18) -> 1 | I19: =SUM(I13:I18) -> 38 | J19: =SUM(J13:J18) -> 1 | K19: =SUM(K13:K18) -> 201 | L19: =SUM(L13:L18) -> 1 | M19: =SUM(M13:M18) -> 899 | N19: =SUM(N13:N18) -> 1 | ... R19: =SUM(R13:R18) -> 1
A21: Sex | B21: Total | D21: Respondent | F21: % | G21: Boulder Cty | I21: Brighton | K21: CCCS Online | M21: Larimer | O21: FRCC Online | Q21: Westminster
A22: Female | B22: 10870 | C22: =B22/B25 -> 0.57687205 | D22: =G22+I22+K22+M22+O22+Q22 -> 2067 | E22: =D22/D25 -> 0.6826288 | F22: =D22/B22 -> 0.19015639 | G22: 333 | H22: =G22/G25 -> 0.68377823 | I22: 28 | J22: =I22/I25 -> 0.73684211 | K22: 150 | L22: =K22/K25 -> 0.74626866 | M22: 542 | N22: =M22/M25 -> 0.6028921 | O22: 323 | P22: =O22/O25 -> 0.76179245 | Q22: 691 | R22: =Q22/Q25 -> 0.70582227
A23: Male | B23: 7964 | C23: =B23/B25 -> 0.42265032 | D23: =G23+I23+K23+M23+O23+Q23 -> 960 | E23: =D23/D25 -> 0.31704095 | F23: =D23/B23 -> 0.12054244 | G23: 154 | H23: =G23/G25 -> 0.31622177 | I23: 10 | J23: =I23/I25 -> 0.26315789 | K23: 51 | L23: =K23/K25 -> 0.25373134 | M23: 356 | N23: =M23/M25 -> 0.39599555 | O23: 101 | P23: =O23/O25 -> 0.23820755 | Q23: 288 | R23: =Q23/Q25 -> 0.29417773
A24: N | B24: 9 | C24: =B24/B25 -> 0.00047763095 | D24: =G24+I24+K24+M24+O24+Q24 -> 1 | E24: =D24/D25 -> 0.00033025099 | F24: =D24/B24 -> 0.11111111 | H24: =G24/G25 -> 0 | J24: =I24/I25 -> 0 | L24: =K24/K25 -> 0 | M24: 1 | N24: =M24/M25 -> 0.0011123471 | P24: =O24/O25 -> 0 | R24: =Q24/Q25 -> 0
A25: Total | B25: =SUM(B22:B24) -> 18843 | C25: =SUM(C22:C24) -> 1 | D25: =SUM(D22:D24) -> 3028 | E25: =SUM(E22:E24) -> 1 | F25: =D25/B25 -> 0.16069628 | G25: =SUM(G22:G24) -> 487 | H25: =SUM(H22:H24) -> 1 | I25: =SUM(I22:I24) -> 38 | J25: =SUM(J22:J24) -> 1 | K25: =SUM(K22:K24) -> 201 | L25: =SUM(L22:L24) -> 1 | M25: =SUM(M22:M24) -> 899 | N25: =SUM(N22:N24) -> 1 | ... R25: =SUM(R22:R24) -> 1
A27: Note: Students less than 18 years old were omitted from this survey because of uncertainty around confidentiality for underage students.
A28: Age | B28: Total | D28: Respondent | F28: % | G28: Boulder Cty | I28: Brighton | K28: CCCS Online | M28: Larimer | O28: FRCC Online | Q28: Westminster
A29: Less than 18 | C29: =B29/B36 -> 0
A30: 18 to 19 | B30: 3573 | C30: =B30/B36 -> 0.18961949 | D30: =G30+I30+K30+M30+O30+Q30 -> 456 | E30: =D30/D36 -> 0.15059445 | F30: =D30/B30 -> 0.12762385 | G30: 64 | H30: =G30/G36 -> 0.13141684 | I30: 9 | J30: =I30/I36 -> 0.23684211 | K30: 12 | L30: =K30/K36 -> 0.059701493 | M30: 188 | N30: =M30/M36 -> 0.20912125 | O30: 18 | P30: =O30/O36 -> 0.04245283 | Q30: 165 | R30: =Q30/Q36 -> 0.16853933
A31: 20 to 21 | B31: 3288 | C31: =B31/B36 -> 0.17449451 | D31: =G31+I31+K31+M31+O31+Q31 -> 331 | E31: =D31/D36 -> 0.10931308 | F31: =D31/B31 -> 0.1006691 | G31: 55 | H31: =G31/G36 -> 0.11293634 | I31: 4 | J31: =I31/I36 -> 0.10526316 | K31: 13 | L31: =K31/K36 -> 0.064676617 | M31: 125 | N31: =M31/M36 -> 0.13904338 | O31: 27 | P31: =O31/O36 -> 0.063679245 | Q31: 107 | R31: =Q31/Q36 -> 0.1092952
A32: 22 to 24 | B32: 3117 | C32: =B32/B36 -> 0.16541952 | D32: =G32+I32+K32+M32+O32+Q32 -> 337 | E32: =D32/D36 -> 0.11129458 | F32: =D32/B32 -> 0.10811678 | G32: 55 | H32: =G32/G36 -> 0.11293634 | I32: 4 | J32: =I32/I36 -> 0.10526316 | K32: 25 | L32: =K32/K36 -> 0.12437811 | M32: 103 | N32: =M32/M36 -> 0.11457175 | O32: 45 | P32: =O32/O36 -> 0.10613208 | Q32: 105 | R32: =Q32/Q36 -> 0.1072523
A33: 25 to 30 | B33: 3699 | C33: =B33/B36 -> 0.19630632 | D33: =G33+I33+K33+M33+O33+Q33 -> 561 | E33: =D33/D36 -> 0.18527081 | F33: =D33/B33 -> 0.15166261 | G33: 97 | H33: =G33/G36 -> 0.19917864 | I33: 5 | J33: =I33/I36 -> 0.13157895 | K33: 41 | L33: =K33/K36 -> 0.2039801 | M33: 150 | N33: =M33/M36 -> 0.16685206 | O33: 81 | P33: =O33/O36 -> 0.19103774 | Q33: 187 | R33: =Q33/Q36 -> 0.19101124
A34: 31 to 40 | B34: 2909 | C34: =B34/B36 -> 0.15438094 | D34: =G34+I34+K34+M34+O34+Q34 -> 628 | E34: =D34/D36 -> 0.20739762 | F34: =D34/B34 -> 0.21588175 | G34: 91 | H34: =G34/G36 -> 0.18685832 | I34: 5 | J34: =I34/I36 -> 0.13157895 | K34: 58 | L34: =K34/K36 -> 0.28855721 | M34: 152 | N34: =M34/M36 -> 0.16907675 | O34: 121 | P34: =O34/O36 -> 0.28537736 | Q34: 201 | R34: =Q34/Q36 -> 0.20531154
A35: Over 40 | B35: 2257 | C35: =B35/B36 -> 0.11977923 | D35: =G35+I35+K35+M35+O35+Q35 -> 715 | E35: =D35/D36 -> 0.23612946 | F35: =D35/B35 -> 0.3167922 | G35: 125 | H35: =G35/G36 -> 0.25667351 | I35: 11 | J35: =I35/I36 -> 0.28947368 | K35: 52 | L35: =K35/K36 -> 0.25870647 | M35: 181 | N35: =M35/M36 -> 0.20133482 | O35: 132 | P35: =O35/O36 -> 0.31132075 | Q35: 214 | R35: =Q35/Q36 -> 0.2185904
A36: Total | B36: =SUM(B29:B35) -> 18843 | C36: =SUM(C29:C35) -> 1 | D36: =SUM(D29:D35) -> 3028 | E36: =SUM(E29:E35) -> 1 | F36: =D36/B36 -> 0.16069628 | G36: =SUM(G29:G35) -> 487 | H36: =SUM(H29:H35) -> 1 | I36: =SUM(I29:I35) -> 38 | J36: =SUM(J29:J35) -> 1 | K36: =SUM(K29:K35) -> 201 | L36: =SUM(L29:L35) -> 1 | M36: =SUM(M29:M35) -> 899 | N36: =SUM(N29:N35) -> 1 | ... R36: =SUM(R29:R35) -> 1
A37: Median | B37: 23.5 | D37: 30.182335 | G37: 31.736702 | I37: 26.028571 | K37: 30.552727 | M37: 28.564688 | O37: 33.744 | Q37: 29.272115
A39: Ethnicity | B39: Total | D39: Respondent | F39: % | G39: Boulder Cty | I39: Brighton | K39: CCCS Online | M39: Larimer | O39: FRCC Online | Q39: Westminster
A40: 2 Or More | B40: 15 | C40: =B40/B48 -> 0.00079605158 | D40: =G40+I40+K40+M40+O40+Q40 -> 4 | E40: =D40/D48 -> 0.001321004 | F40: =D40/B40 -> 0.26666667 | I40: 1 | K40: 1 | L40: =K40/K48 -> 0.0049751244 | M40: 2 | N40: =M40/M48 -> 0.0022246941 | P40: =O40/O48 -> 0 | R40: =Q40/Q48 -> 0
A41: American Indian | B41: 338 | C41: =B41/B48 -> 0.017937696 | D41: =G41+I41+K41+M41+O41+Q41 -> 50 | E41: =D41/D48 -> 0.01651255 | F41: =D41/B41 -> 0.14792899 | G41: 9 | H41: =G41/G48 -> 0.018480493 | I41: 1 | J41: =I41/I48 -> 0.026315789 | K41: 3 | L41: =K41/K48 -> 0.014925373 | M41: 12 | N41: =M41/M48 -> 0.013348165 | O41: 7 | P41: =O41/O48 -> 0.016509434 | Q41: 18 | R41: =Q41/Q48 -> 0.018386108
A42: Asian | B42: 784 | C42: =B42/B48 -> 0.041606963 | D42: =G42+I42+K42+M42+O42+Q42 -> 92 | E42: =D42/D48 -> 0.030383091 | F42: =D42/B42 -> 0.11734694 | G42: 19 | H42: =G42/G48 -> 0.039014374 | I42: 1 | J42: =I42/I48 -> 0.026315789 | K42: 6 | L42: =K42/K48 -> 0.029850746 | M42: 14 | N42: =M42/M48 -> 0.015572859 | O42: 6 | P42: =O42/O48 -> 0.014150943 | Q42: 46 | R42: =Q42/Q48 -> 0.046986721
A43: Black | B43: 371 | C43: =B43/B48 -> 0.019689009 | D43: =G43+I43+K43+M43+O43+Q43 -> 56 | E43: =D43/D48 -> 0.018494055 | F43: =D43/B43 -> 0.1509434 | G43: 8 | H43: =G43/G48 -> 0.016427105 | J43: =I43/I48 -> 0 | K43: 4 | L43: =K43/K48 -> 0.019900498 | M43: 15 | N43: =M43/M48 -> 0.016685206 | O43: 4 | P43: =O43/O48 -> 0.0094339623 | Q43: 25 | R43: =Q43/Q48 -> 0.025536261
A44: Hispanic | B44: 2500 | C44: =B44/B48 -> 0.13267526 | D44: =G44+I44+K44+M44+O44+Q44 -> 334 | E44: =D44/D48 -> 0.11030383 | F44: =D44/B44 -> 0.1336 | G44: 53 | H44: =G44/G48 -> 0.10882957 | I44: 14 | J44: =I44/I48 -> 0.36842105 | K44: 16 | L44: =K44/K48 -> 0.07960199 | M44: 79 | N44: =M44/M48 -> 0.087875417 | O44: 41 | P44: =O44/O48 -> 0.096698113 | Q44: 131 | R44: =Q44/Q48 -> 0.13381001
A45: International | B45: 190 | C45: =B45/B48 -> 0.01008332 | D45: =G45+I45+K45+M45+O45+Q45 -> 33 | E45: =D45/D48 -> 0.010898283 | F45: =D45/B45 -> 0.17368421 | G45: 6 | H45: =G45/G48 -> 0.012320329 | J45: =I45/I48 -> 0 | K45: 2 | L45: =K45/K48 -> 0.0099502488 | M45: 5 | N45: =M45/M48 -> 0.0055617353 | P45: =O45/O48 -> 0 | Q45: 20 | R45: =Q45/Q48 -> 0.020429009
...

Sheet Demographics
A1: Survey of all Currently enrolled students Fall 2012 -- Demographics
A3: Primary Campus | B3: Total | D3: Respondent | F3: % of campus
A4: Boulder County | B4: 2638 | C4: =B4/B10 -> 0.13999894 | D4: 487 | E4: =D4/D10 -> 0.16083223 | F4: =D4/B4 -> 0.18460955 | H4: Brighton students were most likely to respond to survey.
A5: Brighton | B5: 184 | C5: =B5/B10 -> 0.0097648994 | D5: 38 | E5: =D5/D10 -> 0.012549538 | F5: =D5/B5 -> 0.20652174 | H5: CCCOnline students were least likely to respond to the survey
A6: CCC Online | B6: 1500 | C6: =B6/B10 -> 0.079605158 | D6: 201 | E6: =D6/D10 -> 0.066380449 | F6: =D6/B6 -> 0.134
A7: Larimer | B7: 5884 | C7: =B7/B10 -> 0.3122645 | D7: 899 | E7: =D7/D10 -> 0.29689564 | F7: =D7/B7 -> 0.15278722
A8: FRCC Online | B8: 2667 | C8: =B8/B10 -> 0.14153797 | D8: 424 | E8: =D8/D10 -> 0.14002642 | F8: =D8/B8 -> 0.15898013
A9: Westminster | B9: 5970 | C9: =B9/B10 -> 0.31682853 | D9: 979 | E9: =D9/D10 -> 0.32331572 | F9: =D9/B9 -> 0.1639866
A10: Total | B10: =SUM(B4:B9) -> 18843 | C10: =SUM(C4:C9) -> 1 | D10: =SUM(D4:D9) -> 3028 | E10: =SUM(E4:E9) -> 1 | F10: =D10/B10 -> 0.16069628
A12: Degree | B12: Total | D12: Respondent | F12: % | G12: Boulder Cty | I12: Brighton | K12: CCCS Online | M12: Larimer | O12: FRCC Online | Q12: Westminster | S12: CCCS Online and Brighton are least likely to be AA
A13: AA | B13: 5794 | C13: =B13/B19 -> 0.30748819 | D13: =G13+I13+K13+M13+O13+Q13 -> 902 | E13: =D13/D19 -> 0.29788639 | F13: =D13/B13 -> 0.15567829 | G13: 145 | H13: =G13/G19 -> 0.29774127 | I13: 9 | J13: =I13/I19 -> 0.23684211 | K13: 46 | L13: =K13/K19 -> 0.22885572 | M13: 299 | N13: =M13/M19 -> 0.33259177 | O13: 127 | P13: =O13/O19 -> 0.2995283 | Q13: 276 | R13: =Q13/Q19 -> 0.28192033
A14: AAS | B14: 5407 | C14: =B14/B19 -> 0.28695006 | D14: =G14+I14+K14+M14+O14+Q14 -> 944 | E14: =D14/D19 -> 0.31175694 | F14: =D14/B14 -> 0.1745885 | G14: 116 | H14: =G14/G19 -> 0.23819302 | I14: 13 | J14: =I14/I19 -> 0.34210526 | K14: 68 | L14: =K14/K19 -> 0.33830846 | M14: 280 | N14: =M14/M19 -> 0.31145717 | O14: 143 | P14: =O14/O19 -> 0.33726415 | Q14: 324 | R14: =Q14/Q19 -> 0.33094995
A15: AGS | B15: 1423 | C15: =B15/B19 -> 0.07551876 | D15: =G15+I15+K15+M15+O15+Q15 -> 201 | E15: =D15/D19 -> 0.066380449 | F15: =D15/B15 -> 0.14125088 | G15: 25 | H15: =G15/G19 -> 0.051334702 | I15: 2 | J15: =I15/I19 -> 0.052631579 | K15: 13 | L15: =K15/K19 -> 0.064676617 | M15: 55 | N15: =M15/M19 -> 0.061179088 | O15: 29 | P15: =O15/O19 -> 0.068396226 | Q15: 77 | R15: =Q15/Q19 -> 0.078651685 | S15: Brighton and Online are most likely to be in AAS
A16: AS | B16: 3365 | C16: =B16/B19 -> 0.17858091 | D16: =G16+I16+K16+M16+O16+Q16 -> 540 | E16: =D16/D19 -> 0.17833554 | F16: =D16/B16 -> 0.16047548 | G16: 84 | H16: =G16/G19 -> 0.1724846 | I16: 11 | J16: =I16/I19 -> 0.28947368 | K16: 40 | L16: =K16/K19 -> 0.19900498 | M16: 167 | N16: =M16/M19 -> 0.18576196 | O16: 50 | P16: =O16/O19 -> 0.11792453 | Q16: 188 | R16: =Q16/Q19 -> 0.19203269
A17: CER | B17: 1445 | C17: =B17/B19 -> 0.076686303 | D17: =G17+I17+K17+M17+O17+Q17 -> 248 | E17: =D17/D19 -> 0.081902246 | F17: =D17/B17 -> 0.1716263 | G17: 79 | H17: =G17/G19 -> 0.16221766 | I17: 1 | J17: =I17/I19 -> 0.026315789 | K17: 18 | L17: =K17/K19 -> 0.089552239 | M17: 52 | N17: =M17/M19 -> 0.057842047 | O17: 40 | P17: =O17/O19 -> 0.094339623 | Q17: 58 | R17: =Q17/Q19 -> 0.059244127
A18: UND | B18: 1409 | C18: =B18/B19 -> 0.074775779 | D18: =G18+I18+K18+M18+O18+Q18 -> 193 | E18: =D18/D19 -> 0.063738441 | F18: =D18/B18 -> 0.13697658 | G18: 38 | H18: =G18/G19 -> 0.078028747 | I18: 2 | J18: =I18/I19 -> 0.052631579 | K18: 16 | L18: =K18/K19 -> 0.07960199 | M18: 46 | N18: =M18/M19 -> 0.051167964 | O18: 35 | P18: =O18/O19 -> 0.08254717 | Q18: 56 | R18: =Q18/Q19 -> 0.057201226
A19: Total | B19: =SUM(B13:B18) -> 18843 | C19: =SUM(C13:C18) -> 1 | D19: =SUM(D13:D18) -> 3028 | E19: =SUM(E13:E18) -> 1 | F19: =D19/B19 -> 0.16069628 | G19: =SUM(G13:G18) -> 487 | H19: =SUM(H13:H18) -> 1 | I19: =SUM(I13:I18) -> 38 | J19: =SUM(J13:J18) -> 1 | K19: =SUM(K13:K18) -> 201 | L19: =SUM(L13:L18) -> 1 | M19: =SUM(M13:M18) -> 899 | N19: =SUM(N13:N18) -> 1 | ... R19: =SUM(R13:R18) -> 1
A21: Sex | B21: Total | D21: Respondent | F21: % | G21: Boulder Cty | I21: Brighton | K21: CCCS Online | M21: Larimer | O21: FRCC Online | Q21: Westminster | S21: Women have higher response rates, and are more likely to attend the online campuses.
A22: Female | B22: 10870 | C22: =B22/B25 -> 0.57687205 | D22: =G22+I22+K22+M22+O22+Q22 -> 2067 | E22: =D22/D25 -> 0.6826288 | F22: =D22/B22 -> 0.19015639 | G22: 333 | H22: =G22/G25 -> 0.68377823 | I22: 28 | J22: =I22/I25 -> 0.73684211 | K22: 150 | L22: =K22/K25 -> 0.74626866 | M22: 542 | N22: =M22/M25 -> 0.6028921 | O22: 323 | P22: =O22/O25 -> 0.76179245 | Q22: 691 | R22: =Q22/Q25 -> 0.70582227
A23: Male | B23: 7964 | C23: =B23/B25 -> 0.42265032 | D23: =G23+I23+K23+M23+O23+Q23 -> 960 | E23: =D23/D25 -> 0.31704095 | F23: =D23/B23 -> 0.12054244 | G23: 154 | H23: =G23/G25 -> 0.31622177 | I23: 10 | J23: =I23/I25 -> 0.26315789 | K23: 51 | L23: =K23/K25 -> 0.25373134 | M23: 356 | N23: =M23/M25 -> 0.39599555 | O23: 101 | P23: =O23/O25 -> 0.23820755 | Q23: 288 | R23: =Q23/Q25 -> 0.29417773
A24: N | B24: 9 | C24: =B24/B25 -> 0.00047763095 | D24: =G24+I24+K24+M24+O24+Q24 -> 1 | E24: =D24/D25 -> 0.00033025099 | F24: =D24/B24 -> 0.11111111 | H24: =G24/G25 -> 0 | J24: =I24/I25 -> 0 | L24: =K24/K25 -> 0 | M24: 1 | N24: =M24/M25 -> 0.0011123471 | P24: =O24/O25 -> 0 | R24: =Q24/Q25 -> 0
A25: Total | B25: =SUM(B22:B24) -> 18843 | C25: =SUM(C22:C24) -> 1 | D25: =SUM(D22:D24) -> 3028 | E25: =SUM(E22:E24) -> 1 | F25: =D25/B25 -> 0.16069628 | G25: =SUM(G22:G24) -> 487 | H25: =SUM(H22:H24) -> 1 | I25: =SUM(I22:I24) -> 38 | J25: =SUM(J22:J24) -> 1 | K25: =SUM(K22:K24) -> 201 | L25: =SUM(L22:L24) -> 1 | M25: =SUM(M22:M24) -> 899 | N25: =SUM(N22:N24) -> 1 | ... R25: =SUM(R22:R24) -> 1
A27: Note: Students less than 18 years old were omitted from this survey because of uncertainty around confidentiality for underage students.
A28: Age | B28: Total | D28: Respondent | F28: % | G28: Boulder Cty | I28: Brighton | K28: CCCS Online | M28: Larimer | O28: FRCC Online | Q28: Westminster
A29: Less than 18 | C29: =B29/B36 -> 0
A30: 18 to 19 | B30: 3573 | C30: =B30/B36 -> 0.18961949 | D30: =G30+I30+K30+M30+O30+Q30 -> 456 | E30: =D30/D36 -> 0.15059445 | F30: =D30/B30 -> 0.12762385 | G30: 64 | H30: =G30/G36 -> 0.13141684 | I30: 9 | J30: =I30/I36 -> 0.23684211 | K30: 12 | L30: =K30/K36 -> 0.059701493 | M30: 188 | N30: =M30/M36 -> 0.20912125 | O30: 18 | P30: =O30/O36 -> 0.04245283 | Q30: 165 | R30: =Q30/Q36 -> 0.16853933 | S30: Respondents are older than the average student.
A31: 20 to 21 | B31: 3288 | C31: =B31/B36 -> 0.17449451 | D31: =G31+I31+K31+M31+O31+Q31 -> 331 | E31: =D31/D36 -> 0.10931308 | F31: =D31/B31 -> 0.1006691 | G31: 55 | H31: =G31/G36 -> 0.11293634 | I31: 4 | J31: =I31/I36 -> 0.10526316 | K31: 13 | L31: =K31/K36 -> 0.064676617 | M31: 125 | N31: =M31/M36 -> 0.13904338 | O31: 27 | P31: =O31/O36 -> 0.063679245 | Q31: 107 | R31: =Q31/Q36 -> 0.1092952
A32: 22 to 24 | B32: 3117 | C32: =B32/B36 -> 0.16541952 | D32: =G32+I32+K32+M32+O32+Q32 -> 337 | E32: =D32/D36 -> 0.11129458 | F32: =D32/B32 -> 0.10811678 | G32: 55 | H32: =G32/G36 -> 0.11293634 | I32: 4 | J32: =I32/I36 -> 0.10526316 | K32: 25 | L32: =K32/K36 -> 0.12437811 | M32: 103 | N32: =M32/M36 -> 0.11457175 | O32: 45 | P32: =O32/O36 -> 0.10613208 | Q32: 105 | R32: =Q32/Q36 -> 0.1072523 | S32: Boulder and FRCC online are the oldest students
A33: 25 to 30 | B33: 3699 | C33: =B33/B36 -> 0.19630632 | D33: =G33+I33+K33+M33+O33+Q33 -> 561 | E33: =D33/D36 -> 0.18527081 | F33: =D33/B33 -> 0.15166261 | G33: 97 | H33: =G33/G36 -> 0.19917864 | I33: 5 | J33: =I33/I36 -> 0.13157895 | K33: 41 | L33: =K33/K36 -> 0.2039801 | M33: 150 | N33: =M33/M36 -> 0.16685206 | O33: 81 | P33: =O33/O36 -> 0.19103774 | Q33: 187 | R33: =Q33/Q36 -> 0.19101124 | S33: Boulder and CCC online are the oldest students
A34: 31 to 40 | B34: 2909 | C34: =B34/B36 -> 0.15438094 | D34: =G34+I34+K34+M34+O34+Q34 -> 628 | E34: =D34/D36 -> 0.20739762 | F34: =D34/B34 -> 0.21588175 | G34: 91 | H34: =G34/G36 -> 0.18685832 | I34: 5 | J34: =I34/I36 -> 0.13157895 | K34: 58 | L34: =K34/K36 -> 0.28855721 | M34: 152 | N34: =M34/M36 -> 0.16907675 | O34: 121 | P34: =O34/O36 -> 0.28537736 | Q34: 201 | R34: =Q34/Q36 -> 0.20531154
A35: Over 40 | B35: 2257 | C35: =B35/B36 -> 0.11977923 | D35: =G35+I35+K35+M35+O35+Q35 -> 715 | E35: =D35/D36 -> 0.23612946 | F35: =D35/B35 -> 0.3167922 | G35: 125 | H35: =G35/G36 -> 0.25667351 | I35: 11 | J35: =I35/I36 -> 0.28947368 | K35: 52 | L35: =K35/K36 -> 0.25870647 | M35: 181 | N35: =M35/M36 -> 0.20133482 | O35: 132 | P35: =O35/O36 -> 0.31132075 | Q35: 214 | R35: =Q35/Q36 -> 0.2185904
A36: Total | B36: =SUM(B29:B35) -> 18843 | C36: =SUM(C29:C35) -> 1 | D36: =SUM(D29:D35) -> 3028 | E36: =SUM(E29:E35) -> 1 | F36: =D36/B36 -> 0.16069628 | G36: =SUM(G29:G35) -> 487 | H36: =SUM(H29:H35) -> 1 | I36: =SUM(I29:I35) -> 38 | J36: =SUM(J29:J35) -> 1 | K36: =SUM(K29:K35) -> 201 | L36: =SUM(L29:L35) -> 1 | M36: =SUM(M29:M35) -> 899 | N36: =SUM(N29:N35) -> 1 | ... R36: =SUM(R29:R35) -> 1
A37: Median | B37: 23.5 | D37: 30.182335 | G37: 31.736702 | I37: 26.028571 | K37: 30.552727 | M37: 28.564688 | O37: 33.744 | Q37: 29.272115
A39: Ethnicity | B39: Total | D39: Respondent | F39: % | G39: Boulder Cty | I39: Brighton | K39: CCCS Online | M39: Larimer | O39: FRCC Online | Q39: Westminster | S39: International Students have the highest response rates.
A40: 2 Or More | B40: 15 | C40: =B40/B48 -> 0.00079605158 | D40: =G40+I40+K40+M40+O40+Q40 -> 4 | E40: =D40/D48 -> 0.001321004 | F40: =D40/B40 -> 0.26666667 | I40: 1 | K40: 1 | L40: =K40/K48 -> 0.0049751244 | M40: 2 | N40: =M40/M48 -> 0.0022246941 | P40: =O40/O48 -> 0 | R40: =Q40/Q48 -> 0
A41: American Indian | B41: 338 | C41: =B41/B48 -> 0.017937696 | D41: =G41+I41+K41+M41+O41+Q41 -> 50 | E41: =D41/D48 -> 0.01651255 | F41: =D41/B41 -> 0.14792899 | G41: 9 | H41: =G41/G48 -> 0.018480493 | I41: 1 | J41: =I41/I48 -> 0.026315789 | K41: 3 | L41: =K41/K48 -> 0.014925373 | M41: 12 | N41: =M41/M48 -> 0.013348165 | O41: 7 | P41: =O41/O48 -> 0.016509434 | Q41: 18 | R41: =Q41/Q48 -> 0.018386108
A42: Asian | B42: 784 | C42: =B42/B48 -> 0.041606963 | D42: =G42+I42+K42+M42+O42+Q42 -> 92 | E42: =D42/D48 -> 0.030383091 | F42: =D42/B42 -> 0.11734694 | G42: 19 | H42: =G42/G48 -> 0.039014374 | I42: 1 | J42: =I42/I48 -> 0.026315789 | K42: 6 | L42: =K42/K48 -> 0.029850746 | M42: 14 | N42: =M42/M48 -> 0.015572859 | O42: 6 | P42: =O42/O48 -> 0.014150943 | Q42: 46 | R42: =Q42/Q48 -> 0.046986721
A43: Black | B43: 371 | C43: =B43/B48 -> 0.019689009 | D43: =G43+I43+K43+M43+O43+Q43 -> 56 | E43: =D43/D48 -> 0.018494055 | F43: =D43/B43 -> 0.1509434 | G43: 8 | H43: =G43/G48 -> 0.016427105 | J43: =I43/I48 -> 0 | K43: 4 | L43: =K43/K48 -> 0.019900498 | M43: 15 | N43: =M43/M48 -> 0.016685206 | O43: 4 | P43: =O43/O48 -> 0.0094339623 | Q43: 25 | R43: =Q43/Q48 -> 0.025536261
A44: Hispanic | B44: 2500 | C44: =B44/B48 -> 0.13267526 | D44: =G44+I44+K44+M44+O44+Q44 -> 334 | E44: =D44/D48 -> 0.11030383 | F44: =D44/B44 -> 0.1336 | G44: 53 | H44: =G44/G48 -> 0.10882957 | I44: 14 | J44: =I44/I48 -> 0.36842105 | K44: 16 | L44: =K44/K48 -> 0.07960199 | M44: 79 | N44: =M44/M48 -> 0.087875417 | O44: 41 | P44: =O44/O48 -> 0.096698113 | Q44: 131 | R44: =Q44/Q48 -> 0.13381001 | S44: Highest concentration of Hispancs are at Brighton
A45: International | B45: 190 | C45: =B45/B48 -> 0.01008332 | D45: =G45+I45+K45+M45+O45+Q45 -> 33 | E45: =D45/D48 -> 0.010898283 | F45: =D45/B45 -> 0.17368421 | G45: 6 | H45: =G45/G48 -> 0.012320329 | J45: =I45/I48 -> 0 | K45: 2 | L45: =K45/K48 -> 0.0099502488 | M45: 5 | N45: =M45/M48 -> 0.0055617353 | P45: =O45/O48 -> 0 | Q45: 20 | R45: =Q45/Q48 -> 0.020429009
...

Sheet Obj Emp 
A1: Survey of all Currently enrolled students Fall 2012 -- Objectives and Employment
A4: =all!A53 -> What is your primary objective in attending FRCC? | B4: Boulder Cty | D4: Brighton | F4: CCCS Onl | H4: Larimer | J4: FRCC Onl | L4: Westminster | N4: Total | P4: Obtaining transfer credits is the most common goal.
A5: =all!A54 -> Earn a Vocational/Technical Certificate | B5: =all!B54 -> 56 | C5: =B5/B14 -> 0.11965812 | D5: =all!D54 -> 1 | E5: =D5/D14 -> 0.027777778 | F5: =all!F54 -> 12 | G5: =F5/F14 -> 0.063492063 | H5: =all!H54 -> 42 | I5: =H5/H14 -> 0.047673099 | J5: =all!J54 -> 32 | K5: =J5/J14 -> 0.07748184 | L5: =all!L54 -> 41 | M5: =L5/L14 -> 0.042842215 | N5: =B5+D5+F5+H5+J5+L5 -> 184 | O5: =N5/N14 -> 0.0625
A6: =all!A55 -> Earn a Vocational/Technical Degree (AAS) | B6: =all!B55 -> 44 | C6: =all!C55 -> 0.094017094 | D6: =all!D55 -> 4 | E6: =all!E55 -> 0.11111111 | F6: =all!F55 -> 18 | G6: =all!G55 -> 0.095238095 | H6: =all!H55 -> 115 | ... O6: =all!O55 -> 0.10427989
A7: =all!A56 -> Earn an Academic Degree (AA, AS, AGS) | B7: =all!B56 -> 208 | C7: =all!C56 -> 0.02991453 | D7: =all!D56 -> 24 | E7: =all!E56 -> 0 | F7: =all!F56 -> 97 | G7: =all!G56 -> 0.026455026 | H7: =all!H56 -> 443 | ... O7: =all!O56 -> 0.024456522
A8: =all!A57 -> Improve skills for present job | B8: =all!B57 -> 14 | C8: =all!C57 -> 0.02991453 | D8: =all!D57 -> 0 | E8: =all!E57 -> 0 | F8: =all!F57 -> 5 | G8: =all!G57 -> 0.026455026 | H8: =all!H57 -> 13 | ... O8: =all!O57 -> 0.027513587
A9: =all!A58 -> Personal interest | B9: =all!B58 -> 14 | C9: =all!C58 -> 0.02991453 | D9: =all!D58 -> 0 | E9: =all!E58 -> 0 | F9: =all!F58 -> 5 | G9: =all!G58 -> 0.026455026 | H9: =all!H58 -> 25 | ... O9: =all!O58 -> 0.027513587
A10: =all!A59 -> Prepare to enter job market | B10: =all!B59 -> 9 | C10: =all!C59 -> 0.019230769 | D10: =all!D59 -> 1 | E10: =all!E59 -> 0.027777778 | F10: =all!F59 -> 1 | G10: =all!G59 -> 0.0052910053 | H10: =all!H59 -> 20 | ... O10: =all!O59 -> 0.021059783
A11: =all!A60 -> Receive financial aid benefits | B11: =all!B60 -> 0 | C11: =all!C60 -> 0 | D11: =all!D60 -> 0 | E11: =all!E60 -> 0 | F11: =all!F60 -> 0 | G11: =all!G60 -> 0 | H11: =all!H60 -> 1 | ... O11: =all!O60 -> 0.0016983696
A12: =all!A61 -> Take a few courses, transfer | B12: =all!B61 -> 122 | C12: =all!C61 -> 0.26068376 | D12: =all!D61 -> 6 | E12: =all!E61 -> 0.16666667 | F12: =all!F61 -> 50 | G12: =all!G61 -> 0.26455026 | H12: =all!H61 -> 219 | ... O12: =all!O61 -> 0.24592391
A13: =all!A62 -> Take concurrent college and high school courses | B13: =all!B62 -> 1 | C13: =all!C62 -> 0.0021367521 | D13: =all!D62 -> 0 | E13: =all!E62 -> 0 | F13: =all!F62 -> 1 | G13: =all!G62 -> 0.0052910053 | H13: =all!H62 -> 3 | ... O13: =all!O62 -> 0.0030570652
A14: Total | B14: =SUM(B5:B13) -> 468 | D14: =SUM(D5:D13) -> 36 | F14: =SUM(F5:F13) -> 189 | H14: =SUM(H5:H13) -> 881 | J14: =SUM(J5:J13) -> 413 | L14: =SUM(L5:L13) -> 957 | N14: =B14+D14+F14+H14+J14+L14 -> 2944
A17: =all!A65 -> Present employment status | B17: Boulder Cty | D17: Brighton | F17: CCCS Onl | H17: Larimer | J17: FRCC Onl | L17: Westminster | N17: Total
A18: =all!A66 -> Employed full or part-time in a job NOT RELATED to your FRCC program. | B18: =all!B66 -> 204 | C18: =all!C66 -> 0.4214876 | D18: =all!D66 -> 14 | E18: =all!E66 -> 0.36842105 | F18: =all!F66 -> 78 | G18: =all!G66 -> 0.39 | H18: =all!H66 -> 427 | ... O18: =all!O66 -> 0.44820717
A19: =all!A67 -> Employed full or part-time in a job RELATED to your FRCC program. | B19: =all!B67 -> 97 | C19: =all!C67 -> 0.20041322 | D19: =all!D67 -> 7 | E19: =all!E67 -> 0.18421053 | F19: =all!F67 -> 64 | G19: =all!G67 -> 0.32 | H19: =all!H67 -> 156 | ... O19: =all!O67 -> 0.21347942
A20: =all!A68 -> Military NOT RELATED to your FRCC program. | B20: =all!B68 -> 1 | C20: =all!C68 -> 0.0020661157 | D20: =all!D68 -> 0 | E20: =all!E68 -> 0 | F20: =all!F68 -> 1 | G20: =all!G68 -> 0.005 | H20: =all!H68 -> 4 | ... O20: =all!O68 -> 0.0026560425
A21: =all!A69 -> Military RELATED to your FRCC program. | B21: =all!B69 -> 2 | C21: =all!C69 -> 0.0041322314 | D21: =all!D69 -> 0 | E21: =all!E69 -> 0 | F21: =all!F69 -> 0 | G21: =all!G69 -> 0 | H21: =all!H69 -> 8 | ... O21: =all!O69 -> 0.005312085
A22: =all!A70 -> Unemployed -- NOT seeking employment. | B22: =all!B70 -> 88 | C22: =all!C70 -> 0.18181818 | D22: =all!D70 -> 7 | E22: =all!E70 -> 0.18421053 | F22: =all!F70 -> 26 | G22: =all!G70 -> 0.13 | H22: =all!H70 -> 135 | ... O22: =all!O70 -> 0.15471448
A23: =all!A71 -> Unemployed -- seeking employment. | B23: =all!B71 -> 92 | C23: =all!C71 -> 0.19008264 | D23: =all!D71 -> 10 | E23: =all!E71 -> 0.26315789 | F23: =all!F71 -> 31 | G23: =all!G71 -> 0.155 | H23: =all!H71 -> 165 | ... O23: =all!O71 -> 0.17563081
A24: =all!A72 -> Total | B24: =all!B72 -> 484 | C24: =all!C72 -> 1 | D24: =all!D72 -> 38 | E24: =all!E72 -> 1 | F24: =all!F72 -> 200 | G24: =all!G72 -> 1 | H24: =all!H72 -> 895 | ... O24: =all!O72 -> 1
A26: =all!A74 -> If employed, how many hours per week are you working | B26: Boulder Cty | D26: Brighton | F26: CCCS Onl | H26: Larimer | J26: FRCC Onl | L26: Westminster | N26: Total | P26: Online students are more likely to be full time workers.
A27: =all!A75 -> 20 or less | B27: =all!B75 -> 102 | C27: =all!C75 -> 0.31677019 | D27: =all!D75 -> 7 | E27: =all!E75 -> 0.30434783 | F27: =all!F75 -> 31 | G27: =all!G75 -> 0.21088435 | H27: =all!H75 -> 250 | ... O27: =all!O75 -> 0.31424447
A28: =all!A76 -> 21-39 | B28: =all!B76 -> 127 | C28: =all!C76 -> 0.39440994 | D28: =all!D76 -> 10 | E28: =all!E76 -> 0.43478261 | F28: =all!F76 -> 39 | G28: =all!G76 -> 0.26530612 | H28: =all!H76 -> 236 | ... O28: =all!O76 -> 0.35178056
A29: =all!A77 -> 40 or more | B29: =all!B77 -> 93 | C29: =all!C77 -> 0.28881988 | D29: =all!D77 -> 6 | E29: =all!E77 -> 0.26086957 | F29: =all!F77 -> 77 | G29: =all!G77 -> 0.52380952 | H29: =all!H77 -> 124 | ... O29: =all!O77 -> 0.33397498
A30: =all!A78 -> Total | B30: =all!B78 -> 322 | C30: =all!C78 -> 1 | D30: =all!D78 -> 23 | E30: =all!E78 -> 1 | F30: =all!F78 -> 147 | G30: =all!G78 -> 1 | H30: =all!H78 -> 610 | ... O30: =all!O78 -> 1
A32: =all!A80 -> How many credit hours are you taking this semester? | B32: Boulder Cty | D32: Brighton | F32: CCCS Onl | H32: Larimer | J32: FRCC Onl | L32: Westminster | N32: Total | P32: Larimer students are most likely to be full-time students
A33: =all!A81 -> 4 or less | B33: =all!B81 -> 99 | C33: =all!C81 -> 0.20412371 | D33: =all!D81 -> 6 | E33: =all!E81 -> 0.16216216 | F33: =all!F81 -> 48 | G33: =all!G81 -> 0.24120603 | H33: =all!H81 -> 98 | ... O33: =all!O81 -> 0.16422385
A34: =all!A82 -> 5 to 11 | B34: =all!B82 -> 230 | C34: =all!C82 -> 0.4742268 | D34: =all!D82 -> 25 | E34: =all!E82 -> 0.67567568 | F34: =all!F82 -> 116 | G34: =all!G82 -> 0.58291457 | H34: =all!H82 -> 360 | ... O34: =all!O82 -> 0.47435043
A35: =all!A83 -> 12 or more | B35: =all!B83 -> 156 | C35: =all!C83 -> 0.32164948 | D35: =all!D83 -> 6 | E35: =all!E83 -> 0.16216216 | F35: =all!F83 -> 35 | G35: =all!G83 -> 0.1758794 | H35: =all!H83 -> 436 | ... O35: =all!O83 -> 0.36142572
A36: =all!A84 -> Total | B36: =all!B84 -> 485 | C36: =all!C84 -> 1 | D36: =all!D84 -> 37 | E36: =all!E84 -> 1 | F36: =all!F84 -> 199 | G36: =all!G84 -> 1 | H36: =all!H84 -> 894 | ... O36: =all!O84 -> 1

Sheet Meeting needs
A1: Survey of all Currently enrolled students Fall 2012 -- Meeting Needs
A3: =all!A111 -> How would you rate your FRCC experience so far? | B3: Boulder Cty | D3: Brighton | F3: CCCS Onl | H3: Larimer | J3: FRCC Onl | L3: Westminster | N3: Total
A4: =all!A112 -> Very Good | B4: =all!B112 -> 232 | C4: =all!C112 -> 0.4813278 | D4: =all!D112 -> 16 | E4: =all!E112 -> 0.43243243 | F4: =all!F112 -> 64 | G4: =all!G112 -> 0.32323232 | H4: =all!H112 -> 397 | ... O4: =all!O112 -> 0.41898692
A5: =all!A113 -> Good | B5: =all!B113 -> 231 | C5: =all!C113 -> 0.47925311 | D5: =all!D113 -> 20 | E5: =all!E113 -> 0.54054054 | F5: =all!F113 -> 114 | G5: =all!G113 -> 0.57575758 | H5: =all!H113 -> 447 | ... O5: =all!O113 -> 0.52465616
A6: =all!A114 -> Poor | B6: =all!B114 -> 16 | C6: =all!C114 -> 0.033195021 | D6: =all!D114 -> 1 | E6: =all!E114 -> 0.027027027 | F6: =all!F114 -> 15 | G6: =all!G114 -> 0.075757576 | H6: =all!H114 -> 35 | ... O6: =all!O114 -> 0.044951359
A7: =all!A115 -> Very Poor | B7: =all!B115 -> 3 | C7: =all!C115 -> 0.0062240664 | D7: =all!D115 -> 0 | E7: =all!E115 -> 0 | F7: =all!F115 -> 5 | G7: =all!G115 -> 0.025252525 | H7: =all!H115 -> 7 | ... O7: =all!O115 -> 0.011405569
A8: =all!A116 -> Total | B8: =all!B116 -> 482 | C8: =all!C116 -> 1 | D8: =all!D116 -> 37 | E8: =all!E116 -> 1 | F8: =all!F116 -> 198 | G8: =all!G116 -> 1 | H8: =all!H116 -> 886 | ... O8: =all!O116 -> 1
A9: =all!A117 -> Percent of Good or Very Good | C9: =all!C117 -> 0.96058091 | E9: =all!E117 -> 0.97297297 | G9: =all!G117 -> 0.8989899 | I9: =all!I117 -> 0.95259594 | K9: =all!K117 -> 0.91885442 | M9: =all!M117 -> 0.94577685 | O9: =all!O117 -> 0.94364307
A11: =all!A86 -> Percent of question Respondents who agree with the following: | B11: Boulder Cty | D11: Brighton | F11: CCCS Onl | H11: Larimer | J11: FRCC Onl | L11: Westminster | N11: Total
A12: =all!A87 -> Instructional program is meeting your educational goals. | B12: =all!B87 -> 457 | C12: =all!C87 -> 0.93839836 | D12: =all!D87 -> 34 | E12: =all!E87 -> 0.89473684 | F12: =all!F87 -> 173 | G12: =all!G87 -> 0.87 | H12: =all!H87 -> 815 | ... O12: =all!O87 -> 0.89861295
A13: =all!A88 -> Technology is enhancing your learning process at FRCC. | B13: =all!B88 -> 401 | C13: =all!C88 -> 0.82340862 | D13: =all!D88 -> 35 | E13: =all!E88 -> 0.92105263 | F13: =all!F88 -> 173 | G13: =all!G88 -> 0.87373737 | H13: =all!H88 -> 762 | ... O13: =all!O88 -> 0.84577279
A14: =all!A89 -> Technology skills you are learning are complete and up to date | B14: =all!B89 -> 407 | C14: =all!C89 -> 0.88478261 | D14: =all!D89 -> 33 | E14: =all!E89 -> 0.89189189 | F14: =all!F89 -> 178 | G14: =all!G89 -> 0.90816327 | H14: =all!H89 -> 781 | ... O14: =all!O89 -> 0.85799207
A16: =all!A91 -> Faculty promote cultural diversity awareness and learning in the classroom | B16: Boulder Cty | D16: Brighton | F16: CCCS Onl | H16: Larimer | J16: FRCC Onl | L16: Westminster | N16: Total
A17: =all!A92 -> About right amount | B17: =all!B92 -> 323 | C17: =all!C92 -> 0.68 | D17: =all!D92 -> 31 | E17: =all!E92 -> 0.86111111 | F17: =all!F92 -> 104 | G17: =all!G92 -> 0.5388601 | H17: =all!H92 -> 615 | ... O17: =all!O92 -> 0.64899762
A18: =all!A93 -> Not enough | B18: =all!B93 -> 37 | C18: =all!C93 -> 0.077894737 | D18: =all!D93 -> 1 | E18: =all!E93 -> 0.027777778 | F18: =all!F93 -> 11 | G18: =all!G93 -> 0.056994819 | H18: =all!H93 -> 60 | ... O18: =all!O93 -> 0.078831125
A19: =all!A94 -> Too much | B19: =all!B94 -> 8 | C19: =all!C94 -> 0.016842105 | D19: =all!D94 -> 1 | E19: =all!E94 -> 0.027777778 | F19: =all!F94 -> 2 | G19: =all!G94 -> 0.010362694 | H19: =all!H94 -> 19 | ... O19: =all!O94 -> 0.016309888
A20: =all!A95 -> Don't know/ don't care | B20: =all!B95 -> 107 | C20: =all!C95 -> 0.22526316 | D20: =all!D95 -> 3 | E20: =all!E95 -> 0.083333333 | F20: =all!F95 -> 76 | G20: =all!G95 -> 0.39378238 | H20: =all!H95 -> 184 | ... O20: =all!O95 -> 0.25586137
B21: =all!B96 -> 475 | C21: =all!C96 -> 1 | D21: =all!D96 -> 36 | E21: =all!E96 -> 1 | F21: =all!F96 -> 193 | G21: =all!G96 -> 1 | H21: =all!H96 -> 878 | I21: =all!I96 -> 1 | ... O21: =all!O96 -> 1
A23: =all!A98 -> FRCC student life has programs that promote campus cultural diversity | B23: Boulder Cty | D23: Brighton | F23: CCCS Onl | H23: Larimer | J23: FRCC Onl | L23: Westminster | N23: Total
A24: =all!A99 -> About right amount | B24: =all!B99 -> 223 | C24: =all!C99 -> 0.47245763 | D24: =all!D99 -> 17 | E24: =all!E99 -> 0.47222222 | F24: =all!F99 -> 58 | G24: =all!G99 -> 0.30208333 | H24: =all!H99 -> 465 | ... O24: =all!O99 -> 0.4592845
A25: =all!A100 -> Not enough | B25: =all!B100 -> 37 | C25: =all!C100 -> 0.078389831 | D25: =all!D100 -> 2 | E25: =all!E100 -> 0.055555556 | F25: =all!F100 -> 10 | G25: =all!G100 -> 0.052083333 | H25: =all!H100 -> 67 | ... O25: =all!O100 -> 0.073935264
A26: =all!A101 -> Too much | B26: =all!B101 -> 9 | C26: =all!C101 -> 0.019067797 | D26: =all!D101 -> 0 | E26: =all!E101 -> 0 | F26: =all!F101 -> 1 | G26: =all!G101 -> 0.0052083333 | H26: =all!H101 -> 14 | ... O26: =all!O101 -> 0.014991482
A27: =all!A102 -> Don't know/don't care | B27: =all!B102 -> 203 | C27: =all!C102 -> 0.43008475 | D27: =all!D102 -> 17 | E27: =all!E102 -> 0.47222222 | F27: =all!F102 -> 123 | G27: =all!G102 -> 0.640625 | H27: =all!H102 -> 331 | ... O27: =all!O102 -> 0.45178876
B28: =all!B103 -> 472 | C28: =all!C103 -> 1 | D28: =all!D103 -> 36 | E28: =all!E103 -> 1 | F28: =all!F103 -> 192 | G28: =all!G103 -> 1 | H28: =all!H103 -> 877 | I28: =all!I103 -> 1 | ... O28: =all!O103 -> 1
A31: =all!A105 -> When do you prefer to take classes: | B31: Boulder Cty | D31: Brighton | F31: CCCS Onl | H31: Larimer | J31: FRCC Onl | L31: Westminster | N31: Total | P31: Campuses vary on when they prefer to take their courses, with the online students most likely to want evening/weekend classes.
A32: =all!A106 -> in the morning | B32: =all!B106 -> 302 | C32: =all!C106 -> 0.6201232 | D32: =all!D106 -> 20 | E32: =all!E106 -> 0.52631579 | F32: =all!F106 -> 67 | G32: =all!G106 -> 0.33333333 | H32: =all!H106 -> 583 | ... O32: =all!O106 -> 0.54887715
A33: =all!A107 -> in the afternoon | B33: =all!B107 -> 279 | C33: =all!C107 -> 0.57289528 | D33: =all!D107 -> 20 | E33: =all!E107 -> 0.52631579 | F33: =all!F107 -> 71 | G33: =all!G107 -> 0.35323383 | H33: =all!H107 -> 559 | ... O33: =all!O107 -> 0.52972259
A34: =all!A108 -> in the evening | B34: =all!B108 -> 183 | C34: =all!C108 -> 0.37577002 | D34: =all!D108 -> 16 | E34: =all!E108 -> 0.42105263 | F34: =all!F108 -> 129 | G34: =all!G108 -> 0.64179104 | H34: =all!H108 -> 293 | ... O34: =all!O108 -> 0.43064729
A35: =all!A109 -> on the weekend | B35: =all!B109 -> 54 | C35: =all!C109 -> 0.11088296 | D35: =all!D109 -> 4 | E35: =all!E109 -> 0.10526316 | F35: =all!F109 -> 72 | G35: =all!G109 -> 0.35820896 | H35: =all!H109 -> 60 | ... O35: =all!O109 -> 0.15323646

Sheet Evaluate Instruction
A1: Survey of all Currently enrolled students Fall 2012 -- Evaluate Instruction
A2: Course Availability had the lowest level of satisfaction.
A4: EVALUATE FRCC INSTRUCTION
A5: =all!A121 -> Quality of instruction | B5: Boulder Cty | D5: Brighton | F5: CCCS Onl | H5: Larimer | J5: FRCC Onl | L5: Westminster | N5: Total | Q5: EVALUATE FRCC INSTRUCTION | R5: Boulder Cty | S5: Brighton | T5: CCCS Onl | U5: Larimer | V5: FRCC Onl | W5: Westminster | X5: Total
A6: Very good | B6: =all!B122 -> 234 | C6: =all!C122 -> 0.4875 | D6: =all!D122 -> 19 | E6: =all!E122 -> 0.52777778 | F6: =all!F122 -> 55 | G6: =all!G122 -> 0.28497409 | H6: =all!H122 -> 406 | I6: =all!I122 -> 0.45823928 | ... O6: =all!O122 -> 0.43941951 | Q6: Quality of instruction | R6: =C11 -> 0.94583333 | S6: =E11 -> 0.91666667 | T6: =G11 -> 0.87564767 | U6: =I11 -> 0.9503386 | V6: =K11 -> 0.92251816 | W6: =M11 -> 0.94031414 | X6: =O11 -> 0.93722578
A7: Good | B7: =all!B123 -> 220 | C7: =all!C123 -> 0.45833333 | D7: =all!D123 -> 14 | E7: =all!E123 -> 0.38888889 | F7: =all!F123 -> 114 | G7: =all!G123 -> 0.59067358 | H7: =all!H123 -> 436 | I7: =all!I123 -> 0.49209932 | ... O7: =all!O123 -> 0.49780628 | Q7: Instructor's knowledge of subject(s) | R7: =C19 -> 0.98121086 | S7: =E19 -> 1 | T7: =G19 -> 0.95811518 | U7: =I19 -> 0.97175141 | V7: =K19 -> 0.98062954 | W7: =M19 -> 0.9707419 | X7: =O19 -> 0.97365755
A8: Poor | B8: =all!B124 -> 23 | C8: =all!C124 -> 0.047916667 | D8: =all!D124 -> 3 | E8: =all!E124 -> 0.083333333 | F8: =all!F124 -> 16 | G8: =all!G124 -> 0.082901554 | H8: =all!H124 -> 32 | I8: =all!I124 -> 0.036117381 | ... O8: =all!O124 -> 0.047249409 | Q8: Course objectives & requirements made clear | R8: =C27 -> 0.9539749 | S8: =E27 -> 0.97297297 | T8: =G27 -> 0.82901554 | U8: =I27 -> 0.9399093 | V8: =K27 -> 0.89638554 | W8: =M27 -> 0.92050209 | X8: =O27 -> 0.92299899
A9: Very poor | B9: =all!B125 -> 3 | C9: =all!C125 -> 0.00625 | D9: =all!D125 -> 0 | E9: =all!E125 -> 0 | F9: =all!F125 -> 8 | G9: =all!G125 -> 0.041450777 | H9: =all!H125 -> 12 | I9: =all!I125 -> 0.013544018 | ... O9: =all!O125 -> 0.015524806 | Q9: Content of course(s) | R9: =C35 -> 0.96861925 | S9: =E35 -> 0.97142857 | T9: =G35 -> 0.9015544 | U9: =I35 -> 0.96493213 | V9: =K35 -> 0.94698795 | W9: =M35 -> 0.95702306 | X9: =O35 -> 0.95640419
A10: Total | B10: =all!B126 -> 480 | C10: =all!C126 -> 1 | D10: =all!D126 -> 36 | E10: =all!E126 -> 1 | F10: =all!F126 -> 193 | G10: =all!G126 -> 1 | H10: =all!H126 -> 886 | I10: =all!I126 -> 1 | ... O10: =all!O126 -> 1 | Q10: Instructional methods | R10: =C43 -> 0.91841004 | S10: =E43 -> 0.91666667 | T10: =G43 -> 0.83419689 | U10: =I43 -> 0.91269841 | V10: =K43 -> 0.87651332 | W10: =M43 -> 0.88272251 | X10: =O43 -> 0.8938113
A11: Percent of Good or Very Good | C11: =all!C127 -> 0.94583333 | E11: =all!E127 -> 0.91666667 | G11: =all!G127 -> 0.87564767 | I11: =all!I127 -> 0.9503386 | K11: =all!K127 -> 0.92251816 | M11: =all!M127 -> 0.94031414 | O11: =all!O127 -> 0.93722578 | Q11: Testing and grading | R11: =C51 -> 0.93096234 | S11: =E51 -> 0.91891892 | T11: =G51 -> 0.85416667 | U11: =I51 -> 0.90702948 | V11: =K51 -> 0.87710843 | W11: =M51 -> 0.90062762 | X11: =O51 -> 0.90135135
Q12: Class Size | R12: =C59 -> 0.98953975 | S12: =E59 -> 0.97297297 | T12: =G59 -> 0.9893617 | U12: =I59 -> 0.97954545 | V12: =K59 -> 0.98300971 | W12: =M59 -> 0.97172775 | X12: =O59 -> 0.97966102
A13: =all!A129 -> Instructor's knowledge of subject(s) | B13: Boulder Cty | D13: Brighton | F13: CCCS Onl | H13: Larimer | J13: FRCC Onl | L13: Westminster | N13: Total | Q13: Course availability | R13: =C67 -> 0.83682008 | S13: =E67 -> 0.83333333 | T13: =G67 -> 0.90052356 | U13: =I67 -> 0.79431818 | V13: =K67 -> 0.84261501 | W13: =M67 -> 0.7775446 | X13: =O67 -> 0.80989495
A14: Very good | B14: =all!B130 -> 323 | C14: =all!C130 -> 0.6743215 | D14: =all!D130 -> 25 | E14: =all!E130 -> 0.69444444 | F14: =all!F130 -> 97 | G14: =all!G130 -> 0.5078534 | H14: =all!H130 -> 552 | I14: =all!I130 -> 0.62372881 | ... O14: =all!O130 -> 0.61465721 | Q14: Overall Evaluation of Instruction | R14: =C75 -> 0.96666667 | S14: =E75 -> 0.89189189 | T14: =G75 -> 0.89473684 | U14: =I75 -> 0.95464853 | V14: =K75 -> 0.93946731 | W14: =M75 -> 0.94549266 | X14: =O75 -> 0.94688769
A15: Good | B15: =all!B131 -> 147 | C15: =all!C131 -> 0.30688935 | D15: =all!D131 -> 11 | E15: =all!E131 -> 0.30555556 | F15: =all!F131 -> 86 | G15: =all!G131 -> 0.45026178 | H15: =all!H131 -> 308 | I15: =all!I131 -> 0.3480226 | ... O15: =all!O131 -> 0.35900034
A16: Poor | B16: =all!B132 -> 8 | C16: =all!C132 -> 0.016701461 | D16: =all!D132 -> 0 | E16: =all!E132 -> 0 | F16: =all!F132 -> 8 | G16: =all!G132 -> 0.041884817 | H16: =all!H132 -> 20 | I16: =all!I132 -> 0.02259887 | ... O16: =all!O132 -> 0.021952043
A17: Very poor | B17: =all!B133 -> 1 | C17: =all!C133 -> 0.0020876827 | D17: =all!D133 -> 0 | E17: =all!E133 -> 0 | F17: =all!F133 -> 0 | G17: =all!G133 -> 0 | H17: =all!H133 -> 5 | I17: =all!I133 -> 0.0056497175 | ... O17: =all!O133 -> 0.0043904086
A18: Total | B18: =all!B134 -> 479 | C18: =all!C134 -> 1 | D18: =all!D134 -> 36 | E18: =all!E134 -> 1 | F18: =all!F134 -> 191 | G18: =all!G134 -> 1 | H18: =all!H134 -> 885 | I18: =all!I134 -> 1 | ... O18: =all!O134 -> 1
A19: Percent of Good or Very Good | C19: =all!C135 -> 0.98121086 | E19: =all!E135 -> 1 | G19: =all!G135 -> 0.95811518 | I19: =all!I135 -> 0.97175141 | K19: =all!K135 -> 0.98062954 | M19: =all!M135 -> 0.9707419 | O19: =all!O135 -> 0.97365755
A21: =all!A137 -> Course objectives & requirements made clear | B21: Boulder Cty | D21: Brighton | F21: CCCS Onl | H21: Larimer | J21: FRCC Onl | L21: Westminster | N21: Total
A22: Very good | B22: =all!B138 -> 254 | C22: =all!C138 -> 0.53138075 | D22: =all!D138 -> 18 | E22: =all!E138 -> 0.48648649 | F22: =all!F138 -> 76 | G22: =all!G138 -> 0.39378238 | H22: =all!H138 -> 443 | I22: =all!I138 -> 0.50226757 | ... O22: =all!O138 -> 0.48024316
A23: Good | B23: =all!B139 -> 202 | C23: =all!C139 -> 0.42259414 | D23: =all!D139 -> 18 | E23: =all!E139 -> 0.48648649 | F23: =all!F139 -> 84 | G23: =all!G139 -> 0.43523316 | H23: =all!H139 -> 386 | I23: =all!I139 -> 0.43764172 | ... O23: =all!O139 -> 0.44275583
A24: Poor | B24: =all!B140 -> 20 | C24: =all!C140 -> 0.041841004 | D24: =all!D140 -> 1 | E24: =all!E140 -> 0.027027027 | F24: =all!F140 -> 25 | G24: =all!G140 -> 0.12953368 | H24: =all!H140 -> 46 | I24: =all!I140 -> 0.052154195 | ... O24: =all!O140 -> 0.065518406
A25: Very poor | B25: =all!B141 -> 2 | C25: =all!C141 -> 0.0041841004 | D25: =all!D141 -> 0 | E25: =all!E141 -> 0 | F25: =all!F141 -> 8 | G25: =all!G141 -> 0.041450777 | H25: =all!H141 -> 7 | I25: =all!I141 -> 0.0079365079 | ... O25: =all!O141 -> 0.011482607
A26: Total | B26: =all!B142 -> 478 | C26: =all!C142 -> 1 | D26: =all!D142 -> 37 | E26: =all!E142 -> 1 | F26: =all!F142 -> 193 | G26: =all!G142 -> 1 | H26: =all!H142 -> 882 | I26: =all!I142 -> 1 | ... O26: =all!O142 -> 1
A27: Percent of Good or Very Good | C27: =all!C143 -> 0.9539749 | E27: =all!E143 -> 0.97297297 | G27: =all!G143 -> 0.82901554 | I27: =all!I143 -> 0.9399093 | K27: =all!K143 -> 0.89638554 | M27: =all!M143 -> 0.92050209 | O27: =all!O143 -> 0.92299899
A29: =all!A145 -> Content of course(s) | B29: Boulder Cty | D29: Brighton | F29: CCCS Onl | H29: Larimer | J29: FRCC Onl | L29: Westminster | N29: Total
A30: Very good | B30: =all!B146 -> 240 | C30: =all!C146 -> 0.50209205 | D30: =all!D146 -> 19 | E30: =all!E146 -> 0.54285714 | F30: =all!F146 -> 71 | G30: =all!G146 -> 0.36787565 | H30: =all!H146 -> 393 | I30: =all!I146 -> 0.44457014 | ... O30: =all!O146 -> 0.44474485
A31: Good | B31: =all!B147 -> 223 | C31: =all!C147 -> 0.4665272 | D31: =all!D147 -> 15 | E31: =all!E147 -> 0.42857143 | F31: =all!F147 -> 103 | G31: =all!G147 -> 0.53367876 | H31: =all!H147 -> 460 | I31: =all!I147 -> 0.52036199 | ... O31: =all!O147 -> 0.51165934
A32: Poor | B32: =all!B148 -> 12 | C32: =all!C148 -> 0.025104603 | D32: =all!D148 -> 1 | E32: =all!E148 -> 0.028571429 | F32: =all!F148 -> 15 | G32: =all!G148 -> 0.077720207 | H32: =all!H148 -> 27 | I32: =all!I148 -> 0.030542986 | ... O32: =all!O148 -> 0.035147009
A33: Very poor | B33: =all!B149 -> 3 | C33: =all!C149 -> 0.0062761506 | D33: =all!D149 -> 0 | E33: =all!E149 -> 0 | F33: =all!F149 -> 4 | G33: =all!G149 -> 0.020725389 | H33: =all!H149 -> 4 | I33: =all!I149 -> 0.0045248869 | ... O33: =all!O149 -> 0.0084488003
A34: Total | B34: =all!B150 -> 478 | C34: =all!C150 -> 1 | D34: =all!D150 -> 35 | E34: =all!E150 -> 1 | F34: =all!F150 -> 193 | G34: =all!G150 -> 1 | H34: =all!H150 -> 884 | I34: =all!I150 -> 1 | ... O34: =all!O150 -> 1
A35: Percent of Good or Very Good | C35: =all!C151 -> 0.96861925 | E35: =all!E151 -> 0.97142857 | G35: =all!G151 -> 0.9015544 | I35: =all!I151 -> 0.96493213 | K35: =all!K151 -> 0.94698795 | M35: =all!M151 -> 0.95702306 | O35: =all!O151 -> 0.95640419
A37: =all!A153 -> Instructional methods | B37: Boulder Cty | D37: Brighton | F37: CCCS Onl | H37: Larimer | J37: FRCC Onl | L37: Westminster | N37: Total
A38: Very good | B38: =all!B154 -> 198 | C38: =all!C154 -> 0.41422594 | D38: =all!D154 -> 14 | E38: =all!E154 -> 0.38888889 | F38: =all!F154 -> 56 | G38: =all!G154 -> 0.29015544 | H38: =all!H154 -> 340 | I38: =all!I154 -> 0.38548753 | ... O38: =all!O154 -> 0.37876226
A39: Good | B39: =all!B155 -> 241 | C39: =all!C155 -> 0.5041841 | D39: =all!D155 -> 19 | E39: =all!E155 -> 0.52777778 | F39: =all!F155 -> 105 | G39: =all!G155 -> 0.54404145 | H39: =all!H155 -> 465 | I39: =all!I155 -> 0.52721088 | ... O39: =all!O155 -> 0.51504904
A40: Poor | B40: =all!B156 -> 36 | C40: =all!C156 -> 0.075313808 | D40: =all!D156 -> 2 | E40: =all!E156 -> 0.055555556 | F40: =all!F156 -> 23 | G40: =all!G156 -> 0.11917098 | H40: =all!H156 -> 68 | I40: =all!I156 -> 0.077097506 | ... O40: =all!O156 -> 0.086574231
A41: Very poor | B41: =all!B157 -> 3 | C41: =all!C157 -> 0.0062761506 | D41: =all!D157 -> 1 | E41: =all!E157 -> 0.027777778 | F41: =all!F157 -> 9 | G41: =all!G157 -> 0.046632124 | H41: =all!H157 -> 9 | I41: =all!I157 -> 0.010204082 | ... O41: =all!O157 -> 0.019614474
A42: Total | B42: =all!B158 -> 478 | C42: =all!C158 -> 1 | D42: =all!D158 -> 36 | E42: =all!E158 -> 1 | F42: =all!F158 -> 193 | G42: =all!G158 -> 1 | H42: =all!H158 -> 882 | I42: =all!I158 -> 1 | ... O42: =all!O158 -> 1
A43: Percent of Good or Very Good | C43: =all!C159 -> 0.91841004 | E43: =all!E159 -> 0.91666667 | G43: =all!G159 -> 0.83419689 | I43: =all!I159 -> 0.91269841 | K43: =all!K159 -> 0.87651332 | M43: =all!M159 -> 0.88272251 | O43: =all!O159 -> 0.8938113
A45: =all!A161 -> Testing and grading | B45: Boulder Cty | D45: Brighton | F45: CCCS Onl | H45: Larimer | J45: FRCC Onl | L45: Westminster | N45: Total
...

Sheet Pers Grow
A1: Survey of all Currently enrolled students Fall 2012 -- Evaluate Personal Growth
A2: The only question that fell below 90% satisfaction was Math abilities
A4: EVALUATE PERSONAL GROWTH
A5: =all!A194 -> Ability to organize ideas | B5: Boulder Cty | D5: Brighton | F5: CCCS Onl | H5: Larimer | J5: FRCC Onl | L5: Westminster | N5: Total | Q5: EVALUATE FRCC INSTRUCTION | R5: Boulder Cty | S5: Brighton | T5: CCCS Onl | U5: Larimer | V5: FRCC Onl | W5: Westminster | X5: Total
A6: =all!A195 -> Very satisfied | B6: =all!B195 -> 107 | C6: =all!C195 -> 0.30571429 | D6: =all!D195 -> 8 | E6: =all!E195 -> 0.25806452 | F6: =all!F195 -> 42 | G6: =all!G195 -> 0.30215827 | H6: =all!H195 -> 230 | ... O6: =all!O195 -> 0.3414966 | Q6: =A5 -> Ability to organize ideas | R6: =C11 -> 0.94285714 | S6: =E11 -> 0.96774194 | T6: =G11 -> 0.95683453 | U6: =I11 -> 0.95776772 | V6: =K11 -> 0.97068404 | W6: =M11 -> 0.95244755 | X6: =O11 -> 0.95555556
A7: =all!A196 -> Satisfied | B7: =all!B196 -> 223 | C7: =all!C196 -> 0.63714286 | D7: =all!D196 -> 22 | E7: =all!E196 -> 0.70967742 | F7: =all!F196 -> 91 | G7: =all!G196 -> 0.65467626 | H7: =all!H196 -> 405 | ... O7: =all!O196 -> 0.61405896 | Q7: =A13 -> Ability to think critically | R7: =C19 -> 0.95639535 | S7: =E19 -> 0.96666667 | T7: =G19 -> 0.95555556 | U7: =I19 -> 0.95945946 | V7: =K19 -> 0.96825397 | W7: =M19 -> 0.95524476 | X7: =O19 -> 0.95873016
A8: =all!A197 -> Dissatisfied | B8: =all!B197 -> 20 | C8: =all!C197 -> 0.057142857 | D8: =all!D197 -> 1 | E8: =all!E197 -> 0.032258065 | F8: =all!F197 -> 6 | G8: =all!G197 -> 0.043165468 | H8: =all!H197 -> 25 | ... O8: =all!O197 -> 0.041723356 | Q8: =A21 -> Ability to write with clarity | R8: =C27 -> 0.93215339 | S8: =E27 -> 0.875 | T8: =G27 -> 0.93571429 | U8: =I27 -> 0.93500739 | V8: =K27 -> 0.94603175 | W8: =M27 -> 0.93681319 | X8: =O27 -> 0.93590318
A9: =all!A198 -> Very dissatisfied | B9: =all!B198 -> 0 | C9: =all!C198 -> 0 | D9: =all!D198 -> 0 | E9: =all!E198 -> 0 | F9: =all!F198 -> 0 | G9: =all!G198 -> 0 | H9: =all!H198 -> 3 | ... O9: =all!O198 -> 0.0027210884 | Q9: =A29 -> Ability to speak with clarity | R9: =C35 -> 0.93235294 | S9: =E35 -> 0.90322581 | T9: =G35 -> 0.93430657 | U9: =I35 -> 0.94680851 | V9: =K35 -> 0.95192308 | W9: =M35 -> 0.92468619 | X9: =O35 -> 0.93667426
A10: Total | B10: =all!B199 -> 350 | C10: =all!C199 -> 1 | D10: =all!D199 -> 31 | E10: =all!E199 -> 1 | F10: =all!F199 -> 139 | G10: =all!G199 -> 1 | H10: =all!H199 -> 663 | I10: =all!I199 -> 1 | ... O10: =all!O199 -> 1 | Q10: =A37 -> Ability and skills in problem solving | R10: =C43 -> 0.94428152 | S10: =E43 -> 0.90322581 | T10: =G43 -> 0.96946565 | U10: =I43 -> 0.95684524 | V10: =K43 -> 0.95145631 | W10: =M43 -> 0.94182825 | X10: =O43 -> 0.94922937
A11: Percent of Satisfied or Very Satisfied | C11: =SUM(C6:C7) -> 0.94285714 | E11: =SUM(E6:E7) -> 0.96774194 | G11: =SUM(G6:G7) -> 0.95683453 | I11: =SUM(I6:I7) -> 0.95776772 | K11: =SUM(K6:K7) -> 0.97068404 | M11: =SUM(M6:M7) -> 0.95244755 | O11: =SUM(O6:O7) -> 0.95555556 | Q11: =A45 -> Knowledge of methods & achievements in the social sciences | R11: =C51 -> 0.93055556 | S11: =E51 -> 0.96774194 | T11: =G51 -> 0.95620438 | U11: =I51 -> 0.92927864 | V11: =K51 -> 0.94476744 | W11: =M51 -> 0.90105541 | X11: =O51 -> 0.92468977
Q12: =A53 -> Knowledge of methods & achievements in science | R12: =C59 -> 0.9027027 | S12: =E59 -> 0.89285714 | T12: =G59 -> 0.90909091 | U12: =I59 -> 0.90055249 | V12: =K59 -> 0.91540785 | W12: =M59 -> 0.86804657 | X12: =O59 -> 0.89278176
A13: =all!A202 -> Ability to think critically | B13: Boulder Cty | D13: Brighton | F13: CCCS Onl | H13: Larimer | J13: FRCC Onl | L13: Westminster | N13: Total | Q13: =A61 -> Knowledge & skills in mathematics | R13: =C67 -> 0.85082873 | S13: =E67 -> 0.87096774 | T13: =G67 -> 0.89333333 | U13: =I67 -> 0.84195804 | V13: =K67 -> 0.87869822 | W13: =M67 -> 0.83118557 | X13: =O67 -> 0.84865093
A14: =all!A203 -> Very satisfied | B14: =all!B203 -> 118 | C14: =all!C203 -> 0.34302326 | D14: =all!D203 -> 6 | E14: =all!E203 -> 0.2 | F14: =all!F203 -> 49 | G14: =all!G203 -> 0.36296296 | H14: =all!H203 -> 259 | ... O14: =all!O203 -> 0.37369615 | Q14: =A69 -> Awareness & appreciation of the arts and humanities | R14: =C75 -> 0.93162393 | S14: =E75 -> 0.93333333 | T14: =G75 -> 0.94160584 | U14: =I75 -> 0.94023324 | V14: =K75 -> 0.93230769 | W14: =M75 -> 0.89509537 | X14: =O75 -> 0.92311091
A15: =all!A204 -> Satisfied | B15: =all!B204 -> 211 | C15: =all!C204 -> 0.61337209 | D15: =all!D204 -> 23 | E15: =all!E204 -> 0.76666667 | F15: =all!F204 -> 80 | G15: =all!G204 -> 0.59259259 | H15: =all!H204 -> 380 | ... O15: =all!O204 -> 0.58503401 | Q15: =A77 -> Awareness & understanding of ethics | R15: =C83 -> 0.93678161 | S15: =E83 -> 0.93333333 | T15: =G83 -> 0.94615385 | U15: =I83 -> 0.93645991 | V15: =K83 -> 0.95015576 | W15: =M83 -> 0.91725105 | X15: =O83 -> 0.93281888
A16: =all!A205 -> Dissatisfied | B16: =all!B205 -> 15 | C16: =all!C205 -> 0.043604651 | D16: =all!D205 -> 1 | E16: =all!E205 -> 0.033333333 | F16: =all!F205 -> 6 | G16: =all!G205 -> 0.044444444 | H16: =all!H205 -> 22 | ... O16: =all!O205 -> 0.036281179
A17: =all!A206 -> Very dissatisfied | B17: =all!B206 -> 0 | C17: =all!C206 -> 0 | D17: =all!D206 -> 0 | E17: =all!E206 -> 0 | F17: =all!F206 -> 0 | G17: =all!G206 -> 0 | H17: =all!H206 -> 5 | ... O17: =all!O206 -> 0.0049886621
A18: Total | B18: =all!B207 -> 344 | C18: =all!C207 -> 1 | D18: =all!D207 -> 30 | E18: =all!E207 -> 1 | F18: =all!F207 -> 135 | G18: =all!G207 -> 1 | H18: =all!H207 -> 666 | I18: =all!I207 -> 1 | ... O18: =all!O207 -> 1
A19: Percent of Satisfied or Very Satisfied | C19: =SUM(C14:C15) -> 0.95639535 | E19: =SUM(E14:E15) -> 0.96666667 | G19: =SUM(G14:G15) -> 0.95555556 | I19: =SUM(I14:I15) -> 0.95945946 | K19: =SUM(K14:K15) -> 0.96825397 | M19: =SUM(M14:M15) -> 0.95524476 | O19: =SUM(O14:O15) -> 0.95873016
A21: =all!A210 -> Ability to write with clarity | B21: Boulder Cty | D21: Brighton | F21: CCCS Onl | H21: Larimer | J21: FRCC Onl | L21: Westminster | N21: Total
A22: =all!A211 -> Very satisfied | B22: =all!B211 -> 118 | C22: =all!C211 -> 0.3480826 | D22: =all!D211 -> 9 | E22: =all!E211 -> 0.28125 | F22: =all!F211 -> 45 | G22: =all!G211 -> 0.32142857 | H22: =all!H211 -> 240 | ... O22: =all!O211 -> 0.35992828
A23: =all!A212 -> Satisfied | B23: =all!B212 -> 198 | C23: =all!C212 -> 0.5840708 | D23: =all!D212 -> 19 | E23: =all!E212 -> 0.59375 | F23: =all!F212 -> 86 | G23: =all!G212 -> 0.61428571 | H23: =all!H212 -> 393 | ... O23: =all!O212 -> 0.5759749
A24: =all!A213 -> Dissatisfied | B24: =all!B213 -> 22 | C24: =all!C213 -> 0.064896755 | D24: =all!D213 -> 3 | E24: =all!E213 -> 0.09375 | F24: =all!F213 -> 8 | G24: =all!G213 -> 0.057142857 | H24: =all!H213 -> 39 | ... O24: =all!O213 -> 0.056925146
A25: =all!A214 -> Very dissatisfied | B25: =all!B214 -> 1 | C25: =all!C214 -> 0.0029498525 | D25: =all!D214 -> 1 | E25: =all!E214 -> 0.03125 | F25: =all!F214 -> 1 | G25: =all!G214 -> 0.0071428571 | H25: =all!H214 -> 5 | ... O25: =all!O214 -> 0.0071716719
A26: Total | B26: =all!B215 -> 339 | C26: =all!C215 -> 1 | D26: =all!D215 -> 32 | E26: =all!E215 -> 1 | F26: =all!F215 -> 140 | G26: =all!G215 -> 1 | H26: =all!H215 -> 677 | I26: =all!I215 -> 1 | ... O26: =all!O215 -> 1
A27: Percent of Satisfied or Very Satisfied | C27: =SUM(C22:C23) -> 0.93215339 | E27: =SUM(E22:E23) -> 0.875 | G27: =SUM(G22:G23) -> 0.93571429 | I27: =SUM(I22:I23) -> 0.93500739 | K27: =SUM(K22:K23) -> 0.94603175 | M27: =SUM(M22:M23) -> 0.93681319 | O27: =SUM(O22:O23) -> 0.93590318
A29: =all!A218 -> Ability to speak with clarity | B29: Boulder Cty | D29: Brighton | F29: CCCS Onl | H29: Larimer | J29: FRCC Onl | L29: Westminster | N29: Total
A30: =all!A219 -> Very satisfied | B30: =all!B219 -> 103 | C30: =all!C219 -> 0.30294118 | D30: =all!D219 -> 7 | E30: =all!E219 -> 0.22580645 | F30: =all!F219 -> 39 | G30: =all!G219 -> 0.28467153 | H30: =all!H219 -> 231 | ... O30: =all!O219 -> 0.34031891
A31: =all!A220 -> Satisfied | B31: =all!B220 -> 214 | C31: =all!C220 -> 0.62941176 | D31: =all!D220 -> 21 | E31: =all!E220 -> 0.67741935 | F31: =all!F220 -> 89 | G31: =all!G220 -> 0.64963504 | H31: =all!H220 -> 392 | ... O31: =all!O220 -> 0.59635535
A32: =all!A221 -> Dissatisfied | B32: =all!B221 -> 23 | C32: =all!C221 -> 0.067647059 | D32: =all!D221 -> 3 | E32: =all!E221 -> 0.096774194 | F32: =all!F221 -> 8 | G32: =all!G221 -> 0.058394161 | H32: =all!H221 -> 32 | ... O32: =all!O221 -> 0.056492027
A33: =all!A222 -> Very dissatisfied | B33: =all!B222 -> 0 | C33: =all!C222 -> 0 | D33: =all!D222 -> 0 | E33: =all!E222 -> 0 | F33: =all!F222 -> 1 | G33: =all!G222 -> 0.0072992701 | H33: =all!H222 -> 3 | ... O33: =all!O222 -> 0.006833713
A34: Total | B34: =all!B223 -> 340 | C34: =all!C223 -> 1 | D34: =all!D223 -> 31 | E34: =all!E223 -> 1 | F34: =all!F223 -> 137 | G34: =all!G223 -> 1 | H34: =all!H223 -> 658 | I34: =all!I223 -> 1 | ... O34: =all!O223 -> 1
A35: Percent of Satisfied or Very Satisfied | C35: =SUM(C30:C31) -> 0.93235294 | E35: =SUM(E30:E31) -> 0.90322581 | G35: =SUM(G30:G31) -> 0.93430657 | I35: =SUM(I30:I31) -> 0.94680851 | K35: =SUM(K30:K31) -> 0.95192308 | M35: =SUM(M30:M31) -> 0.92468619 | O35: =SUM(O30:O31) -> 0.93667426
A37: =all!A226 -> Ability and skills in problem solving | B37: Boulder Cty | D37: Brighton | F37: CCCS Onl | H37: Larimer | J37: FRCC Onl | L37: Westminster | N37: Total
A38: =all!A227 -> Very satisfied | B38: =all!B227 -> 104 | C38: =all!C227 -> 0.30498534 | D38: =all!D227 -> 6 | E38: =all!E227 -> 0.19354839 | F38: =all!F227 -> 44 | G38: =all!G227 -> 0.33587786 | H38: =all!H227 -> 246 | ... O38: =all!O227 -> 0.35539438
A39: =all!A228 -> Satisfied | B39: =all!B228 -> 218 | C39: =all!C228 -> 0.63929619 | D39: =all!D228 -> 22 | E39: =all!E228 -> 0.70967742 | F39: =all!F228 -> 83 | G39: =all!G228 -> 0.63358779 | H39: =all!H228 -> 397 | ... O39: =all!O228 -> 0.593835
A40: =all!A229 -> Dissatisfied | B40: =all!B229 -> 18 | C40: =all!C229 -> 0.052785924 | D40: =all!D229 -> 2 | E40: =all!E229 -> 0.064516129 | F40: =all!F229 -> 4 | G40: =all!G229 -> 0.030534351 | H40: =all!H229 -> 24 | ... O40: =all!O229 -> 0.04306437
A41: =all!A230 -> Very dissatisfied | B41: =all!B230 -> 1 | C41: =all!C230 -> 0.0029325513 | D41: =all!D230 -> 1 | E41: =all!E230 -> 0.032258065 | F41: =all!F230 -> 0 | G41: =all!G230 -> 0 | H41: =all!H230 -> 5 | ... O41: =all!O230 -> 0.0077062557
A42: Total | B42: =all!B231 -> 341 | C42: =all!C231 -> 1 | D42: =all!D231 -> 31 | E42: =all!E231 -> 1 | F42: =all!F231 -> 131 | G42: =all!G231 -> 1 | H42: =all!H231 -> 672 | I42: =all!I231 -> 1 | ... O42: =all!O231 -> 1
A43: Percent of Satisfied or Very Satisfied | C43: =SUM(C38:C39) -> 0.94428152 | E43: =SUM(E38:E39) -> 0.90322581 | G43: =SUM(G38:G39) -> 0.96946565 | I43: =SUM(I38:I39) -> 0.95684524 | K43: =SUM(K38:K39) -> 0.95145631 | M43: =SUM(M38:M39) -> 0.94182825 | O43: =SUM(O38:O39) -> 0.94922937
A45: =all!A234 -> Knowledge of methods & achievements in the social sciences | B45: Boulder Cty | D45: Brighton | F45: CCCS Onl | H45: Larimer | J45: FRCC Onl | L45: Westminster | N45: Total
...

Sheet Eval Stud Serv
A1: Survey of all Currently enrolled students Fall 2012 -- Evaluate Student and Business services
A2: Academic Advising and Career Counseling had the lowest overall ratings
A4: EVALUATE STUDENT SERVICES
A5: =all!A275 -> Admission/registration procedures | B5: Boulder Cty | D5: Brighton | F5: CCCS Onl | H5: Larimer | J5: FRCC Onl | L5: Westminster | N5: Total | Q5: Evaluate FRCC Student Services | R5: Boulder Cty | S5: Brighton | T5: CCCS Onl | U5: Larimer | V5: FRCC Onl | W5: Westminster | X5: Total
A6: =all!A276 -> Very good | B6: =all!B276 -> 193 | C6: =all!C276 -> 0.43370787 | D6: =all!D276 -> 14 | E6: =all!E276 -> 0.4 | F6: =all!F276 -> 69 | G6: =all!G276 -> 0.39884393 | H6: =all!H276 -> 301 | ... O6: =all!O276 -> 0.40458849 | Q6: =A5 -> Admission/registration procedures | R6: =C11 -> 0.94382022 | S6: =E11 -> 0.91428571 | T6: =G11 -> 0.9132948 | U6: =I11 -> 0.91512915 | V6: =K11 -> 0.92802057 | W6: =M11 -> 0.91021324 | X6: =O11 -> 0.91988347
