Workbook
Name _ftn1: 'ME Curriculum'!$N$43
Name _ftnref1: 'ME Curriculum'!#REF!
Name flow_chart_print: Flowchart!$A$1:$P$32
Name Table_5_1_Curriculum: #REF!
Name Workloads: #REF!

Sheet ME Curriculum
E1: MERRIMACK COLLEGE
E2: MECHANICAL ENGINEERING CURRICULUM | CO2: ECO 1201 Introduction to Economics
CO3: ECO 1202 Topics in Introductory Economics
A4: Name | C4: ID # | F4: Class year: | I4: ADVISOR: | AR4: JUNIOR YEAR | CO4: ECO 3305 Ecological Economics
B6: FALL | I6: SPRING | AT6: UTS | AV6: Queensland | CA6: Arts and Literature | CD6: Ethics
F7: FRESHMAN YEAR | AR7: MACK | AS7: Sydney | AT7: Fall | AU7: Spring | AV7: Fall (sem 2) | AW7: Spring (sem 1) | CI7: Historical Studies | CN7: Social Science
A8: GEN 1001 | B8: Intro. to Eng. | C8: 4 | H8: MTH 1505 | I8: Applied Statistics | J8: 4 | AR8: CEN 3010 Structures | AS8: CIVL 2230 Intro to Structural Concepts | AT8: 48349 Structural Analysis | AV8: CIVL 2340 Struct | CB8: ='[1]LS Core'!D4 -> 6. Arts & Lit (AL) | CE8: ='[1]LS Core'!F4 -> 4. Ethics (E) | CJ8: ='[1]LS Core'!J4 -> 8. Historical Studies (H) | CO8: ='[1]LS Core'!L4 -> 9. Social Science (SS)
A9: MTH 1217 | B9: Calculus I | C9: 4 | H9: MTH 1218 | I9: Calculus II | J9: 4 | N9: Pre-requisites or co-requisites not met | AR9: CEN 3020 Geotechnical Engineering | AS9: CIVL 2410 Soil Mechanics | AT9: 48330 Soil Behaviour | AV9: CIVL 2210 Soil | CA9: ='[1]LS Core'!C5 -> Communication Arts and Sciences | CB9: ='[1]LS Core'!D5 -> WRT 2790 Public and Private Writing from the Civil War Era | CD9: ='[1]LS Core'!E5 -> Management | CE9: ='[1]LS Core'!F5 -> MGT 3325 Ethics and Social Responsibility | CI9: ='[1]LS Core'!I5 -> Economics | CJ9: ='[1]LS Core'!J5 -> ECO 3314 U.S. Economic History | CN9: ='[1]LS Core'!K5 -> Communication Arts and Sciences | CO9: ='[1]LS Core'!L5 -> COM 2201 Introduction to Interpersonal Communication
A10: PHL 1000 | B10: Intro to Philosophy | C10: 4 | H10: PHY 2211 | I10: Physics I | J10: 4 | N10: Pre-requisite for another course | CA10: ='[1]LS Core'!C6 -> Communication Arts and Sciences | CB10: ='[1]LS Core'!D6 -> WRT 3060 Writing the Personal Memoir | CD10: ='[1]LS Core'!E6 -> Philosophy | CE10: ='[1]LS Core'!F6 -> PHL 2020W Perspectives on the Good Life | CI10: ='[1]LS Core'!I6 -> Economics | CJ10: ='[1]LS Core'!J6 -> ECO 3312 The History of Economic Thought | CN10: ='[1]LS Core'!K6 -> Communication Arts and Sciences | CO10: ='[1]LS Core'!L6 -> COM 2301 Introduction to Organizational Communication
A11: FYW 1050 | B11: College Writing | C11: 4 | H11: Arts & Lit (AL) | I11: Elective (course here) | J11: 4 | N11: Co-requisite for another course | AR11: =CONCATENATE(H26," ",I26) -> MEN 3014 Dynamics / Vibrations | AS11: CIVL 3612 Env and Fluids Eng* | AU11: 48350 Env and SanEng | CA11: ='[1]LS Core'!C7 -> English | CB11: ='[1]LS Core'!D7 -> ENG 1060 Horror Fiction | CD11: ='[1]LS Core'!E7 -> Philosophy | CE11: ='[1]LS Core'!F7 -> PHL 2030 Contemporary Moral Problems | CI11: ='[1]LS Core'!I7 -> History | CJ11: ='[1]LS Core'!J7 -> HIS 1106 History of American Civilization, 1600-1877 | CN11: ='[1]LS Core'!K7 -> Communication Arts and Sciences | CO11: ='[1]LS Core'!L7 -> COM 2401 Introduction to Mass Communication
AR12: CEN 3030 Transpo | AU12: 48370 Trans in the Env | AW12: CIVL 2410 Transpo | CA12: ='[1]LS Core'!C8 -> English | CB12: ='[1]LS Core'!D8 -> ENG 1500 Major British and World Authors | CD12: ='[1]LS Core'!E8 -> Philosophy | CE12: ='[1]LS Core'!F8 -> PHL 2040 Introduction to Political Philosophy | CI12: ='[1]LS Core'!I8 -> History | CJ12: ='[1]LS Core'!J8 -> HIS 1107 History of American Civilization, 1877-2000 | CN12: ='[1]LS Core'!K8 -> Communication Arts and Sciences | CO12: ='[1]LS Core'!L8 -> COM 3231 Intercultural Communication (D)
C13: =SUM(C8:C12) -> 16 | J13: =SUM(J8:J12) -> 16 | CA13: ='[1]LS Core'!C9 -> English | CB13: ='[1]LS Core'!D9 -> ENG 1550 Major American Authors | CD13: ='[1]LS Core'!E9 -> Philosophy | CE13: ='[1]LS Core'!F9 -> PHL 2050 Ethics in the Professions | CI13: ='[1]LS Core'!I9 -> History | CJ13: ='[1]LS Core'!J9 -> HIS 1119 History of Western Civilization I | CN13: ='[1]LS Core'!K9 -> Economics | CO13: ='[1]LS Core'!L9 -> ECO 1201 Introduction to Economics
CA14: ='[1]LS Core'!C10 -> English | CB14: ='[1]LS Core'!D10 -> ENG 2050W Introduction to Literary Studies | CD14: ='[1]LS Core'!E10 -> Philosophy | CE14: ='[1]LS Core'!F10 -> PHL 2060 Biomedical Ethics | CI14: ='[1]LS Core'!I10 -> History | CJ14: ='[1]LS Core'!J10 -> HIS 1120 History of Western Civilization II | CN14: ='[1]LS Core'!K10 -> Economics | CO14: ='[1]LS Core'!L10 -> ECO 1202 Topics in Introductory Economics
F15: SOPHOMORE YEAR | N15: INSTRUCTIONS FOR USE | AS15: * may be offered only in Fall but we offer only in Spring | CA15: ='[1]LS Core'!C11 -> English | CB15: ='[1]LS Core'!D11 -> ENG 2200 Introduction to Poetry | CD15: ='[1]LS Core'!E11 -> Philosophy | CE15: ='[1]LS Core'!F11 -> PHL 2070 Environmental Ethics | CI15: ='[1]LS Core'!I11 -> History | CJ15: ='[1]LS Core'!J11 -> HIS 2329 American Social History | CN15: ='[1]LS Core'!K11 -> Economics | CO15: ='[1]LS Core'!L11 -> ECO 1203 Principles of Economics – Micro
A16: GEN 2010 | B16: Mechanics I | C16: 4 | H16: GEN 2012 | I16: Mechanics II | J16: 4 | N16: 1. Enter a 1 into the boxes outlined in green beside courses that you have completed successfully | CA16: ='[1]LS Core'!C12 -> English | CB16: ='[1]LS Core'!D12 -> ENG 2300 Detective Fiction | CD16: ='[1]LS Core'!E12 -> Philosophy | CE16: ='[1]LS Core'!F12 -> PHL 2080 Approaches to Ethics | CI16: ='[1]LS Core'!I12 -> History | CJ16: ='[1]LS Core'!J12 -> HIS 2340 History of Latin America (D) | CN16: ='[1]LS Core'!K12 -> Economics | CO16: ='[1]LS Core'!L12 -> ECO 1204 Principles of Economics – Macro
A17: PHY 2212 | B17: Physics II | C17: 4 | H17: MTH 2220 | I17: Diff. Equations | J17: 4 | CA17: ='[1]LS Core'!C13 -> English | CB17: ='[1]LS Core'!D13 -> ENG 2740 Politics in Literature | CD17: ='[1]LS Core'!E13 -> Philosophy | CE17: ='[1]LS Core'!F13 -> PHL 2090 Values in a Technological Culture | CI17: ='[1]LS Core'!I13 -> History | CJ17: ='[1]LS Core'!J13 -> HIS 3350 Ancient History | CN17: ='[1]LS Core'!K13 -> Economics | CO17: ='[1]LS Core'!L13 -> ECO 1225 Economics of Gender (D)
A18: MTH 2219 | B18: Calculus III | C18: 4 | H18: GEN3040 | I18: Fluid Mech. | J18: 4 | N18: 2. Now you're ready to begin planning the upcoming semester. Enter a 1 into the green boxes beside courses in which you would like to enroll next semester. | CA18: ='[1]LS Core'!C14 -> English | CB18: ='[1]LS Core'!D14 -> ENG 2750 Adapting the Graphic Novel to Film | CD18: ='[1]LS Core'!E14 -> Philosophy | CE18: ='[1]LS Core'!F14 -> PHL 2100 Women, Ethics and Society (D) | CI18: ='[1]LS Core'!I14 -> History | CJ18: ='[1]LS Core'!J14 -> HIS 3360 Medieval Civilization | CN18: ='[1]LS Core'!K14 -> Economics | CO18: ='[1]LS Core'!L14 -> ECO 2201 Intermediate Micro-Economics
A19: CSC 1610 | B19: Computer Science I | C19: 4 | H19: CHM 1180 | I19: Engineering Chemistry | J19: 4 | CA19: ='[1]LS Core'!C15 -> English | CB19: ='[1]LS Core'!D15 -> ENG 2770 Literature and Film | CD19: ='[1]LS Core'!E15 -> Philosophy | CE19: ='[1]LS Core'!F15 -> PHL 2310 Socrates and the Examined Life | CI19: ='[1]LS Core'!I15 -> History | CJ19: ='[1]LS Core'!J15 -> HIS 3370 Renaissance and Reformation | CN19: ='[1]LS Core'!K15 -> Economics | CO19: ='[1]LS Core'!L15 -> ECO 2202 Intermediate Macro-Economics
N20: 3. The cell will turn red if you are missing any co or pre-requisites, which are shown in teal and pink, respectively. | CA20: ='[1]LS Core'!C16 -> English | CB20: ='[1]LS Core'!D16 -> ENG 3020 A History of the English Language | CD20: ='[1]LS Core'!E16 -> Philosophy | CE20: ='[1]LS Core'!F16 -> PHL 2500 Theories of Justice | CI20: ='[1]LS Core'!I16 -> History | CJ20: ='[1]LS Core'!J16 -> HIS 3376 Era of the French Revolution | CN20: ='[1]LS Core'!K16 -> Economics | CO20: ='[1]LS Core'!L16 -> ECO 3303 Economic Development
CA21: ='[1]LS Core'!C17 -> English | CB21: ='[1]LS Core'!D17 -> ENG 3100 Beowulf and Old English Literature | CD21: ='[1]LS Core'!E17 -> Philosophy | CE21: ='[1]LS Core'!F17 -> PHL 3020 Philosophy of Law | CI21: ='[1]LS Core'!I17 -> History | CJ21: ='[1]LS Core'!J17 -> HIS 3378 History of Modern Britain | CN21: ='[1]LS Core'!K17 -> Economics | CO21: ='[1]LS Core'!L17 -> ECO 3304 Economics of Education
C22: =SUM(C16:C21) -> 16 | J22: =SUM(J16:J20) -> 16 | N22: 4. You may keep track of your progress through the curriculum by clicking on the Flowchart sheet. All completed courses will be outlined in yellow. | CA22: ='[1]LS Core'!C18 -> English | CB22: ='[1]LS Core'!D18 -> ENG 3140 Chaucer and Middle English Literature | CD22: ='[1]LS Core'!E18 -> Philosophy | CE22: ='[1]LS Core'!F18 -> PHL 3030 Global Justice | CI22: ='[1]LS Core'!I18 -> History | CJ22: ='[1]LS Core'!J18 -> HIS 3380 History of Modern Technology | CN22: ='[1]LS Core'!K18 -> Economics | CO22: ='[1]LS Core'!L18 -> ECO 3305 Ecological Economics
CA23: ='[1]LS Core'!C19 -> English | CB23: ='[1]LS Core'!D19 -> ENG 3200 Renaissance Literature | CD23: ='[1]LS Core'!E19 -> Philosophy | CE23: ='[1]LS Core'!F19 -> PHL 3180 Existentialism | CI23: ='[1]LS Core'!I19 -> History | CJ23: ='[1]LS Core'!J19 -> HIS 3390 Modern European Social History | CN23: ='[1]LS Core'!K19 -> Economics | CO23: ='[1]LS Core'!L19 -> ECO 3306 International Economics
F24: JUNIOR YEAR | CA24: ='[1]LS Core'!C20 -> English | CB24: ='[1]LS Core'!D20 -> ENG 3220 Renaissance Drama | CD24: ='[1]LS Core'!E20 -> Religious and Theological Studies | CE24: ='[1]LS Core'!F20 -> RTS 2800 Christian Social Ethics (D) | CI24: ='[1]LS Core'!I20 -> History | CJ24: ='[1]LS Core'!J20 -> HIS 3391 Women in Modern European History (D) | CN24: ='[1]LS Core'!K20 -> Economics | CO24: ='[1]LS Core'!L20 -> ECO 3307 Labor Economics
A25: MEN 3020 | B25: Materials Science | C25: 4 | H25: MEN 3010 | I25: Machine Design | J25: 4 | CA25: ='[1]LS Core'!C21 -> English | CB25: ='[1]LS Core'!D21 -> ENG 3250 Shakespearean Drama | CD25: ='[1]LS Core'!E21 -> Religious and Theological Studies | CE25: ='[1]LS Core'!F21 -> RTS 2900 Holocaust: Theology, Reality and Aftermath (D) | CI25: ='[1]LS Core'!I21 -> History | CJ25: ='[1]LS Core'!J21 -> HIS 3320 The American City | CN25: ='[1]LS Core'!K21 -> Economics | CO25: ='[1]LS Core'!L21 -> ECO 3308 Managerial Economics
A26: MEN 3034 | B26: Heat and Mass Transfer | C26: 4 | H26: MEN 3014 | I26: Dynamics / Vibrations | J26: 4 | CA26: ='[1]LS Core'!C22 -> English | CB26: ='[1]LS Core'!D22 -> ENG 3280 Angels and Demons: Milton and the Culture of Revolution | CD26: ='[1]LS Core'!E22 -> Religious and Theological Studies | CE26: ='[1]LS Core'!F22 -> RTS 2950 Ethics in the Abrahamic Traditions | CI26: ='[1]LS Core'!I22 -> History | CJ26: ='[1]LS Core'!J22 -> HIS 3326 History of American Architecture | CN26: ='[1]LS Core'!K22 -> Economics | CO26: ='[1]LS Core'!L22 -> ECO 3309 Marxian Economics
A27: MEN 3030 | B27: Thermodynamics I | C27: 2 | H27: MEN 3032 | I27: Thermodynamics II | J27: 2 | CA27: ='[1]LS Core'!C23 -> English | CB27: ='[1]LS Core'!D23 -> ENG 3300 Restoration and Eighteenth-Century Literature | CD27: ='[1]LS Core'!E23 -> Religious and Theological Studies | CE27: ='[1]LS Core'!F23 -> RTS 3700 African-American Theology (D) | CI27: ='[1]LS Core'!I23 -> History | CJ27: ='[1]LS Core'!J23 -> HIS 3401 Topics in Nineteenth-Century Europe | CN27: ='[1]LS Core'!K23 -> Economics | CO27: ='[1]LS Core'!L23 -> ECO 3310 Money and Finance
A28: RTS 1100 | B28: Christianity in Context | C28: 4 | H28: Ethics (E) | I28: Elective (course here) | J28: 4 | CA28: ='[1]LS Core'!C24 -> English | CB28: ='[1]LS Core'!D24 -> ENG 3320 Eighteenth-Century Novel | CD28: ='[1]LS Core'!E24 -> Religious and Theological Studies | CE28: ='[1]LS Core'!F24 -> RTS 3710 Feminist Theology (D) | CI28: ='[1]LS Core'!I24 -> History | CJ28: ='[1]LS Core'!J24 -> HIS 3410 Twentieth-Century Europe | CN28: ='[1]LS Core'!K24 -> Economics | CO28: ='[1]LS Core'!L24 -> ECO 3311 Public Finance
A29: Hist. Studies (H) | B29: Elective (course here) | C29: 4 | H29: MEN 3090 | I29: Professionalism & Ethics | J29: 1 | CA29: ='[1]LS Core'!C25 -> English | CB29: ='[1]LS Core'!D25 -> ENG 3350 Sex, Race, and Empire: 1660-1814 | CD29: ='[1]LS Core'!E25 -> Religious and Theological Studies | CE29: ='[1]LS Core'!F25 -> RTS 3800 The Catholic Thing: Merton and Day | CI29: ='[1]LS Core'!I25 -> History | CJ29: ='[1]LS Core'!J25 -> HIS 3425 Contemporary United States History | CN29: ='[1]LS Core'!K25 -> Economics | CO29: ='[1]LS Core'!L25 -> ECO 3312 The History of Economic Thought
CA30: ='[1]LS Core'!C26 -> English | CB30: ='[1]LS Core'!D26 -> ENG 3400 British Romanticism | CD30: ='[1]LS Core'!E26 -> Religious and Theological Studies | CE30: ='[1]LS Core'!F26 -> RTS 3850 War and Peace: Religious Perspectives | CI30: ='[1]LS Core'!I26 -> History | CJ30: ='[1]LS Core'!J26 -> HIS 3434 Age of the American Revolution, 1763-1800 | CN30: ='[1]LS Core'!K26 -> Economics | CO30: ='[1]LS Core'!L26 -> ECO 3313 Topics in Quantitative Economics
C31: =C25+C26+C27+C28+C29 -> 18 | J31: =SUM(J25:J29) -> 15 | CA31: ='[1]LS Core'!C27 -> English | CB31: ='[1]LS Core'!D27 -> ENG 3420 American Romanticism | CD31: ='[1]LS Core'!E27 -> 0 | CE31: ='[1]LS Core'!F27 -> 0 | CI31: ='[1]LS Core'!I27 -> History | CJ31: ='[1]LS Core'!J27 -> HIS 3435 American Colonial History | CN31: ='[1]LS Core'!K27 -> Economics | CO31: ='[1]LS Core'!L27 -> ECO 3314 U.S. Economic History
CA32: ='[1]LS Core'!C28 -> English | CB32: ='[1]LS Core'!D28 -> ENG 3440 Victorian Literature | CD32: ='[1]LS Core'!E28 -> 0 | CE32: ='[1]LS Core'!F28 -> 0 | CI32: ='[1]LS Core'!I28 -> History | CJ32: ='[1]LS Core'!J28 -> HIS 3437 Civil War and Reconstruction | CN32: ='[1]LS Core'!K28 -> Economics | CO32: ='[1]LS Core'!L28 -> ECO 3315 Urban and Regional Economics
F33: SENIOR YEAR | CA33: ='[1]LS Core'!C29 -> English | CB33: ='[1]LS Core'!D29 -> ENG 3470 Realism and Naturalism in America | CD33: ='[1]LS Core'!E29 -> 0 | CE33: ='[1]LS Core'!F29 -> 0 | CI33: ='[1]LS Core'!I29 -> History | CJ33: ='[1]LS Core'!J29 -> HIS 3439 Slavery and Race in the Early Modern Atlantic World, 1400-1800 (D) | CN33: ='[1]LS Core'!K29 -> History | CO33: ='[1]LS Core'!L29 -> HIS 3376 Era of the French Revolution
A34: MEN | B34: Depth elective | C34: 4 | H34: MEN 4901 | I34: Des. Project | J34: 4 | L34: See note next page | CA34: ='[1]LS Core'!C30 -> English | CB34: ='[1]LS Core'!D30 -> ENG 3500 Modern British Literature | CD34: ='[1]LS Core'!E30 -> 0 | CE34: ='[1]LS Core'!F30 -> 0 | CI34: ='[1]LS Core'!I30 -> History | CJ34: ='[1]LS Core'!J30 -> HIS 3470 History of Imperial Russia | CN34: ='[1]LS Core'!K30 -> History | CO34: ='[1]LS Core'!L30 -> HIS 3380 History of Modern Technology
A35: MEN | B35: Depth elective | C35: 4 | H35: MEN | I35: Depth elective | J35: 4 | CA35: ='[1]LS Core'!C31 -> English | CB35: ='[1]LS Core'!D31 -> ENG 3520 Modern Irish Literature | CD35: ='[1]LS Core'!E31 -> 0 | CE35: ='[1]LS Core'!F31 -> 0 | CI35: ='[1]LS Core'!I31 -> History | CJ35: ='[1]LS Core'!J31 -> HIS 3471 History of Twentieth-Century Russia | CN35: ='[1]LS Core'!K31 -> History | CO35: ='[1]LS Core'!L31 -> HIS 3390 Modern European Social History
A36: Technical | B36: Elective (course here) | C36: 4 | E36: Work with your advisor here. | H36: MEN 4900 | I36: Senior Seminar | J36: 1 | CA36: ='[1]LS Core'!C32 -> English | CB36: ='[1]LS Core'!D32 -> ENG 3550 Modern American Literature | CI36: ='[1]LS Core'!I32 -> History | CJ36: ='[1]LS Core'!J32 -> HIS 3525 Environmental History of North America | CN36: ='[1]LS Core'!K32 -> History | CO36: ='[1]LS Core'!L32 -> HIS 3391 Women in Modern European History
A37: Soc. Science (SS) | B37: Elective (course here) | C37: 4 | H37: Soc. Science (SS) | I37: Elective (course here) | J37: 4 | CA37: ='[1]LS Core'!C33 -> English | CB37: ='[1]LS Core'!D33 -> ENG 3620 Contemporary American Literature | CI37: ='[1]LS Core'!I33 -> Political Science | CJ37: ='[1]LS Core'!J33 -> POL 2581 Political Thought: Plato to Machiavelli | CN37: ='[1]LS Core'!K33 -> Political Science | CO37: ='[1]LS Core'!L33 -> POL 1000 Current Issues in Politics and Government
H38: MEN | I38: Depth elective | J38: 4 | CA38: ='[1]LS Core'!C34 -> English | CB38: ='[1]LS Core'!D34 -> ENG 3650 Contemporary American Drama | CI38: ='[1]LS Core'!I34 -> Political Science | CJ38: ='[1]LS Core'!J34 -> POL 2582 Political Thought: Machiavelli to Marx | CN38: ='[1]LS Core'!K34 -> Political Science | CO38: ='[1]LS Core'!L34 -> POL 1100 Politics of the United States
CA39: ='[1]LS Core'!C35 -> English | CB39: ='[1]LS Core'!D35 -> ENG 3680 World Drama | CI39: ='[1]LS Core'!I35 -> Religious and Theological Studies | CJ39: ='[1]LS Core'!J35 -> RTS 2450 History of Christian Thought | CN39: ='[1]LS Core'!K35 -> Political Science | CO39: ='[1]LS Core'!L35 -> POL 1500 Comparative Politics
F40: TOOK FE EXAM | CA40: ='[1]LS Core'!C36 -> English | CB40: ='[1]LS Core'!D36 -> ENG 3685 The Graphic Novel | CI40: ='[1]LS Core'!I36 -> Religious and Theological Studies | CJ40: ='[1]LS Core'!J36 -> RTS 3400 American Catholicism | CN40: ='[1]LS Core'!K36 -> Political Science | CO40: ='[1]LS Core'!L36 -> POL 2000W Political Science Methods (Q)
F41: DIVERSITY CRS. | I41: Enter course used here | CA41: ='[1]LS Core'!C37 -> English | CB41: ='[1]LS Core'!D37 -> ENG 3700 Self and Society: The Victorian Novel | CI41: ='[1]LS Core'!I37 -> Visual and Performing Arts | CJ41: ='[1]LS Core'!J37 -> FAA 1610 Art History I | CN41: ='[1]LS Core'!K37 -> Political Science | CO41: ='[1]LS Core'!L37 -> POL 2111 State and Local Politics
...

Sheet Flowchart
H3: =CONCATENATE("BS in Civil Engineering",CHAR(10),"Class of 2012 Flowchart") -> BS in Civil Engineering Class of 2012 Flowchart | AA3: ='ME Curriculum'!A8 -> GEN 1001 | AB3: ='ME Curriculum'!B8 -> Intro. to Eng. | AC3: ='ME Curriculum'!C8 -> 4 | AD3: ='ME Curriculum'!D8 -> 0 | AH3: ='ME Curriculum'!H8 -> MTH 1505 | AI3: ='ME Curriculum'!I8 -> Applied Statistics | AJ3: ='ME Curriculum'!J8 -> 4 | AK3: ='ME Curriculum'!K8 -> 0
N4: Student Name: | O4: ='ME Curriculum'!B4 | AA4: ='ME Curriculum'!A9 -> MTH 1217 | AB4: ='ME Curriculum'!B9 -> Calculus I | AC4: ='ME Curriculum'!C9 -> 4 | AD4: ='ME Curriculum'!D9 -> 0 | AH4: ='ME Curriculum'!H9 -> MTH 1218 | AI4: ='ME Curriculum'!I9 -> Calculus II | AJ4: ='ME Curriculum'!J9 -> 4 | AK4: ='ME Curriculum'!K9 -> 0
N5: Student Number: | O5: ='ME Curriculum'!D4 | AA5: ='ME Curriculum'!A10 -> PHL 1000 | AB5: ='ME Curriculum'!B10 -> Intro to Philosophy | AC5: ='ME Curriculum'!C10 -> 4 | AD5: ='ME Curriculum'!D10 -> 0 | AH5: ='ME Curriculum'!H10 -> PHY 2211 | AI5: ='ME Curriculum'!I10 -> Physics I | AJ5: ='ME Curriculum'!J10 -> 4 | AK5: ='ME Curriculum'!K10 -> 0
B6: =CONCATENATE('ME Curriculum'!A8,CHAR(10),'ME Curriculum'!B8) -> GEN 1001 Intro. to Eng. | D6: =CONCATENATE('ME Curriculum'!A19,CHAR(10),'ME Curriculum'!B19) -> CSC 1610 Computer Science I | N6: Class year: | O6: ='ME Curriculum'!G4 | AA6: ='ME Curriculum'!A11 -> FYW 1050 | AB6: ='ME Curriculum'!B11 -> College Writing | AC6: ='ME Curriculum'!C11 -> 4 | AD6: ='ME Curriculum'!D11 -> 0 | AH6: ='ME Curriculum'!H11 -> Arts & Lit (AL) | AI6: ='ME Curriculum'!I11 -> Elective (course here) | AJ6: ='ME Curriculum'!J11 -> 4 | AK6: ='ME Curriculum'!K11 -> 0
N7: Advisor: | O7: ='ME Curriculum'!J4
D8: =CONCATENATE('ME Curriculum'!H8,CHAR(10),'ME Curriculum'!I8) -> MTH 1505 Applied Statistics | L8: =CONCATENATE('ME Curriculum'!H34," ",'ME Curriculum'!I34) -> MEN 4901 Des. Project
H10: =CONCATENATE('ME Curriculum'!H17,CHAR(10),'ME Curriculum'!I17) -> MTH 2220 Diff. Equations | J10: =CONCATENATE('ME Curriculum'!A26,CHAR(13),'ME Curriculum'!B26) -> MEN 3034_x000D_Heat and Mass Transfer | L10: =CONCATENATE('ME Curriculum'!A34," ",'ME Curriculum'!B34) -> MEN Depth elective
S11: mag factor
B12: =CONCATENATE('ME Curriculum'!A9,CHAR(10),'ME Curriculum'!B9) -> MTH 1217 Calculus I | D12: =CONCATENATE('ME Curriculum'!H9,CHAR(10),'ME Curriculum'!I9) -> MTH 1218 Calculus II | F12: =CONCATENATE('ME Curriculum'!A18,CHAR(10),'ME Curriculum'!B18) -> MTH 2219 Calculus III | J12: =CONCATENATE('ME Curriculum'!H18,CHAR(10),'ME Curriculum'!I18) -> GEN3040 Fluid Mech. | S12: 1.63 | T12: Want | AF12: ='ME Curriculum'!F15 -> SOPHOMORE YEAR
R13: 19.79 | S13: =R13*S12 -> 32.2577 | T13: 36 | AA13: ='ME Curriculum'!A16 -> GEN 2010 | AB13: ='ME Curriculum'!B16 -> Mechanics I | AC13: ='ME Curriculum'!C16 -> 4 | AD13: ='ME Curriculum'!D16 -> 0 | AH13: ='ME Curriculum'!H16 -> GEN 2012 | AI13: ='ME Curriculum'!I16 -> Mechanics II | AJ13: ='ME Curriculum'!J16 -> 4 | AK13: ='ME Curriculum'!K16 -> 0
B14: =CONCATENATE('ME Curriculum'!H19,CHAR(10),'ME Curriculum'!I19) -> CHM 1180 Engineering Chemistry | J14: =CONCATENATE('ME Curriculum'!H26,CHAR(10),'ME Curriculum'!I26) -> MEN 3014 Dynamics / Vibrations | L14: =CONCATENATE('ME Curriculum'!H35," ",'ME Curriculum'!I35) -> MEN Depth elective | R14: 14.75 | S14: =R14*S12 -> 24.0425 | T14: 24 | AA14: ='ME Curriculum'!A17 -> PHY 2212 | AB14: ='ME Curriculum'!B17 -> Physics II | AC14: ='ME Curriculum'!C17 -> 4 | AD14: ='ME Curriculum'!D17 -> 0 | AH14: ='ME Curriculum'!H17 -> MTH 2220 | AI14: ='ME Curriculum'!I17 -> Diff. Equations | AJ14: ='ME Curriculum'!J17 -> 4 | AK14: ='ME Curriculum'!K17 -> 0
AA15: ='ME Curriculum'!A18 -> MTH 2219 | AB15: ='ME Curriculum'!B18 -> Calculus III | AC15: ='ME Curriculum'!C18 -> 4 | AD15: ='ME Curriculum'!D18 -> 0 | AH15: ='ME Curriculum'!H18 -> GEN3040 | AI15: ='ME Curriculum'!I18 -> Fluid Mech. | AJ15: ='ME Curriculum'!J18 -> 4 | AK15: ='ME Curriculum'!K18 -> 0
B16: Pre-calculus | D16: =CONCATENATE('ME Curriculum'!H10,CHAR(10),'ME Curriculum'!I10) -> PHY 2211 Physics I | F16: =CONCATENATE('ME Curriculum'!A17,CHAR(10),'ME Curriculum'!B17) -> PHY 2212 Physics II | H16: =CONCATENATE('ME Curriculum'!H16,CHAR(10),'ME Curriculum'!I16) -> GEN 2012 Mechanics II | J16: =CONCATENATE('ME Curriculum'!A25,CHAR(10),'ME Curriculum'!B25) -> MEN 3020 Materials Science | L16: =CONCATENATE('ME Curriculum'!H38," ",'ME Curriculum'!I38) -> MEN Depth elective | AA16: ='ME Curriculum'!A19 -> CSC 1610 | AB16: ='ME Curriculum'!B19 -> Computer Science I | AC16: ='ME Curriculum'!C19 -> 4 | AD16: ='ME Curriculum'!D19 -> 0 | AH16: ='ME Curriculum'!H19 -> CHM 1180 | AI16: ='ME Curriculum'!I19 -> Engineering Chemistry | AJ16: ='ME Curriculum'!J19 -> 4 | AK16: ='ME Curriculum'!K19 -> 0
B18: =CONCATENATE('ME Curriculum'!A11,CHAR(10),'ME Curriculum'!B11) -> FYW 1050 College Writing | F18: =CONCATENATE('ME Curriculum'!A16,CHAR(10),'ME Curriculum'!B16) -> GEN 2010 Mechanics I | J18: =CONCATENATE('ME Curriculum'!H25,CHAR(10),'ME Curriculum'!I25) -> MEN 3010 Machine Design | L18: =CONCATENATE('ME Curriculum'!A35," ",'ME Curriculum'!B35) -> MEN Depth elective
B20: =CONCATENATE('ME Curriculum'!A28," ",'ME Curriculum'!B28) -> RTS 1100 Christianity in Context | D20: =CONCATENATE('ME Curriculum'!H28," ",'ME Curriculum'!I28) -> Ethics (E) Elective (course here) | F20: =CONCATENATE('ME Curriculum'!A27,CHAR(10),'ME Curriculum'!B27) -> MEN 3030 Thermodynamics I | H20: =CONCATENATE('ME Curriculum'!H27,CHAR(10),'ME Curriculum'!I27) -> MEN 3032 Thermodynamics II | J20: Senior standing | L20: =CONCATENATE('ME Curriculum'!H36,CHAR(10),'ME Curriculum'!I36) -> MEN 4900 Senior Seminar
AF21: ='ME Curriculum'!F24 -> JUNIOR YEAR
B22: =CONCATENATE('ME Curriculum'!A10," ",'ME Curriculum'!B10) -> PHL 1000 Intro to Philosophy | J22: =CONCATENATE('ME Curriculum'!H29," ",'ME Curriculum'!I29) -> MEN 3090 Professionalism & Ethics | AA22: ='ME Curriculum'!A25 -> MEN 3020 | AB22: ='ME Curriculum'!B25 -> Materials Science | AC22: ='ME Curriculum'!C25 -> 4 | AD22: ='ME Curriculum'!D25 -> 0 | AH22: ='ME Curriculum'!H25 -> MEN 3010 | AI22: ='ME Curriculum'!I25 -> Machine Design | AJ22: ='ME Curriculum'!J25 -> 4 | AK22: ='ME Curriculum'!K25 -> 0
AA23: ='ME Curriculum'!A26 -> MEN 3034 | AB23: ='ME Curriculum'!B26 -> Heat and Mass Transfer | AC23: ='ME Curriculum'!C26 -> 4 | AD23: ='ME Curriculum'!D26 -> 0 | AH23: ='ME Curriculum'!H26 -> MEN 3014 | AI23: ='ME Curriculum'!I26 -> Dynamics / Vibrations | AJ23: ='ME Curriculum'!J26 -> 4 | AK23: ='ME Curriculum'!K26 -> 0
B24: =CONCATENATE('ME Curriculum'!A37," ",'ME Curriculum'!B37) -> Soc. Science (SS) Elective (course here) | J24: Permission of academic advisor | L24: =CONCATENATE('ME Curriculum'!A36," ",'ME Curriculum'!B36) -> Technical Elective (course here) | AA24: ='ME Curriculum'!A27 -> MEN 3030 | AB24: ='ME Curriculum'!B27 -> Thermodynamics I | AC24: ='ME Curriculum'!C27 -> 2 | AD24: ='ME Curriculum'!D27 -> 0 | AH24: ='ME Curriculum'!H27 -> MEN 3032 | AI24: ='ME Curriculum'!I27 -> Thermodynamics II | AJ24: ='ME Curriculum'!J27 -> 2 | AK24: ='ME Curriculum'!K27 -> 0
F25: Steps to your goal: | AA25: ='ME Curriculum'!A28 -> RTS 1100 | AB25: ='ME Curriculum'!B28 -> Christianity in Context | AC25: ='ME Curriculum'!C28 -> 4 | AD25: ='ME Curriculum'!D28 -> 0 | AH25: ='ME Curriculum'!H28 -> Ethics (E) | AI25: ='ME Curriculum'!I28 -> Elective (course here) | AJ25: ='ME Curriculum'!J28 -> 4 | AK25: ='ME Curriculum'!K28 -> 0
B26: =CONCATENATE('ME Curriculum'!H11," ",'ME Curriculum'!I11) -> Arts & Lit (AL) Elective (course here) | F26: =CONCATENATE("BSME",CHAR(10),"Pass FE Exam",CHAR(10),"Pass PE Exam") -> BSME Pass FE Exam Pass PE Exam | J26: Key | AA26: ='ME Curriculum'!A29 -> Hist. Studies (H) | AB26: ='ME Curriculum'!B29 -> Elective (course here) | AC26: ='ME Curriculum'!C29 -> 4 | AD26: ='ME Curriculum'!D29 -> 0 | AH26: ='ME Curriculum'!H29 -> MEN 3090 | AI26: ='ME Curriculum'!I29 -> Professionalism & Ethics | AJ26: ='ME Curriculum'!J29 -> 1 | AK26: ='ME Curriculum'!K29 -> 0
J27: Pre-requisite:
B28: =CONCATENATE('ME Curriculum'!H37," ",'ME Curriculum'!I37) -> Soc. Science (SS) Elective (course here) | H28: ='ME Curriculum'!F40 -> TOOK FE EXAM | J28: Co-requisite
H29: ='ME Curriculum'!F41 -> DIVERSITY CRS.
B30: =CONCATENATE('ME Curriculum'!A29," ",'ME Curriculum'!B29) -> Hist. Studies (H) Elective (course here) | AF30: ='ME Curriculum'!F32 -> 0
H31: Our mission is to prepare exceptional engineers! | AA31: ='ME Curriculum'!A33 -> 0 | AB31: ='ME Curriculum'!B33 -> 0 | AC31: ='ME Curriculum'!C33 -> 0 | AD31: ='ME Curriculum'!D33 -> 0 | AH31: ='ME Curriculum'!H33 -> 0 | AI31: ='ME Curriculum'!I33 -> 0 | AJ31: ='ME Curriculum'!J33 -> 0 | AK31: ='ME Curriculum'!K33 -> 0
AA32: ='ME Curriculum'!A34 -> MEN | AB32: ='ME Curriculum'!B34 -> Depth elective | AC32: ='ME Curriculum'!C34 -> 4 | AD32: ='ME Curriculum'!D34 -> 0 | AH32: ='ME Curriculum'!H34 -> MEN 4901 | AI32: ='ME Curriculum'!I34 -> Des. Project | AJ32: ='ME Curriculum'!J34 -> 4 | AK32: ='ME Curriculum'!K34 -> 0
AA33: ='ME Curriculum'!A35 -> MEN | AB33: ='ME Curriculum'!B35 -> Depth elective | AC33: ='ME Curriculum'!C35 -> 4 | AD33: ='ME Curriculum'!D35 -> 0 | AH33: ='ME Curriculum'!H35 -> MEN | AI33: ='ME Curriculum'!I35 -> Depth elective | AJ33: ='ME Curriculum'!J35 -> 4 | AK33: ='ME Curriculum'!K35 -> 0
AA34: ='ME Curriculum'!A36 -> Technical | AB34: ='ME Curriculum'!B36 -> Elective (course here) | AC34: ='ME Curriculum'!C36 -> 4 | AD34: ='ME Curriculum'!D36 -> 0 | AH34: ='ME Curriculum'!H36 -> MEN 4900 | AI34: ='ME Curriculum'!I36 -> Senior Seminar | AJ34: ='ME Curriculum'!J36 -> 1 | AK34: ='ME Curriculum'!K36 -> 0
AA35: ='ME Curriculum'!A37 -> Soc. Science (SS) | AB35: ='ME Curriculum'!B37 -> Elective (course here) | AC35: ='ME Curriculum'!C37 -> 4 | AD35: ='ME Curriculum'!D37 -> 0 | AH35: ='ME Curriculum'!H37 -> Soc. Science (SS) | AI35: ='ME Curriculum'!I37 -> Elective (course here) | AJ35: ='ME Curriculum'!J37 -> 4 | AK35: ='ME Curriculum'!K37 -> 0
AH36: ='ME Curriculum'!H38 -> MEN | AI36: ='ME Curriculum'!I38 -> Depth elective | AJ36: ='ME Curriculum'!J38 -> 4 | AK36: ='ME Curriculum'!K38 -> 0
AF37: ='ME Curriculum'!F40 -> TOOK FE EXAM | AG37: ='ME Curriculum'!H40 -> 0
AF38: ='ME Curriculum'!F41 -> DIVERSITY CRS. | AG38: ='ME Curriculum'!H41 -> 0

Sheet General Education
A2: Foundations
A3: Requirement | B3: Y | C3: N | D3: Course(s) taken | E3: Credits
A4: ='ME Curriculum'!A11 -> FYW 1050 | B4: =IF('ME Curriculum'!D11=1,"x"," ") | C4: =IF(B4=" ","x","") -> x | E4: =IF(B4="x",'ME Curriculum'!C11,0) -> 0
A5: ='ME Curriculum'!A10 -> PHL 1000 | B5: =IF('ME Curriculum'!D10=1,"x"," ") | C5: =IF(B5=" ","x","") -> x | E5: =IF(B5="x",'ME Curriculum'!C10,0) -> 0
A6: ='ME Curriculum'!H28 -> Ethics (E) | B6: =IF('ME Curriculum'!K28=1,"x"," ") | C6: =IF(B6=" ","x","") -> x | D6: =IF(B6="x",'ME Curriculum'!I28,"") | E6: =IF(B6="x",'ME Curriculum'!J28,0) -> 0
A7: Quantitative Reasoning (Q) | B7: =IF('ME Curriculum'!D9=1,"x"," ") | C7: =IF(B7=" ","x","") -> x | D7: =IF(B7="x",'ME Curriculum'!B9,"") | E7: =IF(B7="x",'ME Curriculum'!C9,0) -> 0
A9: Explorations
A10: Requirement | B10: Y | C10: N | D10: Course(s) taken | E10: Credits
A11: ='ME Curriculum'!A28 -> RTS 1100 | B11: =IF('ME Curriculum'!D28=1,"x"," ") | C11: =IF(B11=" ","x","") -> x | E11: =IF(B11="x",'ME Curriculum'!C28,0) -> 0
A12: ='ME Curriculum'!H11 -> Arts & Lit (AL) | B12: =IF('ME Curriculum'!K11=1,"x"," ") | C12: =IF(B12=" ","x","") -> x | D12: =IF(B12="x",'ME Curriculum'!I11,"") | E12: =IF(B12="x",'ME Curriculum'!J11,0) -> 0
A13: Foreign language* | B13: =IF('ME Curriculum'!K9=1,"x"," ") | C13: =IF(B13=" ","x","") -> x | D13: =IF(B13="x",'ME Curriculum'!I9,"") | E13: =IF(B13="x",'ME Curriculum'!J9,0) -> 0
A14: ='ME Curriculum'!A29 -> Hist. Studies (H) | B14: =IF('ME Curriculum'!D29=1,"x"," ") | C14: =IF(B14=" ","x","") -> x | D14: =IF(B14="x",'ME Curriculum'!B29,"") | E14: =IF(B14="x",'ME Curriculum'!C29,0) -> 0
A15: ='ME Curriculum'!A37 -> Soc. Science (SS) | B15: =IF('ME Curriculum'!D37=1,"x"," ") | C15: =IF(B15=" ","x","") -> x | D15: =IF(B15="x",'ME Curriculum'!B36,"") | E15: =IF(B15="x",'ME Curriculum'!C37,0) -> 0
A16: ='ME Curriculum'!H37 -> Soc. Science (SS) | B16: =IF('ME Curriculum'!K37=1,"x"," ") | C16: =IF(B16=" ","x","") -> x | D16: =IF(B16="x",'ME Curriculum'!I37,"") | E16: =IF(B16="x",'ME Curriculum'!J37,0) -> 0
A18: Cultural Diversity (D) | B18: =IF('ME Curriculum'!H40=1,"x"," ") | C18: =IF(B18=" ","x","") -> x | D18: =IF('ME Curriculum'!I40=1,"x"," ")
A19: FE Exam taken | B19: =IF('ME Curriculum'!H39=1,"x"," ") | C19: =IF(B19=" ","x","") -> x
A20: Writing intensive (W)** | B20: =IF('ME Curriculum'!D8=1,"x"," ") | C20: =IF(B20=" ","x","") -> x | D20: =IF(B20="x",'ME Curriculum'!B8,"")
A21: Experiential (X)*** | B21: =IF('ME Curriculum'!K33=1,"x"," ") | C21: =IF(B21=" ","x","") -> x | D21: =IF(B21="x",'ME Curriculum'!I33,"")
A24: * Use Calculus II as replacement for this requirement
A25: ** Use GEN 1001
A26: *** use CEN 4901

Sheet ABET Summary
B2: Curriculum Analysis
B3: Curricular | C3: Number of Credits*
B4: Category | C4: Criteria | D4: Table I-1
C5: Requirement | D5: of Self-Study | E5: Actuals | F5: taken
B6: College-level Mathematics and Basic Science | C6: 1 yr (30-32 cr) | D6: 32 | E6: =H56 -> 35 | F6: =I56 -> 0
B7: Engineering Topics | C7: 1.5 yr (45-48 cr) | D7: =32*1.5 -> 48 | E7: =H74 -> 4 | F7: =I74 -> 0
B8: General Education | C8: Inst. Reqmt=44 | D8: 44 | E8: =#REF! -> #REF! | F8: =#REF! -> #REF! | G8: MEN 1001 counts for 4 more if taken F08 or later
B9: Please List Below Any Applicable Program Criteria Requirements:
B16: MECHANICAL ENGINEERING | C16: {=SUMPRODUCT(I59:I73,J59:J73)/I74} -> #DIV/0! | D16: =VLOOKUP(C16,L32:M43,2) -> #DIV/0!
B17: OVERALL | C17: {=(SUMPRODUCT(I44:I54,J44:J54)+SUMPRODUCT(I59:I73,J59:J73)+SUMPRODUCT(I41:I79,J41:J79)+SUMPRODUCT(I41:I97,J41:J97)+I70*J70)/(I56+I74+#REF!+I70)} -> #REF! | D17: =VLOOKUP(C17,L33:M44,2) -> #REF!
B18: MATH AND SCIENCE | C18: {=(SUMPRODUCT(I44:I48,J44:J48)+SUMPRODUCT(I50:I54,J50:J54))/I56} -> #DIV/0! | D18: =VLOOKUP(C18,L34:M45,2) -> #DIV/0! | K18: A | L18: 4
B19: GENERAL EDUCATION | C19: {=(SUMPRODUCT(I41:I79,J41:J79)+SUMPRODUCT(I41:I97,J41:J97))/#REF!} -> #REF! | D19: =VLOOKUP(C19,L35:M46,2) -> #REF! | K19: A- | L19: 3.7
K20: B | L20: 3
K21: B- | L21: 2.7
K22: B+ | L22: 3.3
K23: C | L23: 2
K24: C- | L24: 1.7
K25: C+ | L25: 2.3
K26: D | L26: 1
K27: D- | L27: 0.7
K28: D+ | L28: 1.3
K29: F | L29: 0
L32: 0 | M32: F
L33: 1.3 | M33: D+
L34: 0.7 | M34: D-
L35: 1 | M35: D
L36: 2.3 | M36: C+ | V36: Table 5-1 Curriculum
L37: 1.7 | M37: C-
L38: 2 | M38: C | V38: Year; | Y38: Category (Credit Hours)
L39: 3.3 | M39: B+ | V39: Semester or | Y39: Math & Basic Sciences | Z39: Engineering Topics Check if Contains Significant Design (√) | AA39: General Education | AB39: Other
L40: 2.7 | M40: B- | V40: Quarter | W40: Course
G41: Reference for Table I-1 | L41: 3 | M41: B | W41: (Department, Number, Title)
H42: Credits | I42: Credits | L42: 3.7 | M42: A- | V42: Freshman; Fall | W42: =G59 -> GEN 1001 Intro. to Eng. | Z42: =H59 -> 4
G43: Science and Math Topics | H43: Required | I43: Taken | L43: 4 | M43: A | V43: Freshman; Fall | W43: =G44 -> MTH 1217 Calculus I | Y43: =H44 -> 4
G44: =CONCATENATE('ME Curriculum'!A9," ",'ME Curriculum'!B9) -> MTH 1217 Calculus I | H44: ='ME Curriculum'!C9 -> 4 | I44: =IF('ME Curriculum'!D9=1,H44,0) -> 0 | J44: =IFERROR(VLOOKUP('ME Curriculum'!E9,K18:L29,2),0.001) -> 0.001 | V44: Freshman; Fall | W44: =G68 -> MEN 3090 Professionalism & Ethics | Y44: =H68 -> 1
G45: =CONCATENATE('ME Curriculum'!H9," ",'ME Curriculum'!I9) -> MTH 1218 Calculus II | H45: ='ME Curriculum'!J9 -> 4 | I45: =IF('ME Curriculum'!K9=1,H45,0) -> 0 | J45: =IFERROR(VLOOKUP('ME Curriculum'!L9,K18:L29,2),0.001) -> 0.001 | V45: Freshman; Fall | W45: =G78 -> FYW 1050 College Writing | AA45: =H78 -> 4
G46: =CONCATENATE('ME Curriculum'!A18," ",'ME Curriculum'!B18) -> MTH 2219 Calculus III | H46: ='ME Curriculum'!C18 -> 4 | I46: =IF('ME Curriculum'!D18=1,H46,0) -> 0 | J46: =IFERROR(VLOOKUP('ME Curriculum'!E18,K18:L29,2),0.001) -> 0.001 | V46: Freshman; Spring | W46: =G48 -> MTH 1505 Applied Statistics | Y46: =H48 -> 4
G47: =CONCATENATE('ME Curriculum'!H17," ",'ME Curriculum'!I17) -> MTH 2220 Diff. Equations | H47: ='ME Curriculum'!J17 -> 4 | I47: =IF('ME Curriculum'!K17=1,H47,0) -> 0 | J47: =IFERROR(VLOOKUP('ME Curriculum'!L17,K18:L29,2),0.001) -> 0.001 | V47: Freshman; Spring | W47: =G45 -> MTH 1218 Calculus II | Y47: =H45 -> 4
G48: =CONCATENATE('ME Curriculum'!H8," ",'ME Curriculum'!I8) -> MTH 1505 Applied Statistics | H48: ='ME Curriculum'!J8 -> 4 | I48: =IF('ME Curriculum'!K8=1,H48,0) -> 0 | J48: =IFERROR(VLOOKUP('ME Curriculum'!L8,K18:L29,2),0.001) -> 0.001 | V48: Freshman; Spring | W48: =G51 -> PHY 2211 Physics I | Y48: =H51 -> 4
G49: Total Math | H49: =SUM(H44:H48) -> 20 | I49: =SUM(I44:I48) -> 0 | V49: Freshman; Spring | W49: =G86 -> Arts & Lit (AL) Elective (course here) | AA49: =H86 -> 4
...
