Workbook

Sheet Inc Exp Forecast
A1: Collaborative I & E forecast
B2: ='Policy decisions'!B8 -> 2012-13 | C2: ='Policy decisions'!C8 -> 2013-14 | D2: ='Policy decisions'!D8 -> 2014-15 | E2: ='Policy decisions'!E8 -> 2015-16 | F2: ='Policy decisions'!F8 -> 2016-17 | G2: ='Policy decisions'!G8 -> 2017-18
A3: INCOME | C3: £ | D3: £ | E3: £ | F3: £ | G3: £
A5: Home Fees | C5: ='Income Model'!E49 -> 93600 | D5: ='Income Model'!F49 -> 187191 | E5: ='Income Model'!G49 -> 246695 | F5: ='Income Model'!H49 -> 241432 | G5: ='Income Model'!I49 -> 148935
A6: International Fees | C6: ='Income Model'!E58 -> 171800 | D6: ='Income Model'!F58 -> 291118.2 | E6: ='Income Model'!G58 -> 338682.16 | F6: ='Income Model'!H58 -> 352486.76 | G6: ='Income Model'!I58 -> 188549.2
A7: Teaching Grants | C7: ='Income Model'!E33 -> Outstanding | D7: ='Income Model'!F33 -> 0 | E7: ='Income Model'!G33 -> 0 | F7: ='Income Model'!H33 -> 0 | G7: ='Income Model'!I33 -> 0
A8: Scholarships / Bursaries | C8: =-'Income Model'!E62 -> -11040 | D8: =-'Income Model'!F62 -> -21958.65 | E8: =-'Income Model'!G62 -> -27641 | F8: =-'Income Model'!H62 -> -26664 | G8: =-'Income Model'!I62 -> -15846
A10: Net Total Fees | B10: 0 | C10: =SUM(C5:C9) -> 254360 | D10: =SUM(D5:D9) -> 456350.55 | E10: =SUM(E5:E9) -> 557736.16 | F10: =SUM(F5:F9) -> 567254.76 | G10: =SUM(G5:G9) -> 321638.2
A12: COSTS
A13: Staff costs
A14: Start up Costs | B14: ='Costing Model'!J21 -> 6566 | C14: ='Costing Model'!K21 -> 5541 | D14: ='Costing Model'!L21 -> 4204 | E14: ='Costing Model'!M21 -> 2111 | F14: ='Costing Model'!N21 -> 3166 | G14: ='Costing Model'!O21 -> 633
A15: Delivery costs | B15: ='Costing Model'!J30 -> 0 | C15: ='Costing Model'!K30 -> 7268 | D15: ='Costing Model'!L30 -> 13739 | E15: ='Costing Model'!M30 -> 17155 | F15: ='Costing Model'!N30 -> 16268 | G15: ='Costing Model'!O30 -> 13142
A16: Management costs | B16: ='Costing Model'!J37 -> 0 | C16: ='Costing Model'!K37 -> 1078 | D16: ='Costing Model'!L37 -> 1100 | E16: ='Costing Model'!M37 -> 1121 | F16: ='Costing Model'!N37 -> 1144 | G16: ='Costing Model'!O37 -> 1167
B17: =SUM(B14:B16) -> 6566 | C17: =SUM(C14:C16) -> 13887 | D17: =SUM(D14:D16) -> 19043 | E17: =SUM(E14:E16) -> 20387 | F17: =SUM(F14:F16) -> 20578 | G17: =SUM(G14:G16) -> 14942
A18: Non- Pay Costs
A19: Commission | B19: ='Costing Model'!J44 -> 0 | C19: ='Costing Model'!K44 -> 20616 | D19: ='Costing Model'!L44 -> 34934 | E19: ='Costing Model'!M44 -> 40642 | F19: ='Costing Model'!N44 -> 42298 | G19: ='Costing Model'!O44 -> 22626
A20: Franchise Costs | B20: ='Costing Model'!J48+'Costing Model'!J49+'Costing Model'!J50 -> 0 | C20: ='Costing Model'!K48+'Costing Model'!K49+'Costing Model'!K50 -> 12500 | D20: =ROUND('Costing Model'!L48+'Costing Model'!L49+'Costing Model'!L50,0) -> 23875 | E20: =ROUND('Costing Model'!M48+'Costing Model'!M49+'Costing Model'!M50,0) -> 35685 | F20: =ROUND('Costing Model'!N48+'Costing Model'!N49+'Costing Model'!N50,0) -> 33905 | G20: =ROUND('Costing Model'!O48+'Costing Model'!O49+'Costing Model'!O50,0) -> 22030
A21: Start up Costs | B21: ='Costing Model'!J22+'Costing Model'!J23+'Costing Model'!J24+'Costing Model'!J25+'Costing Model'!J26+'Costing Model'!J27 -> 25200 | C21: ='Costing Model'!K22+'Costing Model'!K23+'Costing Model'!K24+'Costing Model'!K25+'Costing Model'!K26+'Costing Model'!K27 -> 0 | D21: ='Costing Model'!L22+'Costing Model'!L23+'Costing Model'!L24+'Costing Model'!L25+'Costing Model'!L26+'Costing Model'!L27 -> 0 | E21: ='Costing Model'!M22+'Costing Model'!M23+'Costing Model'!M24+'Costing Model'!M25+'Costing Model'!M26+'Costing Model'!M27 -> 0 | F21: ='Costing Model'!N22+'Costing Model'!N23+'Costing Model'!N24+'Costing Model'!N25+'Costing Model'!N26+'Costing Model'!N27 -> 0 | G21: ='Costing Model'!O22+'Costing Model'!O23+'Costing Model'!O24+'Costing Model'!O25+'Costing Model'!O26+'Costing Model'!O27 -> 0
A22: Delivery costs | B22: ='Costing Model'!J31+'Costing Model'!J32+'Costing Model'!J33+'Costing Model'!J34+'Costing Model'!J35 -> 0 | C22: ='Costing Model'!K31+'Costing Model'!K32+'Costing Model'!K33+'Costing Model'!K34+'Costing Model'!K35 -> 403 | D22: ='Costing Model'!L31+'Costing Model'!L32+'Costing Model'!L33+'Costing Model'!L34+'Costing Model'!L35 -> 825 | E22: ='Costing Model'!M31+'Costing Model'!M32+'Costing Model'!M33+'Costing Model'!M34+'Costing Model'!M35 -> 1261 | F22: ='Costing Model'!N31+'Costing Model'!N32+'Costing Model'!N33+'Costing Model'!N34+'Costing Model'!N35 -> 1287 | G22: ='Costing Model'!O31+'Costing Model'!O32+'Costing Model'!O33+'Costing Model'!O34+'Costing Model'!O35 -> 874
A23: Management costs | B23: ='Costing Model'!J38+'Costing Model'!J39+'Costing Model'!J40 -> 2400 | C23: ='Costing Model'!K38+'Costing Model'!K39+'Costing Model'!K40 -> 2448 | D23: ='Costing Model'!L38+'Costing Model'!L39+'Costing Model'!L40 -> 4993 | E23: ='Costing Model'!M38+'Costing Model'!M39+'Costing Model'!M40 -> 7640 | F23: ='Costing Model'!N38+'Costing Model'!N39+'Costing Model'!N40 -> 7793 | G23: ='Costing Model'!O38+'Costing Model'!O39+'Costing Model'!O40 -> 5300
B24: =SUM(B19:B23) -> 27600 | C24: =SUM(C19:C23) -> 35967 | D24: =SUM(D19:D23) -> 64627 | E24: =SUM(E19:E23) -> 85228 | F24: =SUM(F19:F23) -> 85283 | G24: =SUM(G19:G23) -> 50830
A26: Overhead Costs | B26: =ROUND('Policy decisions'!B33*'Inc Exp Forecast'!B17,0) -> 2626 | C26: =ROUND('Policy decisions'!C33*'Inc Exp Forecast'!C17,0) -> 5555 | D26: =ROUND('Policy decisions'!D33*'Inc Exp Forecast'!D17,0) -> 7617 | E26: =ROUND('Policy decisions'!E33*'Inc Exp Forecast'!E17,0) -> 8155 | F26: =ROUND('Policy decisions'!F33*'Inc Exp Forecast'!F17,0) -> 8231 | G26: =ROUND('Policy decisions'!G33*'Inc Exp Forecast'!G17,0) -> 5977
A29: Surplus/ (Loss) | B29: =ROUND(B10-B17-B24-B26,0) -> -36792 | C29: =ROUND(C10-C17-C24-C26,0) -> 198951 | D29: =ROUND(D10-D17-D24-D26,0) -> 365064 | E29: =ROUND(E10-E17-E24-E26,0) -> 443966 | F29: =ROUND(F10-F17-F24-F26,0) -> 453163 | G29: =ROUND(G10-G17-G24-G26,0) -> 249889
A31: Cumulative Surplus / (Loss) | B31: =B29 -> -36792 | C31: =B31+C29 -> 162159 | D31: =C31+D29 -> 527223 | E31: =D31+E29 -> 971189 | F31: =E31+F29 -> 1424352 | G31: =F31+G29 -> 1674241

Sheet Policy decisions
A1: Basis and assumption within model
A3: Rate of staff delivering is it cost of backfill or actual cost of staff involved | H3: -
A5: Currency risk is ignored within the model
A7: Definition of Years | B7: Year 0 | C7: Year 1 | D7: Year 2 | E7: Year 3 | F7: Year 4 | G7: Year 5
B8: 2012-13 | C8: 2013-14 | D8: 2014-15 | E8: 2015-16 | F8: 2016-17 | G8: 2017-18
A15: Inflation rate defined
B17: Year 0 | C17: Year 1 | D17: Year 2 | E17: Year 3 | F17: Year 4 | G17: Year 5
A18: Inflation Pay | B18: 0 | C18: 0.02 | D18: 0.02 | E18: 0.02 | F18: 0.02 | G18: 0.02
A19: Other costs | B19: 0 | C19: 0.02 | D19: 0.02 | E19: 0.02 | F19: 0.02 | G19: 0.02
A20: Income | B20: 0 | C20: 0 | D20: 0.02 | E20: 0.02 | F20: 0.02 | G20: 0.02
A22: Compounded Interest
B23: Year 0 | C23: Year 1 | D23: Year 2 | E23: Year 3 | F23: Year 4 | G23: Year 5
A24: Inflation Pay | B24: =1 -> 1 | C24: =B24+C18 -> 1.02 | D24: =ROUND(C24*(1+D18),4) -> 1.0404 | E24: =ROUND(D24*(1+E18),4) -> 1.0612 | F24: =ROUND(E24*(1+F18),4) -> 1.0824 | G24: =ROUND(F24*(1+G18),4) -> 1.104
A25: Other costs | B25: =1 -> 1 | C25: =B25+C19 -> 1.02 | D25: =ROUND(C25*(1+D19),4) -> 1.0404 | E25: =ROUND(D25*(1+E19),4) -> 1.0612 | F25: =ROUND(E25*(1+F19),4) -> 1.0824 | G25: =ROUND(F25*(1+G19),4) -> 1.104
A26: Income | B26: =1 -> 1 | C26: =B26+C20 -> 1 | D26: =ROUND(C26*(1+D20),4) -> 1.02 | E26: =ROUND(D26*(1+E20),4) -> 1.0404 | F26: =ROUND(E26*(1+F20),4) -> 1.0612 | G26: =ROUND(F26*(1+G20),4) -> 1.0824
A29: Scholarship / bursary rate
A30: % of income | B30: 0.15 | C30: 0.15 | D30: 0.15 | E30: 0.15 | F30: 0.15 | G30: 0.15
A32: Overhead Rate
A33: % of Total Staff Costs | B33: 0.4 | C33: 0.4 | D33: 0.4 | E33: 0.4 | F33: 0.4 | G33: 0.4
A35: 1st year withdrawal rate | C35: 0.08
A36: 2-4th year Withdrawal / non completion rate | C36: 0.05
A38: Commission Rate | C38: 0.1
A40: Franchise Cost % Fee if relevant | C40: 0
A42: PAS Group Feedback
A44: Also could have different rate for placement year? | E44: Assumptions for placement year Yes or no?
A46: Add support costs on staff costs

Sheet Income Model
A1: Income Estimate
K2: Notes re model
A3: Home Intake | E3: 10 | F3: 10 | G3: 10 | H3: 0 | I3: 0
A4: International Intake | E4: 15 | F4: 10 | G4: 10 | H4: 0 | I4: 0
A6: Home
A8: Number of students - FTE | E8: ='Policy decisions'!C8 -> 2013-14 | F8: ='Policy decisions'!D8 -> 2014-15 | G8: ='Policy decisions'!E8 -> 2015-16 | H8: ='Policy decisions'!F8 -> 2016-17 | I8: ='Policy decisions'!G8 -> 2017-18 | K8: That FTE rolled forward automatically
A9: First Year - 1FTE | E9: =ROUND(E3*(1-'Policy decisions'!$C$35),1) -> 9.2 | F9: =ROUND(F3*(1-'Policy decisions'!$C$35),1) -> 9.2 | G9: =ROUND(G3*(1-'Policy decisions'!$C$35),1) -> 9.2 | H9: =ROUND(H3*(1-'Policy decisions'!$C$35),1) -> 0 | I9: =ROUND(I3*(1-'Policy decisions'!$C$35),1) -> 0 | K9: with withdrawal / non completion rate
A10: Second Year 1 FTE | F10: =E9*(1-$E$25) -> 8.74 | G10: =F9*(1-$E$25) -> 8.74 | H10: =G9*(1-$E$25) -> 8.74 | I10: =H9*(1-$E$25) -> 0 | K10: applied to student numbers for future
A11: Placement Year 0.5 FTE | G11: =ROUND(F10*0.5*(1-$E$25),1) -> 4.2 | H11: =ROUND(G10*0.5*(1-$E$25),1) -> 4.2 | I11: =ROUND(H10*0.5*(1-$E$25),1) -> 4.2 | K11: years
A12: Final Year 1 FTE | H12: =ROUND(G11*2*(1-$E$25),1) -> 8 | I12: =ROUND(H11*2*(1-$E$25),1) -> 8
A13: Total Home Student FTE | E13: =SUM(E9:E12) -> 9.2 | F13: =SUM(F9:F12) -> 17.94 | G13: =SUM(G9:G12) -> 22.14 | H13: =SUM(H9:H12) -> 20.94 | I13: =SUM(I9:I12) -> 12.2
A14: Number of cohorts | E14: 1 | F14: 2 | G14: 3 | H14: 3 | I14: 2 | K14: The model will w
A15: International
A17: Number of students - FTE | E17: ='Policy decisions'!C8 -> 2013-14 | F17: ='Policy decisions'!D8 -> 2014-15 | G17: ='Policy decisions'!E8 -> 2015-16 | H17: ='Policy decisions'!F8 -> 2016-17 | I17: ='Policy decisions'!G8 -> 2017-18 | K17: Note That the model could be used for student headcount
A18: First Year - 1FTE | E18: =ROUND(E4*(1-'Policy decisions'!$C$35),1) -> 13.8 | F18: =ROUND(F4*(1-'Policy decisions'!$C$35),1) -> 9.2 | G18: =ROUND(G4*(1-'Policy decisions'!$C$35),1) -> 9.2 | H18: =ROUND(H4*(1-'Policy decisions'!$C$35),1) -> 0 | I18: =ROUND(I4*(1-'Policy decisions'!$C$35),1) -> 0 | K18: However then the fee rate would have would have to be
A19: Second Year 1 FTE | F19: =E18*(1-$E$25) -> 13.11 | G19: =F18*(1-$E$25) -> 8.74 | H19: =G18*(1-$E$25) -> 8.74 | I19: =H18*(1-$E$25) -> 0 | K19: per headcount.
A20: Placement Year 0.5 FTE | G20: =ROUND(F19*0.5*(1-$E$25),1) -> 6.2 | H20: =ROUND(G19*0.5*(1-$E$25),1) -> 4.2 | I20: =ROUND(H19*0.5*(1-$E$25),1) -> 4.2
A21: Final Year 1 FTE | H21: =ROUND(G20*2*(1-$E$25),1) -> 11.8 | I21: =ROUND(H20*2*(1-$E$25),1) -> 8
A22: Total Intl Students | E22: =SUM(E18:E21) -> 13.8 | F22: =SUM(F18:F21) -> 22.31 | G22: =SUM(G18:G21) -> 24.14 | H22: =SUM(H18:H21) -> 24.74 | I22: =SUM(I18:I21) -> 12.2
A23: Number of cohorts | E23: 1 | F23: 2 | G23: 3 | H23: 3 | I23: 2
A24: TOTAL NUMBER OF COHORTS | E24: 1 | F24: 2 | G24: 3 | H24: 3 | I24: 2
A25: Withdrawal - Non Completion Rate | E25: ='Policy decisions'!C36 -> 0.05
A27: RATE PER STUDENT / PER COHORT | E27: £ | F27: £ | G27: £ | H27: £ | I27: £
B28: Fees Home | C28: Fees paid by student per FTE | E28: 2000 | F28: =ROUND($E28*'Policy decisions'!D$26,0) -> 2040 | G28: =ROUND($E28*'Policy decisions'!E$26,0) -> 2081 | H28: =ROUND($E28*'Policy decisions'!F$26,0) -> 2122 | I28: =ROUND($E28*'Policy decisions'!G$26,0) -> 2165 | K28: That income per student / cohort
C29: Fees paid by employer per FTE | E29: 5000 | F29: =ROUND($E29*'Policy decisions'!D$26,0) -> 5100 | G29: =ROUND($E29*'Policy decisions'!E$26,0) -> 5202 | H29: =ROUND($E29*'Policy decisions'!F$26,0) -> 5306 | I29: =ROUND($E29*'Policy decisions'!G$26,0) -> 5412 | K29: increased for rate of inflation
C30: Fees paid by third party per FTE | E30: 1000 | F30: =ROUND($E30*'Policy decisions'!D$26,0) -> 1020 | G30: =ROUND($E30*'Policy decisions'!E$26,0) -> 1040 | H30: =ROUND($E30*'Policy decisions'!F$26,0) -> 1061 | I30: =ROUND($E30*'Policy decisions'!G$26,0) -> 1082 | K30: shown on assumption sheet
C31: Block rate paid per cohort | E31: 20000 | F31: =ROUND($E31*'Policy decisions'!D$26,0) -> 20400 | G31: =ROUND($E31*'Policy decisions'!E$26,0) -> 20808 | H31: =ROUND($E31*'Policy decisions'!F$26,0) -> 21224 | I31: =ROUND($E31*'Policy decisions'!G$26,0) -> 21648
K32: To Check
B33: Grant | C33: Teaching grant (B Courses only) | E33: Outstanding
B36: Fees International
C37: Fees paid by student per FTE | E37: 3000 | F37: =ROUND($E37*'Policy decisions'!D$26,0) -> 3060 | G37: =ROUND($E37*'Policy decisions'!E$26,0) -> 3121 | H37: =ROUND($E37*'Policy decisions'!F$26,0) -> 3184 | I37: =ROUND($E37*'Policy decisions'!G$26,0) -> 3247
C38: Fees paid by employer per FTE | E38: 8000 | F38: =ROUND($E38*'Policy decisions'!D$26,0) -> 8160 | G38: =ROUND($E38*'Policy decisions'!E$26,0) -> 8323 | H38: =ROUND($E38*'Policy decisions'!F$26,0) -> 8490 | I38: =ROUND($E38*'Policy decisions'!G$26,0) -> 8659
C39: Fees paid by third party per FTE | E39: 0 | F39: =ROUND($E39*'Policy decisions'!D$26,0) -> 0 | G39: =ROUND($E39*'Policy decisions'!E$26,0) -> 0 | H39: =ROUND($E39*'Policy decisions'!F$26,0) -> 0 | I39: =ROUND($E39*'Policy decisions'!G$26,0) -> 0
C40: Block rate paid per cohort | E40: 20000 | F40: =ROUND($E40*'Policy decisions'!D$26,0) -> 20400 | G40: =ROUND($E40*'Policy decisions'!E$26,0) -> 20808 | H40: =ROUND($E40*'Policy decisions'!F$26,0) -> 21224 | I40: =ROUND($E40*'Policy decisions'!G$26,0) -> 21648
A43: Estimated Income
B45: Fees Home | C45: Fees paid by student | E45: =ROUND(E28*E$13,0) -> 18400 | F45: =ROUND(F28*F$13,0) -> 36598 | G45: =ROUND(G28*G$13,0) -> 46073 | H45: =ROUND(H28*H$13,0) -> 44435 | I45: =ROUND(I28*I$13,0) -> 26413
C46: Fees paid by employer | E46: =ROUND(E29*E$13,0) -> 46000 | F46: =ROUND(F29*F$13,0) -> 91494 | G46: =ROUND(G29*G$13,0) -> 115172 | H46: =ROUND(H29*H$13,0) -> 111108 | I46: =ROUND(I29*I$13,0) -> 66026
C47: Fees paid by third party | E47: =ROUND(E30*E$13,0) -> 9200 | F47: =ROUND(F30*F$13,0) -> 18299 | G47: =ROUND(G30*G$13,0) -> 23026 | H47: =ROUND(H30*H$13,0) -> 22217 | I47: =ROUND(I30*I$13,0) -> 13200
C48: Block rate paid per cohort | E48: =ROUND(E31*E$14,0) -> 20000 | F48: =ROUND(F31*F$14,0) -> 40800 | G48: =ROUND(G31*G$14,0) -> 62424 | H48: =ROUND(H31*H$14,0) -> 63672 | I48: =ROUND(I31*I$14,0) -> 43296
B49: Home Fees Sub total | E49: =SUM(E45:E48) -> 93600 | F49: =SUM(F45:F48) -> 187191 | G49: =SUM(G45:G48) -> 246695 | H49: =SUM(H45:H48) -> 241432 | I49: =SUM(I45:I48) -> 148935
...

Sheet Costing Model
A1: Aston University Costing of Collaborative Provision
Q2: Notes
E3: Rate per student £ | F3: Number of students | G3: Wastage % | H3: Number of students completing | J3: Income £
A4: Income | B4: Fees | C4: Fees paid by student | E4: 3000 | F4: 5 | G4: 0.05 | H4: =F4*(1-G4) -> 4.75 | J4: =E4*H4 -> 14250
C5: Fees paid by employer | E5: 2000 | F5: =5 -> 5 | G5: =G4 -> 0.05 | H5: =F5*(1-G5) -> 4.75 | J5: =E5*H5 -> 9500
C6: Fees paid by third party | E6: 0 | F6: 6 | G6: 0 | H6: =F6*(1-G6) -> 6 | J6: =E6*H6 -> 0
B9: Grant | C9: Teaching grant (B Courses only) | E9: 1495 | F9: 0 | H9: =F9*G9 -> 0 | J9: =E9*H9 -> 0
C10: CFEE grant | E10: 0 | H10: =F10*G10 -> 0 | J10: =E10*H10 -> 0
C11: Widening Participation attributable | E11: 0 | H11: =F11*G11 -> 0 | J11: =E11*H11 -> 0
B13: TOTAL | J13: =SUM(J4:J12) -> 23750
A18: Costs
A19: Direct Costs | J19: ='Policy decisions'!B8 -> 2012-13 | K19: ='Policy decisions'!C8 -> 2013-14 | L19: ='Policy decisions'!D8 -> 2014-15 | M19: ='Policy decisions'!E8 -> 2015-16 | N19: ='Policy decisions'!F8 -> 2016-17 | O19: ='Policy decisions'!G8 -> 2017-18
F20: % Allowances | G20: Cost Excl VAT | H20: VAT Rate | J20: Cost Incl VAT
B21: Course Development | D21: Staff cost for development | G21: ='Staff Costing Schedule'!K36 -> 6566 | H21: N/A | J21: =G21*1 -> 6566 | K21: ='Staff Costing Schedule'!Q36 -> 5541 | L21: ='Staff Costing Schedule'!R36 -> 4204 | M21: ='Staff Costing Schedule'!S36 -> 2111 | N21: ='Staff Costing Schedule'!T36 -> 3166 | O21: ='Staff Costing Schedule'!U36 -> 633
D22: Materials | G22: 5000 | H22: 0.2 | J22: =ROUND(G22*(1+H22),0) -> 6000
D23: Consultancy | G23: 1000 | H23: 0.2 | J23: =ROUND(G23*(1+H23),0) -> 1200
D24: Primary purpose Advertising | G24: 5000 | H24: 0 | J24: =ROUND(G24*(1+H24),0) -> 5000
D25: Closed course advertising | G25: 2000 | H25: 0.2 | J25: =ROUND(G25*(1+H25),0) -> 2400
D26: IT / Hardware | G26: 8000 | H26: 0.2 | J26: =ROUND(G26*(1+H26),0) -> 9600
D27: External assessor / examiner | G27: 1000 | J27: =ROUND(G27*(1+H27),0) -> 1000
G29: £ PER COHORT
B30: Course Delivery | D30: Staff costs | G30: ='Staff Costing Schedule'!K52 -> 0 | H30: N/A | K30: ='Staff Costing Schedule'!Q52 -> 7268 | L30: ='Staff Costing Schedule'!R52 -> 13739 | M30: ='Staff Costing Schedule'!S52 -> 17155 | N30: ='Staff Costing Schedule'!T52 -> 16268 | O30: ='Staff Costing Schedule'!U52 -> 13142 | Q30: Linked to inflation and number of cohorts
B31: (Variable cost based on | D31: Consultancy | E31: Costs per cohort | G31: 50 | H31: 0.2 | I31: =ROUND($G31*(1+$H31),0) -> 60 | K31: =ROUND($I31*'Income Model'!E$24*'Policy decisions'!C$25,0) -> 61 | L31: =ROUND($I31*'Income Model'!F$24*'Policy decisions'!D$25,0) -> 125 | M31: =ROUND($I31*'Income Model'!G$24*'Policy decisions'!E$25,0) -> 191 | N31: =ROUND($I31*'Income Model'!H$24*'Policy decisions'!F$25,0) -> 195 | O31: =ROUND($I31*'Income Model'!I$24*'Policy decisions'!G$25,0) -> 132 | Q31: Linked to inflation and number of cohorts
B32: number of students/cohorts) | D32: Course Materials | E32: Costs per cohort | G32: 100 | H32: 0.2 | I32: =ROUND($G32*(1+$H32),0) -> 120 | K32: =ROUND($I32*'Income Model'!E$24*'Policy decisions'!C$25,0) -> 122 | L32: =ROUND($I32*'Income Model'!F$24*'Policy decisions'!D$25,0) -> 250 | M32: =ROUND($I32*'Income Model'!G$24*'Policy decisions'!E$25,0) -> 382 | N32: =ROUND($I32*'Income Model'!H$24*'Policy decisions'!F$25,0) -> 390 | O32: =ROUND($I32*'Income Model'!I$24*'Policy decisions'!G$25,0) -> 265 | Q32: Linked to inflation and number of cohorts
D33: IT costs | E33: Costs per cohort | G33: 100 | H33: 0.2 | I33: =ROUND($G33*(1+$H33),0) -> 120 | K33: =ROUND($I33*'Income Model'!E$24*'Policy decisions'!C$25,0) -> 122 | L33: =ROUND($I33*'Income Model'!F$24*'Policy decisions'!D$25,0) -> 250 | M33: =ROUND($I33*'Income Model'!G$24*'Policy decisions'!E$25,0) -> 382 | N33: =ROUND($I33*'Income Model'!H$24*'Policy decisions'!F$25,0) -> 390 | O33: =ROUND($I33*'Income Model'!I$24*'Policy decisions'!G$25,0) -> 265 | Q33: Linked to inflation and number of cohorts
D34: Library | E34: Costs per cohort | G34: 40 | H34: 0.2 | I34: =ROUND($G34*(1+$H34),0) -> 48 | K34: =ROUND($I34*'Income Model'!E$24*'Policy decisions'!C$25,0) -> 49 | L34: =ROUND($I34*'Income Model'!F$24*'Policy decisions'!D$25,0) -> 100 | M34: =ROUND($I34*'Income Model'!G$24*'Policy decisions'!E$25,0) -> 153 | N34: =ROUND($I34*'Income Model'!H$24*'Policy decisions'!F$25,0) -> 156 | O34: =ROUND($I34*'Income Model'!I$24*'Policy decisions'!G$25,0) -> 106 | Q34: Linked to inflation and number of cohorts
D35: Examination costs | E35: Costs per cohort | G35: 40 | H35: 0.2 | I35: =ROUND($G35*(1+$H35),0) -> 48 | K35: =ROUND($I35*'Income Model'!E$24*'Policy decisions'!C$25,0) -> 49 | L35: =ROUND($I35*'Income Model'!F$24*'Policy decisions'!D$25,0) -> 100 | M35: =ROUND($I35*'Income Model'!G$24*'Policy decisions'!E$25,0) -> 153 | N35: =ROUND($I35*'Income Model'!H$24*'Policy decisions'!F$25,0) -> 156 | O35: =ROUND($I35*'Income Model'!I$24*'Policy decisions'!G$25,0) -> 106 | Q35: Linked to inflation and number of cohorts
B37: Quality / Collaborative Visits | D37: Staff Cost | G37: ='Staff Costing Schedule'!K67 -> 0 | H37: N/A | K37: ='Staff Costing Schedule'!Q67 -> 1078 | L37: ='Staff Costing Schedule'!R67 -> 1100 | M37: ='Staff Costing Schedule'!S67 -> 1121 | N37: ='Staff Costing Schedule'!T67 -> 1144 | O37: ='Staff Costing Schedule'!U67 -> 1167
D38: Travel | G38: 1000 | H38: 0.2 | I38: =ROUND($G38*(1+$H38),0) -> 1200 | J38: 1200 | K38: =ROUND($I38*'Income Model'!E$24*'Policy decisions'!C$25,0) -> 1224 | L38: =ROUND($I38*'Income Model'!F$24*'Policy decisions'!D$25,0) -> 2497 | M38: =ROUND($I38*'Income Model'!G$24*'Policy decisions'!E$25,0) -> 3820 | N38: =ROUND($I38*'Income Model'!H$24*'Policy decisions'!F$25,0) -> 3897 | O38: =ROUND($I38*'Income Model'!I$24*'Policy decisions'!G$25,0) -> 2650 | Q38: Linked to inflation and number of cohorts
D39: Accomodation | G39: 500 | H39: 0.2 | I39: =ROUND($G39*(1+$H39),0) -> 600 | J39: =ROUND(G39*(1+H39),0) -> 600 | K39: =ROUND($I39*'Income Model'!E$24*'Policy decisions'!C$25,0) -> 612 | L39: =ROUND($I39*'Income Model'!F$24*'Policy decisions'!D$25,0) -> 1248 | M39: =ROUND($I39*'Income Model'!G$24*'Policy decisions'!E$25,0) -> 1910 | N39: =ROUND($I39*'Income Model'!H$24*'Policy decisions'!F$25,0) -> 1948 | O39: =ROUND($I39*'Income Model'!I$24*'Policy decisions'!G$25,0) -> 1325 | Q39: Linked to inflation and number of cohorts
D40: Entertaining | G40: 500 | H40: 0.2 | I40: =ROUND($G40*(1+$H40),0) -> 600 | J40: =ROUND(G40*(1+H40),0) -> 600 | K40: =ROUND($I40*'Income Model'!E$24*'Policy decisions'!C$25,0) -> 612 | L40: =ROUND($I40*'Income Model'!F$24*'Policy decisions'!D$25,0) -> 1248 | M40: =ROUND($I40*'Income Model'!G$24*'Policy decisions'!E$25,0) -> 1910 | N40: =ROUND($I40*'Income Model'!H$24*'Policy decisions'!F$25,0) -> 1948 | O40: =ROUND($I40*'Income Model'!I$24*'Policy decisions'!G$25,0) -> 1325 | Q40: Linked to inflation and number of cohorts
B44: Commission paid for student recruitment | F44: ='Policy decisions'!C38 -> 0.1 | H44: 0.2 | K44: =ROUND($F44*(1+$H44)*'Income Model'!E58,0) -> 20616 | L44: =ROUND($F44*(1+$H44)*'Income Model'!F58,0) -> 34934 | M44: =ROUND($F44*(1+$H44)*'Income Model'!G58,0) -> 40642 | N44: =ROUND($F44*(1+$H44)*'Income Model'!H58,0) -> 42298 | O44: =ROUND($F44*(1+$H44)*'Income Model'!I58,0) -> 22626 | Q44: Insert commission %
Q45: Assuming commission on all intl fees
B46: Franchise Cost for delivery of education by | H46: N/A
B47: another eligible body ( therefore nil VAT)
D48: Standard Franchise Fee per student | G48: 500 | H48: N/A | K48: =ROUND($G48*('Income Model'!E74+'Income Model'!E83),0) -> 12500 | L48: =ROUND($G48*('Income Model'!F74+'Income Model'!F83),0) -> 23875 | M48: =ROUND($G48*('Income Model'!G74+'Income Model'!G83),0) -> 35685 | N48: =ROUND($G48*('Income Model'!H74+'Income Model'!H83),0) -> 33905 | O48: =ROUND($G48*('Income Model'!I74+'Income Model'!I83),0) -> 22030 | Q48: }
C49: or | D49: Standard cost per cohort | F49: OR | G49: 0 | H49: N/A | K49: =IF((K48+K50)>0,0,$G49*'Income Model'!E$90*'Policy decisions'!C$26) -> 0 | L49: =IF((L48+L50)>0,0,$G49*'Income Model'!F$90*'Policy decisions'!D$26) -> 0 | M49: =IF((M48+M50)>0,0,$G49*'Income Model'!G$90*'Policy decisions'!E$26) -> 0 | N49: =IF((N48+N50)>0,0,$G49*'Income Model'!H$90*'Policy decisions'!F$26) -> 0 | O49: =IF((O48+O50)>0,0,$G49*'Income Model'!I$90*'Policy decisions'!G$26) -> 0 | Q49: } Circular dependency
C50: or | D50: % of fees collected | F50: ='Policy decisions'!C40 -> 0 | H50: N/A | K50: =IF(((K49+K48)>1),0,$F50*('Income Model'!E99+'Income Model'!E108)) -> 0 | L50: =IF(((L49+L48)>1),0,$F50*('Income Model'!F99+'Income Model'!F108)) -> 0 | M50: =IF(((M49+M48)>1),0,$F50*('Income Model'!G99+'Income Model'!G108)) -> 0 | N50: =IF(((N49+N48)>1),0,$F50*('Income Model'!H99+'Income Model'!H108)) -> 0 | O50: =IF(((O49+O48)>1),0,$F50*('Income Model'!I99+'Income Model'!I108)) -> 0 | Q50: }

Sheet Staff Costing Schedule
C1: Normal grade range | D1: HERA Grade - Spine Point | E1: Gross salary | F1: On costs | G1: Total Annual Cost | H1: Number of days per annum | I1: Rate per hour
C2: (and spine points) | F2: =0.16+0.12 -> 0.28 | I2: 7.5 | J2: hours
A4: WORKING
A5: Sessional Lecturer | F5: =E5*F$2 -> 0 | G5: =E5+F5 -> 0 | H5: =((52-8)*5) -> 220 | I5: =G5/H5/I$2 -> 0
A7: Academic
B8: Teaching and Scholarship | C8: Grade 7 (22 - 28) | D8: 28 | E8: =VLOOKUP(D8,'Pay Source data'!$A$1:$B$58,2,FALSE) -> 28401 | F8: =E8*F$2 -> 7952.28 | G8: =E8+F8 -> 36353.28 | H8: =((52-8)*5) -> 220 | I8: =ROUND(G8/H8/I$2,2) -> 22.03
B9: Lecturer | C9: Grade 8 -9 (30 - 43) | D9: 35 | E9: =VLOOKUP(D9,'Pay Source data'!$A$1:$B$58,2,FALSE) -> 33884 | F9: =E9*F$2 -> 9487.52 | G9: =E9+F9 -> 43371.52 | H9: =((52-8)*5) -> 220 | I9: =ROUND(G9/H9/I$2,2) -> 26.29
B10: Senior Lecturer | C10: Grade 10 (44-49) | D10: 40 | E10: =VLOOKUP(D10,'Pay Source data'!$A$1:$B$58,2,FALSE) -> 40430 | F10: =E10*F$2 -> 11320.4 | G10: =E10+F10 -> 51750.4 | H10: =((52-8)*5)-10 -> 210 | I10: =ROUND(G10/H10/I$2,2) -> 32.86
B11: Reader | C11: Grade 10 - 10+ (44-58) | D11: 45 | E11: =VLOOKUP(D11,'Pay Source data'!$A$1:$B$58,2,FALSE) -> 46846 | F11: =E11*F$2 -> 13116.88 | G11: =E11+F11 -> 59962.88 | H11: =((52-8)*5)-20 -> 200 | I11: =ROUND(G11/H11/I$2,2) -> 39.98
B12: Professor | C12: Professorial (1-19) | D12: 18 | E12: =VLOOKUP(D12,'Pay Source data'!$A$63:$B$81,2,FALSE) -> 93000 | F12: =E12*F$2 -> 26040 | G12: =E12+F12 -> 119040 | H12: =((52-8)*5)-25 -> 195 | I12: =ROUND(G12/H12/I$2,2) -> 81.39
A13: Support Costs
B14: Administrator | C14: Grade5- 6 (15-21) | D14: 16 | E14: =VLOOKUP(D14,'Pay Source data'!$A$1:$B$58,2,FALSE) -> 19972 | F14: =E14*F$2 -> 5592.16 | G14: =E14+F14 -> 25564.16 | H14: 220 | I14: =ROUND(G14/H14/I$2,2) -> 15.49
B15: Senior Administrator | C15: Grade7-8 (22-35) | D15: 30 | E15: =VLOOKUP(D15,'Pay Source data'!$A$1:$B$58,2,FALSE) -> 30122 | F15: =E15*F$2 -> 8434.16 | G15: =E15+F15 -> 38556.16 | H15: 220 | I15: =ROUND(G15/H15/I$2,2) -> 23.37
B16: Team Manager | C16: Grade 9-10 (36-58) | D16: 51 | E16: =VLOOKUP(D16,'Pay Source data'!$A$1:$B$58,2,FALSE) -> 55908 | F16: =E16*F$2 -> 15654.24 | G16: =E16+F16 -> 71562.24 | H16: 220 | I16: =ROUND(G16/H16/I$2,2) -> 43.37
Q17: Inflation %
Q18: 0.02 | R18: 0.03 | S18: 0.02
A19: Staff costing of activities
C20: Normal grade range | D20: HERA Grade - Spine Point | E20: Gross salary | F20: On costs | G20: Total Annual Cost | H20: Number of days per annum | I20: Rate per hour | J20: Hours | K20: Year 0 Cost of Time | L20: Hours Year 1 | M20: Hours Year 2 | N20: Hours Year 3 | O20: Hours Year 4 | P20: Hours Year 5 | Q20: Cost Year 1 | R20: Cost Year 2 | S20: Cost Year 3 | T20: Cost Year 4 | U20: Cost Year 5
C21: (and spine points) | F21: =0.16+0.12 -> 0.28 | I21: 7.5 hrs per day | J21: =K21 -> 2012-13 | K21: ='Policy decisions'!B8 -> 2012-13 | L21: ='Policy decisions'!C8 -> 2013-14 | M21: ='Policy decisions'!D8 -> 2014-15 | N21: ='Policy decisions'!E8 -> 2015-16 | O21: ='Policy decisions'!F8 -> 2016-17 | P21: ='Policy decisions'!G8 -> 2017-18 | Q21: =L21 -> 2013-14 | R21: =M21 -> 2014-15 | S21: =N21 -> 2015-16 | T21: =O21 -> 2016-17 | U21: =P21 -> 2017-18
A22: Course Development
A24: Sessional Lecturer | F24: =E24*F$2 -> 0 | G24: =E24+F24 -> 0 | H24: =((52-8)*5) -> 220 | I24: ='Pay Source data'!I93 -> 44.47 | K24: =ROUND(J24*I24,0) -> 0 | L24: 20 | M24: 20 | N24: 20 | O24: 60 | P24: 10 | Q24: =ROUND($I24*'Policy decisions'!C$24*(L24),0) -> 907 | R24: =ROUND($I24*'Policy decisions'!D$24*(M24),0) -> 925 | S24: =ROUND($I24*'Policy decisions'!E$24*(N24),0) -> 944 | T24: =ROUND($I24*'Policy decisions'!F$24*(O24),0) -> 2888 | U24: =ROUND($I24*'Policy decisions'!G$24*(P24),0) -> 491
A26: Academic
B27: Teaching and Scholarship | C27: Grade 7 (22 - 28) | D27: 28 | E27: =VLOOKUP(D27,'Pay Source data'!$A$1:$B$58,2,FALSE) -> 28401 | F27: =E27*F$2 -> 7952.28 | G27: =E27+F27 -> 36353.28 | H27: =((52-8)*5) -> 220 | I27: =ROUND(G27/H27/I$2,2) -> 22.03 | J27: 10 | K27: =ROUND(J27*I27,0) -> 220 | L27: 50 | Q27: =ROUND($I27*'Policy decisions'!C$24*(L27),0) -> 1124 | R27: =ROUND($I27*'Policy decisions'!D$24*(M27),0) -> 0 | S27: =ROUND($I27*'Policy decisions'!E$24*(N27),0) -> 0 | T27: =ROUND($I27*'Policy decisions'!F$24*(O27),0) -> 0 | U27: =ROUND($I27*'Policy decisions'!G$24*(P27),0) -> 0
B28: Lecturer | C28: Grade 8 -9 (30 - 43) | D28: 35 | E28: =VLOOKUP(D28,'Pay Source data'!$A$1:$B$58,2,FALSE) -> 33884 | F28: =E28*F$2 -> 9487.52 | G28: =E28+F28 -> 43371.52 | H28: =((52-8)*5) -> 220 | I28: =ROUND(G28/H28/I$2,2) -> 26.29 | K28: =ROUND(J28*I28,0) -> 0 | Q28: =ROUND($I28*'Policy decisions'!C$24*(L28),0) -> 0 | R28: =ROUND($I28*'Policy decisions'!D$24*(M28),0) -> 0 | S28: =ROUND($I28*'Policy decisions'!E$24*(N28),0) -> 0 | T28: =ROUND($I28*'Policy decisions'!F$24*(O28),0) -> 0 | U28: =ROUND($I28*'Policy decisions'!G$24*(P28),0) -> 0
B29: Senior Lecturer | C29: Grade 10 (44-49) | D29: 40 | E29: =VLOOKUP(D29,'Pay Source data'!$A$1:$B$58,2,FALSE) -> 40430 | F29: =E29*F$2 -> 11320.4 | G29: =E29+F29 -> 51750.4 | H29: =((52-8)*5)-10 -> 210 | I29: =ROUND(G29/H29/I$2,2) -> 32.86 | J29: 30 | K29: =ROUND(J29*I29,0) -> 986 | N29: 10 | Q29: =ROUND($I29*'Policy decisions'!C$24*(L29),0) -> 0 | R29: =ROUND($I29*'Policy decisions'!D$24*(M29),0) -> 0 | S29: =ROUND($I29*'Policy decisions'!E$24*(N29),0) -> 349 | T29: =ROUND($I29*'Policy decisions'!F$24*(O29),0) -> 0 | U29: =ROUND($I29*'Policy decisions'!G$24*(P29),0) -> 0
B30: Reader | C30: Grade 10 - 10+ (44-58) | D30: 55 | E30: =VLOOKUP(D30,'Pay Source data'!$A$1:$B$58,2,FALSE) -> 62905.02 | F30: =E30*F$2 -> 17613.406 | G30: =E30+F30 -> 80518.426 | H30: =((52-8)*5)-20 -> 200 | I30: =ROUND(G30/H30/I$2,2) -> 53.68 | J30: 40 | K30: =ROUND(J30*I30,0) -> 2147 | L30: 30 | M30: 30 | Q30: =ROUND($I30*'Policy decisions'!C$24*(L30),0) -> 1643 | R30: =ROUND($I30*'Policy decisions'!D$24*(M30),0) -> 1675 | S30: =ROUND($I30*'Policy decisions'!E$24*(N30),0) -> 0 | T30: =ROUND($I30*'Policy decisions'!F$24*(O30),0) -> 0 | U30: =ROUND($I30*'Policy decisions'!G$24*(P30),0) -> 0
B31: Professor | C31: Professorial (1-19) | D31: 18 | E31: =VLOOKUP(D31,'Pay Source data'!$A$63:$B$81,2,FALSE) -> 93000 | F31: =E31*F$2 -> 26040 | G31: =E31+F31 -> 119040 | H31: =((52-8)*5)-25 -> 195 | I31: =ROUND(G31/H31/I$2,2) -> 81.39 | J31: 20 | K31: =ROUND(J31*I31,0) -> 1628 | Q31: =ROUND($I31*'Policy decisions'!C$24*(L31),0) -> 0 | R31: =ROUND($I31*'Policy decisions'!D$24*(M31),0) -> 0 | S31: =ROUND($I31*'Policy decisions'!E$24*(N31),0) -> 0 | T31: =ROUND($I31*'Policy decisions'!F$24*(O31),0) -> 0 | U31: =ROUND($I31*'Policy decisions'!G$24*(P31),0) -> 0
A32: Support Staff | Q32: =ROUND($I32*'Policy decisions'!C$24*(L32),0) -> 0 | R32: =ROUND($I32*'Policy decisions'!D$24*(M32),0) -> 0 | S32: =ROUND($I32*'Policy decisions'!E$24*(N32),0) -> 0 | T32: =ROUND($I32*'Policy decisions'!F$24*(O32),0) -> 0 | U32: =ROUND($I32*'Policy decisions'!G$24*(P32),0) -> 0
B33: =B14 -> Administrator | C33: =C14 -> Grade5- 6 (15-21) | D33: =D14 -> 16 | E33: =VLOOKUP(D33,'Pay Source data'!$A$1:$B$58,2,FALSE) -> 19972 | F33: =E33*F$2 -> 5592.16 | G33: =E33+F33 -> 25564.16 | H33: =((52-8)*5)-10 -> 210 | I33: =ROUND(G33/H33/I$2,2) -> 16.23 | J33: 20 | K33: =ROUND(J33*I33,0) -> 325 | L33: 5 | Q33: =ROUND($I33*'Policy decisions'!C$24*(L33),0) -> 83 | R33: =ROUND($I33*'Policy decisions'!D$24*(M33),0) -> 0 | S33: =ROUND($I33*'Policy decisions'!E$24*(N33),0) -> 0 | T33: =ROUND($I33*'Policy decisions'!F$24*(O33),0) -> 0 | U33: =ROUND($I33*'Policy decisions'!G$24*(P33),0) -> 0
B34: =B15 -> Senior Administrator | C34: =C15 -> Grade7-8 (22-35) | D34: =D15 -> 30 | E34: =VLOOKUP(D34,'Pay Source data'!$A$1:$B$58,2,FALSE) -> 30122 | F34: =E34*F$2 -> 8434.16 | G34: =E34+F34 -> 38556.16 | H34: =((52-8)*5)-20 -> 200 | I34: =ROUND(G34/H34/I$2,2) -> 25.7 | J34: 30 | K34: =ROUND(J34*I34,0) -> 771 | L34: 30 | M34: 60 | N34: 30 | O34: 10 | P34: 5 | Q34: =ROUND($I34*'Policy decisions'!C$24*(L34),0) -> 786 | R34: =ROUND($I34*'Policy decisions'!D$24*(M34),0) -> 1604 | S34: =ROUND($I34*'Policy decisions'!E$24*(N34),0) -> 818 | T34: =ROUND($I34*'Policy decisions'!F$24*(O34),0) -> 278 | U34: =ROUND($I34*'Policy decisions'!G$24*(P34),0) -> 142
B35: =B16 -> Team Manager | C35: =C16 -> Grade 9-10 (36-58) | D35: =D16 -> 51 | E35: =VLOOKUP(D35,'Pay Source data'!$A$1:$B$58,2,FALSE) -> 55908 | F35: =E35*F$2 -> 15654.24 | G35: =E35+F35 -> 71562.24 | H35: =((52-8)*5)-25 -> 195 | I35: =ROUND(G35/H35/I$2,2) -> 48.93 | J35: 10 | K35: =ROUND(J35*I35,0) -> 489 | L35: 20 | Q35: =ROUND($I35*'Policy decisions'!C$24*(L35),0) -> 998 | R35: =ROUND($I35*'Policy decisions'!D$24*(M35),0) -> 0 | S35: =ROUND($I35*'Policy decisions'!E$24*(N35),0) -> 0 | T35: =ROUND($I35*'Policy decisions'!F$24*(O35),0) -> 0 | U35: =ROUND($I35*'Policy decisions'!G$24*(P35),0) -> 0
A36: Pay cost of Course Development | K36: =SUM(K24:K35) -> 6566 | Q36: =SUM(Q24:Q35) -> 5541 | R36: =SUM(R24:R35) -> 4204 | S36: =SUM(S24:S35) -> 2111 | T36: =SUM(T24:T35) -> 3166 | U36: =SUM(U24:U35) -> 633
A37: Course Delivery
A38: Sessional Lecturer | F38: =E38*F$2 -> 0 | G38: =E38+F38 -> 0 | H38: =((52-8)*5) -> 220 | I38: ='Pay Source data'!I93 -> 44.47 | K38: =ROUND(J38*I38,0) -> 0 | L38: 20 | M38: 20 | N38: 20 | O38: 6 | P38: 45 | Q38: =ROUND($I38*'Policy decisions'!C$24*(L38),0) -> 907 | R38: =ROUND($I38*'Policy decisions'!D$24*(M38),0) -> 925 | S38: =ROUND($I38*'Policy decisions'!E$24*(N38),0) -> 944 | T38: =ROUND($I38*'Policy decisions'!F$24*(O38),0) -> 289 | U38: =ROUND($I38*'Policy decisions'!G$24*(P38),0) -> 2209
A40: Academic
B41: Teaching and Scholarship | C41: Grade 7 (22 - 28) | D41: 28 | E41: =VLOOKUP(D41,'Pay Source data'!$A$1:$B$58,2,FALSE) -> 28401 | F41: =E41*F$2 -> 7952.28 | G41: =E41+F41 -> 36353.28 | H41: =((52-8)*5) -> 220 | I41: =ROUND(G41/H41/I$2,2) -> 22.03 | K41: =ROUND(J41*I41,0) -> 0 | L41: 200 | M41: 100 | N41: 150 | O41: 150 | P41: 100 | Q41: =ROUND($I41*'Policy decisions'!C$24*(L41),0) -> 4494 | R41: =ROUND($I41*'Policy decisions'!D$24*(M41),0) -> 2292 | S41: =ROUND($I41*'Policy decisions'!E$24*(N41),0) -> 3507 | T41: =ROUND($I41*'Policy decisions'!F$24*(O41),0) -> 3577 | U41: =ROUND($I41*'Policy decisions'!G$24*(P41),0) -> 2432
B42: Lecturer | C42: Grade 8 -9 (30 - 43) | D42: 35 | E42: =VLOOKUP(D42,'Pay Source data'!$A$1:$B$58,2,FALSE) -> 33884 | F42: =E42*F$2 -> 9487.52 | G42: =E42+F42 -> 43371.52 | H42: =((52-8)*5) -> 220 | I42: =ROUND(G42/H42/I$2,2) -> 26.29 | K42: =ROUND(J42*I42,0) -> 0 | M42: 250 | N42: 350 | O42: 350 | P42: 250 | Q42: =ROUND($I42*'Policy decisions'!C$24*(L42),0) -> 0 | R42: =ROUND($I42*'Policy decisions'!D$24*(M42),0) -> 6838 | S42: =ROUND($I42*'Policy decisions'!E$24*(N42),0) -> 9765 | T42: =ROUND($I42*'Policy decisions'!F$24*(O42),0) -> 9960 | U42: =ROUND($I42*'Policy decisions'!G$24*(P42),0) -> 7256
B43: Senior Lecturer | C43: Grade 10 (44-49) | D43: 40 | E43: =VLOOKUP(D43,'Pay Source data'!$A$1:$B$58,2,FALSE) -> 40430 | F43: =E43*F$2 -> 11320.4 | G43: =E43+F43 -> 51750.4 | H43: =((52-8)*5)-10 -> 210 | I43: =ROUND(G43/H43/I$2,2) -> 32.86 | K43: =ROUND(J43*I43,0) -> 0 | Q43: =ROUND($I43*'Policy decisions'!C$24*(L43),0) -> 0 | R43: =ROUND($I43*'Policy decisions'!D$24*(M43),0) -> 0 | S43: =ROUND($I43*'Policy decisions'!E$24*(N43),0) -> 0 | T43: =ROUND($I43*'Policy decisions'!F$24*(O43),0) -> 0 | U43: =ROUND($I43*'Policy decisions'!G$24*(P43),0) -> 0
B44: Reader | C44: Grade 10 - 10+ (44-58) | D44: 45 | E44: =VLOOKUP(D44,'Pay Source data'!$A$1:$B$58,2,FALSE) -> 46846 | F44: =E44*F$2 -> 13116.88 | G44: =E44+F44 -> 59962.88 | H44: =((52-8)*5)-20 -> 200 | I44: =ROUND(G44/H44/I$2,2) -> 39.98 | K44: =ROUND(J44*I44,0) -> 0 | M44: 50 | N44: 50 | O44: 50 | P44: 25 | Q44: =ROUND($I44*'Policy decisions'!C$24*(L44),0) -> 0 | R44: =ROUND($I44*'Policy decisions'!D$24*(M44),0) -> 2080 | S44: =ROUND($I44*'Policy decisions'!E$24*(N44),0) -> 2121 | T44: =ROUND($I44*'Policy decisions'!F$24*(O44),0) -> 2164 | U44: =ROUND($I44*'Policy decisions'!G$24*(P44),0) -> 1103
B45: Professor | C45: Professorial (1-19) | D45: 18 | E45: =VLOOKUP(D45,'Pay Source data'!$A$63:$B$81,2,FALSE) -> 93000 | F45: =E45*F$2 -> 26040 | G45: =E45+F45 -> 119040 | H45: =((52-8)*5)-25 -> 195 | I45: =ROUND(G45/H45/I$2,2) -> 81.39 | K45: =ROUND(J45*I45,0) -> 0 | Q45: =ROUND($I45*'Policy decisions'!C$24*(L45),0) -> 0 | R45: =ROUND($I45*'Policy decisions'!D$24*(M45),0) -> 0 | S45: =ROUND($I45*'Policy decisions'!E$24*(N45),0) -> 0 | T45: =ROUND($I45*'Policy decisions'!F$24*(O45),0) -> 0 | U45: =ROUND($I45*'Policy decisions'!G$24*(P45),0) -> 0
...

Sheet Pay Source data
A1: 1 | B1: 13353
A2: 2 | B2: 13702
A3: 3 | B3: 14061
A4: 4 | B4: 14376
A5: 5 | B5: 14758
A6: 6 | B6: 15151
A7: 7 | B7: 15503
A8: 8 | B8: 15932
A9: 9 | B9: 16376
A10: 10 | B10: 16846
A11: 11 | B11: 17329
A12: 12 | B12: 17827
... A58: 58 | B58: 68724.204
A61: Professorial Grades
A63: 1 | B63: 52557 | C63: Band 1
A64: 2 | B64: 54131 | C64: Band 1
A65: 3 | B65: 55748 | C65: Band 1
A66: 4 | B66: 57416 | C66: Band 1
A67: 5 | B67: 59134 | C67: Band 1
A68: 6 | B68: 60906 | C68: Band 1
A69: 7 | B69: 62728 | C69: Band 1
A70: 8 | B70: 64604 | C70: Band 1
A71: 9 | B71: 66537 | C71: Band 1
A72: 10 | B72: 68528 | C72: Band 1
A73: 11 | B73: 70579 | C73: Band 1
A74: 12 | B74: 72694 | C74: Band 1
... A78: 16 | B78: 81799 | C78: Band 1
A79: 17 | B79: 82024 | C79: Band 2 | D79: Not fixed bands just a range
A80: 18 | B80: 93000 | C80: Band 2 | D80: Not fixed bands just a range
A81: 19 | B81: 105595 | C81: Band 2 | D81: Not fixed bands just a range
A86: STANDARD RATES AS ADVERTISED BY HR
A87: SESSIONAL LECTURERS:
D88: Basic | F88: Holiday | I88: Total | K88: On Costs
D89: Hourly | F89: Pay | I89: Hourly | K89: Ni er
D90: Rate | I90: Rate
D91: £ | F91: £ | I91: £
B92: Lecturer 1 | D92: 31.38 | E92: plus | F92: 3.38 | G92: holiday pay | H92: Total | I92: 34.76
B93: Lecturer 2 | D93: 40.15 | E93: plus | F93: 4.32 | G93: holiday pay | H93: Total | I93: 44.47
B94: Lecturer 3 | D94: 45.16 | E94: plus | F94: 4.86 | G94: holiday pay | H94: Total | I94: 50.02
