Workbook
Name TitleRegion1.a1.g37.1: Report!$A$2
Name TitleRegion1.a1.j537.4: Lunch!$J$537
Name TitleRegion1.a2.bf555.2: Details!$BF$555
Name TitleRegion1.a5.n506.3: Fund4!$N$506
Name TitleRegion2.p4.ad540.3: Fund4!$AD$540

Sheet Report
A1: 9999 | B1: = district number | C1: Enter the number of the target district or charter school in cell A1. For state | G1: n/a
A2: n/a | B2: n/a | C2: totals, enter district = 9999. | E2: n/a | F2: n/a | G2: n/a
A3: n/a | B3: n/a | C3: The "Details" tab includes all these revenues in one-line-per-district format. | G3: n/a
A4: GENERAL EDUCATION REVENUE, FY 2015 | C4: n/a | D4: n/a | E4: n/a | F4: n/a | G4: n/a
A5: =VLOOKUP(A1,Details!A16:C555,3)&" #"&+Report!A1 -> STATE TOTAL #9999 | C5: n/a | D5: n/a | E5: n/a | F5: n/a | G5: Percent
A6: n/a | B6: n/a | C6: n/a | D6: Old Law | E6: New Law | F6: Change | G6: Change
A7: 1 | B7: Average Daily Membership (ADM) | C7: n/a | D7: =SUMIF(Details!$A$16:$A$555,Report!$A$1,Details!E$16:E$555) -> 840941.27 | E7: =D7 -> 840941.27 | F7: =E7-D7 -> 0 | G7: =IF(D7=0,0,F7/D7) -> 0
B8: General revenue | C8: n/a
A9: =A7+1 -> 2 | B9: Basic | C9: n/a | D9: =SUMIF(Details!$A$16:$A$555,Report!$A$1,Details!Y$16:Y$555) -> 5316551850 | E9: =SUMIF(Details!$A$16:$A$555,Report!$A$1,Details!AJ$16:AJ$555) -> 5339444347 | F9: =E9-D9 -> 22892497 | G9: =IF(D9=0,0,F9/D9) -> 0.0043058918
A10: =A9+1 -> 3 | B10: Declining pupil | C10: n/a | D10: =SUMIF(Details!$A$16:$A$555,Report!$A$1,Details!Z$16:Z$555) -> 4813900 | E10: =SUMIF(Details!$A$16:$A$555,Report!$A$1,Details!AK$16:AK$555) -> 4834632 | F10: =E10-D10 -> 20732 | G10: =IF(D10=0,0,F10/D10) -> 0.0043066952
A11: =A10+1 -> 4 | B11: Transportation sparsity | C11: n/a | D11: =SUMIF(Details!$A$16:$A$555,Report!$A$1,Details!AA$16:AA$555) -> 62730918 | E11: =SUMIF(Details!$A$16:$A$555,Report!$A$1,Details!AL$16:AL$555) -> 63001021 | F11: =E11-D11 -> 270103 | G11: =IF(D11=0,0,F11/D11) -> 0.0043057396
A12: =A11+1 -> 5 | B12: Compensatory | C12: n/a | D12: =SUMIF(Details!$A$16:$A$555,Report!$A$1,Details!AB$16:AB$555) -> 520691593 | E12: =SUMIF(Details!$A$16:$A$555,Report!$A$1,Details!AM$16:AM$555) -> 5.2331235e+08 | F12: =E12-D12 -> 2620754.9 | G12: =IF(D12=0,0,F12/D12) -> 0.0050332192
A13: =A12+1 -> 6 | B13: Sparsity | C13: n/a | D13: =SUMIF(Details!$A$16:$A$555,Report!$A$1,Details!AC$16:AC$555) -> 24748981 | E13: =SUMIF(Details!$A$16:$A$555,Report!$A$1,Details!AN$16:AN$555) -> 24844845 | F13: =E13-D13 -> 95864 | G13: =IF(D13=0,0,F13/D13) -> 0.0038734524
A14: =A13+1 -> 7 | B14: Small Schools | C14: n/a | D14: =SUMIF(Details!$A$16:$A$555,Report!$A$1,Details!AD$16:AD$555) -> 15885225 | E14: =SUMIF(Details!$A$16:$A$555,Report!$A$1,Details!AO$16:AO$555) -> 16053909 | F14: =E14-D14 -> 168684.31 | G14: =IF(D14=0,0,F14/D14) -> 0.010618944
A15: =A14+1 -> 8 | B15: Q Comp/teacher dev and improv | C15: n/a | D15: =SUMIF(Details!$A$16:$A$555,Report!$A$1,Details!AE$16:AE$555) -> 109925771 | E15: =SUMIF(Details!$A$16:$A$555,Report!$A$1,Details!AP$16:AP$555) -> 1.1992577e+08 | F15: =E15-D15 -> 10000000 | G15: =IF(D15=0,0,F15/D15) -> 0.090970479
A16: =A15+1 -> 9 | B16: Limited English | C16: n/a | D16: =SUMIF(Details!$A$16:$A$555,Report!$A$1,Details!AF$16:AF$555) -> 43885142 | E16: =SUMIF(Details!$A$16:$A$555,Report!$A$1,Details!AQ$16:AQ$555) -> 49329631 | F16: =E16-D16 -> 5444489 | G16: =IF(D16=0,0,F16/D16) -> 0.12406224
A17: =A16+1 -> 10 | B17: Equity | C17: n/a | D17: =SUMIF(Details!$A$16:$A$555,Report!$A$1,Details!AG$16:AG$555) -> 1.0636934e+08 | E17: =SUMIF(Details!$A$16:$A$555,Report!$A$1,Details!AR$16:AR$555) -> 1.0640829e+08 | F17: =E17-D17 -> 38950 | G17: =IF(D17=0,0,F17/D17) -> 0.00036617694
A18: =A17+1 -> 11 | B18: Other general education | C18: n/a | D18: =SUMIF(Details!$A$16:$A$555,Report!$A$1,Details!AH$16:AH$555) -> 1.3547691e+09 | E18: =SUMIF(Details!$A$16:$A$555,Report!$A$1,Details!AS$16:AS$555) -> 1.3547696e+09 | F18: =E18-D18 -> 539 | G18: =IF(D18=0,0,F18/D18) -> 3.9785378e-07
A19: =A18+1 -> 12 | B19: Total general education + Q Comp | C19: n/a | D19: =SUMIF(Details!$A$16:$A$555,Report!$A$1,Details!AI$16:AI$555) -> 7.5603718e+09 | E19: =SUMIF(Details!$A$16:$A$555,Report!$A$1,Details!AT$16:AT$555) -> 7.6019244e+09 | F19: =E19-D19 -> 41552613 | G19: =IF(D19=0,0,F19/D19) -> 0.0054961071
A20: n/a | B20: Community education | C20: n/a | D20: n/a | E20: n/a | F20: n/a | G20: n/a
A21: =A19+1 -> 13 | B21: ECFE | C21: n/a | D21: =SUMIF(Details!$A$16:$A$555,Report!$A$1,Details!AU$16:AU$555) -> 44058720 | E21: =SUMIF(Details!$A$16:$A$555,Report!$A$1,Details!AY$16:AY$555) -> 49240393 | F21: =E21-D21 -> 5181672.6 | G21: =IF(D21=0,0,F21/D21) -> 0.11760833
A22: =A21+1 -> 14 | B22: School readiness | C22: n/a | D22: =SUMIF(Details!$A$16:$A$555,Report!$A$1,Details!AV$16:AV$555) -> 10092925 | E22: =SUMIF(Details!$A$16:$A$555,Report!$A$1,Details!AZ$16:AZ$555) -> 12092513 | F22: =E22-D22 -> 1999588.8 | G22: =IF(D22=0,0,F22/D22) -> 0.19811788
A23: =A22+1 -> 15 | B23: School lunch | C23: n/a | D23: =SUMIF(Details!$A$16:$A$555,Report!$A$1,Details!AW$16:AW$555) -> 12055556 | E23: =SUMIF(Details!$A$16:$A$555,Report!$A$1,Details!BA$16:BA$555) -> 15404752 | F23: =E23-D23 -> 3349196 | G23: =IF(D23=0,0,F23/D23) -> 0.27781347
A24: =A23+1 -> 16 | B24: Fund 4 total | C24: =+"= ("&+A21&")+("&+A22&")+("&+A23&") =" -> = (13)+(14)+(15) = | D24: =D21+D22+D23 -> 66207201 | E24: =E21+E22+E23 -> 76737658 | F24: =F21+F22+F23 -> 10530457 | G24: =IF(D24=0,0,F24/D24) -> 0.15905305
A25: =A24+1 -> 17 | B25: General + community education | C25: =+"= ("&+A19&")+("&+A24&") =" -> = (12)+(16) = | D25: =D19+D24 -> 7.626579e+09 | E25: =E19+E24 -> 7.6786621e+09 | F25: =F19+F24 -> 52083071 | G25: =IF(D25=0,0,F25/D25) -> 0.0068291524
A26: n/a | B26: General revenue Per ADM | C26: n/a | D26: n/a | E26: n/a | F26: n/a | G26: n/a
A27: =A25+1 -> 18 | B27: Basic | C27: =+"= ("&+A9&")/("&+A$7&") =" -> = (2)/(1) = | D27: =D9/D$7 -> 6322.1441 | E27: =E9/E$7 -> 6349.3665 | F27: =E27-D27 -> 27.222468 | G27: =IF(D27=0,0,F27/D27) -> 0.0043058918
A28: =A27+1 -> 19 | B28: Declining pupil | C28: =+"= ("&+A10&")/("&+A$7&") =" -> = (3)/(1) = | D28: =D10/D$7 -> 5.7244188 | E28: =E10/E$7 -> 5.7490721 | F28: =E28-D28 -> 0.024653327 | G28: =IF(D28=0,0,F28/D28) -> 0.0043066952
A29: =A28+1 -> 20 | B29: Transportation sparsity | C29: =+"= ("&+A11&")/("&+A$7&") =" -> = (4)/(1) = | D29: =D11/D$7 -> 74.596075 | E29: =E11/E$7 -> 74.917266 | F29: =E29-D29 -> 0.32119128 | G29: =IF(D29=0,0,F29/D29) -> 0.0043057396
A30: =A29+1 -> 21 | B30: Compensatory | C30: =+"= ("&+A12&")/("&+A$7&") =" -> = (5)/(1) = | D30: =D12/D$7 -> 619.17712 | E30: =E12/E$7 -> 622.29357 | F30: =E30-D30 -> 3.1164542 | G30: =IF(D30=0,0,F30/D30) -> 0.0050332192
A31: =A30+1 -> 22 | B31: Sparsity | C31: =+"= ("&+A13&")/("&+A$7&") =" -> = (6)/(1) = | D31: =D13/D$7 -> 29.430094 | E31: =E13/E$7 -> 29.54409 | F31: =E31-D31 -> 0.11399607 | G31: =IF(D31=0,0,F31/D31) -> 0.0038734524
A32: =A31+1 -> 23 | B32: Small Schools | C32: =+"= ("&+A14&")/("&+A$7&") =" -> = (7)/(1) = | D32: =D14/D$7 -> 18.889815 | E32: =E14/E$7 -> 19.090405 | F32: =E32-D32 -> 0.20058988 | G32: =IF(D32=0,0,F32/D32) -> 0.010618944
A33: =A32+1 -> 24 | B33: Q Comp/teacher dev and improv | C33: =+"= ("&+A15&")/("&+A$7&") =" -> = (8)/(1) = | D33: =D15/D$7 -> 130.71754 | E33: =E15/E$7 -> 142.60897 | F33: =E33-D33 -> 11.891437 | G33: =IF(D33=0,0,F33/D33) -> 0.090970479
A34: =A33+1 -> 25 | B34: Limited English | C34: =+"= ("&+A16&")/("&+A$7&") =" -> = (9)/(1) = | D34: =D16/D$7 -> 52.185739 | E34: =E16/E$7 -> 58.660019 | F34: =E34-D34 -> 6.4742797 | G34: =IF(D34=0,0,F34/D34) -> 0.12406224
A35: =A34+1 -> 26 | B35: Equity | C35: =+"= ("&+A17&")/("&+A$7&") =" -> = (10)/(1) = | D35: =D17/D$7 -> 126.48843 | E35: =E17/E$7 -> 126.53475 | F35: =E35-D35 -> 0.046317146 | G35: =IF(D35=0,0,F35/D35) -> 0.00036617694
A36: =A35+1 -> 27 | B36: Other general revenue | C36: =+"= ("&+A18&")/("&+A$7&") =" -> = (11)/(1) = | D36: =D18/D$7 -> 1611.0151 | E36: =E18/E$7 -> 1611.0158 | F36: =E36-D36 -> 0.00064094845 | G36: =IF(D36=0,0,F36/D36) -> 3.9785378e-07
A37: =A36+1 -> 28 | B37: Total general revenue | C37: =+"= ("&+A19&")/("&+A$7&") =" -> = (12)/(1) = | D37: =D19/D$7 -> 8990.3684 | E37: =E19/E$7 -> 9039.7804 | F37: =E37-D37 -> 49.412028 | G37: =IF(D37=0,0,F37/D37) -> 0.0054961071
A38: end of worksheet

Sheet Details
A1: FY 2015 General Revenue Changes From 2014 Legislation | H1: rest of line left blank
A2: n/a | B2: n/a | C2: n/a | D2: n/a | E2: A | F2: B | G2: C | H2: D | I2: E | J2: F | K2: G | L2: H | M2: I | N2: rest of line left blank
A3: n/a | B3: n/a | C3: n/a | D3: n/a | E3: n/a | F3: Change | G3: Change | H3: Change | I3: Change | J3: Change | K3: Change | L3: Change | M3: Change | N3: Change | O3: Change | P3: Change | Q3: Change | R3: Change | S3: Change | T3: Change | U3: Change | V3: Change | W3: Change | X3: Change | Y3: Old Law | Z3: Old Law | AA3: Old Law | AB3: Old Law | AC3: Old Law | AD3: Old Law | AE3: Old Law | AF3: Old Law | AG3: Old Law | AH3: Old Law | AI3: Old Law | AJ3: New Law | AK3: New Law | AL3: New Law | AM3: New Law | AN3: New Law | AO3: New Law | AP3: New Law | AQ3: New Law | AR3: New Law | AS3: New Law | AT3: New Law | AU3: Old Law | AV3: Old Law | AW3: Old Law | AX3: Old Law | AY3: New Law | AZ3: New Law | BA3: New Law | BB3: New Law | BC3: Change | BD3: Change | BE3: Change | BF3: Change
A4: n/a | B4: n/a | C4: n/a | D4: n/a | E4: n/a | F4: Based on | G4: Teacher | H4: n/a | I4: n/a | J4: Total | K4: n/a | L4: General Plus | M4: Gened | N4: n/a | O4: Declining | P4: n/a | Q4: n/a | R4: n/a | S4: n/a | T4: n/a | U4: n/a | V4: n/a | W4: Other | X4: n/a | Y4: n/a | Z4: Declining | AA4: n/a | AB4: n/a | AC4: n/a | AD4: n/a | AE4: n/a | AF4: n/a | AG4: n/a | AH4: Other | AI4: n/a | AJ4: n/a | AK4: Declining | AL4: n/a | AM4: n/a | AN4: n/a | AO4: n/a | AP4: n/a | AQ4: n/a | AR4: n/a | AS4: Other | AT4: n/a | AU4: n/a | AV4: n/a | AW4: n/a | AX4: n/a | AY4: n/a | AZ4: n/a | BA4: n/a | BB4: n/a | BC4: n/a | BD4: n/a | BE4: n/a | BF4: n/a
A5: n/a | B5: n/a | C5: n/a | D5: n/a | E5: n/a | F5: Formula | G5: Development/ | H5: English | I5: Other | J5: General | K5: Community | L5: Community | M5: Per ADM | O5: Pupil | P5: Transport | Q5: Compen | S5: Small | T5: Q Comp Plus | U5: English | W5: General | X5: Total | Z5: Pupil | AA5: Transport | AB5: Compen | AD5: Small | AE5: Q Comp Plus | AF5: English | AH5: General | AI5: Total | AK5: Pupil | AL5: Transport | AM5: Compen | AO5: Small | AP5: Q Comp Plus | AQ5: English | AS5: General | AT5: Total | AV5: School | AW5: School | AX5: Fund 4 | AZ5: School | BA5: School | BB5: Fund 4 | BD5: School | BE5: School | BF5: Fund 4
A6: n/a | B6: n/a | C6: n/a | D6: REGION | E6: ADM | F6: Increase | G6: Improvement | H6: Learner | I6: General | J6: =+"= "&+F2&"+"&+G2&"+"&+H2&"+"&+I2 -> = B+C+D+E | K6: Education | L6: Education | M6: =+"= "&+J2&"/"&+E2 -> = F/A | N6: Basic | O6: Revenue | P6: Sparsity | Q6: -satory | R6: Sparsity | S6: Schools | T6: Tchr Develop | U6: Learner | V6: Equity | W6: Revenue | X6: Gened | Y6: Basic | Z6: Revenue | AA6: Sparsity | AB6: -satory | AC6: Sparsity | AD6: Schools | AE6: Tchr Develop | AF6: Learner | AG6: Equity | AH6: Revenue | AI6: Gened | AJ6: Basic | AK6: Revenue | AL6: Sparsity | AM6: -satory | AN6: Sparsity | AO6: Schools | AP6: Tchr Develop | AQ6: Learner | AR6: Equity | AS6: Revenue | AT6: Gened | AU6: ECFE | AV6: Readiness | AW6: Lunch | AX6: Total | AY6: ECFE | AZ6: Readiness | BA6: Lunch | BB6: Total | BC6: ECFE | BD6: Readiness | BE6: Lunch | BF6: Total
A7: n/a | B7: n/a | C7: STATE TOTAL | D7: n/a | E7: =E555 -> 840941.27 | F7: =F555 -> 26068635 | G7: =G555 -> 10000000 | H7: =H555 -> 5444489 | I7: =I555 -> 39489 | J7: =J555 -> 41552613 | K7: =K555 -> 10530457 | L7: =L555 -> 52083071 | M7: =IF(E7=0,0,J7/E7) -> 49.412028 | N7: =N555 -> 22892497 | O7: =O555 -> 20732 | P7: =P555 -> 270103 | Q7: =Q555 -> 2620754.9 | R7: =R555 -> 95864 | S7: =S555 -> 168684.31 | T7: =T555 -> 10000000 | U7: =U555 -> 5444489 | ... AT7: =AT555 -> 7.6019244e+09 | AU7: =SUM(AU16:AU546) -> 44058720 | AV7: =SUM(AV16:AV546) -> 10092925 | AW7: =SUM(AW16:AW546) -> 12055556 | AX7: =SUM(AX16:AX546) -> 66207201 | AY7: =SUM(AY16:AY546) -> 49240393 | AZ7: =SUM(AZ16:AZ546) -> 12092513 | BA7: =SUM(BA16:BA546) -> 15404752 | BB7: =SUM(BB16:BB546) -> 76737658 | ... BF7: =SUM(BF16:BF546) -> 10530457
A8: 9001 | B8: 1 | C8: MPLS & ST PAUL | E8: =E547 -> 73700 | F8: =F547 -> 2634788.5 | G8: =G547 -> 993386.72 | H8: =H547 -> 1284008 | I8: =I547 -> 320 | J8: =J547 -> 4912503.2 | K8: =K547 -> 1278779.7 | L8: =L547 -> 6191283 | ... BF8: =BF547 -> 1278779.7
A9: 9002 | B9: 2 | C9: OTHER METRO, INNER | E9: =E548 -> 87641 | F9: =F548 -> 2664331.5 | G9: =G548 -> 448605.9 | H9: =H548 -> 837897 | I9: =I548 -> 937 | J9: =J548 -> 3951771.4 | K9: =K548 -> 1114238.5 | L9: =L548 -> 5066009.9 | ... BF9: =BF548 -> 1114238.5
A10: 9003 | B10: 3 | C10: OTHER METRO, OUTER | E10: =E549 -> 264063 | F10: =F549 -> 7616955.8 | G10: =G549 -> 1332753.2 | H10: =H549 -> 1495046 | I10: =I549 -> 2983 | J10: =J549 -> 10447738 | K10: =K549 -> 2954969.5 | L10: =L549 -> 13402707 | ... BF10: =BF549 -> 2954969.5
A11: 9004 | B11: 4 | C11: NONMET>=2K | E11: =E550 -> 183950 | F11: =F550 -> 5629737.1 | G11: =G550 -> 3373983.3 | H11: =H550 -> 642220 | I11: =I550 -> 5692 | J11: =J550 -> 9651632.4 | K11: =K550 -> 2433388.7 | L11: =L550 -> 12085021 | ... BF11: =BF550 -> 2433388.7
A12: 9005 | B12: 5 | C12: NONMET 1K-2K | E12: =E551 -> 94919 | F12: =F551 -> 3209164.2 | G12: =G551 -> 1838428 | H12: =H551 -> 230184 | I12: =I551 -> 1413 | J12: =J551 -> 5279189.2 | K12: =K551 -> 1222011.8 | L12: =L551 -> 6501201 | ... BF12: =BF551 -> 1222011.8
A13: 9006 | B13: 6 | C13: NONMET < 1K | E13: =E552 -> 85764 | F13: =F552 -> 2766300 | G13: =G552 -> 2014282.6 | H13: =H552 -> 163998 | I13: =I552 -> 1947 | J13: =J552 -> 4946527.6 | K13: =K552 -> 1278202.4 | L13: =L552 -> 6224730 | ... BF13: =BF552 -> 1278202.4
A14: 9008 | B14: 7 | C14: CHARTER TOTAL | E14: =E554 -> 48273.74 | F14: =F554 -> 1607985.2 | G14: =G554 -> 407527.86 | H14: =H554 -> 792215 | I14: =I554 -> 25928 | J14: =J554 -> 2833656 | K14: =K554 -> 117252.4 | L14: =L554 -> 2950908.4 | ... BF14: =BF554 -> 117252.4
A15: line left blank intentionally
A16: 1 | B16: 1 | C16: AITKIN | D16: 5 | E16: 1214 | F16: =SUM(N16:S16) -> 39129.5 | G16: =T16 -> 28028.62 | H16: =U16 -> 0 | I16: =J16-F16-G16-H16 -> -8.1490725e-10 | J16: =X16 -> 67158.12 | K16: =BF16 -> 16975.521 | L16: =J16+K16 -> 84133.641 | M16: =IF(E16=0,0,J16/E16) -> 55.319703 | N16: =AJ16-Y16 -> 33145 | O16: =AK16-Z16 -> 118 | P16: =AL16-AA16 -> 1867 | Q16: =AM16-AB16 -> 3554.5 | R16: =AN16-AC16 -> 445 | S16: =AO16-AD16 -> 0 | T16: =AP16-AE16 -> 28028.62 | U16: =AQ16-AF16 -> 0 | ... X16: =AT16-AI16 -> 67158.12 | Y16: 7697595 | Z16: 27311 | AA16: 433524 | AB16: 706208 | AC16: 93915 | AD16: 0 | AE16: 0 | AF16: 0 | AG16: 190915 | AH16: =AI16-SUM(Y16:AG16) -> 846735.49 | AI16: 9996203.5 | AJ16: 7730740 | AK16: 27429 | AL16: 435391 | AM16: 709762.5 | AN16: 94360 | AO16: 0 | AP16: 28028.62 | AQ16: 0 | AR16: 190915 | AS16: =AT16-SUM(AJ16:AR16) -> 846735.49 | AT16: 10063362 | AU16: 54960 | AV16: 15440.137 | AW16: 21755.5 | AX16: =AU16+AV16+AW16 -> 92155.637 | AY16: 61423.754 | AZ16: 18499.104 | BA16: 29208.3 | BB16: =AY16+AZ16+BA16 -> 109131.16 | BC16: 6463.754 | BD16: 3058.9671 | BE16: 7452.8 | BF16: 16975.521
A17: 1.2 | B17: 3 | C17: MINNEAPOLIS | D17: 1 | E17: 36143 | F17: =SUM(N17:S17) -> 1264471.5 | G17: =T17 -> 0 | H17: =U17 -> 658222 | I17: =J17-F17-G17-H17 -> 450 | J17: =X17 -> 1923143.5 | K17: =BF17 -> 629038 | L17: =J17+K17 -> 2552181.5 | M17: =IF(E17=0,0,J17/E17) -> 53.209294 | N17: =AJ17-Y17 -> 972535 | O17: =AK17-Z17 -> 0 | P17: =AL17-AA17 -> 0 | Q17: =AM17-AB17 -> 291936.5 | R17: =AN17-AC17 -> 0 | S17: =AO17-AD17 -> 0 | T17: =AP17-AE17 -> 0 | U17: =AQ17-AF17 -> 658222 | ... X17: =AT17-AI17 -> 1923143.5 | Y17: 225861528 | Z17: 0 | AA17: 0 | AB17: 58001944 | AC17: 0 | AD17: 0 | AE17: 9433320 | AF17: 4960800 | AG17: 1945070 | AH17: =AI17-SUM(Y17:AG17) -> 1.0237699e+08 | AI17: 4.0257966e+08 | AJ17: 226834063 | AK17: 0 | AL17: 0 | AM17: 58293880 | AN17: 0 | AO17: 0 | AP17: 9433320 | AQ17: 5619022 | AR17: 1945070 | AS17: =AT17-SUM(AJ17:AR17) -> 1.0237744e+08 | AT17: 4.045028e+08 | AU17: 3288000 | AV17: 754971.72 | AW17: 446710.75 | AX17: =AU17+AV17+AW17 -> 4489682.5 | AY17: 3674696.2 | AZ17: 904545.12 | BA17: 539479.15 | BB17: =AY17+AZ17+BA17 -> 5118720.5 | BC17: 386696.2 | BD17: 149573.4 | BE17: 92768.4 | BF17: 629038
A18: 2 | B18: 1 | C18: HILL CITY | D18: 6 | E18: 286 | F18: =SUM(N18:S18) -> 11318.75 | G18: =T18 -> 9253.28 | H18: =U18 -> 0 | I18: =J18-F18-G18-H18 -> -2.055458e-10 | J18: =X18 -> 20572.03 | K18: =BF18 -> 4419.1907 | L18: =J18+K18 -> 24991.221 | M18: =IF(E18=0,0,J18/E18) -> 71.930175 | N18: =AJ18-Y18 -> 7598 | O18: =AK18-Z18 -> 0 | P18: =AL18-AA18 -> 500 | Q18: =AM18-AB18 -> 1753.75 | R18: =AN18-AC18 -> 1467 | S18: =AO18-AD18 -> 0 | T18: =AP18-AE18 -> 9253.28 | U18: =AQ18-AF18 -> 0 | ... X18: =AT18-AI18 -> 20572.03 | Y18: 1764734 | Z18: 0 | AA18: 116222 | AB18: 348435 | AC18: 309481 | AD18: 112997 | AE18: 0 | AF18: 0 | AG18: 43769 | AH18: =AI18-SUM(Y18:AG18) -> 185553.45 | AI18: 2881191.5 | AJ18: 1772332 | AK18: 0 | AL18: 116722 | AM18: 350188.75 | AN18: 310948 | AO18: 112997 | AP18: 9253.28 | AQ18: 0 | AR18: 43769 | AS18: =AT18-SUM(AJ18:AR18) -> 185553.45 | AT18: 2901763.5 | AU18: 18000 | AV18: 4552.0407 | AW18: 4038.375 | AX18: =AU18+AV18+AW18 -> 26590.416 | AY18: 20116.95 | AZ18: 5453.8814 | BA18: 5438.775 | BB18: =AY18+AZ18+BA18 -> 31009.606 | BC18: 2116.95 | BD18: 901.84066 | BE18: 1400.4 | BF18: 4419.1907
A19: 4 | B19: 1 | C19: MCGREGOR | D19: 6 | E19: 403 | F19: =SUM(N19:S19) -> 17772 | G19: =T19 -> 12865.2 | H19: =U19 -> 0 | I19: =J19-F19-G19-H19 -> -4 | J19: =X19 -> 30633.2 | K19: =BF19 -> 5820.9041 | L19: =J19+K19 -> 36454.104 | M19: =IF(E19=0,0,J19/E19) -> 76.012903 | N19: =AJ19-Y19 -> 10915 | O19: =AK19-Z19 -> 23 | P19: =AL19-AA19 -> 882 | Q19: =AM19-AB19 -> 3378 | R19: =AN19-AC19 -> 2574 | S19: =AO19-AD19 -> 0 | T19: =AP19-AE19 -> 12865.2 | U19: =AQ19-AF19 -> 0 | ... X19: =AT19-AI19 -> 30633.2 | Y19: 2534900 | Z19: 5202 | AA19: 204780 | AB19: 671141 | AC19: 543041 | AD19: 129493 | AE19: 0 | AF19: 196524 | AG19: 111492.45 | AH19: =AI19-SUM(Y19:AG19) -> 116087.25 | AI19: 4512660.7 | AJ19: 2545815 | AK19: 5225 | AL19: 205662 | AM19: 674519 | AN19: 545615 | AO19: 129493 | AP19: 12865.2 | AQ19: 196524 | AR19: 111488.45 | AS19: =AT19-SUM(AJ19:AR19) -> 116087.25 | AT19: 4543293.9 | AU19: 18000 | AV19: 6559.4995 | AW19: 6477 | AX19: =AU19+AV19+AW19 -> 31036.5 | AY19: 20116.95 | AZ19: 7859.0537 | BA19: 8881.4 | BB19: =AY19+AZ19+BA19 -> 36857.404 | BC19: 2116.95 | BD19: 1299.5541 | BE19: 2404.4 | BF19: 5820.9041
A20: 6 | B20: 3 | C20: SOUTH ST. PAUL | D20: 2 | E20: 3424 | F20: =SUM(N20:S20) -> 104508.25 | G20: =T20 -> 0 | H20: =U20 -> 17949 | I20: =J20-F20-G20-H20 -> -32 | J20: =X20 -> 122425.25 | K20: =BF20 -> 47426.495 | L20: =J20+K20 -> 169851.75 | M20: =IF(E20=0,0,J20/E20) -> 35.755038 | N20: =AJ20-Y20 -> 92985 | O20: =AK20-Z20 -> 0 | P20: =AL20-AA20 -> 0 | Q20: =AM20-AB20 -> 11523.25 | R20: =AN20-AC20 -> 0 | S20: =AO20-AD20 -> 0 | T20: =AP20-AE20 -> 0 | U20: =AQ20-AF20 -> 17949 | ... X20: =AT20-AI20 -> 122425.25 | Y20: 21594836 | Z20: 0 | AA20: 0 | AB20: 2289439 | AC20: 0 | AD20: 0 | AE20: 894920 | AF20: 102490 | AG20: 565681.25 | AH20: =AI20-SUM(Y20:AG20) -> 4901901.2 | AI20: 30349267 | AJ20: 21687821 | AK20: 0 | AL20: 0 | AM20: 2300962.2 | AN20: 0 | AO20: 0 | AP20: 894920 | AQ20: 120439 | AR20: 565681.25 | AS20: =AT20-SUM(AJ20:AR20) -> 4901869.2 | AT20: 30471693 | AU20: 172200 | AV20: 46014.727 | AW20: 53246.625 | AX20: =AU20+AV20+AW20 -> 271461.35 | AY20: 192452.15 | AZ20: 55131.067 | BA20: 71304.625 | BB20: =AY20+AZ20+BA20 -> 318887.85 | BC20: 20252.155 | BD20: 9116.3402 | BE20: 18058 | BF20: 47426.495
A21: 11 | B21: 1 | C21: ANOKA-HENNEPIN | D21: 3 | E21: 36852 | F21: =SUM(N21:S21) -> 1079402.2 | G21: =T21 -> 0 | H21: =U21 -> 263828 | I21: =J21-F21-G21-H21 -> -93 | J21: =X21 -> 1343137.2 | K21: =BF21 -> 466375.05 | L21: =J21+K21 -> 1809512.3 | M21: =IF(E21=0,0,J21/E21) -> 36.446794 | N21: =AJ21-Y21 -> 1009545 | O21: =AK21-Z21 -> 0 | P21: =AL21-AA21 -> 0 | Q21: =AM21-AB21 -> 69857.25 | R21: =AN21-AC21 -> 0 | S21: =AO21-AD21 -> 0 | T21: =AP21-AE21 -> 0 | U21: =AQ21-AF21 -> 263828 | ... X21: =AT21-AI21 -> 1343137.2 | Y21: 234456731 | Z21: 0 | AA21: 0 | AB21: 13879238 | AC21: 0 | AD21: 0 | AE21: 9927580 | AF21: 1371434 | AG21: 5015607.5 | AH21: =AI21-SUM(Y21:AG21) -> 76244246 | AI21: 3.4089484e+08 | AJ21: 235466276 | AK21: 0 | AL21: 0 | AM21: 13949095 | AN21: 0 | AO21: 0 | AP21: 9927580 | AQ21: 1635262 | AR21: 5015607.5 | AS21: =AT21-SUM(AJ21:AR21) -> 76244153 | AT21: 3.4223797e+08 | AU21: 1906560 | AV21: 426057.97 | AW21: 529197.25 | AX21: =AU21+AV21+AW21 -> 2861815.2 | AY21: 2130787.3 | AZ21: 510467.67 | BA21: 686935.25 | BB21: =AY21+AZ21+BA21 -> 3328190.3 | BC21: 224227.34 | BD21: 84409.702 | BE21: 157738 | BF21: 466375.05
A22: 12 | B22: 1 | C22: CENTENNIAL | D22: 3 | E22: 6370 | F22: =SUM(N22:S22) -> 178812 | G22: =T22 -> 0 | H22: =U22 -> 6145 | I22: =J22-F22-G22-H22 -> 0 | J22: =X22 -> 184957 | K22: =BF22 -> 58277.118 | L22: =J22+K22 -> 243234.12 | M22: =IF(E22=0,0,J22/E22) -> 29.035636 | N22: =AJ22-Y22 -> 174565 | O22: =AK22-Z22 -> 0 | P22: =AL22-AA22 -> 0 | Q22: =AM22-AB22 -> 4247 | R22: =AN22-AC22 -> 0 | S22: =AO22-AD22 -> 0 | T22: =AP22-AE22 -> 0 | U22: =AQ22-AF22 -> 6145 | ... X22: =AT22-AI22 -> 184957 | Y22: 40540976 | Z22: 0 | AA22: 0 | AB22: 843794 | AC22: 0 | AD22: 0 | AE22: 1698320 | AF22: 66126 | AG22: 1094382.5 | AH22: =AI22-SUM(Y22:AG22) -> 8142722.7 | AI22: 52386321 | AJ22: 40715541 | AK22: 0 | AL22: 0 | AM22: 848041 | AN22: 0 | AO22: 0 | AP22: 1698320 | AQ22: 72271 | AR22: 1094382.5 | AS22: =AT22-SUM(AJ22:AR22) -> 8142722.7 | AT22: 52571278 | AU22: 283200 | AV22: 52613.312 | AW22: 80648.5 | AX22: =AU22+AV22+AW22 -> 416461.81 | AY22: 316506.68 | AZ22: 63036.95 | BA22: 95195.3 | BB22: =AY22+AZ22+BA22 -> 474738.93 | BC22: 33306.68 | BD22: 10423.638 | BE22: 14546.8 | BF22: 58277.118
A23: 13 | B23: 1 | C23: COLUMBIA HEIGHTS | D23: 2 | E23: 3171 | F23: =SUM(N23:S23) -> 117359 | G23: =T23 -> 80205.16 | H23: =U23 -> 65273 | I23: =J23-F23-G23-H23 -> 1.3096724e-10 | J23: =X23 -> 262837.16 | K23: =BF23 -> 53930.153 | L23: =J23+K23 -> 316767.31 | M23: =IF(E23=0,0,J23/E23) -> 82.887783 | N23: =AJ23-Y23 -> 83332 | O23: =AK23-Z23 -> 0 | P23: =AL23-AA23 -> 0 | Q23: =AM23-AB23 -> 34027 | R23: =AN23-AC23 -> 0 | S23: =AO23-AD23 -> 0 | T23: =AP23-AE23 -> 80205.16 | U23: =AQ23-AF23 -> 65273 | ... X23: =AT23-AI23 -> 262837.16 | Y23: 19353140 | Z23: 0 | AA23: 0 | AB23: 6760484 | AC23: 0 | AD23: 0 | AE23: 0 | AF23: 572400 | AG23: 491306.25 | AH23: =AI23-SUM(Y23:AG23) -> 5302122.3 | AI23: 32479453 | AJ23: 19436472 | AK23: 0 | AL23: 0 | AM23: 6794511 | AN23: 0 | AO23: 0 | AP23: 80205.16 | AQ23: 637673 | AR23: 491306.25 | AS23: =AT23-SUM(AJ23:AR23) -> 5302122.3 | AT23: 32742290 | AU23: 233400 | AV23: 68793.225 | AW23: 50437.125 | AX23: =AU23+AV23+AW23 -> 352630.35 | AY23: 260849.79 | AZ23: 82422.393 | BA23: 63288.325 | BB23: =AY23+AZ23+BA23 -> 406560.5 | BC23: 27449.785 | BD23: 13629.168 | BE23: 12851.2 | BF23: 53930.153
A24: 14 | B24: 1 | C24: FRIDLEY | D24: 3 | E24: 2922 | F24: =SUM(N24:S24) -> 96690.5 | G24: =T24 -> 0 | H24: =U24 -> 69391 | I24: =J24-F24-G24-H24 -> 0 | J24: =X24 -> 166081.5 | K24: =BF24 -> 37934.043 | L24: =J24+K24 -> 204015.54 | M24: =IF(E24=0,0,J24/E24) -> 56.838296 | N24: =AJ24-Y24 -> 79755 | O24: =AK24-Z24 -> 0 | P24: =AL24-AA24 -> 0 | Q24: =AM24-AB24 -> 16935.5 | R24: =AN24-AC24 -> 0 | S24: =AO24-AD24 -> 0 | T24: =AP24-AE24 -> 0 | U24: =AQ24-AF24 -> 69391 | ... X24: =AT24-AI24 -> 166081.5 | Y24: 18522301 | Z24: 0 | AA24: 0 | AB24: 3364745 | AC24: 0 | AD24: 0 | AE24: 765440 | AF24: 271159 | AG24: 496551.25 | AH24: =AI24-SUM(Y24:AG24) -> 3988639.4 | AI24: 27408836 | AJ24: 18602056 | AK24: 0 | AL24: 0 | AM24: 3381680.5 | AN24: 0 | AO24: 0 | AP24: 765440 | AQ24: 340550 | AR24: 496551.25 | AS24: =AT24-SUM(AJ24:AR24) -> 3988639.4 | AT24: 27574917 | AU24: 133200 | AV24: 44608.863 | AW24: 41142.875 | AX24: =AU24+AV24+AW24 -> 218951.74 | AY24: 148865.43 | AZ24: 53446.676 | BA24: 54573.675 | BB24: =AY24+AZ24+BA24 -> 256885.78 | BC24: 15665.43 | BD24: 8837.8133 | BE24: 13430.8 | BF24: 37934.043
A25: 15 | B25: 1 | C25: ST. FRANCIS | D25: 3 | E25: 4683 | F25: =SUM(N25:S25) -> 133889.25 | G25: =T25 -> 0 | H25: =U25 -> 13820 | I25: =J25-F25-G25-H25 -> 0 | J25: =X25 -> 147709.25 | K25: =BF25 -> 68341.504 | L25: =J25+K25 -> 216050.75 | M25: =IF(E25=0,0,J25/E25) -> 31.541587 | N25: =AJ25-Y25 -> 125320 | O25: =AK25-Z25 -> 655 | P25: =AL25-AA25 -> 1485 | Q25: =AM25-AB25 -> 6429.25 | R25: =AN25-AC25 -> 0 | S25: =AO25-AD25 -> 0 | T25: =AP25-AE25 -> 0 | U25: =AQ25-AF25 -> 13820 | ... X25: =AT25-AI25 -> 147709.25 | Y25: 29104317 | Z25: 152164 | AA25: 344843 | AB25: 1277363 | AC25: 0 | AD25: 0 | AE25: 1282320 | AF25: 59329 | AG25: 839643.75 | AH25: =AI25-SUM(Y25:AG25) -> 5007351.2 | AI25: 38067331 | AJ25: 29229637 | AK25: 152819 | AL25: 346328 | AM25: 1283792.2 | AN25: 0 | AO25: 0 | AP25: 1282320 | AQ25: 73149 | AR25: 839643.75 | AS25: =AT25-SUM(AJ25:AR25) -> 5007351.2 | AT25: 38215040 | AU25: 256800 | AV25: 53954.161 | AW25: 79837.625 | AX25: =AU25+AV25+AW25 -> 390591.79 | AY25: 287001.82 | AZ25: 64643.446 | BA25: 107288.02 | BB25: =AY25+AZ25+BA25 -> 458933.29 | BC25: 30201.82 | BD25: 10689.284 | BE25: 27450.4 | BF25: 68341.504
A26: 16 | B26: 1 | C26: SPRING LAKE PARK | D26: 3 | E26: 5500 | F26: =SUM(N26:S26) -> 161594.5 | G26: =T26 -> 0 | H26: =U26 -> 79222 | I26: =J26-F26-G26-H26 -> 0 | J26: =X26 -> 240816.5 | K26: =BF26 -> 63351.181 | L26: =J26+K26 -> 304167.68 | M26: =IF(E26=0,0,J26/E26) -> 43.784818 | N26: =AJ26-Y26 -> 148750 | O26: =AK26-Z26 -> 0 | P26: =AL26-AA26 -> 0 | Q26: =AM26-AB26 -> 12844.5 | R26: =AN26-AC26 -> 0 | S26: =AO26-AD26 -> 0 | T26: =AP26-AE26 -> 0 | U26: =AQ26-AF26 -> 79222 | ... X26: =AT26-AI26 -> 240816.5 | Y26: 34545700 | Z26: 0 | AA26: 0 | AB26: 2551945 | AC26: 0 | AD26: 0 | AE26: 1451060 | AF26: 301750 | AG26: 944717.5 | AH26: =AI26-SUM(Y26:AG26) -> 7400518.1 | AI26: 47195691 | AJ26: 34694450 | AK26: 0 | AL26: 0 | AM26: 2564789.5 | AN26: 0 | AO26: 0 | AP26: 1451060 | AQ26: 380972 | AR26: 944717.5 | AS26: =AT26-SUM(AJ26:AR26) -> 7400518.1 | AT26: 47436507 | AU26: 248520 | AV26: 68151.136 | AW26: 73118 | AX26: =AU26+AV26+AW26 -> 389789.14 | AY26: 277748.02 | AZ26: 81653.094 | BA26: 93739.2 | BB26: =AY26+AZ26+BA26 -> 453140.32 | BC26: 29228.023 | BD26: 13501.958 | BE26: 20621.2 | BF26: 63351.181
A27: 22 | B27: 1 | C27: DETROIT LAKES | D27: 4 | E27: 2836 | F27: =SUM(N27:S27) -> 87466 | G27: =T27 -> 72872.6 | H27: =U27 -> 0 | I27: =J27-F27-G27-H27 -> 1.4988473e-09 | J27: =X27 -> 160338.6 | K27: =BF27 -> 37533.085 | L27: =J27+K27 -> 197871.68 | M27: =IF(E27=0,0,J27/E27) -> 56.536883 | N27: =AJ27-Y27 -> 77400 | O27: =AK27-Z27 -> 0 | P27: =AL27-AA27 -> 1783 | Q27: =AM27-AB27 -> 8283 | R27: =AN27-AC27 -> 0 | S27: =AO27-AD27 -> 0 | T27: =AP27-AE27 -> 72872.6 | U27: =AQ27-AF27 -> 0 | ... X27: =AT27-AI27 -> 160338.6 | Y27: 17975376 | Z27: 0 | AA27: 414099 | AB27: 1645666 | AC27: 0 | AD27: 0 | AE27: 0 | AF27: 14395 | AG27: 445824 | AH27: =AI27-SUM(Y27:AG27) -> 3104301.4 | AI27: 23599661 | AJ27: 18052776 | AK27: 0 | AL27: 415882 | AM27: 1653949 | AN27: 0 | AO27: 0 | AP27: 72872.6 | AQ27: 14395 | AR27: 445824 | AS27: =AT27-SUM(AJ27:AR27) -> 3104301.4 | AT27: 23760000 | AU27: 127200 | AV27: 35211.888 | AW27: 43424.5 | AX27: =AU27+AV27+AW27 -> 205836.39 | AY27: 142159.78 | AZ27: 42187.993 | BA27: 59021.7 | BB27: =AY27+AZ27+BA27 -> 243369.47 | BC27: 14959.78 | BD27: 6976.1047 | BE27: 15597.2 | BF27: 37533.085
... A546: 6000 | B546: 60 | C546: SPED OTHER | D546: 0 | E546: 0 | F546: =SUM(N546:S546) -> 35240.5 | G546: =T546 -> 200081.04 | H546: =U546 -> 0 | I546: =J546-F546-G546-H546 -> 0 | J546: =X546 -> 235321.54 | K546: =BF546 -> 0 | L546: =J546+K546 -> 235321.54 | M546: =IF(E546=0,0,J546/E546) -> 0 | N546: =AJ546-Y546 -> 0 | O546: =AK546-Z546 -> 0 | P546: =AL546-AA546 -> 0 | Q546: =AM546-AB546 -> 35240.5 | R546: =AN546-AC546 -> 0 | S546: =AO546-AD546 -> 0 | T546: =AP546-AE546 -> 200081.04 | U546: =AQ546-AF546 -> 0 | ... X546: =AT546-AI546 -> 235321.54 | Y546: 0 | Z546: 0 | AA546: 0 | AB546: 7001583 | AC546: 0 | AD546: 0 | AE546: 0 | AF546: 0 | AG546: 0 | AH546: =AI546-SUM(Y546:AG546) -> 0 | AI546: 7001583 | AJ546: 0 | AK546: 0 | AL546: 0 | AM546: 7036823.5 | AN546: 0 | AO546: 0 | AP546: 200081.04 | AQ546: 0 | AR546: 0 | AS546: =AT546-SUM(AJ546:AR546) -> 0 | AT546: 7236904.5 | AU546: 0 | AV546: 0 | AW546: 0 | AX546: =AU546+AV546+AW546 -> 0 | AY546: 0 | AZ546: 0 | BA546: 0 | BB546: =AY546+AZ546+BA546 -> 0 | BC546: 0 | BD546: 0 | BE546: 0 | BF546: 0
A547: 9001 | B547: 1 | C547: MPLS & ST PAUL | D547: 1 | E547: =SUMIF($D$16:$D$546,$D547,E$16:E$546) -> 73700 | F547: =SUM(N547:S547) -> 2634788.5 | G547: =T547 -> 993386.72 | H547: =U547 -> 1284008 | I547: =J547-F547-G547-H547 -> 320 | J547: =X547 -> 4912503.2 | K547: =BF547 -> 1278779.7 | L547: =J547+K547 -> 6191283 | M547: =IF(E547=0,0,J547/E547) -> 66.655403 | N547: =SUMIF($D$16:$D$546,$D547,N$16:N$546) -> 1990735 | O547: =SUMIF($D$16:$D$546,$D547,O$16:O$546) -> 66 | P547: =SUMIF($D$16:$D$546,$D547,P$16:P$546) -> 0 | Q547: =SUMIF($D$16:$D$546,$D547,Q$16:Q$546) -> 643987.5 | R547: =SUMIF($D$16:$D$546,$D547,R$16:R$546) -> 0 | S547: =SUMIF($D$16:$D$546,$D547,S$16:S$546) -> 0 | T547: =SUMIF($D$16:$D$546,$D547,T$16:T$546) -> 993386.72 | U547: =SUMIF($D$16:$D$546,$D547,U$16:U$546) -> 1284008 | ... AW547: =SUMIF($D$16:$D$546,$D547,AW$16:AW$546) -> 1067559.5 | AX547: =AU547+AV547+AW547 -> 8793295.6 | AY547: =SUMIF($D$16:$D$546,$D547,AY$16:AY$546) -> 6921974.3 | AZ547: =SUMIF($D$16:$D$546,$D547,AZ$16:AZ$546) -> 1835727.5 | BA547: =SUMIF($D$16:$D$546,$D547,BA$16:BA$546) -> 1314373.5 | BB547: =AY547+AZ547+BA547 -> 10072075 | BC547: =SUMIF($D$16:$D$546,$D547,BC$16:BC$546) -> 728414.27 | BD547: =SUMIF($D$16:$D$546,$D547,BD$16:BD$546) -> 303551.47 | BE547: =SUMIF($D$16:$D$546,$D547,BE$16:BE$546) -> 246814 | BF547: =SUMIF($D$16:$D$546,$D547,BF$16:BF$546) -> 1278779.7
A548: 9002 | B548: 2 | C548: OTHER METRO, INNER | D548: 2 | E548: =SUMIF($D$16:$D$546,$D548,E$16:E$546) -> 87641 | F548: =SUM(N548:S548) -> 2664331.5 | G548: =T548 -> 448605.9 | H548: =U548 -> 837897 | I548: =J548-F548-G548-H548 -> 937 | J548: =X548 -> 3951771.4 | K548: =BF548 -> 1114238.5 | L548: =J548+K548 -> 5066009.9 | M548: =IF(E548=0,0,J548/E548) -> 45.090442 | N548: =SUMIF($D$16:$D$546,$D548,N$16:N$546) -> 2385150 | O548: =SUMIF($D$16:$D$546,$D548,O$16:O$546) -> 643 | P548: =SUMIF($D$16:$D$546,$D548,P$16:P$546) -> 28 | Q548: =SUMIF($D$16:$D$546,$D548,Q$16:Q$546) -> 278510.5 | R548: =SUMIF($D$16:$D$546,$D548,R$16:R$546) -> 0 | S548: =SUMIF($D$16:$D$546,$D548,S$16:S$546) -> 0 | T548: =SUMIF($D$16:$D$546,$D548,T$16:T$546) -> 448605.9 | U548: =SUMIF($D$16:$D$546,$D548,U$16:U$546) -> 837897 | ... AW548: =SUMIF($D$16:$D$546,$D548,AW$16:AW$546) -> 1126670.1 | AX548: =AU548+AV548+AW548 -> 7182526.4 | AY548: =SUMIF($D$16:$D$546,$D548,AY$16:AY$546) -> 5493134.4 | AZ548: =SUMIF($D$16:$D$546,$D548,AZ$16:AZ$546) -> 1366784.4 | BA548: =SUMIF($D$16:$D$546,$D548,BA$16:BA$546) -> 1436846.1 | BB548: =AY548+AZ548+BA548 -> 8296764.9 | BC548: =SUMIF($D$16:$D$546,$D548,BC$16:BC$546) -> 578054.37 | BD548: =SUMIF($D$16:$D$546,$D548,BD$16:BD$546) -> 226008.17 | BE548: =SUMIF($D$16:$D$546,$D548,BE$16:BE$546) -> 310176 | BF548: =SUMIF($D$16:$D$546,$D548,BF$16:BF$546) -> 1114238.5
A549: 9003 | B549: 3 | C549: OTHER METRO, OUTER | D549: 3 | E549: =SUMIF($D$16:$D$546,$D549,E$16:E$546) -> 264063 | F549: =SUM(N549:S549) -> 7616955.8 | G549: =T549 -> 1332753.2 | H549: =U549 -> 1495046 | I549: =J549-F549-G549-H549 -> 2983 | J549: =X549 -> 10447738 | K549: =BF549 -> 2954969.5 | L549: =J549+K549 -> 13402707 | M549: =IF(E549=0,0,J549/E549) -> 39.565323 | N549: =SUMIF($D$16:$D$546,$D549,N$16:N$546) -> 7198383 | O549: =SUMIF($D$16:$D$546,$D549,O$16:O$546) -> 3625 | P549: =SUMIF($D$16:$D$546,$D549,P$16:P$546) -> 18034 | Q549: =SUMIF($D$16:$D$546,$D549,Q$16:Q$546) -> 396913.75 | R549: =SUMIF($D$16:$D$546,$D549,R$16:R$546) -> 0 | S549: =SUMIF($D$16:$D$546,$D549,S$16:S$546) -> 0 | T549: =SUMIF($D$16:$D$546,$D549,T$16:T$546) -> 1332753.2 | U549: =SUMIF($D$16:$D$546,$D549,U$16:U$546) -> 1495046 | ... AW549: =SUMIF($D$16:$D$546,$D549,AW$16:AW$546) -> 3444689.1 | AX549: =AU549+AV549+AW549 -> 19845930 | AY549: =SUMIF($D$16:$D$546,$D549,AY$16:AY$546) -> 15251464 | AZ549: =SUMIF($D$16:$D$546,$D549,AZ$16:AZ$546) -> 3300480.2 | BA549: =SUMIF($D$16:$D$546,$D549,BA$16:BA$546) -> 4248954.7 | BB549: =AY549+AZ549+BA549 -> 22800899 | BC549: =SUMIF($D$16:$D$546,$D549,BC$16:BC$546) -> 1604944.5 | BD549: =SUMIF($D$16:$D$546,$D549,BD$16:BD$546) -> 545759.43 | BE549: =SUMIF($D$16:$D$546,$D549,BE$16:BE$546) -> 804265.6 | BF549: =SUMIF($D$16:$D$546,$D549,BF$16:BF$546) -> 2954969.5
A550: 9004 | B550: 4 | C550: NONMET>=2K | D550: 4 | E550: =SUMIF($D$16:$D$546,$D550,E$16:E$546) -> 183950 | F550: =SUM(N550:S550) -> 5629737.1 | G550: =T550 -> 3373983.3 | H550: =U550 -> 642220 | I550: =J550-F550-G550-H550 -> 5692 | J550: =X550 -> 9651632.4 | K550: =BF550 -> 2433388.7 | L550: =J550+K550 -> 12085021 | M550: =IF(E550=0,0,J550/E550) -> 52.468782 | N550: =SUMIF($D$16:$D$546,$D550,N$16:N$546) -> 4999972 | O550: =SUMIF($D$16:$D$546,$D550,O$16:O$546) -> 4656 | P550: =SUMIF($D$16:$D$546,$D550,P$16:P$546) -> 69330 | Q550: =SUMIF($D$16:$D$546,$D550,Q$16:Q$546) -> 482651.5 | R550: =SUMIF($D$16:$D$546,$D550,R$16:R$546) -> 2691 | S550: =SUMIF($D$16:$D$546,$D550,S$16:S$546) -> 70436.6 | T550: =SUMIF($D$16:$D$546,$D550,T$16:T$546) -> 3373983.3 | U550: =SUMIF($D$16:$D$546,$D550,U$16:U$546) -> 642220 | ... AW550: =SUMIF($D$16:$D$546,$D550,AW$16:AW$546) -> 2536009.4 | AX550: =AU550+AV550+AW550 -> 15372210 | AY550: =SUMIF($D$16:$D$546,$D550,AY$16:AY$546) -> 11663003 | AZ550: =SUMIF($D$16:$D$546,$D550,AZ$16:AZ$546) -> 2876107.2 | BA550: =SUMIF($D$16:$D$546,$D550,BA$16:BA$546) -> 3266489 | BB550: =AY550+AZ550+BA550 -> 17805599 | BC550: =SUMIF($D$16:$D$546,$D550,BC$16:BC$546) -> 1227322.9 | BD550: =SUMIF($D$16:$D$546,$D550,BD$16:BD$546) -> 475586.14 | BE550: =SUMIF($D$16:$D$546,$D550,BE$16:BE$546) -> 730479.6 | BF550: =SUMIF($D$16:$D$546,$D550,BF$16:BF$546) -> 2433388.7
A551: 9005 | B551: 5 | C551: NONMET 1K-2K | D551: 5 | E551: =SUMIF($D$16:$D$546,$D551,E$16:E$546) -> 94919 | F551: =SUM(N551:S551) -> 3209164.2 | G551: =T551 -> 1838428 | H551: =U551 -> 230184 | I551: =J551-F551-G551-H551 -> 1413 | J551: =X551 -> 5279189.2 | K551: =BF551 -> 1222011.8 | L551: =J551+K551 -> 6501201 | M551: =IF(E551=0,0,J551/E551) -> 55.617834 | N551: =SUMIF($D$16:$D$546,$D551,N$16:N$546) -> 2568758 | O551: =SUMIF($D$16:$D$546,$D551,O$16:O$546) -> 4039 | P551: =SUMIF($D$16:$D$546,$D551,P$16:P$546) -> 76735 | Q551: =SUMIF($D$16:$D$546,$D551,Q$16:Q$546) -> 231286.5 | R551: =SUMIF($D$16:$D$546,$D551,R$16:R$546) -> 3416 | S551: =SUMIF($D$16:$D$546,$D551,S$16:S$546) -> 324929.71 | T551: =SUMIF($D$16:$D$546,$D551,T$16:T$546) -> 1838428 | U551: =SUMIF($D$16:$D$546,$D551,U$16:U$546) -> 230184 | ... AW551: =SUMIF($D$16:$D$546,$D551,AW$16:AW$546) -> 1398843.9 | AX551: =AU551+AV551+AW551 -> 7107824.7 | AY551: =SUMIF($D$16:$D$546,$D551,AY$16:AY$546) -> 5081943.9 | AZ551: =SUMIF($D$16:$D$546,$D551,AZ$16:AZ$546) -> 1391998.3 | BA551: =SUMIF($D$16:$D$546,$D551,BA$16:BA$546) -> 1855894.3 | BB551: =AY551+AZ551+BA551 -> 8329836.5 | BC551: =SUMIF($D$16:$D$546,$D551,BC$16:BC$546) -> 534783.91 | BD551: =SUMIF($D$16:$D$546,$D551,BD$16:BD$546) -> 230177.48 | BE551: =SUMIF($D$16:$D$546,$D551,BE$16:BE$546) -> 457050.4 | BF551: =SUMIF($D$16:$D$546,$D551,BF$16:BF$546) -> 1222011.8
A552: 9006 | B552: 6 | C552: NONMET < 1K | D552: 6 | E552: =SUMIF($D$16:$D$546,$D552,E$16:E$546) -> 85764 | F552: =SUM(N552:S552) -> 2766300 | G552: =T552 -> 2014282.6 | H552: =U552 -> 163998 | I552: =J552-F552-G552-H552 -> 1947 | J552: =X552 -> 4946527.6 | K552: =BF552 -> 1278202.4 | L552: =J552+K552 -> 6224730 | M552: =IF(E552=0,0,J552/E552) -> 57.676037 | N552: =SUMIF($D$16:$D$546,$D552,N$16:N$546) -> 2317751 | O552: =SUMIF($D$16:$D$546,$D552,O$16:O$546) -> 7353 | P552: =SUMIF($D$16:$D$546,$D552,P$16:P$546) -> 102721 | Q552: =SUMIF($D$16:$D$546,$D552,Q$16:Q$546) -> 254160 | R552: =SUMIF($D$16:$D$546,$D552,R$16:R$546) -> 84315 | S552: =SUMIF($D$16:$D$546,$D552,S$16:S$546) -> 0 | T552: =SUMIF($D$16:$D$546,$D552,T$16:T$546) -> 2014282.6 | U552: =SUMIF($D$16:$D$546,$D552,U$16:U$546) -> 163998 | ... AW552: =SUMIF($D$16:$D$546,$D552,AW$16:AW$546) -> 1403757.2 | AX552: =AU552+AV552+AW552 -> 6827386.8 | AY552: =SUMIF($D$16:$D$546,$D552,AY$16:AY$546) -> 4828872.7 | AZ552: =SUMIF($D$16:$D$546,$D552,AZ$16:AZ$546) -> 1321415.7 | BA552: =SUMIF($D$16:$D$546,$D552,BA$16:BA$546) -> 1955300.8 | BB552: =AY552+AZ552+BA552 -> 8105589.2 | BC552: =SUMIF($D$16:$D$546,$D552,BC$16:BC$546) -> 508152.68 | BD552: =SUMIF($D$16:$D$546,$D552,BD$16:BD$546) -> 218506.11 | BE552: =SUMIF($D$16:$D$546,$D552,BE$16:BE$546) -> 551543.6 | BF552: =SUMIF($D$16:$D$546,$D552,BF$16:BF$546) -> 1278202.4
A553: 9007 | B553: 0 | C553: DISTRICT TOTAL | D553: 0 | E553: =SUM(E16:E349) -> 792667.53 | F553: =SUM(N553:S553) -> 24423952 | G553: =T553 -> 9377079.7 | H553: =U553 -> 4652274 | I553: =J553-F553-G553-H553 -> 9239 | J553: =X553 -> 38462545 | K553: =BF553 -> 10413205 | L553: =J553+K553 -> 48875750 | M553: =IF(E553=0,0,J553/E553) -> 48.522922 | N553: =SUM(N16:N349) -> 21595481 | O553: =SUM(O16:O349) -> 17209 | P553: =SUM(P16:P349) -> 264632 | Q553: =SUM(Q16:Q349) -> 2287509.8 | R553: =SUM(R16:R349) -> 90436 | S553: =SUM(S16:S349) -> 168684.31 | T553: =SUM(T16:T349) -> 9377079.7 | U553: =SUM(U16:U349) -> 4652274 | ... AW553: =SUM(AW16:AW349) -> 11599847 | AX553: =AU553+AV553+AW553 -> 65751492 | AY553: =SUM(AY16:AY349) -> 49240393 | AZ553: =SUM(AZ16:AZ349) -> 12092513 | BA553: =SUM(BA16:BA349) -> 14831791 | BB553: =AY553+AZ553+BA553 -> 76164697 | BC553: =SUM(BC16:BC349) -> 5181672.6 | BD553: =SUM(BD16:BD349) -> 1999588.8 | BE553: =SUM(BE16:BE349) -> 3231943.6 | BF553: =SUM(BF16:BF349) -> 10413205
A554: 9008 | B554: 7 | C554: CHARTER TOTAL | D554: 7 | E554: =SUMIF($D$16:$D$546,$D554,E$16:E$546) -> 48273.74 | F554: =SUM(N554:S554) -> 1607985.2 | G554: =T554 -> 407527.86 | H554: =U554 -> 792215 | I554: =J554-F554-G554-H554 -> 25928 | J554: =X554 -> 2833656 | K554: =BF554 -> 117252.4 | L554: =J554+K554 -> 2950908.4 | M554: =IF(E554=0,0,J554/E554) -> 58.699741 | N554: =SUMIF($D$16:$D$546,$D554,N$16:N$546) -> 1297016 | O554: =SUMIF($D$16:$D$546,$D554,O$16:O$546) -> 3523 | P554: =SUMIF($D$16:$D$546,$D554,P$16:P$546) -> 5471 | Q554: =SUMIF($D$16:$D$546,$D554,Q$16:Q$546) -> 296547.18 | R554: =SUMIF($D$16:$D$546,$D554,R$16:R$546) -> 5428 | S554: =SUMIF($D$16:$D$546,$D554,S$16:S$546) -> 0 | T554: =SUMIF($D$16:$D$546,$D554,T$16:T$546) -> 407527.86 | U554: =SUMIF($D$16:$D$546,$D554,U$16:U$546) -> 792215 | ... AW554: =SUMIF($D$16:$D$546,$D554,AW$16:AW$546) -> 455709.5 | AX554: =AU554+AV554+AW554 -> 455709.5 | AY554: =SUMIF($D$16:$D$546,$D554,AY$16:AY$546) -> 0 | AZ554: =SUMIF($D$16:$D$546,$D554,AZ$16:AZ$546) -> 0 | BA554: =SUMIF($D$16:$D$546,$D554,BA$16:BA$546) -> 572961.9 | BB554: =AY554+AZ554+BA554 -> 572961.9 | BC554: =SUMIF($D$16:$D$546,$D554,BC$16:BC$546) -> 0 | BD554: =SUMIF($D$16:$D$546,$D554,BD$16:BD$546) -> 0 | BE554: =SUMIF($D$16:$D$546,$D554,BE$16:BE$546) -> 117252.4 | BF554: =SUMIF($D$16:$D$546,$D554,BF$16:BF$546) -> 117252.4
A555: 9999 | B555: 0 | C555: STATE TOTAL | D555: 0 | E555: =SUM(E16:E546) -> 840941.27 | F555: =SUM(F16:F546) -> 26068635 | G555: =SUM(G16:G546) -> 10000000 | H555: =SUM(H16:H546) -> 5444489 | I555: =SUM(I16:I546) -> 39489 | J555: =SUM(J16:J546) -> 41552613 | K555: =SUM(K16:K546) -> 10530457 | L555: =SUM(L16:L546) -> 52083071 | ... BF555: =SUM(BF16:BF546) -> 10530457
A556: End of worksheet

Sheet Fund4
A1: HF 3172 Conference Bill Totals | D1: rest of line left blank intentionally
A2: House Research Estimates | D2: rest of line left blank intentionally
A3: May 21, 2014 | D3: rest of line left blank intentionally
A4: n/a | B4: n/a | C4: n/a | D4: n/a | E4: n/a | F4: n/a | G4: n/a | H4: n/a | I4: n/a | J4: n/a | K4: n/a | L4: n/a | M4: n/a | N4: n/a | O4: column left blank intentionally | P4: n/a | Q4: n/a | R4: n/a | S4: Old Law | T4: Old Law | U4: Old Law | V4: Old Law | W4: New Law | X4: New Law | Y4: New Law | Z4: New Law | AA4: Change | AB4: Change | AC4: Change | AD4: Change
A5: n/a | B5: n/a | C5: n/a | D5: School | E5: n/a | F5: n/a | G5: n/a | H5: School | I5: n/a | J5: n/a | K5: n/a | L5: School | M5: n/a | N5: n/a | P5: n/a | Q5: n/a | R5: n/a | S5: n/a | T5: n/a | U5: n/a | V5: n/a | W5: n/a | X5: n/a | Y5: n/a | Z5: n/a | AA5: n/a | AB5: n/a | AC5: n/a | AD5: n/a
A6: Dist. | C6: ECFE | D6: Readiness | E6: Sch Lunch | G6: ECFE | H6: Readiness | I6: Sch Lunch | J6: Increase | K6: ECFE | L6: Readiness | M6: Sch Lunch | N6: Conference | P6: n/a | Q6: n/a | R6: n/a | S6: n/a | T6: School | U6: School | V6: Fund 4 | W6: n/a | X6: School | Y6: School | Z6: Fund 4 | AA6: n/a | AB6: School | AC6: School | AD6: Fund 4
A7: No. | B7: District Name | C7: Base | D7: Base | E7: Base | F7: Base Total | G7: Conf-Base | H7: House - Base | I7: Increase | J7: Total | K7: Conference | L7: House | M7: House | N7: Total | P7: n/a | Q7: n/a | R7: n/a | S7: ECFE | T7: Readiness | U7: Lunch | V7: Total | W7: ECFE | X7: Readiness | Y7: Lunch | Z7: Total | AA7: ECFE | AB7: Readiness | AC7: Lunch | AD7: Total
A8: n/a | B8: Total, All Districts | C8: 44058720 | D8: 10092925 | E8: 96444452 | F8: 1.505961e+08 | G8: 5181672.6 | H8: 1999588.8 | I8: 3349196 | J8: 10530457 | K8: 49240393 | L8: 12092513 | M8: 99793648 | N8: 1.6112655e+08 | P8: n/a | Q8: n/a | R8: n/a | S8: =SUM(S10:S540) -> 44058720 | T8: =SUM(T10:T540) -> 10092925 | U8: =SUM(U10:U540) -> 96444452 | V8: =SUM(V10:V540) -> 1.505961e+08 | W8: =SUM(W10:W540) -> 49240393 | X8: =SUM(X10:X540) -> 12092513 | Y8: =SUM(Y10:Y540) -> 99793648 | Z8: =SUM(Z10:Z540) -> 1.6112655e+08 | ... AD8: =SUM(AD10:AD540) -> 10530457
A9: line left blank intentionally
A10: 1 | B10: Aitkin | C10: 54960 | D10: 15440.137 | E10: 174044 | F10: 244444.14 | G10: 6463.754 | H10: 3058.9671 | I10: 7452.8 | J10: 16975.521 | K10: 61423.754 | L10: 18499.104 | M10: 181496.8 | N10: 261419.66 | P10: 1 | Q10: 1 | R10: AITKIN | S10: 54960 | T10: 15440.137 | U10: 174044 | V10: 244444.14 | W10: 61423.754 | X10: 18499.104 | Y10: 181496.8 | Z10: 261419.66 | AA10: 6463.754 | AB10: 3058.9671 | AC10: 7452.8 | AD10: 16975.521
A11: 1.2 | B11: Minneapolis | C11: 3288000 | D11: 754971.72 | E11: 3573686 | F11: 7616657.7 | G11: 386696.2 | H11: 149573.4 | I11: 92768.4 | J11: 629038 | K11: 3674696.2 | L11: 904545.12 | M11: 3666454.4 | N11: 8245695.7 | P11: 1.2 | Q11: 3 | R11: MINNEAPOLIS | S11: 3288000 | T11: 754971.72 | U11: 3573686 | V11: 7616657.7 | W11: 3674696.2 | X11: 904545.12 | Y11: 3666454.4 | Z11: 8245695.7 | AA11: 386696.2 | AB11: 149573.4 | AC11: 92768.4 | AD11: 629038
A12: 2 | B12: Hill City | C12: 18000 | D12: 4552.0407 | E12: 32307 | F12: 54859.041 | G12: 2116.95 | H12: 901.84066 | I12: 1400.4 | J12: 4419.1907 | K12: 20116.95 | L12: 5453.8814 | M12: 33707.4 | N12: 59278.231 | P12: 2 | Q12: 1 | R12: HILL CITY | S12: 18000 | T12: 4552.0407 | U12: 32307 | V12: 54859.041 | W12: 20116.95 | X12: 5453.8814 | Y12: 33707.4 | Z12: 59278.231 | AA12: 2116.95 | AB12: 901.84066 | AC12: 1400.4 | AD12: 4419.1907
A13: 4 | B13: Mcgregor | C13: 18000 | D13: 6559.4995 | E13: 51816 | F13: 76375.5 | G13: 2116.95 | H13: 1299.5541 | I13: 2404.4 | J13: 5820.9041 | K13: 20116.95 | L13: 7859.0537 | M13: 54220.4 | N13: 82196.404 | P13: 4 | Q13: 1 | R13: MCGREGOR | S13: 18000 | T13: 6559.4995 | U13: 51816 | V13: 76375.5 | W13: 20116.95 | X13: 7859.0537 | Y13: 54220.4 | Z13: 82196.404 | AA13: 2116.95 | AB13: 1299.5541 | AC13: 2404.4 | AD13: 5820.9041
A14: 6 | B14: South St. Paul | C14: 172200 | D14: 46014.727 | E14: 425973 | F14: 644187.73 | G14: 20252.155 | H14: 9116.3402 | I14: 18058 | J14: 47426.495 | K14: 192452.15 | L14: 55131.067 | M14: 444031 | N14: 691614.22 | P14: 6 | Q14: 3 | R14: SOUTH ST. PAUL | S14: 172200 | T14: 46014.727 | U14: 425973 | V14: 644187.73 | W14: 192452.15 | X14: 55131.067 | Y14: 444031 | Z14: 691614.22 | AA14: 20252.155 | AB14: 9116.3402 | AC14: 18058 | AD14: 47426.495
A15: 11 | B15: Anoka-Hennepin | C15: 1906560 | D15: 426057.97 | E15: 4233578 | F15: 6566196 | G15: 224227.34 | H15: 84409.702 | I15: 157738 | J15: 466375.05 | K15: 2130787.3 | L15: 510467.67 | M15: 4391316 | N15: 7032571 | P15: 11 | Q15: 1 | R15: ANOKA-HENNEPIN | S15: 1906560 | T15: 426057.97 | U15: 4233578 | V15: 6566196 | W15: 2130787.3 | X15: 510467.67 | Y15: 4391316 | Z15: 7032571 | AA15: 224227.34 | AB15: 84409.702 | AC15: 157738 | AD15: 466375.05
A16: 12 | B16: Centennial | C16: 283200 | D16: 52613.312 | E16: 645188 | F16: 981001.31 | G16: 33306.68 | H16: 10423.638 | I16: 14546.8 | J16: 58277.118 | K16: 316506.68 | L16: 63036.95 | M16: 659734.8 | N16: 1039278.4 | P16: 12 | Q16: 1 | R16: CENTENNIAL | S16: 283200 | T16: 52613.312 | U16: 645188 | V16: 981001.31 | W16: 316506.68 | X16: 63036.95 | Y16: 659734.8 | Z16: 1039278.4 | AA16: 33306.68 | AB16: 10423.638 | AC16: 14546.8 | AD16: 58277.118
A17: 13 | B17: Columbia Heights | C17: 233400 | D17: 68793.225 | E17: 403497 | F17: 705690.23 | G17: 27449.785 | H17: 13629.168 | I17: 12851.2 | J17: 53930.153 | K17: 260849.79 | L17: 82422.393 | M17: 416348.2 | N17: 759620.38 | P17: 13 | Q17: 1 | R17: COLUMBIA HEIGHTS | S17: 233400 | T17: 68793.225 | U17: 403497 | V17: 705690.23 | W17: 260849.79 | X17: 82422.393 | Y17: 416348.2 | Z17: 759620.38 | AA17: 27449.785 | AB17: 13629.168 | AC17: 12851.2 | AD17: 53930.153
A18: 14 | B18: Fridley | C18: 133200 | D18: 44608.863 | E18: 329143 | F18: 506951.86 | G18: 15665.43 | H18: 8837.8133 | I18: 13430.8 | J18: 37934.043 | K18: 148865.43 | L18: 53446.676 | M18: 342573.8 | N18: 544885.91 | P18: 14 | Q18: 1 | R18: FRIDLEY | S18: 133200 | T18: 44608.863 | U18: 329143 | V18: 506951.86 | W18: 148865.43 | X18: 53446.676 | Y18: 342573.8 | Z18: 544885.91 | AA18: 15665.43 | AB18: 8837.8133 | AC18: 13430.8 | AD18: 37934.043
A19: 15 | B19: St. Francis | C19: 256800 | D19: 53954.161 | E19: 638701 | F19: 949455.16 | G19: 30201.82 | H19: 10689.284 | I19: 27450.4 | J19: 68341.504 | K19: 287001.82 | L19: 64643.446 | M19: 666151.4 | N19: 1017796.7 | P19: 15 | Q19: 1 | R19: ST. FRANCIS | S19: 256800 | T19: 53954.161 | U19: 638701 | V19: 949455.16 | W19: 287001.82 | X19: 64643.446 | Y19: 666151.4 | Z19: 1017796.7 | AA19: 30201.82 | AB19: 10689.284 | AC19: 27450.4 | AD19: 68341.504
A20: 16 | B20: Spring Lake Park | C20: 248520 | D20: 68151.136 | E20: 584944 | F20: 901615.14 | G20: 29228.023 | H20: 13501.958 | I20: 20621.2 | J20: 63351.181 | K20: 277748.02 | L20: 81653.094 | M20: 605565.2 | N20: 964966.32 | P20: 16 | Q20: 1 | R20: SPRING LAKE PARK | S20: 248520 | T20: 68151.136 | U20: 584944 | V20: 901615.14 | W20: 277748.02 | X20: 81653.094 | Y20: 605565.2 | Z20: 964966.32 | AA20: 29228.023 | AB20: 13501.958 | AC20: 20621.2 | AD20: 63351.181
A21: 22 | B21: Detroit Lakes | C21: 127200 | D21: 35211.888 | E21: 347396 | F21: 509807.89 | G21: 14959.78 | H21: 6976.1047 | I21: 15597.2 | J21: 37533.085 | K21: 142159.78 | L21: 42187.993 | M21: 362993.2 | N21: 547340.97 | P21: 22 | Q21: 1 | R21: DETROIT LAKES | S21: 127200 | T21: 35211.888 | U21: 347396 | V21: 509807.89 | W21: 142159.78 | X21: 42187.993 | Y21: 362993.2 | Z21: 547340.97 | AA21: 14959.78 | AB21: 6976.1047 | AC21: 15597.2 | AD21: 37533.085
... A346: 4000 | B346: City Academy | C346: 0 | D346: 0 | E346: 0 | F346: 0 | G346: 0 | H346: 0 | I346: 0 | J346: 0 | K346: 0 | L346: 0 | M346: 0 | N346: 0 | P346: 4003 | Q346: 7 | R346: NEW HEIGHTS SCHOOL, INC. | S346: 0 | T346: 0 | U346: 9678 | V346: 9678 | W346: 0 | X346: 0 | Y346: 10134 | Z346: 10134 | AA346: 0 | AB346: 0 | AC346: 456 | AD346: 456
A347: 4001 | B347: Bluffview Montessori | C347: 0 | D347: 0 | E347: 18547 | F347: 18547 | G347: 0 | H347: 0 | I347: 813.6 | J347: 813.6 | L347: 0 | M347: 19360.6 | N347: 19360.6 | P347: 4004 | Q347: 7 | R347: CEDAR RIVERSIDE COMMUNITY SCHOOL | S347: 0 | T347: 0 | U347: 23419 | V347: 23419 | W347: 0 | X347: 0 | Y347: 23462.6 | Z347: 23462.6 | AA347: 0 | AB347: 0 | AC347: 43.6 | AD347: 43.6
A348: 4003 | B348: New Heights School, Inc. | C348: 0 | D348: 0 | E348: 9678 | F348: 9678 | G348: 0 | H348: 0 | I348: 456 | J348: 456 | L348: 0 | M348: 10134 | N348: 10134 | P348: 4005 | Q348: 7 | R348: METRO DEAF SCH & MN NORTH STAR ACAD | S348: 0 | T348: 0 | U348: 5607 | V348: 5607 | W348: 0 | X348: 0 | Y348: 5890.2 | Z348: 5890.2 | AA348: 0 | AB348: 0 | AC348: 283.2 | AD348: 283.2
A349: 4004 | B349: Cedar Riverside Community | C349: 0 | D349: 0 | E349: 23419 | F349: 23419 | G349: 0 | H349: 0 | I349: 43.6 | J349: 43.6 | L349: 0 | M349: 23462.6 | N349: 23462.6 | P349: 4006 | Q349: 7 | R349: SKILLS FOR TOMORROW CHARTER SCHOOL | S349: 0 | T349: 0 | U349: 0 | V349: 0 | W349: 0 | X349: 0 | Y349: 0 | Z349: 0 | AA349: 0 | AB349: 0 | AC349: 0 | AD349: 0
A350: 4005 | B350: Metro Deaf Sch & North Star | C350: 0 | D350: 0 | E350: 5607 | F350: 5607 | G350: 0 | H350: 0 | I350: 283.2 | J350: 283.2 | L350: 0 | M350: 5890.2 | N350: 5890.2 | P350: 4007 | Q350: 7 | R350: MINNESOTA NEW COUNTRY SCHOOL | S350: 0 | T350: 0 | U350: 0 | V350: 0 | W350: 0 | X350: 0 | Y350: 0 | Z350: 0 | AA350: 0 | AB350: 0 | AC350: 0 | AD350: 0
A351: 4007 | B351: Minnesota New Country | C351: 0 | D351: 0 | E351: 0 | F351: 0 | G351: 0 | H351: 0 | I351: 0 | J351: 0 | L351: 0 | M351: 0 | N351: 0 | P351: 4008 | Q351: 7 | R351: PACT CHARTER SCHOOL | S351: 0 | T351: 0 | U351: 30144 | V351: 30144 | W351: 0 | X351: 0 | Y351: 32054.8 | Z351: 32054.8 | AA351: 0 | AB351: 0 | AC351: 1910.8 | AD351: 1910.8
A352: 4008 | B352: Pact Charter School | C352: 0 | D352: 0 | E352: 30144 | F352: 30144 | G352: 0 | H352: 0 | I352: 1910.8 | J352: 1910.8 | L352: 0 | M352: 32054.8 | N352: 32054.8 | P352: 4011 | Q352: 7 | R352: NEW VISIONS CHARTER SCHOOL | S352: 0 | T352: 0 | U352: 33343 | V352: 33343 | W352: 0 | X352: 0 | Y352: 33533.4 | Z352: 33533.4 | AA352: 0 | AB352: 0 | AC352: 190.4 | AD352: 190.4
A353: 4011 | B353: New Visions | C353: 0 | D353: 0 | E353: 33343 | F353: 33343 | G353: 0 | H353: 0 | I353: 190.4 | J353: 190.4 | L353: 0 | M353: 33533.4 | N353: 33533.4 | P353: 4012 | Q353: 7 | R353: EMILY CHARTER SCHOOL | S353: 0 | T353: 0 | U353: 0 | V353: 0 | W353: 0 | X353: 0 | Y353: 0 | Z353: 0 | AA353: 0 | AB353: 0 | AC353: 0 | AD353: 0
A354: 4015 | B354: Community Of Peace Academy | C354: 0 | D354: 0 | E354: 0 | F354: 0 | G354: 0 | H354: 0 | I354: 0 | J354: 0 | L354: 0 | M354: 0 | N354: 0 | P354: 4015 | Q354: 7 | R354: COMMUNITY OF PEACE ACADEMY | S354: 0 | T354: 0 | U354: 0 | V354: 0 | W354: 0 | X354: 0 | Y354: 0 | Z354: 0 | AA354: 0 | AB354: 0 | AC354: 0 | AD354: 0
A355: 4016 | B355: World Learner | C355: 0 | D355: 0 | E355: 0 | F355: 0 | G355: 0 | H355: 0 | I355: 0 | J355: 0 | L355: 0 | M355: 0 | N355: 0 | P355: 4016 | Q355: 7 | R355: WORLD LEARNER CHARTER SCHOOL | S355: 0 | T355: 0 | U355: 0 | V355: 0 | W355: 0 | X355: 0 | Y355: 0 | Z355: 0 | AA355: 0 | AB355: 0 | AC355: 0 | AD355: 0
A356: 4017 | B356: Minnesota Trans | C356: 0 | D356: 0 | E356: 101110 | F356: 101110 | G356: 0 | H356: 0 | I356: 691.2 | J356: 691.2 | L356: 0 | M356: 101801.2 | N356: 101801.2 | P356: 4017 | Q356: 7 | R356: MINNESOTA TRANSITIONS CHARTER SCH | S356: 0 | T356: 0 | U356: 101110 | V356: 101110 | W356: 0 | X356: 0 | Y356: 101801.2 | Z356: 101801.2 | AA356: 0 | AB356: 0 | AC356: 691.2 | AD356: 691.2
A357: 4018 | B357: Achieve Language Academy | C357: 0 | D357: 0 | E357: 0 | F357: 0 | G357: 0 | H357: 0 | I357: 0 | J357: 0 | L357: 0 | M357: 0 | N357: 0 | P357: 4018 | Q357: 7 | R357: ACHIEVE LANGUAGE ACADEMY | S357: 0 | T357: 0 | U357: 0 | V357: 0 | W357: 0 | X357: 0 | Y357: 0 | Z357: 0 | AA357: 0 | AB357: 0 | AC357: 0 | AD357: 0
A358: 4020 | B358: Duluth Public Schools Academy | C358: 0 | D358: 0 | E358: 119060 | F358: 119060 | G358: 0 | H358: 0 | I358: 4846 | J358: 4846 | L358: 0 | M358: 123906 | N358: 123906 | P358: 4019 | Q358: 7 | R358: ST. PAUL FAMILY LEARN | S358: 0 | T358: 0 | U358: 0 | V358: 0 | W358: 0 | X358: 0 | Y358: 0 | Z358: 0 | AA358: 0 | AB358: 0 | AC358: 0 | AD358: 0
... A506: 6000 | B506: Cooperative & Intermed Districts | C506: 0 | D506: 0 | E506: 0 | F506: 0 | G506: 0 | H506: 0 | I506: 0 | J506: 0 | L506: 0 | M506: 0 | N506: 0 | P506: 4183 | Q506: 7 | R506: LIONSGATE ACADEMY | S506: 0 | T506: 0 | U506: 10261 | V506: 10261 | W506: 0 | X506: 0 | Y506: 10522.2 | Z506: 10522.2 | AA506: 0 | AB506: 0 | AC506: 261.2 | AD506: 261.2
A507: end of first table | P507: 4184 | Q507: 7 | R507: ASPEN ACADEMY | S507: 0 | T507: 0 | U507: 24418 | V507: 24418 | W507: 0 | X507: 0 | Y507: 25206.8 | Z507: 25206.8 | AA507: 0 | AB507: 0 | AC507: 788.8 | AD507: 788.8
P508: 4185 | Q508: 7 | R508: DAVINCI ACADEMY | S508: 0 | T508: 0 | U508: 26446 | V508: 26446 | W508: 0 | X508: 0 | Y508: 27825.6 | Z508: 27825.6 | AA508: 0 | AB508: 0 | AC508: 1379.6 | AD508: 1379.6
P509: 4186 | Q509: 7 | R509: GLOBAL ACADEMY | S509: 0 | T509: 0 | U509: 68725 | V509: 68725 | W509: 0 | X509: 0 | Y509: 71279.4 | Z509: 71279.4 | AA509: 0 | AB509: 0 | AC509: 2554.4 | AD509: 2554.4
P510: 4187 | Q510: 7 | R510: MICHAEL FROME ACADEMY | S510: 0 | T510: 0 | U510: 0 | V510: 0 | W510: 0 | X510: 0 | Y510: 0 | Z510: 0 | AA510: 0 | AB510: 0 | AC510: 0 | AD510: 0
P511: 4188 | Q511: 7 | R511: COLOGNE ACADEMY | S511: 0 | T511: 0 | U511: 32104 | V511: 32104 | W511: 0 | X511: 0 | Y511: 33743.6 | Z511: 33743.6 | AA511: 0 | AB511: 0 | AC511: 1639.6 | AD511: 1639.6
...

Sheet Lunch
C1: n/a | D1: A | E1: B | F1: C | G1: D | H1: G | I1: H | J1: I
C2: n/a | D2: n/a | E2: n/a | F2: n/a | G2: Lunch | H2: Revenue | I2: Revenue | J2: Revenue
C3: n/a | D3: Lunch | E3: Lunch | F3: Lunch | G3: Total | H3: Old Law | I3: Old Law | J3: Change
C4: n/a | D4: Free | E4: Reduced | F4: Full | G4: =+"= "&+D1&"+"&+E1&"+"&+F1 -> = A+B+C | H4: =+"= .125 x "&+G1 -> = .125 x D | I4: =+"= "&+H1&" + 0.40 x "&+E1 -> = G + 0.40 x B | J4: =+"= "&+I1&"-"&+H1 -> = H-G
C5: n/a | D5: =SUM(D7:D537) -> 36343194 | E5: =SUM(E7:E537) -> 8372990 | F5: =SUM(F7:F537) -> 51728268 | G5: =SUM(G7:G537) -> 96444452 | H5: =SUM(H7:H537) -> 12055556 | I5: =SUM(I7:I537) -> 15404752 | J5: =SUM(J7:J537) -> 3349196
A6: line left blank intentionally
A7: 1 | B7: 1 | C7: AITKIN | D7: 66497 | E7: 18632 | F7: 88915 | G7: =SUM(D7:F7) -> 174044 | H7: =G7*0.125 -> 21755.5 | I7: =H7+0.4*E7 -> 29208.3 | J7: =I7-H7 -> 7452.8
A8: 1.2 | B8: 3 | C8: MINNEAPOLIS | D8: 2738005 | E8: 231921 | F8: 603760 | G8: =SUM(D8:F8) -> 3573686 | H8: =G8*0.125 -> 446710.75 | I8: =H8+0.4*E8 -> 539479.15 | J8: =I8-H8 -> 92768.4
A9: 2 | B9: 1 | C9: HILL CITY | D9: 18357 | E9: 3501 | F9: 10449 | G9: =SUM(D9:F9) -> 32307 | H9: =G9*0.125 -> 4038.375 | I9: =H9+0.4*E9 -> 5438.775 | J9: =I9-H9 -> 1400.4
A10: 4 | B10: 1 | C10: MCGREGOR | D10: 32065 | E10: 6011 | F10: 13740 | G10: =SUM(D10:F10) -> 51816 | H10: =G10*0.125 -> 6477 | I10: =H10+0.4*E10 -> 8881.4 | J10: =I10-H10 -> 2404.4
A11: 6 | B11: 3 | C11: SOUTH ST. PAUL | D11: 179811 | E11: 45145 | F11: 201017 | G11: =SUM(D11:F11) -> 425973 | H11: =G11*0.125 -> 53246.625 | I11: =H11+0.4*E11 -> 71304.625 | J11: =I11-H11 -> 18058
A12: 11 | B12: 1 | C12: ANOKA-HENNEPIN | D12: 1304651 | E12: 394345 | F12: 2534582 | G12: =SUM(D12:F12) -> 4233578 | H12: =G12*0.125 -> 529197.25 | I12: =H12+0.4*E12 -> 686935.25 | J12: =I12-H12 -> 157738
A13: 12 | B13: 1 | C13: CENTENNIAL | D13: 116891 | E13: 36367 | F13: 491930 | G13: =SUM(D13:F13) -> 645188 | H13: =G13*0.125 -> 80648.5 | I13: =H13+0.4*E13 -> 95195.3 | J13: =I13-H13 -> 14546.8
A14: 13 | B14: 1 | C14: COLUMBIA HEIGHTS | D14: 307645 | E14: 32128 | F14: 63724 | G14: =SUM(D14:F14) -> 403497 | H14: =G14*0.125 -> 50437.125 | I14: =H14+0.4*E14 -> 63288.325 | J14: =I14-H14 -> 12851.2
A15: 14 | B15: 1 | C15: FRIDLEY | D15: 202498 | E15: 33577 | F15: 93068 | G15: =SUM(D15:F15) -> 329143 | H15: =G15*0.125 -> 41142.875 | I15: =H15+0.4*E15 -> 54573.675 | J15: =I15-H15 -> 13430.8
A16: 15 | B16: 1 | C16: ST. FRANCIS | D16: 149835 | E16: 68626 | F16: 420240 | G16: =SUM(D16:F16) -> 638701 | H16: =G16*0.125 -> 79837.625 | I16: =H16+0.4*E16 -> 107288.02 | J16: =I16-H16 -> 27450.4
A17: 16 | B17: 1 | C17: SPRING LAKE PARK | D17: 214759 | E17: 51553 | F17: 318632 | G17: =SUM(D17:F17) -> 584944 | H17: =G17*0.125 -> 73118 | I17: =H17+0.4*E17 -> 93739.2 | J17: =I17-H17 -> 20621.2
A18: 22 | B18: 1 | C18: DETROIT LAKES | D18: 124548 | E18: 38993 | F18: 183855 | G18: =SUM(D18:F18) -> 347396 | H18: =G18*0.125 -> 43424.5 | I18: =H18+0.4*E18 -> 59021.7 | J18: =I18-H18 -> 15597.2
... A537: 6000 | B537: 60 | C537: SPED OTHER | D537: 0 | E537: 0 | F537: 0 | G537: =SUM(D537:F537) -> 0 | H537: =G537*0.125 -> 0 | I537: =H537+0.4*E537 -> 0 | J537: =I537-H537 -> 0
C538: end of worksheet
