Workbook

Sheet Summary
A1: Community and Technical Colleges, Report of Fundable Operating Expenses, Fiscal Year (FY) 2009
A2: Summary of Expense divided Contact Hours
A3: Contact Hours for fall 2008 and spring and summer 2009
A4: Fund | B4: Total Expense by Discipline | D4: Contact Hours | E4: Expense | F4: Expense per Contact Hour
A5: 1 | B5: Agriculture | D5: =D36 -> 1551137 | E5: =E36+E67+IFERROR($E$105/$D$105*D5,0) -> 13876460 | F5: =IFERROR(E5/D5,"") -> 8.9459924
A6: 2 | B6: Architecture and Precision Production Trades | D6: =D37 -> 3763085 | E6: =E37+E68+IFERROR($E$105/$D$105*D6,0) -> 37235884 | F6: =IFERROR(E6/D6,"") -> 9.8950421
A7: 3 | B7: Biology, Physical Sciences, and Science Technology | D7: =D38 -> 31074434 | E7: =E38+E69+IFERROR($E$105/$D$105*D7,0) -> 2.4197537e+08 | F7: =IFERROR(E7/D7,"") -> 7.7869597
A8: 4 | B8: Business Management, Marketing, and Administrative Services | D8: =D39 -> 18277419 | E8: =E39+E70+IFERROR($E$105/$D$105*D8,0) -> 1.4533196e+08 | F8: =IFERROR(E8/D8,"") -> 7.9514488
A9: 5 | B9: Career Pilot | D9: =D40 -> 146309 | E9: =E40+E71+IFERROR($E$105/$D$105*D9,0) -> 5130181.1 | F9: =IFERROR(E9/D9,"") -> 35.064016
A10: 6 | B10: Communications | D10: =D41 -> 4054192 | E10: =E41+E72+IFERROR($E$105/$D$105*D10,0) -> 36137263 | F10: =IFERROR(E10/D10,"") -> 8.913555
A11: 7 | B11: Computer and Information Sciences | D11: =D42 -> 11481191 | E11: =E42+E73+IFERROR($E$105/$D$105*D11,0) -> 1.1340407e+08 | F11: =IFERROR(E11/D11,"") -> 9.8773789
A12: 8 | B12: Construction Trades | D12: =D43 -> 1612212 | E12: =E43+E74+IFERROR($E$105/$D$105*D12,0) -> 17208435 | F12: =IFERROR(E12/D12,"") -> 10.673804
A13: 9 | B13: Consumer and Homemaking Education | D13: =D44 -> 9431343 | E13: =E44+E75+IFERROR($E$105/$D$105*D13,0) -> 73362250 | F13: =IFERROR(E13/D13,"") -> 7.7785582
A14: 10 | B14: Engineering | D14: =D45 -> 294975 | E14: =E45+E76+IFERROR($E$105/$D$105*D14,0) -> 3326493.7 | F14: =IFERROR(E14/D14,"") -> 11.277206
A15: 11 | B15: Engineering Related | D15: =D46 -> 7217480 | E15: =E46+E77+IFERROR($E$105/$D$105*D15,0) -> 60817644 | F15: =IFERROR(E15/D15,"") -> 8.4264374
A16: 12 | B16: English Language, Lit, Philosophy, Humanities, & Interdisciplinary | D16: =D47 -> 41737869 | E16: =E47+E78+IFERROR($E$105/$D$105*D16,0) -> 3.4472903e+08 | F16: =IFERROR(E16/D16,"") -> 8.2593827
... A30: 26 | B30: Visual and Performing Arts | D30: =D61 -> 13836400 | E30: =E61+E92+IFERROR($E$105/$D$105*D30,0) -> 1.3418793e+08 | F30: =IFERROR(E30/D30,"") -> 9.6981825
A31: 28 | B31: Developmental Education - Math | D31: =D62 -> 0 | E31: =E62+E93+IFERROR($E$105/$D$105*D31,0) -> 0 | F31: =IFERROR(E31/D31,0) -> 0
A32: 29 | B32: Developmental Education - Reading/Writing | D32: =D63 -> 0 | E32: =E63+E94+IFERROR($E$105/$D$105*D32,0) -> 0 | F32: =IFERROR(E32/D32,0) -> 0
B33: Total | D33: =SUM(D5:D32) -> 269950015 | E33: =SUM(E5:E32) -> 2272008424 | F33: =IFERROR(E33/D33,"") -> 8.4164041
A35: Fund | B35: Departmental Operating Expense by Discipline | D35: Contact Hours | E35: Expense | F35: Expense per Contact Hour
A36: 1 | B36: Agriculture | D36: =SUM('1:57'!D36) -> 1551137 | E36: =SUM('1:57'!E36) -> 2967127 | F36: =IFERROR(E36/D36,"") -> 1.9128723
A37: 2 | B37: Architecture and Precision Production Trades | D37: =SUM('1:57'!D37) -> 3763085 | E37: =SUM('1:57'!E37) -> 7682498 | F37: =IFERROR(E37/D37,"") -> 2.0415425
A38: 3 | B38: Biology, Physical Sciences, and Science Technology | D38: =SUM('1:57'!D38) -> 31074434 | E38: =SUM('1:57'!E38) -> 32810791 | F38: =IFERROR(E38/D38,"") -> 1.0558773
A39: 4 | B39: Business Management, Marketing, and Administrative Services | D39: =SUM('1:57'!D39) -> 18277419 | E39: =SUM('1:57'!E39) -> 20195638 | F39: =IFERROR(E39/D39,"") -> 1.1049502
A40: 5 | B40: Career Pilot | D40: =SUM('1:57'!D40) -> 146309 | E40: =SUM('1:57'!E40) -> 3242038 | F40: =IFERROR(E40/D40,"") -> 22.158842
A41: 6 | B41: Communications | D41: =SUM('1:57'!D41) -> 4054192 | E41: =SUM('1:57'!E41) -> 10290344 | F41: =IFERROR(E41/D41,"") -> 2.5381985
A42: 7 | B42: Computer and Information Sciences | D42: =SUM('1:57'!D42) -> 11481191 | E42: =SUM('1:57'!E42) -> 23283792 | F42: =IFERROR(E42/D42,"") -> 2.0279945
A43: 8 | B43: Construction Trades | D43: =SUM('1:57'!D43) -> 1612212 | E43: =SUM('1:57'!E43) -> 4576316 | F43: =IFERROR(E43/D43,"") -> 2.8385324
A44: 9 | B44: Consumer and Homemaking Education | D44: =SUM('1:57'!D44) -> 9431343 | E44: =SUM('1:57'!E44) -> 12400648 | F44: =IFERROR(E44/D44,"") -> 1.3148337
A45: 10 | B45: Engineering | D45: =SUM('1:57'!D45) -> 294975 | E45: =SUM('1:57'!E45) -> 679278 | F45: =IFERROR(E45/D45,"") -> 2.3028324
A46: 11 | B46: Engineering Related | D46: =SUM('1:57'!D46) -> 7217480 | E46: =SUM('1:57'!E46) -> 11803661 | F46: =IFERROR(E46/D46,"") -> 1.6354269
A47: 12 | B47: English Language, Lit, Philosophy, Humanities, & Interdisciplinary | D47: =SUM('1:57'!D47) -> 41737869 | E47: =SUM('1:57'!E47) -> 37124038 | F47: =IFERROR(E47/D47,"") -> 0.88945696
... A63: 29 | B63: Developmental Education - Reading/Writing | D63: =SUM('1:57'!D63) -> 0 | E63: =SUM('1:57'!E63) -> 0 | F63: =IFERROR(E63/D63,"")
C64: Total | D64: =SUM(D36:D63) -> 269950015 | E64: =SUM(E36:E63) -> 319938491 | F64: =IFERROR(E64/D64,"") -> 1.1851768
A66: Fund | B66: Faculty Salaries by Discipline | D66: Contact Hours | E66: Expense | F66: Expense per Contact Hour
A67: 1 | B67: Agriculture | D67: =D36 -> 1551137 | E67: =SUM('1:57'!E67) -> 5010423 | F67: =IFERROR(E67/D67,"") -> 3.2301615
A68: 2 | B68: Architecture and Precision Production Trades | D68: =D37 -> 3763085 | E68: =SUM('1:57'!E68) -> 15242530 | F68: =IFERROR(E68/D68,"") -> 4.050541
A69: 3 | B69: Biology, Physical Sciences, and Science Technology | D69: =D38 -> 31074434 | E69: =SUM('1:57'!E69) -> 90989788 | F69: =IFERROR(E69/D69,"") -> 2.9281237
A70: 4 | B70: Business Management, Marketing, and Administrative Services | D70: =D39 -> 18277419 | E70: =SUM('1:57'!E70) -> 55628055 | F70: =IFERROR(E70/D70,"") -> 3.04354
...

Sheet Rate History
A1: =Summary!A1 -> Community and Technical Colleges, Report of Fundable Operating Expenses, Fiscal Year (FY) 2009
A2: Rate History | O2: Year over Year Change
A3: Fund | B3: Expense per Contact Hour by Discipline | C3: 2009 | D3: 2008 | E3: 2007 | F3: 2006 | G3: 2005 | H3: 2004 | I3: 2003 | J3: 2002 | K3: 2001 | L3: 2000 | M3: 1999 | O3: 2009 | P3: 2008 | Q3: 2007 | R3: 2006 | S3: 2005 | T3: 2004 | U3: 2003 | V3: 2002 | W3: 2001 | X3: 2000
A4: 1 | B4: Agriculture | C4: =Summary!F5 -> 8.9459924 | D4: 7.7 | E4: 7.37 | G4: 7.25 | H4: 9.82 | I4: 7.18 | J4: 7.58 | K4: 7 | L4: 6.67 | M4: 6.81 | O4: =IFERROR(C4/D4-1,"") -> 0.16181719 | P4: =IFERROR(D4/E4-1,"") -> 0.044776119 | Q4: =IFERROR(E4/F4-1,"") | R4: =IFERROR(F4/G4-1,"") -> -1 | S4: =IFERROR(G4/H4-1,"") -> -0.26171079 | T4: =IFERROR(H4/I4-1,"") -> 0.36768802 | U4: =IFERROR(I4/J4-1,"") -> -0.052770449 | V4: =IFERROR(J4/K4-1,"") -> 0.082857143 | ... X4: =IFERROR(L4/M4-1,"") -> -0.020558003
A5: 2 | B5: Architecture and Precision Production Trades | C5: =Summary!F6 -> 9.8950421 | D5: 8.88 | E5: 10.29 | G5: 8.82 | H5: 11.31 | I5: 7.31 | J5: 7.27 | K5: 7.56 | L5: 6.83 | M5: 6.64 | O5: =IFERROR(C5/D5-1,"") -> 0.11430654 | P5: =IFERROR(D5/E5-1,"") -> -0.13702624 | Q5: =IFERROR(E5/F5-1,"") | R5: =IFERROR(F5/G5-1,"") -> -1 | S5: =IFERROR(G5/H5-1,"") -> -0.22015915 | T5: =IFERROR(H5/I5-1,"") -> 0.54719562 | U5: =IFERROR(I5/J5-1,"") -> 0.0055020633 | V5: =IFERROR(J5/K5-1,"") -> -0.038359788 | ... X5: =IFERROR(L5/M5-1,"") -> 0.028614458
A6: 3 | B6: Biology, Physical Sciences, and Science Technology | C6: =Summary!F7 -> 7.7869597 | D6: 6.85 | E6: 6.65 | G6: 6.19 | H6: 7.98 | I6: 5.86 | J6: 6.04 | K6: 5.9 | L6: 5.69 | M6: 5.51 | O6: =IFERROR(C6/D6-1,"") -> 0.13678244 | P6: =IFERROR(D6/E6-1,"") -> 0.030075188 | Q6: =IFERROR(E6/F6-1,"") | R6: =IFERROR(F6/G6-1,"") -> -1 | S6: =IFERROR(G6/H6-1,"") -> -0.22431078 | T6: =IFERROR(H6/I6-1,"") -> 0.36177474 | U6: =IFERROR(I6/J6-1,"") -> -0.029801325 | V6: =IFERROR(J6/K6-1,"") -> 0.023728814 | ... X6: =IFERROR(L6/M6-1,"") -> 0.032667877
A7: 4 | B7: Business Management, Marketing, and Administrative Services | C7: =Summary!F8 -> 7.9514488 | D7: 7.11 | E7: 6.97 | G7: 6.58 | H7: 8.86 | I7: 6.69 | J7: 6.46 | K7: 6.07 | L7: 6.13 | M7: 6.22 | O7: =IFERROR(C7/D7-1,"") -> 0.11834723 | P7: =IFERROR(D7/E7-1,"") -> 0.020086083 | Q7: =IFERROR(E7/F7-1,"") | R7: =IFERROR(F7/G7-1,"") -> -1 | S7: =IFERROR(G7/H7-1,"") -> -0.25733634 | T7: =IFERROR(H7/I7-1,"") -> 0.32436472 | U7: =IFERROR(I7/J7-1,"") -> 0.035603715 | V7: =IFERROR(J7/K7-1,"") -> 0.064250412 | ... X7: =IFERROR(L7/M7-1,"") -> -0.014469453
A8: 5 | B8: Career Pilot | C8: =Summary!F9 -> 35.064016 | D8: 33.87 | E8: 30.76 | G8: 23.45 | H8: 25.28 | I8: 13.77 | J8: 11.03 | K8: 16.04 | L8: 19.42 | M8: 18.69 | O8: =IFERROR(C8/D8-1,"") -> 0.035252899 | P8: =IFERROR(D8/E8-1,"") -> 0.10110533 | Q8: =IFERROR(E8/F8-1,"") | R8: =IFERROR(F8/G8-1,"") -> -1 | S8: =IFERROR(G8/H8-1,"") -> -0.072389241 | T8: =IFERROR(H8/I8-1,"") -> 0.83587509 | U8: =IFERROR(I8/J8-1,"") -> 0.24841342 | V8: =IFERROR(J8/K8-1,"") -> -0.31234414 | ... X8: =IFERROR(L8/M8-1,"") -> 0.03905832
A9: 6 | B9: Communications | C9: =Summary!F10 -> 8.913555 | D9: 7.65 | E9: 7.3 | G9: 7.3 | H9: 10.01 | I9: 7.21 | J9: 7.26 | K9: 6.99 | L9: 9.21 | M9: 8.21 | O9: =IFERROR(C9/D9-1,"") -> 0.16517059 | P9: =IFERROR(D9/E9-1,"") -> 0.047945205 | Q9: =IFERROR(E9/F9-1,"") | R9: =IFERROR(F9/G9-1,"") -> -1 | S9: =IFERROR(G9/H9-1,"") -> -0.27072927 | T9: =IFERROR(H9/I9-1,"") -> 0.38834951 | U9: =IFERROR(I9/J9-1,"") -> -0.0068870523 | V9: =IFERROR(J9/K9-1,"") -> 0.038626609 | ... X9: =IFERROR(L9/M9-1,"") -> 0.12180268
A10: 7 | B10: Computer and Information Sciences | C10: =Summary!F11 -> 9.8773789 | D10: 8.52 | E10: 8.44 | G10: 7.57 | H10: 9.93 | I10: 6.94 | J10: 6.92 | K10: 6.69 | L10: 6.32 | M10: 5.44 | O10: =IFERROR(C10/D10-1,"") -> 0.15931678 | P10: =IFERROR(D10/E10-1,"") -> 0.009478673 | Q10: =IFERROR(E10/F10-1,"") | R10: =IFERROR(F10/G10-1,"") -> -1 | S10: =IFERROR(G10/H10-1,"") -> -0.23766365 | T10: =IFERROR(H10/I10-1,"") -> 0.43083573 | U10: =IFERROR(I10/J10-1,"") -> 0.0028901734 | V10: =IFERROR(J10/K10-1,"") -> 0.034379671 | ... X10: =IFERROR(L10/M10-1,"") -> 0.16176471
A11: 8 | B11: Construction Trades | C11: =Summary!F12 -> 10.673804 | D11: 8.03 | E11: 7.77 | G11: 8.2 | H11: 10.92 | I11: 7.36 | J11: 6.75 | K11: 6.12 | L11: 6.42 | M11: 5.99 | O11: =IFERROR(C11/D11-1,"") -> 0.32924089 | P11: =IFERROR(D11/E11-1,"") -> 0.033462033 | Q11: =IFERROR(E11/F11-1,"") | R11: =IFERROR(F11/G11-1,"") -> -1 | S11: =IFERROR(G11/H11-1,"") -> -0.24908425 | T11: =IFERROR(H11/I11-1,"") -> 0.48369565 | U11: =IFERROR(I11/J11-1,"") -> 0.09037037 | V11: =IFERROR(J11/K11-1,"") -> 0.10294118 | ... X11: =IFERROR(L11/M11-1,"") -> 0.071786311
A12: 9 | B12: Consumer and Homemaking Education | C12: =Summary!F13 -> 7.7785582 | D12: 6.75 | E12: 6.49 | G12: 6.14 | H12: 8.08 | I12: 5.49 | J12: 5.51 | K12: 5.52 | L12: 5.14 | M12: 5.35 | O12: =IFERROR(C12/D12-1,"") -> 0.15237899 | P12: =IFERROR(D12/E12-1,"") -> 0.040061633 | Q12: =IFERROR(E12/F12-1,"") | R12: =IFERROR(F12/G12-1,"") -> -1 | S12: =IFERROR(G12/H12-1,"") -> -0.24009901 | T12: =IFERROR(H12/I12-1,"") -> 0.47176685 | U12: =IFERROR(I12/J12-1,"") -> -0.0036297641 | V12: =IFERROR(J12/K12-1,"") -> -0.0018115942 | ... X12: =IFERROR(L12/M12-1,"") -> -0.039252336
A13: 10 | B13: Engineering | C13: =Summary!F14 -> 11.277206 | D13: 7.86 | E13: 7.53 | G13: 10.3 | H13: 11.38 | I13: 8.92 | J13: 8.54 | K13: 11.49 | L13: 9.83 | M13: 7.64 | O13: =IFERROR(C13/D13-1,"") -> 0.43475898 | P13: =IFERROR(D13/E13-1,"") -> 0.043824701 | Q13: =IFERROR(E13/F13-1,"") | R13: =IFERROR(F13/G13-1,"") -> -1 | S13: =IFERROR(G13/H13-1,"") -> -0.094903339 | T13: =IFERROR(H13/I13-1,"") -> 0.27578475 | U13: =IFERROR(I13/J13-1,"") -> 0.044496487 | V13: =IFERROR(J13/K13-1,"") -> -0.256745 | ... X13: =IFERROR(L13/M13-1,"") -> 0.28664921
A14: 11 | B14: Engineering Related | C14: =Summary!F15 -> 8.4264374 | D14: 7.41 | E14: 7.09 | G14: 6.82 | H14: 9.52 | I14: 7.23 | J14: 6.89 | K14: 6.58 | L14: 6.71 | M14: 6.42 | O14: =IFERROR(C14/D14-1,"") -> 0.13717104 | P14: =IFERROR(D14/E14-1,"") -> 0.045133992 | Q14: =IFERROR(E14/F14-1,"") | R14: =IFERROR(F14/G14-1,"") -> -1 | S14: =IFERROR(G14/H14-1,"") -> -0.28361345 | T14: =IFERROR(H14/I14-1,"") -> 0.31673582 | U14: =IFERROR(I14/J14-1,"") -> 0.04934688 | V14: =IFERROR(J14/K14-1,"") -> 0.047112462 | ... X14: =IFERROR(L14/M14-1,"") -> 0.04517134
A15: 12 | B15: English Language, Lit, Philosophy, Humanities, & Interdisciplinary | C15: =Summary!F16 -> 8.2593827 | D15: 7.31 | E15: 7.08 | G15: 6.48 | H15: 8.33 | I15: 5.83 | J15: 5.94 | K15: 5.75 | L15: 5.68 | M15: 5.26 | O15: =IFERROR(C15/D15-1,"") -> 0.12987452 | P15: =IFERROR(D15/E15-1,"") -> 0.032485876 | Q15: =IFERROR(E15/F15-1,"") | R15: =IFERROR(F15/G15-1,"") -> -1 | S15: =IFERROR(G15/H15-1,"") -> -0.22208884 | T15: =IFERROR(H15/I15-1,"") -> 0.42881647 | U15: =IFERROR(I15/J15-1,"") -> -0.018518519 | V15: =IFERROR(J15/K15-1,"") -> 0.033043478 | ... X15: =IFERROR(L15/M15-1,"") -> 0.079847909
... A31: 29 | B31: Developmental Education - Reading/Writing | C31: =Summary!F32 -> 0 | D31: 0 | E31: 0 | G31: 0 | H31: 0 | I31: 0 | J31: 0 | K31: 0 | L31: 0 | M31: 0 | O31: =IFERROR(C31/D31-1,"") | P31: =IFERROR(D31/E31-1,"") | Q31: =IFERROR(E31/F31-1,"") | R31: =IFERROR(F31/G31-1,"") | S31: =IFERROR(G31/H31-1,"") | T31: =IFERROR(H31/I31-1,"") | U31: =IFERROR(I31/J31-1,"") | V31: =IFERROR(J31/K31-1,"") | ... X31: =IFERROR(L31/M31-1,"")
B32: Average | C32: =AVERAGE(C4:C31) -> 9.871227 | D32: =AVERAGE(D4:D31) -> 8.67 | E32: =AVERAGE(E4:E31) -> 8.4635714 | G32: =AVERAGE(G4:G31) -> 7.7992857 | H32: =AVERAGE(H4:H31) -> 9.7525 | I32: =AVERAGE(I4:I31) -> 6.9428571 | J32: =AVERAGE(J4:J31) -> 7.0071429 | K32: =AVERAGE(K4:K31) -> 7.0107143 | L32: =AVERAGE(L4:L31) -> 7.0171429 | M32: =AVERAGE(M4:M31) -> 6.5617857 | O32: =IFERROR(C32/D32-1,"") -> 0.13854982 | P32: =IFERROR(D32/E32-1,"") -> 0.024390244 | Q32: =IFERROR(E32/F32-1,"") | R32: =IFERROR(F32/G32-1,"") -> -1 | S32: =IFERROR(G32/H32-1,"") -> -0.20027832 | T32: =IFERROR(H32/I32-1,"") -> 0.40468107 | U32: =IFERROR(I32/J32-1,"") -> -0.0091743119 | V32: =IFERROR(J32/K32-1,"") -> -0.00050942435 | ... X32: =IFERROR(L32/M32-1,"") -> 0.069395308
B33: Median | C33: =MEDIAN(C4:C31) -> 9.3311851 | D33: =MEDIAN(D4:D31) -> 7.78 | E33: =MEDIAN(E4:E31) -> 7.525 | G33: =MEDIAN(G4:G31) -> 7.345 | H33: =MEDIAN(H4:H31) -> 9.615 | I33: =MEDIAN(I4:I31) -> 6.995 | J33: =MEDIAN(J4:J31) -> 6.905 | K33: =MEDIAN(K4:K31) -> 6.69 | L33: =MEDIAN(L4:L31) -> 6.69 | M33: =MEDIAN(M4:M31) -> 6.32 | O33: =IFERROR(C33/D33-1,"") -> 0.19938111 | P33: =IFERROR(D33/E33-1,"") -> 0.033887043 | Q33: =IFERROR(E33/F33-1,"") | R33: =IFERROR(F33/G33-1,"") -> -1 | S33: =IFERROR(G33/H33-1,"") -> -0.23608944 | T33: =IFERROR(H33/I33-1,"") -> 0.37455325 | U33: =IFERROR(I33/J33-1,"") -> 0.013034033 | V33: =IFERROR(J33/K33-1,"") -> 0.032137519 | ... X33: =IFERROR(L33/M33-1,"") -> 0.058544304
B34: Standard Deviation | C34: =STDEV(C4:C31) -> 5.9203334 | D34: =STDEV(D4:D31) -> 5.7536855 | E34: =STDEV(E4:E31) -> 5.2587227 | G34: =STDEV(G4:G31) -> 4.1137528 | H34: =STDEV(H4:H31) -> 4.4105653 | I34: =STDEV(I4:I31) -> 2.7509808 | J34: =STDEV(J4:J31) -> 2.6772026 | K34: =STDEV(K4:K31) -> 3.0868058 | L34: =STDEV(L4:L31) -> 3.4645516 | M34: =STDEV(M4:M31) -> 3.2525364 | O34: =IFERROR(C34/D34-1,"") -> 0.028963686 | P34: =IFERROR(D34/E34-1,"") -> 0.094122236 | Q34: =IFERROR(E34/F34-1,"") | R34: =IFERROR(F34/G34-1,"") -> -1 | S34: =IFERROR(G34/H34-1,"") -> -0.067295782 | T34: =IFERROR(H34/I34-1,"") -> 0.60327012 | U34: =IFERROR(I34/J34-1,"") -> 0.027557936 | V34: =IFERROR(J34/K34-1,"") -> -0.13269483 | ... X34: =IFERROR(L34/M34-1,"") -> 0.065184562

Sheet FTSE Summary
A1: =Summary!A1 -> Community and Technical Colleges, Report of Fundable Operating Expenses, Fiscal Year (FY) 2009
A2: Average Total Expenditure per Full-Time Student Equivalent (FTSE)
A3: Institution | B3: Annual State Funded Semester Credit Hours | C3: Total FTSE | D3: Total Expenditure | E3: Average Expenditure per FTSE
A4: Alamo | B4: 1058786 | C4: =B4/30 -> 35292.867 | D4: ='1'!$E$33 -> 2.0866447e+08 | E4: =IFERROR(D4/C4,"") -> 5912.3695
A5: Alvin | B5: 95665 | C5: =B5/30 -> 3188.8333 | D5: ='2'!$E$33 -> 21650677 | E5: =IFERROR(D5/C5,"") -> 6789.5292
A6: Amarillo | B6: 182539 | C6: =B6/30 -> 6084.6333 | D6: ='3'!$E$33 -> 37778402 | E6: =IFERROR(D6/C6,"") -> 6208.8215
A7: Angelina | B7: 95200 | C7: =B7/30 -> 3173.3333 | D7: ='4'!$E$33 -> 14259157 | E7: =IFERROR(D7/C7,"") -> 4493.4318
A8: Austin | B8: 697698 | C8: =B8/30 -> 23256.6 | D8: ='5'!$E$33 -> 1.5176977e+08 | E8: =IFERROR(D8/C8,"") -> 6525.8796
A9: Blinn | B9: 355946 | C9: =B9/30 -> 11864.867 | D9: ='6'!$E$33 -> 42057632 | E9: =IFERROR(D9/C9,"") -> 3544.7202
A10: Brazosport | B10: 68879 | C10: =B10/30 -> 2295.9667 | D10: ='7'!$E$33 -> 15048156 | E10: =IFERROR(D10/C10,"") -> 6554.1701
A11: Central Texas | B11: 260038 | C11: =B11/30 -> 8667.9333 | D11: ='8'!$E$33 -> 47596057 | E11: =IFERROR(D11/C11,"") -> 5491.0502
A12: Cisco | B12: 77412 | C12: =B12/30 -> 2580.4 | D12: ='9'!$E$33 -> 9521537 | E12: =IFERROR(D12/C12,"") -> 3689.9461
A13: Clarendon | B13: 29191 | C13: =B13/30 -> 973.03333 | D13: ='10'!$E$33 -> 3900789 | E13: =IFERROR(D13/C13,"") -> 4008.8955
A14: Coastal Bend | B14: 72230 | C14: =B14/30 -> 2407.6667 | D14: ='11'!$E$33 -> 14139348 | E14: =IFERROR(D14/C14,"") -> 5872.6352
A15: College Of The Mainland | B15: 74308 | C15: =B15/30 -> 2476.9333 | D15: ='12'!$E$33 -> 0 | E15: =IFERROR(D15/C15,"") -> 0
A16: Collin | B16: 442157 | C16: =B16/30 -> 14738.567 | D16: ='13'!$E$33 -> 80287869 | E16: =IFERROR(D16/C16,"") -> 5447.4679
A17: Dallas | B17: 1240673 | C17: =B17/30 -> 41355.767 | D17: ='14'!$E$33 -> 233857119 | E17: =IFERROR(D17/C17,"") -> 5654.7644
A18: Del Mar | B18: 211926 | C18: =B18/30 -> 7064.2 | D18: ='15'!$E$33 -> 53827021 | E18: =IFERROR(D18/C18,"") -> 7619.691
A19: El Paso | B19: 492251 | C19: =B19/30 -> 16408.367 | D19: ='16'!$E$33 -> 82584383 | E19: =IFERROR(D19/C19,"") -> 5033.0654
A20: Frank Phillips | B20: 24842 | C20: =B20/30 -> 828.06667 | D20: ='17'!$E$33 -> 6035988 | E20: =IFERROR(D20/C20,"") -> 7289.2537
A21: Galveston | B21: 39172 | C21: =B21/30 -> 1305.7333 | D21: ='18'!$E$33 -> 12047577 | E21: =IFERROR(D21/C21,"") -> 9226.6749
A22: Grayson | B22: 92493 | C22: =B22/30 -> 3083.1 | D22: ='19'!$E$33 -> 14481730 | E22: =IFERROR(D22/C22,"") -> 4697.1328
A23: Hill | B23: 80072 | C23: =B23/30 -> 2669.0667 | D23: ='20'!$E$33 -> 11551061 | E23: =IFERROR(D23/C23,"") -> 4327.7529
A24: Houston | B24: 951017 | C24: =B24/30 -> 31700.567 | D24: ='21'!$E$33 -> 180970906 | E24: =IFERROR(D24/C24,"") -> 5708.7593
A25: Howard | B25: 65104 | C25: =B25/30 -> 2170.1333 | D25: ='22'!$E$33 -> 16020108 | E25: =IFERROR(D25/C25,"") -> 7382.0847
A26: Kilgore | B26: 122178 | C26: =B26/30 -> 4072.6 | D26: ='23'!$E$33 -> 21474142 | E26: =IFERROR(D26/C26,"") -> 5272.8336
A27: Laredo | B27: 165170 | C27: =B27/30 -> 5505.6667 | D27: ='24'!$E$33 -> 35259656 | E27: =IFERROR(D27/C27,"") -> 6404.2482
A28: Lee | B28: 126763 | C28: =B28/30 -> 4225.4333 | D28: ='25'!$E$33 -> 28444801 | E28: =IFERROR(D28/C28,"") -> 6731.8068
A29: Lonestar | B29: 869997 | C29: =B29/30 -> 28999.9 | D29: ='26'!$E$33 -> 166864847 | E29: =IFERROR(D29/C29,"") -> 5753.9801
A30: Mclennan | B30: 176902 | C30: =B30/30 -> 5896.7333 | D30: ='27'!$E$33 -> 36014717 | E30: =IFERROR(D30/C30,"") -> 6107.5709
A31: Midland | B31: 112925 | C31: =B31/30 -> 3764.1667 | D31: ='28'!$E$33 -> 27584805 | E31: =IFERROR(D31/C31,"") -> 7328.2634
A32: Navarro | B32: 186501 | C32: =B32/30 -> 6216.7 | D32: ='29'!$E$33 -> 21320555 | E32: =IFERROR(D32/C32,"") -> 3429.5615
A33: North Central Texas | B33: 159586 | C33: =B33/30 -> 5319.5333 | D33: ='30'!$E$33 -> 18359956 | E33: =IFERROR(D33/C33,"") -> 3451.4223
A34: Northeast Texas | B34: 54306 | C34: =B34/30 -> 1810.2 | D34: ='31'!$E$33 -> 9366376 | E34: =IFERROR(D34/C34,"") -> 5174.2216
A35: Odessa | B35: 87447 | C35: =B35/30 -> 2914.9 | D35: ='32'!$E$33 -> 21099064 | E35: =IFERROR(D35/C35,"") -> 7238.3492
A36: Panola | B36: 42511 | C36: =B36/30 -> 1417.0333 | D36: ='33'!$E$33 -> 9725576 | E36: =IFERROR(D36/C36,"") -> 6863.3361
A37: Paris | B37: 99580 | C37: =B37/30 -> 3319.3333 | D37: ='34'!$E$33 -> 13129915 | E37: =IFERROR(D37/C37,"") -> 3955.588
A38: Ranger | B38: 18370 | C38: =B38/30 -> 612.33333 | D38: ='35'!$E$33 -> 2777146 | E38: =IFERROR(D38/C38,"") -> 4535.35
A39: San Jacinto | B39: 502458 | C39: =B39/30 -> 16748.6 | D39: ='36'!$E$33 -> 91502268 | E39: =IFERROR(D39/C39,"") -> 5463.2786
A40: South Plains | B40: 196135 | C40: =B40/30 -> 6537.8333 | D40: ='37'!$E$33 -> 28369105 | E40: =IFERROR(D40/C40,"") -> 4339.2212
...

Sheet Discipline Summary
A1: =Summary!A1 -> Community and Technical Colleges, Report of Fundable Operating Expenses, Fiscal Year (FY) 2009
A2: Discipline Summary of Expense per Contact Hour by Institution
A3: Institution | B3: AG | C3: ARCH | D3: SCI | E3: BA | F3: CP | G3: COMM | H3: CS | I3: CNSTR | J3: HE | K3: ENG | L3: ENGR | M3: LA | N3: FL | O3: HODA | P3: HODH | Q3: HOO | R3: HORT | S3: NUR | T3: MATH | U3: AUTO | V3: MECH | W3: ELECT | X3: PE | Y3: PA | Z3: SS | AA3: FA | AB3: DEM | AC3: DER | AD3: Total
A4: Alamo | B4: ='1'!$F$5 -> 7.603128 | C4: ='1'!$F$6 -> 12.101788 | D4: ='1'!$F$7 -> 9.3650965 | E4: ='1'!$F$8 -> 9.8422926 | F4: ='1'!$F$9 -> 106.94003 | G4: ='1'!$F$10 -> 11.115511 | H4: ='1'!$F$11 -> 10.972126 | I4: ='1'!$F$12 -> 10.720533 | J4: ='1'!$F$13 -> 9.8017384 | K4: ='1'!$F$14 -> 18.137073 | L4: ='1'!$F$15 -> 13.197996 | M4: ='1'!$F$16 -> 9.1869356 | N4: ='1'!$F$17 -> 7.955001 | O4: ='1'!$F$18 -> 18.027764 | P4: ='1'!$F$19 | Q4: ='1'!$F$20 -> 11.011956 | R4: ='1'!$F$21 -> 17.684688 | S4: ='1'!$F$22 -> 12.723883 | T4: ='1'!$F$23 -> 8.807904 | U4: ='1'!$F$24 -> 10.611408 | V4: ='1'!$F$25 -> 12.076936 | W4: ='1'!$F$26 -> 5.3409289 | X4: ='1'!$F$27 -> 10.129854 | Y4: ='1'!$F$28 -> 9.1611829 | Z4: ='1'!$F$29 -> 8.4327659 | AA4: ='1'!$F$30 -> 11.060968 | AB4: ='1'!$F$31 | AC4: ='1'!$F$32 | AD4: ='1'!$F$33 -> 9.7162787
A5: Alvin | B5: ='2'!$F$5 -> 8.6873651 | C5: ='2'!$F$6 -> 8.3352263 | D5: ='2'!$F$7 -> 6.1853423 | E5: ='2'!$F$8 -> 12.184762 | F5: ='2'!$F$9 | G5: ='2'!$F$10 -> 9.9408003 | H5: ='2'!$F$11 -> 11.672517 | I5: ='2'!$F$12 -> 8.7301207 | J5: ='2'!$F$13 -> 8.9508497 | K5: ='2'!$F$14 | L5: ='2'!$F$15 -> 10.821927 | M5: ='2'!$F$16 -> 8.538 | N5: ='2'!$F$17 -> 6.5555529 | O5: ='2'!$F$18 -> 11.376602 | P5: ='2'!$F$19 | Q5: ='2'!$F$20 -> 12.572931 | R5: ='2'!$F$21 -> 13.03966 | S5: ='2'!$F$22 -> 9.328425 | T5: ='2'!$F$23 -> 7.6104371 | U5: ='2'!$F$24 -> 9.7415278 | V5: ='2'!$F$25 -> 4.1168106 | W5: ='2'!$F$26 -> 6.1233897 | X5: ='2'!$F$27 -> 11.653483 | Y5: ='2'!$F$28 -> 8.6467055 | Z5: ='2'!$F$29 -> 7.5431497 | AA5: ='2'!$F$30 -> 15.171573 | AB5: ='2'!$F$31 | AC5: ='2'!$F$32 | AD5: ='2'!$F$33 -> 9.5229469
A6: Amarillo | B6: ='3'!$F$5 -> 8.0869201 | C6: ='3'!$F$6 -> 9.3206261 | D6: ='3'!$F$7 -> 7.6568165 | E6: ='3'!$F$8 -> 8.550775 | F6: ='3'!$F$9 -> 9.372029 | G6: ='3'!$F$10 -> 8.6788066 | H6: ='3'!$F$11 -> 8.4152715 | I6: ='3'!$F$12 -> 9.3683925 | J6: ='3'!$F$13 -> 7.2552275 | K6: ='3'!$F$14 -> 7.6237403 | L6: ='3'!$F$15 -> 8.4617076 | M6: ='3'!$F$16 -> 9.0307993 | N6: ='3'!$F$17 -> 8.0342085 | O6: ='3'!$F$18 -> 9.5572207 | P6: ='3'!$F$19 -> 8.7007774 | Q6: ='3'!$F$20 -> 8.5852933 | R6: ='3'!$F$21 -> 8.7756293 | S6: ='3'!$F$22 -> 9.9102305 | T6: ='3'!$F$23 -> 7.8894405 | U6: ='3'!$F$24 -> 9.3684072 | V6: ='3'!$F$25 -> 9.3647828 | W6: ='3'!$F$26 -> 8.8138505 | X6: ='3'!$F$27 -> 5.9301319 | Y6: ='3'!$F$28 -> 8.3706665 | Z6: ='3'!$F$29 -> 6.1359837 | AA6: ='3'!$F$30 -> 8.0141502 | AB6: ='3'!$F$31 | AC6: ='3'!$F$32 | AD6: ='3'!$F$33 -> 8.1607864
A7: Angelina | B7: ='4'!$F$5 -> 4.6391615 | C7: ='4'!$F$6 -> 9.3478806 | D7: ='4'!$F$7 -> 5.5250562 | E7: ='4'!$F$8 -> 6.2645132 | F7: ='4'!$F$9 | G7: ='4'!$F$10 -> 10.795874 | H7: ='4'!$F$11 -> 11.010949 | I7: ='4'!$F$12 -> 6.9055094 | J7: ='4'!$F$13 -> 6.2990453 | K7: ='4'!$F$14 -> 14.97098 | L7: ='4'!$F$15 -> 6.7748572 | M7: ='4'!$F$16 -> 5.4044949 | N7: ='4'!$F$17 -> 5.2572775 | O7: ='4'!$F$18 -> 10.626404 | P7: ='4'!$F$19 | Q7: ='4'!$F$20 -> 6.3219565 | R7: ='4'!$F$21 -> 9.4369868 | S7: ='4'!$F$22 -> 5.9932117 | T7: ='4'!$F$23 -> 6.6025368 | U7: ='4'!$F$24 -> 9.5240129 | V7: ='4'!$F$25 -> 8.2259822 | W7: ='4'!$F$26 -> 6.7741876 | X7: ='4'!$F$27 -> 7.0417084 | Y7: ='4'!$F$28 -> 5.7587599 | Z7: ='4'!$F$29 -> 5.3035952 | AA7: ='4'!$F$30 -> 7.9509374 | AB7: ='4'!$F$31 | AC7: ='4'!$F$32 | AD7: ='4'!$F$33 -> 6.4829172
A8: Austin | B8: ='5'!$F$5 -> 7.2688884 | C8: ='5'!$F$6 -> 16.158143 | D8: ='5'!$F$7 -> 11.141 | E8: ='5'!$F$8 -> 9.7895707 | F8: ='5'!$F$9 | G8: ='5'!$F$10 -> 8.6445183 | H8: ='5'!$F$11 -> 15.967604 | I8: ='5'!$F$12 -> 6.049005 | J8: ='5'!$F$13 -> 14.841007 | K8: ='5'!$F$14 -> 16.617903 | L8: ='5'!$F$15 -> 12.704747 | M8: ='5'!$F$16 -> 10.011883 | N8: ='5'!$F$17 -> 9.7165447 | O8: ='5'!$F$18 -> 15.532566 | P8: ='5'!$F$19 -> 31.583078 | Q8: ='5'!$F$20 -> 15.016359 | R8: ='5'!$F$21 | S8: ='5'!$F$22 -> 18.609714 | T8: ='5'!$F$23 -> 9.0883159 | U8: ='5'!$F$24 -> 15.092925 | V8: ='5'!$F$25 -> 49.152354 | W8: ='5'!$F$26 -> 31.112665 | X8: ='5'!$F$27 -> 9.8652915 | Y8: ='5'!$F$28 -> 10.288539 | Z8: ='5'!$F$29 -> 8.461757 | AA8: ='5'!$F$30 -> 14.663626 | AB8: ='5'!$F$31 | AC8: ='5'!$F$32 | AD8: ='5'!$F$33 -> 10.858162
A9: Blinn | B9: ='6'!$F$5 -> 7.158193 | C9: ='6'!$F$6 -> 11.25051 | D9: ='6'!$F$7 -> 4.7774171 | E9: ='6'!$F$8 -> 7.3522632 | F9: ='6'!$F$9 | G9: ='6'!$F$10 -> 4.0733694 | H9: ='6'!$F$11 -> 15.342066 | I9: ='6'!$F$12 -> 11.25049 | J9: ='6'!$F$13 -> 3.6226236 | K9: ='6'!$F$14 | L9: ='6'!$F$15 -> 25.121388 | M9: ='6'!$F$16 -> 6.5980677 | N9: ='6'!$F$17 -> 5.9577049 | O9: ='6'!$F$18 -> 14.039926 | P9: ='6'!$F$19 -> 25.203667 | Q9: ='6'!$F$20 -> 7.4140944 | R9: ='6'!$F$21 | S9: ='6'!$F$22 -> 7.74297 | T9: ='6'!$F$23 -> 5.6779825 | U9: ='6'!$F$24 -> 11.250381 | V9: ='6'!$F$25 -> 11.250567 | W9: ='6'!$F$26 -> 11.250705 | X9: ='6'!$F$27 -> 6.999174 | Y9: ='6'!$F$28 -> 5.8783649 | Z9: ='6'!$F$29 -> 4.7355482 | AA9: ='6'!$F$30 -> 6.6259243 | AB9: ='6'!$F$31 | AC9: ='6'!$F$32 | AD9: ='6'!$F$33 -> 6.0424602
A10: Brazosport | B10: ='7'!$F$5 | C10: ='7'!$F$6 -> 11.082239 | D10: ='7'!$F$7 -> 10.834324 | E10: ='7'!$F$8 -> 11.521906 | F10: ='7'!$F$9 | G10: ='7'!$F$10 | H10: ='7'!$F$11 -> 11.140116 | I10: ='7'!$F$12 -> 11.18581 | J10: ='7'!$F$13 -> 7.8099524 | K10: ='7'!$F$14 | L10: ='7'!$F$15 -> 6.2738347 | M10: ='7'!$F$16 -> 9.24087 | N10: ='7'!$F$17 -> 9.5126537 | O10: ='7'!$F$18 -> 22.819283 | P10: ='7'!$F$19 | Q10: ='7'!$F$20 -> 18.302609 | R10: ='7'!$F$21 | S10: ='7'!$F$22 -> 14.667404 | T10: ='7'!$F$23 -> 8.8103484 | U10: ='7'!$F$24 -> 10.574499 | V10: ='7'!$F$25 -> 30.5166 | W10: ='7'!$F$26 -> 12.528932 | X10: ='7'!$F$27 -> 11.329425 | Y10: ='7'!$F$28 -> 9.4245573 | Z10: ='7'!$F$29 -> 8.4508676 | AA10: ='7'!$F$30 -> 13.531377 | AB10: ='7'!$F$31 | AC10: ='7'!$F$32 | AD10: ='7'!$F$33 -> 10.086423
A11: Central Texas | B11: ='8'!$F$5 -> 5.254863 | C11: ='8'!$F$6 -> 13.701736 | D11: ='8'!$F$7 -> 7.5121892 | E11: ='8'!$F$8 -> 7.1024759 | F11: ='8'!$F$9 -> 57.081274 | G11: ='8'!$F$10 -> 7.3751735 | H11: ='8'!$F$11 -> 17.923499 | I11: ='8'!$F$12 -> 9.1514465 | J11: ='8'!$F$13 -> 5.7736249 | K11: ='8'!$F$14 -> 158.1185 | L11: ='8'!$F$15 -> 4.9243556 | M11: ='8'!$F$16 -> 7.1963464 | N11: ='8'!$F$17 -> 7.4144033 | O11: ='8'!$F$18 -> 13.664617 | P11: ='8'!$F$19 | Q11: ='8'!$F$20 -> 10.801458 | R11: ='8'!$F$21 | S11: ='8'!$F$22 -> 9.3515086 | T11: ='8'!$F$23 -> 6.5494019 | U11: ='8'!$F$24 -> 8.8400672 | V11: ='8'!$F$25 -> 7.038938 | W11: ='8'!$F$26 -> 28.22519 | X11: ='8'!$F$27 -> 8.6165652 | Y11: ='8'!$F$28 -> 9.0450087 | Z11: ='8'!$F$29 -> 6.0041752 | AA11: ='8'!$F$30 -> 6.9630226 | AB11: ='8'!$F$31 | AC11: ='8'!$F$32 | AD11: ='8'!$F$33 -> 8.3298475
A12: Cisco | B12: ='9'!$F$5 -> 9.5496279 | C12: ='9'!$F$6 -> 5.831037 | D12: ='9'!$F$7 -> 4.928326 | E12: ='9'!$F$8 -> 4.3696829 | F12: ='9'!$F$9 | G12: ='9'!$F$10 | H12: ='9'!$F$11 -> 19.330405 | I12: ='9'!$F$12 -> 6.1648408 | J12: ='9'!$F$13 -> 5.3224353 | K12: ='9'!$F$14 | L12: ='9'!$F$15 -> 5.7743063 | M12: ='9'!$F$16 -> 5.81278 | N12: ='9'!$F$17 -> 5.6333109 | O12: ='9'!$F$18 -> 7.7161365 | P12: ='9'!$F$19 | Q12: ='9'!$F$20 -> 4.4878608 | R12: ='9'!$F$21 -> 9.06687 | S12: ='9'!$F$22 -> 6.0331279 | T12: ='9'!$F$23 -> 5.7901659 | U12: ='9'!$F$24 -> 10.17417 | V12: ='9'!$F$25 | W12: ='9'!$F$26 -> 6.0870681 | X12: ='9'!$F$27 -> 11.01165 | Y12: ='9'!$F$28 -> 6.4448931 | Z12: ='9'!$F$29 -> 5.2359233 | AA12: ='9'!$F$30 -> 6.3329309 | AB12: ='9'!$F$31 | AC12: ='9'!$F$32 | AD12: ='9'!$F$33 -> 5.9323664
A13: Clarendon | B13: ='10'!$F$5 -> 8.6128713 | C13: ='10'!$F$6 -> 6.4237601 | D13: ='10'!$F$7 -> 5.4478402 | E13: ='10'!$F$8 -> 5.7112874 | F13: ='10'!$F$9 | G13: ='10'!$F$10 -> 4.4995703 | H13: ='10'!$F$11 -> 8.0778073 | I13: ='10'!$F$12 | J13: ='10'!$F$13 -> 4.2064095 | K13: ='10'!$F$14 | L13: ='10'!$F$15 -> 6.8884955 | M13: ='10'!$F$16 -> 5.7055589 | N13: ='10'!$F$17 -> 5.8404329 | O13: ='10'!$F$18 | P13: ='10'!$F$19 | Q13: ='10'!$F$20 -> 3.728902 | R13: ='10'!$F$21 | S13: ='10'!$F$22 -> 6.1526649 | T13: ='10'!$F$23 -> 5.6137572 | U13: ='10'!$F$24 | V13: ='10'!$F$25 | W13: ='10'!$F$26 -> 9.6252648 | X13: ='10'!$F$27 -> 7.1579446 | Y13: ='10'!$F$28 -> 3.2897348 | Z13: ='10'!$F$29 -> 5.2216391 | AA13: ='10'!$F$30 -> 4.6881988 | AB13: ='10'!$F$31 | AC13: ='10'!$F$32 | AD13: ='10'!$F$33 -> 5.8401165
A14: Coastal Bend | B14: ='11'!$F$5 -> 6.1299472 | C14: ='11'!$F$6 -> 7.7305296 | D14: ='11'!$F$7 -> 7.329332 | E14: ='11'!$F$8 -> 9.677696 | F14: ='11'!$F$9 | G14: ='11'!$F$10 -> 8.2196618 | H14: ='11'!$F$11 -> 7.3042059 | I14: ='11'!$F$12 -> 8.1937359 | J14: ='11'!$F$13 -> 7.7345147 | K14: ='11'!$F$14 -> 5.8566515 | L14: ='11'!$F$15 -> 7.2800603 | M14: ='11'!$F$16 -> 7.9696088 | N14: ='11'!$F$17 -> 11.615175 | O14: ='11'!$F$18 -> 20.290563 | P14: ='11'!$F$19 -> 15.271303 | Q14: ='11'!$F$20 -> 7.9136272 | R14: ='11'!$F$21 | S14: ='11'!$F$22 -> 9.3939955 | T14: ='11'!$F$23 -> 8.2826606 | U14: ='11'!$F$24 -> 8.001576 | V14: ='11'!$F$25 -> 12.109986 | W14: ='11'!$F$26 -> 7.7689706 | X14: ='11'!$F$27 -> 7.4397659 | Y14: ='11'!$F$28 -> 9.292929 | Z14: ='11'!$F$29 -> 4.1869452 | AA14: ='11'!$F$30 -> 5.9344476 | AB14: ='11'!$F$31 | AC14: ='11'!$F$32 | AD14: ='11'!$F$33 -> 7.7665212
A15: College Of The Mainland | B15: ='12'!$F$5 | C15: ='12'!$F$6 | D15: ='12'!$F$7 | E15: ='12'!$F$8 | F15: ='12'!$F$9 | G15: ='12'!$F$10 | H15: ='12'!$F$11 | I15: ='12'!$F$12 | J15: ='12'!$F$13 | K15: ='12'!$F$14 | L15: ='12'!$F$15 | M15: ='12'!$F$16 | N15: ='12'!$F$17 | O15: ='12'!$F$18 | P15: ='12'!$F$19 | Q15: ='12'!$F$20 | R15: ='12'!$F$21 | S15: ='12'!$F$22 | T15: ='12'!$F$23 | U15: ='12'!$F$24 | V15: ='12'!$F$25 | W15: ='12'!$F$26 | X15: ='12'!$F$27 | Y15: ='12'!$F$28 | Z15: ='12'!$F$29 | AA15: ='12'!$F$30 | AB15: ='12'!$F$31 | AC15: ='12'!$F$32 | AD15: ='12'!$F$33
A16: Collin | B16: ='13'!$F$5 -> 4.7648644 | C16: ='13'!$F$6 -> 4.7651411 | D16: ='13'!$F$7 -> 9.4830794 | E16: ='13'!$F$8 -> 6.1766291 | F16: ='13'!$F$9 -> 4.7655608 | G16: ='13'!$F$10 -> 5.026632 | H16: ='13'!$F$11 -> 9.626001 | I16: ='13'!$F$12 -> 4.7651824 | J16: ='13'!$F$13 -> 10.133978 | K16: ='13'!$F$14 -> 38.176576 | L16: ='13'!$F$15 -> 10.602595 | M16: ='13'!$F$16 -> 8.2870209 | N16: ='13'!$F$17 -> 6.6600235 | O16: ='13'!$F$18 -> 21.253024 | P16: ='13'!$F$19 -> 25.351457 | Q16: ='13'!$F$20 -> 8.5724336 | R16: ='13'!$F$21 -> 15.697639 | S16: ='13'!$F$22 | T16: ='13'!$F$23 -> 7.7443332 | U16: ='13'!$F$24 | V16: ='13'!$F$25 -> 4.7484744 | W16: ='13'!$F$26 -> 4.7649132 | X16: ='13'!$F$27 -> 9.3597281 | Y16: ='13'!$F$28 -> 10.715827 | Z16: ='13'!$F$29 -> 7.5481908 | AA16: ='13'!$F$30 -> 10.485568 | AB16: ='13'!$F$31 | AC16: ='13'!$F$32 | AD16: ='13'!$F$33 -> 8.5502295
A17: Dallas | B17: ='14'!$F$5 -> 18.048833 | C17: ='14'!$F$6 -> 10.543374 | D17: ='14'!$F$7 -> 7.786414 | E17: ='14'!$F$8 -> 8.0099742 | F17: ='14'!$F$9 -> 14.985355 | G17: ='14'!$F$10 -> 9.2199116 | H17: ='14'!$F$11 -> 8.3429283 | I17: ='14'!$F$12 -> 17.586012 | J17: ='14'!$F$13 -> 7.2534746 | K17: ='14'!$F$14 -> 13.549484 | L17: ='14'!$F$15 -> 5.6978975 | M17: ='14'!$F$16 -> 8.3289394 | N17: ='14'!$F$17 -> 7.4357531 | O17: ='14'!$F$18 -> 11.721522 | P17: ='14'!$F$19 | Q17: ='14'!$F$20 -> 7.9472452 | R17: ='14'!$F$21 -> 18.233515 | S17: ='14'!$F$22 -> 13.271347 | T17: ='14'!$F$23 -> 7.4227707 | U17: ='14'!$F$24 -> 10.26988 | V17: ='14'!$F$25 -> 5.603513 | W17: ='14'!$F$26 -> 7.130562 | X17: ='14'!$F$27 -> 9.131402 | Y17: ='14'!$F$28 -> 7.3195167 | Z17: ='14'!$F$29 -> 6.9661325 | AA17: ='14'!$F$30 -> 8.9691655 | AB17: ='14'!$F$31 | AC17: ='14'!$F$32 | AD17: ='14'!$F$33 -> 8.0469197
A18: Del Mar | B18: ='15'!$F$5 -> 10.756891 | C18: ='15'!$F$6 -> 10.92784 | D18: ='15'!$F$7 -> 8.8862029 | E18: ='15'!$F$8 -> 11.396527 | F18: ='15'!$F$9 | G18: ='15'!$F$10 -> 13.081413 | H18: ='15'!$F$11 -> 10.547526 | I18: ='15'!$F$12 -> 9.6666716 | J18: ='15'!$F$13 -> 10.455213 | K18: ='15'!$F$14 -> 11.504869 | L18: ='15'!$F$15 -> 9.5010016 | M18: ='15'!$F$16 -> 10.539652 | N18: ='15'!$F$17 -> 10.410124 | O18: ='15'!$F$18 -> 12.935012 | P18: ='15'!$F$19 -> 17.961474 | Q18: ='15'!$F$20 -> 10.623309 | R18: ='15'!$F$21 -> 12.432344 | S18: ='15'!$F$22 -> 41.315897 | T18: ='15'!$F$23 -> 11.522115 | U18: ='15'!$F$24 -> 11.302936 | V18: ='15'!$F$25 -> 8.0622707 | W18: ='15'!$F$26 -> 11.951463 | X18: ='15'!$F$27 -> 9.1569601 | Y18: ='15'!$F$28 -> 11.180262 | Z18: ='15'!$F$29 -> 9.0633488 | AA18: ='15'!$F$30 -> 13.553434 | AB18: ='15'!$F$31 | AC18: ='15'!$F$32 | AD18: ='15'!$F$33 -> 10.650911
A19: El Paso | B19: ='16'!$F$5 -> 6.2512499 | C19: ='16'!$F$6 -> 10.244708 | D19: ='16'!$F$7 -> 7.0825259 | E19: ='16'!$F$8 -> 10.151685 | F19: ='16'!$F$9 | G19: ='16'!$F$10 -> 14.204122 | H19: ='16'!$F$11 -> 8.3471899 | I19: ='16'!$F$12 -> 11.96718 | J19: ='16'!$F$13 -> 8.5803816 | K19: ='16'!$F$14 -> 7.556908 | L19: ='16'!$F$15 -> 7.0326793 | M19: ='16'!$F$16 -> 8.1031955 | N19: ='16'!$F$17 -> 8.0218947 | O19: ='16'!$F$18 -> 12.992937 | P19: ='16'!$F$19 -> 19.612233 | Q19: ='16'!$F$20 -> 12.170391 | R19: ='16'!$F$21 -> 18.373765 | S19: ='16'!$F$22 -> 10.396209 | T19: ='16'!$F$23 -> 6.8789527 | U19: ='16'!$F$24 -> 9.1257704 | V19: ='16'!$F$25 -> 13.856148 | W19: ='16'!$F$26 -> 12.795458 | X19: ='16'!$F$27 -> 16.580552 | Y19: ='16'!$F$28 -> 8.9353051 | Z19: ='16'!$F$29 -> 6.7972596 | AA19: ='16'!$F$30 -> 8.6718181 | AB19: ='16'!$F$31 | AC19: ='16'!$F$32 | AD19: ='16'!$F$33 -> 8.225632
A20: Frank Phillips | B20: ='17'!$F$5 -> 15.366507 | C20: ='17'!$F$6 -> 9.8666787 | D20: ='17'!$F$7 -> 8.0573843 | E20: ='17'!$F$8 -> 8.4728841 | F20: ='17'!$F$9 | G20: ='17'!$F$10 | H20: ='17'!$F$11 -> 18.791832 | I20: ='17'!$F$12 -> 8.6581371 | J20: ='17'!$F$13 -> 10.036666 | K20: ='17'!$F$14 | L20: ='17'!$F$15 -> 9.2843395 | M20: ='17'!$F$16 -> 7.4003882 | N20: ='17'!$F$17 -> 4.7219607 | O20: ='17'!$F$18 -> 6.4453714 | P20: ='17'!$F$19 | Q20: ='17'!$F$20 -> 10.305719 | R20: ='17'!$F$21 | S20: ='17'!$F$22 -> 8.205769 | T20: ='17'!$F$23 -> 8.5514496 | U20: ='17'!$F$24 | V20: ='17'!$F$25 -> 7.2632472 | W20: ='17'!$F$26 -> 5.5073506 | X20: ='17'!$F$27 -> 10.055101 | Y20: ='17'!$F$28 -> 5.6336066 | Z20: ='17'!$F$29 -> 8.2165908 | AA20: ='17'!$F$30 -> 6.9306177 | AB20: ='17'!$F$31 | AC20: ='17'!$F$32 | AD20: ='17'!$F$33 -> 9.319715
A21: Galveston | B21: ='18'!$F$5 -> 9.6351592 | C21: ='18'!$F$6 -> 20.76308 | D21: ='18'!$F$7 -> 12.720033 | E21: ='18'!$F$8 -> 13.653291 | F21: ='18'!$F$9 | G21: ='18'!$F$10 -> 20.388707 | H21: ='18'!$F$11 -> 11.258889 | I21: ='18'!$F$12 | J21: ='18'!$F$13 -> 12.027525 | K21: ='18'!$F$14 | L21: ='18'!$F$15 | M21: ='18'!$F$16 -> 11.28605 | N21: ='18'!$F$17 -> 12.664099 | O21: ='18'!$F$18 -> 20.788873 | P21: ='18'!$F$19 | Q21: ='18'!$F$20 -> 10.249885 | R21: ='18'!$F$21 | S21: ='18'!$F$22 -> 15.439726 | T21: ='18'!$F$23 -> 10.70909 | U21: ='18'!$F$24 | V21: ='18'!$F$25 | W21: ='18'!$F$26 -> 17.213707 | X21: ='18'!$F$27 -> 23.458568 | Y21: ='18'!$F$28 -> 15.31952 | Z21: ='18'!$F$29 -> 11.230752 | AA21: ='18'!$F$30 -> 13.524825 | AB21: ='18'!$F$31 | AC21: ='18'!$F$32 | AD21: ='18'!$F$33 -> 12.946699
A22: Grayson | B22: ='19'!$F$5 -> 6.4183174 | C22: ='19'!$F$6 -> 10.378645 | D22: ='19'!$F$7 -> 6.7963108 | E22: ='19'!$F$8 -> 6.8963201 | F22: ='19'!$F$9 | G22: ='19'!$F$10 | H22: ='19'!$F$11 -> 7.248884 | I22: ='19'!$F$12 | J22: ='19'!$F$13 -> 4.9088028 | K22: ='19'!$F$14 -> 5.0417793 | L22: ='19'!$F$15 -> 6.8491772 | M22: ='19'!$F$16 -> 5.9072755 | N22: ='19'!$F$17 -> 6.6074189 | O22: ='19'!$F$18 -> 9.9278488 | P22: ='19'!$F$19 | Q22: ='19'!$F$20 -> 6.33573 | R22: ='19'!$F$21 | S22: ='19'!$F$22 -> 7.2379158 | T22: ='19'!$F$23 -> 5.4382688 | U22: ='19'!$F$24 -> 6.9617466 | V22: ='19'!$F$25 -> 2.830995 | W22: ='19'!$F$26 -> 5.0977583 | X22: ='19'!$F$27 -> 19.163741 | Y22: ='19'!$F$28 -> 8.66081 | Z22: ='19'!$F$29 -> 5.6372614 | AA22: ='19'!$F$30 -> 7.2970461 | AB22: ='19'!$F$31 | AC22: ='19'!$F$32 | AD22: ='19'!$F$33 -> 6.7321438
A23: Hill | B23: ='20'!$F$5 -> 10.636468 | C23: ='20'!$F$6 -> 6.152947 | D23: ='20'!$F$7 -> 5.0571983 | E23: ='20'!$F$8 -> 3.6519747 | F23: ='20'!$F$9 | G23: ='20'!$F$10 -> 3.145252 | H23: ='20'!$F$11 -> 6.1628086 | I23: ='20'!$F$12 -> 44.185693 | J23: ='20'!$F$13 -> 5.2040747 | K23: ='20'!$F$14 | L23: ='20'!$F$15 -> 3.980321 | M23: ='20'!$F$16 -> 4.9163667 | N23: ='20'!$F$17 -> 3.5153807 | O23: ='20'!$F$18 -> 13.113798 | P23: ='20'!$F$19 | Q23: ='20'!$F$20 -> 4.853892 | R23: ='20'!$F$21 | S23: ='20'!$F$22 -> 8.8820794 | T23: ='20'!$F$23 -> 5.418964 | U23: ='20'!$F$24 -> 6.481421 | V23: ='20'!$F$25 -> 3.2209313 | W23: ='20'!$F$26 -> 3.9877765 | X23: ='20'!$F$27 -> 10.102399 | Y23: ='20'!$F$28 -> 4.8454473 | Z23: ='20'!$F$29 -> 4.8376801 | AA23: ='20'!$F$30 -> 5.9413096 | AB23: ='20'!$F$31 | AC23: ='20'!$F$32 | AD23: ='20'!$F$33 -> 5.6533171
A24: Houston | B24: ='21'!$F$5 -> 7.5717862 | C24: ='21'!$F$6 -> 10.49381 | D24: ='21'!$F$7 -> 7.7594327 | E24: ='21'!$F$8 -> 7.927107 | F24: ='21'!$F$9 | G24: ='21'!$F$10 -> 7.100753 | H24: ='21'!$F$11 -> 17.885655 | I24: ='21'!$F$12 -> 8.6766306 | J24: ='21'!$F$13 -> 7.5896704 | K24: ='21'!$F$14 -> 7.0589286 | L24: ='21'!$F$15 -> 7.0593779 | M24: ='21'!$F$16 -> 8.8513603 | N24: ='21'!$F$17 -> 8.0463045 | O24: ='21'!$F$18 -> 11.090433 | P24: ='21'!$F$19 | Q24: ='21'!$F$20 -> 11.210675 | R24: ='21'!$F$21 -> 14.386804 | S24: ='21'!$F$22 -> 17.449869 | T24: ='21'!$F$23 -> 7.5386879 | U24: ='21'!$F$24 -> 10.191141 | V24: ='21'!$F$25 -> 11.277381 | W24: ='21'!$F$26 -> 10.044887 | X24: ='21'!$F$27 -> 10.224512 | Y24: ='21'!$F$28 -> 10.88683 | Z24: ='21'!$F$29 -> 7.3306278 | AA24: ='21'!$F$30 -> 9.2193061 | AB24: ='21'!$F$31 | AC24: ='21'!$F$32 | AD24: ='21'!$F$33 -> 8.4703174
A25: Howard | B25: ='22'!$F$5 -> 6.7855839 | C25: ='22'!$F$6 -> 8.8223869 | D25: ='22'!$F$7 -> 6.4189867 | E25: ='22'!$F$8 -> 5.5783164 | F25: ='22'!$F$9 -> 18.833436 | G25: ='22'!$F$10 -> 5.2008484 | H25: ='22'!$F$11 -> 6.6003836 | I25: ='22'!$F$12 -> 5.7487078 | J25: ='22'!$F$13 -> 4.7556051 | K25: ='22'!$F$14 | L25: ='22'!$F$15 -> 4.8615433 | M25: ='22'!$F$16 -> 9.1752903 | N25: ='22'!$F$17 -> 7.5582872 | O25: ='22'!$F$18 -> 14.286455 | P25: ='22'!$F$19 -> 18.641513 | Q25: ='22'!$F$20 -> 10.551427 | R25: ='22'!$F$21 -> 10.25587 | S25: ='22'!$F$22 -> 8.6249717 | T25: ='22'!$F$23 -> 7.0888624 | U25: ='22'!$F$24 -> 11.585187 | V25: ='22'!$F$25 -> 8.5030693 | W25: ='22'!$F$26 -> 4.9901169 | X25: ='22'!$F$27 -> 21.119922 | Y25: ='22'!$F$28 -> 6.5588598 | Z25: ='22'!$F$29 -> 5.9845289 | AA25: ='22'!$F$30 -> 7.0994931 | AB25: ='22'!$F$31 | AC25: ='22'!$F$32 | AD25: ='22'!$F$33 -> 6.9639624
A26: Kilgore | B26: ='23'!$F$5 -> 10.889133 | C26: ='23'!$F$6 -> 7.5294358 | D26: ='23'!$F$7 -> 6.5107157 | E26: ='23'!$F$8 -> 5.8715035 | F26: ='23'!$F$9 | G26: ='23'!$F$10 -> 9.7377863 | H26: ='23'!$F$11 -> 5.6669197 | I26: ='23'!$F$12 -> 31.500801 | J26: ='23'!$F$13 -> 5.4661961 | K26: ='23'!$F$14 -> 9.6287155 | L26: ='23'!$F$15 -> 6.5452359 | M26: ='23'!$F$16 -> 5.6715125 | N26: ='23'!$F$17 -> 10.738252 | O26: ='23'!$F$18 -> 8.2291732 | P26: ='23'!$F$19 | Q26: ='23'!$F$20 -> 6.4821209 | R26: ='23'!$F$21 | S26: ='23'!$F$22 -> 6.0619576 | T26: ='23'!$F$23 -> 5.5736412 | U26: ='23'!$F$24 -> 8.0798115 | V26: ='23'!$F$25 -> 5.2982565 | W26: ='23'!$F$26 -> 2.6091502 | X26: ='23'!$F$27 -> 7.5815142 | Y26: ='23'!$F$28 -> 7.1914131 | Z26: ='23'!$F$29 -> 4.8182223 | AA26: ='23'!$F$30 -> 7.0699401 | AB26: ='23'!$F$31 | AC26: ='23'!$F$32 | AD26: ='23'!$F$33 -> 6.3100891
A27: Laredo | B27: ='24'!$F$5 | C27: ='24'!$F$6 -> 4.8604269 | D27: ='24'!$F$7 -> 9.0317849 | E27: ='24'!$F$8 -> 11.590372 | F27: ='24'!$F$9 | G27: ='24'!$F$10 -> 46.621408 | H27: ='24'!$F$11 -> 12.264061 | I27: ='24'!$F$12 -> 32.941637 | J27: ='24'!$F$13 -> 4.8604269 | K27: ='24'!$F$14 | L27: ='24'!$F$15 -> 4.8604269 | M27: ='24'!$F$16 -> 9.9950895 | N27: ='24'!$F$17 -> 37.064594 | O27: ='24'!$F$18 -> 15.747452 | P27: ='24'!$F$19 | Q27: ='24'!$F$20 -> 10.976809 | R27: ='24'!$F$21 | S27: ='24'!$F$22 -> 13.978552 | T27: ='24'!$F$23 -> 8.5425702 | U27: ='24'!$F$24 -> 17.820155 | V27: ='24'!$F$25 -> 4.8604269 | W27: ='24'!$F$26 -> 16.945557 | X27: ='24'!$F$27 -> 9.7791978 | Y27: ='24'!$F$28 -> 8.5681104 | Z27: ='24'!$F$29 -> 7.3194094 | AA27: ='24'!$F$30 -> 12.008796 | AB27: ='24'!$F$31 | AC27: ='24'!$F$32 | AD27: ='24'!$F$33 -> 10.006486
A28: Lee | B28: ='25'!$F$5 -> 6.5150615 | C28: ='25'!$F$6 -> 13.296722 | D28: ='25'!$F$7 -> 8.5895474 | E28: ='25'!$F$8 -> 8.3021555 | F28: ='25'!$F$9 -> 13.122999 | G28: ='25'!$F$10 -> 10.827348 | H28: ='25'!$F$11 -> 11.809821 | I28: ='25'!$F$12 -> 13.154391 | J28: ='25'!$F$13 -> 7.6909453 | K28: ='25'!$F$14 | L28: ='25'!$F$15 -> 7.5861246 | M28: ='25'!$F$16 -> 11.660686 | N28: ='25'!$F$17 -> 8.5471707 | O28: ='25'!$F$18 -> 11.974481 | P28: ='25'!$F$19 | Q28: ='25'!$F$20 -> 21.588573 | R28: ='25'!$F$21 | S28: ='25'!$F$22 -> 13.159051 | T28: ='25'!$F$23 -> 9.8617939 | U28: ='25'!$F$24 -> 5.3690544 | V28: ='25'!$F$25 -> 5.0794045 | W28: ='25'!$F$26 -> 8.8564963 | X28: ='25'!$F$27 -> 17.06585 | Y28: ='25'!$F$28 -> 6.9136482 | Z28: ='25'!$F$29 -> 8.4198523 | AA28: ='25'!$F$30 -> 10.893075 | AB28: ='25'!$F$31 | AC28: ='25'!$F$32 | AD28: ='25'!$F$33 -> 9.821547
A29: Lonestar | B29: ='26'!$F$5 -> 7.7134447 | C29: ='26'!$F$6 -> 9.9564979 | D29: ='26'!$F$7 -> 8.5145243 | E29: ='26'!$F$8 -> 8.8563079 | F29: ='26'!$F$9 | G29: ='26'!$F$10 -> 6.2883745 | H29: ='26'!$F$11 -> 8.9180766 | I29: ='26'!$F$12 -> 9.5928889 | J29: ='26'!$F$13 -> 7.7949436 | K29: ='26'!$F$14 -> 11.179744 | L29: ='26'!$F$15 -> 10.280072 | M29: ='26'!$F$16 -> 9.2692435 | N29: ='26'!$F$17 -> 8.2476344 | O29: ='26'!$F$18 -> 13.399958 | P29: ='26'!$F$19 -> 24.630547 | Q29: ='26'!$F$20 -> 11.436342 | R29: ='26'!$F$21 -> 13.665918 | S29: ='26'!$F$22 -> 10.4484 | T29: ='26'!$F$23 -> 8.1846372 | U29: ='26'!$F$24 -> 10.765871 | V29: ='26'!$F$25 -> 20.076787 | W29: ='26'!$F$26 -> 9.6555888 | X29: ='26'!$F$27 -> 9.8459951 | Y29: ='26'!$F$28 -> 8.370463 | Z29: ='26'!$F$29 -> 8.0508206 | AA29: ='26'!$F$30 -> 11.265285 | AB29: ='26'!$F$31 | AC29: ='26'!$F$32 | AD29: ='26'!$F$33 -> 9.0428653
A30: Mclennan | B30: ='27'!$F$5 -> 19.57065 | C30: ='27'!$F$6 | D30: ='27'!$F$7 -> 7.1958456 | E30: ='27'!$F$8 -> 8.6889837 | F30: ='27'!$F$9 | G30: ='27'!$F$10 -> 4.4804666 | H30: ='27'!$F$11 -> 14.144782 | I30: ='27'!$F$12 | J30: ='27'!$F$13 -> 11.933381 | K30: ='27'!$F$14 -> 4.13433 | L30: ='27'!$F$15 -> 5.1270182 | M30: ='27'!$F$16 -> 9.259157 | N30: ='27'!$F$17 -> 7.4724001 | O30: ='27'!$F$18 -> 14.077367 | P30: ='27'!$F$19 | Q30: ='27'!$F$20 -> 9.4475851 | R30: ='27'!$F$21 -> 10.660119 | S30: ='27'!$F$22 -> 9.7085887 | T30: ='27'!$F$23 -> 8.0724652 | U30: ='27'!$F$24 | V30: ='27'!$F$25 -> 4.8658262 | W30: ='27'!$F$26 -> 4.1339904 | X30: ='27'!$F$27 -> 11.360024 | Y30: ='27'!$F$28 -> 8.0652051 | Z30: ='27'!$F$29 -> 7.0317389 | AA30: ='27'!$F$30 -> 11.432698 | AB30: ='27'!$F$31 | AC30: ='27'!$F$32 | AD30: ='27'!$F$33 -> 9.1835904
A31: Midland | B31: ='28'!$F$5 -> 11.751039 | C31: ='28'!$F$6 -> 10.447105 | D31: ='28'!$F$7 -> 8.5459247 | E31: ='28'!$F$8 -> 9.5097997 | F31: ='28'!$F$9 -> 56.354169 | G31: ='28'!$F$10 -> 15.708817 | H31: ='28'!$F$11 -> 18.604414 | I31: ='28'!$F$12 -> 12.224132 | J31: ='28'!$F$13 -> 8.2570613 | K31: ='28'!$F$14 -> 12.224315 | L31: ='28'!$F$15 -> 22.970868 | M31: ='28'!$F$16 -> 10.057296 | N31: ='28'!$F$17 -> 6.1555479 | O31: ='28'!$F$18 -> 11.369432 | P31: ='28'!$F$19 | Q31: ='28'!$F$20 -> 10.998096 | R31: ='28'!$F$21 -> 11.136654 | S31: ='28'!$F$22 -> 10.567138 | T31: ='28'!$F$23 -> 9.4004353 | U31: ='28'!$F$24 -> 12.622044 | V31: ='28'!$F$25 -> 20.467673 | W31: ='28'!$F$26 -> 16.787769 | X31: ='28'!$F$27 -> 11.086924 | Y31: ='28'!$F$28 -> 11.624163 | Z31: ='28'!$F$29 -> 8.4185209 | AA31: ='28'!$F$30 -> 10.499586 | AB31: ='28'!$F$31 | AC31: ='28'!$F$32 | AD31: ='28'!$F$33 -> 10.259887
A32: Navarro | B32: ='29'!$F$5 -> 4.4052562 | C32: ='29'!$F$6 -> 3.6355182 | D32: ='29'!$F$7 -> 4.8736893 | E32: ='29'!$F$8 -> 5.0977139 | F32: ='29'!$F$9 | G32: ='29'!$F$10 -> 9.0342118 | H32: ='29'!$F$11 -> 3.9061387 | I32: ='29'!$F$12 -> 3.0909939 | J32: ='29'!$F$13 -> 3.0239477 | K32: ='29'!$F$14 -> 27.880767 | L32: ='29'!$F$15 -> 4.2812889 | M32: ='29'!$F$16 -> 4.8428438 | N32: ='29'!$F$17 -> 3.9426749 | O32: ='29'!$F$18 -> 9.2492198 | P32: ='29'!$F$19 | Q32: ='29'!$F$20 -> 4.7134093 | R32: ='29'!$F$21 | S32: ='29'!$F$22 -> 7.043702 | T32: ='29'!$F$23 -> 4.8481751 | U32: ='29'!$F$24 | V32: ='29'!$F$25 -> 7.6898541 | W32: ='29'!$F$26 -> 2.5907998 | X32: ='29'!$F$27 -> 5.4138395 | Y32: ='29'!$F$28 -> 4.6277458 | Z32: ='29'!$F$29 -> 4.8070763 | AA32: ='29'!$F$30 -> 5.8691715 | AB32: ='29'!$F$31 | AC32: ='29'!$F$32 | AD32: ='29'!$F$33 -> 4.8550314
A33: North Central Texas | B33: ='30'!$F$5 -> 9.4428956 | C33: ='30'!$F$6 -> 15.918096 | D33: ='30'!$F$7 -> 5.3461661 | E33: ='30'!$F$8 -> 4.0754412 | F33: ='30'!$F$9 | G33: ='30'!$F$10 -> 2.7103647 | H33: ='30'!$F$11 -> 45.815292 | I33: ='30'!$F$12 | J33: ='30'!$F$13 -> 6.0421247 | K33: ='30'!$F$14 | L33: ='30'!$F$15 -> 3.5047304 | M33: ='30'!$F$16 -> 5.8303439 | N33: ='30'!$F$17 -> 4.2004657 | O33: ='30'!$F$18 -> 8.2842734 | P33: ='30'!$F$19 | Q33: ='30'!$F$20 -> 7.2686052 | R33: ='30'!$F$21 | S33: ='30'!$F$22 -> 5.8519113 | T33: ='30'!$F$23 -> 4.8874102 | U33: ='30'!$F$24 | V33: ='30'!$F$25 -> 18.157334 | W33: ='30'!$F$26 -> 18.688033 | X33: ='30'!$F$27 -> 6.5441834 | Y33: ='30'!$F$28 -> 6.578324 | Z33: ='30'!$F$29 -> 4.63345 | AA33: ='30'!$F$30 -> 6.5850482 | AB33: ='30'!$F$31 | AC33: ='30'!$F$32 | AD33: ='30'!$F$33 -> 5.8965891
A34: Northeast Texas | B34: ='31'!$F$5 -> 20.385866 | C34: ='31'!$F$6 -> 6.2137341 | D34: ='31'!$F$7 -> 7.5843059 | E34: ='31'!$F$8 -> 6.8301798 | F34: ='31'!$F$9 | G34: ='31'!$F$10 -> 7.8591085 | H34: ='31'!$F$11 -> 16.737141 | I34: ='31'!$F$12 -> 3.9162287 | J34: ='31'!$F$13 -> 6.1142147 | K34: ='31'!$F$14 | L34: ='31'!$F$15 -> 3.2432249 | M34: ='31'!$F$16 -> 6.0978209 | N34: ='31'!$F$17 -> 12.892973 | O34: ='31'!$F$18 -> 12.441144 | P34: ='31'!$F$19 -> 16.178456 | Q34: ='31'!$F$20 -> 9.1426199 | R34: ='31'!$F$21 | S34: ='31'!$F$22 -> 10.093203 | T34: ='31'!$F$23 -> 7.4010594 | U34: ='31'!$F$24 -> 18.799433 | V34: ='31'!$F$25 -> 28.282114 | W34: ='31'!$F$26 -> 3.2432249 | X34: ='31'!$F$27 -> 6.5276187 | Y34: ='31'!$F$28 -> 8.9216551 | Z34: ='31'!$F$29 -> 6.2182426 | AA34: ='31'!$F$30 -> 10.51268 | AB34: ='31'!$F$31 | AC34: ='31'!$F$32 | AD34: ='31'!$F$33 -> 7.9638673
A35: Odessa | B35: ='32'!$F$5 -> 12.498638 | C35: ='32'!$F$6 -> 7.5442876 | D35: ='32'!$F$7 -> 8.7714862 | E35: ='32'!$F$8 -> 10.283215 | F35: ='32'!$F$9 | G35: ='32'!$F$10 -> 5.7581792 | H35: ='32'!$F$11 -> 11.20881 | I35: ='32'!$F$12 -> 5.4369894 | J35: ='32'!$F$13 -> 9.5969757 | K35: ='32'!$F$14 | L35: ='32'!$F$15 -> 8.8056515 | M35: ='32'!$F$16 -> 9.550645 | N35: ='32'!$F$17 -> 10.228937 | O35: ='32'!$F$18 -> 11.593647 | P35: ='32'!$F$19 | Q35: ='32'!$F$20 -> 12.163211 | R35: ='32'!$F$21 | S35: ='32'!$F$22 -> 10.556769 | T35: ='32'!$F$23 -> 9.3234961 | U35: ='32'!$F$24 -> 10.14441 | V35: ='32'!$F$25 -> 15.067998 | W35: ='32'!$F$26 -> 9.9823519 | X35: ='32'!$F$27 -> 10.759446 | Y35: ='32'!$F$28 -> 11.043071 | Z35: ='32'!$F$29 -> 8.7108221 | AA35: ='32'!$F$30 -> 11.287246 | AB35: ='32'!$F$31 | AC35: ='32'!$F$32 | AD35: ='32'!$F$33 -> 9.876891
A36: Panola | B36: ='33'!$F$5 -> 6.8482311 | C36: ='33'!$F$6 -> 10.667412 | D36: ='33'!$F$7 -> 8.6049741 | E36: ='33'!$F$8 -> 8.5226668 | F36: ='33'!$F$9 | G36: ='33'!$F$10 -> 14.11534 | H36: ='33'!$F$11 -> 16.257305 | I36: ='33'!$F$12 -> 30.563153 | J36: ='33'!$F$13 -> 7.6300123 | K36: ='33'!$F$14 | L36: ='33'!$F$15 -> 11.466413 | M36: ='33'!$F$16 -> 8.4808513 | N36: ='33'!$F$17 -> 11.80611 | O36: ='33'!$F$18 -> 11.106546 | P36: ='33'!$F$19 | Q36: ='33'!$F$20 -> 9.8587208 | R36: ='33'!$F$21 | S36: ='33'!$F$22 -> 8.438679 | T36: ='33'!$F$23 -> 11.055967 | U36: ='33'!$F$24 | V36: ='33'!$F$25 -> 13.123721 | W36: ='33'!$F$26 -> 13.125797 | X36: ='33'!$F$27 -> 10.016527 | Y36: ='33'!$F$28 -> 8.1624002 | Z36: ='33'!$F$29 -> 7.5322617 | AA36: ='33'!$F$30 -> 10.265722 | AB36: ='33'!$F$31 | AC36: ='33'!$F$32 | AD36: ='33'!$F$33 -> 9.5473743
A37: Paris | B37: ='34'!$F$5 -> 11.80778 | C37: ='34'!$F$6 -> 6.4165052 | D37: ='34'!$F$7 -> 4.1966374 | E37: ='34'!$F$8 -> 4.925964 | F37: ='34'!$F$9 | G37: ='34'!$F$10 -> 6.5579111 | H37: ='34'!$F$11 -> 5.2139374 | I37: ='34'!$F$12 -> 4.9842829 | J37: ='34'!$F$13 -> 4.2062521 | K37: ='34'!$F$14 | L37: ='34'!$F$15 -> 4.7571779 | M37: ='34'!$F$16 -> 4.8829156 | N37: ='34'!$F$17 -> 4.9155923 | O37: ='34'!$F$18 -> 10.322751 | P37: ='34'!$F$19 | Q37: ='34'!$F$20 -> 7.1936335 | R37: ='34'!$F$21 | S37: ='34'!$F$22 -> 8.1668483 | T37: ='34'!$F$23 -> 4.0650701 | U37: ='34'!$F$24 | V37: ='34'!$F$25 -> 6.9154212 | W37: ='34'!$F$26 -> 6.7198657 | X37: ='34'!$F$27 -> 5.8543478 | Y37: ='34'!$F$28 -> 4.7662597 | Z37: ='34'!$F$29 -> 4.7796827 | AA37: ='34'!$F$30 -> 6.2983893 | AB37: ='34'!$F$31 | AC37: ='34'!$F$32 | AD37: ='34'!$F$33 -> 5.2325053
A38: Ranger | B38: ='35'!$F$5 -> 9.5295718 | C38: ='35'!$F$6 -> 5.5988156 | D38: ='35'!$F$7 -> 5.4565997 | E38: ='35'!$F$8 -> 8.5030207 | F38: ='35'!$F$9 | G38: ='35'!$F$10 | H38: ='35'!$F$11 -> 5.7573267 | I38: ='35'!$F$12 | J38: ='35'!$F$13 -> 5.6104362 | K38: ='35'!$F$14 | L38: ='35'!$F$15 | M38: ='35'!$F$16 -> 6.3586302 | N38: ='35'!$F$17 | O38: ='35'!$F$18 | P38: ='35'!$F$19 | Q38: ='35'!$F$20 -> 6.2541673 | R38: ='35'!$F$21 | S38: ='35'!$F$22 -> 5.6678692 | T38: ='35'!$F$23 -> 6.6380516 | U38: ='35'!$F$24 | V38: ='35'!$F$25 | W38: ='35'!$F$26 -> 15.279839 | X38: ='35'!$F$27 -> 16.339343 | Y38: ='35'!$F$28 | Z38: ='35'!$F$29 -> 5.1335304 | AA38: ='35'!$F$30 -> 8.622799 | AB38: ='35'!$F$31 | AC38: ='35'!$F$32 | AD38: ='35'!$F$33 -> 6.692547
A39: San Jacinto | B39: ='36'!$F$5 -> 6.2234127 | C39: ='36'!$F$6 -> 7.1857919 | D39: ='36'!$F$7 -> 6.9344729 | E39: ='36'!$F$8 -> 7.1827576 | F39: ='36'!$F$9 -> 27.828345 | G39: ='36'!$F$10 -> 6.6998457 | H39: ='36'!$F$11 -> 10.988779 | I39: ='36'!$F$12 -> 13.586631 | J39: ='36'!$F$13 -> 7.9443031 | K39: ='36'!$F$14 -> 10.113149 | L39: ='36'!$F$15 -> 10.677431 | M39: ='36'!$F$16 -> 7.1640733 | N39: ='36'!$F$17 -> 7.7477582 | O39: ='36'!$F$18 -> 10.773094 | P39: ='36'!$F$19 | Q39: ='36'!$F$20 -> 10.692494 | R39: ='36'!$F$21 -> 10.420676 | S39: ='36'!$F$22 -> 11.306878 | T39: ='36'!$F$23 -> 7.4212012 | U39: ='36'!$F$24 -> 10.181733 | V39: ='36'!$F$25 -> 13.534282 | W39: ='36'!$F$26 -> 8.6333935 | X39: ='36'!$F$27 -> 8.3777158 | Y39: ='36'!$F$28 -> 10.210569 | Z39: ='36'!$F$29 -> 7.1759507 | AA39: ='36'!$F$30 -> 9.5083222 | AB39: ='36'!$F$31 | AC39: ='36'!$F$32 | AD39: ='36'!$F$33 -> 8.2112624
A40: South Plains | B40: ='37'!$F$5 -> 14.089905 | C40: ='37'!$F$6 -> 6.3468567 | D40: ='37'!$F$7 -> 5.7317683 | E40: ='37'!$F$8 -> 6.3595983 | F40: ='37'!$F$9 -> 4.9855256 | G40: ='37'!$F$10 -> 5.4908554 | H40: ='37'!$F$11 -> 6.8326313 | I40: ='37'!$F$12 -> 10.177973 | J40: ='37'!$F$13 -> 5.7200797 | K40: ='37'!$F$14 -> 45.788236 | L40: ='37'!$F$15 -> 7.3147536 | M40: ='37'!$F$16 -> 6.5008245 | N40: ='37'!$F$17 -> 5.6155453 | O40: ='37'!$F$18 -> 6.5513722 | P40: ='37'!$F$19 | Q40: ='37'!$F$20 -> 8.9761028 | R40: ='37'!$F$21 -> 8.495444 | S40: ='37'!$F$22 -> 6.2515868 | T40: ='37'!$F$23 -> 5.3358092 | U40: ='37'!$F$24 -> 6.47327 | V40: ='37'!$F$25 -> 6.0163193 | W40: ='37'!$F$26 -> 19.442521 | X40: ='37'!$F$27 -> 11.043951 | Y40: ='37'!$F$28 -> 3.8530066 | Z40: ='37'!$F$29 -> 5.4109881 | AA40: ='37'!$F$30 -> 10.489288 | AB40: ='37'!$F$31 | AC40: ='37'!$F$32 | AD40: ='37'!$F$33 -> 6.4250799
...

Sheet Discipline Analysis
A1: =Summary!A1 -> Community and Technical Colleges, Report of Fundable Operating Expenses, Fiscal Year (FY) 2009
A2: Discipline Analysis by Institution | X2: Discipline
A3: 29 | X3: Agriculture
X4: Architecture and Precision Production Trades
A5: Institution | B5: Contact Hours | C5: Total | E5: Faculty Salaries | G5: Academic Support | I5: Institutional Support | K5: Student Services | M5: Departmental Operating Expense | O5: Research | Q5: Scholarships and Fellowships | S5: Equipment Depreciation | U5: Local Benefits | X5: Biology, Physical Sciences, and Science Technology
C6: Expense | D6: per Hour | E6: Expense | F6: per Hour | G6: Expense | H6: per Hour | I6: Expense | J6: per Hour | K6: Expense | L6: per Hour | M6: Expense | N6: per Hour | O6: Expense | P6: per Hour | Q6: Expense | R6: per Hour | S6: Expense | T6: per Hour | U6: Expense | V6: per Hour | X6: Business Management, Marketing, and Administrative Services
A7: Alamo | B7: =OFFSET('1'!$D$4,$A$3,0) -> 21475760 | C7: =OFFSET('1'!$E$4,$A$3,0) -> 2.0866447e+08 | D7: =IFERROR(C7/$B7,"") -> 9.7162787 | E7: =OFFSET('1'!$E$66,$A$3,0) -> 77393596 | F7: =IFERROR(E7/$B7,"") -> 3.6037652 | G7: ='1'!$F$100*B7 -> 20629575 | H7: =IFERROR(G7/$B7,"") -> 0.96059813 | I7: ='1'!$F$98*'Discipline Analysis'!B7 -> 41105949 | J7: =IFERROR(I7/$B7,"") -> 1.9140626 | K7: ='1'!$F$99*'Discipline Analysis'!B7 -> 22112733 | L7: =IFERROR(K7/$B7,"") -> 1.0296601 | M7: =OFFSET('1'!$E$35,$A$3,0) -> 34855466 | N7: =IFERROR(M7/$B7,"") -> 1.6230143 | O7: ='1'!$F$101*'Discipline Analysis'!B7 -> 0 | P7: =IFERROR(O7/$B7,"") -> 0 | Q7: ='1'!$F$102*'Discipline Analysis'!B7 -> 509820 | R7: =IFERROR(Q7/$B7,"") -> 0.023739323 | S7: ='1'!$F$103*'Discipline Analysis'!B7 -> 3850832 | T7: =IFERROR(S7/$B7,"") -> 0.17931063 | U7: ='1'!$F$104*'Discipline Analysis'!B7 -> 8206499 | V7: =IFERROR(U7/$B7,"") -> 0.38212846 | X7: Career Pilot
A8: Alvin | B8: =OFFSET('2'!$D$4,$A$3,0) -> 2273527 | C8: =OFFSET('2'!$E$4,$A$3,0) -> 21650677 | D8: =IFERROR(C8/$B8,"") -> 9.5229469 | E8: =OFFSET('2'!$E$66,$A$3,0) -> 10862327 | F8: =IFERROR(E8/$B8,"") -> 4.7777427 | G8: ='2'!$F$100*B8 -> 2612791 | H8: =IFERROR(G8/$B8,"") -> 1.1492237 | I8: ='2'!$F$98*'Discipline Analysis'!B8 -> 3176221 | J8: =IFERROR(I8/$B8,"") -> 1.3970456 | K8: ='2'!$F$99*'Discipline Analysis'!B8 -> 1824302 | L8: =IFERROR(K8/$B8,"") -> 0.80241053 | M8: =OFFSET('2'!$E$35,$A$3,0) -> 2537931 | N8: =IFERROR(M8/$B8,"") -> 1.1162968 | O8: ='2'!$F$101*'Discipline Analysis'!B8 -> 0 | P8: =IFERROR(O8/$B8,"") -> 0 | Q8: ='2'!$F$102*'Discipline Analysis'!B8 -> 0 | R8: =IFERROR(Q8/$B8,"") -> 0 | S8: ='2'!$F$103*'Discipline Analysis'!B8 -> 350670 | T8: =IFERROR(S8/$B8,"") -> 0.15424053 | U8: ='2'!$F$104*'Discipline Analysis'!B8 -> 286435 | V8: =IFERROR(U8/$B8,"") -> 0.12598707 | X8: Communications
A9: Amarillo | B9: =OFFSET('3'!$D$4,$A$3,0) -> 4629260 | C9: =OFFSET('3'!$E$4,$A$3,0) -> 37778402 | D9: =IFERROR(C9/$B9,"") -> 8.1607864 | E9: =OFFSET('3'!$E$66,$A$3,0) -> 14157756 | F9: =IFERROR(E9/$B9,"") -> 3.0583195 | G9: ='3'!$F$100*B9 -> 2743581 | H9: =IFERROR(G9/$B9,"") -> 0.59266081 | I9: ='3'!$F$98*'Discipline Analysis'!B9 -> 8889447 | J9: =IFERROR(I9/$B9,"") -> 1.9202739 | K9: ='3'!$F$99*'Discipline Analysis'!B9 -> 2938366 | L9: =IFERROR(K9/$B9,"") -> 0.63473773 | M9: =OFFSET('3'!$E$35,$A$3,0) -> 6481338 | N9: =IFERROR(M9/$B9,"") -> 1.4000808 | O9: ='3'!$F$101*'Discipline Analysis'!B9 -> 0 | P9: =IFERROR(O9/$B9,"") -> 0 | Q9: ='3'!$F$102*'Discipline Analysis'!B9 -> 0 | R9: =IFERROR(Q9/$B9,"") -> 0 | S9: ='3'!$F$103*'Discipline Analysis'!B9 -> 875149 | T9: =IFERROR(S9/$B9,"") -> 0.18904728 | U9: ='3'!$F$104*'Discipline Analysis'!B9 -> 1692765 | V9: =IFERROR(U9/$B9,"") -> 0.36566643 | X9: Computer and Information Sciences
A10: Angelina | B10: =OFFSET('4'!$D$4,$A$3,0) -> 2199497 | C10: =OFFSET('4'!$E$4,$A$3,0) -> 14259157 | D10: =IFERROR(C10/$B10,"") -> 6.4829172 | E10: =OFFSET('4'!$E$66,$A$3,0) -> 7703398 | F10: =IFERROR(E10/$B10,"") -> 3.5023453 | G10: ='4'!$F$100*B10 -> 1819097 | H10: =IFERROR(G10/$B10,"") -> 0.82705137 | I10: ='4'!$F$98*'Discipline Analysis'!B10 -> 2051976 | J10: =IFERROR(I10/$B10,"") -> 0.93292967 | K10: ='4'!$F$99*'Discipline Analysis'!B10 -> 981246 | L10: =IFERROR(K10/$B10,"") -> 0.44612291 | M10: =OFFSET('4'!$E$35,$A$3,0) -> 1245818 | N10: =IFERROR(M10/$B10,"") -> 0.56641041 | O10: ='4'!$F$101*'Discipline Analysis'!B10 -> 0 | P10: =IFERROR(O10/$B10,"") -> 0 | Q10: ='4'!$F$102*'Discipline Analysis'!B10 -> 0 | R10: =IFERROR(Q10/$B10,"") -> 0 | S10: ='4'!$F$103*'Discipline Analysis'!B10 -> 301027 | T10: =IFERROR(S10/$B10,"") -> 0.13686175 | U10: ='4'!$F$104*'Discipline Analysis'!B10 -> 156595 | V10: =IFERROR(U10/$B10,"") -> 0.071195823 | X10: Construction Trades
A11: Austin | B11: =OFFSET('5'!$D$4,$A$3,0) -> 13977483 | C11: =OFFSET('5'!$E$4,$A$3,0) -> 1.5176977e+08 | D11: =IFERROR(C11/$B11,"") -> 10.858162 | E11: =OFFSET('5'!$E$66,$A$3,0) -> 66503577 | F11: =IFERROR(E11/$B11,"") -> 4.7579079 | G11: ='5'!$F$100*B11 -> 18485769 | H11: =IFERROR(G11/$B11,"") -> 1.3225392 | I11: ='5'!$F$98*'Discipline Analysis'!B11 -> 26906537 | J11: =IFERROR(I11/$B11,"") -> 1.9249916 | K11: ='5'!$F$99*'Discipline Analysis'!B11 -> 17053869 | L11: =IFERROR(K11/$B11,"") -> 1.2200958 | M11: =OFFSET('5'!$E$35,$A$3,0) -> 16825020 | N11: =IFERROR(M11/$B11,"") -> 1.2037232 | O11: ='5'!$F$101*'Discipline Analysis'!B11 -> 0 | P11: =IFERROR(O11/$B11,"") -> 0 | Q11: ='5'!$F$102*'Discipline Analysis'!B11 -> 0 | R11: =IFERROR(Q11/$B11,"") -> 0 | S11: ='5'!$F$103*'Discipline Analysis'!B11 -> 2282609 | T11: =IFERROR(S11/$B11,"") -> 0.16330615 | U11: ='5'!$F$104*'Discipline Analysis'!B11 -> 3712390 | V11: =IFERROR(U11/$B11,"") -> 0.26559789 | X11: Consumer and Homemaking Education
A12: Blinn | B12: =OFFSET('6'!$D$4,$A$3,0) -> 6960349 | C12: =OFFSET('6'!$E$4,$A$3,0) -> 42057632 | D12: =IFERROR(C12/$B12,"") -> 6.0424602 | E12: =OFFSET('6'!$E$66,$A$3,0) -> 20715696 | F12: =IFERROR(E12/$B12,"") -> 2.9762439 | G12: ='6'!$F$100*B12 -> 3129156 | H12: =IFERROR(G12/$B12,"") -> 0.44956884 | I12: ='6'!$F$98*'Discipline Analysis'!B12 -> 6088267 | J12: =IFERROR(I12/$B12,"") -> 0.87470714 | K12: ='6'!$F$99*'Discipline Analysis'!B12 -> 3887200 | L12: =IFERROR(K12/$B12,"") -> 0.55847774 | M12: =OFFSET('6'!$E$35,$A$3,0) -> 6729802 | N12: =IFERROR(M12/$B12,"") -> 0.96687709 | O12: ='6'!$F$101*'Discipline Analysis'!B12 -> 0 | P12: =IFERROR(O12/$B12,"") -> 0 | Q12: ='6'!$F$102*'Discipline Analysis'!B12 -> 510820 | R12: =IFERROR(Q12/$B12,"") -> 0.073389998 | S12: ='6'!$F$103*'Discipline Analysis'!B12 -> 325793 | T12: =IFERROR(S12/$B12,"") -> 0.046806992 | U12: ='6'!$F$104*'Discipline Analysis'!B12 -> 670898 | V12: =IFERROR(U12/$B12,"") -> 0.096388558 | X12: Engineering
