Workbook

Sheet Sheet1
A2: LE Hight Upper | B2: 0.035 | D2: x | E2: upper y | F2: lower y | G2: LE adjust upper x | H2: LE adj upper Y | I2: LE adjust Lower x | J2: LE adj lower Y | K2: T adjust upper X | L2: T adj upper Y | M2: T adj lower x | N2: T adj lower Y | O2: C of T adj Upper X | P2: C of T asj upper Y | Q2: C of T adj lower X | R2: C of T adj lower Y | S2: AoA x upper | T2: AoA y upper | U2: AoA x lower | V2: AoA y lower
A3: Le hight lower | B3: 0.035 | D3: 0 | E3: 0.035 | F3: 0.035 | G3: =D3 -> 0 | H3: =E3+(($B$2-$E$3)*(1-D3)) -> 0.035 | I3: =D3*(1-$B$4)+$B$4 -> 0 | J3: =F3*$B$2/$E$3 -> 0.035 | K3: =G3 -> 0 | L3: =(H3-($H$3*(1-D3)))*($B$5-(0.7*$H$3))/($H$11-(0.7*$H$3))+($H$3*(1-D3)) -> 0.035 | M3: =I3 -> 0 | N3: =J3 -> 0.035 | O3: =D3*$B$6/0.3 -> 0 | P3: =L3 -> 0.035 | Q3: =(M3-$B$4)*($B$6-$B$4)/($M$11-$B$4)+$B$4 -> 0 | R3: =N3 -> 0.035 | S3: =(O3*COS($B$8))-(P3*SIN($B$8)) -> 0 | T3: =(O3*SIN($B$8))+(P3*COS($B$8)) -> 0.035 | U3: =(Q3*COS($B$8))-(R3*SIN($B$8)) -> 0 | V3: =(Q3*SIN($B$8))+(R3*COS($B$8)) -> 0.035
A4: LE x Lower | B4: 0 | D4: 0.0125 | E4: 0.0545 | F4: 0.0193 | G4: =D4 -> 0.0125 | H4: =E4+(($B$2-$E$3)*(1-D4)) -> 0.0545 | I4: =D4*(1-$B$4)+$B$4 -> 0.0125 | J4: =F4*$B$2/$E$3 -> 0.0193 | K4: =G4 -> 0.0125 | L4: =(H4-($H$3*(1-D4)))*($B$5-(0.7*$H$3))/($H$11-(0.7*$H$3))+($H$3*(1-D4)) -> 0.0545 | M4: =I4 -> 0.0125 | N4: =J4 -> 0.0193 | O4: =D4*$B$6/0.3 -> 0.0125 | P4: =L4 -> 0.0545 | Q4: =(M4-$B$4)*($B$6-$B$4)/($M$11-$B$4)+$B$4 -> 0.0125 | R4: =N4 -> 0.0193 | S4: =(O4*COS($B$8))-(P4*SIN($B$8)) -> 0.0125 | T4: =(O4*SIN($B$8))+(P4*COS($B$8)) -> 0.0545 | U4: =(Q4*COS($B$8))-(R4*SIN($B$8)) -> 0.0125 | V4: =(Q4*SIN($B$8))+(R4*COS($B$8)) -> 0.0193
A5: Thickness | B5: 0.117 | D5: 0.025 | E5: 0.065 | F5: 0.0147 | G5: =D5 -> 0.025 | H5: =E5+(($B$2-$E$3)*(1-D5)) -> 0.065 | I5: =D5*(1-$B$4)+$B$4 -> 0.025 | J5: =F5*$B$2/$E$3 -> 0.0147 | K5: =G5 -> 0.025 | L5: =(H5-($H$3*(1-D5)))*($B$5-(0.7*$H$3))/($H$11-(0.7*$H$3))+($H$3*(1-D5)) -> 0.065 | M5: =I5 -> 0.025 | N5: =J5 -> 0.0147 | O5: =D5*$B$6/0.3 -> 0.025 | P5: =L5 -> 0.065 | Q5: =(M5-$B$4)*($B$6-$B$4)/($M$11-$B$4)+$B$4 -> 0.025 | R5: =N5 -> 0.0147 | S5: =(O5*COS($B$8))-(P5*SIN($B$8)) -> 0.025 | T5: =(O5*SIN($B$8))+(P5*COS($B$8)) -> 0.065 | U5: =(Q5*COS($B$8))-(R5*SIN($B$8)) -> 0.025 | V5: =(Q5*SIN($B$8))+(R5*COS($B$8)) -> 0.0147
A6: C of Thickness | B6: 0.3 | D6: 0.05 | E6: 0.079 | F6: 0.0093 | G6: =D6 -> 0.05 | H6: =E6+(($B$2-$E$3)*(1-D6)) -> 0.079 | I6: =D6*(1-$B$4)+$B$4 -> 0.05 | J6: =F6*$B$2/$E$3 -> 0.0093 | K6: =G6 -> 0.05 | L6: =(H6-($H$3*(1-D6)))*($B$5-(0.7*$H$3))/($H$11-(0.7*$H$3))+($H$3*(1-D6)) -> 0.079 | M6: =I6 -> 0.05 | N6: =J6 -> 0.0093 | O6: =D6*$B$6/0.3 -> 0.05 | P6: =L6 -> 0.079 | Q6: =(M6-$B$4)*($B$6-$B$4)/($M$11-$B$4)+$B$4 -> 0.05 | R6: =N6 -> 0.0093 | S6: =(O6*COS($B$8))-(P6*SIN($B$8)) -> 0.05 | T6: =(O6*SIN($B$8))+(P6*COS($B$8)) -> 0.079 | U6: =(Q6*COS($B$8))-(R6*SIN($B$8)) -> 0.05 | V6: =(Q6*SIN($B$8))+(R6*COS($B$8)) -> 0.0093
A7: a deg | B7: 0 | D7: 0.075 | E7: 0.0885 | F7: 0.0063 | G7: =D7 -> 0.075 | H7: =E7+(($B$2-$E$3)*(1-D7)) -> 0.0885 | I7: =D7*(1-$B$4)+$B$4 -> 0.075 | J7: =F7*$B$2/$E$3 -> 0.0063 | K7: =G7 -> 0.075 | L7: =(H7-($H$3*(1-D7)))*($B$5-(0.7*$H$3))/($H$11-(0.7*$H$3))+($H$3*(1-D7)) -> 0.0885 | M7: =I7 -> 0.075 | N7: =J7 -> 0.0063 | O7: =D7*$B$6/0.3 -> 0.075 | P7: =L7 -> 0.0885 | Q7: =(M7-$B$4)*($B$6-$B$4)/($M$11-$B$4)+$B$4 -> 0.075 | R7: =N7 -> 0.0063 | S7: =(O7*COS($B$8))-(P7*SIN($B$8)) -> 0.075 | T7: =(O7*SIN($B$8))+(P7*COS($B$8)) -> 0.0885 | U7: =(Q7*COS($B$8))-(R7*SIN($B$8)) -> 0.075 | V7: =(Q7*SIN($B$8))+(R7*COS($B$8)) -> 0.0063
A8: a rad | B8: =B7/180*3.1415 -> 0 | D8: 0.1 | E8: 0.096 | F8: 0.0042 | G8: =D8 -> 0.1 | H8: =E8+(($B$2-$E$3)*(1-D8)) -> 0.096 | I8: =D8*(1-$B$4)+$B$4 -> 0.1 | J8: =F8*$B$2/$E$3 -> 0.0042 | K8: =G8 -> 0.1 | L8: =(H8-($H$3*(1-D8)))*($B$5-(0.7*$H$3))/($H$11-(0.7*$H$3))+($H$3*(1-D8)) -> 0.096 | M8: =I8 -> 0.1 | N8: =J8 -> 0.0042 | O8: =D8*$B$6/0.3 -> 0.1 | P8: =L8 -> 0.096 | Q8: =(M8-$B$4)*($B$6-$B$4)/($M$11-$B$4)+$B$4 -> 0.1 | R8: =N8 -> 0.0042 | S8: =(O8*COS($B$8))-(P8*SIN($B$8)) -> 0.1 | T8: =(O8*SIN($B$8))+(P8*COS($B$8)) -> 0.096 | U8: =(Q8*COS($B$8))-(R8*SIN($B$8)) -> 0.1 | V8: =(Q8*SIN($B$8))+(R8*COS($B$8)) -> 0.0042
A9: B unit | B9: 2.5 | D9: 0.15 | E9: 0.1069 | F9: 0.0015 | G9: =D9 -> 0.15 | H9: =E9+(($B$2-$E$3)*(1-D9)) -> 0.1069 | I9: =D9*(1-$B$4)+$B$4 -> 0.15 | J9: =F9*$B$2/$E$3 -> 0.0015 | K9: =G9 -> 0.15 | L9: =(H9-($H$3*(1-D9)))*($B$5-(0.7*$H$3))/($H$11-(0.7*$H$3))+($H$3*(1-D9)) -> 0.1069 | M9: =I9 -> 0.15 | N9: =J9 -> 0.0015 | O9: =D9*$B$6/0.3 -> 0.15 | P9: =L9 -> 0.1069 | Q9: =(M9-$B$4)*($B$6-$B$4)/($M$11-$B$4)+$B$4 -> 0.15 | R9: =N9 -> 0.0015 | S9: =(O9*COS($B$8))-(P9*SIN($B$8)) -> 0.15 | T9: =(O9*SIN($B$8))+(P9*COS($B$8)) -> 0.1069 | U9: =(Q9*COS($B$8))-(R9*SIN($B$8)) -> 0.15 | V9: =(Q9*SIN($B$8))+(R9*COS($B$8)) -> 0.0015
A10: Taper | B10: 1 | D10: 0.2 | E10: 0.1136 | F10: 0.0003 | G10: =D10 -> 0.2 | H10: =E10+(($B$2-$E$3)*(1-D10)) -> 0.1136 | I10: =D10*(1-$B$4)+$B$4 -> 0.2 | J10: =F10*$B$2/$E$3 -> 0.0003 | K10: =G10 -> 0.2 | L10: =(H10-($H$3*(1-D10)))*($B$5-(0.7*$H$3))/($H$11-(0.7*$H$3))+($H$3*(1-D10)) -> 0.1136 | M10: =I10 -> 0.2 | N10: =J10 -> 0.0003 | O10: =D10*$B$6/0.3 -> 0.2 | P10: =L10 -> 0.1136 | Q10: =(M10-$B$4)*($B$6-$B$4)/($M$11-$B$4)+$B$4 -> 0.2 | R10: =N10 -> 0.0003 | S10: =(O10*COS($B$8))-(P10*SIN($B$8)) -> 0.2 | T10: =(O10*SIN($B$8))+(P10*COS($B$8)) -> 0.1136 | U10: =(Q10*COS($B$8))-(R10*SIN($B$8)) -> 0.2 | V10: =(Q10*SIN($B$8))+(R10*COS($B$8)) -> 0.0003
A11: cells | B11: 9 | D11: 0.3 | E11: 0.117 | F11: 0 | G11: =D11 -> 0.3 | H11: =E11+(($B$2-$E$3)*(1-D11)) -> 0.117 | I11: =D11*(1-$B$4)+$B$4 -> 0.3 | J11: =F11*$B$2/$E$3 -> 0 | K11: =G11 -> 0.3 | L11: =(H11-($H$3*(1-D11)))*($B$5-(0.7*$H$3))/($H$11-(0.7*$H$3))+($H$3*(1-D11)) -> 0.117 | M11: =I11 -> 0.3 | N11: =J11 -> 0 | O11: =D11*$B$6/0.3 -> 0.3 | P11: =L11 -> 0.117 | Q11: =(M11-$B$4)*($B$6-$B$4)/($M$11-$B$4)+$B$4 -> 0.3 | R11: =N11 -> 0 | S11: =(O11*COS($B$8))-(P11*SIN($B$8)) -> 0.3 | T11: =(O11*SIN($B$8))+(P11*COS($B$8)) -> 0.117 | U11: =(Q11*COS($B$8))-(R11*SIN($B$8)) -> 0.3 | V11: =(Q11*SIN($B$8))+(R11*COS($B$8)) -> 0
A12: unit S | B12: =2*SUM(E24:I24) -> 2.5 | D12: 0.4 | E12: 0.114 | F12: 0 | G12: =D12 -> 0.4 | H12: =E12+(($B$2-$E$3)*(1-D12)) -> 0.114 | I12: =D12*(1-$B$4)+$B$4 -> 0.4 | J12: =F12*$B$2/$E$3 -> 0 | K12: =G12 -> 0.4 | L12: =(H12-($H$3*(1-D12)))*($B$5-(0.7*$H$3))/($H$11-(0.7*$H$3))+($H$3*(1-D12)) -> 0.114 | M12: =I12 -> 0.4 | N12: =J12 -> 0 | O12: =(D12-0.3)*(1-$B$6)/0.7+$B$6 -> 0.4 | P12: =L12 -> 0.114 | Q12: =(M12-$M$11)*(1-$B$6)/(1-$M$11)+$B$6 -> 0.4 | R12: =N12 -> 0 | S12: =(O12*COS($B$8))-(P12*SIN($B$8)) -> 0.4 | T12: =(O12*SIN($B$8))+(P12*COS($B$8)) -> 0.114 | U12: =(Q12*COS($B$8))-(R12*SIN($B$8)) -> 0.4 | V12: =(Q12*SIN($B$8))+(R12*COS($B$8)) -> 0
A13: S | B13: 150 | D13: 0.5 | E13: 0.1052 | F13: 0 | G13: =D13 -> 0.5 | H13: =E13+(($B$2-$E$3)*(1-D13)) -> 0.1052 | I13: =D13*(1-$B$4)+$B$4 -> 0.5 | J13: =F13*$B$2/$E$3 -> 0 | K13: =G13 -> 0.5 | L13: =(H13-($H$3*(1-D13)))*($B$5-(0.7*$H$3))/($H$11-(0.7*$H$3))+($H$3*(1-D13)) -> 0.1052 | M13: =I13 -> 0.5 | N13: =J13 -> 0 | O13: =(D13-0.3)*(1-$B$6)/0.7+$B$6 -> 0.5 | P13: =L13 -> 0.1052 | Q13: =(M13-$M$11)*(1-$B$6)/(1-$M$11)+$B$6 -> 0.5 | R13: =N13 -> 0 | S13: =(O13*COS($B$8))-(P13*SIN($B$8)) -> 0.5 | T13: =(O13*SIN($B$8))+(P13*COS($B$8)) -> 0.1052 | U13: =(Q13*COS($B$8))-(R13*SIN($B$8)) -> 0.5 | V13: =(Q13*SIN($B$8))+(R13*COS($B$8)) -> 0
A14: B | B14: =B9*SQRT(B13/B12) -> 19.364917 | D14: 0.6 | E14: 0.0915 | F14: 0 | G14: =D14 -> 0.6 | H14: =E14+(($B$2-$E$3)*(1-D14)) -> 0.0915 | I14: =D14*(1-$B$4)+$B$4 -> 0.6 | J14: =F14*$B$2/$E$3 -> 0 | K14: =G14 -> 0.6 | L14: =(H14-($H$3*(1-D14)))*($B$5-(0.7*$H$3))/($H$11-(0.7*$H$3))+($H$3*(1-D14)) -> 0.0915 | M14: =I14 -> 0.6 | N14: =J14 -> 0 | O14: =(D14-0.3)*(1-$B$6)/0.7+$B$6 -> 0.6 | P14: =L14 -> 0.0915 | Q14: =(M14-$M$11)*(1-$B$6)/(1-$M$11)+$B$6 -> 0.6 | R14: =N14 -> 0 | S14: =(O14*COS($B$8))-(P14*SIN($B$8)) -> 0.6 | T14: =(O14*SIN($B$8))+(P14*COS($B$8)) -> 0.0915 | U14: =(Q14*COS($B$8))-(R14*SIN($B$8)) -> 0.6 | V14: =(Q14*SIN($B$8))+(R14*COS($B$8)) -> 0
A15: AR | B15: =(B14^2)/B13 -> 2.5 | D15: 0.7 | E15: 0.0735 | F15: 0 | G15: =D15 -> 0.7 | H15: =E15+(($B$2-$E$3)*(1-D15)) -> 0.0735 | I15: =D15*(1-$B$4)+$B$4 -> 0.7 | J15: =F15*$B$2/$E$3 -> 0 | K15: =G15 -> 0.7 | L15: =(H15-($H$3*(1-D15)))*($B$5-(0.7*$H$3))/($H$11-(0.7*$H$3))+($H$3*(1-D15)) -> 0.0735 | M15: =I15 -> 0.7 | N15: =J15 -> 0 | O15: =(D15-0.3)*(1-$B$6)/0.7+$B$6 -> 0.7 | P15: =L15 -> 0.0735 | Q15: =(M15-$M$11)*(1-$B$6)/(1-$M$11)+$B$6 -> 0.7 | R15: =N15 -> 0 | S15: =(O15*COS($B$8))-(P15*SIN($B$8)) -> 0.7 | T15: =(O15*SIN($B$8))+(P15*COS($B$8)) -> 0.0735 | U15: =(Q15*COS($B$8))-(R15*SIN($B$8)) -> 0.7 | V15: =(Q15*SIN($B$8))+(R15*COS($B$8)) -> 0
A16: line length | B16: 20 | D16: 0.8 | E16: 0.0522 | F16: 0 | G16: =D16 -> 0.8 | H16: =E16+(($B$2-$E$3)*(1-D16)) -> 0.0522 | I16: =D16*(1-$B$4)+$B$4 -> 0.8 | J16: =F16*$B$2/$E$3 -> 0 | K16: =G16 -> 0.8 | L16: =(H16-($H$3*(1-D16)))*($B$5-(0.7*$H$3))/($H$11-(0.7*$H$3))+($H$3*(1-D16)) -> 0.0522 | M16: =I16 -> 0.8 | N16: =J16 -> 0 | O16: =(D16-0.3)*(1-$B$6)/0.7+$B$6 -> 0.8 | P16: =L16 -> 0.0522 | Q16: =(M16-$M$11)*(1-$B$6)/(1-$M$11)+$B$6 -> 0.8 | R16: =N16 -> 0 | S16: =(O16*COS($B$8))-(P16*SIN($B$8)) -> 0.8 | T16: =(O16*SIN($B$8))+(P16*COS($B$8)) -> 0.0522 | U16: =(Q16*COS($B$8))-(R16*SIN($B$8)) -> 0.8 | V16: =(Q16*SIN($B$8))+(R16*COS($B$8)) -> 0
A17: hight above stream line | B17: =SIN(B22)*B16 -> 18.973666 | D17: 0.9 | E17: 0.028 | F17: 0 | G17: =D17 -> 0.9 | H17: =E17+(($B$2-$E$3)*(1-D17)) -> 0.028 | I17: =D17*(1-$B$4)+$B$4 -> 0.9 | J17: =F17*$B$2/$E$3 -> 0 | K17: =G17 -> 0.9 | L17: =(H17-($H$3*(1-D17)))*($B$5-(0.7*$H$3))/($H$11-(0.7*$H$3))+($H$3*(1-D17)) -> 0.028 | M17: =I17 -> 0.9 | N17: =J17 -> 0 | O17: =(D17-0.3)*(1-$B$6)/0.7+$B$6 -> 0.9 | P17: =L17 -> 0.028 | Q17: =(M17-$M$11)*(1-$B$6)/(1-$M$11)+$B$6 -> 0.9 | R17: =N17 -> 0 | S17: =(O17*COS($B$8))-(P17*SIN($B$8)) -> 0.9 | T17: =(O17*SIN($B$8))+(P17*COS($B$8)) -> 0.028 | U17: =(Q17*COS($B$8))-(R17*SIN($B$8)) -> 0.9 | V17: =(Q17*SIN($B$8))+(R17*COS($B$8)) -> 0
A18: slider width | B18: 2 | D18: 0.95 | E18: 0.0149 | F18: 0 | G18: =D18 -> 0.95 | H18: =E18+(($B$2-$E$3)*(1-D18)) -> 0.0149 | I18: =D18*(1-$B$4)+$B$4 -> 0.95 | J18: =F18*$B$2/$E$3 -> 0 | K18: =G18 -> 0.95 | L18: =(H18-($H$3*(1-D18)))*($B$5-(0.7*$H$3))/($H$11-(0.7*$H$3))+($H$3*(1-D18)) -> 0.0149 | M18: =I18 -> 0.95 | N18: =J18 -> 0 | O18: =(D18-0.3)*(1-$B$6)/0.7+$B$6 -> 0.95 | P18: =L18 -> 0.0149 | Q18: =(M18-$M$11)*(1-$B$6)/(1-$M$11)+$B$6 -> 0.95 | R18: =N18 -> 0 | S18: =(O18*COS($B$8))-(P18*SIN($B$8)) -> 0.95 | T18: =(O18*SIN($B$8))+(P18*COS($B$8)) -> 0.0149 | U18: =(Q18*COS($B$8))-(R18*SIN($B$8)) -> 0.95 | V18: =(Q18*SIN($B$8))+(R18*COS($B$8)) -> 0
A19: arc | B19: =B14/B17 -> 1.0206207 | D19: 1 | E19: 0.0012 | F19: 0 | G19: =D19 -> 1 | H19: =E19+(($B$2-$E$3)*(1-D19)) -> 0.0012 | I19: =D19*(1-$B$4)+$B$4 -> 1 | J19: =F19*$B$2/$E$3 -> 0 | K19: =G19 -> 1 | L19: =(H19-($H$3*(1-D19)))*($B$5-(0.7*$H$3))/($H$11-(0.7*$H$3))+($H$3*(1-D19)) -> 0.0012 | M19: =I19 -> 1 | N19: =J19 -> 0 | O19: =(D19-0.3)*(1-$B$6)/0.7+$B$6 -> 1 | P19: =L19 -> 0.0012 | Q19: =(M19-$M$11)*(1-$B$6)/(1-$M$11)+$B$6 -> 1 | R19: =N19 -> 0 | S19: =(O19*COS($B$8))-(P19*SIN($B$8)) -> 1 | T19: =(O19*SIN($B$8))+(P19*COS($B$8)) -> 0.0012 | U19: =(Q19*COS($B$8))-(R19*SIN($B$8)) -> 1 | V19: =(Q19*SIN($B$8))+(R19*COS($B$8)) -> 0
A20: cell width | B20: =B14/9 -> 2.1516574
A21: expected glide | B21: 3
A22: theta | B22: =ATAN(B21) -> 1.2490458 | D22: Rib | E22: 1 | F22: =E22+1 -> 2 | G22: =F22+1 -> 3 | H22: =G22+1 -> 4 | I22: =H22+1 -> 5
A23: riser | B23: 1.5 | D23: cord unit | E23: =SIN(ACOS((2*E22-1)*COS(ASIN($B$10))/$B$11)) -> 1 | F23: =SIN(ACOS((2*F22-1)*COS(ASIN($B$10))/$B$11)) -> 1 | G23: =SIN(ACOS((2*G22-1)*COS(ASIN($B$10))/$B$11)) -> 1 | H23: =SIN(ACOS((2*H22-1)*COS(ASIN($B$10))/$B$11)) -> 1 | I23: =SIN(ACOS((2*I22-1)*COS(ASIN($B$10))/$B$11)) -> 1
A24: CG x | B24: =-COS(B22)*(B16+B23) -> -6.798897 | D24: s | E24: =E23*B9/18 -> 0.13888889 | F24: =(E23+F23)*$B$9/18 -> 0.27777778 | G24: =(F23+G23)*$B$9/18 -> 0.27777778 | H24: =(G23+H23)*$B$9/18 -> 0.27777778 | I24: =(H23+I23)*$B$9/18 -> 0.27777778
A25: CG y | B25: =-(SIN(B22)*B23) -> -1.4230249 | D25: cord | E25: =E23*SQRT($B$13/$B$12) -> 7.7459667 | F25: =F23*SQRT($B$13/$B$12) -> 7.7459667 | G25: =G23*SQRT($B$13/$B$12) -> 7.7459667 | H25: =H23*SQRT($B$13/$B$12) -> 7.7459667 | I25: =I23*SQRT($B$13/$B$12) -> 7.7459667

Sheet Sheet2
H1: rib 1 | L1: rib 0
A2: c 1 | B2: =Sheet1!E25 -> 7.7459667 | D2: =Sheet1!O3 -> 0 | E2: =Sheet1!P3 -> 0.035 | F2: =Sheet1!Q3 -> 0 | G2: =Sheet1!R3 -> 0.035 | H2: =D2*$B$2 -> 0 | I2: =E2*$B$2 -> 0.27110883 | J2: =F2*$B$2 -> 0 | K2: =G2*$B$2 -> 0.27110883 | L2: =D2*$B$3 -> 0 | M2: =E2*$B$3 -> 0.27110883 | N2: =F2*$B$3 -> 0 | O2: =G2*$B$3 -> 0.27110883
A3: c 0 | B3: =Sheet1!E25 -> 7.7459667 | D3: =Sheet1!O4 -> 0.0125 | E3: =Sheet1!P4 -> 0.0545 | F3: =Sheet1!Q4 -> 0.0125 | G3: =Sheet1!R4 -> 0.0193 | H3: =D3*$B$2 -> 0.096824584 | I3: =E3*$B$2 -> 0.42215518 | J3: =F3*$B$2 -> 0.096824584 | K3: =G3*$B$2 -> 0.14949716 | L3: =D3*$B$3 -> 0.096824584 | M3: =E3*$B$3 -> 0.42215518 | N3: =F3*$B$3 -> 0.096824584 | O3: =G3*$B$3 -> 0.14949716
A4: t | B4: =ATAN((Sheet1!B20-Sheet1!B18)/2/Sheet1!B17) -> 0.0039965025 | D4: =Sheet1!O5 -> 0.025 | E4: =Sheet1!P5 -> 0.065 | F4: =Sheet1!Q5 -> 0.025 | G4: =Sheet1!R5 -> 0.0147 | H4: =D4*$B$2 -> 0.19364917 | I4: =E4*$B$2 -> 0.50348784 | J4: =F4*$B$2 -> 0.19364917 | K4: =G4*$B$2 -> 0.11386571 | L4: =D4*$B$3 -> 0.19364917 | M4: =E4*$B$3 -> 0.50348784 | N4: =F4*$B$3 -> 0.19364917 | O4: =G4*$B$3 -> 0.11386571
D5: =Sheet1!O6 -> 0.05 | E5: =Sheet1!P6 -> 0.079 | F5: =Sheet1!Q6 -> 0.05 | G5: =Sheet1!R6 -> 0.0093 | H5: =D5*$B$2 -> 0.38729833 | I5: =E5*$B$2 -> 0.61193137 | J5: =F5*$B$2 -> 0.38729833 | K5: =G5*$B$2 -> 0.07203749 | L5: =D5*$B$3 -> 0.38729833 | M5: =E5*$B$3 -> 0.61193137 | N5: =F5*$B$3 -> 0.38729833 | O5: =G5*$B$3 -> 0.07203749
D6: =Sheet1!O7 -> 0.075 | E6: =Sheet1!P7 -> 0.0885 | F6: =Sheet1!Q7 -> 0.075 | G6: =Sheet1!R7 -> 0.0063 | H6: =D6*$B$2 -> 0.5809475 | I6: =E6*$B$2 -> 0.68551805 | J6: =F6*$B$2 -> 0.5809475 | K6: =G6*$B$2 -> 0.04879959 | L6: =D6*$B$3 -> 0.5809475 | M6: =E6*$B$3 -> 0.68551805 | N6: =F6*$B$3 -> 0.5809475 | O6: =G6*$B$3 -> 0.04879959
D7: =Sheet1!O8 -> 0.1 | E7: =Sheet1!P8 -> 0.096 | F7: =Sheet1!Q8 -> 0.1 | G7: =Sheet1!R8 -> 0.0042 | H7: =D7*$B$2 -> 0.77459667 | I7: =E7*$B$2 -> 0.7436128 | J7: =F7*$B$2 -> 0.77459667 | K7: =G7*$B$2 -> 0.03253306 | L7: =D7*$B$3 -> 0.77459667 | M7: =E7*$B$3 -> 0.7436128 | N7: =F7*$B$3 -> 0.77459667 | O7: =G7*$B$3 -> 0.03253306
D8: =Sheet1!O9 -> 0.15 | E8: =Sheet1!P9 -> 0.1069 | F8: =Sheet1!Q9 -> 0.15 | G8: =Sheet1!R9 -> 0.0015 | H8: =D8*$B$2 -> 1.161895 | I8: =E8*$B$2 -> 0.82804384 | J8: =F8*$B$2 -> 1.161895 | K8: =G8*$B$2 -> 0.01161895 | L8: =D8*$B$3 -> 1.161895 | M8: =E8*$B$3 -> 0.82804384 | N8: =F8*$B$3 -> 1.161895 | O8: =G8*$B$3 -> 0.01161895
D9: =Sheet1!O10 -> 0.2 | E9: =Sheet1!P10 -> 0.1136 | F9: =Sheet1!Q10 -> 0.2 | G9: =Sheet1!R10 -> 0.0003 | H9: =D9*$B$2 -> 1.5491933 | I9: =E9*$B$2 -> 0.87994182 | J9: =F9*$B$2 -> 1.5491933 | K9: =G9*$B$2 -> 0.00232379 | L9: =D9*$B$3 -> 1.5491933 | M9: =E9*$B$3 -> 0.87994182 | N9: =F9*$B$3 -> 1.5491933 | O9: =G9*$B$3 -> 0.00232379
D10: =Sheet1!O11 -> 0.3 | E10: =Sheet1!P11 -> 0.117 | F10: =Sheet1!Q11 -> 0.3 | G10: =Sheet1!R11 -> 0 | H10: =D10*$B$2 -> 2.32379 | I10: =E10*$B$2 -> 0.9062781 | J10: =F10*$B$2 -> 2.32379 | K10: =G10*$B$2 -> 0 | L10: =D10*$B$3 -> 2.32379 | M10: =E10*$B$3 -> 0.9062781 | N10: =F10*$B$3 -> 2.32379 | O10: =G10*$B$3 -> 0
D11: =Sheet1!O12 -> 0.4 | E11: =Sheet1!P12 -> 0.114 | F11: =Sheet1!Q12 -> 0.4 | G11: =Sheet1!R12 -> 0 | H11: =D11*$B$2 -> 3.0983867 | I11: =E11*$B$2 -> 0.8830402 | J11: =F11*$B$2 -> 3.0983867 | K11: =G11*$B$2 -> 0 | L11: =D11*$B$3 -> 3.0983867 | M11: =E11*$B$3 -> 0.8830402 | N11: =F11*$B$3 -> 3.0983867 | O11: =G11*$B$3 -> 0
D12: =Sheet1!O13 -> 0.5 | E12: =Sheet1!P13 -> 0.1052 | F12: =Sheet1!Q13 -> 0.5 | G12: =Sheet1!R13 -> 0 | H12: =D12*$B$2 -> 3.8729833 | I12: =E12*$B$2 -> 0.8148757 | J12: =F12*$B$2 -> 3.8729833 | K12: =G12*$B$2 -> 0 | L12: =D12*$B$3 -> 3.8729833 | M12: =E12*$B$3 -> 0.8148757 | N12: =F12*$B$3 -> 3.8729833 | O12: =G12*$B$3 -> 0
D13: =Sheet1!O14 -> 0.6 | E13: =Sheet1!P14 -> 0.0915 | F13: =Sheet1!Q14 -> 0.6 | G13: =Sheet1!R14 -> 0 | H13: =D13*$B$2 -> 4.64758 | I13: =E13*$B$2 -> 0.70875595 | J13: =F13*$B$2 -> 4.64758 | K13: =G13*$B$2 -> 0 | L13: =D13*$B$3 -> 4.64758 | M13: =E13*$B$3 -> 0.70875595 | N13: =F13*$B$3 -> 4.64758 | O13: =G13*$B$3 -> 0
D14: =Sheet1!O15 -> 0.7 | E14: =Sheet1!P15 -> 0.0735 | F14: =Sheet1!Q15 -> 0.7 | G14: =Sheet1!R15 -> 0 | H14: =D14*$B$2 -> 5.4221767 | I14: =E14*$B$2 -> 0.56932855 | J14: =F14*$B$2 -> 5.4221767 | K14: =G14*$B$2 -> 0 | L14: =D14*$B$3 -> 5.4221767 | M14: =E14*$B$3 -> 0.56932855 | N14: =F14*$B$3 -> 5.4221767 | O14: =G14*$B$3 -> 0
D15: =Sheet1!O16 -> 0.8 | E15: =Sheet1!P16 -> 0.0522 | F15: =Sheet1!Q16 -> 0.8 | G15: =Sheet1!R16 -> 0 | H15: =D15*$B$2 -> 6.1967734 | I15: =E15*$B$2 -> 0.40433946 | J15: =F15*$B$2 -> 6.1967734 | K15: =G15*$B$2 -> 0 | L15: =D15*$B$3 -> 6.1967734 | M15: =E15*$B$3 -> 0.40433946 | N15: =F15*$B$3 -> 6.1967734 | O15: =G15*$B$3 -> 0
D16: =Sheet1!O17 -> 0.9 | E16: =Sheet1!P17 -> 0.028 | F16: =Sheet1!Q17 -> 0.9 | G16: =Sheet1!R17 -> 0 | H16: =D16*$B$2 -> 6.97137 | I16: =E16*$B$2 -> 0.21688707 | J16: =F16*$B$2 -> 6.97137 | K16: =G16*$B$2 -> 0 | L16: =D16*$B$3 -> 6.97137 | M16: =E16*$B$3 -> 0.21688707 | N16: =F16*$B$3 -> 6.97137 | O16: =G16*$B$3 -> 0
... D18: =Sheet1!O19 -> 1 | E18: =Sheet1!P19 -> 0.0012 | F18: =Sheet1!Q19 -> 1 | G18: =Sheet1!R19 -> 0 | H18: =D18*$B$2 -> 7.7459667 | I18: =E18*$B$2 -> 0.00929516 | J18: =F18*$B$2 -> 7.7459667 | K18: =G18*$B$2 -> 0 | L18: =D18*$B$3 -> 7.7459667 | M18: =E18*$B$3 -> 0.00929516 | N18: =F18*$B$3 -> 7.7459667 | O18: =G18*$B$3 -> 0
D21: Panel 0 | L21: upper | N21: lower | P21: upper | S21: lower | V21: upper x | W21: upper y | X21: lower x | Y21: lower y | AB21: x | AC21: y | AD21: length to CG
D22: =Sheet1!S3 -> 0 | E22: =Sheet1!T3 -> 0.035 | F22: =Sheet1!U3 -> 0 | G22: =Sheet1!V3 -> 0.035 | H22: =D22*$B$2 -> 0 | I22: =E22*$B$2 -> 0.27110883 | J22: =F22*$B$2 -> 0 | K22: =G22*$B$2 -> 0.27110883 | L22: =H22-(0.25*$J$38) -> -1.9364917 | M22: =I22-(0.25*$K$38)+Sheet1!$B$17 -> 19.244775 | N22: =J22-(0.25*$J$38) -> -1.9364917 | O22: =K22-(0.25*$K$38)+Sheet1!$B$17 -> 19.244775 | P22: =L22 -> -1.9364917 | Q22: =M22*COS($B$4) -> 19.244621 | R22: =M22*SIN($B$4)+(Sheet1!$B$18/2) -> 1.0769116 | S22: =N22 -> -1.9364917 | T22: =O22*COS($B$4) -> 19.244621 | U22: =O22*SIN($B$4)+(Sheet1!$B$18/2) -> 1.0769116 | V22: 0 | W22: =R22*2 -> 2.1538232 | X22: 0 | Y22: =U22*2 -> 2.1538232 | AA22: A | AB22: =N22 -> -1.9364917 | AC22: =O22 -> 19.244775 | AD22: =SQRT(((AB22-Sheet1!$B$24)^2)+((AC22-Sheet1!$B$25)^2)) -> 21.232073
D23: =Sheet1!S4 -> 0.0125 | E23: =Sheet1!T4 -> 0.0545 | F23: =Sheet1!U4 -> 0.0125 | G23: =Sheet1!V4 -> 0.0193 | H23: =D23*$B$2 -> 0.096824584 | I23: =E23*$B$2 -> 0.42215518 | J23: =F23*$B$2 -> 0.096824584 | K23: =G23*$B$2 -> 0.14949716 | L23: =H23-(0.25*$J$38) -> -1.8396671 | M23: =I23-(0.25*$K$38)+Sheet1!$B$17 -> 19.395821 | N23: =J23-(0.25*$J$38) -> -1.8396671 | O23: =K23-(0.25*$K$38)+Sheet1!$B$17 -> 19.123163 | P23: =L23 -> -1.8396671 | Q23: =M23*COS($B$4) -> 19.395666 | R23: =M23*SIN($B$4)+(Sheet1!$B$18/2) -> 1.0775152 | S23: =N23 -> -1.8396671 | T23: =O23*COS($B$4) -> 19.12301 | U23: =O23*SIN($B$4)+(Sheet1!$B$18/2) -> 1.0764256 | V23: =SQRT(((P23-P22)^2)+((Q23-Q22)^2))+V22 -> 0.1794147 | W23: =R23*2 -> 2.1550305 | X23: =SQRT(((S23-S22)^2)+((T23-T22)^2))+X22 -> 0.15544827 | Y23: =U23*2 -> 2.1528511 | AA23: B | AB23: =(N29+N30)/2 -> 0 | AC23: =(O29+O30)/2 -> 18.974828 | AD23: =SQRT(((AB23-Sheet1!$B$24)^2)+((AC23-Sheet1!$B$25)^2)) -> 21.501102
D24: =Sheet1!S5 -> 0.025 | E24: =Sheet1!T5 -> 0.065 | F24: =Sheet1!U5 -> 0.025 | G24: =Sheet1!V5 -> 0.0147 | H24: =D24*$B$2 -> 0.19364917 | I24: =E24*$B$2 -> 0.50348784 | J24: =F24*$B$2 -> 0.19364917 | K24: =G24*$B$2 -> 0.11386571 | L24: =H24-(0.25*$J$38) -> -1.7428425 | M24: =I24-(0.25*$K$38)+Sheet1!$B$17 -> 19.477154 | N24: =J24-(0.25*$J$38) -> -1.7428425 | O24: =K24-(0.25*$K$38)+Sheet1!$B$17 -> 19.087532 | P24: =L24 -> -1.7428425 | Q24: =M24*COS($B$4) -> 19.476998 | R24: =M24*SIN($B$4)+(Sheet1!$B$18/2) -> 1.0778403 | S24: =N24 -> -1.7428425 | T24: =O24*COS($B$4) -> 19.087379 | U24: =O24*SIN($B$4)+(Sheet1!$B$18/2) -> 1.0762832 | V24: =SQRT(((P24-P23)^2)+((Q24-Q23)^2))+V23 -> 0.30586586 | W24: =R24*2 -> 2.1556806 | X24: =SQRT(((S24-S23)^2)+((T24-T23)^2))+X23 -> 0.25862084 | Y24: =U24*2 -> 2.1525663 | AA24: C | AB24: =L32 -> 1.9364917 | AC24: =M32 -> 19.788542 | AD24: =SQRT(((AB24-Sheet1!$B$24)^2)+((AC24-Sheet1!$B$25)^2)) -> 22.939869
D25: =Sheet1!S6 -> 0.05 | E25: =Sheet1!T6 -> 0.079 | F25: =Sheet1!U6 -> 0.05 | G25: =Sheet1!V6 -> 0.0093 | H25: =D25*$B$2 -> 0.38729833 | I25: =E25*$B$2 -> 0.61193137 | J25: =F25*$B$2 -> 0.38729833 | K25: =G25*$B$2 -> 0.07203749 | L25: =H25-(0.25*$J$38) -> -1.5491933 | M25: =I25-(0.25*$K$38)+Sheet1!$B$17 -> 19.585597 | N25: =J25-(0.25*$J$38) -> -1.5491933 | O25: =K25-(0.25*$K$38)+Sheet1!$B$17 -> 19.045703 | P25: =L25 -> -1.5491933 | Q25: =M25*COS($B$4) -> 19.585441 | R25: =M25*SIN($B$4)+(Sheet1!$B$18/2) -> 1.0782737 | S25: =N25 -> -1.5491933 | T25: =O25*COS($B$4) -> 19.045551 | U25: =O25*SIN($B$4)+(Sheet1!$B$18/2) -> 1.076116 | V25: =SQRT(((P25-P24)^2)+((Q25-Q24)^2))+V24 -> 0.52781137 | W25: =R25*2 -> 2.1565474 | X25: =SQRT(((S25-S24)^2)+((T25-T24)^2))+X24 -> 0.45673589 | Y25: =U25*2 -> 2.152232 | AA25: D | AB25: =(N34+N35)/2 -> 3.8729833 | AC25: =(O34+O35)/2 -> 18.973666 | AD25: =SQRT(((AB25-Sheet1!$B$24)^2)+((AC25-Sheet1!$B$25)^2)) -> 23.019862
D26: =Sheet1!S7 -> 0.075 | E26: =Sheet1!T7 -> 0.0885 | F26: =Sheet1!U7 -> 0.075 | G26: =Sheet1!V7 -> 0.0063 | H26: =D26*$B$2 -> 0.5809475 | I26: =E26*$B$2 -> 0.68551805 | J26: =F26*$B$2 -> 0.5809475 | K26: =G26*$B$2 -> 0.04879959 | L26: =H26-(0.25*$J$38) -> -1.3555442 | M26: =I26-(0.25*$K$38)+Sheet1!$B$17 -> 19.659184 | N26: =J26-(0.25*$J$38) -> -1.3555442 | O26: =K26-(0.25*$K$38)+Sheet1!$B$17 -> 19.022466 | P26: =L26 -> -1.3555442 | Q26: =M26*COS($B$4) -> 19.659027 | R26: =M26*SIN($B$4)+(Sheet1!$B$18/2) -> 1.0785678 | S26: =N26 -> -1.3555442 | T26: =O26*COS($B$4) -> 19.022314 | U26: =O26*SIN($B$4)+(Sheet1!$B$18/2) -> 1.0760231 | V26: =SQRT(((P26-P25)^2)+((Q26-Q25)^2))+V25 -> 0.73497052 | W26: =R26*2 -> 2.1571355 | X26: =SQRT(((S26-S25)^2)+((T26-T25)^2))+X25 -> 0.65177432 | Y26: =U26*2 -> 2.1520463 | AA26: B | AB26: =N38 -> 5.809475 | AC26: =O38 -> 18.973666 | AD26: =SQRT(((AB26-Sheet1!$B$24)^2)+((AC26-Sheet1!$B$25)^2)) -> 23.979075
D27: =Sheet1!S8 -> 0.1 | E27: =Sheet1!T8 -> 0.096 | F27: =Sheet1!U8 -> 0.1 | G27: =Sheet1!V8 -> 0.0042 | H27: =D27*$B$2 -> 0.77459667 | I27: =E27*$B$2 -> 0.7436128 | J27: =F27*$B$2 -> 0.77459667 | K27: =G27*$B$2 -> 0.03253306 | L27: =H27-(0.25*$J$38) -> -1.161895 | M27: =I27-(0.25*$K$38)+Sheet1!$B$17 -> 19.717279 | N27: =J27-(0.25*$J$38) -> -1.161895 | O27: =K27-(0.25*$K$38)+Sheet1!$B$17 -> 19.006199 | P27: =L27 -> -1.161895 | Q27: =M27*COS($B$4) -> 19.717121 | R27: =M27*SIN($B$4)+(Sheet1!$B$18/2) -> 1.0787999 | S27: =N27 -> -1.161895 | T27: =O27*COS($B$4) -> 19.006047 | U27: =O27*SIN($B$4)+(Sheet1!$B$18/2) -> 1.0759581 | V27: =SQRT(((P27-P26)^2)+((Q27-Q26)^2))+V26 -> 0.93714606 | W27: =R27*2 -> 2.1575999 | X27: =SQRT(((S27-S26)^2)+((T27-T26)^2))+X26 -> 0.84610547 | Y27: =U27*2 -> 2.1519162
D28: =Sheet1!S9 -> 0.15 | E28: =Sheet1!T9 -> 0.1069 | F28: =Sheet1!U9 -> 0.15 | G28: =Sheet1!V9 -> 0.0015 | H28: =D28*$B$2 -> 1.161895 | I28: =E28*$B$2 -> 0.82804384 | J28: =F28*$B$2 -> 1.161895 | K28: =G28*$B$2 -> 0.01161895 | L28: =H28-(0.25*$J$38) -> -0.77459667 | M28: =I28-(0.25*$K$38)+Sheet1!$B$17 -> 19.80171 | N28: =J28-(0.25*$J$38) -> -0.77459667 | O28: =K28-(0.25*$K$38)+Sheet1!$B$17 -> 18.985285 | P28: =L28 -> -0.77459667 | Q28: =M28*COS($B$4) -> 19.801552 | R28: =M28*SIN($B$4)+(Sheet1!$B$18/2) -> 1.0791374 | S28: =N28 -> -0.77459667 | T28: =O28*COS($B$4) -> 18.985133 | U28: =O28*SIN($B$4)+(Sheet1!$B$18/2) -> 1.0758745 | V28: =SQRT(((P28-P27)^2)+((Q28-Q27)^2))+V27 -> 1.3335404 | W28: =R28*2 -> 2.1582747 | X28: =SQRT(((S28-S27)^2)+((T28-T27)^2))+X27 -> 1.2339681 | Y28: =U28*2 -> 2.1517491
D29: =Sheet1!S10 -> 0.2 | E29: =Sheet1!T10 -> 0.1136 | F29: =Sheet1!U10 -> 0.2 | G29: =Sheet1!V10 -> 0.0003 | H29: =D29*$B$2 -> 1.5491933 | I29: =E29*$B$2 -> 0.87994182 | J29: =F29*$B$2 -> 1.5491933 | K29: =G29*$B$2 -> 0.00232379 | L29: =H29-(0.25*$J$38) -> -0.38729833 | M29: =I29-(0.25*$K$38)+Sheet1!$B$17 -> 19.853608 | N29: =J29-(0.25*$J$38) -> -0.38729833 | O29: =K29-(0.25*$K$38)+Sheet1!$B$17 -> 18.97599 | P29: =L29 -> -0.38729833 | Q29: =M29*COS($B$4) -> 19.853449 | R29: =M29*SIN($B$4)+(Sheet1!$B$18/2) -> 1.0793448 | S29: =N29 -> -0.38729833 | T29: =O29*COS($B$4) -> 18.975838 | U29: =O29*SIN($B$4)+(Sheet1!$B$18/2) -> 1.0758374 | V29: =SQRT(((P29-P28)^2)+((Q29-Q28)^2))+V28 -> 1.7243004 | W29: =R29*2 -> 2.1586896 | X29: =SQRT(((S29-S28)^2)+((T29-T28)^2))+X28 -> 1.6213779 | Y29: =U29*2 -> 2.1516748
D30: =Sheet1!S11 -> 0.3 | E30: =Sheet1!T11 -> 0.117 | F30: =Sheet1!U11 -> 0.3 | G30: =Sheet1!V11 -> 0 | H30: =D30*$B$2 -> 2.32379 | I30: =E30*$B$2 -> 0.9062781 | J30: =F30*$B$2 -> 2.32379 | K30: =G30*$B$2 -> 0 | L30: =H30-(0.25*$J$38) -> 0.38729833 | M30: =I30-(0.25*$K$38)+Sheet1!$B$17 -> 19.879944 | N30: =J30-(0.25*$J$38) -> 0.38729833 | O30: =K30-(0.25*$K$38)+Sheet1!$B$17 -> 18.973666 | P30: =L30 -> 0.38729833 | Q30: =M30*COS($B$4) -> 19.879785 | R30: =M30*SIN($B$4)+(Sheet1!$B$18/2) -> 1.07945 | S30: =N30 -> 0.38729833 | T30: =O30*COS($B$4) -> 18.973514 | U30: =O30*SIN($B$4)+(Sheet1!$B$18/2) -> 1.0758281 | V30: =SQRT(((P30-P29)^2)+((Q30-Q29)^2))+V29 -> 2.4993446 | W30: =R30*2 -> 2.1589001 | X30: =SQRT(((S30-S29)^2)+((T30-T29)^2))+X29 -> 2.3959781 | Y30: =U30*2 -> 2.1516562
D31: =Sheet1!S12 -> 0.4 | E31: =Sheet1!T12 -> 0.114 | F31: =Sheet1!U12 -> 0.4 | G31: =Sheet1!V12 -> 0 | H31: =D31*$B$2 -> 3.0983867 | I31: =E31*$B$2 -> 0.8830402 | J31: =F31*$B$2 -> 3.0983867 | K31: =G31*$B$2 -> 0 | L31: =H31-(0.25*$J$38) -> 1.161895 | M31: =I31-(0.25*$K$38)+Sheet1!$B$17 -> 19.856706 | N31: =J31-(0.25*$J$38) -> 1.161895 | O31: =K31-(0.25*$K$38)+Sheet1!$B$17 -> 18.973666 | P31: =L31 -> 1.161895 | Q31: =M31*COS($B$4) -> 19.856548 | R31: =M31*SIN($B$4)+(Sheet1!$B$18/2) -> 1.0793572 | S31: =N31 -> 1.161895 | T31: =O31*COS($B$4) -> 18.973514 | U31: =O31*SIN($B$4)+(Sheet1!$B$18/2) -> 1.0758281 | V31: =SQRT(((P31-P30)^2)+((Q31-Q30)^2))+V30 -> 3.2742898 | W31: =R31*2 -> 2.1587143 | X31: =SQRT(((S31-S30)^2)+((T31-T30)^2))+X30 -> 3.1705748 | Y31: =U31*2 -> 2.1516562
D32: =Sheet1!S13 -> 0.5 | E32: =Sheet1!T13 -> 0.1052 | F32: =Sheet1!U13 -> 0.5 | G32: =Sheet1!V13 -> 0 | H32: =D32*$B$2 -> 3.8729833 | I32: =E32*$B$2 -> 0.8148757 | J32: =F32*$B$2 -> 3.8729833 | K32: =G32*$B$2 -> 0 | L32: =H32-(0.25*$J$38) -> 1.9364917 | M32: =I32-(0.25*$K$38)+Sheet1!$B$17 -> 19.788542 | N32: =J32-(0.25*$J$38) -> 1.9364917 | O32: =K32-(0.25*$K$38)+Sheet1!$B$17 -> 18.973666 | P32: =L32 -> 1.9364917 | Q32: =M32*COS($B$4) -> 19.788384 | R32: =M32*SIN($B$4)+(Sheet1!$B$18/2) -> 1.0790847 | S32: =N32 -> 1.9364917 | T32: =O32*COS($B$4) -> 18.973514 | U32: =O32*SIN($B$4)+(Sheet1!$B$18/2) -> 1.0758281 | V32: =SQRT(((P32-P31)^2)+((Q32-Q31)^2))+V31 -> 4.0518799 | W32: =R32*2 -> 2.1581695 | X32: =SQRT(((S32-S31)^2)+((T32-T31)^2))+X31 -> 3.9451714 | Y32: =U32*2 -> 2.1516562
D33: =Sheet1!S14 -> 0.6 | E33: =Sheet1!T14 -> 0.0915 | F33: =Sheet1!U14 -> 0.6 | G33: =Sheet1!V14 -> 0 | H33: =D33*$B$2 -> 4.64758 | I33: =E33*$B$2 -> 0.70875595 | J33: =F33*$B$2 -> 4.64758 | K33: =G33*$B$2 -> 0 | L33: =H33-(0.25*$J$38) -> 2.7110883 | M33: =I33-(0.25*$K$38)+Sheet1!$B$17 -> 19.682422 | N33: =J33-(0.25*$J$38) -> 2.7110883 | O33: =K33-(0.25*$K$38)+Sheet1!$B$17 -> 18.973666 | P33: =L33 -> 2.7110883 | Q33: =M33*COS($B$4) -> 19.682265 | R33: =M33*SIN($B$4)+(Sheet1!$B$18/2) -> 1.0786606 | S33: =N33 -> 2.7110883 | T33: =O33*COS($B$4) -> 18.973514 | U33: =O33*SIN($B$4)+(Sheet1!$B$18/2) -> 1.0758281 | V33: =SQRT(((P33-P32)^2)+((Q33-Q32)^2))+V32 -> 4.8337118 | W33: =R33*2 -> 2.1573213 | X33: =SQRT(((S33-S32)^2)+((T33-T32)^2))+X32 -> 4.7197681 | Y33: =U33*2 -> 2.1516562
D34: =Sheet1!S15 -> 0.7 | E34: =Sheet1!T15 -> 0.0735 | F34: =Sheet1!U15 -> 0.7 | G34: =Sheet1!V15 -> 0 | H34: =D34*$B$2 -> 5.4221767 | I34: =E34*$B$2 -> 0.56932855 | J34: =F34*$B$2 -> 5.4221767 | K34: =G34*$B$2 -> 0 | L34: =H34-(0.25*$J$38) -> 3.485685 | M34: =I34-(0.25*$K$38)+Sheet1!$B$17 -> 19.542995 | N34: =J34-(0.25*$J$38) -> 3.485685 | O34: =K34-(0.25*$K$38)+Sheet1!$B$17 -> 18.973666 | P34: =L34 -> 3.485685 | Q34: =M34*COS($B$4) -> 19.542838 | R34: =M34*SIN($B$4)+(Sheet1!$B$18/2) -> 1.0781034 | S34: =N34 -> 3.485685 | T34: =O34*COS($B$4) -> 18.973514 | U34: =O34*SIN($B$4)+(Sheet1!$B$18/2) -> 1.0758281 | V34: =SQRT(((P34-P33)^2)+((Q34-Q33)^2))+V33 -> 5.6207567 | W34: =R34*2 -> 2.1562068 | X34: =SQRT(((S34-S33)^2)+((T34-T33)^2))+X33 -> 5.4943648 | Y34: =U34*2 -> 2.1516562
D35: =Sheet1!S16 -> 0.8 | E35: =Sheet1!T16 -> 0.0522 | F35: =Sheet1!U16 -> 0.8 | G35: =Sheet1!V16 -> 0 | H35: =D35*$B$2 -> 6.1967734 | I35: =E35*$B$2 -> 0.40433946 | J35: =F35*$B$2 -> 6.1967734 | K35: =G35*$B$2 -> 0 | L35: =H35-(0.25*$J$38) -> 4.2602817 | M35: =I35-(0.25*$K$38)+Sheet1!$B$17 -> 19.378005 | N35: =J35-(0.25*$J$38) -> 4.2602817 | O35: =K35-(0.25*$K$38)+Sheet1!$B$17 -> 18.973666 | P35: =L35 -> 4.2602817 | Q35: =M35*COS($B$4) -> 19.377851 | R35: =M35*SIN($B$4)+(Sheet1!$B$18/2) -> 1.077444 | S35: =N35 -> 4.2602817 | T35: =O35*COS($B$4) -> 18.973514 | U35: =O35*SIN($B$4)+(Sheet1!$B$18/2) -> 1.0758281 | V35: =SQRT(((P35-P34)^2)+((Q35-Q34)^2))+V34 -> 6.4127296 | W35: =R35*2 -> 2.1548881 | X35: =SQRT(((S35-S34)^2)+((T35-T34)^2))+X34 -> 6.2689614 | Y35: =U35*2 -> 2.1516562
D36: =Sheet1!S17 -> 0.9 | E36: =Sheet1!T17 -> 0.028 | F36: =Sheet1!U17 -> 0.9 | G36: =Sheet1!V17 -> 0 | H36: =D36*$B$2 -> 6.97137 | I36: =E36*$B$2 -> 0.21688707 | J36: =F36*$B$2 -> 6.97137 | K36: =G36*$B$2 -> 0 | L36: =H36-(0.25*$J$38) -> 5.0348784 | M36: =I36-(0.25*$K$38)+Sheet1!$B$17 -> 19.190553 | N36: =J36-(0.25*$J$38) -> 5.0348784 | O36: =K36-(0.25*$K$38)+Sheet1!$B$17 -> 18.973666 | P36: =L36 -> 5.0348784 | Q36: =M36*COS($B$4) -> 19.1904 | R36: =M36*SIN($B$4)+(Sheet1!$B$18/2) -> 1.0766949 | S36: =N36 -> 5.0348784 | T36: =O36*COS($B$4) -> 18.973514 | U36: =O36*SIN($B$4)+(Sheet1!$B$18/2) -> 1.0758281 | V36: =SQRT(((P36-P35)^2)+((Q36-Q35)^2))+V35 -> 7.2096849 | W36: =R36*2 -> 2.1533898 | X36: =SQRT(((S36-S35)^2)+((T36-T35)^2))+X35 -> 7.0435581 | Y36: =U36*2 -> 2.1516562
D37: =Sheet1!S18 -> 0.95 | E37: =Sheet1!T18 -> 0.0149 | F37: =Sheet1!U18 -> 0.95 | G37: =Sheet1!V18 -> 0 | H37: =D37*$B$2 -> 7.3586684 | I37: =E37*$B$2 -> 0.1154149 | J37: =F37*$B$2 -> 7.3586684 | K37: =G37*$B$2 -> 0 | L37: =H37-(0.25*$J$38) -> 5.4221767 | M37: =I37-(0.25*$K$38)+Sheet1!$B$17 -> 19.089081 | N37: =J37-(0.25*$J$38) -> 5.4221767 | O37: =K37-(0.25*$K$38)+Sheet1!$B$17 -> 18.973666 | P37: =L37 -> 5.4221767 | Q37: =M37*COS($B$4) -> 19.088928 | R37: =M37*SIN($B$4)+(Sheet1!$B$18/2) -> 1.0762894 | S37: =N37 -> 5.4221767 | T37: =O37*COS($B$4) -> 18.973514 | U37: =O37*SIN($B$4)+(Sheet1!$B$18/2) -> 1.0758281 | V37: =SQRT(((P37-P36)^2)+((Q37-Q36)^2))+V36 -> 7.6100553 | W37: =R37*2 -> 2.1525787 | X37: =SQRT(((S37-S36)^2)+((T37-T36)^2))+X36 -> 7.4308564 | Y37: =U37*2 -> 2.1516562
D38: =Sheet1!S19 -> 1 | E38: =Sheet1!T19 -> 0.0012 | F38: =Sheet1!U19 -> 1 | G38: =Sheet1!V19 -> 0 | H38: =D38*$B$2 -> 7.7459667 | I38: =E38*$B$2 -> 0.00929516 | J38: =F38*$B$2 -> 7.7459667 | K38: =G38*$B$2 -> 0 | L38: =H38-(0.25*$J$38) -> 5.809475 | M38: =I38-(0.25*$K$38)+Sheet1!$B$17 -> 18.982961 | N38: =J38-(0.25*$J$38) -> 5.809475 | O38: =K38-(0.25*$K$38)+Sheet1!$B$17 -> 18.973666 | P38: =L38 -> 5.809475 | Q38: =M38*COS($B$4) -> 18.98281 | R38: =M38*SIN($B$4)+(Sheet1!$B$18/2) -> 1.0758652 | S38: =N38 -> 5.809475 | T38: =O38*COS($B$4) -> 18.973514 | U38: =O38*SIN($B$4)+(Sheet1!$B$18/2) -> 1.0758281 | V38: =SQRT(((P38-P37)^2)+((Q38-Q37)^2))+V37 -> 8.0116287 | W38: =R38*2 -> 2.1517305 | X38: =SQRT(((S38-S37)^2)+((T38-T37)^2))+X37 -> 7.8181548 | Y38: =U38*2 -> 2.1516562

Sheet Sheet2 (2)
H1: rib 2 | L1: rib 1.5
A2: c 2 | B2: =Sheet1!F25 -> 7.7459667 | D2: =Sheet1!O3 -> 0 | E2: =Sheet1!P3 -> 0.035 | F2: =Sheet1!Q3 -> 0 | G2: =Sheet1!R3 -> 0.035 | H2: =D2*$B$2 -> 0 | I2: =E2*$B$2 -> 0.27110883 | J2: =F2*$B$2 -> 0 | K2: =G2*$B$2 -> 0.27110883 | L2: =D2*$B$4 -> 0 | M2: =E2*$B$4 -> 0.27110883 | N2: =F2*$B$4 -> 0 | O2: =G2*$B$4 -> 0.27110883
A3: c 1 | B3: =Sheet1!E25 -> 7.7459667 | D3: =Sheet1!O4 -> 0.0125 | E3: =Sheet1!P4 -> 0.0545 | F3: =Sheet1!Q4 -> 0.0125 | G3: =Sheet1!R4 -> 0.0193 | H3: =D3*$B$2 -> 0.096824584 | I3: =E3*$B$2 -> 0.42215518 | J3: =F3*$B$2 -> 0.096824584 | K3: =G3*$B$2 -> 0.14949716 | L3: =D3*$B$4 -> 0.096824584 | M3: =E3*$B$4 -> 0.42215518 | N3: =F3*$B$4 -> 0.096824584 | O3: =G3*$B$4 -> 0.14949716
A4: c 1.5 | B4: =(B2+B3)/2 -> 7.7459667 | D4: =Sheet1!O5 -> 0.025 | E4: =Sheet1!P5 -> 0.065 | F4: =Sheet1!Q5 -> 0.025 | G4: =Sheet1!R5 -> 0.0147 | H4: =D4*$B$2 -> 0.19364917 | I4: =E4*$B$2 -> 0.50348784 | J4: =F4*$B$2 -> 0.19364917 | K4: =G4*$B$2 -> 0.11386571 | L4: =D4*$B$4 -> 0.19364917 | M4: =E4*$B$4 -> 0.50348784 | N4: =F4*$B$4 -> 0.19364917 | O4: =G4*$B$4 -> 0.11386571
A5: t | B5: =Sheet1!B19/9 -> 0.1134023 | D5: =Sheet1!O6 -> 0.05 | E5: =Sheet1!P6 -> 0.079 | F5: =Sheet1!Q6 -> 0.05 | G5: =Sheet1!R6 -> 0.0093 | H5: =D5*$B$2 -> 0.38729833 | I5: =E5*$B$2 -> 0.61193137 | J5: =F5*$B$2 -> 0.38729833 | K5: =G5*$B$2 -> 0.07203749 | L5: =D5*$B$4 -> 0.38729833 | M5: =E5*$B$4 -> 0.61193137 | N5: =F5*$B$4 -> 0.38729833 | O5: =G5*$B$4 -> 0.07203749
D6: =Sheet1!O7 -> 0.075 | E6: =Sheet1!P7 -> 0.0885 | F6: =Sheet1!Q7 -> 0.075 | G6: =Sheet1!R7 -> 0.0063 | H6: =D6*$B$2 -> 0.5809475 | I6: =E6*$B$2 -> 0.68551805 | J6: =F6*$B$2 -> 0.5809475 | K6: =G6*$B$2 -> 0.04879959 | L6: =D6*$B$4 -> 0.5809475 | M6: =E6*$B$4 -> 0.68551805 | N6: =F6*$B$4 -> 0.5809475 | O6: =G6*$B$4 -> 0.04879959
D7: =Sheet1!O8 -> 0.1 | E7: =Sheet1!P8 -> 0.096 | F7: =Sheet1!Q8 -> 0.1 | G7: =Sheet1!R8 -> 0.0042 | H7: =D7*$B$2 -> 0.77459667 | I7: =E7*$B$2 -> 0.7436128 | J7: =F7*$B$2 -> 0.77459667 | K7: =G7*$B$2 -> 0.03253306 | L7: =D7*$B$4 -> 0.77459667 | M7: =E7*$B$4 -> 0.7436128 | N7: =F7*$B$4 -> 0.77459667 | O7: =G7*$B$4 -> 0.03253306
D8: =Sheet1!O9 -> 0.15 | E8: =Sheet1!P9 -> 0.1069 | F8: =Sheet1!Q9 -> 0.15 | G8: =Sheet1!R9 -> 0.0015 | H8: =D8*$B$2 -> 1.161895 | I8: =E8*$B$2 -> 0.82804384 | J8: =F8*$B$2 -> 1.161895 | K8: =G8*$B$2 -> 0.01161895 | L8: =D8*$B$4 -> 1.161895 | M8: =E8*$B$4 -> 0.82804384 | N8: =F8*$B$4 -> 1.161895 | O8: =G8*$B$4 -> 0.01161895
D9: =Sheet1!O10 -> 0.2 | E9: =Sheet1!P10 -> 0.1136 | F9: =Sheet1!Q10 -> 0.2 | G9: =Sheet1!R10 -> 0.0003 | H9: =D9*$B$2 -> 1.5491933 | I9: =E9*$B$2 -> 0.87994182 | J9: =F9*$B$2 -> 1.5491933 | K9: =G9*$B$2 -> 0.00232379 | L9: =D9*$B$4 -> 1.5491933 | M9: =E9*$B$4 -> 0.87994182 | N9: =F9*$B$4 -> 1.5491933 | O9: =G9*$B$4 -> 0.00232379
D10: =Sheet1!O11 -> 0.3 | E10: =Sheet1!P11 -> 0.117 | F10: =Sheet1!Q11 -> 0.3 | G10: =Sheet1!R11 -> 0 | H10: =D10*$B$2 -> 2.32379 | I10: =E10*$B$2 -> 0.9062781 | J10: =F10*$B$2 -> 2.32379 | K10: =G10*$B$2 -> 0 | L10: =D10*$B$4 -> 2.32379 | M10: =E10*$B$4 -> 0.9062781 | N10: =F10*$B$4 -> 2.32379 | O10: =G10*$B$4 -> 0
D11: =Sheet1!O12 -> 0.4 | E11: =Sheet1!P12 -> 0.114 | F11: =Sheet1!Q12 -> 0.4 | G11: =Sheet1!R12 -> 0 | H11: =D11*$B$2 -> 3.0983867 | I11: =E11*$B$2 -> 0.8830402 | J11: =F11*$B$2 -> 3.0983867 | K11: =G11*$B$2 -> 0 | L11: =D11*$B$4 -> 3.0983867 | M11: =E11*$B$4 -> 0.8830402 | N11: =F11*$B$4 -> 3.0983867 | O11: =G11*$B$4 -> 0
D12: =Sheet1!O13 -> 0.5 | E12: =Sheet1!P13 -> 0.1052 | F12: =Sheet1!Q13 -> 0.5 | G12: =Sheet1!R13 -> 0 | H12: =D12*$B$2 -> 3.8729833 | I12: =E12*$B$2 -> 0.8148757 | J12: =F12*$B$2 -> 3.8729833 | K12: =G12*$B$2 -> 0 | L12: =D12*$B$4 -> 3.8729833 | M12: =E12*$B$4 -> 0.8148757 | N12: =F12*$B$4 -> 3.8729833 | O12: =G12*$B$4 -> 0
D13: =Sheet1!O14 -> 0.6 | E13: =Sheet1!P14 -> 0.0915 | F13: =Sheet1!Q14 -> 0.6 | G13: =Sheet1!R14 -> 0 | H13: =D13*$B$2 -> 4.64758 | I13: =E13*$B$2 -> 0.70875595 | J13: =F13*$B$2 -> 4.64758 | K13: =G13*$B$2 -> 0 | L13: =D13*$B$4 -> 4.64758 | M13: =E13*$B$4 -> 0.70875595 | N13: =F13*$B$4 -> 4.64758 | O13: =G13*$B$4 -> 0
D14: =Sheet1!O15 -> 0.7 | E14: =Sheet1!P15 -> 0.0735 | F14: =Sheet1!Q15 -> 0.7 | G14: =Sheet1!R15 -> 0 | H14: =D14*$B$2 -> 5.4221767 | I14: =E14*$B$2 -> 0.56932855 | J14: =F14*$B$2 -> 5.4221767 | K14: =G14*$B$2 -> 0 | L14: =D14*$B$4 -> 5.4221767 | M14: =E14*$B$4 -> 0.56932855 | N14: =F14*$B$4 -> 5.4221767 | O14: =G14*$B$4 -> 0
D15: =Sheet1!O16 -> 0.8 | E15: =Sheet1!P16 -> 0.0522 | F15: =Sheet1!Q16 -> 0.8 | G15: =Sheet1!R16 -> 0 | H15: =D15*$B$2 -> 6.1967734 | I15: =E15*$B$2 -> 0.40433946 | J15: =F15*$B$2 -> 6.1967734 | K15: =G15*$B$2 -> 0 | L15: =D15*$B$4 -> 6.1967734 | M15: =E15*$B$4 -> 0.40433946 | N15: =F15*$B$4 -> 6.1967734 | O15: =G15*$B$4 -> 0
D16: =Sheet1!O17 -> 0.9 | E16: =Sheet1!P17 -> 0.028 | F16: =Sheet1!Q17 -> 0.9 | G16: =Sheet1!R17 -> 0 | H16: =D16*$B$2 -> 6.97137 | I16: =E16*$B$2 -> 0.21688707 | J16: =F16*$B$2 -> 6.97137 | K16: =G16*$B$2 -> 0 | L16: =D16*$B$4 -> 6.97137 | M16: =E16*$B$4 -> 0.21688707 | N16: =F16*$B$4 -> 6.97137 | O16: =G16*$B$4 -> 0
D17: =Sheet1!O18 -> 0.95 | E17: =Sheet1!P18 -> 0.0149 | F17: =Sheet1!Q18 -> 0.95 | G17: =Sheet1!R18 -> 0 | H17: =D17*$B$2 -> 7.3586684 | I17: =E17*$B$2 -> 0.1154149 | J17: =F17*$B$2 -> 7.3586684 | K17: =G17*$B$2 -> 0 | L17: =D17*$B$4 -> 7.3586684 | M17: =E17*$B$4 -> 0.1154149 | N17: =F17*$B$4 -> 7.3586684 | O17: =G17*$B$4 -> 0
D18: =Sheet1!O19 -> 1 | E18: =Sheet1!P19 -> 0.0012 | F18: =Sheet1!Q19 -> 1 | G18: =Sheet1!R19 -> 0 | H18: =D18*$B$2 -> 7.7459667 | I18: =E18*$B$2 -> 0.00929516 | J18: =F18*$B$2 -> 7.7459667 | K18: =G18*$B$2 -> 0 | L18: =D18*$B$4 -> 7.7459667 | M18: =E18*$B$4 -> 0.00929516 | N18: =F18*$B$4 -> 7.7459667 | O18: =G18*$B$4 -> 0
D21: Panel 0 | L21: rib 2 | T21: rib 1 | X21: rib 2 upper tilted | AA21: rib 2 lower tilted | AD21: upper s2 | AE21: upper s1 | AF21: upper a2 | AG21: upper c | AH21: gama 1 | AI21: gama 2 | AJ21: upper x1 | AK21: upper y1 | AL21: upper x2 | AM21: upper y2 | AN21: lower s2 | AO21: lower s1 | AP21: lower a2 | AQ21: lower c | AR21: gama 1 | AS21: gama 2 | AT21: lower x1 | AU21: lower y1 | AV21: lower x2 | AW21: lower y2 | AZ21: X | BA21: Y | BB21: length to cg
D22: =Sheet1!S3 -> 0 | E22: =Sheet1!T3 -> 0.035 | F22: =Sheet1!U3 -> 0 | G22: =Sheet1!V3 -> 0.035 | H22: =D22*$B$2 -> 0 | I22: =E22*$B$2 -> 0.27110883 | J22: =F22*$B$2 -> 0 | K22: =G22*$B$2 -> 0.27110883 | L22: =H22-(0.25*$J$38) -> -1.9364917 | M22: =I22-(0.25*$K$38)+Sheet1!$B$17 -> 19.244775 | N22: =J22-(0.25*$J$38) -> -1.9364917 | O22: =K22-(0.25*$K$38)+Sheet1!$B$17 -> 19.244775 | P22: =D22*$B$3 -> 0 | Q22: =E22*$B$3 -> 0.27110883 | R22: =F22*$B$3 -> 0 | S22: =G22*$B$3 -> 0.27110883 | T22: =P22-(0.25*$R$38) -> -1.9364917 | U22: =Q22-(0.25*$S$38)+Sheet1!$B$17 -> 19.244775 | V22: =R22-(0.25*$R$38) -> -1.9364917 | W22: =S22-(0.25*$S$38)+Sheet1!$B$17 -> 19.244775 | X22: =L22 -> -1.9364917 | Y22: =M22*COS($B$5) -> 19.121163 | Z22: =M22*SIN($B$5) -> 2.1777271 | AA22: =N22 -> -1.9364917 | AB22: =O22*COS($B$5) -> 19.121163 | AC22: =O22*SIN($B$5) -> 2.1777271 | AF22: =SQRT(((T22-X22)^2)+((U22-Y22)^2)+(Z22^2)) -> 2.1812326 | AG22: =SQRT(((T22-X23)^2)+((U22-Y23)^2)+(Z23^2)) -> 2.1971135 | AH22: =ACOS(((AF22^2)+(AG22^2)-(AD23^2))/(2*AF22*AG22)) -> 0.081657466 | AI22: =ACOS(((AF23^2)+(AG22^2)-(AE23^2))/(2*AF23*AG22))-AH22 -> 1.3322676e-15 | AJ22: 0 | AK22: 0 | AL22: =AF22 -> 2.1812326 | AM22: 0 | AP22: =SQRT(((V22-AA22)^2)+((W22-AB22)^2)+(AC22^2)) -> 2.1812326 | AQ22: =SQRT(((V22-AA23)^2)+((W22-AB23)^2)+(AC23^2)) -> 2.1798795 | AR22: =ACOS(((AP22^2)+(AQ22^2)-(AN23^2))/(2*AP22*AQ22)) -> 0.071301116 | AS22: =ACOS(((AP23^2)+(AQ22^2)-(AO23^2))/(2*AP23*AQ22))-AR22 -> 0 | AT22: 0 | AU22: 0 | AV22: =AF22 -> 2.1812326 | AW22: 0 | AY22: A | AZ22: =N22 -> -1.9364917 | BA22: =O22 -> 19.244775 | BB22: =SQRT(((AZ22-Sheet1!$B$24)^2)+((BA22-Sheet1!$B$25)^2)) -> 21.232073
D23: =Sheet1!S4 -> 0.0125 | E23: =Sheet1!T4 -> 0.0545 | F23: =Sheet1!U4 -> 0.0125 | G23: =Sheet1!V4 -> 0.0193 | H23: =D23*$B$2 -> 0.096824584 | I23: =E23*$B$2 -> 0.42215518 | J23: =F23*$B$2 -> 0.096824584 | K23: =G23*$B$2 -> 0.14949716 | L23: =H23-(0.25*$J$38) -> -1.8396671 | M23: =I23-(0.25*$K$38)+Sheet1!$B$17 -> 19.395821 | N23: =J23-(0.25*$J$38) -> -1.8396671 | O23: =K23-(0.25*$K$38)+Sheet1!$B$17 -> 19.123163 | P23: =D23*$B$3 -> 0.096824584 | Q23: =E23*$B$3 -> 0.42215518 | R23: =F23*$B$3 -> 0.096824584 | S23: =G23*$B$3 -> 0.14949716 | T23: =P23-(0.25*$R$38) -> -1.8396671 | U23: =Q23-(0.25*$S$38)+Sheet1!$B$17 -> 19.395821 | V23: =R23-(0.25*$R$38) -> -1.8396671 | W23: =S23-(0.25*$S$38)+Sheet1!$B$17 -> 19.123163 | X23: =L23 -> -1.8396671 | Y23: =M23*COS($B$5) -> 19.271239 | Z23: =M23*SIN($B$5) -> 2.1948195 | AA23: =N23 -> -1.8396671 | AB23: =O23*COS($B$5) -> 19.000332 | AC23: =O23*SIN($B$5) -> 2.1639656 | AD23: =SQRT(((X23-X22)^2)+((Y23-Y22)^2)+((Z22-Z23)^2)) -> 0.17941572 | AE23: =SQRT(((T22-T23)^2)+((U22-U23)^2)) -> 0.17941572 | AF23: =SQRT(((T23-X23)^2)+((U23-Y23)^2)+(Z23^2)) -> 2.1983524 | AG23: =SQRT(((T23-X24)^2)+((U23-Y24)^2)+(Z24^2)) -> 2.206583 | AH23: =ACOS(((AF23^2)+(AG23^2)-(AD24^2))/(2*AF23*AG23))-AI22 -> 0.057299779 | AI23: =ACOS(((AF24^2)+(AG23^2)-(AE24^2))/(2*AF24*AG23))-AH23 -> 1.3322676e-15 | AJ23: =-COS(AI22)*AF23+AL23 -> -0.0085599136 | AK23: =SIN(AI22)*AF23+AM23 -> 0.17921141 | AL23: =COS(AH22)*AG22+AJ22 -> 2.1897925 | AM23: =SIN(AH22)*AG22+AK22 -> 0.17921141 | AN23: =SQRT(((AA23-AA22)^2)+((AB23-AB22)^2)+((AC22-AC23)^2)) -> 0.15544903 | AO23: =SQRT(((V22-V23)^2)+((W22-W23)^2)) -> 0.15544903 | AP23: =SQRT(((V23-AA23)^2)+((W23-AB23)^2)+(AC23^2)) -> 2.1674489 | AQ23: =SQRT(((V23-AA24)^2)+((W23-AB24)^2)+(AC24^2)) -> 2.1678852 | AR23: =ACOS(((AP23^2)+(AQ23^2)-(AN24^2))/(2*AP23*AQ23)) -> 0.047600249 | AS23: =ACOS(((AP24^2)+(AQ23^2)-(AO24^2))/(2*AP24*AQ23))-AR23 -> -4.6629367e-15 | AT23: =-COS(AS22)*AP23+AV23 -> 0.0068918278 | AU23: =SIN(AS22)*AP23+AW23 -> 0.17921141 | AV23: =COS(AR22)*AQ22+AT22 -> 2.1743407 | AW23: =SIN(AH22)*AG22+AK22 -> 0.17921141 | AY23: B | AZ23: =(N29+N30)/2 -> 0 | BA23: =(O29+O30)/2 -> 18.974828 | BB23: =SQRT(((AZ23-Sheet1!$B$24)^2)+((BA23-Sheet1!$B$25)^2)) -> 21.501102
D24: =Sheet1!S5 -> 0.025 | E24: =Sheet1!T5 -> 0.065 | F24: =Sheet1!U5 -> 0.025 | G24: =Sheet1!V5 -> 0.0147 | H24: =D24*$B$2 -> 0.19364917 | I24: =E24*$B$2 -> 0.50348784 | J24: =F24*$B$2 -> 0.19364917 | K24: =G24*$B$2 -> 0.11386571 | L24: =H24-(0.25*$J$38) -> -1.7428425 | M24: =I24-(0.25*$K$38)+Sheet1!$B$17 -> 19.477154 | N24: =J24-(0.25*$J$38) -> -1.7428425 | O24: =K24-(0.25*$K$38)+Sheet1!$B$17 -> 19.087532 | P24: =D24*$B$3 -> 0.19364917 | Q24: =E24*$B$3 -> 0.50348784 | R24: =F24*$B$3 -> 0.19364917 | S24: =G24*$B$3 -> 0.11386571 | T24: =P24-(0.25*$R$38) -> -1.7428425 | U24: =Q24-(0.25*$S$38)+Sheet1!$B$17 -> 19.477154 | V24: =R24-(0.25*$R$38) -> -1.7428425 | W24: =S24-(0.25*$S$38)+Sheet1!$B$17 -> 19.087532 | X24: =L24 -> -1.7428425 | Y24: =M24*COS($B$5) -> 19.352049 | Z24: =M24*SIN($B$5) -> 2.204023 | AA24: =N24 -> -1.7428425 | AB24: =O24*COS($B$5) -> 18.96493 | AC24: =O24*SIN($B$5) -> 2.1599336 | AD24: =SQRT(((X24-X23)^2)+((Y24-Y23)^2)+((Z23-Z24)^2)) -> 0.12645157 | AE24: =SQRT(((T23-T24)^2)+((U23-U24)^2)) -> 0.12645157 | AF24: =SQRT(((T24-X24)^2)+((U24-Y24)^2)+(Z24^2)) -> 2.2075708 | AG24: =SQRT(((T24-X25)^2)+((U24-Y25)^2)+(Z25^2)) -> 2.2248061 | AH24: =ACOS(((AF24^2)+(AG24^2)-(AD25^2))/(2*AF24*AG24))-AI23 -> 0.099887448 | AI24: =ACOS(((AF25^2)+(AG24^2)-(AE25^2))/(2*AF25*AG24))-AH24 -> 1.3322676e-15 | AJ24: =-COS(AI23)*AF24+AL24 -> -0.013169098 | AK24: =SIN(AI23)*AF24+AM24 -> 0.30557895 | AL24: =COS(AH23)*AG23+AJ23 -> 2.1944017 | AM24: =SIN(AH23)*AG23+AK23 -> 0.30557895 | AN24: =SQRT(((AA24-AA23)^2)+((AB24-AB23)^2)+((AC23-AC24)^2)) -> 0.10317267 | AO24: =SQRT(((V23-V24)^2)+((W23-W24)^2)) -> 0.10317267 | AP24: =SQRT(((V24-AA24)^2)+((W24-AB24)^2)+(AC24^2)) -> 2.1634104 | AQ24: =SQRT(((V24-AA25)^2)+((W24-AB25)^2)+(AC25^2)) -> 2.1701008 | AR24: =ACOS(((AP24^2)+(AQ24^2)-(AN25^2))/(2*AP24*AQ24)) -> 0.091413776 | AS24: =ACOS(((AP25^2)+(AQ24^2)-(AO25^2))/(2*AP25*AQ24))-AR24 -> -1.110223e-15 | AT24: =-COS(AS23)*AP24+AV24 -> 0.0089110895 | AU24: =SIN(AS23)*AP24+AW24 -> 0.30557895 | AV24: =COS(AR23)*AQ23+AT23 -> 2.1723215 | AW24: =SIN(AH23)*AG23+AK23 -> 0.30557895 | AY24: C | AZ24: =N32 -> 1.9364917 | BA24: =O32 -> 18.973666 | BB24: =SQRT(((AZ24-Sheet1!$B$24)^2)+((BA24-Sheet1!$B$25)^2)) -> 22.188556
D25: =Sheet1!S6 -> 0.05 | E25: =Sheet1!T6 -> 0.079 | F25: =Sheet1!U6 -> 0.05 | G25: =Sheet1!V6 -> 0.0093 | H25: =D25*$B$2 -> 0.38729833 | I25: =E25*$B$2 -> 0.61193137 | J25: =F25*$B$2 -> 0.38729833 | K25: =G25*$B$2 -> 0.07203749 | L25: =H25-(0.25*$J$38) -> -1.5491933 | M25: =I25-(0.25*$K$38)+Sheet1!$B$17 -> 19.585597 | N25: =J25-(0.25*$J$38) -> -1.5491933 | O25: =K25-(0.25*$K$38)+Sheet1!$B$17 -> 19.045703 | P25: =D25*$B$3 -> 0.38729833 | Q25: =E25*$B$3 -> 0.61193137 | R25: =F25*$B$3 -> 0.38729833 | S25: =G25*$B$3 -> 0.07203749 | T25: =P25-(0.25*$R$38) -> -1.5491933 | U25: =Q25-(0.25*$S$38)+Sheet1!$B$17 -> 19.585597 | V25: =R25-(0.25*$R$38) -> -1.5491933 | W25: =S25-(0.25*$S$38)+Sheet1!$B$17 -> 19.045703 | X25: =L25 -> -1.5491933 | Y25: =M25*COS($B$5) -> 19.459796 | Z25: =M25*SIN($B$5) -> 2.2162944 | AA25: =N25 -> -1.5491933 | AB25: =O25*COS($B$5) -> 18.92337 | AC25: =O25*SIN($B$5) -> 2.1552003 | AD25: =SQRT(((X25-X24)^2)+((Y25-Y24)^2)+((Z24-Z25)^2)) -> 0.22194594 | AE25: =SQRT(((T24-T25)^2)+((U24-U25)^2)) -> 0.22194594 | AF25: =SQRT(((T25-X25)^2)+((U25-Y25)^2)+(Z25^2)) -> 2.2198619 | AG25: =SQRT(((T25-X26)^2)+((U25-Y26)^2)+(Z26^2)) -> 2.2336554 | AH25: =ACOS(((AF25^2)+(AG25^2)-(AD26^2))/(2*AF25*AG25))-AI24 -> 0.092859147 | AI25: =ACOS(((AF26^2)+(AG25^2)-(AE26^2))/(2*AF26*AG25))-AH25 -> 4.8849813e-15 | AJ25: =-COS(AI24)*AF25+AL25 -> -0.019314677 | AK25: =SIN(AI24)*AF25+AM25 -> 0.52743979 | AL25: =COS(AH24)*AG24+AJ24 -> 2.2005472 | AM25: =SIN(AH24)*AG24+AK24 -> 0.52743979 | AN25: =SQRT(((AA25-AA24)^2)+((AB25-AB24)^2)+((AC24-AC25)^2)) -> 0.19811512 | AO25: =SQRT(((V24-V25)^2)+((W24-W25)^2)) -> 0.19811512 | AP25: =SQRT(((V25-AA25)^2)+((W25-AB25)^2)+(AC25^2)) -> 2.1586695 | AQ25: =SQRT(((V25-AA26)^2)+((W25-AB26)^2)+(AC26^2)) -> 2.1661506 | AR25: =ACOS(((AP25^2)+(AQ25^2)-(AN26^2))/(2*AP25*AQ25)) -> 0.090159239 | AS25: =ACOS(((AP26^2)+(AQ25^2)-(AO26^2))/(2*AP26*AQ25))-AR25 -> 1.3322676e-15 | AT25: =-COS(AS24)*AP25+AV25 -> 0.011281527 | AU25: =SIN(AS24)*AP25+AW25 -> 0.52743979 | AV25: =COS(AR24)*AQ24+AT24 -> 2.169951 | AW25: =SIN(AH24)*AG24+AK24 -> 0.52743979 | AY25: D | AZ25: =(N34+N35)/2 -> 3.8729833 | BA25: =(O34+O35)/2 -> 18.973666 | BB25: =SQRT(((AZ25-Sheet1!$B$24)^2)+((BA25-Sheet1!$B$25)^2)) -> 23.019862
D26: =Sheet1!S7 -> 0.075 | E26: =Sheet1!T7 -> 0.0885 | F26: =Sheet1!U7 -> 0.075 | G26: =Sheet1!V7 -> 0.0063 | H26: =D26*$B$2 -> 0.5809475 | I26: =E26*$B$2 -> 0.68551805 | J26: =F26*$B$2 -> 0.5809475 | K26: =G26*$B$2 -> 0.04879959 | L26: =H26-(0.25*$J$38) -> -1.3555442 | M26: =I26-(0.25*$K$38)+Sheet1!$B$17 -> 19.659184 | N26: =J26-(0.25*$J$38) -> -1.3555442 | O26: =K26-(0.25*$K$38)+Sheet1!$B$17 -> 19.022466 | P26: =D26*$B$3 -> 0.5809475 | Q26: =E26*$B$3 -> 0.68551805 | R26: =F26*$B$3 -> 0.5809475 | S26: =G26*$B$3 -> 0.04879959 | T26: =P26-(0.25*$R$38) -> -1.3555442 | U26: =Q26-(0.25*$S$38)+Sheet1!$B$17 -> 19.659184 | V26: =R26-(0.25*$R$38) -> -1.3555442 | W26: =S26-(0.25*$S$38)+Sheet1!$B$17 -> 19.022466 | X26: =L26 -> -1.3555442 | Y26: =M26*COS($B$5) -> 19.53291 | Z26: =M26*SIN($B$5) -> 2.2246214 | AA26: =N26 -> -1.3555442 | AB26: =O26*COS($B$5) -> 18.900281 | AC26: =O26*SIN($B$5) -> 2.1525708 | AD26: =SQRT(((X26-X25)^2)+((Y26-Y25)^2)+((Z25-Z26)^2)) -> 0.20715936 | AE26: =SQRT(((T25-T26)^2)+((U25-U26)^2)) -> 0.20715936 | AF26: =SQRT(((T26-X26)^2)+((U26-Y26)^2)+(Z26^2)) -> 2.2282023 | AG26: =SQRT(((T26-X27)^2)+((U26-Y27)^2)+(Z27^2)) -> 2.2406321 | AH26: =ACOS(((AF26^2)+(AG26^2)-(AD27^2))/(2*AF26*AG26))-AI25 -> 0.090342408 | AI26: =ACOS(((AF27^2)+(AG26^2)-(AE27^2))/(2*AF27*AG26))-AH26 -> 2.4424907e-15 | AJ26: =-COS(AI25)*AF26+AL26 -> -0.023484891 | AK26: =SIN(AI25)*AF26+AM26 -> 0.73455717 | AL26: =COS(AH25)*AG25+AJ25 -> 2.2047174 | AM26: =SIN(AH25)*AG25+AK25 -> 0.73455717 | AN26: =SQRT(((AA26-AA25)^2)+((AB26-AB25)^2)+((AC25-AC26)^2)) -> 0.19503846 | AO26: =SQRT(((V25-V26)^2)+((W25-W26)^2)) -> 0.19503846 | AP26: =SQRT(((V26-AA26)^2)+((W26-AB26)^2)+(AC26^2)) -> 2.1560357 | AQ26: =SQRT(((V26-AA27)^2)+((W26-AB27)^2)+(AC27^2)) -> 2.1638575 | AR26: =ACOS(((AP26^2)+(AQ26^2)-(AN27^2))/(2*AP26*AQ26)) -> 0.089927891 | AS26: =ACOS(((AP27^2)+(AQ26^2)-(AO27^2))/(2*AP27*AQ26))-AR26 -> 1.3322676e-15 | AT26: =-COS(AS25)*AP26+AV26 -> 0.012598437 | AU26: =SIN(AS25)*AP26+AW26 -> 0.73455717 | AV26: =COS(AR25)*AQ25+AT25 -> 2.1686341 | AW26: =SIN(AH25)*AG25+AK25 -> 0.73455717 | AY26: B | AZ26: =N38 -> 5.809475 | BA26: =O38 -> 18.973666 | BB26: =SQRT(((AZ26-Sheet1!$B$24)^2)+((BA26-Sheet1!$B$25)^2)) -> 23.979075
D27: =Sheet1!S8 -> 0.1 | E27: =Sheet1!T8 -> 0.096 | F27: =Sheet1!U8 -> 0.1 | G27: =Sheet1!V8 -> 0.0042 | H27: =D27*$B$2 -> 0.77459667 | I27: =E27*$B$2 -> 0.7436128 | J27: =F27*$B$2 -> 0.77459667 | K27: =G27*$B$2 -> 0.03253306 | L27: =H27-(0.25*$J$38) -> -1.161895 | M27: =I27-(0.25*$K$38)+Sheet1!$B$17 -> 19.717279 | N27: =J27-(0.25*$J$38) -> -1.161895 | O27: =K27-(0.25*$K$38)+Sheet1!$B$17 -> 19.006199 | P27: =D27*$B$3 -> 0.77459667 | Q27: =E27*$B$3 -> 0.7436128 | R27: =F27*$B$3 -> 0.77459667 | S27: =G27*$B$3 -> 0.03253306 | T27: =P27-(0.25*$R$38) -> -1.161895 | U27: =Q27-(0.25*$S$38)+Sheet1!$B$17 -> 19.717279 | V27: =R27-(0.25*$R$38) -> -1.161895 | W27: =S27-(0.25*$S$38)+Sheet1!$B$17 -> 19.006199 | X27: =L27 -> -1.161895 | Y27: =M27*COS($B$5) -> 19.590632 | Z27: =M27*SIN($B$5) -> 2.2311954 | AA27: =N27 -> -1.161895 | AB27: =O27*COS($B$5) -> 18.884119 | AC27: =O27*SIN($B$5) -> 2.1507301 | AD27: =SQRT(((X27-X26)^2)+((Y27-Y26)^2)+((Z26-Z27)^2)) -> 0.20217567 | AE27: =SQRT(((T26-T27)^2)+((U26-U27)^2)) -> 0.20217567 | AF27: =SQRT(((T27-X27)^2)+((U27-Y27)^2)+(Z27^2)) -> 2.2347869 | AG27: =SQRT(((T27-X28)^2)+((U27-Y28)^2)+(Z28^2)) -> 2.2743762 | AH27: =ACOS(((AF27^2)+(AG27^2)-(AD28^2))/(2*AF27*AG27))-AI26 -> 0.17516888 | AI27: =ACOS(((AF28^2)+(AG27^2)-(AE28^2))/(2*AF28*AG27))-AH27 -> 3.1086245e-15 | AJ27: =-COS(AI26)*AF27+AL27 -> -0.026777165 | AK27: =SIN(AI26)*AF27+AM27 -> 0.93670602 | AL27: =COS(AH26)*AG26+AJ26 -> 2.2080097 | AM27: =SIN(AH26)*AG26+AK26 -> 0.93670602 | AN27: =SQRT(((AA27-AA26)^2)+((AB27-AB26)^2)+((AC26-AC27)^2)) -> 0.19433116 | AO27: =SQRT(((V26-V27)^2)+((W26-W27)^2)) -> 0.19433116 | AP27: =SQRT(((V27-AA27)^2)+((W27-AB27)^2)+(AC27^2)) -> 2.154192 | AQ27: =SQRT(((V27-AA28)^2)+((W27-AB28)^2)+(AC28^2)) -> 2.1876641 | AR27: =ACOS(((AP27^2)+(AQ27^2)-(AN28^2))/(2*AP27*AQ27)) -> 0.17823671 | AS27: =ACOS(((AP28^2)+(AQ27^2)-(AO28^2))/(2*AP28*AQ27))-AR27 -> -6.6613381e-16 | AT27: =-COS(AS26)*AP27+AV27 -> 0.013520274 | AU27: =SIN(AS26)*AP27+AW27 -> 0.93670602 | AV27: =COS(AR26)*AQ26+AT26 -> 2.1677123 | AW27: =SIN(AH26)*AG26+AK26 -> 0.93670602
D28: =Sheet1!S9 -> 0.15 | E28: =Sheet1!T9 -> 0.1069 | F28: =Sheet1!U9 -> 0.15 | G28: =Sheet1!V9 -> 0.0015 | H28: =D28*$B$2 -> 1.161895 | I28: =E28*$B$2 -> 0.82804384 | J28: =F28*$B$2 -> 1.161895 | K28: =G28*$B$2 -> 0.01161895 | L28: =H28-(0.25*$J$38) -> -0.77459667 | M28: =I28-(0.25*$K$38)+Sheet1!$B$17 -> 19.80171 | N28: =J28-(0.25*$J$38) -> -0.77459667 | O28: =K28-(0.25*$K$38)+Sheet1!$B$17 -> 18.985285 | P28: =D28*$B$3 -> 1.161895 | Q28: =E28*$B$3 -> 0.82804384 | R28: =F28*$B$3 -> 1.161895 | S28: =G28*$B$3 -> 0.01161895 | T28: =P28-(0.25*$R$38) -> -0.77459667 | U28: =Q28-(0.25*$S$38)+Sheet1!$B$17 -> 19.80171 | V28: =R28-(0.25*$R$38) -> -0.77459667 | W28: =S28-(0.25*$S$38)+Sheet1!$B$17 -> 18.985285 | X28: =L28 -> -0.77459667 | Y28: =M28*COS($B$5) -> 19.67452 | Z28: =M28*SIN($B$5) -> 2.2407496 | AA28: =N28 -> -0.77459667 | AB28: =O28*COS($B$5) -> 18.86334 | AC28: =O28*SIN($B$5) -> 2.1483634 | AD28: =SQRT(((X28-X27)^2)+((Y28-Y27)^2)+((Z27-Z28)^2)) -> 0.3963945 | AE28: =SQRT(((T27-T28)^2)+((U27-U28)^2)) -> 0.3963945 | AF28: =SQRT(((T28-X28)^2)+((U28-Y28)^2)+(Z28^2)) -> 2.2443564 | AG28: =SQRT(((T28-X29)^2)+((U28-Y29)^2)+(Z29^2)) -> 2.2810153 | AH28: =ACOS(((AF28^2)+(AG28^2)-(AD29^2))/(2*AF28*AG28))-AI27 -> 0.17215393 | AI28: =ACOS(((AF29^2)+(AG28^2)-(AE29^2))/(2*AF29*AG28))-AH28 -> 3.7747583e-15 | AJ28: =-COS(AI27)*AF28+AL28 -> -0.031561938 | AK28: =SIN(AI27)*AF28+AM28 -> 1.3330716 | AL28: =COS(AH27)*AG27+AJ27 -> 2.2127945 | AM28: =SIN(AH27)*AG27+AK27 -> 1.3330716 | AN28: =SQRT(((AA28-AA27)^2)+((AB28-AB27)^2)+((AC27-AC28)^2)) -> 0.3878626 | AO28: =SQRT(((V27-V28)^2)+((W27-W28)^2)) -> 0.3878626 | AP28: =SQRT(((V28-AA28)^2)+((W28-AB28)^2)+(AC28^2)) -> 2.1518216 | AQ28: =SQRT(((V28-AA29)^2)+((W28-AB29)^2)+(AC29^2)) -> 2.1858992 | AR28: =ACOS(((AP28^2)+(AQ28^2)-(AN29^2))/(2*AP28*AQ28)) -> 0.17817238 | AS28: =ACOS(((AP29^2)+(AQ28^2)-(AO29^2))/(2*AP29*AQ28))-AR28 -> 6.6613381e-16 | AT28: =-COS(AS27)*AP28+AV28 -> 0.014705493 | AU28: =SIN(AS27)*AP28+AW28 -> 1.3330716 | AV28: =COS(AR27)*AQ27+AT27 -> 2.1665271 | AW28: =SIN(AH27)*AG27+AK27 -> 1.3330716
D29: =Sheet1!S10 -> 0.2 | E29: =Sheet1!T10 -> 0.1136 | F29: =Sheet1!U10 -> 0.2 | G29: =Sheet1!V10 -> 0.0003 | H29: =D29*$B$2 -> 1.5491933 | I29: =E29*$B$2 -> 0.87994182 | J29: =F29*$B$2 -> 1.5491933 | K29: =G29*$B$2 -> 0.00232379 | L29: =H29-(0.25*$J$38) -> -0.38729833 | M29: =I29-(0.25*$K$38)+Sheet1!$B$17 -> 19.853608 | N29: =J29-(0.25*$J$38) -> -0.38729833 | O29: =K29-(0.25*$K$38)+Sheet1!$B$17 -> 18.97599 | P29: =D29*$B$3 -> 1.5491933 | Q29: =E29*$B$3 -> 0.87994182 | R29: =F29*$B$3 -> 1.5491933 | S29: =G29*$B$3 -> 0.00232379 | T29: =P29-(0.25*$R$38) -> -0.38729833 | U29: =Q29-(0.25*$S$38)+Sheet1!$B$17 -> 19.853608 | V29: =R29-(0.25*$R$38) -> -0.38729833 | W29: =S29-(0.25*$S$38)+Sheet1!$B$17 -> 18.97599 | X29: =L29 -> -0.38729833 | Y29: =M29*COS($B$5) -> 19.726085 | Z29: =M29*SIN($B$5) -> 2.2466223 | AA29: =N29 -> -0.38729833 | AB29: =O29*COS($B$5) -> 18.854104 | AC29: =O29*SIN($B$5) -> 2.1473116 | AD29: =SQRT(((X29-X28)^2)+((Y29-Y28)^2)+((Z28-Z29)^2)) -> 0.39076003 | AE29: =SQRT(((T28-T29)^2)+((U28-U29)^2)) -> 0.39076003 | AF29: =SQRT(((T29-X29)^2)+((U29-Y29)^2)+(Z29^2)) -> 2.2502386 | AG29: =SQRT(((T29-X30)^2)+((U29-Y30)^2)+(Z30^2)) -> 2.3813829 | AH29: =ACOS(((AF29^2)+(AG29^2)-(AD30^2))/(2*AF29*AG29))-AI28 -> 0.33149726 | AI29: =ACOS(((AF30^2)+(AG29^2)-(AE30^2))/(2*AF30*AG29))-AH29 -> 3.9968029e-15 | AJ29: =-COS(AI28)*AF29+AL29 -> -0.034503036 | AK29: =SIN(AI28)*AF29+AM29 -> 1.7238206 | AL29: =COS(AH28)*AG28+AJ28 -> 2.2157356 | AM29: =SIN(AH28)*AG28+AK28 -> 1.7238206 | AN29: =SQRT(((AA29-AA28)^2)+((AB29-AB28)^2)+((AC28-AC29)^2)) -> 0.38740986 | AO29: =SQRT(((V28-V29)^2)+((W28-W29)^2)) -> 0.38740986 | AP29: =SQRT(((V29-AA29)^2)+((W29-AB29)^2)+(AC29^2)) -> 2.150768 | AQ29: =SQRT(((V29-AA30)^2)+((W29-AB30)^2)+(AC30^2)) -> 2.2858788 | AR29: =ACOS(((AP29^2)+(AQ29^2)-(AN30^2))/(2*AP29*AQ29)) -> 0.34570831 | AS29: =ACOS(((AP30^2)+(AQ29^2)-(AO30^2))/(2*AP30*AQ29))-AR29 -> 0 | AT29: =-COS(AS28)*AP29+AV29 -> 0.015232256 | AU29: =SIN(AS28)*AP29+AW29 -> 1.7238206 | AV29: =COS(AR28)*AQ28+AT28 -> 2.1660003 | AW29: =SIN(AH28)*AG28+AK28 -> 1.7238206
D30: =Sheet1!S11 -> 0.3 | E30: =Sheet1!T11 -> 0.117 | F30: =Sheet1!U11 -> 0.3 | G30: =Sheet1!V11 -> 0 | H30: =D30*$B$2 -> 2.32379 | I30: =E30*$B$2 -> 0.9062781 | J30: =F30*$B$2 -> 2.32379 | K30: =G30*$B$2 -> 0 | L30: =H30-(0.25*$J$38) -> 0.38729833 | M30: =I30-(0.25*$K$38)+Sheet1!$B$17 -> 19.879944 | N30: =J30-(0.25*$J$38) -> 0.38729833 | O30: =K30-(0.25*$K$38)+Sheet1!$B$17 -> 18.973666 | P30: =D30*$B$3 -> 2.32379 | Q30: =E30*$B$3 -> 0.9062781 | R30: =F30*$B$3 -> 2.32379 | S30: =G30*$B$3 -> 0 | T30: =P30-(0.25*$R$38) -> 0.38729833 | U30: =Q30-(0.25*$S$38)+Sheet1!$B$17 -> 19.879944 | V30: =R30-(0.25*$R$38) -> 0.38729833 | W30: =S30-(0.25*$S$38)+Sheet1!$B$17 -> 18.973666 | X30: =L30 -> 0.38729833 | Y30: =M30*COS($B$5) -> 19.752252 | Z30: =M30*SIN($B$5) -> 2.2496025 | AA30: =N30 -> 0.38729833 | AB30: =O30*COS($B$5) -> 18.851795 | AC30: =O30*SIN($B$5) -> 2.1470486 | AD30: =SQRT(((X30-X29)^2)+((Y30-Y29)^2)+((Z29-Z30)^2)) -> 0.77504426 | AE30: =SQRT(((T29-T30)^2)+((U29-U30)^2)) -> 0.77504426 | AF30: =SQRT(((T30-X30)^2)+((U30-Y30)^2)+(Z30^2)) -> 2.2532236 | AG30: =SQRT(((T30-X31)^2)+((U30-Y31)^2)+(Z31^2)) -> 2.3815168 | AH30: =ACOS(((AF30^2)+(AG30^2)-(AD31^2))/(2*AF30*AG30))-AI29 -> 0.33143405 | AI30: =ACOS(((AF31^2)+(AG30^2)-(AE31^2))/(2*AF31*AG30))-AH30 -> 3.9968029e-15 | AJ30: =-COS(AI29)*AF30+AL30 -> -0.035995534 | AK30: =SIN(AI29)*AF30+AM30 -> 2.4988634 | AL30: =COS(AH29)*AG29+AJ29 -> 2.2172281 | AM30: =SIN(AH29)*AG29+AK29 -> 2.4988634 | AN30: =SQRT(((AA30-AA29)^2)+((AB30-AB29)^2)+((AC29-AC30)^2)) -> 0.77460015 | AO30: =SQRT(((V29-V30)^2)+((W29-W30)^2)) -> 0.77460015 | AP30: =SQRT(((V30-AA30)^2)+((W30-AB30)^2)+(AC30^2)) -> 2.1505047 | AQ30: =SQRT(((V30-AA31)^2)+((W30-AB31)^2)+(AC31^2)) -> 2.2857538 | AR30: =ACOS(((AP30^2)+(AQ30^2)-(AN31^2))/(2*AP30*AQ30)) -> 0.3457264 | AS30: =ACOS(((AP31^2)+(AQ30^2)-(AO31^2))/(2*AP31*AQ30))-AR30 -> 0 | AT30: =-COS(AS29)*AP30+AV30 -> 0.015363947 | AU30: =SIN(AS29)*AP30+AW30 -> 2.4988634 | AV30: =COS(AR29)*AQ29+AT29 -> 2.1658686 | AW30: =SIN(AH29)*AG29+AK29 -> 2.4988634
D31: =Sheet1!S12 -> 0.4 | E31: =Sheet1!T12 -> 0.114 | F31: =Sheet1!U12 -> 0.4 | G31: =Sheet1!V12 -> 0 | H31: =D31*$B$2 -> 3.0983867 | I31: =E31*$B$2 -> 0.8830402 | J31: =F31*$B$2 -> 3.0983867 | K31: =G31*$B$2 -> 0 | L31: =H31-(0.25*$J$38) -> 1.161895 | M31: =I31-(0.25*$K$38)+Sheet1!$B$17 -> 19.856706 | N31: =J31-(0.25*$J$38) -> 1.161895 | O31: =K31-(0.25*$K$38)+Sheet1!$B$17 -> 18.973666 | P31: =D31*$B$3 -> 3.0983867 | Q31: =E31*$B$3 -> 0.8830402 | R31: =F31*$B$3 -> 3.0983867 | S31: =G31*$B$3 -> 0 | T31: =P31-(0.25*$R$38) -> 1.161895 | U31: =Q31-(0.25*$S$38)+Sheet1!$B$17 -> 19.856706 | V31: =R31-(0.25*$R$38) -> 1.161895 | W31: =S31-(0.25*$S$38)+Sheet1!$B$17 -> 18.973666 | X31: =L31 -> 1.161895 | Y31: =M31*COS($B$5) -> 19.729163 | Z31: =M31*SIN($B$5) -> 2.2469729 | AA31: =N31 -> 1.161895 | AB31: =O31*COS($B$5) -> 18.851795 | AC31: =O31*SIN($B$5) -> 2.1470486 | AD31: =SQRT(((X31-X30)^2)+((Y31-Y30)^2)+((Z30-Z31)^2)) -> 0.77494516 | AE31: =SQRT(((T30-T31)^2)+((U30-U31)^2)) -> 0.77494516 | AF31: =SQRT(((T31-X31)^2)+((U31-Y31)^2)+(Z31^2)) -> 2.2505898 | AG31: =SQRT(((T31-X32)^2)+((U31-Y32)^2)+(Z32^2)) -> 2.3774804 | AH31: =ACOS(((AF31^2)+(AG31^2)-(AD32^2))/(2*AF31*AG31))-AI30 -> 0.33319159 | AI31: =ACOS(((AF32^2)+(AG31^2)-(AE32^2))/(2*AF32*AG31))-AH31 -> 3.9968029e-15 | AJ31: =-COS(AI30)*AF31+AL31 -> -0.034678624 | AK31: =SIN(AI30)*AF31+AM31 -> 3.2738075 | AL31: =COS(AH30)*AG30+AJ30 -> 2.2159112 | AM31: =SIN(AH30)*AG30+AK30 -> 3.2738075 | AN31: =SQRT(((AA31-AA30)^2)+((AB31-AB30)^2)+((AC30-AC31)^2)) -> 0.77459667 | AO31: =SQRT(((V30-V31)^2)+((W30-W31)^2)) -> 0.77459667 | AP31: =SQRT(((V31-AA31)^2)+((W31-AB31)^2)+(AC31^2)) -> 2.1505047 | AQ31: =SQRT(((V31-AA32)^2)+((W31-AB32)^2)+(AC32^2)) -> 2.2857538 | AR31: =ACOS(((AP31^2)+(AQ31^2)-(AN32^2))/(2*AP31*AQ31)) -> 0.3457264 | AS31: =ACOS(((AP32^2)+(AQ31^2)-(AO32^2))/(2*AP32*AQ31))-AR31 -> 0 | AT31: =-COS(AS30)*AP31+AV31 -> 0.015363947 | AU31: =SIN(AS30)*AP31+AW31 -> 3.2738075 | AV31: =COS(AR30)*AQ30+AT30 -> 2.1658686 | AW31: =SIN(AH30)*AG30+AK30 -> 3.2738075
