Workbook
Name Disability_Type: options!$A$7:$A$20
Name dist: data!$A$2:$A$616
Name Inclusion: options!$A$32:$A$34
Name Options: options!$A$2:$A$4
Name Placement: options!$A$23:$A$29

Sheet SF-6 Form per Capita
O4: =NOW() -> 41654.45
L9: Center for School Options and Finance
L10: Office of Finance Program Services
L11: SF-6
L12: School Age Form
L13: for Per Capita Calculation
L14: Report To Certify the Excess Cost For School District School-Age Pupils
L15: Who Were Provided Special Education and Related Services
L16: To be filed by educating district (3323.14 O.R.C.) for school year 2012-2013
C18: Section I.
E19: Educating District - City, Exempted Village or Local
F20: Ada Ex Vill SD (045187, Hardin County)
C23: Section II. Salaries, Benefits, and General Student Costs (General Fund) | N23: Actual Costs | O23: Students with disabilities (excluding speech 05) counted in EFM ADM | P23: Cost per FTE (Column N/ Column O)
D24: 1. | E24: Special Education Salaries and Benefits
D25: A. | E25: Special Education teacher salaries and benefits by district (Functions 1220, 1230 and 1240 and objects 11x, 12x, 131, 21x, 24x, 261)) | N25: =IF(F$20<>"Please select a district.",VLOOKUP(F$20,data!A$3:M$616,5,FALSE),"") -> 258311.59 | O25: =IF(F$20<>"Please select a district.",VLOOKUP(F$20,data!A$3:M$616,4,FALSE),"") -> 73.543579 | P25: =IF(F$20<>"Please select a district.",N25/O25,"") -> 3512.3609
D26: 2. | E26: Instructional Salaries and Benefits by districts | N26: Reported Costs | O26: EFM ADM | P26: Cost per FTE (Column N/ Column O)
E27: Teacher salaries and benefits by district (functions 11xx, objects 11x, 12x, 131, 21x, 24x, 261)) | N27: =IF(F$20<>"Please select a district.",VLOOKUP(F$20,data!A$3:M$616,6,FALSE),"") -> 3403388.6 | O27: =IF(F$20<>"Please select a district.",VLOOKUP(F$20,data!A$3:M$616,13,FALSE),"") -> 895.11318 | P27: =IF(F$20<>"Please select a district.",N27/O27,"") -> 3802.1879
C28: Section III. General Student Costs (General Fund) | N28: Reported Costs | O28: EFM ADM | P28: Cost per FTE (Column N/ Column O)
D29: 3. Instructional Supplies and Materials By District
D30: Instructional Supplies and Materials (Func 1XXX - Obj 5XX) | N30: =IF(F$20<>"Please select a district.",VLOOKUP(F$20,data!A$3:M$616,7,FALSE),"") -> 39513.79 | O30: =IF(F$20<>"Please select a district.",VLOOKUP(F$20,data!A$3:M$616,13,FALSE),"") -> 895.11318 | P30: =IF(F$20<>"Please select a district.",N30/O30,"") -> 44.143903
D31: 4. Instructional Equipment
D32: Instructional Equipment (Func 1XXX - Obj 6XX, Obj 7XX) | N32: =IF(F$20<>"Please select a district.",VLOOKUP(F$20,data!A$3:M$616,8,FALSE),"") -> 1625.99 | O32: =IF(F$20<>"Please select a district.",VLOOKUP(F$20,data!A$3:M$616,13,FALSE),"") -> 895.11318 | P32: =IF(F$20<>"Please select a district.",N32/O32,"") -> 1.8165189
D33: 5. Administration Costs - By District from EFM Report | N33: =IF(F$20<>"Please select a district.",VLOOKUP(F$20,data!A$3:M$616,9,FALSE),"") -> 1029606.7 | O33: =IF(F$20<>"Please select a district.",VLOOKUP(F$20,data!A$3:M$616,13,FALSE),"") -> 895.11318 | P33: =IF(F$20<>"Please select a district.",N33/O33,"") -> 1150.2531
D34: 6. Operations Support Costs - By District from EFM Report | N34: =IF(F$20<>"Please select a district.",VLOOKUP(F$20,data!A$3:M$616,10,FALSE),"") -> 1051317.6 | O34: =IF(F$20<>"Please select a district.",VLOOKUP(F$20,data!A$3:M$616,13,FALSE),"") -> 895.11318 | P34: =IF(F$20<>"Please select a district.",N34/O34,"") -> 1174.508
D35: 7. Staff Support Costs - By District from EFM Report | N35: =IF(F$20<>"Please select a district.",VLOOKUP(F$20,data!A$3:M$616,11,FALSE),"") -> 225441.78 | O35: =IF(F$20<>"Please select a district.",VLOOKUP(F$20,data!A$3:M$616,13,FALSE),"") -> 895.11318 | P35: =IF(F$20<>"Please select a district.",N35/O35,"") -> 251.85841
D36: 8. Pupil Support Costs - By District from EFM Report | N36: =IF(F$20<>"Please select a district.",VLOOKUP(F$20,data!A$3:M$616,12,FALSE),"") -> 317263.88 | O36: =IF(F$20<>"Please select a district.",VLOOKUP(F$20,data!A$3:M$616,13,FALSE),"") -> 895.11318 | P36: =IF(F$20<>"Please select a district.",N36/O36,"") -> 354.43996
C38: Section V. Totals
D39: 9. | E39: Total Cost per FTE | P39: =IF(F$20<>"Please select a district.",SUM(P30:P36,P27,P25),"") -> 10291.569
D45: City, Exempted Village or Local Superintendent Signature | M45: Treasurer Signature

Sheet SF-6 Form Specific Student
P1: =NOW() -> 41654.45
L7: Office of School Finance
L8: SF-6
L9: School Age Form
L10: for Specific Student Calculation
L11: Report To Certify the Excess Cost For School District School-Age Pupils
L12: Who Were Provided Special Education and Related Services
L13: To be filed by educating district (3323.14 O.R.C.) for school year 2012-2013
C15: Please make selections and type data only in those cells highlighted in blue.
C16: Section I.
D17: A. | E17: Educating District - City, Exempted Village or Local
F18: Please select a district.
D20: B. | E20: Resident District - City, Exempted Village or Local
F21: Please select a district.
D23: C. | E23: Student disability condition
F24: Please select a disability condition.
D26: D. | E26: Method of placement (EMIS status code).
F27: Please select a placement explanation.
D29: E. | E29: Percent of time in regular classroom (0 to 100)
F30: 0 | H30: %
C32: Section II. Salaries, Benefits, and General Student Costs (General Fund) | N32: Actual Costs | O32: Served student FTE by Disability | P32: FTE Percent | Q32: Cost per FTE (Column N/ Column O)*Column P
D33: 1. | E33: Special Education Salaries and Benefits
D34: A. | E34: Specific teacher(s) salary | P34: =IF(AND(F$18<>"Please select a district.",F30=100),1,IF(AND(F$18<>"Please select a district.",F$30<>100),(100-F30)/100,"")) | Q34: =IF(IF(O34<>"",F$18<>"Please select a district."),(N34/O34)*P34,"")
E35: Specific teacher(s) benefits | O35: =IF(AND(F18<>"Please select a district.",O34<>""),O34,"") | P35: =IF(AND(F$18<>"Please select a district.",F30=100),1,IF(AND(F$18<>"Please select a district.",F$30<>100),(100-F30)/100,"")) | Q35: =IF(AND(O34<>"",F$18<>"Please select a district."),(N35/O35)*P35,"")
D36: 2. | E36: Instructional Salaries and Benefits by districts | O36: EFM ADM
E37: Teacher salaries and benefits by district (functions 11xx, objects 11x, 12x, 131, 21x, 24x, 261)) | N37: =IF(AND(N50="",F$18<>"Please select a district."),VLOOKUP(F$18,data!A$3:M$616,6,FALSE),"") | O37: =IF(F$18<>"Please select a district.",VLOOKUP(F$18,data!A$3:M$616,13,FALSE),"") | P37: =IF(F18<>"Please select a district.",F$30/100,"") | Q37: =IF(AND(F$18<>"Please select a district.", P37<>0),(N37/O37)*P37,"")
C38: Section III. General Student Costs (General Fund) | N38: Reported Costs | O38: EFM ADM | Q38: Cost per FTE (Column N/ Column O)
D39: 3. Instructional Supplies and Materials By District
D40: Instructional Supplies and Materials (Func 1XXX - Obj 5XX) | N40: =IF(AND(N50="",F$18<>"Please select a district."),VLOOKUP(F$18,data!A$3:M$616,7,FALSE),"") | O40: =IF(F$18<>"Please select a district.",VLOOKUP(F$18,data!A$3:M$616,13,FALSE),"") | Q40: =IF(AND(F$18<>"Please select a district.",N40<>""),N40/O40,"")
D41: 4. Instructional Equipment
D42: Instructional Equipment (Func 1XXX - Obj 6XX, Obj 7XX) | N42: =IF(AND(N50="",F$18<>"Please select a district."),VLOOKUP(F$18,data!A$3:M$616,8,FALSE),"") | O42: =IF(F$18<>"Please select a district.",VLOOKUP(F$18,data!A$3:M$616,13,FALSE),"") | Q42: =IF(AND(F$18<>"Please select a district.",N42<>""),N42/O42,"")
D43: 5. Administration Costs - By District from EFM Report | N43: =IF(F$18<>"Please select a district.",VLOOKUP(F$18,data!A$3:M$616,9,FALSE),"") | O43: =IF(F$18<>"Please select a district.",VLOOKUP(F$18,data!A$3:M$616,13,FALSE),"") | Q43: =IF(AND(F$18<>"Please select a district.",N43<>""),N43/O43,"")
D44: 6. Operations Support Costs - By District from EFM Report | N44: =IF(AND(N50="",F$18<>"Please select a district."),VLOOKUP(F$18,data!A$3:M$616,10,FALSE),"") | O44: =IF(F$18<>"Please select a district.",VLOOKUP(F$18,data!A$3:M$616,13,FALSE),"") | Q44: =IF(AND(N44<>"",F$18<>"Please select a district."),N44/O44,"")
D45: 7. Staff Support Costs - By District from EFM Report | N45: =IF(AND(N50="",F$18<>"Please select a district."),VLOOKUP(F$18,data!A$3:M$616,11,FALSE),"") | O45: =IF(F$18<>"Please select a district.",VLOOKUP(F$18,data!A$3:M$616,13,FALSE),"") | Q45: =IF(AND(N45<>"",F$18<>"Please select a district."),N45/O45,"")
D46: 8. Pupil Support Costs - By District from EFM Report | N46: =IF(AND(N50="",F$18<>"Please select a district."),VLOOKUP(F$18,data!A$3:M$616,12,FALSE),"") | O46: =IF(F$18<>"Please select a district.",VLOOKUP(F$18,data!A$3:M$616,13,FALSE),"") | Q46: =IF(AND(N46<>"",F$18<>"Please select a district."),N46/O46,"")
C48: Section IV. Specific Student Costs and Related Services (General Fund). Completing these fields will replace some items automatically calculated above. | N48: Actual Costs | O48: Served student FTE by Disability | Q48: Cost per FTE (Column N/ Column O)
D49: 9. Provide itemized costs directly tied to a specific student(s).
D50: A. | E50: Contract services (include this item instead of Lines 3,4, 6, 7, and 8 above) | Q50: =IF(AND(F$18<>"Please select a district.",O50<>""),N50/O50,"")
D51: B. | E51: Supplies for specific students | Q51: =IF(AND(F$18<>"Please select a district.",O51<>""),N51/O51,"")
D52: C. | E52: Equipment for specific students | Q52: =IF(AND(F$18<>"Please select a district.",O52<>""),N52/O52,"")
...

Sheet Student level data
H1: =NOW() -> 41654.45
F5: Office of School Finance
F6: SF-6
F7: School Age Form
F9: Report To Certify the Excess Cost For School District School-Age Pupils
F10: Who Were Provided Special Education and Related Services
F11: To be filed by educating district (3323.14 O.R.C.) for school year 2012-2013
B15: Specific Student Calculation or Per Capita | C15: Student SSID | D15: Educating District | E15: Resident District | F15: Disability Condition | G15: EMIS Method of Placement Reason | H15: Dates of Enrollment | J15: Total Days Enrolled
H16: From | I16: To
A17: 1 | B17: Per capita | C17: AA1111111 | D17: 000111 | E17: 000222 | F17: 12 | G17: T | H17: 40411 | I17: 40713 | J17: 180
A18: 2
A19: 3
A20: 4
A21: 5
A22: 6
A23: 7
A24: 8
A25: 9
A26: 10
A27: 11
A28: 12
A29: 13
... A597: 581

Sheet Data Notes
A3: Sheet Name | B3: Cell | C3: Description
A4: SF-6 Form Per Capita | B4: N25 | C4: FY2013 expenditure reported to funds 001, 494, 016, and 532 and functions 122X, 123X, 124X and object codes 11X, 12X, 21X, 24X, 131 and 261
A5: SF-6 Form Per Capita | B5: N27 | C5: FY2013 expenditure reported to funds 001, 494, 016, and 532 and function 11XX and object codes 11X, 12X, 21X, 24X, 131 and 261
A6: SF-6 Form Per Capita | B6: N30 | C6: FY2013 expenditure reported to funds 001, 494, 016, and 532 and function 1XXX and object codes 5XX
A7: SF-6 Form Per Capita | B7: N32 | C7: FY2013 expenditure reported to funds 001, 494, 016, and 532 and function 1XXX and object codes 6XX and 7XX
A8: SF-6 Form Per Capita | B8: N33 | C8: FY2013 EFM General Fund administrative expenditure total
A9: SF-6 Form Per Capita | B9: N34 | C9: FY2013 EFM General Fund operations expenditure total
A10: SF-6 Form Per Capita | B10: N35 | C10: FY2013 EFM General Fund staff support expenditure total
A11: SF-6 Form Per Capita | B11: N36 | C11: FY2013 EFM General Fund pupil support expenditure total
A12: SF-6 Form Per Capita | B12: O25 | C12: FY2013 EFM ADM of those student with a disability condition excluding Speech and lanaguage (05)
A13: SF-6 Form Per Capita | B13: O27-O36 | C13: FY2013 EFM ADM total
A14: SF-6 Form Specific Student | B14: N34-N35 | C14: District submitted FY2013 data
... A28: SF-6 Form Specific Student | B28: O37-O46 | C28: FY2013 EFM ADM total

Sheet data
A1: dist | B1: SCHOOL_YEAR | C1: DIST_IRN | D1: disadm_nospch | E1: DISABILITY_SALBEN | F1: reg_salben | G1: INSTR_SUP | H1: INSTR_EQ | I1: admin_gf_total | J1: ops_gf_total | K1: staff_gf_total | L1: pupil_gf_total | M1: adm1
A2: Please select a district.
A3: Ada Ex Vill SD (045187, Hardin County) | B3: 2013 | C3: 045187 | D3: 73.543579 | E3: 258311.59 | F3: 3403388.6 | G3: 39513.79 | H3: 1625.99 | I3: 1029606.7 | J3: 1051317.6 | K3: 225441.78 | L3: 317263.88 | M3: 895.11318
A4: Adams County/Ohio Valley Local (061903, Adams County) | B4: 2013 | C4: 061903 | D4: 619.31737 | E4: 3056826.1 | F4: 12637877 | G4: 404585.18 | H4: 324961.92 | I4: 4091594.3 | J4: 4406534.8 | K4: 671700.4 | L4: 1427576.7 | M4: 3870.3596
A5: Adena Local SD (049494, Ross County) | B5: 2013 | C5: 049494 | D5: 127.13581 | E5: 315332.02 | F5: 4157448.1 | G5: 68884.79 | H5: 38608.7 | I5: 1354155 | J5: 1585922.5 | K5: 509147.5 | L5: 257592.51 | M5: 1216.1175
A6: Akron City SD (043489, Summit County) | B6: 2013 | C6: 043489 | D6: 3685.546 | E6: 26618725 | F6: 90373302 | G6: 3630531.8 | H6: 175671.07 | I6: 32105925 | J6: 41416051 | K6: 9500703.7 | L6: 17270744 | M6: 21858.043
A7: Alexander Local SD (045906, Athens County) | B7: 2013 | C7: 045906 | D7: 251.69069 | E7: 478605.28 | F7: 2500288.1 | G7: 96592.07 | H7: 103613.4 | I7: 1509541.2 | J7: 2605827.2 | K7: 499470.27 | L7: 475253 | M7: 1618.3287
A8: Allen East Local SD (045757, Allen County) | B8: 2013 | C8: 045757 | D8: 90.351566 | E8: 294491.37 | F8: 3937086.1 | G8: 30902.75 | H8: 4126.48 | I8: 1212985.9 | J8: 1336868.5 | K8: 142278.1 | L8: 327969.28 | M8: 1134.6609
A9: Alliance City SD (043497, Stark County) | B9: 2013 | C9: 043497 | D9: 473.69492 | E9: 2851236.7 | F9: 10092219 | G9: 383525.57 | H9: 32716.72 | I9: 3144028.9 | J9: 3729061.3 | K9: 377666.7 | L9: 1142979 | M9: 2826.4684
A10: Amanda-Clearcreek Local SD (046847, Fairfield County) | B10: 2013 | C10: 046847 | D10: 178.43712 | E10: 742921.28 | F10: 4452717.6 | G10: 455880.81 | H10: 161539.67 | I10: 1680111.6 | J10: 2336376.8 | K10: 149986.82 | L10: 649970.13 | M10: 1699.6096
A11: Amherst Ex Vill SD (045195, Lorain County) | B11: 2013 | C11: 045195 | D11: 564.79918 | E11: 1915106.5 | F11: 14709090 | G11: 333767.53 | H11: 74854.9 | I11: 3815741.4 | J11: 4443189.1 | K11: 1617544.6 | L11: 1631269.2 | M11: 3907.2493
A12: Anna Local SD (049759, Shelby County) | B12: 2013 | C12: 049759 | D12: 104.52196 | E12: 244554.48 | F12: 4246738.2 | G12: 248996.6 | H12: 10901.69 | I12: 1235529.9 | J12: 1435170.3 | K12: 250080.55 | L12: 417663.6 | M12: 1223.2201
A13: Ansonia Local SD (046623, Darke County) | B13: 2013 | C13: 046623 | D13: 79.11701 | E13: 468821.2 | F13: 2659319.6 | G13: 74047.57 | H13: 15911.14 | I13: 736530.15 | J13: 962498.37 | K13: 335321.16 | L13: 144733.44 | M13: 693.28239
A14: Anthony Wayne Local SD (048207, Lucas County) | B14: 2013 | C14: 048207 | D14: 332.23086 | E14: 1357138.8 | F14: 16613694 | G14: 277000.55 | H14: 0 | I14: 4292699.8 | J14: 5907296.7 | K14: 895643.67 | L14: 1784266.6 | M14: 4301.8674
... A263: Kalida Local SD (049346, Putnam County) | B263: 2013 | C263: 049346 | D263: 57.696043 | E263: 198549.61 | F263: 2441555 | G263: 72886.36 | H263: 96665.78 | I263: 840968.11 | J263: 597330.63 | K263: 213232.7 | L263: 191277.17 | M263: 616.28244
A264: Kelleys Island Local SD (046797, Erie County) | B264: 2013 | C264: 046797 | D264: #N/A | E264: 0 | F264: 44699.59 | G264: 1573.86 | H264: 0 | I264: 124152.34 | J264: 139123.68 | K264: 20924.76 | L264: 4392.45 | M264: 1.9111111
A265: Kenston Local SD (047191, Geauga County) | B265: 2013 | C265: 047191 | D265: 189.29683 | E265: 2087890.2 | F265: 14167603 | G265: 165311.73 | H265: 36291.39 | I265: 4790072.9 | J265: 6022726.1 | K265: 545376.01 | L265: 2131785.6 | M265: 2980.2308
A266: Kent City SD (044164, Portage County) | B266: 2013 | C266: 044164 | D266: 422.30652 | E266: 3348340.5 | F266: 18467484 | G266: 89635.03 | H266: 88.96 | I266: 5184907.8 | J266: 4945666.1 | K266: 955296.52 | L266: 2597801.6 | M266: 3247.19
A267: Kenton City SD (044172, Hardin County) | B267: 2013 | C267: 044172 | D267: 223.8319 | E267: 1055826.4 | F267: 7139657.4 | G267: 110912.22 | H267: 95862.07 | I267: 2201210.3 | J267: 2240522.7 | K267: 534896.44 | L267: 435564.18 | M267: 1912.3663
A268: Kettering City SD (044180, Montgomery County) | B268: 2013 | C268: 044180 | D268: 833.05769 | E268: 5893555.8 | F268: 31217010 | G268: 1599157.9 | H268: 133415.47 | I268: 9376149 | J268: 11286750 | K268: 5118959.7 | L268: 6558531.5 | M268: 7123.7483
A269: Keystone Local SD (048165, Lorain County) | B269: 2013 | C269: 048165 | D269: 141.20356 | E269: 832448.63 | F269: 5716641.8 | G269: 221227.56 | H269: 16289.59 | I269: 2094908.1 | J269: 2078706.1 | K269: 396784.06 | L269: 814041.12 | M269: 1582.2351
A270: Kings Local SD (050435, Warren County) | B270: 2013 | C270: 050435 | D270: 465.06248 | E270: 2686844.8 | F270: 16616532 | G270: 627328.34 | H270: 82937.75 | I270: 4468911.5 | J270: 6921333.4 | K270: 1076020.6 | L270: 2281302.4 | M270: 3981.3408
A271: Kirtland Local SD (047878, Lake County) | B271: 2013 | C271: 047878 | D271: 95.71749 | E271: 657049.76 | F271: 5522518 | G271: 175139.6 | H271: 27504.68 | I271: 2009844.4 | J271: 2295352.6 | K271: 279703.86 | L271: 786743.78 | M271: 1156.9768
A272: LaBrae Local SD (050245, Trumbull County) | B272: 2013 | C272: 050245 | D272: 207.63735 | E272: 584586.06 | F272: 5594617.7 | G272: 103301.52 | H272: 22492.32 | I272: 1502963.3 | J272: 1715259.8 | K272: 147875.4 | L272: 679551.16 | M272: 1436.1178
A273: Lake Local SD (049866, Stark County) | B273: 2013 | C273: 049866 | D273: 354.9144 | E273: 1652966.2 | F273: 12473015 | G273: 240187.57 | H273: 277164.8 | I273: 3871307 | J273: 4759887.7 | K273: 1413908.3 | L273: 836653.14 | M273: 3459.5981
A274: Lake Local SD (050690, Wood County) | B274: 2013 | C274: 050690 | D274: 172.13399 | E274: 0 | F274: 5713292.7 | G274: 64492.89 | H274: 8506.41 | I274: 1970250.6 | J274: 2071386.1 | K274: 240822.74 | L274: 400587.36 | M274: 1618.1875
A275: Lakeview Local SD (050187, Trumbull County) | B275: 2013 | C275: 050187 | D275: 168.38246 | E275: 823690.73 | F275: 6561583.2 | G275: 357854.23 | H275: 0 | I275: 1540561.5 | J275: 1482062.8 | K275: 677886.97 | L275: 816301.65 | M275: 1815.379
A276: Lakewood City SD (044198, Cuyahoga County) | B276: 2013 | C276: 044198 | D276: 651.86033 | E276: 6815065.1 | F276: 23607254 | G276: 537533.75 | H276: 379568.15 | I276: 6789587.2 | J276: 7445434.8 | K276: 2905763.9 | L276: 3239523.4 | M276: 5426.2564
... A342: Miamisburg City SD (044396, Montgomery County) | B342: 2013 | C342: 044396 | D342: 756.53297 | E342: 3168424.8 | F342: 18564191 | G342: 260723.61 | H342: 0 | I342: 4953857.9 | J342: 6579069.6 | K342: 1081859.5 | L342: 3114400.7 | M342: 5314.2889
A343: Middle Bass Local SD (048959, Ottawa County) | B343: 2013 | C343: 048959 | D343: #N/A | E343: #N/A | F343: #N/A | G343: #N/A | H343: #N/A | I343: 34563.15 | J343: 120601.46 | K343: 0 | L343: 0 | M343: #N/A
A344: Middletown City SD (044404, Butler County) | B344: 2013 | C344: 044404 | D344: 907.74976 | E344: 5181895.7 | F344: 25107217 | G344: 417225.95 | H344: 0 | I344: 7131053.8 | J344: 8446021 | K344: 1227634.2 | L344: 4043775.7 | M344: 6275.2782
A345: Midview Local SD (048173, Lorain County) | B345: 2013 | C345: 048173 | D345: 319.37144 | E345: 1052757.6 | F345: 11990741 | G345: 195874.81 | H345: 52361.3 | I345: 3229871 | J345: 4054475.8 | K345: 744584.84 | L345: 901275.3 | M345: 3149.0172
A346: Milford Ex Vill SD (045500, Clermont County) | B346: 2013 | C346: 045500 | D346: 657.78056 | E346: 3704126.4 | F346: 23412149 | G346: 564270.35 | H346: 153792.23 | I346: 5844238.4 | J346: 9864357 | K346: 1081072.2 | L346: 1834266.1 | M346: 6135.8599
A347: Millcreek-West Unity Local SD (050633, Williams County) | B347: 2013 | C347: 050633 | D347: 78.877864 | E347: 275180.06 | F347: 2382119 | G347: 48894.6 | H347: 2793 | I347: 994451.49 | J347: 884506.65 | K347: 89811.83 | L347: 232828.02 | M347: 636.41017
A348: Miller City-New Cleveland Loca (049361, Putnam County) | B348: 2013 | C348: 049361 | D348: 35.168113 | E348: 139697.2 | F348: 1961098.8 | G348: 27387.14 | H348: 0 | I348: 496753.13 | J348: 444238.94 | K348: 131781.92 | L348: 109299.36 | M348: 458.9376
A349: Milton-Union Ex Vill SD (045518, Miami County) | B349: 2013 | C349: 045518 | D349: 177.25802 | E349: 676006.31 | F349: 5383606.6 | G349: 96636.98 | H349: 113065.3 | I349: 2036974.6 | J349: 1554892.4 | K349: 186101.06 | L349: 782756.08 | M349: 1508.0059
A350: Minerva Local SD (049890, Stark County) | B350: 2013 | C350: 049890 | D350: 246.65767 | E350: 532705.78 | F350: 6208874.7 | G350: 153459.94 | H350: 3387.55 | I350: 2166746.5 | J350: 2141592.6 | K350: 235513.45 | L350: 745867.13 | M350: 1946.8307
A351: Minford Local SD (049627, Scioto County) | B351: 2013 | C351: 049627 | D351: 176.79168 | E351: 559516.58 | F351: 5291962.3 | G351: 94951.22 | H351: 15900.02 | I351: 1534025.3 | J351: 2322112.2 | K351: 329897.24 | L351: 460518.94 | M351: 1503.3097
A352: Minster Local SD (045948, Auglaize County) | B352: 2013 | C352: 045948 | D352: 75.066591 | E352: 336231.48 | F352: 3585126.1 | G352: 62452.77 | H352: 68068.66 | I352: 780993.64 | J352: 1009439.3 | K352: 254946.71 | L352: 202342.15 | M352: 815.94694
A353: Mississinawa Valley Local SD (046672, Darke County) | B353: 2013 | C353: 046672 | D353: 110.13645 | E353: 544262.62 | F353: 2735440.7 | G353: 100501.58 | H353: 11233.22 | I353: 744383.53 | J353: 966472.24 | K353: 464148.1 | L353: 186315.95 | M353: 695.60259
...

Sheet options
A1: Options
A2: Please select a calculation option.
A3: I would like Excess Cost for my district to be calculated on a per capita basis.
A4: I would like Excess Cost for my district to be calculated on an individual student basis.
A6: Disability Type
A7: Please select a disability condition.
A8: Category 1. Speech and Language Impairments (Disability condition 05)
A9: Category 2. Specific Learning Disabilities (Disability condition 10)
A10: Category 2. Cognitive Disabilities (formerly Developmentally Handicapped) (Disability condition 09)
A11: Category 2. Other health impairment, minor (Disability condition 15)
A12: Category 3. Deafness (Hearing Impairment) (Disability condition 03)
A13: Category 3. Visual Impairments (Disability condition 04)
... A29: Non-resident student attending special ed program (including coop) (How Received Code=B)
