Workbook

Sheet Report
A1: 1.2 | B1: = LEA number (Enter 1.2 for Minneapolis) | F1: =COUNTIF(Inputs!A14:A2020,Report!A1) -> 18
A3: FINS WITH APPROVED BUDGETS THAT HAVE NO SPENDING | C3: FINs with Approved budgets that have no spending
A4: =IF(F4=0,"No such LEA is listed.",VLOOKUP(A1,Inputs!A14:C2092,3,FALSE)&" #"&FIXED(A1,0,TRUE)) -> MINNEAPOLIS PUBLIC SCHOOL DIST. #1 | C4: 40182 | F4: =COUNTIF(Inputs!A14:A2092,A1) -> 18
B6: Total | C6: =SUM(C8:C25) -> 48119406 | F6: =SUM(F8:F25) -> 18
A8: =IF($F8=1,VLOOKUP(1000*$A$1+$E8,Inputs!$E$14:$H$2020,2),"") -> 406 | B8: =IF(F6=0,"This LEA has already requested some reimbursement for all federal programs for which it has approved budgets.",IF($F8=1,VLOOKUP(1000*$A$1+$E8,Inputs!$E$14:$H$2020,3),"")) -> FORMULA - 406 - Title I, Part D: Prevention and Intervention Programs for Children who are Neglected and Delinquent or At-Risk | C8: =IF($F8=1,VLOOKUP(1000*$A$1+$E8,Inputs!$E$14:$H$2020,4),"") -> 431923.45 | E8: 1 | F8: =COUNTIF(Inputs!$E$14:$E$2020,1000*Report!$A$1+Report!E8) -> 1
A9: =IF($F9=1,VLOOKUP(1000*$A$1+$E9,Inputs!$E$14:$H$2020,2),"") -> 414 | B9: =IF($F9=1,VLOOKUP(1000*$A$1+$E9,Inputs!$E$14:$H$2020,3),"") -> FORMULA - 414 - Title II, Part A: Teacher and Principal Training and Recruitment | C9: =IF($F9=1,VLOOKUP(1000*$A$1+$E9,Inputs!$E$14:$H$2020,4),"") -> 4381705.4 | E9: =E8+1 -> 2 | F9: =COUNTIF(Inputs!$E$14:$E$2020,1000*Report!$A$1+Report!E9) -> 1
A10: =IF($F10=1,VLOOKUP(1000*$A$1+$E10,Inputs!$E$14:$H$2020,2),"") -> 417 | B10: =IF($F10=1,VLOOKUP(1000*$A$1+$E10,Inputs!$E$14:$H$2020,3),"") -> FORMULA - 417 - Title III, Part A, English Language Acquisition, Language Enhancement and Academic Achievement | C10: =IF($F10=1,VLOOKUP(1000*$A$1+$E10,Inputs!$E$14:$H$2020,4),"") -> 892808.37 | E10: =E9+1 -> 3 | F10: =COUNTIF(Inputs!$E$14:$E$2020,1000*Report!$A$1+Report!E10) -> 1
A11: =IF($F11=1,VLOOKUP(1000*$A$1+$E11,Inputs!$E$14:$H$2020,2),"") -> 419 | B11: =IF($F11=1,VLOOKUP(1000*$A$1+$E11,Inputs!$E$14:$H$2020,3),"") -> FORMULA - 419 - IDEA Special Education FY2010 Federal Part B Section 611 Regular Allocation | C11: =IF($F11=1,VLOOKUP(1000*$A$1+$E11,Inputs!$E$14:$H$2020,4),"") -> 8739208.8 | E11: =E10+1 -> 4 | F11: =COUNTIF(Inputs!$E$14:$E$2020,1000*Report!$A$1+Report!E11) -> 1
A12: =IF($F12=1,VLOOKUP(1000*$A$1+$E12,Inputs!$E$14:$H$2020,2),"") -> 420 | B12: =IF($F12=1,VLOOKUP(1000*$A$1+$E12,Inputs!$E$14:$H$2020,3),"") -> FORMULA - 420 - IDEA Special Education FY2010 Federal Part B Section 619 Preschool Regular Allocation | C12: =IF($F12=1,VLOOKUP(1000*$A$1+$E12,Inputs!$E$14:$H$2020,4),"") -> 329028.09 | E12: =E11+1 -> 5 | F12: =COUNTIF(Inputs!$E$14:$E$2020,1000*Report!$A$1+Report!E12) -> 1
A13: =IF($F13=1,VLOOKUP(1000*$A$1+$E13,Inputs!$E$14:$H$2020,2),"") -> 422 | B13: =IF($F13=1,VLOOKUP(1000*$A$1+$E13,Inputs!$E$14:$H$2020,3),"") -> Formula - 422 - Part C IEIC, Ages 0-2, Phase 2 Materials | C13: =IF($F13=1,VLOOKUP(1000*$A$1+$E13,Inputs!$E$14:$H$2020,4),"") -> 505772.27 | E13: =E12+1 -> 6 | F13: =COUNTIF(Inputs!$E$14:$E$2020,1000*Report!$A$1+Report!E13) -> 1
A14: =IF($F14=1,VLOOKUP(1000*$A$1+$E14,Inputs!$E$14:$H$2020,2),"") -> 428 | B14: =IF($F14=1,VLOOKUP(1000*$A$1+$E14,Inputs!$E$14:$H$2020,3),"") -> FORMULA - 428 - Carl D. Perkins Career and Technical Education Act - Basic Grant | C14: =IF($F14=1,VLOOKUP(1000*$A$1+$E14,Inputs!$E$14:$H$2020,4),"") -> 759165.6 | E14: =E13+1 -> 7 | F14: =COUNTIF(Inputs!$E$14:$E$2020,1000*Report!$A$1+Report!E14) -> 1
A15: =IF($F15=1,VLOOKUP(1000*$A$1+$E15,Inputs!$E$14:$H$2020,2),"") -> 437 | B15: =IF($F15=1,VLOOKUP(1000*$A$1+$E15,Inputs!$E$14:$H$2020,3),"") -> Formula - 437 - Sec. 619 Preschool Incentive Personnel Development | C15: =IF($F15=1,VLOOKUP(1000*$A$1+$E15,Inputs!$E$14:$H$2020,4),"") -> 10920 | E15: =E14+1 -> 8 | F15: =COUNTIF(Inputs!$E$14:$E$2020,1000*Report!$A$1+Report!E15) -> 1
A16: =IF($F16=1,VLOOKUP(1000*$A$1+$E16,Inputs!$E$14:$H$2020,2),"") -> 438 | B16: =IF($F16=1,VLOOKUP(1000*$A$1+$E16,Inputs!$E$14:$H$2020,3),"") -> Formula - 438 - Federal Adult Basic Education (ABE) Formula Revenue | C16: =IF($F16=1,VLOOKUP(1000*$A$1+$E16,Inputs!$E$14:$H$2020,4),"") -> 454140.29 | E16: =E15+1 -> 9 | F16: =COUNTIF(Inputs!$E$14:$E$2020,1000*Report!$A$1+Report!E16) -> 1
A17: =IF($F17=1,VLOOKUP(1000*$A$1+$E17,Inputs!$E$14:$H$2020,2),"") -> 441 | B17: =IF($F17=1,VLOOKUP(1000*$A$1+$E17,Inputs!$E$14:$H$2020,3),"") -> Formula - 441 - Part B Section 619 Preschool Supplemental, IEIC, Ages 3-5, Phase 2 for SERVS | C17: =IF($F17=1,VLOOKUP(1000*$A$1+$E17,Inputs!$E$14:$H$2020,4),"") -> 18525 | E17: =E16+1 -> 10 | F17: =COUNTIF(Inputs!$E$14:$E$2020,1000*Report!$A$1+Report!E17) -> 1
A18: =IF($F18=1,VLOOKUP(1000*$A$1+$E18,Inputs!$E$14:$H$2020,2),"") -> 470 | B18: =IF($F18=1,VLOOKUP(1000*$A$1+$E18,Inputs!$E$14:$H$2020,3),"") -> FORMULA - 470 - Title I, Part A: Improving the Academic Achievement of the Disadvantaged Stimulus | C18: =IF($F18=1,VLOOKUP(1000*$A$1+$E18,Inputs!$E$14:$H$2020,4),"") -> 19725159 | E18: =E17+1 -> 11 | F18: =COUNTIF(Inputs!$E$14:$E$2020,1000*Report!$A$1+Report!E18) -> 1
A19: =IF($F19=1,VLOOKUP(1000*$A$1+$E19,Inputs!$E$14:$H$2020,2),"") -> 471 | B19: =IF($F19=1,VLOOKUP(1000*$A$1+$E19,Inputs!$E$14:$H$2020,3),"") -> FORMULA - 471 - Title I, Part D: Prevention and Intervention Programs for Children who are Neglected and Delinquent or At-Risk Targeted Stimulus | C19: =IF($F19=1,VLOOKUP(1000*$A$1+$E19,Inputs!$E$14:$H$2020,4),"") -> 270909.88 | E19: =E18+1 -> 12 | F19: =COUNTIF(Inputs!$E$14:$E$2020,1000*Report!$A$1+Report!E19) -> 1
A20: =IF($F20=1,VLOOKUP(1000*$A$1+$E20,Inputs!$E$14:$H$2020,2),"") -> 478 | B20: =IF($F20=1,VLOOKUP(1000*$A$1+$E20,Inputs!$E$14:$H$2020,3),"") -> COMPETITIVE - 478 - ARRA McKinney Vento: Education for Homeless Children and Youth | C20: =IF($F20=1,VLOOKUP(1000*$A$1+$E20,Inputs!$E$14:$H$2020,4),"") -> 172626 | E20: =E19+1 -> 13 | F20: =COUNTIF(Inputs!$E$14:$E$2020,1000*Report!$A$1+Report!E20) -> 1
... A25: =IF($F25=1,VLOOKUP(1000*$A$1+$E25,Inputs!$E$14:$H$2020,2),"") -> 849 | B25: =IF($F25=1,VLOOKUP(1000*$A$1+$E25,Inputs!$E$14:$H$2020,3),"") -> MINNESOTA TITLE I SCHOOL IMPROVEMENT GRANT, ROUND 3 | C25: =IF($F25=1,VLOOKUP(1000*$A$1+$E25,Inputs!$E$14:$H$2020,4),"") -> 1100000 | E25: =E24+1 -> 18 | F25: =COUNTIF(Inputs!$E$14:$E$2020,1000*Report!$A$1+Report!E25) -> 1

Sheet Summary
A1: SUMMARY
D3: EXPENDITURES | E3: # LEA'S
C5: TOTAL | D5: =SUM(D12:D483) -> 3.2144286e+08 | E5: =SUM(E7:E9) -> 470
C7: DISTRICTS | D7: =SUM(D12:D306) -> 2.7640094e+08 | E7: =COUNT(D12:D306) -> 295
C8: CHARTERS | D8: =SUM(D308:D438) -> 12794310 | E8: =COUNT(D308:D438) -> 131
C9: OTHERS | D9: =SUM(D440:D483) -> 32247611 | E9: =COUNT(D440:D483) -> 44
A12: 1 | B12: 1 | C12: AITKIN PUBLIC SCHOOL DISTRICT | D12: 127249.67
A13: 1.2 | B13: 3 | C13: MINNEAPOLIS PUBLIC SCHOOL DIST. | D13: 48119406
A14: 2 | B14: 1 | C14: HILL CITY PUBLIC SCHOOL DISTRICT | D14: 325991.73
A15: 4 | B15: 1 | C15: MCGREGOR PUBLIC SCHOOL DISTRICT | D15: 538222.8
A16: 6 | B16: 3 | C16: SOUTH ST. PAUL PUBLIC SCHOOL DIST. | D16: 80352.29
A17: 11 | B17: 1 | C17: ANOKA-HENNEPIN PUBLIC SCHOOL DIST. | D17: 19186278
A18: 12 | B18: 1 | C18: CENTENNIAL PUBLIC SCHOOL DISTRICT | D18: 1453013.9
A19: 13 | B19: 1 | C19: COLUMBIA HEIGHTS PUBLIC SCHOOL DIST | D19: 4504146.7
A20: 14 | B20: 1 | C20: FRIDLEY PUBLIC SCHOOL DISTRICT | D20: 1372502.1
A21: 15 | B21: 1 | C21: ST. FRANCIS PUBLIC SCHOOL DISTRICT | D21: 64148.91
A22: 16 | B22: 1 | C22: SPRING LAKE PARK PUBLIC SCHOOLS | D22: 1125947.1
A23: 22 | B23: 1 | C23: DETROIT LAKES PUBLIC SCHOOL DIST. | D23: 24010.42
... A483: 991 | B483: 83 | C483: REGN 6 & 8-S.W/W.C. SRV COOPERATIVE | D483: 354563.46

Sheet Inputs
B1: formattedOrganizationId | C1: organizationName | F1: UFARSFinanceCode | G1: title | H1: allocationAmount
A4: Excluded from lookup range because of duplicate LEA number:
A6: 1 | B6: 23 | C6: U OF M - MINNEAPOLIS CAMPUS | F6: 866 | G6: Sole Source - 866 - Career and Technical Education Teacher Licensure Grant | H6: 64221
A7: 1 | B7: 23 | C7: U OF M - MINNEAPOLIS CAMPUS | F7: 880 | G7: Sole Source - 880 - Library Services & Technology Act State Grants - Statewide Initative - Minnesota Digital Library | H7: 135000
A8: 111 | B8: 80 | C8: WHITE EARTH RESERVATION TRIBAL COUN | F8: 438 | G8: Formula - 438 - Federal Adult Basic Education (ABE) Formula Revenue | H8: 7481.44
A9: 115 | B9: 80 | C9: INSTITUTE FOR NEW AMERICANS | F9: 438 | G9: Formula - 438 - Federal Adult Basic Education (ABE) Formula Revenue | H9: 102852.66
A10: 115 | B10: 80 | C10: INSTITUTE FOR NEW AMERICANS | F10: 801 | G10: Competitive - 801 - English Literacy and Civics Education Program (EL/Civics) | H10: 40000
A12: Lookup range:
A14: 1 | B14: 1 | C14: AITKIN PUBLIC SCHOOL DISTRICT | D14: =IF(A14=A13,D13+1,1) -> 1 | E14: =1000*A14+D14 -> 1001 | F14: 470 | G14: FORMULA - 470 - Title I, Part A: Improving the Academic Achievement of the Disadvantaged Stimulus | H14: 127249.67
A15: 1.2 | B15: 3 | C15: MINNEAPOLIS PUBLIC SCHOOL DIST. | D15: =IF(A15=A14,D14+1,1) -> 1 | E15: =1000*A15+D15 -> 1201 | F15: 406 | G15: FORMULA - 406 - Title I, Part D: Prevention and Intervention Programs for Children who are Neglected and Delinquent or At-Risk | H15: 431923.45
A16: 1.2 | B16: 3 | C16: MINNEAPOLIS PUBLIC SCHOOL DIST. | D16: =IF(A16=A15,D15+1,1) -> 2 | E16: =1000*A16+D16 -> 1202 | F16: 414 | G16: FORMULA - 414 - Title II, Part A: Teacher and Principal Training and Recruitment | H16: 4381705.4
A17: 1.2 | B17: 3 | C17: MINNEAPOLIS PUBLIC SCHOOL DIST. | D17: =IF(A17=A16,D16+1,1) -> 3 | E17: =1000*A17+D17 -> 1203 | F17: 417 | G17: FORMULA - 417 - Title III, Part A, English Language Acquisition, Language Enhancement and Academic Achievement | H17: 892808.37
A18: 1.2 | B18: 3 | C18: MINNEAPOLIS PUBLIC SCHOOL DIST. | D18: =IF(A18=A17,D17+1,1) -> 4 | E18: =1000*A18+D18 -> 1204 | F18: 419 | G18: FORMULA - 419 - IDEA Special Education FY2010 Federal Part B Section 611 Regular Allocation | H18: 8739208.8
A19: 1.2 | B19: 3 | C19: MINNEAPOLIS PUBLIC SCHOOL DIST. | D19: =IF(A19=A18,D18+1,1) -> 5 | E19: =1000*A19+D19 -> 1205 | F19: 420 | G19: FORMULA - 420 - IDEA Special Education FY2010 Federal Part B Section 619 Preschool Regular Allocation | H19: 329028.09
A20: 1.2 | B20: 3 | C20: MINNEAPOLIS PUBLIC SCHOOL DIST. | D20: =IF(A20=A19,D19+1,1) -> 6 | E20: =1000*A20+D20 -> 1206 | F20: 422 | G20: Formula - 422 - Part C IEIC, Ages 0-2, Phase 2 Materials | H20: 505772.27
A21: 1.2 | B21: 3 | C21: MINNEAPOLIS PUBLIC SCHOOL DIST. | D21: =IF(A21=A20,D20+1,1) -> 7 | E21: =1000*A21+D21 -> 1207 | F21: 428 | G21: FORMULA - 428 - Carl D. Perkins Career and Technical Education Act - Basic Grant | H21: 759165.6
A22: 1.2 | B22: 3 | C22: MINNEAPOLIS PUBLIC SCHOOL DIST. | D22: =IF(A22=A21,D21+1,1) -> 8 | E22: =1000*A22+D22 -> 1208 | F22: 437 | G22: Formula - 437 - Sec. 619 Preschool Incentive Personnel Development | H22: 10920
A23: 1.2 | B23: 3 | C23: MINNEAPOLIS PUBLIC SCHOOL DIST. | D23: =IF(A23=A22,D22+1,1) -> 9 | E23: =1000*A23+D23 -> 1209 | F23: 438 | G23: Formula - 438 - Federal Adult Basic Education (ABE) Formula Revenue | H23: 454140.29
A24: 1.2 | B24: 3 | C24: MINNEAPOLIS PUBLIC SCHOOL DIST. | D24: =IF(A24=A23,D23+1,1) -> 10 | E24: =1000*A24+D24 -> 1210 | F24: 441 | G24: Formula - 441 - Part B Section 619 Preschool Supplemental, IEIC, Ages 3-5, Phase 2 for SERVS | H24: 18525
A25: 1.2 | B25: 3 | C25: MINNEAPOLIS PUBLIC SCHOOL DIST. | D25: =IF(A25=A24,D24+1,1) -> 11 | E25: =1000*A25+D25 -> 1211 | F25: 470 | G25: FORMULA - 470 - Title I, Part A: Improving the Academic Achievement of the Disadvantaged Stimulus | H25: 19725159
... A2020: 6979 | B2020: 61 | C2020: MID STATE EDUCATION DISTRICT | D2020: =IF(A2020=A2019,D2019+1,1) -> 4 | E2020: =1000*A2020+D2020 -> 6979004 | F2020: 486 | G2020: FORMULA - 486 - Part C ARRA Federal Stimulus Funds Opportunity | H2020: 11918.64
C2022: Not listed:
A2024: 25 | B2024: 1 | C2024: PINE POINT PUBLIC SCHOOL DISTRICT | D2024: =IF(A2024=A2023,0,1) -> 1
A2025: 36 | B2025: 1 | C2025: KELLIHER PUBLIC SCHOOL DISTRICT | D2025: =IF(A2025=A2024,0,1) -> 1
A2026: 85 | B2026: 1 | C2026: SPRINGFIELD PUBLIC SCHOOL DISTRICT | D2026: =IF(A2026=A2025,0,1) -> 1
A2027: 97 | B2027: 1 | C2027: MOOSE LAKE PUBLIC SCHOOL DISTRICT | D2027: =IF(A2027=A2026,0,1) -> 1
A2028: 99 | B2028: 1 | C2028: ESKO PUBLIC SCHOOL DISTRICT | D2028: =IF(A2028=A2027,0,1) -> 1
A2029: 177 | B2029: 1 | C2029: WINDOM PUBLIC SCHOOL DISTRICT | D2029: =IF(A2029=A2028,0,1) -> 1
A2030: 207 | B2030: 1 | C2030: BRANDON PUBLIC SCHOOL DISTRICT | D2030: =IF(A2030=A2029,0,1) -> 1
A2031: 238 | B2031: 1 | C2031: MABEL-CANTON PUBLIC SCHOOL DIST. | D2031: =IF(A2031=A2030,0,1) -> 1
A2032: 256 | B2032: 1 | C2032: RED WING PUBLIC SCHOOL DISTRICT | D2032: =IF(A2032=A2031,0,1) -> 1
A2033: 323 | B2033: 2 | C2033: FRANCONIA PUBLIC SCHOOL DISTRICT | D2033: =IF(A2033=A2032,0,1) -> 1
A2034: 332 | B2034: 1 | C2034: MORA PUBLIC SCHOOL DISTRICT | D2034: =IF(A2034=A2033,0,1) -> 1
A2035: 414 | B2035: 1 | C2035: MINNEOTA PUBLIC SCHOOL DISTRICT | D2035: =IF(A2035=A2034,0,1) -> 1
A2036: 435 | B2036: 1 | C2036: WAUBUN PUBLIC SCHOOL DISTRICT | D2036: 1
A2037: 463 | B2037: 1 | C2037: EDEN VALLEY-WATKINS SCHOOL DISTRICT | D2037: 1
A2038: 542 | B2038: 1 | C2038: BATTLE LAKE PUBLIC SCHOOL DISTRICT | D2038: 1
A2039: 577 | B2039: 1 | C2039: WILLOW RIVER PUBLIC SCHOOL DISTRICT | D2039: 1
A2040: 581 | B2040: 1 | C2040: EDGERTON PUBLIC SCHOOL DISTRICT | D2040: 1
A2041: 627 | B2041: 1 | C2041: OKLEE PUBLIC SCHOOL DISTRICT | D2041: 1
...
