Workbook

Sheet Legend
A2: Legend
D3: Local
D5: State
D7: Federal
D9: Other
D11: Indeterminate
D13: Wilmington
A15: Source | B15: Delaware Department of Education
A17: All files are "read only" and based on data collections from the Delaware Department of Education.
A18: The conclusions reached in this document are those of the author(s) and do not necessarily represent those
A19: of Ball State University.

Sheet DE District Master
A1: TABLE 30 | M1: TABLE 31 | X1: TABLE 31 (CONTINUED) | AD1: TABLE 32 | AM1: TABLE 32 (CONTINUED) | AT1: TABLE 33 | BC1: TABLE 33 (CONTINUED) | BL1: TABLE 36
A2: INCOME SOURCES BY DISTRICT | M2: REVENUE RECEIPTS - STATE APPROPRIATIONS | X2: REVENUE RECEIPTS - STATE APPROPRIATIONS | AD2: REVENUE RECEIPTS - FEDERAL SOURCES | AM2: REVENUE RECEIPTS - FEDERAL SOURCES | AT2: REVENUE RECEIPTS - LOCAL SOURCES FOR CURRENT EXPENSES | BC2: REVENUE RECEIPTS - LOCAL SOURCES FOR OTHER THAN CURRENT EXPENSES | BL2: NONREVENUE RECEIPTS
A3: 2006-2007 | M3: 2006-2007 | X3: 2006-2007 | AD3: 2006-2007 | AM3: 2006-2007 | AT3: 2006-2007 | BC3: 2006-2007 | BL3: 2006-2007
C4: Total | D4: Total | E4: Total | F4: Total | H4: Total | I4: Total | J4: Total | K4: Total | N4: State | O4: State | P4: State | Q4: State | R4: State | S4: State | U4: State | V4: State | Y4: State | Z4: State | AA4: State | AB4: Total | AE4: Federal | AF4: Federal | AG4: Federal | AH4: Federal | AI4: Federal | AJ4: Federal | AK4: Federal | AM4: Federal | AN4: Federal | AO4: Omit | AP4: Federal | AQ4: Federal | AR4: Total | AU4: Local | AV4: Indeterminate | AW4: Other | AX4: Other | AY4: Other | AZ4: Other | BD4: Local | BE4: Local | BF4: Other | BG4: Local | BH4: Total | BI4: Total | BM4: Omit | BN4: Omit | BO4: Omit | BP4: Omit | BQ4: Omit | BR4: Omit | BS4: Omit | BT4: Omit
C5: Revenue Receipts | H5: Nonrevenue Receipts | K5: Net Total | N5: Division I | O5: Division I | P5: Division II | Q5: Division II | R5: Division III | S5: Trans- | U5: Debt Service | Y5: Academic | Z5: Related | AA5: Other | AB5: Total | AE5: IASA | AF5: IASA | AG5: IDEA-B | AH5: IDEA-B | AI5: IASA | AJ5: Public | AK5: IASA | AN5: Vocational | AO5: Adult Basic | AP5: Drug Free | AR5: Total | AU5: tAXes for current | AV5: Tuition | AW5: Interest | AX5: Rent | AY5: Athletic | BD5: Taxes for Tuition | BE5: Taxes for Debt | BF5: Interest Construction | BG5: Taxes for Minor | BH5: Total | BI5: Net Revenue | BM5: Sale Of Bonds | BQ5: Local
A6: District | B6: Enrollment | C6: State | D6: Federal | E6: Net Local | F6: Total | H6: State | I6: Local | J6: Total | K6: Income | M6: District | N6: Salaries | O6: Other Cost | P6: Energy | Q6: Other Cost | R6: Equalization | S6: Portation | U6: Principal | V6: Interest | X6: District | Y6: Allocation | Z6: Services * | AA6: State | AB6: State | AD6: District | AE6: Title I | AF6: Title VI | AG6: Basic | AH6: Pre-School | AI6: Migrant | AJ6: Law 874 | AK6: Title II | AM6: District | AN6: Education | AO6: Education | AP6: Schools | AQ6: Other | AR6: Federal | AT6: District | AU6: Operations | AV6: Incoming | AW6: Received | AX6: Income | AY6: Funds | AZ6: Other | BA6: Total | BC6: District | BD6: Outgoing | BE6: Service | BF6: Fund | BG6: Caps. | BH6: Other | BI6: Receipts | BL6: District | BM6: State | BN6: Local | BO6: Total | BP6: Other State | BQ6: Sale of Property | BR6: Insurance Adjustments | BS6: Other nonrevenue | BT6: Total Nonrevenue Receipts
A7: NEW CASTLE COUNTY | M7: NEW CASTLE COUNTY | X7: NEW CASTLE COUNTY | AD7: NEW CASTLE COUNTY | AM7: NEW CASTLE COUNTY | AT7: NEW CASTLE COUNTY | BC7: NEW CASTLE COUNTY | BL7: NEW CASTLE COUNTY
A8: Appoquinimink | B8: 7563 | C8: 64263835 | D8: 1970175 | E8: 18043387 | F8: 84277397 | H8: 18068830 | I8: 6348508 | J8: 24417337 | K8: 108694734 | M8: Appoquinimink | N8: 23974228 | O8: 11628610 | P8: 1334956 | Q8: 1668672 | R8: 7621457 | S8: 3975480 | U8: 2632373 | V8: 705926 | X8: Appoquinimink | Y8: 278221 | Z8: 84335 | AA8: 10359577 | AB8: 64263835 | AD8: Appoquinimink | AE8: 275551 | AF8: 32853 | AG8: 981819 | AH8: 41568 | AI8: 0 | AJ8: 0 | AK8: 266718 | AM8: Appoquinimink | AN8: 63667 | AO8: 69655 | AP8: 37529 | AQ8: 200815 | AR8: 1970175 | AT8: Appoquinimink | AU8: 9971564 | AV8: 0 | AW8: 417820 | AX8: 76663 | AY8: 101667 | AZ8: 0 | BA8: 10567714 | BC8: Appoquinimink | BD8: 4558320 | BE8: 3127855 | BF8: 715380 | BG8: 707609 | BH8: 9109164 | BI8: 18043387 | BL8: Appoquinimink | BM8: 18068830 | BN8: 6348508 | BO8: 24417337 | BP8: 0 | BQ8: 0 | BR8: 0 | BS8: 0 | BT8: 24417337
A9: Brandywine | B9: 10267 | C9: 81295677 | D9: 7673827 | E9: 53251846 | F9: 142221350 | H9: 25910296 | I9: 17273530 | J9: 43183826 | K9: 185405176 | M9: Brandywine | N9: 37262351 | O9: 18248511 | P9: 1798102 | Q9: 2395125 | R9: 4176986 | S9: 2943732 | U9: 2843974 | V9: 950216 | X9: Brandywine | Y9: 359222 | Z9: 777 | AA9: 10316681 | AB9: 81295677 | AD9: Brandywine | AE9: 2723247 | AF9: 21143 | AG9: 2826704 | AH9: 114376 | AI9: 0 | AJ9: 0 | AK9: 1266236 | AM9: Brandywine | AN9: 271827 | AO9: 0 | AP9: 128466 | AQ9: 321827 | AR9: 7673827 | AT9: Brandywine | AU9: 33986504 | AV9: 776842 | AW9: 758943 | AX9: 42508 | AY9: 31894 | AZ9: 5573542 | BA9: 41170234 | BC9: Brandywine | BD9: 5200997 | BE9: 5654241 | BF9: 788398 | BG9: 883404 | BH9: 12527040 | BI9: 53251846 | BL9: Brandywine | BM9: 25910296 | BN9: 17273530 | BO9: 43183826 | BP9: 0 | BQ9: 0 | BR9: 0 | BS9: 0 | BT9: 43183826
A10: Data Service Center | C10: 0 | D10: 0 | E10: 2263611 | F10: 2263611 | H10: 0 | I10: 0 | J10: 0 | K10: 2263611 | M10: Data Service Center | N10: 0 | O10: 0 | P10: 0 | Q10: 0 | R10: 0 | S10: 0 | U10: 0 | V10: 0 | X10: Data Service Center | Y10: 0 | Z10: 0 | AA10: 0 | AB10: 0 | AD10: Data Service Center | AE10: 0 | AF10: 0 | AG10: 0 | AH10: 0 | AI10: 0 | AJ10: 0 | AK10: 0 | AM10: Data Service Center | AN10: 0 | AO10: 0 | AP10: 0 | AQ10: 0 | AR10: 0 | AT10: Data Service Center | AU10: 0 | AV10: 0 | AW10: 0 | AX10: 0 | AY10: 0 | AZ10: 2263611 | BA10: 2263611 | BC10: Data Service Center | BD10: 0 | BE10: 0 | BF10: 0 | BG10: 0 | BH10: 0 | BI10: 2263611 | BL10: Data Service Center | BM10: 0 | BN10: 0 | BO10: 0 | BP10: 0 | BQ10: 0 | BR10: 0 | BS10: 0 | BT10: 0
A11: Christina | B11: 17864 | C11: 135408184 | D11: 9614024 | E11: 71479665 | F11: 216501873 | H11: 0 | I11: 925 | J11: -925 | K11: 216500948 | M11: Christina | N11: 56263088 | O11: 27251038 | P11: 2947749 | Q11: 3914307 | R11: 6670313 | S11: 14797604 | U11: 4651560 | V11: 1576043 | X11: Christina | Y11: 477816 | Z11: 94440 | AA11: 16764226 | AB11: 135408184 | AD11: Christina | AE11: 3460419 | AF11: 156594 | AG11: 2490600 | AH11: 134451 | AI11: 0 | AJ11: 0 | AK11: 1615639 | AM11: Christina | AN11: 407740 | AO11: 120989 | AP11: 157284 | AQ11: 1070308 | AR11: 9614024 | AT11: Christina | AU11: 56821062 | AV11: 0 | AW11: 1172681 | AX11: 91003 | AY11: 53974 | AZ11: 1949773 | BA11: 60088494 | BC11: Christina | BD11: 20022068 | BE11: 9565869 | BF11: 1220894 | BG11: 1758848 | BH11: 32567679 | BI11: 71479665 | BL11: Christina | BM11: 0 | BN11: 925 | BO11: 925 | BP11: 0 | BQ11: 0 | BR11: 0 | BS11: 0 | BT11: 925
A12: Brennen School | B12: 280 | C12: 12712785 | D12: 0 | E12: 8325288 | F12: 21038073 | H12: 0 | I12: 0 | J12: 0 | K12: 21038073 | M12: Brennen School | N12: 7207212 | O12: 3647988 | P12: 208579 | Q12: 272157 | R12: 541520 | S12: 0 | U12: 341656 | V12: 202156 | X12: Brennen School | Y12: 46957 | Z12: 0 | AA12: 244560 | AB12: 12712785 | AD12: Brennen School | AE12: 0 | AF12: 0 | AG12: 0 | AH12: 0 | AI12: 0 | AJ12: 0 | AK12: 0 | AM12: Brennen School | AN12: 0 | AO12: 0 | AP12: 0 | AQ12: 0 | AR12: 0 | AT12: Brennen School | AU12: 0 | AV12: 8186947 | AW12: 25641 | AX12: 0 | AY12: 0 | AZ12: 127660 | BA12: 8340248 | BC12: Brennen School | BD12: 0 | BE12: 0 | BF12: 0 | BG12: 0 | BH12: 0 | BI12: 8325288 | BL12: Brennen School | BM12: 0 | BN12: 0 | BO12: 0 | BP12: 0 | BQ12: 0 | BR12: 0 | BS12: 0 | BT12: 0
A13: Margaret S. Sterck | B13: 94 | C13: 5723244 | D13: 113563 | E13: 4709811 | F13: 10546618 | H13: 8000000 | I13: 0 | J13: 8000000 | K13: 18546618 | M13: Margaret S. Sterck | N13: 3375267 | O13: 1629453 | P13: 57799 | Q13: 75417 | R13: 155687 | S13: 0 | U13: 190 | V13: 41 | X13: Margaret S. Sterck | Y13: 13495 | Z13: 0 | AA13: 415895 | AB13: 5723244 | AD13: Margaret S. Sterck | AE13: 0 | AF13: 0 | AG13: 0 | AH13: 0 | AI13: 0 | AJ13: 0 | AK13: 0 | AM13: Margaret S. Sterck | AN13: 0 | AO13: 0 | AP13: 0 | AQ13: 113563 | AR13: 113563 | AT13: Margaret S. Sterck | AU13: 0 | AV13: 4652439 | AW13: 9355 | AX13: 0 | AY13: 0 | AZ13: 56091 | BA13: 4717884 | BC13: Margaret S. Sterck | BD13: 0 | BE13: 0 | BF13: 0 | BG13: 0 | BH13: 0 | BI13: 4709811 | BL13: Margaret S. Sterck | BM13: 8000000 | BN13: 0 | BO13: 8000000 | BP13: 0 | BQ13: 0 | BR13: 0 | BS13: 0 | BT13: 8000000
A14: Reach/CBIP | B14: 0 | C14: 2056842 | D14: 0 | E14: 3315200 | F14: 5372041 | H14: 0 | I14: 0 | J14: 0 | K14: 5372041 | M14: Reach/CBIP | N14: 1217514 | O14: 556026 | P14: 42721 | Q14: 55743 | R14: 115073 | S14: 0 | U14: 1231 | V14: 268 | X14: Reach/CBIP | Y14: 9978 | Z14: 0 | AA14: 58288 | AB14: 2056842 | AD14: Reach/CBIP | AE14: 0 | AF14: 0 | AG14: 0 | AH14: 0 | AI14: 0 | AJ14: 0 | AK14: 0 | AM14: Reach/CBIP | AN14: 0 | AO14: 0 | AP14: 0 | AQ14: 0 | AR14: 0 | AT14: Reach/CBIP | AU14: 0 | AV14: 3245371 | AW14: 13395 | AX14: 0 | AY14: 0 | AZ14: 56433 | BA14: 3315200 | BC14: Reach/CBIP | BD14: 0 | BE14: 0 | BF14: 0 | BG14: 0 | BH14: 0 | BI14: 3315200 | BL14: Reach/CBIP | BM14: 0 | BN14: 0 | BO14: 0 | BP14: 0 | BQ14: 0 | BR14: 0 | BS14: 0 | BT14: 0
A15: Douglass | B15: 106 | C15: 7076816 | D15: 0 | E15: 6120559 | F15: 13197375 | H15: 0 | I15: 0 | J15: 0 | K15: 13197375 | M15: Douglass | N15: 3918718 | O15: 1914586 | P15: 221144 | Q15: 288552 | R15: 498440 | S15: 0 | U15: 0 | V15: 0 | X15: Douglass | Y15: 49892 | Z15: 0 | AA15: 185485 | AB15: 7076816 | AD15: Douglass | AE15: 0 | AF15: 0 | AG15: 0 | AH15: 0 | AI15: 0 | AJ15: 0 | AK15: 0 | AM15: Douglass | AN15: 0 | AO15: 0 | AP15: 0 | AQ15: 0 | AR15: 0 | AT15: Douglass | AU15: 0 | AV15: 6042690 | AW15: 10966 | AX15: 0 | AY15: 0 | AZ15: 66903 | BA15: 6210559 | BC15: Douglass | BD15: 0 | BE15: 0 | BF15: 0 | BG15: 0 | BH15: 0 | BI15: 6120559 | BL15: Douglass | BM15: 0 | BN15: 0 | BO15: 0 | BP15: 0 | BQ15: 0 | BR15: 0 | BS15: 0 | BT15: 0
A16: Colonial | B16: 10216 | C16: 74333224 | D16: 7525790 | E16: 32021141 | F16: 113880156 | H16: 23929476 | I16: 11786160 | J16: 35715636 | K16: 149595792 | M16: Colonial | N16: 31995020 | O16: 15934553 | P16: 1679689 | Q16: 2041742 | R16: 3917739 | S16: 5004872 | U16: 5009397 | V16: 1762023 | X16: Colonial | Y16: 365092 | Z16: 0 | AA16: 6623097 | AB16: 74333224 | AD16: Colonial | AE16: 2651082 | AF16: 54769 | AG16: 2460378 | AH16: 115038 | AI16: 0 | AJ16: 0 | AK16: 1259978 | AM16: Colonial | AN16: 117920 | AO16: 5904 | AP16: 127598 | AQ16: 733122 | AR16: 7525790 | AT16: Colonial | AU16: 22066660 | AV16: 598999 | AW16: 1666233 | AX16: 42874 | AY16: 21693 | AZ16: 21453 | BA16: 24417912 | BC16: Colonial | BD16: 7511588 | BE16: 4226123 | BF16: 436959 | BG16: 1305478 | BH16: 13480148 | BI16: 32021141 | BL16: Colonial | BM16: 23929476 | BN16: 11786160 | BO16: 35715636 | BP16: 0 | BQ16: 0 | BR16: 0 | BS16: 0 | BT16: 35715636
A17: John G. Leach | B17: 67 | C17: 5709379 | D17: 0 | E17: 3389289 | F17: 9098667 | H17: 0 | I17: 0 | J17: 0 | K17: 9098667 | M17: John G. Leach | N17: 3199539 | O17: 1596941 | P17: 110572 | Q17: 119683 | R17: 162456 | S17: 0 | U17: 266111 | V17: 92420 | X17: John G. Leach | Y17: 14087 | Z17: 0 | AA17: 147570 | AB17: 5709379 | AD17: John G. Leach | AE17: 0 | AF17: 0 | AG17: 0 | AH17: 0 | AI17: 0 | AJ17: 0 | AK17: 0 | AM17: John G. Leach | AN17: 0 | AO17: 0 | AP17: 0 | AQ17: 0 | AR17: 0 | AT17: John G. Leach | AU17: 0 | AV17: 3200000 | AW17: 53904 | AX17: 0 | AY17: 0 | AZ17: 135385 | BA17: 3389289 | BC17: John G. Leach | BD17: 0 | BE17: 0 | BF17: 0 | BG17: 0 | BH17: 0 | BI17: 3389289 | BL17: John G. Leach | BM17: 0 | BN17: 0 | BO17: 0 | BP17: 0 | BQ17: 0 | BR17: 0 | BS17: 0 | BT17: 0
A18: New Castle Voc-Tech | B18: 3794 | C18: 42608732 | D18: 2277859 | E18: 27249270 | F18: 72135861 | H18: 5342313 | I18: 0 | J18: 5342313 | K18: 77478174 | M18: New Castle Voc-Tech | N18: 16265912 | O18: 8407392 | P18: 1365665 | Q18: 1831125 | R18: 1713144 | S18: 4327018 | U18: 591819 | V18: 133425 | X18: New Castle Voc-Tech | Y18: 169633 | Z18: 15546 | AA18: 7788053 | AB18: 42608732 | AD18: New Castle Voc-Tech | AE18: 474563 | AF18: 9973 | AG18: 735552 | AH18: 0 | AI18: 0 | AJ18: 0 | AK18: 201499 | AM18: New Castle Voc-Tech | AN18: 626402 | AO18: 62170 | AP18: 24558 | AQ18: 143143 | AR18: 2277859 | AT18: New Castle Voc-Tech | AU18: 23814669 | AV18: 0 | AW18: 666356 | AX18: 0 | AY18: 35460 | AZ18: 1734414 | BA18: 26250899 | BC18: New Castle Voc-Tech | BD18: 0 | BE18: 897428 | BF18: 102629 | BG18: 0 | BH18: 1000057 | BI18: 27249270 | BL18: New Castle Voc-Tech | BM18: 5342313 | BN18: 0 | BO18: 5342313 | BP18: 0 | BQ18: 0 | BR18: 0 | BS18: 0 | BT18: 5342313
A19: Red Clay | B19: 15545 | C19: 113643134 | D19: 11867910 | E19: 57580215 | F19: 183091259 | H19: 17174796 | I19: 11449864 | J19: 28624660 | K19: 211715919 | M19: Red Clay | N19: 49525480 | O19: 25077066 | P19: 2421276 | Q19: 3243036 | R19: 5639350 | S19: 6083470 | U19: 1113134 | V19: 512890 | X19: Red Clay | Y19: 515354 | Z19: 26039 | AA19: 19486038 | AB19: 113643134 | AD19: Red Clay | AE19: 3564230 | AF19: 40011 | AG19: 4048047 | AH19: 117609 | AI19: 0 | AJ19: 0 | AK19: 1948380 | AM19: Red Clay | AN19: 193483 | AO19: 42104 | AP19: 181263 | AQ19: 1732784 | AR19: 11867910 | AT19: Red Clay | AU19: 41647573 | AV19: 569450 | AW19: 730635 | AX19: 212067 | AY19: 0 | AZ19: 11564314 | BA19: 54724039 | BC19: Red Clay | BD19: 12097079 | BE19: 7623173 | BF19: 1380054 | BG19: 29330 | BH19: 21129637 | BI19: 57580215 | BL19: Red Clay | BM19: 17174796 | BN19: 11449864 | BO19: 28624660 | BP19: 0 | BQ19: 0 | BR19: 0 | BS19: 0 | BT19: 28624660
A20: Meadow Wood | B20: 128 | C20: 3625852 | D20: 80462 | E20: 3981063 | F20: 7687377 | H20: 0 | I20: 0 | J20: 0 | K20: 7687377 | M20: Meadow Wood | N20: 1405242 | O20: 766854 | P20: 25903 | Q20: 153649 | R20: 175994 | S20: 985153 | U20: 0 | V20: 0 | X20: Meadow Wood | Y20: 15261 | Z20: 0 | AA20: 97796 | AB20: 3625852 | AD20: Meadow Wood | AE20: 0 | AF20: 0 | AG20: 7888 | AH20: 0 | AI20: 0 | AJ20: 0 | AK20: 0 | AM20: Meadow Wood | AN20: 0 | AO20: 0 | AP20: 0 | AQ20: 72574 | AR20: 80462 | AT20: Meadow Wood | AU20: 0 | AV20: 3895574 | AW20: 22591 | AX20: 0 | AY20: 0 | AZ20: 62898 | BA20: 3981063 | BC20: Meadow Wood | BD20: 0 | BE20: 0 | BF20: 0 | BG20: 0 | BH20: 0 | BI20: 3981063 | BL20: Meadow Wood | BM20: 0 | BN20: 0 | BO20: 0 | BP20: 0 | BQ20: 0 | BR20: 0 | BS20: 0 | BT20: 0
A21: Central School | B21: 107 | C21: 4399956 | D21: 0 | E21: 4544383 | F21: 8944339 | H21: 0 | I21: 0 | J21: 0 | K21: 8944339 | M21: Central School | N21: 2144503 | O21: 1259429 | P21: 48455 | Q21: 154265 | R21: 236915 | S21: 403245 | U21: 0 | V21: 0 | X21: Central School | Y21: 20544 | Z21: 0 | AA21: 132600 | AB21: 4399956 | AD21: Central School | AE21: 0 | AF21: 0 | AG21: 0 | AH21: 0 | AI21: 0 | AJ21: 0 | AK21: 0 | AM21: Central School | AN21: 0 | AO21: 0 | AP21: 0 | AQ21: 0 | AR21: 0 | AT21: Central School | AU21: 0 | AV21: 4517322 | AW21: 20046 | AX21: 0 | AY21: 0 | AZ21: 7016 | BA21: 4544384 | BC21: Central School | BD21: 0 | BE21: 0 | BF21: 0 | BG21: 0 | BH21: 0 | BI21: 4544383 | BL21: Central School | BM21: 0 | BN21: 0 | BO21: 0 | BP21: 0 | BQ21: 0 | BR21: 0 | BS21: 0 | BT21: 0
A22: COUNTY TOTALS | C22: 552857660 | D22: 41123610 | E22: 296274728 | F22: 890255997 | H22: 98425711 | I22: 46858987 | J22: 145282847 | K22: 1035538844 | M22: COUNTY TOTALS | N22: 237754074 | O22: 117918447 | P22: 12262610 | Q22: 16213473 | R22: 31625074 | S22: 38520574 | U22: 17451445 | V22: 5935408 | X22: COUNTY TOTALS | Y22: 2335552 | Z22: 221137 | AA22: 72619866 | AB22: 552857660 | AD22: COUNTY TOTALS | AE22: 13149092 | AF22: 315343 | AG22: 13550988 | AH22: 523042 | AI22: 0 | AJ22: 0 | AK22: 6558450 | AM22: COUNTY TOTALS | AN22: 1681039 | AO22: 300822 | AP22: 656698 | AQ22: 4388136 | AR22: 41123610 | AT22: COUNTY TOTALS | AU22: 188308032 | AV22: 35685634 | AW22: 5568566 | AX22: 465115 | AY22: 244688 | AZ22: 23619493 | BA22: 253981530 | BC22: COUNTY TOTALS | BD22: 49390052 | BE22: 31094689 | BF22: 4644314 | BG22: 4684669 | BH22: 89813725 | BI22: 296274728 | BL22: COUNTY TOTALS | BM22: 98425711 | BN22: 46858987 | BO22: 145284697 | BP22: 0 | BQ22: 0 | BR22: 0 | BS22: 0 | BT22: 145284697
A24: KENT COUNTY | M24: KENT COUNTY | X24: KENT COUNTY | AD24: KENT COUNTY | AM24: KENT COUNTY | AT24: KENT COUNTY | BC24: KENT COUNTY | BL24: KENT COUNTY
A25: Caesar Rodney | B25: 6596 | C25: 55628420 | D25: 4305278 | E25: 10403044 | F25: 70336742 | H25: 0 | I25: 707 | J25: -707 | K25: 70336035 | M25: Caesar Rodney | N25: 21179996 | O25: 10651162 | P25: 988056 | Q25: 1448534 | R25: 8769828 | S25: 2707819 | U25: 4228620 | V25: 1037364 | X25: Caesar Rodney | Y25: 229503 | Z25: 0 | AA25: 4387537 | AB25: 55628420 | AD25: Caesar Rodney | AE25: 1805825 | AF25: 20927 | AG25: 1459532 | AH25: 7 | AI25: 0 | AJ25: 0 | AK25: 605432 | AM25: Caesar Rodney | AN25: 198367 | AO25: 0 | AP25: 85123 | AQ25: 130066 | AR25: 4305278 | AT25: Caesar Rodney | AU25: 3809302 | AV25: 1758352 | AW25: 175638 | AX25: 19831 | AY25: 50142 | AZ25: 3110725 | BA25: 8923990 | BC25: Caesar Rodney | BD25: 2010420 | BE25: 1002592 | BF25: 66909 | BG25: 561482 | BH25: 3641403 | BI25: 10403044 | BL25: Caesar Rodney | BM25: 0 | BN25: 707 | BO25: 707 | BP25: 0 | BQ25: 0 | BR25: 0 | BS25: 0 | BT25: 707
A26: John S. Charlton | B26: 182 | C26: 7071182 | D26: 0 | E26: 3643114 | F26: 10714295 | H26: 0 | I26: 0 | J26: 0 | K26: 10714295 | M26: John S. Charlton | N26: 2630224 | O26: 1266921 | P26: 123137 | Q26: 160671 | R26: 824783 | S26: 1013191 | U26: 702613 | V26: 244768 | X26: John S. Charlton | Y26: 25239 | Z26: 0 | AA26: 79635 | AB26: 7071182 | AD26: John S. Charlton | AE26: 0 | AF26: 0 | AG26: 0 | AH26: 0 | AI26: 0 | AJ26: 0 | AK26: 0 | AM26: John S. Charlton | AN26: 0 | AO26: 0 | AP26: 0 | AQ26: 0 | AR26: 0 | AT26: John S. Charlton | AU26: 0 | AV26: 2924995 | AW26: 29255 | AX26: 0 | AY26: 0 | AZ26: 688864 | BA26: 3643114 | BC26: John S. Charlton | BD26: 0 | BE26: 0 | BF26: 0 | BG26: 0 | BH26: 0 | BI26: 3643114 | BL26: John S. Charlton | BM26: 0 | BN26: 0 | BO26: 0 | BP26: 0 | BQ26: 0 | BR26: 0 | BS26: 0 | BT26: 0
A27: Dover Air Base | B27: 173 | C27: 0 | D27: -264974 | E27: 6215907 | F27: 5950933 | H27: 0 | I27: 0 | J27: 0 | K27: 5950933 | M27: Dover Air Base | N27: 0 | O27: 0 | P27: 0 | Q27: 0 | R27: 0 | S27: 0 | U27: 0 | V27: 0 | X27: Dover Air Base | Y27: 0 | Z27: 0 | AA27: 0 | AB27: 0 | AD27: Dover Air Base | AE27: 0 | AF27: 0 | AG27: 0 | AH27: 0 | AI27: 0 | AJ27: 0 | AK27: 0 | AM27: Dover Air Base | AN27: 0 | AO27: 0 | AP27: 0 | AQ27: 0 | AR27: -264974 | AT27: Dover Air Base | AU27: 0 | AV27: 0 | AW27: 0 | AX27: 0 | AY27: 0 | AZ27: 6215907 | BA27: 6215907 | BC27: Dover Air Base | BD27: 0 | BE27: 0 | BF27: 0 | BG27: 0 | BH27: 0 | BI27: 6215907 | BL27: Dover Air Base | BM27: 0 | BN27: 0 | BO27: 0 | BP27: 0 | BQ27: 0 | BR27: 0 | BS27: 0 | BT27: 0
A28: Capital | B28: 6069 | C28: 54131729 | D28: 7183885 | E28: 16763757 | F28: 78079371 | H28: 0 | I28: 0 | J28: 0 | K28: 78079371 | M28: Capital | N28: 23193720 | O28: 11163354 | P28: 1123311 | Q28: 1458383 | R28: 6413909 | S28: 2965507 | U28: 1903739 | V28: 644646 | X28: Capital | Y28: 244764 | Z28: 2720 | AA28: 5017676 | AB28: 54131729 | AD28: Capital | AE28: 3287894 | AF28: 41751 | AG28: 1406423 | AH28: 46390 | AI28: 0 | AJ28: 0 | AK28: 1013028 | AM28: Capital | AN28: 163350 | AO28: 0 | AP28: 129938 | AQ28: 1095112 | AR28: 7183885 | AT28: Capital | AU28: 9488740 | AV28: 958979 | AW28: 453421 | AX28: 33160 | AY28: 31312 | AZ28: 1307648 | BA28: 12273260 | BC28: Capital | BD28: 3642333 | BE28: 2064691 | BF28: 55941 | BG28: 782703 | BH28: 6545668 | BI28: 16763757 | BL28: Capital | BM28: 0 | BN28: 0 | BO28: 0 | BP28: 0 | BQ28: 0 | BR28: 0 | BS28: 0 | BT28: 0
A29: Polytech | B29: 1162 | C29: 14610912 | D29: 1473299 | E29: 4960631 | F29: 21044843 | H29: 981992 | I29: 245498 | J29: 1227490 | K29: 22272333 | M29: Polytech | N29: 5061855 | O29: 2361293 | P29: 412132 | Q29: 536564 | R29: 1801863 | S29: 1122890 | U29: 298260 | V29: 32241 | X29: Polytech | Y29: 51652 | Z29: 4250 | AA29: 2927912 | AB29: 14610912 | AD29: Polytech | AE29: 126936 | AF29: 7698 | AG29: 173596 | AH29: 7000 | AI29: 0 | AJ29: 0 | AK29: 123008 | AM29: Polytech | AN29: 623948 | AO29: 86458 | AP29: 8740 | AQ29: 315916 | AR29: 1473299 | AT29: Polytech | AU29: 3239673 | AV29: 0 | AW29: 123480 | AX29: 0 | AY29: 14114 | AZ29: 1561524 | BA29: 4938791 | BC29: Polytech | BD29: 0 | BE29: 203552 | BF29: 29899 | BG29: 0 | BH29: 233450 | BI29: 4960631 | BL29: Polytech | BM29: 981992 | BN29: 245498 | BO29: 1227490 | BP29: 0 | BQ29: 0 | BR29: 0 | BS29: 0 | BT29: 1227490
A30: Lake Forest | B30: 3890 | C30: 32678873 | D30: 3102710 | E30: 7573329 | F30: 43354912 | H30: 9103238 | I30: 0 | J30: 9103238 | K30: 52458150 | M30: Lake Forest | N30: 12624237 | O30: 6142843 | P30: 693588 | Q30: 754341 | R30: 5509537 | S30: 2019609 | U30: 2861 | V30: 622 | X30: Lake Forest | Y30: 143806 | Z30: 67235 | AA30: 4720193 | AB30: 32678873 | AD30: Lake Forest | AE30: 1038644 | AF30: 15713 | AG30: 694988 | AH30: 61228 | AI30: 0 | AJ30: 0 | AK30: 430387 | AM30: Lake Forest | AN30: 82197 | AO30: 77626 | AP30: 79390 | AQ30: 622537 | AR30: 3102710 | AT30: Lake Forest | AU30: 2696000 | AV30: 1801712 | AW30: 408651 | AX30: 8848 | AY30: 27375 | AZ30: 1756487 | BA30: 6699073 | BC30: Lake Forest | BD30: 1018343 | BE30: 484085 | BF30: 28089 | BG30: 295100 | BH30: 1825618 | BI30: 7573329 | BL30: Lake Forest | BM30: 9103238 | BN30: 0 | BO30: 9103238 | BP30: 0 | BQ30: 0 | BR30: 0 | BS30: 0 | BT30: 9103238
A31: Milford | B31: 3943 | C31: 33946384 | D31: 2673712 | E31: 5702409 | F31: 42322506 | H31: 0 | I31: 0 | J31: 0 | K31: 42322506 | M31: Milford | N31: 14516176 | O31: 6793859 | P31: 719874 | Q31: 935469 | R31: 4939356 | S31: 2492388 | U31: 1084106 | V31: 251689 | X31: Milford | Y31: 145567 | Z31: 0 | AA31: 2067900 | AB31: 33946384 | AD31: Milford | AE31: 1025784 | AF31: 21213 | AG31: 909114 | AH31: 51246 | AI31: 0 | AJ31: 0 | AK31: 380851 | AM31: Milford | AN31: 71322 | AO31: 0 | AP31: 42497 | AQ31: 171686 | AR31: 2673712 | AT31: Milford | AU31: 3835393 | AV31: 0 | AW31: 399644 | AX31: 10867 | AY31: 29788 | AZ31: 452805 | BA31: 4728497 | BC31: Milford | BD31: 1841294 | BE31: 469989 | BF31: 46104 | BG31: 394172 | BH31: 2751559 | BI31: 5702409 | BL31: Milford | BM31: 0 | BN31: 0 | BO31: 0 | BP31: 0 | BQ31: 0 | BR31: 0 | BS31: 0 | BT31: 0
A32: Smyrna | B32: 4206 | C32: 37071292 | D32: 2023254 | E32: 5506320 | F32: 44600866 | H32: 11355038 | I32: 2381800 | J32: 13736838 | K32: 58337704 | M32: Smyrna | N32: 14474981 | O32: 7014748 | P32: 786569 | Q32: 972673 | R32: 5788787 | S32: 1777691 | U32: 2490201 | V32: 900575 | X32: Smyrna | Y32: 162002 | Z32: 0 | AA32: 2703064 | AB32: 37071292 | AD32: Smyrna | AE32: 798595 | AF32: 9336 | AG32: 732897 | AH32: 45807 | AI32: 0 | AJ32: 0 | AK32: 265961 | AM32: Smyrna | AN32: 91550 | AO32: 0 | AP32: 44062 | AQ32: 35046 | AR32: 2023254 | AT32: Smyrna | AU32: 3658226 | AV32: 0 | AW32: 360976 | AX32: 0 | AY32: 28863 | AZ32: 386634 | BA32: 4434699 | BC32: Smyrna | BD32: 946353 | BE32: 782382 | BF32: 247896 | BG32: 138847 | BH32: 2115478 | BI32: 5506320 | BL32: Smyrna | BM32: 11355038 | BN32: 2381800 | BO32: 13736838 | BP32: 0 | BQ32: 0 | BR32: 0 | BS32: 0 | BT32: 13736838
A33: COUNTY TOTALS | C33: 235138792 | D33: 20497164 | E33: 60768511 | F33: 316404468 | H33: 21440268 | I33: 2628005 | J33: 24066859 | K33: 340471327 | M33: COUNTY TOTALS | N33: 93681189 | O33: 45394180 | P33: 4846667 | Q33: 6266635 | R33: 34048063 | S33: 14099095 | U33: 10710400 | V33: 3111905 | X33: COUNTY TOTALS | Y33: 1002533 | Z33: 74205 | AA33: 21903917 | AB33: 235138792 | AD33: COUNTY TOTALS | AE33: 8083678 | AF33: 116638 | AG33: 5376550 | AH33: 211678 | AI33: 0 | AJ33: 0 | AK33: 2818667 | AM33: COUNTY TOTALS | AN33: 1230734 | AO33: 164084 | AP33: 389750 | AQ33: 2370363 | AR33: 20497164 | AT33: COUNTY TOTALS | AU33: 26727334 | AV33: 7444038 | AW33: 1951065 | AX33: 72706 | AY33: 181594 | AZ33: 15480594 | BA33: 51857331 | BC33: COUNTY TOTALS | BD33: 9458743 | BE33: 5007291 | BF33: 474838 | BG33: 2172304 | BH33: 17113176 | BI33: 60768511 | BL33: COUNTY TOTALS | BM33: 21440268 | BN33: 2628005 | BO33: 24068273 | BP33: 0 | BQ33: 0 | BR33: 0 | BS33: 0 | BT33: 24068273
A35: SUSSEX COUNTY | M35: SUSSEX COUNTY | X35: SUSSEX COUNTY | AD35: SUSSEX COUNTY | AM35: SUSSEX COUNTY | AT35: SUSSEX COUNTY | BC35: SUSSEX COUNTY | BL35: SUSSEX COUNTY
A36: Cape Henlopen | B36: 4368 | C36: 40026958 | D36: 2581820 | E36: 28763180 | F36: 71371958 | H36: 29954000 | I36: 7488500 | J36: 37442500 | K36: 108814458 | M36: Cape Henlopen | N36: 19922398 | O36: 9930655 | P36: 839342 | Q36: 992200 | R36: 552826 | S36: 3409704 | U36: 1506801 | V36: 537677 | X36: Cape Henlopen | Y36: 179024 | Z36: 0 | AA36: 2156331 | AB36: 40026958 | AD36: Cape Henlopen | AE36: 992178 | AF36: 16788 | AG36: 877302 | AH36: 89371 | AI36: 0 | AJ36: 0 | AK36: 394505 | AM36: Cape Henlopen | AN36: 91151 | AO36: 0 | AP36: 64094 | AQ36: 56431 | AR36: 2581820 | AT36: Cape Henlopen | AU36: 13417874 | AV36: 2084983 | AW36: 399504 | AX36: 44987 | AY36: 38536 | AZ36: 1132982 | BA36: 17118866 | BC36: Cape Henlopen | BD36: 6996139 | BE36: 3936995 | BF36: 551299 | BG36: 896790 | BH36: 12381223 | BI36: 28763180 | BL36: Cape Henlopen | BM36: 29954000 | BN36: 7488500 | BO36: 37442500 | BP36: 0 | BQ36: 0 | BR36: 0 | BS36: 0 | BT36: 37442500
A37: Delmar | B37: 1070 | C37: 9811994 | D37: 496718 | E37: 1403602 | F37: 11712314 | H37: 2243460 | I37: 560798 | J37: 2804258 | K37: 14516572 | M37: Delmar | N37: 3740105 | O37: 1861217 | P37: 203466 | Q37: 289658 | R37: 1560478 | S37: 481231 | U37: 718529 | V37: 130918 | X37: Delmar | Y37: 39914 | Z37: 18266 | AA37: 768212 | AB37: 9811994 | AD37: Delmar | AE37: 178371 | AF37: 3455 | AG37: 189328 | AH37: 4948 | AI37: 0 | AJ37: 0 | AK37: 72918 | AM37: Delmar | AN37: 36557 | AO37: 0 | AP37: 6162 | AQ37: 4979 | AR37: 496718 | AT37: Delmar | AU37: 580403 | AV37: 520545 | AW37: 105803 | AX37: 0 | AY37: 34496 | AZ37: 226128 | BA37: 1467375 | BC37: Delmar | BD37: 324444 | BE37: 343101 | BF37: 60820 | BG37: 47470 | BH37: 775835 | BI37: 1403602 | BL37: Delmar | BM37: 2243460 | BN37: 560798 | BO37: 2804258 | BP37: 0 | BQ37: 0 | BR37: 0 | BS37: 0 | BT37: 2804258
A38: Indian River | B38: 7933 | C38: 59736396 | D38: 6189557 | E38: 29743583 | F38: 95669536 | H38: 12242433 | I38: 8161467 | J38: 20403900 | K38: 116073436 | M38: Indian River | N38: 28309183 | O38: 13252713 | P38: 1243935 | Q38: 1712348 | R38: 782243 | S38: 4915191 | U38: 2551290 | V38: 1356321 | X38: Indian River | Y38: 297004 | Z38: 19432 | AA38: 5296737 | AB38: 59736396 | AD38: Indian River | AE38: 2193197 | AF38: 51602 | AG38: 2059149 | AH38: 112006 | AI38: 0 | AJ38: 0 | AK38: 925447 | AM38: Indian River | AN38: 198102 | AO38: 40005 | AP38: 108889 | AQ38: 501160 | AR38: 6189557 | AT38: Indian River | AU38: 18420821 | AV38: 2277450 | AW38: 646714 | AX38: 17082 | AY38: 78909 | AZ38: 3116266 | BA38: 24557243 | BC38: Indian River | BD38: 4322654 | BE38: 4352617 | BF38: 615918 | BG38: 479112 | BH38: 9770301 | BI38: 29743583 | BL38: Indian River | BM38: 0 | BN38: 8161467 | BO38: 8161467 | BP38: 0 | BQ38: 0 | BR38: 0 | BS38: 0 | BT38: 8161467
A39: Howard T. Ennis | B39: 113 | C39: 4919147 | D39: 0 | E39: 2317004 | F39: 7236151 | H39: 0 | I39: 0 | J39: 0 | K39: 7236151 | M39: Howard T. Ennis | N39: 2190131 | O39: 1107494 | P39: 47496 | Q39: 62956 | R39: 39864 | S39: 1002239 | U39: 6877 | V39: 1496 | X39: Howard T. Ennis | Y39: 13500 | Z39: 0 | AA39: 447093 | AB39: 4919147 | AD39: Howard T. Ennis | AE39: 0 | AF39: 0 | AG39: 0 | AH39: 0 | AI39: 0 | AJ39: 0 | AK39: 0 | AM39: Howard T. Ennis | AN39: 0 | AO39: 0 | AP39: 0 | AQ39: 0 | AR39: 0 | AT39: Howard T. Ennis | AU39: 0 | AV39: 2009418 | AW39: 50162 | AX39: 0 | AY39: 78313 | AZ39: 57735 | BA39: 2195627 | BC39: Howard T. Ennis | BD39: 2131 | BE39: 119246 | BF39: 0 | BG39: 0 | BH39: 121377 | BI39: 2317004 | BL39: Howard T. Ennis | BM39: 0 | BN39: 0 | BO39: 0 | BP39: 0 | BQ39: 0 | BR39: 0 | BS39: 0 | BT39: 0
A40: Laurel | B40: 2069 | C40: 17575401 | D40: 1768936 | E40: 3062302 | F40: 22406639 | H40: 0 | I40: 0 | J40: 0 | K40: 22406639 | M40: Laurel | N40: 7746958 | O40: 3760657 | P40: 350312 | Q40: 411334 | R40: 2410086 | S40: 1342789 | U40: 70389 | V40: 15308 | X40: Laurel | Y40: 76892 | Z40: 0 | AA40: 1390675 | AB40: 17575401 | AD40: Laurel | AE40: 796261 | AF40: 23 | AG40: 479359 | AH40: 42294 | AI40: 0 | AJ40: 0 | AK40: 303550 | AM40: Laurel | AN40: 51008 | AO40: 0 | AP40: 40280 | AQ40: 56162 | AR40: 1768936 | AT40: Laurel | AU40: 1672235 | AV40: 0 | AW40: 123821 | AX40: 1800 | AY40: 26116 | AZ40: 608596 | BA40: 2432568 | BC40: Laurel | BD40: 814718 | BE40: 248769 | BF40: 0 | BG40: 0 | BH40: 1063487 | BI40: 3062302 | BL40: Laurel | BM40: 0 | BN40: 0 | BO40: 0 | BP40: 0 | BQ40: 0 | BR40: 0 | BS40: 0 | BT40: 0
A41: Seaford | B41: 3298 | C41: 29384747 | D41: 4774642 | E41: 6125347 | F41: 40284737 | H41: 0 | I41: 0 | J41: 0 | K41: 40284737 | M41: Seaford | N41: 13037026 | O41: 6415365 | P41: 638076 | Q41: 875723 | R41: 4247951 | S41: 1929480 | U41: 220587 | V41: 53146 | X41: Seaford | Y41: 128545 | Z41: 42882 | AA41: 1795965 | AB41: 29384747 | AD41: Seaford | AE41: 2199025 | AF41: 25647 | AG41: 774085 | AH41: 42710 | AI41: 0 | AJ41: 0 | AK41: 495843 | AM41: Seaford | AN41: 96594 | AO41: 0 | AP41: 64026 | AQ41: 1076712 | AR41: 4774642 | AT41: Seaford | AU41: 3689125 | AV41: 758557 | AW41: 224899 | AX41: 12598 | AY41: 34931 | AZ41: 397312 | BA41: 5117422 | BC41: Seaford | BD41: 903979 | BE41: 1038525 | BF41: 65227 | BG41: 187273 | BH41: 2195004 | BI41: 6125347 | BL41: Seaford | BM41: 0 | BN41: 0 | BO41: 0 | BP41: 0 | BQ41: 0 | BR41: 0 | BS41: 0 | BT41: 0
A42: Sussex Technical | B42: 1227 | C42: 13313919 | D42: 926149 | E42: 7170522 | F42: 21410590 | H42: 2763840 | I42: 1842560 | J42: 4606400 | K42: 26016990 | M42: Sussex Technical | N42: 5489864 | O42: 2717079 | P42: 382749 | Q42: 637713 | R42: 247154 | S42: 1700040 | U42: 337676 | V42: 52923 | X42: Sussex Technical | Y42: 54588 | Z42: 2087 | AA42: 1692045 | AB42: 13313919 | AD42: Sussex Technical | AE42: 177882 | AF42: 3272 | AG42: 246164 | AH42: 0 | AI42: 0 | AJ42: 0 | AK42: 83293 | AM42: Sussex Technical | AN42: 248716 | AO42: 81944 | AP42: 6009 | AQ42: 78868 | AR42: 926149 | AT42: Sussex Technical | AU42: 5074556 | AV42: 0 | AW42: 174986 | AX42: 700 | AY42: 32671 | AZ42: 1279572 | BA42: 6562485 | BC42: Sussex Technical | BD42: 0 | BE42: 604795 | BF42: 105975 | BG42: 0 | BH42: 710770 | BI42: 7170522 | BL42: Sussex Technical | BM42: 2763840 | BN42: 1842560 | BO42: 4606400 | BP42: 0 | BQ42: 0 | BR42: 0 | BS42: 0 | BT42: 4606400
...

Sheet DE Charter Master
A1: TABLE 30 | M1: TABLE 31 | X1: TABLE 31 (CONTINUED) | AD1: TABLE 32 | AM1: TABLE 32 (CONTINUED) | AT1: TABLE 33 | BC1: TABLE 33 (CONTINUED)
A2: INCOME SOURCES BY CHARTER SCHOOL | M2: REVENUE RECEIPTS | X2: REVENUE RECEIPTS FOR CHARTER SCHOOLS | AD2: REVENUE RECEIPTS FOR CHARTER SCHOOLS | AM2: REVENUE RECEIPTS FOR CHARTER SCHOOLS | AT2: REVENUE RECEIPTS FOR CHARTER SCHOOLS | BC2: REVENUE RECEIPTS FOR CHARTER SCHOOLS
A3: 2006-2007 | M3: STATE APPROPRIATIONS FOR CHARTER SCHOOLS | X3: STATE APPROPRIATIONS | AD3: FEDERAL SOURCES | AM3: FEDERAL SOURCES | AT3: LOCAL SOURCES | BC3: LOCAL SOURCES
M4: 2006-2007 | X4: 2006-2007 | AD4: 2006-2007 | AM4: 2006-2007 | AT4: 2006-2007 | BC4: 2006-2007
AU5: Current Expenses | BD5: Other Than Current Expenses
C6: Total | D6: Total | E6: Total | F6: Total | H6: Total | I6: Total | J6: Total | K6: Total | N6: State | O6: State | P6: State | Q6: State | R6: State | S6: State | U6: State | V6: State | Y6: State | Z6: State | AA6: State | AB6: Total | AE6: Federal | AF6: Federal | AG6: Federal | AH6: Federal | AI6: Federal | AJ6: Federal | AK6: Federal | AN6: Federal | AO6: Omit | AP6: Federal | AQ6: Federal | AR6: Total | AU6: Local | AV6: Indeterminate | AW6: Other | AX6: Other | AY6: Other | AZ6: Other | BA6: Total | BD6: Taxes For | BE6: Taxes For | BF6: Interest | BG6: Taxes For | BI6: Net
C7: Revenue Receipts | H7: Nonrevenue Receipts | K7: Net Total | N7: Division I | O7: Division I | P7: Division II | Q7: Division II | R7: Division III | S7: Trans- | U7: Debt Service | Y7: Academic | Z7: Related | AA7: Other | AB7: Total | AE7: IASA | AF7: IASA | AG7: IDEA-B | AH7: IDEA-B | AI7: IASA | AJ7: Public | AK7: IASA | AN7: Vocational | AO7: Adult Basic | AP7: Drug Free | AR7: Total | AU7: Taxes for Current | AV7: Tuition | AW7: Interest | AX7: Rent | AY7: Athletic | BD7: Tuition | BE7: Debt | BF7: Construction | BG7: Minor | BH7: Total | BI7: Revenue
A8: District | B8: Enrollment | C8: State | D8: Federal | E8: Net Local | F8: Total | H8: State | I8: Local | J8: Total | K8: Income | M8: District | N8: Salaries | O8: Other Cost | P8: Energy | Q8: Other Cost | R8: Equalization | S8: Portation | U8: Principal | V8: Interest | X8: District | Y8: Allocation | Z8: Services * | AA8: State | AB8: State | AD8: District | AE8: Title I | AF8: Title VI | AG8: Basic | AH8: Pre-School | AI8: Migrant | AJ8: Law 874 | AK8: Title II | AM8: District | AN8: Education | AO8: Education | AP8: Schools | AQ8: Other | AR8: Federal | AT8: District | AU8: Operations | AV8: Incoming | AW8: Received | AX8: Income | AY8: Funds | AZ8: Other | BA8: Total | BC8: District | BD8: Outgoing | BE8: Service | BF8: Fund | BG8: Caps. | BH8: Other | BI8: Receipts
A9: CHARTER SCHOOL | M9: CHARTER SCHOOL | X9: CHARTER SCHOOL | AD9: CHARTER SCHOOL | AM9: CHARTER SCHOOL | AT9: CHARTER SCHOOL | BC9: CHARTER SCHOOL
A11: Charter School of Wilmington | C11: 5319093 | D11: 25168 | E11: 2852399 | F11: 8196660 | H11: 0 | I11: 0 | J11: 0 | K11: 8196660 | M11: Charter School of Wilmington | N11: 0 | O11: 0 | P11: 0 | Q11: 0 | R11: 0 | S11: 0 | T11: 0 | U11: 0 | V11: 0 | X11: Charter School of Wilmington | Y11: 0 | Z11: 0 | AA11: 5319093 | AB11: 5319093 | AD11: Charter School of Wilmington | AE11: 0 | AF11: 2562 | AG11: 2335 | AH11: 0 | AI11: 0 | AJ11: 0 | AK11: 17417 | AM11: Charter School of Wilmington | AN11: 0 | AO11: 0 | AP11: 2854 | AQ11: 0 | AR11: 25168 | AT11: Charter School of Wilmington | AU11: 0 | AV11: 2534741 | AW11: 255587 | AX11: 0 | AY11: 11227 | AZ11: 50844 | BA11: 2852399 | BC11: Charter School of Wilmington | BD11: 0 | BE11: 0 | BF11: 0 | BG11: 0 | BH11: 0 | BI11: 2852399
A12: Positive Outcms | C12: 1541017 | D12: 78640 | E12: 264289 | F12: 1883946 | H12: 0 | I12: 0 | J12: 0 | K12: 1883946 | M12: Positive Outcms | N12: 0 | O12: 0 | P12: 0 | Q12: 0 | R12: 0 | S12: 0 | T12: 0 | U12: 0 | V12: 0 | X12: Positive Outcms | Y12: 0 | Z12: 0 | AA12: 1541017 | AB12: 1541017 | AD12: Positive Outcms | AE12: 33440 | AF12: 788 | AG12: 20831 | AH12: 0 | AI12: 0 | AJ12: 0 | AK12: 8434 | AM12: Positive Outcms | AN12: 13492 | AO12: 0 | AP12: 725 | AQ12: 930 | AR12: 78640 | AT12: Positive Outcms | AU12: 0 | AV12: 0 | AW12: 0 | AX12: 0 | AY12: 0 | AZ12: 265427 | BA12: 265427 | BC12: Positive Outcms | BD12: 0 | BE12: 0 | BF12: 0 | BG12: 0 | BH12: 0 | BI12: 264289
A13: East Side | C13: 1505392 | D13: 115578 | E13: 1392883 | F13: 3013853 | H13: 0 | I13: 0 | J13: 0 | K13: 3013853 | M13: East Side | N13: 0 | O13: 0 | P13: 0 | Q13: 0 | R13: 0 | S13: 0 | T13: 0 | U13: 0 | V13: 0 | X13: East Side | Y13: 0 | Z13: 0 | AA13: 1505392 | AB13: 1505392 | AD13: East Side | AE13: 63138 | AF13: 1728 | AG13: 23483 | AH13: 580 | AI13: 0 | AJ13: 0 | AK13: 18588 | AM13: East Side | AN13: 0 | AO13: 0 | AP13: 6502 | AQ13: 1559 | AR13: 115578 | AT13: East Side | AU13: 0 | AV13: 0 | AW13: 0 | AX13: 0 | AY13: 0 | AZ13: 1392883 | BA13: 1392883 | BC13: East Side | BD13: 0 | BE13: 0 | BF13: 0 | BG13: 0 | BH13: 0 | BI13: 1392883
A14: Campus Comm | C14: 4084029 | D14: 214724 | E14: 736396 | F14: 5035149 | H14: 0 | I14: 0 | J14: 0 | K14: 5035149 | M14: Campus Comm | N14: 0 | O14: 0 | P14: 0 | Q14: 0 | R14: 0 | S14: 0 | T14: 0 | U14: 0 | V14: 0 | X14: Campus Comm | Y14: 0 | Z14: 0 | AA14: 4084029 | AB14: 4084029 | AD14: Campus Comm | AE14: 79476 | AF14: 1584 | AG14: 89236 | AH14: 0 | AI14: 0 | AJ14: 0 | AK14: 22355 | AM14: Campus Comm | AN14: 14476 | AO14: 0 | AP14: 4769 | AQ14: 2827 | AR14: 214724 | AT14: Campus Comm | AU14: 0 | AV14: 653041 | AW14: 14004 | AX14: 0 | AY14: 0 | AZ14: 69351 | BA14: 736396 | BC14: Campus Comm | BD14: 0 | BE14: 0 | BF14: 0 | BG14: 0 | BH14: 0 | BI14: 736396
A15: Thomas Edison | C15: 4933143 | D15: 1122976 | E15: 2913695 | F15: 8969814 | H15: 0 | I15: 0 | J15: 0 | K15: 8969814 | M15: Thomas Edison | N15: 0 | O15: 0 | P15: 0 | Q15: 0 | R15: 0 | S15: 0 | T15: 0 | U15: 0 | V15: 0 | X15: Thomas Edison | Y15: 0 | Z15: 0 | AA15: 4933143 | AB15: 4933143 | AD15: Thomas Edison | AE15: 490783 | AF15: 5077 | AG15: 342304 | AH15: 1512 | AI15: 0 | AJ15: 0 | AK15: 254753 | AM15: Thomas Edison | AN15: 0 | AO15: 0 | AP15: 17100 | AQ15: 11447 | AR15: 1122976 | AT15: Thomas Edison | AU15: 0 | AV15: 2803872 | AW15: 67163 | AX15: 0 | AY15: 0 | AZ15: 0 | BA15: 2913695 | BC15: Thomas Edison | BD15: 0 | BE15: 0 | BF15: 0 | BG15: 0 | BH15: 0 | BI15: 2913695
A16: Sussex Academy | C16: 2173127 | D16: 99320 | E16: 551462 | F16: 2823909 | H16: 0 | I16: 0 | J16: 0 | K16: 2823909 | M16: Sussex Academy | N16: 0 | O16: 0 | P16: 0 | Q16: 0 | R16: 0 | S16: 0 | T16: 0 | U16: 0 | V16: 0 | X16: Sussex Academy | Y16: 0 | Z16: 0 | AA16: 2173127 | AB16: 2173127 | AD16: Sussex Academy | AE16: 25932 | AF16: 4328 | AG16: 47424 | AH16: 0 | AI16: 0 | AJ16: 0 | AK16: 19385 | AM16: Sussex Academy | AN16: 0 | AO16: 0 | AP16: 2250 | AQ16: 0 | AR16: 99320 | AT16: Sussex Academy | AU16: 0 | AV16: 0 | AW16: 0 | AX16: 0 | AY16: 0 | AZ16: 551462 | BA16: 551462 | BC16: Sussex Academy | BD16: 0 | BE16: 0 | BF16: 0 | BG16: 0 | BH16: 0 | BI16: 551462
A17: Delaware Military Academy | C17: 3142234 | D17: 141517 | E17: 2106049 | F17: 5389800 | H17: 0 | I17: 0 | J17: 0 | K17: 5389800 | M17: Delaware Military Academy | N17: 0 | O17: 0 | P17: 0 | Q17: 0 | R17: 0 | S17: 0 | T17: 0 | U17: 0 | V17: 0 | X17: Delaware Military Academy | Y17: 0 | Z17: 0 | AA17: 3142234 | AB17: 3142234 | AD17: Delaware Military Academy | AE17: 61261 | AF17: 893 | AG17: 52777 | AH17: 0 | AI17: 0 | AJ17: 0 | AK17: 13582 | AM17: Delaware Military Academy | AN17: 7846 | AO17: 0 | AP17: 2728 | AQ17: 2431 | AR17: 141517 | AT17: Delaware Military Academy | AU17: 0 | AV17: 0 | AW17: 0 | AX17: 0 | AY17: 0 | AZ17: 2106049 | BA17: 2106049 | BC17: Delaware Military Academy | BD17: 0 | BE17: 0 | BF17: 0 | BG17: 0 | BH17: 0 | BI17: 2106049
A18: Kuumba | C18: 1624415 | D18: 278332 | E18: 971736 | F18: 2874484 | H18: 0 | I18: 0 | J18: 0 | K18: 2874484 | M18: Kuumba | N18: 0 | O18: 0 | P18: 0 | Q18: 0 | R18: 0 | S18: 0 | T18: 0 | U18: 0 | V18: 0 | X18: Kuumba | Y18: 0 | Z18: 0 | AA18: 1624415 | AB18: 1624415 | AD18: Kuumba | AE18: 107823 | AF18: 454 | AG18: 27975 | AH18: 646 | AI18: 0 | AJ18: 0 | AK18: 20065 | AM18: Kuumba | AN18: 0 | AO18: 0 | AP18: 2570 | AQ18: 118800 | AR18: 278332 | AT18: Kuumba | AU18: 0 | AV18: 0 | AW18: 0 | AX18: 0 | AY18: 0 | AZ18: 971736 | BA18: 971736 | BC18: Kuumba | BD18: 0 | BE18: 0 | BF18: 0 | BG18: 0 | BH18: 0 | BI18: 971736
A19: Marion T. Academy | C19: 3162374 | D19: 626164 | E19: 1630455 | F19: 5418993 | H19: 0 | I19: 0 | J19: 0 | K19: 5418993 | M19: Marion T. Academy | N19: 0 | O19: 0 | P19: 0 | Q19: 0 | R19: 0 | S19: 0 | T19: 0 | U19: 0 | V19: 0 | X19: Marion T. Academy | Y19: 0 | Z19: 0 | AA19: 3162374 | AB19: 3162374 | AD19: Marion T. Academy | AE19: 426944 | AF19: 0 | AG19: 147731 | AH19: 3757 | AI19: 0 | AJ19: 0 | AK19: 29342 | AM19: Marion T. Academy | AN19: 0 | AO19: 0 | AP19: 7987 | AQ19: 10402 | AR19: 626164 | AT19: Marion T. Academy | AU19: 0 | AV19: 0 | AW19: 0 | AX19: 0 | AY19: 0 | AZ19: 1633644 | BA19: 1633644 | BC19: Marion T. Academy | BD19: 0 | BE19: 0 | BF19: 0 | BG19: 0 | BH19: 0 | BI19: 1630455
A20: Providence Creek | C20: 4202965 | D20: 223951 | E20: 895220 | F20: 5322136 | H20: 0 | I20: 0 | J20: 0 | K20: 5322136 | M20: Providence Creek | N20: 0 | O20: 0 | P20: 0 | Q20: 5216 | R20: 0 | S20: 0 | T20: 0 | U20: 0 | V20: 0 | X20: Providence Creek | Y20: 0 | Z20: 0 | AA20: 4197749 | AB20: 4202965 | AD20: Providence Creek | AE20: 91306 | AF20: 37 | AG20: 101570 | AH20: 1437 | AI20: 0 | AJ20: 0 | AK20: 19228 | AM20: Providence Creek | AN20: 0 | AO20: 0 | AP20: 4890 | AQ20: 5483 | AR20: 223951 | AT20: Providence Creek | AU20: 0 | AV20: 734830 | AW20: 19948 | AX20: 0 | AY20: 5915 | AZ20: 141228 | BA20: 901922 | BC20: Providence Creek | BD20: 0 | BE20: 0 | BF20: 0 | BG20: 0 | BH20: 0 | BI20: 895220
A21: MOT | C21: 4715827 | D21: 177526 | E21: 1542892 | F21: 6436245 | H21: 0 | I21: 0 | J21: 0 | K21: 6436245 | M21: MOT | N21: 0 | O21: 0 | P21: 0 | Q21: 2608 | R21: 0 | S21: 0 | T21: 0 | U21: 0 | V21: 0 | X21: MOT | Y21: 0 | Z21: 0 | AA21: 4713219 | AB21: 4715827 | AD21: MOT | AE21: 17984 | AF21: 3861 | AG21: 107388 | AH21: 772 | AI21: 0 | AJ21: 0 | AK21: 26783 | AM21: MOT | AN21: 16609 | AO21: 0 | AP21: 3629 | AQ21: 500 | AR21: 177526 | AT21: MOT | AU21: 0 | AV21: 1247976 | AW21: 121770 | AX21: 21200 | AY21: 0 | AZ21: 151946 | BA21: 1542892 | BC21: MOT | BD21: 0 | BE21: 0 | BF21: 0 | BG21: 0 | BH21: 0 | BI21: 1542892
A22: Newark Charter | C22: 4045576 | D22: 137916 | E22: 3313125 | F22: 7496618 | H22: 0 | I22: 0 | J22: 0 | K22: 7496618 | M22: Newark Charter | N22: 0 | O22: 0 | P22: 0 | Q22: 0 | R22: 0 | S22: 0 | T22: 0 | U22: 0 | V22: 0 | X22: Newark Charter | Y22: 0 | Z22: 0 | AA22: 4045576 | AB22: 4045576 | AD22: Newark Charter | AE22: 10970 | AF22: 3664 | AG22: 120726 | AH22: 0 | AI22: 0 | AJ22: 0 | AK22: 1326 | AM22: Newark Charter | AN22: 0 | AO22: 0 | AP22: 606 | AQ22: 625 | AR22: 137916 | AT22: Newark Charter | AU22: 0 | AV22: 2688395 | AW22: 175230 | AX22: 19658 | AY22: 3775 | AZ22: 426167 | BA22: 3313125 | BC22: Newark Charter | BD22: 0 | BE22: 0 | BF22: 0 | BG22: 0 | BH22: 0 | BI22: 3313125
... A30: CHARTER SCHOOL TOTAL | C30: 48546674 | D30: 4698404 | E30: 19596250 | F30: 75693727 | H30: 0 | I30: 0 | J30: 0 | K30: 75693727 | M30: CHARTER SCHOOL TOTAL | N30: 0 | O30: 0 | P30: 0 | Q30: 7824 | R30: 0 | S30: 0 | T30: 0 | U30: 0 | V30: 0 | X30: CHARTER SCHOOL TOTAL | Y30: 0 | Z30: 0 | AA30: 48538850 | AB30: 48546674 | AD30: CHARTER SCHOOL TOTAL | AE30: 1698503 | AF30: 27944 | AG30: 1249501 | AH30: 10920 | AI30: 0 | AJ30: 0 | AK30: 509288 | AM30: CHARTER SCHOOL TOTAL | AN30: 52423 | AO30: 0 | AP30: 63275 | AQ30: 1086549 | AR30: 4698404 | AT30: CHARTER SCHOOL TOTAL | AU30: 0 | AV30: 12695058 | AW30: 700653 | AX30: 40858 | AY30: 20917 | AZ30: 8968359 | BA30: 22468407 | BC30: CHARTER SCHOOL TOTAL | BD30: 0 | BE30: 0 | BF30: 0 | BG30: 0 | BH30: 0 | BI30: 22448649
M31: Note: Row totals may vary due to rounding. | X31: Note: Row totals may vary due to rounding. * Related Services Reflects Contractual Option Only | AD31: Note: Row totals may vary due to rounding. | AM31: Note: Row totals may vary due to rounding. | AT31: Note: Row totals may vary due to rounding. | AX31: Source: School Districts’ Annual Financial Statement To DOE Finance Section | BC31: Source: School Districts’ Annual Financial Statement To DOE Finance Section
A32: Source: School Districts’ Annual Financial Statement To DOE Finance Section | M32: Source: School Districts' Annual Financial Statement To DOE Finance Section | X32: Source: School Districts’ Annual Financial Statement To DOE Finance Section | AD32: Source: School Districts’ Annual Financial Statement To DOE Finance Section | AM32: Source: School Districts’ Annual Financial Statement To DOE Finance Section
AW39: 161 | BC39: 162
F41: 155 | Z41: 157 | AG41: 159 | AO41: 160
Q42: 156
AB43: Revenue Receipts Pie Chart
H45: GRAPH DATA
AB46: Division II
H47: State Funds | I47: Federal Funds | J47: Local Funds* | K47: Total | AB47: 7824
H48: 48546674 | I48: 4698404 | J48: 19596250 | K48: 75693727 | AB48: Division II - $7,824 (0.0%)
H49: State Funds - $48,546,674 64.1% | I49: Federal Funds - $4,698,404 6.2% | J49: Local Funds* - $19,596,250 25.9% | K49: Total $75693727 Million | AB49: 0.00016116449
H50: 0.64135663 | I50: 0.062071247 | J50: 0.25888869 | K50: 0.96231657

Sheet Figures 1,2,4
A1: Figure 1 | I1: Figure 2
A2: Delaware (2006-07) | B2: Statewide | D2: Statewide Weighted for Charter Enrollment | F2: Wilmington | J2: District | K2: Charter | L2: Difference
A3: Per-Pupil Revenue | I3: State | J3: =B4 -> 13654.705 | K3: =B5 -> 9989.5607 | L3: =B6 -> 3665.1442
A4: District | B4: =B14 -> 13654.705 | D4: 13852 | F4: =F14 -> 14754.344 | I4: Statewide Weighted | J4: =D4 -> 13852 | K4: =D5 -> 9990 | L4: =D6 -> 3862
A5: Charter | B5: =C14 -> 9989.5607 | D5: 9990 | F5: =G14 -> 10149.959 | I5: =F2 -> Wilmington | J5: =F4 -> 14754.344 | K5: =F5 -> 10149.959 | L5: =F6 -> 4604.3858
A6: Difference | B6: =B4-B5 -> 3665.1442 | D6: 3862 | F6: =F4-F5 -> 4604.3858
B7: =B6/B4 -> 0.26841621 | D7: 0.279 | F7: =F6/F4 -> 0.31206983
A8: Per-Pupil Revenue by Source | B8: District | C8: Charter | D8: District | E8: Charter | F8: District | G8: Charter
A9: Federal | B9: ='DE District Wrk'!AA48 -> 655.36609 | C9: ='DE Charter Wrk'!Z34 -> 620.25122 | D9: 639 | E9: =C9 -> 620.25122 | F9: ='DE District Wrk'!AA65 -> 565.62103 | G9: ='Wilmington Charters'!Z24 -> 848.88114
A10: State | B10: ='DE District Wrk'!Q48 -> 8586.9638 | C10: ='DE Charter Wrk'!P34 -> 6408.8018 | D10: 8543 | E10: =C10 -> 6408.8018 | F10: ='DE District Wrk'!Q65 -> 8341.543 | G10: ='Wilmington Charters'!P24 -> 5911.7489
A11: Local | B11: ='DE District Wrk'!F48 -> 3402.0159 | C11: ='DE Charter Wrk'!E34 -> 1675.9152 | D11: 3578 | E11: =C11 -> 1675.9152 | F11: ='DE District Wrk'!F65 -> 4382.9856 | G11: ='Wilmington Charters'!E24 -> 1984.813
A12: Other | B12: ='DE District Wrk'!AF48 -> 560.22181 | C12: ='DE Charter Wrk'!AD34 -> 1284.5923 | D12: 559 | E12: =C12 -> 1284.5923 | F12: ='DE District Wrk'!AF65 -> 552.52579 | G12: ='Wilmington Charters'!AD24 -> 1404.5156
A13: Indeterminate | B13: ='DE District Wrk'!AG48 -> 450.13724 | D13: 533 | E13: =C13 -> 0 | F13: ='DE District Wrk'!AG65 -> 911.669
A14: Total | B14: =SUM(B9:B13) -> 13654.705 | C14: =SUM(C9:C13) -> 9989.5607 | D14: =D4 -> 13852 | E14: =C14 -> 9989.5607 | F14: =SUM(F9:F13) -> 14754.344 | G14: =SUM(G9:G13) -> 10149.959
A15: Enrollment
A16: District | B16: ='DE District Wrk'!B44 -> 114250 | D16: n/a | F16: ='DE District Wrk'!B61 -> 34124
B17: =B16/(B16+B18) -> 0.93782064 | D17: n/a | F17: =F16/(F16+F18) -> 0.91392147
A18: Charter | B18: ='DE Charter Wrk'!C30 -> 7575 | D18: n/a | F18: ='Wilmington Charters'!C19 -> 3214
B19: =B18/(B16+B18) -> 0.062179356 | D19: n/a | F19: =F18/(F16+F18) -> 0.086078526
A20: Number of Charters | B20: 17 | D20: n/a | F20: 7
A21: Total Revenue
A22: District | B22: ='DE District Wrk'!AH47 -> 1560050027 | D22: n/a | F22: ='DE District Wrk'!AH64 -> 503477250
B23: =B22/B26 -> 0.95373849 | D23: n/a | F23: =F22/F26 -> 0.93914939
A24: Charter | B24: ='DE Charter Wrk'!AF33 -> 75670922 | D24: n/a | F24: ='Wilmington Charters'!AF23 -> 32621967
B25: =B24/B26 -> 0.046261511 | D25: n/a | F25: =F24/F26 -> 0.060850615
A26: Total | B26: =B22+B24 -> 1635720949 | D26: n/a | F26: =F22+F24 -> 536099217
A27: Percentage of Revenue by Source | B27: District | C27: Charter | D27: District | E27: Charter | F27: District | G27: Charter | I27: Figure 4
A28: Federal | B28: ='DE District Wrk'!AA49 -> 0.047995625 | C28: ='DE Charter Wrk'!Z35 -> 0.06208994 | D28: =D9/D$14 -> 0.046130523 | E28: =C28 -> 0.06208994 | F28: ='DE District Wrk'!AA66 -> 0.038335897 | G28: ='Wilmington Charters'!Z25 -> 0.083633951 | J28: Federal | K28: State | L28: Local | M28: Other | N28: Indeterminate
A29: State | B29: ='DE District Wrk'!Q49 -> 0.62886484 | C29: ='DE Charter Wrk'!P35 -> 0.64154992 | D29: =D10/D$14 -> 0.61673405 | E29: =C29 -> 0.64154992 | F29: ='DE District Wrk'!Q66 -> 0.56536182 | G29: ='Wilmington Charters'!P25 -> 0.58244069 | I29: Statewide District | J29: =B9 -> 655.36609 | K29: =B10 -> 8586.9638 | L29: =B11 -> 3402.0159 | M29: =B12 -> 560.22181 | N29: =B13 -> 450.13724
A30: Local | B30: ='DE District Wrk'!F49 -> 0.24914606 | C30: ='DE Charter Wrk'!E35 -> 0.16776666 | D30: =D11/D$14 -> 0.25830205 | E30: =C30 -> 0.16776666 | F30: ='DE District Wrk'!F66 -> 0.29706407 | G30: ='Wilmington Charters'!E25 -> 0.19554888 | I30: Statewide Charter | J30: =C9 -> 620.25122 | K30: =C10 -> 6408.8018 | L30: =C11 -> 1675.9152 | M30: =C12 -> 1284.5923 | N30: =C13 -> 0
A31: Other | B31: ='DE District Wrk'!AF49 -> 0.04102775 | C31: ='DE Charter Wrk'!AD35 -> 0.12859348 | D31: =D12/D$14 -> 0.040355183 | E31: =C31 -> 0.12859348 | F31: ='DE District Wrk'!AF66 -> 0.037448345 | G31: ='Wilmington Charters'!AD25 -> 0.13837648 | I31: Statewide Weighted | J31: =D9 -> 639 | K31: =D10 -> 8543 | L31: =D11 -> 3578 | M31: =D12 -> 559 | N31: =D13 -> 533
A32: Indeterminate | B32: ='DE District Wrk'!AG49 -> 0.032965725 | D32: =D13/D$14 -> 0.038478198 | E32: =C32 -> 0 | F32: ='DE District Wrk'!AG66 -> 0.061789868 | I32: Wilmington District | J32: =F9 -> 565.62103 | K32: =F10 -> 8341.543 | L32: =F11 -> 4382.9856 | M32: =F12 -> 552.52579 | N32: =F13 -> 911.669
A33: Change in district school funding if subjected to charter funding structure | I33: Wilmington Charter | J33: =G9 -> 848.88114 | K33: =G10 -> 5911.7489 | L33: =G11 -> 1984.813 | M33: =G12 -> 1404.5156 | N33: =G13 -> 0
B34: ($418 million) | F34: ($157 million)
B35: =B6*B16 -> 4.1874272e+08 | F35: =F6*F16 -> 1.5712006e+08

Sheet Figure 3
A1: State Charter School Policies
A2: Figure 3
A3: State Policies | B3: Yes | C3: No | D3: Partial
A4: Charter schools received their funding directly from the state | B4: X
A5: Charter schools are eligible for local funding | B5: X
A6: Cap on funding a charter school can receive | C6: X
A7: District public school receive differential funding (e.g. more funding for 9-12 vs. K-8 schools) | B7: X
A8: Charter schools receive differential funding | B8: X
A9: State allows districts to withhold funding from charter schools for providing adminstrative services | C9: X
A10: State "holds harmless" ditrict funding for charter enrollment | C10: X
A11: School is considered LEA if authorized by non-district organization | B11: X
A12: School is considered LEA if authorized by district | B12: X
A13: Cap on number of charter schools | C13: X
A14: Cap on number of charters schools authorized per year | C14: X
A15: Cap on number of studens attending charter schools | C15: X
A16: Charter schools have an open enrollment policy | B16: X
A19: The state charter school law specified a cap of no more than five charter schools per year for the first three years after passage of the charter school law. Those caps ended with the 1998-99 school year. While the law no longer specifies a cap, local school boards and the state department of education may limit the number of charters geranted in a given year. Such action requires the approval of the state board of education. To date, neither districts nor the state department have requested permission to limite charters in any year.

Sheet Figure 5
A1: Figure 5: State Characteristics
C2: Statewide District | D2: Statewide Charter
A3: Percentage of students eligible for free or reduced price lunch | C3: 0.372 | D3: 0.323
A4: Percentage of schools eligible for Title 1 | C4: 0.831 | D4: 1
A5: Percent of students by school type
B6: Primary (K-5) | C6: 0.434 | D6: 0.594
B7: Middle (6-8) | C7: 0.239 | D7: 0.077
B8: High (9-12) | C8: 0.304 | D8: 0.21
B9: Other (K-12,K-8, etc.) | C9: 0.023 | D9: 0.119

Sheet Figure 6
A1: Figure 6: State Scorecard
B2: Findings | C2: Delaware | E2: Use the following options only
A3: Federal Funding | B3: Charters have access to federal funds according to state statutes (Yes = black, No = white)* | C3: Y | E3: Y
B4: Percentage of federal revenue equals percentage of total enrollment for charter schools (<, >, or =) | C4: > | E4: P
A5: State Funding | B5: Charters have access to state funds according to state statutes (Yes = black, No = white) | C5: Y | E5: N
B6: Percentage of state revenue equals percentage of total enrollment for charter schools (<, >, or =) | C6: >
A7: Local Funding | B7: Charters have access to local funds according to state statutes (Yes = black, No = white) | C7: Y
B8: Percentage of local revenue equals percentage of total enrollment for charter schools (<, >, or =) | C8: >
A9: Facilities Funding | B9: Charters have access to facilities funds according to state statutes (Yes = black, No = white) | C9: N | E9: http://www.doe.k12.de.us/infosuites/schools/charterschools/Reports/charter_DECharterSchoolFAQ-Apr06.pdf
B10: Percentage of facilities revenue equals percentage of total enrollment for charter schools (<, >, or =) | C10: N
A11: Data Availability | B11: State provides detailed, public data on federal, state, local and other revenues for district schools (Yes = black, Partial = grey, No = white) | C11: Y
B12: State provides detailed, public data on federal, state, local and other revenues for charter schools (Yes = black, Partial = grey, No = white) | C12: Y
A13: Funding Formula | B13: Charters are treated as LEAs for funding purposes (Yes = black, Partial = grey, No = white) | C13: Y
B14: State funds student (black) or the LEA (grey) | C14: S | E14: S | F14: L | H14: Use these options for the query to the left only (B18)
B15: State funding formula is fair and equitable (Yes = black, No = white | C15: N
A17: * For this finding, No could indicate that the statue is silent or that it denies access.

Sheet DE District Wrk
A1: TABLE 30
A2: INCOME SOURCES BY DISTRICT
A3: 2006-2007
C4: Local | D4: Local | E4: Local | F4: Local | G4: State | H4: State | I4: State | J4: State | K4: State | L4: State | M4: State | N4: State | O4: State | P4: State | Q4: State | R4: Federal | S4: Federal | T4: Federal | U4: Federal | V4: Federal | W4: Federal | X4: Federal | Y4: Federal | Z4: Federal | AA4: Federal | AB4: Other | AC4: Other | AD4: Other | AE4: Other | AF4: Other | AG4: Indeterminate
C5: tAXes for current | D5: Taxes for Tuition | E5: Taxes for Debt | F5: Taxes for Minor | G5: Division I | H5: Division I | I5: Division II | J5: Division II | K5: Division III | L5: Trans- | M5: Debt Service | O5: Academic | P5: Related | Q5: Other | R5: IASA | S5: IASA | T5: IDEA-B | U5: IDEA-B | V5: IASA | W5: Public | X5: IASA | Y5: Vocational | Z5: Drug Free | AB5: Interest | AC5: Rent | AD5: Athletic | AF5: Interest Construction | AG5: Tuition | AH5: combo of state and local too from the choice program
A6: District | B6: Enrollment | C6: Operations | D6: Outgoing | E6: Service | F6: Caps. | G6: Salaries | H6: Other Cost | I6: Energy | J6: Other Cost | K6: Equalization | L6: Portation | M6: Principal | N6: Interest | O6: Allocation | P6: Services * | Q6: State | R6: Title I | S6: Title VI | T6: Basic | U6: Pre-School | V6: Migrant | W6: Law 874 | X6: Title II | Y6: Education | Z6: Schools | AA6: Other | AB6: Received | AC6: Income | AD6: Funds | AE6: Other | AF6: Fund | AG6: Incoming
A7: NEW CASTLE COUNTY
A8: Appoquinimink | B8: 7563 | C8: 9971564 | D8: 4558320 | E8: 3127855 | F8: 707609 | G8: 23974228 | H8: 11628610 | I8: 1334956 | J8: 1668672 | K8: 7621457 | L8: 3975480 | M8: 2632373 | N8: 705926 | O8: 278221 | P8: 84335 | Q8: 10359577 | R8: 275551 | S8: 32853 | T8: 981819 | U8: 41568 | V8: 0 | W8: 0 | X8: 266718 | Y8: 63667 | Z8: 37529 | AA8: 200815 | AB8: 417820 | AC8: 76663 | AD8: 101667 | AE8: 0 | AF8: 715380 | AG8: 0
A9: Brandywine | B9: 10267 | C9: 33986504 | D9: 5200997 | E9: 5654241 | F9: 883404 | G9: 37262351 | H9: 18248511 | I9: 1798102 | J9: 2395125 | K9: 4176986 | L9: 2943732 | M9: 2843974 | N9: 950216 | O9: 359222 | P9: 777 | Q9: 10316681 | R9: 2723247 | S9: 21143 | T9: 2826704 | U9: 114376 | V9: 0 | W9: 0 | X9: 1266236 | Y9: 271827 | Z9: 128466 | AA9: 321827 | AB9: 758943 | AC9: 42508 | AD9: 31894 | AE9: 5573542 | AF9: 788398 | AG9: 776842
A10: Data Service Center | C10: 0 | D10: 0 | E10: 0 | F10: 0 | G10: 0 | H10: 0 | I10: 0 | J10: 0 | K10: 0 | L10: 0 | M10: 0 | N10: 0 | O10: 0 | P10: 0 | Q10: 0 | R10: 0 | S10: 0 | T10: 0 | U10: 0 | V10: 0 | W10: 0 | X10: 0 | Y10: 0 | Z10: 0 | AA10: 0 | AB10: 0 | AC10: 0 | AD10: 0 | AE10: 2263611 | AF10: 0 | AG10: 0
A11: Christina | B11: 17864 | C11: 56821062 | D11: 20022068 | E11: 9565869 | F11: 1758848 | G11: 56263088 | H11: 27251038 | I11: 2947749 | J11: 3914307 | K11: 6670313 | L11: 14797604 | M11: 4651560 | N11: 1576043 | O11: 477816 | P11: 94440 | Q11: 16764226 | R11: 3460419 | S11: 156594 | T11: 2490600 | U11: 134451 | V11: 0 | W11: 0 | X11: 1615639 | Y11: 407740 | Z11: 157284 | AA11: 1070308 | AB11: 1172681 | AC11: 91003 | AD11: 53974 | AE11: 1949773 | AF11: 1220894 | AG11: 0
A12: Brennen School | B12: 280 | C12: 0 | D12: 0 | E12: 0 | F12: 0 | G12: 7207212 | H12: 3647988 | I12: 208579 | J12: 272157 | K12: 541520 | L12: 0 | M12: 341656 | N12: 202156 | O12: 46957 | P12: 0 | Q12: 244560 | R12: 0 | S12: 0 | T12: 0 | U12: 0 | V12: 0 | W12: 0 | X12: 0 | Y12: 0 | Z12: 0 | AA12: 0 | AB12: 25641 | AC12: 0 | AD12: 0 | AE12: 127660 | AF12: 0 | AG12: 8186947
A13: Margaret S. Sterck | B13: 94 | C13: 0 | D13: 0 | E13: 0 | F13: 0 | G13: 3375267 | H13: 1629453 | I13: 57799 | J13: 75417 | K13: 155687 | L13: 0 | M13: 190 | N13: 41 | O13: 13495 | P13: 0 | Q13: 415895 | R13: 0 | S13: 0 | T13: 0 | U13: 0 | V13: 0 | W13: 0 | X13: 0 | Y13: 0 | Z13: 0 | AA13: 113563 | AB13: 9355 | AC13: 0 | AD13: 0 | AE13: 56091 | AF13: 0 | AG13: 4652439
A14: Reach/CBIP | B14: 0 | C14: 0 | D14: 0 | E14: 0 | F14: 0 | G14: 1217514 | H14: 556026 | I14: 42721 | J14: 55743 | K14: 115073 | L14: 0 | M14: 1231 | N14: 268 | O14: 9978 | P14: 0 | Q14: 58288 | R14: 0 | S14: 0 | T14: 0 | U14: 0 | V14: 0 | W14: 0 | X14: 0 | Y14: 0 | Z14: 0 | AA14: 0 | AB14: 13395 | AC14: 0 | AD14: 0 | AE14: 56433 | AF14: 0 | AG14: 3245371
A15: Douglass | B15: 106 | C15: 0 | D15: 0 | E15: 0 | F15: 0 | G15: 3918718 | H15: 1914586 | I15: 221144 | J15: 288552 | K15: 498440 | L15: 0 | M15: 0 | N15: 0 | O15: 49892 | P15: 0 | Q15: 185485 | R15: 0 | S15: 0 | T15: 0 | U15: 0 | V15: 0 | W15: 0 | X15: 0 | Y15: 0 | Z15: 0 | AA15: 0 | AB15: 10966 | AC15: 0 | AD15: 0 | AE15: 66903 | AF15: 0 | AG15: 6042690
A16: Colonial | B16: 10216 | C16: 22066660 | D16: 7511588 | E16: 4226123 | F16: 1305478 | G16: 31995020 | H16: 15934553 | I16: 1679689 | J16: 2041742 | K16: 3917739 | L16: 5004872 | M16: 5009397 | N16: 1762023 | O16: 365092 | P16: 0 | Q16: 6623097 | R16: 2651082 | S16: 54769 | T16: 2460378 | U16: 115038 | V16: 0 | W16: 0 | X16: 1259978 | Y16: 117920 | Z16: 127598 | AA16: 733122 | AB16: 1666233 | AC16: 42874 | AD16: 21693 | AE16: 21453 | AF16: 436959 | AG16: 598999
A17: John G. Leach | B17: 67 | C17: 0 | D17: 0 | E17: 0 | F17: 0 | G17: 3199539 | H17: 1596941 | I17: 110572 | J17: 119683 | K17: 162456 | L17: 0 | M17: 266111 | N17: 92420 | O17: 14087 | P17: 0 | Q17: 147570 | R17: 0 | S17: 0 | T17: 0 | U17: 0 | V17: 0 | W17: 0 | X17: 0 | Y17: 0 | Z17: 0 | AA17: 0 | AB17: 53904 | AC17: 0 | AD17: 0 | AE17: 135385 | AF17: 0 | AG17: 3200000
A18: New Castle Voc-Tech | B18: 3794 | C18: 23814669 | D18: 0 | E18: 897428 | F18: 0 | G18: 16265912 | H18: 8407392 | I18: 1365665 | J18: 1831125 | K18: 1713144 | L18: 4327018 | M18: 591819 | N18: 133425 | O18: 169633 | P18: 15546 | Q18: 7788053 | R18: 474563 | S18: 9973 | T18: 735552 | U18: 0 | V18: 0 | W18: 0 | X18: 201499 | Y18: 626402 | Z18: 24558 | AA18: 143143 | AB18: 666356 | AC18: 0 | AD18: 35460 | AE18: 1734414 | AF18: 102629 | AG18: 0
