Workbook
Name Bureaus: 'Lookup Values'!$H$3:$I$32
Name Crosswalk: 'Lookup Values'!$A$3:$C$97
Name Funds: 'Lookup Values'!$E$3:$F$91
Name FY2008_09: '$ FY 2008-09'!$A$2:$J$78
Name FY2008_09P: 'Pos FY 2008-09'!$A$2:$F$40
Name FY2009_10: '$ FY 2009-10'!$A$2:$J$80
Name FY2009_10P: 'Pos FY 2009-10'!$A$2:$F$42
Name FY2010_11: '$ FY 2010-11'!$A$2:$J$83
Name FY2010_11P: 'Pos FY 2010-11'!$A$2:$F$42
Name FY2011_12: '$ FY 2011-12'!$A$2:$J$81
Name FY2011_12P: 'Pos FY 2011-12'!$A$2:$F$41
Name FY2012_13: '$ FY 2012-13'!$A$2:$J$80
Name FY2012_13P: 'Pos FY 2012-13'!$A$2:$F$42
Name Model: Model!$A$2:$B$92

Sheet Cost Pool
B1: FY 2012-13 | D1: FY 2014-15
B2: CAL Target | C2: True-Up | D2: CAL Target | E2: Notes
A3: 100-AT | C3: 3896819 | D3: =2407924+2807419 -> 5215343
A4: 100-AU | C4: 7331204 | D4: =3857204+4497147 -> 8354351
A5: 100-BO | C5: 547957 | D5: =906446+1056834 -> 1963280
A6: 100-EM | C6: 1547205 | D6: =934412+1089439 -> 2023851
A7: 100-FR | C7: 118183 | D7: =ROUND((126895*1.025),0) -> 130067 | E7: Emergency mgmt (FREO000004 Fund Center)
A8: 100-GR | C8: 1153236 | D8: =489067+570207 -> 1059274
A9: 100-MF | C9: =6331726+3948799+7738854 -> 18019379 | D9: =3877845+2472450+2282739+4521212+2882650+2661465 -> 18698361 | E9: MFDR, MFIB, MFHR
A10: 100-MY | C10: 1426760 | D10: =880777+1026906 -> 1907683
A11: 100-NI | C11: =276487+99995 -> 376482 | D11: =ROUND(((540500+114494)*1.025),0) -> 671369 | E11: Information & Referral and Public Involvement best practices (CDIR, CDNRNOPI)
A12: 100-OE | C12: =1147492*0.68 -> 780294.56 | D12: =ROUND(((180733+131362+235337+325007)*1.025),0) -> 894250 | E12: Citywide Comm, Training, Tech Support and % admin (CDCEEC, TE, TS & 68% of CDAS)
A13: 100-PA | C13: 1216601 | D13: =427690+498647 -> 926337 | E13: Commissioner's Office (PACO000001)
A14: 100-PN | C14: =982037+889207 -> 1871244 | D14: =ROUND(((0.5*(68428+544977)+758163)*1.025),0) -> 1091487 | E14: Comp Planning & 1/2 of district liaisons (CDAPDI, CDCP00)
A15: 100-PS | C15: 650735 | D15: =427690+498647 -> 926337
A16: 100-PU | C16: 692124 | D16: =427690+498647 -> 926337
A17: 100-PW | C17: 770804 | D17: =427690+498647 -> 926337
A18: 100-SA | C18: 274049 | D18: =134087+156333 -> 290420 | E18: City memberships and dues (MFSA000002)
A19: Total Cost Pool | B19: 44611991 | C19: =SUM(C3:C18) -> 40673077 | D19: =SUM(D3:D18) -> 46005084
A20: Portland Children's Levy Allocation | B20: -25000 | C20: -25000 | D20: -25000
A21: Property Management License | B21: -25000 | C21: -25000 | D21: -25000
A22: Cable Fund | B22: -25000 | C22: -25000 | D22: -25000
A23: Arts Education & Access Fund | B23: -25000 | C23: -25000 | D23: -25000
A24: Convention & Tourism | B24: -25000 | C24: -25000 | D24: -25000
A25: Cost Pool to Allocate | B25: =SUM(B19:B24) -> 44486991 | C25: =SUM(C19:C24) -> 40548077 | D25: =SUM(D19:D24) -> 45880084

Sheet Charges
A1: FY 2014-15 General Fund Overhead
A4: Fund | B4: FY 2013-14 CAL Charge | C4: Difference | D4: FY 2014-15 CAL Charge | E4: FY 2012-13 True-Up | F4: FY 2014-15 Total Charge
A5: 100 - General Fund | B5: 19855263 | C5: 1385103 | D5: 21240366 | E5: 600980 | F5: 21841346
A6: 200 - Transportation Operating Fund | B6: 6564665 | C6: -508470 | D6: 6056195 | E6: -450673 | F6: 5605522
A7: 201 - Assessment Collection Fund | B7: 12 | C7: -12 | D7: 0 | E7: -14 | F7: -14
A8: 202 - Emergency Communication Fund | B8: 877412 | C8: -127411 | D8: 750001 | E8: -93155 | F8: 656846
A9: 203 - Development Services Fund | B9: 1044982 | C9: -65065 | D9: 979917 | E9: 46474 | F9: 1026391
A10: 204 - Property Management License Fund | B10: 0 | C10: 25000 | D10: 25000 | E10: 0 | F10: 25000
A11: 206 - MHCRC Agency Fund | B11: 0 | C11: 25000 | D11: 25000 | E11: 0 | F11: 25000
A12: 209 - Convention and Tourism Fund | B12: 56826 | C12: -31826 | D12: 25000 | E12: 0 | F12: 25000
A13: 213 - Housing Investment Fund | B13: 218979 | C13: -130730 | D13: 88249 | E13: 35960 | F13: 124209
A14: 215 - Parks Local Option Levy Fund | B14: 9633 | C14: 4601 | D14: 14234 | E14: 34000 | F14: 48234
A15: 216 - Children's Investment Fund | B15: 25000 | C15: 0 | D15: 25000 | E15: 0 | F15: 25000
A16: 221 - Tax Increment Financing Reimbursement Fund | B16: 835994 | C16: -92863 | D16: 743131 | E16: -279718 | F16: 463413
... A42: Grand Total | B42: 47391244 | C42: -1386158 | D42: 46005086 | E42: -2483580 | F42: 43521506
C44: Recovery Rate | D44: =1-(GETPIVOTDATA(" FY 2014-15 CAL Charge",$A$3,"Fund","100 - General Fund")/GETPIVOTDATA(" FY 2014-15 CAL Charge",$A$3)) -> 0.53830396

Sheet Model
A1: Allocated Fund | B1: Billed Fund | C1: Fund | D1: Bureau | E1: FY 2008-09 Actuals | F1: FY 2009-10 Actuals | G1: FY 2010-11 Actuals | H1: FY 2011-12 Actuals | I1: FY 2012-13 Actuals | J1: FY 2008-09 Positions | K1: FY 2009-10 Positions | L1: FY 2010-11 Positions | M1: FY 2011-12 Positions | N1: FY 2012-13 Positions | O1: CAL Weighted % | P1: True-Up Weighted % | Q1: FY 2012-13 CAL Charge | R1: FY 2012-13 True-Up | S1: FY 2012-13 True-Up Charge | T1: FY 2013-14 CAL Charge | U1: Difference | V1: FY 2014-15 CAL Charge | W1: FY 2014-15 with True-Up
A2: 100-AT | B2: =VLOOKUP(A2,Crosswalk,2,FALSE) -> 100-AT | C2: =CONCATENATE((LEFT(B2,3))," - ",(VLOOKUP((LEFT(B2,3)),Funds,2,FALSE))) -> 100 - General Fund | D2: =VLOOKUP((RIGHT(B2,2)),Bureaus,2,FALSE) -> Office of the City Attorney | E2: =IF(B2="Excluded",0,(IF(ISNA(VLOOKUP(A2,FY2008_09,10,FALSE)),0,(VLOOKUP(A2,FY2008_09,10,FALSE))))) -> 0 | F2: =IF(B2="Excluded",0,(IF(ISNA(VLOOKUP(A2,FY2009_10,10,FALSE)),0,(VLOOKUP(A2,FY2009_10,10,FALSE))))) -> 0 | G2: =IF(B2="Excluded",0,(IF(ISNA(VLOOKUP(A2,FY2010_11,10,FALSE)),0,(VLOOKUP(A2,FY2010_11,10,FALSE))))) -> 0 | H2: =IF(B2="Excluded",0,(IF(ISNA(VLOOKUP(A2,FY2011_12,10,FALSE)),0,(VLOOKUP(A2,FY2011_12,10,FALSE))))) -> 0 | I2: =IF(B2="Excluded",0,(IF(ISNA(VLOOKUP(A2,FY2012_13,10,FALSE)),0,(VLOOKUP(A2,FY2012_13,10,FALSE))))) -> 0 | J2: =IF(B2="Excluded",0,(IF(ISNA(VLOOKUP(A2,FY2008_09P,6,FALSE)),0,(VLOOKUP(A2,FY2008_09P,6,FALSE))))) -> 0 | K2: =IF(B2="Excluded",0,(IF(ISNA(VLOOKUP(A2,FY2009_10P,6,FALSE)),0,(VLOOKUP(A2,FY2009_10P,6,FALSE))))) -> 0 | L2: =IF(B2="Excluded",0,(IF(ISNA(VLOOKUP(A2,FY2010_11P,6,FALSE)),0,(VLOOKUP(A2,FY2010_11P,6,FALSE))))) -> 0 | M2: =IF(B2="Excluded",0,(IF(ISNA(VLOOKUP(A2,FY2011_12P,6,FALSE)),0,(VLOOKUP(A2,FY2011_12P,6,FALSE))))) -> 0 | N2: =IF(B2="Excluded",0,(IF(ISNA(VLOOKUP(A2,FY2012_13P,6,FALSE)),0,(VLOOKUP(A2,FY2012_13P,6,FALSE))))) -> 0 | O2: =(AVERAGE(G2:I2)*0.75)+(AVERAGE(L2:N2)*0.25) -> 0 | P2: =(AVERAGE(E2:G2)*0.75)+(AVERAGE(J2:L2)*0.25) -> 0 | Q2: 0 | R2: =S2-Q2 -> 0 | S2: =ROUND((P2*'Cost Pool'!$C$25),0) -> 0 | U2: =V2-T2 -> 0 | V2: =ROUND((O2*'Cost Pool'!$D$25),0) -> 0 | W2: =V2+R2 -> 0
A3: 100-AU | B3: =VLOOKUP(A3,Crosswalk,2,FALSE) -> 100-AU | C3: =CONCATENATE((LEFT(B3,3))," - ",(VLOOKUP((LEFT(B3,3)),Funds,2,FALSE))) -> 100 - General Fund | D3: =VLOOKUP((RIGHT(B3,2)),Bureaus,2,FALSE) -> Office of the City Auditor | E3: =IF(B3="Excluded",0,(IF(ISNA(VLOOKUP(A3,FY2008_09,10,FALSE)),0,(VLOOKUP(A3,FY2008_09,10,FALSE))))) -> 0 | F3: =IF(B3="Excluded",0,(IF(ISNA(VLOOKUP(A3,FY2009_10,10,FALSE)),0,(VLOOKUP(A3,FY2009_10,10,FALSE))))) -> 0 | G3: =IF(B3="Excluded",0,(IF(ISNA(VLOOKUP(A3,FY2010_11,10,FALSE)),0,(VLOOKUP(A3,FY2010_11,10,FALSE))))) -> 0 | H3: =IF(B3="Excluded",0,(IF(ISNA(VLOOKUP(A3,FY2011_12,10,FALSE)),0,(VLOOKUP(A3,FY2011_12,10,FALSE))))) -> 0 | I3: =IF(B3="Excluded",0,(IF(ISNA(VLOOKUP(A3,FY2012_13,10,FALSE)),0,(VLOOKUP(A3,FY2012_13,10,FALSE))))) -> 0 | J3: =IF(B3="Excluded",0,(IF(ISNA(VLOOKUP(A3,FY2008_09P,6,FALSE)),0,(VLOOKUP(A3,FY2008_09P,6,FALSE))))) -> 0 | K3: =IF(B3="Excluded",0,(IF(ISNA(VLOOKUP(A3,FY2009_10P,6,FALSE)),0,(VLOOKUP(A3,FY2009_10P,6,FALSE))))) -> 0 | L3: =IF(B3="Excluded",0,(IF(ISNA(VLOOKUP(A3,FY2010_11P,6,FALSE)),0,(VLOOKUP(A3,FY2010_11P,6,FALSE))))) -> 0 | M3: =IF(B3="Excluded",0,(IF(ISNA(VLOOKUP(A3,FY2011_12P,6,FALSE)),0,(VLOOKUP(A3,FY2011_12P,6,FALSE))))) -> 0 | N3: =IF(B3="Excluded",0,(IF(ISNA(VLOOKUP(A3,FY2012_13P,6,FALSE)),0,(VLOOKUP(A3,FY2012_13P,6,FALSE))))) -> 0 | O3: =(AVERAGE(G3:I3)*0.75)+(AVERAGE(L3:N3)*0.25) -> 0 | P3: =(AVERAGE(E3:G3)*0.75)+(AVERAGE(J3:L3)*0.25) -> 0 | R3: =S3-Q3 -> 0 | S3: =ROUND((P3*'Cost Pool'!$C$25),0) -> 0 | U3: =V3-T3 -> 0 | V3: =ROUND((O3*'Cost Pool'!$D$25),0) -> 0 | W3: =V3+R3 -> 0
A4: 100-BO | B4: =VLOOKUP(A4,Crosswalk,2,FALSE) -> 100-BO | C4: =CONCATENATE((LEFT(B4,3))," - ",(VLOOKUP((LEFT(B4,3)),Funds,2,FALSE))) -> 100 - General Fund | D4: =VLOOKUP((RIGHT(B4,2)),Bureaus,2,FALSE) -> City Budget Office | E4: =IF(B4="Excluded",0,(IF(ISNA(VLOOKUP(A4,FY2008_09,10,FALSE)),0,(VLOOKUP(A4,FY2008_09,10,FALSE))))) -> 0 | F4: =IF(B4="Excluded",0,(IF(ISNA(VLOOKUP(A4,FY2009_10,10,FALSE)),0,(VLOOKUP(A4,FY2009_10,10,FALSE))))) -> 0 | G4: =IF(B4="Excluded",0,(IF(ISNA(VLOOKUP(A4,FY2010_11,10,FALSE)),0,(VLOOKUP(A4,FY2010_11,10,FALSE))))) -> 0 | H4: =IF(B4="Excluded",0,(IF(ISNA(VLOOKUP(A4,FY2011_12,10,FALSE)),0,(VLOOKUP(A4,FY2011_12,10,FALSE))))) -> 0 | I4: =IF(B4="Excluded",0,(IF(ISNA(VLOOKUP(A4,FY2012_13,10,FALSE)),0,(VLOOKUP(A4,FY2012_13,10,FALSE))))) -> 0 | J4: =IF(B4="Excluded",0,(IF(ISNA(VLOOKUP(A4,FY2008_09P,6,FALSE)),0,(VLOOKUP(A4,FY2008_09P,6,FALSE))))) -> 0 | K4: =IF(B4="Excluded",0,(IF(ISNA(VLOOKUP(A4,FY2009_10P,6,FALSE)),0,(VLOOKUP(A4,FY2009_10P,6,FALSE))))) -> 0 | L4: =IF(B4="Excluded",0,(IF(ISNA(VLOOKUP(A4,FY2010_11P,6,FALSE)),0,(VLOOKUP(A4,FY2010_11P,6,FALSE))))) -> 0 | M4: =IF(B4="Excluded",0,(IF(ISNA(VLOOKUP(A4,FY2011_12P,6,FALSE)),0,(VLOOKUP(A4,FY2011_12P,6,FALSE))))) -> 0 | N4: =IF(B4="Excluded",0,(IF(ISNA(VLOOKUP(A4,FY2012_13P,6,FALSE)),0,(VLOOKUP(A4,FY2012_13P,6,FALSE))))) -> 0 | O4: =(AVERAGE(G4:I4)*0.75)+(AVERAGE(L4:N4)*0.25) -> 0 | P4: =(AVERAGE(E4:G4)*0.75)+(AVERAGE(J4:L4)*0.25) -> 0 | R4: =S4-Q4 -> 0 | S4: =ROUND((P4*'Cost Pool'!$C$25),0) -> 0 | U4: =V4-T4 -> 0 | V4: =ROUND((O4*'Cost Pool'!$D$25),0) -> 0 | W4: =V4+R4 -> 0
A5: 100-CB | B5: =VLOOKUP(A5,Crosswalk,2,FALSE) -> 100-MF | C5: =CONCATENATE((LEFT(B5,3))," - ",(VLOOKUP((LEFT(B5,3)),Funds,2,FALSE))) -> 100 - General Fund | D5: =VLOOKUP((RIGHT(B5,2)),Bureaus,2,FALSE) -> Office of Management & Finance | E5: =IF(B5="Excluded",0,(IF(ISNA(VLOOKUP(A5,FY2008_09,10,FALSE)),0,(VLOOKUP(A5,FY2008_09,10,FALSE))))) -> 0.0022176202 | F5: =IF(B5="Excluded",0,(IF(ISNA(VLOOKUP(A5,FY2009_10,10,FALSE)),0,(VLOOKUP(A5,FY2009_10,10,FALSE))))) -> 0.0018047776 | G5: =IF(B5="Excluded",0,(IF(ISNA(VLOOKUP(A5,FY2010_11,10,FALSE)),0,(VLOOKUP(A5,FY2010_11,10,FALSE))))) -> 0.0014272866 | H5: =IF(B5="Excluded",0,(IF(ISNA(VLOOKUP(A5,FY2011_12,10,FALSE)),0,(VLOOKUP(A5,FY2011_12,10,FALSE))))) -> 0.001956749 | I5: =IF(B5="Excluded",0,(IF(ISNA(VLOOKUP(A5,FY2012_13,10,FALSE)),0,(VLOOKUP(A5,FY2012_13,10,FALSE))))) -> 0 | J5: =IF(B5="Excluded",0,(IF(ISNA(VLOOKUP(A5,FY2008_09P,6,FALSE)),0,(VLOOKUP(A5,FY2008_09P,6,FALSE))))) -> 0.0011472275 | K5: =IF(B5="Excluded",0,(IF(ISNA(VLOOKUP(A5,FY2009_10P,6,FALSE)),0,(VLOOKUP(A5,FY2009_10P,6,FALSE))))) -> 0.0011013216 | L5: =IF(B5="Excluded",0,(IF(ISNA(VLOOKUP(A5,FY2010_11P,6,FALSE)),0,(VLOOKUP(A5,FY2010_11P,6,FALSE))))) -> 0.0011307243 | M5: =IF(B5="Excluded",0,(IF(ISNA(VLOOKUP(A5,FY2011_12P,6,FALSE)),0,(VLOOKUP(A5,FY2011_12P,6,FALSE))))) -> 0.0010948239 | N5: =IF(B5="Excluded",0,(IF(ISNA(VLOOKUP(A5,FY2012_13P,6,FALSE)),0,(VLOOKUP(A5,FY2012_13P,6,FALSE))))) -> 0 | O5: =(AVERAGE(G5:I5)*0.75)+(AVERAGE(L5:N5)*0.25) -> 0.0010314712 | P5: =(AVERAGE(E5:G5)*0.75)+(AVERAGE(J5:L5)*0.25) -> 0.0016440272 | Q5: 55477 | R5: =S5-Q5 -> 11185 | S5: =ROUND((P5*'Cost Pool'!$C$25),0) -> 66662 | T5: 74159 | U5: =V5-T5 -> -26835 | V5: =ROUND((O5*'Cost Pool'!$D$25),0) -> 47324 | W5: =V5+R5 -> 58509
A6: 100-EM | B6: =VLOOKUP(A6,Crosswalk,2,FALSE) -> 100-EM | C6: =CONCATENATE((LEFT(B6,3))," - ",(VLOOKUP((LEFT(B6,3)),Funds,2,FALSE))) -> 100 - General Fund | D6: =VLOOKUP((RIGHT(B6,2)),Bureaus,2,FALSE) -> Portland Bureau of Emergency Management | E6: =IF(B6="Excluded",0,(IF(ISNA(VLOOKUP(A6,FY2008_09,10,FALSE)),0,(VLOOKUP(A6,FY2008_09,10,FALSE))))) -> 0 | F6: =IF(B6="Excluded",0,(IF(ISNA(VLOOKUP(A6,FY2009_10,10,FALSE)),0,(VLOOKUP(A6,FY2009_10,10,FALSE))))) -> 0 | G6: =IF(B6="Excluded",0,(IF(ISNA(VLOOKUP(A6,FY2010_11,10,FALSE)),0,(VLOOKUP(A6,FY2010_11,10,FALSE))))) -> 0 | H6: =IF(B6="Excluded",0,(IF(ISNA(VLOOKUP(A6,FY2011_12,10,FALSE)),0,(VLOOKUP(A6,FY2011_12,10,FALSE))))) -> 0 | I6: =IF(B6="Excluded",0,(IF(ISNA(VLOOKUP(A6,FY2012_13,10,FALSE)),0,(VLOOKUP(A6,FY2012_13,10,FALSE))))) -> 0 | J6: =IF(B6="Excluded",0,(IF(ISNA(VLOOKUP(A6,FY2008_09P,6,FALSE)),0,(VLOOKUP(A6,FY2008_09P,6,FALSE))))) -> 0 | K6: =IF(B6="Excluded",0,(IF(ISNA(VLOOKUP(A6,FY2009_10P,6,FALSE)),0,(VLOOKUP(A6,FY2009_10P,6,FALSE))))) -> 0 | L6: =IF(B6="Excluded",0,(IF(ISNA(VLOOKUP(A6,FY2010_11P,6,FALSE)),0,(VLOOKUP(A6,FY2010_11P,6,FALSE))))) -> 0 | M6: =IF(B6="Excluded",0,(IF(ISNA(VLOOKUP(A6,FY2011_12P,6,FALSE)),0,(VLOOKUP(A6,FY2011_12P,6,FALSE))))) -> 0 | N6: =IF(B6="Excluded",0,(IF(ISNA(VLOOKUP(A6,FY2012_13P,6,FALSE)),0,(VLOOKUP(A6,FY2012_13P,6,FALSE))))) -> 0 | O6: =(AVERAGE(G6:I6)*0.75)+(AVERAGE(L6:N6)*0.25) -> 0 | P6: =(AVERAGE(E6:G6)*0.75)+(AVERAGE(J6:L6)*0.25) -> 0 | R6: =S6-Q6 -> 0 | S6: =ROUND((P6*'Cost Pool'!$C$25),0) -> 0 | U6: =V6-T6 -> 0 | V6: =ROUND((O6*'Cost Pool'!$D$25),0) -> 0 | W6: =V6+R6 -> 0
A7: 100-FM | B7: =VLOOKUP(A7,Crosswalk,2,FALSE) -> Excluded | C7: =CONCATENATE((LEFT(B7,3))," - ",(VLOOKUP((LEFT(B7,3)),Funds,2,FALSE))) -> #N/A | D7: =VLOOKUP((RIGHT(B7,2)),Bureaus,2,FALSE) -> #N/A | E7: =IF(B7="Excluded",0,(IF(ISNA(VLOOKUP(A7,FY2008_09,10,FALSE)),0,(VLOOKUP(A7,FY2008_09,10,FALSE))))) -> 0 | F7: =IF(B7="Excluded",0,(IF(ISNA(VLOOKUP(A7,FY2009_10,10,FALSE)),0,(VLOOKUP(A7,FY2009_10,10,FALSE))))) -> 0 | G7: =IF(B7="Excluded",0,(IF(ISNA(VLOOKUP(A7,FY2010_11,10,FALSE)),0,(VLOOKUP(A7,FY2010_11,10,FALSE))))) -> 0 | H7: =IF(B7="Excluded",0,(IF(ISNA(VLOOKUP(A7,FY2011_12,10,FALSE)),0,(VLOOKUP(A7,FY2011_12,10,FALSE))))) -> 0 | I7: =IF(B7="Excluded",0,(IF(ISNA(VLOOKUP(A7,FY2012_13,10,FALSE)),0,(VLOOKUP(A7,FY2012_13,10,FALSE))))) -> 0 | J7: =IF(B7="Excluded",0,(IF(ISNA(VLOOKUP(A7,FY2008_09P,6,FALSE)),0,(VLOOKUP(A7,FY2008_09P,6,FALSE))))) -> 0 | K7: =IF(B7="Excluded",0,(IF(ISNA(VLOOKUP(A7,FY2009_10P,6,FALSE)),0,(VLOOKUP(A7,FY2009_10P,6,FALSE))))) -> 0 | L7: =IF(B7="Excluded",0,(IF(ISNA(VLOOKUP(A7,FY2010_11P,6,FALSE)),0,(VLOOKUP(A7,FY2010_11P,6,FALSE))))) -> 0 | M7: =IF(B7="Excluded",0,(IF(ISNA(VLOOKUP(A7,FY2011_12P,6,FALSE)),0,(VLOOKUP(A7,FY2011_12P,6,FALSE))))) -> 0 | N7: =IF(B7="Excluded",0,(IF(ISNA(VLOOKUP(A7,FY2012_13P,6,FALSE)),0,(VLOOKUP(A7,FY2012_13P,6,FALSE))))) -> 0 | O7: =(AVERAGE(G7:I7)*0.75)+(AVERAGE(L7:N7)*0.25) -> 0 | P7: =(AVERAGE(E7:G7)*0.75)+(AVERAGE(J7:L7)*0.25) -> 0 | R7: =S7-Q7 -> 0 | S7: =ROUND((P7*'Cost Pool'!$C$25),0) -> 0 | U7: =V7-T7 -> 0 | V7: =ROUND((O7*'Cost Pool'!$D$25),0) -> 0 | W7: =V7+R7 -> 0
A8: 100-FR | B8: =VLOOKUP(A8,Crosswalk,2,FALSE) -> 100-FR | C8: =CONCATENATE((LEFT(B8,3))," - ",(VLOOKUP((LEFT(B8,3)),Funds,2,FALSE))) -> 100 - General Fund | D8: =VLOOKUP((RIGHT(B8,2)),Bureaus,2,FALSE) -> Portland Fire & Rescue | E8: =IF(B8="Excluded",0,(IF(ISNA(VLOOKUP(A8,FY2008_09,10,FALSE)),0,(VLOOKUP(A8,FY2008_09,10,FALSE))))) -> 0.095037556 | F8: =IF(B8="Excluded",0,(IF(ISNA(VLOOKUP(A8,FY2009_10,10,FALSE)),0,(VLOOKUP(A8,FY2009_10,10,FALSE))))) -> 0.093702445 | G8: =IF(B8="Excluded",0,(IF(ISNA(VLOOKUP(A8,FY2010_11,10,FALSE)),0,(VLOOKUP(A8,FY2010_11,10,FALSE))))) -> 0.092479395 | H8: =IF(B8="Excluded",0,(IF(ISNA(VLOOKUP(A8,FY2011_12,10,FALSE)),0,(VLOOKUP(A8,FY2011_12,10,FALSE))))) -> 0.10048504 | I8: =IF(B8="Excluded",0,(IF(ISNA(VLOOKUP(A8,FY2012_13,10,FALSE)),0,(VLOOKUP(A8,FY2012_13,10,FALSE))))) -> 0.095039456 | J8: =IF(B8="Excluded",0,(IF(ISNA(VLOOKUP(A8,FY2008_09P,6,FALSE)),0,(VLOOKUP(A8,FY2008_09P,6,FALSE))))) -> 0.098279159 | K8: =IF(B8="Excluded",0,(IF(ISNA(VLOOKUP(A8,FY2009_10P,6,FALSE)),0,(VLOOKUP(A8,FY2009_10P,6,FALSE))))) -> 0.092755751 | L8: =IF(B8="Excluded",0,(IF(ISNA(VLOOKUP(A8,FY2010_11P,6,FALSE)),0,(VLOOKUP(A8,FY2010_11P,6,FALSE))))) -> 0.097744833 | M8: =IF(B8="Excluded",0,(IF(ISNA(VLOOKUP(A8,FY2011_12P,6,FALSE)),0,(VLOOKUP(A8,FY2011_12P,6,FALSE))))) -> 0.095249681 | N8: =IF(B8="Excluded",0,(IF(ISNA(VLOOKUP(A8,FY2012_13P,6,FALSE)),0,(VLOOKUP(A8,FY2012_13P,6,FALSE))))) -> 0.083984709 | O8: =(AVERAGE(G8:I8)*0.75)+(AVERAGE(L8:N8)*0.25) -> 0.095082576 | P8: =(AVERAGE(E8:G8)*0.75)+(AVERAGE(J8:L8)*0.25) -> 0.094369828 | Q8: 3790346 | R8: =S8-Q8 -> 36169 | S8: =ROUND((P8*'Cost Pool'!$C$25),0) -> 3826515 | T8: 4615922 | U8: =V8-T8 -> -253525 | V8: =ROUND((O8*'Cost Pool'!$D$25),0) -> 4362397 | W8: =V8+R8 -> 4398566
A9: 100-GR | B9: =VLOOKUP(A9,Crosswalk,2,FALSE) -> 100-GR | C9: =CONCATENATE((LEFT(B9,3))," - ",(VLOOKUP((LEFT(B9,3)),Funds,2,FALSE))) -> 100 - General Fund | D9: =VLOOKUP((RIGHT(B9,2)),Bureaus,2,FALSE) -> Office of Government Relations | E9: =IF(B9="Excluded",0,(IF(ISNA(VLOOKUP(A9,FY2008_09,10,FALSE)),0,(VLOOKUP(A9,FY2008_09,10,FALSE))))) -> 0 | F9: =IF(B9="Excluded",0,(IF(ISNA(VLOOKUP(A9,FY2009_10,10,FALSE)),0,(VLOOKUP(A9,FY2009_10,10,FALSE))))) -> 0 | G9: =IF(B9="Excluded",0,(IF(ISNA(VLOOKUP(A9,FY2010_11,10,FALSE)),0,(VLOOKUP(A9,FY2010_11,10,FALSE))))) -> 0 | H9: =IF(B9="Excluded",0,(IF(ISNA(VLOOKUP(A9,FY2011_12,10,FALSE)),0,(VLOOKUP(A9,FY2011_12,10,FALSE))))) -> 0 | I9: =IF(B9="Excluded",0,(IF(ISNA(VLOOKUP(A9,FY2012_13,10,FALSE)),0,(VLOOKUP(A9,FY2012_13,10,FALSE))))) -> 0 | J9: =IF(B9="Excluded",0,(IF(ISNA(VLOOKUP(A9,FY2008_09P,6,FALSE)),0,(VLOOKUP(A9,FY2008_09P,6,FALSE))))) -> 0 | K9: =IF(B9="Excluded",0,(IF(ISNA(VLOOKUP(A9,FY2009_10P,6,FALSE)),0,(VLOOKUP(A9,FY2009_10P,6,FALSE))))) -> 0 | L9: =IF(B9="Excluded",0,(IF(ISNA(VLOOKUP(A9,FY2010_11P,6,FALSE)),0,(VLOOKUP(A9,FY2010_11P,6,FALSE))))) -> 0 | M9: =IF(B9="Excluded",0,(IF(ISNA(VLOOKUP(A9,FY2011_12P,6,FALSE)),0,(VLOOKUP(A9,FY2011_12P,6,FALSE))))) -> 0 | N9: =IF(B9="Excluded",0,(IF(ISNA(VLOOKUP(A9,FY2012_13P,6,FALSE)),0,(VLOOKUP(A9,FY2012_13P,6,FALSE))))) -> 0 | O9: =(AVERAGE(G9:I9)*0.75)+(AVERAGE(L9:N9)*0.25) -> 0 | P9: =(AVERAGE(E9:G9)*0.75)+(AVERAGE(J9:L9)*0.25) -> 0 | R9: =S9-Q9 -> 0 | S9: =ROUND((P9*'Cost Pool'!$C$25),0) -> 0 | U9: =V9-T9 -> 0 | V9: =ROUND((O9*'Cost Pool'!$D$25),0) -> 0 | W9: =V9+R9 -> 0
A10: 100-HC | B10: =VLOOKUP(A10,Crosswalk,2,FALSE) -> 100-HC | C10: =CONCATENATE((LEFT(B10,3))," - ",(VLOOKUP((LEFT(B10,3)),Funds,2,FALSE))) -> 100 - General Fund | D10: =VLOOKUP((RIGHT(B10,2)),Bureaus,2,FALSE) -> Portland Housing Bureau | E10: =IF(B10="Excluded",0,(IF(ISNA(VLOOKUP(A10,FY2008_09,10,FALSE)),0,(VLOOKUP(A10,FY2008_09,10,FALSE))))) -> 0.016583044 | F10: =IF(B10="Excluded",0,(IF(ISNA(VLOOKUP(A10,FY2009_10,10,FALSE)),0,(VLOOKUP(A10,FY2009_10,10,FALSE))))) -> 0.013071424 | G10: =IF(B10="Excluded",0,(IF(ISNA(VLOOKUP(A10,FY2010_11,10,FALSE)),0,(VLOOKUP(A10,FY2010_11,10,FALSE))))) -> 0.01107242 | H10: =IF(B10="Excluded",0,(IF(ISNA(VLOOKUP(A10,FY2011_12,10,FALSE)),0,(VLOOKUP(A10,FY2011_12,10,FALSE))))) -> 0.013028296 | I10: =IF(B10="Excluded",0,(IF(ISNA(VLOOKUP(A10,FY2012_13,10,FALSE)),0,(VLOOKUP(A10,FY2012_13,10,FALSE))))) -> 0.011762371 | J10: =IF(B10="Excluded",0,(IF(ISNA(VLOOKUP(A10,FY2008_09P,6,FALSE)),0,(VLOOKUP(A10,FY2008_09P,6,FALSE))))) -> 0.0052262588 | K10: =IF(B10="Excluded",0,(IF(ISNA(VLOOKUP(A10,FY2009_10P,6,FALSE)),0,(VLOOKUP(A10,FY2009_10P,6,FALSE))))) -> 0.0045276554 | L10: =IF(B10="Excluded",0,(IF(ISNA(VLOOKUP(A10,FY2010_11P,6,FALSE)),0,(VLOOKUP(A10,FY2010_11P,6,FALSE))))) -> 0.0087945223 | M10: =IF(B10="Excluded",0,(IF(ISNA(VLOOKUP(A10,FY2011_12P,6,FALSE)),0,(VLOOKUP(A10,FY2011_12P,6,FALSE))))) -> 0.0074204732 | N10: =IF(B10="Excluded",0,(IF(ISNA(VLOOKUP(A10,FY2012_13P,6,FALSE)),0,(VLOOKUP(A10,FY2012_13P,6,FALSE))))) -> 0.0066183602 | O10: =(AVERAGE(G10:I10)*0.75)+(AVERAGE(L10:N10)*0.25) -> 0.010868552 | P10: =(AVERAGE(E10:G10)*0.75)+(AVERAGE(J10:L10)*0.25) -> 0.011727425 | Q10: 619527 | R10: =S10-Q10 -> -144002 | S10: =ROUND((P10*'Cost Pool'!$C$25),0) -> 475525 | T10: 756944 | U10: =V10-T10 -> -258294 | V10: =ROUND((O10*'Cost Pool'!$D$25),0) -> 498650 | W10: =V10+R10 -> 354648
A11: 100-HN | B11: =VLOOKUP(A11,Crosswalk,2,FALSE) -> Excluded | C11: =CONCATENATE((LEFT(B11,3))," - ",(VLOOKUP((LEFT(B11,3)),Funds,2,FALSE))) -> #N/A | D11: =VLOOKUP((RIGHT(B11,2)),Bureaus,2,FALSE) -> #N/A | E11: =IF(B11="Excluded",0,(IF(ISNA(VLOOKUP(A11,FY2008_09,10,FALSE)),0,(VLOOKUP(A11,FY2008_09,10,FALSE))))) -> 0 | F11: =IF(B11="Excluded",0,(IF(ISNA(VLOOKUP(A11,FY2009_10,10,FALSE)),0,(VLOOKUP(A11,FY2009_10,10,FALSE))))) -> 0 | G11: =IF(B11="Excluded",0,(IF(ISNA(VLOOKUP(A11,FY2010_11,10,FALSE)),0,(VLOOKUP(A11,FY2010_11,10,FALSE))))) -> 0 | H11: =IF(B11="Excluded",0,(IF(ISNA(VLOOKUP(A11,FY2011_12,10,FALSE)),0,(VLOOKUP(A11,FY2011_12,10,FALSE))))) -> 0 | I11: =IF(B11="Excluded",0,(IF(ISNA(VLOOKUP(A11,FY2012_13,10,FALSE)),0,(VLOOKUP(A11,FY2012_13,10,FALSE))))) -> 0 | J11: =IF(B11="Excluded",0,(IF(ISNA(VLOOKUP(A11,FY2008_09P,6,FALSE)),0,(VLOOKUP(A11,FY2008_09P,6,FALSE))))) -> 0 | K11: =IF(B11="Excluded",0,(IF(ISNA(VLOOKUP(A11,FY2009_10P,6,FALSE)),0,(VLOOKUP(A11,FY2009_10P,6,FALSE))))) -> 0 | L11: =IF(B11="Excluded",0,(IF(ISNA(VLOOKUP(A11,FY2010_11P,6,FALSE)),0,(VLOOKUP(A11,FY2010_11P,6,FALSE))))) -> 0 | M11: =IF(B11="Excluded",0,(IF(ISNA(VLOOKUP(A11,FY2011_12P,6,FALSE)),0,(VLOOKUP(A11,FY2011_12P,6,FALSE))))) -> 0 | N11: =IF(B11="Excluded",0,(IF(ISNA(VLOOKUP(A11,FY2012_13P,6,FALSE)),0,(VLOOKUP(A11,FY2012_13P,6,FALSE))))) -> 0 | O11: =(AVERAGE(G11:I11)*0.75)+(AVERAGE(L11:N11)*0.25) -> 0 | P11: =(AVERAGE(E11:G11)*0.75)+(AVERAGE(J11:L11)*0.25) -> 0 | R11: =S11-Q11 -> 0 | S11: =ROUND((P11*'Cost Pool'!$C$25),0) -> 0 | U11: =V11-T11 -> 0 | V11: =ROUND((O11*'Cost Pool'!$D$25),0) -> 0 | W11: =V11+R11 -> 0
A12: 100-MF | B12: =VLOOKUP(A12,Crosswalk,2,FALSE) -> 100-MF | C12: =CONCATENATE((LEFT(B12,3))," - ",(VLOOKUP((LEFT(B12,3)),Funds,2,FALSE))) -> 100 - General Fund | D12: =VLOOKUP((RIGHT(B12,2)),Bureaus,2,FALSE) -> Office of Management & Finance | E12: =IF(B12="Excluded",0,(IF(ISNA(VLOOKUP(A12,FY2008_09,10,FALSE)),0,(VLOOKUP(A12,FY2008_09,10,FALSE))))) -> 0.01455677 | F12: =IF(B12="Excluded",0,(IF(ISNA(VLOOKUP(A12,FY2009_10,10,FALSE)),0,(VLOOKUP(A12,FY2009_10,10,FALSE))))) -> 0.0089164785 | G12: =IF(B12="Excluded",0,(IF(ISNA(VLOOKUP(A12,FY2010_11,10,FALSE)),0,(VLOOKUP(A12,FY2010_11,10,FALSE))))) -> 0.0086234507 | H12: =IF(B12="Excluded",0,(IF(ISNA(VLOOKUP(A12,FY2011_12,10,FALSE)),0,(VLOOKUP(A12,FY2011_12,10,FALSE))))) -> 0.0092323106 | I12: =IF(B12="Excluded",0,(IF(ISNA(VLOOKUP(A12,FY2012_13,10,FALSE)),0,(VLOOKUP(A12,FY2012_13,10,FALSE))))) -> 0.011412877 | J12: =IF(B12="Excluded",0,(IF(ISNA(VLOOKUP(A12,FY2008_09P,6,FALSE)),0,(VLOOKUP(A12,FY2008_09P,6,FALSE))))) -> 0.0085404716 | K12: =IF(B12="Excluded",0,(IF(ISNA(VLOOKUP(A12,FY2009_10P,6,FALSE)),0,(VLOOKUP(A12,FY2009_10P,6,FALSE))))) -> 0.0085658346 | L12: =IF(B12="Excluded",0,(IF(ISNA(VLOOKUP(A12,FY2010_11P,6,FALSE)),0,(VLOOKUP(A12,FY2010_11P,6,FALSE))))) -> 0.0085432502 | M12: =IF(B12="Excluded",0,(IF(ISNA(VLOOKUP(A12,FY2011_12P,6,FALSE)),0,(VLOOKUP(A12,FY2011_12P,6,FALSE))))) -> 0.0088802384 | N12: =IF(B12="Excluded",0,(IF(ISNA(VLOOKUP(A12,FY2012_13P,6,FALSE)),0,(VLOOKUP(A12,FY2012_13P,6,FALSE))))) -> 0.01004165 | O12: =(AVERAGE(G12:I12)*0.75)+(AVERAGE(L12:N12)*0.25) -> 0.0096059211 | P12: =(AVERAGE(E12:G12)*0.75)+(AVERAGE(J12:L12)*0.25) -> 0.010161638 | Q12: 771800 | R12: =S12-Q12 -> -359765 | S12: =ROUND((P12*'Cost Pool'!$C$25),0) -> 412035 | T12: =40689+408676+24350+21778+869452+164251+86020+133 -> 1615349 | U12: =V12-T12 -> -1174629 | V12: =ROUND((O12*'Cost Pool'!$D$25),0) -> 440720 | W12: =V12+R12 -> 80955
A13: 100-MY | B13: =VLOOKUP(A13,Crosswalk,2,FALSE) -> 100-MY | C13: =CONCATENATE((LEFT(B13,3))," - ",(VLOOKUP((LEFT(B13,3)),Funds,2,FALSE))) -> 100 - General Fund | D13: =VLOOKUP((RIGHT(B13,2)),Bureaus,2,FALSE) -> Office of the Mayor | E13: =IF(B13="Excluded",0,(IF(ISNA(VLOOKUP(A13,FY2008_09,10,FALSE)),0,(VLOOKUP(A13,FY2008_09,10,FALSE))))) -> 6.5888669e-05 | F13: =IF(B13="Excluded",0,(IF(ISNA(VLOOKUP(A13,FY2009_10,10,FALSE)),0,(VLOOKUP(A13,FY2009_10,10,FALSE))))) -> 1.3793117e-05 | G13: =IF(B13="Excluded",0,(IF(ISNA(VLOOKUP(A13,FY2010_11,10,FALSE)),0,(VLOOKUP(A13,FY2010_11,10,FALSE))))) -> 0.00071522188 | H13: =IF(B13="Excluded",0,(IF(ISNA(VLOOKUP(A13,FY2011_12,10,FALSE)),0,(VLOOKUP(A13,FY2011_12,10,FALSE))))) -> 0.001335013 | I13: =IF(B13="Excluded",0,(IF(ISNA(VLOOKUP(A13,FY2012_13,10,FALSE)),0,(VLOOKUP(A13,FY2012_13,10,FALSE))))) -> 0.0016048761 | J13: =IF(B13="Excluded",0,(IF(ISNA(VLOOKUP(A13,FY2008_09P,6,FALSE)),0,(VLOOKUP(A13,FY2008_09P,6,FALSE))))) -> 0.00025493945 | K13: =IF(B13="Excluded",0,(IF(ISNA(VLOOKUP(A13,FY2009_10P,6,FALSE)),0,(VLOOKUP(A13,FY2009_10P,6,FALSE))))) -> 0.00024473813 | L13: =IF(B13="Excluded",0,(IF(ISNA(VLOOKUP(A13,FY2010_11P,6,FALSE)),0,(VLOOKUP(A13,FY2010_11P,6,FALSE))))) -> 0.00025127206 | M13: =IF(B13="Excluded",0,(IF(ISNA(VLOOKUP(A13,FY2011_12P,6,FALSE)),0,(VLOOKUP(A13,FY2011_12P,6,FALSE))))) -> 0.0002432942 | N13: =IF(B13="Excluded",0,(IF(ISNA(VLOOKUP(A13,FY2012_13P,6,FALSE)),0,(VLOOKUP(A13,FY2012_13P,6,FALSE))))) -> 0.00011410966 | O13: =(AVERAGE(G13:I13)*0.75)+(AVERAGE(L13:N13)*0.25) -> 0.00096450075 | P13: =(AVERAGE(E13:G13)*0.75)+(AVERAGE(J13:L13)*0.25) -> 0.00026130505 | R13: =S13-Q13 -> 10595 | S13: =ROUND((P13*'Cost Pool'!$C$25),0) -> 10595 | U13: =V13-T13 -> 44251 | V13: =ROUND((O13*'Cost Pool'!$D$25),0) -> 44251 | W13: =V13+R13 -> 54846
A14: 100-NI | B14: =VLOOKUP(A14,Crosswalk,2,FALSE) -> 100-NI | C14: =CONCATENATE((LEFT(B14,3))," - ",(VLOOKUP((LEFT(B14,3)),Funds,2,FALSE))) -> 100 - General Fund | D14: =VLOOKUP((RIGHT(B14,2)),Bureaus,2,FALSE) -> Office of Neighborhood Involvement | E14: =IF(B14="Excluded",0,(IF(ISNA(VLOOKUP(A14,FY2008_09,10,FALSE)),0,(VLOOKUP(A14,FY2008_09,10,FALSE))))) -> 0.006025896 | F14: =IF(B14="Excluded",0,(IF(ISNA(VLOOKUP(A14,FY2009_10,10,FALSE)),0,(VLOOKUP(A14,FY2009_10,10,FALSE))))) -> 0.0073010783 | G14: =IF(B14="Excluded",0,(IF(ISNA(VLOOKUP(A14,FY2010_11,10,FALSE)),0,(VLOOKUP(A14,FY2010_11,10,FALSE))))) -> 0.0066956638 | H14: =IF(B14="Excluded",0,(IF(ISNA(VLOOKUP(A14,FY2011_12,10,FALSE)),0,(VLOOKUP(A14,FY2011_12,10,FALSE))))) -> 0.006416703 | I14: =IF(B14="Excluded",0,(IF(ISNA(VLOOKUP(A14,FY2012_13,10,FALSE)),0,(VLOOKUP(A14,FY2012_13,10,FALSE))))) -> 0.0062092428 | J14: =IF(B14="Excluded",0,(IF(ISNA(VLOOKUP(A14,FY2008_09P,6,FALSE)),0,(VLOOKUP(A14,FY2008_09P,6,FALSE))))) -> 0.0059910771 | K14: =IF(B14="Excluded",0,(IF(ISNA(VLOOKUP(A14,FY2009_10P,6,FALSE)),0,(VLOOKUP(A14,FY2009_10P,6,FALSE))))) -> 0.0052618698 | L14: =IF(B14="Excluded",0,(IF(ISNA(VLOOKUP(A14,FY2010_11P,6,FALSE)),0,(VLOOKUP(A14,FY2010_11P,6,FALSE))))) -> 0.0056536215 | M14: =IF(B14="Excluded",0,(IF(ISNA(VLOOKUP(A14,FY2011_12P,6,FALSE)),0,(VLOOKUP(A14,FY2011_12P,6,FALSE))))) -> 0.0051091783 | N14: =IF(B14="Excluded",0,(IF(ISNA(VLOOKUP(A14,FY2012_13P,6,FALSE)),0,(VLOOKUP(A14,FY2012_13P,6,FALSE))))) -> 0.0051349347 | O14: =(AVERAGE(G14:I14)*0.75)+(AVERAGE(L14:N14)*0.25) -> 0.0061552136 | P14: =(AVERAGE(E14:G14)*0.75)+(AVERAGE(J14:L14)*0.25) -> 0.0064145402 | Q14: 255373 | R14: =S14-Q14 -> 4724 | S14: =ROUND((P14*'Cost Pool'!$C$25),0) -> 260097 | T14: 307900 | U14: =V14-T14 -> -25498 | V14: =ROUND((O14*'Cost Pool'!$D$25),0) -> 282402 | W14: =V14+R14 -> 287126
A15: 100-OE | B15: =VLOOKUP(A15,Crosswalk,2,FALSE) -> 100-OE | C15: =CONCATENATE((LEFT(B15,3))," - ",(VLOOKUP((LEFT(B15,3)),Funds,2,FALSE))) -> 100 - General Fund | D15: =VLOOKUP((RIGHT(B15,2)),Bureaus,2,FALSE) -> Office of Equity & Human Rights | E15: =IF(B15="Excluded",0,(IF(ISNA(VLOOKUP(A15,FY2008_09,10,FALSE)),0,(VLOOKUP(A15,FY2008_09,10,FALSE))))) -> 0 | F15: =IF(B15="Excluded",0,(IF(ISNA(VLOOKUP(A15,FY2009_10,10,FALSE)),0,(VLOOKUP(A15,FY2009_10,10,FALSE))))) -> 0.00012879132 | G15: =IF(B15="Excluded",0,(IF(ISNA(VLOOKUP(A15,FY2010_11,10,FALSE)),0,(VLOOKUP(A15,FY2010_11,10,FALSE))))) -> 0.00012795821 | H15: =IF(B15="Excluded",0,(IF(ISNA(VLOOKUP(A15,FY2011_12,10,FALSE)),0,(VLOOKUP(A15,FY2011_12,10,FALSE))))) -> 0.00013486394 | I15: =IF(B15="Excluded",0,(IF(ISNA(VLOOKUP(A15,FY2012_13,10,FALSE)),0,(VLOOKUP(A15,FY2012_13,10,FALSE))))) -> 0.00034857036 | J15: =IF(B15="Excluded",0,(IF(ISNA(VLOOKUP(A15,FY2008_09P,6,FALSE)),0,(VLOOKUP(A15,FY2008_09P,6,FALSE))))) -> 0 | K15: =IF(B15="Excluded",0,(IF(ISNA(VLOOKUP(A15,FY2009_10P,6,FALSE)),0,(VLOOKUP(A15,FY2009_10P,6,FALSE))))) -> 0.00073421439 | L15: =IF(B15="Excluded",0,(IF(ISNA(VLOOKUP(A15,FY2010_11P,6,FALSE)),0,(VLOOKUP(A15,FY2010_11P,6,FALSE))))) -> 0.00075381619 | M15: =IF(B15="Excluded",0,(IF(ISNA(VLOOKUP(A15,FY2011_12P,6,FALSE)),0,(VLOOKUP(A15,FY2011_12P,6,FALSE))))) -> 0.00072988261 | N15: =IF(B15="Excluded",0,(IF(ISNA(VLOOKUP(A15,FY2012_13P,6,FALSE)),0,(VLOOKUP(A15,FY2012_13P,6,FALSE))))) -> 0.0010269869 | O15: =(AVERAGE(G15:I15)*0.75)+(AVERAGE(L15:N15)*0.25) -> 0.00036207194 | P15: =(AVERAGE(E15:G15)*0.75)+(AVERAGE(J15:L15)*0.25) -> 0.00018818993 | R15: =S15-Q15 -> 7631 | S15: =ROUND((P15*'Cost Pool'!$C$25),0) -> 7631 | T15: 5027 | U15: =V15-T15 -> 11585 | V15: =ROUND((O15*'Cost Pool'!$D$25),0) -> 16612 | W15: =V15+R15 -> 24243
A16: 100-PA | B16: =VLOOKUP(A16,Crosswalk,2,FALSE) -> 100-PA | C16: =CONCATENATE((LEFT(B16,3))," - ",(VLOOKUP((LEFT(B16,3)),Funds,2,FALSE))) -> 100 - General Fund | D16: =VLOOKUP((RIGHT(B16,2)),Bureaus,2,FALSE) -> Commissioner of Public Affairs | E16: =IF(B16="Excluded",0,(IF(ISNA(VLOOKUP(A16,FY2008_09,10,FALSE)),0,(VLOOKUP(A16,FY2008_09,10,FALSE))))) -> 0.00014060118 | F16: =IF(B16="Excluded",0,(IF(ISNA(VLOOKUP(A16,FY2009_10,10,FALSE)),0,(VLOOKUP(A16,FY2009_10,10,FALSE))))) -> 0.00054905953 | G16: =IF(B16="Excluded",0,(IF(ISNA(VLOOKUP(A16,FY2010_11,10,FALSE)),0,(VLOOKUP(A16,FY2010_11,10,FALSE))))) -> 0.00054550792 | H16: =IF(B16="Excluded",0,(IF(ISNA(VLOOKUP(A16,FY2011_12,10,FALSE)),0,(VLOOKUP(A16,FY2011_12,10,FALSE))))) -> 0.0005678438 | I16: =IF(B16="Excluded",0,(IF(ISNA(VLOOKUP(A16,FY2012_13,10,FALSE)),0,(VLOOKUP(A16,FY2012_13,10,FALSE))))) -> 0.00051316152 | J16: =IF(B16="Excluded",0,(IF(ISNA(VLOOKUP(A16,FY2008_09P,6,FALSE)),0,(VLOOKUP(A16,FY2008_09P,6,FALSE))))) -> 0.00025493945 | K16: =IF(B16="Excluded",0,(IF(ISNA(VLOOKUP(A16,FY2009_10P,6,FALSE)),0,(VLOOKUP(A16,FY2009_10P,6,FALSE))))) -> 0.00012236907 | L16: =IF(B16="Excluded",0,(IF(ISNA(VLOOKUP(A16,FY2010_11P,6,FALSE)),0,(VLOOKUP(A16,FY2010_11P,6,FALSE))))) -> 0.00025127206 | M16: =IF(B16="Excluded",0,(IF(ISNA(VLOOKUP(A16,FY2011_12P,6,FALSE)),0,(VLOOKUP(A16,FY2011_12P,6,FALSE))))) -> 0.0002432942 | N16: =IF(B16="Excluded",0,(IF(ISNA(VLOOKUP(A16,FY2012_13P,6,FALSE)),0,(VLOOKUP(A16,FY2012_13P,6,FALSE))))) -> 0.00022821932 | O16: =(AVERAGE(G16:I16)*0.75)+(AVERAGE(L16:N16)*0.25) -> 0.00046686044 | P16: =(AVERAGE(E16:G16)*0.75)+(AVERAGE(J16:L16)*0.25) -> 0.00036117387 | R16: =S16-Q16 -> 14645 | S16: =ROUND((P16*'Cost Pool'!$C$25),0) -> 14645 | U16: =V16-T16 -> 21420 | V16: =ROUND((O16*'Cost Pool'!$D$25),0) -> 21420 | W16: =V16+R16 -> 36065
A17: 100-PK | B17: =VLOOKUP(A17,Crosswalk,2,FALSE) -> 100-PK | C17: =CONCATENATE((LEFT(B17,3))," - ",(VLOOKUP((LEFT(B17,3)),Funds,2,FALSE))) -> 100 - General Fund | D17: =VLOOKUP((RIGHT(B17,2)),Bureaus,2,FALSE) -> Portland Parks & Recreation | E17: =IF(B17="Excluded",0,(IF(ISNA(VLOOKUP(A17,FY2008_09,10,FALSE)),0,(VLOOKUP(A17,FY2008_09,10,FALSE))))) -> 0.056437483 | F17: =IF(B17="Excluded",0,(IF(ISNA(VLOOKUP(A17,FY2009_10,10,FALSE)),0,(VLOOKUP(A17,FY2009_10,10,FALSE))))) -> 0.055888742 | G17: =IF(B17="Excluded",0,(IF(ISNA(VLOOKUP(A17,FY2010_11,10,FALSE)),0,(VLOOKUP(A17,FY2010_11,10,FALSE))))) -> 0.055903952 | H17: =IF(B17="Excluded",0,(IF(ISNA(VLOOKUP(A17,FY2011_12,10,FALSE)),0,(VLOOKUP(A17,FY2011_12,10,FALSE))))) -> 0.061110813 | I17: =IF(B17="Excluded",0,(IF(ISNA(VLOOKUP(A17,FY2012_13,10,FALSE)),0,(VLOOKUP(A17,FY2012_13,10,FALSE))))) -> 0.057201607 | J17: =IF(B17="Excluded",0,(IF(ISNA(VLOOKUP(A17,FY2008_09P,6,FALSE)),0,(VLOOKUP(A17,FY2008_09P,6,FALSE))))) -> 0.29713193 | K17: =IF(B17="Excluded",0,(IF(ISNA(VLOOKUP(A17,FY2009_10P,6,FALSE)),0,(VLOOKUP(A17,FY2009_10P,6,FALSE))))) -> 0.33810573 | L17: =IF(B17="Excluded",0,(IF(ISNA(VLOOKUP(A17,FY2010_11P,6,FALSE)),0,(VLOOKUP(A17,FY2010_11P,6,FALSE))))) -> 0.34059928 | M17: =IF(B17="Excluded",0,(IF(ISNA(VLOOKUP(A17,FY2011_12P,6,FALSE)),0,(VLOOKUP(A17,FY2011_12P,6,FALSE))))) -> 0.36141354 | N17: =IF(B17="Excluded",0,(IF(ISNA(VLOOKUP(A17,FY2012_13P,6,FALSE)),0,(VLOOKUP(A17,FY2012_13P,6,FALSE))))) -> 0.41444628 | O17: =(AVERAGE(G17:I17)*0.75)+(AVERAGE(L17:N17)*0.25) -> 0.13659235 | P17: =(AVERAGE(E17:G17)*0.75)+(AVERAGE(J17:L17)*0.25) -> 0.12337729 | Q17: 3463800 | R17: =S17-Q17 -> 1538912 | S17: =ROUND((P17*'Cost Pool'!$C$25),0) -> 5002712 | T17: 4009808 | U17: =V17-T17 -> 2257061 | V17: =ROUND((O17*'Cost Pool'!$D$25),0) -> 6266869 | W17: =V17+R17 -> 7805781
A18: 100-PL | B18: =VLOOKUP(A18,Crosswalk,2,FALSE) -> 100-PL | C18: =CONCATENATE((LEFT(B18,3))," - ",(VLOOKUP((LEFT(B18,3)),Funds,2,FALSE))) -> 100 - General Fund | D18: =VLOOKUP((RIGHT(B18,2)),Bureaus,2,FALSE) -> Portland Police Bureau | E18: =IF(B18="Excluded",0,(IF(ISNA(VLOOKUP(A18,FY2008_09,10,FALSE)),0,(VLOOKUP(A18,FY2008_09,10,FALSE))))) -> 0.14605162 | F18: =IF(B18="Excluded",0,(IF(ISNA(VLOOKUP(A18,FY2009_10,10,FALSE)),0,(VLOOKUP(A18,FY2009_10,10,FALSE))))) -> 0.14926776 | G18: =IF(B18="Excluded",0,(IF(ISNA(VLOOKUP(A18,FY2010_11,10,FALSE)),0,(VLOOKUP(A18,FY2010_11,10,FALSE))))) -> 0.13726817 | H18: =IF(B18="Excluded",0,(IF(ISNA(VLOOKUP(A18,FY2011_12,10,FALSE)),0,(VLOOKUP(A18,FY2011_12,10,FALSE))))) -> 0.1574626 | I18: =IF(B18="Excluded",0,(IF(ISNA(VLOOKUP(A18,FY2012_13,10,FALSE)),0,(VLOOKUP(A18,FY2012_13,10,FALSE))))) -> 0.14672147 | J18: =IF(B18="Excluded",0,(IF(ISNA(VLOOKUP(A18,FY2008_09P,6,FALSE)),0,(VLOOKUP(A18,FY2008_09P,6,FALSE))))) -> 0.17195666 | K18: =IF(B18="Excluded",0,(IF(ISNA(VLOOKUP(A18,FY2009_10P,6,FALSE)),0,(VLOOKUP(A18,FY2009_10P,6,FALSE))))) -> 0.15993637 | L18: =IF(B18="Excluded",0,(IF(ISNA(VLOOKUP(A18,FY2010_11P,6,FALSE)),0,(VLOOKUP(A18,FY2010_11P,6,FALSE))))) -> 0.15754758 | M18: =IF(B18="Excluded",0,(IF(ISNA(VLOOKUP(A18,FY2011_12P,6,FALSE)),0,(VLOOKUP(A18,FY2011_12P,6,FALSE))))) -> 0.15157229 | N18: =IF(B18="Excluded",0,(IF(ISNA(VLOOKUP(A18,FY2012_13P,6,FALSE)),0,(VLOOKUP(A18,FY2012_13P,6,FALSE))))) -> 0.13978433 | O18: =(AVERAGE(G18:I18)*0.75)+(AVERAGE(L18:N18)*0.25) -> 0.14777174 | P18: =(AVERAGE(E18:G18)*0.75)+(AVERAGE(J18:L18)*0.25) -> 0.14893361 | Q18: 7796139 | R18: =S18-Q18 -> -1757168 | S18: =ROUND((P18*'Cost Pool'!$C$25),0) -> 6038971 | T18: 7405955 | U18: =V18-T18 -> -626175 | V18: =ROUND((O18*'Cost Pool'!$D$25),0) -> 6779780 | W18: =V18+R18 -> 5022612
A19: 100-PN | B19: =VLOOKUP(A19,Crosswalk,2,FALSE) -> 100-PN | C19: =CONCATENATE((LEFT(B19,3))," - ",(VLOOKUP((LEFT(B19,3)),Funds,2,FALSE))) -> 100 - General Fund | D19: =VLOOKUP((RIGHT(B19,2)),Bureaus,2,FALSE) -> Bureau of Planning & Sustainability | E19: =IF(B19="Excluded",0,(IF(ISNA(VLOOKUP(A19,FY2008_09,10,FALSE)),0,(VLOOKUP(A19,FY2008_09,10,FALSE))))) -> 0.0089831277 | F19: =IF(B19="Excluded",0,(IF(ISNA(VLOOKUP(A19,FY2009_10,10,FALSE)),0,(VLOOKUP(A19,FY2009_10,10,FALSE))))) -> 0.010856299 | G19: =IF(B19="Excluded",0,(IF(ISNA(VLOOKUP(A19,FY2010_11,10,FALSE)),0,(VLOOKUP(A19,FY2010_11,10,FALSE))))) -> 0.0075519462 | H19: =IF(B19="Excluded",0,(IF(ISNA(VLOOKUP(A19,FY2011_12,10,FALSE)),0,(VLOOKUP(A19,FY2011_12,10,FALSE))))) -> 0.00809581 | I19: =IF(B19="Excluded",0,(IF(ISNA(VLOOKUP(A19,FY2012_13,10,FALSE)),0,(VLOOKUP(A19,FY2012_13,10,FALSE))))) -> 0.0072462535 | J19: =IF(B19="Excluded",0,(IF(ISNA(VLOOKUP(A19,FY2008_09P,6,FALSE)),0,(VLOOKUP(A19,FY2008_09P,6,FALSE))))) -> 0.010452518 | K19: =IF(B19="Excluded",0,(IF(ISNA(VLOOKUP(A19,FY2009_10P,6,FALSE)),0,(VLOOKUP(A19,FY2009_10P,6,FALSE))))) -> 0.012236907 | L19: =IF(B19="Excluded",0,(IF(ISNA(VLOOKUP(A19,FY2010_11P,6,FALSE)),0,(VLOOKUP(A19,FY2010_11P,6,FALSE))))) -> 0.010993153 | M19: =IF(B19="Excluded",0,(IF(ISNA(VLOOKUP(A19,FY2011_12P,6,FALSE)),0,(VLOOKUP(A19,FY2011_12P,6,FALSE))))) -> 0.011252357 | N19: =IF(B19="Excluded",0,(IF(ISNA(VLOOKUP(A19,FY2012_13P,6,FALSE)),0,(VLOOKUP(A19,FY2012_13P,6,FALSE))))) -> 0.0087293889 | O19: =(AVERAGE(G19:I19)*0.75)+(AVERAGE(L19:N19)*0.25) -> 0.008304744 | P19: =(AVERAGE(E19:G19)*0.75)+(AVERAGE(J19:L19)*0.25) -> 0.0096547247 | Q19: 722401 | R19: =S19-Q19 -> -330920 | S19: =ROUND((P19*'Cost Pool'!$C$25),0) -> 391481 | T19: 794342 | U19: =V19-T19 -> -413320 | V19: =ROUND((O19*'Cost Pool'!$D$25),0) -> 381022 | W19: =V19+R19 -> 50102
A20: 100-PS | B20: =VLOOKUP(A20,Crosswalk,2,FALSE) -> 100-PS | C20: =CONCATENATE((LEFT(B20,3))," - ",(VLOOKUP((LEFT(B20,3)),Funds,2,FALSE))) -> 100 - General Fund | D20: =VLOOKUP((RIGHT(B20,2)),Bureaus,2,FALSE) -> Commissioner of Public Safety | E20: =IF(B20="Excluded",0,(IF(ISNA(VLOOKUP(A20,FY2008_09,10,FALSE)),0,(VLOOKUP(A20,FY2008_09,10,FALSE))))) -> 0 | F20: =IF(B20="Excluded",0,(IF(ISNA(VLOOKUP(A20,FY2009_10,10,FALSE)),0,(VLOOKUP(A20,FY2009_10,10,FALSE))))) -> 0 | G20: =IF(B20="Excluded",0,(IF(ISNA(VLOOKUP(A20,FY2010_11,10,FALSE)),0,(VLOOKUP(A20,FY2010_11,10,FALSE))))) -> 0 | H20: =IF(B20="Excluded",0,(IF(ISNA(VLOOKUP(A20,FY2011_12,10,FALSE)),0,(VLOOKUP(A20,FY2011_12,10,FALSE))))) -> 0 | I20: =IF(B20="Excluded",0,(IF(ISNA(VLOOKUP(A20,FY2012_13,10,FALSE)),0,(VLOOKUP(A20,FY2012_13,10,FALSE))))) -> 0 | J20: =IF(B20="Excluded",0,(IF(ISNA(VLOOKUP(A20,FY2008_09P,6,FALSE)),0,(VLOOKUP(A20,FY2008_09P,6,FALSE))))) -> 0 | K20: =IF(B20="Excluded",0,(IF(ISNA(VLOOKUP(A20,FY2009_10P,6,FALSE)),0,(VLOOKUP(A20,FY2009_10P,6,FALSE))))) -> 0 | L20: =IF(B20="Excluded",0,(IF(ISNA(VLOOKUP(A20,FY2010_11P,6,FALSE)),0,(VLOOKUP(A20,FY2010_11P,6,FALSE))))) -> 0 | M20: =IF(B20="Excluded",0,(IF(ISNA(VLOOKUP(A20,FY2011_12P,6,FALSE)),0,(VLOOKUP(A20,FY2011_12P,6,FALSE))))) -> 0 | N20: =IF(B20="Excluded",0,(IF(ISNA(VLOOKUP(A20,FY2012_13P,6,FALSE)),0,(VLOOKUP(A20,FY2012_13P,6,FALSE))))) -> 0 | O20: =(AVERAGE(G20:I20)*0.75)+(AVERAGE(L20:N20)*0.25) -> 0 | P20: =(AVERAGE(E20:G20)*0.75)+(AVERAGE(J20:L20)*0.25) -> 0 | R20: =S20-Q20 -> 0 | S20: =ROUND((P20*'Cost Pool'!$C$25),0) -> 0 | U20: =V20-T20 -> 0 | V20: =ROUND((O20*'Cost Pool'!$D$25),0) -> 0 | W20: =V20+R20 -> 0
A21: 100-PU | B21: =VLOOKUP(A21,Crosswalk,2,FALSE) -> 100-PU | C21: =CONCATENATE((LEFT(B21,3))," - ",(VLOOKUP((LEFT(B21,3)),Funds,2,FALSE))) -> 100 - General Fund | D21: =VLOOKUP((RIGHT(B21,2)),Bureaus,2,FALSE) -> Commissioner of Public Utilities | E21: =IF(B21="Excluded",0,(IF(ISNA(VLOOKUP(A21,FY2008_09,10,FALSE)),0,(VLOOKUP(A21,FY2008_09,10,FALSE))))) -> 0 | F21: =IF(B21="Excluded",0,(IF(ISNA(VLOOKUP(A21,FY2009_10,10,FALSE)),0,(VLOOKUP(A21,FY2009_10,10,FALSE))))) -> 0 | G21: =IF(B21="Excluded",0,(IF(ISNA(VLOOKUP(A21,FY2010_11,10,FALSE)),0,(VLOOKUP(A21,FY2010_11,10,FALSE))))) -> 0 | H21: =IF(B21="Excluded",0,(IF(ISNA(VLOOKUP(A21,FY2011_12,10,FALSE)),0,(VLOOKUP(A21,FY2011_12,10,FALSE))))) -> 0 | I21: =IF(B21="Excluded",0,(IF(ISNA(VLOOKUP(A21,FY2012_13,10,FALSE)),0,(VLOOKUP(A21,FY2012_13,10,FALSE))))) -> 0 | J21: =IF(B21="Excluded",0,(IF(ISNA(VLOOKUP(A21,FY2008_09P,6,FALSE)),0,(VLOOKUP(A21,FY2008_09P,6,FALSE))))) -> 0 | K21: =IF(B21="Excluded",0,(IF(ISNA(VLOOKUP(A21,FY2009_10P,6,FALSE)),0,(VLOOKUP(A21,FY2009_10P,6,FALSE))))) -> 0 | L21: =IF(B21="Excluded",0,(IF(ISNA(VLOOKUP(A21,FY2010_11P,6,FALSE)),0,(VLOOKUP(A21,FY2010_11P,6,FALSE))))) -> 0 | M21: =IF(B21="Excluded",0,(IF(ISNA(VLOOKUP(A21,FY2011_12P,6,FALSE)),0,(VLOOKUP(A21,FY2011_12P,6,FALSE))))) -> 0 | N21: =IF(B21="Excluded",0,(IF(ISNA(VLOOKUP(A21,FY2012_13P,6,FALSE)),0,(VLOOKUP(A21,FY2012_13P,6,FALSE))))) -> 0 | O21: =(AVERAGE(G21:I21)*0.75)+(AVERAGE(L21:N21)*0.25) -> 0 | P21: =(AVERAGE(E21:G21)*0.75)+(AVERAGE(J21:L21)*0.25) -> 0 | R21: =S21-Q21 -> 0 | S21: =ROUND((P21*'Cost Pool'!$C$25),0) -> 0 | U21: =V21-T21 -> 0 | V21: =ROUND((O21*'Cost Pool'!$D$25),0) -> 0 | W21: =V21+R21 -> 0
A22: 100-PW | B22: =VLOOKUP(A22,Crosswalk,2,FALSE) -> 100-PW | C22: =CONCATENATE((LEFT(B22,3))," - ",(VLOOKUP((LEFT(B22,3)),Funds,2,FALSE))) -> 100 - General Fund | D22: =VLOOKUP((RIGHT(B22,2)),Bureaus,2,FALSE) -> Commissioner of Public Works | E22: =IF(B22="Excluded",0,(IF(ISNA(VLOOKUP(A22,FY2008_09,10,FALSE)),0,(VLOOKUP(A22,FY2008_09,10,FALSE))))) -> 0 | F22: =IF(B22="Excluded",0,(IF(ISNA(VLOOKUP(A22,FY2009_10,10,FALSE)),0,(VLOOKUP(A22,FY2009_10,10,FALSE))))) -> 0 | G22: =IF(B22="Excluded",0,(IF(ISNA(VLOOKUP(A22,FY2010_11,10,FALSE)),0,(VLOOKUP(A22,FY2010_11,10,FALSE))))) -> 0 | H22: =IF(B22="Excluded",0,(IF(ISNA(VLOOKUP(A22,FY2011_12,10,FALSE)),0,(VLOOKUP(A22,FY2011_12,10,FALSE))))) -> 0 | I22: =IF(B22="Excluded",0,(IF(ISNA(VLOOKUP(A22,FY2012_13,10,FALSE)),0,(VLOOKUP(A22,FY2012_13,10,FALSE))))) -> 0 | J22: =IF(B22="Excluded",0,(IF(ISNA(VLOOKUP(A22,FY2008_09P,6,FALSE)),0,(VLOOKUP(A22,FY2008_09P,6,FALSE))))) -> 0 | K22: =IF(B22="Excluded",0,(IF(ISNA(VLOOKUP(A22,FY2009_10P,6,FALSE)),0,(VLOOKUP(A22,FY2009_10P,6,FALSE))))) -> 0 | L22: =IF(B22="Excluded",0,(IF(ISNA(VLOOKUP(A22,FY2010_11P,6,FALSE)),0,(VLOOKUP(A22,FY2010_11P,6,FALSE))))) -> 0 | M22: =IF(B22="Excluded",0,(IF(ISNA(VLOOKUP(A22,FY2011_12P,6,FALSE)),0,(VLOOKUP(A22,FY2011_12P,6,FALSE))))) -> 0 | N22: =IF(B22="Excluded",0,(IF(ISNA(VLOOKUP(A22,FY2012_13P,6,FALSE)),0,(VLOOKUP(A22,FY2012_13P,6,FALSE))))) -> 0 | O22: =(AVERAGE(G22:I22)*0.75)+(AVERAGE(L22:N22)*0.25) -> 0 | P22: =(AVERAGE(E22:G22)*0.75)+(AVERAGE(J22:L22)*0.25) -> 0 | R22: =S22-Q22 -> 0 | S22: =ROUND((P22*'Cost Pool'!$C$25),0) -> 0 | U22: =V22-T22 -> 0 | V22: =ROUND((O22*'Cost Pool'!$D$25),0) -> 0 | W22: =V22+R22 -> 0
A23: 100-SA | B23: =VLOOKUP(A23,Crosswalk,2,FALSE) -> 100-SA | C23: =CONCATENATE((LEFT(B23,3))," - ",(VLOOKUP((LEFT(B23,3)),Funds,2,FALSE))) -> 100 - General Fund | D23: =VLOOKUP((RIGHT(B23,2)),Bureaus,2,FALSE) -> Special Appropriations | E23: =IF(B23="Excluded",0,(IF(ISNA(VLOOKUP(A23,FY2008_09,10,FALSE)),0,(VLOOKUP(A23,FY2008_09,10,FALSE))))) -> 0.013632242 | F23: =IF(B23="Excluded",0,(IF(ISNA(VLOOKUP(A23,FY2009_10,10,FALSE)),0,(VLOOKUP(A23,FY2009_10,10,FALSE))))) -> 0.0079987576 | G23: =IF(B23="Excluded",0,(IF(ISNA(VLOOKUP(A23,FY2010_11,10,FALSE)),0,(VLOOKUP(A23,FY2010_11,10,FALSE))))) -> 0.0068913073 | H23: =IF(B23="Excluded",0,(IF(ISNA(VLOOKUP(A23,FY2011_12,10,FALSE)),0,(VLOOKUP(A23,FY2011_12,10,FALSE))))) -> 0.009156456 | I23: =IF(B23="Excluded",0,(IF(ISNA(VLOOKUP(A23,FY2012_13,10,FALSE)),0,(VLOOKUP(A23,FY2012_13,10,FALSE))))) -> 0.014089506 | J23: =IF(B23="Excluded",0,(IF(ISNA(VLOOKUP(A23,FY2008_09P,6,FALSE)),0,(VLOOKUP(A23,FY2008_09P,6,FALSE))))) -> 0 | K23: =IF(B23="Excluded",0,(IF(ISNA(VLOOKUP(A23,FY2009_10P,6,FALSE)),0,(VLOOKUP(A23,FY2009_10P,6,FALSE))))) -> 0 | L23: =IF(B23="Excluded",0,(IF(ISNA(VLOOKUP(A23,FY2010_11P,6,FALSE)),0,(VLOOKUP(A23,FY2010_11P,6,FALSE))))) -> 0 | M23: =IF(B23="Excluded",0,(IF(ISNA(VLOOKUP(A23,FY2011_12P,6,FALSE)),0,(VLOOKUP(A23,FY2011_12P,6,FALSE))))) -> 0 | N23: =IF(B23="Excluded",0,(IF(ISNA(VLOOKUP(A23,FY2012_13P,6,FALSE)),0,(VLOOKUP(A23,FY2012_13P,6,FALSE))))) -> 0 | O23: =(AVERAGE(G23:I23)*0.75)+(AVERAGE(L23:N23)*0.25) -> 0.0075343173 | P23: =(AVERAGE(E23:G23)*0.75)+(AVERAGE(J23:L23)*0.25) -> 0.0071305767 | R23: =S23-Q23 -> 289131 | S23: =ROUND((P23*'Cost Pool'!$C$25),0) -> 289131 | T23: 269857 | U23: =V23-T23 -> 75818 | V23: =ROUND((O23*'Cost Pool'!$D$25),0) -> 345675 | W23: =V23+R23 -> 634806
A24: 100-SD | B24: =VLOOKUP(A24,Crosswalk,2,FALSE) -> 100-PN | C24: =CONCATENATE((LEFT(B24,3))," - ",(VLOOKUP((LEFT(B24,3)),Funds,2,FALSE))) -> 100 - General Fund | D24: =VLOOKUP((RIGHT(B24,2)),Bureaus,2,FALSE) -> Bureau of Planning & Sustainability | E24: =IF(B24="Excluded",0,(IF(ISNA(VLOOKUP(A24,FY2008_09,10,FALSE)),0,(VLOOKUP(A24,FY2008_09,10,FALSE))))) -> 0.0030128132 | F24: =IF(B24="Excluded",0,(IF(ISNA(VLOOKUP(A24,FY2009_10,10,FALSE)),0,(VLOOKUP(A24,FY2009_10,10,FALSE))))) -> 0 | G24: =IF(B24="Excluded",0,(IF(ISNA(VLOOKUP(A24,FY2010_11,10,FALSE)),0,(VLOOKUP(A24,FY2010_11,10,FALSE))))) -> 0 | H24: =IF(B24="Excluded",0,(IF(ISNA(VLOOKUP(A24,FY2011_12,10,FALSE)),0,(VLOOKUP(A24,FY2011_12,10,FALSE))))) -> 0 | I24: =IF(B24="Excluded",0,(IF(ISNA(VLOOKUP(A24,FY2012_13,10,FALSE)),0,(VLOOKUP(A24,FY2012_13,10,FALSE))))) -> 0 | J24: =IF(B24="Excluded",0,(IF(ISNA(VLOOKUP(A24,FY2008_09P,6,FALSE)),0,(VLOOKUP(A24,FY2008_09P,6,FALSE))))) -> 0.0035691523 | K24: =IF(B24="Excluded",0,(IF(ISNA(VLOOKUP(A24,FY2009_10P,6,FALSE)),0,(VLOOKUP(A24,FY2009_10P,6,FALSE))))) -> 0 | L24: =IF(B24="Excluded",0,(IF(ISNA(VLOOKUP(A24,FY2010_11P,6,FALSE)),0,(VLOOKUP(A24,FY2010_11P,6,FALSE))))) -> 0 | M24: =IF(B24="Excluded",0,(IF(ISNA(VLOOKUP(A24,FY2011_12P,6,FALSE)),0,(VLOOKUP(A24,FY2011_12P,6,FALSE))))) -> 0 | N24: =IF(B24="Excluded",0,(IF(ISNA(VLOOKUP(A24,FY2012_13P,6,FALSE)),0,(VLOOKUP(A24,FY2012_13P,6,FALSE))))) -> 0 | O24: =(AVERAGE(G24:I24)*0.75)+(AVERAGE(L24:N24)*0.25) -> 0 | P24: =(AVERAGE(E24:G24)*0.75)+(AVERAGE(J24:L24)*0.25) -> 0.0010506327 | R24: =S24-Q24 -> 42601 | S24: =ROUND((P24*'Cost Pool'!$C$25),0) -> 42601 | U24: =V24-T24 -> 0 | V24: =ROUND((O24*'Cost Pool'!$D$25),0) -> 0 | W24: =V24+R24 -> 42601
A25: 100-ZD | B25: =VLOOKUP(A25,Crosswalk,2,FALSE) -> PDC | C25: =CONCATENATE((LEFT(B25,3))," - ",(VLOOKUP((LEFT(B25,3)),Funds,2,FALSE))) -> PDC - Portland Development Commission | D25: =VLOOKUP((RIGHT(B25,2)),Bureaus,2,FALSE) -> #N/A | E25: =IF(B25="Excluded",0,(IF(ISNA(VLOOKUP(A25,FY2008_09,10,FALSE)),0,(VLOOKUP(A25,FY2008_09,10,FALSE))))) -> 0 | F25: =IF(B25="Excluded",0,(IF(ISNA(VLOOKUP(A25,FY2009_10,10,FALSE)),0,(VLOOKUP(A25,FY2009_10,10,FALSE))))) -> 0.0069937688 | G25: =IF(B25="Excluded",0,(IF(ISNA(VLOOKUP(A25,FY2010_11,10,FALSE)),0,(VLOOKUP(A25,FY2010_11,10,FALSE))))) -> 0.0041964137 | H25: =IF(B25="Excluded",0,(IF(ISNA(VLOOKUP(A25,FY2011_12,10,FALSE)),0,(VLOOKUP(A25,FY2011_12,10,FALSE))))) -> 0.0053166192 | I25: =IF(B25="Excluded",0,(IF(ISNA(VLOOKUP(A25,FY2012_13,10,FALSE)),0,(VLOOKUP(A25,FY2012_13,10,FALSE))))) -> 0.0064587168 | J25: =IF(B25="Excluded",0,(IF(ISNA(VLOOKUP(A25,FY2008_09P,6,FALSE)),0,(VLOOKUP(A25,FY2008_09P,6,FALSE))))) -> 0 | K25: =IF(B25="Excluded",0,(IF(ISNA(VLOOKUP(A25,FY2009_10P,6,FALSE)),0,(VLOOKUP(A25,FY2009_10P,6,FALSE))))) -> 0 | L25: =IF(B25="Excluded",0,(IF(ISNA(VLOOKUP(A25,FY2010_11P,6,FALSE)),0,(VLOOKUP(A25,FY2010_11P,6,FALSE))))) -> 0 | M25: =IF(B25="Excluded",0,(IF(ISNA(VLOOKUP(A25,FY2011_12P,6,FALSE)),0,(VLOOKUP(A25,FY2011_12P,6,FALSE))))) -> 0 | N25: =IF(B25="Excluded",0,(IF(ISNA(VLOOKUP(A25,FY2012_13P,6,FALSE)),0,(VLOOKUP(A25,FY2012_13P,6,FALSE))))) -> 0 | O25: =(AVERAGE(G25:I25)*0.75)+(AVERAGE(L25:N25)*0.25) -> 0.0039929374 | P25: =(AVERAGE(E25:G25)*0.75)+(AVERAGE(J25:L25)*0.25) -> 0.0027975456 | Q25: 126913 | R25: =S25-Q25 -> -13478 | S25: =ROUND((P25*'Cost Pool'!$C$25),0) -> 113435 | T25: 146823 | U25: =V25-T25 -> 36373 | V25: =ROUND((O25*'Cost Pool'!$D$25),0) -> 183196 | W25: =V25+R25 -> 169718
A26: 200-TR | B26: =VLOOKUP(A26,Crosswalk,2,FALSE) -> 200 | C26: =CONCATENATE((LEFT(B26,3))," - ",(VLOOKUP((LEFT(B26,3)),Funds,2,FALSE))) -> 200 - Transportation Operating Fund | D26: =VLOOKUP((RIGHT(B26,2)),Bureaus,2,FALSE) -> #N/A | E26: =IF(B26="Excluded",0,(IF(ISNA(VLOOKUP(A26,FY2008_09,10,FALSE)),0,(VLOOKUP(A26,FY2008_09,10,FALSE))))) -> 0.10596635 | F26: =IF(B26="Excluded",0,(IF(ISNA(VLOOKUP(A26,FY2009_10,10,FALSE)),0,(VLOOKUP(A26,FY2009_10,10,FALSE))))) -> 0.11291081 | G26: =IF(B26="Excluded",0,(IF(ISNA(VLOOKUP(A26,FY2010_11,10,FALSE)),0,(VLOOKUP(A26,FY2010_11,10,FALSE))))) -> 0.11137921 | H26: =IF(B26="Excluded",0,(IF(ISNA(VLOOKUP(A26,FY2011_12,10,FALSE)),0,(VLOOKUP(A26,FY2011_12,10,FALSE))))) -> 0.10835876 | I26: =IF(B26="Excluded",0,(IF(ISNA(VLOOKUP(A26,FY2012_13,10,FALSE)),0,(VLOOKUP(A26,FY2012_13,10,FALSE))))) -> 0.12633395 | J26: =IF(B26="Excluded",0,(IF(ISNA(VLOOKUP(A26,FY2008_09P,6,FALSE)),0,(VLOOKUP(A26,FY2008_09P,6,FALSE))))) -> 0.10184831 | K26: =IF(B26="Excluded",0,(IF(ISNA(VLOOKUP(A26,FY2009_10P,6,FALSE)),0,(VLOOKUP(A26,FY2009_10P,6,FALSE))))) -> 0.093734704 | L26: =IF(B26="Excluded",0,(IF(ISNA(VLOOKUP(A26,FY2010_11P,6,FALSE)),0,(VLOOKUP(A26,FY2010_11P,6,FALSE))))) -> 0.097116653 | M26: =IF(B26="Excluded",0,(IF(ISNA(VLOOKUP(A26,FY2011_12P,6,FALSE)),0,(VLOOKUP(A26,FY2011_12P,6,FALSE))))) -> 0.094884739 | N26: =IF(B26="Excluded",0,(IF(ISNA(VLOOKUP(A26,FY2012_13P,6,FALSE)),0,(VLOOKUP(A26,FY2012_13P,6,FALSE))))) -> 0.086038683 | O26: =(AVERAGE(G26:I26)*0.75)+(AVERAGE(L26:N26)*0.25) -> 0.10968799 | P26: =(AVERAGE(E26:G26)*0.75)+(AVERAGE(J26:L26)*0.25) -> 0.10695573 | Q26: 5760647 | R26: =S26-Q26 -> -1423798 | S26: =ROUND((P26*'Cost Pool'!$C$25),0) -> 4336849 | T26: 6564665 | U26: =V26-T26 -> -1532171 | V26: =ROUND((O26*'Cost Pool'!$D$25),0) -> 5032494 | W26: =V26+R26 -> 3608696
A27: 201-AU | B27: =VLOOKUP(A27,Crosswalk,2,FALSE) -> 201 | C27: =CONCATENATE((LEFT(B27,3))," - ",(VLOOKUP((LEFT(B27,3)),Funds,2,FALSE))) -> 201 - Assessment Collection Fund | D27: =VLOOKUP((RIGHT(B27,2)),Bureaus,2,FALSE) -> #N/A | E27: =IF(B27="Excluded",0,(IF(ISNA(VLOOKUP(A27,FY2008_09,10,FALSE)),0,(VLOOKUP(A27,FY2008_09,10,FALSE))))) -> 0 | F27: =IF(B27="Excluded",0,(IF(ISNA(VLOOKUP(A27,FY2009_10,10,FALSE)),0,(VLOOKUP(A27,FY2009_10,10,FALSE))))) -> 0 | G27: =IF(B27="Excluded",0,(IF(ISNA(VLOOKUP(A27,FY2010_11,10,FALSE)),0,(VLOOKUP(A27,FY2010_11,10,FALSE))))) -> 0 | H27: =IF(B27="Excluded",0,(IF(ISNA(VLOOKUP(A27,FY2011_12,10,FALSE)),0,(VLOOKUP(A27,FY2011_12,10,FALSE))))) -> 0 | I27: =IF(B27="Excluded",0,(IF(ISNA(VLOOKUP(A27,FY2012_13,10,FALSE)),0,(VLOOKUP(A27,FY2012_13,10,FALSE))))) -> 0 | J27: =IF(B27="Excluded",0,(IF(ISNA(VLOOKUP(A27,FY2008_09P,6,FALSE)),0,(VLOOKUP(A27,FY2008_09P,6,FALSE))))) -> 0 | K27: =IF(B27="Excluded",0,(IF(ISNA(VLOOKUP(A27,FY2009_10P,6,FALSE)),0,(VLOOKUP(A27,FY2009_10P,6,FALSE))))) -> 0 | L27: =IF(B27="Excluded",0,(IF(ISNA(VLOOKUP(A27,FY2010_11P,6,FALSE)),0,(VLOOKUP(A27,FY2010_11P,6,FALSE))))) -> 0 | M27: =IF(B27="Excluded",0,(IF(ISNA(VLOOKUP(A27,FY2011_12P,6,FALSE)),0,(VLOOKUP(A27,FY2011_12P,6,FALSE))))) -> 0 | N27: =IF(B27="Excluded",0,(IF(ISNA(VLOOKUP(A27,FY2012_13P,6,FALSE)),0,(VLOOKUP(A27,FY2012_13P,6,FALSE))))) -> 0 | O27: =(AVERAGE(G27:I27)*0.75)+(AVERAGE(L27:N27)*0.25) -> 0 | P27: =(AVERAGE(E27:G27)*0.75)+(AVERAGE(J27:L27)*0.25) -> 0 | Q27: 14 | R27: =S27-Q27 -> -14 | S27: =ROUND((P27*'Cost Pool'!$C$25),0) -> 0 | T27: 12 | U27: =V27-T27 -> -12 | V27: =ROUND((O27*'Cost Pool'!$D$25),0) -> 0 | W27: =V27+R27 -> -14
A28: 202-EC | B28: =VLOOKUP(A28,Crosswalk,2,FALSE) -> 202 | C28: =CONCATENATE((LEFT(B28,3))," - ",(VLOOKUP((LEFT(B28,3)),Funds,2,FALSE))) -> 202 - Emergency Communication Fund | D28: =VLOOKUP((RIGHT(B28,2)),Bureaus,2,FALSE) -> #N/A | E28: =IF(B28="Excluded",0,(IF(ISNA(VLOOKUP(A28,FY2008_09,10,FALSE)),0,(VLOOKUP(A28,FY2008_09,10,FALSE))))) -> 0.015096047 | F28: =IF(B28="Excluded",0,(IF(ISNA(VLOOKUP(A28,FY2009_10,10,FALSE)),0,(VLOOKUP(A28,FY2009_10,10,FALSE))))) -> 0.015061403 | G28: =IF(B28="Excluded",0,(IF(ISNA(VLOOKUP(A28,FY2010_11,10,FALSE)),0,(VLOOKUP(A28,FY2010_11,10,FALSE))))) -> 0.014385446 | H28: =IF(B28="Excluded",0,(IF(ISNA(VLOOKUP(A28,FY2011_12,10,FALSE)),0,(VLOOKUP(A28,FY2011_12,10,FALSE))))) -> 0.015384301 | I28: =IF(B28="Excluded",0,(IF(ISNA(VLOOKUP(A28,FY2012_13,10,FALSE)),0,(VLOOKUP(A28,FY2012_13,10,FALSE))))) -> 0.014987205 | J28: =IF(B28="Excluded",0,(IF(ISNA(VLOOKUP(A28,FY2008_09P,6,FALSE)),0,(VLOOKUP(A28,FY2008_09P,6,FALSE))))) -> 0.019120459 | K28: =IF(B28="Excluded",0,(IF(ISNA(VLOOKUP(A28,FY2009_10P,6,FALSE)),0,(VLOOKUP(A28,FY2009_10P,6,FALSE))))) -> 0.018844836 | L28: =IF(B28="Excluded",0,(IF(ISNA(VLOOKUP(A28,FY2010_11P,6,FALSE)),0,(VLOOKUP(A28,FY2010_11P,6,FALSE))))) -> 0.018971041 | M28: =IF(B28="Excluded",0,(IF(ISNA(VLOOKUP(A28,FY2011_12P,6,FALSE)),0,(VLOOKUP(A28,FY2011_12P,6,FALSE))))) -> 0.017760477 | N28: =IF(B28="Excluded",0,(IF(ISNA(VLOOKUP(A28,FY2012_13P,6,FALSE)),0,(VLOOKUP(A28,FY2012_13P,6,FALSE))))) -> 0.016317681 | O28: =(AVERAGE(G28:I28)*0.75)+(AVERAGE(L28:N28)*0.25) -> 0.015610005 | P28: =(AVERAGE(E28:G28)*0.75)+(AVERAGE(J28:L28)*0.25) -> 0.015880419 | Q28: 785607 | R28: =S28-Q28 -> -141687 | S28: =ROUND((P28*'Cost Pool'!$C$25),0) -> 643920 | T28: 877412 | U28: =V28-T28 -> -161224 | V28: =ROUND((O28*'Cost Pool'!$D$25),0) -> 716188 | W28: =V28+R28 -> 574501
A29: 202-MF | B29: =VLOOKUP(A29,Crosswalk,2,FALSE) -> 202 | C29: =CONCATENATE((LEFT(B29,3))," - ",(VLOOKUP((LEFT(B29,3)),Funds,2,FALSE))) -> 202 - Emergency Communication Fund | D29: =VLOOKUP((RIGHT(B29,2)),Bureaus,2,FALSE) -> #N/A | E29: =IF(B29="Excluded",0,(IF(ISNA(VLOOKUP(A29,FY2008_09,10,FALSE)),0,(VLOOKUP(A29,FY2008_09,10,FALSE))))) -> 0.00013500757 | F29: =IF(B29="Excluded",0,(IF(ISNA(VLOOKUP(A29,FY2009_10,10,FALSE)),0,(VLOOKUP(A29,FY2009_10,10,FALSE))))) -> 0.0020342999 | G29: =IF(B29="Excluded",0,(IF(ISNA(VLOOKUP(A29,FY2010_11,10,FALSE)),0,(VLOOKUP(A29,FY2010_11,10,FALSE))))) -> 0.0025591922 | H29: =IF(B29="Excluded",0,(IF(ISNA(VLOOKUP(A29,FY2011_12,10,FALSE)),0,(VLOOKUP(A29,FY2011_12,10,FALSE))))) -> 0.00017401543 | I29: =IF(B29="Excluded",0,(IF(ISNA(VLOOKUP(A29,FY2012_13,10,FALSE)),0,(VLOOKUP(A29,FY2012_13,10,FALSE))))) -> 1.0510384e-05 | J29: =IF(B29="Excluded",0,(IF(ISNA(VLOOKUP(A29,FY2008_09P,6,FALSE)),0,(VLOOKUP(A29,FY2008_09P,6,FALSE))))) -> 0 | K29: =IF(B29="Excluded",0,(IF(ISNA(VLOOKUP(A29,FY2009_10P,6,FALSE)),0,(VLOOKUP(A29,FY2009_10P,6,FALSE))))) -> 0 | L29: =IF(B29="Excluded",0,(IF(ISNA(VLOOKUP(A29,FY2010_11P,6,FALSE)),0,(VLOOKUP(A29,FY2010_11P,6,FALSE))))) -> 0 | M29: =IF(B29="Excluded",0,(IF(ISNA(VLOOKUP(A29,FY2011_12P,6,FALSE)),0,(VLOOKUP(A29,FY2011_12P,6,FALSE))))) -> 0 | N29: =IF(B29="Excluded",0,(IF(ISNA(VLOOKUP(A29,FY2012_13P,6,FALSE)),0,(VLOOKUP(A29,FY2012_13P,6,FALSE))))) -> 0 | O29: =(AVERAGE(G29:I29)*0.75)+(AVERAGE(L29:N29)*0.25) -> 0.0006859295 | P29: =(AVERAGE(E29:G29)*0.75)+(AVERAGE(J29:L29)*0.25) -> 0.0011821249 | R29: =S29-Q29 -> 47933 | S29: =ROUND((P29*'Cost Pool'!$C$25),0) -> 47933 | U29: =V29-T29 -> 31471 | V29: =ROUND((O29*'Cost Pool'!$D$25),0) -> 31471 | W29: =V29+R29 -> 79404
A30: 203-DS | B30: =VLOOKUP(A30,Crosswalk,2,FALSE) -> 203 | C30: =CONCATENATE((LEFT(B30,3))," - ",(VLOOKUP((LEFT(B30,3)),Funds,2,FALSE))) -> 203 - Development Services Fund | D30: =VLOOKUP((RIGHT(B30,2)),Bureaus,2,FALSE) -> #N/A | E30: =IF(B30="Excluded",0,(IF(ISNA(VLOOKUP(A30,FY2008_09,10,FALSE)),0,(VLOOKUP(A30,FY2008_09,10,FALSE))))) -> 0.036798226 | F30: =IF(B30="Excluded",0,(IF(ISNA(VLOOKUP(A30,FY2009_10,10,FALSE)),0,(VLOOKUP(A30,FY2009_10,10,FALSE))))) -> 0.022244936 | G30: =IF(B30="Excluded",0,(IF(ISNA(VLOOKUP(A30,FY2010_11,10,FALSE)),0,(VLOOKUP(A30,FY2010_11,10,FALSE))))) -> 0.017730271 | H30: =IF(B30="Excluded",0,(IF(ISNA(VLOOKUP(A30,FY2011_12,10,FALSE)),0,(VLOOKUP(A30,FY2011_12,10,FALSE))))) -> 0.021407969 | I30: =IF(B30="Excluded",0,(IF(ISNA(VLOOKUP(A30,FY2012_13,10,FALSE)),0,(VLOOKUP(A30,FY2012_13,10,FALSE))))) -> 0.023347979 | J30: =IF(B30="Excluded",0,(IF(ISNA(VLOOKUP(A30,FY2008_09P,6,FALSE)),0,(VLOOKUP(A30,FY2008_09P,6,FALSE))))) -> 0.047418738 | K30: =IF(B30="Excluded",0,(IF(ISNA(VLOOKUP(A30,FY2009_10P,6,FALSE)),0,(VLOOKUP(A30,FY2009_10P,6,FALSE))))) -> 0.038056779 | L30: =IF(B30="Excluded",0,(IF(ISNA(VLOOKUP(A30,FY2010_11P,6,FALSE)),0,(VLOOKUP(A30,FY2010_11P,6,FALSE))))) -> 0.021358126 | M30: =IF(B30="Excluded",0,(IF(ISNA(VLOOKUP(A30,FY2011_12P,6,FALSE)),0,(VLOOKUP(A30,FY2011_12P,6,FALSE))))) -> 0.022748008 | N30: =IF(B30="Excluded",0,(IF(ISNA(VLOOKUP(A30,FY2012_13P,6,FALSE)),0,(VLOOKUP(A30,FY2012_13P,6,FALSE))))) -> 0.024419467 | O30: =(AVERAGE(G30:I30)*0.75)+(AVERAGE(L30:N30)*0.25) -> 0.021332021 | P30: =(AVERAGE(E30:G30)*0.75)+(AVERAGE(J30:L30)*0.25) -> 0.028096162 | Q30: 1092926 | R30: =S30-Q30 -> 46319 | S30: =ROUND((P30*'Cost Pool'!$C$25),0) -> 1139245 | T30: 1044982 | U30: =V30-T30 -> -66267 | V30: =ROUND((O30*'Cost Pool'!$D$25),0) -> 978715 | W30: =V30+R30 -> 1025034
A31: 204-MF | B31: =VLOOKUP(A31,Crosswalk,2,FALSE) -> 204 | C31: =CONCATENATE((LEFT(B31,3))," - ",(VLOOKUP((LEFT(B31,3)),Funds,2,FALSE))) -> 204 - Property Management License Fund | D31: =VLOOKUP((RIGHT(B31,2)),Bureaus,2,FALSE) -> #N/A | E31: =IF(B31="Excluded",0,(IF(ISNA(VLOOKUP(A31,FY2008_09,10,FALSE)),0,(VLOOKUP(A31,FY2008_09,10,FALSE))))) -> 0 | F31: =IF(B31="Excluded",0,(IF(ISNA(VLOOKUP(A31,FY2009_10,10,FALSE)),0,(VLOOKUP(A31,FY2009_10,10,FALSE))))) -> 0 | G31: =IF(B31="Excluded",0,(IF(ISNA(VLOOKUP(A31,FY2010_11,10,FALSE)),0,(VLOOKUP(A31,FY2010_11,10,FALSE))))) -> 0 | H31: =IF(B31="Excluded",0,(IF(ISNA(VLOOKUP(A31,FY2011_12,10,FALSE)),0,(VLOOKUP(A31,FY2011_12,10,FALSE))))) -> 0 | I31: =IF(B31="Excluded",0,(IF(ISNA(VLOOKUP(A31,FY2012_13,10,FALSE)),0,(VLOOKUP(A31,FY2012_13,10,FALSE))))) -> 0 | J31: =IF(B31="Excluded",0,(IF(ISNA(VLOOKUP(A31,FY2008_09P,6,FALSE)),0,(VLOOKUP(A31,FY2008_09P,6,FALSE))))) -> 0 | K31: =IF(B31="Excluded",0,(IF(ISNA(VLOOKUP(A31,FY2009_10P,6,FALSE)),0,(VLOOKUP(A31,FY2009_10P,6,FALSE))))) -> 0 | L31: =IF(B31="Excluded",0,(IF(ISNA(VLOOKUP(A31,FY2010_11P,6,FALSE)),0,(VLOOKUP(A31,FY2010_11P,6,FALSE))))) -> 0 | M31: =IF(B31="Excluded",0,(IF(ISNA(VLOOKUP(A31,FY2011_12P,6,FALSE)),0,(VLOOKUP(A31,FY2011_12P,6,FALSE))))) -> 0 | N31: =IF(B31="Excluded",0,(IF(ISNA(VLOOKUP(A31,FY2012_13P,6,FALSE)),0,(VLOOKUP(A31,FY2012_13P,6,FALSE))))) -> 0 | O31: =(AVERAGE(G31:I31)*0.75)+(AVERAGE(L31:N31)*0.25) -> 0 | P31: =(AVERAGE(E31:G31)*0.75)+(AVERAGE(J31:L31)*0.25) -> 0 | R31: =S31-Q31 -> 0 | S31: =ROUND((P31*'Cost Pool'!$C$25),0) -> 0 | T31: 0 | U31: =V31-T31 -> 25000 | V31: 25000 | W31: 25000
A32: 206-CB | B32: =VLOOKUP(A32,Crosswalk,2,FALSE) -> 206-MF | C32: =CONCATENATE((LEFT(B32,3))," - ",(VLOOKUP((LEFT(B32,3)),Funds,2,FALSE))) -> 206 - MHCRC Agency Fund | D32: =VLOOKUP((RIGHT(B32,2)),Bureaus,2,FALSE) -> Office of Management & Finance | E32: =IF(B32="Excluded",0,(IF(ISNA(VLOOKUP(A32,FY2008_09,10,FALSE)),0,(VLOOKUP(A32,FY2008_09,10,FALSE))))) -> 0 | F32: =IF(B32="Excluded",0,(IF(ISNA(VLOOKUP(A32,FY2009_10,10,FALSE)),0,(VLOOKUP(A32,FY2009_10,10,FALSE))))) -> 0 | G32: =IF(B32="Excluded",0,(IF(ISNA(VLOOKUP(A32,FY2010_11,10,FALSE)),0,(VLOOKUP(A32,FY2010_11,10,FALSE))))) -> 0 | H32: =IF(B32="Excluded",0,(IF(ISNA(VLOOKUP(A32,FY2011_12,10,FALSE)),0,(VLOOKUP(A32,FY2011_12,10,FALSE))))) -> 0 | I32: =IF(B32="Excluded",0,(IF(ISNA(VLOOKUP(A32,FY2012_13,10,FALSE)),0,(VLOOKUP(A32,FY2012_13,10,FALSE))))) -> 0 | J32: =IF(B32="Excluded",0,(IF(ISNA(VLOOKUP(A32,FY2008_09P,6,FALSE)),0,(VLOOKUP(A32,FY2008_09P,6,FALSE))))) -> 0 | K32: =IF(B32="Excluded",0,(IF(ISNA(VLOOKUP(A32,FY2009_10P,6,FALSE)),0,(VLOOKUP(A32,FY2009_10P,6,FALSE))))) -> 0 | L32: =IF(B32="Excluded",0,(IF(ISNA(VLOOKUP(A32,FY2010_11P,6,FALSE)),0,(VLOOKUP(A32,FY2010_11P,6,FALSE))))) -> 0 | M32: =IF(B32="Excluded",0,(IF(ISNA(VLOOKUP(A32,FY2011_12P,6,FALSE)),0,(VLOOKUP(A32,FY2011_12P,6,FALSE))))) -> 0 | N32: =IF(B32="Excluded",0,(IF(ISNA(VLOOKUP(A32,FY2012_13P,6,FALSE)),0,(VLOOKUP(A32,FY2012_13P,6,FALSE))))) -> 0 | O32: =(AVERAGE(G32:I32)*0.75)+(AVERAGE(L32:N32)*0.25) -> 0 | P32: =(AVERAGE(E32:G32)*0.75)+(AVERAGE(J32:L32)*0.25) -> 0 | Q32: 0 | R32: =S32-Q32 -> 0 | S32: =ROUND((P32*'Cost Pool'!$C$25),0) -> 0 | T32: 0 | U32: =V32-T32 -> 25000 | V32: 25000 | W32: 25000
