Workbook

Sheet Elementary
B1: Elementary
C2: Alcohol | D2: Tobacco | E2: Other Drugs | F2: Distribution | G2: Assaults | H2: Arson | I2: Handgun | J2: Rifle | K2: Other Firearm | L2: Other Weapon | M2: Totals
B3: District
B4: Alpine | C4: - | D4: - | E4: 3 | F4: - | G4: 6 | H4: - | I4: - | J4: - | K4: - | L4: 3 | M4: =SUM(C4:L4) -> 12
B5: Beaver | C5: - | D5: - | E5: - | F5: - | G5: - | H5: - | I5: - | J5: - | K5: - | L5: - | M5: =SUM(C5:L5) -> 0
B6: Box Elder | C6: - | D6: - | E6: - | F6: - | G6: 7 | H6: - | I6: - | J6: - | K6: - | L6: 1 | M6: =SUM(C6:L6) -> 8
B7: Cache | C7: - | D7: - | E7: - | F7: - | G7: 40 | H7: - | I7: 1 | J7: - | K7: - | L7: - | M7: =SUM(C7:L7) -> 41
B8: Canyons | C8: - | D8: 2 | E8: 12 | F8: - | G8: 44 | H8: 2 | I8: - | J8: - | K8: 3 | L8: 39 | M8: =SUM(C8:L8) -> 102
B9: Carbon | C9: - | D9: - | E9: 1 | F9: - | G9: - | H9: - | I9: - | J9: - | K9: - | L9: - | M9: =SUM(C9:L9) -> 1
B10: Daggett | C10: - | D10: - | E10: - | F10: - | G10: - | H10: - | I10: - | J10: - | K10: - | L10: - | M10: =SUM(C10:L10) -> 0
B11: Davis | C11: 2 | D11: 2 | E11: 2 | F11: - | G11: 259 | H11: - | I11: 1 | J11: - | K11: - | L11: 65 | M11: =SUM(C11:L11) -> 331
B12: Duchesne | C12: - | D12: - | E12: - | F12: - | G12: 7 | H12: - | I12: - | J12: - | K12: - | L12: - | M12: =SUM(C12:L12) -> 7
B13: Emery | C13: - | D13: - | E13: - | F13: - | G13: - | H13: - | I13: - | J13: - | K13: - | L13: - | M13: =SUM(C13:L13) -> 0
B14: Garfield | C14: - | D14: - | E14: - | F14: - | G14: 2 | H14: - | I14: - | J14: - | K14: - | L14: - | M14: =SUM(C14:L14) -> 2
B15: Grand | C15: - | D15: - | E15: - | F15: - | G15: 1 | H15: - | I15: - | J15: - | K15: - | L15: 5 | M15: =SUM(C15:L15) -> 6
B16: Granite | C16: - | D16: 5 | E16: 18 | F16: 6 | G16: 121 | H16: - | I16: - | J16: - | K16: - | L16: 31 | M16: =SUM(C16:L16) -> 181
B17: Iron | C17: - | D17: - | E17: - | F17: - | G17: - | H17: - | I17: - | J17: - | K17: - | L17: - | M17: =SUM(C17:L17) -> 0
B18: Jordan | C18: - | D18: - | E18: - | F18: - | G18: 159 | H18: 1 | I18: 1 | J18: - | K18: - | L18: 33 | M18: =SUM(C18:L18) -> 194
B19: Juab | C19: - | D19: - | E19: - | F19: - | G19: - | H19: - | I19: - | J19: - | K19: - | L19: - | M19: =SUM(C19:L19) -> 0
B20: Kane | C20: - | D20: - | E20: - | F20: - | G20: 1 | H20: - | I20: - | J20: - | K20: - | L20: - | M20: =SUM(C20:L20) -> 1
B21: Logan | C21: - | D21: - | E21: - | F21: - | G21: 4 | H21: - | I21: - | J21: - | K21: - | L21: 1 | M21: =SUM(C21:L21) -> 5
B22: Millard | C22: - | D22: - | E22: - | F22: - | G22: 6 | H22: - | I22: - | J22: - | K22: - | L22: - | M22: =SUM(C22:L22) -> 6
B23: Morgan | C23: - | D23: - | E23: - | F23: - | G23: - | H23: - | I23: - | J23: - | K23: - | L23: - | M23: =SUM(C23:L23) -> 0
B24: Murray | C24: - | D24: - | E24: 1 | F24: - | G24: 1 | H24: - | I24: - | J24: - | K24: - | L24: 1 | M24: =SUM(C24:L24) -> 3
B25: Nebo | C25: - | D25: - | E25: - | F25: - | G25: 22 | H25: - | I25: - | J25: - | K25: - | L25: 3 | M25: =SUM(C25:L25) -> 25
B26: North Sanpete | C26: - | D26: - | E26: - | F26: - | G26: - | H26: - | I26: - | J26: - | K26: - | L26: - | M26: =SUM(C26:L26) -> 0
B27: North Summit | C27: - | D27: - | E27: - | F27: - | G27: - | H27: - | I27: - | J27: - | K27: - | L27: - | M27: =SUM(C27:L27) -> 0
B28: Ogden | C28: - | D28: - | E28: - | F28: - | G28: 6 | H28: - | I28: - | J28: - | K28: - | L28: 5 | M28: =SUM(C28:L28) -> 11
B29: Park City | C29: - | D29: - | E29: - | F29: - | G29: - | H29: - | I29: - | J29: - | K29: - | L29: 2 | M29: =SUM(C29:L29) -> 2
B30: Piute | C30: - | D30: - | E30: - | F30: - | G30: - | H30: - | I30: - | J30: - | K30: - | L30: - | M30: =SUM(C30:L30) -> 0
B31: Provo | C31: - | D31: - | E31: - | F31: - | G31: 8 | H31: - | I31: - | J31: - | K31: - | L31: 1 | M31: =SUM(C31:L31) -> 9
B32: Rich | C32: - | D32: - | E32: - | F32: - | G32: - | H32: - | I32: - | J32: - | K32: - | L32: - | M32: =SUM(C32:L32) -> 0
B33: Salt Lake | C33: - | D33: 3 | E33: 2 | F33: - | G33: 73 | H33: - | I33: - | J33: 2 | K33: 5 | L33: 33 | M33: =SUM(C33:L33) -> 118
B34: San Juan | C34: - | D34: - | E34: - | F34: - | G34: 2 | H34: - | I34: - | J34: - | K34: - | L34: 1 | M34: =SUM(C34:L34) -> 3
B35: Sevier | C35: - | D35: - | E35: - | F35: - | G35: - | H35: - | I35: - | J35: - | K35: - | L35: - | M35: =SUM(C35:L35) -> 0
B36: South Sanpete | C36: - | D36: - | E36: - | F36: - | G36: - | H36: 2 | I36: - | J36: - | K36: - | L36: - | M36: =SUM(C36:L36) -> 2
B37: South Summit | C37: - | D37: - | E37: - | F37: - | G37: - | H37: - | I37: - | J37: - | K37: - | L37: - | M37: =SUM(C37:L37) -> 0
B38: Tintic | C38: - | D38: - | E38: - | F38: - | G38: - | H38: - | I38: - | J38: - | K38: - | L38: - | M38: =SUM(C38:L38) -> 0
B39: Tooele | C39: - | D39: - | E39: 5 | F39: - | G39: 1 | H39: - | I39: - | J39: - | K39: - | L39: 2 | M39: =SUM(C39:L39) -> 8
B40: Uintah | C40: 1 | D40: - | E40: 2 | F40: - | G40: - | H40: - | I40: - | J40: - | K40: - | L40: 8 | M40: =SUM(C40:L40) -> 11
...

Sheet ElementaryCharter
B1: Elementary
C2: Alcohol | D2: Tobacco | E2: Other Drugs | F2: Distribution | G2: Assaults | H2: Arson | I2: Handgun | J2: Rifle | K2: Other Firearm | L2: Other Weapon | M2: Totals
B3: Charter
B4: AMES | C4: - | D4: - | E4: - | F4: - | G4: - | H4: - | I4: - | J4: - | K4: - | L4: - | M4: =SUM(C4:L4) -> 0
B5: City Academy | C5: - | D5: - | E5: - | F5: - | G5: - | H5: - | I5: - | J5: - | K5: - | L5: - | M5: =SUM(C5:L5) -> 0
B6: Thomas Edison North | C6: 1 | D6: - | E6: - | F6: - | G6: - | H6: - | I6: - | J6: - | K6: - | L6: - | M6: =SUM(C6:L6) -> 1
B7: Karl G. Maeser Preparatory Academy | C7: - | D7: - | E7: - | F7: - | G7: - | H7: - | I7: - | J7: - | K7: - | L7: - | M7: =SUM(C7:L7) -> 0
B8: Legacy Preparatory Academy | C8: - | D8: 1 | E8: - | F8: - | G8: - | H8: - | I8: - | J8: - | K8: - | L8: - | M8: =SUM(C8:L8) -> 1
B9: North Star Academy | C9: 1 | D9: - | E9: - | F9: - | G9: 1 | H9: - | I9: - | J9: - | K9: - | L9: - | M9: =SUM(C9:L9) -> 2
B10: Monticello Academy | C10: 3 | D10: - | E10: 2 | F10: 1 | G10: 23 | H10: - | I10: - | J10: - | K10: - | L10: 4 | M10: =SUM(C10:L10) -> 33
B11: Excelsior Academy | C11: - | D11: - | E11: 1 | F11: - | G11: - | H11: - | I11: - | J11: - | K11: - | L11: - | M11: =SUM(C11:L11) -> 1
B12: East Hollywood High | C12: - | D12: - | E12: - | F12: - | G12: - | H12: - | I12: - | J12: - | K12: - | L12: - | M12: =SUM(C12:L12) -> 0
B13: Spectrum Academy | C13: - | D13: - | E13: - | F13: - | G13: 6 | H13: - | I13: - | J13: - | K13: - | L13: 4 | M13: =SUM(C13:L13) -> 10
B14: Dual Immersion Academy | C14: - | D14: - | E14: - | F14: - | G14: 14 | H14: - | I14: - | J14: - | K14: - | L14: 2 | M14: =SUM(C14:L14) -> 16
B15: Quail Run Primary | C15: - | D15: - | E15: - | F15: - | G15: 3 | H15: - | I15: - | J15: - | K15: - | L15: 1 | M15: =SUM(C15:L15) -> 4
B16: Odyssey Charter School | C16: - | D16: - | E16: - | F16: - | G16: 1 | H16: - | I16: - | J16: - | K16: - | L16: - | M16: =SUM(C16:L16) -> 1
B17: Oquirrh Mountain Charter | C17: - | D17: - | E17: - | F17: - | G17: 1 | H17: - | I17: - | J17: - | K17: - | L17: - | M17: =SUM(C17:L17) -> 1
B18: Lincoln Academy | C18: - | D18: - | E18: - | F18: - | G18: 1 | H18: - | I18: - | J18: - | K18: - | L18: - | M18: =SUM(C18:L18) -> 1
B19: Entheos Academy | C19: - | D19: - | E19: - | F19: - | G19: 1 | H19: - | I19: - | J19: - | K19: - | L19: - | M19: =SUM(C19:L19) -> 1
B20: Maria Montessori | C20: - | D20: - | E20: - | F20: - | G20: 1 | H20: - | I20: - | J20: - | K20: - | L20: - | M20: =SUM(C20:L20) -> 1
B21: American Leadership Academy | C21: - | D21: - | E21: - | F21: - | G21: 18 | H21: - | I21: - | J21: - | K21: - | L21: 4 | M21: =SUM(C21:L21) -> 22
B22: Good Foundations Academy | C22: - | D22: - | E22: - | F22: - | G22: 2 | H22: - | I22: - | J22: - | K22: - | L22: - | M22: =SUM(C22:L22) -> 2
B23: Pinnacle Canyon Academy | C23: - | D23: - | E23: - | F23: - | G23: - | H23: - | I23: - | J23: - | K23: - | L23: 1 | M23: =SUM(C23:L23) -> 1
B24: Quest Academy | C24: - | D24: - | E24: - | F24: - | G24: - | H24: - | I24: - | J24: - | K24: - | L24: 1 | M24: =SUM(C24:L24) -> 1
B25: Syracuse Arts Academy | C25: - | D25: - | E25: - | F25: - | G25: - | H25: - | I25: - | J25: - | K25: - | L25: 1 | M25: =SUM(C25:L25) -> 1
B26: Charter School Total | C26: =SUM(C4:C25) -> 5 | D26: =SUM(D4:D25) -> 1 | E26: =SUM(E4:E25) -> 3 | F26: =SUM(F4:F25) -> 1 | G26: =SUM(G4:G25) -> 72 | H26: =SUM(H4:H25) -> 0 | I26: =SUM(I4:I25) -> 0 | J26: =SUM(J4:J25) -> 0 | ... M26: =SUM(M4:M25) -> 100
B27: Grand Total | C27: =SUM(C26,Elementary!C45) -> 8 | D27: =SUM(D26,Elementary!D45) -> 14 | E27: =SUM(E26,Elementary!E45) -> 50 | F27: =SUM(F26,Elementary!F45) -> 7 | G27: =SUM(G26,Elementary!G45) -> 957 | H27: =SUM(H26,Elementary!H45) -> 5 | I27: =SUM(I26,Elementary!I45) -> 4 | J27: =SUM(J26,Elementary!J45) -> 2 | ... L27: =SUM(L26,Elementary!L45) -> 278 | M27: 1333

Sheet Middle_Jr
B1: Middle
C2: Alcohol | D2: Tobacco | E2: Other Drugs | F2: Distribution | G2: Assaults | H2: Arson | I2: Handgun | J2: Rifle | K2: Other Firearm | L2: Other Weapon | M2: Totals
B3: District
B4: Alpine | C4: - | D4: 16 | E4: 59 | F4: 11 | G4: 25 | H4: 2 | I4: - | J4: - | K4: - | L4: 30 | M4: =SUM(C4:L4) -> 143
B5: Beaver | C5: - | D5: - | E5: - | F5: - | G5: - | H5: - | I5: - | J5: - | K5: - | L5: - | M5: =SUM(C5:L5) -> 0
B6: Box Elder | C6: 4 | D6: 2 | E6: 12 | F6: - | G6: 6 | H6: - | I6: - | J6: - | K6: 3 | L6: 4 | M6: =SUM(C6:L6) -> 31
B7: Cache | C7: - | D7: 8 | E7: 14 | F7: 1 | G7: 25 | H7: - | I7: - | J7: - | K7: - | L7: 6 | M7: =SUM(C7:L7) -> 54
B8: Canyons | C8: 5 | D8: 30 | E8: 50 | F8: 14 | G8: 105 | H8: 4 | I8: - | J8: - | K8: 3 | L8: 32 | M8: =SUM(C8:L8) -> 243
B9: Carbon | C9: - | D9: - | E9: - | F9: - | G9: - | H9: - | I9: - | J9: - | K9: - | L9: - | M9: =SUM(C9:L9) -> 0
B10: Daggett | C10: - | D10: - | E10: - | F10: - | G10: - | H10: - | I10: - | J10: - | K10: - | L10: - | M10: =SUM(C10:L10) -> 0
B11: Davis | C11: 13 | D11: 28 | E11: 94 | F11: - | G11: 127 | H11: - | I11: - | J11: - | K11: 1 | L11: 37 | M11: =SUM(C11:L11) -> 300
B12: Duchesne | C12: 3 | D12: - | E12: 4 | F12: - | G12: 1 | H12: - | I12: - | J12: - | K12: - | L12: - | M12: =SUM(C12:L12) -> 8
B13: Emery | C13: - | D13: - | E13: - | F13: - | G13: - | H13: - | I13: - | J13: - | K13: - | L13: - | M13: =SUM(C13:L13) -> 0
B14: Garfield | C14: - | D14: - | E14: - | F14: - | G14: - | H14: - | I14: - | J14: - | K14: - | L14: - | M14: =SUM(C14:L14) -> 0
B15: Grand | C15: - | D15: - | E15: - | F15: - | G15: - | H15: - | I15: - | J15: - | K15: - | L15: - | M15: =SUM(C15:L15) -> 0
B16: Granite | C16: 16 | D16: 19 | E16: 147 | F16: 17 | G16: 85 | H16: - | I16: 1 | J16: - | K16: - | L16: 45 | M16: =SUM(C16:L16) -> 330
B17: Iron | C17: 2 | D17: 6 | E17: 3 | F17: - | G17: 17 | H17: - | I17: - | J17: - | K17: 1 | L17: 1 | M17: =SUM(C17:L17) -> 30
B18: Jordan | C18: 4 | D18: 4 | E18: 47 | F18: 13 | G18: 41 | H18: 3 | I18: - | J18: - | K18: 1 | L18: 18 | M18: =SUM(C18:L18) -> 131
B19: Juab | C19: - | D19: - | E19: - | F19: - | G19: 2 | H19: - | I19: - | J19: - | K19: - | L19: - | M19: =SUM(C19:L19) -> 2
B20: Kane | C20: - | D20: - | E20: - | F20: - | G20: - | H20: - | I20: - | J20: - | K20: - | L20: - | M20: =SUM(C20:L20) -> 0
B21: Logan | C21: - | D21: 1 | E21: 8 | F21: - | G21: 1 | H21: - | I21: - | J21: - | K21: - | L21: - | M21: =SUM(C21:L21) -> 10
B22: Millard | C22: - | D22: - | E22: - | F22: - | G22: - | H22: - | I22: - | J22: - | K22: - | L22: - | M22: =SUM(C22:L22) -> 0
B23: Morgan | C23: - | D23: - | E23: - | F23: - | G23: 16 | H23: - | I23: - | J23: - | K23: 1 | L23: 2 | M23: =SUM(C23:L23) -> 19
B24: Murray | C24: 1 | D24: 2 | E24: 18 | F24: 1 | G24: 11 | H24: - | I24: - | J24: - | K24: - | L24: 11 | M24: =SUM(C24:L24) -> 44
B25: Nebo | C25: 2 | D25: 13 | E25: 31 | F25: 6 | G25: 21 | H25: - | I25: - | J25: - | K25: 3 | L25: 15 | M25: =SUM(C25:L25) -> 91
B26: North Sanpete | C26: 1 | D26: - | E26: - | F26: 1 | G26: 5 | H26: - | I26: - | J26: - | K26: 1 | L26: 1 | M26: =SUM(C26:L26) -> 9
B27: North Summit | C27: - | D27: - | E27: - | F27: - | G27: - | H27: - | I27: - | J27: - | K27: - | L27: - | M27: =SUM(C27:L27) -> 0
B28: Ogden | C28: 3 | D28: - | E28: 34 | F28: 1 | G28: 4 | H28: - | I28: - | J28: - | K28: 1 | L28: 6 | M28: =SUM(C28:L28) -> 49
B29: Park City | C29: 2 | D29: - | E29: 8 | F29: - | G29: 7 | H29: - | I29: - | J29: - | K29: - | L29: 2 | M29: =SUM(C29:L29) -> 19
B30: Piute | C30: - | D30: - | E30: - | F30: - | G30: - | H30: - | I30: - | J30: - | K30: - | L30: - | M30: =SUM(C30:L30) -> 0
B31: Provo | C31: - | D31: - | E31: 1 | F31: - | G31: 4 | H31: - | I31: - | J31: - | K31: - | L31: 1 | M31: =SUM(C31:L31) -> 6
B32: Rich | C32: - | D32: - | E32: - | F32: - | G32: - | H32: - | I32: - | J32: - | K32: - | L32: 1 | M32: =SUM(C32:L32) -> 1
B33: Salt Lake | C33: 5 | D33: 1 | E33: 16 | F33: 2 | G33: 29 | H33: - | I33: - | J33: 2 | K33: 1 | L33: 8 | M33: =SUM(C33:L33) -> 64
B34: San Juan | C34: - | D34: - | E34: - | F34: - | G34: 3 | H34: - | I34: - | J34: - | K34: - | L34: 3 | M34: =SUM(C34:L34) -> 6
B35: Sevier | C35: - | D35: - | E35: - | F35: - | G35: 5 | H35: 1 | I35: - | J35: - | K35: - | L35: 2 | M35: =SUM(C35:L35) -> 8
B36: South Sanpete | C36: - | D36: - | E36: - | F36: - | G36: - | H36: - | I36: - | J36: - | K36: - | L36: - | M36: =SUM(C36:L36) -> 0
B37: South Summit | C37: - | D37: - | E37: - | F37: - | G37: - | H37: - | I37: - | J37: - | K37: - | L37: - | M37: =SUM(C37:L37) -> 0
B38: Tintic | C38: - | D38: - | E38: - | F38: - | G38: - | H38: - | I38: - | J38: - | K38: - | L38: - | M38: =SUM(C38:L38) -> 0
B39: Tooele | C39: - | D39: 2 | E39: 9 | F39: - | G39: 6 | H39: - | I39: - | J39: - | K39: - | L39: 5 | M39: =SUM(C39:L39) -> 22
B40: Uintah | C40: 5 | D40: - | E40: 17 | F40: 2 | G40: 4 | H40: - | I40: - | J40: - | K40: - | L40: 1 | M40: =SUM(C40:L40) -> 29
...

Sheet MiddleCharter
B1: Middle
C2: Alcohol | D2: Tobacco | E2: Other Drugs | F2: Distribution | G2: Assaults | H2: Arson | I2: Handgun | J2: Rifle | K2: Other Firearm | L2: Other Weapon | M2: Totals
B3: Charter
B4: AMES | M4: =SUM(C4:L4) -> 0
B5: City Academy | M5: =SUM(C5:L5) -> 0
B6: Thomas Edison--North | M6: =SUM(C6:L6) -> 0
B7: Karl G. Maeser Preparatory Academy | M7: =SUM(C7:L7) -> 0
B8: Walden School of Liberal Arts | E8: 1 | G8: 1 | M8: =SUM(C8:L8) -> 2
B9: Early Light Academy at Daybreak | L9: 1 | M9: =SUM(C9:L9) -> 1
B10: Charter School Total: | C10: =SUM(C4:C9) -> 0 | D10: =SUM(D4:D9) -> 0 | E10: =SUM(E4:E9) -> 1 | F10: =SUM(F4:F9) -> 0 | G10: =SUM(G4:G9) -> 1 | I10: =SUM(I4:I9) -> 0 | J10: =SUM(J4:J9) -> 0 | K10: =SUM(K4:K9) -> 0 | L10: =SUM(L4:L9) -> 1 | M10: =SUM(C10:L10) -> 3
B11: Grand Total: | C11: =SUM(C10,Middle_Jr!C45) -> 71 | D11: =SUM(D10,Middle_Jr!D45) -> 146 | E11: =SUM(E10,Middle_Jr!E45) -> 594 | F11: =SUM(F10,Middle_Jr!F45) -> 70 | G11: =SUM(G10,Middle_Jr!G45) -> 573 | H11: =SUM(H10,Middle_Jr!H45) -> 10 | I11: =SUM(I10,Middle_Jr!I45) -> 1 | J11: =SUM(J10,Middle_Jr!J45) -> 2 | ... L11: =SUM(L10,Middle_Jr!L45) -> 250 | M11: 1733

Sheet HS
B1: High
C2: Alcohol | D2: Tobacco | E2: Other Drugs | F2: Distribution | G2: Assaults | H2: Arson | I2: Handgun | J2: Rifle | K2: Other Firearm | L2: Other Weapon | M2: Totals
B3: District
B4: Alpine | C4: 12 | D4: 38 | E4: 49 | F4: 7 | G4: 7 | L4: 9 | M4: =SUM(C4:L4) -> 122
B5: Beaver | C5: 1 | M5: =SUM(C5:L5) -> 1
B6: Box Elder | D6: 2 | E6: 3 | G6: 12 | K6: 3 | L6: 1 | M6: =SUM(C6:L6) -> 21
B7: Cache | C7: 6 | D7: 2 | E7: 27 | F7: 2 | G7: 11 | L7: 2 | M7: =SUM(C7:L7) -> 50
B8: Canyons | C8: 12 | D8: 5 | E8: 45 | F8: 4 | G8: 36 | H8: 3 | L8: 7 | M8: =SUM(C8:L8) -> 112
B9: Carbon | C9: 1 | E9: 10 | I9: 1 | J9: 1 | L9: 1 | M9: =SUM(C9:L9) -> 14
B10: Daggett | M10: =SUM(C10:L10) -> 0
B11: Davis | C11: 20 | D11: 24 | E11: 108 | G11: 27 | K11: 5 | L11: 13 | M11: =SUM(C11:L11) -> 197
B12: Duchesne | C12: 3 | D12: 17 | E12: 7 | G12: 11 | L12: 3 | M12: =SUM(C12:L12) -> 41
B13: Emery | M13: =SUM(C13:L13) -> 0
B14: Garfield | E14: 2 | M14: =SUM(C14:L14) -> 2
B15: Grand | C15: 6 | E15: 4 | F15: 2 | G15: 1 | M15: =SUM(C15:L15) -> 13
B16: Granite | C16: 12 | D16: 15 | E16: 181 | F16: 8 | G16: 34 | L16: 23 | M16: =SUM(C16:L16) -> 273
B17: Iron | D17: 10 | E17: 18 | G17: 11 | K17: 2 | M17: =SUM(C17:L17) -> 41
B18: Jordan | C18: 9 | D18: 4 | E18: 44 | F18: 11 | G18: 3 | L18: 2 | M18: =SUM(C18:L18) -> 73
B19: Juab | D19: 1 | M19: =SUM(C19:L19) -> 1
B20: Kane | M20: =SUM(C20:L20) -> 0
B21: Logan | F21: 3 | L21: 3 | M21: =SUM(C21:L21) -> 6
B22: Millard | M22: =SUM(C22:L22) -> 0
B23: Morgan | C23: 1 | E23: 2 | L23: 1 | M23: =SUM(C23:L23) -> 4
B24: Murray | C24: 1 | D24: 6 | E24: 24 | G24: 5 | L24: 1 | M24: =SUM(C24:L24) -> 37
B25: Nebo | C25: 5 | D25: 55 | E25: 49 | F25: 2 | G25: 12 | K25: 2 | L25: 10 | M25: =SUM(C25:L25) -> 135
B26: North Sanpete | M26: =SUM(C26:L26) -> 0
B27: North Summit | M27: =SUM(C27:L27) -> 0
B28: Ogden | C28: 1 | D28: 1 | E28: 21 | L28: 8 | M28: =SUM(C28:L28) -> 31
B29: Park City | C29: 9 | D29: 3 | E29: 12 | G29: 1 | M29: =SUM(C29:L29) -> 25
B30: Piute | M30: =SUM(C30:L30) -> 0
B31: Provo | C31: 3 | D31: 2 | E31: 23 | G31: 8 | K31: 1 | M31: =SUM(C31:L31) -> 37
B32: Rich | M32: =SUM(C32:L32) -> 0
B33: Salt Lake | C33: 8 | D33: 9 | E33: 55 | F33: 5 | G33: 37 | I33: 16 | J33: 6 | K33: 2 | L33: 22 | M33: =SUM(C33:L33) -> 160
B34: San Juan | C34: 9 | D34: 3 | E34: 30 | G34: 9 | L34: 5 | M34: =SUM(C34:L34) -> 56
B35: Sevier | M35: =SUM(C35:L35) -> 0
B36: South Sanpete | D36: 3 | E36: 1 | M36: =SUM(C36:L36) -> 4
B37: South Summit | M37: =SUM(C37:L37) -> 0
B38: Tintic | M38: =SUM(C38:L38) -> 0
B39: Tooele | C39: 1 | D39: 21 | E39: 30 | F39: 5 | G39: 2 | K39: 1 | L39: 1 | M39: =SUM(C39:L39) -> 61
B40: Uintah | C40: 2 | E40: 10 | I40: 1 | J40: 3 | L40: 2 | M40: =SUM(C40:L40) -> 18
...

Sheet HSCharter
B1: High
C2: Alcohol | D2: Tobacco | E2: Other Drugs | F2: Distribution | G2: Assaults | H2: Arson | I2: Handgun | J2: Rifle | K2: Other Firearm | L2: Other Weapon | M2: Totals
B3: Charter
B4: AMES | C4: 1 | E4: 2 | L4: 2 | M4: =SUM(C4:L4) -> 5
B5: City Academy | C5: 1 | M5: =SUM(C5:L5) -> 1
B6: Thomas Edison--North | M6: =SUM(C6:L6) -> 0
B7: Karl G. Maeser Preparatory Academy | C7: 3 | L7: 3 | M7: =SUM(C7:L7) -> 6
B8: Tuachahn High for the Performing Arts | D8: 2 | E8: 1 | L8: 1 | M8: =SUM(C8:L8) -> 4
B9: Fast Forward High | E9: 16 | M9: =SUM(C9:L9) -> 16
B10: East Hollywood High | E10: 2 | F10: 1 | G10: 1 | M10: =SUM(C10:L10) -> 4
B11: Davinci Academy | G11: 3 | M11: =SUM(C11:L11) -> 3
B12: City Academy | L12: 1 | M12: =SUM(C12:L12) -> 1
B13: Uintah River High | L13: 1 | M13: =SUM(C13:L13) -> 1
B14: Charter Total | C14: =SUM(C4:C13) -> 5 | D14: =SUM(D4:D13) -> 2 | E14: =SUM(E4:E13) -> 21 | F14: =SUM(F4:F13) -> 1 | G14: =SUM(G4:G13) -> 4 | H14: =SUM(H4:H13) -> 0 | I14: =SUM(I4:I13) -> 0 | J14: =SUM(J4:J13) -> 0 | ... M14: =SUM(M4:M13) -> 41
B15: Grand Total | C15: =SUM(C14,HS!C45) -> 137 | D15: =SUM(D14,HS!D45) -> 284 | E15: =SUM(E14,HS!E45) -> 817 | F15: =SUM(F14,HS!F45) -> 50 | G15: =SUM(G14,HS!G45) -> 247 | H15: =SUM(H14,HS!H45) -> 3 | I15: =SUM(I14,HS!I45) -> 18 | J15: =SUM(J14,HS!J45) -> 10 | ... M15: =SUM(M14,HS!M45) -> 1711
