Workbook
Name Ans_1: #REF!
Name Ans_1: #REF!
Name Ans_10: #REF!
Name Ans_10: #REF!
Name Ans_100: #REF!
Name Ans_100: #REF!
Name Ans_11: #REF!
Name Ans_11: #REF!
Name Ans_12: #REF!
Name Ans_12: #REF!
Name Ans_13: #REF!
Name Ans_13: #REF!
Name Ans_14: #REF!
Name Ans_14: #REF!
Name Ans_15: #REF!
Name Ans_15: #REF!
Name Ans_16: #REF!
Name Ans_16: #REF!
Name Ans_17: [1]SAP!$T$114
Name Ans_19: #REF!
Name Ans_19: #REF!
Name Ans_2: #REF!
Name Ans_2: #REF!
Name Ans_20: #REF!
Name Ans_20: #REF!
Name Ans_21: #REF!
Name Ans_21: #REF!
Name Ans_22: #REF!
Name Ans_22: #REF!
Name Ans_25: #REF!
Name Ans_25: #REF!
Name Ans_3: #REF!
Name Ans_3: #REF!
Name Ans_32: #REF!
Name Ans_32: #REF!
Name Ans_33: #REF!
Name Ans_33: #REF!
Name Ans_34: #REF!
Name Ans_34: #REF!
Name Ans_35: #REF!
Name Ans_35: #REF!
Name Ans_36: #REF!
Name Ans_36: #REF!
Name Ans_37: #REF!
Name Ans_37: #REF!
Name Ans_38: #REF!
Name Ans_38: #REF!
Name Ans_39: #REF!
Name Ans_39: #REF!
Name Ans_4: #REF!
Name Ans_4: #REF!
Name Ans_40: #REF!
Name Ans_40: #REF!
Name Ans_47: #REF!
Name Ans_47: #REF!
Name Ans_48: #REF!
Name Ans_48: #REF!
Name Ans_49: #REF!
Name Ans_49: #REF!
Name Ans_5: #REF!

Sheet Cover
C22: COMPANY COVER SHEET
C26: PLEASE USE IN CONJUNCTION WITH SCSI GUIDANCE NOTES and BCIS ISO 15686 Supplement

Sheet contents
A1: CT | B1: Contents
B3: Life Cycle Cost Parameters
B4: Basis of Estimate
B5: Life Cycle Cost Summary
B6: Level 1 Breakdown
B7: Construction Cost Summary
B8: Other Construction Costs
B9: Operations, Maintenance and Occupancy
B10: Major Replacement
B11: End Of Life Costs
B12: Non Construction Costs
B13: Income

Sheet Parameters
A1: LCC | B1: Life Cycle Cost Parameters
A3: PROJECT TITLE:
A4: Location
A5: Project Details:
A8: Owner:
A9: Occupier:
A10: Prepared By:
A12: DATES
A13: Plan | C13: Preparation date: | H13: Indexing Base
A14: Construction Cost | C14: Base Date: | H14: Start Date:
C15: Date of Completion: | H15: Date of Hand Over:
A16: Maintenance | C16: Start Date: | H16: End Date:
A17: Operation | C17: Start Date: | H17: End Date:
A18: Occupancy | C18: Start Date: | H18: End Date:
A19: End of Life | C19: End Date: | H19: Hand Back Liability Period:
A20: Period of Analysis: | D20: Unit of time: (w/m/year) | H20: Total Asset Life Expectancy:
A22: BASIS OF YEARS (eg. Calendar; financial year) – please state
A25: PROCUREMENT DETAILS
A26: Procurement Route:
A27: Procurement Stage:
A28: Tender Basis:
A29: Market Conditions:
A31: BUILDINGS ENVIRONMENTAL TARGET
A32: Scheme | D32: Target Score
A33: Other Considerations
A35: BASIS OF COST
A36: Current Price | D36: Discount Rate
A37: Net Present Value | D37: Escalation Rate
A38: Escalation Rate | D38: GIFA | H38: 0

Sheet Basis of Est.
A1: LCC | B1: Basis of Life Cycle Cost
A3: Schedule of Areas
A5: Basement floors: | D5: Percentage of gross floor area:
A6: Ground floor | D6: Below ground floor
A7: Upper floors | D7: Single storey construction
A8: Total (Gross Internal Floor Area) | D8: Two storey construction
A9: Usable Area | D9: ____ storey construction
A10: Circulation Area | D10: ____ storey construction
A11: Ancillary Areas | D11: Average storey height:
A12: Internal divisions | D12: Below ground floor(s)
A13: Total (Gross Internal Floor Area) | D13: Ground floor
A14: Spaces not enclosed: | D14: Above ground floor(s)
A15: Areas Requiring Regular Cleaning | D15: External vertical envelope (Ext. walls, windows & doors)
A16: Internal cube | D16: Area of Glazing
... A19: Exclusions | D19: Inclusions
A20: 1 | D20: 1
A21: 2 | D21: 2
A22: 3 | D22: 3
A23: 4 | D23: 4
A24: 5 | D24: 5
A25: 6 | D25: 6
A26: 7 | D26: 7
A27: 8 | D27: 8
A28: 9 | D28: 9
A29: 10 | D29: 10
A30: 11 | D30: 11
A31: 12 | D31: 12
... A36: 17 | D36: 17
A38: Documents Used as Bases of Analysis | E38: Source
A39: 1.
A40: 2.
A41: 3.
A42: 4.
A43: 5.

Sheet Summary
B1: WLCC | C1: Life Cycle Cost Summary | I1: Years | K1: 60
B3: WLCC | C3: Whole Life Cycle Cost | E3: Life Cycle Cost | G3: €/m2 | I3: Total Present Value | K3: €/m2
B5: CC | C5: Construction Costs | E5: ='Summary L1'!F8 -> 0 | G5: 0 | I5: =E5 -> 0 | K5: 0
B7: 2.0 | C7: Maintenance Costs | E7: ='Summary L1'!F18 -> 17004 | G7: 0 | I7: ='Summary L1'!H18 -> 9549.681 | K7: 0
B9: 3.0 | C9: Operations Costs | E9: ='Summary L1'!F36 -> 1800000 | G9: 0 | I9: ='Summary L1'!H36 -> 1057691.5 | K9: 0
B11: 4.0 | C11: Occupancy Costs | E11: ='Summary L1'!F56 -> 0 | G11: 0 | I11: ='Summary L1'!H56 -> 0 | K11: 0
B13: 5.0 | C13: End of Life Costs | E13: ='Summary L1'!F64 -> 0 | G13: 0 | I13: ='Summary L1'!H64 -> 0 | K13: 0
B15: LLC | C15: Life Cycle Cost (2.0 - 5.0) | E15: =SUM(E7:E14) -> 1817004 | G15: 0 | I15: =SUM(I7:I14) -> 1067241.1 | K15: 0
B17: TLLC | C17: Total Life Cycle Cost (Incld Construction) | E17: =E5+E15 -> 1817004 | G17: 0 | I17: =I5+I15 -> 1067241.1 | K17: 0
B19: 6.0 | C19: Non Construction Costs | E19: ='Summary L1'!F74 -> 0 | G19: 0 | I19: ='Summary L1'!H74 -> 0 | K19: 0
B21: 7.0 | C21: Income | E21: ='Summary L1'!F86 -> 0 | G21: 0 | I21: ='Summary L1'!H86 -> 0 | K21: 0
B23: 8.0 | C23: Externalities | E23: ='Summary L1'!F82 -> 0 | G23: 0 | I23: ='Summary L1'!H82 -> 0 | K23: 0
B25: WLC | C25: Whole Life Cycle Cost (ex VAT) | E25: =SUM(E17:E23) -> 1817004 | G25: 0 | I25: =SUM(I17:I23) -> 1067241.1 | K25: 0
B27: VAT | C27: Vat | E27: =(E25*0.135) -> 245295.54 | G27: 0 | I27: =I25*0.135 -> 144077.55 | K27: 0
B29: WLC VAT | C29: Whole Life Cycle Cost (Inc. VAT) | E29: =SUM(E25:E27) -> 2062299.5 | G29: 0 | I29: =SUM(I25:I28) -> 1211318.7 | K29: 0
B32: NAE | C32: Net Annual Expediture | E32: Annual Costs | G32: €/m2 | I32: %
B34: 2.0 | C34: Maintenance Costs | E34: ='Summary L1'!E18 -> 283.4 | G34: 0 | I34: =E34/E41 -> 0.0093582623
B36: 3.0 | C36: Operations Costs | E36: ='Summary L1'!E36 -> 30000 | G36: 0 | I36: =E36/E41 -> 0.99064174
B38: 4.0 | C38: Occupancy Costs | E38: ='Summary L1'!E56 -> 0 | G38: 0 | I38: =E38/E41 -> 0
B41: NAE | C41: Net Annual Expeniture | E41: =SUM(E34:E38) -> 30283.4 | G41: 0 | I41: =SUM(I34:I38) -> 1
B43: 7.0 | C43: Annual Income | E43: 0 | G43: 0
B45: WNAE | C45: Whole Net Annual Expeniture | E45: =E41-E43 -> 30283.4 | G45: =G41-G43 -> 0

Sheet Summary L1
B1: LLC | D1: Life Cycle Costs Analysis | G1: 60 | H1: Years
C2: Ref | D2: BCIS | E2: Annual Amount | F2: Life Cycle Cost | G2: Escalated Life Cycle Cost | H2: Total Present Value
B4: Construction Costs | C4: 1.0 | D4: Construction Costs
C5: 1.1 | D5: Construction works costs
C6: 1.2 | D6: Other construction related costs
C7: 1.3 | D7: Client definable costs | F7: 0 | G7: =F7 -> 0 | H7: =F7 -> 0
D8: Total Construction Costs | F8: =SUM(F5:F7) -> 0 | G8: =SUM(G5:G7) -> 0 | H8: =SUM(H5:H7) -> 0
B10: Maintenance, Operations and Occupancy Costs | C10: 2.0 | D10: Maintenance Costs
C11: ='AP2-O&M L2'!A4 -> 2.1 | D11: ='AP2-O&M L2'!B4 -> Major replacement | E11: ='AP2-O&M L2'!G5 -> 283.4 | F11: ='AP2-O&M L2'!H5 -> 17004 | G11: ='AP2-O&M L2'!J5 -> 41273.171 | H11: ='AP2-O&M L2'!L5 -> 9549.681
C12: ='AP2-O&M L2'!A6 -> 2.2 | D12: ='AP2-O&M L2'!B6 -> Subsequent refurbishment and adaptation costs
C13: ='AP2-O&M L2'!A8 -> 2.3 | D13: ='AP2-O&M L2'!B8 -> Redecoration - internal / external
C14: ='AP2-O&M L2'!A10 -> 2.4 | D14: ='AP2-O&M L2'!B10 -> Minor replacement, repairs and PPM maintenance costs
C15: ='AP2-O&M L2'!A12 -> 2.5 | D15: ='AP2-O&M L2'!B12 -> Unscheduled repairs, replacement and maintenance
C16: ='AP2-O&M L2'!A14 -> 2.6 | D16: ='AP2-O&M L2'!B14 -> Grounds maintenance
C17: ='AP2-O&M L2'!A16 -> 2.7 | D17: ='AP2-O&M L2'!B16 -> Client definable costs
D18: Total Maintenance Costs | E18: =E11+E12+E13+E14+E15+E16+E17 -> 283.4 | F18: =SUM(F11:F17) -> 17004 | G18: =SUM(G11:G17) -> 41273.171 | H18: =SUM(H11:H17) -> 9549.681
C20: 3.0 | D20: Operations Costs
C21: ='AP2-O&M L2'!A20 -> 3.1 | D21: ='AP2-O&M L2'!B20 -> Cleaning costs
C22: ='AP2-O&M L2'!B21 -> 3.1.1 | D22: ='AP2-O&M L2'!C21 -> Windows and external surfaces
C23: ='AP2-O&M L2'!B23 -> 3.1.2 | D23: ='AP2-O&M L2'!C23 -> Internal cleaning
C24: ='AP2-O&M L2'!B25 -> 3.1.3 | D24: ='AP2-O&M L2'!C25 -> Specialist cleaning
C25: ='AP2-O&M L2'!B27 -> 3.1.4 | D25: ='AP2-O&M L2'!C27 -> External works cleaning
C26: ='AP2-O&M L2'!A29 -> 3.2 | D26: ='AP2-O&M L2'!B29 -> Utilities costs gas and electric
C27: ='AP2-O&M L2'!B30 -> 3.2.1 | D27: ='AP2-O&M L2'!C30 -> Fuel Costs | E27: ='AP2-O&M L2'!G46 -> 30000 | F27: ='AP2-O&M L2'!H46 -> 1800000 | G27: ='AP2-O&M L2'!J46 -> 5038351.2 | H27: ='AP2-O&M L2'!L46 -> 1057691.5
C28: ='AP2-O&M L2'!B32 -> 3.2.2 | D28: ='AP2-O&M L2'!C32 -> Water and Drainage
C29: ='AP2-O&M L2'!A34 -> 3.3 | D29: ='AP2-O&M L2'!B34 -> Administration Costs
C30: ='AP2-O&M L2'!B35 -> 3.3.1 | D30: ='AP2-O&M L2'!C35 -> Property management
C31: ='AP2-O&M L2'!B37 -> 3.3.2 | D31: ='AP2-O&M L2'!C37 -> Staff engaged with servicing the building
C32: ='AP2-O&M L2'!B39 -> 3.3.3 | D32: ='AP2-O&M L2'!C39 -> Waste management disposal
C33: ='AP2-O&M L2'!A41 -> 3.4 | D33: ='AP2-O&M L2'!B41 -> Overhead costs | E33: =SUMIF('AP2-O&M L2'!$A$3:$A$82,'Summary L1'!$C33,'AP2-O&M L2'!$G$3:$G$82) -> 0 | F33: =SUMIF('AP2-O&M L2'!$A$3:$A$82,'Summary L1'!$C33,'AP2-O&M L2'!$H$3:$H$82) -> 0 | G33: =SUMIF('AP2-O&M L2'!$A$3:$A$82,'Summary L1'!$C33,'AP2-O&M L2'!$J$3:$J$82) -> 0 | H33: =SUMIF('AP2-O&M L2'!$A$3:$A$82,'Summary L1'!$C33,'AP2-O&M L2'!$L$3:$L$82) -> 0
C34: ='AP2-O&M L2'!A43 -> 3.5 | D34: ='AP2-O&M L2'!B43 -> Taxes | E34: =SUMIF('AP2-O&M L2'!$A$3:$A$82,'Summary L1'!$C34,'AP2-O&M L2'!$G$3:$G$82) -> 0 | F34: =SUMIF('AP2-O&M L2'!$A$3:$A$82,'Summary L1'!$C34,'AP2-O&M L2'!$H$3:$H$82) -> 0 | G34: =SUMIF('AP2-O&M L2'!$A$3:$A$82,'Summary L1'!$C34,'AP2-O&M L2'!$J$3:$J$82) -> 0 | H34: =SUMIF('AP2-O&M L2'!$A$3:$A$82,'Summary L1'!$C34,'AP2-O&M L2'!$L$3:$L$82) -> 0
C35: ='AP2-O&M L2'!A45 -> 3.6 | D35: ='AP2-O&M L2'!B45 -> Client definable costs | E35: =SUMIF('AP2-O&M L2'!$A$3:$A$82,'Summary L1'!$C35,'AP2-O&M L2'!$G$3:$G$82) -> 0 | F35: =SUMIF('AP2-O&M L2'!$A$3:$A$82,'Summary L1'!$C35,'AP2-O&M L2'!$H$3:$H$82) -> 0 | G35: =SUMIF('AP2-O&M L2'!$A$3:$A$82,'Summary L1'!$C35,'AP2-O&M L2'!$J$3:$J$82) -> 0 | H35: =SUMIF('AP2-O&M L2'!$A$3:$A$82,'Summary L1'!$C35,'AP2-O&M L2'!$L$3:$L$82) -> 0
D36: Total Operations Costs | E36: =SUM(E21:E32) -> 30000 | F36: =SUM(F21:F32) -> 1800000 | G36: =SUM(G21:G32) -> 5038351.2 | H36: =SUM(H21:H32) -> 1057691.5
C38: 4.0 | D38: Occupancy Costs
C39: ='AP2-O&M L2'!A49 -> 4.1 | D39: ='AP2-O&M L2'!B49 -> Internal moves | E39: =SUMIF('AP2-O&M L2'!$A$3:$A$82,'Summary L1'!$C39,'AP2-O&M L2'!$G$3:$G$82) -> 0 | F39: =SUMIF('AP2-O&M L2'!$A$3:$A$82,'Summary L1'!$C39,'AP2-O&M L2'!$H$3:$H$82) -> 0 | G39: =SUMIF('AP2-O&M L2'!$A$3:$A$82,'Summary L1'!$C39,'AP2-O&M L2'!$J$3:$J$82) -> 0 | H39: =SUMIF('AP2-O&M L2'!$A$3:$A$82,'Summary L1'!$C39,'AP2-O&M L2'!$L$3:$L$82) -> 0
C40: ='AP2-O&M L2'!A51 -> 4.2 | D40: ='AP2-O&M L2'!B51 -> Reception and customer hosting | E40: =SUMIF('AP2-O&M L2'!$A$3:$A$82,'Summary L1'!$C40,'AP2-O&M L2'!$G$3:$G$82) -> 0 | F40: =SUMIF('AP2-O&M L2'!$A$3:$A$82,'Summary L1'!$C40,'AP2-O&M L2'!$H$3:$H$82) -> 0 | G40: =SUMIF('AP2-O&M L2'!$A$3:$A$82,'Summary L1'!$C40,'AP2-O&M L2'!$J$3:$J$82) -> 0 | H40: =SUMIF('AP2-O&M L2'!$A$3:$A$82,'Summary L1'!$C40,'AP2-O&M L2'!$L$3:$L$82) -> 0
C41: ='AP2-O&M L2'!A53 -> 4.3 | D41: Security
C42: ='AP2-O&M L2'!A55 -> 4.4 | D42: ='AP2-O&M L2'!B55 -> Helpdesk
C43: ='AP2-O&M L2'!A57 -> 4.5 | D43: ='AP2-O&M L2'!B57 -> Switchboard / telephones
C44: ='AP2-O&M L2'!A59 -> 4.6 | D44: ='AP2-O&M L2'!B59 -> Postroom - mail services
...

Sheet Cost Plan L2
B8: Insert Cost Plan Construction Cost

Sheet AP1-Other Const Costs L2
A1: OCC | B1: Other Construction Costs Profile | F1: Years | G1: 60
A2: REF | B2: BCIS | C2: Description | D2: Qty | E2: Unit | F2: Rate | G2: Cost
A3: 1.2 | B3: Other Construction Costs
A4: 1.2 | B4: Other Related Construction Costs
C5: State client requirements, standards required, working restrictions and procurement context
C7: Total Non Construction Costs | G7: =SUM(G4:G6) -> 0

Sheet AP2-O&M L2
A1: O&M | B1: Operations and Maintenance | J1: Years | L1: 60
A2: Ref | B2: BCIS | C2: Description | D2: Qty | E2: Unit | F2: Rate | G2: Annual Cost | H2: Life Cycle Cost | I2: (e) | J2: Escalated Life Cycle Cost | K2: (i) | L2: Present Value | N2: Present Value Factor | P2: Escalation factor
A3: 2.0 | B3: Maintenance Costs
A4: 2.1 | B4: Major replacement
A5: 2.1 | C5: AP3 - Replacement Costs | G5: ='AP3-Replacement L2'!$K$24 -> 283.4 | H5: ='AP3-Replacement L2'!$L$24 -> 17004 | J5: ='AP3-Replacement L2'!$N$24 -> 41273.171 | L5: ='AP3-Replacement L2'!$P$24 -> 9549.681
A6: 2.2 | B6: Subsequent refurbishment and adaptation costs
A7: 2.2 | C7: State client requirements, standards required, working restrictions and procurement context
A8: 2.3 | B8: Redecoration - internal / external
A9: 2.3 | C9: State client requirements, standards required, working restrictions and procurement context
A10: 2.4 | B10: Minor replacement, repairs and PPM maintenance costs
A11: 2.4 | C11: State client requirements, standards required, working restrictions and procurement context
A12: 2.5 | B12: Unscheduled repairs, replacement and maintenance
A13: 2.5 | C13: State client requirements, standards required, working restrictions and procurement context
A14: 2.6 | B14: Grounds maintenance
A15: 2.6 | C15: State client requirements, standards required, working restrictions and procurement context
A16: 2.7 | B16: Client definable costs
C17: Total Maintenance Costs | G17: =SUM(G4:G16) -> 283.4 | H17: =SUM(H5:H16) -> 17004 | J17: =SUM(J5:J16) -> 41273.171 | L17: =SUM(L4:L16) -> 9549.681
A19: 3.0 | B19: Operations Costs
A20: 3.1 | B20: Cleaning costs
A21: 3.1 | B21: 3.1.1 | C21: Windows and external surfaces
A22: 3.1 | B22: 3.1.1 | C22: State client requirements, standards required, working restrictions and procurement context
A23: 3.1 | B23: 3.1.2 | C23: Internal cleaning
A24: 3.1 | B24: 3.1.2 | C24: State client requirements, standards required, working restrictions and procurement context
A25: 3.1 | B25: 3.1.3 | C25: Specialist cleaning
A26: 3.1 | B26: 3.1.3 | C26: State client requirements, standards required, working restrictions and procurement context
A27: 3.1 | B27: 3.1.4 | C27: External works cleaning
A28: 3.1 | B28: 3.1.4 | C28: State client requirements, standards required, working restrictions and procurement context
A29: 3.2 | B29: Utilities costs gas and electric
A30: 3.2 | B30: 3.2.1 | C30: Fuel Costs
A31: 3.2 | B31: 3.2.1 | C31: ESB - estimated yearly costs | D31: 1 | E31: LS | F31: 30000 | G31: =F31*D31 -> 30000 | H31: =G31*$L$1 -> 1800000 | I31: 0.03 | J31: =P31*G31 -> 5038351.2 | K31: 0.05 | L31: =G31*N31 -> 1057691.5 | N31: =IF(I31=K31,$L$1,(1-((1+I31)/(1+K31))^$L$1)/(((1+K31)/(1+I31))-1)) -> 35.256382 | P31: =(((1+I31)^61-1)/I31)-1 -> 167.94504
A32: 3.2 | B32: 3.2.2 | C32: Water and Drainage
A33: 3.2 | B33: 3.2.2 | C33: State client requirements, standards required, working restrictions and procurement context
A34: 3.3 | B34: Administration Costs
A35: 3.3 | B35: 3.3.1 | C35: Property management
A36: 3.3 | B36: 3.3.1 | C36: State client requirements, standards required, working restrictions and procurement context
A37: 3.3 | B37: 3.3.2 | C37: Staff engaged with servicing the building
A38: 3.3 | B38: 3.3.2 | C38: State client requirements, standards required, working restrictions and procurement context
A39: 3.3 | B39: 3.3.3 | C39: Waste management disposal
A40: 3.3 | B40: 3.3.3 | C40: State client requirements, standards required, working restrictions and procurement context
A41: 3.4 | B41: Overhead costs
...

Sheet AP3-Replacement L2
A1: MR | B1: Major Replacement Costs | N1: Years | P1: 60
A2: REF | C2: Description | D2: Qty | E2: Unit | F2: Rate | G2: Year | H2: Cost TODAY | I2: f | J2: Factored Cost | K2: Annual Cost Equiv. | L2: Life Cycle Cost (ne) | M2: (e) | N2: Escalated LLC | O2: (i) | P2: Present Value
A3: 2.0 | B3: Maintenance (Replacement) Costs
A4: 2.1 | B4: Major Replacement
A5: 22 | B5: Internal Walls, Partitions
A6: 22 | C6: Stud Partitions | D6: 1 | E6: LS | F6: 14170 | G6: 30 | H6: =D6*F6 -> 14170 | I6: 1.2 | J6: =H6*I6 -> 17004 | K6: =L6/P1 -> 283.4 | L6: =J6 -> 17004 | M6: 0.03 | N6: =J6*T6 -> 41273.171 | O6: 0.05 | P6: =J6*R6 -> 9549.681 | R6: =((1+M6)/(1+O6))^G6 -> 0.5616138 | T6: =(1+M6)^G6 -> 2.4272625
C9: Insert Replacement Costs
C24: Total Major Replacement Costs | H24: =SUM(H5:H23) -> 14170 | J24: =SUM(J6:J23) -> 17004 | K24: =SUM(K5:K23) -> 283.4 | L24: =SUM(L5:L23) -> 17004 | N24: =SUM(N5:N23) -> 41273.171 | P24: =SUM(P5:P23) -> 9549.681

Sheet AP4-End of Life L2
A1: EOL | B1: End Of Life Costs Profile | N1: Years | P1: 60
A2: REF | B2: BCIS | C2: Description | D2: Qty | E2: Unit | F2: Rate | G2: Year | H2: Cost | I2: f | J2: Factored Cost | K2: Annual Cost Equiv. | L2: Life Cycle Cost | M2: (e) | N2: Escalated Costs | O2: (i) | P2: Acc. Present Value | Q2: Check Present Value | S2: f | T2: f1 | U2: f2 | V2: 1 | W2: 1 | X2: 2 | Y2: 2 | Z2: 3 | AA2: 3 | AB2: 4 | AC2: 4 | AD2: 5 | AE2: 5 | AF2: 6 | AG2: 6 | AH2: 7 | AI2: 7 | AJ2: 8 | AK2: 8 | AL2: 9 | AM2: 9 | AN2: 10 | AO2: 10 | AP2: 11 | AQ2: 11 | AR2: 12 | AS2: 12 | AT2: 13 | AU2: 13 | AV2: 14 | AW2: 14 | AX2: 15 | AY2: 15 | AZ2: 16 | BA2: 16 | BB2: 17 | BC2: 17 | BD2: 18 | BE2: 18 | BF2: 19 | BG2: 19 | BH2: 20 | BI2: 20 | BJ2: 21 | BK2: 21 | BL2: 22 | BM2: 22 | BN2: 23 | BO2: 23 | BP2: 24 | BQ2: 24 | BR2: 25 | BS2: 25 | BT2: 26 | BU2: 26 | BV2: 27 | BW2: 27 | BX2: 28 | BY2: 28 | BZ2: 29 | CA2: 29 | CB2: 30 | CC2: 30 | CD2: 31 | CE2: 31 | CF2: 32 | CG2: 32 | CH2: 33 | CI2: 33 | CJ2: 34 | CK2: 34 | CL2: 35 | CM2: 35 | CN2: 36 | CO2: 36 | CP2: 37 | CQ2: 37 | CR2: 38 | CS2: 38 | CT2: 39 | CU2: 39 | CV2: 40 | CW2: 40 | CX2: 41 | CY2: 41 | CZ2: 42 | DA2: 42 | DB2: 43 | DC2: 43 | DD2: 44 | DE2: 44 | DF2: 45 | DG2: 45 | DH2: 46 | DI2: 46 | DJ2: 47 | DK2: 47 | DL2: 48 | DM2: 48 | DN2: 49 | DO2: 49 | DP2: 50 | DQ2: 50 | DR2: 51 | DS2: 51 | DT2: 52 | DU2: 52 | DV2: 53 | DW2: 53 | DX2: 54 | DY2: 54 | DZ2: 55 | EA2: 55 | EB2: 56 | EC2: 56 | ED2: 57 | EE2: 57 | EF2: 58 | EG2: 58 | EH2: 59 | EI2: 59 | EJ2: 60 | EK2: 60
A3: 5.0 | B3: End of Life Costs
A4: 5.1 | B4: Disposal inspections
A5: 5.1 | C5: State client requirements, standards required, working restrictions and procurement context | Q5: =((1/U5^$W$2)*W5)+((1/U5^$Y$2)*Y5)+((1/U5^$AA$2)*AA5)+((1/U5^$AC$2)*AC5)+((1/U5^$AE$2)*AE5)+((1/U5^$AG$2)*AG5)+((1/U5^$AI$2)*AI5)+((1/U5^$AK$2)*AK5)+((1/U5^$AM$2)*AM5)+((1/U5^$AO$2)*AO5)+((1/U5^$AQ$2)*AQ5)+((1/U5^$AS$2)*AS5)+((1/U5^$AU$2)*AU5)+((1/U5^$AW$2)*AW5)+((1/U5^$AY$2)*AY5)+((1/U5^$BA$2)*BA5)+((1/U5^$BC$2)*BC5)+((1/U5^$BE$2)*BE5)+((1/U5^$BG$2)*BG5)+((1/U5^$BI$2)*BI5)+((1/U5^$BK$2)*BK5)+((1/U5^$BM$2)*BM5)+((1/U5^$BO$2)*BO5)+((1/U5^$BQ$2)*BQ5)+((1/U5^$BS$2)*BS5)+((1/U5^$BU$2)*BU5)+((1/U5^$BW$2)*BW5)+((1/U5^$BY$2)*BY5)+((1/U5^$CA$2)*CA5)+((1/U5^$CC$2)*CC5)+((1/U5^$CE$2)*CE5)+((1/U5^$CG$2)*CG5)+((1/U5^$CI$2)*CI5)+((1/U5^$CK$2)*CK5)+((1/U5^$CM$2)*CM5)+((1/U5^$CO$2)*CO5)+((1/U5^$CQ$2)*CQ5)+((1/U5^$CS$2)*CS5)+((1/U5^$CU$2)*CU5)+((1/U5^$CW$2)*CW5)+((1/U5^$CY$2)*CY5)+((1/U5^$DA$2)*DA5)+((1/U5^$DC$2)*DC5)+((1/U5^$DE$2)*DE5)+((1/U5^$DG$2)*DG5)+((1/U5^$DI$2)*DI5)+((1/U5^$DK$2)*DK5)+((1/U5^$DM$2)*DM5)+((1/U5^$DO$2)*DO5)+((1/U5^$DQ$2)*DQ5)+((1/U5^$DS$2)*DS5)+((1/U5^$DU$2)*DU5)+((1/U5^$DW$2)*DW5)+((1/U5^$DY$2)*DY5)+((1/U5^$EA$2)*EA5)+((1/U5^$EC$2)*EC5)+((1/U5^$EE$2)*EE5)+((1/U5^$EG$2)*EG5)+((1/U5^$EI$2)*EI5)+(1/U5^$EK$2)*EK5 -> 0 | S5: =((1+M5)/(1+O5)) -> 1 | T5: =1+M5 -> 1 | U5: =(1+O5) -> 1 | V5: =IF(INT(V$2)=INT($G5),($J5),(0)) -> 0 | W5: =IF(INT(W$2)=INT($G5),($J5),(0))*$T5^W$2 -> 0 | X5: =IF(INT(X$2)=INT($G5),($J5),(0)) -> 0 | Y5: =IF(INT(Y$2)=INT($G5),($J5),(0))*$T5^Y$2 -> 0 | Z5: =IF(INT(Z$2)=INT($G5),($J5),(0)) -> 0 | AA5: =IF(INT(AA$2)=INT($G5),($J5),(0))*$T5^AA$2 -> 0 | AB5: =IF(INT(AB$2)=INT($G5),($J5),(0)) -> 0 | AC5: =IF(INT(AC$2)=INT($G5),($J5),(0))*$T5^AC$2 -> 0 | AD5: =IF(INT(AD$2)=INT($G5),($J5),(0)) -> 0 | AE5: =IF(INT(AE$2)=INT($G5),($J5),(0))*$T5^AE$2 -> 0 | AF5: =IF(INT(AF$2)=INT($G5),($J5),(0)) -> 0 | AG5: =IF(INT(AG$2)=INT($G5),($J5),(0))*$T5^AG$2 -> 0 | AH5: =IF(INT(AH$2)=INT($G5),($J5),(0)) -> 0 | AI5: =IF(INT(AI$2)=INT($G5),($J5),(0))*$T5^AI$2 -> 0 | AJ5: =IF(INT(AJ$2)=INT($G5),($J5),(0)) -> 0 | AK5: =IF(INT(AK$2)=INT($G5),($J5),(0))*$T5^AK$2 -> 0 | AL5: =IF(INT(AL$2)=INT($G5),($J5),(0)) -> 0 | AM5: =IF(INT(AM$2)=INT($G5),($J5),(0))*$T5^AM$2 -> 0 | AN5: =IF(INT(AN$2)=INT($G5),($J5),(0)) -> 0 | AO5: =IF(INT(AO$2)=INT($G5),($J5),(0))*$T5^AO$2 -> 0 | AP5: =IF(INT(AP$2)=INT($G5),($J5),(0)) -> 0 | AQ5: =IF(INT(AQ$2)=INT($G5),($J5),(0))*$T5^AQ$2 -> 0 | AR5: =IF(INT(AR$2)=INT($G5),($J5),(0)) -> 0 | AS5: =IF(INT(AS$2)=INT($G5),($J5),(0))*$T5^AS$2 -> 0 | AT5: =IF(INT(AT$2)=INT($G5),($J5),(0)) -> 0 | AU5: =IF(INT(AU$2)=INT($G5),($J5),(0))*$T5^AU$2 -> 0 | AV5: =IF(INT(AV$2)=INT($G5),($J5),(0)) -> 0 | AW5: =IF(INT(AW$2)=INT($G5),($J5),(0))*$T5^AW$2 -> 0 | AX5: =IF(INT(AX$2)=INT($G5),($J5),(0)) -> 0 | AY5: =IF(INT(AY$2)=INT($G5),($J5),(0))*$T5^AY$2 -> 0 | AZ5: =IF(INT(AZ$2)=INT($G5),($J5),(0)) -> 0 | BA5: =IF(INT(BA$2)=INT($G5),($J5),(0))*$T5^BA$2 -> 0 | BB5: =IF(INT(BB$2)=INT($G5),($J5),(0)) -> 0 | BC5: =IF(INT(BC$2)=INT($G5),($J5),(0))*$T5^BC$2 -> 0 | BD5: =IF(INT(BD$2)=INT($G5),($J5),(0)) -> 0 | BE5: =IF(INT(BE$2)=INT($G5),($J5),(0))*$T5^BE$2 -> 0 | BF5: =IF(INT(BF$2)=INT($G5),($J5),(0)) -> 0 | BG5: =IF(INT(BG$2)=INT($G5),($J5),(0))*$T5^BG$2 -> 0 | BH5: =IF(INT(BH$2)=INT($G5),($J5),(0)) -> 0 | BI5: =IF(INT(BI$2)=INT($G5),($J5),(0))*$T5^BI$2 -> 0 | BJ5: =IF(INT(BJ$2)=INT($G5),($J5),(0)) -> 0 | BK5: =IF(INT(BK$2)=INT($G5),($J5),(0))*$T5^BK$2 -> 0 | BL5: =IF(INT(BL$2)=INT($G5),($J5),(0)) -> 0 | BM5: =IF(INT(BM$2)=INT($G5),($J5),(0))*$T5^BM$2 -> 0 | BN5: =IF(INT(BN$2)=INT($G5),($J5),(0)) -> 0 | BO5: =IF(INT(BO$2)=INT($G5),($J5),(0))*$T5^BO$2 -> 0 | BP5: =IF(INT(BP$2)=INT($G5),($J5),(0)) -> 0 | BQ5: =IF(INT(BQ$2)=INT($G5),($J5),(0))*$T5^BQ$2 -> 0 | BR5: =IF(INT(BR$2)=INT($G5),($J5),(0)) -> 0 | BS5: =IF(INT(BS$2)=INT($G5),($J5),(0))*$T5^BS$2 -> 0 | BT5: =IF(INT(BT$2)=INT($G5),($J5),(0)) -> 0 | BU5: =IF(INT(BU$2)=INT($G5),($J5),(0))*$T5^BU$2 -> 0 | BV5: =IF(INT(BV$2)=INT($G5),($J5),(0)) -> 0 | BW5: =IF(INT(BW$2)=INT($G5),($J5),(0))*$T5^BW$2 -> 0 | BX5: =IF(INT(BX$2)=INT($G5),($J5),(0)) -> 0 | BY5: =IF(INT(BY$2)=INT($G5),($J5),(0))*$T5^BY$2 -> 0 | BZ5: =IF(INT(BZ$2)=INT($G5),($J5),(0)) -> 0 | CA5: =IF(INT(CA$2)=INT($G5),($J5),(0))*$T5^CA$2 -> 0 | CB5: =IF(INT(CB$2)=INT($G5),($J5),(0)) -> 0 | CC5: =IF(INT(CC$2)=INT($G5),($J5),(0))*$T5^CC$2 -> 0 | CD5: =IF(INT(CD$2)=INT($G5),($J5),(0)) -> 0 | CE5: =IF(INT(CE$2)=INT($G5),($J5),(0))*$T5^CE$2 -> 0 | CF5: =IF(INT(CF$2)=INT($G5),($J5),(0)) -> 0 | CG5: =IF(INT(CG$2)=INT($G5),($J5),(0))*$T5^CG$2 -> 0 | CH5: =IF(INT(CH$2)=INT($G5),($J5),(0)) -> 0 | CI5: =IF(INT(CI$2)=INT($G5),($J5),(0))*$T5^CI$2 -> 0 | CJ5: =IF(INT(CJ$2)=INT($G5),($J5),(0)) -> 0 | CK5: =IF(INT(CK$2)=INT($G5),($J5),(0))*$T5^CK$2 -> 0 | CL5: =IF(INT(CL$2)=INT($G5),($J5),(0)) -> 0 | CM5: =IF(INT(CM$2)=INT($G5),($J5),(0))*$T5^CM$2 -> 0 | CN5: =IF(INT(CN$2)=INT($G5),($J5),(0)) -> 0 | CO5: =IF(INT(CO$2)=INT($G5),($J5),(0))*$T5^CO$2 -> 0 | CP5: =IF(INT(CP$2)=INT($G5),($J5),(0)) -> 0 | CQ5: =IF(INT(CQ$2)=INT($G5),($J5),(0))*$T5^CQ$2 -> 0 | CR5: =IF(INT(CR$2)=INT($G5),($J5),(0)) -> 0 | CS5: =IF(INT(CS$2)=INT($G5),($J5),(0))*$T5^CS$2 -> 0 | CT5: =IF(INT(CT$2)=INT($G5),($J5),(0)) -> 0 | CU5: =IF(INT(CU$2)=INT($G5),($J5),(0))*$T5^CU$2 -> 0 | CV5: =IF(INT(CV$2)=INT($G5),($J5),(0)) -> 0 | CW5: =IF(INT(CW$2)=INT($G5),($J5),(0))*$T5^CW$2 -> 0 | CX5: =IF(INT(CX$2)=INT($G5),($J5),(0)) -> 0 | CY5: =IF(INT(CY$2)=INT($G5),($J5),(0))*$T5^CY$2 -> 0 | CZ5: =IF(INT(CZ$2)=INT($G5),($J5),(0)) -> 0 | DA5: =IF(INT(DA$2)=INT($G5),($J5),(0))*$T5^DA$2 -> 0 | DB5: =IF(INT(DB$2)=INT($G5),($J5),(0)) -> 0 | DC5: =IF(INT(DC$2)=INT($G5),($J5),(0))*$T5^DC$2 -> 0 | DD5: =IF(INT(DD$2)=INT($G5),($J5),(0)) -> 0 | DE5: =IF(INT(DE$2)=INT($G5),($J5),(0))*$T5^DE$2 -> 0 | DF5: =IF(INT(DF$2)=INT($G5),($J5),(0)) -> 0 | DG5: =IF(INT(DG$2)=INT($G5),($J5),(0))*$T5^DG$2 -> 0 | DH5: =IF(INT(DH$2)=INT($G5),($J5),(0)) -> 0 | DI5: =IF(INT(DI$2)=INT($G5),($J5),(0))*$T5^DI$2 -> 0 | DJ5: =IF(INT(DJ$2)=INT($G5),($J5),(0)) -> 0 | DK5: =IF(INT(DK$2)=INT($G5),($J5),(0))*$T5^DK$2 -> 0 | DL5: =IF(INT(DL$2)=INT($G5),($J5),(0)) -> 0 | DM5: =IF(INT(DM$2)=INT($G5),($J5),(0))*$T5^DM$2 -> 0 | DN5: =IF(INT(DN$2)=INT($G5),($J5),(0)) -> 0 | DO5: =IF(INT(DO$2)=INT($G5),($J5),(0))*$T5^DO$2 -> 0 | DP5: =IF(INT(DP$2)=INT($G5),($J5),(0)) -> 0 | DQ5: =IF(INT(DQ$2)=INT($G5),($J5),(0))*$T5^DQ$2 -> 0 | DR5: =IF(INT(DR$2)=INT($G5),($J5),(0)) -> 0 | DS5: =IF(INT(DS$2)=INT($G5),($J5),(0))*$T5^DS$2 -> 0 | DT5: =IF(INT(DT$2)=INT($G5),($J5),(0)) -> 0 | DU5: =IF(INT(DU$2)=INT($G5),($J5),(0))*$T5^DU$2 -> 0 | DV5: =IF(INT(DV$2)=INT($G5),($J5),(0)) -> 0 | DW5: =IF(INT(DW$2)=INT($G5),($J5),(0))*$T5^DW$2 -> 0 | DX5: =IF(INT(DX$2)=INT($G5),($J5),(0)) -> 0 | DY5: =IF(INT(DY$2)=INT($G5),($J5),(0))*$T5^DY$2 -> 0 | DZ5: =IF(INT(DZ$2)=INT($G5),($J5),(0)) -> 0 | EA5: =IF(INT(EA$2)=INT($G5),($J5),(0))*$T5^EA$2 -> 0 | EB5: =IF(INT(EB$2)=INT($G5),($J5),(0)) -> 0 | EC5: =IF(INT(EC$2)=INT($G5),($J5),(0))*$T5^EC$2 -> 0 | ED5: =IF(INT(ED$2)=INT($G5),($J5),(0)) -> 0 | EE5: =IF(INT(EE$2)=INT($G5),($J5),(0))*$T5^EE$2 -> 0 | EF5: =IF(INT(EF$2)=INT($G5),($J5),(0)) -> 0 | EG5: =IF(INT(EG$2)=INT($G5),($J5),(0))*$T5^EG$2 -> 0 | EH5: =IF(INT(EH$2)=INT($G5),($J5),(0)) -> 0 | EI5: =IF(INT(EI$2)=INT($G5),($J5),(0))*$T5^EI$2 -> 0 | EJ5: =IF(INT(EJ$2)=INT($G5),($J5),(0)) -> 0 | EK5: =IF(INT(EK$2)=INT($G5),($J5),(0))*$T5^EK$2 -> 0
A6: 5.2 | B6: Demolitions
A7: 5.2 | C7: State client requirements, standards required, working restrictions and procurement context | Q7: =((1/U7^$W$2)*W7)+((1/U7^$Y$2)*Y7)+((1/U7^$AA$2)*AA7)+((1/U7^$AC$2)*AC7)+((1/U7^$AE$2)*AE7)+((1/U7^$AG$2)*AG7)+((1/U7^$AI$2)*AI7)+((1/U7^$AK$2)*AK7)+((1/U7^$AM$2)*AM7)+((1/U7^$AO$2)*AO7)+((1/U7^$AQ$2)*AQ7)+((1/U7^$AS$2)*AS7)+((1/U7^$AU$2)*AU7)+((1/U7^$AW$2)*AW7)+((1/U7^$AY$2)*AY7)+((1/U7^$BA$2)*BA7)+((1/U7^$BC$2)*BC7)+((1/U7^$BE$2)*BE7)+((1/U7^$BG$2)*BG7)+((1/U7^$BI$2)*BI7)+((1/U7^$BK$2)*BK7)+((1/U7^$BM$2)*BM7)+((1/U7^$BO$2)*BO7)+((1/U7^$BQ$2)*BQ7)+((1/U7^$BS$2)*BS7)+((1/U7^$BU$2)*BU7)+((1/U7^$BW$2)*BW7)+((1/U7^$BY$2)*BY7)+((1/U7^$CA$2)*CA7)+((1/U7^$CC$2)*CC7)+((1/U7^$CE$2)*CE7)+((1/U7^$CG$2)*CG7)+((1/U7^$CI$2)*CI7)+((1/U7^$CK$2)*CK7)+((1/U7^$CM$2)*CM7)+((1/U7^$CO$2)*CO7)+((1/U7^$CQ$2)*CQ7)+((1/U7^$CS$2)*CS7)+((1/U7^$CU$2)*CU7)+((1/U7^$CW$2)*CW7)+((1/U7^$CY$2)*CY7)+((1/U7^$DA$2)*DA7)+((1/U7^$DC$2)*DC7)+((1/U7^$DE$2)*DE7)+((1/U7^$DG$2)*DG7)+((1/U7^$DI$2)*DI7)+((1/U7^$DK$2)*DK7)+((1/U7^$DM$2)*DM7)+((1/U7^$DO$2)*DO7)+((1/U7^$DQ$2)*DQ7)+((1/U7^$DS$2)*DS7)+((1/U7^$DU$2)*DU7)+((1/U7^$DW$2)*DW7)+((1/U7^$DY$2)*DY7)+((1/U7^$EA$2)*EA7)+((1/U7^$EC$2)*EC7)+((1/U7^$EE$2)*EE7)+((1/U7^$EG$2)*EG7)+((1/U7^$EI$2)*EI7)+(1/U7^$EK$2)*EK7 -> 0 | S7: =((1+M7)/(1+O7)) -> 1 | T7: =1+M7 -> 1 | U7: =(1+O7) -> 1 | V7: =IF(INT(V$2)=INT($G7),($J7),(0)) -> 0 | W7: =IF(INT(W$2)=INT($G7),($J7),(0))*$T7^W$2 -> 0 | X7: =IF(INT(X$2)=INT($G7),($J7),(0)) -> 0 | Y7: =IF(INT(Y$2)=INT($G7),($J7),(0))*$T7^Y$2 -> 0 | Z7: =IF(INT(Z$2)=INT($G7),($J7),(0)) -> 0 | AA7: =IF(INT(AA$2)=INT($G7),($J7),(0))*$T7^AA$2 -> 0 | AB7: =IF(INT(AB$2)=INT($G7),($J7),(0)) -> 0 | AC7: =IF(INT(AC$2)=INT($G7),($J7),(0))*$T7^AC$2 -> 0 | AD7: =IF(INT(AD$2)=INT($G7),($J7),(0)) -> 0 | AE7: =IF(INT(AE$2)=INT($G7),($J7),(0))*$T7^AE$2 -> 0 | AF7: =IF(INT(AF$2)=INT($G7),($J7),(0)) -> 0 | AG7: =IF(INT(AG$2)=INT($G7),($J7),(0))*$T7^AG$2 -> 0 | AH7: =IF(INT(AH$2)=INT($G7),($J7),(0)) -> 0 | AI7: =IF(INT(AI$2)=INT($G7),($J7),(0))*$T7^AI$2 -> 0 | AJ7: =IF(INT(AJ$2)=INT($G7),($J7),(0)) -> 0 | AK7: =IF(INT(AK$2)=INT($G7),($J7),(0))*$T7^AK$2 -> 0 | AL7: =IF(INT(AL$2)=INT($G7),($J7),(0)) -> 0 | AM7: =IF(INT(AM$2)=INT($G7),($J7),(0))*$T7^AM$2 -> 0 | AN7: =IF(INT(AN$2)=INT($G7),($J7),(0)) -> 0 | AO7: =IF(INT(AO$2)=INT($G7),($J7),(0))*$T7^AO$2 -> 0 | AP7: =IF(INT(AP$2)=INT($G7),($J7),(0)) -> 0 | AQ7: =IF(INT(AQ$2)=INT($G7),($J7),(0))*$T7^AQ$2 -> 0 | AR7: =IF(INT(AR$2)=INT($G7),($J7),(0)) -> 0 | AS7: =IF(INT(AS$2)=INT($G7),($J7),(0))*$T7^AS$2 -> 0 | AT7: =IF(INT(AT$2)=INT($G7),($J7),(0)) -> 0 | AU7: =IF(INT(AU$2)=INT($G7),($J7),(0))*$T7^AU$2 -> 0 | AV7: =IF(INT(AV$2)=INT($G7),($J7),(0)) -> 0 | AW7: =IF(INT(AW$2)=INT($G7),($J7),(0))*$T7^AW$2 -> 0 | AX7: =IF(INT(AX$2)=INT($G7),($J7),(0)) -> 0 | AY7: =IF(INT(AY$2)=INT($G7),($J7),(0))*$T7^AY$2 -> 0 | AZ7: =IF(INT(AZ$2)=INT($G7),($J7),(0)) -> 0 | BA7: =IF(INT(BA$2)=INT($G7),($J7),(0))*$T7^BA$2 -> 0 | BB7: =IF(INT(BB$2)=INT($G7),($J7),(0)) -> 0 | BC7: =IF(INT(BC$2)=INT($G7),($J7),(0))*$T7^BC$2 -> 0 | BD7: =IF(INT(BD$2)=INT($G7),($J7),(0)) -> 0 | BE7: =IF(INT(BE$2)=INT($G7),($J7),(0))*$T7^BE$2 -> 0 | BF7: =IF(INT(BF$2)=INT($G7),($J7),(0)) -> 0 | BG7: =IF(INT(BG$2)=INT($G7),($J7),(0))*$T7^BG$2 -> 0 | BH7: =IF(INT(BH$2)=INT($G7),($J7),(0)) -> 0 | BI7: =IF(INT(BI$2)=INT($G7),($J7),(0))*$T7^BI$2 -> 0 | BJ7: =IF(INT(BJ$2)=INT($G7),($J7),(0)) -> 0 | BK7: =IF(INT(BK$2)=INT($G7),($J7),(0))*$T7^BK$2 -> 0 | BL7: =IF(INT(BL$2)=INT($G7),($J7),(0)) -> 0 | BM7: =IF(INT(BM$2)=INT($G7),($J7),(0))*$T7^BM$2 -> 0 | BN7: =IF(INT(BN$2)=INT($G7),($J7),(0)) -> 0 | BO7: =IF(INT(BO$2)=INT($G7),($J7),(0))*$T7^BO$2 -> 0 | BP7: =IF(INT(BP$2)=INT($G7),($J7),(0)) -> 0 | BQ7: =IF(INT(BQ$2)=INT($G7),($J7),(0))*$T7^BQ$2 -> 0 | BR7: =IF(INT(BR$2)=INT($G7),($J7),(0)) -> 0 | BS7: =IF(INT(BS$2)=INT($G7),($J7),(0))*$T7^BS$2 -> 0 | BT7: =IF(INT(BT$2)=INT($G7),($J7),(0)) -> 0 | BU7: =IF(INT(BU$2)=INT($G7),($J7),(0))*$T7^BU$2 -> 0 | BV7: =IF(INT(BV$2)=INT($G7),($J7),(0)) -> 0 | BW7: =IF(INT(BW$2)=INT($G7),($J7),(0))*$T7^BW$2 -> 0 | BX7: =IF(INT(BX$2)=INT($G7),($J7),(0)) -> 0 | BY7: =IF(INT(BY$2)=INT($G7),($J7),(0))*$T7^BY$2 -> 0 | BZ7: =IF(INT(BZ$2)=INT($G7),($J7),(0)) -> 0 | CA7: =IF(INT(CA$2)=INT($G7),($J7),(0))*$T7^CA$2 -> 0 | CB7: =IF(INT(CB$2)=INT($G7),($J7),(0)) -> 0 | CC7: =IF(INT(CC$2)=INT($G7),($J7),(0))*$T7^CC$2 -> 0 | CD7: =IF(INT(CD$2)=INT($G7),($J7),(0)) -> 0 | CE7: =IF(INT(CE$2)=INT($G7),($J7),(0))*$T7^CE$2 -> 0 | CF7: =IF(INT(CF$2)=INT($G7),($J7),(0)) -> 0 | CG7: =IF(INT(CG$2)=INT($G7),($J7),(0))*$T7^CG$2 -> 0 | CH7: =IF(INT(CH$2)=INT($G7),($J7),(0)) -> 0 | CI7: =IF(INT(CI$2)=INT($G7),($J7),(0))*$T7^CI$2 -> 0 | CJ7: =IF(INT(CJ$2)=INT($G7),($J7),(0)) -> 0 | CK7: =IF(INT(CK$2)=INT($G7),($J7),(0))*$T7^CK$2 -> 0 | CL7: =IF(INT(CL$2)=INT($G7),($J7),(0)) -> 0 | CM7: =IF(INT(CM$2)=INT($G7),($J7),(0))*$T7^CM$2 -> 0 | CN7: =IF(INT(CN$2)=INT($G7),($J7),(0)) -> 0 | CO7: =IF(INT(CO$2)=INT($G7),($J7),(0))*$T7^CO$2 -> 0 | CP7: =IF(INT(CP$2)=INT($G7),($J7),(0)) -> 0 | CQ7: =IF(INT(CQ$2)=INT($G7),($J7),(0))*$T7^CQ$2 -> 0 | CR7: =IF(INT(CR$2)=INT($G7),($J7),(0)) -> 0 | CS7: =IF(INT(CS$2)=INT($G7),($J7),(0))*$T7^CS$2 -> 0 | CT7: =IF(INT(CT$2)=INT($G7),($J7),(0)) -> 0 | CU7: =IF(INT(CU$2)=INT($G7),($J7),(0))*$T7^CU$2 -> 0 | CV7: =IF(INT(CV$2)=INT($G7),($J7),(0)) -> 0 | CW7: =IF(INT(CW$2)=INT($G7),($J7),(0))*$T7^CW$2 -> 0 | CX7: =IF(INT(CX$2)=INT($G7),($J7),(0)) -> 0 | CY7: =IF(INT(CY$2)=INT($G7),($J7),(0))*$T7^CY$2 -> 0 | CZ7: =IF(INT(CZ$2)=INT($G7),($J7),(0)) -> 0 | DA7: =IF(INT(DA$2)=INT($G7),($J7),(0))*$T7^DA$2 -> 0 | DB7: =IF(INT(DB$2)=INT($G7),($J7),(0)) -> 0 | DC7: =IF(INT(DC$2)=INT($G7),($J7),(0))*$T7^DC$2 -> 0 | DD7: =IF(INT(DD$2)=INT($G7),($J7),(0)) -> 0 | DE7: =IF(INT(DE$2)=INT($G7),($J7),(0))*$T7^DE$2 -> 0 | DF7: =IF(INT(DF$2)=INT($G7),($J7),(0)) -> 0 | DG7: =IF(INT(DG$2)=INT($G7),($J7),(0))*$T7^DG$2 -> 0 | DH7: =IF(INT(DH$2)=INT($G7),($J7),(0)) -> 0 | DI7: =IF(INT(DI$2)=INT($G7),($J7),(0))*$T7^DI$2 -> 0 | DJ7: =IF(INT(DJ$2)=INT($G7),($J7),(0)) -> 0 | DK7: =IF(INT(DK$2)=INT($G7),($J7),(0))*$T7^DK$2 -> 0 | DL7: =IF(INT(DL$2)=INT($G7),($J7),(0)) -> 0 | DM7: =IF(INT(DM$2)=INT($G7),($J7),(0))*$T7^DM$2 -> 0 | DN7: =IF(INT(DN$2)=INT($G7),($J7),(0)) -> 0 | DO7: =IF(INT(DO$2)=INT($G7),($J7),(0))*$T7^DO$2 -> 0 | DP7: =IF(INT(DP$2)=INT($G7),($J7),(0)) -> 0 | DQ7: =IF(INT(DQ$2)=INT($G7),($J7),(0))*$T7^DQ$2 -> 0 | DR7: =IF(INT(DR$2)=INT($G7),($J7),(0)) -> 0 | DS7: =IF(INT(DS$2)=INT($G7),($J7),(0))*$T7^DS$2 -> 0 | DT7: =IF(INT(DT$2)=INT($G7),($J7),(0)) -> 0 | DU7: =IF(INT(DU$2)=INT($G7),($J7),(0))*$T7^DU$2 -> 0 | DV7: =IF(INT(DV$2)=INT($G7),($J7),(0)) -> 0 | DW7: =IF(INT(DW$2)=INT($G7),($J7),(0))*$T7^DW$2 -> 0 | DX7: =IF(INT(DX$2)=INT($G7),($J7),(0)) -> 0 | DY7: =IF(INT(DY$2)=INT($G7),($J7),(0))*$T7^DY$2 -> 0 | DZ7: =IF(INT(DZ$2)=INT($G7),($J7),(0)) -> 0 | EA7: =IF(INT(EA$2)=INT($G7),($J7),(0))*$T7^EA$2 -> 0 | EB7: =IF(INT(EB$2)=INT($G7),($J7),(0)) -> 0 | EC7: =IF(INT(EC$2)=INT($G7),($J7),(0))*$T7^EC$2 -> 0 | ED7: =IF(INT(ED$2)=INT($G7),($J7),(0)) -> 0 | EE7: =IF(INT(EE$2)=INT($G7),($J7),(0))*$T7^EE$2 -> 0 | EF7: =IF(INT(EF$2)=INT($G7),($J7),(0)) -> 0 | EG7: =IF(INT(EG$2)=INT($G7),($J7),(0))*$T7^EG$2 -> 0 | EH7: =IF(INT(EH$2)=INT($G7),($J7),(0)) -> 0 | EI7: =IF(INT(EI$2)=INT($G7),($J7),(0))*$T7^EI$2 -> 0 | EJ7: =IF(INT(EJ$2)=INT($G7),($J7),(0)) -> 0 | EK7: =IF(INT(EK$2)=INT($G7),($J7),(0))*$T7^EK$2 -> 0
A8: 5.3 | B8: Reinstatement costs
A9: 5.3 | C9: State client requirements, standards required, working restrictions and procurement context | Q9: =((1/U9^$W$2)*W9)+((1/U9^$Y$2)*Y9)+((1/U9^$AA$2)*AA9)+((1/U9^$AC$2)*AC9)+((1/U9^$AE$2)*AE9)+((1/U9^$AG$2)*AG9)+((1/U9^$AI$2)*AI9)+((1/U9^$AK$2)*AK9)+((1/U9^$AM$2)*AM9)+((1/U9^$AO$2)*AO9)+((1/U9^$AQ$2)*AQ9)+((1/U9^$AS$2)*AS9)+((1/U9^$AU$2)*AU9)+((1/U9^$AW$2)*AW9)+((1/U9^$AY$2)*AY9)+((1/U9^$BA$2)*BA9)+((1/U9^$BC$2)*BC9)+((1/U9^$BE$2)*BE9)+((1/U9^$BG$2)*BG9)+((1/U9^$BI$2)*BI9)+((1/U9^$BK$2)*BK9)+((1/U9^$BM$2)*BM9)+((1/U9^$BO$2)*BO9)+((1/U9^$BQ$2)*BQ9)+((1/U9^$BS$2)*BS9)+((1/U9^$BU$2)*BU9)+((1/U9^$BW$2)*BW9)+((1/U9^$BY$2)*BY9)+((1/U9^$CA$2)*CA9)+((1/U9^$CC$2)*CC9)+((1/U9^$CE$2)*CE9)+((1/U9^$CG$2)*CG9)+((1/U9^$CI$2)*CI9)+((1/U9^$CK$2)*CK9)+((1/U9^$CM$2)*CM9)+((1/U9^$CO$2)*CO9)+((1/U9^$CQ$2)*CQ9)+((1/U9^$CS$2)*CS9)+((1/U9^$CU$2)*CU9)+((1/U9^$CW$2)*CW9)+((1/U9^$CY$2)*CY9)+((1/U9^$DA$2)*DA9)+((1/U9^$DC$2)*DC9)+((1/U9^$DE$2)*DE9)+((1/U9^$DG$2)*DG9)+((1/U9^$DI$2)*DI9)+((1/U9^$DK$2)*DK9)+((1/U9^$DM$2)*DM9)+((1/U9^$DO$2)*DO9)+((1/U9^$DQ$2)*DQ9)+((1/U9^$DS$2)*DS9)+((1/U9^$DU$2)*DU9)+((1/U9^$DW$2)*DW9)+((1/U9^$DY$2)*DY9)+((1/U9^$EA$2)*EA9)+((1/U9^$EC$2)*EC9)+((1/U9^$EE$2)*EE9)+((1/U9^$EG$2)*EG9)+((1/U9^$EI$2)*EI9)+(1/U9^$EK$2)*EK9 -> 0 | S9: =((1+M9)/(1+O9)) -> 1 | T9: =1+M9 -> 1 | U9: =(1+O9) -> 1 | V9: =IF(INT(V$2)=INT($G9),($J9),(0)) -> 0 | W9: =IF(INT(W$2)=INT($G9),($J9),(0))*$T9^W$2 -> 0 | X9: =IF(INT(X$2)=INT($G9),($J9),(0)) -> 0 | Y9: =IF(INT(Y$2)=INT($G9),($J9),(0))*$T9^Y$2 -> 0 | Z9: =IF(INT(Z$2)=INT($G9),($J9),(0)) -> 0 | AA9: =IF(INT(AA$2)=INT($G9),($J9),(0))*$T9^AA$2 -> 0 | AB9: =IF(INT(AB$2)=INT($G9),($J9),(0)) -> 0 | AC9: =IF(INT(AC$2)=INT($G9),($J9),(0))*$T9^AC$2 -> 0 | AD9: =IF(INT(AD$2)=INT($G9),($J9),(0)) -> 0 | AE9: =IF(INT(AE$2)=INT($G9),($J9),(0))*$T9^AE$2 -> 0 | AF9: =IF(INT(AF$2)=INT($G9),($J9),(0)) -> 0 | AG9: =IF(INT(AG$2)=INT($G9),($J9),(0))*$T9^AG$2 -> 0 | AH9: =IF(INT(AH$2)=INT($G9),($J9),(0)) -> 0 | AI9: =IF(INT(AI$2)=INT($G9),($J9),(0))*$T9^AI$2 -> 0 | AJ9: =IF(INT(AJ$2)=INT($G9),($J9),(0)) -> 0 | AK9: =IF(INT(AK$2)=INT($G9),($J9),(0))*$T9^AK$2 -> 0 | AL9: =IF(INT(AL$2)=INT($G9),($J9),(0)) -> 0 | AM9: =IF(INT(AM$2)=INT($G9),($J9),(0))*$T9^AM$2 -> 0 | AN9: =IF(INT(AN$2)=INT($G9),($J9),(0)) -> 0 | AO9: =IF(INT(AO$2)=INT($G9),($J9),(0))*$T9^AO$2 -> 0 | AP9: =IF(INT(AP$2)=INT($G9),($J9),(0)) -> 0 | AQ9: =IF(INT(AQ$2)=INT($G9),($J9),(0))*$T9^AQ$2 -> 0 | AR9: =IF(INT(AR$2)=INT($G9),($J9),(0)) -> 0 | AS9: =IF(INT(AS$2)=INT($G9),($J9),(0))*$T9^AS$2 -> 0 | AT9: =IF(INT(AT$2)=INT($G9),($J9),(0)) -> 0 | AU9: =IF(INT(AU$2)=INT($G9),($J9),(0))*$T9^AU$2 -> 0 | AV9: =IF(INT(AV$2)=INT($G9),($J9),(0)) -> 0 | AW9: =IF(INT(AW$2)=INT($G9),($J9),(0))*$T9^AW$2 -> 0 | AX9: =IF(INT(AX$2)=INT($G9),($J9),(0)) -> 0 | AY9: =IF(INT(AY$2)=INT($G9),($J9),(0))*$T9^AY$2 -> 0 | AZ9: =IF(INT(AZ$2)=INT($G9),($J9),(0)) -> 0 | BA9: =IF(INT(BA$2)=INT($G9),($J9),(0))*$T9^BA$2 -> 0 | BB9: =IF(INT(BB$2)=INT($G9),($J9),(0)) -> 0 | BC9: =IF(INT(BC$2)=INT($G9),($J9),(0))*$T9^BC$2 -> 0 | BD9: =IF(INT(BD$2)=INT($G9),($J9),(0)) -> 0 | BE9: =IF(INT(BE$2)=INT($G9),($J9),(0))*$T9^BE$2 -> 0 | BF9: =IF(INT(BF$2)=INT($G9),($J9),(0)) -> 0 | BG9: =IF(INT(BG$2)=INT($G9),($J9),(0))*$T9^BG$2 -> 0 | BH9: =IF(INT(BH$2)=INT($G9),($J9),(0)) -> 0 | BI9: =IF(INT(BI$2)=INT($G9),($J9),(0))*$T9^BI$2 -> 0 | BJ9: =IF(INT(BJ$2)=INT($G9),($J9),(0)) -> 0 | BK9: =IF(INT(BK$2)=INT($G9),($J9),(0))*$T9^BK$2 -> 0 | BL9: =IF(INT(BL$2)=INT($G9),($J9),(0)) -> 0 | BM9: =IF(INT(BM$2)=INT($G9),($J9),(0))*$T9^BM$2 -> 0 | BN9: =IF(INT(BN$2)=INT($G9),($J9),(0)) -> 0 | BO9: =IF(INT(BO$2)=INT($G9),($J9),(0))*$T9^BO$2 -> 0 | BP9: =IF(INT(BP$2)=INT($G9),($J9),(0)) -> 0 | BQ9: =IF(INT(BQ$2)=INT($G9),($J9),(0))*$T9^BQ$2 -> 0 | BR9: =IF(INT(BR$2)=INT($G9),($J9),(0)) -> 0 | BS9: =IF(INT(BS$2)=INT($G9),($J9),(0))*$T9^BS$2 -> 0 | BT9: =IF(INT(BT$2)=INT($G9),($J9),(0)) -> 0 | BU9: =IF(INT(BU$2)=INT($G9),($J9),(0))*$T9^BU$2 -> 0 | BV9: =IF(INT(BV$2)=INT($G9),($J9),(0)) -> 0 | BW9: =IF(INT(BW$2)=INT($G9),($J9),(0))*$T9^BW$2 -> 0 | BX9: =IF(INT(BX$2)=INT($G9),($J9),(0)) -> 0 | BY9: =IF(INT(BY$2)=INT($G9),($J9),(0))*$T9^BY$2 -> 0 | BZ9: =IF(INT(BZ$2)=INT($G9),($J9),(0)) -> 0 | CA9: =IF(INT(CA$2)=INT($G9),($J9),(0))*$T9^CA$2 -> 0 | CB9: =IF(INT(CB$2)=INT($G9),($J9),(0)) -> 0 | CC9: =IF(INT(CC$2)=INT($G9),($J9),(0))*$T9^CC$2 -> 0 | CD9: =IF(INT(CD$2)=INT($G9),($J9),(0)) -> 0 | CE9: =IF(INT(CE$2)=INT($G9),($J9),(0))*$T9^CE$2 -> 0 | CF9: =IF(INT(CF$2)=INT($G9),($J9),(0)) -> 0 | CG9: =IF(INT(CG$2)=INT($G9),($J9),(0))*$T9^CG$2 -> 0 | CH9: =IF(INT(CH$2)=INT($G9),($J9),(0)) -> 0 | CI9: =IF(INT(CI$2)=INT($G9),($J9),(0))*$T9^CI$2 -> 0 | CJ9: =IF(INT(CJ$2)=INT($G9),($J9),(0)) -> 0 | CK9: =IF(INT(CK$2)=INT($G9),($J9),(0))*$T9^CK$2 -> 0 | CL9: =IF(INT(CL$2)=INT($G9),($J9),(0)) -> 0 | CM9: =IF(INT(CM$2)=INT($G9),($J9),(0))*$T9^CM$2 -> 0 | CN9: =IF(INT(CN$2)=INT($G9),($J9),(0)) -> 0 | CO9: =IF(INT(CO$2)=INT($G9),($J9),(0))*$T9^CO$2 -> 0 | CP9: =IF(INT(CP$2)=INT($G9),($J9),(0)) -> 0 | CQ9: =IF(INT(CQ$2)=INT($G9),($J9),(0))*$T9^CQ$2 -> 0 | CR9: =IF(INT(CR$2)=INT($G9),($J9),(0)) -> 0 | CS9: =IF(INT(CS$2)=INT($G9),($J9),(0))*$T9^CS$2 -> 0 | CT9: =IF(INT(CT$2)=INT($G9),($J9),(0)) -> 0 | CU9: =IF(INT(CU$2)=INT($G9),($J9),(0))*$T9^CU$2 -> 0 | CV9: =IF(INT(CV$2)=INT($G9),($J9),(0)) -> 0 | CW9: =IF(INT(CW$2)=INT($G9),($J9),(0))*$T9^CW$2 -> 0 | CX9: =IF(INT(CX$2)=INT($G9),($J9),(0)) -> 0 | CY9: =IF(INT(CY$2)=INT($G9),($J9),(0))*$T9^CY$2 -> 0 | CZ9: =IF(INT(CZ$2)=INT($G9),($J9),(0)) -> 0 | DA9: =IF(INT(DA$2)=INT($G9),($J9),(0))*$T9^DA$2 -> 0 | DB9: =IF(INT(DB$2)=INT($G9),($J9),(0)) -> 0 | DC9: =IF(INT(DC$2)=INT($G9),($J9),(0))*$T9^DC$2 -> 0 | DD9: =IF(INT(DD$2)=INT($G9),($J9),(0)) -> 0 | DE9: =IF(INT(DE$2)=INT($G9),($J9),(0))*$T9^DE$2 -> 0 | DF9: =IF(INT(DF$2)=INT($G9),($J9),(0)) -> 0 | DG9: =IF(INT(DG$2)=INT($G9),($J9),(0))*$T9^DG$2 -> 0 | DH9: =IF(INT(DH$2)=INT($G9),($J9),(0)) -> 0 | DI9: =IF(INT(DI$2)=INT($G9),($J9),(0))*$T9^DI$2 -> 0 | DJ9: =IF(INT(DJ$2)=INT($G9),($J9),(0)) -> 0 | DK9: =IF(INT(DK$2)=INT($G9),($J9),(0))*$T9^DK$2 -> 0 | DL9: =IF(INT(DL$2)=INT($G9),($J9),(0)) -> 0 | DM9: =IF(INT(DM$2)=INT($G9),($J9),(0))*$T9^DM$2 -> 0 | DN9: =IF(INT(DN$2)=INT($G9),($J9),(0)) -> 0 | DO9: =IF(INT(DO$2)=INT($G9),($J9),(0))*$T9^DO$2 -> 0 | DP9: =IF(INT(DP$2)=INT($G9),($J9),(0)) -> 0 | DQ9: =IF(INT(DQ$2)=INT($G9),($J9),(0))*$T9^DQ$2 -> 0 | DR9: =IF(INT(DR$2)=INT($G9),($J9),(0)) -> 0 | DS9: =IF(INT(DS$2)=INT($G9),($J9),(0))*$T9^DS$2 -> 0 | DT9: =IF(INT(DT$2)=INT($G9),($J9),(0)) -> 0 | DU9: =IF(INT(DU$2)=INT($G9),($J9),(0))*$T9^DU$2 -> 0 | DV9: =IF(INT(DV$2)=INT($G9),($J9),(0)) -> 0 | DW9: =IF(INT(DW$2)=INT($G9),($J9),(0))*$T9^DW$2 -> 0 | DX9: =IF(INT(DX$2)=INT($G9),($J9),(0)) -> 0 | DY9: =IF(INT(DY$2)=INT($G9),($J9),(0))*$T9^DY$2 -> 0 | DZ9: =IF(INT(DZ$2)=INT($G9),($J9),(0)) -> 0 | EA9: =IF(INT(EA$2)=INT($G9),($J9),(0))*$T9^EA$2 -> 0 | EB9: =IF(INT(EB$2)=INT($G9),($J9),(0)) -> 0 | EC9: =IF(INT(EC$2)=INT($G9),($J9),(0))*$T9^EC$2 -> 0 | ED9: =IF(INT(ED$2)=INT($G9),($J9),(0)) -> 0 | EE9: =IF(INT(EE$2)=INT($G9),($J9),(0))*$T9^EE$2 -> 0 | EF9: =IF(INT(EF$2)=INT($G9),($J9),(0)) -> 0 | EG9: =IF(INT(EG$2)=INT($G9),($J9),(0))*$T9^EG$2 -> 0 | EH9: =IF(INT(EH$2)=INT($G9),($J9),(0)) -> 0 | EI9: =IF(INT(EI$2)=INT($G9),($J9),(0))*$T9^EI$2 -> 0 | EJ9: =IF(INT(EJ$2)=INT($G9),($J9),(0)) -> 0 | EK9: =IF(INT(EK$2)=INT($G9),($J9),(0))*$T9^EK$2 -> 0
A10: 5.4 | B10: Salavge costs
A11: 5.4 | C11: State client requirements, standards required, working restrictions and procurement context | Q11: =((1/U11^$W$2)*W11)+((1/U11^$Y$2)*Y11)+((1/U11^$AA$2)*AA11)+((1/U11^$AC$2)*AC11)+((1/U11^$AE$2)*AE11)+((1/U11^$AG$2)*AG11)+((1/U11^$AI$2)*AI11)+((1/U11^$AK$2)*AK11)+((1/U11^$AM$2)*AM11)+((1/U11^$AO$2)*AO11)+((1/U11^$AQ$2)*AQ11)+((1/U11^$AS$2)*AS11)+((1/U11^$AU$2)*AU11)+((1/U11^$AW$2)*AW11)+((1/U11^$AY$2)*AY11)+((1/U11^$BA$2)*BA11)+((1/U11^$BC$2)*BC11)+((1/U11^$BE$2)*BE11)+((1/U11^$BG$2)*BG11)+((1/U11^$BI$2)*BI11)+((1/U11^$BK$2)*BK11)+((1/U11^$BM$2)*BM11)+((1/U11^$BO$2)*BO11)+((1/U11^$BQ$2)*BQ11)+((1/U11^$BS$2)*BS11)+((1/U11^$BU$2)*BU11)+((1/U11^$BW$2)*BW11)+((1/U11^$BY$2)*BY11)+((1/U11^$CA$2)*CA11)+((1/U11^$CC$2)*CC11)+((1/U11^$CE$2)*CE11)+((1/U11^$CG$2)*CG11)+((1/U11^$CI$2)*CI11)+((1/U11^$CK$2)*CK11)+((1/U11^$CM$2)*CM11)+((1/U11^$CO$2)*CO11)+((1/U11^$CQ$2)*CQ11)+((1/U11^$CS$2)*CS11)+((1/U11^$CU$2)*CU11)+((1/U11^$CW$2)*CW11)+((1/U11^$CY$2)*CY11)+((1/U11^$DA$2)*DA11)+((1/U11^$DC$2)*DC11)+((1/U11^$DE$2)*DE11)+((1/U11^$DG$2)*DG11)+((1/U11^$DI$2)*DI11)+((1/U11^$DK$2)*DK11)+((1/U11^$DM$2)*DM11)+((1/U11^$DO$2)*DO11)+((1/U11^$DQ$2)*DQ11)+((1/U11^$DS$2)*DS11)+((1/U11^$DU$2)*DU11)+((1/U11^$DW$2)*DW11)+((1/U11^$DY$2)*DY11)+((1/U11^$EA$2)*EA11)+((1/U11^$EC$2)*EC11)+((1/U11^$EE$2)*EE11)+((1/U11^$EG$2)*EG11)+((1/U11^$EI$2)*EI11)+(1/U11^$EK$2)*EK11 -> 0 | S11: =((1+M11)/(1+O11)) -> 1 | T11: =1+M11 -> 1 | U11: =(1+O11) -> 1 | V11: =IF(INT(V$2)=INT($G11),($J11),(0)) -> 0 | W11: =IF(INT(W$2)=INT($G11),($J11),(0))*$T11^W$2 -> 0 | X11: =IF(INT(X$2)=INT($G11),($J11),(0)) -> 0 | Y11: =IF(INT(Y$2)=INT($G11),($J11),(0))*$T11^Y$2 -> 0 | Z11: =IF(INT(Z$2)=INT($G11),($J11),(0)) -> 0 | AA11: =IF(INT(AA$2)=INT($G11),($J11),(0))*$T11^AA$2 -> 0 | AB11: =IF(INT(AB$2)=INT($G11),($J11),(0)) -> 0 | AC11: =IF(INT(AC$2)=INT($G11),($J11),(0))*$T11^AC$2 -> 0 | AD11: =IF(INT(AD$2)=INT($G11),($J11),(0)) -> 0 | AE11: =IF(INT(AE$2)=INT($G11),($J11),(0))*$T11^AE$2 -> 0 | AF11: =IF(INT(AF$2)=INT($G11),($J11),(0)) -> 0 | AG11: =IF(INT(AG$2)=INT($G11),($J11),(0))*$T11^AG$2 -> 0 | AH11: =IF(INT(AH$2)=INT($G11),($J11),(0)) -> 0 | AI11: =IF(INT(AI$2)=INT($G11),($J11),(0))*$T11^AI$2 -> 0 | AJ11: =IF(INT(AJ$2)=INT($G11),($J11),(0)) -> 0 | AK11: =IF(INT(AK$2)=INT($G11),($J11),(0))*$T11^AK$2 -> 0 | AL11: =IF(INT(AL$2)=INT($G11),($J11),(0)) -> 0 | AM11: =IF(INT(AM$2)=INT($G11),($J11),(0))*$T11^AM$2 -> 0 | AN11: =IF(INT(AN$2)=INT($G11),($J11),(0)) -> 0 | AO11: =IF(INT(AO$2)=INT($G11),($J11),(0))*$T11^AO$2 -> 0 | AP11: =IF(INT(AP$2)=INT($G11),($J11),(0)) -> 0 | AQ11: =IF(INT(AQ$2)=INT($G11),($J11),(0))*$T11^AQ$2 -> 0 | AR11: =IF(INT(AR$2)=INT($G11),($J11),(0)) -> 0 | AS11: =IF(INT(AS$2)=INT($G11),($J11),(0))*$T11^AS$2 -> 0 | AT11: =IF(INT(AT$2)=INT($G11),($J11),(0)) -> 0 | AU11: =IF(INT(AU$2)=INT($G11),($J11),(0))*$T11^AU$2 -> 0 | AV11: =IF(INT(AV$2)=INT($G11),($J11),(0)) -> 0 | AW11: =IF(INT(AW$2)=INT($G11),($J11),(0))*$T11^AW$2 -> 0 | AX11: =IF(INT(AX$2)=INT($G11),($J11),(0)) -> 0 | AY11: =IF(INT(AY$2)=INT($G11),($J11),(0))*$T11^AY$2 -> 0 | AZ11: =IF(INT(AZ$2)=INT($G11),($J11),(0)) -> 0 | BA11: =IF(INT(BA$2)=INT($G11),($J11),(0))*$T11^BA$2 -> 0 | BB11: =IF(INT(BB$2)=INT($G11),($J11),(0)) -> 0 | BC11: =IF(INT(BC$2)=INT($G11),($J11),(0))*$T11^BC$2 -> 0 | BD11: =IF(INT(BD$2)=INT($G11),($J11),(0)) -> 0 | BE11: =IF(INT(BE$2)=INT($G11),($J11),(0))*$T11^BE$2 -> 0 | BF11: =IF(INT(BF$2)=INT($G11),($J11),(0)) -> 0 | BG11: =IF(INT(BG$2)=INT($G11),($J11),(0))*$T11^BG$2 -> 0 | BH11: =IF(INT(BH$2)=INT($G11),($J11),(0)) -> 0 | BI11: =IF(INT(BI$2)=INT($G11),($J11),(0))*$T11^BI$2 -> 0 | BJ11: =IF(INT(BJ$2)=INT($G11),($J11),(0)) -> 0 | BK11: =IF(INT(BK$2)=INT($G11),($J11),(0))*$T11^BK$2 -> 0 | BL11: =IF(INT(BL$2)=INT($G11),($J11),(0)) -> 0 | BM11: =IF(INT(BM$2)=INT($G11),($J11),(0))*$T11^BM$2 -> 0 | BN11: =IF(INT(BN$2)=INT($G11),($J11),(0)) -> 0 | BO11: =IF(INT(BO$2)=INT($G11),($J11),(0))*$T11^BO$2 -> 0 | BP11: =IF(INT(BP$2)=INT($G11),($J11),(0)) -> 0 | BQ11: =IF(INT(BQ$2)=INT($G11),($J11),(0))*$T11^BQ$2 -> 0 | BR11: =IF(INT(BR$2)=INT($G11),($J11),(0)) -> 0 | BS11: =IF(INT(BS$2)=INT($G11),($J11),(0))*$T11^BS$2 -> 0 | BT11: =IF(INT(BT$2)=INT($G11),($J11),(0)) -> 0 | BU11: =IF(INT(BU$2)=INT($G11),($J11),(0))*$T11^BU$2 -> 0 | BV11: =IF(INT(BV$2)=INT($G11),($J11),(0)) -> 0 | BW11: =IF(INT(BW$2)=INT($G11),($J11),(0))*$T11^BW$2 -> 0 | BX11: =IF(INT(BX$2)=INT($G11),($J11),(0)) -> 0 | BY11: =IF(INT(BY$2)=INT($G11),($J11),(0))*$T11^BY$2 -> 0 | BZ11: =IF(INT(BZ$2)=INT($G11),($J11),(0)) -> 0 | CA11: =IF(INT(CA$2)=INT($G11),($J11),(0))*$T11^CA$2 -> 0 | CB11: =IF(INT(CB$2)=INT($G11),($J11),(0)) -> 0 | CC11: =IF(INT(CC$2)=INT($G11),($J11),(0))*$T11^CC$2 -> 0 | CD11: =IF(INT(CD$2)=INT($G11),($J11),(0)) -> 0 | CE11: =IF(INT(CE$2)=INT($G11),($J11),(0))*$T11^CE$2 -> 0 | CF11: =IF(INT(CF$2)=INT($G11),($J11),(0)) -> 0 | CG11: =IF(INT(CG$2)=INT($G11),($J11),(0))*$T11^CG$2 -> 0 | CH11: =IF(INT(CH$2)=INT($G11),($J11),(0)) -> 0 | CI11: =IF(INT(CI$2)=INT($G11),($J11),(0))*$T11^CI$2 -> 0 | CJ11: =IF(INT(CJ$2)=INT($G11),($J11),(0)) -> 0 | CK11: =IF(INT(CK$2)=INT($G11),($J11),(0))*$T11^CK$2 -> 0 | CL11: =IF(INT(CL$2)=INT($G11),($J11),(0)) -> 0 | CM11: =IF(INT(CM$2)=INT($G11),($J11),(0))*$T11^CM$2 -> 0 | CN11: =IF(INT(CN$2)=INT($G11),($J11),(0)) -> 0 | CO11: =IF(INT(CO$2)=INT($G11),($J11),(0))*$T11^CO$2 -> 0 | CP11: =IF(INT(CP$2)=INT($G11),($J11),(0)) -> 0 | CQ11: =IF(INT(CQ$2)=INT($G11),($J11),(0))*$T11^CQ$2 -> 0 | CR11: =IF(INT(CR$2)=INT($G11),($J11),(0)) -> 0 | CS11: =IF(INT(CS$2)=INT($G11),($J11),(0))*$T11^CS$2 -> 0 | CT11: =IF(INT(CT$2)=INT($G11),($J11),(0)) -> 0 | CU11: =IF(INT(CU$2)=INT($G11),($J11),(0))*$T11^CU$2 -> 0 | CV11: =IF(INT(CV$2)=INT($G11),($J11),(0)) -> 0 | CW11: =IF(INT(CW$2)=INT($G11),($J11),(0))*$T11^CW$2 -> 0 | CX11: =IF(INT(CX$2)=INT($G11),($J11),(0)) -> 0 | CY11: =IF(INT(CY$2)=INT($G11),($J11),(0))*$T11^CY$2 -> 0 | CZ11: =IF(INT(CZ$2)=INT($G11),($J11),(0)) -> 0 | DA11: =IF(INT(DA$2)=INT($G11),($J11),(0))*$T11^DA$2 -> 0 | DB11: =IF(INT(DB$2)=INT($G11),($J11),(0)) -> 0 | DC11: =IF(INT(DC$2)=INT($G11),($J11),(0))*$T11^DC$2 -> 0 | DD11: =IF(INT(DD$2)=INT($G11),($J11),(0)) -> 0 | DE11: =IF(INT(DE$2)=INT($G11),($J11),(0))*$T11^DE$2 -> 0 | DF11: =IF(INT(DF$2)=INT($G11),($J11),(0)) -> 0 | DG11: =IF(INT(DG$2)=INT($G11),($J11),(0))*$T11^DG$2 -> 0 | DH11: =IF(INT(DH$2)=INT($G11),($J11),(0)) -> 0 | DI11: =IF(INT(DI$2)=INT($G11),($J11),(0))*$T11^DI$2 -> 0 | DJ11: =IF(INT(DJ$2)=INT($G11),($J11),(0)) -> 0 | DK11: =IF(INT(DK$2)=INT($G11),($J11),(0))*$T11^DK$2 -> 0 | DL11: =IF(INT(DL$2)=INT($G11),($J11),(0)) -> 0 | DM11: =IF(INT(DM$2)=INT($G11),($J11),(0))*$T11^DM$2 -> 0 | DN11: =IF(INT(DN$2)=INT($G11),($J11),(0)) -> 0 | DO11: =IF(INT(DO$2)=INT($G11),($J11),(0))*$T11^DO$2 -> 0 | DP11: =IF(INT(DP$2)=INT($G11),($J11),(0)) -> 0 | DQ11: =IF(INT(DQ$2)=INT($G11),($J11),(0))*$T11^DQ$2 -> 0 | DR11: =IF(INT(DR$2)=INT($G11),($J11),(0)) -> 0 | DS11: =IF(INT(DS$2)=INT($G11),($J11),(0))*$T11^DS$2 -> 0 | DT11: =IF(INT(DT$2)=INT($G11),($J11),(0)) -> 0 | DU11: =IF(INT(DU$2)=INT($G11),($J11),(0))*$T11^DU$2 -> 0 | DV11: =IF(INT(DV$2)=INT($G11),($J11),(0)) -> 0 | DW11: =IF(INT(DW$2)=INT($G11),($J11),(0))*$T11^DW$2 -> 0 | DX11: =IF(INT(DX$2)=INT($G11),($J11),(0)) -> 0 | DY11: =IF(INT(DY$2)=INT($G11),($J11),(0))*$T11^DY$2 -> 0 | DZ11: =IF(INT(DZ$2)=INT($G11),($J11),(0)) -> 0 | EA11: =IF(INT(EA$2)=INT($G11),($J11),(0))*$T11^EA$2 -> 0 | EB11: =IF(INT(EB$2)=INT($G11),($J11),(0)) -> 0 | EC11: =IF(INT(EC$2)=INT($G11),($J11),(0))*$T11^EC$2 -> 0 | ED11: =IF(INT(ED$2)=INT($G11),($J11),(0)) -> 0 | EE11: =IF(INT(EE$2)=INT($G11),($J11),(0))*$T11^EE$2 -> 0 | EF11: =IF(INT(EF$2)=INT($G11),($J11),(0)) -> 0 | EG11: =IF(INT(EG$2)=INT($G11),($J11),(0))*$T11^EG$2 -> 0 | EH11: =IF(INT(EH$2)=INT($G11),($J11),(0)) -> 0 | EI11: =IF(INT(EI$2)=INT($G11),($J11),(0))*$T11^EI$2 -> 0 | EJ11: =IF(INT(EJ$2)=INT($G11),($J11),(0)) -> 0 | EK11: =IF(INT(EK$2)=INT($G11),($J11),(0))*$T11^EK$2 -> 0
A12: 5.5 | B12: Client definable costs | EJ12: =IF(INT(EJ$2)=INT($G12),($J12),(0)) -> 0 | EK12: =IF(INT(EK$2)=INT($G12),($J12),(0))*$T12^EK$2 -> 0
C13: Total End of Life Costs | H13: =SUM(H5:H12) -> 0 | J13: =SUM(J5:J12) -> 0 | K13: =SUM(K5:K12) -> 0 | L13: =SUM(L5:L12) -> 0 | N13: =SUM(N5:N11) -> 0 | P13: =SUM(P5:P12) -> 0 | Q13: =SUM(Q5:Q12) -> 0 | V13: =SUM(V4:V12) -> 0 | W13: =SUM(W4:W12) -> 0 | X13: =SUM(X4:X12) -> 0 | Y13: =SUM(Y4:Y12) -> 0 | Z13: =SUM(Z4:Z12) -> 0 | AA13: =SUM(AA4:AA12) -> 0 | AB13: =SUM(AB4:AB12) -> 0 | AC13: =SUM(AC4:AC12) -> 0 | ... EK13: =SUM(EK4:EK12) -> 0
P23: =(1+J23) -> 1

Sheet AP5-Non Construction L2
A1: NCC | B1: Non Construction Costs Profile | F1: Years | G1: 60
A2: REF | B2: BCIS | C2: Description | D2: Qty | E2: Unit | F2: Rate | G2: Cost
A3: 6.0 | B3: Non Construction Costs
A4: 6.1 | B4: Land and enabling works
A5: 6.1 | C5: State client requirements, standards required, working restrictions and procurement context
A6: 6.2 | B6: Finance costs
A7: 6.2 | C7: State client requirements, standards required, working restrictions and procurement context
A8: 6.3 | B8: Rent costs
A9: 6.3 | C9: State client requirements, standards required, working restrictions and procurement context
A10: 6.4 | B10: Strategic estate management
A11: 6.4 | C11: State client requirements, standards required, working restrictions and procurement context
A12: 6.5 | B12: Space charges
A13: 6.5 | C13: State client requirements, standards required, working restrictions and procurement context
A14: 6.6 | B14: Taxes on costs
A15: 6.6 | C15: State client requirements, standards required, working restrictions and procurement context
A16: 6.7 | B16: Client definable costs
C17: Total Non Construction Costs | G17: =SUM(G4:G16) -> 0

Sheet AP6-Income L2 
A1: IN | B1: Income | J1: Years | L1: 60
A2: REF | B2: BCIS | C2: Description | D2: Qty | E2: Unit | F2: Rate | G2: Annual Income | H2: Life Cycle Income | I2: (e) | J2: Escaled Life Cycle Income | K2: (i) | L2: Acc. Present Value | N2: f | O2: f1 | P2: f2 | Q2: (n) | R2: Annual Amount
A3: 7.0 | B3: Income
A4: 7.1 | B4: Income from Sales
C5: State client requirements, standards required, working restrictions and procurement context | N5: =(1-((1+I5)/(1+K5))^Q5) -> 0 | O5: =(((1+K5)/(1+I5))-1) -> 0 | P5: =IF(N5=0,Q5,N5/O5) -> 60 | Q5: 60 | R5: =G5 -> 0
A6: 7.2 | B6: Third party income during occupation
C7: State client requirements, standards required, working restrictions and procurement context | N7: =(1-((1+I7)/(1+K7))^Q7) -> 0 | O7: =(((1+K7)/(1+I7))-1) -> 0 | P7: =IF(N7=0,Q7,N7/O7) -> 0
A8: 7.3 | B8: Taxes on income
C9: State client requirements, standards required, working restrictions and procurement context | N9: =(1-((1+I9)/(1+K9))^Q9) -> 0 | O9: =(((1+K9)/(1+I9))-1) -> 0 | P9: =IF(N9=0,Q9,N9/O9) -> 0
A10: 7.4 | B10: Loss of income
C11: State client requirements, standards required, working restrictions and procurement context | N11: =(1-((1+I11)/(1+K11))^Q11) -> 0 | O11: =(((1+K11)/(1+I11))-1) -> 0 | P11: =IF(N11=0,Q11,N11/O11) -> 0
A12: 7.5 | B12: Client definable costs
B13: Total Income | G13: =SUM(G4:G12) -> 0 | H13: =SUM(H4:H12) -> 0 | J13: =SUM(J4:J12) -> 0 | L13: =SUM(L4:L12) -> 0
