Workbook

Sheet School Budget (1)
A1: Fresh Fruit & Vegetable Program Projected Budget Tool for SY 2014-2015
A5: Instructions: The tool will determine your monthly budget based on your school's enrollment and the # of serving days per month.
A6: Step 1. Enter data into grey-colored cells in the "FFVP School Information" table.
A7: Step 2. Enter the "# of Serving Days per Month" for each month (July-June) in the "Projected Monthly FFVP Budget for SY 2014-2015" table. You must fill in the entire table to determine your monthly budget.
A8: Step 3. Check your work! Cell E24 should match "July FFVP Allocation", cell E34 should match "October FFVP Allocation", and cell E35 should match "Total FFVP Allocation". The cells labeled "July FFVP Allocation", "October FFVP Allocation", and "Total FFVP Allocation" will turn green if you've entered all the information correctly.
A10: FFVP School Information
A11: SFA/District Name | D11: ='School Budget (1)'!D11:F11 -> 0
A12: School Name
A13: # of Student Participating in FFVP
A14: July FFVP Allocation
A15: October FFVP Allocation
A16: Total FFVP Allocation | D16: =SUM(D14:F15) -> 0
A17: Total FFVP Funds Available per Student | D17: =D16/D13 -> #DIV/0!
A19: Projected Monthly FFVP Budget for SY 2014- 2015
A20: Allocation | B20: Month | C20: # of Serving Days per Month | D20: # of Servings per Month | E20: Total Monthly Budget | F20: Total Monthly Operational Cost Budget | G20: Total Montly Administrative Cost Budget
A21: July | B21: July | D21: =C21*$D$13 -> 0 | E21: =D21/$D$24*$D$14 -> #DIV/0! | F21: =E21-G21 -> #DIV/0! | G21: =E21*0.1 -> #DIV/0!
B22: August | D22: =C22*$D$13 -> 0 | E22: =D22/$D$24*$D$14 -> #DIV/0! | F22: =E22-G22 -> #DIV/0! | G22: =E22*0.1 -> #DIV/0!
B23: September | D23: =C23*$D$13 -> 0 | E23: =D23/$D$24*$D$14 -> #DIV/0! | F23: =E23-G23 -> #DIV/0! | G23: =E23*0.1 -> #DIV/0!
B24: July Totals | C24: =SUM(C21:C23) -> 0 | D24: =SUM(D21:D23) -> 0 | E24: =SUM(E21:E23) -> #DIV/0! | F24: =SUM(F21:F23) -> #DIV/0! | G24: =SUM(G21:G23) -> #DIV/0!
A25: October | B25: October | D25: =C25*$D$13 -> 0 | E25: =D25/$D$34*$D$15 -> #DIV/0! | F25: =E25-G25 -> #DIV/0! | G25: =E25*0.1 -> #DIV/0!
B26: November | D26: =C26*$D$13 -> 0 | E26: =D26/$D$34*$D$15 -> #DIV/0! | F26: =E26-G26 -> #DIV/0! | G26: =E26*0.1 -> #DIV/0!
B27: December | D27: =C27*$D$13 -> 0 | E27: =D27/$D$34*$D$15 -> #DIV/0! | F27: =E27-G27 -> #DIV/0! | G27: =E27*0.1 -> #DIV/0!
B28: January | D28: =C28*$D$13 -> 0 | E28: =D28/$D$34*$D$15 -> #DIV/0! | F28: =E28-G28 -> #DIV/0! | G28: =E28*0.1 -> #DIV/0!
B29: February | D29: =C29*$D$13 -> 0 | E29: =D29/$D$34*$D$15 -> #DIV/0! | F29: =E29-G29 -> #DIV/0! | G29: =E29*0.1 -> #DIV/0!
B30: March | D30: =C30*$D$13 -> 0 | E30: =D30/$D$34*$D$15 -> #DIV/0! | F30: =E30-G30 -> #DIV/0! | G30: =E30*0.1 -> #DIV/0!
B31: April | D31: =C31*$D$13 -> 0 | E31: =D31/$D$34*$D$15 -> #DIV/0! | F31: =E31-G31 -> #DIV/0! | G31: =E31*0.1 -> #DIV/0!
B32: May | D32: =C32*$D$13 -> 0 | E32: =D32/$D$34*$D$15 -> #DIV/0! | F32: =E32-G32 -> #DIV/0! | G32: =E32*0.1 -> #DIV/0!
B33: June | D33: =C33*$D$13 -> 0 | E33: =D33/$D$34*$D$15 -> #DIV/0! | F33: =E33-G33 -> #DIV/0! | G33: =E33*0.1 -> #DIV/0!
B34: October Totals | C34: =SUM(C25:C33) -> 0 | D34: =SUM(D25:D33) -> 0 | E34: =SUM(E25:E33) -> #DIV/0! | F34: =SUM(F25:F33) -> #DIV/0! | G34: =SUM(G25:G33) -> #DIV/0!
A35: Totals | C35: =SUM(C24,C34) -> 0 | D35: =SUM(D24,D34) -> 0 | E35: =SUM(E24,E34) -> #DIV/0! | F35: =SUM(F24,F34) -> #DIV/0! | G35: =SUM(G24,G34) -> #DIV/0!

Sheet School Budget (2)
A1: Fresh Fruit & Vegetable Program Projected Budget Tool for SY 2014-2015
A5: Instructions: The tool will determine your monthly budget based on your school's enrollment and the # of serving days per month.
A6: Step 1. Enter data into grey-colored cells in the "FFVP School Information" table.
A7: Step 2. Enter the "# of Serving Days per Month" for each month (July-June) in the "Projected Monthly FFVP Budget for SY 2014-2015" table. You must fill in the entire table to determine your monthly budget.
A8: Step 3. Check your work! Cell E24 should match "July FFVP Allocation", cell E34 should match "October FFVP Allocation", and cell E35 should match "Total FFVP Allocation". The cells labeled "July FFVP Allocation", "October FFVP Allocation", and "Total FFVP Allocation" will turn green if you've entered all the information correctly.
A10: FFVP School Information
A11: SFA/District Name | D11: ='School Budget (1)'!D11:F11 -> 0
A12: School Name
A13: # of Student Participating in FFVP
A14: July FFVP Allocation
A15: October FFVP Allocation
A16: Total FFVP Allocation | D16: =SUM(D14:F15) -> 0
A17: Total FFVP Funds Available per Student | D17: =D16/D13 -> #DIV/0!
A19: Projected Monthly FFVP Budget for SY 2014- 2015
A20: Allocation | B20: Month | C20: # of Serving Days per Month | D20: # of Servings per Month | E20: Total Monthly Budget | F20: Total Monthly Operational Cost Budget | G20: Total Montly Administrative Cost Budget
A21: July | B21: July | D21: =C21*$D$13 -> 0 | E21: =D21/$D$24*$D$14 -> #DIV/0! | F21: =E21-G21 -> #DIV/0! | G21: =E21*0.1 -> #DIV/0!
B22: August | D22: =C22*$D$13 -> 0 | E22: =D22/$D$24*$D$14 -> #DIV/0! | F22: =E22-G22 -> #DIV/0! | G22: =E22*0.1 -> #DIV/0!
B23: September | D23: =C23*$D$13 -> 0 | E23: =D23/$D$24*$D$14 -> #DIV/0! | F23: =E23-G23 -> #DIV/0! | G23: =E23*0.1 -> #DIV/0!
B24: July Totals | C24: =SUM(C21:C23) -> 0 | D24: =SUM(D21:D23) -> 0 | E24: =SUM(E21:E23) -> #DIV/0! | F24: =SUM(F21:F23) -> #DIV/0! | G24: =SUM(G21:G23) -> #DIV/0!
A25: October | B25: October | D25: =C25*$D$13 -> 0 | E25: =D25/$D$34*$D$15 -> #DIV/0! | F25: =E25-G25 -> #DIV/0! | G25: =E25*0.1 -> #DIV/0!
B26: November | D26: =C26*$D$13 -> 0 | E26: =D26/$D$34*$D$15 -> #DIV/0! | F26: =E26-G26 -> #DIV/0! | G26: =E26*0.1 -> #DIV/0!
B27: December | D27: =C27*$D$13 -> 0 | E27: =D27/$D$34*$D$15 -> #DIV/0! | F27: =E27-G27 -> #DIV/0! | G27: =E27*0.1 -> #DIV/0!
B28: January | D28: =C28*$D$13 -> 0 | E28: =D28/$D$34*$D$15 -> #DIV/0! | F28: =E28-G28 -> #DIV/0! | G28: =E28*0.1 -> #DIV/0!
B29: February | D29: =C29*$D$13 -> 0 | E29: =D29/$D$34*$D$15 -> #DIV/0! | F29: =E29-G29 -> #DIV/0! | G29: =E29*0.1 -> #DIV/0!
B30: March | D30: =C30*$D$13 -> 0 | E30: =D30/$D$34*$D$15 -> #DIV/0! | F30: =E30-G30 -> #DIV/0! | G30: =E30*0.1 -> #DIV/0!
B31: April | D31: =C31*$D$13 -> 0 | E31: =D31/$D$34*$D$15 -> #DIV/0! | F31: =E31-G31 -> #DIV/0! | G31: =E31*0.1 -> #DIV/0!
B32: May | D32: =C32*$D$13 -> 0 | E32: =D32/$D$34*$D$15 -> #DIV/0! | F32: =E32-G32 -> #DIV/0! | G32: =E32*0.1 -> #DIV/0!
B33: June | D33: =C33*$D$13 -> 0 | E33: =D33/$D$34*$D$15 -> #DIV/0! | F33: =E33-G33 -> #DIV/0! | G33: =E33*0.1 -> #DIV/0!
B34: October Totals | C34: =SUM(C25:C33) -> 0 | D34: =SUM(D25:D33) -> 0 | E34: =SUM(E25:E33) -> #DIV/0! | F34: =SUM(F25:F33) -> #DIV/0! | G34: =SUM(G25:G33) -> #DIV/0!
A35: Totals | C35: =SUM(C24,C34) -> 0 | D35: =SUM(D24,D34) -> 0 | E35: =SUM(E24,E34) -> #DIV/0! | F35: =SUM(F24,F34) -> #DIV/0! | G35: =SUM(G24,G34) -> #DIV/0!

Sheet School Budget (3)
A1: Fresh Fruit & Vegetable Program Projected Budget Tool for SY 2014-2015
A5: Instructions: The tool will determine your monthly budget based on your school's enrollment and the # of serving days per month.
A6: Step 1. Enter data into grey-colored cells in the "FFVP School Information" table.
A7: Step 2. Enter the "# of Serving Days per Month" for each month (July-June) in the "Projected Monthly FFVP Budget for SY 2014-2015" table. You must fill in the entire table to determine your monthly budget.
A8: Step 3. Check your work! Cell E24 should match "July FFVP Allocation", cell E34 should match "October FFVP Allocation", and cell E35 should match "Total FFVP Allocation". The cells labeled "July FFVP Allocation", "October FFVP Allocation", and "Total FFVP Allocation" will turn green if you've entered all the information correctly.
A10: FFVP School Information
A11: SFA/District Name | D11: ='School Budget (1)'!D11:F11 -> 0
A12: School Name
A13: # of Student Participating in FFVP
A14: July FFVP Allocation
A15: October FFVP Allocation
A16: Total FFVP Allocation | D16: =SUM(D14:F15) -> 0
A17: Total FFVP Funds Available per Student | D17: =D16/D13 -> #DIV/0!
A19: Projected Monthly FFVP Budget for SY 2014- 2015
A20: Allocation | B20: Month | C20: # of Serving Days per Month | D20: # of Servings per Month | E20: Total Monthly Budget | F20: Total Monthly Operational Cost Budget | G20: Total Montly Administrative Cost Budget
A21: July | B21: July | D21: =C21*$D$13 -> 0 | E21: =D21/$D$24*$D$14 -> #DIV/0! | F21: =E21-G21 -> #DIV/0! | G21: =E21*0.1 -> #DIV/0!
B22: August | D22: =C22*$D$13 -> 0 | E22: =D22/$D$24*$D$14 -> #DIV/0! | F22: =E22-G22 -> #DIV/0! | G22: =E22*0.1 -> #DIV/0!
B23: September | D23: =C23*$D$13 -> 0 | E23: =D23/$D$24*$D$14 -> #DIV/0! | F23: =E23-G23 -> #DIV/0! | G23: =E23*0.1 -> #DIV/0!
B24: July Totals | C24: =SUM(C21:C23) -> 0 | D24: =SUM(D21:D23) -> 0 | E24: =SUM(E21:E23) -> #DIV/0! | F24: =SUM(F21:F23) -> #DIV/0! | G24: =SUM(G21:G23) -> #DIV/0!
A25: October | B25: October | D25: =C25*$D$13 -> 0 | E25: =D25/$D$34*$D$15 -> #DIV/0! | F25: =E25-G25 -> #DIV/0! | G25: =E25*0.1 -> #DIV/0!
B26: November | D26: =C26*$D$13 -> 0 | E26: =D26/$D$34*$D$15 -> #DIV/0! | F26: =E26-G26 -> #DIV/0! | G26: =E26*0.1 -> #DIV/0!
B27: December | D27: =C27*$D$13 -> 0 | E27: =D27/$D$34*$D$15 -> #DIV/0! | F27: =E27-G27 -> #DIV/0! | G27: =E27*0.1 -> #DIV/0!
B28: January | D28: =C28*$D$13 -> 0 | E28: =D28/$D$34*$D$15 -> #DIV/0! | F28: =E28-G28 -> #DIV/0! | G28: =E28*0.1 -> #DIV/0!
B29: February | D29: =C29*$D$13 -> 0 | E29: =D29/$D$34*$D$15 -> #DIV/0! | F29: =E29-G29 -> #DIV/0! | G29: =E29*0.1 -> #DIV/0!
B30: March | D30: =C30*$D$13 -> 0 | E30: =D30/$D$34*$D$15 -> #DIV/0! | F30: =E30-G30 -> #DIV/0! | G30: =E30*0.1 -> #DIV/0!
B31: April | D31: =C31*$D$13 -> 0 | E31: =D31/$D$34*$D$15 -> #DIV/0! | F31: =E31-G31 -> #DIV/0! | G31: =E31*0.1 -> #DIV/0!
B32: May | D32: =C32*$D$13 -> 0 | E32: =D32/$D$34*$D$15 -> #DIV/0! | F32: =E32-G32 -> #DIV/0! | G32: =E32*0.1 -> #DIV/0!
B33: June | D33: =C33*$D$13 -> 0 | E33: =D33/$D$34*$D$15 -> #DIV/0! | F33: =E33-G33 -> #DIV/0! | G33: =E33*0.1 -> #DIV/0!
B34: October Totals | C34: =SUM(C25:C33) -> 0 | D34: =SUM(D25:D33) -> 0 | E34: =SUM(E25:E33) -> #DIV/0! | F34: =SUM(F25:F33) -> #DIV/0! | G34: =SUM(G25:G33) -> #DIV/0!
A35: Totals | C35: =SUM(C24,C34) -> 0 | D35: =SUM(D24,D34) -> 0 | E35: =SUM(E24,E34) -> #DIV/0! | F35: =SUM(F24,F34) -> #DIV/0! | G35: =SUM(G24,G34) -> #DIV/0!

Sheet School Budget (4)
A1: Fresh Fruit & Vegetable Program Projected Budget Tool for SY 2014-2015
A5: Instructions: The tool will determine your monthly budget based on your school's enrollment and the # of serving days per month.
A6: Step 1. Enter data into grey-colored cells in the "FFVP School Information" table.
A7: Step 2. Enter the "# of Serving Days per Month" for each month (July-June) in the "Projected Monthly FFVP Budget for SY 2014-2015" table. You must fill in the entire table to determine your monthly budget.
A8: Step 3. Check your work! Cell E24 should match "July FFVP Allocation", cell E34 should match "October FFVP Allocation", and cell E35 should match "Total FFVP Allocation". The cells labeled "July FFVP Allocation", "October FFVP Allocation", and "Total FFVP Allocation" will turn green if you've entered all the information correctly.
A10: FFVP School Information
A11: SFA/District Name | D11: ='School Budget (1)'!D11:F11 -> 0
A12: School Name
A13: # of Student Participating in FFVP
A14: July FFVP Allocation
A15: October FFVP Allocation
A16: Total FFVP Allocation | D16: =SUM(D14:F15) -> 0
A17: Total FFVP Funds Available per Student | D17: =D16/D13 -> #DIV/0!
A19: Projected Monthly FFVP Budget for SY 2014- 2015
A20: Allocation | B20: Month | C20: # of Serving Days per Month | D20: # of Servings per Month | E20: Total Monthly Budget | F20: Total Monthly Operational Cost Budget | G20: Total Montly Administrative Cost Budget
A21: July | B21: July | D21: =C21*$D$13 -> 0 | E21: =D21/$D$24*$D$14 -> #DIV/0! | F21: =E21-G21 -> #DIV/0! | G21: =E21*0.1 -> #DIV/0!
B22: August | D22: =C22*$D$13 -> 0 | E22: =D22/$D$24*$D$14 -> #DIV/0! | F22: =E22-G22 -> #DIV/0! | G22: =E22*0.1 -> #DIV/0!
B23: September | D23: =C23*$D$13 -> 0 | E23: =D23/$D$24*$D$14 -> #DIV/0! | F23: =E23-G23 -> #DIV/0! | G23: =E23*0.1 -> #DIV/0!
B24: July Totals | C24: =SUM(C21:C23) -> 0 | D24: =SUM(D21:D23) -> 0 | E24: =SUM(E21:E23) -> #DIV/0! | F24: =SUM(F21:F23) -> #DIV/0! | G24: =SUM(G21:G23) -> #DIV/0!
A25: October | B25: October | D25: =C25*$D$13 -> 0 | E25: =D25/$D$34*$D$15 -> #DIV/0! | F25: =E25-G25 -> #DIV/0! | G25: =E25*0.1 -> #DIV/0!
B26: November | D26: =C26*$D$13 -> 0 | E26: =D26/$D$34*$D$15 -> #DIV/0! | F26: =E26-G26 -> #DIV/0! | G26: =E26*0.1 -> #DIV/0!
B27: December | D27: =C27*$D$13 -> 0 | E27: =D27/$D$34*$D$15 -> #DIV/0! | F27: =E27-G27 -> #DIV/0! | G27: =E27*0.1 -> #DIV/0!
B28: January | D28: =C28*$D$13 -> 0 | E28: =D28/$D$34*$D$15 -> #DIV/0! | F28: =E28-G28 -> #DIV/0! | G28: =E28*0.1 -> #DIV/0!
B29: February | D29: =C29*$D$13 -> 0 | E29: =D29/$D$34*$D$15 -> #DIV/0! | F29: =E29-G29 -> #DIV/0! | G29: =E29*0.1 -> #DIV/0!
B30: March | D30: =C30*$D$13 -> 0 | E30: =D30/$D$34*$D$15 -> #DIV/0! | F30: =E30-G30 -> #DIV/0! | G30: =E30*0.1 -> #DIV/0!
B31: April | D31: =C31*$D$13 -> 0 | E31: =D31/$D$34*$D$15 -> #DIV/0! | F31: =E31-G31 -> #DIV/0! | G31: =E31*0.1 -> #DIV/0!
B32: May | D32: =C32*$D$13 -> 0 | E32: =D32/$D$34*$D$15 -> #DIV/0! | F32: =E32-G32 -> #DIV/0! | G32: =E32*0.1 -> #DIV/0!
B33: June | D33: =C33*$D$13 -> 0 | E33: =D33/$D$34*$D$15 -> #DIV/0! | F33: =E33-G33 -> #DIV/0! | G33: =E33*0.1 -> #DIV/0!
B34: October Totals | C34: =SUM(C25:C33) -> 0 | D34: =SUM(D25:D33) -> 0 | E34: =SUM(E25:E33) -> #DIV/0! | F34: =SUM(F25:F33) -> #DIV/0! | G34: =SUM(G25:G33) -> #DIV/0!
A35: Totals | C35: =SUM(C24,C34) -> 0 | D35: =SUM(D24,D34) -> 0 | E35: =SUM(E24,E34) -> #DIV/0! | F35: =SUM(F24,F34) -> #DIV/0! | G35: =SUM(G24,G34) -> #DIV/0!

Sheet School Budget (5)
A1: Fresh Fruit & Vegetable Program Projected Budget Tool for SY 2014-2015
A5: Instructions: The tool will determine your monthly budget based on your school's enrollment and the # of serving days per month.
A6: Step 1. Enter data into grey-colored cells in the "FFVP School Information" table.
A7: Step 2. Enter the "# of Serving Days per Month" for each month (July-June) in the "Projected Monthly FFVP Budget for SY 2014-2015" table. You must fill in the entire table to determine your monthly budget.
A8: Step 3. Check your work! Cell E24 should match "July FFVP Allocation", cell E34 should match "October FFVP Allocation", and cell E35 should match "Total FFVP Allocation". The cells labeled "July FFVP Allocation", "October FFVP Allocation", and "Total FFVP Allocation" will turn green if you've entered all the information correctly.
A10: FFVP School Information
A11: SFA/District Name | D11: ='School Budget (1)'!D11:F11 -> 0
A12: School Name
A13: # of Student Participating in FFVP
A14: July FFVP Allocation
A15: October FFVP Allocation
A16: Total FFVP Allocation | D16: =SUM(D14:F15) -> 0
A17: Total FFVP Funds Available per Student | D17: =D16/D13 -> #DIV/0!
A19: Projected Monthly FFVP Budget for SY 2014- 2015
A20: Allocation | B20: Month | C20: # of Serving Days per Month | D20: # of Servings per Month | E20: Total Monthly Budget | F20: Total Monthly Operational Cost Budget | G20: Total Montly Administrative Cost Budget
A21: July | B21: July | D21: =C21*$D$13 -> 0 | E21: =D21/$D$24*$D$14 -> #DIV/0! | F21: =E21-G21 -> #DIV/0! | G21: =E21*0.1 -> #DIV/0!
B22: August | D22: =C22*$D$13 -> 0 | E22: =D22/$D$24*$D$14 -> #DIV/0! | F22: =E22-G22 -> #DIV/0! | G22: =E22*0.1 -> #DIV/0!
B23: September | D23: =C23*$D$13 -> 0 | E23: =D23/$D$24*$D$14 -> #DIV/0! | F23: =E23-G23 -> #DIV/0! | G23: =E23*0.1 -> #DIV/0!
B24: July Totals | C24: =SUM(C21:C23) -> 0 | D24: =SUM(D21:D23) -> 0 | E24: =SUM(E21:E23) -> #DIV/0! | F24: =SUM(F21:F23) -> #DIV/0! | G24: =SUM(G21:G23) -> #DIV/0!
A25: October | B25: October | D25: =C25*$D$13 -> 0 | E25: =D25/$D$34*$D$15 -> #DIV/0! | F25: =E25-G25 -> #DIV/0! | G25: =E25*0.1 -> #DIV/0!
B26: November | D26: =C26*$D$13 -> 0 | E26: =D26/$D$34*$D$15 -> #DIV/0! | F26: =E26-G26 -> #DIV/0! | G26: =E26*0.1 -> #DIV/0!
B27: December | D27: =C27*$D$13 -> 0 | E27: =D27/$D$34*$D$15 -> #DIV/0! | F27: =E27-G27 -> #DIV/0! | G27: =E27*0.1 -> #DIV/0!
B28: January | D28: =C28*$D$13 -> 0 | E28: =D28/$D$34*$D$15 -> #DIV/0! | F28: =E28-G28 -> #DIV/0! | G28: =E28*0.1 -> #DIV/0!
B29: February | D29: =C29*$D$13 -> 0 | E29: =D29/$D$34*$D$15 -> #DIV/0! | F29: =E29-G29 -> #DIV/0! | G29: =E29*0.1 -> #DIV/0!
B30: March | D30: =C30*$D$13 -> 0 | E30: =D30/$D$34*$D$15 -> #DIV/0! | F30: =E30-G30 -> #DIV/0! | G30: =E30*0.1 -> #DIV/0!
B31: April | D31: =C31*$D$13 -> 0 | E31: =D31/$D$34*$D$15 -> #DIV/0! | F31: =E31-G31 -> #DIV/0! | G31: =E31*0.1 -> #DIV/0!
B32: May | D32: =C32*$D$13 -> 0 | E32: =D32/$D$34*$D$15 -> #DIV/0! | F32: =E32-G32 -> #DIV/0! | G32: =E32*0.1 -> #DIV/0!
B33: June | D33: =C33*$D$13 -> 0 | E33: =D33/$D$34*$D$15 -> #DIV/0! | F33: =E33-G33 -> #DIV/0! | G33: =E33*0.1 -> #DIV/0!
B34: October Totals | C34: =SUM(C25:C33) -> 0 | D34: =SUM(D25:D33) -> 0 | E34: =SUM(E25:E33) -> #DIV/0! | F34: =SUM(F25:F33) -> #DIV/0! | G34: =SUM(G25:G33) -> #DIV/0!
A35: Totals | C35: =SUM(C24,C34) -> 0 | D35: =SUM(D24,D34) -> 0 | E35: =SUM(E24,E34) -> #DIV/0! | F35: =SUM(F24,F34) -> #DIV/0! | G35: =SUM(G24,G34) -> #DIV/0!

Sheet School Budget (6)
A1: Fresh Fruit & Vegetable Program Projected Budget Tool for SY 2014-2015
A5: Instructions: The tool will determine your monthly budget based on your school's enrollment and the # of serving days per month.
A6: Step 1. Enter data into grey-colored cells in the "FFVP School Information" table.
A7: Step 2. Enter the "# of Serving Days per Month" for each month (July-June) in the "Projected Monthly FFVP Budget for SY 2014-2015" table. You must fill in the entire table to determine your monthly budget.
A8: Step 3. Check your work! Cell E24 should match "July FFVP Allocation", cell E34 should match "October FFVP Allocation", and cell E35 should match "Total FFVP Allocation". The cells labeled "July FFVP Allocation", "October FFVP Allocation", and "Total FFVP Allocation" will turn green if you've entered all the information correctly.
A10: FFVP School Information
A11: SFA/District Name | D11: ='School Budget (1)'!D11:F11 -> 0
A12: School Name
A13: # of Student Participating in FFVP
A14: July FFVP Allocation
A15: October FFVP Allocation
A16: Total FFVP Allocation | D16: =SUM(D14:F15) -> 0
A17: Total FFVP Funds Available per Student | D17: =D16/D13 -> #DIV/0!
A19: Projected Monthly FFVP Budget for SY 2014- 2015
A20: Allocation | B20: Month | C20: # of Serving Days per Month | D20: # of Servings per Month | E20: Total Monthly Budget | F20: Total Monthly Operational Cost Budget | G20: Total Montly Administrative Cost Budget
A21: July | B21: July | D21: =C21*$D$13 -> 0 | E21: =D21/$D$24*$D$14 -> #DIV/0! | F21: =E21-G21 -> #DIV/0! | G21: =E21*0.1 -> #DIV/0!
B22: August | D22: =C22*$D$13 -> 0 | E22: =D22/$D$24*$D$14 -> #DIV/0! | F22: =E22-G22 -> #DIV/0! | G22: =E22*0.1 -> #DIV/0!
B23: September | D23: =C23*$D$13 -> 0 | E23: =D23/$D$24*$D$14 -> #DIV/0! | F23: =E23-G23 -> #DIV/0! | G23: =E23*0.1 -> #DIV/0!
B24: July Totals | C24: =SUM(C21:C23) -> 0 | D24: =SUM(D21:D23) -> 0 | E24: =SUM(E21:E23) -> #DIV/0! | F24: =SUM(F21:F23) -> #DIV/0! | G24: =SUM(G21:G23) -> #DIV/0!
A25: October | B25: October | D25: =C25*$D$13 -> 0 | E25: =D25/$D$34*$D$15 -> #DIV/0! | F25: =E25-G25 -> #DIV/0! | G25: =E25*0.1 -> #DIV/0!
B26: November | D26: =C26*$D$13 -> 0 | E26: =D26/$D$34*$D$15 -> #DIV/0! | F26: =E26-G26 -> #DIV/0! | G26: =E26*0.1 -> #DIV/0!
B27: December | D27: =C27*$D$13 -> 0 | E27: =D27/$D$34*$D$15 -> #DIV/0! | F27: =E27-G27 -> #DIV/0! | G27: =E27*0.1 -> #DIV/0!
B28: January | D28: =C28*$D$13 -> 0 | E28: =D28/$D$34*$D$15 -> #DIV/0! | F28: =E28-G28 -> #DIV/0! | G28: =E28*0.1 -> #DIV/0!
B29: February | D29: =C29*$D$13 -> 0 | E29: =D29/$D$34*$D$15 -> #DIV/0! | F29: =E29-G29 -> #DIV/0! | G29: =E29*0.1 -> #DIV/0!
B30: March | D30: =C30*$D$13 -> 0 | E30: =D30/$D$34*$D$15 -> #DIV/0! | F30: =E30-G30 -> #DIV/0! | G30: =E30*0.1 -> #DIV/0!
B31: April | D31: =C31*$D$13 -> 0 | E31: =D31/$D$34*$D$15 -> #DIV/0! | F31: =E31-G31 -> #DIV/0! | G31: =E31*0.1 -> #DIV/0!
B32: May | D32: =C32*$D$13 -> 0 | E32: =D32/$D$34*$D$15 -> #DIV/0! | F32: =E32-G32 -> #DIV/0! | G32: =E32*0.1 -> #DIV/0!
B33: June | D33: =C33*$D$13 -> 0 | E33: =D33/$D$34*$D$15 -> #DIV/0! | F33: =E33-G33 -> #DIV/0! | G33: =E33*0.1 -> #DIV/0!
B34: October Totals | C34: =SUM(C25:C33) -> 0 | D34: =SUM(D25:D33) -> 0 | E34: =SUM(E25:E33) -> #DIV/0! | F34: =SUM(F25:F33) -> #DIV/0! | G34: =SUM(G25:G33) -> #DIV/0!
A35: Totals | C35: =SUM(C24,C34) -> 0 | D35: =SUM(D24,D34) -> 0 | E35: =SUM(E24,E34) -> #DIV/0! | F35: =SUM(F24,F34) -> #DIV/0! | G35: =SUM(G24,G34) -> #DIV/0!

Sheet School Budget (7)
A1: Fresh Fruit & Vegetable Program Projected Budget Tool for SY 2014-2015
A5: Instructions: The tool will determine your monthly budget based on your school's enrollment and the # of serving days per month.
A6: Step 1. Enter data into grey-colored cells in the "FFVP School Information" table.
A7: Step 2. Enter the "# of Serving Days per Month" for each month (July-June) in the "Projected Monthly FFVP Budget for SY 2014-2015" table. You must fill in the entire table to determine your monthly budget.
A8: Step 3. Check your work! Cell E24 should match "July FFVP Allocation", cell E34 should match "October FFVP Allocation", and cell E35 should match "Total FFVP Allocation". The cells labeled "July FFVP Allocation", "October FFVP Allocation", and "Total FFVP Allocation" will turn green if you've entered all the information correctly.
A10: FFVP School Information
A11: SFA/District Name | D11: ='School Budget (1)'!D11:F11 -> 0
A12: School Name
A13: # of Student Participating in FFVP
A14: July FFVP Allocation
A15: October FFVP Allocation
A16: Total FFVP Allocation | D16: =SUM(D14:F15) -> 0
A17: Total FFVP Funds Available per Student | D17: =D16/D13 -> #DIV/0!
A19: Projected Monthly FFVP Budget for SY 2014- 2015
A20: Allocation | B20: Month | C20: # of Serving Days per Month | D20: # of Servings per Month | E20: Total Monthly Budget | F20: Total Monthly Operational Cost Budget | G20: Total Montly Administrative Cost Budget
A21: July | B21: July | D21: =C21*$D$13 -> 0 | E21: =D21/$D$24*$D$14 -> #DIV/0! | F21: =E21-G21 -> #DIV/0! | G21: =E21*0.1 -> #DIV/0!
B22: August | D22: =C22*$D$13 -> 0 | E22: =D22/$D$24*$D$14 -> #DIV/0! | F22: =E22-G22 -> #DIV/0! | G22: =E22*0.1 -> #DIV/0!
B23: September | D23: =C23*$D$13 -> 0 | E23: =D23/$D$24*$D$14 -> #DIV/0! | F23: =E23-G23 -> #DIV/0! | G23: =E23*0.1 -> #DIV/0!
B24: July Totals | C24: =SUM(C21:C23) -> 0 | D24: =SUM(D21:D23) -> 0 | E24: =SUM(E21:E23) -> #DIV/0! | F24: =SUM(F21:F23) -> #DIV/0! | G24: =SUM(G21:G23) -> #DIV/0!
A25: October | B25: October | D25: =C25*$D$13 -> 0 | E25: =D25/$D$34*$D$15 -> #DIV/0! | F25: =E25-G25 -> #DIV/0! | G25: =E25*0.1 -> #DIV/0!
B26: November | D26: =C26*$D$13 -> 0 | E26: =D26/$D$34*$D$15 -> #DIV/0! | F26: =E26-G26 -> #DIV/0! | G26: =E26*0.1 -> #DIV/0!
B27: December | D27: =C27*$D$13 -> 0 | E27: =D27/$D$34*$D$15 -> #DIV/0! | F27: =E27-G27 -> #DIV/0! | G27: =E27*0.1 -> #DIV/0!
B28: January | D28: =C28*$D$13 -> 0 | E28: =D28/$D$34*$D$15 -> #DIV/0! | F28: =E28-G28 -> #DIV/0! | G28: =E28*0.1 -> #DIV/0!
B29: February | D29: =C29*$D$13 -> 0 | E29: =D29/$D$34*$D$15 -> #DIV/0! | F29: =E29-G29 -> #DIV/0! | G29: =E29*0.1 -> #DIV/0!
B30: March | D30: =C30*$D$13 -> 0 | E30: =D30/$D$34*$D$15 -> #DIV/0! | F30: =E30-G30 -> #DIV/0! | G30: =E30*0.1 -> #DIV/0!
B31: April | D31: =C31*$D$13 -> 0 | E31: =D31/$D$34*$D$15 -> #DIV/0! | F31: =E31-G31 -> #DIV/0! | G31: =E31*0.1 -> #DIV/0!
B32: May | D32: =C32*$D$13 -> 0 | E32: =D32/$D$34*$D$15 -> #DIV/0! | F32: =E32-G32 -> #DIV/0! | G32: =E32*0.1 -> #DIV/0!
B33: June | D33: =C33*$D$13 -> 0 | E33: =D33/$D$34*$D$15 -> #DIV/0! | F33: =E33-G33 -> #DIV/0! | G33: =E33*0.1 -> #DIV/0!
B34: October Totals | C34: =SUM(C25:C33) -> 0 | D34: =SUM(D25:D33) -> 0 | E34: =SUM(E25:E33) -> #DIV/0! | F34: =SUM(F25:F33) -> #DIV/0! | G34: =SUM(G25:G33) -> #DIV/0!
A35: Totals | C35: =SUM(C24,C34) -> 0 | D35: =SUM(D24,D34) -> 0 | E35: =SUM(E24,E34) -> #DIV/0! | F35: =SUM(F24,F34) -> #DIV/0! | G35: =SUM(G24,G34) -> #DIV/0!

Sheet School Budget (8)
A1: Fresh Fruit & Vegetable Program Projected Budget Tool for SY 2014-2015
A5: Instructions: The tool will determine your monthly budget based on your school's enrollment and the # of serving days per month.
A6: Step 1. Enter data into grey-colored cells in the "FFVP School Information" table.
A7: Step 2. Enter the "# of Serving Days per Month" for each month (July-June) in the "Projected Monthly FFVP Budget for SY 2014-2015" table. You must fill in the entire table to determine your monthly budget.
A8: Step 3. Check your work! Cell E24 should match "July FFVP Allocation", cell E34 should match "October FFVP Allocation", and cell E35 should match "Total FFVP Allocation". The cells labeled "July FFVP Allocation", "October FFVP Allocation", and "Total FFVP Allocation" will turn green if you've entered all the information correctly.
A10: FFVP School Information
A11: SFA/District Name | D11: ='School Budget (1)'!D11:F11 -> 0
A12: School Name
A13: # of Student Participating in FFVP
A14: July FFVP Allocation
A15: October FFVP Allocation
A16: Total FFVP Allocation | D16: =SUM(D14:F15) -> 0
A17: Total FFVP Funds Available per Student | D17: =D16/D13 -> #DIV/0!
A19: Projected Monthly FFVP Budget for SY 2014- 2015
A20: Allocation | B20: Month | C20: # of Serving Days per Month | D20: # of Servings per Month | E20: Total Monthly Budget | F20: Total Monthly Operational Cost Budget | G20: Total Montly Administrative Cost Budget
A21: July | B21: July | D21: =C21*$D$13 -> 0 | E21: =D21/$D$24*$D$14 -> #DIV/0! | F21: =E21-G21 -> #DIV/0! | G21: =E21*0.1 -> #DIV/0!
B22: August | D22: =C22*$D$13 -> 0 | E22: =D22/$D$24*$D$14 -> #DIV/0! | F22: =E22-G22 -> #DIV/0! | G22: =E22*0.1 -> #DIV/0!
B23: September | D23: =C23*$D$13 -> 0 | E23: =D23/$D$24*$D$14 -> #DIV/0! | F23: =E23-G23 -> #DIV/0! | G23: =E23*0.1 -> #DIV/0!
B24: July Totals | C24: =SUM(C21:C23) -> 0 | D24: =SUM(D21:D23) -> 0 | E24: =SUM(E21:E23) -> #DIV/0! | F24: =SUM(F21:F23) -> #DIV/0! | G24: =SUM(G21:G23) -> #DIV/0!
A25: October | B25: October | D25: =C25*$D$13 -> 0 | E25: =D25/$D$34*$D$15 -> #DIV/0! | F25: =E25-G25 -> #DIV/0! | G25: =E25*0.1 -> #DIV/0!
B26: November | D26: =C26*$D$13 -> 0 | E26: =D26/$D$34*$D$15 -> #DIV/0! | F26: =E26-G26 -> #DIV/0! | G26: =E26*0.1 -> #DIV/0!
B27: December | D27: =C27*$D$13 -> 0 | E27: =D27/$D$34*$D$15 -> #DIV/0! | F27: =E27-G27 -> #DIV/0! | G27: =E27*0.1 -> #DIV/0!
B28: January | D28: =C28*$D$13 -> 0 | E28: =D28/$D$34*$D$15 -> #DIV/0! | F28: =E28-G28 -> #DIV/0! | G28: =E28*0.1 -> #DIV/0!
B29: February | D29: =C29*$D$13 -> 0 | E29: =D29/$D$34*$D$15 -> #DIV/0! | F29: =E29-G29 -> #DIV/0! | G29: =E29*0.1 -> #DIV/0!
B30: March | D30: =C30*$D$13 -> 0 | E30: =D30/$D$34*$D$15 -> #DIV/0! | F30: =E30-G30 -> #DIV/0! | G30: =E30*0.1 -> #DIV/0!
B31: April | D31: =C31*$D$13 -> 0 | E31: =D31/$D$34*$D$15 -> #DIV/0! | F31: =E31-G31 -> #DIV/0! | G31: =E31*0.1 -> #DIV/0!
B32: May | D32: =C32*$D$13 -> 0 | E32: =D32/$D$34*$D$15 -> #DIV/0! | F32: =E32-G32 -> #DIV/0! | G32: =E32*0.1 -> #DIV/0!
B33: June | D33: =C33*$D$13 -> 0 | E33: =D33/$D$34*$D$15 -> #DIV/0! | F33: =E33-G33 -> #DIV/0! | G33: =E33*0.1 -> #DIV/0!
B34: October Totals | C34: =SUM(C25:C33) -> 0 | D34: =SUM(D25:D33) -> 0 | E34: =SUM(E25:E33) -> #DIV/0! | F34: =SUM(F25:F33) -> #DIV/0! | G34: =SUM(G25:G33) -> #DIV/0!
A35: Totals | C35: =SUM(C24,C34) -> 0 | D35: =SUM(D24,D34) -> 0 | E35: =SUM(E24,E34) -> #DIV/0! | F35: =SUM(F24,F34) -> #DIV/0! | G35: =SUM(G24,G34) -> #DIV/0!

Sheet School Budget (9)
A1: Fresh Fruit & Vegetable Program Projected Budget Tool for SY 2014-2015
A5: Instructions: The tool will determine your monthly budget based on your school's enrollment and the # of serving days per month.
A6: Step 1. Enter data into grey-colored cells in the "FFVP School Information" table.
A7: Step 2. Enter the "# of Serving Days per Month" for each month (July-June) in the "Projected Monthly FFVP Budget for SY 2014-2015" table. You must fill in the entire table to determine your monthly budget.
A8: Step 3. Check your work! Cell E24 should match "July FFVP Allocation", cell E34 should match "October FFVP Allocation", and cell E35 should match "Total FFVP Allocation". The cells labeled "July FFVP Allocation", "October FFVP Allocation", and "Total FFVP Allocation" will turn green if you've entered all the information correctly.
A10: FFVP School Information
A11: SFA/District Name | D11: ='School Budget (1)'!D11:F11 -> 0
A12: School Name
A13: # of Student Participating in FFVP
A14: July FFVP Allocation
A15: October FFVP Allocation
A16: Total FFVP Allocation | D16: =SUM(D14:F15) -> 0
A17: Total FFVP Funds Available per Student | D17: =D16/D13 -> #DIV/0!
A19: Projected Monthly FFVP Budget for SY 2014- 2015
A20: Allocation | B20: Month | C20: # of Serving Days per Month | D20: # of Servings per Month | E20: Total Monthly Budget | F20: Total Monthly Operational Cost Budget | G20: Total Montly Administrative Cost Budget
A21: July | B21: July | D21: =C21*$D$13 -> 0 | E21: =D21/$D$24*$D$14 -> #DIV/0! | F21: =E21-G21 -> #DIV/0! | G21: =E21*0.1 -> #DIV/0!
B22: August | D22: =C22*$D$13 -> 0 | E22: =D22/$D$24*$D$14 -> #DIV/0! | F22: =E22-G22 -> #DIV/0! | G22: =E22*0.1 -> #DIV/0!
B23: September | D23: =C23*$D$13 -> 0 | E23: =D23/$D$24*$D$14 -> #DIV/0! | F23: =E23-G23 -> #DIV/0! | G23: =E23*0.1 -> #DIV/0!
B24: July Totals | C24: =SUM(C21:C23) -> 0 | D24: =SUM(D21:D23) -> 0 | E24: =SUM(E21:E23) -> #DIV/0! | F24: =SUM(F21:F23) -> #DIV/0! | G24: =SUM(G21:G23) -> #DIV/0!
A25: October | B25: October | D25: =C25*$D$13 -> 0 | E25: =D25/$D$34*$D$15 -> #DIV/0! | F25: =E25-G25 -> #DIV/0! | G25: =E25*0.1 -> #DIV/0!
B26: November | D26: =C26*$D$13 -> 0 | E26: =D26/$D$34*$D$15 -> #DIV/0! | F26: =E26-G26 -> #DIV/0! | G26: =E26*0.1 -> #DIV/0!
B27: December | D27: =C27*$D$13 -> 0 | E27: =D27/$D$34*$D$15 -> #DIV/0! | F27: =E27-G27 -> #DIV/0! | G27: =E27*0.1 -> #DIV/0!
B28: January | D28: =C28*$D$13 -> 0 | E28: =D28/$D$34*$D$15 -> #DIV/0! | F28: =E28-G28 -> #DIV/0! | G28: =E28*0.1 -> #DIV/0!
B29: February | D29: =C29*$D$13 -> 0 | E29: =D29/$D$34*$D$15 -> #DIV/0! | F29: =E29-G29 -> #DIV/0! | G29: =E29*0.1 -> #DIV/0!
B30: March | D30: =C30*$D$13 -> 0 | E30: =D30/$D$34*$D$15 -> #DIV/0! | F30: =E30-G30 -> #DIV/0! | G30: =E30*0.1 -> #DIV/0!
B31: April | D31: =C31*$D$13 -> 0 | E31: =D31/$D$34*$D$15 -> #DIV/0! | F31: =E31-G31 -> #DIV/0! | G31: =E31*0.1 -> #DIV/0!
B32: May | D32: =C32*$D$13 -> 0 | E32: =D32/$D$34*$D$15 -> #DIV/0! | F32: =E32-G32 -> #DIV/0! | G32: =E32*0.1 -> #DIV/0!
B33: June | D33: =C33*$D$13 -> 0 | E33: =D33/$D$34*$D$15 -> #DIV/0! | F33: =E33-G33 -> #DIV/0! | G33: =E33*0.1 -> #DIV/0!
B34: October Totals | C34: =SUM(C25:C33) -> 0 | D34: =SUM(D25:D33) -> 0 | E34: =SUM(E25:E33) -> #DIV/0! | F34: =SUM(F25:F33) -> #DIV/0! | G34: =SUM(G25:G33) -> #DIV/0!
A35: Totals | C35: =SUM(C24,C34) -> 0 | D35: =SUM(D24,D34) -> 0 | E35: =SUM(E24,E34) -> #DIV/0! | F35: =SUM(F24,F34) -> #DIV/0! | G35: =SUM(G24,G34) -> #DIV/0!

Sheet School Budget (10)
A1: Fresh Fruit & Vegetable Program Projected Budget Tool for SY 2014-2015
A5: Instructions: The tool will determine your monthly budget based on your school's enrollment and the # of serving days per month.
A6: Step 1. Enter data into grey-colored cells in the "FFVP School Information" table.
A7: Step 2. Enter the "# of Serving Days per Month" for each month (July-June) in the "Projected Monthly FFVP Budget for SY 2014-2015" table. You must fill in the entire table to determine your monthly budget.
A8: Step 3. Check your work! Cell E24 should match "July FFVP Allocation", cell E34 should match "October FFVP Allocation", and cell E35 should match "Total FFVP Allocation". The cells labeled "July FFVP Allocation", "October FFVP Allocation", and "Total FFVP Allocation" will turn green if you've entered all the information correctly.
A10: FFVP School Information
A11: SFA/District Name | D11: ='School Budget (1)'!D11:F11 -> 0
A12: School Name
A13: # of Student Participating in FFVP
A14: July FFVP Allocation
A15: October FFVP Allocation
A16: Total FFVP Allocation | D16: =SUM(D14:F15) -> 0
A17: Total FFVP Funds Available per Student | D17: =D16/D13 -> #DIV/0!
A19: Projected Monthly FFVP Budget for SY 2014- 2015
A20: Allocation | B20: Month | C20: # of Serving Days per Month | D20: # of Servings per Month | E20: Total Monthly Budget | F20: Total Monthly Operational Cost Budget | G20: Total Montly Administrative Cost Budget
A21: July | B21: July | D21: =C21*$D$13 -> 0 | E21: =D21/$D$24*$D$14 -> #DIV/0! | F21: =E21-G21 -> #DIV/0! | G21: =E21*0.1 -> #DIV/0!
B22: August | D22: =C22*$D$13 -> 0 | E22: =D22/$D$24*$D$14 -> #DIV/0! | F22: =E22-G22 -> #DIV/0! | G22: =E22*0.1 -> #DIV/0!
B23: September | D23: =C23*$D$13 -> 0 | E23: =D23/$D$24*$D$14 -> #DIV/0! | F23: =E23-G23 -> #DIV/0! | G23: =E23*0.1 -> #DIV/0!
B24: July Totals | C24: =SUM(C21:C23) -> 0 | D24: =SUM(D21:D23) -> 0 | E24: =SUM(E21:E23) -> #DIV/0! | F24: =SUM(F21:F23) -> #DIV/0! | G24: =SUM(G21:G23) -> #DIV/0!
A25: October | B25: October | D25: =C25*$D$13 -> 0 | E25: =D25/$D$34*$D$15 -> #DIV/0! | F25: =E25-G25 -> #DIV/0! | G25: =E25*0.1 -> #DIV/0!
B26: November | D26: =C26*$D$13 -> 0 | E26: =D26/$D$34*$D$15 -> #DIV/0! | F26: =E26-G26 -> #DIV/0! | G26: =E26*0.1 -> #DIV/0!
B27: December | D27: =C27*$D$13 -> 0 | E27: =D27/$D$34*$D$15 -> #DIV/0! | F27: =E27-G27 -> #DIV/0! | G27: =E27*0.1 -> #DIV/0!
B28: January | D28: =C28*$D$13 -> 0 | E28: =D28/$D$34*$D$15 -> #DIV/0! | F28: =E28-G28 -> #DIV/0! | G28: =E28*0.1 -> #DIV/0!
B29: February | D29: =C29*$D$13 -> 0 | E29: =D29/$D$34*$D$15 -> #DIV/0! | F29: =E29-G29 -> #DIV/0! | G29: =E29*0.1 -> #DIV/0!
B30: March | D30: =C30*$D$13 -> 0 | E30: =D30/$D$34*$D$15 -> #DIV/0! | F30: =E30-G30 -> #DIV/0! | G30: =E30*0.1 -> #DIV/0!
B31: April | D31: =C31*$D$13 -> 0 | E31: =D31/$D$34*$D$15 -> #DIV/0! | F31: =E31-G31 -> #DIV/0! | G31: =E31*0.1 -> #DIV/0!
B32: May | D32: =C32*$D$13 -> 0 | E32: =D32/$D$34*$D$15 -> #DIV/0! | F32: =E32-G32 -> #DIV/0! | G32: =E32*0.1 -> #DIV/0!
B33: June | D33: =C33*$D$13 -> 0 | E33: =D33/$D$34*$D$15 -> #DIV/0! | F33: =E33-G33 -> #DIV/0! | G33: =E33*0.1 -> #DIV/0!
B34: October Totals | C34: =SUM(C25:C33) -> 0 | D34: =SUM(D25:D33) -> 0 | E34: =SUM(E25:E33) -> #DIV/0! | F34: =SUM(F25:F33) -> #DIV/0! | G34: =SUM(G25:G33) -> #DIV/0!
A35: Totals | C35: =SUM(C24,C34) -> 0 | D35: =SUM(D24,D34) -> 0 | E35: =SUM(E24,E34) -> #DIV/0! | F35: =SUM(F24,F34) -> #DIV/0! | G35: =SUM(G24,G34) -> #DIV/0!

Sheet School Budget (11)
A1: Fresh Fruit & Vegetable Program Projected Budget Tool for SY 2014-2015
A5: Instructions: The tool will determine your monthly budget based on your school's enrollment and the # of serving days per month.
A6: Step 1. Enter data into grey-colored cells in the "FFVP School Information" table.
A7: Step 2. Enter the "# of Serving Days per Month" for each month (July-June) in the "Projected Monthly FFVP Budget for SY 2014-2015" table. You must fill in the entire table to determine your monthly budget.
A8: Step 3. Check your work! Cell E24 should match "July FFVP Allocation", cell E34 should match "October FFVP Allocation", and cell E35 should match "Total FFVP Allocation". The cells labeled "July FFVP Allocation", "October FFVP Allocation", and "Total FFVP Allocation" will turn green if you've entered all the information correctly.
A10: FFVP School Information
A11: SFA/District Name | D11: ='School Budget (1)'!D11:F11 -> 0
A12: School Name
A13: # of Student Participating in FFVP
A14: July FFVP Allocation
A15: October FFVP Allocation
A16: Total FFVP Allocation | D16: =SUM(D14:F15) -> 0
A17: Total FFVP Funds Available per Student | D17: =D16/D13 -> #DIV/0!
A19: Projected Monthly FFVP Budget for SY 2014- 2015
A20: Allocation | B20: Month | C20: # of Serving Days per Month | D20: # of Servings per Month | E20: Total Monthly Budget | F20: Total Monthly Operational Cost Budget | G20: Total Montly Administrative Cost Budget
A21: July | B21: July | D21: =C21*$D$13 -> 0 | E21: =D21/$D$24*$D$14 -> #DIV/0! | F21: =E21-G21 -> #DIV/0! | G21: =E21*0.1 -> #DIV/0!
B22: August | D22: =C22*$D$13 -> 0 | E22: =D22/$D$24*$D$14 -> #DIV/0! | F22: =E22-G22 -> #DIV/0! | G22: =E22*0.1 -> #DIV/0!
B23: September | D23: =C23*$D$13 -> 0 | E23: =D23/$D$24*$D$14 -> #DIV/0! | F23: =E23-G23 -> #DIV/0! | G23: =E23*0.1 -> #DIV/0!
B24: July Totals | C24: =SUM(C21:C23) -> 0 | D24: =SUM(D21:D23) -> 0 | E24: =SUM(E21:E23) -> #DIV/0! | F24: =SUM(F21:F23) -> #DIV/0! | G24: =SUM(G21:G23) -> #DIV/0!
A25: October | B25: October | D25: =C25*$D$13 -> 0 | E25: =D25/$D$34*$D$15 -> #DIV/0! | F25: =E25-G25 -> #DIV/0! | G25: =E25*0.1 -> #DIV/0!
B26: November | D26: =C26*$D$13 -> 0 | E26: =D26/$D$34*$D$15 -> #DIV/0! | F26: =E26-G26 -> #DIV/0! | G26: =E26*0.1 -> #DIV/0!
B27: December | D27: =C27*$D$13 -> 0 | E27: =D27/$D$34*$D$15 -> #DIV/0! | F27: =E27-G27 -> #DIV/0! | G27: =E27*0.1 -> #DIV/0!
B28: January | D28: =C28*$D$13 -> 0 | E28: =D28/$D$34*$D$15 -> #DIV/0! | F28: =E28-G28 -> #DIV/0! | G28: =E28*0.1 -> #DIV/0!
B29: February | D29: =C29*$D$13 -> 0 | E29: =D29/$D$34*$D$15 -> #DIV/0! | F29: =E29-G29 -> #DIV/0! | G29: =E29*0.1 -> #DIV/0!
B30: March | D30: =C30*$D$13 -> 0 | E30: =D30/$D$34*$D$15 -> #DIV/0! | F30: =E30-G30 -> #DIV/0! | G30: =E30*0.1 -> #DIV/0!
B31: April | D31: =C31*$D$13 -> 0 | E31: =D31/$D$34*$D$15 -> #DIV/0! | F31: =E31-G31 -> #DIV/0! | G31: =E31*0.1 -> #DIV/0!
B32: May | D32: =C32*$D$13 -> 0 | E32: =D32/$D$34*$D$15 -> #DIV/0! | F32: =E32-G32 -> #DIV/0! | G32: =E32*0.1 -> #DIV/0!
B33: June | D33: =C33*$D$13 -> 0 | E33: =D33/$D$34*$D$15 -> #DIV/0! | F33: =E33-G33 -> #DIV/0! | G33: =E33*0.1 -> #DIV/0!
B34: October Totals | C34: =SUM(C25:C33) -> 0 | D34: =SUM(D25:D33) -> 0 | E34: =SUM(E25:E33) -> #DIV/0! | F34: =SUM(F25:F33) -> #DIV/0! | G34: =SUM(G25:G33) -> #DIV/0!
A35: Totals | C35: =SUM(C24,C34) -> 0 | D35: =SUM(D24,D34) -> 0 | E35: =SUM(E24,E34) -> #DIV/0! | F35: =SUM(F24,F34) -> #DIV/0! | G35: =SUM(G24,G34) -> #DIV/0!

Sheet School Budget (12)
A1: Fresh Fruit & Vegetable Program Projected Budget Tool for SY 2014-2015
A5: Instructions: The tool will determine your monthly budget based on your school's enrollment and the # of serving days per month.
A6: Step 1. Enter data into grey-colored cells in the "FFVP School Information" table.
A7: Step 2. Enter the "# of Serving Days per Month" for each month (July-June) in the "Projected Monthly FFVP Budget for SY 2014-2015" table. You must fill in the entire table to determine your monthly budget.
A8: Step 3. Check your work! Cell E24 should match "July FFVP Allocation", cell E34 should match "October FFVP Allocation", and cell E35 should match "Total FFVP Allocation". The cells labeled "July FFVP Allocation", "October FFVP Allocation", and "Total FFVP Allocation" will turn green if you've entered all the information correctly.
A10: FFVP School Information
A11: SFA/District Name | D11: ='School Budget (1)'!D11:F11 -> 0
A12: School Name
A13: # of Student Participating in FFVP
A14: July FFVP Allocation
A15: October FFVP Allocation
A16: Total FFVP Allocation | D16: =SUM(D14:F15) -> 0
A17: Total FFVP Funds Available per Student | D17: =D16/D13 -> #DIV/0!
A19: Projected Monthly FFVP Budget for SY 2014- 2015
A20: Allocation | B20: Month | C20: # of Serving Days per Month | D20: # of Servings per Month | E20: Total Monthly Budget | F20: Total Monthly Operational Cost Budget | G20: Total Montly Administrative Cost Budget
A21: July | B21: July | D21: =C21*$D$13 -> 0 | E21: =D21/$D$24*$D$14 -> #DIV/0! | F21: =E21-G21 -> #DIV/0! | G21: =E21*0.1 -> #DIV/0!
B22: August | D22: =C22*$D$13 -> 0 | E22: =D22/$D$24*$D$14 -> #DIV/0! | F22: =E22-G22 -> #DIV/0! | G22: =E22*0.1 -> #DIV/0!
B23: September | D23: =C23*$D$13 -> 0 | E23: =D23/$D$24*$D$14 -> #DIV/0! | F23: =E23-G23 -> #DIV/0! | G23: =E23*0.1 -> #DIV/0!
B24: July Totals | C24: =SUM(C21:C23) -> 0 | D24: =SUM(D21:D23) -> 0 | E24: =SUM(E21:E23) -> #DIV/0! | F24: =SUM(F21:F23) -> #DIV/0! | G24: =SUM(G21:G23) -> #DIV/0!
A25: October | B25: October | D25: =C25*$D$13 -> 0 | E25: =D25/$D$34*$D$15 -> #DIV/0! | F25: =E25-G25 -> #DIV/0! | G25: =E25*0.1 -> #DIV/0!
B26: November | D26: =C26*$D$13 -> 0 | E26: =D26/$D$34*$D$15 -> #DIV/0! | F26: =E26-G26 -> #DIV/0! | G26: =E26*0.1 -> #DIV/0!
B27: December | D27: =C27*$D$13 -> 0 | E27: =D27/$D$34*$D$15 -> #DIV/0! | F27: =E27-G27 -> #DIV/0! | G27: =E27*0.1 -> #DIV/0!
B28: January | D28: =C28*$D$13 -> 0 | E28: =D28/$D$34*$D$15 -> #DIV/0! | F28: =E28-G28 -> #DIV/0! | G28: =E28*0.1 -> #DIV/0!
B29: February | D29: =C29*$D$13 -> 0 | E29: =D29/$D$34*$D$15 -> #DIV/0! | F29: =E29-G29 -> #DIV/0! | G29: =E29*0.1 -> #DIV/0!
B30: March | D30: =C30*$D$13 -> 0 | E30: =D30/$D$34*$D$15 -> #DIV/0! | F30: =E30-G30 -> #DIV/0! | G30: =E30*0.1 -> #DIV/0!
B31: April | D31: =C31*$D$13 -> 0 | E31: =D31/$D$34*$D$15 -> #DIV/0! | F31: =E31-G31 -> #DIV/0! | G31: =E31*0.1 -> #DIV/0!
B32: May | D32: =C32*$D$13 -> 0 | E32: =D32/$D$34*$D$15 -> #DIV/0! | F32: =E32-G32 -> #DIV/0! | G32: =E32*0.1 -> #DIV/0!
B33: June | D33: =C33*$D$13 -> 0 | E33: =D33/$D$34*$D$15 -> #DIV/0! | F33: =E33-G33 -> #DIV/0! | G33: =E33*0.1 -> #DIV/0!
B34: October Totals | C34: =SUM(C25:C33) -> 0 | D34: =SUM(D25:D33) -> 0 | E34: =SUM(E25:E33) -> #DIV/0! | F34: =SUM(F25:F33) -> #DIV/0! | G34: =SUM(G25:G33) -> #DIV/0!
A35: Totals | C35: =SUM(C24,C34) -> 0 | D35: =SUM(D24,D34) -> 0 | E35: =SUM(E24,E34) -> #DIV/0! | F35: =SUM(F24,F34) -> #DIV/0! | G35: =SUM(G24,G34) -> #DIV/0!

Sheet School Budget (13)
A1: Fresh Fruit & Vegetable Program Projected Budget Tool for SY 2014-2015
A5: Instructions: The tool will determine your monthly budget based on your school's enrollment and the # of serving days per month.
A6: Step 1. Enter data into grey-colored cells in the "FFVP School Information" table.
A7: Step 2. Enter the "# of Serving Days per Month" for each month (July-June) in the "Projected Monthly FFVP Budget for SY 2014-2015" table. You must fill in the entire table to determine your monthly budget.
A8: Step 3. Check your work! Cell E24 should match "July FFVP Allocation", cell E34 should match "October FFVP Allocation", and cell E35 should match "Total FFVP Allocation". The cells labeled "July FFVP Allocation", "October FFVP Allocation", and "Total FFVP Allocation" will turn green if you've entered all the information correctly.
A10: FFVP School Information
A11: SFA/District Name | D11: ='School Budget (1)'!D11:F11 -> 0
A12: School Name
A13: # of Student Participating in FFVP
A14: July FFVP Allocation
A15: October FFVP Allocation
A16: Total FFVP Allocation | D16: =SUM(D14:F15) -> 0
A17: Total FFVP Funds Available per Student | D17: =D16/D13 -> #DIV/0!
A19: Projected Monthly FFVP Budget for SY 2014- 2015
A20: Allocation | B20: Month | C20: # of Serving Days per Month | D20: # of Servings per Month | E20: Total Monthly Budget | F20: Total Monthly Operational Cost Budget | G20: Total Montly Administrative Cost Budget
A21: July | B21: July | D21: =C21*$D$13 -> 0 | E21: =D21/$D$24*$D$14 -> #DIV/0! | F21: =E21-G21 -> #DIV/0! | G21: =E21*0.1 -> #DIV/0!
B22: August | D22: =C22*$D$13 -> 0 | E22: =D22/$D$24*$D$14 -> #DIV/0! | F22: =E22-G22 -> #DIV/0! | G22: =E22*0.1 -> #DIV/0!
B23: September | D23: =C23*$D$13 -> 0 | E23: =D23/$D$24*$D$14 -> #DIV/0! | F23: =E23-G23 -> #DIV/0! | G23: =E23*0.1 -> #DIV/0!
B24: July Totals | C24: =SUM(C21:C23) -> 0 | D24: =SUM(D21:D23) -> 0 | E24: =SUM(E21:E23) -> #DIV/0! | F24: =SUM(F21:F23) -> #DIV/0! | G24: =SUM(G21:G23) -> #DIV/0!
A25: October | B25: October | D25: =C25*$D$13 -> 0 | E25: =D25/$D$34*$D$15 -> #DIV/0! | F25: =E25-G25 -> #DIV/0! | G25: =E25*0.1 -> #DIV/0!
B26: November | D26: =C26*$D$13 -> 0 | E26: =D26/$D$34*$D$15 -> #DIV/0! | F26: =E26-G26 -> #DIV/0! | G26: =E26*0.1 -> #DIV/0!
B27: December | D27: =C27*$D$13 -> 0 | E27: =D27/$D$34*$D$15 -> #DIV/0! | F27: =E27-G27 -> #DIV/0! | G27: =E27*0.1 -> #DIV/0!
B28: January | D28: =C28*$D$13 -> 0 | E28: =D28/$D$34*$D$15 -> #DIV/0! | F28: =E28-G28 -> #DIV/0! | G28: =E28*0.1 -> #DIV/0!
B29: February | D29: =C29*$D$13 -> 0 | E29: =D29/$D$34*$D$15 -> #DIV/0! | F29: =E29-G29 -> #DIV/0! | G29: =E29*0.1 -> #DIV/0!
B30: March | D30: =C30*$D$13 -> 0 | E30: =D30/$D$34*$D$15 -> #DIV/0! | F30: =E30-G30 -> #DIV/0! | G30: =E30*0.1 -> #DIV/0!
B31: April | D31: =C31*$D$13 -> 0 | E31: =D31/$D$34*$D$15 -> #DIV/0! | F31: =E31-G31 -> #DIV/0! | G31: =E31*0.1 -> #DIV/0!
B32: May | D32: =C32*$D$13 -> 0 | E32: =D32/$D$34*$D$15 -> #DIV/0! | F32: =E32-G32 -> #DIV/0! | G32: =E32*0.1 -> #DIV/0!
B33: June | D33: =C33*$D$13 -> 0 | E33: =D33/$D$34*$D$15 -> #DIV/0! | F33: =E33-G33 -> #DIV/0! | G33: =E33*0.1 -> #DIV/0!
B34: October Totals | C34: =SUM(C25:C33) -> 0 | D34: =SUM(D25:D33) -> 0 | E34: =SUM(E25:E33) -> #DIV/0! | F34: =SUM(F25:F33) -> #DIV/0! | G34: =SUM(G25:G33) -> #DIV/0!
A35: Totals | C35: =SUM(C24,C34) -> 0 | D35: =SUM(D24,D34) -> 0 | E35: =SUM(E24,E34) -> #DIV/0! | F35: =SUM(F24,F34) -> #DIV/0! | G35: =SUM(G24,G34) -> #DIV/0!

Sheet School Budget (14)
A1: Fresh Fruit & Vegetable Program Projected Budget Tool for SY 2014-2015
A5: Instructions: The tool will determine your monthly budget based on your school's enrollment and the # of serving days per month.
A6: Step 1. Enter data into grey-colored cells in the "FFVP School Information" table.
A7: Step 2. Enter the "# of Serving Days per Month" for each month (July-June) in the "Projected Monthly FFVP Budget for SY 2014-2015" table. You must fill in the entire table to determine your monthly budget.
A8: Step 3. Check your work! Cell E24 should match "July FFVP Allocation", cell E34 should match "October FFVP Allocation", and cell E35 should match "Total FFVP Allocation". The cells labeled "July FFVP Allocation", "October FFVP Allocation", and "Total FFVP Allocation" will turn green if you've entered all the information correctly.
A10: FFVP School Information
A11: SFA/District Name | D11: ='School Budget (1)'!D11:F11 -> 0
A12: School Name
A13: # of Student Participating in FFVP
A14: July FFVP Allocation
A15: October FFVP Allocation
A16: Total FFVP Allocation | D16: =SUM(D14:F15) -> 0
A17: Total FFVP Funds Available per Student | D17: =D16/D13 -> #DIV/0!
A19: Projected Monthly FFVP Budget for SY 2014- 2015
A20: Allocation | B20: Month | C20: # of Serving Days per Month | D20: # of Servings per Month | E20: Total Monthly Budget | F20: Total Monthly Operational Cost Budget | G20: Total Montly Administrative Cost Budget
A21: July | B21: July | D21: =C21*$D$13 -> 0 | E21: =D21/$D$24*$D$14 -> #DIV/0! | F21: =E21-G21 -> #DIV/0! | G21: =E21*0.1 -> #DIV/0!
B22: August | D22: =C22*$D$13 -> 0 | E22: =D22/$D$24*$D$14 -> #DIV/0! | F22: =E22-G22 -> #DIV/0! | G22: =E22*0.1 -> #DIV/0!
B23: September | D23: =C23*$D$13 -> 0 | E23: =D23/$D$24*$D$14 -> #DIV/0! | F23: =E23-G23 -> #DIV/0! | G23: =E23*0.1 -> #DIV/0!
B24: July Totals | C24: =SUM(C21:C23) -> 0 | D24: =SUM(D21:D23) -> 0 | E24: =SUM(E21:E23) -> #DIV/0! | F24: =SUM(F21:F23) -> #DIV/0! | G24: =SUM(G21:G23) -> #DIV/0!
A25: October | B25: October | D25: =C25*$D$13 -> 0 | E25: =D25/$D$34*$D$15 -> #DIV/0! | F25: =E25-G25 -> #DIV/0! | G25: =E25*0.1 -> #DIV/0!
B26: November | D26: =C26*$D$13 -> 0 | E26: =D26/$D$34*$D$15 -> #DIV/0! | F26: =E26-G26 -> #DIV/0! | G26: =E26*0.1 -> #DIV/0!
B27: December | D27: =C27*$D$13 -> 0 | E27: =D27/$D$34*$D$15 -> #DIV/0! | F27: =E27-G27 -> #DIV/0! | G27: =E27*0.1 -> #DIV/0!
B28: January | D28: =C28*$D$13 -> 0 | E28: =D28/$D$34*$D$15 -> #DIV/0! | F28: =E28-G28 -> #DIV/0! | G28: =E28*0.1 -> #DIV/0!
B29: February | D29: =C29*$D$13 -> 0 | E29: =D29/$D$34*$D$15 -> #DIV/0! | F29: =E29-G29 -> #DIV/0! | G29: =E29*0.1 -> #DIV/0!
B30: March | D30: =C30*$D$13 -> 0 | E30: =D30/$D$34*$D$15 -> #DIV/0! | F30: =E30-G30 -> #DIV/0! | G30: =E30*0.1 -> #DIV/0!
B31: April | D31: =C31*$D$13 -> 0 | E31: =D31/$D$34*$D$15 -> #DIV/0! | F31: =E31-G31 -> #DIV/0! | G31: =E31*0.1 -> #DIV/0!
B32: May | D32: =C32*$D$13 -> 0 | E32: =D32/$D$34*$D$15 -> #DIV/0! | F32: =E32-G32 -> #DIV/0! | G32: =E32*0.1 -> #DIV/0!
B33: June | D33: =C33*$D$13 -> 0 | E33: =D33/$D$34*$D$15 -> #DIV/0! | F33: =E33-G33 -> #DIV/0! | G33: =E33*0.1 -> #DIV/0!
B34: October Totals | C34: =SUM(C25:C33) -> 0 | D34: =SUM(D25:D33) -> 0 | E34: =SUM(E25:E33) -> #DIV/0! | F34: =SUM(F25:F33) -> #DIV/0! | G34: =SUM(G25:G33) -> #DIV/0!
A35: Totals | C35: =SUM(C24,C34) -> 0 | D35: =SUM(D24,D34) -> 0 | E35: =SUM(E24,E34) -> #DIV/0! | F35: =SUM(F24,F34) -> #DIV/0! | G35: =SUM(G24,G34) -> #DIV/0!

Sheet School Budget (15)
A1: Fresh Fruit & Vegetable Program Projected Budget Tool for SY 2014-2015
A5: Instructions: The tool will determine your monthly budget based on your school's enrollment and the # of serving days per month.
A6: Step 1. Enter data into grey-colored cells in the "FFVP School Information" table.
A7: Step 2. Enter the "# of Serving Days per Month" for each month (July-June) in the "Projected Monthly FFVP Budget for SY 2014-2015" table. You must fill in the entire table to determine your monthly budget.
A8: Step 3. Check your work! Cell E24 should match "July FFVP Allocation", cell E34 should match "October FFVP Allocation", and cell E35 should match "Total FFVP Allocation". The cells labeled "July FFVP Allocation", "October FFVP Allocation", and "Total FFVP Allocation" will turn green if you've entered all the information correctly.
A10: FFVP School Information
A11: SFA/District Name | D11: ='School Budget (1)'!D11:F11 -> 0
A12: School Name
A13: # of Student Participating in FFVP
A14: July FFVP Allocation
A15: October FFVP Allocation
A16: Total FFVP Allocation | D16: =SUM(D14:F15) -> 0
A17: Total FFVP Funds Available per Student | D17: =D16/D13 -> #DIV/0!
A19: Projected Monthly FFVP Budget for SY 2014- 2015
A20: Allocation | B20: Month | C20: # of Serving Days per Month | D20: # of Servings per Month | E20: Total Monthly Budget | F20: Total Monthly Operational Cost Budget | G20: Total Montly Administrative Cost Budget
A21: July | B21: July | D21: =C21*$D$13 -> 0 | E21: =D21/$D$24*$D$14 -> #DIV/0! | F21: =E21-G21 -> #DIV/0! | G21: =E21*0.1 -> #DIV/0!
B22: August | D22: =C22*$D$13 -> 0 | E22: =D22/$D$24*$D$14 -> #DIV/0! | F22: =E22-G22 -> #DIV/0! | G22: =E22*0.1 -> #DIV/0!
B23: September | D23: =C23*$D$13 -> 0 | E23: =D23/$D$24*$D$14 -> #DIV/0! | F23: =E23-G23 -> #DIV/0! | G23: =E23*0.1 -> #DIV/0!
B24: July Totals | C24: =SUM(C21:C23) -> 0 | D24: =SUM(D21:D23) -> 0 | E24: =SUM(E21:E23) -> #DIV/0! | F24: =SUM(F21:F23) -> #DIV/0! | G24: =SUM(G21:G23) -> #DIV/0!
A25: October | B25: October | D25: =C25*$D$13 -> 0 | E25: =D25/$D$34*$D$15 -> #DIV/0! | F25: =E25-G25 -> #DIV/0! | G25: =E25*0.1 -> #DIV/0!
B26: November | D26: =C26*$D$13 -> 0 | E26: =D26/$D$34*$D$15 -> #DIV/0! | F26: =E26-G26 -> #DIV/0! | G26: =E26*0.1 -> #DIV/0!
B27: December | D27: =C27*$D$13 -> 0 | E27: =D27/$D$34*$D$15 -> #DIV/0! | F27: =E27-G27 -> #DIV/0! | G27: =E27*0.1 -> #DIV/0!
B28: January | D28: =C28*$D$13 -> 0 | E28: =D28/$D$34*$D$15 -> #DIV/0! | F28: =E28-G28 -> #DIV/0! | G28: =E28*0.1 -> #DIV/0!
B29: February | D29: =C29*$D$13 -> 0 | E29: =D29/$D$34*$D$15 -> #DIV/0! | F29: =E29-G29 -> #DIV/0! | G29: =E29*0.1 -> #DIV/0!
B30: March | D30: =C30*$D$13 -> 0 | E30: =D30/$D$34*$D$15 -> #DIV/0! | F30: =E30-G30 -> #DIV/0! | G30: =E30*0.1 -> #DIV/0!
B31: April | D31: =C31*$D$13 -> 0 | E31: =D31/$D$34*$D$15 -> #DIV/0! | F31: =E31-G31 -> #DIV/0! | G31: =E31*0.1 -> #DIV/0!
B32: May | D32: =C32*$D$13 -> 0 | E32: =D32/$D$34*$D$15 -> #DIV/0! | F32: =E32-G32 -> #DIV/0! | G32: =E32*0.1 -> #DIV/0!
B33: June | D33: =C33*$D$13 -> 0 | E33: =D33/$D$34*$D$15 -> #DIV/0! | F33: =E33-G33 -> #DIV/0! | G33: =E33*0.1 -> #DIV/0!
B34: October Totals | C34: =SUM(C25:C33) -> 0 | D34: =SUM(D25:D33) -> 0 | E34: =SUM(E25:E33) -> #DIV/0! | F34: =SUM(F25:F33) -> #DIV/0! | G34: =SUM(G25:G33) -> #DIV/0!
A35: Totals | C35: =SUM(C24,C34) -> 0 | D35: =SUM(D24,D34) -> 0 | E35: =SUM(E24,E34) -> #DIV/0! | F35: =SUM(F24,F34) -> #DIV/0! | G35: =SUM(G24,G34) -> #DIV/0!

Sheet School Budget (16)
A1: Fresh Fruit & Vegetable Program Projected Budget Tool for SY 2014-2015
A5: Instructions: The tool will determine your monthly budget based on your school's enrollment and the # of serving days per month.
A6: Step 1. Enter data into grey-colored cells in the "FFVP School Information" table.
A7: Step 2. Enter the "# of Serving Days per Month" for each month (July-June) in the "Projected Monthly FFVP Budget for SY 2014-2015" table. You must fill in the entire table to determine your monthly budget.
A8: Step 3. Check your work! Cell E24 should match "July FFVP Allocation", cell E34 should match "October FFVP Allocation", and cell E35 should match "Total FFVP Allocation". The cells labeled "July FFVP Allocation", "October FFVP Allocation", and "Total FFVP Allocation" will turn green if you've entered all the information correctly.
A10: FFVP School Information
A11: SFA/District Name | D11: ='School Budget (1)'!D11:F11 -> 0
A12: School Name
A13: # of Student Participating in FFVP
A14: July FFVP Allocation
A15: October FFVP Allocation
A16: Total FFVP Allocation | D16: =SUM(D14:F15) -> 0
A17: Total FFVP Funds Available per Student | D17: =D16/D13 -> #DIV/0!
A19: Projected Monthly FFVP Budget for SY 2014- 2015
A20: Allocation | B20: Month | C20: # of Serving Days per Month | D20: # of Servings per Month | E20: Total Monthly Budget | F20: Total Monthly Operational Cost Budget | G20: Total Montly Administrative Cost Budget
A21: July | B21: July | D21: =C21*$D$13 -> 0 | E21: =D21/$D$24*$D$14 -> #DIV/0! | F21: =E21-G21 -> #DIV/0! | G21: =E21*0.1 -> #DIV/0!
B22: August | D22: =C22*$D$13 -> 0 | E22: =D22/$D$24*$D$14 -> #DIV/0! | F22: =E22-G22 -> #DIV/0! | G22: =E22*0.1 -> #DIV/0!
B23: September | D23: =C23*$D$13 -> 0 | E23: =D23/$D$24*$D$14 -> #DIV/0! | F23: =E23-G23 -> #DIV/0! | G23: =E23*0.1 -> #DIV/0!
B24: July Totals | C24: =SUM(C21:C23) -> 0 | D24: =SUM(D21:D23) -> 0 | E24: =SUM(E21:E23) -> #DIV/0! | F24: =SUM(F21:F23) -> #DIV/0! | G24: =SUM(G21:G23) -> #DIV/0!
A25: October | B25: October | D25: =C25*$D$13 -> 0 | E25: =D25/$D$34*$D$15 -> #DIV/0! | F25: =E25-G25 -> #DIV/0! | G25: =E25*0.1 -> #DIV/0!
B26: November | D26: =C26*$D$13 -> 0 | E26: =D26/$D$34*$D$15 -> #DIV/0! | F26: =E26-G26 -> #DIV/0! | G26: =E26*0.1 -> #DIV/0!
B27: December | D27: =C27*$D$13 -> 0 | E27: =D27/$D$34*$D$15 -> #DIV/0! | F27: =E27-G27 -> #DIV/0! | G27: =E27*0.1 -> #DIV/0!
B28: January | D28: =C28*$D$13 -> 0 | E28: =D28/$D$34*$D$15 -> #DIV/0! | F28: =E28-G28 -> #DIV/0! | G28: =E28*0.1 -> #DIV/0!
B29: February | D29: =C29*$D$13 -> 0 | E29: =D29/$D$34*$D$15 -> #DIV/0! | F29: =E29-G29 -> #DIV/0! | G29: =E29*0.1 -> #DIV/0!
B30: March | D30: =C30*$D$13 -> 0 | E30: =D30/$D$34*$D$15 -> #DIV/0! | F30: =E30-G30 -> #DIV/0! | G30: =E30*0.1 -> #DIV/0!
B31: April | D31: =C31*$D$13 -> 0 | E31: =D31/$D$34*$D$15 -> #DIV/0! | F31: =E31-G31 -> #DIV/0! | G31: =E31*0.1 -> #DIV/0!
B32: May | D32: =C32*$D$13 -> 0 | E32: =D32/$D$34*$D$15 -> #DIV/0! | F32: =E32-G32 -> #DIV/0! | G32: =E32*0.1 -> #DIV/0!
B33: June | D33: =C33*$D$13 -> 0 | E33: =D33/$D$34*$D$15 -> #DIV/0! | F33: =E33-G33 -> #DIV/0! | G33: =E33*0.1 -> #DIV/0!
B34: October Totals | C34: =SUM(C25:C33) -> 0 | D34: =SUM(D25:D33) -> 0 | E34: =SUM(E25:E33) -> #DIV/0! | F34: =SUM(F25:F33) -> #DIV/0! | G34: =SUM(G25:G33) -> #DIV/0!
A35: Totals | C35: =SUM(C24,C34) -> 0 | D35: =SUM(D24,D34) -> 0 | E35: =SUM(E24,E34) -> #DIV/0! | F35: =SUM(F24,F34) -> #DIV/0! | G35: =SUM(G24,G34) -> #DIV/0!

Sheet School Budget (17)
A1: Fresh Fruit & Vegetable Program Projected Budget Tool for SY 2014-2015
A5: Instructions: The tool will determine your monthly budget based on your school's enrollment and the # of serving days per month.
A6: Step 1. Enter data into grey-colored cells in the "FFVP School Information" table.
A7: Step 2. Enter the "# of Serving Days per Month" for each month (July-June) in the "Projected Monthly FFVP Budget for SY 2014-2015" table. You must fill in the entire table to determine your monthly budget.
A8: Step 3. Check your work! Cell E24 should match "July FFVP Allocation", cell E34 should match "October FFVP Allocation", and cell E35 should match "Total FFVP Allocation". The cells labeled "July FFVP Allocation", "October FFVP Allocation", and "Total FFVP Allocation" will turn green if you've entered all the information correctly.
A10: FFVP School Information
A11: SFA/District Name | D11: ='School Budget (1)'!D11:F11 -> 0
A12: School Name
A13: # of Student Participating in FFVP
A14: July FFVP Allocation
A15: October FFVP Allocation
A16: Total FFVP Allocation | D16: =SUM(D14:F15) -> 0
A17: Total FFVP Funds Available per Student | D17: =D16/D13 -> #DIV/0!
A19: Projected Monthly FFVP Budget for SY 2014- 2015
A20: Allocation | B20: Month | C20: # of Serving Days per Month | D20: # of Servings per Month | E20: Total Monthly Budget | F20: Total Monthly Operational Cost Budget | G20: Total Montly Administrative Cost Budget
A21: July | B21: July | D21: =C21*$D$13 -> 0 | E21: =D21/$D$24*$D$14 -> #DIV/0! | F21: =E21-G21 -> #DIV/0! | G21: =E21*0.1 -> #DIV/0!
B22: August | D22: =C22*$D$13 -> 0 | E22: =D22/$D$24*$D$14 -> #DIV/0! | F22: =E22-G22 -> #DIV/0! | G22: =E22*0.1 -> #DIV/0!
B23: September | D23: =C23*$D$13 -> 0 | E23: =D23/$D$24*$D$14 -> #DIV/0! | F23: =E23-G23 -> #DIV/0! | G23: =E23*0.1 -> #DIV/0!
B24: July Totals | C24: =SUM(C21:C23) -> 0 | D24: =SUM(D21:D23) -> 0 | E24: =SUM(E21:E23) -> #DIV/0! | F24: =SUM(F21:F23) -> #DIV/0! | G24: =SUM(G21:G23) -> #DIV/0!
A25: October | B25: October | D25: =C25*$D$13 -> 0 | E25: =D25/$D$34*$D$15 -> #DIV/0! | F25: =E25-G25 -> #DIV/0! | G25: =E25*0.1 -> #DIV/0!
B26: November | D26: =C26*$D$13 -> 0 | E26: =D26/$D$34*$D$15 -> #DIV/0! | F26: =E26-G26 -> #DIV/0! | G26: =E26*0.1 -> #DIV/0!
B27: December | D27: =C27*$D$13 -> 0 | E27: =D27/$D$34*$D$15 -> #DIV/0! | F27: =E27-G27 -> #DIV/0! | G27: =E27*0.1 -> #DIV/0!
B28: January | D28: =C28*$D$13 -> 0 | E28: =D28/$D$34*$D$15 -> #DIV/0! | F28: =E28-G28 -> #DIV/0! | G28: =E28*0.1 -> #DIV/0!
B29: February | D29: =C29*$D$13 -> 0 | E29: =D29/$D$34*$D$15 -> #DIV/0! | F29: =E29-G29 -> #DIV/0! | G29: =E29*0.1 -> #DIV/0!
B30: March | D30: =C30*$D$13 -> 0 | E30: =D30/$D$34*$D$15 -> #DIV/0! | F30: =E30-G30 -> #DIV/0! | G30: =E30*0.1 -> #DIV/0!
B31: April | D31: =C31*$D$13 -> 0 | E31: =D31/$D$34*$D$15 -> #DIV/0! | F31: =E31-G31 -> #DIV/0! | G31: =E31*0.1 -> #DIV/0!
B32: May | D32: =C32*$D$13 -> 0 | E32: =D32/$D$34*$D$15 -> #DIV/0! | F32: =E32-G32 -> #DIV/0! | G32: =E32*0.1 -> #DIV/0!
B33: June | D33: =C33*$D$13 -> 0 | E33: =D33/$D$34*$D$15 -> #DIV/0! | F33: =E33-G33 -> #DIV/0! | G33: =E33*0.1 -> #DIV/0!
B34: October Totals | C34: =SUM(C25:C33) -> 0 | D34: =SUM(D25:D33) -> 0 | E34: =SUM(E25:E33) -> #DIV/0! | F34: =SUM(F25:F33) -> #DIV/0! | G34: =SUM(G25:G33) -> #DIV/0!
A35: Totals | C35: =SUM(C24,C34) -> 0 | D35: =SUM(D24,D34) -> 0 | E35: =SUM(E24,E34) -> #DIV/0! | F35: =SUM(F24,F34) -> #DIV/0! | G35: =SUM(G24,G34) -> #DIV/0!

Sheet School Budget (18)
A1: Fresh Fruit & Vegetable Program Projected Budget Tool for SY 2014-2015
A5: Instructions: The tool will determine your monthly budget based on your school's enrollment and the # of serving days per month.
A6: Step 1. Enter data into grey-colored cells in the "FFVP School Information" table.
A7: Step 2. Enter the "# of Serving Days per Month" for each month (July-June) in the "Projected Monthly FFVP Budget for SY 2014-2015" table. You must fill in the entire table to determine your monthly budget.
A8: Step 3. Check your work! Cell E24 should match "July FFVP Allocation", cell E34 should match "October FFVP Allocation", and cell E35 should match "Total FFVP Allocation". The cells labeled "July FFVP Allocation", "October FFVP Allocation", and "Total FFVP Allocation" will turn green if you've entered all the information correctly.
A10: FFVP School Information
