Workbook

Sheet Natural Gas
A1: Meter Read Dates
A2: Natural Gas Bill Information | D2: Calculated Values
A3: From Date | B3: To Date | C3: Therms /Month | D3: Days | E3: Average Temp | F3: Average BTU/Hr | G3: Avg. Watts
A9: =B10+1 -> 41653 | B9: =L9-K9 -> 41681 | C9: 12.897 | D9: =B9-A9 -> 28 | E9: =AVERAGEIFS('Temperature Data'!B$4:B$2116,'Temperature Data'!A$4:A$2116,">="&A9,'Temperature Data'!A$4:A$2116,"<="&B9) -> 34.275862 | F9: =C9*100000/D9/24 -> 1919.1964 | G9: =F9/3.413 -> 562.31949 | K9: 2 | L9: 41683
A10: =B11+1 -> 41619 | B10: =L10-K10 -> 41652 | C10: 11.076 | D10: =B10-A10 -> 33 | E10: =AVERAGEIFS('Temperature Data'!B$4:B$2116,'Temperature Data'!A$4:A$2116,">="&A10,'Temperature Data'!A$4:A$2116,"<="&B10) -> 38.411765 | F10: =C10*100000/D10/24 -> 1398.4848 | G10: =F10/3.413 -> 409.75237 | K10: 2 | L10: 41654
A11: =B12+1 -> 41588 | B11: =L11-K11 -> 41618 | C11: 8.485 | D11: =B11-A11 -> 30 | E11: =AVERAGEIFS('Temperature Data'!B$4:B$2116,'Temperature Data'!A$4:A$2116,">="&A11,'Temperature Data'!A$4:A$2116,"<="&B11) -> 42 | F11: =C11*100000/D11/24 -> 1178.4722 | G11: =F11/3.413 -> 345.28925 | K11: 2 | L11: 41620
A12: =B13+1 -> 41553 | B12: =L12-K12 -> 41587 | C12: 4.643 | D12: =B12-A12 -> 34 | E12: =AVERAGEIFS('Temperature Data'!B$4:B$2116,'Temperature Data'!A$4:A$2116,">="&A12,'Temperature Data'!A$4:A$2116,"<="&B12) -> 58.828571 | F12: =C12*100000/D12/24 -> 568.9951 | G12: =F12/3.413 -> 166.71406 | K12: 2 | L12: 41589
A13: =B14+1 -> 41525 | B13: =L13-K13 -> 41552 | C13: 1.472 | D13: =B13-A13 -> 27 | E13: =AVERAGEIFS('Temperature Data'!B$4:B$2116,'Temperature Data'!A$4:A$2116,">="&A13,'Temperature Data'!A$4:A$2116,"<="&B13) -> 74.821429 | F13: =C13*100000/D13/24 -> 227.16049 | G13: =F13/3.413 -> 66.557426 | K13: 5 | L13: 41557
A14: =B15+1 -> 41496 | B14: =L14-K14 -> 41524 | C14: 1.36 | D14: =B14-A14 -> 28 | E14: =AVERAGEIFS('Temperature Data'!B$4:B$2116,'Temperature Data'!A$4:A$2116,">="&A14,'Temperature Data'!A$4:A$2116,"<="&B14) -> 80.827586 | F14: =C14*100000/D14/24 -> 202.38095 | G14: =F14/3.413 -> 59.297085 | K14: 4 | L14: 41528
A15: =B16+1 -> 41465 | B15: =L15-K15 -> 41495 | C15: 1.355 | D15: =B15-A15 -> 30 | E15: =AVERAGEIFS('Temperature Data'!B$4:B$2116,'Temperature Data'!A$4:A$2116,">="&A15,'Temperature Data'!A$4:A$2116,"<="&B15) -> 83.064516 | F15: =C15*100000/D15/24 -> 188.19444 | G15: =F15/3.413 -> 55.140476 | K15: 3 | L15: 41498
A16: =B17+1 -> 41435 | B16: =L16-K16 -> 41464 | C16: 1.466 | D16: =B16-A16 -> 29 | E16: =AVERAGEIFS('Temperature Data'!B$4:B$2116,'Temperature Data'!A$4:A$2116,">="&A16,'Temperature Data'!A$4:A$2116,"<="&B16) -> 81.366667 | F16: =C16*100000/D16/24 -> 210.63218 | G16: =F16/3.413 -> 61.714674 | K16: 3 | L16: 41467
A17: =B18+1 -> 41405 | B17: =L17-K17 -> 41434 | C17: 1.351 | D17: =B17-A17 -> 29 | E17: =AVERAGEIFS('Temperature Data'!B$4:B$2116,'Temperature Data'!A$4:A$2116,">="&A17,'Temperature Data'!A$4:A$2116,"<="&B17) -> 71.3 | F17: =C17*100000/D17/24 -> 194.1092 | G17: =F17/3.413 -> 56.873482 | K17: 3 | L17: 41437
A18: =B19+1 -> 41375 | B18: =L18-K18 -> 41404 | C18: 4.612 | D18: =B18-A18 -> 29 | E18: =AVERAGEIFS('Temperature Data'!B$4:B$2116,'Temperature Data'!A$4:A$2116,">="&A18,'Temperature Data'!A$4:A$2116,"<="&B18) -> 57.8 | F18: =C18*100000/D18/24 -> 662.64368 | G18: =F18/3.413 -> 194.15285 | K18: 3 | L18: 41407
A19: =B20+1 -> 41347 | B19: =L19-K19 -> 41374 | C19: 5.849 | D19: =B19-A19 -> 27 | E19: =AVERAGEIFS('Temperature Data'!B$4:B$2116,'Temperature Data'!A$4:A$2116,">="&A19,'Temperature Data'!A$4:A$2116,"<="&B19) -> 51.892857 | F19: =C19*100000/D19/24 -> 902.62346 | G19: =F19/3.413 -> 264.46629 | K19: 2 | L19: 41376
A20: =B21+1 -> 41314 | B20: =L20-K20 -> 41346 | C20: 9.692 | D20: =B20-A20 -> 32 | E20: =AVERAGEIFS('Temperature Data'!B$4:B$2116,'Temperature Data'!A$4:A$2116,">="&A20,'Temperature Data'!A$4:A$2116,"<="&B20) -> 43.393939 | F20: =C20*100000/D20/24 -> 1261.9792 | G20: =F20/3.413 -> 369.75657 | K20: 1 | L20: 41347
... A29: =B30+1 -> 41036 | B29: =L29-K29 -> 41068 | C29: 1.238 | D29: =B29-A29 -> 32 | E29: =AVERAGEIFS('Temperature Data'!B$4:B$2116,'Temperature Data'!A$4:A$2116,">="&A29,'Temperature Data'!A$4:A$2116,"<="&B29) -> 71.969697 | F29: =C29*100000/D29/24 -> 161.19792 | G29: =F29/3.413 -> 47.230565 | K29: 4 | L29: 41072
A30: =B31+1 -> 41007 | B30: =L30-K30 -> 41035 | C30: 1.464 | D30: =COUNTIFS('Temperature Data'!A3:A1120,">="&A30,'Temperature Data'!A3:A1120,"<="&B30) -> 29 | E30: =AVERAGEIFS('Temperature Data'!B$4:B$2116,'Temperature Data'!A$4:A$2116,">="&A30,'Temperature Data'!A$4:A$2116,"<="&B30) -> 68.310345 | F30: =C30*100000/D30/24 -> 210.34483 | G30: =F30/3.413 -> 61.63048 | K30: 4 | L30: 41039
A31: =B32+1 -> 40978 | B31: =L31-K31 -> 41006 | C31: 2.254 | D31: =COUNTIFS('Temperature Data'!A42:A1120,">="&A31,'Temperature Data'!A42:A1120,"<="&B31) -> 29 | E31: =AVERAGEIFS('Temperature Data'!B$4:B$2116,'Temperature Data'!A$4:A$2116,">="&A31,'Temperature Data'!A$4:A$2116,"<="&B31) -> 63.827586 | F31: =C31*100000/D31/24 -> 323.85057 | G31: =F31/3.413 -> 94.887364 | K31: 4 | L31: 41010
A32: =B33+1 -> 40949 | B32: =L32-K32 -> 40977 | C32: 6.781 | D32: =B32-A32 -> 28 | E32: =AVERAGEIFS('Temperature Data'!B$4:B$2116,'Temperature Data'!A$4:A$2116,">="&A32,'Temperature Data'!A$4:A$2116,"<="&B32) -> 48.310345 | F32: =C32*100000/D32/24 -> 1009.0774 | G32: =F32/3.413 -> 295.65701 | K32: 4 | L32: 40981
A33: =B34+1 -> 40920 | B33: =L33-K33 -> 40948 | C33: 9.128 | D33: =B33-A33 -> 28 | E33: =AVERAGEIFS('Temperature Data'!B$4:B$2116,'Temperature Data'!A$4:A$2116,">="&A33,'Temperature Data'!A$4:A$2116,"<="&B33) -> 43.793103 | F33: =C33*100000/D33/24 -> 1358.3333 | G33: =F33/3.413 -> 397.98808 | K33: 4 | L33: 40952
A34: =B35+1 -> 40886 | B34: =L34-K34 -> 40919 | C34: 10.573 | D34: =B34-A34 -> 33 | E34: =AVERAGEIFS('Temperature Data'!B$4:B$2116,'Temperature Data'!A$4:A$2116,">="&A34,'Temperature Data'!A$4:A$2116,"<="&B34) -> 43.205882 | F34: =C34*100000/D34/24 -> 1334.9747 | G34: =F34/3.413 -> 391.14408 | K34: 2 | L34: 40921
A35: =B36+1 -> 40853 | B35: =L35-K35 -> 40885 | C35: 6.946 | D35: =B35-A35 -> 32 | E35: =AVERAGEIFS('Temperature Data'!B$4:B$2116,'Temperature Data'!A$4:A$2116,">="&A35,'Temperature Data'!A$4:A$2116,"<="&B35) -> 47.30303 | F35: =C35*100000/D35/24 -> 904.42708 | G35: =F35/3.413 -> 264.99475 | K35: 4 | L35: 40889
A36: =B37+1 -> 40824 | B36: =L36-K36 -> 40852 | C36: 2.572 | D36: =B36-A36 -> 28 | E36: =AVERAGEIFS('Temperature Data'!B$4:B$2116,'Temperature Data'!A$4:A$2116,">="&A36,'Temperature Data'!A$4:A$2116,"<="&B36) -> 59.689655 | F36: =C36*100000/D36/24 -> 382.7381 | G36: =F36/3.413 -> 112.14125 | K36: 4 | L36: 40856
A37: =B38+1 -> 40795 | B37: =L37-K37 -> 40823 | C37: 1.232 | D37: =B37-A37 -> 28 | E37: =AVERAGEIFS('Temperature Data'!B$4:B$2116,'Temperature Data'!A$4:A$2116,">="&A37,'Temperature Data'!A$4:A$2116,"<="&B37) -> 71.034483 | F37: =C37*100000/D37/24 -> 183.33333 | G37: =F37/3.413 -> 53.716183 | K37: 4 | L37: 40827
A38: =B39+1 -> 40763 | B38: =L38-K38 -> 40794 | C38: 0.785 | D38: =B38-A38 -> 31 | E38: =AVERAGEIFS('Temperature Data'!B$4:B$2116,'Temperature Data'!A$4:A$2116,">="&A38,'Temperature Data'!A$4:A$2116,"<="&B38) -> 85.15625 | F38: =C38*100000/D38/24 -> 105.51075 | G38: =F38/3.413 -> 30.914372 | K38: 4 | L38: 40798
A39: =B40+1 -> 40734 | B39: =L39-K39 -> 40762 | C39: 0.895 | D39: =B39-A39 -> 28 | E39: =AVERAGEIFS('Temperature Data'!B$4:B$2116,'Temperature Data'!A$4:A$2116,">="&A39,'Temperature Data'!A$4:A$2116,"<="&B39) -> 90.413793 | F39: =C39*100000/D39/24 -> 133.18452 | G39: =F39/3.413 -> 39.022714 | K39: 4 | L39: 40766
A40: =B41+1 -> 40704 | B40: =L40-K40 -> 40733 | C40: 1.346 | D40: =B40-A40 -> 29 | E40: =AVERAGEIFS('Temperature Data'!B$4:B$2116,'Temperature Data'!A$4:A$2116,">="&A40,'Temperature Data'!A$4:A$2116,"<="&B40) -> 86.633333 | F40: =C40*100000/D40/24 -> 193.3908 | G40: =F40/3.413 -> 56.662996 | K40: 4 | L40: 40737
A41: =B42+1 -> 40672 | B41: =L41-K41 -> 40703 | C41: 1.234 | D41: =B41-A41 -> 31 | E41: =AVERAGEIFS('Temperature Data'!B$4:B$2116,'Temperature Data'!A$4:A$2116,">="&A41,'Temperature Data'!A$4:A$2116,"<="&B41) -> 74.375 | F41: =C41*100000/D41/24 -> 165.86022 | G41: =F41/3.413 -> 48.596606 | K41: 4 | L41: 40707
A42: =B43+1 -> 40642 | B42: =L42-K42 -> 40671 | C42: 2.127 | D42: =B42-A42 -> 29 | E42: =AVERAGEIFS('Temperature Data'!B$4:B$2116,'Temperature Data'!A$4:A$2116,">="&A42,'Temperature Data'!A$4:A$2116,"<="&B42) -> 64.266667 | F42: =C42*100000/D42/24 -> 305.60345 | G42: =F42/3.413 -> 89.541004 | K42: 4 | L42: 40675
A43: =B44+1 -> 40615 | B43: =L43-K43 -> 40641 | C43: 4.033 | D43: =B43-A43 -> 26 | E43: =AVERAGEIFS('Temperature Data'!B$4:B$2116,'Temperature Data'!A$4:A$2116,">="&A43,'Temperature Data'!A$4:A$2116,"<="&B43) -> 58.740741 | F43: =C43*100000/D43/24 -> 646.3141 | G43: =F43/3.413 -> 189.36833 | K43: 4 | L43: 40645
A44: =B45+1 -> 40581 | B44: =L44-K44 -> 40614 | C44: 6.933 | D44: =B44-A44 -> 33 | E44: =AVERAGEIFS('Temperature Data'!B$4:B$2116,'Temperature Data'!A$4:A$2116,">="&A44,'Temperature Data'!A$4:A$2116,"<="&B44) -> 53.178571 | F44: =C44*100000/D44/24 -> 875.37879 | G44: =F44/3.413 -> 256.48368 | K44: 2 | L44: 40616
A45: =#REF!+1 -> #REF! | B45: =L45-K45 -> 40580 | K45: 7 | L45: 40587

Sheet Temperature Data
A1: WEATHER AND PRECIPITATION
A3: DATE | B3: AVG
A4: 40587 | B4: 50 | D4: 50
A5: 40588 | B5: 53 | D5: 53
A6: 40589 | B6: 57 | D6: 57
A7: 40590 | B7: 57 | D7: 57
A8: 40591 | B8: 69 | D8: 69
A9: 40592 | B9: 61 | D9: 61
A10: 40593 | B10: 67 | D10: 67
A11: 40594 | B11: 67 | D11: 67
A12: 40595 | B12: 50 | D12: 50
A13: 40596 | B13: 43 | D13: 43
A14: 40597 | B14: 65 | D14: 65
A15: 40598 | B15: 49 | D15: 49
... A348: 40931 | B348: 46 | D348: 46
A349: 40932 | B349: 50 | C349: 38 | D349: 50
A350: 40933 | B350: 45 | C350: 55 | D350: 45
A351: 40934 | B351: 44 | C351: 48 | D351: 44
A352: 40935 | B352: 49 | C352: 48 | D352: 49
A353: 40936 | B353: 39 | C353: 43 | D353: 39
A354: 40937 | B354: 43 | C354: 44 | D354: 43
A355: 40938 | B355: 50 | C355: 50 | D355: 50
A356: 40939 | B356: 55 | C356: 47 | D356: 55
A357: 40940 | B357: 51 | C357: 54 | D357: 51
A358: 40941 | B358: 52 | C358: 55 | D358: 52
A359: 40942 | B359: 55 | C359: 43 | D359: 55
A360: 40943 | B360: 41 | C360: 45 | D360: 41
... A377: 40960 | B377: 47 | C377: 66 | D377: 47
A378: 40961 | B378: 54 | D378: 54
A379: 40962 | B379: 55 | D379: 55
A380: 40963 | B380: 43 | D380: 43
A381: 40964 | B381: 45 | D381: 45
A382: 40965 | B382: 52 | D382: 52
A383: 40966 | B383: 56 | D383: 56
A384: 40967 | B384: 61 | D384: 61
A385: 40968 | B385: 52 | D385: 52
A386: 40969 | B386: 58 | D386: 58
A387: 40970 | B387: 52 | D387: 52
A388: 40971 | B388: 45 | D388: 45
A389: 40972 | B389: 50 | D389: 50
...
