Workbook

Sheet Cover

Sheet Introduction
A4: American Indian Higher Education Consortium
A5: American Indian Measures for Success (AIMS)
A7: AIMS-Key Indicator System 2011 (AKIS-2011)

Sheet INSTRUCTIONS
A1: American Indian Higher Education Consortium
A2: American Indian Measures for Success (AIMS)
A4: AIMS-Key Indicator System 2011 (AKIS-2011)
A6: INSTRUCTIONS

Sheet 1.1 Overall Institution Profile
A1: Institution | B1: =B5 -> Oglala Lakota College | K1: degree
A2: Indicator 1: Overall Institution Profile | K2: 4-year & master's
A3: Table 1.1: Institution Profile, Contact Information, and Data Sources / AY 2010-11 | K3: 4-year& doctoral
A4: Institution Profile | K4: 4-year undergraduate
A5: Institution Name | B5: Oglala Lakota College | G5: Web Address | H5: www.olc.edu | K5: 2-year
A6: Address 1 | B6: Piya Wiconi - Three Mile Creek Road | G6: Highest Degree Offered | H6: 4-year & master's | I6: Academic Term | J6: semester
A7: Address 2 | B7: P.O. Box 490 | G7: Year Founded | H7: 1971 | I7: Land Granted Status | J7: yes | K7: academic term
A8: City | B8: Kyle | C8: State | D8: SD | E8: Zip | F8: 57752 | G8: Chartering Tribe | H8: Oglala Sioux Tribal Council | K8: quarter
A9: Telephone | B9: (605) 455-6000 | G9: Location | H9: on-reservation | I9: Operational Funding Source | J9: Pl-471 | K9: semester
A10: Person(s) Responsible for this Report | K10: trimester
A11: Name | B11: Title | D11: Telephone | G11: Email Address | K11: other
A12: Ursula R. Gaertmer. Ph.D. | B12: Institutional Research | D12: 605-455-6044 | G12: ugaertner@olc.edu
K13: land granted status
K14: yes
A15: Data Sources | K15: no
D16: Person(s) Responsible | G16: Notes
A17: Indicator 1: Overall Institution Profile | D17: Ursula R. Gaertner | K17: location
A18: Indicator 2: Financial Resources and Student Costs | D18: W. Eric Christiansen | K18: on reservation
A19: Indicator 3: Physical Resources | D19: W. Eric Christiansen | K19: off reservation
A20: Indicator 4: Student Enrollment and Graduation by Major Group | D20: Leslie Mesteth
A21: Indicator 5: Course Enrollment and Completion | D21: Leslie Mesteth
A22: Indicator 6: Student Activities | D22: Ruth Cedar Face
A23: Indicator 7: Personnel Demographics, Professional Development, Research, and Outcomes | D23: Faith Richards
A24: Indicator 8: Students with Disabilities Enrollment and Graduation | D24: Ruth Cedar Face
A25: Notes:
A27: Please certify that your institution's President has seen and approved this submission.
A28: Thomas Shortbull, President | D28: Ursula R. Gaertner, Institutional Research | H28: 40876
A29: President's Name | D29: Certified By | H29: Date

Sheet 1.2 Institution Profile
A1: Institution | D1: ='1.1 Overall Institution Profile'!$B$1 -> Oglala Lakota College
A2: Indicator 1: Overall Institution Profile
A3: Table 1.2: Institution Indian Student Count or Full Time Equivalent and Tribal Affiliations / AY 2010-11
A4: Please enter the institution's Indian Student Count or Full time Equivalent (FTE)1 and five largest tribal affiliations of enrolled students.
A5: Indian Student Count
B6: AY 2003-04 | E6: AY 2004-05 | H6: AY 2005-06 | K6: AY 2006-07 | N6: AY 2007-08
B7: Total | E7: Total | H7: Total | K7: Total | N7: Total
B8: 1126.4 | E8: 1202.51 | H8: 1131.51 | K8: 1069.8 | N8: 1069.63
B9: AY 2008-09
B10: Total
B11: 1046.35
A12: Full Time Equivalent (FTE)
C13: AY 2003-04 | H13: AY 2004-05 | M13: AY 2005-06
A14: American Indian | C14: Non-Indian | E14: FTE | F14: American Indian | H14: Non-Indian | J14: FTE | K14: American Indian | M14: Non-Indian | O14: FTE
A15: M | B15: F | C15: M | D15: F | E15: Total | F15: M | G15: F | H15: M | I15: F | J15: Total | K15: M | L15: F | M15: M | N15: F | O15: Total
A16: 0 | B16: 0 | C16: 0 | D16: 0 | E16: =SUM(A16:D16) -> 0 | F16: 0 | G16: 0 | H16: 0 | I16: 0 | J16: =SUM(F16:I16) -> 0 | K16: 0 | L16: 0 | M16: 0 | N16: 0 | O16: =SUM(K16:N16) -> 0
C17: AY 2006-07 | H17: AY 2007-08 | M17: AY 2008-09
A18: American Indian | C18: Non-Indian | E18: FTE | F18: American Indian | H18: Non-Indian | J18: FTE | K18: American Indian | M18: Non-Indian | O18: FTE
A19: M | B19: F | C19: M | D19: F | E19: Total | F19: M | G19: F | H19: M | I19: F | J19: Total | K19: M | L19: F | M19: M | N19: F | O19: Total
A20: 0 | B20: 0 | C20: 0 | D20: 0 | E20: =SUM(A20:D20) -> 0 | F20: 0 | G20: 0 | H20: 0 | I20: 0 | J20: =SUM(F20:I20) -> 0 | K20: 0 | L20: 0 | M20: 0 | N20: 0 | O20: =SUM(K20:N20) -> 0
A21: AY 2010-11 | C21: Part-Time AI Students | D21: Part-Time Non-AI Students | E21: Full-Time AI Students | F21: Full-Time Non-AI Students | G21: Part-Time AI Credits | H21: Part-Time Non-AI Credits | I21: Full-Time AI Credits | J21: Full-Time Non-AI Credits | K21: CEU AI Credits TOTAL | L21: CEU Non-AI Credits TOTAL | M21: ISC (see note) | N21: FTE (see note)
A22: Summer 2010 | C22: 282 | D22: 46 | E22: 40 | F22: 4 | G22: 1441 | H22: 181 | I22: 497 | J22: 49 | K22: 0 | L22: 0
A23: Fall 2010 | C23: 756 | D23: 98 | E23: 919 | F23: 57 | G23: 4427 | H23: 497 | I23: 11359 | J23: 717 | K23: 0 | L23: 0
A24: Winter 2011 | C24: NA | D24: NA | E24: NA | F24: NA | G24: NA | H24: NA | I24: NA | J24: NA | K24: NA | L24: NA
A25: Spring 2011 | C25: 719 | D25: 109 | E25: 967 | F25: 52 | G25: 4125 | H25: 462 | I25: 12131 | J25: 659 | K25: 0 | L25: 0
A26: TOTAL | C26: =SUM(C22:C25) -> 1757 | D26: =SUM(D22:D25) -> 253 | E26: =SUM(E22:E25) -> 1926 | F26: =SUM(F22:F25) -> 113 | G26: =SUM(G22:G25) -> 9993 | H26: =SUM(H22:H25) -> 1140 | I26: =SUM(I22:I25) -> 23987 | J26: =SUM(J22:J25) -> 1425 | ... L26: =SUM(L22:L25) -> 0 | M26: =SUM(G26,I26,K26)/24 -> 1415.8333 | N26: =SUM(G26:J26)/24 -> 1522.7083
A27: ISC-- See glossary for full definition. ISC=(FTAICR+PTAICR+CEU)/24, where CEUs used in calculation are limited to 10 percent of the institution’s ISC.
A28: FTE--The sum of credits enrolled in by all students divided by 24 equals the full-time equivalency. FTE=(FTCR+PTCR)/24
A29: Five Largest Tribal Affiliations of Students Enrolled at Tribal College
A30: Please list the five largest federally recognized tribes served by your institution. Total should not exceed total number of American Indian students enrolled (please see Table 4.2).
A31: Fall 2010 (October 15, 2010)
A32: Tribe | F32: # Enrolled | G32: % of Enrollment
A33: Oglala Sioux Tribe | F33: 1101 | G33: =SUM(F33/SUM('4.2 Major Group Totals'!D$10:'4.2 Major Group Totals'!E$10)) -> 0.65731343
A34: Cheyenne River | F34: 297 | G34: =SUM(F34/SUM('4.2 Major Group Totals'!D$10:'4.2 Major Group Totals'!E$10)) -> 0.17731343
A35: Rosebud Sioux | F35: 94 | G35: =SUM(F35/SUM('4.2 Major Group Totals'!D$10:'4.2 Major Group Totals'!E$10)) -> 0.056119403
A36: Standing Rock | F36: 42 | G36: =SUM(F36/SUM('4.2 Major Group Totals'!D$10:'4.2 Major Group Totals'!E$10)) -> 0.025074627
A37: Sisseton-Wahpeton | F37: 13 | G37: =SUM(F37/SUM('4.2 Major Group Totals'!D$10:'4.2 Major Group Totals'!E$10)) -> 0.007761194 | I37: =SUM(G33:H37) -> 0.92358209
A39: Other Tribes Represented Within Student Body | I39: NEW FOR 2011
A40: Please list all federally recognized tribes served by your institution. If more space is needed, please insert more lines.
A41: Fall 2010 (October 15, 2010)
...

Sheet 1.3(11) First Time Students
A1: Institution | D1: ='1.1 Overall Institution Profile'!$B$1 -> Oglala Lakota College
A2: Indicator 1: Overall Institution Profile
A3: Table 1.3(10): First Time Entering Students Demographics / AY 2010-11
A4: Please enter the institution's first time entering student enrollment, background, and characteristics, including first-time freshman and transfer-in students. All data on this page is for the first time entering students only- not the entire institution
A5: First Time Entering Student Enrollment | L5: First Time Entering Student Background and Characteristics
D6: American Indian | F6: Non-Indian | H6: Total | L6: Number of students who graduated from
D7: M | E7: F | F7: M | G7: F | H7: M | I7: F | J7: Total | L7: Public High School not located on a reservation | R7: 38
A8: Full Time | D8: 129 | E8: 169 | F8: 4 | G8: 4 | H8: =SUM(D8,F8) -> 133 | I8: =SUM(E8,G8) -> 173 | J8: =SUM(H8:I8) -> 306 | L8: Reservation-based public High School | R8: 5
A9: Part Time | D9: 39 | E9: 50 | F9: 5 | G9: 9 | H9: =SUM(D9,F9) -> 44 | I9: =SUM(E9,G9) -> 59 | J9: =SUM(H9:I9) -> 103 | L9: BIA school | R9: 87
A10: Total | D10: =SUM(D8:D9) -> 168 | E10: =SUM(E8:E9) -> 219 | F10: =SUM(F8:F9) -> 9 | G10: =SUM(G8:G9) -> 13 | H10: =SUM(D10,F10) -> 177 | I10: =SUM(E10,G10) -> 232 | J10: =SUM(H10:I10) -> 409 | L10: Tribal or Contract High School | R10: 54
L11: Other High School | R11: 114
A12: First Time Entering Students Pre-College Preparation | L12: Not Reported | R12: 0
A13: Number of students who
A14: Graduated High School with Diploma | J14: 298 | L14: Number of students who are
A15: Earned GED | J15: 111 | L15: Single - No Children | R15: 205
A16: Enrolled under Ability to Benefit provision | J16: 0 | L16: Single with dependent children | R16: 168
A17: Dual enrolled High School and College | J17: 0 | L17: Married - No Children | R17: 8
A18: Have No High School Diploma or GED | J18: 0 | L18: Married with dependent children | R18: 28
A19: Not Reported | J19: 0 | L19: Not Reported | R19: 0 | S19: =SUM(R15:R19) -> 409
J20: =SUM(J14:J19) -> 409 | L20: Responsible for elderly family members in home | R20: 0
A21: Age range of students
A22: Number of students who are: | D22: 16-24 | E22: 25-34 | F22: 35-49 | G22: 50-64 | H22: 65 & over | I22: Not Reported | L22: Number of students who are
D23: 243 | E23: 115 | F23: 39 | G23: 9 | H23: 3 | I23: 0 | L23: First Generation Students | R23: 345
I24: =SUM(D23:J23) -> 409 | L24: Not First Generation Students | R24: 64 | S24: =SUM(R23:R24) -> 409
A25: Native language speakers | D25: None | E25: Basic | F25: Inter. | G25: Adv. | H25: Fluent | I25: Not Reported | L25: Not Reported | R25: 0
A26: (Self-reporting) | D26: 0 | E26: 38 | F26: 0 | G26: 0 | H26: 0 | I26: 371
I27: =SUM(D26:J26) -> 409 | L27: Primary residence is
A28: Skill Assessment / Placement Test Results | L28: On / near reservation (within 60 miles) | R28: 409
C29: Reading | E29: Writing / Composition | G29: Mathematics | I29: Science | L29: In-State | R29: 404
B30: Test Name | C30: Accuplacer | E30: NA | G30: Accuplacer | I30: NA | L30: Out-of-State | R30: 5
A31: Number of students | B31: Taking Test | C31: 344 | E31: NA | G31: 336 | I31: NA | L31: Not Reported | R31: 0
B32: Placed in Remedial / | C32: 204 | E32: NA | G32: 236 | I32: NA
B33: Development Course | L33: Financial Background
B34: Based on Test Results | L34: Average family income ($) in student's household | R34: 12987
L35: Number of students employed less than 20 hrs/week (excluding work / study) | R35: 65
A36: Please note if any data collected is from a sample of students (e.g. financial background data is only from students | L36: Number of students employed 20 or more hrs/week (excluding work / study) | R36: 80
A37: who applied for financial aid). | L37: Number of students eligible for financial aid | R37: 348
A38: Notes: | L38: Number of students in need, but not eligible for financial aid | R38: 24 | S38: =SUM(R37:R38) -> 372
A39: Re. Skills assessment: students take the Reading/sentence structure test and the Math test. Reading and Comp are in one test. We do not test Science.

Sheet 1.4 Institution Retention
A1: Institution | B1: ='1.1 Overall Institution Profile'!$B$1 -> Oglala Lakota College
A2: Indicator 1: Overall Institution Profile
A3: Table 1.4: Institution Total Student Retention and Completion -- NEW FOR 2011
A4: Accurate retention numbers for all Tribal Colleges and Universities have been a challenge to obtain. The method that has been used has yielded grossly undercalculated numbers. In an effort to find a way to capture a true representation of retention numbers for degree seekers and to include those students who are non-degree-seeking but whose completion is a success, please complete the following tables. If you have suggestions on how to improve this indicator, please include them in the Notes section below. If your institution uses a different method of calculating retention and/or completion, please demonstrate it on this page (e.g., create tables, provide formulas).
A5: Please enter the total number of students entering the institution for the first-time in Fall 2009, including transfers.
B6: Certificate | D6: Associate's | F6: Bachelor's | H6: Total
B7: Part-Time | C7: Full-Time | D7: Part-Time | E7: Full-Time | F7: Part-Time | G7: Full-Time | H7: Part-Time | I7: Full-Time
A8: First-time entering students in fall 2009 | B8: 0 | C8: 3 | D8: 26 | E8: 116 | F8: 9 | G8: 51 | H8: =SUM(B8,D8,F8) -> 35 | I8: =SUM(C8,E8,G8) -> 170
A9: Graduated in AY 2009-10 | B9: 0 | C9: 0 | D9: 0 | E9: 1 | F9: 0 | G9: 0 | H9: =SUM(B9,D9,F9) -> 0 | I9: =SUM(C9,E9,G9) -> 1
A10: Transferred to another college or university in AY 2009-10 | B10: 0 | C10: 0 | D10: 0 | E10: 0 | F10: 0 | G10: 0 | H10: =SUM(B10,D10,F10) -> 0 | I10: =SUM(C10,E10,G10) -> 0
A11: Withdrew or stopped out in AY 2009-10 | B11: 0 | C11: 2 | D11: 15 | E11: 42 | F11: 7 | G11: 24 | H11: =SUM(B11,D11,F11) -> 22 | I11: =SUM(C11,E11,G11) -> 68
A12: Other Exclusions in 2009-10* | B12: 0 | C12: 0 | D12: 0 | E12: 0 | F12: 0 | G12: 0 | H12: =SUM(B12,D12,F12) -> 0 | I12: =SUM(C12,E12,G12) -> 0
A13: Returned in fall 2010 | B13: 0 | C13: 1 | D13: 11 | E13: 74 | F13: 2 | G13: 27 | H13: =SUM(B13,D13,F13) -> 13 | I13: =SUM(C13,E13,G13) -> 102
A14: Graduated in AY 2010-11 | B14: 0 | C14: 0 | D14: 0 | E14: 1 | F14: 0 | G14: 0 | H14: =SUM(B14,D14,F14) -> 0 | I14: =SUM(C14,E14,G14) -> 1
A15: Transferred to another college or university in AY 2010-11 | B15: 0 | C15: 0 | D15: 0 | E15: 0 | F15: 0 | G15: 0 | H15: =SUM(B15,D15,F15) -> 0 | I15: =SUM(C15,E15,G15) -> 0
A16: Withdrew or stopped out in AY 2010-11 | B16: 0 | C16: 0 | D16: 2 | E16: 27 | F16: 1 | G16: 5 | H16: =SUM(B16,D16,F16) -> 3 | I16: =SUM(C16,E16,G16) -> 32
A17: Other Exclusions in 2010-11* | B17: 0 | C17: 0 | D17: 0 | E17: 0 | F17: 0 | G17: 0 | H17: =SUM(B17,D17,F17) -> 0 | I17: =SUM(C17,E17,G17) -> 0
A18: Returned in fall 2011 | B18: 0 | C18: 1 | D18: 10 | E18: 41 | F18: 4 | G18: 18 | H18: =SUM(B18,D18,F18) -> 14 | I18: =SUM(C18,E18,G18) -> 60
A19: Retention Rate 2009 to 2010 | B19: =(B13+B9)/(B8-B10-B12) -> #DIV/0! | C19: =(C13+C9)/(C8-C10-C12) -> 0.33333333 | D19: =(D13+D9)/(D8-D10-D12) -> 0.42307692 | E19: =(E13+E9)/(E8-E10-E12) -> 0.64655172 | F19: =(F13+F9)/(F8-F10-F12) -> 0.22222222 | G19: =(G13+G9)/(G8-G10-G12) -> 0.52941176 | H19: =(H13+H9)/(H8-H10-H12) -> 0.37142857 | I19: =(I13+I9)/(I8-I10-I12) -> 0.60588235
A20: Retention Rate 2010 to 2011 | B20: =(B18+B14)/(B8-B15-B17) -> #DIV/0! | C20: =(C18+C14)/(C8-C15-C17) -> 0.33333333 | D20: =(D18+D14)/(D8-D15-D17) -> 0.38461538 | E20: =(E18+E14)/(E8-E15-E17) -> 0.36206897 | F20: =(F18+F14)/(F8-F15-F17) -> 0.44444444 | G20: =(G18+G14)/(G8-G15-G17) -> 0.35294118 | H20: =(H18+H14)/(H8-H15-H17) -> 0.4 | I20: =(I18+I14)/(I8-I15-I17) -> 0.35882353
A22: Please enter the total number of students entering the institution for the first-time in Fall 2010, including transfers.
B23: Certificate | D23: Associate's | F23: Bachelor's | H23: Total
B24: Part-Time | C24: Full-Time | D24: Part-Time | E24: Full-Time | F24: Part-Time | G24: Full-Time | H24: Part-Time | I24: Full-Time
A25: First-time entering students in fall 2010 | B25: 0 | C25: 1 | D25: 34 | E25: 115 | F25: 21 | G25: 57 | H25: =SUM(B25,D25,F25) -> 55 | I25: =SUM(C25,E25,G25) -> 173
A26: Graduated in AY 2010-11 | B26: 0 | C26: 0 | D26: 0 | E26: 0 | F26: 0 | G26: 0 | H26: =SUM(B26,D26,F26) -> 0 | I26: =SUM(C26,E26,G26) -> 0
A27: Transferred to another college or university in AY 2010-11 | B27: 0 | C27: 0 | D27: 0 | E27: 0 | F27: 0 | G27: 0 | H27: =SUM(B27,D27,F27) -> 0 | I27: =SUM(C27,E27,G27) -> 0
A28: Withdrew or stopped out in AY 2010-11 | B28: 0 | C28: 1 | D28: 21 | E28: 76 | F28: 14 | G28: 37 | H28: =SUM(B28,D28,F28) -> 35 | I28: =SUM(C28,E28,G28) -> 114
A29: Other Exclusions in 2010-11* | B29: 0 | C29: 0 | D29: 0 | E29: 0 | F29: 0 | G29: 0 | H29: =SUM(B29,D29,F29) -> 0 | I29: =SUM(C29,E29,G29) -> 0
A30: Returned in fall 2011 | B30: 0 | C30: 0 | D30: 16 | E30: 47 | F30: 8 | G30: 25 | H30: =SUM(B30,D30,F30) -> 24 | I30: =SUM(C30,E30,G30) -> 72
A31: Retention Rate 2010 to 2011 | B31: =(B30+B26)/(B25-B27-B29) -> #DIV/0! | C31: =(C30+C26)/(C25-C27-C29) -> 0 | D31: =(D30+D26)/(D25-D27-D29) -> 0.47058824 | E31: =(E30+E26)/(E25-E27-E29) -> 0.40869565 | F31: =(F30+F26)/(F25-F27-F29) -> 0.38095238 | G31: =(G30+G26)/(G25-G27-G29) -> 0.43859649 | H31: =SUM(B31,D31,F31) -> #DIV/0! | I31: =SUM(C31,E31,G31) -> 0.84729214
A32: * Exclusions include students who are deceased, permanently disabled, have joined armed forces, and are on official church missions.
A34: Successful Course Completion
A35: Please enter the total number of students.
B36: Non-Degree Seeking or Undeclared | E36: Certificate or Degree-Seeking | H36: Total
B37: Fall 2010 | C37: Spring 2011 | D37: Summer 2011 | E37: Fall 2010 | F37: Spring 2011 | G37: Summer 2011 | H37: Fall 2010 | I37: Spring 2011 | J37: Summer 2011 | K37: AY 10-11 Total
A38: Total Number of Course Enrollments* | B38: 383 | C38: 427 | D38: 39 | E38: 6283 | F38: 6386 | G38: 443 | H38: =SUM(B38,E38) -> 6666 | I38: =SUM(C38,F38) -> 6813 | J38: =SUM(D38,G38) -> 482 | K38: =SUM(H38:J38) -> 13961
A39: Total Number of Successful Course Completions** | B39: 275 | C39: 349 | D39: 3 | E39: 3419 | F39: 3419 | G39: 331 | H39: =SUM(B39,E39) -> 3694 | I39: =SUM(C39,F39) -> 3768 | J39: =SUM(D39,G39) -> 334 | K39: =SUM(H39:J39) -> 7796
A40: Successful Course Completion Rate | B40: =B39/B38 -> 0.71801567 | C40: =C39/C38 -> 0.81733021 | D40: =D39/D38 -> 0.076923077 | E40: =E39/E38 -> 0.5441668 | F40: =F39/F38 -> 0.53538992 | G40: =G39/G38 -> 0.74717833 | H40: =H39/H38 -> 0.55415542 | I40: =I39/I38 -> 0.55306033 | ... K40: =K39/K38 -> 0.55841272
A41: * This will count students multiple times.
A42: ** Successful completion means passing with a grade of A, B, C, D, CR (credit), or P (pass)
...

Sheet 1.5(11) Community Education
B1: Institution | C1: ='1.1 Overall Institution Profile'!$B$1 -> Oglala Lakota College
A2: Indicator 1: Overall Institution Profile
A3: Table 1.5(10): Community Education Participation and Program Completion / AY 2010-11
A4: Please enter the institution's participation in community education programs
A5: Community Education Participation: (June 2009 - May 2010)
A6: Target Audience | B6: Program Name | C6: Funding Source of Program | D6: Number of Participants | H6: Number of students who completed the program* | I6: After completion of the program, Number matriculated into
D7: American Indian | E7: Non-Indian | F7: Unknown Race | G7: Total | I7: Your Institution | J7: Another Institution of Higher Education
A8: K-Grade 5 Students | B8: 4-Highschool Enrichment Ag in the classroom | C8: USDA NIFA | D8: 46 | E8: 0 | F8: 0 | G8: =SUM(D8:F8) -> 46 | H8: m
B9: Eagle Nest District Literacy Project | C9: BIA | D9: 10 | E9: 0 | F9: 0 | G9: =SUM(D9:F9) -> 10 | H9: 10
B10: NASA/SEMA/STEEP | C10: NASA | D10: 1800 | E10: 0 | F10: 0 | G10: =SUM(D10:F10) -> 1800 | H10: 1800
B11: Build your own Library Program | C11: Build your own Library Program | D11: 1000 | E11: 0 | F11: 0 | G11: =SUM(D11:F11) -> 1000 | H11: 1000
B12: Woksape Tipi Taniyohila Kici (Library) | C12: IMLS Grant | D12: 1054 | E12: 0 | F12: 0 | G12: =SUM(D12:F12) -> 1054 | H12: 1054
A13: Grade 6-8 Students | B13: 4-Highschool Enrichment Ag in the classroom | C13: USDA NIFA | D13: 60 | E13: 0 | F13: 0 | G13: =SUM(D13:F13) -> 60 | H13: m
B14: Juging OLC Science Fair | C14: USDA NIFA | D14: 30 | E14: 0 | F14: 0 | G14: =SUM(D14:F14) -> 30 | H14: m
B15: Eagle Nest District Literacy Project | C15: BIA | D15: 10 | E15: 0 | F15: 0 | G15: =SUM(D15:F15) -> 10 | H15: 10
B16: NASA/SEMA//LNSFC | C16: NASA | D16: 1200 | E16: 0 | F16: 0 | G16: =SUM(D16:F16) -> 1200 | H16: 1200
B17: STEEP | C17: NSF/HOPA/BUSH | D17: 30 | E17: 0 | F17: 0 | G17: =SUM(D17:F17) -> 30 | H17: 30
A18: Grade 9-12 Students | B18: JDC Organic Gardening | C18: USDA NIFA | D18: 75 | E18: 0 | F18: 0 | G18: =SUM(D18:F18) -> 75 | H18: m | I18: m | J18: m
B19: Career Day Pine Ridge Highschool | C19: NACTEP | D19: 150 | E19: 0 | F19: 0 | G19: =SUM(D19:F19) -> 150 | H19: 150 | I19: m | J19: m
B20: Career Day PR College Center | C20: NACTEP | D20: 30 | E20: 0 | F20: 0 | G20: =SUM(D20:F20) -> 30 | H20: 30 | I20: m | J20: m
B21: NASA/SEMA | C21: NASA | D21: 600 | E21: 0 | F21: 0 | G21: =SUM(D21:F21) -> 600 | H21: 600 | I21: m | J21: m
B22: LNSFC/STEEP | C22: NASA | D22: 30 | E22: 0 | F22: 0 | G22: =SUM(D22:F22) -> 30 | H22: 30 | I22: m | J22: m
G23: =SUM(D23:F23) -> 0
G24: =SUM(D24:F24) -> 0
B25: Build your own Library Program | C25: Build your own Library Program | D25: 500 | E25: 0 | F25: 0 | G25: =SUM(D25:F25) -> 500 | H25: 500 | I25: m | J25: m
A26: Adults | B26: Community Workshop/Community Gardening | C26: USDA NIFA | D26: 25 | E26: 0 | F26: 0 | G26: =SUM(D26:F26) -> 25 | H26: m | I26: m | J26: m
B27: Home Food Preservation | C27: USDA NIFA | D27: 30 | E27: 0 | F27: 0 | G27: =SUM(D27:F27) -> 30 | H27: m | I27: m | J27: m
B28: phone & e-mail requests for Ag information | C28: USDA NIFA | D28: 120 | E28: 0 | F28: 0 | G28: =SUM(D28:F28) -> 120 | H28: m | I28: m | J28: m
B29: Tree Planting | C29: USDA NIFA | D29: 10 | E29: 0 | F29: 0 | G29: =SUM(D29:F29) -> 10 | H29: m | I29: m | J29: m
B30: Erosion Control | C30: USDA NIFA | D30: 35 | E30: 0 | F30: 0 | G30: =SUM(D30:F30) -> 35 | H30: m | I30: m | J30: m
B31: NASA/SEMA | C31: NASA | D31: 30 | E31: 0 | F31: 0 | G31: =SUM(D31:F31) -> 30 | H31: m | I31: m | J31: m
B32: LNSFC | C32: NASA | D32: 10 | E32: 0 | F32: 0 | G32: =SUM(D32:F32) -> 10 | H32: m | I32: m | J32: m
B33: STEEP | C33: STEEP | D33: 20 | E33: 0 | F33: 0 | G33: =SUM(D33:F33) -> 20 | H33: m | I33: m | J33: m
B34: Lakota Premiere of "The Chiefs…." | C34: Library | D34: 20 | E34: 0 | F34: 0 | G34: =SUM(D34:F34) -> 20 | H34: m | I34: m | J34: m
B35: 3rd Annual Gathering of Lakota Elders | C35: Library | D35: 30 | E35: 0 | F35: 0 | G35: =SUM(D35:F35) -> 30 | H35: m | I35: m | J35: m
B36: Defenders of the Black Hills | C36: Library | D36: 25 | E36: 0 | F36: 0 | G36: =SUM(D36:F36) -> 25 | H36: m | I36: m | J36: m
B37: Sweetgrass Project "Bullying" | C37: Library | D37: 25 | E37: 0 | F37: 0 | G37: =SUM(D37:F37) -> 25 | H37: m | I37: m | J37: m
B38: 2010 Census | C38: Library | D38: 20 | E38: 0 | F38: 0 | G38: =SUM(D38:F38) -> 20 | H38: m | I38: m | J38: m
B39: James Welch by Kim Bettelyoun | C39: Library | D39: 25 | E39: 0 | F39: 0 | G39: =SUM(D39:F39) -> 25 | H39: m | I39: m | J39: m
B40: GED | C40: BIA/471 | D40: 597 | E40: 12 | F40: 0 | G40: =SUM(D40:F40) -> 609 | H40: 10 | I40: m | J40: m
...

Sheet 2.1 Student Tuition & Costs
A1: Institution | C1: ='1.1 Overall Institution Profile'!B1 -> Oglala Lakota College
A2: Indicator 2: Financial Resources and Student Costs
A3: Table 2.1: Student Tuition, Financial Aid, and Costs / AY 2010-11
A4: Please enter the tuition cost per credit hour, the total amount of financial aid received and the number of students receiving aid, and undergraduate student costs.
A5: Tuition Cost per Credit Hour | D5: AY 10-11
A6: Undergraduate | B6: American Indian Student | D6: 80
B7: Non-Indian Student | D7: 98
A8: Graduate | B8: American Indian Student | D8: 115
B9: Non-Indian Student | D9: 115
A11: Sources and Amount of Financial Aid | D11: AY 10-11
A12: American Indian College Fund Scholarship | C12: Total Dollar Amount | D12: 270830
C13: Total Number of Recipients | D13: 208
A14: Federal Pell Grants | C14: Total Dollar Amount | D14: 5189010
C15: Total Number of Recipients | D15: 1445
A16: Federal Supplemental Educational Opportunity Grant | C16: Total Dollar Amount | D16: 86872
C17: Total Number of Recipients | D17: 195
A18: State Scholarships/Grants | C18: Total Dollar Amount | D18: 74947
C19: Total Number of Recipients | D19: 249
A20: Academic Competitiveness Grant | C20: Total Dollar Amount | D20: 15893
C21: Total Number of Recipients | D21: 28
A22: School-to-Work | C22: Total Dollar Amount | D22: 0
C23: Total Number of Recipients | D23: 0
A24: Tribal Scholarships | C24: Total Dollar Amount | D24: 922811
C25: Total Number of Recipients | D25: 423
A26: Tuition Waiver/Discount | C26: Total Dollar Amount | D26: 30149
C27: Total Number of Recipients | D27: 67
A28: Other Scholarships | C28: Total Dollar Amount | D28: 253854
C29: Total Number of Recipients | D29: 189
A30: Federal College Work Study | C30: Total Dollar Amount | D30: 72855
C31: Total Number of Recipients | D31: 51
A32: State Work Study | C32: Total Dollar Amount | D32: 0
C33: Total Number of Recipients | D33: 0
A34: Institutional Work Study | C34: Total Dollar Amount | D34: 0
C35: Total Number of Recipients | D35: 0
A37: Average Full Time Undergraduate Student Costs for Academic Year | D37: AY 10-11
A38: Tuition | D38: 1920
A39: Room and Board | D39: 5400
A40: Transportation | D40: 3000
A41: Text Books | D41: 1200
A42: Supplies | D42: m
...

Sheet 3.1 Academic Building
A1: Institution | B1: ='1.1 Overall Institution Profile'!B1 -> Oglala Lakota College
A2: Indicator 3: Physical Resources
A3: Table 3.1: Building Facilities
A4: Please briefly summarize the institution's buildings. Identify building usage by main function. Reproduce this work sheet as needed. If building is used for multiple purposes (e.g. classroom and laboratory) please list building name as many times as necessary and identify total square feet for each main function.
A5: Does your institution have daycare or other early childhood learning facilities? | G5: NEW FOR 2011
A6: Existing Buildings
A7: Building Name | B7: Campus Site | C7: Year Built / Acquired | D7: No. of Stories | E7: Total sq. ft. | F7: Main Function | G7: Own / Lease | H7: Note | J7: Campus Site
A8: Piya Wiconi | B8: Main Campus | C8: 1980 | D8: 2 | E8: 24800 | F8: Administration/Office | G8: Own | J8: Main Campus
A9: Pine Ridge House 1 | B9: Satellite Site | C9: 1939 | D9: 1 | E9: 1700 | F9: Auxiliary | G9: Own | J9: Branch Campus
A10: Pine Ridge House 2 | B10: Satellite Site | C10: 1939 | D10: 1 | E10: 1700 | F10: Auxiliary | G10: Own | J10: Satellite Site
A11: Classrooms | B11: Satellite Site | C11: 1970 | D11: 1 | E11: 3080 | F11: Classroom | G11: Own
A12: Martin Building | B12: Satellite Site | C12: 1947 | D12: 1 | E12: 2500 | F12: Auxiliary | G12: Own | J12: Main Function
A13: Voc-Ed Building Metal Building | B13: Main Campus | C13: 1981 | D13: 1 | E13: 8400 | F13: Administration/Office | G13: Own | J13: Administration/Office
A14: Wooden Building | B14: Main Campus | C14: 1988 | D14: 1 | E14: 2100 | F14: Administration/Office | G14: Own | J14: Auxiliary
A15: Kyle Center | B15: Satellite Site | C15: 1994 | D15: 1 | E15: m | F15: Administration/Office | G15: Own | J15: Classroom
A16: Batesland Center | B16: Satellite Site | C16: 1994 | D16: 1 | E16: 5000 | F16: Administration/Office | G16: Own | J16: Cultural Center/Museum
A17: Porcupine Center | B17: Satellite Site | C17: 1997 | D17: 1 | E17: 6582 | F17: Classroom | G17: Own | J17: Distance Learning
A18: Pine Ridge Center | B18: Satellite Site | C18: 1997 | D18: 1 | E18: 12150 | F18: Classroom | G18: Own | J18: Laboratory
A19: Manderson Center | B19: Satellite Site | C19: 1998 | D19: 1 | E19: m | F19: Classroom | G19: Own | J19: Library
A20: Wanblee Center | B20: Satellite Site | C20: 1998 | D20: 1 | E20: m | F20: Classroom | G20: Own | J20: Research
A21: Oglala Center | B21: Satellite Site | C21: 1998 | D21: 1 | E21: m | F21: Classroom | G21: Own | J21: Residence
A22: Allen Center | B22: Satellite Site | C22: 1999 | D22: 1 | E22: m | F22: Classroom | G22: Own | J22: Student Services/Recreation
A23: Martin Center | B23: Satellite Site | C23: 1999 | D23: 1 | E23: m | F23: Classroom | G23: Own
A24: Rapid City Center | B24: Satellite Site | C24: 1999 | D24: 1 | E24: m | F24: Classroom | G24: Own | J24: Own/Lease
A25: Kyle Center Addition | B25: Satellite Site | C25: 2001 | D25: 1 | E25: m | F25: Classroom | G25: Own | J25: Assigned by Tribe
A26: Pine Ridge Log Cabin | B26: Satellite Site | C26: m | D26: 1 | E26: 4526 | F26: Auxiliary | G26: Own | J26: Donated
A27: Nursing Dorm | B27: Satellite Site | C27: 2003 | D27: 1 | E27: m | F27: Residence | G27: Own | J27: Lease/Rent
A28: Lakota Center for Science & Technology | B28: Main Campus | C28: 2003 | D28: 1 | E28: 6000 | F28: Laboratory | G28: Own | J28: Own
A29: Nursing Building | B29: Satellite Site | C29: 2004 | D29: 1 | E29: 8000 | F29: Classroom | G29: Own
A30: Pine Ridge College Center Expansion | B30: Satellite Site | C30: 2004 | D30: 1 | E30: 4500 | F30: Classroom | G30: Own
A31: He Sapa College Center Expansion | B31: Satellite Site | C31: 2006 | D31: 1 | E31: 6500 | F31: Classroom | G31: Own
A32: Cheyenne River College Center | B32: Satellite Site | C32: 2000 | D32: 1 | E32: 25000 | F32: Classroom | G32: Assigned by Tribe
A33: Pine Ridge Dorms | B33: Satellite Site | C33: 2006 | D33: 1 | E33: 4200 | F33: Residence | G33: Own
A34: Pole Barn Building | B34: Main Campus | C34: 2008 | D34: 1 | E34: 2040 | F34: Administration/Office | G34: Own
A35: Bookstore | B35: Main Campus | C35: 2008 | D35: 1 | E35: 3625 | F35: Administration/Office | G35: Own
A36: Batesland Head Start | B36: Satellite Site | C36: 2008 | D36: 1 | E36: 1680 | F36: Classroom | G36: Own
A37: Wanblee Head Start | B37: Satellite Site | C37: 2008 | D37: 1 | E37: 2576 | F37: Classroom | G37: Own
A38: Pejuta Haka Dorms | B38: Satellite Site | C38: 2009 | D38: 1 | E38: 9000 | F38: Residence | G38: Own
A39: Martin Head Start | B39: Satellite Site | C39: 2009 | D39: 1 | E39: 2591 | F39: Classroom | G39: Own
A40: Manderson Head Start | B40: Satellite Site | C40: 2009 | D40: 1 | E40: 3200 | F40: Classroom | G40: Own
...

Sheet 3.2 Library Fac & Res Equipment
A1: Institution | D1: ='1.1 Overall Institution Profile'!B1 -> Oglala Lakota College
A2: Indicator 3: Physical Resources | N2: Inter-Library System
A3: Table 3.2: Library Facilities / AY 2010-11 | N3: Computer Lab w/ Internet
A4: Please briefly summarize the current status of library facilities. | N4: <select one>
A5: Library Facility | N5: Yes
A6: Library Name | C6: Total sq. ft. | D6: Year Built / Remodeled | E6: Volumes | F6: Periodicals | H6: Catalogue On-line Access | I6: Inter-Library System | J6: Computer Lab w/ Internet | K6: Community Library Status | L6: Community Learning Center | N6: No
F7: Print | G7: Electronic
A8: Woksape Tipi | C8: 18000 | D8: 1997 | E8: 49000 | F8: 60 | G8: 80* | H8: Yes | I8: Yes | J8: Yes | K8: Community Library | L8: Yes
N10: Community Library
A11: Special Cultural Collections: Please briefly describe any cultural or tribal museum/archival collections housed in library or other building.
A12: Museum, Archival Collections; - Lakota Artifacts (e.g. head dresses, pipes, moccasins), - manuscripts, microfilm, video, audio, photographs, maps, posters, rare books, publications covering broad spectrum of Lakota history, society, culture, and institutions; - institutional records of Oglala Lakota College and Oglala Sioux Tribe; - Artwork by Oglala Lakota artists (contemporary).
A13: Library Improvements / Acquisitions during academic year
A14: AY 10-11 | B14: None. Remodeling project is underway for AY2011-2012.
A15: Notes:
A16: * w/3000+ titles

Sheet 3.3 Research Equipment
A1: Institution | B1: ='1.1 Overall Institution Profile'!B1 -> Oglala Lakota College
A2: Indicator 3: Physical Resources
A3: Table 3.3: Instructional/ Research Equipment and Facilities Acquired /AY 2010-11
A4: Please enter major instructional/ research equipment and facilities acquired during the academic year
A5: Major Instructional/ Research Equipment and Facilities Acquisition
B6: AY 10-11
A7: Equipment or Facility Name | B7: Math & Science Lab Renovation - New equipment
A8: Purchase Cost | B8: 73818
A9: Number of Units | B9: 1 lot
A10: Purpose | B10: update science labs
A11: Equipment or Facility Name
A12: Purchase Cost
A13: Number of Units
A14: Purpose
A15: Equipment or Facility Name
A16: Purchase Cost
A17: Number of Units
A18: Purpose
A19: Equipment or Facility Name
A20: Purchase Cost
A21: Number of Units
A22: Purpose
... A63: Notes:
A64: 0

Sheet 4.1 Majors
B1: Institution | C1: ='1.1 Overall Institution Profile'!$B$1 -> Oglala Lakota College | E1: Major Group ID/Major Groups
A2: Indicator 4: Student Enrollment and Graduation by Major Group | E2: AC - Accounting
A3: Table 4.1: Major Groups | E3: AG - Agriculture and Farming
A4: Please identify your institution's specific majors and degrees offered by major group. If you have additional majors, please add them as needed. | E4: AL - American Indian Languages
A5: Major Groups | E5: AS - American Indian Studies
A6: I.D. | B6: Major Groups | C6: Specific Majors (and Degrees Offered) | E6: AR - Art
A7: AC | B7: Accounting | C7: (AA) | E7: AU - Automotive Technology
A8: AL | B8: American Indian Languages | C8: Lakota Language (CT) | E8: BI - Biology
A9: AS | B9: American Indian Studies | C9: Lakota Studies (AA, BA); K-12 Lakota Studies Education (BS); Tribal Law (AA); | E9: BT - Building Trades
A10: AR | B10: Art | C10: Fine Art (AA) | E10: BU - Business
A11: BT | B11: Building Trades | C11: Electrical Technology (AAS); General Construction (CT, AAS); | E11: CH - Chemistry
A12: BU | B12: Business | C12: Business Administration (BS); | E12: CS - Computer Science
A13: CS | B13: Computer Science | C13: Information Technology (AA, BS); | E13: CT - Computer Technology
E14: CL - Corrections/Law Enforcement
A15: EA | B15: Education-Paraprofessional | C15: Child Development Associate (CT); Early Childhood (AA); Elementary Education (AA) | E15: EA - Education-Paraprofessional
A16: EO | B16: Education-Professional | C16: Early Childhood (BA); K-8 Elementary Education (BS); | E16: EO - Education-Professional
A17: ES | B17: Environmental Science/Natural Resources | C17: Natural Science (BS) | E17: EN - English
A18: HC | E18: ES - Environmental Science/Natural Resources
A19: HI | B19: Hospitality Industry | C19: Customer Service (CT, AAS) | E19: GE - Geography
A20: HS | B20: Human Services | C20: Social Work (BSW); Chemical Dependency Counseling (AA) | E20: HS - Health Careers
A21: LA | B21: Liberal Arts/General Studies | C21: Liberal Atrs (AA); English and Communications (BA) | E21: HI - Hospitality Industry
A22: LS | B22: Life Science | C22: Life Science (AA) | E22: HS - Human Services
A23: NU | B23: Nursing | C23: Nursing (AA) | E23: IP - Individualized Program
A24: OA | B24: Office Administration/Technology | C24: Office Technology (CT, AAS); Office Software Applications (CT, AAS) | E24: LA - Liberal Arts/General Studies
A25: SC | B25: Science | C25: Science, Engineering & Mathematics (AA); Secondary Education Physical Science (BS) | E25: LS - Life Sciences
A26: SS | B26: Social Science | C26: Social Science (AA, BA) | E26: MA - Mathematics
A27: VC | B27: Vocational | C27: program discontinued
A28: MS | B28: Master's | C28: Lakota Leadership/Management (MA); Secondary/Middle/Elementary Educational Administration (MA) | E28: NU - Nursing
A29: UN | B29: Undeclared/Nondeclared | C29: Undeclared | E29: OA - Office Administration/Technology
E30: PA - Paralegal
E31: PE - Pre-Engineering/Engineering
E32: PV - Pre-Veterinary Science
E33: SC - Science
E34: SS - Social Science
A35: Notes: | E35: VC - Vocational/Career Programs
E36: UD - Undeclared/Nondeclared
E37: MS - Master's Degree Programs

Sheet 4.2(AC) Major Group Enroll-Grad
A1: Institution | D1: ='1.1 Overall Institution Profile'!B1 -> Oglala Lakota College
A2: Indicator 4: Student Enrollment and Graduation by Major Group
A3: Table 4.2(AC): Major Group Fall Enrollment, Graduation & Post-Graduate / AY 2010-11
B4: Major Group | C4: AC - Accounting
B5: Please enter the number of students enrolled in this major group for the fall semester.
F6: Fall 2010 (October 15, 2010)
B7: Fall Enrollment (Snapshot) | D7: American Indian | F7: Non-Indian
D8: M | E8: F | F8: M | G8: F | H8: Total
C9: Full Time | D9: 0 | E9: 19 | F9: 0 | G9: 2 | H9: =SUM(D9:G9) -> 21
C10: Part Time | D10: 0 | E10: 14 | F10: 0 | G10: 0 | H10: =SUM(D10:G10) -> 14
C11: Total | D11: =SUM(D9:D10) -> 0 | E11: =SUM(E9:E10) -> 33 | F11: =SUM(F9:F10) -> 0 | G11: =SUM(G9:G10) -> 2 | H11: =SUM(D11:G11) -> 35
B12: Please enter the number of diploma, certificates, and degrees earned in this major group. Also enter the number of students graduating with degrees who earned a GPA of 3.0 or above, and the number who were admitted to a 4 year (Associate degree graduates), or graduate school (Bachelor's degree graduates). Lastly, enter the number of all graduating students(certificate or degree) who secured employment after graduation.
F13: July 1, 2010- June 30, 2011
B14: Graduation | D14: American Indian | F14: Non-Indian
D15: M | E15: F | F15: M | G15: F | H15: Total
A16: Apprenticeship/Occupational Program | D16: na | E16: na | F16: na | G16: na | H16: =SUM(D16:G16) -> 0
A17: Diploma | D17: na | E17: na | F17: na | G17: na | H17: =SUM(D17:G17) -> 0
A18: Certificate | D18: na | E18: na | F18: na | G18: na | H18: =SUM(D18:G18) -> 0
A19: Associate Degree | D19: 2 | E19: 10 | F19: 0 | G19: 1 | H19: =SUM(D19:G19) -> 13
B20: Assoc. graduates admitted to four-year program | D20: 0 | E20: 0 | F20: 0 | G20: 0 | H20: =SUM(D20:G20) -> 0
B21: Assoc. graduated with a GPA of 3.0 or above | D21: 1 | E21: 4 | F21: 0 | G21: 1 | H21: =SUM(D21:G21) -> 6
A22: Bachelor's Degree | D22: na | E22: na | F22: na | G22: na | H22: =SUM(D22:G22) -> 0
B23: Bach. graduates admitted to graduate school | D23: na | E23: na | F23: na | G23: na | H23: =SUM(D23:G23) -> 0
B24: Bach. graduated with a GPA of 3.0 or above | D24: na | E24: na | F24: na | G24: na | H24: =SUM(D24:G24) -> 0
A25: Master's Degree | D25: na | E25: na | F25: na | G25: na | H25: =SUM(D25:G25) -> 0
A26: Employed after graduation | D26: m | E26: m | F26: m | G26: m | H26: =SUM(D26:G26) -> 0
A28: Notes:
A29: na = not offered; m = not tracked

Sheet 4.2(AG) Major Group Enroll-Grad
A1: Institution | D1: ='1.1 Overall Institution Profile'!B1 -> Oglala Lakota College
A2: Indicator 4: Student Enrollment and Graduation by Major Group
A3: Table 4.2(AG): Major Group Fall Enrollment, Graduation & Post-Graduate / AY 2010-11
B4: Major Group | C4: AG - Agriculture and Farming
B5: Please enter the number of students enrolled in this major group for the fall semester.
F6: Fall 2010 (October 15, 2010)
B7: Fall Enrollment (Snapshot) | D7: American Indian | F7: Non-Indian
D8: M | E8: F | F8: M | G8: F | H8: Total
C9: Full Time | D9: na | E9: na | F9: na | G9: na | H9: =SUM(D9:G9) -> 0
C10: Part Time | D10: na | E10: na | F10: na | G10: na | H10: =SUM(D10:G10) -> 0
C11: Total | D11: =SUM(D9:D10) -> 0 | E11: =SUM(E9:E10) -> 0 | F11: =SUM(F9:F10) -> 0 | G11: =SUM(G9:G10) -> 0 | H11: =SUM(D11:G11) -> 0
B12: Please enter the number of diploma, certificates, and degrees earned in this major group. Also enter the number of students graduating with degrees who earned a GPA of 3.0 or above, and the number who were admitted to a 4 year (Associate degree graduates), or graduate school (Bachelor's degree graduates). Lastly, enter the number of all graduating students(certificate or degree) who secured employment after graduation.
F13: July 1, 2010- June 30, 2011
B14: Graduation | D14: American Indian | F14: Non-Indian
D15: M | E15: F | F15: M | G15: F | H15: Total
A16: Apprenticeship/Occupational Program | D16: na | E16: na | F16: na | G16: na | H16: =SUM(D16:G16) -> 0
A17: Diploma | D17: na | E17: na | F17: na | G17: na | H17: =SUM(D17:G17) -> 0
A18: Certificate | D18: na | E18: na | F18: na | G18: na | H18: =SUM(D18:G18) -> 0
A19: Associate Degree | D19: na | E19: na | F19: na | G19: na | H19: =SUM(D19:G19) -> 0
B20: Assoc. graduates admitted to four-year program | D20: na | E20: na | F20: na | G20: na | H20: =SUM(D20:G20) -> 0
B21: Assoc. graduated with a GPA of 3.0 or above | D21: na | E21: na | F21: na | G21: na | H21: =SUM(D21:G21) -> 0
A22: Bachelor's Degree | D22: na | E22: na | F22: na | G22: na | H22: =SUM(D22:G22) -> 0
B23: Bach. graduates admitted to graduate school | D23: na | E23: na | F23: na | G23: na | H23: =SUM(D23:G23) -> 0
B24: Bach. graduated with a GPA of 3.0 or above | D24: na | E24: na | F24: na | G24: na | H24: =SUM(D24:G24) -> 0
A25: Master's Degree | D25: na | E25: na | F25: na | G25: na | H25: =SUM(D25:G25) -> 0
A26: Employed after graduation | D26: na | E26: na | F26: na | G26: na | H26: =SUM(D26:G26) -> 0
A28: Notes:

Sheet 4.2(AL) Major Group Enroll-Grad
A1: Institution | D1: ='1.1 Overall Institution Profile'!B1 -> Oglala Lakota College
A2: Indicator 4: Student Enrollment and Graduation by Major Group
A3: Table 4.2(AL): Major Group Fall Enrollment, Graduation & Post-Graduate / AY 2010-11
B4: Major Group | C4: AL - American Indian Languages
B5: Please enter the number of students enrolled in this major group for the fall semester.
F6: Fall 2010 (October 15, 2010)
B7: Fall Enrollment (Snapshot) | D7: American Indian | F7: Non-Indian
D8: M | E8: F | F8: M | G8: F | H8: Total
C9: Full Time | D9: 0 | E9: 0 | F9: 0 | G9: 0 | H9: =SUM(D9:G9) -> 0
C10: Part Time | D10: 0 | E10: 0 | F10: 0 | G10: 0 | H10: =SUM(D10:G10) -> 0
C11: Total | D11: =SUM(D9:D10) -> 0 | E11: =SUM(E9:E10) -> 0 | F11: =SUM(F9:F10) -> 0 | G11: =SUM(G9:G10) -> 0 | H11: =SUM(D11:G11) -> 0
B12: Please enter the number of diploma, certificates, and degrees earned in this major group. Also enter the number of students graduating with degrees who earned a GPA of 3.0 or above, and the number who were admitted to a 4 year (Associate degree graduates), or graduate school (Bachelor's degree graduates). Lastly, enter the number of all graduating students(certificate or degree) who secured employment after graduation.
F13: July 1, 2010- June 30, 2011
B14: Graduation | D14: American Indian | F14: Non-Indian
D15: M | E15: F | F15: M | G15: F | H15: Total
A16: Apprenticeship/Occupational Program | D16: na | E16: na | F16: na | G16: na | H16: =SUM(D16:G16) -> 0
A17: Diploma | D17: na | E17: na | F17: na | G17: na | H17: =SUM(D17:G17) -> 0
A18: Certificate | D18: 0 | E18: 5 | F18: 0 | G18: 0 | H18: =SUM(D18:G18) -> 5
A19: Associate Degree | D19: na | E19: na | F19: na | G19: na | H19: =SUM(D19:G19) -> 0
B20: Assoc. graduates admitted to four-year program | D20: na | E20: na | F20: na | G20: na | H20: =SUM(D20:G20) -> 0
B21: Assoc. graduated with a GPA of 3.0 or above | D21: na | E21: na | F21: na | G21: na | H21: =SUM(D21:G21) -> 0
A22: Bachelor's Degree | D22: na | E22: na | F22: na | G22: na | H22: =SUM(D22:G22) -> 0
B23: Bach. graduates admitted to graduate school | D23: na | E23: na | F23: na | G23: na | H23: =SUM(D23:G23) -> 0
B24: Bach. graduated with a GPA of 3.0 or above | D24: na | E24: na | F24: na | G24: na | H24: =SUM(D24:G24) -> 0
A25: Master's Degree | D25: na | E25: na | F25: na | G25: na | H25: =SUM(D25:G25) -> 0
A26: Employed after graduation | D26: m | E26: m | F26: m | G26: m | H26: =SUM(D26:G26) -> 0
A28: Notes:
A29: na = not offered; m = not tracked;

Sheet 4.2(AS) Major Group Enroll-Grad
A1: Institution | D1: ='1.1 Overall Institution Profile'!B1 -> Oglala Lakota College
A2: Indicator 4: Student Enrollment and Graduation by Major Group
A3: Table 4.2(AS): Major Group Fall Enrollment, Graduation & Post-Graduate / AY 2010-11
B4: Major Group | C4: AS - American Indian Studies
B5: Please enter the number of students enrolled in this major group for the fall semester.
F6: Fall 2010 (October 15, 2010)
B7: Fall Enrollment (Snapshot) | D7: American Indian | F7: Non-Indian
D8: M | E8: F | F8: M | G8: F | H8: Total
C9: Full Time | D9: 31 | E9: 39 | F9: 0 | G9: 0 | H9: =SUM(D9:G9) -> 70
C10: Part Time | D10: 23 | E10: 46 | F10: 3 | G10: 2 | H10: =SUM(D10:G10) -> 74
C11: Total | D11: =SUM(D9:D10) -> 54 | E11: =SUM(E9:E10) -> 85 | F11: =SUM(F9:F10) -> 3 | G11: =SUM(G9:G10) -> 2 | H11: =SUM(D11:G11) -> 144
B12: Please enter the number of diploma, certificates, and degrees earned in this major group. Also enter the number of students graduating with degrees who earned a GPA of 3.0 or above, and the number who were admitted to a 4 year (Associate degree graduates), or graduate school (Bachelor's degree graduates). Lastly, enter the number of all graduating students(certificate or degree) who secured employment after graduation.
F13: July 1, 2010- June 30, 2011
B14: Graduation | D14: American Indian | F14: Non-Indian
D15: M | E15: F | F15: M | G15: F | H15: Total
A16: Apprenticeship/Occupational Program | D16: na | E16: na | F16: na | G16: na | H16: =SUM(D16:G16) -> 0
A17: Diploma | D17: na | E17: na | F17: na | G17: na | H17: =SUM(D17:G17) -> 0
A18: Certificate | D18: na | E18: na | F18: na | G18: na | H18: =SUM(D18:G18) -> 0
A19: Associate Degree | D19: 7 | E19: 20 | F19: 0 | G19: 1 | H19: =SUM(D19:G19) -> 28
B20: Assoc. graduates admitted to four-year program | D20: 0 | E20: 0 | F20: 0 | G20: 0 | H20: =SUM(D20:G20) -> 0
B21: Assoc. graduated with a GPA of 3.0 or above | D21: 2 | E21: 12 | F21: 0 | G21: 1 | H21: =SUM(D21:G21) -> 15
A22: Bachelor's Degree | D22: 4 | E22: 6 | F22: 1 | G22: 0 | H22: =SUM(D22:G22) -> 11
B23: Bach. graduates admitted to graduate school | D23: 0 | E23: 0 | F23: 0 | G23: 0 | H23: =SUM(D23:G23) -> 0
B24: Bach. graduated with a GPA of 3.0 or above | D24: 2 | E24: 3 | F24: 1 | G24: 0 | H24: =SUM(D24:G24) -> 6
A25: Master's Degree | D25: na | E25: na | F25: na | G25: na | H25: =SUM(D25:G25) -> 0
A26: Employed after graduation | D26: m | E26: m | F26: m | G26: m | H26: =SUM(D26:G26) -> 0
A28: Notes:
A29: na = not offered; m = not tracked;

Sheet 4.2(AR) Major Group Enroll-Grad
A1: Institution | D1: ='1.1 Overall Institution Profile'!B1 -> Oglala Lakota College
A2: Indicator 4: Student Enrollment and Graduation by Major Group
A3: Table 4.2(AR): Major Group Fall Enrollment, Graduation & Post-Graduate / AY 2010-11
B4: Major Group | C4: AR - Art
B5: Please enter the number of students enrolled in this major group for the fall semester.
F6: Fall 2010 (October 15, 2010)
B7: Fall Enrollment (Snapshot) | D7: American Indian | F7: Non-Indian
D8: M | E8: F | F8: M | G8: F | H8: Total
C9: Full Time | D9: 6 | E9: 2 | F9: 0 | G9: 0 | H9: =SUM(D9:G9) -> 8
C10: Part Time | D10: 1 | E10: 1 | F10: 0 | G10: 0 | H10: =SUM(D10:G10) -> 2
C11: Total | D11: =SUM(D9:D10) -> 7 | E11: =SUM(E9:E10) -> 3 | F11: =SUM(F9:F10) -> 0 | G11: =SUM(G9:G10) -> 0 | H11: =SUM(D11:G11) -> 10
B12: Please enter the number of diploma, certificates, and degrees earned in this major group. Also enter the number of students graduating with degrees who earned a GPA of 3.0 or above, and the number who were admitted to a 4 year (Associate degree graduates), or graduate school (Bachelor's degree graduates). Lastly, enter the number of all graduating students(certificate or degree) who secured employment after graduation.
F13: July 1, 2010- June 30, 2011
B14: Graduation | D14: American Indian | F14: Non-Indian
D15: M | E15: F | F15: M | G15: F | H15: Total
A16: Apprenticeship/Occupational Program | D16: na | E16: na | F16: na | G16: na | H16: =SUM(D16:G16) -> 0
A17: Diploma | D17: na | E17: na | F17: na | G17: na | H17: =SUM(D17:G17) -> 0
A18: Certificate | D18: na | E18: na | F18: na | G18: na | H18: =SUM(D18:G18) -> 0
A19: Associate Degree | D19: 0 | E19: 0 | F19: 0 | G19: 0 | H19: =SUM(D19:G19) -> 0
B20: Assoc. graduates admitted to four-year program | D20: 0 | E20: 0 | F20: 0 | G20: 0 | H20: =SUM(D20:G20) -> 0
B21: Assoc. graduated with a GPA of 3.0 or above | D21: 0 | E21: 0 | F21: 0 | G21: 0 | H21: =SUM(D21:G21) -> 0
A22: Bachelor's Degree | D22: na | E22: na | F22: na | G22: na | H22: =SUM(D22:G22) -> 0
B23: Bach. graduates admitted to graduate school | D23: na | E23: na | F23: na | G23: na | H23: =SUM(D23:G23) -> 0
B24: Bach. graduated with a GPA of 3.0 or above | D24: na | E24: na | F24: na | G24: na | H24: =SUM(D24:G24) -> 0
A25: Master's Degree | D25: na | E25: na | F25: na | G25: na | H25: =SUM(D25:G25) -> 0
A26: Employed after graduation | D26: m | E26: m | F26: m | G26: m | H26: =SUM(D26:G26) -> 0
A28: Notes:
A29: na = not offered; m = not tracked;

Sheet 4.2(AU) Major Group Enroll-Grad
A1: Institution | D1: ='1.1 Overall Institution Profile'!B1 -> Oglala Lakota College
A2: Indicator 4: Student Enrollment and Graduation by Major Group
A3: Table 4.2(AU): Major Group Fall Enrollment, Graduation & Post-Graduate / AY 2010-11
B4: Major Group | C4: AU - Automotive
B5: Please enter the number of students enrolled in this major group for the fall semester.
F6: Fall 2010 (October 15, 2010)
B7: Fall Enrollment (Snapshot) | D7: American Indian | F7: Non-Indian
D8: M | E8: F | F8: M | G8: F | H8: Total
C9: Full Time | D9: na | E9: na | F9: na | G9: na | H9: =SUM(D9:G9) -> 0
C10: Part Time | D10: na | E10: na | F10: na | G10: na | H10: =SUM(D10:G10) -> 0
C11: Total | D11: =SUM(D9:D10) -> 0 | E11: =SUM(E9:E10) -> 0 | F11: =SUM(F9:F10) -> 0 | G11: =SUM(G9:G10) -> 0 | H11: =SUM(D11:G11) -> 0
B12: Please enter the number of diploma, certificates, and degrees earned in this major group. Also enter the number of students graduating with degrees who earned a GPA of 3.0 or above, and the number who were admitted to a 4 year (Associate degree graduates), or graduate school (Bachelor's degree graduates). Lastly, enter the number of all graduating students(certificate or degree) who secured employment after graduation.
F13: July 1, 2010- June 30, 2011
B14: Graduation | D14: American Indian | F14: Non-Indian
D15: M | E15: F | F15: M | G15: F | H15: Total
A16: Apprenticeship/Occupational Program | D16: na | E16: na | F16: na | G16: na | H16: =SUM(D16:G16) -> 0
A17: Diploma | D17: na | E17: na | F17: na | G17: na | H17: =SUM(D17:G17) -> 0
A18: Certificate | D18: na | E18: na | F18: na | G18: na | H18: =SUM(D18:G18) -> 0
A19: Associate Degree | D19: na | E19: na | F19: na | G19: na | H19: =SUM(D19:G19) -> 0
B20: Assoc. graduates admitted to four-year program | D20: na | E20: na | F20: na | G20: na | H20: =SUM(D20:G20) -> 0
B21: Assoc. graduated with a GPA of 3.0 or above | D21: na | E21: na | F21: na | G21: na | H21: =SUM(D21:G21) -> 0
A22: Bachelor's Degree | D22: na | E22: na | F22: na | G22: na | H22: =SUM(D22:G22) -> 0
B23: Bach. graduates admitted to graduate school | D23: na | E23: na | F23: na | G23: na | H23: =SUM(D23:G23) -> 0
B24: Bach. graduated with a GPA of 3.0 or above | D24: na | E24: na | F24: na | G24: na | H24: =SUM(D24:G24) -> 0
A25: Master's Degree | D25: na | E25: na | F25: na | G25: na | H25: =SUM(D25:G25) -> 0
A26: Employed after graduation | D26: na | E26: na | F26: na | G26: na | H26: =SUM(D26:G26) -> 0
A28: Notes:

Sheet 4.2(BI) Major Group Enroll-Grad
A1: Institution | D1: ='1.1 Overall Institution Profile'!B1 -> Oglala Lakota College
A2: Indicator 4: Student Enrollment and Graduation by Major Group
A3: Table 4.2(BI): Major Group Fall Enrollment, Graduation & Post-Graduate / AY 2010-11
B4: Major Group | C4: BI - Biology
B5: Please enter the number of students enrolled in this major group for the fall semester.
F6: Fall 2010 (October 15, 2010)
B7: Fall Enrollment (Snapshot) | D7: American Indian | F7: Non-Indian
D8: M | E8: F | F8: M | G8: F | H8: Total
C9: Full Time | D9: na | E9: na | F9: na | G9: na | H9: =SUM(D9:G9) -> 0
C10: Part Time | D10: na | E10: na | F10: na | G10: na | H10: =SUM(D10:G10) -> 0
C11: Total | D11: =SUM(D9:D10) -> 0 | E11: =SUM(E9:E10) -> 0 | F11: =SUM(F9:F10) -> 0 | G11: =SUM(G9:G10) -> 0 | H11: =SUM(D11:G11) -> 0
B12: Please enter the number of diploma, certificates, and degrees earned in this major group. Also enter the number of students graduating with degrees who earned a GPA of 3.0 or above, and the number who were admitted to a 4 year (Associate degree graduates), or graduate school (Bachelor's degree graduates). Lastly, enter the number of all graduating students(certificate or degree) who secured employment after graduation.
F13: July 1, 2010- June 30, 2011
B14: Graduation | D14: American Indian | F14: Non-Indian
D15: M | E15: F | F15: M | G15: F | H15: Total
A16: Apprenticeship/Occupational Program | D16: na | E16: na | F16: na | G16: na | H16: =SUM(D16:G16) -> 0
A17: Diploma | D17: na | E17: na | F17: na | G17: na | H17: =SUM(D17:G17) -> 0
A18: Certificate | D18: na | E18: na | F18: na | G18: na | H18: =SUM(D18:G18) -> 0
A19: Associate Degree | D19: na | E19: na | F19: na | G19: na | H19: =SUM(D19:G19) -> 0
B20: Assoc. graduates admitted to four-year program | D20: na | E20: na | F20: na | G20: na | H20: =SUM(D20:G20) -> 0
B21: Assoc. graduated with a GPA of 3.0 or above | D21: na | E21: na | F21: na | G21: na | H21: =SUM(D21:G21) -> 0
A22: Bachelor's Degree | D22: na | E22: na | F22: na | G22: na | H22: =SUM(D22:G22) -> 0
B23: Bach. graduates admitted to graduate school | D23: na | E23: na | F23: na | G23: na | H23: =SUM(D23:G23) -> 0
B24: Bach. graduated with a GPA of 3.0 or above | D24: na | E24: na | F24: na | G24: na | H24: =SUM(D24:G24) -> 0
A25: Master's Degree | D25: na | E25: na | F25: na | G25: na | H25: =SUM(D25:G25) -> 0
A26: Employed after graduation | D26: na | E26: na | F26: na | G26: na | H26: =SUM(D26:G26) -> 0
A28: Notes:

Sheet 4.2(BT) Major Group Enroll-Grad
A1: Institution | D1: ='1.1 Overall Institution Profile'!B1 -> Oglala Lakota College
A2: Indicator 4: Student Enrollment and Graduation by Major Group
A3: Table 4.2(BT): Major Group Fall Enrollment, Graduation & Post-Graduate / AY 2010-11
B4: Major Group | C4: BT - Building Trades
B5: Please enter the number of students enrolled in this major group for the fall semester.
F6: Fall 2010 (October 15, 2010)
B7: Fall Enrollment (Snapshot) | D7: American Indian | F7: Non-Indian
D8: M | E8: F | F8: M | G8: F | H8: Total
C9: Full Time | D9: 0 | E9: 0 | F9: 0 | G9: 0 | H9: =SUM(D9:G9) -> 0
C10: Part Time | D10: 0 | E10: 0 | F10: 0 | G10: 0 | H10: =SUM(D10:G10) -> 0
C11: Total | D11: =SUM(D9:D10) -> 0 | E11: =SUM(E9:E10) -> 0 | F11: =SUM(F9:F10) -> 0 | G11: =SUM(G9:G10) -> 0 | H11: =SUM(D11:G11) -> 0
B12: Please enter the number of diploma, certificates, and degrees earned in this major group. Also enter the number of students graduating with degrees who earned a GPA of 3.0 or above, and the number who were admitted to a 4 year (Associate degree graduates), or graduate school (Bachelor's degree graduates). Lastly, enter the number of all graduating students(certificate or degree) who secured employment after graduation.
F13: July 1, 2010- June 30, 2011
B14: Graduation | D14: American Indian | F14: Non-Indian
D15: M | E15: F | F15: M | G15: F | H15: Total
A16: Apprenticeship/Occupational Program | D16: na | E16: na | F16: na | G16: na | H16: =SUM(D16:G16) -> 0
A17: Diploma | D17: na | E17: na | F17: na | G17: na | H17: =SUM(D17:G17) -> 0
A18: Certificate | D18: 2 | E18: 1 | F18: 0 | G18: 0 | H18: =SUM(D18:G18) -> 3
A19: Associate Degree | D19: 4 | E19: 0 | F19: 0 | G19: 0 | H19: =SUM(D19:G19) -> 4
B20: Assoc. graduates admitted to four-year program | D20: 0 | E20: 0 | F20: 0 | G20: 0 | H20: =SUM(D20:G20) -> 0
B21: Assoc. graduated with a GPA of 3.0 or above | D21: 2 | E21: 0 | F21: 0 | G21: 0 | H21: =SUM(D21:G21) -> 2
A22: Bachelor's Degree | D22: na | E22: na | F22: na | G22: na | H22: =SUM(D22:G22) -> 0
B23: Bach. graduates admitted to graduate school | D23: na | E23: na | F23: na | G23: na | H23: =SUM(D23:G23) -> 0
B24: Bach. graduated with a GPA of 3.0 or above | D24: na | E24: na | F24: na | G24: na | H24: =SUM(D24:G24) -> 0
A25: Master's Degree | D25: na | E25: na | F25: na | G25: na | H25: =SUM(D25:G25) -> 0
A26: Employed after graduation | D26: m | E26: m | F26: m | G26: m | H26: =SUM(D26:G26) -> 0
A28: Notes:
A29: na = not offered; m = not tracked;

Sheet 4.2(BU) Major Group Enroll-Grad
A1: Institution | D1: ='1.1 Overall Institution Profile'!B1 -> Oglala Lakota College
A2: Indicator 4: Student Enrollment and Graduation by Major Group
A3: Table 4.2(BU): Major Group Fall Enrollment, Graduation & Post-Graduate / AY 2010-11
B4: Major Group | C4: BU - Business
B5: Please enter the number of students enrolled in this major group for the fall semester.
F6: Fall 2010 (October 15, 2010)
B7: Fall Enrollment (Snapshot) | D7: American Indian | F7: Non-Indian
D8: M | E8: F | F8: M | G8: F | H8: Total
C9: Full Time | D9: 77 | E9: 115 | F9: 3 | G9: 0 | H9: =SUM(D9:G9) -> 195
C10: Part Time | D10: 40 | E10: 69 | F10: 2 | G10: 4 | H10: =SUM(D10:G10) -> 115
C11: Total | D11: =SUM(D9:D10) -> 117 | E11: =SUM(E9:E10) -> 184 | F11: =SUM(F9:F10) -> 5 | G11: =SUM(G9:G10) -> 4 | H11: =SUM(D11:G11) -> 310
B12: Please enter the number of diploma, certificates, and degrees earned in this major group. Also enter the number of students graduating with degrees who earned a GPA of 3.0 or above, and the number who were admitted to a 4 year (Associate degree graduates), or graduate school (Bachelor's degree graduates). Lastly, enter the number of all graduating students(certificate or degree) who secured employment after graduation.
F13: July 1, 2010- June 30, 2011
B14: Graduation | D14: American Indian | F14: Non-Indian
D15: M | E15: F | F15: M | G15: F | H15: Total
A16: Apprenticeship/Occupational Program | D16: na | E16: na | F16: na | G16: na | H16: =SUM(D16:G16) -> 0
A17: Diploma | D17: na | E17: na | F17: na | G17: na | H17: =SUM(D17:G17) -> 0
A18: Certificate | D18: 0 | E18: 0 | F18: 0 | G18: 0 | H18: =SUM(D18:G18) -> 0
A19: Associate Degree | D19: 3 | E19: 20 | F19: 0 | G19: 1 | H19: =SUM(D19:G19) -> 24
B20: Assoc. graduates admitted to four-year program | D20: 0 | E20: 0 | F20: 0 | G20: 0 | H20: =SUM(D20:G20) -> 0
B21: Assoc. graduated with a GPA of 3.0 or above | D21: 2 | E21: 12 | F21: 0 | G21: 1 | H21: =SUM(D21:G21) -> 15
A22: Bachelor's Degree | D22: 1 | E22: 8 | F22: 0 | G22: 1 | H22: =SUM(D22:G22) -> 10
B23: Bach. graduates admitted to graduate school | D23: 0 | E23: 0 | F23: 0 | G23: 0 | H23: =SUM(D23:G23) -> 0
B24: Bach. graduated with a GPA of 3.0 or above | D24: 1 | E24: 8 | F24: 0 | G24: 1 | H24: =SUM(D24:G24) -> 10
A25: Master's Degree | D25: na | E25: na | F25: na | G25: na | H25: =SUM(D25:G25) -> 0
A26: Employed after graduation | D26: m | E26: m | F26: m | G26: m | H26: =SUM(D26:G26) -> 0
A28: Notes:
A29: na = not offered; m = not tracked;

Sheet 4.2(CH) Major Group Enroll-Grad
A1: Institution | D1: ='1.1 Overall Institution Profile'!B1 -> Oglala Lakota College
A2: Indicator 4: Student Enrollment and Graduation by Major Group
A3: Table 4.2(CH): Major Group Fall Enrollment, Graduation & Post-Graduate / AY 2010-11
B4: Major Group | C4: CH - Chemistry
B5: Please enter the number of students enrolled in this major group for the fall semester.
F6: Fall 2010 (October 15, 2010)
B7: Fall Enrollment (Snapshot) | D7: American Indian | F7: Non-Indian
D8: M | E8: F | F8: M | G8: F | H8: Total
C9: Full Time | D9: na | E9: na | F9: na | G9: na | H9: =SUM(D9:G9) -> 0
C10: Part Time | D10: na | E10: na | F10: na | G10: na | H10: =SUM(D10:G10) -> 0
C11: Total | D11: =SUM(D9:D10) -> 0 | E11: =SUM(E9:E10) -> 0 | F11: =SUM(F9:F10) -> 0 | G11: =SUM(G9:G10) -> 0 | H11: =SUM(D11:G11) -> 0
B12: Please enter the number of diploma, certificates, and degrees earned in this major group. Also enter the number of students graduating with degrees who earned a GPA of 3.0 or above, and the number who were admitted to a 4 year (Associate degree graduates), or graduate school (Bachelor's degree graduates). Lastly, enter the number of all graduating students(certificate or degree) who secured employment after graduation.
F13: July 1, 2010- June 30, 2011
B14: Graduation | D14: American Indian | F14: Non-Indian
D15: M | E15: F | F15: M | G15: F | H15: Total
A16: Apprenticeship/Occupational Program | D16: na | E16: na | F16: na | G16: na | H16: =SUM(D16:G16) -> 0
A17: Diploma | D17: na | E17: na | F17: na | G17: na | H17: =SUM(D17:G17) -> 0
A18: Certificate | D18: na | E18: na | F18: na | G18: na | H18: =SUM(D18:G18) -> 0
