Workbook

Sheet Dates
B3: Key Dates for Odd year Election Calendar | D3: DATES
B6: Enter Date of Previous November General Election | D6: 41583
B7: Enter Date that Legislative Session Begins | D7: 41695
B8: Enter Date of First Monday in January | D8: 41645
B9: Enter Date of Township Election (2nd Tues in March) | D9: 41709
B10: Enter Date of Primary Election (2nd Tues.) | D10: 41863
B11: Enter Date of General Election (1st Tuesday after 1st Monday in Nov.) | D11: 41947
B12: Enter Date of Next Years March Township Election | D12: 42073
B13: Enter New Years Day | D13: 41640
B14: Enter Martin Luther King Jr. Day | D14: 41659
B15: Enter Presidents Day | D15: 41687
B16: Enter Memorial Day | D16: 41785
B17: Enter Independence Day Holiday | D17: 41824
... B31: Enter date of 2014 Precinct Caucuses | D31: 41674
B34: Formulas on next pages will automatically update Calendar (Even Year)

Sheet Combined Elections Calendar
A1: 2014 Minnesota Combined Elections Calendar - Revised
A2: Updated 6-17-2014
A3: This calendar lists important election dates related to the 2014 Election Cycle. Date entries include citations to Minnesota Statutes or Minnesota Rules. Minnesota Statutes and Rules are available at http://www.revisor.leg.state.mn.us. In all matters, Minnesota Election Law is the final authority, not this calendar. Changes to Minnesota Election Law enacted by the Minnesota State Legislature in 2014 may alter dates or other information on this calendar. For the most current version of this document please check the Secretary of State's website at www.sos.state.mn.us.
A5: This calendar is not intended to provide legal advice and should not be used as a substitute for legal guidance. Readers should consult with an attorney for advice concerning specific situations.
A7: *Metro Towns (200.02, subd. 24): Towns located in Anoka, Carver, Chisago, Dakota, Hennepin, Isanti, Ramsey, Scott, Sherburne, Washington, and Wright Counties.
A9: **Metropolitan area (473.121, subd. 2): The area over which the Metropolitan Council has jurisdiction, including only the counties of Anoka; Carver; Dakota excluding the city of Northfield; Hennepin excluding the cities of Hanover and Rockford; Ramsey; Scott excluding the city of New Prague; and Washington.
A11: Calculation of Dates: Dates on the 2014 Minnesota Combined Election Calendar are calculated in the following manner, pursuant to Minnesota Statutes, Chapter 645: When counting the number of days before an election or other event, the day before the event is the first day counted. When counting the number of days after an election or other event, the day after the event is the first day counted. When the last day falls on a weekend or legal holiday, that day is usually omitted from the computation.
A13: Note: When Minnesota Election Law requires that action be taken on or before a date that falls on a weekend, this calendar usually uses the previous Friday date to ensure timely action.
A15: For relevant law on the calculation of dates, see Minn. Stat. §§ 645.13; 645.15; 645.151; 331A.08, subd. 1; 331A.08, subd. 2.
A17: 645.13 Time; publication for successive weeks. When the term "successive weeks" is used in any law providing for the publishing of notices, the word "weeks" shall be construed as calendar weeks. The publication upon any day of such weeks shall be sufficient publication for that week, but at least five days shall elapse between each publication. At least the number of weeks specified in "successive weeks" shall elapse between the first publication and the day for the happening of the event for which the publication is made.
A19: 645.15 Computation of time. Where the performance or doing of any act, duty, matter, payment, or thing is ordered or directed, and the period of time or duration for the performance or doing thereof is prescribed and fixed by law, the time, except as otherwise provided in sections 645.13 and 645.14, shall be computed so as to exclude the first and include the last day of the prescribed or fixed period or duration of time. When the last day of the period falls on Saturday, Sunday or a legal holiday, that day shall be omitted from the computation.
A21: 645.151 Timely delivery or filing. When an application, payment, return, claim, statement or other document is to be delivered to or filed with a department, agency or instrumentality of this state or of a political subdivision on or before a prescribed date and the prescribed date falls on a Saturday, Sunday or legal holiday, it is timely delivered or filed if it is delivered or filed on the next succeeding day which is not a Saturday, Sunday or legal holiday.
A23: 331A.08 Subd.1. Time for publication. The time for publication of public notices shall be computed to exclude the first day of publication and include the day on which the act or event, of which notice is given, is to happen or which completes the full period required for publication. Subd. 2. Time for act or proceeding. The time within which an act is to be done or proceeding had or taken, as prescribed by the rules of procedure, shall be computed by excluding the first day and including the last. If the last day is Sunday or a legal holiday the party shall have the next secular day in which to do the act or take the proceeding.
A25: Begin Date | B25: End Date | C25: Bolded type indicates subdivision affected: | D25: Statute § | E25: Affected | F25: Reference
A26: 41603 | B26: 41603 | C26: Secretary of State: Deadline for 2013 HAVA Grant Progress Reports on HAVA grant funds used for both the 2005 HAVA grants and 2010 HAVA equipment grants. Unless all funds have been disbursed and reported on in a previous year. These reports cover the period of 10/1/2012 to 9/30/2013. 42 U.S.C. 15421 | D26: 42 USC 15421 | E26: Secretary of State | F26: HAVA
A27: 41603 | B27: 41603 | C27: Counties: Deadline for 2013 HAVA Grant Progress Reports on HAVA grant funds used for both the 2005 HAVA grants and 2010 HAVA equipment grants. Unless all funds have been disbursed and reported on in a previous year. These reports cover the period of 10/1/2012 to 9/30/2013. 42 U.S.C. 15421 | D27: 42 USC 15421 | E27: Counties | F27: HAVA
A28: =+Dates!$D$9-98 -> 41611 | B28: =+Dates!$D$9-98 -> 41611 | C28: Counties: Last day to designate location for March township elections absentee voting - 14 weeks before election. Minn. Stat. §203B.081 | D28: 203B.081 | E28: Counties | F28: AB
A29: =+Dates!$D$9-98 -> 41611 | B29: =+Dates!$D$9-98 -> 41611 | C29: Towns with March Elections: Last day to designate location for March township elections absentee voting - 14 weeks before election. Minn. Stat. §203B.081 | D29: 203B.081 | E29: Towns with March Elections | F29: AB
A30: 41612 | B30: 41612 | C30: Secretary of State: Application deadline for cities, townships, and counties applying for 2013-2014 EAID Grant. 42 U.S.C. 15421 | D30: 42 USC 15421 | E30: Secretary of State | F30: HAVA
A31: 41612 | B31: 41612 | C31: Counties: Application deadline for cities, townships, and counties applying for 2013-2014 EAID Grant. 42 U.S.C. 15421 | D31: 42 USC 15421 | E31: Counties | F31: HAVA
A32: 41612 | B32: 41612 | C32: Cities with a Primary: Application deadline for cities, townships, and counties applying for 2013-2014 EAID Grant. 42 U.S.C. 15421 | D32: 42 USC 15421 | E32: Cities with a Primary | F32: HAVA
A33: 41612 | B33: 41612 | C33: Cities without a Primary: Application deadline for cities, townships, and counties applying for 2013-2014 EAID Grant. 42 U.S.C. 15421 | D33: 42 USC 15421 | E33: Cities without a Primary | F33: HAVA
A34: 41612 | B34: 41612 | C34: Towns with March Elections: Application deadline for cities, townships, and counties applying for 2013-2014 EAID Grant. 42 U.S.C. 15421 | D34: 42 USC 15421 | E34: Towns with March Elections | F34: HAVA
A35: 41612 | B35: 41612 | C35: Towns with November Elections: Application deadline for cities, townships, and counties applying for 2013-2014 EAID Grant. 42 U.S.C. 15421 | D35: 42 USC 15421 | E35: Towns with November Elections | F35: HAVA
A36: =+Dates!$D$9-90 -> 41619 | B36: =+Dates!$D$9-90 -> 41619 | C36: Counties: Last day to change polling place prior to March township elections - not less than 90 days prior to election. Minn. Stat. §204B.16, subd. 3 | D36: 204B.16, subd. 3 | E36: Counties | F36: Polling Place
A37: =+Dates!$D$9-90 -> 41619 | B37: =+Dates!$D$9-90 -> 41619 | C37: Towns with March Elections: Last day to change polling place prior to March township elections - not less than 90 days prior to election. Minn. Stat. §204B.16, subd. 3 | D37: 204B.16, subd. 3 | E37: Towns with March Elections | F37: Polling Place
A38: =+Dates!$D$9-90 -> 41619 | B38: =+Dates!$D$9-90 -> 41619 | C38: Secretary of State: The municipal governing body, school board, or county board may authorize mail balloting by resolution - no later than 90 days prior to the first election at which mail balloting will be used. Minn. Rule 8210.3000, subp. 2 | D38: 8210.3000, subp. 2 | E38: Secretary of State | F38: Mail Elections
A39: =+Dates!$D$9-90 -> 41619 | B39: =+Dates!$D$9-90 -> 41619 | C39: Counties: The municipal governing body, school board, or county board may authorize mail balloting by resolution - no later than 90 days prior to the first election at which mail balloting will be used. Minn. Rule 8210.3000, subp. 2 | D39: 8210.3000, subp. 2 | E39: Counties | F39: Mail Elections
A40: =+Dates!$D$9-90 -> 41619 | B40: =+Dates!$D$9-90 -> 41619 | C40: Towns with March Elections: The municipal governing body, school board, or county board may authorize mail balloting by resolution - no later than 90 days prior to the first election at which mail balloting will be used. Minn. Rule 8210.3000, subp. 2 | D40: 8210.3000, subp. 2 | E40: Towns with March Elections | F40: Mail Elections
A41: =+Dates!$D$9-90 -> 41619 | B41: =+Dates!$D$9-90 -> 41619 | C41: Secretary of State: Last day for townships with March election to revoke mail election precinct prior to election - no later than 90 days before the next affected election. Minn. Rule 8210.3000, subp. 2 | D41: 8210.3000, subp. 2 | E41: Secretary of State | F41: Mail Elections
A42: =+Dates!$D$9-90 -> 41619 | B42: =+Dates!$D$9-90 -> 41619 | C42: Counties: Last day for townships with March election to revoke mail election precinct prior to election - no later than 90 days before the next affected election. Minn. Rule 8210.3000, subp. 2 | D42: 8210.3000, subp. 2 | E42: Counties | F42: Mail Elections
A43: =+Dates!$D$9-90 -> 41619 | B43: =+Dates!$D$9-90 -> 41619 | C43: Towns with March Elections: Last day for townships with March election to revoke mail election precinct prior to election - no later than 90 days before the next affected election. Minn. Rule 8210.3000, subp. 2 | D43: 8210.3000, subp. 2 | E43: Towns with March Elections | F43: Mail Elections
A44: =+Dates!$D$6+40 -> 41623 | B44: =+Dates!$D$6+47 -> 41630 | C44: School Districts with a Primary: Last day for winning candidates to file an acceptance and oath of office with the clerk - within 30 days of issuance of certificate of election. Minn. Stat. §205A.10, subd. 3 | D44: 205A.10, subd. 3 | E44: School Districts with a Primary | F44: After the Election
A45: =+Dates!$D$6+40 -> 41623 | B45: =+Dates!$D$6+47 -> 41630 | C45: School Districts without a Primary: Last day for winning candidates to file an acceptance and oath of office with the clerk - within 30 days of issuance of certificate of election. Minn. Stat. §205A.10, subd. 3 | D45: 205A.10, subd. 3 | E45: School Districts without a Primary | F45: After the Election
A46: =+Dates!$D$9-84 -> 41625 | B46: =+Dates!$D$9-84 -> 41625 | C46: Secretary of State: Last day for County Auditor to meet or otherwise communicate with March township officials to review election procedures for 2014 March Township Elections - at least 12 weeks before the March town general election. Minn. Stat. §204B.28, subd. 1 | D46: 204B.28, subd. 1 | E46: Secretary of State | F46: Election Day
A47: =+Dates!$D$9-84 -> 41625 | B47: =+Dates!$D$9-84 -> 41625 | C47: Counties: Last day for County Auditor to meet or otherwise communicate with March township officials to review election procedures for 2014 March Township Elections - at least 12 weeks before the March town general election. Minn. Stat. §204B.28, subd. 1 | D47: 204B.28, subd. 1 | E47: Counties | F47: Election Day
A48: =+Dates!$D$9-84 -> 41625 | B48: =+Dates!$D$9-84 -> 41625 | C48: Towns with March Elections: Last day for County Auditor to meet or otherwise communicate with March township officials to review election procedures for 2014 March Township Elections - at least 12 weeks before the March town general election. Minn. Stat. §204B.28, subd. 1 | D48: 204B.28, subd. 1 | E48: Towns with March Elections | F48: Election Day
A49: =+Dates!$D$9-84 -> 41625 | B49: =+Dates!$D$9-84 -> 41625 | C49: Towns with March Elections: Last day to publish first of two notices of town offices to be elected at March election. Notice to include first and last dates to file for town office, and the closing time for filing (new 2013 language requires the municipal clerk's office to be open for filing from 1-5 p.m. on the last day of the filing period) – at least two weeks before the first day to file an Affidavit of Candidacy. Minn. Stat. §205.13, subd. 2 | D49: 205.13, subd. 2 | E49: Towns with March Elections | F49: Notice
A50: =+Dates!$D$9-81 -> 41628 | B50: =+Dates!$D$9-81 -> 41628 | C50: Towns with March Elections: Last day to post notice of town offices to be elected at March election. Notice to include first and last dates to file for town office, and the closing time for filing on the last day to file - 10 days before the first day to file affidavits of candidacy. Minn. Stat. §205.13, subd. 2 | D50: 205.13, subd. 2 | E50: Towns with March Elections | F50: Notice
A51: =+Dates!$D$9-77 -> 41632 | B51: =+Dates!$D$9-77 -> 41632 | C51: Towns with March Elections: Last day to publish second of two notices of town offices to be elected at March election. Notice to include first and last dates to file for town office, and the closing time for filing (new 2013 language requires the municipal clerk's office to be open for filing from 1-5 p.m. on the last day of the filing period) – at least two weeks before the first day to file an Affidavit of Candidacy. Minn. Stat. §205.13, subd. 2 | D51: 205.13, subd. 2 | E51: Towns with March Elections | F51: Notice
...

Sheet 1
A3: l;l | B3: kk | C3: kk
A28: Begin Date | B28: End Date | C28: Bolded type indicates subdivision affected: | D28: Statute § | E28: Affected | F28: Reference

Sheet 2

Sheet 3

Sheet 4

Sheet 5

Sheet 6

Sheet 7

Sheet 8

Sheet 9

Sheet 10

Sheet 11

Sheet 12

Sheet 13

Sheet 14

Sheet 15

Sheet 16
