Workbook

Sheet Caratula

Sheet Primer nivel de atención
A1: Ministerio de Salud Pública y Asistencia Social/ Comisión de Salud del Congreso/ Organización Panamericana de la Salud
A2: Conjunto de Atenciones en Salud (primero y segundo nivel) (1) Propuesta para la Iniciativa de Ley 42-16
A3: Primer borrador- agosto 2010
A4: PRIMER NIVEL DE ATENCIÓN
A5: Etapa de vida | B5: Atenciones (puestos de salud y equipos de atención ambulatoria) | C5: Base de cálculo | D5: Cobertura (2) (se refiere sólo a la población de responsabilidad del MSPAS) | E5: Número de personas/ atenciones/ prestaciones | F5: Costo unitario por tipo de atención | G5: Costo total por tipo de atención
A6: Gestación (Mujeres gestantes) | B6: Atención prenatal
B7: 1. Consulta prenatal integral | C7: Embarazos esperados (2.3% del total de la población rural=127,087 | D7: 100% de cobertura de atención prenatal (4 consultas por embarazo esperado por año según norma del MSPAS) | E7: ='estructura de cálculo'!F19*4 -> 508348.2 | F7: 20.32 | G7: =E7*F7 -> 10329635
B8: 1.1. Inmunización contra tétanos y difteria | D8: 100% de los embarazos esperados con 3 dosis de TDA según norma del MSPAS | E8: ='estructura de cálculo'!F19*3 -> 381261.15
B9: 1.2. Suplementación con micronutrientes | D9: Suministro de ácido fólico y hierro según norma del MSPAS al 100% de los embarazos esperados | E9: ='estructura de cálculo'!F19 -> 127087.05
B10: 1.3. Exámenes de laboratorio (orina, sífilis, grupo y Rh, glicemia, HB/HT) | D10: realización de examenes de laboratorio según normas del MSPAS al 100% de embarazos esperados en un año | E10: ='estructura de cálculo'!F19 -> 127087.05
B11: 2. Consejería | D11: 100% de los embarazos esperados reciben consejería (cuidados del embarazo, ETS, VIH, MEE, etc.) | E11: ='estructura de cálculo'!F19 -> 127087.05
B12: 3. Detección y referencia de embarazos de alto riesgo (solo incluye costos para el transporte) | C12: 10% del total de embarazos esperados considerados como embarazos de alto riesgo | D12: 100% de embarazos de alto riesgo detectados y referidos a establecimientos del segundo nivel | E12: ='estructura de cálculo'!F19*0.1 -> 12708.705
B13: Atención postnatal tardía
B14: 4. Consulta postnatal | C14: 100% de los partos esperados y atendidos en establecimientos del segundo nivel de atención | D14: 100% de las puerperas esperadas recibiendo una consulta en el post parto tardío | E14: ='estructura de cálculo'!F19 -> 127087.05
B15: 4.1. Administración de micronutrientes | D15: 100% de puerperas esperadas recibiedo micronutrientes durante el post parto tardío según norma del MSPAS | E15: ='estructura de cálculo'!F19 -> 127087.05
B16: 4.2. Educación sanitaria | D16: 100% de puerperas en consulta postnatal recibiéndo educación sanitaria | E16: ='estructura de cálculo'!F19 -> 127087.05
B17: 5. Detección y referencia de casos de alto riesgo (sólo incluye costos para el transporte) | C17: 10% del total de puerperas atentidas en el post parto tardío | D17: 100% de las puerperas de alto riesgo detectadas y referidas a establecimientos del segundo nivel de atención | E17: ='estructura de cálculo'!F19*0.1 -> 12708.705
A18: Neonato | B18: Atención neonatal
B19: 6. Consulta neonatal (40 días de nacido) | C19: 100% de los nacimientos esperados y atendidos en establecimientos del segundo nivel de atención | D19: 100% de neonatos esperados atendidos durante el período neonatal tardío | E19: ='estructura de cálculo'!F19 -> 127087.05
B20: 6.1. Consejería | D20: 100% de las madres recibiendo consejería sobre los cuidados del neonato durante el período tardío | E20: ='estructura de cálculo'!F19 -> 127087.05
B21: 6.2. Vacunación (aplicación de la vacuna BCG) | D21: 100% de neonatos esperados vacunados con una dosis de BCG | E21: ='estructura de cálculo'!F19 -> 127087.05
B22: 7. Consulta de morbilidad en el neonato | C22: 10% del total de neonatos esperados que requerirán ser atentidos por un problema de salud | D22: 100% de neonatos que demandan atención por causas específicas de morbilidad en especial relacionadas con enfermedades prevalentes en la infancia | E22: ='estructura de cálculo'!F19*0.1 -> 12708.705
B23: 8. Detección y referencia del 3% de neonatos (sólo incluye costos par ael transporte) | C23: 3% del total de neonatos esperados atentidos en la consulta de morbilidad | D23: 100% de los neonatos en alto riesgo detectados y referidos a establecimientos del segundo nivel de atención | E23: =E22*0.03 -> 381.26115
A24: Niños menores de 1 año | B24: Atención integral al niño menor de 1 año
B25: 9. Consulta integral del niño menor de 1 año (incluye control de crecimiento y consejería nutricional) | C25: 2.73% del total de la población son niños menores de 1 año= 150,792 | D25: 100% de niños menores de un año recibiendo 5 consultas al año según norma del MSPAS | E25: ='estructura de cálculo'!F5*5 -> 753957.73
B26: 9.1. Vacunación (esquema completo) | C26: Total de niños menores de 1 año= 1570,792 | D26: 100% de niños menores de un año vacunados con esquema completo (3 dosis de pentavalente, polio)según norma del MSPAS | E26: ='estructura de cálculo'!F5*3 -> 452374.64
B27: 9.2. Suplementación con micronutrientes: (vitamina A y hierro) | D27: 100% de niños suplementados con micronutrientes según norma del MSPAS | E27: ='estructura de cálculo'!F5 -> 150791.55
B28: 10. Visita domiciliar familiar integral | D28: 100% de madres de niños menores de 1 año visitadas a nivel del hogar para recibir consejería personalizada a nivel de la familia | E28: ='estructura de cálculo'!F5 -> 150791.55
B29: 11. Consulta morbilidad niños menores de 1 año (incluye medicamentos) | C29: 20% del total de niños menores de 1 año | D29: 100% de niños recibiendo dos consultas de morbilidad al año de enfermedades prevalentes en la infancia | E29: ='estructura de cálculo'!F5*0.2*2 -> 60316.619
B30: 12. Detección y referencia del niño a los establecimientos del segundo nivel (sólo incluye costos para el transporte) | C30: 5% de niños de alto riesgo esperados del total de niños menores de 1 años atendidos en la consulta | D30: 100% de niños de alto riesgo detectados y referidos a establecimientos del segundo nivel | E30: =E29*0.05 -> 3015.8309
A31: Niños de 1 año a menores de 5 años | B31: Atención de niños de 1 año a menores de 5 años
B32: 13. Consulta integral del niño de 1 año menor de 5 años (incluye control de crecimiento, vigilancia y desarrollo y consejería nutricional) | C32: Total de niños de 1 año a menores de 5 años | D32: 100% de niños menores de un año recibiendo 2 consultas al año por intervalo de edad = 8 consultas al año | E32: ='estructura de cálculo'!F8*8 -> 5738146
B33: 13.1. Evaluación de estado nutricional | D33: 100% de niños evaluados nutricionalmente en los establecimientos de salud | E33: ='estructura de cálculo'!F8 -> 717268.25
B34: 13.2. Vacunación (refuerzos): OPV, PENTA, DPT y SR. | D34: 100% de niños vacunados con esquema completo según norma del MSPAS | E34: ='estructura de cálculo'!F8 -> 717268.25
B35: 13.3. Suplementación con micronutrientes: (vitamina A y hierro) | D35: 100% de niños suplementados con micronutrientes según norma del MSPAS | E35: ='estructura de cálculo'!F8 -> 717268.25
B36: 13.4. Administración de desparasitantes a partir de los 2 años) | C36: Total de niños de 2 años a menores de 5 años | D36: 100% de niños de 2 años a menores de 5 años desparasitados cada 6 meses = 6 dosis de desparasitantes | E36: ='estructura de cálculo'!F7*6 -> 3253981
B37: 14. Consulta morbilidad niños de 1 año a menores de 5 años (incluye medicamentos) | C37: 20% del total de niños de 1 año a menores de 5 años | D37: 100% de niños con dos consultas año por morbilidad específica, por enfermedades prevalentes de la infancia y otras | E37: ='estructura de cálculo'!F8*0.2 -> 143453.65
B38: 15. Dtección y referencia del niño a los establecimientos del segundo nivel (5%) (sólo incluye costos para el transporte) | C38: 5% de niños de alto riesgo esperados del total de niños de 1 año a menores de 5 años atendidos en la consulta | D38: 100% de niños de alto riesgo detectados y referidos a establecimientos del segundo nivel | E38: =E37*0.05 -> 7172.6825
A39: Escolares | B39: Atención del escolar
B40: 16. Consulta integral del escolar (incluye evaluación neurosensorial y cognositiva) | C40: 100% de niños en edad escolar de 5 a 14 años | D40: 100% de consultas integrales a niños en edad escolar (1 consulta al año por niño) | E40: ='estructura de cálculo'!F10 -> 1848174.2
...

Sheet estructura de cálculo
A3: Estructura porcentual de la población: | B3: % | C3: Población total | D3: Población objeto de la Ley* | E3: Población Urbana objeto de la Ley (46% del total de la población) | F3: Población Rural objeto de la Ley (54% del total de la población)
A4: Población total | C4: 14017057 | D4: =C4*73/100 -> 10232452 | E4: =D4*0.46 -> 4706927.7 | F4: =D4*0.54 -> 5525523.9
A5: Niños y niñas menores de 1 año | B5: 0.027291812 | C5: =C4*2.729/100 -> 382525.49 | D5: =C5*73/100 -> 279243.6 | E5: =D5*0.46 -> 128452.06 | F5: =D5*0.54 -> 150791.55
A6: Niños y niñas de 1 a menores de 2 años | B6: 0.0316655 | C6: =C4*3.167/100 -> 443920.2 | D6: =C6*73/100 -> 324061.74 | E6: =D6*0.46 -> 149068.4 | F6: =D6*0.54 -> 174993.34
A7: Niños y niñas de 2 a menores de 5 años | B7: 0.098145556 | C7: =C4*9.815/100 -> 1375774.1 | D7: =C7*73/100 -> 1004315.1 | E7: =D7*0.46 -> 461984.96 | F7: =D7*0.54 -> 542330.17
A8: Niños y niñas de 1 a menores de 5 años | B8: =B6+B7 -> 0.12981106 | C8: =C4*12.981/100 -> 1819554.2 | D8: =C8*73/100 -> 1328274.5 | E8: =D8*0.46 -> 611006.29 | F8: =D8*0.54 -> 717268.25
A9: Niños y niñas menores de 5 años | B9: 0.15710287 | C9: =C4*15.71/100 -> 2202079.7 | D9: =C9*73/100 -> 1607518.1 | E9: =D9*0.46 -> 739458.35 | F9: =D9*0.54 -> 868059.8
A10: Niños en edad escolar (5 a 14 años) | B10: 0.2713 | C10: =C4*27.13/100 -> 3802827.6 | D10: =C10*90/100 -> 3422544.8 | E10: =D10*0.46 -> 1574370.6 | F10: =D10*0.54 -> 1848174.2
A11: Adolescentes (15 a 18 años) | B11: 0.0923 | C11: =C4*9.23/100 -> 1293774.4 | D11: =C11*90/100 -> 1164396.9 | E11: =D11*0.46 -> 535622.59 | F11: =D11*0.54 -> 628774.34
A12: Adultos (14 a 54) | B12: 0.48 | C12: =C4*48/100 -> 6728187.4 | D12: =C12*73/100 -> 4911576.8 | E12: =D12*0.46 -> 2259325.3 | F12: =D12*0.54 -> 2652251.5
A13: Adultos hombres (14 a 54) | B13: =B12/2 -> 0.24 | C13: =C4*24/100 -> 3364093.7 | D13: =C13*73/100 -> 2455788.4 | E13: =D13*0.46 -> 1129662.7 | F13: =D13*0.54 -> 1326125.7
A14: Adultos mujeres (14 a 54) | B14: =B12/2 -> 0.24 | C14: =C4*24/100 -> 3364093.7 | D14: =C14*73/100 -> 2455788.4 | E14: =D14*0.46 -> 1129662.7 | F14: =D14*0.54 -> 1326125.7
A15: Adultos mayores (54 a … ) | B15: 0.09 | C15: =C4*9/100 -> 1261535.1 | D15: =C15*73/100 -> 920920.64 | E15: =D15*0.46 -> 423623.5 | F15: =D15*0.54 -> 497297.15
A16: Adultos mayores hombres (54 a….) | B16: 0.045 | C16: =C4*4.5/100 -> 630767.56 | D16: =C16*73/100 -> 460460.32 | E16: =D16*0.46 -> 211811.75 | F16: =D16*0.54 -> 248648.57
A17: Adultos mayores mujeres (54 a….) | B17: 0.045 | C17: =C4*4.5/100 -> 630767.56 | D17: =C17*73/100 -> 460460.32 | E17: =D17*0.46 -> 211811.75 | F17: =D17*0.54 -> 248648.57
A18: Mujeres en edad fértil (10 a 54 años) (REVISAR) | B18: =4520490/14017057 -> 0.32249922 | C18: =C4*32.25/100 -> 4520500.9 | D18: =C18*90/100 -> 4068450.8 | E18: =D18*0.46 -> 1871487.4 | F18: =D18*0.54 -> 2196963.4
A19: Embarazos esperados | B19: 0.023 | C19: =C4*2.3/100 -> 322392.31 | D19: =C19*73/100 -> 235346.39 | E19: =D19*0.46 -> 108259.34 | F19: =D19*0.54 -> 127087.05
A20: Casos esperados de diabetes mielitus ( a partir de la prevalencia de casos en una población, en este caso guatemala) (REVISAR) | G20: Un estudio realizado en 2002 en la zona periurbana de la ciudad de Guatemala (Villa Nueva) halló una prevalencia de diabetes de 8,4% en ambos sexos y en grupos de población mayor de 40 años.
A21: Casos esperados de hipertensión arterial
A22: Casos esperados EPOC
A23: Casos esperados de artritis cronica
A24: Casos de VIH SIDA
A26: * No incluye el 17% cubierto por el IGSS y el 10% cubierto por prestadores privados
A27: ** Para el caso de los niños de 5 a 14 años, adolescnetes de 15 a 18 y mujeres en edad fértil únicamente se le quitará el 10% que es cubierto por prestadores privados

Sheet Segundo nivel de atención
A1: Ministerio de Salud Pública y Asistencia Social/ Comisión de Salud del Congreso/ Organización Panamericana de la Salud
A2: Conjunto de atenciones en salud (primero y segundo nivel) (1) Propuesta para la Iniciativa de Ley 42-16
A3: Primer borrador- agosto 2010
A4: SEGUNDO NIVEL DE ATENCIÓN
A5: Etapa de vida | B5: Atenciones (centros de salud- CAIMI, Hospitales Tipo I | C5: Base de cálculo | D5: Cobertura[2] (se refiere sólo a la población de responsabilidad del MSPAS) | E5: Número de personas/ atenciones/ prestaciones | F5: Costo unitario por tipo de atención | G5: Costo total por tipo de atención
A6: Gestación (Mujeres gestantes) | B6: Atención prenatal
B7: 1. Consulta prenatal | C7: Embarazos esperados (2.3% del total de la población urbana =108,259) | D7: 100% de cobertura de atención prenatal (4 consultas por embarazo esperado por año según norma del MSPAS) | E7: ='estructura de cálculo'!E19*4 -> 433037.35 | F7: 20.32 | G7: =E7*F7 -> 8799319
B8: 1.1. Inmunización contra tétanos y difteria | D8: !00% de los embarazos esperados con 3 dosis de TDA según norma del MSPAS | E8: ='estructura de cálculo'!E19*3 -> 324778.01
B9: 1.2. Suplementación con micronutrientes | D9: Suministro de ácido fólico y hierro según norma del MSPAS al 100% de los embarazos esperados | E9: ='estructura de cálculo'!E19 -> 108259.34
B10: 1.3. Consejería incluido en la tención prenatal, es la misma auxiliar | D10: 100% de embarazos esperados reciben consejería (cuidados del embarazo, ETS, VIH, MEE, etc) | E10: ='estructura de cálculo'!E19 -> 108259.34
B11: 1.4. Exámenes de laboratorio (orina, sífilis, grupo y Rh, glicemia, HB/HT, VIH) | D11: Realizaciòn de examenes de laboratorio según norma del MSPAS al 100% de los embarazos esperados | E11: ='estructura de cálculo'!E19 -> 108259.34
B12: 1.5. Administración de medicamentos (5%) | C12: 5% del total de embarazos esperados | D12: 100% de mujeres atentidas por una morbilidad específica | E12: ='estructura de cálculo'!E19*0.05 -> 5412.9669
B13: 2. Atención prenatal embarazo de alto riesgo | C13: 10% de embarazos de alto riesgo detectados en establecimientos del primer nivel de atención y 10% del total de embarazos esperados en riesgo detectados en el segundo nivel de atención | D13: 100% de embarazos de alto riesgo (área urbana y rural) atendidos | E13: ='estructura de cálculo'!E19*0.1+'Primer nivel de atención'!E12 -> 23534.639
B14: 2.1. Referencia de embarazos de alto riesgo al tercer nivel de atención (20%) | C14: 20% del total de embarazos de alto riesgo (urbano y rural) | D14: 100% de embarazos de alto riesgo referidos al tercer nivel de atención | E14: =E13*0.2 -> 4706.9277
B15: 3. Evaluación bucodental | C15: Total de embarazos esperados | D15: 100% de mujeres embarazadas con exámenes bucodentales | E15: ='estructura de cálculo'!E19 -> 108259.34
B16: Atención del parto
B17: 4. Atención de los partos normales | C17: Total de embarazos esperados población urbana y rural (no incluye los embarazos de alto riesgo) | D17: 100% de la población objetivo de la Ley partos normales rurales y urbanos atendidos | E17: ='estructura de cálculo'!D19 -> 235346.39
B18: 5. Atención de partos de alto riesgo (incluye área rural y urbana) | C18: Atención de partos de alto riesgo del área urbana y rural (no incluye el 20% de embarazos de alto riesgo referidos al tercer nivel de atención) | D18: 100% de partos de alto riesgo atendidos | E18: =E13-E14 -> 18827.711
B19: Atención post parto
B20: 6. Consulta postnatal temprana | C20: 100% de partos normales esperados del área urbana y rural | D20: 100% de cobertura de atención a puerperas (1 consulta en el postparto temprano) incluye área urbana y rural | E20: ='estructura de cálculo'!D19 -> 235346.39
B21: 7. Consulta postnatal tardía | C21: 100% de partos esperados del área urbana | D21: 100% de cobertura de atención a puerperas (1 consulta en el postparto tardío) | E21: ='estructura de cálculo'!E19 -> 108259.34
B22: 7.1. Administración de micronutrientes | D22: 100% de cobertura en administración de micronutrientes a puerperas | E22: ='estructura de cálculo'!E19 -> 108259.34
B23: 7.2. Educación sanitaria | D23: 100% de puerperas recibiendo consejería | E23: ='estructura de cálculo'!E19 -> 108259.34
B24: 8. Post parto complicado detectado y referido (hemorragia / pre-eclampsia) | C24: 20% del total de embarazos esperados | D24: 100% de cobertura de mujeres con un post parto complicado referidas al tercer nivel de atención | E24: =E20*0.2 -> 47069.277
A25: Neonato | B25: Atención neonatal
B26: 9. Consulta neonatal temprana | C26: 100% de los nacimientos esperados y atendidos | D26: 100% de neonatos esperados atendidos durante el período neonatal | E26: ='estructura de cálculo'!D19 -> 235346.39
B27: 9.1. Consejería a la madre del neonato | D27: 100% de las madres recibiendo consejería sobre los cuidados del neonato durante el período tardío | E27: ='estructura de cálculo'!D19 -> 235346.39
B28: 9.2. Vacunación (aplicación de la vacuna BCG) | D28: 10% de neontatos esperados vacunados conun adosis de BCG | E28: ='estructura de cálculo'!E19 -> 108259.34
B29: 9.3. Administración de vitamina K | D29: 100% de neonatos esperados con una dosis de vitamina K | E29: ='estructura de cálculo'!D19 -> 235346.39
B30: 9.4. Prevención profiláctica ocular | D30: 100% de neonatos esperados con prevención profiláctica ocular | E30: ='estructura de cálculo'!D19 -> 235346.39
B31: 10. Consulta de morbilidad del neonato | C31: 10% del total de neonatos esperados que requeriràn ser atendidos por un problema de salud | D31: 100% de neonatos que demandan atención por causas especìficas de morbilidad en especial relacionadas con enfermedades prevalentes en la infancia | E31: ='estructura de cálculo'!E19*0.1 -> 10825.934
B32: 11. Atención del neonato de alto riesgo del área rural | C32: Total de neonatos referidos por el primer nivel de atención | D32: 100% de los neonatos identificados con alto riesgo en el primer nivel de atención | E32: ='Primer nivel de atención'!E23 -> 381.26115
B33: 12. Detección y referencia de casos de alto riesgo (sòlo incluye costos para el transporte) | C33: 3% del total de neonatos eperados atendidos en la consulta de morbilidad (total 11,207) | D33: 100% de neonatos de alto riesgo referidos al tercer nivel de atención | E33: =11207*0.03 -> 336.21
A34: Niño menor de 1 año | B34: Atención integral al niño menor de 1 año
B35: 13. Consulta integral del niño menor de 1 año (incluye control de crecimiento y consejería nutricional) | C35: 2.73% del total de población son niños menores de 1 año=128,452 | D35: 100% de niños menores de un año recibiendo 5 consultas al año segùn norma del MSPAS | E35: ='estructura de cálculo'!E5*5 -> 642260.29
B36: 13.1. Vacunación (esquema completo: 3 dosis de pentavalente, polio) | D36: 100% de niños menores de un año vacunados con esquema completo (3 dosis de pentavalente, polio) según norma del MSPAS | E36: ='estructura de cálculo'!E5*3 -> 385356.17
B37: 13.2. Suplementación con micronutrientes: (vitamina A y hierro) | D37: 100% de niños suplementados con micronutrientes según norma del MSPAS | E37: ='estructura de cálculo'!E5 -> 128452.06
B38: 14. Visita domiciliar familia integral | D38: 100% de madres de niños menores de 1 año visitadas a nivel del hogar para recibir consejería personalizada a nivel de la familia | E38: ='estructura de cálculo'!E5 -> 128452.06
B39: 15. Consulta morbilidad niños menores de 1 año (incluye medicamentos) | C39: 20% del total de niños menores de 1 año | D39: 100% de niños recibiendo dos consultas de morbilidad al año de enfermedades prevalentes en la infancia | E39: ='estructura de cálculo'!E5*0.2 -> 25690.412
B40: 16. Atención de los niños referidos del primer nivel de atención | C40: Total de niños de alto riesgo referidos por el primer nivel de atención | D40: 100% de niños referidos por el primer nivel atendidos en el segundo nivel | E40: ='Primer nivel de atención'!E30 -> 3015.8309
...
