Workbook

Sheet All stats
A1: Team | B1: Tourney | C1: Set | D1: PPG | E1: PPB | F1: 15PG
A2: Bellaire | B2: ACF Fall Texas | C2: ACF Fall | D2: 299.5 | E2: 18.06 | F2: n/a
A3: Cinco Ranch | B3: ACF Fall Texas | C3: ACF Fall | D3: 62.5 | E3: 8.06 | F3: n/a
A4: Dorman | B4: ACF Fall UVA | C4: ACF Fall | D4: 330.3 | E4: 23.57 | F4: n/a
A5: Georgetown Day School | B5: ACF Fall UVA | C5: ACF Fall | D5: 282.3 | E5: 19.68 | F5: n/a
A6: Hanover | B6: ACF Fall Yale | C6: ACF Fall | D6: =((172.5*4)+(267.9*7))/11 -> 233.20909 | E6: =(1210+450)/(27+72) -> 16.767677 | F6: n/a
A7: IMSA | B7: ACF Fall NIU | C7: ACF Fall | D7: 399.6 | E7: 23.31 | F7: n/a
A8: Kealing A | B8: ACF Fall Texas | C8: ACF Fall | D8: 271 | E8: 17.7 | F8: n/a
A9: Loyola A | B9: ACF Fall NIU | C9: ACF Fall | D9: 368.3 | E9: 23.58 | F9: n/a
A10: Loyola B | B10: ACF Fall NIU | C10: ACF Fall | D10: 185 | E10: 14.43 | F10: n/a
A11: Macomb | B11: ACF Fall NIU | C11: ACF Fall | D11: 285 | E11: 18.92 | F11: n/a
A12: North Hollywood A | B12: ACF Fall West | C12: ACF Fall | D12: 233 | E12: 16.85 | F12: n/a
A13: North Hollywood B | B13: ACF Fall West | C13: ACF Fall | D13: 73 | E13: 10.49 | F13: n/a
A14: Rancho Bernardo | B14: ACF Fall West | C14: ACF Fall | D14: 224.5 | E14: 16.78 | F14: n/a
A15: Seven Lakes A | B15: ACF Fall Texas | C15: ACF Fall | D15: 425.8 | E15: 24.08 | F15: n/a
A16: Seven Lakes B | B16: ACF Fall Texas | C16: ACF Fall | D16: 37.2 | E16: 5.21 | F16: n/a
A17: St. Anselm's | B17: ACF Fall UVA | C17: ACF Fall | D17: 348.3 | E17: 23 | F17: n/a
A18: St. John's A | B18: ACF Fall Texas | C18: ACF Fall | D18: 169.4 | E18: 13.51 | F18: n/a
... A36: SJS B | B36: Texas ACF Regionals | C36: ACF Regs | D36: 58.8 | E36: 10.4 | F36: n/a
A37: Alpharetta | B37: ATTACK (National) | C37: ATTACK | D37: 278.3 | E37: 17.82 | F37: 1.8888889
A38: Alpharetta B | B38: ATTACK (Varsity) | C38: ATTACK | D38: 187.1 | E38: 12.81 | F38: =2/7 -> 0.28571429
A39: Athens Academy | B39: ATTACK (National) | C39: ATTACK | D39: 287.2 | E39: 19.88 | F39: 2.3333333
A40: Brookwood A | B40: ATTACK (National) | C40: ATTACK | D40: 367.2 | E40: 22.32 | F40: 2.3333333
A41: Brookwood B | B41: ATTACK (Varsity) | C41: ATTACK | D41: 277.1 | E41: 15.47 | F41: =6/7 -> 0.85714286
A42: Chattahoochee A | B42: ATTACK (National) | C42: ATTACK | D42: 307.2 | E42: 20.34 | F42: 2.1111111
A43: Chattahoochee B | B43: ATTACK (National) | C43: ATTACK | D43: 266.1 | E43: 20.53 | F43: 2.3333333
A44: Chattahoochee C | B44: ATTACK (Varsity) | C44: ATTACK | D44: 172.1 | E44: 13.6 | F44: =5/7 -> 0.71428571
A45: Collins Hill | B45: ATTACK (Varsity) | C45: ATTACK | D45: 248.6 | E45: 13.8 | F45: =10/7 -> 1.4285714
A46: Dorman A | B46: ATTACK (National) | C46: ATTACK | D46: 478.9 | E46: 24.91 | F46: 7.3333333
A47: Dorman B | B47: ATTACK (National) | C47: ATTACK | D47: 307.2 | E47: 18.19 | F47: 2.5555556
A48: Dorman C | B48: ATTACK (National) | C48: ATTACK | D48: 193.3 | E48: 16.43 | F48: 1.6666667
A49: East Paulding | B49: ATTACK (Varsity) | C49: ATTACK | D49: 90.8 | E49: 7.67 | F49: =3/6 -> 0.5
A50: Eastside (GA) | B50: ATTACK (Varsity) | C50: ATTACK | D50: 353.3 | E50: 17.28 | F50: =14/9 -> 1.5555556
A51: Grayson | B51: ATTACK (Varsity) | C51: ATTACK | D51: 130 | E51: 10 | F51: 0
A52: GSMST | B52: ATTACK (Varsity) | C52: ATTACK | D52: 326.1 | E52: 16.45 | F52: =21/9 -> 2.3333333
A53: Johns Creek A | B53: ATTACK (Varsity) | C53: ATTACK | D53: 295.6 | E53: 15.19 | F53: =13/9 -> 1.4444444
A54: Johns Creek B | B54: ATTACK (Varsity) | C54: ATTACK | D54: 133 | E54: 11.29 | F54: =1/5 -> 0.2
A55: Kell | B55: ATTACK (Varsity) | C55: ATTACK | D55: 132.9 | E55: 10.68 | F55: =4/7 -> 0.57142857
A56: Marist A | B56: ATTACK (National) | C56: ATTACK | D56: 270 | E56: 20.66 | F56: 2.2222222
A57: Marist B | B57: ATTACK (Varsity) | C57: ATTACK | D57: 265.7 | E57: 13.51 | F57: =10/7 -> 1.4285714
...

Sheet All IS Sets
A1: Team | B1: Tourney | C1: Set | D1: PPG | E1: PPB | F1: 15PG
A2: Amherst Central A | B2: Bull Bowl | C2: IS107 | D2: 145.5 | E2: 10 | F2: =8/11 -> 0.72727273
A3: Amherst Central B | B3: Bull Bowl | C3: IS107 | D3: 117 | E3: 8.44 | F3: 1
A4: Arcadia A | B4: UCLA TWAIN | C4: IS107 | D4: 403.5 | E4: 20.95 | F4: 4.6
A5: Arcadia B | B5: UCLA TWAIN | C5: IS107 | D5: 385 | E5: 19.37 | F5: 5.2
A6: Arcadia C | B6: UCLA TWAIN | C6: IS107 | D6: 177.5 | E6: 13.75 | F6: 1.6
A7: Arcadia D | B7: UCLA TWAIN | C7: IS107 | D7: 223.5 | E7: 15.41 | F7: 3.3
A8: Arcadia E | B8: UCLA TWAIN | C8: IS107 | D8: 127.5 | E8: 11.1 | F8: 1.3
A9: Arcadia F | B9: UCLA TWAIN | C9: IS107 | D9: 175.5 | E9: 14.71 | F9: 2.3
A10: Armstrong A | B10: GINVIT | C10: IS107 | D10: 277 | E10: 15.05 | F10: 3
A11: Armstrong B | B11: GINVIT | C11: IS107 | D11: 149.5 | E11: 10.58 | F11: 1.2
A12: Armstrong C | B12: GINVIT | C12: IS107 | D12: 123.5 | E12: 9.53 | F12: 0.6
A13: Armstrong D | B13: GINVIT | C13: IS107 | D13: 98.9 | E13: 6.67 | F13: 0.7
A14: Armstrong E | B14: GINVIT | C14: IS107 | D14: 33.9 | E14: 5 | F14: 0.2
A15: Bellaire A | B15: Texas Kickoff Classic | C15: IS107 | D15: 325 | E15: 19.48 | F15: =32/8 -> 4
A16: Bellaire B | B16: Texas Kickoff Classic | C16: IS107 | D16: 308.8 | E16: 16.32 | F16: =26/8 -> 3.25
A17: Bergen A | B17: PHSAT | C17: IS107 | D17: 315 | E17: 16.11 | F17: 2
A18: Bergen B | B18: PHSAT | C18: IS107 | D18: 160 | E18: 13.57 | F18: =6/8 -> 0.75
A19: Berryhill | B19: Tulsa Fall Challenge | C19: IS107 | D19: 76.7 | E19: 10 | F19: 0
A20: Biotech A | B20: PHSAT | C20: IS107 | D20: 131.2 | E20: 12.83 | F20: =6/8 -> 0.75
A21: Biotech B | B21: PHSAT | C21: IS107 | D21: 36.2 | E21: 8.82 | F21: 0
A22: Biotech C | B22: PHSAT | C22: IS107 | D22: 21.9 | E22: 3.33 | F22: 0.5
A23: Bishop Kelly A | B23: Boise State Treasure Valley Tournament III | C23: IS107 | D23: 170.6 | E23: 13.73 | F23: =11/8 -> 1.375
A24: Bishop Kelly B | B24: Boise State Treasure Valley Tournament III | C24: IS107 | D24: 27.5 | E24: 3.53 | F24: =2/8 -> 0.25
A25: Blair | B25: Maryland Fall HS Tournament | C25: IS107 | D25: 408.8 | E25: 22 | F25: =79/12 -> 6.5833333
A26: Blair A | B26: PHSAT | C26: IS107 | D26: 131.2 | E26: 8.07 | F26: =11/8 -> 1.375
A27: Blair B | B27: PHSAT | C27: IS107 | D27: 75.6 | E27: 7.84 | F27: 0.5
A28: Blair C | B28: PHSAT | C28: IS107 | D28: 56.2 | E28: 5.76 | F28: =2/8 -> 0.25
A29: Brashear | B29: SAGACITY VII | C29: IS107 | D29: 104.7 | E29: 8.39 | F29: =6/11 -> 0.54545455
A30: Broughton | B30: Quaker Bowl | C30: IS107 | D30: 37 | E30: 8 | F30: =4/5 -> 0.8
A31: Caesar Rodney | B31: Maryland Fall HS Tournament | C31: IS107 | D31: 116 | E31: 10.89 | F31: =8/10 -> 0.8
A32: Camp Hill | B32: SAGACITY VII | C32: IS107 | D32: 326.1 | E32: 15.79 | F32: =31/11 -> 2.8181818
A33: Carlisle | B33: Quaker Bowl | C33: IS107 | D33: 126.2 | E33: 9.61 | F33: 1
A34: Carrboro A | B34: Quaker Bowl | C34: IS107 | D34: 178.5 | E34: 11.98 | F34: 1.6
A35: Centennial A | B35: Maryland Fall HS Tournament | C35: IS107 | D35: 186.1 | E35: 13.77 | F35: =20/9 -> 2.2222222
A36: Centennial B | B36: Maryland Fall HS Tournament | C36: IS107 | D36: 146.1 | E36: 12.13 | F36: =10/9 -> 1.1111111
A37: Centennial C | B37: Maryland Fall HS Tournament | C37: IS107 | D37: 90 | E37: 8 | F37: =9/9 -> 1
A38: Centennial D | B38: Maryland Fall HS Tournament | C38: IS107 | D38: 65.6 | E38: 8.28 | F38: =4/9 -> 0.44444444
A39: Central | B39: GINVIT | C39: IS107 | D39: 438.2 | E39: 21.05 | F39: =64/11 -> 5.8181818
A40: Chanhassen Blue | B40: GINVIT | C40: IS107 | D40: 150 | E40: 13.65 | F40: 0.7
...

Sheet All sets
A1: Set | B1: All IS Sets | C1: ACF Fall | D1: ACF Regs | E1: ATTACK | F1: BDAT | G1: DAFT | H1: FKT | I1: GSAC | J1: HFT | K1: HT22 | L1: HT23 | M1: IMSANITY2 | N1: IS103A | O1: IS106A | P1: IS107 | Q1: IS108A | R1: IS109 | S1: IS110A | T1: IS111 | U1: IS112A | V1: IS113 | W1: IS114A | X1: IS115 | Y1: LIST | Z1: MN Novice | AA1: OLEFIN | AB1: RAVE | AC1: RMTP | AD1: SCTD1 | AE1: WUHSAC
A2: Stat lines | B2: =COUNT('All IS Sets'!$E$2:$E$1047) -> 1046 | C2: =COUNT('ACF Fall'!$E$2:$E$807) -> 21 | D2: =COUNT('ACF Regs'!$E$2:$E$807) -> 14 | E2: =COUNT(ATTACK!$E$2:$E$807) -> 34 | F2: =COUNT(BDAT!$E$2:$E$807) -> 112 | G2: =COUNT(DAFT!$E$2:$E$807) -> 42 | H2: =COUNT(FKT!$E$2:$E$807) -> 48 | I2: =COUNT(GSAC!$E$2:$E$807) -> 162 | J2: =COUNT(HFT!$E$2:$E$807) -> 115 | K2: =COUNT(HT22!$E$2:$E$807) -> 187 | L2: =COUNT(HT23!$E$2:$E$807) -> 77 | M2: =COUNT(IMSANITY2!$E$2:$E$807) -> 44 | N2: =COUNT(IS103A!$E$2:$E$807) -> 14 | O2: =COUNT(IS106A!$E$2:$E$807) -> 64 | P2: =COUNT(IS107!$E$2:$E$807) -> 255 | Q2: =COUNT(IS108A!$E$2:$E$807) -> 117 | R2: =COUNT(IS109!$E$2:$E$807) -> 415 | S2: =COUNT(IS110A!$E$2:$E$807) -> 152 | T2: =COUNT(IS111!$E$2:$E$783) -> 273 | U2: =COUNT(IS112A!$E$2:$E$783) -> 272 | V2: =COUNT(IS113!$E$2:$E$783) -> 230 | W2: =COUNT(IS114A!$E$2:$E$783) -> 96 | X2: =COUNT(IS115!$E$2:$E$783) -> 90 | Y2: =COUNT(LIST!$E$2:$E$783) -> 51 | Z2: =COUNT('MN Novice'!$E$2:$E$807) -> 30 | AA2: =COUNT(OLEFIN!$E$2:$E$807) -> 73 | AB2: =COUNT(RAVE!$E$2:$E$807) -> 36 | AC2: =COUNT(RMTP!$E$2:$E$807) -> 24 | AD2: =COUNT(SCTD1!$E$2:$E$807) -> 17 | AE2: =COUNT(WUHSAC!$E$2:$E$807) -> 34
A3: Average | B3: =AVERAGE('All IS Sets'!$E$2:$E$1047) -> 11.899635 | C3: =AVERAGE('ACF Fall'!$E$2:$E$807) -> 16.938461 | D3: =AVERAGE('ACF Regs'!$E$2:$E$807) -> 14.693571 | E3: =AVERAGE(ATTACK!$E$2:$E$807) -> 14.248235 | F3: =AVERAGE(BDAT!$E$2:$E$807) -> 11.6875 | G3: =AVERAGE(DAFT!$E$2:$E$807) -> 12.62619 | H3: =AVERAGE(FKT!$E$2:$E$807) -> 14.780833 | I3: =AVERAGE(GSAC!$E$2:$E$807) -> 15.66561 | J3: =AVERAGE(HFT!$E$2:$E$807) -> 12.96678 | K3: =AVERAGE(HT22!$E$2:$E$807) -> 14.560802 | L3: =AVERAGE(HT23!$E$2:$E$807) -> 12.985195 | M3: =AVERAGE(IMSANITY2!$E$2:$E$807) -> 13.709773 | N3: =AVERAGE(IS103A!$E$2:$E$807) -> 16.260714 | O3: =AVERAGE(IS106A!$E$2:$E$807) -> 13.235781 | P3: =AVERAGE(IS107!$E$2:$E$807) -> 12.355327 | Q3: =AVERAGE(IS108A!$E$2:$E$807) -> 15.290256 | R3: =AVERAGE(IS109!$E$2:$E$807) -> 11.017976 | S3: =AVERAGE(IS110A!$E$2:$E$807) -> 14.104671 | T3: =AVERAGE(IS111!$E$2:$E$783) -> 12.838939 | U3: =AVERAGE(IS112A!$E$2:$E$783) -> 15.541728 | V3: =AVERAGE(IS113!$E$2:$E$783) -> 12.819957 | W3: =AVERAGE(IS114A!$E$2:$E$783) -> 13.364167 | X3: =AVERAGE(IS115!$E$2:$E$783) -> 14.188444 | Y3: =AVERAGE(LIST!$E$2:$E$783) -> 18.906275 | Z3: =AVERAGE('MN Novice'!$E$2:$E$807) -> 13.82 | AA3: =AVERAGE(OLEFIN!$E$2:$E$807) -> 14.922347 | AB3: =AVERAGE(RAVE!$E$2:$E$807) -> 16.205833 | AC3: =AVERAGE(RMTP!$E$2:$E$807) -> 15.824167 | AD3: =AVERAGE(SCTD1!$E$2:$E$807) -> 14.147647 | AE3: =AVERAGE(WUHSAC!$E$2:$E$807) -> 13.834118
A4: Median | B4: =MEDIAN('All IS Sets'!$E$2:$E$1047) -> 11.1 | C4: =MEDIAN('ACF Fall'!$E$2:$E$807) -> 16.85 | D4: =MEDIAN('ACF Regs'!$E$2:$E$807) -> 15.07 | E4: =MEDIAN(ATTACK!$E$2:$E$807) -> 13.7 | F4: =MEDIAN(BDAT!$E$2:$E$807) -> 10 | G4: =MEDIAN(DAFT!$E$2:$E$807) -> 11.905 | H4: =MEDIAN(FKT!$E$2:$E$807) -> 14.675 | I4: =MEDIAN(GSAC!$E$2:$E$807) -> 14.94 | J4: =MEDIAN(HFT!$E$2:$E$807) -> 11.32 | K4: =MEDIAN(HT22!$E$2:$E$807) -> 13.79 | L4: =MEDIAN(HT23!$E$2:$E$807) -> 12.95 | M4: =MEDIAN(IMSANITY2!$E$2:$E$807) -> 12.83 | N4: =MEDIAN(IS103A!$E$2:$E$807) -> 16.41 | O4: =MEDIAN(IS106A!$E$2:$E$807) -> 12.205 | P4: =MEDIAN(IS107!$E$2:$E$807) -> 11.52 | Q4: =MEDIAN(IS108A!$E$2:$E$807) -> 15.21 | R4: =MEDIAN(IS109!$E$2:$E$807) -> 10.32 | S4: =MEDIAN(IS110A!$E$2:$E$807) -> 13.485 | T4: =MEDIAN(IS111!$E$2:$E$783) -> 12.1875 | U4: =MEDIAN(IS112A!$E$2:$E$783) -> 15.855 | V4: =MEDIAN(IS113!$E$2:$E$783) -> 12.495 | W4: =MEDIAN(IS114A!$E$2:$E$783) -> 13.43 | X4: =MEDIAN(IS115!$E$2:$E$783) -> 13.49 | Y4: =MEDIAN(LIST!$E$2:$E$783) -> 19.43 | Z4: =MEDIAN('MN Novice'!$E$2:$E$807) -> 14.295 | AA4: =MEDIAN(OLEFIN!$E$2:$E$807) -> 13.72 | AB4: =MEDIAN(RAVE!$E$2:$E$807) -> 16.11 | AC4: =MEDIAN(RMTP!$E$2:$E$807) -> 15.325 | AD4: =MEDIAN(SCTD1!$E$2:$E$807) -> 14.72 | AE4: =MEDIAN(WUHSAC!$E$2:$E$807) -> 13.335
A5: 3rd Quartile | B5: =QUARTILE('All IS Sets'!$E$2:$E$1047,3) -> 15.23 | C5: =QUARTILE('ACF Fall'!$E$2:$E$807,3) -> 22.95 | D5: =QUARTILE('ACF Regs'!$E$2:$E$807,3) -> 15.9425 | E5: =QUARTILE(ATTACK!$E$2:$E$807,3) -> 17.75 | F5: =QUARTILE(BDAT!$E$2:$E$807,3) -> 16.315 | G5: =QUARTILE(DAFT!$E$2:$E$807,3) -> 16.395 | H5: =QUARTILE(FKT!$E$2:$E$807,3) -> 18.1775 | I5: =QUARTILE(GSAC!$E$2:$E$807,3) -> 20.095 | J5: =QUARTILE(HFT!$E$2:$E$807,3) -> 17.948983 | K5: =QUARTILE(HT22!$E$2:$E$807,3) -> 19.013643 | L5: =QUARTILE(HT23!$E$2:$E$807,3) -> 15.47 | M5: =QUARTILE(IMSANITY2!$E$2:$E$807,3) -> 17.1125 | N5: =QUARTILE(IS103A!$E$2:$E$807,3) -> 18.075 | O5: =QUARTILE(IS106A!$E$2:$E$807,3) -> 16.3725 | P5: =QUARTILE(IS107!$E$2:$E$807,3) -> 16.03 | Q5: =QUARTILE(IS108A!$E$2:$E$807,3) -> 18.86 | R5: =QUARTILE(IS109!$E$2:$E$807,3) -> 13.865 | S5: =QUARTILE(IS110A!$E$2:$E$807,3) -> 16.9725 | T5: =QUARTILE(IS111!$E$2:$E$783,3) -> 16.36 | U5: =QUARTILE(IS112A!$E$2:$E$783,3) -> 18.6175 | V5: =QUARTILE(IS113!$E$2:$E$783,3) -> 15.5175 | W5: =QUARTILE(IS114A!$E$2:$E$783,3) -> 16.155 | X5: =QUARTILE(IS115!$E$2:$E$783,3) -> 17.09 | Y5: =QUARTILE(LIST!$E$2:$E$783,3) -> 24.6 | Z5: =QUARTILE('MN Novice'!$E$2:$E$807,3) -> 15.9325 | AA5: =QUARTILE(OLEFIN!$E$2:$E$807,3) -> 18.64 | AB5: =QUARTILE(RAVE!$E$2:$E$807,3) -> 20.07 | AC5: =QUARTILE(RMTP!$E$2:$E$807,3) -> 20.42 | AD5: =QUARTILE(SCTD1!$E$2:$E$807,3) -> 16.63 | AE5: =QUARTILE(WUHSAC!$E$2:$E$807,3) -> 15.85
A6: 1st Quartile | B6: =QUARTILE('All IS Sets'!$E$2:$E$1047,1) -> 8.2725 | C6: =QUARTILE('ACF Fall'!$E$2:$E$807,1) -> 13.51 | D6: =QUARTILE('ACF Regs'!$E$2:$E$807,1) -> 12.575 | E6: =QUARTILE(ATTACK!$E$2:$E$807,1) -> 10.3325 | F6: =QUARTILE(BDAT!$E$2:$E$807,1) -> 7.2325 | G6: =QUARTILE(DAFT!$E$2:$E$807,1) -> 8.8275 | H6: =QUARTILE(FKT!$E$2:$E$807,1) -> 10.3275 | I6: =QUARTILE(GSAC!$E$2:$E$807,1) -> 10.63 | J6: =QUARTILE(HFT!$E$2:$E$807,1) -> 7.8703704 | K6: =QUARTILE(HT22!$E$2:$E$807,1) -> 10.725 | L6: =QUARTILE(HT23!$E$2:$E$807,1) -> 9.43 | M6: =QUARTILE(IMSANITY2!$E$2:$E$807,1) -> 9.7625 | N6: =QUARTILE(IS103A!$E$2:$E$807,1) -> 12.7225 | O6: =QUARTILE(IS106A!$E$2:$E$807,1) -> 10.155 | P6: =QUARTILE(IS107!$E$2:$E$807,1) -> 8.635 | Q6: =QUARTILE(IS108A!$E$2:$E$807,1) -> 12.31 | R6: =QUARTILE(IS109!$E$2:$E$807,1) -> 7.365 | S6: =QUARTILE(IS110A!$E$2:$E$807,1) -> 11.395 | T6: =QUARTILE(IS111!$E$2:$E$783,1) -> 9.29 | U6: =QUARTILE(IS112A!$E$2:$E$783,1) -> 12.6725 | V6: =QUARTILE(IS113!$E$2:$E$783,1) -> 9.5775 | W6: =QUARTILE(IS114A!$E$2:$E$783,1) -> 10 | X6: =QUARTILE(IS115!$E$2:$E$783,1) -> 10.8425 | Y6: =QUARTILE(LIST!$E$2:$E$783,1) -> 14.29 | Z6: =QUARTILE('MN Novice'!$E$2:$E$807,1) -> 11.3925 | AA6: =QUARTILE(OLEFIN!$E$2:$E$807,1) -> 10.47 | AB6: =QUARTILE(RAVE!$E$2:$E$807,1) -> 12.5825 | AC6: =QUARTILE(RMTP!$E$2:$E$807,1) -> 10.205 | AD6: =QUARTILE(SCTD1!$E$2:$E$807,1) -> 11.67 | AE6: =QUARTILE(WUHSAC!$E$2:$E$807,1) -> 11.7425
A7: Standard Deviation | B7: =STDEVP('All IS Sets'!$E$2:$E$1047) -> 4.9266947 | C7: =STDEVP('ACF Fall'!$E$2:$E$807) -> 5.320735 | D7: =STDEVP('ACF Regs'!$E$2:$E$807) -> 2.5715549 | E7: =STDEVP(ATTACK!$E$2:$E$807) -> 4.9206315 | F7: =STDEVP(BDAT!$E$2:$E$807) -> 5.6993403 | G7: =STDEVP(DAFT!$E$2:$E$807) -> 5.2462817 | H7: =STDEVP(FKT!$E$2:$E$807) -> 6.2956277 | I7: =STDEVP(GSAC!$E$2:$E$807) -> 5.9906616 | J7: =STDEVP(HFT!$E$2:$E$807) -> 6.7200255 | K7: =STDEVP(HT22!$E$2:$E$807) -> 5.4129903 | L7: =STDEVP(HT23!$E$2:$E$807) -> 4.9985724 | M7: =STDEVP(IMSANITY2!$E$2:$E$807) -> 5.265221 | N7: =STDEVP(IS103A!$E$2:$E$807) -> 4.676295 | O7: =STDEVP(IS106A!$E$2:$E$807) -> 4.5246156 | P7: =STDEVP(IS107!$E$2:$E$807) -> 4.8886401 | Q7: =STDEVP(IS108A!$E$2:$E$807) -> 4.4008959 | R7: =STDEVP(IS109!$E$2:$E$807) -> 4.8573811 | S7: =STDEVP(IS110A!$E$2:$E$807) -> 4.1103576 | T7: =STDEVP(IS111!$E$2:$E$783) -> 4.9026111 | U7: =STDEVP(IS112A!$E$2:$E$783) -> 4.3516992 | V7: =STDEVP(IS113!$E$2:$E$783) -> 4.7182662 | W7: =STDEVP(IS114A!$E$2:$E$783) -> 4.2225347 | X7: =STDEVP(IS115!$E$2:$E$783) -> 4.6509349 | Y7: =STDEVP(LIST!$E$2:$E$783) -> 5.5416271 | Z7: =STDEVP('MN Novice'!$E$2:$E$807) -> 3.2179611 | AA7: =STDEVP(OLEFIN!$E$2:$E$807) -> 6.0907992 | AB7: =STDEVP(RAVE!$E$2:$E$807) -> 4.7243409 | AC7: =STDEVP(RMTP!$E$2:$E$807) -> 6.1575495 | AD7: =STDEVP(SCTD1!$E$2:$E$807) -> 3.2773241 | AE7: =STDEVP(WUHSAC!$E$2:$E$807) -> 4.3121198
A8: Max | B8: =MAX('All IS Sets'!$E$2:$E$1047) -> 24.85 | C8: =MAX('ACF Fall'!$E$2:$E$807) -> 24.08 | D8: =MAX('ACF Regs'!$E$2:$E$807) -> 19.56 | E8: =MAX(ATTACK!$E$2:$E$807) -> 24.91 | F8: =MAX(BDAT!$E$2:$E$807) -> 25.29 | G8: =MAX(DAFT!$E$2:$E$807) -> 23.28 | H8: =MAX(FKT!$E$2:$E$807) -> 26.91 | I8: =MAX(GSAC!$E$2:$E$807) -> 27.45 | J8: =MAX(HFT!$E$2:$E$807) -> 26.77 | K8: =MAX(HT22!$E$2:$E$807) -> 26.145833 | L8: =MAX(HT23!$E$2:$E$807) -> 25.35 | M8: =MAX(IMSANITY2!$E$2:$E$807) -> 25.97 | N8: =MAX(IS103A!$E$2:$E$807) -> 25.58 | O8: =MAX(IS106A!$E$2:$E$807) -> 24.53 | P8: =MAX(IS107!$E$2:$E$807) -> 24.14 | Q8: =MAX(IS108A!$E$2:$E$807) -> 25.09 | R8: =MAX(IS109!$E$2:$E$807) -> 24.85 | S8: =MAX(IS110A!$E$2:$E$807) -> 22.92 | T8: =MAX(IS111!$E$2:$E$783) -> 24.26 | U8: =MAX(IS112A!$E$2:$E$783) -> 25.38 | V8: =MAX(IS113!$E$2:$E$783) -> 24.86 | W8: =MAX(IS114A!$E$2:$E$783) -> 22.19 | X8: =MAX(IS115!$E$2:$E$783) -> 24.78 | Y8: =MAX(LIST!$E$2:$E$783) -> 27.5 | Z8: =MAX('MN Novice'!$E$2:$E$807) -> 20.27 | AA8: =MAX(OLEFIN!$E$2:$E$807) -> 26.76 | AB8: =MAX(RAVE!$E$2:$E$807) -> 25.07 | AC8: =MAX(RMTP!$E$2:$E$807) -> 25.61 | AD8: =MAX(SCTD1!$E$2:$E$807) -> 19.43 | AE8: =MAX(WUHSAC!$E$2:$E$807) -> 24.15
A9: Min | B9: =MIN('All IS Sets'!$E$2:$E$1047) -> 0 | C9: =MIN('ACF Fall'!$E$2:$E$807) -> 5.21 | D9: =MIN('ACF Regs'!$E$2:$E$807) -> 10.4 | E9: =MIN(ATTACK!$E$2:$E$807) -> 4.44 | F9: =MIN(BDAT!$E$2:$E$807) -> 0.56 | G9: =MIN(DAFT!$E$2:$E$807) -> 0.83 | H9: =MIN(FKT!$E$2:$E$807) -> 2.5 | I9: =MIN(GSAC!$E$2:$E$807) -> 4.44 | J9: =MIN(HFT!$E$2:$E$807) -> 1.58 | K9: =MIN(HT22!$E$2:$E$807) -> 3.33 | L9: =MIN(HT23!$E$2:$E$807) -> 2.86 | M9: =MIN(IMSANITY2!$E$2:$E$807) -> 4.17 | N9: =MIN(IS103A!$E$2:$E$807) -> 8.18 | O9: =MIN(IS106A!$E$2:$E$807) -> 5 | P9: =MIN(IS107!$E$2:$E$807) -> 1.8 | Q9: =MIN(IS108A!$E$2:$E$807) -> 5 | R9: =MIN(IS109!$E$2:$E$807) -> 0 | S9: =MIN(IS110A!$E$2:$E$807) -> 5.68 | T9: =MIN(IS111!$E$2:$E$783) -> 0.83 | U9: =MIN(IS112A!$E$2:$E$783) -> 0 | V9: =MIN(IS113!$E$2:$E$783) -> 2.08 | W9: =MIN(IS114A!$E$2:$E$783) -> 3.33 | X9: =MIN(IS115!$E$2:$E$783) -> 4.84 | Y9: =MIN(LIST!$E$2:$E$783) -> 4.87 | Z9: =MIN('MN Novice'!$E$2:$E$807) -> 6.32 | AA9: =MIN(OLEFIN!$E$2:$E$807) -> 4.35 | AB9: =MIN(RAVE!$E$2:$E$807) -> 4.55 | AC9: =MIN(RMTP!$E$2:$E$807) -> 6.94 | AD9: =MIN(SCTD1!$E$2:$E$807) -> 6.77 | AE9: =MIN(WUHSAC!$E$2:$E$807) -> 5.26

Sheet ACF Fall
A1: Team | B1: Tourney | C1: Set | D1: PPG | E1: PPB | F1: 15PG
A2: Bellaire | B2: ACF Fall Texas | C2: ACF Fall | D2: 299.5 | E2: 18.06 | F2: n/a
A3: Cinco Ranch | B3: ACF Fall Texas | C3: ACF Fall | D3: 62.5 | E3: 8.06 | F3: n/a
A4: Dorman | B4: ACF Fall UVA | C4: ACF Fall | D4: 330.3 | E4: 23.57 | F4: n/a
A5: Georgetown Day School | B5: ACF Fall UVA | C5: ACF Fall | D5: 282.3 | E5: 19.68 | F5: n/a
A6: Hanover | B6: ACF Fall Yale | C6: ACF Fall | D6: =((172.5*4)+(267.9*7))/11 -> 233.20909 | E6: =(1210+450)/(27+72) -> 16.767677 | F6: n/a
A7: IMSA | B7: ACF Fall NIU | C7: ACF Fall | D7: 399.6 | E7: 23.31 | F7: n/a
A8: Kealing A | B8: ACF Fall Texas | C8: ACF Fall | D8: 271 | E8: 17.7 | F8: n/a
A9: Loyola A | B9: ACF Fall NIU | C9: ACF Fall | D9: 368.3 | E9: 23.58 | F9: n/a
A10: Loyola B | B10: ACF Fall NIU | C10: ACF Fall | D10: 185 | E10: 14.43 | F10: n/a
A11: Macomb | B11: ACF Fall NIU | C11: ACF Fall | D11: 285 | E11: 18.92 | F11: n/a
A12: North Hollywood A | B12: ACF Fall West | C12: ACF Fall | D12: 233 | E12: 16.85 | F12: n/a
A13: North Hollywood B | B13: ACF Fall West | C13: ACF Fall | D13: 73 | E13: 10.49 | F13: n/a
A14: Rancho Bernardo | B14: ACF Fall West | C14: ACF Fall | D14: 224.5 | E14: 16.78 | F14: n/a
A15: Seven Lakes A | B15: ACF Fall Texas | C15: ACF Fall | D15: 425.8 | E15: 24.08 | F15: n/a
A16: Seven Lakes B | B16: ACF Fall Texas | C16: ACF Fall | D16: 37.2 | E16: 5.21 | F16: n/a
A17: St. Anselm's | B17: ACF Fall UVA | C17: ACF Fall | D17: 348.3 | E17: 23 | F17: n/a
A18: St. John's A | B18: ACF Fall Texas | C18: ACF Fall | D18: 169.4 | E18: 13.51 | F18: n/a
... A22: Treasure Valley Math & Science | B22: ACF Fall Boise State | C22: ACF Fall | D22: 144 | E22: 13.23 | F22: n/a

Sheet ACF Regs
A1: Team | B1: Tourney | C1: Set | D1: PPG | E1: PPB | F1: 15PG
A2: Bellarmine | B2: Texas ACF Regionals | C2: ACF Regs | D2: 361.8 | E2: 19.56 | F2: n/a
A3: Centennial | B3: Texas ACF Regionals | C3: ACF Regs | D3: 267.9 | E3: 15.83 | F3: n/a
A4: Chattahoochee (GA) | B4: Texas ACF Regionals | C4: ACF Regs | D4: 147.1 | E4: 11.76 | F4: n/a
A5: DCC | B5: Texas ACF Regionals | C5: ACF Regs | D5: 218.9 | E5: 14.62 | F5: n/a
A6: Dorman | B6: Texas ACF Regionals | C6: ACF Regs | D6: 201.5 | E6: 15.22 | F6: n/a
A7: GDS | B7: Texas ACF Regionals | C7: ACF Regs | D7: 185 | E7: 14.92 | F7: n/a
A8: Hunter | B8: Texas ACF Regionals | C8: ACF Regs | D8: 310.7 | E8: 17.65 | F8: n/a
A9: Kealing | B9: Texas ACF Regionals | C9: ACF Regs | D9: 112.5 | E9: 12.44 | F9: n/a
A10: LASA A | B10: Texas ACF Regionals | C10: ACF Regs | D10: 212.9 | E10: 15.98 | F10: n/a
A11: LASA B | B11: Texas ACF Regionals | C11: ACF Regs | D11: 160.7 | E11: 12.98 | F11: n/a
A12: Loyola | B12: Texas ACF Regionals | C12: ACF Regs | D12: 222.9 | E12: 15.42 | F12: n/a
A13: Seven Lakes | B13: Texas ACF Regionals | C13: ACF Regs | D13: 292.1 | E13: 17.72 | F13: n/a
... A15: SJS B | B15: Texas ACF Regionals | C15: ACF Regs | D15: 58.8 | E15: 10.4 | F15: n/a

Sheet ATTACK
A1: Team | B1: Tourney | C1: Set | D1: PPG | E1: PPB | F1: 15PG
A2: Alpharetta | B2: ATTACK (National) | C2: ATTACK | D2: 278.3 | E2: 17.82 | F2: 1.8888889
A3: Alpharetta B | B3: ATTACK (Varsity) | C3: ATTACK | D3: 187.1 | E3: 12.81 | F3: =2/7 -> 0.28571429
A4: Athens Academy | B4: ATTACK (National) | C4: ATTACK | D4: 287.2 | E4: 19.88 | F4: 2.3333333
A5: Brookwood A | B5: ATTACK (National) | C5: ATTACK | D5: 367.2 | E5: 22.32 | F5: 2.3333333
A6: Brookwood B | B6: ATTACK (Varsity) | C6: ATTACK | D6: 277.1 | E6: 15.47 | F6: =6/7 -> 0.85714286
A7: Chattahoochee A | B7: ATTACK (National) | C7: ATTACK | D7: 307.2 | E7: 20.34 | F7: 2.1111111
A8: Chattahoochee B | B8: ATTACK (National) | C8: ATTACK | D8: 266.1 | E8: 20.53 | F8: 2.3333333
A9: Chattahoochee C | B9: ATTACK (Varsity) | C9: ATTACK | D9: 172.1 | E9: 13.6 | F9: =5/7 -> 0.71428571
A10: Collins Hill | B10: ATTACK (Varsity) | C10: ATTACK | D10: 248.6 | E10: 13.8 | F10: =10/7 -> 1.4285714
A11: Dorman A | B11: ATTACK (National) | C11: ATTACK | D11: 478.9 | E11: 24.91 | F11: 7.3333333
A12: Dorman B | B12: ATTACK (National) | C12: ATTACK | D12: 307.2 | E12: 18.19 | F12: 2.5555556
A13: Dorman C | B13: ATTACK (National) | C13: ATTACK | D13: 193.3 | E13: 16.43 | F13: 1.6666667
A14: East Paulding | B14: ATTACK (Varsity) | C14: ATTACK | D14: 90.8 | E14: 7.67 | F14: =3/6 -> 0.5
A15: Eastside (GA) | B15: ATTACK (Varsity) | C15: ATTACK | D15: 353.3 | E15: 17.28 | F15: =14/9 -> 1.5555556
A16: Grayson | B16: ATTACK (Varsity) | C16: ATTACK | D16: 130 | E16: 10 | F16: 0
A17: GSMST | B17: ATTACK (Varsity) | C17: ATTACK | D17: 326.1 | E17: 16.45 | F17: =21/9 -> 2.3333333
A18: Johns Creek A | B18: ATTACK (Varsity) | C18: ATTACK | D18: 295.6 | E18: 15.19 | F18: =13/9 -> 1.4444444
A19: Johns Creek B | B19: ATTACK (Varsity) | C19: ATTACK | D19: 133 | E19: 11.29 | F19: =1/5 -> 0.2
A20: Kell | B20: ATTACK (Varsity) | C20: ATTACK | D20: 132.9 | E20: 10.68 | F20: =4/7 -> 0.57142857
A21: Marist A | B21: ATTACK (National) | C21: ATTACK | D21: 270 | E21: 20.66 | F21: 2.2222222
A22: Marist B | B22: ATTACK (Varsity) | C22: ATTACK | D22: 265.7 | E22: 13.51 | F22: =10/7 -> 1.4285714
A23: Marist C | B23: ATTACK (Varsity) | C23: ATTACK | D23: 98.3 | E23: 8.12 | F23: =2/6 -> 0.33333333
A24: Milton | B24: ATTACK (Varsity) | C24: ATTACK | D24: 110 | E24: 8.46 | F24: =10/7 -> 1.4285714
A25: Norcross A | B25: ATTACK (National) | C25: ATTACK | D25: 334.4 | E25: 20.53 | F25: 3.1111111
A26: Oak Mountain Academy | B26: ATTACK (Varsity) | C26: ATTACK | D26: 200.8 | E26: 13.6 | F26: =5/6 -> 0.83333333
A27: Prince Avenue | B27: ATTACK (Varsity) | C27: ATTACK | D27: 135 | E27: 10.64 | F27: =1/6 -> 0.16666667
A28: River Ridge | B28: ATTACK (Varsity) | C28: ATTACK | D28: 107 | E28: 8.57 | F28: =3/5 -> 0.6
A29: Roswell A | B29: ATTACK (Varsity) | C29: ATTACK | D29: 255 | E29: 14.83 | F29: =12/9 -> 1.3333333
A30: Roswell B | B30: ATTACK (Varsity) | C30: ATTACK | D30: 144.2 | E30: 9.2 | F30: =4/6 -> 0.66666667
A31: Sequoyah | B31: ATTACK (Varsity) | C31: ATTACK | D31: 40.8 | E31: 7.14 | F31: =1/6 -> 0.16666667
A32: Stephenson | B32: ATTACK (Varsity) | C32: ATTACK | D32: 23.3 | E32: 4.44 | F32: =2/6 -> 0.33333333
A33: Wesleyan | B33: ATTACK (Varsity) | C33: ATTACK | D33: 280.7 | E33: 17.54 | F33: =13/7 -> 1.8571429
A34: Wheeler | B34: ATTACK (Varsity) | C34: ATTACK | D34: 170 | E34: 12.31 | F34: =6/7 -> 0.85714286
A35: Woodland | B35: ATTACK (Varsity) | C35: ATTACK | D35: 126.4 | E35: 10.23 | F35: =3/7 -> 0.42857143

Sheet BDAT
A1: Team | B1: Tourney | C1: Set | D1: PPG | E1: PPB | F1: 15PG
A2: Alma Bryant | B2: Norcross BDAT | C2: BDAT | D2: 153 | E2: 11.11 | F2: n/a
A3: Alpharetta | B3: Norcross BDAT | C3: BDAT | D3: 277.5 | E3: 16.23 | F3: n/a
A4: Athens Academy | B4: Norcross BDAT | C4: BDAT | D4: 394.4 | E4: 20.26 | F4: n/a
A5: Baconton A | B5: Quizcat Open | C5: BDAT | D5: 261.9 | E5: 12.58 | F5: =13/8 -> 1.625
A6: Baconton B | B6: Quizcat Open | C6: BDAT | D6: 145.6 | E6: 9.34 | F6: 1
A7: Baconton C | B7: Quizcat Open | C7: BDAT | D7: 103.1 | E7: 7.87 | F7: 0.5
A8: BHS A | B8: Quizcat Open | C8: BDAT | D8: 391.9 | E8: 17.81 | F8: 3
A9: BHS B | B9: Quizcat Open | C9: BDAT | D9: 56.2 | E9: 5.81 | F9: =2/8 -> 0.25
A10: Blacksburg | B10: Virginia Cav Classic | C10: BDAT | D10: 261.1 | E10: 13.78 | F10: =19/9 -> 2.1111111
A11: BMS A | B11: Quizcat Open | C11: BDAT | D11: 78.8 | E11: 7.24 | F11: =2/8 -> 0.25
A12: BMS B | B12: Quizcat Open | C12: BDAT | D12: 15.6 | E12: 4.44 | F12: 0
A13: Brookwood A | B13: Norcross BDAT | C13: BDAT | D13: 458.8 | E13: 21.37 | F13: n/a
A14: Brookwood B | B14: Norcross BDAT | C14: BDAT | D14: 159.2 | E14: 10.65 | F14: n/a
A15: Brookwood C | B15: Norcross BDAT | C15: BDAT | D15: 77 | E15: 6.82 | F15: n/a
A16: Cave Spring A | B16: Virginia Cav Classic | C16: BDAT | D16: 331.7 | E16: 17.26 | F16: =37/9 -> 4.1111111
A17: Cave Spring B | B17: Virginia Cav Classic | C17: BDAT | D17: 120 | E17: 10.66 | F17: =4/9 -> 0.44444444
A18: Centennial A | B18: Norcross BDAT | C18: BDAT | D18: 655.6 | E18: 25.29 | F18: n/a
A19: Centennial B | B19: Norcross BDAT | C19: BDAT | D19: 122.5 | E19: 9.17 | F19: n/a
A20: Charlottesville | B20: Virginia Cav Classic | C20: BDAT | D20: 145 | E20: 8.7 | F20: =8/9 -> 0.88888889
A21: Chattahoochee | B21: Norcross BDAT | C21: BDAT | D21: 362.9 | E21: 18.31 | F21: n/a
A22: Chattahoochee | B22: Virginia Cav Classic | C22: BDAT | D22: 361.7 | E22: 20.76 | F22: =31/9 -> 3.4444444
A23: Christiansburg | B23: Virginia Cav Classic | C23: BDAT | D23: 415 | E23: 21.39 | F23: =43/9 -> 4.7777778
A24: Clayton A | B24: Missouri S&T Fall | C24: BDAT | D24: 436 | E24: 17.79 | F24: 3.7
A25: Clayton B | B25: Missouri S&T Fall | C25: BDAT | D25: 123.1 | E25: 7.12 | F25: =3/8 -> 0.375
A26: Cosby A | B26: Virginia Cav Classic | C26: BDAT | D26: 93.3 | E26: 8.22 | F26: =12/9 -> 1.3333333
A27: Cosby B | B27: Virginia Cav Classic | C27: BDAT | D27: 68.3 | E27: 6.89 | F27: =5/9 -> 0.55555556
A28: Dixon A | B28: Missouri S&T Fall | C28: BDAT | D28: 106.7 | E28: 8.06 | F28: 0
A29: Dixon B | B29: Missouri S&T Fall | C29: BDAT | D29: 25 | E29: 6 | F29: =1/6 -> 0.16666667
A30: Dixon C | B30: Missouri S&T Fall | C30: BDAT | D30: 10 | E30: 1.67 | F30: 0
A31: Dorman A | B31: Virginia Cav Classic | C31: BDAT | D31: 552.2 | E31: 24.37 | F31: =98/9 -> 10.888889
A32: Dorman B | B32: Virginia Cav Classic | C32: BDAT | D32: 357.8 | E32: 20.78 | F32: =45/9 -> 5
A33: Duluth | B33: Norcross BDAT | C33: BDAT | D33: 196.4 | E33: 11.97 | F33: n/a
A34: Early College Academy | B34: Bonfire of the Manatees | C34: BDAT | D34: 112 | E34: 10 | F34: =2/6 -> 0.33333333
A35: East Chapel Hill A | B35: Bonfire of the Manatees | C35: BDAT | D35: 384 | E35: 20.7 | F35: =27/6 -> 4.5
A36: East Chapel Hill B | B36: Bonfire of the Manatees | C36: BDAT | D36: 99 | E36: 9 | F36: 0
A37: Eastside | B37: Norcross BDAT | C37: BDAT | D37: 339.3 | E37: 16.57 | F37: n/a
A38: Elon School | B38: Bonfire of the Manatees | C38: BDAT | D38: 49 | E38: 6.5 | F38: 0
A39: Enloe A | B39: Bonfire of the Manatees | C39: BDAT | D39: 384 | E39: 20.1 | F39: 4
A40: Enloe B | B40: Bonfire of the Manatees | C40: BDAT | D40: 81 | E40: 5.4 | F40: 0.5
...

Sheet DAFT
A1: Team | B1: Tourney | C1: Set | D1: PPG | E1: PPB | F1: 15PG
A2: Bate | B2: DAFT | C2: DAFT | D2: 56.7 | E2: 8 | F2: =1/6 -> 0.16666667
A3: Bergen A | B3: St. Joseph's DAFT mirror | C3: DAFT | D3: 197 | E3: 13.78 | F3: 1.8
A4: Bergen B | B4: St. Joseph's DAFT mirror | C4: DAFT | D4: 144 | E4: 10.56 | F4: 1.5
A5: Bergen C | B5: St. Joseph's DAFT mirror | C5: DAFT | D5: 81.5 | E5: 8.54 | F5: 0.5
A6: Charter A | B6: St. Joseph's DAFT mirror | C6: DAFT | D6: 246 | E6: 17.39 | F6: 1.5
A7: Charter B | B7: St. Joseph's DAFT mirror | C7: DAFT | D7: 145.5 | E7: 11.52 | F7: 1.3
A8: Charter C | B8: St. Joseph's DAFT mirror | C8: DAFT | D8: 77 | E8: 6.2 | F8: 0.5
A9: Charter D | B9: St. Joseph's DAFT mirror | C9: DAFT | D9: 44 | E9: 5.81 | F9: 0.3
A10: Danville | B10: DAFT | C10: DAFT | D10: 267.1 | E10: 14.54 | F10: =14/7 -> 2
A11: DCC A | B11: DAFT | C11: DAFT | D11: 567.5 | E11: 22.45 | F11: =54/6 -> 9
A12: DCC B | B12: DAFT | C12: DAFT | D12: 332.9 | E12: 16.94 | F12: =17/7 -> 2.4285714
A13: GDS | B13: St. Joseph's DAFT mirror | C13: DAFT | D13: 430.5 | E13: 21.34 | F13: 6.4
A14: GNS A | B14: St. Joseph's DAFT mirror | C14: DAFT | D14: 177 | E14: 13.99 | F14: 1.7
A15: GNS B | B15: St. Joseph's DAFT mirror | C15: DAFT | D15: 48 | E15: 8 | F15: 0.2
A16: Grayson A | B16: DAFT | C16: DAFT | D16: 329 | E16: 17.75 | F16: =10/5 -> 2
A17: High Tech A | B17: St. Joseph's DAFT mirror | C17: DAFT | D17: 337 | E17: 20.51 | F17: 4.6
A18: High Tech B | B18: St. Joseph's DAFT mirror | C18: DAFT | D18: 173 | E18: 11.84 | F18: 1.9
A19: High Tech C | B19: St. Joseph's DAFT mirror | C19: DAFT | D19: 111.5 | E19: 11.07 | F19: 1.6
A20: Hunter A | B20: St. Joseph's DAFT mirror | C20: DAFT | D20: 476.5 | E20: 22.39 | F20: 7.8
A21: Hunter B | B21: St. Joseph's DAFT mirror | C21: DAFT | D21: 461 | E21: 23.28 | F21: 7.2
A22: Hunter C | B22: St. Joseph's DAFT mirror | C22: DAFT | D22: 349 | E22: 20.23 | F22: 6
A23: Hunter D | B23: St. Joseph's DAFT mirror | C23: DAFT | D23: 99.5 | E23: 9.81 | F23: 0.4
A24: Kellenberg | B24: St. Joseph's DAFT mirror | C24: DAFT | D24: 139 | E24: 11.97 | F24: 1.6
A25: Manual A | B25: DAFT | C25: DAFT | D25: 274.2 | E25: 17.8 | F25: =13/6 -> 2.1666667
A26: Manual B | B26: DAFT | C26: DAFT | D26: 85 | E26: 10.93 | F26: =2/6 -> 0.33333333
A27: Millburn A | B27: St. Joseph's DAFT mirror | C27: DAFT | D27: 216.5 | E27: 13.26 | F27: 2.6
A28: Millburn B | B28: St. Joseph's DAFT mirror | C28: DAFT | D28: 162 | E28: 10.88 | F28: 1.1
A29: Millburn C | B29: St. Joseph's DAFT mirror | C29: DAFT | D29: 93 | E29: 9.79 | F29: 1.3
A30: Piarist A | B30: DAFT | C30: DAFT | D30: 194 | E30: 14.76 | F30: =7/5 -> 1.4
A31: Piarist B | B31: DAFT | C31: DAFT | D31: 68.3 | E31: 10.45 | F31: =1/6 -> 0.16666667
A32: Ridgewood A | B32: St. Joseph's DAFT mirror | C32: DAFT | D32: 155.5 | E32: 12.43 | F32: 1
A33: Ridgewood B | B33: St. Joseph's DAFT mirror | C33: DAFT | D33: 81 | E33: 7.5 | F33: 0.2
A34: Ridgewood C | B34: St. Joseph's DAFT mirror | C34: DAFT | D34: 54 | E34: 5.28 | F34: 0.1
A35: Seton Hall A | B35: St. Joseph's DAFT mirror | C35: DAFT | D35: 120 | E35: 8.75 | F35: 0.5
A36: SJHS Green | B36: St. Joseph's DAFT mirror | C36: DAFT | D36: 189 | E36: 12.26 | F36: 1.7
A37: SJHS White | B37: St. Joseph's DAFT mirror | C37: DAFT | D37: 173 | E37: 13.15 | F37: 1.9
A38: Wissahicken | B38: St. Joseph's DAFT mirror | C38: DAFT | D38: 274.5 | E38: 18.79 | F38: 4
A39: Woodford A | B39: DAFT | C39: DAFT | D39: 162.9 | E39: 13.65 | F39: =9/7 -> 1.2857143
A40: Woodford B | B40: DAFT | C40: DAFT | D40: 97.5 | E40: 9.06 | F40: =3/6 -> 0.5
...

Sheet FKT
A1: Team | B1: Tourney | C1: Set | D1: PPG | E1: PPB | F1: 15PG
A2: Academic Aves | B2: Centerville FKT | C2: FKT | D2: 504 | E2: 25.91 | F2: n/a
A3: Beachwood Bison | B3: Olmsted Falls FKT | C3: FKT | D3: 405.7 | E3: 21.91 | F3: n/a
A4: Brookville A | B4: Centerville FKT | C4: FKT | D4: 91.4 | E4: 7.76 | F4: n/a
A5: Brookville B | B5: Centerville FKT | C5: FKT | D5: 62.9 | E5: 6.48 | F5: n/a
A6: Brush Varsity A | B6: Olmsted Falls FKT | C6: FKT | D6: 214.3 | E6: 17.78 | F6: n/a
A7: Brush Varsity B | B7: Olmsted Falls FKT | C7: FKT | D7: 142.9 | E7: 10.83 | F7: n/a
A8: Butler A | B8: Centerville FKT | C8: FKT | D8: 201.4 | E8: 13.93 | F8: n/a
A9: Butler B | B9: Centerville FKT | C9: FKT | D9: 65.7 | E9: 6.96 | F9: n/a
A10: Carroll Blue | B10: Centerville FKT | C10: FKT | D10: 254.4 | E10: 17.43 | F10: n/a
A11: Carroll Red | B11: Centerville FKT | C11: FKT | D11: 108.6 | E11: 7.33 | F11: n/a
A12: Centerville A | B12: Centerville FKT | C12: FKT | D12: 197.1 | E12: 16.23 | F12: n/a
A13: Centerville B | B13: Centerville FKT | C13: FKT | D13: 203.8 | E13: 14.41 | F13: n/a
... A49: Waynedale | B49: Olmsted Falls FKT | C49: FKT | D49: 34.3 | E49: 8.46 | F49: n/a

Sheet GSAC
A1: Team | B1: Tourney | C1: Set | D1: PPG | E1: PPB | F1: 15PG
A2: Auburn A | B2: New Trier Varsity Uber Competitive | C2: GSAC | D2: 496 | E2: 26.27 | F2: 8.9
A3: Auburn B | B3: New Trier Varsity Uber Competitive | C3: GSAC | D3: 252 | E3: 20.25 | F3: 3.6
A4: Auburn C | B4: New Trier Varsity Standard | C4: GSAC | D4: 156.5 | E4: 11.76 | F4: 1.1
A5: Barrington | B5: New Trier Varsity Standard | C5: GSAC | D5: 322.7 | E5: 17.64 | F5: =24/11 -> 2.1818182
A6: Beachwood | B6: Glen Gonsalves Memorial Sunday (prelims) | C6: GSAC | D6: 484 | E6: 24.92 | F6: =17/5 -> 3.4
A7: Belvidere North A | B7: New Trier Varsity Uber Competitive | C7: GSAC | D7: 332 | E7: 25.38 | F7: 5
A8: Belvidere North B | B8: New Trier Varsity Standard | C8: GSAC | D8: 126.7 | E8: 8.52 | F8: 1
A9: Belvidere North C | B9: New Trier Varsity Standard | C9: GSAC | D9: 47.5 | E9: 5.29 | F9: 0.2
A10: Branford | B10: UF GSAC | C10: GSAC | D10: 140.6 | E10: 9.32 | F10: n/a
A11: Buffalo Grove A | B11: New Trier Varsity Uber Competitive | C11: GSAC | D11: 345 | E11: 22.95 | F11: 4.9
A12: Buffalo Grove B | B12: New Trier Varsity Standard | C12: GSAC | D12: 102 | E12: 9.06 | F12: 0.2
A13: Caesar Rodney | B13: GSAC | C13: GSAC | D13: 258.04 | E13: 19.772727 | F13: n/a
A14: Carbondale | B14: New Trier Varsity Uber Competitive | C14: GSAC | D14: 350.5 | E14: 24.79 | F14: 6.2
A15: Cave Spring | B15: GSAC | C15: GSAC | D15: 397.5 | E15: 21.640625 | F15: n/a
A16: Centennial | B16: New Trier Varsity Uber Competitive | C16: GSAC | D16: 277 | E16: 20.11 | F16: 4.4
A17: Chaminade A | B17: UF GSAC | C17: GSAC | D17: 83.8 | E17: 10.69 | F17: n/a
A18: Chaminade B | B18: UF GSAC | C18: GSAC | D18: 92.5 | E18: 8.18 | F18: n/a
A19: Chaminade C* | B19: UF GSAC | C19: GSAC | D19: 130.6 | E19: 10.38 | F19: n/a
A20: Chatham A | B20: St. Joseph's GSAC mirror | C20: GSAC | D20: 73 | E20: 7.5 | F20: n/a
A21: Chiles A | B21: UF GSAC | C21: GSAC | D21: 257.9 | E21: 16.79 | F21: n/a
A22: Chiles B* | B22: UF GSAC | C22: GSAC | D22: 168.8 | E22: 13.1 | F22: n/a
A23: CIS A | B23: Mort Walker Invitational | C23: GSAC | D23: 168.5 | E23: 14.17 | F23: n/a
A24: CIS B | B24: Mort Walker Invitational | C24: GSAC | D24: 118 | E24: 7.95 | F24: n/a
A25: Classical Consortium Academy | B25: New Trier Varsity Standard | C25: GSAC | D25: 131.1 | E25: 12.26 | F25: 0.8
A26: Clayton A | B26: Mort Walker Invitational | C26: GSAC | D26: 426.5 | E26: 21.82 | F26: n/a
A27: Clayton B | B27: Mort Walker Invitational | C27: GSAC | D27: 168.9 | E27: 10.13 | F27: n/a
A28: Clayton C | B28: Mort Walker Invitational | C28: GSAC | D28: 199 | E28: 12.95 | F28: n/a
A29: Clover Hill | B29: GSAC | C29: GSAC | D29: 191.04 | E29: 15.833333 | F29: n/a
A30: Cloverleaf | B30: Glen Gonsalves Memorial Sunday (prelims) | C30: GSAC | D30: 308 | E30: 19.11 | F30: =9/5 -> 1.8
A31: Copley 1 | B31: Glen Gonsalves Memorial Sunday (prelims) | C31: GSAC | D31: 412 | E31: 18.5 | F31: =12/5 -> 2.4
A32: Copley 2 | B32: Glen Gonsalves Memorial Sunday (prelims) | C32: GSAC | D32: 172 | E32: 13.67 | F32: =4/5 -> 0.8
A33: Cosby A | B33: GSAC | C33: GSAC | D33: 162 | E33: 12.837838 | F33: n/a
A34: Cosby B | B34: GSAC | C34: GSAC | D34: 116.98 | E34: 10.416667 | F34: n/a
A35: Crete-Monee A | B35: New Trier Varsity Standard | C35: GSAC | D35: 93.1 | E35: 10.39 | F35: 0.3
A36: Crete-Monee B | B36: New Trier Varsity Standard | C36: GSAC | D36: 60.6 | E36: 5.59 | F36: 0.3
A37: Culver Academies A | B37: New Trier Varsity Uber Competitive | C37: GSAC | D37: 346.5 | E37: 22.92 | F37: 5.2
A38: Culver B | B38: New Trier Varsity Standard | C38: GSAC | D38: 115 | E38: 9.02 | F38: 0.5
A39: DeSoto | B39: UF GSAC | C39: GSAC | D39: 240.6 | E39: 14.34 | F39: n/a
A40: Detroit Catholic Central | B40: New Trier Varsity Uber Competitive | C40: GSAC | D40: 513 | E40: 25.49 | F40: 9.7
...

Sheet HFT
A1: Team | B1: Tourney | C1: Set | D1: PPG | E1: PPB | F1: 15PG
A2: Adair A | B2: Western Kentucky Hilltopper Invitational | C2: HFT | D2: 107 | E2: 9.81 | F2: n/a
A3: Adair B | B3: Western Kentucky Hilltopper Invitational | C3: HFT | D3: 22 | E3: 1.58 | F3: n/a
A4: Adair C | B4: Western Kentucky Hilltopper Invitational | C4: HFT | D4: 27 | E4: 3.5 | F4: n/a
A5: Alpharetta | B5: Georgia Harvard Fall Tournament mirror | C5: HFT | D5: 285 | E5: 17.14 | F5: n/a
A6: Athens Academy | B6: Georgia Harvard Fall Tournament mirror | C6: HFT | D6: 339 | E6: 20.27 | F6: n/a
A7: Auburn A | B7: Harvard Fall at Rockford Auburn | C7: HFT | D7: 516.4 | E7: 25.35 | F7: n/a
A8: Auburn B | B8: Harvard Fall at Rockford Auburn | C8: HFT | D8: 281.7 | E8: 17.72 | F8: n/a
A9: Bainbridge | B9: Georgia Harvard Fall Tournament mirror | C9: HFT | D9: 256 | E9: 16.12 | F9: n/a
A10: Ballard | B10: Western Kentucky Hilltopper Invitational | C10: HFT | D10: 182.7 | E10: 13.93 | F10: n/a
A11: Barren | B11: Western Kentucky Hilltopper Invitational | C11: HFT | D11: 113 | E11: 11.32 | F11: n/a
A12: Belvidere North | B12: Harvard Fall at Rockford Auburn | C12: HFT | D12: 318.3 | E12: 20.23 | F12: n/a
A13: Boylan | B13: Harvard Fall at Rockford Auburn | C13: HFT | D13: 88.3 | E13: 8.61 | F13: n/a
... A116: WW South B | B116: Harvard Fall at Rockford Auburn | C116: HFT | D116: 37.2 | E116: 6.67 | F116: n/a

Sheet HT22
A1: Team | B1: Tourney | C1: Set | D1: PPG | E1: PPB | F1: 15PG
A2: Adair | B2: Danville Fall Tournament | C2: HT22 | D2: 243.36667 | E2: 14.133333 | F2: 2.2222222
A3: Anacostia | B3: STANLEY CUP | C3: HT22 | D3: 36 | E3: 6.36 | F3: =2/5 -> 0.4
A4: Antonian | B4: HoHoHo | C4: HT22 | D4: 237.2 | E4: 17.27 | F4: =31/9 -> 3.4444444
A5: Awty A | B5: HoHoHo | C5: HT22 | D5: 148.1 | E5: 10.55 | F5: =20/8 -> 2.5
A6: Awty B | B6: HoHoHo | C6: HT22 | D6: 82.1 | E6: 8.87 | F6: =5/7 -> 0.71428571
A7: Bellaire A | B7: HoHoHo | C7: HT22 | D7: 307.5 | E7: 20.26 | F7: 5.5
A8: Bellaire B | B8: HoHoHo | C8: HT22 | D8: 132.5 | E8: 10.78 | F8: =14/8 -> 1.75
A9: Bellaire C | B9: HoHoHo | C9: HT22 | D9: 257.2 | E9: 14.84 | F9: =26/9 -> 2.8888889
A10: Belvidere North | B10: Loyburn | C10: HT22 | D10: 406.8 | E10: 22.37 | F10: =73/11 -> 6.6363636
A11: Bethel | B11: OSU Winter War | C11: HT22 | D11: 128 | E11: 10.81 | F11: 0.6
A12: Bethlehem | B12: Danville Fall Tournament | C12: HT22 | D12: 212.8 | E12: 12.941176 | F12: 2.3333333
A13: Bishop's A | B13: Triton Fall | C13: HT22 | D13: 244.4 | E13: 19.79 | F13: =36/9 -> 4
A14: Bishop's B | B14: Triton Fall | C14: HT22 | D14: 117.8 | E14: 12.67 | F14: =15/9 -> 1.6666667
A15: Blair A | B15: STANLEY CUP | C15: HT22 | D15: 469 | E15: 19.51 | F15: =53/5 -> 10.6
A16: Blair B | B16: STANLEY CUP | C16: HT22 | D16: 158 | E16: 14.84 | F16: 2
A17: Buffalo Grove A | B17: Loyburn | C17: HT22 | D17: 469.1 | E17: 20.99 | F17: =84/11 -> 7.6363636
A18: Buffalo Grove B | B18: Loyburn | C18: HT22 | D18: 50.9 | E18: 4.52 | F18: =2/11 -> 0.18181818
A19: Caesar Rodney | B19: STANLEY CUP | C19: HT22 | D19: 256 | E19: 16.3 | F19: =19/5 -> 3.8
A20: Canyon Crest | B20: Triton Fall | C20: HT22 | D20: 351 | E20: 21.76 | F20: 5.3
A21: Carbondale | B21: Loyburn | C21: HT22 | D21: 490 | E21: 24.73 | F21: =98/11 -> 8.9090909
A22: Carlsbad A | B22: Triton Fall | C22: HT22 | D22: 218.3 | E22: 17.04 | F22: =20/9 -> 2.2222222
A23: Carlsbad B | B23: Triton Fall | C23: HT22 | D23: 135 | E23: 13.22 | F23: 1.4
A24: Centennial A | B24: STANLEY CUP | C24: HT22 | D24: 265 | E24: 15.6 | F24: =22/5 -> 4.4
A25: Centennial B | B25: STANLEY CUP | C25: HT22 | D25: 183 | E25: 12.38 | F25: =16/5 -> 3.2
A26: Centralia | B26: Missouri Tiger Bowl | C26: HT22 | D26: 158 | E26: 9.3846154 | F26: 0.6
A27: Chantily A | B27: STANLEY CUP | C27: HT22 | D27: 165 | E27: 11.58 | F27: =8/5 -> 1.6
A28: Chantily B | B28: STANLEY CUP | C28: HT22 | D28: 38 | E28: 9.09 | F28: =1/5 -> 0.2
A29: Chapel Hill | B29: Tar Heel Cup 2011 | C29: HT22 | D29: 168.3 | E29: 14.63 | F29: =14/6 -> 2.3333333
A30: Christian Life | B30: Loyburn | C30: HT22 | D30: 65.5 | E30: 4.52 | F30: =10/11 -> 0.90909091
A31: Cinco Ranch | B31: HoHoHo | C31: HT22 | D31: 60 | E31: 12.37 | F31: =3/7 -> 0.42857143
A32: CIS A | B32: Missouri Tiger Bowl | C32: HT22 | D32: 258 | E32: 14.177215 | F32: 3.1
A33: CIS B | B33: Missouri Tiger Bowl | C33: HT22 | D33: 169 | E33: 9.84375 | F33: 1.4
A34: Cistercian A | B34: HoHoHo | C34: HT22 | D34: 454.6 | E34: 23.64 | F34: =86/12 -> 7.1666667
A35: Cistercian B | B35: HoHoHo | C35: HT22 | D35: 274.4 | E35: 17.47 | F35: =34/9 -> 3.7777778
A36: Columbus Academy | B36: OSU Winter War | C36: HT22 | D36: 224 | E36: 14.6 | F36: 3.3
A37: Columbus Alternative | B37: OSU Winter War | C37: HT22 | D37: 224 | E37: 15.06 | F37: 2.7
A38: Cuba | B38: Missouri Tiger Bowl | C38: HT22 | D38: 239 | E38: 12 | F38: 1.5
A39: Daviess County | B39: Danville Fall Tournament | C39: HT22 | D39: 274.52727 | E39: 18.72093 | F39: 2.7272727
A40: DCC A | B40: OSU Winter War | C40: HT22 | D40: 585.5 | E40: 24.88 | F40: =117/11 -> 10.636364
...

Sheet HT23
A1: Team | B1: Tourney | C1: Set | D1: PPG | E1: PPB | F1: 15PG
A2: Alpharetta | B2: Georgia 5A Regionals | C2: HT23 | D2: 511 | E2: 22.46 | F2: 7
A3: Archer | B3: Georgia 5A Regionals | C3: HT23 | D3: 81 | E3: 8.24 | F3: =3/5 -> 0.6
A4: Brookwood | B4: Georgia 5A Regionals | C4: HT23 | D4: 617 | E4: 23.64 | F4: =45/5 -> 9
A5: Cave Spring | B5: TANKBATTLE | C5: HT23 | D5: 200.5 | E5: 12.12 | F5: 1.9090909
A6: Centennial | B6: Georgia 5A Regionals | C6: HT23 | D6: 177 | E6: 14 | F6: =7/5 -> 1.4
A7: Cherokee | B7: Georgia 5A Regionals | C7: HT23 | D7: 138 | E7: 13.18 | F7: =8/5 -> 1.6
A8: Christiansburg | B8: TANKBATTLE | C8: HT23 | D8: 482.5 | E8: 23.13 | F8: 7.6666667
A9: Collins Hill | B9: Georgia 5A Regionals | C9: HT23 | D9: 261 | E9: 14.77 | F9: =19/5 -> 3.8
A10: Duluth A | B10: Georgia 5A Regionals | C10: HT23 | D10: 293 | E10: 16.46 | F10: =15/5 -> 3
A11: Duluth B | B11: Georgia 5A Regionals | C11: HT23 | D11: 184 | E11: 13.33 | F11: =12/5 -> 2.4
A12: Etowah | B12: Georgia 5A Regionals | C12: HT23 | D12: 402 | E12: 17.87 | F12: =24/5 -> 4.8
A13: Freeman A | B13: TANKBATTLE | C13: HT23 | D13: 186.4 | E13: 14.35 | F13: 1.6363636
A14: Freeman B | B14: TANKBATTLE | C14: HT23 | D14: 57.7 | E14: 9.43 | F14: 0.27272727
A15: Grayson | B15: Georgia 5A Regionals | C15: HT23 | D15: 206 | E15: 12.68 | F15: =10/5 -> 2
A16: House | B16: TANKBATTLE | C16: HT23 | D16: 140 | E16: 10 | F16: 1.2727273
A17: Howard | B17: TANKBATTLE | C17: HT23 | D17: 122.7 | E17: 8.92 | F17: 0.72727273
A18: Lafayette | B18: North Kansas City Varsity Invitational | C18: HT23 | D18: 72.8 | E18: 7 | F18: =4/9 -> 0.44444444
A19: Lee's Summit North | B19: North Kansas City Varsity Invitational | C19: HT23 | D19: 236.1 | E19: 15.24 | F19: 2
A20: Liberty | B20: North Kansas City Varsity Invitational | C20: HT23 | D20: 386.8 | E20: 17.17 | F20: =40/11 -> 3.6363636
A21: Liberty North | B21: North Kansas City Varsity Invitational | C21: HT23 | D21: 166.2 | E21: 12.71 | F21: =14/8 -> 1.75
A22: Lone Jack A | B22: North Kansas City Varsity Invitational | C22: HT23 | D22: 68.8 | E22: 6.76 | F22: =3/8 -> 0.375
A23: Lone Jack B | B23: North Kansas City Varsity Invitational | C23: HT23 | D23: 25 | E23: 4.12 | F23: =3/9 -> 0.33333333
A24: Maggie Walker A | B24: TANKBATTLE | C24: HT23 | D24: 407.7 | E24: 21.8 | F24: 6.6363636
A25: Maggie Walker B | B25: TANKBATTLE | C25: HT23 | D25: 379.1 | E25: 19.47 | F25: 6
A26: Maggie Walker C | B26: TANKBATTLE | C26: HT23 | D26: 229.5 | E26: 16 | F26: 1.4545455
A27: Mountain View | B27: Georgia 5A Regionals | C27: HT23 | D27: 133 | E27: 13.64 | F27: =7/5 -> 1.4
A28: Nandua A | B28: TANKBATTLE | C28: HT23 | D28: 177.3 | E28: 13.95 | F28: 2.2727273
A29: Nandua B | B29: TANKBATTLE | C29: HT23 | D29: 87.7 | E29: 8.8 | F29: 0.81818182
A30: Nandua C | B30: TANKBATTLE | C30: HT23 | D30: 71.4 | E30: 7.07 | F30: 0.72727273
A31: Norcross | B31: Georgia 5A Regionals | C31: HT23 | D31: 560 | E31: 23.75 | F31: =36/5 -> 7.2
A32: North Gwinnett | B32: Georgia 5A Regionals | C32: HT23 | D32: 309 | E32: 15.47 | F32: =21/5 -> 4.2
A33: Oak Grove | B33: North Kansas City Varsity Invitational | C33: HT23 | D33: 163.3 | E33: 10.41 | F33: =8/9 -> 0.88888889
A34: Oak Park | B34: North Kansas City Varsity Invitational | C34: HT23 | D34: 77.5 | E34: 7.84 | F34: 0
A35: Park Hill A | B35: North Kansas City Varsity Invitational | C35: HT23 | D35: 211.9 | E35: 12.43 | F35: =19/9 -> 2.1111111
A36: Park Hill B | B36: North Kansas City Varsity Invitational | C36: HT23 | D36: 132.5 | E36: 11 | F36: =7/8 -> 0.875
A37: Park Hill South | B37: North Kansas City Varsity Invitational | C37: HT23 | D37: 195.6 | E37: 12.69 | F37: 2
A38: Parkview | B38: Georgia 5A Regionals | C38: HT23 | D38: 152 | E38: 8.86 | F38: =8/5 -> 1.6
A39: Quince Orchard | B39: TANKBATTLE | C39: HT23 | D39: 151.4 | E39: 13.96 | F39: 1.5454545
A40: Richard Montgomery | B40: TANKBATTLE | C40: HT23 | D40: 426.4 | E40: 22.98 | F40: 6.5454545
...

Sheet IMSANITY2
A1: Team | B1: Tourney | C1: Set | D1: PPG | E1: PPB | F1: 15PG
A2: Bloomington A | B2: BMI | C2: IMSANITY 2 | D2: 207.8 | E2: 16.34 | F2: n/a
A3: Bloomington B | B3: BMI | C3: IMSANITY 2 | D3: 128.9 | E3: 9.66 | F3: n/a
A4: Carbondale | B4: BMI | C4: IMSANITY 2 | D4: 470.9 | E4: 23.64 | F4: n/a
A5: Champaign Centennial A | B5: BMI | C5: IMSANITY 2 | D5: 297.8 | E5: 20.45 | F5: n/a
A6: Champaign Centennial B | B6: BMI | C6: IMSANITY 2 | D6: 95.7 | E6: 7.18 | F6: n/a
A7: Crete-Monee A | B7: TRIUMVIR | C7: IMSANITY 2 | D7: 35 | E7: 6.32 | F7: n/a
A8: Crete-Monee B | B8: TRIUMVIR | C8: IMSANITY 2 | D8: 51.9 | E8: 6.25 | F8: n/a
A9: Danville A | B9: BMI | C9: IMSANITY 2 | D9: 101.1 | E9: 9.78 | F9: n/a
A10: Danville B | B10: BMI | C10: IMSANITY 2 | D10: 57.1 | E10: 10 | F10: n/a
A11: Dunlap | B11: BMI | C11: IMSANITY 2 | D11: 175.6 | E11: 13.24 | F11: n/a
A12: Fenton | B12: TRIUMVIR | C12: IMSANITY 2 | D12: 217.7 | E12: 17.11 | F12: n/a
A13: Fieldcrest | B13: BMI | C13: IMSANITY 2 | D13: 107.1 | E13: 9.23 | F13: n/a
... A45: WWS B | B45: TRIUMVIR | C45: IMSANITY 2 | D45: 73.5 | E45: 10.61 | F45: n/a

Sheet IS103A
A1: Team | B1: Tourney | C1: Set | D1: PPG | E1: PPB | F1: 15PG
A2: Copley A | B2: South Range Academic Challenge | C2: IS103A | D2: 382.5 | E2: 21.32 | F2: =21/6 -> 3.5
A3: Copley B | B3: South Range Academic Challenge | C3: IS103A | D3: 237.5 | E3: 16.98 | F3: =7/6 -> 1.1666667
A4: East Palestine | B4: South Range Academic Challenge | C4: IS103A | D4: 99.2 | E4: 12.59 | F4: 0
A5: LaBrae | B5: South Range Academic Challenge | C5: IS103A | D5: 145.8 | E5: 16.36 | F5: 1
A6: Lisbon | B6: South Range Academic Challenge | C6: IS103A | D6: 33.3 | E6: 8.18 | F6: =1/6 -> 0.16666667
A7: Lowellville | B7: South Range Academic Challenge | C7: IS103A | D7: 145 | E7: 14.86 | F7: =2/6 -> 0.33333333
A8: Olmsted Falls B | B8: South Range Academic Challenge | C8: IS103A | D8: 278.3 | E8: 17.1 | F8: =7/6 -> 1.1666667
A9: Olmsted Falls C | B9: South Range Academic Challenge | C9: IS103A | D9: 179.2 | E9: 16.46 | F9: 1
A10: Solon A | B10: South Range Academic Challenge | C10: IS103A | D10: 535.8 | E10: 23.55 | F10: =32/6 -> 5.3333333
A11: Solon B | B11: South Range Academic Challenge | C11: IS103A | D11: 235.8 | E11: 18.4 | F11: =12/6 -> 2
A12: Solon C | B12: South Range Academic Challenge | C12: IS103A | D12: 120.8 | E12: 13.12 | F12: =8/6 -> 1.3333333
A13: TCTC | B13: South Range Academic Challenge | C13: IS103A | D13: 54.2 | E13: 11.25 | F13: =1/6 -> 0.16666667
A14: Warren G. Harding | B14: South Range Academic Challenge | C14: IS103A | D14: 535.8 | E14: 25.58 | F14: =40/6 -> 6.6666667
A15: Western Reserve | B15: South Range Academic Challenge | C15: IS103A | D15: 76.7 | E15: 11.9 | F15: =2/6 -> 0.33333333

Sheet IS106A
A1: Team | B1: Tourney | C1: Set | D1: PPG | E1: PPB | F1: 15PG
A2: Alexandria | B2: LSU Tiger Bowl I | C2: IS106A | D2: 65.8 | E2: 13.33 | F2: 0
A3: Burlington A | B3: Pre-Holiday Academic Tournament V | C3: IS106A | D3: 205.6 | E3: 17.97 | F3: 1
A4: Burlington B | B4: Pre-Holiday Academic Tournament V | C4: IS106A | D4: 118.8 | E4: 11.33 | F4: =3/8 -> 0.375
A5: C.E. Byrd | B5: LSU Tiger Bowl I | C5: IS106A | D5: 358.6 | E5: 20.86 | F5: =9/7 -> 1.2857143
A6: Catholic of Pointe Coupee A | B6: LSU Tiger Bowl I | C6: IS106A | D6: 132.9 | E6: 13.75 | F6: =2/7 -> 0.28571429
A7: Catholic of Pointe Coupee B | B7: LSU Tiger Bowl I | C7: IS106A | D7: 58.3 | E7: 11.11 | F7: 0
A8: Champlain Valley A | B8: Pre-Holiday Academic Tournament V | C8: IS106A | D8: 211.2 | E8: 19.15 | F8: =13/8 -> 1.625
A9: Champlain Valley B | B9: Pre-Holiday Academic Tournament V | C9: IS106A | D9: 114.4 | E9: 11.9 | F9: =3/8 -> 0.375
A10: Colebrook A | B10: Pre-Holiday Academic Tournament V | C10: IS106A | D10: 85.6 | E10: 10.29 | F10: =1/8 -> 0.125
A11: Colebrook B | B11: Pre-Holiday Academic Tournament V | C11: IS106A | D11: 46.2 | E11: 5.77 | F11: 0
A12: Colton-Pierrepont A | B12: Pre-Holiday Academic Tournament V | C12: IS106A | D12: 138.1 | E12: 13.06 | F12: =1/8 -> 0.125
A13: Colton-Pierrepont B | B13: Pre-Holiday Academic Tournament V | C13: IS106A | D13: 61.9 | E13: 8.04 | F13: =2/8 -> 0.25
A14: Colton-Pierrepont C | B14: Pre-Holiday Academic Tournament V | C14: IS106A | D14: 33.1 | E14: 9.64 | F14: 0
A15: Dutchtown A | B15: LSU Tiger Bowl I | C15: IS106A | D15: 252.9 | E15: 18.55 | F15: =6/7 -> 0.85714286
A16: Dutchtown B | B16: LSU Tiger Bowl I | C16: IS106A | D16: 146.7 | E16: 19.03 | F16: =3/6 -> 0.5
A17: E.D. White Catholic | B17: LSU Tiger Bowl I | C17: IS106A | D17: 206.7 | E17: 18.44 | F17: 0.5
A18: Emma Willard A | B18: Pre-Holiday Academic Tournament V | C18: IS106A | D18: 121.9 | E18: 12.16 | F18: =2/8 -> 0.25
A19: Essex A | B19: Pre-Holiday Academic Tournament V | C19: IS106A | D19: 206.2 | E19: 18.28 | F19: =9/8 -> 1.125
A20: Essex B (Heavy Medals) | B20: Pre-Holiday Academic Tournament V | C20: IS106A | D20: 80.6 | E20: 11.45 | F20: =3/8 -> 0.375
A21: Essex C (Fab 4.5) | B21: Pre-Holiday Academic Tournament V | C21: IS106A | D21: 128.1 | E21: 13.22 | F21: 0.5
A22: Essex D (Rah Rah Rasputins) | B22: Pre-Holiday Academic Tournament V | C22: IS106A | D22: 115 | E22: 12.44 | F22: =2/8 -> 0.25
A23: Fair Haven A | B23: Pre-Holiday Academic Tournament V | C23: IS106A | D23: 96.2 | E23: 10.95 | F23: =2/8 -> 0.25
A24: Fair Haven B | B24: Pre-Holiday Academic Tournament V | C24: IS106A | D24: 38.1 | E24: 5 | F24: =1/8 -> 0.125
A25: Fair Haven C | B25: Pre-Holiday Academic Tournament V | C25: IS106A | D25: 75 | E25: 7.94 | F25: =1/8 -> 0.125
A26: Gorham A | B26: Pre-Holiday Academic Tournament V | C26: IS106A | D26: 139 | E26: 14.64 | F26: =6/5 -> 1.2
A27: Grand Coteau Sacred Heart | B27: LSU Tiger Bowl I | C27: IS106A | D27: 122.9 | E27: 17.1 | F27: 1
A28: Hanover A | B28: Pre-Holiday Academic Tournament V | C28: IS106A | D28: 435 | E28: 24.53 | F28: =44/8 -> 5.5
A29: Hanover B | B29: Pre-Holiday Academic Tournament V | C29: IS106A | D29: 106.4 | E29: 10.14 | F29: =6/7 -> 0.85714286
A30: Lafayette A | B30: LSU Tiger Bowl I | C30: IS106A | D30: 373.6 | E30: 20.77 | F30: 2
A31: Lafayette B | B31: LSU Tiger Bowl I | C31: IS106A | D31: 200.7 | E31: 16.11 | F31: =5/7 -> 0.71428571
A32: Lusher | B32: LSU Tiger Bowl I | C32: IS106A | D32: 226.4 | E32: 17.88 | F32: =4/7 -> 0.57142857
A33: Middlebury A | B33: Pre-Holiday Academic Tournament V | C33: IS106A | D33: 326.2 | E33: 21.62 | F33: =28/8 -> 3.5
A34: Middlebury B | B34: Pre-Holiday Academic Tournament V | C34: IS106A | D34: 97.5 | E34: 11.76 | F34: =5/8 -> 0.625
A35: Montpelier A | B35: Pre-Holiday Academic Tournament V | C35: IS106A | D35: 90.6 | E35: 13.44 | F35: =2/8 -> 0.25
A36: Montpelier B | B36: Pre-Holiday Academic Tournament V | C36: IS106A | D36: 61.9 | E36: 8.52 | F36: =1/8 -> 0.125
A37: Montpelier C | B37: Pre-Holiday Academic Tournament V | C37: IS106A | D37: 77.5 | E37: 10.16 | F37: =2/8 -> 0.25
A38: Mt. Abraham A | B38: Pre-Holiday Academic Tournament V | C38: IS106A | D38: 243.1 | E38: 19.54 | F38: 1
A39: Mt. Abraham B | B39: Pre-Holiday Academic Tournament V | C39: IS106A | D39: 103.8 | E39: 8.67 | F39: 0
A40: Mt. Abraham C | B40: Pre-Holiday Academic Tournament V | C40: IS106A | D40: 91.9 | E40: 8.59 | F40: =2/8 -> 0.25
...

Sheet IS107
A1: Team | B1: Tourney | C1: Set | D1: PPG | E1: PPB | F1: 15PG
A2: Amherst Central A | B2: Bull Bowl | C2: IS107 | D2: 145.5 | E2: 10 | F2: =8/11 -> 0.72727273
A3: Amherst Central B | B3: Bull Bowl | C3: IS107 | D3: 117 | E3: 8.44 | F3: 1
A4: Arcadia A | B4: UCLA TWAIN | C4: IS107 | D4: 403.5 | E4: 20.95 | F4: 4.6
A5: Arcadia B | B5: UCLA TWAIN | C5: IS107 | D5: 385 | E5: 19.37 | F5: 5.2
A6: Arcadia C | B6: UCLA TWAIN | C6: IS107 | D6: 177.5 | E6: 13.75 | F6: 1.6
A7: Arcadia D | B7: UCLA TWAIN | C7: IS107 | D7: 223.5 | E7: 15.41 | F7: 3.3
A8: Arcadia E | B8: UCLA TWAIN | C8: IS107 | D8: 127.5 | E8: 11.1 | F8: 1.3
A9: Arcadia F | B9: UCLA TWAIN | C9: IS107 | D9: 175.5 | E9: 14.71 | F9: 2.3
A10: Armstrong A | B10: GINVIT | C10: IS107 | D10: 277 | E10: 15.05 | F10: 3
A11: Armstrong B | B11: GINVIT | C11: IS107 | D11: 149.5 | E11: 10.58 | F11: 1.2
A12: Armstrong C | B12: GINVIT | C12: IS107 | D12: 123.5 | E12: 9.53 | F12: 0.6
A13: Armstrong D | B13: GINVIT | C13: IS107 | D13: 98.9 | E13: 6.67 | F13: 0.7
A14: Armstrong E | B14: GINVIT | C14: IS107 | D14: 33.9 | E14: 5 | F14: 0.2
A15: Bellaire A | B15: Texas Kickoff Classic | C15: IS107 | D15: 325 | E15: 19.48 | F15: =32/8 -> 4
A16: Bellaire B | B16: Texas Kickoff Classic | C16: IS107 | D16: 308.8 | E16: 16.32 | F16: =26/8 -> 3.25
A17: Bergen A | B17: PHSAT | C17: IS107 | D17: 315 | E17: 16.11 | F17: 2
A18: Bergen B | B18: PHSAT | C18: IS107 | D18: 160 | E18: 13.57 | F18: =6/8 -> 0.75
A19: Berryhill | B19: Tulsa Fall Challenge | C19: IS107 | D19: 76.7 | E19: 10 | F19: 0
A20: Biotech A | B20: PHSAT | C20: IS107 | D20: 131.2 | E20: 12.83 | F20: =6/8 -> 0.75
A21: Biotech B | B21: PHSAT | C21: IS107 | D21: 36.2 | E21: 8.82 | F21: 0
A22: Biotech C | B22: PHSAT | C22: IS107 | D22: 21.9 | E22: 3.33 | F22: 0.5
A23: Bishop Kelly A | B23: Boise State Treasure Valley Tournament III | C23: IS107 | D23: 170.6 | E23: 13.73 | F23: =11/8 -> 1.375
A24: Bishop Kelly B | B24: Boise State Treasure Valley Tournament III | C24: IS107 | D24: 27.5 | E24: 3.53 | F24: =2/8 -> 0.25
A25: Blair | B25: Maryland Fall HS Tournament | C25: IS107 | D25: 408.8 | E25: 22 | F25: =79/12 -> 6.5833333
A26: Blair A | B26: PHSAT | C26: IS107 | D26: 131.2 | E26: 8.07 | F26: =11/8 -> 1.375
A27: Blair B | B27: PHSAT | C27: IS107 | D27: 75.6 | E27: 7.84 | F27: 0.5
A28: Blair C | B28: PHSAT | C28: IS107 | D28: 56.2 | E28: 5.76 | F28: =2/8 -> 0.25
A29: Brashear | B29: SAGACITY VII | C29: IS107 | D29: 104.7 | E29: 8.39 | F29: =6/11 -> 0.54545455
A30: Broughton | B30: Quaker Bowl | C30: IS107 | D30: 37 | E30: 8 | F30: =4/5 -> 0.8
A31: Caesar Rodney | B31: Maryland Fall HS Tournament | C31: IS107 | D31: 116 | E31: 10.89 | F31: =8/10 -> 0.8
A32: Camp Hill | B32: SAGACITY VII | C32: IS107 | D32: 326.1 | E32: 15.79 | F32: =31/11 -> 2.8181818
A33: Carlisle | B33: Quaker Bowl | C33: IS107 | D33: 126.2 | E33: 9.61 | F33: 1
A34: Carrboro A | B34: Quaker Bowl | C34: IS107 | D34: 178.5 | E34: 11.98 | F34: 1.6
A35: Centennial A | B35: Maryland Fall HS Tournament | C35: IS107 | D35: 186.1 | E35: 13.77 | F35: =20/9 -> 2.2222222
A36: Centennial B | B36: Maryland Fall HS Tournament | C36: IS107 | D36: 146.1 | E36: 12.13 | F36: =10/9 -> 1.1111111
A37: Centennial C | B37: Maryland Fall HS Tournament | C37: IS107 | D37: 90 | E37: 8 | F37: =9/9 -> 1
A38: Centennial D | B38: Maryland Fall HS Tournament | C38: IS107 | D38: 65.6 | E38: 8.28 | F38: =4/9 -> 0.44444444
A39: Central | B39: GINVIT | C39: IS107 | D39: 438.2 | E39: 21.05 | F39: =64/11 -> 5.8181818
A40: Chanhassen Blue | B40: GINVIT | C40: IS107 | D40: 150 | E40: 13.65 | F40: 0.7
...

Sheet IS108A
A1: Team | B1: Tourney | C1: Set | D1: PPG | E1: PPB | F1: 15PG
A2: Altamont | B2: William Rufus King Memorial | C2: IS108A | D2: 264.5 | E2: 18.02 | F2: 3
A3: Athens | B3: SOCIAL | C3: IS108A | D3: 170.3 | E3: 12.59 | F3: =6/8 -> 0.75
A4: Beachwood B | B4: BRAVE Falcon | C4: IS108A | D4: 471.4 | E4: 24.81 | F4: =52/7 -> 7.4285714
A5: Belleville | B5: Wisconsin Fall | C5: IS108A | D5: 240 | E5: 15.31 | F5: 2.1
A6: Blaine A | B6: SOCIAL | C6: IS108A | D6: 74.6 | E6: 7.14 | F6: =2/7 -> 0.28571429
A7: Blue Ridge | B7: Crusader Cup | C7: IS108A | D7: 180 | E7: 15.71 | F7: n/a
A8: Branford | B8: Rickards Brain Bowl | C8: IS108A | D8: 150 | E8: 12.56 | F8: =8/6 -> 1.3333333
A9: Cashion | B9: L.L. Lewis Cup | C9: IS108A | D9: 75.8 | E9: 10.22 | F9: =1/7 -> 0.14285714
A10: Chanhassen A | B10: SOCIAL | C10: IS108A | D10: 174.6 | E10: 13.8 | F10: =3/7 -> 0.42857143
A11: Chanhassen B | B11: SOCIAL | C11: IS108A | D11: 184.7 | E11: 15.31 | F11: =12/8 -> 1.5
A12: Chapman A | B12: Crusader Cup | C12: IS108A | D12: 138.6 | E12: 18.53 | F12: n/a
A13: Charles F. Brush A | B13: BRAVE Falcon | C13: IS108A | D13: 220.1 | E13: 15.4 | F13: =20/6 -> 3.3333333
A14: Charles F. Brush B | B14: BRAVE Falcon | C14: IS108A | D14: 154.2 | E14: 14.13 | F14: =8/6 -> 1.3333333
A15: Chaska A | B15: SOCIAL | C15: IS108A | D15: 373.8 | E15: 21.22 | F15: =53/11 -> 4.8181818
A16: Chaska B | B16: SOCIAL | C16: IS108A | D16: 242.1 | E16: 18.19 | F16: =19/8 -> 2.375
A17: Chaska C | B17: SOCIAL | C17: IS108A | D17: 148.4 | E17: 13.02 | F17: =12/8 -> 1.5
A18: Chaska D | B18: SOCIAL | C18: IS108A | D18: 160.5 | E18: 15.32 | F18: =3/8 -> 0.375
A19: Chaska E | B19: SOCIAL | C19: IS108A | D19: 123 | E19: 13.49 | F19: =12/7 -> 1.7142857
A20: Columbia A | B20: William Rufus King Memorial | C20: IS108A | D20: 118.5 | E20: 10.69 | F20: 0.4
A21: D. W. Daniel | B21: Crusader Cup | C21: IS108A | D21: 257.1 | E21: 19.51 | F21: n/a
A22: Detroit Catholic Central A | B22: BRAVE Falcon | C22: IS108A | D22: 415.5 | E22: 22.65 | F22: =42/7 -> 6
A23: Detroit Catholic Central B | B23: BRAVE Falcon | C23: IS108A | D23: 301.4 | E23: 18.11 | F23: =25/6 -> 4.1666667
A24: Divine Child A | B24: BRAVE Falcon | C24: IS108A | D24: 121.7 | E24: 14.83 | F24: =4/5 -> 0.8
A25: Divine Child B | B25: BRAVE Falcon | C25: IS108A | D25: 96.5 | E25: 11.56 | F25: 1
A26: Dorman C | B26: Crusader Cup | C26: IS108A | D26: 487.1 | E26: 23.11 | F26: n/a
A27: Dorman C | B27: Crusader Cup | C27: IS108A | D27: 244.3 | E27: 15.15 | F27: n/a
A28: Dorman D | B28: Crusader Cup | C28: IS108A | D28: 298.6 | E28: 20.74 | F28: n/a
A29: Dorman D | B29: Crusader Cup | C29: IS108A | D29: 168.6 | E29: 16.82 | F29: n/a
A30: Drummond | B30: L.L. Lewis Cup | C30: IS108A | D30: 259.2 | E30: 13.85 | F30: =15/8 -> 1.875
A31: Eastside A | B31: Rickards Brain Bowl | C31: IS108A | D31: 309.4 | E31: 20.05 | F31: =24/9 -> 2.6666667
