Workbook

Sheet Pages 1-3
A1: Food Safety Programs and Auditing Protocol for the Tomato Supply Chain
A2: Greenhouse - USDA Checklist
A5: AUDITEE INFORMATION
A6: Company Name:
A7: Street Address: | E7: City, State, Zip:
A8: Are multiple sites covered by this audit? | D8: Yes | F8: No | H8: How Many?
A9: Audited Operation Address/GPS:
A11: Company Contact: | E11: Company Contact Title:
A12: Phone Number: | F12: Fax Number:
A13: E-Mail Address:
A14: AUDIT INFORMATION
A15: Date of Audit: | D15: Start Time: | G15: End Time:
A16: Description of Operation:
A17: Does this Operation Field Pack Tomatoes? | E17: Yes | G17: No
A18: Harvest Company Name (If Applicable):
A19: Other Contractors:
A20: Commodities Covered by Audit:
A21: Total Acres Covered by Audit:
A22: Audit Performed By: United States Department of Agriculture, Agricultural Marketing Service
A23: Fruit and Vegetable Program, Specialty Crops Inspection Division
A24: Field Office:
A25: Auditor(s) Name(s): (list lead auditor first)
A27: Auditor(s) Signature(s): (list lead auditor first)
A29: Persons Interviewed:
A31: Auditee Representative Name:
A34: Auditee representative informed of non-conformances during closing meeting? (Yes or No)
A36: Internal Use Only
A37: Audit Received: | D37: Certificate Mailed: | F37: Posted to Website:
A38: Reviewing Official Name:
A39: Reviewing Official Signature:
A40: Date Approved:
A43: AUDITOR COMPLETION INSTRUCTIONS
A45: All questions on the Food Safety Programs and Auditing Protocol for the Fresh Tomato Supply Chain, Greenhouse - USDA Checklist shall be assessed according to the verification instructions outlined in the Commodity Specific Food Safety Guidelines for the Fresh Tomato Supply Chain 2nd Edition - July 2008 and the Food Safety Programs and Auditing Protocol for the Fresh Tomato Supply Chain, 2011 - Greenhouse standard. Auditors shall have a copy of these verification instructions with them when performing audits to verify questions are assessed appropriately. All questions shall be assessed using one of the following:
B47: Compliant (C) - The operation meets the requirements of the Food Safety Programs and Auditing Protocol for the Fresh Tomato Supply Chain, 2011 - Greenhouse standard.
B48: Corrective Action Needed (CAN) - The operation does not meet the requirement(s) of the verification instructions, however the non-conformance is not considered to be an immediate food safety risk.
B49: Immediate Action Required (IAR) - The operation does not meet the requirement(s) of the verification instructions and the non-conformance is considered an imminent food safety risk. An imminent food safety risk is present when produce is grown, processed, packed or held under conditions that promote or cause the produce to become contaminated. Observation of employee practices (personal or hygienic) that jeopardize or may jeopardize the safety of the produce are considered an "IAR". The presence or evidence of rodents, an excessive amount of insects or pests are also considered an "IAR".
B50: Not Applicable (N/A) - The question is not applicable to the operation.
A52: Auditor Comments: The auditor shall document the findings associated with any question answered "CAN" or "IAR" in the auditor comment section of the checklist. Auditors may also document observations associated with any question on the checklist whether or not the question is a non-conformity if the explanation clarifies why a question was answered compliant. The auditor shall write a comment for each question answered "N/A" addressing why the question was answered "N/A".
A54: Tallying the Audit: Once the auditor finishes the audit, the score sheet shall be filled out by recording the number of C, CAN, IAR, and NA's for each section of the audit. The question number of any question answered as CAN or IAR for each section shall be noted in the last column of the score sheet.
A56: USDA ACCEPTANCE CRITERIA
...

Sheet Scoresheet
A1: Audit Summary | C1: Name of Auditee: | F1: ='Pages 1-3'!B6 -> 0
C2: Date of audit: | F2: ='Pages 1-3'!B15 -> 0
A3: Section | B3: Questions | C3: Total # in Section | D3: # of C | E3: #of CAN | F3: # of IAR | G3: # of NA | H3: Question # of any CAN or IAR
A4: 1 | B4: Management Responsibility | C4: 6 | D4: =COUNTIF(Checklist!C5:C10,"✓") -> 0 | E4: =COUNTIF(Checklist!D5:D10,"✓") -> 0 | F4: =COUNTIF(Checklist!E5:E10,"✓") -> 0 | G4: =COUNTIF(Checklist!F5:F10,"✓") -> 0
A5: 2 | B5: Farm History and Assessment | C5: 5 | D5: =COUNTIF(Checklist!C13:C17,"✓") -> 0 | E5: =COUNTIF(Checklist!D13:D17,"✓") -> 0 | F5: =COUNTIF(Checklist!E13:E17,"✓") -> 0 | G5: =COUNTIF(Checklist!F13:F17,"✓") -> 0
A6: 3 | B6: Greenhouse | C6: 3 | D6: =COUNTIF(Checklist!C20:C22,"✓") -> 0 | E6: =COUNTIF(Checklist!D20:D22,"✓") -> 0 | F6: =COUNTIF(Checklist!E20:E22,"✓") -> 0 | G6: =COUNTIF(Checklist!F20:F22,"✓") -> 0
A7: 4 | B7: Soil and Amendments | C7: 3 | D7: =COUNTIF(Checklist!C25:C27,"✓") -> 0 | E7: =COUNTIF(Checklist!D25:D27,"✓") -> 0 | F7: =COUNTIF(Checklist!E25:E27,"✓") -> 0 | G7: =COUNTIF(Checklist!F25:F27,"✓") -> 0
A8: 5 | B8: PreHarvest Agricultural Water | C8: 7 | D8: =COUNTIF(Checklist!C30:C36,"✓") -> 0 | E8: =COUNTIF(Checklist!D30:D36,"✓") -> 0 | F8: =COUNTIF(Checklist!E30:E36,"✓") -> 0 | G8: =COUNTIF(Checklist!F30:F36,"✓") -> 0
A9: 6 | B9: Pest Control and Pesticide Usage | C9: 10 | D9: =COUNTIF(Checklist!C40:C50,"✓") -> 0 | E9: =COUNTIF(Checklist!D40:D50,"✓") -> 0 | F9: =COUNTIF(Checklist!E40:E50,"✓") -> 0 | G9: =COUNTIF(Checklist!F40:F50,"✓") -> 0
A10: 7 | B10: Tomato or Equipment Sanitizing Agents Used During Harvest | C10: 3 | D10: =COUNTIF(Checklist!C53:C55,"✓") -> 0 | E10: =COUNTIF(Checklist!D53:D55,"✓") -> 0 | F10: =COUNTIF(Checklist!E53:E55,"✓") -> 0 | G10: =COUNTIF(Checklist!F53:F55,"✓") -> 0
A11: 8 | B11: Equipment, Containers and Packaging Materials | C11: 6 | D11: =COUNTIF(Checklist!C58:C63,"✓") -> 0 | E11: =COUNTIF(Checklist!D58:D63,"✓") -> 0 | F11: =COUNTIF(Checklist!E58:E63,"✓") -> 0 | G11: =COUNTIF(Checklist!F58:F63,"✓") -> 0
A12: 9 | B12: Cleaning and Washing Procedures | C12: 13 | D12: =COUNTIF(Checklist!C67:C80,"✓") -> 0 | E12: =COUNTIF(Checklist!D67:D80,"✓") -> 0 | F12: =COUNTIF(Checklist!E67:E80,"✓") -> 0 | G12: =COUNTIF(Checklist!F67:F80,"✓") -> 0
A13: 10 | B13: Transportation | C13: 2 | D13: =COUNTIF(Checklist!C83:C84,"✓") -> 0 | E13: =COUNTIF(Checklist!D83:D84,"✓") -> 0 | F13: =COUNTIF(Checklist!E83:E84,"✓") -> 0 | G13: =COUNTIF(Checklist!F83:F84,"✓") -> 0
A14: 11 | B14: Employee Hygiene Policies and Employee Training | C14: 24 | D14: =COUNTIF(Checklist!C88:C113,"✓") -> 0 | E14: =COUNTIF(Checklist!D88:D113,"✓") -> 0 | F14: =COUNTIF(Checklist!E88:E113,"✓") -> 0 | G14: =COUNTIF(Checklist!F88:F113,"✓") -> 0
A15: 12 | B15: Education and Training | C15: 4 | D15: =COUNTIF(Checklist!C116:C119,"✓") -> 0 | E15: =COUNTIF(Checklist!D116:D119,"✓") -> 0 | F15: =COUNTIF(Checklist!E116:E119,"✓") -> 0 | G15: =COUNTIF(Checklist!F116:F119,"✓") -> 0
A16: 13 | B16: Record Keeping and Traceability | C16: 7 | D16: =COUNTIF(Checklist!C123:C131,"✓") -> 0 | E16: =COUNTIF(Checklist!D123:D131,"✓") -> 0 | F16: =COUNTIF(Checklist!E123:E131,"✓") -> 0 | G16: =COUNTIF(Checklist!F123:F131,"✓") -> 0

Sheet Checklist
A1: Name of Auditee: | C1: ='Pages 1-3'!B6 -> 0
A2: Date of Audit: | C2: ='Pages 1-3'!B15 -> 0
A3: Q # | B3: Requirement | C3: C | D3: CAN | E3: IAR | F3: NA | G3: Auditor Comments
A4: 1 | B4: Management Responsibility
A5: 1.1 | B5: Operation has designated an individual responsible for food safety.
A6: 1.2 | B6: Responsible individual has evidence of training in food safety relevant to tomatoes.
A7: 1.3 | B7: Operation has current copies of the Commodity Specific Food Safety Guidelines for the Fresh Tomato Supply Chain, Food Safety Programs and Auditing Protocol for the Fresh Tomato Supply Chain and additional food safety documents as required by state and/or federal regulation.
A8: 1.4 | B8: Operation has procedures for conducting self-audits and conducts self-audits to verify compliance with established internal policies and procedures.
A9: 1.5 | B9: Operation has a written procedure and timelines for implementing and documenting corrective actions.
A10: 1.6 | B10: Operation has a “zero tolerance” policy for controllable practices and conditions that result in immediate food safety risks.
A12: 2 | B12: Farm History and Assessment
A13: 2.1 | B13: An environmental assessment has been conducted, including potential hazards on the property, past property use and adjacent land.
A14: 2.2 | B14: The environmental assessment shall consider domestic animal operations.
A15: 2.3 | B15: Grounds are reasonably free of litter, debris and standing water.
A16: 2.4 | B16: System for removing waste materials from product handling area works efficiently.
... A38: 6 | B38: Produce Containers and Packaging Materials
B39: A. Pest Control in Facility
A40: 6.1 | B40: Operation has a written pest control program, performed by a trained pest control operator. Pest control operators are licensed where required by prevailing regulation or law.
A41: 6.2 | B41: There is a clear area surrounding the facility to deter pest infestation.
A42: 6.3 | B42: There is no evidence of significant pest populations (birds, rodents, insects) reasonably likely to contaminate tomatoes.
A43: 6.4 | B43: There are no bait stations containing toxic baits inside the facility.
A44: 6.5 | B44: Traps do not contain toxic bait and are placed at the interval and location recommended by the pest control operator. Traps must be labeled with a number or other identifier and their locations are documented on a map.
A45: 6.6 | B45: Bug zappers and insect attractant devices, if used, are not placed in a location where product or food handling equipment or food packaging materials may become adulterated.
A46: 6.7 | B46: Operation has a written policy prohibiting domestic animals in the greenhouse.
B47: B. Pesticide Usage
A48: 6.8 | B48: Pesticide chemicals and their use must comply with all requirements of national (e.g., EPA) registration and any federal, state or local regulations.
A49: 6.9 | B49: Equipment used to apply pesticides shall be maintained and calibrated at a frequency sufficient to assure accuracy of delivery.
A50: 6.1 | B50: Water used to mix pesticides meets EPA microbial standards for drinking water; i.e., 40 CFR Part 141.63.
A52: 7 | B52: Tomato or Equipment Sanitizing Agents Used During Harvest
A53: 7.1 | B53: All compounds used to clean or sanitize food contact containers, tools, utensils, equipment or other food contact surfaces are approved for that use by the US EPA, FDA or other prevailing agency. Actual use conforms to label directions.
A54: 7.2 | B54: Chemicals used on product that are not registered pesticides may be permitted for food contact use if allowed under regulations of the FDA or prevailing agency.
A55: 7.3 | B55: All chemicals, cleaning compounds and solvents are stored in a secure and locked location.
A57: 8 | B57: Equipment, Containers and Packaging Materials
A58: 8.1 | B58: Harvest and other food contact implements, buckets and totes are clean and sanitized as necessary according to SOP.
A59: 8.2 | B59: Reusable containers and food contact equipment and utensils shall be constructed of impervious materials that can be easily cleaned and sanitized.
A60: 8.3 | B60: All containers shall be marked for their intended use (finished produce containers, trash containers, etc.).
A61: 8.4 | B61: Operation has a written procedure for inspecting incoming packaging material.
... A65: 9 | B65: Cleaning and Washing Procedures
B66: A. Cleaning Materials Including Cloths
A67: 9.1 | B67: Operation shall have a policy that cloths, towels, or other cleaning materials shall not be used to wipe tomatoes.
...

Sheet CAR Duplication Instructions
A1: DUPLICATION OF CORRECTIVE ACTION TAB INSTRUCTIONS
A3: Any item on any checklist with a checkmark beside the Corrective Action Needed (CAN) box or the Immediate Action Required (IAR) box must be documented using a Corrective Action Report. A separate form is required for each item with either of these entities. If there is more than one form needed, follow the instructions below to duplicate the Corrective Action Report Tab:
B4: 1. Right-click the "Corrective Action Report" Tab at the bottom of Excel.
B6: 2. Click "Move or Copy.
B8: 3. Under the box titled "Before Sheet," select "(move to end)"
B10: 4. Place a check in the box beside "Create a Copy"
B12: 5. Click "Ok"

Sheet Corrective Action Report 
A1: Food Safety Programs and Auditing Protocol
A2: for the Fresh Tomato Supply Chain
A3: Greenhouse Standard
A5: USDA, AMS, Fruit and Vegetable Program | F5: Report #:
A6: Good Agricultural Practice & Good Handling Practices | H6: of
A7: CORRECTIVE ACTION REPORT
A8: Company Name/Farm: | C8: ='Pages 1-3'!B6 -> 0 | F8: Date: | G8: ='Pages 1-3'!B15 -> 0
A10: Lead Auditor:
A12: Crop(s):
A14: Description of Non Conformity:
A24: Notified company staff at time of finding non-conformity: (Yes or No)
A25: Checklist question number and/or section of auditee food safety plan associated with non-conformity:
A26: Corrective Action Proposed and Time Frame for Implementation: (Attach separate sheet if necessary)
A39: Company Representative Signature:
A41: Signature affirms statements concerning Non-Conformity, Corrective Action, and Implementation are correct.
A42: Auditor signature for acceptance of proposed corrective action and timetable for implementation:
A45: Top portion for AUDITOR USE ONLY; bottom portion for Company and Auditor use.
