Workbook

Sheet Descriptions
A1: 12-13 LAR Strategy Descriptions for Board Summary
A2: updated: | B2: 40358
A4: Strat # | B4: Strat Name | C4: Description
A5: A.1.1. | B5: Close Gaps in Participation and Success | C5: This strategy supports efforts to meet Closing the Gaps by 2015’s participation and success goals. Activities include implementing the P-16 College Readiness and Success Strategic Action Plan; collaborating with public schools and community-based organizations to provide information to historically underrepresented populations to prepare them academically and financially for college; ensuring the success of student recruitment and retention by Texas colleges and universities; supporting high schools with low college-going rates; implementing an outreach plan for students in foster care; promoting information on the tuition and fee exemption program; collaborating with state leadership in public education and workforce, and other stakeholders to ensure a seamless, and high-quality educational system; and supporting non-loan financial aid programs (including grants, scholarships, work-study, and instuition exemptions administered by the Coordinating Board to help financially needed students), loan forgiveness programs and loan repayment programs.
A6: A.1.2. | B6: Close Gaps by Administering Loan Programs | C6: This strategy includes funding for administration of the Hinson-Hazlewood Loan Program. No General Revenue is used to support the loan program. All of these funds are generated by the program. In FY09, 8,812 students received $87,389,984 in loans for an average loan amount of $9,917. It is estimated that 9,500 students will receive $95,000,000 in loans in FY10 for an average amount of $10,000.
A7: A.1.3. | B7: Close Gaps by Administering College Readiness Initiatives | C7: This strategy includes funding for the administration of all college readiness programs and initiatives that support the goals and objectives of the P-16 College Readiness and Success Strategic Action Plan. The Plan is designed to increase student success and decrease the number of students enrolling in developmental course work in institutions of higher education. The strategy includes staff resources for college readiness activities, including Adult Basic Education and Developmental Education activities, in the Divisions of P-16 Initiatives, Academic Affairs and Research, and Planning and Accountability.
A8: A.2.1. | B8: Close Gaps in Excellence | C8: This strategy includes funding for the academic program responsibilities of the Academic Affairs and Research Division, including funding for excellence initiatives. The strategy includes funding for the personnel whose primary responsibility is institutional program review, administration of the health-related trusteed funds (including the residency programs and the grant programs supported by the tobacco settlement funding included in Goal G), and the Coordinating Board efforts to close the gaps in excellence.
A9: A.2.2. | B9: Close Gaps in Research | C9: This strategy provides all of the funding for the administration and staff supervision of the research programs by the Academic Affairs and Research Division. The strategy includes funding for personnel whose primary responsibility is administration of the Norman Hackerman Advanced Research Program, Summer Engineering Program, Engineering Recruitment Program, Research Assessment Program, Research Development Fund, and the agency’s related efforts to close the gaps in research.
A10: A.3.1. | B10: Close Gaps by Providing Planning and Information | C10: This strategy provides all of the funding for the Planning and Accountability Division, including the Education Data Center and Information Access Initiative, and funding for planning initiatives. The strategy includes funding for the personnel whose responsibilities include planning for higher education, collection of the state’s higher education data, analysis of higher education issues, the state’s higher education accountability system, planning for the state’s higher education facilities, and higher education finance analysis. This strategy includes funding for the Higher Education Policy Institute (HEPI). The Coordinating Board received a grant from the Houston Endowment, Inc. to conduct research and analysis of the critical higher education issues that challenge Texas. HEPI has established research agendas in the four areas as approved by the Houston Endowment: student outcomes, developmental education, Hispanic student success, and cost efficiency. The project has provided the Coordinating Board critical input that has shaped internal policy as well as its recommendations to the legislature, thereby fulfilling the intent of the original grant proposal. In preparation for the 2011 legislative session, HEPI is developing recommendations to further influence policy.
A11: B.1.1. | B11: License Plate Scholarships Program | C11: The Coordinating Board manages accounts for a number of specialty license plate programs designed to generate funding for scholarships and other education-related programs. These include (citation provided for authorizing statute in the Texas Transportation Code): • Texas Collegiate License Plate Scholarship (§ 504.615); • Houston Livestock Show and Rodeo License Plate Scholarship (§ 504.613); • Girl Scout License Plate Programs (§ 504.622); • “College for All Texans” Campaign License Plate Program (§ 504.657); • Boy Scout License Plate Scholarship (§ 504.6545); and • Cotton Boll License Plate Scholarship (§ 504.636). In a typical year, approximately 40 students will receive awards totaling $50,000 through the Collegiate License Plate program. The other specialty plates represent approximately 10 awards per year for $13,500.
A12: B.1.2. | B12: Fifth-Year Accounting Students Program | C12: The Fifth-Year Accounting Student Scholarship Program provides need-based scholarships to students who have completed 120 hours of college work and sign a statement of intent to take the Texas CPA examination. Eligible students must be enrolled on at least a half-time basis. This program was created in 1991 when the requirements to sit for the Texas CPA exam were changed from 120 to 150 hours of required course work. Because of the added financial burden of an additional year of college work, this program was created to provide scholarships to students with financial need who have completed at least 120 hours of college work, including 15 hours of Accounting. Funding in this program is provided through set-asides from state fees paid by Certified Public Accountants. HB 2440, 81st Texas legislature, shifted all scholarship activities to the Texas State Board of Public Accountancy (TSBPA) by the end of the fall 2009 term. As new fees are collected, they will be retained and accumulated by TSBPA. In accordance with these provisions, new funds for the next biennium will not be transferred to THECB.
A13: B.1.3. | B13: Early High School Graduation Scholarship Program | C13: For students graduating prior to September 1, 2005, this program provides funds for reimbursing institutions for tuition exemptions up to $1,000 to students who completed grades 9-12 in no more than 36 continuous months. For students graduating after September 1, 2005, the program provides tuition and fee exemptions up to $2,000 to students who completed grades 9-12 with the Recommended or higher High School Program in no more than 36 months. Students who graduate within 41 or 46 months may qualify (with a lesser award) if the student also graduates with a specified number of college credits. Students at independent colleges may receive awards if their colleges provide matching awards. The funding is provided from the Foundation School Fund through an inter-agency contract with the Texas Education Agency. In FY 2009, a total of 6,783 students received a total of $6,562,746 (average award of $968). Thus far in FY 2010, a total of 6,268 students have received a $5,968,540 (average award of $952).
A14: B.1.4. | B14: TANF Scholarship Program | C14: This program provides a one-year exemption from the payment of tuition and fees to students who were dependent children for whom their families received federal Temporary Assistance to Need Families (TANF) for at least six months during their senior year in high school. The funding is provided from the Foundation School Fund through an inter-agency contract with the Texas Education Agency. In FY 2009, 24 students received a total of $80,513 (average award of $3,355). Thus far in FY 2010,12 students have received $27,936 (average award of $2,328).
A15: B.1.5. | B15: Educational Aide Program | C15: The intent of this program is to encourage certain educational aides and substitute teachers to obtain full teaching certification. The Educational Aide program provides need-based exemptions from the payment of tuition and fees (other than class or laboratory fees) to students enrolled in courses leading up to teacher certification at Texas public institutions of higher education. To receive an initial award, a student must be a Texas resident, have worked at least one of the past five years as an educational aide or 180 days of the past five years as a substitute teacher, be currently employed in some capacity by a school district in Texas, show financial need, be enrolled in courses leading to teacher certification, and meet the academic progress standards of the institution. The funding is provided from the Foundation School Fund through an inter-agency contract with the Texas Education Agency. In FY 2009, a total of 4,958 students received $12,541,202 (average award of $2,529). Thus far in FY 2010, 4,022 students have received $9,326,465 (average award of $2,319).
... A69: H.1.3. | B69: Other Support Services | C69: This strategy includes Building Services, Purchasing and Supply, Mail Services, and Copy Services. Operating and support costs are allocated based on the percentage of operating budget associated with each direct strategy, with the exception of building rent, which is allocated based on the FTEs associated with each direct strategy.

Sheet EI
B1: 12-13 LAR Exceptional Items Summary -- DRAFT 06/24
A2: Ranking | B2: Agency Priority | C2: Exceptional Item Name/Strategy (in strategy order) | D2: EI Name | E2: Short EI Name | F2: Division | G2: Divisional Priority | H2: BOARD Description | I2: Short Description | J2: FY12 | K2: FY13 | L2: Biennium Total | M2: MOF
A3: 9 | B3: Exceptional Item Request #9 | C3: Texas High School Completion and Success Initiatives (HB2237) A.1.3. College Readiness Admin ($300,000/yr) | D3: Texas High School Completion and Success Initiatives (HB2237) | E3: Transfer HB2237 Funds (Admin) | F3: A1.3. | G3: 1st | H3: The 81st Texas Legislature moved the statutory responsibility for Mathematics, Science, Technology Teacher Preparatory Academies and the Intensive Programs from the public education section to the higher education section of the Texas Education Code but did not appropriate funding to the Coordinating Board. Currently, funding is provided to TEA under General Appropriations Act, Senate Bill 1, 81st Texas Legislature, Section 51 (pages III-19 and 20), Texas High School Completion and Success Initiative. In turn, TEA provides the Coordinating Board with funding through a Memorandum of Understanding. TEA has indicated they will not request funding in the 2012-2013 LAR since they have no statutory authority for these two programs. Therefore, the Coordinating Board would need to seek this appropriation in order to fund these programs for the 2012-2013. The amounts indicated above represent administrative funds. The requested grant funds are shown in Strategy E.1.10. | I3: Provides a direct appropriation to THECB of GR funds for Texas High School Completion and Success Initiative (HB 2237). These funds are currently appropriated to TEA and then transferred to CB via MOU. TEA has indicated that they will not request these funds in 12-13. | J3: 300000 | K3: 300000 | L3: =J3+K3 -> 600000 | M3: GR
A4: 10 | B4: Exceptional Item Request #10 | C4: National Student Clearinghouse Data A.3.1. Planning and Information | D4: National Student Clearing House Data | E4: National Student Clearing House Data | F4: A.3.1. | G4: 3rd | H4: To enhance the capability of research in the area of college access and success, this purchase of matching records from the National Student Clearing house would provide increased coverage of student higher education attendance patterns. Currently the longitudinal tracking is limited to only students attending higher education institutions in the state. | I4: Provides funds to purchase matching records from NSCH to provide increased coverage of student higher education attendance patterns. | J4: 250000 | K4: 250000 | L4: 500000 | M4: GR
A5: 6 | B5: Exceptional Item Request #6 | C5: Teach for Texas Loan Repayment Program -- B.1.6. | D5: Teach for Texas Loan Repayment Program | E5: Teach for Texas Loan Repay Program | F5: B.1.6. | G5: 5th | H5: The number of applications for participation in this program has increased by 76% during the past four years, and yet the funding has increased by 16% during that period. Funding for the FY2010-2011 biennium ($11.2 million) was sufficient for only 1,124 of approximately 5,000 applicant teachers in FY2010 (22%). Staff recommends raising the funding level by $19,378,557 per year over the base funding, to provide loan repayment for 5,000 teachers. (Note: For FY10 receipts from borrower payments applied to TFT conditional grants will provide loan repayment funds for approximately 200 additional teachers. This source of funds will diminish over the next few years as the loans in these portfolios are paid-in-full or go into default.) | I5: Provides loan repayment for 5,000 additional teachers. | J5: 19378557 | K5: 19378557 | L5: 38757114 | M5: GR
A6: 1 | B6: Exceptional Item Request #1 | C6: TEXAS Grants B.1.9. Student Financial Aid | D6: TEXAS Grants | E6: TEXAS Grants | F6: B.1.9. | G6: 1st | H6: CB staff recommends increased funding for this program by $148.33 million. This will enable us to keep the number of new students added to the program level with the numbers added for the 2010/2011 biennium and increase the overall number of students by over 17,000 students for the biennium. | I6: Keeps the number of new students added to the program level with the numbers added for the 2010/2011 biennium and increases the overall number of students by over 17,000 students for the biennium. | J6: 53365819 | K6: 94963455 | L6: =J6+K6 -> 148329274
A7: 2 | B7: Exceptional Item Request #2 | C7: Texas Education Opportunity Grants (TEOG) B.1.9. Student Financial Aid | D7: Texas Education Opportunity Grants (TEOG) | E7: Texas Education Opportunity Grants | F7: B.1.9. | G7: 2nd | H7: CB staff recommends that the Legislature substantially increase funding for the TEOG by $10 million. This will enable an additional 2,630 new students to enter the program during the 2012/2013 biennium and overall fund an additional 4,090 students for the biennium. | I7: Provides funding for an additional 2,630 new students to enter the program during the 2012/2013 biennium and overall funding for an additional 4,090 students for the biennium. | J7: 4706947 | K7: 5293053 | L7: =J7+K7 -> 10000000
A8: 3 | B8: Exceptional Item Request #3 | C8: Texas College Work Study B.1.9. Student Financial Aid | D8: Texas College Work Study | E8: Texas College Work Study | F8: B.1.9. | G8: 3rd | H8: CB staff recommends doubling the funding over the 2010-2011 biennium, which was $15 million. This increase will enable an additional 6,024 students to participate in the program each year of the biennium. | I8: Provides funding for an additional 6,024 students to participate in the program each year of the biennium (double the funding over the 2010-2011 biennium). | J8: 7500000 | K8: 7500000 | L8: =J8+K8 -> 15000000
A9: 4 | B9: Exceptional Item Request #4 | C9: Tuition Equalization Grants (TEG) B.1.9. | D9: Tuition Equalization Grants (TEG) | E9: Tuition Equalization Grants | F9: B.1.9. | G9: 4th | H9: CB staff recommends that the Legislature increase funding for the TEG by $10,587,465. This will enable the number of students served by the program to remain relatively steady for the 2012/2013 biennium. | I9: Provides funding to enable the number of students served by the program to remain relatively steady for the 2012/2013 biennium. | J9: 5293732 | K9: 5293733 | L9: =J9+K9 -> 10587465
A10: 5 | B10: Exceptional Item Request #5 | C10: Higher Education Performance Incentive Initiative | D10: Higher Education Performance Incentive Initiative | E10: Higher Ed Perf Incentive Initiative | F10: B.1.12. | G10: 1st | H10: The incentive funding was originally appropriated by rider in FY 2009 as General Revenue funds and then funded during the FY 2010-11 biennium through federal American Recovery and Reinvestment (ARRA) funds, which will not be available for FY 2012-13. This request would restore the General Revenue funding for this program. | I10: Restores GR that was replaced by ARRA funds in 10-11. | J10: 40000000 | K10: 40000000 | L10: 80000000 | M10: GR
A11: 11 | B11: Exceptional Item Request #11 | C11: Baylor College of Medicine Undergraduate Education -- D.1.1. | D11: Baylor College of Medicine Undergraduate Education | E11: Baylor College of Medicine | F11: D.1.1. | G11: 2nd | H11: This Exceptional Item funding of $6,868,594 would provide to Baylor College of Medicine (BCM) the amount it is authorized by statute to receive for each Texas medical student enrolled at the College. This per-student amount is based on the average General Revenue (GR) expended in the previous fiscal year for each medical student at The University of Texas Medical Branch at Galveston and The University of Texas Southwestern Medical Center in Dallas. The per-student amount includes GR expended by the two UT institutions for instruction and operations, infrastructure and benefits, but does not include formula funding appropriated to the UT institutions for research. This funding is the equivalent formula funding that is provided to all public Health-Related Institutions for medical education. | I11: Provides to Baylor College of Medicine the amount it is authorized by statute to receive for each Texas medical student enrolled at the College. | J11: 4637202.1 | K11: 2231392.1 | L11: 6868594.2 | M11: GR
A12: 7 | B12: Exceptional Item Request #7 | C12: Physician Education Loan Repayment Program -- D.1.8. | D12: Physician Education Loan Repayment Program | E12: Physician Ed Loan Repayment | F12: D.1.8. | G12: 6th | H12: The 81st Legislature authorized changes to the tax code relating to smokeless tobacco and directed specified percentages of the increased revenue to a new account for the PELRP. The increased funding allows for loan repayments in the amount of $25,000, $35,000, $45,000, and $55,000 for 1st, 2nd, 3rd, and 4th- year participants, for a maximum aggregate of $160,000. The State Comptroller's revenue projections for this fund exceed the amount of this exceptional item, which is requested to fund administrative costs and loan repayments totaling $13,500,000 to 450 physicians in FY2012 and $23,625,000 to 675 physicians in FY2013. The administrative costs of $346,711 in FY12 and $348,711 in FY13 include personnel costs for the 4 FTEs authorized in Contingency Rider 17.49 for the FY2010-2011 biennium. | I12: Authorizes spending authority for additional revenue available from smokeless tobacco funds (GR-D 5144) under HB 2154 (81st). | J12: 6846711 | K12: 8973711 | L12: 15820422 | M12: GR-D
A13: 8 | B13: Exceptional Item Request #8 | C13: Restoration of Reduction to College Readiness Grants Strategy -- E.1.10. | D13: Restoration of Reduction to College Readiness Grants Strategy | E13: Restoration of Reduction to CRI Grants | F13: E.1.10. | G13: 2nd | H13: This exceptional item would restore funding to the original 2010-2011 level to address the goal of the P-16 College Readiness and Success Strategic Action Plan to "reduce the need for developmental education and to increase student success." Restoring these funds would ensure the Coordinating Board has resources necessary to support vertical alignment statewide through higher education engagement activities and vertical alignment initiatives that involve both higher education and K-12 faculty. | I13: Restores 10-11 funding included in the 5% reductions. | J13: 1351445.4 | K13: 900963.6 | L13: 2252409 | M13: GR
A14: 9 | B14: Exceptional Item Request #9 | C14: Texas High School Completion and Success Initiatives (HB2237) E.1.10. College Readiness Grants ($6,009,000/yr) | D14: Texas High School Completion and Success Initiatives (HB2237) | E14: Transfer HB2237 Funds (Grants) | F14: E.1.10. | G14: 1st | H14: The 81st Texas Legislature moved the statutory responsibility for Mathematics, Science, Technology Teacher Preparatory Academies and the Intensive Programs from the public education section to the higher education section of the Texas Education Code but did not appropriate funding to the Coordinating Board. Currently, funding is provided to TEA under General Appropriations Act, Senate Bill 1, 81st Texas Legislature, Section 51 (pages III-19 and 20), Texas High School Completion and Success Initiative. In turn, TEA provides the Coordinating Board with funding through a Memorandum of Understanding. TEA has indicated they will not request funding in the 2012-2013 LAR since they have no statutory authority for these two programs. Therefore, the Coordinating Board would need to seek this appropriation in order to fund these programs for the 2012-2013. The amounts indicated above represent grants funds. The requested administrative funds are shown in Strategy A.1.3. | I14: Provides a direct appropriation to THECB of GR funds for Texas High School Completion and Success Initiative (HB 2237). These funds are currently appropriated to TEA and then transferred to CB via MOU. TEA has indicated that they will not request these funds in 12-13. | J14: =4704500-300000 -> 4404500 | K14: =4704500-300000 -> 4404500 | L14: =J14+K14 -> 8809000 | M14: GR
B15: Total, All Exceptional Items | J15: 78772916 | K15: 78043624 | L15: 1.5681654e+08

Sheet A - Baseline Request
A1: 2014-15 Baseline Request Summary
B2: Biennial Total | D2: FY14 | G2: FY 15 | L2: Biennium
B3: Gen Rev | C3: GR- Dedicated | D3: GR-Related | E3: Other | F3: TOTAL | G3: Gen Rev | H3: GR- Dedicated | I3: GR-Related | J3: Other | K3: TOTAL | L3: Gen Rev | M3: GR- Dedicated | N3: GR-Related | O3: Other | P3: TOTAL
A4: Goal A: Coordinate Higher Education
A5: A.1.1. College Readiness and Success | B5: 4437458 | C5: 0 | D5: ='[1]In and Out Base '!$L$3 -> 1863521 | E5: =SUM('[2]Agency Summary'!$H$8:$L$9) -> 0 | F5: =D5+E5 -> 1863521 | G5: 3070224 | H5: 404431 | I5: ='[1]In and Out Base '!$N$3 -> 1863521 | J5: =SUM('[2]Agency Summary'!$M$8:$Q$9) -> 0 | K5: =I5+J5 -> 1863521 | L5: =G5+B5 -> 7507682 | M5: =H5+C5 -> 404431 | N5: =SUM(F5,K5) -> 3727042 | O5: =J5+E5 -> 0 | P5: =N5+O5 -> 3727042 | S5: =N5='[3]In and Out Base '!$S$3 -> TRUE
A6: A.1.2. State Loan Programs | B6: 0 | C6: 0 | D6: =B6/2 -> 0 | E6: =SUM('[2]Agency Summary'!$H$10:$L$10) -> 5650000 | F6: =D6+E6 -> 5650000 | G6: 0 | H6: 0 | I6: =B6/2 -> 0 | J6: =SUM('[2]Agency Summary'!$M$10:$Q$10) -> 5650000 | K6: =I6+J6 -> 5650000 | L6: =G6+B6 -> 0 | M6: =H6+C6 -> 0 | N6: =D6+I6 -> 0 | O6: =J6+E6 -> 11300000 | P6: =N6+O6 -> 11300000
A7: A.1.3. Student Grants and Special Programs | B7: 2256682 | C7: 0 | D7: ='[1]In and Out Base '!$L$4 -> 925301 | E7: 0 | F7: =D7+E7 -> 925301 | G7: 1618572 | H7: 0 | I7: ='[1]In and Out Base '!$N$4 -> 925301 | J7: 0 | K7: =I7+J7 -> 925301 | L7: =G7+B7 -> 3875254 | M7: =H7+C7 -> 0 | N7: =D7+I7 -> 1850602 | O7: =J7+E7 -> 0 | P7: =N7+O7 -> 1850602 | S7: =N7='[3]In and Out Base '!$S$4 -> TRUE
A8: A.2.1. Workforce, Academic Affairs, and Research | B8: 3078290 | C8: 0 | D8: ='[1]In and Out Base '!$L$5 -> 1692255 | E8: =SUM('[2]Agency Summary'!$H$15:$L$15) -> 3000 | F8: =D8+E8 -> 1695255 | G8: 1558356 | H8: 0 | I8: =SUM('[1]In and Out Base '!$M$5:$N$5) -> 1692255 | J8: =SUM('[2]Agency Summary'!$M$15:$Q$15) -> 3000 | K8: =I8+J8 -> 1695255 | L8: =G8+B8 -> 4636646 | M8: =H8+C8 -> 0 | N8: =D8+I8 -> 3384510 | O8: =J8+E8 -> 6000 | P8: =N8+O8 -> 3390510 | S8: =N8='[3]In and Out Base '!$S$5 -> TRUE
A9: A.2.2. Close Gaps in Research | B9: 0 | C9: 0 | D9: =B9/2 -> 0 | E9: 0 | F9: =D9+E9 -> 0 | G9: 326285 | H9: 0 | I9: =B9/2 -> 0 | J9: 0 | K9: =I9+J9 -> 0 | L9: =G9+B9 -> 326285 | M9: =H9+C9 -> 0 | N9: =D9+I9 -> 0 | O9: =J9+E9 -> 0 | P9: =N9+O9 -> 0
A10: A.3.1. Planning, Information, & Evaluation | B10: 3244680 | C10: 0 | D10: ='[1]In and Out Base '!$L$6 -> 1989978 | E10: =SUM('[2]Agency Summary'!$H$16:$L$16) -> 400000 | F10: =D10+E10 -> 2389978 | G10: 2064813 | H10: 0 | I10: =SUM('[1]In and Out Base '!$M$6:$N$6) -> 1989978 | J10: =SUM('[2]Agency Summary'!$M$16:$Q$16) -> 0 | K10: =I10+J10 -> 1989978 | L10: =G10+B10 -> 5309493 | M10: =H10+C10 -> 0 | N10: =D10+I10 -> 3979956 | O10: =J10+E10 -> 400000 | P10: =N10+O10 -> 4379956 | S10: =N10='[3]In and Out Base '!$S$6 -> TRUE
A11: A.3.2. Higher Education Policy Institute | D11: =B11+C11 -> 0 | E11: =SUM('[2]Agency Summary'!$H$17:$L$17) -> 423060 | F11: =D11+E11 -> 423060 | I11: =G11+H11 -> 0 | J11: =SUM('[2]Agency Summary'!$M$17:$Q$17) -> 423060 | K11: =I11+J11 -> 423060 | N11: =D11+I11 -> 0 | O11: =J11+E11 -> 846120 | P11: =N11+O11 -> 846120
A12: Goal B: Close the Gaps by Improving Affordability
A13: B.1.1 Texas Grant Program | B13: ='B - Reductions '!I11 -> 1549925 | D13: ='[3]In and Out Base '!$L$7 -> 290391465 | E13: =SUM('[2]Agency Summary'!$H$26:$L$26) -> 5000 | F13: =D13+E13 -> 290396465 | I13: ='[3]In and Out Base '!$N$7 -> 290391465 | J13: =SUM('[2]Agency Summary'!$M$26:$Q$26) -> 5000 | K13: =I13+J13 -> 290396465 | N13: =D13+I13 -> 580782930 | O13: =J13+E13 -> 10000 | P13: =N13+O13 -> 580792930 | S13: =N13='[3]In and Out Base '!$S$7 -> TRUE
A14: B.1.2 Texas B-On-Time Program | B14: ='B - Reductions '!I12 -> 7067451 | C14: ='B - Reductions '!J12 -> 0 | D14: ='[3]In and Out Base '!$M$8 -> 40278896 | E14: 0 | F14: =D14+E14 -> 40278896 | I14: ='[3]In and Out Base '!$O$8 -> 40278895 | K14: =I14+J14 -> 40278895 | N14: =D14+I14 -> 80557791 | O14: =J14+E14 -> 0 | P14: =N14+O14 -> 80557791 | S14: =N14='[3]In and Out Base '!$S$8 -> TRUE
A15: B.1.3 Tuition Equalization Grants | B15: ='B - Reductions '!I14 -> 4006794 | D15: ='[1]In and Out Base '!$L$9 -> 84422827 | F15: =D15+E15 -> 84422827 | I15: =SUM('[1]In and Out Base '!$M$9:$N$9) -> 84422827 | K15: =I15+J15 -> 84422827 | N15: =D15+I15 -> 168845654 | O15: =J15+E15 -> 0 | P15: =N15+O15 -> 168845654 | S15: =N15='[3]In and Out Base '!$S$9 -> TRUE
A16: B.1.4 Texas Educational Opportunity Grant Prg | B16: ='B - Reductions '!I13 -> 35625000 | D16: ='[1]In and Out Base '!$L$10 -> 32674694 | F16: =D16+E16 -> 32674694 | I16: =SUM('[1]In and Out Base '!$M$10:$N$10) -> 32674694 | K16: =I16+J16 -> 32674694 | N16: =D16+I16 -> 65349388 | O16: =J16+E16 -> 0 | P16: =N16+O16 -> 65349388 | S16: =N16='[3]In and Out Base '!$S$10 -> TRUE
A17: B.1.5. College Work Study Program | B17: ='B - Reductions '!I15 -> 2637650 | D17: ='[1]In and Out Base '!$L$11 -> 7529639 | F17: =D17+E17 -> 7529639 | I17: =SUM('[1]In and Out Base '!$M$11:$N$11) -> 7529639 | K17: =I17+J17 -> 7529639 | N17: =D17+I17 -> 15059278 | O17: =J17+E17 -> 0 | P17: =N17+O17 -> 15059278 | S17: =N17='[3]In and Out Base '!$S$11 -> TRUE
A18: B.1.6. License Plate Scholarships Program | B18: 0 | C18: 1099000 | D18: ='[1]In and Out Base '!$M$12 -> 549500 | E18: =SUM('[2]Agency Summary'!$H$18:$L$18) -> 0 | F18: =D18+E18 -> 549500 | G18: 0 | H18: 93000 | I18: =SUM('[1]In and Out Base '!$M$12:$N$12) -> 549500 | J18: =SUM('[2]Agency Summary'!$M$18:$Q$18) -> 0 | K18: =I18+J18 -> 549500 | L18: =G18+B18 -> 0 | M18: =C18 -> 1099000 | N18: =D18+I18 -> 1099000 | O18: =J18+E18 -> 0 | P18: =N18+O18 -> 1099000 | S18: =N18='[3]In and Out Base '!$S$12 -> TRUE
A19: B.1.2. Fifth-Year Accounting Students Prg | B19: 0 | C19: 0 | D19: =B19+C19 -> 0 | E19: 0 | F19: =D19+E19 -> 0 | G19: 0 | H19: 0 | I19: =G19+H19 -> 0 | J19: 0 | K19: =I19+J19 -> 0 | L19: =G19+B19 -> 0 | M19: =H19+C19 -> 0 | N19: =D19+I19 -> 0 | O19: =J19+E19 -> 0 | P19: =N19+O19 -> 0
A20: B.1.7. Early High School Grad Scholarships | B20: 0 | C20: 0 | D20: =B20+C20 -> 0 | E20: =SUM('[2]Agency Summary'!$H$19:$L$19) -> 0 | F20: =D20+E20 -> 0 | G20: 0 | H20: 0 | I20: =G20+H20 -> 0 | J20: =SUM('[2]Agency Summary'!$M$19:$Q$19) -> 0 | K20: =I20+J20 -> 0 | L20: =G20+B20 -> 0 | M20: =H20+C20 -> 0 | N20: =D20+I20 -> 0 | O20: =J20+E20 -> 0 | P20: =N20+O20 -> 0
A21: B.1.8. TANF Scholarship Program | B21: 0 | C21: 0 | D21: =B21+C21 -> 0 | E21: =SUM('[2]Agency Summary'!$H$20:$L$20) -> 0 | F21: =D21+E21 -> 0 | G21: 0 | H21: 0 | I21: =G21+H21 -> 0 | J21: =SUM('[2]Agency Summary'!$M$20:$Q$20) -> 0 | K21: =I21+J21 -> 0 | L21: =G21+B21 -> 0 | M21: =H21+C21 -> 0 | N21: =D21+I21 -> 0 | O21: =J21+E21 -> 0 | P21: =N21+O21 -> 0
A22: B.1.9. Educational Aide Program | B22: 0 | C22: 0 | D22: =B22+C22 -> 0 | E22: =SUM('[2]Agency Summary'!$H$21:$L$21) -> 0 | F22: =D22+E22 -> 0 | G22: 0 | H22: 0 | I22: =G22+H22 -> 0 | J22: =SUM('[2]Agency Summary'!$M$21:$Q$21) -> 0 | K22: =I22+J22 -> 0 | L22: =G22+B22 -> 0 | M22: =H22+C22 -> 0 | N22: =D22+I22 -> 0 | O22: =J22+E22 -> 0 | P22: =N22+O22 -> 0
A23: B.1.10. Teach for Texas Loan Repayment | B23: 10000000 | C23: 0 | D23: ='[1]In and Out Base '!$L$16 -> 500000 | E23: =SUM('[2]Agency Summary'!$H$22:$L$22) -> 0 | F23: =D23+E23 -> 500000 | G23: 5771443 | H23: 0 | I23: =SUM('[1]In and Out Base '!$M$16:$N$16) -> 500000 | J23: =SUM('[2]Agency Summary'!$M$22:$Q$22) -> 0 | K23: =I23+J23 -> 500000 | L23: =B23 -> 10000000 | M23: =H23+C23 -> 0 | N23: =D23+I23 -> 1000000 | O23: =J23+E23 -> 0 | P23: =N23+O23 -> 1000000 | S23: =N23='[3]In and Out Base '!$S$16 -> TRUE
A24: B.1.11. Border Faculty Loan Repayment Prg | B24: 375626 | C24: 0 | D24: =SUM('[1]In and Out Base '!$K$17:$L$17) -> 187813 | E24: =SUM('[2]Agency Summary'!$H$23:$L$23) -> 0 | F24: =D24+E24 -> 187813 | G24: 187813 | H24: 0 | I24: =SUM('[1]In and Out Base '!$M$17:$N$17) -> 187813 | J24: =SUM('[2]Agency Summary'!$M$23:$Q$23) -> 0 | K24: =I24+J24 -> 187813 | L24: =B24 -> 375626 | M24: =H24+C24 -> 0 | N24: =D24+I24 -> 375626 | O24: =J24+E24 -> 0 | P24: =N24+O24 -> 375626 | S24: =N24='[3]In and Out Base '!$S$17 -> TRUE
A25: B.1.12. OAG Lawyers Loan Repayment Prg | B25: 496072 | C25: 0 | D25: =SUM('[1]In and Out Base '!$K$18:$L$18) -> 248036 | E25: =SUM('[2]Agency Summary'!$H$24:$L$24) -> 0 | F25: =D25+E25 -> 248036 | G25: 330715 | H25: 0 | I25: =SUM('[1]In and Out Base '!$M$18:$N$18) -> 248036 | J25: =SUM('[2]Agency Summary'!$M$24:$Q$24) -> 0 | K25: =I25+J25 -> 248036 | L25: =B25 -> 496072 | M25: =H25+C25 -> 0 | N25: =D25+I25 -> 496072 | O25: =J25+E25 -> 0 | P25: =N25+O25 -> 496072 | S25: =N25='[3]In and Out Base '!$S$18 -> TRUE
A26: B.1.13. Doctoral Incentive Program | B26: 0 | C26: 0 | D26: =B26+C26 -> 0 | E26: =SUM('[2]Agency Summary'!$H$31:$L$31) -> 0 | F26: =D26+E26 -> 0 | G26: 650000 | H26: 0 | I26: 0 | J26: =SUM('[2]Agency Summary'!$M$31:$Q$31) -> 0 | K26: =I26+J26 -> 0 | L26: =G26+B26 -> 650000 | M26: =H26+C26 -> 0 | N26: =D26+I26 -> 0 | O26: =J26+E26 -> 0 | P26: =N26+O26 -> 0
A27: B.1.14. Engineering Recruitment Program | B27: 0 | C27: 0 | D27: =B27+C27 -> 0 | E27: =SUM('[2]Agency Summary'!$H$32:$L$32) -> 0 | F27: =D27+E27 -> 0 | G27: 950000 | H27: 0 | I27: 0 | J27: =SUM('[2]Agency Summary'!$M$32:$Q$32) -> 0 | K27: =I27+J27 -> 0 | L27: =G27+B27 -> 950000 | M27: =H27+C27 -> 0 | N27: =D27+I27 -> 0 | O27: =J27+E27 -> 0 | P27: =N27+O27 -> 0
A28: B.1.15. Top Ten Percent Scholarships | B28: 8500000 | C28: 0 | D28: ='[1]In and Out Base '!$L$21 -> 4250000 | E28: =SUM('[2]Agency Summary'!$H$34:$L$34) -> 0 | F28: =D28+E28 -> 4250000 | G28: 25612000 | H28: 0 | I28: =SUM('[1]In and Out Base '!$M$21:$N$21) -> 4250000 | J28: =SUM('[2]Agency Summary'!$M$34:$Q$34) -> 0 | K28: =I28+J28 -> 4250000 | L28: =G28+B28 -> 34112000 | M28: =H28+C28 -> 0 | N28: =D28+I28 -> 8500000 | O28: =J28+E28 -> 0 | P28: =N28+O28 -> 8500000 | S28: =N28='[3]In and Out Base '!$S$21 -> TRUE
A29: B.1.16. Texas Armed Services Scholarships | B29: 4220000 | C29: 0 | D29: ='[3]In and Out Base '!$L$22 -> 3560000 | E29: =SUM('[2]Agency Summary'!$H$35:$L$35) -> 0 | F29: =D29+E29 -> 3560000 | G29: 875000 | H29: 0 | I29: ='[3]In and Out Base '!$N$22 -> 3560000 | J29: =SUM('[2]Agency Summary'!$M$35:$Q$35) -> 0 | K29: =I29+J29 -> 3560000 | L29: =G29+B29 -> 5095000 | M29: =H29+C29 -> 0 | N29: =D29+I29 -> 7120000 | O29: =J29+E29 -> 0 | P29: =N29+O29 -> 7120000 | S29: =N29='[3]In and Out Base '!$S$22 -> TRUE
A30: B.1.17. Combat Tuition Reimbursement Prg | B30: 0 | C30: 0 | D30: =B30+C30 -> 0 | E30: =SUM('[2]Agency Summary'!$H$36:$L$36) -> 0 | F30: =D30+E30 -> 0 | G30: 349500 | H30: 0 | I30: 0 | J30: =SUM('[2]Agency Summary'!$M$36:$Q$36) -> 0 | K30: =I30+J30 -> 0 | L30: =G30+B30 -> 349500 | M30: =H30+C30 -> 0 | N30: =D30+I30 -> 0 | O30: =J30+E30 -> 0 | P30: =N30+O30 -> 0
A31: B.1.18. Texas Career Opportunity Grants | B31: 0 | C31: 0 | D31: =B31+C31 -> 0 | E31: =SUM('[2]Agency Summary'!$H$37:$L$37) -> 0 | F31: =D31+E31 -> 0 | G31: 642500 | H31: 0 | I31: 0 | J31: =SUM('[2]Agency Summary'!$M$37:$Q$37) -> 0 | K31: =I31+J31 -> 0 | L31: =G31+B31 -> 642500 | M31: =H31+C31 -> 0 | N31: =D31+I31 -> 0 | O31: =J31+E31 -> 0 | P31: =N31+O31 -> 0
A32: B.1.19. T-STEM Challenge Scholarship Prg | B32: 0 | C32: 0 | D32: =B32/2 -> 0 | E32: =SUM('[2]Agency Summary'!$H$39:$L$39) -> 3000000 | F32: =D32+E32 -> 3000000 | I32: =B32/2 -> 0 | J32: =SUM('[2]Agency Summary'!$M$39:$Q$39) -> 3000000 | K32: =I32+J32 -> 3000000 | N32: =D32+I32 -> 0 | O32: =SUM(E32,J32) -> 6000000 | P32: =N32+O32 -> 6000000
A33: Goal C: Close the Gaps by Providing Trusteed Funds for Research
A34: C.1.1. N. Hackerman Advanced Research Prg | B34: 3000000 | C34: 0 | D34: =SUM('[1]In and Out Base '!$K$26:$L$26) -> 1000000 | E34: =SUM('[2]Agency Summary'!$H$40:$L$40) -> 0 | F34: =D34+E34 -> 1000000 | G34: 0 | H34: 0 | I34: UB | J34: =SUM('[2]Agency Summary'!$M$40:$Q$40) -> 0 | K34: =J34 -> 0 | L34: =G34+B34 -> 3000000 | M34: =H34+C34 -> 0 | N34: =D34 -> 1000000 | O34: =J34+E34 -> 0 | P34: =N34+O34 -> 1000000 | S34: =N34='[3]In and Out Base '!$S$26 -> TRUE
A35: C.1.2. Texas Research Incentive Prg | B35: 35625000 | D35: =SUM('[1]In and Out Base '!$K$27:$L$27) -> 17812500 | E35: =SUM('[2]Agency Summary'!$H$38:$L$38) -> 0 | F35: =D35+E35 -> 17812500 | I35: =SUM('[1]In and Out Base '!$M$27:$N$27) -> 17812500 | J35: =SUM('[2]Agency Summary'!$M$38:$Q$38) -> 0 | K35: =I35+J35 -> 17812500 | N35: =D35+I35 -> 35625000 | O35: =E35+J35 -> 0 | P35: =N35+O35 -> 35625000 | S35: =N35='[3]In and Out Base '!$S$27 -> TRUE
A36: Goal D: Close the Gaps by Providing Trusteed Funds for Health Care Education
A37: D.1.1. Family Practice Residency Program | B37: 7600000 | C37: 0 | D37: ='[1]In and Out Base '!$L$28 -> 4800000 | E37: =SUM('[2]Agency Summary'!$H$43:$L$43) -> 0 | F37: =D37+E37 -> 4800000 | G37: 0 | H37: 0 | I37: =SUM('[1]In and Out Base '!$M$28:$N$28) -> 4800000 | J37: =SUM('[2]Agency Summary'!$M$43:$Q$43) -> 0 | K37: =I37+J37 -> 4800000 | L37: =G37+B37 -> 7600000 | M37: =H37+C37 -> 0 | N37: =D37+I37 -> 9600000 | O37: =J37+E37 -> 0 | P37: =N37+O37 -> 9600000 | S37: =N37='[3]In and Out Base '!$S$28 -> TRUE
A38: D.1.2. Preceptorship Program | B38: 0 | C38: 0 | D38: =B38+C38 -> 0 | E38: =SUM('[2]Agency Summary'!$H$44:$L$44) -> 0 | F38: =D38+E38 -> 0 | G38: 0 | H38: 0 | I38: 0 | J38: =SUM('[2]Agency Summary'!$M$44:$Q$44) -> 0 | K38: =I38+J38 -> 0 | L38: =G38+B38 -> 0 | M38: =H38+C38 -> 0 | N38: =D38+I38 -> 0 | O38: =J38+E38 -> 0 | P38: =N38+O38 -> 0
A39: D.1.3. Primary Care Residency Program | B39: 0 | C39: 0 | D39: =B39+C39 -> 0 | E39: =SUM('[2]Agency Summary'!$H$45:$L$45) -> 0 | F39: =D39+E39 -> 0 | G39: 0 | H39: 0 | I39: 0 | J39: =SUM('[2]Agency Summary'!$M$45:$Q$45) -> 0 | K39: =I39+J39 -> 0 | L39: =G39+B39 -> 0 | M39: =H39+C39 -> 0 | N39: =D39+I39 -> 0 | O39: =J39+E39 -> 0 | P39: =N39+O39 -> 0
A40: D.1.4. Graduate Medical Education (GME) | B40: 0 | C40: 0 | D40: =B40+C40 -> 0 | E40: =SUM('[2]Agency Summary'!$H$46:$L$46) -> 0 | F40: =D40+E40 -> 0 | G40: 0 | H40: 0 | I40: 0 | J40: =SUM('[2]Agency Summary'!$M$46:$Q$46) -> 0 | K40: =I40+J40 -> 0 | L40: =G40+B40 -> 0 | M40: =H40+C40 -> 0 | N40: =D40+I40 -> 0 | O40: =J40+E40 -> 0 | P40: =N40+O40 -> 0
...

Sheet B - Reductions 
A1: 10 Percent Biennial Base Reduction Options Schedule
A3: First 5% Reduction | Z3: Second 5% Reduction
A4: (priority order) | B4: Strategy Name | C4: FY12 Budgeted | E4: FY13 Budgeted | G4: FY12-13 Budgeted Base | I4: Proposed FY14-15 Base | K4: Proposed FY14-15 Base | L4: First Proposed Reduction | O4: Second Proposed Reduction | R4: FTE Reductions (FY12-FY13 Base) | T4: First Reduction % of Proposed Base | U4: Second Reduction % of Proposed Base | V4: TOTAL Reduction % of Proposed Base | W4: Running Total | X4: Cumulative % | Z4: (priority order) | AA4: Strategy Name | AB4: Proposed FY14-15 Base | AC4: Second Proposed Reduction | AD4: Second Reduction % of Proposed Base
A5: Rank of First Reduction | C5: GR | D5: GR-D | E5: GR | F5: GR-D | G5: GR | H5: GR-D | I5: GR | J5: GR-D | K5: GR/GR-D | L5: GR | M5: GR-Dedicated | N5: GR/GR-D | O5: GR | P5: GR-Dedicated | Q5: Total GR/ GR-D | R5: FY 12 | S5: FY 13 | Z5: Rank of Second Reduction | AB5: GR/GR-D | AC5: GR/GR-D
A6: Column1 | B6: Column3 | C6: Column4 | D6: Column5 | E6: Column6 | F6: Column7 | G6: Column8 | H6: Column9 | I6: Column10 | J6: Column11 | K6: Column112 | L6: Column12 | M6: Column13 | N6: Column14 | O6: Column15 | P6: Column16 | Q6: Column17 | R6: Column18 | S6: Column19 | T6: Column20 | U6: Column21 | V6: Column22 | W6: =W4+N7+Q7 -> #VALUE! | X6: =W6/(G$38+H$38) -> #VALUE! | Z6: Column2 | AA6: Column3 | AB6: Column112 | AC6: Column17 | AD6: Column21
A7: 1 | B7: D.1.11. Alzheimer's Disease Cen | C7: 5230625 | G7: =SUM(C7,E7) -> 5230625 | H7: =SUM(D7,F7) -> 0 | I7: =[4]WAAR!F13 -> 4230625 | K7: =SUM(Table1[[#This Row],[Column10]:[Column11]]) -> 4230625 | L7: =[4]WAAR!H13 -> 0 | M7: =[4]WAAR!I13 -> 0 | N7: 627035 | O7: =[4]WAAR!H27 -> 475000 | P7: =[4]WAAR!I27 -> 0 | Q7: =SUM(O7:P7) -> 475000 | R7: 0 | S7: 0 | T7: =N7/(SUM(I7:J7)) -> 0.14821333 | U7: =Q7/SUM(I7:J7) -> 0.11227655 | V7: =(N7+Q7)/(I7+J7) -> 0.26048988 | W7: =W5+#REF!+#REF! -> #REF! | X7: =W7/(G$38+H$38) -> #REF! | Z7: 1 | AA7: D.1.11. Alzheimer's Disease Cen | AB7: 4230625 | AC7: =[1]Reductions!$Q$26 -> 152035 | AD7: =Table2[[#This Row],[Column17]]/Table2[[#This Row],[Column112]] -> 0.035936771 | AH7: E.1.2. Baylor COM-GME | AK7: =T8+Table2[[#This Row],[Column21]] -> 0.1954032
A8: 2 | B8: A.1.1. College Readiness and Success | C8: =1415140-101036 -> 1314104 | E8: =1415140-142388 -> 1272752 | G8: =SUM(C8,E8) -> 2586856 | H8: =SUM(D8,F8) -> 0 | I8: =SUM('[5]In and Out Base '!$K$3,'[5]In and Out Base '!$M$3) -> 4027042 | K8: ='A - Baseline Request'!N5 -> 3727042 | L8: =[5]Reductions!$P$4 -> 642178 | M8: 0 | N8: =L8+M8 -> 642178 | O8: =[5]Reductions!$Q$4 -> 569695 | P8: 0 | Q8: =SUM(O8:P8) -> 569695 | R8: 0 | S8: 0 | T8: =N8/(SUM(I8:J8)) -> 0.15946643 | U8: =Q8/SUM(I8:J8) -> 0.14146736 | V8: =(N8+Q8)/(I8+J8) -> 0.30093379 | W8: =#REF!+N9+Q9 -> #REF! | X8: =W8/(G$38+H$38) -> #REF! | Z8: 2 | AA8: A.1.1. College Readiness and Success | AB8: ='A - Baseline Request'!N5 -> 3727042 | AC8: 569695 | AD8: =Table2[[#This Row],[Column17]]/Table2[[#This Row],[Column112]] -> 0.15285446 | AH8: E.1.1. Baylor Col of Med UGME | AK8: =T9+Table2[[#This Row],[Column21]] -> 0.19936135
A9: 3 | B9: A.2.1. Workforce, Academic Affairs, & Research | C9: =1244915-95000+120000 -> 1269915 | E9: =1244916-97001+120000 -> 1267915 | G9: =SUM(C9,E9) -> 2537830 | H9: =SUM(D9,F9) -> 0 | I9: 3309510 | K9: ='A - Baseline Request'!N8 -> 3384510 | L9: =[5]Reductions!$P$6 -> 153915 | M9: =[4]WAAR!I8 -> 0 | N9: =L9+M9 -> 153915 | O9: =[5]Reductions!$Q$6 -> 174442 | P9: =[4]WAAR!I22 -> 0 | Q9: =SUM(O9:P9) -> 174442 | R9: 0 | S9: 0 | T9: =N9/(SUM(I9:J9)) -> 0.046506885 | U9: =Q9/SUM(I9:J9) -> 0.052709313 | V9: =(N9+Q9)/(I9+J9) -> 0.099216198 | W9: =W8+#REF!+#REF! -> #REF! | X9: =W9/(G$38+H$38) -> #REF! | Z9: 3 | AA9: A.2.1. Workforce, Academic Affairs, & Research | AB9: ='A - Baseline Request'!N8 -> 3384510 | AC9: 174442 | AD9: =Table2[[#This Row],[Column17]]/Table2[[#This Row],[Column112]] -> 0.051541287 | AH9: A.1.1. College Readiness and Success | AK9: =T10+Table2[[#This Row],[Column21]] -> 0.10010581
A10: 4 | B10: A.3.1. Planning, Information and Evaluation | C10: =1755091-107751 -> 1647340 | E10: =1755091-157751 -> 1597340 | G10: =SUM(C10,E10) -> 3244680 | H10: =SUM(D10,F10) -> 0 | I10: 3829956 | K10: ='A - Baseline Request'!N10 -> 3979956 | L10: =[5]Reductions!$P$7 -> 186000 | M10: =[4]PIE!I8 -> 0 | N10: =L10+M10 -> 186000 | O10: =[5]Reductions!$Q$7 -> 149956 | P10: =[4]PIE!I18 -> 0 | Q10: =SUM(O10:P10) -> 149956 | R10: 0 | S10: 0 | T10: =N10/(SUM(I10:J10)) -> 0.048564527 | U10: =Q10/SUM(I10:J10) -> 0.039153452 | V10: =(N10+Q10)/(I10+J10) -> 0.087717979 | W10: =#REF!+#REF!+#REF! -> #REF! | X10: =W10/(G$38+H$38) -> #REF! | Z10: 4 | AA10: A.3.1. Planning, Information and Evaluation | AB10: ='A - Baseline Request'!N10 -> 3979956 | AC10: 149956 | AD10: =Table2[[#This Row],[Column17]]/Table2[[#This Row],[Column112]] -> 0.037677803 | AH10: A.2.1. Workforce, Academic Affairs, and Research | AK10: =T11+Table2[[#This Row],[Column21]] -> 0.087677642
A11: 5 | B11: I.1.3. Other Support Services | C11: 774963 | E11: 774962 | G11: =SUM(C11,E11) -> 1549925 | H11: =SUM(D11,F11) -> 0 | I11: =[4]BSS!F21 -> 1549925 | K11: =SUM(Table1[[#This Row],[Column10]:[Column11]]) -> 1549925 | L11: =[4]BSS!H21 -> 77496 | M11: =[4]BSS!I21 -> 0 | N11: =L11+M11 -> 77496 | O11: =[4]BSS!H40 -> 77496 | P11: =[4]BSS!I40 -> 0 | Q11: =SUM(O11:P11) -> 77496 | R11: 0 | S11: 0 | T11: =N11/(SUM(I11:J11)) -> 0.049999839 | U11: =Q11/SUM(I11:J11) -> 0.049999839 | V11: =(N11+Q11)/(I11+J11) -> 0.099999677 | W11: =#REF!+N13+Q13 -> #REF! | Z11: 5 | AA11: I.1.3. Other Support Services | AB11: 1549925 | AC11: 77496 | AD11: =Table2[[#This Row],[Column17]]/Table2[[#This Row],[Column112]] -> 0.049999839 | AH11: A.3.1. Planning, Information and Evaluation | AK11: =T12+Table2[[#This Row],[Column21]] -> 0.071543815
A12: 6 | B12: I.1.1. Central Administration | C12: =2911961+615252 -> 3527213 | E12: =2911961+494845 -> 3406806 | G12: =SUM(C12,E12) -> 6934019 | H12: =SUM(D12,F12) -> 0 | I12: =[4]BSS!F20+133432 -> 7067451 | K12: ='A - Baseline Request'!N78 -> 7142451 | L12: =[4]BSS!H20 -> 346701 | M12: =[4]BSS!I20 -> 0 | N12: =[1]Reductions!$P$34 -> 152261 | O12: =[4]BSS!H39 -> 346701 | P12: =[4]BSS!I39 -> 0 | Q12: =SUM(O12:P12) -> 346701 | R12: 0 | S12: 0 | T12: =N12/(SUM(I12:J12)) -> 0.021543977 | U12: =Q12/SUM(I12:J12) -> 0.049056018 | V12: =(N12+Q12)/(I12+J12) -> 0.070599994 | W12: =W14+N15+Q15 -> #REF! | Z12: 6 | AA12: B.1.11. Border Faculty LRP | AB12: 375626 | AC12: 375626 | AD12: =Table2[[#This Row],[Column17]]/Table2[[#This Row],[Column112]] -> 1 | AH12: I.1.3. Other Sup Ser | AK12: =T14+Table2[[#This Row],[Column21]] -> 1.2370973
A13: 7 | B13: C.1.2. TX Research Incentive Pro | C13: 17812500 | E13: 17812500 | G13: =SUM(C13,E13) -> 35625000 | H13: =SUM(D13,F13) -> 0 | I13: =[4]PIE!F9 -> 35625000 | K13: =SUM(Table1[[#This Row],[Column10]:[Column11]]) -> 35625000 | L13: =ROUND([4]PIE!H9,0) -> 1781250 | M13: =[4]PIE!I9 -> 0 | N13: =ROUND(L13+M13,0) -> 1781250 | O13: =[4]PIE!H19 -> 1781250 | P13: =[4]PIE!I19 -> 0 | Q13: =ROUND(SUM(O13:P13),0) -> 1781250 | R13: 0 | S13: 0 | T13: =N13/(SUM(I13:J13)) -> 0.05 | U13: =Q13/SUM(I13:J13) -> 0.05 | V13: =(N13+Q13)/(I13+J13) -> 0.1 | W13: =W11+N14+Q14 -> #REF! | Z13: 7 | AA13: A.1.3. Student Grants and Special Prgs | AB13: 1850602 | AC13: 92530 | AD13: =Table2[[#This Row],[Column17]]/Table2[[#This Row],[Column112]] -> 0.049999946 | AH13: B.1.11. Border Faculty LRP | AK13: =T23+Table2[[#This Row],[Column21]] -> 0.049999946
A14: 8 | B14: D.1.5. Joint Admiss Md Pro | C14: 7006794 | G14: =SUM(C14,E14) -> 7006794 | H14: =SUM(D14,F14) -> 0 | I14: =[4]WAAR!F12 -> 4006794 | K14: =SUM(Table1[[#This Row],[Column10]:[Column11]]) -> 4006794 | L14: =[4]WAAR!H12 -> 950000 | M14: =[4]WAAR!I12 -> 0 | N14: =L14+M14 -> 950000 | O14: =[4]WAAR!H26 -> 475000 | P14: =[4]WAAR!I26 -> 0 | Q14: =SUM(O14:P14) -> 475000 | R14: 0 | S14: 0 | T14: =N14/(SUM(I14:J14)) -> 0.23709729 | U14: =Q14/SUM(I14:J14) -> 0.11854865 | V14: =(N14+Q14)/(I14+J14) -> 0.35564594 | W14: =W13+N12+Q12 -> #REF! | Z14: 8 | AA14: I.1.1. Central Administration | AB14: ='A - Baseline Request'!N78 -> 7142451 | AC14: 474425 | AD14: =Table2[[#This Row],[Column17]]/Table2[[#This Row],[Column112]] -> 0.066423277 | AH14: A.1.3. Student Grants and Special Prgs | AK14: =T18+Table2[[#This Row],[Column21]] -> 0.64363225
A15: 9 | B15: I.1.2. Information Resources | C15: =1281089-72067 -> 1209022 | E15: =1281089-86655+234194 -> 1428628 | G15: =SUM(C15,E15)-1299000 -> 1338650 | H15: =SUM(D15,F15) -> 0 | I15: =[4]ISS!F8 -> 2637650 | K15: ='A - Baseline Request'!N79 -> 2640033 | L15: =[4]ISS!H8 -> 0 | M15: =[4]ISS!I8 -> 0 | N15: 66933 | O15: =[4]ISS!H13 -> 66933 | P15: =[4]ISS!I13 -> 0 | Q15: =SUM(O15:P15) -> 66933 | R15: 0 | S15: 0 | T15: =N15/(SUM(I15:J15)) -> 0.025375998 | U15: =Q15/SUM(I15:J15) -> 0.025375998 | V15: =(N15+Q15)/(I15+J15) -> 0.050751995 | W15: =W12+#REF!+#REF! -> #REF! | X15: =W15/(G$38+H$38) -> #REF! | Z15: 9 | AA15: I.1.2. Information Resources | AB15: ='A - Baseline Request'!N79 -> 2640033 | AC15: 66933 | AD15: =Table2[[#This Row],[Column17]]/Table2[[#This Row],[Column112]] -> 0.025353092 | AH15: I.1.1. Central Adm | AK15: =Table1[[#This Row],[Column20]]+Table2[[#This Row],[Column21]] -> 0.05072909
A16: 10 | B16: A.1.3. Student Grants and Special Prgs | C16: =1300774-172433 -> 1128341 | E16: =1300774-172433 -> 1128341 | G16: =SUM(C16,E16) -> 2256682 | H16: =SUM(D16,F16) -> 0 | I16: 1850602 | K16: =SUM(Table1[[#This Row],[Column10]:[Column11]]) -> 1850602 | L16: =[5]Reductions!$P$5 -> 92530 | M16: =[4]P16!I9 -> 0 | N16: =L16+M16 -> 92530 | O16: =[5]Reductions!$Q$5 -> 92530 | P16: =[4]P16!I20 -> 0 | Q16: =SUM(O16:P16) -> 92530 | R16: 0 | S16: 0 | T16: =N16/(SUM(I16:J16)) -> 0.049999946 | U16: =Q16/SUM(I16:J16) -> 0.049999946 | V16: =(N16+Q16)/(I16+J16) -> 0.099999892 | W16: =#REF!+#REF!+#REF! -> #REF! | X16: =W16/(G$38+H$38) -> #REF! | Z16: 10 | AA16: D.1.10. Prof Nurse Shortage | AB16: 30000000 | AC16: 1500000 | AD16: =Table2[[#This Row],[Column17]]/Table2[[#This Row],[Column112]] -> 0.05 | AH16: I.1.2. Info Resources | AK16: =T37+Table2[[#This Row],[Column21]] -> 0.05
A17: 11 | B17: D.1.10. Prof Nurse Shortage | C17: 15000000 | E17: 15000000 | G17: =SUM(C17,E17) -> 30000000 | H17: =SUM(D17,F17) -> 0 | I17: =[4]PIE!F12 -> 30000000 | K17: =SUM(Table1[[#This Row],[Column10]:[Column11]]) -> 30000000 | L17: =[4]PIE!H12 -> 1500000 | M17: =[4]PIE!I12 -> 0 | N17: =L17+M17 -> 1500000 | O17: =[4]PIE!H22 -> 1500000 | P17: =[4]PIE!I22 -> 0 | Q17: =SUM(O17:P17) -> 1500000 | R17: 0 | S17: 0 | T17: =N17/(SUM(I17:J17)) -> 0.05 | U17: =Q17/SUM(I17:J17) -> 0.05 | V17: =(N17+Q17)/(I17+J17) -> 0.1 | W17: =#REF!+N18+Q18 -> #REF! | X17: =W17/(G$38+H$38) -> #REF! | Z17: 11 | AA17: D.1.5. Joint Admiss Md Pro | AB17: 4006794 | AC17: 475000 | AD17: =Table2[[#This Row],[Column17]]/Table2[[#This Row],[Column112]] -> 0.11854865 | AH17: F.1.2. Centers for Teacher Ed | AK17: =T13+Table2[[#This Row],[Column21]] -> 0.16854865
A18: 12 | B18: B.1.2 Texas B-On-Time | C18: 17304000 | D18: 80557791 | E18: 14104000 | G18: =SUM(C18,E18) -> 31408000 | H18: =SUM(D18,F18) -> 80557791 | I18: =[4]BSS!F15 -> 14000000 | J18: =[4]BSS!G15 -> 33000000 | K18: ='A - Baseline Request'!N14 -> 80557791 | L18: =[4]BSS!H15 -> 0 | M18: =[4]BSS!I15 -> 0 | N18: =[3]Reductions!$P$10 -> 46498680 | O18: =[4]BSS!H34 -> 0 | P18: =[4]BSS!I34 -> 0 | Q18: =SUM(O18:P18) -> 0 | T18: =N18/(SUM(Table1[[#This Row],[Column112]])) -> 0.57720898 | U18: =Q18/SUM(I18:J18) -> 0 | V18: =(N18+Q18)/(I18+J18) -> 0.98933362 | W18: =W17+#REF!+#REF! -> #REF! | X18: =W18/(G$38+H$38) -> #REF! | Z18: 12 | AA18: C.1.2. TX Research Incentive Pro | AB18: 35625000 | AC18: 1781250 | AD18: =Table2[[#This Row],[Column17]]/Table2[[#This Row],[Column112]] -> 0.05 | AH18: D.1.10. Prof Nurse Shortage | AK18: =#REF!+Table2[[#This Row],[Column21]] -> #REF!
B19: B.1.1 TEXAS Grants | C19: 325164261 | E19: 234373565 | G19: =SUM(C19,E19) -> 559537826 | H19: =SUM(D19,F19) -> 0 | I19: =[4]BSS!F12 -> 600000000 | K19: ='A - Baseline Request'!N13 -> 580782930 | L19: =[4]BSS!H12 -> 0 | M19: =[4]BSS!I12 -> 0 | N19: 0 | O19: =[4]BSS!H31 -> 40302661 | P19: =[4]BSS!I31 -> 0 | Q19: =SUM(O19:P19) -> 40302661 | T19: =N19/(SUM(I19:J19)) -> 0 | U19: =Q19/SUM(I19:J19) -> 0.067171102 | V19: =(N19+Q19)/(I19+J19) -> 0.067171102 | W19: =W18+#REF!+#REF! -> #REF! | X19: =W19/(G$38+H$38) -> #REF! | Z19: 13 | AA19: B.1.3 Tuition Equalization Grants | AB19: ='A - Baseline Request'!N15 -> 168845654 | AC19: =[3]Reductions!$Q$11 -> 9703951 | AD19: =Table2[[#This Row],[Column17]]/Table2[[#This Row],[Column112]] -> 0.057472317 | AH19: D.1.5. Joint Admiss Md Pro | AK19: =T17+Table2[[#This Row],[Column21]] -> 0.10747232
B20: B.1.3 Tuition Equalization Grants | C20: 12030800 | E20: 12030800 | G20: =SUM(C20,E20) -> 24061600 | H20: =SUM(D20,F20) -> 0 | I20: 168845954 | K20: ='A - Baseline Request'!N15 -> 168845654 | L20: 15273669 | M20: =[4]BSS!I13 -> 0 | N20: 0 | O20: =[6]BSS!$H$33 -> 15273669 | P20: =[4]BSS!I32 -> 0 | Q20: =SUM(O20:P20) -> 15273669 | T20: =N20/(SUM(I20:J20)) -> 0 | U20: =Q20/SUM(I20:J20) -> 0.090459195 | V20: =(N20+Q20)/(I20+J20) -> 0.090459195 | W20: =#REF!+#REF!+#REF! -> #REF! | X20: =W20/(G$38+H$38) -> #REF! | Z20: 14 | AA20: B.1.4. Texas Educational Opp. Grnt Prg | AB20: ='A - Baseline Request'!N16 -> 65349388 | AC20: =[3]Reductions!$Q$12 -> 3755781 | AD20: =Table2[[#This Row],[Column17]]/Table2[[#This Row],[Column112]] -> 0.057472321 | AH20: C.1.2. TX Research Incentive Pro | AK20: =T16+Table2[[#This Row],[Column21]] -> 0.10747227
B21: B.1.4. Texas Educational Opp. Grnt Prg | C21: 84422827 | E21: 84422827 | G21: =SUM(C21,E21) -> 168845654 | H21: =SUM(D21,F21) -> 0 | I21: 58649087 | K21: ='A - Baseline Request'!N16 -> 65349388 | N21: =L21+M21 -> 0 | Q21: =SUM(O21:P21) -> 0 | T21: 0 | W21: =W20+#REF!+#REF! -> #REF! | X21: =W21/(G$38+H$38) -> #REF! | Z21: 15 | AA21: B.1.1 TEXAS Grants | AB21: ='A - Baseline Request'!N13 -> 580782930 | AC21: =[3]Reductions!$Q$9 -> 33378940 | AD21: =Table2[[#This Row],[Column17]]/Table2[[#This Row],[Column112]] -> 0.057472316 | AH21: B.1.3 Tuition Equalization Grants | AK21: =#REF!+Table2[[#This Row],[Column21]] -> #REF!
B22: B.1.5 College Work Study | C22: 7529639 | E22: 7529639 | G22: =SUM(C22,E22) -> 15059278 | H22: =SUM(D22,F22) -> 0 | I22: 30000000 | K22: ='A - Baseline Request'!N17 -> 15059278 | L22: =[4]BSS!H16 -> 0 | M22: =[4]BSS!I16 -> 0 | N22: =L22+M22 -> 0 | O22: =[4]BSS!H35 -> 0 | P22: =[4]BSS!I35 -> 0 | Q22: =SUM(O22:P22) -> 0 | T22: =N22/(SUM(I22:J22)) -> 0 | U22: =Q22/SUM(I22:J22) -> 0 | V22: =(N22+Q22)/(I22+J22) -> 0 | W22: =#REF!+N19+Q19 -> #REF! | X22: =W22/(G$38+H$38) -> #REF! | AA22: B.1.2 Texas B-On-Time | AB22: ='A - Baseline Request'!N14 -> 80557791 | AC22: 0 | AD22: =Table2[[#This Row],[Column17]]/Table2[[#This Row],[Column112]] -> 0 | AH22: B.1.4. Texas Educational Opp. Grnt Prg | AK22: =#REF!+Table2[[#This Row],[Column21]] -> #REF!
B23: B.1.6. License Plate Scholarships | C23: 0 | D23: 542000 | F23: 557000 | G23: =SUM(C23,E23) -> 0 | H23: =SUM(D23,F23) -> 1099000 | J23: =[4]BSS!G8 -> 1099000 | K23: =SUM(Table1[[#This Row],[Column10]:[Column11]]) -> 1099000 | L23: =[4]BSS!H8 -> 0 | M23: =[4]BSS!I8 -> 0 | N23: =L23+M23 -> 0 | O23: =[4]BSS!H27 -> 0 | P23: =[4]BSS!I27 -> 0 | Q23: =SUM(O23:P23) -> 0 | R23: 0 | S23: 0 | T23: =N23/(SUM(I23:J23)) -> 0 | U23: =Q23/SUM(I23:J23) -> 0 | V23: =(N23+Q23)/(I23+J23) -> 0 | W23: =#REF!+N26+Q26 -> #REF! | X23: =W23/(G$38+H$38) -> #REF! | AA23: B.1.5 College Work Study | AB23: ='A - Baseline Request'!N17 -> 15059278 | AC23: 0 | AD23: =Table2[[#This Row],[Column17]]/Table2[[#This Row],[Column112]] -> 0 | AH23: B.1.1 TEXAS Grants | AK23: =+#REF!+Table2[[#This Row],[Column21]] -> #REF!
B24: B.1.10. Teach for TX LRP | C24: 500000 | E24: 500000 | G24: =SUM(C24,E24) -> 1000000 | H24: =SUM(D24,F24) -> 0 | I24: =[4]BSS!F9 -> 10000000 | K24: ='A - Baseline Request'!N23 -> 1000000 | N24: =L24+M24 -> 0 | Q24: =SUM(O24:P24) -> 0 | T24: 0 | W24: =W30+#REF!+#REF! -> #REF! | X24: =W24/(G$38+H$38) -> #REF! | AA24: B.1.6. License Plate Scholarships | AB24: ='A - Baseline Request'!N18 -> 1099000 | AC24: 0 | AD24: =Table2[[#This Row],[Column17]]/Table2[[#This Row],[Column112]] -> 0 | AH24: B.1.2 Texas B-On-Time | AK24: 0
B25: B.1.11. Border Faculty LRP | C25: 187813 | E25: 187813 | G25: =SUM(C25,E25) -> 375626 | H25: =SUM(D25,F25) -> 0 | I25: =[4]BSS!F10 -> 375626 | K25: =SUM(Table1[[#This Row],[Column10]:[Column11]]) -> 375626 | L25: =[4]BSS!H10 -> 0 | M25: =[4]BSS!I10 -> 0 | N25: =L25+M25 -> 0 | O25: =[4]BSS!H29 -> 375626 | P25: =[4]BSS!I29 -> 0 | Q25: =SUM(O25:P25) -> 375626 | R25: 0 | S25: 0 | T25: =N25/(SUM(I25:J25)) -> 0 | U25: =Q25/SUM(I25:J25) -> 1 | V25: =(N25+Q25)/(I25+J25) -> 1 | W25: =#REF!+N22+Q22 -> #REF! | X25: =W25/(G$38+H$38) -> #REF! | AA25: B.1.10. Teach for TX LRP | AB25: ='A - Baseline Request'!N23 -> 1000000 | AC25: 0 | AD25: =Table2[[#This Row],[Column17]]/Table2[[#This Row],[Column112]] -> 0 | AH25: B.1.5 College Work Study | AK25: 0
B26: B.1.12. OAG Lawyers LRP | C26: 248036 | E26: 248036 | G26: =SUM(C26,E26) -> 496072 | H26: =SUM(D26,F26) -> 0 | I26: =[4]BSS!F11 -> 496072 | K26: =SUM(Table1[[#This Row],[Column10]:[Column11]]) -> 496072 | L26: =[4]BSS!H11 -> 0 | M26: =[4]BSS!I11 -> 0 | N26: =L26+M26 -> 0 | O26: =[4]BSS!H30 -> 0 | P26: =[4]BSS!I30 -> 0 | Q26: =SUM(O26:P26) -> 0 | R26: 0 | S26: 0 | T26: =N26/(SUM(I26:J26)) -> 0 | U26: =Q26/SUM(I26:J26) -> 0 | V26: =(N26+Q26)/(I26+J26) -> 0 | W26: =W25+#REF!+#REF! -> #REF! | X26: =W26/(G$38+H$38) -> #REF! | AA26: B.1.12. OAG Lawyers LRP | AB26: =SUM(Table1[[#This Row],[Column10]:[Column11]]) -> 496072 | AC26: 0 | AD26: =Table2[[#This Row],[Column17]]/Table2[[#This Row],[Column112]] -> 0 | AH26: B.1.6. License Plate Scholarships | AK26: 0
B27: B.1.15. Top 10% Scholarships | C27: 21862446 | E27: 17762446 | G27: =SUM(C27,E27) -> 39624892 | H27: =SUM(D27,F27) -> 0 | I27: =[4]BSS!F17 -> 8500000 | K27: =SUM(Table1[[#This Row],[Column10]:[Column11]]) -> 8500000 | L27: =[4]BSS!H17 -> 0 | M27: =[4]BSS!I17 -> 0 | N27: =L27+M27 -> 0 | O27: =[4]BSS!H36 -> 0 | P27: =[4]BSS!I36 -> 0 | Q27: =SUM(O27:P27) -> 0 | R27: 0 | S27: 0 | T27: =N27/(SUM(I27:J27)) -> 0 | U27: =Q27/SUM(I27:J27) -> 0 | V27: =(N27+Q27)/(I27+J27) -> 0 | W27: =#REF!+N25+Q25 -> #REF! | X27: =W27/(G$38+H$38) -> #REF! | AA27: B.1.15. Top 10% Scholarships | AB27: =SUM(Table1[[#This Row],[Column10]:[Column11]]) -> 8500000 | AC27: 0 | AD27: =Table2[[#This Row],[Column17]]/Table2[[#This Row],[Column112]] -> 0 | AH27: B.1.10. Teach for TX LRP | AK27: =#REF!+Table2[[#This Row],[Column21]] -> #REF!
B28: B.1.16. Armed Services Scholarships | C28: 3560000 | E28: 3560000 | G28: =SUM(C28,E28) -> 7120000 | H28: =SUM(D28,F28) -> 0 | I28: =[4]BSS!F18 -> 4220000 | K28: ='[3]In and Out Base '!$S$22 -> 7120000 | L28: =[4]BSS!H18 -> 0 | M28: =[4]BSS!I18 -> 0 | N28: =L28+M28 -> 0 | O28: =[4]BSS!H37 -> 0 | P28: =[4]BSS!I37 -> 0 | Q28: =SUM(O28:P28) -> 0 | R28: 1.9 | S28: 1.9 | T28: =N28/(SUM(I28:J28)) -> 0 | U28: =Q28/SUM(I28:J28) -> 0 | V28: =(N28+Q28)/(I28+J28) -> 0 | W28: =W27+#REF!+#REF! -> #REF! | X28: =W28/(G$38+H$38) -> #REF! | AA28: B.1.16. Armed Services Scholarships | AB28: ='A - Baseline Request'!N29 -> 7120000 | AC28: 0 | AD28: =Table2[[#This Row],[Column17]]/Table2[[#This Row],[Column112]] -> 0 | AH28: B.1.12. OAG Lawyers LRP | AK28: 0
B29: C.1.1. Advanced Research Pro | C29: 1000000 | E29: 0 | G29: =SUM(C29,E29) -> 1000000 | H29: =SUM(D29,F29) -> 0 | I29: =[4]WAAR!F10 -> 3000000 | K29: ='A - Baseline Request'!N34 -> 1000000 | L29: =[4]WAAR!H10 -> 0 | M29: =[4]WAAR!I10 -> 0 | N29: =L29+M29 -> 0 | O29: =[4]WAAR!H24 -> 0 | P29: =[4]WAAR!I24 -> 0 | Q29: =SUM(O29:P29) -> 0 | R29: 0 | S29: 0 | T29: =N29/(SUM(I29:J29)) -> 0 | U29: =Q29/SUM(I29:J29) -> 0 | V29: =(N29+Q29)/(I29+J29) -> 0 | W29: =W23+N27+Q27 -> #REF! | X29: =W29/(G$38+H$38) -> #REF! | AA29: C.1.1. Advanced Research Pro | AB29: ='A - Baseline Request'!N34 -> 1000000 | AC29: 0 | AD29: =Table2[[#This Row],[Column17]]/Table2[[#This Row],[Column112]] -> 0 | AH29: B.1.15. Top 10% Scholarships | AK29: =0 -> 0
B30: D.1.1. Family Practice Res Pro | C30: 2800000 | E30: 2800000 | G30: =SUM(C30,E30) -> 5600000 | H30: =SUM(D30,F30) -> 0 | I30: =[4]WAAR!F11 -> 7600000 | K30: ='A - Baseline Request'!N37 -> 9600000 | L30: =[4]WAAR!H11 -> 0 | M30: =[4]WAAR!I11 -> 0 | N30: =L30+M30 -> 0 | O30: =[4]WAAR!H25 -> 0 | P30: =[4]WAAR!I25 -> 0 | Q30: =SUM(O30:P30) -> 0 | R30: 0 | S30: 0 | T30: =N30/(SUM(I30:J30)) -> 0 | U30: =Q30/SUM(I30:J30) -> 0 | V30: =(N30+Q30)/(I30+J30) -> 0 | W30: =W29+#REF!+#REF! -> #REF! | X30: =W30/(G$38+H$38) -> #REF! | AA30: D.1.1. Family Practice Res Pro | AB30: ='A - Baseline Request'!N37 -> 9600000 | AC30: 0 | AD30: =Table2[[#This Row],[Column17]]/Table2[[#This Row],[Column112]] -> 0 | AH30: B.1.16. Armed Services Scholarships | AK30: 0
B31: D.1.6. Physician Ed Loan Repay | C31: 0 | D31: 5600000 | G31: =SUM(C31,E31) -> 0 | H31: =SUM(D31,F31) -> 5600000 | J31: =[4]BSS!G19 -> 5600000 | K31: =SUM(Table1[[#This Row],[Column10]:[Column11]]) -> 5600000 | L31: =[4]BSS!H19 -> 0 | M31: =[4]BSS!I19 -> 0 | N31: =L31+M31 -> 0 | O31: =[4]BSS!H38 -> 0 | P31: =[4]BSS!I38 -> 0 | Q31: =SUM(O31:P31) -> 0 | R31: 0 | S31: 0 | T31: =N31/(SUM(I31:J31)) -> 0 | U31: =Q31/SUM(I31:J31) -> 0 | V31: =(N31+Q31)/(I31+J31) -> 0 | W31: =#REF!+N29+Q29 -> #REF! | X31: =W31/(G$38+H$38) -> #REF! | AA31: D.1.6. Physician Ed Loan Repay | AB31: =SUM(Table1[[#This Row],[Column10]:[Column11]]) -> 5600000 | AC31: 0 | AD31: =Table2[[#This Row],[Column17]]/Table2[[#This Row],[Column112]] -> 0 | AH31: C.1.1. Adv Research Pro | AK31: 0
B32: E.1.1. Baylor Col of Med - UGME | C32: 40123625 | E32: 35741187 | G32: =SUM(C32,E32) -> 75864812 | H32: =SUM(D32,F32) -> 0 | I32: =[4]PIE!F10 -> 75864812 | K32: 0 | N32: =L32+M32 -> 0 | Q32: =SUM(O32:P32) -> 0 | T32: 0 | W32: =W31+#REF!+#REF! -> #REF! | X32: =W32/(G$38+H$38) -> #REF! | AA32: E.1.1. Baylor Col of Med - UGME | AB32: 0 | AD32: 0 | AH32: D.1.1. Fam Pract Res Pro | AK32: 0
B33: E.1.2. Baylor Col of Med - GME | C33: 5176507 | E33: 5176507 | G33: =SUM(C33,E33) -> 10353014 | H33: =SUM(D33,F33) -> 0 | I33: =[4]PIE!F11 -> 10353014 | K33: 0 | N33: =L33+M33 -> 0 | Q33: =SUM(O33:P33) -> 0 | T33: 0 | W33: =#REF!+#REF!+#REF! -> #REF! | X33: =W33/(G$38+H$38) -> #REF! | AA33: E.1.2. Baylor Col of Med - GME | AB33: 0 | AD33: 0 | AH33: D.1.6. Physician Ed Loan Repay | AK33: 0
B34: F.1.1. Developmental Ed Program | C34: 2000000 | E34: 2000000 | G34: =SUM(C34,E34) -> 4000000 | H34: =SUM(D34,F34) -> 0 | I34: =[4]P16!F10 -> 4000000 | K34: =SUM(Table1[[#This Row],[Column10]:[Column11]]) -> 4000000 | L34: =[4]P16!H10 -> 0 | M34: =[4]P16!I10 -> 0 | N34: =L34+M34 -> 0 | O34: =[4]P16!H21 -> 0 | P34: =[4]P16!I21 -> 0 | Q34: =SUM(O34:P34) -> 0 | R34: 0 | S34: 0 | T34: =N34/(SUM(I34:J34)) -> 0 | U34: =Q34/SUM(I34:J34) -> 0 | V34: =(N34+Q34)/(I34+J34) -> 0 | W34: =#REF!+N34+Q34 -> #REF! | X34: =W34/(G$38+H$38) -> #REF! | AA34: F.1.1. Developmental Ed Program | AB34: =SUM(Table1[[#This Row],[Column10]:[Column11]]) -> 4000000 | AC34: 0 | AD34: =Table2[[#This Row],[Column17]]/Table2[[#This Row],[Column112]] -> 0 | AH34: D.1.11. Alzheimer's Dis Cen | AK34: =T7 -> 0.14821333
