Workbook

Sheet Instructions
B6: DO NOT DOWNLOAD THIS FORM!
B7: Presumptive Medicaid Trial Eligibility Tool Instructions
B9: The following information is the instructions for completing the Presumptive Medicaid Trial Eligibility Tool.
B10: Questions section:
B11: Answer each question that displays as it pertains to the patient.
B13: Household Members and Income List:
B14: List all household members that are related to the patient as long as they are the parent, the spouse, a related child under 19, the sibling (if patient and sibling are both under 19) or anyone that will be included in the same tax filing household as the patient. List the income received by those members excluding Child Support, Workman's Compensation, Student Financial Aid and Veterans income paid by a Veterans agency. If anyone listed is pregnant, add the unborn(s) to the list of members, enter $0.00 as the amount of income and "None" for the frequency. If a household member has no income, enter $0.00 as the income amount and "None" for the frequency. Use the "Multiple Income Calculator Job Aid" to calculate monthly income when a member has income from multiple sources paid at different frequencies. Use the "Total Monthly Income" amount to complete the Household Member and Income List for the member. If more than one member has multiple income sources paid at different frequencies, clear the contents and complete the "Multiple Income Calculator Job Aid" for each member this applies to. Once all household members and their income are listed, the tool will indicate if the patient may be eligible for Medicaid. Click on the Presumptive Eligibility Tab to complete the Presumptive Medicaid Trail Eligibility Tool.

Sheet Presumptive Eligibility
B5: DO NOT DOWNLOAD THIS FORM!
B6: Presumptive Medicaid Trial Eligibility Tool
B8: If the patient is under 26 and received Idaho Medicaid thru the foster care program on their 18th birthday, they are eligible for Presumptive Eligibility. They do not have an income test, automatically send these customers for Presumptive Eligibility.
B9: Question Section: Please answer the following questions as they pertain to the patient.
B10: Do they have a related child, under the age 18, living with them?
B11: Are they pregnant?
B12: Are they under 19 years old?
B14: =IF(H10="",Calculations!A10,IF(H10="Yes",Calculations!A11,IF(D11="",Calculations!A10,IF(D11="Yes",Calculations!A11,IF(E12="",Calculations!A10,IF(E12="Yes",Calculations!A11,IF(E12="No",Calculations!A9,IF(H10="No",Calculations!A10,IF(D11="No",Calculations!A10,""))))))))) -> Please complete the highlighted question.
B16: Household Members and Income List: Please tell us about the members in the patients household and their income.
B18: Name | F18: Household Members Income | I18: Frequency
B35: Total Household Members: | E35: =COUNTA(B20:E34) -> 0 | F35: Total Monthly Income: | I35: =SUM(Calculations!A24:A38) -> 0
B37: Results:
B38: =IF(ISNUMBER(SEARCH("not",B14)),Calculations!A9,IF(ISNUMBER(SEARCH("name",Calculations!A63)),Calculations!A63,IF(ISNUMBER(SEARCH("name",Calculations!A64)),Calculations!A64,IF(ISNUMBER(SEARCH("name",Calculations!A65)),Calculations!A65,IF(ISNUMBER(SEARCH("name",Calculations!A66)),Calculations!A66,IF(ISNUMBER(SEARCH("name",Calculations!A67)),Calculations!A67,IF(ISNUMBER(SEARCH("name",Calculations!A68)),Calculations!A68,IF(ISNUMBER(SEARCH("name",Calculations!A69)),Calculations!A69,IF(ISNUMBER(SEARCH("name",Calculations!A70)),Calculations!A70,IF(ISNUMBER(SEARCH("name",Calculations!A71)),Calculations!A71,IF(ISNUMBER(SEARCH("name",Calculations!A72)),Calculations!A72,IF(ISNUMBER(SEARCH("name",Calculations!A73)),Calculations!A73,IF(ISNUMBER(SEARCH("name",Calculations!A74)),Calculations!A74,IF(ISNUMBER(SEARCH("name",Calculations!A75)),Calculations!A75,IF(ISNUMBER(SEARCH("name",Calculations!A76)),Calculations!A76,IF(ISNUMBER(SEARCH("name",Calculations!A77)),Calculations!A77,IF(AND(E35>0,I35=0),Calculations!A7,IF(Calculations!A22>I35,Calculations!A7,IF(Calculations!A22<I35,Calculations!A8,IF(B14=Calculations!A10,Calculations!A10,IF(B14=Calculations!A11,Calculations!A11,IF(B20="",Calculations!A11,IF(I35=0,""))))))))))))))))))))))) -> Please complete the highlighted question.
B40: Household Size | C40: Maximum Adult Income Limit | D40: Pregnant Woman Income Limit | E40: Maximum Child Income Limit
B41: 1 | C41: 205 | D41: 1273 | E41: 1771
B42: 2 | C42: 251 | D42: 1719 | E42: 2391
B43: 3 | C43: 317 | D43: 2165 | E43: 3011
B44: 4 | C44: 382 | D44: 2610 | E44: 3631
B45: 5 | C45: 448 | D45: 3056 | E45: 4250
B46: 6 | C46: 513 | D46: 3501 | E46: 4870
B47: 7 | C47: 579 | D47: 3947 | E47: 5490
B48: 8 | C48: 645 | D48: 4392 | E48: 6110
B49: 9 | C49: 710 | D49: 4838 | E49: 6730
B50: 10 | C50: 775 | D50: 5284 | E50: 7350
B51: 11 | C51: 840 | D51: 5730 | E51: 7970
B52: 12 | C52: 905 | D52: 6176 | E52: 8590
... B55: 15 | C55: 1100 | D55: 7514 | E55: 10450
B57: Click on the Instructions Tab to return to the Instructions page.

Sheet Calculations
A2: Yes
A3: No
A5: Are they pregnant?
A6: Are they under 19 years old?
A7: This person may be eligible for Medicaid.
A8: This person would not be eligible for Medicaid
A9: This person does not qualify for presumptive eligibility.
A10: Please complete the highlighted question.
A11: Please tell us about each household member and their income.
A13: None | B13: *0
A14: Annually | B14: /12
A15: Bi-Weekly | B15: *2.15
A16: Monthly
A17: Quarterly | B17: /3
A18: Semi-Annually | B18: /6
A19: Semi-Monthly | B19: *2
A20: Weekly | B20: *4.3
A22: =SUMIF(A45:A60,'Presumptive Eligibility'!E35,Calculations!I45:I60) -> 0
A24: =IF('Presumptive Eligibility'!I20=$A$13,'Presumptive Eligibility'!F20*0,(IF('Presumptive Eligibility'!I20=$A$15,'Presumptive Eligibility'!F20*2.15,IF('Presumptive Eligibility'!I20=$A$14,'Presumptive Eligibility'!F20/12,IF('Presumptive Eligibility'!I20=$A$16,'Presumptive Eligibility'!F20,IF('Presumptive Eligibility'!I20=$A$17,'Presumptive Eligibility'!F20/3,IF('Presumptive Eligibility'!I20=$A$18,'Presumptive Eligibility'!F20/6,IF('Presumptive Eligibility'!I20=$A$19,'Presumptive Eligibility'!F20*2,IF('Presumptive Eligibility'!I20=$A$20,'Presumptive Eligibility'!F20*4.3,"")))))))))
A25: =IF('Presumptive Eligibility'!I21=$A$13,'Presumptive Eligibility'!F21*0,(IF('Presumptive Eligibility'!I21=$A$15,'Presumptive Eligibility'!F21*2.15,IF('Presumptive Eligibility'!I21=$A$14,'Presumptive Eligibility'!F21/12,IF('Presumptive Eligibility'!I21=$A$16,'Presumptive Eligibility'!F21,IF('Presumptive Eligibility'!I21=$A$17,'Presumptive Eligibility'!F21/3,IF('Presumptive Eligibility'!I21=$A$18,'Presumptive Eligibility'!F21/6,IF('Presumptive Eligibility'!I21=$A$19,'Presumptive Eligibility'!F21*2,IF('Presumptive Eligibility'!I21=$A$20,'Presumptive Eligibility'!F21*4.3,"")))))))))
A26: =IF('Presumptive Eligibility'!I22=$A$13,'Presumptive Eligibility'!F22*0,(IF('Presumptive Eligibility'!I22=$A$15,'Presumptive Eligibility'!F22*2.15,IF('Presumptive Eligibility'!I22=$A$14,'Presumptive Eligibility'!F22/12,IF('Presumptive Eligibility'!I22=$A$16,'Presumptive Eligibility'!F22,IF('Presumptive Eligibility'!I22=$A$17,'Presumptive Eligibility'!F22/3,IF('Presumptive Eligibility'!I22=$A$18,'Presumptive Eligibility'!F22/6,IF('Presumptive Eligibility'!I22=$A$19,'Presumptive Eligibility'!F22*2,IF('Presumptive Eligibility'!I22=$A$20,'Presumptive Eligibility'!F22*4.3,"")))))))))
A27: =IF('Presumptive Eligibility'!I23=$A$13,'Presumptive Eligibility'!F23*0,(IF('Presumptive Eligibility'!I23=$A$15,'Presumptive Eligibility'!F23*2.15,IF('Presumptive Eligibility'!I23=$A$14,'Presumptive Eligibility'!F23/12,IF('Presumptive Eligibility'!I23=$A$16,'Presumptive Eligibility'!F23,IF('Presumptive Eligibility'!I23=$A$17,'Presumptive Eligibility'!F23/3,IF('Presumptive Eligibility'!I23=$A$18,'Presumptive Eligibility'!F23/6,IF('Presumptive Eligibility'!I23=$A$19,'Presumptive Eligibility'!F23*2,IF('Presumptive Eligibility'!I23=$A$20,'Presumptive Eligibility'!F23*4.3,"")))))))))
A28: =IF('Presumptive Eligibility'!I24=$A$13,'Presumptive Eligibility'!F24*0,(IF('Presumptive Eligibility'!I24=$A$15,'Presumptive Eligibility'!F24*2.15,IF('Presumptive Eligibility'!I24=$A$14,'Presumptive Eligibility'!F24/12,IF('Presumptive Eligibility'!I24=$A$16,'Presumptive Eligibility'!F24,IF('Presumptive Eligibility'!I24=$A$17,'Presumptive Eligibility'!F24/3,IF('Presumptive Eligibility'!I24=$A$18,'Presumptive Eligibility'!F24/6,IF('Presumptive Eligibility'!I24=$A$19,'Presumptive Eligibility'!F24*2,IF('Presumptive Eligibility'!I24=$A$20,'Presumptive Eligibility'!F24*4.3,"")))))))))
A29: =IF('Presumptive Eligibility'!I25=$A$13,'Presumptive Eligibility'!F25*0,(IF('Presumptive Eligibility'!I25=$A$15,'Presumptive Eligibility'!F25*2.15,IF('Presumptive Eligibility'!I25=$A$14,'Presumptive Eligibility'!F25/12,IF('Presumptive Eligibility'!I25=$A$16,'Presumptive Eligibility'!F25,IF('Presumptive Eligibility'!I25=$A$17,'Presumptive Eligibility'!F25/3,IF('Presumptive Eligibility'!I25=$A$18,'Presumptive Eligibility'!F25/6,IF('Presumptive Eligibility'!I25=$A$19,'Presumptive Eligibility'!F25*2,IF('Presumptive Eligibility'!I25=$A$20,'Presumptive Eligibility'!F25*4.3,"")))))))))
A30: =IF('Presumptive Eligibility'!I26=$A$13,'Presumptive Eligibility'!F26*0,(IF('Presumptive Eligibility'!I26=$A$15,'Presumptive Eligibility'!F26*2.15,IF('Presumptive Eligibility'!I26=$A$14,'Presumptive Eligibility'!F26/12,IF('Presumptive Eligibility'!I26=$A$16,'Presumptive Eligibility'!F26,IF('Presumptive Eligibility'!I26=$A$17,'Presumptive Eligibility'!F26/3,IF('Presumptive Eligibility'!I26=$A$18,'Presumptive Eligibility'!F26/6,IF('Presumptive Eligibility'!I26=$A$19,'Presumptive Eligibility'!F26*2,IF('Presumptive Eligibility'!I26=$A$20,'Presumptive Eligibility'!F26*4.3,"")))))))))
A31: =IF('Presumptive Eligibility'!I27=$A$13,'Presumptive Eligibility'!F27*0,(IF('Presumptive Eligibility'!I27=$A$15,'Presumptive Eligibility'!F27*2.15,IF('Presumptive Eligibility'!I27=$A$14,'Presumptive Eligibility'!F27/12,IF('Presumptive Eligibility'!I27=$A$16,'Presumptive Eligibility'!F27,IF('Presumptive Eligibility'!I27=$A$17,'Presumptive Eligibility'!F27/3,IF('Presumptive Eligibility'!I27=$A$18,'Presumptive Eligibility'!F27/6,IF('Presumptive Eligibility'!I27=$A$19,'Presumptive Eligibility'!F27*2,IF('Presumptive Eligibility'!I27=$A$20,'Presumptive Eligibility'!F27*4.3,"")))))))))
A32: =IF('Presumptive Eligibility'!I28=$A$13,'Presumptive Eligibility'!F28*0,(IF('Presumptive Eligibility'!I28=$A$15,'Presumptive Eligibility'!F28*2.15,IF('Presumptive Eligibility'!I28=$A$14,'Presumptive Eligibility'!F28/12,IF('Presumptive Eligibility'!I28=$A$16,'Presumptive Eligibility'!F28,IF('Presumptive Eligibility'!I28=$A$17,'Presumptive Eligibility'!F28/3,IF('Presumptive Eligibility'!I28=$A$18,'Presumptive Eligibility'!F28/6,IF('Presumptive Eligibility'!I28=$A$19,'Presumptive Eligibility'!F28*2,IF('Presumptive Eligibility'!I28=$A$20,'Presumptive Eligibility'!F28*4.3,"")))))))))
A33: =IF('Presumptive Eligibility'!I29=$A$13,'Presumptive Eligibility'!F29*0,(IF('Presumptive Eligibility'!I29=$A$15,'Presumptive Eligibility'!F29*2.15,IF('Presumptive Eligibility'!I29=$A$14,'Presumptive Eligibility'!F29/12,IF('Presumptive Eligibility'!I29=$A$16,'Presumptive Eligibility'!F29,IF('Presumptive Eligibility'!I29=$A$17,'Presumptive Eligibility'!F29/3,IF('Presumptive Eligibility'!I29=$A$18,'Presumptive Eligibility'!F29/6,IF('Presumptive Eligibility'!I29=$A$19,'Presumptive Eligibility'!F29*2,IF('Presumptive Eligibility'!I29=$A$20,'Presumptive Eligibility'!F29*4.3,"")))))))))
A34: =IF('Presumptive Eligibility'!I30=$A$13,'Presumptive Eligibility'!F30*0,(IF('Presumptive Eligibility'!I30=$A$15,'Presumptive Eligibility'!F30*2.15,IF('Presumptive Eligibility'!I30=$A$14,'Presumptive Eligibility'!F30/12,IF('Presumptive Eligibility'!I30=$A$16,'Presumptive Eligibility'!F30,IF('Presumptive Eligibility'!I30=$A$17,'Presumptive Eligibility'!F30/3,IF('Presumptive Eligibility'!I30=$A$18,'Presumptive Eligibility'!F30/6,IF('Presumptive Eligibility'!I30=$A$19,'Presumptive Eligibility'!F30*2,IF('Presumptive Eligibility'!I30=$A$20,'Presumptive Eligibility'!F30*4.3,"")))))))))
A35: =IF('Presumptive Eligibility'!I31=$A$13,'Presumptive Eligibility'!F31*0,(IF('Presumptive Eligibility'!I31=$A$15,'Presumptive Eligibility'!F31*2.15,IF('Presumptive Eligibility'!I31=$A$14,'Presumptive Eligibility'!F31/12,IF('Presumptive Eligibility'!I31=$A$16,'Presumptive Eligibility'!F31,IF('Presumptive Eligibility'!I31=$A$17,'Presumptive Eligibility'!F31/3,IF('Presumptive Eligibility'!I31=$A$18,'Presumptive Eligibility'!F31/6,IF('Presumptive Eligibility'!I31=$A$19,'Presumptive Eligibility'!F31*2,IF('Presumptive Eligibility'!I31=$A$20,'Presumptive Eligibility'!F31*4.3,"")))))))))
... A38: =IF('Presumptive Eligibility'!I34=$A$13,'Presumptive Eligibility'!F34*0,(IF('Presumptive Eligibility'!I34=$A$15,'Presumptive Eligibility'!F34*2.15,IF('Presumptive Eligibility'!I34=$A$14,'Presumptive Eligibility'!F34/12,IF('Presumptive Eligibility'!I34=$A$16,'Presumptive Eligibility'!F34,IF('Presumptive Eligibility'!I34=$A$17,'Presumptive Eligibility'!F34/3,IF('Presumptive Eligibility'!I34=$A$18,'Presumptive Eligibility'!F34/6,IF('Presumptive Eligibility'!I34=$A$19,'Presumptive Eligibility'!F34*2,IF('Presumptive Eligibility'!I34=$A$20,'Presumptive Eligibility'!F34*4.3,"")))))))))
B41: Title XIX Rules | C41: Title XIX Rules | D41: Title XIX Rules | E41: 88 Basic | F41: 67 Pregnancy | G41: 60 Basic | H41: 86 Basic | I41: 80 Basic
B42: 82 Basic | C42: Need DRA | D42: Need DRA | E42: 89 Enhanced | F42: Title XIX Rules | G42: 63 Enhanced | H42: 87 Enhanced | I42: 81 Enhanced
B43: 83 Enhanced | E43: Title XIX Rules | F43: Need DRA | G43: Age 6-19 | H43: 76 Access | I43: 71 Access
B44: Need DRA | E44: Need DRA | G44: Title XXI Rules | H44: Title XXI Rules | I44: Title XXI Rules
A45: 1 | B45: 205 | C45: 643 | D45: 1190 | E45: 958 | F45: 1273 | G45: 958 – 1273 | H45: 1436 | I45: 1771
A46: 2 | B46: 251 | C46: 786 | D46: 1454 | E46: 1293 | F46: 1719 | G46: 1293 - 1719 | H46: 1939 | I46: 2391
A47: 3 | B47: 317 | C47: 991 | D47: 1833 | E47: 1628 | F47: 2165 | G47: 1628 - 2165 | H47: 2441 | I47: 3011
A48: 4 | B48: 382 | C48: 1196 | D48: 2213 | E48: 1963 | F48: 2610 | G48: 1963 - 2610 | H48: 2944 | I48: 3631
A49: 5 | B49: 448 | C49: 1401 | D49: 2592 | E49: 2298 | F49: 3056 | G49: 2298 - 3056 | H49: 3446 | I49: 4250
...
