Workbook

Sheet IS
A1: X | B1: Dell Incorporated
B2: Income Statement
B3: FY Ended Feb. 3
B4: $ in Millions
C5: 2008 | D5: =C5+1 -> 2009 | E5: =D5+1 -> 2010 | F5: =E5+1 -> 2011 | G5: =F5+1 -> 2012 | H5: 2013E | I5: 2014E | J5: 2015E | K5: 2016E | L5: 2017E
B6: Net Revenue:
B7: Products | C7: 53728 | D7: 52337 | E7: 43697 | F7: 50002 | G7: 49906 | H7: =H9-H8 -> 43892 | I7: =I9-I8 -> 42217 | J7: =J9-J8 -> 40431 | K7: =K9-K8 -> 39243 | L7: =L9-L8 -> 37970
B8: Services, Incl Software | C8: 7405 | D8: 8764 | E8: 9205 | F8: 11492 | G8: 12165 | H8: =(G8-F8)+G8 -> 12838 | I8: =(H8-G8)+H8 -> 13511 | J8: =(I8-H8)+I8 -> 14184 | K8: =(J8-I8)+J8 -> 14857 | L8: =(K8-J8)+K8 -> 15530
B9: Total Revenue | C9: =SUM(C7+C8) -> 61133 | D9: =SUM(D7+D8) -> 61101 | E9: =SUM(E7+E8) -> 52902 | F9: =SUM(F7+F8) -> 61494 | G9: =SUM(G7+G8) -> 62071 | H9: 56730 | I9: 55728 | J9: 54615 | K9: 54100 | L9: 53500
B11: Cost of Net Revenue:
B12: Products | C12: -45149 | D12: -44670 | E12: -37534 | F12: -42068 | G12: -39689 | H12: =H14*80% -> -36624.888 | I12: =I14*80% -> -35977.997 | J12: =J14*80% -> -35259.444 | K12: =K14*80% -> -34926.96 | L12: =L14*80% -> -34539.6
B13: Services, Incl Software | C13: -4313 | D13: -5474 | E13: -6107 | F13: -8030 | G13: -8571 | H13: =H14-H12 -> -9156.222 | I13: =I14-I12 -> -8994.4992 | J13: =J14-J12 -> -8814.861 | K13: =K14-K12 -> -8731.74 | L13: =L14-L12 -> -8634.9
B14: Total Cost of Revenue | C14: =SUM(C12:C13) -> -49462 | D14: =SUM(D12:D13) -> -50144 | E14: =SUM(E12:E13) -> -43641 | F14: =SUM(F12:F13) -> -50098 | G14: =SUM(G12:G13) -> -48260 | H14: =-(H9-H16) -> -45781.11 | I14: =-(I9-I16) -> -44972.496 | J14: =-(J9-J16) -> -44074.305 | K14: =-(K9-K16) -> -43658.7 | L14: =-(L9-L16) -> -43174.5
B16: Gross Margin | C16: =SUM(C9+C14) -> 11671 | D16: =SUM(D9+D14) -> 10957 | E16: =SUM(E9+E14) -> 9261 | F16: =SUM(F9+F14) -> 11396 | G16: =SUM(G9+G14) -> 13811 | H16: =H9*H36 -> 10948.89 | I16: =I9*I36 -> 10755.504 | J16: =J9*J36 -> 10540.695 | K16: =K9*K36 -> 10441.3 | L16: =L9*L36 -> 10325.5
B18: SG&A | C18: -7538 | D18: -7102 | E18: -6465 | F18: -7302 | G18: -8524 | H18: =-H9*H37 -> -7772.01 | I18: =-I9*I37 -> -7746.192 | J18: =-J9*J37 -> -7646.1 | K18: =-K9*K37 -> -7574 | L18: =-L9*L37 -> -7329.5
B19: RD&E | C19: -610 | D19: -663 | E19: -624 | F19: -661 | G19: -856 | H19: =-H9*1.5% -> -850.95 | I19: =-I9*1.5% -> -835.92 | J19: =-J9*2% -> -1092.3 | K19: =-K9*2% -> -1082 | L19: =-L9*2.5% -> -1337.5
B20: In-process R&D | C20: -83 | D20: -2 | E20: 0 | F20: 0 | G20: 0 | H20: 0 | I20: 0 | J20: 0 | K20: 0 | L20: 0
B21: Operating Expenses | C21: =SUM(C18:C20) -> -8231 | D21: =SUM(D18:D20) -> -7767 | E21: =SUM(E18:E20) -> -7089 | F21: =SUM(F18:F20) -> -7963 | G21: =SUM(G18:G20) -> -9380 | H21: =SUM(H18:H20) -> -8622.96 | I21: =SUM(I18:I20) -> -8582.112 | J21: =SUM(J18:J20) -> -8738.4 | ... L21: =SUM(L18:L20) -> -8667
B23: EBITDA | C23: =SUM(C16+C21-C24) -> 4047 | D23: =SUM(D16+D21-D24) -> 3959 | E23: =SUM(E16+E21-E24) -> 3024 | F23: =SUM(F16+F21-F24) -> 4403 | G23: =SUM(G16+G21-G24) -> 5367 | H23: =SUM(H16+H21-H24) -> 3176.88 | I23: =SUM(I16+I21-I24) -> 3009.312 | J23: =SUM(J16+J21-J24) -> 2621.52 | ... L23: =SUM(L16+L21-L24) -> 2461
B24: D&A | C24: -607 | D24: -769 | E24: -852 | F24: -970 | G24: -936 | H24: =-H9*1.5% -> -850.95 | I24: =-I9*1.5% -> -835.92 | J24: =-J9*1.5% -> -819.225 | K24: =-K9*1.5% -> -811.5 | L24: =-L9*1.5% -> -802.5
B26: Operating Income | C26: =SUM(C23+C24) -> 3440 | D26: =SUM(D23+D24) -> 3190 | E26: =SUM(E23+E24) -> 2172 | F26: =SUM(F23+F24) -> 3433 | G26: =SUM(G23+G24) -> 4431 | H26: =SUM(H23+H24) -> 2325.93 | I26: =SUM(I23+I24) -> 2173.392 | J26: =SUM(J23+J24) -> 1802.295 | ... L26: =SUM(L23+L24) -> 1658.5
B27: Interest and Other | C27: 387 | D27: 134 | E27: -148 | F27: -83 | G27: -191 | H27: -100 | I27: -100 | J27: 100 | K27: 150 | L27: 200
B28: Pretax Income | C28: =SUM(C26:C27) -> 3827 | D28: =SUM(D26:D27) -> 3324 | E28: =SUM(E26:E27) -> 2024 | F28: =SUM(F26:F27) -> 3350 | G28: =SUM(G26:G27) -> 4240 | H28: =SUM(H26:H27) -> 2225.93 | I28: =SUM(I26:I27) -> 2073.392 | J28: =SUM(J26:J27) -> 1902.295 | ... L28: =SUM(L26:L27) -> 1858.5
B30: Tax Provision | C30: -880 | D30: -846 | E30: -591 | F30: -715 | G30: -748 | H30: =-H28*25% -> -556.4825 | I30: =-I28*25% -> -518.348 | J30: =-J28*25% -> -475.57375 | K30: =-K28*35% -> -677.355 | L30: =-L28*35% -> -650.475
B31: Net Income | C31: =SUM(C28:C30) -> 2947 | D31: =SUM(D28:D30) -> 2478 | E31: =SUM(E28:E30) -> 1433 | F31: =SUM(F28:F30) -> 2635 | G31: =SUM(G28:G30) -> 3492 | H31: =SUM(H28:H30) -> 1669.4475 | I31: =SUM(I28:I30) -> 1555.044 | J31: =SUM(J28:J30) -> 1426.7213 | ... L31: =SUM(L28:L30) -> 1208.025
B32: Diluted Shares Outstanding | C32: 2247 | D32: 1986 | E32: 1962 | F32: 1955 | G32: 1853 | H32: 1600 | I32: 1550 | J32: 1500 | K32: 1450 | L32: 1400
B33: EPS | C33: =C31/C32 -> 1.3115265 | D33: =D31/D32 -> 1.2477341 | E33: =E31/E32 -> 0.73037717 | F33: =F31/F32 -> 1.3478261 | G33: =G31/G32 -> 1.8845116 | H33: =H31/H32 -> 1.0434047 | I33: =I31/I32 -> 1.0032542 | J33: =J31/J32 -> 0.9511475 | ... L33: =L31/L32 -> 0.862875
B35: Margin Analysis
B36: Gross Margin | C36: =C16/C9 -> 0.19091162 | D36: =D16/D9 -> 0.17932603 | E36: =E16/E9 -> 0.17505954 | F36: =F16/F9 -> 0.18531889 | G36: =G16/G9 -> 0.22250326 | H36: 0.193 | I36: 0.193 | J36: 0.193 | K36: 0.193 | L36: 0.193
B37: SG&A Expense / Revenue | C37: =-C18/C9 -> 0.12330493 | D37: =-D18/D9 -> 0.11623378 | E37: =-E18/E9 -> 0.1222071 | F37: =-F18/F9 -> 0.11874329 | G37: =-G18/G9 -> 0.13732661 | H37: 0.137 | I37: 0.139 | J37: 0.14 | K37: 0.14 | L37: 0.137
B38: EBITDA Margin | C38: =C23/C9 -> 0.066199925 | D38: =D23/D9 -> 0.064794357 | E38: =E23/E9 -> 0.0571623 | F38: =F23/F9 -> 0.071600481 | G38: =G23/G9 -> 0.086465499 | H38: =H23/H9 -> 0.056 | I38: =I23/I9 -> 0.054 | J38: =J23/J9 -> 0.048 | ... L38: =L23/L9 -> 0.046
B39: D&A / Revenue | C39: =-C24/C9 -> 0.0099291708 | D39: =-D24/D9 -> 0.012585719 | E39: =-E24/E9 -> 0.016105251 | F39: =-F24/F9 -> 0.015773897 | G39: =-G24/G9 -> 0.015079506 | H39: =-H24/H9 -> 0.015 | I39: =-I24/I9 -> 0.015 | J39: =-J24/J9 -> 0.015 | ... L39: =-L24/L9 -> 0.015
B41: Growth Rates
B42: Net Revenues | D42: =D9/C9-1 -> -0.00052344887 | E42: =E9/D9-1 -> -0.13418766 | F42: =F9/E9-1 -> 0.16241352 | G42: =G9/F9-1 -> 0.0093830292 | H42: =H9/G9-1 -> -0.086046624 | I42: =I9/H9-1 -> -0.017662612 | J42: =J9/I9-1 -> -0.019972007 | K42: =K9/J9-1 -> -0.0094296439 | L42: =L9/K9-1 -> -0.011090573
B43: Selling, General & Administrative | D43: =D18/C18-1 -> -0.057840276 | E43: =E18/D18-1 -> -0.089693044 | F43: =F18/E18-1 -> 0.12946636 | G43: =G18/F18-1 -> 0.16735141 | H43: =H18/G18-1 -> -0.088220319 | I43: =I18/H18-1 -> -0.0033219206 | J43: =J18/I18-1 -> -0.012921446 | K43: =K18/J18-1 -> -0.0094296439 | L43: =L18/K18-1 -> -0.032281489
B44: EBITDA (before 1-Time Items) | D44: =D23/C23-1 -> -0.021744502 | E44: =E23/D23-1 -> -0.23617075 | F44: =F23/E23-1 -> 0.45601852 | G44: =G23/F23-1 -> 0.21894163 | H44: =H23/G23-1 -> -0.40807155 | I44: =I23/H23-1 -> -0.052746091 | J44: =J23/I23-1 -> -0.12886401 | K44: =K23/J23-1 -> -0.0094296439 | L44: =-L23/K23+1 -> 0.052295132
B45: D&A | D45: =D24/C24-1 -> 0.26688633 | E45: =E24/D24-1 -> 0.10793238 | F45: =F24/E24-1 -> 0.13849765 | G45: =G24/F24-1 -> -0.035051546 | H45: =H24/G24-1 -> -0.090865385 | I45: =I24/H24-1 -> -0.017662612 | J45: =J24/I24-1 -> -0.019972007 | K45: =K24/J24-1 -> -0.0094296439 | L45: =L24/K24-1 -> -0.011090573
B46: Operating Income | D46: =D26/C26-1 -> -0.072674419 | E46: =E26/D26-1 -> -0.31912226 | F46: =F26/E26-1 -> 0.5805709 | G46: =G26/F26-1 -> 0.29070784 | H46: =H26/G26-1 -> -0.47507786 | I46: =I26/H26-1 -> -0.065581509 | J46: =J26/I26-1 -> -0.17074554 | K46: =K26/J26-1 -> -0.0094296439 | L46: =L26/K26-1 -> -0.071024478
B47: Pretax Income | D47: =D28/C28-1 -> -0.13143454 | E47: =E28/D28-1 -> -0.39109507 | F47: =F28/E28-1 -> 0.65513834 | G47: =G28/F28-1 -> 0.26567164 | H47: =H28/G28-1 -> -0.47501651 | I47: =I28/H28-1 -> -0.068527761 | J47: =J28/I28-1 -> -0.082520334 | K47: =K28/J28-1 -> 0.017350096 | L47: =L28/K28-1 -> -0.03968377
B48: Net Income | D48: =D31/C31-1 -> -0.15914489 | E48: =E31/D31-1 -> -0.42171106 | F48: =F31/E31-1 -> 0.83879972 | G48: =G31/F31-1 -> 0.32523719 | H48: =H31/G31-1 -> -0.52192225 | I48: =I31/H31-1 -> -0.068527761 | J48: =J31/I31-1 -> -0.082520334 | K48: =K31/J31-1 -> -0.11829658 | L48: =L31/K31-1 -> -0.03968377
...

Sheet BS
A1: X | B1: Dell Incorporated
B2: Balance Sheet
B3: FY Ended Feb. 3
B4: $ in Millions
C5: 2008 | D5: =C5+1 -> 2009 | E5: =D5+1 -> 2010 | F5: =E5+1 -> 2011 | G5: =F5+1 -> 2012 | H5: 2013E | I5: 2014E | J5: 2015E | K5: 2016E | L5: 2017E
B6: Current Assets:
B7: Cash & Cash Equivalents | C7: 7764 | D7: 8352 | E7: 10635 | F7: 13913 | G7: 13852 | H7: =CF!H45 -> 15744.597 | I7: =CF!I45 -> 18418.561 | J7: =CF!J45 -> 20752.508 | K7: =CF!K45 -> 23689.953 | L7: =CF!L45 -> 26718.478
B8: Short-term Investments | C8: 208 | D8: 740 | E8: 373 | F8: 452 | G8: 966 | H8: =SUM(C8:G8)/5 -> 547.8 | I8: 548 | J8: 548 | K8: 548 | L8: 548
B9: Accounts Receivable | C9: 5961 | D9: 4731 | E9: 5837 | F9: 6493 | G9: 6476 | H9: 6476 | I9: 6476 | J9: 6476 | K9: 6476 | L9: 6476
B10: Financing Receivables | C10: 1732 | D10: 1712 | E10: 2706 | F10: 3643 | G10: 3327 | H10: 3327 | I10: 3327 | J10: 3327 | K10: 3327 | L10: 3327
B11: Inventories | C11: 1180 | D11: 867 | E11: 1051 | F11: 1301 | G11: 1404 | H11: 1500 | I11: 1600 | J11: 1700 | K11: 1800 | L11: 1900
B12: Other Current Assets | C12: 3035 | D12: 3749 | E12: 3643 | F12: 3219 | G12: 3423 | H12: 3423 | I12: 3423 | J12: 3423 | K12: 3423 | L12: 3423
B13: Total Current Assets | C13: =SUM(C7:C12) -> 19880 | D13: =SUM(D7:D12) -> 20151 | E13: =SUM(E7:E12) -> 24245 | F13: =SUM(F7:F12) -> 29021 | G13: =SUM(G7:G12) -> 29448 | H13: =SUM(H7:H12) -> 31018.397 | I13: =SUM(I7:I12) -> 33792.561 | J13: =SUM(J7:J12) -> 36226.508 | ... L13: =SUM(L7:L12) -> 42392.478
B15: PP&E | C15: 2668 | D15: 2277 | E15: 2181 | F15: 1953 | G15: 2124 | H15: =G15-CF!H7-CF!H25 -> 1948.05 | I15: =H15-CF!I7-CF!I25 -> 1812.13 | J15: =I15-CF!J7-CF!J25 -> 1792.905 | K15: =J15-CF!K7-CF!K25 -> 1881.405 | L15: =K15-CF!L7-CF!L25 -> 2078.905
B16: Investments | C16: 1560 | D16: 454 | E16: 781 | F16: 704 | G16: 3404 | H16: =SUM(C16:G16)/5 -> 1380.6 | I16: 1381 | J16: 1381 | K16: 1381 | L16: 1381
B17: LT Financing Receivables | C17: 407 | D17: 500 | E17: 332 | F17: 799 | G17: 1372 | H17: 1400 | I17: 1500 | J17: 1500 | K17: 1550 | L17: 1550
B18: Goodwill | C18: 1648 | D18: 1737 | E18: 4074 | F18: 4365 | G18: 5838 | H18: 6000 | I18: 6000 | J18: 6000 | K18: 6000 | L18: 6000
B19: Intangibles | C19: 780 | D19: 724 | E19: 1694 | F19: 1495 | G19: 1857 | H19: 1857 | I19: 1857 | J19: 1857 | K19: 1857 | L19: 1857
B20: Other Non-current Assets | C20: 618 | D20: 657 | E20: 345 | F20: 262 | G20: 490 | H20: 500 | I20: 500 | J20: 500 | K20: 500 | L20: 500
B21: Total Assets | C21: =SUM(C13:C20) -> 27561 | D21: =SUM(D13:D20) -> 26500 | E21: =SUM(E13:E20) -> 33652 | F21: =SUM(F13:F20) -> 38599 | G21: =SUM(G13:G20) -> 44533 | H21: =SUM(H13:H20) -> 44104.048 | I21: =SUM(I13:I20) -> 46842.691 | J21: =SUM(J13:J20) -> 49257.413 | ... L21: =SUM(L13:L20) -> 55759.383
B23: Current Liabilities:
B24: Short-Term Debt | C24: 225 | D24: 113 | E24: 663 | F24: 851 | G24: 2867 | H24: 2867 | I24: 2867 | J24: 2867 | K24: 2867 | L24: 2867
B25: Accounts Payable | C25: 11492 | D25: 8309 | E25: 11373 | F25: 11293 | G25: 11656 | H25: 11700 | I25: 11800 | J25: 12000 | K25: 12200 | L25: 12300
B26: Accrued and Other | C26: 4323 | D26: 3736 | E26: 3884 | F26: 4181 | G26: 3934 | H26: 4000 | I26: 4100 | J26: 4100 | K26: 4200 | L26: 4200
B27: ST Deferred Revenue | C27: 2486 | D27: 2701 | E27: 3040 | F27: 3158 | G27: 3544 | H27: 3544 | I27: 3544 | J27: 3700 | K27: 3700 | L27: 3700
B28: Total Current Liabilities | C28: =SUM(C24:C27) -> 18526 | D28: =SUM(D24:D27) -> 14859 | E28: =SUM(E24:E27) -> 18960 | F28: =SUM(F24:F27) -> 19483 | G28: =SUM(G24:G27) -> 22001 | H28: =SUM(H24:H27) -> 22111 | I28: =SUM(I24:I27) -> 22311 | J28: =SUM(J24:J27) -> 22667 | ... L28: =SUM(L24:L27) -> 23067
B30: LT Debt | C30: 362 | D30: 1898 | E30: 3417 | F30: 5146 | G30: 6387 | H30: 6387 | I30: 6387 | J30: 6387 | K30: 6387 | L30: 6387
B31: LT Deferred Revenue | C31: 2774 | D31: 3000 | E31: 3029 | F31: 3518 | G31: 3836 | H31: 4000 | I31: 4100 | J31: 4200 | K31: 4300 | L31: 4300
B32: Other Non-current Liabilities | C32: 2070 | D32: 2472 | E32: 2605 | F32: 2686 | G32: 3392 | H32: 3300 | I32: 3300 | J32: 3300 | K32: 3300 | L32: 3300
B33: Total Liabilities | C33: =SUM(C28:C32) -> 23732 | D33: =SUM(D28:D32) -> 22229 | E33: =SUM(E28:E32) -> 28011 | F33: =SUM(F28:F32) -> 30833 | G33: =SUM(G28:G32) -> 35616 | H33: =SUM(H28:H32) -> 35798 | I33: =SUM(I28:I32) -> 36098 | J33: =SUM(J28:J32) -> 36554 | ... L33: =SUM(L28:L32) -> 37054
B35: Redeemable Common Stock | C35: 94 | D35: 0 | E35: 0 | F35: 0 | G35: 0 | H35: 0 | I35: 0 | J35: 0 | K35: 0 | L35: 0
B36: Common Stock | C36: 10589 | D36: 11189 | E36: 11472 | F36: 11797 | G36: 12187 | H36: 10906 | I36: 12790 | J36: 13822 | K36: 15841 | L36: 18358
B37: Treasury Stock | C37: -25037 | D37: -27904 | E37: -27904 | F37: -28704 | G37: -31445 | H37: =G37+CF!H33 -> -32445 | I37: =H37+CF!I33 -> -33445 | J37: =I37+CF!J33 -> -33945 | K37: =J37+CF!K33 -> -34445 | L37: =K37+CF!L33 -> -34945
B38: Retained Earnings | C38: 18199 | D38: 20677 | E38: 22110 | F38: 24744 | G38: 28236 | H38: =G38+IS!H31 -> 29905.447 | I38: =H38+IS!I31 -> 31460.491 | J38: =I38+IS!J31 -> 32887.213 | K38: =J38+IS!K31 -> 34145.158 | L38: =K38+IS!L31 -> 35353.183
B39: AOCI | C39: -16 | D39: 309 | E39: -37 | F39: -71 | G39: -61 | H39: -61 | I39: -61 | J39: -61 | K39: -61 | L39: -61
B40: Total Shareholders' Equity | C40: 3735 | D40: 4271 | E40: 5641 | F40: 7766 | G40: =SUM(G36:G39) -> 8917 | H40: =SUM(H36:H39) -> 8305.4475 | I40: =SUM(I36:I39) -> 10744.491 | J40: =SUM(J36:J39) -> 12703.213 | K40: =SUM(K36:K39) -> 15480.158 | L40: =SUM(L36:L39) -> 18705.183
B41: Total L + SE | C41: =SUM(C33+C35+C40) -> 27561 | D41: =SUM(D33+D40) -> 26500 | E41: =SUM(E33+E40) -> 33652 | F41: =SUM(F33+F40) -> 38599 | G41: =SUM(G33+G40) -> 44533 | H41: =SUM(H33+H40) -> 44103.447 | I41: =SUM(I33+I40) -> 46842.491 | J41: =SUM(J33+J40) -> 49257.213 | K41: =SUM(K33+K40) -> 52434.158 | L41: =SUM(L33+L40) -> 55759.183
B44: Stock Price (Dec. 31) | C44: 10.08 | D44: 14.13 | E44: 13.34 | F44: 14.4 | G44: 10.14
B45: Total Shares (millions) | C45: =IS!C32 -> 2247 | D45: =IS!D32 -> 1986 | E45: =IS!E32 -> 1962 | F45: =IS!F32 -> 1955 | G45: =IS!G32 -> 1853
B46: Market Cap ($ millions) | C46: =C44*C45 -> 22649.76 | D46: =D44*D45 -> 28062.18 | E46: =E44*E45 -> 26173.08 | F46: =F44*F45 -> 28152 | G46: =G44*G45 -> 18789.42
...

Sheet CF
A1: X | B1: Dell Incorporated
B2: Cash Flow Statement
B3: FY Ended Feb. 3
B4: $ in Millions
B5: Cash Flow From Operations: | C5: 2008 | D5: =C5+1 -> 2009 | E5: =D5+1 -> 2010 | F5: =E5+1 -> 2011 | G5: =F5+1 -> 2012 | H5: 2013E | I5: 2014E | J5: 2015E | K5: 2016E | L5: 2017E
B6: Net Income | C6: =IS!C31 -> 2947 | D6: =IS!D31 -> 2478 | E6: =IS!E31 -> 1433 | F6: =IS!F31 -> 2635 | G6: =IS!G31 -> 3492 | H6: =IS!H31 -> 1669.4475 | I6: =IS!I31 -> 1555.044 | J6: =IS!J31 -> 1426.7213 | ... L6: =IS!L31 -> 1208.025
B7: Depreciation and Amortization | C7: 607 | D7: 769 | E7: 852 | F7: 970 | G7: 936 | H7: =-IS!H24 -> 850.95 | I7: =-IS!I24 -> 835.92 | J7: =-IS!J24 -> 819.225 | K7: =-IS!K24 -> 811.5 | L7: =-IS!L24 -> 802.5
B8: Stock-Based Compensation | C8: 329 | D8: 418 | E8: 312 | F8: 332 | G8: 362 | H8: 362 | I8: 362 | J8: 362 | K8: 362 | L8: 362
B9: Forex Impact on Assets & Liabilities | C9: 30 | D9: -115 | E9: 59 | F9: -4 | G9: -5 | H9: 10 | I9: 10 | J9: 10 | K9: 10 | L9: 10
B10: Deferred Income Taxes | C10: -308 | D10: 86 | E10: -52 | F10: -45 | G10: 19 | H10: -30 | I10: -30 | J10: -30 | K10: -30 | L10: -30
B11: Provision for Doubtful Accounts | C11: 187 | D11: 310 | E11: 429 | F11: 382 | G11: 234 | H11: 308 | I11: 308 | J11: 308 | K11: 308 | L11: 308
B12: Other | C12: 30 | D12: 34 | E12: 102 | F12: 26 | G12: 21 | H12: 20 | I12: 20 | J12: 25 | K12: 30 | L12: 30
B13: Accounts Receivable | C13: -1086 | D13: 480 | E13: -660 | F13: -707 | G13: -53 | H13: -405 | I13: -405 | J13: -405 | K13: -405 | L13: -405
B14: Financing Receivables | C14: -394 | D14: -302 | E14: -1085 | F14: -709 | G14: -372 | H14: -570 | I14: -570 | J14: -570 | K14: -570 | L14: -570
B15: Inventories | C15: -498 | D15: 309 | E15: -183 | F15: -248 | G15: -52 | H15: -250 | I15: -250 | J15: -250 | K15: -250 | L15: -250
B16: Other assets | C16: -121 | D16: -106 | E16: -225 | F16: 516 | G16: -28 | H16: 100 | I16: 150 | J16: 200 | K16: 225 | L16: 250
B17: Accounts Payable | C17: 837 | D17: -3117 | E17: 2833 | F17: -151 | G17: 327 | H17: -500 | I17: 300 | J17: -400 | K17: 300 | L17: 300
B18: Deferred Service Revenue | C18: 1032 | D18: 663 | E18: 135 | F18: 551 | G18: 720 | H18: 720 | I18: 720 | J18: 720 | K18: 720 | L18: 720
B19: Accrued and Other Liabilities | C19: 274 | D19: -13 | E19: -44 | F19: 421 | G19: -74 | H19: -100 | I19: -100 | J19: -100 | K19: -100 | L19: -100
B20: Net Cash Flows from Operating Activities | C20: =SUM(C6:C19) -> 3866 | D20: =SUM(D6:D19) -> 1894 | E20: =SUM(E6:E19) -> 3906 | F20: =SUM(F6:F19) -> 3969 | G20: =SUM(G6:G19) -> 5527 | H20: =SUM(H6:H19) -> 2185.3975 | I20: =SUM(I6:I19) -> 2905.964 | J20: =SUM(J6:J19) -> 2115.9462 | ... L20: =SUM(L6:L19) -> 2635.525
B22: Cash Flows from Investing:
B23: Purchases | C23: -2394 | D23: -1584 | E23: -1383 | F23: -1360 | G23: -4656 | H23: =SUM(C23:G23)/5 -> -2275.4 | I23: -2275 | J23: -2275 | K23: -2275 | L23: -2275
B24: Maturities and Sales | C24: 3679 | D24: 2333 | E24: 1538 | F24: 1358 | G24: 1435 | H24: =SUM(C24:G24)/5 -> 2068.6 | I24: 2069 | J24: 2069 | K24: 2069 | L24: 2069
B25: Capital Expenditures | C25: -831 | D25: -440 | E25: -367 | F25: -444 | G25: -675 | H25: -675 | I25: -700 | J25: -800 | K25: -900 | L25: -1000
B26: Proceeds from Sales of Facility & Land | C26: 0 | D26: 44 | E26: 16 | F26: 18 | G26: 14 | H26: 20 | I26: 20 | J26: 20 | K26: 20 | L26: 20
B27: Purchase of Financing Receivables | C27: 0 | D27: 0 | E27: 0 | F27: -430 | G27: 0 | H27: 0 | I27: 0 | J27: 0 | K27: 0 | L27: 0
B28: Collections on Purchased Receivables | C28: 0 | D28: 0 | E28: 0 | F28: 69 | G28: 278 | H28: 200 | I28: 200 | J28: 200 | K28: 200 | L28: 200
B29: Acquisition, Net of Cash Received | C29: -2217 | D29: -176 | E29: -3613 | F29: -376 | G29: -2562 | H29: -1800 | I29: -1800 | J29: -1800 | K29: -1700 | L29: -1500
B30: Net Cash Flows from Investing Activities | C30: =SUM(C23:C29) -> -1763 | D30: =SUM(D23:D29) -> 177 | E30: =SUM(E23:E29) -> -3809 | F30: =SUM(F23:F29) -> -1165 | G30: =SUM(G23:G29) -> -6166 | H30: =SUM(H23:H29) -> -2461.8 | I30: =SUM(I23:I29) -> -2486 | J30: =SUM(J23:J29) -> -2586 | ... L30: =SUM(L23:L29) -> -2486
B32: Cash Flows from Financing:
B33: Repurchase of Common Stock | C33: -4004 | D33: -2867 | E33: 0 | F33: -800 | G33: -2717 | H33: -1000 | I33: -1000 | J33: -500 | K33: -500 | L33: -500
B34: Proceeds from Stock Issuance | C34: 136 | D34: 79 | E34: 2 | F34: 12 | G34: 40 | H34: 40 | I34: 40 | J34: 40 | K34: 40 | L34: 40
B35: (Repayment) Issuance of Commercial Paper, Net | C35: -100 | D35: 100 | E35: 76 | F35: -176 | G35: 635 | H35: 500 | I35: 600 | J35: 650 | K35: 700 | L35: 725
B36: Repayments of Debt | C36: -165 | D36: -237 | E36: -122 | F36: -1630 | G36: -1435 | H36: -1435 | I36: -1500 | J36: -1550 | K36: -1600 | L36: -1650
B37: Proceeds from Borrowings | C37: 66 | D37: 1519 | E37: 2058 | F37: 3069 | G37: 4050 | H37: 4050 | I37: 4100 | J37: 4150 | K37: 4200 | L37: 4250
B38: Other | C38: -53 | D38: 0 | E38: -2 | F38: 2 | G38: 4 | H38: 4 | I38: 4 | J38: 4 | K38: 4 | L38: 4
B39: Net Cash Flows from Financing Activities | C39: =SUM(C33:C38) -> -4120 | D39: =SUM(D33:D38) -> -1406 | E39: =SUM(E33:E38) -> 2012 | F39: =SUM(F33:F38) -> 477 | G39: =SUM(G33:G38) -> 577 | H39: =SUM(H33:H38) -> 2159 | I39: =SUM(I33:I38) -> 2244 | J39: =SUM(J33:J38) -> 2794 | ... L39: =SUM(L33:L38) -> 2869
B41: Forex Impact | C41: 152 | D41: -77 | E41: 174 | F41: -3 | G41: 1 | H41: 10 | I41: 10 | J41: 10 | K41: 10 | L41: 10
B43: Net Change in Cash & Equivalents | C43: =C41+C39+C30+C20 -> -1865 | D43: =D41+D39+D30+D20 -> 588 | E43: =E41+E39+E30+E20 -> 2283 | F43: =F41+F39+F30+F20 -> 3278 | G43: =G41+G39+G30+G20 -> -61 | H43: =H41+H39+H30+H20 -> 1892.5975 | I43: =I41+I39+I30+I20 -> 2673.964 | J43: =J41+J39+J30+J20 -> 2333.9462 | ... L43: =L41+L39+L30+L20 -> 3028.525
B44: Cash & Equivalents, Beginning of Period | C44: 9546 | D44: =C45 -> 7764 | E44: =D45 -> 8352 | F44: =E45 -> 10635 | G44: =F45 -> 13913 | H44: =G45 -> 13852 | I44: =H45 -> 15744.597 | J44: =I45 -> 18418.561 | K44: =J45 -> 20752.508 | L44: =K45 -> 23689.953
...

Sheet DCF
A1: X | B1: Dell Incorporated
B2: Discounted Cash Flow Analysis
B3: FY Ended Feb. 3
B4: =[1]IS!B4 -> $ in Millions
C5: =[1]IS!AD5 -> 2011 | D5: =C5+1 -> 2012 | E5: =D5+1 -> 2013 | F5: =E5+1 -> 2014 | G5: =F5+1 -> 2015 | H5: =G5+1 -> 2016 | I5: =H5+1 -> 2017
B6: Operating Income | C6: =IS!F26 -> 3433 | D6: =IS!G26 -> 4431 | E6: =IS!H26 -> 2325.93 | F6: =IS!I26 -> 2173.392 | G6: =IS!J26 -> 1802.295 | H6: =IS!K26 -> 1785.3 | I6: =IS!L26 -> 1658.5
B7: Tax-Affected EBIT (Operating Income )* (1-T) | C7: =C6*(1-0.35) -> 2231.45 | D7: =D6*(1-0.35) -> 2880.15 | E7: =E6*(1-0.35) -> 1511.8545 | F7: =F6*(1-0.35) -> 1412.7048 | G7: =G6*(1-0.35) -> 1171.4918 | H7: =H6*(1-0.35) -> 1160.445 | I7: =I6*(1-0.35) -> 1078.025
B8: (+) Depreciation | C8: =-IS!F24 -> 970 | D8: =-IS!G24 -> 936 | E8: =-IS!H24 -> 850.95 | F8: =-IS!I24 -> 835.92 | G8: =-IS!J24 -> 819.225 | H8: =-IS!K24 -> 811.5 | I8: =-IS!L24 -> 802.5
B9: (+) Amortization of Intangibles | C9: 0 | D9: 0 | E9: 0 | F9: 0 | G9: 0 | H9: 0 | I9: 0
B10: (-) Capital Expenditures | C10: =CF!F25 -> -444 | D10: =CF!G25 -> -675 | E10: =CF!H25 -> -675 | F10: =CF!I25 -> -700 | G10: =CF!J25 -> -800 | H10: =CF!K25 -> -900 | I10: =CF!L25 -> -1000
B11: (-) Acquisition Spending | C11: =CF!F29 -> -376 | D11: =CF!G29 -> -2562 | E11: =CF!H29 -> -1800 | F11: =CF!I29 -> -1800 | G11: =CF!J29 -> -1800 | H11: =CF!K29 -> -1700 | I11: =CF!L29 -> -1500
B12: Unlevered Free Cash Flow to the Firm (UFCFF) | C12: =SUM(C6:C11) -> 5814.45 | D12: =SUM(D6:D11) -> 5010.15 | E12: =SUM(E6:E11) -> 2213.7345 | F12: =SUM(F6:F11) -> 1922.0168 | G12: =SUM(G6:G11) -> 1193.0118 | H12: =SUM(H6:H11) -> 1157.245 | I12: =SUM(I6:I11) -> 1039.025
B14: Net Present Value of 5 yr UFCFF | C14: =NPV(I21,E12:I12) -> 6099.1418 | E14: Risk-Free Rate (Normalized 10 Yr Treasury) | I14: 0.0185
B15: Terminal Value (Perpetuity Growth Method) | C15: =I12*(1+I22)/(I21-I22) -> 17045.696 | E15: Target Debt to Capital | I15: 0.51
B16: Discounted Terminal Value | C16: =C15/(1+I21)^5 -> 11207.534 | E16: Equity Risk Premium (CAPM) | I16: =(10%-I14) -> 0.0815
B17: Enterprise Value | C17: =C14+C16 -> 17306.675 | E17: Beta (Equity) | I17: 1.59
B18: (+) Cash | C18: =BS!F7 -> 13913 | E18: Cost of Equity | I18: =I14 + I17*I16 -> 0.148085
B19: (-) Market Value of Debt | C19: =-(BS!F24+BS!F30) -> -5997 | E19: Cost of Debt | I19: 0.045
B20: (-) PV of Operating Leases | C20: 0
B21: Equity Value | C21: =SUM(C17:C20) -> 25222.675 | E21: Weighted Average Cost of Capital (WACC) | I21: =I18*(1-I15)+I19*(I15)*(1-I23) -> 0.08747915
B22: (/) Diluted Shares Outstanding | C22: 1853 | E22: Perpetuity Growth Rate | I22: 0.025
B23: Implied Equity Value per Share | C23: =C21/C22 -> 13.611805 | E23: Tax Rate | I23: 0.35
