Workbook

Sheet Test Spec
A1: Transmitter Tests
A2: Priority | B2: Test Equip. | D2: Symbol | E2: Pattern | F2: Applicable Preset | G2: Test | J2: Comment/Test recommendation | K2: Crosstalk* | L2: Importance | M2: PF22 Status | N2: Comment
A3: Core | B3: Agilent VNA | D3: SDD22 | E3: PRBS31 or PRBS9 | F3: N/A | G3: Differential return loss output | K3: No | M3: Tested
A4: Core | B4: Agilent VNA | D4: SCC22 | E4: PRBS31 or PRBS9 | F4: N/A | G4: Common mode return loss output | K4: No | M4: Tested
A5: Core | B5: Agilent VNA | D5: SDC22 | E5: PRBS31 or PRBS9 | F5: N/A | G5: Common mode to differential reflection | K5: No | M5: Tested
A6: Core | B6: Tektronix BERTScope | D6: RJ | E6: PRBS31 | F6: All | G6: Random jitter | J6: Use preset 0 and choose a random preset with reasonable eye | K6: Yes | L6: 3 | M6: Tested | N6: Cross talk isimportant here.
A7: Core | B7: Tektronix BERTScope | D7: DCD | E7: PRBS31 or PRBS9 | F7: All | G7: Duty cycle distortion | J7: Use preset 0 and choose a random preset with reasonable eye | K7: No | M7: Tested
A8: Core | B8: Tektronix BERTScope | D8: TJ-DDJ | E8: PRBS31 | F8: All | G8: Total jitter, excluding DDJ | J8: Use preset 0 and choose a random preset with reasonable eye | K8: Yes | L8: 3 | M8: Tested
A9: Core | B9: Tektronix BERTScope | D9: DDJ | E9: PRBS9 | F9: All | G9: DDJ | J9: Use preset 0 and choose a random preset with reasonable eye | K9: Yes | M9: Tested
A10: Core | B10: Tektronix BERTScope | D10: J2, J9 | E10: PRBS31 | F10: Preset 0 | G10: High, low probabaility jitter | K10: Yes | L10: 5 | M10: Tested | N10: J2 is not critical but J9 must have cross talk sources
A11: Core | B11: Agilent Sampling Scope | D11: DDPWS | E11: PRBS9 | F11: Preset 0 | G11: Data-depedent pulse width shrinkage | K11: No | M11: Tested
A12: Core | B12: Agilent Sampling Scope | D12: tr, tf | E12: PRBS9 | F12: Preset 0 | G12: Output transition time | K12: No | M12: Tested
A13: Secondary | B13: Agilent Sampling Scope | D13: Vcm | E13: PRBS9 | F13: All | G13: AC common mode output voltage | J13: Test preset 0 and two other presets chosen at random | K13: Yes | M13: Tested
A14: Core | B14: Agilent Sampling Scope | D14: X1, X2, Y1, Y2 | E14: PRBS31 | F14: Preset 0 | G14: Eye mask test | K14: Yes | L14: 4 | M14: Tested | N14: Cross talk is also very important here.
A15: Secondary | B15: Agilent Sampling Scope | D15: QSQ | E15: PRBS9 | F15: Preset 0 | K15: Yes | L15: 5 | M15: No Test
A16: Secondary | B16: Agilent Sampling Scope | D16: Vf | E16: PRBS9 | F16: Preset 1 only | G16: Steady-state output voltage | J16: Test both amplitude=0 and amplitude=1 | K16: No | M16: Tested
A17: Tertiary | B17: Agilent Sampling Scope | D17: Vdiffpp | E17: N/A | F17: N/A | G17: Differential p-p output voltage, driver disabled | M17: Tested
A18: Secondary | B18: Calculate from the Sampling Scope measurements | E18: PRBS9 | F18: Preset 1 only | G18: Peak linear fit pulse response | J18: Calculated from RTS Measurements | M18: Tested
A19: Secondary | D19: e | E19: PRBS9 | F19: Any except preset 0 | G19: Normalized error (linear fit) | J19: Use presets 2 and 15 | M19: Tested
A20: Secondary | E20: PRBS9 | F20: Any except preset 0 | G20: C-1, C0, C+1 tap weights | J20: Measure c0, c-1, c+1, use presets 2 and 15 with both settings of the amplitude bit | M20: Tested
A21: Secondary | B21: Agilent Sampling Scope | E21: PRBS9 | F21: Any except preset 0 | G21: Far end transmit output noise (Short channel) | J21: Use presets 2 and 15 | K21: Yes | M21: No Test
A22: Secondary | B22: Agilent Sampling Scope | E22: PRBS9 | F22: Any except preset 0 | G22: Far end transmit output noise (Long channel) | J22: Use presets 2 and 15 | K22: Yes | M22: No Test
A23: Tertiary | B23: Calc from multiple C-1, C0, C+1 with changes to max/min ranges | D23: TX_pre full range | E23: N/A | G23: TX Pre_cursor full scale range | J23: Tested below on tap weight test | M23: No Test
A24: Tertiary | D24: TX_post full range | E24: N/A | G24: TX Post_cursor full scale range | J24: Tested below on tap weight test | M24: No Test
A25: Tertiary | B25: Calc from multiple C-1,C0,C+1 with single-step changes | E25: N/A | F25: Any except preset 0 | G25: Equalizer coefficient step size | J25: No good way to test this | M25: No Test
A26: Tertiary | B26: Agilent Sampling Scope | E26: N/A | F26: N/A | G26: Termination mismatch | M26: No Test
A28: Receiver Tests
A29: Priority | B29: Test Equip. | D29: Symbol | E29: Pattern | F29: Applicable Preset | G29: Parameter | J29: Comment/Test recommendation | K29: Crosstalk* | L29: Importance
A30: Core | B30: Agilent VNA | D30: SDD11 | E30: PRBS31 or PRBS9 | F30: N/A | G30: Differential return loss input | K30: No | M30: Tested
A31: Core | B31: Agilent VNA | D31: SCC11 | E31: PRBS31 or PRBS9 | F31: N/A | G31: Common mode return loss input | K31: No | M31: Tested
A32: Core | B32: Agilent VNA | D32: SDC11 | E32: PRBS31 or PRBS9 | F32: N/A | G32: Common mode to differential reflection | K32: No | M32: Tested
A33: Secondary | B33: Standard Transmitter and standard high-loss cable | G33: Receiver test - long channel | M33: No Test | N33: Need to know what they realisitcially expect. What is worse case.
A34: Secondary | B34: Standard Transmitter and standard high-loss cable | G34: Receiver test - short channel | M34: No Test | N34: This is stressing eye and sending it over something and see if receiver gets everything. Make sure no bit errors
A35: Secondary | B35: Tektronix BERTScope | G35: RX tolerance testing for use with linear cables | M35: PF23 Alpha
A36: Secondary | B36: Tektronix BERTScope | G36: RX tolerance testing for use with limiting active cables | M36: PF23 Alpha
B41: Priorities - Description
B42: Core | D42: Must test at each PlugFest | K42: *A crosstalk source is required to be connected to the port input for these tests
B43: Secondary | D43: Required for compliance, but not all items will be tested at each PF. | K43: 5 Highest priority
B44: Tertiary | D44: Required for compliance, but will likely not be tested at the PF.

Sheet DUT Info
A1: Serial Number: | B1: 123456
A2: Model: | B2: SFI
A3: Part Number | B3: SFI-123456
A4: FW # | B4: 9.99.9999

Sheet Lane 1
A1: Transmitter Tests
A2: Priority | B2: Parameter | C2: Master Spec Page | D2: Calculated Result | E2: Measurement Units | F2: Pass/Fail | G2: Measured | H2: Frequency in GHz | I2: Parameter | J2: Factor | K2: Conversion | L2: # Fails | M2: # Waveforms | N2: Samples Per Waveform | O2: Comments
A3: Core | B3: SDD22 | C3: =IF(D3="","NT",IF(H3<=5.6,-12+1.71*SQRT(H3),-6.7+13*LOG10((H3/7)))) -> -12 | D3: =+G3 -> 0 | E3: dB | F3: =IF(D3="","Fail",IF(D3<=C3,"Pass", "Fail")) -> Fail | I3: =+B3 -> SDD22
A4: Core | B4: SCC22 | C4: =IF(D4="","NT",-2) -> -2 | D4: =+G4 -> 0 | E4: dB | F4: =IF(D4="","Fail",IF(D4<=C4,"Pass", "Fail")) -> Fail | I4: =+B4 -> SCC22
A5: Core | B5: SDC22 | C5: =IF(D5="","NT",-16+((2/3)*H5)) -> -16 | D5: =+G5 -> 0 | E5: dB | F5: =IF(D5="","Fail",IF(D5<=C5,"Pass", "Fail")) -> Fail | I5: =+B5 -> SDC22
A6: Core | B6: RJ - preset 0 | C6: 0.15 | D6: =+K6 -> 0 | E6: UI | F6: =IF(G6="","Fail",IF(D6<=C6,"Pass", "Fail")) -> Fail | I6: =+B6 -> RJ - preset 0 | J6: 14.069 | K6: =(G6/1000)*J6 -> 0 | O6: Converted from RMS to the spec value - P2P
A7: Core | B7: RJ - preset 15 - Amplitude 0 | C7: 0.15 | D7: =+K7 -> 0 | E7: UI | F7: =IF(G7="","Fail",IF(D7<=C7,"Pass", "Fail")) -> Fail | I7: =+B7 -> RJ - preset 15 - Amplitude 0 | J7: 14.069 | K7: =(G7/1000)*J7 -> 0 | O7: Converted from RMS to the spec value - P2P
A8: Core | B8: RJ - preset 15 - Amplitude 1 | C8: 0.15 | D8: =+K8 -> 0 | E8: UI | F8: =IF(G8="","Fail",IF(D8<=C8,"Pass", "Fail")) -> Fail | I8: =+B8 -> RJ - preset 15 - Amplitude 1 | J8: 14.069 | K8: =(G8/1000)*J8 -> 0 | O8: Converted from RMS to the spec value - P2P
A9: Core | B9: DCD - preset 0 | C9: 0.035 | D9: =+K9 -> 0 | E9: UI | F9: =IF(G9="","Fail",IF(D9<=C9,"Pass", "Fail")) -> Fail | I9: =+B9 -> DCD - preset 0 | J9: 1000 | K9: =+G9/J9 -> 0 | O9: Divide value on BERTScope by 1000
A10: Core | B10: DCD - preset 15 - amplitude 0 | C10: 0.035 | D10: =+K10 -> 0 | E10: UI | F10: =IF(G10="","Fail",IF(D10<=C10,"Pass", "Fail")) -> Fail | I10: =+B10 -> DCD - preset 15 - amplitude 0 | J10: 1000 | K10: =+G10/J10 -> 0 | O10: Divide value on BERTScope by 1000
A11: Core | B11: DCD - preset 15 - amplitude 1 | C11: 0.035 | D11: =+K11 -> 0 | E11: UI | F11: =IF(G11="","Fail",IF(D11<=C11,"Pass", "Fail")) -> Fail | I11: =+B11 -> DCD - preset 15 - amplitude 1 | J11: 1000 | K11: =+G11/J11 -> 0 | O11: Divide value on BERTScope by 1000
A12: Core | B12: TJ - preset 0 | C12: Used to calc TJ-DDJ | D12: =+K12 -> 0 | E12: UI | F12: N/A | I12: =+B12 -> TJ - preset 0 | J12: 1000 | K12: =+G12/J12 -> 0 | O12: Divide value on BERTScope by 1000
A13: Core | B13: TJ - preset 15 - amplitude 0 | C13: Used to calc TJ-DDJ | D13: =+K13 -> 0 | E13: UI | F13: N/A | I13: =+B13 -> TJ - preset 15 - amplitude 0 | J13: 1000 | K13: =+G13/J13 -> 0 | O13: Divide value on BERTScope by 1000
A14: Core | B14: TJ - preset 15 - amplitude 1 | C14: Used to calc TJ-DDJ | D14: =+K14 -> 0 | E14: UI | F14: N/A | I14: =+B14 -> TJ - preset 15 - amplitude 1 | J14: 1000 | K14: =+G14/J14 -> 0 | O14: Divide value on BERTScope by 1000
A15: Core | B15: DDJ - preset 0 | C15: Used to calc TJ-DDJ | D15: =+K15 -> 0 | E15: UI | F15: N/A | I15: =+B15 -> DDJ - preset 0 | J15: 1000 | K15: =+G15/J15 -> 0 | O15: Divide value on BERTScope by 1000
A16: Core | B16: DDJ - preset 15 - amplitude 0 | C16: Used to calc TJ-DDJ | D16: =+K16 -> 0 | E16: UI | F16: N/A | I16: =+B16 -> DDJ - preset 15 - amplitude 0 | J16: 1000 | K16: =+G16/J16 -> 0 | O16: Divide value on BERTScope by 1000
A17: Core | B17: DDJ - preset 15 - amplitude 1 | C17: Used to calc TJ-DDJ | D17: =+K17 -> 0 | E17: UI | F17: N/A | I17: =+B17 -> DDJ - preset 15 - amplitude 1 | J17: 1000 | K17: =+G17/J17 -> 0 | O17: Divide value on BERTScope by 1000
A18: Core | B18: TJ-DDJ - preset 0 | C18: 0.25 | D18: =+K18 -> 0 | E18: UI | F18: =IF(OR(G12="",D15=""),"Fail",IF(D18<=C18,"Pass", "Fail")) -> Fail | I18: =+B18 -> TJ-DDJ - preset 0 | K18: =+K12-K15 -> 0 | O18: Divide value on BERTScope by 1000
A19: Core | B19: TJ-DDJ - preset 15 - amplitude 0 | C19: 0.25 | D19: =+K19 -> 0 | E19: UI | F19: =IF(OR(G13="",D16=""),"Fail",IF(D19<=C19,"Pass", "Fail")) -> Fail | I19: =+B19 -> TJ-DDJ - preset 15 - amplitude 0 | K19: =+K13-K16 -> 0 | O19: Divide value on BERTScope by 1000
A20: Core | B20: TJ-DDJ - preset 15 - amplitude 1 | C20: 0.25 | D20: =+K20 -> 0 | E20: UI | F20: =IF(OR(G14="",D17=""),"Fail",IF(D20<=C20,"Pass", "Fail")) -> Fail | I20: =+B20 -> TJ-DDJ - preset 15 - amplitude 1 | K20: =+K14-K17 -> 0 | O20: Divide value on BERTScope by 1000
A21: Core | B21: J2 - preset 0 | C21: 0.19 | D21: =+K21 -> 0 | E21: UI | F21: =IF(G21="","Fail",IF(D21<=C21,"Pass", "Fail")) -> Fail | I21: =+B21 -> J2 - preset 0 | J21: 1000 | K21: =+G21/J21 -> 0 | O21: Divide value on BERTScope by 1000
A22: Core | B22: J9 - preset 0 | C22: 0.33 | D22: =+K22 -> 0 | E22: UI | F22: =IF(G22="","Fail",IF(D22<=C22,"Pass", "Fail")) -> Fail | I22: =+B22 -> J9 - preset 0 | J22: 1000 | K22: =+G22/J22 -> 0 | O22: Divide value on BERTScope by 1000
A23: Core | B23: DDPWS | C23: 0.11 | D23: =+K23 -> 0 | E23: UI | F23: =IF(G23="","Fail",IF(D23<=C23,"Pass", "Fail")) -> Fail | I23: =+B23 -> DDPWS | J23: 1000 | K23: =+G23/J23 -> 0 | O23: Tektronix BERTSCope DDPWS
A24: Core | B24: DDPWS | C24: 0.11 | D24: =+B79 -> 1 | E24: UI | F24: =IF(G24="","Fail",IF(D24<=C24,"Pass", "Fail")) -> Fail | I24: =+B24 -> DDPWS | O24: Agilent DDPWS - see calculation in Cell B40 | Q24: Testing Order
A25: Core | B25: X1, X2, Y1, Y2 | C25: 5e-05 | D25: =+L25/(M25*N25) -> 0 | E25: UI | F25: =IF(L25="","NT",IF(D25<=C25,"Pass", "Fail")) -> NT | G25: See columns L-M | I25: =+B25 -> X1, X2, Y1, Y2 | M25: 110 | N25: 16200 | O25: BERTScope Eye Mask | Q25: Preset 0 | R25: Agilent and then BERTScope
A26: Core | B26: X1, X2, Y1, Y2 | C26: 5e-05 | D26: =+L26/(M26*N26) -> 0 | E26: UI | F26: =IF(L26="","Fail",IF(D26<=C26,"Pass", "Fail")) -> Fail | I26: =+B26 -> X1, X2, Y1, Y2 | M26: 110 | N26: 16200 | O26: Agilent Eye Mask | Q26: Eye Mask | R26: Make sure settings are correct.
A27: Core | B27: Tr | C27: 24 | D27: =+G27 -> 0 | E27: ps | F27: =IF(D27="","Fail",IF(D27>=C27,"Pass","Fail")) -> Fail | I27: =+B27 -> Tr | Q27: Tr | R27: PRBS11
A28: Core | B28: Tf | C28: 24 | D28: =+G28 -> 0 | E28: ps | F28: =IF(D28="","Fail",IF(D28>=C28,"Pass","Fail")) -> Fail | I28: =+B28 -> Tf | Q28: tf | R28: PRBS11
A29: Secondary | B29: Vcm preset 0 | C29: 20 | D29: =+K29 -> 0 | E29: mV RMS | F29: =IF(G29="","Fail",IF(D29<=C29,"Pass", "Fail")) -> Fail | I29: =+B29 -> Vcm preset 0 | J29: 2 | K29: =+G29/J29 -> 0 | O29: AC common mode output voltage. Scope value is divided by two. | Q29: vcm | R29: Take Max value
A30: Secondary | B30: Vcm preset 2 - amplitude 0 | C30: 30 | D30: =+K30 -> 0 | E30: mV RMS | F30: =IF(G30="","Fail",IF(D30<=C30,"Pass", "Fail")) -> Fail | I30: =+B30 -> Vcm preset 2 - amplitude 0 | J30: 2 | K30: =+G30/J30 -> 0 | O30: AC common mode output voltage. Scope value is divided by two. | Q30: vdiffp | R30: Take Max value
A31: Secondary | B31: Vcm preset 2 - amplitude 1 | C31: 30 | D31: =+K31 -> 0 | E31: mV RMS | F31: =IF(G31="","Fail",IF(D31<=C31,"Pass", "Fail")) -> Fail | I31: =+B31 -> Vcm preset 2 - amplitude 1 | J31: 2 | K31: =+G31/J31 -> 0 | O31: AC common mode output voltage. Scope value is divided by two. | Q31: DDPWs | R31: See calculations in B71:76
A32: Secondary | B32: Vcm preset 15 - amplitude 0 | C32: 30 | D32: =+K32 -> 0 | E32: mV RMS | F32: =IF(G32="","Fail",IF(D32<=C32,"Pass", "Fail")) -> Fail | I32: =+B32 -> Vcm preset 15 - amplitude 0 | J32: 2 | K32: =+G32/J32 -> 0 | O32: AC common mode output voltage. Scope value is divided by two. | Q32: Preset 1
A33: Secondary | B33: Vcm preset 15 - amplitude 1 | C33: 30 | D33: =+K33 -> 0 | E33: mV RMS | F33: =IF(G33="","Fail",IF(D33<=C33,"Pass", "Fail")) -> Fail | I33: =+B33 -> Vcm preset 15 - amplitude 1 | J33: 2 | K33: =+G33/J33 -> 0 | O33: AC common mode output voltage. Scope value is divided by two. | Q33: Preset 2
A34: Core | B34: Vdiffpp | C34: 30 | D34: =+G34 -> 0 | E34: mV | F34: =IF(G34="","Fail",IF(D34<=C34,"Pass", "Fail")) -> Fail | I34: =+B34 -> Vdiffpp | Q34: Preset 15
A35: Secondary | B35: e preset 1 - amplitude 0 | C35: 0.037 | D35: =+G35 -> 0 | F35: =IF(G35="","Fail",IF(D35<=C35,"Pass", "Fail")) -> Fail | I35: =+B35 -> e preset 1 - amplitude 0
A36: Secondary | B36: e preset 1 - amplitude 1 | C36: 0.037 | D36: =+G36 -> 0 | F36: =IF(G36="","Fail",IF(D36<=C36,"Pass", "Fail")) -> Fail | I36: =+B36 -> e preset 1 - amplitude 1 | O36: rms_normalized_e - checked in preset 1 only
A37: Secondary | B37: e preset 2 - amplitude 0 | C37: 0.037 | D37: =+G37 -> 0 | E37: Calc # | F37: =IF(G37="","Fail",IF(D37<=C37,"Pass", "Fail")) -> Fail | I37: =+B37 -> e preset 2 - amplitude 0
A38: Secondary | B38: e preset 2 - amplitude 1 | C38: 0.037 | D38: =+G38 -> 0 | E38: Calc # | F38: =IF(G38="","Fail",IF(D38<=C38,"Pass", "Fail")) -> Fail | I38: =+B38 -> e preset 2 - amplitude 1
A39: Secondary | B39: e preset 15 - amplitude 0 | C39: 0.037 | D39: =+G39 -> 0 | E39: Calc # | F39: =IF(G39="","Fail",IF(D39<=C39,"Pass", "Fail")) -> Fail | I39: =+B39 -> e preset 15 - amplitude 0
A40: Secondary | B40: e preset 15 - amplitude 1 | C40: 0.037 | D40: =+G40 -> 0 | E40: Calc # | F40: =IF(G40="","Fail",IF(D40<=C40,"Pass", "Fail")) -> Fail | I40: =+B40 -> e preset 15 - amplitude 1
...

Sheet Lane 2
A1: Transmitter Tests
A2: Priority | B2: Parameter | C2: Spec See Page 1 | D2: Calculated Results | E2: Measurement Units | F2: Pass/Fail | G2: Measured | H2: Frequency in GHz | I2: Parameter | J2: Factor | K2: Conversion | L2: # Fails | M2: # Waveforms | N2: Samples Per Waveform | O2: Comments
A3: Core | B3: =+'Lane 1'!$B3 -> SDD22 | C3: =IF(D3="","NT",IF(H3<=5.6,-12+1.71*SQRT(H3),-6.7+13*LOG10((H3/7)))) -> -12 | D3: =+G3 -> 0 | E3: dB | F3: =IF(D3="","Fail",IF(D3<=C3,"Pass", "Fail")) -> Fail | I3: =+B3 -> SDD22
A4: Core | B4: =+'Lane 1'!$B4 -> SCC22 | C4: =IF(D4="","NT",-2) -> -2 | D4: =+G4 -> 0 | E4: dB | F4: =IF(D4="","Fail",IF(D4<=C4,"Pass", "Fail")) -> Fail | I4: =+B4 -> SCC22
A5: Core | B5: =+'Lane 1'!$B5 -> SDC22 | C5: =IF(D5="","NT",-16+((2/3)*H5)) -> -16 | D5: =+G5 -> 0 | E5: dB | F5: =IF(D5="","Fail",IF(D5<=C5,"Pass", "Fail")) -> Fail | I5: =+B5 -> SDC22
A6: Core | B6: =+'Lane 1'!$B6 -> RJ - preset 0 | C6: =+'Lane 1'!C6 -> 0.15 | D6: =+K6 -> 0 | E6: UI | F6: =IF(G6="","Fail",IF(D6<=C6,"Pass", "Fail")) -> Fail | I6: =+B6 -> RJ - preset 0 | J6: 14.069 | K6: =(G6/1000)*J6 -> 0 | O6: Converted from RMS to the spec value - P2P
A7: Core | B7: =+'Lane 1'!$B7 -> RJ - preset 15 - Amplitude 0 | C7: =+'Lane 1'!C7 -> 0.15 | D7: =+K7 -> 0 | E7: UI | F7: =IF(G7="","Fail",IF(D7<=C7,"Pass", "Fail")) -> Fail | I7: =+B7 -> RJ - preset 15 - Amplitude 0 | J7: 14.069 | K7: =(G7/1000)*J7 -> 0 | O7: Converted from RMS to the spec value - P2P
A8: Core | B8: =+'Lane 1'!$B8 -> RJ - preset 15 - Amplitude 1 | C8: =+'Lane 1'!C8 -> 0.15 | D8: =+K8 -> 0 | E8: UI | F8: =IF(G8="","Fail",IF(D8<=C8,"Pass", "Fail")) -> Fail | I8: =+B8 -> RJ - preset 15 - Amplitude 1 | J8: 14.069 | K8: =(G8/1000)*J8 -> 0 | O8: Converted from RMS to the spec value - P2P
A9: Core | B9: =+'Lane 1'!$B9 -> DCD - preset 0 | C9: =+'Lane 1'!C9 -> 0.035 | D9: =+K9 -> 0 | E9: UI | F9: =IF(G9="","Fail",IF(D9<=C9,"Pass", "Fail")) -> Fail | I9: =+B9 -> DCD - preset 0 | J9: 1000 | K9: =+G9/J9 -> 0 | O9: Divide value on BERTScope by 1000
A10: Core | B10: =+'Lane 1'!$B10 -> DCD - preset 15 - amplitude 0 | C10: =+'Lane 1'!C10 -> 0.035 | D10: =+K10 -> 0 | E10: UI | F10: =IF(G10="","Fail",IF(D10<=C10,"Pass", "Fail")) -> Fail | I10: =+B10 -> DCD - preset 15 - amplitude 0 | J10: 1000 | K10: =+G10/J10 -> 0 | O10: Divide value on BERTScope by 1000
A11: Core | B11: =+'Lane 1'!$B11 -> DCD - preset 15 - amplitude 1 | C11: =+'Lane 1'!C11 -> 0.035 | D11: =+K11 -> 0 | E11: UI | F11: =IF(G11="","Fail",IF(D11<=C11,"Pass", "Fail")) -> Fail | I11: =+B11 -> DCD - preset 15 - amplitude 1 | J11: 1000 | K11: =+G11/J11 -> 0 | O11: Divide value on BERTScope by 1000
A12: Core | B12: =+'Lane 1'!$B12 -> TJ - preset 0 | C12: =+'Lane 1'!C12 -> Used to calc TJ-DDJ | D12: =+K12 -> 0 | E12: UI | F12: N/A | I12: =+B12 -> TJ - preset 0 | J12: 1000 | K12: =+G12/J12 -> 0 | O12: Divide value on BERTScope by 1000
A13: Core | B13: =+'Lane 1'!$B13 -> TJ - preset 15 - amplitude 0 | C13: =+'Lane 1'!C13 -> Used to calc TJ-DDJ | D13: =+K13 -> 0 | E13: UI | F13: N/A | I13: =+B13 -> TJ - preset 15 - amplitude 0 | J13: 1000 | K13: =+G13/J13 -> 0 | O13: Divide value on BERTScope by 1000
A14: Core | B14: =+'Lane 1'!$B14 -> TJ - preset 15 - amplitude 1 | C14: =+'Lane 1'!C14 -> Used to calc TJ-DDJ | D14: =+K14 -> 0 | E14: UI | F14: N/A | I14: =+B14 -> TJ - preset 15 - amplitude 1 | J14: 1000 | K14: =+G14/J14 -> 0 | O14: Divide value on BERTScope by 1000
A15: Core | B15: =+'Lane 1'!$B15 -> DDJ - preset 0 | C15: =+'Lane 1'!C15 -> Used to calc TJ-DDJ | D15: =+K15 -> 0 | E15: UI | F15: N/A | I15: =+B15 -> DDJ - preset 0 | J15: 1000 | K15: =+G15/J15 -> 0 | O15: Divide value on BERTScope by 1000
A16: Core | B16: =+'Lane 1'!$B16 -> DDJ - preset 15 - amplitude 0 | C16: =+'Lane 1'!C16 -> Used to calc TJ-DDJ | D16: =+K16 -> 0 | E16: UI | F16: N/A | I16: =+B16 -> DDJ - preset 15 - amplitude 0 | J16: 1000 | K16: =+G16/J16 -> 0 | O16: Divide value on BERTScope by 1000
A17: Core | B17: =+'Lane 1'!$B17 -> DDJ - preset 15 - amplitude 1 | C17: =+'Lane 1'!C17 -> Used to calc TJ-DDJ | D17: =+K17 -> 0 | E17: UI | F17: N/A | I17: =+B17 -> DDJ - preset 15 - amplitude 1 | J17: 1000 | K17: =+G17/J17 -> 0 | O17: Divide value on BERTScope by 1000
A18: Core | B18: =+'Lane 1'!$B18 -> TJ-DDJ - preset 0 | C18: =+'Lane 1'!C18 -> 0.25 | D18: =+K18 -> 0 | E18: UI | F18: =IF(OR(G12="",D15=""),"Fail",IF(D18<=C18,"Pass", "Fail")) -> Fail | I18: =+B18 -> TJ-DDJ - preset 0 | K18: =+K12-K15 -> 0 | O18: Divide value on BERTScope by 1000
A19: Core | B19: =+'Lane 1'!$B19 -> TJ-DDJ - preset 15 - amplitude 0 | C19: =+'Lane 1'!C19 -> 0.25 | D19: =+K19 -> 0 | E19: UI | F19: =IF(OR(G13="",D16=""),"Fail",IF(D19<=C19,"Pass", "Fail")) -> Fail | I19: =+B19 -> TJ-DDJ - preset 15 - amplitude 0 | K19: =+K13-K16 -> 0 | O19: Divide value on BERTScope by 1000
A20: Core | B20: =+'Lane 1'!$B20 -> TJ-DDJ - preset 15 - amplitude 1 | C20: =+'Lane 1'!C20 -> 0.25 | D20: =+K20 -> 0 | E20: UI | F20: =IF(OR(G14="",D17=""),"Fail",IF(D20<=C20,"Pass", "Fail")) -> Fail | I20: =+B20 -> TJ-DDJ - preset 15 - amplitude 1 | K20: =+K14-K17 -> 0 | O20: Divide value on BERTScope by 1000
A21: Core | B21: =+'Lane 1'!$B21 -> J2 - preset 0 | C21: =+'Lane 1'!C21 -> 0.19 | D21: =+K21 -> 0 | E21: UI | F21: =IF(G21="","Fail",IF(D21<=C21,"Pass", "Fail")) -> Fail | I21: =+B21 -> J2 - preset 0 | J21: 1000 | K21: =+G21/J21 -> 0 | O21: Divide value on BERTScope by 1000
A22: Core | B22: =+'Lane 1'!$B22 -> J9 - preset 0 | C22: =+'Lane 1'!C22 -> 0.33 | D22: =+K22 -> 0 | E22: UI | F22: =IF(G22="","Fail",IF(D22<=C22,"Pass", "Fail")) -> Fail | I22: =+B22 -> J9 - preset 0 | J22: 1000 | K22: =+G22/J22 -> 0 | O22: Divide value on BERTScope by 1000
A23: Core | B23: =+'Lane 1'!$B23 -> DDPWS | C23: =+'Lane 1'!C23 -> 0.11 | D23: =+K23 -> 0 | E23: UI | F23: =IF(G23="","Fail",IF(D23<=C23,"Pass", "Fail")) -> Fail | I23: =+B23 -> DDPWS | J23: 1000 | K23: =+G23/J23 -> 0 | O23: Tektronix DDPWS
A24: Core | B24: =+'Lane 1'!$B24 -> DDPWS | C24: =+'Lane 1'!C24 -> 0.11 | D24: =+B79 -> 1 | E24: UI | F24: =IF(G24="","Fail",IF(D24<=C24,"Pass", "Fail")) -> Fail | I24: =+B24 -> DDPWS | O24: Agilent DDPWS - see calculation in Cell B40 | Q24: {='Lane 1'!Q24:R34} -> Testing Order | R24: 0
A25: Core | B25: =+'Lane 1'!$B25 -> X1, X2, Y1, Y2 | C25: =+'Lane 1'!C25 -> 5e-05 | D25: =+L25/(M25*N25) -> 0 | E25: UI | F25: =IF(L25="","NT",IF(D25<=C25,"Pass", "Fail")) -> NT | G25: See columns L-M | I25: =+B25 -> X1, X2, Y1, Y2 | M25: 110 | N25: 16200 | O25: BERTScope Eye Mask | Q25: Preset 0 | R25: Agilent and then BERTScope
A26: Core | B26: =+'Lane 1'!$B26 -> X1, X2, Y1, Y2 | C26: =+'Lane 1'!C26 -> 5e-05 | D26: =+L26/(M26*N26) -> 0 | E26: UI | F26: =IF(L26="","Fail",IF(D26<=C26,"Pass", "Fail")) -> Fail | I26: =+B26 -> X1, X2, Y1, Y2 | M26: 110 | N26: 16200 | O26: Agilent Eye Mask | Q26: Eye Mask | R26: Make sure settings are correct.
A27: Core | B27: =+'Lane 1'!$B27 -> Tr | C27: =+'Lane 1'!C27 -> 24 | D27: =+G27 -> 0 | E27: ps | F27: =IF(D27="","Fail",IF(D27>=C27,"Pass","Fail")) -> Fail | I27: =+B27 -> Tr | Q27: Tr | R27: PRBS11
A28: Core | B28: =+'Lane 1'!$B28 -> Tf | C28: =+'Lane 1'!C28 -> 24 | D28: =+G28 -> 0 | E28: ps | F28: =IF(D28="","Fail",IF(D28>=C28,"Pass","Fail")) -> Fail | I28: =+B28 -> Tf | Q28: tf | R28: PRBS11
A29: Secondary | B29: =+'Lane 1'!$B29 -> Vcm preset 0 | C29: =+'Lane 1'!C29 -> 20 | D29: =+K29 -> 0 | E29: mV RMS | F29: =IF(G29="","Fail",IF(D29<=C29,"Pass", "Fail")) -> Fail | I29: =+B29 -> Vcm preset 0 | J29: 2 | K29: =+G29/J29 -> 0 | O29: AC common mode output voltage. Scope value is divided by two. | Q29: vcm | R29: Take Max value
A30: Secondary | B30: =+'Lane 1'!$B30 -> Vcm preset 2 - amplitude 0 | C30: =+'Lane 1'!C30 -> 30 | D30: =+K30 -> 0 | E30: mV RMS | F30: =IF(G30="","Fail",IF(D30<=C30,"Pass", "Fail")) -> Fail | I30: =+B30 -> Vcm preset 2 - amplitude 0 | J30: 2 | K30: =+G30/J30 -> 0 | O30: AC common mode output voltage. Scope value is divided by two. | Q30: vdiffp | R30: Take Max value
A31: Secondary | B31: =+'Lane 1'!$B31 -> Vcm preset 2 - amplitude 1 | C31: =+'Lane 1'!C31 -> 30 | D31: =+K31 -> 0 | E31: mV RMS | F31: =IF(G31="","Fail",IF(D31<=C31,"Pass", "Fail")) -> Fail | I31: =+B31 -> Vcm preset 2 - amplitude 1 | J31: 2 | K31: =+G31/J31 -> 0 | O31: AC common mode output voltage. Scope value is divided by two. | Q31: DDPWs | R31: See calculations in B71:76
A32: Secondary | B32: =+'Lane 1'!$B32 -> Vcm preset 15 - amplitude 0 | C32: =+'Lane 1'!C32 -> 30 | D32: =+K32 -> 0 | E32: mV RMS | F32: =IF(G32="","Fail",IF(D32<=C32,"Pass", "Fail")) -> Fail | I32: =+B32 -> Vcm preset 15 - amplitude 0 | J32: 2 | K32: =+G32/J32 -> 0 | O32: AC common mode output voltage. Scope value is divided by two. | Q32: Preset 1 | R32: 0
A33: Secondary | B33: =+'Lane 1'!$B33 -> Vcm preset 15 - amplitude 1 | C33: =+'Lane 1'!C33 -> 30 | D33: =+K33 -> 0 | E33: mV RMS | F33: =IF(G33="","Fail",IF(D33<=C33,"Pass", "Fail")) -> Fail | I33: =+B33 -> Vcm preset 15 - amplitude 1 | J33: 2 | K33: =+G33/J33 -> 0 | O33: AC common mode output voltage. Scope value is divided by two. | Q33: Preset 2 | R33: 0
A34: Core | B34: =+'Lane 1'!$B34 -> Vdiffpp | C34: =+'Lane 1'!C34 -> 30 | D34: =+G34 -> 0 | E34: mV | F34: =IF(G34="","Fail",IF(D34<=C34,"Pass", "Fail")) -> Fail | I34: =+B34 -> Vdiffpp | Q34: Preset 15 | R34: 0
A35: Secondary | B35: =+'Lane 1'!$B35 -> e preset 1 - amplitude 0 | C35: =+'Lane 1'!C35 -> 0.037 | D35: =+G35 -> 0 | F35: =IF(G35="","Fail",IF(D35<=C35,"Pass", "Fail")) -> Fail | I35: =+B35 -> e preset 1 - amplitude 0
A36: Secondary | B36: =+'Lane 1'!$B36 -> e preset 1 - amplitude 1 | C36: =+'Lane 1'!C36 -> 0.037 | D36: =+G36 -> 0 | F36: =IF(G36="","Fail",IF(D36<=C36,"Pass", "Fail")) -> Fail | I36: =+B36 -> e preset 1 - amplitude 1 | O36: rms_normalized_e - checked in preset 1 only
A37: Secondary | B37: =+'Lane 1'!$B37 -> e preset 2 - amplitude 0 | C37: =+'Lane 1'!C37 -> 0.037 | D37: =+G37 -> 0 | F37: =IF(G37="","Fail",IF(D37<=C37,"Pass", "Fail")) -> Fail | I37: =+B37 -> e preset 2 - amplitude 0
A38: Secondary | B38: =+'Lane 1'!$B38 -> e preset 2 - amplitude 1 | C38: =+'Lane 1'!C38 -> 0.037 | D38: =+G38 -> 0 | F38: =IF(G38="","Fail",IF(D38<=C38,"Pass", "Fail")) -> Fail | I38: =+B38 -> e preset 2 - amplitude 1
A39: Secondary | B39: =+'Lane 1'!$B39 -> e preset 15 - amplitude 0 | C39: =+'Lane 1'!C39 -> 0.037 | D39: =+G39 -> 0 | F39: =IF(G39="","Fail",IF(D39<=C39,"Pass", "Fail")) -> Fail | I39: =+B39 -> e preset 15 - amplitude 0
A40: Secondary | B40: =+'Lane 1'!$B40 -> e preset 15 - amplitude 1 | C40: =+'Lane 1'!C40 -> 0.037 | D40: =+G40 -> 0 | F40: =IF(G40="","Fail",IF(D40<=C40,"Pass", "Fail")) -> Fail | I40: =+B40 -> e preset 15 - amplitude 1
...

Sheet Lane 3
A1: Transmitter Tests
A2: Priority | B2: Parameter | C2: Spec See Page 1 | D2: Calculated Results | E2: Measurement Units | F2: Pass/Fail | G2: Measured | H2: Frequency in GHz | I2: Parameter | J2: Factor | K2: Conversion | L2: # Fails | M2: # Waveforms | N2: Samples Per Waveform | O2: Comments
A3: Core | B3: =+'Lane 1'!$B3 -> SDD22 | C3: =IF(D3="","NT",IF(H3<=5.6,-12+1.71*SQRT(H3),-6.7+13*LOG10((H3/7)))) -> -12 | D3: =+G3 -> 0 | E3: dB | F3: =IF(D3="","Fail",IF(D3<=C3,"Pass", "Fail")) -> Fail | I3: =+B3 -> SDD22
A4: Core | B4: =+'Lane 1'!$B4 -> SCC22 | C4: =IF(D4="","NT",-2) -> -2 | D4: =+G4 -> 0 | E4: dB | F4: =IF(D4="","Fail",IF(D4<=C4,"Pass", "Fail")) -> Fail | I4: =+B4 -> SCC22
A5: Core | B5: =+'Lane 1'!$B5 -> SDC22 | C5: =IF(D5="","NT",-16+((2/3)*H5)) -> -16 | D5: =+G5 -> 0 | E5: dB | F5: =IF(D5="","Fail",IF(D5<=C5,"Pass", "Fail")) -> Fail | I5: =+B5 -> SDC22
A6: Core | B6: =+'Lane 1'!$B6 -> RJ - preset 0 | C6: =+'Lane 1'!C6 -> 0.15 | D6: =+K6 -> 0 | E6: UI | F6: =IF(G6="","Fail",IF(D6<=C6,"Pass", "Fail")) -> Fail | I6: =+B6 -> RJ - preset 0 | J6: 14.069 | K6: =(G6/1000)*J6 -> 0 | O6: Converted from RMS to the spec value - P2P
A7: Core | B7: =+'Lane 1'!$B7 -> RJ - preset 15 - Amplitude 0 | C7: =+'Lane 1'!C7 -> 0.15 | D7: =+K7 -> 0 | E7: UI | F7: =IF(G7="","Fail",IF(D7<=C7,"Pass", "Fail")) -> Fail | I7: =+B7 -> RJ - preset 15 - Amplitude 0 | J7: 14.069 | K7: =(G7/1000)*J7 -> 0 | O7: Converted from RMS to the spec value - P2P
A8: Core | B8: =+'Lane 1'!$B8 -> RJ - preset 15 - Amplitude 1 | C8: =+'Lane 1'!C8 -> 0.15 | D8: =+K8 -> 0 | E8: UI | F8: =IF(G8="","Fail",IF(D8<=C8,"Pass", "Fail")) -> Fail | I8: =+B8 -> RJ - preset 15 - Amplitude 1 | J8: 14.069 | K8: =(G8/1000)*J8 -> 0 | O8: Converted from RMS to the spec value - P2P
A9: Core | B9: =+'Lane 1'!$B9 -> DCD - preset 0 | C9: =+'Lane 1'!C9 -> 0.035 | D9: =+K9 -> 0 | E9: UI | F9: =IF(G9="","Fail",IF(D9<=C9,"Pass", "Fail")) -> Fail | I9: =+B9 -> DCD - preset 0 | J9: 1000 | K9: =+G9/J9 -> 0 | O9: Divide value on BERTScope by 1000
A10: Core | B10: =+'Lane 1'!$B10 -> DCD - preset 15 - amplitude 0 | C10: =+'Lane 1'!C10 -> 0.035 | D10: =+K10 -> 0 | E10: UI | F10: =IF(G10="","Fail",IF(D10<=C10,"Pass", "Fail")) -> Fail | I10: =+B10 -> DCD - preset 15 - amplitude 0 | J10: 1000 | K10: =+G10/J10 -> 0 | O10: Divide value on BERTScope by 1000
A11: Core | B11: =+'Lane 1'!$B11 -> DCD - preset 15 - amplitude 1 | C11: =+'Lane 1'!C11 -> 0.035 | D11: =+K11 -> 0 | E11: UI | F11: =IF(G11="","Fail",IF(D11<=C11,"Pass", "Fail")) -> Fail | I11: =+B11 -> DCD - preset 15 - amplitude 1 | J11: 1000 | K11: =+G11/J11 -> 0 | O11: Divide value on BERTScope by 1000
A12: Core | B12: =+'Lane 1'!$B12 -> TJ - preset 0 | C12: =+'Lane 1'!C12 -> Used to calc TJ-DDJ | D12: =+K12 -> 0 | E12: UI | F12: N/A | I12: =+B12 -> TJ - preset 0 | J12: 1000 | K12: =+G12/J12 -> 0 | O12: Divide value on BERTScope by 1000
A13: Core | B13: =+'Lane 1'!$B13 -> TJ - preset 15 - amplitude 0 | C13: =+'Lane 1'!C13 -> Used to calc TJ-DDJ | D13: =+K13 -> 0 | E13: UI | F13: N/A | I13: =+B13 -> TJ - preset 15 - amplitude 0 | J13: 1000 | K13: =+G13/J13 -> 0 | O13: Divide value on BERTScope by 1000
A14: Core | B14: =+'Lane 1'!$B14 -> TJ - preset 15 - amplitude 1 | C14: =+'Lane 1'!C14 -> Used to calc TJ-DDJ | D14: =+K14 -> 0 | E14: UI | F14: N/A | I14: =+B14 -> TJ - preset 15 - amplitude 1 | J14: 1000 | K14: =+G14/J14 -> 0 | O14: Divide value on BERTScope by 1000
A15: Core | B15: =+'Lane 1'!$B15 -> DDJ - preset 0 | C15: =+'Lane 1'!C15 -> Used to calc TJ-DDJ | D15: =+K15 -> 0 | E15: UI | F15: N/A | I15: =+B15 -> DDJ - preset 0 | J15: 1000 | K15: =+G15/J15 -> 0 | O15: Divide value on BERTScope by 1000
A16: Core | B16: =+'Lane 1'!$B16 -> DDJ - preset 15 - amplitude 0 | C16: =+'Lane 1'!C16 -> Used to calc TJ-DDJ | D16: =+K16 -> 0 | E16: UI | F16: N/A | I16: =+B16 -> DDJ - preset 15 - amplitude 0 | J16: 1000 | K16: =+G16/J16 -> 0 | O16: Divide value on BERTScope by 1000
A17: Core | B17: =+'Lane 1'!$B17 -> DDJ - preset 15 - amplitude 1 | C17: =+'Lane 1'!C17 -> Used to calc TJ-DDJ | D17: =+K17 -> 0 | E17: UI | F17: N/A | I17: =+B17 -> DDJ - preset 15 - amplitude 1 | J17: 1000 | K17: =+G17/J17 -> 0 | O17: Divide value on BERTScope by 1000
A18: Core | B18: =+'Lane 1'!$B18 -> TJ-DDJ - preset 0 | C18: =+'Lane 1'!C18 -> 0.25 | D18: =+K18 -> 0 | E18: UI | F18: =IF(OR(G12="",D15=""),"Fail",IF(D18<=C18,"Pass", "Fail")) -> Fail | I18: =+B18 -> TJ-DDJ - preset 0 | K18: =+K12-K15 -> 0 | O18: Divide value on BERTScope by 1000
A19: Core | B19: =+'Lane 1'!$B19 -> TJ-DDJ - preset 15 - amplitude 0 | C19: =+'Lane 1'!C19 -> 0.25 | D19: =+K19 -> 0 | E19: UI | F19: =IF(OR(G13="",D16=""),"Fail",IF(D19<=C19,"Pass", "Fail")) -> Fail | I19: =+B19 -> TJ-DDJ - preset 15 - amplitude 0 | K19: =+K13-K16 -> 0 | O19: Divide value on BERTScope by 1000
A20: Core | B20: =+'Lane 1'!$B20 -> TJ-DDJ - preset 15 - amplitude 1 | C20: =+'Lane 1'!C20 -> 0.25 | D20: =+K20 -> 0 | E20: UI | F20: =IF(OR(G14="",D17=""),"Fail",IF(D20<=C20,"Pass", "Fail")) -> Fail | I20: =+B20 -> TJ-DDJ - preset 15 - amplitude 1 | K20: =+K14-K17 -> 0 | O20: Divide value on BERTScope by 1000
A21: Core | B21: =+'Lane 1'!$B21 -> J2 - preset 0 | C21: =+'Lane 1'!C21 -> 0.19 | D21: =+K21 -> 0 | E21: UI | F21: =IF(G21="","Fail",IF(D21<=C21,"Pass", "Fail")) -> Fail | I21: =+B21 -> J2 - preset 0 | J21: 1000 | K21: =+G21/J21 -> 0 | O21: Divide value on BERTScope by 1000
A22: Core | B22: =+'Lane 1'!$B22 -> J9 - preset 0 | C22: =+'Lane 1'!C22 -> 0.33 | D22: =+K22 -> 0 | E22: UI | F22: =IF(G22="","Fail",IF(D22<=C22,"Pass", "Fail")) -> Fail | I22: =+B22 -> J9 - preset 0 | J22: 1000 | K22: =+G22/J22 -> 0 | O22: Divide value on BERTScope by 1000
A23: Core | B23: =+'Lane 1'!$B23 -> DDPWS | C23: =+'Lane 1'!C23 -> 0.11 | D23: =+K23 -> 0 | E23: UI | F23: =IF(G23="","Fail",IF(D23<=C23,"Pass", "Fail")) -> Fail | I23: =+B23 -> DDPWS | J23: 1000 | K23: =+G23/J23 -> 0 | O23: Tektronix DDPWS
A24: Core | B24: =+'Lane 1'!$B24 -> DDPWS | C24: =+'Lane 1'!C24 -> 0.11 | D24: =+B79 -> 1 | E24: UI | F24: =IF(G24="","Fail",IF(D24<=C24,"Pass", "Fail")) -> Fail | I24: =+B24 -> DDPWS | O24: Agilent DDPWS - see calculation in Cell B40 | Q24: {='Lane 1'!Q24:R34} -> Testing Order | R24: 0
A25: Core | B25: =+'Lane 1'!$B25 -> X1, X2, Y1, Y2 | C25: =+'Lane 1'!C25 -> 5e-05 | D25: =+L25/(M25*N25) -> 0 | E25: UI | F25: =IF(L25="","NT",IF(D25<=C25,"Pass", "Fail")) -> NT | G25: See columns L-M | I25: =+B25 -> X1, X2, Y1, Y2 | M25: 110 | N25: 16200 | O25: BERTScope Eye Mask | Q25: Preset 0 | R25: Agilent and then BERTScope
A26: Core | B26: =+'Lane 1'!$B26 -> X1, X2, Y1, Y2 | C26: =+'Lane 1'!C26 -> 5e-05 | D26: =+L26/(M26*N26) -> 0 | E26: UI | F26: =IF(L26="","Fail",IF(D26<=C26,"Pass", "Fail")) -> Fail | I26: =+B26 -> X1, X2, Y1, Y2 | M26: 110 | N26: 16200 | O26: Agilent Eye Mask | Q26: Eye Mask | R26: Make sure settings are correct.
A27: Core | B27: =+'Lane 1'!$B27 -> Tr | C27: =+'Lane 1'!C27 -> 24 | D27: =+G27 -> 0 | E27: ps | F27: =IF(D27="","Fail",IF(D27>=C27,"Pass","Fail")) -> Fail | I27: =+B27 -> Tr | Q27: Tr | R27: PRBS11
A28: Core | B28: =+'Lane 1'!$B28 -> Tf | C28: =+'Lane 1'!C28 -> 24 | D28: =+G28 -> 0 | E28: ps | F28: =IF(D28="","Fail",IF(D28>=C28,"Pass","Fail")) -> Fail | I28: =+B28 -> Tf | Q28: tf | R28: PRBS11
A29: Secondary | B29: =+'Lane 1'!$B29 -> Vcm preset 0 | C29: =+'Lane 1'!C29 -> 20 | D29: =+K29 -> 0 | E29: mV RMS | F29: =IF(G29="","Fail",IF(D29<=C29,"Pass", "Fail")) -> Fail | I29: =+B29 -> Vcm preset 0 | J29: 2 | K29: =+G29/J29 -> 0 | O29: AC common mode output voltage. Scope value is divided by two. | Q29: vcm | R29: Take Max value
A30: Secondary | B30: =+'Lane 1'!$B30 -> Vcm preset 2 - amplitude 0 | C30: =+'Lane 1'!C30 -> 30 | D30: =+K30 -> 0 | E30: mV RMS | F30: =IF(G30="","Fail",IF(D30<=C30,"Pass", "Fail")) -> Fail | I30: =+B30 -> Vcm preset 2 - amplitude 0 | J30: 2 | K30: =+G30/J30 -> 0 | O30: AC common mode output voltage. Scope value is divided by two. | Q30: vdiffp | R30: Take Max value
A31: Secondary | B31: =+'Lane 1'!$B31 -> Vcm preset 2 - amplitude 1 | C31: =+'Lane 1'!C31 -> 30 | D31: =+K31 -> 0 | E31: mV RMS | F31: =IF(G31="","Fail",IF(D31<=C31,"Pass", "Fail")) -> Fail | I31: =+B31 -> Vcm preset 2 - amplitude 1 | J31: 2 | K31: =+G31/J31 -> 0 | O31: AC common mode output voltage. Scope value is divided by two. | Q31: DDPWs | R31: See calculations in B71:76
A32: Secondary | B32: =+'Lane 1'!$B32 -> Vcm preset 15 - amplitude 0 | C32: =+'Lane 1'!C32 -> 30 | D32: =+K32 -> 0 | E32: mV RMS | F32: =IF(G32="","Fail",IF(D32<=C32,"Pass", "Fail")) -> Fail | I32: =+B32 -> Vcm preset 15 - amplitude 0 | J32: 2 | K32: =+G32/J32 -> 0 | O32: AC common mode output voltage. Scope value is divided by two. | Q32: Preset 1 | R32: 0
A33: Secondary | B33: =+'Lane 1'!$B33 -> Vcm preset 15 - amplitude 1 | C33: =+'Lane 1'!C33 -> 30 | D33: =+K33 -> 0 | E33: mV RMS | F33: =IF(G33="","Fail",IF(D33<=C33,"Pass", "Fail")) -> Fail | I33: =+B33 -> Vcm preset 15 - amplitude 1 | J33: 2 | K33: =+G33/J33 -> 0 | O33: AC common mode output voltage. Scope value is divided by two. | Q33: Preset 2 | R33: 0
A34: Core | B34: =+'Lane 1'!$B34 -> Vdiffpp | C34: =+'Lane 1'!C34 -> 30 | D34: =+G34 -> 0 | E34: mV | F34: =IF(G34="","Fail",IF(D34<=C34,"Pass", "Fail")) -> Fail | I34: =+B34 -> Vdiffpp | Q34: Preset 15 | R34: 0
A35: Secondary | B35: =+'Lane 1'!$B35 -> e preset 1 - amplitude 0 | C35: =+'Lane 1'!C35 -> 0.037 | D35: =+G35 -> 0 | F35: =IF(G35="","Fail",IF(D35<=C35,"Pass", "Fail")) -> Fail | I35: =+B35 -> e preset 1 - amplitude 0
A36: Secondary | B36: =+'Lane 1'!$B36 -> e preset 1 - amplitude 1 | C36: =+'Lane 1'!C36 -> 0.037 | D36: =+G36 -> 0 | F36: =IF(G36="","Fail",IF(D36<=C36,"Pass", "Fail")) -> Fail | I36: =+B36 -> e preset 1 - amplitude 1 | O36: rms_normalized_e - checked in preset 1 only
A37: Secondary | B37: =+'Lane 1'!$B37 -> e preset 2 - amplitude 0 | C37: =+'Lane 1'!C37 -> 0.037 | D37: =+G37 -> 0 | F37: =IF(G37="","Fail",IF(D37<=C37,"Pass", "Fail")) -> Fail | I37: =+B37 -> e preset 2 - amplitude 0
A38: Secondary | B38: =+'Lane 1'!$B38 -> e preset 2 - amplitude 1 | C38: =+'Lane 1'!C38 -> 0.037 | D38: =+G38 -> 0 | F38: =IF(G38="","Fail",IF(D38<=C38,"Pass", "Fail")) -> Fail | I38: =+B38 -> e preset 2 - amplitude 1
A39: Secondary | B39: =+'Lane 1'!$B39 -> e preset 15 - amplitude 0 | C39: =+'Lane 1'!C39 -> 0.037 | D39: =+G39 -> 0 | F39: =IF(G39="","Fail",IF(D39<=C39,"Pass", "Fail")) -> Fail | I39: =+B39 -> e preset 15 - amplitude 0
A40: Secondary | B40: =+'Lane 1'!$B40 -> e preset 15 - amplitude 1 | C40: =+'Lane 1'!C40 -> 0.037 | D40: =+G40 -> 0 | F40: =IF(G40="","Fail",IF(D40<=C40,"Pass", "Fail")) -> Fail | I40: =+B40 -> e preset 15 - amplitude 1
...

Sheet Lane 4
A1: Transmitter Tests
A2: Priority | B2: Parameter | C2: Spec See Page 1 | D2: Calculated Results | E2: Measurement Units | F2: Pass/Fail | G2: Measured | H2: Frequency in GHz | I2: Parameter | J2: Factor | K2: Conversion | L2: # Fails | M2: # Waveforms | N2: Samples Per Waveform | O2: Comments
A3: Core | B3: =+'Lane 1'!$B3 -> SDD22 | C3: =IF(D3="","NT",IF(H3<=5.6,-12+1.71*SQRT(H3),-6.7+13*LOG10((H3/7)))) -> -12 | D3: =+G3 -> 0 | E3: dB | F3: =IF(D3="","Fail",IF(D3<=C3,"Pass", "Fail")) -> Fail | I3: =+B3 -> SDD22
A4: Core | B4: =+'Lane 1'!$B4 -> SCC22 | C4: =IF(D4="","NT",-2) -> -2 | D4: =+G4 -> 0 | E4: dB | F4: =IF(D4="","Fail",IF(D4<=C4,"Pass", "Fail")) -> Fail | I4: =+B4 -> SCC22
A5: Core | B5: =+'Lane 1'!$B5 -> SDC22 | C5: =IF(D5="","NT",-16+((2/3)*H5)) -> -16 | D5: =+G5 -> 0 | E5: dB | F5: =IF(D5="","Fail",IF(D5<=C5,"Pass", "Fail")) -> Fail | I5: =+B5 -> SDC22
A6: Core | B6: =+'Lane 1'!$B6 -> RJ - preset 0 | C6: =+'Lane 1'!C6 -> 0.15 | D6: =+K6 -> 0 | E6: UI | F6: =IF(G6="","Fail",IF(D6<=C6,"Pass", "Fail")) -> Fail | I6: =+B6 -> RJ - preset 0 | J6: 14.069 | K6: =(G6/1000)*J6 -> 0 | O6: Converted from RMS to the spec value - P2P
A7: Core | B7: =+'Lane 1'!$B7 -> RJ - preset 15 - Amplitude 0 | C7: =+'Lane 1'!C7 -> 0.15 | D7: =+K7 -> 0 | E7: UI | F7: =IF(G7="","Fail",IF(D7<=C7,"Pass", "Fail")) -> Fail | I7: =+B7 -> RJ - preset 15 - Amplitude 0 | J7: 14.069 | K7: =(G7/1000)*J7 -> 0 | O7: Converted from RMS to the spec value - P2P
A8: Core | B8: =+'Lane 1'!$B8 -> RJ - preset 15 - Amplitude 1 | C8: =+'Lane 1'!C8 -> 0.15 | D8: =+K8 -> 0 | E8: UI | F8: =IF(G8="","Fail",IF(D8<=C8,"Pass", "Fail")) -> Fail | I8: =+B8 -> RJ - preset 15 - Amplitude 1 | J8: 14.069 | K8: =(G8/1000)*J8 -> 0 | O8: Converted from RMS to the spec value - P2P
A9: Core | B9: =+'Lane 1'!$B9 -> DCD - preset 0 | C9: =+'Lane 1'!C9 -> 0.035 | D9: =+K9 -> 0 | E9: UI | F9: =IF(G9="","Fail",IF(D9<=C9,"Pass", "Fail")) -> Fail | I9: =+B9 -> DCD - preset 0 | J9: 1000 | K9: =+G9/J9 -> 0 | O9: Divide value on BERTScope by 1000
A10: Core | B10: =+'Lane 1'!$B10 -> DCD - preset 15 - amplitude 0 | C10: =+'Lane 1'!C10 -> 0.035 | D10: =+K10 -> 0 | E10: UI | F10: =IF(G10="","Fail",IF(D10<=C10,"Pass", "Fail")) -> Fail | I10: =+B10 -> DCD - preset 15 - amplitude 0 | J10: 1000 | K10: =+G10/J10 -> 0 | O10: Divide value on BERTScope by 1000
A11: Core | B11: =+'Lane 1'!$B11 -> DCD - preset 15 - amplitude 1 | C11: =+'Lane 1'!C11 -> 0.035 | D11: =+K11 -> 0 | E11: UI | F11: =IF(G11="","Fail",IF(D11<=C11,"Pass", "Fail")) -> Fail | I11: =+B11 -> DCD - preset 15 - amplitude 1 | J11: 1000 | K11: =+G11/J11 -> 0 | O11: Divide value on BERTScope by 1000
A12: Core | B12: =+'Lane 1'!$B12 -> TJ - preset 0 | C12: =+'Lane 1'!C12 -> Used to calc TJ-DDJ | D12: =+K12 -> 0 | E12: UI | F12: N/A | I12: =+B12 -> TJ - preset 0 | J12: 1000 | K12: =+G12/J12 -> 0 | O12: Divide value on BERTScope by 1000
A13: Core | B13: =+'Lane 1'!$B13 -> TJ - preset 15 - amplitude 0 | C13: =+'Lane 1'!C13 -> Used to calc TJ-DDJ | D13: =+K13 -> 0 | E13: UI | F13: N/A | I13: =+B13 -> TJ - preset 15 - amplitude 0 | J13: 1000 | K13: =+G13/J13 -> 0 | O13: Divide value on BERTScope by 1000
A14: Core | B14: =+'Lane 1'!$B14 -> TJ - preset 15 - amplitude 1 | C14: =+'Lane 1'!C14 -> Used to calc TJ-DDJ | D14: =+K14 -> 0 | E14: UI | F14: N/A | I14: =+B14 -> TJ - preset 15 - amplitude 1 | J14: 1000 | K14: =+G14/J14 -> 0 | O14: Divide value on BERTScope by 1000
A15: Core | B15: =+'Lane 1'!$B15 -> DDJ - preset 0 | C15: =+'Lane 1'!C15 -> Used to calc TJ-DDJ | D15: =+K15 -> 0 | E15: UI | F15: N/A | I15: =+B15 -> DDJ - preset 0 | J15: 1000 | K15: =+G15/J15 -> 0 | O15: Divide value on BERTScope by 1000
A16: Core | B16: =+'Lane 1'!$B16 -> DDJ - preset 15 - amplitude 0 | C16: =+'Lane 1'!C16 -> Used to calc TJ-DDJ | D16: =+K16 -> 0 | E16: UI | F16: N/A | I16: =+B16 -> DDJ - preset 15 - amplitude 0 | J16: 1000 | K16: =+G16/J16 -> 0 | O16: Divide value on BERTScope by 1000
A17: Core | B17: =+'Lane 1'!$B17 -> DDJ - preset 15 - amplitude 1 | C17: =+'Lane 1'!C17 -> Used to calc TJ-DDJ | D17: =+K17 -> 0 | E17: UI | F17: N/A | I17: =+B17 -> DDJ - preset 15 - amplitude 1 | J17: 1000 | K17: =+G17/J17 -> 0 | O17: Divide value on BERTScope by 1000
A18: Core | B18: =+'Lane 1'!$B18 -> TJ-DDJ - preset 0 | C18: =+'Lane 1'!C18 -> 0.25 | D18: =+K18 -> 0 | E18: UI | F18: =IF(OR(G12="",D15=""),"Fail",IF(D18<=C18,"Pass", "Fail")) -> Fail | I18: =+B18 -> TJ-DDJ - preset 0 | K18: =+K12-K15 -> 0 | O18: Divide value on BERTScope by 1000
A19: Core | B19: =+'Lane 1'!$B19 -> TJ-DDJ - preset 15 - amplitude 0 | C19: =+'Lane 1'!C19 -> 0.25 | D19: =+K19 -> 0 | E19: UI | F19: =IF(OR(G13="",D16=""),"Fail",IF(D19<=C19,"Pass", "Fail")) -> Fail | I19: =+B19 -> TJ-DDJ - preset 15 - amplitude 0 | K19: =+K13-K16 -> 0 | O19: Divide value on BERTScope by 1000
A20: Core | B20: =+'Lane 1'!$B20 -> TJ-DDJ - preset 15 - amplitude 1 | C20: =+'Lane 1'!C20 -> 0.25 | D20: =+K20 -> 0 | E20: UI | F20: =IF(OR(G14="",D17=""),"Fail",IF(D20<=C20,"Pass", "Fail")) -> Fail | I20: =+B20 -> TJ-DDJ - preset 15 - amplitude 1 | K20: =+K14-K17 -> 0 | O20: Divide value on BERTScope by 1000
A21: Core | B21: =+'Lane 1'!$B21 -> J2 - preset 0 | C21: =+'Lane 1'!C21 -> 0.19 | D21: =+K21 -> 0 | E21: UI | F21: =IF(G21="","Fail",IF(D21<=C21,"Pass", "Fail")) -> Fail | I21: =+B21 -> J2 - preset 0 | J21: 1000 | K21: =+G21/J21 -> 0 | O21: Divide value on BERTScope by 1000
A22: Core | B22: =+'Lane 1'!$B22 -> J9 - preset 0 | C22: =+'Lane 1'!C22 -> 0.33 | D22: =+K22 -> 0 | E22: UI | F22: =IF(G22="","Fail",IF(D22<=C22,"Pass", "Fail")) -> Fail | I22: =+B22 -> J9 - preset 0 | J22: 1000 | K22: =+G22/J22 -> 0 | O22: Divide value on BERTScope by 1000
A23: Core | B23: =+'Lane 1'!$B23 -> DDPWS | C23: =+'Lane 1'!C23 -> 0.11 | D23: =+K23 -> 0 | E23: UI | F23: =IF(G23="","Fail",IF(D23<=C23,"Pass", "Fail")) -> Fail | I23: =+B23 -> DDPWS | J23: 1000 | K23: =+G23/J23 -> 0 | O23: Tektronix DDPWS
A24: Core | B24: =+'Lane 1'!$B24 -> DDPWS | C24: =+'Lane 1'!C24 -> 0.11 | D24: =+B79 -> 1 | E24: UI | F24: =IF(G24="","Fail",IF(D24<=C24,"Pass", "Fail")) -> Fail | I24: =+B24 -> DDPWS | O24: Agilent DDPWS - see calculation in Cell B40 | Q24: {='Lane 1'!Q24:R34} -> Testing Order | R24: 0
A25: Core | B25: =+'Lane 1'!$B25 -> X1, X2, Y1, Y2 | C25: =+'Lane 1'!C25 -> 5e-05 | D25: =+L25/(M25*N25) -> 0 | E25: UI | F25: =IF(L25="","NT",IF(D25<=C25,"Pass", "Fail")) -> NT | G25: See columns L-M | I25: =+B25 -> X1, X2, Y1, Y2 | M25: 110 | N25: 16200 | O25: BERTScope Eye Mask | Q25: Preset 0 | R25: Agilent and then BERTScope
A26: Core | B26: =+'Lane 1'!$B26 -> X1, X2, Y1, Y2 | C26: =+'Lane 1'!C26 -> 5e-05 | D26: =+L26/(M26*N26) -> 0 | E26: UI | F26: =IF(L26="","Fail",IF(D26<=C26,"Pass", "Fail")) -> Fail | I26: =+B26 -> X1, X2, Y1, Y2 | M26: 110 | N26: 16200 | O26: Agilent Eye Mask | Q26: Eye Mask | R26: Make sure settings are correct.
A27: Core | B27: =+'Lane 1'!$B27 -> Tr | C27: =+'Lane 1'!C27 -> 24 | D27: =+G27 -> 0 | E27: ps | F27: =IF(D27="","Fail",IF(D27>=C27,"Pass","Fail")) -> Fail | I27: =+B27 -> Tr | Q27: Tr | R27: PRBS11
A28: Core | B28: =+'Lane 1'!$B28 -> Tf | C28: =+'Lane 1'!C28 -> 24 | D28: =+G28 -> 0 | E28: ps | F28: =IF(D28="","Fail",IF(D28>=C28,"Pass","Fail")) -> Fail | I28: =+B28 -> Tf | Q28: tf | R28: PRBS11
A29: Secondary | B29: =+'Lane 1'!$B29 -> Vcm preset 0 | C29: =+'Lane 1'!C29 -> 20 | D29: =+K29 -> 0 | E29: mV RMS | F29: =IF(G29="","Fail",IF(D29<=C29,"Pass", "Fail")) -> Fail | I29: =+B29 -> Vcm preset 0 | J29: 2 | K29: =+G29/J29 -> 0 | O29: AC common mode output voltage. Scope value is divided by two. | Q29: vcm | R29: Take Max value
A30: Secondary | B30: =+'Lane 1'!$B30 -> Vcm preset 2 - amplitude 0 | C30: =+'Lane 1'!C30 -> 30 | D30: =+K30 -> 0 | E30: mV RMS | F30: =IF(G30="","Fail",IF(D30<=C30,"Pass", "Fail")) -> Fail | I30: =+B30 -> Vcm preset 2 - amplitude 0 | J30: 2 | K30: =+G30/J30 -> 0 | O30: AC common mode output voltage. Scope value is divided by two. | Q30: vdiffp | R30: Take Max value
A31: Secondary | B31: =+'Lane 1'!$B31 -> Vcm preset 2 - amplitude 1 | C31: =+'Lane 1'!C31 -> 30 | D31: =+K31 -> 0 | E31: mV RMS | F31: =IF(G31="","Fail",IF(D31<=C31,"Pass", "Fail")) -> Fail | I31: =+B31 -> Vcm preset 2 - amplitude 1 | J31: 2 | K31: =+G31/J31 -> 0 | O31: AC common mode output voltage. Scope value is divided by two. | Q31: DDPWs | R31: See calculations in B71:76
A32: Secondary | B32: =+'Lane 1'!$B32 -> Vcm preset 15 - amplitude 0 | C32: =+'Lane 1'!C32 -> 30 | D32: =+K32 -> 0 | E32: mV RMS | F32: =IF(G32="","Fail",IF(D32<=C32,"Pass", "Fail")) -> Fail | I32: =+B32 -> Vcm preset 15 - amplitude 0 | J32: 2 | K32: =+G32/J32 -> 0 | O32: AC common mode output voltage. Scope value is divided by two. | Q32: Preset 1 | R32: 0
A33: Secondary | B33: =+'Lane 1'!$B33 -> Vcm preset 15 - amplitude 1 | C33: =+'Lane 1'!C33 -> 30 | D33: =+K33 -> 0 | E33: mV RMS | F33: =IF(G33="","Fail",IF(D33<=C33,"Pass", "Fail")) -> Fail | I33: =+B33 -> Vcm preset 15 - amplitude 1 | J33: 2 | K33: =+G33/J33 -> 0 | O33: AC common mode output voltage. Scope value is divided by two. | Q33: Preset 2 | R33: 0
A34: Core | B34: =+'Lane 1'!$B34 -> Vdiffpp | C34: =+'Lane 1'!C34 -> 30 | D34: =+G34 -> 0 | E34: mV | F34: =IF(G34="","Fail",IF(D34<=C34,"Pass", "Fail")) -> Fail | I34: =+B34 -> Vdiffpp | Q34: Preset 15 | R34: 0
A35: Secondary | B35: =+'Lane 1'!$B35 -> e preset 1 - amplitude 0 | C35: =+'Lane 1'!C35 -> 0.037 | D35: =+G35 -> 0 | F35: =IF(G35="","Fail",IF(D35<=C35,"Pass", "Fail")) -> Fail | I35: =+B35 -> e preset 1 - amplitude 0
A36: Secondary | B36: =+'Lane 1'!$B36 -> e preset 1 - amplitude 1 | C36: =+'Lane 1'!C36 -> 0.037 | D36: =+G36 -> 0 | F36: =IF(G36="","Fail",IF(D36<=C36,"Pass", "Fail")) -> Fail | I36: =+B36 -> e preset 1 - amplitude 1 | O36: rms_normalized_e - checked in preset 1 only
A37: Secondary | B37: =+'Lane 1'!$B37 -> e preset 2 - amplitude 0 | C37: =+'Lane 1'!C37 -> 0.037 | D37: =+G37 -> 0 | F37: =IF(G37="","Fail",IF(D37<=C37,"Pass", "Fail")) -> Fail | I37: =+B37 -> e preset 2 - amplitude 0
A38: Secondary | B38: =+'Lane 1'!$B38 -> e preset 2 - amplitude 1 | C38: =+'Lane 1'!C38 -> 0.037 | D38: =+G38 -> 0 | F38: =IF(G38="","Fail",IF(D38<=C38,"Pass", "Fail")) -> Fail | I38: =+B38 -> e preset 2 - amplitude 1
A39: Secondary | B39: =+'Lane 1'!$B39 -> e preset 15 - amplitude 0 | C39: =+'Lane 1'!C39 -> 0.037 | D39: =+G39 -> 0 | F39: =IF(G39="","Fail",IF(D39<=C39,"Pass", "Fail")) -> Fail | I39: =+B39 -> e preset 15 - amplitude 0
A40: Secondary | B40: =+'Lane 1'!$B40 -> e preset 15 - amplitude 1 | C40: =+'Lane 1'!C40 -> 0.037 | D40: =+G40 -> 0 | F40: =IF(G40="","Fail",IF(D40<=C40,"Pass", "Fail")) -> Fail | I40: =+B40 -> e preset 15 - amplitude 1
...

Sheet Summary
A1: Lane Number 1 | K1: Lane Number 2
A2: Parameter | B2: Spec | C2: Measured Value | D2: Pass/Fail | E2: Margin | F2: Margin % | G2: Test Equipment | K2: Parameter | L2: Spec | M2: Measured Value | N2: Pass/Fail | O2: Margin | P2: Margin % | Q2: Test Equipment
A3: =+'Lane 1'!$B$61 -> SDD11 | B3: =+'Lane 1'!$C$61 -> -12 | C3: =+'Lane 1'!$D$61 -> 0 | D3: =IF(C3<=B3,"Pass","Fail") -> Fail | E3: =+C3-B3 -> 12 | F3: =+E3/B3 -> -1 | G3: VNA | K3: =+'Lane 2'!$B$61 -> SDD11 | L3: =+'Lane 2'!$C$61 -> -12 | M3: =+'Lane 2'!$D$61 -> 0 | N3: =IF(M3<=L3,"Pass","Fail") -> Fail | O3: =+M3-L3 -> 12 | P3: =+O3/L3 -> -1 | Q3: VNA
A4: =+'Lane 1'!$B$3 -> SDD22 | B4: =+'Lane 1'!$C$3 -> -12 | C4: =+'Lane 1'!$D$3 -> 0 | D4: =IF(C4<=B4,"Pass","Fail") -> Fail | E4: =+C4-B4 -> 12 | F4: =+E4/B4 -> -1 | G4: VNA | K4: =+'Lane 2'!$B$3 -> SDD22 | L4: =+'Lane 2'!$C$3 -> -12 | M4: =+'Lane 2'!$D$3 -> 0 | N4: =IF(M4<=L4,"Pass","Fail") -> Fail | O4: =+M4-L4 -> 12 | P4: =+O4/L4 -> -1 | Q4: VNA
A5: =+'Lane 1'!$B$62 -> SCC11 | B5: =+'Lane 1'!$C$62 -> -2 | C5: =+'Lane 1'!$D$62 -> 0 | D5: =IF(C5<=B5,"Pass","Fail") -> Fail | E5: =+C5-B5 -> 2 | F5: =+E5/B5 -> -1 | G5: VNA | K5: =+'Lane 2'!$B$62 -> SCC11 | L5: =+'Lane 2'!$C$62 -> -2 | M5: =+'Lane 2'!$D$62 -> 0 | N5: =IF(M5<=L5,"Pass","Fail") -> Fail | O5: =+M5-L5 -> 2 | P5: =+O5/L5 -> -1 | Q5: VNA
A6: =+'Lane 1'!$B$4 -> SCC22 | B6: =+'Lane 1'!$C$4 -> -2 | C6: =+'Lane 1'!$D$4 -> 0 | D6: =IF(C6<=B6,"Pass","Fail") -> Fail | E6: =+C6-B6 -> 2 | F6: =+E6/B6 -> -1 | G6: VNA | K6: =+'Lane 2'!$B$4 -> SCC22 | L6: =+'Lane 2'!$C$4 -> -2 | M6: =+'Lane 2'!$D$4 -> 0 | N6: =IF(M6<=L6,"Pass","Fail") -> Fail | O6: =+M6-L6 -> 2 | P6: =+O6/L6 -> -1 | Q6: VNA
A7: =+'Lane 1'!$B$63 -> SDC11 | B7: =+'Lane 1'!$C$63 -> -16 | C7: =+'Lane 1'!$D$63 -> 0 | D7: =IF(C7<=B7,"Pass","Fail") -> Fail | E7: =+C7-B7 -> 16 | F7: =+E7/B7 -> -1 | G7: VNA | K7: =+'Lane 2'!$B$63 -> SDC11 | L7: =+'Lane 2'!$C$63 -> -16 | M7: =+'Lane 2'!$D$63 -> 0 | N7: =IF(M7<=L7,"Pass","Fail") -> Fail | O7: =+M7-L7 -> 16 | P7: =+O7/L7 -> -1 | Q7: VNA
A8: =+'Lane 1'!$B$5 -> SDC22 | B8: =+'Lane 1'!$C$5 -> -16 | C8: =+'Lane 1'!$D$5 -> 0 | D8: =IF(C8<=B8,"Pass","Fail") -> Fail | E8: =+C8-B8 -> 16 | F8: =+E8/B8 -> -1 | G8: VNA | K8: =+'Lane 2'!$B$5 -> SDC22 | L8: =+'Lane 2'!$C$5 -> -16 | M8: =+'Lane 2'!$D$5 -> 0 | N8: =IF(M8<=L8,"Pass","Fail") -> Fail | O8: =+M8-L8 -> 16 | P8: =+O8/L8 -> -1 | Q8: VNA
A9: =+'Lane 1'!$B$6 -> RJ - preset 0 | B9: =+'Lane 1'!$C$6 -> 0.15 | C9: =+'Lane 1'!$D$6 -> 0 | D9: =IF('Lane 1'!$G$6="","Fail",IF(C9<=B9,"Pass","Fail")) -> Fail | E9: =+B9-C9 -> 0.15 | F9: =+E9/B9 -> 1 | G9: BERTScope | K9: =+'Lane 2'!$B$6 -> RJ - preset 0 | L9: =+'Lane 2'!$C$6 -> 0.15 | M9: =+'Lane 2'!$D$6 -> 0 | N9: =IF('Lane 2'!$G$6="","Fail",IF(M9<=L9,"Pass","Fail")) -> Fail | O9: =+L9-M9 -> 0.15 | P9: =+O9/L9 -> 1 | Q9: BERTScope
A10: =+'Lane 1'!$B$9 -> DCD - preset 0 | B10: =+'Lane 1'!$C$9 -> 0.035 | C10: =+'Lane 1'!$D$9 -> 0 | D10: =IF('Lane 1'!$G$9="","Fail",IF(C10<=B10,"Pass","Fail")) -> Fail | E10: =+B10-C10 -> 0.035 | F10: =+E10/B10 -> 1 | G10: BERTScope | K10: =+'Lane 2'!$B$9 -> DCD - preset 0 | L10: =+'Lane 2'!$C$9 -> 0.035 | M10: =+'Lane 2'!$D$9 -> 0 | N10: =IF('Lane 2'!$G$9="","Fail",IF(M10<=L10,"Pass","Fail")) -> Fail | O10: =+L10-M10 -> 0.035 | P10: =+O10/L10 -> 1 | Q10: BERTScope
A11: =+'Lane 1'!$B$18 -> TJ-DDJ - preset 0 | B11: =+'Lane 1'!$C$18 -> 0.25 | C11: =+'Lane 1'!$D$18 -> 0 | D11: =IF(OR('Lane 1'!$G$12="",'Lane 1'!$G$15=""),"Fail",IF(C11<=B11,"Pass","Fail")) -> Fail | E11: =+B11-C11 -> 0.25 | F11: =+E11/B11 -> 1 | G11: BERTScope | K11: =+'Lane 2'!$B$18 -> TJ-DDJ - preset 0 | L11: =+'Lane 2'!$C$18 -> 0.25 | M11: =+'Lane 2'!$D$18 -> 0 | N11: =IF(OR('Lane 2'!$G$12="",'Lane 2'!$G$15=""),"Fail",IF(M11<=L11,"Pass","Fail")) -> Fail | O11: =+L11-M11 -> 0.25 | P11: =+O11/L11 -> 1 | Q11: BERTScope
A12: =+'Lane 1'!$B$21 -> J2 - preset 0 | B12: =+'Lane 1'!$C$21 -> 0.19 | C12: =+'Lane 1'!$D$21 -> 0 | D12: =IF('Lane 1'!$G$21="","Fail",IF(C12<=B12,"Pass","Fail")) -> Fail | E12: =+C12-B12 -> -0.19 | F12: =+E12/B12 -> -1 | G12: BERTScope | K12: =+'Lane 2'!$B$21 -> J2 - preset 0 | L12: =+'Lane 2'!$C$21 -> 0.19 | M12: =+'Lane 2'!$D$21 -> 0 | N12: =IF('Lane 2'!$G$21="","Fail",IF(M12<=L12,"Pass","Fail")) -> Fail | O12: =+M12-L12 -> -0.19 | P12: =+O12/L12 -> -1 | Q12: BERTScope
A13: =+'Lane 1'!$B$22 -> J9 - preset 0 | B13: =+'Lane 1'!$C$22 -> 0.33 | C13: =+'Lane 1'!$D$22 -> 0 | D13: =IF('Lane 1'!$G$22="","Fail",IF(C13<=B13,"Pass","Fail")) -> Fail | E13: =+C13-B13 -> -0.33 | F13: =+E13/B13 -> -1 | G13: BERTScope | K13: =+'Lane 2'!$B$22 -> J9 - preset 0 | L13: =+'Lane 2'!$C$22 -> 0.33 | M13: =+'Lane 2'!$D$22 -> 0 | N13: =IF('Lane 2'!$G$22="","Fail",IF(M13<=L13,"Pass","Fail")) -> Fail | O13: =+M13-L13 -> -0.33 | P13: =+O13/L13 -> -1 | Q13: BERTScope
A14: =+'Lane 1'!$B$23 -> DDPWS | B14: =+'Lane 1'!$C$24 -> 0.11 | C14: =+'Lane 1'!$D$24 -> 1 | D14: =IF('Lane 1'!$G$24="","Fail",IF(C14<=B14,"Pass","Fail")) -> Fail | E14: =+C14-B14 -> 0.89 | F14: =+E14/B14 -> 8.0909091 | G14: Sampling Scope | K14: =+'Lane 2'!$B$23 -> DDPWS | L14: =+'Lane 2'!$C$24 -> 0.11 | M14: =+'Lane 2'!$D$24 -> 1 | N14: =IF('Lane 2'!$G$24="","Fail",IF(M14<=L14,"Pass","Fail")) -> Fail | O14: =+M14-L14 -> 0.89 | P14: =+O14/L14 -> 8.0909091 | Q14: Sampling Scope
A15: =+'Lane 1'!$B$26 -> X1, X2, Y1, Y2 | B15: =+'Lane 1'!$C$26 -> 5e-05 | C15: =+'Lane 1'!$D$26 -> 0 | D15: =IF('Lane 1'!$L$26="","Fail",IF(C15<=B15,"Pass","Fail")) -> Fail | E15: =+C15-B15 -> -5e-05 | F15: =+E15/B15 -> -1 | G15: Sampling Scope | K15: =+'Lane 2'!$B$26 -> X1, X2, Y1, Y2 | L15: =+'Lane 2'!$C$26 -> 5e-05 | M15: =+'Lane 2'!$D$26 -> 0 | N15: =IF('Lane 2'!$L$26="","Fail",IF(M15<=L15,"Pass","Fail")) -> Fail | O15: =+M15-L15 -> -5e-05 | P15: =+O15/L15 -> -1 | Q15: Sampling Scope
A16: =+'Lane 1'!$B$27 -> Tr | B16: =+'Lane 1'!$C$27 -> 24 | C16: =+'Lane 1'!$D$27 -> 0 | D16: =IF(C16>=B16,"Pass","Fail") -> Fail | E16: =+C16-B16 -> -24 | F16: =+E16/B16 -> -1 | G16: Sampling Scope | K16: =+'Lane 2'!$B$27 -> Tr | L16: =+'Lane 2'!$C$27 -> 24 | M16: =+'Lane 2'!$D$27 -> 0 | N16: =IF(M16>=L16,"Pass","Fail") -> Fail | O16: =+M16-L16 -> -24 | P16: =+O16/L16 -> -1 | Q16: Sampling Scope
A17: =+'Lane 1'!$B$28 -> Tf | B17: =+'Lane 1'!$C$28 -> 24 | C17: =+'Lane 1'!$D$28 -> 0 | D17: =IF(C17>=B17,"Pass","Fail") -> Fail | E17: =+C17-B17 -> -24 | F17: =+E17/B17 -> -1 | G17: Sampling Scope | K17: =+'Lane 2'!$B$28 -> Tf | L17: =+'Lane 2'!$C$28 -> 24 | M17: =+'Lane 2'!$D$28 -> 0 | N17: =IF(M17>=L17,"Pass","Fail") -> Fail | O17: =+M17-L17 -> -24 | P17: =+O17/L17 -> -1 | Q17: Sampling Scope
A18: =+'Lane 1'!$B$29 -> Vcm preset 0 | B18: =+'Lane 1'!$C$29 -> 20 | C18: =+'Lane 1'!$D$29 -> 0 | D18: =IF('Lane 1'!$G$29="","Fail",IF(C18<=B18,"Pass","Fail")) -> Fail | E18: =+C18-B18 -> -20 | F18: =+E18/B18 -> -1 | G18: Sampling Scope | K18: =+'Lane 2'!$B$29 -> Vcm preset 0 | L18: =+'Lane 2'!$C$29 -> 20 | M18: =+'Lane 2'!$D$29 -> 0 | N18: =IF('Lane 2'!$G$29="","Fail",IF(M18<=L18,"Pass","Fail")) -> Fail | O18: =+M18-L18 -> -20 | P18: =+O18/L18 -> -1 | Q18: Sampling Scope
A19: =+'Lane 1'!$B$34 -> Vdiffpp | B19: =+'Lane 1'!$C$34 -> 30 | C19: =+'Lane 1'!$D$34 -> 0 | D19: =IF('Lane 1'!$G$34="","Fail",IF(C19<=B19,"Pass","Fail")) -> Fail | E19: =+C19-B19 -> -30 | F19: =+E19/B19 -> -1 | G19: Sampling Scope | K19: =+'Lane 2'!$B$34 -> Vdiffpp | L19: =+'Lane 2'!$C$34 -> 30 | M19: =+'Lane 2'!$D$34 -> 0 | N19: =IF('Lane 2'!$G$34="","Fail",IF(M19<=L19,"Pass","Fail")) -> Fail | O19: =+M19-L19 -> -30 | P19: =+O19/L19 -> -1 | Q19: Sampling Scope
A29: Please paste screen shot from BERTScope testing here | K29: Please paste screen shot from BERTScope testing here
A44: Lane Number 3 | K44: Lane Number 4
A45: Parameter | B45: Spec | C45: Measured Value | D45: Pass/Fail | E45: Margin | F45: Margin % | G45: Test Equipment | K45: Parameter | L45: Spec | M45: Measured Value | N45: Pass/Fail | O45: Margin | P45: Margin % | Q45: Test Equipment
A46: =+'Lane 3'!$B$61 -> SDD11 | B46: =+'Lane 3'!$C$61 -> -12 | C46: =+'Lane 3'!$D$61 -> 0 | D46: =IF(C46<=B46,"Pass","Fail") -> Fail | E46: =+C46-B46 -> 12 | F46: =+E46/B46 -> -1 | G46: VNA | K46: =+'Lane 4'!$B$61 -> SDD11 | L46: =+'Lane 4'!$C$61 -> -12 | M46: =+'Lane 4'!$D$61 -> 0 | N46: =IF(M46<=L46,"Pass","Fail") -> Fail | O46: =+M46-L46 -> 12 | P46: =+O46/L46 -> -1 | Q46: VNA
A47: =+'Lane 3'!$B$3 -> SDD22 | B47: =+'Lane 3'!$C$3 -> -12 | C47: =+'Lane 3'!$D$3 -> 0 | D47: =IF(C47<=B47,"Pass","Fail") -> Fail | E47: =+C47-B47 -> 12 | F47: =+E47/B47 -> -1 | G47: VNA | K47: =+'Lane 4'!$B$3 -> SDD22 | L47: =+'Lane 4'!$C$3 -> -12 | M47: =+'Lane 4'!$D$3 -> 0 | N47: =IF(M47<=L47,"Pass","Fail") -> Fail | O47: =+M47-L47 -> 12 | P47: =+O47/L47 -> -1 | Q47: VNA
A48: =+'Lane 3'!$B$62 -> SCC11 | B48: =+'Lane 3'!$C$62 -> -2 | C48: =+'Lane 3'!$D$62 -> 0 | D48: =IF(C48<=B48,"Pass","Fail") -> Fail | E48: =+C48-B48 -> 2 | F48: =+E48/B48 -> -1 | G48: VNA | K48: =+'Lane 4'!$B$62 -> SCC11 | L48: =+'Lane 4'!$C$62 -> -2 | M48: =+'Lane 4'!$D$62 -> 0 | N48: =IF(M48<=L48,"Pass","Fail") -> Fail | O48: =+M48-L48 -> 2 | P48: =+O48/L48 -> -1 | Q48: VNA
A49: =+'Lane 3'!$B$4 -> SCC22 | B49: =+'Lane 3'!$C$4 -> -2 | C49: =+'Lane 3'!$D$4 -> 0 | D49: =IF(C49<=B49,"Pass","Fail") -> Fail | E49: =+C49-B49 -> 2 | F49: =+E49/B49 -> -1 | G49: VNA | K49: =+'Lane 4'!$B$4 -> SCC22 | L49: =+'Lane 4'!$C$4 -> -2 | M49: =+'Lane 4'!$D$4 -> 0 | N49: =IF(M49<=L49,"Pass","Fail") -> Fail | O49: =+M49-L49 -> 2 | P49: =+O49/L49 -> -1 | Q49: VNA
A50: =+'Lane 3'!$B$63 -> SDC11 | B50: =+'Lane 3'!$C$63 -> -16 | C50: =+'Lane 3'!$D$63 -> 0 | D50: =IF(C50<=B50,"Pass","Fail") -> Fail | E50: =+C50-B50 -> 16 | F50: =+E50/B50 -> -1 | G50: VNA | K50: =+'Lane 4'!$B$63 -> SDC11 | L50: =+'Lane 4'!$C$63 -> -16 | M50: =+'Lane 4'!$D$63 -> 0 | N50: =IF(M50<=L50,"Pass","Fail") -> Fail | O50: =+M50-L50 -> 16 | P50: =+O50/L50 -> -1 | Q50: VNA
A51: =+'Lane 3'!$B$5 -> SDC22 | B51: =+'Lane 3'!$C$5 -> -16 | C51: =+'Lane 3'!$D$5 -> 0 | D51: =IF(C51<=B51,"Pass","Fail") -> Fail | E51: =+C51-B51 -> 16 | F51: =+E51/B51 -> -1 | G51: VNA | K51: =+'Lane 4'!$B$5 -> SDC22 | L51: =+'Lane 4'!$C$5 -> -16 | M51: =+'Lane 4'!$D$5 -> 0 | N51: =IF(M51<=L51,"Pass","Fail") -> Fail | O51: =+M51-L51 -> 16 | P51: =+O51/L51 -> -1 | Q51: VNA
A52: =+'Lane 3'!$B$6 -> RJ - preset 0 | B52: =+'Lane 3'!$C$6 -> 0.15 | C52: =+'Lane 3'!$D$6 -> 0 | D52: =IF('Lane 3'!$G$6="","Fail",IF(C52<=B52,"Pass","Fail")) -> Fail | E52: =+B52-C52 -> 0.15 | F52: =+E52/B52 -> 1 | G52: BERTScope | K52: =+'Lane 4'!$B$6 -> RJ - preset 0 | L52: =+'Lane 4'!$C$6 -> 0.15 | M52: =+'Lane 4'!$D$6 -> 0 | N52: =IF('Lane 4'!$G$6="","Fail",IF(M52<=L52,"Pass","Fail")) -> Fail | O52: =+L52-M52 -> 0.15 | P52: =+O52/L52 -> 1 | Q52: BERTScope
A53: =+'Lane 3'!$B$9 -> DCD - preset 0 | B53: =+'Lane 3'!$C$9 -> 0.035 | C53: =+'Lane 3'!$D$9 -> 0 | D53: =IF('Lane 3'!$G$9="","Fail",IF(C53<=B53,"Pass","Fail")) -> Fail | E53: =+B53-C53 -> 0.035 | F53: =+E53/B53 -> 1 | G53: BERTScope | K53: =+'Lane 4'!$B$9 -> DCD - preset 0 | L53: =+'Lane 4'!$C$9 -> 0.035 | M53: =+'Lane 4'!$D$9 -> 0 | N53: =IF('Lane 4'!$G$9="","Fail",IF(M53<=L53,"Pass","Fail")) -> Fail | O53: =+L53-M53 -> 0.035 | P53: =+O53/L53 -> 1 | Q53: BERTScope
A54: =+'Lane 3'!$B$18 -> TJ-DDJ - preset 0 | B54: =+'Lane 3'!$C$18 -> 0.25 | C54: =+'Lane 3'!$D$18 -> 0 | D54: =IF(OR('Lane 3'!$G$12="",'Lane 3'!$G$15=""),"Fail",IF(C54<=B54,"Pass","Fail")) -> Fail | E54: =+B54-C54 -> 0.25 | F54: =+E54/B54 -> 1 | G54: BERTScope | K54: =+'Lane 4'!$B$18 -> TJ-DDJ - preset 0 | L54: =+'Lane 4'!$C$18 -> 0.25 | M54: =+'Lane 4'!$D$18 -> 0 | N54: =IF(OR('Lane 4'!$G$12="",'Lane 4'!$G$15=""),"Fail",IF(M54<=L54,"Pass","Fail")) -> Fail | O54: =+L54-M54 -> 0.25 | P54: =+O54/L54 -> 1 | Q54: BERTScope
A55: =+'Lane 3'!$B$21 -> J2 - preset 0 | B55: =+'Lane 3'!$C$21 -> 0.19 | C55: =+'Lane 3'!$D$21 -> 0 | D55: =IF('Lane 3'!$G$21="","Fail",IF(C55<=B55,"Pass","Fail")) -> Fail | E55: =+C55-B55 -> -0.19 | F55: =+E55/B55 -> -1 | G55: BERTScope | K55: =+'Lane 4'!$B$21 -> J2 - preset 0 | L55: =+'Lane 4'!$C$21 -> 0.19 | M55: =+'Lane 4'!$D$21 -> 0 | N55: =IF('Lane 4'!$G$21="","Fail",IF(M55<=L55,"Pass","Fail")) -> Fail | O55: =+M55-L55 -> -0.19 | P55: =+O55/L55 -> -1 | Q55: BERTScope
A56: =+'Lane 3'!$B$22 -> J9 - preset 0 | B56: =+'Lane 3'!$C$22 -> 0.33 | C56: =+'Lane 3'!$D$22 -> 0 | D56: =IF('Lane 3'!$G$22="","Fail",IF(C56<=B56,"Pass","Fail")) -> Fail | E56: =+C56-B56 -> -0.33 | F56: =+E56/B56 -> -1 | G56: BERTScope | K56: =+'Lane 4'!$B$22 -> J9 - preset 0 | L56: =+'Lane 4'!$C$22 -> 0.33 | M56: =+'Lane 4'!$D$22 -> 0 | N56: =IF('Lane 4'!$G$22="","Fail",IF(M56<=L56,"Pass","Fail")) -> Fail | O56: =+M56-L56 -> -0.33 | P56: =+O56/L56 -> -1 | Q56: BERTScope
