Workbook

Sheet SUMMARY
B31: Table 1: Annual cases of bacterial meningitis and septicaemia by country and type (2009/10)
C32: Meningococcal meningitis & septicaemia | E32: Pneumococcal meningitis | F32: Haemophilus influenzae meningitis | G32: TB meningitis | H32: Other causes | I32: Neonatal Group B Streptococcal septicaemia* | J32: Total
C33: All | D33: MenB
B34: England | C34: ='UK MD'!F45 -> 1207.8 | D34: ='UK MD'!G45 -> 1074.0793 | E34: ='UK non-MD'!H35 -> 379.70414 | F34: ='UK non-MD'!C49 -> 31 | G34: ='UK non-MD'!D49 -> 192 | H34: ='UK non-MD'!E49 -> 275 | J34: =SUM(E34:I34)+C34 +C35 -> 2142.7041
B35: Wales | C35: ='UK MD'!$F$46 -> 57.2 | D35: ='UK MD'!$G$46 -> 49.4
B36: Scotland* | C36: ='UK MD'!F48 -> 139 | D36: ='UK MD'!G48 -> 123.97297 | E36: ='UK non-MD'!C71 -> 25 | F36: ='UK non-MD'!D71 -> 2 | G36: ='UK non-MD'!E71 -> 10 | H36: ='UK non-MD'!F71 -> 81 | J36: =SUM(E36:I36)+C36 -> 257
B37: Northern Ireland | C37: ='UK MD'!F47 -> 65 | D37: ='UK MD'!G47 -> 61.75 | E37: ='UK non-MD'!C57 -> 2 | F37: ='UK non-MD'!D57 -> 0 | G37: ='UK non-MD'!E57 -> 0 | H37: ='UK non-MD'!F57 -> 36 | J37: =SUM(E37:I37)+C37 -> 103
B38: Total UK | C38: =SUM(C34:C37) -> 1469 | D38: =SUM(D34:D37) -> 1309.2023 | E38: =SUM(E34:E37) -> 406.70414 | F38: =SUM(F34:F37) -> 33 | G38: =SUM(G34:G37) -> 202 | H38: =SUM(H34:H37) -> 392 | I38: 274 | J38: =SUM(E38:I38)+C38 -> 2776.7041
B39: * Scottish data is for calendar year 2009 because epidemiological data was unavailable
B41: Table 2: Annual cases of bacterial meningitis and septicaemia by country and type to represent the burden of uncontrolled disease
C42: Meningococcal meningitis & septicaemia | E42: Pneumococcal meningitis | F42: Haemophilus influenzae meningitis | G42: TB meningitis | H42: Other causes | I42: Neonatal Group B Streptococcal septicaemia* | J42: Total
C43: All | D43: MenB
B44: England | C44: ='UK MD'!J45 -> 1708.5576 | D44: ='UK MD'!D45 -> 1571.6703 | E44: ='UK non-MD'!H36 -> 383.76961 | F44: ='UK non-MD'!C50 -> 29 | G44: ='UK non-MD'!D50 -> 188.3 | H44: ='UK non-MD'!E50 -> 338.4 | J44: =SUM(E44:I44)+C44+C45 -> 2723.5938
B45: Wales | C45: ='UK MD'!$J$46 -> 75.566675 | D45: ='UK MD'!$D$46 -> 69.363881
B46: Scotland | C46: ='UK MD'!C48 -> 183.6 | D46: ='UK MD'!D48 -> 137.25304 | E46: ='UK non-MD'!C72 -> 22.333333 | F46: ='UK non-MD'!D72 -> 4.6666667 | G46: ='UK non-MD'!E72 -> 7.4 | H46: ='UK non-MD'!F72 -> 35.5 | J46: =SUM(E46:I46)+C46 -> 253.5
B47: Northern Ireland | C47: ='UK MD'!C47 -> 106 | D47: ='UK MD'!D47 -> 91.524335 | E47: ='UK non-MD'!C58 -> 2 | F47: ='UK non-MD'!D58 -> 0.33333333 | G47: ='UK non-MD'!E58 -> 0.5 | H47: ='UK non-MD'!F58 -> 44.5 | J47: =SUM(E47:I47)+C47 -> 153.33333
B48: Total UK | C48: =SUM(C44:C47) -> 2073.7242 | D48: =SUM(D44:D47) -> 1869.8116 | E48: =SUM(E44:E47) -> 408.10295 | F48: =SUM(F44:F47) -> 34 | G48: =SUM(G44:G47) -> 196.2 | H48: =SUM(H44:H47) -> 418.4 | I48: 274 | J48: =SUM(E48:I48)+C48 -> 3404.4272

Sheet UK MD
B42: Table 3: Cases of meningococcal disease in the UK in 2009/10 and 10 year averages
C43: 10 YEAR AVERAGE | F43: 2009/10 | I43: 10 yr average MenC - 2009/10 MenC | J43: 10 yr average meningo cases reduced to reflect the impact of MenC vaccination
C44: Total Mening | D44: MenB | E44: MenC | F44: Total Mening | G44: MenB | H44: MenC
B45: ENGLAND | C45: =D65 -> 1809 | D45: =L65 -> 1571.6703 | E45: =M65 -> 124.88602 | F45: =D64 -> 1207.8 | G45: =L64 -> 1074.0793 | H45: =M64 -> 24.443571 | I45: =E45-H45 -> 100.44245 | J45: =C45-I45 -> 1708.5576
B46: WALES | C46: =C79*1.3 -> 82.03 | D46: =J79 -> 69.363881 | E46: =M79 -> 6.4633255 | F46: =C78*1.3 -> 57.2 | G46: =J78 -> 49.4 | H46: =M78 -> 0 | I46: =E46-H46 -> 6.4633255 | J46: =C46-I46 -> 75.566675
B47: NI | C47: =C93 -> 106 | D47: =I93 -> 91.524335 | E47: =K93 -> 4.5153946 | F47: =C92 -> 65 | G47: =I92 -> 61.75 | H47: =K92 -> 0 | I47: =E47-H47 -> 4.5153946 | J47: =C47-I47 -> 101.48461
B48: SCOTLAND | C48: =C107 -> 183.6 | D48: =I107 -> 137.25304 | E48: =K107 -> 19.857932 | F48: =C106 -> 139 | G48: =I106 -> 123.97297 | H48: =K106 -> 0 | I48: =E48-H48 -> 19.857932 | J48: =C48-I48 -> 163.74207
B49: TOTAL | C49: =SUM(C45:C48) -> 2180.63 | D49: =SUM(D45:D48) -> 1869.8116 | E49: =SUM(E45:E48) -> 155.72267 | F49: =SUM(F45:F48) -> 1469 | G49: =SUM(G45:G48) -> 1309.2023 | H49: =SUM(H45:H48) -> 24.443571 | I49: =SUM(I45:I48) -> 131.2791 | J49: =SUM(J45:J48) -> 2049.3509
B52: Table 4: Cases of meningococal disease in England: HES1 and Lab confirmed data2 (2000/01 to 2009/10)
E53: Meningococcal Reference Unit isolates of Neisseria menengitidis
B54: Year | C54: HES Admissions data A39 | D54: Cleaned HES admissions data | E54: All cases | F54: All grouped cases (A,B,C,W135 & Y) | G54: Ungrouped cases | H54: MenB | I54: MenC | J54: MenB as a percentage of all grouped cases | K54: MenC as a percentage of all grouped cases | L54: Total MenB estimate | M54: Total MenC estimate
B55: 00/01 | C55: 3225 | D55: =C55*0.9 -> 2902.5 | E55: =F55+G55 -> 2344 | F55: 2173 | G55: 171 | H55: 1616 | I55: 389 | J55: =H55/F55*100 -> 74.367234 | K55: =I55/F55*100 -> 17.901519 | L55: =D55*(J55/100) -> 2158.509 | M55: =D55*K55/100 -> 519.59158
B56: 01/02 | C56: 2639 | D56: =C56*0.9 -> 2375.1 | E56: =F56+G56 -> 1855 | F56: 1745 | G56: 110 | H56: 1426 | I56: 198 | J56: =H56/F56*100 -> 81.719198 | K56: =I56/F56*100 -> 11.346705 | L56: =D56*(J56/100) -> 1940.9127 | M56: =D56*K56/100 -> 269.49559
B57: 02/03 | C57: 2133 | D57: =C57*0.9 -> 1919.7 | E57: =F57+G57 -> 1416 | F57: 1339 | G57: 77 | H57: 1162 | I57: 115 | J57: =H57/F57*100 -> 86.78118 | K57: =I57/F57*100 -> 8.5884989 | L57: =D57*(J57/100) -> 1665.9383 | M57: =D57*K57/100 -> 164.87341
B58: 03/04 | C58: 2103 | D58: =C58*0.9 -> 1892.7 | E58: =F58+G58 -> 1438 | F58: 1386 | G58: 52 | H58: 1250 | I58: 61 | J58: =H58/F58*100 -> 90.18759 | K58: =I58/F58*100 -> 4.4011544 | L58: =D58*(J58/100) -> 1706.9805 | M58: =D58*K58/100 -> 83.300649
B59: 04/05 | C59: 1874 | D59: =C59*0.9 -> 1686.6 | E59: =F59+G59 -> 1384 | F59: 1329 | G59: 55 | H59: 1220 | I59: 41 | J59: =H59/F59*100 -> 91.798345 | K59: =I59/F59*100 -> 3.0850263 | L59: =D59*(J59/100) -> 1548.2709 | M59: =D59*K59/100 -> 52.032054
B60: 05/06 | C60: 1728 | D60: =C60*0.9 -> 1555.2 | E60: =F60+G60 -> 1227 | F60: 1201 | G60: 26 | H60: 1105 | I60: 30 | J60: =H60/F60*100 -> 92.006661 | K60: =I60/F60*100 -> 2.4979184 | L60: =D60*(J60/100) -> 1430.8876 | M60: =D60*K60/100 -> 38.847627
B61: 06/07 | C61: 1622 | D61: =C61*0.9 -> 1459.8 | E61: =F61+G61 -> 1094 | F61: 1046 | G61: 48 | H61: 958 | I61: 28 | J61: =H61/F61*100 -> 91.586998 | K61: =I61/F61*100 -> 2.6768642 | L61: =D61*(J61/100) -> 1336.987 | M61: =D61*K61/100 -> 39.076864
B62: 07/08 | C62: 1724 | D62: =C62*0.9 -> 1551.6 | E62: =F62+G62 -> 1190 | F62: 1117 | G62: 73 | H62: 1038 | I62: 28 | J62: =H62/F62*100 -> 92.927484 | K62: =I62/F62*100 -> 2.5067144 | L62: =D62*(J62/100) -> 1441.8628 | M62: =D62*K62/100 -> 38.894181
B63: 08/09 | C63: 1710 | D63: =C63*0.9 -> 1539 | E63: =F63+G63 -> 1111 | F63: 1093 | G63: 18 | H63: 1003 | I63: 13 | J63: =H63/F63*100 -> 91.765782 | K63: =I63/F63*100 -> 1.189387 | L63: =D63*(J63/100) -> 1412.2754 | M63: =D63*K63/100 -> 18.304666
B64: 09/10 | C64: 1342 | D64: =C64*0.9 -> 1207.8 | E64: =F64+G64 -> 852 | F64: 840 | G64: 12 | H64: 747 | I64: 17 | J64: =H64/F64*100 -> 88.928571 | K64: =I64/F64*100 -> 2.0238095 | L64: =D64*(J64/100) -> 1074.0793 | M64: =D64*K64/100 -> 24.443571
B65: Average (past 10 yrs) | C65: =AVERAGE(C55:C64) -> 2010 | D65: =AVERAGE(D55:D64) -> 1809 | E65: =AVERAGE(E55:E64) -> 1391.1 | F65: =AVERAGE(F55:F64) -> 1326.9 | G65: =AVERAGE(G55:G64) -> 64.2 | H65: =AVERAGE(H55:H64) -> 1152.5 | I65: =AVERAGE(I55:I64) -> 92 | J65: =AVERAGE(J55:J64) -> 88.206904 | ... M65: =AVERAGE(M55:M64) -> 124.88602
B67: Table 5: Meningococcal Reference Unit isolates of Neisseria meningitidis: Wales2 (2000/01 to 2009/10)
B68: Year | C68: All cases | D68: All grouped cases (A,B,C,W135 & Y) | E68: Ungrouped cases | F68: MenB | G68: MenC | H68: MenB as a percentage of all grouped cases | I68: Total MenB estimate | J68: Total MenB estimate with 1.3 uplift | K68: MenC as a percentage of all grouped cases | L68: Total MenC estimate | M68: Total MenC estimate with 1.3 uplift
B69: 00/01 | C69: =D69+E69 -> 104 | D69: 99 | E69: 5 | F69: 74 | G69: 23 | H69: =F69/D69*100 -> 74.747475 | I69: =(E69*(H69/100))+F69 -> 77.737374 | J69: =I69*1.3 -> 101.05859 | K69: =G69/D69*100 -> 23.232323 | L69: =(E69*(K69/100))+G69 -> 24.161616 | M69: =L69*1.3 -> 31.410101
B70: 01/02 | C70: =D70+E70 -> 107 | D70: 105 | E70: 2 | F70: 78 | G70: 13 | H70: =F70/D70*100 -> 74.285714 | I70: =(E70*(H70/100))+F70 -> 79.485714 | J70: =I70*1.3 -> 103.33143 | K70: =G70/D70*100 -> 12.380952 | L70: =(E70*(K70/100))+G70 -> 13.247619 | M70: =L70*1.3 -> 17.221905
B71: 02/03 | C71: =D71+E71 -> 61 | D71: 59 | E71: 2 | F71: 49 | G71: 6 | H71: =F71/D71*100 -> 83.050847 | I71: =(E71*(H71/100))+F71 -> 50.661017 | J71: =I71*1.3 -> 65.859322 | K71: =G71/D71*100 -> 10.169492 | L71: =(E71*(K71/100))+G71 -> 6.2033898 | M71: =L71*1.3 -> 8.0644068
B72: 03/04 | C72: =D72+E72 -> 55 | D72: 55 | E72: 0 | F72: 47 | G72: 3 | H72: =F72/D72*100 -> 85.454545 | I72: =(E72*(H72/100))+F72 -> 47 | J72: =I72*1.3 -> 61.1 | K72: =G72/D72*100 -> 5.4545455 | L72: =(E72*(K72/100))+G72 -> 3 | M72: =L72*1.3 -> 3.9
B73: 04/05 | C73: =D73+E73 -> 57 | D73: 57 | E73: 0 | F73: 54 | G73: 1 | H73: =F73/D73*100 -> 94.736842 | I73: =(E73*(H73/100))+F73 -> 54 | J73: =I73*1.3 -> 70.2 | K73: =G73/D73*100 -> 1.754386 | L73: =(E73*(K73/100))+G73 -> 1 | M73: =L73*1.3 -> 1.3
B74: 05/06 | C74: =D74+E74 -> 53 | D74: 53 | E74: 0 | F74: 52 | G74: 0 | H74: =F74/D74*100 -> 98.113208 | I74: =(E74*(H74/100))+F74 -> 52 | J74: =I74*1.3 -> 67.6 | K74: =G74/D74*100 -> 0 | L74: =(E74*(K74/100))+G74 -> 0 | M74: =L74*1.3 -> 0
B75: 06/07 | C75: =D75+E75 -> 42 | D75: 38 | E75: 4 | F75: 35 | G75: 1 | H75: =F75/D75*100 -> 92.105263 | I75: =(E75*(H75/100))+F75 -> 38.684211 | J75: =I75*1.3 -> 50.289474 | K75: =G75/D75*100 -> 2.6315789 | L75: =(E75*(K75/100))+G75 -> 1.1052632 | M75: =L75*1.3 -> 1.4368421
B76: 07/08 | C76: =D76+E76 -> 53 | D76: 53 | E76: 0 | F76: 47 | G76: 1 | H76: =F76/D76*100 -> 88.679245 | I76: =(E76*(H76/100))+F76 -> 47 | J76: =I76*1.3 -> 61.1 | K76: =G76/D76*100 -> 1.8867925 | L76: =(E76*(K76/100))+G76 -> 1 | M76: =L76*1.3 -> 1.3
B77: 08/09 | C77: =D77+E77 -> 55 | D77: 55 | E77: 0 | F77: 49 | G77: 0 | H77: =F77/D77*100 -> 89.090909 | I77: =(E77*(H77/100))+F77 -> 49 | J77: =I77*1.3 -> 63.7 | K77: =G77/D77*100 -> 0 | L77: =(E77*(K77/100))+G77 -> 0 | M77: =L77*1.3 -> 0
B78: 09/10 | C78: =D78+E78 -> 44 | D78: 44 | E78: 0 | F78: 38 | G78: 0 | H78: =F78/D78*100 -> 86.363636 | I78: =(E78*(H78/100))+F78 -> 38 | J78: =I78*1.3 -> 49.4 | K78: =G78/D78*100 -> 0 | L78: =(E78*(K78/100))+G78 -> 0 | M78: =L78*1.3 -> 0
B79: Average (past 10 yrs) | C79: =AVERAGE(C69:C78) -> 63.1 | D79: =AVERAGE(D69:D78) -> 61.8 | E79: =AVERAGE(E69:E78) -> 1.3 | F79: =AVERAGE(F69:F78) -> 52.3 | G79: =AVERAGE(G69:G78) -> 4.8 | H79: =AVERAGE(H69:H78) -> 86.662769 | I79: =AVERAGE(I69:I78) -> 53.356832 | J79: =AVERAGE(J69:J78) -> 69.363881 | ... M79: =AVERAGE(M69:M78) -> 6.4633255
B81: Table 6: Enhanced surveillance of meningococcal disease in Northern Ireland3. Notifications validated with lab confirmed data (2000/01 to 2009/10)
B82: Year | C82: All cases | D82: All grouped cases (A,B,C,W135 & Y) | E82: Ungrouped cases | F82: MenB | G82: MenC | H82: MenB as a percentage of all grouped cases | I82: Total MenB estimate | J82: MenC as a percentage of all grouped cases | K82: Total MenC estimate
B83: 00/01 | C83: =D83+E83 -> 167 | D83: 97 | E83: 70 | F83: 72 | G83: 8 | H83: =F83/D83*100 -> 74.226804 | I83: =(E83*(H83/100))+F83 -> 123.95876 | J83: =G83/D83*100 -> 8.2474227 | K83: =(E83*(J83/100))+G83 -> 13.773196
B84: 01/02 | C84: =D84+E84 -> 137 | D84: 86 | E84: 51 | F84: 69 | G84: 9 | H84: =F84/D84*100 -> 80.232558 | I84: =(E84*(H84/100))+F84 -> 109.9186 | J84: =G84/D84*100 -> 10.465116 | K84: =(E84*(J84/100))+G84 -> 14.337209
B85: 02/03 | C85: =D85+E85 -> 116 | D85: 73 | E85: 43 | F85: 64 | G85: 6 | H85: =F85/D85*100 -> 87.671233 | I85: =(E85*(H85/100))+F85 -> 101.69863 | J85: =G85/D85*100 -> 8.2191781 | K85: =(E85*(J85/100))+G85 -> 9.5342466
...

Sheet UK non-MD
B30: Table 9: Cases of pneumococcal meningitis in England and Wales: HES1 and NOIDS5 data (2007/8 to 2009/10)
E31: Notifications of pneumococcal meningitis by calendar year (2007-2009)
B32: Year | C32: HES Admissions data G001 | D32: Cleaned HES admissions data | E32: England and Wales | F32: England | G32: Uplift required to convert English NOIDS to E&W NOIDS | H32: Cleaned HES admissions data uplifted to include Wales
B33: 2007-08 | C33: 490 | D33: =C33*0.75 -> 367.5 | E33: 173 | F33: 168 | G33: =E33/F33 -> 1.0297619 | H33: =D33*G33 -> 378.4375
B34: 2008-09 | C34: 487 | D34: =C34*0.75 -> 365.25 | E34: 169 | F34: 157 | G34: =E34/F34 -> 1.0764331 | H34: =D34*G34 -> 393.1672
B35: 2009-10 | C35: 460 | D35: =C35*0.75 -> 345 | E35: 186 | F35: 169 | G35: =E35/F35 -> 1.1005917 | H35: =D35*G35 -> 379.70414
B36: Average over past 3 years | C36: =AVERAGE(C33:C35) -> 479 | D36: =AVERAGE(D33:D35) -> 359.25 | E36: =AVERAGE(E33:E35) -> 176 | F36: =AVERAGE(F33:F35) -> 164.66667 | G36: =AVERAGE(G33:G35) -> 1.0689289 | H36: =AVERAGE(H33:H35) -> 383.76961
B38: Table 10: Cases of other bacterial meningitis in England and Wales: NOIDS5 data (2000 to 2009)
B39: Year | C39: Hi | D39: TB men | E39: Other causes
B40: 2000 | C40: 39 | D40: 94 | E40: 464
B41: 2001 | C41: 74 | D41: 161 | E41: 517
B42: 2002 | C42: 62 | D42: 140 | E42: 361
B43: 2003 | C43: 63 | D43: 150 | E43: 323
B44: 2004 | C44: 45 | D44: 140 | E44: 294
B45: 2005 | C45: 44 | D45: 228 | E45: 315
B46: 2006 | C46: 57 | D46: 252 | E46: 321
B47: 2007 | C47: 32 | D47: 320 | E47: 254
B48: 2008 | C48: 24 | D48: 206 | E48: 260
B49: 2009 | C49: 31 | D49: 192 | E49: 275
B50: Average | C50: =AVERAGE(C47:C49) -> 29 | D50: =AVERAGE(D40:D49) -> 188.3 | E50: =AVERAGE(E40:E49) -> 338.4
B52: Table 11: Cases of other bacterial meningitis in Northern Ireland sourced from PHA6,7 (2006 to 2009)
B53: Year | C53: Pneumococcal meningitis | D53: Hib meningitis | E53: TB meningitis | F53: Other bacterial meningitis
B54: 2006 | C54: 5 | D54: 0 | E54: 0 | F54: 63
B55: 2007 | C55: 1 | D55: 1 | E55: 1 | F55: 39
B56: 2008 | C56: 3 | D56: 0 | E56: 1 | F56: 40
B57: 2009 | C57: 2 | D57: 0 | E57: 0 | F57: 36
B58: Average | C58: =AVERAGE(C55:C57) -> 2 | D58: =AVERAGE(D55:D57) -> 0.33333333 | E58: =AVERAGE(E54:E57) -> 0.5 | F58: =AVERAGE(F54:F57) -> 44.5
B60: Table 12: Cases of other bacterial meningitis in Scotland sourced from HPS8,9,10 (2000 to 2009)
B61: Year | C61: Cases of Pneumococcal meningitis reported to SPIDER | D61: Haemophilus influenzae CSF isolates (and cases from 2002) | E61: TB Meningitis Cases reported to ESMI | F61: Other bacterial (CSF Isolates)
B62: 2000 | C62: 32 | D62: 3 | E62: 7 | F62: 23
B63: 2001 | C63: 38 | D63: 4 | E63: 4 | F63: 17
B64: 2002 | C64: 35 | D64: 6 | E64: 7 | F64: 20
B65: 2003 | C65: 27 | D65: 7 | E65: 7 | F65: 20
B66: 2004 | C66: 19 | D66: 6 | E66: 8 | F66: 20
B67: 2005 | C67: 36 | D67: 7 | E67: 3 | F67: 17
B68: 2006 | C68: 37 | D68: 2 | E68: 8 | F68: 45
B69: 2007 | C69: 18 | D69: 6 | E69: 9 | F69: 54
B70: 2008 | C70: 24 | D70: 6 | E70: 11 | F70: 58
B71: 2009 | C71: 25 | D71: 2 | E71: 10 | F71: 81
B72: Average | C72: =AVERAGE(C69:C71) -> 22.333333 | D72: =AVERAGE(D69:D71) -> 4.6666667 | E72: =AVERAGE(E62:E71) -> 7.4 | F72: =AVERAGE(F62:F71) -> 35.5

Sheet Refs
A1: References
A3: 1. http://www.hesonline.nhs.uk/Ease/servlet/ContentServer?siteID=1937&categoryID=203
A4: 2. http://www.hpa.org.uk/Topics/InfectiousDiseases/InfectionsAZ/MeningococcalDisease/EpidemiologicalData/
A5: 3. http://www.publichealthagency.org/directorate-public-health/health-protection/meningococcal-disease
A6: 4. http://www.hps.scot.nhs.uk/surveillance/SystemsDetail.aspx?id=13
A7: 5. http://www.hpa.org.uk/infections/topics_az/noids/archive.htm
A8: 6. http://www.publichealth.hscni.net/directorate-public-health/health-protection/surveillance-data
A9: 7. http://www.publichealthagency.org/directorate-public-health/health-protection/tuberculosis
A10: 8. http://www.hps.scot.nhs.uk/resp/ssdetail.aspx?id=14
A11: 9. http://www.hps.scot.nhs.uk/surveillance/SystemsDetail.aspx?id=18
A12: 10. http://www.hps.scot.nhs.uk/resp/ssdetail.aspx?id=15
