Workbook
Name Cu: [1]Elements!$C$26
Name Dy: [1]Elements!$C$27
Name Er: [1]Elements!$C$28
Name Eu: [1]Elements!$C$29
Name ex: #REF!
Name F: [1]Elements!$C$30
Name Fe: [1]Elements!$C$31
Name Fr: [1]Elements!$C$32
Name Ga: [1]Elements!$C$33
Name Gd: [1]Elements!$C$34
Name Ge: [1]Elements!$C$35
Name H: [1]Elements!$C$36
Name He: [1]Elements!$C$37
Name Hf: [1]Elements!$C$38
Name Hg: [1]Elements!$C$39
Name Ho: [1]Elements!$C$40
Name HX: #REF!
Name I: [1]Elements!$C$41
Name In: [1]Elements!$C$42
Name Ir: [1]Elements!$C$43
Name K: [1]Elements!$C$44
Name Kr: [1]Elements!$C$45
Name Krx: '[2]SO2+O2'!$C$4
Name La: [1]Elements!$C$46
Name Li: [1]Elements!$C$47
Name Lu: [1]Elements!$C$48
Name Mg: [1]Elements!$C$49
Name Mn: [1]Elements!$C$50
Name Mo: [1]Elements!$C$51
Name MolsSO3: '[2]SO2+O2'!$C$6:$I$6
Name N: [1]Elements!$C$52
Name Na: [1]Elements!$C$53
Name Nb: [1]Elements!$C$54
Name Nd: [1]Elements!$C$55
Name Ne: [1]Elements!$C$56
Name NGEqns: #REF!
Name NGRfrm: #REF!
Name Ni: [1]Elements!$C$57
Name Np: [1]Elements!$C$58
Name O: [1]Elements!$C$59
Name Os: [1]Elements!$C$60
Name P: [1]Elements!$C$61
Name Pa: [1]Elements!$C$62
Name Pb: [1]Elements!$C$63
Name PbCond: [3]ZnCond!$A$39
Name PbCond2: [4]ZnCond!#REF!
Name Pd: [1]Elements!$C$64
Name Pm: [1]Elements!$C$65
Name Po: [1]Elements!$C$66
Name Pr: [1]Elements!$C$67
Name PressUnit: '[5]Title and Units panel'!$N$37
Name Pressure: '[2]SO2+O2'!$C$5:$I$5
Name Pt: [1]Elements!$C$68
Name Pu: [1]Elements!$C$69
Name QtyUnit: '[5]Title and Units panel'!$K$37
Name Ra: [1]Elements!$C$70
Name Rb: [1]Elements!$C$71
Name Re: [1]Elements!$C$72
Name Rh: [1]Elements!$C$73
Name Rn: [1]Elements!$C$74

Sheet MainEntry&Data
B1: Note: text box appearance may vary with different Windows and Excel versions.
D2: Please Read Cell Comments
J11: Offgas temp., °C | K11: 900
J12: Heat loss, kJ | K12: 40
D18: Natural Gas Properties | J18: Oxidant Properties
D19: Species | E19: Mol. mass | F19: Vol % | J19: % O2 in Oxidant | K19: 0.21
C20: Methane | D20: CH4 | E20: 16.043 | F20: 0.93 | J20: Upper limit on % excess oxidant | K20: 1
C21: Ethene | D21: C2H4 | E21: 28.054 | F21: 0.005
C22: Ethane | D22: C2H6 | E22: 30.07 | F22: 0.02 | J22: Element Balance
C23: Propane | D23: C3H8 | E23: 44.097 | F23: 0.004 | J23: moles | K23: mass | M23: Figure 1. Relationship between the % gross available heat and the % excess oxidant used for NG combustion.
C24: Butanes & higher | D24: C4H10 + | E24: 58.124 | F24: 0.003 | I24: C | J24: =F20+2*F21+2*F22+3*F23+4*F24+F26+F27 -> 1.012 | K24: =12.01*J24 -> 12.15412 | M24: Chart and table will reconfigure when any entry value is changed. Legend refers to offgas temp. (cell K11).
C25: Hydrogen | D25: H2 | E25: 2.016 | F25: 0.005 | I25: H | J25: =4*F20+4*F21+6*F22+8*F23+10*F24+2*F25+2*F28 -> 3.942 | K25: =1.00795*J25 -> 3.9733389 | M25: Excel's Trendline tool can be used to give a linear equation fit to the results.
C26: Carbon monoxide | D26: CO | E26: 28.011 | F26: 0.005 | I26: O | J26: =F26+2*F27+F28 -> 0.016 | K26: =16*J26 -> 0.256
C27: Carbon dioxide | D27: CO2 | E27: 44.011 | F27: 0.003 | I27: N | J27: =2*F29 -> 0.04 | K27: =14.007*J27 -> 0.56028 | Q27: Summary of Results
C28: Water vapor | D28: H2O | E28: 18.016 | F28: 0.005 | I28: Sum | J28: =SUM(J24:J27) -> 5.01 | K28: =SUM(K24:K27) -> 16.943739 | M28: =Calcs!L7 -> % XS oxidant | N28: =Calcs!M7 -> 0 | O28: =Calcs!N7 -> 0.1 | P28: =Calcs!O7 -> 0.2 | Q28: =Calcs!P7 -> 0.4 | R28: =Calcs!Q7 -> 0.6 | S28: =Calcs!R7 -> 0.8 | T28: =Calcs!S7 -> 1
C29: Nitrogen (by diff.) | D29: N2 | E29: 28.014 | F29: =1 - SUM(F20:F28) -> 0.02 | M29: =Calcs!L40 -> % gross avail heat | N29: =Calcs!M40 -> 0.60836935 | O29: =Calcs!N40 -> 0.57576557 | P29: =Calcs!O40 -> 0.54316178 | Q29: =Calcs!P40 -> 0.47795421 | R29: =Calcs!Q40 -> 0.41274664 | S29: =Calcs!R40 -> 0.34753907 | T29: =Calcs!S40 -> 0.2823315
M30: =Calcs!L41 -> Heat loss, kJ/mol of NG | N30: =Calcs!M41 -> 40 | O30: =Calcs!N41 -> 40 | P30: =Calcs!O41 -> 40 | Q30: =Calcs!P41 -> 40 | R30: =Calcs!Q41 -> 40 | S30: =Calcs!R41 -> 40 | T30: =Calcs!S41 -> 40
D31: Molecular mass of NG | E31: =E20*F20+E21*F21+E22*F22+E23*F23+E24*F24+E25*F25+E26*F26+E27*F27+E28*F28+E29*F29 -> 16.944948 | M31: =Calcs!L42 -> % net avail heat | N31: =Calcs!M42 -> 0.55837597 | O31: =Calcs!N42 -> 0.52577218 | P31: =Calcs!O42 -> 0.49316839 | Q31: =Calcs!P42 -> 0.42796082 | R31: =Calcs!Q42 -> 0.36275325 | S31: =Calcs!R42 -> 0.29754568 | T31: =Calcs!S42 -> 0.23233811
E34: Table I. Molar DH°form at 25 °C | I34: Table II. Molar DH°reax at 25 °C
E35: kJ/g-mol | H35: Reaction to form H2O(g) | K35: kJ/g-mol
D36: CH4 | E36: -74.81 | G36: 2O2 + CH4 → CO2 + 2H2O(g) | K36: =2*E45+E44 - E36 -> -802.327
D37: C2H4 | E37: 52.467 | G37: 3O2 + C2H4 → 2CO2 + 2H2O(g) | K37: =2*E45+2*E44 - E37 -> -1323.113
D38: C2H6 | E38: -84.684 | G38: 3½O2 + C2H6 → 2CO2 + 3H2O(g) | K38: =3*E45+2*E44 - E38 -> -1427.776
C39: NG reactant species | D39: C3H8 | E39: -103.847 | G39: 5O2 + C3H8 → 3CO2 + 4H2O(g) | K39: =4*E45+3*E44 - E39 -> -2043.936
D40: C4H10 | E40: -126.148 | G40: 6½O2 + C4H10 → 4CO2 + 5H2O(g) | K40: =5*E45+4*E44 - E40 -> -2656.958
D41: H2 | E41: 0 | G41: ½O2 + H2 → H2O(g) | K41: =E45 -> -241.814
D42: CO | E42: -110.529 | G42: ½O2 + CO → CO2 | K42: =E44-E42 -> -282.98
C44: Combustion | D44: CO2 | E44: -393.509 | G44: H2O(g) → H2O(liq) | K44: -44.02
C45: products | D45: H2O(g) | E45: -241.814
D46: H2O(liq) | E46: -285.83
C48: Table III. Heat Content Above 25 °C, J/g-mol
C49: T (°C) | D49: O2 | E49: N2 | F49: H2O(g) | G49: CO2
C50: 25 | D50: 0 | E50: 0 | F50: 0 | G50: 0
C51: 192.5 | D51: 5022.2001 | E51: 4862.988 | F51: 5707.7289 | G51: 6776.6053
C52: 360 | D52: 10322.96 | E52: 9872.3201 | F52: 11690.433 | G52: 14482.885
C53: 527.5 | D53: 15867.47 | E53: 15072.094 | F53: 18014.031 | G53: 22850.716
C54: 695 | D54: 21596.854 | E54: 20444.54 | F54: 24689.831 | G54: 31691.271
C55: 862.5 | D55: 27467.517 | E55: 25966.04 | F55: 31710.227 | G55: 40880.219
C56: 1030 | D56: 33449.504 | E56: 31615.127 | F56: 39058.912 | G56: 50333.073
C57: 1197.5 | D57: 39522.532 | E57: 37373.239 | F57: 46714.937 | G57: 59990.298
...

Sheet Calcs
B1: Please read cell comments
C2: Legend
B3: Entered in MainEntry
N4: Material Balance Calculations
F6: Natural Gas Properties | L6: Vol. % O2 in oxidant gas | M6: ='MainEntry&Data'!K19 -> 0.21
D7: Species | E7: Mol. mass | F7: Vol % | G7: Mass, g | H7: Mass % | I7: DH°comb | L7: % XS oxidant | M7: 0 | N7: =S7*0.1 -> 0.1 | O7: =S7*0.2 -> 0.2 | P7: =S7*0.4 -> 0.4 | Q7: =S7*0.6 -> 0.6 | R7: =S7*0.8 -> 0.8 | S7: ='MainEntry&Data'!K20 -> 1
C8: Methane | D8: CH4 | E8: 16.043 | F8: ='MainEntry&Data'!F20 -> 0.93 | G8: =E8*F8 -> 14.91999 | H8: =G8/$E$19 -> 0.88049783 | I8: =F8*'MainEntry&Data'!K36 -> -746.16411 | AT8: Vol. % O2 in oxidant gas | AU8: ='MainEntry&Data'!K19 -> 0.21
C9: Ethene | D9: C2H4 | E9: 28.054 | F9: ='MainEntry&Data'!F21 -> 0.005 | G9: =E9*F9 -> 0.14027 | H9: =G9/$E$19 -> 0.0082779835 | I9: =F9*'MainEntry&Data'!K37 -> -6.615565 | L9: Combustion products | M9: =3*F8 + 4*F9 + 5*F10 + 7*F11 + 9*F12 + F13 + F14 + F15 + F16 + F17 -> 3.003 | O9: Offgas temp., °C | P9: ='MainEntry&Data'!K11 -> 900 | AT9: Desired %O2 in comb. flame | AU9: 0 | AV9: =AY9*0.25 -> 0.0125 | AW9: =AY9*0.5 -> 0.025 | AX9: =AY9*0.75 -> 0.0375 | AY9: 0.05
C10: Ethane | D10: C2H6 | E10: 30.07 | F10: ='MainEntry&Data'!F22 -> 0.02 | G10: =E10*F10 -> 0.6014 | H10: =G10/$E$19 -> 0.035491404 | I10: =F10*'MainEntry&Data'!K38 -> -28.55552 | L10: Stoichiometric oxidant | M10: =(2*F8 + 3*F9 + 3.5*F10 + 5*F11 + 6.5*F12 + 0.5*F13 + 0.5*F14)/M6 -> 9.4738095
C11: Propane | D11: C3H8 | E11: 44.097 | F11: ='MainEntry&Data'!F23 -> 0.004 | G11: =E11*F11 -> 0.176388 | H11: =G11/$E$19 -> 0.010409474 | I11: =F11*'MainEntry&Data'!K39 -> -8.175744 | L11: Stoichiometric oxidant inerts | M11: =M10*(1-M6) -> 7.4843095 | AT11: Combustion products | AU11: =3*F8 + 4*F9 + 5*F10 + 7*F11 + 9*F12 + F13 + F14 + F15 + F16 + F17 -> 3.003
C12: Butanes & higher | D12: C4H10 + | E12: 58.124 | F12: ='MainEntry&Data'!F24 -> 0.003 | G12: =E12*F12 -> 0.174372 | H12: =G12/$E$19 -> 0.010290501 | I12: =F12*'MainEntry&Data'!K40 -> -7.970874 | L12: Oxidant gas required | M12: =M10*(1+M7) -> 9.4738095 | N12: =$M$10*(1+N7) -> 10.42119 | O12: =$M$10*(1+O7) -> 11.368571 | P12: =$M$10*(1+P7) -> 13.263333 | Q12: =$M$10*(1+Q7) -> 15.158095 | R12: =$M$10*(1+R7) -> 17.052857 | S12: =$M$10*(1+S7) -> 18.947619 | AT12: Stoichiometric oxidant | AU12: =(2*F8 + 3*F9 + 3.5*F10 + 5*F11 + 6.5*F12 + 0.5*F13 + 0.5*F14)/AU8 -> 9.4738095
C13: Hydrogen | D13: H2 | E13: 2.016 | F13: ='MainEntry&Data'!F25 -> 0.005 | G13: =E13*F13 -> 0.01008 | H13: =G13/$E$19 -> 0.00059486757 | I13: =F13*'MainEntry&Data'!K41 -> -1.20907 | L13: Excess oxidant | M13: =M12-$M$10 -> 0 | N13: =N12-$M$10 -> 0.94738095 | O13: =O12-$M$10 -> 1.8947619 | P13: =P12-$M$10 -> 3.7895238 | Q13: =Q12-$M$10 -> 5.6842857 | R13: =R12-$M$10 -> 7.5790476 | S13: =S12-$M$10 -> 9.4738095 | AT13: Stoichiometric oxidant inerts | AU13: =AU12*(1-AU8) -> 7.4843095
C14: Carbon monoxide | D14: CO | E14: 28.011 | F14: ='MainEntry&Data'!F26 -> 0.005 | G14: =E14*F14 -> 0.140055 | H14: =G14/$E$19 -> 0.0082652954 | I14: =F14*'MainEntry&Data'!K42 -> -1.4149 | L14: %O2 in offgas | M14: =$M$6*M13/($M$9 + $M$11 + M13) -> 0 | N14: =$M$6*N13/($M$9 + $M$11 + N13) -> 0.017398809 | O14: =$M$6*O13/($M$9 + $M$11 + O13) -> 0.032135172 | P14: =$M$6*P13/($M$9 + $M$11 + P13) -> 0.055740652 | Q14: =$M$6*Q13/($M$9 + $M$11 + Q13) -> 0.07381461 | R14: =$M$6*R13/($M$9 + $M$11 + R13) -> 0.08809745 | S14: =$M$6*S13/($M$9 + $M$11 + S13) -> 0.099668761 | AT14: Excess oxidant | AU14: =AU9*($AU$11+$AU$13)/($AU$8-AU9) -> 0 | AV14: =AV9*($AU$11+$AU$13)/($AU$8-AV9) -> 0.66375377 | AW14: =AW9*($AU$11+$AU$13)/($AU$8-AW9) -> 1.417204 | AX14: =AX9*($AU$11+$AU$13)/($AU$8-AX9) -> 2.2798499 | AY14: =AY9*($AU$11+$AU$13)/($AU$8-AY9) -> 3.2772842
C15: Carbon dioxide | D15: CO2 | E15: 44.011 | F15: ='MainEntry&Data'!F27 -> 0.003 | G15: =E15*F15 -> 0.132033 | H15: =G15/$E$19 -> 0.0077918799 | I15: 0 | L15: Offgas amount | M15: =$M$9+$M$11+M13 -> 10.48731 | N15: =$M$9+$M$11+N13 -> 11.43469 | O15: =$M$9+$M$11+O13 -> 12.382071 | P15: =$M$9+$M$11+P13 -> 14.276833 | Q15: =$M$9+$M$11+Q13 -> 16.171595 | R15: =$M$9+$M$11+R13 -> 18.066357 | S15: =$M$9+$M$11+S13 -> 19.961119 | AT15: % stoichiometric oxidant gas | AU15: =AU17/$AU$12 -> 1 | AV15: =AV17/$AU$12 -> 1.070062 | AW15: =AW17/$AU$12 -> 1.1495918 | AX15: =AX17/$AU$12 -> 1.2406476 | AY15: =AY17/$AU$12 -> 1.345931
C16: Water vapor | D16: H2O | E16: 18.016 | F16: ='MainEntry&Data'!F28 -> 0.005 | G16: =E16*F16 -> 0.09008 | H16: =G16/$E$19 -> 0.0053160387 | I16: 0 | L16: Dry stack gas amount | M16: =M15-$M$21 -> 8.5163095 | N16: =N15-$M$21 -> 9.4636905 | O16: =O15-$M$21 -> 10.411071 | P16: =P15-$M$21 -> 12.305833 | Q16: =Q15-$M$21 -> 14.200595 | R16: =R15-$M$21 -> 16.095357 | S16: =S15-$M$21 -> 17.990119 | AT16: % excess oxidant gas | AU16: =AU14/$AU$12 -> 0 | AV16: =AV14/$AU$12 -> 0.070061971 | AW16: =AW14/$AU$12 -> 0.14959178 | AX16: =AX14/$AU$12 -> 0.24064764 | AY16: =AY14/$AU$12 -> 0.34593098
C17: Nitrogen (by diff.) | D17: N2 | E17: 28.014 | F17: ='MainEntry&Data'!F29 -> 0.02 | G17: =E17*F17 -> 0.56028 | H17: =G17/$E$19 -> 0.033064722 | I17: 0 | L17: %O2 in dry offgas | M17: =$M$6*M13/M16 -> 0 | N17: =$M$6*N13/N16 -> 0.021022454 | O17: =$M$6*O13/O16 -> 0.038218929 | P17: =$M$6*P13/P16 -> 0.064668518 | Q17: =$M$6*Q13/Q16 -> 0.084059857 | R17: =$M$6*R13/R16 -> 0.098885659 | S17: =$M$6*S13/S16 -> 0.11058848 | AT17: Required oxidant | AU17: =$AU$12+AU14 -> 9.4738095 | AV17: =$AU$12+AV14 -> 10.137563 | AW17: =$AU$12+AW14 -> 10.891014 | AX17: =$AU$12+AX14 -> 11.753659 | AY17: =$AU$12+AY14 -> 12.751094
L18: Oxidant mass | M18: =M12*($M$6*$E$20+(1-$M$6)*$E$17) -> 273.32945 | N18: =N12*($M$6*$E$20+(1-$M$6)*$E$17) -> 300.66239 | O18: =O12*($M$6*$E$20+(1-$M$6)*$E$17) -> 327.99534 | P18: =P12*($M$6*$E$20+(1-$M$6)*$E$17) -> 382.66123 | Q18: =Q12*($M$6*$E$20+(1-$M$6)*$E$17) -> 437.32712 | R18: =R12*($M$6*$E$20+(1-$M$6)*$E$17) -> 491.993 | S18: =S12*($M$6*$E$20+(1-$M$6)*$E$17) -> 546.65889 | AT18: Combustion water | AU18: =2*F8+2*F9+3*F10+4*F11+5*F12+F13+F16 -> 1.971
D19: Molecular mass of NG | E19: =E8*F8+E9*F9+E10*F10+E11*F11+E12*F12+E13*F13+E14*F14+E15*F15+E16*F16+E17*F17 -> 16.944948 | H19: DH°comb of NG, kJ/g-mol | I19: =SUM(I8:I14) -> -800.10578 | L19: Oxidant/NG mass ratio | M19: =M18/$E$19 -> 16.130439 | N19: =N18/$E$19 -> 17.743483 | O19: =O18/$E$19 -> 19.356527 | P19: =P18/$E$19 -> 22.582614 | Q19: =Q18/$E$19 -> 25.808702 | R19: =R18/$E$19 -> 29.03479 | S19: =S18/$E$19 -> 32.260878 | AT19: Stack gas volume | AU19: =$AU$11+$AU$13+AU14 -> 10.48731 | AV19: =$AU$11+$AU$13+AV14 -> 11.151063 | AW19: =$AU$11+$AU$13+AW14 -> 11.904514 | AX19: =$AU$11+$AU$13+AX14 -> 12.767159 | AY19: =$AU$11+$AU$13+AY14 -> 13.764594
D20: Molecular mass of O2 | E20: 32 | AT20: Dry stack gas volume | AU20: =AU19-$AU$18 -> 8.5163095 | AV20: =AV19-$AU$18 -> 9.1800633 | AW20: =AW19-$AU$18 -> 9.9335135 | AX20: =AX19-$AU$18 -> 10.796159 | AY20: =AY19-$AU$18 -> 11.793594
L21: Offgas H2O | M21: =2*F8+2*F9+3*F10+4*F11+5*F12+F13+F16 -> 1.971 | N21: =$M$21 -> 1.971 | O21: =$M$21 -> 1.971 | P21: =$M$21 -> 1.971 | Q21: =$M$21 -> 1.971 | R21: =$M$21 -> 1.971 | S21: =$M$21 -> 1.971 | AT21: %O2 in dry stack gas | AU21: =$AU$8*AU14/AU20 -> 0 | AV21: =$AU$8*AV14/AV20 -> 0.015183805 | AW21: =$AU$8*AW14/AW20 -> 0.02996048 | AX21: =$AU$8*AX14/AX20 -> 0.044346185 | AY21: =$AU$8*AY14/AY20 -> 0.058356232
G22: moles | H22: mass | K22: Amount, | L22: Offgas CO2 | M22: =F8+2*F9+2*F10+3*F11+4*F12+F14+F15 -> 1.012 | N22: =$M$22 -> 1.012 | O22: =$M$22 -> 1.012 | P22: =$M$22 -> 1.012 | Q22: =$M$22 -> 1.012 | R22: =$M$22 -> 1.012 | S22: =$M$22 -> 1.012
F23: CO2 produced by combustion | G23: ='MainEntry&Data'!J24-F15 -> 1.009 | H23: =G23*28.01 -> 28.26209 | K23: g-mol | L23: Offgas N2 | M23: =$F$17+M12*(1-$M$6) -> 7.5043095 | N23: =$F$17+N12*(1-$M$6) -> 8.2527405 | O23: =$F$17+O12*(1-$M$6) -> 9.0011714 | P23: =$F$17+P12*(1-$M$6) -> 10.498033 | Q23: =$F$17+Q12*(1-$M$6) -> 11.994895 | R23: =$F$17+R12*(1-$M$6) -> 13.491757 | S23: =$F$17+S12*(1-$M$6) -> 14.988619 | AT23: Oxidant mass | AU23: =AU17*($AU$8*$E$20+(1-$AU$8)*$E$17) -> 273.32945 | AV23: =AV17*($AU$8*$E$17+(1-$AU$8)*$E$14) -> 283.96967 | AW23: =AW17*($AU$8*$E$17+(1-$AU$8)*$E$14) -> 305.07504 | AX23: =AX17*($AU$8*$E$17+(1-$AU$8)*$E$14) -> 329.23916 | AY23: =AY17*($AU$8*$E$17+(1-$AU$8)*$E$14) -> 357.17892
F24: H2O produced by combustion | G24: ='MainEntry&Data'!J25/2 - F16 -> 1.966 | H24: =G24*18.016 -> 35.419456 | L24: Offgas O2 | M24: =(M12-$M$10)*$M$6 -> 0 | N24: =(N12-$M$10)*$M$6 -> 0.19895 | O24: =(O12-$M$10)*$M$6 -> 0.3979 | P24: =(P12-$M$10)*$M$6 -> 0.7958 | Q24: =(Q12-$M$10)*$M$6 -> 1.1937 | R24: =(R12-$M$10)*$M$6 -> 1.5916 | S24: =(S12-$M$10)*$M$6 -> 1.9895 | AT24: Ox/NG mass ratio | AU24: =AU23/#REF! -> #REF! | AV24: =AV23/#REF! -> #REF! | AW24: =AW23/#REF! -> #REF! | AX24: =AX23/#REF! -> #REF! | AY24: =AY23/#REF! -> #REF!
F25: Stoich. O2 required for combustion | G25: =G23+G24/2 -> 1.992 | H25: =G25*32 -> 63.744
L26: Offgas H2O | M26: =M21/M15 -> 0.18794143 | N26: =N21/N15 -> 0.17237021 | O26: =O21/O15 -> 0.15918177 | P26: =P21/P15 -> 0.13805582 | Q26: =Q21/Q15 -> 0.12188037 | R26: =R21/R15 -> 0.10909781 | S26: =S21/S15 -> 0.098741959
K27: Composition, | L27: Offgas CO2 | M27: =M22/M15 -> 0.096497581 | N27: =N22/N15 -> 0.088502614 | O27: =O22/O15 -> 0.081731074 | P27: =P22/P15 -> 0.070884066 | Q27: =Q22/Q15 -> 0.06257886 | R27: =R22/R15 -> 0.05601572 | S27: =S22/S15 -> 0.05069856
F28: Table IV. Heat content equation parameters, J/g-mol = A + BT + CT2 + DT3 | K28: vol. % | L28: Offgas N2 | M28: =M23/M15 -> 0.71556098 | N28: =N23/N15 -> 0.72172837 | O28: =O23/O15 -> 0.72695199 | P28: =P23/P15 -> 0.73531946 | Q28: =Q23/Q15 -> 0.74172616 | R28: =R23/R15 -> 0.74678902 | S28: =S23/S15 -> 0.75089072
D29: N2, 25 - 1750 °C | H29: O2, 25 - 1750 °C | L29: Offgas O2 | M29: =M24/M15 -> 0 | N29: =N24/N15 -> 0.017398809 | O29: =O24/O15 -> 0.032135172 | P29: =P24/P15 -> 0.055740652 | Q29: =Q24/Q15 -> 0.07381461 | R29: =R24/R15 -> 0.08809745 | S29: =S24/S15 -> 0.099668761
C30: A | D30: B | E30: C | G30: A | H30: B | I30: C
C31: -818 | D31: 29.08 | E31: 0.002294 | G31: -965 | H31: 30.94 | I31: 0.002309
O32: Available Heat Calculations
C33: H2O(g), 25 - 1750 °C | H33: CO2, 25 - 1750 °C
B34: A | C34: B | D34: C | E34: D | G34: A | H34: B | I34: C | J34: D | L34: Species | M34: Heat content at offgas temperature, kJ
B35: -778 | C35: 32.2 | D35: 0.006755 | E35: -4.45e-07 | G35: -1082 | H35: 38.87 | I35: 0.01395 | J35: -3.167e-06 | L35: H2O | M35: =M21*(B35+C35*P9+D35*P9^2+E35*P9^3)/1000 -> 65.731165 | N35: =$M$35 -> 65.731165 | O35: =$M$35 -> 65.731165 | P35: =$M$35 -> 65.731165 | Q35: =$M$35 -> 65.731165 | R35: =$M$35 -> 65.731165 | S35: =$M$35 -> 65.731165
L36: CO2 | M36: =M22*(G35+H35*P9+I35*P9^2+J35*P9^3)/1000 -> 43.406458 | N36: =$M$36 -> 43.406458 | O36: =$M$36 -> 43.406458 | P36: =$M$36 -> 43.406458 | Q36: =$M$36 -> 43.406458 | R36: =$M$36 -> 43.406458 | S36: =$M$36 -> 43.406458
L37: N2 | M37: =M23*($C$31+$D$31*$P$9+$E$31*$P$9^2)/1000 -> 204.20832 | N37: =N23*($C$31+$D$31*$P$9+$E$31*$P$9^2)/1000 -> 224.57473 | O37: =O23*($C$31+$D$31*$P$9+$E$31*$P$9^2)/1000 -> 244.94114 | P37: =P23*($C$31+$D$31*$P$9+$E$31*$P$9^2)/1000 -> 285.67395 | Q37: =Q23*($C$31+$D$31*$P$9+$E$31*$P$9^2)/1000 -> 326.40677 | R37: =R23*($C$31+$D$31*$P$9+$E$31*$P$9^2)/1000 -> 367.13958 | S37: =S23*($C$31+$D$31*$P$9+$E$31*$P$9^2)/1000 -> 407.8724
L38: O2 | M38: =M24*($G$31+$H$31*$P$9+$I$31*$P$9^2)/1000 -> 0 | N38: =N24*($G$31+$H$31*$P$9+$I$31*$P$9^2)/1000 -> 5.7200691 | O38: =O24*($G$31+$H$31*$P$9+$I$31*$P$9^2)/1000 -> 11.440138 | P38: =P24*($G$31+$H$31*$P$9+$I$31*$P$9^2)/1000 -> 22.880277 | Q38: =Q24*($G$31+$H$31*$P$9+$I$31*$P$9^2)/1000 -> 34.320415 | R38: =R24*($G$31+$H$31*$P$9+$I$31*$P$9^2)/1000 -> 45.760553 | S38: =S24*($G$31+$H$31*$P$9+$I$31*$P$9^2)/1000 -> 57.200691
L39: Total | M39: =SUM(M35:M38) -> 313.34594 | N39: =SUM(N35:N38) -> 339.43242 | O39: =SUM(O35:O38) -> 365.5189 | P39: =SUM(P35:P38) -> 417.69185 | Q39: =SUM(Q35:Q38) -> 469.86481 | R39: =SUM(R35:R38) -> 522.03776 | S39: =SUM(S35:S38) -> 574.21071
L40: % gross avail heat | M40: =(-$I$19-M39)/-$I$19 -> 0.60836935 | N40: =(-$I$19-N39)/-$I$19 -> 0.57576557 | O40: =(-$I$19-O39)/-$I$19 -> 0.54316178 | P40: =(-$I$19-P39)/-$I$19 -> 0.47795421 | Q40: =(-$I$19-Q39)/-$I$19 -> 0.41274664 | R40: =(-$I$19-R39)/-$I$19 -> 0.34753907 | S40: =(-$I$19-S39)/-$I$19 -> 0.2823315
L41: Heat loss, kJ/mol of NG | M41: ='MainEntry&Data'!K12 -> 40 | N41: =$M$41 -> 40 | O41: =$M$41 -> 40 | P41: =$M$41 -> 40 | Q41: =$M$41 -> 40 | R41: =$M$41 -> 40 | S41: =$M$41 -> 40
...

Sheet StoredResults
F2: Multiple Results of Available Heat Calculations Using 21% O2 Oxidant
B4: Offgas temp., °C | C4: 600 | D4: 700 | E4: 800 | F4: 900 | G4: 1000 | H4: 1100 | I4: 1200 | J4: 1300 | K4: 1400
C6: 0 | D6: 0 | E6: 0 | F6: 0 | G6: 0 | H6: 0 | I6: 0 | J6: 0 | K6: 0
C7: 0.13 | D7: 0.13 | E7: 0.13 | F7: 0.13 | G7: 0.13 | H7: 0.13 | I7: 0.13 | J7: 0.13 | K7: 0.13
C8: 0.26 | D8: 0.26 | E8: 0.26 | F8: 0.26 | G8: 0.26 | H8: 0.26 | I8: 0.26 | J8: 0.26 | K8: 0.26
B9: % XS oxidant | C9: 0.52 | D9: 0.52 | E9: 0.52 | F9: 0.52 | G9: 0.52 | H9: 0.52 | I9: 0.52 | J9: 0.52 | K9: 0.52 | AA9: Table 1. Heat content equation parameters, J/g-mol = A + BT + CT2 + DT3
C10: 0.78 | D10: 0.78 | E10: 0.78 | F10: 0.78 | G10: 0.78 | H10: 0.78 | I10: 0.78 | J10: 0.78 | K10: 0.78 | Y10: N2, 25 - 1750 °C | AC10: O2, 25 - 1750 °C
C11: 1.04 | D11: 1.04 | E11: 1.04 | F11: 1.04 | G11: 1.04 | H11: 1.04 | I11: 1.04 | J11: 1.04 | K11: 1.04 | X11: A | Y11: B | Z11: C | AB11: A | AC11: B | AD11: C
C12: 1.3 | D12: 1.3 | E12: 1.3 | F12: 1.3 | G12: 1.3 | H12: 1.3 | I12: 1.3 | J12: 1.3 | K12: 1.3 | X12: -818 | Y12: 29.08 | Z12: 0.002294 | AB12: -965 | AC12: 30.94 | AD12: 0.002309
C14: 0.7512319 | D14: 0.70450258 | E14: 0.65687153 | F14: 0.60836935 | G14: 0.55902668 | H14: 0.5088741 | I14: 0.45794225 | J14: 0.40626172 | K14: 0.35386313 | X14: H2O, 25 - 1750 °C | AC14: CO2, 25 - 1750 °C
C15: 0.72404731 | D15: 0.67232193 | E15: 0.6196241 | F15: 0.56598443 | G15: 0.51143354 | H15: 0.45600203 | I15: 0.39972051 | J15: 0.34261961 | K15: 0.28472993 | W15: A | X15: B | Y15: C | Z15: D | AB15: A | AC15: B | AD15: C | AE15: D
C16: 0.69686273 | D16: 0.64014129 | E16: 0.58237668 | F16: 0.52359951 | G16: 0.4638404 | H16: 0.40312995 | I16: 0.34149878 | J16: 0.2789775 | K16: 0.21559672 | W16: -778 | X16: 32.2 | Y16: 0.006755 | Z16: -4.45e-07 | AB16: -1082 | AC16: 38.87 | AD16: 0.01395 | AE16: -3.167e-06
B17: % gross avail heat | C17: 0.64249356 | D17: 0.57578 | E17: 0.50788184 | F17: 0.43882967 | G17: 0.36865412 | H17: 0.2973858 | I17: 0.22505532 | J17: 0.15169328 | K17: 0.077330306
C18: 0.58812439 | D18: 0.51141871 | E18: 0.43338699 | F18: 0.35405983 | G18: 0.27346785 | H18: 0.19164165 | I18: 0.10861185 | J18: 0.02440906 | K18: -0.060936107
C19: 0.53375522 | D19: 0.44705743 | E19: 0.35889215 | F19: 0.26928999 | G19: 0.17828157 | H19: 0.085897496 | I19: -0.0078316178 | J19: -0.10287516 | K19: -0.19920252
C20: 0.47938605 | D20: 0.38269614 | E20: 0.2843973 | F20: 0.18452015 | G20: 0.083095292 | H20: -0.019846656 | I20: -0.12427508 | J20: -0.23015938 | K20: -0.33746893
D22: Species | E22: Vol %
C23: Methane | D23: CH4 | E23: 0.93
C24: Ethene | D24: C2H4 | E24: 0.005
C25: Ethane | D25: C2H6 | E25: 0.02
C26: Propane | D26: C3H8 | E26: 0.004
C27: Butanes & higher | D27: C4H10 + | E27: 0.003
C28: Hydrogen | D28: H2 | E28: 0.005 | L28: Figure 1. Results of gross available heat calculations for 9 different offgas temperatures, between 0% and 130% excess oxidant.
C29: Carbon monoxide | D29: CO | E29: 0.005 | L29: Excel's Trendline tool can be used to obtain linear equation fits to each line.
C30: Carbon dioxide | D30: CO2 | E30: 0.003 | L30: Values based on H2O(g) as the combustion product.
C31: Water vapor | D31: H2O | E31: 0.005
C32: Nitrogen (by diff.) | D32: N2 | E32: 0.02
O36: Results for Methane Combustion
M37: % XS oxidant | N37: 0 | O37: 0.1 | P37: 0.2 | Q37: 0.4 | R37: 0.6 | S37: 0.8 | T37: 1
M38: % avail heat | N38: 0.65674743 | O38: 0.6280241 | P38: 0.59930076 | Q38: 0.54185408 | R38: 0.4844074 | S38: 0.42696072 | T38: 0.36951404 | U38: 800°C
K39: Values based on H2O(g) as the combustion product | M39: % avail heat | N39: 0.60822831 | O39: 0.57554319 | P39: 0.54285807 | Q39: 0.47748783 | R39: 0.41211759 | S39: 0.34674735 | T39: 0.28137712 | U39: 900°C
M40: % avail heat | N40: 0.55886749 | O40: 0.52216605 | P40: 0.48546462 | Q40: 0.41206175 | R40: 0.33865888 | S40: 0.26525601 | T40: 0.19185314 | U40: 1000°C
AE69: 800
AE70: 900
