Workbook
Name Inputall: 'All sites (detail)'!$A$14:$AA$973

Sheet Site reports
A1: LITERACY INCENTIVE AID | F1: LiteracyIncentiveAid
A2: Minnesota Department of Education | F2: 41227
A4: 1 | B4: = District or charter number | C4: Enter the appropriate district and school numbers in the yellow cells.
A5: 3 | B5: = School number | C5: District and charter names and numbers can be found in the Names tab. | J5: Lookup: | K5: =10000*A4+A5 -> 10003
C6: For Minneapolis, enter district = 1.2. | J6: Listed site? | K6: =COUNTIF('All sites (detail)'!A14:A973,'Site reports'!K5) -> 1
C7: Almost every charter school has school number = 10. | J7: Any filters? | K7: =SUMIF('All sites (detail)'!$A$14:$A$973,'Site reports'!K5,'All sites (detail)'!$G$14:$G$973) -> 1
B8: =IF(K6=1,VLOOKUP(10000*$A$4+$A$5,Inputall,4,FALSE),"NOT A LISTED SITE") -> AITKIN PUBLIC SCHOOL DISTRICT
B9: =IF(K6=1,VLOOKUP(10000*$A$4+$A$5,Inputall,6,FALSE),"NOT A LISTED SITE") -> PALISADE ELEMENTARY | C9: FY 2010 | D9: FY 2011 | E9: FY 2012 | F9: Total
B11: MCA Proficiency Counts
A13: 1 | B13: Total grade 3 reading scores | C13: =IF(K7=1,"Filtered",SUMIF('All sites (detail)'!$A$14:$A$973,'Site reports'!$K$5,'All sites (detail)'!H$14:H$973)) -> Filtered | D13: =IF(K7=1,"Filtered",SUMIF('All sites (detail)'!$A$14:$A$973,'Site reports'!$K$5,'All sites (detail)'!J$14:J$973)) -> Filtered | E13: =IF(K7=1,"Filtered",SUMIF('All sites (detail)'!$A$14:$A$973,'Site reports'!$K$5,'All sites (detail)'!L$14:L$973)) -> Filtered | F13: =IF(K7=1,"Filtered",C13+D13+E13) -> Filtered
A14: =A13+1 -> 2 | B14: Total scores in the proficient range | C14: =IF(K7=1,"Filtered",SUMIF('All sites (detail)'!$A$14:$A$973,'Site reports'!$K$5,'All sites (detail)'!I$14:I$973)) -> Filtered | D14: =IF(K7=1,"Filtered",SUMIF('All sites (detail)'!$A$14:$A$973,'Site reports'!$K$5,'All sites (detail)'!K$14:K$973)) -> Filtered | E14: =IF(K7=1,"Filtered",SUMIF('All sites (detail)'!$A$14:$A$973,'Site reports'!$K$5,'All sites (detail)'!M$14:M$973)) -> Filtered | F14: =IF(K7=1,"Filtered",C14+D14+E14) -> Filtered
A15: =A14+1 -> 3 | B15: =+"Proficiency portion = ("&FIXED(A14,0)&")/("&FIXED(A13,0)&") =" -> Proficiency portion = (2)/(1) = | C15: =IF(K7=1,"Filtered",IF(C13=0,0,C14/C13)) -> Filtered | D15: =IF(K7=1,"Filtered",IF(D13=0,0,D14/D13)) -> Filtered | E15: =IF(K7=1,"Filtered",IF(E13=0,0,E14/E13)) -> Filtered | F15: =IF(K7=1,"Filtered",IF(F13=0,0,F14/F13)) -> Filtered
A17: =A15+1 -> 4 | B17: =+"Proficiency allowance = $530 x ("&FIXED(A15,0)&") =" -> Proficiency allowance = $530 x (3) = | C17: n/a | D17: n/a | E17: n/a | F17: =IF(F18=0,0,IF(K7=1,"n/a",ROUND(530*F15,2))) -> n/a
A18: =A17+1 -> 5 | B18: Grade 3 enrollment as of October 2011 | C18: n/a | D18: n/a | E18: n/a | F18: =SUMIF('All sites (detail)'!$A$14:$A$973,'Site reports'!$K$5,'All sites (detail)'!T$14:T$973) -> 7
A19: =A18+1 -> 6 | B19: =+"Proficiency aid = ("&FIXED(A17,0)&") x ("&FIXED(A18,0)&") =" -> Proficiency aid = (4) x (5) = | C19: n/a | D19: n/a | E19: n/a | F19: =IF(K7=1,"n/a",SUMIF('All sites (detail)'!$A$14:$A$973,'Site reports'!$K$5,'All sites (detail)'!X$14:X$973)) -> n/a
B21: Growth Model Results
A23: =A19+1 -> 7 | B23: Total grade 4 reading growth results | C23: =IF(K7=1,"Filtered",SUMIF('All sites (detail)'!$A$14:$A$973,'Site reports'!$K$5,'All sites (detail)'!N$14:N$973)) -> Filtered | D23: =IF(K7=1,"Filtered",SUMIF('All sites (detail)'!$A$14:$A$973,'Site reports'!$K$5,'All sites (detail)'!P$14:P$973)) -> Filtered | E23: =IF(K7=1,"Filtered",SUMIF('All sites (detail)'!$A$14:$A$973,'Site reports'!$K$5,'All sites (detail)'!R$14:R$973)) -> Filtered | F23: =IF(K7=1,"Filtered",C23+D23+E23) -> Filtered
A24: =A23+1 -> 8 | B24: Total with high or medium growth | C24: =IF(K7=1,"Filtered",SUMIF('All sites (detail)'!$A$14:$A$973,'Site reports'!$K$5,'All sites (detail)'!O$14:O$973)) -> Filtered | D24: =IF(K7=1,"Filtered",SUMIF('All sites (detail)'!$A$14:$A$973,'Site reports'!$K$5,'All sites (detail)'!Q$14:Q$973)) -> Filtered | E24: =IF(K7=1,"Filtered",SUMIF('All sites (detail)'!$A$14:$A$973,'Site reports'!$K$5,'All sites (detail)'!S$14:S$973)) -> Filtered | F24: =IF(K7=1,"Filtered",C24+D24+E24) -> Filtered
A25: =A24+1 -> 9 | B25: =+"High/Medium Growth portion = ("&FIXED(A24,0)&")/("&FIXED(A23,0)&") =" -> High/Medium Growth portion = (8)/(7) = | C25: =IF(K7=1,"Filtered",IF(C23=0,0,C24/C23)) -> Filtered | D25: =IF(K7=1,"Filtered",IF(D23=0,0,D24/D23)) -> Filtered | E25: =IF(K7=1,"Filtered",IF(E23=0,0,E24/E23)) -> Filtered | F25: =IF(K7=1,"Filtered",IF(F23=0,0,F24/F23)) -> Filtered
A27: =A25+1 -> 10 | B27: =+"Growth allowance = $530 x ("&FIXED(A25,0)&") =" -> Growth allowance = $530 x (9) = | C27: n/a | D27: n/a | E27: n/a | F27: =IF(F28=0,0,IF(K7=1,"n/a",ROUND(530*F25,2))) -> n/a
A28: =A27+1 -> 11 | B28: Grade 4 enrollment as of October 2011 | C28: n/a | D28: n/a | E28: n/a | F28: =SUMIF('All sites (detail)'!$A$14:$A$973,'Site reports'!$K$5,'All sites (detail)'!U$14:U$973) -> 5
A29: =A28+1 -> 12 | B29: =+"Growth aid = ("&FIXED(A27,0)&") x ("&FIXED(A28,0)&") =" -> Growth aid = (10) x (11) = | C29: n/a | D29: n/a | E29: n/a | F29: =IF(K7=1,"n/a",SUMIF('All sites (detail)'!$A$14:$A$973,'Site reports'!$K$5,'All sites (detail)'!Y$14:Y$973)) -> n/a
A31: =A29+1 -> 13 | B31: =+"Gross literacy incentive aid = ("&FIXED(A19,0)&")+("&FIXED(A29,0)&") =" -> Gross literacy incentive aid = (6)+(12) = | C31: n/a | D31: n/a | E31: n/a | F31: =SUMIF('All sites (detail)'!$A$14:$A$973,'Site reports'!$K$5,'All sites (detail)'!Z$14:Z$973) -> 4975.4
A33: =A31+1 -> 14 | B33: Proration rate (approximate) | C33: n/a | D33: n/a | E33: n/a | F33: 0.95577976
A34: =A33+1 -> 15 | B34: =+"Prorated literacy incentive aid = ("&FIXED(A31,0)&") x ("&FIXED(A33,0)&") =" -> Prorated literacy incentive aid = (13) x (14) = | C34: n/a | D34: n/a | E34: n/a | F34: =ROUND(F31*F33,2) -> 4755.39
A36: Notes:
A38: Literacy incentive aid goes into effect in FY 2013, based on legislation passed in 2011 and amended in 2012.
A39: For FY 2013 only, the state total aid entitlement is capped at $48,585,000.
A41: Aid is based on grade reading 3 proficiency and grade 4 reading growth, based on the prior 3 years'
A42: administrations of the Minnesota Comprehensive Assessment (MCA). The calculation is done separately
A43: for each building.
A45: Test counts are shown as "Filtered" if any of a site's total test counts, as shown in lines 1 and 7, have been
A46: filtered because at least one total is between 1 and 9.
A48: Please direct questions to Bob Porter at either 651-582-8851 or bob.porter@state.mn.us.
A71: 1 | B71: Does Not Meet Standards | C71: =SUMIF(#REF!,'Site reports'!$K$5,#REF!) -> #REF! | D71: =SUMIF(#REF!,'Site reports'!$K$5,#REF!) -> #REF! | E71: =SUMIF(#REF!,'Site reports'!$K$5,#REF!) -> #REF! | F71: =SUM(C71:E71) -> #REF!
A72: =A71+1 -> 2 | B72: Partially Meets Standards | C72: =SUMIF(#REF!,'Site reports'!$K$5,#REF!) -> #REF! | D72: =SUMIF(#REF!,'Site reports'!$K$5,#REF!) -> #REF! | E72: =SUMIF(#REF!,'Site reports'!$K$5,#REF!) -> #REF! | F72: =SUM(C72:E72) -> #REF!
A73: =A72+1 -> 3 | B73: Meets Standards | C73: =SUMIF(#REF!,'Site reports'!$K$5,#REF!) -> #REF! | D73: =SUMIF(#REF!,'Site reports'!$K$5,#REF!) -> #REF! | E73: =SUMIF(#REF!,'Site reports'!$K$5,#REF!) -> #REF! | F73: =SUM(C73:E73) -> #REF!
A74: =A73+1 -> 4 | B74: Exceeds Standards | C74: =SUMIF(#REF!,'Site reports'!$K$5,#REF!) -> #REF! | D74: =SUMIF(#REF!,'Site reports'!$K$5,#REF!) -> #REF! | E74: =SUMIF(#REF!,'Site reports'!$K$5,#REF!) -> #REF! | F74: =SUM(C74:E74) -> #REF!
A77: =A19+1 -> 7 | B77: Low proficiency, high growth | C77: =SUMIF(#REF!,'Site reports'!$K$5,#REF!) -> #REF! | D77: =SUMIF(#REF!,'Site reports'!$K$5,#REF!) -> #REF! | E77: =SUMIF(#REF!,'Site reports'!$K$5,#REF!) -> #REF! | F77: =SUM(C77:E77) -> #REF!
A78: =A77+1 -> 8 | B78: Low proficiency, medium growth | C78: =SUMIF(#REF!,'Site reports'!$K$5,#REF!) -> #REF! | D78: =SUMIF(#REF!,'Site reports'!$K$5,#REF!) -> #REF! | E78: =SUMIF(#REF!,'Site reports'!$K$5,#REF!) -> #REF! | F78: =SUM(C78:E78) -> #REF!
...

Sheet District totals
A1: ESTIMATED DISTRICT AND CHARTER SCHOOL GROSS REVENUE TOTALS | G1: LiteracyIncentiveAid
A2: FOR FY 2013 LITERACY INCENTIVE AID | G2: 41227
A4: For FY 2013 only, the state total aid entitlement is capped at $48,585,000, requiring a
A5: proration factor that is currently estimated to be about 95.6%.
D7: Gross | E7: Gross | F7: Gross | G7: Prorated
D8: Proficiency | E8: Growth | F8: Combined | G8: Combined
C10: TOTAL | D10: =SUM(D12:D436) -> 25776436 | E10: =SUM(E12:E436) -> 25056404 | F10: =SUM(F12:F436) -> 50832840 | G10: =SUM(G12:G436) -> 48585000
A12: 1 | B12: 1 | C12: AITKIN PUBLIC SCHOOL DISTRICT | D12: 44506.34 | E12: 27820.58 | F12: =D12+E12 -> 72326.92 | G12: 69128.61
A13: 1.2 | B13: 3 | C13: MINNEAPOLIS PUBLIC SCHOOL DIST. | D13: 845442.7 | E13: 1060531.8 | F13: =D13+E13 -> 1905974.5 | G13: 1821691.9
A14: 2 | B14: 1 | C14: HILL CITY PUBLIC SCHOOL DISTRICT | D14: 5840.85 | E14: 8000 | F14: =D14+E14 -> 13840.85 | G14: 13228.8
A15: 4 | B15: 1 | C15: MCGREGOR PUBLIC SCHOOL DISTRICT | D15: 12854.16 | E15: 14707.5 | F15: =D15+E15 -> 27561.66 | G15: 26342.88
A16: 6 | B16: 3 | C16: SOUTH ST. PAUL PUBLIC SCHOOL DIST. | D16: 101601.7 | E16: 100482.67 | F16: =D16+E16 -> 202084.37 | G16: 193148.15
A17: 11 | B17: 1 | C17: ANOKA-HENNEPIN PUBLIC SCHOOL DIST. | D17: 1142008.3 | E17: 1141962.8 | F17: =D17+E17 -> 2283971.1 | G17: 2182973.4
A18: 12 | B18: 1 | C18: CENTENNIAL PUBLIC SCHOOL DISTRICT | D18: 217231.62 | E18: 202646 | F18: =D18+E18 -> 419877.62 | G18: 401310.53
A19: 13 | B19: 1 | C19: COLUMBIA HEIGHTS PUBLIC SCHOOL DIST | D19: 84253.2 | E19: 77298.95 | F19: =D19+E19 -> 161552.15 | G19: 154408.28
A20: 14 | B20: 1 | C20: FRIDLEY PUBLIC SCHOOL DISTRICT | D20: 75163.56 | E20: 87093.96 | F20: =D20+E20 -> 162257.52 | G20: 155082.45
A21: 15 | B21: 1 | C21: ST. FRANCIS PUBLIC SCHOOL DISTRICT | D21: 165388.68 | E21: 155083.46 | F21: =D21+E21 -> 320472.14 | G21: 306300.79
A22: 16 | B22: 1 | C22: SPRING LAKE PARK PUBLIC SCHOOLS | D22: 165114.36 | E22: 154826.5 | F22: =D22+E22 -> 319940.86 | G22: 305793
A23: 22 | B23: 1 | C23: DETROIT LAKES PUBLIC SCHOOL DIST. | D23: 97308.27 | E23: 79426.72 | F23: =D23+E23 -> 176734.99 | G23: 168919.73
... A436: 4202 | B436: 7 | C436: MINNESOTA SCHOOL OF SCIENCE | D436: 7844 | E436: 12366.76 | F436: =D436+E436 -> 20210.76 | G436: 19317.04

Sheet Names
A1: Districts and Schools by Listed by Number | G1: Districts and Schools Listed Alphabetically
A3: 1 | B3: 1 | C3: AITKIN PUBLIC SCHOOL DISTRICT | D3: 2 | E3: RIPPLESIDE ELEMENTARY | G3: 2396 | H3: 1 | I3: A.C.G.C. | J3: 100 | K3: A.C.G.C. NORTH ELEMENTARY
A4: 1 | B4: 1 | C4: AITKIN PUBLIC SCHOOL DISTRICT | D4: 3 | E4: PALISADE ELEMENTARY | G4: 2396 | H4: 1 | I4: A.C.G.C. | J4: 200 | K4: A.C.G.C. SOUTH ELEMENTARY
A5: 1.2 | B5: 3 | C5: MINNEAPOLIS PUBLIC SCHOOL DIST. | D5: 103 | E5: ARMATAGE ELEMENTARY | G5: 4073 | H5: 7 | I5: ACADEMIA CESAR CHAVEZ CHARTER SCH. | J5: 10 | K5: ACADEMIA CESAR CHAVEZ CHARTER SCH.
A6: 1.2 | B6: 3 | C6: MINNEAPOLIS PUBLIC SCHOOL DIST. | D6: 105 | E6: BANCROFT ELEMENTARY | G6: 4197 | H6: 7 | I6: ACADEMY OF NORTH MINNEAPOLIS | J6: 10 | K6: ACADEMY OF NORTH MINNEAPOLIS
A7: 1.2 | B7: 3 | C7: MINNEAPOLIS PUBLIC SCHOOL DIST. | D7: 106 | E7: BARTON OPEN ELEMENTARY | G7: 4018 | H7: 7 | I7: ACHIEVE LANGUAGE ACADEMY | J7: 10 | K7: ACHIEVE LANGUAGE ACADEMY
A8: 1.2 | B8: 3 | C8: MINNEAPOLIS PUBLIC SCHOOL DIST. | D8: 107 | E8: BETHUNE ELEMENTARY | G8: 2854 | H8: 1 | I8: ADA-BORUP PUBLIC SCHOOL DISTRICT | J8: 10 | K8: ADA ELEMENTARY
A9: 1.2 | B9: 3 | C9: MINNEAPOLIS PUBLIC SCHOOL DIST. | D9: 110 | E9: BURROUGHS ELEMENTARY | G9: 4135 | H9: 7 | I9: ADAM ABDULLE ACADEMY | J9: 10 | K9: ADAM ABDULLE ACADEMY
A10: 1.2 | B10: 3 | C10: MINNEAPOLIS PUBLIC SCHOOL DIST. | D10: 121 | E10: LAKE HARRIET UPPER SCHOOL | G10: 511 | H10: 1 | I10: ADRIAN PUBLIC SCHOOL DISTRICT | J10: 10 | K10: ADRIAN ELEMENTARY
A11: 1.2 | B11: 3 | C11: MINNEAPOLIS PUBLIC SCHOOL DIST. | D11: 123 | E11: HALE ELEMENTARY | G11: 1 | H11: 1 | I11: AITKIN PUBLIC SCHOOL DISTRICT | J11: 2 | K11: RIPPLESIDE ELEMENTARY
A12: 1.2 | B12: 3 | C12: MINNEAPOLIS PUBLIC SCHOOL DIST. | D12: 124 | E12: PARK VIEW MONTESSORI ELEMENTARY | G12: 1 | H12: 1 | I12: AITKIN PUBLIC SCHOOL DISTRICT | J12: 3 | K12: PALISADE ELEMENTARY
A13: 1.2 | B13: 3 | C13: MINNEAPOLIS PUBLIC SCHOOL DIST. | D13: 130 | E13: HIAWATHA ELEMENTARY | G13: 745 | H13: 1 | I13: ALBANY PUBLIC SCHOOL DISTRICT | J13: 10 | K13: ALBANY ELEMENTARY
A14: 1.2 | B14: 3 | C14: MINNEAPOLIS PUBLIC SCHOOL DIST. | D14: 134 | E14: LK NOKOMIS COMM-KEEWAYDIN CAMPUS | G14: 745 | H14: 1 | I14: ALBANY PUBLIC SCHOOL DISTRICT | J14: 30 | K14: AVON ELEMENTARY
... A947: 4197 | B947: 7 | C947: ACADEMY OF NORTH MINNEAPOLIS | D947: 10 | E947: ACADEMY OF NORTH MINNEAPOLIS | G947: 2805 | H947: 1 | I947: ZUMBROTA-MAZEPPA SCHOOL DISTRICT | J947: 1 | K947: ZUMBROTA-MAZEPPA ELEMENTARY

Sheet All sites (summary)
A1: FY 2013 LITERACY INCENTIVE REVENUE BY SITE | F1: A site's results are filtered if there are fewer than 10 scores in any year for either
F2: proficiency or growth. If any of a site's results are filtered, then everything in | P2: 48585000
F3: columns A, B, C, D, G, and H is filtered. If you are responsible for a filtered site and you
F4: want the detail, contact Bob Porter at bob.porter@state.mn.us or at 651-582-8851.
G6: A | H6: B | I6: C | J6: D | K6: E | L6: F | M6: G | N6: H | O6: I | P6: J
O8: Gross | P8: Prorated
A9: To see the results for a particular district, click on the | G9: 3 Year | H9: 3 Year | I9: Proficiency | J9: Growth | K9: Oct 11 | L9: Oct 11 | M9: Proficiency | N9: Growth | O9: Combined | P9: Revenue
A10: down arrow in cell A14 then indicate the appropriate | G10: Proficiency | H10: Growth | I10: Allowance | J10: Allowance | K10: Enroll | L10: Enroll | M10: Revenue | N10: Revenue | O10: Revenue | P10: =+"= "&+O6&" x" -> = I x
A11: district number. | F11: Filtered? | G11: Portion | H11: Portion | I11: =+"= $535 X "&+G6 -> = $535 X A | J11: =+"= $535 X "&+H6 -> = $535 X B | K11: Grade 3 | L11: Grade 4 | M11: =+"= "&+I6&" X "&+K6 -> = C X E | N11: =+"= "&+J6&" X "&+L6 -> = D X F | O11: =+"= "&+M6&"+"&+N6 -> = G+H | P11: 0.95577976
C13: TOTAL | G13: n/a | H13: n/a | I13: n/a | J13: n/a | K13: =SUBTOTAL(9,K15:K974) -> 61966 | L13: =SUBTOTAL(9,L15:L974) -> 60492 | M13: n/a | N13: n/a | O13: =SUBTOTAL(9,O15:O974) -> 50832840 | P13: =SUBTOTAL(9,P15:P974) -> 48585000
A15: 1 | B15: 1 | C15: AITKIN PUBLIC SCHOOL DISTRICT | D15: 2 | E15: RIPPLESIDE ELEMENTARY | F15: 0 | G15: 0.76494024 | H15: 0.73214286 | I15: 405.42 | J15: 388.04 | K15: 102 | L15: 67 | M15: 41352.84 | N15: 25998.68 | O15: 67351.52 | P15: =ROUND(O15*P$11,2) -> 64373.22
A16: 1 | B16: 1 | C16: AITKIN PUBLIC SCHOOL DISTRICT | D16: 3 | E16: PALISADE ELEMENTARY | F16: 1 | G16: Filtered | H16: Filtered | I16: Filtered | J16: Filtered | K16: 7 | L16: 5 | M16: Filtered | N16: Filtered | O16: 4975.4 | P16: =ROUND(O16*P$11,2) -> 4755.39
A17: 1.2 | B17: 3 | C17: MINNEAPOLIS PUBLIC SCHOOL DIST. | D17: 103 | E17: ARMATAGE ELEMENTARY | F17: 0 | G17: 0.8377193 | H17: 0.85326087 | I17: 443.99 | J17: 452.23 | K17: 80 | L17: 74 | M17: 35519.2 | N17: 33465.02 | O17: 68984.22 | P17: =ROUND(O17*P$11,2) -> 65933.72
A18: 1.2 | B18: 3 | C18: MINNEAPOLIS PUBLIC SCHOOL DIST. | D18: 105 | E18: BANCROFT ELEMENTARY | F18: 0 | G18: 0.35164835 | H18: 0.68072289 | I18: 186.37 | J18: 360.78 | K18: 55 | L18: 74 | M18: 10250.35 | N18: 26697.72 | O18: 36948.07 | P18: =ROUND(O18*P$11,2) -> 35314.22
A19: 1.2 | B19: 3 | C19: MINNEAPOLIS PUBLIC SCHOOL DIST. | D19: 106 | E19: BARTON OPEN ELEMENTARY | F19: 0 | G19: 0.86307054 | H19: 0.83333333 | I19: 457.43 | J19: 441.67 | K19: 81 | L19: 80 | M19: 37051.83 | N19: 35333.6 | O19: 72385.43 | P19: =ROUND(O19*P$11,2) -> 69184.53
A20: 1.2 | B20: 3 | C20: MINNEAPOLIS PUBLIC SCHOOL DIST. | D20: 107 | E20: BETHUNE ELEMENTARY | F20: 0 | G20: 0.33552632 | H20: 0.62 | I20: 177.83 | J20: 328.6 | K20: 43 | L20: 55 | M20: 7646.69 | N20: 18073 | O20: 25719.69 | P20: =ROUND(O20*P$11,2) -> 24582.36
A21: 1.2 | B21: 3 | C21: MINNEAPOLIS PUBLIC SCHOOL DIST. | D21: 110 | E21: BURROUGHS ELEMENTARY | F21: 0 | G21: 0.86716792 | H21: 0.89014085 | I21: 459.6 | J21: 471.77 | K21: 146 | L21: 125 | M21: 67101.6 | N21: 58971.25 | O21: 126072.85 | P21: =ROUND(O21*P$11,2) -> 120497.88
A22: 1.2 | B22: 3 | C22: MINNEAPOLIS PUBLIC SCHOOL DIST. | D22: 121 | E22: LAKE HARRIET UPPER SCHOOL | F22: 0 | G22: 0.94117647 | H22: 0.8375 | I22: 498.82 | J22: 443.88 | K22: 128 | L22: 111 | M22: 63848.96 | N22: 49270.68 | O22: 113119.64 | P22: =ROUND(O22*P$11,2) -> 108117.46
A23: 1.2 | B23: 3 | C23: MINNEAPOLIS PUBLIC SCHOOL DIST. | D23: 123 | E23: HALE ELEMENTARY | F23: 0 | G23: 0.88390501 | H23: 0.80434783 | I23: 468.47 | J23: 426.3 | K23: 135 | L23: 123 | M23: 63243.45 | N23: 52434.9 | O23: 115678.35 | P23: =ROUND(O23*P$11,2) -> 110563.03
A24: 1.2 | B24: 3 | C24: MINNEAPOLIS PUBLIC SCHOOL DIST. | D24: 124 | E24: PARK VIEW MONTESSORI ELEMENTARY | F24: 1 | G24: Filtered | H24: Filtered | I24: Filtered | J24: Filtered | K24: 0 | L24: 0 | M24: Filtered | N24: Filtered | O24: 0 | P24: =ROUND(O24*P$11,2) -> 0
A25: 1.2 | B25: 3 | C25: MINNEAPOLIS PUBLIC SCHOOL DIST. | D25: 130 | E25: HIAWATHA ELEMENTARY | F25: 0 | G25: 0.55797101 | H25: 0.84745763 | I25: 295.72 | J25: 449.15 | K25: 43 | L25: 51 | M25: 12715.96 | N25: 22906.65 | O25: 35622.61 | P25: =ROUND(O25*P$11,2) -> 34047.37
A26: 1.2 | B26: 3 | C26: MINNEAPOLIS PUBLIC SCHOOL DIST. | D26: 134 | E26: LK NOKOMIS COMM-KEEWAYDIN CAMPUS | F26: 1 | G26: Filtered | H26: Filtered | I26: Filtered | J26: Filtered | K26: 0 | L26: 64 | M26: Filtered | N26: Filtered | O26: 23560.96 | P26: =ROUND(O26*P$11,2) -> 22519.09
A27: 1.2 | B27: 3 | C27: MINNEAPOLIS PUBLIC SCHOOL DIST. | D27: 135 | E27: KENNY ELEMENTARY | F27: 0 | G27: 0.76510067 | H27: 0.72 | I27: 405.5 | J27: 381.6 | K27: 54 | L27: 54 | M27: 21897 | N27: 20606.4 | O27: 42503.4 | P27: =ROUND(O27*P$11,2) -> 40623.89
A28: 1.2 | B28: 3 | C28: MINNEAPOLIS PUBLIC SCHOOL DIST. | D28: 136 | E28: KENWOOD ELEMENTARY | F28: 0 | G28: 0.859375 | H28: 0.82352941 | I28: 455.47 | J28: 436.47 | K28: 79 | L28: 71 | M28: 35982.13 | N28: 30989.37 | O28: 66971.5 | P28: =ROUND(O28*P$11,2) -> 64010
A29: 1.2 | B29: 3 | C29: MINNEAPOLIS PUBLIC SCHOOL DIST. | D29: 139 | E29: LONGFELLOW ELEMENTARY | F29: 1 | G29: Filtered | H29: Filtered | I29: Filtered | J29: Filtered | K29: 0 | L29: 0 | M29: Filtered | N29: Filtered | O29: 0 | P29: =ROUND(O29*P$11,2) -> 0
A30: 1.2 | B30: 3 | C30: MINNEAPOLIS PUBLIC SCHOOL DIST. | D30: 140 | E30: LORING ELEMENTARY | F30: 0 | G30: 0.65128205 | H30: 0.73652695 | I30: 345.18 | J30: 390.36 | K30: 57 | L30: 64 | M30: 19675.26 | N30: 24983.04 | O30: 44658.3 | P30: =ROUND(O30*P$11,2) -> 42683.5
A31: 1.2 | B31: 3 | C31: MINNEAPOLIS PUBLIC SCHOOL DIST. | D31: 144 | E31: LYNDALE ELEMENTARY | F31: 0 | G31: 0.53038674 | H31: 0.78472222 | I31: 281.1 | J31: 415.9 | K31: 65 | L31: 68 | M31: 18271.5 | N31: 28281.2 | O31: 46552.7 | P31: =ROUND(O31*P$11,2) -> 44494.13
A32: 1.2 | B32: 3 | C32: MINNEAPOLIS PUBLIC SCHOOL DIST. | D32: 151 | E32: JENNY LIND ELEMENTARY | F32: 0 | G32: 0.46460177 | H32: 0.75845411 | I32: 246.24 | J32: 401.98 | K32: 78 | L32: 79 | M32: 19206.72 | N32: 31756.42 | O32: 50963.14 | P32: =ROUND(O32*P$11,2) -> 48709.54
A33: 1.2 | B33: 3 | C33: MINNEAPOLIS PUBLIC SCHOOL DIST. | D33: 152 | E33: NORTHROP ELEMENTARY | F33: 0 | G33: 0.51871658 | H33: 0.8255814 | I33: 274.92 | J33: 437.56 | K33: 54 | L33: 57 | M33: 14845.68 | N33: 24940.92 | O33: 39786.6 | P33: =ROUND(O33*P$11,2) -> 38027.23
A34: 1.2 | B34: 3 | C34: MINNEAPOLIS PUBLIC SCHOOL DIST. | D34: 155 | E34: PILLSBURY ELEMENTARY | F34: 0 | G34: 0.51526718 | H34: 0.76525822 | I34: 273.09 | J34: 405.59 | K34: 94 | L34: 87 | M34: 25670.46 | N34: 35286.33 | O34: 60956.79 | P34: =ROUND(O34*P$11,2) -> 58261.27
A35: 1.2 | B35: 3 | C35: MINNEAPOLIS PUBLIC SCHOOL DIST. | D35: 156 | E35: PRATT ELEMENTARY | F35: 0 | G35: 0.49253731 | H35: 0.85185185 | I35: 261.04 | J35: 451.48 | K35: 23 | L35: 22 | M35: 6003.92 | N35: 9932.56 | O35: 15936.48 | P35: =ROUND(O35*P$11,2) -> 15231.77
A36: 1.2 | B36: 3 | C36: MINNEAPOLIS PUBLIC SCHOOL DIST. | D36: 160 | E36: SEWARD ELEMENTARY | F36: 0 | G36: 0.75272727 | H36: 0.76515152 | I36: 398.95 | J36: 405.53 | K36: 92 | L36: 96 | M36: 36703.4 | N36: 38930.88 | O36: 75634.28 | P36: =ROUND(O36*P$11,2) -> 72289.71
A37: 1.2 | B37: 3 | C37: MINNEAPOLIS PUBLIC SCHOOL DIST. | D37: 161 | E37: SHERIDAN ELEMENTARY | F37: 0 | G37: 0.3081761 | H37: 0.68461538 | I37: 163.33 | J37: 362.85 | K37: 55 | L37: 62 | M37: 8983.15 | N37: 22496.7 | O37: 31479.85 | P37: =ROUND(O37*P$11,2) -> 30087.8
A38: 1.2 | B38: 3 | C38: MINNEAPOLIS PUBLIC SCHOOL DIST. | D38: 165 | E38: WAITE PARK ELEMENTARY | F38: 0 | G38: 0.64516129 | H38: 0.7804878 | I38: 341.94 | J38: 413.66 | K38: 69 | L38: 75 | M38: 23593.86 | N38: 31024.5 | O38: 54618.36 | P38: =ROUND(O38*P$11,2) -> 52203.12
A39: 1.2 | B39: 3 | C39: MINNEAPOLIS PUBLIC SCHOOL DIST. | D39: 167 | E39: WENONAH EL. | F39: 1 | G39: Filtered | H39: Filtered | I39: Filtered | J39: Filtered | K39: 68 | L39: 0 | M39: Filtered | N39: Filtered | O39: 26395.56 | P39: =ROUND(O39*P$11,2) -> 25228.34
A40: 1.2 | B40: 3 | C40: MINNEAPOLIS PUBLIC SCHOOL DIST. | D40: 170 | E40: WINDOM OPEN ELEMENTARY | F40: 0 | G40: 0.54054054 | H40: 0.90983607 | I40: 286.49 | J40: 482.21 | K40: 60 | L40: 46 | M40: 17189.4 | N40: 22181.66 | O40: 39371.06 | P40: =ROUND(O40*P$11,2) -> 37630.06
A41: 1.2 | B41: 3 | C41: MINNEAPOLIS PUBLIC SCHOOL DIST. | D41: 175 | E41: RAMSEY FINE ARTS ELEMENTARY | F41: 0 | G41: 0.48648649 | H41: 0.67399267 | I41: 257.84 | J41: 357.22 | K41: 111 | L41: 106 | M41: 28620.24 | N41: 37865.32 | O41: 66485.56 | P41: =ROUND(O41*P$11,2) -> 63545.55
A42: 1.2 | B42: 3 | C42: MINNEAPOLIS PUBLIC SCHOOL DIST. | D42: 179 | E42: JEFFERSON ELEMENTARY | F42: 0 | G42: 0.35795455 | H42: 0.77118644 | I42: 189.72 | J42: 408.73 | K42: 73 | L42: 61 | M42: 13849.56 | N42: 24932.53 | O42: 38782.09 | P42: =ROUND(O42*P$11,2) -> 37067.14
A43: 1.2 | B43: 3 | C43: MINNEAPOLIS PUBLIC SCHOOL DIST. | D43: 180 | E43: DOWLING ELEMENTARY | F43: 0 | G43: 0.87068966 | H43: 0.70909091 | I43: 461.47 | J43: 375.82 | K43: 86 | L43: 83 | M43: 39686.42 | N43: 31193.06 | O43: 70879.48 | P43: =ROUND(O43*P$11,2) -> 67745.17
A44: 1.2 | B44: 3 | C44: MINNEAPOLIS PUBLIC SCHOOL DIST. | D44: 190 | E44: ANDERSEN OPEN ELEMENTARY | F44: 0 | G44: 0.29198966 | H44: 0.73650794 | I44: 154.75 | J44: 390.35 | K44: 120 | L44: 131 | M44: 18570 | N44: 51135.85 | O44: 69705.85 | P44: =ROUND(O44*P$11,2) -> 66623.44
...

Sheet All sites (detail)
A1: Inputs for Site Reports | G1: Results are filtered if there are fewer that 10 results in columns A, C, E, G, I, or K.
G2: If anything is filtered here, then everything is filtered.
G3: If you are responsible for a filtered site and you want the detail, contact Bob Porter at bob.porter@state.mn.us or at 651-582-8851.
H5: A | I5: B | J5: C | K5: D | L5: E | M5: F | N5: G | O5: H | P5: I | Q5: J | R5: K | S5: L | T5: M | U5: N | V5: O | W5: P | X5: Q | Y5: R | Z5: S | AA5: T
AA7: Prorated
H8: FY 2010 | I8: FY 2010 | J8: FY 2011 | K8: FY 2011 | L8: FY 2012 | M8: FY 2012 | N8: FY 2010 | O8: FY 2010 | P8: FY 2011 | Q8: FY 2011 | R8: FY 2012 | S8: FY 2012 | T8: Oct 11 | U8: Oct 11 | X8: Total | Y8: Total | Z8: Gross | AA8: Revenue
H9: MCA | I9: MCA | J9: MCA | K9: MCA | L9: MCA | M9: MCA | N9: Growth | O9: Growth | P9: Growth | Q9: Growth | R9: Growth | S9: Growth | T9: Enroll | U9: Enroll | V9: Proficiency | W9: Growth | X9: Proficiency | Y9: Growth | Z9: Combined | AA9: =+"= "&+Z5&" x" -> = S x
G10: Filtered? | H10: Total | I10: Proficient | J10: Total | K10: Proficient | L10: Total | M10: Proficient | N10: Total | O10: High/Med | P10: Total | Q10: High/Med | R10: Total | S10: High/Med | T10: Grade 3 | U10: Grade 4 | V10: Portion | W10: Portion | X10: Revenue | Y10: Revenue | Z10: Revenue | AA10: 0.95577976
B12: TOTAL | G12: =SUM(G14:G973) -> 101 | H12: n/a | I12: n/a | J12: n/a | K12: n/a | L12: n/a | M12: n/a | N12: n/a | O12: n/a | P12: n/a | Q12: n/a | R12: n/a | S12: n/a | T12: =SUM(T14:T973) -> 61966 | U12: =SUM(U14:U973) -> 60492 | V12: n/a | W12: n/a | X12: =SUM(X14:X973) -> 25556308 | Y12: =SUM(Y14:Y973) -> 24819917 | Z12: =SUM(Z14:Z973) -> 50832840 | AA12: =SUM(AA14:AA973) -> 48585000
A14: 10002 | B14: 1 | C14: 1 | D14: AITKIN PUBLIC SCHOOL DISTRICT | E14: 2 | F14: RIPPLESIDE ELEMENTARY | G14: 0 | H14: 84 | I14: 61 | J14: 69 | K14: 54 | L14: 98 | M14: 77 | N14: 79 | O14: 58 | P14: 82 | Q14: 60 | R14: 63 | S14: 46 | T14: 102 | U14: 67 | V14: 0.76494024 | W14: 0.73214286 | X14: 41352.84 | Y14: 25998.68 | Z14: 67351.52 | AA14: =ROUND(Z14*AA$10,2) -> 64373.22
A15: 10003 | B15: 1 | C15: 1 | D15: AITKIN PUBLIC SCHOOL DISTRICT | E15: 3 | F15: PALISADE ELEMENTARY | G15: 1 | H15: Filtered | I15: Filtered | J15: Filtered | K15: Filtered | L15: Filtered | M15: Filtered | N15: Filtered | O15: Filtered | P15: Filtered | Q15: Filtered | R15: Filtered | S15: Filtered | T15: 7 | U15: 5 | V15: Filtered | W15: Filtered | X15: Filtered | Y15: Filtered | Z15: 4975.4 | AA15: =ROUND(Z15*AA$10,2) -> 4755.39
A16: 12103 | B16: 1.2 | C16: 3 | D16: MINNEAPOLIS PUBLIC SCHOOL DIST. | E16: 103 | F16: ARMATAGE ELEMENTARY | G16: 0 | H16: 74 | I16: 62 | J16: 75 | K16: 61 | L16: 79 | M16: 68 | N16: 68 | O16: 54 | P16: 51 | Q16: 44 | R16: 65 | S16: 59 | T16: 80 | U16: 74 | V16: 0.8377193 | W16: 0.85326087 | X16: 35519.2 | Y16: 33465.02 | Z16: 68984.22 | AA16: =ROUND(Z16*AA$10,2) -> 65933.72
A17: 12105 | B17: 1.2 | C17: 3 | D17: MINNEAPOLIS PUBLIC SCHOOL DIST. | E17: 105 | F17: BANCROFT ELEMENTARY | G17: 0 | H17: 62 | I17: 17 | J17: 63 | K17: 23 | L17: 57 | M17: 24 | N17: 48 | O17: 34 | P17: 66 | Q17: 45 | R17: 52 | S17: 34 | T17: 55 | U17: 74 | V17: 0.35164835 | W17: 0.68072289 | X17: 10250.35 | Y17: 26697.72 | Z17: 36948.07 | AA17: =ROUND(Z17*AA$10,2) -> 35314.22
A18: 12106 | B18: 1.2 | C18: 3 | D18: MINNEAPOLIS PUBLIC SCHOOL DIST. | E18: 106 | F18: BARTON OPEN ELEMENTARY | G18: 0 | H18: 88 | I18: 73 | J18: 73 | K18: 62 | L18: 80 | M18: 73 | N18: 82 | O18: 67 | P18: 82 | Q18: 67 | R18: 70 | S18: 61 | T18: 81 | U18: 80 | V18: 0.86307054 | W18: 0.83333333 | X18: 37051.83 | Y18: 35333.6 | Z18: 72385.43 | AA18: =ROUND(Z18*AA$10,2) -> 69184.53
A19: 12107 | B19: 1.2 | C19: 3 | D19: MINNEAPOLIS PUBLIC SCHOOL DIST. | E19: 107 | F19: BETHUNE ELEMENTARY | G19: 0 | H19: 57 | I19: 18 | J19: 53 | K19: 20 | L19: 42 | M19: 13 | N19: 27 | O19: 17 | P19: 28 | Q19: 20 | R19: 45 | S19: 25 | T19: 43 | U19: 55 | V19: 0.33552632 | W19: 0.62 | X19: 7646.69 | Y19: 18073 | Z19: 25719.69 | AA19: =ROUND(Z19*AA$10,2) -> 24582.36
A20: 12110 | B20: 1.2 | C20: 3 | D20: MINNEAPOLIS PUBLIC SCHOOL DIST. | E20: 110 | F20: BURROUGHS ELEMENTARY | G20: 0 | H20: 128 | I20: 106 | J20: 127 | K20: 108 | L20: 144 | M20: 132 | N20: 121 | O20: 106 | P20: 116 | Q20: 104 | R20: 118 | S20: 106 | T20: 146 | U20: 125 | V20: 0.86716792 | W20: 0.89014085 | X20: 67101.6 | Y20: 58971.25 | Z20: 126072.85 | AA20: =ROUND(Z20*AA$10,2) -> 120497.88
A21: 12121 | B21: 1.2 | C21: 3 | D21: MINNEAPOLIS PUBLIC SCHOOL DIST. | E21: 121 | F21: LAKE HARRIET UPPER SCHOOL | G21: 0 | H21: 103 | I21: 98 | J21: 115 | K21: 105 | L21: 122 | M21: 117 | N21: 115 | O21: 94 | P21: 98 | Q21: 83 | R21: 107 | S21: 91 | T21: 128 | U21: 111 | V21: 0.94117647 | W21: 0.8375 | X21: 63848.96 | Y21: 49270.68 | Z21: 113119.64 | AA21: =ROUND(Z21*AA$10,2) -> 108117.46
A22: 12123 | B22: 1.2 | C22: 3 | D22: MINNEAPOLIS PUBLIC SCHOOL DIST. | E22: 123 | F22: HALE ELEMENTARY | G22: 0 | H22: 124 | I22: 105 | J22: 119 | K22: 106 | L22: 136 | M22: 124 | N22: 130 | O22: 95 | P22: 123 | Q22: 108 | R22: 115 | S22: 93 | T22: 135 | U22: 123 | V22: 0.88390501 | W22: 0.80434783 | X22: 63243.45 | Y22: 52434.9 | Z22: 115678.35 | AA22: =ROUND(Z22*AA$10,2) -> 110563.03
A23: 12124 | B23: 1.2 | C23: 3 | D23: MINNEAPOLIS PUBLIC SCHOOL DIST. | E23: 124 | F23: PARK VIEW MONTESSORI ELEMENTARY | G23: 0 | H23: 0 | I23: 0 | J23: 0 | K23: 0 | L23: 0 | M23: 0 | N23: 22 | O23: 12 | P23: 0 | Q23: 0 | R23: 0 | S23: 0 | T23: 0 | U23: 0 | V23: 0 | W23: 0.54545455 | X23: 0 | Y23: 0 | Z23: 0 | AA23: =ROUND(Z23*AA$10,2) -> 0
A24: 12130 | B24: 1.2 | C24: 3 | D24: MINNEAPOLIS PUBLIC SCHOOL DIST. | E24: 130 | F24: HIAWATHA ELEMENTARY | G24: 0 | H24: 48 | I24: 16 | J24: 50 | K24: 32 | L24: 40 | M24: 29 | N24: 32 | O24: 28 | P24: 41 | Q24: 37 | R24: 45 | S24: 35 | T24: 43 | U24: 51 | V24: 0.55797101 | W24: 0.84745763 | X24: 12715.96 | Y24: 22906.65 | Z24: 35622.61 | AA24: =ROUND(Z24*AA$10,2) -> 34047.37
A25: 12134 | B25: 1.2 | C25: 3 | D25: MINNEAPOLIS PUBLIC SCHOOL DIST. | E25: 134 | F25: LK NOKOMIS COMM-KEEWAYDIN CAMPUS | G25: 0 | H25: 0 | I25: 0 | J25: 0 | K25: 0 | L25: 0 | M25: 0 | N25: 57 | O25: 36 | P25: 52 | Q25: 41 | R25: 58 | S25: 39 | T25: 0 | U25: 64 | V25: 0 | W25: 0.69461078 | X25: 0 | Y25: 23560.96 | Z25: 23560.96 | AA25: =ROUND(Z25*AA$10,2) -> 22519.09
A26: 12135 | B26: 1.2 | C26: 3 | D26: MINNEAPOLIS PUBLIC SCHOOL DIST. | E26: 135 | F26: KENNY ELEMENTARY | G26: 0 | H26: 45 | I26: 33 | J26: 56 | K26: 39 | L26: 48 | M26: 42 | N26: 38 | O26: 20 | P26: 61 | Q26: 49 | R26: 51 | S26: 39 | T26: 54 | U26: 54 | V26: 0.76510067 | W26: 0.72 | X26: 21897 | Y26: 20606.4 | Z26: 42503.4 | AA26: =ROUND(Z26*AA$10,2) -> 40623.89
A27: 12136 | B27: 1.2 | C27: 3 | D27: MINNEAPOLIS PUBLIC SCHOOL DIST. | E27: 136 | F27: KENWOOD ELEMENTARY | G27: 0 | H27: 46 | I27: 37 | J27: 71 | K27: 62 | L27: 75 | M27: 66 | N27: 35 | O27: 29 | P27: 57 | Q27: 47 | R27: 61 | S27: 50 | T27: 79 | U27: 71 | V27: 0.859375 | W27: 0.82352941 | X27: 35982.13 | Y27: 30989.37 | Z27: 66971.5 | AA27: =ROUND(Z27*AA$10,2) -> 64010
... A51: 12282 | B51: 1.2 | C51: 3 | D51: MINNEAPOLIS PUBLIC SCHOOL DIST. | E51: 282 | F51: LUCY LANEY @ CLEVELAND PARK ELEM. | G51: 0 | H51: 58 | I51: 19 | J51: 50 | K51: 18 | L51: 61 | M51: 22 | N51: 38 | O51: 23 | P51: 52 | Q51: 31 | R51: 49 | S51: 38 | T51: 65 | U51: 66 | V51: 0.34911243 | W51: 0.6618705 | X51: 12026.95 | Y51: 23152.14 | Z51: 35179.09 | AA51: =ROUND(Z51*AA$10,2) -> 33623.46
A52: 12283 | B52: 1.2 | C52: 3 | D52: MINNEAPOLIS PUBLIC SCHOOL DIST. | E52: 283 | F52: CROSSTOWN EDUCATIONAL CENTER | G52: 1 | H52: Filtered | I52: Filtered | J52: Filtered | K52: Filtered | L52: Filtered | M52: Filtered | N52: Filtered | O52: Filtered | P52: Filtered | Q52: Filtered | R52: Filtered | S52: Filtered | T52: 0 | U52: 0 | V52: Filtered | W52: Filtered | X52: Filtered | Y52: Filtered | Z52: 0 | AA52: =ROUND(Z52*AA$10,2) -> 0
A53: 12287 | B53: 1.2 | C53: 3 | D53: MINNEAPOLIS PUBLIC SCHOOL DIST. | E53: 287 | F53: HALL ELEMENTARY | G53: 0 | H53: 48 | I53: 15 | J53: 63 | K53: 27 | L53: 61 | M53: 30 | N53: 44 | O53: 20 | P53: 40 | Q53: 35 | R53: 52 | S53: 41 | T53: 62 | U53: 57 | V53: 0.41860465 | W53: 0.70588235 | X53: 13755.32 | Y53: 21324.84 | Z53: 35080.16 | AA53: =ROUND(Z53*AA$10,2) -> 33528.91
A54: 12288 | B54: 1.2 | C54: 3 | D54: MINNEAPOLIS PUBLIC SCHOOL DIST. | E54: 288 | F54: NELLIE STONE JOHNSON ELEMENTARY | G54: 0 | H54: 85 | I54: 21 | J54: 70 | K54: 35 | L54: 81 | M54: 39 | N54: 53 | O54: 38 | P54: 64 | Q54: 49 | R54: 67 | S54: 42 | T54: 84 | U54: 86 | V54: 0.40254237 | W54: 0.70108696 | X54: 17921.4 | Y54: 31955.88 | Z54: 49877.28 | AA54: =ROUND(Z54*AA$10,2) -> 47671.69
A55: 12289 | B55: 1.2 | C55: 3 | D55: MINNEAPOLIS PUBLIC SCHOOL DIST. | E55: 289 | F55: WHITTIER PARK ELEMENTARY | G55: 0 | H55: 93 | I55: 56 | J55: 91 | K55: 55 | L55: 100 | M55: 58 | N55: 50 | O55: 39 | P55: 84 | Q55: 68 | R55: 85 | S55: 60 | T55: 102 | U55: 97 | V55: 0.59507042 | W55: 0.76255708 | X55: 32169.78 | Y55: 39203.52 | Z55: 71373.3 | AA55: =ROUND(Z55*AA$10,2) -> 68217.16
A56: 12290 | B56: 1.2 | C56: 3 | D56: MINNEAPOLIS PUBLIC SCHOOL DIST. | E56: 290 | F56: CITYVIEW PAM MAGNET | G56: 1 | H56: Filtered | I56: Filtered | J56: Filtered | K56: Filtered | L56: Filtered | M56: Filtered | N56: Filtered | O56: Filtered | P56: Filtered | Q56: Filtered | R56: Filtered | S56: Filtered | T56: 8 | U56: 7 | V56: Filtered | W56: Filtered | X56: Filtered | Y56: Filtered | Z56: 4000.59 | AA56: =ROUND(Z56*AA$10,2) -> 3823.68
A57: 12291 | B57: 1.2 | C57: 3 | D57: MINNEAPOLIS PUBLIC SCHOOL DIST. | E57: 291 | F57: HMONG INTERNATIONAL ACADEMY | G57: 0 | H57: 37 | I57: 5 | J57: 33 | K57: 12 | L57: 46 | M57: 9 | N57: 23 | O57: 15 | P57: 31 | Q57: 21 | R57: 23 | S57: 17 | T57: 47 | U57: 34 | V57: 0.22413793 | W57: 0.68831169 | X57: 5583.13 | Y57: 12403.54 | Z57: 17986.67 | AA57: =ROUND(Z57*AA$10,2) -> 17191.3
A58: 12311 | B58: 1.2 | C58: 3 | D58: MINNEAPOLIS PUBLIC SCHOOL DIST. | E58: 311 | F58: SPAN | G58: 1 | H58: Filtered | I58: Filtered | J58: Filtered | K58: Filtered | L58: Filtered | M58: Filtered | N58: Filtered | O58: Filtered | P58: Filtered | Q58: Filtered | R58: Filtered | S58: Filtered | T58: 6 | U58: 7 | V58: Filtered | W58: Filtered | X58: Filtered | Y58: Filtered | Z58: 2755.98 | AA58: =ROUND(Z58*AA$10,2) -> 2634.11
A59: 12401 | B59: 1.2 | C59: 3 | D59: MINNEAPOLIS PUBLIC SCHOOL DIST. | E59: 401 | F59: MPS D/HH | G59: 1 | H59: Filtered | I59: Filtered | J59: Filtered | K59: Filtered | L59: Filtered | M59: Filtered | N59: Filtered | O59: Filtered | P59: Filtered | Q59: Filtered | R59: Filtered | S59: Filtered | T59: 0 | U59: 1 | V59: Filtered | W59: Filtered | X59: Filtered | Y59: Filtered | Z59: 0 | AA59: =ROUND(Z59*AA$10,2) -> 0
A60: 12405 | B60: 1.2 | C60: 3 | D60: MINNEAPOLIS PUBLIC SCHOOL DIST. | E60: 405 | F60: URBAN LEAGUE ACADEMY ELEMENTARY | G60: 1 | H60: Filtered | I60: Filtered | J60: Filtered | K60: Filtered | L60: Filtered | M60: Filtered | N60: Filtered | O60: Filtered | P60: Filtered | Q60: Filtered | R60: Filtered | S60: Filtered | T60: 11 | U60: 8 | V60: Filtered | W60: Filtered | X60: Filtered | Y60: Filtered | Z60: 5690.65 | AA60: =ROUND(Z60*AA$10,2) -> 5439.01
A61: 12418 | B61: 1.2 | C61: 3 | D61: MINNEAPOLIS PUBLIC SCHOOL DIST. | E61: 418 | F61: TATANKA ACADEMY | G61: 1 | H61: Filtered | I61: Filtered | J61: Filtered | K61: Filtered | L61: Filtered | M61: Filtered | N61: Filtered | O61: Filtered | P61: Filtered | Q61: Filtered | R61: Filtered | S61: Filtered | T61: 5 | U61: 0 | V61: Filtered | W61: Filtered | X61: Filtered | Y61: Filtered | Z61: 331.25 | AA61: =ROUND(Z61*AA$10,2) -> 316.6
A62: 12625 | B62: 1.2 | C62: 3 | D62: MINNEAPOLIS PUBLIC SCHOOL DIST. | E62: 625 | F62: RIVER BEND EDUCATIONAL CENTER | G62: 1 | H62: Filtered | I62: Filtered | J62: Filtered | K62: Filtered | L62: Filtered | M62: Filtered | N62: Filtered | O62: Filtered | P62: Filtered | Q62: Filtered | R62: Filtered | S62: Filtered | T62: 9 | U62: 10 | V62: Filtered | W62: Filtered | X62: Filtered | Y62: Filtered | Z62: 4655.69 | AA62: =ROUND(Z62*AA$10,2) -> 4449.81
A63: 12689 | B63: 1.2 | C63: 3 | D63: MINNEAPOLIS PUBLIC SCHOOL DIST. | E63: 689 | F63: MPS METRO SJ | G63: 1 | H63: Filtered | I63: Filtered | J63: Filtered | K63: Filtered | L63: Filtered | M63: Filtered | N63: Filtered | O63: Filtered | P63: Filtered | Q63: Filtered | R63: Filtered | S63: Filtered | T63: 5 | U63: 9 | V63: Filtered | W63: Filtered | X63: Filtered | Y63: Filtered | Z63: 3107.75 | AA63: =ROUND(Z63*AA$10,2) -> 2970.32
A64: 20001 | B64: 2 | C64: 1 | D64: HILL CITY PUBLIC SCHOOL DISTRICT | E64: 1 | F64: HILL CITY ELEMENTARY | G64: 0 | H64: 15 | I64: 13 | J64: 19 | K64: 11 | L64: 15 | M64: 12 | N64: 18 | O64: 14 | P64: 16 | Q64: 13 | R64: 19 | S64: 13 | T64: 15 | U64: 20 | V64: 0.73469388 | W64: 0.75471698 | X64: 5840.85 | Y64: 8000 | Z64: 13840.85 | AA64: =ROUND(Z64*AA$10,2) -> 13228.8
A65: 40010 | B65: 4 | C65: 1 | D65: MCGREGOR PUBLIC SCHOOL DISTRICT | E65: 10 | F65: MCGREGOR ELEMENTARY | G65: 0 | H65: 19 | I65: 14 | J65: 31 | K65: 24 | L65: 33 | M65: 23 | N65: 22 | O65: 16 | P65: 17 | Q65: 14 | R65: 33 | S65: 24 | T65: 33 | U65: 37 | V65: 0.73493976 | W65: 0.75 | X65: 12854.16 | Y65: 14707.5 | Z65: 27561.66 | AA65: =ROUND(Z65*AA$10,2) -> 26342.88
A66: 60735 | B66: 6 | C66: 3 | D66: SOUTH ST. PAUL PUBLIC SCHOOL DIST. | E66: 735 | F66: LINCOLN CENTER ELEMENTARY | G66: 0 | H66: 125 | I66: 82 | J66: 127 | K66: 90 | L66: 148 | M66: 113 | N66: 123 | O66: 98 | P66: 114 | Q66: 91 | R66: 130 | S66: 105 | T66: 149 | U66: 137 | V66: 0.7125 | W66: 0.80108992 | X66: 56266.87 | Y66: 58167.46 | Z66: 114434.33 | AA66: =ROUND(Z66*AA$10,2) -> 109374.02
A67: 60737 | B67: 6 | C67: 3 | D67: SOUTH ST. PAUL PUBLIC SCHOOL DIST. | E67: 737 | F67: KAPOSIA EDUCATION CENTER ELEMENTARY | G67: 0 | H67: 123 | I67: 98 | J67: 118 | K67: 94 | L67: 103 | M67: 83 | N67: 91 | O67: 58 | P67: 111 | Q67: 72 | R67: 111 | S67: 80 | T67: 107 | U67: 119 | V67: 0.7994186 | W67: 0.67092652 | X67: 45334.83 | Y67: 42315.21 | Z67: 87650.04 | AA67: =ROUND(Z67*AA$10,2) -> 83774.13
...

Sheet Statute
A1: 124D.98 Literacy incentive aid, as amended in 2012:
A3: Subdivision 1. Literacy incentive aid.
A5: In fiscal year 2013 and later, a district's literacy incentive aid equals
A6: the sum of the proficiency aid under subdivision 2, and the growth
A7: aid under subdivision 3.
A9: Subd. 2. Proficiency aid.
A11: In fiscal year 2013 and later, the proficiency aid for each school is equal
A12: to the product of the school's proficiency allowance times the number of
A13: third grade pupils at the school on October 1 of the previous fiscal year.
A14: A school's proficiency allowance is equal to the percentage of students
A15: in each building that meet or exceed proficiency on the third grade
A16: reading Minnesota Comprehensive Assessment, averaged across the
... A27: averaged across the previous three test administrations, times $530.
