Workbook

Sheet Worksheet Instructions
B2: Charter School Funding -- Inequity Persists
B3: May 2010
B5: Supporting Excel Spreadsheet
B6: Worksheet Legend and Instructions
B7: Arizona
B9: Data Source:
B10: The source for revenue and enrollment data was the Arizona Department of Education’s (ADE) web site. District and charter data were obtained from the FY 2006-07 Annual Report of the Arizona Superintendent of Public Instruction, Volume I and Volume II. At web site:
B11: http://www/ade.state.az.us/schoolfinance/Reports/Default.asp
B13: Disclaimer:
B14: This is a "read only" file containing data collections from the Arizona Department of Education. The conclusions reached in this document are those of the author(s) and do not necessarily represent those of Ball State University.
B16: File Management:
B17: This is a "Final (Read-Only)" Excel file. This means you will not be able to edit this file, but you can copy whole worksheets, paste them into a new file (workbook), and then save that file under a different name. No "Protection" has been set for this file.
... B20: This spreadsheet was designed for use by the author/researcher, not for third-party use. Some of the data in this spreadsheet may be useful to third-parties, but any interpretations or additional analysis by third-parties is done so at their own risk.

Sheet TEMPLATE-Figure 1 Amounts
A1: Figure 1 | G1: Figure 2
A2: Arizona 2006-07 | B2: Statewide | D2: Maricopa County
A3: Per-Pupil Revenue
A4: District | B4: ='#s for Report-State'!I32 -> 9576.9467 | D4: ='#s for Report-Maricopa County'!I12 -> 9559.6363
A5: Charter | B5: ='#s for Report-State'!I39 -> 7596.7418 | D5: ='#s for Report-Maricopa County'!I18 -> 7376.2156
A6: Difference | B6: =B4-B5 -> 1980.2049 | D6: =D4-D5 -> 2183.4207
B7: =B6/B4 -> 0.20676787 | D7: =D6/D4 -> 0.22839998
A8: Per-Pupil Revenue by Source | B8: District | C8: Charter | D8: District | E8: Charter
A9: Federal | B9: ='#s for Report-State'!M32 -> 1022.1014 | C9: ='#s for Report-State'!M39 -> 657.67405 | D9: ='#s for Report-Maricopa County'!M12 -> 770.7282 | E9: ='#s for Report-Maricopa County'!M18 -> 393.02965
A10: State | B10: ='#s for Report-State'!L32 -> 4668.6343 | C10: ='#s for Report-State'!L39 -> 6402.4844 | D10: ='#s for Report-Maricopa County'!L12 -> 4452.2663 | E10: ='#s for Report-Maricopa County'!L18 -> 6409.1268
A11: Local | B11: ='#s for Report-State'!J32 -> 3881.851 | C11: ='#s for Report-State'!J39 -> 522.96061 | D11: ='#s for Report-Maricopa County'!J12 -> 4334.1476 | E11: ='#s for Report-Maricopa County'!J18 -> 565.41195
A12: Other | B12: ='#s for Report-State'!K32 -> 4.3600155 | C12: ='#s for Report-State'!K39 -> 13.622706 | D12: ='#s for Report-Maricopa County'!K12 -> 2.4942239 | E12: ='#s for Report-Maricopa County'!K18 -> 8.6472116
A13: Indeterminate | B13: 0 | C13: 0 | D13: 0 | E13: 0
A14: Total | B14: =SUM(B9:B13) -> 9576.9467 | C14: =SUM(C9:C13) -> 7596.7418 | D14: =SUM(D9:D13) -> 9559.6363 | E14: =SUM(E9:E13) -> 7376.2156
A15: Enrollment
A16: District | B16: ='#s for Report-State'!H31 -> 934595.52 | D16: ='#s for Report-Maricopa County'!H11 -> 587562.72
B17: =B16/(B16+B18) -> 0.91285604 | D17: =D16/(D16+D18) -> 0.90934342 | H17: District | I17: Charter | J17: Difference
A18: Charter | B18: ='#s for Report-State'!H38 -> 89219.276 | D18: ='#s for Report-Maricopa County'!H17 -> 58576.802 | G18: Arizona | H18: =B4 -> 9576.9467 | I18: =B5 -> 7596.7418 | J18: =B6 -> 1980.2049
B19: =B18/(B16+B18) -> 0.08714396 | D19: =D18/(D16+D18) -> 0.090656584 | G19: Maricopa County | H19: =D4 -> 9559.6363 | I19: =D5 -> 7376.2156 | J19: =D6 -> 2183.4207
A20: Number of Charters | B20: ='#s for Report-State'!G38 -> 448 | D20: ='#s for Report-Maricopa County'!G17 -> 194 | G20: City B Name Here | H20: 0 | I20: 0 | J20: 0
A21: Total Revenue | G21: City C Name Here | H21: 0 | I21: 0 | J21: 0
A22: District | B22: ='#s for Report-State'!I31 -> 8.9505715e+09 | D22: ='#s for Report-Maricopa County'!I11 -> 5616885964
B23: =B22/B26 -> 0.92960622 | D23: =D22/D26 -> 0.92857036
A24: Charter | B24: ='#s for Report-State'!I38 -> 6.777758e+08 | D24: ='#s for Report-Maricopa County'!I17 -> 432075120
B25: =B24/B26 -> 0.070393784 | D25: =D24/D26 -> 0.071429641
A26: Total | B26: =B24+B22 -> 9628347269 | D26: =D24+D22 -> 6048961084
A27: Percentage of Revenue by Source | B27: District | C27: Charter | D27: District | E27: Charter | G27: Figure 4
A28: Federal | B28: ='#s for Report-State'!M33 -> 0.10672518 | C28: ='#s for Report-State'!M40 -> 0.086573175 | D28: ='#s for Report-Maricopa County'!M13 -> 0.080623171 | E28: ='#s for Report-Maricopa County'!M19 -> 0.053283374
A29: State | B29: ='#s for Report-State'!L33 -> 0.48748671 | C29: ='#s for Report-State'!L40 -> 0.84279348 | D29: ='#s for Report-Maricopa County'!L13 -> 0.46573595 | E29: ='#s for Report-Maricopa County'!L19 -> 0.86889092
A30: Local | B30: ='#s for Report-State'!J33 -> 0.40533284 | C30: ='#s for Report-State'!J40 -> 0.068840119 | D30: ='#s for Report-Maricopa County'!J13 -> 0.45337996 | E30: ='#s for Report-Maricopa County'!J19 -> 0.076653393
A31: Other | B31: ='#s for Report-State'!K33 -> 0.00045526155 | C31: ='#s for Report-State'!K40 -> 0.0017932301 | D31: ='#s for Report-Maricopa County'!K13 -> 0.00026091201 | E31: ='#s for Report-Maricopa County'!K19 -> 0.00117231
A32: Change in district school funding if subjected to charter funding structure
B33: ='#s for Report-State'!I52 -> -1.8506906e+09 | D33: ='#s for Report-Maricopa County'!I31 -> -1.2828966e+09
B35: =SUM(B28:B31) -> 1 | C35: =SUM(C28:C31) -> 1 | D35: =SUM(D28:D31) -> 1 | E35: =SUM(E28:E31) -> 1
H48: Federal | I48: State | J48: Local | K48: Other | L48: Indeterminate
G49: Statewide District | H49: =B9 -> 1022.1014 | I49: =B10 -> 4668.6343 | J49: =B11 -> 3881.851 | K49: =B12 -> 4.3600155 | L49: 0
G50: Statewide Charter | H50: =C9 -> 657.67405 | I50: =C10 -> 6402.4844 | J50: =C11 -> 522.96061 | K50: =C12 -> 13.622706 | L50: 0
G51: Maricopa-District | H51: =D9 -> 770.7282 | I51: =D10 -> 4452.2663 | J51: =D11 -> 4334.1476 | K51: =D12 -> 2.4942239 | L51: 0
G52: Maricopa-Charter | H52: =E9 -> 393.02965 | I52: =E10 -> 6409.1268 | J52: =E11 -> 565.41195 | K52: =E12 -> 8.6472116 | L52: 0
G53: City B District | H53: 0 | I53: 0 | J53: 0 | K53: 0 | L53: 0
...

Sheet Figures 1,2,4-Weighted
A1: Figure 1 | I1: Figure 2
A2: Arizona 2006-07 | B2: Statewide | D2: Statewide Weighted for Charter Enrollment | F2: Maricopa County
A3: Per-Pupil Revenue
A4: District | B4: ='[1]#s for Report-State'!I32 -> 9576.9467 | D4: 9576 | F4: ='[1]#s for Report-Maricopa County'!I12 -> 9559.6363
A5: Charter | B5: ='[1]#s for Report-State'!I39 -> 7596.7418 | D5: 7597 | F5: ='[1]#s for Report-Maricopa County'!I18 -> 7376.2156
A6: Difference | B6: =B4-B5 -> 1980.2049 | D6: 1979 | F6: =F4-F5 -> 2183.4207
B7: =B6/B4 -> 0.20676787 | D7: 0.207 | F7: =F6/F4 -> 0.22839998
A8: Per-Pupil Revenue by Source | B8: District | C8: Charter | D8: District | E8: Charter | F8: District | G8: Charter
A9: Federal | B9: ='[1]#s for Report-State'!M32 -> 1022.1014 | C9: ='[1]#s for Report-State'!M39 -> 657.67405 | D9: =1003 -> 1003 | E9: =C9 -> 657.67405 | F9: ='[1]#s for Report-Maricopa County'!M12 -> 770.7282 | G9: ='[1]#s for Report-Maricopa County'!M18 -> 393.02965
A10: State | B10: ='[1]#s for Report-State'!L32 -> 4668.6343 | C10: ='[1]#s for Report-State'!L39 -> 6402.4844 | D10: 4653 | E10: =C10 -> 6402.4844 | F10: ='[1]#s for Report-Maricopa County'!L12 -> 4452.2663 | G10: ='[1]#s for Report-Maricopa County'!L18 -> 6409.1268
A11: Local | B11: ='[1]#s for Report-State'!J32 -> 3881.851 | C11: ='[1]#s for Report-State'!J39 -> 522.96061 | D11: 3916 | E11: =C11 -> 522.96061 | F11: ='[1]#s for Report-Maricopa County'!J12 -> 4334.1476 | G11: ='[1]#s for Report-Maricopa County'!J18 -> 565.41195
A12: Other | B12: ='[1]#s for Report-State'!K32 -> 4.3600155 | C12: ='[1]#s for Report-State'!K39 -> 13.622706 | D12: 4 | E12: =C12 -> 13.622706 | F12: ='[1]#s for Report-Maricopa County'!K12 -> 2.4942239 | G12: ='[1]#s for Report-Maricopa County'!K18 -> 8.6472116
A13: Indeterminate | B13: 0 | C13: 0 | D13: 0 | E13: =C13 -> 0 | F13: 0 | G13: 0
A14: Total | B14: =SUM(B9:B13) -> 9576.9467 | C14: =SUM(C9:C13) -> 7596.7418 | D14: =D4 -> 9576 | E14: =C14 -> 7596.7418 | F14: =SUM(F9:F13) -> 9559.6363 | G14: =SUM(G9:G13) -> 7376.2156
A15: Enrollment
A16: District | B16: ='[1]#s for Report-State'!H31 -> 934595.52 | D16: n/a | F16: ='[1]#s for Report-Maricopa County'!H11 -> 587562.72
B17: =B16/(B16+B18) -> 0.91285604 | D17: n/a | F17: =F16/(F16+F18) -> 0.90934342 | J17: District | K17: Charter | L17: Difference
A18: Charter | B18: ='[1]#s for Report-State'!H38 -> 89219.276 | D18: n/a | F18: ='[1]#s for Report-Maricopa County'!H17 -> 58576.802 | I18: Arizona | J18: =B4 -> 9576.9467 | K18: =B5 -> 7596.7418 | L18: =B6 -> 1980.2049
B19: =B18/(B16+B18) -> 0.08714396 | D19: n/a | F19: =F18/(F16+F18) -> 0.090656584 | I19: Arizona Weighted | J19: =D4 -> 9576 | K19: =D5 -> 7597 | L19: =D6 -> 1979
A20: Number of Charters | B20: ='[1]#s for Report-State'!G38 -> 448 | D20: n/a | F20: ='[1]#s for Report-Maricopa County'!G17 -> 194 | I20: Maricopa County | J20: =F4 -> 9559.6363 | K20: =F5 -> 7376.2156 | L20: =F6 -> 2183.4207
A21: Total Revenue | I21: City C Name Here | J21: 0 | K21: 0 | L21: 0
A22: District | B22: ='[1]#s for Report-State'!I31 -> 8.9505715e+09 | D22: n/a | F22: ='[1]#s for Report-Maricopa County'!I11 -> 5616885964
B23: =B22/B26 -> 0.92960622 | D23: n/a | F23: =F22/F26 -> 0.92857036
A24: Charter | B24: ='[1]#s for Report-State'!I38 -> 6.777758e+08 | D24: n/a | F24: ='[1]#s for Report-Maricopa County'!I17 -> 432075120
B25: =B24/B26 -> 0.070393784 | D25: n/a | F25: =F24/F26 -> 0.071429641
A26: Total | B26: =B24+B22 -> 9628347269 | D26: n/a | F26: =F24+F22 -> 6048961084
A27: Percentage of Revenue by Source | B27: District | C27: Charter | D27: District | E27: Charter | F27: District | G27: Charter | I27: Figure 4
A28: Federal | B28: ='[1]#s for Report-State'!M33 -> 0.10672518 | C28: ='[1]#s for Report-State'!M40 -> 0.086573175 | D28: =D9/$D$14 -> 0.10474102 | E28: =C28 -> 0.086573175 | F28: ='[1]#s for Report-Maricopa County'!M13 -> 0.080623171 | G28: ='[1]#s for Report-Maricopa County'!M19 -> 0.053283374
A29: State | B29: ='[1]#s for Report-State'!L33 -> 0.48748671 | C29: ='[1]#s for Report-State'!L40 -> 0.84279348 | D29: =D10/$D$14 -> 0.48590226 | E29: =C29 -> 0.84279348 | F29: ='[1]#s for Report-Maricopa County'!L13 -> 0.46573595 | G29: ='[1]#s for Report-Maricopa County'!L19 -> 0.86889092
A30: Local | B30: ='[1]#s for Report-State'!J33 -> 0.40533284 | C30: ='[1]#s for Report-State'!J40 -> 0.068840119 | D30: =D11/$D$14 -> 0.40893901 | E30: =C30 -> 0.068840119 | F30: ='[1]#s for Report-Maricopa County'!J13 -> 0.45337996 | G30: ='[1]#s for Report-Maricopa County'!J19 -> 0.076653393
A31: Other | B31: ='[1]#s for Report-State'!K33 -> 0.00045526155 | C31: ='[1]#s for Report-State'!K40 -> 0.0017932301 | D31: =D12/$D$14 -> 0.00041771094 | E31: =C31 -> 0.0017932301 | F31: ='[1]#s for Report-Maricopa County'!K13 -> 0.00026091201 | G31: ='[1]#s for Report-Maricopa County'!K19 -> 0.00117231
A32: Change in district school funding if subjected to charter funding structure
B33: ($1.9 billion) | F33: ($1.3 billion)
B35: =(B$16*B$5)-B$22 -> -1.8506906e+09 | F35: =(F$16*F$5)-F$22 -> -1.2828966e+09
B36: =SUM(B28:B31) -> 1 | C36: =SUM(C28:C31) -> 1 | F36: =SUM(F28:F31) -> 1 | G36: =SUM(G28:G31) -> 1
J48: Federal | K48: State | L48: Local | M48: Other | N48: Indeterminate
I49: Statewide District | J49: =B9 -> 1022.1014 | K49: =B10 -> 4668.6343 | L49: =B11 -> 3881.851 | M49: =B12 -> 4.3600155 | N49: 0
I50: Statewide Weighted | J50: =D9 -> 1003 | K50: =D10 -> 4653 | L50: =D11 -> 3916 | M50: =D12 -> 4 | N50: =D13 -> 0
I51: Statewide Charter | J51: =C9 -> 657.67405 | K51: =C10 -> 6402.4844 | L51: =C11 -> 522.96061 | M51: =C12 -> 13.622706 | N51: 0
I52: Maricopa District | J52: =F9 -> 770.7282 | K52: =F10 -> 4452.2663 | L52: =F11 -> 4334.1476 | M52: =F12 -> 2.4942239 | N52: 0
...

Sheet Report Figures 1,3,5,6
B3: Figure 1
B4: Arizona (2006-07) | C4: Statewide | E4: Statewide Weighted for Charter Enrollment | G4: Maricopa County | J4: Scroll down & to right
B5: Per-Pupil Revenue
B6: District | C6: 9576.9467 | E6: 9576 | G6: 9559.6363
B7: Charter | C7: 7596.7418 | E7: 7597 | G7: 7376.2156
B8: Difference | C8: ($1,980) | E8: ($1,979) | G8: ($2,183)
C9: (20.7%) | E9: (20.7%) | G9: (22.8%)
B10: Per-Pupil Revenue by Source | C10: District | D10: Charter | E10: District | F10: Charter | G10: District | H10: Charter
B11: Federal | C11: 1022.1014 | D11: 657.67405 | E11: 1003 | F11: 657.67405 | G11: 770.7282 | H11: 393.02965
B12: State | C12: 4668.6343 | D12: 6402.4844 | E12: 4653 | F12: 6402.4844 | G12: 4452.2663 | H12: 6409.1268
B13: Local | C13: 3881.851 | D13: 522.96061 | E13: 3916 | F13: 522.96061 | G13: 4334.1476 | H13: 565.41195
B14: Other | C14: 4.3600155 | D14: 13.622706 | E14: 4 | F14: 13.622706 | G14: 2.4942239 | H14: 8.6472116
B15: Indeterminate | C15: 0 | D15: 0 | E15: 0 | F15: 0 | G15: 0 | H15: 0
B16: Total | C16: 9576.9467 | D16: 7596.7418 | E16: 9576 | F16: 7596.7418 | G16: 9559.6363 | H16: 7376.2156
B17: Enrollment
B18: District | C18: 934595.52 | E18: N/A | G18: 587562.72
C19: 0.91285604 | E19: N/A | G19: 0.90934342
B20: Charter | C20: 89219.276 | E20: N/A | G20: 58576.802
C21: 0.08714396 | E21: N/A | G21: 0.090656584
B22: Number of Charters | C22: 448 | E22: N/A | G22: 194
B23: Total Revenue
B24: District | C24: 8.9505715e+09 | E24: N/A | G24: 5616885964
C25: 0.92960622 | E25: N/A | G25: 0.92857036
B26: Charter | C26: 6.777758e+08 | E26: N/A | G26: 432075120
C27: 0.070393784 | E27: N/A | G27: 0.071429641
B28: Total | C28: 9628347269 | E28: N/A | G28: 6048961084
B29: Percentage of Revenue by Source | C29: District | D29: Charter | E29: District | F29: Charter | G29: District | H29: Charter
B30: Federal | C30: 0.10672518 | D30: 0.086573175 | E30: 0.10474102 | F30: 0.086573175 | G30: 0.080623171 | H30: 0.053283374
B31: State | C31: 0.48748671 | D31: 0.84279348 | E31: 0.48590226 | F31: 0.84279348 | G31: 0.46573595 | H31: 0.86889092
B32: Local | C32: 0.40533284 | D32: 0.068840119 | E32: 0.40893901 | F32: 0.068840119 | G32: 0.45337996 | H32: 0.076653393
B33: Other | C33: 0.00045526155 | D33: 0.0017932301 | E33: 0.00041771094 | F33: 0.0017932301 | G33: 0.00026091201 | H33: 0.00117231
B34: Indeterminate | C34: =C15 -> 0 | D34: =D15 -> 0 | E34: 0 | F34: 0 | G34: 0 | H34: 0
B35: Change in district school funding if subjected to charter funding structure
C36: ($1.9 billion) | G36: ($1.3 billion)
J38: Figure 3
J39: State Policies | K39: Yes | L39: No | M39: Partial
J40: Charter schools receive their funding directly from the state | M40: X3
J41: Charter schools are eligible for local funding | L41: X
J42: Cap on funding a charter school can receive | L42: X
J43: District public schools receive differential funding (e.g. more funding for 9-12 vs. K-8 schools) | K43: X
...

Sheet #s for Report-State
B3: Calculation of District and Charter School Amounts -- State Totals | N3: 1/21/2009
G4: # of | H4: 2006-2007 Revenues
G5: Districts /
G6: Charter | K6: County /
G7: Schools | H7: ADM | I7: Total | J7: Local | K7: Intermediate | L7: State | M7: Federal | N7: NOTES
B8: State Districts: Per Annual Report of the Arizona Superintendent of Public Instruction, Fiscal Year 2006-2007, Volume II, Section I | G8: 238 | H8: 935227.91 | I8: =SUM(J8:M8) -> 8953120539 | J8: 3627960547 | K8: 4074851 | L8: 4365833746 | M8: 955251395
C9: Adjustments:
D10: District-Sponsored Charter Schools -- AFR Not Submitted: Per Annual Report of the Arizona Superintendent of Public Instruction, Fiscal Year 2006-2007, Volume II, pg. II-5
D11: San Pedro Valley High Schools | G11: N/A | H11: -39.3 | L11: =-225563.11-16767.478-1737.9 -> -244068.49 | N11: 1
E12: #020209700
E13: Benson Unified School District
D14: Sterling Acad of Math & Science | G14: N/A | H14: -36.903 | L14: =-69629.33-3034.616-344.4 -> -73008.346 | N14: 1
E15: #080208760
E16: Peach Springs Unified SD
D17: Vail Charter High School | G17: N/A | H17: -142.845 | L17: =-813348.45-64316.604-6666.23 -> -884331.28 | N17: 1
E18: #100220700
E19: Vail Unified School District
D20: Civano Charter School | G20: N/A | H20: -86.385 | L20: =-446489.57-35298.998-4006.18 -> -485794.75 | N20: 1
E21: #100220705
E22: Vail Unified School District
D23: Coolidge High School | G23: N/A | H23: -63.12 | L23: =-103103.17-28928.852-2998.39 -> -135030.41 | N23: 1
E24: #110221710
E25: Coolidge Unified SD
D26: Casa Verde High School | G26: N/A | H26: -263.84 | L26: =-595729.2-118795.147-12312.79 -> -726837.14 | N26: 1
E27: #110502700
E28: Casa Grande Union High SD
E29: Adjustment Subtotal | G29: N/A | H29: =SUM(H11:H26) -> -632.393 | L29: =SUM(L11:L26) -> -2549070.4 | N29: 5
B31: Total -- State Districts | G31: 238 | H31: =H8+H29 -> 934595.52 | I31: =SUM(J31:M31) -> 8.9505715e+09 | J31: =J8+J29 -> 3627960547 | K31: =K8+K29 -> 4074851 | L31: =L8+L29 -> 4.3632847e+09 | M31: =M8+M29 -> 955251395 | N31: 3
B32: Total -- District Per Pupil | I32: =I31/$H31 -> 9576.9467 | J32: =J31/$H31 -> 3881.851 | K32: =K31/$H31 -> 4.3600155 | L32: =L31/$H31 -> 4668.6343 | M32: =M31/$H31 -> 1022.1014
B33: % of Revenues by Source: Districts | I33: =SUM(J33:M33) -> 1 | J33: =J31/$I31 -> 0.40533284 | K33: =K31/$I31 -> 0.00045526155 | L33: =L31/$I31 -> 0.48748671 | M33: =M31/$I31 -> 0.10672518
B34: State Charter Schools: Per Annual Report of the Arizona Superintendent of Public Instruction, Fiscal Year 2006-2007, Volume II, Section II | G34: 442 | H34: 88586.883 | I34: =SUM(J34:M34) -> 675226730 | J34: 46658167 | K34: 1215408 | L34: 568675952 | M34: 58677203
C35: Adjustments:
D36: District-Sponsored Charter Schools -- AFR Not Submitted: Per Annual Report of the Arizona Superintendent of Public Instruction, Fiscal Year 2006-2007, Volume II, pg. II-5 -- subtotal from above | G36: 6 | H36: 632.393 | L36: 2549070.4 | N36: 2 & 5
B38: Total -- State Charter Schools4 | G38: =G34+G36 -> 448 | H38: =H34+H36 -> 89219.276 | I38: =SUM(J38:M38) -> 6.777758e+08 | J38: =J34+J36 -> 46658167 | K38: =K34+K36 -> 1215408 | L38: =L34+L36 -> 5.7122502e+08 | M38: =M34+M36 -> 58677203 | N38: 3
B39: Total -- Charter Schools Per Pupil4 | I39: =I38/$H38 -> 7596.7418 | J39: =J38/$H38 -> 522.96061 | K39: =K38/$H38 -> 13.622706 | L39: =L38/$H38 -> 6402.4844 | M39: =M38/$H38 -> 657.67405
B40: % of Revenues by Source: Charters | I40: =SUM(J40:M40) -> 1 | J40: =J38/$I38 -> 0.068840119 | K40: =K38/$I38 -> 0.0017932301 | L40: =L38/$I38 -> 0.84279348 | M40: =M38/$I38 -> 0.086573175
B41: Statistics: | H41: ADM | I41: Total | J41: Local | K41: County/ Interm. | L41: State | M41: Federal
C42: Total State Public K-12 Education-ADM | H42: =H31+H38 -> 1023814.8
C43: Total State Public K-12 Education-Revenue | I43: =SUM(J43:M43) -> 9628347269 | J43: =J38+J31 -> 3674618714 | K43: =K38+K31 -> 5290259 | L43: =L38+L31 -> 4934509698 | M43: =M38+M31 -> 1013928598
C44: State K-12 Total-% of Revenue by Source | I44: =SUM(J44:M44) -> 1 | J44: =J43/I43 -> 0.38164584 | K44: =K43/I43 -> 0.00054944622 | L44: =L43/I43 -> 0.5124981 | M44: =M43/I43 -> 0.10530661
...

Sheet #s for Report-Maricopa County
B3: Calculation of District and Charter School Amounts -- Maricopa County Totals | N3: 1/21/2009
G4: # of | H4: 2006-2007 Revenues
G5: Districts /
G6: Charter | K6: County /
G7: Schools | H7: ADM | I7: Total | J7: Local | K7: Intermediate | L7: State | M7: Federal | N7: NOTES
B8: Maricopa County Districts: Per Annual Report of the Arizona Superintendent of Public Instruction, Fiscal Year 2006-2007, Volume II, Section I | G8: 58 | H8: 587562.72 | I8: =SUM(J8:M8) -> 5616885964 | J8: 2546583549 | K8: 1465513 | L8: 2615985743 | M8: 452851159
C9: No Adjustments:
B11: Total -- Maricopa County Districts | G11: =G8+G9 -> 58 | H11: =SUM(H8:H9) -> 587562.72 | I11: =SUM(J11:M11) -> 5616885964 | J11: =J8 -> 2546583549 | K11: =K8 -> 1465513 | L11: =L8 -> 2615985743 | M11: =M8 -> 452851159 | N11: 1
B12: Total -- District Per Pupil | I12: =I11/$H11 -> 9559.6363 | J12: =J11/$H11 -> 4334.1476 | K12: =K11/$H11 -> 2.4942239 | L12: =L11/$H11 -> 4452.2663 | M12: =M11/$H11 -> 770.7282
B13: % of Revenues by Source: Districts | I13: =SUM(J13:M13) -> 1 | J13: =J11/$I11 -> 0.45337996 | K13: =K11/$I11 -> 0.00026091201 | L13: =L11/$I11 -> 0.46573595 | M13: =M11/$I11 -> 0.080623171
B14: Maricopa County Charter Schools: Per Annual Report of the Arizona Superintendent of Public Instruction, Fiscal Year 2006-2007, Volume II, Section II | G14: 194 | H14: 58576.802 | I14: =SUM(J14:M14) -> 432075120 | J14: 33120024 | K14: 506526 | L14: 375426150 | M14: 23022420
C15: No Adjustments:
B17: Total -- Maricopa Charter Schools2 | G17: =G14+G15 -> 194 | H17: =H14+H15 -> 58576.802 | I17: =SUM(J17:M17) -> 432075120 | J17: =J14+J15 -> 33120024 | K17: =K14+K15 -> 506526 | L17: =L14+L15 -> 375426150 | M17: =M14+M15 -> 23022420 | N17: 1
B18: Total -- Charter Schools Per Pupil | I18: =I17/$H17 -> 7376.2156 | J18: =J17/$H17 -> 565.41195 | K18: =K17/$H17 -> 8.6472116 | L18: =L17/$H17 -> 6409.1268 | M18: =M17/$H17 -> 393.02965
B19: % of Revenues by Source: Charters | I19: =SUM(J19:M19) -> 1 | J19: =J17/$I17 -> 0.076653393 | K19: =K17/$I17 -> 0.00117231 | L19: =L17/$I17 -> 0.86889092 | M19: =M17/$I17 -> 0.053283374
B20: Statistics: | H20: ADM | I20: Total | J20: Local | K20: County/ Interm. | L20: State | M20: Federal
C21: Total Maricopa County Public K-12 Education | H21: =H11+H17 -> 646139.53
C22: Total Maricopa County Public K-12-Revenue | I22: =SUM(J22:M22) -> 6048961084 | J22: =J17+J11 -> 2579703573 | K22: =K17+K11 -> 1972039 | L22: =L17+L11 -> 2991411893 | M22: =M17+M11 -> 475873579
C23: Maricopa Total-% of Revenue by Source | I23: =SUM(J23:M23) -> 1 | J23: =J22/I22 -> 0.42647052 | K23: =K22/I22 -> 0.00032601284 | L23: =L22/I22 -> 0.49453317 | M23: =M22/I22 -> 0.078670299
C24: % District Students | H24: =H11/H21 -> 0.90934342
C25: % Charter Students | H25: =H17/H21 -> 0.090656584
C26: Revenue by Source-% District Share | I26: =I11/I22 -> 0.92857036 | J26: =J11/J22 -> 0.98716131 | K26: =K11/K22 -> 0.74314605 | L26: =L11/L22 -> 0.87449868 | M26: =M11/M22 -> 0.95162072
C27: Revenue by Source-% Charter Share | I27: =I17/I22 -> 0.071429641 | J27: =J17/J22 -> 0.012838694 | K27: =K17/K22 -> 0.25685395 | L27: =L17/L22 -> 0.12550132 | M27: =M17/M22 -> 0.048379278
I28: =SUM(I26:I27) -> 1 | J28: =SUM(J26:J27) -> 1 | K28: =SUM(K26:K27) -> 1 | L28: =SUM(L26:L27) -> 1 | M28: =SUM(M26:M27) -> 1
C29: Per Pupil Difference: Districts-Charters | I29: =I12-I18 -> 2183.4207 | J29: =J12-J18 -> 3768.7356 | K29: =K12-K18 -> -6.1529877 | L29: =L12-L18 -> -1956.8604 | M29: =M12-M18 -> 377.69855
C30: Change in charter school funding if district per pupil is applied to charter schools: More / (Less) | I30: =(I12*$H$17)-I17 -> 1.278978e+08 | J30: =(J12*$H$17)-J17 -> 2.2076048e+08 | K30: =(K12*$H$17)-K17 -> -360422.34 | L30: =(L12*$H$17)-L17 -> -1.1462663e+08 | M30: =(M12*$H$17)-M17 -> 22124373
C31: Change in district school funding if charter schools per pupil is applied to all districts: More / (Less) | I31: =(I18*$H$11)-I11 -> -1.2828966e+09 | J31: =(J18*$H$11)-J11 -> -2.2143686e+09 | K31: =(K18*$H$11)-K11 -> 3615266.2 | L31: =(L18*$H$11)-L11 -> 1.1497782e+09 | M31: =(M18*$H$11)-M11 -> -2.2192159e+08
B34: NOTES:
B35: 1 | C35: Total used for the 2006-2007 Charter School Funding study.
B36: 2 | C36: In 2006-2007 in Maricopa County there were 194 state-sponsored charter organizations (none district-sponsored) operating 252 charter school campuses.

Sheet Charter & District Data
A1: Per Pupil Revenue
A2: For Public School Districts and 337 State-Sponsored Public Charter Schools | T2: Revenue by Source and Total Per Pupil Revenue
A3: 2006-2007 | L3: SAVE A COPY OF THIS FILE | T3: Maricopa County Charter Schools
A4: County | D4: District or Charter | G4: Total | H4: Enroll- | L4: BEFORE YOU BEGIN TO SORT | T4: 2006-2007
A5: # | B5: Name | C5: D/C | D5: # | E5: Name | F5: Type | G5: Revenue | H5: ment | I5: $PP | T5: County | W5: Charter Organization | Z5: Revenue Source | AF5: Per Pupil
A6: A | B6: B | C6: C | D6: D | E6: E | F6: F | G6: G | H6: H | I6: I | T6: # | U6: Name | V6: C/D | W6: # | X6: Name | Y6: Type | Z6: Local | AA6: Intermed | AB6: State | AC6: Federal | AD6: Total | AE6: ADM | AF6: Revenue
A7: 0 | B7: ~State | C7: ~C | D7: ~C-999999999 | E7: ~Total-Charters | F7: ~99 | G7: 675226730 | H7: 88586.893 | I7: 7622.1968 | K7: About MS Excel 2007 Tables (see at LEFT) | T7: 07 | U7: Maricopa | V7: C | W7: C-078799000 | X7: Academy of Arizona | Y7: 87 | Z7: 1483 | AA7: 0 | AB7: 2146211 | AC7: 123011 | AD7: =SUM(Z7:AC7) -> 2270705 | AE7: 338.68 | AF7: 6704.5736
A8: 0 | B8: ~State | C8: ~D | D8: ~D-999999999 | E8: ~Total-Districts | F8: ~99 | G8: 8953120539 | H8: 935228 | I8: 9573 | L8: Click the the arrow buttons in row 6 (purple) to sort. | T8: 07 | U8: Maricopa | V8: C | W8: C-078604000 | X8: Academy of Excellence | Y8: 86 | Z8: 23754 | AA8: 0 | AB8: 991909 | AC8: 177218 | AD8: =SUM(Z8:AC8) -> 1192881 | AE8: 115.59 | AF8: 10319.933
A9: 01 | B9: Apache | C9: C | D9: C-999999000 | E9: ~Subtotal-Charter Schools | F9: 99 | G9: 1095428 | H9: 96.525 | I9: 11348.645 | L9: Select a sort order to sort the list. | T9: 07 | U9: Maricopa | V9: C | W9: C-078794000 | X9: Academy with Community Partners | Y9: 87 | Z9: 19740 | AA9: 0 | AB9: 1246414 | AC9: 99506 | AD9: =SUM(Z9:AC9) -> 1365660 | AE9: 175.41 | AF9: 7785.531
A10: 01 | B10: Apache | C10: D | D10: D-999999000 | E10: ~Subtotal-Districts | F10: 9 | G10: 180814970 | H10: 12885.848 | I10: 14032.058 | L10: The last button used displays an up or down arrow. | T10: 07 | U10: Maricopa | V10: C | W10: C-078979000 | X10: Accelerated Learning Center | Y10: 89 | Z10: 64628 | AA10: 0 | AB10: 1931842 | AC10: 0 | AD10: =SUM(Z10:AC10) -> 1996470 | AE10: 282.34 | AF10: 7071.1553
A11: 01 | B11: Apache | C11: C | D11: C-018752000 | E11: 4-Winds Academy | F11: 87 | G11: 382743 | H11: 31.875 | I11: 12007.624 | L11: Always use buttons to sort (not Data | Sort). | T11: 07 | U11: Maricopa | V11: C | W11: C-078701000 | X11: Acclaim | Y11: 87 | Z11: 61351 | AA11: 0 | AB11: 2179720 | AC11: 381239 | AD11: =SUM(Z11:AC11) -> 2622310 | AE11: 336.59 | AF11: 7790.8137
A12: 01 | B12: Apache | C12: D | D12: D-010307000 | E12: Alpine | F12: E | G12: 1218442 | H12: 54.09 | I12: 22526.197 | L12: For lowest to highest per pupil in a county: | T12: 07 | U12: Maricopa | V12: C | W12: C-078938000 | X12: Advance Ed Services | Y12: 89 | Z12: 43397 | AA12: 3347 | AB12: 249416 | AC12: 6522 | AD12: =SUM(Z12:AC12) -> 302682 | AE12: 41.86 | AF12: 7230.817
A13: 01 | B13: Apache | C13: D | D13: D-010224000 | E13: Chinle | F13: U | G13: 54534230 | H13: 3658.725 | I13: 14905.255 | L13: First, sort $PP from lowest to highest (col. I). | T13: 07 | U13: Maricopa | V13: C | W13: C-078782000 | X13: Advance Ed Services, Inc. | Y13: 87 | Z13: 176722 | AA13: 1065 | AB13: 1140201 | AC13: 10052 | AD13: =SUM(Z13:AC13) -> 1328040 | AE13: 163.925 | AF13: 8101.5098
A14: 01 | B14: Apache | C14: D | D14: D-010306000 | E14: Choncho | F14: E | G14: 3138263 | H14: 187.71 | I14: 16718.678 | L14: Then, sort by County (col. A or B) | T14: 07 | U14: Maricopa | V14: C | W14: C-078501000 | X14: Ahwatukee Foothills Prep | Y14: 85 | Z14: 197337 | AA14: 0 | AB14: 1592269 | AC14: 98778 | AD14: =SUM(Z14:AC14) -> 1888384 | AE14: 225.95 | AF14: 8357.5304
A15: 01 | B15: Apache | C15: D | D15: D-010220000 | E15: Ganado | F15: U | G15: 24947680 | H15: 1759.295 | I15: 14180.498 | L15: To see all subtotals by county and the state total: | T15: 07 | U15: Maricopa | V15: C | W15: C-078793000 | X15: AIBT Non-Profit-Phoenix | Y15: 87 | Z15: 7578 | AA15: 0 | AB15: 1052557 | AC15: 25552 | AD15: =SUM(Z15:AC15) -> 1085687 | AE15: 151.76 | AF15: 7153.9734
A16: 01 | B16: Apache | C16: C | D16: C-018759000 | E16: Kin Dah Lichii Olta | F16: 87 | G16: 433103 | H16: 40.49 | I16: 10696.542 | L16: Click the arrow button in E6 and sort A to Z. | T16: 07 | U16: Maricopa | V16: C | W16: C-078970000 | X16: Air Academy High | Y16: 89 | Z16: 171861 | AA16: 0 | AB16: 1179817 | AC16: 1344 | AD16: =SUM(Z16:AC16) -> 1353022 | AE16: 188.848 | AF16: 7164.6086
A17: 01 | B17: Apache | C17: D | D17: D-010323000 | E17: Mcnary | F17: E | G17: 2548648 | H17: 155.78 | I17: 16360.56 | L17: To return tor original sort order: | T17: 07 | U17: Maricopa | V17: C | W17: C-078967000 | X17: All Aboard | Y17: 89 | Z17: 3357 | AA17: 0 | AB17: 437264 | AC17: 17689 | AD17: =SUM(Z17:AC17) -> 458310 | AE17: 61.155 | AF17: 7494.236
A18: 01 | B18: Apache | C18: C | D18: C-018760000 | E18: Nazlini Community | F18: 87 | G18: 279582 | H18: 24.16 | I18: 11572.103 | M18: 1) Use button at E6 to sort A to Z. | T18: 07 | U18: Maricopa | V18: C | W18: C-078724000 | X18: Allen-Cochran | Y18: 87 | Z18: 66356 | AA18: 0 | AB18: 1890662 | AC18: 0 | AD18: =SUM(Z18:AC18) -> 1957018 | AE18: 290.66 | AF18: 6733.0145
A19: 01 | B19: Apache | C19: D | D19: D-010227000 | E19: Red Mesa | F19: U | G19: 17339902 | H19: 975.785 | I19: 17770.208 | M19: 2) Use button at B6 to sort A to Z. | T19: 07 | U19: Maricopa | V19: C | W19: C-078989000 | X19: American Basic | Y19: 89 | Z19: 113998 | AA19: 0 | AB19: 3542782 | AC19: 169125 | AD19: =SUM(Z19:AC19) -> 3825905 | AE19: 582.51 | AF19: 6567.9645
A20: 01 | B20: Apache | C20: D | D20: D-010210000 | E20: Round Valley | F20: U | G20: 12377297 | H20: 1411.95 | I20: 8766.1015 | T20: 07 | U20: Maricopa | V20: C | W20: C-078785000 | X20: APEX Ed Systems, Inc. | Y20: 87 | Z20: 106359 | AA20: 0 | AB20: 1011226 | AC20: 0 | AD20: =SUM(Z20:AC20) -> 1117585 | AE20: 153.575 | AF20: 7277.1284
A21: 01 | B21: Apache | C21: D | D21: D-010218000 | E21: Sanders | F21: U | G21: 15088528 | H21: 1037.9 | I21: 14537.555 | T21: 07 | U21: Maricopa | V21: C | W21: C-078946000 | X21: Apex Public Academy | Y21: 89 | Z21: 1595 | AA21: 0 | AB21: 268774 | AC21: 34343 | AD21: =SUM(Z21:AC21) -> 304712 | AE21: 44.1 | AF21: 6909.5692
A22: 01 | B22: Apache | C22: D | D22: D-010201000 | E22: St. Johns | F22: U | G22: 9633254 | H22: 999.813 | I22: 9635.0558 | T22: 07 | U22: Maricopa | V22: C | W22: C-078665000 | X22: Arizona Academy of Sci. & Tech. | Y22: 86 | Z22: 5236 | AA22: 0 | AB22: 883625 | AC22: 30832 | AD22: =SUM(Z22:AC22) -> 919693 | AE22: 132.605 | AF22: 6935.5831
A23: 01 | B23: Apache | C23: D | D23: D-010309000 | E23: Vernon | F23: E | G23: 1469331 | H23: 71.515 | I23: 20545.774 | K23: Highlighting Legend: | T23: 07 | U23: Maricopa | V23: C | W23: C-078707000 | X23: Arizona Agribus. & Equine, Inc. | Y23: 87 | Z23: 36706 | AA23: 0 | AB23: 1596867 | AC23: 19509 | AD23: =SUM(Z23:AC23) -> 1653082 | AE23: 229.043 | AF23: 7217.3435
A24: 01 | B24: Apache | C24: D | D24: D-010208000 | E24: Window Rock | F24: U | G24: 38519395 | H24: 2573.285 | I24: 14968.958 | L24: Purple = Drop-down arrow buttons. | T24: 07 | U24: Maricopa | V24: C | W24: C-078993000 | X24: Arizona Agribusiness & Equine | Y24: 89 | Z24: 38521 | AA24: 0 | AB24: 1978054 | AC24: 208687 | AD24: 2225262 | AE24: 288.66 | AF24: 7708.9379
A25: 02 | B25: Cochise | C25: C | D25: C-999999000 | E25: ~Subtotal-Charter Schools | F25: 99 | G25: 10348167 | H25: 1338.95 | I25: 7728.5687 | L25: Yellow = Subtotals by county and state total | T25: 07 | U25: Maricopa | V25: C | W25: C-078723000 | X25: Arizona Call-a-Teen Youth | Y25: 87 | Z25: 202706 | AA25: 0 | AB25: 572577 | AC25: 0 | AD25: =SUM(Z25:AC25) -> 775283 | AE25: 84.818 | AF25: 9140.548
A26: 02 | B26: Cochise | C26: D | D26: D-999999000 | E26: ~Subtotal-Districts | F26: 9 | G26: 168974628 | H26: 18844.609 | I26: 8966.7357 | M26: for public charter schools. | T26: 07 | U26: Maricopa | V26: C | W26: C-078511000 | X26: Arizona Connections | Y26: 85 | Z26: 20910 | AA26: 0 | AB26: 3065283 | AC26: 0 | AD26: =SUM(Z26:AC26) -> 3086193 | AE26: 475.86 | AF26: 6485.5062
A27: 02 | B27: Cochise | C27: D | D27: D-020342000 | E27: Apache | F27: E | G27: 174587 | H27: 6.54 | I27: 26695.26 | L27: Green = Subtotals by county and state total | T27: 07 | U27: Maricopa | V27: C | W27: C-078922000 | X27: Arizona Integrated Academics & Tech | Y27: 89 | Z27: 0 | AA27: 0 | AB27: 2541796 | AC27: 0 | AD27: =SUM(Z27:AC27) -> 2541796 | AE27: 413.71 | AF27: 6143.9076
A28: 02 | B28: Cochise | C28: D | D28: D-020453000 | E28: Ash Creek | F28: E | G28: 854056 | H28: 31.085 | I28: 27474.859 | M28: for public school districts. | T28: 07 | U28: Maricopa | V28: C | W28: C-078991000 | X28: Arizona Montessori-Anthem | Y28: 89 | Z28: 24518 | AA28: 0 | AB28: 599486 | AC28: 217523 | AD28: =SUM(Z28:AC28) -> 841527 | AE28: 88.38 | AF28: 9521.6904
A29: 02 | B29: Cochise | C29: D | D29: D-020209000 | E29: Benson | F29: U | G29: 9145748 | H29: 972.485 | I29: 9404.5132 | T29: 07 | U29: Maricopa | V29: C | W29: C-078722000 | X29: Arizona School for the Arts | Y29: 87 | Z29: 364418 | AA29: 51000 | AB29: 2407732 | AC29: 30388 | AD29: =SUM(Z29:AC29) -> 2853538 | AE29: 361.71 | AF29: 7889.0216
A30: 02 | B30: Cochise | C30: D | D30: D-020202000 | E30: Bisbee | F30: U | G30: 10861881 | H30: 944.19 | I30: 11503.914 | T30: 07 | U30: Maricopa | V30: C | W30: C-078961000 | X30: Ascending Roots | Y30: 89 | Z30: 19830 | AA30: 0 | AB30: 618973 | AC30: 128296 | AD30: =SUM(Z30:AC30) -> 767099 | AE30: 93.81 | AF30: 8177.156
A31: 02 | B31: Cochise | C31: D | D31: D-020214000 | E31: Bowie | F31: U | G31: 1632181 | H31: 91.12 | I31: 17912.434 | T31: 07 | U31: Maricopa | V31: C | W31: C-078510000 | X31: Arizona Agribus. & Equine, Inc. | Y31: 85 | Z31: 16677 | AA31: 0 | AB31: 872503 | AC31: 3141 | AD31: =SUM(Z31:AC31) -> 892321 | AE31: 124.11 | AF31: 7189.7591
A32: 02 | B32: Cochise | C32: C | D32: C-028750000 | E32: Center for Academic Success | F32: 87 | G32: 4572594 | H32: 583.825 | I32: 7832.1312 | T32: 07 | U32: Maricopa | V32: C | W32: C-078614000 | X32: Avondale Learning | Y32: 86 | Z32: 8297 | AA32: 0 | AB32: 565100 | AC32: 20644 | AD32: =SUM(Z32:AC32) -> 594041 | AE32: 78.19 | AF32: 7597.4038
A33: 02 | B33: Cochise | C33: D | D33: D-020326000 | E33: Cochise | F33: E | G33: 1230120 | H33: 59.615 | I33: 20634.404 | K33: D/C Legend: | T33: 07 | U33: Maricopa | V33: C | W33: C-078731000 | X33: Back-to-Basics | Y33: 87 | Z33: 15210 | AA33: 0 | AB33: 1115515 | AC33: 170015 | AD33: =SUM(Z33:AC33) -> 1300740 | AE33: 168.39 | AF33: 7724.568
A34: 02 | B34: Cochise | C34: C | D34: C-028701000 | E34: Cochise Community Dev. Corp | F34: 87 | G34: 1567979 | H34: 211.105 | I34: 7427.484 | L34: C = Public Charter School | T34: 07 | U34: Maricopa | V34: C | W34: C-078988000 | X34: Ball Charter-Dobson | Y34: 89 | Z34: 503809 | AA34: 0 | AB34: 3492648 | AC34: 14138 | AD34: =SUM(Z34:AC34) -> 4010595 | AE34: 561.715 | AF34: 7139.9108
A35: 02 | B35: Cochise | C35: D | D35: D-020801000 | E35: Cochise Tech | F35: T | G35: 2083967 | H35: 474.273 | I35: 4394.0241 | L35: D = Traditional Public School District | T35: 07 | U35: Maricopa | V35: C | W35: C-078987000 | X35: Ball Charter-Hearn | Y35: 89 | Z35: 297748 | AA35: 0 | AB35: 3115399 | AC35: 85283 | AD35: 3498430 | AE35: 518.555 | AF35: 6746.4975
A36: 02 | B36: Cochise | C36: D | D36: D-020345000 | E36: Double Adobe | F36: E | G36: 601016 | H36: 55.54 | I36: 10821.318 | T36: 07 | U36: Maricopa | V36: C | W36: C-078736000 | X36: BASIS | Y36: 87 | Z36: 289180 | AA36: 0 | AB36: 1586098 | AC36: 55463 | AD36: =SUM(Z36:AC36) -> 1930741 | AE36: 248.63 | AF36: 7765.519
A37: 02 | B37: Cochise | C37: D | D37: D-020227000 | E37: Douglas | F37: U | G37: 31399430 | H37: 3985.565 | I37: 7878.2883 | T37: 07 | U37: Maricopa | V37: C | W37: C-078972000 | X37: Bell Canyon | Y37: 89 | Z37: 136073 | AA37: 0 | AB37: 2172997 | AC37: 130483 | AD37: =SUM(Z37:AC37) -> 2439553 | AE37: 346.1 | AF37: 7048.694
A38: 02 | B38: Cochise | C38: D | D38: D-020412000 | E38: Elfrida | F38: E | G38: 1475013 | H38: 167.45 | I38: 8808.6772 | T38: 07 | U38: Maricopa | V38: C | W38: C-078766000 | X38: Benchmark | Y38: 87 | Z38: 154416 | AA38: 0 | AB38: 2387546 | AC38: 32157 | AD38: =SUM(Z38:AC38) -> 2574119 | AE38: 374.98 | AF38: 6864.6834
A39: 02 | B39: Cochise | C39: D | D39: D-020381000 | E39: Forrest | F39: E | G39: 0 | H39: 0 | I39: 0 | K39: Type Code Legend: | T39: 07 | U39: Maricopa | V39: C | W39: C-078754000 | X39: Benjamin Franklin | Y39: 87 | Z39: 203513 | AA39: 0 | AB39: 9985260 | AC39: 0 | AD39: =SUM(Z39:AC39) -> 10188773 | AE39: 1716.453 | AF39: 5935.9464
A40: 02 | B40: Cochise | C40: D | D40: D-020100000 | E40: Fort Huachuca | F40: A | G40: 14746472 | H40: 971.32 | I40: 15181.889 | T40: 07 | U40: Maricopa | V40: C | W40: C-078745000 | X40: Blueprint Ed | Y40: 87 | Z40: 9984 | AA40: 0 | AB40: 1222666 | AC40: 130196 | AD40: =SUM(Z40:AC40) -> 1362846 | AE40: 175.4 | AF40: 7769.9316
...

Sheet County Revenue Sources
A1: Traditional Public School District Revenue and Public Charter School Revenue By Source**
A2: Aggregated by County & State for Public School Districts & by Total State for Public Charter Schools
A3: 2006-2007 | T3: SAVE A COPY OF THIS FILE
A4: County | C4: Total | D4: Enroll- | F4: Federal | I4: State | L4: County/Intermediate* | O4: Local | T4: BEFORE YOU BEGIN TO SORT
A5: # | B5: Name | C5: Revenue | D5: ment | E5: $PP | F5: Amount | G5: % | H5: $PP | I5: Amount | J5: % | K5: $PP | L5: Amount | M5: % | N5: $PP | O5: Amount | P5: % | Q5: $PP
A6: A | B6: B | C6: C | D6: D | E6: E | F6: F | G6: G | H6: H | I6: I | J6: J | K6: K | L6: L | M6: M | N6: N | O6: O | P6: P | Q6: Q
A7: 0 | B7: ~Total-C | C7: 675226730 | D7: 88587 | E7: 7622.1876 | F7: 58677203 | G7: 0.0869 | H7: 662.3681 | I7: 5.6867595e+08 | J7: 0.8422 | K7: 6419.4064 | L7: 1215408.1 | M7: 0.0018 | N7: 13.719938 | O7: 46658167 | P7: 0.0691 | Q7: 526.69316 | S7: About Excel 2007 Tables
A8: 0 | B8: ~Total-D | C8: 8953120539 | D8: 935219 | E8: 9573.2877 | F8: 955251395 | G8: 0.1066948 | H8: 1021.42 | I8: 4365833746 | J8: 0.48763263 | K8: 4668.2475 | L8: 4074850 | M8: 0.00045513181 | N8: 4.3571078 | O8: 3627960548 | P8: 0.40521744 | Q8: 3879.2631 | T8: 1) Click the the arrow buttons in row 6 (purple) to sort.
A9: 01 | B9: Apache | C9: =F9+I9+L9+O9 -> 180814970 | D9: 12885 | E9: =$C9/D9 -> 14032.982 | F9: 77676166 | G9: =F9/$C9 -> 0.42958924 | H9: =F9/$D9 -> 6028.418 | I9: 78896695 | J9: =I9/$C9 -> 0.4363394 | K9: =I9/$D9 -> 6123.1428 | L9: 61698 | M9: =L9/$C9 -> 0.00034122175 | N9: =L9/$D9 -> 4.7883586 | O9: 24180411 | P9: =O9/$C9 -> 0.13373014 | Q9: =O9/$D9 -> 1876.6326 | T9: 2) Select a sort order to sort the list.
A10: 02 | B10: Cochise | C10: =F10+I10+L10+O10 -> 168974628 | D10: 18844 | E10: =$C10/D10 -> 8967.0255 | F10: 26240638 | G10: =F10/$C10 -> 0.15529336 | H10: =F10/$D10 -> 1392.5195 | I10: 95406241 | J10: =I10/$C10 -> 0.56461874 | K10: =I10/$D10 -> 5062.9506 | L10: 120996 | M10: =L10/$C10 -> 0.00071606016 | N10: =L10/$D10 -> 6.4209297 | O10: 47206753 | P10: =O10/$C10 -> 0.27937184 | Q10: =O10/$D10 -> 2505.1344 | T10: The last button used displays an up or down arrow.
A11: 03 | B11: Coconino | C11: =F11+I11+L11+O11 -> 187279341 | D11: 17937 | E11: =$C11/D11 -> 10440.951 | F11: 39779807 | G11: =F11/$C11 -> 0.21240894 | H11: =F11/$D11 -> 2217.7514 | I11: 71999887 | J11: =I11/$C11 -> 0.38445184 | K11: =I11/$D11 -> 4014.0429 | L11: 1121484 | M11: =L11/$C11 -> 0.0059882953 | N11: =L11/$D11 -> 62.523499 | O11: 74378163 | P11: =O11/$C11 -> 0.39715092 | Q11: =O11/$D11 -> 4146.6334 | T11: Always use buttons to sort (not Data | Sort).
A12: 04 | B12: Gila | C12: =F12+I12+L12+O12 -> 78430781 | D12: 7585 | E12: =$C12/D12 -> 10340.248 | F12: 16969152 | G12: =F12/$C12 -> 0.21635832 | H12: =F12/$D12 -> 2237.1987 | I12: 35924121 | J12: =I12/$C12 -> 0.458036 | K12: =I12/$D12 -> 4736.2058 | L12: 0 | M12: =L12/$C12 -> 0 | N12: =L12/$D12 -> 0 | O12: 25537508 | P12: =O12/$C12 -> 0.32560568 | Q12: =O12/$D12 -> 3366.8435 | T12: For lowest to highest revenue per pupil ($PP) by county:
A13: 05 | B13: Graham | C13: =F13+I13+L13+O13 -> 50375843 | D13: 5744 | E13: =$C13/D13 -> 8770.1677 | F13: 7804918 | G13: =F13/$C13 -> 0.15493374 | H13: =F13/$D13 -> 1358.7949 | I13: 33115297 | J13: =I13/$C13 -> 0.65736462 | K13: =I13/$D13 -> 5765.1979 | L13: 22392 | M13: =L13/$C13 -> 0.00044449877 | N13: =L13/$D13 -> 3.8983287 | O13: 9433236 | P13: =O13/$C13 -> 0.18725713 | Q13: =O13/$D13 -> 1642.2765 | T13: 1) Click the arrow button in cell E6.
A14: 06 | B14: Greenlee | C14: =F14+I14+L14+O14 -> 13872990 | D14: 1620 | E14: =$C14/D14 -> 8563.5741 | F14: 990720 | G14: =F14/$C14 -> 0.071413589 | H14: =F14/$D14 -> 611.55556 | I14: 4079074 | J14: =I14/$C14 -> 0.29402991 | K14: =I14/$D14 -> 2517.9469 | L14: 0 | M14: =L14/$C14 -> 0 | N14: =L14/$D14 -> 0 | O14: 8803196 | P14: =O14/$C14 -> 0.6345565 | Q14: =O14/$D14 -> 5434.0716 | T14: 2) Select "Sort Smallest to Largest"
A15: 15 | B15: La Paz | C15: =F15+I15+L15+O15 -> 27062698 | D15: 2514 | E15: =$C15/D15 -> 10764.796 | F15: 9104245 | G15: =F15/$C15 -> 0.33641306 | H15: =F15/$D15 -> 3621.4181 | I15: 11527455 | J15: =I15/$C15 -> 0.42595365 | K15: =I15/$D15 -> 4585.3043 | L15: 10287 | M15: =L15/$C15 -> 0.00038011731 | N15: =L15/$D15 -> 4.0918854 | O15: 6420711 | P15: =O15/$C15 -> 0.23725317 | Q15: =O15/$D15 -> 2553.9821 | T15: To return tor original sort order:
A16: 07 | B16: Maricopa | C16: =F16+I16+L16+O16 -> 5616885964 | D16: 587562 | E16: =$C16/D16 -> 9559.6481 | F16: 452851159 | G16: =F16/$C16 -> 0.080623171 | H16: =F16/$D16 -> 770.72915 | I16: 2615985743 | J16: =I16/$C16 -> 0.46573595 | K16: =I16/$D16 -> 4452.2718 | L16: 1465513 | M16: =L16/$C16 -> 0.00026091201 | N16: =L16/$D16 -> 2.494227 | O16: 2546583549 | P16: =O16/$C16 -> 0.45337996 | Q16: =O16/$D16 -> 4334.1529 | U16: Use button at B6 to sort A to Z.
A17: 08 | B17: Mohave | C17: =F17+I17+L17+O17 -> 179327654 | D17: 23158 | E17: =$C17/D17 -> 7743.659 | F17: 21858795 | G17: =F17/$C17 -> 0.12189305 | H17: =F17/$D17 -> 943.89822 | I17: 85494623 | J17: =I17/$C17 -> 0.47675091 | K17: =I17/$D17 -> 3691.7965 | L17: 488878 | M17: =L17/$C17 -> 0.0027261718 | N17: =L17/$D17 -> 21.110545 | O17: 71485358 | P17: =O17/$C17 -> 0.39862986 | Q17: =O17/$D17 -> 3086.8537
A18: 09 | B18: Navajo | C18: =F18+I18+L18+O18 -> 214837537 | D18: 20947 | E18: =$C18/D18 -> 10256.244 | F18: 62747791 | G18: =F18/$C18 -> 0.29207089 | H18: =F18/$D18 -> 2995.5502 | I18: 106962377 | J18: =I18/$C18 -> 0.49787564 | K18: =I18/$D18 -> 5106.3339 | L18: 162264 | M18: =L18/$C18 -> 0.00075528701 | N18: =L18/$D18 -> 7.7464076 | O18: 44965105 | P18: =O18/$C18 -> 0.20929818 | Q18: =O18/$D18 -> 2146.6131
A19: 10 | B19: Pima | C19: =F19+I19+L19+O19 -> 1205478547 | D19: 127936 | E19: =$C19/D19 -> 9422.5124 | F19: 124072911 | G19: =F19/$C19 -> 0.1029242 | H19: =F19/$D19 -> 969.80452 | I19: 619064850 | J19: =I19/$C19 -> 0.51354282 | K19: =I19/$D19 -> 4838.8636 | L19: 310694 | M19: =L19/$C19 -> 0.00025773499 | N19: =L19/$D19 -> 2.4285111 | O19: 462030092 | P19: =O19/$C19 -> 0.38327525 | Q19: =O19/$D19 -> 3611.4158
A20: 11 | B20: Pinal | C20: =F20+I20+L20+O20 -> 437783091 | D20: 40439 | E20: =$C20/D20 -> 10825.765 | F20: 36208180 | G20: =F20/$C20 -> 0.082708037 | H20: =F20/$D20 -> 895.37773 | I20: 270879276 | J20: =I20/$C20 -> 0.61875226 | K20: =I20/$D20 -> 6698.4662 | L20: 154352 | M20: =L20/$C20 -> 0.00035257643 | N20: =L20/$D20 -> 3.8169094 | O20: 130541283 | P20: =O20/$C20 -> 0.29818713 | Q20: =O20/$D20 -> 3228.1036
A21: 12 | B21: Santa Cruz | C21: =F21+I21+L21+O21 -> 89180580 | D21: 9976 | E21: =$C21/D21 -> 8939.5128 | F21: 12160176 | G21: =F21/$C21 -> 0.13635453 | H21: =F21/$D21 -> 1218.9431 | I21: 50186210 | J21: =I21/$C21 -> 0.56274819 | K21: =I21/$D21 -> 5030.6947 | L21: 40682 | M21: =L21/$C21 -> 0.00045617555 | N21: =L21/$D21 -> 4.0779872 | O21: 26793512 | P21: =O21/$C21 -> 0.30044111 | Q21: =O21/$D21 -> 2685.7971
A22: 13 | B22: Yavapai | C22: =F22+I22+L22+O22 -> 192793187 | D22: 23707 | E22: =$C22/D22 -> 8132.3317 | F22: 16917820 | G22: =F22/$C22 -> 0.08775113 | H22: =F22/$D22 -> 713.62129 | I22: 86553264 | J22: =I22/$C22 -> 0.44894358 | K22: =I22/$D22 -> 3650.9581 | L22: 19126 | M22: =L22/$C22 -> 9.920475e-05 | N22: =L22/$D22 -> 0.80676593 | O22: 89302977 | P22: =O22/$C22 -> 0.46320608 | Q22: =O22/$D22 -> 3766.9455
A23: 14 | B23: Yuma | C23: =F23+I23+L23+O23 -> 310022728 | D23: 34365 | E23: =$C23/D23 -> 9021.4674 | F23: 49868917 | G23: =F23/$C23 -> 0.16085568 | H23: =F23/$D23 -> 1451.1543 | I23: 199758633 | J23: =I23/$C23 -> 0.64433545 | K23: =I23/$D23 -> 5812.8512 | L23: 96484 | M23: =L23/$C23 -> 0.00031121589 | N23: =L23/$D23 -> 2.807624 | O23: 60298694 | P23: =O23/$C23 -> 0.19449766 | Q23: =O23/$D23 -> 1754.6543
A24: * For traditional school districts these amounts represent "County" revenues (with zero Intermediate revenue dollars); for public charter schools these amounts represent "Intermediate" revenues (with zero County revenue dollars).
A25: $PP = Dollars Per Pupil | S25: Highlighting Legend:
A26: DATA SOURCE: Annual Report of the Arizona Superintendent of Public Instruction; Volume II, Fiscal Year 2006-2007. | T26: Purple = Drop-down arrow buttons.
A27: DATA PRESENTATION: By EduAnalytics, LLC; November, 2008. | T27: Yellow = Total for 337 state-sponsored public
A28: ~Total-C = The total of 337 state-sponsored public charter schools (Yellow Highlight). | U28: charter schools.
A29: ~Total-D = The total of all public school districts (Green Highlight). | T29: Green = Total for all public school districts.
A30: ** Includes 337 state-sponsored public charter schools.

Sheet County Valuations & Other
A1: Revenues, Special Program Expenditures, & Tax Metrics by Public School Districts & Public Charter Schools**
A2: Aggregated by County & State for Public School Districts & by Total State for Public Charter Schools
A3: 2006-2007 | S3: SAVE A COPY OF THIS FILE
A4: County | C4: Total | D4: Enroll- | F4: Special Prog. Expenditures | I4: F&RL | J4: Primary Tax | M4: Secondary Tax | S4: BEFORE YOU BEGIN TO SORT
A5: # | B5: Name | C5: Revenue | D5: ment | E5: $PP | F5: Amount | G5: % Rev | H5: $PP | I5: %* | J5: Rates | K5: Valuation | L5: v$PP | M5: Rates | N5: Valuation | O5: v$PP | P5: SRP
A6: A | B6: B | C6: C | D6: D | E6: E | F6: F | G6: G | H6: H | I6: I | J6: J | K6: K | L6: L | M6: M | N6: N | O6: O | P6: P
A7: 0 | B7: ~Total-C | C7: 675226730 | D7: 88587 | E7: 7622.1876 | F7: 21322550 | G7: =F7/$C7 -> 0.031578356 | H7: =F7/$D7 -> 240.69615 | I7: 0.71 | J7: N/A | K7: N/A | L7: N/A | M7: N/A | N7: N/A | O7: N/A | P7: N/A | R7: About Excel 2007 Tables
A8: 0 | B8: ~Total-D | C8: 8953120539 | D8: 935219 | E8: 9573.2877 | F8: 830546708 | G8: 0.092766171 | H8: 888.07724 | I8: 0.51 | J8: 3.3472 | K8: 97703636366 | L8: =K8/D8 -> 104471.4 | M8: 1.0029 | N8: 68138541654 | O8: =N8/D8 -> 72858.38 | P8: 1577237503 | S8: 1) Click the the arrow buttons in row 6 (purple) to sort.
A9: 01 | B9: Apache | C9: 180814970 | D9: 12885 | E9: =$C9/D9 -> 14032.982 | F9: 12222014 | G9: =F9/$C9 -> 0.067594038 | H9: =F9/$D9 -> 948.54591 | I9: 0.76 | J9: 1.7785 | K9: 316510258 | L9: =K9/D9 -> 24564.242 | M9: 0.324 | N9: 323062906 | O9: =N9/D9 -> 25072.791 | P9: 96920585 | S9: 2) Select a sort order to sort the list.
A10: 02 | B10: Cochise | C10: 168974628 | D10: 18844 | E10: =$C10/D10 -> 8967.0255 | F10: 15983209 | G10: =F10/$C10 -> 0.094589402 | H10: =F10/$D10 -> 848.18558 | I10: 0.53 | J10: 4.3933 | K10: 1058250292 | L10: =K10/D10 -> 56158.474 | M10: 0.5179 | N10: 481706105 | O10: =N10/D10 -> 25562.837 | P10: 0 | S10: The last button used displays an up or down arrow.
A11: 03 | B11: Coconino | C11: 187279341 | D11: 17937 | E11: =$C11/D11 -> 10440.951 | F11: 16121806 | G11: =F11/$C11 -> 0.086084273 | H11: =F11/$D11 -> 898.80169 | I11: 0.52 | J11: 2.1987 | K11: 2487006890 | L11: =K11/D11 -> 138652.33 | M11: 1.3394 | N11: 1313169139 | O11: =N11/D11 -> 73210.076 | P11: 64250389 | S11: Always use buttons to sort (not Data | Sort).
A12: 04 | B12: Gila | C12: 78430781 | D12: 7585 | E12: =$C12/D12 -> 10340.248 | F12: 5668384 | G12: =F12/$C12 -> 0.072272441 | H12: =F12/$D12 -> 747.31496 | I12: 0.59 | J12: 4.0733 | K12: 412254721 | L12: =K12/D12 -> 54351.315 | M12: 0.5917 | N12: 422267703 | O12: =N12/D12 -> 55671.418 | P12: 4552243 | S12: For lowest to highest revenue per pupil ($PP) by county:
A13: 05 | B13: Graham | C13: 50375843 | D13: 5744 | E13: =$C13/D13 -> 8770.1677 | F13: 3835905 | G13: =F13/$C13 -> 0.076145723 | H13: =F13/$D13 -> 667.81076 | I13: 0.54 | J13: 2.8143 | K13: 231877607 | L13: =K13/D13 -> 40368.664 | M13: 0.5419 | N13: 119712036 | O13: =N13/D13 -> 20841.232 | P13: 0 | S13: 1) Click the arrow button in cell E6.
A14: 06 | B14: Greenlee | C14: 13872990 | D14: 1620 | E14: =$C14/D14 -> 8563.5741 | F14: 663995 | G14: =F14/$C14 -> 0.047862429 | H14: =F14/$D14 -> 409.87346 | I14: 0.32 | J14: 2.9344 | K14: 226709610 | L14: =K14/D14 -> 139944.2 | M14: 1.0906 | N14: 226907616 | O14: =N14/D14 -> 140066.43 | P14: 0 | S14: 2) Select "Sort Smallest to Largest"
A15: 15 | B15: La Paz | C15: 27062698 | D15: 2514 | E15: =$C15/D15 -> 10764.796 | F15: 2032601 | G15: =F15/$C15 -> 0.075107109 | H15: =F15/$D15 -> 808.51273 | I15: 0.73 | J15: 3.4066 | K15: 242972908 | L15: =K15/D15 -> 96647.935 | M15: 0.3623 | N15: 262162688 | O15: =N15/D15 -> 104281.1 | P15: 22844 | S15: To return tor original sort order:
A16: 07 | B16: Maricopa | C16: 5616885964 | D16: 587562 | E16: =$C16/D16 -> 9559.6481 | F16: 551193121 | G16: =F16/$C16 -> 0.098131442 | H16: =F16/$D16 -> 938.10206 | I16: 0.47 | J16: 3.4581 | K16: 73908685462 | L16: =K16/D16 -> 125788.74 | M16: 1.5597 | N16: 48596875163 | O16: =N16/D16 -> 82709.357 | P16: 1179789391 | T16: Use button at B6 to sort A to Z.
A17: 08 | B17: Mohave | C17: 179327654 | D17: 23158 | E17: =$C17/D17 -> 7743.659 | F17: 13405112 | G17: =F17/$C17 -> 0.074752063 | H17: =F17/$D17 -> 578.85448 | I17: 0.54 | J17: 3.3332 | K17: 2070249481 | L17: =K17/D17 -> 89396.73 | M17: 0.737 | N17: 2427944665 | O17: =N17/D17 -> 104842.59 | P17: 934488
A18: 09 | B18: Navajo | C18: 214837537 | D18: 20947 | E18: =$C18/D18 -> 10256.244 | F18: 20970400 | G18: =F18/$C18 -> 0.097610503 | H18: =F18/$D18 -> 1001.1171 | I18: 0.64 | J18: 1.7753 | K18: 2017524373 | L18: =K18/D18 -> 96315.672 | M18: 1.3906 | N18: 753947031 | O18: =N18/D18 -> 35993.079 | P18: 99333204
A19: 10 | B19: Pima | C19: 1205478547 | D19: 127936 | E19: =$C19/D19 -> 9422.5124 | F19: 110854999 | G19: =F19/$C19 -> 0.09195933 | H19: =F19/$D19 -> 866.48792 | I19: 0.54 | J19: 4.096 | K19: 6457831337 | L19: =K19/D19 -> 50477.046 | M19: 1.2892 | N19: 6858304185 | O19: =N19/D19 -> 53607.305 | P19: 0
A20: 11 | B20: Pinal | C20: 437783091 | D20: 40439 | E20: =$C20/D20 -> 10825.765 | F20: 32725880 | G20: =F20/$C20 -> 0.074753641 | H20: =F20/$D20 -> 809.26531 | I20: 0.51 | J20: 3.2501 | K20: 2879274131 | L20: =K20/D20 -> 71200.429 | M20: 1.3179 | N20: 2016929870 | O20: =N20/D20 -> 49875.859 | P20: 130324799
A21: 12 | B21: Santa Cruz | C21: 89180580 | D21: 9976 | E21: =$C21/D21 -> 8939.5128 | F21: 6734141 | G21: =F21/$C21 -> 0.075511294 | H21: =F21/$D21 -> 675.03418 | I21: 0.73 | J21: 4.4039 | K21: 313107669 | L21: =K21/D21 -> 31386.094 | M21: 0.6747 | N21: 330896085 | O21: =N21/D21 -> 33169.215 | P21: 0 | R21: Highlighting Legend:
A22: 13 | B22: Yavapai | C22: 192793187 | D22: 23707 | E22: =$C22/D22 -> 8132.3317 | F22: 17427946 | G22: =F22/$C22 -> 0.090397105 | H22: =F22/$D22 -> 735.13924 | I22: 0.47 | J22: 3.5565 | K22: 3438516696 | L22: =K22/D22 -> 145042.25 | M22: 0.3018 | N22: 2169966384 | O22: =N22/D22 -> 91532.728 | P22: 1109560 | S22: Purple = Drop-down arrow buttons.
A23: 14 | B23: Yuma | C23: 310022728 | D23: 34365 | E23: =$C23/D23 -> 9021.4674 | F23: 20707195 | G23: =F23/$C23 -> 0.066792506 | H23: =F23/$D23 -> 602.56642 | I23: 0.72 | J23: 2.8466 | K23: 1642864931 | L23: =K23/D23 -> 47806.342 | M23: 1.0706 | N23: 1834663078 | O23: =N23/D23 -> 53387.548 | P23: 0 | S23: Yellow = Total for 337 state-sponsored public
A24: * Percentage of Free & Reduced Price Lunch Eligibility at March 2007 for public school districts; as of 2008 for public charter schools. | T24: charter schools.
A25: $PP = dollars per pupil. | S25: Green = Total for all public school districts.
A26: v$PP = Valuation on a per pupil basis.
A27: DATA SOURCE: Annual Report of the Arizona Superintendent of Public Instruction; Volume II, Fiscal Year 2006-2007.
A28: DATA PRESENTATION: By EduAnalytics, LLC; November, 2008.
A29: ~Total-C = The total of 337 state-sponsored public charter schools (Yellow Highlight).
A30: ~Total-D = The total of all public school districts (Green Highlight).
A31: ** Includes 337 state-sponsored public charter schools.
