Workbook

Sheet     INSTRUCTIONS    
A1: Annual Finance Report Instructions
A3: We have created an electronic form of the Annual Finance Report to make it easier and quicker
A4: for you to file this report with GSMISTS.
A6: We are requesting that you send it via email, but faxed and mailed copies are acceptable.
A10: 1. | B10: On each of the TABS, please fill in the information for the YELLOW highlights only
B11: (yellow highlighted areas). Do not input any information in the GREEN highlights
B12: because these cell auto-fill from information already entered.
A14: 2. | B14: New this year, please attach 12 months of current bank statement to the report.
A16: 3. | B16: In the upper right hand of the Finance Report page (TAB), click on the picture and
B17: this will create an email; attach a saved copy of the file to this email and send
B18: it to MVP@gsmists.org.

Sheet    Finance Report   
B1: Finance Report | X1: Click to Submit & Attach File
U3: Reason for report
V4: End of Year
V5: Chang e in Leadership
V6: Group Divided
V7: Group Disbanded
B10: The Annual Finance Report is required to be completed for each group and submitted to a Girl Scout Service Center by
B11: June 1 of each year. Please attach a copy of the Detailed Cash Report & 12 months ofcurrent bank statement to this report.
B13: For the year ending: | D13: May 31, | J13: Group # | R13: INCOME AND EXPENSES
B15: Service Unit name: | R15: Beginning Balance | Z15: =+'Detailed Cash Report'!U9 -> 0
R16: (Previous year’s ending balance)
B17: Level (check one) | D17: D | F17: B | H17: J | J17: C | L17: S | N17: A
R18: Total Income | Z18: =+'Detailed Cash Report'!I64 -> 0
B19: Leader/Advisor name:
B21: E-mail: | R21: Subtotal | Z21: =+Z15+Z18 -> 0
B23: Phone: | C23: Home | I23: Cell | R23: Less:
B25: Address: | R25: Total Expenses | Z25: =+'Detailed Cash Report'!S64 -> 0
B27: City: | K27: ZIP
R28: TOTAL BALANCE | Z28: =IF(('Detailed Cash Report'!U62)=(Z21-Z25),Z21-Z25,FALSE) -> 0
B30: Financial Institution: | R30: As of: | Y30: _ _ / _ _ / _ _
B32: Account # | R32: Amount to be used
R33: during summer months
B34: Authorized Signatures: | R34: Used for:
C35: 1.
R36: Person completing this report:
C37: 2.
R38: Name | W38: =+'Detailed Cash Report'!Q1 -> 0
C39: 3.
R40: Phone
B42: Please list any equipment (flags, books, camping gear, supplies, | R42: E-mail
B43: etc.) and the name and address where the equipment is stored:
R44: Signature | W44: Date

Sheet Detailed Cash Report
A1: GIRL SCOUTS OF MICHIGAN SHORE TO SHORE | G1: TROOP # | P1: PREPARED BY:
G3: FOR THE YEAR | J3: -
E5: INCOME | K5: EXPENSES
B6: Date | C6: Activity / Description | E6: Dues | F6: Fall Product / Cookie Sales | G6: Other Funds / Sponsorship | I6: TOTAL INCOME | K6: Program Events | L6: Product Sales Sweep/ Square Fees | M6: Badges & Pin Awards | N6: Supplies | O6: Service Projects | P6: Trips & Fees | Q6: Copies / Postage | S6: TOTAL EXPENSES | U6: Running Balance
C9: Beginning Balance
A11: 1 | I11: =SUM(E11:G11) -> 0 | S11: =SUM(K11:Q11) -> 0 | U11: =+U9+I11-S11 -> 0
A12: 2 | I12: =SUM(E12:G12) -> 0 | S12: =SUM(K12:Q12) -> 0 | U12: =+U11+I12-S12 -> 0
A13: 3 | I13: =SUM(E13:G13) -> 0 | S13: =SUM(K13:Q13) -> 0 | U13: =+U12+I13-S13 -> 0
A14: 4 | I14: =SUM(E14:G14) -> 0 | S14: =SUM(K14:Q14) -> 0 | U14: =+U13+I14-S14 -> 0
A15: 5 | I15: =SUM(E15:G15) -> 0 | S15: =SUM(K15:Q15) -> 0 | U15: =+U14+I15-S15 -> 0
A16: 6 | I16: =SUM(E16:G16) -> 0 | S16: =SUM(K16:Q16) -> 0 | U16: =+U15+I16-S16 -> 0
A17: 7 | I17: =SUM(E17:G17) -> 0 | S17: =SUM(K17:Q17) -> 0 | U17: =+U16+I17-S17 -> 0
A18: 8 | I18: =SUM(E18:G18) -> 0 | S18: =SUM(K18:Q18) -> 0 | U18: =+U17+I18-S18 -> 0
A19: 9 | I19: =SUM(E19:G19) -> 0 | S19: =SUM(K19:Q19) -> 0 | U19: =+U18+I19-S19 -> 0
A20: 10 | I20: =SUM(E20:G20) -> 0 | S20: =SUM(K20:Q20) -> 0 | U20: =+U19+I20-S20 -> 0
A21: 11 | I21: =SUM(E21:G21) -> 0 | S21: =SUM(K21:Q21) -> 0 | U21: =+U20+I21-S21 -> 0
A22: 12 | I22: =SUM(E22:G22) -> 0 | S22: =SUM(K22:Q22) -> 0 | U22: =+U21+I22-S22 -> 0
A23: 13 | I23: =SUM(E23:G23) -> 0 | S23: =SUM(K23:Q23) -> 0 | U23: =+U22+I23-S23 -> 0
... A50: 40 | I50: =SUM(E50:G50) -> 0 | S50: =SUM(K50:Q50) -> 0 | U50: =+U49+I50-S50 -> 0
A51: =+A50+1 -> 41 | I51: =SUM(E51:G51) -> 0 | S51: =SUM(K51:Q51) -> 0 | U51: =+U50+I51-S51 -> 0
A52: =+A51+1 -> 42 | I52: =SUM(E52:G52) -> 0 | S52: =SUM(K52:Q52) -> 0 | U52: =+U51+I52-S52 -> 0
A53: =+A52+1 -> 43 | I53: =SUM(E53:G53) -> 0 | S53: =SUM(K53:Q53) -> 0 | U53: =+U52+I53-S53 -> 0
A54: =+A53+1 -> 44 | I54: =SUM(E54:G54) -> 0 | S54: =SUM(K54:Q54) -> 0 | U54: =+U53+I54-S54 -> 0
A55: =+A54+1 -> 45 | I55: =SUM(E55:G55) -> 0 | S55: =SUM(K55:Q55) -> 0 | U55: =+U54+I55-S55 -> 0
A56: =+A55+1 -> 46 | I56: =SUM(E56:G56) -> 0 | S56: =SUM(K56:Q56) -> 0 | U56: =+U55+I56-S56 -> 0
A57: =+A56+1 -> 47 | I57: =SUM(E57:G57) -> 0 | S57: =SUM(K57:Q57) -> 0 | U57: =+U56+I57-S57 -> 0
A58: =+A57+1 -> 48 | I58: =SUM(E58:G58) -> 0 | S58: =SUM(K58:Q58) -> 0 | U58: =+U57+I58-S58 -> 0
A59: =+A58+1 -> 49 | I59: =SUM(E59:G59) -> 0 | S59: =SUM(K59:Q59) -> 0 | U59: =+U58+I59-S59 -> 0
A60: =+A59+1 -> 50 | I60: =SUM(E60:G60) -> 0 | S60: =SUM(K60:Q60) -> 0 | U60: =+U59+I60-S60 -> 0
A61: =+A60+1 -> 51 | I61: =SUM(E61:G61) -> 0 | S61: =SUM(K61:Q61) -> 0 | U61: =+U60+I61-S61 -> 0
A62: =+A61+1 -> 52 | I62: =SUM(E62:G62) -> 0 | S62: =SUM(K62:Q62) -> 0 | U62: =+U61+I62-S62 -> 0
C64: TOTALS | E64: =SUM(E9:E63) -> 0 | F64: =SUM(F9:F63) -> 0 | G64: =SUM(G9:G63) -> 0 | I64: =SUM(I9:I63) -> 0 | K64: =SUM(K9:K63) -> 0 | M64: =SUM(M9:M63) -> 0 | N64: =SUM(N9:N63) -> 0 | O64: =SUM(O9:O63) -> 0 | P64: =SUM(P9:P63) -> 0 | Q64: =SUM(Q9:Q63) -> 0 | R64: =SUM(R9:R63) -> 0 | S64: =SUM(S9:S63) -> 0 | U64: =IF((U9+I64-S64)=U62,U9+I64-S64,0) -> 0
C67: =+G1 -> TROOP # | E67: =+K1 -> 0
C69: YEAR ENDING | E69: =+N3 -> 0
C72: INCOME
C73: =+F6 -> Fall Product / Cookie Sales | F73: =+F64 -> 0 | G73: =+F73/F$77 -> #DIV/0!
C74: =+G6 -> Other Funds / Sponsorship | F74: =+G64 -> 0 | G74: =+F74/F$77 -> #DIV/0!
C77: TOTAL | F77: =+I64 -> 0 | G77: =+F77/F$77 -> #DIV/0!
C80: EXPENSES
C81: =+K6 -> Program Events | F81: =+K64 -> 0 | G81: =+F81/F$77 -> #DIV/0!
...

Sheet Copy bank statements here
A1: Please Attach (or cut & paste) your 12 months of bank activity here
