Workbook

Sheet GF Recon
B2: DSA | C2: FY 2010 | D2: FY 2011
B3: Adult Ed | C3: 2400000 | D3: 3600000
B4: IDEA MOE | C4: =7607573+1968 -> 7609541 | D4: =6526678+1968 -> 6528646
B5: Early Childhood Education | C5: -26109 | D5: -58191
B6: RPDP | C6: 7897804 | D6: =+C6 -> 7897804
C8: =SUM(C3:C7) -> 17881236 | D8: =SUM(D3:D7) -> 17968259
C18: GOV | D18: LEG | F18: GOV | G18: LEG | I18: BIENNIAL
C19: FY 2010 | D19: FY2010 | E19: DIFF | F19: FY 2011 | G19: FY 2011 | H19: DIFF | I19: TOTAL
B20: SLOT TAX | C20: 36173569 | D20: 35888197 | E20: =D20-C20 -> -285372.33 | F20: 36571479 | G20: 36554830 | H20: =G20-F20 -> -16648.589 | I20: =E20+H20 -> -302020.92
B21: PERM SCHOOL FUND | C21: 14631920 | D21: 13100000 | E21: =D21-C21 -> -1531920 | F21: 14924558 | G21: 13100000 | H21: =G21-F21 -> -1824558 | I21: =E21+H21 -> -3356478
B22: FEDERAL LEASE REVENUE | C22: 9198446 | D22: 10706000 | E22: =D22-C22 -> 1507554 | F22: 9474399 | G22: 10706000 | H22: =G22-F22 -> 1231601 | I22: =E22+H22 -> 2739155
B23: REAL PROPERTY TRANS TAX AB 458 | D23: 1000000 | E23: =D23-C23 -> 1000000 | F23: 0 | G23: 1000000 | H23: =G23-F23 -> 1000000 | I23: =E23+H23 -> 2000000
C25: =SUM(C20:C24) -> 60003935 | D25: =SUM(D20:D24) -> 60694197 | E25: =SUM(E20:E24) -> 690261.67 | F25: =SUM(F20:F24) -> 60970436 | G25: =SUM(G20:G24) -> 61360830 | H25: =SUM(H20:H24) -> 390394.41 | I25: =SUM(I20:I24) -> 1080656.1

Sheet DSA
A1: State of Nevada
A2: Distributive School Account
A3: Fiscal Years 2010 Through 2013
H4: Legislature Approved Plus
B5: Legislature Approved | F5: Actual | H5: 26th Special Session Adjustments | L5: Governor Recommends | P5: Biennium | R5: Biennium
B6: FY 2008 | D6: FY 2009 | F6: FY 2009 | H6: FY 2010 | J6: FY 2011 | L6: FY 2012 | N6: FY 2013 | P6: Total | R6: Change
A7: Revenues and Appropriations
A8: General Fund Appropriations | B8: 1041362589 | D8: 1090795262 | F8: 1137402312 | H8: =1173542690+69080821-18917900-42371-33893 -> 1223629347 | J8: =1154625174-69080821+33893+139533874 -> 1225112120 | L8: =DSASUMM!AI130 -> 1.0882807e+09 | N8: =DSASUMM!AK130 -> 1.1113311e+09 | P8: =SUM(L8:N8) -> 2.1996118e+09 | R8: =P8-SUM(H8:J8) -> -2.4912964e+08
A10: Federal Education Stabilization Fund | B10: 0 | D10: 0 | F10: 139626106 | H10: 0 | J10: 0 | L10: 0 | N10: 0 | P10: =SUM(L10:N10) -> 0 | R10: =P10-SUM(H10:J10) -> 0
A12: State Guaranteed Revenues
A13: Local School Support Tax | B13: 1021135885 | D13: 1108717188 | H13: 872948748 | J13: 888433910 | L13: =-DSASUMM!AI121 -> 9.4173479e+08 | N13: =-DSASUMM!AK121 -> 9.6998665e+08 | P13: =SUM(L13:N13) -> 1.9117214e+09 | R13: =P13-SUM(H13:J13) -> 1.5033878e+08
A14: Local School Support Tax Rate Sunset | H14: 0 | J14: 0 | P14: =SUM(L14:N14) -> 0 | R14: =P14-SUM(H14:J14) -> 0
A15: Public School Operating Property Tax (1/3) | B15: 258661179 | D15: 290268708 | H15: 262851182 | J15: 212922114 | L15: =-DSASUMM!AI122 -> 202433266 | N15: =-DSASUMM!AK122 -> 202931773 | P15: =SUM(L15:N15) -> 405365039 | R15: =P15-SUM(H15:J15) -> -70408257
A16: School District Debt Service Excess Reserves | H16: 0 | J16: 0 | L16: =-DSASUMM!AI123 -> 0 | N16: =-DSASUMM!AK123 -> 0 | P16: =SUM(L16:N16) -> 0 | R16: =P16-SUM(H16:J16) -> 0
A17: Clark County School District Capital Construction Funds | B17: 0 | D17: 0 | H17: 10000000 | J17: 10000000 | L17: =-DSASUMM!AI124 -> 20000000 | N17: =-DSASUMM!AK124 -> 20000000 | P17: =SUM(L17:N17) -> 40000000 | R17: =P17-SUM(H17:J17) -> 20000000
A18: Transfer from closure of CC RDA | B18: 0 | D18: 0 | H18: 6000000 | J18: 5400000 | L18: 0 | N18: 0 | P18: =SUM(L18:N18) -> 0 | R18: =P18-SUM(H18:J18) -> -11400000
A19: 26th Special Session - CCSD Capital Construction Funds | H19: 0 | J19: 25000000 | L19: 0 | N19: 0 | P19: =SUM(L19:N19) -> 0 | R19: =P19-SUM(H19:J19) -> -25000000
A21: Total State Guaranteed Revenues | B21: =SUM(B13:B20) -> 1279797064 | D21: =SUM(D13:D20) -> 1398985896 | F21: =SUM(F13:F20) -> 0 | H21: =SUM(H13:H20) -> 1151799930 | J21: =SUM(J13:J20) -> 1141756024 | L21: =SUM(L13:L20) -> 1.1641681e+09 | N21: =SUM(N13:N20) -> 1.1929184e+09 | P21: =SUM(P13:P20) -> 2.3570865e+09 | R21: =SUM(R13:R20) -> 63530526
A23: Dedicated State Revenues
A24: DSA Share of Slot Tax | B24: 37682635 | D24: 40294194 | F24: 34617391 | H24: 33712074 | J24: 33359606 | L24: =DSASUMM!AI133 -> 33542238 | N24: =DSASUMM!AK133 -> 34144068 | P24: =SUM(L24:N24) -> 67686306 | R24: =P24-SUM(H24:J24) -> 614626
A25: Permanent School Fund | B25: 11800136 | D25: 12315982 | F25: 13118714 | H25: 9173420 | J25: 8000000 | L25: =DSASUMM!AI134 -> 6600000 | N25: =DSASUMM!AK134 -> 6800000 | P25: =SUM(L25:N25) -> 13400000 | R25: =P25-SUM(H25:J25) -> -3773420
A26: Federal Mineral Lease Revenue | B26: 6354164 | D26: 6354164 | F26: 21609333 | H26: 8116846 | J26: 8000000 | L26: =DSASUMM!G135 -> 8000000 | N26: =DSASUMM!H135 -> 8000000 | P26: =SUM(L26:N26) -> 16000000 | R26: =P26-SUM(H26:J26) -> -116846
A27: Out of State Local School Support Tax | B27: 116384350 | D27: 123716564 | F27: 93575531 | H27: 86190829 | J27: 87867090 | L27: =DSASUMM!AI136 -> 93138606 | N27: =DSASUMM!AK136 -> 95932745 | P27: =SUM(L27:N27) -> 1.8907135e+08 | R27: =P27-SUM(H27:J27) -> 15013432
A28: Out of State Local School Support Tax Sunset | H28: 0 | J28: 0 | P28: =SUM(L28:N28) -> 0 | R28: =P28-SUM(H28:J28) -> 0
A29: Estate Tax | B29: 100 | D29: 100 | F29: 16.32 | H29: 0 | J29: 0 | P29: =SUM(L29:N29) -> 0 | R29: =P29-SUM(H29:J29) -> 0
A30: Prior Year Refunds | B30: 0 | D30: 0 | F30: 35787.86 | H30: 816539 | J30: 0 | L30: 0 | N30: 0 | P30: =SUM(L30:N30) -> 0 | R30: =P30-SUM(H30:J30) -> -816539
A31: Real Property Tax - Sec. 36 of AB 458 | B31: 0 | D31: 0 | F31: 0 | H31: 0 | J31: 0 | L31: 0 | N31: 0 | P31: =SUM(L31:N31) -> 0 | R31: =P31-SUM(H31:J31) -> 0
A32: Other | H32: 0 | P32: =SUM(L32:N32) -> 0 | R32: =P32-SUM(H32:J32) -> 0
A34: Total Dedicated State Revenues | B34: =SUM(B24:B33) -> 172221385 | D34: =SUM(D24:D33) -> 182681004 | F34: =SUM(F24:F33) -> 1.6295677e+08 | H34: =SUM(H24:H33) -> 138009708 | J34: =SUM(J24:J33) -> 137226696 | L34: =SUM(L24:L33) -> 1.4128084e+08 | N34: =SUM(N24:N33) -> 1.4487681e+08 | P34: =SUM(P24:P33) -> 2.8615766e+08 | R34: =SUM(R24:R33) -> 10921253
A36: Local Revenues
A37: Federal Revenue | B37: 5837244 | D37: 5837244 | H37: 8499450 | J37: 7863361 | L37: =-DSASUMM!AI73 -> 8499450 | N37: =-DSASUMM!AK73 -> 8499450 | P37: =SUM(L37:N37) -> 16998900 | R37: =P37-SUM(H37:J37) -> 636089
A38: Other Local Revenue | B38: 52643811 | D38: 52643811 | H38: 80820145 | J38: 94520861 | L38: =-DSASUMM!AI74 -> 80820145 | N38: =-DSASUMM!AK74 -> 80820145 | P38: =SUM(L38:N38) -> 161640290 | R38: =P38-SUM(H38:J38) -> -13700716
A39: Public School Operating Property Tax (2/3) | B39: 517322359 | D39: 580537415 | H39: 525702505 | J39: 425844229 | L39: =-DSASUMM!AI75 -> 404866532 | N39: =-DSASUMM!AK75 -> 405863545 | P39: =SUM(L39:N39) -> 810730077 | R39: =P39-SUM(H39:J39) -> -140816657
A40: Government Services Tax | B40: 98664516 | D40: 102591364 | H40: 75725120 | J40: 81402633 | L40: =-DSASUMM!AI76 -> 72381781 | N40: =-DSASUMM!AK76 -> 72381781 | P40: =SUM(L40:N40) -> 144763562 | R40: =P40-SUM(H40:J40) -> -12364191
A41: Franchise Tax | B41: 2940945 | D41: 3029173 | H41: 3451000 | J41: 4236760 | L41: =-DSASUMM!AI77 -> 3661166 | N41: =-DSASUMM!AK77 -> 3771001 | P41: =SUM(L41:N41) -> 7432167 | R41: =P41-SUM(H41:J41) -> -255593
A42: Obligations | B42: 2748725 | D42: 2748725 | H42: 710310 | J42: 49497203 | L42: 0 | N42: 0 | P42: =SUM(L42:N42) -> 0 | R42: =P42-SUM(H42:J42) -> -50207513
A43: Other State Support | B43: 210381 | D43: 210381 | H43: =76582+931314 -> 1007896 | J43: 879943 | L43: =-DSASUMM!AI85 -> 931314 | N43: =-DSASUMM!AK85 -> 931314 | P43: =SUM(L43:N43) -> 1862628 | R43: =P43-SUM(H43:J43) -> -25211
A44: School District Fund Balance | B44: 0 | D44: 0 | H44: 26897029 | J44: 92308915 | L44: 0 | N44: 0 | P44: =SUM(L44:N44) -> 0 | R44: =P44-SUM(H44:J44) -> -119205944
A46: Total Local Revenues | B46: =SUM(B37:B45) -> 680367981 | D46: =SUM(D37:D45) -> 747598113 | F46: =SUM(F37:F45) -> 0 | H46: =SUM(H37:H45) -> 722813455 | J46: =SUM(J37:J45) -> 756553905 | L46: =SUM(L37:L45) -> 571160388 | N46: =SUM(N37:N45) -> 572267236 | P46: =SUM(P37:P45) -> 1143427624 | R46: =SUM(R37:R45) -> -335939736
A48: Total Revenues and Appropriations | B48: =B8+B10+B21+B34+B46 -> 3173749019 | D48: =D8+D10+D21+D34+D46 -> 3420060275 | F48: =F8+F10+F21+F34+F46 -> 1.4399852e+09 | H48: =H8+H10+H21+H34+H46 -> 3236252440 | J48: =J8+J10+J21+J34+J46 -> 3260648745 | L48: =L8+L10+L21+L34+L46 -> 2.96489e+09 | N48: =N8+N10+N21+N34+N46 -> 3.0213936e+09 | P48: =P8+P10+P21+P34+P46 -> 5.9862836e+09 | R48: =R8+R10+R21+R34+R46 -> -5.106176e+08
...

Sheet DSABUDGET
B1: DISTRIBUTIVE SCHOOL ACCOUNT - SUMMARY FOR 2011-13 BIENNIUM
C2: 2010 | E2: 2011 | H2: 2012 | J2: 2013
C3: 26th Special | D3: 2010 | E3: 26th Special | F3: 2011 | H3: Legislature | J3: Legislature
C4: Session | D4: Actual | E4: Session | F4: Estimated | H4: Approved | J4: Approved
A5: WEIGHTED ENROLLMENT | C5: 425648.4 | D5: 421386.6 | E5: 429706.6 | F5: =DSADATABASE!B4 -> 422569.6 | H5: =+DSASUMM!AI97 -> 421987.1 | J5: =+DSASUMM!AK97 -> 423499.6
B6: ADDITIONAL ENROLLMENT FOR HOLD HARMLESS | C6: 0 | D6: 4140.6 | E6: 0 | F6: 1367.2 | H6: 0 | J6: 0
A7: TOTAL ENROLLMENT * | C7: =SUM(C5:C6) -> 425648.4 | D7: =SUM(D5:D6) -> 425527.2 | E7: =SUM(E5:E6) -> 429706.6 | F7: =SUM(F5:F6) -> 423936.8 | H7: =SUM(H5:H6) -> 421987.1 | J7: =SUM(J5:J6) -> 423499.6
A8: BASIC SUPPORT | C8: =C9/C7 -> 5186.3621 | D8: =D9/D7 -> 5185.6039 | E8: 5192 | F8: =F9/F7 -> 5192.2041 | H8: =ROUND(H9/H7,0) -> 5263 | J8: =ROUND(J9/J7,0) -> 5374
A9: TOTAL REGULAR BASIC SUPPORT ** | C9: =DSASUMM!B95 -> 2207566730 | D9: =DSASUMM!C95 -> 2206615525 | E9: 2230973023 | F9: 2201166405 | H9: =DSASUMM!AI95 -> 2.2209496e+09 | J9: =DSASUMM!AK95 -> 2.2759271e+09
A11: CATEGORICAL FUNDING:
B12: SPECIAL EDUCATION *** | C12: =DSASUMM!B102 -> 121252632 | D12: =DSASUMM!C102 -> 121252632 | E12: =DSASUMM!E102 -> 121252632 | F12: =DSASUMM!E102 -> 121252632 | H12: =DSASUMM!AI102 -> 121252632 | J12: =DSASUMM!AK102 -> 121252632
B13: CLASS-SIZE REDUCTION | C13: =DSASUMM!B101 -> 142682929 | D13: =DSASUMM!C101 -> 142682930 | E13: =DSASUMM!E101 -> 144348993 | F13: =DSASUMM!E101 -> 144348993 | H13: =DSASUMM!AI101-1 -> 1.3921345e+08 | J13: =DSASUMM!AK101 -> 1.4263961e+08
B14: CLASS-SIZE REDUCTION - AT-RISK KINDERGARTEN | C14: =DSASUMM!B116 -> 1580391 | D14: =DSASUMM!C116 -> 1580390 | E14: =DSASUMM!E116 -> 1586508 | F14: =DSASUMM!E116 -> 1586508 | H14: =DSASUMM!AI116+1 -> 1554599 | J14: =DSASUMM!AK116 -> 1582409.4
B15: SPECIAL UNITS/GIFTED & TALENTED | C15: =DSASUMM!B103 -> 162571 | D15: =DSASUMM!C103 -> 162566 | E15: =DSASUMM!E103 -> 167459 | F15: =DSASUMM!E103 -> 167459 | H15: =DSASUMM!AI103 -> 158414 | J15: =DSASUMM!AK103 -> 162163
B16: ADULT HIGH SCHOOL DIPLOMA | C16: =DSASUMM!B104 -> 21170456 | D16: =DSASUMM!C104 -> 21170456 | E16: =DSASUMM!E104 -> 22673833 | F16: =DSASUMM!E104 -> 22673833 | H16: =DSASUMM!AI104 -> 17011957 | J16: =DSASUMM!AK104 -> 17758916
B17: SCHOOL LUNCH PROGRAM STATE MATCH | C17: =DSASUMM!B105 -> 588732 | D17: =DSASUMM!C105 -> 588732 | E17: =DSASUMM!E105 -> 588732 | F17: =DSASUMM!E105 -> 588732 | H17: =DSASUMM!AI105 -> 588732 | J17: =DSASUMM!AK105 -> 588732
B18: RPDP - TRANSFER TO REMEDIATION TRUST FUND | C18: =DSASUMM!B109 -> 7897804 | D18: =DSASUMM!C109 -> 7897804 | E18: =DSASUMM!E109 -> 7897804 | F18: =DSASUMM!E109 -> 7897804 | H18: =DSASUMM!AI109 -> 0 | J18: =DSASUMM!AK109 -> 0
B19: EARLY CHILDHOOD EDUCATION | C19: =DSASUMM!B111 -> 3338875 | D19: =DSASUMM!C111 -> 3304982 | E19: 3338875 | F19: =DSASUMM!E111 -> 3372768 | H19: =DSASUMM!AI111 -> 3338875 | J19: =DSASUMM!AK111 -> 3338875
B20: LIBRARY MEDIA SPECIALIST | C20: =DSASUMM!B112 -> 18798 | D20: =DSASUMM!C112 -> 18798 | E20: =DSASUMM!E112 -> 18798 | F20: =DSASUMM!E112 -> 18798 | H20: =DSASUMM!AI112 -> 18798 | J20: =DSASUMM!AK112 -> 18798
B21: SPECIAL ELEMENTARY COUNSELING | C21: =DSASUMM!B115 -> 850000 | D21: =DSASUMM!C115 -> 850000 | E21: =DSASUMM!E115 -> 850000 | F21: =DSASUMM!E115 -> 850000 | H21: =DSASUMM!AI115 -> 850000 | J21: =DSASUMM!AK115 -> 850000
B22: SPECIAL TRANSPORTATION | C22: =DSASUMM!B117 -> 170908 | D22: =DSASUMM!C117 -> 128541 | E22: =DSASUMM!E117 -> 170908 | F22: =DSASUMM!E117 -> 170908 | H22: =DSASUMM!AI117 -> 128541 | J22: =DSASUMM!AK117 -> 128541
A24: NRS ADJUSTMENT | C24: =+DSASUMM!B106 -> 0 | D24: 7225368 | E24: 0 | F24: =DSASUMM!E106 -> 0 | G24: 0 | H24: 0 | J24: 0
A25: OTHER ADJUSTMENTS | C25: =DSASUMM!B118 -> 0 | D25: =DSASUMM!C118 -> -39739 | E25: 0 | F25: 0 | H25: =DSASUMM!AI118 -> 0 | J25: =DSASUMM!AK118 -> 0
A26: TOTAL REQUIRED STATE SUPPORT | C26: =SUM(C12:C25)+C9 -> 2507280826 | D26: =SUM(D12:D25)+D9 -> 2513438985 | E26: =SUM(E12:E25)+E9+1 -> 2533867566 | F26: =SUM(F12:F25)+F9 -> 2504094840 | H26: =SUM(H12:H25)+H9 -> 2.5050656e+09 | J26: =SUM(J12:J25)+J9 -> 2.5642478e+09
A28: LESS
B29: =DSASUMM!A121 -> LOCAL SCHOOL SUPPORT TAX - 2.60% | C29: =DSASUMM!B121 -> -905809371 | D29: =DSASUMM!C121 -> -872948748 | E29: -944174996 | F29: =DSASUMM!E121 -> -9.2146231e+08 | H29: =DSASUMM!AI121 -> -9.4173479e+08 | J29: =DSASUMM!AK121 -> -9.6998665e+08
B30: =DSASUMM!A122 -> 1/3 PUBLIC SCHOOLS OPERATING PROPERTY TAX | C30: =DSASUMM!B122 -> -253196604 | D30: =DSASUMM!C122 -> -262851182 | E30: -231116201 | F30: =DSASUMM!E122 -> -220536619 | H30: =DSASUMM!AI122 -> -202433266 | J30: =DSASUMM!AK122 -> -202931773
B31: =+DSASUMM!A124 -> CAPITAL CONSTRUCTION FUNDS | C31: =DSASUMM!B124 -> -10000000 | D31: =C31 -> -10000000 | E31: =DSASUMM!E124 -> -35000000 | F31: =DSASUMM!E124 -> -35000000 | H31: =+DSASUMM!AI124 -> -20000000 | J31: =+DSASUMM!AK124 -> -20000000
B32: TRANSFER FROM CLOSURE OF CC RDA | C32: =DSASUMM!B125 -> -6000000 | D32: =DSASUMM!C125 -> -6000000 | E32: =DSASUMM!E125 -> -5400000 | F32: =DSASUMM!E125 -> -5400000 | H32: =+DSADATABASE!C88 -> 0 | J32: =+DSADATABASE!D88 -> 0
A33: TOTAL STATE SHARE | C33: =SUM(C26:C32) -> 1332274851 | D33: =SUM(D26:D32) -> 1361639055 | E33: =SUM(E26:E32) -> 1318176369 | F33: =SUM(F26:F32) -> 1.3216959e+09 | H33: =SUM(H26:H32) -> 1.3408976e+09 | J33: =SUM(J26:J32) -> 1.3713293e+09
A35: STATE SHARE ELEMENTS
B36: =+DSASUMM!A130 -> GENERAL FUND | C36: =DSASUMM!B130 -> 1173542690 | D36: =DSASUMM!C130 -> 1173542690 | E36: =1267051744-112426570 -> 1154625174 | F36: =DSASUMM!E130 -> 1154625174 | H36: =((1083061369-33139431)+273232418+47028999+1559)-19078532-57561639-42519999-197260069-1+57950189-3147958-286178-20000000 -> 1088280727 | J36: =((920092905-21438031)+406170563+95121601+25)-19078532+1196-58769982-42732000-195882063+52392914-3147958-1113360-286178-20000000 -> 1111331100
B37: =+DSASUMM!A131 -> GENERAL FUND TRANSFER FY 2010 TO FY 2009 | C37: =DSASUMM!B131 -> 0 | D37: =DSASUMM!C131 -> -18917900 | E37: =DSASUMM!E131 -> 0 | F37: 0 | H37: =DSASUMM!AI131 -> 0 | J37: =DSASUMM!AK131 -> 0
B38: =+DSASUMM!A132 -> GENERAL FUND TRANSFER FY 2011 TO FY 2010 | C38: 0 | D38: =DSASUMM!C132 -> 69080821 | E38: 0 | F38: =DSASUMM!E132 -> -69080821 | H38: 0 | J38: 0
B39: =+DSASUMM!A133 -> DSA SHARE OF SLOT TAX | C39: =DSASUMM!B133 -> 35888197 | D39: =DSASUMM!C133 -> 33712074 | E39: 36554830 | F39: =DSASUMM!E133 -> 33300806 | H39: =DSASUMM!AI133 -> 33542238 | J39: =DSASUMM!AK133 -> 34144068
B40: =+DSASUMM!A134 -> PERMANENT SCHOOL FUND | C40: =DSASUMM!B134 -> 13100000 | D40: =DSASUMM!C134 -> 9173420 | E40: 13100000 | F40: =DSASUMM!E134 -> 6700000 | H40: =DSASUMM!AI134 -> 6600000 | J40: =DSASUMM!AK134 -> 6800000
B41: =+DSASUMM!A135 -> FEDERAL MINERAL LEASE REVENUE | C41: =DSASUMM!B135 -> 10706000 | D41: =DSASUMM!C135 -> 8116846 | E41: 10706000 | F41: =DSASUMM!E135 -> 8000000 | H41: =DSASUMM!AI135 -> 8000000 | J41: =DSASUMM!AK135 -> 8000000
B42: =+DSASUMM!A136 -> OUT OF STATE LSST - 2.60% | C42: =DSASUMM!B136 -> 98037864 | D42: =DSASUMM!C136 -> 86190829 | E42: 102190265 | F42: =DSASUMM!E136 -> 91133635 | H42: =DSASUMM!AI136 -> 93138606 | J42: =DSASUMM!AK136 -> 95932745
B43: =+DSASUMM!A137 -> IP1 (2009) ROOM TAX REVENUE TRANSFER | C43: 0 | D43: 0 | E43: 0 | F43: 0 | H43: =+DSASUMM!AI137 -> 111336000 | J43: =+DSASUMM!AK137 -> 115121424
B44: =+DSASUMM!A138 -> REAL PROPERTY TAX | C44: =DSASUMM!B138 -> 1000000 | D44: =DSASUMM!C138 -> 0 | E44: 1000000 | F44: 0 | H44: =DSASUMM!AI138 -> 0 | J44: =DSASUMM!AK138 -> 0
...

Sheet DSADATABASE
A1: DISTRIBUTIVE SCHOOL ACCOUNT DATA BASE ELEMENTS
A2: TOTAL WEIGHTED ENROLLMENT | F2: AVERAGE SALARIES - FY 10 ACTUAL
A3: FY 10 Actual | B3: FY 11 Actual | C3: FY 12 Projected | D3: FY 13 Projected | I3: Total | J3: Total | K3: Average
A4: 425527.2 | B4: 422569.6 | C4: =423191.8-1204.7 -> 421987.1 | D4: =424460.6-961 -> 423499.6 | F4: Classification | I4: Expenditures | J4: FTE | K4: Salary
A5: % Increase | B5: =B4/A4-1 -> -0.006950437 | C5: =C4/B4-1 -> -0.0013784711 | D5: =D4/C4-1 -> 0.0035842328 | F5: Instruction - Licensed | I5: =904927421+189927658 -> 1094855079 | J5: =C25 -> 20489.15 | K5: =ROUND(I5/J5,0) -> 53436
F6: Instruction - Non-Licensed | I6: =63583541 -> 63583541 | J6: =C26 -> 2051.3 | K6: =ROUND(I6/J6,0) -> 30997
A7: 1ST GRADE ENROLLMENT | F7: Instruction Support - Licensed | I7: 151777440 | J7: =C27 -> 2328.71 | K7: =ROUND(I7/J7,0) -> 65177
A8: =A$3 -> FY 10 Actual | B8: =B$3 -> FY 11 Actual | C8: =C$3 -> FY 12 Projected | D8: =D$3 -> FY 13 Projected | F8: Instruction Support - Non-Licensed | I8: 37561815 | J8: =C28 -> 959.07 | K8: =ROUND(I8/J8,0) -> 39165
A9: 33849 | B9: 33865 | C9: 33933 | D9: 34379 | F9: Administration - Licensed | I9: 123265166 | J9: =C29 -> 1405.47 | K9: =ROUND(I9/J9,0) -> 87704
A10: % Increase | B10: =B9/A9-1 -> 0.00047268752 | C10: =C9/B9-1 -> 0.0020079728 | D10: =D9/C9-1 -> 0.013143548 | F10: Administration - Non-Licensed | I10: 133143886 | J10: =C30 -> 2881.37 | K10: =ROUND(I10/J10,0) -> 46209
F11: All Other Personnel | I11: =245320910+7112424 -> 252433334 | J11: =C31 -> 5844.97 | K11: =ROUND(I11/J11,0) -> 43188
A12: 2ND GRADE ENROLLMENT | F12: Class Size Reduction Personnel | I12: 107048220 | J12: 2173 | K12: =ROUND(I12/J12,0) -> 49263
A13: =A$3 -> FY 10 Actual | B13: =B$3 -> FY 11 Actual | C13: =C$3 -> FY 12 Projected | D13: =D$3 -> FY 13 Projected | F13: AVERAGE STARTING SALARY - FY 11
A14: 33824 | B14: 33447 | C14: 33688 | D14: 33848 | F14: Instruction - Licensed | K14: 39166
A15: % Increase | B15: =B14/A14-1 -> -0.011145932 | C15: =C14/B14-1 -> 0.0072054295 | D15: =D14/C14-1 -> 0.0047494657 | F15: Instruction - Non-Licensed | K15: =ROUND(K6*1*0.75,0) -> 23248
F16: Instruction Support - Licensed | K16: =ROUND(K7*1*0.75,0) -> 48883
A17: 3RD GRADE ENROLLMENT | F17: Instruction Support - Non-Licensed | K17: =ROUND(K8*1*0.75,0) -> 29374
A18: =A$3 -> FY 10 Actual | B18: =B$3 -> FY 11 Actual | C18: =C$3 -> FY 12 Projected | D18: =D$3 -> FY 13 Projected | F18: Administration - Licensed | K18: =ROUND(K9*1*0.75,0) -> 65778
A19: 34068 | B19: 33631 | C19: 33533 | D19: 33773 | F19: Administration - Non-Licensed | K19: =ROUND(K10*1*0.75,0) -> 34657
A20: % Increase | B20: =B19/A19-1 -> -0.012827287 | C20: =C19/B19-1 -> -0.0029139782 | D20: =D19/C19-1 -> 0.0071571288 | F20: All Other Personnel | K20: =ROUND(K11*1*0.75,0) -> 32391
F22: DSA Licensed Instruction Avg Salary | J22: =K5 -> 53436
A23: STUDENT STAFFING RATIO - FY 10 ACTUAL | F23: CSR Licensed Instruction Avg Salary | J23: =K12 -> 49263
A24: Classification | C24: FY 10 FTE | D24: Ratio | F24: CSR as % of DSA Avg Salary | J24: =J23/J22 -> 0.92190658
A25: Instruction - Licensed | C25: =16984.12+3505.03 -> 20489.15 | D25: =A$4/C25 -> 20.768416
A26: Instruction - Non-Licensed | C26: =722.62+1328.68 -> 2051.3 | D26: =A$4/C26 -> 207.44269
A27: Instruction Support - Licensed | C27: =1907.5+421.21 -> 2328.71 | D27: =A$4/C27 -> 182.73087 | F27: COST OF LIVING ADJUSTMENT | J27: FY 12 | K27: FY 13
A28: Instruction Support - Non-Licensed | C28: =879.2+79.87 -> 959.07 | D28: =A$4/C28 -> 443.68732 | F28: Decision Unit E-670 | J28: =1-0.025 -> 0.975 | K28: 1
A29: Administration - Licensed | C29: =1395.67+9.8 -> 1405.47 | D29: =A$4/C29 -> 302.76505
A30: Administration - Non-Licensed | C30: =2862.93+18.44 -> 2881.37 | D30: =A$4/C30 -> 147.68225
A31: All Other Personnel | C31: =4938.68+906.29 -> 5844.97 | D31: =A$4/C31 -> 72.80229 | F31: BUILDING SQUARE FOOTAGE | I31: FY 10 | J31: FY 11 | K31: FY 12 | L31: FY 13
A32: Total Personnel | C32: =SUM(C25:C31) -> 35960.04 | D32: =A$4/C32 -> 11.833335 | F32: Elementary Schools | I32: 18694453 | J32: 18993030 | K32: =J32 -> 18993030 | L32: 19073275
F33: Middle/Junior High Schools | I33: 10814292 | J33: 10910924 | K33: 10921298 | L33: 10905431
F34: High Schools | I34: 16789936 | J34: 17193059 | K34: 17232900 | L34: =K34 -> 17232900
A35: LOCAL SCHOOL SUPPORT TAX | F35: Special Schools | I35: 616424 | J35: 619924 | K35: =J35 -> 619924 | L35: =K35 -> 619924
A36: =A$3 -> FY 10 Actual | B36: =B$3 -> FY 11 Actual | C36: =C$3 -> FY 12 Projected | D36: =D$3 -> FY 13 Projected | F36: Other Facilities | I36: 3159801 | J36: =I36 -> 3159801 | K36: 3175121 | L36: 3207827
A37: =-DSASUMM!C121 -> 872948748 | B37: =((976301000+36294942)*0.91) -> 9.2146231e+08 | C37: =((856899000+38664518)*0.91) -> 8.149628e+08 | D37: =(884060000+38370244)*0.91 -> 8.3941152e+08 | F37: Total Building Square Footage | I37: =SUM(I32:I36) -> 50074906 | J37: =SUM(J32:J36) -> 50876738 | K37: =SUM(K32:K36) -> 50942273 | L37: =SUM(L32:L36) -> 51039357 | N37: =872948748/N38 -> 0.91013734
A38: % Increase | B38: =(B37-A37)/A37 -> 0.05557435 | C38: =(C37-B37)/B37 -> -0.11557663 | D38: =(D37-C37)/C37 -> 0.0299998 | F38: Yearly % Increase | J38: =J37/I37-1 -> 0.016012651 | K38: =K37/J37-1 -> 0.0012881132 | L38: =L37/K37-1 -> 0.001905765 | N38: =872948748+86190829 -> 959139577
A40: OUT OF STATE LOCAL SCHOOL SUPPORT TAX | H40: ENHANCEMENT | I40: =DSASUMM!Q3 -> DSAE671 | K40: =J$27 -> FY 12 | L40: =K$27 -> FY 13
A41: =A$3 -> FY 10 Actual | B41: =B$3 -> FY 11 Actual | C41: =C$3 -> FY 12 Projected | D41: =D$3 -> FY 13 Projected | H41: Suspend Merits | K41: =DSASUMM!Q146 -> 0.4529 | L41: =DSASUMM!R146 -> -0.0912
A42: =DSASUMM!C136 -> 86190829 | B42: =(976301000+36294942)-B37 -> 91133635 | C42: =((856899000+38664518)-C37) -> 80600717 | D42: =(884060000+38370244)-D37 -> 83018722
...

Sheet DSASUMM
I1: Enrollment Change | M1: Benefit Change | O1: 2.5% Salary Reduction | Q1: Merit/Longevity | S1: PERS Equalization | W1: Per Pupil Budget Reduction | Y1: New Equipment | AC1: Transfer RPDP$ to BA 2615 | AE1: IP1 Rm Tx to DSA | AG1: Revenue Adjustments
A2: DISTRIBUTIVE SCHOOL ACCOUNT MAIN WORK SHEET - 2011-13 BIENNIUM
B3: 2009-10 | E3: 2010-11 | F3: % | G3: DSABASE | H3: DSABASE | I3: DSAM200 | J3: DSAM200 | K3: DSAM101 | L3: =K3 -> DSAM101 | M3: DSAM300 | N3: DSAM300 | O3: DSAE670 | P3: =O3 -> DSAE670 | Q3: DSAE671 | R3: =Q3 -> DSAE671 | S3: DSAE601 | T3: =S3 -> DSAE601 | U3: DSAE300 | V3: =U3 -> DSAE300 | W3: DSAE600 | X3: =W3 -> DSAE600 | Y3: DSAE710 | Z3: =Y3 -> DSAE710 | AA3: DSAE602 | AB3: =AA3 -> DSAE602 | AC3: DSAE904 | AD3: =AC3 -> DSAE904 | AE3: DSAE130 | AF3: =AE3 -> DSAE130 | AG3: DSAE140 | AH3: =AG3 -> DSAE140 | AI3: DSABME | AJ3: % CHG | AK3: DSABME | AL3: % CHG
B4: WK PROGRAM | C4: ACTUAL | D4: % CHG | E4: WK PROGRAM | F4: CHG | G4: 2011-12 | H4: 2012-13 | I4: =$G4 -> 2011-12 | J4: =$H4 -> 2012-13 | K4: =$G4 -> 2011-12 | L4: =$H4 -> 2012-13 | M4: =$G4 -> 2011-12 | N4: =$H4 -> 2012-13 | O4: =$G4 -> 2011-12 | P4: =$H4 -> 2012-13 | Q4: =$G$4 -> 2011-12 | R4: =$H$4 -> 2012-13 | S4: =$G$4 -> 2011-12 | T4: =$H$4 -> 2012-13 | U4: =$G$4 -> 2011-12 | V4: =$H$4 -> 2012-13 | W4: =$G$4 -> 2011-12 | X4: =$H$4 -> 2012-13 | Y4: =$G$4 -> 2011-12 | Z4: =$H$4 -> 2012-13 | AA4: =$G$4 -> 2011-12 | AB4: =$H$4 -> 2012-13 | AC4: =Y4 -> 2011-12 | AD4: =Z4 -> 2012-13 | AE4: =Y4 -> 2011-12 | AF4: =Z4 -> 2012-13 | AG4: =AA4 -> 2011-12 | AH4: =AB4 -> 2012-13 | AI4: =$G$4 -> 2011-12 | AJ4: =$G$4 -> 2011-12 | AK4: =$H$4 -> 2012-13 | AL4: =$H$4 -> 2012-13
A5: SALARIES | B5: 1813834741 | C5: =1912223758-C6-C7 -> 1856620261 | D5: =ROUND(C5/B5-1,4) -> 0.0236 | E5: =1911029454-E6-E7 -> 1849660599 | F5: =ROUND(E5/C5-1,4) -> -0.0037 | G5: =BASESAL!F53 -> 1901538049 | H5: =BASESAL!H53 -> 1939568810 | I5: =M200SAL!D69 -> -1881325 | J5: =M200SAL!G69 -> 2963658 | M5: =M300SAL!D72 -> -21371138 | N5: =M300SAL!G72 -> -21853490 | O5: =+E670SAL!D71 -> -46957144 | P5: =+E670SAL!G71 -> -47896287 | Q5: =E671SAL!D72+E671SAL!D81 -> 0 | R5: =E671SAL!G72+E671SAL!G81 -> 0 | S5: ='E601 SAL'!D72+'E601 SAL'!D81 -> -77466814 | T5: ='E601 SAL'!G72+'E601 SAL'!F81 -> -79220365 | AC5: 0 | AD5: 0 | AE5: 0 | AF5: 0 | AG5: 0 | AH5: 0 | AI5: =G5+I5+K5+M5+O5+Q5+S5+U5+W5+Y5+AA5+AG5+AC5+AE5 -> 1.7538616e+09 | AJ5: =ROUND(AI5/C5-1,4) -> -0.0553 | AK5: =H5+J5+L5+N5+P5+R5+T5+V5+X5+Z5+AB5+AH5+AD5+AF5 -> 1.7935623e+09 | AL5: =ROUND(AK5/AI5-1,4) -> 0.0226
A6: SUBSTITUTE PAY | B6: 39306246 | C6: =35121511+1216611 -> 36338122 | D6: =ROUND(C6/B6-1,4) -> -0.0755 | E6: =36975586+1044466 -> 38020052 | F6: =ROUND(E6/C6-1,4) -> 0.0463 | G6: =BASESAL!F54 -> 36338122 | H6: =BASESAL!H54 -> 36338122 | I6: =M200SAL!D70 -> -302309 | J6: =M200SAL!G70 -> -173148 | M6: =M300SAL!D73 -> 0 | N6: =M300SAL!G73 -> 0 | O6: =+E670SAL!D72 -> 0 | P6: =+E670SAL!G72 -> 0 | Q6: =E671SAL!D73 -> 0 | R6: =E671SAL!G73 -> 0 | AC6: 0 | AD6: 0 | AE6: 0 | AF6: 0 | AG6: 0 | AH6: 0 | AI6: =G6+I6+K6+M6+O6+Q6+S6+U6+W6+Y6+AA6+AG6+AC6+AE6 -> 36035813 | AJ6: =ROUND(AI6/C6,4)-1 -> -0.0083 | AK6: =H6+J6+L6+N6+P6+R6+T6+V6+X6+Z6+AB6+AH6+AD6+AF6 -> 36164974 | AL6: =ROUND(AK6/AI6-1,4) -> 0.0036
A7: EXTRA DUTY MISCELLANEOUS | B7: 25416599 | C7: 19265375 | D7: =ROUND(C7/B7-1,4) -> -0.242 | E7: 23348803 | F7: =ROUND(E7/C7-1,4) -> 0.212 | G7: =BASESAL!F55 -> 20845444 | H7: =BASESAL!H55 -> 21262353 | I7: =M200SAL!D71 -> -173420 | J7: =M200SAL!G71 -> -101313 | M7: =M300SAL!D74 -> 0 | N7: =M300SAL!G74 -> 0 | O7: =+E670SAL!D73 -> 0 | P7: =+E670SAL!G73 -> 0 | Q7: =E671SAL!D74 -> 0 | R7: =E671SAL!G74 -> 0 | AC7: 0 | AD7: 0 | AE7: 0 | AF7: 0 | AG7: 0 | AH7: 0 | AI7: =G7+I7+K7+M7+O7+Q7+S7+U7+W7+Y7+AA7+AG7+AC7+AE7 -> 20672024 | AJ7: =ROUND(AI7/C7,4)-1 -> 0.073 | AK7: =H7+J7+L7+N7+P7+R7+T7+V7+X7+Z7+AB7+AH7+AD7+AF7 -> 21161040 | AL7: =ROUND(AK7/AI7-1,4) -> 0.0237
A8: FRINGES | AC8: 0 | AD8: 0 | AE8: 0 | AF8: 0 | AG8: 0 | AH8: 0 | AI8: =G8+I8+K8+M8+O8+Q8+S8+U8+W8+Y8+AA8+AG8+AC8+AE8 -> 0 | AK8: =H8+J8+L8+N8+P8+R8+T8+V8+X8+Z8+AB8+AH8+AD8+AF8 -> 0
A9: RETIREMENT | B9: 387981279 | C9: 381217472 | D9: =ROUND(C9/B9-1,4) -> -0.0174 | E9: 384499471 | F9: =ROUND(E9/C9-1,4) -> 0.0086 | G9: =BASESAL!F57 -> 408830681 | H9: =BASESAL!H57 -> 417007294 | I9: =M200SAL!D72 -> -404485.34 | J9: =M200SAL!G72 -> 637186.62 | M9: =M300SAL!D75 -> 37666631 | N9: =M300SAL!G75 -> 38516776 | O9: =E670SAL!D74 -> -11152322 | P9: =E670SAL!G74 -> -11375368 | Q9: =E671SAL!D75 -> 0 | R9: =E671SAL!G75 -> 0 | S9: ='E601 SAL'!D75 -> -18398368 | T9: ='E601 SAL'!G75 -> -18814837 | AC9: 0 | AD9: 0 | AE9: 0 | AF9: 0 | AG9: 0 | AH9: 0 | AI9: =G9+I9+K9+M9+O9+Q9+S9+U9+W9+Y9+AA9+AG9+AC9+AE9 -> 416542137 | AJ9: =ROUND(AI9/C9,4)-1 -> 0.0927 | AK9: =H9+J9+L9+N9+P9+R9+T9+V9+X9+Z9+AB9+AH9+AD9+AF9 -> 425971052 | AL9: =ROUND(AK9/AI9-1,4) -> 0.0226
A10: WORKER'S COMP | B10: 14085077 | C10: 7794417 | D10: =ROUND(C10/B10-1,4) -> -0.4466 | E10: 9375209 | F10: =ROUND(E10/C10-1,4) -> 0.2028 | G10: =BASESAL!F58 -> 7983749 | H10: =BASESAL!H58 -> 8140462 | I10: =M200SAL!D73 -> -9607 | J10: =M200SAL!G73 -> 10961 | M10: =M300SAL!D76 -> -87109 | N10: =M300SAL!G76 -> -89075 | O10: =+E670SAL!D75 -> -191397 | P10: =+E670SAL!G75 -> -195225 | Q10: =E671SAL!D76 -> 0 | R10: =E671SAL!G76 -> 0 | S10: ='E601 SAL'!D76 -> -315755 | T10: ='E601 SAL'!G76 -> -322902 | AC10: 0 | AD10: 0 | AE10: 0 | AF10: 0 | AG10: 0 | AH10: 0 | AI10: =G10+I10+K10+M10+O10+Q10+S10+U10+W10+Y10+AA10+AG10+AC10+AE10 -> 7379881 | AJ10: =ROUND(AI10/C10,4)-1 -> -0.0532 | AK10: =H10+J10+L10+N10+P10+R10+T10+V10+X10+Z10+AB10+AH10+AD10+AF10 -> 7544221 | AL10: =ROUND(AK10/AI10-1,4) -> 0.0223
A11: UNEMPLOYMENT COMP | B11: 1499168 | C11: 6869299 | D11: =ROUND(C11/B11-1,4) -> 3.5821 | E11: 6488035 | F11: =ROUND(E11/C11-1,4) -> -0.0555 | G11: =BASESAL!F59 -> 7035728 | H11: =BASESAL!H59 -> 7173832 | I11: =M200SAL!D74 -> -8466 | J11: =M200SAL!G74 -> 9660 | M11: =M300SAL!D77 -> -76766 | N11: =M300SAL!G77 -> -78498 | O11: =+E670SAL!D76 -> -168670 | P11: =+E670SAL!G76 -> -172044 | Q11: =E671SAL!D77 -> 0 | R11: =E671SAL!G77 -> 0 | S11: ='E601 SAL'!D77 -> -278260 | T11: ='E601 SAL'!G77 -> -284559 | AC11: 0 | AD11: 0 | AE11: 0 | AF11: 0 | AG11: 0 | AH11: 0 | AI11: =G11+I11+K11+M11+O11+Q11+S11+U11+W11+Y11+AA11+AG11+AC11+AE11 -> 6503566 | AJ11: =ROUND(AI11/C11,4)-1 -> -0.0532 | AK11: =H11+J11+L11+N11+P11+R11+T11+V11+X11+Z11+AB11+AH11+AD11+AF11 -> 6648391 | AL11: =ROUND(AK11/AI11-1,4) -> 0.0223
A12: MEDICARE | B12: 24848431 | C12: 24924833 | D12: =ROUND(C12/B12-1,4) -> 0.0031 | E12: 26283600 | F12: =ROUND(E12/C12-1,4) -> 0.0545 | G12: =BASESAL!F60 -> 25529978 | H12: =BASESAL!H60 -> 26031104 | I12: =M200SAL!D75 -> -30722 | J12: =M200SAL!G75 -> 35051 | M12: =M300SAL!D78 -> -278552 | N12: =M300SAL!G78 -> -284838 | O12: =+E670SAL!D77 -> -612039 | P12: =+E670SAL!G77 -> -624280 | Q12: =E671SAL!D78 -> 0 | R12: =E671SAL!G78 -> 0 | S12: ='E601 SAL'!D78 -> -1009703 | T12: ='E601 SAL'!G78 -> -1032558 | AC12: 0 | AD12: 0 | AE12: 0 | AF12: 0 | AG12: 0 | AH12: 0 | AI12: =G12+I12+K12+M12+O12+Q12+S12+U12+W12+Y12+AA12+AG12+AC12+AE12 -> 23598962 | AJ12: =ROUND(AI12/C12,4)-1 -> -0.0532 | AK12: =H12+J12+L12+N12+P12+R12+T12+V12+X12+Z12+AB12+AH12+AD12+AF12 -> 24124479 | AL12: =ROUND(AK12/AI12-1,4) -> 0.0223
A13: MEDICAL INSURANCE | B13: 255724363 | C13: 251025893 | D13: =ROUND(C13/B13-1,4) -> -0.0184 | E13: 260273017 | F13: =ROUND(E13/C13-1,4) -> 0.0368 | G13: =BASESAL!F61 -> 249272063 | H13: =BASESAL!H61 -> 249272063 | I13: =M200SAL!D76 -> -343729 | J13: =M200SAL!G76 -> 548403 | M13: =M300SAL!D79 -> 0 | N13: =M300SAL!G79 -> 0 | O13: =+E670SAL!D78 -> 0 | P13: =+E670SAL!G78 -> 0 | Q13: =E671SAL!D79 -> 0 | R13: =E671SAL!G79 -> 0 | AA13: 0 | AB13: 0 | AC13: 0 | AD13: 0 | AE13: 0 | AF13: 0 | AG13: 0 | AH13: 0 | AI13: =G13+I13+K13+M13+O13+Q13+S13+U13+W13+Y13+AA13+AG13+AC13+AE13 -> 248928334 | AJ13: =ROUND(AI13/C13,4)-1 -> -0.0084 | AK13: =H13+J13+L13+N13+P13+R13+T13+V13+X13+Z13+AB13+AH13+AD13+AF13 -> 249820466 | AL13: =ROUND(AK13/AI13-1,4) -> 0.0036
A14: OTHER | B14: 9998816 | C14: 8233092 | D14: =ROUND(C14/B14-1,4) -> -0.1766 | E14: 8594046 | F14: =ROUND(E14/C14-1,4) -> 0.0438 | G14: =BASESAL!F62 -> 8434255 | H14: =BASESAL!H62 -> 8599811 | I14: =M200SAL!D77 -> -10149 | J14: =M200SAL!G77 -> 11580 | M14: =M300SAL!D80 -> -92024 | N14: =M300SAL!G80 -> -94102 | O14: =+E670SAL!D79 -> -202198 | P14: =+E670SAL!G79 -> -206241 | Q14: =E671SAL!D80 -> 0 | R14: =E671SAL!G80 -> 0 | S14: ='E601 SAL'!D80 -> -333572 | T14: ='E601 SAL'!G80 -> -341123 | AC14: 0 | AD14: 0 | AE14: 0 | AF14: 0 | AG14: 0 | AH14: 0 | AI14: =G14+I14+K14+M14+O14+Q14+S14+U14+W14+Y14+AA14+AG14+AC14+AE14 -> 7796312 | AJ14: =ROUND(AI14/C14,4)-1 -> -0.0531 | AK14: =H14+J14+L14+N14+P14+R14+T14+V14+X14+Z14+AB14+AH14+AD14+AF14 -> 7969925 | AL14: =ROUND(AK14/AI14-1,4) -> 0.0223
A15: TOTAL FRINGES | B15: =SUM(B9:B14) -> 694137134 | C15: =SUM(C9:C14) -> 680065006 | D15: =ROUND(C15/B15-1,4) -> -0.0203 | E15: =SUM(E9:E14) -> 695513378 | F15: =ROUND(E15/C15-1,4) -> 0.0227 | G15: =SUM(G9:G14) -> 707086454 | H15: =SUM(H9:H14) -> 716224566 | I15: =SUM(I9:I14) -> -807158.34 | J15: =SUM(J9:J14) -> 1252841.6 | K15: =SUM(K9:K14) -> 0 | L15: =SUM(L9:L14) -> 0 | M15: =SUM(M9:M14) -> 37132180 | N15: =SUM(N9:N14) -> 37970263 | ... AH15: =SUM(AH9:AH14) -> 0 | AI15: =G15+I15+K15+M15+O15+Q15+S15+U15+W15+Y15+AA15+AG15+AC15+AE15 -> 710749192 | AJ15: =ROUND(AI15/C15-1,4) -> 0.0451 | AK15: =(H15+L15+J15+N15+P15+R15+T15+V15+X15+Z15+AB15+AH15+AF15) -> 722078534 | AL15: =ROUND(AK15/AI15-1,4) -> 0.0159
A16: Sub-Total - Salaries and Fringe | B16: =+B5+B6+B7+B15 -> 2572694720 | C16: =+C5+C6+C7+C15 -> 2592288764 | E16: =+E5+E6+E7+E15 -> 2606542832 | G16: =+G5+G6+G7+G15 -> 2665808069 | H16: =+H5+H6+H7+H15 -> 2713393851 | I16: =+I5+I6+I7+I15 -> -3164212.3 | J16: =+J5+J6+J7+J15 -> 3942038.6 | K16: =+K5+K6+K7+K15 -> 0 | L16: =+L5+L6+L7+L15 -> 0 | M16: =+M5+M6+M7+M15 -> 15761042 | N16: =+N5+N6+N7+N15 -> 16116773 | ... AI16: =+AI5+AI6+AI7+AI15 -> 2.5213187e+09 | AK16: =+AK5+AK6+AK7+AK15 -> 2.5729669e+09
A18: FULL DAY KINDERGARTEN - 22 | B18: 0 | C18: 0 | D18: =ROUND(C18/B18-1,4) -> #DIV/0! | E18: 0 | F18: =ROUND(E18/C18-1,4) -> #DIV/0! | G18: =C18 -> 0 | H18: =G18 -> 0 | AI18: =(G18+K18+I18+M18+O18+Q18+S18+U18+W18+Y18+AA18) -> 0 | AJ18: =ROUND(AI18/C18,4)-1 -> #DIV/0! | AK18: =(H18+L18+J18+N18+P18+R18+T18+V18+X18+Z18+AB18) -> 0 | AL18: =ROUND(AK18/AI18-1,4) -> #DIV/0!
A19: RETIRED EMPOYEES GROUP INS | B19: 36645582 | C19: 27980315 | D19: =ROUND(C19/B19-1,4) -> -0.2365 | E19: =25660901+3759244 -> 29420145 | F19: =ROUND(E19/C19-1,4) -> 0.0515 | G19: 27062825 | H19: 27118499 | AA19: 0 | AB19: 0 | AI19: =G19+I19+K19+M19+O19+Q19+S19+U19+W19+Y19+AA19+AG19+AC19+AE19 -> 27062825 | AJ19: =ROUND(AI19/C19,4)-1 -> -0.0328 | AK19: =H19+J19+L19+N19+P19+R19+T19+V19+X19+Z19+AB19+AH19+AD19+AF19 -> 27118499 | AL19: =ROUND(AK19/AI19-1,4) -> 0.0021
A21: TOTAL SALARY AND FRINGE | B21: =SUM(B16:B20) -> 2609340302 | C21: =SUM(C16:C20) -> 2620269079 | D21: =ROUND(C21/B21-1,4) -> 0.0042 | E21: =SUM(E16:E20) -> 2635962977 | F21: =ROUND(E21/C21-1,4) -> 0.006 | G21: =SUM(G16:G20) -> 2692870894 | H21: =SUM(H16:H20) -> 2740512350 | I21: =SUM(I16:I20) -> -3164212.3 | J21: =SUM(J16:J20) -> 3942038.6 | K21: =SUM(K16:K20) -> 0 | L21: =SUM(L16:L20) -> 0 | M21: =SUM(M16:M20) -> 15761042 | N21: =SUM(N16:N20) -> 16116773 | ... AI21: =SUM(AI16:AI20) -> 2.5483815e+09 | AJ21: =ROUND(AI21/C21-1,4) -> -0.0274 | AK21: =SUM(AK16:AK20) -> 2.6000854e+09 | AL21: =ROUND(AK21/AI21-1,4) -> 0.0203
A22: BENEFIT/SALARY | B22: =B15/B5 -> 0.3826904 | C22: =C15/C5 -> 0.36629192 | D22: =ROUND(C22/B22-1,4) -> -0.0429 | E22: =E15/E5 -> 0.37602216 | F22: =ROUND(E22/C22-1,4) -> 0.0266 | G22: =G15/G5 -> 0.37184975 | H22: =H15/H5 -> 0.36927 | I22: =I15/I5 -> 0.42903716 | J22: =J15/J5 -> 0.42273488 | O22: =O15/O5 -> 0.262508 | P22: =P15/P5 -> 0.26250799 | AI22: =AI15/AI5 -> 0.40524816 | AK22: =AK15/AK5 -> 0.40259462
A23: OPERATING:
A24: Heat | B24: 15147689 | C24: 12057552 | D24: =ROUND(C24/B24-1,4) -> -0.204 | E24: 12626587 | F24: =ROUND(E24/C24-1,4) -> 0.0472 | G24: =C24 -> 12057552 | H24: =G24 -> 12057552 | I24: =M200OPR!R55 -> 209347 | J24: =M200OPR!T55 -> 232725 | K24: =M101INF!S55 -> 0 | L24: =M101INF!V55 -> 0 | AC24: 0 | AD24: 0 | AE24: 0 | AF24: 0 | AG24: 0 | AH24: 0 | AI24: =G24+I24+K24+M24+O24+Q24+S24+U24+W24+Y24+AA24+AG24+AC24+AE24 -> 12266899 | AJ24: =ROUND(AI24/C24,4)-1 -> 0.0174 | AK24: =H24+J24+L24+N24+P24+R24+T24+V24+X24+Z24+AB24+AH24+AD24+AF24 -> 12290277 | AL24: =ROUND(AK24/AI24-1,4) -> 0.0019
A25: Electricity | B25: 72409307 | C25: 65089232 | D25: =ROUND(C25/B25-1,4) -> -0.1011 | E25: 70760567 | F25: =ROUND(E25/C25-1,4) -> 0.0871 | G25: =C25 -> 65089232 | H25: =G25 -> 65089232 | I25: =M200OPR!R56 -> 1125534 | J25: =M200OPR!T56 -> 1251724 | K25: =M101INF!S56 -> 0 | L25: =M101INF!V56 -> 0 | AC25: 0 | AD25: 0 | AE25: 0 | AF25: 0 | AG25: 0 | AH25: 0 | AI25: =G25+I25+K25+M25+O25+Q25+S25+U25+W25+Y25+AA25+AG25+AC25+AE25 -> 66214766 | AJ25: =ROUND(AI25/C25,4)-1 -> 0.0173 | AK25: =H25+J25+L25+N25+P25+R25+T25+V25+X25+Z25+AB25+AH25+AD25+AF25 -> 66340956 | AL25: =ROUND(AK25/AI25-1,4) -> 0.0019
A26: Pupil Transportation | B26: 25014207 | C26: 16707325 | D26: =ROUND(C26/B26-1,4) -> -0.3321 | E26: 16907458 | F26: =ROUND(E26/C26-1,4) -> 0.012 | G26: =C26 -> 16707325 | H26: =G26 -> 16707325 | I26: =M200OPR!R60 -> -139014 | J26: =M200OPR!T60 -> -79630 | K26: =M101INF!S60 -> 0 | L26: =M101INF!V60 -> 0 | AC26: 0 | AD26: 0 | AE26: 0 | AF26: 0 | AG26: 0 | AH26: 0 | AI26: =G26+I26+K26+M26+O26+Q26+S26+U26+W26+Y26+AA26+AG26+AC26+AE26 -> 16568311 | AJ26: =ROUND(AI26/C26,4)-1 -> -0.0083 | AK26: =H26+J26+L26+N26+P26+R26+T26+V26+X26+Z26+AB26+AH26+AD26+AF26 -> 16627695 | AL26: =ROUND(AK26/AI26-1,4) -> 0.0036 | AM26: Total Txtbook, Software, Hardware, Instructional Supplies
A27: Textbooks | B27: 28420804 | C27: 23810368 | D27: =ROUND(C27/B27-1,4) -> -0.1622 | E27: 36559619 | F27: =ROUND(E27/C27-1,4) -> 0.5354 | G27: =C27 -> 23810368 | H27: =G27 -> 23810368 | I27: =M200OPR!R61 -> -198080 | J27: =M200OPR!T61 -> -113448 | K27: =M101INF!S61 -> 0 | L27: =M101INF!V61 -> 0 | AC27: 0 | AD27: 0 | AE27: 0 | AF27: 0 | AG27: 0 | AH27: 0 | AI27: =G27+I27+K27+M27+O27+Q27+S27+U27+W27+Y27+AA27+AG27+AC27+AE27 -> 23612288 | AJ27: =ROUND(AI27/C27,4)-1 -> -0.0083 | AK27: =H27+J27+L27+N27+P27+R27+T27+V27+X27+Z27+AB27+AH27+AD27+AF27 -> 23696920 | AL27: =ROUND(AK27/AI27-1,4) -> 0.0036 | AM27: =AI27+AI36+AI37+AI52 -> 101336415 | AN27: =AK27+AK36+AK37+AK52 -> 101699617
A28: Library | B28: 2389288 | C28: 2397912 | D28: =ROUND(C28/B28-1,4) -> 0.0036 | E28: 2674356 | F28: =ROUND(E28/C28-1,4) -> 0.1153 | G28: =C28 -> 2397912 | H28: =G28 -> 2397912 | I28: =M200OPR!R62 -> -19930 | J28: =M200OPR!T62 -> -11407 | K28: =M101INF!S62 -> 0 | L28: =M101INF!V62 -> 0 | AC28: 0 | AD28: 0 | AE28: 0 | AF28: 0 | AG28: 0 | AH28: 0 | AI28: =G28+I28+K28+M28+O28+Q28+S28+U28+W28+Y28+AA28+AG28+AC28+AE28 -> 2377982 | AJ28: =ROUND(AI28/C28,4)-1 -> -0.0083 | AK28: =H28+J28+L28+N28+P28+R28+T28+V28+X28+Z28+AB28+AH28+AD28+AF28 -> 2386505 | AL28: =ROUND(AK28/AI28-1,4) -> 0.0036
A29: Maintenance/Repair | B29: 37797695 | C29: 25553696 | D29: =ROUND(C29/B29-1,4) -> -0.3239 | E29: 29366243 | F29: =ROUND(E29/C29-1,4) -> 0.1492 | G29: =C29 -> 25553696 | H29: =G29 -> 25553696 | I29: =M200OPR!R59 -> 442146 | J29: =M200OPR!T59 -> 491688 | K29: =M101INF!S59 -> 0 | L29: =M101INF!V59 -> 0 | AC29: 0 | AD29: 0 | AE29: 0 | AF29: 0 | AG29: 0 | AH29: 0 | AI29: =G29+I29+K29+M29+O29+Q29+S29+U29+W29+Y29+AA29+AG29+AC29+AE29 -> 25995842 | AJ29: =ROUND(AI29/C29,4)-1 -> 0.0173 | AK29: =H29+J29+L29+N29+P29+R29+T29+V29+X29+Z29+AB29+AH29+AD29+AF29 -> 26045384 | AL29: =ROUND(AK29/AI29-1,4) -> 0.0019
A30: Professional Services | B30: 60276021 | C30: 47269193 | D30: =ROUND(C30/B30-1,4) -> -0.2158 | E30: 44995473 | F30: =ROUND(E30/C30-1,4) -> -0.0481 | G30: =C30 -> 47269193 | H30: =G30 -> 47269193 | I30: =M200OPR!R66 -> -394980 | J30: =M200OPR!T66 -> -226987 | K30: =M101INF!S66 -> 0 | L30: =M101INF!V66 -> 0 | AC30: 0 | AD30: 0 | AE30: 0 | AF30: 0 | AG30: 0 | AH30: 0 | AI30: =G30+I30+K30+M30+O30+Q30+S30+U30+W30+Y30+AA30+AG30+AC30+AE30 -> 46874213 | AJ30: =ROUND(AI30/C30,4)-1 -> -0.0084 | AK30: =H30+J30+L30+N30+P30+R30+T30+V30+X30+Z30+AB30+AH30+AD30+AF30 -> 47042206 | AL30: =ROUND(AK30/AI30-1,4) -> 0.0036
A31: Water/Sewer/Garbage | B31: 26434884 | C31: 26757018 | D31: =ROUND(C31/B31-1,4) -> 0.0122 | E31: 28806985 | F31: =ROUND(E31/C31-1,4) -> 0.0766 | G31: =C31 -> 26757018 | H31: =G31 -> 26757018 | I31: =M200OPR!R57 -> 461438 | J31: =M200OPR!T57 -> 513310 | K31: =M101INF!S57 -> 0 | L31: =M101INF!V57 -> 0 | AC31: 0 | AD31: 0 | AE31: 0 | AF31: 0 | AG31: 0 | AH31: 0 | AI31: =G31+I31+K31+M31+O31+Q31+S31+U31+W31+Y31+AA31+AG31+AC31+AE31 -> 27218456 | AJ31: =ROUND(AI31/C31,4)-1 -> 0.0172 | AK31: =H31+J31+L31+N31+P31+R31+T31+V31+X31+Z31+AB31+AH31+AD31+AF31 -> 27270328 | AL31: =ROUND(AK31/AI31-1,4) -> 0.0019
A32: Liability Insurance | B32: 14869666 | C32: 5925229 | D32: =ROUND(C32/B32-1,4) -> -0.6015 | E32: 11103735 | F32: =ROUND(E32/C32-1,4) -> 0.874 | G32: =C32 -> 5925229 | H32: =G32 -> 5925229 | I32: =M200OPR!R67 -> -49511 | J32: =M200OPR!T67 -> -28453 | K32: =M101INF!S67 -> 0 | L32: =M101INF!V67 -> 0 | AC32: 0 | AD32: 0 | AE32: 0 | AF32: 0 | AG32: 0 | AH32: 0 | AI32: =G32+I32+K32+M32+O32+Q32+S32+U32+W32+Y32+AA32+AG32+AC32+AE32 -> 5875718 | AJ32: =ROUND(AI32/C32,4)-1 -> -0.0084 | AK32: =H32+J32+L32+N32+P32+R32+T32+V32+X32+Z32+AB32+AH32+AD32+AF32 -> 5896776 | AL32: =ROUND(AK32/AI32-1,4) -> 0.0036
A33: Property Insurance | B33: 2110090 | C33: 1981658 | D33: =ROUND(C33/B33-1,4) -> -0.0609 | E33: 2096411 | F33: =ROUND(E33/C33-1,4) -> 0.0579 | G33: =C33 -> 1981658 | H33: =G33 -> 1981658 | I33: =M200OPR!R58 -> 35656 | J33: =M200OPR!T58 -> 39501 | K33: =M101INF!S58 -> 0 | L33: =M101INF!V58 -> 0 | AC33: 0 | AD33: 0 | AE33: 0 | AF33: 0 | AG33: 0 | AH33: 0 | AI33: =G33+I33+K33+M33+O33+Q33+S33+U33+W33+Y33+AA33+AG33+AC33+AE33 -> 2017314 | AJ33: =ROUND(AI33/C33,4)-1 -> 0.018 | AK33: =H33+J33+L33+N33+P33+R33+T33+V33+X33+Z33+AB33+AH33+AD33+AF33 -> 2021159 | AL33: =ROUND(AK33/AI33-1,4) -> 0.0019
A34: Postage/Communications | B34: 9132685 | C34: 13152322 | D34: =ROUND(C34/B34-1,4) -> 0.4401 | E34: 15645874 | F34: =ROUND(E34/C34-1,4) -> 0.1896 | G34: =C34 -> 13152322 | H34: =G34 -> 13152322 | I34: =M200OPR!R68 -> -109899 | J34: =M200OPR!T68 -> -63156 | K34: =M101INF!S68 -> 0 | L34: =M101INF!V68 -> 0 | AC34: 0 | AD34: 0 | AE34: 0 | AF34: 0 | AG34: 0 | AH34: 0 | AI34: =G34+I34+K34+M34+O34+Q34+S34+U34+W34+Y34+AA34+AG34+AC34+AE34 -> 13042423 | AJ34: =ROUND(AI34/C34,4)-1 -> -0.0084 | AK34: =H34+J34+L34+N34+P34+R34+T34+V34+X34+Z34+AB34+AH34+AD34+AF34 -> 13089166 | AL34: =ROUND(AK34/AI34-1,4) -> 0.0036
A35: Printing/Binding | B35: 4744863 | C35: 3217410 | D35: =ROUND(C35/B35-1,4) -> -0.3219 | E35: 3570599 | F35: =ROUND(E35/C35-1,4) -> 0.1098 | G35: =C35 -> 3217410 | H35: =G35 -> 3217410 | I35: =M200OPR!R69 -> -26885 | J35: =M200OPR!T69 -> -15450 | K35: =M101INF!S69 -> 0 | L35: =M101INF!V69 -> 0 | AC35: 0 | AD35: 0 | AE35: 0 | AF35: 0 | AG35: 0 | AH35: 0 | AI35: =G35+I35+K35+M35+O35+Q35+S35+U35+W35+Y35+AA35+AG35+AC35+AE35 -> 3190525 | AJ35: =ROUND(AI35/C35,4)-1 -> -0.0084 | AK35: =H35+J35+L35+N35+P35+R35+T35+V35+X35+Z35+AB35+AH35+AD35+AF35 -> 3201960 | AL35: =ROUND(AK35/AI35-1,4) -> 0.0036
A36: Instructional Supplies | B36: 50790482 | C36: 70944435 | D36: =ROUND(C36/B36-1,4) -> 0.3968 | E36: 43758545 | F36: =ROUND(E36/C36-1,4) -> -0.3832 | G36: =C36 -> 70944435 | H36: =G36 -> 70944435 | I36: =M200OPR!R63 -> -590197 | J36: =M200OPR!T63 -> -338031 | K36: =M101INF!S63 -> 0 | L36: =M101INF!V63 -> 0 | AC36: 0 | AD36: 0 | AE36: 0 | AF36: 0 | AG36: 0 | AH36: 0 | AI36: =G36+I36+K36+M36+O36+Q36+S36+U36+W36+Y36+AA36+AG36+AC36+AE36 -> 70354238 | AJ36: =ROUND(AI36/C36,4)-1 -> -0.0083 | AK36: =H36+J36+L36+N36+P36+R36+T36+V36+X36+Z36+AB36+AH36+AD36+AF36 -> 70606404 | AL36: =ROUND(AK36/AI36-1,4) -> 0.0036
A37: Instructional Computer Software | B37: 4542022 | C37: 7384984 | D37: =ROUND(C37/B37-1,4) -> 0.6259 | E37: 12090009 | F37: =ROUND(E37/C37-1,4) -> 0.6371 | G37: =C37 -> 7384984 | H37: =G37 -> 7384984 | I37: =M200OPR!R64 -> -61440 | J37: =M200OPR!T64 -> -35191 | K37: =M101INF!S64 -> 0 | L37: =M101INF!V64 -> 0 | AC37: 0 | AD37: 0 | AE37: 0 | AF37: 0 | AG37: 0 | AH37: 0 | AI37: =G37+I37+K37+M37+O37+Q37+S37+U37+W37+Y37+AA37+AG37+AC37+AE37 -> 7323544 | AJ37: =ROUND(AI37/C37,4)-1 -> -0.0083 | AK37: =H37+J37+L37+N37+P37+R37+T37+V37+X37+Z37+AB37+AH37+AD37+AF37 -> 7349793 | AL37: =ROUND(AK37/AI37-1,4) -> 0.0036
A38: Other Supplies | B38: 17719581 | C38: 16515016 | D38: =ROUND(C38/B38-1,4) -> -0.068 | E38: 12943249 | F38: =ROUND(E38/C38-1,4) -> -0.2163 | G38: =C38 -> 16515016 | H38: =G38 -> 16515016 | I38: =M200OPR!R65 -> -137401 | J38: =M200OPR!T65 -> -78700 | K38: =M101INF!S65 -> 0 | L38: =M101INF!V65 -> 0 | AC38: 0 | AD38: 0 | AE38: 0 | AF38: 0 | AG38: 0 | AH38: 0 | AI38: =G38+I38+K38+M38+O38+Q38+S38+U38+W38+Y38+AA38+AG38+AC38+AE38 -> 16377615 | AJ38: =ROUND(AI38/C38,4)-1 -> -0.0083 | AK38: =H38+J38+L38+N38+P38+R38+T38+V38+X38+Z38+AB38+AH38+AD38+AF38 -> 16436316 | AL38: =ROUND(AK38/AI38-1,4) -> 0.0036
A39: Other Fuel | B39: 3147423 | C39: 2531857 | D39: =ROUND(C39/B39-1,4) -> -0.1956 | E39: 2598274 | F39: =ROUND(E39/C39-1,4) -> 0.0262 | G39: =C39 -> 2531857 | H39: =G39 -> 2531857 | I39: =M200OPR!R70 -> -21157 | J39: =M200OPR!T70 -> -12158 | K39: =M101INF!S70 -> 0 | L39: =M101INF!V70 -> 0 | AC39: 0 | AD39: 0 | AE39: 0 | AF39: 0 | AG39: 0 | AH39: 0 | AI39: =G39+I39+K39+M39+O39+Q39+S39+U39+W39+Y39+AA39+AG39+AC39+AE39 -> 2510700 | AJ39: =ROUND(AI39/C39,4)-1 -> -0.0084 | AK39: =H39+J39+L39+N39+P39+R39+T39+V39+X39+Z39+AB39+AH39+AD39+AF39 -> 2519699 | AL39: =ROUND(AK39/AI39-1,4) -> 0.0036
A40: Staff Travel/Training | B40: 5086485 | C40: 3539980 | D40: =ROUND(C40/B40-1,4) -> -0.304 | E40: 3252815 | F40: =ROUND(E40/C40-1,4) -> -0.0811 | G40: =C40 -> 3539980 | H40: =G40 -> 3539980 | I40: =M200OPR!R71 -> -29582 | J40: =M200OPR!T71 -> -17001 | K40: =M101INF!S71 -> 0 | L40: =M101INF!V71 -> 0 | AC40: 0 | AD40: 0 | AE40: 0 | AF40: 0 | AG40: 0 | AH40: 0 | AI40: =G40+I40+K40+M40+O40+Q40+S40+U40+W40+Y40+AA40+AG40+AC40+AE40 -> 3510398 | AJ40: =ROUND(AI40/C40,4)-1 -> -0.0084 | AK40: =H40+J40+L40+N40+P40+R40+T40+V40+X40+Z40+AB40+AH40+AD40+AF40 -> 3522979 | AL40: =ROUND(AK40/AI40-1,4) -> 0.0036
A41: All Other | B41: 12417407 | C41: =9226066+492955 -> 9719021 | D41: =ROUND(C41/B41-1,4) -> -0.2173 | E41: =14087021+505890 -> 14592911 | F41: =ROUND(E41/C41-1,4) -> 0.5015 | G41: =C41 -> 9719021 | H41: =G41 -> 9719021 | I41: =M200OPR!R72 -> -81212 | J41: =M200OPR!T72 -> -46671 | K41: =M101INF!S72 -> 0 | L41: =M101INF!V72 -> 0 | AC41: 0 | AD41: 0 | AE41: 0 | AF41: 0 | AG41: 0 | AH41: 0 | AI41: =G41+I41+K41+M41+O41+Q41+S41+U41+W41+Y41+AA41+AG41+AC41+AE41 -> 9637809 | AJ41: =ROUND(AI41/C41,4)-1 -> -0.0084 | AK41: =H41+J41+L41+N41+P41+R41+T41+V41+X41+Z41+AB41+AH41+AD41+AF41 -> 9672350 | AL41: =ROUND(AK41/AI41-1,4) -> 0.0036
A42: Facility Leasing/Rental | B42: 7564852 | C42: 8531546 | D42: =ROUND(C42/B42-1,4) -> 0.1278 | E42: 8889492 | F42: =ROUND(E42/C42-1,4) -> 0.042 | G42: =C42 -> 8531546 | H42: =G42 -> 8531546 | AC42: 0 | AD42: 0 | AE42: 0 | AF42: 0 | AG42: 0 | AH42: 0 | AI42: =G42+I42+K42+M42+O42+Q42+S42+U42+W42+Y42+AA42+AG42+AC42+AE42 -> 8531546 | AJ42: =ROUND(AI42/C42,4)-1 -> 0 | AK42: =H42+J42+L42+N42+P42+R42+T42+V42+X42+Z42+AB42+AH42+AD42+AF42 -> 8531546 | AL42: =ROUND(AK42/AI42-1,4) -> 0
...

Sheet AVG SAL
A1: DSA CALCULATIONS - AVERAGE TEACHER SALARY AND FRINGE BENEFITS (SEE NOTE)
E2: 10 FY | F2: 11 FY | G2: 12 FY | H2: 13 FY
E3: SALARY | F3: SALARY | G3: SALARY | H3: SALARY
A4: INSTRUCTIONAL PERSONNEL
A5: FY 10 AVG SALARY | E5: =DSADATABASE!K5 -> 53436
A6: FY 11 @ 1% Roll-Up PLUS 0% Cola | F6: =ROUND((E5*1.01)*1,0) -> 53970
A7: FY 12 @ 2% Roll-Up | G7: =ROUND(F6*1.02,0) -> 55049
A8: FY 13 @ 2% Roll-Up | H8: =ROUND(G7*1.02,0) -> 56150
C9: 11 FY
A10: FRINGE BENEFITS | C10: AVG RATE
A11: RETIREMENT | C11: =BASESAL!C57 -> 0.215 | E11: =ROUND(E$5*C11,0) -> 11489 | F11: =ROUND(F$6*C11,0) -> 11604 | G11: =ROUND(G$7*C11,0) -> 11836 | H11: =ROUND(H$8*C11,0) -> 12072
A12: WORKER'S COMP | C12: =BASESAL!C58 -> 0.004076 | E12: =ROUND(E$5*C12,0) -> 218 | F12: =ROUND(F$6*C12,0) -> 220 | G12: =ROUND(G$7*C12,0) -> 224 | H12: =ROUND(H$8*C12,0) -> 229
A13: UNEMP INS | C13: =BASESAL!C59 -> 0.003592 | E13: =ROUND(E$5*C13,0) -> 192 | F13: =ROUND(F$6*C13,0) -> 194 | G13: =ROUND(G$7*C13,0) -> 198 | H13: =ROUND(H$8*C13,0) -> 202
A14: MEDICARE | C14: =BASESAL!C60 -> 0.013034 | E14: =ROUND(E$5*C14,0) -> 696 | F14: =ROUND(F$6*C14,0) -> 703 | G14: =ROUND(G$7*C14,0) -> 718 | H14: =ROUND(H$8*C14,0) -> 732
A15: MEDICAL INS | C15: =DSADATABASE!C70 -> 6980.69 | E15: =DSADATABASE!C70 -> 6980.69 | F15: =DSADATABASE!C70 -> 6980.69 | G15: =DSADATABASE!D70 -> 6980.69 | H15: =DSADATABASE!E70 -> 6980.69
A16: OTHER | C16: =BASESAL!C62 -> 0.004306 | E16: =ROUND(E$5*C16,0) -> 230 | F16: =ROUND(F$6*C16,0) -> 232 | G16: =ROUND(G$7*C16,0) -> 237 | H16: =H$8*C16 -> 241.7819
E17: =SUM(E11:E16) -> 19805.69 | F17: =SUM(F11:F16) -> 19933.69 | G17: =SUM(G11:G16) -> 20193.69 | H17: =SUM(H11:H16) -> 20457.472
A19: TOTAL SALARY AND FRINGE BENEFITS | E19: =E5+E17 -> 73241.69 | F19: =F6+F17 -> 73903.69 | G19: =G7+G17 -> 75242.69 | H19: =H8+H17 -> 76607.472
A21: NOTE: VARIABLES TO IMPACT AVERAGE
A22: 1. AVERAGE STARTING SALARIES OF NEW TEACHERS HIRED AFTER FY ACTUAL AVERAGE
A23: 2. NUMBER OF FY 10 TEACHERS WHO LEAVE SERVICE (RETIREMENT, CHANGE OF PROFESSION, ETC)
A24: 3. NUMBER OF FY 10 TEACHERS NO LONGER ELIGIBLE FOR MERIT ADJUSTMENT
A25: 4. FINAL FRINGE RATES AFTER FY 11 BUDGETED AVERAGE
A26: 5. LOCAL COLLECTIVE BARGAINING AGREEMENTS

Sheet BASESAL
A1: DISTRIBUTIVE SCHOOL ACCOUNT - BASE SALARY
B2: FY10 | C2: FY11 | D2: =C2 -> FY11 | E2: FY12 | F2: =E2 -> FY12 | G2: FY13 | H2: =G2 -> FY13
B3: POS | C3: POS | D3: $ | E3: POS | F3: $ | G3: POS | H3: $
A4: WEIGHTED ENROLLMENT | B4: =DSADATABASE!A4 -> 425527.2 | C4: =DSADATABASE!B4 -> 422569.6 | E4: =DSADATABASE!C4 -> 421987.1 | G4: =DSADATABASE!D4 -> 423499.6
A5: AVG STARTING TEACHER SALARY | D5: =DSADATABASE!K14 -> 39166 | F5: =D5 -> 39166 | H5: =F5 -> 39166
A7: INSTRUCTIONAL PERSONNEL
A8: LICENSED | B8: =DSADATABASE!C25 -> 20489.15 | C8: =ROUND(C$4/B9,2)-B8 -> -143.96 | E8: =(B8) -> 20489.15 | G8: =(E12) -> 20345.19
A9: STUDENT RATIO | B9: =ROUND(B$4/B8,2) -> 20.77 | D9: =ROUND(C8*D5,0) -> -5638337 | E9: =(C8) -> -143.96 | F9: =ROUND(D9*1.02,0) -> -5751104 | H9: =ROUND(F9*1.02,0) -> -5866126
A10: 2%ROLL-UP | D10: =ROUND(B8*B12,0) -> 1105799426 | F10: =ROUND(D10*1.02,0) -> 1127915415 | H10: =ROUND((F10+F11)*1.02,0) -> 1150473723
A11: FY 10 AVG SALARY | B11: =DSADATABASE!K5 -> 53436 | F11: =E11*F5 -> 0 | H11: =G11*H5 -> 0
A12: FY11 = FY10 @ 1% Roll-Up Plus 0% Cola | B12: =ROUND((B11*1.01)*1,0) -> 53970 | E12: =SUM(E8:E11) -> 20345.19 | F12: =SUM(F8:F11) -> 1122164311 | G12: =SUM(G8:G11) -> 20345.19 | H12: =SUM(H8:H11) -> 1144607597
A14: INSTRUCTIONAL PERSONNEL
A15: NON-LICENSED | B15: =DSADATABASE!C26 -> 2051.3 | C15: =ROUND(C$4/B16,2)-B15 -> -14.23 | E15: =(B15) -> 2051.3 | G15: =(E19) -> 2037.07
A16: STUDENT RATIO | B16: =ROUND(B$4/B15,2) -> 207.44 | D16: =ROUND(C15*DSADATABASE!K15,0) -> -330819 | E16: =(C15) -> -14.23 | F16: =ROUND(D16*1.02,0) -> -337435 | H16: =ROUND(F16*1.02,0) -> -344184
A17: 2%ROLL-UP | D17: =ROUND(B15*B19,0) -> 64220049 | F17: =ROUND(D17*1.02,0) -> 65504450 | H17: =ROUND((F17+F18)*1.02,0) -> 66814539
A18: =$A$11 -> FY 10 AVG SALARY | B18: =DSADATABASE!K6 -> 30997 | H18: =(G18*B19)*0.75 -> 0
A19: =$A$12 -> FY11 = FY10 @ 1% Roll-Up Plus 0% Cola | B19: =ROUND((B18*1.01)*1,0) -> 31307 | E19: =SUM(E15:E18) -> 2037.07 | F19: =SUM(F15:F18) -> 65167015 | G19: =SUM(G15:G18) -> 2037.07 | H19: =SUM(H15:H18) -> 66470355
A21: INSTRUCTION SUPPORT PERSONNEL
A22: LICENSED | B22: =DSADATABASE!C27 -> 2328.71 | C22: =ROUND(C$4/B23,2)-B22 -> -16.17 | E22: =(B22) -> 2328.71 | G22: =(E26) -> 2312.54
A23: STUDENT RATIO | B23: =ROUND(B$4/B22,2) -> 182.73 | D23: =ROUND(C22*DSADATABASE!K16,0) -> -790438 | E23: =(C22) -> -16.17 | F23: =ROUND(D23*1.02,0) -> -806247 | H23: =ROUND(F23*1.02,0) -> -822372
A24: 2%ROLL-UP | D24: =ROUND(B22*B26,0) -> 153296651 | F24: =ROUND(D24*1.02,0) -> 156362584 | H24: =ROUND((F24+F25)*1.02,0) -> 159489836
A25: =$A$11 -> FY 10 AVG SALARY | B25: =DSADATABASE!K7 -> 65177 | H25: =(G25*B26)*0.75 -> 0
A26: =$A$12 -> FY11 = FY10 @ 1% Roll-Up Plus 0% Cola | B26: =ROUND((B25*1.01)*1,0) -> 65829 | E26: =SUM(E22:E25) -> 2312.54 | F26: =SUM(F22:F25) -> 155556337 | G26: =SUM(G22:G25) -> 2312.54 | H26: =SUM(H22:H25) -> 158667464
A28: NON LICENSED | B28: =DSADATABASE!C28 -> 959.07 | C28: =ROUND(C$4/B29,2)-B28 -> -6.67 | E28: =(B28) -> 959.07 | G28: =(E32) -> 952.4
A29: STUDENT RATIO | B29: =ROUND(B$4/B28,2) -> 443.69 | D29: =ROUND(C28*DSADATABASE!K17,0) -> -195925 | E29: =(C28) -> -6.67 | F29: =ROUND(D29*1.02,0) -> -199844 | H29: =ROUND(F29*1.02,0) -> -203841
A30: 2%ROLL-UP | D30: =ROUND(B28*B32,0) -> 37937932 | F30: =ROUND(D30*1.02,0) -> 38696691 | H30: =ROUND((F30+F31)*1.02,0) -> 39470625
A31: =$A$11 -> FY 10 AVG SALARY | B31: =DSADATABASE!K8 -> 39165 | H31: =(G31*B32)*0.75 -> 0
A32: =$A$12 -> FY11 = FY10 @ 1% Roll-Up Plus 0% Cola | B32: =ROUND((B31*1.01)*1,0) -> 39557 | E32: =SUM(E28:E31) -> 952.4 | F32: =SUM(F28:F31) -> 38496847 | G32: =SUM(G28:G31) -> 952.4 | H32: =SUM(H28:H31) -> 39266784
A34: ADMINISTRATIVE SUPPORT PERSONNEL
A35: LICENSED | B35: =DSADATABASE!C29 -> 1405.47 | C35: =ROUND(C$4/B36,2)-B35 -> -9.79 | E35: =(B35) -> 1405.47 | G35: =(E39) -> 1395.68
A36: STUDENT RATIO | B36: =ROUND(B$4/B35,2) -> 302.77 | D36: =ROUND(C35*DSADATABASE!K18,0) -> -643967 | E36: =(C35) -> -9.79 | F36: =ROUND(D36*1.02,0) -> -656846 | H36: =ROUND(F36*1.02,0) -> -669983
A37: 2%ROLL-UP | D37: =ROUND(B35*B39,0) -> 124497938 | F37: =ROUND(D37*1.02,0) -> 126987897 | H37: =ROUND((F37+F38)*1.02,0) -> 129527655
A38: =$A$11 -> FY 10 AVG SALARY | B38: =DSADATABASE!K9 -> 87704 | H38: =(G38*B39)*0.75 -> 0
A39: =$A$12 -> FY11 = FY10 @ 1% Roll-Up Plus 0% Cola | B39: =ROUND((B38*1.01)*1,0) -> 88581 | E39: =SUM(E35:E38) -> 1395.68 | F39: =SUM(F35:F38) -> 126331051 | G39: =SUM(G35:G38) -> 1395.68 | H39: =SUM(H35:H38) -> 128857672
A41: NON-LICENSED | B41: =DSADATABASE!C30 -> 2881.37 | C41: =ROUND(C$4/B42,2)-B41 -> -19.98 | E41: =(B41) -> 2881.37 | G41: =(E45) -> 2861.39
A42: STUDENT RATIO | B42: =ROUND(B$4/B41,2) -> 147.68 | D42: =ROUND(C41*DSADATABASE!K19,0) -> -692447 | E42: =(C41) -> -19.98 | F42: =ROUND(D42*1.02,0) -> -706296 | H42: =ROUND(F42*1.02,0) -> -720422
A43: 2%ROLL-UP | D43: =ROUND(B41*B45,0) -> 133145226 | F43: =ROUND(D43*1.02,0) -> 135808131 | H43: =ROUND((F43+F44)*1.02,0) -> 138524294
A44: =$A$11 -> FY 10 AVG SALARY | B44: =DSADATABASE!K10 -> 46209 | H44: =(G44*B45)*0.75 -> 0
A45: =$A$12 -> FY11 = FY10 @ 1% Roll-Up Plus 0% Cola | B45: =ROUND((B44*1)*1,0) -> 46209 | E45: =SUM(E41:E44) -> 2861.39 | F45: =SUM(F41:F44) -> 135101835 | G45: =SUM(G41:G44) -> 2861.39 | H45: =SUM(H41:H44) -> 137803872
A47: OTHER LICENSED & NON-LICENSED | B47: =DSADATABASE!C31 -> 5844.97 | C47: =ROUND(C$4/B48,2)-B47 -> -40.44 | E47: =(B47) -> 5844.97 | G47: =(E51) -> 5804.53
...

Sheet M200SAL
A1: DISTRIBUTIVE SCHOOL ACCOUNT - DECISION M-200 SALARY
B2: =BASESAL!B2 -> FY10 | C2: =BASESAL!C2 -> FY11 | D2: =BASESAL!D2 -> FY11 | E2: =BASESAL!E2 -> FY12 | F2: =BASESAL!F2 -> FY12 | G2: =BASESAL!G2 -> FY13 | H2: =BASESAL!H2 -> FY13
B3: POS | C3: POS | D3: $ | E3: POS | F3: $ | G3: POS | H3: $
A4: WEIGHTED ENROLLMENT | B4: =BASESAL!B4 -> 425527.2 | C4: =BASESAL!C4 -> 422569.6 | E4: =BASESAL!E4 -> 421987.1 | G4: =BASESAL!G4 -> 423499.6
A5: AVG STARTING TEACHER SALARY | D5: =BASESAL!D5 -> 39166 | F5: =D5 -> 39166 | H5: =F5 -> 39166
A7: INSTRUCTIONAL PERSONNEL
A8: LICENSED | B8: =BASESAL!B8 -> 20489.15 | C8: =BASESAL!C8 -> -143.96 | E8: =(B8) -> 20489.15 | G8: =(E12) -> 20317.14
A9: STUDENT RATIO | B9: =BASESAL!B9 -> 20.77 | D9: =ROUND(C8*D5,0) -> -5638337 | E9: =(C8) -> -143.96 | F9: =ROUND(D9*1.02,0) -> -5751104 | H9: =ROUND(F9*1.02,0) -> -5866126
A10: 2%ROLL-UP | D10: =ROUND(B8*B12,0) -> 1105799426 | F10: =ROUND(D10*1.02,0) -> 1127915415 | H10: =ROUND((F10+F11)*1.02,0) -> 1149353145
A11: =BASESAL!A11 -> FY 10 AVG SALARY | B11: =BASESAL!B11 -> 53436 | E11: =ROUND((E$4/B9)-E8-E9,2) -> -28.05 | F11: =ROUND(E11*F5,0) -> -1098606 | G11: =ROUND((G$4/B9)-G8-G9,2) -> 72.83 | H11: =ROUND(G11*H5,0) -> 2852460
A12: =BASESAL!A12 -> FY11 = FY10 @ 1% Roll-Up Plus 0% Cola | B12: =BASESAL!B12 -> 53970 | E12: =SUM(E8:E11) -> 20317.14 | F12: =SUM(F8:F11) -> 1121065705 | G12: =SUM(G8:G11) -> 20389.97 | H12: =SUM(H8:H11) -> 1146339479
A14: INSTRUCTIONAL PERSONNEL
A15: NON-LICENSED | B15: =BASESAL!B15 -> 2051.3 | C15: =BASESAL!C15 -> -14.23 | E15: =(B15) -> 2051.3 | G15: =(E19) -> 2034.26
A16: STUDENT RATIO | B16: =BASESAL!B16 -> 207.44 | D16: =ROUND(C15*DSADATABASE!K15,0) -> -330819 | E16: =(C15) -> -14.23 | F16: =ROUND(D16*1.02,0) -> -337435 | H16: =ROUND(F16*1.02,0) -> -344184
A17: 2%ROLL-UP | D17: =ROUND(B15*B19,0) -> 64220049 | F17: =ROUND(D17*1.02,0) -> 65504450 | H17: =ROUND((F17+F18)*1.02,0) -> 66747905
A18: =$A$11 -> FY 10 AVG SALARY | B18: =BASESAL!B18 -> 30997 | E18: =ROUND((E$4/B16)-E15-E16,2) -> -2.81 | F18: =ROUND(E18*DSADATABASE!$K$15,0) -> -65327 | G18: =ROUND((G$4/B16)-G15-G16,2) -> 7.29 | H18: =ROUND(G18*DSADATABASE!$K$15,0) -> 169478
A19: =$A$12 -> FY11 = FY10 @ 1% Roll-Up Plus 0% Cola | B19: =BASESAL!B19 -> 31307 | E19: =SUM(E15:E18) -> 2034.26 | F19: =SUM(F15:F18) -> 65101688 | G19: =SUM(G15:G18) -> 2041.55 | H19: =SUM(H15:H18) -> 66573199
A21: INSTRUCTION SUPPORT PERSONNEL
A22: LICENSED | B22: =BASESAL!B22 -> 2328.71 | C22: =BASESAL!C22 -> -16.17 | E22: =(B22) -> 2328.71 | G22: =(E26) -> 2309.35
A23: STUDENT RATIO | B23: =BASESAL!B23 -> 182.73 | D23: =ROUND(C22*DSADATABASE!K16,0) -> -790438 | E23: =(C22) -> -16.17 | F23: =ROUND(D23*1.02,0) -> -806247 | H23: =ROUND(F23*1.02,0) -> -822372
A24: 2%ROLL-UP | D24: =ROUND(B22*B26,0) -> 153296651 | F24: =ROUND(D24*1.02,0) -> 156362584 | H24: =ROUND((F24+F25)*1.02,0) -> 159330780
A25: =$A$11 -> FY 10 AVG SALARY | B25: =BASESAL!B25 -> 65177 | E25: =ROUND((E$4/B23)-E22-E23,2) -> -3.19 | F25: =ROUND(E25*DSADATABASE!$K$16,0) -> -155937 | G25: =ROUND((G$4/B23)-G22-G23,2) -> 8.27 | H25: =ROUND(G25*DSADATABASE!$K$16,0) -> 404262
A26: =$A$12 -> FY11 = FY10 @ 1% Roll-Up Plus 0% Cola | B26: =BASESAL!B26 -> 65829 | E26: =SUM(E22:E25) -> 2309.35 | F26: =SUM(F22:F25) -> 155400400 | G26: =SUM(G22:G25) -> 2317.62 | H26: =SUM(H22:H25) -> 158912670
A28: NON-LICENSED | B28: =BASESAL!B28 -> 959.07 | C28: =BASESAL!C28 -> -6.67 | E28: =(B28) -> 959.07 | G28: =(E32) -> 951.09
A29: STUDENT RATIO | B29: =BASESAL!B29 -> 443.69 | D29: =ROUND(C28*DSADATABASE!K17,0) -> -195925 | E29: =(C28) -> -6.67 | F29: =ROUND(D29*1.02,0) -> -199844 | H29: =ROUND(F29*1.02,0) -> -203841
A30: 2%ROLL-UP | D30: =ROUND(B28*B32,0) -> 37937932 | F30: =ROUND(D30*1.02,0) -> 38696691 | H30: =ROUND((F30+F31)*1.02,0) -> 39431375
A31: =$A$11 -> FY 10 AVG SALARY | B31: =BASESAL!B31 -> 39165 | E31: =ROUND((E$4/B29)-E28-E29,2) -> -1.31 | F31: =ROUND(E31*DSADATABASE!$K$17,0) -> -38480 | G31: =ROUND((G$4/B29)-G28-G29,2) -> 3.4 | H31: =ROUND(G31*DSADATABASE!$K$17,0) -> 99872
A32: =$A$12 -> FY11 = FY10 @ 1% Roll-Up Plus 0% Cola | B32: =BASESAL!B32 -> 39557 | E32: =SUM(E28:E31) -> 951.09 | F32: =SUM(F28:F31) -> 38458367 | G32: =SUM(G28:G31) -> 954.49 | H32: =SUM(H28:H31) -> 39327406
A34: ADMINISTRATIVE SUPPORT PERSONNEL
A35: LICENSED | B35: =BASESAL!B35 -> 1405.47 | C35: =BASESAL!C35 -> -9.79 | E35: =(B35) -> 1405.47 | G35: =(E39) -> 1393.75
A36: STUDENT RATIO | B36: =BASESAL!B36 -> 302.77 | D36: =ROUND(C35*DSADATABASE!K18,0) -> -643967 | E36: =(C35) -> -9.79 | F36: =ROUND(D36*1.02,0) -> -656846 | H36: =ROUND(F36*1.02,0) -> -669983
A37: 2%ROLL-UP | D37: =ROUND(B35*B39,0) -> 124497938 | F37: =ROUND(D37*1.02,0) -> 126987897 | H37: =ROUND((F37+F38)*1.02,0) -> 129398164
A38: =$A$11 -> FY 10 AVG SALARY | B38: =BASESAL!B38 -> 87704 | E38: =ROUND((E$4/B36)-E35-E36,2) -> -1.93 | F38: =ROUND(E38*DSADATABASE!$K$18,0) -> -126952 | G38: =ROUND((G$4/B36)-G35-G36,2) -> 5 | H38: =ROUND(G38*DSADATABASE!$K$18,0) -> 328890
A39: =$A$12 -> FY11 = FY10 @ 1% Roll-Up Plus 0% Cola | B39: =BASESAL!B39 -> 88581 | E39: =SUM(E35:E38) -> 1393.75 | F39: =SUM(F35:F38) -> 126204099 | G39: =SUM(G35:G38) -> 1398.75 | H39: =SUM(H35:H38) -> 129057071
A41: NON-LICENSED | B41: =BASESAL!B41 -> 2881.37 | C41: =BASESAL!C41 -> -19.98 | E41: =(B41) -> 2881.37 | G41: =(E45) -> 2857.44
A42: STUDENT RATIO | B42: =BASESAL!B42 -> 147.68 | D42: =ROUND(C41*DSADATABASE!K19,0) -> -692447 | E42: =(C41) -> -19.98 | F42: =ROUND(D42*1.02,0) -> -706296 | H42: =ROUND(F42*1.02,0) -> -720422
A43: 2%ROLL-UP | D43: =ROUND(B41*B45,0) -> 133145226 | F43: =ROUND(D43*1.02,0) -> 135808131 | H43: =ROUND((F43+F44)*1.02,0) -> 138384661
A44: =$A$11 -> FY 10 AVG SALARY | B44: =BASESAL!B44 -> 46209 | E44: =ROUND((E$4/B42)-E41-E42,2) -> -3.95 | F44: =ROUND(E44*DSADATABASE!$K$19,0) -> -136895 | G44: =ROUND((G$4/B42)-G41-G42,2) -> 10.24 | H44: =ROUND(G44*DSADATABASE!$K$19,0) -> 354888
A45: =$A$12 -> FY11 = FY10 @ 1% Roll-Up Plus 0% Cola | B45: =BASESAL!B45 -> 46209 | E45: =SUM(E41:E44) -> 2857.44 | F45: =SUM(F41:F44) -> 134964940 | G45: =SUM(G41:G44) -> 2867.68 | H45: =SUM(H41:H44) -> 138019127
A47: OTHER LICENSED & NON-LICENSED | B47: =BASESAL!B47 -> 5844.97 | C47: =BASESAL!C47 -> -40.44 | E47: =(B47) -> 5844.97 | G47: =(E51) -> 5796.53
...

Sheet M300SAL
A1: DISTRIBUTIVE SCHOOL ACCOUNT - DECISION M-300 SALARY
B2: =BASESAL!B2 -> FY10 | C2: =BASESAL!C2 -> FY11 | D2: =BASESAL!D2 -> FY11 | E2: =BASESAL!E2 -> FY12 | F2: =BASESAL!F2 -> FY12 | G2: =BASESAL!G2 -> FY13 | H2: =BASESAL!H2 -> FY13
B3: POS | C3: POS | D3: $ | E3: POS | F3: $ | G3: POS | H3: $
