Workbook

Sheet instruction-districts
B1: Full-Time Equivalents (FTEs) by Position
B2: Licensed and Classified Personnel
B3: FY 2009
B5: Local Education Agencies | C5: INSTRUCTION | K5: SUPPORT
C6: CLASSROOM TEACHERS | I6: Instructional Aides | J6: Instructional Coordinators and Supervisors | K6: Elementary Guidance Counselors | L6: Secondary Guidance Counselors | M6: Librarians and Media Specialists | N6: Library and Media Support Staff
C7: Pre-Kindergarten | E7: Kindergarten | F7: Elementary | G7: Secondary | H7: Special Education
C8: Regular | D8: Special
C9: CACTUS Database | D9: CACTUS Database | E9: CACTUS Database | F9: CACTUS Database | G9: CACTUS Database | H9: CACTUS Database | I9: Classified Personnel Report | J9: CACTUS Database | K9: CACTUS Database | L9: CACTUS Database | M9: CACTUS Database | N9: Classified Personnel Report
B10: DISTRICT
A11: 1 | B11: Alpine | C11: 8 | D11: 16.53 | E11: 105.12 | F11: 1203.71 | G11: 966.72 | H11: 222.86 | I11: 599.19 | J11: ='Licensed FTEs'!K5+'Licensed FTEs'!L5 -> 108.34 | K11: 0 | L11: 66.88 | M11: 18.5 | N11: 57.16
A12: 2 | B12: Beaver | C12: 0.5 | D12: 0 | E12: 3 | F12: 37.45 | G12: 30.28 | H12: 7.35 | I12: 36.02 | J12: ='Licensed FTEs'!K6+'Licensed FTEs'!L6 -> 1.6 | K12: 0 | L12: 2.01 | M12: 0 | N12: 2.86
A13: 3 | B13: Box Elder | C13: 1 | D13: 8 | E13: 24.03 | F13: 168.39 | G13: 220.33 | H13: 44.82 | I13: 213 | J13: ='Licensed FTEs'!K7+'Licensed FTEs'!L7 -> 9.06 | K13: 0.5 | L13: 15 | M13: 5 | N13: 12
A14: 4 | B14: Cache | C14: 0 | D14: 5 | E14: 26.5 | F14: 235.68 | G14: 271.31 | H14: 56.85 | I14: 301.56 | J14: ='Licensed FTEs'!K8+'Licensed FTEs'!L8 -> 33.69 | K14: 0 | L14: 18.88 | M14: 20 | N14: 0
A15: 5 | B15: Carbon | C15: 0 | D15: 2 | E15: 11 | F15: 67.01 | G15: 65.13 | H15: 20.74 | I15: 80.86 | J15: ='Licensed FTEs'!K9+'Licensed FTEs'!L9 -> 16.03 | K15: 1 | L15: 6.24 | M15: 0.83 | N15: 3.43
A16: 6 | B16: Daggett | C16: 0 | D16: 0 | E16: 1 | F16: 4.9 | G16: 6.29 | H16: 0.58 | I16: 5.13 | J16: ='Licensed FTEs'!K10+'Licensed FTEs'!L10 -> 2.96 | K16: 0 | L16: 0 | M16: 0.25 | N16: 0
A17: 7 | B17: Davis | C17: 2.67 | D17: 15.83 | E17: 129.09 | F17: 1204.14 | G17: 1143.09 | H17: 286.5 | I17: 1131.55 | J17: ='Licensed FTEs'!K11+'Licensed FTEs'!L11 -> 158.86 | K17: 37.65 | L17: 87.3 | M17: 17.5 | N17: 60.27
A18: 8 | B18: Duchesne | C18: 0 | D18: 1 | E18: 11.5 | F18: 94.64 | G18: 85.74 | H18: 24.86 | I18: 88.76 | J18: ='Licensed FTEs'!K12+'Licensed FTEs'!L12 -> 2.98 | K18: 0 | L18: 3.85 | M18: 6 | N18: 4.93
A19: 9 | B19: Emery | C19: 0 | D19: 1 | E19: 6.51 | F19: 49 | G19: 50.55 | H19: 12.02 | I19: 35.51 | J19: ='Licensed FTEs'!K13+'Licensed FTEs'!L13 -> 2.67 | K19: 0 | L19: 0.5 | M19: 1.1 | N19: 8.52
A20: 10 | B20: Garfield | C20: 0.5 | D20: 0 | E20: 3.66 | F20: 23.84 | G20: 31.18 | H20: 5.93 | I20: 24.71 | J20: ='Licensed FTEs'!K14+'Licensed FTEs'!L14 -> 4.82 | K20: 0.8 | L20: 1.7 | M20: 0 | N20: 4.49
A21: 11 | B21: Grand | C21: 0 | D21: 1 | E21: 5 | F21: 30.54 | G21: 39.47 | H21: 8.5 | I21: 45.5 | J21: ='Licensed FTEs'!K15+'Licensed FTEs'!L15 -> 2.83 | K21: 0 | L21: 2 | M21: 2 | N21: 0
A22: 12 | B22: Granite | C22: 11 | D22: 26.25 | E22: 142.92 | F22: 1221.27 | G22: 1142.42 | H22: 310.2 | I22: 616.93 | J22: ='Licensed FTEs'!K16+'Licensed FTEs'!L16 -> 278.22 | K22: 1 | L22: 83.18 | M22: 20.58 | N22: 32.97
... A50: 35 | B50: Weber | C50: 0 | D50: 9 | E50: 58.5 | F50: 545.18 | G50: 502.18 | H50: 154.02 | I50: 332.98 | J50: ='Licensed FTEs'!K44+'Licensed FTEs'!L44 -> 44.07 | K50: 16.15 | L50: 38.15 | M50: 12.83 | N50: 27.2
B51: DISTRICT TOTAL | C51: =SUM(C11:C50) -> 43.64 | D51: =SUM(D11:D50) -> 196.25 | E51: =SUM(E11:E50) -> 1094.01 | F51: =SUM(F11:F50) -> 9680.44 | G51: =SUM(G11:G50) -> 9055.62 | H51: =SUM(H11:H50) -> 2350.64 | I51: =SUM(I11:I50) -> 7471.23 | J51: =SUM(J11:J50) -> 1486.34 | ... N51: =SUM(N11:N50) -> 477.36
B52: CHARTER TOTAL | C52: 3.5 | D52: 0 | E52: 54.3 | F52: 583.69 | G52: 506.81 | H52: 85.24 | I52: 461.21 | J52: 39.47 | K52: 4.58 | L52: 22 | M52: 11.97 | N52: 24.5
B53: GRAND TOTAL | C53: =C51+C52 -> 47.14 | D53: =D51+D52 -> 196.25 | E53: =E51+E52 -> 1148.31 | F53: =F51+F52 -> 10264.13 | G53: =G51+G52 -> 9562.43 | H53: =H51+H52 -> 2435.88 | I53: =I51+I52 -> 7932.44 | J53: =J51+J52 -> 1525.81 | ... N53: =N51+N52 -> 501.86
B55: Note: School-Based Specialists were added as a new Educator Category in FY09. They are included with Instructional Coordinators and Supervisors, but some had been counted as Classroom Teachers in previous years.

Sheet instruction-charters
B1: Full-Time Equivalents (FTEs) by Position
B2: Licensed and Classified Personnel
B3: FY 2009
B5: Local Education Agencies | C5: INSTRUCTION | K5: SUPPORT
C6: CLASSROOM TEACHERS | I6: Instructional Aides | J6: Instructional Coordinators and Supervisors | K6: Elementary Guidance Counselors | L6: Secondary Guidance Counselors | M6: Librarians and Media Specialists | N6: Library and Media Support Staff
C7: Pre-Kindergarten | E7: Kindergarten | F7: Elementary | G7: Secondary | H7: Special Education
C8: Regular | D8: Special
C9: CACTUS Database | D9: CACTUS Database | E9: CACTUS Database | F9: CACTUS Database | G9: CACTUS Database | H9: CACTUS Database | I9: Classified Personnel Report | J9: CACTUS Database | K9: CACTUS Database | L9: CACTUS Database | M9: CACTUS Database | N9: Classified Personnel Report
B10: CHARTER SCHOOL
A11: 8B | B11: American Leadership Academy | C11: 2 | D11: 0 | E11: 1 | F11: 26.5 | G11: 37.29 | H11: 6.5 | I11: ='Classified FTEs'!C49 -> 14.73 | J11: ='Licensed FTEs'!K46+'Licensed FTEs'!L46 -> 7.12 | K11: 0.5 | L11: 1 | M11: 0 | N11: ='Classified FTEs'!G49 -> 1
A12: 74 | B12: American Preparatory Academy | C12: 0 | D12: 0 | E12: 1 | F12: 12.6 | G12: 10.47 | H12: 1 | I12: ='Classified FTEs'!C50 -> 14.9 | J12: ='Licensed FTEs'!K47+'Licensed FTEs'!L47 -> 0.5 | K12: 0.13 | L12: 0.09 | M12: 0 | N12: ='Classified FTEs'!G50 -> 0
A13: 83 | B13: AMES | C13: 0 | D13: 0 | E13: 0 | F13: 0 | G13: 19.76 | H13: 0.5 | I13: ='Classified FTEs'!C51 -> 4.13 | J13: ='Licensed FTEs'!K48+'Licensed FTEs'!L48 -> 0.16 | K13: 0 | L13: 1.5 | M13: 0 | N13: ='Classified FTEs'!G51 -> 0
A14: 3B | B14: BSTA | C14: 0 | D14: 0 | E14: 0 | F14: 0 | G14: 13.67 | H14: 1.2 | I14: ='Classified FTEs'!C52 -> 0 | J14: ='Licensed FTEs'!K49+'Licensed FTEs'!L49 -> 0 | K14: 0 | L14: 0 | M14: 0 | N14: ='Classified FTEs'!G52 -> 0
A15: 9D | B15: Canyon Rim Academy | C15: 0 | D15: 0 | E15: 2 | F15: 18 | G15: 0 | H15: 1 | I15: ='Classified FTEs'!C53 -> 8.65 | J15: ='Licensed FTEs'!K50+'Licensed FTEs'!L50 -> 0 | K15: 0 | L15: 0 | M15: 0 | N15: ='Classified FTEs'!G53 -> 0
A16: 84 | B16: CBA Center | C16: 0 | D16: 0 | E16: 0 | F16: 0 | G16: 0 | H16: 0 | I16: ='Classified FTEs'!C54 -> 1.25 | J16: ='Licensed FTEs'!K51+'Licensed FTEs'!L51 -> 0 | K16: 0 | L16: 0 | M16: 0 | N16: ='Classified FTEs'!G54 -> 0
A17: 2D | B17: Channing Hall | C17: 0 | D17: 0 | E17: 2 | F17: 14.7 | G17: 10.04 | H17: 1.1 | I17: ='Classified FTEs'!C55 -> 11.1 | J17: ='Licensed FTEs'!K52+'Licensed FTEs'!L52 -> 1.11 | K17: 0 | L17: 0 | M17: 0 | N17: ='Classified FTEs'!G55 -> 1.47
A18: 87 | B18: City Academy | C18: 0 | D18: 0 | E18: 0 | F18: 0 | G18: 13.71 | H18: 0.11 | I18: ='Classified FTEs'!C56 -> 6.66 | J18: ='Licensed FTEs'!K53+'Licensed FTEs'!L53 -> 2.08 | K18: 0 | L18: 1 | M18: 0 | N18: ='Classified FTEs'!G56 -> 0.69
A19: 3E | B19: C.S. Lewis Academy | C19: 0 | D19: 0 | E19: 2 | F19: 13.75 | G19: 1 | H19: 1.5 | I19: ='Classified FTEs'!C57 -> 3 | J19: ='Licensed FTEs'!K54+'Licensed FTEs'!L54 -> 0.25 | K19: 0 | L19: 0 | M19: 0 | N19: ='Classified FTEs'!G57 -> 0
A20: A3 | B20: DaVinci Academy | C20: 0 | D20: 0 | E20: 0 | F20: 0 | G20: 15.62 | H20: 1.67 | I20: ='Classified FTEs'!C58 -> 2.8 | J20: ='Licensed FTEs'!K55+'Licensed FTEs'!L55 -> 0 | K20: 0 | L20: 1 | M20: 0.5 | N20: ='Classified FTEs'!G58 -> 0
A21: 4E | B21: Dual Immersion Academy | C21: 0 | D21: 0 | E21: 4 | F21: 8 | G21: 0 | H21: 1 | I21: ='Classified FTEs'!C59 -> 7 | J21: ='Licensed FTEs'!K56+'Licensed FTEs'!L56 -> 0 | K21: 0 | L21: 0 | M21: 0 | N21: ='Classified FTEs'!G59 -> 0
A22: A8 | B22: East Hollywood High | C22: 0 | D22: 0 | E22: 0 | F22: 0 | G22: 17.15 | H22: 0 | I22: ='Classified FTEs'!C60 -> 2.5 | J22: ='Licensed FTEs'!K57+'Licensed FTEs'!L57 -> 1.25 | K22: 0 | L22: 1 | M22: 0.13 | N22: ='Classified FTEs'!G60 -> 0.75
A23: 5E | B23: Edith Bowen Lab School | C23: 0 | D23: 0 | E23: 0 | F23: 14.5 | G23: 0 | H23: 1 | I23: ='Classified FTEs'!C61 -> 0.38 | J23: ='Licensed FTEs'!K58+'Licensed FTEs'!L58 -> 0 | K23: 0 | L23: 0 | M23: 2.6 | N23: ='Classified FTEs'!G61 -> 0
A24: 3C | B24: Entheos Academy | C24: 0 | D24: 0 | E24: 1 | F24: 10.22 | G24: 6 | H24: 0.91 | I24: ='Classified FTEs'!C62 -> 6.6 | J24: ='Licensed FTEs'!K59+'Licensed FTEs'!L59 -> 0 | K24: 0 | L24: 0 | M24: 0 | N24: ='Classified FTEs'!G62 -> 0.6
A25: 98 | B25: Fast Forward High | C25: 0 | D25: 0 | E25: 0 | F25: 0 | G25: 13 | H25: 0.9 | I25: ='Classified FTEs'!C63 -> 2.5 | J25: ='Licensed FTEs'!K60+'Licensed FTEs'!L60 -> 0.1 | K25: 0 | L25: 1.1 | M25: 0 | N25: ='Classified FTEs'!G63 -> 0.5
A26: 82 | B26: Freedom Academy | C26: 0 | D26: 0 | E26: 2.5 | F26: 18.51 | G26: 6.46 | H26: 2.5 | I26: ='Classified FTEs'!C64 -> 9.75 | J26: ='Licensed FTEs'!K61+'Licensed FTEs'!L61 -> 1.65 | K26: 0 | L26: 0 | M26: 0 | N26: ='Classified FTEs'!G64 -> 0.5
A27: 7E | B27: Gateway Preparatory Academy | C27: 0 | D27: 0 | E27: 1 | F27: 19.5 | G27: 4.75 | H27: 1 | I27: ='Classified FTEs'!C65 -> 21.75 | J27: ='Licensed FTEs'!K62+'Licensed FTEs'!L62 -> 1.5 | K27: 0 | L27: 0 | M27: 0 | N27: ='Classified FTEs'!G65 -> 1.43
A28: 5D | B28: George Washington Academy | C28: 0 | D28: 0 | E28: 2 | F28: 16.45 | G28: 0.55 | H28: 1 | I28: ='Classified FTEs'!C66 -> 4.95 | J28: ='Licensed FTEs'!K63+'Licensed FTEs'!L63 -> 0.5 | K28: 0 | L28: 0 | M28: 0 | N28: ='Classified FTEs'!G66 -> 0.18
A29: 1E | B29: Guadalupe School | C29: 0 | D29: 0 | E29: 0 | F29: 3 | G29: 0 | H29: 0.39 | I29: ='Classified FTEs'!C67 -> 4.5 | J29: ='Licensed FTEs'!K64+'Licensed FTEs'!L64 -> 0.51 | K29: 0 | L29: 0 | M29: 0 | N29: ='Classified FTEs'!G67 -> 0.5
A30: 2C | B30: Intech Collegiate High | C30: 0 | D30: 0 | E30: 0 | F30: 0 | G30: 6 | H30: 0 | I30: ='Classified FTEs'!C68 -> 1.63 | J30: ='Licensed FTEs'!K65+'Licensed FTEs'!L65 -> 0.59 | K30: 0 | L30: 0.65 | M30: 0 | N30: ='Classified FTEs'!G68 -> 0
A31: A5 | B31: Itineris Early College High | C31: 0 | D31: 0 | E31: 0 | F31: 0 | G31: 10.38 | H31: 0 | I31: ='Classified FTEs'!C69 -> 0 | J31: ='Licensed FTEs'!K66+'Licensed FTEs'!L66 -> 0 | K31: 0 | L31: 2 | M31: 0 | N31: ='Classified FTEs'!G69 -> 0
A32: 93 | B32: John Hancock | C32: 0 | D32: 0 | E32: 0.72 | F32: 8 | G32: 2.33 | H32: 1 | I32: ='Classified FTEs'!C70 -> 5.12 | J32: ='Licensed FTEs'!K67+'Licensed FTEs'!L67 -> 0 | K32: 0 | L32: 0 | M32: 0 | N32: ='Classified FTEs'!G70 -> 0.09
A33: 2E | B33: Karl G. Maeser Prep Academy | C33: 0 | D33: 0 | E33: 0 | F33: 0 | G33: 13.25 | H33: 0.66 | I33: ='Classified FTEs'!C71 -> 0 | J33: ='Licensed FTEs'!K68+'Licensed FTEs'!L68 -> 0.66 | K33: 0 | L33: 0 | M33: 0.5 | N33: ='Classified FTEs'!G71 -> 0
A34: 4C | B34: Lakeview Academy | C34: 0 | D34: 0 | E34: 1 | F34: 22 | G34: 8.64 | H34: 3.29 | I34: ='Classified FTEs'!C72 -> 19.75 | J34: ='Licensed FTEs'!K69+'Licensed FTEs'!L69 -> 1 | K34: 0 | L34: 0.3 | M34: 1 | N34: ='Classified FTEs'!G72 -> 0
A35: 5C | B35: Legacy Prep Academy | C35: 0 | D35: 0 | E35: 0 | F35: 11.31 | G35: 8.13 | H35: 1.17 | I35: ='Classified FTEs'!C73 -> 23.76 | J35: ='Licensed FTEs'!K70+'Licensed FTEs'!L70 -> 0 | K35: 1 | L35: 0 | M35: 0 | N35: ='Classified FTEs'!G73 -> 1
A36: 6C | B36: Liberty Academy | C36: 0 | D36: 0 | E36: 2 | F36: 7.56 | G36: 1 | H36: 0.63 | I36: ='Classified FTEs'!C74 -> 13 | J36: ='Licensed FTEs'!K71+'Licensed FTEs'!L71 -> 0.88 | K36: 0 | L36: 0 | M36: 0 | N36: ='Classified FTEs'!G74 -> 0.88
A37: 2B | B37: Lincoln Academy | C37: 0.5 | D37: 0 | E37: 0.5 | F37: 11 | G37: 6.5 | H37: 2 | I37: ='Classified FTEs'!C75 -> 22.34 | J37: ='Licensed FTEs'!K72+'Licensed FTEs'!L72 -> 0 | K37: 0 | L37: 0.5 | M37: 0 | N37: ='Classified FTEs'!G75 -> 1
A38: 8E | B38: Merit College Prep Academy | C38: 0 | D38: 0 | E38: 0 | F38: 0 | G38: 18.25 | H38: 2 | I38: ='Classified FTEs'!C76 -> 0 | J38: ='Licensed FTEs'!K73+'Licensed FTEs'!L73 -> 0 | K38: 0 | L38: 1 | M38: 0 | N38: ='Classified FTEs'!G76 -> 0
A39: A7 | B39: Moab Community School | C39: 0 | D39: 0 | E39: 0.31 | F39: 3.05 | G39: 0 | H39: 1 | I39: ='Classified FTEs'!C77 -> 1.76 | J39: ='Licensed FTEs'!K74+'Licensed FTEs'!L74 -> 0 | K39: 0 | L39: 0 | M39: 0 | N39: ='Classified FTEs'!G77 -> 0
A40: 7C | B40: Monticello Academy | C40: 0 | D40: 0 | E40: 2.02 | F40: 13.29 | G40: 15.39 | H40: 1.14 | I40: ='Classified FTEs'!C78 -> 6.24 | J40: ='Licensed FTEs'!K75+'Licensed FTEs'!L75 -> 0.15 | K40: 0 | L40: 0.32 | M40: 0 | N40: ='Classified FTEs'!G78 -> 1
A41: 8C | B41: Mountainville Academy | C41: 0 | D41: 0 | E41: 1.5 | F41: 15.63 | G41: 4.04 | H41: 0 | I41: ='Classified FTEs'!C79 -> 12 | J41: ='Licensed FTEs'!K76+'Licensed FTEs'!L76 -> 1 | K41: 0 | L41: 0 | M41: 1 | N41: ='Classified FTEs'!G79 -> 0
...

Sheet support-districts
B1: Full-Time Equivalents (FTEs) by Position
B2: Licensed and Classified Personnel
B3: FY 2009
B5: Local Education Agencies | C5: SUPPORT | M5: TOTAL FTEs
C6: LEA Administrators | E6: LEA Administrative Support Staff | F6: School Administrators | G6: School Administrative Support Staff | H6: Student Support Services Staff | L6: Other Support Staff
H8: Student Support Services | I8: Student Transportation Supervisors | J8: School Food Services Supervisors | K8: School Nurses
C9: CACTUS Database | D9: Classified Personnel Report | E9: Classified Personnel Report | F9: CACTUS Database | G9: Classified Personnel Report | H9: CACTUS Database | I9: Classified Personnel Report | J9: Classified Personnel Report | K9: Classified Personnel Report | L9: Classified Personnel Report
B10: DISTRICT
A11: 1 | B11: Alpine | C11: 22 | D11: ='Classified FTEs'!H7+'Classified FTEs'!K7 -> 1 | E11: ='Classified FTEs'!I7+'Classified FTEs'!L7+'Classified FTEs'!M7+'Classified FTEs'!N7+'Classified FTEs'!O7 -> 101.12 | F11: 107 | G11: ='Classified FTEs'!E7+'Classified FTEs'!F7+'Classified FTEs'!J7 -> 214.46 | H11: 75.15 | I11: ='Classified FTEs'!V7 -> 4 | J11: ='Classified FTEs'!AD7 -> 5 | K11: ='Classified FTEs'!D7 -> 0 | L11: ='Classified FTEs'!T7+'Classified FTEs'!U7+'Classified FTEs'!W7+'Classified FTEs'!X7+'Classified FTEs'!Y7+'Classified FTEs'!AC7+'Classified FTEs'!AE7+'Classified FTEs'!AF7+'Classified FTEs'!AL7 -> 835.81 | M11: =SUM(C11:L11)+SUM('instruction-districts'!C11:N11) -> 4738.55
A12: 2 | B12: Beaver | C12: 2.75 | D12: ='Classified FTEs'!H8+'Classified FTEs'!K8 -> 0 | E12: ='Classified FTEs'!I8+'Classified FTEs'!L8+'Classified FTEs'!M8+'Classified FTEs'!N8+'Classified FTEs'!O8 -> 2.43 | F12: 2.78 | G12: ='Classified FTEs'!E8+'Classified FTEs'!F8+'Classified FTEs'!J8 -> 5.89 | H12: 0.75 | I12: ='Classified FTEs'!V8 -> 0 | J12: ='Classified FTEs'!AD8 -> 0 | K12: ='Classified FTEs'!D8 -> 0.2 | L12: ='Classified FTEs'!T8+'Classified FTEs'!U8+'Classified FTEs'!W8+'Classified FTEs'!X8+'Classified FTEs'!Y8+'Classified FTEs'!AC8+'Classified FTEs'!AE8+'Classified FTEs'!AF8+'Classified FTEs'!AL8 -> 27.78 | M12: =SUM(C12:L12)+SUM('instruction-districts'!C12:N12) -> 163.65
A13: 3 | B13: Box Elder | C13: 4.5 | D13: ='Classified FTEs'!H9+'Classified FTEs'!K9 -> 5 | E13: ='Classified FTEs'!I9+'Classified FTEs'!L9+'Classified FTEs'!M9+'Classified FTEs'!N9+'Classified FTEs'!O9 -> 7 | F13: 26.3 | G13: ='Classified FTEs'!E9+'Classified FTEs'!F9+'Classified FTEs'!J9 -> 46 | H13: 20.73 | I13: ='Classified FTEs'!V9 -> 1 | J13: ='Classified FTEs'!AD9 -> 1 | K13: ='Classified FTEs'!D9 -> 3 | L13: ='Classified FTEs'!T9+'Classified FTEs'!U9+'Classified FTEs'!W9+'Classified FTEs'!X9+'Classified FTEs'!Y9+'Classified FTEs'!AC9+'Classified FTEs'!AE9+'Classified FTEs'!AF9+'Classified FTEs'!AL9 -> 249 | M13: =SUM(C13:L13)+SUM('instruction-districts'!C13:N13) -> 1084.66
A14: 4 | B14: Cache | C14: 3.33 | D14: ='Classified FTEs'!H10+'Classified FTEs'!K10 -> 1 | E14: ='Classified FTEs'!I10+'Classified FTEs'!L10+'Classified FTEs'!M10+'Classified FTEs'!N10+'Classified FTEs'!O10 -> 18.79 | F14: 27.27 | G14: ='Classified FTEs'!E10+'Classified FTEs'!F10+'Classified FTEs'!J10 -> 36.24 | H14: 33.92 | I14: ='Classified FTEs'!V10 -> 3.66 | J14: ='Classified FTEs'!AD10 -> 23 | K14: ='Classified FTEs'!D10 -> 2.5 | L14: ='Classified FTEs'!T10+'Classified FTEs'!U10+'Classified FTEs'!W10+'Classified FTEs'!X10+'Classified FTEs'!Y10+'Classified FTEs'!AC10+'Classified FTEs'!AE10+'Classified FTEs'!AF10+'Classified FTEs'!AL10 -> 256.37 | M14: =SUM(C14:L14)+SUM('instruction-districts'!C14:N14) -> 1375.55
A15: 5 | B15: Carbon | C15: 6 | D15: ='Classified FTEs'!H11+'Classified FTEs'!K11 -> 3 | E15: ='Classified FTEs'!I11+'Classified FTEs'!L11+'Classified FTEs'!M11+'Classified FTEs'!N11+'Classified FTEs'!O11 -> 16.92 | F15: 11 | G15: ='Classified FTEs'!E11+'Classified FTEs'!F11+'Classified FTEs'!J11 -> 15.52 | H15: 4.5 | I15: ='Classified FTEs'!V11 -> 1 | J15: ='Classified FTEs'!AD11 -> 0.5 | K15: ='Classified FTEs'!D11 -> 0 | L15: ='Classified FTEs'!T11+'Classified FTEs'!U11+'Classified FTEs'!W11+'Classified FTEs'!X11+'Classified FTEs'!Y11+'Classified FTEs'!AC11+'Classified FTEs'!AE11+'Classified FTEs'!AF11+'Classified FTEs'!AL11 -> 66.95 | M15: =SUM(C15:L15)+SUM('instruction-districts'!C15:N15) -> 399.66
A16: 6 | B16: Daggett | C16: 0.88 | D16: ='Classified FTEs'!H12+'Classified FTEs'!K12 -> 0.85 | E16: ='Classified FTEs'!I12+'Classified FTEs'!L12+'Classified FTEs'!M12+'Classified FTEs'!N12+'Classified FTEs'!O12 -> 1 | F16: 0.76 | G16: ='Classified FTEs'!E12+'Classified FTEs'!F12+'Classified FTEs'!J12 -> 1.5 | H16: 0 | I16: ='Classified FTEs'!V12 -> 0 | J16: ='Classified FTEs'!AD12 -> 0 | K16: ='Classified FTEs'!D12 -> 0 | L16: ='Classified FTEs'!T12+'Classified FTEs'!U12+'Classified FTEs'!W12+'Classified FTEs'!X12+'Classified FTEs'!Y12+'Classified FTEs'!AC12+'Classified FTEs'!AE12+'Classified FTEs'!AF12+'Classified FTEs'!AL12 -> 8.7 | M16: =SUM(C16:L16)+SUM('instruction-districts'!C16:N16) -> 34.8
A17: 7 | B17: Davis | C17: 26 | D17: ='Classified FTEs'!H13+'Classified FTEs'!K13 -> 13 | E17: ='Classified FTEs'!I13+'Classified FTEs'!L13+'Classified FTEs'!M13+'Classified FTEs'!N13+'Classified FTEs'!O13 -> 131.21 | F17: 174.52 | G17: ='Classified FTEs'!E13+'Classified FTEs'!F13+'Classified FTEs'!J13 -> 259.27 | H17: 98.69 | I17: ='Classified FTEs'!V13 -> 2 | J17: ='Classified FTEs'!AD13 -> 6.45 | K17: ='Classified FTEs'!D13 -> 0 | L17: ='Classified FTEs'!T13+'Classified FTEs'!U13+'Classified FTEs'!W13+'Classified FTEs'!X13+'Classified FTEs'!Y13+'Classified FTEs'!AC13+'Classified FTEs'!AE13+'Classified FTEs'!AF13+'Classified FTEs'!AL13 -> 1057.92 | M17: =SUM(C17:L17)+SUM('instruction-districts'!C17:N17) -> 6043.51
A18: 8 | B18: Duchesne | C18: 3 | D18: ='Classified FTEs'!H14+'Classified FTEs'!K14 -> 1 | E18: ='Classified FTEs'!I14+'Classified FTEs'!L14+'Classified FTEs'!M14+'Classified FTEs'!N14+'Classified FTEs'!O14 -> 10.5 | F18: 12.65 | G18: ='Classified FTEs'!E14+'Classified FTEs'!F14+'Classified FTEs'!J14 -> 19.73 | H18: 2 | I18: ='Classified FTEs'!V14 -> 1 | J18: ='Classified FTEs'!AD14 -> 1 | K18: ='Classified FTEs'!D14 -> 1 | L18: ='Classified FTEs'!T14+'Classified FTEs'!U14+'Classified FTEs'!W14+'Classified FTEs'!X14+'Classified FTEs'!Y14+'Classified FTEs'!AC14+'Classified FTEs'!AE14+'Classified FTEs'!AF14+'Classified FTEs'!AL14 -> 93.69 | M18: =SUM(C18:L18)+SUM('instruction-districts'!C18:N18) -> 469.83
A19: 9 | B19: Emery | C19: 4 | D19: ='Classified FTEs'!H15+'Classified FTEs'!K15 -> 1 | E19: ='Classified FTEs'!I15+'Classified FTEs'!L15+'Classified FTEs'!M15+'Classified FTEs'!N15+'Classified FTEs'!O15 -> 3 | F19: 9.49 | G19: ='Classified FTEs'!E15+'Classified FTEs'!F15+'Classified FTEs'!J15 -> 11.88 | H19: 2 | I19: ='Classified FTEs'!V15 -> 1 | J19: ='Classified FTEs'!AD15 -> 1 | K19: ='Classified FTEs'!D15 -> 0 | L19: ='Classified FTEs'!T15+'Classified FTEs'!U15+'Classified FTEs'!W15+'Classified FTEs'!X15+'Classified FTEs'!Y15+'Classified FTEs'!AC15+'Classified FTEs'!AE15+'Classified FTEs'!AF15+'Classified FTEs'!AL15 -> 56.95 | M19: =SUM(C19:L19)+SUM('instruction-districts'!C19:N19) -> 257.7
A20: 10 | B20: Garfield | C20: 2.47 | D20: ='Classified FTEs'!H16+'Classified FTEs'!K16 -> 2 | E20: ='Classified FTEs'!I16+'Classified FTEs'!L16+'Classified FTEs'!M16+'Classified FTEs'!N16+'Classified FTEs'!O16 -> 2 | F20: 5.44 | G20: ='Classified FTEs'!E16+'Classified FTEs'!F16+'Classified FTEs'!J16 -> 7 | H20: 1 | I20: ='Classified FTEs'!V16 -> 1 | J20: ='Classified FTEs'!AD16 -> 1 | K20: ='Classified FTEs'!D16 -> 0.5 | L20: ='Classified FTEs'!T16+'Classified FTEs'!U16+'Classified FTEs'!W16+'Classified FTEs'!X16+'Classified FTEs'!Y16+'Classified FTEs'!AC16+'Classified FTEs'!AE16+'Classified FTEs'!AF16+'Classified FTEs'!AL16 -> 20.57 | M20: =SUM(C20:L20)+SUM('instruction-districts'!C20:N20) -> 144.61
A21: 11 | B21: Grand | C21: 1 | D21: ='Classified FTEs'!H17+'Classified FTEs'!K17 -> 1 | E21: ='Classified FTEs'!I17+'Classified FTEs'!L17+'Classified FTEs'!M17+'Classified FTEs'!N17+'Classified FTEs'!O17 -> 4 | F21: 6 | G21: ='Classified FTEs'!E17+'Classified FTEs'!F17+'Classified FTEs'!J17 -> 9 | H21: 2 | I21: ='Classified FTEs'!V17 -> 1 | J21: ='Classified FTEs'!AD17 -> 1 | K21: ='Classified FTEs'!D17 -> 0 | L21: ='Classified FTEs'!T17+'Classified FTEs'!U17+'Classified FTEs'!W17+'Classified FTEs'!X17+'Classified FTEs'!Y17+'Classified FTEs'!AC17+'Classified FTEs'!AE17+'Classified FTEs'!AF17+'Classified FTEs'!AL17 -> 39.5 | M21: =SUM(C21:L21)+SUM('instruction-districts'!C21:N21) -> 201.34
A22: 12 | B22: Granite | C22: 37.71 | D22: ='Classified FTEs'!H18+'Classified FTEs'!K18 -> 1 | E22: ='Classified FTEs'!I18+'Classified FTEs'!L18+'Classified FTEs'!M18+'Classified FTEs'!N18+'Classified FTEs'!O18 -> 102.6 | F22: 136.23 | G22: ='Classified FTEs'!E18+'Classified FTEs'!F18+'Classified FTEs'!J18 -> 306.25 | H22: 146.08 | I22: ='Classified FTEs'!V18 -> 2 | J22: ='Classified FTEs'!AD18 -> 34.56 | K22: ='Classified FTEs'!D18 -> 20.83 | L22: ='Classified FTEs'!T18+'Classified FTEs'!U18+'Classified FTEs'!W18+'Classified FTEs'!X18+'Classified FTEs'!Y18+'Classified FTEs'!AC18+'Classified FTEs'!AE18+'Classified FTEs'!AF18+'Classified FTEs'!AL18 -> 1115.52 | M22: =SUM(C22:L22)+SUM('instruction-districts'!C22:N22) -> 5789.72
... A50: 35 | B50: Weber | C50: 21 | D50: ='Classified FTEs'!H46+'Classified FTEs'!K46 -> 1 | E50: ='Classified FTEs'!I46+'Classified FTEs'!L46+'Classified FTEs'!M46+'Classified FTEs'!N46+'Classified FTEs'!O46 -> 47.7 | F50: 61 | G50: ='Classified FTEs'!E46+'Classified FTEs'!F46+'Classified FTEs'!J46 -> 93.79 | H50: 45.02 | I50: ='Classified FTEs'!V46 -> 2 | J50: ='Classified FTEs'!AD46 -> 3 | K50: ='Classified FTEs'!D46 -> 14.33 | L50: ='Classified FTEs'!T46+'Classified FTEs'!U46+'Classified FTEs'!W46+'Classified FTEs'!X46+'Classified FTEs'!Y46+'Classified FTEs'!AC46+'Classified FTEs'!AE46+'Classified FTEs'!AF46+'Classified FTEs'!AL46 -> 450.41 | M50: =SUM(C50:L50)+SUM('instruction-districts'!C50:N50) -> 2479.51
B51: DISTRICT TOTAL | C51: =SUM(C11:C50) -> 256.21 | D51: =SUM(D11:D50) -> 73.28 | E51: =SUM(E11:E50) -> 774.39 | F51: =SUM(F11:F50) -> 1155.45 | G51: =SUM(G11:G50) -> 2180.58 | H51: =SUM(H11:H50) -> 850.54 | I51: =SUM(I11:I50) -> 43.21 | J51: =SUM(J11:J50) -> 110.13 | ... M51: =SUM(M11:M50) -> 46818.2
B52: CHARTER TOTAL | C52: 12.23 | D52: 39.56 | E52: 33.79 | F52: 66.6 | G52: 124.26 | H52: 8.67 | I52: 0 | J52: 12.19 | K52: 6.12 | L52: 129.57 | M52: 2230.26
B53: GRAND TOTAL | C53: =C51+C52 -> 268.44 | D53: =D51+D52 -> 112.84 | E53: =E51+E52 -> 808.18 | F53: =F51+F52 -> 1222.05 | G53: =G51+G52 -> 2304.84 | H53: =H51+H52 -> 859.21 | I53: =I51+I52 -> 43.21 | J53: =J51+J52 -> 122.32 | ... M53: =M51+M52 -> 49048.46

Sheet support-charters
B1: Full-Time Equivalents (FTEs) by Position
B2: Licensed and Classified Personnel
B3: FY 2009
B5: Local Education Agencies | C5: SUPPORT | M5: TOTAL FTEs
C6: LEA Administrators | E6: LEA Administrative Support Staff | F6: School Administrators | G6: School Administrative Support Staff | H6: Student Support Services Staff | L6: Other Support Staff
H8: Student Support Services | I8: Student Transportation Supervisors | J8: School Food Services Supervisors | K8: School Nurses
C9: CACTUS Database | D9: Classified Personnel Report | E9: Classified Personnel Report | F9: CACTUS Database | G9: Classified Personnel Report | H9: CACTUS Database | I9: Classified Personnel Report | J9: Classified Personnel Report | K9: Classified Personnel Report | L9: Classified Personnel Report
B10: CHARTER SCHOOL
A11: 8B | B11: American Leadership Academy | C11: 0 | D11: ='Classified FTEs'!H49+'Classified FTEs'!K49 -> 0 | E11: ='Classified FTEs'!I49+'Classified FTEs'!L49+'Classified FTEs'!M49+'Classified FTEs'!N49+'Classified FTEs'!O49 -> 0.5 | F11: 0.59 | G11: ='Classified FTEs'!E49+'Classified FTEs'!F49+'Classified FTEs'!J49 -> 9.97 | H11: 0 | I11: ='Classified FTEs'!V49 -> 0 | J11: ='Classified FTEs'!AD49 -> 0.25 | K11: ='Classified FTEs'!D49 -> 0 | L11: ='Classified FTEs'!T49+'Classified FTEs'!U49+'Classified FTEs'!W49+'Classified FTEs'!X49+'Classified FTEs'!Y49+'Classified FTEs'!AC49+'Classified FTEs'!AE49+'Classified FTEs'!AF49+'Classified FTEs'!AL49 -> 3.96 | M11: =SUM(C11:L11)+SUM('instruction-charters'!C11:N11) -> 112.91
A12: 74 | B12: American Preparatory Academy | C12: 0.58 | D12: ='Classified FTEs'!H50+'Classified FTEs'!K50 -> 0 | E12: ='Classified FTEs'!I50+'Classified FTEs'!L50+'Classified FTEs'!M50+'Classified FTEs'!N50+'Classified FTEs'!O50 -> 0 | F12: 1.3 | G12: ='Classified FTEs'!E50+'Classified FTEs'!F50+'Classified FTEs'!J50 -> 12.45 | H12: 0.36 | I12: ='Classified FTEs'!V50 -> 0 | J12: ='Classified FTEs'!AD50 -> 0 | K12: ='Classified FTEs'!D50 -> 0 | L12: ='Classified FTEs'!T50+'Classified FTEs'!U50+'Classified FTEs'!W50+'Classified FTEs'!X50+'Classified FTEs'!Y50+'Classified FTEs'!AC50+'Classified FTEs'!AE50+'Classified FTEs'!AF50+'Classified FTEs'!AL50 -> 1.95 | M12: =SUM(C12:L12)+SUM('instruction-charters'!C12:N12) -> 57.33
A13: 83 | B13: AMES | C13: 0 | D13: ='Classified FTEs'!H51+'Classified FTEs'!K51 -> 1 | E13: ='Classified FTEs'!I51+'Classified FTEs'!L51+'Classified FTEs'!M51+'Classified FTEs'!N51+'Classified FTEs'!O51 -> 0.13 | F13: 2 | G13: ='Classified FTEs'!E51+'Classified FTEs'!F51+'Classified FTEs'!J51 -> 1.5 | H13: 0 | I13: ='Classified FTEs'!V51 -> 0 | J13: ='Classified FTEs'!AD51 -> 0 | K13: ='Classified FTEs'!D51 -> 0 | L13: ='Classified FTEs'!T51+'Classified FTEs'!U51+'Classified FTEs'!W51+'Classified FTEs'!X51+'Classified FTEs'!Y51+'Classified FTEs'!AC51+'Classified FTEs'!AE51+'Classified FTEs'!AF51+'Classified FTEs'!AL51 -> 1.32 | M13: =SUM(C13:L13)+SUM('instruction-charters'!C13:N13) -> 32
A14: 3B | B14: BSTA | C14: 1 | D14: ='Classified FTEs'!H52+'Classified FTEs'!K52 -> 0 | E14: ='Classified FTEs'!I52+'Classified FTEs'!L52+'Classified FTEs'!M52+'Classified FTEs'!N52+'Classified FTEs'!O52 -> 0.1 | F14: 0 | G14: ='Classified FTEs'!E52+'Classified FTEs'!F52+'Classified FTEs'!J52 -> 2 | H14: 0 | I14: ='Classified FTEs'!V52 -> 0 | J14: ='Classified FTEs'!AD52 -> 0 | K14: ='Classified FTEs'!D52 -> 0 | L14: ='Classified FTEs'!T52+'Classified FTEs'!U52+'Classified FTEs'!W52+'Classified FTEs'!X52+'Classified FTEs'!Y52+'Classified FTEs'!AC52+'Classified FTEs'!AE52+'Classified FTEs'!AF52+'Classified FTEs'!AL52 -> 1 | M14: =SUM(C14:L14)+SUM('instruction-charters'!C14:N14) -> 18.97
A15: 9D | B15: Canyon Rim Academy | C15: 0 | D15: ='Classified FTEs'!H53+'Classified FTEs'!K53 -> 3 | E15: ='Classified FTEs'!I53+'Classified FTEs'!L53+'Classified FTEs'!M53+'Classified FTEs'!N53+'Classified FTEs'!O53 -> 0 | F15: 1 | G15: ='Classified FTEs'!E53+'Classified FTEs'!F53+'Classified FTEs'!J53 -> 2.21 | H15: 0.53 | I15: ='Classified FTEs'!V53 -> 0 | J15: ='Classified FTEs'!AD53 -> 0.76 | K15: ='Classified FTEs'!D53 -> 0 | L15: ='Classified FTEs'!T53+'Classified FTEs'!U53+'Classified FTEs'!W53+'Classified FTEs'!X53+'Classified FTEs'!Y53+'Classified FTEs'!AC53+'Classified FTEs'!AE53+'Classified FTEs'!AF53+'Classified FTEs'!AL53 -> 2.78 | M15: =SUM(C15:L15)+SUM('instruction-charters'!C15:N15) -> 39.93
A16: 84 | B16: CBA Center | C16: 0 | D16: ='Classified FTEs'!H54+'Classified FTEs'!K54 -> 0 | E16: ='Classified FTEs'!I54+'Classified FTEs'!L54+'Classified FTEs'!M54+'Classified FTEs'!N54+'Classified FTEs'!O54 -> 0 | F16: 0 | G16: ='Classified FTEs'!E54+'Classified FTEs'!F54+'Classified FTEs'!J54 -> 0 | H16: 0 | I16: ='Classified FTEs'!V54 -> 0 | J16: ='Classified FTEs'!AD54 -> 0 | K16: ='Classified FTEs'!D54 -> 0 | L16: ='Classified FTEs'!T54+'Classified FTEs'!U54+'Classified FTEs'!W54+'Classified FTEs'!X54+'Classified FTEs'!Y54+'Classified FTEs'!AC54+'Classified FTEs'!AE54+'Classified FTEs'!AF54+'Classified FTEs'!AL54 -> 0.78 | M16: =SUM(C16:L16)+SUM('instruction-charters'!C16:N16) -> 2.03
A17: 2D | B17: Channing Hall | C17: 0 | D17: ='Classified FTEs'!H55+'Classified FTEs'!K55 -> 1 | E17: ='Classified FTEs'!I55+'Classified FTEs'!L55+'Classified FTEs'!M55+'Classified FTEs'!N55+'Classified FTEs'!O55 -> 0.42 | F17: 1.11 | G17: ='Classified FTEs'!E55+'Classified FTEs'!F55+'Classified FTEs'!J55 -> 2 | H17: 0.5 | I17: ='Classified FTEs'!V55 -> 0 | J17: ='Classified FTEs'!AD55 -> 0 | K17: ='Classified FTEs'!D55 -> 0 | L17: ='Classified FTEs'!T55+'Classified FTEs'!U55+'Classified FTEs'!W55+'Classified FTEs'!X55+'Classified FTEs'!Y55+'Classified FTEs'!AC55+'Classified FTEs'!AE55+'Classified FTEs'!AF55+'Classified FTEs'!AL55 -> 2.92 | M17: =SUM(C17:L17)+SUM('instruction-charters'!C17:N17) -> 49.47
A18: 87 | B18: City Academy | C18: 0 | D18: ='Classified FTEs'!H56+'Classified FTEs'!K56 -> 0.5 | E18: ='Classified FTEs'!I56+'Classified FTEs'!L56+'Classified FTEs'!M56+'Classified FTEs'!N56+'Classified FTEs'!O56 -> 0.22 | F18: 0.56 | G18: ='Classified FTEs'!E56+'Classified FTEs'!F56+'Classified FTEs'!J56 -> 1 | H18: 0 | I18: ='Classified FTEs'!V56 -> 0 | J18: ='Classified FTEs'!AD56 -> 0 | K18: ='Classified FTEs'!D56 -> 0 | L18: ='Classified FTEs'!T56+'Classified FTEs'!U56+'Classified FTEs'!W56+'Classified FTEs'!X56+'Classified FTEs'!Y56+'Classified FTEs'!AC56+'Classified FTEs'!AE56+'Classified FTEs'!AF56+'Classified FTEs'!AL56 -> 1.97 | M18: =SUM(C18:L18)+SUM('instruction-charters'!C18:N18) -> 28.5
A19: 3E | B19: C.S. Lewis Academy | C19: 0 | D19: ='Classified FTEs'!H57+'Classified FTEs'!K57 -> 0 | E19: ='Classified FTEs'!I57+'Classified FTEs'!L57+'Classified FTEs'!M57+'Classified FTEs'!N57+'Classified FTEs'!O57 -> 0 | F19: 1 | G19: ='Classified FTEs'!E57+'Classified FTEs'!F57+'Classified FTEs'!J57 -> 1 | H19: 0 | I19: ='Classified FTEs'!V57 -> 0 | J19: ='Classified FTEs'!AD57 -> 0 | K19: ='Classified FTEs'!D57 -> 0 | L19: ='Classified FTEs'!T57+'Classified FTEs'!U57+'Classified FTEs'!W57+'Classified FTEs'!X57+'Classified FTEs'!Y57+'Classified FTEs'!AC57+'Classified FTEs'!AE57+'Classified FTEs'!AF57+'Classified FTEs'!AL57 -> 1 | M19: =SUM(C19:L19)+SUM('instruction-charters'!C19:N19) -> 24.5
A20: A3 | B20: DaVinci Academy | C20: 0 | D20: ='Classified FTEs'!H58+'Classified FTEs'!K58 -> 1 | E20: ='Classified FTEs'!I58+'Classified FTEs'!L58+'Classified FTEs'!M58+'Classified FTEs'!N58+'Classified FTEs'!O58 -> 1 | F20: 1.86 | G20: ='Classified FTEs'!E58+'Classified FTEs'!F58+'Classified FTEs'!J58 -> 2 | H20: 0 | I20: ='Classified FTEs'!V58 -> 0 | J20: ='Classified FTEs'!AD58 -> 1 | K20: ='Classified FTEs'!D58 -> 1 | L20: ='Classified FTEs'!T58+'Classified FTEs'!U58+'Classified FTEs'!W58+'Classified FTEs'!X58+'Classified FTEs'!Y58+'Classified FTEs'!AC58+'Classified FTEs'!AE58+'Classified FTEs'!AF58+'Classified FTEs'!AL58 -> 2.3 | M20: =SUM(C20:L20)+SUM('instruction-charters'!C20:N20) -> 31.75
A21: 4E | B21: Dual Immersion Academy | C21: 1 | D21: ='Classified FTEs'!H59+'Classified FTEs'!K59 -> 2 | E21: ='Classified FTEs'!I59+'Classified FTEs'!L59+'Classified FTEs'!M59+'Classified FTEs'!N59+'Classified FTEs'!O59 -> 3 | F21: 0 | G21: ='Classified FTEs'!E59+'Classified FTEs'!F59+'Classified FTEs'!J59 -> 0 | H21: 0 | I21: ='Classified FTEs'!V59 -> 0 | J21: ='Classified FTEs'!AD59 -> 0 | K21: ='Classified FTEs'!D59 -> 0 | L21: ='Classified FTEs'!T59+'Classified FTEs'!U59+'Classified FTEs'!W59+'Classified FTEs'!X59+'Classified FTEs'!Y59+'Classified FTEs'!AC59+'Classified FTEs'!AE59+'Classified FTEs'!AF59+'Classified FTEs'!AL59 -> 6 | M21: =SUM(C21:L21)+SUM('instruction-charters'!C21:N21) -> 32
A22: A8 | B22: East Hollywood High | C22: 0 | D22: ='Classified FTEs'!H60+'Classified FTEs'!K60 -> 1.6 | E22: ='Classified FTEs'!I60+'Classified FTEs'!L60+'Classified FTEs'!M60+'Classified FTEs'!N60+'Classified FTEs'!O60 -> 0 | F22: 0 | G22: ='Classified FTEs'!E60+'Classified FTEs'!F60+'Classified FTEs'!J60 -> 2 | H22: 0 | I22: ='Classified FTEs'!V60 -> 0 | J22: ='Classified FTEs'!AD60 -> 0 | K22: ='Classified FTEs'!D60 -> 0 | L22: ='Classified FTEs'!T60+'Classified FTEs'!U60+'Classified FTEs'!W60+'Classified FTEs'!X60+'Classified FTEs'!Y60+'Classified FTEs'!AC60+'Classified FTEs'!AE60+'Classified FTEs'!AF60+'Classified FTEs'!AL60 -> 2.7 | M22: =SUM(C22:L22)+SUM('instruction-charters'!C22:N22) -> 29.08
A23: 5E | B23: Edith Bowen Lab School | C23: 0 | D23: ='Classified FTEs'!H61+'Classified FTEs'!K61 -> 0 | E23: ='Classified FTEs'!I61+'Classified FTEs'!L61+'Classified FTEs'!M61+'Classified FTEs'!N61+'Classified FTEs'!O61 -> 1 | F23: 1 | G23: ='Classified FTEs'!E61+'Classified FTEs'!F61+'Classified FTEs'!J61 -> 1.78 | H23: 0.54 | I23: ='Classified FTEs'!V61 -> 0 | J23: ='Classified FTEs'!AD61 -> 1 | K23: ='Classified FTEs'!D61 -> 0 | L23: ='Classified FTEs'!T61+'Classified FTEs'!U61+'Classified FTEs'!W61+'Classified FTEs'!X61+'Classified FTEs'!Y61+'Classified FTEs'!AC61+'Classified FTEs'!AE61+'Classified FTEs'!AF61+'Classified FTEs'!AL61 -> 0.5 | M23: =SUM(C23:L23)+SUM('instruction-charters'!C23:N23) -> 24.3
A24: 3C | B24: Entheos Academy | C24: 0 | D24: ='Classified FTEs'!H62+'Classified FTEs'!K62 -> 0 | E24: ='Classified FTEs'!I62+'Classified FTEs'!L62+'Classified FTEs'!M62+'Classified FTEs'!N62+'Classified FTEs'!O62 -> 0.4 | F24: 1 | G24: ='Classified FTEs'!E62+'Classified FTEs'!F62+'Classified FTEs'!J62 -> 1.7 | H24: 0 | I24: ='Classified FTEs'!V62 -> 0 | J24: ='Classified FTEs'!AD62 -> 0 | K24: ='Classified FTEs'!D62 -> 0 | L24: ='Classified FTEs'!T62+'Classified FTEs'!U62+'Classified FTEs'!W62+'Classified FTEs'!X62+'Classified FTEs'!Y62+'Classified FTEs'!AC62+'Classified FTEs'!AE62+'Classified FTEs'!AF62+'Classified FTEs'!AL62 -> 3 | M24: =SUM(C24:L24)+SUM('instruction-charters'!C24:N24) -> 31.43
A25: 98 | B25: Fast Forward High | C25: 0 | D25: ='Classified FTEs'!H63+'Classified FTEs'!K63 -> 1 | E25: ='Classified FTEs'!I63+'Classified FTEs'!L63+'Classified FTEs'!M63+'Classified FTEs'!N63+'Classified FTEs'!O63 -> 2 | F25: 0.9 | G25: ='Classified FTEs'!E63+'Classified FTEs'!F63+'Classified FTEs'!J63 -> 0 | H25: 0 | I25: ='Classified FTEs'!V63 -> 0 | J25: ='Classified FTEs'!AD63 -> 0 | K25: ='Classified FTEs'!D63 -> 0 | L25: ='Classified FTEs'!T63+'Classified FTEs'!U63+'Classified FTEs'!W63+'Classified FTEs'!X63+'Classified FTEs'!Y63+'Classified FTEs'!AC63+'Classified FTEs'!AE63+'Classified FTEs'!AF63+'Classified FTEs'!AL63 -> 1 | M25: =SUM(C25:L25)+SUM('instruction-charters'!C25:N25) -> 23
A26: 82 | B26: Freedom Academy | C26: 0 | D26: ='Classified FTEs'!H64+'Classified FTEs'!K64 -> 1 | E26: ='Classified FTEs'!I64+'Classified FTEs'!L64+'Classified FTEs'!M64+'Classified FTEs'!N64+'Classified FTEs'!O64 -> 0.5 | F26: 2 | G26: ='Classified FTEs'!E64+'Classified FTEs'!F64+'Classified FTEs'!J64 -> 2 | H26: 0.25 | I26: ='Classified FTEs'!V64 -> 0 | J26: ='Classified FTEs'!AD64 -> 0 | K26: ='Classified FTEs'!D64 -> 0 | L26: ='Classified FTEs'!T64+'Classified FTEs'!U64+'Classified FTEs'!W64+'Classified FTEs'!X64+'Classified FTEs'!Y64+'Classified FTEs'!AC64+'Classified FTEs'!AE64+'Classified FTEs'!AF64+'Classified FTEs'!AL64 -> 8.69 | M26: =SUM(C26:L26)+SUM('instruction-charters'!C26:N26) -> 56.31
A27: 7E | B27: Gateway Preparatory Academy | C27: 0 | D27: ='Classified FTEs'!H65+'Classified FTEs'!K65 -> 0 | E27: ='Classified FTEs'!I65+'Classified FTEs'!L65+'Classified FTEs'!M65+'Classified FTEs'!N65+'Classified FTEs'!O65 -> 2 | F27: 1 | G27: ='Classified FTEs'!E65+'Classified FTEs'!F65+'Classified FTEs'!J65 -> 0 | H27: 0 | I27: ='Classified FTEs'!V65 -> 0 | J27: ='Classified FTEs'!AD65 -> 0 | K27: ='Classified FTEs'!D65 -> 0.79 | L27: ='Classified FTEs'!T65+'Classified FTEs'!U65+'Classified FTEs'!W65+'Classified FTEs'!X65+'Classified FTEs'!Y65+'Classified FTEs'!AC65+'Classified FTEs'!AE65+'Classified FTEs'!AF65+'Classified FTEs'!AL65 -> 1.96 | M27: =SUM(C27:L27)+SUM('instruction-charters'!C27:N27) -> 56.68
A28: 5D | B28: George Washington Academy | C28: 0 | D28: ='Classified FTEs'!H66+'Classified FTEs'!K66 -> 0 | E28: ='Classified FTEs'!I66+'Classified FTEs'!L66+'Classified FTEs'!M66+'Classified FTEs'!N66+'Classified FTEs'!O66 -> 1.09 | F28: 1.3 | G28: ='Classified FTEs'!E66+'Classified FTEs'!F66+'Classified FTEs'!J66 -> 0.13 | H28: 0 | I28: ='Classified FTEs'!V66 -> 0 | J28: ='Classified FTEs'!AD66 -> 0 | K28: ='Classified FTEs'!D66 -> 0 | L28: ='Classified FTEs'!T66+'Classified FTEs'!U66+'Classified FTEs'!W66+'Classified FTEs'!X66+'Classified FTEs'!Y66+'Classified FTEs'!AC66+'Classified FTEs'!AE66+'Classified FTEs'!AF66+'Classified FTEs'!AL66 -> 1 | M28: =SUM(C28:L28)+SUM('instruction-charters'!C28:N28) -> 29.15
A29: 1E | B29: Guadalupe School | C29: 0 | D29: ='Classified FTEs'!H67+'Classified FTEs'!K67 -> 0.83 | E29: ='Classified FTEs'!I67+'Classified FTEs'!L67+'Classified FTEs'!M67+'Classified FTEs'!N67+'Classified FTEs'!O67 -> 0.75 | F29: 1 | G29: ='Classified FTEs'!E67+'Classified FTEs'!F67+'Classified FTEs'!J67 -> 1.25 | H29: 0 | I29: ='Classified FTEs'!V67 -> 0 | J29: ='Classified FTEs'!AD67 -> 0 | K29: ='Classified FTEs'!D67 -> 0 | L29: ='Classified FTEs'!T67+'Classified FTEs'!U67+'Classified FTEs'!W67+'Classified FTEs'!X67+'Classified FTEs'!Y67+'Classified FTEs'!AC67+'Classified FTEs'!AE67+'Classified FTEs'!AF67+'Classified FTEs'!AL67 -> 2.88 | M29: =SUM(C29:L29)+SUM('instruction-charters'!C29:N29) -> 15.61
A30: 2C | B30: Intech Collegiate High | C30: 0 | D30: ='Classified FTEs'!H68+'Classified FTEs'!K68 -> 0.3 | E30: ='Classified FTEs'!I68+'Classified FTEs'!L68+'Classified FTEs'!M68+'Classified FTEs'!N68+'Classified FTEs'!O68 -> 0 | F30: 1 | G30: ='Classified FTEs'!E68+'Classified FTEs'!F68+'Classified FTEs'!J68 -> 0.69 | H30: 0 | I30: ='Classified FTEs'!V68 -> 0 | J30: ='Classified FTEs'!AD68 -> 0 | K30: ='Classified FTEs'!D68 -> 0 | L30: ='Classified FTEs'!T68+'Classified FTEs'!U68+'Classified FTEs'!W68+'Classified FTEs'!X68+'Classified FTEs'!Y68+'Classified FTEs'!AC68+'Classified FTEs'!AE68+'Classified FTEs'!AF68+'Classified FTEs'!AL68 -> 1.06 | M30: =SUM(C30:L30)+SUM('instruction-charters'!C30:N30) -> 11.92
A31: A5 | B31: Itineris Early College High | C31: 0 | D31: ='Classified FTEs'!H69+'Classified FTEs'!K69 -> 0 | E31: ='Classified FTEs'!I69+'Classified FTEs'!L69+'Classified FTEs'!M69+'Classified FTEs'!N69+'Classified FTEs'!O69 -> 0 | F31: 1 | G31: ='Classified FTEs'!E69+'Classified FTEs'!F69+'Classified FTEs'!J69 -> 3 | H31: 0 | I31: ='Classified FTEs'!V69 -> 0 | J31: ='Classified FTEs'!AD69 -> 0 | K31: ='Classified FTEs'!D69 -> 0 | L31: ='Classified FTEs'!T69+'Classified FTEs'!U69+'Classified FTEs'!W69+'Classified FTEs'!X69+'Classified FTEs'!Y69+'Classified FTEs'!AC69+'Classified FTEs'!AE69+'Classified FTEs'!AF69+'Classified FTEs'!AL69 -> 0 | M31: =SUM(C31:L31)+SUM('instruction-charters'!C31:N31) -> 16.38
A32: 93 | B32: John Hancock | C32: 0 | D32: ='Classified FTEs'!H70+'Classified FTEs'!K70 -> 1 | E32: ='Classified FTEs'!I70+'Classified FTEs'!L70+'Classified FTEs'!M70+'Classified FTEs'!N70+'Classified FTEs'!O70 -> 0 | F32: 1 | G32: ='Classified FTEs'!E70+'Classified FTEs'!F70+'Classified FTEs'!J70 -> 1 | H32: 0.04 | I32: ='Classified FTEs'!V70 -> 0 | J32: ='Classified FTEs'!AD70 -> 0 | K32: ='Classified FTEs'!D70 -> 0 | L32: ='Classified FTEs'!T70+'Classified FTEs'!U70+'Classified FTEs'!W70+'Classified FTEs'!X70+'Classified FTEs'!Y70+'Classified FTEs'!AC70+'Classified FTEs'!AE70+'Classified FTEs'!AF70+'Classified FTEs'!AL70 -> 0 | M32: =SUM(C32:L32)+SUM('instruction-charters'!C32:N32) -> 20.3
A33: 2E | B33: Karl G. Maeser Prep Academy | C33: 0 | D33: ='Classified FTEs'!H71+'Classified FTEs'!K71 -> 0 | E33: ='Classified FTEs'!I71+'Classified FTEs'!L71+'Classified FTEs'!M71+'Classified FTEs'!N71+'Classified FTEs'!O71 -> 0.85 | F33: 0.9 | G33: ='Classified FTEs'!E71+'Classified FTEs'!F71+'Classified FTEs'!J71 -> 1.8 | H33: 0 | I33: ='Classified FTEs'!V71 -> 0 | J33: ='Classified FTEs'!AD71 -> 0 | K33: ='Classified FTEs'!D71 -> 0 | L33: ='Classified FTEs'!T71+'Classified FTEs'!U71+'Classified FTEs'!W71+'Classified FTEs'!X71+'Classified FTEs'!Y71+'Classified FTEs'!AC71+'Classified FTEs'!AE71+'Classified FTEs'!AF71+'Classified FTEs'!AL71 -> 0 | M33: =SUM(C33:L33)+SUM('instruction-charters'!C33:N33) -> 18.62
A34: 4C | B34: Lakeview Academy | C34: 0 | D34: ='Classified FTEs'!H72+'Classified FTEs'!K72 -> 2 | E34: ='Classified FTEs'!I72+'Classified FTEs'!L72+'Classified FTEs'!M72+'Classified FTEs'!N72+'Classified FTEs'!O72 -> 0 | F34: 2 | G34: ='Classified FTEs'!E72+'Classified FTEs'!F72+'Classified FTEs'!J72 -> 2.5 | H34: 0 | I34: ='Classified FTEs'!V72 -> 0 | J34: ='Classified FTEs'!AD72 -> 0 | K34: ='Classified FTEs'!D72 -> 0 | L34: ='Classified FTEs'!T72+'Classified FTEs'!U72+'Classified FTEs'!W72+'Classified FTEs'!X72+'Classified FTEs'!Y72+'Classified FTEs'!AC72+'Classified FTEs'!AE72+'Classified FTEs'!AF72+'Classified FTEs'!AL72 -> 5 | M34: =SUM(C34:L34)+SUM('instruction-charters'!C34:N34) -> 68.48
A35: 5C | B35: Legacy Prep Academy | C35: 0.14 | D35: ='Classified FTEs'!H73+'Classified FTEs'!K73 -> 4 | E35: ='Classified FTEs'!I73+'Classified FTEs'!L73+'Classified FTEs'!M73+'Classified FTEs'!N73+'Classified FTEs'!O73 -> 4 | F35: 1 | G35: ='Classified FTEs'!E73+'Classified FTEs'!F73+'Classified FTEs'!J73 -> 1 | H35: 0 | I35: ='Classified FTEs'!V73 -> 0 | J35: ='Classified FTEs'!AD73 -> 0 | K35: ='Classified FTEs'!D73 -> 0 | L35: ='Classified FTEs'!T73+'Classified FTEs'!U73+'Classified FTEs'!W73+'Classified FTEs'!X73+'Classified FTEs'!Y73+'Classified FTEs'!AC73+'Classified FTEs'!AE73+'Classified FTEs'!AF73+'Classified FTEs'!AL73 -> 3.4 | M35: =SUM(C35:L35)+SUM('instruction-charters'!C35:N35) -> 59.91
A36: 6C | B36: Liberty Academy | C36: 0 | D36: ='Classified FTEs'!H74+'Classified FTEs'!K74 -> 0.5 | E36: ='Classified FTEs'!I74+'Classified FTEs'!L74+'Classified FTEs'!M74+'Classified FTEs'!N74+'Classified FTEs'!O74 -> 0 | F36: 0.5 | G36: ='Classified FTEs'!E74+'Classified FTEs'!F74+'Classified FTEs'!J74 -> 2 | H36: 0 | I36: ='Classified FTEs'!V74 -> 0 | J36: ='Classified FTEs'!AD74 -> 0 | K36: ='Classified FTEs'!D74 -> 0 | L36: ='Classified FTEs'!T74+'Classified FTEs'!U74+'Classified FTEs'!W74+'Classified FTEs'!X74+'Classified FTEs'!Y74+'Classified FTEs'!AC74+'Classified FTEs'!AE74+'Classified FTEs'!AF74+'Classified FTEs'!AL74 -> 1 | M36: =SUM(C36:L36)+SUM('instruction-charters'!C36:N36) -> 29.95
A37: 2B | B37: Lincoln Academy | C37: 0.5 | D37: ='Classified FTEs'!H75+'Classified FTEs'!K75 -> 1 | E37: ='Classified FTEs'!I75+'Classified FTEs'!L75+'Classified FTEs'!M75+'Classified FTEs'!N75+'Classified FTEs'!O75 -> 1.2 | F37: 1 | G37: ='Classified FTEs'!E75+'Classified FTEs'!F75+'Classified FTEs'!J75 -> 1.9 | H37: 0.44 | I37: ='Classified FTEs'!V75 -> 0 | J37: ='Classified FTEs'!AD75 -> 0 | K37: ='Classified FTEs'!D75 -> 0 | L37: ='Classified FTEs'!T75+'Classified FTEs'!U75+'Classified FTEs'!W75+'Classified FTEs'!X75+'Classified FTEs'!Y75+'Classified FTEs'!AC75+'Classified FTEs'!AE75+'Classified FTEs'!AF75+'Classified FTEs'!AL75 -> 0 | M37: =SUM(C37:L37)+SUM('instruction-charters'!C37:N37) -> 50.38
A38: 8E | B38: Merit College Prep Academy | C38: 0 | D38: ='Classified FTEs'!H76+'Classified FTEs'!K76 -> 0 | E38: ='Classified FTEs'!I76+'Classified FTEs'!L76+'Classified FTEs'!M76+'Classified FTEs'!N76+'Classified FTEs'!O76 -> 0 | F38: 0 | G38: ='Classified FTEs'!E76+'Classified FTEs'!F76+'Classified FTEs'!J76 -> 0 | H38: 0 | I38: ='Classified FTEs'!V76 -> 0 | J38: ='Classified FTEs'!AD76 -> 0 | K38: ='Classified FTEs'!D76 -> 0 | L38: ='Classified FTEs'!T76+'Classified FTEs'!U76+'Classified FTEs'!W76+'Classified FTEs'!X76+'Classified FTEs'!Y76+'Classified FTEs'!AC76+'Classified FTEs'!AE76+'Classified FTEs'!AF76+'Classified FTEs'!AL76 -> 0 | M38: =SUM(C38:L38)+SUM('instruction-charters'!C38:N38) -> 21.25
A39: A7 | B39: Moab Community School | C39: 0 | D39: ='Classified FTEs'!H77+'Classified FTEs'!K77 -> 0 | E39: ='Classified FTEs'!I77+'Classified FTEs'!L77+'Classified FTEs'!M77+'Classified FTEs'!N77+'Classified FTEs'!O77 -> 1.5 | F39: 1 | G39: ='Classified FTEs'!E77+'Classified FTEs'!F77+'Classified FTEs'!J77 -> 0 | H39: 0 | I39: ='Classified FTEs'!V77 -> 0 | J39: ='Classified FTEs'!AD77 -> 0 | K39: ='Classified FTEs'!D77 -> 0 | L39: ='Classified FTEs'!T77+'Classified FTEs'!U77+'Classified FTEs'!W77+'Classified FTEs'!X77+'Classified FTEs'!Y77+'Classified FTEs'!AC77+'Classified FTEs'!AE77+'Classified FTEs'!AF77+'Classified FTEs'!AL77 -> 0.88 | M39: =SUM(C39:L39)+SUM('instruction-charters'!C39:N39) -> 9.5
A40: 7C | B40: Monticello Academy | C40: 0 | D40: ='Classified FTEs'!H78+'Classified FTEs'!K78 -> 1 | E40: ='Classified FTEs'!I78+'Classified FTEs'!L78+'Classified FTEs'!M78+'Classified FTEs'!N78+'Classified FTEs'!O78 -> 0 | F40: 0.32 | G40: ='Classified FTEs'!E78+'Classified FTEs'!F78+'Classified FTEs'!J78 -> 2.9 | H40: 0 | I40: ='Classified FTEs'!V78 -> 0 | J40: ='Classified FTEs'!AD78 -> 1 | K40: ='Classified FTEs'!D78 -> 0 | L40: ='Classified FTEs'!T78+'Classified FTEs'!U78+'Classified FTEs'!W78+'Classified FTEs'!X78+'Classified FTEs'!Y78+'Classified FTEs'!AC78+'Classified FTEs'!AE78+'Classified FTEs'!AF78+'Classified FTEs'!AL78 -> 5.91 | M40: =SUM(C40:L40)+SUM('instruction-charters'!C40:N40) -> 50.68
A41: 8C | B41: Mountainville Academy | C41: 0.36 | D41: ='Classified FTEs'!H79+'Classified FTEs'!K79 -> 0 | E41: ='Classified FTEs'!I79+'Classified FTEs'!L79+'Classified FTEs'!M79+'Classified FTEs'!N79+'Classified FTEs'!O79 -> 1 | F41: 0 | G41: ='Classified FTEs'!E79+'Classified FTEs'!F79+'Classified FTEs'!J79 -> 2.5 | H41: 0 | I41: ='Classified FTEs'!V79 -> 0 | J41: ='Classified FTEs'!AD79 -> 0 | K41: ='Classified FTEs'!D79 -> 0 | L41: ='Classified FTEs'!T79+'Classified FTEs'!U79+'Classified FTEs'!W79+'Classified FTEs'!X79+'Classified FTEs'!Y79+'Classified FTEs'!AC79+'Classified FTEs'!AE79+'Classified FTEs'!AF79+'Classified FTEs'!AL79 -> 3 | M41: =SUM(C41:L41)+SUM('instruction-charters'!C41:N41) -> 42.03
A42: 9B | B42: Navigator Pointe Academy | C42: 0.94 | D42: ='Classified FTEs'!H80+'Classified FTEs'!K80 -> 0 | E42: ='Classified FTEs'!I80+'Classified FTEs'!L80+'Classified FTEs'!M80+'Classified FTEs'!N80+'Classified FTEs'!O80 -> 0 | F42: 1 | G42: ='Classified FTEs'!E80+'Classified FTEs'!F80+'Classified FTEs'!J80 -> 1.74 | H42: 0.4 | I42: ='Classified FTEs'!V80 -> 0 | J42: ='Classified FTEs'!AD80 -> 0 | K42: ='Classified FTEs'!D80 -> 3.18 | L42: ='Classified FTEs'!T80+'Classified FTEs'!U80+'Classified FTEs'!W80+'Classified FTEs'!X80+'Classified FTEs'!Y80+'Classified FTEs'!AC80+'Classified FTEs'!AE80+'Classified FTEs'!AF80+'Classified FTEs'!AL80 -> 1.94 | M42: =SUM(C42:L42)+SUM('instruction-charters'!C42:N42) -> 48.86
...

Sheet Licensed FTEs
E1: CLASSROOM TEACHERS | L1: Instructional Coordinators and Supervisors | M1: Elementary Guidance Counselors | N1: Secondary Guidance Counselors | O1: Librarians and Media Specialists | P1: LEA Administrators | Q1: School Administrators | R1: Student Support Services | S1: TOTAL FTEs
E2: PreKindergarten | G2: Kindergarten | H2: Elementary | I2: Secondary | J2: Special Education | K2: School-Based Specialists
E4: Regular | F4: Special
B5: 1 | C5: ALPINE DISTRICT | E5: 8 | F5: 16.53 | G5: 105.12 | H5: 1203.71 | I5: 966.72 | J5: 222.86 | K5: 60.52 | L5: 47.82 | M5: 0 | N5: 66.88 | O5: 18.5 | P5: 22 | Q5: 107 | R5: 75.15 | S5: 2920.82
B6: 2 | C6: BEAVER DISTRICT | E6: 0.5 | F6: 0 | G6: 3 | H6: 37.45 | I6: 30.28 | J6: 7.35 | K6: 0 | L6: 1.6 | M6: 0 | N6: 2.01 | O6: 0 | P6: 2.75 | Q6: 2.78 | R6: 0.75 | S6: 88.47
B7: 3 | C7: BOX ELDER DISTRICT | E7: 1 | F7: 8 | G7: 24.03 | H7: 168.39 | I7: 220.33 | J7: 44.82 | K7: 5.06 | L7: 4 | M7: 0.5 | N7: 15 | O7: 5 | P7: 4.5 | Q7: 26.3 | R7: 20.73 | S7: 547.66
B8: 4 | C8: CACHE DISTRICT | E8: 0 | F8: 5 | G8: 26.5 | H8: 235.68 | I8: 271.31 | J8: 56.85 | K8: 23.87 | L8: 9.82 | M8: 0 | N8: 18.88 | O8: 20 | P8: 3.33 | Q8: 27.27 | R8: 33.92 | S8: 732.43
B9: 5 | C9: CARBON DISTRICT | E9: 0 | F9: 2 | G9: 11 | H9: 67.01 | I9: 65.13 | J9: 20.74 | K9: 13.55 | L9: 2.48 | M9: 1 | N9: 6.24 | O9: 0.83 | P9: 6 | Q9: 11 | R9: 4.5 | S9: 211.48
B10: 6 | C10: DAGGETT DISTRICT | E10: 0 | F10: 0 | G10: 1 | H10: 4.9 | I10: 6.29 | J10: 0.58 | K10: 2.34 | L10: 0.62 | M10: 0 | N10: 0 | O10: 0.25 | P10: 0.88 | Q10: 0.76 | R10: 0 | S10: 17.62
B11: 7 | C11: DAVIS DISTRICT | E11: 2.67 | F11: 15.83 | G11: 129.09 | H11: 1204.14 | I11: 1143.09 | J11: 286.5 | K11: 99.57 | L11: 59.29 | M11: 37.65 | N11: 87.3 | O11: 17.5 | P11: 26 | Q11: 174.52 | R11: 98.69 | S11: 3381.83
B12: 8 | C12: DUCHESNE DISTRICT | E12: 0 | F12: 1 | G12: 11.5 | H12: 94.64 | I12: 85.74 | J12: 24.86 | K12: 2.48 | L12: 0.5 | M12: 0 | N12: 3.85 | O12: 6 | P12: 3 | Q12: 12.65 | R12: 2 | S12: 248.22
B13: 9 | C13: EMERY DISTRICT | E13: 0 | F13: 1 | G13: 6.51 | H13: 49 | I13: 50.55 | J13: 12.02 | K13: 2.17 | L13: 0.5 | M13: 0 | N13: 0.5 | O13: 1.1 | P13: 4 | Q13: 9.49 | R13: 2 | S13: 138.83
B14: 10 | C14: GARFIELD DISTRICT | E14: 0.5 | F14: 0 | G14: 3.66 | H14: 23.84 | I14: 31.18 | J14: 5.93 | K14: 0.05 | L14: 4.77 | M14: 0.8 | N14: 1.7 | O14: 0 | P14: 2.47 | Q14: 5.44 | R14: 1 | S14: 81.34
B15: 11 | C15: GRAND DISTRICT | E15: 0 | F15: 1 | G15: 5 | H15: 30.54 | I15: 39.47 | J15: 8.5 | K15: 1.08 | L15: 1.75 | M15: 0 | N15: 2 | O15: 2 | P15: 1 | Q15: 6 | R15: 2 | S15: 100.34
B16: 12 | C16: GRANITE DISTRICT | E16: 11 | F16: 26.25 | G16: 142.92 | H16: 1221.27 | I16: 1142.42 | J16: 310.2 | K16: 217.7 | L16: 60.52 | M16: 1 | N16: 83.18 | O16: 20.58 | P16: 37.71 | Q16: 136.23 | R16: 146.08 | S16: 3557.07
... B44: 35 | C44: WEBER DISTRICT | E44: 0 | F44: 9 | G44: 58.5 | H44: 545.18 | I44: 502.18 | J44: 154.02 | K44: 22.78 | L44: 21.29 | M44: 16.15 | N44: 38.15 | O44: 12.83 | P44: 21 | Q44: 61 | R44: 45.02 | S44: 1507.1
A45: Distric Total | E45: 43.64 | F45: 196.25 | G45: 1094.02 | H45: 9680.44 | I45: 9055.59 | J45: 2350.6 | K45: 981.92 | L45: 504.94 | M45: 133.17 | N45: 603.56 | O45: 249.68 | P45: 261.2 | Q45: 1155.44 | R45: 850.55 | S45: 27161.01
B46: 8B | C46: AMERICAN LEADERSHIP ACADEMY | E46: 2 | F46: 0 | G46: 1 | H46: 26.5 | I46: 37.29 | J46: 6.5 | K46: 6.87 | L46: 0.25 | M46: 0.5 | N46: 1 | O46: 0 | P46: 0 | Q46: 0.59 | R46: 0 | S46: 82.5
B47: 74 | C47: AMERICAN PREPARATORY ACADEMY | E47: 0 | F47: 0 | G47: 1 | H47: 12.6 | I47: 10.47 | J47: 1 | K47: 0.5 | L47: 0 | M47: 0.13 | N47: 0.09 | O47: 0 | P47: 0.58 | Q47: 1.3 | R47: 0.36 | S47: 28.03
B48: 83 | C48: ACADEMY FOR MATH ENGINEERING & SCIENCE (AMES) | E48: 0 | F48: 0 | G48: 0 | H48: 0 | I48: 19.76 | J48: 0.5 | K48: 0.16 | L48: 0 | M48: 0 | N48: 1.5 | O48: 0 | P48: 0 | Q48: 2 | R48: 0 | S48: 23.92
B49: 3B | C49: BEEHIVE SCIENCE & TECHNOLOGY ACADEMY (BSTA) | E49: 0 | F49: 0 | G49: 0 | H49: 0 | I49: 13.67 | J49: 1.2 | K49: 0 | L49: 0 | M49: 0 | N49: 0 | O49: 0 | P49: 1 | Q49: 0 | R49: 0 | S49: 15.87
B50: 9D | C50: CANYON RIM ACADEMY | E50: 0 | F50: 0 | G50: 2 | H50: 18 | I50: 0 | J50: 1 | K50: 0 | L50: 0 | M50: 0 | N50: 0 | O50: 0 | P50: 0 | Q50: 1 | R50: 0.53 | S50: 22.53
C51: CBA
B52: 2D | C52: CHANNING HALL | E52: 0 | F52: 0 | G52: 2 | H52: 14.7 | I52: 10.04 | J52: 1.1 | K52: 1.11 | L52: 0 | M52: 0 | N52: 0 | O52: 0 | P52: 0 | Q52: 1.11 | R52: 0.5 | S52: 30.56
B53: 87 | C53: CITY ACADEMY | E53: 0 | F53: 0 | G53: 0 | H53: 0 | I53: 13.71 | J53: 0.11 | K53: 2.08 | L53: 0 | M53: 0 | N53: 1 | O53: 0 | P53: 0 | Q53: 0.56 | R53: 0 | S53: 17.46
B54: 3E | C54: CS LEWIS ACADEMY | E54: 0 | F54: 0 | G54: 2 | H54: 13.75 | I54: 1 | J54: 1.5 | K54: 0.25 | L54: 0 | M54: 0 | N54: 0 | O54: 0 | P54: 0 | Q54: 1 | R54: 0 | S54: 19.5
B55: A3 | C55: DAVINCI ACADEMY | E55: 0 | F55: 0 | G55: 0 | H55: 0 | I55: 15.62 | J55: 1.67 | K55: 0 | L55: 0 | M55: 0 | N55: 1 | O55: 0.5 | P55: 0 | Q55: 1.86 | R55: 0 | S55: 20.65
B56: 4E | C56: DUAL IMMERSION ACADEMY | E56: 0 | F56: 0 | G56: 4 | H56: 8 | I56: 0 | J56: 1 | K56: 0 | L56: 0 | M56: 0 | N56: 0 | O56: 0 | P56: 1 | Q56: 0 | R56: 0 | S56: 14
B57: A8 | C57: EAST HOLLYWOOD HIGH | E57: 0 | F57: 0 | G57: 0 | H57: 0 | I57: 17.15 | J57: 0 | K57: 1.25 | L57: 0 | M57: 0 | N57: 1 | O57: 0.13 | P57: 0 | Q57: 0 | R57: 0 | S57: 19.53
B58: 5E | C58: EDITH BOWEN LABORATORY SCHOOL | E58: 0 | F58: 0 | G58: 0 | H58: 14.5 | I58: 0 | J58: 1 | K58: 0 | L58: 0 | M58: 0 | N58: 0 | O58: 2.6 | P58: 0 | Q58: 1 | R58: 0.54 | S58: 19.63
B59: 3C | C59: ENTHEOS ACADEMY | E59: 0 | F59: 0 | G59: 1 | H59: 10.22 | I59: 6 | J59: 0.91 | K59: 0 | L59: 0 | M59: 0 | N59: 0 | O59: 0 | P59: 0 | Q59: 1 | R59: 0 | S59: 19.13
B60: 98 | C60: FAST FORWARD HIGH | E60: 0 | F60: 0 | G60: 0 | H60: 0 | I60: 13 | J60: 0.9 | K60: 0.1 | L60: 0 | M60: 0 | N60: 1.1 | O60: 0 | P60: 0 | Q60: 0.9 | R60: 0 | S60: 16
B61: 82 | C61: FREEDOM ACADEMY | E61: 0 | F61: 0 | G61: 2.5 | H61: 18.51 | I61: 6.46 | J61: 2.5 | K61: 1.65 | L61: 0 | M61: 0 | N61: 0 | O61: 0 | P61: 0 | Q61: 2 | R61: 0.25 | S61: 33.87
B62: 7E | C62: GATEWAY PREPARATORY ACADEMY | E62: 0 | F62: 0 | G62: 1 | H62: 19.5 | I62: 4.75 | J62: 1 | K62: 1 | L62: 0.5 | M62: 0 | N62: 0 | O62: 0 | P62: 0 | Q62: 1 | R62: 0 | S62: 28.75
B63: 5D | C63: GEORGE WASHINGTON ACADEMY | E63: 0 | F63: 0 | G63: 2 | H63: 16.45 | I63: 0.55 | J63: 1 | K63: 0.5 | L63: 0 | M63: 0 | N63: 0 | O63: 0 | P63: 0 | Q63: 1.3 | R63: 0 | S63: 21.8
B64: 1E | C64: GUADALUPE SCHOOL | E64: 0 | F64: 0 | G64: 0 | H64: 3 | I64: 0 | J64: 0.39 | K64: 0.51 | L64: 0 | M64: 0 | N64: 0 | O64: 0 | P64: 0 | Q64: 1 | R64: 0 | S64: 4.9
B65: 2C | C65: INTECH COLLEGIATE HIGH SCHOOL | E65: 0 | F65: 0 | G65: 0 | H65: 0 | I65: 6 | J65: 0 | K65: 0.59 | L65: 0 | M65: 0 | N65: 0.65 | O65: 0 | P65: 0 | Q65: 1 | R65: 0 | S65: 8.23
B66: A5 | C66: ITINERIS EARLY COLLEGE HIGH | E66: 0 | F66: 0 | G66: 0 | H66: 0 | I66: 10.38 | J66: 0 | K66: 0 | L66: 0 | M66: 0 | N66: 2 | O66: 0 | P66: 0 | Q66: 1 | R66: 0 | S66: 13.38
B67: 93 | C67: JOHN HANCOCK CHARTER SCHOOL | E67: 0 | F67: 0 | G67: 0.72 | H67: 8 | I67: 2.33 | J67: 1 | K67: 0 | L67: 0 | M67: 0 | N67: 0 | O67: 0 | P67: 0 | Q67: 1 | R67: 0.04 | S67: 13.08
B68: 2E | C68: KARL G MAESER PREPARATORY ACADEMY | E68: 0 | F68: 0 | G68: 0 | H68: 0 | I68: 13.25 | J68: 0.66 | K68: 0 | L68: 0.66 | M68: 0 | N68: 0 | O68: 0.5 | P68: 0 | Q68: 0.9 | R68: 0 | S68: 15.97
...

Sheet Classified FTEs
A1: CLASSIFIED PERSONNEL FTEs
A2: FY 2009
C4: 1000 Instruction | D4: 2000 Support Services | AD4: 3100 School Food Services | AH4: 3300 Community Services | AJ4: 4000 Facilities Acquistion/ Construction | AM4: TOTAL CLASSIFIED PERSONNEL
D5: 2100 Students | F5: 2200 Instructional Staff | H5: 2300 District Gen. Admin. | J5: 2400 Sch. Admin. | K5: 2500 Business | Q5: 2600 Maintenance & Operation | U5: 2700 Student Transportation | AA5: 2900 Other
B6: District | C6: Tchr. Aides & Para- professional | D6: Health Services Personnel | E6: Secretary/ Clerical | F6: Secretary/ Clerical | G6: Media Center Aides | H6: Supv. and Directors | I6: Secretary/ Clerical | J6: Secretary/ Clerical | K6: School Business Admin. | L6: Supv. and Directors | M6: Accounting Personnel | N6: Secretary/ Clerical | O6: Other Personnel | P6: TOTAL BUSINESS | Q6: Secretary/ Clerical | R6: Supervisors | S6: Custodians/ Maintenance | T6: TOTAL M&O | U6: Secretary/ Clerical | V6: Supervisors | W6: Bus Drivers | X6: Mechanics/ Garage Personnel | Y6: Other Personnel | Z6: TOTAL TRANS. | AA6: Supv. and Directors | AB6: Other Personnel | AC6: TOTAL OTHER | AD6: Supv. and Directors | AE6: Secretary/ Clerical | AF6: Food Service Personnel | AG6: TOTAL SCHOOL FOODS | AH6: Secretary/ Clerical | AI6: Other Personnel | AJ6: Building/ Construction | AK6: Supv. and Directors | AL6: TOTAL FACILITY/ CONSTR.
A7: 1 | B7: Alpine | C7: 599.19 | D7: 0 | E7: 25.99 | F7: 22.99 | G7: 57.16 | H7: 0 | I7: 2 | J7: 165.48 | K7: 1 | L7: 7 | M7: 3 | N7: 13.26 | O7: 75.86 | P7: =SUM(K7:O7) -> 100.12 | Q7: 3 | R7: 6 | S7: 325.23 | T7: =SUM(Q7:S7) -> 334.23 | U7: 5.75 | V7: 4 | W7: 176.85 | X7: 6 | Y7: 57.19 | Z7: =SUM(U7:Y7) -> 249.79 | AA7: 0 | AB7: 0 | AC7: =SUM(AA7:AB7) -> 0 | AD7: 5 | AE7: 2 | AF7: 253.79 | AG7: =SUM(AD7:AF7) -> 260.79 | AH7: 0 | AI7: 0 | AJ7: 0 | AK7: 0 | AL7: =SUM(AH7:AK7) -> 0 | AM7: 1817.74
A8: 2 | B8: Beaver | C8: 36.02 | D8: 0.2 | E8: 0 | F8: 0 | G8: 2.86 | H8: 0 | I8: 1.43 | J8: 5.89 | K8: 0 | L8: 0 | M8: 0 | N8: 1 | O8: 0 | P8: =SUM(K8:O8) -> 1 | Q8: 0 | R8: 0 | S8: 12.71 | T8: =SUM(Q8:S8) -> 12.71 | U8: 0.35 | V8: 0 | W8: 5 | X8: 0.49 | Y8: 0 | Z8: =SUM(U8:Y8) -> 5.84 | AA8: 0 | AB8: 0 | AC8: =SUM(AA8:AB8) -> 0 | AD8: 0 | AE8: 0.23 | AF8: 8 | AG8: =SUM(AD8:AF8) -> 8.23 | AH8: 0 | AI8: 0 | AJ8: 0.5 | AK8: 0.5 | AL8: =SUM(AH8:AK8) -> 1 | AM8: 75.18
A9: 3 | B9: Box Elder | C9: 213 | D9: 3 | E9: 4 | F9: 8 | G9: 12 | H9: 5 | I9: 1 | J9: 34 | K9: 0 | L9: 2 | M9: 4 | N9: 0 | O9: 0 | P9: =SUM(K9:O9) -> 6 | Q9: 1 | R9: 16 | S9: 62 | T9: =SUM(Q9:S9) -> 79 | U9: 1 | V9: 1 | W9: 76 | X9: 2 | Y9: 0 | Z9: =SUM(U9:Y9) -> 80 | AA9: 0 | AB9: 0 | AC9: =SUM(AA9:AB9) -> 0 | AD9: 1 | AE9: 1 | AF9: 90 | AG9: =SUM(AD9:AF9) -> 92 | AH9: 0 | AI9: 0 | AJ9: 0 | AK9: 0 | AL9: =SUM(AH9:AK9) -> 0 | AM9: 537
A10: 4 | B10: Cache | C10: 301.56 | D10: 2.5 | E10: 0.39 | F10: 0 | G10: 0 | H10: 0 | I10: 13.93 | J10: 35.85 | K10: 1 | L10: 1 | M10: 1 | N10: 2.86 | O10: 0 | P10: =SUM(K10:O10) -> 5.86 | Q10: 0 | R10: 10.57 | S10: 85.86 | T10: =SUM(Q10:S10) -> 96.43 | U10: 1.71 | V10: 3.66 | W10: 78.98 | X10: 5 | Y10: 1.71 | Z10: =SUM(U10:Y10) -> 91.06 | AA10: 2 | AB10: 17.31 | AC10: =SUM(AA10:AB10) -> 19.31 | AD10: 23 | AE10: 1 | AF10: 50.23 | AG10: =SUM(AD10:AF10) -> 74.23 | AH10: 0 | AI10: 0 | AJ10: 2 | AK10: 0 | AL10: =SUM(AH10:AK10) -> 2 | AM10: 643.12
A11: 5 | B11: Carbon | C11: 80.86 | D11: 0 | E11: 0 | F11: 0 | G11: 3.43 | H11: 2 | I11: 3.62 | J11: 15.52 | K11: 1 | L11: 0 | M11: 3.22 | N11: 2.2 | O11: 7.88 | P11: =SUM(K11:O11) -> 14.3 | Q11: 0.88 | R11: 1 | S11: 29.64 | T11: =SUM(Q11:S11) -> 31.52 | U11: 0.91 | V11: 1 | W11: 13.52 | X11: 4 | Y11: 0 | Z11: =SUM(U11:Y11) -> 19.43 | AA11: 0 | AB11: 0 | AC11: =SUM(AA11:AB11) -> 0 | AD11: 0.5 | AE11: 1.46 | AF11: 15.54 | AG11: =SUM(AD11:AF11) -> 17.5 | AH11: 0 | AI11: 0 | AJ11: 0 | AK11: 0 | AL11: =SUM(AH11:AK11) -> 0 | AM11: 188.18
A12: 6 | B12: Daggett | C12: 5.13 | D12: 0 | E12: 0 | F12: 0 | G12: 0 | H12: 0 | I12: 1 | J12: 1.5 | K12: 0.85 | L12: 0 | M12: 0 | N12: 0 | O12: 0 | P12: =SUM(K12:O12) -> 0.85 | Q12: 0 | R12: 0.5 | S12: 3.44 | T12: =SUM(Q12:S12) -> 3.94 | U12: 0.15 | V12: 0 | W12: 1.73 | X12: 0.5 | Y12: 0 | Z12: =SUM(U12:Y12) -> 2.38 | AA12: 0 | AB12: 0 | AC12: =SUM(AA12:AB12) -> 0 | AD12: 0 | AE12: 0 | AF12: 1.88 | AG12: =SUM(AD12:AF12) -> 1.88 | AH12: 0 | AI12: 0 | AJ12: 0.5 | AK12: 0 | AL12: =SUM(AH12:AK12) -> 0.5 | AM12: 17.18
A13: 7 | B13: Davis | C13: 1131.55 | D13: 0 | E13: 2 | F13: 92.99 | G13: 60.27 | H13: 12 | I13: 3.06 | J13: 164.28 | K13: 1 | L13: 4 | M13: 11 | N13: 36.16 | O13: 76.99 | P13: =SUM(K13:O13) -> 129.15 | Q13: 8.88 | R13: 6 | S13: 497.22 | T13: =SUM(Q13:S13) -> 512.1 | U13: 8.48 | V13: 2 | W13: 147.19 | X13: 12 | Y13: 60.71 | Z13: =SUM(U13:Y13) -> 230.38 | AA13: 4 | AB13: 59.83 | AC13: =SUM(AA13:AB13) -> 63.83 | AD13: 6.45 | AE13: 3.48 | AF13: 236.13 | AG13: =SUM(AD13:AF13) -> 246.06 | AH13: 0 | AI13: 0 | AJ13: 8 | AK13: 6 | AL13: =SUM(AH13:AK13) -> 14 | AM13: 2661.67
