Workbook
Name Print_Area_MI: 'CPI-based on June12'!$A$3:$K$45

Sheet CPI-based on June12
M1: Revised Referendum Cap Inflation Estimates
M2: FY 2005 - FY 2021
A3: CPI - Urban Consumers
A4: June 2012 Update
A5: With new formula allowances and finalized FY 2011 data
A7: Source of CPI Data: DOF- John Peloquin
A9: Date: July 17, 2012
D13: CALENDAR | E13: CALENDAR | F13: CALENDAR | G13: CALENDAR | H13: FISCAL | I13: RATE OF | J13: CUMMULATIVE
D14: QUARTER | E14: QUARTER | F14: QUARTER | G14: QUARTER | H14: YEAR | I14: INCREASE | J14: RATE OF
D15: 1 | E15: 2 | F15: 3 | G15: 4 | H15: AVERAGE | J15: INCREASE
L17: A | M17: B | N17: C | O17: D | P17: E | Q17: F | R17: G
H19: (PYQ3+PYQ4+CYQ1+CYQ2)/4 | M19: Projected | O19: Projected | Q19: Std. Cap | R19: Projected
I20: (CY AVG/PY AVG)-1 | L20: Annual | M20: Inflation | N20: Formula | O20: Inflation | P20: Projected | Q20: Increase | R20: Inflation
A21: Fiscal | C21: Calendar | D21: 1st | E21: 2nd | F21: 3rd | G21: 4th | J21: (CY % / BASE YR %) | L21: Projected | M21: Ratio | N21: Allow Based | O21: Based | P21: Std. Cap | Q21: over | R21: Ratio
A22: Year | C22: Year | L22: Inflation | M22: Std. Cap | N22: Std. Cap | O22: Std. Cap | P22: Gtr of C or D | Q22: FY 2004 | R22: Alt. Cap*
D23: ='CPI-June2012'!C174 -> 1.780667 | E23: ='CPI-June2012'!C175 -> 1.794667 | F23: ='CPI-June2012'!C176 -> 1.804333 | G23: ='CPI-June2012'!C177 -> 1.815
A24: 2003 | C24: 2003 | D24: ='CPI-June2012'!C178 -> 1.833667 | E24: ='CPI-June2012'!C179 -> 1.830667 | F24: ='CPI-June2012'!C180 -> 1.844333 | G24: ='CPI-June2012'!C181 -> 1.851333 | H24: =(F23+G23+D24+E24)/4 -> 1.8209168
A25: =A24+1 -> 2004 | C25: 2004 | D25: ='CPI-June2012'!C182 -> 1.867 | E25: ='CPI-June2012'!C183 -> 1.881667 | F25: ='CPI-June2012'!C184 -> 1.893667 | G25: ='CPI-June2012'!C185 -> 1.914 | H25: =(F24+G24+D25+E25)/4 -> 1.8610833 | I25: =ROUND((H25/H24)-1,4) -> 0.0221
A26: =A25+1 -> 2005 | C26: 2005 | D26: ='CPI-June2012'!C186 -> 1.923667 | E26: ='CPI-June2012'!C187 -> 1.936667 | F26: ='CPI-June2012'!C188 -> 1.966 | G26: ='CPI-June2012'!C189 -> 1.984333 | H26: =(F25+G25+D26+E26)/4 -> 1.9170003 | I26: =(H26/H25)-1 -> 0.030045405 | J26: =(H26/$H$25)-1 -> 0.030045405 | L26: 0.0301 | M26: 1.0301 | N26: =ROUND(4601*0.186,2) -> 855.79 | O26: =M26*855.79 -> 881.54928 | P26: =IF(N26>O26,N26,O26) -> 881.54928 | Q26: =P26-855.79 -> 25.759279 | R26: =M26 -> 1.0301
A27: =A26+1 -> 2006 | C27: 2006 | D27: ='CPI-June2012'!C190 -> 1.994667 | E27: ='CPI-June2012'!C191 -> 2.012667 | F27: ='CPI-June2012'!C192 -> 2.031667 | G27: ='CPI-June2012'!C193 -> 2.023333 | H27: =(F26+G26+D27+E27)/4 -> 1.9894167 | I27: =(H27/H26)-1 -> 0.037775947 | J27: =(H27/$H$25)-1 -> 0.068956346 | L27: 0.0381 | M27: 1.0693 | N27: =ROUND(4783*0.186,2) -> 889.64 | O27: =M27*855.79 -> 915.09625 | P27: =IF(N27>O27,N27,O27) -> 915.09625 | Q27: =P27-855.79 -> 59.306247 | R27: =M27 -> 1.0693
A28: =A27+1 -> 2007 | C28: 2007 | D28: ='CPI-June2012'!C194 -> 2.04317 | E28: ='CPI-June2012'!C195 -> 2.06631 | F28: ='CPI-June2012'!C196 -> 2.07939 | G28: ='CPI-June2012'!C197 -> 2.104897 | H28: =(F27+G27+D28+E28)/4 -> 2.04112 | I28: =(H28/H27)-1 -> 0.02598915 | J28: =(H28/$H$25)-1 -> 0.096737612 | L28: 0.0261 | M28: 1.0973 | N28: =ROUND(4974*0.26,2) -> 1293.24 | O28: =M28*1294 -> 1419.9062 | P28: =IF(N28>O28,N28,O28) -> 1419.9062 | Q28: =P28-855.79 -> 564.1162 | R28: =M28 -> 1.0973
A29: =A28+1 -> 2008 | C29: 2008 | D29: ='CPI-June2012'!C198 -> 2.127543 | E29: ='CPI-June2012'!C199 -> 2.15549 | F29: ='CPI-June2012'!C200 -> 2.189037 | G29: ='CPI-June2012'!C201 -> 2.138137 | H29: =(F28+G28+D29+E29)/4 -> 2.11683 | I29: =(H29/H28)-1 -> 0.037092381 | J29: =(H29/$H$25)-1 -> 0.13741822 | L29: 0.0367 | M29: 1.1376 | N29: =ROUND(5074*0.26,2) -> 1319.24 | O29: =M29*1294 -> 1472.0544 | P29: =IF(N29>O29,N29,O29) -> 1472.0544 | Q29: =P29-855.79 -> 616.2644 | R29: =M29 -> 1.1376
A30: =A29+1 -> 2009 | C30: =C29+1 -> 2009 | D30: ='CPI-June2012'!C202 -> 2.124487 | E30: ='CPI-June2012'!C203 -> 2.134753 | F30: ='CPI-June2012'!C204 -> 2.153627 | G30: ='CPI-June2012'!C205 -> 2.16973 | H30: =(F29+G29+D30+E30)/4 -> 2.1466035 | I30: =(H30/H29)-1 -> 0.014065135 | J30: =(H30/$H$25)-1 -> 0.15341616 | L30: 0.0142 | M30: 1.1537 | N30: =ROUND(5124*0.26,2) -> 1332.24 | O30: =M30*1294 -> 1492.8878 | P30: =IF(N30>O30,N30,O30) -> 1492.8878 | Q30: =P30-855.79 -> 637.0978 | R30: =R$29+(0.25*(5124/5074-1)) -> 1.1400635
A31: =A30+1 -> 2010 | C31: =C30+1 -> 2010 | D31: ='CPI-June2012'!C206 -> 2.174353 | E31: ='CPI-June2012'!C207 -> 2.172537 | F31: ='CPI-June2012'!C208 -> 2.18025 | G31: ='CPI-June2012'!C209 -> 2.19625 | H31: =(F30+G30+D31+E31)/4 -> 2.1675617 | I31: =(H31/H30)-1 -> 0.0097634472 | J31: =(H31/$H$25)-1 -> 0.16467748 | L31: 0.0093 | M31: 1.1644 | N31: =ROUND(5124*0.26,2) -> 1332.24 | O31: =M31*1294 -> 1506.7336 | P31: =IF(N31>O31,N31,O31) -> 1506.7336 | Q31: =P31-855.79 -> 650.9436 | R31: =R30 -> 1.1400635
A32: =A31+1 -> 2011 | C32: =C31+1 -> 2011 | D32: ='CPI-June2012'!C210 -> 2.22079 | E32: ='CPI-June2012'!C211 -> 2.245003 | F32: ='CPI-June2012'!C212 -> 2.26217 | G32: ='CPI-June2012'!C213 -> 2.269503 | H32: =(F31+G31+D32+E32)/4 -> 2.2105732 | I32: =(H32/H31)-1 -> 0.019843264 | J32: =(H32/$H$25)-1 -> 0.18778848 | L32: 0.0203 | M32: 1.1881 | N32: =ROUND(5124*0.26,2) -> 1332.24 | O32: =M32*1294 -> 1537.4014 | P32: =IF(N32>O32,N32,O32) -> 1537.4014 | Q32: =P32-855.79 -> 681.6114 | R32: =R31 -> 1.1400635
A33: =A32+1 -> 2012 | C33: =C32+1 -> 2012 | D33: ='CPI-June2012'!C214 -> 2.283453 | E33: ='CPI-June2012'!C215 -> 2.286697 | F33: ='CPI-June2012'!C216 -> 2.285411 | G33: ='CPI-June2012'!C217 -> 2.293216 | H33: =(F32+G32+D33+E33)/4 -> 2.2754557 | I33: =(H33/H32)-1 -> 0.029350984 | J33: =(H33/$H$25)-1 -> 0.22265124 | L33: 0.0294 | M33: 1.223 | N33: =ROUND(5174*0.26,2) -> 1345.24 | O33: =M33*1294 -> 1582.562 | P33: =IF(N33>O33,N33,O33) -> 1582.562 | Q33: =P33-855.79 -> 726.772 | R33: =R$29+(0.25*(5174/5074-1)) -> 1.1425271
A34: =A33+1 -> 2013 | B34: e | C34: =C33+1 -> 2013 | D34: ='CPI-June2012'!C218 -> 2.301574 | E34: ='CPI-June2012'!C219 -> 2.308332 | F34: ='CPI-June2012'!C220 -> 2.321753 | G34: ='CPI-June2012'!C221 -> 2.335328 | H34: =(F33+G33+D34+E34)/4 -> 2.2971332 | I34: =(H34/H33)-1 -> 0.009526663 | J34: =(H34/$H$25)-1 -> 0.23429903 | L34: =ROUND(I34,4) -> 0.0095 | M34: =ROUND(H34/H$25,4) -> 1.2343 | N34: =ROUND(5224*0.26,2) -> 1358.24 | O34: =M34*1294 -> 1597.1842 | P34: =IF(N34>O34,N34,O34) -> 1597.1842 | Q34: =P34-855.79 -> 741.3942 | R34: =R$29+(0.25*(5224/5074-1)) -> 1.1449906
A35: 2014 | B35: e | C35: 2014 | D35: ='CPI-June2012'!C222 -> 2.350866 | E35: ='CPI-June2012'!C223 -> 2.366506 | F35: ='CPI-June2012'!C224 -> 2.380039 | G35: ='CPI-June2012'!C225 -> 2.3906 | H35: =(F34+G34+D35+E35)/4 -> 2.3436132 | I35: =(H35/H34)-1 -> 0.020233915 | J35: =(H35/$H$25)-1 -> 0.25927373 | L35: =ROUND(I35,4) -> 0.0202 | M35: =ROUND(H35/H$25,4) -> 1.2593 | N35: =ROUND(5224*0.26,2) -> 1358.24 | O35: =M35*1294 -> 1629.5342 | P35: =IF(N35>O35,N35,O35) -> 1629.5342 | Q35: =P35-855.79 -> 773.7442 | R35: =R34 -> 1.1449906
A36: 2015 | B36: e | C36: 2015 | D36: ='CPI-June2012'!C226 -> 2.402466 | E36: ='CPI-June2012'!C227 -> 2.414209 | F36: ='CPI-June2012'!C228 -> 2.425851 | G36: ='CPI-June2012'!C229 -> 2.437073 | H36: =(F35+G35+D36+E36)/4 -> 2.3968285 | I36: =(H36/H35)-1 -> 0.022706498 | J36: =(H36/$H$25)-1 -> 0.28786743 | L36: =ROUND(I36,4) -> 0.0227 | M36: =ROUND(H36/H$25,4) -> 1.2879 | N36: =ROUND(5224*0.26,2) -> 1358.24 | O36: =M36*1294 -> 1666.5426 | P36: =IF(N36>O36,N36,O36) -> 1666.5426 | Q36: =P36-855.79 -> 810.7526 | R36: =R34 -> 1.1449906
A37: 2016 | B37: e | C37: 2016 | D37: ='CPI-June2012'!C230 -> 2.447769 | E37: ='CPI-June2012'!C231 -> 2.458114 | F37: ='CPI-June2012'!C232 -> 2.468058 | G37: ='CPI-June2012'!C233 -> 2.477882 | H37: =(F36+G36+D37+E37)/4 -> 2.4422017 | I37: =(H37/H36)-1 -> 0.018930537 | J37: =(H37/$H$25)-1 -> 0.31224745 | L37: =ROUND(I37,4) -> 0.0189 | M37: =ROUND(H37/H$25,4) -> 1.3122 | N37: =ROUND(5224*0.26,2) -> 1358.24 | O37: =M37*1294 -> 1697.9868 | P37: =IF(N37>O37,N37,O37) -> 1697.9868 | Q37: =P37-855.79 -> 842.1968 | R37: =R35 -> 1.1449906
A38: 2017 | B38: e | C38: 2017 | D38: ='CPI-June2012'!C234 -> 2.488213 | E38: ='CPI-June2012'!C235 -> 2.498003 | F38: ='CPI-June2012'!C236 -> 2.507966 | G38: ='CPI-June2012'!C237 -> 2.518264 | H38: =(F37+G37+D38+E38)/4 -> 2.483039 | I38: =(H38/H37)-1 -> 0.016721489 | J38: =(H38/$H$25)-1 -> 0.33419018 | L38: =ROUND(I38,4) -> 0.0167 | M38: =ROUND(H38/H$25,4) -> 1.3342 | N38: =ROUND(5224*0.26,2) -> 1358.24 | O38: =M38*1294 -> 1726.4548 | P38: =IF(N38>O38,N38,O38) -> 1726.4548 | Q38: =P38-855.79 -> 870.6648 | R38: =R36 -> 1.1449906
A39: 2018 | B39: e | C39: 2018 | D39: ='CPI-June2012'!C238 -> 2.530389 | E39: ='CPI-June2012'!C239 -> 2.541152 | F39: ='CPI-June2012'!C240 -> 2.552185 | G39: ='CPI-June2012'!C241 -> 2.56261 | H39: =(F38+G38+D39+E39)/4 -> 2.5244427 | I39: =(H39/H38)-1 -> 0.016674627 | J39: =(H39/$H$25)-1 -> 0.35643731 | L39: =ROUND(I39,4) -> 0.0167 | M39: =ROUND(H39/H$25,4) -> 1.3564 | N39: =ROUND(5224*0.26,2) -> 1358.24 | O39: =M39*1294 -> 1755.1816 | P39: =IF(N39>O39,N39,O39) -> 1755.1816 | Q39: =P39-855.79 -> 899.3916 | R39: =R37 -> 1.1449906
A40: 2019 | B40: e | C40: 2019 | D40: ='CPI-June2012'!C242 -> 2.57404 | E40: ='CPI-June2012'!C243 -> 2.584514 | F40: ='CPI-June2012'!C244 -> 2.595031 | G40: ='CPI-June2012'!C245 -> 2.605791 | H40: =(F39+G39+D40+E40)/4 -> 2.5683372 | I40: =(H40/H39)-1 -> 0.017387798 | J40: =(H40/$H$25)-1 -> 0.38002276 | L40: =ROUND(I40,4) -> 0.0174 | M40: =ROUND(H40/H$25,4) -> 1.38 | N40: =ROUND(5224*0.26,2) -> 1358.24 | O40: =M40*1294 -> 1785.72 | P40: =IF(N40>O40,N40,O40) -> 1785.72 | Q40: =P40-855.79 -> 929.93 | R40: =R38 -> 1.1449906
A41: 2020 | B41: e | C41: 2020 | D41: ='CPI-June2012'!C246 -> 2.617143 | E41: ='CPI-June2012'!C247 -> 2.627373 | F41: ='CPI-June2012'!C248 -> 2.639292 | G41: ='CPI-June2012'!C249 -> 2.652716 | H41: =(F40+G40+D41+E41)/4 -> 2.6113345 | I41: =(H41/H40)-1 -> 0.016741279 | J41: =(H41/$H$25)-1 -> 0.40312611 | L41: =ROUND(I41,4) -> 0.0167 | M41: =ROUND(H41/H$25,4) -> 1.4031 | N41: =ROUND(5224*0.26,2) -> 1358.24 | O41: =M41*1294 -> 1815.6114 | P41: =IF(N41>O41,N41,O41) -> 1815.6114 | Q41: =P41-855.79 -> 959.8214 | R41: =R39 -> 1.1449906
A42: 2021 | B42: e | C42: 2021 | D42: ='CPI-June2012'!C250 -> 2.666496 | E42: ='CPI-June2012'!C251 -> 2.680403 | F42: ='CPI-June2012'!C252 -> 2.694528 | G42: ='CPI-June2012'!C253 -> 2.708918 | H42: =(F41+G41+D42+E42)/4 -> 2.6597267 | I42: =(H42/H41)-1 -> 0.018531617 | J42: =(H42/$H$25)-1 -> 0.4291283 | L42: =ROUND(I42,4) -> 0.0185 | M42: =ROUND(H42/H$25,4) -> 1.4291 | N42: =ROUND(5224*0.26,2) -> 1358.24 | O42: =M42*1294 -> 1849.2554 | P42: =IF(N42>O42,N42,O42) -> 1849.2554 | Q42: =P42-855.79 -> 993.4654 | R42: =R40 -> 1.1449906
A44: Notes:
A45: 1. Assumes no increase in formula allowance after FY 2013 as per current law.
A46: 2. Finalized calculation through FY 2012 based on actual Bureau of Labor Statistics data.

Sheet CPI-June2012
A1: obs | B1: obs | C1: CPI | D1: previous | E1: diff | F1: df-current | G1: df-previous
A2: 81.625694 | B2: 1959Q1 | C2: 0.289933 | D2: 0.289933 | E2: =C2-D2 -> 0
A3: 81.626389 | B3: 1959Q2 | C3: 0.290433 | D3: 0.290433 | E3: =C3-D3 -> 0 | F3: =C3-C2 -> 0.0005 | G3: =D3-D2 -> 0.0005
A4: 81.627083 | B4: 1959Q3 | C4: 0.291933 | D4: 0.291933 | E4: =C4-D4 -> 0 | F4: =C4-C3 -> 0.0015 | G4: =D4-D3 -> 0.0015
A5: 81.627778 | B5: 1959Q4 | C5: 0.2937 | D5: 0.2937 | E5: =C5-D5 -> 0 | F5: =C5-C4 -> 0.001767 | G5: =D5-D4 -> 0.001767
A6: 81.667361 | B6: 1960Q1 | C6: 0.293967 | D6: 0.293967 | E6: =C6-D6 -> 0 | F6: =C6-C5 -> 0.000267 | G6: =D6-D5 -> 0.000267
A7: 81.668056 | B7: 1960Q2 | C7: 0.295733 | D7: 0.295733 | E7: =C7-D7 -> 0 | F7: =C7-C6 -> 0.001766 | G7: =D7-D6 -> 0.001766
A8: 81.66875 | B8: 1960Q3 | C8: 0.2959 | D8: 0.2959 | E8: =C8-D8 -> 0 | F8: =C8-C7 -> 0.000167 | G8: =D8-D7 -> 0.000167
A9: 81.669444 | B9: 1960Q4 | C9: 0.2978 | D9: 0.2978 | E9: =C9-D9 -> 0 | F9: =C9-C8 -> 0.0019 | G9: =D9-D8 -> 0.0019
A10: 81.709028 | B10: 1961Q1 | C10: 0.2984 | D10: 0.2984 | E10: =C10-D10 -> 0 | F10: =C10-C9 -> 0.0006 | G10: =D10-D9 -> 0.0006
A11: 81.709722 | B11: 1961Q2 | C11: 0.2983 | D11: 0.2983 | E11: =C11-D11 -> 0 | F11: =C11-C10 -> -0.0001 | G11: =D11-D10 -> -0.0001
A12: 81.710417 | B12: 1961Q3 | C12: 0.299467 | D12: 0.299467 | E12: =C12-D12 -> 0 | F12: =C12-C11 -> 0.001167 | G12: =D12-D11 -> 0.001167
A13: 81.711111 | B13: 1961Q4 | C13: 0.2999 | D13: 0.2999 | E13: =C13-D13 -> 0 | F13: =C13-C12 -> 0.000433 | G13: =D13-D12 -> 0.000433
A14: 81.750694 | B14: 1962Q1 | C14: 0.301067 | D14: 0.301067 | E14: =C14-D14 -> 0 | F14: =C14-C13 -> 0.001167 | G14: =D14-D13 -> 0.001167
... A198: 83.667361 | B198: 2008Q1 | C198: 2.127543 | D198: 2.12776 | E198: =C198-D198 -> -0.000217 | F198: =C198-C197 -> 0.022646 | G198: =D198-D197 -> 0.023153
A199: 83.668056 | B199: 2008Q2 | C199: 2.15549 | D199: 2.155523 | E199: =C199-D199 -> -3.3e-05 | F199: =C199-C198 -> 0.027947 | G199: =D199-D198 -> 0.027763 | H199: =(SUM(C196:C199))/4 -> 2.11683 | I199: =(SUM(D196:D199))/4 -> 2.116815
A200: 83.66875 | B200: 2008Q3 | C200: 2.189037 | D200: 2.189217 | E200: =C200-D200 -> -0.00018 | F200: =C200-C199 -> 0.033547 | G200: =D200-D199 -> 0.033694
A201: 83.669444 | B201: 2008Q4 | C201: 2.138137 | D201: 2.13753 | E201: =C201-D201 -> 0.000607 | F201: =C201-C200 -> -0.0509 | G201: =D201-D200 -> -0.051687
A202: 83.709028 | B202: 2009Q1 | C202: 2.124487 | D202: 2.124513 | E202: =C202-D202 -> -2.6e-05 | F202: =C202-C201 -> -0.01365 | G202: =D202-D201 -> -0.013017
A203: 83.709722 | B203: 2009Q2 | C203: 2.134753 | D203: 2.13468 | E203: =C203-D203 -> 7.3e-05 | F203: =C203-C202 -> 0.010266 | G203: =D203-D202 -> 0.010167 | H203: =(SUM(C200:C203))/4 -> 2.1466035 | I203: =(SUM(D200:D203))/4 -> 2.146485
A204: 83.710417 | B204: 2009Q3 | C204: 2.153627 | D204: 2.15419 | E204: =C204-D204 -> -0.000563 | F204: =C204-C203 -> 0.018874 | G204: =D204-D203 -> 0.01951
A205: 83.711111 | B205: 2009Q4 | C205: 2.16973 | D205: 2.16853 | E205: =C205-D205 -> 0.0012 | F205: =C205-C204 -> 0.016103 | G205: =D205-D204 -> 0.01434
A206: 83.750694 | B206: 2010Q1 | C206: 2.174353 | D206: 2.175437 | E206: =C206-D206 -> -0.001084 | F206: =C206-C205 -> 0.004623 | G206: =D206-D205 -> 0.006907
A207: 83.751389 | B207: 2010Q2 | C207: 2.172537 | D207: 2.1727 | E207: =C207-D207 -> -0.000163 | F207: =C207-C206 -> -0.001816 | G207: =D207-D206 -> -0.002737 | H207: =(SUM(C204:C207))/4 -> 2.1675617 | I207: =(SUM(D204:D207))/4 -> 2.1677143
A208: 83.752083 | B208: 2010Q3 | C208: 2.18025 | D208: 2.180387 | E208: =C208-D208 -> -0.000137 | F208: =C208-C207 -> 0.007713 | G208: =D208-D207 -> 0.007687
A209: 83.752778 | B209: 2010Q4 | C209: 2.19625 | D209: 2.194653 | E209: =C209-D209 -> 0.001597 | F209: =C209-C208 -> 0.016 | G209: =D209-D208 -> 0.014266
A210: 83.792361 | B210: 2011Q1 | C210: 2.22079 | D210: 2.22274 | E210: =C210-D210 -> -0.00195 | F210: =C210-C209 -> 0.02454 | G210: =D210-D209 -> 0.028087
A211: 83.793056 | B211: 2011Q2 | C211: 2.245003 | D211: 2.245137 | E211: =C211-D211 -> -0.000134 | F211: =C211-C210 -> 0.024213 | G211: =D211-D210 -> 0.022397 | H211: =(SUM(C208:C211))/4 -> 2.2105732 | I211: =(SUM(D208:D211))/4 -> 2.2107292
A212: 83.79375 | B212: 2011Q3 | C212: 2.26217 | D212: 2.26216 | E212: =C212-D212 -> 1e-05 | F212: =C212-C211 -> 0.017167 | G212: =D212-D211 -> 0.017023
A213: 83.794444 | B213: 2011Q4 | C213: 2.269503 | D213: 2.267652 | E213: =C213-D213 -> 0.001851 | F213: =C213-C212 -> 0.007333 | G213: =D213-D212 -> 0.005492
A214: 83.834028 | B214: 2012Q1 | C214: 2.283453 | D214: 2.272871 | E214: =C214-D214 -> 0.010582 | F214: =C214-C213 -> 0.01395 | G214: =D214-D213 -> 0.005219
A215: 83.834722 | B215: 2012Q2 | C215: 2.286697 | D215: 2.275018 | E215: =C215-D215 -> 0.011679 | F215: =C215-C214 -> 0.003244 | G215: =D215-D214 -> 0.002147
A216: 83.835417 | B216: 2012Q3 | C216: 2.285411 | D216: 2.28782 | E216: =C216-D216 -> -0.002409 | F216: =C216-C215 -> -0.001286 | G216: =D216-D215 -> 0.012802
A217: 83.836111 | B217: 2012Q4 | C217: 2.293216 | D217: 2.296079 | E217: =C217-D217 -> -0.002863 | F217: =C217-C216 -> 0.007805 | G217: =D217-D216 -> 0.008259
A218: 83.875694 | B218: 2013Q1 | C218: 2.301574 | D218: 2.306713 | E218: =C218-D218 -> -0.005139 | F218: =C218-C217 -> 0.008358 | G218: =D218-D217 -> 0.010634
A219: 83.876389 | B219: 2013Q2 | C219: 2.308332 | D219: 2.318653 | E219: =C219-D219 -> -0.010321 | F219: =C219-C218 -> 0.006758 | G219: =D219-D218 -> 0.01194
A220: 83.877083 | B220: 2013Q3 | C220: 2.321753 | D220: 2.330801 | E220: =C220-D220 -> -0.009048 | F220: =C220-C219 -> 0.013421 | G220: =D220-D219 -> 0.012148
A221: 83.877778 | B221: 2013Q4 | C221: 2.335328 | D221: 2.342539 | E221: =C221-D221 -> -0.007211 | F221: =C221-C220 -> 0.013575 | G221: =D221-D220 -> 0.011738
A222: 83.917361 | B222: 2014Q1 | C222: 2.350866 | D222: 2.353455 | E222: =C222-D222 -> -0.002589 | F222: =C222-C221 -> 0.015538 | G222: =D222-D221 -> 0.010916
A223: 83.918056 | B223: 2014Q2 | C223: 2.366506 | D223: 2.365486 | E223: =C223-D223 -> 0.00102 | F223: =C223-C222 -> 0.01564 | G223: =D223-D222 -> 0.012031
...
