Workbook

Sheet all
A1: Survey of all Currently enrolled students Fall 2013 -- All questions by Primary Campus
A3: Primary Campus | B3: Total | D3: Respondent | F3: % of campus
A4: Boulder County | B4: 2474 | C4: =B4/B10 -> 0.1386072 | D4: 361 | E4: =D4/D10 -> 0.17888999 | F4: =D4/B4 -> 0.14591754
A5: Brighton | B5: 169 | C5: =B5/B10 -> 0.0094683176 | D5: 15 | E5: =D5/D10 -> 0.0074331021 | F5: =D5/B5 -> 0.088757396
A6: CCC Online | B6: 1609 | C6: =B6/B10 -> 0.090145106 | D6: 132 | E6: =D6/D10 -> 0.065411298 | F6: =D6/B6 -> 0.082038533
A7: Larimer | B7: 5555 | C7: =B7/B10 -> 0.31122192 | D7: 560 | E7: =D7/D10 -> 0.27750248 | F7: =D7/B7 -> 0.10081008
A8: FRCC Online | B8: 2384 | C8: =B8/B10 -> 0.13356491 | D8: 254 | E8: =D8/D10 -> 0.1258672 | F8: =D8/B8 -> 0.10654362
A9: Westminster | B9: 5658 | C9: =B9/B10 -> 0.31699255 | D9: 696 | E9: =D9/D10 -> 0.34489594 | F9: =D9/B9 -> 0.12301166
A10: Total | B10: =SUM(B4:B9) -> 17849 | C10: =SUM(C4:C9) -> 1 | D10: =SUM(D4:D9) -> 2018 | E10: =SUM(E4:E9) -> 1 | F10: =D10/B10 -> 0.11305956
A12: Degree | B12: Total | D12: Respondent | F12: % | G12: Boulder Cty | I12: Brighton | K12: CCCS Online | M12: Larimer | O12: FRCC Online | Q12: Westminster
A13: A.A. | B13: 5702 | C13: =B13/B19 -> 0.31945767 | D13: 598 | E13: =D13/D19 -> 0.296333 | F13: =D13/B13 -> 0.10487548 | G13: 109 | H13: =G13/G19 -> 0.30193906 | I13: 2 | J13: =I13/I19 -> 0.13333333 | K13: 40 | L13: =K13/K19 -> 0.3030303 | M13: 171 | N13: =M13/M19 -> 0.30535714 | O13: 75 | P13: =O13/O19 -> 0.29527559 | Q13: 201 | R13: =Q13/Q19 -> 0.2887931
A14: A.A.S. | B14: 4875 | C14: =B14/B19 -> 0.27312454 | D14: 682 | E14: =D14/D19 -> 0.33795837 | F14: =D14/B14 -> 0.13989744 | G14: 92 | H14: =G14/G19 -> 0.25484765 | I14: 5 | J14: =I14/I19 -> 0.33333333 | K14: 42 | L14: =K14/K19 -> 0.31818182 | M14: 192 | N14: =M14/M19 -> 0.34285714 | O14: 101 | P14: =O14/O19 -> 0.3976378 | Q14: 250 | R14: =Q14/Q19 -> 0.3591954
A15: A.G.S. | B15: 978 | C15: =B15/B19 -> 0.054792986 | D15: 93 | E15: =D15/D19 -> 0.046085233 | F15: =D15/B15 -> 0.095092025 | G15: 14 | H15: =G15/G19 -> 0.038781163 | I15: 2 | J15: =I15/I19 -> 0.13333333 | K15: 5 | L15: =K15/K19 -> 0.037878788 | M15: 26 | N15: =M15/M19 -> 0.046428571 | O15: 15 | P15: =O15/O19 -> 0.059055118 | Q15: 31 | R15: =Q15/Q19 -> 0.04454023
A16: A.S. | B16: 3711 | C16: =B16/B19 -> 0.20791081 | D16: 385 | E16: =D16/D19 -> 0.19078295 | F16: =D16/B16 -> 0.10374562 | G16: 70 | H16: =G16/G19 -> 0.19390582 | I16: 4 | J16: =I16/I19 -> 0.26666667 | K16: 32 | L16: =K16/K19 -> 0.24242424 | M16: 101 | N16: =M16/M19 -> 0.18035714 | O16: 32 | P16: =O16/O19 -> 0.12598425 | Q16: 146 | R16: =Q16/Q19 -> 0.20977011
A17: Certificate | B17: 1249 | C17: =B17/B19 -> 0.069975909 | D17: 161 | E17: =D17/D19 -> 0.079781962 | F17: =D17/B17 -> 0.12890312 | G17: 54 | H17: =G17/G19 -> 0.14958449 | I17: 2 | J17: =I17/I19 -> 0.13333333 | K17: 4 | L17: =K17/K19 -> 0.03030303 | M17: 39 | N17: =M17/M19 -> 0.069642857 | O17: 24 | P17: =O17/O19 -> 0.094488189 | Q17: 38 | R17: =Q17/Q19 -> 0.054597701
A18: Undeclared | B18: 1334 | C18: =B18/B19 -> 0.074738081 | D18: 99 | E18: =D18/D19 -> 0.049058474 | F18: =D18/B18 -> 0.074212894 | G18: 22 | H18: =G18/G19 -> 0.060941828 | J18: =I18/I19 -> 0 | K18: 9 | L18: =K18/K19 -> 0.068181818 | M18: 31 | N18: =M18/M19 -> 0.055357143 | O18: 7 | P18: =O18/O19 -> 0.027559055 | Q18: 30 | R18: =Q18/Q19 -> 0.043103448
A19: Total | B19: =SUM(B13:B18) -> 17849 | C19: =SUM(C13:C18) -> 1 | D19: =SUM(D13:D18) -> 2018 | E19: =SUM(E13:E18) -> 1 | F19: =D19/B19 -> 0.11305956 | G19: =SUM(G13:G18) -> 361 | H19: =SUM(H13:H18) -> 1 | I19: =SUM(I13:I18) -> 15 | J19: =SUM(J13:J18) -> 1 | K19: =SUM(K13:K18) -> 132 | L19: =SUM(L13:L18) -> 1 | M19: =SUM(M13:M18) -> 560 | N19: =SUM(N13:N18) -> 1 | ... R19: =SUM(R13:R18) -> 1
A21: Sex | B21: Total | D21: Respondent | F21: % | G21: Boulder Cty | I21: Brighton | K21: CCCS Online | M21: Larimer | O21: FRCC Online | Q21: Westminster
A22: Female | B22: 10082 | C22: =B22/B25 -> 0.56484957 | D22: 1403 | E22: =D22/D25 -> 0.69524281 | F22: =D22/B22 -> 0.1391589 | G22: 270 | H22: =G22/G25 -> 0.74792244 | I22: 12 | J22: =I22/I25 -> 0.8 | K22: 91 | L22: =K22/K25 -> 0.68939394 | M22: 344 | N22: =M22/M25 -> 0.61428571 | O22: 203 | P22: =O22/O25 -> 0.7992126 | Q22: 483 | R22: =Q22/Q25 -> 0.69396552
A23: Male | B23: 7757 | C23: =B23/B25 -> 0.43459017 | D23: 614 | E23: =D23/D25 -> 0.30426165 | F23: =D23/B23 -> 0.079154312 | G23: 91 | H23: =G23/G25 -> 0.25207756 | I23: 3 | J23: =I23/I25 -> 0.2 | K23: 41 | L23: =K23/K25 -> 0.31060606 | M23: 216 | N23: =M23/M25 -> 0.38571429 | O23: 50 | P23: =O23/O25 -> 0.19685039 | Q23: 213 | R23: =Q23/Q25 -> 0.30603448
A24: N | B24: 10 | C24: =B24/B25 -> 0.00056025548 | D24: 1 | E24: =D24/D25 -> 0.00049554014 | F24: =D24/B24 -> 0.1 | H24: =G24/G25 -> 0 | J24: =I24/I25 -> 0 | L24: =K24/K25 -> 0 | N24: =M24/M25 -> 0 | O24: 1 | P24: =O24/O25 -> 0.0039370079 | R24: =Q24/Q25 -> 0
A25: Total | B25: =SUM(B22:B24) -> 17849 | C25: =SUM(C22:C24) -> 1 | D25: =SUM(D22:D24) -> 2018 | E25: =SUM(E22:E24) -> 1 | F25: =D25/B25 -> 0.11305956 | G25: =SUM(G22:G24) -> 361 | H25: =SUM(H22:H24) -> 1 | I25: =SUM(I22:I24) -> 15 | J25: =SUM(J22:J24) -> 1 | K25: =SUM(K22:K24) -> 132 | L25: =SUM(L22:L24) -> 1 | M25: =SUM(M22:M24) -> 560 | N25: =SUM(N22:N24) -> 1 | ... R25: =SUM(R22:R24) -> 1
A27: Note: Students less than 18 years old were omitted from this survey because of uncertainty around confidentiality for underage students.
A28: Age | B28: Total | D28: Respondent | F28: % | G28: Boulder Cty | I28: Brighton | K28: CCCS Online | M28: Larimer | O28: FRCC Online | Q28: Westminster
A29: Less than 18 | C29: =B29/B36 -> 0
A30: 18 to 19 | B30: 3505 | C30: =B30/B36 -> 0.19636954 | D30: 307 | E30: =D30/D36 -> 0.15213082 | F30: =D30/B30 -> 0.087589158 | G30: 68 | H30: =G30/G36 -> 0.18836565 | I30: 2 | J30: =I30/I36 -> 0.13333333 | K30: 4 | L30: =K30/K36 -> 0.03030303 | M30: 92 | N30: =M30/M36 -> 0.16428571 | O30: 10 | P30: =O30/O36 -> 0.039370079 | Q30: 131 | R30: =Q30/Q36 -> 0.18821839
A31: 20 to 21 | B31: 3135 | C31: =B31/B36 -> 0.17564009 | D31: 227 | E31: =D31/D36 -> 0.11248761 | F31: =D31/B31 -> 0.072408293 | G31: 37 | H31: =G31/G36 -> 0.10249307 | I31: 4 | J31: =I31/I36 -> 0.26666667 | K31: 6 | L31: =K31/K36 -> 0.045454545 | M31: 74 | N31: =M31/M36 -> 0.13214286 | O31: 11 | P31: =O31/O36 -> 0.043307087 | Q31: 95 | R31: =Q31/Q36 -> 0.13649425
A32: 22 to 24 | B32: 3036 | C32: =B32/B36 -> 0.17009356 | D32: 237 | E32: =D32/D36 -> 0.11744301 | F32: =D32/B32 -> 0.078063241 | G32: 38 | H32: =G32/G36 -> 0.10526316 | I32: 1 | J32: =I32/I36 -> 0.066666667 | K32: 23 | L32: =K32/K36 -> 0.17424242 | M32: 56 | N32: =M32/M36 -> 0.1 | O32: 37 | P32: =O32/O36 -> 0.14566929 | Q32: 82 | R32: =Q32/Q36 -> 0.11781609
A33: 25 to 30 | B33: 3460 | C33: =B33/B36 -> 0.19384839 | D33: 394 | E33: =D33/D36 -> 0.19524281 | F33: =D33/B33 -> 0.11387283 | G33: 65 | H33: =G33/G36 -> 0.1800554 | I33: 3 | J33: =I33/I36 -> 0.2 | K33: 29 | L33: =K33/K36 -> 0.21969697 | M33: 115 | N33: =M33/M36 -> 0.20535714 | O33: 49 | P33: =O33/O36 -> 0.19291339 | Q33: 133 | R33: =Q33/Q36 -> 0.19109195
A34: 31 to 40 | B34: 2707 | C34: =B34/B36 -> 0.15166116 | D34: 409 | E34: =D34/D36 -> 0.20267592 | F34: =D34/B34 -> 0.15108977 | G34: 62 | H34: =G34/G36 -> 0.17174515 | I34: 3 | J34: =I34/I36 -> 0.2 | K34: 32 | L34: =K34/K36 -> 0.24242424 | M34: 114 | N34: =M34/M36 -> 0.20357143 | O34: 70 | P34: =O34/O36 -> 0.27559055 | Q34: 128 | R34: =Q34/Q36 -> 0.18390805
A35: Over 40 | B35: 2006 | C35: =B35/B36 -> 0.11238725 | D35: 444 | E35: =D35/D36 -> 0.22001982 | F35: =D35/B35 -> 0.22133599 | G35: 91 | H35: =G35/G36 -> 0.25207756 | I35: 2 | J35: =I35/I36 -> 0.13333333 | K35: 38 | L35: =K35/K36 -> 0.28787879 | M35: 109 | N35: =M35/M36 -> 0.19464286 | O35: 77 | P35: =O35/O36 -> 0.30314961 | Q35: 127 | R35: =Q35/Q36 -> 0.18247126
A36: Total | B36: =SUM(B29:B35) -> 17849 | C36: =SUM(C29:C35) -> 1 | D36: =SUM(D29:D35) -> 2018 | E36: =SUM(E29:E35) -> 1 | F36: =D36/B36 -> 0.11305956 | G36: =SUM(G29:G35) -> 361 | H36: =SUM(H29:H35) -> 1 | I36: =SUM(I29:I35) -> 15 | J36: =SUM(J29:J35) -> 1 | K36: =SUM(K29:K35) -> 132 | L36: =SUM(L29:L35) -> 1 | M36: =SUM(M29:M35) -> 560 | N36: =SUM(N29:N35) -> 1 | ... R36: =SUM(R29:R35) -> 1
A37: Median | B37: 24 | D37: 28 | G37: 28 | I37: 27 | K37: 32 | M37: 28 | O37: 32 | Q37: 26
A39: Ethnicity | B39: Total | D39: Respondent | F39: % | G39: Boulder Cty | I39: Brighton | K39: CCCS Online | M39: Larimer | O39: FRCC Online | Q39: Westminster
A40: 2 Or More | B40: 15 | C40: =B40/B48 -> 0.00084038321 | D40: 2 | E40: =D40/D48 -> 0.00099108028 | F40: =D40/B40 -> 0.13333333 | K40: 1 | L40: =K40/K48 -> 0.0075757576 | M40: 1 | N40: =M40/M48 -> 0.0017857143 | P40: =O40/O48 -> 0 | R40: =Q40/Q48 -> 0
A41: American Indian | B41: 366 | C41: =B41/B48 -> 0.02050535 | D41: 43 | E41: =D41/D48 -> 0.021308226 | F41: =D41/B41 -> 0.11748634 | G41: 12 | H41: =G41/G48 -> 0.033240997 | I41: 1 | J41: =I41/I48 -> 0.066666667 | K41: 2 | L41: =K41/K48 -> 0.015151515 | M41: 10 | N41: =M41/M48 -> 0.017857143 | O41: 7 | P41: =O41/O48 -> 0.027559055 | Q41: 11 | R41: =Q41/Q48 -> 0.015804598
A42: Asian | B42: 761 | C42: =B42/B48 -> 0.042635442 | D42: 65 | E42: =D42/D48 -> 0.032210109 | F42: =D42/B42 -> 0.085413929 | G42: 11 | H42: =G42/G48 -> 0.030470914 | J42: =I42/I48 -> 0 | K42: 2 | L42: =K42/K48 -> 0.015151515 | M42: 15 | N42: =M42/M48 -> 0.026785714 | O42: 7 | P42: =O42/O48 -> 0.027559055 | Q42: 30 | R42: =Q42/Q48 -> 0.043103448
A43: Black | B43: 393 | C43: =B43/B48 -> 0.02201804 | D43: 37 | E43: =D43/D48 -> 0.018334985 | F43: =D43/B43 -> 0.094147583 | G43: 10 | H43: =G43/G48 -> 0.027700831 | J43: =I43/I48 -> 0 | K43: 3 | L43: =K43/K48 -> 0.022727273 | M43: 5 | N43: =M43/M48 -> 0.0089285714 | O43: 9 | P43: =O43/O48 -> 0.035433071 | Q43: 10 | R43: =Q43/Q48 -> 0.014367816
A44: Hispanic | B44: 2367 | C44: =B44/B48 -> 0.13261247 | D44: 250 | E44: =D44/D48 -> 0.12388503 | F44: =D44/B44 -> 0.10561893 | G44: 39 | H44: =G44/G48 -> 0.10803324 | I44: 4 | J44: =I44/I48 -> 0.26666667 | K44: 12 | L44: =K44/K48 -> 0.090909091 | M44: 48 | N44: =M44/M48 -> 0.085714286 | O44: 38 | P44: =O44/O48 -> 0.1496063 | Q44: 109 | R44: =Q44/Q48 -> 0.1566092
A45: International | B45: 225 | C45: =B45/B48 -> 0.012605748 | D45: 35 | E45: =D45/D48 -> 0.017343905 | F45: =D45/B45 -> 0.15555556 | G45: 14 | H45: =G45/G48 -> 0.038781163 | I45: 1 | J45: =I45/I48 -> 0.066666667 | K45: 2 | L45: =K45/K48 -> 0.015151515 | M45: 5 | N45: =M45/M48 -> 0.0089285714 | O45: 2 | P45: =O45/O48 -> 0.0078740157 | Q45: 11 | R45: =Q45/Q48 -> 0.015804598
...

Sheet Demographics
A1: Survey of all Currently enrolled students Fall 2013 -- Demographics
A3: Primary Campus | B3: Total | D3: Respondent | F3: % of campus
A4: Boulder County | B4: 2474 | C4: =B4/B10 -> 0.1386072 | D4: 361 | E4: =D4/D10 -> 0.17888999 | F4: =D4/B4 -> 0.14591754
A5: Brighton | B5: 169 | C5: =B5/B10 -> 0.0094683176 | D5: 15 | E5: =D5/D10 -> 0.0074331021 | F5: =D5/B5 -> 0.088757396 | G5: Boulder Students were most likely to respond to survey.
A6: CCC Online | B6: 1609 | C6: =B6/B10 -> 0.090145106 | D6: 132 | E6: =D6/D10 -> 0.065411298 | F6: =D6/B6 -> 0.082038533 | G6: CCCOnline students were least likely to respond to the survey
A7: Larimer | B7: 5555 | C7: =B7/B10 -> 0.31122192 | D7: 560 | E7: =D7/D10 -> 0.27750248 | F7: =D7/B7 -> 0.10081008
A8: FRCC Online | B8: 2384 | C8: =B8/B10 -> 0.13356491 | D8: 254 | E8: =D8/D10 -> 0.1258672 | F8: =D8/B8 -> 0.10654362
A9: Westminster | B9: 5658 | C9: =B9/B10 -> 0.31699255 | D9: 696 | E9: =D9/D10 -> 0.34489594 | F9: =D9/B9 -> 0.12301166
A10: Total | B10: =SUM(B4:B9) -> 17849 | C10: =SUM(C4:C9) -> 1 | D10: =SUM(D4:D9) -> 2018 | E10: =SUM(E4:E9) -> 1 | F10: =D10/B10 -> 0.11305956
A12: Degree | B12: Total | D12: Respondent | F12: % | G12: Boulder Cty | I12: Brighton | K12: CCCS Online | M12: Larimer | O12: FRCC Online | Q12: Westminster
A13: A.A. | B13: 5702 | C13: =B13/B19 -> 0.31945767 | D13: 598 | E13: =D13/D19 -> 0.296333 | F13: =D13/B13 -> 0.10487548 | G13: 109 | H13: =G13/G19 -> 0.30193906 | I13: 2 | J13: =I13/I19 -> 0.13333333 | K13: 40 | L13: =K13/K19 -> 0.3030303 | M13: 171 | N13: =M13/M19 -> 0.30535714 | O13: 75 | P13: =O13/O19 -> 0.29527559 | Q13: 201 | R13: =Q13/Q19 -> 0.2887931
A14: A.A.S. | B14: 4875 | C14: =B14/B19 -> 0.27312454 | D14: 682 | E14: =D14/D19 -> 0.33795837 | F14: =D14/B14 -> 0.13989744 | G14: 92 | H14: =G14/G19 -> 0.25484765 | I14: 5 | J14: =I14/I19 -> 0.33333333 | K14: 42 | L14: =K14/K19 -> 0.31818182 | M14: 192 | N14: =M14/M19 -> 0.34285714 | O14: 101 | P14: =O14/O19 -> 0.3976378 | Q14: 250 | R14: =Q14/Q19 -> 0.3591954
A15: A.G.S. | B15: 978 | C15: =B15/B19 -> 0.054792986 | D15: 93 | E15: =D15/D19 -> 0.046085233 | F15: =D15/B15 -> 0.095092025 | G15: 14 | H15: =G15/G19 -> 0.038781163 | I15: 2 | J15: =I15/I19 -> 0.13333333 | K15: 5 | L15: =K15/K19 -> 0.037878788 | M15: 26 | N15: =M15/M19 -> 0.046428571 | O15: 15 | P15: =O15/O19 -> 0.059055118 | Q15: 31 | R15: =Q15/Q19 -> 0.04454023
A16: A.S. | B16: 3711 | C16: =B16/B19 -> 0.20791081 | D16: 385 | E16: =D16/D19 -> 0.19078295 | F16: =D16/B16 -> 0.10374562 | G16: 70 | H16: =G16/G19 -> 0.19390582 | I16: 4 | J16: =I16/I19 -> 0.26666667 | K16: 32 | L16: =K16/K19 -> 0.24242424 | M16: 101 | N16: =M16/M19 -> 0.18035714 | O16: 32 | P16: =O16/O19 -> 0.12598425 | Q16: 146 | R16: =Q16/Q19 -> 0.20977011
A17: Certificate | B17: 1249 | C17: =B17/B19 -> 0.069975909 | D17: 161 | E17: =D17/D19 -> 0.079781962 | F17: =D17/B17 -> 0.12890312 | G17: 54 | H17: =G17/G19 -> 0.14958449 | I17: 2 | J17: =I17/I19 -> 0.13333333 | K17: 4 | L17: =K17/K19 -> 0.03030303 | M17: 39 | N17: =M17/M19 -> 0.069642857 | O17: 24 | P17: =O17/O19 -> 0.094488189 | Q17: 38 | R17: =Q17/Q19 -> 0.054597701
A18: Undeclared | B18: 1334 | C18: =B18/B19 -> 0.074738081 | D18: 99 | E18: =D18/D19 -> 0.049058474 | F18: =D18/B18 -> 0.074212894 | G18: 22 | H18: =G18/G19 -> 0.060941828 | J18: =I18/I19 -> 0 | K18: 9 | L18: =K18/K19 -> 0.068181818 | M18: 31 | N18: =M18/M19 -> 0.055357143 | O18: 7 | P18: =O18/O19 -> 0.027559055 | Q18: 30 | R18: =Q18/Q19 -> 0.043103448
A19: Total | B19: =SUM(B13:B18) -> 17849 | C19: =SUM(C13:C18) -> 1 | D19: =SUM(D13:D18) -> 2018 | E19: =SUM(E13:E18) -> 1 | F19: =D19/B19 -> 0.11305956 | G19: =SUM(G13:G18) -> 361 | H19: =SUM(H13:H18) -> 1 | I19: =SUM(I13:I18) -> 15 | J19: =SUM(J13:J18) -> 1 | K19: =SUM(K13:K18) -> 132 | L19: =SUM(L13:L18) -> 1 | M19: =SUM(M13:M18) -> 560 | N19: =SUM(N13:N18) -> 1 | ... R19: =SUM(R13:R18) -> 1
A21: Sex | B21: Total | D21: Respondent | F21: % | G21: Boulder Cty | I21: Brighton | K21: CCCS Online | M21: Larimer | O21: FRCC Online | Q21: Westminster | S21: Women have higher response rates, and are more likely to attend the online campuses.
A22: Female | B22: 10082 | C22: =B22/B25 -> 0.56484957 | D22: 1403 | E22: =D22/D25 -> 0.69524281 | F22: =D22/B22 -> 0.1391589 | G22: 270 | H22: =G22/G25 -> 0.74792244 | I22: 12 | J22: =I22/I25 -> 0.8 | K22: 91 | L22: =K22/K25 -> 0.68939394 | M22: 344 | N22: =M22/M25 -> 0.61428571 | O22: 203 | P22: =O22/O25 -> 0.7992126 | Q22: 483 | R22: =Q22/Q25 -> 0.69396552
A23: Male | B23: 7757 | C23: =B23/B25 -> 0.43459017 | D23: 614 | E23: =D23/D25 -> 0.30426165 | F23: =D23/B23 -> 0.079154312 | G23: 91 | H23: =G23/G25 -> 0.25207756 | I23: 3 | J23: =I23/I25 -> 0.2 | K23: 41 | L23: =K23/K25 -> 0.31060606 | M23: 216 | N23: =M23/M25 -> 0.38571429 | O23: 50 | P23: =O23/O25 -> 0.19685039 | Q23: 213 | R23: =Q23/Q25 -> 0.30603448
A24: N | B24: 10 | C24: =B24/B25 -> 0.00056025548 | D24: 1 | E24: =D24/D25 -> 0.00049554014 | F24: =D24/B24 -> 0.1 | H24: =G24/G25 -> 0 | J24: =I24/I25 -> 0 | L24: =K24/K25 -> 0 | N24: =M24/M25 -> 0 | O24: 1 | P24: =O24/O25 -> 0.0039370079 | R24: =Q24/Q25 -> 0
A25: Total | B25: =SUM(B22:B24) -> 17849 | C25: =SUM(C22:C24) -> 1 | D25: =SUM(D22:D24) -> 2018 | E25: =SUM(E22:E24) -> 1 | F25: =D25/B25 -> 0.11305956 | G25: =SUM(G22:G24) -> 361 | H25: =SUM(H22:H24) -> 1 | I25: =SUM(I22:I24) -> 15 | J25: =SUM(J22:J24) -> 1 | K25: =SUM(K22:K24) -> 132 | L25: =SUM(L22:L24) -> 1 | M25: =SUM(M22:M24) -> 560 | N25: =SUM(N22:N24) -> 1 | ... R25: =SUM(R22:R24) -> 1
A27: Note: Students less than 18 years old were omitted from this survey because of uncertainty around confidentiality for underage students.
A28: Age | B28: Total | D28: Respondent | F28: % | G28: Boulder Cty | I28: Brighton | K28: CCCS Online | M28: Larimer | O28: FRCC Online | Q28: Westminster
A29: Less than 18 | C29: =B29/B36 -> 0
A30: 18 to 19 | B30: 3505 | C30: =B30/B36 -> 0.19636954 | D30: 307 | E30: =D30/D36 -> 0.15213082 | F30: =D30/B30 -> 0.087589158 | G30: 68 | H30: =G30/G36 -> 0.18836565 | I30: 2 | J30: =I30/I36 -> 0.13333333 | K30: 4 | L30: =K30/K36 -> 0.03030303 | M30: 92 | N30: =M30/M36 -> 0.16428571 | O30: 10 | P30: =O30/O36 -> 0.039370079 | Q30: 131 | R30: =Q30/Q36 -> 0.18821839 | S30: Respondents are older than the average student.
A31: 20 to 21 | B31: 3135 | C31: =B31/B36 -> 0.17564009 | D31: 227 | E31: =D31/D36 -> 0.11248761 | F31: =D31/B31 -> 0.072408293 | G31: 37 | H31: =G31/G36 -> 0.10249307 | I31: 4 | J31: =I31/I36 -> 0.26666667 | K31: 6 | L31: =K31/K36 -> 0.045454545 | M31: 74 | N31: =M31/M36 -> 0.13214286 | O31: 11 | P31: =O31/O36 -> 0.043307087 | Q31: 95 | R31: =Q31/Q36 -> 0.13649425
A32: 22 to 24 | B32: 3036 | C32: =B32/B36 -> 0.17009356 | D32: 237 | E32: =D32/D36 -> 0.11744301 | F32: =D32/B32 -> 0.078063241 | G32: 38 | H32: =G32/G36 -> 0.10526316 | I32: 1 | J32: =I32/I36 -> 0.066666667 | K32: 23 | L32: =K32/K36 -> 0.17424242 | M32: 56 | N32: =M32/M36 -> 0.1 | O32: 37 | P32: =O32/O36 -> 0.14566929 | Q32: 82 | R32: =Q32/Q36 -> 0.11781609 | S32: Online students are older than Site campus students
A33: 25 to 30 | B33: 3460 | C33: =B33/B36 -> 0.19384839 | D33: 394 | E33: =D33/D36 -> 0.19524281 | F33: =D33/B33 -> 0.11387283 | G33: 65 | H33: =G33/G36 -> 0.1800554 | I33: 3 | J33: =I33/I36 -> 0.2 | K33: 29 | L33: =K33/K36 -> 0.21969697 | M33: 115 | N33: =M33/M36 -> 0.20535714 | O33: 49 | P33: =O33/O36 -> 0.19291339 | Q33: 133 | R33: =Q33/Q36 -> 0.19109195
A34: 31 to 40 | B34: 2707 | C34: =B34/B36 -> 0.15166116 | D34: 409 | E34: =D34/D36 -> 0.20267592 | F34: =D34/B34 -> 0.15108977 | G34: 62 | H34: =G34/G36 -> 0.17174515 | I34: 3 | J34: =I34/I36 -> 0.2 | K34: 32 | L34: =K34/K36 -> 0.24242424 | M34: 114 | N34: =M34/M36 -> 0.20357143 | O34: 70 | P34: =O34/O36 -> 0.27559055 | Q34: 128 | R34: =Q34/Q36 -> 0.18390805
A35: Over 40 | B35: 2006 | C35: =B35/B36 -> 0.11238725 | D35: 444 | E35: =D35/D36 -> 0.22001982 | F35: =D35/B35 -> 0.22133599 | G35: 91 | H35: =G35/G36 -> 0.25207756 | I35: 2 | J35: =I35/I36 -> 0.13333333 | K35: 38 | L35: =K35/K36 -> 0.28787879 | M35: 109 | N35: =M35/M36 -> 0.19464286 | O35: 77 | P35: =O35/O36 -> 0.30314961 | Q35: 127 | R35: =Q35/Q36 -> 0.18247126
A36: Total | B36: =SUM(B29:B35) -> 17849 | C36: =SUM(C29:C35) -> 1 | D36: =SUM(D29:D35) -> 2018 | E36: =SUM(E29:E35) -> 1 | F36: =D36/B36 -> 0.11305956 | G36: =SUM(G29:G35) -> 361 | H36: =SUM(H29:H35) -> 1 | I36: =SUM(I29:I35) -> 15 | J36: =SUM(J29:J35) -> 1 | K36: =SUM(K29:K35) -> 132 | L36: =SUM(L29:L35) -> 1 | M36: =SUM(M29:M35) -> 560 | N36: =SUM(N29:N35) -> 1 | ... R36: =SUM(R29:R35) -> 1
A37: Median | B37: 24 | D37: 28 | G37: 28 | I37: 27 | K37: 32 | M37: 28 | O37: 32 | Q37: 26
A39: Ethnicity | B39: Total | D39: Respondent | F39: % | G39: Boulder Cty | I39: Brighton | K39: CCCS Online | M39: Larimer | O39: FRCC Online | Q39: Westminster | S39: International Students have the highest response rates.
A40: 2 Or More | B40: 15 | C40: =B40/B48 -> 0.00084038321 | D40: 2 | E40: =D40/D48 -> 0.00099108028 | F40: =D40/B40 -> 0.13333333 | K40: 1 | L40: =K40/K48 -> 0.0075757576 | M40: 1 | N40: =M40/M48 -> 0.0017857143 | P40: =O40/O48 -> 0 | R40: =Q40/Q48 -> 0
A41: American Indian | B41: 366 | C41: =B41/B48 -> 0.02050535 | D41: 43 | E41: =D41/D48 -> 0.021308226 | F41: =D41/B41 -> 0.11748634 | G41: 12 | H41: =G41/G48 -> 0.033240997 | I41: 1 | J41: =I41/I48 -> 0.066666667 | K41: 2 | L41: =K41/K48 -> 0.015151515 | M41: 10 | N41: =M41/M48 -> 0.017857143 | O41: 7 | P41: =O41/O48 -> 0.027559055 | Q41: 11 | R41: =Q41/Q48 -> 0.015804598
A42: Asian | B42: 761 | C42: =B42/B48 -> 0.042635442 | D42: 65 | E42: =D42/D48 -> 0.032210109 | F42: =D42/B42 -> 0.085413929 | G42: 11 | H42: =G42/G48 -> 0.030470914 | J42: =I42/I48 -> 0 | K42: 2 | L42: =K42/K48 -> 0.015151515 | M42: 15 | N42: =M42/M48 -> 0.026785714 | O42: 7 | P42: =O42/O48 -> 0.027559055 | Q42: 30 | R42: =Q42/Q48 -> 0.043103448
A43: Black | B43: 393 | C43: =B43/B48 -> 0.02201804 | D43: 37 | E43: =D43/D48 -> 0.018334985 | F43: =D43/B43 -> 0.094147583 | G43: 10 | H43: =G43/G48 -> 0.027700831 | J43: =I43/I48 -> 0 | K43: 3 | L43: =K43/K48 -> 0.022727273 | M43: 5 | N43: =M43/M48 -> 0.0089285714 | O43: 9 | P43: =O43/O48 -> 0.035433071 | Q43: 10 | R43: =Q43/Q48 -> 0.014367816
A44: Hispanic | B44: 2367 | C44: =B44/B48 -> 0.13261247 | D44: 250 | E44: =D44/D48 -> 0.12388503 | F44: =D44/B44 -> 0.10561893 | G44: 39 | H44: =G44/G48 -> 0.10803324 | I44: 4 | J44: =I44/I48 -> 0.26666667 | K44: 12 | L44: =K44/K48 -> 0.090909091 | M44: 48 | N44: =M44/M48 -> 0.085714286 | O44: 38 | P44: =O44/O48 -> 0.1496063 | Q44: 109 | R44: =Q44/Q48 -> 0.1566092 | S44: Highest concentration of Hispancs are at Brighton
A45: International | B45: 225 | C45: =B45/B48 -> 0.012605748 | D45: 35 | E45: =D45/D48 -> 0.017343905 | F45: =D45/B45 -> 0.15555556 | G45: 14 | H45: =G45/G48 -> 0.038781163 | I45: 1 | J45: =I45/I48 -> 0.066666667 | K45: 2 | L45: =K45/K48 -> 0.015151515 | M45: 5 | N45: =M45/M48 -> 0.0089285714 | O45: 2 | P45: =O45/O48 -> 0.0078740157 | Q45: 11 | R45: =Q45/Q48 -> 0.015804598
...

Sheet Obj Emp 
A1: Survey of all Currently enrolled students Fall 2013 -- Objectives and Employment
A3: What is the MAIN reason you are attending FRCC? | B3: Boulder Cty | D3: Brighton | F3: CCCS Online | H3: Larimer | J3: FRCC Online | L3: Westminster | N3: Total | P3: Obtaining transfer credits is the most common goal. Only 3% indicate they are at FRCC for "Personal Interest".
A4: Earn an Academic Degree (AA, AS, AGS) | B4: 162 | C4: =B4/B12 -> 0.46820809 | D4: 6 | E4: =D4/D12 -> 0.42857143 | F4: 67 | G4: =F4/F12 -> 0.54032258 | H4: 267 | I4: =H4/H12 -> 0.48722628 | J4: 151 | K4: =J4/J12 -> 0.62916667 | L4: 337 | M4: =L4/L12 -> 0.49558824 | N4: =L4+J4+H4+F4+D4+B4 -> 990 | O4: =N4/N12 -> 0.50717213
A5: Earn a Vocational/Technical Degree (AAS) | B5: 23 | C5: =B5/B12 -> 0.066473988 | D5: 4 | E5: =D5/D12 -> 0.28571429 | F5: 11 | G5: =F5/F12 -> 0.088709677 | H5: 71 | I5: =H5/H12 -> 0.12956204 | J5: 22 | K5: =J5/J12 -> 0.091666667 | L5: 83 | M5: =L5/L12 -> 0.12205882 | N5: =L5+J5+H5+F5+D5+B5 -> 214 | O5: =N5/N12 -> 0.10963115
A6: Earn a Vo/Tech Certificate | B6: 38 | C6: =B6/B12 -> 0.10982659 | D6: 1 | E6: =D6/D12 -> 0.071428571 | F6: 4 | G6: =F6/F12 -> 0.032258065 | H6: 31 | I6: =H6/H12 -> 0.056569343 | J6: 14 | K6: =J6/J12 -> 0.058333333 | L6: 34 | M6: =L6/L12 -> 0.05 | N6: =L6+J6+H6+F6+D6+B6 -> 122 | O6: =N6/N12 -> 0.0625
A7: Take a few courses, transfer | B7: 80 | C7: =B7/B12 -> 0.23121387 | E7: =D7/D12 -> 0 | F7: 30 | G7: =F7/F12 -> 0.24193548 | H7: 129 | I7: =H7/H12 -> 0.23540146 | J7: 37 | K7: =J7/J12 -> 0.15416667 | L7: 187 | M7: =L7/L12 -> 0.275 | N7: =L7+J7+H7+F7+D7+B7 -> 463 | O7: =N7/N12 -> 0.23719262
A8: Prepare to enter job market | B8: 14 | C8: =B8/B12 -> 0.040462428 | D8: 1 | E8: =D8/D12 -> 0.071428571 | F8: 5 | G8: =F8/F12 -> 0.040322581 | H8: 18 | I8: =H8/H12 -> 0.032846715 | J8: 8 | K8: =J8/J12 -> 0.033333333 | L8: 12 | M8: =L8/L12 -> 0.017647059 | N8: =L8+J8+H8+F8+D8+B8 -> 58 | O8: =N8/N12 -> 0.029713115
A9: Improve skills for present job | B9: 8 | C9: =B9/B12 -> 0.023121387 | D9: 1 | E9: =D9/D12 -> 0.071428571 | F9: 4 | G9: =F9/F12 -> 0.032258065 | H9: 13 | I9: =H9/H12 -> 0.023722628 | J9: 4 | K9: =J9/J12 -> 0.016666667 | L9: 13 | M9: =L9/L12 -> 0.019117647 | N9: =L9+J9+H9+F9+D9+B9 -> 43 | O9: =N9/N12 -> 0.022028689
A10: Receive financial aid benefits | B10: 1 | C10: =B10/B12 -> 0.0028901734 | E10: =D10/D12 -> 0 | G10: =F10/F12 -> 0 | H10: 4 | I10: =H10/H12 -> 0.0072992701 | K10: =J10/J12 -> 0 | L10: 3 | M10: =L10/L12 -> 0.0044117647 | N10: =L10+J10+H10+F10+D10+B10 -> 8 | O10: =N10/N12 -> 0.0040983607
A11: Personal Interest | B11: 20 | C11: =B11/B12 -> 0.057803468 | D11: 1 | E11: =D11/D12 -> 0.071428571 | F11: 3 | G11: =F11/F12 -> 0.024193548 | H11: 15 | I11: =H11/H12 -> 0.027372263 | J11: 4 | K11: =J11/J12 -> 0.016666667 | L11: 11 | M11: =L11/L12 -> 0.016176471 | N11: =L11+J11+H11+F11+D11+B11 -> 54 | O11: =N11/N12 -> 0.027663934
A12: Total | B12: =SUM(B4:B11) -> 346 | C12: =SUM(C4:C11) -> 1 | D12: =SUM(D4:D11) -> 14 | E12: =SUM(E4:E11) -> 1 | F12: =SUM(F4:F11) -> 124 | G12: =SUM(G4:G11) -> 1 | H12: =SUM(H4:H11) -> 548 | I12: =SUM(I4:I11) -> 1 | ... O12: =SUM(O4:O11) -> 1
A14: Present employment status | B14: Boulder Cty | D14: Brighton | F14: CCCS Online | H14: Larimer | J14: FRCC Online | L14: Westminster | N14: Total | P14: 63% of students are Employed.
A15: Employed | B15: 228 | C15: =B15/B19 -> 0.63865546 | D15: 12 | E15: =D15/D19 -> 0.8 | F15: 86 | G15: =F15/F19 -> 0.65648855 | H15: 342 | I15: =H15/H19 -> 0.61621622 | J15: 156 | K15: =J15/J19 -> 0.61904762 | L15: 430 | M15: =L15/L19 -> 0.62228654 | N15: =B15+D15+F15+H15+J15+L15 -> 1254 | O15: =N15/N19 -> 0.62668666
A16: Military | B16: 1 | C16: =B16/B19 -> 0.0028011204 | E16: =D16/D19 -> 0 | F16: 2 | G16: =F16/F19 -> 0.015267176 | H16: 4 | I16: =H16/H19 -> 0.0072072072 | K16: =J16/J19 -> 0 | L16: 6 | M16: =L16/L19 -> 0.008683068 | N16: =B16+D16+F16+H16+J16+L16 -> 13 | O16: =N16/N19 -> 0.0064967516
A17: Unemployed Seeking Employment | B17: 54 | C17: =B17/B19 -> 0.1512605 | D17: 2 | E17: =D17/D19 -> 0.13333333 | F17: 25 | G17: =F17/F19 -> 0.19083969 | H17: 100 | I17: =H17/H19 -> 0.18018018 | J17: 49 | K17: =J17/J19 -> 0.19444444 | L17: 122 | M17: =L17/L19 -> 0.17655572 | N17: =B17+D17+F17+H17+J17+L17 -> 352 | O17: =N17/N19 -> 0.17591204
A18: Unemployed NOT seeking employment | B18: 74 | C18: =B18/B19 -> 0.20728291 | D18: 1 | E18: =D18/D19 -> 0.066666667 | F18: 18 | G18: =F18/F19 -> 0.13740458 | H18: 109 | I18: =H18/H19 -> 0.1963964 | J18: 47 | K18: =J18/J19 -> 0.18650794 | L18: 133 | M18: =L18/L19 -> 0.19247467 | N18: =B18+D18+F18+H18+J18+L18 -> 382 | O18: =N18/N19 -> 0.19090455
A19: Total | B19: =SUM(B15:B18) -> 357 | C19: =SUM(C15:C18) -> 1 | D19: =SUM(D15:D18) -> 15 | E19: =SUM(E15:E18) -> 1 | F19: =SUM(F15:F18) -> 131 | G19: =SUM(G15:G18) -> 1 | H19: =SUM(H15:H18) -> 555 | I19: =SUM(I15:I18) -> 1 | ... O19: =SUM(O15:O18) -> 1
A21: If employed, how many hours per week are you working | B21: Boulder Cty | D21: Brighton | F21: CCCS Online | H21: Larimer | J21: FRCC Online | L21: Westminster | N21: Total | P21: Online students are most likely to be full-time students
A22: 20 or less | B22: 98 | C22: =B22/B25 -> 0.4 | D22: 5 | E22: =D22/D25 -> 0.38461538 | F22: 22 | G22: =F22/F25 -> 0.23913043 | H22: 148 | I22: =H22/H25 -> 0.41456583 | J22: 24 | K22: =J22/J25 -> 0.14371257 | L22: 155 | M22: =L22/L25 -> 0.33549784 | N22: =B22+D22+F22+H22+J22+L22 -> 452 | O22: =N22/N25 -> 0.33832335
A23: 21-39 | B23: 103 | C23: =B23/B25 -> 0.42040816 | D23: 4 | E23: =D23/D25 -> 0.30769231 | F23: 23 | G23: =F23/F25 -> 0.25 | H23: 136 | I23: =H23/H25 -> 0.38095238 | J23: 42 | K23: =J23/J25 -> 0.25149701 | L23: 183 | M23: =L23/L25 -> 0.3961039 | N23: =B23+D23+F23+H23+J23+L23 -> 491 | O23: =N23/N25 -> 0.36751497
A24: 40 or more | B24: 44 | C24: =B24/B25 -> 0.17959184 | D24: 4 | E24: =D24/D25 -> 0.30769231 | F24: 47 | G24: =F24/F25 -> 0.51086957 | H24: 73 | I24: =H24/H25 -> 0.20448179 | J24: 101 | K24: =J24/J25 -> 0.60479042 | L24: 124 | M24: =L24/L25 -> 0.26839827 | N24: =B24+D24+F24+H24+J24+L24 -> 393 | O24: =N24/N25 -> 0.29416168
A25: Total | B25: =SUM(B22:B24) -> 245 | C25: =SUM(C22:C24) -> 1 | D25: =SUM(D22:D24) -> 13 | E25: =SUM(E22:E24) -> 1 | F25: =SUM(F22:F24) -> 92 | G25: =SUM(G22:G24) -> 1 | H25: =SUM(H22:H24) -> 357 | I25: =SUM(I22:I24) -> 1 | ... M25: =SUM(M22:M24) -> 1 | N25: =SUM(N21:N24) -> 1336 | O25: =SUM(O21:O24) -> 1
A27: How many credit hours are you taking this semester? | B27: Boulder Cty | D27: Brighton | F27: CCCS Online | H27: Larimer | J27: FRCC Online | L27: Westminster | N27: Total | P27: Larimer students are most likely to be full-time students
A28: 4 or less | B28: 44 | C28: =B28/B31 -> 0.12290503 | D28: 4 | E28: =D28/D31 -> 0.26666667 | F28: 17 | G28: =F28/F31 -> 0.12977099 | H28: 41 | I28: =H28/H31 -> 0.07400722 | J28: 36 | K28: =J28/J31 -> 0.14229249 | L28: 65 | M28: =L28/L31 -> 0.093930636 | N28: =B28+D28+F28+H28+J28+L28 -> 207 | O28: =N28/N31 -> 0.10334498
A29: 5 to 11 | B29: 168 | C29: =B29/B31 -> 0.46927374 | D29: 8 | E29: =D29/D31 -> 0.53333333 | F29: 74 | G29: =F29/F31 -> 0.5648855 | H29: 216 | I29: =H29/H31 -> 0.3898917 | J29: 155 | K29: =J29/J31 -> 0.61264822 | L29: 324 | M29: =L29/L31 -> 0.46820809 | N29: =B29+D29+F29+H29+J29+L29 -> 945 | O29: =N29/N31 -> 0.47179231
A30: 12 or more | B30: 146 | C30: =B30/B31 -> 0.40782123 | D30: 3 | E30: =D30/D31 -> 0.2 | F30: 40 | G30: =F30/F31 -> 0.30534351 | H30: 297 | I30: =H30/H31 -> 0.53610108 | J30: 62 | K30: =J30/J31 -> 0.24505929 | L30: 303 | M30: =L30/L31 -> 0.43786127 | N30: =B30+D30+F30+H30+J30+L30 -> 851 | O30: =N30/N31 -> 0.42486271
A31: Total | B31: =SUM(B28:B30) -> 358 | C31: =SUM(C28:C30) -> 1 | D31: =SUM(D28:D30) -> 15 | E31: =SUM(E28:E30) -> 1 | F31: =SUM(F28:F30) -> 131 | G31: =SUM(G28:G30) -> 1 | H31: =SUM(H28:H30) -> 554 | I31: =SUM(I28:I30) -> 1 | ... O31: =SUM(O28:O30) -> 1

Sheet Meeting needs
A1: Survey of all Currently enrolled students Fall 2013 -- Meeting Needs
A3: How would you rate your FRCC experience so far? | B3: Boulder Cty | D3: Brighton | F3: CCCS Online | H3: Larimer | J3: FRCC Online | L3: Westminster | N3: Total
A4: Very Good | B4: 169 | C4: =B4/B8 -> 0.47206704 | D4: 6 | E4: =D4/D8 -> 0.4 | F4: 49 | G4: =F4/F8 -> 0.37984496 | H4: 252 | I4: =H4/H8 -> 0.4606947 | J4: 101 | K4: =J4/J8 -> 0.39920949 | L4: 300 | M4: =L4/L8 -> 0.43668122 | N4: =B4+D4+F4+H4+J4+L4 -> 877 | O4: =N4/N8 -> 0.44092509
A5: Good | B5: 171 | C5: =B5/B8 -> 0.47765363 | D5: 8 | E5: =D5/D8 -> 0.53333333 | F5: 63 | G5: =F5/F8 -> 0.48837209 | H5: 280 | I5: =H5/H8 -> 0.511883 | J5: 133 | K5: =J5/J8 -> 0.5256917 | L5: 358 | M5: =L5/L8 -> 0.52110626 | N5: =B5+D5+F5+H5+J5+L5 -> 1013 | O5: =N5/N8 -> 0.50930116
A6: Poor | B6: 12 | C6: =B6/B8 -> 0.033519553 | D6: 1 | E6: =D6/D8 -> 0.066666667 | F6: 13 | G6: =F6/F8 -> 0.10077519 | H6: 13 | I6: =H6/H8 -> 0.023765996 | J6: 12 | K6: =J6/J8 -> 0.04743083 | L6: 22 | M6: =L6/L8 -> 0.03202329 | N6: =B6+D6+F6+H6+J6+L6 -> 73 | O6: =N6/N8 -> 0.03670186
A7: Very Poor | B7: 6 | C7: =B7/B8 -> 0.016759777 | E7: =D7/D8 -> 0 | F7: 4 | G7: =F7/F8 -> 0.031007752 | H7: 2 | I7: =H7/H8 -> 0.0036563071 | J7: 7 | K7: =J7/J8 -> 0.027667984 | L7: 7 | M7: =L7/L8 -> 0.010189229 | N7: =B7+D7+F7+H7+J7+L7 -> 26 | O7: =N7/N8 -> 0.013071895
A8: Total | B8: =SUM(B4:B7) -> 358 | C8: =SUM(C4:C7) -> 1 | D8: =SUM(D4:D7) -> 15 | E8: =SUM(E4:E7) -> 1 | F8: =SUM(F4:F7) -> 129 | G8: =SUM(G4:G7) -> 1 | H8: =SUM(H4:H7) -> 547 | I8: =SUM(I4:I7) -> 1 | ... O8: =SUM(O4:O7) -> 1
A9: Percent of Good or Very Good | C9: =SUM(C4:C5) -> 0.94972067 | E9: =SUM(E4:E5) -> 0.93333333 | G9: =SUM(G4:G5) -> 0.86821705 | I9: =SUM(I4:I5) -> 0.9725777 | K9: =SUM(K4:K5) -> 0.92490119 | M9: =SUM(M4:M5) -> 0.95778748 | O9: =SUM(O4:O5) -> 0.95022624
A11: Percent of question Respondents who agree with the following: | B11: Boulder Cty | D11: Brighton | F11: CCCS Online | H11: Larimer | J11: FRCC Online | L11: Westminster | N11: Total
A12: Instructional program is meeting your educational goals. | B12: 336 | C12: 0.93854749 | D12: 12 | E12: 0.8 | F12: 113 | G12: 0.86259542 | H12: 524 | I12: 0.94584838 | J12: 229 | K12: 0.90513834 | L12: 647 | M12: 0.93768116 | N12: =B12+D12+F12+H12+J12+L12 -> 1861 | O12: =AVERAGE(C12,E12,G12,I12,K12,M12) -> 0.8983018
A13: Is the use of technology helping you learn at FRCC? | B13: 321 | C13: 0.89415042 | D13: 15 | E13: 1 | F13: 118 | G13: 0.90076336 | H13: 508 | I13: 0.92531876 | J13: 237 | K13: 0.948 | L13: 627 | M13: 0.91399417 | N13: =B13+D13+F13+H13+J13+L13 -> 1826 | O13: =AVERAGE(C13,E13,G13,I13,K13,M13) -> 0.93037112
A14: Are the Technology skills you are learning complete and up-to-date? | B14: 314 | C14: 0.89971347 | D14: 14 | E14: 0.93333333 | F14: 112 | G14: 0.86821705 | H14: 498 | I14: 0.91544118 | J14: 230 | K14: 0.92 | L14: 620 | M14: 0.91851852 | N14: =B14+D14+F14+H14+J14+L14 -> 1788 | O14: =AVERAGE(C14,E14,G14,I14,K14,M14) -> 0.90920392
A16: Faculty promote cultural diversity awareness and learning in the classroom | B16: Boulder Cty | D16: Brighton | F16: CCCS Online | H16: Larimer | J16: FRCC Online | L16: Westminster | N16: Total
A17: Not enough | B17: 17 | C17: =B17/B21 -> 0.04735376 | E17: =D17/D21 -> 0 | F17: 9 | G17: =F17/F21 -> 0.069767442 | H17: 45 | I17: =H17/H21 -> 0.082116788 | J17: 16 | K17: =J17/J21 -> 0.064257028 | L17: 50 | M17: =L17/L21 -> 0.073206442 | N17: =B17+D17+F17+H17+J17+L17 -> 137 | O17: =N17/N21 -> 0.069087242
A18: About right amount | B18: 274 | C18: =B18/B21 -> 0.7632312 | D18: 12 | E18: =D18/D21 -> 0.8 | F18: 69 | G18: =F18/F21 -> 0.53488372 | H18: 373 | I18: =H18/H21 -> 0.68065693 | J18: 158 | K18: =J18/J21 -> 0.63453815 | L18: 484 | M18: =L18/L21 -> 0.70863836 | N18: =B18+D18+F18+H18+J18+L18 -> 1370 | O18: =N18/N21 -> 0.69087242
A19: Too much | B19: 11 | C19: =B19/B21 -> 0.030640669 | E19: =D19/D21 -> 0 | F19: 5 | G19: =F19/F21 -> 0.03875969 | H19: 6 | I19: =H19/H21 -> 0.010948905 | J19: 2 | K19: =J19/J21 -> 0.0080321285 | L19: 11 | M19: =L19/L21 -> 0.016105417 | N19: =B19+D19+F19+H19+J19+L19 -> 35 | O19: =N19/N21 -> 0.017650025
A20: Don't know/ don't care | B20: 57 | C20: =B20/B21 -> 0.15877437 | D20: 3 | E20: =D20/D21 -> 0.2 | F20: 46 | G20: =F20/F21 -> 0.35658915 | H20: 124 | I20: =H20/H21 -> 0.22627737 | J20: 73 | K20: =J20/J21 -> 0.29317269 | L20: 138 | M20: =L20/L21 -> 0.20204978 | N20: =B20+D20+F20+H20+J20+L20 -> 441 | O20: =N20/N21 -> 0.22239032
B21: =SUM(B17:B20) -> 359 | C21: =SUM(C17:C20) -> 1 | D21: =SUM(D17:D20) -> 15 | E21: =SUM(E17:E20) -> 1 | F21: =SUM(F17:F20) -> 129 | G21: =SUM(G17:G20) -> 1 | H21: =SUM(H17:H20) -> 548 | I21: =SUM(I17:I20) -> 1 | ... O21: =SUM(O17:O20) -> 1
A23: FRCC student life has programs that promote campus cultural diversity awareness and learning | B23: Boulder Cty | D23: Brighton | F23: CCCS Online | H23: Larimer | J23: FRCC Online | L23: Westminster | N23: Total
A24: Not enough | B24: 29 | C24: =B24/B28 -> 0.081232493 | D24: 1 | E24: =D24/D28 -> 0.066666667 | F24: 11 | G24: =F24/F28 -> 0.085271318 | H24: 44 | I24: =H24/H28 -> 0.081180812 | J24: 15 | K24: =J24/J28 -> 0.060728745 | L24: 48 | M24: =L24/L28 -> 0.070484581 | N24: =B24+D24+F24+H24+J24+L24 -> 148 | O24: =N24/N28 -> 0.075088787
A25: About right amount | B25: 188 | C25: =B25/B28 -> 0.52661064 | D25: 7 | E25: =D25/D28 -> 0.46666667 | F25: 38 | G25: =F25/F28 -> 0.29457364 | H25: 268 | I25: =H25/H28 -> 0.49446494 | J25: 109 | K25: =J25/J28 -> 0.44129555 | L25: 331 | M25: =L25/L28 -> 0.48604993 | N25: =B25+D25+F25+H25+J25+L25 -> 941 | O25: =N25/N28 -> 0.47742263
A26: Too much | B26: 12 | C26: =B26/B28 -> 0.033613445 | E26: =D26/D28 -> 0 | F26: 2 | G26: =F26/F28 -> 0.015503876 | H26: 12 | I26: =H26/H28 -> 0.022140221 | K26: =J26/J28 -> 0 | L26: 10 | M26: =L26/L28 -> 0.014684288 | N26: =B26+D26+F26+H26+J26+L26 -> 36 | O26: =N26/N28 -> 0.01826484
A27: Don't know/ don't care | B27: 128 | C27: =B27/B28 -> 0.35854342 | D27: 7 | E27: =D27/D28 -> 0.46666667 | F27: 78 | G27: =F27/F28 -> 0.60465116 | H27: 218 | I27: =H27/H28 -> 0.40221402 | J27: 123 | K27: =J27/J28 -> 0.49797571 | L27: 292 | M27: =L27/L28 -> 0.4287812 | N27: =B27+D27+F27+H27+J27+L27 -> 846 | O27: =N27/N28 -> 0.42922374
B28: =SUM(B24:B27) -> 357 | C28: =SUM(C24:C27) -> 1 | D28: =SUM(D24:D27) -> 15 | E28: =SUM(E24:E27) -> 1 | F28: =SUM(F24:F27) -> 129 | G28: =SUM(G24:G27) -> 1 | H28: =SUM(H24:H27) -> 542 | I28: =SUM(I24:I27) -> 1 | ... O28: =SUM(O24:O27) -> 1
A30: When do you prefer to take classes: | B30: Boulder Cty | D30: Brighton | F30: CCCS Online | H30: Larimer | J30: FRCC Online | L30: Westminster | N30: Total | P30: Campuses vary on when they prefer to take their courses, with the online students most likely to want evening/weekend classes.
A31: Mornings | B31: 259 | C31: =B31/B35 -> 0.4072327 | D31: 9 | E31: =D31/D35 -> 0.32142857 | F31: 52 | G31: =F31/F35 -> 0.2212766 | H31: 371 | I31: =H31/H35 -> 0.40282302 | J31: 105 | K31: =J31/J35 -> 0.23281596 | L31: 443 | M31: =L31/L35 -> 0.38156761 | N31: =B31+D31+F31+H31+J31+L31 -> 1239 | O31: =N31/N35 -> 0.36101399
A32: Afternoons | B32: 224 | C32: =B32/B35 -> 0.35220126 | D32: 11 | E32: =D32/D35 -> 0.39285714 | F32: 53 | G32: =F32/F35 -> 0.22553191 | H32: 333 | I32: =H32/H35 -> 0.36156352 | J32: 103 | K32: =J32/J35 -> 0.22838137 | L32: 399 | M32: =L32/L35 -> 0.34366925 | N32: =B32+D32+F32+H32+J32+L32 -> 1123 | O32: =N32/N35 -> 0.32721445
A33: Evenings | B33: 114 | C33: =B33/B35 -> 0.17924528 | D33: 7 | E33: =D33/D35 -> 0.25 | F33: 84 | G33: =F33/F35 -> 0.35744681 | H33: 174 | I33: =H33/H35 -> 0.18892508 | J33: 159 | K33: =J33/J35 -> 0.35254989 | L33: 259 | M33: =L33/L35 -> 0.22308355 | N33: =B33+D33+F33+H33+J33+L33 -> 797 | O33: =N33/N35 -> 0.23222611
A34: Weekends | B34: 39 | C34: =B34/B35 -> 0.061320755 | D34: 1 | E34: =D34/D35 -> 0.035714286 | F34: 46 | G34: =F34/F35 -> 0.19574468 | H34: 43 | I34: =H34/H35 -> 0.046688382 | J34: 84 | K34: =J34/J35 -> 0.18625277 | L34: 60 | M34: =L34/L35 -> 0.051679587 | N34: =B34+D34+F34+H34+J34+L34 -> 273 | O34: =N34/N35 -> 0.079545455
A35: Total (can choose multiples) | B35: =SUM(B31:B34) -> 636 | C35: =SUM(C31:C34) -> 1 | D35: =SUM(D31:D34) -> 28 | E35: =SUM(E31:E34) -> 1 | F35: =SUM(F31:F34) -> 235 | G35: =SUM(G31:G34) -> 1 | H35: =SUM(H31:H34) -> 921 | I35: =SUM(I31:I34) -> 1 | ... O35: =SUM(O31:O34) -> 1

Sheet Evaluate Instruction
A1: Survey of all Currently enrolled students Fall 2013 -- Evaluate Instruction
A2: Course Availability had the lowest level of satisfaction.
Q3: Attributes rated at less than 90% satisfaction are highlighted. Course Availability affects all campuses
A4: Quality of instruction | B4: Boulder Cty | D4: Brighton | F4: CCCS Online | H4: Larimer | J4: FRCC Online | L4: Westminster | N4: Total | Q4: EVALUATE FRCC INSTRUCTION | R4: Boulder | S4: Brighton | T4: CCCS Onl | U4: Larimer | V4: FRCC Onl | W4: Westminster | X4: Total
A5: Very good | B5: 176 | C5: =B5/B9 -> 0.5 | D5: 7 | E5: =D5/D9 -> 0.46666667 | F5: 50 | G5: =F5/F9 -> 0.3968254 | H5: 269 | I5: =H5/H9 -> 0.49722736 | J5: 103 | K5: =J5/J9 -> 0.42040816 | L5: 332 | M5: =L5/L9 -> 0.49185185 | N5: =B5+D5+F5+H5+J5+L5 -> 937 | O5: =N5/N9 -> 0.47952917 | Q5: Quality of instruction | R5: =C10 -> 0.94886364 | S5: =E10 -> 0.86666667 | T5: =G10 -> 0.8968254 | U5: =I10 -> 0.97966728 | V5: =K10 -> 0.93877551 | W5: =M10 -> 0.96740741 | X5: =O10 -> 0.95854657
A6: Good | B6: 158 | C6: =B6/B9 -> 0.44886364 | D6: 6 | E6: =D6/D9 -> 0.4 | F6: 63 | G6: =F6/F9 -> 0.5 | H6: 261 | I6: =H6/H9 -> 0.48243993 | J6: 127 | K6: =J6/J9 -> 0.51836735 | L6: 321 | M6: =L6/L9 -> 0.47555556 | N6: =B6+D6+F6+H6+J6+L6 -> 936 | O6: =N6/N9 -> 0.4790174 | Q6: Instructor's knowledge of subject | R6: =C18 -> 0.97727273 | S6: =E18 -> 0.86666667 | T6: =G18 -> 0.944 | U6: =I18 -> 0.98523985 | V6: =K18 -> 0.9755102 | W6: =M18 -> 0.98216939 | X6: =O18 -> 0.97797131
A7: Poor | B7: 14 | C7: =B7/B9 -> 0.039772727 | D7: 1 | E7: =D7/D9 -> 0.066666667 | F7: 9 | G7: =F7/F9 -> 0.071428571 | H7: 11 | I7: =H7/H9 -> 0.020332717 | J7: 12 | K7: =J7/J9 -> 0.048979592 | L7: 17 | M7: =L7/L9 -> 0.025185185 | N7: =B7+D7+F7+H7+J7+L7 -> 64 | O7: =N7/N9 -> 0.032753327 | Q7: Course objectives & requirements made clear | R7: =C26 -> 0.95170455 | S7: =E26 -> 1 | T7: =G26 -> 0.84 | U7: =I26 -> 0.95563771 | V7: =K26 -> 0.90612245 | W7: =M26 -> 0.94510386 | X7: =O26 -> 0.9380123
A8: Very poor | B8: 4 | C8: =B8/B9 -> 0.011363636 | D8: 1 | E8: =D8/D9 -> 0.066666667 | F8: 4 | G8: =F8/F9 -> 0.031746032 | I8: =H8/H9 -> 0 | J8: 3 | K8: =J8/J9 -> 0.012244898 | L8: 5 | M8: =L8/L9 -> 0.0074074074 | N8: =B8+D8+F8+H8+J8+L8 -> 17 | O8: =N8/N9 -> 0.0087001024 | Q8: Course content | R8: =C34 -> 0.96296296 | S8: =E34 -> 1 | T8: =G34 -> 0.86507937 | U8: =I34 -> 0.98518519 | V8: =K34 -> 0.94693878 | W8: =M34 -> 0.97181009 | X8: =O34 -> 0.96412096
A9: Total | B9: =SUM(B5:B8) -> 352 | C9: =SUM(C5:C8) -> 1 | D9: =SUM(D5:D8) -> 15 | E9: =SUM(E5:E8) -> 1 | F9: =SUM(F5:F8) -> 126 | G9: =SUM(G5:G8) -> 1 | H9: =SUM(H5:H8) -> 541 | I9: =SUM(I5:I8) -> 1 | ... M9: =SUM(M5:M8) -> 1 | N9: =SUM(N3:N8) -> 1954 | O9: =SUM(O3:O8) -> 1 | Q9: Instructional methods | R9: =C42 -> 0.9031339 | S9: =E42 -> 0.93333333 | T9: =G42 -> 0.84 | U9: =I42 -> 0.93357934 | V9: =K42 -> 0.89795918 | W9: =M42 -> 0.9346211 | X9: =O42 -> 0.91799077
A10: Percent of Good or Very Good | C10: =SUM(C5:C6) -> 0.94886364 | E10: =SUM(E5:E6) -> 0.86666667 | G10: =SUM(G5:G6) -> 0.8968254 | I10: =SUM(I5:I6) -> 0.97966728 | K10: =SUM(K5:K6) -> 0.93877551 | M10: =SUM(M5:M6) -> 0.96740741 | O10: =SUM(O5:O6) -> 0.95854657 | Q10: Testing and grading | R10: =C50 -> 0.9226361 | S10: =E50 -> 0.93333333 | T10: =G50 -> 0.90322581 | U10: =I50 -> 0.94248609 | V10: =K50 -> 0.91056911 | W10: =M50 -> 0.93768546 | X10: =O50 -> 0.93066256
Q11: Class Size | R11: =C58 -> 0.99430199 | S11: =E58 -> 1 | T11: =G58 -> 0.992 | U11: =I58 -> 0.97592593 | V11: =K58 -> 0.98367347 | W11: =M58 -> 0.98222222 | X11: =O58 -> 0.98359815
A12: Instructor's knowledge of subject(s) | B12: Boulder Cty | D12: Brighton | F12: CCCS Online | H12: Larimer | J12: FRCC Online | L12: Westminster | N12: Total | Q12: Course availability | R12: =C66 -> 0.83954155 | S12: =E66 -> 0.73333333 | T12: =G66 -> 0.84126984 | U12: =I66 -> 0.80961183 | V12: =K66 -> 0.86585366 | W12: =M66 -> 0.81845238 | X12: =O66 -> 0.82657773
A13: Very good | B13: 225 | C13: =B13/B17 -> 0.63920455 | D13: 10 | E13: =D13/D17 -> 0.66666667 | F13: 66 | G13: =F13/F17 -> 0.528 | H13: 354 | I13: =H13/H17 -> 0.65313653 | J13: 139 | K13: =J13/J17 -> 0.56734694 | L13: 434 | M13: =L13/L17 -> 0.6448737 | N13: =B13+D13+F13+H13+J13+L13 -> 1228 | O13: =N13/N17 -> 0.62909836 | Q13: Overall Evaluation of Instruction | R13: =C74 -> 0.96306818 | S13: =E74 -> 0.86666667 | T13: =G74 -> 0.896 | U13: =I74 -> 0.97966728 | V13: =K74 -> 0.9382716 | W13: =M74 -> 0.97481481 | X13: =O74 -> 0.96360841
A14: Good | B14: 119 | C14: =B14/B17 -> 0.33806818 | D14: 3 | E14: =D14/D17 -> 0.2 | F14: 52 | G14: =F14/F17 -> 0.416 | H14: 180 | I14: =H14/H17 -> 0.33210332 | J14: 100 | K14: =J14/J17 -> 0.40816327 | L14: 227 | M14: =L14/L17 -> 0.33729569 | N14: =B14+D14+F14+H14+J14+L14 -> 681 | O14: =N14/N17 -> 0.34887295
A15: Poor | B15: 7 | C15: =B15/B17 -> 0.019886364 | D15: 1 | E15: =D15/D17 -> 0.066666667 | F15: 5 | G15: =F15/F17 -> 0.04 | H15: 6 | I15: =H15/H17 -> 0.011070111 | J15: 4 | K15: =J15/J17 -> 0.016326531 | L15: 10 | M15: =L15/L17 -> 0.014858841 | N15: =B15+D15+F15+H15+J15+L15 -> 33 | O15: =N15/N17 -> 0.016905738
A16: Very poor | B16: 1 | C16: =B16/B17 -> 0.0028409091 | D16: 1 | E16: =D16/D17 -> 0.066666667 | F16: 2 | G16: =F16/F17 -> 0.016 | H16: 2 | I16: =H16/H17 -> 0.0036900369 | J16: 2 | K16: =J16/J17 -> 0.0081632653 | L16: 2 | M16: =L16/L17 -> 0.0029717682 | N16: =B16+D16+F16+H16+J16+L16 -> 10 | O16: =N16/N17 -> 0.0051229508
A17: Total | B17: =SUM(B13:B16) -> 352 | C17: =SUM(C13:C16) -> 1 | D17: =SUM(D13:D16) -> 15 | E17: =SUM(E13:E16) -> 1 | F17: =SUM(F13:F16) -> 125 | G17: =SUM(G13:G16) -> 1 | H17: =SUM(H13:H16) -> 542 | I17: =SUM(I13:I16) -> 1 | ... M17: =SUM(M13:M16) -> 1 | N17: =SUM(N12:N16) -> 1952 | O17: =SUM(O12:O16) -> 1
A18: Percent of Good or Very Good | C18: =SUM(C13:C14) -> 0.97727273 | E18: =SUM(E13:E14) -> 0.86666667 | G18: =SUM(G13:G14) -> 0.944 | I18: =SUM(I13:I14) -> 0.98523985 | K18: =SUM(K13:K14) -> 0.9755102 | M18: =SUM(M13:M14) -> 0.98216939 | O18: =SUM(O13:O14) -> 0.97797131
A20: Course objectives & requirements made clear | B20: Boulder Cty | D20: Brighton | F20: CCCS Online | H20: Larimer | J20: FRCC Online | L20: Westminster | N20: Total
A21: Very good | B21: 165 | C21: =B21/B25 -> 0.46875 | D21: 8 | E21: =D21/D25 -> 0.53333333 | F21: 52 | G21: =F21/F25 -> 0.416 | H21: 272 | I21: =H21/H25 -> 0.50277264 | J21: 106 | K21: =J21/J25 -> 0.43265306 | L21: 327 | M21: =L21/L25 -> 0.4851632 | N21: =B21+D21+F21+H21+J21+L21 -> 930 | O21: =N21/N25 -> 0.47643443
A22: Good | B22: 170 | C22: =B22/B25 -> 0.48295455 | D22: 7 | E22: =D22/D25 -> 0.46666667 | F22: 53 | G22: =F22/F25 -> 0.424 | H22: 245 | I22: =H22/H25 -> 0.45286506 | J22: 116 | K22: =J22/J25 -> 0.47346939 | L22: 310 | M22: =L22/L25 -> 0.45994065 | N22: =B22+D22+F22+H22+J22+L22 -> 901 | O22: =N22/N25 -> 0.46157787
A23: Poor | B23: 14 | C23: =B23/B25 -> 0.039772727 | E23: =D23/D25 -> 0 | F23: 12 | G23: =F23/F25 -> 0.096 | H23: 21 | I23: =H23/H25 -> 0.038817006 | J23: 20 | K23: =J23/J25 -> 0.081632653 | L23: 32 | M23: =L23/L25 -> 0.047477745 | N23: =B23+D23+F23+H23+J23+L23 -> 99 | O23: =N23/N25 -> 0.050717213
A24: Very poor | B24: 3 | C24: =B24/B25 -> 0.0085227273 | E24: =D24/D25 -> 0 | F24: 8 | G24: =F24/F25 -> 0.064 | H24: 3 | I24: =H24/H25 -> 0.0055452865 | J24: 3 | K24: =J24/J25 -> 0.012244898 | L24: 5 | M24: =L24/L25 -> 0.0074183976 | N24: =B24+D24+F24+H24+J24+L24 -> 22 | O24: =N24/N25 -> 0.011270492
A25: Total | B25: =SUM(B21:B24) -> 352 | C25: =SUM(C21:C24) -> 1 | D25: =SUM(D21:D24) -> 15 | E25: =SUM(E21:E24) -> 1 | F25: =SUM(F21:F24) -> 125 | G25: =SUM(G21:G24) -> 1 | H25: =SUM(H21:H24) -> 541 | I25: =SUM(I21:I24) -> 1 | ... M25: =SUM(M21:M24) -> 1 | N25: =SUM(N19:N24) -> 1952 | O25: =SUM(O19:O24) -> 1
A26: Percent of Good or Very Good | C26: =SUM(C21:C22) -> 0.95170455 | E26: =SUM(E21:E22) -> 1 | G26: =SUM(G21:G22) -> 0.84 | I26: =SUM(I21:I22) -> 0.95563771 | K26: =SUM(K21:K22) -> 0.90612245 | M26: =SUM(M21:M22) -> 0.94510386 | O26: =SUM(O21:O22) -> 0.9380123
A28: Content of course(s) | B28: Boulder Cty | D28: Brighton | F28: CCCS Online | H28: Larimer | J28: FRCC Online | L28: Westminster | N28: Total
A29: Very good | B29: 162 | C29: =B29/B33 -> 0.46153846 | D29: 8 | E29: =D29/D33 -> 0.53333333 | F29: 50 | G29: =F29/F33 -> 0.3968254 | H29: 256 | I29: =H29/H33 -> 0.47407407 | J29: 115 | K29: =J29/J33 -> 0.46938776 | L29: 323 | M29: =L29/L33 -> 0.47922849 | N29: =B29+D29+F29+H29+J29+L29 -> 914 | O29: =N29/N33 -> 0.4684777
A30: Good | B30: 176 | C30: =B30/B33 -> 0.5014245 | D30: 7 | E30: =D30/D33 -> 0.46666667 | F30: 59 | G30: =F30/F33 -> 0.46825397 | H30: 276 | I30: =H30/H33 -> 0.51111111 | J30: 117 | K30: =J30/J33 -> 0.47755102 | L30: 332 | M30: =L30/L33 -> 0.4925816 | N30: =B30+D30+F30+H30+J30+L30 -> 967 | O30: =N30/N33 -> 0.49564326
A31: Poor | B31: 10 | C31: =B31/B33 -> 0.028490028 | E31: =D31/D33 -> 0 | F31: 10 | G31: =F31/F33 -> 0.079365079 | H31: 8 | I31: =H31/H33 -> 0.014814815 | J31: 12 | K31: =J31/J33 -> 0.048979592 | L31: 13 | M31: =L31/L33 -> 0.019287834 | N31: =B31+D31+F31+H31+J31+L31 -> 53 | O31: =N31/N33 -> 0.027165556
A32: Very poor | B32: 3 | C32: =B32/B33 -> 0.0085470085 | E32: =D32/D33 -> 0 | F32: 7 | G32: =F32/F33 -> 0.055555556 | I32: =H32/H33 -> 0 | J32: 1 | K32: =J32/J33 -> 0.0040816327 | L32: 6 | M32: =L32/L33 -> 0.0089020772 | N32: =B32+D32+F32+H32+J32+L32 -> 17 | O32: =N32/N33 -> 0.0087134803
A33: Total | B33: =SUM(B29:B32) -> 351 | C33: =SUM(C29:C32) -> 1 | D33: =SUM(D29:D32) -> 15 | E33: =SUM(E29:E32) -> 1 | F33: =SUM(F29:F32) -> 126 | G33: =SUM(G29:G32) -> 1 | H33: =SUM(H29:H32) -> 540 | I33: =SUM(I29:I32) -> 1 | ... M33: =SUM(M29:M32) -> 1 | N33: =SUM(N27:N32) -> 1951 | O33: =SUM(O27:O32) -> 1
A34: Percent of Good or Very Good | C34: =SUM(C29:C30) -> 0.96296296 | E34: =SUM(E29:E30) -> 1 | G34: =SUM(G29:G30) -> 0.86507937 | I34: =SUM(I29:I30) -> 0.98518519 | K34: =SUM(K29:K30) -> 0.94693878 | M34: =SUM(M29:M30) -> 0.97181009 | O34: =SUM(O29:O30) -> 0.96412096
A36: Instructional methods | B36: Boulder Cty | D36: Brighton | F36: CCCS Online | H36: Larimer | J36: FRCC Online | L36: Westminster | N36: Total
A37: Very good | B37: 144 | C37: =B37/B41 -> 0.41025641 | D37: 7 | E37: =D37/D41 -> 0.46666667 | F37: 38 | G37: =F37/F41 -> 0.304 | H37: 217 | I37: =H37/H41 -> 0.400369 | J37: 87 | K37: =J37/J41 -> 0.35510204 | L37: 271 | M37: =L37/L41 -> 0.40267459 | N37: =B37+D37+F37+H37+J37+L37 -> 764 | O37: =N37/N41 -> 0.39159405
A38: Good | B38: 173 | C38: =B38/B41 -> 0.49287749 | D38: 7 | E38: =D38/D41 -> 0.46666667 | F38: 67 | G38: =F38/F41 -> 0.536 | H38: 289 | I38: =H38/H41 -> 0.53321033 | J38: 133 | K38: =J38/J41 -> 0.54285714 | L38: 358 | M38: =L38/L41 -> 0.53194651 | N38: =B38+D38+F38+H38+J38+L38 -> 1027 | O38: =N38/N41 -> 0.52639672
A39: Poor | B39: 26 | C39: =B39/B41 -> 0.074074074 | E39: =D39/D41 -> 0 | F39: 12 | G39: =F39/F41 -> 0.096 | H39: 34 | I39: =H39/H41 -> 0.062730627 | J39: 20 | K39: =J39/J41 -> 0.081632653 | L39: 34 | M39: =L39/L41 -> 0.050520059 | N39: =B39+D39+F39+H39+J39+L39 -> 126 | O39: =N39/N41 -> 0.064582266
A40: Very poor | B40: 8 | C40: =B40/B41 -> 0.022792023 | D40: 1 | E40: =D40/D41 -> 0.066666667 | F40: 8 | G40: =F40/F41 -> 0.064 | H40: 2 | I40: =H40/H41 -> 0.0036900369 | J40: 5 | K40: =J40/J41 -> 0.020408163 | L40: 10 | M40: =L40/L41 -> 0.014858841 | N40: =B40+D40+F40+H40+J40+L40 -> 34 | O40: =N40/N41 -> 0.017426961
A41: Total | B41: =SUM(B37:B40) -> 351 | C41: =SUM(C37:C40) -> 1 | D41: =SUM(D37:D40) -> 15 | E41: =SUM(E37:E40) -> 1 | F41: =SUM(F37:F40) -> 125 | G41: =SUM(G37:G40) -> 1 | H41: =SUM(H37:H40) -> 542 | I41: =SUM(I37:I40) -> 1 | ... M41: =SUM(M37:M40) -> 1 | N41: =SUM(N35:N40) -> 1951 | O41: =SUM(O35:O40) -> 1
A42: Percent of Good or Very Good | C42: =SUM(C37:C38) -> 0.9031339 | E42: =SUM(E37:E38) -> 0.93333333 | G42: =SUM(G37:G38) -> 0.84 | I42: =SUM(I37:I38) -> 0.93357934 | K42: =SUM(K37:K38) -> 0.89795918 | M42: =SUM(M37:M38) -> 0.9346211 | O42: =SUM(O37:O38) -> 0.91799077
A44: Testing and grading | B44: Boulder Cty | D44: Brighton | F44: CCCS Online | H44: Larimer | J44: FRCC Online | L44: Westminster | N44: Total
...

Sheet Pers Grow
A1: Survey of all Currently enrolled students Fall 2013 -- Evaluate Personal Growth
A2: The only question that fell below 90% satisfaction was Math abilities
A4: Ability to organize ideas | B4: Boulder Cty | D4: Brighton | F4: CCCS Online | H4: Larimer | J4: FRCC Online | L4: Westminster | N4: Total | Q4: EVALUATE FRCC INSTRUCTION | R4: Boulder | S4: Brighton | T4: CCCS Online | U4: Larimer | V4: FRCC Online | W4: West minster | X4: Total
A5: Very satisfied | B5: 86 | C5: =B5/B9 -> 0.33076923 | D5: 7 | E5: =D5/D9 -> 0.58333333 | F5: 31 | G5: =F5/F9 -> 0.33695652 | H5: 141 | I5: =H5/H9 -> 0.32867133 | J5: 63 | K5: =J5/J9 -> 0.34615385 | L5: 180 | M5: =L5/L9 -> 0.34351145 | N5: =B5+D5+F5+H5+J5+L5 -> 508 | O5: =N5/N9 -> 0.3388926 | Q5: =A4 -> Ability to organize ideas | R5: =C10 -> 0.92692308 | S5: =E10 -> 1 | T5: =G10 -> 0.90217391 | U5: =I10 -> 0.96270396 | V5: =K10 -> 0.93406593 | W5: =M10 -> 0.94465649 | X5: =O10 -> 0.94329553
A6: Satisfied | B6: 155 | C6: =B6/B9 -> 0.59615385 | D6: 5 | E6: =D6/D9 -> 0.41666667 | F6: 52 | G6: =F6/F9 -> 0.56521739 | H6: 272 | I6: =H6/H9 -> 0.63403263 | J6: 107 | K6: =J6/J9 -> 0.58791209 | L6: 315 | M6: =L6/L9 -> 0.60114504 | N6: =B6+D6+F6+H6+J6+L6 -> 906 | O6: =N6/N9 -> 0.60440294 | Q6: =A12 -> Ability to think critically | R6: =C18 -> 0.95736434 | S6: =E18 -> 1 | T6: =G18 -> 0.91397849 | U6: =I18 -> 0.95591647 | V6: =K18 -> 0.94652406 | W6: =M18 -> 0.95327103 | X6: =O18 -> 0.95181518
A7: Dissatisfied | B7: 17 | C7: =B7/B9 -> 0.065384615 | E7: =D7/D9 -> 0 | F7: 7 | G7: =F7/F9 -> 0.076086957 | H7: 16 | I7: =H7/H9 -> 0.037296037 | J7: 8 | K7: =J7/J9 -> 0.043956044 | L7: 23 | M7: =L7/L9 -> 0.04389313 | N7: =B7+D7+F7+H7+J7+L7 -> 71 | O7: =N7/N9 -> 0.04736491 | Q7: =A20 -> Ability to write with clarity | R7: =C26 -> 0.95510204 | S7: =E26 -> 0.92307692 | T7: =G26 -> 0.91489362 | U7: =I26 -> 0.95774648 | V7: =K26 -> 0.94148936 | W7: =M26 -> 0.94756554 | X7: =O26 -> 0.94866667
A8: Very dissatisfied | B8: 2 | C8: =B8/B9 -> 0.0076923077 | E8: =D8/D9 -> 0 | F8: 2 | G8: =F8/F9 -> 0.02173913 | I8: =H8/H9 -> 0 | J8: 4 | K8: =J8/J9 -> 0.021978022 | L8: 6 | M8: =L8/L9 -> 0.011450382 | N8: =B8+D8+F8+H8+J8+L8 -> 14 | O8: =N8/N9 -> 0.0093395597 | Q8: =A28 -> Ability to speak with clarity | R8: =C34 -> 0.93625498 | S8: =E34 -> 1 | T8: =G34 -> 0.91011236 | U8: =I34 -> 0.93601896 | V8: =K34 -> 0.93854749 | W8: =M34 -> 0.94817658 | X8: =O34 -> 0.93957909
A9: Total | B9: =SUM(B5:B8) -> 260 | C9: =SUM(C5:C8) -> 1 | D9: =SUM(D5:D8) -> 12 | E9: =SUM(E5:E8) -> 1 | F9: =SUM(F5:F8) -> 92 | G9: =SUM(G5:G8) -> 1 | H9: =SUM(H5:H8) -> 429 | I9: =SUM(I5:I8) -> 1 | ... M9: =SUM(M5:M8) -> 1 | N9: =SUM(N3:N8) -> 1499 | O9: =SUM(O3:O8) -> 1 | Q9: =A36 -> Ability and skills in problem solving | R9: =C42 -> 0.9739777 | S9: =E42 -> 1 | T9: =G42 -> 0.9010989 | U9: =I42 -> 0.96270396 | V9: =K42 -> 0.96825397 | W9: =M42 -> 0.95202952 | X9: =O42 -> 0.95819726
A10: Percent of Satisfied or Very Satisfied | C10: =SUM(C5:C6) -> 0.92692308 | E10: =SUM(E5:E6) -> 1 | G10: =SUM(G5:G6) -> 0.90217391 | I10: =SUM(I5:I6) -> 0.96270396 | K10: =SUM(K5:K6) -> 0.93406593 | M10: =SUM(M5:M6) -> 0.94465649 | O10: =SUM(O5:O6) -> 0.94329553 | Q10: =A44 -> Knowledge of methods & problems in the social sciences | R10: =C50 -> 0.94716981 | S10: =E50 -> 1 | T10: =G50 -> 0.91666667 | U10: =I50 -> 0.94654788 | V10: =K50 -> 0.93085106 | W10: =M50 -> 0.94824399 | X10: =O50 -> 0.94390716
Q11: =A52 -> Knowledge of methods & achievements in science | R11: =C58 -> 0.95035461 | S11: =E58 -> 0.90909091 | T11: =G58 -> 0.90816327 | U11: =I58 -> 0.92765957 | V11: =K58 -> 0.91489362 | W11: =M58 -> 0.93189964 | X11: =O58 -> 0.93030492
A12: Ability to think critically | B12: Boulder Cty | D12: Brighton | F12: CCCS Online | H12: Larimer | J12: FRCC Online | L12: Westminster | N12: Total | Q12: =A60 -> Knowledge & skills in mathematics | R12: =C66 -> 0.92 | S12: =E66 -> 0.90909091 | T12: =G66 -> 0.86666667 | U12: =I66 -> 0.88427948 | V12: =K66 -> 0.89417989 | W12: =M66 -> 0.9047619 | X12: =O66 -> 0.89781931
A13: Very satisfied | B13: 106 | C13: =B13/B17 -> 0.41085271 | D13: 5 | E13: =D13/D17 -> 0.45454545 | F13: 34 | G13: =F13/F17 -> 0.3655914 | H13: 162 | I13: =H13/H17 -> 0.37587007 | J13: 71 | K13: =J13/J17 -> 0.37967914 | L13: 206 | M13: =L13/L17 -> 0.38504673 | N13: =B13+D13+F13+H13+J13+L13 -> 584 | O13: =N13/N17 -> 0.38547855 | Q13: =A68 -> Awareness & appreciation of the arts and humanities | R13: =C74 -> 0.95719844 | S13: =E74 -> 1 | T13: =G74 -> 0.94791667 | U13: =I74 -> 0.94651163 | V13: =K74 -> 0.92391304 | W13: =M74 -> 0.9297597 | X13: =O74 -> 0.94013158
A14: Satisfied | B14: 141 | C14: =B14/B17 -> 0.54651163 | D14: 6 | E14: =D14/D17 -> 0.54545455 | F14: 51 | G14: =F14/F17 -> 0.5483871 | H14: 250 | I14: =H14/H17 -> 0.5800464 | J14: 106 | K14: =J14/J17 -> 0.56684492 | L14: 304 | M14: =L14/L17 -> 0.5682243 | N14: =B14+D14+F14+H14+J14+L14 -> 858 | O14: =N14/N17 -> 0.56633663 | Q14: =A76 -> Awareness & understanding of ethics | R14: =C82 -> 0.9379845 | S14: =E82 -> 1 | T14: =G82 -> 0.91397849 | U14: =I82 -> 0.94536817 | V14: =K82 -> 0.93684211 | W14: =M82 -> 0.94296578 | X14: =O82 -> 0.94066667
A15: Dissatisfied | B15: 9 | C15: =B15/B17 -> 0.034883721 | E15: =D15/D17 -> 0 | F15: 8 | G15: =F15/F17 -> 0.086021505 | H15: 17 | I15: =H15/H17 -> 0.039443155 | J15: 7 | K15: =J15/J17 -> 0.037433155 | L15: 21 | M15: =L15/L17 -> 0.039252336 | N15: =B15+D15+F15+H15+J15+L15 -> 62 | O15: =N15/N17 -> 0.040924092
A16: Very dissatisfied | B16: 2 | C16: =B16/B17 -> 0.007751938 | E16: =D16/D17 -> 0 | G16: =F16/F17 -> 0 | H16: 2 | I16: =H16/H17 -> 0.0046403712 | J16: 3 | K16: =J16/J17 -> 0.016042781 | L16: 4 | M16: =L16/L17 -> 0.0074766355 | N16: =B16+D16+F16+H16+J16+L16 -> 11 | O16: =N16/N17 -> 0.0072607261
A17: Total | B17: =SUM(B13:B16) -> 258 | C17: =SUM(C13:C16) -> 1 | D17: =SUM(D13:D16) -> 11 | E17: =SUM(E13:E16) -> 1 | F17: =SUM(F13:F16) -> 93 | G17: =SUM(G13:G16) -> 1 | H17: =SUM(H13:H16) -> 431 | I17: =SUM(I13:I16) -> 1 | ... M17: =SUM(M13:M16) -> 1 | N17: =SUM(N11:N16) -> 1515 | O17: =SUM(O11:O16) -> 1
A18: Percent of Satisfied or Very Satisfied | C18: =SUM(C13:C14) -> 0.95736434 | E18: =SUM(E13:E14) -> 1 | G18: =SUM(G13:G14) -> 0.91397849 | I18: =SUM(I13:I14) -> 0.95591647 | K18: =SUM(K13:K14) -> 0.94652406 | M18: =SUM(M13:M14) -> 0.95327103 | O18: =SUM(O13:O14) -> 0.95181518
A20: Ability to write with clarity | B20: Boulder Cty | D20: Brighton | F20: CCCS Online | H20: Larimer | J20: FRCC Online | L20: Westminster | N20: Total
A21: Very satisfied | B21: 97 | C21: =B21/B25 -> 0.39591837 | D21: 4 | E21: =D21/D25 -> 0.30769231 | F21: 35 | G21: =F21/F25 -> 0.37234043 | H21: 157 | I21: =H21/H25 -> 0.3685446 | J21: 75 | K21: =J21/J25 -> 0.39893617 | L21: 205 | M21: =L21/L25 -> 0.38389513 | N21: =B21+D21+F21+H21+J21+L21 -> 573 | O21: =N21/N25 -> 0.382
A22: Satisfied | B22: 137 | C22: =B22/B25 -> 0.55918367 | D22: 8 | E22: =D22/D25 -> 0.61538462 | F22: 51 | G22: =F22/F25 -> 0.54255319 | H22: 251 | I22: =H22/H25 -> 0.58920188 | J22: 102 | K22: =J22/J25 -> 0.54255319 | L22: 301 | M22: =L22/L25 -> 0.56367041 | N22: =B22+D22+F22+H22+J22+L22 -> 850 | O22: =N22/N25 -> 0.56666667
A23: Dissatisfied | B23: 9 | C23: =B23/B25 -> 0.036734694 | D23: 1 | E23: =D23/D25 -> 0.076923077 | F23: 8 | G23: =F23/F25 -> 0.085106383 | H23: 17 | I23: =H23/H25 -> 0.039906103 | J23: 8 | K23: =J23/J25 -> 0.042553191 | L23: 23 | M23: =L23/L25 -> 0.043071161 | N23: =B23+D23+F23+H23+J23+L23 -> 66 | O23: =N23/N25 -> 0.044
A24: Very dissatisfied | B24: 2 | C24: =B24/B25 -> 0.0081632653 | E24: =D24/D25 -> 0 | G24: =F24/F25 -> 0 | H24: 1 | I24: =H24/H25 -> 0.0023474178 | J24: 3 | K24: =J24/J25 -> 0.015957447 | L24: 5 | M24: =L24/L25 -> 0.0093632959 | N24: =B24+D24+F24+H24+J24+L24 -> 11 | O24: =N24/N25 -> 0.0073333333
A25: Total | B25: =SUM(B21:B24) -> 245 | C25: =SUM(C21:C24) -> 1 | D25: =SUM(D21:D24) -> 13 | E25: =SUM(E21:E24) -> 1 | F25: =SUM(F21:F24) -> 94 | G25: =SUM(G21:G24) -> 1 | H25: =SUM(H21:H24) -> 426 | I25: =SUM(I21:I24) -> 1 | ... M25: =SUM(M21:M24) -> 1 | N25: =SUM(N19:N24) -> 1500 | O25: =SUM(O19:O24) -> 1
A26: Percent of Satisfied or Very Satisfied | C26: =SUM(C21:C22) -> 0.95510204 | E26: =SUM(E21:E22) -> 0.92307692 | G26: =SUM(G21:G22) -> 0.91489362 | I26: =SUM(I21:I22) -> 0.95774648 | K26: =SUM(K21:K22) -> 0.94148936 | M26: =SUM(M21:M22) -> 0.94756554 | O26: =SUM(O21:O22) -> 0.94866667
A28: Ability to speak with clarity | B28: Boulder Cty | D28: Brighton | F28: CCCS Online | H28: Larimer | J28: FRCC Online | L28: Westminster | N28: Total
A29: Very satisfied | B29: 89 | C29: =B29/B33 -> 0.35458167 | D29: 4 | E29: =D29/D33 -> 0.36363636 | F29: 29 | G29: =F29/F33 -> 0.3258427 | H29: 142 | I29: =H29/H33 -> 0.33649289 | J29: 63 | K29: =J29/J33 -> 0.35195531 | L29: 185 | M29: =L29/L33 -> 0.35508637 | N29: =B29+D29+F29+H29+J29+L29 -> 512 | O29: =N29/N33 -> 0.34758995
A30: Satisfied | B30: 146 | C30: =B30/B33 -> 0.58167331 | D30: 7 | E30: =D30/D33 -> 0.63636364 | F30: 52 | G30: =F30/F33 -> 0.58426966 | H30: 253 | I30: =H30/H33 -> 0.59952607 | J30: 105 | K30: =J30/J33 -> 0.58659218 | L30: 309 | M30: =L30/L33 -> 0.59309021 | N30: =B30+D30+F30+H30+J30+L30 -> 872 | O30: =N30/N33 -> 0.59198914
A31: Dissatisfied | B31: 12 | C31: =B31/B33 -> 0.047808765 | E31: =D31/D33 -> 0 | F31: 7 | G31: =F31/F33 -> 0.078651685 | H31: 26 | I31: =H31/H33 -> 0.061611374 | J31: 8 | K31: =J31/J33 -> 0.044692737 | L31: 22 | M31: =L31/L33 -> 0.042226488 | N31: =B31+D31+F31+H31+J31+L31 -> 75 | O31: =N31/N33 -> 0.050916497
A32: Very dissatisfied | B32: 4 | C32: =B32/B33 -> 0.015936255 | E32: =D32/D33 -> 0 | F32: 1 | G32: =F32/F33 -> 0.011235955 | H32: 1 | I32: =H32/H33 -> 0.0023696682 | J32: 3 | K32: =J32/J33 -> 0.016759777 | L32: 5 | M32: =L32/L33 -> 0.009596929 | N32: =B32+D32+F32+H32+J32+L32 -> 14 | O32: =N32/N33 -> 0.0095044128
