Workbook

Sheet Exhibit A - Total Contract
A1: Section L -Attachment 7 - Price Schedule
A2: DE-SOL-0003816
A3: Total Contract
A4: Amendment 000006
A6: Total Contract
B7: DPLH | E7: Labor | H7: Direct Labor Costs | K7: Fringe Benefits | N7: Fringe Benefit Rate | Q7: Onsite Overhead | T7: Onsite | U7: Total Costs
A8: Cost Element | E8: Straight | F8: Over | G8: Double | H8: Straight | I8: Over | J8: Double | T8: Overhead
B9: Straight | C9: Over | D9: Double | E9: Time | F9: Time | G9: Time | H9: Time | I9: Time | J9: Time | K9: Straight | L9: Over | M9: Double | N9: Straight | O9: Over | P9: Double | Q9: Straight | R9: Over | S9: Double | U9: Straight | V9: Over | W9: Double | X9: Total
B10: Time | C10: Time | D10: Time | E10: Rate | F10: Rate | G10: Rate | H10: Costs | I10: Costs | J10: Costs | K10: Time | L10: Time | M10: Time | N10: Time | O10: Time | P10: Time | Q10: Time | R10: Time | S10: Time | T10: Rate | U10: Time | V10: Time | W10: Time | X10: Costs
A12: Cost Plus Fixed Fee (CPFF) Tasks
A13: **Prime Contractor Labor
A14: Bargaining Employee:
A15: Mechanic | B15: =3630*5 -> 18150 | C15: ='Exhibit A - Transition'!C14+'Exhibit A - Year 1'!C15+'Exhibit A - Year 2'!C15+'Exhibit A - Year 3'!C15+'Exhibit A - Year 4'!C15+'Exhibit A - Year 5'!C15 -> 500 | D15: ='Exhibit A - Transition'!D14+'Exhibit A - Year 1'!D15+'Exhibit A - Year 2'!D15+'Exhibit A - Year 3'!D15+'Exhibit A - Year 4'!D15+'Exhibit A - Year 5'!D15 -> 300 | E15: 0 | F15: 0 | G15: 0 | H15: 0 | I15: 0 | J15: 0 | K15: 0 | L15: 0 | M15: 0 | N15: 0 | O15: 0 | P15: 0 | Q15: 0 | R15: 0 | S15: 0 | T15: 0 | U15: 0 | V15: 0 | W15: 0 | X15: 0
A16: Mobile Crane Inspector | B16: =120*5 -> 600 | C16: ='Exhibit A - Transition'!C15+'Exhibit A - Year 1'!C16+'Exhibit A - Year 2'!C16+'Exhibit A - Year 3'!C16+'Exhibit A - Year 4'!C16+'Exhibit A - Year 5'!C16 -> 0 | D16: ='Exhibit A - Transition'!D15+'Exhibit A - Year 1'!D16+'Exhibit A - Year 2'!D16+'Exhibit A - Year 3'!D16+'Exhibit A - Year 4'!D16+'Exhibit A - Year 5'!D16 -> 0
A17: Laborer | B17: =5625*5 -> 28125 | C17: ='Exhibit A - Transition'!C16+'Exhibit A - Year 1'!C17+'Exhibit A - Year 2'!C17+'Exhibit A - Year 3'!C17+'Exhibit A - Year 4'!C17+'Exhibit A - Year 5'!C17 -> 750 | D17: ='Exhibit A - Transition'!D16+'Exhibit A - Year 1'!D17+'Exhibit A - Year 2'!D17+'Exhibit A - Year 3'!D17+'Exhibit A - Year 4'!D17+'Exhibit A - Year 5'!D17 -> 450
A18: Heavy Equipment Operator | B18: =5625*5 -> 28125 | C18: ='Exhibit A - Transition'!C17+'Exhibit A - Year 1'!C18+'Exhibit A - Year 2'!C18+'Exhibit A - Year 3'!C18+'Exhibit A - Year 4'!C18+'Exhibit A - Year 5'!C18 -> 750 | D18: ='Exhibit A - Transition'!D17+'Exhibit A - Year 1'!D18+'Exhibit A - Year 2'!D18+'Exhibit A - Year 3'!D18+'Exhibit A - Year 4'!D18+'Exhibit A - Year 5'!D18 -> 450
A19: Truck Driver | B19: =5625*5 -> 28125 | C19: ='Exhibit A - Transition'!C18+'Exhibit A - Year 1'!C19+'Exhibit A - Year 2'!C19+'Exhibit A - Year 3'!C19+'Exhibit A - Year 4'!C19+'Exhibit A - Year 5'!C19 -> 750 | D19: ='Exhibit A - Transition'!D18+'Exhibit A - Year 1'!D19+'Exhibit A - Year 2'!D19+'Exhibit A - Year 3'!D19+'Exhibit A - Year 4'!D19+'Exhibit A - Year 5'!D19 -> 450
A20: (Itemize each additional position) | C20: ='Exhibit A - Transition'!C19+'Exhibit A - Year 1'!C20+'Exhibit A - Year 2'!C20+'Exhibit A - Year 3'!C20+'Exhibit A - Year 4'!C20+'Exhibit A - Year 5'!C20 -> 0 | D20: ='Exhibit A - Transition'!D19+'Exhibit A - Year 1'!D20+'Exhibit A - Year 2'!D20+'Exhibit A - Year 3'!D20+'Exhibit A - Year 4'!D20+'Exhibit A - Year 5'!D20 -> 0
C21: ='Exhibit A - Transition'!C20+'Exhibit A - Year 1'!C21+'Exhibit A - Year 2'!C21+'Exhibit A - Year 3'!C21+'Exhibit A - Year 4'!C21+'Exhibit A - Year 5'!C21 -> 0 | D21: ='Exhibit A - Transition'!D20+'Exhibit A - Year 1'!D21+'Exhibit A - Year 2'!D21+'Exhibit A - Year 3'!D21+'Exhibit A - Year 4'!D21+'Exhibit A - Year 5'!D21 -> 0
A22: Non-Bargaining Employees: | C22: ='Exhibit A - Transition'!C21+'Exhibit A - Year 1'!C22+'Exhibit A - Year 2'!C22+'Exhibit A - Year 3'!C22+'Exhibit A - Year 4'!C22+'Exhibit A - Year 5'!C22 -> 0 | D22: ='Exhibit A - Transition'!D21+'Exhibit A - Year 1'!D22+'Exhibit A - Year 2'!D22+'Exhibit A - Year 3'!D22+'Exhibit A - Year 4'!D22+'Exhibit A - Year 5'!D22 -> 0
A23: Program Manager | B23: =1775*5 -> 8875 | C23: ='Exhibit A - Transition'!C22+'Exhibit A - Year 1'!C23+'Exhibit A - Year 2'!C23+'Exhibit A - Year 3'!C23+'Exhibit A - Year 4'!C23+'Exhibit A - Year 5'!C23 -> 0 | D23: ='Exhibit A - Transition'!D22+'Exhibit A - Year 1'!D23+'Exhibit A - Year 2'!D23+'Exhibit A - Year 3'!D23+'Exhibit A - Year 4'!D23+'Exhibit A - Year 5'!D23 -> 0
A24: Operations & Maintenance Manager | B24: 8875 | C24: ='Exhibit A - Transition'!C23+'Exhibit A - Year 1'!C24+'Exhibit A - Year 2'!C24+'Exhibit A - Year 3'!C24+'Exhibit A - Year 4'!C24+'Exhibit A - Year 5'!C24 -> 0 | D24: ='Exhibit A - Transition'!D23+'Exhibit A - Year 1'!D24+'Exhibit A - Year 2'!D24+'Exhibit A - Year 3'!D24+'Exhibit A - Year 4'!D24+'Exhibit A - Year 5'!D24 -> 0
A25: Administrative Assistant | B25: 8875 | C25: ='Exhibit A - Transition'!C24+'Exhibit A - Year 1'!C25+'Exhibit A - Year 2'!C25+'Exhibit A - Year 3'!C25+'Exhibit A - Year 4'!C25+'Exhibit A - Year 5'!C25 -> 0 | D25: ='Exhibit A - Transition'!D24+'Exhibit A - Year 1'!D25+'Exhibit A - Year 2'!D25+'Exhibit A - Year 3'!D25+'Exhibit A - Year 4'!D25+'Exhibit A - Year 5'!D25 -> 0
A26: Shop Manager | B26: 8875 | C26: ='Exhibit A - Transition'!C25+'Exhibit A - Year 1'!C26+'Exhibit A - Year 2'!C26+'Exhibit A - Year 3'!C26+'Exhibit A - Year 4'!C26+'Exhibit A - Year 5'!C26 -> 0 | D26: ='Exhibit A - Transition'!D25+'Exhibit A - Year 1'!D26+'Exhibit A - Year 2'!D26+'Exhibit A - Year 3'!D26+'Exhibit A - Year 4'!D26+'Exhibit A - Year 5'!D26 -> 0
A27: Supply Technician | B27: 9375 | C27: ='Exhibit A - Transition'!C26+'Exhibit A - Year 1'!C27+'Exhibit A - Year 2'!C27+'Exhibit A - Year 3'!C27+'Exhibit A - Year 4'!C27+'Exhibit A - Year 5'!C27 -> 100 | D27: ='Exhibit A - Transition'!D26+'Exhibit A - Year 1'!D27+'Exhibit A - Year 2'!D27+'Exhibit A - Year 3'!D27+'Exhibit A - Year 4'!D27+'Exhibit A - Year 5'!D27 -> 0
A28: Construction Technician | B28: 0 | C28: ='Exhibit A - Transition'!C27+'Exhibit A - Year 1'!C28+'Exhibit A - Year 2'!C28+'Exhibit A - Year 3'!C28+'Exhibit A - Year 4'!C28+'Exhibit A - Year 5'!C28 -> 0 | D28: ='Exhibit A - Transition'!D27+'Exhibit A - Year 1'!D28+'Exhibit A - Year 2'!D28+'Exhibit A - Year 3'!D28+'Exhibit A - Year 4'!D28+'Exhibit A - Year 5'!D28 -> 0
A29: (Itemize each additional position)
A32: Subtotal (Provide Subtotals for Each) | B32: 148100 | C32: =SUM(C15:C31) -> 2850 | D32: =SUM(D15:D31) -> 1650 | H32: 0 | I32: 0 | J32: 0 | K32: 0 | L32: 0 | M32: 0 | N32: 0 | O32: 0 | P32: 0 | Q32: 0 | R32: 0 | S32: 0 | T32: 0 | U32: 0 | V32: 0 | W32: 0 | X32: 0
A33: Subcontractor Labor (If Applicable)
A34: (Itemize for Each Position)
A38: Subtotal (Provide Subtotals for Each) | B38: 0 | H38: 0 | I38: 0 | J38: 0 | K38: 0 | L38: 0 | M38: 0 | N38: 0 | Q38: 0 | R38: 0 | S38: 0 | T38: 0 | U38: 0 | V38: 0 | W38: 0 | X38: 0
A39: Subtotal CPFF Labor Related Costs | B39: 0 | H39: 0 | I39: 0 | J39: 0 | K39: 0 | L39: 0 | M39: 0 | Q39: 0 | R39: 0 | S39: 0 | X39: 0
A40: Other Direct Costs:
A41: Material | X41: =500000*5 -> 2500000
A42: Construction | X42: =500000*5 -> 2500000
A43: Subtotal CPFF Costs | B43: 0 | H43: 0 | I43: 0 | J43: 0 | K43: 0 | L43: 0 | M43: 0 | Q43: 0 | R43: 0 | S43: 0 | X43: 0
A44: G&A (Identify G&A Rate)
A45: Total CPFF Proposed Costs
A46: Reserve Fee
A47: Total Proposed CPFF Fee
...

Sheet Exhibit A - Transition
A1: Section L - Attachment 7 - Price Schedule
A2: DE-SOL-0003816
A3: Transition (up to 30-days), To be determined
A4: Amendment 000006
A6: Total Contract
B7: DPLH | E7: Labor | H7: Direct Labor Costs | K7: Fringe Benefits | N7: Fringe Benefit Rate | Q7: Onsite Overhead | T7: Onsite | U7: Total Costs
A8: Cost Element | E8: Straight | F8: Over | G8: Double | H8: Straight | I8: Over | J8: Double | T8: Overhead
B9: Straight | C9: Over | D9: Double | E9: Time | F9: Time | G9: Time | H9: Time | I9: Time | J9: Time | K9: Straight | L9: Over | M9: Double | N9: Straight | O9: Over | P9: Double | Q9: Straight | R9: Over | S9: Double | U9: Straight | V9: Over | W9: Double | X9: Total
A11: Cost Plus Fixed Fee (CPFF) Tasks
A12: ***Prime Contractor Labor
A13: Bargaining Employee:
A23: Non-Bargaining Employees:
A33: Subtotal (Provide Subtotals for Each) | H33: 0 | I33: 0 | J33: 0 | K33: 0 | L33: 0 | M33: 0 | N33: 0 | O33: 0 | P33: 0 | Q33: 0 | R33: 0 | S33: 0 | T33: 0 | U33: 0 | V33: 0 | W33: 0 | X33: 0
A34: Subcontractor Labor (If Applicable)
A35: (Itemize for Each Position)
A39: Subtotal (Provide Subtotals for Each) | B39: 0 | H39: 0 | I39: 0 | J39: 0 | K39: 0 | L39: 0 | M39: 0 | N39: 0 | Q39: 0 | R39: 0 | S39: 0 | T39: 0 | U39: 0 | V39: 0 | W39: 0 | X39: 0
A40: Subtotal Labor Related Costs | B40: 0 | H40: 0 | I40: 0 | J40: 0 | K40: 0 | L40: 0 | M40: 0 | Q40: 0 | R40: 0 | S40: 0 | X40: 0
A41: Other Direct Costs:
A42: Material | Z42: =+'Exhibit A - Year 1'!X34+'Exhibit A - Year 2'!I32+'Exhibit A - Year 3'!I32+'Exhibit A - Year 4'!I32+'Exhibit A - Year 5'!I33 -> 0
A43: Construction | Z43: =+'Exhibit A - Year 1'!X35+'Exhibit A - Year 2'!I33+'Exhibit A - Year 3'!I33+'Exhibit A - Year 4'!I33+'Exhibit A - Year 5'!I34 -> 0
A44: Subtotal Costs | B44: 0 | H44: 0 | I44: 0 | J44: 0 | K44: 0 | L44: 0 | M44: 0 | Q44: 0 | R44: 0 | S44: 0 | X44: 0
A45: G&A (Identify G&A Rate)
A46: Total Proposed Costs
A49: Total Proposal | B49: 0 | H49: 0 | I49: 0 | J49: 0 | K49: 0 | L49: 0 | M49: 0 | Q49: 0 | R49: 0 | S49: 0 | X49: 0
A52: No fee applicable in the transition phase

Sheet Exhibit A - Year 1
A1: Section L - Attachment 7 - Price Schedule
A2: DE-SOL-0003816
A3: Base Year (February 1, 2013 - January 31, 2014)
A4: Amendment 000006
A6: Total Contract
B7: DPLH | E7: Labor | H7: Direct Labor Costs | K7: Fringe Benefits | N7: Fringe Benefit Rate | Q7: Onsite Overhead | T7: Onsite | U7: Total Costs
A8: Cost Element | E8: Straight | F8: Over | G8: Double | H8: Straight | I8: Over | J8: Double | T8: Overhead
B9: Straight | C9: Over | D9: Double | E9: Time | F9: Time | G9: Time | H9: Time | I9: Time | J9: Time | K9: Straight | L9: Over | M9: Double | N9: Straight | O9: Over | P9: Double | Q9: Straight | R9: Over | S9: Double | U9: Straight | V9: Over | W9: Double | X9: Total
B10: Time | C10: Time | D10: Time | E10: Rate | F10: Rate | G10: Rate | H10: Costs | I10: Costs | J10: Costs | K10: Time | L10: Time | M10: Time | N10: Time | O10: Time | P10: Time | Q10: Time | R10: Time | S10: Time | T10: Rate | U10: Time | V10: Time | W10: Time | X10: Costs
A12: Cost Plus Fixed Fee (CPFF) Tasks
A13: **Prime Contractor Labor
A14: Bargaining Employee:
A15: Mechanic | B15: 3630 | C15: 100 | D15: 60 | E15: 0 | F15: 0 | G15: 0 | H15: 0 | I15: 0 | J15: 0 | K15: 0 | L15: 0 | M15: 0 | N15: 0 | O15: 0 | P15: 0 | Q15: 0 | R15: 0 | S15: 0 | T15: 0 | U15: 0 | V15: 0 | W15: 0 | X15: 0
A16: Mobile Crane Inspector | B16: 120
A17: Laborer | B17: 5625 | C17: 150 | D17: 90
A18: Heavy Equipment Operator | B18: 5625 | C18: 150 | D18: 90
A19: Truck Driver | B19: 5625 | C19: 150 | D19: 90
A20: (Itemize each additional position)
A22: Non-Bargaining Employees:
A23: Program Manager | B23: 1775 | C23: 0
A24: Operations & Maintenance Manager | B24: 1775 | C24: 0
A25: Administrative Assistant | B25: 1775
A26: Shop Manager | B26: 1775 | C26: 0
A27: Supply Technician | B27: 1875 | C27: 20
A28: Construction Technician
A29: (Itemize each additional position)
A32: Subtotal (Provide Subtotals for Each) | B32: =SUM(B15:B31) -> 29600 | C32: =SUM(C15:C31) -> 570 | D32: =SUM(D15:D31) -> 330 | H32: 0 | I32: 0 | J32: 0 | K32: 0 | L32: 0 | M32: 0 | N32: 0 | O32: 0 | P32: 0 | Q32: 0 | R32: 0 | S32: 0 | T32: 0 | U32: 0 | V32: 0 | W32: 0 | X32: 0
A33: Subcontractor Labor (If Applicable)
A34: (Itemize for Each Position)
A38: Subtotal (Provide Subtotals for Each) | B38: 0 | H38: 0 | I38: 0 | J38: 0 | K38: 0 | L38: 0 | M38: 0 | N38: 0 | Q38: 0 | R38: 0 | S38: 0 | T38: 0 | U38: 0 | V38: 0 | W38: 0 | X38: 0
A39: Subtotal CPFF Labor Related Costs | B39: 0 | H39: 0 | I39: 0 | J39: 0 | K39: 0 | L39: 0 | M39: 0 | Q39: 0 | R39: 0 | S39: 0 | X39: 0
A40: Other Direct Costs:
A41: Material | X41: 500000 | Z41: =+'Exhibit A - Year 1'!X34+'Exhibit A - Year 2'!I32+'Exhibit A - Year 3'!I32+'Exhibit A - Year 4'!I32+'Exhibit A - Year 5'!I33 -> 0
A42: Construction | X42: 500000 | Z42: =+'Exhibit A - Year 1'!X35+'Exhibit A - Year 2'!I33+'Exhibit A - Year 3'!I33+'Exhibit A - Year 4'!I33+'Exhibit A - Year 5'!I34 -> 0
A43: Subtotal CPFF Costs | B43: 0 | H43: 0 | I43: 0 | J43: 0 | K43: 0 | L43: 0 | M43: 0 | Q43: 0 | R43: 0 | S43: 0 | X43: 0
A44: G&A (Identify G&A Rate)
A45: Total CPFF Proposed Costs
A46: Rerserve Fee
A47: Total Proposed CPFF Fee
A48: Total CPFF Proposal | B48: 0 | H48: 0 | I48: 0 | J48: 0 | K48: 0 | L48: 0 | M48: 0 | Q48: 0 | R48: 0 | S48: 0 | X48: 0
...

Sheet Exhibit A - Year 2
A1: Section L - Attachment 7 - Price Schedule
A2: DE-SOL-0003816
A3: Option Year 1 (February 1, 2014 - January 31, 2015)
A4: Amendment 000006
A6: Total Contract
B7: DPLH | E7: Labor | H7: Direct Labor Costs | K7: Fringe Benefits | N7: Fringe Benefit Rate | Q7: Onsite Overhead | T7: Onsite | U7: Total Costs
A8: Cost Element | E8: Straight | F8: Over | G8: Double | H8: Straight | I8: Over | J8: Double | T8: Overhead
B9: Straight | C9: Over | D9: Double | E9: Time | F9: Time | G9: Time | H9: Time | I9: Time | J9: Time | K9: Straight | L9: Over | M9: Double | N9: Straight | O9: Over | P9: Double | Q9: Straight | R9: Over | S9: Double | U9: Straight | V9: Over | W9: Double | X9: Total
B10: Time | C10: Time | D10: Time | E10: Rate | F10: Rate | G10: Rate | H10: Costs | I10: Costs | J10: Costs | K10: Time | L10: Time | M10: Time | N10: Time | O10: Time | P10: Time | Q10: Time | R10: Time | S10: Time | T10: Rate | U10: Time | V10: Time | W10: Time | X10: Costs
A12: Cost Plus Fixed Fee (CPFF) Tasks
A13: **Prime Contractor Labor
A14: Bargaining Employee:
A15: Mechanic | B15: 3630 | C15: 100 | D15: 60 | E15: 0 | F15: 0 | G15: 0 | H15: 0 | I15: 0 | J15: 0 | K15: 0 | L15: 0 | M15: 0 | N15: 0 | O15: 0 | P15: 0 | Q15: 0 | R15: 0 | S15: 0 | T15: 0 | U15: 0 | V15: 0 | W15: 0 | X15: 0
A16: Mobile Crane Inspector | B16: 120
A17: Laborer | B17: 5625 | C17: 150 | D17: 90
A18: Heavy Equipment Operator | B18: 5625 | C18: 150 | D18: 90
A19: Truck Driver | B19: 5625 | C19: 150 | D19: 90
A20: (Itemize each additional position)
A22: Non-Bargaining Employees:
A23: Program Manager | B23: 1775 | C23: 0
A24: Operations & Maintenance Manager | B24: 1775 | C24: 0
A25: Administrative Assistant | B25: 1775
A26: Shop Manager | B26: 1775 | C26: 0
A27: Supply Technician | B27: 1875 | C27: 20
A28: Construction Technician | B28: 0 | C28: 0 | D28: 0
A29: (Itemize each additional position)
A32: Subtotal (Provide Subtotals for Each) | B32: =SUM(B15:B31) -> 29600 | C32: =SUM(C15:C31) -> 570 | D32: =SUM(D15:D31) -> 330 | H32: 0 | I32: 0 | J32: 0 | K32: 0 | L32: 0 | M32: 0 | N32: 0 | O32: 0 | P32: 0 | Q32: 0 | R32: 0 | S32: 0 | T32: 0 | U32: 0 | V32: 0 | W32: 0 | X32: 0
A33: Subcontractor Labor (If Applicable)
A34: (Itemize for Each Position)
A38: Subtotal (Provide Subtotals for Each) | B38: 0 | H38: 0 | I38: 0 | J38: 0 | K38: 0 | L38: 0 | M38: 0 | N38: 0 | Q38: 0 | R38: 0 | S38: 0 | T38: 0 | U38: 0 | V38: 0 | W38: 0 | X38: 0
A39: Subtotal CPFF Labor Related Costs | B39: 0 | H39: 0 | I39: 0 | J39: 0 | K39: 0 | L39: 0 | M39: 0 | Q39: 0 | R39: 0 | S39: 0 | X39: 0
A40: Other Direct Costs:
A41: Material | X41: 500000 | Z41: =+'Exhibit A - Year 1'!X34+'Exhibit A - Year 2'!I32+'Exhibit A - Year 3'!I32+'Exhibit A - Year 4'!I32+'Exhibit A - Year 5'!I33 -> 0
A42: Construction | X42: 500000 | Z42: =+'Exhibit A - Year 1'!X35+'Exhibit A - Year 2'!I33+'Exhibit A - Year 3'!I33+'Exhibit A - Year 4'!I33+'Exhibit A - Year 5'!I34 -> 0
A43: Subtotal CPFF Costs | B43: 0 | H43: 0 | I43: 0 | J43: 0 | K43: 0 | L43: 0 | M43: 0 | Q43: 0 | R43: 0 | S43: 0 | X43: 0
A44: G&A (Identify G&A Rate)
A45: Total CPFF Proposed Costs
A46: Reserve Fee
A47: Total Proposed CPFF Fee
A48: Total CPFF Proposal | B48: 0 | H48: 0 | I48: 0 | J48: 0 | K48: 0 | L48: 0 | M48: 0 | Q48: 0 | R48: 0 | S48: 0 | X48: 0
...

Sheet Exhibit A - Year 3
A1: Section L - Attachment 7 - Price Schedule
A2: DE-SOL-0003816
A3: Option Year 2 (February 1, 2015 - January 31, 2016)
A4: Amendment 000006
A6: Total Contract
B7: DPLH | E7: Labor | H7: Direct Labor Costs | K7: Fringe Benefits | N7: Fringe Benefit Rate | Q7: Onsite Overhead | T7: Onsite | U7: Total Costs
A8: Cost Element | E8: Straight | F8: Over | G8: Double | H8: Straight | I8: Over | J8: Double | T8: Overhead
B9: Straight | C9: Over | D9: Double | E9: Time | F9: Time | G9: Time | H9: Time | I9: Time | J9: Time | K9: Straight | L9: Over | M9: Double | N9: Straight | O9: Over | P9: Double | Q9: Straight | R9: Over | S9: Double | U9: Straight | V9: Over | W9: Double | X9: Total
B10: Time | C10: Time | D10: Time | E10: Rate | F10: Rate | G10: Rate | H10: Costs | I10: Costs | J10: Costs | K10: Time | L10: Time | M10: Time | N10: Time | O10: Time | P10: Time | Q10: Time | R10: Time | S10: Time | T10: Rate | U10: Time | V10: Time | W10: Time | X10: Costs
A12: Cost Plus Fixed Fee (CPFF) Tasks
A13: **Prime Contractor Labor
A14: Bargaining Employee:
A15: Mechanic | B15: 3630 | C15: 100 | D15: 60 | E15: 0 | F15: 0 | G15: 0 | H15: 0 | I15: 0 | J15: 0 | K15: 0 | L15: 0 | M15: 0 | N15: 0 | O15: 0 | P15: 0 | Q15: 0 | R15: 0 | S15: 0 | T15: 0 | U15: 0 | V15: 0 | W15: 0 | X15: 0
A16: Mobile Crane Inspector | B16: 120
A17: Laborer | B17: 5625 | C17: 150 | D17: 90
A18: Heavy Equipment Operator | B18: 5625 | C18: 150 | D18: 90
A19: Truck Driver | B19: 5625 | C19: 150 | D19: 90
A20: (Itemize each additional position)
A22: Non-Bargaining Employees:
A23: Program Manager | B23: 1775 | C23: 0
A24: Operations & Maintenance Manager | B24: 1775 | C24: 0
A25: Administrative Assistant | B25: 1775
A26: Shop Manager | B26: 1775 | C26: 0
A27: Supply Technician | B27: 1875 | C27: 20
A28: Construction Technician | B28: 0 | C28: 0 | D28: 0
A29: (Itemize each additional position)
A32: Subtotal (Provide Subtotals for Each) | B32: =SUM(B15:B31) -> 29600 | C32: =SUM(C15:C31) -> 570 | D32: =SUM(D15:D31) -> 330 | H32: 0 | I32: 0 | J32: 0 | K32: 0 | L32: 0 | M32: 0 | N32: 0 | O32: 0 | P32: 0 | Q32: 0 | R32: 0 | S32: 0 | T32: 0 | U32: 0 | V32: 0 | W32: 0 | X32: 0
A33: Subcontractor Labor (If Applicable)
A34: (Itemize for Each Position)
A38: Subtotal (Provide Subtotals for Each) | B38: 0 | H38: 0 | I38: 0 | J38: 0 | K38: 0 | L38: 0 | M38: 0 | N38: 0 | Q38: 0 | R38: 0 | S38: 0 | T38: 0 | U38: 0 | V38: 0 | W38: 0 | X38: 0
A39: Subtotal CPFF Labor Related Costs | B39: 0 | H39: 0 | I39: 0 | J39: 0 | K39: 0 | L39: 0 | M39: 0 | Q39: 0 | R39: 0 | S39: 0 | X39: 0
A40: Other Direct Costs:
A41: Material | X41: 500000 | Z41: =+'Exhibit A - Year 1'!X34+'Exhibit A - Year 2'!I32+'Exhibit A - Year 3'!I32+'Exhibit A - Year 4'!I32+'Exhibit A - Year 5'!I33 -> 0
A42: Construction | X42: 500000 | Z42: =+'Exhibit A - Year 1'!X35+'Exhibit A - Year 2'!I33+'Exhibit A - Year 3'!I33+'Exhibit A - Year 4'!I33+'Exhibit A - Year 5'!I34 -> 0
A43: Subtotal CPFF Costs | B43: 0 | H43: 0 | I43: 0 | J43: 0 | K43: 0 | L43: 0 | M43: 0 | Q43: 0 | R43: 0 | S43: 0 | X43: 0
A44: G&A (Identify G&A Rate)
A45: Total CPFF Proposed Costs
A46: Reserve Fee
A47: Total Proposed CPFF Fee
A48: Total CPFF Proposal | B48: 0 | H48: 0 | I48: 0 | J48: 0 | K48: 0 | L48: 0 | M48: 0 | Q48: 0 | R48: 0 | S48: 0 | X48: 0
...

Sheet Exhibit A - Year 4
A1: Section L - Attachment 7 - Price Schedule
A2: DE-SOL-0003816
A3: Option Year 3 (February 1, 2016 - January 31, 2017)
A4: Amendment 000006
A6: Total Contract
B7: DPLH | E7: Labor | H7: Direct Labor Costs | K7: Fringe Benefits | N7: Fringe Benefit Rate | Q7: Onsite Overhead | T7: Onsite | U7: Total Costs
A8: Cost Element | E8: Straight | F8: Over | G8: Double | H8: Straight | I8: Over | J8: Double | T8: Overhead
B9: Straight | C9: Over | D9: Double | E9: Time | F9: Time | G9: Time | H9: Time | I9: Time | J9: Time | K9: Straight | L9: Over | M9: Double | N9: Straight | O9: Over | P9: Double | Q9: Straight | R9: Over | S9: Double | U9: Straight | V9: Over | W9: Double | X9: Total
B10: Time | C10: Time | D10: Time | E10: Rate | F10: Rate | G10: Rate | H10: Costs | I10: Costs | J10: Costs | K10: Time | L10: Time | M10: Time | N10: Time | O10: Time | P10: Time | Q10: Time | R10: Time | S10: Time | T10: Rate | U10: Time | V10: Time | W10: Time | X10: Costs
A12: Cost Plus Fixed Fee (CPFF) Tasks
A13: **Prime Contractor Labor
A14: Bargaining Employee:
A15: Mechanic | B15: 3630 | C15: 100 | D15: 60 | E15: 0 | F15: 0 | G15: 0 | H15: 0 | I15: 0 | J15: 0 | K15: 0 | L15: 0 | M15: 0 | N15: 0 | O15: 0 | P15: 0 | Q15: 0 | R15: 0 | S15: 0 | T15: 0 | U15: 0 | V15: 0 | W15: 0 | X15: 0
A16: Mobile Crane Inspector | B16: 120
A17: Laborer | B17: 5625 | C17: 150 | D17: 90
A18: Heavy Equipment Operator | B18: 5625 | C18: 150 | D18: 90
A19: Truck Driver | B19: 5625 | C19: 150 | D19: 90
A20: (Itemize each additional position)
A22: Non-Bargaining Employees:
A23: Program Manager | B23: 1775 | C23: 0
A24: Operations & Maintenance Manager | B24: 1775 | C24: 0
A25: Administrative Assistant | B25: 1775
A26: Shop Manager | B26: 1775 | C26: 0
A27: Supply Technician | B27: 1875 | C27: 20
A28: Construction Technician
A29: (Itemize each additional position)
A32: Subtotal (Provide Subtotals for Each) | B32: =SUM(B15:B31) -> 29600 | C32: =SUM(C15:C31) -> 570 | D32: =SUM(D15:D31) -> 330 | H32: 0 | I32: 0 | J32: 0 | K32: 0 | L32: 0 | M32: 0 | N32: 0 | O32: 0 | P32: 0 | Q32: 0 | R32: 0 | S32: 0 | T32: 0 | U32: 0 | V32: 0 | W32: 0 | X32: 0
A33: Subcontractor Labor (If Applicable)
A34: (Itemize for Each Position)
A38: Subtotal (Provide Subtotals for Each) | B38: 0 | H38: 0 | I38: 0 | J38: 0 | K38: 0 | L38: 0 | M38: 0 | N38: 0 | Q38: 0 | R38: 0 | S38: 0 | T38: 0 | U38: 0 | V38: 0 | W38: 0 | X38: 0
A39: Subtotal CPFF Labor Related Costs | B39: 0 | H39: 0 | I39: 0 | J39: 0 | K39: 0 | L39: 0 | M39: 0 | Q39: 0 | R39: 0 | S39: 0 | X39: 0
A40: Other Direct Costs:
A41: Material | X41: 500000 | Z41: =+'Exhibit A - Year 1'!X34+'Exhibit A - Year 2'!I32+'Exhibit A - Year 3'!I32+'Exhibit A - Year 4'!I32+'Exhibit A - Year 5'!I33 -> 0
A42: Construction | X42: 500000 | Z42: =+'Exhibit A - Year 1'!X35+'Exhibit A - Year 2'!I33+'Exhibit A - Year 3'!I33+'Exhibit A - Year 4'!I33+'Exhibit A - Year 5'!I34 -> 0
A43: Subtotal CPFF Costs | B43: 0 | H43: 0 | I43: 0 | J43: 0 | K43: 0 | L43: 0 | M43: 0 | Q43: 0 | R43: 0 | S43: 0 | X43: 0
A44: G&A (Identify G&A Rate)
A45: Total CPFF Proposed Costs
A46: Reserve Fee
A47: Total Proposed CPFF Fee
A48: Total CPFF Proposal | B48: 0 | H48: 0 | I48: 0 | J48: 0 | K48: 0 | L48: 0 | M48: 0 | Q48: 0 | R48: 0 | S48: 0 | X48: 0
...

Sheet Exhibit A - Year 5
A1: Section L - Attachment 7 - Price Schedule
A2: DE-SOL-0003816
A3: Option Year 4 (February 1, 2017 - January 31, 2018)
A4: Amendment 000006
A6: Total Contract
B7: DPLH | E7: Labor | H7: Direct Labor Costs | K7: Fringe Benefits | N7: Fringe Benefit Rate | Q7: Onsite Overhead | T7: Onsite | U7: Total Costs
A8: Cost Element | E8: Straight | F8: Over | G8: Double | H8: Straight | I8: Over | J8: Double | T8: Overhead
B9: Straight | C9: Over | D9: Double | E9: Time | F9: Time | G9: Time | H9: Time | I9: Time | J9: Time | K9: Straight | L9: Over | M9: Double | N9: Straight | O9: Over | P9: Double | Q9: Straight | R9: Over | S9: Double | U9: Straight | V9: Over | W9: Double | X9: Total
B10: Time | C10: Time | D10: Time | E10: Rate | F10: Rate | G10: Rate | H10: Costs | I10: Costs | J10: Costs | K10: Time | L10: Time | M10: Time | N10: Time | O10: Time | P10: Time | Q10: Time | R10: Time | S10: Time | T10: Rate | U10: Time | V10: Time | W10: Time | X10: Costs
A12: Cost Plus Fixed Fee (CPFF) Tasks
A13: **Prime Contractor Labor
A14: Bargaining Employee:
A15: Mechanic | B15: 3630 | C15: 100 | D15: 60 | E15: 0 | F15: 0 | G15: 0 | H15: 0 | I15: 0 | J15: 0 | K15: 0 | L15: 0 | M15: 0 | N15: 0 | O15: 0 | P15: 0 | Q15: 0 | R15: 0 | S15: 0 | T15: 0 | U15: 0 | V15: 0 | W15: 0 | X15: 0
A16: Mobile Crane Inspector | B16: 120
A17: Laborer | B17: 5625 | C17: 150 | D17: 90
A18: Heavy Equipment Operator | B18: 5625 | C18: 150 | D18: 90
A19: Truck Driver | B19: 5625 | C19: 150 | D19: 90
A20: (Itemize each additional position)
A22: Non-Bargaining Employees:
A23: Program Manager | B23: 1775 | C23: 0
A24: Operations & Maintenance Manager | B24: 1775 | C24: 0
A25: Administrative Assistant | B25: 1775
A26: Shop Manager | B26: 1775 | C26: 0
A27: Supply Technician | B27: 1875 | C27: 20
A28: Construction Technician
A29: (Itemize each additional position)
A32: Subtotal (Provide Subtotals for Each) | B32: =SUM(B15:B31) -> 29600 | C32: =SUM(C15:C31) -> 570 | D32: =SUM(D15:D31) -> 330 | H32: 0 | I32: 0 | J32: 0 | K32: 0 | L32: 0 | M32: 0 | N32: 0 | O32: 0 | P32: 0 | Q32: 0 | R32: 0 | S32: 0 | T32: 0 | U32: 0 | V32: 0 | W32: 0 | X32: 0
A33: Subcontractor Labor (If Applicable)
A34: (Itemize for Each Position)
A38: Subtotal (Provide Subtotals for Each) | B38: 0 | H38: 0 | I38: 0 | J38: 0 | K38: 0 | L38: 0 | M38: 0 | N38: 0 | Q38: 0 | R38: 0 | S38: 0 | T38: 0 | U38: 0 | V38: 0 | W38: 0 | X38: 0
A39: Subtotal CPFF Labor Related Costs | B39: 0 | H39: 0 | I39: 0 | J39: 0 | K39: 0 | L39: 0 | M39: 0 | Q39: 0 | R39: 0 | S39: 0 | X39: 0
A40: Other Direct Costs:
A41: Material | X41: 500000 | Z41: =+'Exhibit A - Year 1'!X34+'Exhibit A - Year 2'!I32+'Exhibit A - Year 3'!I32+'Exhibit A - Year 4'!I32+'Exhibit A - Year 5'!I33 -> 0
A42: Construction | X42: 500000 | Z42: =+'Exhibit A - Year 1'!X35+'Exhibit A - Year 2'!I33+'Exhibit A - Year 3'!I33+'Exhibit A - Year 4'!I33+'Exhibit A - Year 5'!I34 -> 0
A43: Subtotal CPFF Costs | B43: 0 | H43: 0 | I43: 0 | J43: 0 | K43: 0 | L43: 0 | M43: 0 | Q43: 0 | R43: 0 | S43: 0 | X43: 0
A44: G&A (Identify G&A Rate)
A45: Total CPFF Proposed Costs
A46: Reserve Fee
A47: Total Proposed CPFF Fee
A48: Total CPFF Proposal | B48: 0 | H48: 0 | I48: 0 | J48: 0 | K48: 0 | L48: 0 | M48: 0 | Q48: 0 | R48: 0 | S48: 0 | X48: 0
...

Sheet Exhibit B - % of Subcontracting
A1: Attachment 7
A2: DE-SOL-0003816
A3: Percentage of Subcontracting - See FAR 52.219-14
A4: Amendment 000006
A6: Description | B6: Base Year 1 | C6: % of | D6: Option Year 1 (Year 2) | E6: % of | F6: Option Year 2 (Year 3) | G6: % of | H6: Option Year 3 (Year 4) | I6: % of | J6: Option Year 4 (Year 5) | K6: % of | L6: Total Option | M6: % of | N6: Total Contract | O6: % of
C7: Total | E7: Total | G7: Total | I7: Total | K7: Total | L7: Years | M7: Total | O7: Total
A8: Total Proposal:
A9: Prime Contractor Fully-Loaded Labor | B9: 0 | D9: 0 | F9: 0 | H9: 0 | J9: 0 | L9: 0 | N9: 0
A10: Teaming Partner(s) Fully-Loaded Labor (if applicable)
A11: Subcontractor(s) Fully-Loaded Labor
A12: Travel
A13: Materials
A14: Other Direct Costs
A15: Total Proposal | B15: 0 | D15: 0 | N15: 0
A17: Proposed Fully-Loaded Labor, Exclusive of Fee:
A18: Prime Contractor Fully-Loaded Labor | B18: 0 | D18: 0 | F18: 0 | H18: 0 | J18: 0 | L18: 0 | N18: 0
A19: Teaming Partner(s) Fully-Loaded Labor (if applicable)
A20: Subcontractor(s) Fully-Loaded Labor
A21: Total Proposed Labor | B21: 0 | D21: 0 | N21: 0
A23: Proposed Direct Productive Labor Hours (DPLH):
A24: Prime Contractor DPLH | B24: 0 | D24: 0 | F24: 0 | H24: 0 | J24: 0 | L24: 0 | N24: 0
A25: Teaming Partner(s) DPLH (if applicable)
A26: Subcontractor(s) DPLH
A27: Total Proposed DPLH | B27: 0 | D27: 0 | F27: 0 | H27: 0 | J27: 0 | L27: 0 | N27: 0
