Workbook

Sheet Instructions
A2: Project Scaling Worksheet
A3: Instructions
A4: What is Project Scaling ?
A5: Project Scaling is the method that will help define the size and risk of a project as well as the amount of Project Management rigor, Governance, Documentation and Reporting needed for each project. A "Level One" project is the most complex and a "Level Three" project is the least complex. The areas that will determine the project level will be the Project Complexity, Project Visibility, Project Duration and Project Cost. Some of these categories will be further broken down into subcategories. For a definition of each Category and Subcategory, please refer to the Definitions tab.
A7: How do I determine a Project’s Level?
A8: The Office of Policy, Planning and Performance Management has developed an easy to use Project Scaling Worksheet that analyzes project characteristics and yields a numerical score and project level.
A10: Steps:
A11: 1. | B11: Open the Project Scaling Worksheet
A12: 2. | B12: Click on the Project Scaling Worksheet tab and assign a value to each of the Characteristics. The fields in orange represent columns that need to be selected.
A13: 3. | B13: The tool will automatically add the values and display the project’s score and level in the Project Score section at the bottom of the page
A14: 4. | B14: Once completed save and archive the file in the project's collaboration site.
A15: 5. | B15: Once you have identified the project level, you can then review the Deliverables Matrix and the accompanying Process Flow Diagram to get an idea of the Project Management Rigor, Governance, Documentation and Reporting that will be needed for your project.

Sheet Defintions
A1: Project Scaling Worksheet
A2: Definitions
A3: Project Complexity
A4: ='Project Scaling Worksheet'!B6 -> Sponsor | B4: Senior manager with a vested interest in the outcome of the project. If the project is a part of a larger effort (program), then the project sponsor can be the actual program manager for the entire effort. The fewer the sponsors, the simpler the communication. If there is no sponsor, there is no clear direction. Too many sponsors could result in conflicting objectives and communication challenges.
A5: ='Project Scaling Worksheet'!B7 -> Project Objectives | B5: Are the project objectives clearly defined? Were clear definitions of the deliverables received for accomplishing this project?
A6: Business Impact | B6: Impact to business if project is not successful
A7: ='Project Scaling Worksheet'!B9 -> Technical Requirements | B7: Are the technical requirements familiar to the group? In the past, has the group developed or delivered similar requirements? Have you completed a project similar to this one in scope and complexity?
A8: ='Project Scaling Worksheet'!B10 -> Team Location | B8: What is the general location of the project team? Are you using internal resources only; using only contractors; or a mix of both? Are team members located in the same building, division, city or country?
A9: ='Project Scaling Worksheet'!B11 -> Deadline | B9: Has a firm deadline to deliver the project been established? Will the deadline allow us to complete the project in a timely manner, or is it to restrictive?
A10: ='Project Scaling Worksheet'!B12 -> Stakeholder Involvement | B10: Outside the project team. How many people need to be kept up to date on the project progress? How complex are the communication needs going to be?
A11: ='Project Scaling Worksheet'!B13 -> External Dependencies | B11: Does project success depend upon an entity outside of the commonwealth - Federal Agency, Vendor/Business Partner, local government, other states, etc.?
A12: Project Team | B12: How experienced is this project team using the technology associated with the project. If the project requires unfamiliar technology, the risk factor goes up.
A13: Cross-Agency | B13: How many agencies will collaborate to build the product?
A14: Number of Systems Impacted | B14: How many existing systems will be impacted by the implementation of the new system?
A15: Organizational Risks | B15: Is there a potential for project failure due to organizational disruptions or cultural resistance?
A17: Project Visibility
A18: Legislative Initiative | B18: Is the legislature watching this project?
A19: Governor Initiative | B19: Is the Governor's office monitoring this project?
A20: Federal Mandate | B20: Did the federal government mandate this project?
A21: Public Facing | B21: Is this project visible to the public?
A23: Project Duration
A24: This section defines the planned duration for the overall project
A26: Project Costs
A27: This section defines the estimated costs for the overall project

Sheet Project Scaling Worksheet
A1: Project Scaling Worksheet V2
B3: Project Complexity
D4: N/A | E4: Low High
D5: =E48 -> 0 | E5: =E49 -> 1 | F5: =E50 -> 2 | G5: =E51 -> 3 | H5: =E52 -> 4 | I5: =E53 -> 5 | K5: Weight
B6: Sponsor | C6: One | J6: More than 1 | K6: 0.5
B7: Project Objectives | C7: Clear | J7: Vague | K7: 0.5
B8: Business Impact | C8: Minimal | J8: Major | K8: 0.5
B9: Technical Requirements | C9: Familiar | J9: Unfamiliar | K9: 0.5
B10: Team Location | C10: One | J10: More than 1 | K10: 0.25
B11: Deadline | C11: Defined | J11: Loose | K11: 0.5
B12: Stakeholder Involvement | C12: 2 People | J12: More than 20 | K12: 0.5
B13: External Dependencies | C13: None | J13: Many | K13: 0.25
B14: Project Team | C14: Experienced | J14: Inexperienced | K14: 0.5
B15: Cross-Agency | C15: One | J15: Many | K15: 0.25
B16: Number of Systems Impacted | C16: One | J16: Many | K16: 0.5
B17: Organizational Risks | C17: Not Likely | J17: Likely | K17: 0.25
B18: Project Complexity Score | D18: =SUM(D6*K6)+(D7*K7)+ (D8*K8) + (D9*K9)+(D10*K10)+(D11*K11)+(D12*K12)+(D13*K13) +(D14*K14)+(D15*K15)+(D16*K16)+(D17*K17) -> 0
B20: Project Visibility
D21: No | G21: Yes
D22: =E55 -> 0 | G22: =E56 -> 5 | K22: Weight
B23: Legislative Initiative | C23: No | D23: 0 | J23: Yes | K23: 0.5
B24: Governor Initiative | C24: No | D24: 0 | J24: Yes | K24: 1
B25: Federal Mandate | C25: No | D25: 0 | J25: Yes | K25: 0.7
B26: Public Facing | C26: No | D26: 0 | J26: Yes | K26: 0.7
B27: Project Visibility Score | D27: =SUM(D23*K23)+(D24*K24)+(D25*K25)+(D26*K26) -> 0
B29: Project Duration
D30: < 6 months | J30: 6 - 12 months | K30: > 12 months
D31: =E58 -> 5 | J31: =E59 -> 10 | K31: =E60 -> 20
B32: Duration of the Project
B34: Project Costs
D35: =<250k | J35: 250k - 1M | K35: > 1M
D36: =E62 -> 10 | J36: =E63 -> 25 | K36: =E64 -> 40
B37: Cost of the Project
B39: Project Score
B40: Total Calculated Score | D40: =D18+D27+ D32 +D37 -> 0 | J40: =IF(D40=0," ",IF(D40 < 50,"Level Three",IF(D40 = 50, "Level Two",IF(D40<75, "Level Two",IF(D40= 50,"Level Two","Level One")))))
B41: Level One Project | D41: 75 - 100
B42: Level Two Project | D42: 50 - 74
B43: Level Three Project | D43: < 50
C48: Project Complexity Values | E48: 0
E49: 1
...
