Workbook
Name Ac: [1]Elements!$C$5
Name Ag: [1]Elements!$C$6
Name Al: [1]Elements!$C$7
Name Am: [1]Elements!$C$8
Name Ar: [1]Elements!$C$9
Name As: [1]Elements!$C$10
Name At: [1]Elements!$C$11
Name Au: [1]Elements!$C$12
Name B: [1]Elements!$C$13
Name Ba: [1]Elements!$C$14
Name Be: [1]Elements!$C$15
Name Bi: [1]Elements!$C$16
Name Br: [1]Elements!$C$17
Name C_: [1]Elements!$C$18
Name Ca: [1]Elements!$C$19
Name Cd: [1]Elements!$C$20
Name Ce: [1]Elements!$C$21
Name Cl: [1]Elements!$C$22
Name CO: [1]Elements!$C$23
Name Cr: [1]Elements!$C$24
Name Cs: [1]Elements!$C$25
Name Cu: [1]Elements!$C$26
Name Dy: [1]Elements!$C$27
Name Er: [1]Elements!$C$28
Name Eu: [1]Elements!$C$29
Name ex: #REF!
Name F: [1]Elements!$C$30
Name Fe: [1]Elements!$C$31
Name Fr: [1]Elements!$C$32
Name Ga: [1]Elements!$C$33
Name Gd: [1]Elements!$C$34
Name Ge: [1]Elements!$C$35
Name H: [1]Elements!$C$36
Name He: [1]Elements!$C$37
Name Hf: [1]Elements!$C$38
Name Hg: [1]Elements!$C$39
Name Ho: [1]Elements!$C$40
Name HX: #REF!
Name I: [1]Elements!$C$41
Name In: [1]Elements!$C$42
Name Ir: [1]Elements!$C$43
Name K: [1]Elements!$C$44
Name Kr: [1]Elements!$C$45
Name Krx: '[2]SO2+O2'!$C$4
Name La: [1]Elements!$C$46
Name Li: [1]Elements!$C$47
Name Lu: [1]Elements!$C$48
Name Mg: [1]Elements!$C$49
Name Mn: [1]Elements!$C$50
Name Mo: [1]Elements!$C$51
Name MolsSO3: '[2]SO2+O2'!$C$6:$I$6
Name N: [1]Elements!$C$52
Name Na: [1]Elements!$C$53
Name Nb: [1]Elements!$C$54
Name Nd: [1]Elements!$C$55
Name Ne: [1]Elements!$C$56
Name NGEqns: #REF!
Name NGRfrm: #REF!
Name Ni: [1]Elements!$C$57
Name Np: [1]Elements!$C$58

Sheet MainEntry
B1: Note: text box appearance may vary with different Windows and Excel versions.
D2: Please read cell comments
H15: Heat loss, J | J15: Hot gas T, °C | L15: Dew Point T, °C | O15: Heat treat Furnace T, °C
H16: 30000 | J16: 1200 | L16: 15 | O16: 1080
L17: =IF(L16>P29,"Error in dpt entry"," ")
C19: Natural Gas/Fuel Properties | I19: Oxidant Properties | Q19: Table 1. Summary of Results
D20: Species | E20: mol % | I20: % O2 in Oxidant | J20: 0.21 | L20: Surplus/deficiency of heat in Burner device
C21: Methane | D21: CH4 | E21: 0.96 | I21: Oxidant temperature, °C | J21: 27 | N21: =Calcs!S23 -> -29151.106 | O21: =IF(N21<0,"<==Too much heat! Remove more heat or lower the % stoich. oxidant","<==Not enough heat! Remove less heat, lower the hot gas temp. or raise the % stoich. oxidant") -> <==Too much heat! Remove more heat or lower the % stoich. oxidant
C22: Ethene | D22: C2H4 | E22: 0.002 | I22: Stoichiometric amount of oxidant | J22: =Calcs!L8 -> 9.6261905
C23: Ethane | D23: C2H6 | E23: 0.015 | N23: Composition of hot burner gas | T23: Composition of Exogas
C24: Propane | D24: C3H8 | E24: 0.006 | I24: % stoichiometric oxidant | J24: 0.55 | O24: % H2 | P24: =Calcs!O11 -> 0.14778214 | T24: % H2 | U24: =Calcs!AD13 -> 0.14439937
C25: Butanes & higher | D25: C4H10 + | E25: 0.002 | I25: Amount of oxidant | J25: =Calcs!L10 -> 5.2944048 | O25: % H2O | P25: =Calcs!O12 -> 0.1296194 | T25: % H2O | U25: =Calcs!AD14 -> 0.039113529
C26: Hydrogen | D26: H2 | E26: 0 | O26: % CO2 | P26: =Calcs!O13 -> 0.037216231 | T26: % CO2 | U26: =Calcs!AD15 -> 0.019467411
C27: Carbon monoxide | D27: CO | E27: 0 | O27: % CO | P27: =Calcs!O14 -> 0.10418516 | T27: % CO | U27: =Calcs!AD16 -> 0.14030654
C28: Carbon dioxide | D28: CO2 | E28: 0.001 | O28: % N2 | P28: =Calcs!O15 -> 0.58119706 | T28: % N2 | U28: =Calcs!AD17 -> 0.65671315
C29: Water vapor | D29: H2O | E29: 0 | O29: Dew point, °C | P29: =Calcs!O16 -> 51.412348
C30: Nitrogen (by diff.) | D30: N2 | E30: =1-SUM(E21:E29) -> 0.014
O31: Volume of hot gas at hot gas temp, m3 | P31: =Calcs!O22 -> 0.87275651 | T31: Volume of furnace gas at furnace temp, m3 | U31: =Calcs!AD25 -> 0.70947296
D32: Fuel temperature, °C | E32: 23
C33: Element Content of Fuel | O33: Reactivity of hot furnace gas | T33: Reactivity of furnace gas
B34: Element | C34: moles | D34: mass | O34: Log pO2 in furnace gas | P34: =Calcs!O17 -> -11.879653 | T34: Log pO2 in exogas | U34: =Calcs!AD19 -> -14.469161 | V34: =IF(U34<U35,"Fe won't oxidize","Fe oxidizes! Adjust an input value.") -> Fe won't oxidize
B35: C | C35: =E21+2*E22+2*E23+3*E24+4*E25+E27+E28 -> 1.021 | D35: =12.01*C35 -> 12.26221 | O35: Log pO2 for Fe/wust. | P35: =Calcs!O18 -> -11.976454 | Q35: =IF(P34<P35,"Fe won't oxidize","Fe oxidizes") -> Fe oxidizes | T35: Log pO2 for Fe/wust. | U35: =Calcs!AD20 -> -13.6392
B36: H | C36: =4*E21+4*E22+6*E23+8*E24+10*E25+2*E26+2*E29 -> 4.006 | D36: =1.00795*C36 -> 4.0378477 | T36: %C in austenite | U36: =Calcs!AD23 -> 0.010572541
B37: O | C37: =E27+2*E28+E29 -> 0.002 | D37: =16*C37 -> 0.032
B38: N | C38: =2*E30 -> 0.028 | D38: =14.007*C38 -> 0.392196
B39: Sum | C39: =SUM(C35:C38) -> 5.057 | D39: =SUM(D35:D38) -> 16.724254

Sheet Calcs
B1: Please read cell comments
P3: Burner Calculations | V3: Cooler Calculations | Z3: Exogas Preparation
B4: Legend | J4: Material Balance/Equilib Calculations | Q4: Heat Balance Calculations | V4: Heat Balance Calculations | Z4: Material Balance/Equilib Calculations
C5: Values Entered on MainEntry
F6: Natural Gas/Fuel Properties | K6: Burner temp, °C | L6: =MainEntry!J16 -> 1200 | N6: Amount of H2: | O6: =(-L17-SQRT(L17^2-4*L16*L18))/(2*L16) -> 1.0670728 | R6: NatGas temp | S6: =MainEntry!E32 -> 23 | V6: Dew point temp, °C | W6: =MainEntry!L16 -> 15 | Z6: Exogas furnace temp, °C | AA6: =MainEntry!O16 -> 1080
C7: Species | D7: Cp | E7: Mol. mass | F7: Vol % | G7: Mass, g | H7: Mass % | K7: Vol. % O2 in oxidant gas | L7: =MainEntry!J20 -> 0.21 | N7: Amount of H2O: | O7: =L12-O6 -> 0.93592724 | R7: Oxidant temp | S7: =MainEntry!J21 -> 27 | V7: pH2O at dpt | W7: =10^(G33+F33/(W6+273)) -> 0.01652913 | Z7: Amount of H2: | AA7: =O6 -> 1.0670728 | AC7: Amount of H2: | AD7: =(-AA23-SQRT(AA23^2-4*AA22*AA24))/(2*AA22) -> 0.92275217
B8: Methane | C8: CH4 | D8: 36 | E8: 16.043 | F8: =MainEntry!E21 -> 0.96 | G8: =E8*F8 -> 15.40128 | H8: =G8/$E$19 -> 0.92082766 | K8: Stoichiometric oxidant | L8: =(2*F8 + 3*F9 + 3.5*F10 + 5*F11 + 6.5*F12 + 0.5*F13 + 0.5*F14)/L7 -> 9.6261905 | N8: Amount of CO2: | O8: =L13-L12+O6-L11 -> 0.26872276 | R8: Bring NatGas to 25°C | S8: =(25-S6)*Q39 -> 73.1148 | V8: Amount of H2O condensing | W8: =-(W7*(O10-O7))/(1-W7)+O7 -> 0.8303015 | Z8: Amount of H2O: | AA8: =O7-W8 -> 0.10562574 | AC8: Amount of H2O: | AD8: =AA19-AD7 -> 0.24994633
B9: Ethene | C9: C2H4 | D9: 43 | E9: 28.054 | F9: =MainEntry!E22 -> 0.002 | G9: =E9*F9 -> 0.056108 | H9: =G9/$E$19 -> 0.0033546431 | K9: % stoichiometric oxidant | L9: =MainEntry!J24 -> 0.55 | N9: Amount of CO: | O9: =L11-O8 -> 0.75227724 | R9: Bring oxidant to 25°C | S9: =L10*(25-S7)*Q40 -> -308.80145 | V9: Cool CO to dpt | W9: =-S16+D14*(W6-25) -> -28812.902 | Z9: Amount of CO2: | AA9: =O8 -> 0.26872276 | AC9: Amount of CO2: | AD9: =AA20-AA19+AD7-AA18 -> 0.12440217
B10: Ethane | C10: C2H6 | D10: 54 | E10: 30.07 | F10: =MainEntry!E23 -> 0.015 | G10: =E10*F10 -> 0.45105 | H10: =G10/$E$19 -> 0.026967844 | K10: Amount of oxidant | L10: =L8*MainEntry!J24 -> 5.2944048 | N10: Amount of hot gas: | O10: =SUM(O6:O9)+L14 -> 7.2205798 | R10: Formation of CO | S10: =O9*D38 -> -83148.451 | V10: Cool CO2 to dpt | W10: =-S17 -> -16158.74 | Z10: Amount of CO: | AA10: =O9 -> 0.75227724 | AC10: Amount of CO: | AD10: =AA18-AD9 -> 0.89659783
B11: Propane | C11: C3H8 | D11: 75 | E11: 44.097 | F11: =MainEntry!E24 -> 0.006 | G11: =E11*F11 -> 0.264582 | H11: =G11/$E$19 -> 0.015819102 | K11: Carbon in, C: | L11: =MainEntry!C35 -> 1.021 | N11: % H2 | O11: =O6/$O$10 -> 0.14778214 | R11: formation of CO2 | S11: =(O8-F15)*D40 -> -105351.32 | V11: Cool H2O to dpt | W11: =-S18 -> -43805.475 | Z11: Amount of N2 | AA11: =L14 -> 4.1965798 | AC11: Amount of N2 | AD11: =AA11 -> 4.1965798
B12: Butanes & higher | C12: C4H10 + | D12: 103 | E12: 58.124 | F12: =MainEntry!E25 -> 0.002 | G12: =E12*F12 -> 0.116248 | H12: =G12/$E$19 -> 0.0069503557 | K12: Hydrogen in, as H2: | L12: =MainEntry!C36/2 -> 2.003 | N12: % H2O | O12: =O7/$O$10 -> 0.1296194 | R12: Formation of H2O | S12: =O7*D42 -> -226320.31 | V12: Cool H2 to dpt | W12: =-S19 -> -37811.851 | Z12: Amount of Ingas | AA12: =SUM(AA7:AA11) -> 6.3902783 | AC12: Amount of Ingas | AD12: =SUM(AD7:AD11) -> 6.3902783
B13: Hydrogen | C13: H2 | D13: 29 | E13: 2.016 | F13: =MainEntry!E26 -> 0 | G13: =E13*F13 -> 0 | H13: =G13/$E$19 -> 0 | K13: Oxygen in, as O: | L13: =MainEntry!C37+ Calcs!L7*Calcs!L10*2 -> 2.22565 | N13: % CO2 | O13: =O8/$O$10 -> 0.037216231 | R13: Formation of NG | S13: =F8*D32+F11*D35 -> -72440.682 | V13: Cool N2 to dpt | W13: =-S20 -> -157175.01 | Z13: % H2 | AA13: =AA7/$AA$12 -> 0.16698377 | AC13: % H2 | AD13: =AD7/$AD$12 -> 0.14439937
B14: Carbon monoxide | C14: CO | D14: 30 | E14: 28.011 | F14: =MainEntry!E27 -> 0 | G14: =E14*F14 -> 0 | H14: =G14/$E$19 -> 0 | K14: Nitrogen in, as N2: | L14: =MainEntry!C38/2 + (1-L7)*L10 -> 4.1965798 | N14: % CO | O14: =O9/$O$10 -> 0.10418516 | R14: Sum of Rx heat | S14: =SUM(S8:S12)-S13 -> -342615.08 | V14: DH°condensation of water vapor | W14: =W8*(D43-D42) -> -36546.551 | Z14: % H2O | AA14: =AA8/$AA$12 -> 0.01652913 | AC14: % H2O | AD14: =AD8/$AD$12 -> 0.039113529
B15: Carbon dioxide | C15: CO2 | D15: 38 | E15: 44.011 | F15: =MainEntry!E28 -> 0.001 | G15: =E15*F15 -> 0.044011 | H15: =G15/$E$19 -> 0.0026313752 | K15: Krx, WGS: | L15: =10^(I41/(L6+273)+J41) -> 2.4553959 | N15: % N2 | O15: =L14/$O$10 -> 0.58119706 | V15: Heat removed in cooler | W15: =SUM(W9:W14) -> -320310.53 | Z15: % CO2 | AA15: =AA9/$AA$12 -> 0.042051809 | AC15: % CO2 | AD15: =AD9/$AD$12 -> 0.019467411
B16: Water vapor | C16: H2O | D16: 33.6 | E16: 18.016 | F16: =MainEntry!E29 -> 0 | G16: =E16*F16 -> 0 | H16: =G16/$E$19 -> 0 | K16: QF parameter a: | L16: =1/L15-1 -> -0.5927337 | N16: Dew point, °C | O16: =F33/(LOG(O12)-G33)-273 -> 51.412348 | R16: Heat CO | S16: =O9*(R33*L6^2+Q33*L6+P33) -> 28512.902 | Z16: % CO | AA16: =AA10/$AA$12 -> 0.11772214 | AC16: % CO | AD16: =AD10/$AD$12 -> 0.14030654
B17: Nitrogen (by diff.) | C17: N2 | D17: 29.1 | E17: 28.014 | F17: =MainEntry!E30 -> 0.014 | G17: =E17*F17 -> 0.392196 | H17: =G17/$E$19 -> 0.02344902 | K17: QF parameter b: | L17: =(L13-2*L11-2*L12)/L15 -L13+L12+L11 -> -0.75836436 | N17: Log pO2 in hot gas | O17: =I33/(L6+273)+J33 - 2*LOG(O14)+2*LOG(O13) -> -11.879653 | P17: =IF(O17<O18,"Fe won't oxidize","Fe oxidizes") -> Fe oxidizes | R17: Heat CO2 | S17: =O8*(R37*L6^2+Q37*L6+P37) -> 16158.74 | Z17: % N2 | AA17: =AA11/$AA$12 -> 0.65671315 | AC17: % N2 | AD17: =AD11/$AD$12 -> 0.65671315
C18: O2 | D18: 29.4 | E18: 32 | K18: QF parameter c: | L18: =(2*L11*L12 + L12^2 -L12*L13)/L15 -> 1.4841428 | N18: log pO2 for Fe/wust. | O18: =F41/(L6+273) +G41 -> -11.976454 | R18: Heat H2O | S18: =O7*(N37*L6^2+M37*L6+L37) -> 43805.475 | Z18: Carbon in, C: | AA18: =AA9+AA10 -> 1.021
D19: Molecular mass of NG | E19: =E8*F8+E9*F9+E10*F10+E11*F11+E12*F12+E13*F13+E14*F14+E15*F15+E16*F16+E17*F17 -> 16.725475 | N19: Activity of C | O19: =(10^(F37/(L6+273) +G37))*(O14^2/O13) -> 0.00025198591 | R19: Heat H2 | S19: =O6*(N41*L6^2+M41*L6+L41) -> 37811.851 | Z19: Hydrogen in, as H2: | AA19: =AA7+AA8 -> 1.1726985 | AC19: Log pO2 in exogas | AD19: =I33/(AA6+273)+J33 - 2*LOG(AD16)+2*LOG(AD15) -> -14.469161 | AE19: =IF(AD19<AD20,"Fe won't oxidize","Fe oxidizes") -> Fe won't oxidize
N20: pCH4 | O20: =(O14^2*O11^2*10^(I37/(L6+273)+J37))/O13 -> 1.5583695e-08 | R20: Heat N2 | S20: =L14*(N33*L6^2+M33*L6+L33) -> 157175.01 | Z20: Oxygen in, as O: | AA20: =AA8+2*AA9+AA10 -> 1.3953485 | AC20: log pO2 for Fe/wust. | AD20: =F41/(AA6+273)+G41 -> -13.6392
G21: moles | R21: Sum of product heat | S21: =SUM(S16:S20) -> 283463.97 | Z21: Krx, WGS: | AA21: =10^(J41+I41/(AA6+273)) -> 1.9522319 | AC21: Activity of C | AD21: =(10^(F37/(AA6+273) +G37))*(AD16^2/AD15) -> 0.0029247538
F22: CO2 + CO produced by combustion | G22: =MainEntry!C35-MainEntry!E28 -> 1.02 | N22: Volume of hot gas at hot gas temp, m3 | O22: =O10*0.0820575*(L6+273)/1000 -> 0.87275651 | R22: Heat loss | S22: =MainEntry!H16 -> 30000 | Z22: QF parameter a: | AA22: =1/AA21-1 -> -0.48776578 | AC22: pCH4 | AD22: =(AD16^2*AD13^2*10^(I37/(AA6+273)+J37))/AD15 -> 3.3619191e-07
F23: CO2 + CO in hot gas | G23: =MainEntry!C35 -> 1.021 | R23: Heat surplus/deficiency | S23: =S14+S21+S22 -> -29151.106 | T23: =IF(S23<0,"<==Remove more heat or lower the % stoich. oxidant","<==Remove less heat, lower the hot gas temp. or raise the % stoich. oxidant") -> <==Remove more heat or lower the % stoich. oxidant | Z23: QF parameter b: | AA23: =(AA20-2*AA18-2*AA19)/AA21 -AA20+AA19+AA18 -> -0.73427963 | AC23: %C | AD23: =AD21/(0.000003037*AA6^2 -0.007284*AA6+4.601) -> 0.010572541
F24: H2O + H2 produced by combustion | G24: =MainEntry!C36/2-MainEntry!E29 -> 2.003 | Z24: QF parameter c: | AA24: =(2*AA18*AA19 + AA19^2 -AA19*AA20)/AA21 -> 1.0928768
F25: H2O + H2 in hot gas | G25: =MainEntry!C36/2 -> 2.003 | AC25: Volume of furnace gas at furnace temp, m3 | AD25: =AD12*0.0820575*(AA6+273)/1000 -> 0.70947296
B30: Table I. Molar DH°form at 25 °C | H30: Table IX. Log Keq parameters, = A/T + B | O30: Table X. Heat content eq'n. parameters, J/g-mol = A + BT + CT2
D31: J/g-mol | F31: pH2O, 273 - 333 K | I31: pO2, 1100 - 1700 K | L31: N2, 750 - 1450°C | P31: CO, 750 - 1450°C
C32: CH4 | D32: -74810 | F32: A | G32: B | I32: A | J32: B | L32: A | M32: B | N32: C | P32: A | Q32: B | R32: C
C33: C2H4 | D33: 52467 | F33: -2295 | G33: 6.187 | I33: -29365 | J33: 8.95 | L33: -1508 | M33: 30.28 | N33: 0.001823 | P33: -1803 | Q33: 31.08 | R33: 0.001673
B34: NatGas0reactant | C34: C2H6 | D34: -84684
B35: reactant | C35: C3H8 | D35: -103847 | F35: aC, 1100 - 1700 K | I35: pCH4, 1100 - 1700 K | L35: H2O(g), 750 - 1450°C | P35: CO2, 750 - 1450°C
B36: species | C36: C4H10 | D36: -126148 | F36: A | G36: B | I36: A | J36: B | L36: A | M36: B | N36: C | P36: A | Q36: B | R36: C
C37: H2 | D37: 0 | F37: 8715 | G37: -8.98 | I37: 13520 | J37: -14.79 | L37: -1463 | M37: 33.87 | N37: 0.005294 | P37: -4845 | Q37: 50.15 | R37: 0.003331
C38: CO | D38: -110529
F39: pO2, Fe/Wust | I39: WGS Keq, 1100 - 1700 K | L39: H2, 750 - 1450°C | P39: Cp of NG | Q39: =D8*F8+D9*F9+D10*F10+D11*F11+D12*F12+D13*F13+D14*F14+D15*F15+D16*F16+D17*F17 -> 36.5574
C40: CO2 | D40: -393509 | F40: A | G40: B | I40: A | J40: B | L40: A | M40: B | N40: C | P40: Cp of oxidant | Q40: =D18*L7+D17*(1-L7) -> 29.163
B41: Combustion | C41: CO | D41: -110530 | F41: -27615 | G41: 6.771 | I41: -1654 | J41: 1.513 | L41: -166 | M41: 27.18 | N41: 0.002073
B42: products | C42: H2O(g) | D42: -241814
C43: H2O(liq) | D43: -285830
B47: Table II. Heat Content Data for Gas Species
B48: T (C) | C48: N2 | D48: H2O | E48: H2 | F48: CO | G48: CO2
...

Sheet StoredResults
C2: Summary of Results from Methane Combustion. Air enters at 50°C.
C12: Heat loss, J | E12: Hot gas T, °C | G12: Dew Point T, °C | J12: Exogas Furnace T, °C
C13: 50000 | E13: 1120 | G13: 20 | J13: 1050
D16: Oxidant Properties | J16: Summary of Results for Methane as Exogas Fuel
D17: % O2 in Oxidant | E17: 0.21 | G17: Surplus/deficiency of heat in Burner device
D18: Oxidant temperature, °C | E18: 50 | I18: -45953.389 | J18: =IF(I18<0,"<==Remove more heat or lower the % stoich. oxidant","<==Lower the hot gas temp. or raise the % stoich. oxidant") -> <==Remove more heat or lower the % stoich. oxidant
D19: Stoichiometric amount of oxidant | E19: 9.5238095
J20: Composition of hot burner gas | O20: Composition of Exogas
D21: % stoichiometric oxidant | E21: 0.57 | J21: % H2 | K21: 0.14111798 | O21: % H2 | P21: 0.13562678
D22: oxidant/gas ratio | E22: 5.4285714 | J22: % H2O | K22: 0.13328421 | O22: % H2O | P22: 0.046118258
J23: % CO2 | K23: 0.042333194 | O23: % CO2 | P23: 0.0242274
J24: % CO | K24: 0.094867903 | O24: % CO | P24: 0.13049396
J25: % N2 | K25: 0.58839671 | O25: % N2 | P25: 0.6635336
J26: Dew point, °C | K26: 51.968576 | O26: Reactivity of exogas
L27: Reactivity of hot furnace gas | O27: Log pO2 in exogas | P27: -14.708334
J28: Log pO2 in furnace gas | K28: -12.831279 | O28: log pO2 for Fe/wust. | P28: -14.102016 | Q28: Fe won't oxidize
J29: log pO2 for Fe/wust. | K29: -13.053121 | L29: Fe oxidizes
E33: Chart Data
B34: % stoichiometric oxidant | C34: 0.4 | D34: 0.5 | E34: 0.6 | F34: 0.7 | G34: 0.8 | H34: 0.9 | I34: 1
B35: % H2 | C35: 0.25 | D35: 0.17774393 | E35: 0.12212669 | F35: 0.079031182 | G35: 0.045593381 | H35: 0.019767131 | I35: 0
B36: % H2O | C36: 0.079403183 | D36: 0.11518174 | E36: 0.14150711 | F36: 0.16063643 | G36: 0.17410233 | H36: 0.18302922 | I36: 0.18831115
B37: % CO2 | C37: 0.019905344 | D37: 0.032162959 | E37: 0.044266751 | F37: 0.05657963 | G37: 0.069315668 | H37: 0.08255972 | I37: 0.096281515
B38: % CO | C38: 0.14858515 | D38: 0.11760686 | E38: 0.090526448 | F38: 0.065959909 | G38: 0.043012446 | H38: 0.021127929 | I38: 0
B39: % N2 | C39: 0.50196923 | D39: 0.55730451 | E39: 0.601573 | F39: 0.63779285 | G39: 0.66797617 | H39: 0.693516 | I39: 0.71540734
B40: Dew point, °C | C40: 41.937416 | D40: 49.077401 | E40: 53.169369 | F40: 55.742119 | G40: 57.396694 | H40: 58.43285 | I40: 59.025295
J41: Natural Gas/Fuel Composition
K42: Species | L42: mol %
J43: Methane | K43: CH4 | L43: 0.96
J44: Ethene | K44: C2H4 | L44: 0.002
J45: Ethane | K45: C2H6 | L45: 0.013
J46: Propane | K46: C3H8 | L46: 0.005
J47: Butanes & higher | K47: C4H10 + | L47: 0.002
J48: Hydrogen | K48: H2 | L48: 0
J49: Carbon monoxide | K49: CO | L49: 0
J50: Carbon dioxide | K50: CO2 | L50: 0.006
J51: Water vapor | K51: H2O | L51: 0
J52: Nitrogen (by diff.) | K52: N2 | L52: =1-SUM(L43:L51) -> 0.012
B59: Hot gas composition for listed NG. Fe will oxidize at and above 53% Stoich air.
B60: % CO and %H2 approach zero % at 100 % stoichiometric air.
