Workbook

Sheet Project Summary
A1: Project Name | B1: << the name from the AGIT project form>>
A3: Costs
A4: Implementation and Year 1 | B4: ='New Budget Costs'!F66+'New Budget Costs'!G66 -> 14.5
A5: Year 2 | B5: ='New Budget Costs'!H66 -> 7
A6: Year 3 | B6: ='New Budget Costs'!I66 -> 7
A7: Year 4 | B7: ='New Budget Costs'!J66 -> 7.5
A8: Year 5 | B8: ='New Budget Costs'!K66 -> 7
A9: Five Year Total Costs | B9: ='New Budget Costs'!L66 -> 43
A11: 5 Year New Budget Costs
A12: ='New Budget Costs'!A12 -> Server and Network Hardware Subtotal | B12: ='New Budget Costs'!L12 -> 6
A13: ='New Budget Costs'!A20 -> Individual Hardware and Peripherals Subtotal | B13: ='New Budget Costs'!L20 -> 6
A14: ='New Budget Costs'!A28 -> Software or Subscriptions Subtotal | B14: ='New Budget Costs'!L28 -> 6
A15: ='New Budget Costs'!A36 -> External Consulting Subtotal | B15: ='New Budget Costs'!L36 -> 6
A16: ='New Budget Costs'!A43 -> Training Subtotal | B16: ='New Budget Costs'!L43 -> 6
A17: ='New Budget Costs'!A51 -> New University of Idaho Personnel Subtotal | B17: ='New Budget Costs'!L51 -> 6
A18: ='New Budget Costs'!A59 -> Service Advertising and Rollout Subtotal | B18: ='New Budget Costs'!L59 -> 6
A19: ='New Budget Costs'!A63 -> Project Contingency | B19: ='New Budget Costs'!L63 -> 1
A20: Total 5 Year New Budget Costs | B20: ='New Budget Costs'!L66 -> 43
A22: 5 Year Personnel Opportunity Costs | B22: ='Personnel Opportunity Costs'!L23 -> 12
A24: Total Project Cost to UI | B24: =B22+B20 -> 55
A26: Desried Project Outcomes | B26: ='New Budget Costs'!B1 -> << the name from the AGIT project form>>
A36: Positive Features | B36: ='New Budget Costs'!B1 -> << the name from the AGIT project form>>
A44: Areas of Concern | B44: ='New Budget Costs'!B1 -> << the name from the AGIT project form>>

Sheet New Budget Costs
A1: Project: | B1: ='Project Summary'!B1:C1 -> << the name from the AGIT project form>> | D1: Solution Type: | F1: <<choose Cloud, Traditional or Hybrid Cloud/Traditional>>
D2: Annual Cost Growth Rate: | F2: 0.03 | G2: Contingency %: | H2: 0.1
D4: Implementation | F4: Costs
A5: Category | B5: Sub Category | C5: Description | D5: Unit Price | E5: Units Rqd | F5: Implementation | G5: Year 1 | H5: Year 2 | I5: Year 3 | J5: Year 4 | K5: Year 5 | L5: Total 5 Year Costs
A6: Server and Network Hardware
B7: Servers for PRD and PPRD | D7: 1 | E7: 1 | F7: =D7*E7 -> 1 | G7: 1 | H7: 1 | I7: 1 | J7: 1 | K7: 1 | L7: =SUM(F7:K7) -> 6
B8: Storage | D8: 0 | E8: 0 | F8: =D8*E8 -> 0 | G8: 0 | H8: 0 | I8: 0 | J8: 0 | K8: 0 | L8: =SUM(F8:K8) -> 0
B9: Racks/Switches/Cabeling/Environmentals | D9: 0 | E9: 0 | F9: =D9*E9 -> 0 | G9: 0 | H9: 0 | I9: 0 | J9: 0 | K9: 0 | L9: =SUM(F9:K9) -> 0
D10: 0 | E10: 0 | F10: =D10*E10 -> 0 | G10: 0 | H10: 0 | I10: 0 | J10: 0 | K10: 0 | L10: =SUM(F10:K10) -> 0
D11: 0 | E11: 0 | F11: =D11*E11 -> 0 | G11: 0 | H11: 0 | I11: 0 | J11: 0 | K11: 0 | L11: =SUM(F11:K11) -> 0
A12: Server and Network Hardware Subtotal | F12: =SUM(F6:F11) -> 1 | G12: =SUM(G6:G11) -> 1 | H12: =SUM(H6:H11) -> 1 | I12: =SUM(I6:I11) -> 1 | J12: =SUM(J6:J11) -> 1 | K12: =SUM(K6:K11) -> 1 | L12: =SUM(L6:L11) -> 6
A14: Individual User Hardware and Peripherals
B15: Desktops/laptops/tablets | D15: 1 | E15: 1 | F15: =E15*D15 -> 1 | G15: 1 | H15: 1 | I15: 1 | J15: 1 | K15: 1 | L15: =SUM(F15:K15) -> 6
B16: Specialized hardware (card readers, scanners, etc.0 | D16: 0 | E16: 0 | F16: =E16*D16 -> 0 | G16: 0 | H16: 0 | I16: 0 | J16: 0 | K16: 0 | L16: =SUM(F16:K16) -> 0
B17: Printers | D17: 0 | E17: 0 | F17: =E17*D17 -> 0 | G17: 0 | H17: 0 | I17: 0 | J17: 0 | K17: 0 | L17: =SUM(F17:K17) -> 0
D18: 0 | E18: 0 | F18: =E18*D18 -> 0 | G18: 0 | H18: 0 | I18: 0 | J18: 0 | K18: 0 | L18: =SUM(F18:K18) -> 0
D19: 0 | E19: 0 | F19: =E19*D19 -> 0 | G19: 0 | H19: 0 | I19: 0 | J19: 0 | K19: 0 | L19: =SUM(F19:K19) -> 0
A20: Individual Hardware and Peripherals Subtotal | F20: =SUM(F15:F19) -> 1 | G20: =SUM(G15:G19) -> 1 | H20: =SUM(H15:H19) -> 1 | I20: =SUM(I15:I19) -> 1 | J20: =SUM(J15:J19) -> 1 | K20: =SUM(K15:K19) -> 1 | L20: =SUM(L15:L19) -> 6
A22: Software or Subscriptions
B23: Database/application server licesens | D23: 1 | E23: 1 | F23: =E23*D23 -> 1 | G23: 1 | H23: 1 | I23: 1 | J23: 1 | K23: 1 | L23: =SUM(F23:K23) -> 6
B24: Software licenses | D24: 0 | E24: 0 | F24: =E24*D24 -> 0 | G24: 0 | H24: 0 | I24: 0 | J24: 0 | K24: 0 | L24: =SUM(F24:K24) -> 0
B25: Subscription costs | D25: 0 | E25: 0 | F25: =E25*D25 -> 0 | G25: 0 | H25: 0 | I25: 0 | J25: 0 | K25: 0 | L25: =SUM(F25:K25) -> 0
B26: Development tools | D26: 0 | E26: 0 | F26: =E26*D26 -> 0 | G26: 0 | H26: 0 | I26: 0 | J26: 0 | K26: 0 | L26: =SUM(F26:K26) -> 0
B27: Monitoring tools | D27: 0 | E27: 0 | F27: =E27*D27 -> 0 | G27: 0 | H27: 0 | I27: 0 | J27: 0 | K27: 0 | L27: =SUM(F27:K27) -> 0
A28: Software or Subscriptions Subtotal | F28: =SUM(F23:F27) -> 1 | G28: =SUM(G23:G27) -> 1 | H28: =SUM(H23:H27) -> 1 | I28: =SUM(I23:I27) -> 1 | J28: =SUM(J23:J27) -> 1 | K28: =SUM(K23:K27) -> 1 | L28: =SUM(L23:L27) -> 6
A30: External Consulting
B31: Development | D31: 1 | E31: 1 | F31: =E31*D31 -> 1 | G31: 1 | H31: 1 | I31: 1 | J31: 1 | K31: 1 | L31: =SUM(F31:K31) -> 6
B32: Functional support | D32: 0 | E32: 0 | F32: =E32*D32 -> 0 | G32: 0 | H32: 0 | I32: 0 | J32: 0 | K32: 0 | L32: =SUM(F32:K32) -> 0
B33: Project management | D33: 0 | E33: 0 | F33: =E33*D33 -> 0 | G33: 0 | H33: 0 | I33: 0 | J33: 0 | K33: 0 | L33: =SUM(F33:K33) -> 0
B34: Business process review | D34: 0 | E34: 0 | F34: =E34*D34 -> 0 | G34: 0 | H34: 0 | I34: 0 | J34: 0 | K34: 0 | L34: =SUM(F34:K34) -> 0
D35: 0 | E35: 0 | F35: =E35*D35 -> 0 | G35: 0 | H35: 0 | I35: 0 | J35: 0 | K35: 0 | L35: =SUM(F35:K35) -> 0
A36: External Consulting Subtotal | F36: =SUM(F31:F35) -> 1 | G36: =SUM(G31:G35) -> 1 | H36: =SUM(H31:H35) -> 1 | I36: =SUM(I31:I35) -> 1 | J36: =SUM(J31:J35) -> 1 | K36: =SUM(K31:K35) -> 1 | L36: =SUM(L31:L35) -> 6
A38: Training
B39: Technical training | D39: 1 | E39: 1 | F39: =E39*D39 -> 1 | G39: 1 | H39: 1 | I39: 1 | J39: 1 | K39: 1 | L39: =SUM(F39:K39) -> 6
B40: Functional training | F40: =E40*D40 -> 0 | G40: 0 | H40: 0 | I40: 0 | J40: 0 | K40: 0 | L40: =SUM(F40:K40) -> 0
B41: End user training | F41: =E41*D41 -> 0 | G41: 0 | H41: 0 | I41: 0 | J41: 0 | K41: 0 | L41: =SUM(F41:K41) -> 0
B42: Administration training | F42: =E42*D42 -> 0 | G42: 0 | H42: 0 | I42: 0 | J42: 0 | K42: 0 | L42: =SUM(F42:K42) -> 0
A43: Training Subtotal | F43: =SUM(F39:F42) -> 1 | G43: =SUM(G39:G42) -> 1 | H43: =SUM(H39:H42) -> 1 | I43: =SUM(I39:I42) -> 1 | J43: =SUM(J39:J42) -> 1 | K43: =SUM(K39:K42) -> 1 | L43: =SUM(F43:K43) -> 6
A45: New University of Idaho Personnel
B46: Temporary Help | D46: 1 | E46: 1 | F46: =E46*D46 -> 1 | G46: 1 | H46: 1 | I46: 1 | J46: 1 | K46: 1 | L46: =SUM(F46:K46) -> 6
...

Sheet Personnel Opportunity Costs
A1: Option 1: | B1: ='New Budget Costs'!B1 -> << the name from the AGIT project form>> | D1: Solution Type: | F1: ='New Budget Costs'!F1 -> <<choose Cloud, Traditional or Hybrid Cloud/Traditional>>
B2: ='New Budget Costs'!B2 -> 0 | D2: Annual Cost Growth Rate: | F2: 0.03
D4: Implementation | F4: Opportunity Cost for Existing Personnel To Work on the Project
A5: Category | B5: Sub Category | C5: Description | D5: Hourly Rate | E5: Hours Rdq | F5: Implementation | G5: Year 1 | H5: Year 2 | I5: Year 3 | J5: Year 4 | K5: Year 5 | L5: Total 5 Year Costs
A6: Department Personnel
B7: Time for line personnel to implement system | D7: 1 | E7: 1 | F7: =D7*E7 -> 1 | G7: 1 | H7: 1 | I7: 1 | J7: 1 | K7: 1 | L7: =SUM(F7:K7) -> 6
B8: Time for technical personnel to implement system | D8: 0 | E8: 0 | F8: =D8*E8 -> 0 | G8: 0 | H8: 0 | I8: 0 | J8: 0 | K8: 0 | L8: =SUM(F8:K8) -> 0
B9: Time for management to coordinate system implemenation | D9: 0 | E9: 0 | F9: =D9*E9 -> 0 | G9: 0 | H9: 0 | I9: 0 | J9: 0 | K9: 0 | L9: =SUM(F9:K9) -> 0
D10: 0 | E10: 0 | F10: =D10*E10 -> 0 | G10: 0 | H10: 0 | I10: 0 | J10: 0 | K10: 0 | L10: =SUM(F10:K10) -> 0
D11: 0 | E11: 0 | F11: =D11*E11 -> 0 | G11: 0 | H11: 0 | I11: 0 | J11: 0 | K11: 0 | L11: =SUM(F11:K11) -> 0
A12: Department Personnel Subtotal | F12: =SUM(F6:F11) -> 1 | G12: =SUM(G6:G11) -> 1 | H12: =SUM(H6:H11) -> 1 | I12: =SUM(I6:I11) -> 1 | J12: =SUM(J6:J11) -> 1 | K12: =SUM(K6:K11) -> 1 | L12: =SUM(L6:L11) -> 6
A14: ITS Personnel
B15: Network setup and facilitation | D15: 1 | E15: 1 | F15: =E15*D15 -> 1 | G15: 1 | H15: 1 | I15: 1 | J15: 1 | K15: 1 | L15: =SUM(F15:K15) -> 6
B16: Server exploration and maintenance | D16: 0 | E16: 0 | F16: =E16*D16 -> 0 | G16: 0 | H16: 0 | I16: 0 | J16: 0 | K16: 0 | L16: =SUM(F16:K16) -> 0
B17: Security | D17: 0 | E17: 0 | F17: =E17*D17 -> 0 | G17: 0 | H17: 0 | I17: 0 | J17: 0 | K17: 0 | L17: =SUM(F17:K17) -> 0
B18: Developer/DBA time | D18: 0 | E18: 0 | F18: =E18*D18 -> 0 | G18: 0 | H18: 0 | I18: 0 | J18: 0 | K18: 0 | L18: =SUM(F18:K18) -> 0
B19: Customer support and help desk added load | D19: 0 | E19: 0 | F19: =E19*D19 -> 0 | G19: 0 | H19: 0 | I19: 0 | J19: 0 | K19: 0 | L19: =SUM(F19:K19) -> 0
A20: ITS Personnel Subtotal | F20: =SUM(F15:F19) -> 1 | G20: =SUM(G15:G19) -> 1 | H20: =SUM(H15:H19) -> 1 | I20: =SUM(I15:I19) -> 1 | J20: =SUM(J15:J19) -> 1 | K20: =SUM(K15:K19) -> 1 | L20: =SUM(L15:L19) -> 6
A23: Project Personnel Opportunity Costs | F23: =F20+F12 -> 2 | G23: =G20+G12 -> 2 | H23: =H20+H12 -> 2 | I23: =I20+I12 -> 2 | J23: =J20+J12 -> 2 | K23: =K20+K12 -> 2 | L23: =L20+L12 -> 12

Sheet TCO Instructions
A1: Number | B1: Step
A2: 1 | B2: Start with the tab entitled "New Budget Costs"
B3: The cost subcategories are only there as examples - replace or add as needed
B4: Costs on this sheet should be net new costs because of the project
B5: - time spent by existing personnel should be included in the "Personnel Oppportunity Cost" sheet
B6: Fill in the "annual cost growth rate" field - consider it inflation, how mush you think costs will rise each year, particulalry on salaries and software costs
B7: - you will have to manually use this field in calculations but it will provide consistency
B8: Fill in the "Contingency %" field
B9: - the more unknowns, the higher this percentage should be. Start with at least 10%
B10: Fill in all the implementation and yearly costs you can think of. Be thorough and be conservative.
B11: Make sure to mark years with an "X" in the "Contingency Year" field if you think that major upgrades or other risk factors will occur in that year. This will not put contingency on the salaries categoriesbut will in others.
B12: Really think through usage. For instance, scale hardware, software or subscriptions based on expected growth.
A13: 2 | B13: Now go to the "Personnel Opportuinty Costs" tab
B14: For both the functional area sponsoring the project and ITS, list the existing positions that will have to devote time to the project.
B15: Use a fully loaded rate (salary plus fringe) and put in either hours or percentages of time.
A16: 3 | B16: Check all calculations and totals on both tabs
A17: 4 | B17: On the "Project Summary" tab
B18: Fill in the project title, which will carry to other sheets
B19: Check totals for correctness
B20: Fill in major concerns, positive features and desired outcomes. If these duplicate areas in the AGIT project form, reference that form and don't fill out these sections.
