Workbook
Name __0506New: #REF!
Name __0506New: #REF!
Name __2006_07_New_Total: #REF!
Name __2006_07_New_Total: #REF!
Name __2006_07SF: #REF!
Name __2006_07SF: #REF!
Name __2007_08: #REF!
Name _01_02: #REF!
Name _02_03: #REF!
Name _0405: #REF!
Name _0506New: #REF!
Name _0506tot: '[1]FY 2005-06'!$A$1:$F$77
Name _2005_06_SF: #REF!
Name _2005_06_SF: #REF!
Name _2005_06_Total: #REF!
Name _2005_06_Total: #REF!
Name _2006_07_New_Total: #REF!
Name _2006_07_New_Total: #REF!
Name _2006_07SF: #REF!
Name _2007_08: #REF!
Name _3_2006_07_New_Total: #REF!
Name _4_2006_07SF: #REF!
Name _8_2006_07_New_SF: #REF!
Name AMTLU: [2]Names!$B$11:$I$69
Name AMTLU: [2]Names!$B$11:$I$69
Name AMTLU: [3]Names!$B$75:$I$83
Name AMTLU: [4]Names!$B$11:$I$69
Name AMTLU: [5]Names!$B$11:$I$69
Name AMTLU: Names!$B$75:$I$83
Name FTSELU: FTSE!$B$6:$P$53
Name FY2007Total: #REF!
Name FY2007Total: #REF!
Name New_Fall_2008: [6]New_Fall_2008!$A$1:$G$79
Name New_SF_05: #REF!
Name New_SF_05: #REF!
Name New_Total_2005: #REF!
Name New_Total_2005: #REF!
Name New05_06: #REF!
Name New05_06: #REF!
Name New0506SF: #REF!
Name NewSF06: #REF!
Name NewTotal: #REF!
Name SCHRPT2: #REF!
Name SCHRPT2: #REF!

Sheet Index
B1: Research Expenditures | C1: Links to Institution Tabs
B2: FY 2010 - Year Ended August 31, 2010 | D2: Accountability
D3: Research
D4: Data
H5: For Insitution Specific Questions, Please Contact the Institution Point of Contact
B6: HRI Institutions - Summary | D6: Click Here | H6: Institution Point of Contact for Sources & Uses Package
H7: Name | I7: Phone Number | J7: Email
B10: The University of Texas Southwestern Medical Center at Dallas | D10: Click Here
B11: The University of Texas Medical Branch at Galveston | D11: Click Here
B12: The University of Texas Health Science Center at Houston | D12: Click Here
B13: The University of Texas Health Science Center at San Antonio | D13: Click Here
B14: The University of Texas M.D. Anderson Cancer Center | D14: Click Here
B15: The University of Texas Health Center at Tyler | D15: Click Here
B16: Texas A&M University System Health Science Center | D16: Click Here
B17: University of North Texas Health Science Center at Fort Worth | D17: Click Here
B18: Texas Tech University Health Sciences Center | D18: Click Here
B20: Input Schedules
B21: FTSE & FTFE
B22: Names Schedule
B23: Template Input Schedule
B25: Output Schedules
B26: Almanac
B27: Accountability - HRI_IE_Research

Sheet Almanac
F1: Health-Related Institutions | K1: Return to Index
F2: FY 2010 Summary of Research Expenditures Data to Almanac Publication
A4: Note: Copy and past Column E values to S&U Almanac Tab. Do not send separately.
A5: Almanac Order | B5: FICE Code | C5: Year | D5: Institution | E5: Total Research Expenditures As Deetermined by Research Survey
A6: 1 | B6: 000089 | C6: FY 10 | D6: Texas A&M HSC | E6: =TAMHSC!$L$17 -> 78170881
A7: 2 | B7: 000412 | C7: =C6 -> FY 10 | D7: Texas Tech HSC | E7: =TTUHSC!$L$17 -> 50888460
A8: 3 | B8: 000130 | C8: =C7 -> FY 10 | D8: U. North Texas HSC | E8: =UNTHSC!$L$17 -> 39854879
A9: 4 | B9: 104952 | C9: =C8 -> FY 10 | D9: UT Galveston Medical Branch | E9: =MBG!$L$17 -> 156825004
A10: 5 | B10: 000404 | C10: =C9 -> FY 10 | D10: UT Health Center Tyler | E10: =THC!$L$17 -> 14378132
A11: 6 | B11: 011618 | C11: =C10 -> FY 10 | D11: UT Houston Health Science Center | E11: =HSH!$L$17 -> 240772552
A12: 7 | B12: 025554 | C12: =C11 -> FY 10 | D12: UT M. D. Anderson | E12: =MDA!$L$17 -> 547034744
A13: 8 | B13: 000040 | C13: =C12 -> FY 10 | D13: UT San Antonio HSC | E13: =HSSA!$L$17 -> 185229018
A14: 9 | B14: 000030 | C14: =C13 -> FY 10 | D14: UT Southwestern Med. | E14: =SWM!$L$17 -> 395314936
D15: Total | E15: =SUM(E6:E14) -> 1708468606
D16: =COUNTA(D6:D14) -> 9
D18: 9 Ok
E19: =IF(E15<>Summary!L98,"Error","Balanced") -> Balanced

Sheet HRI_IE_Research
G1: Academic Institutions | N1: Return to Index
G2: FY 2010 Accountability Data From Sources & Uses Reports To HRI_Research
A3: Purpose: This tab is used for input to the Accountability System | G3: November 15, 2012
A5: Data to HRI_Research | F5: FICE
E6: 2010 | F6: Code
F7: Order Used | R7: Institution Point of Contact for Sources & Uses
A8: S & U Order | D8: Institution Name | E8: Load Year | F8: FICE Code | G8: Total of Federal & Private | H8: Expenditures Per Tenure/Tenure Track FTE | I8: Federal & Private As a % of St. Approp. | J8: Federal | K8: State | L8: Private | M8: Institutional | N8: Total Research Expenditures | R8: Name | S8: Phone Number | T8: Email
A9: HRI_Research Columns | E9: A | F9: B | G9: C | H9: D | I9: E | J9: F | K9: G | L9: H | M9: I | N9: J | O9: K | P9: L | Q9: M
A10: HRI_Research Data Labels | E10: Load_Year | F10: FICE | G10: Expenditures | H10: ExpendPerFTE | I10: Eres_StApprop | J10: TResearch_Fed | K10: TResearch_State | L10: TResearch_Pri | M10: TResearch_Inst | N10: TResearch_Total | O10: Patents | P10: PatentApply | Q10: PatentIssue
A11: 390 | D11: UT Southwestern Med. | E11: =$E$6 -> 2010 | F11: 30 | G11: =J11+L11 -> 326768776 | H11: =SWM!$O$44 -> 905578 | I11: =SWM!$O$42 -> 186.3 | J11: =SWM!$F$41 -> 232026985 | K11: =SWM!$G$41+SWM!$H$41 -> 49817136 | L11: =SWM!$J$41+SWM!$K$41 -> 94741791 | M11: =SWM!$I$41 -> 18729024 | N11: =SWM!$L$17 -> 395314936
A12: 420 | D12: UT San Antonio HSC | E12: =$E$6 -> 2010 | F12: 40 | G12: =J12+L12 -> 157403572 | H12: =HSSA!$O$44 -> 476980521 | I12: =HSSA!$O$42 -> 235.5 | J12: =HSSA!$F$41 -> 121723410 | K12: =HSSA!$G$41+HSSA!$H$41 -> 6949370 | L12: =HSSA!$J$41+HSSA!$K$41 -> 35680162 | M12: =HSSA!$I$41 -> 20876076 | N12: =HSSA!$L$17 -> 185229018
A13: 450 | D13: Texas A&M HSC | E13: =$E$6 -> 2010 | F13: 89 | G13: =J13+L13 -> 39619168 | H13: =TAMHSC!$O$44 -> 1760852 | I13: =TAMHSC!$O$42 -> 21.39 | J13: =TAMHSC!$F$41 -> 33511244 | K13: =TAMHSC!$G$41+TAMHSC!$H$41 -> 11348288 | L13: =TAMHSC!$J$41+TAMHSC!$K$41 -> 6107924 | M13: =TAMHSC!$I$41 -> 27203425 | N13: =TAMHSC!$L$17 -> 78170881
A14: 460 | D14: U. North Texas HSC | E14: =$E$6 -> 2010 | F14: 130 | G14: =J14+L14 -> 29666539 | H14: =UNTHSC!$O$44 -> 725343 | I14: =UNTHSC!$O$42 -> 16.47 | J14: =UNTHSC!$F$41 -> 25935870 | K14: =UNTHSC!$G$41+UNTHSC!$H$41 -> 1316900 | L14: =UNTHSC!$J$41+UNTHSC!$K$41 -> 3730669 | M14: =UNTHSC!$I$41 -> 8871440 | N14: =UNTHSC!$L$17 -> 39854879
A15: 440 | D15: UT Health Center Tyler | E15: =$E$6 -> 2010 | F15: 404 | G15: =J15+L15 -> 8798651 | H15: =THC!$O$44 -> N/A | I15: =THC!$O$42 -> 4.54 | J15: =THC!$F$41 -> 7250324 | K15: =THC!$G$41+THC!$H$41 -> 2339810 | L15: =THC!$J$41+THC!$K$41 -> 1548327 | M15: =THC!$I$41 -> 3239671 | N15: =THC!$L$17 -> 14378132
A16: 470 | D16: Texas Tech HSC | E16: =$E$6 -> 2010 | F16: 412 | G16: =J16+L16 -> 16905019 | H16: =TTUHSC!$O$44 -> 211313 | I16: =TTUHSC!$O$42 -> 3.96 | J16: =TTUHSC!$F$41 -> 12950246 | K16: =TTUHSC!$G$41+TTUHSC!$H$41 -> 29208029 | L16: =TTUHSC!$J$41+TTUHSC!$K$41 -> 3954773 | M16: =TTUHSC!$I$41 -> 4775412 | N16: =TTUHSC!$L$17 -> 50888460
A17: 410 | D17: UT Houston Health Science Center | E17: =$E$6 -> 2010 | F17: 11618 | G17: =J17+L17 -> 185676139 | H17: =HSH!$O$44 -> 676687 | I17: =HSH!$O$42 -> 158.08 | J17: =HSH!$F$41 -> 150323653 | K17: =HSH!$G$41+HSH!$H$41 -> 43517011 | L17: =HSH!$J$41+HSH!$K$41 -> 35352486 | M17: =HSH!$I$41 -> 11579402 | N17: =HSH!$L$17 -> 240772552
A18: 430 | D18: UT M. D. Anderson | E18: =$E$6 -> 2010 | F18: 25554 | G18: =J18+L18 -> 339032775 | H18: =MDA!$O$44 -> 832595 | I18: =MDA!$O$42 -> 769.99 | J18: =MDA!$F$41 -> 206664447 | K18: =MDA!$G$41+MDA!$H$41 -> 176805729 | L18: =MDA!$J$41+MDA!$K$41 -> 132368328 | M18: =MDA!$I$41 -> 31196240 | N18: =MDA!$L$17 -> 547034744
A19: 400 | D19: UT Galveston Medical Branch | E19: =$E$6 -> 2010 | F19: 104952 | G19: =J19+L19 -> 147318206 | H19: =MBG!$O$44 -> 449772 | I19: =MBG!$O$42 -> 81.1 | J19: =MBG!$F$41 -> 128839602 | K19: =MBG!$G$41+MBG!$H$41 -> 1674687 | L19: =MBG!$J$41+MBG!$K$41 -> 18478604 | M19: =MBG!$I$41 -> 7832111 | N19: =MBG!$L$17 -> 156825004
D20: Statewide Total | E20: =$E$6 -> 2010 | F20: 445566 | G20: =J20+L20 -> 1251188845 | H20: =Summary!$O$341 -> 826576 | I20: =Summary!$O$330 -> 79.6 | J20: =SUM(J11:J19) -> 919225781 | K20: =SUM(K11:K19) -> 322976960 | L20: =SUM(L11:L19) -> 331963064 | M20: =SUM(M11:M19) -> 134302801 | N20: =SUM(N11:N19) -> 1708468606
E21: =COUNTA(E11:E19) -> 9
B22: Note: Accountability Data excludes all Auxiliary Revenue & Expenditures.
B23: Accountability Data excludes all Public Service Expenditures.
J32: =IF(J20<>Summary!$F$320,"Error","Balanced") -> Balanced | K32: =IF(K20<>(Summary!$G$320+Summary!$H$320),"Error","Balanced") -> Balanced | L32: =IF(L20<>(Summary!$J$320+Summary!$K$320),"Error","Balanced") -> Balanced | M32: =IF(M20<>Summary!$I$320,"Error","Balanced") -> Balanced | N32: =IF(N20<>Summary!$L$320,"Error","Balanced") -> Balanced
G38: 1251188845 | J38: 919225781 | K38: 322976960 | L38: 331963064 | M38: 134302801 | N38: 1708468606
G40: =G38-G20 -> 0 | N40: =N38-N20 -> 0
D42: 2010 Hash Totals | F42: =SUM(F11:F20) -> 588795 | G42: =SUM(G11:G20) -> 2502377690 | H42: =SUM(H11:H20) -> 483369237 | I42: =SUM(I11:I20) -> 1556.93 | J42: =SUM(J11:J20) -> 1838451562 | K42: =SUM(K11:K20) -> 645953920 | L42: =SUM(L11:L20) -> 663926128 | M42: =SUM(M11:M20) -> 268605602 | N42: =SUM(N11:N20) -> 3416937212 | P42: =SUM(F42:O42) -> 9.8202117e+09

Sheet Accountability
E1: Health-Related Institutions | I1: Return to Index
E2: FY 2010 Summary of Research Expenditures By Source to Accountability System
E3: August 17, 2011
A5: Note: Copy and past Columns D,E,F,&G values to S&U Accountability Tab. Do not send separately.
A6: FICE Code | B6: Year | C6: Institution | D6: Total Research Expenditures | E6: Federal | F6: State | G6: Private | H6: Institutional | I6: Check
A7: 000030 | B7: FY 10 | C7: UT Southwestern Med. | D7: =SWM!$L$17 -> 395314936 | E7: =SWM!$F$41 -> 232026985 | F7: =SWM!$G$41+SWM!$H$41 -> 49817136 | G7: =SWM!$J$41+SWM!$K$41 -> 94741791 | H7: =SWM!$I$41 -> 18729024 | I7: =IF(SUM(E7:H7)<>D7,"Error", "Balanced") -> Balanced
A8: 000040 | B8: =B7 -> FY 10 | C8: UT San Antonio HSC | D8: =HSSA!$L$17 -> 185229018 | E8: =HSSA!$F$41 -> 121723410 | F8: =HSSA!$G$41+HSSA!$H$41 -> 6949370 | G8: =HSSA!$J$41+HSSA!$K$41 -> 35680162 | H8: =HSSA!$I$41 -> 20876076 | I8: =IF(SUM(E8:H8)<>D8,"Error", "Balanced") -> Balanced
A9: 000089 | B9: =B8 -> FY 10 | C9: Texas A&M HSC | D9: =TAMHSC!$L$17 -> 78170881 | E9: =TAMHSC!$F$41 -> 33511244 | F9: =TAMHSC!$G$41+TAMHSC!$H$41 -> 11348288 | G9: =TAMHSC!$J$41+TAMHSC!$K$41 -> 6107924 | H9: =TAMHSC!$I$41 -> 27203425 | I9: =IF(SUM(E9:H9)<>D9,"Error", "Balanced") -> Balanced
A10: 000130 | B10: =B9 -> FY 10 | C10: U. North Texas HSC | D10: =UNTHSC!$L$17 -> 39854879 | E10: =UNTHSC!$F$41 -> 25935870 | F10: =UNTHSC!$G$41+UNTHSC!$H$41 -> 1316900 | G10: =UNTHSC!$J$41+UNTHSC!$K$41 -> 3730669 | H10: =UNTHSC!$I$41 -> 8871440 | I10: =IF(SUM(E10:H10)<>D10,"Error", "Balanced") -> Balanced
A11: 000404 | B11: =B10 -> FY 10 | C11: UT Health Center Tyler | D11: =THC!$L$17 -> 14378132 | E11: =THC!$F$41 -> 7250324 | F11: =THC!$G$41+THC!$H$41 -> 2339810 | G11: =THC!$J$41+THC!$K$41 -> 1548327 | H11: =THC!$I$41 -> 3239671 | I11: =IF(SUM(E11:H11)<>D11,"Error", "Balanced") -> Balanced
A12: 000412 | B12: =B11 -> FY 10 | C12: Texas Tech HSC | D12: =TTUHSC!$L$17 -> 50888460 | E12: =TTUHSC!$F$41 -> 12950246 | F12: =TTUHSC!$G$41+TTUHSC!$H$41 -> 29208029 | G12: =TTUHSC!$J$41+TTUHSC!$K$41 -> 3954773 | H12: =TTUHSC!$I$41 -> 4775412 | I12: =IF(SUM(E12:H12)<>D12,"Error", "Balanced") -> Balanced
A13: 011618 | B13: =B12 -> FY 10 | C13: UT Houston Health Science Center | D13: =HSH!$L$17 -> 240772552 | E13: =HSH!$F$41 -> 150323653 | F13: =HSH!$G$41+HSH!$H$41 -> 43517011 | G13: =HSH!$J$41+HSH!$K$41 -> 35352486 | H13: =HSH!$I$41 -> 11579402 | I13: =IF(SUM(E13:H13)<>D13,"Error", "Balanced") -> Balanced
A14: 025554 | B14: =B13 -> FY 10 | C14: UT M. D. Anderson | D14: =MDA!$L$17 -> 547034744 | E14: =MDA!$F$41 -> 206664447 | F14: =MDA!$G$41+MDA!$H$41 -> 176805729 | G14: =MDA!$J$41+MDA!$K$41 -> 132368328 | H14: =MDA!$I$41 -> 31196240 | I14: =IF(SUM(E14:H14)<>D14,"Error", "Balanced") -> Balanced
A15: 104952 | B15: =B14 -> FY 10 | C15: UT Galveston Medical Branch | D15: =MBG!$L$17 -> 156825004 | E15: =MBG!$F$41 -> 128839602 | F15: =MBG!$G$41+MBG!$H$41 -> 1674687 | G15: =MBG!$J$41+MBG!$K$41 -> 18478604 | H15: =MBG!$I$41 -> 7832111 | I15: =IF(SUM(E15:H15)<>D15,"Error", "Balanced") -> Balanced
C16: Total | D16: =SUM(D7:D15) -> 1708468606 | E16: =SUM(E7:E15) -> 919225781 | F16: =SUM(F7:F15) -> 322976960 | G16: =SUM(G7:G15) -> 331963064 | H16: =SUM(H7:H15) -> 134302801 | I16: =IF(SUM(E16:H16)<>D16,"Error", "Balanced") -> Balanced
C17: =COUNTA(C7:C15) -> 9
C19: 9 Ok
D21: =IF(D16<>Summary!L98,"Error","Balanced") -> Balanced | E21: =IF(E16<>Summary!F320,"Error","Balanced") -> Balanced | F21: =IF(F16<>Summary!G320+Summary!H320,"Error","Balanced") -> Balanced | G21: =IF(G16<>Summary!J320+Summary!K320,"Error","Balanced") -> Balanced | H21: =IF(H16<>Summary!I320,"Error","Balanced") -> Balanced

Sheet List
D1: Health-Related Institutions | H1: Return to Index
D2: FY 2010 Summary of Research Expenditures
D3: December 21, 2011
A5: Institution | B5: Research Expenditures Per SRECNA | C5: R & D Not Meeting the Definition of the Research Exp. Survey | D5: Indirect Costs Associated w/ R & D | E5: Capital Outlay for Research | F5: Institution's Research Foundation Expenditures for R & D | G5: Pass Throughts From TX Eng. Exp. Station | H5: Total Research Expenditures As Deetermined by Research Survey
A6: =SWM!$B$1 -> The University of Texas Southwestern Medical Center at Dallas | B6: =SWM!$K$10 -> 308606969 | C6: =SWM!$K$9*-1 -> 0 | D6: =SWM!$L$13 -> 75968647 | E6: =SWM!$L$14 -> 10739320 | F6: =SWM!$L$15 -> 0 | G6: =SWM!$L$16 -> 0 | H6: =SUM(B6:G6) -> 395314936
A7: =MBG!$B$1 -> The University of Texas Medical Branch at Galveston | B7: =MBG!$K$10 -> 116760151 | C7: =MBG!$K$9*-1 -> 0 | D7: =MBG!$L$13 -> 35455128 | E7: =MBG!$L$14 -> 4609725 | F7: =MBG!$L$15 -> 0 | G7: =MBG!$L$16 -> 0 | H7: =SUM(B7:G7) -> 156825004
A8: =HSH!$B$1 -> The University of Texas Health Science Center at Houston | B8: =HSH!$K$10 -> 194367928 | C8: =HSH!$K$9*-1 -> 0 | D8: =HSH!$L$13 -> 42189454 | E8: =HSH!$L$14 -> 4215170 | F8: =HSH!$L$15 -> 0 | G8: =HSH!$L$16 -> 0 | H8: =SUM(B8:G8) -> 240772552
A9: =HSSA!$B$1 -> The University of Texas Health Science Center at San Antonio | B9: =HSSA!$K$10 -> 145165310 | C9: =HSSA!$K$9*-1 -> 0 | D9: =HSSA!$L$13 -> 33528292 | E9: =HSSA!$L$14 -> 6535416 | F9: =HSSA!$L$15 -> 0 | G9: =HSSA!$L$16 -> 0 | H9: =SUM(B9:G9) -> 185229018
A10: =MDA!$B$1 -> The University of Texas M.D. Anderson Cancer Center | B10: =MDA!$K$10 -> 463104671 | C10: =MDA!$K$9*-1 -> 0 | D10: =MDA!$L$13 -> 75631023 | E10: =MDA!$L$14 -> 8299050 | F10: =MDA!$L$15 -> 0 | G10: =MDA!$L$16 -> 0 | H10: =SUM(B10:G10) -> 547034744
A11: =THC!$B$1 -> The University of Texas Health Center at Tyler | B11: =THC!$K$10 -> 12168890 | C11: =THC!$K$9*-1 -> 0 | D11: =THC!$L$13 -> 1844206 | E11: =THC!$L$14 -> 365036 | F11: =THC!$L$15 -> 0 | G11: =THC!$L$16 -> 0 | H11: =SUM(B11:G11) -> 14378132
A12: =TAMHSC!$B$1 -> Texas A&M University System Health Science Center | B12: =TAMHSC!$K$10 -> 39877051 | C12: =TAMHSC!$K$9*-1 -> -1645160 | D12: =TAMHSC!$L$13 -> 678676 | E12: =TAMHSC!$L$14 -> 1386271 | F12: =TAMHSC!$L$15 -> 37511984 | G12: =TAMHSC!$L$16 -> 362059 | H12: =SUM(B12:G12) -> 78170881
A13: =UNTHSC!$B$1 -> University of North Texas Health Science Center at Fort Worth | B13: =UNTHSC!$K$10 -> 33368122 | C13: =UNTHSC!$K$9*-1 -> 0 | D13: =UNTHSC!$L$13 -> 5567035 | E13: =UNTHSC!$L$14 -> 919722 | F13: =UNTHSC!$L$15 -> 0 | G13: =UNTHSC!$L$16 -> 0 | H13: =SUM(B13:G13) -> 39854879
A14: =TTUHSC!$B$1 -> Texas Tech University Health Sciences Center | B14: =TTUHSC!$K$10 -> 41854717 | C14: =TTUHSC!$K$9*-1 -> 0 | D14: =TTUHSC!$L$13 -> 3872809 | E14: =TTUHSC!$L$14 -> 5160934 | F14: =TTUHSC!$L$15 -> 0 | G14: =TTUHSC!$L$16 -> 0 | H14: =SUM(B14:G14) -> 50888460
A15: Total | B15: =SUM(B6:B14) -> 1355273809 | C15: =SUM(C6:C14) -> -1645160 | D15: =SUM(D6:D14) -> 274735270 | E15: =SUM(E6:E14) -> 42230644 | F15: =SUM(F6:F14) -> 37511984 | G15: =SUM(G6:G14) -> 362059 | H15: =SUM(H6:H14) -> 1708468606
A16: =COUNTA(A6:A14) -> 9
H18: =IF(H15<>Summary!L98,"Error","")
H20: Amounts for Formula Funding

Sheet Summary
B1: Summary of All University Institutions | N1: Return to Index | AA1: 12 | AB1: 13
B2: =Input!$B$5 -> For the Year Ended August 31, 2010
B3: =Input!$B$6 -> Source: FY 2010 Research Expenditure Survey
N4: Zoom % should be at 75%.
B6: =Input!$B$7 -> FY 2010
B7: Summary of R & D Expenditures | K7: Overall Total | L7: Defined For Survey
K8: =HSH!$K$8 -> 194367928 | L8: =HSH!$L$8 -> 194367928
K9: =HSSA!$K$8 -> 145165310 | L9: =HSSA!$L$8 -> 145165310
K10: =MBG!$K$8 -> 116760151 | L10: =MBG!$L$8 -> 116760151
K11: =MDA!$K$8 -> 463104671 | L11: =MDA!$L$8 -> 463104671
K12: =SWM!$K$8 -> 308606969 | L12: =SWM!$L$8 -> 308606969
K13: =TAMHSC!$K$8 -> 38231891 | L13: =TAMHSC!$L$8 -> 38231891
K14: =THC!$K$8 -> 12168890 | L14: =THC!$L$8 -> 12168890
K15: =TTUHSC!$K$8 -> 41854717 | L15: =TTUHSC!$L$8 -> 41854717
K16: =UNTHSC!$K$8 -> 33368122 | L16: =UNTHSC!$L$8 -> 33368122
B17: R & D Expenses as defined for the Research Expenditure Survey | K17: =SUM(K8:K16) -> 1353628649 | L17: =SUM(L8:L16) -> 1353628649 | AB17: =SUM(C17:L17) -> 2707257298
K18: =HSH!$K$9 -> 0
K19: =HSSA!$K$9 -> 0
K20: =MBG!$K$9 -> 0
K21: =MDA!$K$9 -> 0
K22: =SWM!$K$9 -> 0
K23: =TAMHSC!$K$9 -> 1645160
K24: =THC!$K$9 -> 0
K25: =TTUHSC!$K$9 -> 0
K26: =UNTHSC!$K$9 -> 0
B27: R & D Expenses not meeting the narrow definition of R & D used in the Research Expenditures Survey | K27: =SUM(K18:K26) -> 1645160 | AB27: =SUM(C27:L27) -> 1645160
K28: =HSH!$K$10 -> 194367928
K29: =HSSA!$K$10 -> 145165310
K30: =MBG!$K$10 -> 116760151
K31: =MDA!$K$10 -> 463104671
K32: =SWM!$K$10 -> 308606969
K33: =TAMHSC!$K$10 -> 39877051
K34: =THC!$K$10 -> 12168890
K35: =TTUHSC!$K$10 -> 41854717
K36: =UNTHSC!$K$10 -> 33368122
B37: Total Expenses for R & D as reported on the Statement of Revenues, Expenses and Changes in Net Assets | K37: =SUM(K28:K36) -> 1355273809
AB38: =SUM(C37:L37) -> 1355273809
K39: =HSH!$K$12 -> 0
K40: =HSSA!$K$12 -> 0
K41: =MBG!$K$12 -> 0
...

Sheet SWM
B1: The University of Texas Southwestern Medical Center at Dallas | N1: Return to Index | AA1: 12 | AB1: 13
B2: =Input!$B$5 -> For the Year Ended August 31, 2010
B3: =Input!$B$6 -> Source: FY 2010 Research Expenditure Survey
N4: Zoom % should be at 75%.
B6: =Input!$B$7 -> FY 2010
B7: Summary of R & D Expenditures | K7: Overall Total | L7: Defined For Survey
B8: R & D Expenses as defined for the Research Expenditure Survey | K8: =L8 -> 308606969 | L8: =Input!$H$10 -> 308606969 | AB8: =SUM(C8:L8) -> 617213938
B9: R & D Expenses not meeting the narrow definition of R & D used in the Research Expenditures Survey | K9: =Input!$F$10 -> 0 | AB9: =SUM(C9:L9) -> 0
B10: Total Expenses for R & D as reported on the Statement of Revenues, Expenses and Changes in Net Assets | H10: =IF(O10<>0,"Out of Balance with SRECNA","") | K10: =SUM(K8:K9) -> 308606969
AB11: =SUM(C10:L10) -> 308606969
B12: Other Research-related Equipment Expenditures (noncurrent fund expenditures, etc. - do not include R & D plant expenses or construction) | K12: =Input!$G$10 -> 806596 | AB12: =SUM(C11:L11) -> 0
B13: Indirect Costs associated with Expenses for R & D as defined for this survey | K13: =L13 -> 75968647 | L13: =Input!$I$10 -> 75968647 | AB13: =SUM(C13:L13) -> 151937294
B14: Capital Outlay for research equipment (do not include R & D plant expenses or construction) | K14: =L14 -> 10739320 | L14: =Input!$J$10 -> 10739320 | AB14: =SUM(C14:L14) -> 21478640
B15: Expenditures for conduct of R & D made by institution's research foundation or 501© corporation on behalf of the institution and not report in institution AFR, including indirect costs not reported above | K15: =L15 -> 0 | L15: =Input!$K$10 -> 0 | AB15: =SUM(C15:L15) -> 0
B16: Pass-throughs from Texas Engineering Experiment Station not reported in R & D Expenditures as defined for the Research Expenditure Survey | K16: =L16 -> 0 | L16: =Input!$L$10 -> 0 | AB16: =SUM(C16:L16) -> 0
B17: Total R & D Expenditures | K17: =SUM(K10:K16) -> 396121532 | L17: =SUM(L8:L16) -> 395314936 | S17: =L17-INT(L17) -> 0 | T17: 0 | U17: 0 | V17: 0 | AB17: =#REF!+#REF!+#REF!+#REF! -> #REF!
F18: =IF(OR(S17<>0,S41<>0,S54<>0),"Do not Enter Cents - Whole Dollars Only","")
B19: R & D Expenditures By Funding Source | F19: Federal | G19: State Appropriations | H19: State Contracts/Grants | I19: Institution Resources | J19: Private For-Profit | K19: Private Non-Profit | L19: Total
B20: Agricultural Sciences | F20: =Input!$M$10 -> 0 | G20: =Input!$N$10 -> 0 | H20: =Input!$O$10 -> 0 | I20: =Input!$P$10 -> 0 | J20: =Input!$Q$10 -> 0 | K20: =Input!$R$10 -> 0 | L20: =SUM(F20:K20) -> 0 | AB20: =SUM(C20:L20) -> 0
B21: Biological and Other Life Sciences | F21: =Input!$S$10 -> 106280934 | G21: =Input!$T$10 -> 18291963 | H21: =Input!$U$10 -> 1441732 | I21: =Input!$V$10 -> 4367700 | J21: =Input!$W$10 -> 2442520 | K21: =Input!$X$10 -> 32004547 | L21: =SUM(F21:K21) -> 164829396 | AB21: =SUM(C21:L21) -> 329658792
B22: Computer Science | F22: =Input!$Y$10 -> 0 | G22: =Input!$Z$10 -> 0 | H22: =Input!$AA$10 -> 0 | I22: =Input!$AB$10 -> 0 | J22: =Input!$AC$10 -> 0 | K22: =Input!$AD$10 -> 0 | L22: =SUM(F22:K22) -> 0 | AB22: =SUM(C22:L22) -> 0
B23: Engineering | F23: =Input!$AE$10 -> 0 | G23: =Input!$AF$10 -> 0 | H23: =Input!$AG$10 -> 0 | I23: =Input!$AH$10 -> 0 | J23: =Input!$AI$10 -> 0 | K23: =Input!$AJ$10 -> 0 | L23: =SUM(F23:K23) -> 0 | AB23: =SUM(C23:L23) -> 0
B24: Environmental Sciences | F24: =Input!$AK$10 -> 0 | G24: =Input!$AL$10 -> 0 | H24: =Input!$AM$10 -> 0 | I24: =Input!$AN$10 -> 0 | J24: =Input!$AO$10 -> 0 | K24: =Input!$AP$10 -> 0 | L24: =SUM(F24:K24) -> 0 | AB24: =SUM(C24:L24) -> 0
B25: Mathematical Sciences | F25: =Input!$AQ$10 -> 0 | G25: =Input!$AR$10 -> 0 | H25: =Input!$AS$10 -> 0 | I25: =Input!$AT$10 -> 0 | J25: =Input!$AU$10 -> 0 | K25: =Input!$AV$10 -> 0 | L25: =SUM(F25:K25) -> 0 | O25: Difference | AB25: =SUM(C25:L25) -> 0
B26: Medical Sciences | F26: =Input!$AW$10 -> 125591611 | G26: =Input!$AX$10 -> 24005050 | H26: =Input!$AY$10 -> 2302310 | I26: =Input!$AZ$10 -> 12131179 | J26: =Input!$BA$10 -> 17165769 | K26: =Input!$BB$10 -> 39115472 | L26: =SUM(F26:K26) -> 220311391 | N26: =IF(O26<>0,"Out of Balance","Balanced") -> Balanced | O26: =L17-L41 -> 0
B27: Physical Sciences | F27: =Input!$BC$10 -> 0 | G27: =Input!$BD$10 -> 0 | H27: =Input!$BE$10 -> 0 | I27: =Input!$BF$10 -> 0 | J27: =Input!$BG$10 -> 0 | K27: =Input!$BH$10 -> 0 | L27: =SUM(F27:K27) -> 0
B28: Psychology | F28: =Input!$BI$10 -> 0 | G28: =Input!$BJ$10 -> 0 | H28: =Input!$BK$10 -> 0 | I28: =Input!$BL$10 -> 0 | J28: =Input!$BM$10 -> 0 | K28: =Input!$BN$10 -> 0 | L28: =SUM(F28:K28) -> 0
B29: Social Sciences | F29: =Input!$BO$10 -> 0 | G29: =Input!$BP$10 -> 0 | H29: =Input!$BQ$10 -> 0 | I29: =Input!$BR$10 -> 0 | J29: =Input!$BS$10 -> 0 | K29: =Input!$BT$10 -> 0 | L29: =SUM(F29:K29) -> 0
B30: Other Sciences not classified above | F30: =Input!$BU$10 -> 154440 | G30: =Input!$BV$10 -> 3548064 | H30: =Input!$BW$10 -> 228017 | I30: =Input!$BX$10 -> 2230145 | J30: =Input!$BY$10 -> 7569 | K30: =Input!$BZ$10 -> 4005914 | L30: =SUM(F30:K30) -> 10174149
B31: Arts and Humanities | F31: =Input!$CA$10 -> 0 | G31: =Input!$CB$10 -> 0 | H31: =Input!$CC$10 -> 0 | I31: =Input!$CD$10 -> 0 | J31: =Input!$CE$10 -> 0 | K31: =Input!$CF$10 -> 0 | L31: =SUM(F31:K31) -> 0
B32: Business Administration | F32: =Input!$CG$10 -> 0 | G32: =Input!$CH$10 -> 0 | H32: =Input!$CI$10 -> 0 | I32: =Input!$CJ$10 -> 0 | J32: =Input!$CK$10 -> 0 | K32: =Input!$CL$10 -> 0 | L32: =SUM(F32:K32) -> 0
B33: Education | F33: =Input!$CM$10 -> 0 | G33: =Input!$CN$10 -> 0 | H33: =Input!$CO$10 -> 0 | I33: =Input!$CP$10 -> 0 | J33: =Input!$CQ$10 -> 0 | K33: =Input!$CR$10 -> 0 | L33: =SUM(F33:K33) -> 0
B34: Law | F34: =Input!$CS$10 -> 0 | G34: =Input!$CT$10 -> 0 | H34: =Input!$CU$10 -> 0 | I34: =Input!$CV$10 -> 0 | J34: =Input!$CW$10 -> 0 | K34: =Input!$CX$10 -> 0 | L34: =SUM(F34:K34) -> 0
B35: Field of Study - Future Use 1 | F35: =Input!$CY$10 -> 0 | G35: =Input!$CZ$10 -> 0 | H35: =Input!$DA$10 -> 0 | I35: =Input!$DB$10 -> 0 | J35: =Input!$DC$10 -> 0 | K35: =Input!$DD$10 -> 0 | L35: =SUM(F35:K35) -> 0
B36: Field of Study - Future Use 2 | F36: =Input!$DE$10 -> 0 | G36: =Input!$DF$10 -> 0 | H36: =Input!$DG$10 -> 0 | I36: =Input!$DH$10 -> 0 | J36: =Input!$DI$10 -> 0 | K36: =Input!$DJ$10 -> 0 | L36: =SUM(F36:K36) -> 0
B37: Field of Study - Future Use 3 | F37: =Input!$DK$10 -> 0 | G37: =Input!$DL$10 -> 0 | H37: =Input!$DM$10 -> 0 | I37: =Input!$DN$10 -> 0 | J37: =Input!$DO$10 -> 0 | K37: =Input!$DP$10 -> 0 | L37: =SUM(F37:K37) -> 0
B38: Field of Study - Future Use 4 | F38: =Input!$DQ$10 -> 0 | G38: =Input!$DR$10 -> 0 | H38: =Input!$DS$10 -> 0 | I38: =Input!$DT$10 -> 0 | J38: =Input!$DU$10 -> 0 | K38: =Input!$DV$10 -> 0 | L38: =SUM(F38:K38) -> 0
B39: Field of Study - Future Use 5 | F39: =Input!$DW$10 -> 0 | G39: =Input!$DX$10 -> 0 | H39: =Input!$DY$10 -> 0 | I39: =Input!$DZ$10 -> 0 | J39: =Input!$EA$10 -> 0 | K39: =Input!$EB$10 -> 0 | L39: =SUM(F39:K39) -> 0
B40: Other Non-Science Activities | F40: =Input!$EC$10 -> 0 | G40: =Input!$ED$10 -> 0 | H40: =Input!$EE$10 -> 0 | I40: =Input!$EF$10 -> 0 | J40: =Input!$EG$10 -> 0 | K40: =Input!$EH$10 -> 0 | L40: =SUM(F40:K40) -> 0 | O40: To Accountability | P40: Sources & Uses | AB40: =SUM(C40:L40) -> 0
B41: Total R & D Expenditures By Funding Source | F41: =SUM(F20:F40) -> 232026985 | G41: =SUM(G20:G40) -> 45845077 | H41: =SUM(H20:H40) -> 3972059 | I41: =SUM(I20:I40) -> 18729024 | J41: =SUM(J20:J40) -> 19615858 | K41: =SUM(K20:K40) -> 75125933 | L41: =SUM(L20:L40) -> 395314936 | O41: ResPercGenRev | P41: State Appropriations | S41: =L41-INT(L41) -> 0 | AB41: =SUM(AB20:AB40) -> 329658792
...

Sheet MBG
B1: The University of Texas Medical Branch at Galveston | N1: Return to Index | AA1: 12 | AB1: 13
B2: =Input!$B$5 -> For the Year Ended August 31, 2010
B3: =Input!$B$6 -> Source: FY 2010 Research Expenditure Survey
N4: Zoom % should be at 75%.
B6: =Input!$B$7 -> FY 2010
B7: Summary of R & D Expenditures | K7: Overall Total | L7: Defined For Survey
B8: R & D Expenses as defined for the Research Expenditure Survey | K8: =L8 -> 116760151 | L8: =Input!$H$11 -> 116760151 | AB8: =SUM(C8:L8) -> 233520302
B9: R & D Expenses not meeting the narrow definition of R & D used in the Research Expenditures Survey | K9: =Input!$F$11 -> 0 | AB9: =SUM(C9:L9) -> 0
B10: Total Expenses for R & D as reported on the Statement of Revenues, Expenses and Changes in Net Assets | H10: =IF(O10<>0,"Out of Balance with SRECNA","") | K10: =SUM(K8:K9) -> 116760151
AB11: =SUM(C10:L10) -> 116760151
B12: Other Research-related Equipment Expenditures (noncurrent fund expenditures, etc. - do not include R & D plant expenses or construction) | K12: =Input!$G$11 -> 0 | AB12: =SUM(C11:L11) -> 0
B13: Indirect Costs associated with Expenses for R & D as defined for this survey | K13: =L13 -> 35455128 | L13: =Input!$I$11 -> 35455128 | AB13: =SUM(C13:L13) -> 70910256
B14: Capital Outlay for research equipment (do not include R & D plant expenses or construction) | K14: =L14 -> 4609725 | L14: =Input!$J$11 -> 4609725 | AB14: =SUM(C14:L14) -> 9219450
B15: Expenditures for conduct of R & D made by institution's research foundation or 501© corporation on behalf of the institution and not report in institution AFR, including indirect costs not reported above | K15: =L15 -> 0 | L15: =Input!$K$11 -> 0 | AB15: =SUM(C15:L15) -> 0
B16: Pass-throughs from Texas Engineering Experiment Station not reported in R & D Expenditures as defined for the Research Expenditure Survey | K16: =L16 -> 0 | L16: =Input!$L$11 -> 0 | AB16: =SUM(C16:L16) -> 0
B17: Total R & D Expenditures | K17: =SUM(K10:K16) -> 156825004 | L17: =SUM(L8:L16) -> 156825004 | S17: =L17-INT(L17) -> 0 | T17: 0 | U17: 0 | V17: 0 | AB17: =#REF!+#REF!+#REF!+#REF! -> #REF!
F18: =IF(OR(S17<>0,S41<>0,S54<>0),"Do not Enter Cents - Whole Dollars Only","")
B19: R & D Expenditures By Funding Source | F19: Federal | G19: State Appropriations | H19: State Contracts/Grants | I19: Institution Resources | J19: Private For-Profit | K19: Private Non-Profit | L19: Total
B20: Agricultural Sciences | F20: =Input!$M$11 -> 0 | G20: =Input!$N$11 -> 0 | H20: =Input!$O$11 -> 0 | I20: =Input!$P$11 -> 0 | J20: =Input!$Q$11 -> 0 | K20: =Input!$R$11 -> 0 | L20: =SUM(F20:K20) -> 0 | AB20: =SUM(C20:L20) -> 0
B21: Biological and Other Life Sciences | F21: =Input!$S$11 -> 51523589 | G21: =Input!$T$11 -> 318588 | H21: =Input!$U$11 -> 90752 | I21: =Input!$V$11 -> 4497868 | J21: =Input!$W$11 -> 1321290 | K21: =Input!$X$11 -> 5361267 | L21: =SUM(F21:K21) -> 63113354 | AB21: =SUM(C21:L21) -> 126226708
B22: Computer Science | F22: =Input!$Y$11 -> 0 | G22: =Input!$Z$11 -> 0 | H22: =Input!$AA$11 -> 0 | I22: =Input!$AB$11 -> 0 | J22: =Input!$AC$11 -> 0 | K22: =Input!$AD$11 -> 0 | L22: =SUM(F22:K22) -> 0 | AB22: =SUM(C22:L22) -> 0
B23: Engineering | F23: =Input!$AE$11 -> 886702 | G23: =Input!$AF$11 -> 398247 | H23: =Input!$AG$11 -> 0 | I23: =Input!$AH$11 -> 99878 | J23: =Input!$AI$11 -> 54945 | K23: =Input!$AJ$11 -> 1482 | L23: =SUM(F23:K23) -> 1441254 | AB23: =SUM(C23:L23) -> 2882508
B24: Environmental Sciences | F24: =Input!$AK$11 -> 0 | G24: =Input!$AL$11 -> 0 | H24: =Input!$AM$11 -> 0 | I24: =Input!$AN$11 -> 0 | J24: =Input!$AO$11 -> 0 | K24: =Input!$AP$11 -> 0 | L24: =SUM(F24:K24) -> 0 | AB24: =SUM(C24:L24) -> 0
B25: Mathematical Sciences | F25: =Input!$AQ$11 -> 0 | G25: =Input!$AR$11 -> 0 | H25: =Input!$AS$11 -> 0 | I25: =Input!$AT$11 -> 0 | J25: =Input!$AU$11 -> 0 | K25: =Input!$AV$11 -> 0 | L25: =SUM(F25:K25) -> 0 | O25: Difference | AB25: =SUM(C25:L25) -> 0
B26: Medical Sciences | F26: =Input!$AW$11 -> 76429311 | G26: =Input!$AX$11 -> 187413 | H26: =Input!$AY$11 -> 679687 | I26: =Input!$AZ$11 -> 3234365 | J26: =Input!$BA$11 -> 2288952 | K26: =Input!$BB$11 -> 9450668 | L26: =SUM(F26:K26) -> 92270396 | N26: =IF(O26<>0,"Out of Balance","Balanced") -> Balanced | O26: =L17-L41 -> 0
B27: Physical Sciences | F27: =Input!$BC$11 -> 0 | G27: =Input!$BD$11 -> 0 | H27: =Input!$BE$11 -> 0 | I27: =Input!$BF$11 -> 0 | J27: =Input!$BG$11 -> 0 | K27: =Input!$BH$11 -> 0 | L27: =SUM(F27:K27) -> 0
B28: Psychology | F28: =Input!$BI$11 -> 0 | G28: =Input!$BJ$11 -> 0 | H28: =Input!$BK$11 -> 0 | I28: =Input!$BL$11 -> 0 | J28: =Input!$BM$11 -> 0 | K28: =Input!$BN$11 -> 0 | L28: =SUM(F28:K28) -> 0
B29: Social Sciences | F29: =Input!$BO$11 -> 0 | G29: =Input!$BP$11 -> 0 | H29: =Input!$BQ$11 -> 0 | I29: =Input!$BR$11 -> 0 | J29: =Input!$BS$11 -> 0 | K29: =Input!$BT$11 -> 0 | L29: =SUM(F29:K29) -> 0
B30: Other Sciences not classified above | F30: =Input!$BU$11 -> 0 | G30: =Input!$BV$11 -> 0 | H30: =Input!$BW$11 -> 0 | I30: =Input!$BX$11 -> 0 | J30: =Input!$BY$11 -> 0 | K30: =Input!$BZ$11 -> 0 | L30: =SUM(F30:K30) -> 0
B31: Arts and Humanities | F31: =Input!$CA$11 -> 0 | G31: =Input!$CB$11 -> 0 | H31: =Input!$CC$11 -> 0 | I31: =Input!$CD$11 -> 0 | J31: =Input!$CE$11 -> 0 | K31: =Input!$CF$11 -> 0 | L31: =SUM(F31:K31) -> 0
B32: Business Administration | F32: =Input!$CG$11 -> 0 | G32: =Input!$CH$11 -> 0 | H32: =Input!$CI$11 -> 0 | I32: =Input!$CJ$11 -> 0 | J32: =Input!$CK$11 -> 0 | K32: =Input!$CL$11 -> 0 | L32: =SUM(F32:K32) -> 0
B33: Education | F33: =Input!$CM$11 -> 0 | G33: =Input!$CN$11 -> 0 | H33: =Input!$CO$11 -> 0 | I33: =Input!$CP$11 -> 0 | J33: =Input!$CQ$11 -> 0 | K33: =Input!$CR$11 -> 0 | L33: =SUM(F33:K33) -> 0
B34: Law | F34: =Input!$CS$11 -> 0 | G34: =Input!$CT$11 -> 0 | H34: =Input!$CU$11 -> 0 | I34: =Input!$CV$11 -> 0 | J34: =Input!$CW$11 -> 0 | K34: =Input!$CX$11 -> 0 | L34: =SUM(F34:K34) -> 0
B35: Field of Study - Future Use 1 | F35: =Input!$CY$11 -> 0 | G35: =Input!$CZ$11 -> 0 | H35: =Input!$DA$11 -> 0 | I35: =Input!$DB$11 -> 0 | J35: =Input!$DC$11 -> 0 | K35: =Input!$DD$11 -> 0 | L35: =SUM(F35:K35) -> 0
B36: Field of Study - Future Use 2 | F36: =Input!$DE$11 -> 0 | G36: =Input!$DF$11 -> 0 | H36: =Input!$DG$11 -> 0 | I36: =Input!$DH$11 -> 0 | J36: =Input!$DI$11 -> 0 | K36: =Input!$DJ$11 -> 0 | L36: =SUM(F36:K36) -> 0
B37: Field of Study - Future Use 3 | F37: =Input!$DK$11 -> 0 | G37: =Input!$DL$11 -> 0 | H37: =Input!$DM$11 -> 0 | I37: =Input!$DN$11 -> 0 | J37: =Input!$DO$11 -> 0 | K37: =Input!$DP$11 -> 0 | L37: =SUM(F37:K37) -> 0
B38: Field of Study - Future Use 4 | F38: =Input!$DQ$11 -> 0 | G38: =Input!$DR$11 -> 0 | H38: =Input!$DS$11 -> 0 | I38: =Input!$DT$11 -> 0 | J38: =Input!$DU$11 -> 0 | K38: =Input!$DV$11 -> 0 | L38: =SUM(F38:K38) -> 0
B39: Field of Study - Future Use 5 | F39: =Input!$DW$11 -> 0 | G39: =Input!$DX$11 -> 0 | H39: =Input!$DY$11 -> 0 | I39: =Input!$DZ$11 -> 0 | J39: =Input!$EA$11 -> 0 | K39: =Input!$EB$11 -> 0 | L39: =SUM(F39:K39) -> 0
B40: Other Non-Science Activities | F40: =Input!$EC$11 -> 0 | G40: =Input!$ED$11 -> 0 | H40: =Input!$EE$11 -> 0 | I40: =Input!$EF$11 -> 0 | J40: =Input!$EG$11 -> 0 | K40: =Input!$EH$11 -> 0 | L40: =SUM(F40:K40) -> 0 | O40: To Accountability | P40: Sources & Uses | AB40: =SUM(C40:L40) -> 0
B41: Total R & D Expenditures By Funding Source | F41: =SUM(F20:F40) -> 128839602 | G41: =SUM(G20:G40) -> 904248 | H41: =SUM(H20:H40) -> 770439 | I41: =SUM(I20:I40) -> 7832111 | J41: =SUM(J20:J40) -> 3665187 | K41: =SUM(K20:K40) -> 14813417 | L41: =SUM(L20:L40) -> 156825004 | O41: ResPercGenRev | P41: State Appropriations | S41: =L41-INT(L41) -> 0 | AB41: =SUM(AB20:AB40) -> 129109216
...

Sheet HSH
B1: The University of Texas Health Science Center at Houston | N1: Return to Index | AA1: 12 | AB1: 13
B2: =Input!$B$5 -> For the Year Ended August 31, 2010
B3: =Input!$B$6 -> Source: FY 2010 Research Expenditure Survey
N4: Zoom % should be at 75%.
B6: =Input!$B$7 -> FY 2010
B7: Summary of R & D Expenditures | K7: Overall Total | L7: Defined For Survey
B8: R & D Expenses as defined for the Research Expenditure Survey | K8: =L8 -> 194367928 | L8: =Input!$H$12 -> 194367928 | AB8: =SUM(C8:L8) -> 388735856
B9: R & D Expenses not meeting the narrow definition of R & D used in the Research Expenditures Survey | K9: =Input!$F$12 -> 0 | AB9: =SUM(C9:L9) -> 0
B10: Total Expenses for R & D as reported on the Statement of Revenues, Expenses and Changes in Net Assets | H10: =IF(O10<>0,"Out of Balance with SRECNA","") | K10: =SUM(K8:K9) -> 194367928
AB11: =SUM(C10:L10) -> 194367928
B12: Other Research-related Equipment Expenditures (noncurrent fund expenditures, etc. - do not include R & D plant expenses or construction) | K12: =Input!$G$12 -> 0 | AB12: =SUM(C11:L11) -> 0
B13: Indirect Costs associated with Expenses for R & D as defined for this survey | K13: =L13 -> 42189454 | L13: =Input!$I$12 -> 42189454 | AB13: =SUM(C13:L13) -> 84378908
B14: Capital Outlay for research equipment (do not include R & D plant expenses or construction) | K14: =L14 -> 4215170 | L14: =Input!$J$12 -> 4215170 | AB14: =SUM(C14:L14) -> 8430340
B15: Expenditures for conduct of R & D made by institution's research foundation or 501© corporation on behalf of the institution and not report in institution AFR, including indirect costs not reported above | K15: =L15 -> 0 | L15: =Input!$K$12 -> 0 | AB15: =SUM(C15:L15) -> 0
B16: Pass-throughs from Texas Engineering Experiment Station not reported in R & D Expenditures as defined for the Research Expenditure Survey | K16: =L16 -> 0 | L16: =Input!$L$12 -> 0 | AB16: =SUM(C16:L16) -> 0
B17: Total R & D Expenditures | K17: =SUM(K10:K16) -> 240772552 | L17: =SUM(L8:L16) -> 240772552 | S17: =L17-INT(L17) -> 0 | T17: 0 | U17: 0 | V17: 0 | AB17: =#REF!+#REF!+#REF!+#REF! -> #REF!
F18: =IF(OR(S17<>0,S41<>0,S54<>0),"Do not Enter Cents - Whole Dollars Only","")
B19: R & D Expenditures By Funding Source | F19: Federal | G19: State Appropriations | H19: State Contracts/Grants | I19: Institution Resources | J19: Private For-Profit | K19: Private Non-Profit | L19: Total
B20: Agricultural Sciences | F20: =Input!$M$12 -> 0 | G20: =Input!$N$12 -> 0 | H20: =Input!$O$12 -> 0 | I20: =Input!$P$12 -> 0 | J20: =Input!$Q$12 -> 0 | K20: =Input!$R$12 -> 0 | L20: =SUM(F20:K20) -> 0 | AB20: =SUM(C20:L20) -> 0
B21: Biological and Other Life Sciences | F21: =Input!$S$12 -> 35368893 | G21: =Input!$T$12 -> 1162935 | H21: =Input!$U$12 -> 388260 | I21: =Input!$V$12 -> 1126511 | J21: =Input!$W$12 -> 399375 | K21: =Input!$X$12 -> 2807980 | L21: =SUM(F21:K21) -> 41253954 | AB21: =SUM(C21:L21) -> 82507908
B22: Computer Science | F22: =Input!$Y$12 -> 0 | G22: =Input!$Z$12 -> 0 | H22: =Input!$AA$12 -> 0 | I22: =Input!$AB$12 -> 0 | J22: =Input!$AC$12 -> 0 | K22: =Input!$AD$12 -> 0 | L22: =SUM(F22:K22) -> 0 | AB22: =SUM(C22:L22) -> 0
B23: Engineering | F23: =Input!$AE$12 -> 0 | G23: =Input!$AF$12 -> 0 | H23: =Input!$AG$12 -> 0 | I23: =Input!$AH$12 -> 0 | J23: =Input!$AI$12 -> 0 | K23: =Input!$AJ$12 -> 0 | L23: =SUM(F23:K23) -> 0 | AB23: =SUM(C23:L23) -> 0
B24: Environmental Sciences | F24: =Input!$AK$12 -> 0 | G24: =Input!$AL$12 -> 0 | H24: =Input!$AM$12 -> 0 | I24: =Input!$AN$12 -> 0 | J24: =Input!$AO$12 -> 0 | K24: =Input!$AP$12 -> 0 | L24: =SUM(F24:K24) -> 0 | AB24: =SUM(C24:L24) -> 0
B25: Mathematical Sciences | F25: =Input!$AQ$12 -> 0 | G25: =Input!$AR$12 -> 0 | H25: =Input!$AS$12 -> 0 | I25: =Input!$AT$12 -> 0 | J25: =Input!$AU$12 -> 0 | K25: =Input!$AV$12 -> 0 | L25: =SUM(F25:K25) -> 0 | O25: Difference | AB25: =SUM(C25:L25) -> 0
B26: Medical Sciences | F26: =Input!$AW$12 -> 114954760 | G26: =Input!$AX$12 -> 16759332 | H26: =Input!$AY$12 -> 25206484 | I26: =Input!$AZ$12 -> 10452891 | J26: =Input!$BA$12 -> 8712860 | K26: =Input!$BB$12 -> 23432271 | L26: =SUM(F26:K26) -> 199518598 | N26: =IF(O26<>0,"Out of Balance","Balanced") -> Balanced | O26: =L17-L41 -> 0
B27: Physical Sciences | F27: =Input!$BC$12 -> 0 | G27: =Input!$BD$12 -> 0 | H27: =Input!$BE$12 -> 0 | I27: =Input!$BF$12 -> 0 | J27: =Input!$BG$12 -> 0 | K27: =Input!$BH$12 -> 0 | L27: =SUM(F27:K27) -> 0
B28: Psychology | F28: =Input!$BI$12 -> 0 | G28: =Input!$BJ$12 -> 0 | H28: =Input!$BK$12 -> 0 | I28: =Input!$BL$12 -> 0 | J28: =Input!$BM$12 -> 0 | K28: =Input!$BN$12 -> 0 | L28: =SUM(F28:K28) -> 0
B29: Social Sciences | F29: =Input!$BO$12 -> 0 | G29: =Input!$BP$12 -> 0 | H29: =Input!$BQ$12 -> 0 | I29: =Input!$BR$12 -> 0 | J29: =Input!$BS$12 -> 0 | K29: =Input!$BT$12 -> 0 | L29: =SUM(F29:K29) -> 0
B30: Other Sciences not classified above | F30: =Input!$BU$12 -> 0 | G30: =Input!$BV$12 -> 0 | H30: =Input!$BW$12 -> 0 | I30: =Input!$BX$12 -> 0 | J30: =Input!$BY$12 -> 0 | K30: =Input!$BZ$12 -> 0 | L30: =SUM(F30:K30) -> 0
B31: Arts and Humanities | F31: =Input!$CA$12 -> 0 | G31: =Input!$CB$12 -> 0 | H31: =Input!$CC$12 -> 0 | I31: =Input!$CD$12 -> 0 | J31: =Input!$CE$12 -> 0 | K31: =Input!$CF$12 -> 0 | L31: =SUM(F31:K31) -> 0
B32: Business Administration | F32: =Input!$CG$12 -> 0 | G32: =Input!$CH$12 -> 0 | H32: =Input!$CI$12 -> 0 | I32: =Input!$CJ$12 -> 0 | J32: =Input!$CK$12 -> 0 | K32: =Input!$CL$12 -> 0 | L32: =SUM(F32:K32) -> 0
B33: Education | F33: =Input!$CM$12 -> 0 | G33: =Input!$CN$12 -> 0 | H33: =Input!$CO$12 -> 0 | I33: =Input!$CP$12 -> 0 | J33: =Input!$CQ$12 -> 0 | K33: =Input!$CR$12 -> 0 | L33: =SUM(F33:K33) -> 0
B34: Law | F34: =Input!$CS$12 -> 0 | G34: =Input!$CT$12 -> 0 | H34: =Input!$CU$12 -> 0 | I34: =Input!$CV$12 -> 0 | J34: =Input!$CW$12 -> 0 | K34: =Input!$CX$12 -> 0 | L34: =SUM(F34:K34) -> 0
B35: Field of Study - Future Use 1 | F35: =Input!$CY$12 -> 0 | G35: =Input!$CZ$12 -> 0 | H35: =Input!$DA$12 -> 0 | I35: =Input!$DB$12 -> 0 | J35: =Input!$DC$12 -> 0 | K35: =Input!$DD$12 -> 0 | L35: =SUM(F35:K35) -> 0
B36: Field of Study - Future Use 2 | F36: =Input!$DE$12 -> 0 | G36: =Input!$DF$12 -> 0 | H36: =Input!$DG$12 -> 0 | I36: =Input!$DH$12 -> 0 | J36: =Input!$DI$12 -> 0 | K36: =Input!$DJ$12 -> 0 | L36: =SUM(F36:K36) -> 0
B37: Field of Study - Future Use 3 | F37: =Input!$DK$12 -> 0 | G37: =Input!$DL$12 -> 0 | H37: =Input!$DM$12 -> 0 | I37: =Input!$DN$12 -> 0 | J37: =Input!$DO$12 -> 0 | K37: =Input!$DP$12 -> 0 | L37: =SUM(F37:K37) -> 0
B38: Field of Study - Future Use 4 | F38: =Input!$DQ$12 -> 0 | G38: =Input!$DR$12 -> 0 | H38: =Input!$DS$12 -> 0 | I38: =Input!$DT$12 -> 0 | J38: =Input!$DU$12 -> 0 | K38: =Input!$DV$12 -> 0 | L38: =SUM(F38:K38) -> 0
B39: Field of Study - Future Use 5 | F39: =Input!$DW$12 -> 0 | G39: =Input!$DX$12 -> 0 | H39: =Input!$DY$12 -> 0 | I39: =Input!$DZ$12 -> 0 | J39: =Input!$EA$12 -> 0 | K39: =Input!$EB$12 -> 0 | L39: =SUM(F39:K39) -> 0
B40: Other Non-Science Activities | F40: =Input!$EC$12 -> 0 | G40: =Input!$ED$12 -> 0 | H40: =Input!$EE$12 -> 0 | I40: =Input!$EF$12 -> 0 | J40: =Input!$EG$12 -> 0 | K40: =Input!$EH$12 -> 0 | L40: =SUM(F40:K40) -> 0 | O40: To Accountability | P40: Sources & Uses | AB40: =SUM(C40:L40) -> 0
B41: Total R & D Expenditures By Funding Source | F41: =SUM(F20:F40) -> 150323653 | G41: =SUM(G20:G40) -> 17922267 | H41: =SUM(H20:H40) -> 25594744 | I41: =SUM(I20:I40) -> 11579402 | J41: =SUM(J20:J40) -> 9112235 | K41: =SUM(K20:K40) -> 26240251 | L41: =SUM(L20:L40) -> 240772552 | O41: ResPercGenRev | P41: State Appropriations | S41: =L41-INT(L41) -> 0 | AB41: =SUM(AB20:AB40) -> 82507908
...

Sheet HSSA
B1: The University of Texas Health Science Center at San Antonio | N1: Return to Index | AA1: 12 | AB1: 13
B2: =Input!$B$5 -> For the Year Ended August 31, 2010
B3: =Input!$B$6 -> Source: FY 2010 Research Expenditure Survey
N4: Zoom % should be at 75%.
B6: =Input!$B$7 -> FY 2010
B7: Summary of R & D Expenditures | K7: Overall Total | L7: Defined For Survey
B8: R & D Expenses as defined for the Research Expenditure Survey | K8: =L8 -> 145165310 | L8: =Input!$H$13 -> 145165310 | AB8: =SUM(C8:L8) -> 290330620
B9: R & D Expenses not meeting the narrow definition of R & D used in the Research Expenditures Survey | K9: =Input!$F$13 -> 0 | AB9: =SUM(C9:L9) -> 0
B10: Total Expenses for R & D as reported on the Statement of Revenues, Expenses and Changes in Net Assets | H10: =IF(O10<>0,"Out of Balance with SRECNA","") | K10: =SUM(K8:K9) -> 145165310
AB11: =SUM(C10:L10) -> 145165310
B12: Other Research-related Equipment Expenditures (noncurrent fund expenditures, etc. - do not include R & D plant expenses or construction) | K12: =Input!$G$13 -> 0 | AB12: =SUM(C11:L11) -> 0
B13: Indirect Costs associated with Expenses for R & D as defined for this survey | K13: =L13 -> 33528292 | L13: =Input!$I$13 -> 33528292 | AB13: =SUM(C13:L13) -> 67056584
B14: Capital Outlay for research equipment (do not include R & D plant expenses or construction) | K14: =L14 -> 6535416 | L14: =Input!$J$13 -> 6535416 | AB14: =SUM(C14:L14) -> 13070832
B15: Expenditures for conduct of R & D made by institution's research foundation or 501© corporation on behalf of the institution and not report in institution AFR, including indirect costs not reported above | K15: =L15 -> 0 | L15: =Input!$K$13 -> 0 | AB15: =SUM(C15:L15) -> 0
B16: Pass-throughs from Texas Engineering Experiment Station not reported in R & D Expenditures as defined for the Research Expenditure Survey | K16: =L16 -> 0 | L16: =Input!$L$13 -> 0 | AB16: =SUM(C16:L16) -> 0
B17: Total R & D Expenditures | K17: =SUM(K10:K16) -> 185229018 | L17: =SUM(L8:L16) -> 185229018 | S17: =L17-INT(L17) -> 0 | T17: 0 | U17: 0 | V17: 0 | AB17: =#REF!+#REF!+#REF!+#REF! -> #REF!
F18: =IF(OR(S17<>0,S41<>0,S54<>0),"Do not Enter Cents - Whole Dollars Only","")
B19: R & D Expenditures By Funding Source | F19: Federal | G19: State Appropriations | H19: State Contracts/Grants | I19: Institution Resources | J19: Private For-Profit | K19: Private Non-Profit | L19: Total
B20: Agricultural Sciences | F20: =Input!$M$13 -> 0 | G20: =Input!$N$13 -> 0 | H20: =Input!$O$13 -> 0 | I20: =Input!$P$13 -> 0 | J20: =Input!$Q$13 -> 0 | K20: =Input!$R$13 -> 0 | L20: =SUM(F20:K20) -> 0 | AB20: =SUM(C20:L20) -> 0
B21: Biological and Other Life Sciences | F21: =Input!$S$13 -> 0 | G21: =Input!$T$13 -> 0 | H21: =Input!$U$13 -> 0 | I21: =Input!$V$13 -> 0 | J21: =Input!$W$13 -> 0 | K21: =Input!$X$13 -> 0 | L21: =SUM(F21:K21) -> 0 | AB21: =SUM(C21:L21) -> 0
B22: Computer Science | F22: =Input!$Y$13 -> 0 | G22: =Input!$Z$13 -> 0 | H22: =Input!$AA$13 -> 0 | I22: =Input!$AB$13 -> 0 | J22: =Input!$AC$13 -> 0 | K22: =Input!$AD$13 -> 0 | L22: =SUM(F22:K22) -> 0 | AB22: =SUM(C22:L22) -> 0
B23: Engineering | F23: =Input!$AE$13 -> 0 | G23: =Input!$AF$13 -> 0 | H23: =Input!$AG$13 -> 0 | I23: =Input!$AH$13 -> 0 | J23: =Input!$AI$13 -> 0 | K23: =Input!$AJ$13 -> 0 | L23: =SUM(F23:K23) -> 0 | AB23: =SUM(C23:L23) -> 0
B24: Environmental Sciences | F24: =Input!$AK$13 -> 0 | G24: =Input!$AL$13 -> 0 | H24: =Input!$AM$13 -> 0 | I24: =Input!$AN$13 -> 0 | J24: =Input!$AO$13 -> 0 | K24: =Input!$AP$13 -> 0 | L24: =SUM(F24:K24) -> 0 | AB24: =SUM(C24:L24) -> 0
B25: Mathematical Sciences | F25: =Input!$AQ$13 -> 0 | G25: =Input!$AR$13 -> 0 | H25: =Input!$AS$13 -> 0 | I25: =Input!$AT$13 -> 0 | J25: =Input!$AU$13 -> 0 | K25: =Input!$AV$13 -> 0 | L25: =SUM(F25:K25) -> 0 | O25: Difference | AB25: =SUM(C25:L25) -> 0
B26: Medical Sciences | F26: =Input!$AW$13 -> 121723410 | G26: =Input!$AX$13 -> 6240743 | H26: =Input!$AY$13 -> 708627 | I26: =Input!$AZ$13 -> 20876076 | J26: =Input!$BA$13 -> 22353048 | K26: =Input!$BB$13 -> 13327114 | L26: =SUM(F26:K26) -> 185229018 | N26: =IF(O26<>0,"Out of Balance","Balanced") -> Balanced | O26: =L17-L41 -> 0
B27: Physical Sciences | F27: =Input!$BC$13 -> 0 | G27: =Input!$BD$13 -> 0 | H27: =Input!$BE$13 -> 0 | I27: =Input!$BF$13 -> 0 | J27: =Input!$BG$13 -> 0 | K27: =Input!$BH$13 -> 0 | L27: =SUM(F27:K27) -> 0
B28: Psychology | F28: =Input!$BI$13 -> 0 | G28: =Input!$BJ$13 -> 0 | H28: =Input!$BK$13 -> 0 | I28: =Input!$BL$13 -> 0 | J28: =Input!$BM$13 -> 0 | K28: =Input!$BN$13 -> 0 | L28: =SUM(F28:K28) -> 0
B29: Social Sciences | F29: =Input!$BO$13 -> 0 | G29: =Input!$BP$13 -> 0 | H29: =Input!$BQ$13 -> 0 | I29: =Input!$BR$13 -> 0 | J29: =Input!$BS$13 -> 0 | K29: =Input!$BT$13 -> 0 | L29: =SUM(F29:K29) -> 0
B30: Other Sciences not classified above | F30: =Input!$BU$13 -> 0 | G30: =Input!$BV$13 -> 0 | H30: =Input!$BW$13 -> 0 | I30: =Input!$BX$13 -> 0 | J30: =Input!$BY$13 -> 0 | K30: =Input!$BZ$13 -> 0 | L30: =SUM(F30:K30) -> 0
B31: Arts and Humanities | F31: =Input!$CA$13 -> 0 | G31: =Input!$CB$13 -> 0 | H31: =Input!$CC$13 -> 0 | I31: =Input!$CD$13 -> 0 | J31: =Input!$CE$13 -> 0 | K31: =Input!$CF$13 -> 0 | L31: =SUM(F31:K31) -> 0
B32: Business Administration | F32: =Input!$CG$13 -> 0 | G32: =Input!$CH$13 -> 0 | H32: =Input!$CI$13 -> 0 | I32: =Input!$CJ$13 -> 0 | J32: =Input!$CK$13 -> 0 | K32: =Input!$CL$13 -> 0 | L32: =SUM(F32:K32) -> 0
B33: Education | F33: =Input!$CM$13 -> 0 | G33: =Input!$CN$13 -> 0 | H33: =Input!$CO$13 -> 0 | I33: =Input!$CP$13 -> 0 | J33: =Input!$CQ$13 -> 0 | K33: =Input!$CR$13 -> 0 | L33: =SUM(F33:K33) -> 0
B34: Law | F34: =Input!$CS$13 -> 0 | G34: =Input!$CT$13 -> 0 | H34: =Input!$CU$13 -> 0 | I34: =Input!$CV$13 -> 0 | J34: =Input!$CW$13 -> 0 | K34: =Input!$CX$13 -> 0 | L34: =SUM(F34:K34) -> 0
B35: Field of Study - Future Use 1 | F35: =Input!$CY$13 -> 0 | G35: =Input!$CZ$13 -> 0 | H35: =Input!$DA$13 -> 0 | I35: =Input!$DB$13 -> 0 | J35: =Input!$DC$13 -> 0 | K35: =Input!$DD$13 -> 0 | L35: =SUM(F35:K35) -> 0
B36: Field of Study - Future Use 2 | F36: =Input!$DE$13 -> 0 | G36: =Input!$DF$13 -> 0 | H36: =Input!$DG$13 -> 0 | I36: =Input!$DH$13 -> 0 | J36: =Input!$DI$13 -> 0 | K36: =Input!$DJ$13 -> 0 | L36: =SUM(F36:K36) -> 0
B37: Field of Study - Future Use 3 | F37: =Input!$DK$13 -> 0 | G37: =Input!$DL$13 -> 0 | H37: =Input!$DM$13 -> 0 | I37: =Input!$DN$13 -> 0 | J37: =Input!$DO$13 -> 0 | K37: =Input!$DP$13 -> 0 | L37: =SUM(F37:K37) -> 0
B38: Field of Study - Future Use 4 | F38: =Input!$DQ$13 -> 0 | G38: =Input!$DR$13 -> 0 | H38: =Input!$DS$13 -> 0 | I38: =Input!$DT$13 -> 0 | J38: =Input!$DU$13 -> 0 | K38: =Input!$DV$13 -> 0 | L38: =SUM(F38:K38) -> 0
B39: Field of Study - Future Use 5 | F39: =Input!$DW$13 -> 0 | G39: =Input!$DX$13 -> 0 | H39: =Input!$DY$13 -> 0 | I39: =Input!$DZ$13 -> 0 | J39: =Input!$EA$13 -> 0 | K39: =Input!$EB$13 -> 0 | L39: =SUM(F39:K39) -> 0
B40: Other Non-Science Activities | F40: =Input!$EC$13 -> 0 | G40: =Input!$ED$13 -> 0 | H40: =Input!$EE$13 -> 0 | I40: =Input!$EF$13 -> 0 | J40: =Input!$EG$13 -> 0 | K40: =Input!$EH$13 -> 0 | L40: =SUM(F40:K40) -> 0 | O40: To Accountability | P40: Sources & Uses | AB40: =SUM(C40:L40) -> 0
B41: Total R & D Expenditures By Funding Source | F41: =SUM(F20:F40) -> 121723410 | G41: =SUM(G20:G40) -> 6240743 | H41: =SUM(H20:H40) -> 708627 | I41: =SUM(I20:I40) -> 20876076 | J41: =SUM(J20:J40) -> 22353048 | K41: =SUM(K20:K40) -> 13327114 | L41: =SUM(L20:L40) -> 185229018 | O41: ResPercGenRev | P41: State Appropriations | S41: =L41-INT(L41) -> 0 | AB41: =SUM(AB20:AB40) -> 0
...

Sheet MDA
B1: The University of Texas M.D. Anderson Cancer Center | N1: Return to Index | AA1: 12 | AB1: 13
B2: =Input!$B$5 -> For the Year Ended August 31, 2010
B3: =Input!$B$6 -> Source: FY 2010 Research Expenditure Survey
N4: Zoom % should be at 75%.
B6: =Input!$B$7 -> FY 2010
B7: Summary of R & D Expenditures | K7: Overall Total | L7: Defined For Survey
B8: R & D Expenses as defined for the Research Expenditure Survey | K8: =L8 -> 463104671 | L8: =Input!$H$14 -> 463104671 | AB8: =SUM(C8:L8) -> 926209342
B9: R & D Expenses not meeting the narrow definition of R & D used in the Research Expenditures Survey | K9: =Input!$F$14 -> 0 | AB9: =SUM(C9:L9) -> 0
B10: Total Expenses for R & D as reported on the Statement of Revenues, Expenses and Changes in Net Assets | H10: =IF(O10<>0,"Out of Balance with SRECNA","") | K10: =SUM(K8:K9) -> 463104671
AB11: =SUM(C10:L10) -> 463104671
B12: Other Research-related Equipment Expenditures (noncurrent fund expenditures, etc. - do not include R & D plant expenses or construction) | K12: =Input!$G$14 -> 0 | AB12: =SUM(C11:L11) -> 0
B13: Indirect Costs associated with Expenses for R & D as defined for this survey | K13: =L13 -> 75631023 | L13: =Input!$I$14 -> 75631023 | AB13: =SUM(C13:L13) -> 151262046
B14: Capital Outlay for research equipment (do not include R & D plant expenses or construction) | K14: =L14 -> 8299050 | L14: =Input!$J$14 -> 8299050 | AB14: =SUM(C14:L14) -> 16598100
B15: Expenditures for conduct of R & D made by institution's research foundation or 501© corporation on behalf of the institution and not report in institution AFR, including indirect costs not reported above | K15: =L15 -> 0 | L15: =Input!$K$14 -> 0 | AB15: =SUM(C15:L15) -> 0
B16: Pass-throughs from Texas Engineering Experiment Station not reported in R & D Expenditures as defined for the Research Expenditure Survey | K16: =L16 -> 0 | L16: =Input!$L$14 -> 0 | AB16: =SUM(C16:L16) -> 0
B17: Total R & D Expenditures | K17: =SUM(K10:K16) -> 547034744 | L17: =SUM(L8:L16) -> 547034744 | S17: =L17-INT(L17) -> 0 | T17: 0 | U17: 0 | V17: 0 | AB17: =#REF!+#REF!+#REF!+#REF! -> #REF!
F18: =IF(OR(S17<>0,S41<>0,S54<>0),"Do not Enter Cents - Whole Dollars Only","")
B19: R & D Expenditures By Funding Source | F19: Federal | G19: State Appropriations | H19: State Contracts/Grants | I19: Institution Resources | J19: Private For-Profit | K19: Private Non-Profit | L19: Total
B20: Agricultural Sciences | F20: =Input!$M$14 -> 0 | G20: =Input!$N$14 -> 0 | H20: =Input!$O$14 -> 0 | I20: =Input!$P$14 -> 0 | J20: =Input!$Q$14 -> 0 | K20: =Input!$R$14 -> 0 | L20: =SUM(F20:K20) -> 0 | AB20: =SUM(C20:L20) -> 0
B21: Biological and Other Life Sciences | F21: =Input!$S$14 -> 65655783 | G21: =Input!$T$14 -> 65613402 | H21: =Input!$U$14 -> 217616 | I21: =Input!$V$14 -> 7409082 | J21: =Input!$W$14 -> 4646129 | K21: =Input!$X$14 -> 20725473 | L21: =SUM(F21:K21) -> 164267485 | AB21: =SUM(C21:L21) -> 328534970
B22: Computer Science | F22: =Input!$Y$14 -> 0 | G22: =Input!$Z$14 -> 0 | H22: =Input!$AA$14 -> 0 | I22: =Input!$AB$14 -> 0 | J22: =Input!$AC$14 -> 0 | K22: =Input!$AD$14 -> 0 | L22: =SUM(F22:K22) -> 0 | AB22: =SUM(C22:L22) -> 0
B23: Engineering | F23: =Input!$AE$14 -> 0 | G23: =Input!$AF$14 -> 0 | H23: =Input!$AG$14 -> 0 | I23: =Input!$AH$14 -> 0 | J23: =Input!$AI$14 -> 0 | K23: =Input!$AJ$14 -> 0 | L23: =SUM(F23:K23) -> 0 | AB23: =SUM(C23:L23) -> 0
B24: Environmental Sciences | F24: =Input!$AK$14 -> 0 | G24: =Input!$AL$14 -> 0 | H24: =Input!$AM$14 -> 0 | I24: =Input!$AN$14 -> 0 | J24: =Input!$AO$14 -> 0 | K24: =Input!$AP$14 -> 0 | L24: =SUM(F24:K24) -> 0 | AB24: =SUM(C24:L24) -> 0
B25: Mathematical Sciences | F25: =Input!$AQ$14 -> 5614173 | G25: =Input!$AR$14 -> 13409038 | H25: =Input!$AS$14 -> 0 | I25: =Input!$AT$14 -> 355017 | J25: =Input!$AU$14 -> 59418 | K25: =Input!$AV$14 -> 396902 | L25: =SUM(F25:K25) -> 19834548 | O25: Difference | AB25: =SUM(C25:L25) -> 39669096
B26: Medical Sciences | F26: =Input!$AW$14 -> 114729585 | G26: =Input!$AX$14 -> 86116417 | H26: =Input!$AY$14 -> 62296 | I26: =Input!$AZ$14 -> 18723770 | J26: =Input!$BA$14 -> 44912739 | K26: =Input!$BB$14 -> 58303336 | L26: =SUM(F26:K26) -> 322848143 | N26: =IF(O26<>0,"Out of Balance","Balanced") -> Balanced | O26: =L17-L41 -> 0
B27: Physical Sciences | F27: =Input!$BC$14 -> 7389134 | G27: =Input!$BD$14 -> 3855001 | H27: =Input!$BE$14 -> 64055 | I27: =Input!$BF$14 -> 871307 | J27: =Input!$BG$14 -> 752820 | K27: =Input!$BH$14 -> 97414 | L27: =SUM(F27:K27) -> 13029731
B28: Psychology | F28: =Input!$BI$14 -> 6777540 | G28: =Input!$BJ$14 -> 5125903 | H28: =Input!$BK$14 -> 0 | I28: =Input!$BL$14 -> 2875185 | J28: =Input!$BM$14 -> 341015 | K28: =Input!$BN$14 -> 1299904 | L28: =SUM(F28:K28) -> 16419547
B29: Social Sciences | F29: =Input!$BO$14 -> 6498232 | G29: =Input!$BP$14 -> 2342001 | H29: =Input!$BQ$14 -> 0 | I29: =Input!$BR$14 -> 961879 | J29: =Input!$BS$14 -> 0 | K29: =Input!$BT$14 -> 833178 | L29: =SUM(F29:K29) -> 10635290
B30: Other Sciences not classified above | F30: =Input!$BU$14 -> 0 | G30: =Input!$BV$14 -> 0 | H30: =Input!$BW$14 -> 0 | I30: =Input!$BX$14 -> 0 | J30: =Input!$BY$14 -> 0 | K30: =Input!$BZ$14 -> 0 | L30: =SUM(F30:K30) -> 0
B31: Arts and Humanities | F31: =Input!$CA$14 -> 0 | G31: =Input!$CB$14 -> 0 | H31: =Input!$CC$14 -> 0 | I31: =Input!$CD$14 -> 0 | J31: =Input!$CE$14 -> 0 | K31: =Input!$CF$14 -> 0 | L31: =SUM(F31:K31) -> 0
B32: Business Administration | F32: =Input!$CG$14 -> 0 | G32: =Input!$CH$14 -> 0 | H32: =Input!$CI$14 -> 0 | I32: =Input!$CJ$14 -> 0 | J32: =Input!$CK$14 -> 0 | K32: =Input!$CL$14 -> 0 | L32: =SUM(F32:K32) -> 0
B33: Education | F33: =Input!$CM$14 -> 0 | G33: =Input!$CN$14 -> 0 | H33: =Input!$CO$14 -> 0 | I33: =Input!$CP$14 -> 0 | J33: =Input!$CQ$14 -> 0 | K33: =Input!$CR$14 -> 0 | L33: =SUM(F33:K33) -> 0
B34: Law | F34: =Input!$CS$14 -> 0 | G34: =Input!$CT$14 -> 0 | H34: =Input!$CU$14 -> 0 | I34: =Input!$CV$14 -> 0 | J34: =Input!$CW$14 -> 0 | K34: =Input!$CX$14 -> 0 | L34: =SUM(F34:K34) -> 0
B35: Field of Study - Future Use 1 | F35: =Input!$CY$14 -> 0 | G35: =Input!$CZ$14 -> 0 | H35: =Input!$DA$14 -> 0 | I35: =Input!$DB$14 -> 0 | J35: =Input!$DC$14 -> 0 | K35: =Input!$DD$14 -> 0 | L35: =SUM(F35:K35) -> 0
B36: Field of Study - Future Use 2 | F36: =Input!$DE$14 -> 0 | G36: =Input!$DF$14 -> 0 | H36: =Input!$DG$14 -> 0 | I36: =Input!$DH$14 -> 0 | J36: =Input!$DI$14 -> 0 | K36: =Input!$DJ$14 -> 0 | L36: =SUM(F36:K36) -> 0
B37: Field of Study - Future Use 3 | F37: =Input!$DK$14 -> 0 | G37: =Input!$DL$14 -> 0 | H37: =Input!$DM$14 -> 0 | I37: =Input!$DN$14 -> 0 | J37: =Input!$DO$14 -> 0 | K37: =Input!$DP$14 -> 0 | L37: =SUM(F37:K37) -> 0
B38: Field of Study - Future Use 4 | F38: =Input!$DQ$14 -> 0 | G38: =Input!$DR$14 -> 0 | H38: =Input!$DS$14 -> 0 | I38: =Input!$DT$14 -> 0 | J38: =Input!$DU$14 -> 0 | K38: =Input!$DV$14 -> 0 | L38: =SUM(F38:K38) -> 0
B39: Field of Study - Future Use 5 | F39: =Input!$DW$14 -> 0 | G39: =Input!$DX$14 -> 0 | H39: =Input!$DY$14 -> 0 | I39: =Input!$DZ$14 -> 0 | J39: =Input!$EA$14 -> 0 | K39: =Input!$EB$14 -> 0 | L39: =SUM(F39:K39) -> 0
B40: Other Non-Science Activities | F40: =Input!$EC$14 -> 0 | G40: =Input!$ED$14 -> 0 | H40: =Input!$EE$14 -> 0 | I40: =Input!$EF$14 -> 0 | J40: =Input!$EG$14 -> 0 | K40: =Input!$EH$14 -> 0 | L40: =SUM(F40:K40) -> 0 | O40: To Accountability | P40: Sources & Uses | AB40: =SUM(C40:L40) -> 0
B41: Total R & D Expenditures By Funding Source | F41: =SUM(F20:F40) -> 206664447 | G41: =SUM(G20:G40) -> 176461762 | H41: =SUM(H20:H40) -> 343967 | I41: =SUM(I20:I40) -> 31196240 | J41: =SUM(J20:J40) -> 50712121 | K41: =SUM(K20:K40) -> 81656207 | L41: =SUM(L20:L40) -> 547034744 | O41: ResPercGenRev | P41: State Appropriations | S41: =L41-INT(L41) -> 0 | AB41: =SUM(AB20:AB40) -> 368204066
...

Sheet THC
B1: The University of Texas Health Center at Tyler | N1: Return to Index | AA1: 12 | AB1: 13
B2: =Input!$B$5 -> For the Year Ended August 31, 2010
B3: =Input!$B$6 -> Source: FY 2010 Research Expenditure Survey
N4: Zoom % should be at 75%.
B6: =Input!$B$7 -> FY 2010
B7: Summary of R & D Expenditures | K7: Overall Total | L7: Defined For Survey
B8: R & D Expenses as defined for the Research Expenditure Survey | K8: =L8 -> 12168890 | L8: =Input!$H$15 -> 12168890 | AB8: =SUM(C8:L8) -> 24337780
B9: R & D Expenses not meeting the narrow definition of R & D used in the Research Expenditures Survey | K9: =Input!$F$15 -> 0 | AB9: =SUM(C9:L9) -> 0
B10: Total Expenses for R & D as reported on the Statement of Revenues, Expenses and Changes in Net Assets | H10: =IF(O10<>0,"Out of Balance with SRECNA","") | K10: =SUM(K8:K9) -> 12168890
AB11: =SUM(C10:L10) -> 12168890
B12: Other Research-related Equipment Expenditures (noncurrent fund expenditures, etc. - do not include R & D plant expenses or construction) | K12: =Input!$G$15 -> 0 | AB12: =SUM(C11:L11) -> 0
B13: Indirect Costs associated with Expenses for R & D as defined for this survey | K13: =L13 -> 1844206 | L13: =Input!$I$15 -> 1844206 | AB13: =SUM(C13:L13) -> 3688412
B14: Capital Outlay for research equipment (do not include R & D plant expenses or construction) | K14: =L14 -> 365036 | L14: =Input!$J$15 -> 365036 | AB14: =SUM(C14:L14) -> 730072
B15: Expenditures for conduct of R & D made by institution's research foundation or 501© corporation on behalf of the institution and not report in institution AFR, including indirect costs not reported above | K15: =L15 -> 0 | L15: =Input!$K$15 -> 0 | AB15: =SUM(C15:L15) -> 0
B16: Pass-throughs from Texas Engineering Experiment Station not reported in R & D Expenditures as defined for the Research Expenditure Survey | K16: =L16 -> 0 | L16: =Input!$L$15 -> 0 | AB16: =SUM(C16:L16) -> 0
B17: Total R & D Expenditures | K17: =SUM(K10:K16) -> 14378132 | L17: =SUM(L8:L16) -> 14378132 | S17: =L17-INT(L17) -> 0 | T17: 0 | U17: 0 | V17: 0 | AB17: =#REF!+#REF!+#REF!+#REF! -> #REF!
F18: =IF(OR(S17<>0,S41<>0,S54<>0),"Do not Enter Cents - Whole Dollars Only","")
B19: R & D Expenditures By Funding Source | F19: Federal | G19: State Appropriations | H19: State Contracts/Grants | I19: Institution Resources | J19: Private For-Profit | K19: Private Non-Profit | L19: Total
B20: Agricultural Sciences | F20: =Input!$M$15 -> 1299948 | G20: =Input!$N$15 -> 0 | H20: =Input!$O$15 -> 0 | I20: =Input!$P$15 -> 0 | J20: =Input!$Q$15 -> 0 | K20: =Input!$R$15 -> 0 | L20: =SUM(F20:K20) -> 1299948 | AB20: =SUM(C20:L20) -> 2599896
B21: Biological and Other Life Sciences | F21: =Input!$S$15 -> 0 | G21: =Input!$T$15 -> 0 | H21: =Input!$U$15 -> 0 | I21: =Input!$V$15 -> 0 | J21: =Input!$W$15 -> 0 | K21: =Input!$X$15 -> 0 | L21: =SUM(F21:K21) -> 0 | AB21: =SUM(C21:L21) -> 0
B22: Computer Science | F22: =Input!$Y$15 -> 0 | G22: =Input!$Z$15 -> 0 | H22: =Input!$AA$15 -> 0 | I22: =Input!$AB$15 -> 0 | J22: =Input!$AC$15 -> 0 | K22: =Input!$AD$15 -> 0 | L22: =SUM(F22:K22) -> 0 | AB22: =SUM(C22:L22) -> 0
B23: Engineering | F23: =Input!$AE$15 -> 0 | G23: =Input!$AF$15 -> 0 | H23: =Input!$AG$15 -> 0 | I23: =Input!$AH$15 -> 0 | J23: =Input!$AI$15 -> 0 | K23: =Input!$AJ$15 -> 0 | L23: =SUM(F23:K23) -> 0 | AB23: =SUM(C23:L23) -> 0
B24: Environmental Sciences | F24: =Input!$AK$15 -> 0 | G24: =Input!$AL$15 -> 0 | H24: =Input!$AM$15 -> 0 | I24: =Input!$AN$15 -> 0 | J24: =Input!$AO$15 -> 0 | K24: =Input!$AP$15 -> 0 | L24: =SUM(F24:K24) -> 0 | AB24: =SUM(C24:L24) -> 0
