Workbook

Sheet Summary
A1: Reference Database Statistics Summary
A2: 2009-2010
A4: * usage constrained by limitations on concurrent users
A5: Database Name | B5: Vendor / Platform | C5: COUNTER-compliant? | D5: Sessions | E5: Searches | F5: Searches, prev. yr | G5: % change | H5: Turnaways | I5: Successful full-text article requests | J5: 2009/10 Price | K5: Cost per Search
A6: ABI/INFORM Dateline | B6: ProQuest | C6: Yes | D6: =ProQuest!N9 -> 4422 | E6: =ProQuest!N8 -> 12816 | H6: 0 | I6: N/A | J6: 0 | K6: N/A
A7: ABI/INFORM Global | B7: ProQuest | C7: Yes | D7: =ProQuest!N15 -> 6822 | E7: =ProQuest!N14 -> 21757 | H7: 0 | I7: N/A | J7: =ProQuest!O14 -> 19320 | K7: =ProQuest!P14 -> 0.88799007
A8: ABI/INFORM Trade & Industry | B8: ProQuest | C8: Yes | D8: =ProQuest!N21 -> 3999 | E8: =ProQuest!N20 -> 11821 | H8: 0 | I8: N/A | J8: 0 | K8: N/A
A9: Abstracts in Anthropology | B9: MetaPress | C9: Yes (R3) | D9: N/A | E9: N/A | H9: N/A | I9: =MetaPress!N8 -> 7 | J9: 0 | K9: N/A
A10: Academic Search Complete (statewide database trial) | B10: EBSCOhost | C10: Yes | D10: =EBSCOhost!N8 -> 42231 | E10: =EBSCOhost!N9 -> 147063 | H10: 0 | I10: N/A | J10: 0 | K10: N/A
A11: Academic Search Premier | B11: EBSCOhost | C11: Yes | D11: =EBSCOhost!N14 -> 36892 | E11: =EBSCOhost!N15 -> 98126 | H11: 0 | I11: N/A | J11: =EBSCOhost!O15 -> 20953 | K11: =EBSCOhost!P15 -> 0.21353158
A12: ALA Guide to Reference | B12: ALA Editions | C12: No | D12: ='ALA Guide to Reference'!N8 -> 20 | E12: N/A | H12: N/A | I12: N/A | J12: ='ALA Guide to Reference'!O8 -> 1238 | K12: ='ALA Guide to Reference'!P8 -> 61.9
A13: Alternative Press Index | B13: FirstSearch | C13: Yes | D13: N/A | E13: =FirstSearch!N8 -> 31 | H13: 0 | I13: N/A | J13: N/A | K13: N/A
A14: Alternative Press Index Archive | B14: FirstSearch | C14: Yes | D14: N/A | E14: =FirstSearch!N13 -> 21 | H14: 0 | I14: N/A | J14: N/A | K14: N/A
A15: America History & Life | B15: EBSCOhost | C15: Yes | D15: =EBSCOhost!N20 -> 2097 | E15: =EBSCOhost!N21 -> 8962 | H15: 0 | I15: N/A | J15: =EBSCOhost!O21 -> 7881 | K15: =EBSCOhost!P21 -> 0.8793796
A16: American State Papers, 1789-1838 | B16: Newsbank | C16: Yes (R2) | D16: N/A | E16: =Newsbank!N8 -> 16 | H16: 0 | I16: N/A | J16: 0 | K16: N/A
A17: ARBA Online | B17: Greenwood Press | C17: Yes (R2) | D17: =Greenwood!N9 -> 21 | E17: =Greenwood!N8 -> 7 | H17: 0 | I17: N/A | J17: =Greenwood!O8 -> 338 | K17: =Greenwood!P8 -> 48.285714
A18: Art Abstracts | B18: WilsonWeb | C18: Yes (R2) | D18: =WilsonWeb!N8 -> 540 | E18: =WilsonWeb!N9 -> 1813 | H18: =WilsonWeb!N11 -> N/A | I18: N/A | J18: =WilsonWeb!O9 -> 6291 | K18: =WilsonWeb!P9 -> 3.4699393
A19: Art Index Retrospective* | B19: WilsonWeb | C19: Yes (R2) | D19: =WilsonWeb!N16 -> 137 | E19: =WilsonWeb!N17 -> 403 | H19: =WilsonWeb!N18 -> 0 | I19: N/A | J19: 0 | K19: N/A
A20: ArticleFirst* | B20: FirstSearch | C20: Yes | D20: =FirstSearch!N18 -> 1066 | E20: =FirstSearch!N19 -> 4271 | H20: =FirstSearch!N21 -> 46 | I20: N/A | J20: 0 | K20: N/A
A21: ARTstor | B21: ArtSTOR | C21: No | D21: =ARTstor!N9 -> 4325 | E21: N/A | H21: N/A | I21: N/A | J21: =ARTstor!O8 -> 13102.5 | K21: N/A
A22: ASFA 1 (Biosciences...) | B22: CSA | C22: Yes (R3) | D22: N/A | E22: =CSA!N13 -> 1855 | H22: 0 | I22: N/A | J22: 0 | K22: N/A
A23: ASFA 2 (Ocean Technology...) | B23: CSA | C23: Yes (R3) | D23: N/A | E23: =CSA!N18 -> 797 | H23: 0 | I23: N/A | J23: 0 | K23: N/A
A24: ASFA 3 (Aquatic Pollution...) | B24: CSA | C24: Yes (R3) | D24: N/A | E24: =CSA!N23 -> 1396 | H24: 0 | I24: N/A | J24: 0 | K24: N/A
A25: ASFA Aquaculture Abstracts | B25: CSA | C25: Yes (R3) | D25: N/A | E25: =CSA!N28 -> 1262 | H25: 0 | I25: N/A | J25: 0 | K25: N/A
A26: ASFA Marine Biotechnology Abstracts | B26: CSA | C26: Yes (R3) | D26: N/A | E26: =CSA!N33 -> 1130 | H26: 0 | I26: N/A | J26: 0 | K26: N/A
A27: ASFA: Aquatic Science & Fisheries Abstracts (all) | B27: CSA | C27: Yes (R3) | D27: N/A | E27: =CSA!N8 -> 6387 | H27: 0 | I27: N/A | J27: =CSA!O8 -> 8265 | K27: =CSA!P8 -> 1.2940348
A28: Bacteriology Abstracts (Microbiology B) | B28: CSA | C28: Yes (R3) | D28: N/A | E28: =CSA!N38 -> 175 | H28: N/A | I28: N/A | J28: 0 | K28: N/A
A29: Biography Index Retrospective* | B29: WilsonWeb | C29: Yes (R2) | D29: N/A | E29: N/A | H29: N/A | I29: N/A | J29: =WilsonWeb!O25 -> 5656 | K29: N/A
A30: Biological Abstracts | B30: Ovid | C30: Yes (R3) | D30: =OVID!N9 -> 11 | E30: =OVID!N8 -> 18 | H30: =OVID!N10 -> 0 | I30: N/A | J30: 0 | K30: N/A
A31: Biological & Agricultural Index Plus | B31: WilsonWeb | C31: Yes (R2) | D31: =WilsonWeb!N32 -> 459 | E31: =WilsonWeb!N33 -> 1099 | H31: =WilsonWeb!N34 -> 0 | I31: N/A | J31: =WilsonWeb!O33 -> 3514.5 | K31: =WilsonWeb!P33 -> 3.1979072
A32: BIOSIS Previews | B32: Ovid | C32: Yes | D32: =OVID!N16 -> 2 | E32: =OVID!N15 -> 2 | H32: =OVID!N17 -> 0 | I32: N/A | J32: 0 | K32: N/A
A33: BIOSIS Previews | B33: Web of Science | C33: Yes | D33: =WebofScience!N8 -> 419 | E33: =WebofScience!N9 -> 1420 | H33: 0 | I33: N/A | J33: 0 | K33: N/A
A34: Biotechnology Research Abstracts | B34: CSA | C34: Yes (R3) | D34: N/A | E34: =CSA!N43 -> 205 | H34: 0 | I34: N/A | J34: 0 | K34: N/A
A35: Book Review Digest Retrospective* | B35: WilsonWeb | C35: Yes (R2) | D35: N/A | E35: N/A | H35: N/A | I35: N/A | J35: =WilsonWeb!O41 -> 9292 | K35: N/A
A36: CIAO | B36: CIAO | C36: No | D36: =CIAO!N9 -> 81 | E36: =CIAO!N10 -> 180 | H36: N/A | I36: =CIAO!N8 -> 51 | J36: =CIAO!O8 -> 1035 | K36: N/A
A37: CINAHL | B37: EBSCOhost | C37: Yes | D37: =EBSCOhost!N26 -> 12480 | E37: =EBSCOhost!N27 -> 63680 | H37: 0 | I37: N/A | J37: =EBSCOhost!O27 -> 5870 | K37: =EBSCOhost!P27 -> 0.092179648
A38: Clase and Periodica* | B38: FirstSearch | C38: Yes | D38: =FirstSearch!N26 -> 55 | E38: =FirstSearch!N27 -> 64 | H38: =FirstSearch!N29 -> 0 | I38: N/A | J38: 0 | K38: N/A
A39: Cochrane Library | B39: Wiley InterScience | C39: No | D39: =Cochrane!N8 -> 1746 | E39: =Cochrane!N9 -> 495 | H39: N/A | I39: N/A | J39: =Cochrane!O9 -> 3241 | K39: N/A
A40: ComDisDome | B40: CSA | C40: Yes (R3) | D40: N/A | E40: =CSA!N48 -> 3215 | I40: N/A | J40: =CSA!O48 -> 2730 | K40: =CSA!P48 -> 0.84914463
A41: Communication Abstracts | B41: CSA | C41: Yes (R3) | D41: N/A | E41: =CSA!N53 -> 5507 | H41: 0 | I41: N/A | J41: =CSA!O53 -> 3025 | K41: =CSA!P53 -> 0.54930089
...

Sheet ALA Guide to Reference
A1: ALA Guide to Reference
A2: 2009-2010
A4: COUNTER-Compliant?: | B4: No
B6: Jul-2009 | C6: Aug-2009 | D6: Sep-2009 | E6: Oct-2009 | F6: Nov-2009 | G6: Dec-2009 | H6: Jan-2010 | I6: Feb-2010 | J6: Mar-2010 | K6: Apr-2010 | L6: May-2010 | M6: Jun-2010 | N6: Total | O6: 2009-2010 price | P6: Price per unit
A7: ALA Guide to Reference
A8: Logins | B8: 2 | C8: 0 | D8: 3 | E8: 3 | F8: 0 | G8: 0 | H8: 2 | I8: 4 | J8: 4 | K8: 0 | L8: 2 | M8: 0 | N8: =SUM(B8:M8) -> 20 | O8: 1238 | P8: =O8/N8 -> 61.9

Sheet ARTstor
A1: ARTstor
A2: 2009-2010
A4: COUNTER-Compliant?: | B4: No
B6: 39995 | C6: 40026 | D6: 40057 | E6: 40087 | F6: 40118 | G6: 40148 | H6: 40179 | I6: 40210 | J6: 40238 | K6: 40269 | L6: 40299 | M6: 40330 | N6: Total | O6: 2009-2010 Price | P6: Price per unit
A7: ARTstor
A8: Events | B8: 61 | C8: 652 | D8: 16228 | E8: 9213 | F8: 26169 | G8: 23414 | H8: 6426 | I8: 29391 | J8: 21204 | K8: 12044 | L8: 17110 | M8: 2254 | N8: =SUM(B8:M8) -> 164166 | O8: 13102.5 | P8: =O8/N8 -> 0.079812507
A9: Sessions | B9: 8 | C9: 15 | D9: 416 | E9: 574 | F9: 517 | G9: 483 | H9: 83 | I9: 729 | J9: 649 | K9: 413 | L9: 410 | M9: 28 | N9: =SUM(B9:M9) -> 4325 | O9: 13102.5 | P9: =O9/N9 -> 3.0294798
A10: Users | B10: 1 | C10: 3 | D10: 165 | E10: 190 | F10: 176 | G10: n/a | H10: n/a | I10: n/a | J10: n/a | K10: n/a | L10: n/a | M10: n/a | N10: =SUM(B10:M10) -> 535 | O10: 13102.5 | P10: =O10/N10 -> 24.490654
A11: Minutes | B11: 1413 | C11: 2644 | D11: 23186 | E11: 11569 | G11: n/a | H11: n/a | I11: n/a | J11: n/a | K11: n/a | L11: n/a | M11: n/a | N11: =SUM(B11:M11) -> 38812 | O11: 13102.5 | P11: =O11/N11 -> 0.33758889
A12: Registrations | D12: 157 | E12: 45 | F12: 17 | G12: 11 | H12: 3 | I12: 171 | J12: 24 | K12: 5 | L12: 7 | M12: 0 | N12: =SUM(B12:M12) -> 440 | O12: 13102.5 | P12: =O12/N12 -> 29.778409
A15: Events: | B15: Number of events.
A17: Sessions: | B17: Number of sessions.
A19: Users: | B19: Number of unique users who logged in during the time period. All users who did not log in are counted as one additional users. The numbers of monthly users are not additive, i.e. the sum of monthly users is not equal to the total number of unique users for all time.
A21: Minutes: | B21: Total minutes used by all sessions.
A23: Registrations: | B23: Number of new registrations.

Sheet CIAO
A1: CIAO
A2: 2009-2010
A4: COUNTER-Compliant?: | B4: No
B6: 39995 | C6: 40026 | D6: 40057 | E6: 40087 | F6: 40118 | G6: 40148 | H6: 40179 | I6: 40210 | J6: 40238 | K6: 40269 | L6: 40299 | M6: 40330 | N6: Total | O6: 2009-2010 Price | P6: Price per unit
A7: CIAO
A8: No of Visitors | B8: 1 | C8: 6 | D8: 7 | E8: 12 | F8: 8 | G8: 9 | H8: 4 | I8: 2 | J8: 2 | K8: 0 | L8: 0 | M8: 0 | N8: =SUM(B8:M8) -> 51 | O8: 1035 | P8: =O8/N8 -> 20.294118
A9: No of Visits | B9: 2 | C9: 9 | D9: 15 | E9: 13 | F9: 16 | G9: 13 | H9: 9 | I9: 2 | J9: 2 | K9: 0 | L9: 0 | M9: 0 | N9: =SUM(B9:M9) -> 81 | O9: 1035 | P9: =O9/N9 -> 12.777778
A10: No of Views | B10: 6 | C10: 44 | D10: 51 | E10: 25 | F10: 18 | G10: 14 | H10: 16 | I10: 2 | J10: 4 | K10: 0 | L10: 0 | M10: 0 | N10: =SUM(B10:M10) -> 180 | O10: 1035 | P10: =O10/N10 -> 5.75
A11: No of Google Searches | B11: 0 | C11: 0 | D11: 0 | E11: 0 | F11: 0 | G11: 0 | H11: 0 | I11: 0 | J11: 0 | K11: 0 | L11: 0 | M11: 0 | N11: =SUM(B11:M11) -> 0 | O11: 1035 | P11: N/A
A12: Articles Viewed | B12: 6 | C12: 36 | D12: 37 | E12: 16 | F12: 14 | G12: 4 | H12: 9 | I12: 1 | J12: 2 | K12: 0 | L12: 0 | M12: 0 | N12: =SUM(B12:M12) -> 125 | O12: 1035 | P12: =O12/N12 -> 8.28
A13: Average Visit Duration | B13: 9 min 21 sec | C13: 9 min 24 sec | D13: 4 min 51 sec | E13: 35 sec | F13: 21 sec | G13: 10 sec | H13: 1 min 15 sec | I13: n/a | J13: 18 sec | K13: n/a | L13: n/a | M13: n/a | N13: —

Sheet Cochrane
A1: Cochrane Library (Wiley)
A2: 2009-2010
A4: COUNTER-Compliant?: | B4: No
B6: 39995 | C6: 40026 | D6: 40057 | E6: 40087 | F6: 40118 | G6: 40148 | H6: 40179 | I6: 40210 | J6: 40238 | K6: 40269 | L6: 40299 | M6: 40330 | N6: Total | O6: 2009-2010 Price | P6: Price per unit
A7: Cochrane Library
A8: User Sessions | B8: 80 | C8: 30 | D8: 141 | E8: 199 | F8: 278 | G8: 90 | H8: 51 | I8: 200 | J8: 266 | K8: 291 | L8: 46 | M8: 74 | N8: =SUM(B8:M8) -> 1746
A9: Searches (Total) | B9: 19 | C9: 8 | D9: 127 | E9: 66 | F9: 102 | G9: 10 | H9: 8 | I9: 19 | J9: 62 | K9: 60 | L9: 6 | M9: 8 | N9: =SUM(B9:M9) -> 495 | O9: 3241 | P9: =O9/N9 -> 6.5474747
A10: Full-Text (Total) | B10: 33 | C10: 27 | D10: 52 | E10: 145 | F10: 211 | G10: 56 | H10: 28 | I10: 62 | J10: 176 | K10: 215 | L10: 38 | M10: 62 | N10: =SUM(B10:M10) -> 1105 | O10: 3241 | P10: =O10/N10 -> 2.9330317
A11: Access Denied | B11: 0 | C11: 0 | D11: 0 | E11: 0 | F11: 0 | G11: 0 | H11: 0 | I11: 139 | J11: 0 | K11: 0 | L11: 0 | M11: 0 | N11: =SUM(B11:M11) -> 139

Sheet Compendex(EI)
A1: Compendex (Engineering Index)
A2: 2009-2010
A4: COUNTER-Compliant?: | B4: Yes (R2)
B6: 39995 | C6: 40026 | D6: 40057 | E6: 40087 | F6: 40118 | G6: 40148 | H6: 40179 | I6: 40210 | J6: 40238 | K6: 40269 | L6: 40299 | M6: 40330 | N6: Total | O6: 2009-2010 Price | P6: Price per unit
A7: Compendex
A8: Sessions | B8: 55 | C8: 27 | D8: 69 | E8: 91 | F8: 435 | G8: 61 | H8: 19 | I8: 44 | J8: 74 | K8: 67 | L8: 188 | M8: 167 | N8: =SUM(B8:M8) -> 1297
A9: Searches | B9: 163 | C9: 67 | D9: 251 | E9: 385 | F9: 4112 | G9: 243 | H9: 77 | I9: 186 | J9: 228 | K9: 222 | L9: 38 | M9: 46 | N9: =SUM(B9:M9) -> 6018 | O9: 16877 | P9: =O9/N9 -> 2.8044201

Sheet CQ Researcher
A1: CQ Researcher
A2: 2009-2010
A4: COUNTER-compliant? | B4: Yes
B6: 39995 | C6: 40026 | D6: 40057 | E6: 40087 | F6: 40118 | G6: 40148 | H6: 40179 | I6: 40210 | J6: 40238 | K6: 40269 | L6: 40299 | M6: 40330 | N6: Total | O6: 2009-2010 Price | P6: Price per unit
A7: CQ Researcher
A8: Sessions | B8: 40 | C8: 2 | D8: 69 | E8: 139 | F8: 133 | G8: 67 | H8: 11 | I8: 100 | J8: 105 | K8: 145 | L8: 18 | M8: 18 | N8: =SUM(B8:M8) -> 847
A9: Searches | B9: 84 | C9: 3 | D9: 99 | E9: 140 | F9: 176 | G9: 56 | H9: 13 | I9: 98 | J9: 116 | K9: 203 | L9: 11 | M9: 28 | N9: =SUM(B9:M9) -> 1027 | O9: 1694 | P9: =O9/N9 -> 1.6494645
A10: Full Text Downloads | B10: 64 | C10: 3 | D10: 139 | E10: 195 | F10: 233 | G10: 78 | H10: 11 | I10: 195 | J10: 156 | K10: 265 | L10: 17 | M10: 25 | N10: =SUM(B10:M10) -> 1381 | O10: 1694 | P10: =O10/N10 -> 1.2266474
A11: Turnaways | B11: 0 | C11: 0 | D11: 0 | E11: 0 | F11: 0 | G11: 0 | H11: 0 | I11: 0 | J11: 0 | K11: 0 | L11: 0 | M11: 0 | N11: =SUM(B11:M11) -> 0
A13: SIMULTANEOUS USERS: | B13: 10

Sheet CSA
A1: CSA Databases
A2: 2009-2010
A4: COUNTER-Compliant?: | B4: Yes (R3)
B6: 39995 | C6: 40026 | D6: 40057 | E6: 40087 | F6: 40118 | G6: 40148 | H6: 40179 | I6: 40210 | J6: 40238 | K6: 40269 | L6: 40299 | M6: 40330 | N6: Total | O6: 2009-2010 Price | P6: Price per unit
A7: ASFA (all)
A8: Searches | B8: =282+355 -> 637 | C8: =205+173 -> 378 | D8: =299+512 -> 811 | E8: =320+561 -> 881 | F8: =131+444 -> 575 | G8: 648 | H8: 145 | I8: 626 | J8: 636 | K8: 483 | L8: 205 | M8: 362 | N8: =SUM(B8:M8) -> 6387 | O8: 8265 | P8: =O8/N8 -> 1.2940348
B11: 39995 | C11: 40026 | D11: 40057 | E11: 40087 | F11: 40118 | G11: 40148 | H11: 40179 | I11: 40210 | J11: 40238 | K11: 40269 | L11: 40299 | M11: 40330 | N11: Total | O11: 2009-2010 Price | P11: Price per unit
A12: ASFA 1 (Biosciences...)
A13: Searches | B13: =34+57 -> 91 | C13: =18+57 -> 75 | D13: =43+124 -> 167 | E13: =21+206 -> 227 | F13: =7+140 -> 147 | G13: 94 | H13: 40 | I13: 296 | J13: 262 | K13: 279 | L13: 68 | M13: 109 | N13: =SUM(B13:M13) -> 1855 | O13: 0 | P13: N/A
B16: 39995 | C16: 40026 | D16: 40057 | E16: 40087 | F16: 40118 | G16: 40148 | H16: 40179 | I16: 40210 | J16: 40238 | K16: 40269 | L16: 40299 | M16: 40330 | N16: Total | O16: 2009-2010 Price | P16: Price per unit
A17: ASFA 2 (Ocean Technology…)
A18: Searches | B18: 23 | C18: 11 | D18: 61 | E18: 64 | F18: 45 | G18: 37 | H18: 19 | I18: 133 | J18: 122 | K18: 174 | L18: 34 | M18: 74 | N18: =SUM(B18:M18) -> 797 | O18: 0 | P18: N/A
B21: 39995 | C21: 40026 | D21: 40057 | E21: 40087 | F21: 40118 | G21: 40148 | H21: 40179 | I21: 40210 | J21: 40238 | K21: 40269 | L21: 40299 | M21: 40330 | N21: Total | O21: 2009-2010 Price | P21: Price per unit
A22: ASFA 3 (Aquatic Pollution…)
A23: Searches | B23: =34+33 -> 67 | C23: =18+11 -> 29 | D23: =43+91 -> 134 | E23: =21+116 -> 137 | F23: =7+101 -> 108 | G23: 55 | H23: 19 | I23: 210 | J23: 212 | K23: 267 | L23: 67 | M23: 91 | N23: =SUM(B23:M23) -> 1396 | O23: 0 | P23: N/A
B26: 39995 | C26: 40026 | D26: 40057 | E26: 40087 | F26: 40118 | G26: 40148 | H26: 40179 | I26: 40210 | J26: 40238 | K26: 40269 | L26: 40299 | M26: 40330 | N26: Total | O26: 2009-2010 Price | P26: Price per unit
A27: ASFA Aquaculture Abstracts
A28: Searches | B28: =34+31 -> 65 | C28: =18+11 -> 29 | D28: =43+82 -> 125 | E28: =21+115 -> 136 | F28: =7+55 -> 62 | G28: 78 | H28: 22 | I28: 190 | J28: 196 | K28: 220 | L28: 56 | M28: 83 | N28: =SUM(B28:M28) -> 1262 | O28: 0 | P28: N/A
B31: 39995 | C31: 40026 | D31: 40057 | E31: 40087 | F31: 40118 | G31: 40148 | H31: 40179 | I31: 40210 | J31: 40238 | K31: 40269 | L31: 40299 | M31: 40330 | N31: Total | O31: 2009-2010 Price | P31: Price per unit
A32: ASFA Marine Biotechnology Abstracts
A33: Searches | B33: =34+32 -> 66 | C33: =18+11 -> 29 | D33: =43+64 -> 107 | E33: =21+57 -> 78 | F33: =7+47 -> 54 | G33: 57 | H33: 21 | I33: 180 | J33: 181 | K33: 218 | L33: 56 | M33: 83 | N33: =SUM(B33:M33) -> 1130 | O33: 0 | P33: N/A
B36: 39995 | C36: 40026 | D36: 40057 | E36: 40087 | F36: 40118 | G36: 40148 | H36: 40179 | I36: 40210 | J36: 40238 | K36: 40269 | L36: 40299 | M36: 40330 | N36: Total | O36: 2009-2010 Price | P36: Price per unit
A37: Bacteriology Abstracts (Microbiology B)
A38: Searches | B38: 0 | C38: 0 | D38: 10 | E38: 11 | F38: 28 | G38: 44 | H38: 20 | I38: 62 | J38: 0 | K38: 0 | L38: 0 | M38: 0 | N38: =SUM(B38:M38) -> 175 | O38: 0 | P38: N/A
B41: 39995 | C41: 40026 | D41: 40057 | E41: 40087 | F41: 40118 | G41: 40148 | H41: 40179 | I41: 40210 | J41: 40238 | K41: 40269 | L41: 40299 | M41: 40330 | N41: Total | O41: 2009-2010 Price | P41: Price per unit
A42: Biotechnology Research Abstracts
A43: Searches | B43: 0 | C43: 0 | D43: 10 | E43: 39 | F43: 28 | G43: 44 | H43: 21 | I43: 63 | J43: 0 | K43: 0 | L43: 0 | M43: 0 | N43: =SUM(B43:M43) -> 205 | O43: 0 | P43: N/A
B46: 39995 | C46: 40026 | D46: 40057 | E46: 40087 | F46: 40118 | G46: 40148 | H46: 40179 | I46: 40210 | J46: 40238 | K46: 40269 | L46: 40299 | M46: 40330 | N46: Total | O46: 2009-2010 Price | P46: Price per unit
A47: ComDisDome
A48: Searches | B48: =34+178 -> 212 | C48: =18+63 -> 81 | D48: =43+174 -> 217 | E48: =21+333 -> 354 | F48: =7+330 -> 337 | G48: 276 | H48: 29 | I48: 467 | J48: 527 | K48: 527 | L48: 74 | M48: 114 | N48: =SUM(B48:M48) -> 3215 | O48: 2730 | P48: =O48/N48 -> 0.84914463
B51: 39995 | C51: 40026 | D51: 40057 | E51: 40087 | F51: 40118 | G51: 40148 | H51: 40179 | I51: 40210 | J51: 40238 | K51: 40269 | L51: 40299 | M51: 40330 | N51: Total | O51: 2009-2010 Price | P51: Price per unit
A52: Communication Abstracts
A53: Searches | B53: 166 | C53: 83 | D53: 609 | E53: 334 | F53: 495 | G53: 886 | H53: 36 | I53: 605 | J53: 622 | K53: 1168 | L53: 344 | M53: 159 | N53: =SUM(B53:M53) -> 5507 | O53: 3025 | P53: =O53/N53 -> 0.54930089
B56: 39995 | C56: 40026 | D56: 40057 | E56: 40087 | F56: 40118 | G56: 40148 | H56: 40179 | I56: 40210 | J56: 40238 | K56: 40269 | L56: 40299 | M56: 40330 | N56: Total | O56: 2009-2010 Price | P56: Price per unit
A57: Conference Papers Index
A58: Searches | B58: 0 | C58: 0 | D58: 16 | E58: 39 | F58: 29 | G58: 40 | H58: 9 | I58: 6 | J58: 0 | K58: 0 | L58: 0 | M58: 0 | N58: =SUM(B58:M58) -> 139 | P58: =O58/N58 -> 0
B61: 39995 | C61: 40026 | D61: 40057 | E61: 40087 | F61: 40118 | G61: 40148 | H61: 40179 | I61: 40210 | J61: 40238 | K61: 40269 | L61: 40299 | M61: 40330 | N61: Total | O61: 2009-2010 Price | P61: Price per unit
A62: EIS: Digests of Environmental Impact Statements
A63: Searches | B63: =7+4 -> 11 | C63: =18+10 -> 28 | D63: =43+16 -> 59 | E63: =21+39 -> 60 | F63: =115+29 -> 144 | G63: 49 | H63: 27 | I63: 217 | J63: 181 | K63: 287 | L63: 59 | M63: 85 | N63: =SUM(B63:M63) -> 1207 | O63: 0 | P63: N/A
B66: 39995 | C66: 40026 | D66: 40057 | E66: 40087 | F66: 40118 | G66: 40148 | H66: 40179 | I66: 40210 | J66: 40238 | K66: 40269 | L66: 40299 | M66: 40330 | N66: Total | O66: 2009-2010 Price | P66: Price per unit
...

Sheet EBSCOhost
A1: EBSCOhost Databases
A2: 2009-2010
A4: COUNTER-Compliant?: | B4: Yes
B6: 39995 | C6: 40026 | D6: 40057 | E6: 40087 | F6: 40118 | G6: 40148 | H6: 40179 | I6: 40210 | J6: 40238 | K6: 40269 | L6: 40299 | M6: 40330 | N6: Total | O6: 2009-2010 Price | P6: Price per unit
A7: Academic Search Complete (statewide database trial)
A8: Sessions | B8: 1739 | C8: 472 | D8: 1942 | E8: 5515 | F8: 5822 | G8: 3360 | H8: 721 | I8: 5065 | J8: 6893 | K8: 7322 | L8: 1676 | M8: 1704 | N8: =SUM(B8:M8) -> 42231
A9: Searches | B9: 6283 | C9: 1738 | D9: 5827 | E9: 20319 | F9: 18168 | G9: 10577 | H9: 1919 | I9: 20656 | J9: 26711 | K9: 23469 | L9: 5666 | M9: 5730 | N9: =SUM(B9:M9) -> 147063 | O9: 0 | P9: N/A
B12: 39995 | C12: 40026 | D12: 40057 | E12: 40087 | F12: 40118 | G12: 40148 | H12: 40179 | I12: 40210 | J12: 40238 | K12: 40269 | L12: 40299 | M12: 40330 | N12: Total | O12: 2009-2010 Price | P12: Price per unit
A13: Academic Search Premier
A14: Sessions | B14: 1951 | C14: 606 | D14: 1895 | E14: 7236 | F14: 6006 | G14: 3339 | H14: 934 | I14: 2751 | J14: 4140 | K14: 5019 | L14: 1517 | M14: 1498 | N14: =SUM(B14:M14) -> 36892
A15: Searches | B15: 6590 | C15: 702 | D15: 4341 | E15: 29174 | F15: 15615 | G15: 7872 | H15: 1240 | I15: 6777 | J15: 10643 | K15: 10549 | L15: 2713 | M15: 1910 | N15: =SUM(B15:M15) -> 98126 | O15: 20953 | P15: =O15/N15 -> 0.21353158
B18: 39995 | C18: 40026 | D18: 40057 | E18: 40087 | F18: 40118 | G18: 40148 | H18: 40179 | I18: 40210 | J18: 40238 | K18: 40269 | L18: 40299 | M18: 40330 | N18: Total | O18: 2009-2010 Price | P18: Price per unit
A19: America History & Life
A20: Sessions | B20: 84 | C20: 22 | D20: 80 | E20: 246 | F20: 266 | G20: 217 | H20: 46 | I20: 203 | J20: 391 | K20: 314 | L20: 131 | M20: 97 | N20: =SUM(B20:M20) -> 2097
A21: Searches | B21: 585 | C21: 69 | D21: 345 | E21: 1105 | F21: 983 | G21: 1160 | H21: 199 | I21: 736 | J21: 1580 | K21: 1259 | L21: 583 | M21: 358 | N21: =SUM(B21:M21) -> 8962 | O21: 7881 | P21: =O21/N21 -> 0.8793796
B24: 39995 | C24: 40026 | D24: 40057 | E24: 40087 | F24: 40118 | G24: 40148 | H24: 40179 | I24: 40210 | J24: 40238 | K24: 40269 | L24: 40299 | M24: 40330 | N24: Total | O24: 2009-2010 Price | P24: Price per unit
A25: CINAHL
A26: Sessions | B26: 420 | C26: 84 | D26: 695 | E26: 1619 | F26: 2251 | G26: 870 | H26: 228 | I26: 1348 | J26: 1834 | K26: 2347 | L26: 436 | M26: 348 | N26: =SUM(B26:M26) -> 12480
A27: Searches | B27: 1995 | C27: 348 | D27: 3581 | E27: 8895 | F27: 12089 | G27: 4221 | H27: 988 | I27: 6126 | J27: 9248 | K27: 12600 | L27: 1996 | M27: 1593 | N27: =SUM(B27:M27) -> 63680 | O27: 5870 | P27: =O27/N27 -> 0.092179648
B30: 39995 | C30: 40026 | D30: 40057 | E30: 40087 | F30: 40118 | G30: 40148 | H30: 40179 | I30: 40210 | J30: 40238 | K30: 40269 | L30: 40299 | M30: 40330 | N30: Total | O30: 2009-2010 Price | P30: Price per unit
A31: EconLit
A32: Sessions | B32: 121 | C32: 43 | D32: 94 | E32: 241 | F32: 285 | G32: 209 | H32: 48 | I32: 135 | J32: 237 | K32: 313 | L32: 173 | M32: 78 | N32: =SUM(B32:M32) -> 1977
A33: Searches | B33: 800 | C33: 186 | D33: 415 | E33: 1096 | F33: 1129 | G33: 1148 | H33: 157 | I33: 575 | J33: 1175 | K33: 1326 | L33: 703 | M33: 301 | N33: =SUM(B33:M33) -> 9011 | O33: 3255 | P33: =O33/N33 -> 0.36122517
B36: 39995 | C36: 40026 | D36: 40057 | E36: 40087 | F36: 40118 | G36: 40148 | H36: 40179 | I36: 40210 | J36: 40238 | K36: 40269 | L36: 40299 | M36: 40330 | N36: Total | O36: 2009-2010 Price | P36: Price per unit
A37: ERIC (free)
A38: Sessions | B38: 69 | C38: 28 | D38: 70 | E38: 218 | F38: 222 | G38: 203 | H38: 38 | I38: 127 | J38: 216 | K38: 241 | L38: 77 | M38: 51 | N38: =SUM(B38:M38) -> 1560
A39: Searches | B39: 486 | C39: 93 | D39: 293 | E39: 1148 | F39: 1108 | G39: 1267 | H39: 195 | I39: 681 | J39: 1379 | K39: 1271 | L39: 522 | M39: 265 | N39: =SUM(B39:M39) -> 8708 | O39: 0 | P39: N/A
B42: 39995 | C42: 40026 | D42: 40057 | E42: 40087 | F42: 40118 | G42: 40148 | H42: 40179 | I42: 40210 | J42: 40238 | K42: 40269 | L42: 40299 | M42: 40330 | N42: Total | O42: 2009-2010 Price | P42: Price per unit
A43: Film & Television Literature Index
A44: Sessions | B44: 70 | C44: 21 | D44: 57 | E44: 178 | F44: 209 | G44: 241 | H44: 35 | I44: 103 | J44: 193 | K44: 242 | L44: 98 | M44: 44 | N44: =SUM(B44:M44) -> 1491
A45: Searches | B45: 476 | C45: 80 | D45: 204 | E45: 740 | F45: 805 | G45: 1146 | H45: 131 | I45: 451 | J45: 1119 | K45: 1022 | L45: 595 | M45: 161 | N45: =SUM(B45:M45) -> 6930 | O45: 1404 | P45: =O45/N45 -> 0.2025974
B48: 39995 | C48: 40026 | D48: 40057 | E48: 40087 | F48: 40118 | G48: 40148 | H48: 40179 | I48: 40210 | J48: 40238 | K48: 40269 | L48: 40299 | M48: 40330 | N48: Total | O48: 2009-2010 Price | P48: Price per unit
A49: FSTA Food Science & Technology Abstracts
A50: Sessions | B50: 53 | C50: 17 | D50: 56 | E50: 197 | F50: 174 | G50: 150 | H50: 37 | I50: 149 | J50: 175 | K50: 225 | L50: 79 | M50: 35 | N50: =SUM(B50:M50) -> 1347
A51: Searches | B51: 342 | C51: 40 | D51: 173 | E51: 679 | F51: 602 | G51: 766 | H51: 118 | I51: 459 | J51: 691 | K51: 991 | L51: 503 | M51: 131 | N51: =SUM(B51:M51) -> 5495 | O51: 6919 | P51: =O51/N51 -> 1.2591447
A52: Simultaneous Users | B52: 1 | C52: 1 | D52: 1 | E52: 1 | F52: 1 | G52: 1 | H52: 1 | I52: 1 | J52: 1 | K52: 1 | L52: 1 | M52: 1
A53: Database Turnaways | B53: 7 | C53: 4 | D53: 6 | E53: 54 | F53: 38 | G53: 27 | H53: 3 | I53: 37 | J53: 55 | K53: 41 | L53: 8 | M53: 2 | N53: =SUM(B53:M53) -> 282
B56: 39995 | C56: 40026 | D56: 40057 | E56: 40087 | F56: 40118 | G56: 40148 | H56: 40179 | I56: 40210 | J56: 40238 | K56: 40269 | L56: 40299 | M56: 40330 | N56: Total | O56: 2009-2010 Price | P56: Price per unit
A57: Funk & Wagnall's New World Encyclopedia (free)
A58: Sessions | B58: 65 | C58: 20 | D58: 70 | E58: 173 | F58: 172 | G58: 170 | H58: 30 | I58: 113 | J58: 171 | K58: 181 | L58: 78 | M58: 61 | N58: =SUM(B58:M58) -> 1304
...

Sheet Elsevier
A1: Elsevier
A2: 2009-2010
A4: COUNTER-Compliant?: | B4: No
B6: 39995 | C6: 40026 | D6: 40057 | E6: 40087 | F6: 40118 | G6: 40148 | H6: 40179 | I6: 40210 | J6: 40238 | K6: 40269 | L6: 40299 | M6: 40330 | N6: Total | O6: 2009-2010 Price | P6: Price per unit
A7: Encyclopedia of Ocean Sciences
A8: Requests for full text chapters | B8: 0 | C8: 0 | D8: 13 | E8: 19 | F8: 0 | G8: 0 | H8: 0 | I8: 1 | J8: 0 | K8: 6 | L8: 11 | M8: 0 | N8: =SUM(B8:M8) -> 50 | O8: 727.65 | P8: =O8/N8 -> 14.553
B11: 39995 | C11: 40026 | D11: 40057 | E11: 40087 | F11: 40118 | G11: 40148 | H11: 40179 | I11: 40210 | J11: 40238 | K11: 40269 | L11: 40299 | M11: 40330 | N11: Total | O11: 2009-2010 Price | P11: Price per unit
A12: Encyclopedia of Ocean Sciences, second ed. | O12: One-time purchase.
A13: Requests for full text chapters | B13: 0 | C13: 0 | D13: 6 | E13: 19 | F13: 5 | G13: 6 | H13: 5 | I13: 18 | J13: 2 | K13: 3 | L13: 3 | M13: 4 | N13: =SUM(B13:M13) -> 71 | O13: 2970.75 | P13: =O13/N13 -> 41.841549

Sheet EMBASE
A1: EMBASE
A2: 2009-2010
A4: COUNTER-Compliant?: | B4: No
B6: 39995 | C6: 40026 | D6: 40057 | E6: 40087 | F6: 40118 | G6: 40148 | H6: 40179 | I6: 40210 | J6: 40238 | K6: 40269 | L6: 40299 | M6: 40330 | N6: Total | O6: 2009-2010 Price | P6: Price per unit
A7: EMBASE.com
A8: Sessions | B8: 50 | C8: 46 | D8: 175 | E8: 208 | F8: 161 | G8: 132 | H8: 95 | I8: 250 | J8: 305 | K8: 256 | L8: 50 | M8: 92 | N8: =SUM(B8:M8) -> 1820
A9: Searches | B9: 97 | C9: 159 | D9: 633 | E9: 658 | F9: 535 | G9: 522 | H9: 286 | I9: 1286 | J9: 1139 | K9: 796 | L9: 106 | M9: 344 | N9: =SUM(B9:M9) -> 6561 | O9: 10927 | P9: =O9/N9 -> 1.6654473

Sheet FirstSearch
A1: FirstSearch
A2: 2009-2010
A4: COUNTER-Compliant?: | B4: Yes
B6: 39995 | C6: 40026 | D6: 40057 | E6: 40087 | F6: 40118 | G6: 40148 | H6: 40179 | I6: 40210 | J6: 40238 | K6: 40269 | L6: 40299 | M6: 40330 | N6: Total | O6: 2009-2010 Price | P6: Price per unit
A7: Alternative Press Index
A8: Searches | B8: 1 | C8: 0 | D8: 3 | E8: 0 | F8: 0 | G8: 2 | H8: 0 | I8: 2 | J8: 15 | K8: 8 | L8: 0 | M8: 0 | N8: =SUM(B8:M8) -> 31 | O8: 0 | P8: N/A
B11: 39995 | C11: 40026 | D11: 40057 | E11: 40087 | F11: 40118 | G11: 40148 | H11: 40179 | I11: 40210 | J11: 40238 | K11: 40269 | L11: 40299 | M11: 40330 | N11: Total | O11: 2009-2010 Price | P11: Price per unit
A12: Alternative Press Index Archive
A13: Searches | B13: 0 | C13: 0 | D13: 0 | E13: 0 | F13: 0 | G13: 0 | H13: 0 | I13: 4 | J13: 11 | K13: 6 | L13: 0 | M13: 0 | N13: =SUM(B13:M13) -> 21 | O13: 0 | P13: N/A
B16: 39995 | C16: 40026 | D16: 40057 | E16: 40087 | F16: 40118 | G16: 40148 | H16: 40179 | I16: 40210 | J16: 40238 | K16: 40269 | L16: 40299 | M16: 40330 | N16: Total | O16: 2009-2010 Price | P16: Price per unit
A17: ArticleFirst
A18: Logons | B18: 87 | C18: 41 | D18: 78 | E18: 175 | F18: 150 | G18: 68 | H18: 32 | I18: 96 | J18: 144 | K18: 96 | L18: 39 | M18: 60 | N18: =SUM(B18:M18) -> 1066
A19: Searches | B19: 443 | C19: 302 | D19: 315 | E19: 728 | F19: 240 | G19: 105 | H19: 204 | I19: 323 | J19: 261 | K19: 488 | L19: 352 | M19: 510 | N19: =SUM(B19:M19) -> 4271 | O19: 0 | P19: N/A
A20: User Limit | B20: 2 | C20: 2 | D20: 2 | E20: 2 | F20: 2 | G20: 2 | H20: 2 | I20: 2 | J20: 2 | K20: 2 | L20: 2 | M20: 20
A21: Turnaways | B21: 0 | C21: 0 | D21: 3 | E21: 7 | F21: 23 | G21: 0 | H21: 0 | I21: 1 | J21: 11 | K21: 1 | L21: 0 | M21: 0 | N21: =SUM(B21:M21) -> 46
B24: 39995 | C24: 40026 | D24: 40057 | E24: 40087 | F24: 40118 | G24: 40148 | H24: 40179 | I24: 40210 | J24: 40238 | K24: 40269 | L24: 40299 | M24: 40330 | N24: Total | O24: 2009-2010 Price | P24: Price per unit
A25: Clase and Periodica
A26: Logons | B26: 5 | C26: 3 | D26: 0 | E26: 7 | F26: 9 | G26: 7 | H26: 0 | I26: 4 | J26: 6 | K26: 5 | L26: 7 | M26: 2 | N26: =SUM(B26:M26) -> 55
A27: Searches | B27: 6 | C27: 5 | D27: 0 | E27: 3 | F27: 4 | G27: 19 | H27: 0 | I27: 7 | J27: 4 | K27: 4 | L27: 11 | M27: 1 | N27: =SUM(B27:M27) -> 64 | O27: 0 | P27: N/A
A28: User Limit | B28: 2 | C28: 2 | D28: 0 | E28: 2 | F28: 2 | G28: 2 | H28: 0 | I28: 2 | J28: 2 | K28: 2 | L28: 2 | M28: 2
A29: Turnaways | B29: 0 | C29: 0 | D29: 0 | E29: 0 | F29: 0 | G29: 0 | H29: 0 | I29: 0 | J29: 0 | K29: 0 | L29: 0 | M29: 0 | N29: =SUM(B29:M29) -> 0
B32: 39995 | C32: 40026 | D32: 40057 | E32: 40087 | F32: 40118 | G32: 40148 | H32: 40179 | I32: 40210 | J32: 40238 | K32: 40269 | L32: 40299 | M32: 40330 | N32: Total | O32: 2009-2010 Price | P32: Price per unit
A33: ERIC (free)
A34: Logons | B34: 54 | C34: 6 | D34: 45 | E34: 103 | F34: 100 | G34: 63 | H34: 15 | I34: 56 | J34: 85 | K34: 48 | L34: 17 | M34: 29 | N34: =SUM(B34:M34) -> 621
A35: Searches | B35: 79 | C35: 15 | D35: 120 | E35: 179 | F35: 183 | G35: 90 | H35: 21 | I35: 104 | J35: 194 | K35: 68 | L35: 35 | M35: 34 | N35: =SUM(B35:M35) -> 1122 | O35: 0 | P35: N/A
A36: User Limit | B36: 2 | C36: 2 | D36: 2 | E36: 2 | F36: 2 | G36: 2 | H36: 2 | I36: 2 | J36: 2 | K36: 2 | L36: 2 | M36: 2
A37: Turnaways | B37: 3 | C37: 0 | D37: 0 | E37: 1 | F37: 2 | G37: 0 | H37: 0 | I37: 0 | J37: 3 | K37: 0 | L37: 0 | M37: 0 | N37: =SUM(B37:M37) -> 9
B40: 39995 | C40: 40026 | D40: 40057 | E40: 40087 | F40: 40118 | G40: 40148 | H40: 40179 | I40: 40210 | J40: 40238 | K40: 40269 | L40: 40299 | M40: 40330 | N40: Total | O40: 2009-2010 Price | P40: Price per unit
A41: GEOBASE
A42: Searches | B42: 2 | C42: 1 | D42: 1 | E42: 9 | F42: 1 | G42: 0 | H42: 0 | I42: 0 | J42: 1 | K42: 4 | L42: 0 | M42: 9 | N42: =SUM(B42:M42) -> 28 | O42: 0 | P42: N/A
B45: 39995 | C45: 40026 | D45: 40057 | E45: 40087 | F45: 40118 | G45: 40148 | H45: 40179 | I45: 40210 | J45: 40238 | K45: 40269 | L45: 40299 | M45: 40330 | N45: Total | O45: 2009-2010 Price | P45: Price per unit
A46: GPO Monthly Catalog
A47: Logons | B47: 12 | C47: 1 | D47: 4 | E47: 13 | F47: 17 | G47: 8 | H47: 4 | I47: 7 | J47: 11 | K47: 16 | L47: 7 | M47: 1 | N47: =SUM(B47:M47) -> 101
A48: Searches | B48: 21 | C48: 2 | D48: 5 | E48: 43 | F48: 29 | G48: 11 | H48: 3 | I48: 5 | J48: 14 | K48: 22 | L48: 10 | M48: 1 | N48: =SUM(B48:M48) -> 166 | O48: 0 | P48: N/A
A49: User Limit | B49: 2 | C49: 2 | D49: 2 | E49: 2 | F49: 2 | G49: 2 | H49: 2 | I49: 2 | J49: 2 | K49: 2 | L49: 2 | M49: 2
A50: Turnaways | B50: 2 | C50: 0 | D50: 0 | E50: 0 | F50: 0 | G50: 0 | H50: 0 | I50: 0 | J50: 0 | K50: 0 | L50: 0 | M50: 0 | N50: =SUM(B50:M50) -> 2
B53: 39995 | C53: 40026 | D53: 40057 | E53: 40087 | F53: 40118 | G53: 40148 | H53: 40179 | I53: 40210 | J53: 40238 | K53: 40269 | L53: 40299 | M53: 40330 | N53: Total | O53: 2009-2010 Price | P53: Price per unit
A54: MEDLINE (free)
A55: Logons | B55: 253 | C55: 78 | D55: 201 | E55: 379 | F55: 454 | G55: 171 | H55: 117 | I55: 282 | J55: 352 | K55: 492 | L55: 103 | M55: 112 | N55: =SUM(B55:M55) -> 2994
A56: Searches | B56: 554 | C56: 137 | D56: 387 | E56: 731 | F56: 903 | G56: 413 | H56: 603 | I56: 609 | J56: 687 | K56: 1084 | L56: 416 | M56: 193 | N56: =SUM(B56:M56) -> 6717 | O56: 0 | P56: N/A
...

Sheet Greenwood
A1: Greenwood Press
A2: 2009-2010
A4: COUNTER-compliant? | B4: Yes (R2)
B6: 39995 | C6: 40026 | D6: 40057 | E6: 40087 | F6: 40118 | G6: 40148 | H6: 40179 | I6: 40210 | J6: 40238 | K6: 40269 | L6: 40299 | M6: 40330 | N6: Total | O6: 2009-2010 Price | P6: Price per unit
A7: ARBA Online
A8: Searches Run | B8: 0 | C8: 0 | D8: 0 | E8: 0 | F8: 1 | G8: 1 | H8: 2 | I8: 0 | J8: 2 | K8: 1 | L8: 0 | M8: 0 | N8: =SUM(B8:M8) -> 7 | O8: 338 | P8: =O8/N8 -> 48.285714
A9: Sessions Run | B9: 2 | C9: 0 | D9: 0 | E9: 1 | F9: 4 | G9: 2 | H9: 1 | I9: 2 | J9: 7 | K9: 1 | L9: 1 | M9: 0 | N9: =SUM(B9:M9) -> 21

Sheet InfoTrac
A1: InfoTRAC
A2: 2009-2010
A4: COUNTER-Compliant?: | B4: Yes
B6: 39995 | C6: 40026 | D6: 40057 | E6: 40087 | F6: 40118 | G6: 40148 | H6: 40179 | I6: 40210 | J6: 40238 | K6: 40269 | L6: 40299 | M6: 40330 | N6: Total | O6: 2009-2010 Price | P6: Price per unit
A7: Literature Resource Center | O7: Access fee only.
A8: Searches Run | B8: 76 | C8: 40 | D8: 255 | E8: 526 | F8: 928 | G8: 1756 | H8: 118 | I8: 445 | J8: 533 | K8: 781 | L8: 388 | M8: 187 | N8: =SUM(B8:M8) -> 6033 | O8: 1986 | P8: =O8/N8 -> 0.32918946
A9: Sessions | B9: 72 | C9: 47 | D9: 147 | E9: 302 | F9: 687 | G9: 859 | H9: 72 | I9: 312 | J9: 283 | K9: 444 | L9: 228 | M9: 88 | N9: =SUM(B9:M9) -> 3541
A10: Turnaways | B10: 0 | C10: 0 | D10: 0 | E10: 0 | F10: 0 | G10: 0 | H10: 0 | I10: 0 | J10: 0 | K10: 0 | L10: 0 | M10: 0 | N10: =SUM(B10:M10) -> 0
A11: Successful Full-Text Article Requests | B11: 20 | C11: 17 | D11: 66 | E11: 156 | F11: 246 | G11: 474 | H11: 53 | I11: 187 | J11: 211 | K11: 229 | L11: 129 | M11: 64 | N11: =SUM(B11:M11) -> 1852 | O11: 1986 | P11: =O11/N11 -> 1.0723542

Sheet ICPSR
A1: ICPSR
A2: 2009-2010
A4: COUNTER-Compliant?: | B4: No
B6: 39995 | C6: 40026 | D6: 40057 | E6: 40087 | F6: 40118 | G6: 40148 | H6: 40179 | I6: 40210 | J6: 40238 | K6: 40269 | L6: 40299 | M6: 40330 | N6: Total | O6: 2009-2010 Price | P6: Price per unit
A7: ICPSR
A8: Unique files downloaded | D8: 64 | E8: 0 | F8: 4 | G8: 31 | H8: 0 | I8: 740 | J8: 63 | K8: 36 | L8: 0 | M8: 0 | N8: =SUM(B8:M8) -> 938 | O8: 8750 | P8: =O8/N8 -> 9.3283582
A9: Total files downloaded | D9: 74 | E9: 0 | F9: 4 | G9: 31 | H9: 0 | I9: 757 | J9: 68 | K9: 72 | L9: 0 | M9: 0 | N9: =SUM(B9:M9) -> 1006 | O9: 8750 | P9: =O9/N9 -> 8.6978131
A10: Members-only files downloaded | D10: 74 | E10: 0 | F10: 4 | G10: 13 | H10: 0 | I10: 757 | J10: 54 | K10: 34 | L10: 0 | M10: 0 | N10: =SUM(B10:M10) -> 936 | O10: 8750 | P10: =O10/N10 -> 9.3482906
A11: Unique datasets downloaded | D11: 38 | E11: 0 | F11: 1 | G11: 11 | H11: 0 | I11: 163 | J11: 10 | K11: 11 | L11: 0 | M11: 0 | N11: =SUM(B11:M11) -> 234 | O11: 8750 | P11: =O11/N11 -> 37.393162
A12: Total datasets downloaded | D12: 40 | E12: 0 | F12: 1 | G12: 11 | H12: 0 | I12: 169 | J12: 10 | K12: 12 | L12: 0 | M12: 0 | N12: =SUM(B12:M12) -> 243 | O12: 8750 | P12: =O12/N12 -> 36.00823
A13: Members-only datasets downloaded | D13: 40 | E13: 0 | F13: 1 | G13: 1 | H13: 0 | I13: 169 | J13: 8 | K13: 4 | L13: 0 | M13: 0 | N13: =SUM(B13:M13) -> 223 | O13: 8750 | P13: =O13/N13 -> 39.237668
A14: Unique studies downloaded | D14: 6 | E14: 0 | F14: 1 | G14: 4 | H14: 0 | I14: 12 | J14: 8 | K14: 7 | L14: 0 | M14: 0 | N14: =SUM(B14:M14) -> 38 | O14: 8750 | P14: =O14/N14 -> 230.26316
A15: Total studies downloaded | D15: 7 | E15: 0 | F15: 1 | G15: 4 | H15: 0 | I15: 16 | J15: 8 | K15: 8 | L15: 0 | M15: 0 | N15: =SUM(B15:M15) -> 44 | O15: 8750 | P15: =O15/N15 -> 198.86364
A16: Members-only studies downloaded | D16: 7 | E16: 0 | F16: 1 | G16: 1 | H16: 0 | I16: 16 | J16: 6 | K16: 4 | L16: 0 | M16: 0 | N16: =SUM(B16:M16) -> 35 | O16: 8750 | P16: =O16/N16 -> 250
A17: Unique users | D17: 2 | E17: 0 | F17: 1 | G17: 2 | H17: 0 | I17: 1 | J17: 6 | K17: 6 | L17: 0 | M17: 0 | N17: =SUM(B17:M17) -> 18 | O17: 8750 | P17: =O17/N17 -> 486.11111
A22: Note: Subscription started November 19, 2009. Price was pro-rated.

Sheet KCDL
A1: KCDL Online
A2: 2009-2010
A4: COUNTER-Compliant? | B4: No
B6: 39995 | C6: 40026 | D6: 40057 | E6: 40087 | F6: 40118 | G6: 40148 | H6: 40179 | I6: 40210 | J6: 40238 | K6: 40269 | L6: 40299 | M6: 40330 | N6: Total | O6: 2009-2010 Price | P6: Price per unit
A7: KCDL Online
A8: Searches | B8: 2 | C8: 1 | D8: 2 | E8: 52 | F8: 20 | G8: 5 | H8: 3 | I8: 26 | J8: 9 | K8: 7 | L8: 1 | M8: 2 | N8: =SUM(B8:M8) -> 130 | O8: 1850 | P8: =O8/N8 -> 14.230769
A9: Web Pages Delivered | B9: 3 | C9: 5 | D9: 9 | E9: 117 | F9: 55 | G9: 14 | H9: 12 | I9: 95 | J9: 27 | K9: 25 | L9: 3 | M9: 5 | N9: =SUM(B9:M9) -> 370
A100: COUNTER com

Sheet Lexi-Comp
A1: Lexi-Comp
A2: 2009-2010
A4: COUNTER-Compliant?: | B4: No
B6: 39995 | C6: 40026 | D6: 40057 | E6: 40087 | F6: 40118 | G6: 40148 | H6: 40179 | I6: 40210 | J6: 40238 | K6: 40269 | L6: 40299 | M6: 40330 | N6: Total | O6: 2009-2010 Price | P6: Price per unit
A7: Lexi-Comp Online
A8: Logins | B8: 119 | C8: 291 | D8: 427 | E8: 574 | F8: 463 | G8: 426 | H8: 476 | I8: 1107 | J8: 950 | K8: 626 | L8: 524 | M8: 707 | N8: =SUM(B8:M8) -> 6690 | O8: 0 | P8: N/A
A9: Searches | B9: 492 | C9: 630 | D9: 802 | E9: 1458 | F9: 946 | G9: 691 | H9: 775 | I9: 2043 | J9: 2030 | K9: 1552 | L9: 1219 | M9: 1759 | N9: =SUM(B9:M9) -> 14397 | O9: 0 | P9: N/A
A10: Documents Retrieved | B10: 614 | C10: 758 | D10: 1131 | E10: 2193 | F10: 1491 | G10: 954 | H10: 1145 | I10: 2319 | J10: 2425 | K10: 1658 | L10: 1684 | M10: 2319 | N10: =SUM(B10:M10) -> 18691 | O10: 0 | P10: N/A

Sheet LexisNexis
A1: LexisNexis
A2: 2009-2010
A4: COUNTER-Compliant?: | B4: Yes
B6: 39995 | C6: 40026 | D6: 40057 | E6: 40087 | F6: 40118 | G6: 40148 | H6: 40179 | I6: 40210 | J6: 40238 | K6: 40269 | L6: 40299 | M6: 40330 | N6: Total | O6: 2009-2010 Price | P6: Price per unit
A7: Academic
A8: Sessions | B8: 1593 | C8: 408 | D8: 1547 | E8: 3973 | F8: 4830 | G8: 2861 | H8: 1309 | I8: 2360 | J8: 5024 | K8: 6066 | L8: 1700 | M8: 842 | N8: =SUM(B8:M8) -> 32513
A9: Searches | B9: 1221 | C9: 285 | D9: 1181 | E9: 3295 | F9: 3719 | G9: 2115 | H9: 760 | I9: 1762 | J9: 4302 | K9: 4314 | L9: 1421 | M9: 682 | N9: =SUM(B9:M9) -> 25057 | O9: 25295.63 | P9: =O9/N9 -> 1.0095235
B12: 39995 | C12: 40026 | D12: 40057 | E12: 40087 | F12: 40118 | G12: 40148 | H12: 40179 | I12: 40210 | J12: 40238 | K12: 40269 | L12: 40299 | M12: 40330 | N12: Total | O12: 2009-2010 Price | P12: Price per unit
A13: Congressional
A14: Sessions | B14: 10 | C14: 8 | D14: 23 | E14: 30 | F14: 28 | G14: 20 | H14: 7 | I14: 13 | J14: 78 | K14: 32 | L14: 9 | M14: 7 | N14: =SUM(B14:M14) -> 265
A15: Searches | B15: 29 | C15: 20 | D15: 49 | E15: 70 | F15: 42 | G15: 100 | H15: 10 | I15: 28 | J15: 292 | K15: 139 | L15: 16 | M15: 26 | N15: =SUM(B15:M15) -> 821 | O15: 7284.14 | P15: =O15/N15 -> 8.8722777

Sheet MathSciNet
A1: MathSciNet
A2: 2009-2010
A4: COUNTER-Compliant?: | B4: No
B6: 39995 | C6: 40026 | D6: 40057 | E6: 40087 | F6: 40118 | G6: 40148 | H6: 40179 | I6: 40210 | J6: 40238 | K6: 40269 | L6: 40299 | M6: 40330 | N6: Total | O6: 2009-2010 Price | P6: Price per unit
A7: MathSciNet
A8: Sessions | B8: 284 | C8: 963 | D8: 600 | E8: 751 | F8: 995 | G8: 1199 | H8: 1065 | I8: 896 | J8: 663 | K8: 791 | L8: 596 | M8: 328 | N8: =SUM(B8:M8) -> 9131
A9: Queries | B9: 575 | C9: 1290 | D9: 913 | E9: 1063 | F9: 1374 | G9: 1582 | H9: 1642 | I9: 1218 | J9: 1203 | K9: 1203 | L9: 974 | M9: 574 | N9: =SUM(B9:M9) -> 13611 | O9: 7751 | P9: =O9/N9 -> 0.56946587

Sheet Mergent
A1: Mergent
A2: 2009-2010
A4: COUNTER-Compliant?: | B4: No
B6: 39995 | C6: 40026 | D6: 40057 | E6: 40087 | F6: 40118 | G6: 40148 | H6: 40179 | I6: 40210 | J6: 40238 | K6: 40269 | L6: 40299 | M6: 40330 | N6: Total | O6: 2009-2010 Price | P6: Price per unit
A7: MergentOnline
A8: Logins | B8: 26 | C8: 5 | D8: 5 | E8: 38 | F8: 665 | G8: 99 | H8: 10 | I8: 144 | J8: 122 | K8: 179 | L8: 46 | M8: 15 | N8: =SUM(B8:M8) -> 1354
A9: Searched | B9: 132 | C9: 43 | D9: 6 | E9: 55 | F9: 3307 | G9: 253 | H9: 31 | I9: 617 | J9: n/a | K9: 273 | L9: 131 | M9: 50 | N9: =SUM(B9:M9) -> 4898 | O9: 15000 | P9: =O9/N9 -> 3.0624745
A10: Companies Viewed | B10: 68 | C10: 9 | D10: 0 | E10: 55 | F10: 939 | G10: 160 | H10: 7 | I10: 653 | J10: 107 | K10: 239 | L10: 74 | M10: 11 | N10: =SUM(B10:M10) -> 2322 | O10: 15000 | P10: =O10/N10 -> 6.4599483
A11: Time in database | B11: 0.30387731 | C11: 0.08943287 | D11: 0.034131944 | E11: 0.24584491 | F11: 6d 23:18:23 | G11: 0.76778935 | H11: 0.086342593 | I11: 1d 02:37:0 | J11: 1d 09:58:3 | K11: 1d 13:42:5 | L11: 0.48851852 | M11: 0.12185185 | N11: —
B14: 39995 | C14: 40026 | D14: 40057 | E14: 40087 | F14: 40118 | G14: 40148 | H14: 40179 | I14: 40210 | J14: 40238 | K14: 40269 | L14: 40299 | M14: 40330 | N14: Total | O14: 2009-2010 Price | P14: Price per unit
A15: Mergent WebReports
A16: Logins | B16: N/A | C16: N/A | D16: N/A | E16: N/A | F16: N/A | G16: N/A | H16: N/A | I16: N/A | J16: N/A | K16: N/A | L16: N/A | M16: N/A | N16: =SUM(B16:M16) -> 0
A17: Searched | B17: N/A | C17: N/A | D17: N/A | E17: N/A | F17: N/A | G17: N/A | H17: N/A | I17: N/A | J17: N/A | K17: N/A | L17: N/A | M17: N/A | N17: =SUM(B17:M17) -> 0 | P17: N/A
A18: Companies Viewed | B18: N/A | C18: N/A | D18: N/A | E18: N/A | F18: N/A | G18: N/A | H18: N/A | I18: N/A | J18: N/A | K18: N/A | L18: N/A | M18: N/A | N18: =SUM(B18:M18) -> 0 | P18: N/A
A19: Time in database | B19: N/A | C19: N/A | D19: N/A | E19: N/A | F19: N/A | G19: N/A | H19: N/A | I19: N/A | J19: N/A | K19: N/A | L19: N/A | M19: N/A | N19: —
A22: Mergent WebReports purchased 4/2010.

Sheet MetaPress
A1: MetaPress
A2: 2009-2010
A4: COUNTER-Compliant?: | B4: Yes (R3)
B6: 39995 | C6: 40026 | D6: 40057 | E6: 40087 | F6: 40118 | G6: 40148 | H6: 40179 | I6: 40210 | J6: 40238 | K6: 40269 | L6: 40299 | M6: 40330 | N6: Total | O6: 2009-2010 Price | P6: Price per unit
A7: Abstracts in Anthropology
A8: Number of Successful Full-Text Article Requests | B8: 0 | C8: 0 | D8: 0 | E8: 0 | F8: 0 | G8: 0 | H8: 1 | I8: 3 | J8: 0 | K8: 0 | L8: 3 | M8: N/A | N8: =SUM(B8:M8) -> 7 | P8: N/A
A10: Note: This subscription allows users to search a database, yet MetaPress usage statistics only measure "article requests," not searches.
A11: Thus these numbers mean nothing. They do NOT mean that the resource was not used.
A12: Canceled for 2009

Sheet netLibrary
A1: NetLibrary
A2: 2009-2010
A4: COUNTER-Compliant?: | B4: No
B6: 39995 | C6: 40026 | D6: 40057 | E6: 40087 | F6: 40118 | G6: 40148 | H6: 40179 | I6: 40210 | J6: 40238 | K6: 40269 | L6: 40299 | M6: 40330 | N6: Total | O6: 2009-2010 Price | P6: Price per unit
A7: NetLibrary
A8: Total Accesses | B8: 44 | C8: 6 | D8: 18 | E8: 44 | F8: 78 | G8: 31 | H8: 40 | I8: 104 | J8: 62 | K8: 131 | L8: 44 | M8: 46 | N8: =SUM(B8:M8) -> 648 | O8: 0 | P8: N/A
A9: Turnaways | B9: 43 | C9: 0 | D9: 5 | E9: 22 | F9: 10 | G9: 0 | H9: 60 | I9: 19 | J9: 2 | K9: 17 | L9: 14 | M9: 23 | N9: =SUM(B9:M9) -> 215
A12: Note: We have 4,478 shared titles

Sheet Newsbank
A1: Newsbank (Readex)
A2: 2009-2010
A4: COUNTER-Compliant?: | B4: Yes (R2)
B6: 39995 | C6: 40026 | D6: 40057 | E6: 40087 | F6: 40118 | G6: 40148 | H6: 40179 | I6: 40210 | J6: 40238 | K6: 40269 | L6: 40299 | M6: 40330 | N6: Total | O6: 2009-2010 Price | P6: Price per unit
A7: American State Papers, 1789-1838 | O7: Access fee only
A8: Searches run | B8: 2 | C8: 0 | D8: 0 | E8: 4 | F8: 0 | G8: 0 | H8: 1 | I8: 0 | J8: 8 | K8: 1 | L8: 0 | M8: 0 | N8: =SUM(B8:M8) -> 16
A9: Sessions | B9: N/A | C9: N/A | D9: N/A | E9: N/A | F9: N/A | G9: N/A | H9: N/A | I9: N/A | J9: N/A | K9: N/A | L9: N/A | M9: N/A | N9: N/A
B12: 39995 | C12: 40026 | D12: 40057 | E12: 40087 | F12: 40118 | G12: 40148 | H12: 40179 | I12: 40210 | J12: 40238 | K12: 40269 | L12: 40299 | M12: 40330 | N12: Total | O12: 2009-2010 Price | P12: Price per unit
A13: Serial Set Maps | O13: Access fee only
A14: Searches run | B14: 1 | C14: 0 | D14: 0 | E14: 5 | F14: 6 | G14: 0 | H14: 1 | I14: 0 | J14: 36 | K14: 5 | L14: 0 | M14: 7 | N14: =SUM(B14:M14) -> 61
A15: Sessions | B15: N/A | C15: N/A | D15: N/A | E15: N/A | F15: N/A | G15: N/A | H15: N/A | I15: N/A | J15: N/A | K15: N/A | L15: N/A | M15: N/A | N15: N/A
B18: 39995 | C18: 40026 | D18: 40057 | E18: 40087 | F18: 40118 | G18: 40148 | H18: 40179 | I18: 40210 | J18: 40238 | K18: 40269 | L18: 40299 | M18: 40330 | N18: Total | O18: 2009-2010 Price | P18: Price per unit
A19: U.S. Congressional Serial Set 1817-1994 | O19: Access fee only
A20: Searches run | B20: 3 | C20: 58 | D20: 51 | E20: 48 | F20: 14 | G20: 12 | H20: 0 | I20: 12 | J20: 89 | K20: 65 | L20: 0 | M20: 2 | N20: =SUM(B20:M20) -> 354
A21: Sessions | B21: N/A | C21: N/A | D21: N/A | E21: N/A | F21: N/A | G21: N/A | H21: N/A | I21: N/A | J21: N/A | K21: N/A | L21: N/A | M21: N/A | N21: N/A
B24: 39995 | C24: 40026 | D24: 40057 | E24: 40087 | F24: 40118 | G24: 40148 | H24: 40179 | I24: 40210 | J24: 40238 | K24: 40269 | L24: 40299 | M24: 40330 | N24: Total | O24: 2009-2010 Price | P24: Price per unit
A25: Total for Service Newsbank | O25: Access fee only
A26: Searches run | B26: 19 | C26: 60 | D26: 52 | E26: 74 | F26: 43 | G26: 12 | H26: 6 | I26: 287 | J26: 133 | K26: 81 | L26: 0 | M26: 19 | N26: =SUM(B26:M26) -> 786
A27: Sessions | B27: 17 | C27: 55 | D27: 28 | E27: 78 | F27: 42 | G27: 30 | H27: 11 | I27: 47 | J27: 93 | K27: 68 | L27: 14 | M27: 18 | N27: =SUM(B27:M27) -> 501

Sheet OVID
A1: OvidSP
A2: 2009-2010
A4: COUNTER-Compliant?: | B4: Yes (R3)
B6: 39995 | C6: 40026 | D6: 40057 | E6: 40087 | F6: 40118 | G6: 40148 | H6: 40179 | I6: 40210 | J6: 40238 | K6: 40269 | L6: 40299 | M6: 40330 | N6: Total | O6: 2009-2010 Price | P6: Price per unit
A7: Biological Abstracts
A8: Total Searches Run | B8: 18 | C8: 0 | D8: 0 | E8: 0 | F8: 0 | G8: 0 | H8: 0 | I8: 0 | J8: 0 | K8: 0 | L8: 0 | M8: 0 | N8: =SUM(B8:M8) -> 18 | O8: N/A | P8: N/A
A9: Total Sessions | B9: 11 | C9: 0 | D9: 0 | E9: 0 | F9: 0 | G9: 0 | H9: 0 | I9: 0 | J9: 0 | K9: 0 | L9: 0 | M9: 0 | N9: =SUM(B9:M9) -> 11
A10: Turnaways | B10: 0 | C10: 0 | D10: 0 | E10: 0 | F10: 0 | G10: 0 | H10: 0 | I10: 0 | J10: 0 | K10: 0 | L10: 0 | M10: 0 | N10: =SUM(B10:M10) -> 0
B13: 39995 | C13: 40026 | D13: 40057 | E13: 40087 | F13: 40118 | G13: 40148 | H13: 40179 | I13: 40210 | J13: 40238 | K13: 40269 | L13: 40299 | M13: 40330 | N13: Total | O13: 2009-2010 Price | P13: Price per unit
A14: BIOSIS Previews
A15: Total Searches Run | B15: 2 | C15: 0 | D15: 0 | E15: 0 | F15: 0 | G15: 0 | H15: 0 | I15: 0 | J15: 0 | K15: 0 | L15: 0 | M15: 0 | N15: =SUM(B15:M15) -> 2 | O15: N/A | P15: N/A
A16: Total Sessions | B16: 2 | C16: 0 | D16: 0 | E16: 0 | F16: 0 | G16: 0 | H16: 0 | I16: 0 | J16: 0 | K16: 0 | L16: 0 | M16: 0 | N16: =SUM(B16:M16) -> 2
A17: Turnaways | B17: 0 | C17: 0 | D17: 0 | E17: 0 | F17: 0 | G17: 0 | H17: 0 | I17: 0 | J17: 0 | K17: 0 | L17: 0 | M17: 0 | N17: =SUM(B17:M17) -> 0
B20: 39995 | C20: 40026 | D20: 40057 | E20: 40087 | F20: 40118 | G20: 40148 | H20: 40179 | I20: 40210 | J20: 40238 | K20: 40269 | L20: 40299 | M20: 40330 | N20: Total | O20: 2009-2010 Price | P20: Price per unit
A21: Ovid MEDLINE (free)
A22: Total Searches Run | B22: 0 | C22: 0 | D22: 0 | E22: 4 | F22: 0 | G22: 0 | H22: 0 | I22: 0 | J22: 3 | K22: 1 | L22: 0 | M22: 0 | N22: =SUM(B22:M22) -> 8 | O22: N/A | P22: N/A
A23: Total Sessions | B23: 0 | C23: 0 | D23: 0 | E23: 1 | F23: 0 | G23: 0 | H23: 0 | I23: 0 | J23: 2 | K23: 3 | L23: 0 | M23: 0 | N23: =SUM(B23:M23) -> 6
A24: Turnaways | B24: 0 | C24: 0 | D24: 0 | E24: 0 | F24: 0 | G24: 0 | H24: 0 | I24: 0 | J24: 0 | K24: 0 | L24: 0 | M24: 0 | N24: =SUM(B24:M24) -> 0
B27: 39995 | C27: 40026 | D27: 40057 | E27: 40087 | F27: 40118 | G27: 40148 | H27: 40179 | I27: 40210 | J27: 40238 | K27: 40269 | L27: 40299 | M27: 40330 | N27: Total | O27: 2009-2010 Price | P27: Price per unit
A28: Journals@Ovid Full Text
A29: Total Searches Run | B29: 153 | C29: 99 | D29: 545 | E29: 541 | F29: 869 | G29: 310 | H29: 192 | I29: 622 | J29: 891 | K29: 1076 | L29: 243 | M29: 344 | N29: =SUM(B29:M29) -> 5885
A30: Total Sessions | B30: 134 | C30: 82 | D30: 556 | E30: 510 | F30: 805 | G30: 298 | H30: 189 | I30: 531 | J30: 760 | K30: 907 | L30: 216 | M30: 289 | N30: =SUM(B30:M30) -> 5277
A31: Turnaways | B31: 0 | C31: 0 | D31: 0 | E31: 0 | F31: 0 | G31: 0 | H31: 0 | I31: 0 | J31: 0 | K31: 0 | L31: 0 | M31: 0 | N31: =SUM(B31:M31) -> 0
B35: 39995 | C35: 40026 | D35: 40057 | E35: 40087 | F35: 40118 | G35: 40148 | H35: 40179 | I35: 40210 | J35: 40238 | K35: 40269 | L35: 40299 | M35: 40330 | N35: Total | O35: 2009-2010 Price | P35: Price per unit
A36: Your Journals@Ovid
A37: Total Searches Run | B37: 3 | C37: 15 | D37: 73 | E37: 53 | F37: 70 | G37: 16 | H37: 25 | I37: 41 | J37: 92 | K37: 27 | L37: 2 | M37: 0 | N37: =SUM(B37:M37) -> 417
A38: Total Sessions | B38: 3 | C38: 11 | D38: 72 | E38: 44 | F38: 60 | G38: 16 | H38: 12 | I38: 40 | J38: 88 | K38: 21 | L38: 2 | M38: 1 | N38: =SUM(B38:M38) -> 370
A39: Turnaways | B39: 0 | C39: 0 | D39: 0 | E39: 0 | F39: 0 | G39: 0 | H39: 0 | I39: 0 | J39: 0 | K39: 0 | L39: 0 | M39: 0 | N39: =SUM(B39:M39) -> 0
B42: 39995 | C42: 40026 | D42: 40057 | E42: 40087 | F42: 40118 | G42: 40148 | H42: 40179 | I42: 40210 | J42: 40238 | K42: 40269 | L42: 40299 | M42: 40330 | N42: Total | O42: 2009-2010 Price | P42: Price per unit
A43: Total for Service Ovid
A44: Total Searches Run | B44: 176 | C44: 114 | D44: 618 | E44: 598 | F44: 939 | G44: 326 | H44: 217 | I44: 633 | J44: 986 | K44: 1104 | L44: 245 | M44: 344 | N44: =SUM(B44:M44) -> 6300 | O44: N/A | P44: N/A
A45: Total Sessions | B45: 150 | C45: 93 | D45: 628 | E45: 555 | F45: 865 | G45: 314 | H45: 197 | I45: 560 | J45: 560 | K45: 812 | L45: 218 | M45: 290 | N45: =SUM(B45:M45) -> 5242
A46: Turnaways | B46: 0 | C46: 0 | D46: 0 | E46: 0 | F46: 0 | G46: 0 | H46: 0 | I46: 0 | J46: 0 | K46: 0 | L46: 0 | M46: 0 | N46: =SUM(B46:M46) -> 0

Sheet Oxford
A1: Oxford
A2: 2009-2010
A4: COUNTER-Compliant?: | B4: No
B6: 39995 | C6: 40026 | D6: 40057 | E6: 40087 | F6: 40118 | G6: 40148 | H6: 40179 | I6: 40210 | J6: 40238 | K6: 40269 | L6: 40299 | M6: 40330 | N6: Total | O6: 2009-2010 Price | P6: Price per unit
A7: Grove Music Online
A8: Session (Logins) | B8: 18 | C8: 7 | D8: 31 | E8: 44 | F8: 27 | G8: 33 | H8: 20 | I8: 57 | J8: 89 | K8: 69 | L8: 29 | M8: 48 | N8: =SUM(B8:M8) -> 472
A9: Full-Content Units Requested | B9: 28 | C9: 15 | D9: 83 | E9: 81 | F9: 74 | G9: 109 | H9: 22 | I9: 162 | J9: 206 | K9: 139 | L9: 92 | M9: 124 | N9: =SUM(B9:M9) -> 1135
A10: Queries (Searches) | B10: 28 | C10: 9 | D10: 48 | E10: 91 | F10: 51 | G10: 64 | H10: 15 | I10: 182 | J10: 163 | K10: 119 | L10: 88 | M10: 123 | N10: =SUM(B10:M10) -> 981 | O10: 1597.5 | P10: =O10/N10 -> 1.6284404
A11: Turnaways | B11: 0 | C11: 0 | D11: 0 | E11: 248 | F11: 0 | G11: 0 | H11: 0 | I11: 117 | J11: 14 | K11: 3 | L11: 0 | M11: 0 | N11: =SUM(B11:M11) -> 382
A13: Oxford English Dictionary
A14: Session (Logins) | B14: 207 | C14: 105 | D14: 505 | E14: 842 | F14: 809 | G14: 625 | H14: 79 | I14: 454 | J14: 941 | K14: 470 | L14: 368 | M14: 221 | N14: =SUM(B14:M14) -> 5626
A15: Full-Content Units Requested | B15: 624 | C15: 264 | D15: 2373 | E15: 3333 | F15: 2475 | G15: 2138 | H15: 268 | I15: 1697 | J15: 3118 | K15: 1361 | L15: 1054 | M15: 677 | N15: =SUM(B15:M15) -> 19382
A16: Queries (Searches) | B16: 708 | C16: 316 | D16: 2668 | E16: 3272 | F16: 2353 | G16: 2252 | H16: 290 | I16: 1930 | J16: 3290 | K16: 1506 | L16: 1224 | M16: 539 | N16: =SUM(B16:M16) -> 20348 | O16: 2968.02 | P16: =O16/N16 -> 0.14586298
A17: Turnaways | B17: 0 | C17: 0 | D17: 0 | E17: 0 | F17: 0 | G17: 0 | H17: 0 | I17: 0 | J17: 0 | K17: 0 | L17: 0 | M17: 0 | N17: =SUM(B17:M17) -> 0

Sheet ProQuest
A1: ProQuest databases
A2: 2009-2010
A4: COUNTER-Compliant?: | B4: Yes
B6: 39995 | C6: 40026 | D6: 40057 | E6: 40087 | F6: 40118 | G6: 40148 | H6: 40179 | I6: 40210 | J6: 40238 | K6: 40269 | L6: 40299 | M6: 40330 | N6: Total | O6: 2009-2010 Price | P6: Price per unit
A7: ABI/INFORM Dateline
A8: Searches | B8: 731 | C8: 308 | D8: 631 | E8: 1795 | F8: 1709 | G8: 1291 | H8: 626 | I8: 1137 | J8: 1496 | K8: 1824 | L8: 705 | M8: 563 | N8: =SUM(B8:M8) -> 12816 | O8: 0 | P8: N/A
A9: Sessions | B9: 201 | C9: 86 | D9: 215 | E9: 544 | F9: 535 | G9: 378 | H9: 212 | I9: 468 | J9: 573 | K9: 711 | L9: 285 | M9: 214 | N9: =SUM(B9:M9) -> 4422
B12: 39995 | C12: 40026 | D12: 40057 | E12: 40087 | F12: 40118 | G12: 40148 | H12: 40179 | I12: 40210 | J12: 40238 | K12: 40269 | L12: 40299 | M12: 40330 | N12: Total | O12: 2009-2010 Price | P12: Price per unit
A13: ABI/INFORM Global
A14: Searches | B14: 1080 | C14: 397 | D14: 1128 | E14: 2641 | F14: 3403 | G14: 2037 | H14: 1199 | I14: 1927 | J14: 2823 | K14: 2643 | L14: 1062 | M14: 1417 | N14: =SUM(B14:M14) -> 21757 | O14: 19320 | P14: =O14/N14 -> 0.88799007
A15: Sessions | B15: 302 | C15: 120 | D15: 328 | E15: 726 | F15: 1002 | G15: 575 | H15: 440 | I15: 772 | J15: 925 | K15: 897 | L15: 327 | M15: 408 | N15: =SUM(B15:M15) -> 6822
B18: 39995 | C18: 40026 | D18: 40057 | E18: 40087 | F18: 40118 | G18: 40148 | H18: 40179 | I18: 40210 | J18: 40238 | K18: 40269 | L18: 40299 | M18: 40330 | N18: Total | O18: 2009-2010 Price | P18: Price per unit
A19: ABI/INFORM Trade & Industry
A20: Searches | B20: 796 | C20: 287 | D20: 639 | E20: 1552 | F20: 1383 | G20: 1217 | H20: 590 | I20: 1132 | J20: 1377 | K20: 1603 | L20: 702 | M20: 543 | N20: =SUM(B20:M20) -> 11821 | O20: 0 | P20: N/A
A21: Sessions | B21: 211 | C21: 86 | D21: 196 | E21: 490 | F21: 485 | G21: 370 | H21: 232 | I21: 438 | J21: 472 | K21: 595 | L21: 220 | M21: 204 | N21: =SUM(B21:M21) -> 3999
B24: 39995 | C24: 40026 | D24: 40057 | E24: 40087 | F24: 40118 | G24: 40148 | H24: 40179 | I24: 40210 | J24: 40238 | K24: 40269 | L24: 40299 | M24: 40330 | N24: Total | O24: 2009-2010 Price | P24: Price per unit
A25: Dissertations & Theses
A26: Searches | B26: 740 | C26: 384 | D26: 841 | E26: 1823 | F26: 1514 | G26: 1281 | H26: 715 | I26: 1150 | J26: 1430 | K26: 1343 | L26: 683 | M26: 710 | N26: =SUM(B26:M26) -> 12614 | O26: 0 | P26: N/A
B29: 39995 | C29: 40026 | D29: 40057 | E29: 40087 | F29: 40118 | G29: 40148 | H29: 40179 | I29: 40210 | J29: 40238 | K29: 40269 | L29: 40299 | M29: 40330 | N29: Total | O29: 2009-2010 Price | P29: Price per unit
A30: Dissertations & Theses: A&I
A31: Searches | B31: 709 | C31: 362 | D31: 776 | E31: 1737 | F31: 1444 | G31: 1246 | H31: 647 | I31: 1016 | J31: 1334 | K31: 1291 | L31: 614 | M31: 658 | N31: =SUM(B31:M31) -> 11834 | O31: 6010 | P31: =O31/N31 -> 0.50785871
A32: Sessions | B32: 215 | C32: 122 | D32: 265 | E32: 551 | F32: 505 | G32: 350 | H32: 216 | I32: 405 | J32: 476 | K32: 542 | L32: 232 | M32: 231 | N32: =SUM(B32:M32) -> 4110
B35: 39995 | C35: 40026 | D35: 40057 | E35: 40087 | F35: 40118 | G35: 40148 | H35: 40179 | I35: 40210 | J35: 40238 | K35: 40269 | L35: 40299 | M35: 40330 | N35: Total | O35: 2009-2010 Price | P35: Price per unit
A36: Dissertations & Theses @ University of Rhode Island / Rhode Island College
A37: Searches | B37: 740 | C37: 384 | D37: 841 | E37: 1822 | F37: 1514 | G37: 1281 | H37: 715 | I37: 1150 | J37: 1430 | K37: 1343 | L37: 682 | M37: 669 | N37: =SUM(B37:M37) -> 12571 | O37: 0 | P37: N/A
A38: Sessions | B38: 226 | C38: 129 | D38: 285 | E38: 595 | F38: 530 | G38: 369 | H38: 238 | I38: 442 | J38: 504 | K38: 567 | L38: 253 | M38: 247 | N38: =SUM(B38:M38) -> 4385
B41: 39995 | C41: 40026 | D41: 40057 | E41: 40087 | F41: 40118 | G41: 40148 | H41: 40179 | I41: 40210 | J41: 40238 | K41: 40269 | L41: 40299 | M41: 40330 | N41: Total | O41: 2009-2010 Price | P41: Price per unit
A42: Los Angeles Times
A43: Searches | B43: 569 | C43: 285 | D43: 470 | E43: 1442 | F43: 1278 | G43: 927 | H43: n/a | I43: n/a | J43: n/a | K43: n/a | L43: n/a | M43: n/a | N43: =SUM(B43:M43) -> 4971 | O43: 0 | P43: N/A
A44: Sessions | B44: 160 | C44: 81 | D44: 148 | E44: 451 | F44: 439 | G44: 225 | H44: n/a | I44: n/a | J44: n/a | K44: n/a | L44: n/a | M44: n/a | N44: =SUM(B44:M44) -> 1504
B47: 39995 | C47: 40026 | D47: 40057 | E47: 40087 | F47: 40118 | G47: 40148 | H47: 40179 | I47: 40210 | J47: 40238 | K47: 40269 | L47: 40299 | M47: 40330 | N47: Total | O47: 2009-2010 Price | P47: Price per unit
A48: ProQuest Historical Newspapers The New York Times (1851-2006)
A49: Searches | B49: 11 | C49: 21 | D49: 0 | E49: n/a | F49: n/a | G49: n/a | H49: n/a | I49: n/a | J49: n/a | K49: n/a | L49: n/a | M49: n/a | N49: =SUM(B49:M49) -> 32 | O49: 0 | P49: N/A
A50: Sessions | B50: 4 | C50: 4 | D50: 0 | E50: n/a | F50: n/a | G50: n/a | H50: n/a | I50: n/a | J50: n/a | K50: n/a | L50: n/a | M50: n/a | N50: =SUM(B50:M50) -> 8
B53: 39995 | C53: 40026 | D53: 40057 | E53: 40087 | F53: 40118 | G53: 40148 | H53: 40179 | I53: 40210 | J53: 40238 | K53: 40269 | L53: 40299 | M53: 40330 | N53: Total | O53: 2009-2010 Price | P53: Price per unit
A54: ProQuest National Newspapers Core
A55: Searches | B55: 699 | C55: 311 | D55: 735 | E55: 1590 | F55: 1605 | G55: 1291 | H55: 725 | I55: 1753 | J55: 1197 | K55: 1478 | L55: 702 | M55: 600 | N55: =SUM(B55:M55) -> 12686 | O55: 3370 | P55: =O55/N55 -> 0.26564717
A56: Sessions | B56: 191 | C56: 87 | D56: 226 | E56: 496 | F56: 560 | G56: 372 | H56: 253 | I56: 523 | J56: 440 | K56: 586 | L56: 211 | M56: 205 | N56: =SUM(B56:M56) -> 4150
B59: 39995 | C59: 40026 | D59: 40057 | E59: 40087 | F59: 40118 | G59: 40148 | H59: 40179 | I59: 40210 | J59: 40238 | K59: 40269 | L59: 40299 | M59: 40330 | N59: Total | O59: 2009-2010 Price | P59: Price per unit
A60: ProQuest Newspapers
...

Sheet ReferenceUSA
A1: ReferenceUSA
A2: 2009-2010
A4: COUNTER-Compliant?: | B4: No
B6: 39995 | C6: 40026 | D6: 40057 | E6: 40087 | F6: 40118 | G6: 40148 | H6: 40179 | I6: 40210 | J6: 40238 | K6: 40269 | L6: 40299 | M6: 40330 | N6: Total
A7: U.S. Business
A8: Logins | B8: 32 | C8: 22 | D8: 64 | E8: 151 | F8: 88 | G8: 53 | H8: 47 | I8: 177 | J8: 107 | K8: 96 | L8: 58 | M8: 88 | N8: =SUM(B8:M8) -> 983
A9: # of Searches | B9: 127 | C9: 99 | D9: 62 | E9: 286 | F9: 125 | G9: 86 | H9: 135 | I9: 575 | J9: 274 | K9: 279 | L9: 122 | M9: 1158 | N9: =SUM(B9:M9) -> 3328
A10: # of Result Pages | B10: 471 | C10: 432 | D10: 137 | E10: 1006 | F10: 559 | G10: 140 | H10: 964 | I10: 1960 | J10: 533 | K10: 373 | L10: 189 | M10: 1121 | N10: =SUM(B10:M10) -> 7885
A11: Total Records on Results | B11: 11677 | C11: 10800 | D11: 3425 | E11: 25150 | F11: 13975 | G11: 3500 | H11: 24100 | I11: 49000 | J11: 11771 | K11: 6372 | L11: 3108 | M11: 18964 | N11: =SUM(B11:M11) -> 181842
A12: # of Detail Views | B12: 23 | C12: 19 | D12: 45 | E12: 270 | F12: 65 | G12: 126 | H12: 0 | I12: 439 | J12: 196 | K12: 160 | L12: 95 | M12: 244 | N12: =SUM(B12:M12) -> 1682
A13: Total Detail Records Viewed | B13: 23 | C13: 19 | D13: 45 | E13: 270 | F13: 65 | G13: 126 | H13: 0 | I13: 439 | J13: 196 | K13: 160 | L13: 95 | M13: 244 | N13: =SUM(B13:M13) -> 1682
A14: # of Prints | B14: 10 | C14: 5 | D14: 2 | E14: 52 | F14: 3 | G14: 0 | H14: 0 | I14: 0 | J14: 6 | K14: 0 | L14: 8 | M14: 4 | N14: =SUM(B14:M14) -> 90
A15: Total Records Printed | B15: 24 | C15: 101 | D15: 50 | E15: 1956 | F15: 2395 | G15: 0 | H15: 0 | I15: 0 | J15: 50 | K15: 0 | L15: 9 | M15: 16 | N15: =SUM(B15:M15) -> 4601
A16: # of Downloads | B16: 71 | C16: 69 | D16: 1 | E16: 19 | F16: 31 | G16: 180 | H16: 144 | I16: 176 | J16: 24 | K16: 11 | L16: 17 | M16: 40 | N16: =SUM(B16:M16) -> 783
A17: Total Records Downloaded | B17: 3479 | C17: 3425 | D17: 25 | E17: 471 | F17: 1054 | G17: 0 | H17: 5779 | I17: 7711 | J17: 782 | K17: 223 | L17: 466 | M17: 1690 | N17: =SUM(B17:M17) -> 25105
A18: # of Emails | B18: 0 | C18: 0 | D18: 0 | E18: 0 | F18: 0 | G18: 0 | H18: 0 | I18: 0 | J18: 0 | K18: 0 | L18: 0 | M18: 0 | N18: =SUM(B18:M18) -> 0
A19: Total Records Emailed | B19: 0 | C19: 0 | D19: 0 | E19: 0 | F19: 0 | G19: 0 | H19: 0 | I19: 0 | J19: 0 | K19: 0 | L19: 0 | M19: 0 | N19: =SUM(B19:M19) -> 0
... A21: Total Records Purchased | B21: 0 | C21: 0 | D21: 0 | E21: 0 | F21: 0 | G21: 0 | H21: 0 | I21: 0 | J21: 0 | K21: 0 | L21: 0 | M21: 0 | N21: =SUM(B21:M21) -> 0
B24: 39995 | C24: 40026 | D24: 40057 | E24: 40087 | F24: 40118 | G24: 40148 | H24: 40179 | I24: 40210 | J24: 40238 | K24: 40269 | L24: 40299 | M24: 40330 | N24: Total
A25: U.S. Residential
A26: Logins | B26: 32 | C26: 22 | D26: 64 | E26: 151 | F26: 88 | G26: 53 | H26: 47 | I26: 177 | J26: 107 | K26: 96 | L26: 58 | M26: 88 | N26: =SUM(B26:M26) -> 983
A27: # of Searches | B27: 8 | C27: 14 | D27: 28 | E27: 18 | F27: 20 | G27: 3 | H27: 9 | I27: 20 | J27: 33 | K27: 32 | L27: 157 | M27: 38 | N27: =SUM(B27:M27) -> 380
A28: # of Result Pages | B28: 9 | C28: 18 | D28: 40 | E28: 31 | F28: 31 | G28: 3 | H28: 9 | I28: 39 | J28: 75 | K28: 40 | L28: 207 | M28: 34 | N28: =SUM(B28:M28) -> 536
