Workbook

Sheet Data
A1: Instructions to Teachers: Fill in your classroom information into the brown boxes. Fill in your name and choose your school from the drop down menu. Each month, fill in as many of the "grade" and "no. of students" boxes you need for your class. Enter your number of minutes of In Motion daily activity and send the whole file into the co-ordinator at the end of each month. The rest of the cells in spreadsheet are locked. You can view or print the summary results on the Charts tab at the bottom of the page.
A2: Teacher's Name: | M2: School:
A3: September | D3: October | G3: November | J3: December | M3: January | P3: February | S3: March | V3: April | Y3: May | AB3: June
A4: grade | D4: grade | G4: grade | J4: grade | M4: grade | P4: grade | S4: grade | V4: grade | Y4: grade | AB4: grade
A5: no. of students | D5: no. of students | G5: no. of students | J5: no. of students | M5: no. of students | P5: no. of students | S5: no. of students | V5: no. of students | Y5: no. of students | AB5: no. of students
A6: grade | D6: grade | G6: grade | J6: grade | M6: grade | P6: grade | S6: grade | V6: grade | Y6: grade | AB6: grade
A7: no. of students | D7: no. of students | G7: no. of students | J7: no. of students | M7: no. of students | P7: no. of students | S7: no. of students | V7: no. of students | Y7: no. of students | AB7: no. of students
A8: grade | D8: grade | G8: grade | J8: grade | M8: grade | P8: grade | S8: grade | V8: grade | Y8: grade | AB8: grade
A9: no. of students | D9: no. of students | G9: no. of students | J9: no. of students | M9: no. of students | P9: no. of students | S9: no. of students | V9: no. of students | Y9: no. of students | AB9: no. of students
A12: 40422 | C12: 1 | D12: 40819 | F12: 1 | G12: 40483 | I12: 1 | J12: 40513 | L12: 1 | M12: 40552 | O12: 1 | P12: 40210 | R12: 1 | S12: 40238 | U12: 1 | V12: 40635 | X12: 1 | Y12: 40299 | AA12: 1 | AB12: 40330 | AD12: 1
A13: 40423 | C13: 2 | D13: 40455 | F13: 2 | G13: 40484 | I13: 2 | J13: 40514 | L13: 2 | M13: 40188 | O13: 2 | P13: 40211 | R13: 2 | S13: 40239 | U13: 2 | V13: 40636 | X13: 2 | Y13: 40300 | AA13: 2 | AB13: 40698 | AD13: 2
A14: 40792 | C14: 3 | D14: 40456 | F14: 3 | G14: 40485 | I14: 3 | J14: 40882 | L14: 3 | M14: 40189 | O14: 3 | P14: 40212 | R14: 3 | S14: 40607 | U14: 3 | V14: 40637 | X14: 3 | Y14: 40301 | AA14: 3 | AB14: 40699 | AD14: 3
A15: 40793 | C15: 4 | D15: 40457 | F15: 4 | G15: 40854 | I15: 4 | J15: 40518 | L15: 4 | M15: 40190 | O15: 4 | P15: 40580 | R15: 4 | S15: 40608 | U15: 4 | V15: 40638 | X15: 4 | Y15: 40302 | AA15: 4 | AB15: 40335 | AD15: 4
A16: 40429 | C16: 5 | D16: 40458 | F16: 5 | G16: 40490 | I16: 5 | J16: 40519 | L16: 5 | M16: 40191 | O16: 5 | P16: 40216 | R16: 5 | S16: 40244 | U16: 5 | V16: 40649 | X16: 5 | Y16: 40670 | AA16: 5 | AB16: 40336 | AD16: 5
A17: 40430 | C17: 6 | D17: 40827 | F17: 6 | G17: 40491 | I17: 6 | J17: 40520 | L17: 6 | M17: 40559 | O17: 6 | P17: 40217 | R17: 6 | S17: 40245 | U17: 6 | V17: 40650 | X17: 6 | Y17: 40671 | AA17: 6 | AB17: 40337 | AD17: 6
A18: 40798 | C18: 7 | D18: 40828 | F18: 7 | G18: 40492 | I18: 7 | J18: 40521 | L18: 7 | M18: 40195 | O18: 7 | P18: 40218 | R18: 7 | S18: 40614 | U18: 7 | V18: 40651 | X18: 7 | Y18: 40672 | AA18: 7 | AB18: 40705 | AD18: 7
A19: 40434 | C19: 8 | D19: 40829 | F19: 8 | G19: 40861 | I19: 8 | J19: 40889 | L19: 8 | M19: 40196 | O19: 8 | P19: 40219 | R19: 8 | S19: 13 | U19: 8 | V19: 40652 | X19: 8 | Y19: 40673 | AA19: 8 | AB19: 40706 | AD19: 8
A20: 40435 | C20: 9 | D20: 40830 | F20: 9 | G20: 40497 | I20: 9 | J20: 40525 | L20: 9 | M20: 40197 | O20: 9 | P20: 40587 | R20: 9 | S20: 40251 | U20: 9 | V20: 40653 | X20: 9 | Y20: 40674 | AA20: 9 | AB20: 40342 | AD20: 9
A21: 40436 | C21: 10 | D21: 40833 | F21: 10 | G21: 40498 | I21: 10 | J21: 40526 | L21: 10 | M21: 40198 | O21: 10 | P21: 40223 | R21: 10 | S21: 40252 | U21: 10 | V21: 40656 | X21: 10 | Y21: 40677 | AA21: 10 | AB21: 40343 | AD21: 10
A22: 40437 | C22: 11 | D22: 40834 | F22: 11 | G22: 40499 | I22: 11 | J22: 40527 | L22: 11 | M22: 40566 | O22: 11 | P22: 40224 | R22: 11 | S22: 40253 | U22: 11 | V22: 40657 | X22: 11 | Y22: 40678 | AA22: 11 | AB22: 40344 | AD22: 11
A23: 40805 | C23: 12 | D23: 40835 | F23: 12 | G23: 40500 | I23: 12 | J23: 40528 | L23: 12 | M23: 40202 | O23: 12 | P23: 40225 | R23: 12 | S23: 40621 | U23: 12 | V23: 40658 | X23: 12 | Y23: 40679 | AA23: 12 | AB23: 40712 | AD23: 12
... A26: 40808 | C26: 15 | D26: 40840 | F26: 15 | G26: 40506 | I26: 15 | J26: 40533 | L26: 15 | M26: 40205 | O26: 15 | P26: 40237 | R26: 15 | S26: 40259 | U26: 15 | V26: 40663 | X26: 15 | Y26: 40685 | AA26: 15 | AB26: 40350 | AD26: 15
A27: 40812 | C27: 16 | D27: 40841 | F27: 16 | G27: 40507 | I27: 16 | J27: 40534 | L27: 16 | M27: 40573 | O27: 16 | P27: 29 Feb | R27: 16 | S27: 40625 | U27: 16 | X27: 16 | Y27: 40686 | AA27: 16 | AB27: 40351 | AD27: 16
A28: 40813 | C28: 17 | D28: 40842 | F28: 17 | G28: 40875 | I28: 17 | L28: 17 | M28: 40209 | O28: 17 | R28: 17 | S28: 40629 | U28: 17 | X28: 17 | Y28: 40687 | AA28: 17 | AB28: 40719 | AD28: 17
A29: 40814 | C29: 18 | D29: 40843 | F29: 18 | G29: 40511 | I29: 18 | L29: 18 | O29: 18 | R29: 18 | S29: 40265 | U29: 18 | X29: 18 | Y29: 40688 | AA29: 18 | AB29: 40720 | AD29: 18
A30: 40815 | C30: 19 | D30: 40844 | F30: 19 | G30: 40512 | I30: 19 | L30: 19 | O30: 19 | R30: 19 | S30: 40266 | U30: 18 | X30: 19 | Y30: 40692 | AA30: 19 | AB30: 40721 | AD30: 19
A31: 40816 | C31: 20 | D31: 40847 | F31: 20 | I31: 20 | L31: 20 | O31: 20 | R31: 20 | S31: 40267 | U31: 18 | X31: 20 | Y31: 40328 | AA31: 20 | AD31: 20
C32: 21 | F32: 21 | I32: 21 | L32: 21 | O32: 21 | R32: 21 | U32: 18 | X32: 21 | Y32: 40329 | AA32: 21 | AD32: 21
A33: month | B33: =A3 -> September | E33: =D3 -> October | H33: =G3 -> November | K33: =J3 -> December | N33: =M3 -> January | Q33: =P3 -> February | T33: =S3 -> March | W33: =V3 -> April | Z33: =Y3 -> May | AC33: =AB3 -> June
A34: average | B34: =IF(AND(B12="",B13="",B14="",B15="",B16="",B17="",B18="",B19="",B20="",B21="",B22="",B23="",B24="",B25="",B26="",B27=""),"",AVERAGE(B12:B32)) | D34: average | E34: =IF(AND(E12="",E13="",E14="",E15="",E16="",E17="",E18="",E19="",E20="",E21="",E22="",E23="",E24="",E25="",E26="",E27=""),"",AVERAGE(E12:E32)) | G34: average | H34: =IF(AND(H12="",H13="",H14="",H15="",H16="",H17="",H18="",H19="",H20="",H21="",H22="",H23="",H24="",H25="",H26="",H27=""),"",AVERAGE(H12:H32)) | J34: average | K34: =IF(AND(K12="",K13="",K14="",K15="",K16="",K17="",K18="",K19="",K20="",K21="",K22="",K23="",K24="",K25="",K26="",K27=""),"",AVERAGE(K12:K32)) | M34: average | N34: =IF(AND(N12="",N13="",N14="",N15="",N16="",N17="",N18="",N19="",N20="",N21="",N22="",N23="",N24="",N25="",N26="",N27=""),"",AVERAGE(N12:N32)) | P34: average | Q34: =IF(AND(Q12="",Q13="",Q14="",Q15="",Q16="",Q17="",Q18="",Q19="",Q20="",Q21="",Q22="",Q23="",Q24="",Q25="",Q26="",Q27=""),"",AVERAGE(Q12:Q32)) | S34: average | T34: =IF(AND(T12="",T13="",T14="",T15="",T16="",T17="",T18="",T19="",T20="",T21="",T22="",T23="",T24="",T25="",T26="",T27=""),"",AVERAGE(T12:T32)) | V34: average | W34: =IF(AND(W12="",W13="",W14="",W15="",W16="",W17="",W18="",W19="",W20="",W21="",W22="",W23="",W24="",W25="",W26="",W27=""),"",AVERAGE(W12:W32)) | Y34: average | Z34: =IF(AND(Z12="",Z13="",Z14="",Z15="",Z16="",Z17="",Z18="",Z19="",Z20="",Z21="",Z22="",Z23="",Z24="",Z25="",Z26="",Z27=""),"",AVERAGE(Z12:Z32)) | AB34: average | AC34: =IF(AND(AC12="",AC13="",AC14="",AC15="",AC16="",AC17="",AC18="",AC19="",AC20="",AC21="",AC22="",AC23="",AC24="",AC25="",AC26="",AC27=""),"",AVERAGE(AC12:AC32))
A35: rate | B35: =IF(AND(B12="",B13="",B14="",B15="",B16="",B17="",B18="",B19="",B20="",B21="",B22="",B23="",B24="",B25="",B26="",B27=""),"",SLOPE(B12:B32,C12:C32)) | D35: rate | E35: =IF(AND(E12="",E13="",E14="",E15="",E16="",E17="",E18="",E19="",E20="",E21="",E22="",E23="",E24="",E25="",E26="",E27=""),"",SLOPE(E12:E32,F12:F32)) | G35: rate | H35: =IF(AND(H12="",H13="",H14="",H15="",H16="",H17="",H18="",H19="",H20="",H21="",H22="",H23="",H24="",H25="",H26="",H27=""),"",SLOPE(H12:H32,I12:I32)) | J35: rate | K35: =IF(AND(K12="",K13="",K14="",K15="",K16="",K17="",K18="",K19="",K20="",K21="",K22="",K23="",K24="",K25="",K26="",K27=""),"",SLOPE(K12:K32,L12:L32)) | M35: rate | N35: =IF(AND(N12="",N13="",N14="",N15="",N16="",N17="",N18="",N19="",N20="",N21="",N22="",N23="",N24="",N25="",N26="",N27=""),"",SLOPE(N12:N32,O12:O32)) | P35: rate | Q35: =IF(AND(Q12="",Q13="",Q14="",Q15="",Q16="",Q17="",Q18="",Q19="",Q20="",Q21="",Q22="",Q23="",Q24="",Q25="",Q26="",Q27=""),"",SLOPE(Q12:Q32,R12:R32)) | S35: rate | T35: =IF(AND(T12="",T13="",T14="",T15="",T16="",T17="",T18="",T19="",T20="",T21="",T22="",T23="",T24="",T25="",T26="",T27=""),"",SLOPE(T12:T32,U12:U32)) | V35: rate | W35: =IF(AND(W12="",W13="",W14="",W15="",W16="",W17="",W18="",W19="",W20="",W21="",W22="",W23="",W24="",W25="",W26="",W27=""),"",SLOPE(W12:W32,X12:X32)) | Y35: rate | Z35: =IF(AND(Z12="",Z13="",Z14="",Z15="",Z16="",Z17="",Z18="",Z19="",Z20="",Z21="",Z22="",Z23="",Z24="",Z25="",Z26="",Z27=""),"",SLOPE(Z12:Z32,AA12:AA32)) | AB35: rate | AC35: =IF(AND(AC12="",AC13="",AC14="",AC15="",AC16="",AC17="",AC18="",AC19="",AC20="",AC21="",AC22="",AC23="",AC24="",AC25="",AC26="",AC27=""),"",SLOPE(AC12:AC32,AD12:AD32))
A36: school | B36: =O2 -> 0 | D36: school | E36: =O2 -> 0 | G36: school | H36: =O2 -> 0 | J36: school | K36: =O2 -> 0 | M36: school | N36: =O2 -> 0 | P36: school | Q36: =O2 -> 0 | S36: school | T36: =O2 -> 0 | V36: school | W36: =O2 -> 0 | Y36: school | Z36: =O2 -> 0 | AB36: school | AC36: =O2 -> 0
A37: 0 min | B37: =COUNTIF(B12:B32,0)/COUNT(B12:B32) -> #DIV/0! | D37: 0 min | E37: =COUNTIF(E12:E30,0)/COUNT(E12:E30) -> #DIV/0! | G37: 0 min | H37: =COUNTIF(H12:H32,0)/COUNT(H12:H32) -> #DIV/0! | J37: 0 min | K37: =COUNTIF(K12:K28,0)/COUNT(K12:K28) -> #DIV/0! | M37: 0 min | N37: =COUNTIF(N12:N30,0)/COUNT(N12:N30) -> #DIV/0! | P37: 0 min | Q37: =COUNTIF(Q12:Q29,0)/COUNT(Q12:Q29) -> #DIV/0! | S37: 0 min | T37: =COUNTIF(T12:T32,0)/COUNT(T12:T32) -> #DIV/0! | V37: 0 min | W37: =COUNTIF(W12:W27,0)/COUNT(W12:W27) -> #DIV/0! | Y37: 0 min | Z37: =COUNTIF(Z12:Z32,0)/COUNT(Z12:Z32) -> #DIV/0! | AB37: 0 min | AC37: =COUNTIF(AC12:AC33,0)/COUNT(AC12:AC33) -> #DIV/0!
A38: 1-5 min | B38: =(COUNTIF(B12:B32,"<6")-COUNTIF(B12:B32,0))/COUNT(B12:B32) -> #DIV/0! | D38: 1-5 min | E38: =(COUNTIF(E12:E30,"<6")-COUNTIF(E12:E30,0))/COUNT(E12:E30) -> #DIV/0! | G38: 1-5 min | H38: =(COUNTIF(H12:H32,"<6")-COUNTIF(H12:H32,0))/COUNT(H12:H32) -> #DIV/0! | J38: 1-5 min | K38: =(COUNTIF(K12:K28,"<6")-COUNTIF(K12:K28,0))/COUNT(K12:K28) -> #DIV/0! | M38: 1-5 min | N38: =(COUNTIF(N12:N30,"<6")-COUNTIF(N12:N30,0))/COUNT(N12:N30) -> #DIV/0! | P38: 1-5 min | Q38: =(COUNTIF(Q12:Q29,"<6")-COUNTIF(Q12:Q29,0))/COUNT(Q12:Q29) -> #DIV/0! | S38: 1-5 min | T38: =(COUNTIF(T12:T32,"<6")-COUNTIF(T12:T32,0))/COUNT(T12:T32) -> #DIV/0! | V38: 1-5 min | W38: =(COUNTIF(W12:W27,"<6")-COUNTIF(W12:W27,0))/COUNT(W12:W27) -> #DIV/0! | Y38: 1-5 min | Z38: =(COUNTIF(Z12:Z32,"<6")-COUNTIF(Z12:Z32,0))/COUNT(Z12:Z32) -> #DIV/0! | AB38: 1-5 min | AC38: =(COUNTIF(AC12:AC33,"<6")-COUNTIF(AC12:AC33,0))/COUNT(AC12:AC33) -> #DIV/0!
A39: 6-10 min | B39: =(COUNTIF(B12:B32,"<11")-COUNTIF(B12:B32,"<6"))/COUNT(B12:B32) -> #DIV/0! | D39: 6-10 min | E39: =(COUNTIF(E12:E30,"<11")-COUNTIF(E12:E30,"<6"))/COUNT(E12:E30) -> #DIV/0! | G39: 6-10 min | H39: =(COUNTIF(H12:H32,"<11")-COUNTIF(H12:H32,"<6"))/COUNT(H12:H32) -> #DIV/0! | J39: 6-10 min | K39: =(COUNTIF(K12:K28,"<11")-COUNTIF(K12:K28,"<6"))/COUNT(K12:K28) -> #DIV/0! | M39: 6-10 min | N39: =(COUNTIF(N12:N30,"<11")-COUNTIF(N12:N30,"<6"))/COUNT(N12:N30) -> #DIV/0! | P39: 6-10 min | Q39: =(COUNTIF(Q12:Q29,"<11")-COUNTIF(Q12:Q29,"<6"))/COUNT(Q12:Q29) -> #DIV/0! | S39: 6-10 min | T39: =(COUNTIF(T12:T32,"<11")-COUNTIF(T12:T32,"<6"))/COUNT(T12:T32) -> #DIV/0! | V39: 6-10 min | W39: =(COUNTIF(W12:W27,"<11")-COUNTIF(W12:W27,"<6"))/COUNT(W12:W27) -> #DIV/0! | Y39: 6-10 min | Z39: =(COUNTIF(Z12:Z32,"<11")-COUNTIF(Z12:Z32,"<6"))/COUNT(Z12:Z32) -> #DIV/0! | AB39: 6-10 min | AC39: =(COUNTIF(AC12:AC33,"<11")-COUNTIF(AC12:AC33,"<6"))/COUNT(AC12:AC33) -> #DIV/0!
A40: 11-15 min | B40: =(COUNTIF(B12:B32,"<16")-COUNTIF(B12:B32,"<11"))/COUNT(B12:B32) -> #DIV/0! | D40: 11-15 min | E40: =(COUNTIF(E12:E30,"<16")-COUNTIF(E12:E30,"<11"))/COUNT(E12:E30) -> #DIV/0! | G40: 11-15 min | H40: =(COUNTIF(H12:H32,"<16")-COUNTIF(H12:H32,"<11"))/COUNT(H12:H32) -> #DIV/0! | J40: 11-15 min | K40: =(COUNTIF(K12:K28,"<16")-COUNTIF(K12:K28,"<11"))/COUNT(K12:K28) -> #DIV/0! | M40: 11-15 min | N40: =(COUNTIF(N12:N30,"<16")-COUNTIF(N12:N30,"<11"))/COUNT(N12:N30) -> #DIV/0! | P40: 11-15 min | Q40: =(COUNTIF(Q12:Q29,"<16")-COUNTIF(Q12:Q29,"<11"))/COUNT(Q12:Q29) -> #DIV/0! | S40: 11-15 min | T40: =(COUNTIF(T12:T32,"<16")-COUNTIF(T12:T32,"<11"))/COUNT(T12:T32) -> #DIV/0! | V40: 11-15 min | W40: =(COUNTIF(W12:W27,"<16")-COUNTIF(W12:W27,"<11"))/COUNT(W12:W27) -> #DIV/0! | Y40: 11-15 min | Z40: =(COUNTIF(Z12:Z32,"<16")-COUNTIF(Z12:Z32,"<11"))/COUNT(Z12:Z32) -> #DIV/0! | AB40: 11-15 min | AC40: =(COUNTIF(AC12:AC33,"<16")-COUNTIF(AC12:AC33,"<11"))/COUNT(AC12:AC33) -> #DIV/0!
A41: 16-20 min | B41: =(COUNTIF(B12:B32,"<21")-COUNTIF(B12:B32,"<16"))/COUNT(B12:B32) -> #DIV/0! | D41: 16-20 min | E41: =(COUNTIF(E12:E30,"<21")-COUNTIF(E12:E30,"<16"))/COUNT(E12:E30) -> #DIV/0! | G41: 16-20 min | H41: =(COUNTIF(H12:H32,"<21")-COUNTIF(H12:H32,"<16"))/COUNT(H12:H32) -> #DIV/0! | J41: 16-20 min | K41: =(COUNTIF(K12:K28,"<21")-COUNTIF(K12:K28,"<16"))/COUNT(K12:K28) -> #DIV/0! | M41: 16-20 min | N41: =(COUNTIF(N12:N30,"<21")-COUNTIF(N12:N30,"<16"))/COUNT(N12:N30) -> #DIV/0! | P41: 16-20 min | Q41: =(COUNTIF(Q12:Q29,"<21")-COUNTIF(Q12:Q29,"<16"))/COUNT(Q12:Q29) -> #DIV/0! | S41: 16-20 min | T41: =(COUNTIF(T12:T32,"<21")-COUNTIF(T12:T32,"<16"))/COUNT(T12:T32) -> #DIV/0! | V41: 16-20 min | W41: =(COUNTIF(W12:W27,"<21")-COUNTIF(W12:W27,"<16"))/COUNT(W12:W27) -> #DIV/0! | Y41: 16-20 min | Z41: =(COUNTIF(Z12:Z32,"<21")-COUNTIF(Z12:Z32,"<16"))/COUNT(Z12:Z32) -> #DIV/0! | AB41: 16-20 min | AC41: =(COUNTIF(AC12:AC33,"<21")-COUNTIF(AC12:AC33,"<16"))/COUNT(AC12:AC33) -> #DIV/0!
A42: 21-25 min | B42: =(COUNTIF(B12:B32,"<26")-COUNTIF(B12:B32,"<21"))/COUNT(B12:B32) -> #DIV/0! | D42: 21-25 min | E42: =(COUNTIF(E12:E30,"<26")-COUNTIF(E12:E30,"<21"))/COUNT(E12:E30) -> #DIV/0! | G42: 21-25 min | H42: =(COUNTIF(H12:H32,"<26")-COUNTIF(H12:H32,"<21"))/COUNT(H12:H32) -> #DIV/0! | J42: 21-25 min | K42: =(COUNTIF(K12:K28,"<26")-COUNTIF(K12:K28,"<21"))/COUNT(K12:K28) -> #DIV/0! | M42: 21-25 min | N42: =(COUNTIF(N12:N30,"<26")-COUNTIF(N12:N30,"<21"))/COUNT(N12:N30) -> #DIV/0! | P42: 21-25 min | Q42: =(COUNTIF(Q12:Q29,"<26")-COUNTIF(Q12:Q29,"<21"))/COUNT(Q12:Q29) -> #DIV/0! | S42: 21-25 min | T42: =(COUNTIF(T12:T32,"<26")-COUNTIF(T12:T32,"<21"))/COUNT(T12:T32) -> #DIV/0! | V42: 21-25 min | W42: =(COUNTIF(W12:W27,"<26")-COUNTIF(W12:W27,"<21"))/COUNT(W12:W27) -> #DIV/0! | Y42: 21-25 min | Z42: =(COUNTIF(Z12:Z32,"<26")-COUNTIF(Z12:Z32,"<21"))/COUNT(Z12:Z32) -> #DIV/0! | AB42: 21-25 min | AC42: =(COUNTIF(AC12:AC33,"<26")-COUNTIF(AC12:AC33,"<21"))/COUNT(AC12:AC33) -> #DIV/0!
A43: 26-30 min | B43: =(COUNTIF(B12:B32,"<31")-COUNTIF(B12:B32,"<26"))/COUNT(B12:B32) -> #DIV/0! | D43: 26-30 min | E43: =(COUNTIF(E12:E30,"<31")-COUNTIF(E12:E30,"<26"))/COUNT(E12:E30) -> #DIV/0! | G43: 26-30 min | H43: =(COUNTIF(H12:H32,"<31")-COUNTIF(H12:H32,"<26"))/COUNT(H12:H32) -> #DIV/0! | J43: 26-30 min | K43: =(COUNTIF(K12:K28,"<31")-COUNTIF(K12:K28,"<26"))/COUNT(K12:K28) -> #DIV/0! | M43: 26-30 min | N43: =(COUNTIF(N12:N30,"<31")-COUNTIF(N12:N30,"<26"))/COUNT(N12:N30) -> #DIV/0! | P43: 26-30 min | Q43: =(COUNTIF(Q12:Q29,"<31")-COUNTIF(Q12:Q29,"<26"))/COUNT(Q12:Q29) -> #DIV/0! | S43: 26-30 min | T43: =(COUNTIF(T12:T32,"<31")-COUNTIF(T12:T32,"<26"))/COUNT(T12:T32) -> #DIV/0! | V43: 26-30 min | W43: =(COUNTIF(W12:W27,"<31")-COUNTIF(W12:W27,"<26"))/COUNT(W12:W27) -> #DIV/0! | Y43: 26-30 min | Z43: =(COUNTIF(Z12:Z32,"<31")-COUNTIF(Z12:Z32,"<26"))/COUNT(Z12:Z32) -> #DIV/0! | AB43: 26-30 min | AC43: =(COUNTIF(AC12:AC33,"<31")-COUNTIF(AC12:AC33,"<26"))/COUNT(AC12:AC33) -> #DIV/0!
A44: 31+ min | B44: =(COUNTIF(B12:B32,">30")/COUNT(B12:B32)) -> #DIV/0! | D44: 31+ min | E44: =(COUNTIF(E12:E30,">30")/COUNT(E12:E30)) -> #DIV/0! | G44: 31+ min | H44: =(COUNTIF(H12:H32,">30")/COUNT(H12:H32)) -> #DIV/0! | J44: 31+ min | K44: =(COUNTIF(K12:K28,">30")/COUNT(K12:K28)) -> #DIV/0! | M44: 31+ min | N44: =(COUNTIF(N12:N30,">30")/COUNT(N12:N30)) -> #DIV/0! | P44: 31+ min | Q44: =(COUNTIF(Q12:Q29,">30")/COUNT(Q12:Q29)) -> #DIV/0! | S44: 31+ min | T44: =(COUNTIF(T12:T32,">30")/COUNT(T12:T32)) -> #DIV/0! | V44: 31+ min | W44: =(COUNTIF(W12:W27,">30")/COUNT(W12:W27)) -> #DIV/0! | Y44: 31+ min | Z44: =(COUNTIF(Z12:Z32,">30")/COUNT(Z12:Z32)) -> #DIV/0! | AB44: 31+ min | AC44: =(COUNTIF(AC12:AC33,">30")/COUNT(AC12:AC33)) -> #DIV/0!
...

Sheet Charts
A1: September In Motion Results | J1: October In Motion Results
B2: Class: | E2: =Data!$F$2 -> 0 | K2: Class: | N2: =Data!$F$2 -> 0
A3: This month we are | D3: =IF(Data!B35>0,"improving by","not improving by") -> improving by | F3: =Data!B35 | G3: min/day | J3: This month we are | N3: =IF(Data!E35>0,"improving by","not improving by") -> improving by | P3: =Data!E35 | Q3: min/day
A22: November In Motion Results | J22: December Motion Results
C23: Class: | E23: =Data!$F$2 -> 0 | K23: Class: | N23: =Data!$F$2 -> 0
A24: This month we are | D24: =IF(Data!H35>0,"improving by","not improving by") -> improving by | F24: =Data!H35 | G24: min/day | J24: This month we are | M24: =IF(Data!K35>0,"improving by","not improving by") -> improving by | O24: =Data!K35 | P24: min/day
A43: January In Motion Results | J43: February In Motion Results
B44: Class: | E44: =Data!$F$2 -> 0 | K44: Class: | N44: =Data!$F$2 -> 0
A45: This month we are | D45: =IF(Data!N35>0,"improving by","not improving by") -> improving by | F45: =Data!N35 | G45: min/day | J45: This month we are | M45: =IF(Data!Q35>0,"improving by","not improving by") -> improving by | O45: =Data!Q35 | P45: min/day
A64: March In Motion Results | J64: April In Motion Results
B65: Class: | E65: =Data!$F$2 -> 0 | K65: Class: | N65: =Data!$F$2 -> 0
A66: This month we are | D66: =IF(Data!T35>0,"improving by","not improving by") -> improving by | F66: =Data!T35 | G66: min/day | J66: This month we are | M66: =IF(Data!W35>0,"improving by","not improving by") -> improving by | O66: =Data!W35 | P66: min/day
A85: May In Motion Results | J85: June In Motion Results
B86: Class: | E86: =Data!$F$2 -> 0 | K86: Class: | N86: =Data!$F$2 -> 0
A87: This month we are | D87: =IF(Data!Z35>0,"improving by","not improving by") -> improving by | F87: =Data!Z35 | G87: min/day | J87: This month we are | M87: =IF(Data!AC35>0,"improving by","not improving by") -> improving by | O87: =Data!AC35 | P87: min/day
A107: Month by Month Average | K107: Month by Month Changes (min/day)
B108: Class: | E108: =Data!$F$2 -> 0
K109: September | M109: =Data!B35
K110: October | M110: =Data!E35
K111: November | M111: =Data!H35
K112: December | M112: =Data!K35
K113: January | M113: =Data!N35
K114: February | M114: =Data!Q35
K115: March | M115: =Data!T35
K116: April | M116: =Data!W35
K117: May | M117: =Data!Z35
K118: June | M118: =Data!AC35
