Workbook

Sheet Test
A1: School Name Here
A2: Class | B2: First Name | C2: Last Name | D2: LEA Student # | E2: Q1 | F2: Q2 | G2: Q3 | H2: Q4 | I2: Q5 | J2: Q6 | K2: Q7 | L2: Q8 | M2: Q9 | N2: Q10 | O2: Q11 | P2: Q12 | Q2: Q13 | R2: Q14 | S2: Q15 | T2: Q16 | U2: Q17 | V2: Q18 | W2: Q19 | X2: Q20 | Y2: Q21 | Z2: Q22 | AA2: Q23 | AB2: Q24 | AC2: Q25 | AD2: Q26 | AE2: Q27 | AF2: Q28 | AG2: Q29 | AH2: Q30 | AI2: Q31 | AJ2: Q32 | AK2: Q33 | AL2: Q34 | AM2: Q35 | AN2: Q36 | AO2: Q37 | AP2: Q38 | AQ2: Q39 | AR2: Q40 | AS2: Q41 | AT2: Q42 | AU2: Q43 | AV2: Q44 | AW2: Q45 | AX2: Q46 | AY2: Q47 | AZ2: Q48 | BA2: Q49 | BB2: Q50 | BC2: Q51 | BD2: Q52 | BE2: Q53 | BF2: Q54 | BG2: Q55 | BH2: Q56 | BI2: Q57 | BJ2: Q58 | BK2: Q59 | BL2: Q60 | BM2: Q61 | BN2: Q62 | BO2: Q63 | BP2: Q64 | BQ2: Q65 | BR2: Q66 | BS2: Q67 | BT2: Q68 | BU2: Q69
A3: Teacher1
A31: Teacher2
A60: Teacher 3
A89: Teacher 4
A118: Teacher5
A147: Teacher6

Sheet Report
A1: Class | B1: First Name | C1: Last Name | D1: LEA Student # | E1: Literacy Subcategories (Total Possible: 51) | O1: Numeracy Subcategories (Totals Possible: 37) | X1: Literacy % Correct | Y1: Numeracy % Correct | Z1: Total % Correct | AA1: Class Average
E2: A | F2: B | G2: C | H2: D | I2: E | J2: F | K2: G | L2: H | M2: I | N2: J | O2: K | P2: L | Q2: M | R2: N | S2: O | T2: P | U2: Q | V2: R | W2: S
A3: =IF(ISBLANK(Test!A3),"",(Test!A3)) -> Teacher1 | B3: =IF(ISBLANK(Test!B3),"",(Test!B3)) | C3: =IF(ISBLANK(Test!C3),"",(Test!C3)) | D3: =IF(ISBLANK(Test!D3),"",(Test!D3)) | E3: =IF(Filter!$C3="","",(COUNTIF(Filter!E3:H3,"a")+1)) | F3: =IF(Filter!$C3="","",(COUNTIF(Filter!I3:L3,"a")+1)) | G3: =IF(Filter!$C3="","",(COUNTIF(Filter!M3:P3,"a")+1)) | H3: =IF(Filter!$C3="","",(COUNTIF(Filter!Q3:S3,"a")+1)) | I3: =IF(Filter!$C3="","",(COUNTIF(Filter!T3:V3,"a")+1)) | J3: =IF(Filter!$C3="","",(COUNTIF(Filter!W3:Z3,"a")+1)) | K3: =IF(Filter!$C3="","",(COUNTIF(Filter!AA3:AD3,"a")+1)) | L3: =IF(Filter!$C3="","",(COUNTIF(Filter!AE3:AI3,"a")+1)) | M3: =IF(Filter!$C3="","",(COUNTIF(Filter!AJ3:AN3,"a")+1)) | N3: =IF(Filter!$C3="","",(COUNTIF(Filter!AO3:AS3,"a")+1)) | O3: =IF(Filter!$C3="","",(COUNTIF(Filter!AT3:AV3,"a")+1)) | P3: =IF(Filter!$C3="","",(COUNTIF(Filter!AW3:AY3,"a")+1)) | Q3: =IF(Filter!$C3="","",(COUNTIF(Filter!AZ3:BA3,"a")+1)) | R3: =IF(Filter!$C3="","",(COUNTIF(Filter!BB3:BD3,"a")+1)) | S3: =IF(Filter!$C3="","",(COUNTIF(Filter!BE3:BG3,"a")+1)) | T3: =IF(Filter!$C3="","",(COUNTIF(Filter!BH3:BJ3,"a")+1)) | U3: =IF(Filter!$C3="","",(COUNTIF(Filter!BK3:BO3,"a")+1)) | V3: =IF(Filter!$C3="","",(COUNTIF(Filter!BP3:BR3,"a")+1)) | W3: =IF(Filter!$C3="","",(COUNTIF(Filter!BS3:BU3,"a")+1)) | X3: =IF(SUM(E3:N3)=0,"",SUM(E3:N3)/51) | Y3: =IF(SUM(O3:W3)=0,"",SUM(O3:W3)/37) | Z3: =IF(SUM(E3:W3)=0,"",SUM(E3:W3)/88) | AA3: =IF(Z3="","",SUM(Z$3:Z$30)/COUNT(Z$3:Z$30))
A4: =IF(ISBLANK(Test!A4),"",(Test!A4)) | B4: =IF(ISBLANK(Test!B4),"",(Test!B4)) | C4: =IF(ISBLANK(Test!C4),"",(Test!C4)) | D4: =IF(ISBLANK(Test!D4),"",(Test!D4)) | E4: =IF(Filter!$C4="","",(COUNTIF(Filter!E4:H4,"a")+1)) | F4: =IF(Filter!$C4="","",(COUNTIF(Filter!I4:L4,"a")+1)) | G4: =IF(Filter!$C4="","",(COUNTIF(Filter!M4:P4,"a")+1)) | H4: =IF(Filter!$C4="","",(COUNTIF(Filter!Q4:S4,"a")+1)) | I4: =IF(Filter!$C4="","",(COUNTIF(Filter!T4:V4,"a")+1)) | J4: =IF(Filter!$C4="","",(COUNTIF(Filter!W4:Z4,"a")+1)) | K4: =IF(Filter!$C4="","",(COUNTIF(Filter!AA4:AD4,"a")+1)) | L4: =IF(Filter!$C4="","",(COUNTIF(Filter!AE4:AI4,"a")+1)) | M4: =IF(Filter!$C4="","",(COUNTIF(Filter!AJ4:AN4,"a")+1)) | N4: =IF(Filter!$C4="","",(COUNTIF(Filter!AO4:AS4,"a")+1)) | O4: =IF(Filter!$C4="","",(COUNTIF(Filter!AT4:AV4,"a")+1)) | P4: =IF(Filter!$C4="","",(COUNTIF(Filter!AW4:AY4,"a")+1)) | Q4: =IF(Filter!$C4="","",(COUNTIF(Filter!AZ4:BA4,"a")+1)) | R4: =IF(Filter!$C4="","",(COUNTIF(Filter!BB4:BD4,"a")+1)) | S4: =IF(Filter!$C4="","",(COUNTIF(Filter!BE4:BG4,"a")+1)) | T4: =IF(Filter!$C4="","",(COUNTIF(Filter!BH4:BJ4,"a")+1)) | U4: =IF(Filter!$C4="","",(COUNTIF(Filter!BK4:BO4,"a")+1)) | V4: =IF(Filter!$C4="","",(COUNTIF(Filter!BP4:BR4,"a")+1)) | W4: =IF(Filter!$C4="","",(COUNTIF(Filter!BS4:BU4,"a")+1)) | X4: =IF(SUM(E4:N4)=0,"",SUM(E4:N4)/51) | Y4: =IF(SUM(O4:W4)=0,"",SUM(O4:W4)/37) | Z4: =IF(SUM(E4:W4)=0,"",SUM(E4:W4)/88) | AA4: =IF(Z4="","",SUM(Z$3:Z$30)/COUNT(Z$3:Z$30))
A5: =IF(ISBLANK(Test!A5),"",(Test!A5)) | B5: =IF(ISBLANK(Test!B5),"",(Test!B5)) | C5: =IF(ISBLANK(Test!C5),"",(Test!C5)) | D5: =IF(ISBLANK(Test!D5),"",(Test!D5)) | E5: =IF(Filter!$C5="","",(COUNTIF(Filter!E5:H5,"a")+1)) | F5: =IF(Filter!$C5="","",(COUNTIF(Filter!I5:L5,"a")+1)) | G5: =IF(Filter!$C5="","",(COUNTIF(Filter!M5:P5,"a")+1)) | H5: =IF(Filter!$C5="","",(COUNTIF(Filter!Q5:S5,"a")+1)) | I5: =IF(Filter!$C5="","",(COUNTIF(Filter!T5:V5,"a")+1)) | J5: =IF(Filter!$C5="","",(COUNTIF(Filter!W5:Z5,"a")+1)) | K5: =IF(Filter!$C5="","",(COUNTIF(Filter!AA5:AD5,"a")+1)) | L5: =IF(Filter!$C5="","",(COUNTIF(Filter!AE5:AI5,"a")+1)) | M5: =IF(Filter!$C5="","",(COUNTIF(Filter!AJ5:AN5,"a")+1)) | N5: =IF(Filter!$C5="","",(COUNTIF(Filter!AO5:AS5,"a")+1)) | O5: =IF(Filter!$C5="","",(COUNTIF(Filter!AT5:AV5,"a")+1)) | P5: =IF(Filter!$C5="","",(COUNTIF(Filter!AW5:AY5,"a")+1)) | Q5: =IF(Filter!$C5="","",(COUNTIF(Filter!AZ5:BA5,"a")+1)) | R5: =IF(Filter!$C5="","",(COUNTIF(Filter!BB5:BD5,"a")+1)) | S5: =IF(Filter!$C5="","",(COUNTIF(Filter!BE5:BG5,"a")+1)) | T5: =IF(Filter!$C5="","",(COUNTIF(Filter!BH5:BJ5,"a")+1)) | U5: =IF(Filter!$C5="","",(COUNTIF(Filter!BK5:BO5,"a")+1)) | V5: =IF(Filter!$C5="","",(COUNTIF(Filter!BP5:BR5,"a")+1)) | W5: =IF(Filter!$C5="","",(COUNTIF(Filter!BS5:BU5,"a")+1)) | X5: =IF(SUM(E5:N5)=0,"",SUM(E5:N5)/51) | Y5: =IF(SUM(O5:W5)=0,"",SUM(O5:W5)/37) | Z5: =IF(SUM(E5:W5)=0,"",SUM(E5:W5)/88) | AA5: =IF(Z5="","",SUM(Z$3:Z$30)/COUNT(Z$3:Z$30))
A6: =IF(ISBLANK(Test!A6),"",(Test!A6)) | B6: =IF(ISBLANK(Test!B6),"",(Test!B6)) | C6: =IF(ISBLANK(Test!C6),"",(Test!C6)) | D6: =IF(ISBLANK(Test!D6),"",(Test!D6)) | E6: =IF(Filter!$C6="","",(COUNTIF(Filter!E6:H6,"a")+1)) | F6: =IF(Filter!$C6="","",(COUNTIF(Filter!I6:L6,"a")+1)) | G6: =IF(Filter!$C6="","",(COUNTIF(Filter!M6:P6,"a")+1)) | H6: =IF(Filter!$C6="","",(COUNTIF(Filter!Q6:S6,"a")+1)) | I6: =IF(Filter!$C6="","",(COUNTIF(Filter!T6:V6,"a")+1)) | J6: =IF(Filter!$C6="","",(COUNTIF(Filter!W6:Z6,"a")+1)) | K6: =IF(Filter!$C6="","",(COUNTIF(Filter!AA6:AD6,"a")+1)) | L6: =IF(Filter!$C6="","",(COUNTIF(Filter!AE6:AI6,"a")+1)) | M6: =IF(Filter!$C6="","",(COUNTIF(Filter!AJ6:AN6,"a")+1)) | N6: =IF(Filter!$C6="","",(COUNTIF(Filter!AO6:AS6,"a")+1)) | O6: =IF(Filter!$C6="","",(COUNTIF(Filter!AT6:AV6,"a")+1)) | P6: =IF(Filter!$C6="","",(COUNTIF(Filter!AW6:AY6,"a")+1)) | Q6: =IF(Filter!$C6="","",(COUNTIF(Filter!AZ6:BA6,"a")+1)) | R6: =IF(Filter!$C6="","",(COUNTIF(Filter!BB6:BD6,"a")+1)) | S6: =IF(Filter!$C6="","",(COUNTIF(Filter!BE6:BG6,"a")+1)) | T6: =IF(Filter!$C6="","",(COUNTIF(Filter!BH6:BJ6,"a")+1)) | U6: =IF(Filter!$C6="","",(COUNTIF(Filter!BK6:BO6,"a")+1)) | V6: =IF(Filter!$C6="","",(COUNTIF(Filter!BP6:BR6,"a")+1)) | W6: =IF(Filter!$C6="","",(COUNTIF(Filter!BS6:BU6,"a")+1)) | X6: =IF(SUM(E6:N6)=0,"",SUM(E6:N6)/51) | Y6: =IF(SUM(O6:W6)=0,"",SUM(O6:W6)/37) | Z6: =IF(SUM(E6:W6)=0,"",SUM(E6:W6)/88) | AA6: =IF(Z6="","",SUM(Z$3:Z$30)/COUNT(Z$3:Z$30))
A7: =IF(ISBLANK(Test!A7),"",(Test!A7)) | B7: =IF(ISBLANK(Test!B7),"",(Test!B7)) | C7: =IF(ISBLANK(Test!C7),"",(Test!C7)) | D7: =IF(ISBLANK(Test!D7),"",(Test!D7)) | E7: =IF(Filter!$C7="","",(COUNTIF(Filter!E7:H7,"a")+1)) | F7: =IF(Filter!$C7="","",(COUNTIF(Filter!I7:L7,"a")+1)) | G7: =IF(Filter!$C7="","",(COUNTIF(Filter!M7:P7,"a")+1)) | H7: =IF(Filter!$C7="","",(COUNTIF(Filter!Q7:S7,"a")+1)) | I7: =IF(Filter!$C7="","",(COUNTIF(Filter!T7:V7,"a")+1)) | J7: =IF(Filter!$C7="","",(COUNTIF(Filter!W7:Z7,"a")+1)) | K7: =IF(Filter!$C7="","",(COUNTIF(Filter!AA7:AD7,"a")+1)) | L7: =IF(Filter!$C7="","",(COUNTIF(Filter!AE7:AI7,"a")+1)) | M7: =IF(Filter!$C7="","",(COUNTIF(Filter!AJ7:AN7,"a")+1)) | N7: =IF(Filter!$C7="","",(COUNTIF(Filter!AO7:AS7,"a")+1)) | O7: =IF(Filter!$C7="","",(COUNTIF(Filter!AT7:AV7,"a")+1)) | P7: =IF(Filter!$C7="","",(COUNTIF(Filter!AW7:AY7,"a")+1)) | Q7: =IF(Filter!$C7="","",(COUNTIF(Filter!AZ7:BA7,"a")+1)) | R7: =IF(Filter!$C7="","",(COUNTIF(Filter!BB7:BD7,"a")+1)) | S7: =IF(Filter!$C7="","",(COUNTIF(Filter!BE7:BG7,"a")+1)) | T7: =IF(Filter!$C7="","",(COUNTIF(Filter!BH7:BJ7,"a")+1)) | U7: =IF(Filter!$C7="","",(COUNTIF(Filter!BK7:BO7,"a")+1)) | V7: =IF(Filter!$C7="","",(COUNTIF(Filter!BP7:BR7,"a")+1)) | W7: =IF(Filter!$C7="","",(COUNTIF(Filter!BS7:BU7,"a")+1)) | X7: =IF(SUM(E7:N7)=0,"",SUM(E7:N7)/51) | Y7: =IF(SUM(O7:W7)=0,"",SUM(O7:W7)/37) | Z7: =IF(SUM(E7:W7)=0,"",SUM(E7:W7)/88) | AA7: =IF(Z7="","",SUM(Z$3:Z$30)/COUNT(Z$3:Z$30))
A8: =IF(ISBLANK(Test!A8),"",(Test!A8)) | B8: =IF(ISBLANK(Test!B8),"",(Test!B8)) | C8: =IF(ISBLANK(Test!C8),"",(Test!C8)) | D8: =IF(ISBLANK(Test!D8),"",(Test!D8)) | E8: =IF(Filter!$C8="","",(COUNTIF(Filter!E8:H8,"a")+1)) | F8: =IF(Filter!$C8="","",(COUNTIF(Filter!I8:L8,"a")+1)) | G8: =IF(Filter!$C8="","",(COUNTIF(Filter!M8:P8,"a")+1)) | H8: =IF(Filter!$C8="","",(COUNTIF(Filter!Q8:S8,"a")+1)) | I8: =IF(Filter!$C8="","",(COUNTIF(Filter!T8:V8,"a")+1)) | J8: =IF(Filter!$C8="","",(COUNTIF(Filter!W8:Z8,"a")+1)) | K8: =IF(Filter!$C8="","",(COUNTIF(Filter!AA8:AD8,"a")+1)) | L8: =IF(Filter!$C8="","",(COUNTIF(Filter!AE8:AI8,"a")+1)) | M8: =IF(Filter!$C8="","",(COUNTIF(Filter!AJ8:AN8,"a")+1)) | N8: =IF(Filter!$C8="","",(COUNTIF(Filter!AO8:AS8,"a")+1)) | O8: =IF(Filter!$C8="","",(COUNTIF(Filter!AT8:AV8,"a")+1)) | P8: =IF(Filter!$C8="","",(COUNTIF(Filter!AW8:AY8,"a")+1)) | Q8: =IF(Filter!$C8="","",(COUNTIF(Filter!AZ8:BA8,"a")+1)) | R8: =IF(Filter!$C8="","",(COUNTIF(Filter!BB8:BD8,"a")+1)) | S8: =IF(Filter!$C8="","",(COUNTIF(Filter!BE8:BG8,"a")+1)) | T8: =IF(Filter!$C8="","",(COUNTIF(Filter!BH8:BJ8,"a")+1)) | U8: =IF(Filter!$C8="","",(COUNTIF(Filter!BK8:BO8,"a")+1)) | V8: =IF(Filter!$C8="","",(COUNTIF(Filter!BP8:BR8,"a")+1)) | W8: =IF(Filter!$C8="","",(COUNTIF(Filter!BS8:BU8,"a")+1)) | X8: =IF(SUM(E8:N8)=0,"",SUM(E8:N8)/51) | Y8: =IF(SUM(O8:W8)=0,"",SUM(O8:W8)/37) | Z8: =IF(SUM(E8:W8)=0,"",SUM(E8:W8)/88) | AA8: =IF(Z8="","",SUM(Z$3:Z$30)/COUNT(Z$3:Z$30))
A9: =IF(ISBLANK(Test!A9),"",(Test!A9)) | B9: =IF(ISBLANK(Test!B9),"",(Test!B9)) | C9: =IF(ISBLANK(Test!C9),"",(Test!C9)) | D9: =IF(ISBLANK(Test!D9),"",(Test!D9)) | E9: =IF(Filter!$C9="","",(COUNTIF(Filter!E9:H9,"a")+1)) | F9: =IF(Filter!$C9="","",(COUNTIF(Filter!I9:L9,"a")+1)) | G9: =IF(Filter!$C9="","",(COUNTIF(Filter!M9:P9,"a")+1)) | H9: =IF(Filter!$C9="","",(COUNTIF(Filter!Q9:S9,"a")+1)) | I9: =IF(Filter!$C9="","",(COUNTIF(Filter!T9:V9,"a")+1)) | J9: =IF(Filter!$C9="","",(COUNTIF(Filter!W9:Z9,"a")+1)) | K9: =IF(Filter!$C9="","",(COUNTIF(Filter!AA9:AD9,"a")+1)) | L9: =IF(Filter!$C9="","",(COUNTIF(Filter!AE9:AI9,"a")+1)) | M9: =IF(Filter!$C9="","",(COUNTIF(Filter!AJ9:AN9,"a")+1)) | N9: =IF(Filter!$C9="","",(COUNTIF(Filter!AO9:AS9,"a")+1)) | O9: =IF(Filter!$C9="","",(COUNTIF(Filter!AT9:AV9,"a")+1)) | P9: =IF(Filter!$C9="","",(COUNTIF(Filter!AW9:AY9,"a")+1)) | Q9: =IF(Filter!$C9="","",(COUNTIF(Filter!AZ9:BA9,"a")+1)) | R9: =IF(Filter!$C9="","",(COUNTIF(Filter!BB9:BD9,"a")+1)) | S9: =IF(Filter!$C9="","",(COUNTIF(Filter!BE9:BG9,"a")+1)) | T9: =IF(Filter!$C9="","",(COUNTIF(Filter!BH9:BJ9,"a")+1)) | U9: =IF(Filter!$C9="","",(COUNTIF(Filter!BK9:BO9,"a")+1)) | V9: =IF(Filter!$C9="","",(COUNTIF(Filter!BP9:BR9,"a")+1)) | W9: =IF(Filter!$C9="","",(COUNTIF(Filter!BS9:BU9,"a")+1)) | X9: =IF(SUM(E9:N9)=0,"",SUM(E9:N9)/51) | Y9: =IF(SUM(O9:W9)=0,"",SUM(O9:W9)/37) | Z9: =IF(SUM(E9:W9)=0,"",SUM(E9:W9)/88) | AA9: =IF(Z9="","",SUM(Z$3:Z$30)/COUNT(Z$3:Z$30))
A10: =IF(ISBLANK(Test!A10),"",(Test!A10)) | B10: =IF(ISBLANK(Test!B10),"",(Test!B10)) | C10: =IF(ISBLANK(Test!C10),"",(Test!C10)) | D10: =IF(ISBLANK(Test!D10),"",(Test!D10)) | E10: =IF(Filter!$C10="","",(COUNTIF(Filter!E10:H10,"a")+1)) | F10: =IF(Filter!$C10="","",(COUNTIF(Filter!I10:L10,"a")+1)) | G10: =IF(Filter!$C10="","",(COUNTIF(Filter!M10:P10,"a")+1)) | H10: =IF(Filter!$C10="","",(COUNTIF(Filter!Q10:S10,"a")+1)) | I10: =IF(Filter!$C10="","",(COUNTIF(Filter!T10:V10,"a")+1)) | J10: =IF(Filter!$C10="","",(COUNTIF(Filter!W10:Z10,"a")+1)) | K10: =IF(Filter!$C10="","",(COUNTIF(Filter!AA10:AD10,"a")+1)) | L10: =IF(Filter!$C10="","",(COUNTIF(Filter!AE10:AI10,"a")+1)) | M10: =IF(Filter!$C10="","",(COUNTIF(Filter!AJ10:AN10,"a")+1)) | N10: =IF(Filter!$C10="","",(COUNTIF(Filter!AO10:AS10,"a")+1)) | O10: =IF(Filter!$C10="","",(COUNTIF(Filter!AT10:AV10,"a")+1)) | P10: =IF(Filter!$C10="","",(COUNTIF(Filter!AW10:AY10,"a")+1)) | Q10: =IF(Filter!$C10="","",(COUNTIF(Filter!AZ10:BA10,"a")+1)) | R10: =IF(Filter!$C10="","",(COUNTIF(Filter!BB10:BD10,"a")+1)) | S10: =IF(Filter!$C10="","",(COUNTIF(Filter!BE10:BG10,"a")+1)) | T10: =IF(Filter!$C10="","",(COUNTIF(Filter!BH10:BJ10,"a")+1)) | U10: =IF(Filter!$C10="","",(COUNTIF(Filter!BK10:BO10,"a")+1)) | V10: =IF(Filter!$C10="","",(COUNTIF(Filter!BP10:BR10,"a")+1)) | W10: =IF(Filter!$C10="","",(COUNTIF(Filter!BS10:BU10,"a")+1)) | X10: =IF(SUM(E10:N10)=0,"",SUM(E10:N10)/51) | Y10: =IF(SUM(O10:W10)=0,"",SUM(O10:W10)/37) | Z10: =IF(SUM(E10:W10)=0,"",SUM(E10:W10)/88) | AA10: =IF(Z10="","",SUM(Z$3:Z$30)/COUNT(Z$3:Z$30))
A11: =IF(ISBLANK(Test!A11),"",(Test!A11)) | B11: =IF(ISBLANK(Test!B11),"",(Test!B11)) | C11: =IF(ISBLANK(Test!C11),"",(Test!C11)) | D11: =IF(ISBLANK(Test!D11),"",(Test!D11)) | E11: =IF(Filter!$C11="","",(COUNTIF(Filter!E11:H11,"a")+1)) | F11: =IF(Filter!$C11="","",(COUNTIF(Filter!I11:L11,"a")+1)) | G11: =IF(Filter!$C11="","",(COUNTIF(Filter!M11:P11,"a")+1)) | H11: =IF(Filter!$C11="","",(COUNTIF(Filter!Q11:S11,"a")+1)) | I11: =IF(Filter!$C11="","",(COUNTIF(Filter!T11:V11,"a")+1)) | J11: =IF(Filter!$C11="","",(COUNTIF(Filter!W11:Z11,"a")+1)) | K11: =IF(Filter!$C11="","",(COUNTIF(Filter!AA11:AD11,"a")+1)) | L11: =IF(Filter!$C11="","",(COUNTIF(Filter!AE11:AI11,"a")+1)) | M11: =IF(Filter!$C11="","",(COUNTIF(Filter!AJ11:AN11,"a")+1)) | N11: =IF(Filter!$C11="","",(COUNTIF(Filter!AO11:AS11,"a")+1)) | O11: =IF(Filter!$C11="","",(COUNTIF(Filter!AT11:AV11,"a")+1)) | P11: =IF(Filter!$C11="","",(COUNTIF(Filter!AW11:AY11,"a")+1)) | Q11: =IF(Filter!$C11="","",(COUNTIF(Filter!AZ11:BA11,"a")+1)) | R11: =IF(Filter!$C11="","",(COUNTIF(Filter!BB11:BD11,"a")+1)) | S11: =IF(Filter!$C11="","",(COUNTIF(Filter!BE11:BG11,"a")+1)) | T11: =IF(Filter!$C11="","",(COUNTIF(Filter!BH11:BJ11,"a")+1)) | U11: =IF(Filter!$C11="","",(COUNTIF(Filter!BK11:BO11,"a")+1)) | V11: =IF(Filter!$C11="","",(COUNTIF(Filter!BP11:BR11,"a")+1)) | W11: =IF(Filter!$C11="","",(COUNTIF(Filter!BS11:BU11,"a")+1)) | X11: =IF(SUM(E11:N11)=0,"",SUM(E11:N11)/51) | Y11: =IF(SUM(O11:W11)=0,"",SUM(O11:W11)/37) | Z11: =IF(SUM(E11:W11)=0,"",SUM(E11:W11)/88) | AA11: =IF(Z11="","",SUM(Z$3:Z$30)/COUNT(Z$3:Z$30))
A12: =IF(ISBLANK(Test!A12),"",(Test!A12)) | B12: =IF(ISBLANK(Test!B12),"",(Test!B12)) | C12: =IF(ISBLANK(Test!C12),"",(Test!C12)) | D12: =IF(ISBLANK(Test!D12),"",(Test!D12)) | E12: =IF(Filter!$C12="","",(COUNTIF(Filter!E12:H12,"a")+1)) | F12: =IF(Filter!$C12="","",(COUNTIF(Filter!I12:L12,"a")+1)) | G12: =IF(Filter!$C12="","",(COUNTIF(Filter!M12:P12,"a")+1)) | H12: =IF(Filter!$C12="","",(COUNTIF(Filter!Q12:S12,"a")+1)) | I12: =IF(Filter!$C12="","",(COUNTIF(Filter!T12:V12,"a")+1)) | J12: =IF(Filter!$C12="","",(COUNTIF(Filter!W12:Z12,"a")+1)) | K12: =IF(Filter!$C12="","",(COUNTIF(Filter!AA12:AD12,"a")+1)) | L12: =IF(Filter!$C12="","",(COUNTIF(Filter!AE12:AI12,"a")+1)) | M12: =IF(Filter!$C12="","",(COUNTIF(Filter!AJ12:AN12,"a")+1)) | N12: =IF(Filter!$C12="","",(COUNTIF(Filter!AO12:AS12,"a")+1)) | O12: =IF(Filter!$C12="","",(COUNTIF(Filter!AT12:AV12,"a")+1)) | P12: =IF(Filter!$C12="","",(COUNTIF(Filter!AW12:AY12,"a")+1)) | Q12: =IF(Filter!$C12="","",(COUNTIF(Filter!AZ12:BA12,"a")+1)) | R12: =IF(Filter!$C12="","",(COUNTIF(Filter!BB12:BD12,"a")+1)) | S12: =IF(Filter!$C12="","",(COUNTIF(Filter!BE12:BG12,"a")+1)) | T12: =IF(Filter!$C12="","",(COUNTIF(Filter!BH12:BJ12,"a")+1)) | U12: =IF(Filter!$C12="","",(COUNTIF(Filter!BK12:BO12,"a")+1)) | V12: =IF(Filter!$C12="","",(COUNTIF(Filter!BP12:BR12,"a")+1)) | W12: =IF(Filter!$C12="","",(COUNTIF(Filter!BS12:BU12,"a")+1)) | X12: =IF(SUM(E12:N12)=0,"",SUM(E12:N12)/51) | Y12: =IF(SUM(O12:W12)=0,"",SUM(O12:W12)/37) | Z12: =IF(SUM(E12:W12)=0,"",SUM(E12:W12)/88) | AA12: =IF(Z12="","",SUM(Z$3:Z$30)/COUNT(Z$3:Z$30))
A13: =IF(ISBLANK(Test!A13),"",(Test!A13)) | B13: =IF(ISBLANK(Test!B13),"",(Test!B13)) | C13: =IF(ISBLANK(Test!C13),"",(Test!C13)) | D13: =IF(ISBLANK(Test!D13),"",(Test!D13)) | E13: =IF(Filter!$C13="","",(COUNTIF(Filter!E13:H13,"a")+1)) | F13: =IF(Filter!$C13="","",(COUNTIF(Filter!I13:L13,"a")+1)) | G13: =IF(Filter!$C13="","",(COUNTIF(Filter!M13:P13,"a")+1)) | H13: =IF(Filter!$C13="","",(COUNTIF(Filter!Q13:S13,"a")+1)) | I13: =IF(Filter!$C13="","",(COUNTIF(Filter!T13:V13,"a")+1)) | J13: =IF(Filter!$C13="","",(COUNTIF(Filter!W13:Z13,"a")+1)) | K13: =IF(Filter!$C13="","",(COUNTIF(Filter!AA13:AD13,"a")+1)) | L13: =IF(Filter!$C13="","",(COUNTIF(Filter!AE13:AI13,"a")+1)) | M13: =IF(Filter!$C13="","",(COUNTIF(Filter!AJ13:AN13,"a")+1)) | N13: =IF(Filter!$C13="","",(COUNTIF(Filter!AO13:AS13,"a")+1)) | O13: =IF(Filter!$C13="","",(COUNTIF(Filter!AT13:AV13,"a")+1)) | P13: =IF(Filter!$C13="","",(COUNTIF(Filter!AW13:AY13,"a")+1)) | Q13: =IF(Filter!$C13="","",(COUNTIF(Filter!AZ13:BA13,"a")+1)) | R13: =IF(Filter!$C13="","",(COUNTIF(Filter!BB13:BD13,"a")+1)) | S13: =IF(Filter!$C13="","",(COUNTIF(Filter!BE13:BG13,"a")+1)) | T13: =IF(Filter!$C13="","",(COUNTIF(Filter!BH13:BJ13,"a")+1)) | U13: =IF(Filter!$C13="","",(COUNTIF(Filter!BK13:BO13,"a")+1)) | V13: =IF(Filter!$C13="","",(COUNTIF(Filter!BP13:BR13,"a")+1)) | W13: =IF(Filter!$C13="","",(COUNTIF(Filter!BS13:BU13,"a")+1)) | X13: =IF(SUM(E13:N13)=0,"",SUM(E13:N13)/51) | Y13: =IF(SUM(O13:W13)=0,"",SUM(O13:W13)/37) | Z13: =IF(SUM(E13:W13)=0,"",SUM(E13:W13)/88) | AA13: =IF(Z13="","",SUM(Z$3:Z$30)/COUNT(Z$3:Z$30))
A14: =IF(ISBLANK(Test!A14),"",(Test!A14)) | B14: =IF(ISBLANK(Test!B14),"",(Test!B14)) | C14: =IF(ISBLANK(Test!C14),"",(Test!C14)) | D14: =IF(ISBLANK(Test!D14),"",(Test!D14)) | E14: =IF(Filter!$C14="","",(COUNTIF(Filter!E14:H14,"a")+1)) | F14: =IF(Filter!$C14="","",(COUNTIF(Filter!I14:L14,"a")+1)) | G14: =IF(Filter!$C14="","",(COUNTIF(Filter!M14:P14,"a")+1)) | H14: =IF(Filter!$C14="","",(COUNTIF(Filter!Q14:S14,"a")+1)) | I14: =IF(Filter!$C14="","",(COUNTIF(Filter!T14:V14,"a")+1)) | J14: =IF(Filter!$C14="","",(COUNTIF(Filter!W14:Z14,"a")+1)) | K14: =IF(Filter!$C14="","",(COUNTIF(Filter!AA14:AD14,"a")+1)) | L14: =IF(Filter!$C14="","",(COUNTIF(Filter!AE14:AI14,"a")+1)) | M14: =IF(Filter!$C14="","",(COUNTIF(Filter!AJ14:AN14,"a")+1)) | N14: =IF(Filter!$C14="","",(COUNTIF(Filter!AO14:AS14,"a")+1)) | O14: =IF(Filter!$C14="","",(COUNTIF(Filter!AT14:AV14,"a")+1)) | P14: =IF(Filter!$C14="","",(COUNTIF(Filter!AW14:AY14,"a")+1)) | Q14: =IF(Filter!$C14="","",(COUNTIF(Filter!AZ14:BA14,"a")+1)) | R14: =IF(Filter!$C14="","",(COUNTIF(Filter!BB14:BD14,"a")+1)) | S14: =IF(Filter!$C14="","",(COUNTIF(Filter!BE14:BG14,"a")+1)) | T14: =IF(Filter!$C14="","",(COUNTIF(Filter!BH14:BJ14,"a")+1)) | U14: =IF(Filter!$C14="","",(COUNTIF(Filter!BK14:BO14,"a")+1)) | V14: =IF(Filter!$C14="","",(COUNTIF(Filter!BP14:BR14,"a")+1)) | W14: =IF(Filter!$C14="","",(COUNTIF(Filter!BS14:BU14,"a")+1)) | X14: =IF(SUM(E14:N14)=0,"",SUM(E14:N14)/51) | Y14: =IF(SUM(O14:W14)=0,"",SUM(O14:W14)/37) | Z14: =IF(SUM(E14:W14)=0,"",SUM(E14:W14)/88) | AA14: =IF(Z14="","",SUM(Z$3:Z$30)/COUNT(Z$3:Z$30))
... A30: =IF(ISBLANK(Test!A30),"",(Test!A30)) | B30: =IF(ISBLANK(Test!B30),"",(Test!B30)) | C30: =IF(ISBLANK(Test!C30),"",(Test!C30)) | D30: =IF(ISBLANK(Test!D30),"",(Test!D30)) | E30: =IF(Filter!$C30="","",(COUNTIF(Filter!E30:H30,"a")+1)) | F30: =IF(Filter!$C30="","",(COUNTIF(Filter!I30:L30,"a")+1)) | G30: =IF(Filter!$C30="","",(COUNTIF(Filter!M30:P30,"a")+1)) | H30: =IF(Filter!$C30="","",(COUNTIF(Filter!Q30:S30,"a")+1)) | I30: =IF(Filter!$C30="","",(COUNTIF(Filter!T30:V30,"a")+1)) | J30: =IF(Filter!$C30="","",(COUNTIF(Filter!W30:Z30,"a")+1)) | K30: =IF(Filter!$C30="","",(COUNTIF(Filter!AA30:AD30,"a")+1)) | L30: =IF(Filter!$C30="","",(COUNTIF(Filter!AE30:AI30,"a")+1)) | M30: =IF(Filter!$C30="","",(COUNTIF(Filter!AJ30:AN30,"a")+1)) | N30: =IF(Filter!$C30="","",(COUNTIF(Filter!AO30:AS30,"a")+1)) | O30: =IF(Filter!$C30="","",(COUNTIF(Filter!AT30:AV30,"a")+1)) | P30: =IF(Filter!$C30="","",(COUNTIF(Filter!AW30:AY30,"a")+1)) | Q30: =IF(Filter!$C30="","",(COUNTIF(Filter!AZ30:BA30,"a")+1)) | R30: =IF(Filter!$C30="","",(COUNTIF(Filter!BB30:BD30,"a")+1)) | S30: =IF(Filter!$C30="","",(COUNTIF(Filter!BE30:BG30,"a")+1)) | T30: =IF(Filter!$C30="","",(COUNTIF(Filter!BH30:BJ30,"a")+1)) | U30: =IF(Filter!$C30="","",(COUNTIF(Filter!BK30:BO30,"a")+1)) | V30: =IF(Filter!$C30="","",(COUNTIF(Filter!BP30:BR30,"a")+1)) | W30: =IF(Filter!$C30="","",(COUNTIF(Filter!BS30:BU30,"a")+1)) | X30: =IF(SUM(E30:N30)=0,"",SUM(E30:N30)/51) | Y30: =IF(SUM(O30:W30)=0,"",SUM(O30:W30)/37) | Z30: =IF(SUM(E30:W30)=0,"",SUM(E30:W30)/88) | AA30: =IF(Z30="","",SUM(Z$3:Z$30)/COUNT(Z$3:Z$30))
A31: =IF(ISBLANK(Test!A31),"",(Test!A31)) -> Teacher2 | B31: =IF(ISBLANK(Test!B31),"",(Test!B31)) | C31: =IF(ISBLANK(Test!C31),"",(Test!C31)) | D31: =IF(ISBLANK(Test!D31),"",(Test!D31)) | E31: =IF(Filter!$C31="","",(COUNTIF(Filter!E31:H31,"a")+1)) | F31: =IF(Filter!$C31="","",(COUNTIF(Filter!I31:L31,"a")+1)) | G31: =IF(Filter!$C31="","",(COUNTIF(Filter!M31:P31,"a")+1)) | H31: =IF(Filter!$C31="","",(COUNTIF(Filter!Q31:S31,"a")+1)) | I31: =IF(Filter!$C31="","",(COUNTIF(Filter!T31:V31,"a")+1)) | J31: =IF(Filter!$C31="","",(COUNTIF(Filter!W31:Z31,"a")+1)) | K31: =IF(Filter!$C31="","",(COUNTIF(Filter!AA31:AD31,"a")+1)) | L31: =IF(Filter!$C31="","",(COUNTIF(Filter!AE31:AI31,"a")+1)) | M31: =IF(Filter!$C31="","",(COUNTIF(Filter!AJ31:AN31,"a")+1)) | N31: =IF(Filter!$C31="","",(COUNTIF(Filter!AO31:AS31,"a")+1)) | O31: =IF(Filter!$C31="","",(COUNTIF(Filter!AT31:AV31,"a")+1)) | P31: =IF(Filter!$C31="","",(COUNTIF(Filter!AW31:AY31,"a")+1)) | Q31: =IF(Filter!$C31="","",(COUNTIF(Filter!AZ31:BA31,"a")+1)) | R31: =IF(Filter!$C31="","",(COUNTIF(Filter!BB31:BD31,"a")+1)) | S31: =IF(Filter!$C31="","",(COUNTIF(Filter!BE31:BG31,"a")+1)) | T31: =IF(Filter!$C31="","",(COUNTIF(Filter!BH31:BJ31,"a")+1)) | U31: =IF(Filter!$C31="","",(COUNTIF(Filter!BK31:BO31,"a")+1)) | V31: =IF(Filter!$C31="","",(COUNTIF(Filter!BP31:BR31,"a")+1)) | W31: =IF(Filter!$C31="","",(COUNTIF(Filter!BS31:BU31,"a")+1)) | X31: =IF(SUM(E31:N31)=0,"",SUM(E31:N31)/51) | Y31: =IF(SUM(O31:W31)=0,"",SUM(O31:W31)/37) | Z31: =IF(SUM(E31:W31)=0,"",SUM(E31:W31)/88) | AA31: =IF(Z31="","",SUM(Z$31:Z$59)/COUNT(Z$31:Z$59))
A32: =IF(ISBLANK(Test!A32),"",(Test!A32)) | B32: =IF(ISBLANK(Test!B32),"",(Test!B32)) | C32: =IF(ISBLANK(Test!C32),"",(Test!C32)) | D32: =IF(ISBLANK(Test!D32),"",(Test!D32)) | E32: =IF(Filter!$C32="","",(COUNTIF(Filter!E32:H32,"a")+1)) | F32: =IF(Filter!$C32="","",(COUNTIF(Filter!I32:L32,"a")+1)) | G32: =IF(Filter!$C32="","",(COUNTIF(Filter!M32:P32,"a")+1)) | H32: =IF(Filter!$C32="","",(COUNTIF(Filter!Q32:S32,"a")+1)) | I32: =IF(Filter!$C32="","",(COUNTIF(Filter!T32:V32,"a")+1)) | J32: =IF(Filter!$C32="","",(COUNTIF(Filter!W32:Z32,"a")+1)) | K32: =IF(Filter!$C32="","",(COUNTIF(Filter!AA32:AD32,"a")+1)) | L32: =IF(Filter!$C32="","",(COUNTIF(Filter!AE32:AI32,"a")+1)) | M32: =IF(Filter!$C32="","",(COUNTIF(Filter!AJ32:AN32,"a")+1)) | N32: =IF(Filter!$C32="","",(COUNTIF(Filter!AO32:AS32,"a")+1)) | O32: =IF(Filter!$C32="","",(COUNTIF(Filter!AT32:AV32,"a")+1)) | P32: =IF(Filter!$C32="","",(COUNTIF(Filter!AW32:AY32,"a")+1)) | Q32: =IF(Filter!$C32="","",(COUNTIF(Filter!AZ32:BA32,"a")+1)) | R32: =IF(Filter!$C32="","",(COUNTIF(Filter!BB32:BD32,"a")+1)) | S32: =IF(Filter!$C32="","",(COUNTIF(Filter!BE32:BG32,"a")+1)) | T32: =IF(Filter!$C32="","",(COUNTIF(Filter!BH32:BJ32,"a")+1)) | U32: =IF(Filter!$C32="","",(COUNTIF(Filter!BK32:BO32,"a")+1)) | V32: =IF(Filter!$C32="","",(COUNTIF(Filter!BP32:BR32,"a")+1)) | W32: =IF(Filter!$C32="","",(COUNTIF(Filter!BS32:BU32,"a")+1)) | X32: =IF(SUM(E32:N32)=0,"",SUM(E32:N32)/51) | Y32: =IF(SUM(O32:W32)=0,"",SUM(O32:W32)/37) | Z32: =IF(SUM(E32:W32)=0,"",SUM(E32:W32)/88) | AA32: =IF(Z32="","",SUM(Z$31:Z$59)/COUNT(Z$31:Z$59))
A33: =IF(ISBLANK(Test!A33),"",(Test!A33)) | B33: =IF(ISBLANK(Test!B33),"",(Test!B33)) | C33: =IF(ISBLANK(Test!C33),"",(Test!C33)) | D33: =IF(ISBLANK(Test!D33),"",(Test!D33)) | E33: =IF(Filter!$C33="","",(COUNTIF(Filter!E33:H33,"a")+1)) | F33: =IF(Filter!$C33="","",(COUNTIF(Filter!I33:L33,"a")+1)) | G33: =IF(Filter!$C33="","",(COUNTIF(Filter!M33:P33,"a")+1)) | H33: =IF(Filter!$C33="","",(COUNTIF(Filter!Q33:S33,"a")+1)) | I33: =IF(Filter!$C33="","",(COUNTIF(Filter!T33:V33,"a")+1)) | J33: =IF(Filter!$C33="","",(COUNTIF(Filter!W33:Z33,"a")+1)) | K33: =IF(Filter!$C33="","",(COUNTIF(Filter!AA33:AD33,"a")+1)) | L33: =IF(Filter!$C33="","",(COUNTIF(Filter!AE33:AI33,"a")+1)) | M33: =IF(Filter!$C33="","",(COUNTIF(Filter!AJ33:AN33,"a")+1)) | N33: =IF(Filter!$C33="","",(COUNTIF(Filter!AO33:AS33,"a")+1)) | O33: =IF(Filter!$C33="","",(COUNTIF(Filter!AT33:AV33,"a")+1)) | P33: =IF(Filter!$C33="","",(COUNTIF(Filter!AW33:AY33,"a")+1)) | Q33: =IF(Filter!$C33="","",(COUNTIF(Filter!AZ33:BA33,"a")+1)) | R33: =IF(Filter!$C33="","",(COUNTIF(Filter!BB33:BD33,"a")+1)) | S33: =IF(Filter!$C33="","",(COUNTIF(Filter!BE33:BG33,"a")+1)) | T33: =IF(Filter!$C33="","",(COUNTIF(Filter!BH33:BJ33,"a")+1)) | U33: =IF(Filter!$C33="","",(COUNTIF(Filter!BK33:BO33,"a")+1)) | V33: =IF(Filter!$C33="","",(COUNTIF(Filter!BP33:BR33,"a")+1)) | W33: =IF(Filter!$C33="","",(COUNTIF(Filter!BS33:BU33,"a")+1)) | X33: =IF(SUM(E33:N33)=0,"",SUM(E33:N33)/51) | Y33: =IF(SUM(O33:W33)=0,"",SUM(O33:W33)/37) | Z33: =IF(SUM(E33:W33)=0,"",SUM(E33:W33)/88) | AA33: =IF(Z33="","",SUM(Z$31:Z$59)/COUNT(Z$31:Z$59))
A34: =IF(ISBLANK(Test!A34),"",(Test!A34)) | B34: =IF(ISBLANK(Test!B34),"",(Test!B34)) | C34: =IF(ISBLANK(Test!C34),"",(Test!C34)) | D34: =IF(ISBLANK(Test!D34),"",(Test!D34)) | E34: =IF(Filter!$C34="","",(COUNTIF(Filter!E34:H34,"a")+1)) | F34: =IF(Filter!$C34="","",(COUNTIF(Filter!I34:L34,"a")+1)) | G34: =IF(Filter!$C34="","",(COUNTIF(Filter!M34:P34,"a")+1)) | H34: =IF(Filter!$C34="","",(COUNTIF(Filter!Q34:S34,"a")+1)) | I34: =IF(Filter!$C34="","",(COUNTIF(Filter!T34:V34,"a")+1)) | J34: =IF(Filter!$C34="","",(COUNTIF(Filter!W34:Z34,"a")+1)) | K34: =IF(Filter!$C34="","",(COUNTIF(Filter!AA34:AD34,"a")+1)) | L34: =IF(Filter!$C34="","",(COUNTIF(Filter!AE34:AI34,"a")+1)) | M34: =IF(Filter!$C34="","",(COUNTIF(Filter!AJ34:AN34,"a")+1)) | N34: =IF(Filter!$C34="","",(COUNTIF(Filter!AO34:AS34,"a")+1)) | O34: =IF(Filter!$C34="","",(COUNTIF(Filter!AT34:AV34,"a")+1)) | P34: =IF(Filter!$C34="","",(COUNTIF(Filter!AW34:AY34,"a")+1)) | Q34: =IF(Filter!$C34="","",(COUNTIF(Filter!AZ34:BA34,"a")+1)) | R34: =IF(Filter!$C34="","",(COUNTIF(Filter!BB34:BD34,"a")+1)) | S34: =IF(Filter!$C34="","",(COUNTIF(Filter!BE34:BG34,"a")+1)) | T34: =IF(Filter!$C34="","",(COUNTIF(Filter!BH34:BJ34,"a")+1)) | U34: =IF(Filter!$C34="","",(COUNTIF(Filter!BK34:BO34,"a")+1)) | V34: =IF(Filter!$C34="","",(COUNTIF(Filter!BP34:BR34,"a")+1)) | W34: =IF(Filter!$C34="","",(COUNTIF(Filter!BS34:BU34,"a")+1)) | X34: =IF(SUM(E34:N34)=0,"",SUM(E34:N34)/51) | Y34: =IF(SUM(O34:W34)=0,"",SUM(O34:W34)/37) | Z34: =IF(SUM(E34:W34)=0,"",SUM(E34:W34)/88) | AA34: =IF(Z34="","",SUM(Z$31:Z$59)/COUNT(Z$31:Z$59))
A35: =IF(ISBLANK(Test!A35),"",(Test!A35)) | B35: =IF(ISBLANK(Test!B35),"",(Test!B35)) | C35: =IF(ISBLANK(Test!C35),"",(Test!C35)) | D35: =IF(ISBLANK(Test!D35),"",(Test!D35)) | E35: =IF(Filter!$C35="","",(COUNTIF(Filter!E35:H35,"a")+1)) | F35: =IF(Filter!$C35="","",(COUNTIF(Filter!I35:L35,"a")+1)) | G35: =IF(Filter!$C35="","",(COUNTIF(Filter!M35:P35,"a")+1)) | H35: =IF(Filter!$C35="","",(COUNTIF(Filter!Q35:S35,"a")+1)) | I35: =IF(Filter!$C35="","",(COUNTIF(Filter!T35:V35,"a")+1)) | J35: =IF(Filter!$C35="","",(COUNTIF(Filter!W35:Z35,"a")+1)) | K35: =IF(Filter!$C35="","",(COUNTIF(Filter!AA35:AD35,"a")+1)) | L35: =IF(Filter!$C35="","",(COUNTIF(Filter!AE35:AI35,"a")+1)) | M35: =IF(Filter!$C35="","",(COUNTIF(Filter!AJ35:AN35,"a")+1)) | N35: =IF(Filter!$C35="","",(COUNTIF(Filter!AO35:AS35,"a")+1)) | O35: =IF(Filter!$C35="","",(COUNTIF(Filter!AT35:AV35,"a")+1)) | P35: =IF(Filter!$C35="","",(COUNTIF(Filter!AW35:AY35,"a")+1)) | Q35: =IF(Filter!$C35="","",(COUNTIF(Filter!AZ35:BA35,"a")+1)) | R35: =IF(Filter!$C35="","",(COUNTIF(Filter!BB35:BD35,"a")+1)) | S35: =IF(Filter!$C35="","",(COUNTIF(Filter!BE35:BG35,"a")+1)) | T35: =IF(Filter!$C35="","",(COUNTIF(Filter!BH35:BJ35,"a")+1)) | U35: =IF(Filter!$C35="","",(COUNTIF(Filter!BK35:BO35,"a")+1)) | V35: =IF(Filter!$C35="","",(COUNTIF(Filter!BP35:BR35,"a")+1)) | W35: =IF(Filter!$C35="","",(COUNTIF(Filter!BS35:BU35,"a")+1)) | X35: =IF(SUM(E35:N35)=0,"",SUM(E35:N35)/51) | Y35: =IF(SUM(O35:W35)=0,"",SUM(O35:W35)/37) | Z35: =IF(SUM(E35:W35)=0,"",SUM(E35:W35)/88) | AA35: =IF(Z35="","",SUM(Z$31:Z$59)/COUNT(Z$31:Z$59))
A36: =IF(ISBLANK(Test!A36),"",(Test!A36)) | B36: =IF(ISBLANK(Test!B36),"",(Test!B36)) | C36: =IF(ISBLANK(Test!C36),"",(Test!C36)) | D36: =IF(ISBLANK(Test!D36),"",(Test!D36)) | E36: =IF(Filter!$C36="","",(COUNTIF(Filter!E36:H36,"a")+1)) | F36: =IF(Filter!$C36="","",(COUNTIF(Filter!I36:L36,"a")+1)) | G36: =IF(Filter!$C36="","",(COUNTIF(Filter!M36:P36,"a")+1)) | H36: =IF(Filter!$C36="","",(COUNTIF(Filter!Q36:S36,"a")+1)) | I36: =IF(Filter!$C36="","",(COUNTIF(Filter!T36:V36,"a")+1)) | J36: =IF(Filter!$C36="","",(COUNTIF(Filter!W36:Z36,"a")+1)) | K36: =IF(Filter!$C36="","",(COUNTIF(Filter!AA36:AD36,"a")+1)) | L36: =IF(Filter!$C36="","",(COUNTIF(Filter!AE36:AI36,"a")+1)) | M36: =IF(Filter!$C36="","",(COUNTIF(Filter!AJ36:AN36,"a")+1)) | N36: =IF(Filter!$C36="","",(COUNTIF(Filter!AO36:AS36,"a")+1)) | O36: =IF(Filter!$C36="","",(COUNTIF(Filter!AT36:AV36,"a")+1)) | P36: =IF(Filter!$C36="","",(COUNTIF(Filter!AW36:AY36,"a")+1)) | Q36: =IF(Filter!$C36="","",(COUNTIF(Filter!AZ36:BA36,"a")+1)) | R36: =IF(Filter!$C36="","",(COUNTIF(Filter!BB36:BD36,"a")+1)) | S36: =IF(Filter!$C36="","",(COUNTIF(Filter!BE36:BG36,"a")+1)) | T36: =IF(Filter!$C36="","",(COUNTIF(Filter!BH36:BJ36,"a")+1)) | U36: =IF(Filter!$C36="","",(COUNTIF(Filter!BK36:BO36,"a")+1)) | V36: =IF(Filter!$C36="","",(COUNTIF(Filter!BP36:BR36,"a")+1)) | W36: =IF(Filter!$C36="","",(COUNTIF(Filter!BS36:BU36,"a")+1)) | X36: =IF(SUM(E36:N36)=0,"",SUM(E36:N36)/51) | Y36: =IF(SUM(O36:W36)=0,"",SUM(O36:W36)/37) | Z36: =IF(SUM(E36:W36)=0,"",SUM(E36:W36)/88) | AA36: =IF(Z36="","",SUM(Z$31:Z$59)/COUNT(Z$31:Z$59))
A37: =IF(ISBLANK(Test!A37),"",(Test!A37)) | B37: =IF(ISBLANK(Test!B37),"",(Test!B37)) | C37: =IF(ISBLANK(Test!C37),"",(Test!C37)) | D37: =IF(ISBLANK(Test!D37),"",(Test!D37)) | E37: =IF(Filter!$C37="","",(COUNTIF(Filter!E37:H37,"a")+1)) | F37: =IF(Filter!$C37="","",(COUNTIF(Filter!I37:L37,"a")+1)) | G37: =IF(Filter!$C37="","",(COUNTIF(Filter!M37:P37,"a")+1)) | H37: =IF(Filter!$C37="","",(COUNTIF(Filter!Q37:S37,"a")+1)) | I37: =IF(Filter!$C37="","",(COUNTIF(Filter!T37:V37,"a")+1)) | J37: =IF(Filter!$C37="","",(COUNTIF(Filter!W37:Z37,"a")+1)) | K37: =IF(Filter!$C37="","",(COUNTIF(Filter!AA37:AD37,"a")+1)) | L37: =IF(Filter!$C37="","",(COUNTIF(Filter!AE37:AI37,"a")+1)) | M37: =IF(Filter!$C37="","",(COUNTIF(Filter!AJ37:AN37,"a")+1)) | N37: =IF(Filter!$C37="","",(COUNTIF(Filter!AO37:AS37,"a")+1)) | O37: =IF(Filter!$C37="","",(COUNTIF(Filter!AT37:AV37,"a")+1)) | P37: =IF(Filter!$C37="","",(COUNTIF(Filter!AW37:AY37,"a")+1)) | Q37: =IF(Filter!$C37="","",(COUNTIF(Filter!AZ37:BA37,"a")+1)) | R37: =IF(Filter!$C37="","",(COUNTIF(Filter!BB37:BD37,"a")+1)) | S37: =IF(Filter!$C37="","",(COUNTIF(Filter!BE37:BG37,"a")+1)) | T37: =IF(Filter!$C37="","",(COUNTIF(Filter!BH37:BJ37,"a")+1)) | U37: =IF(Filter!$C37="","",(COUNTIF(Filter!BK37:BO37,"a")+1)) | V37: =IF(Filter!$C37="","",(COUNTIF(Filter!BP37:BR37,"a")+1)) | W37: =IF(Filter!$C37="","",(COUNTIF(Filter!BS37:BU37,"a")+1)) | X37: =IF(SUM(E37:N37)=0,"",SUM(E37:N37)/51) | Y37: =IF(SUM(O37:W37)=0,"",SUM(O37:W37)/37) | Z37: =IF(SUM(E37:W37)=0,"",SUM(E37:W37)/88) | AA37: =IF(Z37="","",SUM(Z$31:Z$59)/COUNT(Z$31:Z$59))
A38: =IF(ISBLANK(Test!A38),"",(Test!A38)) | B38: =IF(ISBLANK(Test!B38),"",(Test!B38)) | C38: =IF(ISBLANK(Test!C38),"",(Test!C38)) | D38: =IF(ISBLANK(Test!D38),"",(Test!D38)) | E38: =IF(Filter!$C38="","",(COUNTIF(Filter!E38:H38,"a")+1)) | F38: =IF(Filter!$C38="","",(COUNTIF(Filter!I38:L38,"a")+1)) | G38: =IF(Filter!$C38="","",(COUNTIF(Filter!M38:P38,"a")+1)) | H38: =IF(Filter!$C38="","",(COUNTIF(Filter!Q38:S38,"a")+1)) | I38: =IF(Filter!$C38="","",(COUNTIF(Filter!T38:V38,"a")+1)) | J38: =IF(Filter!$C38="","",(COUNTIF(Filter!W38:Z38,"a")+1)) | K38: =IF(Filter!$C38="","",(COUNTIF(Filter!AA38:AD38,"a")+1)) | L38: =IF(Filter!$C38="","",(COUNTIF(Filter!AE38:AI38,"a")+1)) | M38: =IF(Filter!$C38="","",(COUNTIF(Filter!AJ38:AN38,"a")+1)) | N38: =IF(Filter!$C38="","",(COUNTIF(Filter!AO38:AS38,"a")+1)) | O38: =IF(Filter!$C38="","",(COUNTIF(Filter!AT38:AV38,"a")+1)) | P38: =IF(Filter!$C38="","",(COUNTIF(Filter!AW38:AY38,"a")+1)) | Q38: =IF(Filter!$C38="","",(COUNTIF(Filter!AZ38:BA38,"a")+1)) | R38: =IF(Filter!$C38="","",(COUNTIF(Filter!BB38:BD38,"a")+1)) | S38: =IF(Filter!$C38="","",(COUNTIF(Filter!BE38:BG38,"a")+1)) | T38: =IF(Filter!$C38="","",(COUNTIF(Filter!BH38:BJ38,"a")+1)) | U38: =IF(Filter!$C38="","",(COUNTIF(Filter!BK38:BO38,"a")+1)) | V38: =IF(Filter!$C38="","",(COUNTIF(Filter!BP38:BR38,"a")+1)) | W38: =IF(Filter!$C38="","",(COUNTIF(Filter!BS38:BU38,"a")+1)) | X38: =IF(SUM(E38:N38)=0,"",SUM(E38:N38)/51) | Y38: =IF(SUM(O38:W38)=0,"",SUM(O38:W38)/37) | Z38: =IF(SUM(E38:W38)=0,"",SUM(E38:W38)/88) | AA38: =IF(Z38="","",SUM(Z$31:Z$59)/COUNT(Z$31:Z$59))
A39: =IF(ISBLANK(Test!A39),"",(Test!A39)) | B39: =IF(ISBLANK(Test!B39),"",(Test!B39)) | C39: =IF(ISBLANK(Test!C39),"",(Test!C39)) | D39: =IF(ISBLANK(Test!D39),"",(Test!D39)) | E39: =IF(Filter!$C39="","",(COUNTIF(Filter!E39:H39,"a")+1)) | F39: =IF(Filter!$C39="","",(COUNTIF(Filter!I39:L39,"a")+1)) | G39: =IF(Filter!$C39="","",(COUNTIF(Filter!M39:P39,"a")+1)) | H39: =IF(Filter!$C39="","",(COUNTIF(Filter!Q39:S39,"a")+1)) | I39: =IF(Filter!$C39="","",(COUNTIF(Filter!T39:V39,"a")+1)) | J39: =IF(Filter!$C39="","",(COUNTIF(Filter!W39:Z39,"a")+1)) | K39: =IF(Filter!$C39="","",(COUNTIF(Filter!AA39:AD39,"a")+1)) | L39: =IF(Filter!$C39="","",(COUNTIF(Filter!AE39:AI39,"a")+1)) | M39: =IF(Filter!$C39="","",(COUNTIF(Filter!AJ39:AN39,"a")+1)) | N39: =IF(Filter!$C39="","",(COUNTIF(Filter!AO39:AS39,"a")+1)) | O39: =IF(Filter!$C39="","",(COUNTIF(Filter!AT39:AV39,"a")+1)) | P39: =IF(Filter!$C39="","",(COUNTIF(Filter!AW39:AY39,"a")+1)) | Q39: =IF(Filter!$C39="","",(COUNTIF(Filter!AZ39:BA39,"a")+1)) | R39: =IF(Filter!$C39="","",(COUNTIF(Filter!BB39:BD39,"a")+1)) | S39: =IF(Filter!$C39="","",(COUNTIF(Filter!BE39:BG39,"a")+1)) | T39: =IF(Filter!$C39="","",(COUNTIF(Filter!BH39:BJ39,"a")+1)) | U39: =IF(Filter!$C39="","",(COUNTIF(Filter!BK39:BO39,"a")+1)) | V39: =IF(Filter!$C39="","",(COUNTIF(Filter!BP39:BR39,"a")+1)) | W39: =IF(Filter!$C39="","",(COUNTIF(Filter!BS39:BU39,"a")+1)) | X39: =IF(SUM(E39:N39)=0,"",SUM(E39:N39)/51) | Y39: =IF(SUM(O39:W39)=0,"",SUM(O39:W39)/37) | Z39: =IF(SUM(E39:W39)=0,"",SUM(E39:W39)/88) | AA39: =IF(Z39="","",SUM(Z$31:Z$59)/COUNT(Z$31:Z$59))
A40: =IF(ISBLANK(Test!A40),"",(Test!A40)) | B40: =IF(ISBLANK(Test!B40),"",(Test!B40)) | C40: =IF(ISBLANK(Test!C40),"",(Test!C40)) | D40: =IF(ISBLANK(Test!D40),"",(Test!D40)) | E40: =IF(Filter!$C40="","",(COUNTIF(Filter!E40:H40,"a")+1)) | F40: =IF(Filter!$C40="","",(COUNTIF(Filter!I40:L40,"a")+1)) | G40: =IF(Filter!$C40="","",(COUNTIF(Filter!M40:P40,"a")+1)) | H40: =IF(Filter!$C40="","",(COUNTIF(Filter!Q40:S40,"a")+1)) | I40: =IF(Filter!$C40="","",(COUNTIF(Filter!T40:V40,"a")+1)) | J40: =IF(Filter!$C40="","",(COUNTIF(Filter!W40:Z40,"a")+1)) | K40: =IF(Filter!$C40="","",(COUNTIF(Filter!AA40:AD40,"a")+1)) | L40: =IF(Filter!$C40="","",(COUNTIF(Filter!AE40:AI40,"a")+1)) | M40: =IF(Filter!$C40="","",(COUNTIF(Filter!AJ40:AN40,"a")+1)) | N40: =IF(Filter!$C40="","",(COUNTIF(Filter!AO40:AS40,"a")+1)) | O40: =IF(Filter!$C40="","",(COUNTIF(Filter!AT40:AV40,"a")+1)) | P40: =IF(Filter!$C40="","",(COUNTIF(Filter!AW40:AY40,"a")+1)) | Q40: =IF(Filter!$C40="","",(COUNTIF(Filter!AZ40:BA40,"a")+1)) | R40: =IF(Filter!$C40="","",(COUNTIF(Filter!BB40:BD40,"a")+1)) | S40: =IF(Filter!$C40="","",(COUNTIF(Filter!BE40:BG40,"a")+1)) | T40: =IF(Filter!$C40="","",(COUNTIF(Filter!BH40:BJ40,"a")+1)) | U40: =IF(Filter!$C40="","",(COUNTIF(Filter!BK40:BO40,"a")+1)) | V40: =IF(Filter!$C40="","",(COUNTIF(Filter!BP40:BR40,"a")+1)) | W40: =IF(Filter!$C40="","",(COUNTIF(Filter!BS40:BU40,"a")+1)) | X40: =IF(SUM(E40:N40)=0,"",SUM(E40:N40)/51) | Y40: =IF(SUM(O40:W40)=0,"",SUM(O40:W40)/37) | Z40: =IF(SUM(E40:W40)=0,"",SUM(E40:W40)/88) | AA40: =IF(Z40="","",SUM(Z$31:Z$59)/COUNT(Z$31:Z$59))
A41: =IF(ISBLANK(Test!A41),"",(Test!A41)) | B41: =IF(ISBLANK(Test!B41),"",(Test!B41)) | C41: =IF(ISBLANK(Test!C41),"",(Test!C41)) | D41: =IF(ISBLANK(Test!D41),"",(Test!D41)) | E41: =IF(Filter!$C41="","",(COUNTIF(Filter!E41:H41,"a")+1)) | F41: =IF(Filter!$C41="","",(COUNTIF(Filter!I41:L41,"a")+1)) | G41: =IF(Filter!$C41="","",(COUNTIF(Filter!M41:P41,"a")+1)) | H41: =IF(Filter!$C41="","",(COUNTIF(Filter!Q41:S41,"a")+1)) | I41: =IF(Filter!$C41="","",(COUNTIF(Filter!T41:V41,"a")+1)) | J41: =IF(Filter!$C41="","",(COUNTIF(Filter!W41:Z41,"a")+1)) | K41: =IF(Filter!$C41="","",(COUNTIF(Filter!AA41:AD41,"a")+1)) | L41: =IF(Filter!$C41="","",(COUNTIF(Filter!AE41:AI41,"a")+1)) | M41: =IF(Filter!$C41="","",(COUNTIF(Filter!AJ41:AN41,"a")+1)) | N41: =IF(Filter!$C41="","",(COUNTIF(Filter!AO41:AS41,"a")+1)) | O41: =IF(Filter!$C41="","",(COUNTIF(Filter!AT41:AV41,"a")+1)) | P41: =IF(Filter!$C41="","",(COUNTIF(Filter!AW41:AY41,"a")+1)) | Q41: =IF(Filter!$C41="","",(COUNTIF(Filter!AZ41:BA41,"a")+1)) | R41: =IF(Filter!$C41="","",(COUNTIF(Filter!BB41:BD41,"a")+1)) | S41: =IF(Filter!$C41="","",(COUNTIF(Filter!BE41:BG41,"a")+1)) | T41: =IF(Filter!$C41="","",(COUNTIF(Filter!BH41:BJ41,"a")+1)) | U41: =IF(Filter!$C41="","",(COUNTIF(Filter!BK41:BO41,"a")+1)) | V41: =IF(Filter!$C41="","",(COUNTIF(Filter!BP41:BR41,"a")+1)) | W41: =IF(Filter!$C41="","",(COUNTIF(Filter!BS41:BU41,"a")+1)) | X41: =IF(SUM(E41:N41)=0,"",SUM(E41:N41)/51) | Y41: =IF(SUM(O41:W41)=0,"",SUM(O41:W41)/37) | Z41: =IF(SUM(E41:W41)=0,"",SUM(E41:W41)/88) | AA41: =IF(Z41="","",SUM(Z$31:Z$59)/COUNT(Z$31:Z$59))
A42: =IF(ISBLANK(Test!A42),"",(Test!A42)) | B42: =IF(ISBLANK(Test!B42),"",(Test!B42)) | C42: =IF(ISBLANK(Test!C42),"",(Test!C42)) | D42: =IF(ISBLANK(Test!D42),"",(Test!D42)) | E42: =IF(Filter!$C42="","",(COUNTIF(Filter!E42:H42,"a")+1)) | F42: =IF(Filter!$C42="","",(COUNTIF(Filter!I42:L42,"a")+1)) | G42: =IF(Filter!$C42="","",(COUNTIF(Filter!M42:P42,"a")+1)) | H42: =IF(Filter!$C42="","",(COUNTIF(Filter!Q42:S42,"a")+1)) | I42: =IF(Filter!$C42="","",(COUNTIF(Filter!T42:V42,"a")+1)) | J42: =IF(Filter!$C42="","",(COUNTIF(Filter!W42:Z42,"a")+1)) | K42: =IF(Filter!$C42="","",(COUNTIF(Filter!AA42:AD42,"a")+1)) | L42: =IF(Filter!$C42="","",(COUNTIF(Filter!AE42:AI42,"a")+1)) | M42: =IF(Filter!$C42="","",(COUNTIF(Filter!AJ42:AN42,"a")+1)) | N42: =IF(Filter!$C42="","",(COUNTIF(Filter!AO42:AS42,"a")+1)) | O42: =IF(Filter!$C42="","",(COUNTIF(Filter!AT42:AV42,"a")+1)) | P42: =IF(Filter!$C42="","",(COUNTIF(Filter!AW42:AY42,"a")+1)) | Q42: =IF(Filter!$C42="","",(COUNTIF(Filter!AZ42:BA42,"a")+1)) | R42: =IF(Filter!$C42="","",(COUNTIF(Filter!BB42:BD42,"a")+1)) | S42: =IF(Filter!$C42="","",(COUNTIF(Filter!BE42:BG42,"a")+1)) | T42: =IF(Filter!$C42="","",(COUNTIF(Filter!BH42:BJ42,"a")+1)) | U42: =IF(Filter!$C42="","",(COUNTIF(Filter!BK42:BO42,"a")+1)) | V42: =IF(Filter!$C42="","",(COUNTIF(Filter!BP42:BR42,"a")+1)) | W42: =IF(Filter!$C42="","",(COUNTIF(Filter!BS42:BU42,"a")+1)) | X42: =IF(SUM(E42:N42)=0,"",SUM(E42:N42)/51) | Y42: =IF(SUM(O42:W42)=0,"",SUM(O42:W42)/37) | Z42: =IF(SUM(E42:W42)=0,"",SUM(E42:W42)/88) | AA42: =IF(Z42="","",SUM(Z$31:Z$59)/COUNT(Z$31:Z$59))
... A59: =IF(ISBLANK(Test!A59),"",(Test!A59)) | B59: =IF(ISBLANK(Test!B59),"",(Test!B59)) | C59: =IF(ISBLANK(Test!C59),"",(Test!C59)) | D59: =IF(ISBLANK(Test!D59),"",(Test!D59)) | E59: =IF(Filter!$C59="","",(COUNTIF(Filter!E59:H59,"a")+1)) | F59: =IF(Filter!$C59="","",(COUNTIF(Filter!I59:L59,"a")+1)) | G59: =IF(Filter!$C59="","",(COUNTIF(Filter!M59:P59,"a")+1)) | H59: =IF(Filter!$C59="","",(COUNTIF(Filter!Q59:S59,"a")+1)) | I59: =IF(Filter!$C59="","",(COUNTIF(Filter!T59:V59,"a")+1)) | J59: =IF(Filter!$C59="","",(COUNTIF(Filter!W59:Z59,"a")+1)) | K59: =IF(Filter!$C59="","",(COUNTIF(Filter!AA59:AD59,"a")+1)) | L59: =IF(Filter!$C59="","",(COUNTIF(Filter!AE59:AI59,"a")+1)) | M59: =IF(Filter!$C59="","",(COUNTIF(Filter!AJ59:AN59,"a")+1)) | N59: =IF(Filter!$C59="","",(COUNTIF(Filter!AO59:AS59,"a")+1)) | O59: =IF(Filter!$C59="","",(COUNTIF(Filter!AT59:AV59,"a")+1)) | P59: =IF(Filter!$C59="","",(COUNTIF(Filter!AW59:AY59,"a")+1)) | Q59: =IF(Filter!$C59="","",(COUNTIF(Filter!AZ59:BA59,"a")+1)) | R59: =IF(Filter!$C59="","",(COUNTIF(Filter!BB59:BD59,"a")+1)) | S59: =IF(Filter!$C59="","",(COUNTIF(Filter!BE59:BG59,"a")+1)) | T59: =IF(Filter!$C59="","",(COUNTIF(Filter!BH59:BJ59,"a")+1)) | U59: =IF(Filter!$C59="","",(COUNTIF(Filter!BK59:BO59,"a")+1)) | V59: =IF(Filter!$C59="","",(COUNTIF(Filter!BP59:BR59,"a")+1)) | W59: =IF(Filter!$C59="","",(COUNTIF(Filter!BS59:BU59,"a")+1)) | X59: =IF(SUM(E59:N59)=0,"",SUM(E59:N59)/51) | Y59: =IF(SUM(O59:W59)=0,"",SUM(O59:W59)/37) | Z59: =IF(SUM(E59:W59)=0,"",SUM(E59:W59)/88) | AA59: =IF(Z59="","",SUM(Z$31:Z$59)/COUNT(Z$31:Z$59))
A60: =IF(ISBLANK(Test!A60),"",(Test!A60)) -> Teacher 3 | B60: =IF(ISBLANK(Test!B60),"",(Test!B60)) | C60: =IF(ISBLANK(Test!C60),"",(Test!C60)) | D60: =IF(ISBLANK(Test!D60),"",(Test!D60)) | E60: =IF(Filter!$C60="","",(COUNTIF(Filter!E60:H60,"a")+1)) | F60: =IF(Filter!$C60="","",(COUNTIF(Filter!I60:L60,"a")+1)) | G60: =IF(Filter!$C60="","",(COUNTIF(Filter!M60:P60,"a")+1)) | H60: =IF(Filter!$C60="","",(COUNTIF(Filter!Q60:S60,"a")+1)) | I60: =IF(Filter!$C60="","",(COUNTIF(Filter!T60:V60,"a")+1)) | J60: =IF(Filter!$C60="","",(COUNTIF(Filter!W60:Z60,"a")+1)) | K60: =IF(Filter!$C60="","",(COUNTIF(Filter!AA60:AD60,"a")+1)) | L60: =IF(Filter!$C60="","",(COUNTIF(Filter!AE60:AI60,"a")+1)) | M60: =IF(Filter!$C60="","",(COUNTIF(Filter!AJ60:AN60,"a")+1)) | N60: =IF(Filter!$C60="","",(COUNTIF(Filter!AO60:AS60,"a")+1)) | O60: =IF(Filter!$C60="","",(COUNTIF(Filter!AT60:AV60,"a")+1)) | P60: =IF(Filter!$C60="","",(COUNTIF(Filter!AW60:AY60,"a")+1)) | Q60: =IF(Filter!$C60="","",(COUNTIF(Filter!AZ60:BA60,"a")+1)) | R60: =IF(Filter!$C60="","",(COUNTIF(Filter!BB60:BD60,"a")+1)) | S60: =IF(Filter!$C60="","",(COUNTIF(Filter!BE60:BG60,"a")+1)) | T60: =IF(Filter!$C60="","",(COUNTIF(Filter!BH60:BJ60,"a")+1)) | U60: =IF(Filter!$C60="","",(COUNTIF(Filter!BK60:BO60,"a")+1)) | V60: =IF(Filter!$C60="","",(COUNTIF(Filter!BP60:BR60,"a")+1)) | W60: =IF(Filter!$C60="","",(COUNTIF(Filter!BS60:BU60,"a")+1)) | X60: =IF(SUM(E60:N60)=0,"",SUM(E60:N60)/51) | Y60: =IF(SUM(O60:W60)=0,"",SUM(O60:W60)/37) | Z60: =IF(SUM(E60:W60)=0,"",SUM(E60:W60)/88) | AA60: =IF(Z60="","",SUM(Z$60:Z$88)/COUNT(Z$60:Z$88))
A61: =IF(ISBLANK(Test!A61),"",(Test!A61)) | B61: =IF(ISBLANK(Test!B61),"",(Test!B61)) | C61: =IF(ISBLANK(Test!C61),"",(Test!C61)) | D61: =IF(ISBLANK(Test!D61),"",(Test!D61)) | E61: =IF(Filter!$C61="","",(COUNTIF(Filter!E61:H61,"a")+1)) | F61: =IF(Filter!$C61="","",(COUNTIF(Filter!I61:L61,"a")+1)) | G61: =IF(Filter!$C61="","",(COUNTIF(Filter!M61:P61,"a")+1)) | H61: =IF(Filter!$C61="","",(COUNTIF(Filter!Q61:S61,"a")+1)) | I61: =IF(Filter!$C61="","",(COUNTIF(Filter!T61:V61,"a")+1)) | J61: =IF(Filter!$C61="","",(COUNTIF(Filter!W61:Z61,"a")+1)) | K61: =IF(Filter!$C61="","",(COUNTIF(Filter!AA61:AD61,"a")+1)) | L61: =IF(Filter!$C61="","",(COUNTIF(Filter!AE61:AI61,"a")+1)) | M61: =IF(Filter!$C61="","",(COUNTIF(Filter!AJ61:AN61,"a")+1)) | N61: =IF(Filter!$C61="","",(COUNTIF(Filter!AO61:AS61,"a")+1)) | O61: =IF(Filter!$C61="","",(COUNTIF(Filter!AT61:AV61,"a")+1)) | P61: =IF(Filter!$C61="","",(COUNTIF(Filter!AW61:AY61,"a")+1)) | Q61: =IF(Filter!$C61="","",(COUNTIF(Filter!AZ61:BA61,"a")+1)) | R61: =IF(Filter!$C61="","",(COUNTIF(Filter!BB61:BD61,"a")+1)) | S61: =IF(Filter!$C61="","",(COUNTIF(Filter!BE61:BG61,"a")+1)) | T61: =IF(Filter!$C61="","",(COUNTIF(Filter!BH61:BJ61,"a")+1)) | U61: =IF(Filter!$C61="","",(COUNTIF(Filter!BK61:BO61,"a")+1)) | V61: =IF(Filter!$C61="","",(COUNTIF(Filter!BP61:BR61,"a")+1)) | W61: =IF(Filter!$C61="","",(COUNTIF(Filter!BS61:BU61,"a")+1)) | X61: =IF(SUM(E61:N61)=0,"",SUM(E61:N61)/51) | Y61: =IF(SUM(O61:W61)=0,"",SUM(O61:W61)/37) | Z61: =IF(SUM(E61:W61)=0,"",SUM(E61:W61)/88) | AA61: =IF(Z61="","",SUM(Z$60:Z$88)/COUNT(Z$60:Z$88))
A62: =IF(ISBLANK(Test!A62),"",(Test!A62)) | B62: =IF(ISBLANK(Test!B62),"",(Test!B62)) | C62: =IF(ISBLANK(Test!C62),"",(Test!C62)) | D62: =IF(ISBLANK(Test!D62),"",(Test!D62)) | E62: =IF(Filter!$C62="","",(COUNTIF(Filter!E62:H62,"a")+1)) | F62: =IF(Filter!$C62="","",(COUNTIF(Filter!I62:L62,"a")+1)) | G62: =IF(Filter!$C62="","",(COUNTIF(Filter!M62:P62,"a")+1)) | H62: =IF(Filter!$C62="","",(COUNTIF(Filter!Q62:S62,"a")+1)) | I62: =IF(Filter!$C62="","",(COUNTIF(Filter!T62:V62,"a")+1)) | J62: =IF(Filter!$C62="","",(COUNTIF(Filter!W62:Z62,"a")+1)) | K62: =IF(Filter!$C62="","",(COUNTIF(Filter!AA62:AD62,"a")+1)) | L62: =IF(Filter!$C62="","",(COUNTIF(Filter!AE62:AI62,"a")+1)) | M62: =IF(Filter!$C62="","",(COUNTIF(Filter!AJ62:AN62,"a")+1)) | N62: =IF(Filter!$C62="","",(COUNTIF(Filter!AO62:AS62,"a")+1)) | O62: =IF(Filter!$C62="","",(COUNTIF(Filter!AT62:AV62,"a")+1)) | P62: =IF(Filter!$C62="","",(COUNTIF(Filter!AW62:AY62,"a")+1)) | Q62: =IF(Filter!$C62="","",(COUNTIF(Filter!AZ62:BA62,"a")+1)) | R62: =IF(Filter!$C62="","",(COUNTIF(Filter!BB62:BD62,"a")+1)) | S62: =IF(Filter!$C62="","",(COUNTIF(Filter!BE62:BG62,"a")+1)) | T62: =IF(Filter!$C62="","",(COUNTIF(Filter!BH62:BJ62,"a")+1)) | U62: =IF(Filter!$C62="","",(COUNTIF(Filter!BK62:BO62,"a")+1)) | V62: =IF(Filter!$C62="","",(COUNTIF(Filter!BP62:BR62,"a")+1)) | W62: =IF(Filter!$C62="","",(COUNTIF(Filter!BS62:BU62,"a")+1)) | X62: =IF(SUM(E62:N62)=0,"",SUM(E62:N62)/51) | Y62: =IF(SUM(O62:W62)=0,"",SUM(O62:W62)/37) | Z62: =IF(SUM(E62:W62)=0,"",SUM(E62:W62)/88) | AA62: =IF(Z62="","",SUM(Z$60:Z$88)/COUNT(Z$60:Z$88))
A63: =IF(ISBLANK(Test!A63),"",(Test!A63)) | B63: =IF(ISBLANK(Test!B63),"",(Test!B63)) | C63: =IF(ISBLANK(Test!C63),"",(Test!C63)) | D63: =IF(ISBLANK(Test!D63),"",(Test!D63)) | E63: =IF(Filter!$C63="","",(COUNTIF(Filter!E63:H63,"a")+1)) | F63: =IF(Filter!$C63="","",(COUNTIF(Filter!I63:L63,"a")+1)) | G63: =IF(Filter!$C63="","",(COUNTIF(Filter!M63:P63,"a")+1)) | H63: =IF(Filter!$C63="","",(COUNTIF(Filter!Q63:S63,"a")+1)) | I63: =IF(Filter!$C63="","",(COUNTIF(Filter!T63:V63,"a")+1)) | J63: =IF(Filter!$C63="","",(COUNTIF(Filter!W63:Z63,"a")+1)) | K63: =IF(Filter!$C63="","",(COUNTIF(Filter!AA63:AD63,"a")+1)) | L63: =IF(Filter!$C63="","",(COUNTIF(Filter!AE63:AI63,"a")+1)) | M63: =IF(Filter!$C63="","",(COUNTIF(Filter!AJ63:AN63,"a")+1)) | N63: =IF(Filter!$C63="","",(COUNTIF(Filter!AO63:AS63,"a")+1)) | O63: =IF(Filter!$C63="","",(COUNTIF(Filter!AT63:AV63,"a")+1)) | P63: =IF(Filter!$C63="","",(COUNTIF(Filter!AW63:AY63,"a")+1)) | Q63: =IF(Filter!$C63="","",(COUNTIF(Filter!AZ63:BA63,"a")+1)) | R63: =IF(Filter!$C63="","",(COUNTIF(Filter!BB63:BD63,"a")+1)) | S63: =IF(Filter!$C63="","",(COUNTIF(Filter!BE63:BG63,"a")+1)) | T63: =IF(Filter!$C63="","",(COUNTIF(Filter!BH63:BJ63,"a")+1)) | U63: =IF(Filter!$C63="","",(COUNTIF(Filter!BK63:BO63,"a")+1)) | V63: =IF(Filter!$C63="","",(COUNTIF(Filter!BP63:BR63,"a")+1)) | W63: =IF(Filter!$C63="","",(COUNTIF(Filter!BS63:BU63,"a")+1)) | X63: =IF(SUM(E63:N63)=0,"",SUM(E63:N63)/51) | Y63: =IF(SUM(O63:W63)=0,"",SUM(O63:W63)/37) | Z63: =IF(SUM(E63:W63)=0,"",SUM(E63:W63)/88) | AA63: =IF(Z63="","",SUM(Z$60:Z$88)/COUNT(Z$60:Z$88))
A64: =IF(ISBLANK(Test!A64),"",(Test!A64)) | B64: =IF(ISBLANK(Test!B64),"",(Test!B64)) | C64: =IF(ISBLANK(Test!C64),"",(Test!C64)) | D64: =IF(ISBLANK(Test!D64),"",(Test!D64)) | E64: =IF(Filter!$C64="","",(COUNTIF(Filter!E64:H64,"a")+1)) | F64: =IF(Filter!$C64="","",(COUNTIF(Filter!I64:L64,"a")+1)) | G64: =IF(Filter!$C64="","",(COUNTIF(Filter!M64:P64,"a")+1)) | H64: =IF(Filter!$C64="","",(COUNTIF(Filter!Q64:S64,"a")+1)) | I64: =IF(Filter!$C64="","",(COUNTIF(Filter!T64:V64,"a")+1)) | J64: =IF(Filter!$C64="","",(COUNTIF(Filter!W64:Z64,"a")+1)) | K64: =IF(Filter!$C64="","",(COUNTIF(Filter!AA64:AD64,"a")+1)) | L64: =IF(Filter!$C64="","",(COUNTIF(Filter!AE64:AI64,"a")+1)) | M64: =IF(Filter!$C64="","",(COUNTIF(Filter!AJ64:AN64,"a")+1)) | N64: =IF(Filter!$C64="","",(COUNTIF(Filter!AO64:AS64,"a")+1)) | O64: =IF(Filter!$C64="","",(COUNTIF(Filter!AT64:AV64,"a")+1)) | P64: =IF(Filter!$C64="","",(COUNTIF(Filter!AW64:AY64,"a")+1)) | Q64: =IF(Filter!$C64="","",(COUNTIF(Filter!AZ64:BA64,"a")+1)) | R64: =IF(Filter!$C64="","",(COUNTIF(Filter!BB64:BD64,"a")+1)) | S64: =IF(Filter!$C64="","",(COUNTIF(Filter!BE64:BG64,"a")+1)) | T64: =IF(Filter!$C64="","",(COUNTIF(Filter!BH64:BJ64,"a")+1)) | U64: =IF(Filter!$C64="","",(COUNTIF(Filter!BK64:BO64,"a")+1)) | V64: =IF(Filter!$C64="","",(COUNTIF(Filter!BP64:BR64,"a")+1)) | W64: =IF(Filter!$C64="","",(COUNTIF(Filter!BS64:BU64,"a")+1)) | X64: =IF(SUM(E64:N64)=0,"",SUM(E64:N64)/51) | Y64: =IF(SUM(O64:W64)=0,"",SUM(O64:W64)/37) | Z64: =IF(SUM(E64:W64)=0,"",SUM(E64:W64)/88) | AA64: =IF(Z64="","",SUM(Z$60:Z$88)/COUNT(Z$60:Z$88))
A65: =IF(ISBLANK(Test!A65),"",(Test!A65)) | B65: =IF(ISBLANK(Test!B65),"",(Test!B65)) | C65: =IF(ISBLANK(Test!C65),"",(Test!C65)) | D65: =IF(ISBLANK(Test!D65),"",(Test!D65)) | E65: =IF(Filter!$C65="","",(COUNTIF(Filter!E65:H65,"a")+1)) | F65: =IF(Filter!$C65="","",(COUNTIF(Filter!I65:L65,"a")+1)) | G65: =IF(Filter!$C65="","",(COUNTIF(Filter!M65:P65,"a")+1)) | H65: =IF(Filter!$C65="","",(COUNTIF(Filter!Q65:S65,"a")+1)) | I65: =IF(Filter!$C65="","",(COUNTIF(Filter!T65:V65,"a")+1)) | J65: =IF(Filter!$C65="","",(COUNTIF(Filter!W65:Z65,"a")+1)) | K65: =IF(Filter!$C65="","",(COUNTIF(Filter!AA65:AD65,"a")+1)) | L65: =IF(Filter!$C65="","",(COUNTIF(Filter!AE65:AI65,"a")+1)) | M65: =IF(Filter!$C65="","",(COUNTIF(Filter!AJ65:AN65,"a")+1)) | N65: =IF(Filter!$C65="","",(COUNTIF(Filter!AO65:AS65,"a")+1)) | O65: =IF(Filter!$C65="","",(COUNTIF(Filter!AT65:AV65,"a")+1)) | P65: =IF(Filter!$C65="","",(COUNTIF(Filter!AW65:AY65,"a")+1)) | Q65: =IF(Filter!$C65="","",(COUNTIF(Filter!AZ65:BA65,"a")+1)) | R65: =IF(Filter!$C65="","",(COUNTIF(Filter!BB65:BD65,"a")+1)) | S65: =IF(Filter!$C65="","",(COUNTIF(Filter!BE65:BG65,"a")+1)) | T65: =IF(Filter!$C65="","",(COUNTIF(Filter!BH65:BJ65,"a")+1)) | U65: =IF(Filter!$C65="","",(COUNTIF(Filter!BK65:BO65,"a")+1)) | V65: =IF(Filter!$C65="","",(COUNTIF(Filter!BP65:BR65,"a")+1)) | W65: =IF(Filter!$C65="","",(COUNTIF(Filter!BS65:BU65,"a")+1)) | X65: =IF(SUM(E65:N65)=0,"",SUM(E65:N65)/51) | Y65: =IF(SUM(O65:W65)=0,"",SUM(O65:W65)/37) | Z65: =IF(SUM(E65:W65)=0,"",SUM(E65:W65)/88) | AA65: =IF(Z65="","",SUM(Z$60:Z$88)/COUNT(Z$60:Z$88))
A66: =IF(ISBLANK(Test!A66),"",(Test!A66)) | B66: =IF(ISBLANK(Test!B66),"",(Test!B66)) | C66: =IF(ISBLANK(Test!C66),"",(Test!C66)) | D66: =IF(ISBLANK(Test!D66),"",(Test!D66)) | E66: =IF(Filter!$C66="","",(COUNTIF(Filter!E66:H66,"a")+1)) | F66: =IF(Filter!$C66="","",(COUNTIF(Filter!I66:L66,"a")+1)) | G66: =IF(Filter!$C66="","",(COUNTIF(Filter!M66:P66,"a")+1)) | H66: =IF(Filter!$C66="","",(COUNTIF(Filter!Q66:S66,"a")+1)) | I66: =IF(Filter!$C66="","",(COUNTIF(Filter!T66:V66,"a")+1)) | J66: =IF(Filter!$C66="","",(COUNTIF(Filter!W66:Z66,"a")+1)) | K66: =IF(Filter!$C66="","",(COUNTIF(Filter!AA66:AD66,"a")+1)) | L66: =IF(Filter!$C66="","",(COUNTIF(Filter!AE66:AI66,"a")+1)) | M66: =IF(Filter!$C66="","",(COUNTIF(Filter!AJ66:AN66,"a")+1)) | N66: =IF(Filter!$C66="","",(COUNTIF(Filter!AO66:AS66,"a")+1)) | O66: =IF(Filter!$C66="","",(COUNTIF(Filter!AT66:AV66,"a")+1)) | P66: =IF(Filter!$C66="","",(COUNTIF(Filter!AW66:AY66,"a")+1)) | Q66: =IF(Filter!$C66="","",(COUNTIF(Filter!AZ66:BA66,"a")+1)) | R66: =IF(Filter!$C66="","",(COUNTIF(Filter!BB66:BD66,"a")+1)) | S66: =IF(Filter!$C66="","",(COUNTIF(Filter!BE66:BG66,"a")+1)) | T66: =IF(Filter!$C66="","",(COUNTIF(Filter!BH66:BJ66,"a")+1)) | U66: =IF(Filter!$C66="","",(COUNTIF(Filter!BK66:BO66,"a")+1)) | V66: =IF(Filter!$C66="","",(COUNTIF(Filter!BP66:BR66,"a")+1)) | W66: =IF(Filter!$C66="","",(COUNTIF(Filter!BS66:BU66,"a")+1)) | X66: =IF(SUM(E66:N66)=0,"",SUM(E66:N66)/51) | Y66: =IF(SUM(O66:W66)=0,"",SUM(O66:W66)/37) | Z66: =IF(SUM(E66:W66)=0,"",SUM(E66:W66)/88) | AA66: =IF(Z66="","",SUM(Z$60:Z$88)/COUNT(Z$60:Z$88))
A67: =IF(ISBLANK(Test!A67),"",(Test!A67)) | B67: =IF(ISBLANK(Test!B67),"",(Test!B67)) | C67: =IF(ISBLANK(Test!C67),"",(Test!C67)) | D67: =IF(ISBLANK(Test!D67),"",(Test!D67)) | E67: =IF(Filter!$C67="","",(COUNTIF(Filter!E67:H67,"a")+1)) | F67: =IF(Filter!$C67="","",(COUNTIF(Filter!I67:L67,"a")+1)) | G67: =IF(Filter!$C67="","",(COUNTIF(Filter!M67:P67,"a")+1)) | H67: =IF(Filter!$C67="","",(COUNTIF(Filter!Q67:S67,"a")+1)) | I67: =IF(Filter!$C67="","",(COUNTIF(Filter!T67:V67,"a")+1)) | J67: =IF(Filter!$C67="","",(COUNTIF(Filter!W67:Z67,"a")+1)) | K67: =IF(Filter!$C67="","",(COUNTIF(Filter!AA67:AD67,"a")+1)) | L67: =IF(Filter!$C67="","",(COUNTIF(Filter!AE67:AI67,"a")+1)) | M67: =IF(Filter!$C67="","",(COUNTIF(Filter!AJ67:AN67,"a")+1)) | N67: =IF(Filter!$C67="","",(COUNTIF(Filter!AO67:AS67,"a")+1)) | O67: =IF(Filter!$C67="","",(COUNTIF(Filter!AT67:AV67,"a")+1)) | P67: =IF(Filter!$C67="","",(COUNTIF(Filter!AW67:AY67,"a")+1)) | Q67: =IF(Filter!$C67="","",(COUNTIF(Filter!AZ67:BA67,"a")+1)) | R67: =IF(Filter!$C67="","",(COUNTIF(Filter!BB67:BD67,"a")+1)) | S67: =IF(Filter!$C67="","",(COUNTIF(Filter!BE67:BG67,"a")+1)) | T67: =IF(Filter!$C67="","",(COUNTIF(Filter!BH67:BJ67,"a")+1)) | U67: =IF(Filter!$C67="","",(COUNTIF(Filter!BK67:BO67,"a")+1)) | V67: =IF(Filter!$C67="","",(COUNTIF(Filter!BP67:BR67,"a")+1)) | W67: =IF(Filter!$C67="","",(COUNTIF(Filter!BS67:BU67,"a")+1)) | X67: =IF(SUM(E67:N67)=0,"",SUM(E67:N67)/51) | Y67: =IF(SUM(O67:W67)=0,"",SUM(O67:W67)/37) | Z67: =IF(SUM(E67:W67)=0,"",SUM(E67:W67)/88) | AA67: =IF(Z67="","",SUM(Z$60:Z$88)/COUNT(Z$60:Z$88))
A68: =IF(ISBLANK(Test!A68),"",(Test!A68)) | B68: =IF(ISBLANK(Test!B68),"",(Test!B68)) | C68: =IF(ISBLANK(Test!C68),"",(Test!C68)) | D68: =IF(ISBLANK(Test!D68),"",(Test!D68)) | E68: =IF(Filter!$C68="","",(COUNTIF(Filter!E68:H68,"a")+1)) | F68: =IF(Filter!$C68="","",(COUNTIF(Filter!I68:L68,"a")+1)) | G68: =IF(Filter!$C68="","",(COUNTIF(Filter!M68:P68,"a")+1)) | H68: =IF(Filter!$C68="","",(COUNTIF(Filter!Q68:S68,"a")+1)) | I68: =IF(Filter!$C68="","",(COUNTIF(Filter!T68:V68,"a")+1)) | J68: =IF(Filter!$C68="","",(COUNTIF(Filter!W68:Z68,"a")+1)) | K68: =IF(Filter!$C68="","",(COUNTIF(Filter!AA68:AD68,"a")+1)) | L68: =IF(Filter!$C68="","",(COUNTIF(Filter!AE68:AI68,"a")+1)) | M68: =IF(Filter!$C68="","",(COUNTIF(Filter!AJ68:AN68,"a")+1)) | N68: =IF(Filter!$C68="","",(COUNTIF(Filter!AO68:AS68,"a")+1)) | O68: =IF(Filter!$C68="","",(COUNTIF(Filter!AT68:AV68,"a")+1)) | P68: =IF(Filter!$C68="","",(COUNTIF(Filter!AW68:AY68,"a")+1)) | Q68: =IF(Filter!$C68="","",(COUNTIF(Filter!AZ68:BA68,"a")+1)) | R68: =IF(Filter!$C68="","",(COUNTIF(Filter!BB68:BD68,"a")+1)) | S68: =IF(Filter!$C68="","",(COUNTIF(Filter!BE68:BG68,"a")+1)) | T68: =IF(Filter!$C68="","",(COUNTIF(Filter!BH68:BJ68,"a")+1)) | U68: =IF(Filter!$C68="","",(COUNTIF(Filter!BK68:BO68,"a")+1)) | V68: =IF(Filter!$C68="","",(COUNTIF(Filter!BP68:BR68,"a")+1)) | W68: =IF(Filter!$C68="","",(COUNTIF(Filter!BS68:BU68,"a")+1)) | X68: =IF(SUM(E68:N68)=0,"",SUM(E68:N68)/51) | Y68: =IF(SUM(O68:W68)=0,"",SUM(O68:W68)/37) | Z68: =IF(SUM(E68:W68)=0,"",SUM(E68:W68)/88) | AA68: =IF(Z68="","",SUM(Z$60:Z$88)/COUNT(Z$60:Z$88))
A69: =IF(ISBLANK(Test!A69),"",(Test!A69)) | B69: =IF(ISBLANK(Test!B69),"",(Test!B69)) | C69: =IF(ISBLANK(Test!C69),"",(Test!C69)) | D69: =IF(ISBLANK(Test!D69),"",(Test!D69)) | E69: =IF(Filter!$C69="","",(COUNTIF(Filter!E69:H69,"a")+1)) | F69: =IF(Filter!$C69="","",(COUNTIF(Filter!I69:L69,"a")+1)) | G69: =IF(Filter!$C69="","",(COUNTIF(Filter!M69:P69,"a")+1)) | H69: =IF(Filter!$C69="","",(COUNTIF(Filter!Q69:S69,"a")+1)) | I69: =IF(Filter!$C69="","",(COUNTIF(Filter!T69:V69,"a")+1)) | J69: =IF(Filter!$C69="","",(COUNTIF(Filter!W69:Z69,"a")+1)) | K69: =IF(Filter!$C69="","",(COUNTIF(Filter!AA69:AD69,"a")+1)) | L69: =IF(Filter!$C69="","",(COUNTIF(Filter!AE69:AI69,"a")+1)) | M69: =IF(Filter!$C69="","",(COUNTIF(Filter!AJ69:AN69,"a")+1)) | N69: =IF(Filter!$C69="","",(COUNTIF(Filter!AO69:AS69,"a")+1)) | O69: =IF(Filter!$C69="","",(COUNTIF(Filter!AT69:AV69,"a")+1)) | P69: =IF(Filter!$C69="","",(COUNTIF(Filter!AW69:AY69,"a")+1)) | Q69: =IF(Filter!$C69="","",(COUNTIF(Filter!AZ69:BA69,"a")+1)) | R69: =IF(Filter!$C69="","",(COUNTIF(Filter!BB69:BD69,"a")+1)) | S69: =IF(Filter!$C69="","",(COUNTIF(Filter!BE69:BG69,"a")+1)) | T69: =IF(Filter!$C69="","",(COUNTIF(Filter!BH69:BJ69,"a")+1)) | U69: =IF(Filter!$C69="","",(COUNTIF(Filter!BK69:BO69,"a")+1)) | V69: =IF(Filter!$C69="","",(COUNTIF(Filter!BP69:BR69,"a")+1)) | W69: =IF(Filter!$C69="","",(COUNTIF(Filter!BS69:BU69,"a")+1)) | X69: =IF(SUM(E69:N69)=0,"",SUM(E69:N69)/51) | Y69: =IF(SUM(O69:W69)=0,"",SUM(O69:W69)/37) | Z69: =IF(SUM(E69:W69)=0,"",SUM(E69:W69)/88) | AA69: =IF(Z69="","",SUM(Z$60:Z$88)/COUNT(Z$60:Z$88))
A70: =IF(ISBLANK(Test!A70),"",(Test!A70)) | B70: =IF(ISBLANK(Test!B70),"",(Test!B70)) | C70: =IF(ISBLANK(Test!C70),"",(Test!C70)) | D70: =IF(ISBLANK(Test!D70),"",(Test!D70)) | E70: =IF(Filter!$C70="","",(COUNTIF(Filter!E70:H70,"a")+1)) | F70: =IF(Filter!$C70="","",(COUNTIF(Filter!I70:L70,"a")+1)) | G70: =IF(Filter!$C70="","",(COUNTIF(Filter!M70:P70,"a")+1)) | H70: =IF(Filter!$C70="","",(COUNTIF(Filter!Q70:S70,"a")+1)) | I70: =IF(Filter!$C70="","",(COUNTIF(Filter!T70:V70,"a")+1)) | J70: =IF(Filter!$C70="","",(COUNTIF(Filter!W70:Z70,"a")+1)) | K70: =IF(Filter!$C70="","",(COUNTIF(Filter!AA70:AD70,"a")+1)) | L70: =IF(Filter!$C70="","",(COUNTIF(Filter!AE70:AI70,"a")+1)) | M70: =IF(Filter!$C70="","",(COUNTIF(Filter!AJ70:AN70,"a")+1)) | N70: =IF(Filter!$C70="","",(COUNTIF(Filter!AO70:AS70,"a")+1)) | O70: =IF(Filter!$C70="","",(COUNTIF(Filter!AT70:AV70,"a")+1)) | P70: =IF(Filter!$C70="","",(COUNTIF(Filter!AW70:AY70,"a")+1)) | Q70: =IF(Filter!$C70="","",(COUNTIF(Filter!AZ70:BA70,"a")+1)) | R70: =IF(Filter!$C70="","",(COUNTIF(Filter!BB70:BD70,"a")+1)) | S70: =IF(Filter!$C70="","",(COUNTIF(Filter!BE70:BG70,"a")+1)) | T70: =IF(Filter!$C70="","",(COUNTIF(Filter!BH70:BJ70,"a")+1)) | U70: =IF(Filter!$C70="","",(COUNTIF(Filter!BK70:BO70,"a")+1)) | V70: =IF(Filter!$C70="","",(COUNTIF(Filter!BP70:BR70,"a")+1)) | W70: =IF(Filter!$C70="","",(COUNTIF(Filter!BS70:BU70,"a")+1)) | X70: =IF(SUM(E70:N70)=0,"",SUM(E70:N70)/51) | Y70: =IF(SUM(O70:W70)=0,"",SUM(O70:W70)/37) | Z70: =IF(SUM(E70:W70)=0,"",SUM(E70:W70)/88) | AA70: =IF(Z70="","",SUM(Z$60:Z$88)/COUNT(Z$60:Z$88))
