Workbook

Sheet Input
A1: Enter information into the gray areas.
B3: Project Name: | C3: Central Avenue Expansion
B4: LGU Name: | C4: Town of Anytown

Sheet Current Population - Method 1
A1: Table 2.2.1. Current Population Analysis Method 1 - Limited Service Area
A2: =Input!C3 -> Central Avenue Expansion
A3: =Input!C4 -> Town of Anytown
A4: Complete the areas shown in gray. Links are toU.S. Census websites for use with the table.
A5: U.S. Census Place or County: | B5: Anytown, NC
A6: Appendix Reference for U.S. Census Information: | C6: D
A7: Bedrooms/Dwelling Unita | B7: Dwelling Units | C7: Bedrooms
A8: 2 | B8: 15834 | C8: =A8*B8 -> 31668
A9: 3 | B9: 16245 | C9: =A9*B9 -> 48735
A10: 4 | B10: 14578 | C10: =A10*B10 -> 58312
A11: 5 | B11: 4960 | C11: =A11*B11 -> 24800
A12: Total Dwelling Units: | B12: =SUM(B8:B11) -> 51617 | C12: =SUM(C8:C11) -> 163515
A13: Total 2010 Population from U.S. Census: | B13: 135489
A14: Persons per Dwelling Unit: | B14: =B13/B12 -> 2.624891
A15: Dwelling Units in Service Area: | B15: 175
A16: Current Population in Sewershed Service Area: | B16: =$B$14*$B$15 -> 459.35593
A17: Total Bedrooms/Dwelling Unit: | B17: =$C$12/$B$12 -> 3.1678517
A18: aZero- or one-bedroom dwellings should be included within the 2 bedroom category.

Sheet Current Population - Method 2
A1: Table 2.2.1. Current Population Analysis Method 2 - Large Service Area
A2: =Input!C3 -> Central Avenue Expansion
A3: =Input!C4 -> Town of Anytown
A4: Complete the areas shown in gray. Links are to U.S. Census Bureau websites for use with this table.
A5: U.S. Census Place or County: | B5: Anytown, NC
A6: Appendix Reference for U.S. Census Information: | B6: A
A7: Total Census 2010 Population: | B7: 135489
A8: Persons per Square Mile in LGU: | B8: 2434.66
A9: LGU Land Area (miles2): | B9: 55.65
A10: WWTP Service Area (miles2): | B10: 48.64
A11: % of LGU in WWTP Service Area: | B11: =$B10/$B9 -> 0.87403414
A12: % of WWTP Service Area in Sewershed Service Area: | B12: 0.9
A13: Current Population in Sewershed Service Area: | B13: =$B$10*$B$8*$B$12 -> 106579.68

Sheet Current Flow
A1: Table 2.3.1. Current Flow Analysis
A2: =Input!C3 -> Central Avenue Expansion
A3: =Input!C4 -> Town of Anytown
A4: Complete the cells in gray. Some cells have pulldown menus. Please use if present.
A5: Current Flow Determination Methodology: | C5: Method 2 - Large Service Area
A6: Current Flow Appendix Reference: | C6: E
A7: Metered Flow
A8: Current Average Daily Flow via Meter | B8: Current Average Daily Flow at WWTP | C8: Percentage of Flow to WWTP from Sewershed
A9: (gpd) | B9: (gpd)
A10: 9059300 | B10: 11750000 | C10: =IF($C$5="Metered", ($A$10/$B$10), "")
A11: Residential Flow as Percentage of Metered Flow in Sewershed: | C11: 0.8
A12: Commercial Flow as Percentage of Metered Flow in Sewershed: | C12: 0.2
A14: Pump Runtime
A15: Drawdown Rate (gpm): | C15: 4250
A16: Pump Runtime (hrs/day): | C16: 12
A17: Peaking Factor: | C17: 3
A18: Current Peaked Flow (gpd): | C18: =IF($C$5="Pump Runtime", ($C$15*60*$C$16*$C$17), "")
A20: Method 1 - Limited Service Area
B21: Bedroom Number | C21: Total Bedrooms
B22: 2 | C22: =IF($C$5="Method 1 - Limited Service Area", ('Current Population - Method 1'!$A8*'Current Population - Method 1'!$B8), "")
B23: 3 | C23: =IF($C$5="Method 1 - Limited Service Area", ('Current Population - Method 1'!$A9*'Current Population - Method 1'!$B9), "")
B24: 4 | C24: =IF($C$5="Method 1 - Limited Service Area", ('Current Population - Method 1'!$A10*'Current Population - Method 1'!$B10), "")
B25: 5 | C25: =IF($C$5="Method 1 - Limited Service Area", ('Current Population - Method 1'!$A11*'Current Population - Method 1'!$B11), "")
A26: Total Bedrooms in Place/County: | C26: =IF($C$5="Method 1 - Limited Service Area", (SUM(C22:C25)), "")
A27: Total Dwelling Units: | C27: =IF($C$5="Method 1 - Limited Service Area", 'Current Population - Method 1'!B12, "")
A28: Total Bedrooms/Dwelling Unit: | C28: =IF($C$5="Method 1 - Limited Service Area", 'Current Population - Method 1'!B17, "")
A29: Dwelling Units in Service Area: | C29: =IF($C$5="Method 1 - Limited Service Area", 'Current Population - Method 1'!B15, "")
A30: Flow per bedroom (gpd/bedroom): | C30: =IF($C$5="Method 1 - Limited Service Area", 120, "")
A31: Peaking Factor: | C31: 3
A32: Total Estimated Service Area Peaked Flow (gpd): | C32: =IF($C$5="Method 1 - Limited Service Area", (($C$28*$C$29*$C$30)*$C$31), "")
A34: Method 2 - Large Service Area
A35: I/I Estimation Methodology: | C35: WWTP Only
A36: WWTP ADF (gpd): | C36: 3650000
A37: WWTP Min ADF (gpd) (if applicable): | C37: 3350000
A38: Percent of LGU in WWTP Service Area: | C38: =IF($C$5="Method 2 - Large Service Area", ('Current Population - Method 2'!B11), "") -> 0.87403414
A39: Percent of Sewershed Service Area in WWTP Service Areaa: | C39: =IF($C$5="Method 2 - Large Service Area", (IF('Current Population - Method 2'!$B$12<>"", 'Current Population - Method 2'!B12, "")), "") -> 0.9
B40: Water ADF | C40: WW ADF
B41: (gpd) | C41: (gpd)
A42: Residential: | B42: 3250000 | C42: =IF($C$5="Method 2 - Large Service Area",(IF($C$5="Method 2 - Large Service Area", ($B$42-(0.1*$B$42)), "")), "") -> 2925000
A43: Commercial: | B43: 450000 | C43: =IF($C$5="Method 2 - Large Service Area",(IF($C$5="Method 2 - Large Service Area", ($B$43-(0.1*$B$43)), "")), "") -> 405000
...

Sheet Future Population
A1: Table 3.4.1. Future Population Analysis
A2: =Input!C3 -> Central Avenue Expansion
A3: =Input!C4 -> Town of Anytown
A4: Complete the cells in gray. Note that some cells may contain pulldown menu. If so, please use pulldown menus to select data.
A5: Current Population Methodology: | D5: Method 2 - Large Service Area | G5: SDC Data Appendix Reference: | H5: F
A6: Current LGU Population: | D6: =IF($D$5="Method 1 - Limited Service Area", 'Current Population - Method 1'!B13, (IF($D$5="Method 2 - Large Service Area", 'Current Population - Method 2'!B7, ""))) -> 135489 | G6: County Name: | H6: Coon
A7: Current Sewershed Service Area Population: | D7: =IF($D$5="Method 1 - Limited Service Area", 'Current Population - Method 1'!B16, (IF($D$5="Method 2 - Large Service Area", 'Current Population - Method 2'!B13, ""))) -> 106579.68 | G7: County Population (2010): | H7: 900687
A8: Percentage of LGU Population in County: | D8: =$D$6/$H$7 -> 0.15042851 | G8: Percentage of Service Area in LGU: | H8: =IF($D$5="Method 1 - Limited Service Area",($D$7/$D$6),(IF($D$5="Method 2 - Large Service Area", ('Current Population - Method 2'!B11*'Current Population - Method 2'!B12), ""))) -> 0.78663073
C9: State Data Center | F9: Alternate Data Source: | G9: Town/County Comprehensive Plan
B10: Year | C10: County Population | D10: LGU Population | E10: Sewershed Service Area Population | F10: County Population | G10: LGU Population | H10: Sewershed Service Area Population
A11: 1 | B11: 2014 | C11: 900987 | D11: =$D$8*$C11 -> 135534.13 | E11: =$H$8*$D11 -> 106615.31 | F11: 901236 | G11: 135678 | H11: =$H$8*$G11 -> 106728.48
A12: =A11+1 -> 2 | B12: 2015 | C12: 901546 | D12: =$D$8*$C12 -> 135618.22 | E12: =$H$8*$D12 -> 106681.46 | F12: 901568 | G12: 135879 | H12: =$H$8*$G12 -> 106886.6
A13: =A12+1 -> 3 | B13: 2016 | C13: 901687 | D13: =$D$8*$C13 -> 135639.43 | E13: =$H$8*$D13 -> 106698.14 | F13: 901987 | G13: 136222 | H13: =$H$8*$G13 -> 107156.41
A14: =A13+1 -> 4 | B14: 2017 | C14: 902126 | D14: =$D$8*$C14 -> 135705.47 | E14: =$H$8*$D14 -> 106750.09 | F14: 902468 | G14: 136546 | H14: =$H$8*$G14 -> 107411.28
A15: =A14+1 -> 5 | B15: 2018 | C15: 902568 | D15: =$D$8*$C15 -> 135771.96 | E15: =$H$8*$D15 -> 106802.39 | F15: 902768 | G15: 136876 | H15: =$H$8*$G15 -> 107670.87
A16: =A15+1 -> 6 | B16: 2019 | C16: 902879 | D16: =$D$8*$C16 -> 135818.74 | E16: =$H$8*$D16 -> 106839.19 | F16: 903012 | G16: 137111 | H16: =$H$8*$G16 -> 107855.73
A17: =A16+1 -> 7 | B17: 2020 | C17: 903004 | D17: =$D$8*$C17 -> 135837.54 | E17: =$H$8*$D17 -> 106853.99 | F17: 903687 | G17: 137564 | H17: =$H$8*$G17 -> 108212.07
A18: =A17+1 -> 8 | B18: 2021 | C18: 903246 | D18: =$D$8*$C18 -> 135873.95 | E18: =$H$8*$D18 -> 106882.62 | F18: 903998 | G18: 137986 | H18: =$H$8*$G18 -> 108544.03
A19: =A18+1 -> 9 | B19: 2022 | C19: 903548 | D19: =$D$8*$C19 -> 135919.38 | E19: =$H$8*$D19 -> 106918.36 | F19: 904126 | G19: 138123 | H19: =$H$8*$G19 -> 108651.8
A20: =A19+1 -> 10 | B20: 2023 | C20: 903687 | D20: =$D$8*$C20 -> 135940.29 | E20: =$H$8*$D20 -> 106934.81 | F20: 904688 | G20: 138555 | H20: =$H$8*$G20 -> 108991.62
A21: =A20+1 -> 11 | B21: 2024 | C21: 904236 | D21: =$D$8*$C21 -> 136022.87 | E21: =$H$8*$D21 -> 106999.77 | F21: 904999 | G21: 138763 | H21: =$H$8*$G21 -> 109155.24
A22: =A21+1 -> 12 | B22: 2025 | C22: 904456 | D22: =$D$8*$C22 -> 136055.97 | E22: =$H$8*$D22 -> 107025.8 | F22: 905237 | G22: 139002 | H22: =$H$8*$G22 -> 109343.24
A23: =A22+1 -> 13 | B23: 2026 | C23: 904798 | D23: =$D$8*$C23 -> 136107.41 | E23: =$H$8*$D23 -> 107066.27 | F23: 905678 | G23: 139100 | H23: =$H$8*$G23 -> 109420.33
... A30: =A29+1 -> 20 | B30: 2033 | C30: 906564 | D30: =$D$8*$C30 -> 136373.07 | E30: =$H$8*$D30 -> 107275.25 | F30: 908001 | G30: 141001 | H30: =$H$8*$G30 -> 110915.72
A31: If using an alternative source of data, provide a justification for use of this data below and provide supporting information in an appendix of the ER/EID.
A32: Appendix Reference: | C32: G
A33: Alternative population information was used because the Town and Coon County recognized the need for organized planning due to the large amount of industry moving into the area. Using GIS-based TAZ analysis, they put together population projections for the next 30 years, of which this is a part.

Sheet Flow
A2: Metered | D2: WWTP Only | F2: Method 1 - Limited Service Area | J2: Yes | K2: SDC
A3: Pump Runtime | D3: WWTP & Water | F3: Method 2 - Large Service Area | J3: No | K3: Other
A4: Method 1 - Limited Service Area
A5: Method 2 - Large Service Area
E9: 0.1
E10: 70
E11: 15

Sheet Future Flow
A1: Table 3.4.2. Future Peak Flow Analysis
A2: =Input!C3 -> Central Avenue Expansion
A3: =Input!C4 -> Town of Anytown
C4: Current Flow Estimation Method: | D4: Method 2 - Large Service Area | I4: Alternative Flow Projections Used in Alternatives Analysis? | J4: Yes
C5: Current Flow for 2010 (gpd): | D5: =IF($D$4="Metered",'Current Flow'!$A$10,(IF($D$4="Pump Runtime",'Current Flow'!$C$18,(IF($D$4="Method 1 - Limited Service Area",'Current Flow'!$C$32,(IF($D$4="Method 2 - Large Service Area",'Current Flow'!$C$48,""))))))) -> 9746354.7 | E5: Peaking Factor: | F5: 2 | I5: Appendix Reference: | J5: F
C6: SDC Data | H6: Alternative Population Data Source: | I6: ='Future Population'!G9 -> Town/County Comprehensive Plan
B7: Year | C7: Residential Flow | D7: Commercial Flow | E7: Industrial Flow | F7: Total Flow | G7: Residential Flow | H7: Commercial Flow | I7: Industrial Flow | J7: Total Flow
C8: (gpd) | D8: (gpd) | E8: (gpd) | F8: (gpd) | G8: (gpd) | H8: (gpd) | I8: (gpd) | J8: (gpd)
A9: 1 | B9: ='Future Population'!B11 -> 2014 | C9: =IF($D$4="Metered",(((('Current Flow'!$A$10*'Current Flow'!$C$11)/'Current Population - Method 2'!$B$13)*('Future Population'!$E11-'Current Population - Method 2'!$B$13)*$F$5)), (IF($D$4="Pump Runtime", ((('Future Population'!$E11-'Current Population - Method 2'!$B$13)*Flow!$E$10)*$F$5), (IF($D$4="Method 1 - Limited Service Area", 0, (IF($D$4="Method 2 - Large Service Area", ((('Future Population'!$E11-'Current Population - Method 2'!$B$13)*Flow!$E$10)*$F$5), ""))))))) -> 4988.7627 | D9: =IF($D$4="Metered",(((('Current Flow'!$A$10*'Current Flow'!$C$12)/'Current Population - Method 2'!$B$13)*('Future Population'!$E11-'Current Population - Method 2'!$B$13))*$F$5), (IF($D$4="Pump Runtime", ((('Future Population'!$E11-'Current Population - Method 2'!$B$13)*Flow!$E$11)*$F$5), (IF($D$4="Method 1 - Limited Service Area", 0, (IF($D$4="Method 2 - Large Service Area", ((('Future Population'!$E11-'Current Population - Method 2'!$B$13)*Flow!$E$11)*$F$5), ""))))))) -> 1069.0206 | E9: =IF($D$4="Method 1 - Limited Service Area", 0, ((($D$5+$C9+$D9)*Flow!$E$9)*$F$5)) -> 1950482.5 | F9: =$D$5+SUM(C9:E9) -> 11702895 | G9: =IF($J$4="Yes", (IF($D$4="Metered",(((('Current Flow'!$A$10*'Current Flow'!$C$11)/'Current Population - Method 2'!$B$13)*('Future Population'!$H11-'Current Population - Method 2'!$B$13))*$F$5), (IF($D$4="Pump Runtime", ((('Future Population'!$H11-'Current Population - Method 2'!$B$13)*Flow!$E$10)*$F$5), (IF($D$4="Method 1 - Limited Service Area", 0, (IF($D$4="Method 2 - Large Service Area", ((('Future Population'!$H11-'Current Population - Method 2'!$B$13)*Flow!$E$10)*$F$5), "")))))))), "") -> 20833.081 | H9: =IF($J$4="Yes", (IF($D$4="Metered",(((('Current Flow'!$A$10*'Current Flow'!$C$12)/'Current Population - Method 2'!$B$13)*('Future Population'!$H11-'Current Population - Method 2'!$B$13))*$F$5), (IF($D$4="Pump Runtime", ((('Future Population'!$H11-'Current Population - Method 2'!$B$13)*Flow!$E$11)*$F$5), (IF($D$4="Method 1 - Limited Service Area", 0, (IF($D$4="Method 2 - Large Service Area", ((('Future Population'!$H11-'Current Population - Method 2'!$B$13)*Flow!$E$11)*$F$5), "")))))))), "") -> 4464.2316 | I9: =IF($J$4="Yes", (IF($D$4="Method 1 - Limited Service Area", 0, ((($D$5+$G9+$H9)*Flow!$E$9)*$F$5))),"") -> 1954330.4 | J9: =IF($J$4="Yes", ($D$5+SUM(G9:I9)), "") -> 11725982
A10: =A9+1 -> 2 | B10: ='Future Population'!B12 -> 2015 | C10: =IF($D$4="Metered",(((('Current Flow'!$A$10*'Current Flow'!$C$11)/'Current Population - Method 2'!$B$13)*('Future Population'!$E12-'Current Population - Method 2'!$B$13)*$F$5)), (IF($D$4="Pump Runtime", ((('Future Population'!$E12-'Current Population - Method 2'!$B$13)*Flow!$E$10)*$F$5), (IF($D$4="Method 1 - Limited Service Area", 0, (IF($D$4="Method 2 - Large Service Area", ((('Future Population'!$E12-'Current Population - Method 2'!$B$13)*Flow!$E$10)*$F$5), ""))))))) -> 14249.4 | D10: =IF($D$4="Metered",(((('Current Flow'!$A$10*'Current Flow'!$C$12)/'Current Population - Method 2'!$B$13)*('Future Population'!$E12-'Current Population - Method 2'!$B$13))*$F$5), (IF($D$4="Pump Runtime", ((('Future Population'!$E12-'Current Population - Method 2'!$B$13)*Flow!$E$11)*$F$5), (IF($D$4="Method 1 - Limited Service Area", 0, (IF($D$4="Method 2 - Large Service Area", ((('Future Population'!$E12-'Current Population - Method 2'!$B$13)*Flow!$E$11)*$F$5), ""))))))) -> 3053.4429 | E10: =IF($D$4="Method 1 - Limited Service Area", 0, ((($D$5+$C10+$D10)*Flow!$E$9)*$F$5)) -> 1952731.5 | F10: =$D$5+SUM(C10:E10) -> 11716389 | G10: =IF($J$4="Yes", (IF($D$4="Metered",(((('Current Flow'!$A$10*'Current Flow'!$C$11)/'Current Population - Method 2'!$B$13)*('Future Population'!$H12-'Current Population - Method 2'!$B$13))*$F$5), (IF($D$4="Pump Runtime", ((('Future Population'!$H12-'Current Population - Method 2'!$B$13)*Flow!$E$10)*$F$5), (IF($D$4="Method 1 - Limited Service Area", 0, (IF($D$4="Method 2 - Large Service Area", ((('Future Population'!$H12-'Current Population - Method 2'!$B$13)*Flow!$E$10)*$F$5), "")))))))), "") -> 42968.87 | H10: =IF($J$4="Yes", (IF($D$4="Metered",(((('Current Flow'!$A$10*'Current Flow'!$C$12)/'Current Population - Method 2'!$B$13)*('Future Population'!$H12-'Current Population - Method 2'!$B$13))*$F$5), (IF($D$4="Pump Runtime", ((('Future Population'!$H12-'Current Population - Method 2'!$B$13)*Flow!$E$11)*$F$5), (IF($D$4="Method 1 - Limited Service Area", 0, (IF($D$4="Method 2 - Large Service Area", ((('Future Population'!$H12-'Current Population - Method 2'!$B$13)*Flow!$E$11)*$F$5), "")))))))), "") -> 9207.6149 | I10: =IF($J$4="Yes", (IF($D$4="Method 1 - Limited Service Area", 0, ((($D$5+$G10+$H10)*Flow!$E$9)*$F$5))),"") -> 1959706.2 | J10: =IF($J$4="Yes", ($D$5+SUM(G10:I10)), "") -> 11758237
A11: =A10+1 -> 3 | B11: ='Future Population'!B13 -> 2016 | C11: =IF($D$4="Metered",(((('Current Flow'!$A$10*'Current Flow'!$C$11)/'Current Population - Method 2'!$B$13)*('Future Population'!$E13-'Current Population - Method 2'!$B$13)*$F$5)), (IF($D$4="Pump Runtime", ((('Future Population'!$E13-'Current Population - Method 2'!$B$13)*Flow!$E$10)*$F$5), (IF($D$4="Method 1 - Limited Service Area", 0, (IF($D$4="Method 2 - Large Service Area", ((('Future Population'!$E13-'Current Population - Method 2'!$B$13)*Flow!$E$10)*$F$5), ""))))))) -> 16585.268 | D11: =IF($D$4="Metered",(((('Current Flow'!$A$10*'Current Flow'!$C$12)/'Current Population - Method 2'!$B$13)*('Future Population'!$E13-'Current Population - Method 2'!$B$13))*$F$5), (IF($D$4="Pump Runtime", ((('Future Population'!$E13-'Current Population - Method 2'!$B$13)*Flow!$E$11)*$F$5), (IF($D$4="Method 1 - Limited Service Area", 0, (IF($D$4="Method 2 - Large Service Area", ((('Future Population'!$E13-'Current Population - Method 2'!$B$13)*Flow!$E$11)*$F$5), ""))))))) -> 3553.986 | E11: =IF($D$4="Method 1 - Limited Service Area", 0, ((($D$5+$C11+$D11)*Flow!$E$9)*$F$5)) -> 1953298.8 | F11: =$D$5+SUM(C11:E11) -> 11719793 | G11: =IF($J$4="Yes", (IF($D$4="Metered",(((('Current Flow'!$A$10*'Current Flow'!$C$11)/'Current Population - Method 2'!$B$13)*('Future Population'!$H13-'Current Population - Method 2'!$B$13))*$F$5), (IF($D$4="Pump Runtime", ((('Future Population'!$H13-'Current Population - Method 2'!$B$13)*Flow!$E$10)*$F$5), (IF($D$4="Method 1 - Limited Service Area", 0, (IF($D$4="Method 2 - Large Service Area", ((('Future Population'!$H13-'Current Population - Method 2'!$B$13)*Flow!$E$10)*$F$5), "")))))))), "") -> 80742.877 | H11: =IF($J$4="Yes", (IF($D$4="Metered",(((('Current Flow'!$A$10*'Current Flow'!$C$12)/'Current Population - Method 2'!$B$13)*('Future Population'!$H13-'Current Population - Method 2'!$B$13))*$F$5), (IF($D$4="Pump Runtime", ((('Future Population'!$H13-'Current Population - Method 2'!$B$13)*Flow!$E$11)*$F$5), (IF($D$4="Method 1 - Limited Service Area", 0, (IF($D$4="Method 2 - Large Service Area", ((('Future Population'!$H13-'Current Population - Method 2'!$B$13)*Flow!$E$11)*$F$5), "")))))))), "") -> 17302.045 | I11: =IF($J$4="Yes", (IF($D$4="Method 1 - Limited Service Area", 0, ((($D$5+$G11+$H11)*Flow!$E$9)*$F$5))),"") -> 1968879.9 | J11: =IF($J$4="Yes", ($D$5+SUM(G11:I11)), "") -> 11813280
A12: =A11+1 -> 4 | B12: ='Future Population'!B14 -> 2017 | C12: =IF($D$4="Metered",(((('Current Flow'!$A$10*'Current Flow'!$C$11)/'Current Population - Method 2'!$B$13)*('Future Population'!$E14-'Current Population - Method 2'!$B$13)*$F$5)), (IF($D$4="Pump Runtime", ((('Future Population'!$E14-'Current Population - Method 2'!$B$13)*Flow!$E$10)*$F$5), (IF($D$4="Method 1 - Limited Service Area", 0, (IF($D$4="Method 2 - Large Service Area", ((('Future Population'!$E14-'Current Population - Method 2'!$B$13)*Flow!$E$10)*$F$5), ""))))))) -> 23857.933 | D12: =IF($D$4="Metered",(((('Current Flow'!$A$10*'Current Flow'!$C$12)/'Current Population - Method 2'!$B$13)*('Future Population'!$E14-'Current Population - Method 2'!$B$13))*$F$5), (IF($D$4="Pump Runtime", ((('Future Population'!$E14-'Current Population - Method 2'!$B$13)*Flow!$E$11)*$F$5), (IF($D$4="Method 1 - Limited Service Area", 0, (IF($D$4="Method 2 - Large Service Area", ((('Future Population'!$E14-'Current Population - Method 2'!$B$13)*Flow!$E$11)*$F$5), ""))))))) -> 5112.4143 | E12: =IF($D$4="Method 1 - Limited Service Area", 0, ((($D$5+$C12+$D12)*Flow!$E$9)*$F$5)) -> 1955065 | F12: =$D$5+SUM(C12:E12) -> 11730390 | G12: =IF($J$4="Yes", (IF($D$4="Metered",(((('Current Flow'!$A$10*'Current Flow'!$C$11)/'Current Population - Method 2'!$B$13)*('Future Population'!$H14-'Current Population - Method 2'!$B$13))*$F$5), (IF($D$4="Pump Runtime", ((('Future Population'!$H14-'Current Population - Method 2'!$B$13)*Flow!$E$10)*$F$5), (IF($D$4="Method 1 - Limited Service Area", 0, (IF($D$4="Method 2 - Large Service Area", ((('Future Population'!$H14-'Current Population - Method 2'!$B$13)*Flow!$E$10)*$F$5), "")))))))), "") -> 116424.45 | H12: =IF($J$4="Yes", (IF($D$4="Metered",(((('Current Flow'!$A$10*'Current Flow'!$C$12)/'Current Population - Method 2'!$B$13)*('Future Population'!$H14-'Current Population - Method 2'!$B$13))*$F$5), (IF($D$4="Pump Runtime", ((('Future Population'!$H14-'Current Population - Method 2'!$B$13)*Flow!$E$11)*$F$5), (IF($D$4="Method 1 - Limited Service Area", 0, (IF($D$4="Method 2 - Large Service Area", ((('Future Population'!$H14-'Current Population - Method 2'!$B$13)*Flow!$E$11)*$F$5), "")))))))), "") -> 24948.096 | I12: =IF($J$4="Yes", (IF($D$4="Method 1 - Limited Service Area", 0, ((($D$5+$G12+$H12)*Flow!$E$9)*$F$5))),"") -> 1977545.5 | J12: =IF($J$4="Yes", ($D$5+SUM(G12:I12)), "") -> 11865273
A13: =A12+1 -> 5 | B13: ='Future Population'!B15 -> 2018 | C13: =IF($D$4="Metered",(((('Current Flow'!$A$10*'Current Flow'!$C$11)/'Current Population - Method 2'!$B$13)*('Future Population'!$E15-'Current Population - Method 2'!$B$13)*$F$5)), (IF($D$4="Pump Runtime", ((('Future Population'!$E15-'Current Population - Method 2'!$B$13)*Flow!$E$10)*$F$5), (IF($D$4="Method 1 - Limited Service Area", 0, (IF($D$4="Method 2 - Large Service Area", ((('Future Population'!$E15-'Current Population - Method 2'!$B$13)*Flow!$E$10)*$F$5), ""))))))) -> 31180.298 | D13: =IF($D$4="Metered",(((('Current Flow'!$A$10*'Current Flow'!$C$12)/'Current Population - Method 2'!$B$13)*('Future Population'!$E15-'Current Population - Method 2'!$B$13))*$F$5), (IF($D$4="Pump Runtime", ((('Future Population'!$E15-'Current Population - Method 2'!$B$13)*Flow!$E$11)*$F$5), (IF($D$4="Method 1 - Limited Service Area", 0, (IF($D$4="Method 2 - Large Service Area", ((('Future Population'!$E15-'Current Population - Method 2'!$B$13)*Flow!$E$11)*$F$5), ""))))))) -> 6681.4924 | E13: =IF($D$4="Method 1 - Limited Service Area", 0, ((($D$5+$C13+$D13)*Flow!$E$9)*$F$5)) -> 1956843.3 | F13: =$D$5+SUM(C13:E13) -> 11741060 | G13: =IF($J$4="Yes", (IF($D$4="Metered",(((('Current Flow'!$A$10*'Current Flow'!$C$11)/'Current Population - Method 2'!$B$13)*('Future Population'!$H15-'Current Population - Method 2'!$B$13))*$F$5), (IF($D$4="Pump Runtime", ((('Future Population'!$H15-'Current Population - Method 2'!$B$13)*Flow!$E$10)*$F$5), (IF($D$4="Method 1 - Limited Service Area", 0, (IF($D$4="Method 2 - Large Service Area", ((('Future Population'!$H15-'Current Population - Method 2'!$B$13)*Flow!$E$10)*$F$5), "")))))))), "") -> 152766.79 | H13: =IF($J$4="Yes", (IF($D$4="Metered",(((('Current Flow'!$A$10*'Current Flow'!$C$12)/'Current Population - Method 2'!$B$13)*('Future Population'!$H15-'Current Population - Method 2'!$B$13))*$F$5), (IF($D$4="Pump Runtime", ((('Future Population'!$H15-'Current Population - Method 2'!$B$13)*Flow!$E$11)*$F$5), (IF($D$4="Method 1 - Limited Service Area", 0, (IF($D$4="Method 2 - Large Service Area", ((('Future Population'!$H15-'Current Population - Method 2'!$B$13)*Flow!$E$11)*$F$5), "")))))))), "") -> 32735.74 | I13: =IF($J$4="Yes", (IF($D$4="Method 1 - Limited Service Area", 0, ((($D$5+$G13+$H13)*Flow!$E$9)*$F$5))),"") -> 1986371.4 | J13: =IF($J$4="Yes", ($D$5+SUM(G13:I13)), "") -> 11918229
A14: =A13+1 -> 6 | B14: ='Future Population'!B16 -> 2019 | C14: =IF($D$4="Metered",(((('Current Flow'!$A$10*'Current Flow'!$C$11)/'Current Population - Method 2'!$B$13)*('Future Population'!$E16-'Current Population - Method 2'!$B$13)*$F$5)), (IF($D$4="Pump Runtime", ((('Future Population'!$E16-'Current Population - Method 2'!$B$13)*Flow!$E$10)*$F$5), (IF($D$4="Method 1 - Limited Service Area", 0, (IF($D$4="Method 2 - Large Service Area", ((('Future Population'!$E16-'Current Population - Method 2'!$B$13)*Flow!$E$10)*$F$5), ""))))))) -> 36332.46 | D14: =IF($D$4="Metered",(((('Current Flow'!$A$10*'Current Flow'!$C$12)/'Current Population - Method 2'!$B$13)*('Future Population'!$E16-'Current Population - Method 2'!$B$13))*$F$5), (IF($D$4="Pump Runtime", ((('Future Population'!$E16-'Current Population - Method 2'!$B$13)*Flow!$E$11)*$F$5), (IF($D$4="Method 1 - Limited Service Area", 0, (IF($D$4="Method 2 - Large Service Area", ((('Future Population'!$E16-'Current Population - Method 2'!$B$13)*Flow!$E$11)*$F$5), ""))))))) -> 7785.527 | E14: =IF($D$4="Method 1 - Limited Service Area", 0, ((($D$5+$C14+$D14)*Flow!$E$9)*$F$5)) -> 1958094.5 | F14: =$D$5+SUM(C14:E14) -> 11748567 | G14: =IF($J$4="Yes", (IF($D$4="Metered",(((('Current Flow'!$A$10*'Current Flow'!$C$11)/'Current Population - Method 2'!$B$13)*('Future Population'!$H16-'Current Population - Method 2'!$B$13))*$F$5), (IF($D$4="Pump Runtime", ((('Future Population'!$H16-'Current Population - Method 2'!$B$13)*Flow!$E$10)*$F$5), (IF($D$4="Method 1 - Limited Service Area", 0, (IF($D$4="Method 2 - Large Service Area", ((('Future Population'!$H16-'Current Population - Method 2'!$B$13)*Flow!$E$10)*$F$5), "")))))))), "") -> 178646.94 | H14: =IF($J$4="Yes", (IF($D$4="Metered",(((('Current Flow'!$A$10*'Current Flow'!$C$12)/'Current Population - Method 2'!$B$13)*('Future Population'!$H16-'Current Population - Method 2'!$B$13))*$F$5), (IF($D$4="Pump Runtime", ((('Future Population'!$H16-'Current Population - Method 2'!$B$13)*Flow!$E$11)*$F$5), (IF($D$4="Method 1 - Limited Service Area", 0, (IF($D$4="Method 2 - Large Service Area", ((('Future Population'!$H16-'Current Population - Method 2'!$B$13)*Flow!$E$11)*$F$5), "")))))))), "") -> 38281.487 | I14: =IF($J$4="Yes", (IF($D$4="Method 1 - Limited Service Area", 0, ((($D$5+$G14+$H14)*Flow!$E$9)*$F$5))),"") -> 1992656.6 | J14: =IF($J$4="Yes", ($D$5+SUM(G14:I14)), "") -> 11955940
A15: =A14+1 -> 7 | B15: ='Future Population'!B17 -> 2020 | C15: =IF($D$4="Metered",(((('Current Flow'!$A$10*'Current Flow'!$C$11)/'Current Population - Method 2'!$B$13)*('Future Population'!$E17-'Current Population - Method 2'!$B$13)*$F$5)), (IF($D$4="Pump Runtime", ((('Future Population'!$E17-'Current Population - Method 2'!$B$13)*Flow!$E$10)*$F$5), (IF($D$4="Method 1 - Limited Service Area", 0, (IF($D$4="Method 2 - Large Service Area", ((('Future Population'!$E17-'Current Population - Method 2'!$B$13)*Flow!$E$10)*$F$5), ""))))))) -> 38403.264 | D15: =IF($D$4="Metered",(((('Current Flow'!$A$10*'Current Flow'!$C$12)/'Current Population - Method 2'!$B$13)*('Future Population'!$E17-'Current Population - Method 2'!$B$13))*$F$5), (IF($D$4="Pump Runtime", ((('Future Population'!$E17-'Current Population - Method 2'!$B$13)*Flow!$E$11)*$F$5), (IF($D$4="Method 1 - Limited Service Area", 0, (IF($D$4="Method 2 - Large Service Area", ((('Future Population'!$E17-'Current Population - Method 2'!$B$13)*Flow!$E$11)*$F$5), ""))))))) -> 8229.2709 | E15: =IF($D$4="Method 1 - Limited Service Area", 0, ((($D$5+$C15+$D15)*Flow!$E$9)*$F$5)) -> 1958597.5 | F15: =$D$5+SUM(C15:E15) -> 11751585 | G15: =IF($J$4="Yes", (IF($D$4="Metered",(((('Current Flow'!$A$10*'Current Flow'!$C$11)/'Current Population - Method 2'!$B$13)*('Future Population'!$H17-'Current Population - Method 2'!$B$13))*$F$5), (IF($D$4="Pump Runtime", ((('Future Population'!$H17-'Current Population - Method 2'!$B$13)*Flow!$E$10)*$F$5), (IF($D$4="Method 1 - Limited Service Area", 0, (IF($D$4="Method 2 - Large Service Area", ((('Future Population'!$H17-'Current Population - Method 2'!$B$13)*Flow!$E$10)*$F$5), "")))))))), "") -> 228535.06 | H15: =IF($J$4="Yes", (IF($D$4="Metered",(((('Current Flow'!$A$10*'Current Flow'!$C$12)/'Current Population - Method 2'!$B$13)*('Future Population'!$H17-'Current Population - Method 2'!$B$13))*$F$5), (IF($D$4="Pump Runtime", ((('Future Population'!$H17-'Current Population - Method 2'!$B$13)*Flow!$E$11)*$F$5), (IF($D$4="Method 1 - Limited Service Area", 0, (IF($D$4="Method 2 - Large Service Area", ((('Future Population'!$H17-'Current Population - Method 2'!$B$13)*Flow!$E$11)*$F$5), "")))))))), "") -> 48971.798 | I15: =IF($J$4="Yes", (IF($D$4="Method 1 - Limited Service Area", 0, ((($D$5+$G15+$H15)*Flow!$E$9)*$F$5))),"") -> 2004772.3 | J15: =IF($J$4="Yes", ($D$5+SUM(G15:I15)), "") -> 12028634
A16: =A15+1 -> 8 | B16: ='Future Population'!B18 -> 2021 | C16: =IF($D$4="Metered",(((('Current Flow'!$A$10*'Current Flow'!$C$11)/'Current Population - Method 2'!$B$13)*('Future Population'!$E18-'Current Population - Method 2'!$B$13)*$F$5)), (IF($D$4="Pump Runtime", ((('Future Population'!$E18-'Current Population - Method 2'!$B$13)*Flow!$E$10)*$F$5), (IF($D$4="Method 1 - Limited Service Area", 0, (IF($D$4="Method 2 - Large Service Area", ((('Future Population'!$E18-'Current Population - Method 2'!$B$13)*Flow!$E$10)*$F$5), ""))))))) -> 42412.342 | D16: =IF($D$4="Metered",(((('Current Flow'!$A$10*'Current Flow'!$C$12)/'Current Population - Method 2'!$B$13)*('Future Population'!$E18-'Current Population - Method 2'!$B$13))*$F$5), (IF($D$4="Pump Runtime", ((('Future Population'!$E18-'Current Population - Method 2'!$B$13)*Flow!$E$11)*$F$5), (IF($D$4="Method 1 - Limited Service Area", 0, (IF($D$4="Method 2 - Large Service Area", ((('Future Population'!$E18-'Current Population - Method 2'!$B$13)*Flow!$E$11)*$F$5), ""))))))) -> 9088.3589 | E16: =IF($D$4="Method 1 - Limited Service Area", 0, ((($D$5+$C16+$D16)*Flow!$E$9)*$F$5)) -> 1959571.1 | F16: =$D$5+SUM(C16:E16) -> 11757427 | G16: =IF($J$4="Yes", (IF($D$4="Metered",(((('Current Flow'!$A$10*'Current Flow'!$C$11)/'Current Population - Method 2'!$B$13)*('Future Population'!$H18-'Current Population - Method 2'!$B$13))*$F$5), (IF($D$4="Pump Runtime", ((('Future Population'!$H18-'Current Population - Method 2'!$B$13)*Flow!$E$10)*$F$5), (IF($D$4="Method 1 - Limited Service Area", 0, (IF($D$4="Method 2 - Large Service Area", ((('Future Population'!$H18-'Current Population - Method 2'!$B$13)*Flow!$E$10)*$F$5), "")))))))), "") -> 275009.2 | H16: =IF($J$4="Yes", (IF($D$4="Metered",(((('Current Flow'!$A$10*'Current Flow'!$C$12)/'Current Population - Method 2'!$B$13)*('Future Population'!$H18-'Current Population - Method 2'!$B$13))*$F$5), (IF($D$4="Pump Runtime", ((('Future Population'!$H18-'Current Population - Method 2'!$B$13)*Flow!$E$11)*$F$5), (IF($D$4="Method 1 - Limited Service Area", 0, (IF($D$4="Method 2 - Large Service Area", ((('Future Population'!$H18-'Current Population - Method 2'!$B$13)*Flow!$E$11)*$F$5), "")))))))), "") -> 58930.543 | I16: =IF($J$4="Yes", (IF($D$4="Method 1 - Limited Service Area", 0, ((($D$5+$G16+$H16)*Flow!$E$9)*$F$5))),"") -> 2016058.9 | J16: =IF($J$4="Yes", ($D$5+SUM(G16:I16)), "") -> 12096353
A17: =A16+1 -> 9 | B17: ='Future Population'!B19 -> 2022 | C17: =IF($D$4="Metered",(((('Current Flow'!$A$10*'Current Flow'!$C$11)/'Current Population - Method 2'!$B$13)*('Future Population'!$E19-'Current Population - Method 2'!$B$13)*$F$5)), (IF($D$4="Pump Runtime", ((('Future Population'!$E19-'Current Population - Method 2'!$B$13)*Flow!$E$10)*$F$5), (IF($D$4="Method 1 - Limited Service Area", 0, (IF($D$4="Method 2 - Large Service Area", ((('Future Population'!$E19-'Current Population - Method 2'!$B$13)*Flow!$E$10)*$F$5), ""))))))) -> 47415.405 | D17: =IF($D$4="Metered",(((('Current Flow'!$A$10*'Current Flow'!$C$12)/'Current Population - Method 2'!$B$13)*('Future Population'!$E19-'Current Population - Method 2'!$B$13))*$F$5), (IF($D$4="Pump Runtime", ((('Future Population'!$E19-'Current Population - Method 2'!$B$13)*Flow!$E$11)*$F$5), (IF($D$4="Method 1 - Limited Service Area", 0, (IF($D$4="Method 2 - Large Service Area", ((('Future Population'!$E19-'Current Population - Method 2'!$B$13)*Flow!$E$11)*$F$5), ""))))))) -> 10160.444 | E17: =IF($D$4="Method 1 - Limited Service Area", 0, ((($D$5+$C17+$D17)*Flow!$E$9)*$F$5)) -> 1960786.1 | F17: =$D$5+SUM(C17:E17) -> 11764717 | G17: =IF($J$4="Yes", (IF($D$4="Metered",(((('Current Flow'!$A$10*'Current Flow'!$C$11)/'Current Population - Method 2'!$B$13)*('Future Population'!$H19-'Current Population - Method 2'!$B$13))*$F$5), (IF($D$4="Pump Runtime", ((('Future Population'!$H19-'Current Population - Method 2'!$B$13)*Flow!$E$10)*$F$5), (IF($D$4="Method 1 - Limited Service Area", 0, (IF($D$4="Method 2 - Large Service Area", ((('Future Population'!$H19-'Current Population - Method 2'!$B$13)*Flow!$E$10)*$F$5), "")))))))), "") -> 290096.78 | H17: =IF($J$4="Yes", (IF($D$4="Metered",(((('Current Flow'!$A$10*'Current Flow'!$C$12)/'Current Population - Method 2'!$B$13)*('Future Population'!$H19-'Current Population - Method 2'!$B$13))*$F$5), (IF($D$4="Pump Runtime", ((('Future Population'!$H19-'Current Population - Method 2'!$B$13)*Flow!$E$11)*$F$5), (IF($D$4="Method 1 - Limited Service Area", 0, (IF($D$4="Method 2 - Large Service Area", ((('Future Population'!$H19-'Current Population - Method 2'!$B$13)*Flow!$E$11)*$F$5), "")))))))), "") -> 62163.596 | I17: =IF($J$4="Yes", (IF($D$4="Method 1 - Limited Service Area", 0, ((($D$5+$G17+$H17)*Flow!$E$9)*$F$5))),"") -> 2019723 | J17: =IF($J$4="Yes", ($D$5+SUM(G17:I17)), "") -> 12118338
A18: =A17+1 -> 10 | B18: ='Future Population'!B20 -> 2023 | C18: =IF($D$4="Metered",(((('Current Flow'!$A$10*'Current Flow'!$C$11)/'Current Population - Method 2'!$B$13)*('Future Population'!$E20-'Current Population - Method 2'!$B$13)*$F$5)), (IF($D$4="Pump Runtime", ((('Future Population'!$E20-'Current Population - Method 2'!$B$13)*Flow!$E$10)*$F$5), (IF($D$4="Method 1 - Limited Service Area", 0, (IF($D$4="Method 2 - Large Service Area", ((('Future Population'!$E20-'Current Population - Method 2'!$B$13)*Flow!$E$10)*$F$5), ""))))))) -> 49718.14 | D18: =IF($D$4="Metered",(((('Current Flow'!$A$10*'Current Flow'!$C$12)/'Current Population - Method 2'!$B$13)*('Future Population'!$E20-'Current Population - Method 2'!$B$13))*$F$5), (IF($D$4="Pump Runtime", ((('Future Population'!$E20-'Current Population - Method 2'!$B$13)*Flow!$E$11)*$F$5), (IF($D$4="Method 1 - Limited Service Area", 0, (IF($D$4="Method 2 - Large Service Area", ((('Future Population'!$E20-'Current Population - Method 2'!$B$13)*Flow!$E$11)*$F$5), ""))))))) -> 10653.887 | E18: =IF($D$4="Method 1 - Limited Service Area", 0, ((($D$5+$C18+$D18)*Flow!$E$9)*$F$5)) -> 1961345.3 | F18: =$D$5+SUM(C18:E18) -> 11768072 | G18: =IF($J$4="Yes", (IF($D$4="Metered",(((('Current Flow'!$A$10*'Current Flow'!$C$11)/'Current Population - Method 2'!$B$13)*('Future Population'!$H20-'Current Population - Method 2'!$B$13))*$F$5), (IF($D$4="Pump Runtime", ((('Future Population'!$H20-'Current Population - Method 2'!$B$13)*Flow!$E$10)*$F$5), (IF($D$4="Method 1 - Limited Service Area", 0, (IF($D$4="Method 2 - Large Service Area", ((('Future Population'!$H20-'Current Population - Method 2'!$B$13)*Flow!$E$10)*$F$5), "")))))))), "") -> 337672.21 | H18: =IF($J$4="Yes", (IF($D$4="Metered",(((('Current Flow'!$A$10*'Current Flow'!$C$12)/'Current Population - Method 2'!$B$13)*('Future Population'!$H20-'Current Population - Method 2'!$B$13))*$F$5), (IF($D$4="Pump Runtime", ((('Future Population'!$H20-'Current Population - Method 2'!$B$13)*Flow!$E$11)*$F$5), (IF($D$4="Method 1 - Limited Service Area", 0, (IF($D$4="Method 2 - Large Service Area", ((('Future Population'!$H20-'Current Population - Method 2'!$B$13)*Flow!$E$11)*$F$5), "")))))))), "") -> 72358.33 | I18: =IF($J$4="Yes", (IF($D$4="Method 1 - Limited Service Area", 0, ((($D$5+$G18+$H18)*Flow!$E$9)*$F$5))),"") -> 2031277.1 | J18: =IF($J$4="Yes", ($D$5+SUM(G18:I18)), "") -> 12187662
A19: =A18+1 -> 11 | B19: ='Future Population'!B21 -> 2024 | C19: =IF($D$4="Metered",(((('Current Flow'!$A$10*'Current Flow'!$C$11)/'Current Population - Method 2'!$B$13)*('Future Population'!$E21-'Current Population - Method 2'!$B$13)*$F$5)), (IF($D$4="Pump Runtime", ((('Future Population'!$E21-'Current Population - Method 2'!$B$13)*Flow!$E$10)*$F$5), (IF($D$4="Method 1 - Limited Service Area", 0, (IF($D$4="Method 2 - Large Service Area", ((('Future Population'!$E21-'Current Population - Method 2'!$B$13)*Flow!$E$10)*$F$5), ""))))))) -> 58813.113 | D19: =IF($D$4="Metered",(((('Current Flow'!$A$10*'Current Flow'!$C$12)/'Current Population - Method 2'!$B$13)*('Future Population'!$E21-'Current Population - Method 2'!$B$13))*$F$5), (IF($D$4="Pump Runtime", ((('Future Population'!$E21-'Current Population - Method 2'!$B$13)*Flow!$E$11)*$F$5), (IF($D$4="Method 1 - Limited Service Area", 0, (IF($D$4="Method 2 - Large Service Area", ((('Future Population'!$E21-'Current Population - Method 2'!$B$13)*Flow!$E$11)*$F$5), ""))))))) -> 12602.81 | E19: =IF($D$4="Method 1 - Limited Service Area", 0, ((($D$5+$C19+$D19)*Flow!$E$9)*$F$5)) -> 1963554.1 | F19: =$D$5+SUM(C19:E19) -> 11781325 | G19: =IF($J$4="Yes", (IF($D$4="Metered",(((('Current Flow'!$A$10*'Current Flow'!$C$11)/'Current Population - Method 2'!$B$13)*('Future Population'!$H21-'Current Population - Method 2'!$B$13))*$F$5), (IF($D$4="Pump Runtime", ((('Future Population'!$H21-'Current Population - Method 2'!$B$13)*Flow!$E$10)*$F$5), (IF($D$4="Method 1 - Limited Service Area", 0, (IF($D$4="Method 2 - Large Service Area", ((('Future Population'!$H21-'Current Population - Method 2'!$B$13)*Flow!$E$10)*$F$5), "")))))))), "") -> 360578.89 | H19: =IF($J$4="Yes", (IF($D$4="Metered",(((('Current Flow'!$A$10*'Current Flow'!$C$12)/'Current Population - Method 2'!$B$13)*('Future Population'!$H21-'Current Population - Method 2'!$B$13))*$F$5), (IF($D$4="Pump Runtime", ((('Future Population'!$H21-'Current Population - Method 2'!$B$13)*Flow!$E$11)*$F$5), (IF($D$4="Method 1 - Limited Service Area", 0, (IF($D$4="Method 2 - Large Service Area", ((('Future Population'!$H21-'Current Population - Method 2'!$B$13)*Flow!$E$11)*$F$5), "")))))))), "") -> 77266.905 | I19: =IF($J$4="Yes", (IF($D$4="Method 1 - Limited Service Area", 0, ((($D$5+$G19+$H19)*Flow!$E$9)*$F$5))),"") -> 2036840.1 | J19: =IF($J$4="Yes", ($D$5+SUM(G19:I19)), "") -> 12221041
A20: =A19+1 -> 12 | B20: ='Future Population'!B22 -> 2025 | C20: =IF($D$4="Metered",(((('Current Flow'!$A$10*'Current Flow'!$C$11)/'Current Population - Method 2'!$B$13)*('Future Population'!$E22-'Current Population - Method 2'!$B$13)*$F$5)), (IF($D$4="Pump Runtime", ((('Future Population'!$E22-'Current Population - Method 2'!$B$13)*Flow!$E$10)*$F$5), (IF($D$4="Method 1 - Limited Service Area", 0, (IF($D$4="Method 2 - Large Service Area", ((('Future Population'!$E22-'Current Population - Method 2'!$B$13)*Flow!$E$10)*$F$5), ""))))))) -> 62457.729 | D20: =IF($D$4="Metered",(((('Current Flow'!$A$10*'Current Flow'!$C$12)/'Current Population - Method 2'!$B$13)*('Future Population'!$E22-'Current Population - Method 2'!$B$13))*$F$5), (IF($D$4="Pump Runtime", ((('Future Population'!$E22-'Current Population - Method 2'!$B$13)*Flow!$E$11)*$F$5), (IF($D$4="Method 1 - Limited Service Area", 0, (IF($D$4="Method 2 - Large Service Area", ((('Future Population'!$E22-'Current Population - Method 2'!$B$13)*Flow!$E$11)*$F$5), ""))))))) -> 13383.799 | E20: =IF($D$4="Method 1 - Limited Service Area", 0, ((($D$5+$C20+$D20)*Flow!$E$9)*$F$5)) -> 1964439.2 | F20: =$D$5+SUM(C20:E20) -> 11786635 | G20: =IF($J$4="Yes", (IF($D$4="Metered",(((('Current Flow'!$A$10*'Current Flow'!$C$11)/'Current Population - Method 2'!$B$13)*('Future Population'!$H22-'Current Population - Method 2'!$B$13))*$F$5), (IF($D$4="Pump Runtime", ((('Future Population'!$H22-'Current Population - Method 2'!$B$13)*Flow!$E$10)*$F$5), (IF($D$4="Method 1 - Limited Service Area", 0, (IF($D$4="Method 2 - Large Service Area", ((('Future Population'!$H22-'Current Population - Method 2'!$B$13)*Flow!$E$10)*$F$5), "")))))))), "") -> 386899.56 | H20: =IF($J$4="Yes", (IF($D$4="Metered",(((('Current Flow'!$A$10*'Current Flow'!$C$12)/'Current Population - Method 2'!$B$13)*('Future Population'!$H22-'Current Population - Method 2'!$B$13))*$F$5), (IF($D$4="Pump Runtime", ((('Future Population'!$H22-'Current Population - Method 2'!$B$13)*Flow!$E$11)*$F$5), (IF($D$4="Method 1 - Limited Service Area", 0, (IF($D$4="Method 2 - Large Service Area", ((('Future Population'!$H22-'Current Population - Method 2'!$B$13)*Flow!$E$11)*$F$5), "")))))))), "") -> 82907.048 | I20: =IF($J$4="Yes", (IF($D$4="Method 1 - Limited Service Area", 0, ((($D$5+$G20+$H20)*Flow!$E$9)*$F$5))),"") -> 2043232.3 | J20: =IF($J$4="Yes", ($D$5+SUM(G20:I20)), "") -> 12259394
A21: =A20+1 -> 13 | B21: ='Future Population'!B23 -> 2026 | C21: =IF($D$4="Metered",(((('Current Flow'!$A$10*'Current Flow'!$C$11)/'Current Population - Method 2'!$B$13)*('Future Population'!$E23-'Current Population - Method 2'!$B$13)*$F$5)), (IF($D$4="Pump Runtime", ((('Future Population'!$E23-'Current Population - Method 2'!$B$13)*Flow!$E$10)*$F$5), (IF($D$4="Method 1 - Limited Service Area", 0, (IF($D$4="Method 2 - Large Service Area", ((('Future Population'!$E23-'Current Population - Method 2'!$B$13)*Flow!$E$10)*$F$5), ""))))))) -> 68123.45 | D21: =IF($D$4="Metered",(((('Current Flow'!$A$10*'Current Flow'!$C$12)/'Current Population - Method 2'!$B$13)*('Future Population'!$E23-'Current Population - Method 2'!$B$13))*$F$5), (IF($D$4="Pump Runtime", ((('Future Population'!$E23-'Current Population - Method 2'!$B$13)*Flow!$E$11)*$F$5), (IF($D$4="Method 1 - Limited Service Area", 0, (IF($D$4="Method 2 - Large Service Area", ((('Future Population'!$E23-'Current Population - Method 2'!$B$13)*Flow!$E$11)*$F$5), ""))))))) -> 14597.882 | E21: =IF($D$4="Method 1 - Limited Service Area", 0, ((($D$5+$C21+$D21)*Flow!$E$9)*$F$5)) -> 1965815.2 | F21: =$D$5+SUM(C21:E21) -> 11794891 | G21: =IF($J$4="Yes", (IF($D$4="Metered",(((('Current Flow'!$A$10*'Current Flow'!$C$11)/'Current Population - Method 2'!$B$13)*('Future Population'!$H23-'Current Population - Method 2'!$B$13))*$F$5), (IF($D$4="Pump Runtime", ((('Future Population'!$H23-'Current Population - Method 2'!$B$13)*Flow!$E$10)*$F$5), (IF($D$4="Method 1 - Limited Service Area", 0, (IF($D$4="Method 2 - Large Service Area", ((('Future Population'!$H23-'Current Population - Method 2'!$B$13)*Flow!$E$10)*$F$5), "")))))))), "") -> 397692.13 | H21: =IF($J$4="Yes", (IF($D$4="Metered",(((('Current Flow'!$A$10*'Current Flow'!$C$12)/'Current Population - Method 2'!$B$13)*('Future Population'!$H23-'Current Population - Method 2'!$B$13))*$F$5), (IF($D$4="Pump Runtime", ((('Future Population'!$H23-'Current Population - Method 2'!$B$13)*Flow!$E$11)*$F$5), (IF($D$4="Method 1 - Limited Service Area", 0, (IF($D$4="Method 2 - Large Service Area", ((('Future Population'!$H23-'Current Population - Method 2'!$B$13)*Flow!$E$11)*$F$5), "")))))))), "") -> 85219.742 | I21: =IF($J$4="Yes", (IF($D$4="Method 1 - Limited Service Area", 0, ((($D$5+$G21+$H21)*Flow!$E$9)*$F$5))),"") -> 2045853.3 | J21: =IF($J$4="Yes", ($D$5+SUM(G21:I21)), "") -> 12275120
... A28: =A27+1 -> 20 | B28: ='Future Population'!B30 -> 2033 | C28: =IF($D$4="Metered",(((('Current Flow'!$A$10*'Current Flow'!$C$11)/'Current Population - Method 2'!$B$13)*('Future Population'!$E30-'Current Population - Method 2'!$B$13)*$F$5)), (IF($D$4="Pump Runtime", ((('Future Population'!$E30-'Current Population - Method 2'!$B$13)*Flow!$E$10)*$F$5), (IF($D$4="Method 1 - Limited Service Area", 0, (IF($D$4="Method 2 - Large Service Area", ((('Future Population'!$E30-'Current Population - Method 2'!$B$13)*Flow!$E$10)*$F$5), ""))))))) -> 97379.776 | D28: =IF($D$4="Metered",(((('Current Flow'!$A$10*'Current Flow'!$C$12)/'Current Population - Method 2'!$B$13)*('Future Population'!$E30-'Current Population - Method 2'!$B$13))*$F$5), (IF($D$4="Pump Runtime", ((('Future Population'!$E30-'Current Population - Method 2'!$B$13)*Flow!$E$11)*$F$5), (IF($D$4="Method 1 - Limited Service Area", 0, (IF($D$4="Method 2 - Large Service Area", ((('Future Population'!$E30-'Current Population - Method 2'!$B$13)*Flow!$E$11)*$F$5), ""))))))) -> 20867.095 | E28: =IF($D$4="Method 1 - Limited Service Area", 0, ((($D$5+$C28+$D28)*Flow!$E$9)*$F$5)) -> 1972920.3 | F28: =$D$5+SUM(C28:E28) -> 11837522 | G28: =IF($J$4="Yes", (IF($D$4="Metered",(((('Current Flow'!$A$10*'Current Flow'!$C$11)/'Current Population - Method 2'!$B$13)*('Future Population'!$H30-'Current Population - Method 2'!$B$13))*$F$5), (IF($D$4="Pump Runtime", ((('Future Population'!$H30-'Current Population - Method 2'!$B$13)*Flow!$E$10)*$F$5), (IF($D$4="Method 1 - Limited Service Area", 0, (IF($D$4="Method 2 - Large Service Area", ((('Future Population'!$H30-'Current Population - Method 2'!$B$13)*Flow!$E$10)*$F$5), "")))))))), "") -> 607046.03 | H28: =IF($J$4="Yes", (IF($D$4="Metered",(((('Current Flow'!$A$10*'Current Flow'!$C$12)/'Current Population - Method 2'!$B$13)*('Future Population'!$H30-'Current Population - Method 2'!$B$13))*$F$5), (IF($D$4="Pump Runtime", ((('Future Population'!$H30-'Current Population - Method 2'!$B$13)*Flow!$E$11)*$F$5), (IF($D$4="Method 1 - Limited Service Area", 0, (IF($D$4="Method 2 - Large Service Area", ((('Future Population'!$H30-'Current Population - Method 2'!$B$13)*Flow!$E$11)*$F$5), "")))))))), "") -> 130081.29 | I28: =IF($J$4="Yes", (IF($D$4="Method 1 - Limited Service Area", 0, ((($D$5+$G28+$H28)*Flow!$E$9)*$F$5))),"") -> 2096696.4 | J28: =IF($J$4="Yes", ($D$5+SUM(G28:I28)), "") -> 12580178
A29: Provide a justification for the peaking factor used for future peak flows.
A30: The peaking factor of 2.0 was used because of the new interceptor being put into place as part of this project as well as the aggressive I/I reduction campaign that the Town plans to implement to reduce I/I issues within the Central Avenue sewershed. By 20 years out, the Town hopes to have an I/I reduction of 50 percent, thereby reducing the peaking factor by half.
A31: If the alternative flow projection was the one accepted for use in the alternatives analysis, then provide a justification as to why the alternative flow projections are preferred over the flows developed based on SDC population projections.
A32: The alternative flow methodology was used because of the alternative population methodology utilized. Since industry is coming to the county, many people will be living in both the County and the Town, and the flows are based upon the higher populations than predicted by the SDC.

Sheet Interceptor Flow
A1: Table 3.4.3. Interceptor Capacity Analysis
A2: =Input!C3 -> Central Avenue Expansion
A3: =Input!C4 -> Town of Anytown
A4: Enter information into the gray cells. Where appropriate, use pulldown menus to select information.
A5: Does the project contain an interceptor with multiple pipe diameters? | D5: Yes | E5: Flow Projection Preferred for Project: | G5: Other
C6: Information Related to Project
C7: Sub-Sewershed A | D7: Sub-Sewershed B | E7: Sub-Sewershed C | F7: Sub-Sewershed D | G7: Sub-Sewershed E
A8: Name: | C8: Area A | D8: Area B | E8: Area C | F8: Area D | G8: Area A
A9: Pipe Diameter (inches): | C9: 10 | D9: 12 | E9: 16 | F9: 24 | G9: 36
A10: Pipe Capacity (gpd): | C10: 1250000 | D10: 4000000 | E10: 6500000 | F10: 10500000 | G10: 12500000
A11: Percent of Project in Sub-Sewershed | C11: 0.1 | D11: 0.2 | E11: 0.2 | F11: 0.3 | G11: 0.2
C12: Total Peak Projected Flow from Sub-Sewersheds (gpd)
B13: Year | C13: Sub-Sewershed A | D13: Sub-Sewershed B | E13: Sub-Sewershed C | F13: Sub-Sewershed D | G13: Sub-Sewershed E
A14: Current: | B14: 2010 | C14: =IF($D$5="Yes", ('Future Flow'!$D$5*C$11), "") -> 974635.47 | D14: =IF($D$9<>"", (IF($D$5="Yes", (('Future Flow'!$D$5*D$11)+C14), "")), "") -> 2923906.4 | E14: =IF($E$9<>"", (IF($D$5="Yes", (('Future Flow'!$D$5*E$11)+D14), "")), "") -> 4873177.4 | F14: =IF($F$9<>"", (IF($D$5="Yes", (('Future Flow'!$D$5*F$11)+E14), "")), "") -> 7797083.8 | G14: =IF($G$9<>"", (IF($D$5="Yes", (('Future Flow'!$D$5*G$11)+F14), "")), "") -> 9746354.7
A15: Year 1: | B15: =IF($D$5="Yes", 'Future Flow'!B9, "") -> 2014 | C15: =IF($D$5="Yes", (IF($G$5="SDC", ('Future Flow'!$F$11*C$11), (IF($G$5="Other", ('Future Flow'!$J$11*C$11), "")))), "") -> 1181328 | D15: =IF($D$9<>"", (IF($D$5="Yes", (IF($G$5="SDC", (('Future Flow'!$F$11*D$11)+C15), (IF($G$5="Other", (('Future Flow'!$J$11*D$11)+C15), "")))), "")), "") -> 3543983.9 | E15: =IF($E$9<>"", (IF($D$5="Yes", (IF($G$5="SDC", (('Future Flow'!$F$11*E$11)+D15), (IF($G$5="Other", (('Future Flow'!$J$11*E$11)+D15), "")))), "")), "") -> 5906639.8 | F15: =IF($F$9<>"", (IF($D$5="Yes", (IF($G$5="SDC", (('Future Flow'!$F$11*F$11)+E15), (IF($G$5="Other", (('Future Flow'!$J$11*F$11)+E15), "")))), "")), "") -> 9450623.7 | G15: =IF($G$9<>"", (IF($D$5="Yes", (IF($G$5="SDC", (('Future Flow'!$F$11*G$11)+F15), (IF($G$5="Other", (('Future Flow'!$J$11*G$11)+F15), "")))), "")), "") -> 11813280
A16: Year 5: | B16: =IF($D$5="Yes", 'Future Flow'!B13, "") -> 2018 | C16: =IF($D$5="Yes", (IF($G$5="SDC", ('Future Flow'!$F$13*C$11), (IF($G$5="Other", ('Future Flow'!$J$13*C$11), "")))), "") -> 1191822.9 | D16: =IF($D$9<>"", (IF($D$5="Yes", (IF($G$5="SDC", (('Future Flow'!$F$13*D$11)+C16), (IF($G$5="Other", (('Future Flow'!$J$13*D$11)+C16), "")))), "")), "") -> 3575468.6 | E16: =IF($E$9<>"", (IF($D$5="Yes", (IF($G$5="SDC", (('Future Flow'!$F$13*E$11)+D16), (IF($G$5="Other", (('Future Flow'!$J$13*E$11)+D16), "")))), "")), "") -> 5959114.3 | F16: =IF($F$9<>"", (IF($D$5="Yes", (IF($G$5="SDC", (('Future Flow'!$F$13*F$11)+E16), (IF($G$5="Other", (('Future Flow'!$J$13*F$11)+E16), "")))), "")), "") -> 9534583 | G16: =IF($G$9<>"", (IF($D$5="Yes", (IF($G$5="SDC", (('Future Flow'!$F$13*G$11)+F16), (IF($G$5="Other", (('Future Flow'!$J$13*G$11)+F16), "")))), "")), "") -> 11918229
A17: Year 10: | B17: =IF($D$5="Yes", 'Future Flow'!B18, "") -> 2023 | C17: =IF($D$5="Yes", (IF($G$5="SDC", ('Future Flow'!F18*C$11), (IF($G$5="Other", ('Future Flow'!$J$18*C$11), "")))), "") -> 1218766.2 | D17: =IF($D$9<>"", (IF($D$5="Yes", (IF($G$5="SDC", (('Future Flow'!G18*D$11)+C17), (IF($G$5="Other", (('Future Flow'!$J$18*D$11)+C17), "")))), "")), "") -> 3656298.7 | E17: =IF($E$9<>"", (IF($D$5="Yes", (IF($G$5="SDC", (('Future Flow'!H18*E$11)+D17), (IF($G$5="Other", (('Future Flow'!$J$18*E$11)+D17), "")))), "")), "") -> 6093831.2 | F17: =IF($F$9<>"", (IF($D$5="Yes", (IF($G$5="SDC", (('Future Flow'!I18*F$11)+E17), (IF($G$5="Other", (('Future Flow'!$J$18*F$11)+E17), "")))), "")), "") -> 9750129.8 | G17: =IF($G$9<>"", (IF($D$5="Yes", (IF($G$5="SDC", (('Future Flow'!J18*G$11)+F17), (IF($G$5="Other", (('Future Flow'!$J$18*G$11)+F17), "")))), "")), "") -> 12187662
A18: Year 15: | B18: =IF($D$5="Yes", 'Future Flow'!B23, "") -> 2028 | C18: =IF($D$5="Yes", (IF($G$5="SDC", ('Future Flow'!$F$23*C$11), (IF($G$5="Other", ('Future Flow'!$J$23*C$11), "")))), "") -> 1238568.6 | D18: =IF($D$9<>"", (IF($D$5="Yes", (IF($G$5="SDC", (('Future Flow'!$F$23*D$11)+C18), (IF($G$5="Other", (('Future Flow'!$J$23*D$11)+C18), "")))), "")), "") -> 3715705.7 | E18: =IF($E$9<>"", (IF($D$5="Yes", (IF($G$5="SDC", (('Future Flow'!$F$23*E$11)+D18), (IF($G$5="Other", (('Future Flow'!$J$23*E$11)+D18), "")))), "")), "") -> 6192842.8 | F18: =IF($F$9<>"", (IF($D$5="Yes", (IF($G$5="SDC", (('Future Flow'!$F$23*F$11)+E18), (IF($G$5="Other", (('Future Flow'!$J$23*F$11)+E18), "")))), "")), "") -> 9908548.5 | G18: =IF($G$9<>"", (IF($D$5="Yes", (IF($G$5="SDC", (('Future Flow'!$F$23*G$11)+F18), (IF($G$5="Other", (('Future Flow'!$J$23*G$11)+F18), "")))), "")), "") -> 12385686
A19: Year 20: | B19: =IF($D$5="Yes", 'Future Flow'!B28, "") -> 2033 | C19: =IF($D$5="Yes", (IF($G$5="SDC", ('Future Flow'!$F$28*C$11), (IF($G$5="Other", ('Future Flow'!$J$28*C$11), "")))), "") -> 1258017.8 | D19: =IF($D$9<>"", (IF($D$5="Yes", (IF($G$5="SDC", (('Future Flow'!$F$28*D$11)+C19), (IF($G$5="Other", (('Future Flow'!$J$28*D$11)+C19), "")))), "")), "") -> 3774053.5 | E19: =IF($E$9<>"", (IF($D$5="Yes", (IF($G$5="SDC", (('Future Flow'!$F$28*E$11)+D19), (IF($G$5="Other", (('Future Flow'!$J$28*E$11)+D19), "")))), "")), "") -> 6290089.2 | F19: =IF($F$9<>"", (IF($D$5="Yes", (IF($G$5="SDC", (('Future Flow'!$F$28*F$11)+E19), (IF($G$5="Other", (('Future Flow'!$J$28*F$11)+E19), "")))), "")), "") -> 10064143 | G19: =IF($G$9<>"", (IF($D$5="Yes", (IF($G$5="SDC", (('Future Flow'!$F$28*G$11)+F19), (IF($G$5="Other", (('Future Flow'!$J$28*G$11)+F19), "")))), "")), "") -> 12580178
C20: Is pipe capacity sufficient to accommodate project 20-year flows in each sewershed?
B21: Year | C21: Sub-Sewershed A | D21: Sub-Sewershed B | E21: Sub-Sewershed C | F21: Sub-Sewershed D | G21: Sub-Sewershed E
A22: Current: | B22: =IF($D$5="Yes", B14,"") -> 2010 | C22: =IF($D$5="Yes", (IF(C$10>C14, "Yes", "No")), "") -> Yes | D22: =IF($D$9<>"", (IF($D$5="Yes", (IF(D$10>D14, "Yes", "No")), "")), "") -> Yes | E22: =IF($E$9<>"", (IF($D$5="Yes", (IF(E$10>E14, "Yes", "No")), "")), "") -> Yes | F22: =IF($F$9<>"", (IF($D$5="Yes", (IF(F$10>F14, "Yes", "No")), "")), "") -> Yes | G22: =IF($G$9<>"", (IF($D$5="Yes", (IF(G$10>G14, "Yes", "No")), "")), "") -> Yes
A23: Year 1: | B23: =B15 -> 2014 | C23: =IF($D$5="Yes", (IF(C$10>C15, "Yes", "No")), "") -> Yes | D23: =IF($D$9<>"", (IF($D$5="Yes", (IF(D$10>D15, "Yes", "No")), "")), "") -> Yes | E23: =IF($E$9<>"", (IF($D$5="Yes", (IF(E$10>E15, "Yes", "No")), "")), "") -> Yes | F23: =IF($F$9<>"", (IF($D$5="Yes", (IF(F$10>F15, "Yes", "No")), "")), "") -> Yes | G23: =IF($G$9<>"", (IF($D$5="Yes", (IF(G$10>G15, "Yes", "No")), "")), "") -> Yes
A24: Year 5: | B24: =B16 -> 2018 | C24: =IF($D$5="Yes", (IF(C$10>C16, "Yes", "No")), "") -> Yes | D24: =IF($D$9<>"", (IF($D$5="Yes", (IF(D$10>D16, "Yes", "No")), "")), "") -> Yes | E24: =IF($E$9<>"", (IF($D$5="Yes", (IF(E$10>E16, "Yes", "No")), "")), "") -> Yes | F24: =IF($F$9<>"", (IF($D$5="Yes", (IF(F$10>F16, "Yes", "No")), "")), "") -> Yes | G24: =IF($G$9<>"", (IF($D$5="Yes", (IF(G$10>G16, "Yes", "No")), "")), "") -> Yes
A25: Year 10: | B25: =B17 -> 2023 | C25: =IF($D$5="Yes", (IF(C$10>C17, "Yes", "No")), "") -> Yes | D25: =IF($D$9<>"", (IF($D$5="Yes", (IF(D$10>D17, "Yes", "No")), "")), "") -> Yes | E25: =IF($E$9<>"", (IF($D$5="Yes", (IF(E$10>E17, "Yes", "No")), "")), "") -> Yes | F25: =IF($F$9<>"", (IF($D$5="Yes", (IF(F$10>F17, "Yes", "No")), "")), "") -> Yes | G25: =IF($G$9<>"", (IF($D$5="Yes", (IF(G$10>G17, "Yes", "No")), "")), "") -> Yes
A26: Year 15: | B26: =B18 -> 2028 | C26: =IF($D$5="Yes", (IF(C$10>C18, "Yes", "No")), "") -> Yes | D26: =IF($D$9<>"", (IF($D$5="Yes", (IF(D$10>D18, "Yes", "No")), "")), "") -> Yes | E26: =IF($E$9<>"", (IF($D$5="Yes", (IF(E$10>E18, "Yes", "No")), "")), "") -> Yes | F26: =IF($F$9<>"", (IF($D$5="Yes", (IF(F$10>F18, "Yes", "No")), "")), "") -> Yes | G26: =IF($G$9<>"", (IF($D$5="Yes", (IF(G$10>G18, "Yes", "No")), "")), "") -> Yes
A27: Year 20: | B27: =B19 -> 2033 | C27: =IF($D$5="Yes", (IF(C$10>C19, "Yes", "No")), "") -> No | D27: =IF($D$9<>"", (IF($D$5="Yes", (IF(D$10>D19, "Yes", "No")), "")), "") -> Yes | E27: =IF($E$9<>"", (IF($D$5="Yes", (IF(E$10>E19, "Yes", "No")), "")), "") -> Yes | F27: =IF($F$9<>"", (IF($D$5="Yes", (IF(F$10>F19, "Yes", "No")), "")), "") -> Yes | G27: =IF($G$9<>"", (IF($D$5="Yes", (IF(G$10>G19, "Yes", "No")), "")), "") -> No
A28: If the answer to the question above is "No" for any sub-sewershed, provide the reason why the current pipe size is proposed and/or what will be done to ensure capacity by the 20-year window (or 50-year window if extended years are considered).
A29: The Town intends to undertake an aggressive I/I campaign, especially in the sewershed at the head of the project and the foot of the project. The goal of the I/I program is to reduce I/I flows by half, which should reduce the flows in the interceptors where "No" is shown substantially so that they have the capacity to take the flow from the project.

Sheet Downstream Flow
A1: Table 4.4.3. Downstream Capacity Analysis
A2: =Input!C3 -> Central Avenue Expansion
A3: =Input!C4 -> Town of Anytown
A4: Complete the boxes shown in gray. Where indicated, use pulldown menus to enter data.
A5: Current Flow Methodology Used: | B5: Method 2 - Large Service Area | F5: Flow Projection Methodology Preferred: | G5: Other
A6: Collection System
A7: Percent WWTP Service Area in Downstream Pipe Sewershed Service Area: | D7: 0.9 | F7: WWTP Current Capacity (gpd): | G7: 16500000
B9: Current Year | C9: Year 1 | D9: Year 5 | E9: Year 10 | F9: Year 15 | G9: Year 20
B10: 2010 | C10: ='Future Flow'!$B$9 -> 2014 | D10: ='Future Flow'!$B$13 -> 2018 | E10: ='Future Flow'!$B$18 -> 2023 | F10: ='Future Flow'!$B$23 -> 2028 | G10: ='Future Flow'!$B$28 -> 2033
A11: Peak Flow from Project (gpd): | B11: =IF($B$5="Metered", 'Current Flow'!$A$10, (IF($B$5="Pump Runtime", 'Current Flow'!$C$18, (IF($B$5="Method 1 - Limited Service Area", 'Current Flow'!$C$32, (IF($B$5="Method 2 - Large Service Area", 'Current Flow'!$C$48, ""))))))) -> 9746354.7 | C11: =IF($G$5="SDC", 'Future Flow'!F9, (IF($G$5="Other", 'Future Flow'!J9, ""))) -> 11725982 | D11: =IF($G$5="SDC", 'Future Flow'!F13, (IF($G$5="Other", 'Future Flow'!J13, ""))) -> 11918229 | E11: =IF($G$5="SDC", 'Future Flow'!F18, (IF($G$5="Other", 'Future Flow'!J18, ""))) -> 12187662 | F11: =IF($G$5="SDC", 'Future Flow'!F23, (IF($G$5="Other", 'Future Flow'!J23, ""))) -> 12385686 | G11: =IF($G$5="SDC", 'Future Flow'!F28, (IF($G$5="Other", 'Future Flow'!J28, ""))) -> 12580178
A12: Downstream Collection System
C13: Downstream Sewershed
A14: Name: | C14: Sewershed A | D14: Sewershed B | E14: Sewershed C | F14: Sewershed D | G14: Sewershed E
A15: Capacity of Pipe(s) in downstream sewershed (gallons): | C15: 20250000 | D15: 20250000 | E15: 24000000 | F15: 24000000 | G15: 25000000
A16: Diameter (inches): | C16: 42 | D16: 42 | E16: 48 | F16: 48 | G16: 52
A17: Peaking Factor: | G17: 2.5
B18: Peak Flow from Downstream Flows (gpd)
B19: Current Year | C19: Year 1 | D19: Year 5 | E19: Year 10 | F19: Year 15 | G19: Year 20
B20: =B10 -> 2010 | C20: =C10 -> 2014 | D20: =D10 -> 2018 | E20: =E10 -> 2023 | F20: =F10 -> 2028 | G20: =G10 -> 2033
A21: =C14 -> Sewershed A | B21: 5000000 | C21: 5500000 | D21: 6000000 | E21: 6500000 | F21: 7000000 | G21: 7500000
A22: =D14 -> Sewershed B | B22: 0 | C22: 0 | D22: 0 | E22: 500000 | F22: 500000 | G22: 500000
A23: =E14 -> Sewershed C | B23: 0 | C23: 200000 | D23: 200000 | E23: 200000 | F23: 200000 | G23: 200000
A24: =F14 -> Sewershed D | B24: 0 | C24: 0 | D24: 0 | E24: 0 | F24: 400000 | G24: 400000
A25: =G14 -> Sewershed E | B25: 2000000 | C25: 200000 | D25: 300000 | E25: 300000 | F25: 300000 | G25: 300000
B26: Total Peak Flow Through Downstream Pipe (gpd)
B27: Current Year | C27: Year 1 | D27: Year 5 | E27: Year 10 | F27: Year 15 | G27: Year 20
B28: =B20 -> 2010 | C28: =C20 -> 2014 | D28: =D20 -> 2018 | E28: =E20 -> 2023 | F28: =F20 -> 2028 | G28: =G20 -> 2033
A29: =A21 -> Sewershed A | B29: =IF($B$21<>"", (IF($B$5="Metered", ('Current Flow'!$A$10+B$21), (IF($B$5="Pump Runtime", ('Current Flow'!$C$18+B$21), (IF($B$5="Method 1 - Limited Service Area", ('Current Flow'!$C$32+B$21), (IF($B$5="Method 2 - Large Service Area", ('Current Flow'!$C$48+B$21), "")))))))), "") -> 14746355 | C29: =IF($B$21<>"", (IF($G$5="SDC", ('Future Flow'!F9+C21), (IF($G$5="Other", ('Future Flow'!J9+C21), "")))), "") -> 17225982 | D29: =IF($B$21<>"", (IF($G$5="SDC", ('Future Flow'!F13+D21), (IF($G$5="Other", ('Future Flow'!J13+D21), "")))), "") -> 17918229 | E29: =IF($B$21<>"", (IF($G$5="SDC", ('Future Flow'!F18+E21), (IF($G$5="Other", ('Future Flow'!J18+E21), "")))), "") -> 18687662 | F29: =IF($B$21<>"", (IF($G$5="SDC", ('Future Flow'!F23+F21), (IF($G$5="Other", ('Future Flow'!J23+F21), "")))), "") -> 19385686 | G29: =IF($B$21<>"", (IF($G$5="SDC", ('Future Flow'!F28+G21), (IF($G$5="Other", ('Future Flow'!J28+G21), "")))), "") -> 20080178
A30: =A22 -> Sewershed B | B30: =IF($B$22<>"", (B29+B22), "") -> 14746355 | C30: =IF($B$22<>"", (C29+C22), "") -> 17225982 | D30: =IF($B$22<>"", (D29+D22), "") -> 17918229 | E30: =IF($B$22<>"", (E29+E22), "") -> 19187662 | F30: =IF($B$22<>"", (F29+F22), "") -> 19885686 | G30: =IF($B$22<>"", (G29+G22), "") -> 20580178
A31: =A23 -> Sewershed C | B31: =IF($B$23<>"", (B30+B23), "") -> 14746355 | C31: =IF($B$23<>"", (C30+C23), "") -> 17425982 | D31: =IF($B$23<>"", (D30+D23), "") -> 18118229 | E31: =IF($B$23<>"", (E30+E23), "") -> 19387662 | F31: =IF($B$23<>"", (F30+F23), "") -> 20085686 | G31: =IF($B$23<>"", (G30+G23), "") -> 20780178
A32: =A24 -> Sewershed D | B32: =IF($B$24<>"", (B31+B24), "") -> 14746355 | C32: =IF($B$24<>"", (C31+C24), "") -> 17425982 | D32: =IF($B$24<>"", (D31+D24), "") -> 18118229 | E32: =IF($B$24<>"", (E31+E24), "") -> 19387662 | F32: =IF($B$24<>"", (F31+F24), "") -> 20485686 | G32: =IF($B$24<>"", (G31+G24), "") -> 21180178
