Workbook

Sheet Design
A1: LAVERS RANCH VINEYARD DESIGN
A4: Field Constraints:
B5: Crop: Wine Grapes
B6: Location: Glenville, Ca
B7: Crop Spacing | D7: 8 | E7: ft by | F7: 6 | G7: ft
B8: Field Size: | C8: 2 separate field
C9: Field A | D9: 13.4 | E9: acres
C10: Field B | D10: 19 | E10: acres
B12: Vineyard row runs NE to SW
B14: Peak Eto Rate = | D14: 0.34 | E14: inches/day
B16: Assuming 40% crop coverage
C17: Kc = | D17: 0.7
B19: Sandy Loam Soil
B21: Irrigation
C22: 24 | D22: hours | E22: 7 | F22: days
A25: 1. Determine Peak ET rate
B27: Peak Eto | C27: =D14 -> 0.34 | D27: inches/day in May from CIMIS Spatial Data
B29: Kc | C29: =D17 -> 0.7
B31: Peak Et = Eto * Kc
B33: Peak ET | C33: =C27*C29 -> 0.238 | D33: inches/day
C34: * Assume 10% increase with drip
B35: Peak ET | C35: =C33*1.1 -> 0.2618 | D35: inches/day
A38: 2. Estimate GPH/vine needed
B42: =C35 -> 0.2618 | C42: inches/day
B43: =C22 -> 24 | C43: hours/day
B44: =E22 -> 7 | C44: days/week
B45: =D7 -> 8 | C45: ft by | D45: =F7 -> 6 | E45: ft Vine spacing
B46: =B45*D45 -> 48 | C46: Sq. ft Vine spacing area
B48: =B42*B46/(96.3*B43) -> 0.0054371755 | C48: GPM/vine (net)
B49: =B48*60 -> 0.32623053 | C49: GPH/vine (net)
B51: * Assuming perfect timing, and no over-irrigation at "driest" point during
C52: peak ET. With drip irrigation, the percent spray loss is zero
B53: * Use DU of 0.8 so that as the systems deteriorates with time, there will be
C54: less chance of under-irrigation on a portion of the field
B55: 0.8 | C55: DU (assumed)
B61: =B49/B55 -> 0.40778816 | C61: GPH/Vine (gross)
A67: 3. Estimate the Number of Emitters/Vine:
A69: Soil Type | D69: Additional Lateral Movement for Drip
D70: Radius (ft)
A71: Coars Sand | D71: 0.5 - 1.5
...

Sheet Block 1
A1: BLOCK 1
A3: Sub-mainline Sizing and Pressure
B6: 150 | C6: C-value for PVC ID > 5"
B7: 145 | C7: C-value for PVC 1.5" < = ID < = 5"
B8: 140 | C8: C-value for PVC < 1.5"
B9: 10 | C9: feet, Total Elevation Drop
B10: 743.9 | C10: feet, Length of Sub-mainline
B11: =B9/B10 -> 0.013442667 | C11: ft/ft, Change in Elevation
B12: 0.5 | C12: GPH/emitter
B13: =B12/60 -> 0.0083333333 | C13: GPM/emitter
B14: 3.045 | C14: ft, emitter spacing
B17: Chg. Elev = Length * ft/ft (elevation change worst case)
B18: Chg. P = Chg. Elev + Hf
A20: Section A
A21: Row | B21: Row Length ft | C21: GPM per Row | D21: Pressure PSI | E21: Length ft | F21: GPM | G21: Pipe ID, in | H21: Velocity, ft/sec | I21: C-Value | J21: Hf (psi) | K21: Chg. Elev (psi) | L21: Chg. P (psi)
A22: Inlet | B22: 0 | C22: 0 | D22: 25 | E22: 0 | F22: 52.5 | G22: 2.193 | H22: =(F22/448.8)/(3.14*((G22/12)^2)/4) -> 4.4619225 | I22: =IF(G22>5,$B$6,IF(5>=G22>1.5,$B$7,IF(1.5>G22,$B$8,0))) -> 145 | J22: =(1050*((F22/I22)^1.852)*(E22/100)*(G22^-4.87))/2.31 -> 0 | K22: =E22*$B$11 -> 0 | L22: =K22-J22 -> 0
A23: 1 | B23: 22.3 | C23: =(B23/$B$14)*$B$13 -> 0.061029009 | D23: =D22+L22 -> 25 | E23: 15.5 | F23: =F22-C23 -> 52.438971 | G23: 2.193 | H23: =(F23/448.8)/(3.14*((G23/12)^2)/4) -> 4.4567358 | I23: =IF(G23>5,$B$6,IF(5>=G23>1.5,$B$7,IF(1.5>G23,$B$8,0))) -> 145 | J23: =(1050*((F23/I23)^1.852)*(E23/100)*(G23^-4.87))/2.31 -> 0.23388203 | K23: =E23*$B$11 -> 0.20836134 | L23: =K23-J23 -> -0.025520687
A24: =A23+1 -> 2 | B24: 33.5 | C24: =(B24/$B$14)*$B$13 -> 0.09168035 | D24: =D23+L23 -> 24.974479 | E24: 7.7 | F24: =F23-C24 -> 52.347291 | G24: 2.193 | H24: =(F24/448.8)/(3.14*((G24/12)^2)/4) -> 4.4489439 | I24: =IF(G24>5,$B$6,IF(5>=G24>1.5,$B$7,IF(1.5>G24,$B$8,0))) -> 145 | J24: =(1050*((F24/I24)^1.852)*(E24/100)*(G24^-4.87))/2.31 -> 0.11581063 | K24: =E24*$B$11 -> 0.10350854 | L24: =K24-J24 -> -0.012302099
A25: =A24+1 -> 3 | B25: 44.6 | C25: =(B25/$B$14)*$B$13 -> 0.12205802 | D25: =D24+L24 -> 24.962177 | E25: 7.7 | F25: =F24-C25 -> 52.225233 | G25: 2.193 | H25: =(F25/448.8)/(3.14*((G25/12)^2)/4) -> 4.4385703 | I25: =IF(G25>5,$B$6,IF(5>=G25>1.5,$B$7,IF(1.5>G25,$B$8,0))) -> 145 | J25: =(1050*((F25/I25)^1.852)*(E25/100)*(G25^-4.87))/2.31 -> 0.11531103 | K25: =E25*$B$11 -> 0.10350854 | L25: =K25-J25 -> -0.01180249
A26: =A25+1 -> 4 | B26: 55.8 | C26: =(B26/$B$14)*$B$13 -> 0.15270936 | D26: =D25+L25 -> 24.950375 | E26: 7.7 | F26: =F25-C26 -> 52.072523 | G26: 2.193 | H26: =(F26/448.8)/(3.14*((G26/12)^2)/4) -> 4.4255917 | I26: =IF(G26>5,$B$6,IF(5>=G26>1.5,$B$7,IF(1.5>G26,$B$8,0))) -> 145 | J26: =(1050*((F26/I26)^1.852)*(E26/100)*(G26^-4.87))/2.31 -> 0.11468736 | K26: =E26*$B$11 -> 0.10350854 | L26: =K26-J26 -> -0.011178819
A27: =A26+1 -> 5 | B27: 66.9 | C27: =(B27/$B$14)*$B$13 -> 0.18308703 | D27: =D26+L26 -> 24.939196 | E27: 7.7 | F27: =F26-C27 -> 51.889436 | G27: 2.193 | H27: =(F27/448.8)/(3.14*((G27/12)^2)/4) -> 4.4100313 | I27: =IF(G27>5,$B$6,IF(5>=G27>1.5,$B$7,IF(1.5>G27,$B$8,0))) -> 145 | J27: =(1050*((F27/I27)^1.852)*(E27/100)*(G27^-4.87))/2.31 -> 0.11394167 | K27: =E27*$B$11 -> 0.10350854 | L27: =K27-J27 -> -0.010433136
A28: =A27+1 -> 6 | B28: 78.1 | C28: =(B28/$B$14)*$B$13 -> 0.21373837 | D28: =D27+L27 -> 24.928763 | E28: 7.7 | F28: =F27-C28 -> 51.675698 | G28: 2.193 | H28: =(F28/448.8)/(3.14*((G28/12)^2)/4) -> 4.3918659 | I28: =IF(G28>5,$B$6,IF(5>=G28>1.5,$B$7,IF(1.5>G28,$B$8,0))) -> 145 | J28: =(1050*((F28/I28)^1.852)*(E28/100)*(G28^-4.87))/2.31 -> 0.11307398 | K28: =E28*$B$11 -> 0.10350854 | L28: =K28-J28 -> -0.0095654465
A29: =A28+1 -> 7 | B29: 89.2 | C29: =(B29/$B$14)*$B$13 -> 0.24411604 | D29: =D28+L28 -> 24.919197 | E29: 7.7 | F29: =F28-C29 -> 51.431582 | G29: 2.193 | H29: =(F29/448.8)/(3.14*((G29/12)^2)/4) -> 4.3711188 | I29: =IF(G29>5,$B$6,IF(5>=G29>1.5,$B$7,IF(1.5>G29,$B$8,0))) -> 145 | J29: =(1050*((F29/I29)^1.852)*(E29/100)*(G29^-4.87))/2.31 -> 0.11208671 | K29: =E29*$B$11 -> 0.10350854 | L29: =K29-J29 -> -0.0085781705
A30: =A29+1 -> 8 | B30: 100.4 | C30: =(B30/$B$14)*$B$13 -> 0.27476738 | D30: =D29+L29 -> 24.910619 | E30: 7.7 | F30: =F29-C30 -> 51.156814 | G30: 2.193 | H30: =(F30/448.8)/(3.14*((G30/12)^2)/4) -> 4.3477665 | I30: =IF(G30>5,$B$6,IF(5>=G30>1.5,$B$7,IF(1.5>G30,$B$8,0))) -> 145 | J30: =(1050*((F30/I30)^1.852)*(E30/100)*(G30^-4.87))/2.31 -> 0.11098023 | K30: =E30*$B$11 -> 0.10350854 | L30: =K30-J30 -> -0.0074716981
A31: =A30+1 -> 9 | B31: 111.6 | C31: =(B31/$B$14)*$B$13 -> 0.30541872 | D31: =D30+L30 -> 24.903147 | E31: 7.7 | F31: =F30-C31 -> 50.851396 | G31: 2.193 | H31: =(F31/448.8)/(3.14*((G31/12)^2)/4) -> 4.3218093 | I31: =IF(G31>5,$B$6,IF(5>=G31>1.5,$B$7,IF(1.5>G31,$B$8,0))) -> 145 | J31: =(1050*((F31/I31)^1.852)*(E31/100)*(G31^-4.87))/2.31 -> 0.10975626 | K31: =E31*$B$11 -> 0.10350854 | L31: =K31-J31 -> -0.0062477233
A32: =A31+1 -> 10 | B32: 122.7 | C32: =(B32/$B$14)*$B$13 -> 0.33579639 | D32: =D31+L31 -> 24.8969 | E32: 7.7 | F32: =F31-C32 -> 50.515599 | G32: 2.193 | H32: =(F32/448.8)/(3.14*((G32/12)^2)/4) -> 4.2932703 | I32: =IF(G32>5,$B$6,IF(5>=G32>1.5,$B$7,IF(1.5>G32,$B$8,0))) -> 145 | J32: =(1050*((F32/I32)^1.852)*(E32/100)*(G32^-4.87))/2.31 -> 0.10841776 | K32: =E32*$B$11 -> 0.10350854 | L32: =K32-J32 -> -0.0049092195
A33: =A32+1 -> 11 | B33: 133.9 | C33: =(B33/$B$14)*$B$13 -> 0.36644773 | D33: =D32+L32 -> 24.891991 | E33: 7.7 | F33: =F32-C33 -> 50.149152 | G33: 2.193 | H33: =(F33/448.8)/(3.14*((G33/12)^2)/4) -> 4.2621263 | I33: =IF(G33>5,$B$6,IF(5>=G33>1.5,$B$7,IF(1.5>G33,$B$8,0))) -> 145 | J33: =(1050*((F33/I33)^1.852)*(E33/100)*(G33^-4.87))/2.31 -> 0.1069657 | K33: =E33*$B$11 -> 0.10350854 | L33: =K33-J33 -> -0.0034571638
A34: =A33+1 -> 12 | B34: 145 | C34: =(B34/$B$14)*$B$13 -> 0.3968254 | D34: =D33+L33 -> 24.888533 | E34: 7.7 | F34: =F33-C34 -> 49.752326 | G34: 2.193 | H34: =(F34/448.8)/(3.14*((G34/12)^2)/4) -> 4.2284005 | I34: =IF(G34>5,$B$6,IF(5>=G34>1.5,$B$7,IF(1.5>G34,$B$8,0))) -> 145 | J34: =(1050*((F34/I34)^1.852)*(E34/100)*(G34^-4.87))/2.31 -> 0.10540344 | K34: =E34*$B$11 -> 0.10350854 | L34: =K34-J34 -> -0.0018949
A35: =A34+1 -> 13 | B35: 156.2 | C35: =(B35/$B$14)*$B$13 -> 0.42747674 | D35: =D34+L34 -> 24.886638 | E35: 7.7 | F35: =F34-C35 -> 49.324849 | G35: 2.193 | H35: =(F35/448.8)/(3.14*((G35/12)^2)/4) -> 4.1920697 | I35: =IF(G35>5,$B$6,IF(5>=G35>1.5,$B$7,IF(1.5>G35,$B$8,0))) -> 145 | J35: =(1050*((F35/I35)^1.852)*(E35/100)*(G35^-4.87))/2.31 -> 0.10373234 | K35: =E35*$B$11 -> 0.10350854 | L35: =K35-J35 -> -0.00022380309
... A50: =A49+1 -> 28 | B50: 161.2 | C50: =(B50/$B$14)*$B$13 -> 0.44116037 | D50: =D49+L49 -> 25.062059 | E50: 7.7 | F50: =F49-C50 -> 42.562124 | G50: 2.193 | H50: =(F50/448.8)/(3.14*((G50/12)^2)/4) -> 3.6173124 | I50: =IF(G50>5,$B$6,IF(5>=G50>1.5,$B$7,IF(1.5>G50,$B$8,0))) -> 145 | J50: =(1050*((F50/I50)^1.852)*(E50/100)*(G50^-4.87))/2.31 -> 0.078941886 | K50: =E50*$B$11 -> 0.10350854 | L50: =K50-J50 -> 0.02456665
A51: Section B
A52: 29 | B52: 167.7 | C52: =(B52/$B$14)*$B$13 -> 0.4589491 | D52: =D50+L50 -> 25.086626 | E52: 11.2 | F52: =F50-C52 -> 42.103175 | G52: 2.193 | H52: =(F52/448.8)/(3.14*((G52/12)^2)/4) -> 3.5783067 | I52: =IF(G52>5,$B$6,IF(5>=G52>1.5,$B$7,IF(1.5>G52,$B$8,0))) -> 145 | J52: =(1050*((F52/I52)^1.852)*(E52/100)*(G52^-4.87))/2.31 -> 0.11254203 | K52: =E52*$B$11 -> 0.15055787 | L52: =K52-J52 -> 0.038015838
A53: =A52+1 -> 30 | B53: 175.7 | C53: =(B53/$B$14)*$B$13 -> 0.48084291 | D53: =D52+L52 -> 25.124641 | E53: 11.8 | F53: =F52-C53 -> 41.622332 | G53: 2.193 | H53: =(F53/448.8)/(3.14*((G53/12)^2)/4) -> 3.5374404 | I53: =IF(G53>5,$B$6,IF(5>=G53>1.5,$B$7,IF(1.5>G53,$B$8,0))) -> 145 | J53: =(1050*((F53/I53)^1.852)*(E53/100)*(G53^-4.87))/2.31 -> 0.11607539 | K53: =E53*$B$11 -> 0.15862347 | L53: =K53-J53 -> 0.04254808
A54: =A53+1 -> 31 | B54: 183.8 | C54: =(B54/$B$14)*$B$13 -> 0.5030104 | D54: =D53+L53 -> 25.16719 | E54: 11.8 | F54: =F53-C54 -> 41.119321 | G54: 2.193 | H54: =(F54/448.8)/(3.14*((G54/12)^2)/4) -> 3.49469 | I54: =IF(G54>5,$B$6,IF(5>=G54>1.5,$B$7,IF(1.5>G54,$B$8,0))) -> 145 | J54: =(1050*((F54/I54)^1.852)*(E54/100)*(G54^-4.87))/2.31 -> 0.11349082 | K54: =E54*$B$11 -> 0.15862347 | L54: =K54-J54 -> 0.045132653
A55: =A54+1 -> 32 | B55: 191.8 | C55: =(B55/$B$14)*$B$13 -> 0.52490421 | D55: =D54+L54 -> 25.212322 | E55: 11.8 | F55: =F54-C55 -> 40.594417 | G55: 2.193 | H55: =(F55/448.8)/(3.14*((G55/12)^2)/4) -> 3.4500789 | I55: =IF(G55>5,$B$6,IF(5>=G55>1.5,$B$7,IF(1.5>G55,$B$8,0))) -> 145 | J55: =(1050*((F55/I55)^1.852)*(E55/100)*(G55^-4.87))/2.31 -> 0.11082232 | K55: =E55*$B$11 -> 0.15862347 | L55: =K55-J55 -> 0.047801146
A56: =A55+1 -> 33 | B56: 199.9 | C56: =(B56/$B$14)*$B$13 -> 0.5470717 | D56: =D55+L55 -> 25.260123 | E56: 11.8 | F56: =F55-C56 -> 40.047345 | G56: 2.193 | H56: =(F56/448.8)/(3.14*((G56/12)^2)/4) -> 3.4035839 | I56: =IF(G56>5,$B$6,IF(5>=G56>1.5,$B$7,IF(1.5>G56,$B$8,0))) -> 145 | J56: =(1050*((F56/I56)^1.852)*(E56/100)*(G56^-4.87))/2.31 -> 0.10807225 | K56: =E56*$B$11 -> 0.15862347 | L56: =K56-J56 -> 0.050551218
A57: =A56+1 -> 34 | B57: 215.7 | C57: =(B57/$B$14)*$B$13 -> 0.59031199 | D57: =D56+L56 -> 25.310675 | E57: 11.8 | F57: =F56-C57 -> 39.457033 | G57: 2.193 | H57: =(F57/448.8)/(3.14*((G57/12)^2)/4) -> 3.3534138 | I57: =IF(G57>5,$B$6,IF(5>=G57>1.5,$B$7,IF(1.5>G57,$B$8,0))) -> 145 | J57: =(1050*((F57/I57)^1.852)*(E57/100)*(G57^-4.87))/2.31 -> 0.10514051 | K57: =E57*$B$11 -> 0.15862347 | L57: =K57-J57 -> 0.053482958
A58: =A57+1 -> 35 | B58: 233.1 | C58: =(B58/$B$14)*$B$13 -> 0.63793103 | D58: =D57+L57 -> 25.364157 | E58: 11.8 | F58: =F57-C58 -> 38.819102 | G58: 2.193 | H58: =(F58/448.8)/(3.14*((G58/12)^2)/4) -> 3.2991967 | I58: =IF(G58>5,$B$6,IF(5>=G58>1.5,$B$7,IF(1.5>G58,$B$8,0))) -> 145 | J58: =(1050*((F58/I58)^1.852)*(E58/100)*(G58^-4.87))/2.31 -> 0.10201403 | K58: =E58*$B$11 -> 0.15862347 | L58: =K58-J58 -> 0.056609443
A59: =A58+1 -> 36 | B59: 250.4 | C59: =(B59/$B$14)*$B$13 -> 0.68527641 | D59: =D58+L58 -> 25.420767 | E59: 11.8 | F59: =F58-C59 -> 38.133826 | G59: 2.193 | H59: =(F59/448.8)/(3.14*((G59/12)^2)/4) -> 3.2409558 | I59: =IF(G59>5,$B$6,IF(5>=G59>1.5,$B$7,IF(1.5>G59,$B$8,0))) -> 145 | J59: =(1050*((F59/I59)^1.852)*(E59/100)*(G59^-4.87))/2.31 -> 0.098703937 | K59: =E59*$B$11 -> 0.15862347 | L59: =K59-J59 -> 0.059919534
A60: =A59+1 -> 37 | B60: 267.8 | C60: =(B60/$B$14)*$B$13 -> 0.73289546 | D60: =D59+L59 -> 25.480686 | E60: 11.8 | F60: =F59-C60 -> 37.40093 | G60: 2.193 | H60: =(F60/448.8)/(3.14*((G60/12)^2)/4) -> 3.1786677 | I60: =IF(G60>5,$B$6,IF(5>=G60>1.5,$B$7,IF(1.5>G60,$B$8,0))) -> 145 | J60: =(1050*((F60/I60)^1.852)*(E60/100)*(G60^-4.87))/2.31 -> 0.095219494 | K60: =E60*$B$11 -> 0.15862347 | L60: =K60-J60 -> 0.063403977
...

Sheet Block 2
A1: Block 2
A3: Sub-mainline Sizing and Pressure
B6: 150 | C6: C-value for PVC ID > 5"
B7: 145 | C7: C-value for PVC 1.5" < = ID < = 5"
B8: 140 | C8: C-value for PVC < 1.5"
B9: 10 | C9: feet, Total Elevation Drop
B10: 352.3 | C10: feet, Length of Sub-mainline
B11: =B9/B10 -> 0.028384899 | C11: ft/ft, Change in Elevation
B12: 0.5 | C12: GPH/emitter
B13: =B12/60 -> 0.0083333333 | C13: GPM/emitter
B14: 3.045 | C14: ft, emitter spacing
B17: Chg. Elev = Length * ft/ft (elevation change worst case)
B18: Chg. P = Chg. Elev + Hf
A21: Section A
A22: Row | B22: Row Length ft | C22: GPM per Row | D22: Pressure PSI | E22: Length ft | F22: GPM | G22: Pipe ID, in | H22: Velocity, ft/sec | I22: C-Value | J22: Hf (psi) | K22: Chg. Elev (psi) | L22: Chg. P (psi)
A23: Inlet | B23: 0 | C23: 0 | D23: 25 | E23: 0 | F23: 48 | G23: 2.193 | H23: =(F23/448.8)/(3.14*((G23/12)^2)/4) -> 4.079472 | I23: =IF(G23>5,$B$6,IF(5>=G23>1.5,$B$7,IF(1.5>G23,$B$8,0))) -> 145 | J23: =(1050*((F23/I23)^1.852)*(E23/100)*(G23^-4.87))/2.31 -> 0 | K23: =E23*$B$11 -> 0 | L23: =K23-J23 -> 0
A24: 1 | B24: 548.4 | C24: =(B24/$B$14)*$B$13 -> 1.500821 | D24: =D23+L23 -> 25 | E24: 1.26 | F24: =F23-C24 -> 46.499179 | G24: 2.193 | H24: =(F24/448.8)/(3.14*((G24/12)^2)/4) -> 3.9519188 | I24: =IF(G24>5,$B$6,IF(5>=G24>1.5,$B$7,IF(1.5>G24,$B$8,0))) -> 145 | J24: =(1050*((F24/I24)^1.852)*(E24/100)*(G24^-4.87))/2.31 -> 0.015217554 | K24: =E24*$B$11 -> 0.035764973 | L24: =K24-J24 -> 0.020547419
A25: =A24+1 -> 2 | B25: 537.8 | C25: =(B25/$B$14)*$B$13 -> 1.4718117 | D25: =D24+L24 -> 25.020547 | E25: 9.2 | F25: =F24-C25 -> 45.027367 | G25: 2.193 | H25: =(F25/448.8)/(3.14*((G25/12)^2)/4) -> 3.826831 | I25: =IF(G25>5,$B$6,IF(5>=G25>1.5,$B$7,IF(1.5>G25,$B$8,0))) -> 145 | J25: =(1050*((F25/I25)^1.852)*(E25/100)*(G25^-4.87))/2.31 -> 0.10468683 | K25: =E25*$B$11 -> 0.26114107 | L25: =K25-J25 -> 0.15645424
A26: =A25+1 -> 3 | B26: 527.2 | C26: =(B26/$B$14)*$B$13 -> 1.4428024 | D26: =D25+L25 -> 25.177002 | E26: 9.2 | F26: =F25-C26 -> 43.584565 | G26: 2.193 | H26: =(F26/448.8)/(3.14*((G26/12)^2)/4) -> 3.7042086 | I26: =IF(G26>5,$B$6,IF(5>=G26>1.5,$B$7,IF(1.5>G26,$B$8,0))) -> 145 | J26: =(1050*((F26/I26)^1.852)*(E26/100)*(G26^-4.87))/2.31 -> 0.098559311 | K26: =E26*$B$11 -> 0.26114107 | L26: =K26-J26 -> 0.16258176
A27: =A26+1 -> 4 | B27: 516.5 | C27: =(B27/$B$14)*$B$13 -> 1.4135194 | D27: =D26+L26 -> 25.339583 | E27: 9.2 | F27: =F26-C27 -> 42.171045 | G27: 2.193 | H27: =(F27/448.8)/(3.14*((G27/12)^2)/4) -> 3.584075 | I27: =IF(G27>5,$B$6,IF(5>=G27>1.5,$B$7,IF(1.5>G27,$B$8,0))) -> 145 | J27: =(1050*((F27/I27)^1.852)*(E27/100)*(G27^-4.87))/2.31 -> 0.092721421 | K27: =E27*$B$11 -> 0.26114107 | L27: =K27-J27 -> 0.16841965
A28: =A27+1 -> 5 | B28: 505.9 | C28: =(B28/$B$14)*$B$13 -> 1.3845101 | D28: =D27+L27 -> 25.508003 | E28: 9.2 | F28: =F27-C28 -> 40.786535 | G28: 2.193 | H28: =(F28/448.8)/(3.14*((G28/12)^2)/4) -> 3.4664069 | I28: =IF(G28>5,$B$6,IF(5>=G28>1.5,$B$7,IF(1.5>G28,$B$8,0))) -> 145 | J28: =(1050*((F28/I28)^1.852)*(E28/100)*(G28^-4.87))/2.31 -> 0.087162687 | K28: =E28*$B$11 -> 0.26114107 | L28: =K28-J28 -> 0.17397839
A29: =A28+1 -> 6 | B29: 495.3 | C29: =(B29/$B$14)*$B$13 -> 1.3555008 | D29: =D28+L28 -> 25.681981 | E29: 9.2 | F29: =F28-C29 -> 39.431034 | G29: 2.193 | H29: =(F29/448.8)/(3.14*((G29/12)^2)/4) -> 3.3512042 | I29: =IF(G29>5,$B$6,IF(5>=G29>1.5,$B$7,IF(1.5>G29,$B$8,0))) -> 145 | J29: =(1050*((F29/I29)^1.852)*(E29/100)*(G29^-4.87))/2.31 -> 0.081873954 | K29: =E29*$B$11 -> 0.26114107 | L29: =K29-J29 -> 0.17926712
A30: =A29+1 -> 7 | B30: 484.7 | C30: =(B30/$B$14)*$B$13 -> 1.3264915 | D30: =D29+L29 -> 25.861249 | E30: 9.2 | F30: =F29-C30 -> 38.104543 | G30: 2.193 | H30: =(F30/448.8)/(3.14*((G30/12)^2)/4) -> 3.238467 | I30: =IF(G30>5,$B$6,IF(5>=G30>1.5,$B$7,IF(1.5>G30,$B$8,0))) -> 145 | J30: =(1050*((F30/I30)^1.852)*(E30/100)*(G30^-4.87))/2.31 -> 0.076846205 | K30: =E30*$B$11 -> 0.26114107 | L30: =K30-J30 -> 0.18429487
A31: =A30+1 -> 8 | B31: 474.1 | C31: =(B31/$B$14)*$B$13 -> 1.2974822 | D31: =D30+L30 -> 26.045543 | E31: 9.2 | F31: =F30-C31 -> 36.807061 | G31: 2.193 | H31: =(F31/448.8)/(3.14*((G31/12)^2)/4) -> 3.1281953 | I31: =IF(G31>5,$B$6,IF(5>=G31>1.5,$B$7,IF(1.5>G31,$B$8,0))) -> 145 | J31: =(1050*((F31/I31)^1.852)*(E31/100)*(G31^-4.87))/2.31 -> 0.072070567 | K31: =E31*$B$11 -> 0.26114107 | L31: =K31-J31 -> 0.18907051
A32: =A31+1 -> 9 | B32: 463.4 | C32: =(B32/$B$14)*$B$13 -> 1.2681992 | D32: =D31+L31 -> 26.234614 | E32: 9.2 | F32: =F31-C32 -> 35.538862 | G32: 2.193 | H32: =(F32/448.8)/(3.14*((G32/12)^2)/4) -> 3.0204123 | I32: =IF(G32>5,$B$6,IF(5>=G32>1.5,$B$7,IF(1.5>G32,$B$8,0))) -> 145 | J32: =(1050*((F32/I32)^1.852)*(E32/100)*(G32^-4.87))/2.31 -> 0.067539272 | K32: =E32*$B$11 -> 0.26114107 | L32: =K32-J32 -> 0.1936018
A33: =A32+1 -> 10 | B33: 452.8 | C33: =(B33/$B$14)*$B$13 -> 1.2391899 | D33: =D32+L32 -> 26.428216 | E33: 9.2 | F33: =F32-C33 -> 34.299672 | G33: 2.193 | H33: =(F33/448.8)/(3.14*((G33/12)^2)/4) -> 2.9150948 | I33: =IF(G33>5,$B$6,IF(5>=G33>1.5,$B$7,IF(1.5>G33,$B$8,0))) -> 145 | J33: =(1050*((F33/I33)^1.852)*(E33/100)*(G33^-4.87))/2.31 -> 0.063242711 | K33: =E33*$B$11 -> 0.26114107 | L33: =K33-J33 -> 0.19789836
A34: =A33+1 -> 11 | B34: 442.2 | C34: =(B34/$B$14)*$B$13 -> 1.2101806 | D34: =D33+L33 -> 26.626114 | E34: 9.2 | F34: =F33-C34 -> 33.089491 | G34: 2.193 | H34: =(F34/448.8)/(3.14*((G34/12)^2)/4) -> 2.8122428 | I34: =IF(G34>5,$B$6,IF(5>=G34>1.5,$B$7,IF(1.5>G34,$B$8,0))) -> 145 | J34: =(1050*((F34/I34)^1.852)*(E34/100)*(G34^-4.87))/2.31 -> 0.059172444 | K34: =E34*$B$11 -> 0.26114107 | L34: =K34-J34 -> 0.20196863
A35: Section B
A36: =A34+1 -> 12 | B36: 438.6 | C36: =(B36/$B$14)*$B$13 -> 1.2003284 | D36: =D34+L34 -> 26.828083 | E36: 9.3 | F36: =F34-C36 -> 31.889163 | G36: 1.72 | H36: =(F36/448.8)/(3.14*((G36/12)^2)/4) -> 4.4058145 | I36: =IF(G36>5,$B$6,IF(5>=G36>1.5,$B$7,IF(1.5>G36,$B$8,0))) -> 145 | J36: =(1050*((F36/I36)^1.852)*(E36/100)*(G36^-4.87))/2.31 -> 0.18236028 | K36: =E36*$B$11 -> 0.26397956 | L36: =K36-J36 -> 0.081619288
A37: =A36+1 -> 13 | B37: 438.1 | C37: =(B37/$B$14)*$B$13 -> 1.19896 | D37: =D36+L36 -> 26.909702 | E37: 9.3 | F37: =F36-C37 -> 30.690203 | G37: 1.72 | H37: =(F37/448.8)/(3.14*((G37/12)^2)/4) -> 4.2401659 | I37: =IF(G37>5,$B$6,IF(5>=G37>1.5,$B$7,IF(1.5>G37,$B$8,0))) -> 145 | J37: =(1050*((F37/I37)^1.852)*(E37/100)*(G37^-4.87))/2.31 -> 0.16986611 | K37: =E37*$B$11 -> 0.26397956 | L37: =K37-J37 -> 0.094113455
A38: =A37+1 -> 14 | B38: 437.5 | C38: =(B38/$B$14)*$B$13 -> 1.197318 | D38: =D37+L37 -> 27.003815 | E38: 9.3 | F38: =F37-C38 -> 29.492885 | G38: 1.72 | H38: =(F38/448.8)/(3.14*((G38/12)^2)/4) -> 4.0747441 | I38: =IF(G38>5,$B$6,IF(5>=G38>1.5,$B$7,IF(1.5>G38,$B$8,0))) -> 145 | J38: =(1050*((F38/I38)^1.852)*(E38/100)*(G38^-4.87))/2.31 -> 0.15779729 | K38: =E38*$B$11 -> 0.26397956 | L38: =K38-J38 -> 0.10618227
A39: =A38+1 -> 15 | B39: 437 | C39: =(B39/$B$14)*$B$13 -> 1.1959496 | D39: =D38+L38 -> 27.109998 | E39: 9.3 | F39: =F38-C39 -> 28.296935 | G39: 1.72 | H39: =(F39/448.8)/(3.14*((G39/12)^2)/4) -> 3.9095114 | I39: =IF(G39>5,$B$6,IF(5>=G39>1.5,$B$7,IF(1.5>G39,$B$8,0))) -> 145 | J39: =(1050*((F39/I39)^1.852)*(E39/100)*(G39^-4.87))/2.31 -> 0.14615193 | K39: =E39*$B$11 -> 0.26397956 | L39: =K39-J39 -> 0.11782763
A40: =A39+1 -> 16 | B40: 436.4 | C40: =(B40/$B$14)*$B$13 -> 1.1943076 | D40: =D39+L39 -> 27.227825 | E40: 9.3 | F40: =F39-C40 -> 27.102627 | G40: 1.72 | H40: =(F40/448.8)/(3.14*((G40/12)^2)/4) -> 3.7445056 | I40: =IF(G40>5,$B$6,IF(5>=G40>1.5,$B$7,IF(1.5>G40,$B$8,0))) -> 145 | J40: =(1050*((F40/I40)^1.852)*(E40/100)*(G40^-4.87))/2.31 -> 0.13493366 | K40: =E40*$B$11 -> 0.26397956 | L40: =K40-J40 -> 0.12904591
A41: =A40+1 -> 17 | B41: 435.9 | C41: =(B41/$B$14)*$B$13 -> 1.1929392 | D41: =D40+L40 -> 27.356871 | E41: 9.3 | F41: =F40-C41 -> 25.909688 | G41: 1.72 | H41: =(F41/448.8)/(3.14*((G41/12)^2)/4) -> 3.5796888 | I41: =IF(G41>5,$B$6,IF(5>=G41>1.5,$B$7,IF(1.5>G41,$B$8,0))) -> 145 | J41: =(1050*((F41/I41)^1.852)*(E41/100)*(G41^-4.87))/2.31 -> 0.12414098 | K41: =E41*$B$11 -> 0.26397956 | L41: =K41-J41 -> 0.13983859
A42: =A41+1 -> 18 | B42: 435.3 | C42: =(B42/$B$14)*$B$13 -> 1.1912972 | D42: =D41+L41 -> 27.49671 | E42: 9.3 | F42: =F41-C42 -> 24.718391 | G42: 1.72 | H42: =(F42/448.8)/(3.14*((G42/12)^2)/4) -> 3.4150989 | I42: =IF(G42>5,$B$6,IF(5>=G42>1.5,$B$7,IF(1.5>G42,$B$8,0))) -> 145 | J42: =(1050*((F42/I42)^1.852)*(E42/100)*(G42^-4.87))/2.31 -> 0.11377755 | K42: =E42*$B$11 -> 0.26397956 | L42: =K42-J42 -> 0.15020201
A43: =A42+1 -> 19 | B43: 434.8 | C43: =(B43/$B$14)*$B$13 -> 1.1899288 | D43: =D42+L42 -> 27.646912 | E43: 9.3 | F43: =F42-C43 -> 23.528462 | G43: 1.72 | H43: =(F43/448.8)/(3.14*((G43/12)^2)/4) -> 3.2506981 | I43: =IF(G43>5,$B$6,IF(5>=G43>1.5,$B$7,IF(1.5>G43,$B$8,0))) -> 145 | J43: =(1050*((F43/I43)^1.852)*(E43/100)*(G43^-4.87))/2.31 -> 0.10384233 | K43: =E43*$B$11 -> 0.26397956 | L43: =K43-J43 -> 0.16013723
A44: =A43+1 -> 20 | B44: 434.2 | C44: =(B44/$B$14)*$B$13 -> 1.1882868 | D44: =D43+L43 -> 27.807049 | E44: 9.3 | F44: =F43-C44 -> 22.340175 | G44: 1.72 | H44: =(F44/448.8)/(3.14*((G44/12)^2)/4) -> 3.0865241 | I44: =IF(G44>5,$B$6,IF(5>=G44>1.5,$B$7,IF(1.5>G44,$B$8,0))) -> 145 | J44: =(1050*((F44/I44)^1.852)*(E44/100)*(G44^-4.87))/2.31 -> 0.094339056 | K44: =E44*$B$11 -> 0.26397956 | L44: =K44-J44 -> 0.16964051
A45: =A44+1 -> 21 | B45: 433.7 | C45: =(B45/$B$14)*$B$13 -> 1.1869184 | D45: =D44+L44 -> 27.97669 | E45: 9.3 | F45: =F44-C45 -> 21.153257 | G45: 1.72 | H45: =(F45/448.8)/(3.14*((G45/12)^2)/4) -> 2.9225391 | I45: =IF(G45>5,$B$6,IF(5>=G45>1.5,$B$7,IF(1.5>G45,$B$8,0))) -> 145 | J45: =(1050*((F45/I45)^1.852)*(E45/100)*(G45^-4.87))/2.31 -> 0.085267168 | K45: =E45*$B$11 -> 0.26397956 | L45: =K45-J45 -> 0.17871239
A46: =A45+1 -> 22 | B46: 433.1 | C46: =(B46/$B$14)*$B$13 -> 1.1852764 | D46: =D45+L45 -> 28.155402 | E46: 9.3 | F46: =F45-C46 -> 19.96798 | G46: 1.72 | H46: =(F46/448.8)/(3.14*((G46/12)^2)/4) -> 2.758781 | I46: =IF(G46>5,$B$6,IF(5>=G46>1.5,$B$7,IF(1.5>G46,$B$8,0))) -> 145 | J46: =(1050*((F46/I46)^1.852)*(E46/100)*(G46^-4.87))/2.31 -> 0.076630563 | K46: =E46*$B$11 -> 0.26397956 | L46: =K46-J46 -> 0.187349
A47: =A46+1 -> 23 | B47: 432.6 | C47: =(B47/$B$14)*$B$13 -> 1.183908 | D47: =D46+L46 -> 28.342751 | E47: 9.3 | F47: =F46-C47 -> 18.784072 | G47: 1.72 | H47: =(F47/448.8)/(3.14*((G47/12)^2)/4) -> 2.595212 | I47: =IF(G47>5,$B$6,IF(5>=G47>1.5,$B$7,IF(1.5>G47,$B$8,0))) -> 145 | J47: =(1050*((F47/I47)^1.852)*(E47/100)*(G47^-4.87))/2.31 -> 0.068429254 | K47: =E47*$B$11 -> 0.26397956 | L47: =K47-J47 -> 0.19555031
...

Sheet Block 3
A1: Block 3
A3: Sub-mainline Sizing and Pressure
B9: 150 | C9: C-value for PVC ID > 5"
B10: 145 | C10: C-value for PVC 1.5" < = ID < = 5"
B11: 140 | C11: C-value for PVC < 1.5"
B12: 0 | C12: feet, Total Elevation Drop
B13: 813.9 | C13: feet, Length of Sub-mainline
B14: =B12/B13 -> 0 | C14: ft/ft, Change in Elevation
B15: 0.5 | C15: GPH/emitter
B16: =B15/60 -> 0.0083333333 | C16: GPM/emitter
B17: 3.045 | C17: ft, emitter spacing
B20: Chg. Elev = Length * ft/ft (elevation change worst case)
B21: Chg. P = Chg. Elev + Hf
A23: Section A
A24: Row | B24: Row Length ft | C24: GPM per Row | D24: Pressure PSI | E24: Length ft | F24: GPM | G24: Pipe ID, in | H24: Velocity, ft/sec | I24: C-Value | J24: Hf (psi) | K24: Chg. Elev (psi) | L24: Chg. P (psi)
A25: Inlet | B25: 0 | C25: 0 | D25: 25 | E25: 0 | F25: 52.5 | G25: 2.193 | H25: =(F25/448.8)/(3.14*((G25/12)^2)/4) -> 4.4619225 | I25: =IF(G25>5,$B$9,IF(5>=G25>1.5,$B$10,IF(1.5>G25,$B$11,0))) -> 145 | J25: =(1050*((F25/I25)^1.852)*(E25/100)*(G25^-4.87))/2.31 -> 0 | K25: =E25*$B$14 -> 0 | L25: =K25-J25 -> 0
A26: 1 | B26: 422.7 | C26: =(B26/$B$17)*$B$16 -> 1.1568144 | D26: =D25+L25 -> 25 | E26: 2.3 | F26: =F25-C26 -> 51.343186 | G26: 2.193 | H26: =(F26/448.8)/(3.14*((G26/12)^2)/4) -> 4.363606 | I26: =IF(G26>5,$B$9,IF(5>=G26>1.5,$B$10,IF(1.5>G26,$B$11,0))) -> 145 | J26: =(1050*((F26/I26)^1.852)*(E26/100)*(G26^-4.87))/2.31 -> 0.033373953 | K26: =E26*$B$14 -> 0 | L26: =K26-J26 -> -0.033373953
A27: =A26+1 -> 2 | B27: 422.2 | C27: =(B27/$B$17)*$B$16 -> 1.1554461 | D27: =D26+L26 -> 24.966626 | E27: 9.3 | F27: =F26-C27 -> 50.187739 | G27: 2.193 | H27: =(F27/448.8)/(3.14*((G27/12)^2)/4) -> 4.2654058 | I27: =IF(G27>5,$B$9,IF(5>=G27>1.5,$B$10,IF(1.5>G27,$B$11,0))) -> 145 | J27: =(1050*((F27/I27)^1.852)*(E27/100)*(G27^-4.87))/2.31 -> 0.1293765 | K27: =E27*$B$14 -> 0 | L27: =K27-J27 -> -0.1293765
A28: =A27+1 -> 3 | B28: 421.6 | C28: =(B28/$B$17)*$B$16 -> 1.1538041 | D28: =D27+L27 -> 24.83725 | E28: 9.3 | F28: =F27-C28 -> 49.033935 | G28: 2.193 | H28: =(F28/448.8)/(3.14*((G28/12)^2)/4) -> 4.1673452 | I28: =IF(G28>5,$B$9,IF(5>=G28>1.5,$B$10,IF(1.5>G28,$B$11,0))) -> 145 | J28: =(1050*((F28/I28)^1.852)*(E28/100)*(G28^-4.87))/2.31 -> 0.12392205 | K28: =E28*$B$14 -> 0 | L28: =K28-J28 -> -0.12392205
A29: =A28+1 -> 4 | B29: 421.1 | C29: =(B29/$B$17)*$B$16 -> 1.1524357 | D29: =D28+L28 -> 24.713327 | E29: 9.3 | F29: =F28-C29 -> 47.8815 | G29: 2.193 | H29: =(F29/448.8)/(3.14*((G29/12)^2)/4) -> 4.0694008 | I29: =IF(G29>5,$B$9,IF(5>=G29>1.5,$B$10,IF(1.5>G29,$B$11,0))) -> 145 | J29: =(1050*((F29/I29)^1.852)*(E29/100)*(G29^-4.87))/2.31 -> 0.11858213 | K29: =E29*$B$14 -> 0 | L29: =K29-J29 -> -0.11858213
A30: =A29+1 -> 5 | B30: 420.5 | C30: =(B30/$B$17)*$B$16 -> 1.1507937 | D30: =D29+L29 -> 24.594745 | E30: 9.3 | F30: =F29-C30 -> 46.730706 | G30: 2.193 | H30: =(F30/448.8)/(3.14*((G30/12)^2)/4) -> 3.971596 | I30: =IF(G30>5,$B$9,IF(5>=G30>1.5,$B$10,IF(1.5>G30,$B$11,0))) -> 145 | J30: =(1050*((F30/I30)^1.852)*(E30/100)*(G30^-4.87))/2.31 -> 0.11335799 | K30: =E30*$B$14 -> 0 | L30: =K30-J30 -> -0.11335799
A31: =A30+1 -> 6 | B31: 420 | C31: =(B31/$B$17)*$B$16 -> 1.1494253 | D31: =D30+L30 -> 24.481387 | E31: 9.3 | F31: =F30-C31 -> 45.581281 | G31: 2.193 | H31: =(F31/448.8)/(3.14*((G31/12)^2)/4) -> 3.8739075 | I31: =IF(G31>5,$B$9,IF(5>=G31>1.5,$B$10,IF(1.5>G31,$B$11,0))) -> 145 | J31: =(1050*((F31/I31)^1.852)*(E31/100)*(G31^-4.87))/2.31 -> 0.10824834 | K31: =E31*$B$14 -> 0 | L31: =K31-J31 -> -0.10824834
A32: =A31+1 -> 7 | B32: 419.4 | C32: =(B32/$B$17)*$B$16 -> 1.1477833 | D32: =D31+L31 -> 24.373139 | E32: 9.3 | F32: =F31-C32 -> 44.433498 | G32: 2.193 | H32: =(F32/448.8)/(3.14*((G32/12)^2)/4) -> 3.7763586 | I32: =IF(G32>5,$B$9,IF(5>=G32>1.5,$B$10,IF(1.5>G32,$B$11,0))) -> 145 | J32: =(1050*((F32/I32)^1.852)*(E32/100)*(G32^-4.87))/2.31 -> 0.10325437 | K32: =E32*$B$14 -> 0 | L32: =K32-J32 -> -0.10325437
A33: =A32+1 -> 8 | B33: 418.9 | C33: =(B33/$B$17)*$B$16 -> 1.1464149 | D33: =D32+L32 -> 24.269885 | E33: 9.3 | F33: =F32-C33 -> 43.287083 | G33: 2.193 | H33: =(F33/448.8)/(3.14*((G33/12)^2)/4) -> 3.6789259 | I33: =IF(G33>5,$B$9,IF(5>=G33>1.5,$B$10,IF(1.5>G33,$B$11,0))) -> 145 | J33: =(1050*((F33/I33)^1.852)*(E33/100)*(G33^-4.87))/2.31 -> 0.098374875 | K33: =E33*$B$14 -> 0 | L33: =K33-J33 -> -0.098374875
A34: =A33+1 -> 9 | B34: 418.3 | C34: =(B34/$B$17)*$B$16 -> 1.1447729 | D34: =D33+L33 -> 24.17151 | E34: 9.3 | F34: =F33-C34 -> 42.14231 | G34: 2.193 | H34: =(F34/448.8)/(3.14*((G34/12)^2)/4) -> 3.5816328 | I34: =IF(G34>5,$B$9,IF(5>=G34>1.5,$B$10,IF(1.5>G34,$B$11,0))) -> 145 | J34: =(1050*((F34/I34)^1.852)*(E34/100)*(G34^-4.87))/2.31 -> 0.093611014 | K34: =E34*$B$14 -> 0 | L34: =K34-J34 -> -0.093611014
A35: =A34+1 -> 10 | B35: 417.8 | C35: =(B35/$B$17)*$B$16 -> 1.1434045 | D35: =D34+L34 -> 24.077899 | E35: 9.3 | F35: =F34-C35 -> 40.998905 | G35: 2.193 | H35: =(F35/448.8)/(3.14*((G35/12)^2)/4) -> 3.484456 | I35: =IF(G35>5,$B$9,IF(5>=G35>1.5,$B$10,IF(1.5>G35,$B$11,0))) -> 145 | J35: =(1050*((F35/I35)^1.852)*(E35/100)*(G35^-4.87))/2.31 -> 0.088961648 | K35: =E35*$B$14 -> 0 | L35: =K35-J35 -> -0.088961648
A36: =A35+1 -> 11 | B36: 417.2 | C36: =(B36/$B$17)*$B$16 -> 1.1417625 | D36: =D35+L35 -> 23.988937 | E36: 9.3 | F36: =F35-C36 -> 39.857143 | G36: 2.193 | H36: =(F36/448.8)/(3.14*((G36/12)^2)/4) -> 3.3874187 | I36: =IF(G36>5,$B$9,IF(5>=G36>1.5,$B$10,IF(1.5>G36,$B$11,0))) -> 145 | J36: =(1050*((F36/I36)^1.852)*(E36/100)*(G36^-4.87))/2.31 -> 0.084427904 | K36: =E36*$B$14 -> 0 | L36: =K36-J36 -> -0.084427904
A37: =A36+1 -> 12 | B37: 416.7 | C37: =(B37/$B$17)*$B$16 -> 1.1403941 | D37: =D36+L36 -> 23.904509 | E37: 9.3 | F37: =F36-C37 -> 38.716749 | G37: 2.193 | H37: =(F37/448.8)/(3.14*((G37/12)^2)/4) -> 3.2904978 | I37: =IF(G37>5,$B$9,IF(5>=G37>1.5,$B$10,IF(1.5>G37,$B$11,0))) -> 145 | J37: =(1050*((F37/I37)^1.852)*(E37/100)*(G37^-4.87))/2.31 -> 0.080008719 | K37: =E37*$B$14 -> 0 | L37: =K37-J37 -> -0.080008719
A38: =A37+1 -> 13 | B38: 416.1 | C38: =(B38/$B$17)*$B$16 -> 1.1387521 | D38: =D37+L37 -> 23.824501 | E38: 9.3 | F38: =F37-C38 -> 37.577997 | G38: 2.193 | H38: =(F38/448.8)/(3.14*((G38/12)^2)/4) -> 3.1937164 | I38: =IF(G38>5,$B$9,IF(5>=G38>1.5,$B$10,IF(1.5>G38,$B$11,0))) -> 145 | J38: =(1050*((F38/I38)^1.852)*(E38/100)*(G38^-4.87))/2.31 -> 0.075705192 | K38: =E38*$B$14 -> 0 | L38: =K38-J38 -> -0.075705192
A39: Section B
A40: =A38+1 -> 14 | B40: 435.9 | C40: =(B40/$B$17)*$B$16 -> 1.1929392 | D40: =D38+L38 -> 23.748795 | E40: 26.9 | F40: =F38-C40 -> 36.385057 | G40: 1.72 | H40: =(F40/448.8)/(3.14*((G40/12)^2)/4) -> 5.0269684 | I40: =IF(G40>5,$B$9,IF(5>=G40>1.5,$B$10,IF(1.5>G40,$B$11,0))) -> 145 | J40: =(1050*((F40/I40)^1.852)*(E40/100)*(G40^-4.87))/2.31 -> 0.67341384 | K40: =E40*$B$14 -> 0 | L40: =K40-J40 -> -0.67341384
A41: =A40+1 -> 15 | B41: 459.2 | C41: =(B41/$B$17)*$B$16 -> 1.256705 | D41: =D40+L40 -> 23.075381 | E41: 29.9 | F41: =F40-C41 -> 35.128352 | G41: 1.72 | H41: =(F41/448.8)/(3.14*((G41/12)^2)/4) -> 4.8533418 | I41: =IF(G41>5,$B$9,IF(5>=G41>1.5,$B$10,IF(1.5>G41,$B$11,0))) -> 145 | J41: =(1050*((F41/I41)^1.852)*(E41/100)*(G41^-4.87))/2.31 -> 0.70134167 | K41: =E41*$B$14 -> 0 | L41: =K41-J41 -> -0.70134167
A42: =A41+1 -> 16 | B42: 482.4 | C42: =(B42/$B$17)*$B$16 -> 1.320197 | D42: =D41+L41 -> 22.37404 | E42: 29.9 | F42: =F41-C42 -> 33.808155 | G42: 1.72 | H42: =(F42/448.8)/(3.14*((G42/12)^2)/4) -> 4.670943 | I42: =IF(G42>5,$B$9,IF(5>=G42>1.5,$B$10,IF(1.5>G42,$B$11,0))) -> 145 | J42: =(1050*((F42/I42)^1.852)*(E42/100)*(G42^-4.87))/2.31 -> 0.65330985 | K42: =E42*$B$14 -> 0 | L42: =K42-J42 -> -0.65330985
A43: =A42+1 -> 17 | B43: 505.7 | C43: =(B43/$B$17)*$B$16 -> 1.3839628 | D43: =D42+L42 -> 21.72073 | E43: 29.9 | F43: =F42-C43 -> 32.424193 | G43: 1.72 | H43: =(F43/448.8)/(3.14*((G43/12)^2)/4) -> 4.4797344 | I43: =IF(G43>5,$B$9,IF(5>=G43>1.5,$B$10,IF(1.5>G43,$B$11,0))) -> 145 | J43: =(1050*((F43/I43)^1.852)*(E43/100)*(G43^-4.87))/2.31 -> 0.60464593 | K43: =E43*$B$14 -> 0 | L43: =K43-J43 -> -0.60464593
A44: =A43+1 -> 18 | B44: 528.9 | C44: =(B44/$B$17)*$B$16 -> 1.4474548 | D44: =D43+L43 -> 21.116084 | E44: 29.9 | F44: =F43-C44 -> 30.976738 | G44: 1.72 | H44: =(F44/448.8)/(3.14*((G44/12)^2)/4) -> 4.2797537 | I44: =IF(G44>5,$B$9,IF(5>=G44>1.5,$B$10,IF(1.5>G44,$B$11,0))) -> 145 | J44: =(1050*((F44/I44)^1.852)*(E44/100)*(G44^-4.87))/2.31 -> 0.5556093 | K44: =E44*$B$14 -> 0 | L44: =K44-J44 -> -0.5556093
A45: =A44+1 -> 19 | B45: 552.2 | C45: =(B45/$B$17)*$B$16 -> 1.5112206 | D45: =D44+L44 -> 20.560475 | E45: 29.9 | F45: =F44-C45 -> 29.465517 | G45: 1.72 | H45: =(F45/448.8)/(3.14*((G45/12)^2)/4) -> 4.0709631 | I45: =IF(G45>5,$B$9,IF(5>=G45>1.5,$B$10,IF(1.5>G45,$B$11,0))) -> 145 | J45: =(1050*((F45/I45)^1.852)*(E45/100)*(G45^-4.87))/2.31 -> 0.50645526 | K45: =E45*$B$14 -> 0 | L45: =K45-J45 -> -0.50645526
A46: =A45+1 -> 20 | B46: 575.5 | C46: =(B46/$B$17)*$B$16 -> 1.5749863 | D46: =D45+L45 -> 20.054019 | E46: 29.9 | F46: =F45-C46 -> 27.890531 | G46: 1.72 | H46: =(F46/448.8)/(3.14*((G46/12)^2)/4) -> 3.8533626 | I46: =IF(G46>5,$B$9,IF(5>=G46>1.5,$B$10,IF(1.5>G46,$B$11,0))) -> 145 | J46: =(1050*((F46/I46)^1.852)*(E46/100)*(G46^-4.87))/2.31 -> 0.45746449 | K46: =E46*$B$14 -> 0 | L46: =K46-J46 -> -0.45746449
A47: =A46+1 -> 21 | B47: 598.7 | C47: =(B47/$B$17)*$B$16 -> 1.6384784 | D47: =D46+L46 -> 19.596555 | E47: 29.9 | F47: =F46-C47 -> 26.252053 | G47: 1.72 | H47: =(F47/448.8)/(3.14*((G47/12)^2)/4) -> 3.62699 | I47: =IF(G47>5,$B$9,IF(5>=G47>1.5,$B$10,IF(1.5>G47,$B$11,0))) -> 145 | J47: =(1050*((F47/I47)^1.852)*(E47/100)*(G47^-4.87))/2.31 -> 0.40894208 | K47: =E47*$B$14 -> 0 | L47: =K47-J47 -> -0.40894208
A48: Section C
A49: =A47+1 -> 22 | B49: 62.2 | C49: =(B49/$B$17)*$B$16 -> 0.17022441 | D49: =D47+L47 -> 19.187613 | E49: 265.9 | F49: =F47-C49 -> 26.081828 | G49: 1.72 | H49: =(F49/448.8)/(3.14*((G49/12)^2)/4) -> 3.6034718 | I49: =IF(G49>5,$B$9,IF(5>=G49>1.5,$B$10,IF(1.5>G49,$B$11,0))) -> 145 | J49: =(1050*((F49/I49)^1.852)*(E49/100)*(G49^-4.87))/2.31 -> 3.5931604 | K49: =E49*$B$14 -> 0 | L49: =K49-J49 -> -3.5931604
...

Sheet Block 4
A1: Block 4
A3: Sub-mainline Sizing and Pressure
B5: 150 | C5: C-value for PVC ID > 5"
B6: 145 | C6: C-value for PVC 1.5" < = ID < = 5"
B7: 140 | C7: C-value for PVC < 1.5"
B8: 10 | C8: feet, Total Elevation Drop
B9: 352.3 | C9: feet, Length of Sub-mainline
B10: =B8/B9 -> 0.028384899 | C10: ft/ft, Change in Elevation
B11: 0.5 | C11: GPH/emitter
B12: =B11/60 -> 0.0083333333 | C12: GPM/emitter
B13: 3.045 | C13: ft, emitter spacing
B16: Chg. Elev = Length * ft/ft (elevation change worst case)
B17: Chg. P = Chg. Elev + Hf
A20: Section A
A21: Row | B21: Row Length ft | C21: GPM per Row | D21: Pressure PSI | E21: Length ft | F21: GPM | G21: Pipe ID, in | H21: Velocity, ft/sec | I21: C-Value | J21: Hf (psi) | K21: Chg. Elev (psi) | L21: Chg. P (psi)
A22: Inlet | B22: 0 | C22: 0 | D22: 25 | E22: 0 | F22: 49.5 | G22: 2.193 | H22: =(F22/448.8)/(3.14*((G22/12)^2)/4) -> 4.2069555 | I22: =IF(G22>5,$B$5,IF(5>=G22>1.5,$B$6,IF(1.5>G22,$B$7,0))) -> 145 | J22: =(1050*((F22/I22)^1.852)*(E22/100)*(G22^-4.87))/2.31 -> 0 | K22: =E22*$B$10 -> 0 | L22: =K22-J22 -> 0
A23: 1 | B23: 718.8 | C23: =(B23/$B$13)*$B$12 -> 1.9671593 | D23: =D22+L22 -> 25 | E23: 0.6 | F23: =F22-C23 -> 47.532841 | G23: 2.193 | H23: =(F23/448.8)/(3.14*((G23/12)^2)/4) -> 4.0397686 | I23: =IF(G23>5,$B$5,IF(5>=G23>1.5,$B$6,IF(1.5>G23,$B$7,0))) -> 145 | J23: =(1050*((F23/I23)^1.852)*(E23/100)*(G23^-4.87))/2.31 -> 0.0075476083 | K23: =E23*$B$10 -> 0.01703094 | L23: =K23-J23 -> 0.0094833312
A24: =A23+1 -> 2 | B24: 703.5 | C24: =(B24/$B$13)*$B$12 -> 1.9252874 | D24: =D23+L23 -> 25.009483 | E24: 7.8 | F24: =F23-C24 -> 45.607553 | G24: 2.193 | H24: =(F24/448.8)/(3.14*((G24/12)^2)/4) -> 3.8761404 | I24: =IF(G24>5,$B$5,IF(5>=G24>1.5,$B$6,IF(1.5>G24,$B$7,0))) -> 145 | J24: =(1050*((F24/I24)^1.852)*(E24/100)*(G24^-4.87))/2.31 -> 0.090885867 | K24: =E24*$B$10 -> 0.22140221 | L24: =K24-J24 -> 0.13051635
A25: =A24+1 -> 3 | B25: 688.3 | C25: =(B25/$B$13)*$B$12 -> 1.8836891 | D25: =D24+L24 -> 25.14 | E25: 7.8 | F25: =F24-C25 -> 43.723864 | G25: 2.193 | H25: =(F25/448.8)/(3.14*((G25/12)^2)/4) -> 3.7160475 | I25: =IF(G25>5,$B$5,IF(5>=G25>1.5,$B$6,IF(1.5>G25,$B$7,0))) -> 145 | J25: =(1050*((F25/I25)^1.852)*(E25/100)*(G25^-4.87))/2.31 -> 0.084056437 | K25: =E25*$B$10 -> 0.22140221 | L25: =K25-J25 -> 0.13734578
A26: =A25+1 -> 4 | B26: 673 | C26: =(B26/$B$13)*$B$12 -> 1.8418172 | D26: =D25+L25 -> 25.277345 | E26: 7.8 | F26: =F25-C26 -> 41.882047 | G26: 2.193 | H26: =(F26/448.8)/(3.14*((G26/12)^2)/4) -> 3.5595133 | I26: =IF(G26>5,$B$5,IF(5>=G26>1.5,$B$6,IF(1.5>G26,$B$7,0))) -> 145 | J26: =(1050*((F26/I26)^1.852)*(E26/100)*(G26^-4.87))/2.31 -> 0.077616833 | K26: =E26*$B$10 -> 0.22140221 | L26: =K26-J26 -> 0.14378538
A27: =A26+1 -> 5 | B27: 657.7 | C27: =(B27/$B$13)*$B$12 -> 1.7999453 | D27: =D26+L26 -> 25.421131 | E27: 7.8 | F27: =F26-C27 -> 40.082102 | G27: 2.193 | H27: =(F27/448.8)/(3.14*((G27/12)^2)/4) -> 3.4065378 | I27: =IF(G27>5,$B$5,IF(5>=G27>1.5,$B$6,IF(1.5>G27,$B$7,0))) -> 145 | J27: =(1050*((F27/I27)^1.852)*(E27/100)*(G27^-4.87))/2.31 -> 0.071552456 | K27: =E27*$B$10 -> 0.22140221 | L27: =K27-J27 -> 0.14984976
A28: =A27+1 -> 6 | B28: 642.5 | C28: =(B28/$B$13)*$B$12 -> 1.758347 | D28: =D27+L27 -> 25.570981 | E28: 7.8 | F28: =F27-C28 -> 38.323755 | G28: 2.193 | H28: =(F28/448.8)/(3.14*((G28/12)^2)/4) -> 3.2570976 | I28: =IF(G28>5,$B$5,IF(5>=G28>1.5,$B$6,IF(1.5>G28,$B$7,0))) -> 145 | J28: =(1050*((F28/I28)^1.852)*(E28/100)*(G28^-4.87))/2.31 -> 0.065848074 | K28: =E28*$B$10 -> 0.22140221 | L28: =K28-J28 -> 0.15555414
A29: =A28+1 -> 7 | B29: 627.2 | C29: =(B29/$B$13)*$B$12 -> 1.7164751 | D29: =D28+L28 -> 25.726535 | E29: 7.8 | F29: =F28-C29 -> 36.60728 | G29: 2.193 | H29: =(F29/448.8)/(3.14*((G29/12)^2)/4) -> 3.1112161 | I29: =IF(G29>5,$B$5,IF(5>=G29>1.5,$B$6,IF(1.5>G29,$B$7,0))) -> 145 | J29: =(1050*((F29/I29)^1.852)*(E29/100)*(G29^-4.87))/2.31 -> 0.0604905 | K29: =E29*$B$10 -> 0.22140221 | L29: =K29-J29 -> 0.16091171
A30: =A29+1 -> 8 | B30: 611.9 | C30: =(B30/$B$13)*$B$12 -> 1.6746032 | D30: =D29+L29 -> 25.887446 | E30: 7.8 | F30: =F29-C30 -> 34.932677 | G30: 2.193 | H30: =(F30/448.8)/(3.14*((G30/12)^2)/4) -> 2.9688933 | I30: =IF(G30>5,$B$5,IF(5>=G30>1.5,$B$6,IF(1.5>G30,$B$7,0))) -> 145 | J30: =(1050*((F30/I30)^1.852)*(E30/100)*(G30^-4.87))/2.31 -> 0.055465848 | K30: =E30*$B$10 -> 0.22140221 | L30: =K30-J30 -> 0.16593637
A31: =A30+1 -> 9 | B31: 596.7 | C31: =(B31/$B$13)*$B$12 -> 1.6330049 | D31: =D30+L30 -> 26.053383 | E31: 7.8 | F31: =F30-C31 -> 33.299672 | G31: 2.193 | H31: =(F31/448.8)/(3.14*((G31/12)^2)/4) -> 2.8301058 | I31: =IF(G31>5,$B$5,IF(5>=G31>1.5,$B$6,IF(1.5>G31,$B$7,0))) -> 145 | J31: =(1050*((F31/I31)^1.852)*(E31/100)*(G31^-4.87))/2.31 -> 0.050759698 | K31: =E31*$B$10 -> 0.22140221 | L31: =K31-J31 -> 0.17064252
A32: =A31+1 -> 10 | B32: 581.4 | C32: =(B32/$B$13)*$B$12 -> 1.591133 | D32: =D31+L31 -> 26.224025 | E32: 7.8 | F32: =F31-C32 -> 31.708539 | G32: 2.193 | H32: =(F32/448.8)/(3.14*((G32/12)^2)/4) -> 2.694877 | I32: =IF(G32>5,$B$5,IF(5>=G32>1.5,$B$6,IF(1.5>G32,$B$7,0))) -> 145 | J32: =(1050*((F32/I32)^1.852)*(E32/100)*(G32^-4.87))/2.31 -> 0.046359486 | K32: =E32*$B$10 -> 0.22140221 | L32: =K32-J32 -> 0.17504273
A33: =A32+1 -> 11 | B33: 566.1 | C33: =(B33/$B$13)*$B$12 -> 1.5492611 | D33: =D32+L32 -> 26.399068 | E33: 7.8 | F33: =F32-C33 -> 30.159278 | G33: 1.72 | H33: =(F33/448.8)/(3.14*((G33/12)^2)/4) -> 4.1668132 | I33: =IF(G33>5,$B$5,IF(5>=G33>1.5,$B$6,IF(1.5>G33,$B$7,0))) -> 145 | J33: =(1050*((F33/I33)^1.852)*(E33/100)*(G33^-4.87))/2.31 -> 0.13793752 | K33: =E33*$B$10 -> 0.22140221 | L33: =K33-J33 -> 0.083464694
A34: =A33+1 -> 12 | B34: 550.9 | C34: =(B34/$B$13)*$B$12 -> 1.5076628 | D34: =D33+L33 -> 26.482533 | E34: 7.8 | F34: =F33-C34 -> 28.651615 | G34: 1.72 | H34: =(F34/448.8)/(3.14*((G34/12)^2)/4) -> 3.9585141 | I34: =IF(G34>5,$B$5,IF(5>=G34>1.5,$B$6,IF(1.5>G34,$B$7,0))) -> 145 | J34: =(1050*((F34/I34)^1.852)*(E34/100)*(G34^-4.87))/2.31 -> 0.12543969 | K34: =E34*$B$10 -> 0.22140221 | L34: =K34-J34 -> 0.095962521
A35: =A34+1 -> 13 | B35: 535.6 | C35: =(B35/$B$13)*$B$12 -> 1.4657909 | D35: =D34+L34 -> 26.578495 | E35: 7.8 | F35: =F34-C35 -> 27.185824 | G35: 1.72 | H35: =(F35/448.8)/(3.14*((G35/12)^2)/4) -> 3.7560001 | I35: =IF(G35>5,$B$5,IF(5>=G35>1.5,$B$6,IF(1.5>G35,$B$7,0))) -> 145 | J35: =(1050*((F35/I35)^1.852)*(E35/100)*(G35^-4.87))/2.31 -> 0.11381438 | K35: =E35*$B$10 -> 0.22140221 | L35: =K35-J35 -> 0.10758783
... A40: =A39+1 -> 18 | B40: 489.7 | C40: =(B40/$B$13)*$B$12 -> 1.3401752 | D40: =D39+L39 -> 27.217739 | E40: 7.8 | F40: =F39-C40 -> 20.293103 | G40: 1.72 | H40: =(F40/448.8)/(3.14*((G40/12)^2)/4) -> 2.8037001 | I40: =IF(G40>5,$B$5,IF(5>=G40>1.5,$B$6,IF(1.5>G40,$B$7,0))) -> 145 | J40: =(1050*((F40/I40)^1.852)*(E40/100)*(G40^-4.87))/2.31 -> 0.066222292 | K40: =E40*$B$10 -> 0.22140221 | L40: =K40-J40 -> 0.15517992
A41: Section B
A42: =A40+1 -> 19 | B42: 480.5 | C42: =(B42/$B$13)*$B$12 -> 1.3149973 | D42: =D40+L40 -> 27.372918 | E42: 8 | F42: =F40-C42 -> 18.978106 | G42: 1.72 | H42: =(F42/448.8)/(3.14*((G42/12)^2)/4) -> 2.6220198 | I42: =IF(G42>5,$B$5,IF(5>=G42>1.5,$B$6,IF(1.5>G42,$B$7,0))) -> 145 | J42: =(1050*((F42/I42)^1.852)*(E42/100)*(G42^-4.87))/2.31 -> 0.05999493 | K42: =E42*$B$10 -> 0.22707919 | L42: =K42-J42 -> 0.16708426
A43: =A42+1 -> 20 | B43: 471.2 | C43: =(B43/$B$13)*$B$12 -> 1.2895457 | D43: =D42+L42 -> 27.540003 | E43: 8 | F43: =F42-C43 -> 17.68856 | G43: 1.72 | H43: =(F43/448.8)/(3.14*((G43/12)^2)/4) -> 2.4438558 | I43: =IF(G43>5,$B$5,IF(5>=G43>1.5,$B$6,IF(1.5>G43,$B$7,0))) -> 145 | J43: =(1050*((F43/I43)^1.852)*(E43/100)*(G43^-4.87))/2.31 -> 0.052664349 | K43: =E43*$B$10 -> 0.22707919 | L43: =K43-J43 -> 0.17441484
A44: =A43+1 -> 21 | B44: 462 | C44: =(B44/$B$13)*$B$12 -> 1.2643678 | D44: =D43+L43 -> 27.714418 | E44: 8 | F44: =F43-C44 -> 16.424193 | G44: 1.72 | H44: =(F44/448.8)/(3.14*((G44/12)^2)/4) -> 2.2691705 | I44: =IF(G44>5,$B$5,IF(5>=G44>1.5,$B$6,IF(1.5>G44,$B$7,0))) -> 145 | J44: =(1050*((F44/I44)^1.852)*(E44/100)*(G44^-4.87))/2.31 -> 0.045905704 | K44: =E44*$B$10 -> 0.22707919 | L44: =K44-J44 -> 0.18117349
A45: =A44+1 -> 22 | B45: 452.7 | C45: =(B45/$B$13)*$B$12 -> 1.2389163 | D45: =D44+L44 -> 27.895591 | E45: 8 | F45: =F44-C45 -> 15.185276 | G45: 1.72 | H45: =(F45/448.8)/(3.14*((G45/12)^2)/4) -> 2.0980015 | I45: =IF(G45>5,$B$5,IF(5>=G45>1.5,$B$6,IF(1.5>G45,$B$7,0))) -> 145 | J45: =(1050*((F45/I45)^1.852)*(E45/100)*(G45^-4.87))/2.31 -> 0.039699503 | K45: =E45*$B$10 -> 0.22707919 | L45: =K45-J45 -> 0.18737969
A46: =A45+1 -> 23 | B46: 443.4 | C46: =(B46/$B$13)*$B$12 -> 1.2134647 | D46: =D45+L45 -> 28.082971 | E46: 8 | F46: =F45-C46 -> 13.971812 | G46: 1.72 | H46: =(F46/448.8)/(3.14*((G46/12)^2)/4) -> 1.9303489 | I46: =IF(G46>5,$B$5,IF(5>=G46>1.5,$B$6,IF(1.5>G46,$B$7,0))) -> 145 | J46: =(1050*((F46/I46)^1.852)*(E46/100)*(G46^-4.87))/2.31 -> 0.034025011 | K46: =E46*$B$10 -> 0.22707919 | L46: =K46-J46 -> 0.19305418
A47: =A46+1 -> 24 | B47: 434.1 | C47: =(B47/$B$13)*$B$12 -> 1.1880131 | D47: =D46+L46 -> 28.276025 | E47: 8 | F47: =F46-C47 -> 12.783799 | G47: 1.72 | H47: =(F47/448.8)/(3.14*((G47/12)^2)/4) -> 1.7662127 | I47: =IF(G47>5,$B$5,IF(5>=G47>1.5,$B$6,IF(1.5>G47,$B$7,0))) -> 145 | J47: =(1050*((F47/I47)^1.852)*(E47/100)*(G47^-4.87))/2.31 -> 0.028861866 | K47: =E47*$B$10 -> 0.22707919 | L47: =K47-J47 -> 0.19821733
A48: =A47+1 -> 25 | B48: 424.8 | C48: =(B48/$B$13)*$B$12 -> 1.1625616 | D48: =D47+L47 -> 28.474242 | E48: 8 | F48: =F47-C48 -> 11.621237 | G48: 1.72 | H48: =(F48/448.8)/(3.14*((G48/12)^2)/4) -> 1.6055929 | I48: =IF(G48>5,$B$5,IF(5>=G48>1.5,$B$6,IF(1.5>G48,$B$7,0))) -> 145 | J48: =(1050*((F48/I48)^1.852)*(E48/100)*(G48^-4.87))/2.31 -> 0.024190096 | K48: =E48*$B$10 -> 0.22707919 | L48: =K48-J48 -> 0.2028891
A49: =A48+1 -> 26 | B49: 415.6 | C49: =(B49/$B$13)*$B$12 -> 1.1373837 | D49: =D48+L48 -> 28.677131 | E49: 8 | F49: =F48-C49 -> 10.483853 | G49: 1.72 | H49: =(F49/448.8)/(3.14*((G49/12)^2)/4) -> 1.4484517 | I49: =IF(G49>5,$B$5,IF(5>=G49>1.5,$B$6,IF(1.5>G49,$B$7,0))) -> 145 | J49: =(1050*((F49/I49)^1.852)*(E49/100)*(G49^-4.87))/2.31 -> 0.019989181 | K49: =E49*$B$10 -> 0.22707919 | L49: =K49-J49 -> 0.20709001
A50: =A49+1 -> 27 | B50: 406.3 | C50: =(B50/$B$13)*$B$12 -> 1.1119321 | D50: =D49+L49 -> 28.884221 | E50: 8 | F50: =F49-C50 -> 9.3719212 | G50: 1.72 | H50: =(F50/448.8)/(3.14*((G50/12)^2)/4) -> 1.2948269 | I50: =IF(G50>5,$B$5,IF(5>=G50>1.5,$B$6,IF(1.5>G50,$B$7,0))) -> 145 | J50: =(1050*((F50/I50)^1.852)*(E50/100)*(G50^-4.87))/2.31 -> 0.016241153 | K50: =E50*$B$10 -> 0.22707919 | L50: =K50-J50 -> 0.21083804
...

Sheet Block 5
A1: Block 5
A3: Sub-mainline Sizing and Pressure
B5: 150 | C5: C-value for PVC ID > 5"
B6: 145 | C6: C-value for PVC 1.5" < = ID < = 5"
B7: 140 | C7: C-value for PVC < 1.5"
B8: 10 | C8: feet, Total Elevation Drop
B9: 670.3 | C9: feet, Length of Sub-mainline
B10: =B8/B9 -> 0.014918693 | C10: ft/ft, Change in Elevation
B11: 0.5 | C11: GPH/emitter
B12: =B11/60 -> 0.0083333333 | C12: GPM/emitter
B13: 3.045 | C13: ft, emitter spacing
B17: Chg. Elev = Length * ft/ft (elevation change worst case)
B18: Chg. P = Chg. Elev + Hf
A20: Section A
A21: Row | B21: Row Length ft | C21: GPM per Row | D21: Pressure PSI | E21: Length ft | F21: GPM | G21: Pipe ID, in | H21: Velocity, ft/sec | I21: C-Value | J21: Hf (psi) | K21: Chg. Elev (psi) | L21: Chg. P (psi)
A22: Inlet | B22: 0 | C22: 0 | D22: 25 | E22: 0 | F22: 52 | G22: 2.193 | H22: =(F22/448.8)/(3.14*((G22/12)^2)/4) -> 4.419428 | I22: =IF(G22>5,$B$5,IF(5>=G22>1.5,$B$6,IF(1.5>G22,$B$7,0))) -> 145 | J22: =(1050*((F22/I22)^1.852)*(E22/100)*(G22^-4.87))/2.31 -> 0 | K22: =E22*$B$10 -> 0 | L22: =-K22-J22 -> 0
A23: 1 | B23: 17.7 | C23: =(B23/$B$13)*$B$12 -> 0.048440066 | D23: =D22+L22 -> 25 | E23: 19.2 | F23: =F22-C23 -> 51.95156 | G23: 2.193 | H23: =(F23/448.8)/(3.14*((G23/12)^2)/4) -> 4.4153112 | I23: =IF(G23>5,$B$5,IF(5>=G23>1.5,$B$6,IF(1.5>G23,$B$7,0))) -> 145 | J23: =(1050*((F23/I23)^1.852)*(E23/100)*(G23^-4.87))/2.31 -> 0.28474458 | K23: =E23*$B$10 -> 0.28643891 | L23: =-K23-J23 -> -0.57118349
A24: =A23+1 -> 2 | B24: 35.7 | C24: =(B24/$B$13)*$B$12 -> 0.097701149 | D24: =D23+L23 -> 24.428817 | E24: 19.6 | F24: =F23-C24 -> 51.853859 | G24: 2.193 | H24: =(F24/448.8)/(3.14*((G24/12)^2)/4) -> 4.4070076 | I24: =IF(G24>5,$B$5,IF(5>=G24>1.5,$B$6,IF(1.5>G24,$B$7,0))) -> 145 | J24: =(1050*((F24/I24)^1.852)*(E24/100)*(G24^-4.87))/2.31 -> 0.28966517 | K24: =E24*$B$10 -> 0.29240639 | L24: =-K24-J24 -> -0.58207155
A25: =A24+1 -> 3 | B25: 53.7 | C25: =(B25/$B$13)*$B$12 -> 0.14696223 | D25: =D24+L24 -> 23.846745 | E25: 19.6 | F25: =F24-C25 -> 51.706897 | G25: 2.193 | H25: =(F25/448.8)/(3.14*((G25/12)^2)/4) -> 4.3945175 | I25: =IF(G25>5,$B$5,IF(5>=G25>1.5,$B$6,IF(1.5>G25,$B$7,0))) -> 145 | J25: =(1050*((F25/I25)^1.852)*(E25/100)*(G25^-4.87))/2.31 -> 0.28814659 | K25: =E25*$B$10 -> 0.29240639 | L25: =-K25-J25 -> -0.58055298
A26: =A25+1 -> 4 | B26: 71.7 | C26: =(B26/$B$13)*$B$12 -> 0.19622332 | D26: =D25+L25 -> 23.266192 | E26: 19.6 | F26: =F25-C26 -> 51.510673 | G26: 2.193 | H26: =(F26/448.8)/(3.14*((G26/12)^2)/4) -> 4.3778407 | I26: =IF(G26>5,$B$5,IF(5>=G26>1.5,$B$6,IF(1.5>G26,$B$7,0))) -> 145 | J26: =(1050*((F26/I26)^1.852)*(E26/100)*(G26^-4.87))/2.31 -> 0.28612472 | K26: =E26*$B$10 -> 0.29240639 | L26: =-K26-J26 -> -0.5785311
A27: =A26+1 -> 5 | B27: 89.7 | C27: =(B27/$B$13)*$B$12 -> 0.2454844 | D27: =D26+L26 -> 22.687661 | E27: 19.6 | F27: =F26-C27 -> 51.265189 | G27: 2.193 | H27: =(F27/448.8)/(3.14*((G27/12)^2)/4) -> 4.3569772 | I27: =IF(G27>5,$B$5,IF(5>=G27>1.5,$B$6,IF(1.5>G27,$B$7,0))) -> 145 | J27: =(1050*((F27/I27)^1.852)*(E27/100)*(G27^-4.87))/2.31 -> 0.28360449 | K27: =E27*$B$10 -> 0.29240639 | L27: =-K27-J27 -> -0.57601087
A28: =A27+1 -> 6 | B28: 107.7 | C28: =(B28/$B$13)*$B$12 -> 0.29474548 | D28: =D27+L27 -> 22.11165 | E28: 19.6 | F28: =F27-C28 -> 50.970443 | G28: 2.193 | H28: =(F28/448.8)/(3.14*((G28/12)^2)/4) -> 4.3319271 | I28: =IF(G28>5,$B$5,IF(5>=G28>1.5,$B$6,IF(1.5>G28,$B$7,0))) -> 145 | J28: =(1050*((F28/I28)^1.852)*(E28/100)*(G28^-4.87))/2.31 -> 0.28059208 | K28: =E28*$B$10 -> 0.29240639 | L28: =-K28-J28 -> -0.57299847
A29: =A28+1 -> 7 | B29: 125.7 | C29: =(B29/$B$13)*$B$12 -> 0.34400657 | D29: =D28+L28 -> 21.538652 | E29: 19.6 | F29: =F28-C29 -> 50.626437 | G29: 2.193 | H29: =(F29/448.8)/(3.14*((G29/12)^2)/4) -> 4.3026903 | I29: =IF(G29>5,$B$5,IF(5>=G29>1.5,$B$6,IF(1.5>G29,$B$7,0))) -> 145 | J29: =(1050*((F29/I29)^1.852)*(E29/100)*(G29^-4.87))/2.31 -> 0.27709494 | K29: =E29*$B$10 -> 0.29240639 | L29: =-K29-J29 -> -0.56950132
A30: =A29+1 -> 8 | B30: 143.7 | C30: =(B30/$B$13)*$B$12 -> 0.39326765 | D30: =D29+L29 -> 20.96915 | E30: 19.6 | F30: =F29-C30 -> 50.233169 | G30: 2.193 | H30: =(F30/448.8)/(3.14*((G30/12)^2)/4) -> 4.2692669 | I30: =IF(G30>5,$B$5,IF(5>=G30>1.5,$B$6,IF(1.5>G30,$B$7,0))) -> 145 | J30: =(1050*((F30/I30)^1.852)*(E30/100)*(G30^-4.87))/2.31 -> 0.27312174 | K30: =E30*$B$10 -> 0.29240639 | L30: =-K30-J30 -> -0.56552812
A31: =A30+1 -> 9 | B31: 161.7 | C31: =(B31/$B$13)*$B$12 -> 0.44252874 | D31: =D30+L30 -> 20.403622 | E31: 19.6 | F31: =F30-C31 -> 49.79064 | G31: 2.193 | H31: =(F31/448.8)/(3.14*((G31/12)^2)/4) -> 4.2316568 | I31: =IF(G31>5,$B$5,IF(5>=G31>1.5,$B$6,IF(1.5>G31,$B$7,0))) -> 145 | J31: =(1050*((F31/I31)^1.852)*(E31/100)*(G31^-4.87))/2.31 -> 0.26868244 | K31: =E31*$B$10 -> 0.29240639 | L31: =-K31-J31 -> -0.56108882
A32: =A31+1 -> 10 | B32: 179.8 | C32: =(B32/$B$13)*$B$12 -> 0.49206349 | D32: =D31+L31 -> 19.842533 | E32: 19.6 | F32: =F31-C32 -> 49.298577 | G32: 2.193 | H32: =(F32/448.8)/(3.14*((G32/12)^2)/4) -> 4.1898368 | I32: =IF(G32>5,$B$5,IF(5>=G32>1.5,$B$6,IF(1.5>G32,$B$7,0))) -> 145 | J32: =(1050*((F32/I32)^1.852)*(E32/100)*(G32^-4.87))/2.31 -> 0.26378554 | K32: =E32*$B$10 -> 0.29240639 | L32: =-K32-J32 -> -0.55619193
A33: =A32+1 -> 11 | B33: 197.8 | C33: =(B33/$B$13)*$B$12 -> 0.54132458 | D33: =D32+L32 -> 19.286341 | E33: 19.6 | F33: =F32-C33 -> 48.757252 | G33: 2.193 | H33: =(F33/448.8)/(3.14*((G33/12)^2)/4) -> 4.1438302 | I33: =IF(G33>5,$B$5,IF(5>=G33>1.5,$B$6,IF(1.5>G33,$B$7,0))) -> 145 | J33: =(1050*((F33/I33)^1.852)*(E33/100)*(G33^-4.87))/2.31 -> 0.25844632 | K33: =E33*$B$10 -> 0.29240639 | L33: =-K33-J33 -> -0.55085271
A34: Section B
A35: =A33+1 -> 12 | B35: 213.7 | C35: =(B35/$B$13)*$B$12 -> 0.58483853 | D35: =D33+L33 -> 18.735489 | E35: 18.4 | F35: =F33-C35 -> 48.172414 | G35: 2.193 | H35: =(F35/448.8)/(3.14*((G35/12)^2)/4) -> 4.0941253 | I35: =IF(G35>5,$B$5,IF(5>=G35>1.5,$B$6,IF(1.5>G35,$B$7,0))) -> 145 | J35: =(1050*((F35/I35)^1.852)*(E35/100)*(G35^-4.87))/2.31 -> 0.23726087 | K35: =E35*$B$10 -> 0.27450395 | L35: =-K35-J35 -> -0.51176482
A36: =A35+1 -> 13 | B36: 211 | C36: =(B36/$B$13)*$B$12 -> 0.57744937 | D36: =D35+L35 -> 18.223724 | E36: 8.2 | F36: =F35-C36 -> 47.594964 | G36: 2.193 | H36: =(F36/448.8)/(3.14*((G36/12)^2)/4) -> 4.0450485 | I36: =IF(G36>5,$B$5,IF(5>=G36>1.5,$B$6,IF(1.5>G36,$B$7,0))) -> 145 | J36: =(1050*((F36/I36)^1.852)*(E36/100)*(G36^-4.87))/2.31 -> 0.10340046 | K36: =E36*$B$10 -> 0.12233328 | L36: =-K36-J36 -> -0.22573375
A37: =A36+1 -> 14 | B37: 208.4 | C37: =(B37/$B$13)*$B$12 -> 0.57033388 | D37: =D36+L36 -> 17.99799 | E37: 8.2 | F37: =F36-C37 -> 47.024631 | G37: 2.193 | H37: =(F37/448.8)/(3.14*((G37/12)^2)/4) -> 3.9965764 | I37: =IF(G37>5,$B$5,IF(5>=G37>1.5,$B$6,IF(1.5>G37,$B$7,0))) -> 145 | J37: =(1050*((F37/I37)^1.852)*(E37/100)*(G37^-4.87))/2.31 -> 0.10111745 | K37: =E37*$B$10 -> 0.12233328 | L37: =-K37-J37 -> -0.22345074
A38: =A37+1 -> 15 | B38: 205.7 | C38: =(B38/$B$13)*$B$12 -> 0.56294472 | D38: =D37+L37 -> 17.774539 | E38: 8.2 | F38: =F37-C38 -> 46.461686 | G38: 2.193 | H38: =(F38/448.8)/(3.14*((G38/12)^2)/4) -> 3.9487323 | I38: =IF(G38>5,$B$5,IF(5>=G38>1.5,$B$6,IF(1.5>G38,$B$7,0))) -> 145 | J38: =(1050*((F38/I38)^1.852)*(E38/100)*(G38^-4.87))/2.31 -> 0.098887038 | K38: =E38*$B$10 -> 0.12233328 | L38: =-K38-J38 -> -0.22122032
A39: =A38+1 -> 16 | B39: 203 | C39: =(B39/$B$13)*$B$12 -> 0.55555556 | D39: =D38+L38 -> 17.553319 | E39: 8.2 | F39: =F38-C39 -> 45.90613 | G39: 2.193 | H39: =(F39/448.8)/(3.14*((G39/12)^2)/4) -> 3.9015161 | I39: =IF(G39>5,$B$5,IF(5>=G39>1.5,$B$6,IF(1.5>G39,$B$7,0))) -> 145 | J39: =(1050*((F39/I39)^1.852)*(E39/100)*(G39^-4.87))/2.31 -> 0.096708357 | K39: =E39*$B$10 -> 0.12233328 | L39: =-K39-J39 -> -0.21904164
A40: =A39+1 -> 17 | B40: 200.4 | C40: =(B40/$B$13)*$B$12 -> 0.54844007 | D40: =D39+L39 -> 17.334277 | E40: 8.2 | F40: =F39-C40 -> 45.35769 | G40: 2.193 | H40: =(F40/448.8)/(3.14*((G40/12)^2)/4) -> 3.8549048 | I40: =IF(G40>5,$B$5,IF(5>=G40>1.5,$B$6,IF(1.5>G40,$B$7,0))) -> 145 | J40: =(1050*((F40/I40)^1.852)*(E40/100)*(G40^-4.87))/2.31 -> 0.094579501 | K40: =E40*$B$10 -> 0.12233328 | L40: =-K40-J40 -> -0.21691278
A41: =A40+1 -> 18 | B41: 197.7 | C41: =(B41/$B$13)*$B$12 -> 0.5410509 | D41: =D40+L40 -> 17.117365 | E41: 8.2 | F41: =F40-C41 -> 44.816639 | G41: 2.193 | H41: =(F41/448.8)/(3.14*((G41/12)^2)/4) -> 3.8089214 | I41: =IF(G41>5,$B$5,IF(5>=G41>1.5,$B$6,IF(1.5>G41,$B$7,0))) -> 145 | J41: =(1050*((F41/I41)^1.852)*(E41/100)*(G41^-4.87))/2.31 -> 0.092500707 | K41: =E41*$B$10 -> 0.12233328 | L41: =-K41-J41 -> -0.21483399
A42: =A41+1 -> 19 | B42: 195 | C42: =(B42/$B$13)*$B$12 -> 0.53366174 | D42: =D41+L41 -> 16.902531 | E42: 8.2 | F42: =F41-C42 -> 44.282978 | G42: 2.193 | H42: =(F42/448.8)/(3.14*((G42/12)^2)/4) -> 3.763566 | I42: =IF(G42>5,$B$5,IF(5>=G42>1.5,$B$6,IF(1.5>G42,$B$7,0))) -> 145 | J42: =(1050*((F42/I42)^1.852)*(E42/100)*(G42^-4.87))/2.31 -> 0.090471143 | K42: =E42*$B$10 -> 0.12233328 | L42: =-K42-J42 -> -0.21280443
A43: =A42+1 -> 20 | B43: 195.8 | C43: =(B43/$B$13)*$B$12 -> 0.53585112 | D43: =D42+L42 -> 16.689726 | E43: 8.2 | F43: =F42-C43 -> 43.747126 | G43: 2.193 | H43: =(F43/448.8)/(3.14*((G43/12)^2)/4) -> 3.7180246 | I43: =IF(G43>5,$B$5,IF(5>=G43>1.5,$B$6,IF(1.5>G43,$B$7,0))) -> 145 | J43: =(1050*((F43/I43)^1.852)*(E43/100)*(G43^-4.87))/2.31 -> 0.088454112 | K43: =E43*$B$10 -> 0.12233328 | L43: =-K43-J43 -> -0.2107874
A44: =A43+1 -> 21 | B44: 197.5 | C44: =(B44/$B$13)*$B$12 -> 0.54050356 | D44: =D43+L43 -> 16.478939 | E44: 8.2 | F44: =F43-C44 -> 43.206623 | G44: 2.193 | H44: =(F44/448.8)/(3.14*((G44/12)^2)/4) -> 3.6720877 | I44: =IF(G44>5,$B$5,IF(5>=G44>1.5,$B$6,IF(1.5>G44,$B$7,0))) -> 145 | J44: =(1050*((F44/I44)^1.852)*(E44/100)*(G44^-4.87))/2.31 -> 0.086440783 | K44: =E44*$B$10 -> 0.12233328 | L44: =-K44-J44 -> -0.20877407
A45: =A44+1 -> 22 | B45: 199.3 | C45: =(B45/$B$13)*$B$12 -> 0.54542967 | D45: =D44+L44 -> 16.270165 | E45: 8.2 | F45: =F44-C45 -> 42.661193 | G45: 2.193 | H45: =(F45/448.8)/(3.14*((G45/12)^2)/4) -> 3.6257322 | I45: =IF(G45>5,$B$5,IF(5>=G45>1.5,$B$6,IF(1.5>G45,$B$7,0))) -> 145 | J45: =(1050*((F45/I45)^1.852)*(E45/100)*(G45^-4.87))/2.31 -> 0.084430742 | K45: =E45*$B$10 -> 0.12233328 | L45: =-K45-J45 -> -0.20676403
A46: =A45+1 -> 23 | B46: 201 | C46: =(B46/$B$13)*$B$12 -> 0.5500821 | D46: =D45+L45 -> 16.063401 | E46: 8.2 | F46: =F45-C46 -> 42.111111 | G46: 2.193 | H46: =(F46/448.8)/(3.14*((G46/12)^2)/4) -> 3.5789813 | I46: =IF(G46>5,$B$5,IF(5>=G46>1.5,$B$6,IF(1.5>G46,$B$7,0))) -> 145 | J46: =(1050*((F46/I46)^1.852)*(E46/100)*(G46^-4.87))/2.31 -> 0.082425613 | K46: =E46*$B$10 -> 0.12233328 | L46: =-K46-J46 -> -0.2047589
...

Sheet Block 6
A1: Block 6
A3: Manifold Size and Pressure for the Longest run
C5: =Design!G156 -> 50.816667 | D5: GPM/block
C6: 0.5 | D6: GPH/emitter
C7: 2 | D7: emitter/vine
C8: =Design!G154 -> 3049 | D8: # Vines
C9: =C8*C7 -> 6098 | D9: # of emitters
C10: 0.03 | D10: Manufacturing cv
C11: 138 | D11: C-value for hose
C12: 3 | D12: ft,emitter spacing
C13: =C12+(C12*0.015) -> 3.045 | D13: ft, distance between emitters with 1.5% extra provided for temperature
D14: expansion and contraction of hose.
C17: 15 | D17: Rows
C18: 1530.6 | D18: Ft, Longest Row
C19: 10 | D19: ft, worst case change in Elevation
C20: =C19/C18 -> 0.0065333856 | D20: Ft/Ft, Elevation Change worst case
C21: =ROUNDDOWN(C18/C13,0) -> 502 | D21: Emitter on this line
C22: =(C21*C6)/60 -> 4.1833333 | D22: GPM, Flow Rate Needed on line
C24: 4 | D24: ft/sec
C25: 0.73 | D25: in, ID
C26: =C24*(3.14*((C25/12)^2)/4)*448 -> 5.2058409 | D26: Flow Rate, GPM
A29: Emitter | B29: Point P psi | C29: Elev. Ft | D29: Length ft | E29: GPM | F29: Hose ID, in | G29: Hf (psi) | H29: Chg. Elev (psi) | I29: Chg. P (psi)
A31: 1 | B31: 25 | C31: 3085 | D31: =$C$13 -> 3.045 | E31: =C22 -> 4.1833333 | F31: 0.72 | G31: =(1050*((E31/$C$11)^1.852)*(D31/100)*(F31^-4.87))/2.31 -> 0.10567175 | H31: =(D31*$C$20)/2.31 -> 0.0086121901 | I31: =H31-G31 -> -0.097059562
A32: =A31+1 -> 2 | B32: =B31+I31 -> 24.90294 | C32: =C31-H31*2.31 -> 3084.9801 | D32: =$C$13 -> 3.045 | E32: =E31-($C$6/60) -> 4.175 | F32: 0.72 | G32: =(1050*((E32/$C$11)^1.852)*(D32/100)*(F32^-4.87))/2.31 -> 0.10528223 | H32: =(D32*$C$20)/2.31 -> 0.0086121901 | I32: =H32-G32 -> -0.096670044
A33: =A32+1 -> 3 | B33: =B32+I32 -> 24.80627 | C33: =C32-H32*2.31 -> 3084.9602 | D33: =$C$13 -> 3.045 | E33: =E32-($C$6/60) -> 4.1666667 | F33: 0.72 | G33: =(1050*((E33/$C$11)^1.852)*(D33/100)*(F33^-4.87))/2.31 -> 0.10489338 | H33: =(D33*$C$20)/2.31 -> 0.0086121901 | I33: =H33-G33 -> -0.096281188
A34: =A33+1 -> 4 | B34: =B33+I33 -> 24.709989 | C34: =C33-H33*2.31 -> 3084.9403 | D34: =$C$13 -> 3.045 | E34: =E33-($C$6/60) -> 4.1583333 | F34: 0.72 | G34: =(1050*((E34/$C$11)^1.852)*(D34/100)*(F34^-4.87))/2.31 -> 0.10450518 | H34: =(D34*$C$20)/2.31 -> 0.0086121901 | I34: =H34-G34 -> -0.095892994
A35: =A34+1 -> 5 | B35: =B34+I34 -> 24.614096 | C35: =C34-H34*2.31 -> 3084.9204 | D35: =$C$13 -> 3.045 | E35: =E34-($C$6/60) -> 4.15 | F35: 0.72 | G35: =(1050*((E35/$C$11)^1.852)*(D35/100)*(F35^-4.87))/2.31 -> 0.10411765 | H35: =(D35*$C$20)/2.31 -> 0.0086121901 | I35: =H35-G35 -> -0.095505462
A36: =A35+1 -> 6 | B36: =B35+I35 -> 24.518591 | C36: =C35-H35*2.31 -> 3084.9005 | D36: =$C$13 -> 3.045 | E36: =E35-($C$6/60) -> 4.1416667 | F36: 0.72 | G36: =(1050*((E36/$C$11)^1.852)*(D36/100)*(F36^-4.87))/2.31 -> 0.10373078 | H36: =(D36*$C$20)/2.31 -> 0.0086121901 | I36: =H36-G36 -> -0.095118593
A37: =A36+1 -> 7 | B37: =B36+I36 -> 24.423472 | C37: =C36-H36*2.31 -> 3084.8806 | D37: =$C$13 -> 3.045 | E37: =E36-($C$6/60) -> 4.1333333 | F37: 0.72 | G37: =(1050*((E37/$C$11)^1.852)*(D37/100)*(F37^-4.87))/2.31 -> 0.10334458 | H37: =(D37*$C$20)/2.31 -> 0.0086121901 | I37: =H37-G37 -> -0.094732386
A38: =A37+1 -> 8 | B38: =B37+I37 -> 24.32874 | C38: =C37-H37*2.31 -> 3084.8607 | D38: =$C$13 -> 3.045 | E38: =E37-($C$6/60) -> 4.125 | F38: 0.72 | G38: =(1050*((E38/$C$11)^1.852)*(D38/100)*(F38^-4.87))/2.31 -> 0.10295903 | H38: =(D38*$C$20)/2.31 -> 0.0086121901 | I38: =H38-G38 -> -0.094346842
A39: =A38+1 -> 9 | B39: =B38+I38 -> 24.234393 | C39: =C38-H38*2.31 -> 3084.8408 | D39: =$C$13 -> 3.045 | E39: =E38-($C$6/60) -> 4.1166667 | F39: 0.72 | G39: =(1050*((E39/$C$11)^1.852)*(D39/100)*(F39^-4.87))/2.31 -> 0.10257415 | H39: =(D39*$C$20)/2.31 -> 0.0086121901 | I39: =H39-G39 -> -0.093961961
A40: =A39+1 -> 10 | B40: =B39+I39 -> 24.140431 | C40: =C39-H39*2.31 -> 3084.821 | D40: =$C$13 -> 3.045 | E40: =E39-($C$6/60) -> 4.1083333 | F40: 0.72 | G40: =(1050*((E40/$C$11)^1.852)*(D40/100)*(F40^-4.87))/2.31 -> 0.10218993 | H40: =(D40*$C$20)/2.31 -> 0.0086121901 | I40: =H40-G40 -> -0.093577744
A41: =A40+1 -> 11 | B41: =B40+I40 -> 24.046853 | C41: =C40-H40*2.31 -> 3084.8011 | D41: =$C$13 -> 3.045 | E41: =E40-($C$6/60) -> 4.1 | F41: 0.72 | G41: =(1050*((E41/$C$11)^1.852)*(D41/100)*(F41^-4.87))/2.31 -> 0.10180638 | H41: =(D41*$C$20)/2.31 -> 0.0086121901 | I41: =H41-G41 -> -0.093194189
A42: =A41+1 -> 12 | B42: =B41+I41 -> 23.953659 | C42: =C41-H41*2.31 -> 3084.7812 | D42: =$C$13 -> 3.045 | E42: =E41-($C$6/60) -> 4.0916667 | F42: 0.72 | G42: =(1050*((E42/$C$11)^1.852)*(D42/100)*(F42^-4.87))/2.31 -> 0.10142349 | H42: =(D42*$C$20)/2.31 -> 0.0086121901 | I42: =H42-G42 -> -0.092811299
A43: =A42+1 -> 13 | B43: =B42+I42 -> 23.860848 | C43: =C42-H42*2.31 -> 3084.7613 | D43: =$C$13 -> 3.045 | E43: =E42-($C$6/60) -> 4.0833333 | F43: 0.72 | G43: =(1050*((E43/$C$11)^1.852)*(D43/100)*(F43^-4.87))/2.31 -> 0.10104126 | H43: =(D43*$C$20)/2.31 -> 0.0086121901 | I43: =H43-G43 -> -0.092429072
... A304: =A303+1 -> 274 | B304: =B303+I303 -> 10.693775 | C304: =C303-H303*2.31 -> 3079.5689 | D304: =$C$13 -> 3.045 | E304: =E303-($C$6/60) -> 1.9083333 | F304: 0.72 | G304: =(1050*((E304/$C$11)^1.852)*(D304/100)*(F304^-4.87))/2.31 -> 0.02469852 | H304: =(D304*$C$20)/2.31 -> 0.0086121901 | I304: =H304-G304 -> -0.01608633
A306: Min P | B306: =MIN(B31:B304) -> 10.693775 | C306: psi
A307: Max P | B307: =MAX(B31:B304) -> 25 | C307: psi
A308: Chg. In P | B308: =B307-B306 -> 14.306225 | C308: psi

Sheet Block 7
A1: Block 7
A3: Sub-mainline Sizing and Pressure
B6: 150 | C6: C-value for PVC ID > 5"
B7: 145 | C7: C-value for PVC 1.5" < = ID < = 5"
B8: 140 | C8: C-value for PVC < 1.5"
B9: 0 | C9: feet, Total Elevation Drop
B10: =80.2+117.4+290.3+130.5 -> 618.4 | C10: feet, Length of Sub-mainline
B11: =B9/B10 -> 0 | C11: ft/ft, Change in Elevation
B12: 0.5 | C12: GPH/emitter
B13: =B12/60 -> 0.0083333333 | C13: GPM/emitter
B14: =3.045 -> 3.045 | C14: ft, emitter spacing
B18: Chg. Elev = Length * ft/ft (elevation change worst case)
B19: Chg. P = Chg. Elev + Hf
A22: Section A Uphill
