Workbook
Name Query_from_DanaDWStaging: 'FY07 TTL Revenue Master'!#REF!
Name Query_from_Profiles: 'FY07 TTL Revenue Master'!$A$6:$AB$494
Name Query_from_Profiles_1: 'Charter Minnea St. Paul Wrk'!$A$6:$R$67
Name Query_from_Profiles_1: 'Charter State Work'!$A$6:$R$136
Name Query_from_Profiles_1: 'District St Wrk'!$A$6:$R$346
Name Query_from_Profiles_1: 'Minnea St Paul Dist wrk'!$A$6:$R$10
Name Query_from_ProfilesRevenue: 'FY07 TTL Revenue Master'!$A$6:$AB$493

Sheet Legend
A2: Legend
D3: Local
D5: State
D7: Federal
D9: Other
D11: Indeterminate
D13: Minneapolis
D15: St. Paul
A18: Source | B18: Minnesota Department of Education
A20: All files are "read only" and based on data collections from the Minnesota Department of Education.
A21: The conclusions reached in this document are those of the author(s) and do not necessarily represent those
A22: of Ball State University.

Sheet Figures 1,2,4
A1: Figure 1 | K1: Figure 2
A2: Minnesota (2006-07) | B2: Statewide | D2: Statewide Weighted for Charter Enrollment | F2: Minneapolis | H2: St. Paul | L2: District | M2: Charter | N2: Difference
A3: Per-Pupil Revenue | K3: State | L3: 11250.462 | M3: 11081.364 | N3: 169.09764
A4: District | B4: =B14 -> 11250.462 | D4: 12720 | F4: =F14 -> 15117.723 | H4: =H14 -> 13509.847 | K4: Statewide Weighted | L4: 12720 | M4: 11081 | N4: 1639
A5: Charter | B5: =C14 -> 11081.364 | D5: 11081 | F5: =G14 -> 11929.984 | H5: =I14 -> 11700.126 | K5: Minneapolis | L5: 15117.723 | M5: 11929.984 | N5: 3187.7392
A6: Difference | B6: =B4-B5 -> 169.09764 | D6: 1639 | F6: =F4-F5 -> 3187.7392 | H6: =H4-H5 -> 1809.7214 | K6: St. Paul | L6: 13509.847 | M6: 11700.126 | N6: 1809.7214
B7: =B6/B4 -> 0.015030284 | D7: 0.129 | F7: =F6/F4 -> 0.21086107 | H7: =H6/H4 -> 0.13395573
A8: Per-Pupil Revenue by Source | B8: District | C8: Charter | D8: District | E8: Charter | F8: District | G8: Charter | H8: District | I8: Charter
A9: Federal | B9: ='District St Wrk'!S348 -> 617.29505 | C9: ='Charter State Work'!S138 -> 1039.2773 | D9: 1080 | E9: 1039.2773 | F9: ='Minnea St Paul Dist wrk'!S8 -> 1729.2229 | G9: ='Charter Minnea St. Paul Wrk'!S37 -> 1211.4557 | H9: ='Minnea St Paul Dist wrk'!S12 -> 1453.0301 | I9: ='Charter Minnea St. Paul Wrk'!S69 -> 975.52296
A10: State | B10: ='District St Wrk'!Q348 -> 7656.899 | C10: ='Charter State Work'!Q138 -> 9429.9787 | D10: 8646 | E10: 9429.9787 | F10: ='Minnea St Paul Dist wrk'!Q8 -> 9750.1383 | G10: ='Charter Minnea St. Paul Wrk'!Q37 -> 9910.712 | H10: ='Minnea St Paul Dist wrk'!Q12 -> 9772.058 | I10: ='Charter Minnea St. Paul Wrk'!Q69 -> 10216.018
A11: Local | B11: ='District St Wrk'!M348 -> 2467.3583 | C11: ='Charter State Work'!M138 -> 488.59691 | D11: 2689 | E11: 488.59691 | F11: ='Minnea St Paul Dist wrk'!M8 -> 3461.8077 | G11: ='Charter Minnea St. Paul Wrk'!M37 -> 780.94731 | H11: ='Minnea St Paul Dist wrk'!M12 -> 2328.0031 | I11: ='Charter Minnea St. Paul Wrk'!M69 -> 453.05269
A12: Other | B12: ='District St Wrk'!T348 -> 658.30959 | C12: ='Charter State Work'!T138 -> 128.73442 | D12: 535 | E12: 128.73442 | F12: ='Minnea St Paul Dist wrk'!T8 -> 475.10942 | G12: ='Charter Minnea St. Paul Wrk'!T37 -> 34.247547 | H12: ='Minnea St Paul Dist wrk'!T12 -> 305.80474 | I12: ='Charter Minnea St. Paul Wrk'!T69 -> 55.531566
A13: Indeterminate | B13: ='District St Wrk'!V348 -> -149.4001 | C13: ='Charter State Work'!V138 -> -5.2231697 | D13: -230 | E13: -5.2231697 | F13: ='Minnea St Paul Dist wrk'!V8 -> -298.55559 | G13: ='Charter Minnea St. Paul Wrk'!V37 -> -7.3789752 | H13: ='Minnea St Paul Dist wrk'!V12 -> -349.0491 | I13: ='Charter Minnea St. Paul Wrk'!V69 -> 0
A14: Total | B14: =SUM(B9:B13) -> 11250.462 | C14: =SUM(C9:C13) -> 11081.364 | D14: 12720 | E14: 11081.364 | F14: =SUM(F9:F13) -> 15117.723 | G14: =SUM(G9:G13) -> 11929.984 | H14: =SUM(H9:H13) -> 13509.847 | I14: =SUM(I9:I13) -> 11700.126
A15: Enrollment
A16: District | B16: ='District St Wrk'!J346 -> 814733.22 | D16: n/a | F16: ='Minnea St Paul Dist wrk'!J6 -> 39479.31 | H16: ='Minnea St Paul Dist wrk'!J10 -> 42379.85
B17: =B16/(B16+B18) -> 0.97159836 | D17: n/a | F17: =F16/(F16+F18) -> 0.85604008 | H17: =H16/(H16+H18) -> 0.87904738
A18: Charter | B18: ='Charter State Work'!J136 -> 23816.18 | D18: n/a | F18: ='Charter Minnea St. Paul Wrk'!J35 -> 6639.22 | H18: ='Charter Minnea St. Paul Wrk'!J67 -> 5831.26
B19: =B18/(B16+B18) -> 0.028401642 | D19: n/a | F19: =F18/(F16+F18) -> 0.14395992 | H19: =H18/(H16+H18) -> 0.12095262
A20: Number of Charters | B20: 129 | D20: n/a | F20: 29 | H20: 27
A21: Total Revenue
A22: District | B22: ='District St Wrk'!W347 -> 9.166125e+09 | D22: n/a | F22: ='Minnea St Paul Dist wrk'!W7 -> 5.9683726e+08 | H22: ='Minnea St Paul Dist wrk'!W11 -> 5.7254528e+08
B23: =B22/B26 -> 0.9720133 | D23: n/a | F23: =F22/F26 -> 0.88283914 | H23: =H22/H26 -> 0.89352453
A24: Charter | B24: ='Charter State Work'!W137 -> 2.6391576e+08 | D24: n/a | F24: ='Charter Minnea St. Paul Wrk'!W36 -> 79205785 | H24: ='Charter Minnea St. Paul Wrk'!W68 -> 68226474
B25: =B24/B26 -> 0.027986705 | D25: n/a | F25: =F24/F26 -> 0.11716086 | H25: =H24/H26 -> 0.10647547
A26: Total | B26: =B22+B24 -> 9.4300407e+09 | D26: n/a | F26: =F22+F24 -> 6.7604305e+08 | H26: =H22+H24 -> 6.4077176e+08
A27: Percentage of Revenue by Source | B27: District | C27: Charter | D27: District | E27: Charter | F27: District | G27: Charter | H27: District | I27: Charter | K27: Figure 4
A28: Federal | B28: =B9/B14 -> 0.054868419 | C28: =C9/C14 -> 0.093786046 | D28: 0.08490566 | E28: 0.093786046 | F28: =F9/F14 -> 0.11438382 | G28: =G9/G14 -> 0.10154714 | H28: =H9/H14 -> 0.10755341 | I28: =I9/I14 -> 0.083377136 | L28: Federal | M28: State | N28: Local | O28: Other | P28: Indeterminate
A29: State | B29: =B10/B14 -> 0.6805853 | C29: =C10/C14 -> 0.85097634 | D29: 0.67971698 | E29: 0.85097634 | F29: =F10/F14 -> 0.64494755 | G29: =G10/G14 -> 0.83073978 | H29: =H10/H14 -> 0.72332855 | I29: =I10/I14 -> 0.87315459 | K29: Statewide District | L29: 617.29505 | M29: 7656.899 | N29: 2467.3583 | O29: 658.30959 | P29: -149.4001
A30: Local | B30: =B11/B14 -> 0.21931174 | C30: =C11/C14 -> 0.044091766 | D30: 0.21139937 | E30: 0.044091766 | F30: =F11/F14 -> 0.22899003 | G30: =G11/G14 -> 0.065460887 | H30: =H11/H14 -> 0.17231899 | I30: =I11/I14 -> 0.038722036 | K30: Statewide Charter | L30: 1039.2773 | M30: 9429.9787 | N30: 488.59691 | O30: 128.73442 | P30: -5.2231697
A31: Other | B31: =B12/B14 -> 0.058514006 | C31: =C12/C14 -> 0.011617199 | D31: 0.042059748 | E31: 0.011617199 | F31: =F12/F14 -> 0.031427314 | G31: =G12/G14 -> 0.002870712 | H31: =H12/H14 -> 0.022635692 | I31: =I12/I14 -> 0.0047462368 | K31: Statewide Weighted | L31: 1080 | M31: 8646 | N31: 2689 | O31: 535 | P31: -230
A32: Indeterminate | B32: =B13/B14 -> -0.013279464 | C32: =C13/C14 -> -0.00047134718 | D32: -0.018081761 | E32: -0.00047134718 | F32: =F13/F14 -> -0.019748715 | G32: =G13/G14 -> -0.00061852351 | H32: =H13/H14 -> -0.025836643 | I32: =I13/I14 -> 0 | K32: Minneapolis District | L32: 1729.2229 | M32: 9750.1383 | N32: 3461.8077 | O32: 475.10942 | P32: -298.55559
A33: Change in district school funding if subjected to charter funding structure | K33: Minneapolis Charter | L33: 1211.4557 | M33: 9910.712 | N33: 780.94731 | O33: 34.247547 | P33: -7.3789752
B34: (137.7 million) | F34: ($125.8 million) | H34: (76.6 million) | K34: St. Paul District | L34: 1453.0301 | M34: 9772.058 | N34: 2328.0031 | O34: 305.80474 | P34: -349.0491
B35: =B6*B16 -> 1.3776946e+08 | F35: =F6*F16 -> 1.2584974e+08 | H35: =H6*H16 -> 76695720 | K35: St. Paul Charter | L35: 975.52296 | M35: 10216.018 | N35: 453.05269 | O35: 55.531566 | P35: 0
A36: Number of schools based only on those schools open during the FY07 school year and received funds
A37: for operations.

Sheet Figure 3
A1: State Charter School Policies
A2: Figure 3
A3: State Policies | B3: Yes | C3: No | D3: Partial
A4: Charter schools received their funding directly from the state | B4: X
A5: Charter schools are eligible for local funding | D5: X1
A6: Cap on funding a charter school can receive | C6: X
A7: District public school receive differential funding (e.g. more funding for 9-12 vs. K-8 schools) | B7: X
A8: Charter schools receive differential funding | B8: X
A9: State allows districts to withhold funding from charter schools for providing adminstrative services | C9: X
A10: State "holds harmless" ditrict funding for charter enrollment | C10: X
A11: School is considered LEA if authorized by non-district organization | B11: X
A12: School is considered LEA if authorized by district | B12: X
A13: Cap on number of charter schools | C13: X2
A14: Cap on number of charters schools authorized per year | C14: X
A15: Cap on number of studens attending charter schools | C15: X
A16: Charter schools have an open enrollment policy | B16: X
A18: 1. Charter schools receive funding equal to the statewide average property tax amount and a minimal amount of additional equalization funding to offset the fiscal impact of district excess levy referenda. However, these additional revenues do not address the disparity in local funding between charter schools and district schools in areas like the Twin Cities.
A19: 2. Minnesota allows the State Department of Education, public and private universities and community colleges, non-profit organizations with assets of at least $2 million, and local public school districts to sponsor an unleimited number of schools with an initial charter term of up to three years.
A20: 3. Minnesota charter schools are available to all students in the state. While admissions prerequisiets are not permitted, charter schools can provide preference for enrollmetn to the siblings of current students and residents.

Sheet Figure 5
C2: Statewide District | D2: Statewide Charter
A3: Percentage of stuents eligible for free or reduced price lunch | C3: 0.302 | D3: 0.533
A4: Percentage of schools eligible for Title 1 | C4: 0.332 | D4: 0.497
A5: Percent of students by school type
B6: Primary (K-5) | C6: 0.452 | D6: 0.504
B7: Middle (6-8) | C7: 0.184 | D7: 0.071
B8: High (9-12) | C8: 0.334 | D8: 0.27
B9: Other (K-12,K-8, etc.) | C9: 0.029 | D9: 0.156

Sheet Figure 6
A1: Figure 6: State Scorecard
B2: Findings | C2: Minnesota | E2: Use the following options only
A3: Federal Funding | B3: Charters have access to federal funds according to state statutes (Yes = black, No = white)* | C3: Y | E3: Y
B4: Percentage of federal revenue equals percentage of total enrollment for charter schools (<, >, or =) | C4: > | E4: P
A5: State Funding | B5: Charters have access to state funds according to state statutes (Yes = black, No = white) | C5: Y | E5: N
B6: Percentage of state revenue equals percentage of total enrollment for charter schools (<, >, or =) | C6: >
A7: Local Funding | B7: Charters have access to local funds according to state statutes (Yes = black, No = white) | C7: Y
B8: Percentage of local revenue equals percentage of total enrollment for charter schools (<, >, or =) | C8: <
A9: Facilities Funding | B9: Charters have access to facilities funds according to state statutes (Yes = black, No = white) | C9: Y
B10: Percentage of facilities revenue equals percentage of total enrollment for charter schools (<, >, or =) | C10: NA
A11: Data Availability | B11: State provides detailed, public data on federal, state, local and other revenues for district schools (Yes = black, Partial = grey, No = white) | C11: Y
B12: State provides detailed, public data on federal, state, local and other revenues for charter schools (Yes = black, Partial = grey, No = white) | C12: Y
A13: Funding Formula | B13: Charters are treated as LEAs for funding purposes (Yes = black, Partial = grey, No = white) | C13: Y
B14: State funds student (black) or the LEA (grey) | C14: S | E14: S | F14: L | H14: Use these options for the query to the left only (B18)
B15: State funding formula is fair and equitable (Yes = black, No = white | C15: N
A17: * For this finding, No could indicate that the statue is silent or that it denies access.

Sheet FY07 TTL Revenue Master
F1: Click here for Definitions
A2: Economic Development Region Number | B2: Economic Development Region | C2: District Type | D2: County Number | E2: County Name | F2: Total Revenues FY07 | G2: District Number | J2: District ADM Served Plus Tuitioned Out | K2: General Fund Revenues | T2: Other Funds Revenues | X2: Grand Total Revenue for All Funds | Y2: Funds 01-07 Total Revenues
K3: Local Sources | N3: State Sources | R3: Federal Sources | S3: Fund 01 Total Revenue | T3: Local, State and Federal Sources | Y3: Local Sources | AA3: State Sources | AB3: Federal Sources
H4: Charter | I4: Charter Location | K4: Property Taxes | L4: Other | M4: Total Local Sources | N4: General Education Aid | O4: Special Education Aid | P4: All Other State Aid | Q4: Total State Sources | R4: Federal | T4: Food Service | U4: Community Service | V4: Building Construction | W4: Debt Service | Y4: Property Taxes | Z4: Other | AG4: deduct from community service fund | AJ4: deduct from community service fund | AO4: Other funds revenues distributed by Local Other State and Federal
F5: Counties and Districts | K5: 1. | L5: 2. You may need to treat this as local to align with Dave's FY03 data | M5: 3. | N5: 4. | O5: 5. | P5: 6. | Q5: 7. | R5: 8. | S5: 9. | T5: 10. | U5: 11. | V5: 12. | W5: 13. | X5: 14. | Y5: 15. | Z5: 16. | AA5: 17. | AB5: 18. | AC5: dat_yer | AD5: NUMBER | AE5: TYPE | AF5: NAME | AG5: Community Service Fund Revenue, Early Childhood Programs | AH5: TYPE | AI5: NAME | AJ5: ABE_AdltDisbld | AK5: Early Childhood Reduction | AL5: ABE Reduction | AO5: Local | AP5: Other | AQ5: State | AR5: Federal
A6: 3 | B6: Northeast Minnesota | C6: 01 | D6: 1 | E6: Aitkin | F6: AITKIN PUBLIC SCHOOL DISTRICT | G6: 0001 | J6: 1322.2 | K6: 613626 | L6: 1325974 | M6: 1939600 | N6: 8539952 | O6: 679449 | P6: 52813 | Q6: 9272214 | R6: 255760 | S6: 11467574 | T6: 589084 | U6: 266585 | V6: 0 | W6: 235402 | X6: 12558645 | Y6: 796996 | Z6: 1895424 | AA6: 9350914 | AB6: 515311 | AC6: 06-07 | AD6: 1 | AE6: 1 | AF6: AITKIN PUBLIC SCHOOL DISTRICT | AG6: 98691.4 | AH6: 1 | AI6: AITKIN PUBLIC SCHOOL DISTRICT | AJ6: 109867.98 | AK6: =AG6*AM6 -> -98691.4 | AL6: =AJ6*AM6 -> -109867.98 | AM6: -1 | AO6: =Y6-K6 -> 183370 | AP6: =Z6-L6 -> 569450 | AQ6: =AA6-Q6 -> 78700 | AR6: =AB6-R6 -> 259551
A7: 11 | B7: Twin Cities Metropolitan Area | C7: 03 | D7: 27 | E7: Hennepin | F7: MINNEAPOLIS PUBLIC SCHOOL DIST. | G7: 0001 | H7: District | I7: Minneapolis | J7: 39479.31 | K7: 58005565 | L7: 20520348 | M7: 78525913 | N7: 293589390 | O7: 49228337 | P7: 18490543 | Q7: 361308270 | R7: 52989194 | S7: 492823377 | T7: 14321379 | U7: 24987946 | V7: 5969817 | W7: 70521510 | X7: 608624030 | Y7: 116149433 | Z7: 39277340 | AA7: 384928731 | AB7: 68268526 | AC7: 06-07 | AD7: 1 | AE7: 3 | AF7: MINNEAPOLIS PUBLIC SCHOOL DIST. | AG7: 4444620.9 | AH7: 3 | AI7: MINNEAPOLIS PUBLIC SCHOOL DIST. | AJ7: 7342147.7 | AK7: =AG7*AM7 -> -4444620.9 | AL7: =AJ7*AM7 -> -7342147.7 | AM7: -1 | AO7: =Y7-K7 -> 58143868 | AP7: =Z7-L7 -> 18756992 | AQ7: =AA7-Q7 -> 23620461 | AR7: =AB7-R7 -> 15279332
A8: 3 | B8: Northeast Minnesota | C8: 01 | D8: 1 | E8: Aitkin | F8: HILL CITY PUBLIC SCHOOL DISTRICT | G8: 0002 | J8: 314.26 | K8: 59861 | L8: 422365 | M8: 482226 | N8: 2659597 | O8: 182721 | P8: 6745 | Q8: 2849063 | R8: 145220 | S8: 3476509 | T8: 146067 | U8: 60528 | V8: 540 | W8: 362730 | X8: 4046376 | Y8: 341788 | Z8: 507664 | AA8: 2965150 | AB8: 231774 | AC8: 06-07 | AD8: 2 | AE8: 1 | AF8: HILL CITY PUBLIC SCHOOL DISTRICT | AG8: 24582.72 | AH8: 1 | AI8: HILL CITY PUBLIC SCHOOL DISTRICT | AJ8: 0 | AK8: =AG8*AM8 -> -24582.72 | AL8: =AJ8*AM8 -> 0 | AM8: -1 | AO8: =Y8-K8 -> 281927 | AP8: =Z8-L8 -> 85299 | AQ8: =AA8-Q8 -> 116087 | AR8: =AB8-R8 -> 86554
A9: 3 | B9: Northeast Minnesota | C9: 01 | D9: 1 | E9: Aitkin | F9: MCGREGOR PUBLIC SCHOOL DISTRICT | G9: 0004 | J9: 421.83 | K9: 362632 | L9: 571834 | M9: 934466 | N9: 3626076 | O9: 220535 | P9: 90345 | Q9: 3936956 | R9: 400799 | S9: 5272221 | T9: 237907 | U9: 146635 | V9: 0 | W9: 750977 | X9: 6407741 | Y9: 1093875 | Z9: 741527 | AA9: 4047284 | AB9: 525055 | AC9: 06-07 | AD9: 4 | AE9: 1 | AF9: MCGREGOR PUBLIC SCHOOL DISTRICT | AG9: 33513.61 | AH9: 1 | AI9: MCGREGOR PUBLIC SCHOOL DISTRICT | AJ9: 0 | AK9: =AG9*AM9 -> -33513.61 | AL9: =AJ9*AM9 -> 0 | AM9: -1 | AO9: =Y9-K9 -> 731243 | AP9: =Z9-L9 -> 169693 | AQ9: =AA9-Q9 -> 110328 | AR9: =AB9-R9 -> 124256
A10: 11 | B10: Twin Cities Metropolitan Area | C10: 03 | D10: 19 | E10: Dakota | F10: SOUTH ST. PAUL PUBLIC SCHOOL DIST. | G10: 0006 | J10: 3331.77 | K10: 4375528 | L10: 1428160 | M10: 5803688 | N10: 21969776 | O10: 2395108 | P10: 590260 | Q10: 24955144 | R10: 1212734 | S10: 31971566 | T10: 1513869 | U10: 2039417 | V10: 0 | W10: 2582813 | X10: 38107665 | Y10: 6668375 | Z10: 3819649 | AA10: 25722047 | AB10: 1897594 | AC10: 06-07 | AD10: 6 | AE10: 3 | AF10: SOUTH ST. PAUL PUBLIC SCHOOL DIST. | AG10: 529225.97 | AH10: 3 | AI10: SOUTH ST. PAUL PUBLIC SCHOOL DIST. | AJ10: 429155.35 | AK10: =AG10*AM10 -> -529225.97 | AL10: =AJ10*AM10 -> -429155.35 | AM10: -1 | AO10: =Y10-K10 -> 2292847 | AP10: =Z10-L10 -> 2391489 | AQ10: =AA10-Q10 -> 766903 | AR10: =AB10-R10 -> 684860
A11: 11 | B11: Twin Cities Metropolitan Area | C11: 01 | D11: 2 | E11: Anoka | F11: ANOKA-HENNEPIN PUBLIC SCHOOL DIST. | G11: 0011 | J11: 41062.22 | K11: 43956546 | L11: 16656073 | M11: 60612619 | N11: 261189813 | O11: 32332020 | P11: 8770426 | Q11: 302292259 | R11: 12194021 | S11: 375098899 | T11: 17386532 | U11: 18176536 | V11: 378597 | W11: 23642958 | X11: 434683523 | Y11: 67622629 | Z11: 40522729 | AA11: 308838462 | AB11: 17699703 | AC11: 06-07 | AD11: 11 | AE11: 1 | AF11: ANOKA-HENNEPIN PUBLIC SCHOOL DIST. | AG11: 3155425.1 | AH11: 1 | AI11: ANOKA-HENNEPIN PUBLIC SCHOOL DIST. | AJ11: 2883706.4 | AK11: =AG11*AM11 -> -3155425.1 | AL11: =AJ11*AM11 -> -2883706.4 | AM11: -1 | AO11: =Y11-K11 -> 23666083 | AP11: =Z11-L11 -> 23866656 | AQ11: =AA11-Q11 -> 6546203 | AR11: =AB11-R11 -> 5505682
A12: 11 | B12: Twin Cities Metropolitan Area | C12: 01 | D12: 2 | E12: Anoka | F12: CENTENNIAL PUBLIC SCHOOL DISTRICT | G12: 0012 | J12: 6985.42 | K12: 5921669 | L12: 2129295 | M12: 8050964 | N12: 45247529 | O12: 6124782 | P12: 162398 | Q12: 51534709 | R12: 1658177 | S12: 61243850 | T12: 2739209 | U12: 2762687 | V12: 0 | W12: 11144656 | X12: 77890403 | Y12: 14114841 | Z12: 7670914 | AA12: 53873080 | AB12: 2231568 | AC12: 06-07 | AD12: 12 | AE12: 1 | AF12: CENTENNIAL PUBLIC SCHOOL DISTRICT | AG12: 399860.9 | AH12: 1 | AI12: CENTENNIAL PUBLIC SCHOOL DISTRICT | AJ12: 46184.74 | AK12: =AG12*AM12 -> -399860.9 | AL12: =AJ12*AM12 -> -46184.74 | AM12: -1 | AO12: =Y12-K12 -> 8193172 | AP12: =Z12-L12 -> 5541619 | AQ12: =AA12-Q12 -> 2338371 | AR12: =AB12-R12 -> 573391
A13: 11 | B13: Twin Cities Metropolitan Area | C13: 01 | D13: 2 | E13: Anoka | F13: COLUMBIA HEIGHTS PUBLIC SCHOOL DIST | G13: 0013 | J13: 3007.27 | K13: 4364222 | L13: 1241359 | M13: 5605581 | N13: 21076189 | O13: 2419271 | P13: 1225006 | Q13: 24720466 | R13: 1588601 | S13: 31914648 | T13: 1401247 | U13: 845664 | V13: 278137 | W13: 3383227 | X13: 37822921 | Y13: 6946875 | Z13: 3271324 | AA13: 25136697 | AB13: 2468025 | AC13: 06-07 | AD13: 13 | AE13: 1 | AF13: COLUMBIA HEIGHTS PUBLIC SCHOOL DIST | AG13: 295832.13 | AH13: 1 | AI13: COLUMBIA HEIGHTS PUBLIC SCHOOL DIST | AJ13: 6533.52 | AK13: =AG13*AM13 -> -295832.13 | AL13: =AJ13*AM13 -> -6533.52 | AM13: -1 | AO13: =Y13-K13 -> 2582653 | AP13: =Z13-L13 -> 2029965 | AQ13: =AA13-Q13 -> 416231 | AR13: =AB13-R13 -> 879424
A14: 11 | B14: Twin Cities Metropolitan Area | C14: 01 | D14: 2 | E14: Anoka | F14: FRIDLEY PUBLIC SCHOOL DISTRICT | G14: 0014 | J14: 2617.16 | K14: 4032545 | L14: 901577 | M14: 4934122 | N14: 17240811 | O14: 2748286 | P14: 512181 | Q14: 20501278 | R14: 1622095 | S14: 27057495 | T14: 1262958 | U14: 1629777 | V14: 49172 | W14: 1006512 | X14: 31005914 | Y14: 5259264 | Z14: 2460173 | AA14: 21077801 | AB14: 2208676 | AC14: 06-07 | AD14: 14 | AE14: 1 | AF14: FRIDLEY PUBLIC SCHOOL DISTRICT | AG14: 197003.37 | AH14: 1 | AI14: FRIDLEY PUBLIC SCHOOL DISTRICT | AJ14: 45764 | AK14: =AG14*AM14 -> -197003.37 | AL14: =AJ14*AM14 -> -45764 | AM14: -1 | AO14: =Y14-K14 -> 1226719 | AP14: =Z14-L14 -> 1558596 | AQ14: =AA14-Q14 -> 576523 | AR14: =AB14-R14 -> 586581
A15: 11 | B15: Twin Cities Metropolitan Area | C15: 01 | D15: 2 | E15: Anoka | F15: ST. FRANCIS PUBLIC SCHOOL DISTRICT | G15: 0015 | J15: 5879.67 | K15: 4143303 | L15: 3622109 | M15: 7765412 | N15: 37742931 | O15: 2948520 | P15: 212446 | Q15: 40903897 | R15: 1663583 | S15: 50332892 | T15: 2522340 | U15: 2144025 | V15: 216362 | W15: 4514165 | X15: 59729783 | Y15: 8341332 | Z15: 7367531 | AA15: 41619575 | AB15: 2401345 | AC15: 06-07 | AD15: 15 | AE15: 1 | AF15: ST. FRANCIS PUBLIC SCHOOL DISTRICT | AG15: 357035.83 | AH15: 1 | AI15: ST. FRANCIS PUBLIC SCHOOL DISTRICT | AJ15: 77119.78 | AK15: =AG15*AM15 -> -357035.83 | AL15: =AJ15*AM15 -> -77119.78 | AM15: -1 | AO15: =Y15-K15 -> 4198029 | AP15: =Z15-L15 -> 3745422 | AQ15: =AA15-Q15 -> 715678 | AR15: =AB15-R15 -> 737762
A16: 11 | B16: Twin Cities Metropolitan Area | C16: 01 | D16: 2 | E16: Anoka | F16: SPRING LAKE PARK PUBLIC SCHOOLS | G16: 0016 | J16: 4712.17 | K16: 5727758 | L16: 1753294 | M16: 7481052 | N16: 28313376 | O16: 2695964 | P16: 215791 | Q16: 31225131 | R16: 1646160 | S16: 40352343 | T16: 1656756 | U16: 2087106 | V16: 4322772 | W16: 2966882 | X16: 51385859 | Y16: 10377295 | Z16: 6919759 | AA16: 31601453 | AB16: 2487352 | AC16: 06-07 | AD16: 16 | AE16: 1 | AF16: SPRING LAKE PARK PUBLIC SCHOOLS | AG16: 251104.86 | AH16: 1 | AI16: SPRING LAKE PARK PUBLIC SCHOOLS | AJ16: 0 | AK16: =AG16*AM16 -> -251104.86 | AL16: =AJ16*AM16 -> 0 | AM16: -1 | AO16: =Y16-K16 -> 4649537 | AP16: =Z16-L16 -> 5166465 | AQ16: =AA16-Q16 -> 376322 | AR16: =AB16-R16 -> 841192
A17: 4 | B17: West Central Minnesota | C17: 01 | D17: 3 | E17: Becker | F17: DETROIT LAKES PUBLIC SCHOOL DIST. | G17: 0022 | J17: 2740.58 | K17: 1347341 | L17: 1331261 | M17: 2678602 | N17: 17848049 | O17: 1881048 | P17: 282182 | Q17: 20011279 | R17: 1499213 | S17: 24189094 | T17: 985590 | U17: 649159 | V17: 0 | W17: 1392084 | X17: 27215927 | Y17: 2662112 | Z17: 2222348 | AA17: 20417666 | AB17: 1913801 | AC17: 06-07 | AD17: 22 | AE17: 1 | AF17: DETROIT LAKES PUBLIC SCHOOL DIST. | AG17: 184375.54 | AH17: 1 | AI17: DETROIT LAKES PUBLIC SCHOOL DIST. | AJ17: 124309.58 | AK17: =AG17*AM17 -> -184375.54 | AL17: =AJ17*AM17 -> -124309.58 | AM17: -1 | AO17: =Y17-K17 -> 1314771 | AP17: =Z17-L17 -> 891087 | AQ17: =AA17-Q17 -> 406387 | AR17: =AB17-R17 -> 414588
A18: 4 | B18: West Central Minnesota | C18: 01 | D18: 3 | E18: Becker | F18: FRAZEE-VERGAS PUBLIC SCHOOL DIST. | G18: 0023 | J18: 1019.77 | K18: 324335 | L18: 529269 | M18: 853604 | N18: 6959062 | O18: 573577 | P18: 28893 | Q18: 7561532 | R18: 579931 | S18: 8995067 | T18: 428245 | U18: 200231 | V18: 0 | W18: 1010079 | X18: 10633621 | Y18: 1244281 | Z18: 793982 | AA18: 7783584 | AB18: 811774 | AC18: 06-07 | AD18: 23 | AE18: 1 | AF18: FRAZEE-VERGAS PUBLIC SCHOOL DIST. | AG18: 92910.66 | AH18: 1 | AI18: FRAZEE-VERGAS PUBLIC SCHOOL DIST. | AJ18: 0 | AK18: =AG18*AM18 -> -92910.66 | AL18: =AJ18*AM18 -> 0 | AM18: -1 | AO18: =Y18-K18 -> 919946 | AP18: =Z18-L18 -> 264713 | AQ18: =AA18-Q18 -> 222052 | AR18: =AB18-R18 -> 231843
A19: 4 | B19: West Central Minnesota | C19: 01 | D19: 3 | E19: Becker | F19: PINE POINT PUBLIC SCHOOL DISTRICT | G19: 0025 | J19: 63.82 | K19: 0 | L19: 201650 | M19: 201650 | N19: 534471 | O19: 77184 | P19: 112998 | Q19: 724653 | R19: 447403 | S19: 1373706 | T19: 61029 | U19: 687185 | V19: 0 | W19: 0 | X19: 2121921 | Y19: 0 | Z19: 257949 | AA19: 756175 | AB19: 1107797 | AC19: 06-07 | AD19: 25 | AE19: 1 | AF19: PINE POINT PUBLIC SCHOOL DISTRICT | AG19: 41869.19 | AH19: 1 | AI19: PINE POINT PUBLIC SCHOOL DISTRICT | AJ19: 0 | AK19: =AG19*AM19 -> -41869.19 | AL19: =AJ19*AM19 -> 0 | AM19: -1 | AO19: =Y19-K19 -> 0 | AP19: =Z19-L19 -> 56299 | AQ19: =AA19-Q19 -> 31522 | AR19: =AB19-R19 -> 660394
... A196: 11 | B196: Twin Cities Metropolitan Area | C196: 01 | D196: 62 | E196: Ramsey | F196: WHITE BEAR LAKE SCHOOL DISTRICT | G196: 0624 | J196: 8636.64 | K196: 13069286 | L196: 2330619 | M196: 15399905 | N196: 51388885 | O196: 7330916 | P196: 1518204 | Q196: 60238005 | R196: 2360414 | S196: 77998324 | T196: 3762902 | U196: 4050704 | V196: 1793277 | W196: 7003993 | X196: 94609201 | Y196: 20693864 | Z196: 9425383 | AA196: 61009375 | AB196: 3480579 | AC196: 06-07 | AD196: 624 | AE196: 1 | AF196: WHITE BEAR LAKE SCHOOL DISTRICT | AG196: 449533.57 | AH196: 1 | AI196: WHITE BEAR LAKE SCHOOL DISTRICT | AJ196: 8641.03 | AK196: =AG196*AM196 -> -449533.57 | AL196: =AJ196*AM196 -> -8641.03 | AM196: -1 | AO196: =Y196-K196 -> 7624578 | AP196: =Z196-L196 -> 7094764 | AQ196: =AA196-Q196 -> 771370 | AR196: =AB196-R196 -> 1120165
A197: 11 | B197: Twin Cities Metropolitan Area | C197: 01 | D197: 62 | E197: Ramsey | F197: ST. PAUL PUBLIC SCHOOL DISTRICT | G197: 0625 | H197: District | I197: St. Paul | J197: 42379.85 | K197: 48650687 | L197: 18437068 | M197: 67087755 | N197: 329659792 | O197: 43546172 | P197: 23370195 | Q197: 396576159 | R197: 41434769 | S197: 505098683 | T197: 20203751 | U197: 25727064 | V197: 2428882 | W197: 33879553 | X197: 587337933 | Y197: 80223356 | Z197: 31397027 | AA197: 414138351 | AB197: 61579199 | AC197: 06-07 | AD197: 625 | AE197: 1 | AF197: ST. PAUL PUBLIC SCHOOL DISTRICT | AG197: 5597682.3 | AH197: 1 | AI197: ST. PAUL PUBLIC SCHOOL DISTRICT | AJ197: 9194966.1 | AK197: =AG197*AM197 -> -5597682.3 | AL197: =AJ197*AM197 -> -9194966.1 | AM197: -1 | AO197: =Y197-K197 -> 31572669 | AP197: =Z197-L197 -> 12959959 | AQ197: =AA197-Q197 -> 17562192 | AR197: =AB197-R197 -> 20144430
A198: 1 | B198: Northwest Minnesota | C198: 01 | D198: 63 | E198: Red Lake | F198: OKLEE PUBLIC SCHOOL DISTRICT | G198: 0627 | J198: 245.46 | K198: 148368 | L198: 293101 | M198: 441469 | N198: 1914632 | O198: 91835 | P198: 17653 | Q198: 2024120 | R198: 47102 | S198: 2512691 | T198: 77741 | U198: 36534 | V198: 0 | W198: 0 | X198: 2626965 | Y198: 156707 | Z198: 321262 | AA198: 2052367 | AB198: 96629 | AC198: 06-07 | AD198: 627 | AE198: 1 | AF198: OKLEE PUBLIC SCHOOL DISTRICT | AG198: 22632.26 | AH198: 1 | AI198: OKLEE PUBLIC SCHOOL DISTRICT | AJ198: 0 | AK198: =AG198*AM198 -> -22632.26 | AL198: =AJ198*AM198 -> 0 | AM198: -1 | AO198: =Y198-K198 -> 8339 | AP198: =Z198-L198 -> 28161 | AQ198: =AA198-Q198 -> 28247 | AR198: =AB198-R198 -> 49527
A199: 1 | B199: Northwest Minnesota | C199: 01 | D199: 63 | E199: Red Lake | F199: PLUMMER PUBLIC SCHOOL DISTRICT | G199: 0628 | J199: 229.96 | K199: 162657 | L199: 445957 | M199: 608614 | N199: 1075937 | O199: 169125 | P199: 10391 | Q199: 1255453 | R199: 134894 | S199: 1998961 | T199: 103912 | U199: 60142 | V199: 0 | W199: 0 | X199: 2163015 | Y199: 183117 | Z199: 490106 | AA199: 1291088 | AB199: 198704 | AC199: 06-07 | AD199: 628 | AE199: 1 | AF199: PLUMMER PUBLIC SCHOOL DISTRICT | AG199: 22685.57 | AH199: 1 | AI199: PLUMMER PUBLIC SCHOOL DISTRICT | AJ199: 0 | AK199: =AG199*AM199 -> -22685.57 | AL199: =AJ199*AM199 -> 0 | AM199: -1 | AO199: =Y199-K199 -> 20460 | AP199: =Z199-L199 -> 44149 | AQ199: =AA199-Q199 -> 35635 | AR199: =AB199-R199 -> 63810
A200: 1 | B200: Northwest Minnesota | C200: 01 | D200: 63 | E200: Red Lake | F200: RED LAKE FALLS PUBLIC SCHOOL DIST. | G200: 0630 | J200: 379.51 | K200: 186066 | L200: 168707 | M200: 354773 | N200: 3041414 | O200: 343943 | P200: 41478 | Q200: 3426835 | R200: 152990 | S200: 3934598 | T200: 181351 | U200: 78621 | V200: 0 | W200: 486947 | X200: 4681517 | Y200: 397248 | Z200: 284487 | AA200: 3767172 | AB200: 232609 | AC200: 06-07 | AD200: 630 | AE200: 1 | AF200: RED LAKE FALLS PUBLIC SCHOOL DIST. | AG200: 29341.52 | AH200: 1 | AI200: RED LAKE FALLS PUBLIC SCHOOL DIST. | AJ200: 0 | AK200: =AG200*AM200 -> -29341.52 | AL200: =AJ200*AM200 -> 0 | AM200: -1 | AO200: =Y200-K200 -> 211182 | AP200: =Z200-L200 -> 115780 | AQ200: =AA200-Q200 -> 340337 | AR200: =AB200-R200 -> 79619
A201: 8 | B201: Southwest Minnesota | C201: 01 | D201: 64 | E201: Redwood | F201: MILROY PUBLIC SCHOOL DISTRICT | G201: 0635 | J201: 69.9 | K201: 144924 | L201: 159717 | M201: 304641 | N201: 572890 | O201: -22840 | P201: 17252 | Q201: 567302 | R201: 56313 | S201: 928256 | T201: 45035 | U201: 34837 | V201: 0 | W201: 0 | X201: 1008127 | Y201: 156666 | Z201: 188930 | AA201: 583271 | AB201: 79260 | AC201: 06-07 | AD201: 635 | AE201: 1 | AF201: MILROY PUBLIC SCHOOL DISTRICT | AG201: 14733.53 | AH201: 1 | AI201: MILROY PUBLIC SCHOOL DISTRICT | AJ201: 0 | AK201: =AG201*AM201 -> -14733.53 | AL201: =AJ201*AM201 -> 0 | AM201: -1 | AO201: =Y201-K201 -> 11742 | AP201: =Z201-L201 -> 29213 | AQ201: =AA201-Q201 -> 15969 | AR201: =AB201-R201 -> 22947
A202: 8 | B202: Southwest Minnesota | C202: 01 | D202: 64 | E202: Redwood | F202: WABASSO PUBLIC SCHOOL DISTRICT | G202: 0640 | J202: 402.19 | K202: 238819 | L202: 195221 | M202: 434040 | N202: 2802615 | O202: 167586 | P202: 74977 | Q202: 3045178 | R202: 150358 | S202: 3629576 | T202: 176686 | U202: 95696 | V202: 0 | W202: 484542 | X202: 4386500 | Y202: 580478 | Z202: 465270 | AA202: 3119492 | AB202: 221260 | AC202: 06-07 | AD202: 640 | AE202: 1 | AF202: WABASSO PUBLIC SCHOOL DISTRICT | AG202: 39033.96 | AH202: 1 | AI202: WABASSO PUBLIC SCHOOL DISTRICT | AJ202: 0 | AK202: =AG202*AM202 -> -39033.96 | AL202: =AJ202*AM202 -> 0 | AM202: -1 | AO202: =Y202-K202 -> 341659 | AP202: =Z202-L202 -> 270049 | AQ202: =AA202-Q202 -> 74314 | AR202: =AB202-R202 -> 70902
A203: 10 | B203: Southeast Minnesota | C203: 01 | D203: 66 | E203: Rice | F203: FARIBAULT PUBLIC SCHOOL DISTRICT | G203: 0656 | J203: 4058.93 | K203: 2724651 | L203: 1545729 | M203: 4270380 | N203: 26710861 | O203: 2872560 | P203: 259970 | Q203: 29843391 | R203: 2072172 | S203: 36185943 | T203: 1955907 | U203: 2522704 | V203: 7198 | W203: 4666791 | X203: 45338543 | Y203: 7030250 | Z203: 3520143 | AA203: 31061382 | AB203: 3726768 | AC203: 06-07 | AD203: 656 | AE203: 1 | AF203: FARIBAULT PUBLIC SCHOOL DISTRICT | AG203: 348147.75 | AH203: 1 | AI203: FARIBAULT PUBLIC SCHOOL DISTRICT | AJ203: 412448.22 | AK203: =AG203*AM203 -> -348147.75 | AL203: =AJ203*AM203 -> -412448.22 | AM203: -1 | AO203: =Y203-K203 -> 4305599 | AP203: =Z203-L203 -> 1974414 | AQ203: =AA203-Q203 -> 1217991 | AR203: =AB203-R203 -> 1654596
A204: 10 | B204: Southeast Minnesota | C204: 01 | D204: 66 | E204: Rice | F204: NORTHFIELD PUBLIC SCHOOL DISTRICT | G204: 0659 | J204: 3944.86 | K204: 4376967 | L204: 1458002 | M204: 5834969 | N204: 24572268 | O204: 1884185 | P204: 259912 | Q204: 26716365 | R204: 1308168 | S204: 33859502 | T204: 1690285 | U204: 2008557 | V204: 64469 | W204: 5562520 | X204: 43185333 | Y204: 9857276 | Z204: 4228288 | AA204: 27319200 | AB204: 1780569 | AC204: 06-07 | AD204: 659 | AE204: 1 | AF204: NORTHFIELD PUBLIC SCHOOL DISTRICT | AG204: 368495.78 | AH204: 1 | AI204: NORTHFIELD PUBLIC SCHOOL DISTRICT | AJ204: 15029 | AK204: =AG204*AM204 -> -368495.78 | AL204: =AJ204*AM204 -> -15029 | AM204: -1 | AO204: =Y204-K204 -> 5480309 | AP204: =Z204-L204 -> 2770286 | AQ204: =AA204-Q204 -> 602835 | AR204: =AB204-R204 -> 472401
A205: 8 | B205: Southwest Minnesota | C205: 01 | D205: 67 | E205: Rock | F205: HILLS-BEAVER CREEK SCHOOL DISTRICT | G205: 0671 | J205: 339.54 | K205: 201896 | L205: 159749 | M205: 361645 | N205: 2382775 | O205: 145498 | P205: 16848 | Q205: 2545121 | R205: 91279 | S205: 2998045 | T205: 132644 | U205: 78344 | V205: 0 | W205: 178002 | X205: 3387035 | Y205: 375605 | Z205: 275839 | AA205: 2586627 | AB205: 148963 | AC205: 06-07 | AD205: 671 | AE205: 1 | AF205: HILLS-BEAVER CREEK SCHOOL DISTRICT | AG205: 20391.98 | AH205: 1 | AI205: HILLS-BEAVER CREEK SCHOOL DISTRICT | AJ205: 0 | AK205: =AG205*AM205 -> -20391.98 | AL205: =AJ205*AM205 -> 0 | AM205: -1 | AO205: =Y205-K205 -> 173709 | AP205: =Z205-L205 -> 116090 | AQ205: =AA205-Q205 -> 41506 | AR205: =AB205-R205 -> 57684
A206: 1 | B206: Northwest Minnesota | C206: 01 | D206: 68 | E206: Roseau | F206: BADGER PUBLIC SCHOOL DISTRICT | G206: 0676 | J206: 226.99 | K206: 183259 | L206: 181091 | M206: 364350 | N206: 1875831 | O206: 91198 | P206: 27430 | Q206: 1994459 | R206: 68634 | S206: 2427443 | T206: 110203 | U206: 37512 | V206: 0 | W206: 53686 | X206: 2628845 | Y206: 233270 | Z206: 226010 | AA206: 2036959 | AB206: 132605 | AC206: 06-07 | AD206: 676 | AE206: 1 | AF206: BADGER PUBLIC SCHOOL DISTRICT | AG206: 20448.88 | AH206: 1 | AI206: BADGER PUBLIC SCHOOL DISTRICT | AJ206: 0 | AK206: =AG206*AM206 -> -20448.88 | AL206: =AJ206*AM206 -> 0 | AM206: -1 | AO206: =Y206-K206 -> 50011 | AP206: =Z206-L206 -> 44919 | AQ206: =AA206-Q206 -> 42500 | AR206: =AB206-R206 -> 63971
A207: 1 | B207: Northwest Minnesota | C207: 01 | D207: 68 | E207: Roseau | F207: ROSEAU PUBLIC SCHOOL DISTRICT | G207: 0682 | J207: 1333.17 | K207: 559893 | L207: 507903 | M207: 1067796 | N207: 9141472 | O207: 738031 | P207: 70128 | Q207: 9949631 | R207: 415248 | S207: 11432675 | T207: 484686 | U207: 309307 | V207: 0 | W207: 1400851 | X207: 13627519 | Y207: 1571428 | Z207: 1082877 | AA207: 10391671 | AB207: 581543 | AC207: 06-07 | AD207: 682 | AE207: 1 | AF207: ROSEAU PUBLIC SCHOOL DISTRICT | AG207: 89591.06 | AH207: 1 | AI207: ROSEAU PUBLIC SCHOOL DISTRICT | AJ207: 0 | AK207: =AG207*AM207 -> -89591.06 | AL207: =AJ207*AM207 -> 0 | AM207: -1 | AO207: =Y207-K207 -> 1011535 | AP207: =Z207-L207 -> 574974 | AQ207: =AA207-Q207 -> 442040 | AR207: =AB207-R207 -> 166295
A208: 1 | B208: Northwest Minnesota | C208: 01 | D208: 68 | E208: Roseau | F208: WARROAD PUBLIC SCHOOL DISTRICT | G208: 0690 | J208: 1261.52 | K208: 456583 | L208: 854426 | M208: 1311009 | N208: 8717220 | O208: 444674 | P208: 224178 | Q208: 9386072 | R208: 649488 | S208: 11346569 | T208: 499742 | U208: 556417 | V208: 38777 | W208: 1293227 | X208: 13734731 | Y208: 1391098 | Z208: 1442918 | AA208: 10025091 | AB208: 875624 | AC208: 06-07 | AD208: 690 | AE208: 1 | AF208: WARROAD PUBLIC SCHOOL DISTRICT | AG208: 109254.74 | AH208: 1 | AI208: WARROAD PUBLIC SCHOOL DISTRICT | AJ208: 0 | AK208: =AG208*AM208 -> -109254.74 | AL208: =AJ208*AM208 -> 0 | AM208: -1 | AO208: =Y208-K208 -> 934515 | AP208: =Z208-L208 -> 588492 | AQ208: =AA208-Q208 -> 639019 | AR208: =AB208-R208 -> 226136
A209: 3 | B209: Northeast Minnesota | C209: 01 | D209: 69 | E209: Saint Louis | F209: CHISHOLM PUBLIC SCHOOL DISTRICT | G209: 0695 | J209: 757.37 | K209: 483555 | L209: 1212906 | M209: 1696461 | N209: 5280620 | O209: 165386 | P209: 94746 | Q209: 5540752 | R209: 307940 | S209: 7545153 | T209: 262046 | U209: 168485 | V209: 0 | W209: 820611 | X209: 8796296 | Y209: 638347 | Z209: 1939270 | AA209: 5749211 | AB209: 469468 | AC209: 06-07 | AD209: 695 | AE209: 1 | AF209: CHISHOLM PUBLIC SCHOOL DISTRICT | AG209: 58610.12 | AH209: 1 | AI209: CHISHOLM PUBLIC SCHOOL DISTRICT | AJ209: 0 | AK209: =AG209*AM209 -> -58610.12 | AL209: =AJ209*AM209 -> 0 | AM209: -1 | AO209: =Y209-K209 -> 154792 | AP209: =Z209-L209 -> 726364 | AQ209: =AA209-Q209 -> 208459 | AR209: =AB209-R209 -> 161528
... A345: 8 | B345: Southwest Minnesota | C345: 01 | D345: 41 | E345: Lincoln | F345: RTR PUBLIC SCHOOLS | G345: 2902 | J345: 564.36 | K345: 406449 | L345: 300075 | M345: 706524 | N345: 3790735 | O345: 148612 | P345: 338771 | Q345: 4278118 | R345: 388758 | S345: 5373400 | T345: 281159 | U345: 97801 | V345: 0 | W345: 62577 | X345: 5814939 | Y345: 503607 | Z345: 480585 | AA345: 4329076 | AB345: 501671 | AC345: 06-07 | AD345: 2902 | AE345: 1 | AF345: RTR PUBLIC SCHOOLS | AG345: 46641.83 | AH345: 1 | AI345: RTR PUBLIC SCHOOLS | AJ345: 0 | AK345: =AG345*AM345 -> -46641.83 | AL345: =AJ345*AM345 -> 0 | AM345: -1 | AO345: =Y345-K345 -> 97158 | AP345: =Z345-L345 -> 180510 | AQ345: =AA345-Q345 -> 50958 | AR345: =AB345-R345 -> 112913
A346: 11 | B346: Twin Cities Metropolitan Area | C346: 07 | D346: 62 | E346: Ramsey | F346: ACADEMIA CESAR CHAVEZ CHARTER SCH. | G346: 4073 | H346: Charter | I346: St. Paul | J346: 262.75 | K346: 0 | L346: 47885 | M346: 47885 | N346: 2086879 | O346: 198549 | P346: 270454 | Q346: 2555882 | R346: 184592 | S346: 2788359 | T346: 146884 | U346: 0 | V346: 0 | W346: 0 | X346: 2935244 | Y346: 0 | Z346: 51947 | AA346: 2564036 | AB346: 319261 | AC346: 06-07 | AD346: 4073 | AE346: 7 | AF346: ACADEMIA CESAR CHAVEZ CHARTER SCH. | AG346: 0 | AH346: 7 | AI346: ACADEMIA CESAR CHAVEZ CHARTER SCH. | AJ346: 0 | AK346: =AG346*AM346 -> 0 | AL346: =AJ346*AM346 -> 0 | AM346: -1 | AO346: =Y346-K346 -> 0 | AP346: =Z346-L346 -> 4062 | AQ346: =AA346-Q346 -> 8154 | AR346: =AB346-R346 -> 134669
A347: 10 | B347: Southeast Minnesota | C347: 07 | D347: 85 | E347: Winona | F347: ACADEMY OF BIOSCIENCES | G347: 4148 | H347: Charter | I347: Statewide | J347: 157.75 | K347: 0 | L347: 17595 | M347: 17595 | N347: 1119571 | O347: 81301 | P347: 330392 | Q347: 1531264 | R347: 233166 | S347: 1782025 | T347: 62354 | U347: 0 | V347: 0 | W347: 0 | X347: 1844380 | Y347: 0 | Z347: 42665 | AA347: 1534220 | AB347: 267495 | AC347: 06-07 | AD347: 4148 | AE347: 7 | AF347: ACADEMY OF BIOSCIENCES | AG347: 0 | AH347: 7 | AI347: ACADEMY OF BIOSCIENCES | AJ347: 0 | AK347: =AG347*AM347 -> 0 | AL347: =AJ347*AM347 -> 0 | AM347: -1 | AO347: =Y347-K347 -> 0 | AP347: =Z347-L347 -> 25070 | AQ347: =AA347-Q347 -> 2956 | AR347: =AB347-R347 -> 34329
A348: 11 | B348: Twin Cities Metropolitan Area | C348: 07 | D348: 82 | E348: Washington | F348: ACHIEVE LANGUAGE ACADEMY | G348: 4018 | H348: Charter | I348: St. Paul | J348: 409.08 | K348: 0 | L348: 89030 | M348: 89030 | N348: 3228896 | O348: 182561 | P348: 598530 | Q348: 4009987 | R348: 227280 | S348: 4326297 | T348: 0 | U348: 24975 | V348: 0 | W348: 0 | X348: 4351272 | Y348: 0 | Z348: 114005 | AA348: 4009987 | AB348: 227280 | AC348: 06-07 | AD348: 4018 | AE348: 7 | AF348: ACHIEVE LANGUAGE ACADEMY | AG348: 0 | AH348: 7 | AI348: ACHIEVE LANGUAGE ACADEMY | AJ348: 0 | AK348: =AG348*AM348 -> 0 | AL348: =AJ348*AM348 -> 0 | AM348: -1 | AO348: =Y348-K348 -> 0 | AP348: =Z348-L348 -> 24975 | AQ348: =AA348-Q348 -> 0 | AR348: =AB348-R348 -> 0
A349: 11 | B349: Twin Cities Metropolitan Area | C349: 07 | D349: 27 | E349: Hennepin | F349: ADAM ABDULLE ACADEMY | G349: 4135 | H349: Charter | I349: Statewide | J349: 112.29 | K349: 0 | L349: 1278 | M349: 1278 | N349: 1080750 | O349: 19392 | P349: 266690 | Q349: 1366832 | R349: 176006 | S349: 1544116 | T349: 67570 | U349: 0 | V349: 0 | W349: 0 | X349: 1611686 | Y349: 0 | Z349: 1278 | AA349: 1368860 | AB349: 241548 | AC349: 06-07 | AD349: 4135 | AE349: 7 | AF349: ADAM ABDULLE ACADEMY | AG349: 0 | AH349: 7 | AI349: ADAM ABDULLE ACADEMY | AJ349: 0 | AK349: =AG349*AM349 -> 0 | AL349: =AJ349*AM349 -> 0 | AM349: -1 | AO349: =Y349-K349 -> 0 | AP349: =Z349-L349 -> 0 | AQ349: =AA349-Q349 -> 2028 | AR349: =AB349-R349 -> 65542
A350: 11 | B350: Twin Cities Metropolitan Area | C350: 07 | D350: 62 | E350: Ramsey | F350: AGRICULTURAL FOOD SCIENCE ACADEMY | G350: 4074 | H350: Charter | I350: Statewide | J350: 203.87 | K350: 0 | L350: 271848 | M350: 271848 | N350: 1439440 | O350: 376937 | P350: 366283 | Q350: 2182660 | R350: 69454 | S350: 2523962 | T350: 38080 | U350: 0 | V350: 0 | W350: 0 | X350: 2562042 | Y350: 0 | Z350: 288268 | AA350: 2184563 | AB350: 89211 | AC350: 06-07 | AD350: 4074 | AE350: 7 | AF350: AGRICULTURAL FOOD SCIENCE ACADEMY | AG350: 0 | AH350: 7 | AI350: AGRICULTURAL FOOD SCIENCE ACADEMY | AJ350: 0 | AK350: =AG350*AM350 -> 0 | AL350: =AJ350*AM350 -> 0 | AM350: -1 | AO350: =Y350-K350 -> 0 | AP350: =Z350-L350 -> 16420 | AQ350: =AA350-Q350 -> 1903 | AR350: =AB350-R350 -> 19757
A351: 11 | B351: Twin Cities Metropolitan Area | C351: 07 | D351: 62 | E351: Ramsey | F351: ARTECH | G351: 4091 | H351: Charter | I351: Statewide | J351: 122.6 | K351: 0 | L351: 16752 | M351: 16752 | N351: 854895 | O351: 203462 | P351: 178658 | Q351: 1237015 | R351: 32280 | S351: 1286047 | T351: 15134 | U351: 0 | V351: 0 | W351: 0 | X351: 1301181 | Y351: 0 | Z351: 27878 | AA351: 1237462 | AB351: 35841 | AC351: 06-07 | AD351: 4091 | AE351: 7 | AF351: ARTECH | AG351: 0 | AH351: 7 | AI351: ARTECH | AJ351: 0 | AK351: =AG351*AM351 -> 0 | AL351: =AJ351*AM351 -> 0 | AM351: -1 | AO351: =Y351-K351 -> 0 | AP351: =Z351-L351 -> 11126 | AQ351: =AA351-Q351 -> 447 | AR351: =AB351-R351 -> 3561
...

Sheet District St Wrk
F1: Click here for Definitions
A2: Economic Development Region Number | B2: Economic Development Region | C2: District Type | D2: County Number | E2: County Name | F2: Total Revenues FY07 | G2: District Number | J2: District ADM Served Plus Tuitioned Out | K2: General Fund Revenues
K3: Local Sources | O3: State Sources | R3: Federal Sources
H4: Charter | I4: Charter Location | K4: Property Taxes | L4: Other funds revenues distributed by Local Other State and Federal | M4: Other | O4: General Education Aid | P4: Special Education Aid | Q4: All Other State Aid | R4: Federal | S4: Federal | T4: Other
F5: Counties and Districts | K5: 1. | L5: Local | M5: 2. | N5: State | O5: 4. | P5: 5. | Q5: 6. | R5: 8. | U5: Early Childhood Reduction | V5: ABE Reduction
A6: 3 | B6: Northeast Minnesota | C6: 01 | D6: 1 | E6: Aitkin | F6: AITKIN PUBLIC SCHOOL DISTRICT | G6: 0001 | J6: 1322.2 | K6: 613626 | L6: 183370 | M6: 1325974 | N6: 78700 | O6: 8539952 | P6: 679449 | Q6: 52813 | R6: 255760 | S6: 259551 | T6: 569450 | U6: -98691.4 | V6: -109867.98
A7: 11 | B7: Twin Cities Metropolitan Area | C7: 03 | D7: 27 | E7: Hennepin | F7: MINNEAPOLIS PUBLIC SCHOOL DIST. | G7: 0001 | H7: District | I7: Minneapolis | J7: 39479.31 | K7: 58005565 | L7: 58143868 | M7: 20520348 | N7: 23620461 | O7: 293589390 | P7: 49228337 | Q7: 18490543 | R7: 52989194 | S7: 15279332 | T7: 18756992 | U7: -4444620.9 | V7: -7342147.7
A8: 3 | B8: Northeast Minnesota | C8: 01 | D8: 1 | E8: Aitkin | F8: HILL CITY PUBLIC SCHOOL DISTRICT | G8: 0002 | J8: 314.26 | K8: 59861 | L8: 281927 | M8: 422365 | N8: 116087 | O8: 2659597 | P8: 182721 | Q8: 6745 | R8: 145220 | S8: 86554 | T8: 85299 | U8: -24582.72 | V8: 0
A9: 3 | B9: Northeast Minnesota | C9: 01 | D9: 1 | E9: Aitkin | F9: MCGREGOR PUBLIC SCHOOL DISTRICT | G9: 0004 | J9: 421.83 | K9: 362632 | L9: 731243 | M9: 571834 | N9: 110328 | O9: 3626076 | P9: 220535 | Q9: 90345 | R9: 400799 | S9: 124256 | T9: 169693 | U9: -33513.61 | V9: 0
A10: 11 | B10: Twin Cities Metropolitan Area | C10: 03 | D10: 19 | E10: Dakota | F10: SOUTH ST. PAUL PUBLIC SCHOOL DIST. | G10: 0006 | J10: 3331.77 | K10: 4375528 | L10: 2292847 | M10: 1428160 | N10: 766903 | O10: 21969776 | P10: 2395108 | Q10: 590260 | R10: 1212734 | S10: 684860 | T10: 2391489 | U10: -529225.97 | V10: -429155.35
A11: 11 | B11: Twin Cities Metropolitan Area | C11: 01 | D11: 2 | E11: Anoka | F11: ANOKA-HENNEPIN PUBLIC SCHOOL DIST. | G11: 0011 | J11: 41062.22 | K11: 43956546 | L11: 23666083 | M11: 16656073 | N11: 6546203 | O11: 261189813 | P11: 32332020 | Q11: 8770426 | R11: 12194021 | S11: 5505682 | T11: 23866656 | U11: -3155425.1 | V11: -2883706.4
A12: 11 | B12: Twin Cities Metropolitan Area | C12: 01 | D12: 2 | E12: Anoka | F12: CENTENNIAL PUBLIC SCHOOL DISTRICT | G12: 0012 | J12: 6985.42 | K12: 5921669 | L12: 8193172 | M12: 2129295 | N12: 2338371 | O12: 45247529 | P12: 6124782 | Q12: 162398 | R12: 1658177 | S12: 573391 | T12: 5541619 | U12: -399860.9 | V12: -46184.74
A13: 11 | B13: Twin Cities Metropolitan Area | C13: 01 | D13: 2 | E13: Anoka | F13: COLUMBIA HEIGHTS PUBLIC SCHOOL DIST | G13: 0013 | J13: 3007.27 | K13: 4364222 | L13: 2582653 | M13: 1241359 | N13: 416231 | O13: 21076189 | P13: 2419271 | Q13: 1225006 | R13: 1588601 | S13: 879424 | T13: 2029965 | U13: -295832.13 | V13: -6533.52
A14: 11 | B14: Twin Cities Metropolitan Area | C14: 01 | D14: 2 | E14: Anoka | F14: FRIDLEY PUBLIC SCHOOL DISTRICT | G14: 0014 | J14: 2617.16 | K14: 4032545 | L14: 1226719 | M14: 901577 | N14: 576523 | O14: 17240811 | P14: 2748286 | Q14: 512181 | R14: 1622095 | S14: 586581 | T14: 1558596 | U14: -197003.37 | V14: -45764
A15: 11 | B15: Twin Cities Metropolitan Area | C15: 01 | D15: 2 | E15: Anoka | F15: ST. FRANCIS PUBLIC SCHOOL DISTRICT | G15: 0015 | J15: 5879.67 | K15: 4143303 | L15: 4198029 | M15: 3622109 | N15: 715678 | O15: 37742931 | P15: 2948520 | Q15: 212446 | R15: 1663583 | S15: 737762 | T15: 3745422 | U15: -357035.83 | V15: -77119.78
A16: 11 | B16: Twin Cities Metropolitan Area | C16: 01 | D16: 2 | E16: Anoka | F16: SPRING LAKE PARK PUBLIC SCHOOLS | G16: 0016 | J16: 4712.17 | K16: 5727758 | L16: 4649537 | M16: 1753294 | N16: 376322 | O16: 28313376 | P16: 2695964 | Q16: 215791 | R16: 1646160 | S16: 841192 | T16: 5166465 | U16: -251104.86 | V16: 0
A17: 4 | B17: West Central Minnesota | C17: 01 | D17: 3 | E17: Becker | F17: DETROIT LAKES PUBLIC SCHOOL DIST. | G17: 0022 | J17: 2740.58 | K17: 1347341 | L17: 1314771 | M17: 1331261 | N17: 406387 | O17: 17848049 | P17: 1881048 | Q17: 282182 | R17: 1499213 | S17: 414588 | T17: 891087 | U17: -184375.54 | V17: -124309.58
A18: 4 | B18: West Central Minnesota | C18: 01 | D18: 3 | E18: Becker | F18: FRAZEE-VERGAS PUBLIC SCHOOL DIST. | G18: 0023 | J18: 1019.77 | K18: 324335 | L18: 919946 | M18: 529269 | N18: 222052 | O18: 6959062 | P18: 573577 | Q18: 28893 | R18: 579931 | S18: 231843 | T18: 264713 | U18: -92910.66 | V18: 0
A19: 4 | B19: West Central Minnesota | C19: 01 | D19: 3 | E19: Becker | F19: PINE POINT PUBLIC SCHOOL DISTRICT | G19: 0025 | J19: 63.82 | K19: 0 | L19: 0 | M19: 201650 | N19: 31522 | O19: 534471 | P19: 77184 | Q19: 112998 | R19: 447403 | S19: 660394 | T19: 56299 | U19: -41869.19 | V19: 0
... A196: 11 | B196: Twin Cities Metropolitan Area | C196: 01 | D196: 62 | E196: Ramsey | F196: WHITE BEAR LAKE SCHOOL DISTRICT | G196: 0624 | J196: 8636.64 | K196: 13069286 | L196: 7624578 | M196: 2330619 | N196: 771370 | O196: 51388885 | P196: 7330916 | Q196: 1518204 | R196: 2360414 | S196: 1120165 | T196: 7094764 | U196: -449533.57 | V196: -8641.03
A197: 11 | B197: Twin Cities Metropolitan Area | C197: 01 | D197: 62 | E197: Ramsey | F197: ST. PAUL PUBLIC SCHOOL DISTRICT | G197: 0625 | H197: District | I197: St. Paul | J197: 42379.85 | K197: 48650687 | L197: 31572669 | M197: 18437068 | N197: 17562192 | O197: 329659792 | P197: 43546172 | Q197: 23370195 | R197: 41434769 | S197: 20144430 | T197: 12959959 | U197: -5597682.3 | V197: -9194966.1
A198: 1 | B198: Northwest Minnesota | C198: 01 | D198: 63 | E198: Red Lake | F198: OKLEE PUBLIC SCHOOL DISTRICT | G198: 0627 | J198: 245.46 | K198: 148368 | L198: 8339 | M198: 293101 | N198: 28247 | O198: 1914632 | P198: 91835 | Q198: 17653 | R198: 47102 | S198: 49527 | T198: 28161 | U198: -22632.26 | V198: 0
A199: 1 | B199: Northwest Minnesota | C199: 01 | D199: 63 | E199: Red Lake | F199: PLUMMER PUBLIC SCHOOL DISTRICT | G199: 0628 | J199: 229.96 | K199: 162657 | L199: 20460 | M199: 445957 | N199: 35635 | O199: 1075937 | P199: 169125 | Q199: 10391 | R199: 134894 | S199: 63810 | T199: 44149 | U199: -22685.57 | V199: 0
A200: 1 | B200: Northwest Minnesota | C200: 01 | D200: 63 | E200: Red Lake | F200: RED LAKE FALLS PUBLIC SCHOOL DIST. | G200: 0630 | J200: 379.51 | K200: 186066 | L200: 211182 | M200: 168707 | N200: 340337 | O200: 3041414 | P200: 343943 | Q200: 41478 | R200: 152990 | S200: 79619 | T200: 115780 | U200: -29341.52 | V200: 0
A201: 8 | B201: Southwest Minnesota | C201: 01 | D201: 64 | E201: Redwood | F201: MILROY PUBLIC SCHOOL DISTRICT | G201: 0635 | J201: 69.9 | K201: 144924 | L201: 11742 | M201: 159717 | N201: 15969 | O201: 572890 | P201: -22840 | Q201: 17252 | R201: 56313 | S201: 22947 | T201: 29213 | U201: -14733.53 | V201: 0
A202: 8 | B202: Southwest Minnesota | C202: 01 | D202: 64 | E202: Redwood | F202: WABASSO PUBLIC SCHOOL DISTRICT | G202: 0640 | J202: 402.19 | K202: 238819 | L202: 341659 | M202: 195221 | N202: 74314 | O202: 2802615 | P202: 167586 | Q202: 74977 | R202: 150358 | S202: 70902 | T202: 270049 | U202: -39033.96 | V202: 0
A203: 10 | B203: Southeast Minnesota | C203: 01 | D203: 66 | E203: Rice | F203: FARIBAULT PUBLIC SCHOOL DISTRICT | G203: 0656 | J203: 4058.93 | K203: 2724651 | L203: 4305599 | M203: 1545729 | N203: 1217991 | O203: 26710861 | P203: 2872560 | Q203: 259970 | R203: 2072172 | S203: 1654596 | T203: 1974414 | U203: -348147.75 | V203: -412448.22
A204: 10 | B204: Southeast Minnesota | C204: 01 | D204: 66 | E204: Rice | F204: NORTHFIELD PUBLIC SCHOOL DISTRICT | G204: 0659 | J204: 3944.86 | K204: 4376967 | L204: 5480309 | M204: 1458002 | N204: 602835 | O204: 24572268 | P204: 1884185 | Q204: 259912 | R204: 1308168 | S204: 472401 | T204: 2770286 | U204: -368495.78 | V204: -15029
A205: 8 | B205: Southwest Minnesota | C205: 01 | D205: 67 | E205: Rock | F205: HILLS-BEAVER CREEK SCHOOL DISTRICT | G205: 0671 | J205: 339.54 | K205: 201896 | L205: 173709 | M205: 159749 | N205: 41506 | O205: 2382775 | P205: 145498 | Q205: 16848 | R205: 91279 | S205: 57684 | T205: 116090 | U205: -20391.98 | V205: 0
A206: 1 | B206: Northwest Minnesota | C206: 01 | D206: 68 | E206: Roseau | F206: BADGER PUBLIC SCHOOL DISTRICT | G206: 0676 | J206: 226.99 | K206: 183259 | L206: 50011 | M206: 181091 | N206: 42500 | O206: 1875831 | P206: 91198 | Q206: 27430 | R206: 68634 | S206: 63971 | T206: 44919 | U206: -20448.88 | V206: 0
A207: 1 | B207: Northwest Minnesota | C207: 01 | D207: 68 | E207: Roseau | F207: ROSEAU PUBLIC SCHOOL DISTRICT | G207: 0682 | J207: 1333.17 | K207: 559893 | L207: 1011535 | M207: 507903 | N207: 442040 | O207: 9141472 | P207: 738031 | Q207: 70128 | R207: 415248 | S207: 166295 | T207: 574974 | U207: -89591.06 | V207: 0
A208: 1 | B208: Northwest Minnesota | C208: 01 | D208: 68 | E208: Roseau | F208: WARROAD PUBLIC SCHOOL DISTRICT | G208: 0690 | J208: 1261.52 | K208: 456583 | L208: 934515 | M208: 854426 | N208: 639019 | O208: 8717220 | P208: 444674 | Q208: 224178 | R208: 649488 | S208: 226136 | T208: 588492 | U208: -109254.74 | V208: 0
A209: 3 | B209: Northeast Minnesota | C209: 01 | D209: 69 | E209: Saint Louis | F209: CHISHOLM PUBLIC SCHOOL DISTRICT | G209: 0695 | J209: 757.37 | K209: 483555 | L209: 154792 | M209: 1212906 | N209: 208459 | O209: 5280620 | P209: 165386 | Q209: 94746 | R209: 307940 | S209: 161528 | T209: 726364 | U209: -58610.12 | V209: 0
... A345: 8 | B345: Southwest Minnesota | C345: 01 | D345: 41 | E345: Lincoln | F345: RTR PUBLIC SCHOOLS | G345: 2902 | J345: 564.36 | K345: 406449 | L345: 97158 | M345: 300075 | N345: 50958 | O345: 3790735 | P345: 148612 | Q345: 338771 | R345: 388758 | S345: 112913 | T345: 180510 | U345: -46641.83 | V345: 0
F346: State | G346: 9999 | J346: =SUM(J6:J345) -> 814733.22 | K346: =SUM(K6:K345) -> 855760925 | L346: =SUM(L6:L345) -> 744354569 | M346: =SUM(M6:M345) -> 410123276 | N346: =SUM(N6:N345) -> 181696457 | O346: =SUM(O6:O345) -> 5305522900 | P346: =SUM(P6:P345) -> 599074487 | Q346: =SUM(Q6:Q345) -> 152036093 | ... V346: =SUM(V6:V345) -> -46502968
M347: =SUM(K346:M346) -> 2010238770 | Q347: =SUM(N346:Q346) -> 6238329937 | S347: =SUM(R346:S346) -> 502930782 | T347: =T346 -> 536346689 | V347: =SUM(U346:V346) -> -1.2172122e+08 | W347: =SUM(M347:V347) -> 9.166125e+09
M348: =M347/J346 -> 2467.3583 | Q348: =Q347/J346 -> 7656.899 | S348: =S347/J346 -> 617.29505 | T348: =T347/J346 -> 658.30959 | V348: =V347/J346 -> -149.4001 | W348: =SUM(K348:V348) -> 11250.462

Sheet Minnea St Paul Dist wrk
F1: Click here for Definitions
A2: Economic Development Region Number | B2: Economic Development Region | C2: District Type | D2: County Number | E2: County Name | F2: Total Revenues FY07 | G2: District Number | J2: District ADM Served Plus Tuitioned Out | K2: General Fund Revenues
K3: Local Sources | O3: State Sources | R3: Federal Sources
H4: Charter | I4: Charter Location | K4: Property Taxes | L4: Other funds revenues distributed by Local Other State and Federal | M4: Other | O4: General Education Aid | P4: Special Education Aid | Q4: All Other State Aid | R4: Federal | S4: Federal | T4: Other
F5: Counties and Districts | K5: 1. | L5: Local | M5: 2. | N5: State | O5: 4. | P5: 5. | Q5: 6. | R5: 8. | U5: Early Childhood Reduction | V5: ABE Reduction
A6: 11 | B6: Twin Cities Metropolitan Area | C6: 03 | D6: 27 | E6: Hennepin | F6: MINNEAPOLIS PUBLIC SCHOOL DIST. | G6: 0001 | H6: District | I6: Minneapolis | J6: 39479.31 | K6: 58005565 | L6: 58143868 | M6: 20520348 | N6: 23620461 | O6: 293589390 | P6: 49228337 | Q6: 18490543 | R6: 52989194 | S6: 15279332 | T6: 18756992 | U6: -4444620.9 | V6: -7342147.7
M7: =SUM(K6:M6) -> 136669781 | Q7: =SUM(N6:Q6) -> 384928731 | S7: =SUM(R6:S6) -> 68268526 | T7: =T6 -> 18756992 | V7: =SUM(U6:V6) -> -11786769 | W7: =SUM(K7:V7) -> 5.9683726e+08
M8: =M7/J6 -> 3461.8077 | Q8: =Q7/J6 -> 9750.1383 | S8: =S7/J6 -> 1729.2229 | T8: =T7/J6 -> 475.10942 | V8: =V7/J6 -> -298.55559 | W8: =SUM(K8:V8) -> 15117.723
A10: 11 | B10: Twin Cities Metropolitan Area | C10: 01 | D10: 62 | E10: Ramsey | F10: ST. PAUL PUBLIC SCHOOL DISTRICT | G10: 0625 | H10: District | I10: St. Paul | J10: 42379.85 | K10: 48650687 | L10: 31572669 | M10: 18437068 | N10: 17562192 | O10: 329659792 | P10: 43546172 | Q10: 23370195 | R10: 41434769 | S10: 20144430 | T10: 12959959 | U10: -5597682.3 | V10: -9194966.1
M11: =SUM(K10:M10) -> 98660424 | Q11: =SUM(N10:Q10) -> 414138351 | S11: =SUM(R10:S10) -> 61579199 | T11: =T10 -> 12959959 | V11: =SUM(U10:V10) -> -14792648 | W11: =SUM(K11:V11) -> 5.7254528e+08
M12: =M11/J10 -> 2328.0031 | Q12: =Q11/J10 -> 9772.058 | S12: =S11/J10 -> 1453.0301 | T12: =T11/J10 -> 305.80474 | V12: =V11/J10 -> -349.0491 | W12: =SUM(K12:V12) -> 13509.847

Sheet Charter State Work
F1: Click here for Definitions
A2: Economic Development Region Number | B2: Economic Development Region | C2: District Type | D2: County Number | E2: County Name | F2: Total Revenues FY07 | G2: District Number | J2: District ADM Served Plus Tuitioned Out | K2: General Fund Revenues
K3: Local Sources | O3: State Sources | R3: Federal Sources
H4: Charter | I4: Charter Location | K4: Property Taxes | L4: Other funds revenues distributed by Local Other State and Federal | M4: Other | O4: General Education Aid | P4: Special Education Aid | Q4: All Other State Aid | R4: Federal | S4: Federal | T4: Other
F5: Counties and Districts | K5: 1. | L5: Local | M5: 2. | N5: State | O5: 4. | P5: 5. | Q5: 6. | R5: 8. | U5: Early Childhood Reduction | V5: ABE Reduction
A6: 11 | B6: Twin Cities Metropolitan Area | C6: 07 | D6: 62 | E6: Ramsey | F6: ACADEMIA CESAR CHAVEZ CHARTER SCH. | G6: 4073 | H6: Charter | I6: St. Paul | J6: 262.75 | K6: 0 | L6: 0 | M6: 47885 | N6: 8154 | O6: 2086879 | P6: 198549 | Q6: 270454 | R6: 184592 | S6: 134669 | T6: 4062 | U6: 0 | V6: 0
A7: 10 | B7: Southeast Minnesota | C7: 07 | D7: 85 | E7: Winona | F7: ACADEMY OF BIOSCIENCES | G7: 4148 | H7: Charter | I7: Statewide | J7: 157.75 | K7: 0 | L7: 0 | M7: 17595 | N7: 2956 | O7: 1119571 | P7: 81301 | Q7: 330392 | R7: 233166 | S7: 34329 | T7: 25070 | U7: 0 | V7: 0
A8: 11 | B8: Twin Cities Metropolitan Area | C8: 07 | D8: 82 | E8: Washington | F8: ACHIEVE LANGUAGE ACADEMY | G8: 4018 | H8: Charter | I8: St. Paul | J8: 409.08 | K8: 0 | L8: 0 | M8: 89030 | N8: 0 | O8: 3228896 | P8: 182561 | Q8: 598530 | R8: 227280 | S8: 0 | T8: 24975 | U8: 0 | V8: 0
A9: 11 | B9: Twin Cities Metropolitan Area | C9: 07 | D9: 27 | E9: Hennepin | F9: ADAM ABDULLE ACADEMY | G9: 4135 | H9: Charter | I9: Statewide | J9: 112.29 | K9: 0 | L9: 0 | M9: 1278 | N9: 2028 | O9: 1080750 | P9: 19392 | Q9: 266690 | R9: 176006 | S9: 65542 | T9: 0 | U9: 0 | V9: 0
A10: 11 | B10: Twin Cities Metropolitan Area | C10: 07 | D10: 62 | E10: Ramsey | F10: AGRICULTURAL FOOD SCIENCE ACADEMY | G10: 4074 | H10: Charter | I10: Statewide | J10: 203.87 | K10: 0 | L10: 0 | M10: 271848 | N10: 1903 | O10: 1439440 | P10: 376937 | Q10: 366283 | R10: 69454 | S10: 19757 | T10: 16420 | U10: 0 | V10: 0
A11: 11 | B11: Twin Cities Metropolitan Area | C11: 07 | D11: 62 | E11: Ramsey | F11: ARTECH | G11: 4091 | H11: Charter | I11: Statewide | J11: 122.6 | K11: 0 | L11: 0 | M11: 16752 | N11: 447 | O11: 854895 | P11: 203462 | Q11: 178658 | R11: 32280 | S11: 3561 | T11: 11126 | U11: 0 | V11: 0
A12: 9 | B12: South Central Minnesota | C12: 07 | D12: 72 | E12: Sibley | F12: ASCENSION ACADEMY CHARTER SCHOOL | G12: 4114 | H12: Charter | I12: Minneapolis | J12: 87.16 | K12: 0 | L12: 0 | M12: 62267 | N12: 1343 | O12: 718200 | P12: 15027 | Q12: 134815 | R12: 157517 | S12: 24562 | T12: 1499 | U12: 0 | V12: 0
A13: 11 | B13: Twin Cities Metropolitan Area | C13: 07 | D13: 2 | E13: Anoka | F13: AUGSBURG ACADEMY FOR HEALTH CAREERS | G13: 4111 | H13: Charter | I13: Minneapolis | J13: 70.7 | K13: 0 | L13: 0 | M13: 13027 | N13: 639 | O13: 599649 | P13: 53838 | Q13: 144839 | R13: 183653 | S13: 14708 | T13: 1073 | U13: 0 | V13: 0
A14: 11 | B14: Twin Cities Metropolitan Area | C14: 07 | D14: 27 | E14: Hennepin | F14: AURORA CHARTER SCHOOL | G14: 4067 | H14: Charter | I14: Minneapolis | J14: 231.57 | K14: 0 | L14: 0 | M14: 2320 | N14: 4465 | O14: 1781024 | P14: 28680 | Q14: 128902 | R14: 120732 | S14: 96513 | T14: 22094 | U14: -2653.05 | V14: 0
A15: 5 | B15: North Central Minnesota | C15: 07 | D15: 18 | E15: Crow Wing | F15: AVALON SCHOOL | G15: 4075 | H15: Charter | I15: St. Paul | J15: 154.51 | K15: 0 | L15: 0 | M15: 88885 | N15: 371 | O15: 1115713 | P15: 191219 | Q15: 242377 | R15: 9127 | S15: 6960 | T15: 2655 | U15: 0 | V15: 0
A16: 11 | B16: Twin Cities Metropolitan Area | C16: 07 | D16: 62 | E16: Ramsey | F16: BEACON ACADEMY | G16: 4124 | H16: Charter | I16: Statewide | J16: 253.08 | K16: 0 | L16: 0 | M16: 203659 | N16: 2064 | O16: 1447572 | P16: 138333 | Q16: 305412 | R16: 191318 | S16: 15715 | T16: 41133 | U16: 0 | V16: 0
A17: 11 | B17: Twin Cities Metropolitan Area | C17: 07 | D17: 10 | E17: Carver | F17: BEACON PREPARATORY SCHOOL | G17: 4133 | H17: Charter | I17: Statewide | J17: 29.97 | K17: 0 | L17: 0 | M17: 56117 | N17: -1 | O17: 174451 | P17: 20096 | Q17: 88124 | R17: 171909 | S17: 0 | T17: 3631 | U17: 0 | V17: 0
... A135: 11 | B135: Twin Cities Metropolitan Area | C135: 07 | D135: 82 | E135: Washington | F135: YINGHUA ACADEMY | G135: 4140 | H135: Charter | I135: St. Paul | J135: 81.73 | K135: 0 | L135: 0 | M135: 123084 | N135: 365 | O135: 399191 | P135: 6818 | Q135: 138457 | R135: 185491 | S135: 812 | T135: 81600 | U135: 0 | V135: 0
F136: State | G136: 9999 | J136: =SUM(J6:J135) -> 23816.18 | K136: =SUM(K6:K135) -> 0 | L136: =SUM(L6:L135) -> 0 | M136: =SUM(M6:M135) -> 11636512 | N136: =SUM(N6:N135) -> 347133 | O136: =SUM(O6:O135) -> 172745986 | P136: =SUM(P6:P135) -> 19975462 | Q136: =SUM(Q6:Q135) -> 31517488 | ... V136: =SUM(V6:V135) -> -46337.59
M137: =SUM(K136:M136) -> 11636512 | Q137: =SUM(N136:Q136) -> 224586069 | S137: =SUM(R136:S136) -> 24751616 | T137: =T136 -> 3065962 | V137: =SUM(U136:V136) -> -124395.95 | W137: =SUM(M137:V137) -> 2.6391576e+08
M138: =M137/J136 -> 488.59691 | Q138: =Q137/J136 -> 9429.9787 | S138: =S137/J136 -> 1039.2773 | T138: =T137/J136 -> 128.73442 | V138: =V137/J136 -> -5.2231697 | W138: =SUM(M138:V138) -> 11081.364

Sheet Charter Minnea St. Paul Wrk
F1: Click here for Definitions
A2: Economic Development Region Number | B2: Economic Development Region | C2: District Type | D2: County Number | E2: County Name | F2: Total Revenues FY07 | G2: District Number | J2: District ADM Served Plus Tuitioned Out | K2: General Fund Revenues
K3: Local Sources | O3: State Sources | R3: Federal Sources
H4: Charter | I4: Charter Location | K4: Property Taxes | L4: Other funds revenues distributed by Local Other State and Federal | M4: Other | O4: General Education Aid | P4: Special Education Aid | Q4: All Other State Aid | R4: Federal | S4: Federal | T4: Other
F5: Counties and Districts | K5: 1. | L5: Local | M5: 2. | N5: State | O5: 4. | P5: 5. | Q5: 6. | R5: 8. | U5: Early Childhood Reduction | V5: ABE Reduction
A6: 9 | B6: South Central Minnesota | C6: 07 | D6: 72 | E6: Sibley | F6: ASCENSION ACADEMY CHARTER SCHOOL | G6: 4114 | H6: Charter | I6: Minneapolis | J6: 87.16 | K6: 0 | L6: 0 | M6: 62267 | N6: 1343 | O6: 718200 | P6: 15027 | Q6: 134815 | R6: 157517 | S6: 24562 | T6: 1499 | U6: 0 | V6: 0
