Workbook

Sheet SchoolDistricts
B1: Administration | F1: Instruction | O1: Student Support
B2: Central Office | D2: School | F2: Classroom | L2: Library | O2: Counselors | Q2: Other Pros (Nurses, etc.) and Parapros
D3: Principals & Assistant Principals | F3: Teachers
B4: Administrators | C4: Support | E4: Support | F4: Preschool | G4: Kindergarten | H4: Elementary | I4: Secondary | J4: Special Education | K4: Parapros | L4: Librarians | M4: Parapros | N4: Leaders and Specialists | O4: Elementary | P4: Secondary | R4: Other Support | S4: Total
A5: Alpine District | B5: 23 | C5: 16.03 | D5: 121.063 | E5: 249.85 | F5: 35.383 | G5: 137.549 | H5: 1414.441 | I5: 1101.651 | J5: 272.403 | K5: 704.24 | L5: 21.521 | M5: 19.23 | N5: 148.701 | O5: 0 | P5: 80.561 | Q5: 111.59 | R5: 920.07 | S5: =SUM(B5:R5) -> 5377.283
A6: Beaver District | B6: 2.75 | C6: 2.58 | D6: 3.99 | E6: 5.22 | F6: 0.5 | G6: 3.009 | H6: 34.991 | I6: 31.4 | J6: 6.72 | K6: 26.64 | L6: 0 | M6: 4.01 | N6: 2.35 | O6: 0 | P6: 2 | Q6: 1.22 | R6: 26.26 | S6: =SUM(B6:R6) -> 153.64
A7: Box Elder District | B7: 7 | C7: 18 | D7: 25.05 | E7: 38 | F7: 9 | G7: 24.53 | H7: 180.998 | I7: 224.515 | J7: 44.68 | K7: 141 | L7: 4.5 | M7: 7 | N7: 19.004 | O7: 3 | P7: 13.033 | Q7: 25.481 | R7: 225 | S7: =SUM(B7:R7) -> 1009.791
A8: Cache District | B8: 3.5 | C8: 30.11 | D8: 32.606 | E8: 39.67 | F8: 8.65 | G8: 29.5 | H8: 255.568 | I8: 290.884 | J8: 49.741 | K8: 469.59 | L8: 15.8 | M8: 8 | N8: 46.634 | O8: 2 | P8: 20.018 | Q8: 66.717 | R8: 282.26 | S8: =SUM(B8:R8) -> 1651.248
A9: Canyons District | B9: 23 | C9: 70.6 | D9: 87.087 | E9: 109.2 | F9: 13.25 | G9: 69.868 | H9: 653.512 | I9: 602.443 | J9: 138.669 | K9: 135.8 | L9: 10.084 | M9: 34.83 | N9: 136.208 | O9: 0.5 | P9: 44.408 | Q9: 99.251 | R9: 481.5 | S9: =SUM(B9:R9) -> 2710.21
A10: Carbon District | B10: 5.5 | C10: 5.51 | D10: 12 | E10: 13.47 | F10: 2 | G10: 15 | H10: 71.71 | I10: 69.2 | J10: 15.342 | K10: 82.47 | L10: 0.5 | M10: 3.78 | N10: 16.563 | O10: 1.9 | P10: 4.94 | Q10: 7 | R10: 76.89 | S10: =SUM(B10:R10) -> 403.775
A11: Daggett District | B11: 1.65 | C11: 1 | D11: 0.86 | E11: 1.75 | F11: 0 | G11: 0.83 | H11: 5.17 | I11: 9.18 | J11: 0.8 | K11: 5.47 | L11: 0.03 | M11: 0 | N11: 1.478 | O11: 0 | P11: 0 | Q11: 0.36 | R11: 8.39 | S11: =SUM(B11:R11) -> 36.968
A12: Davis District | B12: 28.5 | C12: 105.9 | D12: 175.047 | E12: 222.75 | F12: 30.918 | G12: 133.178 | H12: 1314.048 | I12: 1083.031 | J12: 277.4 | K12: 991.51 | L12: 19.09 | M12: 51.59 | N12: 204.724 | O12: 31.956 | P12: 84.9 | Q12: 136.073 | R12: 1062.82 | S12: =SUM(B12:R12) -> 5953.435
A13: Duchesne District | B13: 3.5 | C13: 12 | D13: 16.25 | E13: 21.13 | F13: 3 | G13: 13.5 | H13: 96.187 | I13: 89.966 | J13: 26.05 | K13: 88.54 | L13: 4.84 | M13: 5.35 | N13: 6.215 | O13: 0 | P13: 5 | Q13: 6.9 | R13: 93.62 | S13: =SUM(B13:R13) -> 492.048
A14: Emery District | B14: 4.5 | C14: 7 | D14: 10.03 | E14: 11.88 | F14: 1 | G14: 7 | H14: 57.707 | I14: 53.199 | J14: 13.488 | K14: 40.08 | L14: 1 | M14: 7.5 | N14: 0.5 | O14: 0 | P14: 3 | Q14: 5 | R14: 52.72 | S14: =SUM(B14:R14) -> 275.604
A15: Garfield District | B15: 2.13 | C15: 3 | D15: 3.07 | E15: 7 | F15: 0.5 | G15: 2.53 | H15: 21.845 | I15: 27.281 | J15: 5.4 | K15: 19.11 | L15: 0 | M15: 0 | N15: 0.2 | O15: 0 | P15: 1.5 | Q15: 2.11 | R15: 18.58 | S15: =SUM(B15:R15) -> 114.256
A16: Grand District | B16: 2 | C16: 5.25 | D16: 5 | E16: 12.14 | F16: 1.05 | G16: 4 | H16: 36 | I16: 36.286 | J16: 8.58 | K16: 26.81 | L16: 1 | M16: 3 | N16: 2.343 | O16: 0 | P16: 2 | Q16: 3 | R16: 39.24 | S16: =SUM(B16:R16) -> 187.699
... A45: Weber District | B45: 13 | C45: 52.31 | D45: 68.618 | E45: 80.68 | F45: 9.308 | G45: 65.006 | H45: 565.882 | I45: 541.321 | J45: 163.583 | K45: 378.58 | L45: 13.83 | M45: 27.25 | N45: 80.961 | O45: 21.962 | P45: 36.405 | Q45: 59.875 | R45: 434.99 | S45: =SUM(B45:R45) -> 2613.561
A46: District Subtotal | B46: =SUM(B5:B45) -> 325.371 | C46: =SUM(C5:C45) -> 695.94 | D46: =SUM(D5:D45) -> 1244.133 | E46: =SUM(E5:E45) -> 2075.27 | F46: =SUM(F5:F45) -> 254.208 | G46: =SUM(G5:G45) -> 1221.227 | H46: =SUM(H5:H45) -> 10651.277 | I46: =SUM(I5:I45) -> 9681.301 | ... R46: =SUM(R5:R45) -> 8836.51 | S46: =SUM(B46:R46) -> 49522.947
A47: Charter Subtotal | B47: =CharterSchools!B90 -> 68.712 | C47: =CharterSchools!C90 -> 34.97 | D47: =CharterSchools!D90 -> 122.047 | E47: =CharterSchools!E90 -> 233.03 | F47: =CharterSchools!F90 -> 0 | G47: =CharterSchools!G90 -> 114.332 | H47: =CharterSchools!H90 -> 1057.56 | I47: =CharterSchools!I90 -> 961.194 | ... S47: =CharterSchools!S90 -> 4098.59
A48: Utah Schools For Deaf & Blind | B48: 3 | F48: 19.71 | J48: 97.891 | N48: 24.39 | O48: 1 | Q48: 14.02 | S48: =SUM(B48:R48) -> 160.011
A49: State Total | B49: =SUM(B46:B48) -> 397.083 | C49: =SUM(C46:C48) -> 730.91 | D49: =SUM(D46:D48) -> 1366.18 | E49: =SUM(E46:E48) -> 2308.3 | F49: =SUM(F46:F48) -> 273.918 | G49: =SUM(G46:G48) -> 1335.559 | H49: =SUM(H46:H48) -> 11708.837 | I49: =SUM(I46:I48) -> 10642.495 | ... R49: =SUM(R46:R48) -> 9084.74 | S49: =SUM(B49:R49) -> 53781.548

Sheet CharterSchools
B1: Administration | F1: Instruction | O1: Student Support
B2: Central Office | D2: School | F2: Classroom | L2: Library | O2: Counselors | Q2: Other Pros (Nurses, etc.) and Parapros
D3: Principals & Assistant Principals | F3: Teachers
B4: Administrators | C4: Support | E4: Support | F4: Preschool | G4: Kindergarten | H4: Elementary | I4: Secondary | J4: Special Education | K4: Parapros | L4: Librarians | M4: Parapros | N4: Leaders and Specialists | O4: Elementary | P4: Secondary | R4: Other Support | S4: Total
A5: Academy For Math Engineering & Science | B5: 0.13 | C5: 2.11 | D5: 1 | E5: 2.36 | F5: 0 | G5: 0 | H5: 0 | I5: 20.518 | J5: 1 | K5: 2.57 | L5: 0 | M5: 0 | N5: 0.17 | O5: 0 | P5: 3 | Q5: 0 | R5: 0 | S5: =SUM(B5:R5) -> 32.858
A6: Alianza Academy | B6: 0 | C6: 0 | D6: 1 | E6: 3.25 | F6: 0 | G6: 3.04 | H6: 11.75 | I6: 1 | J6: 3 | K6: 13 | L6: 0 | M6: 0 | N6: 0 | O6: 0 | P6: 0 | Q6: 0 | R6: 5 | S6: =SUM(B6:R6) -> 41.04
A7: American Leadership Academy | B7: 2 | C7: 4 | D7: 2 | E7: 8 | F7: 0 | G7: 3.5 | H7: 27 | I7: 36.767 | J7: 6.08 | K7: 39 | L7: 0.6 | M7: 0 | N7: 5.365 | O7: 0 | P7: 3 | Q7: 1 | R7: 5 | S7: =SUM(B7:R7) -> 143.312
A8: American Preparatory Academy | B8: 2.8 | C8: 0 | D8: 7 | E8: 29.09 | F8: 0 | G8: 6 | H8: 42.261 | I8: 48.092 | J8: 2.178 | K8: 33.53 | L8: 0 | M8: 0 | N8: 4.473 | O8: 0.35 | P8: 2.35 | Q8: 3.355 | R8: 19.96 | S8: =SUM(B8:R8) -> 201.439
A9: Aristotle Academy | B9: 2 | C9: 0 | D9: 1 | E9: 2 | F9: 0 | G9: 2.132 | H9: 7.61 | I9: 4.765 | J9: 1 | K9: 1 | L9: 0 | M9: 0 | N9: 0 | O9: 0 | P9: 0 | Q9: 0 | R9: 0 | S9: =SUM(B9:R9) -> 21.507
A10: Bear River Charter School | B10: 1 | C10: 0.5 | D10: 1 | E10: 1 | F10: 0 | G10: 0.5 | H10: 6.924 | I10: 4.205 | J10: 1 | K10: 4.5 | L10: 0 | M10: 0 | N10: 0.27 | O10: 0 | P10: 0.17 | Q10: 0.4 | R10: 2 | S10: =SUM(B10:R10) -> 23.469
A11: Beehive Science & Technology Academy | B11: 1.3 | C11: 0 | D11: 0 | E11: 2 | F11: 0 | G11: 0 | H11: 0 | I11: 14.253 | J11: 1.083 | K11: 1.31 | L11: 0.108 | M11: 0 | N11: 1.989 | O11: 0 | P11: 0 | Q11: 0 | R11: 0 | S11: =SUM(B11:R11) -> 22.043
A12: Canyon Grove Academy | B12: 0 | C12: 0 | D12: 0.754 | E12: 4.75 | F12: 0 | G12: 2 | H12: 9.158 | I12: 6.403 | J12: 1.75 | K12: 4 | L12: 0.308 | M12: 0 | N12: 6.434 | O12: 0 | P12: 0 | Q12: 0 | R12: 7 | S12: =SUM(B12:R12) -> 42.557
A13: Canyon Rim Academy | B13: 1.67 | C13: 0 | D13: 1 | E13: 2.7 | F13: 0 | G13: 2 | H13: 19 | I13: 0 | J13: 2 | K13: 13.35 | L13: 0 | M13: 0 | N13: 0.33 | O13: 0 | P13: 0 | Q13: 1.531 | R13: 4 | S13: =SUM(B13:R13) -> 47.581
A14: Channing Hall | B14: 1 | C14: 2.5 | D14: 2.25 | E14: 0 | F14: 0 | G14: 2 | H14: 18.494 | I14: 11.8 | J14: 2 | K14: 11.9 | L14: 0 | M14: 2.24 | N14: 1.8 | O14: 0 | P14: 0 | Q14: 2 | R14: 4.38 | S14: =SUM(B14:R14) -> 62.364
A15: City Academy | B15: 1.5 | C15: 0 | D15: 0.9 | E15: 1.49 | F15: 0 | G15: 0 | H15: 0 | I15: 13.927 | J15: 0 | K15: 5.23 | L15: 0 | M15: 0.75 | N15: 2.884 | O15: 0 | P15: 1 | Q15: 0 | R15: 1.96 | S15: =SUM(B15:R15) -> 29.641
A16: Cs Lewis Academy | B16: 0 | C16: 0 | D16: 0 | E16: 2.32 | F16: 0 | G16: 2 | H16: 14 | I16: 0 | J16: 1 | K16: 3.37 | L16: 0 | M16: 0 | N16: 0 | O16: 0 | P16: 0 | Q16: 1.45 | R16: 3.29 | S16: =SUM(B16:R16) -> 27.43
... A43: Maria Montessori Academy | B43: 0 | C43: 0.5 | D43: 1 | E43: 3 | F43: 0 | G43: 2.366 | H43: 16 | I43: 0 | J43: 2 | K43: 5.16 | L43: 0 | M43: 0 | N43: 0 | O43: 0 | P43: 0 | Q43: 2.448 | R43: 2.64 | S43: =SUM(B43:R43) -> 35.114
A44: Merit College Preparatory Academy | B44: 0.15 | D44: 1.378 | F44: 0 | G44: 0 | H44: 0 | I44: 15.682 | J44: 0.985 | L44: 0 | N44: 2.4 | O44: 0 | P44: 0.583 | Q44: 0 | S44: =SUM(B44:R44) -> 21.178
A45: Moab Charter School | B45: 1 | C45: 0 | D45: 1 | E45: 1 | F45: 0 | G45: 1 | H45: 5 | I45: 0 | J45: 0.5 | K45: 1.5 | L45: 0 | M45: 0 | N45: 0 | O45: 0 | P45: 0 | Q45: 0 | R45: 1 | S45: =SUM(B45:R45) -> 12
A46: Monticello Academy | B46: 3 | C46: 0 | D46: 0 | E46: 1.5 | F46: 0 | G46: 2.117 | H46: 17.187 | I46: 15.595 | J46: 1.516 | K46: 7.8 | L46: 1 | M46: 0.2 | N46: 1 | O46: 0 | P46: 0.5 | Q46: 1 | R46: 3.4 | S46: =SUM(B46:R46) -> 55.815
A47: Mountain Heights Academy | B47: 0 | C47: 0 | D47: 1 | E47: 2 | F47: 0 | G47: 0 | H47: 0 | I47: 17.948 | J47: 0.89 | K47: 0.51 | L47: 0 | M47: 0 | N47: 2.4 | O47: 0 | P47: 1.144 | Q47: 0 | R47: 0 | S47: =SUM(B47:R47) -> 25.892
A48: Mountainville Academy | B48: 2 | C48: 0 | D48: 2.444 | E48: 3.5 | F48: 0 | G48: 1.5 | H48: 18.913 | I48: 15.831 | J48: 1.71 | K48: 14.25 | L48: 1 | M48: 1 | N48: 1 | O48: 0 | P48: 1 | Q48: 1 | R48: 5 | S48: =SUM(B48:R48) -> 70.148
A49: Navigator Pointe Academy | B49: 0 | C49: 0 | D49: 1 | E49: 3 | F49: 0 | G49: 1 | H49: 14.7 | I49: 11.17 | J49: 3.5 | K49: 18 | L49: 0.34 | M49: 0 | N49: 0 | O49: 0.2 | P49: 0.2 | Q49: 0.935 | R49: 2 | S49: =SUM(B49:R49) -> 56.045
A50: Nuames | B50: 0 | C50: 0 | D50: 3 | E50: 1 | F50: 0 | G50: 0 | H50: 0 | I50: 19.022 | J50: 0.2 | K50: 1 | L50: 0 | M50: 0 | N50: 1.16 | O50: 0 | P50: 1.98 | Q50: 0 | R50: 1.25 | S50: =SUM(B50:R50) -> 28.612
A51: Noah Webster Academy | B51: 0 | C51: 0 | D51: 1 | E51: 3.5 | F51: 0 | G51: 1.917 | H51: 19 | I51: 0 | J51: 0 | K51: 11.5 | L51: 0 | M51: 0.25 | N51: 3 | O51: 0 | P51: 0 | Q51: 0.308 | R51: 5.5 | S51: =SUM(B51:R51) -> 45.975
A52: North Davis Preparatory Academy | B52: 0 | C52: 0 | D52: 2.4 | E52: 3.67 | F52: 0 | G52: 2 | H52: 23.683 | I52: 12.25 | J52: 2 | K52: 15.53 | L52: 1 | M52: 0.56 | N52: 2.618 | O52: 0.05 | P52: 0.95 | Q52: 1 | R52: 3.3 | S52: =SUM(B52:R52) -> 71.011
A53: North Star Academy | B53: 0 | C53: 0 | D53: 1.3 | E53: 3 | F53: 0 | G53: 1 | H53: 11.35 | I53: 11.27 | J53: 0.64 | K53: 11.89 | L53: 0.95 | M53: 0 | N53: 0.507 | O53: 0.25 | P53: 0.75 | Q53: 1.33 | R53: 1.42 | S53: =SUM(B53:R53) -> 45.657
A54: Odyssey Charter School | B54: 1 | C54: 0 | D54: 2 | E54: 1.6 | F54: 0 | G54: 2 | H54: 20.071 | I54: 1.006 | J54: 1.5 | K54: 20.63 | L54: 0 | M54: 0.62 | N54: 1 | O54: 0.627 | P54: 0 | Q54: 0 | R54: 1.45 | S54: =SUM(B54:R54) -> 53.504
A55: Ogden Preparatory Academy | B55: 0.05 | C55: 1 | D55: 1.8 | E55: 3.81 | F55: 0 | G55: 2 | H55: 22.121 | I55: 17.909 | J55: 4.2 | K55: 18.92 | L55: 1 | M55: 1.75 | N55: 0.95 | O55: 0.25 | P55: 1.25 | Q55: 1.5 | R55: 5.52 | S55: =SUM(B55:R55) -> 84.03
A56: Open Classroom | B56: 0 | C56: 0 | D56: 1 | E56: 2 | F56: 0 | G56: 1.2 | H56: 15.3 | I56: 0 | J56: 1.8 | K56: 2.02 | L56: 0 | M56: 0 | N56: 1.5 | O56: 0.9 | P56: 0 | Q56: 0 | R56: 4.87 | S56: =SUM(B56:R56) -> 30.59
... A59: Pinnacle Canyon Academy | B59: 2.25 | C59: 0 | D59: 1.8 | E59: 2 | F59: 0 | G59: 1.056 | H59: 11.504 | I59: 21.578 | J59: 1.904 | K59: 20 | L59: 1.056 | M59: 1 | N59: 1.601 | O59: 0.521 | P59: 0 | Q59: 1.587 | R59: 6 | S59: =SUM(B59:R59) -> 73.857
A60: Pioneer Hs For The Performing Arts | B60: 0 | D60: 0.95 | F60: 0 | G60: 0 | H60: 0 | I60: 5.925 | J60: 0 | L60: 0 | N60: 1.5 | O60: 0 | P60: 1 | Q60: 0 | S60: =SUM(B60:R60) -> 9.375
A61: Promontory School Of El | B61: 0 | C61: 0 | D61: 1 | E61: 1.97 | F61: 0 | G61: 1 | H61: 14.5 | I61: 4.25 | J61: 1 | K61: 8.13 | L61: 0 | M61: 0.2 | N61: 0 | O61: 0 | P61: 0 | Q61: 0 | R61: 2.57 | S61: =SUM(B61:R61) -> 34.62
A62: Providence Hall | B62: 0.4 | C62: 0 | D62: 2 | E62: 11 | F62: 0 | G62: 2.5 | H62: 28.079 | I62: 33.879 | J62: 5.011 | K62: 20.25 | L62: 1 | M62: 1 | N62: 2 | O62: 0.5 | P62: 2 | Q62: 0 | R62: 5.16 | S62: =SUM(B62:R62) -> 114.779
A63: Quest Academy | B63: 3 | C63: 0 | D63: 0 | E63: 3.41 | F63: 0 | G63: 2 | H63: 21.83 | I63: 10.306 | J63: 3.17 | K63: 12.06 | L63: 0.5 | M63: 0.53 | N63: 1.772 | O63: 0.25 | P63: 0.25 | Q63: 1 | R63: 1.37 | S63: =SUM(B63:R63) -> 61.448
A64: Ranches Academy | B64: 1.5 | C64: 0 | D64: 1 | E64: 1 | F64: 0 | G64: 1 | H64: 14.282 | I64: 0 | J64: 1 | K64: 9.5 | L64: 0 | M64: 0.5 | N64: 1 | O64: 0 | P64: 0 | Q64: 0 | R64: 1.75 | S64: =SUM(B64:R64) -> 32.532
A65: Reagan Academy | B65: 1 | C65: 0 | D65: 2 | E65: 3 | F65: 0 | G65: 2 | H65: 25.219 | I65: 7.714 | J65: 4 | K65: 12.5 | L65: 1 | M65: 0 | N65: 1 | O65: 0 | P65: 0 | Q65: 2 | R65: 4.15 | S65: =SUM(B65:R65) -> 65.583
A66: Renaissance Academy | B66: 1.65 | C66: 0.5 | D66: 0.255 | E66: 4 | F66: 0 | G66: 2.5 | H66: 21.139 | I66: 9.953 | J66: 1 | K66: 8 | L66: 1 | M66: 1 | N66: 2.143 | O66: 0.8 | P66: 0.2 | Q66: 1 | R66: 0.5 | S66: =SUM(B66:R66) -> 55.64
A67: Rockwell Charter High School | B67: 1.433 | C67: 0.5 | D67: 0.84 | E67: 2 | F67: 0 | G67: 0 | H67: 0 | I67: 20.385 | J67: 1 | K67: 2 | L67: 0 | M67: 0.5 | N67: 2 | O67: 0 | P67: 1 | Q67: 1 | R67: 5.6 | S67: =SUM(B67:R67) -> 38.258
A68: Salt Lake Arts Academy | B68: 1 | C68: 0.5 | D68: 1 | E68: 1 | F68: 0 | G68: 0 | H68: 2.1 | I68: 13.06 | J68: 1 | K68: 2.5 | L68: 0 | M68: 0 | N68: 0 | O68: 0 | P68: 0 | Q68: 0.2 | R68: 1 | S68: =SUM(B68:R68) -> 23.36
...
