Workbook
Name _PL2: SPA!#REF!
Name Apr_95: #REF!
Name Aug_94: #REF!
Name Charges: #REF!
Name Dec_94: #REF!
Name Expenditures: #REF!
Name Feb_95: #REF!
Name Fiscal_Yr_Expend_Budget: #REF!
Name Hired: Summary!$A$75:$A$76
Name HlthIns: Summary!$A$82:$A$86
Name Jan_95: #REF!
Name Jul_94: #REF!
Name Jun_95: #REF!
Name Mar_95: #REF!
Name May_95: #REF!
Name Nov_94: #REF!
Name Oct_94: #REF!
Name PL: 'EPA Clinical Benefits'!#REF!
Name ProfessFees: #REF!
Name Receipts: #REF!
Name Retire: Summary!$A$78:$A$80
Name Sep_94: #REF!

Sheet Summary
A1: UNC-CH SCHOOL OF MEDICINE | E1: Legend
A2: Benefits Eligibility for Permanent Positions | E2: Eligible | F2: a
E3: Ineligible | F3: x
A5: Benefit Description | C5: EPA Faculty with Clinical Benefits | E5: EPA | F5: SPA | G5: FY13 | J5: FY11
C6: FTE .50 - .74 | D6: FTE .75+ | E6: FTE .75+ | F6: FTE .75+ | G6: Monthly | H6: Annual | I6: Desc | J6: Monthly | K6: Annual | L6: Notes
A7: A. Basic University Benefits
A8: 1. Social Security | C8: a | D8: a | E8: a | F8: a
B9: 6.20% of taxable earnings up to $113,700 | G9: 0.062 | I9: CY2013 | J9: 0.062
A10: 2. Medicare | C10: a | D10: a | E10: a | F10: a | G10: 113700 | I10: Earnings Max | J10: 106800 | L10: Cap increased to $113,700 effective 1/1/13
B11: 1.45% of taxable earnings | G11: 0.0145 | J11: 0.0145
A12: 3. University Retirement Fund (option of a or b)
B13: 6% of salary mandatory employee contribution
A14: a. N.C. Teachers and State Employees Retirement System | C14: x | D14: a | E14: a | F14: a | G14: 0.1423 | J14: 0.1051
B15: (TSERS; a "defined benefit" program) | G15: 375000 | I15: Before 7/1/96 | J15: 360000
B16: 14.23% of salary | G16: 250000 | I16: After 7/1/96 | J16: 245000
B17: Applicable salary maximum of $250,000 per year if hired on or after 7/1/1996
B18: Applicable salary maximum of $375,000 per year if hired before 7/1/1996
A19: **OR**
A20: b. Optional Retirement Plan | C20: x | D20: a | E20: a | F20: x | G20: 0.1258 | J20: 0.1226
B21: (ORP; TIAA-CREF, VALIC, Lincoln, Fidelity; a "defined contribution" program) | G21: 375000 | I21: Before 7/1/96 | J21: 360000
B22: 6.84% of salary - matching employer contribution | G22: 250000 | I22: After 7/1/96 | J22: 245000
B23: 5.74% of salary - Retiree Health Plan Reserve
B24: Applicable salary maximum of $250,000 per year if hired on or after 7/1/1996
B25: Applicable salary maximum of $375,000 per year if hired before 7/1/1996
A26: 4. Composite Benefit Fund | C26: a | D26: a | E26: a | F26: a
B27: 0.35% of salary | G27: 0.0035 | J27: 0.004
B28: Covers unemployment, workers compensation, and short-term disability pay
A29: 5. Comprehensive Health Insurance for Employee Coverage | C29: x | D29: a | E29: a | F29: a | G29: =H29/12 -> 432.66 | H29: 5191.92 | I29: University | J29: =K29/12 -> 410.8 | K29: 4929.6
B30: State of North Carolina Teachers' and State Employees' Comprehensive | G30: =H30/12 -> 432.66 | H30: 5191.92 | I30: HCS | J30: =K30/12 -> 410.8 | K30: 4929.6
B31: Major Medical Plan
C32: a | D32: a | E32: a | F32: a | G32: 0.00241 | I32: Transit | J32: 0.0024
C33: a | D33: a | E33: a | F33: a | G33: 0.0054 | I33: Communication Core | J33: 0.0054 | L33: Communication Technologies Core Fee (OC 3225)
A34: B. UNC P&A Supplemental Benefits | L34: must select 80:20 plan for wrap around coverage
A35: 1. Comprehensive Health Insurance Reimbursement for Family | C35: a | D35: a | E35: x | F35: x | G35: 22.76 | H35: =G35*12 -> 273.12 | I35: Ee Only
B36: State of North Carolina Teachers' and State Employees' Comprehensive | G36: 286.16 | H36: =G36*12+H35 -> 3707.04 | I36: Ee Child | J36: =K36/12 -> 237.62 | K36: 2851.44
B37: Major Medical Plan | G37: 629.64 | H37: =G37*12+H35 -> 7828.8 | I37: Ee Spouse | J37: =K37/12 -> 547.48 | K37: 6569.76
G38: 666.18 | H38: =G38*12+H35 -> 8267.28 | I38: Family | J38: =K38/12 -> 580.44 | K38: 6965.28
A39: 2. Professional Liability Insurance | C39: a | D39: a | E39: As applicable | F39: As applicable
A40: 3. Supplemental Retirement Fund | C40: a | D40: a | E40: x | F40: x | G40: 0.035 | J40: 0.035
B41: 3.5% of salary | G41: No Max | I41: Before 7/1/96 | J41: No Max
...

Sheet EPA Clinical Benefits
A1: FY13 FRINGE BENEFIT WORKSHEET - EPA with Clinical Benefits
A2: Name:
A3: FTE: | C3: Enter a value between .50 and 1.00
A4: Hired Prior to 7/1/96? | B4: No | C4: Select Yes or No
A5: State or Optional Retirement? | B5: State | C5: Select State, Optional, or Not Applicable
A6: Health Insurance? | B6: Family | C6: Select a value from Chart A
A7: Life, Disab, Supp Health, Dental - Dependents? | B7: Ee and Dep | C7: Select a value from Chart B
I8: Chart A
A9: Description | B9: Object Code | C9: Factor | D9: Formula | E9: Annual | F9: Monthly | G9: % Salary | I9: Health Ins Reimb | J9: Mthly Rate
I10: Ee Only | J10: =Summary!G35 -> 22.76
A11: Salary | B11: 11XX, 13XX | E11: 0 | F11: =IF(ISERROR(E11/12),"-",E11/12) -> 0 | I11: Ee and Child | J11: =Summary!G36 -> 286.16
I12: Ee and Spouse | J12: =Summary!G37 -> 629.64
A13: BASIC BENEFITS | I13: Family | J13: =Summary!G38 -> 666.18
I14: Chart B
A15: Social Security1 | B15: 1812 | C15: =CONCATENATE(Summary!$G$9*100,"% of Salary") -> 6.2% of Salary | E15: =IF($E$11>=Summary!$G$10,Summary!$G$9*Summary!$G$10,$E$11*Summary!$G$9) -> 0 | F15: =IF(ISERROR(E15/12),"-",E15/12) -> 0 | I15: Supp Health | J15: Mthly Rate
I16: Ee Only | J16: =Summary!$G$58 -> 121.86
A17: Medicare | B17: 1813 | C17: =CONCATENATE(Summary!$G$11*100,"% of Salary") -> 1.45% of Salary | E17: =SUM($E$11*Summary!$G$11) -> 0 | F17: =IF(ISERROR(E17/12),"-",E17/12) -> 0 | I17: Ee and Dep | J17: =Summary!$G$58+Summary!$G$59 -> 322.81
I18: Chart C
A19: State Retirement2 | B19: 1822 | C19: =CONCATENATE(Summary!$G$14*100,"% of Salary") -> 14.23% of Salary | D19: =IF($E$11>=Summary!$G$15,Summary!$G$15,$E$11)*Summary!$G$14 -> 0 | E19: =IF(AND(B4="Yes",B5="State"),D19,(IF(AND(B4="No",B5="State"),D20,"-"))) -> 0 | F19: =IF(ISERROR(E19/12),"-",E19/12) -> 0 | I19: Dental Ins | J19: Mthly Rate
D20: =IF($E$11>Summary!$G$16,Summary!$G$16,$E$11)*Summary!$G$14 -> 0 | I20: Ee Only | J20: =Summary!$G$60 -> 41.55
A21: Optional State Retirement3 | B21: 187X | C21: =CONCATENATE(Summary!$G$20*100,"% of Salary") -> 12.58% of Salary | D21: =IF($E$11>Summary!$G$21,Summary!$G$21,$E$11)*Summary!$G$20 -> 0 | E21: =IF(AND(B4="Yes",B5="Optional"),D21,(IF(AND(B4="No",B5="Optional"),D22,"-"))) -> - | F21: =IF(ISERROR(E21/12),"-",E21/12) -> - | I21: Ee and Dep | J21: =Summary!$G$60+Summary!$G$61 -> 125.76
D22: =IF($E$11>Summary!$G$22,Summary!$G$22,$E$11)*Summary!$G$20 -> 0
A23: Health Insurance | B23: 1832 | C23: =CONCATENATE(Summary!$G$29,"/month") -> 432.66/month | E23: =IF(B3>0.74,Summary!$G$29*12,"-") -> - | F23: =IF(ISERROR(E23/12),"-",E23/12) -> -
A25: Unemployment, workers compensation, etc . | B25: 1892 | C25: =CONCATENATE(Summary!$G$27*100,"% of Salary") -> 0.35% of Salary | E25: =SUM($E$11*Summary!$G$27) -> 0 | F25: =IF(ISERROR(E25/12),"-",E25/12) -> 0
A27: Transit Tax | B27: 3914 | C27: =CONCATENATE(Summary!$G$76*100,"% of Salary") -> 0.241% of Salary | E27: =SUM($E$11*Summary!$G$76) -> 0 | F27: =IF(ISERROR(E27/12),"-",E27/12) -> 0
A29: Communication Technologies Core Fee | B29: 3225 | C29: =CONCATENATE(Summary!$G$75*100,"% of Salary") -> 0.54% of Salary | E29: =SUM($E$11*Summary!$G$75) -> 0 | F29: =IF(ISERROR(E29/12),"-",E29/12) -> 0
A30: Total Basic Benefits | E30: =SUM(E15:E29) -> 0 | F30: =SUM(F15:F29) -> 0 | G30: =IF(ISERROR(E30/$E$11),"-",E30/$E$11) -> -
A31: CLINICAL BENEFITS
A33: Health Insurance Reimbursement | B33: 1802 | C33: See Chart A | E33: =IF(ISERROR(INDEX(I10:J13,MATCH(B6,I10:I13,0),2)*12),"-",INDEX(I10:J13,MATCH(B6,I10:I13,0),2)*12) -> 7994.16 | F33: =IF(ISERROR(E33/12),"-",E33/12) -> 666.18
A35: Professional Liability Insurance | B35: 1803 | C35: Enter Amount | F35: =IF(ISERROR(E35/12),"-",E35/12) -> 0
A37: Supplemental Retirement4 | B37: 1804 | C37: =CONCATENATE(Summary!$G$40*100,"% of Salary") -> 3.5% of Salary | D37: =$E$11*Summary!$G$40 -> 0 | E37: =IF(B4="Yes",D37,IF(B4="No",D38,"Error")) -> 0 | F37: =IF(ISERROR(E37/12),"-",E37/12) -> 0
D38: =IF($E$11>Summary!$G$42,Summary!$G$42,$E$11)*Summary!$G$40 -> 0
A39: Life Insurance5 | B39: 1801 | C39: =CONCATENATE(Summary!$G$43*100,"% of Salary") -> 0.672% of Salary | D39: =IF($E$11>Summary!$G$44,Summary!$G$44,$E$11)*Summary!$G$43 -> 0 | E39: =IF(B7="Ee Only",D39,IF(B7="Ee and Dep",D40, "Error")) -> 38 | F39: =IF(ISERROR(E39/12),"-",E39/12) -> 3.17
C40: + Depend. Cov. | D40: =D39+Summary!G45 -> 38
A41: Accidental Death & Dismemberment5 | B41: 1801 | C41: =CONCATENATE(Summary!$G$48*100,"% of Salary") -> 0.1152% of Salary | D41: =IF($E$11>Summary!G49,Summary!G49,$E$11)*Summary!G48 -> 0 | E41: =IF(B7="Ee Only",D41,IF(B7="Ee and Dep",D42, "Error")) -> 0 | F41: =IF(ISERROR(E41/12),"-",E41/12) -> 0
C42: + Depend. Cov. | D42: =D41+IF($E$11>Summary!G49,Summary!G49,$E$11)*Summary!G50 -> 0
A43: Disability | B43: 1805 | C43: =CONCATENATE(Summary!$G$52*100,"% of Salary") -> 0.9% of Salary | E43: =$E$11*Summary!$G$52 -> 0 | F43: =IF(ISERROR(E43/12),"-",E43/12) -> 0
A45: Supplemental Health | B45: 1808 | C45: See Chart B | E45: =INDEX(I16:J17,MATCH(B7,I16:I17,0),2)*12 -> 3873.72 | F45: =IF(ISERROR(E45/12),"-",E45/12) -> 322.81
A47: Dental Insurance | B47: 1808 | C47: See Chart D | E47: =INDEX(I20:J21,MATCH(B7,I20:I21,0),2)*12 -> 1509.12 | F47: =IF(ISERROR(E47/12),"-",E47/12) -> 125.76
A49: Total Clinical Benefits | E49: =SUM(E33:E48) -> 13415 | F49: =SUM(F32:F47) -> 1117.92 | G49: =IF(ISERROR(E49/$E$11),"-",E49/$E$11) -> -
...

Sheet EPA Clin Bfts - Allocation
A1: FY13 FRINGE BENEFIT WORKSHEET - Proposed Funding Sources
A2: ='EPA Clinical Benefits'!B2 -> 0
E3: Default P&A Acct4 | G3: 1st State Acct5 | I3: 2nd State Acct5
A4: Description | B4: Object Code | C4: Annual | D4: Ee Only Portion | E4: Acct: | G4: Acct: | I4: Acct: | K4: Acct: | M4: Acct: | O4: Acct: | Q4: Acct: | S4: Acct: | U4: Acct: | W4: Acct: | Y4: Acct: | AA4: Acct: | AC4: Acct: | AE4: Check
E5: Fund%: | F5: =E8/$C$8 -> #DIV/0! | G5: Fund%: | H5: =G8/$C$8 -> #DIV/0! | I5: Fund%: | J5: =I8/$C$8 -> #DIV/0! | K5: Fund%: | L5: =K8/$C$8 -> #DIV/0! | M5: Fund%: | N5: =M8/$C$8 -> #DIV/0! | O5: Fund%: | P5: =O8/$C$8 -> #DIV/0! | Q5: Fund%: | R5: =Q8/$C$8 -> #DIV/0! | S5: Fund%: | T5: =S8/$C$8 -> #DIV/0! | U5: Fund%: | V5: =U8/$C$8 -> #DIV/0! | W5: Fund%: | X5: =W8/$C$8 -> #DIV/0! | Y5: Fund%: | Z5: =Y8/$C$8 -> #DIV/0! | AA5: Fund%: | AB5: =AA8/$C$8 -> #DIV/0! | AC5: Fund%: | AD5: =AC8/$C$8 -> #DIV/0! | AE5: =F5+H5+J5+L5+N5+P5+R5+T5+V5+X5+Z5+AB5+AD5 -> #DIV/0!
E6: Fund%26: | F6: =F5+$H$5+$J$5 -> #DIV/0! | AE6: =F6+L5+N5+P5+R5+T5+V5+X5+Z5+AB5+AD5 -> #DIV/0!
A8: Salary | B8: 11XX, 13XX | C8: ='EPA Clinical Benefits'!E11 -> 0 | E8: =C8-SUM(G8:AD8) -> 0 | S8: 0 | U8: 0 | W8: 0 | Y8: 0 | AA8: 0 | AC8: 0 | AE8: =C8-SUM(E8:AD8) -> 0
A10: BASIC BENEFITS
A12: Social Security | B12: 1812 | C12: ='EPA Clinical Benefits'!E15 -> 0 | E12: =$C12*($F$5-($AE$5-1)) -> #DIV/0! | G12: =$C$12*H$5 -> #DIV/0! | I12: =$C$12*J$5 -> #DIV/0! | K12: =$C$12*L$5 -> #DIV/0! | M12: =$C$12*N$5 -> #DIV/0! | O12: =$C$12*P$5 -> #DIV/0! | Q12: =$C$12*R$5 -> #DIV/0! | S12: =$C$12*T$5 -> #DIV/0! | U12: =$C$12*V$5 -> #DIV/0! | W12: =$C$12*X$5 -> #DIV/0! | Y12: =$C$12*Z$5 -> #DIV/0! | AA12: =$C$12*AB$5 -> #DIV/0! | AC12: =$C$12*AD$5 -> #DIV/0! | AE12: =C12-SUM(E12:AD12) -> #DIV/0!
A14: Medicare | B14: 1813 | C14: ='EPA Clinical Benefits'!E17 -> 0 | E14: =$C14*($F$5-($AE$5-1)) -> #DIV/0! | G14: =$C$14*H$5 -> #DIV/0! | I14: =$C$14*J$5 -> #DIV/0! | K14: =$C$14*L$5 -> #DIV/0! | M14: =$C$14*N$5 -> #DIV/0! | O14: =$C$14*P$5 -> #DIV/0! | Q14: =$C$14*R$5 -> #DIV/0! | S14: =$C$14*T$5 -> #DIV/0! | U14: =$C$14*V$5 -> #DIV/0! | W14: =$C$14*X$5 -> #DIV/0! | Y14: =$C$14*Z$5 -> #DIV/0! | AA14: =$C$14*AB$5 -> #DIV/0! | AC14: =$C$14*AD$5 -> #DIV/0! | AE14: =C14-SUM(E14:AD14) -> #DIV/0!
A16: State Retirement | B16: 1822 | C16: ='EPA Clinical Benefits'!E19 -> 0 | E16: =IF(ISERROR($C16*($F$5-($AE$5-1))),0,$C16*($F$5-($AE$5-1))) -> 0 | G16: =IF(ISERROR($C$16*H$5),0,$C$16*H$5) -> 0 | I16: =IF(ISERROR($C$16*J$5),0,$C$16*J$5) -> 0 | K16: =IF(ISERROR($C$16*L$5),0,$C$16*L$5) -> 0 | M16: =IF(ISERROR($C$16*N$5),0,$C$16*N$5) -> 0 | O16: =IF(ISERROR($C$16*P$5),0,$C$16*P$5) -> 0 | Q16: =IF(ISERROR($C$16*R$5),0,$C$16*R$5) -> 0 | S16: =IF(ISERROR($C$16*T$5),0,$C$16*T$5) -> 0 | U16: =IF(ISERROR($C$16*V$5),0,$C$16*V$5) -> 0 | W16: =IF(ISERROR($C$16*X$5),0,$C$16*X$5) -> 0 | Y16: =IF(ISERROR($C$16*Z$5),0,$C$16*Z$5) -> 0 | AA16: =IF(ISERROR($C$16*AB$5),0,$C$16*AB$5) -> 0 | AC16: =IF(ISERROR($C$16*AD$5),0,$C$16*AD$5) -> 0 | AE16: =IF(ISERROR(C16-SUM(E16:AD16)),0,C16-SUM(E16:AD16)) -> 0
A18: Optional State Retirement | B18: 187X | C18: ='EPA Clinical Benefits'!E21 -> - | E18: =IF(ISERROR($C$18*(F$5-(AE5-1))),0,$C$18*(F$5-(AE5-1))) -> 0 | G18: =IF(ISERROR($C$18*H$5),0,$C$18*H$5) -> 0 | I18: =IF(ISERROR($C$18*J$5),0,$C$18*J$5) -> 0 | K18: =IF(ISERROR($C$18*L$5),0,$C$18*L$5) -> 0 | M18: =IF(ISERROR($C$18*N$5),0,$C$18*N$5) -> 0 | O18: =IF(ISERROR($C$18*P$5),0,$C$18*P$5) -> 0 | Q18: =IF(ISERROR($C$18*R$5),0,$C$18*R$5) -> 0 | S18: =IF(ISERROR($C$18*T$5),0,$C$18*T$5) -> 0 | U18: =IF(ISERROR($C$18*V$5),0,$C$18*V$5) -> 0 | W18: =IF(ISERROR($C$18*X$5),0,$C$18*X$5) -> 0 | Y18: =IF(ISERROR($C$18*Z$5),0,$C$18*Z$5) -> 0 | AA18: =IF(ISERROR($C$18*AB$5),0,$C$18*AB$5) -> 0 | AC18: =IF(ISERROR($C$18*AD$5),0,$C$18*AD$5) -> 0 | AE18: =IF(ISERROR(C18-SUM(E18:AD18)),0,C18-SUM(E18:AD18)) -> 0
A20: Health Insurance | B20: 1832 | C20: ='EPA Clinical Benefits'!E23 -> - | E20: =IF(ISERROR($C20*($F$5-($AE$5-1))),0,($C20*($F$5-($AE$5-1)))) -> 0 | G20: =IF(ISERROR($C$20*H$5),0,$C$20*H$5) -> 0 | I20: =IF(ISERROR($C$20*J$5),0,$C$20*J$5) -> 0 | K20: =IF(ISERROR($C$20*L$5),0,$C$20*L$5) -> 0 | M20: =IF(ISERROR($C$20*N$5),0,$C$20*N$5) -> 0 | O20: =IF(ISERROR($C$20*P$5),0,$C$20*P$5) -> 0 | Q20: =IF(ISERROR($C$20*R$5),0,$C$20*R$5) -> 0 | S20: =IF(ISERROR($C$20*T$5),0,$C$20*T$5) -> 0 | U20: =IF(ISERROR($C$20*V$5),0,$C$20*V$5) -> 0 | W20: =IF(ISERROR($C$20*X$5),0,$C$20*X$5) -> 0 | Y20: =IF(ISERROR($C$20*Z$5),0,$C$20*Z$5) -> 0 | AA20: =IF(ISERROR($C$20*AB$5),0,$C$20*AB$5) -> 0 | AC20: =IF(ISERROR($C$20*AD$5),0,$C$20*AD$5) -> 0 | AE20: =IF(ISERROR(C20-SUM(E20:AD20)),0,C20-SUM(E20:AD20)) -> 0
A22: Unemployment, workers comp, etc . | B22: 1892 | C22: ='EPA Clinical Benefits'!E25 -> 0 | E22: =$C22*($F$5-($AE$5-1)) -> #DIV/0! | G22: =$C$22*H$5 -> #DIV/0! | I22: =$C$22*J$5 -> #DIV/0! | K22: =$C$22*L$5 -> #DIV/0! | M22: =$C$22*N$5 -> #DIV/0! | O22: =$C$22*P$5 -> #DIV/0! | Q22: =$C$22*R$5 -> #DIV/0! | S22: =$C$22*T$5 -> #DIV/0! | U22: =$C$22*V$5 -> #DIV/0! | W22: =$C$22*X$5 -> #DIV/0! | Y22: =$C$22*Z$5 -> #DIV/0! | AA22: =$C$22*AB$5 -> #DIV/0! | AC22: =$C$22*AD$5 -> #DIV/0! | AE22: =C22-SUM(E22:AD22) -> #DIV/0!
A24: Transit Tax | B24: 3914 | C24: ='EPA Clinical Benefits'!E27 -> 0 | E24: =$C24*($F$5-($AE$5-1)) -> #DIV/0! | G24: =$C$24*H$5 -> #DIV/0! | I24: =$C$24*J$5 -> #DIV/0! | K24: =$C$24*L$5 -> #DIV/0! | M24: =$C$24*N$5 -> #DIV/0! | O24: =$C$24*P$5 -> #DIV/0! | Q24: =$C$24*R$5 -> #DIV/0! | S24: =$C$24*T$5 -> #DIV/0! | U24: =$C$24*V$5 -> #DIV/0! | W24: =$C$24*X$5 -> #DIV/0! | Y24: =$C$24*Z$5 -> #DIV/0! | AA24: =$C$24*AB$5 -> #DIV/0! | AC24: =$C$24*AD$5 -> #DIV/0! | AE24: =C24-SUM(E24:AD24) -> #DIV/0!
A26: Communication Technologies Core Fee | B26: 3225 | C26: ='EPA Clinical Benefits'!E29 -> 0 | F26: =$C26*($F$5-($AE$5-1)) -> #DIV/0! | H26: =$C$26*H$5 -> #DIV/0! | J26: =$C$26*J$5 -> #DIV/0! | L26: =$C$26*L$5 -> #DIV/0! | N26: =$C$26*N$5 -> #DIV/0! | P26: =$C$26*P$5 -> #DIV/0! | R26: =$C$26*R$5 -> #DIV/0! | T26: =$C$26*T$5 -> #DIV/0! | V26: =$C$26*V$5 -> #DIV/0! | X26: =$C$26*X$5 -> #DIV/0! | Z26: =$C$26*Z$5 -> #DIV/0! | AB26: =$C$26*AB$5 -> #DIV/0! | AD26: =$C$26*AD$5 -> #DIV/0!
A27: Total Basic Benefits | C27: =SUM(C12:C26) -> 0 | E27: =SUM(E12:F26) -> #DIV/0! | G27: =SUM(G12:H26) -> #DIV/0! | I27: =SUM(I12:J26) -> #DIV/0! | K27: =SUM(K12:L26) -> #DIV/0! | M27: =SUM(M12:N26) -> #DIV/0! | O27: =SUM(O12:P26) -> #DIV/0! | Q27: =SUM(Q12:R26) -> #DIV/0! | S27: =SUM(S12:T26) -> #DIV/0! | U27: =SUM(U12:V26) -> #DIV/0! | W27: =SUM(W12:X26) -> #DIV/0! | Y27: =SUM(Y12:Z26) -> #DIV/0! | AA27: =SUM(AA12:AB26) -> #DIV/0! | AC27: =SUM(AC12:AD26) -> #DIV/0! | AE27: =C27-SUM(E27:AD27) -> #DIV/0!
A28: CLINICAL BENEFITS
A30: Health Insurance Reimbursement1 | B30: 1802 | C30: ='EPA Clinical Benefits'!E33 -> 7994.16 | E30: =$C$30 -> 7994.16 | AE30: =C30-SUM(E30:AD30) -> 0
A32: Professional Liability Insurance1 | B32: 1803 | C32: ='EPA Clinical Benefits'!E35 -> 0 | E32: =$C$32 -> 0 | AE32: =C32-SUM(E32:AD32) -> 0
A34: Supplemental Retirement2 | B34: 1804 | C34: ='EPA Clinical Benefits'!E37 -> 0 | E34: =$C34*($F$6-($AE$5-1)) -> #DIV/0! | K34: =$C$34*L$5 -> #DIV/0! | M34: =$C$34*N$5 -> #DIV/0! | O34: =$C$34*P$5 -> #DIV/0! | Q34: =$C$34*R$5 -> #DIV/0! | S34: =$C$34*T$5 -> #DIV/0! | U34: =$C$34*V$5 -> #DIV/0! | W34: =$C$34*X$5 -> #DIV/0! | Y34: =$C$34*Z$5 -> #DIV/0! | AA34: =$C$34*AB$5 -> #DIV/0! | AC34: =$C$34*AD$5 -> #DIV/0! | AE34: =C34-SUM(E34:AD34) -> #DIV/0!
A36: Life Insurance3 | B36: 1801 | C36: ='EPA Clinical Benefits'!E39 -> 38 | D36: ='EPA Clinical Benefits'!D39 -> 0 | E36: =($D36*($F$6-($AE$5-1)))+($C36-$D36) -> #DIV/0! | K36: =$D$36*L$5 -> #DIV/0! | M36: =$D$36*N$5 -> #DIV/0! | O36: =$D$36*P$5 -> #DIV/0! | Q36: =$D$36*R$5 -> #DIV/0! | S36: =$D$36*T$5 -> #DIV/0! | U36: =$D$36*V$5 -> #DIV/0! | W36: =$D$36*X$5 -> #DIV/0! | Y36: =$D$36*Z$5 -> #DIV/0! | AA36: =$D$36*AB$5 -> #DIV/0! | AC36: =$D$36*AD$5 -> #DIV/0! | AE36: =C36-SUM(E36:AD36) -> #DIV/0!
A38: Accidental Death & Dismemberment3 | B38: 1801 | C38: ='EPA Clinical Benefits'!E41 -> 0 | D38: ='EPA Clinical Benefits'!D41 -> 0 | E38: =($D38*($F$6-($AE$5-1)))+($C38-$D38) -> #DIV/0! | K38: =($D$38*L$5) -> #DIV/0! | M38: =($D$38*N$5) -> #DIV/0! | O38: =($D$38*P$5) -> #DIV/0! | Q38: =($D$38*R$5) -> #DIV/0! | S38: =($D$38*T$5) -> #DIV/0! | U38: =($D$38*V$5) -> #DIV/0! | W38: =($D$38*X$5) -> #DIV/0! | Y38: =($D$38*Z$5) -> #DIV/0! | AA38: =($D$38*AB$5) -> #DIV/0! | AC38: =($D$38*AD$5) -> #DIV/0! | AE38: =C38-SUM(E38:AD38) -> #DIV/0!
A40: Disability2 | B40: 1805 | C40: ='EPA Clinical Benefits'!E43 -> 0 | E40: =$C40*($F$6-($AE$5-1)) -> #DIV/0! | K40: =$C$40*L$5 -> #DIV/0! | M40: =$C$40*N$5 -> #DIV/0! | O40: =$C$40*P$5 -> #DIV/0! | Q40: =$C$40*R$5 -> #DIV/0! | S40: =$C$40*T$5 -> #DIV/0! | U40: =$C$40*V$5 -> #DIV/0! | W40: =$C$40*X$5 -> #DIV/0! | Y40: =$C$40*Z$5 -> #DIV/0! | AA40: =$C$40*AB$5 -> #DIV/0! | AC40: =$C$40*AD$5 -> #DIV/0! | AE40: =C40-SUM(E40:AD40) -> #DIV/0!
A42: Supplemental Health3 | B42: 1808 | C42: ='EPA Clinical Benefits'!E45 -> 3873.72 | D42: ='EPA Clinical Benefits'!J16*12 -> 1462.32 | E42: =($D42*($F$6-($AE$5-1)))+($C42-$D42) -> #DIV/0! | K42: =($D$42*L$5) -> #DIV/0! | M42: =($D$42*N$5) -> #DIV/0! | O42: =($D$42*P$5) -> #DIV/0! | Q42: =($D$42*R$5) -> #DIV/0! | S42: =($D$42*T$5) -> #DIV/0! | U42: =($D$42*V$5) -> #DIV/0! | W42: =($D$42*X$5) -> #DIV/0! | Y42: =($D$42*Z$5) -> #DIV/0! | AA42: =($D$42*AB$5) -> #DIV/0! | AC42: =($D$42*AD$5) -> #DIV/0! | AE42: =C42-SUM(E42:AD42) -> #DIV/0!
A44: Dental Insurance3 | B44: 1808 | C44: ='EPA Clinical Benefits'!E47 -> 1509.12 | D44: ='EPA Clinical Benefits'!J20*12 -> 498.6 | E44: =($D44*($F$6-($AE$5-1)))+($C44-$D44) -> #DIV/0! | K44: =($D$44*L$5) -> #DIV/0! | M44: =($D$44*N$5) -> #DIV/0! | O44: =($D$44*P$5) -> #DIV/0! | Q44: =($D$44*R$5) -> #DIV/0! | S44: =($D$44*T$5) -> #DIV/0! | U44: =($D$44*V$5) -> #DIV/0! | W44: =($D$44*X$5) -> #DIV/0! | Y44: =($D$44*Z$5) -> #DIV/0! | AA44: =($D$44*AB$5) -> #DIV/0! | AC44: =($D$44*AD$5) -> #DIV/0! | AE44: =C44-SUM(E44:AD44) -> #DIV/0!
A46: Total Clinical Benefits | C46: =SUM(C30:C45) -> 13415 | D46: =SUM(D29:D45) -> 1960.92 | E46: =SUM(E30:E45) -> #DIV/0! | G46: =SUM(G30:G45) -> 0 | I46: =SUM(I30:I45) -> 0 | K46: =SUM(K30:K45) -> #DIV/0! | M46: =SUM(M30:M45) -> #DIV/0! | O46: =SUM(O30:O45) -> #DIV/0! | Q46: =SUM(Q30:Q45) -> #DIV/0! | S46: =SUM(S30:S45) -> #DIV/0! | U46: =SUM(U30:U45) -> #DIV/0! | W46: =SUM(W30:W45) -> #DIV/0! | Y46: =SUM(Y30:Y45) -> #DIV/0! | AA46: =SUM(AA30:AA45) -> #DIV/0! | AC46: =SUM(AC30:AC45) -> #DIV/0! | AE46: =C46-SUM(E46:AD46) -> #DIV/0!
A47: TOTAL COMPENSATION | C47: =SUM(C8+C27+C46) -> 13415 | E47: =E8+E27+E46 -> #DIV/0! | G47: =G8+G27+G46 -> #DIV/0! | I47: =I8+I27+I46 -> #DIV/0! | K47: =K8+K27+K46 -> #DIV/0! | M47: =M8+M27+M46 -> #DIV/0! | O47: =O8+O27+O46 -> #DIV/0! | Q47: =Q8+Q27+Q46 -> #DIV/0! | S47: =S8+S27+S46 -> #DIV/0! | U47: =U8+U27+U46 -> #DIV/0! | W47: =W8+W27+W46 -> #DIV/0! | Y47: =Y8+Y27+Y46 -> #DIV/0! | AA47: =AA8+AA27+AA46 -> #DIV/0! | AC47: =AC8+AC27+AC46 -> #DIV/0! | AE47: =C47-SUM(E47:AD47) -> #DIV/0!
A49: NOTES: | B49: 1) This Clinical benefit (Health Insurance Reimbursement and Professional Liability) can only be spread across P&A funding sources. Actual payment of Health Insurance Reimbursement on each account is determined at the time the check request is processed. Actual payment of Professional Liability on each account is determined semi-annually by information provided to UNC P&A. | Q49: 1) This Clinical benefit (Health Insurance Reimbursement and Professional Liability) can only be spread across P&A funding sources. Actual payment of Health Insurance Reimbursement on each account is determined at the time the check request is processed. Actual payment of Professional Liability on each account is determined semi-annually by information provided to UNC P&A.
B50: 2) Entire Clinical benefit will be spread across all funding sources (except State funds) based on Fund% in that source (Supplemental Retirement and Disability). | Q50: 2) Entire Clinical benefit will be spread across all funding sources (except State funds) based on Fund% in that source (Supplemental Retirement and Disability).
B51: 3) Only the employee portion of the Clinical benefit will be spread across all funding sources (except State funds) based on Fund% in that source (Life Insurance, AD&D, Supplemental Health, Dental). | Q51: 3) Only the employee portion of the Clinical benefit will be spread across all funding sources (except State funds) based on Fund% in that source (Life Insurance, AD&D, Supplemental Health, Dental).
B52: 4) List only the default P&A account in this column. This is normally the account for the department and division where the faculty member's primary appointment lies. | Q52: 4) List only the default P&A account in this column. This is normally the account for the department and division where the faculty member's primary appointment lies.
B53: 5) List only State accounts (2 ledgers including AHEC) in these columns. If only one State account is applicable, leave second State account column blank. If no State account is applicable, leave both State account columns blank. | Q53: 5) List only State accounts (2 ledgers including AHEC) in these columns. If only one State account is applicable, leave second State account column blank. If no State account is applicable, leave both State account columns blank.
B54: 6) Fund%2 is used to allocate Clinical Benefits that can be spread across all sources except State Funds. These benefits include the entire portion of Supplemental Retirement and Disability as well as the employee only portion of Life Insurance, AD&D, Supplemental Health, and Dental Insurance. This % is automatically calculated by redistributing the Fund% on State dollars back to the default P&A Account. | Q54: 6) Fund%2 is used to allocate Clinical Benefits that can be spread across all sources except State Funds. These benefits include the entire portion of Supplemental Retirement and Disability as well as the employee only portion of Life Insurance, AD&D, Supplemental Health, and Dental Insurance. This % is automatically calculated by redistributing the Fund% on State dollars back to the default P&A Account.

Sheet EPA
A1: FY13 FRINGE BENEFIT WORKSHEET - EPA
A2: Name:
A3: FTE: | C3: Enter a value between .50 and 1.00
A4: Hired Prior to 7/1/96? | C4: Select Yes or No
A5: State or Optional Retirement? | C5: Select State, Optional, or Not Applicable
A7: Description | B7: Object Code | C7: Factor | D7: Formula | E7: Annual | F7: Monthly
A9: Salary | B9: 11XX, 13XX | F9: =E9/12 -> 0
A11: BENEFITS
A13: Social Security1 | B13: 1812 | C13: =CONCATENATE(Summary!$G$9*100,"% of Salary") -> 6.2% of Salary | E13: =IF($E$9>=Summary!G10,Summary!G9*Summary!G10,$E$9*Summary!G9) -> 0 | F13: =IF(ISERROR(E13/12),"-",E13/12) -> 0 | G13: =IF(ISERROR(F13/12),"-",F13/12) -> 0
A15: Medicare | B15: 1813 | C15: =CONCATENATE(Summary!$G$11*100,"% of Salary") -> 1.45% of Salary | E15: =SUM($E$9*Summary!G11) -> 0 | F15: =IF(ISERROR(E15/12),"-",E15/12) -> 0 | G15: =IF(ISERROR(F15/12),"-",F15/12) -> 0
A17: State Retirement2 | B17: 1822 | C17: =CONCATENATE(Summary!$G$14*100,"% of Salary") -> 14.23% of Salary | D17: =IF($E$9>=Summary!$G$15,Summary!$G$15,$E$9)*Summary!$G$14 -> 0 | E17: =IF(AND(B3>0.74,B4="Yes",B5="State"),D17,(IF(AND(B3>0.74,B4="No",B5="State"),D18,"-"))) -> - | F17: =IF(ISERROR(E17/12),"-",E17/12) -> - | G17: =IF(ISERROR(F17/12),"-",F17/12) -> -
D18: =IF($E$9>Summary!$G$16,Summary!$G$16,$E$9)*Summary!$G$14 -> 0
A19: Optional State Retirement3 | B19: 187X | C19: =CONCATENATE(Summary!$G$20*100,"% of Salary") -> 12.58% of Salary | D19: =IF($E$9>Summary!$G$21,Summary!$G$21,$E$9)*Summary!$G$20 -> 0 | E19: =IF(AND(B3>0.74,B4="Yes",B5="Optional"),D19,(IF(AND(B3>0.74,B4="No",B5="Optional"),D20,"-"))) -> - | F19: =IF(ISERROR(E19/12),"-",E19/12) -> - | G19: =IF(ISERROR(F19/12),"-",F19/12) -> -
D20: =IF($E$9>Summary!$G$22,Summary!$G$22,$E$9)*Summary!$G$20 -> 0
A21: Health Insurance | B21: 1832 | C21: =CONCATENATE(Summary!$G$29,"/month") -> 432.66/month | E21: =IF(B3>0.74,Summary!$G$29*12,"-") -> - | F21: =IF(ISERROR(E21/12),"-",E21/12) -> - | G21: =IF(ISERROR(F21/12),"-",F21/12) -> -
A23: Unemployment, workers compensation, etc . | B23: 1892 | C23: =CONCATENATE(Summary!$G$27*100,"% of Salary") -> 0.35% of Salary | E23: =SUM($E$9*Summary!G27) -> 0 | F23: =IF(ISERROR(E23/12),"-",E23/12) -> 0 | G23: =IF(ISERROR(F23/12),"-",F23/12) -> 0
A25: Transit Tax | B25: 3914 | C25: =CONCATENATE(Summary!$G$76*100,"% of Salary") -> 0.241% of Salary | E25: =SUM($E$9*Summary!G76) -> 0 | F25: =IF(ISERROR(E25/12),"-",E25/12) -> 0 | G25: =IF(ISERROR(F25/12),"-",F25/12) -> 0
A27: Communication Technologies Core Fee | B27: 3225 | C27: =CONCATENATE(Summary!$G$75*100,"% of Salary") -> 0.54% of Salary | E27: =SUM($E$9*Summary!G75) -> 0 | F27: =IF(ISERROR(E27/12),"-",E27/12) -> 0 | G27: =IF(ISERROR(F27/12),"-",F27/12) -> 0
A29: Professional Liability | B29: 1803 | C29: Enter Amount | F29: =IF(ISERROR(E29/12),"-",E29/12) -> 0 | G29: =IF(ISERROR(F29/12),"-",F29/12) -> 0
A31: Total Benefits | E31: =SUM(E13:E30) -> 0 | F31: =SUM(F13:G30) -> 0
A32: TOTAL COMPENSATION | E32: =E9+E31 -> 0 | F32: =F9+F31 -> 0
E33: Benefits as % of Salary = | F33: =E31/E9 -> #DIV/0!
A34: NOTES:
A35: ='EPA Clinical Benefits'!A54 -> 1) Social Security: CY2013 Salary maximum is $113,700
A36: ='EPA Clinical Benefits'!A55 -> 2) State and Optional Retirement: $375,000 salary max if employed PRIOR to 07/01/96, $250,000 max if employed AFTER 07/01/96

Sheet SPA
A1: FY13 FRINGE BENEFIT WORKSHEET - SPA
A2: Name:
A3: TSSD: | C3: Enter date
A4: Years of State Service: | B4: =IF(TRUNC(DAYS360(B3,Summary!G85,FALSE)/360,0)>35,"0",TRUNC(DAYS360(B3,Summary!G85,FALSE)/360,0)) -> 0
A6: Description | B6: Object Code | C6: Factor | D6: Formula | E6: Annual | F6: Monthly | I6: Chart A
I7: State Service | J7: Percent | L7: Years | M7: Percent
A8: Salary | B8: 1210 | F8: =E8/12 -> 0 | I8: Less than 10 yrs | J8: 0 | L8: 1 | M8: 0
I9: 10 but less than 15 yrs | J9: 0.015 | L9: 2 | M9: 0
A10: Longevity Pay | B10: 1271 | C10: See Chart A | D10: =IF(ISERROR(INDEX(L8:M44,MATCH(B4,L8:L44,0),2)),"0",INDEX(L8:M44,MATCH(B4,L8:L44,0),2)) -> 0 | E10: =$E$8*D10 -> 0 | I10: 15 but less than 20 yrs | J10: 0.0225 | L10: 3 | M10: 0
I11: 20 but less than 25 yrs | J11: 0.0325 | L11: 4 | M11: 0
A12: BENEFITS | I12: 25 or more yrs | J12: 0.045 | L12: 5 | M12: 0
L13: 6 | M13: 0
A14: Social Security1 | B14: 1812 | C14: =CONCATENATE(Summary!$G$9*100,"% of Salary") -> 6.2% of Salary | E14: =IF(($E$8+$E$10)>=Summary!$G$10,Summary!$G$9*Summary!$G$10,($E$8+$E$10)*Summary!$G$9) -> 0 | F14: =E14/12 -> 0 | L14: 7 | M14: 0
L15: 8 | M15: 0
A16: Medicare | B16: 1813 | C16: =CONCATENATE(Summary!$G$11*100,"% of Salary") -> 1.45% of Salary | E16: =SUM(($E$8+$E$10)*Summary!G11) -> 0 | F16: =E16/12 -> 0 | L16: 9 | M16: 0
L17: 10 | M17: 0.015
A18: State Retirement2 | B18: 1822 | C18: =CONCATENATE(Summary!$G$14*100,"% of Salary") -> 14.23% of Salary | E18: =SUM(($E$8+$E$10)*Summary!G14) -> 0 | F18: =IF(ISERROR(E18/12),"-",E18/12) -> 0 | L18: 11 | M18: 0.015
L19: 12 | M19: 0.015
A20: Health Insurance | B20: 1832 | C20: =CONCATENATE(Summary!$G$29,"/month") -> 432.66/month | E20: =Summary!G29*12 -> 5191.92 | F20: =E20/12 -> 432.66 | L20: 13 | M20: 0.015
L21: 14 | M21: 0.015
A22: Unemployment, workers compensation, etc . | B22: 1892 | C22: =CONCATENATE(Summary!$G$27*100,"% of Salary") -> 0.35% of Salary | E22: =SUM(($E$8+$E$10)*Summary!G27) -> 0 | F22: =E22/12 -> 0 | L22: 15 | M22: 0.0225
L23: 16 | M23: 0.0225
A24: Transit Tax | B24: 3914 | C24: =CONCATENATE(Summary!$G$76*100,"% of Salary") -> 0.241% of Salary | E24: =SUM(($E$8+$E$10)*Summary!G76) -> 0 | F24: =E24/12 -> 0 | L24: 17 | M24: 0.0225
L25: 18 | M25: 0.0225
A26: Severance Pay | B26: 1251 | C26: =CONCATENATE(Summary!G74*100,"% of Salary") -> 0.75% of Salary | E26: =SUM(($E$8+$E$10)*Summary!G74) -> 0 | F26: =E26/12 -> 0 | L26: 19 | M26: 0.0225
L27: 20 | M27: 0.0325
A28: Communication Technologies Core Fee | B28: 3225 | C28: =CONCATENATE(Summary!$G$75*100,"% of Salary") -> 0.54% of Salary | E28: =SUM($E$8+$E$10)*Summary!G76 -> 0 | F28: =IF(ISERROR(E28/12),"-",E28/12) -> 0 | G28: =IF(ISERROR(F28/12),"-",F28/12) -> 0
A30: Professional Liability | B30: 1803 | C30: Enter Amount | F30: =E30/12 -> 0 | L30: 21 | M30: 0.0325
L31: 22 | M31: 0.0325
A32: Total Benefits | E32: =SUM(E14:E31) -> 5191.92 | F32: =SUM(F14:G24) -> 432.66 | L32: 23 | M32: 0.0325
A33: TOTAL COMPENSATION | E33: =E8+E32 -> 5191.92 | F33: =F8+F32 -> 432.66 | L33: 24 | M33: 0.0325
E34: Benefits as % of Salary = | F34: =E32/(E8+E10) -> #DIV/0! | L34: 25 | M34: 0.045
A35: NOTES: | L35: 26 | M35: 0.045
A36: ='EPA Clinical Benefits'!A54 -> 1) Social Security: CY2013 Salary maximum is $113,700 | L36: 27 | M36: 0.045
L37: 28 | M37: 0.045
L38: 29 | M38: 0.045
L39: 30 | M39: 0.045
L40: 31 | M40: 0.045
L41: 32 | M41: 0.045
L42: 33 | M42: 0.045
...

Sheet HCS
A1: FY13 FRINGE BENEFIT WORKSHEET - HCS
A2: Name:
A3: TSSD: | C3: Enter date
A4: Years of State Service: | B4: =IF(TRUNC(DAYS360(B3,Summary!G85,FALSE)/360,0)>35,"0",TRUNC(DAYS360(B3,Summary!G85,FALSE)/360,0)) -> 0
A5: Health Insurance? | C5: Select a value from Chart A
A7: Description | B7: Object Code | C7: Factor | D7: Formula | E7: Annual | F7: Monthly | I7: Chart A
I8: Hlth Ins Spec Pay | J8: Mnthly Amt | L8: Years | M8: Percent
A9: Salary | B9: 1981/2 | F9: =E9/12 -> 0 | I9: Ee Only | J9: 8.22 | L9: 1 | M9: 0
I10: Ee and Child | J10: 103.28 | L10: 2 | M10: 0
A11: Longevity Pay | B11: 1983 | C11: See Chart B | D11: =IF(ISERROR(INDEX(L9:M43,MATCH(B4,L9:L43,0),2)),"0",INDEX(L9:M43,MATCH(B4,L9:L43,0),2)) -> 0 | E11: =$E$9*D11 -> 0 | F11: =E11/12 -> 0 | I11: Ee and Spouse | J11: 227.26 | L11: 3 | M11: 0
I12: Family | J12: 240.44 | L12: 4 | M12: 0
A13: BENEFITS | I13: Chart B | L13: 5 | M13: 0
I14: State Service | J14: Percent | L14: 6 | M14: 0
A15: Social Security1 | B15: 1989 | C15: =CONCATENATE(Summary!$G$9*100,"% of Salary") -> 6.2% of Salary | E15: =IF(($E$9+$E$11)>=Summary!$G$10,Summary!$G$9*Summary!$G$10,($E$9+$E$11)*Summary!$G$9) -> 0 | F15: =E15/12 -> 0 | I15: Less than 10 yrs | J15: 0 | L15: 7 | M15: 0
I16: 10 but less than 15 yrs | J16: 0.015 | L16: 8 | M16: 0
A17: Medicare | B17: 1989 | C17: =CONCATENATE(Summary!$G$11*100,"% of Salary") -> 1.45% of Salary | E17: =SUM(($E$9+$E$11)*Summary!G11) -> 0 | F17: =E17/12 -> 0 | I17: 15 but less than 20 yrs | J17: 0.0225 | L17: 9 | M17: 0
I18: 20 but less than 25 yrs | J18: 0.0325 | L18: 10 | M18: 0.015
A19: State Retirement2 | B19: 1989 | C19: =CONCATENATE(Summary!$G$14*100,"% of Salary") -> 14.23% of Salary | E19: =SUM(($E$9+$E$11)*Summary!G14) -> 0 | F19: =IF(ISERROR(E19/12),"-",E19/12) -> 0 | I19: 25 or more yrs | J19: 0.045 | L19: 11 | M19: 0.015
L20: 12 | M20: 0.015
A21: Health Insurance | B21: 1989 | C21: =CONCATENATE(Summary!$G$30,"/month") -> 432.66/month | E21: =Summary!G30*12 -> 5191.92 | F21: =E21/12 -> 432.66 | L21: 13 | M21: 0.015
L22: 14 | M22: 0.015
A23: Health Insurance Special Pay | B23: 1983 | C23: See Chart A | E23: =IFERROR(INDEX(I9:J12,MATCH(B5,I9:I12,0),2)*12,) -> 0 | L23: 15 | M23: 0.0225
L24: 16 | M24: 0.0225
A25: Professional Liability | B25: 1803 | C25: Enter Amount | F25: =E25/12 -> 0 | L25: 17 | M25: 0.0225
L26: 18 | M26: 0.0225
A27: Total Benefits | E27: =SUM(E15:E26) -> 5191.92 | F27: =SUM(F15:G22) -> 432.66 | L27: 19 | M27: 0.0225
A28: TOTAL COMPENSATION | E28: =E9+E27 -> 5191.92 | F28: =F9+F27 -> 432.66 | L28: 20 | M28: 0.0325
E29: Benefits as % of Salary = | F29: =E27/(E9+E11) -> #DIV/0! | L29: 21 | M29: 0.0325
A30: NOTES: | L30: 22 | M30: 0.0325
A31: ='EPA Clinical Benefits'!A54 -> 1) Social Security: CY2013 Salary maximum is $113,700 | L31: 23 | M31: 0.0325
L32: 24 | M32: 0.0325
L33: 25 | M33: 0.045
L34: 26 | M34: 0.045
L35: 27 | M35: 0.045
L36: 28 | M36: 0.045
L37: 29 | M37: 0.045
L38: 30 | M38: 0.045
L39: 31 | M39: 0.045
L40: 32 | M40: 0.045
L41: 33 | M41: 0.045
...

Sheet Fellow - Univ Payroll
A1: FY13 FRINGE BENEFIT WORKSHEET - Fellow
A2: Name:
A3: Medical Benefits? | C3: Select a value from Chart A
I4: Chart A
A5: Description | B5: Object Code | C5: Factor | D5: Formula | E5: Annual | F5: Monthly | I5: Health Ins | J5: Mthly Rate
I6: Ee Only | J6: =Summary!G78 -> 208
A7: Salary | B7: 11XX, 13XX | F7: =E7/12 -> 0 | I7: Ee and Child | J7: =Summary!G79 -> 286
I8: Ee and Spouse | J8: =Summary!G80 -> 416
A9: BASIC BENEFITS | I9: Family | J9: =Summary!G81 -> 629
A11: Social Security1 | B11: 1812 | C11: =CONCATENATE(Summary!$G$9*100,"% of Salary") -> 6.2% of Salary | E11: =IF($E$7>=Summary!$G$10,Summary!$G$9*Summary!$G$10,$E$7*Summary!$G$9) -> 0 | F11: =E11/12 -> 0
A13: Medicare | B13: 1813 | C13: =CONCATENATE(Summary!$G$11*100,"% of Salary") -> 1.45% of Salary | E13: =SUM($E$7*Summary!G11) -> 0 | F13: =E13/12 -> 0
A15: Unemployment, workers compensation, etc . | B15: 1892 | C15: =CONCATENATE(Summary!$G$27*100,"% of Salary") -> 0.35% of Salary | E15: =SUM($E$7*Summary!G27) -> 0 | F15: =E15/12 -> 0
A17: Transit Tax | B17: 3914 | C17: =CONCATENATE(Summary!$G$76*100,"% of Salary") -> 0.241% of Salary | E17: =SUM($E$7*Summary!G76) -> 0 | F17: =E17/12 -> 0
A19: Communication Technologies Core Fee | B19: 3225 | C19: =CONCATENATE(Summary!$G$75*100,"% of Salary") -> 0.54% of Salary | E19: =SUM($E$7)*Summary!G75 -> 0 | F19: =E19/12 -> 0
A21: Total Basic Benefits | E21: =SUM(E11:E19) -> 0 | F21: =SUM(F11:G19) -> 0
A22: CLINICAL BENEFITS
A24: Medical Benefits | B24: 1809 | C24: See Chart A | E24: =IFERROR(INDEX(I6:J9,MATCH(B3,I6:I9,0),2)*12,) -> 0 | F24: =E24/12 -> 0
A26: Disability Benefits | B26: 1809 | C26: =CONCATENATE("$",Summary!G83," per month") -> $11.33 per month | E26: =Summary!G83*12 -> 135.96 | F26: =E26/12 -> 11.33
A28: Professional Liability Insurance2 | B28: 1803 | C28: Enter Amount | F28: =E28/12 -> 0
A30: Total Clinical Benefits | E30: =SUM(E24:E29) -> 135.96 | F30: =SUM(F23:F29) -> 11.33
A31: TOTAL COMPENSATION | E31: =SUM(E7+E21+E30) -> 135.96 | F31: =SUM(F7+F21+F30) -> 11.33
E32: Benefits as % of Salary = | F32: =(E30+E21)/E7 -> #DIV/0!
A33: NOTES:
A34: ='EPA Clinical Benefits'!A54 -> 1) Social Security: CY2013 Salary maximum is $113,700
A35: 2) Professional Liablity is paid by the GME office UNLESS the Fellow is considered a clinical scholar

Sheet Resident
A1: FY13 FRINGE BENEFIT WORKSHEET - Resident
A2: Name:
A3: PGY Level: | C3: Select a value from Chart A
A4: Medical Benefits? | C4: Select a value from Chart B
I5: Chart A | J5: Eff 10/1/11
A6: Description | B6: Object Code | C6: Factor | D6: Formula | E6: Annual | F6: Monthly | I6: PGY Level | J6: Sugg Salary
I7: 1 | J7: 46984
A8: Salary | B8: 1901 | D8: =INDEX(I7:J15,MATCH(B3,I7:I15,0),2) | E8: =IFERROR(INDEX(I7:J15,MATCH(B3,I7:I15,0),2),) -> 0 | F8: =E8/12 -> 0 | I8: 2 | J8: 48622
I9: 3 | J9: 50203
A10: BENEFITS | I10: 4 | J10: 51306
I11: 5 | J11: 53427
A12: Social Security1 | B12: 1902 | C12: =CONCATENATE(Summary!$G$9*100,"% of Salary") -> 6.2% of Salary | E12: =IF($E$8>=Summary!$G$10,Summary!$G$9*Summary!$G$10,$E$8*Summary!$G$9) -> 0 | F12: =E12/12 -> 0 | I12: 6 | J12: 54551
I13: 7 | J13: 55676
A14: Medicare | B14: 1903 | C14: =CONCATENATE(Summary!$G$11*100,"% of Salary") -> 1.45% of Salary | E14: =SUM($E$8*Summary!G11) -> 0 | F14: =E14/12 -> 0 | I14: 8 | J14: 56801
I15: 9 | J15: =J14 -> 56801
A16: Health Insurance | B16: 1904 | C16: See Chart B | E16: =IFERROR(INDEX(I18:J21,MATCH(B4,I18:I21,0),2)*12,) -> 0 | F16: =E16/12 -> 0 | I16: Chart B
I17: Health Ins | J17: Mnthly Rate
A18: Total Benefits | E18: =SUM(E12:E17) -> 0 | F18: =SUM(F12:G17) -> 0 | I18: Ee Only | J18: =Summary!G78 -> 208
A19: TOTAL COMPENSATION | E19: =E8+E18 -> 0 | F19: =F8+F18 -> 0 | I19: Ee and Child | J19: =Summary!G79 -> 286
E20: Benefits as % of Salary = | F20: =E18/E8 -> #DIV/0! | I20: Ee and Spouse | J20: =Summary!G80 -> 416
A21: NOTES: | I21: Family | J21: =Summary!G81 -> 629
A22: ='EPA Clinical Benefits'!A54 -> 1) Social Security: CY2013 Salary maximum is $113,700

Sheet ECC
A1: FY13 FRINGE BENEFIT WORKSHEET - EPA One-Time Payments for Extended Clinical Care Agreements
A2: Name:
A3: Hired Prior to 7/1/96? | B3: Yes | C3: Enter Yes or No
A4: State or Optional Retirement? | B4: Optional | C4: Select State, Optional, or Not Applicable
A9: Description | B9: Object Code | C9: Factor | D9: Formula | E9: OTP
A11: One-Time Payment Amount | B11: 1133
A13: BENEFITS
A15: Medicare | B15: 1813 | C15: =CONCATENATE(Summary!$G$11*100,"% of Salary") -> 1.45% of Salary | E15: =SUM($E$11*Summary!G11) -> 0
A17: State Retirement | B17: 1822 | C17: =CONCATENATE(Summary!$G$14*100,"% of Salary") -> 14.23% of Salary | D17: =IF($E$11>=Summary!$G$15,Summary!$G$15,$E$11)*Summary!$G$14 -> 0 | E17: =IF(AND(B3="Yes",B4="State"),D17,(IF(AND(B3="No",B4="State"),D18,"-"))) -> -
D18: =IF($E$11>Summary!$G$16,Summary!$G$16,$E$11)*Summary!$G$14 -> 0
A19: Optional State Retirement | B19: 187X | C19: =CONCATENATE(Summary!$G$20*100,"% of Salary") -> 12.58% of Salary | D19: =IF($E$11>Summary!$G$21,Summary!$G$21,$E$11)*Summary!$G$20 -> 0 | E19: =IF(AND(B3="Yes",B4="Optional"),D19,(IF(AND(B3="No",B4="Optional"),D20,"-"))) -> 0
D20: =IF($E$11>Summary!$G$22,Summary!$G$22,$E$11)*Summary!$G$20 -> 0
A21: Unemployment, workers compensation, etc. | B21: 1892 | C21: =CONCATENATE(Summary!$G$27*100,"% of Salary") -> 0.35% of Salary | E21: =SUM($E$11*Summary!G27) -> 0
A23: Transit Tax | B23: 3914 | C23: =CONCATENATE(Summary!$G$76*100,"% of Salary") -> 0.241% of Salary | E23: =SUM($E$11*Summary!G76) -> 0
A25: Communication Technologies Core Fee | B25: 3225 | C25: =CONCATENATE(Summary!$G$75*100,"% of Salary") -> 0.54% of Salary | E25: =SUM($E$11*Summary!G75) -> 0 | F25: =IF(ISERROR(E25/12),"-",E25/12) -> 0 | G25: =IF(ISERROR(F25/12),"-",F25/12) -> 0
A27: Total Benefits | E27: =SUM(E15:E25) -> 0
A28: TOTAL COMPENSATION | E28: =E11+E27 -> 0
A30: Notes:
A31: 1) SSN Tax may be applicable but not included as most physicians' salaries are over the maximum taxable amount.
