Workbook

Sheet SUMMARY
B31: Table 1: Annual cases of bacterial meningitis and septicaemia by country and type (2011/12)
C32: Meningococcal meningitis & septicaemia | E32: Pneumococcal meningitis | F32: Haemophilus influenzae meningitis | G32: TB meningitis | H32: Other causes | I32: Neonatal Group B Streptococcal septicaemia* | J32: Total
C33: All | D33: MenB
B34: England | C34: ='UK MD'!F44 -> 1178.1 | D34: ='UK MD'!G44 -> 990.89507 | E34: ='UK non-MD'!H37 -> 297.13865 | F34: ='UK non-MD'!C54 -> 7 | G34: ='UK non-MD'!D51 -> 192 | H34: ='UK non-MD'!E54 -> 71 | J34: =SUM(E34:I34)+C34 +C35 -> 1789.4386
B35: Wales | C35: ='UK MD'!$F$45 -> 44.2 | D35: ='UK MD'!$G$45 -> 33.8
B36: Scotland* | C36: ='UK MD'!F47 -> 85 | D36: ='UK MD'!G47 -> 62.115385 | E36: ='UK non-MD'!C83 -> 37 | F36: ='UK non-MD'!D83 -> 5 | G36: ='UK non-MD'!E83 -> 5 | H36: ='UK non-MD'!F83 -> 106 | J36: =SUM(E36:I36)+C36 -> 238
B37: Northern Ireland | C37: ='UK MD'!F46 -> 48 | D37: ='UK MD'!G46 -> 39.771429 | E37: ='UK non-MD'!C66 -> 6 | F37: ='UK non-MD'!D66 -> 0 | G37: ='UK non-MD'!E66 -> 0 | H37: ='UK non-MD'!F66 -> 2 | J37: =SUM(E37:I37)+C37 -> 56
B38: Total UK | C38: =SUM(C34:C37) -> 1355.3 | D38: =SUM(D34:D37) -> 1126.5819 | E38: =SUM(E34:E37) -> 340.13865 | F38: =SUM(F34:F37) -> 12 | G38: =SUM(G34:G37) -> 197 | H38: =SUM(H34:H37) -> 179 | I38: 274 | J38: =SUM(E38:I38)+C38 -> 2357.4386
B39: * Scottish data is for calendar year 2012 because epidemiological data was unavailable
B41: Table 2: Annual cases of bacterial meningitis and septicaemia by country and type to represent the burden of uncontrolled disease
C42: Meningococcal meningitis & septicaemia | E42: Pneumococcal meningitis | F42: Haemophilus influenzae meningitis | G42: TB meningitis | H42: Other causes | I42: Neonatal Group B Streptococcal septicaemia** | J42: Total
C43: All | D43: MenB
B44: England | C44: ='UK MD'!J44 -> 1658.6355 | D44: ='UK MD'!D44 -> 1493.7649 | E44: ='UK non-MD'!H38 -> 358.04633 | F44: ='UK non-MD'!C56 -> 18.5 | G44: ='UK non-MD'!D56 -> 198.77778 | H44: ='UK non-MD'!E56 -> 274 | J44: =SUM(E44:I44)+C44+C45 -> 2579.4777
B45: Wales | C45: ='UK MD'!$J$45 -> 71.518073 | D45: ='UK MD'!$D$45 -> 64.216174
B46: Scotland* | C46: ='UK MD'!C47 -> 147.58333 | D46: ='UK MD'!D47 -> 118.44 | E46: ='UK non-MD'!C85 -> 25.833333 | F46: ='UK non-MD'!D85 -> 3.8333333 | G46: ='UK non-MD'!E85 -> 7.0833333 | H46: ='UK non-MD'!F85 -> 51.166667 | J46: =SUM(E46:I46)+C46 -> 235.5
B47: Northern Ireland | C47: ='UK MD'!C46 -> 97.916667 | D47: ='UK MD'!D46 -> 84.370279 | E47: ='UK non-MD'!C67 -> 2.8333333 | F47: ='UK non-MD'!D67 -> 0.16666667 | G47: ='UK non-MD'!E67 -> 0.71428571 | H47: ='UK non-MD'!F67 -> 32.571429 | J47: =SUM(E47:I47)+C47 -> 134.20238
B48: Total UK | C48: =SUM(C44:C47) -> 1975.6536 | D48: =SUM(D44:D47) -> 1760.7914 | E48: =SUM(E44:E47) -> 386.713 | F48: =SUM(F44:F47) -> 22.5 | G48: =SUM(G44:G47) -> 206.5754 | H48: =SUM(H44:H47) -> 357.7381 | I48: 274 | J48: =SUM(E48:I48)+C48 -> 3223.1801
B49: * Scottish data is for calendar years 2000 - 2012 because epidemiological data was unavailable

Sheet UK MD
B41: Table 1: Cases of meningococcal disease in the UK in 2011/12 and 12 year averages
C42: 12 YEAR AVERAGE | F42: 2011/12 | I42: 12 yr average MenC - 2011/12 MenC | J42: 12 yr average meningo cases reduced to reflect the impact of MenC vaccination
C43: Total Mening | D43: MenB | E43: MenC | F43: Total Mening | G43: MenB | H43: MenC
B44: ENGLAND | C44: =D66 -> 1721.85 | D44: =L66 -> 1493.7649 | E44: =M66 -> 110.01573 | F44: =D65 -> 1178.1 | G44: =L65 -> 990.89507 | H44: =M65 -> 46.801233 | I44: =E44-H44 -> 63.214495 | J44: =C44-I44 -> 1658.6355
B45: WALES | C45: =C82*1.3 -> 77.025 | D45: =J82 -> 64.216174 | E45: =M82 -> 5.5069266 | F45: =C81*1.3 -> 44.2 | G45: =J81 -> 33.8 | H45: =M81 -> 0 | I45: =E45-H45 -> 5.5069266 | J45: =C45-I45 -> 71.518073
B46: NI | C46: =C98 -> 97.916667 | D46: =I98 -> 84.370279 | E46: =K98 -> 3.9914002 | F46: =C97 -> 48 | G46: =I97 -> 39.771429 | H46: =K97 -> 2.7428571 | I46: =E46-H46 -> 1.2485431 | J46: =C46-I46 -> 96.668124
B47: SCOTLAND | C47: =C115 -> 147.58333 | D47: =I115 -> 118.44 | E47: =K115 -> 7.8898945 | F47: =C114 -> 85 | G47: =I114 -> 62.115385 | H47: =K114 -> 3.2692308 | I47: =E47-H47 -> 4.6206638 | J47: =C47-I47 -> 142.96267
B48: TOTAL | C48: =SUM(C44:C47) -> 2044.375 | D48: =SUM(D44:D47) -> 1760.7914 | E48: =SUM(E44:E47) -> 127.40395 | F48: =SUM(F44:F47) -> 1355.3 | G48: =SUM(G44:G47) -> 1126.5819 | H48: =SUM(H44:H47) -> 52.813321 | I48: =SUM(I44:I47) -> 74.590628 | J48: =SUM(J44:J47) -> 1969.7844
B51: Table 2: Cases of meningococal disease in England: HES and Lab confirmed data (2000/01 to 2011/12)
E52: Meningococcal Reference Unit isolates of Neisseria menengitidis
B53: Year | C53: HES Admissions data A39 | D53: Cleaned HES admissions data | E53: All cases | F53: All cases (excl. ungroupable) | G53: Ungroupable cases | H53: MenB | I53: MenC | J53: MenB as a percentage of all cases (excl. Ungroupable) | K53: MenC as a percentage of all cases (excl. Ungroupable) | L53: Total MenB estimate | M53: Total MenC estimate
B54: 00/01 | C54: 3225 | D54: =C54*0.9 -> 2902.5 | E54: 2342 | F54: =E54-G54 -> 2333 | G54: 9 | H54: 1688 | I54: 412 | J54: =H54/F54*100 -> 72.353193 | K54: =I54/F54*100 -> 17.659666 | L54: =D54*(J54/100) -> 2100.0514 | M54: =D54*K54/100 -> 512.5718
B55: 01/02 | C55: 2639 | D55: =C55*0.9 -> 2375.1 | E55: 1854 | F55: =E55-G55 -> 1851 | G55: 3 | H55: 1501 | I55: 210 | J55: =H55/F55*100 -> 81.091302 | K55: =I55/F55*100 -> 11.345219 | L55: =D55*(J55/100) -> 1925.9995 | M55: =D55*K55/100 -> 269.46029
B56: 02/03 | C56: 2133 | D56: =C56*0.9 -> 1919.7 | E56: 1415 | F56: =E56-G56 -> 1413 | G56: 2 | H56: 1210 | I56: 121 | J56: =H56/F56*100 -> 85.633404 | K56: =I56/F56*100 -> 8.5633404 | L56: =D56*(J56/100) -> 1643.9045 | M56: =D56*K56/100 -> 164.39045
B57: 03/04 | C57: 2103 | D57: =C57*0.9 -> 1892.7 | E57: 1438 | F57: =E57-G57 -> 1436 | G57: 2 | H57: 1297 | I57: 64 | J57: =H57/F57*100 -> 90.320334 | K57: =I57/F57*100 -> 4.4568245 | L57: =D57*(J57/100) -> 1709.493 | M57: =D57*K57/100 -> 84.354318
B58: 04/05 | C58: 1874 | D58: =C58*0.9 -> 1686.6 | E58: 1384 | F58: =E58-G58 -> 1384 | G58: 0 | H58: 1274 | I58: 42 | J58: =H58/F58*100 -> 92.052023 | K58: =I58/F58*100 -> 3.0346821 | L58: =D58*(J58/100) -> 1552.5494 | M58: =D58*K58/100 -> 51.182948
B59: 05/06 | C59: 1728 | D59: =C59*0.9 -> 1555.2 | E59: 1226 | F59: =E59-G59 -> 1226 | G59: 0 | H59: 1156 | I59: 30 | J59: =H59/F59*100 -> 94.290375 | K59: =I59/F59*100 -> 2.4469821 | L59: =D59*(J59/100) -> 1466.4039 | M59: =D59*K59/100 -> 38.055465
B60: 06/07 | C60: 1622 | D60: =C60*0.9 -> 1459.8 | E60: 1091 | F60: =E60-G60 -> 1090 | G60: 1 | H60: 991 | I60: 29 | J60: =H60/F60*100 -> 90.917431 | K60: =I60/F60*100 -> 2.6605505 | L60: =D60*(J60/100) -> 1327.2127 | M60: =D60*K60/100 -> 38.838716
B61: 07/08 | C61: 1724 | D61: =C61*0.9 -> 1551.6 | E61: 1190 | F61: =E61-G61 -> 1188 | G61: 2 | H61: 1082 | I61: 29 | J61: =H61/F61*100 -> 91.077441 | K61: =I61/F61*100 -> 2.4410774 | L61: =D61*(J61/100) -> 1413.1576 | M61: =D61*K61/100 -> 37.875758
B62: 08/09 | C62: 1710 | D62: =C62*0.9 -> 1539 | E62: 1109 | F62: =E62-G62 -> 1108 | G62: 1 | H62: 1050 | I62: 13 | J62: =H62/F62*100 -> 94.765343 | K62: =I62/F62*100 -> 1.1732852 | L62: =D62*(J62/100) -> 1458.4386 | M62: =D62*K62/100 -> 18.056859
B63: 09/10 | C63: 1342 | D63: =C63*0.9 -> 1207.8 | E63: 862 | F63: =E63-G63 -> 859 | G63: 3 | H63: 792 | I63: 18 | J63: =H63/F63*100 -> 92.200233 | K63: =I63/F63*100 -> 2.0954598 | L63: =D63*(J63/100) -> 1113.5944 | M63: =D63*K63/100 -> 25.308964
B64: 10/11 | C64: 1549 | D64: =C64*0.9 -> 1394.1 | E64: 1010 | F64: =E64-G64 -> 1005 | G64: 5 | H64: 882 | I64: 24 | J64: =H64/F64*100 -> 87.761194 | K64: =I64/F64*100 -> 2.3880597 | L64: =D64*(J64/100) -> 1223.4788 | M64: =D64*K64/100 -> 33.29194
B65: 11/12 | C65: 1309 | D65: =C65*0.9 -> 1178.1 | E65: 732 | F65: =E65-G65 -> 730 | G65: 2 | H65: 614 | I65: 29 | J65: =H65/F65*100 -> 84.109589 | K65: =I65/F65*100 -> 3.9726027 | L65: =D65*(J65/100) -> 990.89507 | M65: =D65*K65/100 -> 46.801233
B66: Average (past 12 yrs) | C66: =AVERAGE(C54:C65) -> 1913.1667 | D66: =AVERAGE(D54:D65) -> 1721.85 | E66: =AVERAGE(E54:E65) -> 1304.4167 | F66: =AVERAGE(F54:F65) -> 1301.9167 | G66: =AVERAGE(G54:G65) -> 2.5 | H66: =AVERAGE(H54:H65) -> 1128.0833 | I66: =AVERAGE(I54:I65) -> 85.083333 | J66: =AVERAGE(J54:J65) -> 88.047655 | ... M66: =AVERAGE(M54:M65) -> 110.01573
B68: Table 3: Meningococcal Reference Unit isolates of Neisseria menengitidis: Wales (2000/01 to 2011/12)
B69: Year | C69: All cases | D69: All cases (excl. ungroupable) | E69: Ungroupable cases | F69: MenB | G69: MenC | H69: MenB as a percentage of all cases (excl. Ungroupable) | I69: Total MenB estimate | J69: Total MenB estimate with 1.3 uplift | K69: MenC as a percentage of all grouped cases | L69: Total MenC estimate | M69: Total MenC estimate with 1.3 uplift
B70: 00/01 | C70: 104 | D70: =C70-E70 -> 101 | E70: 3 | F70: 74 | G70: 23 | H70: =F70/D70*100 -> 73.267327 | I70: =(E70*(H70/100))+F70 -> 76.19802 | J70: =I70*1.3 -> 99.057426 | K70: =G70/D70*100 -> 22.772277 | L70: =(E70*(K70/100))+G70 -> 23.683168 | M70: =L70*1.3 -> 30.788119
B71: 01/02 | C71: 107 | D71: =C71-E71 -> 107 | E71: 0 | F71: 78 | G71: 13 | H71: =F71/D71*100 -> 72.897196 | I71: =(E71*(H71/100))+F71 -> 78 | J71: =I71*1.3 -> 101.4 | K71: =G71/D71*100 -> 12.149533 | L71: =(E71*(K71/100))+G71 -> 13 | M71: =L71*1.3 -> 16.9
B72: 02/03 | C72: 61 | D72: =C72-E72 -> 60 | E72: 1 | F72: 49 | G72: 6 | H72: =F72/D72*100 -> 81.666667 | I72: =(E72*(H72/100))+F72 -> 49.816667 | J72: =I72*1.3 -> 64.761667 | K72: =G72/D72*100 -> 10 | L72: =(E72*(K72/100))+G72 -> 6.1 | M72: =L72*1.3 -> 7.93
B73: 03/04 | C73: 55 | D73: =C73-E73 -> 55 | E73: 0 | F73: 47 | G73: 3 | H73: =F73/D73*100 -> 85.454545 | I73: =(E73*(H73/100))+F73 -> 47 | J73: =I73*1.3 -> 61.1 | K73: =G73/D73*100 -> 5.4545455 | L73: =(E73*(K73/100))+G73 -> 3 | M73: =L73*1.3 -> 3.9
B74: 04/05 | C74: 57 | D74: =C74-E74 -> 57 | E74: 0 | F74: 54 | G74: 1 | H74: =F74/D74*100 -> 94.736842 | I74: =(E74*(H74/100))+F74 -> 54 | J74: =I74*1.3 -> 70.2 | K74: =G74/D74*100 -> 1.754386 | L74: =(E74*(K74/100))+G74 -> 1 | M74: =L74*1.3 -> 1.3
B75: 05/06 | C75: 53 | D75: =C75-E75 -> 53 | E75: 0 | F75: 52 | G75: 0 | H75: =F75/D75*100 -> 98.113208 | I75: =(E75*(H75/100))+F75 -> 52 | J75: =I75*1.3 -> 67.6 | K75: =G75/D75*100 -> 0 | L75: =(E75*(K75/100))+G75 -> 0 | M75: =L75*1.3 -> 0
B76: 06/07 | C76: 42 | D76: =C76-E76 -> 40 | E76: 2 | F76: 35 | G76: 1 | H76: =F76/D76*100 -> 87.5 | I76: =(E76*(H76/100))+F76 -> 36.75 | J76: =I76*1.3 -> 47.775 | K76: =G76/D76*100 -> 2.5 | L76: =(E76*(K76/100))+G76 -> 1.05 | M76: =L76*1.3 -> 1.365
B77: 07/08 | C77: 53 | D77: =C77-E77 -> 53 | E77: 0 | F77: 47 | G77: 1 | H77: =F77/D77*100 -> 88.679245 | I77: =(E77*(H77/100))+F77 -> 47 | J77: =I77*1.3 -> 61.1 | K77: =G77/D77*100 -> 1.8867925 | L77: =(E77*(K77/100))+G77 -> 1 | M77: =L77*1.3 -> 1.3
B78: 08/09 | C78: 55 | D78: =C78-E78 -> 55 | E78: 0 | F78: 49 | G78: 0 | H78: =F78/D78*100 -> 89.090909 | I78: =(E78*(H78/100))+F78 -> 49 | J78: =I78*1.3 -> 63.7 | K78: =G78/D78*100 -> 0 | L78: =(E78*(K78/100))+G78 -> 0 | M78: =L78*1.3 -> 0
B79: 09/10 | C79: 47 | D79: =C79-E79 -> 47 | E79: 0 | F79: 40 | G79: 0 | H79: =F79/D79*100 -> 85.106383 | I79: =(E79*(H79/100))+F79 -> 40 | J79: =I79*1.3 -> 52 | K79: =G79/D79*100 -> 0 | L79: =(E79*(K79/100))+G79 -> 0 | M79: =L79*1.3 -> 0
B80: 10/11 | C80: 43 | D80: =C80-E80 -> 43 | E80: 0 | F80: 37 | G80: 2 | H80: =F80/D80*100 -> 86.046512 | I80: =(E80*(H80/100))+F80 -> 37 | J80: =I80*1.3 -> 48.1 | K80: =G80/D80*100 -> 4.6511628 | L80: =(E80*(K80/100))+G80 -> 2 | M80: =L80*1.3 -> 2.6
B81: 11/12 | C81: 34 | D81: =C81-E81 -> 34 | E81: 0 | F81: 26 | G81: 0 | H81: =F81/D81*100 -> 76.470588 | I81: =(E81*(H81/100))+F81 -> 26 | J81: =I81*1.3 -> 33.8 | K81: =G81/D81*100 -> 0 | L81: =(E81*(K81/100))+G81 -> 0 | M81: =L81*1.3 -> 0
B82: Average (past 12 yrs) | C82: =AVERAGE(C70:C81) -> 59.25 | D82: =AVERAGE(D70:D81) -> 58.75 | E82: =AVERAGE(E70:E81) -> 0.5 | F82: =AVERAGE(F70:F81) -> 49 | G82: =AVERAGE(G70:G81) -> 4.1666667 | H82: =AVERAGE(H70:H81) -> 84.919118 | I82: =AVERAGE(I70:I81) -> 49.397057 | J82: =AVERAGE(J70:J81) -> 64.216174 | ... M82: =AVERAGE(M70:M81) -> 5.5069266
B84: Table 4: Enhanced surveillance of meningococcal disease in Northern Ireland. Notifications validated with lab confirmed data (2000/01 to 2011/12)
...

Sheet UK non-MD
B30: Table 1: Cases of pneumococcal meningitis in England and Wales: HES and NOIDS data (2007/8 to 2011/12)
E31: Notifications of pneumococcal meningitis by calendar year (2007-2012)
B32: Year | C32: HES Admissions data G001 | D32: Cleaned HES admissions data | E32: England and Wales | F32: England | G32: Uplift required to convert English NOIDS to E&W NOIDS | H32: Cleaned HES admissions data uplifted to include Wales
B33: 2007-08 | C33: 490 | D33: =C33*0.75 -> 367.5 | E33: 173 | F33: 168 | G33: =E33/F33 -> 1.0297619 | H33: =D33*G33 -> 378.4375
B34: 2008-09 | C34: 487 | D34: =C34*0.75 -> 365.25 | E34: 169 | F34: 157 | G34: =E34/F34 -> 1.0764331 | H34: =D34*G34 -> 393.1672
B35: 2009-10 | C35: 460 | D35: =C35*0.75 -> 345 | E35: 186 | F35: 169 | G35: =E35/F35 -> 1.1005917 | H35: =D35*G35 -> 379.70414
B36: 2010-11 | C36: 428 | D36: =C36*0.75 -> 321 | E36: 148 | F36: 139 | G36: =E36/F36 -> 1.0647482 | H36: =D36*G36 -> 341.78417
B37: 2011-12 | C37: 371 | D37: =C37*0.75 -> 278.25 | E37: 57 | F37: ? | G37: =AVERAGE(G33:G36) -> 1.0678837 | H37: =D37*G37 -> 297.13865
B38: Average over past 5 years | C38: =AVERAGE(C33:C37) -> 447.2 | D38: =AVERAGE(D33:D37) -> 335.4 | E38: =AVERAGE(E33:E37) -> 146.6 | F38: =AVERAGE(F33:F37) -> 158.25 | G38: =AVERAGE(G33:G37) -> 1.0678837 | H38: =AVERAGE(H33:H37) -> 358.04633
B40: Table 2: Cases of other bacterial meningitis in England and Wales: NOIDS data (2000 to 2012)
B41: Year | C41: Hi | D41: TB men | E41: Other causes
B42: 2000 | C42: 39 | D42: 94 | E42: 464
B43: 2001 | C43: 74 | D43: 161 | E43: 517
B44: 2002 | C44: 62 | D44: 140 | E44: 361
B45: 2003 | C45: 63 | D45: 150 | E45: 323
B46: 2004 | C46: 45 | D46: 140 | E46: 294
B47: 2005 | C47: 44 | D47: 228 | E47: 315
B48: 2006 | C48: 57 | D48: 252 | E48: 321
B49: 2007 | C49: 32 | D49: 320 | E49: 254
B50: 2008 | C50: 24 | D50: 206 | E50: 260
B51: 2009 | C51: 31 | D51: 192 | E51: 275
B52: 2010 | C52: 12 | D52: ? | E52: 211
B53: 2011 | C53: 5 | D53: ? | E53: 86
B54: 2012 | C54: 7 | D54: ? | E54: 71
B56: Average | C56: =AVERAGE(C49:C55) -> 18.5 | D56: =AVERAGE(D43:D55) -> 198.77778 | E56: =AVERAGE(E43:E55) -> 274
B58: Table 3: Cases of other bacterial meningitis in Northern Ireland sourced from PHA (2006 to 2012)
B59: Year | C59: Pneumococcal meningitis | D59: Hib meningitis | E59: TB meningitis | F59: Other bacterial meningitis
B60: 2006 | C60: 5 | D60: 0 | E60: 0 | F60: 63
B61: 2007 | C61: 1 | D61: 1 | E61: 1 | F61: 39
B62: 2008 | C62: 3 | D62: 0 | E62: 1 | F62: 40
B63: 2009 | C63: 2 | D63: 0 | E63: 0 | F63: 36
B64: 2010 | C64: 2 | D64: 0 | E64: 1 | F64: 45
B65: 2011 | C65: 3 | D65: 0 | E65: 2 | F65: 3
B66: 2012 | C66: 6 | D66: 0 | E66: 0 | F66: 2
B67: Average | C67: =AVERAGE(C61:C66) -> 2.8333333 | D67: =AVERAGE(D61:D66) -> 0.16666667 | E67: =AVERAGE(E60:E66) -> 0.71428571 | F67: =AVERAGE(F60:F66) -> 32.571429
B69: Table 4: Cases of other bacterial meningitis in Scotland sourced from HPS (2000 to 2012)
B70: Year | C70: Cases of Pneumococcal meningitis reported to SPIDER | D70: Haemophilus influenzae CSF isolates (and cases from 2002) | E70: TB Meningitis Cases reported to ESMI* | F70: Other bacterial (CSF Isolates)
B71: 2000 | C71: 32 | D71: 3 | E71: 7 | F71: 23
B72: 2001 | C72: 38 | D72: 4 | E72: 4 | F72: 17
B73: 2002 | C73: 35 | D73: 6 | E73: 7 | F73: 20
...

Sheet NOTES
