Workbook
Name LivestockWildlife: [1]DATA!$B$4:$B$28
Name Plant_Name: '[1]Plant Species ID-08'!$A$2:$A$890

Sheet ID-CPA-011
B1: Prescibed Grazing - 528 ID-CPA-011
B2: Rangeland Health Evaluation Idaho
A3: Natural Resources Conservation Service | E3: January 2014
A5: Client : _____________________________________________ | E5: Date: ______________________________________________
A6: Conservationist : _____________________________________ | E6: Location: ___________________________________________
A7: Ecological Site : _____________________________________ | E7: Reference Vegetation State: _____________________________
A9: Departure from Expected | C9: Code | E9: Instructions:
A10: None to Slight........................................................... | C10: NS | E10: (1) Assign 17 indicator ratings. If indicator not present, rate None to Slight.
A11: Slight to Moderate.............................................................. | C11: SM | E11: (2) Assign overall rating for each attribute based on preponderance of evidence. The charts below provide a visual guide for determining the preponderance of evidence.
A12: Moderate...................................................................... | C12: M
A13: Moderate to Extreme.............................................................. | C13: ME | E13: (3) Justify each attribute rating in writing.
A14: Extreme to Total.............................................................. | C14: ET
A15: Indicator | B15: Rating | E15: Comments
A16: 1. Rills | B16: S | C16: H
A18: 2. Water-flow Patterns | B18: S | C18: H
A20: 3. Pedestals and/or terracettes | B20: S | C20: H
A22: 4. Bare Ground ______% | B22: S | C22: H
A24: 5. Gullies | B24: S | C24: H
A26: 6. Wind-scoured, blowouts, and/or deposition areas | B26: S
A28: 7. Litter movement | B28: S
A30: 8. Soil surface resistance to erosion | B30: S | C30: H | D30: B
I31: Attribute Rating Frequency
A32: 9. Soil Surface loss or degradation | B32: S | C32: H | D32: B | I32: SSS | K32: HF | M32: BI
I33: NS | J33: =COUNTIF(I39:I48,I33) -> 0 | K33: NS | L33: =COUNTIF(K39:K48,K33) -> 0 | M33: NS | N33: =COUNTIF(M39:M48,M33) -> 0
A34: 10. Plant community composition and distribution relative to infiltration and runoff | C34: H | I34: SM | J34: =COUNTIF(I40:I48,I34) -> 0 | K34: SM | L34: =COUNTIF(K40:K48,K34) -> 0 | M34: SM | N34: =COUNTIF(M40:M48,M34) -> 0
I35: M | J35: =COUNTIF(I41:I48,I35) -> 0 | K35: M | L35: =COUNTIF(K41:K48,K35) -> 0 | M35: M | N35: =COUNTIF(M41:M48,M35) -> 0
A36: 11. Compaction layer | B36: S | C36: H | D36: B | I36: ME | J36: =COUNTIF(I42:I48,I36) -> 0 | K36: ME | L36: =COUNTIF(K42:K48,K36) -> 0 | M36: ME | N36: =COUNTIF(M42:M48,M36) -> 0
I37: ET | J37: =COUNTIF(I43:I48,I37) -> 0 | K37: ET | L37: =COUNTIF(K43:K48,K37) -> 0 | M37: ET | N37: =COUNTIF(M43:M48,M37) -> 0
A38: 12. Functional/structural groups | D38: B
I39: ='ID-CPA-011'!B17 -> 0 | K39: ='ID-CPA-011'!B17 -> 0 | M39: ='ID-CPA-011'!B31 -> 0
A40: 13. Plant mortality/decadence | D40: B | I40: ='ID-CPA-011'!B19 -> 0 | K40: ='ID-CPA-011'!B19 -> 0 | M40: ='ID-CPA-011'!B33 -> 0
I41: ='ID-CPA-011'!B21 -> 0 | K41: ='ID-CPA-011'!B21 -> 0 | M41: ='ID-CPA-011'!B37 -> 0
A42: 14. Litter amount | C42: H | D42: B | I42: ='ID-CPA-011'!B23 -> 0 | K42: ='ID-CPA-011'!B23 -> 0 | M42: ='ID-CPA-011'!D39 -> 0
I43: ='ID-CPA-011'!B25 -> 0 | K43: ='ID-CPA-011'!B25 -> 0 | M43: ='ID-CPA-011'!D41 -> 0
A44: 15. Annual production | D44: B | I44: ='ID-CPA-011'!B27 -> 0 | K44: ='ID-CPA-011'!B31 -> 0 | M44: ='ID-CPA-011'!C43 -> 0
I45: ='ID-CPA-011'!B29 -> 0 | K45: ='ID-CPA-011'!B33 -> 0 | M45: ='ID-CPA-011'!D45 -> 0
A46: 16. Invasive plants | D46: B | I46: ='ID-CPA-011'!B31 -> 0 | K46: ='ID-CPA-011'!C35 -> 0 | M46: ='ID-CPA-011'!D47 -> 0
I47: ='ID-CPA-011'!B33 -> 0 | K47: ='ID-CPA-011'!B37 -> 0 | M47: ='ID-CPA-011'!D49 -> 0
A48: 17. Reproductive capability of perennial plants | D48: B | I48: ='ID-CPA-011'!B37 -> 0 | K48: ='ID-CPA-011'!C43 -> 0
A66: Soil-Site Stability Rating :
...
