Workbook
Name \: [1]Formula!#REF!
Name \a: [1]Formula!#REF!
Name \b: [1]Formula!#REF!
Name \c: [1]Formula!#REF!
Name \p: [1]Formula!#REF!
Name _10: #N/A
Name _11: #N/A
Name _12: #N/A
Name _13: #N/A
Name _14: #N/A
Name _15: #N/A
Name _6: #N/A
Name _8: #N/A
Name _9: #N/A
Name AV9_15: #N/A
Name BUDGET: #N/A
Name CAREA: #N/A
Name CEBUDGET: #N/A
Name CF: #N/A
Name CL: #N/A
Name CTACC: #N/A
Name DSM: #N/A
Name FMP: #N/A
Name JTOT: #N/A
Name LETTER: #N/A
Name MACRO: [1]Formula!#REF!
Name p: #N/A
Name PCAP: #N/A
Name PCODE: #N/A
Name POINT: #N/A
Name PREMIUM: #N/A
Name Print_Area_MI: [1]Formula!#REF!
Name PRYBASE: #N/A
Name REP: #N/A
Name RMP: #N/A
Name RMV: #N/A
Name Sched3Mail: #REF!
Name SCODE: #N/A
Name SECBASE: #N/A
Name SENMail: #REF!
Name T_Finance: #REF!
Name TOT: #N/A
Name WMACRO: #N/A
Name WMEALS: #N/A
Name Z: #N/A

Sheet Sheet1
AA1: APPENDIX 1
C4: Allocations from the Growth Fund 2013/14
T7: 19
T8: Variation by Year Group
A9: Cost Centre | B9: DfE No | C9: School | D9: Growth in Year Group in Sept 2012 | E9: Estimate Increase | F9: AWPU Rate | G9: Estimated Allocation | I9: Actual Increase@ Oct 12 | J9: Funding Allocation | L9: Growth in Year Group in Sept 2013 | M9: Estimate Increase | N9: Current Pupil Entitlement Estimate | O9: Estimated Allocation | Q9: Actual Oct 13 Pupil Variation | R9: No of Places to be Funded | S9: Amount To be Allocated | T9: Rec | U9: Y1 | V9: Y2 | W9: Y3 | X9: Y4 | Y9: Y5 | Z9: Y6
S10: 3096
A11: REABY | B11: 3302034 | C11: BROOKFIELDS | D11: 3 | E11: 20 | F11: =VLOOKUP(D11,$E$76:$F$82,2,0) -> 2406.0653 | G11: =+E11*F11/12*7 -> 28070.762 | I11: 20 | J11: 29484 | L11: =+D11+1 -> 4 | M11: =+E11 -> 20 | N11: 3102.4449 | O11: =+M11*N11/12*7 -> 36195.191 | P11: =+N11*M11/12*5 -> 25853.708 | Q11: =VLOOKUP(B11,[2]Sheet1!A$6:H$305,8,0) -> 48 | R11: 20 | S11: =+$S$10*R11/12*7 -> 36120 | T11: =VLOOKUP($B11,[3]oct13!$D$3:$K$244,[3]oct13!E$1,0)-VLOOKUP(Sheet1!$B11,[3]oct12!$E$3:$L$435,[3]oct12!F$1,0) -> 6 | U11: =VLOOKUP($B11,[3]oct13!$D$3:$K$244,[3]oct13!F$1,0)-VLOOKUP(Sheet1!$B11,[3]oct12!$E$3:$L$435,[3]oct12!G$1,0) -> 5 | V11: =VLOOKUP($B11,[3]oct13!$D$3:$K$244,[3]oct13!G$1,0)-VLOOKUP(Sheet1!$B11,[3]oct12!$E$3:$L$435,[3]oct12!H$1,0) -> 9 | W11: =VLOOKUP($B11,[3]oct13!$D$3:$K$244,[3]oct13!H$1,0)-VLOOKUP(Sheet1!$B11,[3]oct12!$E$3:$L$435,[3]oct12!I$1,0) -> 20 | X11: =VLOOKUP($B11,[3]oct13!$D$3:$K$244,[3]oct13!I$1,0)-VLOOKUP(Sheet1!$B11,[3]oct12!$E$3:$L$435,[3]oct12!J$1,0) -> 4 | Y11: =VLOOKUP($B11,[3]oct13!$D$3:$K$244,[3]oct13!J$1,0)-VLOOKUP(Sheet1!$B11,[3]oct12!$E$3:$L$435,[3]oct12!K$1,0) -> -2 | Z11: =VLOOKUP($B11,[3]oct13!$D$3:$K$244,[3]oct13!K$1,0)-VLOOKUP(Sheet1!$B11,[3]oct12!$E$3:$L$435,[3]oct12!L$1,0) -> 6
A12: REAKC | B12: 3302063 | C12: REGENTS PARK | D12: 1 | E12: 30 | F12: =VLOOKUP(D12,$E$76:$F$82,2,0) -> 2417.5937 | G12: =+E12*F12/12*7 -> 42307.889 | I12: 30 | J12: 29430.333 | L12: =+D12+1 -> 2 | M12: =+E12 -> 30 | N12: 3102.4449 | O12: =+M12*N12/12*7 -> 54292.786 | P12: =+N12*M12/12*5 -> 38780.562 | Q12: =VLOOKUP(B12,[2]Sheet1!A$6:H$305,8,0) -> 34 | R12: 30 | S12: =+$S$10*R12/12*7 -> 54180 | T12: =VLOOKUP($B12,[3]oct13!$D$3:$K$244,[3]oct13!E$1,0)-VLOOKUP(Sheet1!$B12,[3]oct12!$E$3:$L$435,[3]oct12!F$1,0) -> 8 | U12: =VLOOKUP($B12,[3]oct13!$D$3:$K$244,[3]oct13!F$1,0)-VLOOKUP(Sheet1!$B12,[3]oct12!$E$3:$L$435,[3]oct12!G$1,0) -> -4 | V12: =VLOOKUP($B12,[3]oct13!$D$3:$K$244,[3]oct13!G$1,0)-VLOOKUP(Sheet1!$B12,[3]oct12!$E$3:$L$435,[3]oct12!H$1,0) -> 30 | W12: =VLOOKUP($B12,[3]oct13!$D$3:$K$244,[3]oct13!H$1,0)-VLOOKUP(Sheet1!$B12,[3]oct12!$E$3:$L$435,[3]oct12!I$1,0) -> 0 | X12: =VLOOKUP($B12,[3]oct13!$D$3:$K$244,[3]oct13!I$1,0)-VLOOKUP(Sheet1!$B12,[3]oct12!$E$3:$L$435,[3]oct12!J$1,0) -> 0 | Y12: =VLOOKUP($B12,[3]oct13!$D$3:$K$244,[3]oct13!J$1,0)-VLOOKUP(Sheet1!$B12,[3]oct12!$E$3:$L$435,[3]oct12!K$1,0) -> 0 | Z12: =VLOOKUP($B12,[3]oct13!$D$3:$K$244,[3]oct13!K$1,0)-VLOOKUP(Sheet1!$B12,[3]oct12!$E$3:$L$435,[3]oct12!L$1,0) -> 0
A13: REAEG | B13: 3302086 | C13: GREET | D13: 2 | E13: 30 | F13: =VLOOKUP(D13,$E$76:$F$82,2,0) -> 2417.5937 | G13: =+E13*F13/12*7 -> 42307.889 | I13: 30 | J13: 42297.5 | L13: =+D13+1 -> 3 | M13: =+E13 -> 30 | N13: 3102.4449 | O13: =+M13*N13/12*7 -> 54292.786 | P13: =+N13*M13/12*5 -> 38780.562 | Q13: =VLOOKUP(B13,[2]Sheet1!A$6:H$305,8,0) -> 31 | R13: 30 | S13: =+$S$10*R13/12*7 -> 54180 | T13: =VLOOKUP($B13,[3]oct13!$D$3:$K$244,[3]oct13!E$1,0)-VLOOKUP(Sheet1!$B13,[3]oct12!$E$3:$L$435,[3]oct12!F$1,0) -> 0 | U13: =VLOOKUP($B13,[3]oct13!$D$3:$K$244,[3]oct13!F$1,0)-VLOOKUP(Sheet1!$B13,[3]oct12!$E$3:$L$435,[3]oct12!G$1,0) -> 0 | V13: =VLOOKUP($B13,[3]oct13!$D$3:$K$244,[3]oct13!G$1,0)-VLOOKUP(Sheet1!$B13,[3]oct12!$E$3:$L$435,[3]oct12!H$1,0) -> 0 | W13: =VLOOKUP($B13,[3]oct13!$D$3:$K$244,[3]oct13!H$1,0)-VLOOKUP(Sheet1!$B13,[3]oct12!$E$3:$L$435,[3]oct12!I$1,0) -> 30 | X13: =VLOOKUP($B13,[3]oct13!$D$3:$K$244,[3]oct13!I$1,0)-VLOOKUP(Sheet1!$B13,[3]oct12!$E$3:$L$435,[3]oct12!J$1,0) -> 1 | Y13: =VLOOKUP($B13,[3]oct13!$D$3:$K$244,[3]oct13!J$1,0)-VLOOKUP(Sheet1!$B13,[3]oct12!$E$3:$L$435,[3]oct12!K$1,0) -> 0 | Z13: =VLOOKUP($B13,[3]oct13!$D$3:$K$244,[3]oct13!K$1,0)-VLOOKUP(Sheet1!$B13,[3]oct12!$E$3:$L$435,[3]oct12!L$1,0) -> 0
A14: REAPK | B14: 3302108 | C14: WARD END | D14: 2 | E14: 60 | F14: =VLOOKUP(D14,$E$76:$F$82,2,0) -> 2417.5937 | G14: =+E14*F14/12*7 -> 84615.779 | I14: 65 | J14: 93514.167 | L14: =+D14+1 -> 3 | M14: =+E14 -> 60 | N14: 3102.4449 | O14: =+M14*N14/12*7 -> 108585.57 | P14: =+N14*M14/12*5 -> 77561.123 | Q14: =VLOOKUP(B14,[2]Sheet1!A$6:H$305,8,0) -> 51 | R14: 51 | S14: =+$S$10*R14/12*7 -> 92106 | T14: =VLOOKUP($B14,[3]oct13!$D$3:$K$244,[3]oct13!E$1,0)-VLOOKUP(Sheet1!$B14,[3]oct12!$E$3:$L$435,[3]oct12!F$1,0)+24.5 -> -4 | U14: =VLOOKUP($B14,[3]oct13!$D$3:$K$244,[3]oct13!F$1,0)-VLOOKUP(Sheet1!$B14,[3]oct12!$E$3:$L$435,[3]oct12!G$1,0) -> -2 | V14: =VLOOKUP($B14,[3]oct13!$D$3:$K$244,[3]oct13!G$1,0)-VLOOKUP(Sheet1!$B14,[3]oct12!$E$3:$L$435,[3]oct12!H$1,0) -> 28 | W14: =VLOOKUP($B14,[3]oct13!$D$3:$K$244,[3]oct13!H$1,0)-VLOOKUP(Sheet1!$B14,[3]oct12!$E$3:$L$435,[3]oct12!I$1,0) -> 29 | X14: =VLOOKUP($B14,[3]oct13!$D$3:$K$244,[3]oct13!I$1,0)-VLOOKUP(Sheet1!$B14,[3]oct12!$E$3:$L$435,[3]oct12!J$1,0) -> 0 | Y14: =VLOOKUP($B14,[3]oct13!$D$3:$K$244,[3]oct13!J$1,0)-VLOOKUP(Sheet1!$B14,[3]oct12!$E$3:$L$435,[3]oct12!K$1,0) -> -1 | Z14: =VLOOKUP($B14,[3]oct13!$D$3:$K$244,[3]oct13!K$1,0)-VLOOKUP(Sheet1!$B14,[3]oct12!$E$3:$L$435,[3]oct12!L$1,0) -> 1
B15: 3302108 | C15: WARD END | Q15: Migration | R15: 50 | S15: =+$S$10*R15/12*5 -> 64500 | T15: from Novem
B16: 3302139 | C16: NANSEN | Q16: Migration | R16: 60 | S16: =+$S$10*R16/12*7 -> 108360 | T16: from Novem
B17: 3302142 | C17: NELSON | I17: 30 | J17: 57253 | L17: 1 | M17: 30 | N17: 3102.4449 | O17: =+M17*N17/12*7 -> 54292.786 | P17: =+N17*M17/12*5 -> 38780.562 | Q17: =VLOOKUP(B17,[2]Sheet1!A$6:H$305,8,0) -> 29 | R17: 21 | S17: =+$S$10*R17/12*7 -> 37926 | T17: =VLOOKUP($B17,[3]oct13!$D$3:$K$244,[3]oct13!E$1,0)-VLOOKUP(Sheet1!$B17,[3]oct12!$E$3:$L$435,[3]oct12!F$1,0) -> -5 | U17: =VLOOKUP($B17,[3]oct13!$D$3:$K$244,[3]oct13!F$1,0)-VLOOKUP(Sheet1!$B17,[3]oct12!$E$3:$L$435,[3]oct12!G$1,0) -> 21 | V17: =VLOOKUP($B17,[3]oct13!$D$3:$K$244,[3]oct13!G$1,0)-VLOOKUP(Sheet1!$B17,[3]oct12!$E$3:$L$435,[3]oct12!H$1,0) -> 1 | W17: =VLOOKUP($B17,[3]oct13!$D$3:$K$244,[3]oct13!H$1,0)-VLOOKUP(Sheet1!$B17,[3]oct12!$E$3:$L$435,[3]oct12!I$1,0) -> -2 | X17: =VLOOKUP($B17,[3]oct13!$D$3:$K$244,[3]oct13!I$1,0)-VLOOKUP(Sheet1!$B17,[3]oct12!$E$3:$L$435,[3]oct12!J$1,0) -> 1 | Y17: =VLOOKUP($B17,[3]oct13!$D$3:$K$244,[3]oct13!J$1,0)-VLOOKUP(Sheet1!$B17,[3]oct12!$E$3:$L$435,[3]oct12!K$1,0) -> 8 | Z17: =VLOOKUP($B17,[3]oct13!$D$3:$K$244,[3]oct13!K$1,0)-VLOOKUP(Sheet1!$B17,[3]oct12!$E$3:$L$435,[3]oct12!L$1,0) -> 5
A18: REAJF | B18: 3302149 | C18: PAGET | D18: 1 | E18: 30 | F18: =VLOOKUP(D18,$E$76:$F$82,2,0) -> 2417.5937 | G18: =+E18*F18/12*7 -> 42307.889 | I18: 28 | J18: 38697.75 | L18: =+D18+1 -> 2 | M18: =+E18 -> 30 | N18: 3102.4449 | O18: =+M18*N18/12*7 -> 54292.786 | P18: =+N18*M18/12*5 -> 38780.562 | Q18: =VLOOKUP(B18,[2]Sheet1!A$6:H$305,8,0) -> 37 | R18: 28 | S18: =+$S$10*R18/12*7 -> 50568 | T18: =VLOOKUP($B18,[3]oct13!$D$3:$K$244,[3]oct13!E$1,0)-VLOOKUP(Sheet1!$B18,[3]oct12!$E$3:$L$435,[3]oct12!F$1,0) -> 5 | U18: =VLOOKUP($B18,[3]oct13!$D$3:$K$244,[3]oct13!F$1,0)-VLOOKUP(Sheet1!$B18,[3]oct12!$E$3:$L$435,[3]oct12!G$1,0) -> 2 | V18: =VLOOKUP($B18,[3]oct13!$D$3:$K$244,[3]oct13!G$1,0)-VLOOKUP(Sheet1!$B18,[3]oct12!$E$3:$L$435,[3]oct12!H$1,0) -> 28 | W18: =VLOOKUP($B18,[3]oct13!$D$3:$K$244,[3]oct13!H$1,0)-VLOOKUP(Sheet1!$B18,[3]oct12!$E$3:$L$435,[3]oct12!I$1,0) -> -1 | X18: =VLOOKUP($B18,[3]oct13!$D$3:$K$244,[3]oct13!I$1,0)-VLOOKUP(Sheet1!$B18,[3]oct12!$E$3:$L$435,[3]oct12!J$1,0) -> 1 | Y18: =VLOOKUP($B18,[3]oct13!$D$3:$K$244,[3]oct13!J$1,0)-VLOOKUP(Sheet1!$B18,[3]oct12!$E$3:$L$435,[3]oct12!K$1,0) -> 2 | Z18: =VLOOKUP($B18,[3]oct13!$D$3:$K$244,[3]oct13!K$1,0)-VLOOKUP(Sheet1!$B18,[3]oct12!$E$3:$L$435,[3]oct12!L$1,0) -> 0
A19: REAJG | B19: 3302150 | C19: PARK HILL | D19: 2 | E19: 30 | F19: =VLOOKUP(D19,$E$76:$F$82,2,0) -> 2417.5937 | G19: =+E19*F19/12*7 -> 42307.889 | I19: 18 | J19: 20446.417 | L19: =+D19+1 -> 3 | M19: =+E19 -> 30 | N19: 3102.4449 | O19: =+M19*N19/12*7 -> 54292.786 | P19: =+N19*M19/12*5 -> 38780.562 | Q19: =VLOOKUP(B19,[2]Sheet1!A$6:H$305,8,0) -> 27 | R19: 24 | S19: =+$S$10*R19/12*7 -> 43344 | T19: =VLOOKUP($B19,[3]oct13!$D$3:$K$244,[3]oct13!E$1,0)-VLOOKUP(Sheet1!$B19,[3]oct12!$E$3:$L$435,[3]oct12!F$1,0) -> 2.5 | U19: =VLOOKUP($B19,[3]oct13!$D$3:$K$244,[3]oct13!F$1,0)-VLOOKUP(Sheet1!$B19,[3]oct12!$E$3:$L$435,[3]oct12!G$1,0) -> 1 | V19: =VLOOKUP($B19,[3]oct13!$D$3:$K$244,[3]oct13!G$1,0)-VLOOKUP(Sheet1!$B19,[3]oct12!$E$3:$L$435,[3]oct12!H$1,0) -> -1 | W19: =VLOOKUP($B19,[3]oct13!$D$3:$K$244,[3]oct13!H$1,0)-VLOOKUP(Sheet1!$B19,[3]oct12!$E$3:$L$435,[3]oct12!I$1,0) -> 24 | X19: =VLOOKUP($B19,[3]oct13!$D$3:$K$244,[3]oct13!I$1,0)-VLOOKUP(Sheet1!$B19,[3]oct12!$E$3:$L$435,[3]oct12!J$1,0) -> -2 | Y19: =VLOOKUP($B19,[3]oct13!$D$3:$K$244,[3]oct13!J$1,0)-VLOOKUP(Sheet1!$B19,[3]oct12!$E$3:$L$435,[3]oct12!K$1,0) -> 1 | Z19: =VLOOKUP($B19,[3]oct13!$D$3:$K$244,[3]oct13!K$1,0)-VLOOKUP(Sheet1!$B19,[3]oct12!$E$3:$L$435,[3]oct12!L$1,0) -> 1
B20: 3302160 | C20: REDNALL HILL | I20: 27 | J20: 37894.5 | N20: 3102.4449 | O20: =+M20*N20/12*7 -> 0 | P20: =+N20*M20/12*5 -> 0 | Q20: =VLOOKUP(B20,[2]Sheet1!A$6:H$305,8,0) -> 41 | R20: 30 | S20: =+$S$10*R20/12*7 -> 54180 | T20: =VLOOKUP($B20,[3]oct13!$D$3:$K$244,[3]oct13!E$1,0)-VLOOKUP(Sheet1!$B20,[3]oct12!$E$3:$L$435,[3]oct12!F$1,0) -> 0 | U20: =VLOOKUP($B20,[3]oct13!$D$3:$K$244,[3]oct13!F$1,0)-VLOOKUP(Sheet1!$B20,[3]oct12!$E$3:$L$435,[3]oct12!G$1,0) -> 0 | V20: =VLOOKUP($B20,[3]oct13!$D$3:$K$244,[3]oct13!G$1,0)-VLOOKUP(Sheet1!$B20,[3]oct12!$E$3:$L$435,[3]oct12!H$1,0) -> 0 | W20: =VLOOKUP($B20,[3]oct13!$D$3:$K$244,[3]oct13!H$1,0)-VLOOKUP(Sheet1!$B20,[3]oct12!$E$3:$L$435,[3]oct12!I$1,0) -> 4 | X20: =VLOOKUP($B20,[3]oct13!$D$3:$K$244,[3]oct13!I$1,0)-VLOOKUP(Sheet1!$B20,[3]oct12!$E$3:$L$435,[3]oct12!J$1,0) -> 22 | Y20: =VLOOKUP($B20,[3]oct13!$D$3:$K$244,[3]oct13!J$1,0)-VLOOKUP(Sheet1!$B20,[3]oct12!$E$3:$L$435,[3]oct12!K$1,0) -> -5 | Z20: =VLOOKUP($B20,[3]oct13!$D$3:$K$244,[3]oct13!K$1,0)-VLOOKUP(Sheet1!$B20,[3]oct12!$E$3:$L$435,[3]oct12!L$1,0) -> 20
B21: 3302161 | C21: REDNALL HILL | I21: 24 | J21: 44307.667 | L21: 1 | M21: 30 | N21: 3102.4449 | O21: =+M21*N21/12*7 -> 54292.786 | P21: =+N21*M21/12*5 -> 38780.562 | Q21: =VLOOKUP(B21,[2]Sheet1!A$6:H$305,8,0) -> 16 | R21: 16 | S21: =+$S$10*R21/12*7 -> 28896 | T21: =VLOOKUP($B21,[3]oct13!$D$3:$K$244,[3]oct13!E$1,0)-VLOOKUP(Sheet1!$B21,[3]oct12!$E$3:$L$435,[3]oct12!F$1,0) -> -15 | U21: =VLOOKUP($B21,[3]oct13!$D$3:$K$244,[3]oct13!F$1,0)-VLOOKUP(Sheet1!$B21,[3]oct12!$E$3:$L$435,[3]oct12!G$1,0) -> 32 | V21: =VLOOKUP($B21,[3]oct13!$D$3:$K$244,[3]oct13!G$1,0)-VLOOKUP(Sheet1!$B21,[3]oct12!$E$3:$L$435,[3]oct12!H$1,0) -> -1 | W21: =VLOOKUP($B21,[3]oct13!$D$3:$K$244,[3]oct13!H$1,0)-VLOOKUP(Sheet1!$B21,[3]oct12!$E$3:$L$435,[3]oct12!I$1,0) -> 0 | X21: =VLOOKUP($B21,[3]oct13!$D$3:$K$244,[3]oct13!I$1,0)-VLOOKUP(Sheet1!$B21,[3]oct12!$E$3:$L$435,[3]oct12!J$1,0) -> 0 | Y21: =VLOOKUP($B21,[3]oct13!$D$3:$K$244,[3]oct13!J$1,0)-VLOOKUP(Sheet1!$B21,[3]oct12!$E$3:$L$435,[3]oct12!K$1,0) -> 0 | Z21: =VLOOKUP($B21,[3]oct13!$D$3:$K$244,[3]oct13!K$1,0)-VLOOKUP(Sheet1!$B21,[3]oct12!$E$3:$L$435,[3]oct12!L$1,0) -> 0
A22: REANQ | B22: 3302179 | C22: STARBANK | D22: 2 | E22: 50 | F22: =VLOOKUP(D22,$E$76:$F$82,2,0) -> 2417.5937 | G22: =+E22*F22/12*7 -> 70513.149 | I22: 84 | J22: 109537.75 | L22: =+D22+1 -> 3 | M22: 80 | N22: 3102.4449 | O22: =+M22*N22/12*7 -> 144780.76 | P22: =+N22*M22/12*5 -> 103414.83 | Q22: =VLOOKUP(B22,[2]Sheet1!A$6:H$305,8,0) -> 101 | R22: 115 | S22: =+$S$10*R22 -> 356040 | T22: =VLOOKUP($B22,[3]oct13!$D$3:$K$244,[3]oct13!E$1,0)-VLOOKUP(Sheet1!$B22,[3]oct12!$E$3:$L$435,[3]oct12!F$1,0) -> 20.5 | U22: =VLOOKUP($B22,[3]oct13!$D$3:$K$244,[3]oct13!F$1,0)-VLOOKUP(Sheet1!$B22,[3]oct12!$E$3:$L$435,[3]oct12!G$1,0) -> -20 | V22: =VLOOKUP($B22,[3]oct13!$D$3:$K$244,[3]oct13!G$1,0)-VLOOKUP(Sheet1!$B22,[3]oct12!$E$3:$L$435,[3]oct12!H$1,0) -> -5 | W22: =VLOOKUP($B22,[3]oct13!$D$3:$K$244,[3]oct13!H$1,0)-VLOOKUP(Sheet1!$B22,[3]oct12!$E$3:$L$435,[3]oct12!I$1,0) -> 56 | X22: =VLOOKUP($B22,[3]oct13!$D$3:$K$244,[3]oct13!I$1,0)-VLOOKUP(Sheet1!$B22,[3]oct12!$E$3:$L$435,[3]oct12!J$1,0) -> 47 | Y22: =VLOOKUP($B22,[3]oct13!$D$3:$K$244,[3]oct13!J$1,0)-VLOOKUP(Sheet1!$B22,[3]oct12!$E$3:$L$435,[3]oct12!K$1,0) -> 0 | Z22: =VLOOKUP($B22,[3]oct13!$D$3:$K$244,[3]oct13!K$1,0)-VLOOKUP(Sheet1!$B22,[3]oct12!$E$3:$L$435,[3]oct12!L$1,0) -> 2
A23: REANR | B23: 3302184 | C23: STECHFORD | D23: 1 | E23: 30 | F23: =VLOOKUP(D23,$E$76:$F$82,2,0) -> 2417.5937 | G23: =+E23*F23/12*7 -> 42307.889 | I23: 28 | J23: 39484.083 | L23: =+D23+1 -> 2 | M23: =+E23 -> 30 | N23: 3102.4449 | O23: =+M23*N23/12*7 -> 54292.786 | P23: =+N23*M23/12*5 -> 38780.562 | Q23: =VLOOKUP(B23,[2]Sheet1!A$6:H$305,8,0) -> 33 | R23: 30 | S23: =+$S$10*R23/12*7 -> 54180 | T23: =VLOOKUP($B23,[3]oct13!$D$3:$K$244,[3]oct13!E$1,0)-VLOOKUP(Sheet1!$B23,[3]oct12!$E$3:$L$435,[3]oct12!F$1,0) -> 1 | U23: =VLOOKUP($B23,[3]oct13!$D$3:$K$244,[3]oct13!F$1,0)-VLOOKUP(Sheet1!$B23,[3]oct12!$E$3:$L$435,[3]oct12!G$1,0) -> 1 | V23: =VLOOKUP($B23,[3]oct13!$D$3:$K$244,[3]oct13!G$1,0)-VLOOKUP(Sheet1!$B23,[3]oct12!$E$3:$L$435,[3]oct12!H$1,0) -> 30 | W23: =VLOOKUP($B23,[3]oct13!$D$3:$K$244,[3]oct13!H$1,0)-VLOOKUP(Sheet1!$B23,[3]oct12!$E$3:$L$435,[3]oct12!I$1,0) -> 0 | X23: =VLOOKUP($B23,[3]oct13!$D$3:$K$244,[3]oct13!I$1,0)-VLOOKUP(Sheet1!$B23,[3]oct12!$E$3:$L$435,[3]oct12!J$1,0) -> 1 | Y23: =VLOOKUP($B23,[3]oct13!$D$3:$K$244,[3]oct13!J$1,0)-VLOOKUP(Sheet1!$B23,[3]oct12!$E$3:$L$435,[3]oct12!K$1,0) -> 0 | Z23: =VLOOKUP($B23,[3]oct13!$D$3:$K$244,[3]oct13!K$1,0)-VLOOKUP(Sheet1!$B23,[3]oct12!$E$3:$L$435,[3]oct12!L$1,0) -> 0
B24: 3302294 | C24: FEATHERSTONE | I24: 30 | J24: 40017.833 | L24: 1 | M24: 30 | N24: 3102.4449 | O24: =+M24*N24/12*7 -> 54292.786 | P24: =+N24*M24/12*5 -> 38780.562 | Q24: =VLOOKUP(B24,[2]Sheet1!A$6:H$305,8,0) -> 29 | R24: 21 | S24: =+$S$10*R24/12*7 -> 37926 | T24: =VLOOKUP($B24,[3]oct13!$D$3:$K$244,[3]oct13!E$1,0)-VLOOKUP(Sheet1!$B24,[3]oct12!$E$3:$L$435,[3]oct12!F$1,0) -> 3 | U24: =VLOOKUP($B24,[3]oct13!$D$3:$K$244,[3]oct13!F$1,0)-VLOOKUP(Sheet1!$B24,[3]oct12!$E$3:$L$435,[3]oct12!G$1,0) -> 21 | V24: =VLOOKUP($B24,[3]oct13!$D$3:$K$244,[3]oct13!G$1,0)-VLOOKUP(Sheet1!$B24,[3]oct12!$E$3:$L$435,[3]oct12!H$1,0) -> 0 | W24: =VLOOKUP($B24,[3]oct13!$D$3:$K$244,[3]oct13!H$1,0)-VLOOKUP(Sheet1!$B24,[3]oct12!$E$3:$L$435,[3]oct12!I$1,0) -> 3 | X24: =VLOOKUP($B24,[3]oct13!$D$3:$K$244,[3]oct13!I$1,0)-VLOOKUP(Sheet1!$B24,[3]oct12!$E$3:$L$435,[3]oct12!J$1,0) -> 3 | Y24: =VLOOKUP($B24,[3]oct13!$D$3:$K$244,[3]oct13!J$1,0)-VLOOKUP(Sheet1!$B24,[3]oct12!$E$3:$L$435,[3]oct12!K$1,0) -> -2 | Z24: =VLOOKUP($B24,[3]oct13!$D$3:$K$244,[3]oct13!K$1,0)-VLOOKUP(Sheet1!$B24,[3]oct12!$E$3:$L$435,[3]oct12!L$1,0) -> 1
A25: REAAN | B25: 3302300 | C25: ARDEN | D25: 4 | E25: 30 | F25: =VLOOKUP(D25,$E$76:$F$82,2,0) -> 2406.0653 | G25: =+E25*F25/12*7 -> 42106.142 | I25: 27 | J25: 38262 | L25: =+D25+1 -> 5 | M25: =+E25 -> 30 | N25: 3102.4449 | O25: =+M25*N25/12*7 -> 54292.786 | P25: =+N25*M25/12*5 -> 38780.562 | Q25: =VLOOKUP(B25,[2]Sheet1!A$6:H$305,8,0) -> 35 | R25: 30 | S25: =+$S$10*R25/12*7 -> 54180 | T25: =VLOOKUP($B25,[3]oct13!$D$3:$K$244,[3]oct13!E$1,0)-VLOOKUP(Sheet1!$B25,[3]oct12!$E$3:$L$435,[3]oct12!F$1,0) -> 1 | U25: =VLOOKUP($B25,[3]oct13!$D$3:$K$244,[3]oct13!F$1,0)-VLOOKUP(Sheet1!$B25,[3]oct12!$E$3:$L$435,[3]oct12!G$1,0) -> 2 | V25: =VLOOKUP($B25,[3]oct13!$D$3:$K$244,[3]oct13!G$1,0)-VLOOKUP(Sheet1!$B25,[3]oct12!$E$3:$L$435,[3]oct12!H$1,0) -> 0 | W25: =VLOOKUP($B25,[3]oct13!$D$3:$K$244,[3]oct13!H$1,0)-VLOOKUP(Sheet1!$B25,[3]oct12!$E$3:$L$435,[3]oct12!I$1,0) -> 0 | X25: =VLOOKUP($B25,[3]oct13!$D$3:$K$244,[3]oct13!I$1,0)-VLOOKUP(Sheet1!$B25,[3]oct12!$E$3:$L$435,[3]oct12!J$1,0) -> 1 | Y25: =VLOOKUP($B25,[3]oct13!$D$3:$K$244,[3]oct13!J$1,0)-VLOOKUP(Sheet1!$B25,[3]oct12!$E$3:$L$435,[3]oct12!K$1,0) -> 30 | Z25: =VLOOKUP($B25,[3]oct13!$D$3:$K$244,[3]oct13!K$1,0)-VLOOKUP(Sheet1!$B25,[3]oct12!$E$3:$L$435,[3]oct12!L$1,0) -> 1
A26: REACD | B26: 3302312 | C26: CHAD VALE | D26: 2 | E26: 30 | F26: =VLOOKUP(D26,$E$76:$F$82,2,0) -> 2417.5937 | G26: =+E26*F26/12*7 -> 42307.889 | I26: 26 | J26: 36657.833 | L26: =+D26+1 -> 3 | M26: =+E26 -> 30 | N26: 3102.4449 | O26: =+M26*N26/12*7 -> 54292.786 | P26: =+N26*M26/12*5 -> 38780.562 | Q26: =VLOOKUP(B26,[2]Sheet1!A$6:H$305,8,0) -> 33 | R26: 30 | S26: =+$S$10*R26/12*7 -> 54180 | T26: =VLOOKUP($B26,[3]oct13!$D$3:$K$244,[3]oct13!E$1,0)-VLOOKUP(Sheet1!$B26,[3]oct12!$E$3:$L$435,[3]oct12!F$1,0) -> 1 | U26: =VLOOKUP($B26,[3]oct13!$D$3:$K$244,[3]oct13!F$1,0)-VLOOKUP(Sheet1!$B26,[3]oct12!$E$3:$L$435,[3]oct12!G$1,0) -> -1 | V26: =VLOOKUP($B26,[3]oct13!$D$3:$K$244,[3]oct13!G$1,0)-VLOOKUP(Sheet1!$B26,[3]oct12!$E$3:$L$435,[3]oct12!H$1,0) -> 2 | W26: =VLOOKUP($B26,[3]oct13!$D$3:$K$244,[3]oct13!H$1,0)-VLOOKUP(Sheet1!$B26,[3]oct12!$E$3:$L$435,[3]oct12!I$1,0) -> 29 | X26: =VLOOKUP($B26,[3]oct13!$D$3:$K$244,[3]oct13!I$1,0)-VLOOKUP(Sheet1!$B26,[3]oct12!$E$3:$L$435,[3]oct12!J$1,0) -> 1 | Y26: =VLOOKUP($B26,[3]oct13!$D$3:$K$244,[3]oct13!J$1,0)-VLOOKUP(Sheet1!$B26,[3]oct12!$E$3:$L$435,[3]oct12!K$1,0) -> 0 | Z26: =VLOOKUP($B26,[3]oct13!$D$3:$K$244,[3]oct13!K$1,0)-VLOOKUP(Sheet1!$B26,[3]oct12!$E$3:$L$435,[3]oct12!L$1,0) -> 1
B27: 3302317 | C27: WORLDS END | I27: 27 | J27: 55298.833 | L27: 1 | M27: 30 | N27: 3102.4449 | O27: =+M27*N27/12*7 -> 54292.786 | P27: =+N27*M27/12*5 -> 38780.562 | Q27: =VLOOKUP(B27,[2]Sheet1!A$6:H$305,8,0) -> 31 | R27: 30 | S27: =+$S$10*R27/12*7 -> 54180 | T27: =VLOOKUP($B27,[3]oct13!$D$3:$K$244,[3]oct13!E$1,0)-VLOOKUP(Sheet1!$B27,[3]oct12!$E$3:$L$435,[3]oct12!F$1,0) -> -1 | U27: =VLOOKUP($B27,[3]oct13!$D$3:$K$244,[3]oct13!F$1,0)-VLOOKUP(Sheet1!$B27,[3]oct12!$E$3:$L$435,[3]oct12!G$1,0) -> 29 | V27: =VLOOKUP($B27,[3]oct13!$D$3:$K$244,[3]oct13!G$1,0)-VLOOKUP(Sheet1!$B27,[3]oct12!$E$3:$L$435,[3]oct12!H$1,0) -> 0 | W27: =VLOOKUP($B27,[3]oct13!$D$3:$K$244,[3]oct13!H$1,0)-VLOOKUP(Sheet1!$B27,[3]oct12!$E$3:$L$435,[3]oct12!I$1,0) -> 0 | X27: =VLOOKUP($B27,[3]oct13!$D$3:$K$244,[3]oct13!I$1,0)-VLOOKUP(Sheet1!$B27,[3]oct12!$E$3:$L$435,[3]oct12!J$1,0) -> 0 | Y27: =VLOOKUP($B27,[3]oct13!$D$3:$K$244,[3]oct13!J$1,0)-VLOOKUP(Sheet1!$B27,[3]oct12!$E$3:$L$435,[3]oct12!K$1,0) -> 0 | Z27: =VLOOKUP($B27,[3]oct13!$D$3:$K$244,[3]oct13!K$1,0)-VLOOKUP(Sheet1!$B27,[3]oct12!$E$3:$L$435,[3]oct12!L$1,0) -> 0
A28: REAQB | B28: 3302447 | C28: OVAL, THE | D28: 3 | E28: 30 | F28: =VLOOKUP(D28,$E$76:$F$82,2,0) -> 2406.0653 | G28: =+E28*F28/12*7 -> 42106.142 | I28: 30 | J28: 50526 | L28: =+D28+1 -> 4 | M28: =+E28 -> 30 | N28: 3102.4449 | O28: =+M28*N28/12*7 -> 54292.786 | P28: =+N28*M28/12*5 -> 38780.562 | Q28: =VLOOKUP(B28,[2]Sheet1!A$6:H$305,8,0) -> 34 | R28: 30 | S28: =+$S$10*R28/12*7 -> 54180 | T28: =VLOOKUP($B28,[3]oct13!$D$3:$K$244,[3]oct13!E$1,0)-VLOOKUP(Sheet1!$B28,[3]oct12!$E$3:$L$435,[3]oct12!F$1,0) -> -1 | U28: =VLOOKUP($B28,[3]oct13!$D$3:$K$244,[3]oct13!F$1,0)-VLOOKUP(Sheet1!$B28,[3]oct12!$E$3:$L$435,[3]oct12!G$1,0) -> 1 | V28: =VLOOKUP($B28,[3]oct13!$D$3:$K$244,[3]oct13!G$1,0)-VLOOKUP(Sheet1!$B28,[3]oct12!$E$3:$L$435,[3]oct12!H$1,0) -> 1 | W28: =VLOOKUP($B28,[3]oct13!$D$3:$K$244,[3]oct13!H$1,0)-VLOOKUP(Sheet1!$B28,[3]oct12!$E$3:$L$435,[3]oct12!I$1,0) -> 1 | X28: =VLOOKUP($B28,[3]oct13!$D$3:$K$244,[3]oct13!I$1,0)-VLOOKUP(Sheet1!$B28,[3]oct12!$E$3:$L$435,[3]oct12!J$1,0) -> 30 | Y28: =VLOOKUP($B28,[3]oct13!$D$3:$K$244,[3]oct13!J$1,0)-VLOOKUP(Sheet1!$B28,[3]oct12!$E$3:$L$435,[3]oct12!K$1,0) -> 2 | Z28: =VLOOKUP($B28,[3]oct13!$D$3:$K$244,[3]oct13!K$1,0)-VLOOKUP(Sheet1!$B28,[3]oct12!$E$3:$L$435,[3]oct12!L$1,0) -> 0
A29: REAKE | B29: 3302460 | C29: ROBIN HOOD | D29: 1 | E29: 30 | F29: =VLOOKUP(D29,$E$76:$F$82,2,0) -> 2417.5937 | G29: =+E29*F29/12*7 -> 42307.889 | I29: 30 | J29: 45865.167 | L29: =+D29+1 -> 2 | M29: =+E29 -> 30 | N29: 3102.4449 | O29: =+M29*N29/12*7 -> 54292.786 | P29: =+N29*M29/12*5 -> 38780.562 | R29: 30 | S29: =+$S$10*R29/12*7 -> 54180
B30: 3302478 | C30: WHITEHOUSE COMMON | I30: 30 | J30: 57725.5 | L30: 1 | M30: 30 | N30: 3102.4449 | O30: =+M30*N30/12*7 -> 54292.786 | P30: =+N30*M30/12*5 -> 38780.562 | Q30: =VLOOKUP(B30,[2]Sheet1!A$6:H$305,8,0) -> 7 | R30: 30 | S30: =+$S$10*R30/12*7 -> 54180 | T30: =VLOOKUP($B30,[3]oct13!$D$3:$K$244,[3]oct13!E$1,0)-VLOOKUP(Sheet1!$B30,[3]oct12!$E$3:$L$435,[3]oct12!F$1,0) -> -30 | U30: =VLOOKUP($B30,[3]oct13!$D$3:$K$244,[3]oct13!F$1,0)-VLOOKUP(Sheet1!$B30,[3]oct12!$E$3:$L$435,[3]oct12!G$1,0) -> 30 | V30: =VLOOKUP($B30,[3]oct13!$D$3:$K$244,[3]oct13!G$1,0)-VLOOKUP(Sheet1!$B30,[3]oct12!$E$3:$L$435,[3]oct12!H$1,0) -> 0 | W30: =VLOOKUP($B30,[3]oct13!$D$3:$K$244,[3]oct13!H$1,0)-VLOOKUP(Sheet1!$B30,[3]oct12!$E$3:$L$435,[3]oct12!I$1,0) -> 0 | X30: =VLOOKUP($B30,[3]oct13!$D$3:$K$244,[3]oct13!I$1,0)-VLOOKUP(Sheet1!$B30,[3]oct12!$E$3:$L$435,[3]oct12!J$1,0) -> -1 | Y30: =VLOOKUP($B30,[3]oct13!$D$3:$K$244,[3]oct13!J$1,0)-VLOOKUP(Sheet1!$B30,[3]oct12!$E$3:$L$435,[3]oct12!K$1,0) -> 2 | Z30: =VLOOKUP($B30,[3]oct13!$D$3:$K$244,[3]oct13!K$1,0)-VLOOKUP(Sheet1!$B30,[3]oct12!$E$3:$L$435,[3]oct12!L$1,0) -> 6
B31: 3302479 | C31: ANGLESY | I31: 27 | J31: 47770.333 | L31: 1 | M31: 30 | N31: 3102.4449 | O31: =+M31*N31/12*7 -> 54292.786 | P31: =+N31*M31/12*5 -> 38780.562 | Q31: =VLOOKUP(B31,[2]Sheet1!A$6:H$305,8,0) -> 21 | R31: 21 | S31: =+$S$10*R31/12*7 -> 37926 | T31: =VLOOKUP($B31,[3]oct13!$D$3:$K$244,[3]oct13!E$1,0)-VLOOKUP(Sheet1!$B31,[3]oct12!$E$3:$L$435,[3]oct12!F$1,0) -> -25 | U31: =VLOOKUP($B31,[3]oct13!$D$3:$K$244,[3]oct13!F$1,0)-VLOOKUP(Sheet1!$B31,[3]oct12!$E$3:$L$435,[3]oct12!G$1,0) -> 31 | V31: =VLOOKUP($B31,[3]oct13!$D$3:$K$244,[3]oct13!G$1,0)-VLOOKUP(Sheet1!$B31,[3]oct12!$E$3:$L$435,[3]oct12!H$1,0) -> 1 | W31: =VLOOKUP($B31,[3]oct13!$D$3:$K$244,[3]oct13!H$1,0)-VLOOKUP(Sheet1!$B31,[3]oct12!$E$3:$L$435,[3]oct12!I$1,0) -> 2 | X31: =VLOOKUP($B31,[3]oct13!$D$3:$K$244,[3]oct13!I$1,0)-VLOOKUP(Sheet1!$B31,[3]oct12!$E$3:$L$435,[3]oct12!J$1,0) -> 3 | Y31: =VLOOKUP($B31,[3]oct13!$D$3:$K$244,[3]oct13!J$1,0)-VLOOKUP(Sheet1!$B31,[3]oct12!$E$3:$L$435,[3]oct12!K$1,0) -> 3 | Z31: =VLOOKUP($B31,[3]oct13!$D$3:$K$244,[3]oct13!K$1,0)-VLOOKUP(Sheet1!$B31,[3]oct12!$E$3:$L$435,[3]oct12!L$1,0) -> 6
B32: 3303025 | C32: ST MARY'S CE (B29) | I32: 30 | J32: 57731.917 | L32: 1 | M32: 30 | N32: 3102.4449 | O32: =+M32*N32/12*7 -> 54292.786 | P32: =+N32*M32/12*5 -> 38780.562 | Q32: =VLOOKUP(B32,[2]Sheet1!A$6:H$305,8,0) -> 28 | R32: 28 | S32: =+$S$10*R32/12*7 -> 50568 | T32: =VLOOKUP($B32,[3]oct13!$D$3:$K$244,[3]oct13!E$1,0)-VLOOKUP(Sheet1!$B32,[3]oct12!$E$3:$L$435,[3]oct12!F$1,0) -> -1 | U32: =VLOOKUP($B32,[3]oct13!$D$3:$K$244,[3]oct13!F$1,0)-VLOOKUP(Sheet1!$B32,[3]oct12!$E$3:$L$435,[3]oct12!G$1,0) -> 30 | V32: =VLOOKUP($B32,[3]oct13!$D$3:$K$244,[3]oct13!G$1,0)-VLOOKUP(Sheet1!$B32,[3]oct12!$E$3:$L$435,[3]oct12!H$1,0) -> 0 | W32: =VLOOKUP($B32,[3]oct13!$D$3:$K$244,[3]oct13!H$1,0)-VLOOKUP(Sheet1!$B32,[3]oct12!$E$3:$L$435,[3]oct12!I$1,0) -> -2 | X32: =VLOOKUP($B32,[3]oct13!$D$3:$K$244,[3]oct13!I$1,0)-VLOOKUP(Sheet1!$B32,[3]oct12!$E$3:$L$435,[3]oct12!J$1,0) -> 1 | Y32: =VLOOKUP($B32,[3]oct13!$D$3:$K$244,[3]oct13!J$1,0)-VLOOKUP(Sheet1!$B32,[3]oct12!$E$3:$L$435,[3]oct12!K$1,0) -> -4 | Z32: =VLOOKUP($B32,[3]oct13!$D$3:$K$244,[3]oct13!K$1,0)-VLOOKUP(Sheet1!$B32,[3]oct12!$E$3:$L$435,[3]oct12!L$1,0) -> 4
B33: 3303311 | C33: ST MICHAEL'S CE (B32) | I33: 27 | J33: 40394.667 | L33: 2 | M33: 30 | N33: 3102.4449 | O33: =+M33*N33/12*7 -> 54292.786 | P33: =+N33*M33/12*5 -> 38780.562 | R33: 30 | S33: =+$S$10*R33/12*7 -> 54180
A34: REAMW | B34: 3303344 | C34: ST MARY'S RC (B17) | D34: 1 | E34: 30 | F34: =VLOOKUP(D34,$E$76:$F$82,2,0) -> 2417.5937 | G34: =+E34*F34/12*7 -> 42307.889 | I34: 30 | J34: 46508 | L34: =+D34+1 -> 2 | M34: =+E34 -> 30 | N34: 3102.4449 | O34: =+M34*N34/12*7 -> 54292.786 | P34: =+N34*M34/12*5 -> 38780.562 | Q34: =VLOOKUP(B34,[2]Sheet1!A$6:H$305,8,0) -> 31 | R34: 30 | S34: =+$S$10*R34/12*7 -> 54180 | T34: =VLOOKUP($B34,[3]oct13!$D$3:$K$244,[3]oct13!E$1,0)-VLOOKUP(Sheet1!$B34,[3]oct12!$E$3:$L$435,[3]oct12!F$1,0) -> 0 | U34: =VLOOKUP($B34,[3]oct13!$D$3:$K$244,[3]oct13!F$1,0)-VLOOKUP(Sheet1!$B34,[3]oct12!$E$3:$L$435,[3]oct12!G$1,0) -> 0 | V34: =VLOOKUP($B34,[3]oct13!$D$3:$K$244,[3]oct13!G$1,0)-VLOOKUP(Sheet1!$B34,[3]oct12!$E$3:$L$435,[3]oct12!H$1,0) -> 30 | W34: =VLOOKUP($B34,[3]oct13!$D$3:$K$244,[3]oct13!H$1,0)-VLOOKUP(Sheet1!$B34,[3]oct12!$E$3:$L$435,[3]oct12!I$1,0) -> -1 | X34: =VLOOKUP($B34,[3]oct13!$D$3:$K$244,[3]oct13!I$1,0)-VLOOKUP(Sheet1!$B34,[3]oct12!$E$3:$L$435,[3]oct12!J$1,0) -> 1 | Y34: =VLOOKUP($B34,[3]oct13!$D$3:$K$244,[3]oct13!J$1,0)-VLOOKUP(Sheet1!$B34,[3]oct12!$E$3:$L$435,[3]oct12!K$1,0) -> -1 | Z34: =VLOOKUP($B34,[3]oct13!$D$3:$K$244,[3]oct13!K$1,0)-VLOOKUP(Sheet1!$B34,[3]oct12!$E$3:$L$435,[3]oct12!L$1,0) -> 2
A35: REALP | B35: 3303363 | C35: ST DUNSTAN'S RC | D35: 2 | E35: 20 | F35: =VLOOKUP(D35,$E$76:$F$82,2,0) -> 2417.5937 | G35: =+E35*F35/12*7 -> 28205.26 | I35: 19 | J35: 30102.333 | L35: =+D35+1 -> 3 | M35: =+E35 -> 20 | N35: 3102.4449 | O35: =+M35*N35/12*7 -> 36195.191 | P35: =+N35*M35/12*5 -> 25853.708 | Q35: =VLOOKUP(B35,[2]Sheet1!A$6:H$305,8,0) -> 34 | R35: 30 | S35: =+$S$10*R35/12*7 -> 54180 | T35: =VLOOKUP($B35,[3]oct13!$D$3:$K$244,[3]oct13!E$1,0)-VLOOKUP(Sheet1!$B35,[3]oct12!$E$3:$L$435,[3]oct12!F$1,0) -> 0 | U35: =VLOOKUP($B35,[3]oct13!$D$3:$K$244,[3]oct13!F$1,0)-VLOOKUP(Sheet1!$B35,[3]oct12!$E$3:$L$435,[3]oct12!G$1,0) -> 13 | V35: =VLOOKUP($B35,[3]oct13!$D$3:$K$244,[3]oct13!G$1,0)-VLOOKUP(Sheet1!$B35,[3]oct12!$E$3:$L$435,[3]oct12!H$1,0) -> 2 | W35: =VLOOKUP($B35,[3]oct13!$D$3:$K$244,[3]oct13!H$1,0)-VLOOKUP(Sheet1!$B35,[3]oct12!$E$3:$L$435,[3]oct12!I$1,0) -> 2 | X35: =VLOOKUP($B35,[3]oct13!$D$3:$K$244,[3]oct13!I$1,0)-VLOOKUP(Sheet1!$B35,[3]oct12!$E$3:$L$435,[3]oct12!J$1,0) -> 8 | Y35: =VLOOKUP($B35,[3]oct13!$D$3:$K$244,[3]oct13!J$1,0)-VLOOKUP(Sheet1!$B35,[3]oct12!$E$3:$L$435,[3]oct12!K$1,0) -> -10 | Z35: =VLOOKUP($B35,[3]oct13!$D$3:$K$244,[3]oct13!K$1,0)-VLOOKUP(Sheet1!$B35,[3]oct12!$E$3:$L$435,[3]oct12!L$1,0) -> 19
B36: 3303412 | C36: AUDLEY | I36: 44 | J36: 62314 | L36: 1 | M36: 30 | N36: 3102.4449 | O36: =+M36*N36/12*7 -> 54292.786 | P36: =+N36*M36/12*5 -> 38780.562 | Q36: =VLOOKUP(B36,[2]Sheet1!A$6:H$305,8,0) -> 33 | R36: 30 | S36: =+$S$10*R36/12*7 -> 54180 | T36: =VLOOKUP($B36,[3]oct13!$D$3:$K$244,[3]oct13!E$1,0)-VLOOKUP(Sheet1!$B36,[3]oct12!$E$3:$L$435,[3]oct12!F$1,0) -> 14 | U36: =VLOOKUP($B36,[3]oct13!$D$3:$K$244,[3]oct13!F$1,0)-VLOOKUP(Sheet1!$B36,[3]oct12!$E$3:$L$435,[3]oct12!G$1,0) -> -3 | V36: =VLOOKUP($B36,[3]oct13!$D$3:$K$244,[3]oct13!G$1,0)-VLOOKUP(Sheet1!$B36,[3]oct12!$E$3:$L$435,[3]oct12!H$1,0) -> 27 | W36: =VLOOKUP($B36,[3]oct13!$D$3:$K$244,[3]oct13!H$1,0)-VLOOKUP(Sheet1!$B36,[3]oct12!$E$3:$L$435,[3]oct12!I$1,0) -> -2 | X36: =VLOOKUP($B36,[3]oct13!$D$3:$K$244,[3]oct13!I$1,0)-VLOOKUP(Sheet1!$B36,[3]oct12!$E$3:$L$435,[3]oct12!J$1,0) -> -2 | Y36: =VLOOKUP($B36,[3]oct13!$D$3:$K$244,[3]oct13!J$1,0)-VLOOKUP(Sheet1!$B36,[3]oct12!$E$3:$L$435,[3]oct12!K$1,0) -> -2 | Z36: =VLOOKUP($B36,[3]oct13!$D$3:$K$244,[3]oct13!K$1,0)-VLOOKUP(Sheet1!$B36,[3]oct12!$E$3:$L$435,[3]oct12!L$1,0) -> 1
A37: REARQ | B37: 3303421 | C37: YARDLEY | D37: 1 | E37: 30 | F37: =VLOOKUP(D37,$E$76:$F$82,2,0) -> 2417.5937 | G37: =+E37*F37/12*7 -> 42307.889 | I37: 30 | J37: 43320.667 | L37: =+D37+1 -> 2 | M37: =+E37 -> 30 | N37: 3102.4449 | O37: =+M37*N37/12*7 -> 54292.786 | P37: =+N37*M37/12*5 -> 38780.562 | Q37: =VLOOKUP(B37,[2]Sheet1!A$6:H$305,8,0) -> 28 | R37: 28 | S37: =+$S$10*R37/12*7 -> 50568 | T37: =VLOOKUP($B37,[3]oct13!$D$3:$K$244,[3]oct13!E$1,0)-VLOOKUP(Sheet1!$B37,[3]oct12!$E$3:$L$435,[3]oct12!F$1,0) -> -1 | U37: =VLOOKUP($B37,[3]oct13!$D$3:$K$244,[3]oct13!F$1,0)-VLOOKUP(Sheet1!$B37,[3]oct12!$E$3:$L$435,[3]oct12!G$1,0) -> 0 | V37: =VLOOKUP($B37,[3]oct13!$D$3:$K$244,[3]oct13!G$1,0)-VLOOKUP(Sheet1!$B37,[3]oct12!$E$3:$L$435,[3]oct12!H$1,0) -> 30 | W37: =VLOOKUP($B37,[3]oct13!$D$3:$K$244,[3]oct13!H$1,0)-VLOOKUP(Sheet1!$B37,[3]oct12!$E$3:$L$435,[3]oct12!I$1,0) -> -1 | X37: =VLOOKUP($B37,[3]oct13!$D$3:$K$244,[3]oct13!I$1,0)-VLOOKUP(Sheet1!$B37,[3]oct12!$E$3:$L$435,[3]oct12!J$1,0) -> 0 | Y37: =VLOOKUP($B37,[3]oct13!$D$3:$K$244,[3]oct13!J$1,0)-VLOOKUP(Sheet1!$B37,[3]oct12!$E$3:$L$435,[3]oct12!K$1,0) -> 0 | Z37: =VLOOKUP($B37,[3]oct13!$D$3:$K$244,[3]oct13!K$1,0)-VLOOKUP(Sheet1!$B37,[3]oct12!$E$3:$L$435,[3]oct12!L$1,0) -> 0
A38: REABX | B38: 3303430 | C38: HODGE HILL | D38: 1 | E38: 30 | F38: =VLOOKUP(D38,$E$76:$F$82,2,0) -> 2417.5937 | G38: =+E38*F38/12*7 -> 42307.889 | I38: 85 | J38: 124821.08 | L38: =+D38+1 -> 2 | M38: =+E38 -> 30 | N38: 3102.4449 | O38: =+M38*N38/12*7 -> 54292.786 | P38: =+N38*M38/12*5 -> 38780.562 | Q38: =VLOOKUP(B38,[2]Sheet1!A$6:H$305,8,0) -> 57 | R38: 30 | S38: =+$S$10*R38/12*7 -> 54180 | T38: =VLOOKUP($B38,[3]oct13!$D$3:$K$244,[3]oct13!E$1,0)-VLOOKUP(Sheet1!$B38,[3]oct12!$E$3:$L$435,[3]oct12!F$1,0) -> 3.5 | U38: =VLOOKUP($B38,[3]oct13!$D$3:$K$244,[3]oct13!F$1,0)-VLOOKUP(Sheet1!$B38,[3]oct12!$E$3:$L$435,[3]oct12!G$1,0) -> 7 | V38: =VLOOKUP($B38,[3]oct13!$D$3:$K$244,[3]oct13!G$1,0)-VLOOKUP(Sheet1!$B38,[3]oct12!$E$3:$L$435,[3]oct12!H$1,0) -> 33 | W38: =VLOOKUP($B38,[3]oct13!$D$3:$K$244,[3]oct13!H$1,0)-VLOOKUP(Sheet1!$B38,[3]oct12!$E$3:$L$435,[3]oct12!I$1,0) -> 4 | X38: =VLOOKUP($B38,[3]oct13!$D$3:$K$244,[3]oct13!I$1,0)-VLOOKUP(Sheet1!$B38,[3]oct12!$E$3:$L$435,[3]oct12!J$1,0) -> 4 | Y38: =VLOOKUP($B38,[3]oct13!$D$3:$K$244,[3]oct13!J$1,0)-VLOOKUP(Sheet1!$B38,[3]oct12!$E$3:$L$435,[3]oct12!K$1,0) -> 6 | Z38: =VLOOKUP($B38,[3]oct13!$D$3:$K$244,[3]oct13!K$1,0)-VLOOKUP(Sheet1!$B38,[3]oct12!$E$3:$L$435,[3]oct12!L$1,0) -> 0
A39: REACN | B39: 3303432 | C39: CLIFTON | D39: 1 | E39: 30 | F39: =VLOOKUP(D39,$E$76:$F$82,2,0) -> 2417.5937 | G39: =+E39*F39/12*7 -> 42307.889 | I39: 38 | J39: 57309.583 | L39: =+D39+1 -> 2 | M39: =+E39 -> 30 | N39: 3102.4449 | O39: =+M39*N39/12*7 -> 54292.786 | P39: =+N39*M39/12*5 -> 38780.562 | Q39: =VLOOKUP(B39,[2]Sheet1!A$6:H$305,8,0) -> 27 | R39: 27 | S39: =+$S$10*R39/12*7 -> 48762 | T39: =VLOOKUP($B39,[3]oct13!$D$3:$K$244,[3]oct13!E$1,0)-VLOOKUP(Sheet1!$B39,[3]oct12!$E$3:$L$435,[3]oct12!F$1,0) -> -5 | U39: =VLOOKUP($B39,[3]oct13!$D$3:$K$244,[3]oct13!F$1,0)-VLOOKUP(Sheet1!$B39,[3]oct12!$E$3:$L$435,[3]oct12!G$1,0) -> 3 | V39: =VLOOKUP($B39,[3]oct13!$D$3:$K$244,[3]oct13!G$1,0)-VLOOKUP(Sheet1!$B39,[3]oct12!$E$3:$L$435,[3]oct12!H$1,0) -> 29 | W39: =VLOOKUP($B39,[3]oct13!$D$3:$K$244,[3]oct13!H$1,0)-VLOOKUP(Sheet1!$B39,[3]oct12!$E$3:$L$435,[3]oct12!I$1,0) -> 0 | X39: =VLOOKUP($B39,[3]oct13!$D$3:$K$244,[3]oct13!I$1,0)-VLOOKUP(Sheet1!$B39,[3]oct12!$E$3:$L$435,[3]oct12!J$1,0) -> 0 | Y39: =VLOOKUP($B39,[3]oct13!$D$3:$K$244,[3]oct13!J$1,0)-VLOOKUP(Sheet1!$B39,[3]oct12!$E$3:$L$435,[3]oct12!K$1,0) -> 0 | Z39: =VLOOKUP($B39,[3]oct13!$D$3:$K$244,[3]oct13!K$1,0)-VLOOKUP(Sheet1!$B39,[3]oct12!$E$3:$L$435,[3]oct12!L$1,0) -> 0
A40: REAHF | B40: 3303434 | C40: MOOR GREEN | D40: 1 | E40: 20 | F40: =VLOOKUP(D40,$E$76:$F$82,2,0) -> 2417.5937 | G40: =+E40*F40/12*7 -> 28205.26 | I40: 41 | J40: 61107.667 | L40: =+D40+1 -> 2 | M40: =+E40 -> 20 | N40: 3102.4449 | O40: =+M40*N40/12*7 -> 36195.191 | P40: =+N40*M40/12*5 -> 25853.708 | R40: 20 | S40: =+$S$10*R40/12*7 -> 36120
A41: REAAE | B41: 3305949 | C41: AL-FURQAN | D41: 1 | E41: 30 | F41: =VLOOKUP(D41,$E$76:$F$82,2,0) -> 2417.5937 | G41: =+E41*F41/12*7 -> 42307.889 | I41: 41 | J41: 57310.75 | L41: =+D41+1 -> 2 | M41: =+E41 -> 30 | N41: 3102.4449 | O41: =+M41*N41/12*7 -> 54292.786 | P41: =+N41*M41/12*5 -> 38780.562 | Q41: =VLOOKUP(B41,[2]Sheet1!A$6:H$305,8,0) -> 18 | R41: 18 | S41: =+$S$10*R41/12*7 -> 32508 | T41: =VLOOKUP($B41,[3]oct13!$D$3:$K$244,[3]oct13!E$1,0)-VLOOKUP(Sheet1!$B41,[3]oct12!$E$3:$L$435,[3]oct12!F$1,0) -> -2 | U41: =VLOOKUP($B41,[3]oct13!$D$3:$K$244,[3]oct13!F$1,0)-VLOOKUP(Sheet1!$B41,[3]oct12!$E$3:$L$435,[3]oct12!G$1,0) -> -9 | V41: =VLOOKUP($B41,[3]oct13!$D$3:$K$244,[3]oct13!G$1,0)-VLOOKUP(Sheet1!$B41,[3]oct12!$E$3:$L$435,[3]oct12!H$1,0) -> 27 | W41: =VLOOKUP($B41,[3]oct13!$D$3:$K$244,[3]oct13!H$1,0)-VLOOKUP(Sheet1!$B41,[3]oct12!$E$3:$L$435,[3]oct12!I$1,0) -> -10 | X41: =VLOOKUP($B41,[3]oct13!$D$3:$K$244,[3]oct13!I$1,0)-VLOOKUP(Sheet1!$B41,[3]oct12!$E$3:$L$435,[3]oct12!J$1,0) -> 8 | Y41: =VLOOKUP($B41,[3]oct13!$D$3:$K$244,[3]oct13!J$1,0)-VLOOKUP(Sheet1!$B41,[3]oct12!$E$3:$L$435,[3]oct12!K$1,0) -> 6 | Z41: =VLOOKUP($B41,[3]oct13!$D$3:$K$244,[3]oct13!K$1,0)-VLOOKUP(Sheet1!$B41,[3]oct12!$E$3:$L$435,[3]oct12!L$1,0) -> -2
B42: 3304009 | C42: WAVERLEY | D42: R | E42: 90 | F42: =VLOOKUP(D42,$E$76:$F$82,2,0) -> 3058.5206 | G42: 0 | I42: 0 | J42: 0 | L42: 1 | M42: =+E42 -> 90 | N42: 3102.4449 | O42: =+M42*N42/12*7 -> 162878.36 | P42: =+N42*M42/12*5 -> 116341.68 | Q42: =VLOOKUP(B42,[2]Sheet1!A$6:H$305,8,0) -> 123 | R42: 106 | S42: =+$S$10*R42/12*7 -> 191436
B43: 3302246 | C43: The Meadows Primary School | Q43: 69 | R43: 24 | S43: =+$S$10*R43/12*7 -> 43344 | T43: =VLOOKUP($B43,[3]oct13!$D$3:$K$244,[3]oct13!E$1,0)-VLOOKUP(Sheet1!$B43,[3]oct12!$E$3:$L$435,[3]oct12!F$1,0) -> 26.5 | U43: =VLOOKUP($B43,[3]oct13!$D$3:$K$244,[3]oct13!F$1,0)-VLOOKUP(Sheet1!$B43,[3]oct12!$E$3:$L$435,[3]oct12!G$1,0) -> 0 | V43: =VLOOKUP($B43,[3]oct13!$D$3:$K$244,[3]oct13!G$1,0)-VLOOKUP(Sheet1!$B43,[3]oct12!$E$3:$L$435,[3]oct12!H$1,0) -> 4 | W43: =VLOOKUP($B43,[3]oct13!$D$3:$K$244,[3]oct13!H$1,0)-VLOOKUP(Sheet1!$B43,[3]oct12!$E$3:$L$435,[3]oct12!I$1,0) -> 4 | X43: =VLOOKUP($B43,[3]oct13!$D$3:$K$244,[3]oct13!I$1,0)-VLOOKUP(Sheet1!$B43,[3]oct12!$E$3:$L$435,[3]oct12!J$1,0) -> -6 | Y43: =VLOOKUP($B43,[3]oct13!$D$3:$K$244,[3]oct13!J$1,0)-VLOOKUP(Sheet1!$B43,[3]oct12!$E$3:$L$435,[3]oct12!K$1,0) -> 0 | Z43: =VLOOKUP($B43,[3]oct13!$D$3:$K$244,[3]oct13!K$1,0)-VLOOKUP(Sheet1!$B43,[3]oct12!$E$3:$L$435,[3]oct12!L$1,0) -> 19
B44: 3302079 | C44: GEORGE DIXON JUNIOR & INFANT | Q44: 60 | R44: 30 | S44: =+$S$10*R44/12*7 -> 54180 | T44: =VLOOKUP($B44,[3]oct13!$D$3:$K$244,[3]oct13!E$1,0)-VLOOKUP(Sheet1!$B44,[3]oct12!$E$3:$L$435,[3]oct12!F$1,0) -> 15 | U44: =VLOOKUP($B44,[3]oct13!$D$3:$K$244,[3]oct13!F$1,0)-VLOOKUP(Sheet1!$B44,[3]oct12!$E$3:$L$435,[3]oct12!G$1,0) -> 16 | V44: =VLOOKUP($B44,[3]oct13!$D$3:$K$244,[3]oct13!G$1,0)-VLOOKUP(Sheet1!$B44,[3]oct12!$E$3:$L$435,[3]oct12!H$1,0) -> 5 | W44: =VLOOKUP($B44,[3]oct13!$D$3:$K$244,[3]oct13!H$1,0)-VLOOKUP(Sheet1!$B44,[3]oct12!$E$3:$L$435,[3]oct12!I$1,0) -> -7 | X44: =VLOOKUP($B44,[3]oct13!$D$3:$K$244,[3]oct13!I$1,0)-VLOOKUP(Sheet1!$B44,[3]oct12!$E$3:$L$435,[3]oct12!J$1,0) -> 6 | Y44: =VLOOKUP($B44,[3]oct13!$D$3:$K$244,[3]oct13!J$1,0)-VLOOKUP(Sheet1!$B44,[3]oct12!$E$3:$L$435,[3]oct12!K$1,0) -> 13 | Z44: =VLOOKUP($B44,[3]oct13!$D$3:$K$244,[3]oct13!K$1,0)-VLOOKUP(Sheet1!$B44,[3]oct12!$E$3:$L$435,[3]oct12!L$1,0) -> 12
...
