Workbook

Sheet MASTER data
A1: PETRON
A2: MASTER SUMMARY SHEET
A4: DATE - 21.3.12
A5: S.NO. | C5: ITEM DECRIPTION | E5: DATE | F5: ULTRATECH CEMENT - RAVAN | G5: RELIANCE - SATNA | H5: SEPCO -CHATISGARH CHAMPA | I5: LAFARGE -CHATISGARH
F6: UNIT RATE (RS.) | G6: UNIT RATE (RS.) | H6: UNIT RATE (RS.) | I6: UNIT RATE (RS.)
A7: 1 | B7: LFG | C7: 220AMP CHANGE OVER SWITCH FRONT HANDLE MAKE L &T | E7: 40941 | I7: 2345
A8: 2 | B8: LFG | C8: dd | E8: 40941 | H8: 345
A9: 3 | B9: SEP | C9: sf | E9: 40941 | G9: 654
B10: RIL | C10: f | E10: 40941 | F10: 324
B11: RIL | C11: jhjuh | E11: 40970 | I11: 2355
B12: LFG | C12: klk | E12: 40941 | I12: 3332
B13: UTC

Sheet UTC
A1: PETRON
A2: ULTRA TECH CEMENT -RAVAN
C3: 2011 | AA3: 2012
A4: S.NO. | B4: ITEM DECRIPTION | C4: 40544 | E4: 40576 | G4: 40608 | I4: 40640 | K4: 40672 | M4: 40704 | O4: 40736 | Q4: 40768 | S4: 40800 | U4: 40832 | W4: 40864 | Y4: 40896 | AA4: 40544 | AC4: 40576 | AE4: 40608 | AG4: 40640 | AI4: 40672 | AK4: 40704 | AM4: 40736 | AO4: 40768 | AQ4: 40800 | AS4: 40832 | AU4: 40864 | AW4: 40896
C5: DATE | D5: UNIT RATE (RS.) | E5: DATE | F5: UNIT RATE (RS.) | G5: DATE | H5: UNIT RATE (RS.) | I5: DATE | J5: UNIT RATE (RS.) | K5: DATE | L5: UNIT RATE (RS.) | M5: DATE | N5: UNIT RATE (RS.) | O5: DATE | P5: UNIT RATE (RS.) | Q5: DATE | R5: UNIT RATE (RS.) | S5: DATE | T5: UNIT RATE (RS.) | U5: DATE | V5: UNIT RATE (RS.) | W5: DATE | X5: UNIT RATE (RS.) | Y5: DATE | Z5: UNIT RATE (RS.) | AA5: DATE | AB5: UNIT RATE (RS.) | AC5: DATE | AD5: UNIT RATE (RS.) | AE5: DATE | AF5: UNIT RATE (RS.) | AG5: DATE | AH5: UNIT RATE (RS.) | AI5: DATE | AJ5: UNIT RATE (RS.) | AK5: DATE | AL5: UNIT RATE (RS.) | AM5: DATE | AN5: UNIT RATE (RS.) | AO5: DATE | AP5: UNIT RATE (RS.) | AQ5: DATE | AR5: UNIT RATE (RS.) | AS5: DATE | AT5: UNIT RATE (RS.) | AU5: DATE | AV5: UNIT RATE (RS.) | AW5: DATE | AX5: UNIT RATE (RS.)
A6: 1 | B6: =IF('MASTER data'!B7="UTC",'MASTER data'!C7,0) -> 0 | C6: =IF('MASTER data'!$B7="UTC",IF(MONTH('MASTER data'!$E7)=MONTH(C$4),'MASTER data'!$E7,""),"") | D6: =IF(C6='MASTER data'!$E7,'MASTER data'!$H7,"") | E6: =IF('MASTER data'!$B7="UTC",IF(MONTH('MASTER data'!$E7)=MONTH(E$4),'MASTER data'!$E7,""),"") | F6: =IF(E6='MASTER data'!$E7,'MASTER data'!$H7,"") | G6: =IF('MASTER data'!$B7="UTC",IF(MONTH('MASTER data'!$E7)=MONTH(G$4),'MASTER data'!$E7,""),"") | H6: =IF(G6='MASTER data'!$E7,'MASTER data'!$H7,"") | I6: =IF('MASTER data'!$B7="UTC",IF(MONTH('MASTER data'!$E7)=MONTH(I$4),'MASTER data'!$E7,""),"") | J6: =IF(I6='MASTER data'!$E7,'MASTER data'!$H7,"") | K6: =IF('MASTER data'!$B7="UTC",IF(MONTH('MASTER data'!$E7)=MONTH(K$4),'MASTER data'!$E7,""),"") | L6: =IF(K6='MASTER data'!$E7,'MASTER data'!$H7,"") | M6: =IF('MASTER data'!$B7="UTC",IF(MONTH('MASTER data'!$E7)=MONTH(M$4),'MASTER data'!$E7,""),"") | N6: =IF(M6='MASTER data'!$E7,'MASTER data'!$H7,"") | O6: =IF('MASTER data'!$B7="UTC",IF(MONTH('MASTER data'!$E7)=MONTH(O$4),'MASTER data'!$E7,""),"") | P6: =IF(O6='MASTER data'!$E7,'MASTER data'!$H7,"") | Q6: =IF('MASTER data'!$B7="UTC",IF(MONTH('MASTER data'!$E7)=MONTH(Q$4),'MASTER data'!$E7,""),"") | R6: =IF(Q6='MASTER data'!$E7,'MASTER data'!$H7,"") | S6: =IF('MASTER data'!$B7="UTC",IF(MONTH('MASTER data'!$E7)=MONTH(S$4),'MASTER data'!$E7,""),"") | T6: =IF(S6='MASTER data'!$E7,'MASTER data'!$H7,"") | U6: =IF('MASTER data'!$B7="UTC",IF(MONTH('MASTER data'!$E7)=MONTH(U$4),'MASTER data'!$E7,""),"") | V6: =IF(U6='MASTER data'!$E7,'MASTER data'!$H7,"") | W6: =IF('MASTER data'!$B7="UTC",IF(MONTH('MASTER data'!$E7)=MONTH(W$4),'MASTER data'!$E7,""),"") | X6: =IF(W6='MASTER data'!$E7,'MASTER data'!$H7,"") | Y6: =IF('MASTER data'!$B7="UTC",IF(MONTH('MASTER data'!$E7)=MONTH(Y$4),'MASTER data'!$E7,""),"") | Z6: =IF(Y6='MASTER data'!$E7,'MASTER data'!$H7,"")
C7: =IF('MASTER data'!$B8="UTC",IF(MONTH('MASTER data'!$E8)=MONTH(C$4),'MASTER data'!$E8,""),"") | D7: =IF(C7='MASTER data'!$E8,'MASTER data'!$H8,"") | E7: =IF('MASTER data'!$B8="UTC",IF(MONTH('MASTER data'!$E8)=MONTH(E$4),'MASTER data'!$E8,""),"") | F7: =IF(E7='MASTER data'!$E8,'MASTER data'!$H8,"") | G7: =IF('MASTER data'!$B8="UTC",IF(MONTH('MASTER data'!$E8)=MONTH(G$4),'MASTER data'!$E8,""),"") | H7: =IF(G7='MASTER data'!$E8,'MASTER data'!$H8,"") | I7: =IF('MASTER data'!$B8="UTC",IF(MONTH('MASTER data'!$E8)=MONTH(I$4),'MASTER data'!$E8,""),"") | J7: =IF(I7='MASTER data'!$E8,'MASTER data'!$H8,"") | K7: =IF('MASTER data'!$B8="UTC",IF(MONTH('MASTER data'!$E8)=MONTH(K$4),'MASTER data'!$E8,""),"") | L7: =IF(K7='MASTER data'!$E8,'MASTER data'!$H8,"") | M7: =IF('MASTER data'!$B8="UTC",IF(MONTH('MASTER data'!$E8)=MONTH(M$4),'MASTER data'!$E8,""),"") | N7: =IF(M7='MASTER data'!$E8,'MASTER data'!$H8,"") | O7: =IF('MASTER data'!$B8="UTC",IF(MONTH('MASTER data'!$E8)=MONTH(O$4),'MASTER data'!$E8,""),"") | P7: =IF(O7='MASTER data'!$E8,'MASTER data'!$H8,"") | Q7: =IF('MASTER data'!$B8="UTC",IF(MONTH('MASTER data'!$E8)=MONTH(Q$4),'MASTER data'!$E8,""),"") | R7: =IF(Q7='MASTER data'!$E8,'MASTER data'!$H8,"") | S7: =IF('MASTER data'!$B8="UTC",IF(MONTH('MASTER data'!$E8)=MONTH(S$4),'MASTER data'!$E8,""),"") | T7: =IF(S7='MASTER data'!$E8,'MASTER data'!$H8,"") | U7: =IF('MASTER data'!$B8="UTC",IF(MONTH('MASTER data'!$E8)=MONTH(U$4),'MASTER data'!$E8,""),"") | V7: =IF(U7='MASTER data'!$E8,'MASTER data'!$H8,"") | W7: =IF('MASTER data'!$B8="UTC",IF(MONTH('MASTER data'!$E8)=MONTH(W$4),'MASTER data'!$E8,""),"") | X7: =IF(W7='MASTER data'!$E8,'MASTER data'!$H8,"") | Y7: =IF('MASTER data'!$B8="UTC",IF(MONTH('MASTER data'!$E8)=MONTH(Y$4),'MASTER data'!$E8,""),"") | Z7: =IF(Y7='MASTER data'!$E8,'MASTER data'!$H8,"")
C8: =IF('MASTER data'!$B9="UTC",IF(MONTH('MASTER data'!$E9)=MONTH(C$4),'MASTER data'!$E9,""),"") | D8: =IF(C8='MASTER data'!$E9,'MASTER data'!$H9,"") | E8: =IF('MASTER data'!$B9="UTC",IF(MONTH('MASTER data'!$E9)=MONTH(E$4),'MASTER data'!$E9,""),"") | F8: =IF(E8='MASTER data'!$E9,'MASTER data'!$H9,"") | G8: =IF('MASTER data'!$B9="UTC",IF(MONTH('MASTER data'!$E9)=MONTH(G$4),'MASTER data'!$E9,""),"") | H8: =IF(G8='MASTER data'!$E9,'MASTER data'!$H9,"") | I8: =IF('MASTER data'!$B9="UTC",IF(MONTH('MASTER data'!$E9)=MONTH(I$4),'MASTER data'!$E9,""),"") | J8: =IF(I8='MASTER data'!$E9,'MASTER data'!$H9,"") | K8: =IF('MASTER data'!$B9="UTC",IF(MONTH('MASTER data'!$E9)=MONTH(K$4),'MASTER data'!$E9,""),"") | L8: =IF(K8='MASTER data'!$E9,'MASTER data'!$H9,"") | M8: =IF('MASTER data'!$B9="UTC",IF(MONTH('MASTER data'!$E9)=MONTH(M$4),'MASTER data'!$E9,""),"") | N8: =IF(M8='MASTER data'!$E9,'MASTER data'!$H9,"") | O8: =IF('MASTER data'!$B9="UTC",IF(MONTH('MASTER data'!$E9)=MONTH(O$4),'MASTER data'!$E9,""),"") | P8: =IF(O8='MASTER data'!$E9,'MASTER data'!$H9,"") | Q8: =IF('MASTER data'!$B9="UTC",IF(MONTH('MASTER data'!$E9)=MONTH(Q$4),'MASTER data'!$E9,""),"") | R8: =IF(Q8='MASTER data'!$E9,'MASTER data'!$H9,"") | S8: =IF('MASTER data'!$B9="UTC",IF(MONTH('MASTER data'!$E9)=MONTH(S$4),'MASTER data'!$E9,""),"") | T8: =IF(S8='MASTER data'!$E9,'MASTER data'!$H9,"") | U8: =IF('MASTER data'!$B9="UTC",IF(MONTH('MASTER data'!$E9)=MONTH(U$4),'MASTER data'!$E9,""),"") | V8: =IF(U8='MASTER data'!$E9,'MASTER data'!$H9,"") | W8: =IF('MASTER data'!$B9="UTC",IF(MONTH('MASTER data'!$E9)=MONTH(W$4),'MASTER data'!$E9,""),"") | X8: =IF(W8='MASTER data'!$E9,'MASTER data'!$H9,"") | Y8: =IF('MASTER data'!$B9="UTC",IF(MONTH('MASTER data'!$E9)=MONTH(Y$4),'MASTER data'!$E9,""),"") | Z8: =IF(Y8='MASTER data'!$E9,'MASTER data'!$H9,"")
C9: =IF('MASTER data'!$B10="UTC",IF(MONTH('MASTER data'!$E10)=MONTH(C$4),'MASTER data'!$E10,""),"") | D9: =IF(C9='MASTER data'!$E10,'MASTER data'!$H10,"") | E9: =IF('MASTER data'!$B10="UTC",IF(MONTH('MASTER data'!$E10)=MONTH(E$4),'MASTER data'!$E10,""),"") | F9: =IF(E9='MASTER data'!$E10,'MASTER data'!$H10,"") | G9: =IF('MASTER data'!$B10="UTC",IF(MONTH('MASTER data'!$E10)=MONTH(G$4),'MASTER data'!$E10,""),"") | H9: =IF(G9='MASTER data'!$E10,'MASTER data'!$H10,"") | I9: =IF('MASTER data'!$B10="UTC",IF(MONTH('MASTER data'!$E10)=MONTH(I$4),'MASTER data'!$E10,""),"") | J9: =IF(I9='MASTER data'!$E10,'MASTER data'!$H10,"") | K9: =IF('MASTER data'!$B10="UTC",IF(MONTH('MASTER data'!$E10)=MONTH(K$4),'MASTER data'!$E10,""),"") | L9: =IF(K9='MASTER data'!$E10,'MASTER data'!$H10,"") | M9: =IF('MASTER data'!$B10="UTC",IF(MONTH('MASTER data'!$E10)=MONTH(M$4),'MASTER data'!$E10,""),"") | N9: =IF(M9='MASTER data'!$E10,'MASTER data'!$H10,"") | O9: =IF('MASTER data'!$B10="UTC",IF(MONTH('MASTER data'!$E10)=MONTH(O$4),'MASTER data'!$E10,""),"") | P9: =IF(O9='MASTER data'!$E10,'MASTER data'!$H10,"") | Q9: =IF('MASTER data'!$B10="UTC",IF(MONTH('MASTER data'!$E10)=MONTH(Q$4),'MASTER data'!$E10,""),"") | R9: =IF(Q9='MASTER data'!$E10,'MASTER data'!$H10,"") | S9: =IF('MASTER data'!$B10="UTC",IF(MONTH('MASTER data'!$E10)=MONTH(S$4),'MASTER data'!$E10,""),"") | T9: =IF(S9='MASTER data'!$E10,'MASTER data'!$H10,"") | U9: =IF('MASTER data'!$B10="UTC",IF(MONTH('MASTER data'!$E10)=MONTH(U$4),'MASTER data'!$E10,""),"") | V9: =IF(U9='MASTER data'!$E10,'MASTER data'!$H10,"") | W9: =IF('MASTER data'!$B10="UTC",IF(MONTH('MASTER data'!$E10)=MONTH(W$4),'MASTER data'!$E10,""),"") | X9: =IF(W9='MASTER data'!$E10,'MASTER data'!$H10,"") | Y9: =IF('MASTER data'!$B10="UTC",IF(MONTH('MASTER data'!$E10)=MONTH(Y$4),'MASTER data'!$E10,""),"") | Z9: =IF(Y9='MASTER data'!$E10,'MASTER data'!$H10,"")
C10: =IF('MASTER data'!$B11="UTC",IF(MONTH('MASTER data'!$E11)=MONTH(C$4),'MASTER data'!$E11,""),"") | D10: =IF(C10='MASTER data'!$E11,'MASTER data'!$H11,"") | E10: =IF('MASTER data'!$B11="UTC",IF(MONTH('MASTER data'!$E11)=MONTH(E$4),'MASTER data'!$E11,""),"") | F10: =IF(E10='MASTER data'!$E11,'MASTER data'!$H11,"") | G10: =IF('MASTER data'!$B11="UTC",IF(MONTH('MASTER data'!$E11)=MONTH(G$4),'MASTER data'!$E11,""),"") | H10: =IF(G10='MASTER data'!$E11,'MASTER data'!$H11,"") | I10: =IF('MASTER data'!$B11="UTC",IF(MONTH('MASTER data'!$E11)=MONTH(I$4),'MASTER data'!$E11,""),"") | J10: =IF(I10='MASTER data'!$E11,'MASTER data'!$H11,"") | K10: =IF('MASTER data'!$B11="UTC",IF(MONTH('MASTER data'!$E11)=MONTH(K$4),'MASTER data'!$E11,""),"") | L10: =IF(K10='MASTER data'!$E11,'MASTER data'!$H11,"") | M10: =IF('MASTER data'!$B11="UTC",IF(MONTH('MASTER data'!$E11)=MONTH(M$4),'MASTER data'!$E11,""),"") | N10: =IF(M10='MASTER data'!$E11,'MASTER data'!$H11,"") | O10: =IF('MASTER data'!$B11="UTC",IF(MONTH('MASTER data'!$E11)=MONTH(O$4),'MASTER data'!$E11,""),"") | P10: =IF(O10='MASTER data'!$E11,'MASTER data'!$H11,"") | Q10: =IF('MASTER data'!$B11="UTC",IF(MONTH('MASTER data'!$E11)=MONTH(Q$4),'MASTER data'!$E11,""),"") | R10: =IF(Q10='MASTER data'!$E11,'MASTER data'!$H11,"") | S10: =IF('MASTER data'!$B11="UTC",IF(MONTH('MASTER data'!$E11)=MONTH(S$4),'MASTER data'!$E11,""),"") | T10: =IF(S10='MASTER data'!$E11,'MASTER data'!$H11,"") | U10: =IF('MASTER data'!$B11="UTC",IF(MONTH('MASTER data'!$E11)=MONTH(U$4),'MASTER data'!$E11,""),"") | V10: =IF(U10='MASTER data'!$E11,'MASTER data'!$H11,"") | W10: =IF('MASTER data'!$B11="UTC",IF(MONTH('MASTER data'!$E11)=MONTH(W$4),'MASTER data'!$E11,""),"") | X10: =IF(W10='MASTER data'!$E11,'MASTER data'!$H11,"") | Y10: =IF('MASTER data'!$B11="UTC",IF(MONTH('MASTER data'!$E11)=MONTH(Y$4),'MASTER data'!$E11,""),"") | Z10: =IF(Y10='MASTER data'!$E11,'MASTER data'!$H11,"")
C11: =IF('MASTER data'!$B12="UTC",IF(MONTH('MASTER data'!$E12)=MONTH(C$4),'MASTER data'!$E12,""),"") | D11: =IF(C11='MASTER data'!$E12,'MASTER data'!$H12,"") | E11: =IF('MASTER data'!$B12="UTC",IF(MONTH('MASTER data'!$E12)=MONTH(E$4),'MASTER data'!$E12,""),"") | F11: =IF(E11='MASTER data'!$E12,'MASTER data'!$H12,"") | G11: =IF('MASTER data'!$B12="UTC",IF(MONTH('MASTER data'!$E12)=MONTH(G$4),'MASTER data'!$E12,""),"") | H11: =IF(G11='MASTER data'!$E12,'MASTER data'!$H12,"") | I11: =IF('MASTER data'!$B12="UTC",IF(MONTH('MASTER data'!$E12)=MONTH(I$4),'MASTER data'!$E12,""),"") | J11: =IF(I11='MASTER data'!$E12,'MASTER data'!$H12,"") | K11: =IF('MASTER data'!$B12="UTC",IF(MONTH('MASTER data'!$E12)=MONTH(K$4),'MASTER data'!$E12,""),"") | L11: =IF(K11='MASTER data'!$E12,'MASTER data'!$H12,"") | M11: =IF('MASTER data'!$B12="UTC",IF(MONTH('MASTER data'!$E12)=MONTH(M$4),'MASTER data'!$E12,""),"") | N11: =IF(M11='MASTER data'!$E12,'MASTER data'!$H12,"") | O11: =IF('MASTER data'!$B12="UTC",IF(MONTH('MASTER data'!$E12)=MONTH(O$4),'MASTER data'!$E12,""),"") | P11: =IF(O11='MASTER data'!$E12,'MASTER data'!$H12,"") | Q11: =IF('MASTER data'!$B12="UTC",IF(MONTH('MASTER data'!$E12)=MONTH(Q$4),'MASTER data'!$E12,""),"") | R11: =IF(Q11='MASTER data'!$E12,'MASTER data'!$H12,"") | S11: =IF('MASTER data'!$B12="UTC",IF(MONTH('MASTER data'!$E12)=MONTH(S$4),'MASTER data'!$E12,""),"") | T11: =IF(S11='MASTER data'!$E12,'MASTER data'!$H12,"") | U11: =IF('MASTER data'!$B12="UTC",IF(MONTH('MASTER data'!$E12)=MONTH(U$4),'MASTER data'!$E12,""),"") | V11: =IF(U11='MASTER data'!$E12,'MASTER data'!$H12,"") | W11: =IF('MASTER data'!$B12="UTC",IF(MONTH('MASTER data'!$E12)=MONTH(W$4),'MASTER data'!$E12,""),"") | X11: =IF(W11='MASTER data'!$E12,'MASTER data'!$H12,"") | Y11: =IF('MASTER data'!$B12="UTC",IF(MONTH('MASTER data'!$E12)=MONTH(Y$4),'MASTER data'!$E12,""),"") | Z11: =IF(Y11='MASTER data'!$E12,'MASTER data'!$H12,"")
C12: =IF('MASTER data'!$B13="UTC",IF(MONTH('MASTER data'!$E13)=MONTH(C$4),'MASTER data'!$E13,""),"") -> 0 | D12: =IF(C12='MASTER data'!$E13,'MASTER data'!$H13,"") -> 0 | E12: =IF('MASTER data'!$B13="UTC",IF(MONTH('MASTER data'!$E13)=MONTH(E$4),'MASTER data'!$E13,""),"") | F12: =IF(E12='MASTER data'!$E13,'MASTER data'!$H13,"") -> 0 | G12: =IF('MASTER data'!$B13="UTC",IF(MONTH('MASTER data'!$E13)=MONTH(G$4),'MASTER data'!$E13,""),"") | H12: =IF(G12='MASTER data'!$E13,'MASTER data'!$H13,"") -> 0 | I12: =IF('MASTER data'!$B13="UTC",IF(MONTH('MASTER data'!$E13)=MONTH(I$4),'MASTER data'!$E13,""),"") | J12: =IF(I12='MASTER data'!$E13,'MASTER data'!$H13,"") -> 0 | K12: =IF('MASTER data'!$B13="UTC",IF(MONTH('MASTER data'!$E13)=MONTH(K$4),'MASTER data'!$E13,""),"") | L12: =IF(K12='MASTER data'!$E13,'MASTER data'!$H13,"") -> 0 | M12: =IF('MASTER data'!$B13="UTC",IF(MONTH('MASTER data'!$E13)=MONTH(M$4),'MASTER data'!$E13,""),"") | N12: =IF(M12='MASTER data'!$E13,'MASTER data'!$H13,"") -> 0 | O12: =IF('MASTER data'!$B13="UTC",IF(MONTH('MASTER data'!$E13)=MONTH(O$4),'MASTER data'!$E13,""),"") | P12: =IF(O12='MASTER data'!$E13,'MASTER data'!$H13,"") -> 0 | Q12: =IF('MASTER data'!$B13="UTC",IF(MONTH('MASTER data'!$E13)=MONTH(Q$4),'MASTER data'!$E13,""),"") | R12: =IF(Q12='MASTER data'!$E13,'MASTER data'!$H13,"") -> 0 | S12: =IF('MASTER data'!$B13="UTC",IF(MONTH('MASTER data'!$E13)=MONTH(S$4),'MASTER data'!$E13,""),"") | T12: =IF(S12='MASTER data'!$E13,'MASTER data'!$H13,"") -> 0 | U12: =IF('MASTER data'!$B13="UTC",IF(MONTH('MASTER data'!$E13)=MONTH(U$4),'MASTER data'!$E13,""),"") | V12: =IF(U12='MASTER data'!$E13,'MASTER data'!$H13,"") -> 0 | W12: =IF('MASTER data'!$B13="UTC",IF(MONTH('MASTER data'!$E13)=MONTH(W$4),'MASTER data'!$E13,""),"") | X12: =IF(W12='MASTER data'!$E13,'MASTER data'!$H13,"") -> 0 | Y12: =IF('MASTER data'!$B13="UTC",IF(MONTH('MASTER data'!$E13)=MONTH(Y$4),'MASTER data'!$E13,""),"") | Z12: =IF(Y12='MASTER data'!$E13,'MASTER data'!$H13,"") -> 0
C13: =IF('MASTER data'!$B14="UTC",IF(MONTH('MASTER data'!$E14)=MONTH(C$4),'MASTER data'!$E14,""),"") | D13: =IF(C13='MASTER data'!$E14,'MASTER data'!$H14,"") -> 0 | E13: =IF('MASTER data'!$B14="UTC",IF(MONTH('MASTER data'!$E14)=MONTH(E$4),'MASTER data'!$E14,""),"") | F13: =IF(E13='MASTER data'!$E14,'MASTER data'!$H14,"") -> 0 | G13: =IF('MASTER data'!$B14="UTC",IF(MONTH('MASTER data'!$E14)=MONTH(G$4),'MASTER data'!$E14,""),"") | H13: =IF(G13='MASTER data'!$E14,'MASTER data'!$H14,"") -> 0 | I13: =IF('MASTER data'!$B14="UTC",IF(MONTH('MASTER data'!$E14)=MONTH(I$4),'MASTER data'!$E14,""),"") | J13: =IF(I13='MASTER data'!$E14,'MASTER data'!$H14,"") -> 0 | K13: =IF('MASTER data'!$B14="UTC",IF(MONTH('MASTER data'!$E14)=MONTH(K$4),'MASTER data'!$E14,""),"") | L13: =IF(K13='MASTER data'!$E14,'MASTER data'!$H14,"") -> 0 | M13: =IF('MASTER data'!$B14="UTC",IF(MONTH('MASTER data'!$E14)=MONTH(M$4),'MASTER data'!$E14,""),"") | N13: =IF(M13='MASTER data'!$E14,'MASTER data'!$H14,"") -> 0 | O13: =IF('MASTER data'!$B14="UTC",IF(MONTH('MASTER data'!$E14)=MONTH(O$4),'MASTER data'!$E14,""),"") | P13: =IF(O13='MASTER data'!$E14,'MASTER data'!$H14,"") -> 0 | Q13: =IF('MASTER data'!$B14="UTC",IF(MONTH('MASTER data'!$E14)=MONTH(Q$4),'MASTER data'!$E14,""),"") | R13: =IF(Q13='MASTER data'!$E14,'MASTER data'!$H14,"") -> 0 | S13: =IF('MASTER data'!$B14="UTC",IF(MONTH('MASTER data'!$E14)=MONTH(S$4),'MASTER data'!$E14,""),"") | T13: =IF(S13='MASTER data'!$E14,'MASTER data'!$H14,"") -> 0 | U13: =IF('MASTER data'!$B14="UTC",IF(MONTH('MASTER data'!$E14)=MONTH(U$4),'MASTER data'!$E14,""),"") | V13: =IF(U13='MASTER data'!$E14,'MASTER data'!$H14,"") -> 0 | W13: =IF('MASTER data'!$B14="UTC",IF(MONTH('MASTER data'!$E14)=MONTH(W$4),'MASTER data'!$E14,""),"") | X13: =IF(W13='MASTER data'!$E14,'MASTER data'!$H14,"") -> 0 | Y13: =IF('MASTER data'!$B14="UTC",IF(MONTH('MASTER data'!$E14)=MONTH(Y$4),'MASTER data'!$E14,""),"") | Z13: =IF(Y13='MASTER data'!$E14,'MASTER data'!$H14,"") -> 0
C14: =IF('MASTER data'!$B15="UTC",IF(MONTH('MASTER data'!$E15)=MONTH(C$4),'MASTER data'!$E15,""),"") | D14: =IF(C14='MASTER data'!$E15,'MASTER data'!$H15,"") -> 0 | E14: =IF('MASTER data'!$B15="UTC",IF(MONTH('MASTER data'!$E15)=MONTH(E$4),'MASTER data'!$E15,""),"") | F14: =IF(E14='MASTER data'!$E15,'MASTER data'!$H15,"") -> 0 | G14: =IF('MASTER data'!$B15="UTC",IF(MONTH('MASTER data'!$E15)=MONTH(G$4),'MASTER data'!$E15,""),"") | H14: =IF(G14='MASTER data'!$E15,'MASTER data'!$H15,"") -> 0 | I14: =IF('MASTER data'!$B15="UTC",IF(MONTH('MASTER data'!$E15)=MONTH(I$4),'MASTER data'!$E15,""),"") | J14: =IF(I14='MASTER data'!$E15,'MASTER data'!$H15,"") -> 0 | K14: =IF('MASTER data'!$B15="UTC",IF(MONTH('MASTER data'!$E15)=MONTH(K$4),'MASTER data'!$E15,""),"") | L14: =IF(K14='MASTER data'!$E15,'MASTER data'!$H15,"") -> 0 | M14: =IF('MASTER data'!$B15="UTC",IF(MONTH('MASTER data'!$E15)=MONTH(M$4),'MASTER data'!$E15,""),"") | N14: =IF(M14='MASTER data'!$E15,'MASTER data'!$H15,"") -> 0 | O14: =IF('MASTER data'!$B15="UTC",IF(MONTH('MASTER data'!$E15)=MONTH(O$4),'MASTER data'!$E15,""),"") | P14: =IF(O14='MASTER data'!$E15,'MASTER data'!$H15,"") -> 0 | Q14: =IF('MASTER data'!$B15="UTC",IF(MONTH('MASTER data'!$E15)=MONTH(Q$4),'MASTER data'!$E15,""),"") | R14: =IF(Q14='MASTER data'!$E15,'MASTER data'!$H15,"") -> 0 | S14: =IF('MASTER data'!$B15="UTC",IF(MONTH('MASTER data'!$E15)=MONTH(S$4),'MASTER data'!$E15,""),"") | T14: =IF(S14='MASTER data'!$E15,'MASTER data'!$H15,"") -> 0 | U14: =IF('MASTER data'!$B15="UTC",IF(MONTH('MASTER data'!$E15)=MONTH(U$4),'MASTER data'!$E15,""),"") | V14: =IF(U14='MASTER data'!$E15,'MASTER data'!$H15,"") -> 0 | W14: =IF('MASTER data'!$B15="UTC",IF(MONTH('MASTER data'!$E15)=MONTH(W$4),'MASTER data'!$E15,""),"") | X14: =IF(W14='MASTER data'!$E15,'MASTER data'!$H15,"") -> 0 | Y14: =IF('MASTER data'!$B15="UTC",IF(MONTH('MASTER data'!$E15)=MONTH(Y$4),'MASTER data'!$E15,""),"") | Z14: =IF(Y14='MASTER data'!$E15,'MASTER data'!$H15,"") -> 0
C15: =IF('MASTER data'!$B16="UTC",IF(MONTH('MASTER data'!$E16)=MONTH(C$4),'MASTER data'!$E16,""),"") | D15: =IF(C15='MASTER data'!$E16,'MASTER data'!$H16,"") -> 0 | E15: =IF('MASTER data'!$B16="UTC",IF(MONTH('MASTER data'!$E16)=MONTH(E$4),'MASTER data'!$E16,""),"") | F15: =IF(E15='MASTER data'!$E16,'MASTER data'!$H16,"") -> 0 | G15: =IF('MASTER data'!$B16="UTC",IF(MONTH('MASTER data'!$E16)=MONTH(G$4),'MASTER data'!$E16,""),"") | H15: =IF(G15='MASTER data'!$E16,'MASTER data'!$H16,"") -> 0 | I15: =IF('MASTER data'!$B16="UTC",IF(MONTH('MASTER data'!$E16)=MONTH(I$4),'MASTER data'!$E16,""),"") | J15: =IF(I15='MASTER data'!$E16,'MASTER data'!$H16,"") -> 0 | K15: =IF('MASTER data'!$B16="UTC",IF(MONTH('MASTER data'!$E16)=MONTH(K$4),'MASTER data'!$E16,""),"") | L15: =IF(K15='MASTER data'!$E16,'MASTER data'!$H16,"") -> 0 | M15: =IF('MASTER data'!$B16="UTC",IF(MONTH('MASTER data'!$E16)=MONTH(M$4),'MASTER data'!$E16,""),"") | N15: =IF(M15='MASTER data'!$E16,'MASTER data'!$H16,"") -> 0 | O15: =IF('MASTER data'!$B16="UTC",IF(MONTH('MASTER data'!$E16)=MONTH(O$4),'MASTER data'!$E16,""),"") | P15: =IF(O15='MASTER data'!$E16,'MASTER data'!$H16,"") -> 0 | Q15: =IF('MASTER data'!$B16="UTC",IF(MONTH('MASTER data'!$E16)=MONTH(Q$4),'MASTER data'!$E16,""),"") | R15: =IF(Q15='MASTER data'!$E16,'MASTER data'!$H16,"") -> 0 | S15: =IF('MASTER data'!$B16="UTC",IF(MONTH('MASTER data'!$E16)=MONTH(S$4),'MASTER data'!$E16,""),"") | T15: =IF(S15='MASTER data'!$E16,'MASTER data'!$H16,"") -> 0 | U15: =IF('MASTER data'!$B16="UTC",IF(MONTH('MASTER data'!$E16)=MONTH(U$4),'MASTER data'!$E16,""),"") | V15: =IF(U15='MASTER data'!$E16,'MASTER data'!$H16,"") -> 0 | W15: =IF('MASTER data'!$B16="UTC",IF(MONTH('MASTER data'!$E16)=MONTH(W$4),'MASTER data'!$E16,""),"") | X15: =IF(W15='MASTER data'!$E16,'MASTER data'!$H16,"") -> 0 | Y15: =IF('MASTER data'!$B16="UTC",IF(MONTH('MASTER data'!$E16)=MONTH(Y$4),'MASTER data'!$E16,""),"") | Z15: =IF(Y15='MASTER data'!$E16,'MASTER data'!$H16,"") -> 0
C16: =IF('MASTER data'!$B17="UTC",IF(MONTH('MASTER data'!$E17)=MONTH(C$4),'MASTER data'!$E17,""),"") | D16: =IF(C16='MASTER data'!$E17,'MASTER data'!$H17,"") -> 0 | E16: =IF('MASTER data'!$B17="UTC",IF(MONTH('MASTER data'!$E17)=MONTH(E$4),'MASTER data'!$E17,""),"") | F16: =IF(E16='MASTER data'!$E17,'MASTER data'!$H17,"") -> 0 | G16: =IF('MASTER data'!$B17="UTC",IF(MONTH('MASTER data'!$E17)=MONTH(G$4),'MASTER data'!$E17,""),"") | H16: =IF(G16='MASTER data'!$E17,'MASTER data'!$H17,"") -> 0 | I16: =IF('MASTER data'!$B17="UTC",IF(MONTH('MASTER data'!$E17)=MONTH(I$4),'MASTER data'!$E17,""),"") | J16: =IF(I16='MASTER data'!$E17,'MASTER data'!$H17,"") -> 0 | K16: =IF('MASTER data'!$B17="UTC",IF(MONTH('MASTER data'!$E17)=MONTH(K$4),'MASTER data'!$E17,""),"") | L16: =IF(K16='MASTER data'!$E17,'MASTER data'!$H17,"") -> 0 | M16: =IF('MASTER data'!$B17="UTC",IF(MONTH('MASTER data'!$E17)=MONTH(M$4),'MASTER data'!$E17,""),"") | N16: =IF(M16='MASTER data'!$E17,'MASTER data'!$H17,"") -> 0 | O16: =IF('MASTER data'!$B17="UTC",IF(MONTH('MASTER data'!$E17)=MONTH(O$4),'MASTER data'!$E17,""),"") | P16: =IF(O16='MASTER data'!$E17,'MASTER data'!$H17,"") -> 0 | Q16: =IF('MASTER data'!$B17="UTC",IF(MONTH('MASTER data'!$E17)=MONTH(Q$4),'MASTER data'!$E17,""),"") | R16: =IF(Q16='MASTER data'!$E17,'MASTER data'!$H17,"") -> 0 | S16: =IF('MASTER data'!$B17="UTC",IF(MONTH('MASTER data'!$E17)=MONTH(S$4),'MASTER data'!$E17,""),"") | T16: =IF(S16='MASTER data'!$E17,'MASTER data'!$H17,"") -> 0 | U16: =IF('MASTER data'!$B17="UTC",IF(MONTH('MASTER data'!$E17)=MONTH(U$4),'MASTER data'!$E17,""),"") | V16: =IF(U16='MASTER data'!$E17,'MASTER data'!$H17,"") -> 0 | W16: =IF('MASTER data'!$B17="UTC",IF(MONTH('MASTER data'!$E17)=MONTH(W$4),'MASTER data'!$E17,""),"") | X16: =IF(W16='MASTER data'!$E17,'MASTER data'!$H17,"") -> 0 | Y16: =IF('MASTER data'!$B17="UTC",IF(MONTH('MASTER data'!$E17)=MONTH(Y$4),'MASTER data'!$E17,""),"") | Z16: =IF(Y16='MASTER data'!$E17,'MASTER data'!$H17,"") -> 0
C17: =IF('MASTER data'!$B18="UTC",IF(MONTH('MASTER data'!$E18)=MONTH(C$4),'MASTER data'!$E18,""),"") | D17: =IF(C17='MASTER data'!$E18,'MASTER data'!$H18,"") -> 0 | E17: =IF('MASTER data'!$B18="UTC",IF(MONTH('MASTER data'!$E18)=MONTH(E$4),'MASTER data'!$E18,""),"") | F17: =IF(E17='MASTER data'!$E18,'MASTER data'!$H18,"") -> 0 | G17: =IF('MASTER data'!$B18="UTC",IF(MONTH('MASTER data'!$E18)=MONTH(G$4),'MASTER data'!$E18,""),"") | H17: =IF(G17='MASTER data'!$E18,'MASTER data'!$H18,"") -> 0 | I17: =IF('MASTER data'!$B18="UTC",IF(MONTH('MASTER data'!$E18)=MONTH(I$4),'MASTER data'!$E18,""),"") | J17: =IF(I17='MASTER data'!$E18,'MASTER data'!$H18,"") -> 0 | K17: =IF('MASTER data'!$B18="UTC",IF(MONTH('MASTER data'!$E18)=MONTH(K$4),'MASTER data'!$E18,""),"") | L17: =IF(K17='MASTER data'!$E18,'MASTER data'!$H18,"") -> 0 | M17: =IF('MASTER data'!$B18="UTC",IF(MONTH('MASTER data'!$E18)=MONTH(M$4),'MASTER data'!$E18,""),"") | N17: =IF(M17='MASTER data'!$E18,'MASTER data'!$H18,"") -> 0 | O17: =IF('MASTER data'!$B18="UTC",IF(MONTH('MASTER data'!$E18)=MONTH(O$4),'MASTER data'!$E18,""),"") | P17: =IF(O17='MASTER data'!$E18,'MASTER data'!$H18,"") -> 0 | Q17: =IF('MASTER data'!$B18="UTC",IF(MONTH('MASTER data'!$E18)=MONTH(Q$4),'MASTER data'!$E18,""),"") | R17: =IF(Q17='MASTER data'!$E18,'MASTER data'!$H18,"") -> 0 | S17: =IF('MASTER data'!$B18="UTC",IF(MONTH('MASTER data'!$E18)=MONTH(S$4),'MASTER data'!$E18,""),"") | T17: =IF(S17='MASTER data'!$E18,'MASTER data'!$H18,"") -> 0 | U17: =IF('MASTER data'!$B18="UTC",IF(MONTH('MASTER data'!$E18)=MONTH(U$4),'MASTER data'!$E18,""),"") | V17: =IF(U17='MASTER data'!$E18,'MASTER data'!$H18,"") -> 0 | W17: =IF('MASTER data'!$B18="UTC",IF(MONTH('MASTER data'!$E18)=MONTH(W$4),'MASTER data'!$E18,""),"") | X17: =IF(W17='MASTER data'!$E18,'MASTER data'!$H18,"") -> 0 | Y17: =IF('MASTER data'!$B18="UTC",IF(MONTH('MASTER data'!$E18)=MONTH(Y$4),'MASTER data'!$E18,""),"") | Z17: =IF(Y17='MASTER data'!$E18,'MASTER data'!$H18,"") -> 0
C18: =IF('MASTER data'!$B19="UTC",IF(MONTH('MASTER data'!$E19)=MONTH(C$4),'MASTER data'!$E19,""),"") | D18: =IF(C18='MASTER data'!$E19,'MASTER data'!$H19,"") -> 0 | E18: =IF('MASTER data'!$B19="UTC",IF(MONTH('MASTER data'!$E19)=MONTH(E$4),'MASTER data'!$E19,""),"") | F18: =IF(E18='MASTER data'!$E19,'MASTER data'!$H19,"") -> 0 | G18: =IF('MASTER data'!$B19="UTC",IF(MONTH('MASTER data'!$E19)=MONTH(G$4),'MASTER data'!$E19,""),"") | H18: =IF(G18='MASTER data'!$E19,'MASTER data'!$H19,"") -> 0 | I18: =IF('MASTER data'!$B19="UTC",IF(MONTH('MASTER data'!$E19)=MONTH(I$4),'MASTER data'!$E19,""),"") | J18: =IF(I18='MASTER data'!$E19,'MASTER data'!$H19,"") -> 0 | K18: =IF('MASTER data'!$B19="UTC",IF(MONTH('MASTER data'!$E19)=MONTH(K$4),'MASTER data'!$E19,""),"") | L18: =IF(K18='MASTER data'!$E19,'MASTER data'!$H19,"") -> 0 | M18: =IF('MASTER data'!$B19="UTC",IF(MONTH('MASTER data'!$E19)=MONTH(M$4),'MASTER data'!$E19,""),"") | N18: =IF(M18='MASTER data'!$E19,'MASTER data'!$H19,"") -> 0 | O18: =IF('MASTER data'!$B19="UTC",IF(MONTH('MASTER data'!$E19)=MONTH(O$4),'MASTER data'!$E19,""),"") | P18: =IF(O18='MASTER data'!$E19,'MASTER data'!$H19,"") -> 0 | Q18: =IF('MASTER data'!$B19="UTC",IF(MONTH('MASTER data'!$E19)=MONTH(Q$4),'MASTER data'!$E19,""),"") | R18: =IF(Q18='MASTER data'!$E19,'MASTER data'!$H19,"") -> 0 | S18: =IF('MASTER data'!$B19="UTC",IF(MONTH('MASTER data'!$E19)=MONTH(S$4),'MASTER data'!$E19,""),"") | T18: =IF(S18='MASTER data'!$E19,'MASTER data'!$H19,"") -> 0 | U18: =IF('MASTER data'!$B19="UTC",IF(MONTH('MASTER data'!$E19)=MONTH(U$4),'MASTER data'!$E19,""),"") | V18: =IF(U18='MASTER data'!$E19,'MASTER data'!$H19,"") -> 0 | W18: =IF('MASTER data'!$B19="UTC",IF(MONTH('MASTER data'!$E19)=MONTH(W$4),'MASTER data'!$E19,""),"") | X18: =IF(W18='MASTER data'!$E19,'MASTER data'!$H19,"") -> 0 | Y18: =IF('MASTER data'!$B19="UTC",IF(MONTH('MASTER data'!$E19)=MONTH(Y$4),'MASTER data'!$E19,""),"") | Z18: =IF(Y18='MASTER data'!$E19,'MASTER data'!$H19,"") -> 0
... C37: =IF('MASTER data'!$B38="UTC",IF(MONTH('MASTER data'!$E38)=MONTH(C$4),'MASTER data'!$E38,""),"") | D37: =IF(C37='MASTER data'!$E38,'MASTER data'!$H38,"") -> 0 | E37: =IF('MASTER data'!$B38="UTC",IF(MONTH('MASTER data'!$E38)=MONTH(E$4),'MASTER data'!$E38,""),"") | F37: =IF(E37='MASTER data'!$E38,'MASTER data'!$H38,"") -> 0 | G37: =IF('MASTER data'!$B38="UTC",IF(MONTH('MASTER data'!$E38)=MONTH(G$4),'MASTER data'!$E38,""),"") | H37: =IF(G37='MASTER data'!$E38,'MASTER data'!$H38,"") -> 0 | I37: =IF('MASTER data'!$B38="UTC",IF(MONTH('MASTER data'!$E38)=MONTH(I$4),'MASTER data'!$E38,""),"") | J37: =IF(I37='MASTER data'!$E38,'MASTER data'!$H38,"") -> 0 | K37: =IF('MASTER data'!$B38="UTC",IF(MONTH('MASTER data'!$E38)=MONTH(K$4),'MASTER data'!$E38,""),"") | L37: =IF(K37='MASTER data'!$E38,'MASTER data'!$H38,"") -> 0 | M37: =IF('MASTER data'!$B38="UTC",IF(MONTH('MASTER data'!$E38)=MONTH(M$4),'MASTER data'!$E38,""),"") | N37: =IF(M37='MASTER data'!$E38,'MASTER data'!$H38,"") -> 0 | O37: =IF('MASTER data'!$B38="UTC",IF(MONTH('MASTER data'!$E38)=MONTH(O$4),'MASTER data'!$E38,""),"") | P37: =IF(O37='MASTER data'!$E38,'MASTER data'!$H38,"") -> 0 | Q37: =IF('MASTER data'!$B38="UTC",IF(MONTH('MASTER data'!$E38)=MONTH(Q$4),'MASTER data'!$E38,""),"") | R37: =IF(Q37='MASTER data'!$E38,'MASTER data'!$H38,"") -> 0 | S37: =IF('MASTER data'!$B38="UTC",IF(MONTH('MASTER data'!$E38)=MONTH(S$4),'MASTER data'!$E38,""),"") | T37: =IF(S37='MASTER data'!$E38,'MASTER data'!$H38,"") -> 0 | U37: =IF('MASTER data'!$B38="UTC",IF(MONTH('MASTER data'!$E38)=MONTH(U$4),'MASTER data'!$E38,""),"") | V37: =IF(U37='MASTER data'!$E38,'MASTER data'!$H38,"") -> 0 | W37: =IF('MASTER data'!$B38="UTC",IF(MONTH('MASTER data'!$E38)=MONTH(W$4),'MASTER data'!$E38,""),"") | X37: =IF(W37='MASTER data'!$E38,'MASTER data'!$H38,"") -> 0 | Y37: =IF('MASTER data'!$B38="UTC",IF(MONTH('MASTER data'!$E38)=MONTH(Y$4),'MASTER data'!$E38,""),"") | Z37: =IF(Y37='MASTER data'!$E38,'MASTER data'!$H38,"") -> 0

Sheet RIL
A1: PETRON
A2: RELIANCE INDUSTRIES LIMITED -SATNA
C3: 2011 | AA3: 2012
A4: S.NO. | B4: ITEM DECRIPTION | C4: 40544 | E4: 40576 | G4: 40608 | I4: 40640 | K4: 40672 | M4: 40704 | O4: 40736 | Q4: 40768 | S4: 40800 | U4: 40832 | W4: 40864 | Y4: 40896
C5: DATE | D5: UNIT RATE (RS.) | E5: DATE | F5: UNIT RATE (RS.) | G5: DATE | H5: UNIT RATE (RS.) | I5: DATE | J5: UNIT RATE (RS.) | K5: DATE | L5: UNIT RATE (RS.) | M5: DATE | N5: UNIT RATE (RS.) | O5: DATE | P5: UNIT RATE (RS.) | Q5: DATE | R5: UNIT RATE (RS.) | S5: DATE | T5: UNIT RATE (RS.) | U5: DATE | V5: UNIT RATE (RS.) | W5: DATE | X5: UNIT RATE (RS.) | Y5: DATE | Z5: UNIT RATE (RS.)
A6: 1 | B6: =IF('MASTER data'!B7="rilG",'MASTER data'!C7,0) -> 0 | C6: =IF('MASTER data'!$B7="RIL",IF(MONTH('MASTER data'!$E7)=MONTH(C$4),'MASTER data'!$E7,""),"") | D6: =IF(C6='MASTER data'!$E7,'MASTER data'!$G7,"") | E6: =IF('MASTER data'!$B7="RIL",IF(MONTH('MASTER data'!$E7)=MONTH(E$4),'MASTER data'!$E7,""),"") | F6: =IF(E6='MASTER data'!$E7,'MASTER data'!$G7,"") | G6: =IF('MASTER data'!$B7="RIL",IF(MONTH('MASTER data'!$E7)=MONTH(G$4),'MASTER data'!$E7,""),"") | H6: =IF(G6='MASTER data'!$E7,'MASTER data'!$G7,"") | I6: =IF('MASTER data'!$B7="RIL",IF(MONTH('MASTER data'!$E7)=MONTH(I$4),'MASTER data'!$E7,""),"") | J6: =IF(I6='MASTER data'!$E7,'MASTER data'!$G7,"") | K6: =IF('MASTER data'!$B7="RIL",IF(MONTH('MASTER data'!$E7)=MONTH(K$4),'MASTER data'!$E7,""),"") | L6: =IF(K6='MASTER data'!$E7,'MASTER data'!$G7,"") | M6: =IF('MASTER data'!$B7="RIL",IF(MONTH('MASTER data'!$E7)=MONTH(M$4),'MASTER data'!$E7,""),"") | N6: =IF(M6='MASTER data'!$E7,'MASTER data'!$G7,"") | O6: =IF('MASTER data'!$B7="RIL",IF(MONTH('MASTER data'!$E7)=MONTH(O$4),'MASTER data'!$E7,""),"") | P6: =IF(O6='MASTER data'!$E7,'MASTER data'!$G7,"") | Q6: =IF('MASTER data'!$B7="RIL",IF(MONTH('MASTER data'!$E7)=MONTH(Q$4),'MASTER data'!$E7,""),"") | R6: =IF(Q6='MASTER data'!$E7,'MASTER data'!$G7,"") | S6: =IF('MASTER data'!$B7="RIL",IF(MONTH('MASTER data'!$E7)=MONTH(S$4),'MASTER data'!$E7,""),"") | T6: =IF(S6='MASTER data'!$E7,'MASTER data'!$G7,"") | U6: =IF('MASTER data'!$B7="RIL",IF(MONTH('MASTER data'!$E7)=MONTH(U$4),'MASTER data'!$E7,""),"") | V6: =IF(U6='MASTER data'!$E7,'MASTER data'!$G7,"") | W6: =IF('MASTER data'!$B7="RIL",IF(MONTH('MASTER data'!$E7)=MONTH(W$4),'MASTER data'!$E7,""),"") | X6: =IF(W6='MASTER data'!$E7,'MASTER data'!$G7,"") | Y6: =IF('MASTER data'!$B7="RIL",IF(MONTH('MASTER data'!$E7)=MONTH(Y$4),'MASTER data'!$E7,""),"") | Z6: =IF(Y6='MASTER data'!$E7,'MASTER data'!$G7,"")
C7: =IF('MASTER data'!$B8="RIL",IF(MONTH('MASTER data'!$E8)=MONTH(C$4),'MASTER data'!$E8,""),"") | D7: =IF(C7='MASTER data'!$E8,'MASTER data'!$G8,"") | E7: =IF('MASTER data'!$B8="RIL",IF(MONTH('MASTER data'!$E8)=MONTH(E$4),'MASTER data'!$E8,""),"") | F7: =IF(E7='MASTER data'!$E8,'MASTER data'!$G8,"") | G7: =IF('MASTER data'!$B8="RIL",IF(MONTH('MASTER data'!$E8)=MONTH(G$4),'MASTER data'!$E8,""),"") | H7: =IF(G7='MASTER data'!$E8,'MASTER data'!$G8,"") | I7: =IF('MASTER data'!$B8="RIL",IF(MONTH('MASTER data'!$E8)=MONTH(I$4),'MASTER data'!$E8,""),"") | J7: =IF(I7='MASTER data'!$E8,'MASTER data'!$G8,"") | K7: =IF('MASTER data'!$B8="RIL",IF(MONTH('MASTER data'!$E8)=MONTH(K$4),'MASTER data'!$E8,""),"") | L7: =IF(K7='MASTER data'!$E8,'MASTER data'!$G8,"") | M7: =IF('MASTER data'!$B8="RIL",IF(MONTH('MASTER data'!$E8)=MONTH(M$4),'MASTER data'!$E8,""),"") | N7: =IF(M7='MASTER data'!$E8,'MASTER data'!$G8,"") | O7: =IF('MASTER data'!$B8="RIL",IF(MONTH('MASTER data'!$E8)=MONTH(O$4),'MASTER data'!$E8,""),"") | P7: =IF(O7='MASTER data'!$E8,'MASTER data'!$G8,"") | Q7: =IF('MASTER data'!$B8="RIL",IF(MONTH('MASTER data'!$E8)=MONTH(Q$4),'MASTER data'!$E8,""),"") | R7: =IF(Q7='MASTER data'!$E8,'MASTER data'!$G8,"") | S7: =IF('MASTER data'!$B8="RIL",IF(MONTH('MASTER data'!$E8)=MONTH(S$4),'MASTER data'!$E8,""),"") | T7: =IF(S7='MASTER data'!$E8,'MASTER data'!$G8,"") | U7: =IF('MASTER data'!$B8="RIL",IF(MONTH('MASTER data'!$E8)=MONTH(U$4),'MASTER data'!$E8,""),"") | V7: =IF(U7='MASTER data'!$E8,'MASTER data'!$G8,"") | W7: =IF('MASTER data'!$B8="RIL",IF(MONTH('MASTER data'!$E8)=MONTH(W$4),'MASTER data'!$E8,""),"") | X7: =IF(W7='MASTER data'!$E8,'MASTER data'!$G8,"") | Y7: =IF('MASTER data'!$B8="RIL",IF(MONTH('MASTER data'!$E8)=MONTH(Y$4),'MASTER data'!$E8,""),"") | Z7: =IF(Y7='MASTER data'!$E8,'MASTER data'!$G8,"")
C8: =IF('MASTER data'!$B9="RIL",IF(MONTH('MASTER data'!$E9)=MONTH(C$4),'MASTER data'!$E9,""),"") | D8: =IF(C8='MASTER data'!$E9,'MASTER data'!$G9,"") | E8: =IF('MASTER data'!$B9="RIL",IF(MONTH('MASTER data'!$E9)=MONTH(E$4),'MASTER data'!$E9,""),"") | F8: =IF(E8='MASTER data'!$E9,'MASTER data'!$G9,"") | G8: =IF('MASTER data'!$B9="RIL",IF(MONTH('MASTER data'!$E9)=MONTH(G$4),'MASTER data'!$E9,""),"") | H8: =IF(G8='MASTER data'!$E9,'MASTER data'!$G9,"") | I8: =IF('MASTER data'!$B9="RIL",IF(MONTH('MASTER data'!$E9)=MONTH(I$4),'MASTER data'!$E9,""),"") | J8: =IF(I8='MASTER data'!$E9,'MASTER data'!$G9,"") | K8: =IF('MASTER data'!$B9="RIL",IF(MONTH('MASTER data'!$E9)=MONTH(K$4),'MASTER data'!$E9,""),"") | L8: =IF(K8='MASTER data'!$E9,'MASTER data'!$G9,"") | M8: =IF('MASTER data'!$B9="RIL",IF(MONTH('MASTER data'!$E9)=MONTH(M$4),'MASTER data'!$E9,""),"") | N8: =IF(M8='MASTER data'!$E9,'MASTER data'!$G9,"") | O8: =IF('MASTER data'!$B9="RIL",IF(MONTH('MASTER data'!$E9)=MONTH(O$4),'MASTER data'!$E9,""),"") | P8: =IF(O8='MASTER data'!$E9,'MASTER data'!$G9,"") | Q8: =IF('MASTER data'!$B9="RIL",IF(MONTH('MASTER data'!$E9)=MONTH(Q$4),'MASTER data'!$E9,""),"") | R8: =IF(Q8='MASTER data'!$E9,'MASTER data'!$G9,"") | S8: =IF('MASTER data'!$B9="RIL",IF(MONTH('MASTER data'!$E9)=MONTH(S$4),'MASTER data'!$E9,""),"") | T8: =IF(S8='MASTER data'!$E9,'MASTER data'!$G9,"") | U8: =IF('MASTER data'!$B9="RIL",IF(MONTH('MASTER data'!$E9)=MONTH(U$4),'MASTER data'!$E9,""),"") | V8: =IF(U8='MASTER data'!$E9,'MASTER data'!$G9,"") | W8: =IF('MASTER data'!$B9="RIL",IF(MONTH('MASTER data'!$E9)=MONTH(W$4),'MASTER data'!$E9,""),"") | X8: =IF(W8='MASTER data'!$E9,'MASTER data'!$G9,"") | Y8: =IF('MASTER data'!$B9="RIL",IF(MONTH('MASTER data'!$E9)=MONTH(Y$4),'MASTER data'!$E9,""),"") | Z8: =IF(Y8='MASTER data'!$E9,'MASTER data'!$G9,"")
C9: =IF('MASTER data'!$B10="RIL",IF(MONTH('MASTER data'!$E10)=MONTH(C$4),'MASTER data'!$E10,""),"") | D9: =IF(C9='MASTER data'!$E10,'MASTER data'!$G10,"") | E9: =IF('MASTER data'!$B10="RIL",IF(MONTH('MASTER data'!$E10)=MONTH(E$4),'MASTER data'!$E10,""),"") -> 40941 | F9: =IF(E9='MASTER data'!$E10,'MASTER data'!$G10,"") -> 0 | G9: =IF('MASTER data'!$B10="RIL",IF(MONTH('MASTER data'!$E10)=MONTH(G$4),'MASTER data'!$E10,""),"") | H9: =IF(G9='MASTER data'!$E10,'MASTER data'!$G10,"") | I9: =IF('MASTER data'!$B10="RIL",IF(MONTH('MASTER data'!$E10)=MONTH(I$4),'MASTER data'!$E10,""),"") | J9: =IF(I9='MASTER data'!$E10,'MASTER data'!$G10,"") | K9: =IF('MASTER data'!$B10="RIL",IF(MONTH('MASTER data'!$E10)=MONTH(K$4),'MASTER data'!$E10,""),"") | L9: =IF(K9='MASTER data'!$E10,'MASTER data'!$G10,"") | M9: =IF('MASTER data'!$B10="RIL",IF(MONTH('MASTER data'!$E10)=MONTH(M$4),'MASTER data'!$E10,""),"") | N9: =IF(M9='MASTER data'!$E10,'MASTER data'!$G10,"") | O9: =IF('MASTER data'!$B10="RIL",IF(MONTH('MASTER data'!$E10)=MONTH(O$4),'MASTER data'!$E10,""),"") | P9: =IF(O9='MASTER data'!$E10,'MASTER data'!$G10,"") | Q9: =IF('MASTER data'!$B10="RIL",IF(MONTH('MASTER data'!$E10)=MONTH(Q$4),'MASTER data'!$E10,""),"") | R9: =IF(Q9='MASTER data'!$E10,'MASTER data'!$G10,"") | S9: =IF('MASTER data'!$B10="RIL",IF(MONTH('MASTER data'!$E10)=MONTH(S$4),'MASTER data'!$E10,""),"") | T9: =IF(S9='MASTER data'!$E10,'MASTER data'!$G10,"") | U9: =IF('MASTER data'!$B10="RIL",IF(MONTH('MASTER data'!$E10)=MONTH(U$4),'MASTER data'!$E10,""),"") | V9: =IF(U9='MASTER data'!$E10,'MASTER data'!$G10,"") | W9: =IF('MASTER data'!$B10="RIL",IF(MONTH('MASTER data'!$E10)=MONTH(W$4),'MASTER data'!$E10,""),"") | X9: =IF(W9='MASTER data'!$E10,'MASTER data'!$G10,"") | Y9: =IF('MASTER data'!$B10="RIL",IF(MONTH('MASTER data'!$E10)=MONTH(Y$4),'MASTER data'!$E10,""),"") | Z9: =IF(Y9='MASTER data'!$E10,'MASTER data'!$G10,"")
C10: =IF('MASTER data'!$B11="RIL",IF(MONTH('MASTER data'!$E11)=MONTH(C$4),'MASTER data'!$E11,""),"") | D10: =IF(C10='MASTER data'!$E11,'MASTER data'!$G11,"") | E10: =IF('MASTER data'!$B11="RIL",IF(MONTH('MASTER data'!$E11)=MONTH(E$4),'MASTER data'!$E11,""),"") | F10: =IF(E10='MASTER data'!$E11,'MASTER data'!$G11,"") | G10: =IF('MASTER data'!$B11="RIL",IF(MONTH('MASTER data'!$E11)=MONTH(G$4),'MASTER data'!$E11,""),"") -> 40970 | H10: =IF(G10='MASTER data'!$E11,'MASTER data'!$G11,"") -> 0 | I10: =IF('MASTER data'!$B11="RIL",IF(MONTH('MASTER data'!$E11)=MONTH(I$4),'MASTER data'!$E11,""),"") | J10: =IF(I10='MASTER data'!$E11,'MASTER data'!$G11,"") | K10: =IF('MASTER data'!$B11="RIL",IF(MONTH('MASTER data'!$E11)=MONTH(K$4),'MASTER data'!$E11,""),"") | L10: =IF(K10='MASTER data'!$E11,'MASTER data'!$G11,"") | M10: =IF('MASTER data'!$B11="RIL",IF(MONTH('MASTER data'!$E11)=MONTH(M$4),'MASTER data'!$E11,""),"") | N10: =IF(M10='MASTER data'!$E11,'MASTER data'!$G11,"") | O10: =IF('MASTER data'!$B11="RIL",IF(MONTH('MASTER data'!$E11)=MONTH(O$4),'MASTER data'!$E11,""),"") | P10: =IF(O10='MASTER data'!$E11,'MASTER data'!$G11,"") | Q10: =IF('MASTER data'!$B11="RIL",IF(MONTH('MASTER data'!$E11)=MONTH(Q$4),'MASTER data'!$E11,""),"") | R10: =IF(Q10='MASTER data'!$E11,'MASTER data'!$G11,"") | S10: =IF('MASTER data'!$B11="RIL",IF(MONTH('MASTER data'!$E11)=MONTH(S$4),'MASTER data'!$E11,""),"") | T10: =IF(S10='MASTER data'!$E11,'MASTER data'!$G11,"") | U10: =IF('MASTER data'!$B11="RIL",IF(MONTH('MASTER data'!$E11)=MONTH(U$4),'MASTER data'!$E11,""),"") | V10: =IF(U10='MASTER data'!$E11,'MASTER data'!$G11,"") | W10: =IF('MASTER data'!$B11="RIL",IF(MONTH('MASTER data'!$E11)=MONTH(W$4),'MASTER data'!$E11,""),"") | X10: =IF(W10='MASTER data'!$E11,'MASTER data'!$G11,"") | Y10: =IF('MASTER data'!$B11="RIL",IF(MONTH('MASTER data'!$E11)=MONTH(Y$4),'MASTER data'!$E11,""),"") | Z10: =IF(Y10='MASTER data'!$E11,'MASTER data'!$G11,"")
C11: =IF('MASTER data'!$B12="RIL",IF(MONTH('MASTER data'!$E12)=MONTH(C$4),'MASTER data'!$E12,""),"") | D11: =IF(C11='MASTER data'!$E12,'MASTER data'!$G12,"") | E11: =IF('MASTER data'!$B12="RIL",IF(MONTH('MASTER data'!$E12)=MONTH(E$4),'MASTER data'!$E12,""),"") | F11: =IF(E11='MASTER data'!$E12,'MASTER data'!$G12,"") | G11: =IF('MASTER data'!$B12="RIL",IF(MONTH('MASTER data'!$E12)=MONTH(G$4),'MASTER data'!$E12,""),"") | H11: =IF(G11='MASTER data'!$E12,'MASTER data'!$G12,"") | I11: =IF('MASTER data'!$B12="RIL",IF(MONTH('MASTER data'!$E12)=MONTH(I$4),'MASTER data'!$E12,""),"") | J11: =IF(I11='MASTER data'!$E12,'MASTER data'!$G12,"") | K11: =IF('MASTER data'!$B12="RIL",IF(MONTH('MASTER data'!$E12)=MONTH(K$4),'MASTER data'!$E12,""),"") | L11: =IF(K11='MASTER data'!$E12,'MASTER data'!$G12,"") | M11: =IF('MASTER data'!$B12="RIL",IF(MONTH('MASTER data'!$E12)=MONTH(M$4),'MASTER data'!$E12,""),"") | N11: =IF(M11='MASTER data'!$E12,'MASTER data'!$G12,"") | O11: =IF('MASTER data'!$B12="RIL",IF(MONTH('MASTER data'!$E12)=MONTH(O$4),'MASTER data'!$E12,""),"") | P11: =IF(O11='MASTER data'!$E12,'MASTER data'!$G12,"") | Q11: =IF('MASTER data'!$B12="RIL",IF(MONTH('MASTER data'!$E12)=MONTH(Q$4),'MASTER data'!$E12,""),"") | R11: =IF(Q11='MASTER data'!$E12,'MASTER data'!$G12,"") | S11: =IF('MASTER data'!$B12="RIL",IF(MONTH('MASTER data'!$E12)=MONTH(S$4),'MASTER data'!$E12,""),"") | T11: =IF(S11='MASTER data'!$E12,'MASTER data'!$G12,"") | U11: =IF('MASTER data'!$B12="RIL",IF(MONTH('MASTER data'!$E12)=MONTH(U$4),'MASTER data'!$E12,""),"") | V11: =IF(U11='MASTER data'!$E12,'MASTER data'!$G12,"") | W11: =IF('MASTER data'!$B12="RIL",IF(MONTH('MASTER data'!$E12)=MONTH(W$4),'MASTER data'!$E12,""),"") | X11: =IF(W11='MASTER data'!$E12,'MASTER data'!$G12,"") | Y11: =IF('MASTER data'!$B12="RIL",IF(MONTH('MASTER data'!$E12)=MONTH(Y$4),'MASTER data'!$E12,""),"") | Z11: =IF(Y11='MASTER data'!$E12,'MASTER data'!$G12,"")
C12: =IF('MASTER data'!$B13="RIL",IF(MONTH('MASTER data'!$E13)=MONTH(C$4),'MASTER data'!$E13,""),"") | D12: =IF(C12='MASTER data'!$E13,'MASTER data'!$G13,"") -> 0 | E12: =IF('MASTER data'!$B13="RIL",IF(MONTH('MASTER data'!$E13)=MONTH(E$4),'MASTER data'!$E13,""),"") | F12: =IF(E12='MASTER data'!$E13,'MASTER data'!$G13,"") -> 0 | G12: =IF('MASTER data'!$B13="RIL",IF(MONTH('MASTER data'!$E13)=MONTH(G$4),'MASTER data'!$E13,""),"") | H12: =IF(G12='MASTER data'!$E13,'MASTER data'!$G13,"") -> 0 | I12: =IF('MASTER data'!$B13="RIL",IF(MONTH('MASTER data'!$E13)=MONTH(I$4),'MASTER data'!$E13,""),"") | J12: =IF(I12='MASTER data'!$E13,'MASTER data'!$G13,"") -> 0 | K12: =IF('MASTER data'!$B13="RIL",IF(MONTH('MASTER data'!$E13)=MONTH(K$4),'MASTER data'!$E13,""),"") | L12: =IF(K12='MASTER data'!$E13,'MASTER data'!$G13,"") -> 0 | M12: =IF('MASTER data'!$B13="RIL",IF(MONTH('MASTER data'!$E13)=MONTH(M$4),'MASTER data'!$E13,""),"") | N12: =IF(M12='MASTER data'!$E13,'MASTER data'!$G13,"") -> 0 | O12: =IF('MASTER data'!$B13="RIL",IF(MONTH('MASTER data'!$E13)=MONTH(O$4),'MASTER data'!$E13,""),"") | P12: =IF(O12='MASTER data'!$E13,'MASTER data'!$G13,"") -> 0 | Q12: =IF('MASTER data'!$B13="RIL",IF(MONTH('MASTER data'!$E13)=MONTH(Q$4),'MASTER data'!$E13,""),"") | R12: =IF(Q12='MASTER data'!$E13,'MASTER data'!$G13,"") -> 0 | S12: =IF('MASTER data'!$B13="RIL",IF(MONTH('MASTER data'!$E13)=MONTH(S$4),'MASTER data'!$E13,""),"") | T12: =IF(S12='MASTER data'!$E13,'MASTER data'!$G13,"") -> 0 | U12: =IF('MASTER data'!$B13="RIL",IF(MONTH('MASTER data'!$E13)=MONTH(U$4),'MASTER data'!$E13,""),"") | V12: =IF(U12='MASTER data'!$E13,'MASTER data'!$G13,"") -> 0 | W12: =IF('MASTER data'!$B13="RIL",IF(MONTH('MASTER data'!$E13)=MONTH(W$4),'MASTER data'!$E13,""),"") | X12: =IF(W12='MASTER data'!$E13,'MASTER data'!$G13,"") -> 0 | Y12: =IF('MASTER data'!$B13="RIL",IF(MONTH('MASTER data'!$E13)=MONTH(Y$4),'MASTER data'!$E13,""),"") | Z12: =IF(Y12='MASTER data'!$E13,'MASTER data'!$G13,"") -> 0
C13: =IF('MASTER data'!$B14="RIL",IF(MONTH('MASTER data'!$E14)=MONTH(C$4),'MASTER data'!$E14,""),"") | D13: =IF(C13='MASTER data'!$E14,'MASTER data'!$G14,"") -> 0 | E13: =IF('MASTER data'!$B14="RIL",IF(MONTH('MASTER data'!$E14)=MONTH(E$4),'MASTER data'!$E14,""),"") | F13: =IF(E13='MASTER data'!$E14,'MASTER data'!$G14,"") -> 0 | G13: =IF('MASTER data'!$B14="RIL",IF(MONTH('MASTER data'!$E14)=MONTH(G$4),'MASTER data'!$E14,""),"") | H13: =IF(G13='MASTER data'!$E14,'MASTER data'!$G14,"") -> 0 | I13: =IF('MASTER data'!$B14="RIL",IF(MONTH('MASTER data'!$E14)=MONTH(I$4),'MASTER data'!$E14,""),"") | J13: =IF(I13='MASTER data'!$E14,'MASTER data'!$G14,"") -> 0 | K13: =IF('MASTER data'!$B14="RIL",IF(MONTH('MASTER data'!$E14)=MONTH(K$4),'MASTER data'!$E14,""),"") | L13: =IF(K13='MASTER data'!$E14,'MASTER data'!$G14,"") -> 0 | M13: =IF('MASTER data'!$B14="RIL",IF(MONTH('MASTER data'!$E14)=MONTH(M$4),'MASTER data'!$E14,""),"") | N13: =IF(M13='MASTER data'!$E14,'MASTER data'!$G14,"") -> 0 | O13: =IF('MASTER data'!$B14="RIL",IF(MONTH('MASTER data'!$E14)=MONTH(O$4),'MASTER data'!$E14,""),"") | P13: =IF(O13='MASTER data'!$E14,'MASTER data'!$G14,"") -> 0 | Q13: =IF('MASTER data'!$B14="RIL",IF(MONTH('MASTER data'!$E14)=MONTH(Q$4),'MASTER data'!$E14,""),"") | R13: =IF(Q13='MASTER data'!$E14,'MASTER data'!$G14,"") -> 0 | S13: =IF('MASTER data'!$B14="RIL",IF(MONTH('MASTER data'!$E14)=MONTH(S$4),'MASTER data'!$E14,""),"") | T13: =IF(S13='MASTER data'!$E14,'MASTER data'!$G14,"") -> 0 | U13: =IF('MASTER data'!$B14="RIL",IF(MONTH('MASTER data'!$E14)=MONTH(U$4),'MASTER data'!$E14,""),"") | V13: =IF(U13='MASTER data'!$E14,'MASTER data'!$G14,"") -> 0 | W13: =IF('MASTER data'!$B14="RIL",IF(MONTH('MASTER data'!$E14)=MONTH(W$4),'MASTER data'!$E14,""),"") | X13: =IF(W13='MASTER data'!$E14,'MASTER data'!$G14,"") -> 0 | Y13: =IF('MASTER data'!$B14="RIL",IF(MONTH('MASTER data'!$E14)=MONTH(Y$4),'MASTER data'!$E14,""),"") | Z13: =IF(Y13='MASTER data'!$E14,'MASTER data'!$G14,"") -> 0
C14: =IF('MASTER data'!$B15="RIL",IF(MONTH('MASTER data'!$E15)=MONTH(C$4),'MASTER data'!$E15,""),"") | D14: =IF(C14='MASTER data'!$E15,'MASTER data'!$G15,"") -> 0 | E14: =IF('MASTER data'!$B15="RIL",IF(MONTH('MASTER data'!$E15)=MONTH(E$4),'MASTER data'!$E15,""),"") | F14: =IF(E14='MASTER data'!$E15,'MASTER data'!$G15,"") -> 0 | G14: =IF('MASTER data'!$B15="RIL",IF(MONTH('MASTER data'!$E15)=MONTH(G$4),'MASTER data'!$E15,""),"") | H14: =IF(G14='MASTER data'!$E15,'MASTER data'!$G15,"") -> 0 | I14: =IF('MASTER data'!$B15="RIL",IF(MONTH('MASTER data'!$E15)=MONTH(I$4),'MASTER data'!$E15,""),"") | J14: =IF(I14='MASTER data'!$E15,'MASTER data'!$G15,"") -> 0 | K14: =IF('MASTER data'!$B15="RIL",IF(MONTH('MASTER data'!$E15)=MONTH(K$4),'MASTER data'!$E15,""),"") | L14: =IF(K14='MASTER data'!$E15,'MASTER data'!$G15,"") -> 0 | M14: =IF('MASTER data'!$B15="RIL",IF(MONTH('MASTER data'!$E15)=MONTH(M$4),'MASTER data'!$E15,""),"") | N14: =IF(M14='MASTER data'!$E15,'MASTER data'!$G15,"") -> 0 | O14: =IF('MASTER data'!$B15="RIL",IF(MONTH('MASTER data'!$E15)=MONTH(O$4),'MASTER data'!$E15,""),"") | P14: =IF(O14='MASTER data'!$E15,'MASTER data'!$G15,"") -> 0 | Q14: =IF('MASTER data'!$B15="RIL",IF(MONTH('MASTER data'!$E15)=MONTH(Q$4),'MASTER data'!$E15,""),"") | R14: =IF(Q14='MASTER data'!$E15,'MASTER data'!$G15,"") -> 0 | S14: =IF('MASTER data'!$B15="RIL",IF(MONTH('MASTER data'!$E15)=MONTH(S$4),'MASTER data'!$E15,""),"") | T14: =IF(S14='MASTER data'!$E15,'MASTER data'!$G15,"") -> 0 | U14: =IF('MASTER data'!$B15="RIL",IF(MONTH('MASTER data'!$E15)=MONTH(U$4),'MASTER data'!$E15,""),"") | V14: =IF(U14='MASTER data'!$E15,'MASTER data'!$G15,"") -> 0 | W14: =IF('MASTER data'!$B15="RIL",IF(MONTH('MASTER data'!$E15)=MONTH(W$4),'MASTER data'!$E15,""),"") | X14: =IF(W14='MASTER data'!$E15,'MASTER data'!$G15,"") -> 0 | Y14: =IF('MASTER data'!$B15="RIL",IF(MONTH('MASTER data'!$E15)=MONTH(Y$4),'MASTER data'!$E15,""),"") | Z14: =IF(Y14='MASTER data'!$E15,'MASTER data'!$G15,"") -> 0
C15: =IF('MASTER data'!$B16="RIL",IF(MONTH('MASTER data'!$E16)=MONTH(C$4),'MASTER data'!$E16,""),"") | D15: =IF(C15='MASTER data'!$E16,'MASTER data'!$G16,"") -> 0 | E15: =IF('MASTER data'!$B16="RIL",IF(MONTH('MASTER data'!$E16)=MONTH(E$4),'MASTER data'!$E16,""),"") | F15: =IF(E15='MASTER data'!$E16,'MASTER data'!$G16,"") -> 0 | G15: =IF('MASTER data'!$B16="RIL",IF(MONTH('MASTER data'!$E16)=MONTH(G$4),'MASTER data'!$E16,""),"") | H15: =IF(G15='MASTER data'!$E16,'MASTER data'!$G16,"") -> 0 | I15: =IF('MASTER data'!$B16="RIL",IF(MONTH('MASTER data'!$E16)=MONTH(I$4),'MASTER data'!$E16,""),"") | J15: =IF(I15='MASTER data'!$E16,'MASTER data'!$G16,"") -> 0 | K15: =IF('MASTER data'!$B16="RIL",IF(MONTH('MASTER data'!$E16)=MONTH(K$4),'MASTER data'!$E16,""),"") | L15: =IF(K15='MASTER data'!$E16,'MASTER data'!$G16,"") -> 0 | M15: =IF('MASTER data'!$B16="RIL",IF(MONTH('MASTER data'!$E16)=MONTH(M$4),'MASTER data'!$E16,""),"") | N15: =IF(M15='MASTER data'!$E16,'MASTER data'!$G16,"") -> 0 | O15: =IF('MASTER data'!$B16="RIL",IF(MONTH('MASTER data'!$E16)=MONTH(O$4),'MASTER data'!$E16,""),"") | P15: =IF(O15='MASTER data'!$E16,'MASTER data'!$G16,"") -> 0 | Q15: =IF('MASTER data'!$B16="RIL",IF(MONTH('MASTER data'!$E16)=MONTH(Q$4),'MASTER data'!$E16,""),"") | R15: =IF(Q15='MASTER data'!$E16,'MASTER data'!$G16,"") -> 0 | S15: =IF('MASTER data'!$B16="RIL",IF(MONTH('MASTER data'!$E16)=MONTH(S$4),'MASTER data'!$E16,""),"") | T15: =IF(S15='MASTER data'!$E16,'MASTER data'!$G16,"") -> 0 | U15: =IF('MASTER data'!$B16="RIL",IF(MONTH('MASTER data'!$E16)=MONTH(U$4),'MASTER data'!$E16,""),"") | V15: =IF(U15='MASTER data'!$E16,'MASTER data'!$G16,"") -> 0 | W15: =IF('MASTER data'!$B16="RIL",IF(MONTH('MASTER data'!$E16)=MONTH(W$4),'MASTER data'!$E16,""),"") | X15: =IF(W15='MASTER data'!$E16,'MASTER data'!$G16,"") -> 0 | Y15: =IF('MASTER data'!$B16="RIL",IF(MONTH('MASTER data'!$E16)=MONTH(Y$4),'MASTER data'!$E16,""),"") | Z15: =IF(Y15='MASTER data'!$E16,'MASTER data'!$G16,"") -> 0
C16: =IF('MASTER data'!$B17="RIL",IF(MONTH('MASTER data'!$E17)=MONTH(C$4),'MASTER data'!$E17,""),"") | D16: =IF(C16='MASTER data'!$E17,'MASTER data'!$G17,"") -> 0 | E16: =IF('MASTER data'!$B17="RIL",IF(MONTH('MASTER data'!$E17)=MONTH(E$4),'MASTER data'!$E17,""),"") | F16: =IF(E16='MASTER data'!$E17,'MASTER data'!$G17,"") -> 0 | G16: =IF('MASTER data'!$B17="RIL",IF(MONTH('MASTER data'!$E17)=MONTH(G$4),'MASTER data'!$E17,""),"") | H16: =IF(G16='MASTER data'!$E17,'MASTER data'!$G17,"") -> 0 | I16: =IF('MASTER data'!$B17="RIL",IF(MONTH('MASTER data'!$E17)=MONTH(I$4),'MASTER data'!$E17,""),"") | J16: =IF(I16='MASTER data'!$E17,'MASTER data'!$G17,"") -> 0 | K16: =IF('MASTER data'!$B17="RIL",IF(MONTH('MASTER data'!$E17)=MONTH(K$4),'MASTER data'!$E17,""),"") | L16: =IF(K16='MASTER data'!$E17,'MASTER data'!$G17,"") -> 0 | M16: =IF('MASTER data'!$B17="RIL",IF(MONTH('MASTER data'!$E17)=MONTH(M$4),'MASTER data'!$E17,""),"") | N16: =IF(M16='MASTER data'!$E17,'MASTER data'!$G17,"") -> 0 | O16: =IF('MASTER data'!$B17="RIL",IF(MONTH('MASTER data'!$E17)=MONTH(O$4),'MASTER data'!$E17,""),"") | P16: =IF(O16='MASTER data'!$E17,'MASTER data'!$G17,"") -> 0 | Q16: =IF('MASTER data'!$B17="RIL",IF(MONTH('MASTER data'!$E17)=MONTH(Q$4),'MASTER data'!$E17,""),"") | R16: =IF(Q16='MASTER data'!$E17,'MASTER data'!$G17,"") -> 0 | S16: =IF('MASTER data'!$B17="RIL",IF(MONTH('MASTER data'!$E17)=MONTH(S$4),'MASTER data'!$E17,""),"") | T16: =IF(S16='MASTER data'!$E17,'MASTER data'!$G17,"") -> 0 | U16: =IF('MASTER data'!$B17="RIL",IF(MONTH('MASTER data'!$E17)=MONTH(U$4),'MASTER data'!$E17,""),"") | V16: =IF(U16='MASTER data'!$E17,'MASTER data'!$G17,"") -> 0 | W16: =IF('MASTER data'!$B17="RIL",IF(MONTH('MASTER data'!$E17)=MONTH(W$4),'MASTER data'!$E17,""),"") | X16: =IF(W16='MASTER data'!$E17,'MASTER data'!$G17,"") -> 0 | Y16: =IF('MASTER data'!$B17="RIL",IF(MONTH('MASTER data'!$E17)=MONTH(Y$4),'MASTER data'!$E17,""),"") | Z16: =IF(Y16='MASTER data'!$E17,'MASTER data'!$G17,"") -> 0
C17: =IF('MASTER data'!$B18="RIL",IF(MONTH('MASTER data'!$E18)=MONTH(C$4),'MASTER data'!$E18,""),"") | D17: =IF(C17='MASTER data'!$E18,'MASTER data'!$G18,"") -> 0 | E17: =IF('MASTER data'!$B18="RIL",IF(MONTH('MASTER data'!$E18)=MONTH(E$4),'MASTER data'!$E18,""),"") | F17: =IF(E17='MASTER data'!$E18,'MASTER data'!$G18,"") -> 0 | G17: =IF('MASTER data'!$B18="RIL",IF(MONTH('MASTER data'!$E18)=MONTH(G$4),'MASTER data'!$E18,""),"") | H17: =IF(G17='MASTER data'!$E18,'MASTER data'!$G18,"") -> 0 | I17: =IF('MASTER data'!$B18="RIL",IF(MONTH('MASTER data'!$E18)=MONTH(I$4),'MASTER data'!$E18,""),"") | J17: =IF(I17='MASTER data'!$E18,'MASTER data'!$G18,"") -> 0 | K17: =IF('MASTER data'!$B18="RIL",IF(MONTH('MASTER data'!$E18)=MONTH(K$4),'MASTER data'!$E18,""),"") | L17: =IF(K17='MASTER data'!$E18,'MASTER data'!$G18,"") -> 0 | M17: =IF('MASTER data'!$B18="RIL",IF(MONTH('MASTER data'!$E18)=MONTH(M$4),'MASTER data'!$E18,""),"") | N17: =IF(M17='MASTER data'!$E18,'MASTER data'!$G18,"") -> 0 | O17: =IF('MASTER data'!$B18="RIL",IF(MONTH('MASTER data'!$E18)=MONTH(O$4),'MASTER data'!$E18,""),"") | P17: =IF(O17='MASTER data'!$E18,'MASTER data'!$G18,"") -> 0 | Q17: =IF('MASTER data'!$B18="RIL",IF(MONTH('MASTER data'!$E18)=MONTH(Q$4),'MASTER data'!$E18,""),"") | R17: =IF(Q17='MASTER data'!$E18,'MASTER data'!$G18,"") -> 0 | S17: =IF('MASTER data'!$B18="RIL",IF(MONTH('MASTER data'!$E18)=MONTH(S$4),'MASTER data'!$E18,""),"") | T17: =IF(S17='MASTER data'!$E18,'MASTER data'!$G18,"") -> 0 | U17: =IF('MASTER data'!$B18="RIL",IF(MONTH('MASTER data'!$E18)=MONTH(U$4),'MASTER data'!$E18,""),"") | V17: =IF(U17='MASTER data'!$E18,'MASTER data'!$G18,"") -> 0 | W17: =IF('MASTER data'!$B18="RIL",IF(MONTH('MASTER data'!$E18)=MONTH(W$4),'MASTER data'!$E18,""),"") | X17: =IF(W17='MASTER data'!$E18,'MASTER data'!$G18,"") -> 0 | Y17: =IF('MASTER data'!$B18="RIL",IF(MONTH('MASTER data'!$E18)=MONTH(Y$4),'MASTER data'!$E18,""),"") | Z17: =IF(Y17='MASTER data'!$E18,'MASTER data'!$G18,"") -> 0
C18: =IF('MASTER data'!$B19="RIL",IF(MONTH('MASTER data'!$E19)=MONTH(C$4),'MASTER data'!$E19,""),"") | D18: =IF(C18='MASTER data'!$E19,'MASTER data'!$G19,"") -> 0 | E18: =IF('MASTER data'!$B19="RIL",IF(MONTH('MASTER data'!$E19)=MONTH(E$4),'MASTER data'!$E19,""),"") | F18: =IF(E18='MASTER data'!$E19,'MASTER data'!$G19,"") -> 0 | G18: =IF('MASTER data'!$B19="RIL",IF(MONTH('MASTER data'!$E19)=MONTH(G$4),'MASTER data'!$E19,""),"") | H18: =IF(G18='MASTER data'!$E19,'MASTER data'!$G19,"") -> 0 | I18: =IF('MASTER data'!$B19="RIL",IF(MONTH('MASTER data'!$E19)=MONTH(I$4),'MASTER data'!$E19,""),"") | J18: =IF(I18='MASTER data'!$E19,'MASTER data'!$G19,"") -> 0 | K18: =IF('MASTER data'!$B19="RIL",IF(MONTH('MASTER data'!$E19)=MONTH(K$4),'MASTER data'!$E19,""),"") | L18: =IF(K18='MASTER data'!$E19,'MASTER data'!$G19,"") -> 0 | M18: =IF('MASTER data'!$B19="RIL",IF(MONTH('MASTER data'!$E19)=MONTH(M$4),'MASTER data'!$E19,""),"") | N18: =IF(M18='MASTER data'!$E19,'MASTER data'!$G19,"") -> 0 | O18: =IF('MASTER data'!$B19="RIL",IF(MONTH('MASTER data'!$E19)=MONTH(O$4),'MASTER data'!$E19,""),"") | P18: =IF(O18='MASTER data'!$E19,'MASTER data'!$G19,"") -> 0 | Q18: =IF('MASTER data'!$B19="RIL",IF(MONTH('MASTER data'!$E19)=MONTH(Q$4),'MASTER data'!$E19,""),"") | R18: =IF(Q18='MASTER data'!$E19,'MASTER data'!$G19,"") -> 0 | S18: =IF('MASTER data'!$B19="RIL",IF(MONTH('MASTER data'!$E19)=MONTH(S$4),'MASTER data'!$E19,""),"") | T18: =IF(S18='MASTER data'!$E19,'MASTER data'!$G19,"") -> 0 | U18: =IF('MASTER data'!$B19="RIL",IF(MONTH('MASTER data'!$E19)=MONTH(U$4),'MASTER data'!$E19,""),"") | V18: =IF(U18='MASTER data'!$E19,'MASTER data'!$G19,"") -> 0 | W18: =IF('MASTER data'!$B19="RIL",IF(MONTH('MASTER data'!$E19)=MONTH(W$4),'MASTER data'!$E19,""),"") | X18: =IF(W18='MASTER data'!$E19,'MASTER data'!$G19,"") -> 0 | Y18: =IF('MASTER data'!$B19="RIL",IF(MONTH('MASTER data'!$E19)=MONTH(Y$4),'MASTER data'!$E19,""),"") | Z18: =IF(Y18='MASTER data'!$E19,'MASTER data'!$G19,"") -> 0
... C37: =IF('MASTER data'!$B38="RIL",IF(MONTH('MASTER data'!$E38)=MONTH(C$4),'MASTER data'!$E38,""),"") | D37: =IF(C37='MASTER data'!$E38,'MASTER data'!$G38,"") -> 0 | E37: =IF('MASTER data'!$B38="RIL",IF(MONTH('MASTER data'!$E38)=MONTH(E$4),'MASTER data'!$E38,""),"") | F37: =IF(E37='MASTER data'!$E38,'MASTER data'!$G38,"") -> 0 | G37: =IF('MASTER data'!$B38="RIL",IF(MONTH('MASTER data'!$E38)=MONTH(G$4),'MASTER data'!$E38,""),"") | H37: =IF(G37='MASTER data'!$E38,'MASTER data'!$G38,"") -> 0 | I37: =IF('MASTER data'!$B38="RIL",IF(MONTH('MASTER data'!$E38)=MONTH(I$4),'MASTER data'!$E38,""),"") | J37: =IF(I37='MASTER data'!$E38,'MASTER data'!$G38,"") -> 0 | K37: =IF('MASTER data'!$B38="RIL",IF(MONTH('MASTER data'!$E38)=MONTH(K$4),'MASTER data'!$E38,""),"") | L37: =IF(K37='MASTER data'!$E38,'MASTER data'!$G38,"") -> 0 | M37: =IF('MASTER data'!$B38="RIL",IF(MONTH('MASTER data'!$E38)=MONTH(M$4),'MASTER data'!$E38,""),"") | N37: =IF(M37='MASTER data'!$E38,'MASTER data'!$G38,"") -> 0 | O37: =IF('MASTER data'!$B38="RIL",IF(MONTH('MASTER data'!$E38)=MONTH(O$4),'MASTER data'!$E38,""),"") | P37: =IF(O37='MASTER data'!$E38,'MASTER data'!$G38,"") -> 0 | Q37: =IF('MASTER data'!$B38="RIL",IF(MONTH('MASTER data'!$E38)=MONTH(Q$4),'MASTER data'!$E38,""),"") | R37: =IF(Q37='MASTER data'!$E38,'MASTER data'!$G38,"") -> 0 | S37: =IF('MASTER data'!$B38="RIL",IF(MONTH('MASTER data'!$E38)=MONTH(S$4),'MASTER data'!$E38,""),"") | T37: =IF(S37='MASTER data'!$E38,'MASTER data'!$G38,"") -> 0 | U37: =IF('MASTER data'!$B38="RIL",IF(MONTH('MASTER data'!$E38)=MONTH(U$4),'MASTER data'!$E38,""),"") | V37: =IF(U37='MASTER data'!$E38,'MASTER data'!$G38,"") -> 0 | W37: =IF('MASTER data'!$B38="RIL",IF(MONTH('MASTER data'!$E38)=MONTH(W$4),'MASTER data'!$E38,""),"") | X37: =IF(W37='MASTER data'!$E38,'MASTER data'!$G38,"") -> 0 | Y37: =IF('MASTER data'!$B38="RIL",IF(MONTH('MASTER data'!$E38)=MONTH(Y$4),'MASTER data'!$E38,""),"") | Z37: =IF(Y37='MASTER data'!$E38,'MASTER data'!$G38,"") -> 0

Sheet SEP
A1: PETRON
A2: SEPCO -CHATISHGARH
C3: 2011 | AA3: 2012
A4: S.NO. | B4: ITEM DECRIPTION | C4: 40544 | E4: 40576 | G4: 40608 | I4: 40640 | K4: 40672 | M4: 40704 | O4: 40736 | Q4: 40768 | S4: 40800 | U4: 40832 | W4: 40864 | Y4: 40896
C5: DATE | D5: UNIT RATE (RS.) | E5: DATE | F5: UNIT RATE (RS.) | G5: DATE | H5: UNIT RATE (RS.) | I5: DATE | J5: UNIT RATE (RS.) | K5: DATE | L5: UNIT RATE (RS.) | M5: DATE | N5: UNIT RATE (RS.) | O5: DATE | P5: UNIT RATE (RS.) | Q5: DATE | R5: UNIT RATE (RS.) | S5: DATE | T5: UNIT RATE (RS.) | U5: DATE | V5: UNIT RATE (RS.) | W5: DATE | X5: UNIT RATE (RS.) | Y5: DATE | Z5: UNIT RATE (RS.)
A6: 1 | B6: =IF('MASTER data'!B7="sep",'MASTER data'!C7,0) -> 0 | C6: =IF('MASTER data'!$B7="SEP",IF(MONTH('MASTER data'!$E7)=MONTH(C$4),'MASTER data'!$E7,""),"") | D6: =IF(C6='MASTER data'!$E7,'MASTER data'!$H7,"") | E6: =IF('MASTER data'!$B7="SEP",IF(MONTH('MASTER data'!$E7)=MONTH(E$4),'MASTER data'!$E7,""),"") | F6: =IF(E6='MASTER data'!$E7,'MASTER data'!$H7,"") | G6: =IF('MASTER data'!$B7="SEP",IF(MONTH('MASTER data'!$E7)=MONTH(G$4),'MASTER data'!$E7,""),"") | H6: =IF(G6='MASTER data'!$E7,'MASTER data'!$H7,"") | I6: =IF('MASTER data'!$B7="SEP",IF(MONTH('MASTER data'!$E7)=MONTH(I$4),'MASTER data'!$E7,""),"") | J6: =IF(I6='MASTER data'!$E7,'MASTER data'!$H7,"") | K6: =IF('MASTER data'!$B7="SEP",IF(MONTH('MASTER data'!$E7)=MONTH(K$4),'MASTER data'!$E7,""),"") | L6: =IF(K6='MASTER data'!$E7,'MASTER data'!$H7,"") | M6: =IF('MASTER data'!$B7="SEP",IF(MONTH('MASTER data'!$E7)=MONTH(M$4),'MASTER data'!$E7,""),"") | N6: =IF(M6='MASTER data'!$E7,'MASTER data'!$H7,"") | O6: =IF('MASTER data'!$B7="SEP",IF(MONTH('MASTER data'!$E7)=MONTH(O$4),'MASTER data'!$E7,""),"") | P6: =IF(O6='MASTER data'!$E7,'MASTER data'!$H7,"") | Q6: =IF('MASTER data'!$B7="SEP",IF(MONTH('MASTER data'!$E7)=MONTH(Q$4),'MASTER data'!$E7,""),"") | R6: =IF(Q6='MASTER data'!$E7,'MASTER data'!$H7,"") | S6: =IF('MASTER data'!$B7="SEP",IF(MONTH('MASTER data'!$E7)=MONTH(S$4),'MASTER data'!$E7,""),"") | T6: =IF(S6='MASTER data'!$E7,'MASTER data'!$H7,"") | U6: =IF('MASTER data'!$B7="SEP",IF(MONTH('MASTER data'!$E7)=MONTH(U$4),'MASTER data'!$E7,""),"") | V6: =IF(U6='MASTER data'!$E7,'MASTER data'!$H7,"") | W6: =IF('MASTER data'!$B7="SEP",IF(MONTH('MASTER data'!$E7)=MONTH(W$4),'MASTER data'!$E7,""),"") | X6: =IF(W6='MASTER data'!$E7,'MASTER data'!$H7,"") | Y6: =IF('MASTER data'!$B7="SEP",IF(MONTH('MASTER data'!$E7)=MONTH(Y$4),'MASTER data'!$E7,""),"") | Z6: =IF(Y6='MASTER data'!$E7,'MASTER data'!$H7,"")
