Workbook

Sheet SchoolDistricts
H1: Regular Education | P1: Special Education | R1: Total
A2: ID | C2: K | D2: Grade 1 | E2: Grade 2 | F2: Grade 3 | G2: Grade 4 | H2: Grade 5 | I2: Grade 6 | J2: Grade 7 | K2: Grade 8 | L2: Grade 9 | M2: Grade 10 | N2: Grade 11 | O2: Grade 12 | P2: Self-Cont. | Q2: Resource | R2: K-12 + SC
A3: 1 | B3: Alpine District | C3: 5977.7667 | D3: 5857.1056 | E3: 5679.9556 | F3: 5711.6222 | G3: 5620.8222 | H3: 5318.5222 | I3: 5391.5778 | J3: 5273.9278 | K3: 5299.7222 | L3: 4937.2444 | M3: 4804.5444 | N3: 4557.2167 | O3: 4283.1722 | P3: 1514.9722 | Q3: 5638.1278 | R3: 70228.172
A4: 2 | B4: Beaver District | C4: 108.91111 | D4: 108.67222 | E4: 125.82778 | F4: 128.87222 | G4: 133.44444 | H4: 111.83889 | I4: 105.14444 | J4: 131.18889 | K4: 112.66667 | L4: 129.77222 | M4: 119.08333 | N4: 113.93333 | O4: 101.75556 | P4: 17.022222 | Q4: 178.06667 | R4: 1548.1333
A5: 3 | B5: Box Elder District | C5: 885.41667 | D5: 912.12222 | E5: 825.88889 | F5: 866.18889 | G5: 843.94444 | H5: 812.07778 | I5: 821.11111 | J5: 787.71111 | K5: 837.84444 | L5: 806.37778 | M5: 782.01667 | N5: 752.58889 | O5: 680.75556 | P5: 251.77222 | Q5: 1005.7 | R5: 10865.817
A6: 4 | B6: Cache District | C6: 1212.2833 | D6: 1254.6778 | E6: 1217.0111 | F6: 1342.5222 | G6: 1199.7167 | H6: 1261.5111 | I6: 1167.7 | J6: 1252.3889 | K6: 1127.6222 | L6: 1149.5889 | M6: 1141.7111 | N6: 1074.1444 | O6: 974.96667 | P6: 339.46667 | Q6: 1449.4778 | R6: 15715.311
A7: 42 | B7: Canyons District | C7: 2551.5389 | D7: 2632.3889 | E7: 2607.7778 | F7: 2664.2778 | G7: 2566.3389 | H7: 2640.5333 | I7: 2581.55 | J7: 2573.9167 | K7: 2414.35 | L7: 2407.3389 | M7: 2540.7722 | N7: 2347.9278 | O7: 2366.0611 | P7: 731.75 | Q7: 2591.6167 | R7: 33626.522
A8: 5 | B8: Carbon District | C8: 347.98333 | D8: 262.98889 | E8: 265.35 | F8: 310.70556 | G8: 262.78333 | H8: 271.36111 | I8: 259.25 | J8: 247.56111 | K8: 241.15556 | L8: 208.45 | M8: 223.23333 | N8: 201.32778 | O8: 194.35556 | P8: 102.19444 | Q8: 423.18889 | R8: 3398.7
A9: 6 | B9: Daggett District | C9: 22.772222 | D9: 13.288889 | E9: 19.422222 | F9: 13.9 | G9: 19.744444 | H9: 11.155556 | I9: 8.2388889 | J9: 10.972222 | K9: 18.55 | L9: 11 | M9: 10.25 | N9: 10 | O9: 9.6444444 | P9: 1 | Q9: 21.061111 | R9: 179.93889
A10: 7 | B10: Davis District | C10: 5590.6611 | D10: 5575.35 | E10: 5416.0056 | F10: 5470.4667 | G10: 5208.1167 | H10: 5186.1833 | I10: 5117.7611 | J10: 5027.9833 | K10: 5036.7 | L10: 4789.1167 | M10: 4744.0444 | N10: 4541.95 | O10: 4428.1778 | P10: 1855.2056 | Q10: 5165.3056 | R10: 67987.722
A11: 8 | B11: Duchesne District | C11: 434.78333 | D11: 415.03333 | E11: 366.78889 | F11: 377.40556 | G11: 357.19444 | H11: 349.37222 | I11: 372.96111 | J11: 351.02222 | K11: 379.89444 | L11: 328.53333 | M11: 294.13333 | N11: 286.92778 | O11: 253.55 | P11: 198.54444 | Q11: 479.46667 | R11: 4766.1444
A12: 9 | B12: Emery District | C12: 194.28889 | D12: 189.81667 | E12: 169.98333 | F12: 170.67222 | G12: 199.52778 | H12: 174.28889 | I12: 175.22778 | J12: 159.17222 | K12: 168.64444 | L12: 174.02222 | M12: 169.18889 | N12: 139.70556 | O12: 146.61111 | P12: 56.95 | Q12: 342.94444 | R12: 2288.1
A13: 10 | B13: Garfield District | C13: 87.944444 | D13: 70.427778 | E13: 72.083333 | F13: 77.533333 | G13: 65.427778 | H13: 69.394444 | I13: 64.911111 | J13: 71.027778 | K13: 73.961111 | L13: 76.333333 | M13: 64.277778 | N13: 64.705556 | O13: 64.2 | P13: 13.855556 | Q13: 98.372222 | R13: 936.08333
A14: 11 | B14: Grand District | C14: 98.388889 | D14: 84.8 | E14: 119.93333 | F14: 100.83889 | G14: 110.98333 | H14: 109.66111 | I14: 114.64444 | J14: 102.35 | K14: 104.96667 | L14: 114.82778 | M14: 101.48333 | N14: 125.44444 | O14: 83.405556 | P14: 41.627778 | Q14: 131.27222 | R14: 1413.3556
... A43: 35 | B43: Weber District | C43: 2294.7611 | D43: 2266.1611 | E43: 2317.1444 | F43: 2317.1333 | G43: 2317.9722 | H43: 2302.5889 | I43: 2288.8778 | J43: 2477.7167 | K43: 2348.1111 | L43: 2366.4056 | M43: 2258.15 | N43: 2130.6167 | O43: 2124.1167 | P43: 817.36111 | Q43: 3061.0722 | R43: 30627.117
B44: DISTRICT SUBTOTAL | C44: =SUM(C3:C43) -> 45223.917 | D44: =SUM(D3:D43) -> 44767.617 | E44: =SUM(E3:E43) -> 43480.178 | F44: =SUM(F3:F43) -> 43548.639 | G44: =SUM(G3:G43) -> 42979.711 | H44: =SUM(H3:H43) -> 41539.611 | I44: =SUM(I3:I43) -> 41039.994 | J44: =SUM(J3:J43) -> 40870.833 | ... R44: =SUM(R3:R43) -> 546199.74
B45: CHARTER SUBTOTAL | C45: =CharterSchools!C87 -> 4277.9 | D45: =CharterSchools!D87 -> 4591.4556 | E45: =CharterSchools!E87 -> 4536.5389 | F45: =CharterSchools!F87 -> 4465.7889 | G45: =CharterSchools!G87 -> 4323.5611 | H45: =CharterSchools!H87 -> 4384.9333 | I45: =CharterSchools!I87 -> 4424.5611 | J45: =CharterSchools!J87 -> 4132.8167 | ... R45: =CharterSchools!R87 -> 49379.611
B46: Utah Schools for Deaf & Blind | C46: 1.0055556 | D46: 1 | E46: 0 | F46: 0.37777778 | G46: 1 | H46: 0 | I46: 0 | J46: 0 | K46: 0 | L46: 0 | M46: 0.038888889 | N46: 0 | O46: 0.98333333 | P46: 216.09444 | Q46: 0 | R46: 220.5
B47: STATE TOTAL | C47: =SUM(C44:C46) -> 49502.822 | D47: =SUM(D44:D46) -> 49360.072 | E47: =SUM(E44:E46) -> 48016.717 | F47: =SUM(F44:F46) -> 48014.806 | G47: =SUM(G44:G46) -> 47304.272 | H47: =SUM(H44:H46) -> 45924.544 | I47: =SUM(I44:I46) -> 45464.556 | J47: =SUM(J44:J46) -> 45003.65 | ... R47: =SUM(R44:R46) -> 595799.86

Sheet CharterSchools
I1: Regular Education | P1: Special Education | R1: Total
C2: K | D2: Grade 1 | E2: Grade 2 | F2: Grade 3 | G2: Grade 4 | H2: Grade 5 | I2: Grade 6 | J2: Grade 7 | K2: Grade 8 | L2: Grade 9 | M2: Grade 10 | N2: Grade 11 | O2: Grade 12 | P2: Self-Cont. | Q2: Resource | R2: K-12 + SC
A3: 83 | B3: Acad for Math Engineering Sci | C3: 0 | D3: 0 | E3: 0 | F3: 0 | G3: 0 | H3: 0 | I3: 0 | J3: 0 | K3: 0 | L3: 127.08889 | M3: 132.23333 | N3: 115.17222 | O3: 107.52222 | P3: 0 | Q3: 23.994444 | R3: 482.01667
A4: 9G | B4: Alianza Academy | C4: 51.916667 | D4: 65.333333 | E4: 57.038889 | F4: 48.155556 | G4: 47.355556 | H4: 54.166667 | I4: 64.538889 | J4: 49.611111 | K4: 33.155556 | L4: 0 | M4: 0 | N4: 0 | O4: 0 | P4: 1.4611111 | Q4: 56.266667 | R4: 472.73333
A5: 8B | B5: American Leadership Academy | C5: 106.58333 | D5: 121.3 | E5: 99.477778 | F5: 109.95556 | G5: 103.02222 | H5: 125.56667 | I5: 121.59444 | J5: 161.34444 | K5: 180.73889 | L5: 173.94444 | M5: 150.25 | N5: 120.90556 | O5: 102.78333 | P5: 28.877778 | Q5: 185.34444 | R5: 1706.3444
A6: 74 | B6: American Preparatory Academy | C6: 176.8 | D6: 201.35556 | E6: 204.27222 | F6: 203.79444 | G6: 211.06667 | H6: 206.43333 | I6: 216.08889 | J6: 279.01667 | K6: 229.42222 | L6: 185.97222 | M6: 85.077778 | N6: 43.444444 | O6: 0 | P6: 2 | Q6: 214.31111 | R6: 2244.7444
A7: 4H | B7: Aristotle Academy | C7: 43.388889 | D7: 25.372222 | E7: 38.861111 | F7: 26.738889 | G7: 25.788889 | H7: 25.216667 | I7: 16.388889 | J7: 17.738889 | K7: 1.2222222 | L7: 0 | M7: 0 | N7: 0 | O7: 0 | P7: 2.3277778 | Q7: 34.438889 | R7: 223.04444
A8: 3G | B8: Bear River Charter School | C8: 19.483333 | D8: 19.3 | E8: 19.511111 | F8: 21.4 | G8: 16.972222 | H8: 19.705556 | I8: 20 | J8: 20 | K8: 19.961111 | L8: 0 | M8: 0 | N8: 0 | O8: 0 | P8: 2.2777778 | Q8: 21.177778 | R8: 178.61111
A9: 3B | B9: Beehive Schience & Tech Acad | C9: 0 | D9: 0 | E9: 0 | F9: 0 | G9: 0 | H9: 0 | I9: 0 | J9: 75.261111 | K9: 53.238889 | L9: 43.516667 | M9: 24.261111 | N9: 16.105556 | O9: 6.7111111 | P9: 0 | Q9: 38.961111 | R9: 219.09444
A10: 9D | B10: Canyon Rim Academy | C10: 77.788889 | D10: 75 | E10: 72.766667 | F10: 75 | G10: 75 | H10: 73.322222 | I10: 74.644444 | J10: 0 | K10: 0 | L10: 0 | M10: 0 | N10: 0 | O10: 0 | P10: 2.6777778 | Q10: 50.427778 | R10: 526.2
A11: 2D | B11: Channing Hall | C11: 74.572222 | D11: 76.877778 | E11: 75.472222 | F11: 76.322222 | G11: 77.638889 | H11: 77.2 | I11: 73.527778 | J11: 69 | K11: 58.494444 | L11: 0 | M11: 0 | N11: 0 | O11: 0 | P11: 1.1333333 | Q11: 63.544444 | R11: 660.23889
A12: 87 | B12: City Academy | C12: 0 | D12: 0 | E12: 0 | F12: 0 | G12: 0 | H12: 0 | I12: 0 | J12: 0 | K12: 22.677778 | L12: 51.788889 | M12: 41.538889 | N12: 40.505556 | O12: 35.694444 | P12: 8.9833333 | Q12: 30.011111 | R12: 201.18889
A13: 3E | B13: Cs Lewis Academy | C13: 34.061111 | D13: 90.75 | E13: 77.194444 | F13: 58.016667 | G13: 69.077778 | H13: 60.583333 | I13: 40.938889 | J13: 0 | K13: 0 | L13: 0 | M13: 0 | N13: 0 | O13: 0 | P13: 0.0055555556 | Q13: 37.411111 | R13: 430.62778
A14: A3 | B14: Davinci Academy | C14: 0 | D14: 133.65556 | E14: 130.38333 | F14: 122.38889 | G14: 81.427778 | H14: 83.794444 | I14: 98.555556 | J14: 47.044444 | K14: 77.1 | L14: 74.377778 | M14: 64.011111 | N14: 55.138889 | O14: 39.083333 | P14: 16.827778 | Q14: 49.711111 | R14: 1023.7889
A15: 4E | B15: Dual Immersion Academy | C15: 75.416667 | D15: 71.061111 | E15: 50.716667 | F15: 54.188889 | G15: 46.022222 | H15: 37.922222 | I15: 36.8 | J15: 19.788889 | K15: 21.988889 | L15: 0 | M15: 0 | N15: 0 | O15: 0 | P15: 0 | Q15: 34.794444 | R15: 413.90556
A16: 6F | B16: Early Light Academy At Daybreak | C16: 70.655556 | D16: 74.144444 | E16: 74.966667 | F16: 73.811111 | G16: 74.016667 | H16: 73.633333 | I16: 71.188889 | J16: 75.911111 | K16: 75.016667 | L16: 68.183333 | M16: 0 | N16: 0 | O16: 0 | P16: 5.6444444 | Q16: 81.466667 | R16: 737.17222
A17: A8 | B17: East Hollywood High | C17: 0 | D17: 0 | E17: 0 | F17: 0 | G17: 0 | H17: 0 | I17: 0 | J17: 0 | K17: 0 | L17: 56.616667 | M17: 84.366667 | N17: 77.85 | O17: 87.688889 | P17: 2.5777778 | Q17: 45.916667 | R17: 309.1
A18: 5E | B18: Edith Bowen Laboratory School | C18: 46.894444 | D18: 46.438889 | E18: 48.927778 | F18: 51.238889 | G18: 52.372222 | H18: 54.366667 | I18: 0 | J18: 0 | K18: 0 | L18: 0 | M18: 0 | N18: 0 | O18: 0 | P18: 2.7833333 | Q18: 44.944444 | R18: 303.02222
A19: 3H | B19: Endeavor Hall | C19: 77.305556 | D19: 74.205556 | E19: 75.961111 | F19: 74.655556 | G19: 71.794444 | H19: 71.833333 | I19: 66.166667 | J19: 44.694444 | K19: 0 | L19: 0 | M19: 0 | N19: 0 | O19: 0 | P19: 0.0055555556 | Q19: 50.15 | R19: 556.62222
A20: 3C | B20: Entheos Academy | C20: 102.73333 | D20: 103.54444 | E20: 101.79444 | F20: 104.35556 | G20: 102.04444 | H20: 104.04444 | I20: 104.91667 | J20: 107.14444 | K20: 92.277778 | L20: 63.816667 | M20: 0 | N20: 0 | O20: 0 | P20: 1.2611111 | Q20: 92.733333 | R20: 987.93333
A21: 7F | B21: Excelsior Academy | C21: 76.444444 | D21: 75.938889 | E21: 78.822222 | F21: 74.6 | G21: 77.322222 | H21: 74.4 | I21: 76.1 | J21: 68.911111 | K21: 56.355556 | L21: 0 | M21: 0 | N21: 0 | O21: 0 | P21: 1.8222222 | Q21: 70.811111 | R21: 660.71667
A22: 98 | B22: Fast Forward High | C22: 0 | D22: 0 | E22: 0 | F22: 0 | G22: 0 | H22: 0 | I22: 0 | J22: 0 | K22: 0 | L22: 33.438889 | M22: 51.366667 | N22: 61.905556 | O22: 71.961111 | P22: 0 | Q22: 32.361111 | R22: 218.67222
A23: 82 | B23: Freedom Academy | C23: 77.733333 | D23: 100.35556 | E23: 75.894444 | F23: 76.738889 | G23: 75.583333 | H23: 74.933333 | I23: 72.466667 | J23: 69.316667 | K23: 75.661111 | L23: 39.205556 | M23: 0 | N23: 0 | O23: 0 | P23: 7.2111111 | Q23: 58.244444 | R23: 745.1
A24: 7E | B24: Gateway Preparatory Academy | C24: 67.8 | D24: 89.65 | E24: 89.633333 | F24: 78.288889 | G24: 95.716667 | H24: 78.75 | I24: 83.45 | J24: 35.538889 | K24: 33.716667 | L24: 0 | M24: 0 | N24: 0 | O24: 0 | P24: 15.266667 | Q24: 73.033333 | R24: 667.81111
A25: 5D | B25: George Washington Academy | C25: 122.87222 | D25: 128.26111 | E25: 151.72222 | F25: 128.46111 | G25: 109.24444 | H25: 129.36667 | I25: 86.95 | J25: 61.35 | K25: 39.522222 | L25: 0 | M25: 0 | N25: 0 | O25: 0 | P25: 4.9833333 | Q25: 75.283333 | R25: 962.73333
A26: 8G | B26: Good Foundations Academy | C26: 61.772222 | D26: 68.105556 | E26: 71.388889 | F26: 68.344444 | G26: 58.25 | H26: 59.233333 | I26: 36.8 | J26: 0 | K26: 0 | L26: 0 | M26: 0 | N26: 0 | O26: 0 | P26: 0.19444444 | Q26: 35.566667 | R26: 424.08889
A27: 1E | B27: Guadalupe School | C27: 25.255556 | D27: 22.655556 | E27: 23.938889 | F27: 22.261111 | G27: 23.044444 | H27: 0 | I27: 0 | J27: 0 | K27: 0 | L27: 0 | M27: 0 | N27: 0 | O27: 0 | P27: 3.1333333 | Q27: 8.2388889 | R27: 120.28889
A28: 8F | B28: Hawthorn Academy | C28: 76.527778 | D28: 76.166667 | E28: 76.944444 | F28: 76.944444 | G28: 75.894444 | H28: 76.366667 | I28: 102.57778 | J28: 92.1 | K28: 81.172222 | L28: 62.244444 | M28: 0 | N28: 0 | O28: 0 | P28: 6 | Q28: 89.2 | R28: 802.93889
A29: 5H | B29: Highmark Charter School | C29: 49.383333 | D29: 66.905556 | E29: 45.933333 | F29: 69.972222 | G29: 52.272222 | H29: 48.305556 | I29: 53.344444 | J29: 83.338889 | K29: 70.288889 | L29: 0 | M29: 0 | N29: 0 | O29: 0 | P29: 0 | Q29: 50.483333 | R29: 539.74444
A30: 2C | B30: Intech Collegiate High School | C30: 0 | D30: 0 | E30: 0 | F30: 0 | G30: 0 | H30: 0 | I30: 0 | J30: 0 | K30: 0 | L30: 58.888889 | M30: 43.355556 | N30: 31.233333 | O30: 21.561111 | P30: 0 | Q30: 18.294444 | R30: 155.03889
A31: A5 | B31: Itineris Early College High | C31: 0 | D31: 0 | E31: 0 | F31: 0 | G31: 0 | H31: 0 | I31: 0 | J31: 0 | K31: 0 | L31: 0 | M31: 0 | N31: 115.26667 | O31: 117.80556 | P31: 0 | Q31: 3.1333333 | R31: 233.07222
A32: 1G | B32: Jefferson Academy | C32: 80.422222 | D32: 101.2 | E32: 100.02778 | F32: 104.21667 | G32: 97.738889 | H32: 94.961111 | I32: 67.011111 | J32: 46.077778 | K32: 39.383333 | L32: 18.394444 | M32: 0 | N32: 0 | O32: 0 | P32: 7.2111111 | Q32: 76.188889 | R32: 756.64444
A33: 93 | B33: John Hancock Charter School | C33: 20 | D33: 19.388889 | E33: 21 | F33: 22.111111 | G33: 21.761111 | H33: 18.472222 | I33: 21.461111 | J33: 22 | K33: 12.627778 | L33: 0 | M33: 0 | N33: 0 | O33: 0 | P33: 3 | Q33: 19.427778 | R33: 181.82222
A34: 2E | B34: Karl G Maeser Preparatory Academy | C34: 0 | D34: 0 | E34: 0 | F34: 0 | G34: 0 | H34: 0 | I34: 0 | J34: 102.16667 | K34: 98.077778 | L34: 125.01667 | M34: 106.12778 | N34: 87.888889 | O34: 63.238889 | P34: 0 | Q34: 41.755556 | R34: 582.51667
A35: 4C | B35: Lakeview Academy | C35: 97.494444 | D35: 74.377778 | E35: 98.15 | F35: 96.4 | G35: 96.755556 | H35: 98.95 | I35: 99.016667 | J35: 71.244444 | K35: 56.261111 | L35: 26.005556 | M35: 0 | N35: 0 | O35: 0 | P35: 4.5777778 | Q35: 68.155556 | R35: 819.23333
A36: 5C | B36: Legacy Preparatory Academy | C36: 107.99444 | D36: 106.79444 | E36: 80.444444 | F36: 81 | G36: 77.4 | H36: 77.816667 | I36: 75.283333 | J36: 124.18889 | K36: 108.38333 | L36: 102.31667 | M36: 41.816667 | N36: 53.272222 | O36: 34.183333 | P36: 7 | Q36: 74.255556 | R36: 1077.8944
A37: 6C | B37: Liberty Academy | C37: 52.722222 | D37: 50.222222 | E37: 41.766667 | F37: 46.727778 | G37: 41.894444 | H37: 39.144444 | I37: 39.583333 | J37: 26.694444 | K37: 20.611111 | L37: 16.677778 | M37: 9.3611111 | N37: 6.5055556 | O37: 9.3777778 | P37: 16.288889 | Q37: 64.077778 | R37: 417.57778
A38: 2B | B38: Lincoln Academy | C38: 45.705556 | D38: 46.255556 | E38: 51.488889 | F38: 51.922222 | G38: 49.255556 | H38: 76.733333 | I38: 78.038889 | J38: 89.75 | K38: 80.272222 | L38: 60.505556 | M38: 0 | N38: 0 | O38: 0 | P38: 9.3166667 | Q38: 68.194444 | R38: 639.24444
A39: 4G | B39: Maria Montessori Academy | C39: 76.594444 | D39: 65.077778 | E39: 64.027778 | F39: 66.233333 | G39: 63.322222 | H39: 59.311111 | I39: 62.361111 | J39: 0 | K39: 0 | L39: 0 | M39: 0 | N39: 0 | O39: 0 | P39: 14.5 | Q39: 51.094444 | R39: 471.42778
A40: 8E | B40: Merit College Preparatory Academy | C40: 0 | D40: 0 | E40: 0 | F40: 0 | G40: 0 | H40: 0 | I40: 0 | J40: 83.477778 | K40: 76.75 | L40: 106.38889 | M40: 93.072222 | N40: 90.9 | O40: 75.983333 | P40: 16.394444 | Q40: 48.25 | R40: 542.96667
...
