Workbook
Name \C: #REF!
Name TABLE1: 'BUDGET DETAIL'!$B$4:$L$140
Name table3: 'BUDGET DETAIL'!$A$4:$L$150
Name table4: 'BUDGET DETAIL'!$A$154:$L$158
Name table5: 'BUDGET DETAIL'!$A$162:$L$169

Sheet BUDGETSIZE
O3: RETIREMENT | P3: TRUST FUND | Q3: REVENUE FUND | R3: DEBT FUND | S3: CONSTRUCTION | T3: OPERATING | U3: TOTAL
A4: SAP | N4: ADJUSTED | O4: @ 0% | P4: @ 0% | Q4: @ 50% | R4: @ 50% | S4: @ 50% | T4: @ 100% | U4: ACTUAL
A5: FUND NO. | B5: OPERATING BUREAUS/FUNDS | C5: LOOK UP VALUES | K5: TABLE | L5: FY 2012 EXP | M5: ADJUSTMENTS | N5: FY 2012 EXP | O5: OF BUDGET | P5: OF BUDGET | Q5: OF BUDGET | R5: OF BUDGET | S5: OF BUDGET | T5: OF BUDGET | U5: ALLOCATED
A7: 100000 | B7: Portland Police Bureau | C7: 18 | E7: 61 | F7: 62 | K7: TABLE 3 | L7: =VLOOKUP(C7,table3,12)+VLOOKUP(D7,table3,12)+VLOOKUP(E7,table3,12)+VLOOKUP(F7,table3,12)+VLOOKUP(G7,table3,12) -> 1.4420687e+08 | N7: =SUM(M7,L7) -> 1.4420687e+08 | T7: =SUM(N7)-SUM(O7:P7)-SUM(Q7:S7)*2 -> 1.4420687e+08 | U7: =SUM(O7:T7) -> 1.4420687e+08
A8: 214000 | B8: Campaign Finance (closed) | K8: TABLE 3 | L8: =VLOOKUP(C8,table3,12)+VLOOKUP(D8,table3,12)+VLOOKUP(E8,table3,12)+VLOOKUP(F8,table3,12)+VLOOKUP(G8,table3,12) -> 0 | N8: =SUM(M8,L8) -> 0 | T8: =SUM(N8)-SUM(O8:P8)-SUM(Q8:S8)*2 -> 0 | U8: =SUM(O8:T8) -> 0
A9: 100000 | B9: Portland Fire & Rescue | C9: 5 | D9: 6 | E9: 50 | F9: 51 | G9: 79 | H9: 81 | K9: TABLE 3 | L9: =VLOOKUP(C9,table3,12)+VLOOKUP(D9,table3,12)+VLOOKUP(E9,table3,12)+VLOOKUP(F9,table3,12)+VLOOKUP(G9,table3,12)+VLOOKUP(H9,table3,12) -> 92119356 | N9: =SUM(M9,L9) -> 92119356 | S9: =VLOOKUP(C9,table3,12)/2+VLOOKUP(G9,table3,12)/2+VLOOKUP(H9,table3,12)/2 -> 640574.41 | T9: =SUM(N9)-SUM(O9:P9)-SUM(Q9:S9)*2 -> 90838207 | U9: =SUM(O9:T9) -> 91478782
A10: 100000 | B10: Portland Parks & Recreation | C10: 16 | D10: ='BUDGET DETAIL'!A21 -> 17 | E10: ='BUDGET DETAIL'!A63 -> 59 | F10: ='BUDGET DETAIL'!A64 -> 60 | K10: TABLE 3 | L10: =VLOOKUP(C10,table3,12)+VLOOKUP(D10,table3,12)+VLOOKUP(E10,table3,12)+VLOOKUP(F10,table3,12)+VLOOKUP(G10,table3,12) -> 56151485 | N10: =SUM(M10,L10) -> 56151485 | S10: =VLOOKUP(C10,table3,12)/2+VLOOKUP(E10,table3,12)/2 -> 919449.24 | T10: =SUM(N10)-SUM(O10:P10)-SUM(Q10:S10)*2 -> 54312587 | U10: =SUM(O10:T10) -> 55232036
A11: 600000 | B11: Sewer System Op | C11: 102 | D11: 103 | E11: ='BUDGET DETAIL'!A51 -> 47 | F11: ='BUDGET DETAIL'!A52 -> 48 | G11: ='BUDGET DETAIL'!A53 -> 49 | K11: TABLE 3 | L11: =VLOOKUP(C11,table3,12)+VLOOKUP(D11,table3,12)+VLOOKUP(E11,table3,12)+VLOOKUP(F11,table3,12)+VLOOKUP(G11,table3,12) -> 1.6866374e+08 | N11: =SUM(M11,L11) -> 1.6866374e+08 | S11: =(VLOOKUP(C11,table3,12)+VLOOKUP(D11,table3,10))/2+VLOOKUP(F11,table3,12)/2 -> 64557865 | T11: =SUM(N11)-SUM(O11:P11)-SUM(Q11:S11)*2 -> 39548010 | U11: =SUM(O11:T11) -> 1.0410587e+08
A12: 608000 | B12: Envtl Remediation | C12: ='BUDGET DETAIL'!A119 -> 115 | D12: 83 | K12: TABLE 3 | L12: =VLOOKUP(C12,table3,12)+VLOOKUP(D12,table3,12)+VLOOKUP(E12,table3,12)+VLOOKUP(F12,table3,12)+VLOOKUP(G12,table3,12) -> 3395384.2 | N12: =SUM(M12,L12) -> 3395384.2 | R12: 0 | S12: =(VLOOKUP(D12,table3,12)) -> 60567 | T12: =SUM(N12)-SUM(O12:P12)-SUM(Q12:S12)*2 -> 3274250.2 | U12: =SUM(O12:T12) -> 3334817.2
A13: 605000 | B13: Solid Waste Mgt | C13: ='BUDGET DETAIL'!A114 -> 110 | K13: TABLE 3 | L13: =VLOOKUP(C13,table3,12)+VLOOKUP(D13,table3,12)+VLOOKUP(E13,table3,12)+VLOOKUP(F13,table3,12)+VLOOKUP(G13,table3,12) -> 3494849.2 | N13: =SUM(M13,L13) -> 3494849.2 | R13: 0 | T13: =SUM(N13)-SUM(O13:P13)-SUM(Q13:S13)*2 -> 3494849.2 | U13: =SUM(O13:T13) -> 3494849.2
A14: 200000 | B14: Transportation Op | C14: 26 | D14: ='BUDGET DETAIL'!A31 -> 27 | E14: 66 | F14: ='BUDGET DETAIL'!A71 -> 67 | G14: ='BUDGET DETAIL'!A72 -> 68 | K14: TABLE 3 | L14: =VLOOKUP(C14,table3,12)+VLOOKUP(D14,table3,12)+VLOOKUP(E14,table3,12)+VLOOKUP(F14,table3,12)+VLOOKUP(G14,table3,12) -> 1.6582504e+08 | N14: =SUM(M14,L14) -> 1.6582504e+08 | R14: 0 | S14: =(VLOOKUP(F14,table3,12)+VLOOKUP(D14,table3,12))/2 -> 43351483 | T14: =SUM(N14)-SUM(O14:P14)-SUM(Q14:S14)*2 -> 79122077 | U14: =SUM(O14:T14) -> 1.2247356e+08
A15: 212000 | B15: Transportation Resv | K15: TABLE 3 | L15: =VLOOKUP(C15,table3,12)+VLOOKUP(D15,table3,12)+VLOOKUP(E15,table3,12)+VLOOKUP(F15,table3,12)+VLOOKUP(G15,table3,12) -> 0 | N15: =SUM(M15,L15) -> 0 | Q15: =N15*0.5 -> 0 | T15: =SUM(N15)-SUM(O15:P15)-SUM(Q15:S15)*2 -> 0 | U15: =SUM(O15:T15) -> 0
A16: 614000 | B16: Sewer System Constr | C16: ='BUDGET DETAIL'!A124 -> 120 | K16: TABLE 3 | L16: =VLOOKUP(C16,table3,12)+VLOOKUP(D16,table3,12)+VLOOKUP(E16,table3,12)+VLOOKUP(F16,table3,12)+VLOOKUP(G16,table3,12) -> 0 | N16: =SUM(M16,L16) -> 0 | T16: =SUM(N16)-SUM(O16:P16)-SUM(Q16:S16)*2 -> 0 | U16: =SUM(O16:T16) -> 0
A17: 609000 | B17: Sewer Sys Debt Rdmpt | C17: 116 | K17: TABLE 3 | L17: =VLOOKUP(C17,table3,12)+VLOOKUP(D17,table3,12)+VLOOKUP(E17,table3,12)+VLOOKUP(F17,table3,12)+VLOOKUP(G17,table3,12) -> 0 | N17: =SUM(M17,L17) -> 0 | R17: 0 | T17: =SUM(N17)-SUM(O17:P17)-SUM(Q17:S17)*2 -> 0 | U17: =SUM(O17:T17) -> 0
A18: 602000 | B18: Water | C18: 105 | D18: 106 | E18: ='BUDGET DETAIL'!$A$73 -> 69 | F18: ='BUDGET DETAIL'!$A$74 -> 70 | K18: TABLE 3 | L18: =VLOOKUP(C18,table3,12)+VLOOKUP(D18,table3,12)+VLOOKUP(E18,table3,12)+VLOOKUP(F18,table3,12)+VLOOKUP(G18,table3,12) -> 1.2132837e+08 | N18: =SUM(M18,L18) -> 1.2132837e+08 | R18: 0 | S18: =(VLOOKUP(F18,table3,12)+VLOOKUP(D18,table3,12))/2 -> 34494078 | T18: =SUM(N18)-SUM(O18:P18)-SUM(Q18:S18)*2 -> 52340211 | U18: =SUM(O18:T18) -> 86834290
A19: 615000 | B19: Water Construction | K19: TABLE 3 | L19: =VLOOKUP(C19,table3,12)+VLOOKUP(D19,table3,12)+VLOOKUP(E19,table3,12)+VLOOKUP(F19,table3,12)+VLOOKUP(G19,table3,12) -> 0 | N19: =SUM(M19,L19) -> 0 | S19: =+N19*0.5 -> 0 | T19: =SUM(N19)-SUM(O19:P19)-SUM(Q19:S19)*2 -> 0 | U19: =SUM(O19:T19) -> 0
A20: 612000 | B20: Water Bond Sinking | C20: ='BUDGET DETAIL'!A123 -> 119 | K20: TABLE 3 | L20: =VLOOKUP(C20,table3,12)+VLOOKUP(D20,table3,12)+VLOOKUP(E20,table3,12)+VLOOKUP(F20,table3,12)+VLOOKUP(G20,table3,12) -> 0 | N20: =SUM(M20,L20) -> 0 | R20: 0 | T20: =SUM(N20)-SUM(O20:P20)-SUM(Q20:S20)*2 -> 0 | U20: =SUM(O20:T20) -> 0
A21: 607000 | B21: Spectator Fac Op | C21: ='BUDGET DETAIL'!$A$117 -> 113 | D21: ='BUDGET DETAIL'!$A$118 -> 114 | K21: TABLE 3 | L21: =VLOOKUP(C21,table3,12)+VLOOKUP(D21,table3,12)+VLOOKUP(E21,table3,12)+VLOOKUP(F21,table3,12)+VLOOKUP(G21,table3,12) -> 1619760.2 | N21: =SUM(M21,L21) -> 1619760.2 | R21: 0 | S21: =(VLOOKUP(C21,table3,12))/2 -> 193827.18 | T21: =SUM(N21)-SUM(O21:P21)-SUM(Q21:S21)*2 -> 1232105.8 | U21: =SUM(O21:T21) -> 1425933
A22: 617000 | B22: Sewer Sys Rate Stblt | K22: TABLE 3 | L22: =VLOOKUP(C22,table3,12)+VLOOKUP(D22,table3,12)+VLOOKUP(E22,table3,12)+VLOOKUP(F22,table3,12)+VLOOKUP(G22,table3,12) -> 0 | N22: =SUM(M22,L22) -> 0 | P22: =+N22*0 -> 0 | T22: =SUM(N22)-SUM(O22:P22)-SUM(Q22:S22)*2 -> 0 | U22: =SUM(O22:T22) -> 0
A23: 619000 | B23: Sewer Sys Safety Net | K23: TABLE 3 | L23: =VLOOKUP(C23,table3,12)+VLOOKUP(D23,table3,12)+VLOOKUP(E23,table3,12)+VLOOKUP(F23,table3,12)+VLOOKUP(G23,table3,12) -> 0 | N23: =SUM(M23,L23) -> 0 | T23: =SUM(N23)-SUM(O23:P23)-SUM(Q23:S23)*2 -> 0 | U23: =SUM(O23:T23) -> 0
A24: 620000 | B24: Sewer Revolving Loan | K24: TABLE 3 | L24: =VLOOKUP(C24,table3,12)+VLOOKUP(D24,table3,12)+VLOOKUP(E24,table3,12)+VLOOKUP(F24,table3,12)+VLOOKUP(G24,table3,12) -> 0 | N24: =SUM(M24,L24) -> 0 | T24: =SUM(N24)-SUM(O24:P24)-SUM(Q24:S24)*2 -> 0 | U24: =SUM(O24:T24) -> 0
A25: 802000 | B25: F&P Suppl Retir Rsrv | C25: 136 | K25: TABLE 3 | L25: =VLOOKUP(C25,table3,12)+VLOOKUP(D25,table3,12)+VLOOKUP(E25,table3,12)+VLOOKUP(F25,table3,12)+VLOOKUP(G25,table3,12) -> 8108.94 | N25: =SUM(M25,L25) -> 8108.94 | O25: =+N25*0 -> 0 | U25: =SUM(O25:T25) -> 0
A26: 800000 | B26: FPDR | C26: ='BUDGET DETAIL'!A138 -> 134 | D26: ='BUDGET DETAIL'!A139 -> 135 | K26: TABLE 3 | L26: =VLOOKUP(C26,table3,12)+VLOOKUP(D26,table3,12)+VLOOKUP(E26,table3,12)+VLOOKUP(F26,table3,12)+VLOOKUP(G26,table3,12) -> 1.0412361e+08 | M26: =-102662983.36 -> -1.0266298e+08 | N26: =SUM(M26,L26) -> 1460629.2 | T26: =SUM(N26)-SUM(O26:P26)-SUM(Q26:S26)*2 -> 1460629.2 | U26: =SUM(O26:T26) -> 1460629.2
A27: 801000 | B27: FPDR Reserve | K27: TABLE 3 | L27: =VLOOKUP(C27,table3,12)+VLOOKUP(D27,table3,12)+VLOOKUP(E27,table3,12)+VLOOKUP(F27,table3,12)+VLOOKUP(G27,table3,12) -> 0 | N27: =SUM(M27,L27) -> 0 | O27: =+N27*0 -> 0 | T27: =SUM(N27)-SUM(O27:P27)-SUM(Q27:S27)*2 -> 0 | U27: =SUM(O27:T27) -> 0
A28: 211000 | B28: Spec Fin & Resource | C28: ='BUDGET DETAIL'!A42 -> 38 | K28: TABLE 3 | L28: =VLOOKUP(C28,table3,12)+VLOOKUP(D28,table3,12)+VLOOKUP(E28,table3,12)+VLOOKUP(F28,table3,12)+VLOOKUP(G28,table3,12) -> 1.3378731e+08 | M28: =-L28 -> -1.3378731e+08 | N28: =SUM(M28,L28) -> 0 | R28: 0 | T28: =SUM(N28)-SUM(O28:P28)-SUM(Q28:S28)*2 -> 0 | U28: =SUM(O28:T28) -> 0
A29: 217000 | B29: Grants | K29: TABLE 3 | L29: =VLOOKUP(C29,table3,12)+VLOOKUP(D29,table3,12)+VLOOKUP(E29,table3,12)+VLOOKUP(F29,table3,12)+VLOOKUP(G29,table3,12) -> 0 | N29: =SUM(M29,L29) -> 0 | Q29: =N29*0.5 -> 0 | T29: =SUM(N29)-SUM(O29:P29)-SUM(Q29:S29)*2 -> 0 | U29: =SUM(O29:T29) -> 0
A30: 853000 | B30: PDC Accounts | C30: ='BUDGET DETAIL'!A29 -> 25 | D30: 71 | K30: TABLE 3 | L30: =VLOOKUP(C30,table3,12)+VLOOKUP(D30,table3,12)+VLOOKUP(E30,table3,12)+VLOOKUP(F30,table3,12)+VLOOKUP(G30,table3,12) -> 4748443.4 | N30: =SUM(M30,L30) -> 4748443.4 | T30: =SUM(N30)-SUM(O30:P30)-SUM(Q30:S30)*2 -> 4748443.4 | U30: =SUM(O30:T30) -> 4748443.4
A31: 204000 | B31: Property Mgt License | C31: ='BUDGET DETAIL'!A39 -> 35 | K31: TABLE 3 | L31: =VLOOKUP(C31,table3,12)+VLOOKUP(D31,table3,12)+VLOOKUP(E31,table3,12)+VLOOKUP(F31,table3,12)+VLOOKUP(G31,table3,12) -> 4683825 | N31: =SUM(M31,L31) -> 4683825 | T31: =SUM(N31)-SUM(O31:P31)-SUM(Q31:S31)*2 -> 4683825 | U31: =SUM(O31:T31) -> 4683825
A32: 201000 | B32: Assessmnt Collection | C32: ='BUDGET DETAIL'!A32 -> 28 | K32: TABLE 3 | L32: =VLOOKUP(C32,table3,12)+VLOOKUP(D32,table3,12)+VLOOKUP(E32,table3,12)+VLOOKUP(F32,table3,12)+VLOOKUP(G32,table3,12) -> 0 | N32: =SUM(M32,L32) -> 0 | T32: =SUM(N32)-SUM(O32:P32)-SUM(Q32:S32)*2 -> 0 | U32: =SUM(O32:T32) -> 0
A33: 209000 | B33: Convention & Tourism | C33: ='BUDGET DETAIL'!A41 -> 37 | K33: TABLE 3 | L33: =VLOOKUP(C33,table3,12)+VLOOKUP(D33,table3,12)+VLOOKUP(E33,table3,12)+VLOOKUP(F33,table3,12)+VLOOKUP(G33,table3,12) -> 3394785.2 | N33: =SUM(M33,L33) -> 3394785.2 | Q33: =+N33*0.5 -> 1697392.6 | T33: =SUM(N33)-SUM(O33:P33)-SUM(Q33:S33)*2 -> 0 | U33: =SUM(O33:T33) -> 1697392.6
A34: 215000 | B34: Parks Local Opt Levy | C34: ='BUDGET DETAIL'!A45 -> 41 | K34: TABLE 3 | L34: =VLOOKUP(C34,table3,12)+VLOOKUP(D34,table3,12)+VLOOKUP(E34,table3,12)+VLOOKUP(F34,table3,12)+VLOOKUP(G34,table3,12) -> 394304 | N34: =SUM(M34,L34) -> 394304 | Q34: =+N34*0.5 -> 197152 | T34: =SUM(N34)-SUM(O34:P34)-SUM(Q34:S34)*2 -> 0 | U34: =SUM(O34:T34) -> 197152
A35: 216000 | B35: Children Investment | C35: ='BUDGET DETAIL'!A46 -> 42 | K35: TABLE 3 | L35: =VLOOKUP(C35,table3,12)+VLOOKUP(D35,table3,12)+VLOOKUP(E35,table3,12)+VLOOKUP(F35,table3,12)+VLOOKUP(G35,table3,12) -> 13946517 | M35: 48701 | N35: =SUM(M35,L35) -> 13995218 | Q35: =+N35*0.5 -> 6997608.8 | T35: =SUM(N35)-SUM(O35:P35)-SUM(Q35:S35)*2 -> 0 | U35: =SUM(O35:T35) -> 6997608.8
A36: 403000 | B36: Public Safety | C36: ='BUDGET DETAIL'!A103 -> 99 | K36: TABLE 3 | L36: =VLOOKUP(C36,table3,12)+VLOOKUP(D36,table3,12)+VLOOKUP(E36,table3,12)+VLOOKUP(F36,table3,12)+VLOOKUP(G36,table3,12) -> 1838261.4 | N36: =SUM(M36,L36) -> 1838261.4 | R36: 0 | S36: =(VLOOKUP(C36,table3,12))/2 -> 919130.68 | T36: =SUM(N36)-SUM(O36:P36)-SUM(Q36:S36)*2 -> 0 | U36: =SUM(O36:T36) -> 919130.68
A37: 316000 | B37: Willamtte Ind URA DS | C37: ='BUDGET DETAIL'!A96 -> 92 | K37: TABLE 3 | L37: =VLOOKUP(C37,table3,12)+VLOOKUP(D37,table3,12)+VLOOKUP(E37,table3,12)+VLOOKUP(F37,table3,12)+VLOOKUP(G37,table3,12) -> 0 | N37: =SUM(M37,L37) -> 0 | R37: 0 | T37: =SUM(N37)-SUM(O37:P37)-SUM(Q37:S37)*2 -> 0 | U37: =SUM(O37:T37) -> 0
A38: 301000 | B38: River Dist URA DR | K38: TABLE 3 | L38: =VLOOKUP(C38,table3,12)+VLOOKUP(D38,table3,12)+VLOOKUP(E38,table3,12)+VLOOKUP(F38,table3,12)+VLOOKUP(G38,table3,12) -> 0 | N38: =SUM(M38,L38) -> 0 | R38: 0 | T38: =SUM(N38)-SUM(O38:P38)-SUM(Q38:S38)*2 -> 0 | U38: =SUM(O38:T38) -> 0
A39: 302000 | B39: Bonded Dbt Int&Sinkg | K39: TABLE 3 | L39: =VLOOKUP(C39,table3,12)+VLOOKUP(D39,table3,12)+VLOOKUP(E39,table3,12)+VLOOKUP(F39,table3,12)+VLOOKUP(G39,table3,12) -> 0 | N39: =SUM(M39,L39) -> 0 | R39: 0 | T39: =SUM(N39)-SUM(O39:P39)-SUM(Q39:S39)*2 -> 0 | U39: =SUM(O39:T39) -> 0
A40: 303000 | B40: DTWF Renwl Bd Sink | K40: TABLE 3 | L40: =VLOOKUP(C40,table3,12)+VLOOKUP(D40,table3,12)+VLOOKUP(E40,table3,12)+VLOOKUP(F40,table3,12)+VLOOKUP(G40,table3,12) -> 0 | N40: =SUM(M40,L40) -> 0 | R40: 0 | T40: =SUM(N40)-SUM(O40:P40)-SUM(Q40:S40)*2 -> 0 | U40: =SUM(O40:T40) -> 0
A41: 305000 | B41: Pension Debt Rdmpt | K41: TABLE 3 | L41: =VLOOKUP(C41,table3,12)+VLOOKUP(D41,table3,12)+VLOOKUP(E41,table3,12)+VLOOKUP(F41,table3,12)+VLOOKUP(G41,table3,12) -> 0 | N41: =SUM(M41,L41) -> 0 | R41: 0 | T41: =SUM(N41)-SUM(O41:P41)-SUM(Q41:S41)*2 -> 0 | U41: =SUM(O41:T41) -> 0
A42: 306000 | B42: SO Park Block Rdmpt | K42: TABLE 3 | L42: =VLOOKUP(C42,table3,12)+VLOOKUP(D42,table3,12)+VLOOKUP(E42,table3,12)+VLOOKUP(F42,table3,12)+VLOOKUP(G42,table3,12) -> 0 | N42: =SUM(M42,L42) -> 0 | R42: 0 | T42: =SUM(N42)-SUM(O42:P42)-SUM(Q42:S42)*2 -> 0 | U42: =SUM(O42:T42) -> 0
A43: 310000 | B43: Cntrl E Ind Distr DS | K43: TABLE 3 | L43: =VLOOKUP(C43,table3,12)+VLOOKUP(D43,table3,12)+VLOOKUP(E43,table3,12)+VLOOKUP(F43,table3,12)+VLOOKUP(G43,table3,12) -> 0 | N43: =SUM(M43,L43) -> 0 | R43: 0 | T43: =SUM(N43)-SUM(O43:P43)-SUM(Q43:S43)*2 -> 0 | U43: =SUM(O43:T43) -> 0
...

Sheet BUDGET DETAIL
B2: Fund | C2: Fund_Name | D2: Bureau | E2: Bureau_Name | F2: Type | G2: Personal | H2: EMS | I2: IMS | J2: CAPITAL_OUTLAY | K2: Debt_Service
A3: TABLE3
A4: 0
A5: 1 | B5: 100 | C5: General Fund | D5: AT | E5: Office of City Attorney | F5: Operating | G5: 0 | H5: 0 | I5: 0 | J5: 0 | K5: 0 | L5: 8387785.4
A6: =A5+1 -> 2 | B6: 100 | C6: General Fund | D6: AU | E6: Office of the City Auditor | F6: Operating | G6: 0 | H6: 0 | I6: 0 | J6: 0 | K6: 0 | L6: 6285473.2
A7: =A6+1 -> 3 | B7: 100 | C7: General Fund | D7: CB | E7: Cable Communications and Franchise Management | F7: Operating | G7: 0 | H7: 0 | I7: 0 | J7: 0 | K7: 0 | L7: 2173400.8
A8: =A7+1 -> 4 | B8: 100 | C8: General Fund | D8: EM | E8: Portland Office of Emergency Management | F8: Operating | G8: 0 | H8: 0 | I8: 0 | J8: 0 | K8: 0 | L8: 1273146.9
A9: =A8+1 -> 5 | B9: 100 | C9: General Fund | D9: FR | E9: Portland Fire and Rescue | F9: Capital | G9: 0 | H9: 0 | I9: 0 | J9: 0 | K9: 0 | L9: 513003.51
A10: =A9+1 -> 6 | B10: 100 | C10: General Fund | D10: FR | E10: Portland Fire and Rescue | F10: Operating | G10: 0 | H10: 0 | I10: 0 | J10: 0 | K10: 0 | L10: 89278598
A11: =A10+1 -> 7 | B11: 100 | C11: General Fund | D11: GR | E11: Office of Government Relations | F11: Operating | G11: 0 | H11: 0 | I11: 0 | J11: 0 | K11: 0 | L11: 1096031.6
A12: =A11+1 -> 8 | B12: 100 | C12: General Fund | D12: HC | E12: Portland Housing Bureau | F12: Operating | G12: 0 | H12: 0 | I12: 0 | J12: 0 | K12: 0 | L12: 11593972
A13: =A12+1 -> 9 | B13: 100 | C13: General Fund | D13: HN | E13: Office of Human Relations | F13: Operating | G13: 0 | H13: 0 | I13: 0 | J13: 0 | K13: 0 | L13: 230029.91
A14: =A13+1 -> 10 | B14: 100 | C14: General Fund | D14: MF | E14: Office of Management and Finance | F14: Operating | G14: 0 | H14: 0 | I14: 0 | J14: 0 | K14: 0 | L14: 37750743
A15: =A14+1 -> 11 | B15: 100 | C15: General Fund | D15: MF | E15: Office of Management and Finance | F15: Capital | G15: 0 | H15: 0 | I15: 0 | J15: 0 | K15: 0 | L15: 532438.52
A16: =A15+1 -> 12 | B16: 100 | C16: General Fund | D16: MY | E16: Office of the Mayor | F16: Operating | G16: 0 | H16: 0 | I16: 0 | J16: 0 | K16: 0 | L16: 3538476.9
A17: =A16+1 -> 13 | B17: 100 | C17: General Fund | D17: NI | E17: Office of Neighborhood Involvement | F17: Operating | G17: 0 | H17: 0 | I17: 0 | J17: 0 | K17: 0 | L17: 6193920.9
... A83: =A82+1 -> 79 | B83: 217 | C83: Grants Fund | D83: FR | E83: Portland Fire and Rescue | F83: Capital | G83: 0 | H83: 0 | I83: 0 | J83: 0 | K83: 0 | L83: 336467.38
A84: =A83+1 -> 80 | B84: 217 | C84: Grants Fund | D84: MY | E84: =#REF! -> #REF! | F84: Operating | G84: 0 | H84: 0 | I84: 0 | J84: 0 | K84: 0 | L84: 2412.5
A85: =A84+1 -> 81 | B85: 403 | C85: Public Safety GO Bond Fund | D85: FR | E85: Portland Fire & Rescue | F85: Capital | G85: 0 | H85: 0 | I85: 0 | J85: 0 | K85: 0 | L85: 431677.92
A86: =A85+1 -> 82 | B86: 604 | C86: Portland International Raceway Fund | D86: PK | E86: Portland Parks & Recreation | F86: Capital | G86: 0 | H86: 0 | I86: 0 | J86: 0 | K86: 0 | L86: 15885.05
A87: =A86+1 -> 83 | B87: 608 | C87: Environmental Remediation Fund | D87: ES | E87: Bureau of Environmental Services | F87: Capital | G87: 0 | H87: 0 | I87: 0 | J87: 0 | K87: 0 | L87: 60567
A88: =A87+1 -> 84 | B88: 308 | C88: Gas Tax Bond Redemption Fund | D88: TR | E88: Portland Bureau of Transportation | F88: Operating | G88: 0 | H88: 0 | I88: 0 | J88: 0 | K88: 0 | L88: 0
A89: =A88+1 -> 85 | B89: 309 | C89: Lents Town Ctr URA Debt Redemption Fund | D89: MF | E89: Office of Management and Finance | F89: Operating | G89: 0 | H89: 0 | I89: 0 | J89: 0 | K89: 0 | L89: 0
A90: =A89+1 -> 86 | B90: 310 | C90: Central Eastside Ind District Debt Service Fund | D90: MF | E90: Office of Management and Finance | F90: Operating | G90: 0 | H90: 0 | I90: 0 | J90: 0 | K90: 0 | L90: 0
A91: =A90+1 -> 87 | B91: 311 | C91: Bancroft Bond Interest and Sinking Fund | D91: AU | E91: Office of the City Auditor | F91: Operating | G91: 0 | H91: 0 | I91: 0 | J91: 0 | K91: 0 | L91: 0
A92: =A91+1 -> 88 | B92: 312 | C92: Convention Center Area Debt Service Fund | D92: MF | E92: Office of Management and Finance | F92: Operating | G92: 0 | H92: 0 | I92: 0 | J92: 0 | K92: 0 | L92: 0
A93: =A92+1 -> 89 | B93: 313 | C93: North Macadam URA Debt Redemption Fund | D93: MF | E93: Office of Management and Finance | F93: Operating | G93: 0 | H93: 0 | I93: 0 | J93: 0 | K93: 0 | L93: 0
A94: =A93+1 -> 90 | B94: 314 | C94: Special Projects Debt Service Fund | D94: MF | E94: Office of Management and Finance | F94: Operating | G94: 0 | H94: 0 | I94: 0 | J94: 0 | K94: 0 | L94: 0
A95: =A94+1 -> 91 | B95: 315 | C95: Gateway URA Debt Redemption Fund | D95: MF | E95: Office of Management and Finance | F95: Operating | G95: 0 | H95: 0 | I95: 0 | J95: 0 | K95: 0 | L95: 0
A96: =A95+1 -> 92 | B96: 316 | C96: Willamette Industrial URA Debt Service Fund | D96: MF | E96: Office of Management and Finance | F96: Operating | G96: 0 | H96: 0 | I96: 0 | J96: 0 | K96: 0 | L96: 0
... A140: =A139+1 -> 136 | B140: 802 | C140: Fire & Police Supplemental Retirement Res Fund | D140: MF | E140: Office of Management and Finance | F140: Operating | G140: 0 | H140: 0 | I140: 0 | J140: 0 | K140: 0 | L140: 8108.94
A141: =A140+1 -> 137
L142: =SUM(L5:L140) -> 1.4281886e+09
A153: TABLE4
A154: 1 | E154: MFOP000010 (Maintenance and Repair) | I154: 0 | L154: =SUM(G154:K154) -> 0
A155: =A154+1 -> 2 | E155: MFOP000042 (facilities) | G155: 178000.5 | H155: 2585852.4 | I155: 0 | L155: =SUM(G155:K155) -> 2763852.9
A156: =A155+1 -> 3 | E156: MFOP000045 (Portland Building) | I156: 0 | L156: =SUM(G156:K156) -> 0
A157: =A156+1 -> 4 | E157: MFOP000061 (Union Station) | G157: 50429.5 | H157: 1655748.8 | I157: 0 | L157: =SUM(G157:K157) -> 1706178.3
A158: =A157+1 -> 5 | E158: MFTS000028 (BTS) | H158: 110679.3 | I158: 0 | L158: =SUM(G158:K158) -> 110679.3
A161: TABLE5
...

Sheet ALLOCATION
A1: 12/13 | B1: =$A$1&+" CENTRAL SERVICES ALLOCATIONS" -> 12/13 CENTRAL SERVICES ALLOCATIONS
A4: SAP
A5: FUND NO. | C5: OPERATING BUREAUS/FUNDS
F8: NUMBER OF EMPLOYEES | L8: ADJUSTED BUDGET SIZE
D9: FY 09/10 | E9: FY 10/11 | F9: FY 2012 No. | G9: FY 11/12 | H9: THREE YEAR | J9: FY 09/10 | K9: FY 10/11 | L9: FY 2012 Adj | N9: THREE YEAR | P9: BLENDED
D10: % | E10: % | F10: of Employees | G10: % | H10: AVERAGE | I10: 0.25 | J10: % | K10: % | L10: Actual Expend. | N10: AVERAGE | O10: 0.75 | P10: FACTOR
A12: 100000 | B12: PL | C12: Portland Police Bureau | D12: 0.1950994 | E12: 0.18715826 | F12: 1207 | G12: =F12/$F$127 -> 0.19287312 | H12: =AVERAGE(G12,E12,D12) -> 0.19171026 | I12: =H12*$I$10 -> 0.047927565 | J12: 157297509 | K12: 1.2957383e+08 | L12: =BUDGETSIZE!U7 -> 1.4420687e+08 | M12: =((J12/$J$127)+(K12/$K$127)+(L12/$L$127))/3 -> 0.13342631 | N12: =M12/$M$127 -> 0.13342631 | O12: =$O$10*N12 -> 0.10006973 | P12: =(O12+I12) -> 0.1479973
A13: 214000 | C13: Campaign Finance | D13: 0 | E13: 0 | F13: 0 | G13: =F13/$F$127 -> 0 | H13: =AVERAGE(G13,E13,D13) -> 0 | I13: =H13*$I$10 -> 0 | J13: 0 | K13: 0 | L13: =BUDGETSIZE!U8 -> 0 | M13: =((J13/$J$127)+(K13/$K$127)+(L13/$L$127))/3 -> 0 | N13: =M13/$M$127 -> 0 | O13: =$O$10*N13 -> 0 | P13: =(O13+I13) -> 0
A14: 100000 | B14: FR | C14: Portland Fire & Rescue | D14: 0.11126522 | E14: 0.11951258 | F14: 750 | G14: =F14/$F$127 -> 0.1198466 | H14: =AVERAGE(G14,E14,D14) -> 0.1168748 | I14: =H14*$I$10 -> 0.029218699 | J14: 92615296 | K14: 85346907 | L14: =BUDGETSIZE!U9 -> 91478782 | M14: =((J14/$J$127)+(K14/$K$127)+(L14/$L$127))/3 -> 0.084031754 | N14: =M14/$M$127 -> 0.084031754 | O14: =$O$10*N14 -> 0.063023816 | P14: =(O14+I14) -> 0.092242515
A15: 100000 | B15: PK | C15: Portland Parks & Recreation | D15: 0.17013407 | E15: 0.16872364 | F15: 974 | G15: =F15/$F$127 -> 0.15564078 | H15: =AVERAGE(G15,E15,D15) -> 0.16483283 | I15: =H15*$I$10 -> 0.041208207 | J15: 60130076 | K15: 51967979 | L15: =BUDGETSIZE!U10 -> 55232036 | M15: =((J15/$J$127)+(K15/$K$127)+(L15/$L$127))/3 -> 0.051883339 | N15: =M15/$M$127 -> 0.051883339 | O15: =$O$10*N15 -> 0.038912505 | P15: =(O15+I15) -> 0.080120712
A16: 600000 | C16: Sewer System Op | D16: 0.073971336 | E16: 0.08467427 | F16: 534 | G16: =F16/$F$127 -> 0.085330777 | H16: =AVERAGE(G16,E16,D16) -> 0.081325461 | I16: =H16*$I$10 -> 0.020331365 | J16: 99640069 | K16: 1.6330032e+08 | L16: =BUDGETSIZE!U11 -> 1.0410587e+08 | M16: =((J16/$J$127)+(K16/$K$127)+(L16/$L$127))/3 -> 0.11710471 | N16: =M16/$M$127 -> 0.11710471 | O16: =$O$10*N16 -> 0.08782853 | P16: =(O16+I16) -> 0.1081599
A17: 608000 | C17: Envtl Remediation | D17: 0.0083217753 | E17: 0.00093735354 | F17: 3 | G17: =F17/$F$127 -> 0.00047938639 | H17: =AVERAGE(G17,E17,D17) -> 0.0032461717 | I17: =H17*$I$10 -> 0.00081154294 | J17: 5556186 | K17: 2744587.6 | L17: =BUDGETSIZE!U12 -> 3334817.2 | M17: =((J17/$J$127)+(K17/$K$127)+(L17/$L$127))/3 -> 0.0034524874 | N17: =M17/$M$127 -> 0.0034524874 | O17: =$O$10*N17 -> 0.0025893655 | P17: =(O17+I17) -> 0.0034009085
A18: 605000 | C18: Solid Waste Mgt | D18: 0.0033903529 | E18: 0.0042180909 | F18: 32 | G18: =F18/$F$127 -> 0.0051134548 | H18: =AVERAGE(G18,E18,D18) -> 0.0042406329 | I18: =H18*$I$10 -> 0.0010601582 | J18: 5397170 | K18: 3106227.1 | L18: =BUDGETSIZE!U13 -> 3494849.2 | M18: =((J18/$J$127)+(K18/$K$127)+(L18/$L$127))/3 -> 0.0035968227 | N18: =M18/$M$127 -> 0.0035968227 | O18: =$O$10*N18 -> 0.002697617 | P18: =(O18+I18) -> 0.0037577752
A19: 200000 | C19: Transportation Op | D19: 0.11126522 | E19: 0.11248242 | F19: 718 | G19: =F19/$F$127 -> 0.11473314 | H19: =AVERAGE(G19,E19,D19) -> 0.11282693 | I19: =H19*$I$10 -> 0.028206732 | J19: 180216986 | K19: 1.4721976e+08 | L19: =BUDGETSIZE!U14 -> 1.2247356e+08 | M19: =((J19/$J$127)+(K19/$K$127)+(L19/$L$127))/3 -> 0.1371764 | N19: =M19/$M$127 -> 0.1371764 | O19: =$O$10*N19 -> 0.1028823 | P19: =(O19+I19) -> 0.13108903
A20: 212000 | C20: Transportation Resv | D20: 0 | E20: 0 | F20: 0 | G20: =F20/$F$127 -> 0 | H20: =AVERAGE(G20,E20,D20) -> 0 | I20: =H20*$I$10 -> 0 | J20: 0 | K20: 0 | L20: =BUDGETSIZE!U15 -> 0 | M20: =((J20/$J$127)+(K20/$K$127)+(L20/$L$127))/3 -> 0 | N20: =M20/$M$127 -> 0 | O20: =$O$10*N20 -> 0 | P20: =(O20+I20) -> 0
A21: 614000 | C21: Sewer System Constr | D21: 0 | E21: 0 | F21: 0 | G21: =F21/$F$127 -> 0 | H21: =AVERAGE(G21,E21,D21) -> 0 | I21: =H21*$I$10 -> 0 | J21: 111275102 | K21: 0 | L21: =BUDGETSIZE!U16 -> 0 | M21: =((J21/$J$127)+(K21/$K$127)+(L21/$L$127))/3 -> 0.026323674 | N21: =M21/$M$127 -> 0.026323674 | O21: =$O$10*N21 -> 0.019742755 | P21: =(O21+I21) -> 0.019742755
A22: 609000 | C22: Sewer Sys Debt Rdmpt | D22: 0 | E22: 0 | F22: 0 | G22: =F22/$F$127 -> 0 | H22: =AVERAGE(G22,E22,D22) -> 0 | I22: =H22*$I$10 -> 0 | J22: 75647150 | K22: 0 | L22: =BUDGETSIZE!U17 -> 0 | M22: =((J22/$J$127)+(K22/$K$127)+(L22/$L$127))/3 -> 0.017895386 | N22: =M22/$M$127 -> 0.017895386 | O22: =$O$10*N22 -> 0.01342154 | P22: =(O22+I22) -> 0.01342154
A23: 602000 | C23: Water | D23: 0.097549699 | E23: 0.09670364 | F23: 595 | G23: =F23/$F$127 -> 0.0950783 | H23: =AVERAGE(G23,E23,D23) -> 0.09644388 | I23: =H23*$I$10 -> 0.02411097 | J23: 76779020 | K23: 79748481 | L23: =BUDGETSIZE!U18 -> 86834290 | M23: =((J23/$J$127)+(K23/$K$127)+(L23/$L$127))/3 -> 0.076694795 | N23: =M23/$M$127 -> 0.076694795 | O23: =$O$10*N23 -> 0.057521096 | P23: =(O23+I23) -> 0.081632066
A24: 615000 | C24: Water Construction | D24: 0 | E24: 0 | F24: 0 | G24: =F24/$F$127 -> 0 | H24: =AVERAGE(G24,E24,D24) -> 0 | I24: =H24*$I$10 -> 0 | J24: 36338000 | K24: 0 | L24: =BUDGETSIZE!U19 -> 0 | M24: =((J24/$J$127)+(K24/$K$127)+(L24/$L$127))/3 -> 0.0085962596 | N24: =M24/$M$127 -> 0.0085962596 | O24: =$O$10*N24 -> 0.0064471947 | P24: =(O24+I24) -> 0.0064471947
A25: 612000 | C25: Water Bond Sinking | D25: 0 | E25: 0 | F25: 0 | G25: =F25/$F$127 -> 0 | H25: =AVERAGE(G25,E25,D25) -> 0 | I25: =H25*$I$10 -> 0 | J25: 14153186 | K25: 0 | L25: =BUDGETSIZE!U20 -> 0 | M25: =((J25/$J$127)+(K25/$K$127)+(L25/$L$127))/3 -> 0.0033481331 | N25: =M25/$M$127 -> 0.0033481331 | O25: =$O$10*N25 -> 0.0025110998 | P25: =(O25+I25) -> 0.0025110998
A26: 607000 | C26: Spectator Fac Op | D26: 0 | E26: 0 | F26: 0 | G26: =F26/$F$127 -> 0 | H26: =AVERAGE(G26,E26,D26) -> 0 | I26: =H26*$I$10 -> 0 | J26: 10184872 | K26: 6818850.4 | L26: =BUDGETSIZE!U21 -> 1425933 | M26: =((J26/$J$127)+(K26/$K$127)+(L26/$L$127))/3 -> 0.0052717913 | N26: =M26/$M$127 -> 0.0052717913 | O26: =$O$10*N26 -> 0.0039538435 | P26: =(O26+I26) -> 0.0039538435
A27: 617000 | C27: Sewer Sys Rate Stblt | D27: 0 | E27: 0 | F27: 0 | G27: =F27/$F$127 -> 0 | H27: =AVERAGE(G27,E27,D27) -> 0 | I27: =H27*$I$10 -> 0 | J27: 0 | K27: 0 | L27: =BUDGETSIZE!U22 -> 0 | M27: =((J27/$J$127)+(K27/$K$127)+(L27/$L$127))/3 -> 0 | N27: =M27/$M$127 -> 0 | O27: =$O$10*N27 -> 0 | P27: =(O27+I27) -> 0
... A60: 100000 | C60: General Fund Transfers | D60: 0 | E60: 0 | F60: 0 | G60: =F60/$F$127 -> 0 | H60: =AVERAGE(G60,E60,D60) -> 0 | I60: =H60*$I$10 -> 0 | J60: 0 | K60: 0 | L60: =BUDGETSIZE!U55 -> 0 | M60: =((J60/$J$127)+(K60/$K$127)+(L60/$L$127))/3 -> 0 | N60: =M60/$M$127 -> 0 | O60: =$O$10*N60 -> 0 | P60: =(O60+I60) -> 0
A61: 100000 | B61: CB | C61: Community Technology | D61: 0.0013869626 | E61: 0.0014060303 | F61: 9 | G61: =F61/$F$127 -> 0.0014381592 | H61: =AVERAGE(G61,E61,D61) -> 0.001410384 | I61: =H61*$I$10 -> 0.000352596 | J61: 1816671 | K61: 868973 | L61: =BUDGETSIZE!U56 -> 2173400.8 | M61: =((J61/$J$127)+(K61/$K$127)+(L61/$L$127))/3 -> 0.0015058108 | N61: =M61/$M$127 -> 0.0015058108 | O61: =$O$10*N61 -> 0.0011293581 | P61: =(O61+I61) -> 0.0014819541
A62: 100000 | C62: Office of Sustainable Development (OSD) | D62: 0.0075512406 | E62: 0 | F62: 0 | G62: =F62/$F$127 -> 0 | H62: =AVERAGE(G62,E62,D62) -> 0.0025170802 | I62: =H62*$I$10 -> 0.00062927005 | J62: 0 | K62: 0 | L62: =BUDGETSIZE!U57 -> 0 | M62: =((J62/$J$127)+(K62/$K$127)+(L62/$L$127))/3 -> 0 | N62: =M62/$M$127 -> 0 | O62: =$O$10*N62 -> 0 | P62: =(O62+I62) -> 0.00062927005
A63: 206000 | C63: Cable | D63: 0 | E63: 0 | F63: 0 | G63: =F63/$F$127 -> 0 | H63: =AVERAGE(G63,E63,D63) -> 0 | I63: =H63*$I$10 -> 0 | J63: 2563138 | K63: 2134040.6 | L63: =BUDGETSIZE!U58 -> 2657851.2 | M63: =((J63/$J$127)+(K63/$K$127)+(L63/$L$127))/3 -> 0.0022919809 | N63: =M63/$M$127 -> 0.0022919809 | O63: =$O$10*N63 -> 0.0017189857 | P63: =(O63+I63) -> 0.0017189857
A64: 100000 | B64: HN | C64: Office of Human Relations | D64: 0.0006164278 | E64: 0.00062490236 | F64: 3 | G64: =F64/$F$127 -> 0.00047938639 | H64: =AVERAGE(G64,E64,D64) -> 0.00057357218 | I64: =H64*$I$10 -> 0.00014339305 | J64: 589509 | K64: 485302.81 | L64: =BUDGETSIZE!U59 -> 230029.91 | M64: =((J64/$J$127)+(K64/$K$127)+(L64/$L$127))/3 -> 0.00038908336 | N64: =M64/$M$127 -> 0.00038908336 | O64: =$O$10*N64 -> 0.00029181252 | P64: =(O64+I64) -> 0.00043520557
A65: 100000 | C65: General Fund Revenues/Balance | D65: 0 | E65: 0 | F65: 0 | G65: =F65/$F$127 -> 0 | H65: =AVERAGE(G65,E65,D65) -> 0 | I65: =H65*$I$10 -> 0 | J65: 0 | K65: 0 | L65: =BUDGETSIZE!U60 -> 0 | M65: =((J65/$J$127)+(K65/$K$127)+(L65/$L$127))/3 -> 0 | N65: =M65/$M$127 -> 0 | O65: =$O$10*N65 -> 0 | P65: =(O65+I65) -> 0
A66: 100000 | C66: Business Licenses | D66: 0 | E66: 0 | F66: 0 | G66: =F66/$F$127 -> 0 | H66: =AVERAGE(G66,E66,D66) -> 0 | I66: =H66*$I$10 -> 0 | J66: 0 | K66: 0 | L66: =BUDGETSIZE!U61 -> 0 | M66: =((J66/$J$127)+(K66/$K$127)+(L66/$L$127))/3 -> 0 | N66: =M66/$M$127 -> 0 | O66: =$O$10*N66 -> 0 | P66: =(O66+I66) -> 0
A67: 208000 | C67: Business Lic Surchg | D67: 0 | E67: 0 | F67: 0 | G67: =F67/$F$127 -> 0 | H67: =AVERAGE(G67,E67,D67) -> 0 | I67: =H67*$I$10 -> 0 | J67: 0 | K67: 0 | L67: =BUDGETSIZE!U62 -> 0 | M67: =((J67/$J$127)+(K67/$K$127)+(L67/$L$127))/3 -> 0 | N67: =M67/$M$127 -> 0 | O67: =$O$10*N67 -> 0 | P67: =(O67+I67) -> 0
A68: 207000 | C68: Prvt Hire TR Safety | D68: 0 | E68: 0 | F68: 0 | G68: =F68/$F$127 -> 0 | H68: =AVERAGE(G68,E68,D68) -> 0 | I68: =H68*$I$10 -> 0 | J68: 15000 | K68: 0 | L68: =BUDGETSIZE!U63 -> 0 | M68: =((J68/$J$127)+(K68/$K$127)+(L68/$L$127))/3 -> 3.5484588e-06 | N68: =M68/$M$127 -> 3.5484588e-06 | O68: =$O$10*N68 -> 2.6613441e-06 | P68: =(O68+I68) -> 2.6613441e-06
A69: 100000 | B69: NI | C69: Office of Neighborhood Involvement | D69: 0.0070889197 | E69: 0.0073426027 | F69: 46 | G69: =F69/$F$127 -> 0.0073505912 | H69: =AVERAGE(G69,E69,D69) -> 0.0072607046 | I69: =H69*$I$10 -> 0.0018151761 | J69: 6439822 | K69: 5925598.8 | L69: =BUDGETSIZE!U64 -> 6203280.8 | M69: =((J69/$J$127)+(K69/$K$127)+(L69/$L$127))/3 -> 0.0057836827 | N69: =M69/$M$127 -> 0.0057836827 | O69: =$O$10*N69 -> 0.004337762 | P69: =(O69+I69) -> 0.0061529381
A70: 100000 | C70: General Services | D70: 0 | E70: 0 | F70: 0 | G70: =F70/$F$127 -> 0 | H70: =AVERAGE(G70,E70,D70) -> 0 | I70: =H70*$I$10 -> 0 | J70: 200320 | K70: 193750 | L70: =BUDGETSIZE!U65 -> 247782.87 | M70: =((J70/$J$127)+(K70/$K$127)+(L70/$L$127))/3 -> 0.00020274036 | N70: =M70/$M$127 -> 0.00020274036 | O70: =$O$10*N70 -> 0.00015205527 | P70: =(O70+I70) -> 0.00015205527
A71: 100000 | C71: Utility Billing Sys Implent | D71: 0 | E71: 0 | F71: 0 | G71: =F71/$F$127 -> 0 | H71: =AVERAGE(G71,E71,D71) -> 0 | I71: =H71*$I$10 -> 0 | J71: 1576023 | K71: 973016 | L71: =BUDGETSIZE!U66 -> 1051576.9 | M71: =((J71/$J$127)+(K71/$K$127)+(L71/$L$127))/3 -> 0.0010841594 | N71: =M71/$M$127 -> 0.0010841594 | O71: =$O$10*N71 -> 0.00081311955 | P71: =(O71+I71) -> 0.00081311955
A72: 703000 | C72: P&D Srvcs Operating | D72: 0.0041608877 | E72: 0.0037494142 | F72: 24 | G72: =F72/$F$127 -> 0.0038350911 | H72: =AVERAGE(G72,E72,D72) -> 0.003915131 | I72: =H72*$I$10 -> 0.00097878274 | J72: 6668958 | K72: 5599834.3 | L72: =BUDGETSIZE!U67 -> 5514266.5 | M72: =((J72/$J$127)+(K72/$K$127)+(L72/$L$127))/3 -> 0.0054794044 | N72: =M72/$M$127 -> 0.0054794044 | O72: =$O$10*N72 -> 0.0041095533 | P72: =(O72+I72) -> 0.0050883361
A73: 100000 | B73: OE | C73: ='BUDGET DETAIL'!E82 -> Office of Equity & Human Rights | D73: 0 | E73: 0 | F73: 0 | G73: =F73/$F$127 -> 0 | H73: =AVERAGE(G73,E73,D73) -> 0 | I73: =H73*$I$10 -> 0 | J73: 0 | K73: 0 | L73: =BUDGETSIZE!U68 -> 375051.66 | M73: =((J73/$J$127)+(K73/$K$127)+(L73/$L$127))/3 -> 0.00013393922 | N73: =M73/$M$127 -> 0.00013393922 | O73: =$O$10*N73 -> 0.00010045441 | P73: =(O73+I73) -> 0.00010045441
A74: 100000 | C74: Revenue Bureau | D74: 0.010325166 | E74: 0.010154663 | F74: 67 | G74: =F74/$F$127 -> 0.010706296 | H74: =AVERAGE(G74,E74,D74) -> 0.010395375 | I74: =H74*$I$10 -> 0.0025988437 | J74: 9942050 | K74: 7041094.7 | L74: =BUDGETSIZE!U69 -> 7398354.2 | M74: =((J74/$J$127)+(K74/$K$127)+(L74/$L$127))/3 -> 0.0074239283 | N74: =M74/$M$127 -> 0.0074239283 | O74: =$O$10*N74 -> 0.0055679462 | P74: =(O74+I74) -> 0.0081667899
A75: 100000 | C75: Special Appropriations | D75: 0 | E75: 0 | F75: 0 | G75: =F75/$F$127 -> 0 | H75: =AVERAGE(G75,E75,D75) -> 0 | I75: =H75*$I$10 -> 0 | J75: 11168785 | K75: 6476768.1 | L75: =BUDGETSIZE!U70 -> 6476768.1 | M75: =((J75/$J$127)+(K75/$K$127)+(L75/$L$127))/3 -> 0.0071902616 | N75: =M75/$M$127 -> 0.0071902616 | O75: =$O$10*N75 -> 0.0053926962 | P75: =(O75+I75) -> 0.0053926962
A76: 220000 | C76: Portland Park Mem Tr | D76: 0 | E76: 0 | F76: 0 | G76: =F76/$F$127 -> 0 | H76: =AVERAGE(G76,E76,D76) -> 0 | I76: =H76*$I$10 -> 0 | J76: 53252 | K76: 0 | L76: =BUDGETSIZE!U71 -> 0 | M76: =((J76/$J$127)+(K76/$K$127)+(L76/$L$127))/3 -> 1.2597502e-05 | N76: =M76/$M$127 -> 1.2597502e-05 | O76: =$O$10*N76 -> 9.4481263e-06 | P76: =(O76+I76) -> 9.4481263e-06
A77: 500000 | C77: Parks Endowment | D77: 0 | E77: 0 | F77: 0 | G77: =F77/$F$127 -> 0 | H77: =AVERAGE(G77,E77,D77) -> 0 | I77: =H77*$I$10 -> 0 | J77: 0 | K77: 225 | L77: =BUDGETSIZE!U72 -> 0 | M77: =((J77/$J$127)+(K77/$K$127)+(L77/$L$127))/3 -> 7.7647524e-08 | N77: =M77/$M$127 -> 7.7647524e-08 | O77: =$O$10*N77 -> 5.8235643e-08 | P77: =(O77+I77) -> 5.8235643e-08
...

Sheet ACTUAL EXP
A1: CITY OF PORTLAND
A2: FY 11/12 GENERAL FUND OVERHEAD "TRUE-UP"
A3: BASED ON ACTUAL EXPENDITURES
A4: USING FY 11/12 DATA
A5: 0.99
D6: BUREAU COST CATEGORIES
G8: ALLOCABLE
D9: TOTAL | E9: INTERNAL | F9: OUTSIDE | G9: OVERHEAD
B10: COST CENTERS | D10: EXPENSE | E10: REVENUE | F10: REVENUE | G10: COSTS
A12: ATTORNEY
B13: AT Office of City Attorney | D13: =5339928*A5 -> 5286528.7 | E13: 0 | F13: 0 | G13: =+D13-E13-F13 -> 5286528.7
A14: AUDITOR
B15: AUDA000001 Management | D15: =8612471*A5 -> 8526346.3 | E15: 0 | F15: 0 | G15: =+D15-E15-F15 -> 8526346.3
B16: AUCA000002 Ind Police Review | D16: 0 | E16: 0 | F16: 0 | G16: =+D16-E16-F16 -> 0
B17: AUDA000002 Council/Contracts | D17: 0 | E17: 0 | F17: 0 | G17: =+D17-E17-F17 -> 0
B18: AUDA000004 Assmts/Fin/Foreclose | D18: 0 | E18: 0 | F18: 0 | G18: =+D18-E18-F18 -> 0
B19: AUCA000003 Progress Board | D19: 0 | E19: 0 | F19: 0 | G19: =+D19-E19-F19 -> 0
B20: AUCA000005 Hearings Officer | D20: 0 | E20: 0 | F20: 0 | G20: =+D20-E20-F20 -> 0
B21: Public involvement best practices | D21: =95752.74*1.027 -> 98338.064 | E21: 0 | F21: 0 | G21: =+D21-E21-F21 -> 98338.064
B22: AUCA000004 Ombudsman Office | D22: 0 | E22: 0 | F22: 0 | G22: =+D22-E22-F22 -> 0
B23: AUCA000006 City Auditor | D23: 0 | E23: 0 | F23: 0 | G23: =+D23-E23-F23 -> 0
A24: AUDIT SERVICES
B25: LAAUAU00000000GL | D25: 0 | E25: 0 | F25: 0 | G25: =+D25-E25-F25 -> 0
B26: LAAUAUPD000000GL | D26: 0 | E26: 0 | F26: 0 | G26: =+D26-E26-F26 -> 0
B27: RECORDS MANAGERMENT | D27: 0 | E27: 0 | F27: 0 | G27: =+D27-E27-F27 -> 0
B28: AUDA000003 Archives & Records | D28: 0 | E28: 0 | F28: 0 | G28: =+D28-E28-F28 -> 0
A29: CITY COUNCIL
B30: PW Commissioner of Public Works | D30: =865896*A5 -> 857237.04 | E30: 0 | F30: 0 | G30: =+D30-E30-F30 -> 857237.04
B31: PS Commissioner of Public Safety | D31: =819242*A5 -> 811049.58 | E31: 0 | F31: 0 | G31: =+D31-E31-F31 -> 811049.58
B32: PA Commissioner of Public Affairs | D32: =1641395*0.666*A5 -> 1082237.4 | E32: 0 | F32: =420.93-420.93 -> 0 | G32: =+D32-E32-F32 -> 1082237.4
B33: PU Commissioner of Public Utilities | D33: =837912*A5 -> 829532.88 | E33: 0 | F33: 0 | G33: =+D33-E33-F33 -> 829532.88
B34: MY Office of the Mayor | D34: =2874982*A5 -> 2846232.2 | E34: 0 | F34: 0 | G34: =+D34-E34-F34 -> 2846232.2
B35: GR Office of Governmental Relations | D35: =1238725*A5 -> 1226337.8 | E35: 0 | F35: 0 | G35: =+D35-E35-F35 -> 1226337.8
A36: PLANNING
B37: Comprehensive Planning | D37: =150820.53*1.027 -> 154892.68 | E37: 0 | F37: 0 | G37: =+D37-E37-F37 -> 154892.68
B38: Governmental Coordination | D38: =115820.48*1.027 -> 118947.63 | E38: 0 | F38: 0 | G38: =+D38-E38-F38 -> 118947.63
B39: District Planning CAPD10000 | D39: =(1276723*1.027)/2 -> 655597.26 | E39: 0 | F39: 0 | G39: =+D39-E39-F39 -> 655597.26
A40: ONI
B41: NIIR Information & Referral | D41: =519862.03*1.027 -> 533898.3 | E41: 0 | F41: =249095*1.027 -> 255820.56 | G41: =+D41-E41-F41 -> 278077.74
A42: PURCHASING
...

Sheet SCH D
A1: Schedule D | B1: FY 13-14 G.F. Overhead | AM1: SPECIAL | AN1: FY 11/12 | AQ1: FY 2013/14 | AS1: INCREASE
B2: BASED ON TARGET AMOUNTS | J2: OMF/ | M2: PUBLIC | P2: OMF | V2: BUREAU | W2: CITY | AC2: BUREAU TOTAL | AG2: CITY-WIDE | AK2: OFFICE OF | AM2: APPROPS | AN2: TOTAL | AQ2: OVERHEAD | AS2: (DECREASE)
A3: =NOW() -> 41276.678 | G3: AUDITOR | J3: FINANCIAL | K3: OMF | M3: INVOLVEMENT | O3: OMF | P3: ACCOUNTING | V3: ALLOCATION | W3: COUNCIL | X3: POEM | Y3: OMF | Z3: ATTORNEY | AA3: PURCHASING | AB3: AUDITOR | AC3: BEFORE | AD3: BUREAU | AE3: PLANNING | AG3: I & R | AI3: OEM | AK3: EQUITY | AL3: SPECIAL | AM3: COUNCIL | AN3: ALLOCATION | AO3: ADJUSTMENTS | AQ3: FOR PROPOSED | AS3: ACTUAL
C4: CITY | E4: AUDIT | F4: RECORDS | G4: SPECIFIC | H4: CITY | J4: SERVICES | K4: FINANCIAL | L4: OMF | M4: BEST | O4: ACCOUNTING | P4: AP WITH | R4: HR | S4: HR | T4: HR | U4: HR | V4: BEFORE | W4: INDIRECT | X4: INDIRECT | Y4: INDIRECT | Z4: INDIRECT | AA4: INDIRECT | AB4: INDIRECT | AC4: OTHER COST | AD4: OF | AE4: INDIRECT | AF4: CITY WIDE | AG4: INDIRECT | AI4: INDIRECT | AJ4: OFFICE OF | AK4: INDIRECT | AL4: APPROPS | AM4: INDIRECT | AN4: ALL | AO4: FOR BUDGET | AP4: ADJ | AQ4: BUDGET USING | AS4: OVER
A5: SAP Fund | B5: OPERATING BUREAUS/FUNDS | C5: ATTORNEY | D5: AUDITOR | E5: SERVICES | F5: MANAGEMENT | G5: ALLOCATIONS | H5: COUNCIL | I5: PURCHASING | J5: ADMIN | K5: PLANNING | L5: GRANTS | M5: PRACTICES | N5: ACCOUNTING | O5: PAYROLL | P5: DISCOUNT | Q5: POEM | R5: ORG 41..49 | S5: ORG 50 | T5: ORG 51 | U5: ORG 52 | V5: INDIRECT | W5: ALLOCATION | X5: ALLOCATION | Y5: ALLOCATION | Z5: ALLOCATION | AA5: ALLOCATION | AB5: ALLOCATION | AC5: ALLOCATIONS | AD5: PLANNING | AE5: ALLOCATION | AF5: I & R | AG5: ALLOCATION | AH5: OEM | AI5: ALLOCATION | AJ5: EQUITY | AK5: ALLOCATION | AL5: COUNCIL | AM5: ALLOCATION | AN5: BUREAUS | AO5: PURPOSES | AP5: CODE | AQ5: TARGET NOS. | AS5: BUDGET
A8: =ALLOCATION!A12 -> 100000 | B8: =ALLOCATION!C12 -> Portland Police Bureau | C8: ='ACTUAL EXP'!$G$13*(ALLOCATION!P12) -> 782391.97 | D8: =(SUM('ACTUAL EXP'!$G$15,'ACTUAL EXP'!$G$17:$G$19,'ACTUAL EXP'!$G$22))*ALLOCATION!P12 -> 1261876.2 | E8: =(('ACTUAL EXP'!$G$25)*(ALLOCATION!P12)) -> 0 | F8: ='ACTUAL EXP'!$G$28*ALLOCATION!P12 -> 0 | G8: ='ACTUAL EXP'!$G$16+'ACTUAL EXP'!$G$20*0.25 -> 0 | H8: =SUM('ACTUAL EXP'!$G$30:$G$35)*ALLOCATION!P12 -> 1132568.1 | I8: =SUM('ACTUAL EXP'!$G$43:$G$47)*ALLOCATION!P12 -> 684105.74 | J8: =(SUM('ACTUAL EXP'!$G$49:$G$50)*ALLOCATION!P12*0.5)+(SUM('ACTUAL EXP'!$G$49:$G$50)*ALLOCATION!P12*0.5) -> 328177.86 | K8: =SUM('ACTUAL EXP'!$G$52:$G$53)*ALLOCATION!P12 -> 346346.06 | L8: =SUM('ACTUAL EXP'!$G$54:$G$54)*ALLOCATION!P12 -> 47229.008 | M8: =SUM('ACTUAL EXP'!$G$21:$G$21)*ALLOCATION!P12 -> 14553.768 | N8: =SUM('ACTUAL EXP'!$G$58:$G$62)*0.39*ALLOCATION!P12 -> 231787.54 | O8: =SUM('ACTUAL EXP'!$G$58:$G$62)*0.27*ALLOCATION!P12 -> 160468.3 | P8: =SUM('ACTUAL EXP'!$G$58:$G$62)*0.34*ALLOCATION!P12 -> 202071.19 | Q8: ='ACTUAL EXP'!$G$85*ALLOCATION!P12 -> 307565.07 | R8: =SUM('ACTUAL EXP'!$G$68:$G$73)*ALLOCATION!P12 -> 838881.95 | S8: =SUM('ACTUAL EXP'!$G$75)*ALLOCATION!P12 -> 117482.63 | T8: =SUM('ACTUAL EXP'!$G$77)*ALLOCATION!P12 -> 77138.62 | U8: =SUM('ACTUAL EXP'!$G$79)*ALLOCATION!P12 -> 116902.71 | V8: =SUM(C8:U8) -> 6649546.7 | W8: =-(H8/$H$111)*($W$117) -> 59889.802 | X8: =-(Q8/$Q$111)*($X$118) -> 43850.657 | Y8: =-(SUM(J8:O8,R8:U8)/SUM($J$111:$O$111,$R$111:$U$111))*$Y$119 -> 139817.76 | Z8: =-(C8/$C$111)*($Z$120) -> 57347.624 | AA8: =-(I8/$I$111)*($AA$121) -> 22326.431 | AB8: =-(SUM(D8:G8)/SUM($D$111:$G$111))*SUM($AB$117:$AB$122) -> 48581.033 | AC8: =SUM(V8:AB8) -> 7021360 | AD8: =SUM('ACTUAL EXP'!$G$37:$G$39)*ALLOCATION!P12 -> 137554.25 | AE8: =(AD8/$AD$111)*SUM($AD$117:$AD$122) -> 7691.4266 | AF8: =SUM('ACTUAL EXP'!$G$41)*ALLOCATION!P12 -> 41154.754 | AG8: =(AF8/$AF$111)*SUM($AF$117:$AF$122) -> 2301.1922 | AH8: =SUM('ACTUAL EXP'!$G$81)*ALLOCATION!P12 -> 17142.556 | AI8: =(AH8/$AH$111)*SUM($AH$117:$AH$122) -> 958.53607 | AJ8: =SUM('ACTUAL EXP'!$G$83)*ALLOCATION!P12 -> 127277.68 | AK8: =(AJ8/$AH$111)*SUM($AH$117:$AH$122) -> 7116.806 | AL8: =SUM('ACTUAL EXP'!$G$64:$G$66)*ALLOCATION!P12 -> 41100.015 | AM8: =(AL8/$AL$111)*SUM($AL$117:$AL$122) -> 2298.1314 | AN8: =SUM(AC8:AM8) -> 7405955.4 | AQ8: =SUM(AO8,AN8) -> 7405955.4 | AS8: =AQ8-AR8 -> 7405955.4
A9: =ALLOCATION!A13 -> 214000 | B9: =ALLOCATION!C13 -> Campaign Finance | C9: ='ACTUAL EXP'!$G$13*(ALLOCATION!P13) -> 0 | D9: =(SUM('ACTUAL EXP'!$G$15,'ACTUAL EXP'!$G$17:$G$19,'ACTUAL EXP'!$G$22))*ALLOCATION!P13 -> 0 | E9: =(('ACTUAL EXP'!$G$25)*(ALLOCATION!P13)) -> 0 | F9: ='ACTUAL EXP'!$G$28*ALLOCATION!P13 -> 0 | G9: 0 | H9: =SUM('ACTUAL EXP'!$G$30:$G$35)*ALLOCATION!P13 -> 0 | I9: =SUM('ACTUAL EXP'!$G$43:$G$47)*ALLOCATION!P13 -> 0 | J9: =(SUM('ACTUAL EXP'!$G$49:$G$50)*ALLOCATION!P13*0.5)+(SUM('ACTUAL EXP'!$G$49:$G$50)*ALLOCATION!P13*0.5) -> 0 | K9: =SUM('ACTUAL EXP'!$G$52:$G$53)*ALLOCATION!P13 -> 0 | L9: =SUM('ACTUAL EXP'!$G$54:$G$54)*ALLOCATION!P13 -> 0 | M9: =SUM('ACTUAL EXP'!$G$21:$G$21)*ALLOCATION!P13 -> 0 | N9: =SUM('ACTUAL EXP'!$G$58:$G$62)*0.39*ALLOCATION!P13 -> 0 | O9: =SUM('ACTUAL EXP'!$G$58:$G$62)*0.27*ALLOCATION!P13 -> 0 | P9: =SUM('ACTUAL EXP'!$G$58:$G$62)*0.34*ALLOCATION!P13 -> 0 | Q9: ='ACTUAL EXP'!$G$85*ALLOCATION!P13 -> 0 | R9: =SUM('ACTUAL EXP'!$G$68:$G$73)*ALLOCATION!P13 -> 0 | S9: =SUM('ACTUAL EXP'!$G$75)*ALLOCATION!P13 -> 0 | T9: =SUM('ACTUAL EXP'!$G$77)*ALLOCATION!P13 -> 0 | U9: =SUM('ACTUAL EXP'!$G$79)*ALLOCATION!P13 -> 0 | V9: =SUM(C9:U9) -> 0 | W9: =-(H9/$H$111)*($W$117) -> 0 | X9: =-(Q9/$Q$111)*($X$118) -> 0 | Y9: =-(SUM(J9:O9,R9:U9)/SUM($J$111:$O$111,$R$111:$U$111))*$Y$119 -> 0 | Z9: =-(C9/$C$111)*($Z$120) -> 0 | AA9: =-(I9/$I$111)*($AA$121) -> 0 | AB9: =-(SUM(D9:G9)/SUM($D$111:$G$111))*SUM($AB$117:$AB$122) -> 0 | AC9: =SUM(V9:AB9) -> 0 | AD9: =SUM('ACTUAL EXP'!$G$37:$G$39)*ALLOCATION!P13 -> 0 | AE9: =(AD9/$AD$111)*SUM($AD$117:$AD$122) -> 0 | AF9: =SUM('ACTUAL EXP'!$G$41)*ALLOCATION!P13 -> 0 | AG9: =(AF9/$AF$111)*SUM($AF$117:$AF$122) -> 0 | AH9: =SUM('ACTUAL EXP'!$G$81)*ALLOCATION!P13 -> 0 | AI9: =(AH9/$AH$111)*SUM($AH$117:$AH$122) -> 0 | AJ9: =SUM('ACTUAL EXP'!$G$83)*ALLOCATION!P13 -> 0 | AK9: =(AJ9/$AH$111)*SUM($AH$117:$AH$122) -> 0 | AL9: =SUM('ACTUAL EXP'!$G$64:$G$66)*ALLOCATION!P13 -> 0 | AM9: =(AL9/$AL$111)*SUM($AL$117:$AL$122) -> 0 | AN9: =SUM(AC9:AM9) -> 0 | AQ9: =SUM(AO9,AN9) -> 0 | AS9: =AQ9-AR9 -> 0
A10: =ALLOCATION!A14 -> 100000 | B10: =ALLOCATION!C14 -> Portland Fire & Rescue | C10: ='ACTUAL EXP'!$G$13*(ALLOCATION!P14) -> 487642.7 | D10: =(SUM('ACTUAL EXP'!$G$15,'ACTUAL EXP'!$G$17:$G$19,'ACTUAL EXP'!$G$22))*ALLOCATION!P14 -> 786491.62 | E10: =(('ACTUAL EXP'!$G$25)*(ALLOCATION!P14)) -> 0 | F10: ='ACTUAL EXP'!$G$28*ALLOCATION!P14 -> 0 | G10: 0 | H10: =SUM('ACTUAL EXP'!$G$30:$G$35)*ALLOCATION!P14 -> 705897.54 | I10: =SUM('ACTUAL EXP'!$G$43:$G$47)*ALLOCATION!P14 -> 426383.69 | J10: =(SUM('ACTUAL EXP'!$G$49:$G$50)*ALLOCATION!P14*0.5)+(SUM('ACTUAL EXP'!$G$49:$G$50)*ALLOCATION!P14*0.5) -> 204543.94 | K10: =SUM('ACTUAL EXP'!$G$52:$G$53)*ALLOCATION!P14 -> 215867.67 | L10: =SUM('ACTUAL EXP'!$G$54:$G$54)*ALLOCATION!P14 -> 29436.5 | M10: =SUM('ACTUAL EXP'!$G$21:$G$21)*ALLOCATION!P14 -> 9070.9503 | N10: =SUM('ACTUAL EXP'!$G$58:$G$62)*0.39*ALLOCATION!P14 -> 144466.59 | O10: =SUM('ACTUAL EXP'!$G$58:$G$62)*0.27*ALLOCATION!P14 -> 100015.33 | P10: =SUM('ACTUAL EXP'!$G$58:$G$62)*0.34*ALLOCATION!P14 -> 125945.23 | Q10: ='ACTUAL EXP'!$G$85*ALLOCATION!P14 -> 191696.58 | R10: =SUM('ACTUAL EXP'!$G$68:$G$73)*ALLOCATION!P14 -> 522851.3 | S10: =SUM('ACTUAL EXP'!$G$75)*ALLOCATION!P14 -> 73223.59 | T10: =SUM('ACTUAL EXP'!$G$77)*ALLOCATION!P14 -> 48078.312 | U10: =SUM('ACTUAL EXP'!$G$79)*ALLOCATION!P14 -> 72862.142 | V10: =SUM(C10:U10) -> 4144473.7 | W10: =-(H10/$H$111)*($W$117) -> 37327.614 | X10: =-(Q10/$Q$111)*($X$118) -> 27330.87 | Y10: =-(SUM(J10:O10,R10:U10)/SUM($J$111:$O$111,$R$111:$U$111))*$Y$119 -> 87144.439 | Z10: =-(C10/$C$111)*($Z$120) -> 35743.146 | AA10: =-(I10/$I$111)*($AA$121) -> 13915.431 | AB10: =-(SUM(D10:G10)/SUM($D$111:$G$111))*SUM($AB$117:$AB$122) -> 30279.179 | AC10: =SUM(V10:AB10) -> 4376214.4 | AD10: =SUM('ACTUAL EXP'!$G$37:$G$39)*ALLOCATION!P14 -> 85733.66 | AE10: =(AD10/$AD$111)*SUM($AD$117:$AD$122) -> 4793.8479 | AF10: =SUM('ACTUAL EXP'!$G$41)*ALLOCATION!P14 -> 25650.59 | AG10: =(AF10/$AF$111)*SUM($AF$117:$AF$122) -> 1434.2678 | AH10: =SUM('ACTUAL EXP'!$G$81)*ALLOCATION!P14 -> 10684.468 | AI10: =(AH10/$AH$111)*SUM($AH$117:$AH$122) -> 597.42832 | AJ10: =SUM('ACTUAL EXP'!$G$83)*ALLOCATION!P14 -> 79328.563 | AK10: =(AJ10/$AH$111)*SUM($AH$117:$AH$122) -> 4435.7031 | AL10: =SUM('ACTUAL EXP'!$G$64:$G$66)*ALLOCATION!P14 -> 25616.472 | AM10: =(AL10/$AL$111)*SUM($AL$117:$AL$122) -> 1432.3601 | AN10: =SUM(AC10:AM10) -> 4615921.7 | AQ10: =SUM(AO10,AN10) -> 4615921.7 | AS10: =AQ10-AR10 -> 4615921.7
A11: =ALLOCATION!A15 -> 100000 | B11: =ALLOCATION!C15 -> Portland Parks & Recreation | C11: ='ACTUAL EXP'!$G$13*(ALLOCATION!P15) -> 423560.45 | D11: =(SUM('ACTUAL EXP'!$G$15,'ACTUAL EXP'!$G$17:$G$19,'ACTUAL EXP'!$G$22))*ALLOCATION!P15 -> 683136.94 | E11: =(('ACTUAL EXP'!$G$25)*(ALLOCATION!P15)) -> 0 | F11: ='ACTUAL EXP'!$G$28*ALLOCATION!P15 -> 0 | G11: 0 | H11: =SUM('ACTUAL EXP'!$G$30:$G$35)*ALLOCATION!P15 -> 613133.91 | I11: =SUM('ACTUAL EXP'!$G$43:$G$47)*ALLOCATION!P15 -> 370351.62 | J11: =(SUM('ACTUAL EXP'!$G$49:$G$50)*ALLOCATION!P15*0.5)+(SUM('ACTUAL EXP'!$G$49:$G$50)*ALLOCATION!P15*0.5) -> 177664.35 | K11: =SUM('ACTUAL EXP'!$G$52:$G$53)*ALLOCATION!P15 -> 187500 | L11: =SUM('ACTUAL EXP'!$G$54:$G$54)*ALLOCATION!P15 -> 25568.181 | M11: =SUM('ACTUAL EXP'!$G$21:$G$21)*ALLOCATION!P15 -> 7878.9157 | N11: =SUM('ACTUAL EXP'!$G$58:$G$62)*0.39*ALLOCATION!P15 -> 125481.9 | O11: =SUM('ACTUAL EXP'!$G$58:$G$62)*0.27*ALLOCATION!P15 -> 86872.086 | P11: =SUM('ACTUAL EXP'!$G$58:$G$62)*0.34*ALLOCATION!P15 -> 109394.48 | Q11: ='ACTUAL EXP'!$G$85*ALLOCATION!P15 -> 166505.28 | R11: =SUM('ACTUAL EXP'!$G$68:$G$73)*ALLOCATION!P15 -> 454142.2 | S11: =SUM('ACTUAL EXP'!$G$75)*ALLOCATION!P15 -> 63601.108 | T11: =SUM('ACTUAL EXP'!$G$77)*ALLOCATION!P15 -> 41760.229 | U11: =SUM('ACTUAL EXP'!$G$79)*ALLOCATION!P15 -> 63287.159 | V11: =SUM(C11:U11) -> 3599838.8 | W11: =-(H11/$H$111)*($W$117) -> 32422.305 | X11: =-(Q11/$Q$111)*($X$118) -> 23739.257 | Y11: =-(SUM(J11:O11,R11:U11)/SUM($J$111:$O$111,$R$111:$U$111))*$Y$119 -> 75692.586 | Z11: =-(C11/$C$111)*($Z$120) -> 31046.056 | AA11: =-(I11/$I$111)*($AA$121) -> 12086.772 | AB11: =-(SUM(D11:G11)/SUM($D$111:$G$111))*SUM($AB$117:$AB$122) -> 26300.122 | AC11: =SUM(V11:AB11) -> 3801125.9 | AD11: =SUM('ACTUAL EXP'!$G$37:$G$39)*ALLOCATION!P15 -> 74467.201 | AE11: =(AD11/$AD$111)*SUM($AD$117:$AD$122) -> 4163.8772 | AF11: =SUM('ACTUAL EXP'!$G$41)*ALLOCATION!P15 -> 22279.787 | AG11: =(AF11/$AF$111)*SUM($AF$117:$AF$122) -> 1245.7873 | AH11: =SUM('ACTUAL EXP'!$G$81)*ALLOCATION!P15 -> 9280.3977 | AI11: =(AH11/$AH$111)*SUM($AH$117:$AH$122) -> 518.91888 | AJ11: =SUM('ACTUAL EXP'!$G$83)*ALLOCATION!P15 -> 68903.812 | AK11: =(AJ11/$AH$111)*SUM($AH$117:$AH$122) -> 3852.7971 | AL11: =SUM('ACTUAL EXP'!$G$64:$G$66)*ALLOCATION!P15 -> 22250.152 | AM11: =(AL11/$AL$111)*SUM($AL$117:$AL$122) -> 1244.1303 | AN11: =SUM(AC11:AM11) -> 4009332.8 | AO11: =-AO72-AO73 -> 475.7093 | AP11: K | AQ11: =SUM(AO11,AN11) -> 4009808.5 | AS11: =AQ11-AR11 -> 4009808.5
A12: =ALLOCATION!A16 -> 600000 | B12: =ALLOCATION!C16 -> Sewer System Op | C12: ='ACTUAL EXP'!$G$13*(ALLOCATION!P16) -> 571790.39 | D12: =(SUM('ACTUAL EXP'!$G$15,'ACTUAL EXP'!$G$17:$G$19,'ACTUAL EXP'!$G$22))*ALLOCATION!P16 -> 922208.72 | E12: =(('ACTUAL EXP'!$G$25)*(ALLOCATION!P16)) -> 0 | F12: ='ACTUAL EXP'!$G$28*ALLOCATION!P16 -> 0 | G12: 0 | H12: =SUM('ACTUAL EXP'!$G$30:$G$35)*ALLOCATION!P16 -> 827707.31 | I12: =SUM('ACTUAL EXP'!$G$43:$G$47)*ALLOCATION!P16 -> 499960.51 | J12: =(SUM('ACTUAL EXP'!$G$49:$G$50)*ALLOCATION!P16*0.5)+(SUM('ACTUAL EXP'!$G$49:$G$50)*ALLOCATION!P16*0.5) -> 239840.07 | K12: =SUM('ACTUAL EXP'!$G$52:$G$53)*ALLOCATION!P16 -> 253117.82 | L12: =SUM('ACTUAL EXP'!$G$54:$G$54)*ALLOCATION!P16 -> 34516.066 | M12: =SUM('ACTUAL EXP'!$G$21:$G$21)*ALLOCATION!P16 -> 10636.235 | N12: =SUM('ACTUAL EXP'!$G$58:$G$62)*0.39*ALLOCATION!P16 -> 169395.77 | O12: =SUM('ACTUAL EXP'!$G$58:$G$62)*0.27*ALLOCATION!P16 -> 117273.99 | P12: =SUM('ACTUAL EXP'!$G$58:$G$62)*0.34*ALLOCATION!P16 -> 147678.36 | Q12: ='ACTUAL EXP'!$G$85*ALLOCATION!P16 -> 224775.76 | R12: =SUM('ACTUAL EXP'!$G$68:$G$73)*ALLOCATION!P16 -> 613074.59 | S12: =SUM('ACTUAL EXP'!$G$75)*ALLOCATION!P16 -> 85859.062 | T12: =SUM('ACTUAL EXP'!$G$77)*ALLOCATION!P16 -> 56374.711 | U12: =SUM('ACTUAL EXP'!$G$79)*ALLOCATION!P16 -> 85435.242 | V12: =SUM(C12:U12) -> 4859644.6 | W12: =-(H12/$H$111)*($W$117) -> 43768.871 | X12: =-(Q12/$Q$111)*($X$118) -> 32047.088 | Y12: =-(SUM(J12:O12,R12:U12)/SUM($J$111:$O$111,$R$111:$U$111))*$Y$119 -> 102182.09 | Z12: =-(C12/$C$111)*($Z$120) -> 41910.988 | AA12: =-(I12/$I$111)*($AA$121) -> 16316.679 | AB12: =-(SUM(D12:G12)/SUM($D$111:$G$111))*SUM($AB$117:$AB$122) -> 35504.158 | AC12: =SUM(V12:AB12) -> 5131374.5 | AD12: =SUM('ACTUAL EXP'!$G$37:$G$39)*ALLOCATION!P16 -> 100527.87 | AE12: =(AD12/$AD$111)*SUM($AD$117:$AD$122) -> 5621.0749 | AF12: =SUM('ACTUAL EXP'!$G$41)*ALLOCATION!P16 -> 30076.859 | AG12: =(AF12/$AF$111)*SUM($AF$117:$AF$122) -> 1681.7652 | AH12: =SUM('ACTUAL EXP'!$G$81)*ALLOCATION!P16 -> 12528.182 | AI12: =(AH12/$AH$111)*SUM($AH$117:$AH$122) -> 700.52063 | AJ12: =SUM('ACTUAL EXP'!$G$83)*ALLOCATION!P16 -> 93017.51 | AK12: =(AJ12/$AH$111)*SUM($AH$117:$AH$122) -> 5201.1286 | AL12: =SUM('ACTUAL EXP'!$G$64:$G$66)*ALLOCATION!P16 -> 30036.854 | AM12: =(AL12/$AL$111)*SUM($AL$117:$AL$122) -> 1679.5283 | AN12: =SUM(AC12:AM12) -> 5412445.8 | AO12: =-AO17-AO18-AO23-AO24-AO25 -> 1659579.5 | AP12: A | AQ12: =SUM(AO12,AN12) -> 7072025.3 | AS12: =AQ12-AR12 -> 7072025.3
A13: =ALLOCATION!A17 -> 608000 | B13: =ALLOCATION!C17 -> Envtl Remediation | C13: ='ACTUAL EXP'!$G$13*(ALLOCATION!P17) -> 17979 | D13: =(SUM('ACTUAL EXP'!$G$15,'ACTUAL EXP'!$G$17:$G$19,'ACTUAL EXP'!$G$22))*ALLOCATION!P17 -> 28997.323 | E13: =(('ACTUAL EXP'!$G$25)*(ALLOCATION!P17)) -> 0 | F13: ='ACTUAL EXP'!$G$28*ALLOCATION!P17 -> 0 | G13: 0 | H13: =SUM('ACTUAL EXP'!$G$30:$G$35)*ALLOCATION!P17 -> 26025.883 | I13: =SUM('ACTUAL EXP'!$G$43:$G$47)*ALLOCATION!P17 -> 15720.429 | J13: =(SUM('ACTUAL EXP'!$G$49:$G$50)*ALLOCATION!P17*0.5)+(SUM('ACTUAL EXP'!$G$49:$G$50)*ALLOCATION!P17*0.5) -> 7541.3732 | K13: =SUM('ACTUAL EXP'!$G$52:$G$53)*ALLOCATION!P17 -> 7958.8699 | L13: =SUM('ACTUAL EXP'!$G$54:$G$54)*ALLOCATION!P17 -> 1085.3004 | M13: =SUM('ACTUAL EXP'!$G$21:$G$21)*ALLOCATION!P17 -> 334.43876 | N13: =SUM('ACTUAL EXP'!$G$58:$G$62)*0.39*ALLOCATION!P17 -> 5326.3688 | O13: =SUM('ACTUAL EXP'!$G$58:$G$62)*0.27*ALLOCATION!P17 -> 3687.4861 | P13: =SUM('ACTUAL EXP'!$G$58:$G$62)*0.34*ALLOCATION!P17 -> 4643.501 | Q13: ='ACTUAL EXP'!$G$85*ALLOCATION!P17 -> 7067.7009 | R13: =SUM('ACTUAL EXP'!$G$68:$G$73)*ALLOCATION!P17 -> 19277.113 | S13: =SUM('ACTUAL EXP'!$G$75)*ALLOCATION!P17 -> 2699.6958 | T13: =SUM('ACTUAL EXP'!$G$77)*ALLOCATION!P17 -> 1772.6093 | U13: =SUM('ACTUAL EXP'!$G$79)*ALLOCATION!P17 -> 2686.3695 | V13: =SUM(C13:U13) -> 152803.46 | W13: =-(H13/$H$111)*($W$117) -> 1376.2396 | X13: =-(Q13/$Q$111)*($X$118) -> 1007.6675 | Y13: =-(SUM(J13:O13,R13:U13)/SUM($J$111:$O$111,$R$111:$U$111))*$Y$119 -> 3212.9465 | Z13: =-(C13/$C$111)*($Z$120) -> 1317.8215 | AA13: =-(I13/$I$111)*($AA$121) -> 513.0509 | AB13: =-(SUM(D13:G13)/SUM($D$111:$G$111))*SUM($AB$117:$AB$122) -> 1116.3693 | AC13: =SUM(V13:AB13) -> 161347.56 | AD13: =SUM('ACTUAL EXP'!$G$37:$G$39)*ALLOCATION!P17 -> 3160.9321 | AE13: =(AD13/$AD$111)*SUM($AD$117:$AD$122) -> 176.74537 | AF13: =SUM('ACTUAL EXP'!$G$41)*ALLOCATION!P17 -> 945.71694 | AG13: =(AF13/$AF$111)*SUM($AF$117:$AF$122) -> 52.880318 | AH13: =SUM('ACTUAL EXP'!$G$81)*ALLOCATION!P17 -> 393.92789 | AI13: =(AH13/$AH$111)*SUM($AH$117:$AH$122) -> 22.026709 | AJ13: =SUM('ACTUAL EXP'!$G$83)*ALLOCATION!P17 -> 2924.7813 | AK13: =(AJ13/$AH$111)*SUM($AH$117:$AH$122) -> 163.54086 | AL13: =SUM('ACTUAL EXP'!$G$64:$G$66)*ALLOCATION!P17 -> 944.45905 | AM13: =(AL13/$AL$111)*SUM($AL$117:$AL$122) -> 52.809982 | AN13: =SUM(AC13:AM13) -> 170185.38 | AQ13: =SUM(AO13,AN13) -> 170185.38 | AS13: =AQ13-AR13 -> 170185.38
A14: =ALLOCATION!A18 -> 605000 | B14: =ALLOCATION!C18 -> Solid Waste Mgt | C14: ='ACTUAL EXP'!$G$13*(ALLOCATION!P18) -> 19865.587 | D14: =(SUM('ACTUAL EXP'!$G$15,'ACTUAL EXP'!$G$17:$G$19,'ACTUAL EXP'!$G$22))*ALLOCATION!P18 -> 32040.093 | E14: =(('ACTUAL EXP'!$G$25)*(ALLOCATION!P18)) -> 0 | F14: ='ACTUAL EXP'!$G$28*ALLOCATION!P18 -> 0 | G14: 0 | H14: =SUM('ACTUAL EXP'!$G$30:$G$35)*ALLOCATION!P18 -> 28756.852 | I14: =SUM('ACTUAL EXP'!$G$43:$G$47)*ALLOCATION!P18 -> 17370.017 | J14: =(SUM('ACTUAL EXP'!$G$49:$G$50)*ALLOCATION!P18*0.5)+(SUM('ACTUAL EXP'!$G$49:$G$50)*ALLOCATION!P18*0.5) -> 8332.7104 | K14: =SUM('ACTUAL EXP'!$G$52:$G$53)*ALLOCATION!P18 -> 8794.0162 | L14: =SUM('ACTUAL EXP'!$G$54:$G$54)*ALLOCATION!P18 -> 1199.184 | M14: =SUM('ACTUAL EXP'!$G$21:$G$21)*ALLOCATION!P18 -> 369.53234 | N14: =SUM('ACTUAL EXP'!$G$58:$G$62)*0.39*ALLOCATION!P18 -> 5885.2795 | O14: =SUM('ACTUAL EXP'!$G$58:$G$62)*0.27*ALLOCATION!P18 -> 4074.4243 | P14: =SUM('ACTUAL EXP'!$G$58:$G$62)*0.34*ALLOCATION!P18 -> 5130.7565 | Q14: ='ACTUAL EXP'!$G$85*ALLOCATION!P18 -> 7809.3344 | R14: =SUM('ACTUAL EXP'!$G$68:$G$73)*ALLOCATION!P18 -> 21299.914 | S14: =SUM('ACTUAL EXP'!$G$75)*ALLOCATION!P18 -> 2982.9823 | T14: =SUM('ACTUAL EXP'!$G$77)*ALLOCATION!P18 -> 1958.6141 | U14: =SUM('ACTUAL EXP'!$G$79)*ALLOCATION!P18 -> 2968.2577 | V14: =SUM(C14:U14) -> 168837.55 | W14: =-(H14/$H$111)*($W$117) -> 1520.6522 | X14: =-(Q14/$Q$111)*($X$118) -> 1113.4049 | Y14: =-(SUM(J14:O14,R14:U14)/SUM($J$111:$O$111,$R$111:$U$111))*$Y$119 -> 3550.0899 | Z14: =-(C14/$C$111)*($Z$120) -> 1456.1042 | AA14: =-(I14/$I$111)*($AA$121) -> 566.88676 | AB14: =-(SUM(D14:G14)/SUM($D$111:$G$111))*SUM($AB$117:$AB$122) -> 1233.5131 | AC14: =SUM(V14:AB14) -> 178278.21 | AD14: =SUM('ACTUAL EXP'!$G$37:$G$39)*ALLOCATION!P18 -> 3492.6175 | AE14: =(AD14/$AD$111)*SUM($AD$117:$AD$122) -> 195.29176 | AF14: =SUM('ACTUAL EXP'!$G$41)*ALLOCATION!P18 -> 1044.9536 | AG14: =(AF14/$AF$111)*SUM($AF$117:$AF$122) -> 58.429196 | AH14: =SUM('ACTUAL EXP'!$G$81)*ALLOCATION!P18 -> 435.26384 | AI14: =(AH14/$AH$111)*SUM($AH$117:$AH$122) -> 24.338033 | AJ14: =SUM('ACTUAL EXP'!$G$83)*ALLOCATION!P18 -> 3231.6867 | AK14: =(AJ14/$AH$111)*SUM($AH$117:$AH$122) -> 180.70166 | AL14: =SUM('ACTUAL EXP'!$G$64:$G$66)*ALLOCATION!P18 -> 1043.5638 | AM14: =(AL14/$AL$111)*SUM($AL$117:$AL$122) -> 58.35148 | AN14: =SUM(AC14:AM14) -> 188043.4 | AQ14: =SUM(AO14,AN14) -> 188043.4 | AS14: =AQ14-AR14 -> 188043.4
A15: =ALLOCATION!A19 -> 200000 | B15: =ALLOCATION!C19 -> Transportation Op | C15: ='ACTUAL EXP'!$G$13*(ALLOCATION!P19) -> 693005.94 | D15: =(SUM('ACTUAL EXP'!$G$15,'ACTUAL EXP'!$G$17:$G$19,'ACTUAL EXP'!$G$22))*ALLOCATION!P19 -> 1117710.5 | E15: =(('ACTUAL EXP'!$G$25)*(ALLOCATION!P19)) -> 0 | F15: ='ACTUAL EXP'!$G$28*ALLOCATION!P19 -> 0 | G15: ='ACTUAL EXP'!$G$20*0.25 -> 0 | H15: =SUM('ACTUAL EXP'!$G$30:$G$35)*ALLOCATION!P19 -> 1003175.5 | I15: =SUM('ACTUAL EXP'!$G$43:$G$47)*ALLOCATION!P19 -> 605948.63 | J15: =(SUM('ACTUAL EXP'!$G$49:$G$50)*ALLOCATION!P19*0.5)+(SUM('ACTUAL EXP'!$G$49:$G$50)*ALLOCATION!P19*0.5) -> 290684.48 | K15: =SUM('ACTUAL EXP'!$G$52:$G$53)*ALLOCATION!P19 -> 306777.02 | L15: =SUM('ACTUAL EXP'!$G$54:$G$54)*ALLOCATION!P19 -> 41833.23 | M15: =SUM('ACTUAL EXP'!$G$21:$G$21)*ALLOCATION!P19 -> 12891.042 | N15: =SUM('ACTUAL EXP'!$G$58:$G$62)*0.39*ALLOCATION!P19 -> 205306.48 | O15: =SUM('ACTUAL EXP'!$G$58:$G$62)*0.27*ALLOCATION!P19 -> 142135.25 | P15: =SUM('ACTUAL EXP'!$G$58:$G$62)*0.34*ALLOCATION!P19 -> 178985.13 | Q15: ='ACTUAL EXP'!$G$85*ALLOCATION!P19 -> 272426.64 | R15: =SUM('ACTUAL EXP'!$G$68:$G$73)*ALLOCATION!P19 -> 743042.1 | S15: =SUM('ACTUAL EXP'!$G$75)*ALLOCATION!P19 -> 104060.58 | T15: =SUM('ACTUAL EXP'!$G$77)*ALLOCATION!P19 -> 68325.755 | U15: =SUM('ACTUAL EXP'!$G$79)*ALLOCATION!P19 -> 103546.91 | V15: =SUM(C15:U15) -> 5889855.2 | W15: =-(H15/$H$111)*($W$117) -> 53047.565 | X15: =-(Q15/$Q$111)*($X$118) -> 38840.846 | Y15: =-(SUM(J15:O15,R15:U15)/SUM($J$111:$O$111,$R$111:$U$111))*$Y$119 -> 123843.98 | Z15: =-(C15/$C$111)*($Z$120) -> 50795.823 | AA15: =-(I15/$I$111)*($AA$121) -> 19775.7 | AB15: =-(SUM(D15:G15)/SUM($D$111:$G$111))*SUM($AB$117:$AB$122) -> 43030.79 | AC15: =SUM(V15:AB15) -> 6219189.9 | AD15: =SUM('ACTUAL EXP'!$G$37:$G$39)*ALLOCATION!P19 -> 121839.07 | AE15: =(AD15/$AD$111)*SUM($AD$117:$AD$122) -> 6812.7033 | AF15: =SUM('ACTUAL EXP'!$G$41)*ALLOCATION!P19 -> 36452.942 | AG15: =(AF15/$AF$111)*SUM($AF$117:$AF$122) -> 2038.2876 | AH15: =SUM('ACTUAL EXP'!$G$81)*ALLOCATION!P19 -> 15184.068 | AI15: =(AH15/$AH$111)*SUM($AH$117:$AH$122) -> 849.02609 | AJ15: =SUM('ACTUAL EXP'!$G$83)*ALLOCATION!P19 -> 112736.57 | AK15: =(AJ15/$AH$111)*SUM($AH$117:$AH$122) -> 6303.7314 | AL15: =SUM('ACTUAL EXP'!$G$64:$G$66)*ALLOCATION!P19 -> 36404.456 | AM15: =(AL15/$AL$111)*SUM($AL$117:$AL$122) -> 2035.5765 | AN15: =SUM(AC15:AM15) -> 6559846.3 | AO15: =-AO16-AO100 -> 4818.9997 | AP15: C | AQ15: =SUM(AO15,AN15) -> 6564665.3 | AS15: =AQ15-AR15 -> 6564665.3
A16: =ALLOCATION!A20 -> 212000 | B16: =ALLOCATION!C20 -> Transportation Resv | C16: ='ACTUAL EXP'!$G$13*(ALLOCATION!P20) -> 0 | D16: =(SUM('ACTUAL EXP'!$G$15,'ACTUAL EXP'!$G$17:$G$19,'ACTUAL EXP'!$G$22))*ALLOCATION!P20 -> 0 | E16: =(('ACTUAL EXP'!$G$25)*(ALLOCATION!P20)) -> 0 | F16: ='ACTUAL EXP'!$G$28*ALLOCATION!P20 -> 0 | G16: 0 | H16: =SUM('ACTUAL EXP'!$G$30:$G$35)*ALLOCATION!P20 -> 0 | I16: =SUM('ACTUAL EXP'!$G$43:$G$47)*ALLOCATION!P20 -> 0 | J16: =(SUM('ACTUAL EXP'!$G$49:$G$50)*ALLOCATION!P20*0.5)+(SUM('ACTUAL EXP'!$G$49:$G$50)*ALLOCATION!P20*0.5) -> 0 | K16: =SUM('ACTUAL EXP'!$G$52:$G$53)*ALLOCATION!P20 -> 0 | L16: =SUM('ACTUAL EXP'!$G$54:$G$54)*ALLOCATION!P20 -> 0 | M16: =SUM('ACTUAL EXP'!$G$21:$G$21)*ALLOCATION!P20 -> 0 | N16: =SUM('ACTUAL EXP'!$G$58:$G$62)*0.39*ALLOCATION!P20 -> 0 | O16: =SUM('ACTUAL EXP'!$G$58:$G$62)*0.27*ALLOCATION!P20 -> 0 | P16: =SUM('ACTUAL EXP'!$G$58:$G$62)*0.34*ALLOCATION!P20 -> 0 | Q16: ='ACTUAL EXP'!$G$85*ALLOCATION!P20 -> 0 | R16: =SUM('ACTUAL EXP'!$G$68:$G$73)*ALLOCATION!P20 -> 0 | S16: =SUM('ACTUAL EXP'!$G$75)*ALLOCATION!P20 -> 0 | T16: =SUM('ACTUAL EXP'!$G$77)*ALLOCATION!P20 -> 0 | U16: =SUM('ACTUAL EXP'!$G$79)*ALLOCATION!P20 -> 0 | V16: =SUM(C16:U16) -> 0 | W16: =-(H16/$H$111)*($W$117) -> 0 | X16: =-(Q16/$Q$111)*($X$118) -> 0 | Y16: =-(SUM(J16:O16,R16:U16)/SUM($J$111:$O$111,$R$111:$U$111))*$Y$119 -> 0 | Z16: =-(C16/$C$111)*($Z$120) -> 0 | AA16: =-(I16/$I$111)*($AA$121) -> 0 | AB16: =-(SUM(D16:G16)/SUM($D$111:$G$111))*SUM($AB$117:$AB$122) -> 0 | AC16: =SUM(V16:AB16) -> 0 | AD16: =SUM('ACTUAL EXP'!$G$37:$G$39)*ALLOCATION!P20 -> 0 | AE16: =(AD16/$AD$111)*SUM($AD$117:$AD$122) -> 0 | AF16: =SUM('ACTUAL EXP'!$G$41)*ALLOCATION!P20 -> 0 | AG16: =(AF16/$AF$111)*SUM($AF$117:$AF$122) -> 0 | AH16: =SUM('ACTUAL EXP'!$G$81)*ALLOCATION!P20 -> 0 | AI16: =(AH16/$AH$111)*SUM($AH$117:$AH$122) -> 0 | AJ16: =SUM('ACTUAL EXP'!$G$83)*ALLOCATION!P20 -> 0 | AK16: =(AJ16/$AH$111)*SUM($AH$117:$AH$122) -> 0 | AL16: =SUM('ACTUAL EXP'!$G$64:$G$66)*ALLOCATION!P20 -> 0 | AM16: =(AL16/$AL$111)*SUM($AL$117:$AL$122) -> 0 | AN16: =SUM(AC16:AM16) -> 0 | AO16: =-AN16 -> 0 | AP16: (C) | AQ16: =SUM(AO16,AN16) -> 0 | AS16: =AQ16-AR16 -> 0
