Workbook

Sheet Districts
B1: Salary1 | G1: Estimated Teacher Benefits3
B2: School Administrator | D2: Classroom Teacher | F2: Admini-strator to Teacher Salary Ratio | O2: Benefits Subtotal | Q2: Estimated Total Teacher Compen-sation
B3: FTEs2 | C3: Annualized Trimmed Mean Salary | D3: FTEs2 | E3: Annualized Trimmed Mean Salary | G3: Social Security | H3: Retirement | O3: Amount | P3: As Percent of Total Compen-sation
A4: District | I4: Health | J4: Dental | K4: Life | L4: Industrial | M4: Unemploy-ment | N4: Long Term Disability
A5: Alpine District | B5: 120.286 | C5: 85374 | D5: 2710.394 | E5: 44872 | F5: =C5/E5 -> 1.9026119 | G5: =E5*0.0765 -> 3432.708 | H5: =E5*0.2026 -> 9091.0672 | I5: 12920.69 | J5: 0 | K5: 35.88 | L5: 157.05 | M5: 21.84 | N5: 148.2 | O5: =SUM(G5:N5) -> 25807.435 | P5: =O5/Q5 -> 0.36513358 | Q5: =E5+O5 -> 70679.435
A6: Beaver District | B6: 3.75 | C6: 75454 | D6: 74.35 | E6: 48612 | F6: =C6/E6 -> 1.5521682 | G6: =E6*0.0765 -> 3718.818 | H6: =E6*0.2026 -> 9848.7912 | I6: 14480 | J6: 957 | K6: 50 | L6: 276 | M6: 48.905 | N6: 109 | O6: =SUM(G6:N6) -> 29488.514 | P6: =O6/Q6 -> 0.37757132 | Q6: =E6+O6 -> 78100.514
A7: Box Elder District | B7: 24.8 | C7: 77552 | D7: 476.618 | E7: 44983 | F7: =C7/E7 -> 1.7240291 | G7: =E7*0.0765 -> 3441.1995 | H7: =E7*0.2026 -> 9113.5558 | I7: 10933 | J7: 0 | K7: 86 | L7: 177 | M7: 22 | N7: 0 | O7: =SUM(G7:N7) -> 23772.755 | P7: =O7/Q7 -> 0.34575659 | Q7: =E7+O7 -> 68755.755
A8: Cache District | B8: 32.606 | C8: 81719 | D8: 613.119 | E8: 47790 | F8: =C8/E8 -> 1.7099602 | G8: =E8*0.0765 -> 3655.935 | H8: =E8*0.2026 -> 9682.254 | I8: 11761.2 | J8: 0 | K8: 0 | L8: 0 | M8: 47.79 | N8: 0 | O8: =SUM(G8:N8) -> 25147.179 | P8: =O8/Q8 -> 0.34477861 | Q8: =E8+O8 -> 72937.179
A9: Canyons District | B9: 80.595 | C9: 84097 | D9: 1456.824 | E9: 45707 | F9: =C9/E9 -> 1.8399151 | G9: =E9*0.0765 -> 3496.5855 | H9: =E9*0.2026 -> 9260.2382 | I9: 7012 | J9: 0 | K9: 53.76 | L9: 365.66 | M9: 45.619 | N9: 156.6 | O9: =SUM(G9:N9) -> 20390.463 | P9: =O9/Q9 -> 0.30849085 | Q9: =E9+O9 -> 66097.463
A10: Carbon District | B10: 12 | C10: 69609 | D10: 170.326 | E10: 44901 | F10: =C10/E10 -> 1.5502773 | G10: =E10*0.0765 -> 3434.9265 | H10: =E10*0.2026 -> 9096.9426 | I10: 17828 | J10: 0 | K10: 70 | L10: 375 | M10: 44.901 | N10: 0 | O10: =SUM(G10:N10) -> 30849.77 | P10: =O10/Q10 -> 0.40725355 | Q10: =E10+O10 -> 75750.77
A11: Daggett District | B11: 0.66 | C11: 46116 | D11: 13.24 | E11: 43716 | F11: =C11/E11 -> 1.0548998 | G11: =E11*0.0765 -> 3344.274 | H11: =E11*0.2026 -> 8856.8616 | I11: 15719 | J11: 0 | K11: 59.05 | L11: 353.65 | M11: 39.215 | N11: 170.64 | O11: =SUM(G11:N11) -> 28542.691 | P11: =O11/Q11 -> 0.39500703 | Q11: =E11+O11 -> 72258.691
A12: Davis District | B12: 175.047 | C12: 73472 | D12: 2813.844 | E12: 47333 | F12: =C12/E12 -> 1.5522363 | G12: =E12*0.0765 -> 3620.9745 | H12: =E12*0.2026 -> 9589.6658 | I12: 13225.21 | J12: 953.97 | K12: 59.27 | L12: 74.67 | M12: 51.3 | N12: 94.5 | O12: =SUM(G12:N12) -> 27669.56 | P12: =O12/Q12 -> 0.36891488 | Q12: =E12+O12 -> 75002.56
A13: Duchesne District | B13: 16 | C13: 66435 | D13: 225.11 | E13: 43428 | F13: =C13/E13 -> 1.5297734 | G13: =E13*0.0765 -> 3322.242 | H13: =E13*0.2026 -> 8798.5128 | I13: 10764 | J13: 0 | K13: 68.94 | L13: 143.31 | M13: 26.06 | N13: 119.43 | O13: =SUM(G13:N13) -> 23242.495 | P13: =O13/Q13 -> 0.3486174 | Q13: =E13+O13 -> 66670.495
A14: Emery District | B14: 10.03 | C14: 81480 | D14: 128.89 | E14: 48768 | F14: =C14/E14 -> 1.6707677 | G14: =E14*0.0765 -> 3730.752 | H14: =E14*0.2026 -> 9880.3968 | I14: 17656 | J14: 842 | K14: 56.4 | L14: 340 | M14: 48.219 | N14: 92.1 | O14: =SUM(G14:N14) -> 32645.868 | P14: =O14/Q14 -> 0.40098657 | Q14: =E14+O14 -> 81413.868
A15: Garfield District | B15: 2.97 | C15: 57370 | D15: 56.486 | E15: 47964 | F15: =C15/E15 -> 1.1961054 | G15: =E15*0.0765 -> 3669.246 | H15: =E15*0.2026 -> 9717.5064 | I15: 14832 | J15: 0 | K15: 49.68 | L15: 172.24 | M15: 35.11 | N15: 167.64 | O15: =SUM(G15:N15) -> 28643.422 | P15: =O15/Q15 -> 0.37389879 | Q15: =E15+O15 -> 76607.422
A16: Grand District | B16: 5 | C16: 75469 | D16: 81.94 | E16: 44454 | F16: =C16/E16 -> 1.6976875 | G16: =E16*0.0765 -> 3400.731 | H16: =E16*0.2026 -> 9006.3804 | I16: 7156.49 | J16: 0 | K16: 63.16 | L16: 296.09 | M16: 40.19 | N16: 219.33 | O16: =SUM(G16:N16) -> 20182.371 | P16: =O16/Q16 -> 0.31224481 | Q16: =E16+O16 -> 64636.371
... A38: South Summit District | B38: 3.9 | C38: 77561 | D38: 71.295 | E38: 49101 | F38: =C38/E38 -> 1.5796216 | G38: =E38*0.0765 -> 3756.2265 | H38: =E38*0.2026 -> 9947.8626 | I38: 14832 | J38: 600 | K38: 90.48 | L38: 364.43 | M38: 1.12 | N38: 118.2 | O38: =SUM(G38:N38) -> 29710.319 | P38: =O38/Q38 -> 0.37698036 | Q38: =E38+O38 -> 78811.319
A39: Tintic District | B39: INS | C39: ― | D39: 14.66 | E39: 48073 | F39: ― | G39: =E39*0.0765 -> 3677.5845 | H39: =E39*0.2026 -> 9739.5898 | I39: 11172 | J39: 1152 | K39: 75 | L39: 2.5 | M39: 48.07 | N39: 197.1 | O39: =SUM(G39:N39) -> 26063.844 | P39: =O39/Q39 -> 0.35156398 | Q39: =E39+O39 -> 74136.844
A40: Tooele District | B40: 30.12 | C40: 80655 | D40: 641.079 | E40: 44297 | F40: =C40/E40 -> 1.8207779 | G40: =E40*0.0765 -> 3388.7205 | H40: =E40*0.2026 -> 8974.5722 | I40: 10646 | J40: 385 | K40: 43 | L40: 202 | M40: 44.101 | N40: 92 | O40: =SUM(G40:N40) -> 23775.394 | P40: =O40/Q40 -> 0.34926631 | Q40: =E40+O40 -> 68072.394
A41: Uintah District | B41: 16.5 | C41: 69469 | D41: 311.914 | E41: 43501 | F41: =C41/E41 -> 1.5969518 | G41: =E41*0.0765 -> 3327.8265 | H41: =E41*0.2026 -> 8813.3026 | I41: 13224 | J41: 0 | K41: 217.51 | L41: 369.76 | M41: 174.01 | N41: 195.76 | O41: =SUM(G41:N41) -> 26322.169 | P41: =O41/Q41 -> 0.37698331 | Q41: =E41+O41 -> 69823.169
A42: Wasatch District | B42: 12 | C42: 84482 | D42: 252.06 | E42: 49191 | F42: =C42/E42 -> 1.717428 | G42: =E42*0.0765 -> 3763.1115 | H42: =E42*0.2026 -> 9966.0966 | I42: 14832 | J42: 1296 | K42: 30.06 | L42: 147.57 | M42: 49.191 | N42: 182.5 | O42: =SUM(G42:N42) -> 30266.529 | P42: =O42/Q42 -> 0.38091455 | Q42: =E42+O42 -> 79457.529
A43: Washington District | B43: 58.05 | C43: 84827 | D43: 1211.457 | E43: 45980 | F43: =C43/E43 -> 1.8448673 | G43: =E43*0.0765 -> 3517.47 | H43: =E43*0.2026 -> 9315.548 | I43: 10494 | J43: 821 | K43: 28 | L43: 284.39 | M43: 45.98 | N43: 189 | O43: =SUM(G43:N43) -> 24695.388 | P43: =O43/Q43 -> 0.34941991 | Q43: =E43+O43 -> 70675.388
A44: Wayne District | B44: 2.35 | C44: 48442 | D44: 34.633 | E44: 40617 | F44: =C44/E44 -> 1.1926533 | G44: =E44*0.0765 -> 3107.2005 | H44: =E44*0.2026 -> 8229.0042 | I44: 14178 | J44: 1136 | K44: 73.8 | L44: 91.61 | M44: 42.43 | N44: 256.82 | O44: =SUM(G44:N44) -> 27114.865 | P44: =O44/Q44 -> 0.40032656 | Q44: =E44+O44 -> 67731.865
A45: Weber District | B45: 68.151 | C45: 74304 | D45: 1317.312 | E45: 44225 | F45: =C45/E45 -> 1.6801357 | G45: =E45*0.0765 -> 3383.2125 | H45: =E45*0.2026 -> 8959.985 | I45: 10507 | J45: 0 | K45: 48.72 | L45: 89.28 | M45: 13.12 | N45: 74.4 | O45: =SUM(G45:N45) -> 23075.718 | P45: =O45/Q45 -> 0.34287476 | Q45: =E45+O45 -> 67300.717
A46: District Subtotal | B46: =SUM(B5:B45) -> 1227.576 | C46: 79274 | D46: =SUM(D5:D45) -> 23416.5 | E46: 46232 | F46: =C46/E46 -> 1.7146998 | O46: 24866.96 | P46: =O46/Q46 -> 0.34975139 | Q46: =E46+O46 -> 71098.96
A47: Charter Subtotal | B47: =Charters!B89 -> 107.628 | C47: =Charters!C89 -> 70693 | D47: =Charters!D89 -> 2139.617 | E47: =Charters!E89 -> 37778 | F47: =C47/E47 -> 1.8712743 | O47: =Charters!O89 -> 13792.5 | P47: =Charters!P89 -> 0.26744941 | Q47: =Charters!Q89 -> 51570.5
A48: Utah Schools for Deaf & Blind | B48: INS | C48: ― | D48: 110.48 | E48: 52782 | F48: ― | O48: DNR | P48: ― | Q48: ―
A49: State Total | B49: =SUM(B46:B47) -> 1335.204 | C49: 78573 | D49: =SUM(D46:D48) -> 25666.597 | E49: 45543 | F49: =C49/E49 -> 1.7252487 | O49: 23939.78 | P49: =O49/Q49 -> 0.34454263 | Q49: =E49+O49 -> 69482.78
A50: 1As reported by local education agencies through the CACTUS (Educator Licensing) database.
A51: 2Based on educators (a) who were employed at least half time, (2) who were assigned for at least half of their time to classroom teaching (Category Code = 610,701,710,720, or 1000) or school administration (Category Code = 800),
A52: and (c) whose reported salary was within three standard deviations of the raw mean salary (trimmed) and divided by their total FTE (annualized).
A53: 3As reported by local education agencies through the Teacher Benefits Report, which is part of the Year End Web Survey.
A54: DNR = Did not report, INS = Reported but insufficient for analysis (did meet criterion to be included in analysis)

Sheet Charters
B1: Salary1 | G1: Estimated Teacher Benefits3 | Q1: Estimated Total Teacher Compen-sation
B2: School Administrator | D2: Classroom Teacher | F2: Admini-strator to Teacher Salary Ratio | O2: Benefits Subtotal
B3: FTEs2 | C3: Annualized Trimmed Mean Salary | D3: FTEs2 | E3: Annualized Trimmed Mean Salary | P3: As Percent of Total Compen-sation
G4: Social Security | H4: Retirement | I4: Health | J4: Dental | K4: Life | L4: Industrial | M4: Unemploy-ment | N4: Long Term Disability | O4: Amount
A5: Academy For Math Engineering & Science (Ames) | B5: 1 | C5: 90000 | D5: 20.516 | E5: 49136 | F5: =C5/E5 -> 1.8316509 | G5: =E5*0.0765 -> 3758.904 | H5: 9755.3926 | I5: 12744.96 | J5: 480 | K5: 118.8 | L5: 192.6 | M5: 192.6 | N5: 288.91 | O5: =SUM(G5:N5) -> 27532.167 | P5: =O5/Q5 -> 0.35910819 | Q5: =E5+O5 -> 76668.167
A6: Alianza Academy | B6: 1 | C6: 57000 | D6: 17.25 | E6: 37076 | F6: =C6/E6 -> 1.5373827 | G6: =E6*0.0765 -> 2836.314 | H6: 7511.5976 | I6: 7253.45 | J6: 703.44 | K6: 45 | L6: 0 | M6: 37.076 | N6: 45 | O6: =SUM(G6:N6) -> 18431.878 | P6: =O6/Q6 -> 0.33205877 | Q6: =E6+O6 -> 55507.878
A7: American Leadership Academy | B7: 2 | C7: 51665 | D7: 70.345 | E7: 39368 | F7: =C7/E7 -> 1.3123603 | G7: =E7*0.0765 -> 3011.652 | H7: 7975.9568 | I7: 9600 | J7: 925 | K7: 0 | L7: 163 | M7: 39.368 | N7: 0 | O7: =SUM(G7:N7) -> 21714.977 | P7: =O7/Q7 -> 0.35549965 | Q7: =E7+O7 -> 61082.977
A8: American Preparatory Academy | B8: 6 | C8: 45633 | D8: 93.566 | E8: 35231 | F8: =C8/E8 -> 1.2952513 | G8: =E8*0.0765 -> 2695.1715 | H8: 2113.86 | I8: 3935.52 | J8: 385.92 | K8: 83.27 | L8: 74.62 | M8: 598.93 | N8: 510.85 | O8: =SUM(G8:N8) -> 10398.142 | P8: =O8/Q8 -> 0.22788379 | Q8: =E8+O8 -> 45629.141
A9: Aristotle Academy | B9: 1 | C9: 60000 | D9: 12 | E9: 38000 | F9: =C9/E9 -> 1.5789474 | G9: =E9*0.0765 -> 2907 | H9: 0 | I9: 425.44 | J9: 0 | K9: 0 | L9: 7.98 | M9: 152 | N9: 0 | O9: =SUM(G9:N9) -> 3492.42 | P9: =O9/Q9 -> 0.084170073 | Q9: =E9+O9 -> 41492.42
A10: Bear River Charter School | B10: 1 | C10: 81000 | D10: 11.561 | E10: 36918 | F10: =C10/E10 -> 2.1940517 | G10: =E10*0.0765 -> 2824.227 | H10: 1799.22 | I10: 4862.13 | J10: 658.75 | K10: 0 | L10: 214.14 | M10: 180.3 | N10: 0 | O10: =SUM(G10:N10) -> 10538.767 | P10: =O10/Q10 -> 0.2220709 | Q10: =E10+O10 -> 47456.767
A11: Beehive Science & Technology Academy | C11: INS | D11: 14.233 | E11: 33663 | G11: =E11*0.0765 -> 2575.2195 | H11: 0 | I11: 3562 | J11: 0 | K11: 0 | L11: 113.71 | M11: 449.32 | N11: 0 | O11: =SUM(G11:N11) -> 6700.2495 | P11: =O11/Q11 -> 0.16599876 | Q11: =E11+O11 -> 40363.249
A12: Canyon Grove Academy | C12: DNR | D12: 13.595 | E12: 33018 | G12: =E12*0.0765 -> 2525.877 | H12: 6689.4468 | I12: 6571.8 | J12: 0 | K12: 286.68 | L12: 138.68 | M12: 33.018 | N12: 365.12 | O12: =SUM(G12:N12) -> 16610.622 | P12: =O12/Q12 -> 0.33469843 | Q12: =E12+O12 -> 49628.622
A13: Canyon Rim Academy | B13: 1 | C13: 85000 | D13: 22 | E13: 41051 | F13: =C13/E13 -> 2.0705951 | G13: =E13*0.0765 -> 3140.4015 | H13: 1500 | I13: 6340 | J13: 493 | K13: 0 | L13: 0 | M13: 41.851 | N13: 0 | O13: =SUM(G13:N13) -> 11515.253 | P13: =O13/Q13 -> 0.2190617 | Q13: =E13+O13 -> 52566.253
A14: Channing Hall | B14: 1.25 | C14: 69720 | D14: 18.5 | E14: 38193 | F14: =C14/E14 -> 1.8254654 | G14: =E14*0.0765 -> 2921.7645 | H14: 2607 | I14: 4324 | J14: 388 | K14: 60 | L14: 140 | M14: 155 | N14: 0 | O14: =SUM(G14:N14) -> 10595.764 | P14: =O14/Q14 -> 0.21717632 | Q14: =E14+O14 -> 48788.764
A15: City Academy | B15: 0.9 | C15: 53832 | D15: 12.917 | E15: 36452 | F15: =C15/E15 -> 1.4767914 | G15: =E15*0.0765 -> 2788.578 | H15: 1653.44 | I15: 5511.45 | J15: 0 | K15: 0 | L15: 121.25 | M15: 36.74 | N15: 0 | O15: =SUM(G15:N15) -> 10111.458 | P15: =O15/Q15 -> 0.21715436 | Q15: =E15+O15 -> 46563.458
A16: Cs Lewis Academy | C16: DNR | D16: 11 | E16: 31536 | G16: =E16*0.0765 -> 2412.504 | H16: 947.7 | I16: 4681.44 | J16: 0 | K16: 14.4 | L16: 0 | M16: 575.7 | N16: 0 | O16: =SUM(G16:N16) -> 8631.744 | P16: =O16/Q16 -> 0.21489243 | Q16: =E16+O16 -> 40167.744
A17: Davinci Academy | B17: 1.25 | C17: 82500 | D17: 31.9 | E17: 37001 | F17: =C17/E17 -> 2.2296695 | G17: =E17*0.0765 -> 2830.5765 | H17: 1224.39 | I17: 4088.57 | J17: 0 | K17: 72.15 | L17: 198.89 | M17: 765.24 | N17: 0 | O17: =SUM(G17:N17) -> 9179.8165 | P17: =O17/Q17 -> 0.19877987 | Q17: =E17+O17 -> 46180.817
A18: Dual Immersion Academy | B18: 1.5 | C18: 52500 | D18: 18.22 | E18: 38832 | F18: =C18/E18 -> 1.3519778 | G18: =E18*0.0765 -> 2970.648 | H18: 776.64 | I18: 4784.51 | J18: 0 | K18: 0 | L18: 231.18 | M18: 516.63 | N18: 0 | O18: =SUM(G18:N18) -> 9279.608 | P18: =O18/Q18 -> 0.1928767 | Q18: =E18+O18 -> 48111.608
A19: Early Light Academy At Daybreak | B19: 0.95 | C19: 77250 | D19: 34.24 | E19: 37252 | F19: =C19/E19 -> 2.0737142 | G19: =E19*0.0765 -> 2849.778 | H19: 0 | I19: 7500 | J19: 0 | K19: 0 | L19: 111.77 | M19: 860.32 | N19: 0 | O19: =SUM(G19:N19) -> 11321.868 | P19: =O19/Q19 -> 0.23308558 | Q19: =E19+O19 -> 48573.868
A20: East Hollywood High | C20: INS | D20: 17.167 | E20: 33365 | G20: =E20*0.0765 -> 2552.4225 | H20: 6759.749 | I20: 4560 | J20: 242.4 | K20: 0 | L20: 225 | M20: 33.365 | N20: 0 | O20: =SUM(G20:N20) -> 14372.936 | P20: =O20/Q20 -> 0.30107997 | Q20: =E20+O20 -> 47737.936
A21: Edith Bowen Laboratory School | B21: 1.3 | C21: 76869 | D21: 16.163 | E21: 45192 | F21: =C21/E21 -> 1.7009426 | G21: =E21*0.0765 -> 3457.188 | H21: 6916.18 | I21: 7235.32 | J21: 812.96 | K21: 81.3 | L21: 150.48 | M21: 45.192 | N21: 125.18 | O21: =SUM(G21:N21) -> 18823.8 | P21: =O21/Q21 -> 0.29404928 | Q21: =E21+O21 -> 64015.8
A22: Endeavor Hall | B22: 1.75 | C22: 65000 | D22: 25.5 | E22: 36882 | F22: =C22/E22 -> 1.7623773 | G22: =E22*0.0765 -> 2821.473 | H22: 2212.92 | I22: 4400 | J22: 310 | K22: 24.12 | L22: 39.17 | M22: 36.882 | N22: 61.78 | O22: =SUM(G22:N22) -> 9906.345 | P22: =O22/Q22 -> 0.21172677 | Q22: =E22+O22 -> 46788.345
A23: Entheos Academy | B23: 1 | C23: 65000 | D23: 44.09 | E23: 38004 | F23: =C23/E23 -> 1.7103463 | G23: =E23*0.0765 -> 2907.306 | H23: 2590.28 | I23: 10915.8 | J23: 1463.28 | K23: 23.93 | L23: 109.51 | M23: 432.76 | N23: 0 | O23: =SUM(G23:N23) -> 18442.866 | P23: =O23/Q23 -> 0.32672967 | Q23: =E23+O23 -> 56446.866
A24: Excelsior Academy | B24: 2 | C24: 47665 | D24: 28.062 | E24: 37797 | F24: =C24/E24 -> 1.2610789 | G24: =E24*0.0765 -> 2891.4705 | H24: 3399.12 | I24: 7200 | J24: 0 | K24: 36 | L24: 150 | M24: 230.1 | N24: 0 | O24: =SUM(G24:N24) -> 13906.691 | P24: =O24/Q24 -> 0.26896901 | Q24: =E24+O24 -> 51703.69
A25: Fast Forward High | B25: 1.04 | C25: 61538 | D25: 11.122 | E25: 36271 | F25: =C25/E25 -> 1.6966171 | G25: =E25*0.0765 -> 2774.7315 | H25: 7348.5046 | I25: 6600 | J25: 250 | K25: 0 | L25: 102 | M25: 36.271 | N25: 0 | O25: =SUM(G25:N25) -> 17111.507 | P25: =O25/Q25 -> 0.32054521 | Q25: =E25+O25 -> 53382.507
A26: Freedom Academy | B26: 1 | C26: 95000 | D26: 36.305 | E26: 40031 | F26: =C26/E26 -> 2.3731608 | G26: =E26*0.0765 -> 3062.3715 | H26: 8110.2806 | I26: 11500 | J26: 0 | K26: 30 | L26: 0 | M26: 40.031 | N26: 0 | O26: =SUM(G26:N26) -> 22742.683 | P26: =O26/Q26 -> 0.36229646 | Q26: =E26+O26 -> 62773.683
A27: Gateway Preparatory Academy | B27: 1.722 | C27: 49508 | D27: 23.655 | E27: 32487 | F27: =C27/E27 -> 1.5239326 | G27: =E27*0.0765 -> 2485.2555 | H27: 1530.65 | I27: 4800 | J27: 0 | K27: 6.65 | L27: 116.32 | M27: 489 | N27: 62 | O27: =SUM(G27:N27) -> 9489.8755 | P27: =O27/Q27 -> 0.22607389 | Q27: =E27+O27 -> 41976.876
A28: George Washington Academy | B28: 1.5 | C28: 62000 | D28: 43.9 | E28: 34301 | F28: =C28/E28 -> 1.8075275 | G28: =E28*0.0765 -> 2624.0265 | H28: 1715.05 | I28: 5516.22 | J28: 0 | K28: 0 | L28: 137.2 | M28: 205.81 | N28: 0 | O28: =SUM(G28:N28) -> 10198.307 | P28: =O28/Q28 -> 0.229179 | Q28: =E28+O28 -> 44499.306
A29: Good Foundations Academy | B29: 1 | C29: 60000 | D29: 23.34 | E29: 35467 | F29: =C29/E29 -> 1.6917134 | G29: =E29*0.0765 -> 2713.2255 | H29: 2482.69 | I29: 4073.8 | J29: 0 | K29: 20.21 | L29: 137.75 | M29: 124.38 | N29: 0 | O29: =SUM(G29:N29) -> 9552.0555 | P29: =O29/Q29 -> 0.21217805 | Q29: =E29+O29 -> 45019.056
A30: Guadalupe School | B30: 1 | C30: 80000 | D30: 6.378 | E30: 37176 | F30: =C30/E30 -> 2.151926 | G30: =E30*0.0765 -> 2843.964 | H30: 1115.28 | I30: 4336.8 | J30: 171 | K30: 65.76 | L30: 105.12 | M30: 141.5 | N30: 0 | O30: =SUM(G30:N30) -> 8779.424 | P30: =O30/Q30 -> 0.19104217 | Q30: =E30+O30 -> 45955.424
A31: Hawthorn Academy | B31: 1 | C31: 82000 | D31: 34.55 | E31: 33861 | F31: =C31/E31 -> 2.421665 | G31: =E31*0.0765 -> 2590.3665 | H31: 0 | I31: 7800 | J31: 0 | K31: 0 | L31: 101.34 | M31: 766.53 | N31: 0 | O31: =SUM(G31:N31) -> 11258.237 | P31: =O31/Q31 -> 0.24952188 | Q31: =E31+O31 -> 45119.236
A32: Highmark Charter School | B32: 1 | C32: 72000 | D32: 22.77 | E32: 34933 | F32: =C32/E32 -> 2.0610884 | G32: =E32*0.0765 -> 2672.3745 | H32: 0 | I32: 7200 | J32: 0 | K32: 0 | L32: 104.84 | M32: 771.39 | N32: 0 | O32: =SUM(G32:N32) -> 10748.604 | P32: =O32/Q32 -> 0.23529394 | Q32: =E32+O32 -> 45681.605
... A37: Karl G Maeser Preparatory Academy | B37: 0.74 | C37: 56100 | D37: 30.605 | E37: 37609 | F37: =C37/E37 -> 1.4916642 | G37: =E37*0.0765 -> 2877.0885 | H37: 7619.5834 | I37: 758.49 | J37: 0 | K37: 98.5 | L37: 82.3 | M37: 37.609 | N37: 0 | O37: =SUM(G37:N37) -> 11473.571 | P37: =O37/Q37 -> 0.23376059 | Q37: =E37+O37 -> 49082.571
A38: Lakeview Academy | C38: INS | D38: 35.818 | E38: 36246 | G38: =E38*0.0765 -> 2772.819 | H38: 2537.22 | I38: 11245.59 | J38: 0 | K38: 0 | L38: 136.89 | M38: 36.246 | N38: 0 | O38: =SUM(G38:N38) -> 16728.765 | P38: =O38/Q38 -> 0.31578743 | Q38: =E38+O38 -> 52974.765
A39: Legacy Preparatory Academy | B39: 2 | C39: 62000 | D39: 51.15 | E39: 35624 | F39: =C39/E39 -> 1.7403997 | G39: =E39*0.0765 -> 2725.236 | H39: 7217.4224 | I39: 10506 | J39: 611 | K39: 10.8 | L39: 106 | M39: 295 | N39: 0 | O39: =SUM(G39:N39) -> 21471.458 | P39: =O39/Q39 -> 0.37606246 | Q39: =E39+O39 -> 57095.458
A40: Liberty Academy | C40: INS | D40: 20.65 | E40: 34580 | G40: =E40*0.0765 -> 2645.37 | H40: 7005.908 | I40: 3668 | J40: 460 | K40: 240 | L40: 276 | M40: 34.58 | N40: 0 | O40: =SUM(G40:N40) -> 14329.858 | P40: =O40/Q40 -> 0.29298507 | Q40: =E40+O40 -> 48909.858
A41: Lincoln Academy | B41: 1 | C41: 69160 | D41: 27.38 | E41: 37130 | F41: =C41/E41 -> 1.8626448 | G41: =E41*0.0765 -> 2840.445 | H41: 884.89 | I41: 8053.04 | J41: 848.63 | K41: 163.58 | L41: 137.38 | M41: 0 | N41: 76.82 | O41: =SUM(G41:N41) -> 13004.785 | P41: =O41/Q41 -> 0.25939645 | Q41: =E41+O41 -> 50134.785
A42: Maria Montessori Academy | B42: 1 | C42: 74500 | D42: 20.125 | E42: 36396 | F42: =C42/E42 -> 2.0469282 | G42: =E42*0.0765 -> 2784.294 | H42: 0 | I42: 7800 | J42: 0 | K42: 0 | L42: 108.63 | M42: 702.16 | N42: 0 | O42: =SUM(G42:N42) -> 11395.084 | P42: =O42/Q42 -> 0.23843535 | Q42: =E42+O42 -> 47791.084
A43: Merit College Preparatory Academy | C43: DNR | D43: 6.35 | E43: 34272 | G43: =E43*0.0765 -> 2621.808 | H43: 1028.16 | I43: 5678.04 | J43: 801.96 | K43: 57.36 | L43: 0 | M43: 727.2 | N43: 56.76 | O43: =SUM(G43:N43) -> 10971.288 | P43: =O43/Q43 -> 0.24249537 | Q43: =E43+O43 -> 45243.288
A44: Moab Charter School | B44: 1 | C44: 60000 | D44: 6.5 | E44: 34000 | F44: =C44/E44 -> 1.7647059 | G44: =E44*0.0765 -> 2601 | H44: 6888.4 | I44: 3932 | J44: 0 | K44: 0 | L44: 150.87 | M44: 34 | N44: 0 | O44: =SUM(G44:N44) -> 13606.27 | P44: =O44/Q44 -> 0.28580836 | Q44: =E44+O44 -> 47606.27
...
