Workbook

Sheet Dedicated Role - Planner
B1: Dedicated Cache Capacity Planner
B3: Input: Data Requirements | C3: Data Type 1 | E3: Data Type 2 | G3: Data Type 3 | I3: Data Type 4 | K3: Data Type 5 | M3: Data Type 6 | O3: Data Type 7 | Q3: Data Type 8 | S3: Data Type 9 | U3: Data Type 10
B4: Average Object Size (Post-Serialization) | C4: 2560 | D4: Bytes | E4: 0 | F4: Bytes | G4: 0 | H4: Bytes | I4: 0 | J4: Bytes | K4: 0 | L4: Bytes | M4: 0 | N4: Bytes | O4: 0 | P4: Bytes | Q4: 0 | R4: Bytes | S4: 0 | T4: Bytes | U4: 0 | V4: Bytes
B5: Maximum Number of Objects | C5: 100000 | D5: Objects | E5: 0 | F5: Objects | G5: 0 | H5: Objects | I5: 0 | J5: Objects | K5: 0 | L5: Objects | M5: 0 | N5: Objects | O5: 0 | P5: Objects | Q5: 0 | R5: Objects | S5: 0 | T5: Objects | U5: 0 | V5: Objects
B6: High Availability Enabled | C6: No | D6: Yes/No | E6: No | F6: Yes/No | G6: No | H6: Yes/No | I6: No | J6: Yes/No | K6: No | L6: Yes/No | M6: No | N6: Yes/No | O6: No | P6: Yes/No | Q6: No | R6: Yes/No | S6: No | T6: Yes/No | U6: No | V6: Yes/No
B8: Input: Throughput Requirements
B9: Number of Reads/sec | C9: 10000 | D9: ops/sec | E9: 0 | F9: /sec | G9: 0 | H9: /sec | I9: 0 | J9: /sec | K9: 0 | L9: /sec | M9: 0 | N9: /sec | O9: 0 | P9: /sec | Q9: 0 | R9: /sec | S9: 0 | T9: /sec | U9: 0 | V9: /sec
B10: Number of Writes/sec | C10: 500 | D10: ops/sec | E10: 0 | F10: /sec | G10: 0 | H10: /sec | I10: 0 | J10: /sec | K10: 0 | L10: /sec | M10: 0 | N10: /sec | O10: 0 | P10: /sec | Q10: 0 | R10: /sec | S10: 0 | T10: /sec | U10: 0 | V10: /sec
B12: Input: Advanced Options | C12: Value
B13: Cushion for peak load - Data | C13: 20 | D13: % increase
B14: Cushion for peak load - Throughput | C14: 20 | D14: % increase
B15: Preserve Data across Azure Updates | C15: Yes
B16: Upgrade Domain Count | C16: Set by planner
B19: Output: Possible Configurations | C19: VM Size | D19: VM Count | E19: Upgrade Domains | F19: Options | G19: ='Reference Data'!G125 -> <blank> | H19: Message
C20: S | D20: ='Reference Data'!D126 -> 5 | E20: ='Reference Data'!E126 -> 5 | F20: ='Reference Data'!F126 -> Feasible | G20: ='Reference Data'!G126 | H20: ='Reference Data'!H126
C21: M | D21: ='Reference Data'!D127 -> 3 | E21: ='Reference Data'!E127 -> 3 | F21: ='Reference Data'!F127 -> Recommended | G21: ='Reference Data'!G127 | H21: ='Reference Data'!H127
C22: L | D22: ='Reference Data'!D128 -> 2 | E22: ='Reference Data'!E128 -> 2 | F22: ='Reference Data'!F128 -> Feasible | G22: ='Reference Data'!G128 | H22: ='Reference Data'!H128
C23: XL | D23: ='Reference Data'!D129 -> 2 | E23: ='Reference Data'!E129 -> 2 | F23: ='Reference Data'!F129 -> Feasible | G23: ='Reference Data'!G129 | H23: ='Reference Data'!H129
C25: ='Reference Data'!$D$131

Sheet Co-located Role - Planner
B1: Co-located Cache Capacity Planner
B3: Input: Cluster Configuration
B4: VM Size | C4: M | D4: VM
B5: Number of VM Instances | C5: 3 | D5: VM
B6: User Data to be stored in Cache | C6: 1500 | D6: MB
B7: High Availability Enabled | C7: No | D7: Yes/No | E7: =IF(C5 = 1, IF(C7 = "Yes", "HA with 1 Node is Not Supported", ""), "")
B9: Output: Feasiblity & Settings
B10: Is it feasible to host Cache in this cluster | C10: ='Reference Data'!D27 -> Yes | D10: ='Reference Data'!D30 -> Please make sure there is enough network & CPU available to sustain load on cache
B11: Cache Size % (Memory required for Cache) | C11: ='Reference Data'!D28 -> 30 | D11: % per VM

Sheet Reference Data
C2: VM Type | D2: Physical Memory (MB) | E2: Cache Working Set (MB) | F2: Cache Data Size on VM (MB) | L2: VM Network | N2: Static Overhead (MB) | P2: Partitions Count per Cache
F3: No HA (Default 2KB) | G3: With HA (Default 2KB) | H3: No HA (1KB) | I3: With HA (1KB) | J3: No HA (128 byte) | K3: With HA (128 byte) | L3: Mbps | M3: MBps | N3: Without HA | O3: With HA (MB)
C4: XS | D4: 766 | E4: 237 | F4: 115 | G4: 71 | H4: 101 | I4: 63 | J4: 42 | K4: 26 | L4: 5 | M4: =L4/8 -> 0.625 | N4: 110 | O4: 150 | P4: 30
C5: S | D5: 1790 | E5: 1020 | F5: 791 | G5: 711 | H5: 696 | I5: 626 | J5: 288 | K5: 259 | L5: 100 | M5: =L5/8 -> 12.5 | N5: 148 | O5: 228 | P5: =P4*2 -> 60
C6: M | D6: 3583 | E6: 2831 | F6: 2372 | G6: 2227 | H6: 2088 | I6: 1960 | J6: 866 | K6: 813 | L6: 200 | M6: =L6/8 -> 25 | N6: 216 | O6: 376 | P6: =P5*2 -> 120
C7: L | D7: 7230 | E7: 6145 | F7: 5243 | G7: 4956 | H7: 4615 | I7: 4363 | J7: 1914 | K7: 1810 | L7: 400 | M7: =L7/8 -> 50 | N7: 365 | O7: 685 | P7: =P6*2 -> 240
C8: XL | D8: 14398 | E8: 13031 | F8: 11236 | G8: 10681 | H8: 9891 | I8: 9402 | J8: 4103 | K8: 3900 | L8: 800 | M8: =L8/8 -> 100 | N8: 644 | O8: 1284 | P8: =P7*2 -> 480
J9: Unused | K9: Unused
C11: Co-located planner INTERNAL CALCULATIONS BEYOND THIS POINT
C13: Input: Internal Variables
C14: Nodes per UD | D14: 1 | E14: VM
C15: Minimum Cache Size | D15: 2 | E15: MB
C17: Computed: Requirement Calculations
C18: Physical Memory on VM | D18: =VLOOKUP('Co-located Role - Planner'!$C$4, 'Reference Data'!$C$4:'Reference Data'!$O$8, 2, FALSE) -> 3583 | E18: MB
C19: Max Physical Memory available to Cache | D19: =VLOOKUP('Co-located Role - Planner'!$C$4, 'Reference Data'!$C$4:'Reference Data'!$O$8, 3, FALSE) -> 2831 | E19: MB
C21: Number of VMs to consider for storage | D21: =MAX(('Co-located Role - Planner'!C5-$D$14), 1) -> 2 | E21: VMs
C22: User Data to be stored per VM (including copies) | D22: =ROUNDUP(('Co-located Role - Planner'!C6/D21) * IF('Co-located Role - Planner'!$C$7 = "Yes", IF(D21>1, 2, 1), 1), 0) -> 750 | E22: MB
C23: Static Cache Overheads (depends on HA ON/OFF) | D23: =VLOOKUP('Co-located Role - Planner'!$C$4, 'Reference Data'!$C$4:'Reference Data'!$O$8, IF('Co-located Role - Planner'!$C$7="Yes", 13, 12), FALSE) -> 216 | E23: MB
C24: Physical Memory for Cache per VM | D24: =ROUNDUP(D22*1.1 + D23, 0) -> 1041 | E24: MB
C26: Feasibility of hosting Cache (1 or 0) | D26: =IF(D24<=D19, 1, 0) -> 1 | E26: Flag
C27: Is it feasible to host Cache in this cluster | D27: =IF($D$26 = 1, IF($D$22 >= $D$15, "Yes", "No"), "No") -> Yes
C28: Physical Memory % required for Cache | D28: =ROUNDUP(D24*100/D18, 0) -> 30 | E28: % per VM | G28: =ROUNDUP(ROUNDUP(((ROUNDUP(('Co-located Role - Planner'!C6/'Co-located Role - Planner'!C5) * IF('Co-located Role - Planner'!$C$7 = "Yes", IF('Co-located Role - Planner'!C5>1, 2, 1), 1), 0))*1.1 + D23), 0)*100/D18, 0) -> 22 | H28: % per VM (without resiliency)
C29: Physical Memory % available for primary role | D29: =ROUNDUP((D19-D24)*100/D18, 0) -> 50 | E29: % per VM
C30: Message (if any) | D30: =IF($D$26 = 0, $C$33, IF(D22 >= $D$15, $C$34, $C$35)) -> Please make sure there is enough network & CPU available to sustain load on cache
C32: Strings Used
C33: Please consider a different configuration (VM size, VM count) or move to Dedicated Cache
C34: Please make sure there is enough network & CPU available to sustain load on cache
C35: Such a small cache is not supported
C40: Dedicated planner INTERNAL CALCULATIONS BEYOND THIS POINT
C42: Input: Maximum Memory Requirements | D42: Value | E42: Unit
C43: Maximum memory to use per VM | D43: 95 | E43: %
C44: Maximum network to use per VM | D44: 80 | E44: %
C45: Time for data transfer during graceful shtudown | D45: 210 | E45: seconds
C46: Maximum Supported Upgraded Domains | D46: 16 | E46: UDs
C47: HA: Storage Overheads | D47: 2 | E47: times
C48: HA: Throughput Overheads(Network/CPU) | D48: 6 | E48: times
C49: Throughput Write Overhead | D49: =4/3 -> 1.3333333 | E49: times
C50: Default Object Size (bytes) | D50: 2048 | E50: bytes
C51: Default Buffer Size (bytes | D51: 1024 | E51: bytes
C53: Computed: Data Requirements | D53: Value | E53: Unit | F53: Value | G53: Unit | H53: Value | I53: Unit | J53: Value | K53: Unit | L53: Value | M53: Unit | N53: Value | O53: Unit | P53: Value | Q53: Unit | R53: Value | S53: Unit | T53: Value | U53: Unit | V53: Value | W53: Unit
...
