Workbook

Sheet Instructivo
B1: INSTRUCTIVO ELABORACION PRESUPUESTO
B3: Para el diligenciamiento del presupuesto favor tener presente las siguientes instrucciones:
A5: Observación General: | B5: Por motivos presupuestales y con el fin que tanto el Receptor Principal (CHF) y las EE, manejen los mismos terminos en cuanto a la ejecución presupuestal, se hace la claridad que este presupuesto se debe preparar trimestralmente y teniendo en cuenta la vigencia aprobada por el fondo mundial. Para esto se hace necesario aclarar algunos parametros a tener en cuenta en la elaboracion de este presupuesto: El año 1 del proyecto VIH abarca el período (Abril1, 2011-Marzo31,2012). Por tanto El trimestre 4 del año 1 para este ejercicio es el período comprendido Enero1-Marzo31,2012 El año 2 del proyecto VIH abarca el período (Abril1, 2012-Marzo31,2013).
B7: RECURSO HUMANO
B9: Esta representado en el recurso humano administrativo y programatico, mediante los siguientes cargos:
B10: Coordinador
B11: Profesionales en Salud Sexual y Reproductiva
B12: Técnicos en Salud Sexual y Reproductiva (SSR)
B13: Contador
B14: Asistente de Información
B15: Apoyo a la Direccion o Representación Legal (esta posición corresponde como su nombre lo indica a un apoyo a la representación legal y estará representado por un valor no superior al 2% del total del presupuesto asignado a la entidad ejecutora sin incluir los rubros de destinación especifica y no deberá ser mayor al salario u honorario mensual de esa posición en su organización. Para ello deberán enviar a CHF soporte del pago mensual o contrato para validar el valor cobrado al proyecto.
A17: Hipotesis | B17: Deberán registrar la manera como se obtiene el costo presupuestado, teniendo en cuenta los rangos mencionados en los términos de referencia
A18: Unidad de Medida | B18: Deberán registrar la unidad de medida con la que se presupuesto, ej (si es salario, o contrato prestacion servicios, jornal, etc)
A19: Costo unitario | B19: Deberán registrar el valor trimestral del salario u honorario de la posición presupuestada (ej: tomar el salario u honorario mensual de los profesionales en salud y multiplicarlo por 3)
A20: Cantidad trimestre xx | B20: Se deberar colocar el numero de posiciones que requieren para esa línea que estan presupuestando.
B23: MONITOREO Y EVALUACION
A24: Hipotesis | B24: Deberán registrar la manera como obtuvieron los costos unitarios presupuestados por las 4 líneas solicitadas (Viaticos, Desplazamientos, Actividades de Gestión y Actividades Servicios Comunitarios )
A25: Unidad de Medida | B25: Deberán registrar la unidad medida con la que realizaron el presupuesto, es decir, para viaticos: el valor viatico por municipio, para desplazamientos será el costo del trayecto ida y vuelta, para las actividades de gestión, sera costo reunión, para las actividades de servicios comunitarios , la unidad de medida será fondo actividades y este será determinado una vez identifiquen la actividad a realizar y estará sujeta a aprobación por parte de CHF)
A26: Costo unitario | B26: Viaticos y Desplazamientos : estarán sujetos a las políticas y procedimientos de su organización, y deberán detallar en esta línea el costo por viaje. Para el caso de las Actividades de Gestión, el costo unitario es $30.000 mensuales Para las Actividades de Servicios Comunitarios el valor mensual será de $200.000 y deberan multiplicarlo por 3, pues la unidad es trimestral y estará sujeto a las propuestas que envien para aprobación de CHF
A27: Cantidad trimestre xx | B27: Para el tema de viajes y desplazamientos, deberán registrar el numero de viajes a realizar . Para las actividades de gestion y las actividades de servicios comunitarios la cantidad es 1, puesto que el costo unitario es trimestral y se presupuesto una sóla por actividad por mes .
B30: PLANIFICACION Y ADMINISTRACION
A31: Hipotesis | B31: Deberán insertar tantas filas como itmes a presupuestar (ej: arriendo, servicios públicos .. Los descritos en el presupuesto)
A32: Unidad de Medida | B32: La unidad de medida sera la correspondiente al rubro en mención, (ej: para arriendo, la unidad de medida será apoyo mensual arriendo, etc…)
A33: Costo unitario | B33: El costo unitario es el valor trimestral de la línea presupuestada, (ej: arriendo, sera el valor mensual por este concepto por 3 meses)
A34: Cantidad trimestre xx | B34: La cantidad será 1 pues el costo unitario esta dado en trimestres.
B36: DESTINACION ESPECIFICA
B37: Estas son partidas que tienen actividades y costos fijos, los cuales son immodificables. Cualquier exceso en el desarrollo de las actividades deberan ser asumidos por la Entidad Ejecutora.
B39: BRIGADAS
B40: Corresponde al costo entregado al lider comunitario para realizar brigadas . Este costo es dado por CHF y no podrá ser utilizado en otro concepto.
B42: ASISTENCIA TECNICA SERVICIO COMUNITARIO
B43: Corresponde a $36.000 por hora para realizar visitas de fortalecimiento y capacitación a los servicios comunitarios en las necesidades identificadas en la evaluación de necesidades. El primera año serán visitas de 24 horas por servicio comunitario pues es el inicio del proceso y el segundo año serán visitas de 12 horas las cuales son de seguimiento y refuerzo. Este costo es dado por CHF y no podrá ser utilizado en otro concepto.
B45: ENCUENTROS PARA CAMPAÑAS ALTERNATIVAS
B46: Es un costo para realizar de manera creativa y alternativa campañas para la movilización social en torno a la prevención del VIH y la promoción de la solidaridad frente a los grupos clave. Este costo es dado por CHF y no podrá ser utilizado en otro concepto.
B48: ENCUENTROS GRUPOS CLAVE
B49: Este costo incluye un apoyo para las reuniones el cual esta dado en agua, café, apoyo alquiler salón.
B51: INCENTIVOS
B52: Este costo corresponde a un apoyo de 3 meses para vincular laboralmente a las mujeres beneficiadas del proyecto. Este costo es dado por CHF y no podrá ser utilizado en otro concepto.
A54: Tope Presupuestal | B54: Es es el presupuesto asignado por cada rubro del presupuesto aprobado por departamento o unión de departamentos. Como su nombre lo indica es el limite prespuestal hasta el cual debe llegar la entidad ejecutora proponente.

Sheet Summary Ant-Choco
A1: PRESUPUESTO ENTIDADES EJECUTORAS
A2: ANTIOQUIA y CHOCO
A4: Nombre Entidad Ejecutora:
A6: Detalle | B6: Presupuesto Total | C6: Tope Presupuestal
A7: Recurso Humano | B7: =+'Fase I Antio-Choco'!AH4 -> 0 | C7: =+'Fase I Antio-Choco'!AI4 -> 622607089
A8: Monitoreo y Evaluación | B8: =+'Fase I Antio-Choco'!AH11 -> 0 | C8: =+'Fase I Antio-Choco'!AI11 -> 186782123
A9: Planeación y Administración | B9: =+'Fase I Antio-Choco'!AH28 -> 0 | C9: =+'Fase I Antio-Choco'!AI28 -> 80049491
A10: Total Rubros de Funcionamiento | B10: =SUM(B7:B9) -> 0 | C10: =SUM(C7:C9) -> 889438703
A12: Destinación Específica | B12: =+'Fase I Antio-Choco'!AH39 -> 279396135 | C12: =+'Fase I Antio-Choco'!AI39 -> 279396135
A13: Total Destinación Específica | B13: =+B12 -> 279396135 | C13: =+C12 -> 279396135
A14: PRESUPUESTO TOTAL | B14: =+B10+B13 -> 279396135 | C14: =+C10+C13 -> 1168834838
A19: XXXXXX
A20: REPRESENTANTE LEGAL

Sheet Fase I Antio-Choco
A1: PRESUPUESTO DETALLADO
A2: No | B2: No de Objetivo: Crear capacidad comunitaria para la adopción de comportamientos seguros, la reducción de la vulnerabilidad social al VIH y el empoderamiento de los grupos clave priorizados | C2: Área de prestación de servicios (APS) | D2: Macro-Categoría | E2: Tarea | F2: Sub -Tarea | G2: Descripción / Hipotesis | H2: Año 1 | I2: Año 2 | M2: Responsable de la ejecución | N2: Tipo de entidad ejecutora | O2: Categorías de costos | P2: Unidad de medida año 1 | Q2: Costo unitario año 1 (valor trimestre) | R2: Cantidad Trimestre 4 | S2: Importe total Trimestre 4 | T2: Cantidad total Año 1 | U2: Total Año 1 | V2: Unidad de medida año 2 | W2: Costo unitario año 2 (valor trimestre) | X2: Cantidad Trimestre 1 año 2 | Y2: Importe total Trimestre 1 año 2 | Z2: Cantidad Trimestre 2 año 2 | AA2: Importe total Trimestre 2 año 2 | AB2: Cantidad Trimestre 3 año 2 | AC2: Importe total Trimestre 3 año 2 | AD2: Cantidad Trimestre 4 año 2 | AE2: Importe total Trimestre 4 año 2 | AF2: Cantidad total Año 2 | AG2: Total Año 2 | AH2: COSTO TOTAL | AI2: Tope Presupuestal
C3: SDA | D3: Activity | H3: T4 | I3: T1 | J3: T2 | K3: T3 | L3: T4
A4: RECURSO HUMANO | AH4: =SUM(AH5:AH10) -> 0 | AI4: 622607089
A5: 7 | B5: 1 | C5: Refuerzo de la sociedad civil | D5: 1.1 Implementar estrategias de promoción de la demanda de asesoría y prueba voluntaria (APV) y de comunicación para el cambio de comportamiento (CCC) | E5: 1.1.5 Identificar y formar líderes pares de los grupos clave priorizados para que actúen como formadores e integren los equipos locales de promoción de la salud y prevención del VIH e ITS | F5: Costo recurso humano administración de la entidad ejecutora | G5: Contador | M5: Entidad Ejecutora | N5: ONG/OBC/Sector Académico | O5: Recursos Humanos | P5: Salario / Honorario | S5: =+R5*Q5 -> 0 | T5: =+R5 -> 0 | U5: =S5 -> 0 | V5: Salario / Honorario | Y5: =+W5*X5 -> 0 | AA5: =+Z5*W5 -> 0 | AC5: =+AB5*W5 -> 0 | AE5: =+AD5*W5 -> 0 | AF5: =+X5+Z5+AB5+AD5 -> 0 | AG5: =+Y5+AA5+AC5+AE5 -> 0 | AH5: =+U5+AG5 -> 0
A6: 7 | B6: 1 | G6: Apoyo a la Dirección o Representación Legal | M6: Entidad Ejecutora | N6: ONG/OBC/Sector Académico | O6: Recursos Humanos | P6: Salario / Honorario | S6: =+R6*Q6 -> 0 | T6: =+R6 -> 0 | U6: =S6 -> 0 | V6: Salario / Honorario | Y6: =+W6*X6 -> 0 | AA6: =+Z6*W6 -> 0 | AC6: =+AB6*W6 -> 0 | AE6: =+AD6*W6 -> 0 | AF6: =+X6+Z6+AB6+AD6 -> 0 | AG6: =+Y6+AA6+AC6+AE6 -> 0 | AH6: =+U6+AG6 -> 0
A7: 7 | B7: 1 | G7: Asistente de Información | M7: Entidad Ejecutora | N7: ONG/OBC/Sector Académico | O7: Recursos Humanos | P7: Salario / Honorario | S7: =+R7*Q7 -> 0 | T7: =+R7 -> 0 | U7: =S7 -> 0 | V7: Salario / Honorario | Y7: =+W7*X7 -> 0 | AA7: =+Z7*W7 -> 0 | AC7: =+AB7*W7 -> 0 | AE7: =+AD7*W7 -> 0 | AF7: =+X7+Z7+AB7+AD7 -> 0 | AG7: =+Y7+AA7+AC7+AE7 -> 0 | AH7: =+U7+AG7 -> 0
A8: 11 | B8: 1 | C8: Refuerzo de la sociedad civil | F8: Costo recurso humano programatico de la entidad ejecutora | G8: Coordinador | M8: Entidad Ejecutora | N8: ONG/OBC/Sector Académico | O8: Recursos Humanos | P8: Salario / Honorario | S8: =+R8*Q8 -> 0 | T8: =+R8 -> 0 | U8: =S8 -> 0 | V8: Salario / Honorario | Y8: =+W8*X8 -> 0 | AA8: =+Z8*W8 -> 0 | AC8: =+AB8*W8 -> 0 | AE8: =+AD8*W8 -> 0 | AF8: =+X8+Z8+AB8+AD8 -> 0 | AG8: =+Y8+AA8+AC8+AE8 -> 0 | AH8: =+U8+AG8 -> 0
A9: 11 | B9: 1 | C9: Refuerzo de la sociedad civil | G9: Profesionales en Salud Sexual y Reproductiva (SSR) | M9: Entidad Ejecutora | N9: ONG/OBC/Sector Académico | O9: Recursos Humanos | P9: Salario / Honorario | S9: =+R9*Q9 -> 0 | T9: =+R9 -> 0 | U9: =S9 -> 0 | V9: Salario / Honorario | Y9: =+W9*X9 -> 0 | AA9: =+Z9*W9 -> 0 | AC9: =+AB9*W9 -> 0 | AE9: =+AD9*W9 -> 0 | AF9: =+X9+Z9+AB9+AD9 -> 0 | AG9: =+Y9+AA9+AC9+AE9 -> 0 | AH9: =+U9+AG9 -> 0
A10: 11 | B10: 1 | C10: Refuerzo de la sociedad civil | G10: Técnicos en Salud Sexual y Reproductiva (SSR) | M10: Entidad Ejecutora | N10: ONG/OBC/Sector Académico | O10: Recursos Humanos | P10: Salario / Honorario | S10: =+R10*Q10 -> 0 | T10: =+R10 -> 0 | U10: =S10 -> 0 | V10: Salario / Honorario | Y10: =+W10*X10 -> 0 | AA10: =+Z10*W10 -> 0 | AC10: =+AB10*W10 -> 0 | AE10: =+AD10*W10 -> 0 | AF10: =+X10+Z10+AB10+AD10 -> 0 | AG10: =+Y10+AA10+AC10+AE10 -> 0 | AH10: =+U10+AG10 -> 0
A11: MONITOREO Y EVALUACION | AH11: =SUM(AH12:AH27) -> 0 | AI11: 186782123
A12: 13 | B12: 1 | C12: Refuerzo de la sociedad civil | D12: 1.1 Implementar estrategias de promoción de la demanda de asesoría y prueba voluntaria (APV) y de comunicación para el cambio de comportamiento (CCC) | E12: 1.1.5 Identificar y formar líderes pares de los grupos clave priorizados para que actúen como formadores e integren los equipos locales de promoción de la salud y prevención del VIH e ITS | F12: Este costo incluye: 1. Viaticos y desplazamientos a los municipios de influencia asignados. 2. Actividades de gestion municipal y departamental para la sostenibilidad de las iniciativas. 3. Actividades en los servicios comunitarios para el encuentro con las comunidades, generación de confianza con las poblaciones priorizadas, actividades de escucha, reducción del estigma y la discriminaciòn, entre otras (Ejm: chocolatadas, teatro o cine al parque, actividades de trueque, acciones sanatorias de apoyo en situaciòn de alta vulnerabilidad para estabilizar a las poblaciones, entre otras) | G12: Viaticos por municipio | M12: Entidad Ejecutora | N12: ONG/OBC/Sector Académico | O12: Monitoreo y evaluación | P12: Viatico | R12: =+SUM(R13:R18) -> 0 | S12: =+SUM(S13:S18) -> 0 | T12: =+SUM(T13:T18) -> 0 | U12: =S12 -> 0 | V12: Viatico | X12: =+SUM(X13:X18) -> 0 | Y12: =+SUM(Y13:Y18) -> 0 | Z12: =+SUM(Z13:Z18) -> 0 | AA12: =+SUM(AA13:AA18) -> 0 | AB12: =+SUM(AB13:AB18) -> 0 | AC12: =+SUM(AC13:AC18) -> 0 | AD12: =+SUM(AD13:AD18) -> 0 | AE12: =+SUM(AE13:AE18) -> 0 | ... AG12: =+SUM(AG13:AG18) -> 0 | AH12: =+U12+AG12 -> 0
G13: Medellin | S13: =+R13*Q13 -> 0 | T13: =+R13 -> 0 | U13: =+S13 -> 0 | Y13: =+W13*X13 -> 0 | AA13: =+$W13*Z13 -> 0 | AC13: =+$W13*AB13 -> 0 | AE13: =+$W13*AD13 -> 0 | AF13: =+X13+Z13+AB13+AD13 -> 0 | AG13: =+Y13+AA13+AC13+AE13 -> 0
G14: Apartado | S14: =+R14*Q14 -> 0 | T14: =+R14 -> 0 | U14: =+S14 -> 0 | Y14: =+W14*X14 -> 0 | AA14: =+$W14*Z14 -> 0 | AC14: =+$W14*AB14 -> 0 | AE14: =+$W14*AD14 -> 0 | AF14: =+X14+Z14+AB14+AD14 -> 0 | AG14: =+Y14+AA14+AC14+AE14 -> 0
G15: Carmen de Viboral | S15: =+R15*Q15 -> 0 | T15: =+R15 -> 0 | U15: =+S15 -> 0 | Y15: =+W15*X15 -> 0 | AA15: =+$W15*Z15 -> 0 | AC15: =+$W15*AB15 -> 0 | AE15: =+$W15*AD15 -> 0 | AF15: =+X15+Z15+AB15+AD15 -> 0 | AG15: =+Y15+AA15+AC15+AE15 -> 0
G16: Quibdo | S16: =+R16*Q16 -> 0 | T16: =+R16 -> 0 | U16: =+S16 -> 0 | Y16: =+W16*X16 -> 0 | AA16: =+$W16*Z16 -> 0 | AC16: =+$W16*AB16 -> 0 | AE16: =+$W16*AD16 -> 0 | AF16: =+X16+Z16+AB16+AD16 -> 0 | AG16: =+Y16+AA16+AC16+AE16 -> 0
G17: Bahia Solano | S17: =+R17*Q17 -> 0 | T17: =+R17 -> 0 | U17: =+S17 -> 0 | Y17: =+W17*X17 -> 0 | AA17: =+$W17*Z17 -> 0 | AC17: =+$W17*AB17 -> 0 | AE17: =+$W17*AD17 -> 0 | AF17: =+X17+Z17+AB17+AD17 -> 0 | AG17: =+Y17+AA17+AC17+AE17 -> 0
G18: Itsmina | S18: =+R18*Q18 -> 0 | T18: =+R18 -> 0 | U18: =+S18 -> 0 | Y18: =+W18*X18 -> 0 | AA18: =+$W18*Z18 -> 0 | AC18: =+$W18*AB18 -> 0 | AE18: =+$W18*AD18 -> 0 | AF18: =+X18+Z18+AB18+AD18 -> 0 | AG18: =+Y18+AA18+AC18+AE18 -> 0
A19: 13 | B19: 1 | C19: Refuerzo de la sociedad civil | G19: Desplazamientos por municipio | M19: Entidad Ejecutora | N19: ONG/OBC/Sector Académico | O19: Monitoreo y evaluación | P19: Desplazamiento | R19: =+SUM(R20:R25) -> 0 | S19: =+SUM(S20:S25) -> 0 | T19: =+R19 -> 0 | U19: =S19 -> 0 | V19: Desplazamiento | X19: =+SUM(X20:X25) -> 0 | Y19: =+SUM(Y20:Y25) -> 0 | Z19: =+SUM(Z20:Z25) -> 0 | AA19: =+SUM(AA20:AA25) -> 0 | AB19: =+SUM(AB20:AB25) -> 0 | AC19: =+AB19*W19 -> 0 | AD19: =+SUM(AD20:AD25) -> 0 | AE19: =+SUM(AE20:AE25) -> 0 | AF19: =+SUM(AF20:AF25) -> 0 | AG19: =+SUM(AG20:AG25) -> 0 | AH19: =+U19+AG19 -> 0
G20: Medellin | S20: =+R20*Q20 -> 0 | T20: =+R20 -> 0 | U20: =+S20 -> 0 | Y20: =+W20*X20 -> 0 | AA20: =+$W20*Z20 -> 0 | AC20: =+$W20*AB20 -> 0 | AE20: =+$W20*AD20 -> 0 | AF20: =+X20+Z20+AB20+AD20 -> 0 | AG20: =+Y20+AA20+AC20+AE20 -> 0
G21: Apartado | S21: =+R21*Q21 -> 0 | T21: =+R21 -> 0 | U21: =+S21 -> 0 | Y21: =+W21*X21 -> 0 | AA21: =+$W21*Z21 -> 0 | AC21: =+$W21*AB21 -> 0 | AE21: =+$W21*AD21 -> 0 | AF21: =+X21+Z21+AB21+AD21 -> 0 | AG21: =+Y21+AA21+AC21+AE21 -> 0
G22: Carmen de Viboral | S22: =+R22*Q22 -> 0 | T22: =+R22 -> 0 | U22: =+S22 -> 0 | Y22: =+W22*X22 -> 0 | AA22: =+$W22*Z22 -> 0 | AC22: =+$W22*AB22 -> 0 | AE22: =+$W22*AD22 -> 0 | AF22: =+X22+Z22+AB22+AD22 -> 0 | AG22: =+Y22+AA22+AC22+AE22 -> 0
G23: Quibdo | S23: =+R23*Q23 -> 0 | T23: =+R23 -> 0 | U23: =+S23 -> 0 | Y23: =+W23*X23 -> 0 | AA23: =+$W23*Z23 -> 0 | AC23: =+$W23*AB23 -> 0 | AE23: =+$W23*AD23 -> 0 | AF23: =+X23+Z23+AB23+AD23 -> 0 | AG23: =+Y23+AA23+AC23+AE23 -> 0
G24: Bahia Solano | S24: =+R24*Q24 -> 0 | T24: =+R24 -> 0 | U24: =+S24 -> 0 | Y24: =+W24*X24 -> 0 | AA24: =+$W24*Z24 -> 0 | AC24: =+$W24*AB24 -> 0 | AE24: =+$W24*AD24 -> 0 | AF24: =+X24+Z24+AB24+AD24 -> 0 | AG24: =+Y24+AA24+AC24+AE24 -> 0
G25: Itsmina | S25: =+R25*Q25 -> 0 | T25: =+R25 -> 0 | U25: =+S25 -> 0 | Y25: =+W25*X25 -> 0 | AA25: =+$W25*Z25 -> 0 | AC25: =+$W25*AB25 -> 0 | AE25: =+$W25*AD25 -> 0 | AF25: =+X25+Z25+AB25+AD25 -> 0 | AG25: =+Y25+AA25+AC25+AE25 -> 0
A26: 13 | B26: 1 | C26: Refuerzo de la sociedad civil | G26: Actividades de Gestión | M26: Entidad Ejecutora | N26: ONG/OBC/Sector Académico | O26: Monitoreo y evaluación | P26: Costo reunión | S26: =+R26*Q26 -> 0 | T26: =+R26 -> 0 | U26: =S26 -> 0 | V26: Costo reunión | Y26: =+W26*X26 -> 0 | AA26: =+Z26*W26 -> 0 | AC26: =+AB26*W26 -> 0 | AE26: =+AD26*W26 -> 0 | AF26: =+X26+Z26+AB26+AD26 -> 0 | AG26: =+Y26+AA26+AC26+AE26 -> 0 | AH26: =+U26+AG26 -> 0
A27: 13 | B27: 1 | C27: Refuerzo de la sociedad civil | G27: Actividades Servicios Comunitarios | M27: Entidad Ejecutora | N27: ONG/OBC/Sector Académico | O27: Monitoreo y evaluación | P27: Actividades | S27: =+R27*Q27 -> 0 | T27: =+R27 -> 0 | U27: =S27 -> 0 | V27: Actividades | Y27: =+W27*X27 -> 0 | AA27: =+Z27*W27 -> 0 | AC27: =+AB27*W27 -> 0 | AE27: =+AD27*W27 -> 0 | AF27: =+X27+Z27+AB27+AD27 -> 0 | AG27: =+Y27+AA27+AC27+AE27 -> 0 | AH27: =+U27+AG27 -> 0
A28: PLANIFICACION Y ADMINISTRACION | AH28: =SUM(AH29) -> 0 | AI28: =97838265-17788774 -> 80049491
A29: 8 | B29: 1 | C29: Refuerzo de la sociedad civil | D29: 1.1 Implementar estrategias de promoción de la demanda de asesoría y prueba voluntaria (APV) y de comunicación para el cambio de comportamiento (CCC) | E29: 1.1.5 Identificar y formar líderes pares de los grupos clave priorizados para que actúen como formadores e integren los equipos locales de promoción de la salud y prevención del VIH e ITS | F29: Este costo incluye los Costos Administrativos (como, Arriendo, servicios públicos, Comunicaciones, impresiones, fotocopias, papelería, correos, gastos bancarios, seguros, mantenimiento y reparaciones, servicios generales, entre otros). | M29: Entidad Ejecutora | N29: ONG/OBC/Sector Académico | O29: Planificación y Administración | S29: =+R29*Q29 -> 0 | T29: =+R29 -> 0 | U29: =S29 -> 0 | Y29: =+W29*X29 -> 0 | AA29: =+Z29*W29 -> 0 | AC29: =+AB29*W29 -> 0 | AE29: =+AD29*W29 -> 0 | AF29: =+X29+Z29+AB29+AD29 -> 0 | AG29: =+Y29+AA29+AC29+AE29 -> 0 | AH29: =+U29+AG29 -> 0
A30: TOTAL RUBROS DE FUNCIONAMIENTO | AH30: =+AH4+AH11+AH28 -> 0 | AI30: =+AI4+AI11+AI28 -> 889438703
AH31: =SUM(AH7:AH29) -> 0
A32: DESTINACION ESPECIFICA
A33: 6 | B33: 1 | C33: CCC (Comunicación para Cambio de Comportamiento)- Medios de comunicación | D33: 1.1 Implementar estrategias de promoción de la demanda de asesoría y prueba voluntaria (APV) y de comunicación para el cambio de comportamiento (CCC) | E33: 1.1.4 Implementar acciones de CCC y de promoción de demanda de APV en medios alternativos y cara-a-cara (outreach) para transformar conductas sexuales de riesgo, promover el uso consistente y adecuado del condón y divulgar servicios y rutas de derechos a los grupos clave | F33: Este costo esta representado por brigadas de acercamiento a los grupos clave en sus entornos naturales | G33: Costo por brigada. El costo asignado por brigada es de $15,355. Incluye alimentación y transporte | M33: Entidad Ejecutora | N33: ONG/OBC/Sector Académico | O33: Capacitación | P33: costo por brigada | Q33: =15355 -> 15355 | R33: 547 | S33: =+R33*Q33 -> 8399185 | T33: =+R33 -> 547 | U33: =S33 -> 8399185 | V33: costo por brigada | W33: =+Q33 -> 15355 | X33: 547 | Y33: =+W33*X33 -> 8399185 | Z33: 547 | AA33: =+Z33*W33 -> 8399185 | AB33: =+Z33 -> 547 | AC33: =+AB33*W33 -> 8399185 | AD33: 549 | AE33: =+AD33*W33 -> 8429895 | AF33: =+X33+Z33+AB33+AD33 -> 2190 | AG33: =+Y33+AA33+AC33+AE33 -> 33627450 | AH33: =+U33+AG33 -> 42026635
A34: 34 | B34: 1 | C34: Refuerzo de las capacidades institucionales | D34: 1.3 Crear y fortalecer servicios comunitarios y/o redes comunitarias tipo A para la prevención del VIH/Sida /ITS, la promoción y referencia a APV, la educación en derechos y el empoderamiento de los grupos clave | E34: 1.3.5 Diseñar e implementar un plan de mejoramiento de capacidades locativas, de dotación y del recurso humano en los servicios comunitarios tipo A para la implementación efectiva de estrategias de CCC, promoción de la demanda de APV, educación en derechos, educación de pares | F34: Desarrollo de asistencia técnica a los servicios comunitarios tipo A asignados en temas identificados en la evaluación de necesidades | G34: Costo por servicio comunitario de 24 horas (valor hora $36.000) | M34: Entidad Ejecutora | N34: ONG/OBC/Sector Académico | O34: Asistencia técnica y gerencial | P34: Costo por hora asistencia tecnica | S34: =+R34*Q34 -> 0 | T34: =+R34 -> 0 | U34: =S34 -> 0 | V34: Costo por hora asistencia tecnica | W34: =36000*24 -> 864000 | X34: 10 | Y34: =+W34*X34 -> 8640000 | Z34: 11 | AA34: =+Z34*W34 -> 9504000 | AC34: =+AB34*W34 -> 0 | AD34: =+AB34 -> 0 | AE34: =+AD34*W34 -> 0 | AF34: =+X34+Z34+AB34+AD34 -> 21 | AG34: =+Y34+AA34+AC34+AE34 -> 18144000 | AH34: =+U34+AG34 -> 18144000
A35: 35 | B35: 1 | C35: Refuerzo de las capacidades institucionales | D35: 1.3 Crear y fortalecer servicios comunitarios y/o redes comunitarias tipo A para la prevención del VIH/Sida /ITS, la promoción y referencia a APV, la educación en derechos y el empoderamiento de los grupos clave | E35: 1.3.5 Diseñar e implementar un plan de mejoramiento de capacidades locativas, de dotación y del recurso humano en los servicios comunitarios tipo A para la implementación efectiva de estrategias de CCC, promoción de la demanda de APV, educación en derechos, educación de pares | F35: Desarrollo de asistencia técnica a los servicios comunitarios tipo A asignados en temas identificados en la evaluación de necesidades | G35: Costo por servicio comunitario de 12 horas (valor hora $36.000) | M35: Entidad Ejecutora | N35: ONG/OBC/Sector Académico | O35: Asistencia técnica y gerencial | P35: Costo por hora asistencia tecnica | S35: =+R35*Q35 -> 0 | T35: =+R35 -> 0 | U35: =S35 -> 0 | V35: Costo por hora asistencia tecnica | W35: =36000*12 -> 432000 | Y35: =+W35*X35 -> 0 | Z35: =+X35 -> 0 | AA35: =+Z35*W35 -> 0 | AB35: 21 | AC35: =+AB35*W35 -> 9072000 | AD35: =+AB35 -> 21 | AE35: =+AD35*W35 -> 9072000 | AF35: =+X35+Z35+AB35+AD35 -> 42 | AG35: =+Y35+AA35+AC35+AE35 -> 18144000 | AH35: =+U35+AG35 -> 18144000
A36: 43 | B36: 1 | C36: Reducción del estigma en todas las circunstancias | D36: 1.4 Implementar estrategias de movilización social para la reducción del estigma y la discriminación, la incidencia política y el agenciamiento social | E36: 1.4.3 Implementar estrategias de comunicación y movilización social del nivel nacional y local (radio, medios alternativos y cara- a-cara) para la sensibilización de las comunidades para la reducción de estigma y discriminación | F36: Desarrollo de campañas locales en medios alternativos desarrolladas en eventos comunitarios para la movilización social en torno a la prevención del VIH y la promoción de la solidaridad frente a los grupos clave | G36: Este costo incluye campañas locales en medios alternativos | M36: Entidad Ejecutora | N36: ONG/OBC/Sector Académico | O36: Material de comunicación | P36: Costo por campaña | S36: =+R36*Q36 -> 0 | T36: =+R36 -> 0 | U36: =S36 -> 0 | V36: Costo por campaña | W36: 5000000 | X36: =+R36 -> 0 | Y36: =+W36*X36 -> 0 | Z36: 1 | AA36: =+Z36*W36 -> 5000000 | AC36: =+AB36*W36 -> 0 | AD36: 1 | AE36: =+AD36*W36 -> 5000000 | AF36: =+X36+Z36+AB36+AD36 -> 2 | AG36: =+Y36+AA36+AC36+AE36 -> 10000000 | AH36: =+U36+AG36 -> 10000000
A37: 46 | B37: 1 | C37: Refuerzo de la sociedad civil | D37: 1.4 Implementar estrategias de movilización social para la reducción del estigma y la discriminación, la incidencia política y el agenciamiento social | E37: 1.4.4 Implementar acciones de fortalecimiento de la capacidad de ciudadana y agenciamiento social de los grupos clave, a través de educación en derechos, empoderamiento y apoyo social | F37: Desarrollo de encuentros quincenales en los servicios comunitarios tipo A para educar en derechos, participación y ciudadanía a los grupos clave. | G37: Este costo incluye un apoyo al encuentro para agua, café y apoyo alquiler salón de reunión | M37: Entidad Ejecutora | N37: ONG/OBC/Sector Académico | O37: Capacitación | P37: Costo por encuentro | S37: =+R37*Q37 -> 0 | T37: =+R37 -> 0 | U37: =S37 -> 0 | V37: Costo por encuentro | W37: 100000 | X37: 26 | Y37: =+W37*X37 -> 2600000 | Z37: 26 | AA37: =+Z37*W37 -> 2600000 | AB37: =+Z37 -> 26 | AC37: =+AB37*W37 -> 2600000 | AD37: 28 | AE37: =+AD37*W37 -> 2800000 | AF37: =+X37+Z37+AB37+AD37 -> 106 | AG37: =+Y37+AA37+AC37+AE37 -> 10600000 | AH37: =+U37+AG37 -> 10600000
A38: 12 | B38: 1 | C38: Refuerzo de la sociedad civil | D38: 1.1 Implementar estrategias de promoción de la demanda de asesoría y prueba voluntaria (APV) y de comunicación para el cambio de comportamiento (CCC) | E38: 1.1.5 Identificar y formar líderes pares de los grupos clave priorizados para que actúen como formadores e integren los equipos locales de promoción de la salud y prevención del VIH e ITS | F38: Costos administrativos, de operación y programaticos de la entidade ejecutora para el trabajo con servicios comunitarios para la identificación, selección, capacitación y seguimiento de lideres pares. Costos de prevención y promoción de APV, CCC, Uso de Condón, Reducción de Estigma y discriminación y seguimiento a tratamientos | G38: Costo Líderes pares de las Entidades Ejecutoras para los temas de prevención, diagnostico y tratamiento | M38: Entidad Ejecutora | N38: ONG/OBC/Sector Académico | O38: Monitoreo y evaluación | P38: Costo Incentivo Lideres Pares | Q38: =150000*3 -> 450000 | R38: 21 | S38: =+R38*Q38 -> 9450000 | T38: =+R38 -> 21 | U38: =S38 -> 9450000 | V38: =+P38 -> Costo Incentivo Lideres Pares | W38: =154500*3 -> 463500 | X38: 21 | Y38: =+W38*X38 -> 9733500 | Z38: =21+95 -> 116 | AA38: =+Z38*W38 -> 53766000 | AB38: =+Z38 -> 116 | AC38: =+AB38*W38 -> 53766000 | AD38: 116 | AE38: =+AD38*W38 -> 53766000 | AF38: =+X38+Z38+AB38+AD38 -> 369 | AG38: =+Y38+AA38+AC38+AE38 -> 171031500 | AH38: =+U38+AG38 -> 180481500
A39: TOTAL DESTINACION ESPECIFICA | AH39: =SUM(AH33:AH38) -> 279396135 | AI39: =+AH39 -> 279396135
A40: TOTAL PRESUPUESTO | AI40: =+AI30+AI39 -> 1168834838

Sheet Summary Bog
A1: PRESUPUESTO ENTIDADES EJECUTORAS
A2: BOGOTA
A4: Nombre Entidad Ejecutora:
A6: Detalle | B6: Presupuesto Total | C6: Tope Presupuestal
A7: Recurso Humano | B7: =+'Fase I Bog'!AH4 -> 0 | C7: =+'Fase I Bog'!AI4 -> 656174819
A8: Monitoreo y Evaluación | B8: =+'Fase I Bog'!AH11 -> 0 | C8: =+'Fase I Bog'!AI11 -> 196852446
A9: Planeación y Administración | B9: =+'Fase I Bog'!AH26 -> 0 | C9: =+'Fase I Bog'!AI26 -> 84365328
A10: Total Rubros de Funcionamiento | B10: =SUM(B7:B9) -> 0 | C10: =SUM(C7:C9) -> 937392593
A12: Destinación Específica | B12: =+'Fase I Bog'!AH37 -> 257295950 | C12: =+'Fase I Bog'!AI37 -> 257295950
A13: Total Destinación Específica | B13: =+B12 -> 257295950 | C13: =+C12 -> 257295950
A14: PRESUPUESTO TOTAL | B14: =+B10+B13 -> 257295950 | C14: =+C10+C13 -> 1194688543
A19: XXXXXX
A20: REPRESENTANTE LEGAL

Sheet Fase I Bog
A1: PRESUPUESTO DETALLADO
A2: No | B2: No de Objetivo: Crear capacidad comunitaria para la adopción de comportamientos seguros, la reducción de la vulnerabilidad social al VIH y el empoderamiento de los grupos clave priorizados | C2: Área de prestación de servicios (APS) | D2: Macro-Categoría | E2: Tarea | F2: Sub -Tarea | G2: Descripción / Hipotesis | H2: Año 1 | I2: Año 2 | M2: Responsable de la ejecución | N2: Tipo de entidad ejecutora | O2: Categorías de costos | P2: Unidad de medida año 1 | Q2: Costo unitario año 1 (valor trimestre) | R2: Cantidad Trimestre 4 | S2: Importe total Trimestre 4 | T2: Cantidad total Año 1 | U2: Total Año 1 | V2: Unidad de medida año 2 | W2: Costo unitario año 2 (valor trimestre) | X2: Cantidad Trimestre 1 año 2 | Y2: Importe total Trimestre 1 año 2 | Z2: Cantidad Trimestre 2 año 2 | AA2: Importe total Trimestre 2 año 2 | AB2: Cantidad Trimestre 3 año 2 | AC2: Importe total Trimestre 3 año 2 | AD2: Cantidad Trimestre 4 año 2 | AE2: Importe total Trimestre 4 año 2 | AF2: Cantidad total Año 2 | AG2: Total Año 2 | AH2: COSTO TOTAL | AI2: Tope Presupuestal
C3: SDA | D3: Activity | H3: T4 | I3: T1 | J3: T2 | K3: T3 | L3: T4
A4: RECURSO HUMANO | AH4: =SUM(AH5:AH10) -> 0 | AI4: 656174819
A5: 7 | B5: 1 | C5: Refuerzo de la sociedad civil | D5: 1.1 Implementar estrategias de promoción de la demanda de asesoría y prueba voluntaria (APV) y de comunicación para el cambio de comportamiento (CCC) | E5: 1.1.5 Identificar y formar líderes pares de los grupos clave priorizados para que actúen como formadores e integren los equipos locales de promoción de la salud y prevención del VIH e ITS | F5: Costo recurso humano administración de la entidad ejecutora | G5: Contador | M5: Entidad Ejecutora | N5: ONG/OBC/Sector Académico | O5: Recursos Humanos | P5: Salario / Honorario | S5: =+R5*Q5 -> 0 | T5: =+R5 -> 0 | U5: =S5 -> 0 | V5: Salario / Honorario | Y5: =+W5*X5 -> 0 | AA5: =+Z5*W5 -> 0 | AC5: =+AB5*W5 -> 0 | AE5: =+AD5*W5 -> 0 | AF5: =+X5+Z5+AB5+AD5 -> 0 | AG5: =+Y5+AA5+AC5+AE5 -> 0 | AH5: =+U5+AG5 -> 0
A6: 7 | B6: 1 | G6: Apoyo a la Dirección o Representación Legal | M6: Entidad Ejecutora | N6: ONG/OBC/Sector Académico | O6: Recursos Humanos | P6: Salario / Honorario | S6: =+R6*Q6 -> 0 | T6: =+R6 -> 0 | U6: =S6 -> 0 | V6: Salario / Honorario | Y6: =+W6*X6 -> 0 | AA6: =+Z6*W6 -> 0 | AC6: =+AB6*W6 -> 0 | AE6: =+AD6*W6 -> 0 | AF6: =+X6+Z6+AB6+AD6 -> 0 | AG6: =+Y6+AA6+AC6+AE6 -> 0 | AH6: =+U6+AG6 -> 0
A7: 7 | B7: 1 | G7: Asistente de Información | M7: Entidad Ejecutora | N7: ONG/OBC/Sector Académico | O7: Recursos Humanos | P7: Salario / Honorario | S7: =+R7*Q7 -> 0 | T7: =+R7 -> 0 | U7: =S7 -> 0 | V7: Salario / Honorario | Y7: =+W7*X7 -> 0 | AA7: =+Z7*W7 -> 0 | AC7: =+AB7*W7 -> 0 | AE7: =+AD7*W7 -> 0 | AF7: =+X7+Z7+AB7+AD7 -> 0 | AG7: =+Y7+AA7+AC7+AE7 -> 0 | AH7: =+U7+AG7 -> 0
A8: 11 | B8: 1 | C8: Refuerzo de la sociedad civil | F8: Costo recurso humano programatico de la entidad ejecutora | G8: Coordinador | M8: Entidad Ejecutora | N8: ONG/OBC/Sector Académico | O8: Recursos Humanos | P8: Salario / Honorario | S8: =+R8*Q8 -> 0 | T8: =+R8 -> 0 | U8: =S8 -> 0 | V8: Salario / Honorario | Y8: =+W8*X8 -> 0 | AA8: =+Z8*W8 -> 0 | AC8: =+AB8*W8 -> 0 | AE8: =+AD8*W8 -> 0 | AF8: =+X8+Z8+AB8+AD8 -> 0 | AG8: =+Y8+AA8+AC8+AE8 -> 0 | AH8: =+U8+AG8 -> 0
A9: 11 | B9: 1 | C9: Refuerzo de la sociedad civil | G9: Profesionales en Salud Sexual y Reproductiva (SSR) | M9: Entidad Ejecutora | N9: ONG/OBC/Sector Académico | O9: Recursos Humanos | P9: Salario / Honorario | S9: =+R9*Q9 -> 0 | T9: =+R9 -> 0 | U9: =S9 -> 0 | V9: Salario / Honorario | Y9: =+W9*X9 -> 0 | AA9: =+Z9*W9 -> 0 | AC9: =+AB9*W9 -> 0 | AE9: =+AD9*W9 -> 0 | AF9: =+X9+Z9+AB9+AD9 -> 0 | AG9: =+Y9+AA9+AC9+AE9 -> 0 | AH9: =+U9+AG9 -> 0
A10: 11 | B10: 1 | C10: Refuerzo de la sociedad civil | G10: Técnicos en Salud Sexual y Reproductiva (SSR) | M10: Entidad Ejecutora | N10: ONG/OBC/Sector Académico | O10: Recursos Humanos | P10: Salario / Honorario | S10: =+R10*Q10 -> 0 | T10: =+R10 -> 0 | U10: =S10 -> 0 | V10: Salario / Honorario | Y10: =+W10*X10 -> 0 | AA10: =+Z10*W10 -> 0 | AC10: =+AB10*W10 -> 0 | AE10: =+AD10*W10 -> 0 | AF10: =+X10+Z10+AB10+AD10 -> 0 | AG10: =+Y10+AA10+AC10+AE10 -> 0 | AH10: =+U10+AG10 -> 0
A11: MONITOREO Y EVALUACION | AH11: =SUM(AH12:AH25) -> 0 | AI11: 196852446
A12: 13 | B12: 1 | C12: Refuerzo de la sociedad civil | D12: 1.1 Implementar estrategias de promoción de la demanda de asesoría y prueba voluntaria (APV) y de comunicación para el cambio de comportamiento (CCC) | E12: 1.1.5 Identificar y formar líderes pares de los grupos clave priorizados para que actúen como formadores e integren los equipos locales de promoción de la salud y prevención del VIH e ITS | F12: Este costo incluye: 1. Viaticos y desplazamientos a los municipios de influencia asignados. 2. Actividades de gestion municipal y departamental para la sostenibilidad de las iniciativas. 3. Actividades en los servicios comunitarios para el encuentro con las comunidades, generación de confianza con las poblaciones priorizadas, actividades de escucha, reducción del estigma y la discriminaciòn, entre otras (Ejm: chocolatadas, teatro o cine al parque, actividades de trueque, acciones sanatorias de apoyo en situaciòn de alta vulnerabilidad para estabilizar a las poblaciones, entre otras) | G12: Viaticos por municipio | M12: Entidad Ejecutora | N12: ONG/OBC/Sector Académico | O12: Monitoreo y evaluación | P12: Viatico | R12: =+SUM(R13:R17) -> 0 | S12: =+SUM(S13:S17) -> 0 | T12: =+SUM(T13:T17) -> 0 | U12: =+SUM(U13:U17) -> 0 | V12: Viatico | X12: =+SUM(X13:X17) -> 0 | Y12: =+SUM(Y13:Y17) -> 0 | Z12: =+SUM(Z13:Z17) -> 0 | AA12: =+SUM(AA13:AA17) -> 0 | AB12: =+SUM(AB13:AB17) -> 0 | AC12: =+SUM(AC13:AC17) -> 0 | AD12: =+SUM(AD13:AD17) -> 0 | AE12: =+SUM(AE13:AE17) -> 0 | ... AG12: =+SUM(AG13:AG17) -> 0 | AH12: =+U12+AG12 -> 0
G13: Bosa | S13: =+R13*Q13 -> 0 | T13: =+R13 -> 0 | U13: =S13 -> 0 | W13: 1 | Y13: =+$W13*X13 -> 0 | AA13: =+$W13*Z13 -> 0 | AC13: =+$W13*AB13 -> 0 | AE13: =+$W13*AD13 -> 0 | AF13: =+X13+Z13+AB13+AD13 -> 0 | AG13: =+Y13+AA13+AC13+AE13 -> 0
G14: Suba | S14: =+R14*Q14 -> 0 | T14: =+R14 -> 0 | U14: =S14 -> 0 | W14: 1 | Y14: =+$W14*X14 -> 0 | AA14: =+$W14*Z14 -> 0 | AC14: =+$W14*AB14 -> 0 | AE14: =+$W14*AD14 -> 0 | AF14: =+X14+Z14+AB14+AD14 -> 0 | AG14: =+Y14+AA14+AC14+AE14 -> 0
G15: Tunjuelito | S15: =+R15*Q15 -> 0 | T15: =+R15 -> 0 | U15: =S15 -> 0 | W15: 1 | Y15: =+$W15*X15 -> 0 | AA15: =+$W15*Z15 -> 0 | AC15: =+$W15*AB15 -> 0 | AE15: =+$W15*AD15 -> 0 | AF15: =+X15+Z15+AB15+AD15 -> 0 | AG15: =+Y15+AA15+AC15+AE15 -> 0
G16: Fontibon | S16: =+R16*Q16 -> 0 | T16: =+R16 -> 0 | U16: =S16 -> 0 | W16: 1 | Y16: =+$W16*X16 -> 0 | AA16: =+$W16*Z16 -> 0 | AC16: =+$W16*AB16 -> 0 | AE16: =+$W16*AD16 -> 0 | AF16: =+X16+Z16+AB16+AD16 -> 0 | AG16: =+Y16+AA16+AC16+AE16 -> 0
G17: Kennedy
A18: 13 | B18: 1 | C18: Refuerzo de la sociedad civil | G18: Desplazamientos por municipio | M18: Entidad Ejecutora | N18: ONG/OBC/Sector Académico | O18: Monitoreo y evaluación | P18: Desplazamiento | R18: =+SUM(R19:R23) -> 0 | S18: =+SUM(S19:S23) -> 0 | T18: =+SUM(T19:T23) -> 0 | U18: =+SUM(U19:U23) -> 0 | V18: Desplazamiento | X18: =+SUM(X19:X23) -> 0 | Y18: =+SUM(Y19:Y23) -> 0 | Z18: =+SUM(Z19:Z23) -> 0 | AA18: =+SUM(AA19:AA23) -> 0 | AB18: =+SUM(AB19:AB23) -> 0 | AC18: =+SUM(AC19:AC23) -> 0 | AD18: =+SUM(AD19:AD23) -> 0 | AE18: =+SUM(AE19:AE23) -> 0 | ... AG18: =+SUM(AG19:AG23) -> 0 | AH18: =+U18+AG18 -> 0
G19: Bosa | S19: =+R19*Q19 -> 0 | T19: =+R19 -> 0 | U19: =S19 -> 0 | W19: 1 | Y19: =+$W19*X19 -> 0 | AA19: =+$W19*Z19 -> 0 | AC19: =+$W19*AB19 -> 0 | AE19: =+$W19*AD19 -> 0 | AF19: =+X19+Z19+AB19+AD19 -> 0 | AG19: =+Y19+AA19+AC19+AE19 -> 0
G20: Suba | S20: =+R20*Q20 -> 0 | T20: =+R20 -> 0 | U20: =S20 -> 0 | W20: 1 | Y20: =+$W20*X20 -> 0 | AA20: =+$W20*Z20 -> 0 | AC20: =+$W20*AB20 -> 0 | AE20: =+$W20*AD20 -> 0 | AF20: =+X20+Z20+AB20+AD20 -> 0 | AG20: =+Y20+AA20+AC20+AE20 -> 0
G21: Tunjuelito | S21: =+R21*Q21 -> 0 | T21: =+R21 -> 0 | U21: =S21 -> 0 | W21: 1 | Y21: =+$W21*X21 -> 0 | AA21: =+$W21*Z21 -> 0 | AC21: =+$W21*AB21 -> 0 | AE21: =+$W21*AD21 -> 0 | AF21: =+X21+Z21+AB21+AD21 -> 0 | AG21: =+Y21+AA21+AC21+AE21 -> 0
G22: Fontibon | S22: =+R22*Q22 -> 0 | T22: =+R22 -> 0 | U22: =S22 -> 0 | W22: 1 | Y22: =+$W22*X22 -> 0 | AA22: =+$W22*Z22 -> 0 | AC22: =+$W22*AB22 -> 0 | AE22: =+$W22*AD22 -> 0 | AF22: =+X22+Z22+AB22+AD22 -> 0 | AG22: =+Y22+AA22+AC22+AE22 -> 0
G23: Kennedy | S23: =+R23*Q23 -> 0 | T23: =+R23 -> 0 | U23: =S23 -> 0 | W23: 1 | Y23: =+$W23*X23 -> 0 | AA23: =+$W23*Z23 -> 0 | AC23: =+$W23*AB23 -> 0 | AE23: =+$W23*AD23 -> 0 | AF23: =+X23+Z23+AB23+AD23 -> 0 | AG23: =+Y23+AA23+AC23+AE23 -> 0
A24: 13 | B24: 1 | C24: Refuerzo de la sociedad civil | G24: Actividades de Gestión | M24: Entidad Ejecutora | N24: ONG/OBC/Sector Académico | O24: Monitoreo y evaluación | P24: Costo reunión | S24: =+R24*Q24 -> 0 | T24: =+R24 -> 0 | U24: =S24 -> 0 | V24: Costo reunión | Y24: =+W24*X24 -> 0 | AA24: =+Z24*W24 -> 0 | AC24: =+AB24*W24 -> 0 | AE24: =+AD24*W24 -> 0 | AF24: =+X24+Z24+AB24+AD24 -> 0 | AG24: =+Y24+AA24+AC24+AE24 -> 0 | AH24: =+U24+AG24 -> 0
A25: 13 | B25: 1 | C25: Refuerzo de la sociedad civil | G25: Actividades Servicios Comunitarios | M25: Entidad Ejecutora | N25: ONG/OBC/Sector Académico | O25: Monitoreo y evaluación | P25: Actividades | S25: =+R25*Q25 -> 0 | T25: =+R25 -> 0 | U25: =S25 -> 0 | V25: Actividades | Y25: =+W25*X25 -> 0 | AA25: =+Z25*W25 -> 0 | AC25: =+AB25*W25 -> 0 | AE25: =+AD25*W25 -> 0 | AF25: =+X25+Z25+AB25+AD25 -> 0 | AG25: =+Y25+AA25+AC25+AE25 -> 0 | AH25: =+U25+AG25 -> 0
A26: PLANIFICACION Y ADMINISTRACION | AH26: =SUM(AH27) -> 0 | AI26: 84365328
A27: 8 | B27: 1 | C27: Refuerzo de la sociedad civil | D27: 1.1 Implementar estrategias de promoción de la demanda de asesoría y prueba voluntaria (APV) y de comunicación para el cambio de comportamiento (CCC) | E27: 1.1.5 Identificar y formar líderes pares de los grupos clave priorizados para que actúen como formadores e integren los equipos locales de promoción de la salud y prevención del VIH e ITS | F27: Este costo incluye los Costos Administrativos (como, Arriendo, servicios públicos, Comunicaciones, impresiones, fotocopias, papelería, correos, gastos bancarios, seguros, mantenimiento y reparaciones, servicios generales, entre otros). | M27: Entidad Ejecutora | N27: ONG/OBC/Sector Académico | O27: Planificación y Administración | S27: =+R27*Q27 -> 0 | T27: =+R27 -> 0 | U27: =S27 -> 0 | Y27: =+W27*X27 -> 0 | AA27: =+Z27*W27 -> 0 | AC27: =+AB27*W27 -> 0 | AE27: =+AD27*W27 -> 0 | AF27: =+X27+Z27+AB27+AD27 -> 0 | AG27: =+Y27+AA27+AC27+AE27 -> 0 | AH27: =+U27+AG27 -> 0
A28: TOTAL RUBROS DE FUNCIONAMIENTO | AH28: =+AH4+AH11+AH26 -> 0 | AI28: =+AI4+AI11+AI26 -> 937392593
AH29: =SUM(AH7:AH27) -> 0
A30: DESTINACION ESPECIFICA
A31: 6 | B31: 1 | C31: CCC (Comunicación para Cambio de Comportamiento)- Medios de comunicación | D31: 1.1 Implementar estrategias de promoción de la demanda de asesoría y prueba voluntaria (APV) y de comunicación para el cambio de comportamiento (CCC) | E31: 1.1.4 Implementar acciones de CCC y de promoción de demanda de APV en medios alternativos y cara-a-cara (outreach) para transformar conductas sexuales de riesgo, promover el uso consistente y adecuado del condón y divulgar servicios y rutas de derechos a los grupos clave | F31: Este costo esta representado por brigadas de acercamiento a los grupos clave en sus entornos naturales | G31: Costo por brigada. El costo asignado por brigada es de $15,355. Incluye alimentación y transporte | M31: Entidad Ejecutora | N31: ONG/OBC/Sector Académico | O31: Capacitación | P31: costo por brigada | Q31: =15355 -> 15355 | R31: 658 | S31: =+R31*Q31 -> 10103590 | T31: =+R31 -> 658 | U31: =S31 -> 10103590 | V31: costo por brigada | W31: =+Q31 -> 15355 | X31: 658 | Y31: =+W31*X31 -> 10103590 | Z31: 658 | AA31: =+Z31*W31 -> 10103590 | AB31: =+Z31 -> 658 | AC31: =+AB31*W31 -> 10103590 | AD31: =+AB31 -> 658 | AE31: =+AD31*W31 -> 10103590 | AF31: =+X31+Z31+AB31+AD31 -> 2632 | AG31: =+Y31+AA31+AC31+AE31 -> 40414360 | AH31: =+U31+AG31 -> 50517950
A32: 34 | B32: 1 | C32: Refuerzo de las capacidades institucionales | D32: 1.3 Crear y fortalecer servicios comunitarios y/o redes comunitarias tipo A para la prevención del VIH/Sida /ITS, la promoción y referencia a APV, la educación en derechos y el empoderamiento de los grupos clave | E32: 1.3.5 Diseñar e implementar un plan de mejoramiento de capacidades locativas, de dotación y del recurso humano en los servicios comunitarios tipo A para la implementación efectiva de estrategias de CCC, promoción de la demanda de APV, educación en derechos, educación de pares | F32: Desarrollo de asistencia técnica a los servicios comunitarios tipo A asignados en temas identificados en la evaluación de necesidades | G32: Costo por servicio comunitario de 24 horas (valor hora $36.000) | M32: Entidad Ejecutora | N32: ONG/OBC/Sector Académico | O32: Asistencia técnica y gerencial | P32: Costo por hora asistencia tecnica | S32: =+R32*Q32 -> 0 | T32: =+R32 -> 0 | U32: =S32 -> 0 | V32: Costo por hora asistencia tecnica | W32: =36000*24 -> 864000 | X32: 7 | Y32: =+W32*X32 -> 6048000 | Z32: =+X32 -> 7 | AA32: =+Z32*W32 -> 6048000 | AC32: =+AB32*W32 -> 0 | AD32: =+AB32 -> 0 | AE32: =+AD32*W32 -> 0 | AF32: =+X32+Z32+AB32+AD32 -> 14 | AG32: =+Y32+AA32+AC32+AE32 -> 12096000 | AH32: =+U32+AG32 -> 12096000
A33: 35 | B33: 1 | C33: Refuerzo de las capacidades institucionales | D33: 1.3 Crear y fortalecer servicios comunitarios y/o redes comunitarias tipo A para la prevención del VIH/Sida /ITS, la promoción y referencia a APV, la educación en derechos y el empoderamiento de los grupos clave | E33: 1.3.5 Diseñar e implementar un plan de mejoramiento de capacidades locativas, de dotación y del recurso humano en los servicios comunitarios tipo A para la implementación efectiva de estrategias de CCC, promoción de la demanda de APV, educación en derechos, educación de pares | F33: Desarrollo de asistencia técnica a los servicios comunitarios tipo A asignados en temas identificados en la evaluación de necesidades | G33: Costo por servicio comunitario de 12 horas (valor hora $36.000) | M33: Entidad Ejecutora | N33: ONG/OBC/Sector Académico | O33: Asistencia técnica y gerencial | P33: Costo por hora asistencia tecnica | S33: =+R33*Q33 -> 0 | T33: =+R33 -> 0 | U33: =S33 -> 0 | V33: Costo por hora asistencia tecnica | W33: =36000*12 -> 432000 | Y33: =+W33*X33 -> 0 | Z33: =+X33 -> 0 | AA33: =+Z33*W33 -> 0 | AB33: 14 | AC33: =+AB33*W33 -> 6048000 | AD33: =+AB33 -> 14 | AE33: =+AD33*W33 -> 6048000 | AF33: =+X33+Z33+AB33+AD33 -> 28 | AG33: =+Y33+AA33+AC33+AE33 -> 12096000 | AH33: =+U33+AG33 -> 12096000
A34: 43 | B34: 1 | C34: Reducción del estigma en todas las circunstancias | D34: 1.4 Implementar estrategias de movilización social para la reducción del estigma y la discriminación, la incidencia política y el agenciamiento social | E34: 1.4.3 Implementar estrategias de comunicación y movilización social del nivel nacional y local (radio, medios alternativos y cara- a-cara) para la sensibilización de las comunidades para la reducción de estigma y discriminación | F34: Desarrollo de campañas locales en medios alternativos desarrolladas en eventos comunitarios para la movilización social en torno a la prevención del VIH y la promoción de la solidaridad frente a los grupos clave | G34: Este costo incluye campañas locales en medios alternativos | M34: Entidad Ejecutora | N34: ONG/OBC/Sector Académico | O34: Material de comunicación | P34: Costo por campaña | S34: =+R34*Q34 -> 0 | T34: =+R34 -> 0 | U34: =S34 -> 0 | V34: Costo por campaña | W34: 5000000 | X34: =+R34 -> 0 | Y34: =+W34*X34 -> 0 | Z34: 1 | AA34: =+Z34*W34 -> 5000000 | AC34: =+AB34*W34 -> 0 | AE34: =+AD34*W34 -> 0 | AF34: =+X34+Z34+AB34+AD34 -> 1 | AG34: =+Y34+AA34+AC34+AE34 -> 5000000 | AH34: =+U34+AG34 -> 5000000
A35: 46 | B35: 1 | C35: Refuerzo de la sociedad civil | D35: 1.4 Implementar estrategias de movilización social para la reducción del estigma y la discriminación, la incidencia política y el agenciamiento social | E35: 1.4.4 Implementar acciones de fortalecimiento de la capacidad de ciudadana y agenciamiento social de los grupos clave, a través de educación en derechos, empoderamiento y apoyo social | F35: Desarrollo de encuentros quincenales en los servicios comunitarios tipo A para educar en derechos, participación y ciudadanía a los grupos clave. | G35: Este costo incluye un apoyo al encuentro para agua, café y apoyo alquiler salón de reunión | M35: Entidad Ejecutora | N35: ONG/OBC/Sector Académico | O35: Capacitación | P35: Costo por encuentro | S35: =+R35*Q35 -> 0 | T35: =+R35 -> 0 | U35: =S35 -> 0 | V35: Costo por encuentro | W35: 100000 | X35: 31 | Y35: =+W35*X35 -> 3100000 | Z35: =+X35 -> 31 | AA35: =+Z35*W35 -> 3100000 | AB35: =+Z35 -> 31 | AC35: =+AB35*W35 -> 3100000 | AD35: =+AB35 -> 31 | AE35: =+AD35*W35 -> 3100000 | AF35: =+X35+Z35+AB35+AD35 -> 124 | AG35: =+Y35+AA35+AC35+AE35 -> 12400000 | AH35: =+U35+AG35 -> 12400000
A36: 12 | B36: 1 | C36: Refuerzo de la sociedad civil | D36: 1.1 Implementar estrategias de promoción de la demanda de asesoría y prueba voluntaria (APV) y de comunicación para el cambio de comportamiento (CCC) | E36: 1.1.5 Identificar y formar líderes pares de los grupos clave priorizados para que actúen como formadores e integren los equipos locales de promoción de la salud y prevención del VIH e ITS | F36: Costos administrativos, de operación y programaticos de la entidade ejecutora para el trabajo con servicios comunitarios para la identificación, selección, capacitación y seguimiento de lideres pares. Costos de prevención y promoción de APV, CCC, Uso de Condón, Reducción de Estigma y discriminación y seguimiento a tratamientos | G36: Costo Líderes pares de las Entidades Ejecutoras para los temas de prevención, diagnostico y tratamiento | M36: Entidad Ejecutora | N36: ONG/OBC/Sector Académico | O36: Monitoreo y evaluación | P36: Costo Incentivo Lideres Pares | Q36: =150000*3 -> 450000 | R36: 21 | S36: =+R36*Q36 -> 9450000 | T36: =+R36 -> 21 | U36: =S36 -> 9450000 | V36: =+P36 -> Costo Incentivo Lideres Pares | W36: =154500*3 -> 463500 | X36: 21 | Y36: =+W36*X36 -> 9733500 | Z36: 105 | AA36: =+Z36*W36 -> 48667500 | AB36: =+Z36 -> 105 | AC36: =+AB36*W36 -> 48667500 | AD36: =+AB36 -> 105 | AE36: =+AD36*W36 -> 48667500 | AF36: =+X36+Z36+AB36+AD36 -> 336 | AG36: =+Y36+AA36+AC36+AE36 -> 155736000 | AH36: =+U36+AG36 -> 165186000
A37: TOTAL DESTINACION ESPECIFICA | AH37: =SUM(AH31:AH36) -> 257295950 | AI37: =+AH37 -> 257295950
A38: TOTAL PRESUPUESTO | AI38: =+AI28+AI37 -> 1194688543

Sheet Summary Valle del Cauca
A1: PRESUPUESTO ENTIDADES EJECUTORAS
A2: VALLE DEL CAUCA
A4: Nombre Entidad Ejecutora:
A6: Detalle | B6: Presupuesto Total | C6: Tope Presupuestal
A7: Recurso Humano | B7: =+'Fase I Valle del Cauca'!AH4 -> 0 | C7: =+'Fase I Valle del Cauca'!AI4 -> 475608787
A8: Monitoreo y Evaluación | B8: =+'Fase I Valle del Cauca'!AH11 -> 0 | C8: =+'Fase I Valle del Cauca'!AI11 -> 142682633
A9: Planeación y Administración | B9: =+'Fase I Valle del Cauca'!AH26 -> 0 | C9: =+'Fase I Valle del Cauca'!AI26 -> 61149698
A10: Total Rubros de Funcionamiento | B10: =SUM(B7:B9) -> 0 | C10: =SUM(C7:C9) -> 679441118
A12: Destinación Específica | B12: =+'Fase I Valle del Cauca'!AH37 -> 198704435 | C12: =+'Fase I Valle del Cauca'!AI37 -> 198704435
A13: Total Destinación Específica | B13: =+B12 -> 198704435 | C13: =+C12 -> 198704435
A14: PRESUPUESTO TOTAL | B14: =+B10+B13 -> 198704435 | C14: =+C10+C13 -> 878145553
A19: XXXXXX
A20: REPRESENTANTE LEGAL

Sheet Fase I Valle del Cauca
A1: PRESUPUESTO DETALLADO
A2: No | B2: No de Objetivo: Crear capacidad comunitaria para la adopción de comportamientos seguros, la reducción de la vulnerabilidad social al VIH y el empoderamiento de los grupos clave priorizados | C2: Área de prestación de servicios (APS) | D2: Macro-Categoría | E2: Tarea | F2: Sub -Tarea | G2: Descripción / Hipotesis | H2: Año 1 | I2: Año 2 | M2: Responsable de la ejecución | N2: Tipo de entidad ejecutora | O2: Categorías de costos | P2: Unidad de medida año 1 | Q2: Costo unitario año 1 (valor trimestre) | R2: Cantidad Trimestre 4 | S2: Importe total Trimestre 4 | T2: Cantidad total Año 1 | U2: Total Año 1 | V2: Unidad de medida año 2 | W2: Costo unitario año 2 (valor trimestre) | X2: Cantidad Trimestre 1 año 2 | Y2: Importe total Trimestre 1 año 2 | Z2: Cantidad Trimestre 2 año 2 | AA2: Importe total Trimestre 2 año 2 | AB2: Cantidad Trimestre 3 año 2 | AC2: Importe total Trimestre 3 año 2 | AD2: Cantidad Trimestre 4 año 2 | AE2: Importe total Trimestre 4 año 2 | AF2: Cantidad total Año 2 | AG2: Total Año 2 | AH2: COSTO TOTAL | AI2: Tope Presupuestal
C3: SDA | D3: Activity | H3: T4 | I3: T1 | J3: T2 | K3: T3 | L3: T4
A4: RECURSO HUMANO | AH4: =SUM(AH5:AH10) -> 0 | AI4: 475608787
A5: 7 | B5: 1 | C5: Refuerzo de la sociedad civil | D5: 1.1 Implementar estrategias de promoción de la demanda de asesoría y prueba voluntaria (APV) y de comunicación para el cambio de comportamiento (CCC) | E5: 1.1.5 Identificar y formar líderes pares de los grupos clave priorizados para que actúen como formadores e integren los equipos locales de promoción de la salud y prevención del VIH e ITS | F5: Costo recurso humano administración de la entidad ejecutora | G5: Contador | M5: Entidad Ejecutora | N5: ONG/OBC/Sector Académico | O5: Recursos Humanos | P5: Salario / Honorario | S5: =+R5*Q5 -> 0 | T5: =+R5 -> 0 | U5: =S5 -> 0 | V5: Salario / Honorario | Y5: =+W5*X5 -> 0 | AA5: =+Z5*W5 -> 0 | AC5: =+AB5*W5 -> 0 | AE5: =+AD5*W5 -> 0 | AF5: =+X5+Z5+AB5+AD5 -> 0 | AG5: =+Y5+AA5+AC5+AE5 -> 0 | AH5: =+U5+AG5 -> 0
A6: 7 | B6: 1 | G6: Apoyo a la Dirección o Representación Legal | M6: Entidad Ejecutora | N6: ONG/OBC/Sector Académico | O6: Recursos Humanos | P6: Salario / Honorario | S6: =+R6*Q6 -> 0 | T6: =+R6 -> 0 | U6: =S6 -> 0 | V6: Salario / Honorario | Y6: =+W6*X6 -> 0 | AA6: =+Z6*W6 -> 0 | AC6: =+AB6*W6 -> 0 | AE6: =+AD6*W6 -> 0 | AF6: =+X6+Z6+AB6+AD6 -> 0 | AG6: =+Y6+AA6+AC6+AE6 -> 0 | AH6: =+U6+AG6 -> 0
A7: 7 | B7: 1 | G7: Asistente de Información | M7: Entidad Ejecutora | N7: ONG/OBC/Sector Académico | O7: Recursos Humanos | P7: Salario / Honorario | S7: =+R7*Q7 -> 0 | T7: =+R7 -> 0 | U7: =S7 -> 0 | V7: Salario / Honorario | Y7: =+W7*X7 -> 0 | AA7: =+Z7*W7 -> 0 | AC7: =+AB7*W7 -> 0 | AE7: =+AD7*W7 -> 0 | AF7: =+X7+Z7+AB7+AD7 -> 0 | AG7: =+Y7+AA7+AC7+AE7 -> 0 | AH7: =+U7+AG7 -> 0
A8: 11 | B8: 1 | C8: Refuerzo de la sociedad civil | F8: Costo recurso humano programatico de la entidad ejecutora | G8: Coordinador | M8: Entidad Ejecutora | N8: ONG/OBC/Sector Académico | O8: Recursos Humanos | P8: Salario / Honorario | S8: =+R8*Q8 -> 0 | T8: =+R8 -> 0 | U8: =S8 -> 0 | V8: Salario / Honorario | Y8: =+W8*X8 -> 0 | AA8: =+Z8*W8 -> 0 | AC8: =+AB8*W8 -> 0 | AE8: =+AD8*W8 -> 0 | AF8: =+X8+Z8+AB8+AD8 -> 0 | AG8: =+Y8+AA8+AC8+AE8 -> 0 | AH8: =+U8+AG8 -> 0
A9: 11 | B9: 1 | C9: Refuerzo de la sociedad civil | G9: Profesionales en Salud Sexual y Reproductiva (SSR) | M9: Entidad Ejecutora | N9: ONG/OBC/Sector Académico | O9: Recursos Humanos | P9: Salario / Honorario | S9: =+R9*Q9 -> 0 | T9: =+R9 -> 0 | U9: =S9 -> 0 | V9: Salario / Honorario | Y9: =+W9*X9 -> 0 | AA9: =+Z9*W9 -> 0 | AC9: =+AB9*W9 -> 0 | AE9: =+AD9*W9 -> 0 | AF9: =+X9+Z9+AB9+AD9 -> 0 | AG9: =+Y9+AA9+AC9+AE9 -> 0 | AH9: =+U9+AG9 -> 0
A10: 11 | B10: 1 | C10: Refuerzo de la sociedad civil | G10: Técnicos en Salud Sexual y Reproductiva (SSR) | M10: Entidad Ejecutora | N10: ONG/OBC/Sector Académico | O10: Recursos Humanos | P10: Salario / Honorario | S10: =+R10*Q10 -> 0 | T10: =+R10 -> 0 | U10: =S10 -> 0 | V10: Salario / Honorario | Y10: =+W10*X10 -> 0 | AA10: =+Z10*W10 -> 0 | AC10: =+AB10*W10 -> 0 | AE10: =+AD10*W10 -> 0 | AF10: =+X10+Z10+AB10+AD10 -> 0 | AG10: =+Y10+AA10+AC10+AE10 -> 0 | AH10: =+U10+AG10 -> 0
A11: MONITOREO Y EVALUACION | AH11: =SUM(AH12:AH25) -> 0 | AI11: 142682633
A12: 13 | B12: 1 | C12: Refuerzo de la sociedad civil | D12: 1.1 Implementar estrategias de promoción de la demanda de asesoría y prueba voluntaria (APV) y de comunicación para el cambio de comportamiento (CCC) | E12: 1.1.5 Identificar y formar líderes pares de los grupos clave priorizados para que actúen como formadores e integren los equipos locales de promoción de la salud y prevención del VIH e ITS | F12: Este costo incluye: 1. Viaticos y desplazamientos a los municipios de influencia asignados. 2. Actividades de gestion municipal y departamental para la sostenibilidad de las iniciativas. 3. Actividades en los servicios comunitarios para el encuentro con las comunidades, generación de confianza con las poblaciones priorizadas, actividades de escucha, reducción del estigma y la discriminaciòn, entre otras (Ejm: chocolatadas, teatro o cine al parque, actividades de trueque, acciones sanatorias de apoyo en situaciòn de alta vulnerabilidad para estabilizar a las poblaciones, entre otras) | G12: Viaticos por municipio | M12: Entidad Ejecutora | N12: ONG/OBC/Sector Académico | O12: Monitoreo y evaluación | P12: Viatico | S12: =+SUM(S13:S17) -> 0 | T12: =+SUM(T13:T17) -> 0 | U12: =+SUM(U13:U17) -> 0 | V12: Viatico | X12: =+SUM(X13:X17) -> 0 | Y12: =+SUM(Y13:Y17) -> 0 | Z12: =+SUM(Z13:Z17) -> 0 | AA12: =+SUM(AA13:AA17) -> 0 | AB12: =+SUM(AB13:AB17) -> 0 | AC12: =+SUM(AC13:AC17) -> 0 | AD12: =+SUM(AD13:AD17) -> 0 | AE12: =+SUM(AE13:AE17) -> 0 | ... AG12: =+SUM(AG13:AG17) -> 0 | AH12: =+U12+AG12 -> 0
G13: Cali | S13: =+Q13*R13 -> 0 | T13: =+R13 -> 0 | U13: =S13 -> 0 | Y13: =+W13*X13 -> 0 | AA13: =+$W13*Z13 -> 0 | AC13: =+$W13*AB13 -> 0 | AE13: =+$W13*AD13 -> 0 | AG13: =+Y13+AA13+AC13+AE13 -> 0
G14: Palmira | S14: =+Q14*R14 -> 0 | T14: =+R14 -> 0 | U14: =S14 -> 0 | Y14: =+W14*X14 -> 0 | AA14: =+$W14*Z14 -> 0 | AC14: =+$W14*AB14 -> 0 | AE14: =+$W14*AD14 -> 0 | AG14: =+Y14+AA14+AC14+AE14 -> 0
G15: Tulua | S15: =+Q15*R15 -> 0 | T15: =+R15 -> 0 | U15: =S15 -> 0 | Y15: =+W15*X15 -> 0 | AA15: =+$W15*Z15 -> 0 | AC15: =+$W15*AB15 -> 0 | AE15: =+$W15*AD15 -> 0 | AG15: =+Y15+AA15+AC15+AE15 -> 0
G16: Buga | S16: =+Q16*R16 -> 0 | T16: =+R16 -> 0 | U16: =S16 -> 0 | Y16: =+W16*X16 -> 0 | AA16: =+$W16*Z16 -> 0 | AC16: =+$W16*AB16 -> 0 | AE16: =+$W16*AD16 -> 0 | AG16: =+Y16+AA16+AC16+AE16 -> 0
G17: Buenaventura | S17: =+Q17*R17 -> 0 | T17: =+R17 -> 0 | U17: =S17 -> 0 | Y17: =+W17*X17 -> 0 | AA17: =+$W17*Z17 -> 0 | AC17: =+$W17*AB17 -> 0 | AE17: =+$W17*AD17 -> 0 | AG17: =+Y17+AA17+AC17+AE17 -> 0
A18: 13 | B18: 1 | C18: Refuerzo de la sociedad civil | G18: Desplazamientos por municipio | M18: Entidad Ejecutora | N18: ONG/OBC/Sector Académico | O18: Monitoreo y evaluación | P18: Desplazamiento | S18: =+SUM(S19:S23) -> 0 | T18: =+SUM(T19:T23) -> 0 | U18: =+SUM(U19:U23) -> 0 | V18: Desplazamiento | X18: =+SUM(X19:X23) -> 0 | Y18: =+SUM(Y19:Y23) -> 0 | Z18: =+SUM(Z19:Z23) -> 0 | AA18: =+SUM(AA19:AA23) -> 0 | AB18: =+SUM(AB19:AB23) -> 0 | AC18: =+SUM(AC19:AC23) -> 0 | AD18: =+SUM(AD19:AD23) -> 0 | AE18: =+SUM(AE19:AE23) -> 0 | ... AG18: =+SUM(AG19:AG23) -> 0 | AH18: =+U18+AG18 -> 0
G19: Cali | S19: =+Q19*R19 -> 0 | T19: =+R19 -> 0 | U19: =S19 -> 0 | Y19: =+W19*X19 -> 0 | AA19: =+$W19*Z19 -> 0 | AC19: =+$W19*AB19 -> 0 | AE19: =+$W19*AD19 -> 0 | AG19: =+Y19+AA19+AC19+AE19 -> 0
G20: Palmira | S20: =+Q20*R20 -> 0 | T20: =+R20 -> 0 | U20: =S20 -> 0 | Y20: =+W20*X20 -> 0 | AA20: =+$W20*Z20 -> 0 | AC20: =+$W20*AB20 -> 0 | AE20: =+$W20*AD20 -> 0 | AG20: =+Y20+AA20+AC20+AE20 -> 0
G21: Tulua | S21: =+Q21*R21 -> 0 | T21: =+R21 -> 0 | U21: =S21 -> 0 | Y21: =+W21*X21 -> 0 | AA21: =+$W21*Z21 -> 0 | AC21: =+$W21*AB21 -> 0 | AE21: =+$W21*AD21 -> 0 | AG21: =+Y21+AA21+AC21+AE21 -> 0
G22: Buga | S22: =+Q22*R22 -> 0 | T22: =+R22 -> 0 | U22: =S22 -> 0 | Y22: =+W22*X22 -> 0 | AA22: =+$W22*Z22 -> 0 | AC22: =+$W22*AB22 -> 0 | AE22: =+$W22*AD22 -> 0 | AG22: =+Y22+AA22+AC22+AE22 -> 0
G23: Buenaventura | S23: =+Q23*R23 -> 0 | T23: =+R23 -> 0 | U23: =S23 -> 0 | Y23: =+W23*X23 -> 0 | AA23: =+$W23*Z23 -> 0 | AC23: =+$W23*AB23 -> 0 | AE23: =+$W23*AD23 -> 0 | AG23: =+Y23+AA23+AC23+AE23 -> 0
A24: 13 | B24: 1 | C24: Refuerzo de la sociedad civil | G24: Actividades de Gestión | M24: Entidad Ejecutora | N24: ONG/OBC/Sector Académico | O24: Monitoreo y evaluación | P24: Costo reunión | S24: =+R24*Q24 -> 0 | T24: =+R24 -> 0 | U24: =S24 -> 0 | V24: Costo reunión | Y24: =+W24*X24 -> 0 | AA24: =+Z24*W24 -> 0 | AC24: =+AB24*W24 -> 0 | AE24: =+AD24*W24 -> 0 | AF24: =+X24+Z24+AB24+AD24 -> 0 | AG24: =+Y24+AA24+AC24+AE24 -> 0 | AH24: =+U24+AG24 -> 0
A25: 13 | B25: 1 | C25: Refuerzo de la sociedad civil | G25: Actividades Servicios Comunitarios | M25: Entidad Ejecutora | N25: ONG/OBC/Sector Académico | O25: Monitoreo y evaluación | P25: Actividades | S25: =+R25*Q25 -> 0 | T25: =+R25 -> 0 | U25: =S25 -> 0 | V25: Actividades | Y25: =+W25*X25 -> 0 | AA25: =+Z25*W25 -> 0 | AC25: =+AB25*W25 -> 0 | AE25: =+AD25*W25 -> 0 | AF25: =+X25+Z25+AB25+AD25 -> 0 | AG25: =+Y25+AA25+AC25+AE25 -> 0 | AH25: =+U25+AG25 -> 0
A26: PLANIFICACION Y ADMINISTRACION | AH26: =SUM(AH27) -> 0 | AI26: 61149698
A27: 8 | B27: 1 | C27: Refuerzo de la sociedad civil | D27: 1.1 Implementar estrategias de promoción de la demanda de asesoría y prueba voluntaria (APV) y de comunicación para el cambio de comportamiento (CCC) | E27: 1.1.5 Identificar y formar líderes pares de los grupos clave priorizados para que actúen como formadores e integren los equipos locales de promoción de la salud y prevención del VIH e ITS | F27: Este costo incluye los Costos Administrativos (como, Arriendo, servicios públicos, Comunicaciones, impresiones, fotocopias, papelería, correos, gastos bancarios, seguros, mantenimiento y reparaciones, servicios generales, entre otros). | M27: Entidad Ejecutora | N27: ONG/OBC/Sector Académico | O27: Planificación y Administración | S27: =+R27*Q27 -> 0 | T27: =+R27 -> 0 | U27: =S27 -> 0 | Y27: =+W27*X27 -> 0 | AA27: =+Z27*W27 -> 0 | AC27: =+AB27*W27 -> 0 | AE27: =+AD27*W27 -> 0 | AF27: =+X27+Z27+AB27+AD27 -> 0 | AG27: =+Y27+AA27+AC27+AE27 -> 0 | AH27: =+U27+AG27 -> 0
A28: TOTAL RUBROS DE FUNCIONAMIENTO | AH28: =+AH4+AH11+AH26 -> 0 | AI28: =+AI4+AI11+AI26 -> 679441118
AH29: =SUM(AH7:AH27) -> 0
A30: DESTINACION ESPECIFICA
A31: 6 | B31: 1 | C31: CCC (Comunicación para Cambio de Comportamiento)- Medios de comunicación | D31: 1.1 Implementar estrategias de promoción de la demanda de asesoría y prueba voluntaria (APV) y de comunicación para el cambio de comportamiento (CCC) | E31: 1.1.4 Implementar acciones de CCC y de promoción de demanda de APV en medios alternativos y cara-a-cara (outreach) para transformar conductas sexuales de riesgo, promover el uso consistente y adecuado del condón y divulgar servicios y rutas de derechos a los grupos clave | F31: Este costo esta representado por brigadas de acercamiento a los grupos clave en sus entornos naturales | G31: Costo por brigada. El costo asignado por brigada es de $15,355. Incluye alimentación y transporte | M31: Entidad Ejecutora | N31: ONG/OBC/Sector Académico | O31: Capacitación | P31: costo por brigada | Q31: =15355 -> 15355 | R31: 419 | S31: =+R31*Q31 -> 6433745 | T31: =+R31 -> 419 | U31: =S31 -> 6433745 | V31: costo por brigada | W31: =+Q31 -> 15355 | X31: 419 | Y31: =+W31*X31 -> 6433745 | Z31: 419 | AA31: =+Z31*W31 -> 6433745 | AB31: =+Z31 -> 419 | AC31: =+AB31*W31 -> 6433745 | AD31: 421 | AE31: =+AD31*W31 -> 6464455 | AF31: =+X31+Z31+AB31+AD31 -> 1678 | AG31: =+Y31+AA31+AC31+AE31 -> 25765690 | AH31: =+U31+AG31 -> 32199435
