Workbook

Sheet 1
A1: شرکت ساختماني گسترش و نوسازی صنایع ایرانیان مانا ( سهامی خاص )
A2: يادداشتهاي توضيحي صورتهاي مالي
A3: دوره مالي ششماهه منتهي به 31 خرداد ماه 1390
A5: مجمع عمومي صاحبان سهام
A7: بااحترام ؛
A9: به پيوست صورتهاي مالي شركت ساختماني گسترش ونوسازي صنايع ايران (سهامي خاص) براي ششماهه منتهي به 31 خردادماه 1390 تقديم مي شود
A10: اجزاي تشكيل دهنده صورتهاي مالي به قرارزيراست:
I12: شماره صفحه
A13: ● ترازنامه | I13: 2
A14: ● صورت سودوزيان | I14: 3
A15: ● گردش حساب سود ( زیان ) انباشته | I15: 3
A16: ● صورت جريان وجوه نقد | I16: 4
A17: ● يادداشتهاي توضيحي:
A18: الف)تاريخچه فعاليت شركت | I18: 5
A19: ب)مبناي تهيه صورتهاي مالي | I19: 5
A20: پ)خلاصه اهم رويه هاي حسابداري | I20: 6
A21: ت)يادداشتهاي مربوط به اقلام مندرج درصورتهاي مالي وسايراطلاعات مالي | I21: 10 - 42
A23: صورتهاي مالي براساس استانداردهاي حسابداري تهيه شده و در تاریخ 1390/05/16 به تائيد هيأت مديره شركت رسيده است .
A25: اعضاي هيئت مديره | D25: سمت | I25: امضاء
A27: علی اصغر پورمند | D27: رئيس هيأت مديره
A29: محمد بخارائی | D29: نایب رئيس هيأت مديره
A31: بیژن سرانجام | D31: مديرعامل
A33: سید کاظم میر ولد | D33: عضو هيأت مديره
A35: محمد سوری | D35: عضو هيأت مديره

Sheet 2
A1: شرکت ساختماني گسترش و نوسازی صنایع ایرانیان مانا ( سهامی خاص )
A2: ترازنامه
A3: درتاریخ 31خرداد 1390
A5: دارائي ها | E5: يادداشت | G5: 1390/03/31 | I5: 1389/09/30 | K5: بدهي هاوحقوق صاحبان سهام | N5: يادداشت | P5: 1390/03/31 | R5: 1389/09/30
G6: ریال | I6: ریال | P6: ریال | R6: ریال
A7: دارئيهای جاری: | K7: بدهيهای جاری :
A8: موجودی نقد | E8: 4 | G8: ='10'!G14 -> 14801539168 | I8: ='10'!I14 -> 7619973112 | L8: حسابهاواسنادپرداختنی تجاری | N8: 13 | P8: ='27'!E13 -> 120699521837 | R8: ='27'!G13 -> 120163410629
A9: حسابهای دريافتنی تجاری | E9: 5 | G9: ='12'!E39 -> 418530015666 | I9: ='12'!G39 -> 358525348462 | L9: سايرحسابهای پرداختنی | N9: 14 | P9: ='29'!F16 -> 151584243124 | R9: ='29'!H16 -> 88974015878
A10: سايرحسابهای دريافتنی | E10: 6 | G10: ='16'!I15 -> 230016308069 | I10: ='16'!K15 -> 138392761768 | L10: شرکتهای گروه | N10: 15 | P10: ='31'!F54 -> 8309143420 | R10: ='31'!H54 -> 10581628534
A11: شرکتهای گروه | E11: 7 | G11: ='18'!F24 -> 27025794602 | I11: ='18'!H24 -> 17307030086 | L11: پيش دريافتها | N11: 16 | P11: ='32'!E11 -> 157855244864 | R11: ='32'!G33 -> 136829044699
A12: موجودی مواد وکالاوپيمان درجريان پيشرفت | E12: 8 | G12: ='19'!E19 -> 13331416599 | I12: ='18'!H34 -> 50994429649 | L12: ذخیره مالیات | N12: 17 | P12: 0 | R12: 0
A13: سفارشات و پیش پرداختها | E13: 9 | G13: ='19'!E29 -> 70121623081 | I13: ='19'!K29 -> 32271397072 | L13: سود سهام پرداختنی | N13: 18 | P13: ='34'!E10 -> 143533971992 | R13: ='34'!G10 -> 65904623492
G14: 0 | I14: 0 | L14: تسهیلات مالی دریافتی کوتاه مدت | N14: 19 | P14: 67311564466 | R14: 36249634412
G15: =SUM(G8:G14) -> 773826697185 | I15: =SUM(I8:I14) -> 605110940149 | P15: =SUM(P8:P14) -> 649293689703 | R15: =SUM(R8:R14) -> 458702357644
A16: دارائيهای غيرجاری : | K16: بدهيهای بلند مدت :
L17: تسهیلات مالی دریافتی بلند مدت | N17: 19 | P17: 0 | R17: 19751134412
A18: داراييهای ثابت مشهود | E18: 10 | G18: ='20'!Z22 -> 30930448145 | I18: ='20'!AB22 -> 28548260406 | K18: ذخيره مزايای پايان خدمت کارکنان | N18: 20 | P18: ='34'!E29 -> 10363884882 | R18: ='34'!G29 -> 8355739578
A19: سرمايه گذاريهای بلندمدت | E19: 11 | G19: ='25'!G11 -> 6485500000 | I19: ='25'!I11 -> 4161000000 | P19: =SUM(P17:P18) -> 10363884882 | R19: =SUM(R17:R18) -> 28106873990
A20: داراييهای نامشهود | E20: 12 | G20: ='26'!F13 -> 610092852 | I20: ='26'!H13 -> 556767852
G21: =SUM(G18:G20) -> 38026040997 | I21: =SUM(I18:I20) -> 33266028258 | K21: جمع بدهیها | P21: =P15+P19 -> 659657574585 | R21: =R19+R15 -> 486809231634
K22: حقوق صاحبان سهام :
K23: سرمايه (63000000سهم1000ريالی با نام تمام پرداخت شده) | N23: 21 | P23: 63000000000 | R23: ='35'!I17 -> 63000000000
K24: اندوخته قانونی | N24: 22 | P24: 6300000000 | R24: ='35'!B34 -> 6300000000
K25: سايراندوخته ها | N25: 23 | P25: 176336710 | R25: ='35'!F34+'35'!D34 -> 176336710
K26: سود انباشته | P26: ='3'!E36 -> 82718826887 | R26: ='3'!I36 -> 82091400063
P27: =SUM(P23:P26) -> 152195163597 | R27: =SUM(R23:R26) -> 151567736773
A29: جمع دارائيها | G29: =G15+G21 -> 811852738182 | I29: =I21+I15 -> 638376968407 | K29: جمع بدهی هاوحقوق صاحبان سهام | P29: =P27+P21 -> 811852738182 | R29: =R27+R21 -> 638376968407
A30: حسابهای انتظامی | E30: 29 | G30: ='40'!F11 -> 1349375121713 | I30: 1202583688216 | K30: حسابهای انتظامی | N30: 29 | P30: ='40'!F11 -> 1349375121713 | R30: 1202583688216
A33: یادداشتهای توضیحی همراه ، جزء لاینفک صورتهای مالی می باشد.

Sheet 3
A1: شرکت ساختماني گسترش و نوسازی صنایع ایرانیان مانا ( سهامی خاص )
A2: صورت سود زیان
A3: دوره مالي شش ماهه منتهي به 31 خرداد ماه 1390
E4: دوره مالی شش ماهه منتهی به | G4: دوره مالی شش ماهه منتهی به | I4: دوره مالی9 ماهه منتهی به
B5: يادداشت | E5: 1390/03/31 | G5: 1389/06/31 | I5: 1389/09/30
E6: ریال | G6: ریال | I6: ریال
A7: درآمدپيمانها | B7: 24 | E7: ='36'!E39 -> 395460814361 | G7: 161824112185 | I7: 314540399293
A8: بهای تمام شده پيمانها | B8: 24 | E8: -261089768129 | G8: -171180935210 | I8: -292371962805
A9: سودناخالص پيمانها | E9: =SUM(E7:E8) -> 134371046232 | G9: =SUM(G7:G8) -> -9356823025 | I9: =SUM(I7:I8) -> 22168436488
A10: سایر درآمدها و هزینه های عملیاتی | B10: 25 | E10: 1786362095 | G10: 25999092628 | I10: ='38'!H9 -> 39073000000
E11: =SUM(E9:E10) -> 136157408327 | G11: =SUM(G9:G10) -> 16642269603 | I11: =I9+I10 -> 61241436488
A12: کسرمی شود:
A13: هزينه های اداری وعمومی | B13: 26 | E13: -26297655991 | G13: -20841115748 | I13: -29358813507
A14: سود(زيان)عملياتی | E14: =SUM(E11:E13) -> 109859752336 | G14: =G11+G13 -> -4198846145 | I14: =SUM(I11:I13) -> 31882622981
E15: 0
A16: هزینه های مالی | B16: 19 | C16: -5824635866 | G16: -6787097912 | I16: -9865225404
A17: خالص سايردرآمدهاوهزينه های غيرعملياتی | B17: 27 | C17: 2162967968 | G17: 27322155579 | I17: 70618232401
E18: =C16+C17 -> -3661667898 | G18: 20535057664 | I18: 60753006997
A20: سودناشی ازفعاليتهای عادی قبل ازماليات | E20: =SUM(E14:E18) -> 106198084438 | G20: =G18+G14 -> 16336211519 | I20: =I18+I14 -> 92635629978
A21: ماليات | B21: 17 | E21: -26111436859 | G21: 0 | I21: -7495229915
A22: سود(زیان)خالص | E22: =SUM(E20:E21) -> 80086647579 | G22: =G20+G21 -> 16336211519 | I22: =I20+I21 -> 85140400063
A24: گردش حساب سود(زیان)انباشته
A26: سود(زیان)خالص | E26: =E22 -> 80086647579 | G26: 16336211519 | I26: =I22 -> 85140400063
A27: سود انباشته درابتدای سال | E27: =I36 -> 82091400063 | G27: 52210792036 | I27: 52211000000
A28: تعديلات سنواتی | G28: -52110047555 | I28: 0
A29: سود (زیان) انباشته درابتدای سال-تعديل شده | G29: 0 | I29: 0
A30: سودقابل تخصيص | E30: =SUM(E26:E29) -> 162178047642 | G30: =SUM(G26:G29) -> 16436956000 | I30: =SUM(I26:I29) -> 137351400063
A31: تخصيص سود:
A32: اندوخته قانوني | E32: 0 | G32: -801681142 | I32: -3150000000
A33: سودسهام مصوب | B33: 29 | E33: -79459220755 | G33: 0 | I33: -52110000000
E34: 0 | G34: =SUM(G32:G33) -> -801681142 | I34: =SUM(I32:I33) -> -55260000000
A36: سود انباشته درپايان سال | E36: =E30+E33 -> 82718826887 | G36: =G30+G34 -> 15635274858 | I36: =I30+I34 -> 82091400063
A38: ازآنجائی که اجزاء تشکيل دهنده سود وزيان جامع محدود به سود دوره جاری وتعديلات سنواتی است،صورت سود وزيان جامع ارائه نشده است.
A41: يادداشتهاي توضيحي همراه جزءلاينفك صورتهاي مالي است .

Sheet 4
B1: شرکت ساختماني گسترش و نوسازی صنایع ایرانیان مانا ( سهامی خاص )
B2: صورت جریان وجوه نقد
B3: دوره مالي شش ماهه منتهي به 31 خرداد ماه 1390
C6: يادداشت | E6: 1390/03/31 | H6: 1389/06/31 | J6: 1389/09/30
E7: ریال | F7: ریال | H7: ریال | J7: ریال
B8: فعاليتهای عملياتی :
B9: جريان خالص ورود ( خروج )وجه نقد ناشی ازفعاليتهای عملياتی | C9: 26 | F9: ='39'!K36 -> 122404882401 | H9: 44773295313 | J9: 9522
B10: بازده سرمايه گذاريهاوسودپرداختی بابت تامين مالی:
B11: سوددريافتی بابت سپرده های سرمايه گذاری نزدبانکها | E11: 898212002 | J11: 2418
B12: سود کارمزد بانکی بابت تسهیلات مالی | E12: -19964104495 | J12: -10223
B13: سهام پرداختنی | E13: -82085236658
B14: جریان خالص ورود ( خروج )وجه نقد ناشی از بازده سرمایه گذاریها و سود | F14: =SUM(E11:E13) -> -101151129151 | H14: 475471071 | J14: -7805
B15: پرداختی بابت تأمین مالی
B16: ماليات بردرآمد:
B17: ماليات بردرآمدپرداختی(شامل پيش پرداخت ماليات) | F17: 0 | J17: -13235
B18: فعاليتهاي سرمايه گذاری :
B19: وجوه پرداختی بابت هزینه های سرمایه ای | E19: -2531862720 | J19: -1632
B20: وجوه حاصل ازفروش داراييهای نامشهود | E20: _
B21: وجوه پرداختی جهت خريد داراييهای نا مشهود و سهام سایر شرکتها | E21: -1674500000 | J21: -1771
B22: وجوه پرداختی جهت خرید داراييهای ثابت مشهود | E22: -4575150528 | J22: -9200
B23: وجوه حاصل از فروش دارائیهای ثابت مشهود | E23: 246808296 | J23: 13083
B24: خالص تعديلات داراييهای ثابت مشهود | E24: 163822670 | H24: 0 | J24: 1218
B26: جريان خالص ورود (خروج )وجه نقدناشی ازفعاليتهای سرمايه گذاری | F26: =SUM(E19:E24) -> -8370882282 | H26: -3356646506 | J26: 1700
B27: جريان خالص خروج وجه نقد قبل از فعاليتهای تامین مالی | F27: =SUM(F9+F14+F17+F26) -> 12882870968 | H27: 41892119878 | J27: -9819
B28: فعاليتهاي تامین مالی :
B29: دریافت تسهیلات مالی | E29: 20015000000 | J29: 50000
B30: پرداخت تسهیلات مالی | J30: -15000
F31: =SUM(E29:E30) -> 20015000000 | H31: -42904784397
B32: جريان خالص خروج وجه نقد | F32: =F31+F27 -> 32897870968 | H32: -1012664519 | J32: 25181
B33: مانده وجه نقددرآغازسال | F33: =H35 -> 29937144560 | H33: 30949809079 | J33: 57432
B35: مانده وجه نقددرپايان سال | F35: =F32+F33 -> 62835015528 | H35: 29937144560 | J35: 82613
F37: 14801539168
B38: مبادلات غير نقدي - افزايش سرمايه از محل مطالبات سهامداران | J38: ---
B39: مبادلات غير نقدي - افزايش سرمايه از محل اندوخته طرح و توسعه | J39: ---
B41: يادداشتهاي توضيحي همراه جزءلاينفك صورتهاي مالي است .

Sheet 10
B1: شرکت ساختماني گسترش و نوسازی صنایع ایرانیان مانا ( سهامی خاص )
B2: یادداشتهای توضیحی صورتهای مالی
B3: دوره مالي شش ماهه منتهي به 31 خرداد ماه 1390
B5: 4-موجودی نقد
E6: يادداشت | G6: 1390/03/31 | I6: 1389/09/30
G7: ریال | I7: ریال
B8: موجودی نقد نزد صندوق | G8: 1215990092 | I8: 0
B9: موجودی نقدی ارزی نزد صندوق | G9: 14882943 | I9: 0
B10: موجودی نقد نزد بانکها | E10: 4-1 | G10: =G21 -> 3040605071 | I10: =I21 -> 2051205950
B11: حساب مشترک باکارفرمایان | E11: 4-2 | G11: ='11'!I34 -> 10731317
B12: تنخواه گردانها | E12: 4-3 | G12: ='12'!E31 -> 10519329745 | I12: 3888767162
B13: وجوه بین راهی | G13: 0 | I13: 1680000000
G14: =SUM(G8:G13) -> 14801539168 | I14: =SUM(I10:I13) -> 7619973112
B16: 4-1- موجودي نزد بانك ها از اقلام ز‌ير تشكيل شده است: | G16: 1390/03/31 | I16: 1389/09/30
G17: ریال | I17: ریال
B18: سپرده های کوتاه مدت ديداری | E18: 4-1-1 | G18: =G32 -> 128620717 | I18: =I32 -> 1072948942
B19: حسابهای جاری | E19: 4-1-2 | G19: ='11'!I20 -> 2910804754 | I19: 977221408
B20: حسابهای جاری ارزی | E20: 4-1-3 | G20: 1179600 | I20: 1035600
G21: =SUM(G18:G20) -> 3040605071 | I21: =SUM(I18:I20) -> 2051205950
B23: 4-1-1 صورت ريزسپرده های کوتاه مدت ديداری نزد بانکها به شرح زير مي باشد:
G24: 1390/03/31 | I24: 1389/09/30
G25: ریال | I25: ریال
B26: بانک پاسارگاد سلیمان خاطر 2218108395041 | G26: 1427472 | I26: 10000
B27: بانک سپه قرنی 5040/62 (طرح سپاس ) | I27: 922877754
B28: بانک سپه -دکترمفتح 29217/53 | G28: 127193245 | I28: 128578370
B29: بانک پاسارگاد میرزای شیراز 3078108395042 | G29: 0 | I29: 17544961
B30: بانک پاسارگاد میرزای شیراز 3078108395041 | G30: 0 | I30: 200566
B31: پاسارگادحساب سپرده سلیمان خاطر221/8100/839504/1 | G31: 0 | I31: 3737291
B32: جمع | G32: =SUM(G26:G31) -> 128620717 | I32: =SUM(I26:I31) -> 1072948942
B34: مبلغ 128،620،717ريال ازسپرده های کوتاه مدت ديداری به منظورصدورضمانت نامه های بانکی به نفع کارفرمايان وثیقه شده است .
B35: نرخ سودتضمين شده سپرده های کوتاه مدت ديداری برای سال جاری براساس قانون عمليات بانکی بدون ربا تعيين شده است.

Sheet 11
B1: شرکت ساختماني گسترش و نوسازی صنایع ایرانیان مانا ( سهامی خاص )
B2: یادداشتهای توضیحی صورتهای مالی
B3: دوره مالي شش ماهه منتهي به 31 خرداد ماه 1390
B5: 4-1-2- صورت ريزحسابهای جاری نزد بانکها به قرار زيرمی باشد:
I6: 1390/03/31 | K6: 1389/09/30
I7: ریال | K7: ریال
B8: بانک ملی جم-0105232355008 | I8: 10217296 | K8: 4235199
B9: بانک سپه-سپهبدقرنی 2900/79 | I9: 157820995 | K9: 894439166
B10: بانک ملت - فجر 2812659/78 | I10: 53124614 | K10: 50054536
B11: بانک سپه-دکترمفتح 2500/49 | I11: 606417 | K11: 15586783
B12: بانک تجارت -ميرعماد 122109100 | I12: 890000 | K12: 0
B13: بانک پاسارگاد- حساب سپرده سلیمان خاطر 221118395041 | I13: 0 | K13: 19639
B14: بانک ملت -شعبه ملک الشعراءبهار 7258386641 | I14: 19435555 | K14: 8447835
B15: بانک سپه-مطهری مدرس 1858800112909 | I15: 0 | K15: 500000
B16: بانک سپه مطهری مدرس 1414/16 | I16: 2665693027 | K16: 0
B17: بانک پاسارگاد- میرزای شیرازی 307118395042 | I17: 0 | K17: 1000000
B18: بانک پاسارگاد- میرزای شیرازی 307118395041 | I18: 1035600 | K18: 957000
B19: بانک توسعه صادرات - بلوار کشاورز 100008707000 | I19: 1981250 | K19: 1981250
I20: =SUM(I8:I19) -> 2910804754 | K20: =SUM(K8:K19) -> 977221408
B23: 4-1-3- صورت ريزحسابهای جاری ارزی به شرح زير می باشد:
E24: 1390/03/31 | I24: 1389/09/30
E25: مبلغ - ارز | G25: ریال | I25: مبلغ - ارز | K25: ریال
B26: پاسارگاد میرزای شیرازی 30771608395041 | E26: 100 | G26: 1179600 | I26: 100 | K26: 1035600
B28: موجودی های ارزی نزد بانکها در پايان سال بر اساس هر دلار 11796ریال تسعیر شده است .
B30: 4-2- مشترک با کارفرمایان بشرح زیر میباشد : | I30: 1390/03/31 | K30: 1389/09/30
I31: ریال | K31: ریال
B32: حساب مشترک با کارفرمای شهرداری | I32: 889935 | K32: 0
B33: حساب مشترک با کارفرمای بانک صادرات | I33: 9841382 | K33: 0
I34: =SUM(I32:I33) -> 10731317 | K34: =SUM(K32:K33) -> 0

Sheet 12
B1: شرکت ساختماني گسترش و نوسازی صنایع ایرانیان مانا ( سهامی خاص )
B2: یادداشتهای توضیحی صورتهای مالی
B3: دوره مالي شش ماهه منتهي به 31 خرداد ماه 1390
B5: 4-3- موجودي تنخواه گردانها متشکل از اقلام ذیل می باشد :
C6: يادداشت | E6: 1390/03/31 | G6: 1389/09/30
E7: ریال | G7: ریال
B8: کارگاهها و دفتر مرکزی | C8: 4-3-1 | E8: =E31 -> 10519329745 | G8: 3613832378
B9: دفتر مرکزی - ارزی ( 5267 دلار ) | E9: 0 | G9: 124934784
B10: بانک ماشین آلات | E10: 0 | G10: 150000000
E11: =SUM(E8:E10) -> 10519329745 | G11: =SUM(G8:G10) -> 3888767162
B13: 4-3-1- موجودی تنخواه گردان کارگاهها و دفتر مرکزی متشکل از اقلام ذیل می باشد:
E14: 1390/03/31 | G14: 1389/09/30
E15: ریال | G15: ریال
B16: کارگاه بانک صادرات مشهد | E16: 3441721520 | G16: 299024099
B17: سالن ورزشی شیراز | E17: 10694 | G17: 1511361
B18: طرح میدان شهداء مشهد | E18: 661573564 | G18: 1822039408
B19: کارگاه سرمایه گذاری ساختمانی سپه-امید2 | E19: 22428618 | G19: 82819005
B20: کارگاه آلومینیوم اراک | E20: 35964200 | G20: 835243
B21: موننکو ایران | E21: 1000000 | G21: 64087590
B22: کارگاه 35 متری بلوار معلم | E22: 2647782563 | G22: 31833957
B23: کارگاه نیاوران | E23: 0 | G23: 208888151
B24: کارگاه استادیوم 50 هزار نفری شیراز | E24: 957062383 | G24: 152721660
B25: کارگاه هلال احمر استان فارس | E25: 54086990 | G25: 101942624
B26: کارگاه تصفیه آب شرب مشهد | E26: 147014285 | G26: 320657515
B27: کارگاه احداث کارخانه کک سازی زرند | E27: 20046976 | G27: 292546961
... B30: سایر | E30: 1131758121 | G30: 5628570
E31: =SUM(E16:E30) -> 10519329745 | G31: =SUM(G16:G30) -> 3613832378
B33: 5-حسابها ی دريافتنی تجاری :
B35: شــــــــرح | C35: يادداشت | E35: 1390/03/31 | G35: 1389/09/30
E36: ریال | G36: ریال
B37: بدهی کارفرمايان | C37: 5-1 | E37: ='13'!N52 -> 417941392081 | G37: ='13'!P52 -> 355949014645
B38: مشارکتها | C38: 5-2 | E38: 588623585 | G38: ='15'!G15 -> 2576333817
B39: جمع | E39: =SUM(E37:E38) -> 418530015666 | G39: =SUM(G37:G38) -> 358525348462

Sheet 13
A1: شرکت ساختماني گسترش و نوسازی صنایع ایرانیان مانا ( سهامی خاص )
A2: یادداشتهای توضیحی صورتهای مالی
A3: دوره مالی شش ماهه منتهی به 31 خرداد ماه 1390
A4: 5-1 - مانده سر فصل كارفرمايان مشتمل بر اقلام زير مي باشد:
B5: 1390/03/31 | P5: 1389/09/30
A6: شرح | B6: خالص کارکرد | D6: سپرده حسن انجام کار یادداشت - 6 | F6: سپرده بیمه یادداشت - 6 | L6: ذخیره مطالبات مشکوک الوصول | N6: خالص | P6: خالص
B7: تأئید شده | H7: مبلغ قابل بازيافت | J7: (بدهی) | N7: حسابهای دريافتنی
B8: ریال | D8: ریال | F8: ریال | J8: 0 | N8: ریال | P8: ریال
A9: توليد موتورهاي‌ ديزلي‌ س | B9: 357743632 | D9: 0 | H9: 0 | J9: 0 | L9: 0 | N9: =SUM(B9+D9+F9+L9) -> 357743632 | P9: 357743632
A10: لوله‌ گستر اسفراين‌ | B10: 2910025997 | D10: 7960356630 | H10: 10000000000 | J10: 0 | N10: =SUM(B10+D10+F10+L10) -> 10870382627 | P10: 25584007017
A11: پتروشيمي‌ تبريز | B11: 403218343 | D11: 0 | J11: 0 | L11: 0 | N11: =SUM(B11+D11+F11+L11) -> 403218343 | P11: 403218343
A12: سازمان‌ هواشناسي‌ | B12: 842837432 | D12: 251737899 | J12: 0 | L12: 0 | N12: =SUM(B12+D12+F12+L12) -> 1094575331 | P12: 1094575331
A13: فولادآذربایجان | B13: 446359120 | D13: 0 | J13: 0 | L13: -446359120 | N13: =SUM(B13+D13+F13+L13) -> 0 | P13: 0
A14: سازمان آب منطقه اي استان آذربايجان شرقي و اردبيل | B14: 2500000000 | D14: 0 | J14: 0 | L14: 0 | N14: =SUM(B14+D14+F14+L14) -> 2500000000 | P14: =SUM(B14:L14) -> 2500000000
A15: آب‌ منطقه‌ اي‌ خراسان‌ سد بيدوازاسفراين‌ | B15: 2527643411 | D15: 3802586900 | J15: 0 | L15: 0 | N15: =SUM(B15+D15+F15+L15) -> 6330230311 | P15: 6106435855
A16: وزارت‌ راه‌ روكش‌ آسفالت‌ محور فيروزكوه‌ | B16: 0 | D16: 529008722 | J16: 0 | L16: 0 | N16: =SUM(B16+D16+F16+L16) -> 529008722 | P16: 529008722
A17: شركت‌ مترو | B17: 936063489 | D17: 0 | J17: 0 | L17: 0 | N17: =SUM(B17+D17+F17+L17) -> 936063489 | P17: 1286206656
A18: نمايشگاه‌هاي‌ بين‌المللي | B18: 927526333 | D18: 0 | J18: 0 | L18: 0 | N18: =SUM(B18+D18+F18+L18) -> 927526333 | P18: 927526333
A19: ژنراتورسازی منتطرقائم | B19: 5285755870 | D19: 0 | F19: 365923667 | J19: 0 | L19: 0 | N19: =SUM(B19+D19+F19+L19) -> 5651679537 | P19: 5285755870
A20: ساختمان‌ مركزي‌ -وزارت‌ نيرو | B20: 0 | D20: 11008298884 | F20: 208599800 | J20: 0 | L20: 0 | N20: =SUM(B20+D20+F20+L20) -> 11216898684 | P20: 11008298884
A21: پتروشيمي اروندماهشهر | B21: 1050571728 | D21: 7268397422 | F21: 2349231968 | J21: 0 | L21: 0 | N21: =SUM(B21+D21+F21+L21) -> 10668201118 | P21: 15775027958
A22: آلومينيوم سازي اراك -ايرالكو | B22: 18990989461 | D22: 6853006999 | F22: 929970806 | H22: 14371823833 | J22: 0 | L22: 0 | N22: =SUM(B22+D22+F22+L22) -> 26773967266 | P22: 35331898917
A23: بانك صادرات استان خراسان رضوي | B23: 1200000000 | D23: 9777171648 | H23: 0 | J23: -388443043 | N23: =SUM(B23+D23+F23+L23) -> 10977171648 | P23: 14024130061
A24: پروژه سا ختمان ميدان شهدا شهر داري مشهد | B24: 0 | D24: 2103100204 | H24: 0 | J24: 0 | L24: 0 | N24: =SUM(B24+D24+F24+L24) -> 2103100204 | P24: 8960595370
A25: شرکت توسعه اماکن ورزشي - شيراز | B25: 3950000000 | D25: 2848775490 | H25: 8109090051 | J25: 0 | L25: 0 | N25: =SUM(B25+D25+F25+L25) -> 6798775490 | P25: 2848775490
A26: شركت حمل ونقل ريلي گسترش | B26: 3300000000 | D26: 0 | H26: 0 | J26: 0 | L26: 0 | N26: =SUM(B26+D26+F26+L26) -> 3300000000 | P26: 3300000000
A27: ساختمان آنود رادينگ ايرالکو | B27: 1218199952 | D27: 2337851383 | F27: 1168925590 | H27: 68676588 | J27: 0 | L27: 0 | N27: =SUM(B27+D27+F27+L27) -> 4724976925 | P27: 5505925021
A28: شرکت سرمايه گذاري ساختماني سپه | B28: 5130082225 | D28: 1496383570 | F28: 5773492178 | H28: 8951596607 | J28: 0 | L28: 0 | N28: =SUM(B28+D28+F28+L28) -> 12399957973 | P28: 6803162048
A29: تکميل ديوارمحوطه فولادسازي زرند ايرانيان | B29: 500000000 | D29: 617744235 | F29: 308872117 | H29: 0 | J29: 0 | L29: 0 | N29: =SUM(B29+D29+F29+L29) -> 1426616352 | P29: 2058737676
A30: محوطه سازي کنستانتره جلال آباد فولاد زرند | B30: 919618362 | D30: 55097992 | F30: 124027623 | H30: 0 | J30: 0 | L30: 0 | N30: =SUM(B30+D30+F30+L30) -> 1098743977 | P30: 489983283
A31: فنس کشی محوطه کک سازی فولادزرندایرانیان | B31: 222989942 | D31: 176145203 | F31: 88072601 | H31: 0 | J31: 0 | L31: 0 | N31: =SUM(B31+D31+F31+L31) -> 487207746 | P31: 0
A32: شرکت موننکو ايران | B32: 84297465 | D32: 3003197308 | F32: 1501598655 | H32: 1468026909 | J32: 0 | L32: 0 | N32: =SUM(B32+D32+F32+L32) -> 4589093428 | P32: 6057120337
A33: شرکت فولاد زرند ايرانيان-کارخانه کک سازي زرند | B33: 126783482282 | D33: 25708428274 | F33: 12854214137 | H33: 0 | J33: -77035440789 | L33: 0 | N33: =SUM(B33+D33+F33+L33) -> 165346124693 | P33: 139199636847
A34: مشارکت فام - کارخانه کنسانتره آهن زرندجلال آباد | B34: 11179257297 | D34: 0 | F34: 0 | H34: 0 | J34: -7018409385 | L34: 0 | N34: =SUM(B34+D34+F34+L34) -> 11179257297 | P34: 29909691130
A35: پيمان مديريت ساختمان مرکزي نيرو | B35: 649598548 | D35: 229808652 | F35: 229808652 | H35: 0 | J35: 0 | L35: 0 | N35: =SUM(B35+D35+F35+L35) -> 1109215852 | P35: 1109412356
A36: اجراي حصارکشي وعمليات ساختماني کنسانتره سيرجان | B36: 743489656 | D36: 296361134 | F36: 148180567 | H36: 0 | J36: 0 | L36: 0 | N36: =SUM(B36+D36+F36+L36) -> 1188031357 | P36: 1215984221
A37: شرکت سرمايه گذاري نيرو | B37: 5198082551 | D37: 1433299511 | F37: 716649754 | H37: 0 | J37: 0 | L37: 0 | N37: =SUM(B37+D37+F37+L37) -> 7348031816 | P37: 184849645
A38: شرکت مديريت طرح واجرائ خانه سازي ايران | B38: 1290000000 | D38: 1843534549 | H38: 0 | J38: -906381453 | L38: 0 | N38: =SUM(B38+D38+F38+L38) -> 3133534549 | P38: 2241885353
A39: سازمان مهندسي وعمران شهر تهران - بلوار معلم | B39: 22734861999 | D39: 1486091027 | F39: 743045514 | H39: 0 | J39: -308043209 | L39: 0 | N39: =SUM(B39+D39+F39+L39) -> 24963998540 | P39: 5670529732
A40: شرکت توسعه اماکن ورزشي- استاديوم 50هزار نفري شيراز | B40: 4600000000 | D40: 2761403143 | H40: 5019683143 | J40: 0 | L40: 0 | N40: =SUM(B40+D40+F40+L40) -> 7361403143 | P40: 10421320443
...

Sheet 14
A1: شركت ساختماني گسترش و نوسازي صنايع ايرانیان مانا (سهامي خاص)
A2: يادداشتهاي توضيحي صورتهاي مالي
A3: دوره مالي شش ماهه منتهي به 31 خرداد ماه 1390
A5: 5-1-1- مبلغ قابل بازيافت ( بدهی ) پيمان بشرح زير مي باشد:
A7: شرح | C7: درآمد شناسائي شده انباشته | E7: صورت وضعيتهاي تائيد شده | G7: مبلغ قابل بازيافت | I7: (بدهی)
C8: ریال | E8: ریال | G8: ریال | I8: ریال
A9: مترو | C9: 426836765 | E9: 426836765 | G9: =IF(C9>E9,C9-E9,0) -> 0 | I9: 0
A10: سد آيدوغموش‌ ميانه‌ | C10: 769942277 | E10: 769942277 | G10: =IF(C10>E10,C10-E10,0) -> 0 | I10: 0
A11: سد بيدواز اسفراين‌ | C11: 120559541950 | E11: 120559541950 | G11: =IF(C11>E11,C11-E11,0) -> 0 | I11: 0
A12: ساختمان‌ مركزي‌ وزار | C12: 144350527772 | E12: 144350527772 | G12: =IF(C12>E12,C12-E12,0) -> 0 | I12: =IF(C12<E12,C12-E12,0) -> 0
A13: لوله‌ هاي‌ بدون‌ درز | C13: 223178734533 | E13: 213178734533 | G13: =IF(C13>E13,C13-E13,0) -> 10000000000 | I13: =IF(C13<E13,C13-E13,0) -> 0
A14: كارخانه‌سيمان‌حما | C14: 76125923416 | E14: 76125923416 | G14: =IF(C14>E14,C14-E14,0) -> 0 | I14: =IF(C14<E14,C14-E14,0) -> 0
A15: کارگاه آلومينيوم اراک | C15: 247590453743 | E15: 233218629910 | G15: =IF(C15>E15,C15-E15,0) -> 14371823833 | I15: =IF(C15<E15,C15-E15,0) -> 0
A16: کارگاه پتروشيمي اروندماهشهر | C16: 163919352803 | E16: 163919352803 | G16: =IF(C16>E16,C16-E16,0) -> 0 | I16: =IF(C16<E16,C16-E16,0) -> 0
A17: کارگاه بانک صادرات استان خراسان رضوي | C17: 233133273454 | E17: 233521716497 | G17: =IF(C17>E17,C17-E17,0) -> 0 | I17: =IF(C17<E17,C17-E17,0) -> -388443043
A18: طر ح مبدان شهد ا مشهد | C18: 48798233853 | E18: 48798233853 | G18: =IF(C18>E18,C18-E18,0) -> 0 | I18: =IF(C18<E18,C18-E18,0) -> 0
A19: سالن ورزشي شيراز | C19: 40588259523 | E19: 32479169472 | G19: =IF(C19>E19,C19-E19,0) -> 8109090051 | I19: =IF(C19<E19,C19-E19,0) -> 0
A20: پروژه فاز 1 جديد خط 3 مترو | C20: 4800000000 | E20: 4800000000 | G20: =IF(C20>E20,C20-E20,0) -> 0 | I20: =IF(C20<E20,C20-E20,0) -> 0
A21: کارگاه آنود رادينگ - ايرالکو | C21: 24418676588 | E21: 24350000000 | G21: =IF(C21>E21,C21-E21,0) -> 68676588 | I21: =IF(C21<E21,C21-E21,0) -> 0
A22: کارگاه سرمايه گذاري ساختماني سپه - اميد 2 | C22: 140000000110 | E22: 131048403503 | G22: =IF(C22>E22,C22-E22,0) -> 8951596607 | I22: =IF(C22<E22,C22-E22,0) -> 0
A23: کارگاه کارخانه فولاد زرند ايرانيان | C23: 11142436776 | E23: 11142436776 | G23: =IF(C23>E23,C23-E23,0) -> 0 | I23: =IF(C23<E23,C23-E23,0) -> 0
... A37: بوستان ولایت | C37: 50000000000 | E37: 50000000000 | G37: =IF(C37>E37,C37-E37,0) -> 0 | I37: =IF(C37<E37,C37-E37,0) -> 0
C38: =SUM(C9:C37) -> 2143285595501 | E38: =SUM(E9:E37) -> 2196810606520 | G38: =SUM(G9:G37) -> 48238897131 | I38: =SUM(I9:I36) -> -101763908150

Sheet 15
A1: شركت ساختماني گسترش و نوسازي صنايع ايرانیان مانا (سهامي خاص)
A2: يادداشتهاي توضيحي صورتهاي مالي
A3: دوره مالي شش ماهه منتهي به 31 خرداد ماه 1390
A5: 5-2- مانده حساب مشارکتها به شرح زيرتفکيک می شود:
A7: شـــــــرح | C7: 1390/03/31-ريال | G7: 1389/09/30
C8: بهای تمام شده دارائیهای ثابت | D8: استهلاک انباشته | E8: ارزش دفتری دارائیهای ثابت | F8: وديعه تلفن | G8: طلب | H8: بدهی
G9: ریال | H9: ریال
A10: مشارکت پارکينگ نمايشگاه بين المللی | C10: 86129800 | D10: -43422427 | E10: 42707373 | F10: 0 | G10: 1551243893 | H10: 0
A11: مشارکت لوله های بدون درز | C11: 237884563 | D11: 0 | E11: 237884563 | F11: 1855000 | G11: 239739563 | H11: 0
A12: مشارکت پرس اسفراين | C12: 1095491800 | D12: -824342138 | E12: 271149662 | F12: 0 | G12: 0 | H12: 1873955013
A13: مشارکت مترو | C13: 14416667 | D13: -9025882 | E13: 5390785 | F13: 2020000 | G13: 0 | H13: 286450583
A14: مشارکت دانشگاه صنعتی اميرکبير | C14: 111162300 | D14: -91826098 | E14: 19336202 | F14: 8280000 | G14: 785350361 | H14: 0
A15: جمع | C15: =SUM(C10:C14) -> 1545085130 | D15: =SUM(D10:D14) -> -968616545 | E15: =SUM(E10:E14) -> 576468585 | F15: =SUM(F10:F14) -> 12155000 | G15: =SUM(G10:G14) -> 2576333817 | H15: =SUM(H10:H14) -> 2160405596
B17: چگونگی ارزيابی وانعکاس مشارکتها درصورتهای مالی دريادداشت شماره 8-3خلاصه اهم رويه های حسابداری توصيف شده است .
B19: شرکت درسنوات گذشته به منظوراجرای پروژه های فوق اقدام به انعقاد قرارداد مشارکت با اشخاص حقيقی وحقوقی نموده که به لحاظ بروزپاره ای مسائل قراردادهای مذکورعمدتاً درسنوات
B20: 1379و1380متوقف گردیده مفتوح بودن پرونده اينگونه قراردادها درمراجع قضايی تسويه حساب با طرفهای قرارداد منوط به صدوررای قطعی ازسوی مراجع يادشده ميباشد.
B22: حسابهای تعدادی ازقراردادهای مشارکت براساس صورتجلسات وتوافق نامه های منعقده بين طرفين مشخص واثرات ريالی آنها درحسابهای شرکت منعکس وليکن تسويه نشده است.
B24: تعدادی ازقراردادهای مشارکت به لحاظ عدم حصول توافق نهايی با طرفهای شريک تا کنون نهائی نگرديده ومترصد تعيين تکليف ازطريق مراجع قضائی ميباشد.

Sheet 16
A1: شركت ساختماني گسترش و نوسازي صنايع ايرانیان مانا (سهامي خاص)
A2: يادداشتهاي توضيحي صورتهاي مالي
A3: دوره مالي شش ماهه منتهي به 31 خرداد ماه 1390
A5: 6- ساير حسابهاي دريافتني:
A6: سرفصل فوق از اقلام زير تشكيل شده است:
C8: يادداشت | E8: 1390/03/31 | K8: 1389/09/30
E9: مانده | G9: ذخيره م.م | I9: خالص | K9: خالص
E10: ریال | G10: ریال | I10: ریال | K10: ریال
A11: اسناد مناقصه | E11: 2988000 | I11: =SUM(E11:G11) -> 2988000 | K11: 55546181
A12: سپرده هاي موقت | C12: 6-1 | E12: =I30 -> 33622599984 | I12: =SUM(E12:G12) -> 33622599984 | K12: =K30 -> 14650095538
A13: بدهي كاركنان | E13: 1018806034 | I13: =SUM(E13:G13) -> 1018806034 | K13: 894231084
A14: ساير حسابهاي دريافتني | C14: 6-2 | E14: ='17'!E57 -> 200763178451 | G14: ='17'!G57 -> -5391264400 | I14: ='17'!I57 -> 195371914051 | K14: ='17'!K57 -> 122792888965
E15: =SUM(E11:E14) -> 235407572469 | G15: =SUM(G11:G14) -> -5391264400 | I15: =SUM(I11:I14) -> 230016308069 | K15: =SUM(K11:K14) -> 138392761768
A17: 6-1- سپرده های موقت از اقلام زیر تشکیل شده است :
I19: 1390/03/31 | K19: 1389/09/30
I20: ریال | K20: ریال
A21: بانک سپه سپهبد قرنی | C21: 6-1-1 | I21: 1182502583 | K21: 6919778906
A22: بانک سپه شعبه مفتح | C22: 6-1-1 | I22: 0 | K22: 1228930000
A23: بانک پاسارگاد-سلیمان خاطر | C23: 6-1-1 | I23: 12303323 | K23: 6365386597
A24: سپرده ضمانتنامه ها | C24: 6-1-1 | I24: 1181842216 | K24: 0
A25: بانک سپه مطهری مدرس 202000/09 | C25: 6-1-2 | I25: 16597544324 | K25: 0
A26: سرمایه گذاری ساختمانی سپه - امید 2 | I26: 0 | K26: 1188000
A27: بانک ملت شعبه ملک الشعرا | I27: 0 | K27: 134312035
A28: شرکت آریا رسانه | I28: 0 | K28: 500000
A29: سپرده نزد بانکها | I29: 14648407538 | K29: 0
I30: =SUM(I21:I29) -> 33622599984 | K30: =SUM(K21:K29) -> 14650095538
A33: 6-1-1-سپرده نزد بانکها بابت10%سپرده صدورضمانت نامه بانکی به نفع کارفرمايان میباشد که پس ازابطال ضمانت نامه ها توسط کارفرمايان قابل دريافت خواهد بود.
A35: 6-1-2- سپرده نزد سازمان گسترش و نوسازی صنایع ایران مربوط به 10% سپرده نقدی بابت صدور ضمانت نامه های تضمین انجام تعهدات پروژه لوله گستراسفراین میباشد

Sheet 17
A1: شركت ساختماني گسترش و نوسازي صنايع ايرانیان مانا (سهامي خاص)
A2: يادداشتهاي توضيحي صورتهاي مالي
A3: دوره مالي شش ماهه منتهي به 31 خرداد ماه 1390
A5: 6-2- سايرحسابهای دريافتنی بشرح زيرمي باشد:
E6: 1390/03/31 | K6: 1389/09/30
C7: يادداشت | E7: مانده | G7: ذخيره م.م | I7: خالص | K7: مانده
E8: میلیون ریال | G8: میلیون ریال | I8: میلیون ریال | K8: میلیون ریال
A9: پشتیبان حاتمی و شیخی_موننکو | E9: 739348587 | G9: 0 | I9: =SUM(E9:G9) -> 739348587 | K9: 9342655
A10: پشتیبان حاتمی و شیخی_پیمان مدیریت موننکو | E10: 9342655 | G10: 0 | I10: =SUM(E10:G10) -> 9342655 | K10: 1208759270
A11: مهندسی راهبردی ابنیه | E11: 75000000000 | G11: 0 | I11: =SUM(E11:G11) -> 75000000000 | K11: 75000000000
A12: بدهکاران موقت | E12: 0 | G12: 0 | I12: =SUM(E12:G12) -> 0 | K12: 115240000
A13: محمود حسامی | E13: 23517759 | G13: 0 | I13: =SUM(E13:G13) -> 23517759 | K13: 23517759
A14: قهرمان بادامه گان | E14: 0 | G14: 0 | I14: =SUM(E14:G14) -> 0 | K14: 560441006
A15: پرویزکاظمی | E15: 0 | G15: 0 | I15: =SUM(E15:G15) -> 0 | K15: 200250000
A16: ابراهیم شعبانی | E16: 507000000 | G16: 0 | I16: =SUM(E16:G16) -> 507000000 | K16: 507000000
A17: وزارت امور اقتصاد و دارائی | C17: 6-2-1 | E17: 431605682 | G17: 0 | I17: =SUM(E17:G17) -> 431605682 | K17: 431605682
A18: مترو | E18: 0 | G18: 0 | I18: =SUM(E18:G18) -> 0 | K18: 719835638
A19: شرکت مهرازشرق | E19: 0 | G19: 0 | I19: =SUM(E19:G19) -> 0 | K19: 153133458
A20: شرکت تهویه | E20: 0 | G20: 0 | I20: =SUM(E20:G20) -> 0 | K20: 1899705941
A21: شرکت تولیدی و صنعتی آلان | E21: 0 | G21: 0 | I21: =SUM(E21:G21) -> 0 | K21: 5663676450
A22: مشارکت فام_کارخانه کنسانتره آهن زرند | E22: 7812892047 | G22: 0 | I22: =SUM(E22:G22) -> 7812892047 | K22: 13541583023
A23: ایستا بنیان | E23: 0 | G23: 0 | I23: =SUM(E23:G23) -> 0 | K23: 226000828
A24: شرکت تولیدی بالان صنعت | E24: 145000000 | G24: 0 | I24: =SUM(E24:G24) -> 145000000 | K24: 145000000
A25: شرکت پاکمن | E25: 0 | G25: 0 | I25: =SUM(E25:G25) -> 0 | K25: 481797950
A26: پروژه استادیوم ورزشی | E26: 0 | G26: 0 | I26: =SUM(E26:G26) -> 0 | K26: 400000000
A27: حسین جعفری | E27: 0 | G27: 0 | I27: =SUM(E27:G27) -> 0 | K27: 420000000
A28: آزمایشات فنی ومکانیک خاک(بتن) | E28: 0 | G28: 0 | I28: =SUM(E28:G28) -> 0 | K28: 137200882
A29: پیمان مدیریت کارگاه موننکو | E29: 0 | G29: 0 | I29: =SUM(E29:G29) -> 0 | K29: 364205944
... A32: فروشگاه الوند | E32: 0 | G32: 0 | I32: =SUM(E32:G32) -> 0 | K32: 160514500
A33: بدهکاران خرید زمین پونک | C33: 6-2-2 | E33: 5391264400 | G33: =-E33 -> -5391264400 | I33: =SUM(E33:G33) -> 0 | K33: 0
A34: حساب مشترک با کارفرما | E34: 0 | G34: 0 | I34: =SUM(E34:G34) -> 0 | K34: 559841382
A35: شرکت نوین نارون | E35: 0 | G35: 0 | I35: =SUM(E35:G35) -> 0 | K35: 142485000
A36: سنگ صدف | E36: 0 | G36: 0 | K36: 198977600
A37: شرکت رایاتدبیرکویر | E37: 0 | G37: 0 | I37: =SUM(E37:G37) -> 0 | K37: 525763500
A38: اجناس واگذاری به شرکت احداث صنعت | C38: 6-2-3 | E38: 101351250 | G38: 0 | I38: =SUM(E38:G38) -> 101351250 | K38: 101351250
A39: شرکت فناوری وتجارت ایلیا | E39: 0 | G39: 0 | I39: =SUM(E39:G39) -> 0 | K39: 806078000
A40: شرکت نگین درب پاسارگاد | E40: 0 | G40: 0 | I40: =SUM(E40:G40) -> 0 | K40: 152500000
A41: تکنیک تراش | E41: 0 | G41: 0 | I41: =SUM(E41:G41) -> 0 | K41: 427095000
A42: سازه گهرکاوه | E42: 0 | G42: 0 | I42: =SUM(E42:G42) -> 0 | K42: 278970800
A43: سنگبری امینی | E43: 0 | G43: 0 | I43: =SUM(E43:G43) -> 0 | K43: 875248700
...

Sheet 18
A1: شركت ساختماني گسترش و نوسازي صنايع ايرانیان مانا (سهامي خاص)
A2: يادداشتهاي توضيحي صورتهاي مالي
A3: دوره مالي شش ماهه منتهي به 31 خرداد ماه 1390
A5: 6-2-1- مانده بدهی این حساب به مبلغ 431605682 ریال مربوط به مازاد پرداختی های شرکت در ارتباط با تسویه حساب مالیاتی تا پایان سال 84 می باشد .
A7: 6-2-2- | B7: مانده حساب فوق به مبلغ 5،391،264،400 ريال عبارت ازمطالبات شرکت بابت فسخ موضوع خريد زمين دراراضی مراد آباد پونک
A8: به طرفیت آقایان سید باقر حسینی ، حبیب ا... افروز ، سعدان ترابی ، نظرعلی تاجیک داودی وحسن دهقان می باشد که اقدامات لازم به منظوروصول آن
A9: ازطریق مراجع قضايی بعمل آمده و نامبردگان تحت تعقيب قرار گرفته اند که منجربه صدور دادنامه بدوی علیه ایشان گردیده است .
A10: جهت مبلغ فوق ذخیره لازم در حسابها منظور شده است .
A13: 6-2-3- | B13: مانده بدهی مذکور به مبلغ 101،351،250 ریال بابت بهای یکدستگاه وانت خريداری شده بنام شرکت احداث صنعت جهت استفاده در
B14: کارگاه سیمان حماء در سوریه می باشد .
A16: 7- | B16: شرکتهای گروه به شرح ذیل می باشد :
F17: 1390/03/31 | H17: 1389/09/30
F18: ریال | H18: ریال
A19: شرکت بازرگانی آفتاب درخشان | F19: 154769310 | H19: 0
A20: شرکت توسعه ساخت و نصب قطعات بتونی و فلزی - مانا ساز | F20: 25836150291 | H20: 16613755085
A21: شرکت فولاد سیرجان ایرانیان | F21: 779625001 | H21: 500100001
A22: شرکت بابک مس ایرانیان | F22: 205250000 | H22: 193175000
A23: شرکت فروسیلیس غرب | F23: 50000000 | H23: 0
F24: =SUM(F19:F23) -> 27025794602 | H24: =SUM(H19:H23) -> 17307030086
A26: 8 - موجودی موادوکالاوپيمان درجريان پيشرفت
A27: موجودی موادوکالاوپيمان درجريان پيشرفت ازاقلام زيرتشکيل شده است:
D29: 1390/03/31 | H29: 1389/09/30
C30: يادداشت | D30: بهای تمام شده | E30: ذخيره کاهش ارزش | F30: خالص | H30: خالص
D31: ریال | E31: ریال | F31: ریال | H31: ریال
A32: پيمان درجريان پيشرفت | D32: 0 | H32: 47916847008
A33: موجودی مواد وکالا | C33: 8-1 | D33: ='19'!E19 -> 13331416599 | F33: =D33-E33 -> 13331416599 | H33: 3077582641
D34: =SUM(D32:D33) -> 13331416599 | E34: =SUM(E32:E33) -> 0 | F34: =SUM(F32:F33) -> 13331416599 | H34: =SUM(H32:H33) -> 50994429649

Sheet 19
A1: شركت ساختماني گسترش و نوسازي صنايع ايرانیان مانا (سهامي خاص)
A2: يادداشتهاي توضيحي صورتهاي مالي
A3: دوره مالي شش ماهه منتهي به 31 خرداد ماه 1390
A5: 8-1 موجودی موادوکالا از اقلام زيرتشکيل شده است:
I7: 1390/03/31 | K7: 1389/09/30
E8: ریال
A9: لوازم یدکی | E9: 1232875385 | I9: =SUM(E9:H9) -> 1232875385 | K9: 592232220
A10: لوازم برقی | E10: 1962349061 | I10: =SUM(E10:H10) -> 1962349061 | K10: 0
A11: لوازم تاسیساتی | E11: 1745994700 | I11: =SUM(E11:H11) -> 1745994700 | K11: 0
A12: مصالح ساختمانی | E12: 1038080320 | I12: =SUM(E12:H12) -> 1038080320 | K12: 1958180102
A13: آهن آلات ساختمانی | E13: 5506682332 | I13: =SUM(E13:H13) -> 5506682332 | K13: 0
A14: ملزومات اداری | E14: 22195431 | I14: =SUM(E14:H14) -> 22195431 | K14: 0
A15: مواد غذایی | E15: 6234872 | I15: =SUM(E15:H15) -> 6234872 | K15: 0
A16: داراییهای نزد انبار | E16: 20403949 | I16: =SUM(E16:H16) -> 20403949 | K16: 0
A17: موادولوازم مصرفی | E17: 1796600549 | I17: =SUM(E17:H17) -> 1796600549 | K17: 0
A18: کالای امانی نزد دیگران | E18: 0 | I18: =SUM(E18:H18) -> 0 | K18: 527170319
E19: =SUM(E9:E18) -> 13331416599 | I19: =SUM(E19:H19) -> 13331416599 | K19: =SUM(K9:K18) -> 3077582641
A21: 9- | B21: پيش پرداختها
B22: مانده حساب سفارشات وپيش پرداختها ازاقلام زيرتشکيل شده است:
C23: يادداشت | E23: 1390/03/31 | I23: 1390/03/31 | K23: 1389/09/30
E24: ریال
B25: وزارت دارايی-ماليات عملکرد | C25: 17 | E25: 13525562507 | I25: =E25 -> 13525562507 | K25: 22815498447
B26: پیش پرداخت خرید جاری | C26: 9-1 | E26: =E36 -> 33506988457 | G26: 0 | I26: =I36 -> 33506988457 | K26: 0
B27: پیش پرداخت به پیمانکاران | C27: 9-2 | E27: =E43 -> 11073970318 | G27: 0 | I27: =I43 -> 11073970318
B28: ساير پيش پرداختها | C28: 9-3 | E28: 12015101799 | G28: =G48 -> 0 | I28: =E28-G28 -> 12015101799 | K28: =K48 -> 9455898625
E29: =SUM(E25:E28) -> 70121623081 | F29: 0 | G29: =SUM(G26:G28) -> 0 | I29: =SUM(I25:I28) -> 70121623081 | K29: =SUM(K25:K28) -> 32271397072
I31: 1390/03/31 | K31: 1389/09/30
A32: 9-1 | B32: پیش پرداخت خرید جاری به شرح زیر میباشد :
B33: دفتر مرکزی | E33: 19611958107 | G33: 0 | I33: =E33 -> 19611958107 | K33: 0
B34: نازک کاری موننکو | E34: 12164428055 | G34: 0 | I34: =E34 -> 12164428055 | K34: 0
B35: سایر | E35: 1730602295 | G35: 0 | I35: =E35 -> 1730602295 | K35: 0
E36: =SUM(E33:E35) -> 33506988457 | G36: =SUM(G29:G35) -> 0 | I36: =SUM(I33:I35) -> 33506988457 | K36: =SUM(K33:K35) -> 0
I38: 1390/03/31 | K38: 1389/09/30
A39: 9-2 | B39: پیش پرداخت پیمانکاران به شرح زیر میباشد :
B40: دفتر مرکزی | E40: 2910320666 | G40: 0 | I40: =E40 -> 2910320666 | K40: 0
B41: بوستان ولایت | E41: 7565670525 | G41: 0 | I41: =E41 -> 7565670525 | K41: 0
B42: سایر | E42: 597979127 | G42: 0 | I42: =E42 -> 597979127 | K42: 0
E43: =SUM(E40:E42) -> 11073970318 | G43: =SUM(G36:G42) -> 0 | I43: =SUM(I40:I42) -> 11073970318 | K43: =SUM(K40:K42) -> 0
A45: 9-3 | B45: ساير پیش پرداختها به قرار زير مي باشد : | I45: 1390/03/31 | K45: 1389/09/30
A46: بيمه | E46: 12015101799 | G46: 0 | I46: =SUM(E46:G46) -> 12015101799 | K46: 9057210375
...

Sheet 20
A1: دوره مالي ششماهه منتهي به 31 خرداد ماه 1390
A2: يادداشتهاي توضيحي صورتهاي مالي
A3: دوره مالي شش ماهه منتهي به 31 خرداد ماه 1390
A5: -10 | B5: داراييهای ثابت مشهود
A6: جدول بهای تمام شده و استهلاک انباشته داراييهای ثابت مشهود به شرح زيراست:
F8: بهای تمام شده -ريال | P8: استهلاک انباشته -ريال | Z8: مبلغ دفتری -ريال
A9: شرح اقلام | F9: مانده در | H9: داراييهای اضافه شده | J9: داراييهای فروخته | L9: نقل و انتقالات و | N9: مانده در | P9: مانده در | R9: استهلاک سال | T9: استهلاک انباشته | V9: نقل وانتقالات و | X9: مانده در | Z9: مانده در | AB9: مانده در
D10: یادداشت | F10: 1389/09/30 | H10: طی سال مالی | J10: شده طی سال مالی | L10: سايرتعديلات | N10: 1390/03/31 | P10: 1389/09/30 | R10: مالی | T10: دارائيهای فروخته شده | V10: سايرتغييرات | X10: 1390/03/31 | Z10: 1390/03/31 | AB10: 1389/12/29
A11: زمين | D11: 10_1 | F11: 1733504656 | L11: --- | N11: 1733504656 | P11: 6063021 | R11: 125981 | T11: 0 | V11: --- | X11: 6063021 | Y11: =SUM(P11:X11) -> 12252023 | Z11: =N11-X11 -> 1727441635 | AB11: 1727441635
A12: ساختمان | D12: 10_2 | F12: 6079978127 | H12: --- | J12: --- | L12: --- | N12: 6079978127 | P12: 3281608920 | R12: 105411172 | T12: 0 | V12: --- | X12: 3325499372 | Z12: =N12-X12 -> 2754478755 | AB12: 2798369207
A13: تاسيسات | F13: 120255119 | H13: 35200000 | J13: --- | L13: --- | N13: =H13+F13 -> 155455119 | O13: =SUM(F13:M13) -> 155455119 | P13: 107522692 | R13: 665981 | T13: 0 | V13: --- | X13: 107522692 | Z13: =N13-X13 -> 47932427 | AB13: 12732427
A14: ماشين آلات وتجهيزات | D14: 10-3 | F14: 42114753780 | H14: 1129133000 | J14: - | L14: --- | N14: =H14+F14 -> 43243886780 | P14: 31077423751 | R14: 807395702 | T14: 0 | V14: --- | X14: 31864845548 | Z14: =N14-X14 -> 11379041232 | AB14: 11037330029
A15: اثاثه فنی | D15: 10-4 | F15: 13107627370 | H15: 986404000 | J15: -100595000 | K15: =SUM(F15:J15) -> 13993436370 | L15: --- | N15: =F15+H15+J15 -> 13993436370 | P15: 10329950542 | R15: 413235163 | T15: -95611558 | V15: --- | X15: =P15+R15+T15 -> 10647574147 | Z15: =N15-X15 -> 3345862223 | AB15: 2777676828
A16: اثاثه اداری | D16: 10-5 | F16: 9596804960 | H16: 2011469000 | J16: -9665000 | L16: --- | N16: =SUM(F16:J16) -> 11598608960 | P16: 4002381417 | R16: 463645068 | T16: -2638839 | V16: --- | X16: 4463387646 | Z16: =N16-X16 -> 7135221314 | AB16: 5594423543
A17: وسايل نقليه | D17: 10-6 | F17: 15365096410 | H17: 412944528 | J17: -21271636 | L17: --- | N17: =SUM(F17:J17) -> 15756769302 | P17: 14777950091 | R17: 247895211 | T17: -21154607 | V17: --- | X17: 15000356899 | Z17: =N17-X17 -> 756412403 | AB17: 587146319
F18: =SUM(F11:F17) -> 88118020422 | H18: =SUM(H13:H17) -> 4575150528 | J18: =SUM(J15:J17) -> -131531636 | L18: =SUM(L12:L17) -> 0 | N18: =SUM(N11:N17) -> 92561639314 | P18: =SUM(P11:P17) -> 63582900434 | R18: =SUM(R11:R17) -> 2038374278 | T18: =SUM(T11:T17) -> -119405004 | V18: =SUM(V12:V17) -> 0 | X18: =SUM(X11:X17) -> 65415249325 | Z18: =SUM(Z11:Z17) -> 27146389989 | AB18: =SUM(AB11:AB17) -> 24535119988
A19: دارائی درجریان تکمیل - مهمانسرای مشهد | F19: 2770049698 | H19: 314008458 | J19: --- | L19: --- | N19: =H19+F19 -> 3084058156 | P19: --- | R19: --- | T19: --- | V19: --- | X19: --- | Z19: 3084058156 | AB19: 2770049698
A20: دارائی درجریان تکمیل - انبار خلیج فارس | F20: 420000000 | H20: 0 | N20: 420000000 | Z20: 420000000 | AB20: 420000000
A21: پيش پرداختهای سرمايه ای | H21: 280000000 | J21: 0 | N21: 280000000 | P21: --- | R21: --- | T21: --- | V21: --- | X21: --- | Z21: 280000000 | AB21: 823090720
F22: =SUM(F18:F21) -> 91308070120 | H22: =SUM(H18:H21) -> 5169158986 | J22: =SUM(J18:J21) -> -131531636 | L22: =SUM(L18:L21) -> 0 | N22: =SUM(N18:N21) -> 96345697470 | P22: =P18 -> 63582900434 | R22: =SUM(R18:R21) -> 2038374278 | T22: =T18 -> -119405004 | V22: =V18 -> 0 | X22: =X18 -> 65415249325 | Z22: =SUM(Z18:Z21) -> 30930448145 | AB22: 28548260406
A25: داراييهای ثابت مشهود شرکت درمقابل خطرات ناشی ازحريق ،سيل،انفجار و زلزله معادل 38/4 ميلياردريال از پوشش بيمه ای برخوردار می باشند.
A26: روش های حسابداری مربوط به تحصيل واستهلاک داراييهای ثابت مشهود دريادداشت شماره (3-3) خلاصه اهم رويه های حسابداری توصيف شده است .
A27: شش دانگ سندساختمان مرکزی بابت بدهی به سازمان خصوصی نزد شرکت گسترش ونوسازی دررهن میباشد .
A28: اسناد مالکِیت 4واحد از ویلاهای شرکت دربابلسر نز د بانک سپه شعبه سپهبد قرنی با بت بیست میلیارد تسهیلات بانکی دررهن میباشد .

Sheet 21
A1: شركت ساختماني گسترش و نوسازي صنايع ايرانیان مانا (سهامي خاص)
A2: يادداشتهاي توضيحي صورتهاي مالي
A3: دوره مالي شش ماهه منتهي به 31 خرداد ماه 1390
A5: 10-1 | B5: مانده حساب زمين درتاريخ ترازنامه متشکل ازاقلام زيرمی باشد: | D5: یاداشت | F5: 1390/3/31 | H5: 1389/9/30
F6: ريال | H6: ريال
B7: عرصه ساختمان دفترمرکزی شرکت به مساحت 560مترمربع | F7: 112000000 | H7: 112000000
B8: يک قطعه زمين به مساحت 2500مترمربع واقع درشهرک صنعتی طولادرجزيره قشم | D8: 10-1-1 | F8: 75000000 | H8: 75000000
B9: حق تقدیمی زمین تیربتنی | F9: 25012800 | H9: 25012800
B10: سه قطعه زمين 510متری جمعا"به مساحت 2550مترمربع واقع درکوی کيان آباد(کيانپارس)شهرستان اهواز | D10: 10-1-2 | F10: 864957382 | H10: 864957382
B11: عرصه چهار واحد ويلاهاي بابلسر جمعا به مساحت 1925/16 متر مربع واقع در شهرستان بابلسر | D11: 10-1-3 | F11: 8392969 | H11: 8392969
B12: یک قطعه زمین به مساحت 178431 متر مربع واقع در حصار امیر ورامین | D12: 10-1-4 | F12: 648141505 | H12: 648141505
F13: =SUM(F7:F12) -> 1733504656 | H13: =SUM(H7:H12) -> 1733504656
A15: 10-1-1 | B15: زمين قشم به مساحت2500مترمربع که درجزيره قشم-شهرک صنعتی طولاواقع است درسال1378ودرراستای تاسيس دفترنمايندگی درمنطقه آزاد قشم خريداری گردید .
B16: با انحلال نمايندگی مانا-قشم زمين مذکور در تملک شرکت باقی و تصميم گـيری در خصوص حفظ و انجام فعاليت های اجرائی ويا فروش آن بالحاظ داشتن صرفه و
B17: صلاح شرکت دردست اقدام می باشد.
A19: 10-1-2 | B19: از پنج قطعه زمين واقع در کيانپارس اهواز دو قطعه از آنها بر اساس نقشه جامع شهر اهواز در طرح احداث خیابان قرارگرفته که بر اساس نظر کارشناس رسمی دادگستری
B20: ارزش روز آن معادل 10،064،000،000 ریال برآورد گردیده است و شهرداری اهواز ملزم به اعطای معوض و یا پرداخت وجه آن گردیده و سه قطعه دیگر قبلا" مورد
B21: ادعای سازمان زمین شهری اهواز بوده که با توجه به فروش یک قطعه زمین در سال 85 ادعای سازمان مذکور عملا" مرتفع و احیاء سه قطعه زمین موجود براساس
B22: تقاضای پروانه ساخت در دست پیگیری قرار دارد.
A24: 10-1-3 | B24: عرصه چهار واحد ويلاي بابلسر جمعا به مساحت 1925/16 متر مربع واقع در مجتمع خزر كنار شهرستان بابلسر می باشد.
A26: 10-1-4 | B26: عرصه زمین حصار امیر ورامین به مساحت178431مترمربع معادل 21% سهم شرکت مانا اززمینهای مذکور می باشد که با توجه به توافق نامه مورخ 87/10/8 و وکالت نامه
B27: شماره 860909 مورخ 87/10/10 جهت اخذ سند تفکیکی در پایان سال 87 به حساب دارایی منظور گردیده است.
A29: 10-2 | B29: مانده حساب ساختمان درتاريخ ترازنامه متشکل از اقلام زیر می باشد: | F29: 1390/3/31 | H29: 1389/9/30
F30: ريال | H30: ريال
B31: ساختمان اداری،تولید،رستوران،مهمانسرا،انبارو محوطه تیربتنی | F31: 3985071284 | H31: 3985071284
B32: ساختمان 4 واحد ويلاي بابلسر | F32: 977642397 | H32: 977642397
B33: ساختمان دفترمرکزی شرکت | F33: 1117264446 | H33: 1117264446
F34: =SUM(F31:F33) -> 6079978127 | H34: =SUM(H31:H33) -> 6079978127
H39: .

Sheet 22
A1: شركت ساختماني گسترش و نوسازي صنايع ايرانیان مانا (سهامي خاص)
A2: يادداشتهاي توضيحي صورتهاي مالي
A3: دوره مالي شش ماهه منتهي به 31 خرداد ماه 1390
A6: 10-3 | B6: افزايش ماشين آلات وتجهيزات مربوط به اقلام زيرمی باشد: | E6: 1390/3/31 | G6: 1389/9/30
E7: ريال | G7: ريال
B8: خرید یک دستگاه ویبراتوربرقی هوندا | G8: 5100000
B9: خرید یک دستگاه کمپرسورباد 3سیلندربا پمپ باد | E9: 0 | G9: 7200000
B10: خرید یک دستگاه باگت بیل میکانیکی کاتر پیلار | E10: 0 | G10: 7000000
B11: خرید سه دستگاه ژنراتورپرکینز | E11: 0 | G11: 212550000
B12: خرید غلطک دستی چرخ آهنی | E12: 0 | G12: 89000000
B13: خرید یکدستگاه بچینگ لیبهر با میکسر 1/2 مترمکعبی | E13: 497000000 | G13: 0
B14: خرید یکدستگاه دامپر یکطرف تخلیه | E14: 44000000 | G14: 0
B15: خرید ویبراتور بنزینی روبین | E15: 28200000 | G15: 0
B16: خرید 9 دستگاه بتونیر | E16: 72500000 | G16: 0
B17: خرید یکدستگاه غلطک دستی چرخ آهنی | E17: 50000000 | G17: 0
B18: خرید 3 دستگاه کمپکتور | E18: 15600000 | G18: 0
B19: تعمیرات و افزایش دارایی | E19: 394273000 | G19: 20750000
B20: سابر | E20: 27560000 | G20: 3000000
E21: =SUM(E13:E20) -> 1129133000 | G21: =SUM(G8:G20) -> 344600000
A23: 10-4 | B23: افزايش اثاثه فنی مربوط به اقلام زيرمی باشد: | E23: 1390/3/31 | G23: 1389/9/30
E24: ريال | G24: ريال
B25: خرید دستگاه برش و خم کن برقی و قیچی آرماتور بری دستی و برقی | E25: 217859000 | G25: 265100000
B26: خرید هاون خشک کن | E26: 0 | G26: 5550000
B27: خرید دستگاه رکتی فایر و ترانس جوش | E27: 27310000 | G27: 147810000
B28: خريد منبع آب وسوخت و تاسیسات کامل شوفاژ خانه | E28: 53900000 | G28: 138720000
B29: خرید دوربین نقشه برداری تو تا ل استیشن و کلیه متعلقات | E29: 156950000 | G29: 179946725
B30: بابت خرید باکت بتن و چسب بتن | E30: 0 | G30: 8900000
B31: خرید کپسول هوا و گاز | E31: 11300000 | G31: 26320000
B32: خرید دریل بتن کن دریل هیلتی | E32: 36670000 | G32: 18430000
B33: خرید کارواش | E33: 0 | G33: 14350000
B34: خرید سیلوی 120 تنی | E34: 0 | G34: 80000000
B35: خرید انواع سنگ فرز و مینی فرز | E35: 6180000 | G35: 5500000
B36: خرید کمپرسور باد | E36: 0 | G36: 8500000
B37: خرید بالا بر برقی | E37: 8100000 | G37: 15000000
B38: خرید انواع پمپ و الکترو پمپ | E38: 18600000 | F38: . | G38: 13050000
B39: سایر | E39: 449535000 | G39: 219272820
E40: =SUM(E25:E39) -> 986404000 | G40: =SUM(G25:G39) -> 1146449545

Sheet 23
A1: شركت ساختماني گسترش و نوسازي صنايع ايرانیان مانا (سهامي خاص)
A2: يادداشتهاي توضيحي صورتهاي مالي
A3: دوره مالي شش ماهه منتهي به 31 خرداد ماه 1390
A5: 10-5 | B5: افزايش اثاثيه اداری مربوط به اقلام زيرمی باشد: | C5: 1390/3/31
C6: ريال
B7: خريد دستگاه کانکس و کانتینر | C7: 214500000
B8: خرید انواع مانیتور رنگی و کیس کامپیوتر و اسکنر و لوازم کا مپیوتری | C8: 439666632
B9: خرید انواع یخچال وتلویزیون و دوربین عکاسی ماشین حساب | C9: 23880000
B10: خرید دستگاه انواع بیسیم ، تلفن و تلفن همراه | C10: 18051533
B11: خرید انواع میز وصندلی فایل و کمد | C11: 371754539
B12: سایر | C12: 943616296
C13: =SUM(C7:C12) -> 2011469000
A15: 10-6 | B15: افزایش وسائط نقلیه در سال مالی مورد گزارش به قرار زیر است : | C15: 1390/3/31
C16: ريال
B17: خرید یکدستگاه پژو پارس خاکستری | C17: 205773000
B18: تعمیرات وسائط نقلیه افزایش دارایی | C18: 207171528
C19: =SUM(C17:C18) -> 412944528
C22: 1390/3/31
A23: 10-7 | B23: کاهش اثاثیه فنی در سال مالی مورد گزارش مربوط به اقلام زیراست: | C23: ريال
B24: فروش یکدستگاه سیلوی سیمان | C24: 100595000
C25: 0
C26: =SUM(C24:C25) -> 100595000
C29: 1390/3/31
A30: 10-8 | B30: کاهش اثاثیه اداری در سال مالی مورد گزارش مربوط به اقلام زیر است: | C30: ريال
B31: بابت برگشت یکدستگاه تلفن همراه | C31: 490000
B32: بابت برگشت 8 دستگاه بی سیم | C32: 9175000
C33: =SUM(C31:C32) -> 9665000

Sheet 24
A1: شركت ساختماني گسترش و نوسازي صنايع ايرانیان مانا (سهامي خاص)
A2: يادداشتهاي توضيحي صورتهاي مالي
A3: دوره مالي شش ماهه منتهي به 31 خرداد ماه 1390
N4: 1390/03/31 | P4: 1389/09/30
A5: 10-9 | B5: کاهش وسائط نقلیه در سال مالی مورد گزارش مربوط به اقلام زیر است: | N5: ريال | P5: ريال
B6: فروش یکدستگاه وانت | N6: 0 | P6: 814250
B7: فروش کفی تک محوره ودو محوره | N7: 0 | P7: 158618405
B8: فروش انواع سواری و مو تور سیکلت | N8: 0 | P8: 418783722
B9: فروش دو دستگاه تانکر بنز خاور | N9: 0 | P9: 8221410
B10: فروش دو دستگاه تراک میکسر | N10: 0 | P10: 432430409
B11: فروش سه دستگاه کمپرسی | N11: 0 | P11: 58181610
B12: فروش کامیون جرثقیلدار | N12: 0 | P12: 606037863
B13: فروش یکدستگاه پاجرواستیشن | N13: 21271636 | P13: 0
N14: =SUM(N13) -> 21271636 | P14: =SUM(P6:P13) -> 1683087669
N17: 1390/03/31 | P17: 1389/09/30
A18: 10-10 | B18: مانده حساب پیش پرداخت سرمایه ای مربوط به اقلام زیر است: | N18: ريال | P18: ريال
B19: پیش پرداخت سرمایه | N19: 0 | P19: 60000000
B20: بابت خرید دارائی ثابت | N20: 280000000 | P20: 763090720
N21: =SUM(N19:N20) -> 280000000 | P21: =SUM(P19:P20) -> 823090720
A23: جدول محاسبه سود(زیان)ناشی ازفروش داراییهای ثابت مشهود طی سال جاری براساس گروه داراییهای فروخته شده به شرح ذیل می باشد:
D24: 1390/03/31 | P24: 1389/09/30
A25: گروه دارایی ثابت | D25: بهای تمام شده | G25: استهلاک انباشته | J25: ارزش دفتری | L25: بهای فروش | N25: سود(زیان)فروش | P25: سود(زیان)فروش
D26: ریال | G26: ریال | J26: ریال | L26: ریال | N26: ریال | P26: ریال
A27: زمین | D27: 0 | G27: 0 | J27: =D27-G27 -> 0 | L27: 0 | N27: =L27-J27 -> 0 | P27: 60831384610
A28: ماشین آلات | D28: 0 | G28: 0 | J28: 0 | L28: 0 | N28: 0 | P28: 3028438748
A29: اثاثیه فنی | D29: 100595000 | G29: 95611558 | J29: =D29-G29 -> 4983442 | L29: 1043875 | N29: 78016558 | P29: 814454
A30: اثاثیه اداری | D30: 9665000 | G30: 2638839 | J30: =D30-G30 -> 7026161 | L30: 6934928 | N30: =L30-J30 -> -91233 | P30: -84146850
A31: وسائط نقلیه | D31: 21271636 | G31: 21154607 | J31: =D31-G31 -> 117029 | L31: 169000000 | N31: =L31-J31 -> 168882971 | P31: 2771124005
D32: =SUM(D27:D31) -> 131531636 | G32: =SUM(G27:G31) -> 119405004 | J32: =SUM(J27:J31) -> 12126632 | L32: =SUM(L27:L31) -> 176978803 | N32: =SUM(N27:N31) -> 246808296 | P32: =SUM(P27:P31) -> 66547614967
F36: .

Sheet 25
A1: شركت ساختماني گسترش و نوسازي صنايع ايرانیان مانا (سهامي خاص)
A2: يادداشتهاي توضيحي صورتهاي مالي
A3: دوره مالي شش ماهه منتهي به 31 خرداد ماه 1390
A5: -11 | B5: سرمايه گذاريهای بلندمدت
B6: سرمايه گذاريهای بلندمدت شامل موارد زيراست:
E7: يادداشت | G7: 1390/03/31 | I7: 1389/09/30
G8: ريال | I8: ريال
A9: سپرده های سرمايه گذاری بلندمدت | E9: 11-1 | G9: =G21 -> 3619500000 | I9: =I21 -> 1995000000
A10: سرمايه گذاريها درسهام شرکتها | E10: 11-2 | G10: =F36 -> 2866000000 | I10: =H36 -> 2166000000
G11: =SUM(G9:G10) -> 6485500000 | I11: =SUM(I9:I10) -> 4161000000
A14: 11-1 | B14: سپرده های سرمايه گذاری بلندمدت بانکی درتاريخ ترازنامه به شرح زيرتفکيک می گردد:
E16: يادداشت | G16: 1390/03/31 | I16: 1389/09/30
G17: ريال | I17: ريال
A18: بانک ملت ملک الشعرا | E18: 11-1-1 | G18: 600000000 | I18: 600000000
A19: بانک ملی جم | E19: 11-1-1 | G19: 120000000 | I19: 120000000
A20: بانک پاسارگاد سلیمان خاطر | G20: 2899500000 | I20: 1275000000
G21: =SUM(G18:G20) -> 3619500000 | I21: =SUM(I18:I20) -> 1995000000
A24: -11-1-1 | B24: نرخ سود تضمين شده سپرده های فوق برای سال جاری براساس قانون عمليات بانکی بدون ربا به ميزان 17درصد تعيين شده است .
A25: مبلغ 715،009،234ريال ازسپرده های ياد شده به منظورصدورضمانت نامه های بانکی به نفع کارفرمايان وثيقه شده است.
A27: 11-2 | B27: سرمايه گذاری درسهام شرکتها به شرح زيرمی باشد:
C28: 1390 | H28: 1389/09/30
C29: تعدادسهام | D29: درصدسرمايه گذاری | E29: ارزش اسمی | F29: بهای تمام شده | H29: بهای تمام شده
E30: ريال | F30: ريال | H30: ريال
A31: شرکت تعاونی شرکت های ساختمانی | C31: 2 | D31: 0.002 | E31: 500000 | F31: =E31*C31 -> 1000000 | H31: 1000000
A32: شرکت بیمه اتکائی ایرانیان | C32: 1750000 | D32: 0.23 | E32: 1000 | F32: =E32*C32 -> 1750000000 | H32: 1750000000
A33: شرکت تضمین شرکتهای ساختمانی | C33: 5000 | D33: 0 | E33: 1000 | F33: =E33*C33 -> 5000000 | H33: 5000000
A34: شرکت ساخت و نصب صنایع بتنی و فلزی | C34: 10000 | D34: 100 | E34: 1000 | F34: =E34*C34 -> 10000000 | H34: 10000000
A35: شرکت فروسیلیس غرب پارس | C35: 1100000 | E35: 1000 | F35: =E35*C35 -> 1100000000 | H35: 400000000
A36: جمع | F36: =SUM(F31:G35) -> 2866000000 | H36: =SUM(H31:I35) -> 2166000000
A38: -11-2-1 | B38: باتوجه به عدم کاهش دائمی درارزش سرمايه گذاری ، ذخيره ای منظورنگرديده است.

Sheet 26
A1: شركت ساختماني گسترش و نوسازي صنايع ايرانیان مانا (سهامي خاص)
A2: يادداشتهاي توضيحي صورتهاي مالي
A3: دوره مالي شش ماهه منتهي به 31 خرداد ماه 1390
A5: -12 | B5: داراييهای نامشهود
B7: داراييهای نامشهود درتاريخ ترازنامه ازاقلام زيرمی باشد: | F7: 1390/03/31 | H7: 1389/09/30
F8: ريال | H8: ريال
B9: حق کاربری اداری ساختمان دفترمرکزی | F9: 343440000 | H9: 343440000
B10: وديعه بیست وشش خط تلفن همراه | F10: 124662000 | H10: 124662000
B11: وديعه شصت و پنج خط تلفن ثابت | F11: 88482852 | H11: 86937852
B12: وديعه برق ،آب وگاز | F12: 53508000 | H12: 1728000
F13: =SUM(F9:F12) -> 610092852 | H13: =SUM(H9:H12) -> 556767852
B15: تغییرات دارائی های نامشهود مربوط به اقلام زیر است: | F15: 1390/03/31 | H15: 1389/09/30
F16: ريال | H16: ريال
B17: واگذاری یک خط تلفن همراه | F17: - | H17: 9318500
B18: پرداخت ودیعه آب | F18: 51780000 | H18: -
B19: پرداخت ودیعه خط ثابت | F19: 1545000 | H19: -
F20: =SUM(F17:F19) -> 53325000 | H20: =SUM(H17:H17) -> 9318500
F39: .

Sheet 27
A1: شركت ساختماني گسترش و نوسازي صنايع ايرانیان مانا (سهامي خاص)
A2: يادداشتهاي توضيحي صورتهاي مالي
A3: دوره مالي شش ماهه منتهي به 31 خرداد ماه 1390
A5: -13 | B5: حسابها واسناد پرداختنی تجاري
B6: حسابها واسناد پرداختنی تجاری از اقلام زيرتشکيل شده است:
B7: شرح | C7: يادداشت | E7: 1390/03/31 | G7: 1389/09/30
E8: ريال | G8: ريال
B9: پيمانکاران | C9: 13-1 | E9: ='27'!E40 -> 52180622554 | G9: =G40 -> 63149452253
B10: کار فرمايان | C10: 13-2 | E10: ='28'!C14 -> 57285533700 | G10: ='28'!E14 -> 42659935390
B11: مشارکت ها | E11: 3609640205 | G11: 5016232088
B12: سايراشخاص(فروشندگان) | C12: 13-3 | E12: ='28'!C39 -> 7623725378 | G12: ='28'!E39 -> 9337790898
B13: جمع | E13: =SUM(E9:E12) -> 120699521837 | G13: =SUM(G9:G12) -> 120163410629
A15: 13-1 | B15: مانده حساب پيمانکاران به شرح زيرمی باشد:
E16: 1390/03/31 | G16: 1389/09/30
E17: ريال | G17: ريال
A18: شرکت نورث ایست کانسترکشن-mcc(چینی) | E18: 0 | G18: 37397054472
A19: گروه اجرايی اسفراين | E19: 8771624880 | G19: 8771624880
A20: شرکت سازه فلز پایدار | E20: 0 | G20: 2161261762
A21: پیمانکاران آند رادینگ | E21: 355265118 | G21: 0
A22: گروه اجرايی آمل -پروژه ديزل سنگين آمل | E22: 0 | G22: 443884256
A23: گروه اجرايی صنایع فولادکرمان | E23: 510942648 | G23: 510942648
A24: شرکت مشيران -پروژه بندرچندمنظوره فريدونکنار | E24: 0 | G24: 443750000
A25: سهیل اسلامی سامانی | E25: 0 | G25: 826495000
A26: ضرغام بری | E26: 281276462 | G26: 281276462
A27: شرکت حفار تزریق | E27: 0 | G27: 245289557
A28: شرکت ابنیه صنعت هکمتانه | E28: 0 | G28: 1705425524
A29: شرکت فاران | E29: 0 | G29: 552499330
... A39: سایر | E39: 7698053497 | G39: 6631705822
A40: جمع : | E40: =SUM(E18:E39) -> 52180622554 | G40: =SUM(G18:G39) -> 63149452253

Sheet 28
A1: شركت ساختماني گسترش و نوسازي صنايع ايرانیان مانا (سهامي خاص)
A2: يادداشتهاي توضيحي صورتهاي مالي
A3: دوره مالي شش ماهه منتهي به 31 خرداد ماه 1390
A5: 13-2 | B5: مانده حساب کارفرمایان به شرح زيرمی باشد:
C6: 1390/03/31 | E6: 1389/09/30
C7: ريال | E7: ريال
B8: شرکت آلومینیوم سازی اراک - ایرالکو | C8: 12216671993 | E8: 7978730359
B9: شرکت احداث صنعت | C9: 4287150609 | E9: 4287150609
B10: پیمان مدیریت - شرکت موننکو | C10: 28102472911 | E10: 12920570216
B11: شرکت سرمایه گذاری ساختمان سپه | C11: 0 | E11: 11372087760
B12: ساختمان مرکزی وزارت نیرو | C12: 5558739655 | E12: 4351810912
B13: سایر | C13: 7120498532 | E13: 1749585534
B14: جمع | C14: =SUM(C8:C13) -> 57285533700 | E14: =SUM(E8:E13) -> 42659935390
A16: 13-3 | B16: مانده حساب سايراشخاص (فروشندگان) ازاقلام زيرتشکيل شده است:
C17: 1390/03/31 | E17: 1389/09/30
C18: ريال | E18: ريال
B19: دات کام شرق | C19: 0 | E19: 194285000
B20: پیمانکاری بوالحسنی | C20: 0 | E20: 124415164
B21: شرکت تچدا بتن | C21: 0 | E21: 466663831
B22: آهن آلات تهران فام | C22: 0 | E22: 265098000
B23: شرکت شن وماسه شازند | C23: 0 | E23: 211417072
B24: شرکت امیدایرانیان باستان | C24: 0 | E24: 471345140
B25: فروشگاه توانا | C25: 0 | E25: 293988000
B26: مانده اقلام بستانکار بانک صادرات | C26: 0 | E26: 546534790
B27: کارگاه تولید بتن آماده باقری | C27: 0 | E27: 215681400
B28: فروشندگان دفتر مرکزی | C28: 1315894420 | E28: 0
B29: شرکت تعاونی حمل جنوب شرق | C29: 0 | E29: 649122000
B30: سنگ بعثت | C30: 0 | E30: 167563000
... B38: سایر | C38: 2223922182 | E38: 4158257197
B39: جمع : | C39: =SUM(C19:C38) -> 7623725378 | E39: =SUM(E19:E38) -> 9337790898 | F39: .

Sheet 29
A1: شركت ساختماني گسترش و نوسازي صنايع ايرانیان مانا(سهامي خاص)
A2: يادداشتهاي توضيحي صورتهاي مالي
A3: دوره مالي شش ماهه منتهي به 31 خرداد ماه 1390
A5: 14- ساير حسابهاي پرداختني
B6: ساير حسابهاي پرداختني از اقلام زير تشكيل شده است:
E7: يادداشت | F7: 1390/03/31 | H7: 1389/09/30
F8: ريال | H8: ريال
B10: مالياتهاي حقوق و تكليفي | F10: 9935333627 | H10: 8462463613
B11: حق بيمه هاي پرداختني | E11: 1_14 | F11: =F26 -> 12845066898 | H11: =H26 -> 10754254534
B12: سپرده حسن انجام كار | E12: 2_14 | F12: ='30'!D29 -> 15201466814 | H12: ='30'!F29 -> 14495874862
B13: ذخيره هزينه هاي تعلق گرفته و پرداخت نشده | F13: 0 | H13: 416000000
B14: متفرقه | E14: 3_14 | F14: ='31'!F33 -> 110513397443 | H14: ='31'!H33 -> 52544202319
B15: سپرده بیمه | E15: 4_14 | F15: ='31'!F46 -> 3088978342 | H15: ='31'!H46 -> 2301220550
F16: =SUM(F10:F15) -> 151584243124 | H16: =SUM(H10:H15) -> 88974015878
A18: 14-1- حق بيمه هاي پرداختني متشكل از اقلام زير مي باشد:
E20: يادداشت | F20: 1390/03/31 | H20: 1389/09/30
F21: ريال | H21: ريال
B22: حق بيمه طرحهاي غير عمراني | E22: 14-1-1 | F22: =F36 -> 8419078814 | H22: =H36 -> 8419078814
B23: سازمان تامين اجتماعي-بيمه مكسوره از كاركنان | F23: 4346946004 | H23: 2290771661
B24: حق بیمه صندوق آینده ساز | F24: 63233310 | H24: 44404059
B25: سایر | F25: 15808770 | H25: 0
F26: =SUM(F22:F25) -> 12845066898 | H26: =SUM(H22:H24) -> 10754254534
A28: 14-1-1-مانده حق بيمه طرحهاي غير عمراني بشرح زير مي باشد:
F29: 1390/03/31 | H29: 1389/09/30
F30: ريال | H30: ريال
B31: سازمان تامين اجتماعي -پتروشيمي ماهشهر | F31: 2577047478 | H31: 2577047478
B32: سازمان تامين اجتماعي- دفتر مطالعات سیاسی | F32: 287873995 | H32: 287873995
B33: سازمان تامين اجتماعي-ساختمان جام جم | F33: 152330340 | H33: 152330340
B34: سازمان تامين اجتماعي- آلومینیوم سازی اراک | F34: 5256508451 | H34: 5256508451
B35: سازمان تامين اجتماعي- پارکینگ نمایشگاه | F35: 145318550 | H35: 145318550
F36: =SUM(F31:F35) -> 8419078814 | H36: =SUM(H31:H35) -> 8419078814

Sheet 30
A1: شركت ساختماني گسترش و نوسازي صنايع ايرانیان مانا(سهامي خاص)
A2: يادداشتهاي توضيحي صورتهاي مالي
A3: دوره مالي شش ماهه منتهي به 31 خرداد ماه 1390
A5: 14-2- سر فصل سپرده حسن انجام كار پرداختني به قرار زير است:
D6: 1390/03/31 | F6: 1389/09/30
D7: ريال | F7: ريال
B8: کارگاه آلومینیوم اراک | D8: 1092090825 | F8: 1003314007
B9: شركت خدمات مهندسي حفار تزريق | D9: 0 | F9: 247714100
B10: طرح میدان شهدائ مشهد | D10: 58726262 | F10: 327173117
B11: سالن ورزشی شیراز | D11: 306488372 | F11: 462519723
B12: سرمایه گذاری ساختمانی سپه | D12: 2533920902 | F12: 2580274793
B13: احداث کارخانه کک سازی زرند | D13: 1067864629 | F13: 618091210
B14: سپرده حسن انجام کار موننکو | D14: 17102514 | F14: 382740768
B15: سعید مختاری مقدم | D15: 44264572 | F15: 44264572
B16: غلامعلی کاردگر | D16: 24984997 | F16: 24984997
B17: محمد رضا ترابی مقدم | D17: 31770458 | F17: 31770458
B18: مشارکت فام _ پروژه سیویل کنسانتره جلال آباد | D18: 659598925 | F18: 701935632
B19: پیمان مدیریت پروژه موننکو | D19: 1452121045 | F19: 444539648
... B28: ساير | D28: 1841676987 | F28: 1876396756
D29: =SUM(D8:D28) -> 15201466814 | F29: =SUM(F8:F28) -> 14495874862

Sheet 31
A1: شركت ساختماني گسترش و نوسازي صنايع ايرانیان مانا (سهامي خاص)
A2: يادداشتهاي توضيحي صورتهاي مالي
A3: دوره مالي شش ماهه منتهي به 31 خرداد ماه 1390
A5: 14-3-سر فصل متفرقه در حسابهای پرداختنی به قرار زير مي باشد:
C6: يادداشت | F6: 1390/03/31 | H6: 1389/09/30
F7: ريال | H7: ريال
A8: بستانکاران موقت | F8: 0 | H8: 4766040230
A9: 35متری بلوارمعلم _شهرداری منطقه 18 | F9: 0 | H9: 458667405
A10: شرکت تکنیکان | F10: 0 | H10: 625000000
A11: کارگاه بانک صادرات استان خراسان رضوی | F11: 0 | H11: 717343793
A12: سالن ورزشی شیراز | F12: 0 | H12: 663901206
A13: کارگاه آنودرادینگ-ایرالکو | F13: 0 | H13: 236430551
A14: حقوق ودستمزد پرداختنی | F14: 2513830170 | H14: 6281075260
A15: کارگاه مدیریت طرح واجرای خانه سازی ایران | F15: 0 | H15: 5151131489
A16: کارگاه احداث کارخانه کک سازی زرند | F16: 0 | H16: 1906742747
A17: تسهیلات خرید دین آینده ساز | F17: 0 | H17: 16337664
A18: شرکت سیمان داراب | F18: 0 | H18: 250000000
A19: ساختمان مرکزی وزارت نیرو | F19: 0 | H19: 26826171
... A32: سایر | F32: 2374087496 | H32: 8689733583
A33: جمع | F33: =SUM(F8:F32) -> 110513397443 | H33: =SUM(H8:H32) -> 52544202319
A35: 4-4 1- سر فصل سپرده بیمه در حسابهای پرداختنی به قرار زير مي باشد:
F36: 1390/03/31 | H36: 1389/09/30
F37: ريال | H37: ريال
A38: کارگاه تصفيه آب شرب مشهد | F38: 477127281 | H38: 469855464
A39: مهندسين مشاور کاوشگران | F39: . | H39: 107500000
A40: سپرده بيمه انتقالي از کارگاه تويو | F40: 0 | H40: 206198750
A41: کارگاه سرمايه گذاري ساختماني سپه - اميد 2 | F41: 1096895572 | H41: 1096895572
