Workbook

Sheet ALL
A1: We try to maintain the basic structure of the existing layout with minimum revisions. It is a unified layout for OAA, OGT, AASWD, and OTELA. So the file contains multiple sheets. Pay special attention to the following: 1. Position 32, Assessment Type, we keep the current coding, but OTELA is coded E for English instead of R for regular. 2. For OTELA, Production Performance Level is reported in position 342-244; Production Scaled Score is reported in position 346-348. This is the only revision compared to the layout used in School Year 2010. 3. On the total scaled score columns, besides the current codes of INV, DNA, we add TOG (test out of grade other than accelerated testing) and DNS (answer document was marked as "Do Not Score". 4. For AASWD, starting with Spring 2013, scaled scores will be reported; raw scores will not be reported.
A2: Start | B2: End | C2: Length | D2: Description | E2: Type | F2: OAT | G2: OGT | H2: AASWD | I2: OTELA
A3: 1 | B3: 11 | C3: 11 | D3: STUDENT-NAME-LAST | E3: alpha or blank
A4: 12 | B4: 19 | C4: 8 | D4: STUDENT-NAME-FIRST | E4: alpha or blank
A5: 20 | B5: 20 | C5: 1 | D5: STUDENT-NAME-MI | E5: alpha or blank
A6: 21 | B6: 29 | C6: 9 | D6: District Student ID (DSID) | E6: alphanumeric or blank
A7: 30 | B7: 31 | C7: 2 | D7: Exam Grade | E7: alphanumeric | F7: 03, 04, 05, 06, 07, 08 | G7: GR | H7: 03, 04, 05, 06, 07, 08, GR | I7: K2 (K through 2), 35 (3 through 5), 68 (6 through 8), 92 (9 through 12)
A8: 32 | B8: 32 | C8: 1 | D8: Assessment Type | E8: alpha | F8: R | G8: R | H8: A | I8: E
A9: 33 | B9: 37 | C9: 5 | D9: filler
A10: 38 | B10: 39 | C10: 2 | D10: Birth Month | E10: numeric or blank | F10: 01, 02,..., 12 | G10: Same As OAT | H10: Same As OAT | I10: Same As OAT
A11: 40 | B11: 41 | C11: 2 | D11: Birth Day | E11: numeric or blank | F11: 01, 02,..., 31 | G11: Same As OAT | H11: Same As OAT | I11: Same As OAT
A12: 42 | B12: 45 | C12: 4 | D12: Birth Year | E12: numeric or blank | F12: CCYY Format | G12: Same As OAT | H12: Same As OAT | I12: Same As OAT
A13: 46 | B13: 47 | C13: 2 | D13: Enrolled Grade | E13: numeric or blank | F13: 22=Kindergarten, 01, 02, …. 13=Adult HS, 14=OGT Only, blank=missing/unknown | G13: Same As OAT | H13: Same As OAT | I13: Same As OAT
A14: 48 | B14: 48 | C14: 1 | D14: Gender | E14: alpha or blank | F14: F=Female | G14: Same As OAT | H14: Same As OAT | I14: Same As OAT
F15: M=Male | G15: Same As OAT | H15: Same As OAT | I15: Same As OAT
F16: blank=unknown | G16: Same As OAT | H16: Same As OAT | I16: Same As OAT
A17: 49 | B17: 49 | C17: 1 | D17: Ethnicity | E17: numeric or blank | F17: 1=American Indian | G17: Same As OAT | H17: Same As OAT | I17: Same As OAT
F18: 2=Asian/Pacific Islander | G18: Same As OAT | H18: Same As OAT | I18: Same As OAT
F19: 3=Black/African American | G19: Same As OAT | H19: Same As OAT | I19: Same As OAT
F20: 4=Hispanic | G20: Same As OAT | H20: Same As OAT | I20: Same As OAT
F21: 5=White | G21: Same As OAT | H21: Same As OAT | I21: Same As OAT
F22: 6=Multi-Racial | G22: Same As OAT | H22: Same As OAT | I22: Same As OAT
F23: 7=Other | G23: Same As OAT | H23: Same As OAT | I23: Same As OAT
F24: Blank=Unknown | G24: Same As OAT | H24: Same As OAT | I24: Same As OAT
A25: 50 | B25: 58 | C25: 9 | D25: filler
A26: 59 | B26: 78 | C26: 20 | D26: Attending District Name | E26: alpha
A27: 79 | B27: 84 | C27: 6 | D27: Attending District IRN | E27: numeric
A28: 85 | B28: 104 | C28: 20 | D28: Attending School Name | E28: alpha
A29: 105 | B29: 110 | C29: 6 | D29: Attending School IRN | E29: numeric
A30: 111 | B30: 112 | C30: 2 | D30: Test Month | E30: numeric | F30: MM | G30: Same As OAT | H30: Same As OAT | I30: Same As OAT
A31: 113 | B31: 114 | C31: 2 | D31: Test Day | E31: numeric or blank | F31: DD | G31: Same As OAT | H31: Same As OAT | I31: Same As OAT
A32: 115 | B32: 118 | C32: 4 | D32: Test Year | E32: numeric | F32: CCYY format | G32: Same As OAT | H32: Same As OAT | I32: Same As OAT
A33: 119 | B33: 123 | C33: 5 | D33: Homeroom ID | E33: alphanumeric or blank | H33: Same As OAT | I33: Same As OAT
A34: 124 | B34: 125 | C34: 2 | D34: filler
A35: 126 | B35: 126 | C35: 1 | D35: Migrant Student | E35: alpha or blank | F35: Y=Yes | G35: Same As OAT | H35: Same As OAT | I35: Same As OAT
F36: Blank=Not Indicated | G36: Same As OAT | H36: Same As OAT | I36: Same As OAT
A37: 127 | B37: 127 | C37: 1 | D37: IEP-Writing | E37: alpha or blank | F37: Y=Yes | G37: Same As OAT | H37: Same As OAT | I37: Same As OAT
F38: Blank=Not Indicated | G38: Same As OAT | H38: Same As OAT | I38: Same As OAT
A39: 128 | B39: 128 | C39: 1 | D39: IEP-Reading | E39: alpha or blank | F39: Y=Yes | G39: Same As OAT | H39: Same As OAT | I39: Same As OAT
F40: Blank=Not Indicated | G40: Same As OAT | H40: Same As OAT | I40: Same As OAT
...

Sheet OAA
A1: Start | B1: End | C1: Length | D1: Description | E1: Type | F1: OAT
A2: 1 | B2: 11 | C2: 11 | D2: STUDENT-NAME-LAST | E2: alpha or blank
A3: 12 | B3: 19 | C3: 8 | D3: STUDENT-NAME-FIRST | E3: alpha or blank
A4: 20 | B4: 20 | C4: 1 | D4: STUDENT-NAME-MI | E4: alpha or blank
A5: 21 | B5: 29 | C5: 9 | D5: District Student ID (DSID) | E5: alphanumeric or blank
A6: 30 | B6: 31 | C6: 2 | D6: Exam Grade | E6: alphanumeric | F6: 03, 04, 05, 06, 07, 08
A7: 32 | B7: 32 | C7: 1 | D7: Assessment Type | E7: alpha | F7: R
A8: 33 | B8: 37 | C8: 5 | D8: filler
A9: 38 | B9: 39 | C9: 2 | D9: Birth Month | E9: numeric or blank | F9: 01, 02,..., 12
A10: 40 | B10: 41 | C10: 2 | D10: Birth Day | E10: numeric or blank | F10: 01, 02,..., 31
A11: 42 | B11: 45 | C11: 4 | D11: Birth Year | E11: numeric or blank | F11: CCYY Format
A12: 46 | B12: 47 | C12: 2 | D12: Enrolled Grade | E12: numeric or blank | F12: 22=Kindergarten, 01, 02, …. 13=Adult HS, 14=OGT Only, blank=missing/unknown
A13: 48 | B13: 48 | C13: 1 | D13: Gender | E13: alpha or blank | F13: F=Female
F14: M=Male
F15: blank=unknown
A16: 49 | B16: 49 | C16: 1 | D16: Ethnicity | E16: numeric or blank | F16: 1=American Indian
F17: 2=Asian/Pacific Islander
F18: 3=Black/African American
F19: 4=Hispanic
F20: 5=White
F21: 6=Multi-Racial
F22: 7=Other
F23: Blank=Unknown
A24: 50 | B24: 58 | C24: 9 | D24: filler
A25: 59 | B25: 78 | C25: 20 | D25: Attending District Name | E25: alpha
A26: 79 | B26: 84 | C26: 6 | D26: Attending District IRN | E26: numeric
A27: 85 | B27: 104 | C27: 20 | D27: Attending School Name | E27: alpha
A28: 105 | B28: 110 | C28: 6 | D28: Attending School IRN | E28: numeric
A29: 111 | B29: 112 | C29: 2 | D29: Test Month | E29: numeric | F29: MM
A30: 113 | B30: 114 | C30: 2 | D30: Test Day | E30: numeric or blank | F30: DD
A31: 115 | B31: 118 | C31: 4 | D31: Test Year | E31: numeric | F31: CCYY format
A32: 119 | B32: 123 | C32: 5 | D32: Homeroom ID | E32: alphanumeric or blank
A33: 124 | B33: 125 | C33: 2 | D33: filler
A34: 126 | B34: 126 | C34: 1 | D34: Migrant Student | E34: alpha or blank | F34: Y=Yes
F35: Blank=Not Indicated
A36: 127 | B36: 127 | C36: 1 | D36: IEP-Writing | E36: alpha or blank | F36: Y=Yes
F37: Blank=Not Indicated
A38: 128 | B38: 128 | C38: 1 | D38: IEP-Reading | E38: alpha or blank | F38: Y=Yes
F39: Blank=Not Indicated
A40: 129 | B40: 129 | C40: 1 | D40: IEP-Mathematics (Listening for OTELA/ELDA) | E40: alpha or blank | F40: Y=Yes
...

Sheet OGT
A1: Start | B1: End | C1: Length | D1: Description | E1: Type | F1: OGT
A2: 1 | B2: 11 | C2: 11 | D2: STUDENT-NAME-LAST | E2: alpha or blank
A3: 12 | B3: 19 | C3: 8 | D3: STUDENT-NAME-FIRST | E3: alpha or blank
A4: 20 | B4: 20 | C4: 1 | D4: STUDENT-NAME-MI | E4: alpha or blank
A5: 21 | B5: 29 | C5: 9 | D5: District Student ID (DSID) | E5: alphanumeric or blank
A6: 30 | B6: 31 | C6: 2 | D6: Exam Grade | E6: alphanumeric | F6: GR
A7: 32 | B7: 32 | C7: 1 | D7: Assessment Type | E7: alpha | F7: R
A8: 33 | B8: 37 | C8: 5 | D8: filler
A9: 38 | B9: 39 | C9: 2 | D9: Birth Month | E9: numeric or blank | F9: =OAA!F9 -> 01, 02,..., 12
A10: 40 | B10: 41 | C10: 2 | D10: Birth Day | E10: numeric or blank | F10: =OAA!F10 -> 01, 02,..., 31
A11: 42 | B11: 45 | C11: 4 | D11: Birth Year | E11: numeric or blank | F11: =OAA!F11 -> CCYY Format
A12: 46 | B12: 47 | C12: 2 | D12: Enrolled Grade | E12: numeric or blank | F12: =OAA!F12 -> 22=Kindergarten, 01, 02, …. 13=Adult HS, 14=OGT Only, blank=missing/unknown
A13: 48 | B13: 48 | C13: 1 | D13: Gender | E13: alpha or blank | F13: =OAA!F13 -> F=Female
F14: =OAA!F14 -> M=Male
F15: =OAA!F15 -> blank=unknown
A16: 49 | B16: 49 | C16: 1 | D16: Ethnicity | E16: numeric or blank | F16: =OAA!F16 -> 1=American Indian
F17: =OAA!F17 -> 2=Asian/Pacific Islander
F18: =OAA!F18 -> 3=Black/African American
F19: =OAA!F19 -> 4=Hispanic
F20: =OAA!F20 -> 5=White
F21: =OAA!F21 -> 6=Multi-Racial
F22: =OAA!F22 -> 7=Other
F23: =OAA!F23 -> Blank=Unknown
A24: 50 | B24: 58 | C24: 9 | D24: filler
A25: 59 | B25: 78 | C25: 20 | D25: Attending District Name | E25: alpha
A26: 79 | B26: 84 | C26: 6 | D26: Attending District IRN | E26: numeric
A27: 85 | B27: 104 | C27: 20 | D27: Attending School Name | E27: alpha
A28: 105 | B28: 110 | C28: 6 | D28: Attending School IRN | E28: numeric
A29: 111 | B29: 112 | C29: 2 | D29: Test Month | E29: numeric | F29: =OAA!F29 -> MM
A30: 113 | B30: 114 | C30: 2 | D30: Test Day | E30: numeric or blank | F30: =OAA!F30 -> DD
A31: 115 | B31: 118 | C31: 4 | D31: Test Year | E31: numeric | F31: =OAA!F31 -> CCYY format
A32: 119 | B32: 123 | C32: 5 | D32: Homeroom ID | E32: alphanumeric or blank
A33: 124 | B33: 125 | C33: 2 | D33: filler
A34: 126 | B34: 126 | C34: 1 | D34: Migrant Student | E34: alpha or blank | F34: =OAA!F34 -> Y=Yes
F35: =OAA!F35 -> Blank=Not Indicated
A36: 127 | B36: 127 | C36: 1 | D36: IEP-Writing | E36: alpha or blank | F36: =OAA!F36 -> Y=Yes
F37: =OAA!F37 -> Blank=Not Indicated
A38: 128 | B38: 128 | C38: 1 | D38: IEP-Reading | E38: alpha or blank | F38: =OAA!F38 -> Y=Yes
F39: =OAA!F39 -> Blank=Not Indicated
A40: 129 | B40: 129 | C40: 1 | D40: IEP-Mathematics (Listening for OTELA/ELDA) | E40: alpha or blank | F40: =OAA!F40 -> Y=Yes
...

Sheet AASWD
A1: We try to maintain the basic structure of the existing layout with minimum revisions. It is a unified layout for OAA, OGT, AASWD, and OTELA. So the file contains multiple sheets. Pay special attention to the following: 1. For AASWD, starting with Spring 2013, scaled scores will be reported; raw scores will not be reported.
A2: Start | B2: End | C2: Length | D2: Description | E2: Type | F2: AASWD
A3: 1 | B3: 11 | C3: 11 | D3: STUDENT-NAME-LAST | E3: alpha or blank
A4: 12 | B4: 19 | C4: 8 | D4: STUDENT-NAME-FIRST | E4: alpha or blank
A5: 20 | B5: 20 | C5: 1 | D5: STUDENT-NAME-MI | E5: alpha or blank
A6: 21 | B6: 29 | C6: 9 | D6: District Student ID (DSID) | E6: alphanumeric or blank
A7: 30 | B7: 31 | C7: 2 | D7: Exam Grade | E7: alphanumeric | F7: 03, 04, 05, 06, 07, 08, GR
A8: 32 | B8: 32 | C8: 1 | D8: Assessment Type | E8: alpha | F8: A
A9: 33 | B9: 37 | C9: 5 | D9: filler
A10: 38 | B10: 39 | C10: 2 | D10: Birth Month | E10: numeric or blank | F10: =OAA!F9 -> 01, 02,..., 12
A11: 40 | B11: 41 | C11: 2 | D11: Birth Day | E11: numeric or blank | F11: =OAA!F10 -> 01, 02,..., 31
A12: 42 | B12: 45 | C12: 4 | D12: Birth Year | E12: numeric or blank | F12: =OAA!F11 -> CCYY Format
A13: 46 | B13: 47 | C13: 2 | D13: Enrolled Grade | E13: numeric or blank | F13: =OAA!F12 -> 22=Kindergarten, 01, 02, …. 13=Adult HS, 14=OGT Only, blank=missing/unknown
A14: 48 | B14: 48 | C14: 1 | D14: Gender | E14: alpha or blank | F14: =OAA!F13 -> F=Female
F15: =OAA!F14 -> M=Male
F16: =OAA!F15 -> blank=unknown
A17: 49 | B17: 49 | C17: 1 | D17: Ethnicity | E17: numeric or blank | F17: =OAA!F16 -> 1=American Indian
F18: =OAA!F17 -> 2=Asian/Pacific Islander
F19: =OAA!F18 -> 3=Black/African American
F20: =OAA!F19 -> 4=Hispanic
F21: =OAA!F20 -> 5=White
F22: =OAA!F21 -> 6=Multi-Racial
F23: =OAA!F22 -> 7=Other
F24: =OAA!F23 -> Blank=Unknown
A25: 50 | B25: 58 | C25: 9 | D25: filler
A26: 59 | B26: 78 | C26: 20 | D26: Attending District Name | E26: alpha
A27: 79 | B27: 84 | C27: 6 | D27: Attending District IRN | E27: numeric
A28: 85 | B28: 104 | C28: 20 | D28: Attending School Name | E28: alpha
A29: 105 | B29: 110 | C29: 6 | D29: Attending School IRN | E29: numeric
A30: 111 | B30: 112 | C30: 2 | D30: Test Month | E30: numeric | F30: =OAA!F29 -> MM
A31: 113 | B31: 114 | C31: 2 | D31: Test Day | E31: numeric or blank | F31: =OAA!F30 -> DD
A32: 115 | B32: 118 | C32: 4 | D32: Test Year | E32: numeric | F32: =OAA!F31 -> CCYY format
A33: 119 | B33: 123 | C33: 5 | D33: Homeroom ID | E33: alphanumeric or blank
A34: 124 | B34: 125 | C34: 2 | D34: filler
A35: 126 | B35: 126 | C35: 1 | D35: Migrant Student | E35: alpha or blank | F35: =OAA!F34 -> Y=Yes
F36: =OAA!F35 -> Blank=Not Indicated
A37: 127 | B37: 127 | C37: 1 | D37: IEP-Writing | E37: alpha or blank | F37: =OAA!F36 -> Y=Yes
F38: =OAA!F37 -> Blank=Not Indicated
A39: 128 | B39: 128 | C39: 1 | D39: IEP-Reading | E39: alpha or blank | F39: =OAA!F38 -> Y=Yes
F40: =OAA!F39 -> Blank=Not Indicated
...

Sheet OTELA
A1: We try to maintain the basic structure of the existing layout with minimum revisions. It is a unified layout for OAA, OGT, AASWD, and OTELA. So the file contains multiple sheets. Pay special attention to the following: 1. Position 32, Assessment Type, we keep the current coding, but OTELA is coded E for English instead of R for regular. 2. For OTELA, Production Performance Level is reported in position 342-244; Production Scaled Score is reported in position 346-348. This is the only revision compared to the layout used in School Year 2010.
A2: Start | B2: End | C2: Length | D2: Description | E2: Type | F2: OTELA
A3: 1 | B3: 11 | C3: 11 | D3: STUDENT-NAME-LAST | E3: alpha or blank
A4: 12 | B4: 19 | C4: 8 | D4: STUDENT-NAME-FIRST | E4: alpha or blank
A5: 20 | B5: 20 | C5: 1 | D5: STUDENT-NAME-MI | E5: alpha or blank
A6: 21 | B6: 29 | C6: 9 | D6: District Student ID (DSID) | E6: alphanumeric or blank
A7: 30 | B7: 31 | C7: 2 | D7: Exam Grade | E7: alphanumeric | F7: K2 (K through 2), 35 (3 through 5), 68 (6 through 8), 92 (9 through 12)
A8: 32 | B8: 32 | C8: 1 | D8: Assessment Type | E8: alpha | F8: E
A9: 33 | B9: 37 | C9: 5 | D9: filler
A10: 38 | B10: 39 | C10: 2 | D10: Birth Month | E10: numeric or blank | F10: =OAA!F9 -> 01, 02,..., 12
A11: 40 | B11: 41 | C11: 2 | D11: Birth Day | E11: numeric or blank | F11: =OAA!F10 -> 01, 02,..., 31
A12: 42 | B12: 45 | C12: 4 | D12: Birth Year | E12: numeric or blank | F12: =OAA!F11 -> CCYY Format
A13: 46 | B13: 47 | C13: 2 | D13: Enrolled Grade | E13: numeric or blank | F13: =OAA!F12 -> 22=Kindergarten, 01, 02, …. 13=Adult HS, 14=OGT Only, blank=missing/unknown
A14: 48 | B14: 48 | C14: 1 | D14: Gender | E14: alpha or blank | F14: =OAA!F13 -> F=Female
F15: =OAA!F14 -> M=Male
F16: =OAA!F15 -> blank=unknown
A17: 49 | B17: 49 | C17: 1 | D17: Ethnicity | E17: numeric or blank | F17: =OAA!F16 -> 1=American Indian
F18: =OAA!F17 -> 2=Asian/Pacific Islander
F19: =OAA!F18 -> 3=Black/African American
F20: =OAA!F19 -> 4=Hispanic
F21: =OAA!F20 -> 5=White
F22: =OAA!F21 -> 6=Multi-Racial
F23: =OAA!F22 -> 7=Other
F24: =OAA!F23 -> Blank=Unknown
A25: 50 | B25: 58 | C25: 9 | D25: filler
A26: 59 | B26: 78 | C26: 20 | D26: Attending District Name | E26: alpha
A27: 79 | B27: 84 | C27: 6 | D27: Attending District IRN | E27: numeric
A28: 85 | B28: 104 | C28: 20 | D28: Attending School Name | E28: alpha
A29: 105 | B29: 110 | C29: 6 | D29: Attending School IRN | E29: numeric
A30: 111 | B30: 112 | C30: 2 | D30: Test Month | E30: numeric | F30: =OAA!F29 -> MM
A31: 113 | B31: 114 | C31: 2 | D31: Test Day | E31: numeric or blank | F31: =OAA!F30 -> DD
A32: 115 | B32: 118 | C32: 4 | D32: Test Year | E32: numeric | F32: =OAA!F31 -> CCYY format
A33: 119 | B33: 123 | C33: 5 | D33: Homeroom ID | E33: alphanumeric or blank
A34: 124 | B34: 125 | C34: 2 | D34: filler
A35: 126 | B35: 126 | C35: 1 | D35: Migrant Student | E35: alpha or blank | F35: =OAA!F34 -> Y=Yes
F36: =OAA!F35 -> Blank=Not Indicated
A37: 127 | B37: 127 | C37: 1 | D37: IEP-Writing | E37: alpha or blank | F37: =OAA!F36 -> Y=Yes
F38: =OAA!F37 -> Blank=Not Indicated
A39: 128 | B39: 128 | C39: 1 | D39: IEP-Reading | E39: alpha or blank | F39: =OAA!F38 -> Y=Yes
F40: =OAA!F39 -> Blank=Not Indicated
...
