Workbook

Sheet 1415T 022414
A1: MISSION COLLEGE
A2: Responsibility | B2: Contact Info. | C2: Fixed Cost Description | D2: Explanation for Adjustments | E2: Criteria | F2: Account Number | G2: Final Budget 2013-14 | H2: Working Budget 2013-14 | I2: Actuals 2013-14 as of 2/28/14 | J2: Budget Adjust. Incr / (Decr) | K2: Tent Budget 2014-15
C3: Academic Senate - Supplies/Materials | F3: 100_206200_6750_54210_819 | G3: 1000 | J3: 0 | K3: =G3+J3 -> 1000
C4: Academic Senate - non teaching stipends | F4: 100_206200_6750_51450_819 | K4: =G4+J4 -> 0
C5: Academic Senate - benefits | F5: 100_206200_6750_53xxx_819 | K5: =G5+J5 -> 0
C6: Academic Senate - dues membership & fee | F6: 100_206200_6750_55910_819 | G6: 0 | H6: 2100 | I6: 2051 | K6: =G6+J6 -> 0
C7: Academic Senate - Travel & Conference | F7: 100_206200_6750_55200_819 | G7: 3000 | H7: 1900 | I7: 1704 | J7: 0 | K7: =G7+J7 -> 3000
C8: Academic Senate President Stipend | E8: C | F8: 100_206200_6750_51450_819 | G8: 5000 | H8: 5000 | I8: 1999 | J8: 0 | K8: =G8+J8 -> 5000 | L8: =K8*11.123% -> 556.15
C9: Academic Senate President - benefits | D9: at 11.123% | E9: C | F9: 100_206200_6750_53XXX_819 | G9: 0 | H9: 0 | I9: 58 | J9: 556 | K9: =G9+J9 -> 556
A10: Senates | B10: Worku Negash | C10: Academic Senate | E10: C | F10: Multiple account numbers | G10: =SUM(G3:G9) -> 9000 | H10: =SUM(H3:H9) -> 9000 | I10: =SUM(I3:I9) -> 5812 | J10: =SUM(J3:J9) -> 556 | K10: =G10+J10 -> 9556
C11: Classified Senate - Hrly classified Salary | F11: 100_206300_6750_52310_819 | G11: 1000 | H11: 1000 | J11: 0 | K11: =G11+J11 -> 1000
C12: Classified Senate - Supplies/Materials | F12: 100_206300_6750_54210_819 | G12: 500 | H12: 500 | J12: 0 | K12: =G12+J12 -> 500
C13: Classified Senate - Food Services | F13: 100_206300_6750_55115_819 | G13: 1500 | H13: 1500 | J13: 0 | K13: =G13+J13 -> 1500
C14: Classified Senate - Travel & Conference | F14: 100_206300_6750_55205_819 | G14: 1500 | H14: 1500 | J14: 0 | K14: =G14+J14 -> 1500
A15: Senates | B15: Worku Negash | C15: Classified Senate | E15: C | F15: Multiple account numbers | G15: =SUM(G11:G14) -> 4500 | H15: =SUM(H11:H14) -> 4500 | J15: =SUM(J11:J14) -> 0 | K15: =G15+J15 -> 4500
A16: Faculty Travel | B16: Worku Negash | C16: Faculty Travel & Conference | D16: 14.4 FT Faculty | E16: D | F16: 100_290100_6600_55210_819 | G16: 29000 | H16: 29000 | I16: 21824 | J16: -200 | K16: =G16+J16 -> 28800
A17: VP Admin. Services | B17: Worku Negash | C17: Tenure Faculty - Salary | D17: 2 faculty @ 5,500 each | E17: D | F17: 100_220910_4900_51310_819 | G17: 0 | J17: 11000 | K17: =G17+J17 -> 11000
A18: VP Admin. Services | C18: Tenure Faculty - Benefits | D18: at 11.123% | E18: D | F18: 100_220910_4900_53xxx_819 | J18: 1224 | K18: =G18+J18 -> 1224
A19: Dean of Instr, Lib. St/LA | C19: Tricore, Link + Consortium, Library Maintenance | D19: Increase in cost | E19: A | F19: 100_230000_6120_55510_819 | G19: 37594 | H19: 37594 | I19: 37326 | J19: 250 | K19: =G19+J19 -> 37844
A20: VP Admin. Services | B20: Worku Negash | C20: Insurance for Athletics | E20: C | F20: 100_220000_6440_55940_819 | G20: 39654 | H20: 39654 | I20: 39654 | K20: =G20+J20 -> 39654 | L20: =K20-I20 -> 0
A21: VP Admin. Services | C21: Insurance for Students | E21: C | F21: 100_220000_6440_55940_819 | G21: 34057 | H21: 34057 | K21: =G21+J21 -> 34057
A22: Athletics | B22: Worku Negash | C22: Coaches Stipends | E22: D | F22: 100_220000_6770_51450_819 | G22: 15000 | H22: 15000 | I22: 6009 | K22: =G22+J22 -> 15000
A23: Athletics | C23: Coaches Benefits | D23: at 11.123% | E23: D | F23: 100_220000_6770_53xxx_819 | G23: 0 | H23: 0 | I23: 0 | J23: 1668 | K23: =G23+J23 -> 1668 | L23: =K22*11.123% -> 1668.45
A24: College President | C24: Accreditation - Non Teach Stipends | E24: C | F24: 100_200700_6090_51450_819 | G24: 0 | H24: 8500 | I24: 9810 | K24: =G24+J24 -> 0
A25: College President | C25: Accreditation - Hrly Classified Salary | E25: C | F25: 100_200700_6090_52310_819 | H25: 1000 | I25: 323 | K25: =G25+J25 -> 0
A26: College President | C26: Accreditation - Benefits | E26: C | F26: 100_200700_6090_53xxx_819 | I26: 1088 | K26: =G26+J26 -> 0
A27: College President | C27: Accreditation - Supplies/Materials | D27: Move to college's oper. budget | E27: C | F27: 100_200700_6090_54210_819 | G27: 10000 | H27: 1500 | I27: 2260 | J27: -10000 | K27: =G27+J27 -> 0
A28: College President | C28: Accreditation - Foods | E28: C | F28: 100_200700_6090_55115_819 | G28: 0 | H28: 150 | K28: =G28+J28 -> 0
A29: College President | C29: Accreditation - Travel, Conference | E29: C | F29: 100_200700_6090_55205_819 | H29: 15000 | K29: =G29+J29 -> 0
A30: College President | C30: Accreditation - Printing | E30: C | F30: 100_200700_6090_55300_819 | H30: 8000 | I30: 223 | K30: =G30+J30 -> 0
A31: College President | B31: Worku Negash | C31: Accreditation - Dues, Memberships & Fees | D31: decrease in FTES | E31: C | F31: 100_200700_6090_55910_819 | G31: 19137 | H31: 19137 | I31: 19137 | J31: -286 | K31: =G31+J31 -> 18851
A32: College President | C32: Accreditation | D32: Dues, Membership | E32: C | F32: Multiple account numbers | G32: =SUM(G24:G31) -> 29137 | H32: =SUM(H24:H31) -> 53287 | I32: =SUM(I24:I31) -> 32841 | J32: =SUM(J24:J31) -> -10286 | K32: =G32+J32 -> 18851
A33: VP Admin. Services | B33: Linda Francis/Virginia | C33: Categorical Program: Transfer Out, Fringe Benefits | D33: Increase funding level | E33: C | F33: 100_220001_7310_57300_819 | G33: 340397 | H33: 340397 | I33: 218683 | J33: 73603 | K33: =G33+J33 -> 414000
A34: VP Admin. Services | B34: Linda Francis/Virginia | C34: Financial Aid Match: SEOG & Fed Work Study | D34: Increase funding level | E34: C | F34: 100_220002_7310_57300_819 | G34: 81876 | H34: 81876 | J34: 12910 | K34: =G34+J34 -> 94786
A35: VP Admin. Services | C35: HigherOne | D35: Increase in cost | E35: F | F35: 100_220900_6490_55160_819 | G35: 2500 | H35: 2500 | I35: 2625 | J35: 125 | K35: =G35+J35 -> 2625
A36: VP Admin. Services | B36: Worku Negash | C36: Astra Schedule | E36: A | F36: 100_220007_6010_55500_819 | G36: 9950 | H36: 37299 | I36: 18242 | K36: =G36+J36 -> 9950
A37: VP Admin. Services | C37: LaserFiche | E37: A | F37: 100_220007_6010_55500_819 | G37: 8160 | K37: =G37+J37 -> 8160
A38: VP Admin. Services | C38: Form Fusion | D38: Increase in cost | E38: A | F38: 100_220007_6010_55500_819 | G38: 949 | J38: 38 | K38: =G38+J38 -> 987
A39: VP Admin. Services | B39: Worku Negash | C39: Curricunet | E39: A | F39: 100_220000_6010_55160_819 | G39: 11800 | H39: 11800 | I39: 11800 | K39: =G39+J39 -> 11800
A40: VP Admin. Services | B40: Worku Negash | C40: Curricunet (Governet) Meta upgrade - one time | E40: A | F40: 100_220000_6010_55160_819 | G40: 0 | H40: 0 | I40: 0 | J40: 15000 | K40: =G40+J40 -> 15000
...

Sheet 1314A 071013
B1: MISSION COLLEGE | D1: MISSION COLLEGE
B2: Budget | I2: Final Budget | J2: 0.92307692 | K2: Actual Exp | M2: Available | N2: 13/14 | O2: Budget Adjust. | P2: Final Budget | Q2: Budget Adjust.
B3: Responsibility | C3: Contact Info. | D3: Fixed Cost Description | F3: Explanation for Adjustments | G3: Criteria | H3: Account Number | I3: 2012-13 | J3: Working Bud | K3: as of 7/10/13 | L3: Encumb. | M3: Budget | N3: Tnt. Budget | O3: Incr / (Decr) | P3: 2013-14 | Q3: Incr/(Decr)
D4: Academic Senate - Supplies/Materials | H4: 100_206200_6750_54210_819 | I4: 1000 | J4: =VLOOKUP(H4,'Datetel Jul 10, 2013'!A:F,6,0) -> 372 | K4: =VLOOKUP(H4,'Datetel Jul 10, 2013'!A:G,7,0) -> 371.39 | L4: =VLOOKUP(H4,'Datetel Jul 10, 2013'!A:I,8,0) -> 0 | M4: =J4-K4-L4 -> 0.61
D5: Academic Senate - Travel & Conference | H5: 100_206200_6750_55200_819 | I5: 3000 | J5: =VLOOKUP(H5,'Datetel Jul 10, 2013'!A:F,6,0)+SUM('Datetel Jul 10, 2013'!F139:F143) -> 3628 | K5: =VLOOKUP(H5,'Datetel Jul 10, 2013'!A:G,7,0) -> 2717.25 | L5: =VLOOKUP(H5,'Datetel Jul 10, 2013'!A:I,8,0) -> 0 | M5: =J5-K5-L5 -> 910.75
B6: Senates | C6: Worku Negash | D6: Academic Senate | G6: C | H6: Multiple account numbers | I6: 4000 | J6: =SUM(J4:J5) -> 4000 | K6: =SUM(K4:K5) -> 3088.64 | L6: =SUM(L4:L5) -> 0 | M6: =J6-K6-L6 -> 911.36 | N6: 4000 | P6: =N6+O6 -> 4000 | Q6: =P6-I6 -> 0
D7: Classified Senate - Hrly classified Salary | H7: 100_206300_6750_52310_819 | I7: 1000 | J7: =VLOOKUP(H7,'Datetel Jul 10, 2013'!A:F,6,0) -> 0 | K7: =VLOOKUP(H7,'Datetel Jul 10, 2013'!A:G,7,0) -> 0 | L7: =VLOOKUP(H7,'Datetel Jul 10, 2013'!A:I,8,0) -> 0 | M7: =J7-K7-L7 -> 0 | P7: =N7+O7 -> 0 | Q7: =O7+P7 -> 0
D8: Classified Senate - Supplies/Materials | H8: 100_206300_6750_54210_819 | I8: 500 | J8: =VLOOKUP(H8,'Datetel Jul 10, 2013'!A:F,6,0) -> 300 | K8: =VLOOKUP(H8,'Datetel Jul 10, 2013'!A:G,7,0) -> 204.23 | L8: =VLOOKUP(H8,'Datetel Jul 10, 2013'!A:I,8,0) -> 0 | M8: =J8-K8-L8 -> 95.77 | P8: =N8+O8 -> 0 | Q8: =O8+P8 -> 0
D9: Classified Senate - Food Services | H9: 100_206300_6750_55115_819 | I9: 1500 | J9: =VLOOKUP(H9,'Datetel Jul 10, 2013'!A:F,6,0) -> 1000 | K9: =VLOOKUP(H9,'Datetel Jul 10, 2013'!A:G,7,0) -> 800 | L9: =VLOOKUP(H9,'Datetel Jul 10, 2013'!A:I,8,0) -> 0 | M9: =J9-K9-L9 -> 200 | P9: =N9+O9 -> 0 | Q9: =O9+P9 -> 0
D10: Classified Senate - Travel & Conference | H10: 100_206300_6750_55205_819 | I10: 1500 | J10: =VLOOKUP(H10,'Datetel Jul 10, 2013'!A:F,6,0) -> 3247 | K10: =VLOOKUP(H10,'Datetel Jul 10, 2013'!A:G,7,0) -> 3246.43 | L10: =VLOOKUP(H10,'Datetel Jul 10, 2013'!A:I,8,0) -> 0 | M10: =J10-K10-L10 -> 0.57 | P10: =N10+O10 -> 0 | Q10: =O10+P10 -> 0
B11: Senates | C11: Worku Negash | D11: Classified Senate | G11: C | H11: Multiple account numbers | I11: 4500 | J11: =SUM(J7:J10) -> 4547 | K11: =SUM(K7:K10) -> 4250.66 | L11: =SUM(L7:L10) -> 0 | M11: =J11-K11-L11 -> 296.34 | N11: 4500 | P11: =N11+O11 -> 4500 | Q11: =P11-I11 -> 0
B12: Senate | D12: Academic Senate President Stipend | G12: C | H12: 100_206200_6750_51450_819 | N12: 5000 | P12: =N12+O12 -> 5000 | Q12: =P12-I12 -> 5000
B13: Faculty Travel | C13: Worku Negash | D13: Faculty Travel & Conference | G13: E | H13: 100_290100_6600_55210_819 | I13: 28800 | J13: =VLOOKUP(H13,'Datetel Jul 10, 2013'!A:F,6,0) -> 28800 | K13: =VLOOKUP(H13,'Datetel Jul 10, 2013'!A:G,7,0) -> 22961.92 | L13: =VLOOKUP(H13,'Datetel Jul 10, 2013'!A:I,8,0) -> 0 | M13: =J13-K13-L13 -> 5838.08 | N13: 29000 | P13: =N13+O13 -> 29000 | Q13: =P13-I13 -> 200
B14: VP Admin. Services | C14: Worku Negash | D14: Tenure Faculty | G14: E | H14: 100_220910_4900_51310_819 | I14: 16500 | J14: =VLOOKUP(H14,'Datetel Jul 10, 2013'!A:F,6,0) -> 16500 | K14: =VLOOKUP(H14,'Datetel Jul 10, 2013'!A:G,7,0) -> 16500 | L14: =VLOOKUP(H14,'Datetel Jul 10, 2013'!A:I,8,0) -> 0 | M14: =J14-K14-L14 -> 0 | N14: 0 | P14: =N14+O14 -> 0 | Q14: =P14-I14 -> -16500
B15: Dean of Instr, Lib. St/LA | C15: Worku Negash | D15: Tricore, Link + Consortium, Library Maintenance | G15: A | H15: 100_290200_6110_55510_819 | I15: 37594 | J15: =VLOOKUP(H15,'Datetel Jul 10, 2013'!A:F,6,0) -> 37971 | K15: =VLOOKUP(H15,'Datetel Jul 10, 2013'!A:G,7,0) -> 37812.03 | L15: =VLOOKUP(H15,'Datetel Jul 10, 2013'!A:I,8,0) -> 53.97 | M15: =J15-K15-L15 -> 105 | N15: 37594 | P15: =N15+O15 -> 37594 | Q15: =P15-I15 -> 0
B16: Dean of Instr, Lib. St/LA | D16: Turnkey Server Migration (One-Time) | G16: A | H16: 100_230000_6120_55510_819 | I16: 4877 | J16: =VLOOKUP(H16,'Datetel Jul 10, 2013'!A:F,6,0) -> 4500 | K16: =VLOOKUP(H16,'Datetel Jul 10, 2013'!A:G,7,0) -> 4500 | L16: =VLOOKUP(H16,'Datetel Jul 10, 2013'!A:I,8,0) -> 0 | M16: =J16-K16-L16 -> 0 | N16: 0 | P16: =N16+O16 -> 0 | Q16: =P16-I16 -> -4877
B17: VP Admin. Services | C17: Worku Negash | D17: Insurance for PE and Athletics Students | G17: C, D | H17: 100_220000_6440_55940_819 | I17: 73711 | J17: =VLOOKUP(H17,'Datetel Jul 10, 2013'!A:F,6,0) -> 73711 | K17: =VLOOKUP(H17,'Datetel Jul 10, 2013'!A:G,7,0) -> 72921.12 | L17: =VLOOKUP(H17,'Datetel Jul 10, 2013'!A:I,8,0) -> 0 | M17: =J17-K17-L17 -> 789.88 | N17: 73711 | P17: =N17+O17 -> 73711 | Q17: =P17-I17 -> 0
B18: VP Admin. Services | C18: Worku Negash | D18: Coaches Stipends (Negotiated Item) | G18: E | H18: 100_220000_6770_51450_819 | I18: 15000 | J18: =VLOOKUP(H18,'Datetel Jul 10, 2013'!A:F,6,0)+SUM('Datetel Jul 10, 2013'!F152:F156) -> 14487 | K18: =SUM('Datetel Jul 10, 2013'!G151:G156) -> 14416.9 | L18: =VLOOKUP(H18,'Datetel Jul 10, 2013'!A:I,8,0) -> 0 | M18: =J18-K18-L18 -> 70.1 | N18: 15000 | P18: =N18+O18 -> 15000 | Q18: =P18-I18 -> 0
B19: College President | D19: Accreditation - Supplies/Materials | G19: C | H19: 100_200700_6090_51450_819 | I19: 0 | J19: =VLOOKUP(H19,'Datetel Jul 10, 2013'!A:F,6,0) -> 11686 | K19: =VLOOKUP(H19,'Datetel Jul 10, 2013'!A:G,7,0) -> 12291.36 | L19: =VLOOKUP(H19,'Datetel Jul 10, 2013'!A:I,8,0) -> 0 | M19: =J19-K19-L19 -> -605.36 | N19: 0 | O19: 8500 | P19: =N19+O19 -> 8500 | Q19: =P19-I19 -> 8500
B20: College President | D20: Accreditation - Supplies/Materials | G20: C | H20: 100_200700_6090_54210_819 | I20: 10000 | J20: =VLOOKUP(H20,'Datetel Jul 10, 2013'!A:F,6,0) -> 1500 | K20: =VLOOKUP(H20,'Datetel Jul 10, 2013'!A:G,7,0) -> 183.64 | L20: =VLOOKUP(H20,'Datetel Jul 10, 2013'!A:I,8,0) -> 0 | M20: =J20-K20-L20 -> 1316.36 | N20: 10000 | O20: -8500 | P20: =N20+O20 -> 1500 | Q20: =P20-I20 -> -8500
B21: College President | D21: Accreditation - PT Faculty Non Teaching Stipend | G21: C | H21: 100_200700_6090_51450_819 | J21: =VLOOKUP(H21,'Datetel Jul 10, 2013'!A:F,6,0)+1327 -> 13013 | K21: =VLOOKUP(H21,'Datetel Jul 10, 2013'!A:G,7,0) -> 12291.36 | L21: =VLOOKUP(H21,'Datetel Jul 10, 2013'!A:I,8,0) -> 0 | M21: =J21-K21-L21 -> 721.64 | N21: 0 | P21: =N21+O21 -> 0 | Q21: =P21-I21 -> 0
B22: College President | C22: Worku Negash | D22: Accreditation - Dues, Memberships & Fees | F22: Incr due to Evaluation visit | G22: C | H22: 100_200700_6090_55910_819 | I22: 17453 | J22: =VLOOKUP(H22,'Datetel Jul 10, 2013'!A:F,6,0) -> 17453 | K22: =VLOOKUP(H22,'Datetel Jul 10, 2013'!A:G,7,0)+'Datetel Jul 10, 2013'!G133+'Datetel Jul 10, 2013'!G134+'Datetel Jul 10, 2013'!G135+'Datetel Jul 10, 2013'!G136 -> 16964.86 | L22: =VLOOKUP(H22,'Datetel Jul 10, 2013'!A:I,8,0) -> 0 | M22: =J22-K22-L22 -> 488.14 | N22: 17453 | O22: =19137-N22 -> 1684 | P22: =N22+O22 -> 19137 | Q22: =P22-I22 -> 1684
B23: VP Admin. Services | C23: Linda Francis/Virginia | D23: Categorical Program: Transfer Out, Fringe Benefits | G23: C | H23: 100_220001_7310_57300_819 | I23: 340397 | J23: =VLOOKUP(H23,'Datetel Jul 10, 2013'!A:F,6,0) -> 340397 | K23: =VLOOKUP(H23,'Datetel Jul 10, 2013'!A:G,7,0) -> 320394.85 | L23: =VLOOKUP(H23,'Datetel Jul 10, 2013'!A:I,8,0) -> 0 | M23: =J23-K23-L23 -> 20002.15 | N23: 340397 | P23: =N23+O23 -> 340397 | Q23: =P23-I23 -> 0
B24: VP Admin. Services | C24: Linda Francis/Virginia | D24: Financial Aid Match: SEOG & Fed Work Study | G24: C | H24: 100_220002_7310_57300_819 | I24: 88013 | J24: =VLOOKUP(H24,'Datetel Jul 10, 2013'!A:F,6,0) -> 88013 | K24: =VLOOKUP(H24,'Datetel Jul 10, 2013'!A:G,7,0) -> 0 | L24: =VLOOKUP(H24,'Datetel Jul 10, 2013'!A:I,8,0) -> 0 | M24: =J24-K24-L24 -> 88013 | N24: 88013 | O24: =81876-88013 -> -6137 | P24: =N24+O24 -> 81876 | Q24: =P24-I24 -> -6137
B25: VP Admin. Services | D25: HigherOne | G25: D | H25: 100_220900_6490_55160_819 | I25: 2500 | J25: =VLOOKUP(H25,'Datetel Jul 10, 2013'!A:F,6,0) -> 2500 | K25: =VLOOKUP(H25,'Datetel Jul 10, 2013'!A:G,7,0) -> 2500 | L25: =VLOOKUP(H25,'Datetel Jul 10, 2013'!A:I,8,0) -> 0 | M25: =J25-K25-L25 -> 0 | N25: 2500 | P25: =N25+O25 -> 2500 | Q25: =P25-I25 -> 0
B26: VP Admin. Services | C26: Worku Negash | D26: Astra Schedule/LaserFiche Avante/FormFusion | G26: A | H26: 100_220007_6010_55500_819 | I26: 19057 | J26: =VLOOKUP(H26,'Datetel Jul 10, 2013'!A:F,6,0) -> 19057 | K26: =VLOOKUP(H26,'Datetel Jul 10, 2013'!A:G,7,0) -> 18110 | L26: =VLOOKUP(H26,'Datetel Jul 10, 2013'!A:I,8,0) -> 0 | M26: =J26-K26-L26 -> 947 | N26: 19057 | P26: =N26+O26 -> 19057 | Q26: =P26-I26 -> 0
B27: VP Admin. Services | C27: Worku Negash | D27: Curricunet | F27: Incr. MC for SLO module | G27: A | H27: 100_220000_6010_55160_819 | I27: 7479 | J27: =VLOOKUP(H27,'Datetel Jul 10, 2013'!A:F,6,0) -> 7479 | K27: =VLOOKUP(H27,'Datetel Jul 10, 2013'!A:G,7,0) -> 7479 | L27: =VLOOKUP(H27,'Datetel Jul 10, 2013'!A:I,8,0) -> 0 | M27: =J27-K27-L27 -> 0 | N27: 7479 | O27: 4321 | P27: =N27+O27 -> 11800 | Q27: =P27-I27 -> 4321
B28: VP Admin. Services | C28: Ron Smith | D28: SARS Software Products -Counseling Sched System | G28: A | H28: 100_220004_6150_55500_819 | I28: 6500 | J28: =VLOOKUP(H28,'Datetel Jul 10, 2013'!A:F,6,0) -> 6453 | K28: =VLOOKUP(H28,'Datetel Jul 10, 2013'!A:G,7,0) -> 6255 | L28: =VLOOKUP(H28,'Datetel Jul 10, 2013'!A:I,8,0) -> 0 | M28: =J28-K28-L28 -> 198 | N28: 6500 | P28: =N28+O28 -> 6500 | Q28: =P28-I28 -> 0
B29: VP Admin. Services | C29: Ron Smith | D29: Angel | F29: Renewal rate adj for 2 yr contr. | G29: A | H29: 100_220005_6150_55500_819 | I29: 78691 | J29: =VLOOKUP(H29,'Datetel Jul 10, 2013'!A:F,6,0) -> 78691 | K29: =VLOOKUP(H29,'Datetel Jul 10, 2013'!A:G,7,0) -> 78691.63 | L29: =VLOOKUP(H29,'Datetel Jul 10, 2013'!A:I,8,0) -> 0 | M29: =J29-K29-L29 -> -0.63 | N29: 83413 | O29: =(165252/2)-83413 -> -787 | P29: =N29+O29 -> 82626 | Q29: =P29-I29 -> 3935
B30: VP Admin. Services | C30: Ron Smith | D30: CCCApply / BOGS (Student-Right-to-know) | G30: A | H30: 100_220006_6150_55500_819 | I30: 15609 | J30: =VLOOKUP(H30,'Datetel Jul 10, 2013'!A:F,6,0) -> 15609 | K30: =VLOOKUP(H30,'Datetel Jul 10, 2013'!A:G,7,0) -> 11514.1 | L30: =VLOOKUP(H30,'Datetel Jul 10, 2013'!A:I,8,0) -> 4099.9 | M30: =J30-K30-L30 -> -5 | N30: 15609 | P30: =N30+O30 -> 15609 | Q30: =P30-I30 -> 0
H31: Total Mission College | I31: =SUM(I6,I11,I12:I30) -> 770681 | J31: =SUM(J6,J11,J13:J30) -> 786367 | K31: =SUM(K6,K11,K13:K30) -> 663127.07 | L31: =SUM(L6,L11,L13:L30) -> 4153.87 | M31: =SUM(M6,M11,M13:M30) -> 119086.06 | N31: =SUM(N6,N11,N12:N30) -> 759226 | O31: =SUM(O6,O11,O12:O30) -> -919 | P31: =SUM(P6,P11,P12:P30) -> 758307 | Q31: =SUM(Q6,Q11,Q12:Q30) -> -12374
M32: 412305
B33: WEST VALLEY COLLEGE | D33: WEST VALLEY COLLEGE
B34: Budget | I34: 0.92307692 | J34: 0.92307692 | K34: Actual Exp | M34: Available | N34: 13/14 | O34: Budget Adjust. | P34: 13/14 | Q34: 13/14
B35: Responsibility | C35: Contact Info. | D35: Fixed Cost Description | E35: Detail Description | F35: Explanation for Adjustments | G35: Criteria | H35: Account Number | I35: Adopt Bud | J35: Working Bud | K35: as of 7/10/13 | L35: Encumb. | M35: Budget | N35: Tnt. Budget | O35: Incr / (Decr) | P35: Adopt Budget | Q35: Adopt Budget
D36: Academic Senate | H36: 100_119304_6750_55115_819 | I36: 1100 | J36: =VLOOKUP(H36,'Datetel Jul 10, 2013'!A:F,6,0) -> 1100 | K36: =VLOOKUP(H36,'Datetel Jul 10, 2013'!A:G,7,0) -> 0 | L36: =VLOOKUP(H36,'Datetel Jul 10, 2013'!A:I,8,0) -> 0 | M36: =J36-K36-L36 -> 1100
D37: Academic Senate | H37: 100_119304_6750_55200_819 | I37: 3300 | J37: =VLOOKUP(H37,'Datetel Jul 10, 2013'!A:F,6,0) -> 3300 | K37: =VLOOKUP(H37,'Datetel Jul 10, 2013'!A:G,7,0) -> 0 | L37: =VLOOKUP(H37,'Datetel Jul 10, 2013'!A:I,8,0) -> 0 | M37: =J37-K37-L37 -> 3300
B38: Senates | C38: Michael Renzi | D38: Academic Senate | G38: C | H38: Multiple account numbers | I38: 4400 | J38: =SUM(J36:J37) -> 4400 | K38: =SUM(K36:K37) -> 0 | L38: =SUM(L36:L37) -> 0 | M38: =J38-K38-L38 -> 4400 | N38: 4400 | P38: =N38+O38 -> 4400 | Q38: =P38-I38 -> 0
D39: Classified Senate | H39: 100_119305_6750_55115_819 | I39: 660 | J39: =VLOOKUP(H39,'Datetel Jul 10, 2013'!A:F,6,0) -> 3660 | K39: =VLOOKUP(H39,'Datetel Jul 10, 2013'!A:G,7,0) -> 3033.84 | L39: =VLOOKUP(H39,'Datetel Jul 10, 2013'!A:I,8,0) -> 0 | M39: =J39-K39-L39 -> 626.16 | P39: =N39+O39 -> 0 | Q39: =P39-I39 -> -660
D40: Classified Senate | H40: 100_119305_6750_55160_819 | I40: 440 | J40: =VLOOKUP(H40,'Datetel Jul 10, 2013'!A:F,6,0) -> 440 | K40: =VLOOKUP(H40,'Datetel Jul 10, 2013'!A:G,7,0) -> 440.02 | L40: =VLOOKUP(H40,'Datetel Jul 10, 2013'!A:I,8,0) -> 0 | M40: =J40-K40-L40 -> -0.02 | P40: =N40+O40 -> 0 | Q40: =P40-I40 -> -440
...

Sheet 1314T 032913
B1: MISSION COLLEGE
B2: Budget | I2: 0.92307692 | J2: 0.92307692 | K2: Actual Exp | M2: Available | N2: Budget Adjust. | O2: 13/14
B3: Responsibility | C3: Contact Info. | D3: Fixed Cost Description | F3: Explanation for Adjustments | G3: Criteria | H3: Account Number | I3: Adopt Bud | J3: Working Bud | K3: as of 2/28/13 | L3: Encumb. | M3: Budget | N3: Incr / (Decr) | O3: Tnt. Budget
D4: Academic Senate - Supplies/Materials | H4: 100_206200_6750_54210_819 | I4: 1000 | J4: =VLOOKUP(H4,'Datetel Feb 28, 2013'!A:F,6,0) -> 1000 | K4: =VLOOKUP(H4,'Datetel Feb 28, 2013'!A:G,7,0) -> 163.62 | L4: =VLOOKUP(H4,'Datetel Feb 28, 2013'!A:I,8,0) -> 0 | M4: =J4-K4-L4 -> 836.38
D5: Academic Senate - Travel & Conference | H5: 100_206200_6750_55200_819 | I5: 3000 | J5: =VLOOKUP(H5,'Datetel Feb 28, 2013'!A:F,6,0) -> 3000 | K5: =VLOOKUP(H5,'Datetel Feb 28, 2013'!A:G,7,0) -> 1067.25 | L5: =VLOOKUP(H5,'Datetel Feb 28, 2013'!A:I,8,0) -> 0 | M5: =J5-K5-L5 -> 1932.75
B6: Senates | C6: Worku Negash | D6: Academic Senate | G6: C | H6: Multiple account numbers | I6: 4000 | J6: =SUM(J4:J5) -> 4000 | K6: =SUM(K4:K5) -> 1230.87 | L6: =SUM(L4:L5) -> 0 | M6: =J6-K6-L6 -> 2769.13 | O6: =J6 -> 4000
D7: Classified Senate - Hrly classified Salary | H7: 100_206300_6750_52310_819 | I7: 1000 | J7: =VLOOKUP(H7,'Datetel Feb 28, 2013'!A:F,6,0) -> 1000 | K7: =VLOOKUP(H7,'Datetel Feb 28, 2013'!A:G,7,0) -> 0 | L7: =VLOOKUP(H7,'Datetel Feb 28, 2013'!A:I,8,0) -> 0 | M7: =J7-K7-L7 -> 1000
D8: Classified Senate - Supplies/Materials | H8: 100_206300_6750_54210_819 | I8: 500 | J8: =VLOOKUP(H8,'Datetel Feb 28, 2013'!A:F,6,0) -> 500 | K8: =VLOOKUP(H8,'Datetel Feb 28, 2013'!A:G,7,0) -> 0 | L8: =VLOOKUP(H8,'Datetel Feb 28, 2013'!A:I,8,0) -> 0 | M8: =J8-K8-L8 -> 500
D9: Classified Senate - Food Services | H9: 100_206300_6750_55115_819 | I9: 1500 | J9: =VLOOKUP(H9,'Datetel Feb 28, 2013'!A:F,6,0) -> 1500 | K9: =VLOOKUP(H9,'Datetel Feb 28, 2013'!A:G,7,0) -> 0 | L9: =VLOOKUP(H9,'Datetel Feb 28, 2013'!A:I,8,0) -> 0 | M9: =J9-K9-L9 -> 1500
D10: Classified Senate - Travel & Conference | H10: 100_206300_6750_55205_819 | I10: 1500 | J10: =VLOOKUP(H10,'Datetel Feb 28, 2013'!A:F,6,0) -> 1500 | K10: =VLOOKUP(H10,'Datetel Feb 28, 2013'!A:G,7,0) -> 197.05 | L10: =VLOOKUP(H10,'Datetel Feb 28, 2013'!A:I,8,0) -> 0 | M10: =J10-K10-L10 -> 1302.95
B11: Senates | C11: Worku Negash | D11: Classified Senate | G11: C | H11: Multiple account numbers | I11: 4500 | J11: =SUM(J7:J10) -> 4500 | K11: =SUM(K7:K10) -> 197.05 | L11: =SUM(L7:L10) -> 0 | M11: =J11-K11-L11 -> 4302.95 | O11: =J11 -> 4500
B12: Senate | D12: Academic Senate President Stipend | F12: FY 13/14 Jul/Jun | G12: C | H12: 100_206200_6750_51450_819 | N12: 5000 | O12: =I12+N12 -> 5000
B13: Faculty Travel | C13: Worku Negash | D13: Faculty Travel & Conference | F13: ACE 145 @ 200 | G13: E | H13: 100_290100_6600_55210_819 | I13: 28800 | J13: =VLOOKUP(H13,'Datetel Feb 28, 2013'!A:F,6,0) -> 28800 | K13: =VLOOKUP(H13,'Datetel Feb 28, 2013'!A:G,7,0) -> 7802.44 | L13: =VLOOKUP(H13,'Datetel Feb 28, 2013'!A:I,8,0) -> 0 | M13: =J13-K13-L13 -> 20997.56 | N13: 200 | O13: =I13+N13 -> 29000
B14: VP Admin. Services | C14: Worku Negash | D14: Tenure Faculty | F14: No tenure bonus for 13/14 | G14: E | H14: 100_220910_4900_51310_819 | I14: 16500 | J14: =VLOOKUP(H14,'Datetel Feb 28, 2013'!A:F,6,0) -> 16500 | K14: =VLOOKUP(H14,'Datetel Feb 28, 2013'!A:G,7,0) -> 16500 | L14: =VLOOKUP(H14,'Datetel Feb 28, 2013'!A:I,8,0) -> 0 | M14: =J14-K14-L14 -> 0 | N14: -16500 | O14: =I14+N14 -> 0
B15: Dean of Instr, Lib. St/LA | C15: Worku Negash | D15: Tricore, Link + Consortium, Library Maintenance | G15: A | H15: 100_290200_6110_55510_819 | I15: 37594 | J15: =VLOOKUP(H15,'Datetel Feb 28, 2013'!A:F,6,0) -> 37971 | K15: =VLOOKUP(H15,'Datetel Feb 28, 2013'!A:G,7,0) -> 36427.35 | L15: =VLOOKUP(H15,'Datetel Feb 28, 2013'!A:I,8,0) -> 1438.65 | M15: =J15-K15-L15 -> 105 | O15: =I15+N15 -> 37594
B16: Dean of Instr, Lib. St/LA | D16: Turnkey Server Migration (One-Time) | F16: one-time cost for FY 12/13 | G16: A | H16: 100_230000_6120_55510_819 | I16: 4877 | J16: =VLOOKUP(H16,'Datetel Feb 28, 2013'!A:F,6,0) -> 4500 | K16: =VLOOKUP(H16,'Datetel Feb 28, 2013'!A:G,7,0) -> 4500 | L16: =VLOOKUP(H16,'Datetel Feb 28, 2013'!A:I,8,0) -> 0 | M16: =J16-K16-L16 -> 0 | N16: -4877 | O16: =I16+N16 -> 0
B17: VP Admin. Services | C17: Worku Negash | D17: Insurance for PE and Athletics Students | G17: C, D | H17: 100_220000_6440_55940_819 | I17: 73711 | J17: =VLOOKUP(H17,'Datetel Feb 28, 2013'!A:F,6,0) -> 73711 | K17: =VLOOKUP(H17,'Datetel Feb 28, 2013'!A:G,7,0) -> 72921.12 | L17: =VLOOKUP(H17,'Datetel Feb 28, 2013'!A:I,8,0) -> 0 | M17: =J17-K17-L17 -> 789.88 | O17: =I17+N17 -> 73711
B18: VP Admin. Services | C18: Worku Negash | D18: Coaches Stipends (Negotiated Item) | G18: E | H18: 100_220000_6770_51450_819 | I18: 15000 | J18: =VLOOKUP(H18,'Datetel Feb 28, 2013'!A:F,6,0) -> 15000 | K18: =SUM('Datetel Feb 28, 2013'!G145:G150) -> 4748.27 | L18: =VLOOKUP(H18,'Datetel Feb 28, 2013'!A:I,8,0) -> 0 | M18: =J18-K18-L18 -> 10251.73 | O18: =I18+N18 -> 15000
B19: College President | D19: Accreditation - Supplies/Materials | F19: Accreditation preparation | G19: C | H19: 100_200700_6090_54210_819 | I19: 10000 | J19: =VLOOKUP(H19,'Datetel Feb 28, 2013'!A:F,6,0) -> 1500 | K19: =VLOOKUP(H19,'Datetel Feb 28, 2013'!A:G,7,0) -> 176.12 | L19: =VLOOKUP(H19,'Datetel Feb 28, 2013'!A:I,8,0) -> 0 | M19: =J19-K19-L19 -> 1323.88 | O19: =I19+N19 -> 10000
B20: College President | D20: Accreditation - PT Faculty Non Teaching Stipend | G20: C | H20: 100_200700_6090_51450_819 | J20: =VLOOKUP(H20,'Datetel Feb 28, 2013'!A:F,6,0) -> 8500 | K20: =VLOOKUP(H20,'Datetel Feb 28, 2013'!A:G,7,0) -> 1817.64 | L20: =VLOOKUP(H20,'Datetel Feb 28, 2013'!A:I,8,0) -> 0 | M20: =J20-K20-L20 -> 6682.36 | O20: =I20+N20 -> 0
B21: College President | C21: Worku Negash | D21: Accreditation - Dues, Memberships & Fees | G21: C | H21: 100_200700_6090_55910_819 | I21: 17453 | J21: =VLOOKUP(H21,'Datetel Feb 28, 2013'!A:F,6,0) -> 17453 | K21: =VLOOKUP(H21,'Datetel Feb 28, 2013'!A:G,7,0)+'Datetel Feb 28, 2013'!G132+'Datetel Feb 28, 2013'!G133+'Datetel Feb 28, 2013'!G134+'Datetel Feb 28, 2013'!G135 -> 15800.35 | L21: =VLOOKUP(H21,'Datetel Feb 28, 2013'!A:I,8,0) -> 0 | M21: =J21-K21-L21 -> 1652.65 | O21: =I21+N21 -> 17453
B22: VP Admin. Services | C22: Linda Francis/Virginia | D22: Categorical Program: Transfer Out, Fringe Benefits | G22: C | H22: 100_220001_7310_57300_819 | I22: 340397 | J22: =VLOOKUP(H22,'Datetel Feb 28, 2013'!A:F,6,0) -> 340397 | K22: =VLOOKUP(H22,'Datetel Feb 28, 2013'!A:G,7,0) -> 242743.92 | L22: =VLOOKUP(H22,'Datetel Feb 28, 2013'!A:I,8,0) -> 0 | M22: =J22-K22-L22 -> 97653.08 | O22: =I22+N22 -> 340397
B23: VP Admin. Services | C23: Linda Francis/Virginia | D23: Financial Aid Match: SEOG & Fed Work Study | G23: C | H23: 100_220002_7310_57300_819 | I23: 88013 | J23: =VLOOKUP(H23,'Datetel Feb 28, 2013'!A:F,6,0) -> 88013 | K23: =VLOOKUP(H23,'Datetel Feb 28, 2013'!A:G,7,0) -> 0 | L23: =VLOOKUP(H23,'Datetel Feb 28, 2013'!A:I,8,0) -> 0 | M23: =J23-K23-L23 -> 88013 | O23: =I23+N23 -> 88013
B24: VP Admin. Services | D24: HigherOne | G24: D | H24: 100_220900_6490_55160_819 | I24: 2500 | J24: =VLOOKUP(H24,'Datetel Feb 28, 2013'!A:F,6,0) -> 2500 | K24: =VLOOKUP(H24,'Datetel Feb 28, 2013'!A:G,7,0) -> 2500 | L24: =VLOOKUP(H24,'Datetel Feb 28, 2013'!A:I,8,0) -> 0 | M24: =J24-K24-L24 -> 0 | O24: =I24+N24 -> 2500
B25: Dir of Information Syst | C25: Worku Negash | D25: Astra Schedule/LaserFiche Avante/FormFusion | G25: A | H25: 100_220007_6010_55500_819 | I25: 19057 | J25: =VLOOKUP(H25,'Datetel Feb 28, 2013'!A:F,6,0) -> 19057 | K25: =VLOOKUP(H25,'Datetel Feb 28, 2013'!A:G,7,0) -> 8160 | L25: =VLOOKUP(H25,'Datetel Feb 28, 2013'!A:I,8,0) -> 0 | M25: =J25-K25-L25 -> 10897 | O25: =I25+N25 -> 19057
B26: Dir of Information Syst | C26: Worku Negash | D26: Curricunet | G26: A | H26: 100_220000_6010_55160_819 | I26: 7479 | J26: =VLOOKUP(H26,'Datetel Feb 28, 2013'!A:F,6,0) -> 7479 | K26: =VLOOKUP(H26,'Datetel Feb 28, 2013'!A:G,7,0) -> 7479 | L26: =VLOOKUP(H26,'Datetel Feb 28, 2013'!A:I,8,0) -> 0 | M26: =J26-K26-L26 -> 0 | O26: =I26+N26 -> 7479
B27: Dir of Information Syst | C27: Ron Smith | D27: SARS Software Products -Counseling Sched System | G27: A | H27: 100_220004_6150_55500_819 | I27: 6500 | J27: =VLOOKUP(H27,'Datetel Feb 28, 2013'!A:F,6,0) -> 6500 | K27: =VLOOKUP(H27,'Datetel Feb 28, 2013'!A:G,7,0) -> 6255 | L27: =VLOOKUP(H27,'Datetel Feb 28, 2013'!A:I,8,0) -> 0 | M27: =J27-K27-L27 -> 245 | O27: =I27+N27 -> 6500
B28: Dir of Information Syst | C28: Ron Smith | D28: Angel | F28: renewal increase 6% | G28: A | H28: 100_220005_6150_55500_819 | I28: 78691 | J28: =VLOOKUP(H28,'Datetel Feb 28, 2013'!A:F,6,0) -> 78691 | K28: =VLOOKUP(H28,'Datetel Feb 28, 2013'!A:G,7,0) -> 78691.63 | L28: =VLOOKUP(H28,'Datetel Feb 28, 2013'!A:I,8,0) -> 0 | M28: =J28-K28-L28 -> -0.63 | N28: 4722 | O28: =I28+N28 -> 83413
B29: Dir of Information Syst | C29: Ron Smith | D29: CCCApply / BOGS (Student-Right-to-know) | G29: A | H29: 100_220006_6150_55500_819 | I29: 15609 | J29: =VLOOKUP(H29,'Datetel Feb 28, 2013'!A:F,6,0) -> 15609 | K29: =VLOOKUP(H29,'Datetel Feb 28, 2013'!A:G,7,0) -> 11514.1 | L29: =VLOOKUP(H29,'Datetel Feb 28, 2013'!A:I,8,0) -> 4099.9 | M29: =J29-K29-L29 -> -5 | O29: =I29+N29 -> 15609
H30: Total Mission College | I30: =SUM(I6,I11,I12:I29) -> 770681 | J30: =SUM(J6,J11,J13:J29) -> 770681 | K30: =SUM(K6,K11,K13:K29) -> 519464.86 | L30: =SUM(L6,L11,L13:L29) -> 5538.55 | M30: =SUM(M6,M11,M13:M29) -> 245677.59 | N30: =SUM(N6,N11,N12:N29) -> -11455 | O30: =SUM(O6,O11,O12:O29) -> 759226
M31: 412305
B32: WEST VALLEY COLLEGE
B33: Budget | I33: 0.92307692 | J33: 0.92307692 | K33: Actual Exp | M33: Available | N33: Budget Adjust. | O33: 13/14
B34: Responsibility | C34: Contact Info. | D34: Fixed Cost Description | E34: Detail Description | F34: Explanation for Adjustments | G34: Criteria | H34: Account Number | I34: Adopt Bud | J34: Working Bud | K34: as of 2/28/13 | L34: Encumb. | M34: Budget | N34: Incr / (Decr) | O34: Tnt. Budget
D35: Academic Senate -to be funded from other source | H35: 100_119304_6750_55115_819 | I35: 1100 | J35: =VLOOKUP(H35,'Datetel Feb 28, 2013'!A:F,6,0) -> 1100 | K35: =VLOOKUP(H35,'Datetel Feb 28, 2013'!A:G,7,0) -> 0 | L35: =VLOOKUP(H35,'Datetel Feb 28, 2013'!A:I,8,0) -> 0 | M35: =J35-K35-L35 -> 1100
D36: Academic Senate -to be funded from other source | H36: 100_119304_6750_55200_819 | I36: 3300 | J36: =VLOOKUP(H36,'Datetel Feb 28, 2013'!A:F,6,0) -> 3300 | K36: =VLOOKUP(H36,'Datetel Feb 28, 2013'!A:G,7,0) -> 0 | L36: =VLOOKUP(H36,'Datetel Feb 28, 2013'!A:I,8,0) -> 0 | M36: =J36-K36-L36 -> 3300
B37: Senates | C37: Michael Renzi | D37: Academic Senate | G37: C | H37: Multiple account numbers | I37: 4400 | J37: =SUM(J35:J36) -> 4400 | K37: =SUM(K35:K36) -> 0 | L37: =SUM(L35:L36) -> 0 | M37: =J37-K37-L37 -> 4400 | O37: =I37 -> 4400 | R37: =0.4*24464 -> 9785.6
D38: Classified Senate | H38: 100_119305_6750_55115_819 | I38: 660 | J38: =VLOOKUP(H38,'Datetel Feb 28, 2013'!A:F,6,0) -> 3660 | K38: =VLOOKUP(H38,'Datetel Feb 28, 2013'!A:G,7,0) -> 452.71 | L38: =VLOOKUP(H38,'Datetel Feb 28, 2013'!A:I,8,0) -> 0 | M38: =J38-K38-L38 -> 3207.29
D39: Classified Senate | H39: 100_119305_6750_55160_819 | I39: 440 | J39: =VLOOKUP(H39,'Datetel Feb 28, 2013'!A:F,6,0) -> 440 | K39: =VLOOKUP(H39,'Datetel Feb 28, 2013'!A:G,7,0) -> 0 | L39: =VLOOKUP(H39,'Datetel Feb 28, 2013'!A:I,8,0) -> 0 | M39: =J39-K39-L39 -> 440
D40: Classified Senate | H40: 100_119305_6750_55200_819 | I40: 3300 | J40: =VLOOKUP(H40,'Datetel Feb 28, 2013'!A:F,6,0) -> 300 | K40: =VLOOKUP(H40,'Datetel Feb 28, 2013'!A:G,7,0) -> 85 | L40: =VLOOKUP(H40,'Datetel Feb 28, 2013'!A:I,8,0) -> 0 | M40: =J40-K40-L40 -> 215
...

Sheet 1213A 080212
B1: MISSION COLLEGE
B2: Budget | I2: 11/12 | J2: 0.91666667 | K2: Actual Exp | L2: Budget Adjust. | M2: 12/13 | N2: Budget Adjust. | O2: 12/13
B3: Responsibility | C3: Contact Info. | D3: Fixed Cost Description | F3: Explanation for Adjustments | G3: Criteria | H3: Account Number | I3: Adopt Bud | J3: Working Bud | K3: as of 6/30/12 | L3: Incr / (Decr) | M3: Tent Bud | N3: Incr / (Decr) | O3: Adopt Bud
D4: Academic Senate - Supplies/Materials | H4: 100_206200_6750_54210_819 | I4: 1000 | J4: =VLOOKUP(H4,'cognos as of Aug 2'!A:F,6,0) -> 414 | K4: =VLOOKUP(H4,'cognos as of Aug 2'!A:G,7,0) -> 250 | M4: =SUM(I4+L4) -> 1000 | P4: =VLOOKUP(H4,Sheet4!A:C,3,0) -> 0
D5: Academic Senate - Food Services | H5: 100_206200_6750_55115_819 | J5: =VLOOKUP(H5,'cognos as of Aug 2'!A:F,6,0) -> 748 | K5: =VLOOKUP(H5,'cognos as of Aug 2'!A:G,7,0) -> 700 | M5: =SUM(I5+L5) -> 0
D6: Academic Senate - Travel & Conference | H6: 100_206200_6750_55200_819 | I6: 3000 | J6: =VLOOKUP(H6,'cognos as of Aug 2'!A:F,6,0) -> 2838 | K6: =VLOOKUP(H6,'cognos as of Aug 2'!A:G,7,0) -> 2838 | M6: =SUM(I6+L6) -> 3000 | P6: =VLOOKUP(H6,Sheet4!A:C,3,0) -> 0
B7: Senates | C7: Worku Negash | D7: Academic Senate | G7: C | H7: Multiple account numbers | I7: 4000 | J7: =SUM(J4:J6) -> 4000 | K7: =SUM(K4:K6) -> 3788 | L7: =SUM(L4:L6) -> 0 | M7: =SUM(I7+L7) -> 4000 | O7: =M7+N7 -> 4000 | P7: =VLOOKUP(H7,Sheet4!A:C,3,0) -> #N/A
D8: Classified Senate - Hrly classified Salary | H8: 100_206300_6750_52310_819 | I8: 1000 | J8: =VLOOKUP(H8,'cognos as of Aug 2'!A:F,6,0) -> 0 | K8: =VLOOKUP(H8,'cognos as of Aug 2'!A:G,7,0) -> 0 | M8: =SUM(I8+L8) -> 1000 | O8: =M8+N8 -> 1000 | P8: =VLOOKUP(H8,Sheet4!A:C,3,0) -> 0
D9: Classified Senate - Supplies/Materials | H9: 100_206300_6750_54210_819 | I9: 500 | J9: =VLOOKUP(H9,'cognos as of Aug 2'!A:F,6,0) -> 375 | K9: =VLOOKUP(H9,'cognos as of Aug 2'!A:G,7,0) -> 374.5 | M9: =SUM(I9+L9) -> 500 | O9: =M9+N9 -> 500 | P9: =VLOOKUP(H9,Sheet4!A:C,3,0) -> 0
D10: Classified Senate - Food Services | H10: 100_206300_6750_55115_819 | I10: 1500 | J10: =VLOOKUP(H10,'cognos as of Aug 2'!A:F,6,0) -> 483 | K10: =VLOOKUP(H10,'cognos as of Aug 2'!A:G,7,0) -> 482.44 | M10: =SUM(I10+L10) -> 1500 | O10: =M10+N10 -> 1500 | P10: =VLOOKUP(H10,Sheet4!A:C,3,0) -> 0
D11: Classified Senate - Travel & Conference | H11: 100_206300_6750_55205_819 | I11: 1500 | J11: =VLOOKUP(H11,'cognos as of Aug 2'!A:F,6,0) -> 3642 | K11: =VLOOKUP(H11,'cognos as of Aug 2'!A:G,7,0) -> 3642 | M11: =SUM(I11+L11) -> 1500 | O11: =M11+N11 -> 1500 | P11: =VLOOKUP(H11,Sheet4!A:C,3,0) -> 0
B12: Senates | C12: Worku Negash | D12: Classified Senate | G12: C | H12: Multiple account numbers | I12: 4500 | J12: =SUM(J8:J11) -> 4500 | K12: =SUM(K8:K11) -> 4498.94 | L12: =SUM(L8:L11) -> 0 | M12: =SUM(I12+L12) -> 4500 | O12: =M12+N12 -> 4500 | P12: =VLOOKUP(H12,Sheet4!A:C,3,0) -> #N/A
B13: Faculty Travel | C13: Worku Negash | D13: Faculty Travel & Conference | G13: E | H13: 100_290100_6600_55210_819 | I13: 28800 | J13: =VLOOKUP(H13,'cognos as of Aug 2'!A:F,6,0) -> 28800 | K13: =VLOOKUP(H13,'cognos as of Aug 2'!A:G,7,0) -> 15059.32 | M13: =SUM(I13+L13) -> 28800 | O13: =M13+N13 -> 28800 | P13: =VLOOKUP(H13,Sheet4!A:C,3,0) -> 0
B14: VP Admin. Services | C14: Worku Negash | D14: Tenure Faculty | G14: E | H14: 100_220910_4900_51310_819 | I14: 11000 | J14: =VLOOKUP(H14,'cognos as of Aug 2'!A:F,6,0) -> 11000 | K14: =VLOOKUP(H14,'cognos as of Aug 2'!A:G,7,0) -> 11000 | L14: 5500 | M14: =SUM(I14+L14) -> 16500 | O14: =M14+N14 -> 16500 | P14: =VLOOKUP(H14,Sheet4!A:C,3,0) -> 0
B15: Dean of Instr, Lib. St/LA | C15: Worku Negash | D15: Tricore, Link + Consortium, Library Maintenance | G15: A | H15: 100_230000_6120_55510_819 | I15: 33700 | J15: 33700 | K15: ='cognos as of Aug 2'!G86 -> 32592.83 | L15: 3894 | M15: =SUM(I15+L15) -> 37594 | O15: =M15+N15 -> 37594 | P15: =VLOOKUP(H15,Sheet4!A:C,3,0) -> multiple
B16: Dean of Instr, Lib. St/LA | D16: Turnkey Server Migration (One-Time) | F16: additional cost | G16: A | H16: 100_230000_6120_55510_819 | L16: 2250 | M16: =SUM(I16+L16) -> 2250 | N16: 2627 | O16: =M16+N16 -> 4877 | P16: =VLOOKUP(H16,Sheet4!A:C,3,0) -> multiple
H17: 100_290200_6110_55510_819 | K17: ='cognos as of Aug 2'!G103 -> 378.87 | O17: =M17+N17 -> 0
B18: VP Admin. Services | C18: Worku Negash | D18: Insurance for PE and Athletics Students | G18: C, D | H18: 100_220000_6440_55940_819 | I18: 73711 | J18: =VLOOKUP(H18,'cognos as of Aug 2'!A:F,6,0) -> 72074 | K18: =VLOOKUP(H18,'cognos as of Aug 2'!A:G,7,0) -> 73712 | M18: =SUM(I18+L18) -> 73711 | O18: =M18+N18 -> 73711 | P18: =VLOOKUP(H18,Sheet4!A:C,3,0) -> 0
B19: VP Admin. Services | C19: Worku Negash | D19: Coaches Stipends (Negotiated Item) | G19: E | H19: 100_220000_6770_51450_819 | I19: 15000 | J19: =VLOOKUP(H19,'cognos as of Aug 2'!A:F,6,0) -> 15000 | K19: 16464.69 | M19: =SUM(I19+L19) -> 15000 | O19: =M19+N19 -> 15000 | P19: =VLOOKUP(H19,Sheet4!A:C,3,0) -> 0
B20: College President | D20: Accreditation - Supplies/Materials | F20: Accreditation preparation | G20: C | H20: 100_200700_6090_54210_819 | I20: 0 | M20: =SUM(I20+L20) -> 0 | N20: 10000 | O20: =M20+N20 -> 10000 | P20: =VLOOKUP(H20,Sheet4!A:C,3,0) -> 0
B21: College President | D21: Accreditation - Professional Services | G21: C | H21: 100_200700_6090_55120_819 | I21: 0 | M21: =SUM(I21+L21) -> 0 | O21: =M21+N21 -> 0 | P21: =VLOOKUP(H21,Sheet4!A:C,3,0) -> 0
B22: College President | C22: Worku Negash | D22: Accreditation - Dues, Memberships & Fees | G22: C | H22: 100_200700_6090_55910_819 | I22: 17453 | J22: =VLOOKUP(H22,'cognos as of Aug 2'!A:F,6,0) -> 17453 | K22: =VLOOKUP(H22,'cognos as of Aug 2'!A:G,7,0) -> 17453 | M22: =SUM(I22+L22) -> 17453 | O22: =M22+N22 -> 17453 | P22: =VLOOKUP(H22,Sheet4!A:C,3,0) -> 0
B23: VP Admin. Services | C23: Linda Francis/Virginia | D23: Categorical Program: Transfer Out, Fringe Benefits | G23: C | H23: 100_220001_7310_57300_819 | I23: 370397 | J23: =VLOOKUP(H23,'cognos as of Aug 2'!A:F,6,0) -> 370397 | K23: =VLOOKUP(H23,'cognos as of Aug 2'!A:G,7,0) -> 332322.45 | L23: -30000 | M23: =SUM(I23+L23) -> 340397 | O23: =M23+N23 -> 340397 | P23: =VLOOKUP(H23,Sheet4!A:C,3,0) -> 0
B24: VP Admin. Services | C24: Linda Francis/Virginia | D24: Financial Aid Match: SEOG & Fed Work Study | F24: annual subs. refund/FA disburs. | G24: C | H24: 100_220002_7310_57300_819 | I24: 82111 | J24: 82111 | K24: ='cognos as of Aug 2'!G77 -> 79869 | M24: =SUM(I24+L24) -> 82111 | N24: 5902 | O24: =M24+N24 -> 88013 | P24: =VLOOKUP(H24,Sheet4!A:C,3,0) -> 0
B25: VP Admin. Services | D25: HigherOne | F25: New | G25: D | H25: 100_220900_6490_55160_819 | N25: 2500 | O25: =M25+N25 -> 2500
B26: Dir of Information Syst | C26: Worku Negash | D26: Astra Schedule/LaserFiche Avante/FormFusion | G26: A | H26: 100_220007_6010_55500_819 | I26: 0 | L26: 19057 | M26: =SUM(I26+L26) -> 19057 | O26: =M26+N26 -> 19057 | P26: =VLOOKUP(H26,Sheet4!A:C,3,0) -> 0
B27: Dir of Information Syst | C27: Worku Negash | D27: Curricunet | F27: 4% rebate for 12/13 | G27: A | H27: 100_220000_6010_55160_819 | I27: 7500 | J27: =VLOOKUP(H27,'cognos as of Aug 2'!A:F,6,0) -> 7800 | K27: =VLOOKUP(H27,'cognos as of Aug 2'!A:G,7,0) -> 7800 | L27: 300 | M27: =SUM(I27+L27) -> 7800 | N27: =-642/2 -> -321 | O27: =M27+N27 -> 7479 | P27: =VLOOKUP(H27,Sheet4!A:C,3,0) -> 0
B28: Dir of Information Syst | C28: Ron Smith | D28: CLARIS Class TRACKS | G28: A | H28: 100_220003_6750_55500_819 | I28: 2343 | J28: =VLOOKUP(H28,'cognos as of Aug 2'!A:F,6,0) -> 2343 | K28: =VLOOKUP(H28,'cognos as of Aug 2'!A:G,7,0) -> 0 | L28: -2343 | M28: =SUM(I28+L28) -> 0 | O28: =M28+N28 -> 0 | P28: =VLOOKUP(H28,Sheet4!A:C,3,0) -> 0
B29: Dir of Information Syst | C29: Ron Smith | D29: SARS Software Products -Counseling Sched System | G29: A | H29: 100_220004_6150_55500_819 | I29: 5670 | J29: 5670 | K29: ='cognos as of Aug 2'!G98 -> 6204.45 | L29: 830 | M29: =SUM(I29+L29) -> 6500 | O29: =M29+N29 -> 6500 | P29: =VLOOKUP(H29,Sheet4!A:C,3,0) -> 0
B30: Dir of Information Syst | C30: Ron Smith | D30: Angel | G30: A | H30: 100_220005_6150_55500_819 | I30: 75190 | J30: =VLOOKUP(H30,'cognos as of Aug 2'!A:F,6,0) -> 76527 | K30: =VLOOKUP(H30,'cognos as of Aug 2'!A:G,7,0) -> 57394.87 | L30: 3501 | M30: =SUM(I30+L30) -> 78691 | O30: =M30+N30 -> 78691 | P30: =VLOOKUP(H30,Sheet4!A:C,3,0) -> 0
B31: Dir of Information Syst | C31: Ron Smith | D31: CCCApply / BOGS (Student-Right-to-know) | G31: A | H31: 100_220006_6150_55500_819 | I31: 11259 | J31: =VLOOKUP(H31,'cognos as of Aug 2'!A:F,6,0) -> 11259 | K31: =VLOOKUP(H31,'cognos as of Aug 2'!A:G,7,0) -> 15384 | L31: 4350 | M31: =SUM(I31+L31) -> 15609 | O31: =M31+N31 -> 15609 | P31: =VLOOKUP(H31,Sheet4!A:C,3,0) -> 0
H32: Total Mission College | I32: 742634 | J32: =SUM(J7,J12,J13:J19,J22,J23:J31) -> 742634 | K32: =SUM(K7,K12,K13:K19,K22,K23:K31) -> 673922.42 | L32: =SUM(L7,L12,L13:L19,L22,L23:L31) -> 7339 | M32: =SUM(M7,M12:M31) -> 749973 | N32: =SUM(N7,N12:N31) -> 20708 | O32: =SUM(O7,O12:O31) -> 770681
M33: =SUM(I32+L32) -> 749973
B34: WEST VALLEY COLLEGE
B35: Budget | I35: 11/12 | J35: 0.91666667 | K35: Actual Exp | L35: Budget Adjust. | M35: 12/13 | N35: Budget Adjust. | O35: 12/13
B36: Responsibility | C36: Contact Info. | D36: Fixed Cost Description | E36: Detail Description | F36: Explanation for Adjustments | G36: Criteria | H36: Account Number | I36: Adopt Bud | J36: Working Bud | K36: as of 6/30/12 | L36: Incr / (Decr) | M36: Tent Bud | N36: Incr / (Decr) | O36: Adopt Bud
D37: Academic Senate -to be funded from other source | H37: 100_119304_6750_55115_819 | I37: 1100 | J37: =VLOOKUP(H37,'cognos as of Aug 2'!A:F,6,0) -> 1100 | K37: =VLOOKUP(H37,'cognos as of Aug 2'!A:G,7,0) -> 614.73 | M37: =SUM(I37+L37) -> 1100 | P37: =VLOOKUP(H37,Sheet4!A:C,3,0) -> 0
D38: Academic Senate -to be funded from other source | H38: 100_119304_6750_55200_819 | I38: 3300 | J38: =VLOOKUP(H38,'cognos as of Aug 2'!A:F,6,0) -> 3300 | K38: =VLOOKUP(H38,'cognos as of Aug 2'!A:G,7,0) -> 3308.65 | M38: =SUM(I38+L38) -> 3300 | P38: =VLOOKUP(H38,Sheet4!A:C,3,0) -> 0
B39: Senates | C39: Michael Renzi | D39: Academic Senate | G39: C | H39: Multiple account numbers | I39: =SUM(I37:I38) -> 4400 | J39: =SUM(J37:J38) -> 4400 | K39: =SUM(K37:K38) -> 3923.38 | L39: =SUM(L37:L38) -> 0 | M39: =SUM(I39+L39) -> 4400 | O39: =M39+N39 -> 4400 | P39: =VLOOKUP(H39,Sheet4!A:C,3,0) -> #N/A
D40: Classified Senate | H40: 100_119305_6750_55115_819 | I40: 660 | J40: =VLOOKUP(H40,'cognos as of Aug 2'!A:F,6,0) -> 2000 | K40: =VLOOKUP(H40,'cognos as of Aug 2'!A:G,7,0) -> 1685.51 | M40: =SUM(I40+L40) -> 660 | O40: =M40+N40 -> 660 | P40: =VLOOKUP(H40,Sheet4!A:C,3,0) -> 0
...

Sheet 1213T 031712
B1: MISSION COLLEGE
B2: Budget | I2: 11/12 | J2: 0.91666667 | K2: Actual Exp | M2: Available | N2: Budget Adjust. | O2: 12/13
B3: Responsibility | C3: Contact Info. | D3: Fixed Cost Description | F3: Explanation for Adjustments | G3: Criteria | H3: Account Number | I3: Adopt Bud | J3: Working Bud | K3: as of 2/8/12 | L3: Encumb. | M3: Budget | N3: Incr / (Decr) | O3: Tent Bud
D4: Academic Senate - Supplies/Materials | H4: 100_206200_6750_54210_819 | I4: 1000 | J4: 1000 | K4: 0 | L4: 250 | M4: =J4-K4-L4 -> 750 | O4: =SUM(I4+N4) -> 1000
D5: Academic Senate - Travel & Conference | H5: 100_206200_6750_55200_819 | I5: 3000 | J5: 3000 | K5: 1637 | L5: 0 | M5: =J5-K5-L5 -> 1363 | O5: =SUM(I5+N5) -> 3000
B6: Senates | C6: Worku Negash | D6: Academic Senate | G6: C | I6: 4000 | J6: =SUM(J4:J5) -> 4000 | K6: =SUM(K4:K5) -> 1637 | L6: =SUM(L4:L5) -> 250 | M6: =SUM(M4:M5) -> 2113 | N6: =SUM(N4:N5) -> 0 | O6: =SUM(I6+N6) -> 4000
D7: Classified Senate - Hrly classified Salary | H7: 100_206300_6750_52310_819 | I7: 1000 | J7: 1000 | K7: 0 | L7: 0 | M7: =J7-K7-L7 -> 1000 | O7: =SUM(I7+N7) -> 1000
D8: Classified Senate - Supplies/Materials | H8: 100_206300_6750_54210_819 | I8: 500 | J8: 500 | K8: 0 | L8: 0 | M8: =J8-K8-L8 -> 500 | O8: =SUM(I8+N8) -> 500
D9: Classified Senate - Food Services | H9: 100_206300_6750_55115_819 | I9: 1500 | J9: 1500 | K9: 182 | L9: 0 | M9: =J9-K9-L9 -> 1318 | O9: =SUM(I9+N9) -> 1500
D10: Classified Senate - Travel & Conference | H10: 100_206300_6750_55205_819 | I10: 1500 | J10: 1500 | K10: 0 | L10: 0 | M10: =J10-K10-L10 -> 1500 | O10: =SUM(I10+N10) -> 1500
B11: Senates | C11: Worku Negash | D11: Classified Senate | G11: C | I11: 4500 | J11: =SUM(J7:J10) -> 4500 | K11: =SUM(K7:K10) -> 182 | L11: =SUM(L7:L10) -> 0 | M11: =SUM(M7:M10) -> 4318 | N11: =SUM(N7:N10) -> 0 | O11: =SUM(I11+N11) -> 4500
B12: Faculty Travel | C12: Worku Negash | D12: Faculty Travel & Conference | F12: 144 FT Faculty @ $200 each | G12: E | H12: 100_290100_6600_55210_819 | I12: 28800 | J12: 28800 | K12: 3064 | L12: 0 | M12: =J12-K12-L12 -> 25736 | O12: =SUM(I12+N12) -> 28800
B13: VP Admin. Services | C13: Worku Negash | D13: Tenure Faculty | F13: 3 Faculty will receive tenure in 12/13 FY @ $5,500 each | G13: E | H13: 100_220910_4900_51310_819 | I13: 11000 | J13: 11000 | K13: 0 | L13: 0 | M13: =J13-K13-L13 -> 11000 | N13: 5500 | O13: =SUM(I13+N13) -> 16500
B14: Dean of Instr, Lib. St/LA | C14: Worku Negash | D14: Tricore, Link + Consortium, Library Maintenance | F14: Increase in cost | G14: A | H14: 100_230000_6120_55510_819 | I14: 33700 | J14: 33700 | K14: 30824 | L14: 2993 | M14: =J14-K14-L14 -> -117 | N14: 3894 | O14: =SUM(I14+N14) -> 37594
B15: Dean of Instr, Lib. St/LA | D15: Turnkey Server Migration (One-Time) | G15: A | H15: 100_230000_6120_55510_819 | N15: 2250 | O15: =SUM(I15+N15) -> 2250
B16: VP Admin. Services | C16: Worku Negash | D16: Insurance for PE and Athletics Students | G16: C, D | H16: 100_220000_6440_55940_819 | I16: 73711 | J16: 72074 | K16: 73712 | L16: 0 | M16: =J16-K16-L16 -> -1638 | O16: =SUM(I16+N16) -> 73711
B17: VP Admin. Services | C17: Worku Negash | D17: Coaches Stipends (Negotiated Item) | G17: E | H17: 100_220000_6770_51450_819 | I17: 15000 | J17: 15000 | K17: =3750+155+54+75+59+42 -> 4135 | L17: 0 | M17: =J17-K17-L17 -> 10865 | O17: =SUM(I17+N17) -> 15000
B18: College President | D18: Accreditation - Supplies/Materials | H18: 100_200700_6090_54210_819 | I18: 0 | M18: =J18-K18-L18 -> 0 | O18: =SUM(I18+N18) -> 0
B19: College President | D19: Accreditation - Professional Services | H19: 100_200700_6090_55120_819 | I19: 0 | M19: =J19-K19-L19 -> 0 | O19: =SUM(I19+N19) -> 0
B20: College President | D20: Accreditation - Other Reassigned Time | H20: 100_200700_6090_51227_819 | I20: 0 | M20: =J20-K20-L20 -> 0 | O20: =SUM(I20+N20) -> 0
B21: College President | C21: Worku Negash | D21: Accreditation - Dues, Memberships & Fees | G21: C | H21: 100_200700_6090_55910_819 | I21: 17453 | J21: 17453 | K21: 17453 | L21: =SUM(L18:L20) -> 0 | M21: =SUM(M18:M20) -> 0 | O21: =SUM(I21+N21) -> 17453
B22: VP Admin. Services | C22: Linda Francis/Virginia | D22: Categorical Program: Transfer Out, Fringe Benefits | F22: Budget Reduction Plan | G22: C | H22: 100_220001_7310_57300_819 | I22: 370397 | J22: 370397 | K22: 93566 | L22: 0 | M22: =J22-K22-L22 -> 276831 | N22: -30000 | O22: =SUM(I22+N22) -> 340397
B23: VP Admin. Services | C23: Linda Francis/Virginia | D23: Financial Aid Match: SEOG & Fed Work Study | G23: C | H23: 100_220002_7310_57300_819 | I23: 82111 | J23: 82111 | K23: 0 | L23: 0 | M23: =J23-K23-L23 -> 82111 | O23: =SUM(I23+N23) -> 82111
B24: Dir of Information Syst | C24: Worku Negash | D24: Astra Schedule/LaserFiche Avante/FormFusion | F24: New | G24: A | H24: 100_220007_6010_55500_819 | I24: 0 | J24: 0 | K24: 0 | M24: =J24-K24-L24 -> 0 | N24: 19057 | O24: =SUM(I24+N24) -> 19057
B25: Dir of Information Syst | C25: Worku Negash | D25: Curricunet | F25: Increase in cost | G25: A | H25: 100_220000_6010_55160_819 | I25: 7500 | J25: 7800 | K25: 7800 | M25: =J25-K25-L25 -> 0 | N25: 300 | O25: =SUM(I25+N25) -> 7800
B26: Dir of Information Syst | C26: Ron Smith | D26: CLARIS Class TRACKS | F26: No longer need | G26: A | H26: 100_220003_6750_55500_819 | I26: 2343 | J26: 2343 | K26: 0 | L26: 0 | M26: =J26-K26-L26 -> 2343 | N26: -2343 | O26: =SUM(I26+N26) -> 0
B27: Dir of Information Syst | C27: Ron Smith | D27: SARS Software Products -Counseling Sched System | F27: Increase in cost | G27: A | H27: 100_220004_6150_55500_819 | I27: 5670 | J27: 5670 | K27: 6204 | L27: 0 | M27: =J27-K27-L27 -> -534 | N27: 830 | O27: =SUM(I27+N27) -> 6500
B28: Dir of Information Syst | C28: Ron Smith | D28: Angel | F28: Increase in cost | G28: A | H28: 100_220005_6150_55500_819 | I28: 75190 | J28: 76527 | K28: 76527 | L28: 0 | M28: =J28-K28-L28 -> 0 | N28: 3501 | O28: =SUM(I28+N28) -> 78691
B29: Dir of Information Syst | C29: Ron Smith | D29: CCCApply / BOGS (Student-Right-to-know) | F29: Increase in cost | G29: A | H29: 100_220006_6150_55500_819 | I29: 11259 | J29: 11259 | K29: 15384 | M29: =J29-K29-L29 -> -4125 | N29: 4350 | O29: =SUM(I29+N29) -> 15609
H30: Total Mission College | I30: 742634 | J30: =SUM(J6,J11,J12:J17,J21,J22:J29) -> 742634 | K30: =SUM(K6,K11,K12:K17,K21,K22:K29) -> 330488 | L30: =SUM(L6,L11,L12:L17,L21,L22:L29) -> 3243 | M30: =SUM(M6,M11,M12:M17,M21,M22:M29) -> 408903 | N30: =SUM(N6,N11,N12:N17,N21,N22:N29) -> 7339 | O30: =SUM(O6,O11:O29) -> 749973
O31: =SUM(I30+N30) -> 749973
B32: WEST VALLEY COLLEGE
B33: Budget | I33: 11/12 | J33: 0.91666667 | K33: Actual Exp | M33: Available | N33: Budget Adjust. | O33: 12/13
B34: Responsibility | C34: Contact Info. | D34: Fixed Cost Description | E34: Detail Description | F34: Explanation for Adjustments | G34: Criteria | H34: Account Number | I34: Adopt Bud | J34: Working Bud | K34: as of 2/8/12 | L34: Encumb. | M34: Budget | N34: Incr / (Decr) | O34: Tent Bud
D35: Academic Senate -to be funded from other source | H35: 100_119304_6750_55115_819 | I35: 1100 | J35: 1100 | K35: 615 | L35: 0 | M35: =J35-K35 -> 485 | O35: =SUM(I35+N35) -> 1100
D36: Academic Senate -to be funded from other source | H36: 100_119304_6750_55200_819 | I36: 3300 | J36: 3300 | K36: 378 | L36: 0 | M36: =J36-K36 -> 2922 | O36: =SUM(I36+N36) -> 3300
B37: Senates | C37: Michael Renzi | D37: Academic Senate | G37: C | I37: =SUM(I35:I36) -> 4400 | J37: =SUM(J35:J36) -> 4400 | K37: =SUM(K35:K36) -> 993 | L37: =SUM(L35:L36) -> 0 | M37: =SUM(M35:M36) -> 3407 | N37: =SUM(N35:N36) -> 0 | O37: =SUM(I37+N37) -> 4400
D38: Classified Senate | H38: 100_119305_6750_55115_819 | I38: 660 | J38: 660 | K38: 0 | L38: 0 | M38: =J38-K38 -> 660 | O38: =SUM(I38+N38) -> 660
D39: Classified Senate | H39: 100_119305_6750_55160_819 | I39: 440 | J39: 440 | K39: 100 | L39: 0 | M39: =J39-K39 -> 340 | O39: =SUM(I39+N39) -> 440
D40: Classified Senate | H40: 100_119305_6750_55200_819 | I40: 3300 | J40: 3300 | K40: 0 | L40: 0 | M40: =J40-K40 -> 3300 | O40: =SUM(I40+N40) -> 3300
...

Sheet 1112Adopt
B1: MISSION COLLEGE | L1: Report on 7/18/11
B2: Budget | J2: 10/11 | K2: 0.90909091 | L2: Actual Exp | N2: Available | O2: Budget Adjust. | P2: 11/12 | Q2: Budget Adjust. | R2: 11/12
B3: Responsibility | C3: Contact Info. | D3: Fixed Cost Description | F3: Explanation for Adjustments | G3: Criteria | H3: Account Number | J3: Adopt Bud | K3: Working Bud | L3: as of 6/30/11 | M3: Encumb. | N3: Budget | O3: Incr / (Decr) | P3: Tent Bud | Q3: Incr / (Decr) | R3: Adopt Bud | T3: Actual Adjust.
D4: Academic Senate - Supplies/Materials | H4: 100_206200_6750_54210_819 | J4: 1000 | K4: 0 | L4: 0 | M4: 0 | N4: =K4-L4-M4 -> 0 | O4: 0 | P4: 1000 | Q4: 0 | R4: =SUM(P4:Q4) -> 1000 | X4: 0
D5: Academic Senate - Travel & Conference | H5: 100_206200_6750_55200_819 | J5: 3000 | K5: 4042 | L5: 3915 | M5: 0 | N5: =K5-L5-M5 -> 127 | O5: 0 | P5: 3000 | Q5: 0 | R5: =SUM(P5:Q5) -> 3000 | X5: 3914.72 | Y5: =L5-X5 -> 0.28
B6: Staff Development | C6: Worku Negash | D6: Academic Senate | G6: C | I6: X | J6: =SUM(J4:J5) -> 4000 | K6: =SUM(K4:K5) -> 4042 | L6: =SUM(L4:L5) -> 3915 | M6: =SUM(M4:M5) -> 0 | N6: =SUM(N4:N5) -> 127 | O6: 0 | P6: 4000 | Q6: 0 | R6: =SUM(P6:Q6) -> 4000 | Y6: =L6-X6 -> 3915
D7: Classified Senate - Hrly classified Salary | H7: 100_206300_6750_52310_819 | I7: X | J7: 1000 | K7: 0 | L7: 0 | M7: 0 | N7: =K7-L7-M7 -> 0 | O7: 0 | P7: 1000 | Q7: 0 | R7: =SUM(P7:Q7) -> 1000 | X7: 0 | Y7: =L7-X7 -> 0
D8: Classified Senate - Supplies/Materials | H8: 100_206300_6750_54210_819 | I8: X | J8: 500 | K8: 500 | L8: 488 | M8: 0 | N8: =K8-L8-M8 -> 12 | O8: 0 | P8: 500 | Q8: 0 | R8: =SUM(P8:Q8) -> 500 | X8: 488.48 | Y8: =L8-X8 -> -0.48
D9: Classified Senate - Food Services | H9: 100_206300_6750_55115_819 | I9: X | J9: 1500 | K9: 2500 | L9: 2500 | M9: 0 | N9: =K9-L9-M9 -> 0 | O9: 0 | P9: 1500 | Q9: 0 | R9: =SUM(P9:Q9) -> 1500 | X9: 2499.74 | Y9: =L9-X9 -> 0.26
D10: Classified Senate - Travel & Conference | H10: 100_206300_6750_55205_819 | I10: X | J10: 1500 | K10: 1500 | L10: 1500 | M10: 0 | N10: =K10-L10-M10 -> 0 | O10: 0 | P10: 1500 | Q10: 0 | R10: =SUM(P10:Q10) -> 1500 | X10: 1500 | Y10: =L10-X10 -> 0
B11: Staff Development | C11: Worku Negash | D11: Classified Senate | G11: C | J11: =SUM(J7:J10) -> 4500 | K11: =SUM(K7:K10) -> 4500 | L11: =SUM(L7:L10) -> 4488 | M11: =SUM(M7:M10) -> 0 | N11: =SUM(N7:N10) -> 12 | O11: 0 | P11: 4500 | Q11: 0 | R11: =SUM(P11:Q11) -> 4500 | Y11: =L11-X11 -> 4488
A12: DW | B12: Dir of Information Syst | C12: Worku Negash | D12: Curricunet | F12: Move from District Wide | G12: A | H12: 100_220000_6010_55160_819 | I12: X | J12: 7500 | K12: 7500 | L12: 7500 | M12: 0 | N12: =K12-L12-M12 -> 0 | O12: -7500 | P12: 0 | Q12: 7500 | R12: =SUM(P12:Q12) -> 7500 | X12: 7500 | Y12: =L12-X12 -> 0
B13: Faculty Travel | C13: Worku Negash | D13: Faculty Travel & Conference | F13: 144 FT Faculty @ $200 each | G13: E | H13: 100_290100_6600_55210_819 | I13: X | J13: 30000 | K13: 30000 | L13: 11208.73 | M13: 0 | N13: =K13-L13-M13 -> 18791.27 | O13: 0 | P13: 30000 | Q13: -1200 | R13: =SUM(P13:Q13) -> 28800 | T13: -1200 | X13: 11208.73 | Y13: =L13-X13 -> 0
B14: VP Admin. Services | C14: Worku Negash | D14: Tenure Faculty | F14: 2 Faculty will receive tenure in 11/12 FY | G14: E | H14: 100_220910_4900_51310_819 | I14: X | J14: 25000 | K14: 25000 | L14: 27500 | M14: 0 | N14: =K14-L14-M14 -> -2500 | O14: -14000 | P14: 11000 | Q14: 0 | R14: =SUM(P14:Q14) -> 11000 | S14: 11 | X14: 27500 | Y14: =L14-X14 -> 0
B15: VP Admin. Services | C15: Worku Negash | D15: Tricore, Link + Consortium, Library Maintenance | G15: A | H15: 100_220000_6120_55510_819 | I15: X | J15: 33700 | K15: 34005 | L15: 34005 | N15: =K15-L15-M15 -> 0 | O15: 0 | P15: 33700 | Q15: 0 | R15: =SUM(P15:Q15) -> 33700 | Y15: =L15-X15 -> 34005
B16: VP Admin. Services | C16: Worku Negash | D16: Insurance for PE and Athletics Students | G16: C, D | H16: 100_220000_6440_55940_819 | I16: X | J16: 28038 | K16: 28336 | L16: 28336 | M16: 0 | N16: =K16-L16-M16 -> 0 | O16: 0 | P16: 28038 | Q16: 45673 | R16: =SUM(P16:Q16) -> 73711 | T16: 45673 | X16: 28336 | Y16: =L16-X16 -> 0
B17: VP Admin. Services | C17: Worku Negash | D17: Coaches Stipends (Negotiated Item) | G17: E | H17: 100_220000_6770_51450_819 | I17: X | J17: 15000 | K17: 15000 | L17: =15000+928+218+75+107+172 -> 16500 | M17: 0 | N17: =K17-L17-M17 -> -1500 | O17: 0 | P17: 15000 | Q17: 0 | R17: =SUM(P17:Q17) -> 15000 | X17: 15000 | Y17: =L17-X17 -> 1500
D18: Accreditation - Supplies/Materials | H18: 100_200700_6090_54210_819 | I18: X | J18: 11900 | K18: 11900 | L18: 11900 | M18: 0 | N18: =K18-L18-M18 -> 0 | O18: -11900 | P18: 0 | Q18: 0 | R18: =SUM(P18:Q18) -> 0 | X18: 11899.4 | Y18: =L18-X18 -> 0.6
D19: Accreditation - Professional Services | H19: 100_200700_6090_55120_819 | I19: X | J19: 350 | K19: 700 | L19: 0 | M19: 0 | N19: =K19-L19-M19 -> 700 | O19: -350 | P19: 0 | Q19: 0 | R19: =SUM(P19:Q19) -> 0 | X19: 0 | Y19: =L19-X19 -> 0
D20: Accreditation - Other Reassigned Time | H20: 100_200700_6090_51227_819 | I20: X | J20: 2750 | K20: 2750 | L20: 0 | M20: 0 | N20: =K20-L20-M20 -> 2750 | O20: -2750 | P20: 0 | Q20: 0 | R20: =SUM(P20:Q20) -> 0 | X20: 0 | Y20: =L20-X20 -> 0
D21: Accreditation - Dues, Memberships & Fees | H21: 100_200700_6090_55910_819 | I21: X | J21: 17453 | K21: 16850 | L21: 16850 | M21: 0 | N21: =K21-L21-M21 -> 0 | O21: 0 | P21: 17453 | Q21: 0 | R21: =SUM(P21:Q21) -> 17453 | X21: 16850 | Y21: =L21-X21 -> 0
B22: College President | C22: Worku Negash | D22: Accreditation | G22: C | J22: =SUM(J18:J21) -> 32453 | K22: =SUM(K18:K21) -> 32200 | L22: =SUM(L18:L21) -> 28750 | M22: =SUM(M18:M21) -> 0 | N22: =SUM(N18:N21) -> 3450 | O22: -15000 | P22: 17453 | Q22: 0 | R22: =SUM(P22:Q22) -> 17453 | S22: 12 | Y22: =L22-X22 -> 28750
B23: Marketing and Communications | C23: Worku Negash | D23: Schedule of classes and catalog | F23: Remove from fixed cost | H23: 100_201000_6770_51450_819 | I23: X | J23: 0 | K23: 800 | L23: =364+5+15+3+4 -> 391 | M23: 0 | N23: =K23-L23-M23 -> 409 | O23: 0 | P23: 0 | Q23: 0 | R23: =SUM(P23:Q23) -> 0 | X23: 364.23 | Y23: =L23-X23 -> 26.77
B24: Marketing and Communications | C24: Worku Negash | D24: Schedule of classes and catalog | F24: Remove from fixed cost | H24: 100_201000_6770_55300_819 | I24: X | J24: 70000 | K24: =45919+12247+8392 -> 66558 | L24: =45919+12246.56+8391.94 -> 66557.5 | N24: =K24-L24-M24 -> 0.5 | O24: 0 | P24: 0 | Q24: 0 | R24: =SUM(P24:Q24) -> 0 | X24: 45918.59 | Y24: =L24-X24 -> 20638.91
B25: Marketing and Communications | C25: Worku Negash | D25: Schedule of classes and catalog | F25: Remove from fixed cost | H25: 100_201000_6770_55921_819 | I25: X | J25: 0 | K25: 2250 | L25: 2250 | M25: 0 | N25: =K25-L25-M25 -> 0 | O25: 0 | P25: 0 | Q25: 0 | R25: 0 | X25: 2250 | Y25: =L25-X25 -> 0
B26: Marketing and Communications | C26: Worku Negash | D26: Schedule of classes and catalog | F26: Remove from fixed cost | J26: =SUM(J23:J25) -> 70000 | K26: =SUM(K23:K25) -> 69608 | L26: =SUM(L23:L25) -> 69198.5 | M26: =SUM(M23:M25) -> 0 | N26: =SUM(N23:N24) -> 409.5 | O26: -70000 | P26: =SUM(P23:P24) -> 0 | Q26: =SUM(Q23:Q24) -> 0 | R26: =SUM(R23:R24) -> 0 | Y26: =L26-X26 -> 69198.5
A27: DW | B27: VC Admin Serv | C27: Linda Francis/Virginia | D27: Categorical Program: Transfer Out, Fringe Benefits | F27: Move from District Wide | G27: C | H27: 100_220001_6600_57300_819 | J27: 0 | K27: 0 | L27: 0 | M27: 0 | N27: 0 | O27: 0 | P27: 0 | Q27: =397684-27287 -> 370397 | R27: =SUM(P27:Q27) -> 370397 | T27: -27287 | X27: 779399.15 | Y27: =L27-X27 -> -779399.15
A28: DW | B28: VC Admin Serv | C28: Linda Francis/Virginia | D28: Financial Aid Match: SEOG & Fed Work Study | F28: Move from District Wide | G28: C | H28: 100_220002_6600_57300_819 | J28: 0 | K28: 0 | L28: 0 | M28: 0 | N28: =SUM(K27:K28)-L28-M28 -> 0 | O28: 0 | P28: 0 | Q28: 82111 | R28: =SUM(P28:Q28) -> 82111 | X28: 779399.15 | Y28: =L28-X28 -> -779399.15
A29: DW | B29: Dir of Information Syst | C29: Ron Smith | D29: CLARIS Class TRACKS | F29: Move from District Wide | G29: A | H29: 100_220003_6750_55500_819 | J29: 0 | K29: 0 | L29: 0 | M29: 0 | N29: 0 | O29: 0 | P29: 0 | Q29: 2343 | R29: =SUM(P29:Q29) -> 2343 | X29: 177854.54 | Y29: =L29-X29 -> -177854.54
A30: DW | B30: Dir of Information Syst | C30: Ron Smith | D30: SARS Software Products -Counseling Sched System | F30: Move from District Wide | G30: A | H30: 100_220004_6750_55500_819 | J30: 0 | K30: 0 | L30: 0 | M30: 0 | N30: =SUM(J29:J30)-L30-M30 -> 0 | O30: 0 | P30: 0 | Q30: 5670 | R30: =SUM(P30:Q30) -> 5670 | X30: 177854.54 | Y30: =L30-X30 -> -177854.54
A31: DW | B31: Dir of Information Syst | C31: Ron Smith | D31: Angel | F31: Move from District Wide | G31: A | H31: 100_220005_6150_55500_819 | J31: 0 | K31: 0 | L31: 0 | M31: 0 | N31: 0 | O31: 0 | P31: 0 | Q31: 75190 | R31: =SUM(P31:Q31) -> 75190 | X31: 113705.4 | Y31: =L31-X31 -> -113705.4
A32: DW | B32: Dir of Information Syst | C32: Ron Smith | D32: CCCApply | F32: Move from District Wide | G32: A | H32: 100_220006_6150_55500_819 | J32: 0 | K32: 0 | L32: 0 | M32: 0 | N32: =SUM(K31:K32)-L32-M32 -> 0 | O32: 0 | P32: 0 | Q32: 11259 | R32: =SUM(P32:Q32) -> 11259 | X32: 113705.4 | Y32: =L32-X32 -> -113705.4
H33: Total Mission College | J33: =SUM(J6,J11:J17,J22,J26:J32) -> 250191 | K33: =SUM(K6,K11:K17,K22,K26:K32) -> 250191 | L33: =SUM(L6,L11:L17,L22,L26:L32) -> 231401.23 | M33: =SUM(M6,M11:M17,M22,M26:M32) -> 0 | N33: =SUM(N6,N11:N17,N22,N26:N32) -> 18789.77 | O33: =SUM(O6,O11:O17,O22,O26:O32) -> -106500 | P33: =SUM(P6,P11:P17,P22,P26:P32) -> 143691 | Q33: =SUM(Q6,Q11:Q17,Q22,Q26:Q32) -> 598943 | R33: =SUM(R6,R11:R17,R22,R26:R32) -> 742634 | Y33: =L33-X33 -> 231401.23
J34: √ | O34: √ | P34: √ | Y34: =L34-X34 -> 0
B35: WEST VALLEY COLLEGE | Y35: =L35-X35 -> 0
