Workbook
Name AdjHigh: 'Adjustment Info'!$A$6
Name AdjLow: 'Adjustment Info'!$A$7
Name AllRacesFemalePop: RegistryInfo!$A$10
Name AllRacesMalePop: RegistryInfo!$A$9
Name AllRacesTotalPop: RegistryInfo!$A$12
Name BlackComplete: Blacks!$P$52
Name BlackFemalePop: RegistryInfo!$A$15
Name BlackMalePop: RegistryInfo!$A$14
Name BlackPop: RegistryInfo!$A$13
Name CaseEnd: 'Adjustment Info'!$B$13
Name CaseStart: 'Adjustment Info'!$A$13
Name CaseYear: RegistryInfo!$A$4
Name IncidenceCases: RegistryInfo!$A$6
Name mortdata: #REF!
Name PercentDups: RegistryInfo!$A$7
Name pops: #REF!
Name PopSexData: 'Pops by Race and Sex'!$1:$1048576
Name RaceSexRegistry: 'Pops by Race and Sex'!$A$8:$A$78
Name RateData: 'SEER US MORT Rates'!$A:$BC
Name RefSiteBF: 'SEER US MORT Rates'!$D$88:$D$106
Name RefSiteBM: 'SEER US MORT Rates'!$D$62:$D$78
Name RefSiteWF: 'SEER US MORT Rates'!$D$34:$D$52
Name RefSiteWM: 'SEER US MORT Rates'!$D$9:$D$25
Name registries: RegistryInfo!$H:$I
Name Registry: RegistryInfo!$A$5
Name Registry_Type: RegistryInfo!$D$5
Name RegMCurrentEnd: 'Adjustment Info'!$B$14
Name RegMCurrentStart: 'Adjustment Info'!$A$14
Name RegMRefEnd: 'Adjustment Info'!$B$15
Name RegMRefStart: 'Adjustment Info'!$A$15
Name seerData: #REF!
Name SEEREnd: 'Adjustment Info'!$B$16
Name SEERStart: 'Adjustment Info'!$A$16
Name summary_pops: RegistryInfo!$K$1:$P$2
Name USMortEnd: 'Adjustment Info'!$B$17
Name USMortStart: 'Adjustment Info'!$A$17
Name WhiteComplete: Whites!$P$52
Name WhiteFemalePop: RegistryInfo!$A$11
Name WhiteMalePop: RegistryInfo!$A$10
Name WhitePop: RegistryInfo!$A$9

Sheet Completeness Report
A1: ='Adjustment Info'!A1 -> Worksheet for Completeness of Case Ascertainment, version 2.2.b
A2: ='Adjustment Info'!A2 -> Alabama, Year of Diagnosis 2010
A4: Interim Completeness Estimates
A5: Adjusted for Reference Mortality
A7: Whites | C7: =IF($A$30=2,"All Races","Blacks") -> Blacks | E7: Race Proportional
A8: Percent | C8: Percent | E8: Percent
A9: Complete | B9: Population | C9: Complete | D9: Population | E9: Complete | F9: Population
A10: =WhiteComplete -> 0 | B10: =WhitePop -> 3401085 | C10: =IF(Registry_Type=2,WhiteComplete,BlackComplete) -> 0 | D10: =IF(Registry_Type=2,AllRacesTotalPop,BlackPop) -> 1283143 | E10: =((A10*B10)+(C10*D10))/F10 -> 0 | F10: =WhitePop+BlackPop -> 4684228
A13: Final Completeness Estimates
A14: Adjusted for Reference Mortality and Duplicate Records
A16: =IncidenceCases -> 0 | B16: ="Total Incidence Cases, "&CaseYear -> Total Incidence Cases, 2010
A17: =PercentDups -> 0 | B17: Percent Duplicate Records
A18: =IF(Registry_Type=4,E10,C10) -> 0 | B18: Race Proportional Completeness, Adjusted for Reference Mortality
A19: =A16-(A16*A17/100) -> 0 | B19: =CaseYear&" Adjusted Total Incidence Cases" -> 2010 Adjusted Total Incidence Cases
A20: =IF(A18=0,0,A16/A18) -> 0 | B20: =CaseYear&" Expected Incidence Cases" -> 2010 Expected Incidence Cases
A22: =IF(A20=0,0,A19/A20) -> 0 | B22: ="Final Completeness Estimate for "&CaseYear&", "&Registry -> Final Completeness Estimate for 2010, Alabama
B23: ="Adjusted for Reference Mortality and Duplicate Records" -> Adjusted for Reference Mortality and Duplicate Records
A30: =Registry_Type -> 4

Sheet RegistryInfo
A1: ='Adjustment Info'!A1 -> Worksheet for Completeness of Case Ascertainment, version 2.2.b | H1: Alabama | I1: 4 | J1: 2010 | K1: 2 | L1: ="Populations for All Races in "&TRIM(Registry)&" for "&CaseYear -> Populations for All Races in Alabama for 2010 | M1: ="Populations for All Races, Males, in "&TRIM(Registry)&" for "&CaseYear -> Populations for All Races, Males, in Alabama for 2010 | N1: ="Populations for All Races, Females, in "&TRIM(Registry)&" for "&CaseYear -> Populations for All Races, Females, in Alabama for 2010
A2: =TRIM('Adjustment Info'!A2) -> Alabama, Year of Diagnosis 2010 | H2: Alaska | I2: 4 | J2: 2009 | K2: 4 | L2: ="Populations for Whites in "&TRIM(Registry)&" for "&CaseYear -> Populations for Whites in Alabama for 2010 | M2: ="Populations for White Males in "&TRIM(Registry)&" for "&CaseYear -> Populations for White Males in Alabama for 2010 | N2: ="Populations for White Females in "&TRIM(Registry)&" for "&CaseYear -> Populations for White Females in Alabama for 2010
H3: Arizona | I3: 4 | J3: 2008
A4: 2010 | B4: Calendar Year for Case Completeness Ascertainment | H4: Arkansas | I4: 4 | J4: 2007
A5: Alabama | B5: Registry Area | D5: =VLOOKUP(Registry,registries,2,FALSE) -> 4 | H5: California | I5: 4 | J5: 2006
B6: ="Total Incidence Cases in "&TRIM(Registry)&" for "&CaseYear -> Total Incidence Cases in Alabama for 2010 | H6: CA - Greater Bay | I6: 4 | J6: 2005
B7: Percent Duplicate Records, per NAACCR Protocol | H7: CA - Greater California | I7: 4 | J7: 2004
H8: CA - Los Angeles | I8: 4 | J8: 2003
A9: =IF(Registry_Type=4,WhiteMalePop+WhiteFemalePop,VLOOKUP(Registry, PopSexData, 6*(CaseYear-1995)+D5, 0)) -> 3401085 | B9: =IF(Registry_Type=4,VLOOKUP($D$5,summary_pops,2,0),VLOOKUP(Registry_Type,summary_pops,3,0)) -> Populations for Whites in Alabama for 2010 | H9: Colorado | I9: 4 | J9: 2002
A10: =IF(Registry_Type=4,VLOOKUP(Registry,PopSexData,6*(CaseYear-1995)+D5,0),VLOOKUP(Registry,PopSexData,6*(CaseYear-1995)+D5+1,0)) -> 1674201 | B10: =IF(Registry_Type=4,VLOOKUP($D$5,summary_pops,3,0),VLOOKUP(Registry_Type,summary_pops,4,0)) -> Populations for White Males in Alabama for 2010 | H10: Connecticut | I10: 4 | J10: 2001
A11: =VLOOKUP(Registry, PopSexData, 6*(CaseYear-1995)+D5+1, 0) -> 1726884 | B11: =VLOOKUP($D$5,summary_pops,4,0) -> Populations for White Females in Alabama for 2010 | H11: Delaware | I11: 4 | J11: 2000
A12: =IF(ISERROR(AllRacesMalePop+AllRacesFemalePop),"No Pop Data Available",AllRacesMalePop+AllRacesFemalePop) -> 5075286 | B12: ="Total Population, All Races, in "&Registry& " for "&CaseYear -> Total Population, All Races, in Alabama for 2010 | H12: Washington, DC | I12: 4 | J12: 1999
A13: =BlackMalePop+BlackFemalePop -> 1283143 | B13: ="Populations for Blacks in "&TRIM(Registry)&" for "&CaseYear -> Populations for Blacks in Alabama for 2010 | H13: Florida | I13: 4 | J13: 1998
A14: =VLOOKUP(Registry, PopSexData, 6*(CaseYear-1995)+(D5+2), 0) -> 598478 | B14: ="Populations for Black Males in "&TRIM(Registry)&" for "&CaseYear -> Populations for Black Males in Alabama for 2010 | H14: Georgia | I14: 4 | J14: 1997
A15: =VLOOKUP(Registry, PopSexData, 6*(CaseYear-1995)+(D5+3), 0) -> 684665 | B15: ="Populations for Black Females in "&TRIM(Registry)&" for "&CaseYear -> Populations for Black Females in Alabama for 2010 | H15: GA - Metropolitan Atlanta | I15: 2 | J15: 1996
H16: Hawaii | I16: 4 | J16: 1995
A17: =WhitePop+BlackPop -> 4684228 | B17: Total Population, Whites and Blacks | H17: Idaho | I17: 4
H18: Illinois | I18: 4
H19: Indiana | I19: 4
H20: Iowa | I20: 4
H21: Kansas | I21: 4
H22: Kentucky | I22: 4
H23: Louisiana | I23: 4
H24: Maine | I24: 4
H25: Maryland | I25: 4
H26: Massachusetts | I26: 4
H27: Michigan | I27: 4
H28: MI - Metropolitan Detroit | I28: 4
H29: Minnesota | I29: 4
... H70: Saskatchewan | I70: 2
H71: Yukon

Sheet Blacks
C1: ='Adjustment Info'!A1 -> Worksheet for Completeness of Case Ascertainment, version 2.2.b
C2: Registry Incidence and Mortality Rates, Blacks
D4: =Registry -> Alabama | G4: SEER (11 Regs) and US Mortality | J4: Unadjusted Results | L4: Mortality Adjustment Terms | O4: Adjusted for Mortality
C5: Black Males | D5: Age-Adjusted Rates (2000 US) | G5: Age-Adjusted Rates (2000 US) | J5: Expected | K5: Unadjusted | L5: Registry | N5: Adj Reg | O5: Expected | P5: Interim
D6: =CaseYear -> 2010 | E6: =RegMCurrentStart&"-"&TEXT(RegMCurrentEnd,"00") -> 2009-2010 | F6: Inc/Mort | G6: =SEERStart&"-"&TEXT(SEEREnd,"00") -> 2006-2010 | H6: =USMortStart&"-"&TEXT(USMortEnd,"00") -> 2006-2010 | I6: Inc/Mort | J6: Incidence | K6: Percent | L6: =RegMRefStart&"-"&TEXT(RegMRefEnd,"00") -> 2006-2010 | M6: Adjust. | N6: =RegMCurrentStart&"-"&TEXT(RegMCurrentEnd,"00") -> 2009-2010 | O6: Incidence | P6: Percent
C7: Cancer Site | D7: Incidence | E7: Mortality | F7: Ratio | G7: Incidence | H7: Mortality | I7: Ratio | J7: Rate | K7: Complete | L7: Mort Rate | M7: Term | N7: Mort Rate | O7: Rate | P7: Complete
A8: Male | B8: Black | C8: Oral Cavity and Pharynx | F8: =IF(E8=0,0,D8/E8) -> 0 | G8: =VLOOKUP(TRIM(A8)&TRIM(B8)&TRIM(C8), RateData, 3*(CaseYear-1995)+5, 0) -> 14.874658 | H8: =VLOOKUP(TRIM(A8)&TRIM(B8)&TRIM(C8), RateData, 3*(CaseYear-1995)+6, 0) -> 5.1800348 | I8: =G8/H8 -> 2.8715363 | J8: =E8*I8 -> 0 | K8: =IF(J8=0,0,(D8/J8*100)) -> 0 | M8: =IF(H8=0,1,IF(L8=0,1,H8/L8)) -> 1 | N8: =IF(M8<=1,(((1-AdjHigh)*E8)+(AdjHigh*M8*E8)),(((1-AdjLow)*E8)+(AdjLow*M8*E8))) -> 0 | O8: =N8*I8 -> 0 | P8: =IF(O8=0,0,D8/O8*100) -> 0
A9: Male | B9: Black | C9: Esophagus | F9: =IF(E9=0,0,D9/E9) -> 0 | G9: =VLOOKUP(TRIM(A9)&TRIM(B9)&TRIM(C9), RateData, 3*(CaseYear-1995)+5, 0) -> 7.418117 | H9: =VLOOKUP(TRIM(A9)&TRIM(B9)&TRIM(C9), RateData, 3*(CaseYear-1995)+6, 0) -> 7.7210963 | I9: =G9/H9 -> 0.96075955 | J9: =E9*I9 -> 0 | K9: =IF(J9=0,0,(D9/J9*100)) -> 0 | M9: =IF(H9=0,1,IF(L9=0,1,H9/L9)) -> 1 | N9: =IF(M9<=1,(((1-AdjHigh)*E9)+(AdjHigh*M9*E9)),(((1-AdjLow)*E9)+(AdjLow*M9*E9))) -> 0 | O9: =N9*I9 -> 0 | P9: =IF(O9=0,0,D9/O9*100) -> 0
A10: Male | B10: Black | C10: Stomach | F10: =IF(E10=0,0,D10/E10) -> 0 | G10: =VLOOKUP(TRIM(A10)&TRIM(B10)&TRIM(C10), RateData, 3*(CaseYear-1995)+5, 0) -> 15.664557 | H10: =VLOOKUP(TRIM(A10)&TRIM(B10)&TRIM(C10), RateData, 3*(CaseYear-1995)+6, 0) -> 9.8378818 | I10: =G10/H10 -> 1.5922693 | J10: =E10*I10 -> 0 | K10: =IF(J10=0,0,(D10/J10*100)) -> 0 | M10: =IF(H10=0,1,IF(L10=0,1,H10/L10)) -> 1 | N10: =IF(M10<=1,(((1-AdjHigh)*E10)+(AdjHigh*M10*E10)),(((1-AdjLow)*E10)+(AdjLow*M10*E10))) -> 0 | O10: =N10*I10 -> 0 | P10: =IF(O10=0,0,D10/O10*100) -> 0
A11: Male | B11: Black | C11: Colon and Rectum | F11: =IF(E11=0,0,D11/E11) -> 0 | G11: =VLOOKUP(TRIM(A11)&TRIM(B11)&TRIM(C11), RateData, 3*(CaseYear-1995)+5, 0) -> 62.572738 | H11: =VLOOKUP(TRIM(A11)&TRIM(B11)&TRIM(C11), RateData, 3*(CaseYear-1995)+6, 0) -> 28.683925 | I11: =G11/H11 -> 2.1814566 | J11: =E11*I11 -> 0 | K11: =IF(J11=0,0,(D11/J11*100)) -> 0 | M11: =IF(H11=0,1,IF(L11=0,1,H11/L11)) -> 1 | N11: =IF(M11<=1,(((1-AdjHigh)*E11)+(AdjHigh*M11*E11)),(((1-AdjLow)*E11)+(AdjLow*M11*E11))) -> 0 | O11: =N11*I11 -> 0 | P11: =IF(O11=0,0,D11/O11*100) -> 0
A12: Male | B12: Black | C12: Liver | F12: =IF(E12=0,0,D12/E12) -> 0 | G12: =VLOOKUP(TRIM(A12)&TRIM(B12)&TRIM(C12), RateData, 3*(CaseYear-1995)+5, 0) -> 16.826308 | H12: =VLOOKUP(TRIM(A12)&TRIM(B12)&TRIM(C12), RateData, 3*(CaseYear-1995)+6, 0) -> 10.432575 | I12: =G12/H12 -> 1.6128623 | J12: =E12*I12 -> 0 | K12: =IF(J12=0,0,(D12/J12*100)) -> 0 | M12: =IF(H12=0,1,IF(L12=0,1,H12/L12)) -> 1 | N12: =IF(M12<=1,(((1-AdjHigh)*E12)+(AdjHigh*M12*E12)),(((1-AdjLow)*E12)+(AdjLow*M12*E12))) -> 0 | O12: =N12*I12 -> 0 | P12: =IF(O12=0,0,D12/O12*100) -> 0
A13: Male | B13: Black | C13: Pancreas | F13: =IF(E13=0,0,D13/E13) -> 0 | G13: =VLOOKUP(TRIM(A13)&TRIM(B13)&TRIM(C13), RateData, 3*(CaseYear-1995)+5, 0) -> 17.958897 | H13: =VLOOKUP(TRIM(A13)&TRIM(B13)&TRIM(C13), RateData, 3*(CaseYear-1995)+6, 0) -> 15.26801 | I13: =G13/H13 -> 1.1762435 | J13: =E13*I13 -> 0 | K13: =IF(J13=0,0,(D13/J13*100)) -> 0 | M13: =IF(H13=0,1,IF(L13=0,1,H13/L13)) -> 1 | N13: =IF(M13<=1,(((1-AdjHigh)*E13)+(AdjHigh*M13*E13)),(((1-AdjLow)*E13)+(AdjLow*M13*E13))) -> 0 | O13: =N13*I13 -> 0 | P13: =IF(O13=0,0,D13/O13*100) -> 0
A14: Male | B14: Black | C14: Lung and Bronchus | F14: =IF(E14=0,0,D14/E14) -> 0 | G14: =VLOOKUP(TRIM(A14)&TRIM(B14)&TRIM(C14), RateData, 3*(CaseYear-1995)+5, 0) -> 92.062273 | H14: =VLOOKUP(TRIM(A14)&TRIM(B14)&TRIM(C14), RateData, 3*(CaseYear-1995)+6, 0) -> 78.484001 | I14: =G14/H14 -> 1.1730069 | J14: =E14*I14 -> 0 | K14: =IF(J14=0,0,(D14/J14*100)) -> 0 | M14: =IF(H14=0,1,IF(L14=0,1,H14/L14)) -> 1 | N14: =IF(M14<=1,(((1-AdjHigh)*E14)+(AdjHigh*M14*E14)),(((1-AdjLow)*E14)+(AdjLow*M14*E14))) -> 0 | O14: =N14*I14 -> 0 | P14: =IF(O14=0,0,D14/O14*100) -> 0
A15: Male | B15: Black | C15: Melanomas of the Skin* | F15: =IF(E15=0,0,D15/E15) -> 0 | G15: =VLOOKUP(TRIM(A15)&TRIM(B15)&TRIM(C15), RateData, 3*(CaseYear-1995)+5, 0) -> 1.2251176 | H15: =VLOOKUP(TRIM(A15)&TRIM(B15)&TRIM(C15), RateData, 3*(CaseYear-1995)+6, 0) -> 0.52085822 | I15: =G15/H15 -> 2.3521134 | J15: =E15*I15 -> 0 | K15: =IF(J15=0,0,(D15/J15*100)) -> 0 | M15: =IF(H15=0,1,IF(L15=0,1,H15/L15)) -> 1 | N15: =IF(M15<=1,(((1-AdjHigh)*E15)+(AdjHigh*M15*E15)),(((1-AdjLow)*E15)+(AdjLow*M15*E15))) -> 0 | O15: =N15*I15 -> 0 | P15: =IF(O15=0,0,D15/O15*100) -> 0
A16: Male | B16: Black | C16: Prostate* | F16: =IF(E16=0,0,D16/E16) -> 0 | G16: =VLOOKUP(TRIM(A16)&TRIM(B16)&TRIM(C16), RateData, 3*(CaseYear-1995)+5, 0) -> 233.04993 | H16: =VLOOKUP(TRIM(A16)&TRIM(B16)&TRIM(C16), RateData, 3*(CaseYear-1995)+6, 0) -> 50.942309 | I16: =G16/H16 -> 4.5747814 | J16: =E16*I16 -> 0 | K16: =IF(J16=0,0,(D16/J16*100)) -> 0 | M16: =IF(H16=0,1,IF(L16=0,1,H16/L16)) -> 1 | N16: =IF(M16<=1,(((1-AdjHigh)*E16)+(AdjHigh*M16*E16)),(((1-AdjLow)*E16)+(AdjLow*M16*E16))) -> 0 | O16: =N16*I16 -> 0 | P16: =IF(O16=0,0,D16/O16*100) -> 0
A17: Male | B17: Black | C17: Bladder (including in situ) | F17: =IF(E17=0,0,D17/E17) -> 0 | G17: =VLOOKUP(TRIM(A17)&TRIM(B17)&TRIM(C17), RateData, 3*(CaseYear-1995)+5, 0) -> 21.775746 | H17: =VLOOKUP(TRIM(A17)&TRIM(B17)&TRIM(C17), RateData, 3*(CaseYear-1995)+6, 0) -> 5.4737353 | I17: =G17/H17 -> 3.9782242 | J17: =E17*I17 -> 0 | K17: =IF(J17=0,0,(D17/J17*100)) -> 0 | M17: =IF(H17=0,1,IF(L17=0,1,H17/L17)) -> 1 | N17: =IF(M17<=1,(((1-AdjHigh)*E17)+(AdjHigh*M17*E17)),(((1-AdjLow)*E17)+(AdjLow*M17*E17))) -> 0 | O17: =N17*I17 -> 0 | P17: =IF(O17=0,0,D17/O17*100) -> 0
A18: Male | B18: Black | C18: Kidney and Renal Pelvis | F18: =IF(E18=0,0,D18/E18) -> 0 | G18: =VLOOKUP(TRIM(A18)&TRIM(B18)&TRIM(C18), RateData, 3*(CaseYear-1995)+5, 0) -> 25.692784 | H18: =VLOOKUP(TRIM(A18)&TRIM(B18)&TRIM(C18), RateData, 3*(CaseYear-1995)+6, 0) -> 5.7201728 | I18: =G18/H18 -> 4.4916098 | J18: =E18*I18 -> 0 | K18: =IF(J18=0,0,(D18/J18*100)) -> 0 | M18: =IF(H18=0,1,IF(L18=0,1,H18/L18)) -> 1 | N18: =IF(M18<=1,(((1-AdjHigh)*E18)+(AdjHigh*M18*E18)),(((1-AdjLow)*E18)+(AdjLow*M18*E18))) -> 0 | O18: =N18*I18 -> 0 | P18: =IF(O18=0,0,D18/O18*100) -> 0
A19: Male | B19: Black | C19: Brain and Other Nervous System | F19: =IF(E19=0,0,D19/E19) -> 0 | G19: =VLOOKUP(TRIM(A19)&TRIM(B19)&TRIM(C19), RateData, 3*(CaseYear-1995)+5, 0) -> 4.3393071 | H19: =VLOOKUP(TRIM(A19)&TRIM(B19)&TRIM(C19), RateData, 3*(CaseYear-1995)+6, 0) -> 2.9802758 | I19: =G19/H19 -> 1.4560086 | J19: =E19*I19 -> 0 | K19: =IF(J19=0,0,(D19/J19*100)) -> 0 | M19: =IF(H19=0,1,IF(L19=0,1,H19/L19)) -> 1 | N19: =IF(M19<=1,(((1-AdjHigh)*E19)+(AdjHigh*M19*E19)),(((1-AdjLow)*E19)+(AdjLow*M19*E19))) -> 0 | O19: =N19*I19 -> 0 | P19: =IF(O19=0,0,D19/O19*100) -> 0
... A23: Male | B23: Black | C23: Leukemias | F23: =IF(E23=0,0,D23/E23) -> 0 | G23: =VLOOKUP(TRIM(A23)&TRIM(B23)&TRIM(C23), RateData, 3*(CaseYear-1995)+5, 0) -> 13.503149 | H23: =VLOOKUP(TRIM(A23)&TRIM(B23)&TRIM(C23), RateData, 3*(CaseYear-1995)+6, 0) -> 8.2149921 | I23: =G23/H23 -> 1.6437202 | J23: =E23*I23 -> 0 | K23: =IF(J23=0,0,(D23/J23*100)) -> 0 | M23: =IF(H23=0,1,IF(L23=0,1,H23/L23)) -> 1 | N23: =IF(M23<=1,(((1-AdjHigh)*E23)+(AdjHigh*M23*E23)),(((1-AdjLow)*E23)+(AdjLow*M23*E23))) -> 0 | O23: =N23*I23 -> 0 | P23: =IF(O23=0,0,D23/O23*100) -> 0
C24: Sum of Rates for Black Males | D24: =SUM(D8:D14)+SUM(D17:D23) -> 0 | J24: =SUM(J8:J14)+SUM(J17:J23) -> 0 | K24: =IF(J24=0,0,(D24/J24*100)) -> 0 | O24: =SUM(O8:O14)+SUM(O17:O23) -> 0 | P24: =IF(O24=0,0,D24/O24*100) -> 0
D27: =Registry -> Alabama | G27: SEER (11 Regs) and US Mortality | J27: Unadjusted Results | L27: Mortality Adjustment Terms | O27: Adjusted for Mortality
C28: Black Females | D28: Age-Adjusted Rates (2000 US) | G28: Age-Adjusted Rates (2000 US) | J28: Expected | K28: Unadjusted | L28: Registry | N28: Adj Reg | O28: Expected | P28: Interim
D29: =CaseYear -> 2010 | E29: =RegMCurrentStart&"-"&TEXT(RegMCurrentEnd,"00") -> 2009-2010 | F29: Inc/Mort | G29: =SEERStart&"-"&TEXT(SEEREnd,"00") -> 2006-2010 | H29: =USMortStart&"-"&TEXT(USMortEnd,"00") -> 2006-2010 | I29: Inc/Mort | J29: Incidence | K29: Percent | L29: =RegMRefStart&"-"&TEXT(RegMRefEnd,"00") -> 2006-2010 | M29: Adjust. | N29: =RegMCurrentStart&"-"&TEXT(RegMCurrentEnd,"00") -> 2009-2010 | O29: Incidence | P29: Percent
C30: Cancer Site | D30: Incidence | E30: Mortality | F30: Ratio | G30: Incidence | H30: Mortality | I30: Ratio | J30: Rate | K30: Complete | L30: Mort Rate | M30: Term | N30: Mort Rate | O30: Rate | P30: Complete
A31: Female | B31: Black | C31: Oral Cavity and Pharynx | F31: =IF(E31=0,0,D31/E31) -> 0 | G31: =VLOOKUP(TRIM(A31)&TRIM(B31)&TRIM(C31), RateData, 3*(CaseYear-1995)+5, 0) -> 5.4865083 | H31: =VLOOKUP(TRIM(A31)&TRIM(B31)&TRIM(C31), RateData, 3*(CaseYear-1995)+6, 0) -> 1.4248003 | I31: =G31/H31 -> 3.850721 | J31: =E31*I31 -> 0 | K31: =IF(J31=0,0,(D31/J31*100)) -> 0 | M31: =IF(H31=0,1,IF(L31=0,1,H31/L31)) -> 1 | N31: =IF(M31<=1,(((1-AdjHigh)*E31)+(AdjHigh*M31*E31)),(((1-AdjLow)*E31)+(AdjLow*M31*E31))) -> 0 | O31: =N31*I31 -> 0 | P31: =IF(O31=0,0,D31/O31*100) -> 0
A32: Female | B32: Black | C32: Esophagus | F32: =IF(E32=0,0,D32/E32) -> 0 | G32: =VLOOKUP(TRIM(A32)&TRIM(B32)&TRIM(C32), RateData, 3*(CaseYear-1995)+5, 0) -> 2.6369319 | H32: =VLOOKUP(TRIM(A32)&TRIM(B32)&TRIM(C32), RateData, 3*(CaseYear-1995)+6, 0) -> 2.1339417 | I32: =G32/H32 -> 1.2357094 | J32: =E32*I32 -> 0 | K32: =IF(J32=0,0,(D32/J32*100)) -> 0 | M32: =IF(H32=0,1,IF(L32=0,1,H32/L32)) -> 1 | N32: =IF(M32<=1,(((1-AdjHigh)*E32)+(AdjHigh*M32*E32)),(((1-AdjLow)*E32)+(AdjLow*M32*E32))) -> 0 | O32: =N32*I32 -> 0 | P32: =IF(O32=0,0,D32/O32*100) -> 0
A33: Female | B33: Black | C33: Stomach | F33: =IF(E33=0,0,D33/E33) -> 0 | G33: =VLOOKUP(TRIM(A33)&TRIM(B33)&TRIM(C33), RateData, 3*(CaseYear-1995)+5, 0) -> 8.5268795 | H33: =VLOOKUP(TRIM(A33)&TRIM(B33)&TRIM(C33), RateData, 3*(CaseYear-1995)+6, 0) -> 4.6579312 | I33: =G33/H33 -> 1.8306151 | J33: =E33*I33 -> 0 | K33: =IF(J33=0,0,(D33/J33*100)) -> 0 | M33: =IF(H33=0,1,IF(L33=0,1,H33/L33)) -> 1 | N33: =IF(M33<=1,(((1-AdjHigh)*E33)+(AdjHigh*M33*E33)),(((1-AdjLow)*E33)+(AdjLow*M33*E33))) -> 0 | O33: =N33*I33 -> 0 | P33: =IF(O33=0,0,D33/O33*100) -> 0
A34: Female | B34: Black | C34: Colon and Rectum | F34: =IF(E34=0,0,D34/E34) -> 0 | G34: =VLOOKUP(TRIM(A34)&TRIM(B34)&TRIM(C34), RateData, 3*(CaseYear-1995)+5, 0) -> 49.90948 | H34: =VLOOKUP(TRIM(A34)&TRIM(B34)&TRIM(C34), RateData, 3*(CaseYear-1995)+6, 0) -> 19.024096 | I34: =G34/H34 -> 2.6234877 | J34: =E34*I34 -> 0 | K34: =IF(J34=0,0,(D34/J34*100)) -> 0 | M34: =IF(H34=0,1,IF(L34=0,1,H34/L34)) -> 1 | N34: =IF(M34<=1,(((1-AdjHigh)*E34)+(AdjHigh*M34*E34)),(((1-AdjLow)*E34)+(AdjLow*M34*E34))) -> 0 | O34: =N34*I34 -> 0 | P34: =IF(O34=0,0,D34/O34*100) -> 0
A35: Female | B35: Black | C35: Liver | F35: =IF(E35=0,0,D35/E35) -> 0 | G35: =VLOOKUP(TRIM(A35)&TRIM(B35)&TRIM(C35), RateData, 3*(CaseYear-1995)+5, 0) -> 4.3669654 | H35: =VLOOKUP(TRIM(A35)&TRIM(B35)&TRIM(C35), RateData, 3*(CaseYear-1995)+6, 0) -> 3.0403811 | I35: =G35/H35 -> 1.4363217 | J35: =E35*I35 -> 0 | K35: =IF(J35=0,0,(D35/J35*100)) -> 0 | M35: =IF(H35=0,1,IF(L35=0,1,H35/L35)) -> 1 | N35: =IF(M35<=1,(((1-AdjHigh)*E35)+(AdjHigh*M35*E35)),(((1-AdjLow)*E35)+(AdjLow*M35*E35))) -> 0 | O35: =N35*I35 -> 0 | P35: =IF(O35=0,0,D35/O35*100) -> 0
A36: Female | B36: Black | C36: Pancreas | F36: =IF(E36=0,0,D36/E36) -> 0 | G36: =VLOOKUP(TRIM(A36)&TRIM(B36)&TRIM(C36), RateData, 3*(CaseYear-1995)+5, 0) -> 14.946438 | H36: =VLOOKUP(TRIM(A36)&TRIM(B36)&TRIM(C36), RateData, 3*(CaseYear-1995)+6, 0) -> 12.476245 | I36: =G36/H36 -> 1.1979917 | J36: =E36*I36 -> 0 | K36: =IF(J36=0,0,(D36/J36*100)) -> 0 | M36: =IF(H36=0,1,IF(L36=0,1,H36/L36)) -> 1 | N36: =IF(M36<=1,(((1-AdjHigh)*E36)+(AdjHigh*M36*E36)),(((1-AdjLow)*E36)+(AdjLow*M36*E36))) -> 0 | O36: =N36*I36 -> 0 | P36: =IF(O36=0,0,D36/O36*100) -> 0
A37: Female | B37: Black | C37: Lung and Bronchus | F37: =IF(E37=0,0,D37/E37) -> 0 | G37: =VLOOKUP(TRIM(A37)&TRIM(B37)&TRIM(C37), RateData, 3*(CaseYear-1995)+5, 0) -> 54.40623 | H37: =VLOOKUP(TRIM(A37)&TRIM(B37)&TRIM(C37), RateData, 3*(CaseYear-1995)+6, 0) -> 37.212903 | I37: =G37/H37 -> 1.4620259 | J37: =E37*I37 -> 0 | K37: =IF(J37=0,0,(D37/J37*100)) -> 0 | M37: =IF(H37=0,1,IF(L37=0,1,H37/L37)) -> 1 | N37: =IF(M37<=1,(((1-AdjHigh)*E37)+(AdjHigh*M37*E37)),(((1-AdjLow)*E37)+(AdjLow*M37*E37))) -> 0 | O37: =N37*I37 -> 0 | P37: =IF(O37=0,0,D37/O37*100) -> 0
A38: Female | B38: Black | C38: Melanomas of the Skin* | F38: =IF(E38=0,0,D38/E38) -> 0 | G38: =VLOOKUP(TRIM(A38)&TRIM(B38)&TRIM(C38), RateData, 3*(CaseYear-1995)+5, 0) -> 0.89533255 | H38: =VLOOKUP(TRIM(A38)&TRIM(B38)&TRIM(C38), RateData, 3*(CaseYear-1995)+6, 0) -> 0.37869984 | I38: =G38/H38 -> 2.3642274 | J38: =E38*I38 -> 0 | K38: =IF(J38=0,0,(D38/J38*100)) -> 0 | M38: =IF(H38=0,1,IF(L38=0,1,H38/L38)) -> 1 | N38: =IF(M38<=1,(((1-AdjHigh)*E38)+(AdjHigh*M38*E38)),(((1-AdjLow)*E38)+(AdjLow*M38*E38))) -> 0 | O38: =N38*I38 -> 0 | P38: =IF(O38=0,0,D38/O38*100) -> 0
A39: Female | B39: Black | C39: Breast* | F39: =IF(E39=0,0,D39/E39) -> 0 | G39: =VLOOKUP(TRIM(A39)&TRIM(B39)&TRIM(C39), RateData, 3*(CaseYear-1995)+5, 0) -> 124.316 | H39: =VLOOKUP(TRIM(A39)&TRIM(B39)&TRIM(C39), RateData, 3*(CaseYear-1995)+6, 0) -> 30.835994 | I39: =G39/H39 -> 4.0315224 | J39: =E39*I39 -> 0 | K39: =IF(J39=0,0,(D39/J39*100)) -> 0 | M39: =IF(H39=0,1,IF(L39=0,1,H39/L39)) -> 1 | N39: =IF(M39<=1,(((1-AdjHigh)*E39)+(AdjHigh*M39*E39)),(((1-AdjLow)*E39)+(AdjLow*M39*E39))) -> 0 | O39: =N39*I39 -> 0 | P39: =IF(O39=0,0,D39/O39*100) -> 0
A40: Female | B40: Black | C40: Cervix | F40: =IF(E40=0,0,D40/E40) -> 0 | G40: =VLOOKUP(TRIM(A40)&TRIM(B40)&TRIM(C40), RateData, 3*(CaseYear-1995)+5, 0) -> 8.3466771 | H40: =VLOOKUP(TRIM(A40)&TRIM(B40)&TRIM(C40), RateData, 3*(CaseYear-1995)+6, 0) -> 4.1509013 | I40: =G40/H40 -> 2.0108108 | J40: =E40*I40 -> 0 | K40: =IF(J40=0,0,(D40/J40*100)) -> 0 | M40: =IF(H40=0,1,IF(L40=0,1,H40/L40)) -> 1 | N40: =IF(M40<=1,(((1-AdjHigh)*E40)+(AdjHigh*M40*E40)),(((1-AdjLow)*E40)+(AdjLow*M40*E40))) -> 0 | O40: =N40*I40 -> 0 | P40: =IF(O40=0,0,D40/O40*100) -> 0
A41: Female | B41: Black | C41: Corpus and Uterus, NOS | F41: =IF(E41=0,0,D41/E41) -> 0 | G41: =VLOOKUP(TRIM(A41)&TRIM(B41)&TRIM(C41), RateData, 3*(CaseYear-1995)+5, 0) -> 23.284969 | H41: =VLOOKUP(TRIM(A41)&TRIM(B41)&TRIM(C41), RateData, 3*(CaseYear-1995)+6, 0) -> 7.3812106 | I41: =G41/H41 -> 3.1546274 | J41: =E41*I41 -> 0 | K41: =IF(J41=0,0,(D41/J41*100)) -> 0 | M41: =IF(H41=0,1,IF(L41=0,1,H41/L41)) -> 1 | N41: =IF(M41<=1,(((1-AdjHigh)*E41)+(AdjHigh*M41*E41)),(((1-AdjLow)*E41)+(AdjLow*M41*E41))) -> 0 | O41: =N41*I41 -> 0 | P41: =IF(O41=0,0,D41/O41*100) -> 0
A42: Female | B42: Black | C42: Ovary | F42: =IF(E42=0,0,D42/E42) -> 0 | G42: =VLOOKUP(TRIM(A42)&TRIM(B42)&TRIM(C42), RateData, 3*(CaseYear-1995)+5, 0) -> 9.8063827 | H42: =VLOOKUP(TRIM(A42)&TRIM(B42)&TRIM(C42), RateData, 3*(CaseYear-1995)+6, 0) -> 6.6815502 | I42: =G42/H42 -> 1.4676808 | J42: =E42*I42 -> 0 | K42: =IF(J42=0,0,(D42/J42*100)) -> 0 | M42: =IF(H42=0,1,IF(L42=0,1,H42/L42)) -> 1 | N42: =IF(M42<=1,(((1-AdjHigh)*E42)+(AdjHigh*M42*E42)),(((1-AdjLow)*E42)+(AdjLow*M42*E42))) -> 0 | O42: =N42*I42 -> 0 | P42: =IF(O42=0,0,D42/O42*100) -> 0
... A49: Female | B49: Black | C49: Leukemias | F49: =IF(E49=0,0,D49/E49) -> 0 | G49: =VLOOKUP(TRIM(A49)&TRIM(B49)&TRIM(C49), RateData, 3*(CaseYear-1995)+5, 0) -> 7.9363909 | H49: =VLOOKUP(TRIM(A49)&TRIM(B49)&TRIM(C49), RateData, 3*(CaseYear-1995)+6, 0) -> 4.7653733 | I49: =G49/H49 -> 1.665429 | J49: =E49*I49 -> 0 | K49: =IF(J49=0,0,(D49/J49*100)) -> 0 | M49: =IF(H49=0,1,IF(L49=0,1,H49/L49)) -> 1 | N49: =IF(M49<=1,(((1-AdjHigh)*E49)+(AdjHigh*M49*E49)),(((1-AdjLow)*E49)+(AdjLow*M49*E49))) -> 0 | O49: =N49*I49 -> 0 | P49: =IF(O49=0,0,D49/O49*100) -> 0
C50: Sum of Rates for Black Females | D50: =SUM(D31:D37)+SUM(D39:D49) -> 0 | J50: =SUM(J31:J37)+SUM(J39:J49) -> 0 | K50: =IF(J50=0,0,(D50/J50*100)) -> 0 | O50: =SUM(O31:O37)+SUM(O39:O49) -> 0 | P50: =IF(O50=0,0,D50/O50*100) -> 0
C52: Sum of Blacks, Gender Weighted | D52: =IF(BlackPop=0,0,((D24*BlackMalePop+D50*BlackFemalePop)/BlackPop)) -> 0 | J52: =IF(BlackPop=0,0,((J24*BlackMalePop+J50*BlackFemalePop)/BlackPop)) -> 0 | K52: =IF(J52=0,0,(D52/J52*100)) -> 0 | O52: =IF(BlackPop=0,0,((O24*BlackMalePop+O50*BlackFemalePop)/BlackPop)) -> 0 | P52: =IF(BlackPop=0,0,((P24*BlackMalePop+P50*BlackFemalePop)/BlackPop)/100) -> 0
C53: Overall Total + Breast + Prostate | D53: =#REF!+D50 -> #REF! | J53: =#REF!+J50 -> #REF! | O53: =#REF!+O50 -> #REF!
...

Sheet Whites
C1: ='Adjustment Info'!A1 -> Worksheet for Completeness of Case Ascertainment, version 2.2.b
C2: =IF(Registry_Type=4,"Registry Incidence and Mortality Rates, Whites","Registry Incidence and Mortality Rates, All Races") -> Registry Incidence and Mortality Rates, Whites
D4: =Registry -> Alabama | G4: SEER (11 Regs) and US Mortality | J4: Unadjusted Results | L4: Mortality Adjustment Terms | O4: Adjusted for Mortality
C5: =IF(Registry_Type=4,"White Males","All Races, Males") -> White Males | D5: Age-Adjusted Rates (2000 US) | G5: Age-Adjusted Rates (2000 US) | J5: Expected | K5: Unadjusted | L5: Registry | N5: Adj Reg | O5: Expected | P5: Interim
D6: =CaseYear -> 2010 | E6: =RegMCurrentStart&"-"&TEXT(RegMCurrentEnd,"00") -> 2009-2010 | F6: Inc/Mort | G6: =SEERStart&"-"&TEXT(SEEREnd,"00") -> 2006-2010 | H6: =USMortStart&"-"&TEXT(USMortEnd,"00") -> 2006-2010 | I6: Inc/Mort | J6: Incidence | K6: Percent | L6: =RegMRefStart&"-"&TEXT(RegMRefEnd,"00") -> 2006-2010 | M6: Adjust. | N6: =RegMCurrentStart&"-"&TEXT(RegMCurrentEnd,"00") -> 2009-2010 | O6: Incidence | P6: Percent
C7: Cancer Site | D7: Incidence | E7: Mortality | F7: Ratio | G7: Incidence | H7: Mortality | I7: Ratio | J7: Rate | K7: Complete | L7: Mort Rate | M7: Term | N7: Mort Rate | O7: Rate | P7: Complete
A8: Male | B8: White | C8: Oral Cavity and Pharynx | F8: =IF(E8=0,0,D8/E8) -> 0 | G8: =VLOOKUP(TRIM(A8)&TRIM(B8)&TRIM(C8), RateData, 3*(CaseYear-1995)+5, 0) -> 15.871862 | H8: =VLOOKUP(TRIM(A8)&TRIM(B8)&TRIM(C8), RateData, 3*(CaseYear-1995)+6, 0) -> 3.6266047 | I8: =G8/H8 -> 4.3765072 | J8: =E8*I8 -> 0 | K8: =IF(J8=0,0,(D8/J8*100)) -> 0 | M8: =IF(H8=0,1,IF(L8=0,1,H8/L8)) -> 1 | N8: =IF(M8<=1,(((1-AdjHigh)*E8)+(AdjHigh*M8*E8)),(((1-AdjLow)*E8)+(AdjLow*M8*E8))) -> 0 | O8: =N8*I8 -> 0 | P8: =IF(O8=0,0,D8/O8*100) -> 0
A9: Male | B9: White | C9: Esophagus | F9: =IF(E9=0,0,D9/E9) -> 0 | G9: =VLOOKUP(TRIM(A9)&TRIM(B9)&TRIM(C9), RateData, 3*(CaseYear-1995)+5, 0) -> 7.8307691 | H9: =VLOOKUP(TRIM(A9)&TRIM(B9)&TRIM(C9), RateData, 3*(CaseYear-1995)+6, 0) -> 7.8062708 | I9: =G9/H9 -> 1.0031383 | J9: =E9*I9 -> 0 | K9: =IF(J9=0,0,(D9/J9*100)) -> 0 | M9: =IF(H9=0,1,IF(L9=0,1,H9/L9)) -> 1 | N9: =IF(M9<=1,(((1-AdjHigh)*E9)+(AdjHigh*M9*E9)),(((1-AdjLow)*E9)+(AdjLow*M9*E9))) -> 0 | O9: =N9*I9 -> 0 | P9: =IF(O9=0,0,D9/O9*100) -> 0
A10: Male | B10: White | C10: Stomach | F10: =IF(E10=0,0,D10/E10) -> 0 | G10: =VLOOKUP(TRIM(A10)&TRIM(B10)&TRIM(C10), RateData, 3*(CaseYear-1995)+5, 0) -> 9.6045281 | H10: =VLOOKUP(TRIM(A10)&TRIM(B10)&TRIM(C10), RateData, 3*(CaseYear-1995)+6, 0) -> 4.2371547 | I10: =G10/H10 -> 2.26674 | J10: =E10*I10 -> 0 | K10: =IF(J10=0,0,(D10/J10*100)) -> 0 | M10: =IF(H10=0,1,IF(L10=0,1,H10/L10)) -> 1 | N10: =IF(M10<=1,(((1-AdjHigh)*E10)+(AdjHigh*M10*E10)),(((1-AdjLow)*E10)+(AdjLow*M10*E10))) -> 0 | O10: =N10*I10 -> 0 | P10: =IF(O10=0,0,D10/O10*100) -> 0
A11: Male | B11: White | C11: Colon and Rectum | F11: =IF(E11=0,0,D11/E11) -> 0 | G11: =VLOOKUP(TRIM(A11)&TRIM(B11)&TRIM(C11), RateData, 3*(CaseYear-1995)+5, 0) -> 49.313825 | H11: =VLOOKUP(TRIM(A11)&TRIM(B11)&TRIM(C11), RateData, 3*(CaseYear-1995)+6, 0) -> 19.057426 | I11: =G11/H11 -> 2.5876435 | J11: =E11*I11 -> 0 | K11: =IF(J11=0,0,(D11/J11*100)) -> 0 | M11: =IF(H11=0,1,IF(L11=0,1,H11/L11)) -> 1 | N11: =IF(M11<=1,(((1-AdjHigh)*E11)+(AdjHigh*M11*E11)),(((1-AdjLow)*E11)+(AdjLow*M11*E11))) -> 0 | O11: =N11*I11 -> 0 | P11: =IF(O11=0,0,D11/O11*100) -> 0
A12: Male | B12: White | C12: Liver | F12: =IF(E12=0,0,D12/E12) -> 0 | G12: =VLOOKUP(TRIM(A12)&TRIM(B12)&TRIM(C12), RateData, 3*(CaseYear-1995)+5, 0) -> 9.682039 | H12: =VLOOKUP(TRIM(A12)&TRIM(B12)&TRIM(C12), RateData, 3*(CaseYear-1995)+6, 0) -> 6.0915644 | I12: =G12/H12 -> 1.5894175 | J12: =E12*I12 -> 0 | K12: =IF(J12=0,0,(D12/J12*100)) -> 0 | M12: =IF(H12=0,1,IF(L12=0,1,H12/L12)) -> 1 | N12: =IF(M12<=1,(((1-AdjHigh)*E12)+(AdjHigh*M12*E12)),(((1-AdjLow)*E12)+(AdjLow*M12*E12))) -> 0 | O12: =N12*I12 -> 0 | P12: =IF(O12=0,0,D12/O12*100) -> 0
A13: Male | B13: White | C13: Pancreas | F13: =IF(E13=0,0,D13/E13) -> 0 | G13: =VLOOKUP(TRIM(A13)&TRIM(B13)&TRIM(C13), RateData, 3*(CaseYear-1995)+5, 0) -> 13.802945 | H13: =VLOOKUP(TRIM(A13)&TRIM(B13)&TRIM(C13), RateData, 3*(CaseYear-1995)+6, 0) -> 12.457835 | I13: =G13/H13 -> 1.1079731 | J13: =E13*I13 -> 0 | K13: =IF(J13=0,0,(D13/J13*100)) -> 0 | M13: =IF(H13=0,1,IF(L13=0,1,H13/L13)) -> 1 | N13: =IF(M13<=1,(((1-AdjHigh)*E13)+(AdjHigh*M13*E13)),(((1-AdjLow)*E13)+(AdjLow*M13*E13))) -> 0 | O13: =N13*I13 -> 0 | P13: =IF(O13=0,0,D13/O13*100) -> 0
A14: Male | B14: White | C14: Lung and Bronchus | F14: =IF(E14=0,0,D14/E14) -> 0 | G14: =VLOOKUP(TRIM(A14)&TRIM(B14)&TRIM(C14), RateData, 3*(CaseYear-1995)+5, 0) -> 65.827583 | H14: =VLOOKUP(TRIM(A14)&TRIM(B14)&TRIM(C14), RateData, 3*(CaseYear-1995)+6, 0) -> 63.247513 | I14: =G14/H14 -> 1.0407932 | J14: =E14*I14 -> 0 | K14: =IF(J14=0,0,(D14/J14*100)) -> 0 | M14: =IF(H14=0,1,IF(L14=0,1,H14/L14)) -> 1 | N14: =IF(M14<=1,(((1-AdjHigh)*E14)+(AdjHigh*M14*E14)),(((1-AdjLow)*E14)+(AdjLow*M14*E14))) -> 0 | O14: =N14*I14 -> 0 | P14: =IF(O14=0,0,D14/O14*100) -> 0
A15: Male | B15: White | C15: Melanomas of the Skin | F15: =IF(E15=0,0,D15/E15) -> 0 | G15: =VLOOKUP(TRIM(A15)&TRIM(B15)&TRIM(C15), RateData, 3*(CaseYear-1995)+5, 0) -> 32.554522 | H15: =VLOOKUP(TRIM(A15)&TRIM(B15)&TRIM(C15), RateData, 3*(CaseYear-1995)+6, 0) -> 4.6444764 | I15: =G15/H15 -> 7.0092986 | J15: =E15*I15 -> 0 | K15: =IF(J15=0,0,(D15/J15*100)) -> 0 | M15: =IF(H15=0,1,IF(L15=0,1,H15/L15)) -> 1 | N15: =IF(M15<=1,(((1-AdjHigh)*E15)+(AdjHigh*M15*E15)),(((1-AdjLow)*E15)+(AdjLow*M15*E15))) -> 0 | O15: =N15*I15 -> 0 | P15: =IF(O15=0,0,D15/O15*100) -> 0
A16: Male | B16: White | C16: Prostate* | F16: =IF(E16=0,0,D16/E16) -> 0 | G16: =VLOOKUP(TRIM(A16)&TRIM(B16)&TRIM(C16), RateData, 3*(CaseYear-1995)+5, 0) -> 149.58027 | H16: =VLOOKUP(TRIM(A16)&TRIM(B16)&TRIM(C16), RateData, 3*(CaseYear-1995)+6, 0) -> 21.2366 | I16: =G16/H16 -> 7.0435129 | J16: =E16*I16 -> 0 | K16: =IF(J16=0,0,(D16/J16*100)) -> 0 | M16: =IF(H16=0,1,IF(L16=0,1,H16/L16)) -> 1 | N16: =IF(M16<=1,(((1-AdjHigh)*E16)+(AdjHigh*M16*E16)),(((1-AdjLow)*E16)+(AdjLow*M16*E16))) -> 0 | O16: =N16*I16 -> 0 | P16: =IF(O16=0,0,D16/O16*100) -> 0
A17: Male | B17: White | C17: Bladder (including in situ) | F17: =IF(E17=0,0,D17/E17) -> 0 | G17: =VLOOKUP(TRIM(A17)&TRIM(B17)&TRIM(C17), RateData, 3*(CaseYear-1995)+5, 0) -> 39.621135 | H17: =VLOOKUP(TRIM(A17)&TRIM(B17)&TRIM(C17), RateData, 3*(CaseYear-1995)+6, 0) -> 8.0806704 | I17: =G17/H17 -> 4.9031989 | J17: =E17*I17 -> 0 | K17: =IF(J17=0,0,(D17/J17*100)) -> 0 | M17: =IF(H17=0,1,IF(L17=0,1,H17/L17)) -> 1 | N17: =IF(M17<=1,(((1-AdjHigh)*E17)+(AdjHigh*M17*E17)),(((1-AdjLow)*E17)+(AdjLow*M17*E17))) -> 0 | O17: =N17*I17 -> 0 | P17: =IF(O17=0,0,D17/O17*100) -> 0
A18: Male | B18: White | C18: Kidney and Renal Pelvis | F18: =IF(E18=0,0,D18/E18) -> 0 | G18: =VLOOKUP(TRIM(A18)&TRIM(B18)&TRIM(C18), RateData, 3*(CaseYear-1995)+5, 0) -> 20.602593 | H18: =VLOOKUP(TRIM(A18)&TRIM(B18)&TRIM(C18), RateData, 3*(CaseYear-1995)+6, 0) -> 5.8698557 | I18: =G18/H18 -> 3.5098977 | J18: =E18*I18 -> 0 | K18: =IF(J18=0,0,(D18/J18*100)) -> 0 | M18: =IF(H18=0,1,IF(L18=0,1,H18/L18)) -> 1 | N18: =IF(M18<=1,(((1-AdjHigh)*E18)+(AdjHigh*M18*E18)),(((1-AdjLow)*E18)+(AdjLow*M18*E18))) -> 0 | O18: =N18*I18 -> 0 | P18: =IF(O18=0,0,D18/O18*100) -> 0
A19: Male | B19: White | C19: Brain and Other Nervous System | F19: =IF(E19=0,0,D19/E19) -> 0 | G19: =VLOOKUP(TRIM(A19)&TRIM(B19)&TRIM(C19), RateData, 3*(CaseYear-1995)+5, 0) -> 8.4448765 | H19: =VLOOKUP(TRIM(A19)&TRIM(B19)&TRIM(C19), RateData, 3*(CaseYear-1995)+6, 0) -> 5.6117135 | I19: =G19/H19 -> 1.5048659 | J19: =E19*I19 -> 0 | K19: =IF(J19=0,0,(D19/J19*100)) -> 0 | M19: =IF(H19=0,1,IF(L19=0,1,H19/L19)) -> 1 | N19: =IF(M19<=1,(((1-AdjHigh)*E19)+(AdjHigh*M19*E19)),(((1-AdjLow)*E19)+(AdjLow*M19*E19))) -> 0 | O19: =N19*I19 -> 0 | P19: =IF(O19=0,0,D19/O19*100) -> 0
... A23: Male | B23: White | C23: Leukemias | F23: =IF(E23=0,0,D23/E23) -> 0 | G23: =VLOOKUP(TRIM(A23)&TRIM(B23)&TRIM(C23), RateData, 3*(CaseYear-1995)+5, 0) -> 18.102435 | H23: =VLOOKUP(TRIM(A23)&TRIM(B23)&TRIM(C23), RateData, 3*(CaseYear-1995)+6, 0) -> 9.8180022 | I23: =G23/H23 -> 1.8438003 | J23: =E23*I23 -> 0 | K23: =IF(J23=0,0,(D23/J23*100)) -> 0 | M23: =IF(H23=0,1,IF(L23=0,1,H23/L23)) -> 1 | N23: =IF(M23<=1,(((1-AdjHigh)*E23)+(AdjHigh*M23*E23)),(((1-AdjLow)*E23)+(AdjLow*M23*E23))) -> 0 | O23: =N23*I23 -> 0 | P23: =IF(O23=0,0,D23/O23*100) -> 0
C24: =IF(Registry_Type=4,"Sum of Rates for White Males","Sum of Rates for All Races, Males") -> Sum of Rates for White Males | D24: =SUM(D8:D15)+SUM(D17:D23) -> 0 | J24: =SUM(J8:J15)+SUM(J17:J23) -> 0 | K24: =IF(J24=0,0,(D24/J24*100)) -> 0 | O24: =SUM(O8:O15)+SUM(O17:O23) -> 0 | P24: =IF(O24=0,0,D24/O24*100) -> 0
D27: =Registry -> Alabama | G27: SEER (11 Regs) and US Mortality | J27: Unadjusted Results | L27: Mortality Adjustment Terms | O27: Adjusted for Mortality
C28: =IF(Registry_Type=4,"White Females","All Races, Females") -> White Females | D28: Age-Adjusted Rates (2000 US) | G28: Age-Adjusted Rates (2000 US) | J28: Expected | K28: Unadjusted | L28: Registry | N28: Adj Reg | O28: Expected | P28: Interim
D29: =CaseYear -> 2010 | E29: =RegMCurrentStart&"-"&TEXT(RegMCurrentEnd,"00") -> 2009-2010 | F29: Inc/Mort | G29: =SEERStart&"-"&TEXT(SEEREnd,"00") -> 2006-2010 | H29: =USMortStart&"-"&TEXT(USMortEnd,"00") -> 2006-2010 | I29: Inc/Mort | J29: Incidence | K29: Percent | L29: =RegMRefStart&"-"&TEXT(RegMRefEnd,"00") -> 2006-2010 | M29: Adjust. | N29: =RegMCurrentStart&"-"&TEXT(RegMCurrentEnd,"00") -> 2009-2010 | O29: Incidence | P29: Percent
C30: Cancer Site | D30: Incidence | E30: Mortality | F30: Ratio | G30: Incidence | H30: Mortality | I30: Ratio | J30: Rate | K30: Complete | L30: Mort Rate | M30: Term | N30: Mort Rate | O30: Rate | P30: Complete
A31: Female | B31: White | C31: Oral Cavity and Pharynx | F31: =IF(E31=0,0,D31/E31) -> 0 | G31: =VLOOKUP(TRIM(A31)&TRIM(B31)&TRIM(C31), RateData, 3*(CaseYear-1995)+5, 0) -> 6.2092334 | H31: =VLOOKUP(TRIM(A31)&TRIM(B31)&TRIM(C31), RateData, 3*(CaseYear-1995)+6, 0) -> 1.376525 | I31: =G31/H31 -> 4.5108031 | J31: =E31*I31 -> 0 | K31: =IF(J31=0,0,(D31/J31*100)) -> 0 | M31: =IF(H31=0,1,IF(L31=0,1,H31/L31)) -> 1 | N31: =IF(M31<=1,(((1-AdjHigh)*E31)+(AdjHigh*M31*E31)),(((1-AdjLow)*E31)+(AdjLow*M31*E31))) -> 0 | O31: =N31*I31 -> 0 | P31: =IF(O31=0,0,D31/O31*100) -> 0
A32: Female | B32: White | C32: Esophagus | F32: =IF(E32=0,0,D32/E32) -> 0 | G32: =VLOOKUP(TRIM(A32)&TRIM(B32)&TRIM(C32), RateData, 3*(CaseYear-1995)+5, 0) -> 1.814712 | H32: =VLOOKUP(TRIM(A32)&TRIM(B32)&TRIM(C32), RateData, 3*(CaseYear-1995)+6, 0) -> 1.5683463 | I32: =G32/H32 -> 1.1570863 | J32: =E32*I32 -> 0 | K32: =IF(J32=0,0,(D32/J32*100)) -> 0 | M32: =IF(H32=0,1,IF(L32=0,1,H32/L32)) -> 1 | N32: =IF(M32<=1,(((1-AdjHigh)*E32)+(AdjHigh*M32*E32)),(((1-AdjLow)*E32)+(AdjLow*M32*E32))) -> 0 | O32: =N32*I32 -> 0 | P32: =IF(O32=0,0,D32/O32*100) -> 0
A33: Female | B33: White | C33: Stomach | F33: =IF(E33=0,0,D33/E33) -> 0 | G33: =VLOOKUP(TRIM(A33)&TRIM(B33)&TRIM(C33), RateData, 3*(CaseYear-1995)+5, 0) -> 4.6807184 | H33: =VLOOKUP(TRIM(A33)&TRIM(B33)&TRIM(C33), RateData, 3*(CaseYear-1995)+6, 0) -> 2.1989153 | I33: =G33/H33 -> 2.1286488 | J33: =E33*I33 -> 0 | K33: =IF(J33=0,0,(D33/J33*100)) -> 0 | M33: =IF(H33=0,1,IF(L33=0,1,H33/L33)) -> 1 | N33: =IF(M33<=1,(((1-AdjHigh)*E33)+(AdjHigh*M33*E33)),(((1-AdjLow)*E33)+(AdjLow*M33*E33))) -> 0 | O33: =N33*I33 -> 0 | P33: =IF(O33=0,0,D33/O33*100) -> 0
A34: Female | B34: White | C34: Colon and Rectum | F34: =IF(E34=0,0,D34/E34) -> 0 | G34: =VLOOKUP(TRIM(A34)&TRIM(B34)&TRIM(C34), RateData, 3*(CaseYear-1995)+5, 0) -> 37.825965 | H34: =VLOOKUP(TRIM(A34)&TRIM(B34)&TRIM(C34), RateData, 3*(CaseYear-1995)+6, 0) -> 13.413173 | I34: =G34/H34 -> 2.820061 | J34: =E34*I34 -> 0 | K34: =IF(J34=0,0,(D34/J34*100)) -> 0 | M34: =IF(H34=0,1,IF(L34=0,1,H34/L34)) -> 1 | N34: =IF(M34<=1,(((1-AdjHigh)*E34)+(AdjHigh*M34*E34)),(((1-AdjLow)*E34)+(AdjLow*M34*E34))) -> 0 | O34: =N34*I34 -> 0 | P34: =IF(O34=0,0,D34/O34*100) -> 0
A35: Female | B35: White | C35: Liver | F35: =IF(E35=0,0,D35/E35) -> 0 | G35: =VLOOKUP(TRIM(A35)&TRIM(B35)&TRIM(C35), RateData, 3*(CaseYear-1995)+5, 0) -> 2.9304058 | H35: =VLOOKUP(TRIM(A35)&TRIM(B35)&TRIM(C35), RateData, 3*(CaseYear-1995)+6, 0) -> 2.0012562 | I35: =G35/H35 -> 1.4642832 | J35: =E35*I35 -> 0 | K35: =IF(J35=0,0,(D35/J35*100)) -> 0 | M35: =IF(H35=0,1,IF(L35=0,1,H35/L35)) -> 1 | N35: =IF(M35<=1,(((1-AdjHigh)*E35)+(AdjHigh*M35*E35)),(((1-AdjLow)*E35)+(AdjLow*M35*E35))) -> 0 | O35: =N35*I35 -> 0 | P35: =IF(O35=0,0,D35/O35*100) -> 0
A36: Female | B36: White | C36: Pancreas | F36: =IF(E36=0,0,D36/E36) -> 0 | G36: =VLOOKUP(TRIM(A36)&TRIM(B36)&TRIM(C36), RateData, 3*(CaseYear-1995)+5, 0) -> 10.692991 | H36: =VLOOKUP(TRIM(A36)&TRIM(B36)&TRIM(C36), RateData, 3*(CaseYear-1995)+6, 0) -> 9.3659457 | I36: =G36/H36 -> 1.1416883 | J36: =E36*I36 -> 0 | K36: =IF(J36=0,0,(D36/J36*100)) -> 0 | M36: =IF(H36=0,1,IF(L36=0,1,H36/L36)) -> 1 | N36: =IF(M36<=1,(((1-AdjHigh)*E36)+(AdjHigh*M36*E36)),(((1-AdjLow)*E36)+(AdjLow*M36*E36))) -> 0 | O36: =N36*I36 -> 0 | P36: =IF(O36=0,0,D36/O36*100) -> 0
A37: Female | B37: White | C37: Lung and Bronchus | F37: =IF(E37=0,0,D37/E37) -> 0 | G37: =VLOOKUP(TRIM(A37)&TRIM(B37)&TRIM(C37), RateData, 3*(CaseYear-1995)+5, 0) -> 50.088374 | H37: =VLOOKUP(TRIM(A37)&TRIM(B37)&TRIM(C37), RateData, 3*(CaseYear-1995)+6, 0) -> 40.410486 | I37: =G37/H37 -> 1.2394895 | J37: =E37*I37 -> 0 | K37: =IF(J37=0,0,(D37/J37*100)) -> 0 | M37: =IF(H37=0,1,IF(L37=0,1,H37/L37)) -> 1 | N37: =IF(M37<=1,(((1-AdjHigh)*E37)+(AdjHigh*M37*E37)),(((1-AdjLow)*E37)+(AdjLow*M37*E37))) -> 0 | O37: =N37*I37 -> 0 | P37: =IF(O37=0,0,D37/O37*100) -> 0
A38: Female | B38: White | C38: Melanomas of the Skin | F38: =IF(E38=0,0,D38/E38) -> 0 | G38: =VLOOKUP(TRIM(A38)&TRIM(B38)&TRIM(C38), RateData, 3*(CaseYear-1995)+5, 0) -> 20.851025 | H38: =VLOOKUP(TRIM(A38)&TRIM(B38)&TRIM(C38), RateData, 3*(CaseYear-1995)+6, 0) -> 1.9678281 | I38: =G38/H38 -> 10.595959 | J38: =E38*I38 -> 0 | K38: =IF(J38=0,0,(D38/J38*100)) -> 0 | M38: =IF(H38=0,1,IF(L38=0,1,H38/L38)) -> 1 | N38: =IF(M38<=1,(((1-AdjHigh)*E38)+(AdjHigh*M38*E38)),(((1-AdjLow)*E38)+(AdjLow*M38*E38))) -> 0 | O38: =N38*I38 -> 0 | P38: =IF(O38=0,0,D38/O38*100) -> 0
A39: Female | B39: White | C39: Breast* | F39: =IF(E39=0,0,D39/E39) -> 0 | G39: =VLOOKUP(TRIM(A39)&TRIM(B39)&TRIM(C39), RateData, 3*(CaseYear-1995)+5, 0) -> 129.10563 | H39: =VLOOKUP(TRIM(A39)&TRIM(B39)&TRIM(C39), RateData, 3*(CaseYear-1995)+6, 0) -> 22.091872 | I39: =G39/H39 -> 5.8440331 | J39: =E39*I39 -> 0 | K39: =IF(J39=0,0,(D39/J39*100)) -> 0 | M39: =IF(H39=0,1,IF(L39=0,1,H39/L39)) -> 1 | N39: =IF(M39<=1,(((1-AdjHigh)*E39)+(AdjHigh*M39*E39)),(((1-AdjLow)*E39)+(AdjLow*M39*E39))) -> 0 | O39: =N39*I39 -> 0 | P39: =IF(O39=0,0,D39/O39*100) -> 0
A40: Female | B40: White | C40: Cervix | F40: =IF(E40=0,0,D40/E40) -> 0 | G40: =VLOOKUP(TRIM(A40)&TRIM(B40)&TRIM(C40), RateData, 3*(CaseYear-1995)+5, 0) -> 7.4015314 | H40: =VLOOKUP(TRIM(A40)&TRIM(B40)&TRIM(C40), RateData, 3*(CaseYear-1995)+6, 0) -> 2.1520457 | I40: =G40/H40 -> 3.4393003 | J40: =E40*I40 -> 0 | K40: =IF(J40=0,0,(D40/J40*100)) -> 0 | M40: =IF(H40=0,1,IF(L40=0,1,H40/L40)) -> 1 | N40: =IF(M40<=1,(((1-AdjHigh)*E40)+(AdjHigh*M40*E40)),(((1-AdjLow)*E40)+(AdjLow*M40*E40))) -> 0 | O40: =N40*I40 -> 0 | P40: =IF(O40=0,0,D40/O40*100) -> 0
A41: Female | B41: White | C41: Corpus and Uterus, NOS | F41: =IF(E41=0,0,D41/E41) -> 0 | G41: =VLOOKUP(TRIM(A41)&TRIM(B41)&TRIM(C41), RateData, 3*(CaseYear-1995)+5, 0) -> 26.456664 | H41: =VLOOKUP(TRIM(A41)&TRIM(B41)&TRIM(C41), RateData, 3*(CaseYear-1995)+6, 0) -> 3.9729982 | I41: =G41/H41 -> 6.659118 | J41: =E41*I41 -> 0 | K41: =IF(J41=0,0,(D41/J41*100)) -> 0 | M41: =IF(H41=0,1,IF(L41=0,1,H41/L41)) -> 1 | N41: =IF(M41<=1,(((1-AdjHigh)*E41)+(AdjHigh*M41*E41)),(((1-AdjLow)*E41)+(AdjLow*M41*E41))) -> 0 | O41: =N41*I41 -> 0 | P41: =IF(O41=0,0,D41/O41*100) -> 0
A42: Female | B42: White | C42: Ovary | F42: =IF(E42=0,0,D42/E42) -> 0 | G42: =VLOOKUP(TRIM(A42)&TRIM(B42)&TRIM(C42), RateData, 3*(CaseYear-1995)+5, 0) -> 13.523524 | H42: =VLOOKUP(TRIM(A42)&TRIM(B42)&TRIM(C42), RateData, 3*(CaseYear-1995)+6, 0) -> 8.4164912 | I42: =G42/H42 -> 1.6067889 | J42: =E42*I42 -> 0 | K42: =IF(J42=0,0,(D42/J42*100)) -> 0 | M42: =IF(H42=0,1,IF(L42=0,1,H42/L42)) -> 1 | N42: =IF(M42<=1,(((1-AdjHigh)*E42)+(AdjHigh*M42*E42)),(((1-AdjLow)*E42)+(AdjLow*M42*E42))) -> 0 | O42: =N42*I42 -> 0 | P42: =IF(O42=0,0,D42/O42*100) -> 0
... A49: Female | B49: White | C49: Leukemias | F49: =IF(E49=0,0,D49/E49) -> 0 | G49: =VLOOKUP(TRIM(A49)&TRIM(B49)&TRIM(C49), RateData, 3*(CaseYear-1995)+5, 0) -> 10.868481 | H49: =VLOOKUP(TRIM(A49)&TRIM(B49)&TRIM(C49), RateData, 3*(CaseYear-1995)+6, 0) -> 5.4756623 | I49: =G49/H49 -> 1.9848705 | J49: =E49*I49 -> 0 | K49: =IF(J49=0,0,(D49/J49*100)) -> 0 | M49: =IF(H49=0,1,IF(L49=0,1,H49/L49)) -> 1 | N49: =IF(M49<=1,(((1-AdjHigh)*E49)+(AdjHigh*M49*E49)),(((1-AdjLow)*E49)+(AdjLow*M49*E49))) -> 0 | O49: =N49*I49 -> 0 | P49: =IF(O49=0,0,D49/O49*100) -> 0
C50: =IF(Registry_Type=4,"Sum of Rates for White Females","Sum of Rates for All Races, Females") -> Sum of Rates for White Females | D50: =SUM(D31:D49) -> 0 | J50: =SUM(J31:J49) -> 0 | K50: =IF(J50=0,0,(D50/J50*100)) -> 0 | O50: =SUM(O31:O49) -> 0 | P50: =IF(O50=0,0,D50/O50*100) -> 0
C52: =IF(Registry_Type=4,"Sum of Whites, Gender Weighted","Sum of All Races, Gender Weighted") -> Sum of Whites, Gender Weighted | D52: =IF(Registry_Type=4,(D24*WhiteMalePop+D50*WhiteFemalePop)/WhitePop,(D24*AllRacesMalePop+D50*AllRacesFemalePop)/AllRacesTotalPop) -> 0 | J52: =IF(Registry_Type=4,((J24*WhiteMalePop+J50*WhiteFemalePop)/WhitePop),((J24*AllRacesMalePop+J50*AllRacesFemalePop)/AllRacesTotalPop)) -> 0 | K52: =IF(J52=0,0,(D52/J52*100)) -> 0 | O52: =IF(Registry_Type=4,((O24*WhiteMalePop+O50*WhiteFemalePop)/WhitePop),((O24*AllRacesMalePop+O50*AllRacesFemalePop)/AllRacesTotalPop)) -> 0 | P52: =IF(Registry_Type=4,((P24*WhiteMalePop+P50*WhiteFemalePop)/WhitePop)/100,((P24*AllRacesMalePop+P50*AllRacesFemalePop)/AllRacesTotalPop)/100) -> 0
C53: Overall Total + Breast + Prostate | D53: =#REF!+D50 -> #REF! | J53: =#REF!+J50 -> #REF! | O53: =#REF!+O50 -> #REF!
...

Sheet Instructions
A1: ='Adjustment Info'!A1 -> Worksheet for Completeness of Case Ascertainment, version 2.2.b
A2: Notes and Instructions for the Completeness of Case Ascertainment Estimate Worksheets
A4: Notes:
A5: 1. | B5: The spreadsheet has been loaded with the information from the SEER Incidence and US Mortality cancer databases.
A6: 2. | B6: The SEER and US Mortality rates may be suppressed due to publication schedules.
A7: 3. | B7: Cancer rates throughout the spreadsheet are per 100,000 and are age-adjusted to the 2000 U.S. Standard.
A8: 4. | B8: The cancer rates for Male Prostate (Whites and Blacks) and Melanomas of the Skin (Blacks) are not included
B9: in the completeness estimate computations.
A10: 5. | B10: The areas requiring information from the Registry are highlighted in yellow.
A11: 6. | B11: The Adjustment Terms have been set to .2 and .2, as per the NAACCR Data Evaluation and Publication Committee.
A14: Instructions:
A15: To obtain an estimate of the completeness of case ascertainment for your registry, perform the following steps:
B16: A: Preliminary Steps:
B17: A1. | C17: Calculate the total number (count) of reportable cases for your registry for the reporting year.
B18: A2. | C18: Complete the NAACCR Duplicate Record Protocol on a sample of all reportable cases.
B20: B: Spreadsheet Setup:
C21: Enter the following information on the RegistryInfo worksheet:
B22: B1. | C22: Enter the Reporting Year for case ascertainment.
B23: B2. | C23: Enter the Registry Area from the list provided.
B24: B3. | C24: Enter the Total Number of reportable cases for your registry for the reporting year (from Step A1).
B25: B4. | C25: Enter the Percent of Duplicate Records per 1,000 records, as per the NAACCR protocol (from Step A2).
B27: C: Registry-specific Incidence and Mortality Rates:
B28: C1. | C28: Compute the age-adjusted cancer incidence and cancer mortality rates (adjusted to US Std Population (19 age groups - Census P25-1130) standard) for your registry for:
D29: White Males
D30: White Females
D31: Black Males
D32: Black Females
C33: Note: | D33: Three sets of rates are required for each of the four race/sex groups:
D34: 1. Incidence rates, one year only, for the reporting year
D35: 2. Mortality rates, 2 year average (Current Mortality), for the 2 year period ending in the reporting year*
D36: 3. Mortality rates, 5 year average (Reference Mortality), for the 5 year period ending in the reporting year
D37: When the Reporting Year and Registry Area are entered in the RegistryInfo worksheet, the column headers
D38: throughout the workbook will display the required year ranges.
E39: * For registries with total populations under 500,000 for one year, use the 3 year average mortality rate
E40: for the 3 year period ending in the reporting year.
C42: Note: | D42: For registries with no information on Race, compute the incidence and mortality rates for All Races Combined,
D43: enter this information in the Whites worksheet, and enter zeroes for all values in the Blacks worksheet.
D44: The RegistryInfo and Completeness Report worksheets will report the All Races information in the
D45: White race areas and zeros in the Black race areas.
B46: C2. | C46: Enter the information from step C1 above on these two worksheets:
...

Sheet Documentation
A1: ='Adjustment Info'!A1 -> Worksheet for Completeness of Case Ascertainment, version 2.2.b
A3: Documentation for Worksheet Formulas
B5: Your State/Province/Area | E5: SEER (11 Regs) and US Mortality | H5: Unadjusted Results | J5: Mortality Adjustment Terms | M5: Adjusted for Mortality
A6: Race/Sex | B6: Age-Adjusted Rates (2000 US) | E6: Age-Adjusted Rates (2000 US) | H6: Expected | I6: Unadjusted | J6: Registry | L6: Adj Reg | M6: Expected | N6: Interim
B7: 2001 | C7: 2000-01 | D7: Inc/Mort | E7: 1997-01 | F7: 1997-01 | G7: Inc/Mort | H7: Incidence | I7: Percent | J7: 1997-01 | K7: Adjust. | L7: 2000-01 | M7: Incidence | N7: Percent
A8: Cancer Site | B8: Incidence | C8: Mortality | D8: Ratio | E8: Incidence | F8: Mortality | G8: Ratio | H8: Rate | I8: Complete | J8: Mort Rate | K8: Term | L8: Mort Rate | M8: Rate | N8: Complete
B9: (1) | C9: (2) | D9: (3)=(1)/(2) | E9: (4) | F9: (5) | G9: (6)=(4)/(5) | H9: (7)=(6)*(2) | I9: (8)=[(1)/(7)]*100 | J9: (9) | K9: (10)=(5)/(9) | L9: (11) | M9: (12)=(6)*(11) | N9: (13)=[(1)/(12)]*100
C12: Current Mortality for Your State/Province/Area | J12: Reference Mortality for Your State/Province/Area
B13: Incidence Rates for Your State/Province/Area
A14: Sum of Race, Gender Weighted | N14: (14)
A16: Formula for Column (11) is as follows:
A17: If (10)<=1
A18: then (11)=(1-AdjHigh)*(2) + AdjHigh*(10)*(2)
A19: else (11)=(1-AdjLow)*(2) + AdjLow*(10)*(2)
A20: where AdjHigh and AdjLow are the reference mortality adjustment terms given on the Adjustment Info sheet.
A22: Formula for Cell (14) is as follows:
A23: (14) = ((SumOfRaceMaleCompleteness*RaceMalePop + SumOfRaceFemaleCompleteness*RaceFemalePop)/RacePop)/100
A24: where RaceMalePop and RaceFemalePop are race-specific populations for males and females from the Populations by Race and Sex sheet,
A25: and RacePop is the race-specific population for males and females combined from the Populations by Race sheet.
A27: Interim Completeness Estimates, Adjusted for Reference Mortality
A29: Whites | C29: Blacks | E29: Race Proportional
A30: Percent | C30: Percent | E30: Percent
A31: Complete | B31: Population | C31: Complete | D31: Population | E31: Complete | F31: Population
A32: (A) | B32: (B) | C32: (C) | D32: (D) | E32: (E) | F32: (F)
A34: Data for Columns (A), (B), (C), (D), and (F) are from the Whites, Blacks and RegistryInfo worksheets.
A35: Formula for Column (E) is (E)=[(A)*(B) + (C)*(D)]/(F)
A36: Formula for Column (F) is (B) + (D)
A39: Final Completeness Estimates, Adjusted for Reference Mortality and Duplicates
A41: (AA) | B41: Total Incidence Cases, 2001
A42: (BB) | B42: Percent Duplicate Records
A43: (CC)=(E) | B43: Race Proportional Completeness Estimates, Adjusted for Reference Mortality
A44: (DD) | B44: 2001 Adjusted Total Incidence Cases
A45: (EE)=(AA)/(CC) | B45: 2001 Expected Incidence Cases
A47: (FF)=(DD)/(EE) | B47: Final Completeness Estimate for 2001, Your State/Province/Area,
B48: Adjusted for Reference Mortality and Duplicate Records
A50: Formula for Row (DD) is as follows:
A51: (DD)=(AA) - [(AA)*(BB)]

Sheet Pops by Race and Sex
A1: Worksheet for Completeness of Case Ascertainment, version 2.2.b
A2: State and Provincial Populations, by Race and Sex, 1995 through 2009
A3: Sources: United States: US Census Bureau as of March 2010; Canada: StatCanada as of December 2010
B5: 1995 | C5: 1995 | D5: 1995 | E5: 1995 | F5: 1995 | G5: 1995 | H5: 1996 | I5: 1996 | J5: 1996 | K5: 1996 | L5: 1996 | M5: 1996 | N5: 1997 | O5: 1997 | P5: 1997 | Q5: 1997 | R5: 1997 | S5: 1997 | T5: 1998 | U5: 1998 | V5: 1998 | W5: 1998 | X5: 1998 | Y5: 1998 | Z5: 1999 | AA5: 1999 | AB5: 1999 | AC5: 1999 | AD5: 1999 | AE5: 1999 | AF5: 2000 | AG5: 2000 | AH5: 2000 | AI5: 2000 | AJ5: 2000 | AK5: 2000 | AL5: 2001 | AM5: 2001 | AN5: 2001 | AO5: 2001 | AP5: 2001 | AQ5: 2001 | AR5: 2002 | AS5: 2002 | AT5: 2002 | AU5: 2002 | AV5: 2002 | AW5: 2002 | AX5: 2003 | AY5: 2003 | AZ5: 2003 | BA5: 2003 | BB5: 2003 | BC5: 2003 | BD5: 2004 | BE5: 2004 | BF5: 2004 | BG5: 2004 | BH5: 2004 | BI5: 2004 | BJ5: 2005 | BK5: 2005 | BL5: 2005 | BM5: 2005 | BN5: 2005 | BO5: 2005 | BP5: 2006 | BQ5: 2006 | BR5: 2006 | BS5: 2006 | BT5: 2006 | BU5: 2006 | BV5: 2007 | BW5: 2007 | BX5: 2007 | BY5: 2007 | BZ5: 2007 | CA5: 2007 | CB5: 2008 | CC5: 2008 | CD5: 2008 | CE5: 2008 | CF5: 2008 | CG5: 2008 | CH5: 2009 | CI5: 2009 | CJ5: 2009 | CK5: 2009 | CL5: 2009 | CM5: 2009 | CN5: 2010 | CO5: 2010 | CP5: 2010 | CQ5: 2010 | CR5: 2010 | CS5: 2010
B6: ALL | C6: ALL | D6: White | E6: White | F6: Black | G6: Black | H6: ALL | I6: ALL | J6: White | K6: White | L6: Black | M6: Black | N6: ALL | O6: ALL | P6: White | Q6: White | R6: Black | S6: Black | T6: ALL | U6: ALL | V6: White | W6: White | X6: Black | Y6: Black | Z6: ALL | AA6: ALL | AB6: White | AC6: White | AD6: Black | AE6: Black | AF6: ALL | AG6: ALL | AH6: White | AI6: White | AJ6: Black | AK6: Black | AL6: ALL | AM6: ALL | AN6: White | AO6: White | AP6: Black | AQ6: Black | AR6: ALL | AS6: ALL | AT6: White | AU6: White | AV6: Black | AW6: Black | AX6: ALL | AY6: ALL | AZ6: White | BA6: White | BB6: Black | BC6: Black | BD6: ALL | BE6: ALL | BF6: White | BG6: White | BH6: Black | BI6: Black | BJ6: ALL | BK6: ALL | BL6: White | BM6: White | BN6: Black | BO6: Black | BP6: ALL | BQ6: ALL | BR6: White | BS6: White | BT6: Black | BU6: Black | BV6: ALL | BW6: ALL | BX6: White | BY6: White | BZ6: Black | CA6: Black | CB6: ALL | CC6: ALL | CD6: White | CE6: White | CF6: Black | CG6: Black | CH6: ALL | CI6: ALL | CJ6: White | CK6: White | CL6: Black | CM6: Black | CN6: ALL | CO6: ALL | CP6: White | CQ6: White | CR6: Black | CS6: Black
B7: Male | C7: Female | D7: Male | E7: Female | F7: Male | G7: Female | H7: Male | I7: Female | J7: Male | K7: Female | L7: Male | M7: Female | N7: Male | O7: Female | P7: Male | Q7: Female | R7: Male | S7: Female | T7: Male | U7: Female | V7: Male | W7: Female | X7: Male | Y7: Female | Z7: Male | AA7: Female | AB7: Male | AC7: Female | AD7: Male | AE7: Female | AF7: Male | AG7: Female | AH7: Male | AI7: Female | AJ7: Male | AK7: Female | AL7: Male | AM7: Female | AN7: Male | AO7: Female | AP7: Male | AQ7: Female | AR7: Male | AS7: Female | AT7: Male | AU7: Female | AV7: Male | AW7: Female | AX7: Male | AY7: Female | AZ7: Male | BA7: Female | BB7: Male | BC7: Female | BD7: Male | BE7: Female | BF7: Male | BG7: Female | BH7: Male | BI7: Female | BJ7: Male | BK7: Female | BL7: Male | BM7: Female | BN7: Male | BO7: Female | BP7: Male | BQ7: Female | BR7: Male | BS7: Female | BT7: Male | BU7: Female | BV7: Male | BW7: Female | BX7: Male | BY7: Female | BZ7: Male | CA7: Female | CB7: Male | CC7: Female | CD7: Male | CE7: Female | CF7: Male | CG7: Female | CH7: Male | CI7: Female | CJ7: Male | CK7: Female | CL7: Male | CM7: Female | CN7: Male | CO7: Female | CP7: Male | CQ7: Female | CR7: Male | CS7: Female
A8: Alabama | B8: 2066303 | C8: 2230497 | D8: 1527045 | E8: 1607048 | F8: 515742 | G8: 598291 | H8: 2083879 | I8: 2247223 | J8: 1538349 | K8: 1616610 | L8: 520918 | M8: 604175 | N8: 2103125 | O8: 2264810 | P8: 1549462 | Q8: 1625381 | R8: 528001 | S8: 612119 | T8: 2122835 | U8: 2281866 | V8: 1562991 | W8: 1635049 | X8: 533599 | Y8: 618649 | Z8: 2136882 | AA8: 2293259 | AB8: 1570643 | AC8: 1640665 | AD8: 539198 | AE8: 623475 | AF8: 2149338 | AG8: 2302835 | AH8: 1576095 | AI8: 1643761 | AJ8: 543178 | AK8: 627439 | AL8: 2158138 | AM8: 2309496 | AN8: 1580087 | AO8: 1645541 | AP8: 546578 | AQ8: 630901 | AR8: 2165719 | AS8: 2314370 | AT8: 1583267 | AU8: 1646445 | AV8: 549217 | AW8: 633374 | AX8: 2179422 | AY8: 2324069 | AZ8: 1590946 | BA8: 1650890 | BB8: 553307 | BC8: 636876 | BD8: 2192872 | BE8: 2337857 | BF8: 1598272 | BG8: 1657539 | BH8: 557319 | BI8: 641873 | BJ8: 2211403 | BK8: 2354514 | BL8: 1609163 | BM8: 1666877 | BN8: 562888 | BO8: 647132 | BP8: 2243501 | BQ8: 2385480 | BR8: 1629110 | BS8: 1685050 | BT8: 572880 | BU8: 657654 | BV8: 2265565 | BW8: 2407275 | BX8: 1643115 | BY8: 1697518 | BZ8: 579036 | CA8: 664831 | CB8: 2287949 | CC8: 2430257 | CD8: 1656414 | CE8: 1710122 | CF8: 586075 | CG8: 673102 | CH8: 2309779 | CI8: 2448159 | CJ8: 1669087 | CK8: 1720115 | CL8: 592661 | CM8: 678586 | CN8: 2322488 | CO8: 2462913 | CP8: 1674201 | CQ8: 1726884 | CR8: 598478 | CS8: 684665
A9: Alaska | B9: 315209 | C9: 289203 | D9: 241228 | E9: 215737 | F9: 13063 | G9: 11791 | H9: 316614 | I9: 291955 | J9: 240895 | K9: 216874 | L9: 12972 | M9: 11491 | N9: 318156 | O9: 294812 | P9: 240363 | Q9: 217545 | R9: 13341 | S9: 12011 | T9: 321423 | U9: 298509 | V9: 241625 | W9: 218931 | X9: 13747 | Y9: 12447 | Z9: 323513 | AA9: 301266 | AB9: 242016 | AC9: 220036 | AD9: 13900 | AE9: 12710 | AF9: 324750 | AG9: 303213 | AH9: 241212 | AI9: 219884 | AJ9: 13979 | AK9: 12728 | AL9: 328135 | AM9: 305579 | AN9: 243010 | AO9: 220808 | AP9: 14442 | AQ9: 12905 | AR9: 332704 | AS9: 309633 | AT9: 245728 | AU9: 222980 | AV9: 14871 | AW9: 13286 | AX9: 335380 | AY9: 313034 | AZ9: 246827 | BA9: 224714 | BB9: 14778 | BC9: 13418 | BD9: 341479 | BE9: 317807 | BF9: 250719 | BG9: 227747 | BH9: 15144 | BI9: 13519 | BJ9: 346026 | BK9: 320920 | BL9: 253360 | BM9: 229332 | BN9: 15369 | BO9: 13402 | BP9: 350181 | BQ9: 325121 | BR9: 256051 | BS9: 231903 | BT9: 15466 | BU9: 13612 | BV9: 353162 | BW9: 327138 | BX9: 257707 | BY9: 232706 | BZ9: 15857 | CA9: 13735 | CB9: 358043 | CC9: 329412 | CD9: 260411 | CE9: 233554 | CF9: 16304 | CG9: 13771 | CH9: 361893 | CI9: 337002 | CJ9: 261942 | CK9: 237925 | CL9: 16271 | CM9: 14302 | CN9: 371569 | CO9: 342577 | CP9: 268492 | CQ9: 241296 | CR9: 17207 | CS9: 14538
A10: Arizona | B10: 2200659 | C10: 2231840 | D10: 1957485 | E10: 1984303 | F10: 77955 | G10: 72469 | H10: 2280058 | I10: 2306882 | J10: 2026609 | K10: 2049348 | L10: 81961 | M10: 75907 | N10: 2357403 | O10: 2379587 | P10: 2095145 | Q10: 2112672 | R10: 85452 | S10: 78993 | T10: 2432754 | U10: 2450588 | V10: 2161465 | W10: 2176043 | X10: 89380 | Y10: 82060 | Z10: 2505524 | AA10: 2518299 | AB10: 2225387 | AC10: 2235195 | AD10: 92706 | AE10: 84913 | AF10: 2576007 | AG10: 2584579 | AH10: 2286610 | AI10: 2292305 | AJ10: 96657 | AK10: 88186 | AL10: 2631801 | AM10: 2641676 | AN10: 2331036 | AO10: 2338263 | AP10: 101524 | AQ10: 92677 | AR10: 2692038 | AS10: 2704217 | AT10: 2378350 | AU10: 2387929 | AV10: 106719 | AW10: 97457 | AX10: 2746287 | AY10: 2764077 | AZ10: 2419988 | BA10: 2434530 | BB10: 111521 | BC10: 102472 | BD10: 2816798 | BE10: 2835606 | BF10: 2474943 | BG10: 2490861 | BH10: 118344 | BI10: 108612 | BJ10: 2908266 | BK10: 2930811 | BL10: 2546316 | BM10: 2565676 | BN10: 126665 | BO10: 116409 | BP10: 3003007 | BQ10: 3026134 | BR10: 2617740 | BS10: 2637738 | BT10: 136589 | BU10: 125561 | BV10: 3070683 | BW10: 3096998 | BX10: 2665511 | BY10: 2688894 | BZ10: 145010 | CA10: 133527 | CB10: 3125084 | CC10: 3155278 | CD10: 2701226 | CE10: 2728728 | CF10: 153329 | CG10: 141288 | CH10: 3153246 | CI10: 3189908 | CJ10: 2715119 | CK10: 2748928 | CL10: 160123 | CM10: 147897 | CN10: 3186528 | CO10: 3226630 | CP10: 2736863 | CQ10: 2774090 | CR10: 164874 | CS10: 152472
A11: Arkansas | B11: 1228626 | C11: 1306773 | D11: 1024618 | E11: 1074863 | F11: 189107 | G11: 215520 | H11: 1248406 | I11: 1323703 | J11: 1039552 | K11: 1087518 | L11: 192760 | M11: 218690 | N11: 1263936 | O11: 1337154 | P11: 1051586 | Q11: 1097570 | R11: 195240 | S11: 221051 | T11: 1277869 | U11: 1348420 | V11: 1062455 | W11: 1105664 | X11: 197552 | Y11: 223228 | Z11: 1292415 | AA11: 1359445 | AB11: 1073571 | AC11: 1114373 | AD11: 199799 | AE11: 224639 | AF11: 1307573 | AG11: 1371015 | AH11: 1084495 | AI11: 1122258 | AJ11: 201462 | AK11: 225797 | AL11: 1314726 | AM11: 1376845 | AN11: 1089018 | AO11: 1125638 | AP11: 202944 | AQ11: 226985 | AR11: 1322688 | AS11: 1383239 | AT11: 1094352 | AU11: 1129765 | AV11: 204372 | AW11: 227958 | AX11: 1333293 | AY11: 1391523 | AZ11: 1101895 | BA11: 1135532 | BB11: 205988 | BC11: 229037 | BD11: 1346638 | BE11: 1403048 | BF11: 1111849 | BG11: 1143496 | BH11: 207731 | BI11: 230981 | BJ11: 1362802 | BK11: 1418295 | BL11: 1123888 | BM11: 1155109 | BN11: 209922 | BO11: 232752 | BP11: 1383333 | BQ11: 1438428 | BR11: 1139123 | BS11: 1169326 | BT11: 213691 | BU11: 236691 | BV11: 1397292 | BW11: 1451358 | BX11: 1149772 | BY11: 1179180 | BZ11: 215316 | CA11: 238117 | CB11: 1410334 | CC11: 1464220 | CD11: 1158925 | CE11: 1187921 | CF11: 217674 | CG11: 240701 | CH11: 1421830 | CI11: 1475013 | CJ11: 1166316 | CK11: 1195266 | CL11: 219939 | CM11: 242268 | CN11: 1434619 | CO11: 1486969 | CP11: 1174454 | CQ11: 1202791 | CR11: 222744 | CS11: 245011
