Workbook

Sheet Sheet1
A1: STable 4: Strains used in this study
A2: Straina | B2: Genotype
A3: RDKY6078 | B3: MATa lys2-10A, hom3-10, ura3∆0, leu2∆0, trp1∆63, his3∆200
A4: RDKY6079 | B4: MATalpha lys2-10A, hom3-10, ura3∆0, leu2∆0, trp1∆63, his3∆200
A5: RDKY6076 | B5: MATa lys2-10A, hom3-10, ura3∆0, leu2∆0, trp1∆63, his3∆200 iYEL062w::Ty912 hxt13::URA3
A6: RDKY6077 | B6: MATa lys2-10A, hom3-10, ura3∆0, leu2∆0, trp1∆63, his3∆200 iYEL062w::Ty912 hxt13::URA3
A7: RDKY6088 | B7: MATa lys2-10A, hom3-10, ura3∆0, leu2∆0, trp1∆63, his3∆200 hxt13::URA3
A8: RDKY6089 | B8: MATa lys2-10A, hom3-10, ura3∆0, leu2∆0, trp1∆63, his3∆200 hxt13::URA3
A9: =CONCATENATE("RDKY",Sheet2!B1) -> RDKY6105 | B9: MATa lys2-10A, hom3-10, ura3∆0, leu2∆0, trp1∆63, his3∆200 hxt13::URA3 mre11::kanMX4
A10: =CONCATENATE("RDKY",Sheet2!C1) -> RDKY6106 | B10: MATa lys2-10A, hom3-10, ura3∆0, leu2∆0, trp1∆63, his3∆200 hxt13::URA3 mre11::kanMX4
A11: =CONCATENATE("RDKY",Sheet2!D1) -> RDKY6499 | B11: MATa lys2-10A, hom3-10, ura3∆0, leu2∆0, trp1∆63, his3∆200 iYEL062w::Ty912 hxt13::URA3 mre11::kanMX4
A12: =CONCATENATE("RDKY",Sheet2!E1) -> RDKY6500 | B12: MATa lys2-10A, hom3-10, ura3∆0, leu2∆0, trp1∆63, his3∆200 iYEL062w::Ty912 hxt13::URA3 mre11::kanMX4
A13: =CONCATENATE("RDKY",Sheet2!B2) -> RDKY6619 | B13: MATa lys2-10A, hom3-10, ura3∆0, leu2∆0, trp1∆63, his3∆200 hxt13::URA3 rad52::kanMX4
A14: =CONCATENATE("RDKY",Sheet2!C2) -> RDKY6620 | B14: MATa lys2-10A, hom3-10, ura3∆0, leu2∆0, trp1∆63, his3∆200 hxt13::URA3 rad52::kanMX4
A15: =CONCATENATE("RDKY",Sheet2!D2) -> RDKY6503 | B15: MATa lys2-10A, hom3-10, ura3∆0, leu2∆0, trp1∆63, his3∆200 iYEL062w::Ty912 hxt13::URA3 rad52::kanMX4
A16: =CONCATENATE("RDKY",Sheet2!E2) -> RDKY6504 | B16: MATa lys2-10A, hom3-10, ura3∆0, leu2∆0, trp1∆63, his3∆200 iYEL062w::Ty912 hxt13::URA3 rad52::kanMX4
A17: RDKY6557 | B17: MATa lys2-10A, hom3-10, ura3∆0, leu2∆0, trp1∆63, his3∆200 hxt13::URA3 rad51::kanMX4
A18: RDKY6558 | B18: MATa lys2-10A, hom3-10, ura3∆0, leu2∆0, trp1∆63, his3∆200 hxt13::URA3 rad51::kanMX4
A19: RDKY6555 | B19: MATa lys2-10A, hom3-10, ura3∆0, leu2∆0, trp1∆63, his3∆200 iYEL062w::Ty912 hxt13::URA3 rad51::kanMX4
A20: RDKY6556 | B20: MATa lys2-10A, hom3-10, ura3∆0, leu2∆0, trp1∆63, his3∆200 iYEL062w::Ty912 hxt13::URA3 rad51::kanMX4
A21: RDKY6597 | B21: MATa lys2-10A, hom3-10, ura3∆0, leu2∆0, trp1∆63, his3∆200 hxt13::URA3 rad59::kanMX4
A22: RDKY6598 | B22: MATa lys2-10A, hom3-10, ura3∆0, leu2∆0, trp1∆63, his3∆200 hxt13::URA3 rad59::kanMX4
A23: RDKY6599 | B23: MATa lys2-10A, hom3-10, ura3∆0, leu2∆0, trp1∆63, his3∆200 iYEL062w::Ty912 hxt13::URA3 rad59::kanMX4
A24: RDKY6600 | B24: MATa lys2-10A, hom3-10, ura3∆0, leu2∆0, trp1∆63, his3∆200 iYEL062w::Ty912 hxt13::URA3 rad59::kanMX4
A25: RDKY6539 | B25: MATa lys2-10A, hom3-10, ura3∆0, leu2∆0, trp1∆63, his3∆200 iYEL062w::Ty912 hxt13::URA3 srs2::kanMX4
A26: RDKY6540 | B26: MATa lys2-10A, hom3-10, ura3∆0, leu2∆0, trp1∆63, his3∆200 iYEL062w::Ty912 hxt13::URA3 srs2::kanMX4
A27: RDKY6107 | B27: MATa lys2-10A, hom3-10, ura3∆0, leu2∆0, trp1∆63, his3∆200 hxt13::URA3 sgs1::kanMX4
A28: RDKY6108 | B28: MATa lys2-10A, hom3-10, ura3∆0, leu2∆0, trp1∆63, his3∆200 hxt13::URA3 sgs1::kanMX4
... A182: RDKY6534 | B182: MATa lys2-10A, hom3-10, ura3∆0, leu2∆0, trp1∆63, his3∆200 iYEL062w::Ty912 hxt13::URA3 est2::kanMX4
A184: a All strains are isogenic to S288c

Sheet Sheet2
A1: mre11 | B1: 6105 | C1: 6106 | D1: 6499 | E1: 6500 | F1: =CONCATENATE("RDKY", B1) -> RDKY6105 | G1: =CONCATENATE("RDKY", C1) -> RDKY6106 | H1: =CONCATENATE("RDKY", D1) -> RDKY6499 | I1: =CONCATENATE("RDKY", E1) -> RDKY6500
A2: rad52 | B2: 6619 | C2: 6620 | D2: 6503 | E2: 6504 | F2: =CONCATENATE("RDKY", B2) -> RDKY6619 | G2: =CONCATENATE("RDKY", C2) -> RDKY6620 | H2: =CONCATENATE("RDKY", D2) -> RDKY6503 | I2: =CONCATENATE("RDKY", E2) -> RDKY6504
A3: rad51 | B3: 6557 | C3: 6558 | D3: 6555 | E3: 6556 | F3: =CONCATENATE("RDKY", B3) -> RDKY6557 | G3: =CONCATENATE("RDKY", C3) -> RDKY6558 | H3: =CONCATENATE("RDKY", D3) -> RDKY6555 | I3: =CONCATENATE("RDKY", E3) -> RDKY6556
A4: rad59 | B4: 6597 | C4: 6598 | D4: 6599 | E4: 6600 | F4: =CONCATENATE("RDKY", B4) -> RDKY6597 | G4: =CONCATENATE("RDKY", C4) -> RDKY6598 | H4: =CONCATENATE("RDKY", D4) -> RDKY6599 | I4: =CONCATENATE("RDKY", E4) -> RDKY6600
A5: srs2 | B5: 5557c | D5: 6539 | E5: 6540 | F5: =CONCATENATE("RDKY", B5) -> RDKY5557c | G5: =CONCATENATE("RDKY", C5) -> RDKY | H5: =CONCATENATE("RDKY", D5) -> RDKY6539 | I5: =CONCATENATE("RDKY", E5) -> RDKY6540
A6: sgs1 | B6: 6107 | C6: 6108 | D6: 6501 | E6: 6502 | F6: =CONCATENATE("RDKY", B6) -> RDKY6107 | G6: =CONCATENATE("RDKY", C6) -> RDKY6108 | H6: =CONCATENATE("RDKY", D6) -> RDKY6501 | I6: =CONCATENATE("RDKY", E6) -> RDKY6502
A7: rad51 rad59 | B7: 7081 | C7: 7082 | D7: 7083 | E7: 7084 | F7: =CONCATENATE("RDKY", B7) -> RDKY7081 | G7: =CONCATENATE("RDKY", C7) -> RDKY7082 | H7: =CONCATENATE("RDKY", D7) -> RDKY7083 | I7: =CONCATENATE("RDKY", E7) -> RDKY7084
A8: rad52 rad51 | B8: 7185 | C8: 7186 | D8: 7187 | E8: 7188 | F8: =CONCATENATE("RDKY", B8) -> RDKY7185 | G8: =CONCATENATE("RDKY", C8) -> RDKY7186 | H8: =CONCATENATE("RDKY", D8) -> RDKY7187 | I8: =CONCATENATE("RDKY", E8) -> RDKY7188
A9: rad52 rad59 | B9: 7189 | C9: 7190 | D9: 7191 | E9: 7192 | F9: =CONCATENATE("RDKY", B9) -> RDKY7189 | G9: =CONCATENATE("RDKY", C9) -> RDKY7190 | H9: =CONCATENATE("RDKY", D9) -> RDKY7191 | I9: =CONCATENATE("RDKY", E9) -> RDKY7192
A10: rad52 rad51 rad59 | B10: 7087 | C10: 7088 | D10: 7085 | E10: 7086 | F10: =CONCATENATE("RDKY", B10) -> RDKY7087 | G10: =CONCATENATE("RDKY", C10) -> RDKY7088 | H10: =CONCATENATE("RDKY", D10) -> RDKY7085 | I10: =CONCATENATE("RDKY", E10) -> RDKY7086
F11: =CONCATENATE("RDKY", B11) -> RDKY | G11: =CONCATENATE("RDKY", C11) -> RDKY | H11: =CONCATENATE("RDKY", D11) -> RDKY | I11: =CONCATENATE("RDKY", E11) -> RDKY
A12: rfa1-t33 | B12: 7042 | D12: 7043 | E12: 7072 | F12: =CONCATENATE("RDKY", B12) -> RDKY7042 | G12: =CONCATENATE("RDKY", C12) -> RDKY | H12: =CONCATENATE("RDKY", D12) -> RDKY7043 | I12: =CONCATENATE("RDKY", E12) -> RDKY7072
A13: rrm3/rtt104 | B13: 5556c | D13: 6527 | E13: 6528 | F13: =CONCATENATE("RDKY", B13) -> RDKY5556c | G13: =CONCATENATE("RDKY", C13) -> RDKY | H13: =CONCATENATE("RDKY", D13) -> RDKY6527 | I13: =CONCATENATE("RDKY", E13) -> RDKY6528
A14: rtt107/esc4 | B14: 6167 | C14: 6168 | D14: 6525 | E14: 6526 | F14: =CONCATENATE("RDKY", B14) -> RDKY6167 | G14: =CONCATENATE("RDKY", C14) -> RDKY6168 | H14: =CONCATENATE("RDKY", D14) -> RDKY6525 | I14: =CONCATENATE("RDKY", E14) -> RDKY6526
A15: sir4 | B15: 7177 | C15: 7178 | D15: 7179 | E15: 7180 | F15: =CONCATENATE("RDKY", B15) -> RDKY7177 | G15: =CONCATENATE("RDKY", C15) -> RDKY7178 | H15: =CONCATENATE("RDKY", D15) -> RDKY7179 | I15: =CONCATENATE("RDKY", E15) -> RDKY7180
A16: mms1 | B16: 6189 | C16: 6190 | D16: 6535 | E16: 6536 | F16: =CONCATENATE("RDKY", B16) -> RDKY6189 | G16: =CONCATENATE("RDKY", C16) -> RDKY6190 | H16: =CONCATENATE("RDKY", D16) -> RDKY6535 | I16: =CONCATENATE("RDKY", E16) -> RDKY6536
A17: rad27 | B17: 6543 | C17: 6544 | D17: 6545 | E17: 6546 | F17: =CONCATENATE("RDKY", B17) -> RDKY6543 | G17: =CONCATENATE("RDKY", C17) -> RDKY6544 | H17: =CONCATENATE("RDKY", D17) -> RDKY6545 | I17: =CONCATENATE("RDKY", E17) -> RDKY6546
A18: cdc9-1 | B18: 7039 | D18: 7040 | E18: 7041 | F18: =CONCATENATE("RDKY", B18) -> RDKY7039 | G18: =CONCATENATE("RDKY", C18) -> RDKY | H18: =CONCATENATE("RDKY", D18) -> RDKY7040 | I18: =CONCATENATE("RDKY", E18) -> RDKY7041
A19: elg1/rtt110 | B19: 6151 | C19: 6152 | D19: 6509 | E19: 6510 | F19: =CONCATENATE("RDKY", B19) -> RDKY6151 | G19: =CONCATENATE("RDKY", C19) -> RDKY6152 | H19: =CONCATENATE("RDKY", D19) -> RDKY6509 | I19: =CONCATENATE("RDKY", E19) -> RDKY6510
F20: =CONCATENATE("RDKY", B20) -> RDKY | G20: =CONCATENATE("RDKY", C20) -> RDKY | H20: =CONCATENATE("RDKY", D20) -> RDKY | I20: =CONCATENATE("RDKY", E20) -> RDKY
A21: sml1 | B21: 6589 | C21: 6590 | D21: 7073 | E21: 7074 | F21: =CONCATENATE("RDKY", B21) -> RDKY6589 | G21: =CONCATENATE("RDKY", C21) -> RDKY6590 | H21: =CONCATENATE("RDKY", D21) -> RDKY7073 | I21: =CONCATENATE("RDKY", E21) -> RDKY7074
A22: mec1 sml1 | B22: 6583 | C22: 6584 | D22: 6581 | E22: 6582 | F22: =CONCATENATE("RDKY", B22) -> RDKY6583 | G22: =CONCATENATE("RDKY", C22) -> RDKY6584 | H22: =CONCATENATE("RDKY", D22) -> RDKY6581 | I22: =CONCATENATE("RDKY", E22) -> RDKY6582
A23: rad53 sml1 | B23: 6585 | C23: 6586 | D23: 6587 | E23: 6588 | F23: =CONCATENATE("RDKY", B23) -> RDKY6585 | G23: =CONCATENATE("RDKY", C23) -> RDKY6586 | H23: =CONCATENATE("RDKY", D23) -> RDKY6587 | I23: =CONCATENATE("RDKY", E23) -> RDKY6588
A24: dun1 | B24: 3739d | D24: 6515 | E24: 6516 | F24: =CONCATENATE("RDKY", B24) -> RDKY3739d | G24: =CONCATENATE("RDKY", C24) -> RDKY | H24: =CONCATENATE("RDKY", D24) -> RDKY6515 | I24: =CONCATENATE("RDKY", E24) -> RDKY6516
A25: chk1 | B25: 3745e | D25: 6623 | E25: 6624 | F25: =CONCATENATE("RDKY", B25) -> RDKY3745e | G25: =CONCATENATE("RDKY", C25) -> RDKY | H25: =CONCATENATE("RDKY", D25) -> RDKY6623 | I25: =CONCATENATE("RDKY", E25) -> RDKY6624
A26: tel1 | B26: 6569 | C26: 6570 | D26: 6571 | E26: 6572 | F26: =CONCATENATE("RDKY", B26) -> RDKY6569 | G26: =CONCATENATE("RDKY", C26) -> RDKY6570 | H26: =CONCATENATE("RDKY", D26) -> RDKY6571 | I26: =CONCATENATE("RDKY", E26) -> RDKY6572
A27: rad9 | B27: 3719e | D27: 6625 | E27: 6626 | F27: =CONCATENATE("RDKY", B27) -> RDKY3719e | G27: =CONCATENATE("RDKY", C27) -> RDKY | H27: =CONCATENATE("RDKY", D27) -> RDKY6625 | I27: =CONCATENATE("RDKY", E27) -> RDKY6626
A28: mrc1 | B28: 6175 | C28: 6176 | D28: 6529 | E28: 6530 | F28: =CONCATENATE("RDKY", B28) -> RDKY6175 | G28: =CONCATENATE("RDKY", C28) -> RDKY6176 | H28: =CONCATENATE("RDKY", D28) -> RDKY6529 | I28: =CONCATENATE("RDKY", E28) -> RDKY6530
A29: csm3 | B29: 6149 | C29: 6150 | D29: 6517 | E29: 6518 | F29: =CONCATENATE("RDKY", B29) -> RDKY6149 | G29: =CONCATENATE("RDKY", C29) -> RDKY6150 | H29: =CONCATENATE("RDKY", D29) -> RDKY6517 | I29: =CONCATENATE("RDKY", E29) -> RDKY6518
A30: sic1 | B30: 6551 | C30: 6552 | D30: 6553 | E30: 6554 | F30: =CONCATENATE("RDKY", B30) -> RDKY6551 | G30: =CONCATENATE("RDKY", C30) -> RDKY6552 | H30: =CONCATENATE("RDKY", D30) -> RDKY6553 | I30: =CONCATENATE("RDKY", E30) -> RDKY6554
F31: =CONCATENATE("RDKY", B31) -> RDKY | G31: =CONCATENATE("RDKY", C31) -> RDKY | H31: =CONCATENATE("RDKY", D31) -> RDKY | I31: =CONCATENATE("RDKY", E31) -> RDKY
A32: rtt105 | B32: 6191 | C32: 6192 | D32: 6537 | E32: 6538 | F32: =CONCATENATE("RDKY", B32) -> RDKY6191 | G32: =CONCATENATE("RDKY", C32) -> RDKY6192 | H32: =CONCATENATE("RDKY", D32) -> RDKY6537 | I32: =CONCATENATE("RDKY", E32) -> RDKY6538
A33: pmr1 | B33: 7017 | C33: 7018 | D33: 7019 | E33: 7020 | F33: =CONCATENATE("RDKY", B33) -> RDKY7017 | G33: =CONCATENATE("RDKY", C33) -> RDKY7018 | H33: =CONCATENATE("RDKY", D33) -> RDKY7019 | I33: =CONCATENATE("RDKY", E33) -> RDKY7020
F34: =CONCATENATE("RDKY", B34) -> RDKY | G34: =CONCATENATE("RDKY", C34) -> RDKY | H34: =CONCATENATE("RDKY", D34) -> RDKY | I34: =CONCATENATE("RDKY", E34) -> RDKY
A35: mlh1 | B35: 6603 | D35: 6601 | E35: 6602 | F35: =CONCATENATE("RDKY", B35) -> RDKY6603 | G35: =CONCATENATE("RDKY", C35) -> RDKY | H35: =CONCATENATE("RDKY", D35) -> RDKY6601 | I35: =CONCATENATE("RDKY", E35) -> RDKY6602
A36: msh2 | B36: 6605 | C36: 6606 | D36: 6607 | E36: 6608 | F36: =CONCATENATE("RDKY", B36) -> RDKY6605 | G36: =CONCATENATE("RDKY", C36) -> RDKY6606 | H36: =CONCATENATE("RDKY", D36) -> RDKY6607 | I36: =CONCATENATE("RDKY", E36) -> RDKY6608
F37: =CONCATENATE("RDKY", B37) -> RDKY | G37: =CONCATENATE("RDKY", C37) -> RDKY | H37: =CONCATENATE("RDKY", D37) -> RDKY | I37: =CONCATENATE("RDKY", E37) -> RDKY
A38: rad6 | B38: 6143 | C38: 6144 | D38: 6507 | E38: 6508 | F38: =CONCATENATE("RDKY", B38) -> RDKY6143 | G38: =CONCATENATE("RDKY", C38) -> RDKY6144 | H38: =CONCATENATE("RDKY", D38) -> RDKY6507 | I38: =CONCATENATE("RDKY", E38) -> RDKY6508
A39: rad5 | B39: 5519f | D39: 6523 | E39: 6524 | F39: =CONCATENATE("RDKY", B39) -> RDKY5519f | G39: =CONCATENATE("RDKY", C39) -> RDKY | H39: =CONCATENATE("RDKY", D39) -> RDKY6523 | I39: =CONCATENATE("RDKY", E39) -> RDKY6524
F40: =CONCATENATE("RDKY", B40) -> RDKY | G40: =CONCATENATE("RDKY", C40) -> RDKY | H40: =CONCATENATE("RDKY", D40) -> RDKY | I40: =CONCATENATE("RDKY", E40) -> RDKY
...

Sheet Sheet3
