Workbook
Name Macro1: [0]!Macro1
Name Macro2: [0]!Macro2

Sheet Sheet1
E1: 170701 | F1: ERROR!!!! PLEASE USE A VALID CODE | I1: 0 | J1: =I1 -> 0 | K1: 2 | L1: ENTER FTE FOR PART-TIME
E2: 170706 | F2: Biological Sciences-Adjunct Faculty
E3: 170707 | F3: Chemistry-Adjunct Faculty
E4: 170709 | F4: English & Foreign L-Adjunct Faculty
E5: 170710 | F5: Fine Arts-Adjunct Faculty
E6: 170711 | F6: Mathematics-Adjunct Faculty
E7: 170713 | F7: Social Sciences-Adjunct Faculty
E8: 170715 | F8: Business Administra-Adjunct Faculty
E9: 170716 | F9: Communications-Adjunct Faculty
E10: 170717 | F10: Elem. Education-Adjunct Faculty
E11: 170718 | F11: Health & Physical E-Adjunct Faculty
E12: 170720 | F12: Nursing B.S. -Adjunct Faculty
E13: 170721 | F13: Nursing M.S. -Adjunct Faculty
... E49: 182800 | F49: Social Work - Summer School
E53: ORGN CODE | F53: FUND CODE | G53: PROG CODE | I53: ORGN CODE | J53: ORGN DESCRIPTION
D54: ORGN | E54: 110103 | I54: 110103 | J54: Office of Academic Affairs - RESTRICTED
D55: ORGN | E55: 121003 | I55: 121003 | J55: Biology - RESTRICTED
D56: ORGN | E56: 122003 | I56: 122003 | J56: Chemistry - RESTRICTED
D57: ORGN | E57: 123003 | I57: 123003 | J57: Communications - RESTRICTED
D58: ORGN | E58: 124003 | I58: 124003 | J58: English & Foreign Language - RESTRICTED
D59: ORGN | E59: 125103 | I59: 125103 | J59: Fine Arts - RESTRICTED
D60: ORGN | E60: 125203 | I60: 125203 | J60: Music - RESTRICTED
D61: ORGN | E61: 125303 | I61: 125303 | J61: Humanities - RESTRICTED
D62: ORGN | E62: 125403 | I62: 125403 | J62: Speech - RESTRICTED
D63: ORGN | E63: 125503 | I63: 125503 | J63: Arts - RESTRICTED
D64: ORGN | E64: 126003 | I64: 126003 | J64: Mathematics - RESTRICTED
D65: ORGN | E65: 127003 | I65: 127003 | J65: Military Science - RESTRICTED
... D109: ORGN | E109: 400103 | I109: 400103 | J109: Student Affairs - RESTRICTED
A111: 45 | B111: ** | D111: ORGN | E111: 180100 | F111: 100000 | G111: 01 | I111: 180100 | J111: Agriculture - Summer School
A112: 46 | B112: ** | D112: ORGN | E112: 180200 | F112: 100000 | G112: 01 | I112: 180200 | J112: Home Economics - Summer School
A113: 47 | B113: ** | D113: ORGN | E113: 180300 | F113: 100000 | G113: 01 | I113: 180300 | J113: Advanced Technologies-Summer Sch
A114: 48 | B114: ** | D114: ORGN | E114: 180600 | F114: 100000 | G114: 01 | I114: 180600 | J114: Biological Sciences-Summer Sch
A115: 49 | B115: ** | D115: ORGN | E115: 180700 | F115: 100000 | G115: 01 | I115: 180700 | J115: Chemistry - Summer School
A116: 50 | B116: ** | D116: ORGN | E116: 180900 | F116: 100000 | G116: 01 | I116: 180900 | J116: English & Foreign Lang.-Summer Sch.
A117: 51 | B117: ** | D117: ORGN | E117: 181000 | F117: 100000 | G117: 01 | I117: 181000 | J117: Fine Arts - Summer School
A118: 52 | B118: ** | D118: ORGN | E118: 181100 | F118: 100000 | G118: 01 | I118: 181100 | J118: Mathematics - Summer School
A119: 53 | B119: ** | D119: ORGN | E119: 181300 | F119: 100000 | G119: 01 | I119: 181300 | J119: Social Science - Summer School
A120: 54 | B120: ** | D120: ORGN | E120: 181500 | F120: 100000 | G120: 01 | I120: 181500 | J120: Business Admini. - Summer School
A121: 55 | B121: ** | D121: ORGN | E121: 181700 | F121: 100000 | G121: 01 | I121: 181700 | J121: Elementary Education - Summer Sch.
A122: 56 | B122: ** | D122: ORGN | E122: 181800 | F122: 100000 | G122: 01 | I122: 181800 | J122: Health & Physical Educ. - Summer
...

Sheet Fall.Spring.ActionForm
B2: ALCORN STATE UNIVERSITY
B4: FALL & SPRING
B5: ADJUNCT & OVERLOAD ASSIGNMENT ACTION FORM
B7: This form is submitted to request a one time payment to existing faculty members/overload, *RECURRING adjunct faculty members,
B8: and staff members/2nd assignment for classes taught during the Fall or Spring Semester. Payment will be made at the close
B9: of the applicable semester.
B10: NOTE: Adjunct Faculty Members who are ORIGINAL APPOINTLENTS to the university, RECENTLY RETIRED, or need to RENEW
B11: after a break in service that extends beyond 1 year are NOT included on this form. A PAF is required by Human Resources.
B13: DEPARTMENT | H13: DATE:
B15: CHECK ONE: | E15: FALL | G15: SPRING
B17: ADJUNCT ORGANIZATION CODE: | G17: =VLOOKUP(E17,Sheet1!E1:F19,2,FALSE) -> #N/A
B19: COMMENTS:
C24: ID NUMBER | E24: FACULTY OR STAFF MEMBER | I24: AMOUNT DUE
B26: 1
B27: 2
B28: 3
B29: 4
B30: 5
B31: 6
B32: 7
B33: 8
B34: 9
B35: 10
B36: 11
B37: 12
... B45: 20
G48: TOTAL | I48: =SUM(I25:I45) -> 0
G49: Budget Office
B50: Chairperson | H50: Date:
B52: Dean | H52: Date:
B54: Area Vice President | H54: Date:

Sheet SummerAssignmentActionForm
B2: ALCORN STATE UNIVERSITY
B4: SUMMER ASSIGNMENT ACTION FORM
B6: This form is submitted to request a one time payment to existing faculty members/overload, *RECURRING adjunct faculty members,
B7: and staff members/2nd assignment for classes taught during a summer session. Payment will be made at the close of the
B8: applicable summer session.
B9: NOTE: Adjunct Faculty Members who are ORIGINAL APPOINTMENTS to the university, RECENTLY RETIRED, or need to RENEW
B10: after a break in service that extends beyond 1 year are NOT included on this form. A PAF is required by Human Resources.
B12: DEPARTMENT | K12: DATE:
B14: CHECK ONE: | D14: SUMMER I | F14: SUMMER II
B16: SUMMER ORGANIZATION CODE: | H16: =VLOOKUP(F16,Sheet1!E21:F49,2,FALSE) -> #N/A
B18: COMMENTS:
B20: ID NUMBER | D20: FACULTY/STAFF MEMBER | F20: POSITION NUMBER | H20: ANNUAL SALARY | J20: MONTHLY SALARY | L20: AMOUNT DUE | P20: For Business Office Use
A22: 1 | J22: =H22/9 -> 0 | Q22: 1
A23: 2 | J23: =H23/9 -> 0 | Q23: 2
A24: 3 | J24: =H24/9 -> 0 | Q24: 3
A25: 4 | J25: =H25/9 -> 0 | Q25: 4
A26: 5 | J26: =H26/9 -> 0 | Q26: 5
A27: 6 | J27: =H27/9 -> 0 | Q27: 6
A28: 7 | J28: =H28/9 -> 0 | Q28: 7
A29: 8 | J29: =H29/9 -> 0 | Q29: 8
A30: 9 | J30: =H30/9 -> 0 | Q30: 9
A31: 10 | J31: =H31/9 -> 0 | Q31: 10
A32: 11 | J32: =H32/9 -> 0 | Q32: 11
A33: 12 | J33: =H33/9 -> 0 | Q33: 12
... A36: 15 | J36: =H36/9 -> 0 | Q36: 15
J39: TOTAL | L39: =SUM(L21:L36) -> 0
J40: Budget Office
B41: SUMMER I
A42: If an employee WHO IS LISTED ABOVE will also be working on a project during SUMMER I, complete this section to request compensation for the portion
A43: of pay that is to be charged to RESTRICTED SOURCES.
B44: ID NUMBER | D44: FACULTY/STAFF MEMBER | F44: RESTRICTED FUND | H44: ORGN | J44: ACCT | L44: AMOUNT DUE (DAYS IN MAY) | N44: AMOUNT DUE (JUNE) | P44: TOTAL AMOUNT DUE
A45: 1 | P45: =+L45+N45 -> 0
A46: 2 | P46: =+L46+N46 -> 0
A47: 3 | P47: =+L47+N47 -> 0
A48: 4 | P48: =+L48+N48 -> 0
A49: 5 | P49: =+L49+N49 -> 0
A50: 6 | P50: =+L50+N50 -> 0
B53: SUMMER II
A54: If an employee WHO IS LISTED ABOVE will also be working on a project during SUMMER II, complete this section to request compensation for the portion
A55: of pay that is to be charged to RESTRICTED SOURCES.
...

Sheet PAF.OriginalRevised
B1: ALCORN STATE UNIVERSITY
B2: PERSONNEL ACTION FORM
B4: To avoid processing delays, please ensure all applicable sections are complete and accurate.
B6: Personal Data
B7: 1 | C7: Last Name | F7: Suffix | G7: First Name | K7: Middle | P7: Prefix | Q7: SSN / ID | U7: Current Date
C9: Current Date | E9: SSN | H9: Date of Birth | M9: Home Phone #
C11: Street Address | G11: City | K11: County | M11: State | W11: Zip Code
C13: Type of Action | I13: Action Dates | O13: Comments
B14: 2 | C14: Original Appointment | F14: Complete Section 4A | I14: Effective date provided by HR | N14: Use the section below for further explanation
C15: Re-Employed (break in employment) | F15: Complete Section 4A | I15: Effective date provided by HR
C16: Extension of Employment (no break) | F16: Complete Sections 4A and 4B | I16: Effective Date
C17: Promotion / Merit / Annual Inc. | F17: Complete Sections 4A and 4B | I17: Effective Date
C18: Transfer | F18: Complete Sections 4A and 4B | I18: Effective Date
C19: Release Time (Projects Only) | F19: Complete Sections 4A and 4B | I19: Effective Date
C20: Separation | F20: Complete Section 4B | I20: Last Date Worked
C21: Other (specify): | I21: Effective Date
B22: Position Data
N23: Adjunct Faculty (select for NEW Adjunct Faculty, RECENTLY RETIRED, or to RENEW former members if there has been more than 1 year break in service, otherwise include on Overload or Summer Assignment Action Form)
B24: 3 | C24: A. Position Type: | F24: Staff | I24: Faculty
C27: B. Rank, if Faculty: | F27: Instructor | I27: Assistant Professor | N27: Associate Professor | R27: Professor | T27: OR | V27: NON FACULTY
C30: C. Pay Type: | F30: 9 Months | I30: 10 Months | N30: 11 Months | R30: 12 Months | V30: Other
C33: D. Pay Frequency: | F33: Monthly | I33: Bi Weekly | N33: One Time Pay at END of the: Semester/Summer Session/Assignment
C36: E. Job Status: | F36: Full Time | H36: 2 | I36: Part-time - FTE for part-time: | L36: =Sheet1!J1 -> 0 | N36: =VLOOKUP(L36,Sheet1!K1:L1,2,FALSE) -> #N/A
C39: F. Assignment: | F39: Regular | I39: Regular (Temporary Funding Source)-End Date: | R39: Temp Employment - End Date:
C42: G. Retiree of PERS of MS? | F42: No | I42: Yes - Retirement Date:
C45: H. Total Salary: | E45: Per Year | H45: Per Hour | L45: Per Other
C48: I. HOME ORGANIZATION (or HOME DEPARTMENT): If this is a Restricted Project, Indicate a Department from the E&G printed budget's Table of Contents that most closely relates to the project, or
C49: indicate the department to which the employee's check should be distributed.
D50: Home Organization Code: | G50: =VLOOKUP(E50,Sheet1!I153:J414,2,FALSE) -> #N/A | V50: 0 | W50: 0
C52: Receiving Department
B53: 4A | C53: POSITIONS CONTAINING E&G FUNDS: budget managers should assign a position from your printed budget. If the position is temporary, an applicable pooled position number should be assigned.
C54: 100% RESTRICTED FUNDS: the position number will be assigned by a Grants & Contracts Accountant
B55: To | C55: Position Number | G55: Position Title
C57: Source of Funding (RECEIVING DEPARTMENT)
C58: E&G Budget Line # | D58: Budget Page # | F58: Fund Code | H58: Organization Code | J58: *Account Code | M58: Budget / Grant Name | S58: **Percentage of Funds | U58: Salary Amount Per Account
M59: =VLOOKUP(H59,Sheet1!I$54:J$289,2,FALSE) -> #N/A | S59: =SUM(U59/U$66) -> #DIV/0!
M60: =VLOOKUP(H60,Sheet1!I$54:J$289,2,FALSE) -> #N/A | S60: =SUM(U60/U$66) -> #DIV/0!
M61: =VLOOKUP(H61,Sheet1!I$54:J$289,2,FALSE) -> #N/A | S61: =SUM(U61/U$66) -> #DIV/0!
M62: =VLOOKUP(H62,Sheet1!I$54:J$289,2,FALSE) -> #N/A | S62: =SUM(U62/U$66) -> #DIV/0!
M63: =VLOOKUP(H63,Sheet1!I$54:J$289,2,FALSE) -> #N/A | S63: =SUM(U63/U$66) -> #DIV/0!
...

Sheet PAF
B1: ALCORN STATE UNIVERSITY
B2: PERSONNEL ACTION FORM
B5: To avoid processing delays, please ensure all applicable sections are complete and accurate.
B7: PERSONAL DATA
B8: 1 | C8: Last Name | F8: Suffix | G8: First Name | K8: Middle | P8: Prefix | Q8: SSN / ID | U8: Current Date
C10: Current Date | E10: SSN | H10: Date of Birth | M10: Home Phone #
C12: Street Address | G12: City | K12: County | M12: State | W12: Zip Code
C14: TYPE OF ACTION | I14: ACTION DATES | N14: COMMENTS
B15: 2 | C15: Original Appointment | F15: Complete Section 4A | I15: Effective date provided by HR | N15: Use the section below for further explanation
C16: Re-Employed (break in employment) | F16: Complete Section 4A | I16: Effective date provided by HR
C17: Extension of Employment (no break) | F17: Complete Sections 4A and 4B | I17: Effective Date
C18: Promotion / Merit / Annual Inc. | F18: Complete Sections 4A and 4B | I18: Effective Date
C19: Transfer | F19: Complete Sections 4A and 4B | I19: Effective Date
C20: Release Time (Projects Only) | F20: Complete Sections 4A and 4B | I20: Effective Date
C21: Separation | F21: Complete Section 4B | I21: Date Last Worked
C22: Other (specify): | I22: Effective Date
B23: POSITION DATA
N24: Adjunct Faculty (select for NEW Adjunct Faculty, RECENTLY RETIRED, or to RENEW former members if there has been more than 1 year break in service, otherwise include on Overload or Summer Assignment Action Form)
B25: 3 | C25: A. Position Type: | F25: Staff | I25: Faculty
C28: B. Rank, if Faculty: | F28: Instructor | I28: Assistant Professor | N28: Associate Professor | R28: Professor | T28: OR | V28: NON FACULTY
C31: C. Pay Type: | F31: 9 Months | I31: 10 Months | N31: 11 Months | R31: 12 Months | V31: Other
C34: D. Pay Frequency: | F34: Monthly | I34: Bi Weekly | N34: One Time Pay at END of the: Semester/Summer Session/Assignment
C37: E. Job Status: | F37: Full Time | H37: 2 | I37: Part-time - FTE for part-time: | L37: =Sheet1!J1 -> 0 | N37: =VLOOKUP(L37,Sheet1!K1:L1,2,FALSE) -> #N/A
C40: F. Assignment: | F40: Regular | I40: Regular (Temporary Funding Source)-End Date: | R40: Temp Employment - End Date:
C43: G. Retiree of PERS of MS? | F43: No | I43: Yes - Retirement Date:
C46: H. Total Salary: | E46: Per Year | H46: Per Hour | L46: Per Other
C49: I. HOME ORGANIZATION (or HOME DEPARTMENT): If this is a Restricted Project, Indicate a Department from the E&G printed budget's Table of Contents that most closely
C50: relates to the project, or indicate the department to which the employee's check should be distributed.
D51: Home Organization Code: | G51: =VLOOKUP(E51,Sheet1!I153:J414,2,FALSE) -> #N/A | V51: 0 | W51: 0
C53: RECEIVING DEPARTMENT
B54: 4A | C54: POSITIONS CONTAINING E&G FUNDS: assign a position from the printed budget. If the position is temporary, an applicable pooled position number may be assigned.
C55: 100% RESTRICTED FUNDS: the position number will be assigned by a Grants & Contracts Accountant
B56: To | C56: Position Number | G56: Position Title
C58: Source of Funding (RECEIVING DEPARTMENT)
C59: E&G Budget Line # | D59: Budget Page # | F59: Fund Code | H59: Organization Code | J59: *Account Code | M59: Budget / Grant Name | S59: **Percentage of Funds | U59: Salary Amount Per Account
M60: =VLOOKUP(H60,Sheet1!I$54:J$289,2,FALSE) -> #N/A | S60: =SUM(U60/U$67) -> #DIV/0!
M61: =VLOOKUP(H61,Sheet1!I$54:J$289,2,FALSE) -> #N/A | S61: =SUM(U61/U$67) -> #DIV/0!
M62: =VLOOKUP(H62,Sheet1!I$54:J$289,2,FALSE) -> #N/A | S62: =SUM(U62/U$67) -> #DIV/0!
M63: =VLOOKUP(H63,Sheet1!I$54:J$289,2,FALSE) -> #N/A | S63: =SUM(U63/U$67) -> #DIV/0!
M64: =VLOOKUP(H64,Sheet1!I$54:J$289,2,FALSE) -> #N/A | S64: =SUM(U64/U$67) -> #DIV/0!
...

Sheet PAF (2)
B1: ALCORN STATE UNIVERSITY
B2: PERSONNEL ACTION FORM
B5: To avoid processing delays, please ensure all applicable sections are complete and accurate.
B7: PERSONAL DATA
B8: 1 | C8: Last Name | F8: Suffix | G8: First Name | K8: Middle | P8: Prefix | Q8: SSN / ID | U8: Current Date
C10: Current Date | E10: SSN | H10: Date of Birth | M10: Home Phone #
C12: Street Address | G12: City | K12: County | M12: State | W12: Zip Code
C14: TYPE OF ACTION | I14: ACTION DATES | N14: COMMENTS
B15: 2 | C15: Original Appointment | F15: Complete Section 4A | I15: Effective date provided by HR | N15: Use the section below for further explanation
C16: Re-Employed (break in employment) | F16: Complete Section 4A | I16: Effective date provided by HR
C17: Extension of Employment (no break) | F17: Complete Sections 4A and 4B | I17: Effective Date
C18: Promotion / Merit / Annual Inc. | F18: Complete Sections 4A and 4B | I18: Effective Date
C19: Transfer | F19: Complete Sections 4A and 4B | I19: Effective Date
C20: Release Time (Projects Only) | F20: Complete Sections 4A and 4B | I20: Effective Date
C21: Separation | F21: Complete Section 4B | I21: Date Last Worked
C22: Other (specify): | I22: Effective Date
B23: POSITION DATA
N24: Adjunct Faculty (select for NEW Adjunct Faculty, RECENTLY RETIRED, or to RENEW former members if there has been more than 1 year break in service, otherwise include on Overload or Summer Assignment Action Form)
B25: 3 | C25: A. Position Type: | F25: Staff | I25: Faculty
C28: B. Rank, if Faculty: | F28: Instructor | I28: Assistant Professor | N28: Associate Professor | R28: Professor | T28: OR | V28: NON FACULTY
C31: C. Pay Type: | F31: 9 Months | I31: 10 Months | N31: 11 Months | R31: 12 Months | V31: Other
C34: D. Pay Frequency: | F34: Monthly | I34: Bi Weekly | N34: One Time Pay at END of the: Semester/Summer Session/Assignment
C37: E. Job Status: | F37: Full Time | H37: 2 | I37: Part-time - FTE for part-time: | L37: =Sheet1!J1 -> 0 | N37: =VLOOKUP(L37,Sheet1!K1:L1,2,FALSE) -> #N/A
C40: F. Assignment: | F40: Regular | I40: Regular (Temporary Funding Source)-End Date: | R40: Temp Employment - End Date:
C43: G. Retiree of PERS of MS? | F43: No | I43: Yes - Retirement Date:
C46: H. Total Salary: | E46: Per Year | H46: Per Hour | L46: Per Other
C49: I. HOME ORGANIZATION (or HOME DEPARTMENT): If this is a Restricted Project, Indicate a Department from the E&G printed budget's Table of Contents that most closely
C50: relates to the project, or indicate the department to which the employee's check should be distributed.
D51: Home Organization Code: | G51: =VLOOKUP(E51,Sheet1!I153:J414,2,FALSE) -> #N/A | V51: 0 | W51: 0
C53: RECEIVING DEPARTMENT
B54: 4A | C54: POSITIONS CONTAINING E&G FUNDS: assign a position from the printed budget. If the position is temporary, an applicable pooled position number may be assigned.
C55: 100% RESTRICTED FUNDS: the position number will be assigned by a Grants & Contracts Accountant
B56: To | C56: Position Number | G56: Position Title
C58: Source of Funding (RECEIVING DEPARTMENT)
C59: E&G Budget Line # | D59: Budget Page # | F59: Fund Code | H59: Organization Code | J59: *Account Code | M59: Budget / Grant Name | S59: **Percentage of Funds | U59: Salary Amount Per Account
M60: =VLOOKUP(H60,Sheet1!I$54:J$289,2,FALSE) -> #N/A | S60: =SUM(U60/U$67) -> #DIV/0!
M61: =VLOOKUP(H61,Sheet1!I$54:J$289,2,FALSE) -> #N/A | S61: =SUM(U61/U$67) -> #DIV/0!
M62: =VLOOKUP(H62,Sheet1!I$54:J$289,2,FALSE) -> #N/A | S62: =SUM(U62/U$67) -> #DIV/0!
M63: =VLOOKUP(H63,Sheet1!I$54:J$289,2,FALSE) -> #N/A | S63: =SUM(U63/U$67) -> #DIV/0!
M64: =VLOOKUP(H64,Sheet1!I$54:J$289,2,FALSE) -> #N/A | S64: =SUM(U64/U$67) -> #DIV/0!
...

Sheet PAF (3)
B1: ALCORN STATE UNIVERSITY
B2: PERSONNEL ACTION FORM
B5: To avoid processing delays, please ensure all applicable sections are complete and accurate.
B7: PERSONAL DATA
B8: 1 | C8: Last Name | F8: Suffix | G8: First Name | K8: Middle | P8: Prefix | Q8: SSN / ID | U8: Current Date
C10: Current Date | E10: SSN | H10: Date of Birth | M10: Home Phone #
C12: Street Address | G12: City | K12: County | M12: State | W12: Zip Code
C14: TYPE OF ACTION | I14: ACTION DATES | N14: COMMENTS
B15: 2 | C15: Original Appointment | F15: Complete Section 4A | I15: Effective date provided by HR | N15: Use the section below for further explanation
C16: Re-Employed (break in employment) | F16: Complete Section 4A | I16: Effective date provided by HR
C17: Extension of Employment (no break) | F17: Complete Sections 4A and 4B | I17: Effective Date
C18: Promotion / Merit / Annual Inc. | F18: Complete Sections 4A and 4B | I18: Effective Date
C19: Transfer | F19: Complete Sections 4A and 4B | I19: Effective Date
C20: Release Time (Projects Only) | F20: Complete Sections 4A and 4B | I20: Effective Date
C21: Separation | F21: Complete Section 4B | I21: Date Last Worked
C22: Other (specify): | I22: Effective Date
B23: POSITION DATA
N24: Adjunct Faculty (select for NEW Adjunct Faculty, RECENTLY RETIRED, or to RENEW former members if there has been more than 1 year break in service, otherwise include on Overload or Summer Assignment Action Form)
B25: 3 | C25: A. Position Type: | F25: Staff | I25: Faculty
C28: B. Rank, if Faculty: | F28: Instructor | I28: Assistant Professor | N28: Associate Professor | R28: Professor | T28: OR | V28: NON FACULTY
C31: C. Pay Type: | F31: 9 Months | I31: 10 Months | N31: 11 Months | R31: 12 Months | V31: Other
C34: D. Pay Frequency: | F34: Monthly | I34: Bi Weekly | N34: One Time Pay at END of the: Semester/Summer Session/Assignment
C37: E. Job Status: | F37: Full Time | H37: 2 | I37: Part-time - FTE for part-time: | L37: =Sheet1!J1 -> 0 | N37: =VLOOKUP(L37,Sheet1!K1:L1,2,FALSE) -> #N/A
C40: F. Assignment: | F40: Regular | I40: Regular (Temporary Funding Source)-End Date: | R40: Temp Employment - End Date:
C43: G. Retiree of PERS of MS? | F43: No | I43: Yes - Retirement Date:
C46: H. Total Salary: | E46: Per Year | H46: Per Hour | L46: Per Other
C49: I. HOME ORGANIZATION (or HOME DEPARTMENT): If this is a Restricted Project, Indicate a Department from the E&G printed budget's Table of Contents that most closely
C50: relates to the project, or indicate the department to which the employee's check should be distributed.
D51: Home Organization Code: | G51: =VLOOKUP(E51,Sheet1!I153:J414,2,FALSE) -> #N/A | V51: 0 | W51: 0
C53: RECEIVING DEPARTMENT
B54: 4A | C54: POSITIONS CONTAINING E&G FUNDS: assign a position from the printed budget. If the position is temporary, an applicable pooled position number may be assigned.
C55: 100% RESTRICTED FUNDS: the position number will be assigned by a Grants & Contracts Accountant
B56: To | C56: Position Number | G56: Position Title
C58: Source of Funding (RECEIVING DEPARTMENT)
C59: E&G Budget Line # | D59: Budget Page # | F59: Fund Code | H59: Organization Code | J59: *Account Code | M59: Budget / Grant Name | S59: **Percentage of Funds | U59: Salary Amount Per Account
M60: =VLOOKUP(H60,Sheet1!I$54:J$289,2,FALSE) -> #N/A | S60: =SUM(U60/U$67) -> #DIV/0!
M61: =VLOOKUP(H61,Sheet1!I$54:J$289,2,FALSE) -> #N/A | S61: =SUM(U61/U$67) -> #DIV/0!
M62: =VLOOKUP(H62,Sheet1!I$54:J$289,2,FALSE) -> #N/A | S62: =SUM(U62/U$67) -> #DIV/0!
M63: =VLOOKUP(H63,Sheet1!I$54:J$289,2,FALSE) -> #N/A | S63: =SUM(U63/U$67) -> #DIV/0!
M64: =VLOOKUP(H64,Sheet1!I$54:J$289,2,FALSE) -> #N/A | S64: =SUM(U64/U$67) -> #DIV/0!
...

Sheet PAF (4)
B1: ALCORN STATE UNIVERSITY
B2: PERSONNEL ACTION FORM
B5: To avoid processing delays, please ensure all applicable sections are complete and accurate.
B7: PERSONAL DATA
B8: 1 | C8: Last Name | F8: Suffix | G8: First Name | K8: Middle | P8: Prefix | Q8: SSN / ID | U8: Current Date
C10: Current Date | E10: SSN | H10: Date of Birth | M10: Home Phone #
C12: Street Address | G12: City | K12: County | M12: State | W12: Zip Code
C14: TYPE OF ACTION | I14: ACTION DATES | N14: COMMENTS
B15: 2 | C15: Original Appointment | F15: Complete Section 4A | I15: Effective date provided by HR | N15: Use the section below for further explanation
C16: Re-Employed (break in employment) | F16: Complete Section 4A | I16: Effective date provided by HR
C17: Extension of Employment (no break) | F17: Complete Sections 4A and 4B | I17: Effective Date
C18: Promotion / Merit / Annual Inc. | F18: Complete Sections 4A and 4B | I18: Effective Date
C19: Transfer | F19: Complete Sections 4A and 4B | I19: Effective Date
C20: Release Time (Projects Only) | F20: Complete Sections 4A and 4B | I20: Effective Date
C21: Separation | F21: Complete Section 4B | I21: Date Last Worked
C22: Other (specify): | I22: Effective Date
B23: POSITION DATA
N24: Adjunct Faculty (select for NEW Adjunct Faculty, RECENTLY RETIRED, or to RENEW former members if there has been more than 1 year break in service, otherwise include on Overload or Summer Assignment Action Form)
B25: 3 | C25: A. Position Type: | F25: Staff | I25: Faculty
C28: B. Rank, if Faculty: | F28: Instructor | I28: Assistant Professor | N28: Associate Professor | R28: Professor | T28: OR | V28: NON FACULTY
C31: C. Pay Type: | F31: 9 Months | I31: 10 Months | N31: 11 Months | R31: 12 Months | V31: Other
C34: D. Pay Frequency: | F34: Monthly | I34: Bi Weekly | N34: One Time Pay at END of the: Semester/Summer Session/Assignment
C37: E. Job Status: | F37: Full Time | H37: 2 | I37: Part-time - FTE for part-time: | L37: =Sheet1!J1 -> 0 | N37: =VLOOKUP(L37,Sheet1!K1:L1,2,FALSE) -> #N/A
C40: F. Assignment: | F40: Regular | I40: Regular (Temporary Funding Source)-End Date: | R40: Temp Employment - End Date:
C43: G. Retiree of PERS of MS? | F43: No | I43: Yes - Retirement Date:
C46: H. Total Salary: | E46: Per Year | H46: Per Hour | L46: Per Other
C49: I. HOME ORGANIZATION (or HOME DEPARTMENT): If this is a Restricted Project, Indicate a Department from the E&G printed budget's Table of Contents that most closely
C50: relates to the project, or indicate the department to which the employee's check should be distributed.
D51: Home Organization Code: | G51: =VLOOKUP(E51,Sheet1!I153:J414,2,FALSE) -> #N/A | V51: 0 | W51: 0
C53: RECEIVING DEPARTMENT
B54: 4A | C54: POSITIONS CONTAINING E&G FUNDS: assign a position from the printed budget. If the position is temporary, an applicable pooled position number may be assigned.
C55: 100% RESTRICTED FUNDS: the position number will be assigned by a Grants & Contracts Accountant
B56: To | C56: Position Number | G56: Position Title
C58: Source of Funding (RECEIVING DEPARTMENT)
C59: E&G Budget Line # | D59: Budget Page # | F59: Fund Code | H59: Organization Code | J59: *Account Code | M59: Budget / Grant Name | S59: **Percentage of Funds | U59: Salary Amount Per Account
M60: =VLOOKUP(H60,Sheet1!I$54:J$289,2,FALSE) -> #N/A | S60: =SUM(U60/U$67) -> #DIV/0!
M61: =VLOOKUP(H61,Sheet1!I$54:J$289,2,FALSE) -> #N/A | S61: =SUM(U61/U$67) -> #DIV/0!
M62: =VLOOKUP(H62,Sheet1!I$54:J$289,2,FALSE) -> #N/A | S62: =SUM(U62/U$67) -> #DIV/0!
M63: =VLOOKUP(H63,Sheet1!I$54:J$289,2,FALSE) -> #N/A | S63: =SUM(U63/U$67) -> #DIV/0!
M64: =VLOOKUP(H64,Sheet1!I$54:J$289,2,FALSE) -> #N/A | S64: =SUM(U64/U$67) -> #DIV/0!
...

Sheet PAF (5)
B1: ALCORN STATE UNIVERSITY
B2: PERSONNEL ACTION FORM
B5: To avoid processing delays, please ensure all applicable sections are complete and accurate.
B7: PERSONAL DATA
B8: 1 | C8: Last Name | F8: Suffix | G8: First Name | K8: Middle | P8: Prefix | Q8: SSN / ID | U8: Current Date
C10: Current Date | E10: SSN | H10: Date of Birth | M10: Home Phone #
C12: Street Address | G12: City | K12: County | M12: State | W12: Zip Code
C14: TYPE OF ACTION | I14: ACTION DATES | N14: COMMENTS
B15: 2 | C15: Original Appointment | F15: Complete Section 4A | I15: Effective date provided by HR | N15: Use the section below for further explanation
C16: Re-Employed (break in employment) | F16: Complete Section 4A | I16: Effective date provided by HR
C17: Extension of Employment (no break) | F17: Complete Sections 4A and 4B | I17: Effective Date
C18: Promotion / Merit / Annual Inc. | F18: Complete Sections 4A and 4B | I18: Effective Date
C19: Transfer | F19: Complete Sections 4A and 4B | I19: Effective Date
C20: Release Time (Projects Only) | F20: Complete Sections 4A and 4B | I20: Effective Date
C21: Separation | F21: Complete Section 4B | I21: Date Last Worked
C22: Other (specify): | I22: Effective Date
B23: POSITION DATA
N24: Adjunct Faculty (select for NEW Adjunct Faculty, RECENTLY RETIRED, or to RENEW former members if there has been more than 1 year break in service, otherwise include on Overload or Summer Assignment Action Form)
B25: 3 | C25: A. Position Type: | F25: Staff | I25: Faculty
C28: B. Rank, if Faculty: | F28: Instructor | I28: Assistant Professor | N28: Associate Professor | R28: Professor | T28: OR | V28: NON FACULTY
C31: C. Pay Type: | F31: 9 Months | I31: 10 Months | N31: 11 Months | R31: 12 Months | V31: Other
C34: D. Pay Frequency: | F34: Monthly | I34: Bi Weekly | N34: One Time Pay at END of the: Semester/Summer Session/Assignment
C37: E. Job Status: | F37: Full Time | H37: 2 | I37: Part-time - FTE for part-time: | L37: =Sheet1!J1 -> 0 | N37: =VLOOKUP(L37,Sheet1!K1:L1,2,FALSE) -> #N/A
C40: F. Assignment: | F40: Regular | I40: Regular (Temporary Funding Source)-End Date: | R40: Temp Employment - End Date:
C43: G. Retiree of PERS of MS? | F43: No | I43: Yes - Retirement Date:
C46: H. Total Salary: | E46: Per Year | H46: Per Hour | L46: Per Other
C49: I. HOME ORGANIZATION (or HOME DEPARTMENT): If this is a Restricted Project, Indicate a Department from the E&G printed budget's Table of Contents that most closely
C50: relates to the project, or indicate the department to which the employee's check should be distributed.
D51: Home Organization Code: | G51: =VLOOKUP(E51,Sheet1!I153:J414,2,FALSE) -> #N/A | V51: 0 | W51: 0
C53: RECEIVING DEPARTMENT
B54: 4A | C54: POSITIONS CONTAINING E&G FUNDS: assign a position from the printed budget. If the position is temporary, an applicable pooled position number may be assigned.
C55: 100% RESTRICTED FUNDS: the position number will be assigned by a Grants & Contracts Accountant
B56: To | C56: Position Number | G56: Position Title
C58: Source of Funding (RECEIVING DEPARTMENT)
C59: E&G Budget Line # | D59: Budget Page # | F59: Fund Code | H59: Organization Code | J59: *Account Code | M59: Budget / Grant Name | S59: **Percentage of Funds | U59: Salary Amount Per Account
M60: =VLOOKUP(H60,Sheet1!I$54:J$289,2,FALSE) -> #N/A | S60: =SUM(U60/U$67) -> #DIV/0!
M61: =VLOOKUP(H61,Sheet1!I$54:J$289,2,FALSE) -> #N/A | S61: =SUM(U61/U$67) -> #DIV/0!
M62: =VLOOKUP(H62,Sheet1!I$54:J$289,2,FALSE) -> #N/A | S62: =SUM(U62/U$67) -> #DIV/0!
M63: =VLOOKUP(H63,Sheet1!I$54:J$289,2,FALSE) -> #N/A | S63: =SUM(U63/U$67) -> #DIV/0!
M64: =VLOOKUP(H64,Sheet1!I$54:J$289,2,FALSE) -> #N/A | S64: =SUM(U64/U$67) -> #DIV/0!
...

Sheet Worksheet.Per Other
B1: ALCORN STATE UNIVERSITY
B2: Worksheet for Calculating a 'Per Other' Amount
A6: 1 | C6: ANNUAL SALARY: What is the total ANNUAL SALARY base?
A8: 2 | C8: ANNUAL MONTHS: What is the total ANNUAL NUMBER OF MONTHS for the position.
C9: * | D9: 9 for 9 month faculty
C10: * | D10: 10 for 10 month faculty
C11: * | D11: 11 for 11 month faculty
C12: * | D12: 12 for 12 month faculty, staff, and biweekly staff
A13: 3 | C13: FULL MONTHS TO BE WORKED: How many FULL MONTHS will actually be worked by the employee?
A15: 4 | C15: WORKING DAYS (beginning month): How many WORKING DAYS are in the partial beginning month? (Count the number of weekdays
C16: in the month by including holidays and excluding Saturday and Sunday.)
A18: 5 | C18: ACTUAL DAYS WORKED (1st month): If the employee will not work a full first month, how many DAYS are expected to be ACTUALLY WORKED?
A20: 6 | C20: WORKING DAYS (final month): How many WORKING DAYS are in the partial ending month? (Count the number of weekdays in the
C21: month by including holidays and excluding Saturday and Sunday.)
A23: 7 | C23: ACTUAL DAYS TO WORK (final month): If the employee will not work a full last month, how many DAYS are expected to be ACTUALLY WORKED?
C27: =B6/B8 -> #DIV/0! | D27: Monthly salary
C30: =SUM(B13*C27) -> #DIV/0! | D30: Pay for actual full months the employee will work
C31: =IF(B18=0,0,(C27/B15)*B18) -> 0 | D31: Partial beginning month - pay for actual days
C32: =IF(B23=0,0,(C27/B20)*B23) -> 0 | D32: Partial ending month - pay for actual days
C34: =SUM(C30:C33) -> #DIV/0! | D34: TOTAL This is the per other amount for Section 3-H of the PAF
