Workbook
Name _KHK61: '375 S.K. EK VE DEĞİŞ G.MEV.'!$A$2
Name _KHK61: '375 S.K. EK VE DEĞİŞ G.MEV. (2'!$A$2
Name bookmark0: '161 S.D.M. TEBLİĞİ'!$A$1
Name bookmark1: '161 S.D.M. TEBLİĞİ'!$A$2
Name bookmark2: '161 S.D.M. TEBLİĞİ'!$A$3
Name bookmark3: '161 S.D.M. TEBLİĞİ'!$A$10
Name bookmark4: '161 S.D.M. TEBLİĞİ'!$A$637
Name bookmark5: '161 S.D.M. TEBLİĞİ'!$B$1168
Name bookmark6: '161 S.D.M. TEBLİĞİ'!$A$1237
Name OLE_LINK11: 'EK GÖSTERGELER '!#REF!
Name OLE_LINK29: 'MAAŞ HAKKINDA '!$A$281
Name OLE_LINK48: 'EK GÖSTERGELER '!#REF!
Name OLE_LINK9: '666 S.K.H.K'!$A$189

Sheet YARDIM ADRESLERİ 
A1: KANUNLAR
A2: Pratik Bilgiler | C2: 1 | D2: http://www.alomaliye.com/pratik_bilgiler_ana.htm
A3: 6245 | B3: S.K. | C3: 2 | D3: http://www.mevzuat.gov.tr/Metin.Aspx?MevzuatKod=1.3.6245&MevzuatIliski=0&sourceXmlSearch=
A4: 657 | B4: S.K. | C4: 3 | D4: http://www.mevzuat.gov.tr/MevzuatMetin/1.5.657.pdf
A5: BUMKO | C5: 4 | D5: http://www.bumko.gov.tr/TR,909/maas-istatistikleri--verileri.html
D6: http://www.memurlar.net/
D7: http://www.memurlar.net/haber/36809/
D8: http://www.memurlar.net/haber/36809/#.UQqB3KP5uZQ

Sheet KATSAYILAR 
A1: MEMUR MAAŞ HESAPLAMALARINDA KULLANILAN KATSAYILAR
A2: Yıl / Ay | B2: Aylık Katsayı | C2: Yan Ödeme Katsayısı | D2: Taban Aylık Katsayısı
A4: 25628 | B4: 7
A5: 25993 | B5: 7
A6: 26359 | B6: 7
A7: 26724 | B7: 7
A8: 27089 | B8: 8 | C8: 4
A9: 27454 | B9: 9 | C9: 4
A10: 27820 | B10: 9 | C10: 4
A11: 28185 | B11: 12 | C11: 4
A12: 28550 | B12: 14 | C12: 4
A13: 28915 | B13: 16 | C13: 6
A14: 29281 | B14: 25 | C14: 6
A15: 29646 | B15: 25 | C15: 6
A16: 30011 | B16: 30 | C16: 8
A17: 30317 | B17: 34 | C17: 9
A18: 30682 | B18: 40 | C18: 11
A19: 30864 | B19: 41 | C19: 12
... A28: 32509 | B28: 128 | C28: 43
A29: 32690 | B29: 205 | C29: 80 | D29: 220
A30: 32874 | B30: 255 | C30: 96 | D30: 280
A31: 33055 | B31: 320 | C31: 120 | D31: 355
A32: 33239 | B32: 352 | C32: 135 | D32: 480
A33: 33420 | B33: 470 | C33: 180 | D33: 640
A34: 33604 | B34: 523 | C34: 202 | D34: 823
A35: 33786 | B35: 651 | C35: 231 | D35: 1137
A36: 33970 | B36: 740 | C36: 255 | D36: 1575
A37: 34151 | B37: 835 | C37: 280 | D37: 1775
A38: 34243 | B38: 940 | C38: 310 | D38: 2000
A39: 34335 | B39: 980 | C39: 320 | D39: 2275
A40: 34425 | B40: 1100 | C40: 360 | D40: 2570
... A92: 41275 | B92: 0.073837 | C92: 0.0234128 | D92: 0.98798
A93: 41456
A94: 41640
A95: 41821

Sheet katsayılar 1
A1: KATSAYILAR VE DEVLET MEMURLARINA SAĞLANAN
A2: SOSYAL YARDIMLAR(*)
A3: =B4 -> (01.01.2013-30.06.2013 döneminde)
A4: Maaş Katsayısı | B4: (01.01.2013-30.06.2013 döneminde) | D4: ='KATSAYILAR '!B95 -> 0
A5: Taban Aylık Katsayısı | D5: ='KATSAYILAR '!D95 -> 0
A6: Yan Ödeme Katsayısı | D6: ='KATSAYILAR '!C95 -> 0
A7: Kıdem Aylığı Göstergesi | C7: 20 | D7: =C7*D4 -> 0
A8: Özel Hizmet Tazminatı Tavanı (8.000 + 1.500) x Maaş Katsayısı ) | C8: 9500 | D8: =C8*D4 -> 0
A9: Aile Yardımı (2.134 x Maaş Katsayısı ) | C9: 2134 | D9: =C9*D4 -> 0
A10: Çocuk Yardımı (250 x Maaş Katsayısı ) | C10: 250 | D10: =C10*D4 -> 0
A11: Doğum Yardımı (2.500 x Maaş Katsayısı) | C11: 2500 | D11: =C11*D4 -> 0
A12: Ölüm Yardımı | B12: Eş ve Çocuğun Ölümü Halinde (8.000 + 1.500) x Maaş Katsayısı | C12: 9500 | D12: =C12*D4 -> 0
B13: Memurun Ölümü Halinde [(8.000 + 1.500) x Maaş Katsayısı] x 2 | C13: 9500 | D13: =(C13*D4)*2 -> 0
A15: KATSAYILAR VE DEVLET MEMURLARINA SAĞLANAN
A16: SOSYAL YARDIMLAR(*)
A17: =B18 -> (01.01.2013-30.06.2013 döneminde)
A18: Maaş Katsayısı | B18: (01.01.2013-30.06.2013 döneminde) | D18: ='KATSAYILAR '!B94 -> 0
A19: Taban Aylık Katsayısı | D19: ='KATSAYILAR '!D94 -> 0
A20: Yan Ödeme Katsayısı | D20: ='KATSAYILAR '!C94 -> 0
A21: Kıdem Aylığı Göstergesi | C21: 20 | D21: =C21*D18 -> 0
A22: Özel Hizmet Tazminatı Tavanı (8.000 + 1.500) x Maaş Katsayısı ) | C22: 9500 | D22: =C22*D18 -> 0
A23: Aile Yardımı (2.134 x Maaş Katsayısı ) | C23: 2134 | D23: =C23*D18 -> 0
A24: Çocuk Yardımı (250 x Maaş Katsayısı ) | C24: 250 | D24: =C24*D18 -> 0
A25: Doğum Yardımı (2.500 x Maaş Katsayısı) | C25: 2500 | D25: =C25*D18 -> 0
A26: Ölüm Yardımı | B26: Eş ve Çocuğun Ölümü Halinde (8.000 + 1.500) x Maaş Katsayısı | C26: 9500 | D26: =C26*D18 -> 0
B27: Memurun Ölümü Halinde [(8.000 + 1.500) x Maaş Katsayısı] x 2 | C27: 9500 | D27: =(C27*D18)*2 -> 0
A29: KATSAYILAR VE DEVLET MEMURLARINA SAĞLANAN
A30: SOSYAL YARDIMLAR(*)
A31: =B32 -> (01.01.2013-30.06.2013 döneminde)
A32: Maaş Katsayısı | B32: (01.01.2013-30.06.2013 döneminde) | D32: ='KATSAYILAR '!B93 -> 0
A33: Taban Aylık Katsayısı | D33: ='KATSAYILAR '!D93 -> 0
A34: Yan Ödeme Katsayısı | D34: ='KATSAYILAR '!C93 -> 0
A35: Kıdem Aylığı Göstergesi | C35: 20 | D35: =C35*D32 -> 0
A36: Özel Hizmet Tazminatı Tavanı (8.000 + 1.500) x Maaş Katsayısı ) | C36: 9500 | D36: =C36*D32 -> 0
A37: Aile Yardımı (2.134 x Maaş Katsayısı ) | C37: 2134 | D37: =C37*D32 -> 0
A38: Çocuk Yardımı (250 x Maaş Katsayısı ) | C38: 250 | D38: =C38*D32 -> 0
A39: Doğum Yardımı (2.500 x Maaş Katsayısı) | C39: 2500 | D39: =C39*D32 -> 0
A40: Ölüm Yardımı | B40: Eş ve Çocuğun Ölümü Halinde (8.000 + 1.500) x Maaş Katsayısı | C40: 9500 | D40: =C40*D32 -> 0
B41: Memurun Ölümü Halinde [(8.000 + 1.500) x Maaş Katsayısı] x 2 | C41: 9500 | D41: =(C41*D32)*2 -> 0
A43: KATSAYILAR VE DEVLET MEMURLARINA SAĞLANAN
...

Sheet E.Y.D.M.AYLIĞI 
A1: EN YÜKSEK DEVLET MEMURU AYLIĞI
A2: Yürürlük Tarihi | B2: Aylık Katsayı | C2: Gösterge | D2: Ek Gösterge | E2: En Yüksek Devlet Memuru Aylığı (TL/YTL)
A4: 1 Mart 1970 | B4: 7 | C4: 1000 | D4: 0 | E4: =(C4+D4)*B4 -> 7000
A5: 1 Aralık 1971 | B5: 7 | C5: 1000 | D5: 200 | E5: =(C5+D5)*B5 -> 8400
A6: 1 Mart 1972 | B6: 7 | C6: 1000 | D6: 200 | E6: =(C6+D6)*B6 -> 8400
A7: 1 Mart 1973 | B7: 7 | C7: 1000 | D7: 200 | E7: =(C7+D7)*B7 -> 8400
A8: 1 Mart 1974 | B8: 8 | C8: 1000 | D8: 200 | E8: =(C8+D8)*B8 -> 9600
A9: 1 Mart 1975 | B9: 9 | C9: 1000 | D9: 200 | E9: =(C9+D9)*B9 -> 10800
A10: 1 Mart 1976 | B10: 9 | C10: 1000 | D10: 200 | E10: =(C10+D10)*B10 -> 10800
A11: 1 Mart 1977 | B11: 12 | C11: 1000 | D11: 200 | E11: =(C11+D11)*B11 -> 14400
A12: 1 Mart 1978 | B12: 14 | C12: 1000 | D12: 200 | E12: =(C12+D12)*B12 -> 16800
A13: 1 Kasım 1978 | B13: 14 | C13: 1200 | D13: 200 | E13: =(C13+D13)*B13 -> 19600
A14: 1 Mart 1979 | B14: 16 | C14: 1200 | D14: 600 | E14: =(C14+D14)*B14 -> 28800
A15: 1 Mart 1980 | B15: 25 | C15: 1200 | D15: 600 | E15: =(C15+D15)*B15 -> 45000
... A90: 1 Temmuz 2012 | B90: 0.071589 | C90: 1500 | D90: 8000 | E90: =(C90+D90)*B90 -> 680.0955
A91: ='KATSAYILAR '!A92 -> 41275 | B91: ='KATSAYILAR '!B92 -> 0.073837 | C91: 1500 | D91: 8000 | E91: =(C91+D91)*B91 -> 701.4515
A92: ='KATSAYILAR '!A93 -> 41456 | B92: ='KATSAYILAR '!B93 -> 0 | C92: 1500 | D92: 8000 | E92: =(C92+D92)*B92 -> 0
A93: ='KATSAYILAR '!A94 -> 41640 | B93: ='KATSAYILAR '!B94 -> 0 | C93: 1500 | D93: 8000 | E93: =(C93+D93)*B93 -> 0
A94: ='KATSAYILAR '!A95 -> 41821 | B94: ='KATSAYILAR '!B95 -> 0 | C94: 1500 | D94: 8000 | E94: =(C94+D94)*B94 -> 0
A95: ='KATSAYILAR '!A96 -> 0 | B95: ='KATSAYILAR '!B96 -> 0 | C95: 1500 | D95: 8000 | E95: =(C95+D95)*B95 -> 0
A96: ='KATSAYILAR '!A97 -> 0 | B96: ='KATSAYILAR '!B97 -> 0 | C96: 1500 | D96: 8000 | E96: =(C96+D96)*B96 -> 0
A97: ='KATSAYILAR '!A98 -> 0 | B97: ='KATSAYILAR '!B98 -> 0 | C97: 1500 | D97: 8000 | E97: =(C97+D97)*B97 -> 0
A98: ='KATSAYILAR '!A99 -> 0 | B98: ='KATSAYILAR '!B99 -> 0 | C98: 1500 | D98: 8000 | E98: =(C98+D98)*B98 -> 0
A99: ='KATSAYILAR '!A100 -> 0 | B99: ='KATSAYILAR '!B100 -> 0 | C99: 1500 | D99: 8000 | E99: =(C99+D99)*B99 -> 0
A100: ='KATSAYILAR '!A101 -> 0 | B100: ='KATSAYILAR '!B101 -> 0 | C100: 1500 | D100: 8000 | E100: =(C100+D100)*B100 -> 0
A101: ='KATSAYILAR '!A102 -> 0 | B101: ='KATSAYILAR '!B102 -> 0 | C101: 1500 | D101: 8000 | E101: =(C101+D101)*B101 -> 0
A102: ='KATSAYILAR '!A103 -> 0 | B102: ='KATSAYILAR '!B103 -> 0 | C102: 1500 | D102: 8000 | E102: =(C102+D102)*B102 -> 0
... A114: ='KATSAYILAR '!A115 -> 0 | B114: ='KATSAYILAR '!B115 -> 0 | C114: 1500 | D114: 8000 | E114: =(C114+D114)*B114 -> 0

Sheet AİLE VE COCUK YARDIMI 
A1: AİLE YARDIMI ÖDENEĞİ | G1: AİLE YARDIMI ÖDENEĞİ
A2: (Eş İçin Yapılan Ödeme) | G2: (Bir Çocuk için Yapılan Ödeme)
A3: Yürürlük Tarihi | B3: Yürürlük Tarihi | C3: Aylık Katsayı | D3: Aylık Katsayı | E3: Gösterge | F3: Tutar (TL/YTL) | G3: GEÇERLİLİK TARİHİ | H3: AYLIK KATSAYI | I3: GÖSTERGE | J3: MİKTAR (TL/YTL)
J4: İlkokul | K4: Orta-Lise | L4: Yüksek Okul | M4: Diğer
G5: 25993 | J5: 10 | K5: 10 | L5: 10 | M5: 10
G6: 1 Mart 1972 | J6: 10 | K6: 10 | L6: 10 | M6: 10
G7: 1 Mart 1973 | J7: 10 | K7: 10 | L7: 10 | M7: 10
G8: 27089 | J8: 25 | K8: 25 | L8: 25 | M8: 25
G9: 27454 | J9: 50 | K9: 50 | L9: 50 | M9: 50
G10: 27820 | J10: 50 | K10: 50 | L10: 50 | M10: 50
G11: 28185 | J11: 50 | K11: 50 | L11: 50 | M11: 50
G12: 28550 | J12: 50 | K12: 50 | L12: 50 | M12: 50
A13: 1 Ekim 1978 | F13: 500 | G13: 28764 | J13: 100 | K13: 200 | L13: 400 | M13: 100
A14: 1 Mart 1979 | F14: 500 | G14: 28915 | J14: 100 | K14: 200 | L14: 400 | M14: 100
A15: 1 Mart 1980 | F15: 500 | G15: 29281 | J15: 100 | K15: 200 | L15: 400 | M15: 100
A16: 1 Mart 1981 | F16: 500 | G16: 29646 | J16: 100 | K16: 200 | L16: 400 | M16: 100
A17: 1 Mart 1982 | F17: 600 | G17: 30011 | J17: 200 | K17: 400 | L17: 600 | M17: 100
A18: 1 Ocak 1983 | F18: 720 | G18: 30317 | J18: 240 | K18: 480 | L18: 720 | M18: 120
A19: 1 Mart 1984 | F19: 900 | G19: 30682 | J19: 300 | K19: 600 | L19: 900 | M19: 150
A20: 30864 | B20: ='KATSAYILAR '!A19 -> 30864 | C20: ='KATSAYILAR '!B19 -> 41 | D20: 41 | E20: 25 | F20: =D20*E20 -> 1025 | G20: 30864 | H20: 41 | I20: 25 | J20: =H20*I20 -> 1025
A21: 31048 | B21: ='KATSAYILAR '!A20 -> 31048 | C21: ='KATSAYILAR '!B20 -> 46 | D21: 46 | E21: =E20 -> 25 | F21: =D21*E21 -> 1150 | G21: 31048 | H21: 46 | I21: 25 | J21: =H21*I21 -> 1150
A22: 31229 | B22: ='KATSAYILAR '!A21 -> 31229 | C22: ='KATSAYILAR '!B21 -> 49 | D22: 49 | E22: =E21 -> 25 | F22: =D22*E22 -> 1225 | G22: 31229 | H22: 49 | I22: 25 | J22: =H22*I22 -> 1225
A23: 01 ocak 1986 | B23: ='KATSAYILAR '!A22 -> 31413 | C23: ='KATSAYILAR '!B22 -> 56 | D23: 56 | E23: =E22 -> 25 | F23: =D23*E23 -> 1400 | G23: 31413 | H23: 56 | I23: 25 | J23: =H23*I23 -> 1400
A24: 31594 | B24: ='KATSAYILAR '!A23 -> 31594 | C24: ='KATSAYILAR '!B23 -> 62 | D24: 62 | E24: =E23 -> 25 | F24: =D24*E24 -> 1550 | G24: 31594 | H24: 62 | I24: 25 | J24: =H24*I24 -> 1550
A25: 31778 | B25: ='KATSAYILAR '!A24 -> 31778 | C25: ='KATSAYILAR '!B24 -> 66 | D25: 66 | E25: =E24 -> 25 | F25: =D25*E25 -> 1650 | G25: 31778 | H25: 66 | I25: 25 | J25: =H25*I25 -> 1650
A26: 31959 | B26: ='KATSAYILAR '!A25 -> 31959 | C26: ='KATSAYILAR '!B25 -> 70 | D26: 70 | E26: =E25 -> 25 | F26: =D26*E26 -> 1750 | G26: 31959 | H26: 70 | I26: 25 | J26: =H26*I26 -> 1750
A27: 32143 | B27: ='KATSAYILAR '!A26 -> 32143 | C27: ='KATSAYILAR '!B26 -> 84 | D27: 84 | E27: =E26 -> 25 | F27: =D27*E27 -> 2100 | G27: 32143 | H27: 84 | I27: 25 | J27: =H27*I27 -> 2100
A28: 32325 | B28: ='KATSAYILAR '!A27 -> 32325 | C28: ='KATSAYILAR '!B27 -> 100 | D28: 100 | E28: =E27 -> 25 | F28: =D28*E28 -> 2500 | G28: 32325 | H28: 100 | I28: 25 | J28: =H28*I28 -> 2500
A29: 32509 | B29: ='KATSAYILAR '!A28 -> 32509 | C29: ='KATSAYILAR '!B28 -> 128 | D29: 128 | E29: =E28 -> 25 | F29: =D29*E29 -> 3200 | G29: 32509 | H29: 128 | I29: 25 | J29: =H29*I29 -> 3200
A30: 32690 | B30: ='KATSAYILAR '!A29 -> 32690 | C30: ='KATSAYILAR '!B29 -> 205 | D30: 205 | E30: 25 | F30: =D30*E30 -> 5125 | G30: 32690 | H30: 205 | I30: 25 | J30: =H30*I30 -> 5125
A31: 32704 | D31: 205 | E31: 250 | F31: =D31*E31 -> 51250 | G31: 32704 | H31: 205 | I31: 50 | J31: =H31*I31 -> 10250
A32: 32874 | B32: ='KATSAYILAR '!A30 -> 32874 | C32: ='KATSAYILAR '!B30 -> 255 | D32: 255 | E32: 250 | F32: =D32*E32 -> 63750 | G32: 32874 | H32: 255 | I32: 50 | J32: =H32*I32 -> 12750
A33: 33055 | B33: ='KATSAYILAR '!A31 -> 33055 | C33: ='KATSAYILAR '!B31 -> 320 | D33: 320 | E33: 250 | F33: =D33*E33 -> 80000 | G33: 33055 | H33: 320 | I33: 50 | J33: =H33*I33 -> 16000
A34: 33239 | B34: ='KATSAYILAR '!A32 -> 33239 | C34: ='KATSAYILAR '!B32 -> 352 | D34: 352 | E34: 250 | F34: =D34*E34 -> 88000 | G34: 33239 | H34: 352 | I34: 50 | J34: =H34*I34 -> 17600
A35: 33420 | B35: ='KATSAYILAR '!A33 -> 33420 | C35: ='KATSAYILAR '!B33 -> 470 | D35: 470 | E35: 250 | F35: =D35*E35 -> 117500 | G35: 33420 | H35: 470 | I35: 50 | J35: =H35*I35 -> 23500
A36: 33434 | D36: 470 | E36: 300 | F36: =D36*E36 -> 141000
A37: 33604 | B37: ='KATSAYILAR '!A34 -> 33604 | C37: ='KATSAYILAR '!B34 -> 523 | D37: 523 | E37: 300 | F37: =D37*E37 -> 156900 | G37: 33604 | H37: 523 | I37: 50 | J37: =H37*I37 -> 26150
A38: 33786 | B38: ='KATSAYILAR '!A35 -> 33786 | C38: ='KATSAYILAR '!B35 -> 651 | D38: 651 | E38: 300 | F38: =D38*E38 -> 195300 | G38: 33786 | H38: 651 | I38: 50 | J38: =H38*I38 -> 32550
A39: 33970 | B39: ='KATSAYILAR '!A36 -> 33970 | C39: ='KATSAYILAR '!B36 -> 740 | D39: 740 | E39: 300 | F39: =D39*E39 -> 222000 | G39: 33970 | H39: 740 | I39: 50 | J39: =H39*I39 -> 37000
A40: 34151 | B40: ='KATSAYILAR '!A37 -> 34151 | C40: ='KATSAYILAR '!B37 -> 835 | D40: 835 | E40: 300 | F40: =D40*E40 -> 250500 | G40: 34151 | H40: 835 | I40: 50 | J40: =H40*I40 -> 41750
...

Sheet sataklık ind
A1: AYLIK SAKATLIK İNDİRİMİ TUTARLARI
A2: ( 01.01.2013 TARİHİNDEN İTİBAREN )
A3: Sakatlık Dereceleri
A4: I. Derece Sakatlar (Çalışma gücünün asgari % 80’ini kaybetmiş olanlar) | B4: 800
A5: II. Derece Sakatlar (Çalışma gücünün asgari % 60’ını kaybetmiş olanlar) | B5: 400
A6: III. Derece Sakatlar (Çalışma gücünün asgari % 40’ını kaybetmiş olanlar) | B6: 190
A8: AYLIK SAKATLIK İNDİRİMİ TUTARLARI
A9: ( 01.01.2012 TARİHİNDEN İTİBAREN )
A10: Sakatlık Dereceleri
A11: I. Derece Sakatlar (Çalışma gücünün asgari % 80’ini kaybetmiş olanlar) | B11: 770
A12: II. Derece Sakatlar (Çalışma gücünün asgari % 60’ını kaybetmiş olanlar) | B12: 380
A13: III. Derece Sakatlar (Çalışma gücünün asgari % 40’ını kaybetmiş olanlar) | B13: 180
A15: AYLIK SAKATLIK İNDİRİMİ TUTARLARI
A16: ( 01.01.2011 TARİHİNDEN İTİBAREN )
A17: Sakatlık Dereceleri
A18: I. Derece Sakatlar (Çalışma gücünün asgari % 80’ini kaybetmiş olanlar) | B18: 700
A19: II. Derece Sakatlar (Çalışma gücünün asgari % 60’ını kaybetmiş olanlar) | B19: 350
A20: III. Derece Sakatlar (Çalışma gücünün asgari % 40’ını kaybetmiş olanlar) | B20: 170
A22: AYLIK SAKATLIK İNDİRİMİ TUTARLARI
A23: ( 01.01.2010 TARİHİNDEN İTİBAREN )
A24: Sakatlık Dereceleri
A25: I. Derece Sakatlar (Çalışma gücünün asgari % 80’ini kaybetmiş olanlar) | B25: 680
A26: II. Derece Sakatlar (Çalışma gücünün asgari % 60’ını kaybetmiş olanlar) | B26: 330
A27: III. Derece Sakatlar (Çalışma gücünün asgari % 40’ını kaybetmiş olanlar) | B27: 160
A29: AYLIK SAKATLIK İNDİRİMİ TUTARLARI
A30: (01.01.2009 - 31.12.2009 TARİHLERİ ARASI)
A31: Sakatlık Dereceleri
A32: I. Derece Sakatlar (Çalışma gücünün asgari % 80’ini kaybetmiş olanlar) | B32: 670
A33: II. Derece Sakatlar (Çalışma gücünün asgari % 60’ını kaybetmiş olanlar) | B33: 330
A34: III. Derece Sakatlar (Çalışma gücünün asgari % 40’ını kaybetmiş olanlar) | B34: 160
A36: AYLIK SAKATLIK İNDİRİMİ TUTARLARI
A37: (01.01.2008 - 31.12.2008 TARİHLERİ ARASI)
A38: Sakatlık Dereceleri
A39: I. Derece Sakatlar (Çalışma gücünün asgari % 80’ini kaybetmiş olanlar) | B39: 600 YTL
A40: II. Derece Sakatlar (Çalışma gücünün asgari % 60’ını kaybetmiş olanlar) | B40: 300 YTL
A41: III. Derece Sakatlar (Çalışma gücünün asgari % 40’ını kaybetmiş olanlar) | B41: 150 YTL
A43: AYLIK SAKATLIK İNDİRİMİ TUTARLARI
A44: (01.01.2007 - 31.12.2007 TARİHLERİ ARASI)
A45: Sakatlık Dereceleri
A46: I. Derece Sakatlar (Çalışma gücünün asgari % 80’ini kaybetmiş olanlar) | B46: 570 YTL
...

Sheet Vergi dilemleri 
A1: 2013 YILI GELİR VERGİSİ TARİFESİ (Ücret Gelirleri İçin)
A2: 10700 | B2: TL'ye kadar | G2: 0.15
A3: 26000 | B3: TL'nin | C3: 10700 | D3: TL'si için | E3: =C3*G2 -> 1605 | F3: TL, fazlası | G3: 0.2
A4: 94000 | B4: TL'nin | C4: 26000 | D4: TL'si için | E4: =((C4-C3)*G3)+E3 -> 4665 | F4: TL, fazlası | G4: 0.27
A5: 94000 | B5: TL'den fazlasının | C5: 94000 | D5: TL'si için | E5: =((C5-C4)*G4)+E4 -> 23025 | F5: TL, fazlası | G5: 0.35
A7: 2012 YILI GELİR VERGİSİ TARİFESİ (Ücret Gelirleri İçin)
A8: 10000 | B8: TL'ye kadar | G8: 0.15
A9: 25000 | B9: TL'nin | C9: 10000 | D9: TL'si için | E9: =C9*G8 -> 1500 | F9: TL, fazlası | G9: 0.2
A10: 88000 | B10: TL'nin | C10: 25000 | D10: TL'si için | E10: =((C10-C9)*G9)+E9 -> 4500 | F10: TL, fazlası | G10: 0.27
A11: 88000 | B11: TL'den fazlasının | C11: 88000 | D11: TL'si için | E11: =((C11-C10)*G10)+E10 -> 21510 | F11: TL, fazlası | G11: 0.35
A12: 0
A14: 2011 YILI GELİR VERGİSİ TARİFESİ (Ücret Gelirleri İçin)
A15: 9400 | B15: TL'ye kadar | G15: 0.15
A16: 23000 | B16: TL'nin | C16: 9400 | D16: TL'si için | E16: =C16*G15 -> 1410 | F16: TL, fazlası | G16: 0.2
A17: 80000 | B17: TL'nin | C17: 23000 | D17: TL'si için | E17: =((C17-C16)*G16)+E16 -> 4130 | F17: TL, fazlası | G17: 0.27
A18: 80000 | B18: TL'den fazlasının | C18: 80000 | D18: TL'si için | E18: =((C18-C17)*G17)+E17 -> 19520 | F18: TL, fazlası | G18: 0.35
A19: oranında vergilendirilir
A21: 2010 YILI GELİR VERGİSİ TARİFESİ (Ücret Gelirleri İçin)
A22: 8800 | B22: TL'ye kadar | G22: 0.15
A23: 22000 | B23: TL'nin | C23: 8800 | D23: TL'si için | E23: =C23*G22 -> 1320 | F23: TL, fazlası | G23: 0.2
A24: 50000 | B24: TL'nin | C24: 22000 | D24: TL'si için | E24: =((C24-C23)*G23)+E23 -> 3960 | F24: TL, fazlası | G24: 0.27
A25: 50000 | B25: liradan fazlasının | C25: 50000 | D25: TL'si için | E25: =((C25-C24)*G24)+E24 -> 11520 | F25: TL, fazlası | G25: 0.35
A26: oranında vergilendirilir
A28: 2009 YILI GELİR VERGİSİ TARİFESİ (Ücretler)
A29: 8700 | B29: TL'ye kadar | G29: 0.15
A30: 22000 | B30: TL'nin | C30: 8700 | D30: TL'si için | E30: 1305 | F30: TL, fazlası | G30: 0.2
A31: 50000 | B31: TL'nin | C31: 22000 | D31: TL'si için | E31: 3965 | F31: TL, fazlası | G31: 0.27
A32: 50000 | B32: liradan fazlasının | C32: 50000 | D32: TL'si için | E32: 11525 | F32: TL, fazlası | G32: 0.35
A33: oranında vergilendirilir
A35: 2008 YILI GELİR VERGİSİ TARİFESİ (Ücretler)
A36: 7800 | B36: YTL'ye kadar | G36: 0.15
A37: 19.800 | B37: YTL'nin | C37: 7.800 | D37: YTL'si için | E37: 1170 | F37: YTL, fazlası | G37: 0.2
A38: 44.700 | B38: YTL'nin | C38: 19.800 | D38: YTL'si için | E38: 3570 | F38: YTL, fazlası | G38: 0.27
A39: 44.700 | B39: liradan fazlasının | C39: 44700 | D39: YTL'si için | E39: 10293 | F39: YTL, fazlası | G39: 0.35
A40: oranında vergilendirilir
A42: 2007 YILI GELİR VERGİSİ TARİFESİ (Ücretler)
A43: 7500 | B43: YTL'ye kadar | G43: 0.15
A44: 19.000 | B44: YTL'nin | C44: 7.500 | D44: YTL'si için | E44: 1125 | F44: YTL, fazlası | G44: 0.2
A45: 43.000 | B45: YTL'nin | C45: 19.000 | D45: YTL'si için | E45: 3425 | F45: YTL, fazlası | G45: 0.27
A46: 43.000 | B46: liradan fazlasının | C46: 43000 | D46: YTL'si için | E46: 9905 | F46: YTL, fazlası | G46: 0.35
...

Sheet Damga vergisi nisbetleri 
A1: 2013 YILI İÇİN BAZI DAMGA VERGİSİ NİSPETLERİ VE MAKTU TUTARLAR
A2: - Ücretlerde (avans olarak ödenenler dahil) | B2: Binde 7,59
A3: - Resmi Dairelere Verilen Makbuz ve İbra Senetleri (Mal ve hizmet alımlarına ilişkin) | B3: Binde 8,25
A4: - Sözleşmeler, Taahhütnameler ve Temliknameler (Belli parayı ihtiva edenler) | B4: Binde 8,25
A5: - Kira Sözleşmeleri (Sözleşme süresine göre kira bedeli üzerinden) | B5: Binde 1,65
A6: - Kefalet, Teminat ve Rehin Senetleri (Belli parayı ihtiva edenler) | B6: Binde 8,25
A7: - Tahkimname ve Sulhnameler (Belli parayı ihtiva edenler) | B7: Binde 8,25
A8: - Fesihnameler (Belli parayı ihtiva eden bir kağıda taalluk edenler dahil) | B8: Binde 1,65
A9: - İkinci El Araç Satış ve (06.06.2008’den itibaren) Devir Sözleşmeleri | B9: Binde 1,65
A10: - İhale Kararları | B10: Binde 4,95
A11: - Yıllık Gelir Vergisi Beyannamesi | B11: 27.9
A12: - Kurumlar Vergisi Beyannamesi | B12: 37.27
A13: - Muhtasar Beyanname | B13: 18.55
A14: - Katma Değer Vergisi Beyannameleri | B14: 18.55
A15: - Diğer Vergi Beyannameleri (damga vergisi beyannameleri hariç) | B15: 18.55
A16: - Belediye ve İl Özel İdarelerine Verilen Beyannameler | B16: 13.75
A17: - Sosyal Güvenlik Kurumlarına Verilen Sigorta Prim Bildirgeleri | B17: 13.75
A18: - Gümrük İdarelerine Verilen Beyannameler | B18: 37.25
A19: - Bilançolar | B19: 21.55
A20: - Gelir Tabloları | B20: 10.55
A21: - İşletme Hesabı Özetleri | B21: 10.55
A22: (Her bir kağıt için hesaplanacak nispi vergi tutarı, (1) sayılı tabloda yer alan sınırlamalar saklı kalmak üzere 01.01.2011’den itibaren 1.251.383,40 TL’yi aşamaz.)
A25: 2012 YILI İÇİN BAZI DAMGA VERGİSİ NİSPETLERİ VE MAKTU TUTARLAR
A26: - Ücretlerde (avans olarak ödenenler dahil) | B26: Binde 6,60
A27: - Resmi Dairelere Verilen Makbuz ve İbra Senetleri (Mal ve hizmet alımlarına ilişkin) | B27: Binde 8,25
A28: - Sözleşmeler, Taahhütnameler ve Temliknameler (Belli parayı ihtiva edenler) | B28: Binde 8,25
A29: - Kira Sözleşmeleri (Sözleşme süresine göre kira bedeli üzerinden) | B29: Binde 1,65
A30: - Kefalet, Teminat ve Rehin Senetleri (Belli parayı ihtiva edenler) | B30: Binde 8,25
A31: - Tahkimname ve Sulhnameler (Belli parayı ihtiva edenler) | B31: Binde 8,25
A32: - Fesihnameler (Belli parayı ihtiva eden bir kağıda taalluk edenler dahil) | B32: Binde 1,65
A33: - İkinci El Araç Satış ve (06.06.2008’den itibaren) Devir Sözleşmeleri | B33: Binde 1,65
A34: - İhale Kararları | B34: Binde 4,95
A35: - Yıllık Gelir Vergisi Beyannamesi | B35: 27.9
A36: - Kurumlar Vergisi Beyannamesi | B36: 37.27
A37: - Muhtasar Beyanname | B37: 18.55
A38: - Katma Değer Vergisi Beyannameleri | B38: 18.55
A39: - Diğer Vergi Beyannameleri (damga vergisi beyannameleri hariç) | B39: 18.55
A40: - Belediye ve İl Özel İdarelerine Verilen Beyannameler | B40: 13.75
A41: - Sosyal Güvenlik Kurumlarına Verilen Sigorta Prim Bildirgeleri | B41: 13.75
A42: - Gümrük İdarelerine Verilen Beyannameler | B42: 37.25
...

Sheet AGİ
A1: 2014 YILI ASGARİ GEÇİM İNDİRİMİ TUTARLARI
A2: Medeni Durum | D2: Aylık (TL) | E2: Medeni Durum | H2: Aylık (TL)
A3: ASGARİ ÜÇRET (01/01/… - 30/06/…. | B3: 0 | D3: 12 | E3: =B3*D3 -> 0 | F3: =((E3*B4%)*15%)/D3 -> 0
A4: Bekâr | B4: 50 | D4: =($F$3/50)*B4 -> 0 | F4: 50
A5: Evli eşi çalışmayan ve çocuksuz | B5: 10 | C5: =B4+B5 -> 60 | D5: =($F$3/50)*C5 -> 0 | E5: Evli eşi çalışan ve çocuksuz | F5: 50 | G5: =F5 -> 50 | H5: =($F$3/$F$24)*G5 -> 0
A6: Evli eşi çalışmayan ve 1 çocuklu | B6: 7.5 | C6: =C5+B6 -> 67.5 | D6: =($F$3/50)*C6 -> 0 | E6: Evli eşi çalışan ve 1 çocuklu | F6: 7,5 | G6: =G5+F6 -> 57.5 | H6: =($F$3/$F$24)*G6 -> 0
A7: Evli eşi çalışmayan ve 2 çocuklu | B7: 7.5 | C7: =C6+B7 -> 75 | D7: =($F$3/50)*C7 -> 0 | E7: Evli eşi çalışan ve 2 çocuklu | F7: 7,5 | G7: =G6+F7 -> 65 | H7: =($F$3/$F$24)*G7 -> 0
A8: Evli eşi çalışmayan ve 3 çocuklu | B8: 5 | C8: =C7+B8 -> 80 | D8: =($F$3/50)*C8 -> 0 | E8: Evli eşi çalışan ve 3 çocuklu | F8: 5 | G8: =G7+F8 -> 70 | H8: =($F$3/$F$24)*G8 -> 0
A9: Evli eşi çalışmayan ve 4 çocuklu | B9: 5 | C9: =C8+B9 -> 85 | D9: =($F$3/50)*C9 -> 0 | E9: Evli eşi çalışan ve 4 çocuklu | F9: 5 | G9: =G8+F9 -> 75 | H9: =($F$3/$F$24)*G9 -> 0
A11: 2013 YILI ASGARİ GEÇİM İNDİRİMİ TUTARLARI
A12: Medeni Durum | D12: Aylık (TL) | E12: Medeni Durum | H12: Aylık (TL)
A13: ASGARİ ÜÇRET (01/01/… - 30/06/…. | B13: 978.6 | D13: 12 | E13: =B13*D13 -> 11743.2 | F13: =((E13*B14%)*15%)/D13 -> 73.395
A14: Bekâr | B14: 50 | D14: =($F$13/50)*B14 -> 73.395 | F14: 50
A15: Evli eşi çalışmayan ve çocuksuz | B15: 10 | C15: =B14+B15 -> 60 | D15: =($F$13/50)*C15 -> 88.074 | E15: Evli eşi çalışan ve çocuksuz | F15: 50 | G15: =F15 -> 50 | H15: =($F$13/$F$24)*G15 -> 73.395
A16: Evli eşi çalışmayan ve 1 çocuklu | B16: 7.5 | C16: =C15+B16 -> 67.5 | D16: =($F$13/50)*C16 -> 99.08325 | E16: Evli eşi çalışan ve 1 çocuklu | F16: 7,5 | G16: =G15+F16 -> 57.5 | H16: =($F$13/$F$24)*G16 -> 84.40425
A17: Evli eşi çalışmayan ve 2 çocuklu | B17: 7.5 | C17: =C16+B17 -> 75 | D17: =($F$13/50)*C17 -> 110.0925 | E17: Evli eşi çalışan ve 2 çocuklu | F17: 7,5 | G17: =G16+F17 -> 65 | H17: =($F$13/$F$24)*G17 -> 95.4135
A18: Evli eşi çalışmayan ve 3 çocuklu | B18: 5 | C18: =C17+B18 -> 80 | D18: =($F$13/50)*C18 -> 117.432 | E18: Evli eşi çalışan ve 3 çocuklu | F18: 5 | G18: =G17+F18 -> 70 | H18: =($F$13/$F$24)*G18 -> 102.753
A19: Evli eşi çalışmayan ve 4 çocuklu | B19: 5 | C19: =C18+B19 -> 85 | D19: =($F$13/50)*C19 -> 124.7715 | E19: Evli eşi çalışan ve 4 çocuklu | F19: 5 | G19: =G18+F19 -> 75 | H19: =($F$13/$F$24)*G19 -> 110.0925
A21: 2012 YILI ASGARİ GEÇİM İNDİRİMİ TUTARLARI
A22: Medeni Durum | D22: Aylık (TL) | E22: Medeni Durum | H22: Aylık (TL)
A23: ASGARİ ÜÇRET (01/01/… - 30/06/…. | B23: 886.5 | D23: 12 | E23: =B23*D23 -> 10638 | F23: =((E23*B24%)*15%)/D23 -> 66.4875
A24: Bekâr | B24: 50 | D24: =($F$23/50)*B24 -> 66.4875 | F24: 50
A25: Evli eşi çalışmayan ve çocuksuz | B25: 10 | C25: =B24+B25 -> 60 | D25: =($F$23/50)*C25 -> 79.785 | E25: Evli eşi çalışan ve çocuksuz | F25: 50 | G25: =F25 -> 50 | H25: =($F$23/$F$24)*G25 -> 66.4875
A26: Evli eşi çalışmayan ve 1 çocuklu | B26: 7.5 | C26: =C25+B26 -> 67.5 | D26: =($F$23/50)*C26 -> 89.758125 | E26: Evli eşi çalışan ve 1 çocuklu | F26: 7,5 | G26: =G25+F26 -> 57.5 | H26: =($F$23/$F$24)*G26 -> 76.460625
A27: Evli eşi çalışmayan ve 2 çocuklu | B27: 7.5 | C27: =C26+B27 -> 75 | D27: =($F$23/50)*C27 -> 99.73125 | E27: Evli eşi çalışan ve 2 çocuklu | F27: 7,5 | G27: =G26+F27 -> 65 | H27: =($F$23/$F$24)*G27 -> 86.43375
A28: Evli eşi çalışmayan ve 3 çocuklu | B28: 5 | C28: =C27+B28 -> 80 | D28: =($F$23/50)*C28 -> 106.38 | E28: Evli eşi çalışan ve 3 çocuklu | F28: 5 | G28: =G27+F28 -> 70 | H28: =($F$23/$F$24)*G28 -> 93.0825
A29: Evli eşi çalışmayan ve 4 çocuklu | B29: 5 | C29: =C28+B29 -> 85 | D29: =($F$23/50)*C29 -> 113.02875 | E29: Evli eşi çalışan ve 4 çocuklu | F29: 5 | G29: =G28+F29 -> 75 | H29: =($F$23/$F$24)*G29 -> 99.73125
A31: 2011 YILI ASGARİ GEÇİM İNDİRİMİ TUTARLARI
A32: Medeni Durum | D32: Aylık (TL) | E32: Medeni Durum | H32: Aylık (TL)
A33: ASGARİ ÜÇRET (01/01/… - 30/06/…. | B33: 796.5 | D33: 12 | E33: =B33*D33 -> 9558 | F33: =((E33*B34%)*15%)/D33 -> 59.7375
A34: Bekâr | B34: 50 | D34: =($F$33/50)*B34 -> 59.7375 | F34: 50
A35: Evli eşi çalışmayan ve çocuksuz | B35: 10 | C35: =B34+B35 -> 60 | D35: =($F$33/50)*C35 -> 71.685 | E35: Evli eşi çalışan ve çocuksuz | F35: 50 | G35: =F35 -> 50 | H35: =($F$33/50)*F35 -> 59.7375
A36: Evli eşi çalışmayan ve 1 çocuklu | B36: 7.5 | C36: =C35+B36 -> 67.5 | D36: =($F$33/50)*C36 -> 80.645625 | E36: Evli eşi çalışan ve 1 çocuklu | F36: 7,5 | G36: =G35+F36 -> 57.5 | H36: =($F$33/50)*G36 -> 68.698125
A37: Evli eşi çalışmayan ve 2 çocuklu | B37: 7.5 | C37: =C36+B37 -> 75 | D37: =($F$33/50)*C37 -> 89.60625 | E37: Evli eşi çalışan ve 2 çocuklu | F37: 7,5 | G37: =G36+F37 -> 65 | H37: =($F$33/50)*G37 -> 77.65875
A38: Evli eşi çalışmayan ve 3 çocuklu | B38: 5 | C38: =C37+B38 -> 80 | D38: =($F$33/50)*C38 -> 95.58 | E38: Evli eşi çalışan ve 3 çocuklu | F38: 5 | G38: =G37+F38 -> 70 | H38: =($F$33/50)*G38 -> 83.6325
A39: Evli eşi çalışmayan ve 4 çocuklu | B39: 5 | C39: =C38+B39 -> 85 | D39: =($F$33/50)*C39 -> 101.55375 | E39: Evli eşi çalışan ve 4 çocuklu | F39: 5 | G39: =G38+F39 -> 75 | H39: =($F$33/50)*G39 -> 89.60625
A41: 2010 YILI ASGARİ GEÇİM İNDİRİMİ TUTARLARI
A42: Medeni Durum | D42: Aylık (TL) | E42: Medeni Durum | H42: Aylık (TL)
A43: Bekâr | D43: 54.68
A44: Evli eşi çalışmayan ve çocuksuz | D44: 65.61 | E44: Evli eşi çalışan ve çocuksuz | H44: 54.68
...

Sheet Sakatıl İnd. İade 
B1: SATAKLIK İNDİRİMİ SONUCU FAZLA KESİLEN GELİR VERGİSİ TABLOSU
C2: Ocak | D2: Şubat | E2: Mart | F2: Nisan | G2: Mayıs | H2: Haziran | I2: Temmuz | J2: Ağustos | K2: Eylül | L2: Ekim | M2: Kasım | N2: Aralık | O2: Toplam
A3: 1 | B3: Aylık G.V.Matrahı | C3: 916.62 | D3: 0 | E3: 0 | F3: 853.09 | G3: 855.96 | H3: 855.96 | I3: 892.7 | J3: 892.7 | K3: 892.7 | L3: 892.7 | M3: 892.7 | N3: 892.7 | O3: =SUM(C3:N3) -> 8837.83
A4: 2 | B4: GELİR VERGİSİ ORANI | C4: 0.15 | D4: 0.15 | E4: 0.15 | F4: 0.15 | G4: 0.15 | H4: 0.15 | I4: 0.15 | J4: 0.15 | K4: 0.15 | L4: 0.15 | M4: 0.15 | N4: 0.15
A5: 3 | B5: Asgari Geçim İndirimi | C5: 99.73 | D5: 0 | E5: 0 | F5: 89.61 | G5: 89.61 | H5: 89.61 | I5: 89.61 | J5: 89.61 | K5: 89.61 | L5: 89.61 | M5: 89.61 | N5: 89.61 | O5: =SUM(C5:N5) -> 906.22
A6: 4 | B6: Ödenen A.G.İ. Miktarı (3) | C6: =C5 -> 99.73 | D6: =D5 -> 0 | E6: =E5 -> 0 | F6: =F5 -> 89.61 | G6: =G5 -> 89.61 | H6: =H5 -> 89.61 | I6: =I5 -> 89.61 | J6: =J5 -> 89.61 | ... N6: =N5 -> 89.61 | O6: =SUM(C6:N6) -> 906.22
A7: 5 | B7: Derece Sakatlık İndirim Miktarı TL | C7: 770 | F7: 700 | G7: 700 | H7: 700 | I7: 700 | J7: 700 | K7: 700 | L7: 700 | M7: 700 | N7: 700 | O7: =SUM(C7:N7) -> 7070
A8: 6 | B8: G.V. (1*2) | C8: =C3*C4 -> 137.493 | D8: =D3*D4 -> 0 | E8: =E3*E4 -> 0 | F8: =F3*F4 -> 127.9635 | G8: =G3*G4 -> 128.394 | H8: =H3*H4 -> 128.394 | I8: =I3*I4 -> 133.905 | J8: =J3*J4 -> 133.905 | ... N8: =N3*N4 -> 133.905 | O8: =SUM(C8:N8) -> 1325.6745
A9: 7 | B9: Kesilen G V (6-4) | C9: =C8-C6 -> 37.763 | D9: =(D8-D5) -> 0 | E9: =(E8-E5) -> 0 | F9: =(F8-F5) -> 38.3535 | G9: =(G8-G5) -> 38.784 | H9: =(H8-H5) -> 38.784 | I9: =(I8-I5) -> 44.295 | J9: =(J8-J5) -> 44.295 | K9: =(K8-K5) -> 44.295 | ... N9: =(N8-N5) -> 44.295 | O9: =SUM(C9:N9) -> 419.4545
A10: 8 | B10: Aylık G.V.Matrahı (1) | C10: =C3 -> 916.62 | D10: =D3 -> 0 | E10: =E3 -> 0 | F10: =F3 -> 853.09 | G10: =G3 -> 855.96 | H10: =H3 -> 855.96 | I10: =I3 -> 892.7 | J10: =J3 -> 892.7 | ... N10: =N3 -> 892.7 | O10: =SUM(C10:N10) -> 8837.83
A11: 9 | B11: Matrah (8-5) | C11: =(C10-C7) -> 146.62 | D11: =(D10-D7) -> 0 | E11: =(E10-E7) -> 0 | F11: =(F10-F7) -> 153.09 | G11: =(G10-G7) -> 155.96 | H11: =(H10-H7) -> 155.96 | I11: =(I10-I7) -> 192.7 | J11: =(J10-J7) -> 192.7 | ... N11: =(N10-N7) -> 192.7 | O11: =SUM(C11:N11) -> 1767.83
A12: 10 | B12: G.V. (9*2) | C12: =C11*C4 -> 21.993 | D12: =D11*D4 -> 0 | E12: =E11*E4 -> 0 | F12: =F11*F4 -> 22.9635 | G12: =G11*G4 -> 23.394 | H12: =H11*H4 -> 23.394 | I12: =I11*I4 -> 28.905 | J12: =J11*J4 -> 28.905 | ... N12: =N11*N4 -> 28.905 | O12: =SUM(C12:N12) -> 265.1745
A13: 11 | B13: Ödenmesi Gereken Agi | C13: =C12 -> 21.993 | D13: =D12 -> 0 | E13: =E12 -> 0 | F13: =F12 -> 22.9635 | G13: =G12 -> 23.394 | H13: =H12 -> 23.394 | I13: =I12 -> 28.905 | J13: =J12 -> 28.905 | ... O13: =O12 -> 265.1745
A14: 12 | B14: Fazla ödenen Agi (4-11) | C14: =C6-C13 -> 77.737 | D14: =D6-D13 -> 0 | E14: =E6-E13 -> 0 | F14: =F6-F13 -> 66.6465 | G14: =G6-G13 -> 66.216 | H14: =H6-H13 -> 66.216 | I14: =I6-I13 -> 60.705 | J14: =J6-J13 -> 60.705 | ... O14: =O6-O13 -> 641.0455
C15: =C8-C12 -> 115.5 | D15: =D8-D12 -> 0 | E15: =E8-E12 -> 0 | F15: =F8-F12 -> 105 | G15: =G8-G12 -> 105 | H15: =H8-H12 -> 105 | I15: =I8-I12 -> 105 | J15: =J8-J12 -> 105 | ... O15: =O8-O12 -> 1060.5
B16: FAZLA KESİLEN VE ÖDENMESİ GEKEN GELİR VERGİSİ | C16: =C15-C14 -> 37.763 | D16: =D15-D14 -> 0 | E16: =E15-E14 -> 0 | F16: =F15-F14 -> 38.3535 | G16: =G15-G14 -> 38.784 | H16: =H15-H14 -> 38.784 | I16: =I15-I14 -> 44.295 | J16: =J15-J14 -> 44.295 | ... O16: =O15-O14 -> 419.4545
C18: =C9-C14 -> -39.974

Sheet agi iade 
C1: =TODAY() -> 41305 | D1: YILI ASGARİ GEÇİM İNDİRİMİ TUTARLARI
A2: Medeni Durum | D2: Aylık (TL) | E2: Medeni Durum | H2: Aylık (TL)
A3: ASGARİ ÜÇRET GİR (01/01/… - 31/02…. | B3: 796.5 | D3: 12 | E3: =B3*D3 -> 9558 | F3: =((E3*B4%)*15%)/D3 -> 59.7375
A4: Bekâr | B4: 50 | D4: =($F$3/50)*B4 -> 59.7375 | F4: 50
A5: Evli eşi çalışmayan ve çocuksuz | B5: 10 | C5: =B4+B5 -> 60 | D5: =($F$3/50)*C5 -> 71.685 | E5: Evli eşi çalışan ve çocuksuz | F5: 50 | G5: =F5 -> 50 | H5: =($F$3/50)*F5 -> 59.7375
A6: Evli eşi çalışmayan ve 1 çocuklu | B6: 7.5 | C6: =C5+B6 -> 67.5 | D6: =($F$3/50)*C6 -> 80.645625 | E6: Evli eşi çalışan ve 1 çocuklu | F6: 7,5 | G6: =G5+F6 -> 57.5 | H6: =($F$3/50)*G6 -> 68.698125
A7: Evli eşi çalışmayan ve 2 çocuklu | B7: 7.5 | C7: =C6+B7 -> 75 | D7: =($F$3/50)*C7 -> 89.60625 | E7: Evli eşi çalışan ve 2 çocuklu | F7: 7,5 | G7: =G6+F7 -> 65 | H7: =($F$3/50)*G7 -> 77.65875
A8: Evli eşi çalışmayan ve 3 çocuklu | B8: 5 | C8: =C7+B8 -> 80 | D8: =($F$3/50)*C8 -> 95.58 | E8: Evli eşi çalışan ve 3 çocuklu | F8: 5 | G8: =G7+F8 -> 70 | H8: =($F$3/50)*G8 -> 83.6325
A9: Evli eşi çalışmayan ve 4 çocuklu | B9: 5 | C9: =C8+B9 -> 85 | D9: =($F$3/50)*C9 -> 101.55375 | E9: Evli eşi çalışan ve 4 çocuklu | F9: 5 | G9: =G8+F9 -> 75 | H9: =($F$3/50)*G9 -> 89.60625
A11: AGİ ÖDEMESİ YAPILACAK | B11: KİŞİNİN ADI VE SOYADI | E11: Halil ibrahim ALACA
A12: aylar | B12: Ödenmesi Gereken | D12: Ödenen | E12: Noksan veya Fazla Ödeme
A13: Ocak | B13: =$D$5 -> 71.685 | D13: =$H$7 -> 77.65875 | E13: =B13-D13 -> -5.97375
A14: Şubat | B14: =$D$5 -> 71.685 | D14: =$H$7 -> 77.65875 | E14: =B14-D14 -> -5.97375
A15: Mart | B15: =$D$5 -> 71.685 | D15: =$H$7 -> 77.65875 | E15: =B15-D15 -> -5.97375
A16: Nisan | B16: =$D$5 -> 71.685 | D16: 0 | E16: =B16-D16 -> 71.685 | G16: H.Kodu | H16: Ek Kod | I16: B | J16: A
A17: Mayıs | B17: =$D$5 -> 71.685 | D17: 0 | E17: =B17-D17 -> 71.685 | G17: 630 | H17: 12,1,1,9 | I17: =B26 -> 412.19375
A18: Haziran | B18: =$D$5 -> 71.685 | D18: 0 | E18: =B18-D18 -> 71.685 | G18: 810 | H18: 1,1,1,3 | I18: =I17 -> 412.19375
A19: Temmuz | B19: =$D$5 -> 71.685 | D19: 0 | E19: =B19-D19 -> 71.685 | G19: 835 | J19: =I17 -> 412.19375
A20: Ağustos | B20: =$D$5 -> 71.685 | D20: 0 | E20: =B20-D20 -> 71.685 | G20: 325 | J20: =I17 -> 412.19375
A21: Eylül | B21: 71.69 | D21: 0 | E21: =B21-D21 -> 71.69
A22: Ekim | B22: 72.69 | D22: 0
A23: Kasım | B23: 73.69 | D23: 0
A24: Aralık | B24: 74.69 | D24: 0
A25: TOPLAMLAR | B25: =SUM(B13:B21) -> 645.17 | D25: =SUM(D13:D21) -> 232.97625 | E25: =SUM(E13:E24) -> 412.19375
A26: Ödenmesi Gereken | B26: =B25-D25 -> 412.19375 | E26: =IF(A27=0," ",A27)
A27: =IF((B26=E25),0,"HATA VAR KONTROL ET") -> 0

Sheet NAKİL BİLDİRİM 
B2: PERSONEL NAKİL BİLDİRİMİ
B3: ADI VE SOYADI
B4: SAYMANLIK KİŞİ NUMARASI
B5: T.C. KİMLİK NUMARASI | E5: 38719013226
B6: VERGİ NUMARASI
B7: SİCİL NUMARASI | D7: KURUM | I7: EMEKLİ | J7: 64227045
B8: MEMURİYET YERİ | D8: ESKİ | I8: YENİ
B9: ÜNVANI | D9: ESKİ | I9: YENİ
B10: DERECE VE KADEMESİ (MÜKTESEP) K.H.A | G10: Göstergesi | H10: Ek Göstergesi | L10: Göstergesi | M10: Ek Göstergesi
D11: ESKİ | E11: 1 | F11: 3 | G11: =IF(ISBLANK($E$5),"",HLOOKUP(F11,$Q$13:$Z$28,E11+1)) -> 1440 | H11: 0 | I11: YENİ | J11: 4 | K11: 1 | L11: =IF(ISBLANK($E$5),"",HLOOKUP(K11,$Q$13:$Z$28,J11+1)) -> 915 | M11: 650 | Q11: MEMUR VE EMEKLİ GÖSTERGE TABLOSU
B12: DERECE VE KADEMESİ (EMEKLİ KESENEĞİ) E.M.A. | D12: ESKİ | E12: 3 | F12: 1 | G12: =IF(ISBLANK($E$5),"",HLOOKUP(F12,$Q$13:$Z$28,E12+1)) -> 1020 | H12: 0 | I12: YENİ | J12: 4 | K12: 1 | L12: =IF(ISBLANK($E$5),"",HLOOKUP(K12,$Q$13:$Z$28,J12+1)) -> 915 | M12: 650 | Q12: DERECELER | R12: K A D E M E L E R
B13: TERFİ TARİHLERİ | C13: K.H.A. | E13: 39744 | R13: 1 | S13: 2 | T13: 3 | U13: 4 | V13: 5 | W13: 6 | X13: 7 | Y13: 8 | Z13: 9
C14: E.M.A. | Q14: 1 | R14: 1320 | S14: 1380 | T14: 1440 | U14: 1500
B15: ATAMA TARİHİ | E15: 40016 | Q15: 2 | R15: 1155 | S15: 1210 | T15: 1265 | U15: 1320 | V15: 1380 | W15: 1440
B16: ÖĞRENİM DURUMU | E16: Lise | Q16: 3 | R16: 1020 | S16: 1065 | T16: 1110 | U16: 1155 | V16: 1210 | W16: 1265 | X16: 1320 | Y16: 1380
B17: YILLIK İZİN DURUMU | E17: 56 GÜN | Q17: 4 | R17: 915 | S17: 950 | T17: 985 | U17: 1020 | V17: 1065 | W17: 1110 | X17: 1155 | Y17: 1210 | Z17: 1265
B18: KIDEM AYLIK ESAS HİZMET SÜRESİ | E18: GÜN | G18: AY | H18: YIL | Q18: 5 | R18: 835 | S18: 865 | T18: 895 | U18: 915 | V18: 950 | W18: 985 | X18: 1020 | Y18: 1065 | Z18: 1110
H19: 19 | Q19: 6 | R19: 760 | S19: 785 | T19: 810 | U19: 835 | V19: 865 | W19: 895 | X19: 915 | Y19: 950 | Z19: 985
B20: TASARRUFU TEŞVİK HESAP NUMARASI | E20: --- | Q20: 7 | R20: 705 | S20: 720 | T20: 740 | U20: 760 | V20: 785 | W20: 810 | X20: 835 | Y20: 865 | Z20: 895
B21: ESKİ MEMURİYETTEN AYRILIŞ TARİHİ | E21: 40037 | Q21: 8 | R21: 660 | S21: 675 | T21: 690 | U21: 705 | V21: 720 | W21: 740 | X21: 760 | Y21: 785 | Z21: 810
B22: YENİ GÖREV YERİNDE AYLIĞA VE EK ÜÇRETE HAK KAZANDIĞI TARİH | E22: 40071 | Q22: 9 | R22: 620 | S22: 630 | T22: 645 | U22: 660 | V22: 675 | W22: 690 | X22: 705 | Y22: 720 | Z22: 740
B23: 15 GÜN İÇİNDE HAREKET ETMEDİĞİ TAKDİRDE GEÇİKME NEDENİ | E23: ---------- | Q23: 10 | R23: 590 | S23: 600 | T23: 610 | U23: 620 | V23: 630 | W23: 645 | X23: 660 | Y23: 675 | Z23: 690
B24: ŞAHSI VE AİLE YOLLUĞUNU ALIP ALMMADIĞI, ALMIŞSA TUTARI | E24: 2.125,82 TL. | H24: Almıştır. | Q24: 11 | R24: 560 | S24: 570 | T24: 580 | U24: 590 | V24: 600 | W24: 610 | X24: 620 | Y24: 630 | Z24: 645
B25: SÜREGELEN GELİR VERGİSİ MATRAH TOPLAMI | E25: =I25+M25 -> 2350.5 | H25: MAAŞA AİT | I25: 2350.5 | L25: DÖNER VS.AİT | M25: 0 | Q25: 12 | R25: 545 | S25: 550 | T25: 555 | U25: 560 | V25: 570 | W25: 580 | X25: 590 | Y25: 600 | Z25: 610
B26: GİYECEK YARDIMI ALIP ALMADIĞI, ALMIŞSA TUTARI | E26: ---------- | Q26: 13 | R26: 530 | S26: 535 | T26: 540 | U26: 545 | V26: 550 | W26: 555 | X26: 560 | Y26: 570 | Z26: 580
B27: BORÇLU İSE BORÇLARINA AİT BİLGİ | E27: 2007/123 Nolu Dosyaya 1.527,97 TL Kişi borcu vardır. | Q27: 14 | R27: 515 | S27: 520 | T27: 525 | U27: 530 | V27: 535 | W27: 540 | X27: 545 | Y27: 550 | Z27: 555
B28: ALMIŞ OLDUĞU RAPORLARININ YIL İÇİNDEKİ TOPLAM SÜRESİ | E28: 2009 Yılında Rapor Almamıştır. | Q28: 15 | R28: 500 | S28: 505 | T28: 510 | U28: 518 | V28: 520 | W28: 525 | X28: 530 | Y28: 535 | Z28: 540
B29: YABANCI DİL TAZMİNATINDAN YARARLANIP YARARLANMADIĞI, YARARLANIYORSA GURUBU | E29: ----------
B30: MEDENİ HALİ | E30: EVLİ, EŞİ ÇALIŞMIYOR 2 ÇOCUKLU
B31: As.Geç.İnd. Durumu | E31: EVLİ, EŞİ ÇALIŞMIYOR 2 ÇOCUKLU
B32: SENDİKA ADI - ÜYE NO | E32: Yok
B35: SENDİKA
B38: Not
C41: MUTEMET | D41: DÜZENLEYEN | H41: PERSONEL BİRİM YETKİLİSİ | K41: MUHASEBE YETKİLİSİ
B43: ADI VE SOYADI | C43: Yelda POLAT | D43: Halil İbrahim ALACA
B44: ÜNVANI | C44: Muhasebe Uzmanı | D44: Muhasebe Şefi
B45: İMZASI
B48: H.İ.ALACA

Sheet EK GÖSTERGELER 
A7: EK GÖSTERGELER
A20: Hazırlamaya Calışan
A21: Halil İbrahim ALACA
A22: MUHASEBE ŞEFİ
A23: BURSA DEFTERDARLIK MUHASEBE MÜDÜRLÜĞÜ
A24: 40851
A57: I SAYILI CETVEL (Ek: 9/4/1990-KHK-418/3 md.; İptal: Ana.Mah.nin 5/2/1992 tarih ve E.1990/22, K.1992/6 sayılı Kararı ile; Yeniden düzenleme: 18/5/1994-KHK-527/3 md.)
A58: HİZMET SINIFLARI İTİBARİYLE UNVAN VEYA AYLIK ALINAN
A59: DERECELERE GÖRE EK GÖSTERGELER
A61: UNVANI | B61: Derece | C61: 1/1/1994’den İtibaren Uygulanacak Ek Göstergeler | D61: 1/1/1995’den İtibaren Uygulanacak Ek Göstergeler
A62: I - GENEL İDARE HİZMETLERİ SINIFI
A63: a) Başbakanlık Müsteşarı, Diyanet İşleri Başkanı (25), Bakan Yardımcısı (28) | B63: 1 | C63: 7000 | D63: 8000
A64: b) Müsteşarlar, (…) (1) | B64: 1 | C64: 6600 | D64: 7600
A65: c)(…)(25) Başbakanlık Teftiş Kurulu Başkanı,Başbakanlık Yüksek Denetleme Kurulu Başkanı, Devlet Personel Başkanı, Afet ve Acil Durum Yönetimi Başkanı, Gelir İdaresi Başkanı, Talim ve Terbiye Kurulu Başkanı, Türk İşbirliği ve Kalkınma İdaresi Başkanı, Sosyal Güvenlik Kurumu Başkanı,(…)(17), Türkiye İstatistik Kurumu Başkanı,Yurtdışı Türkler ve Akraba Topluluklar Başkanı (5)(8)(9)(13)(14)(20)(24)(25) | B65: 1 | C65: 6100 | D65: 7000
A66: d)GAP İdaresi Başkanı, Doğu Anadolu Projesi Bölge Kalkınma İdaresi Başkanı, Konya Ovası Projesi Bölge Kalkınma İdaresi Başkanı,(28) Doğu Karadeniz Projesi Bölge Kalkınma İdaresi Başkanı, Kalkınma Araştırmaları Merkezi Başkanı,(29) Ulaştırma, Denizcilik ve Haberleşme Araştırmaları Merkezi Başkanı(34), Atatürk Kültür, Dil ve Tarih Yüksek Kurumu Başkanı,Toplu Konut İdaresi Başkanı ve (...)11 Kamu Ortaklığı İdaresi Başkanı, Başbakan Başmüşaviri, Başbakanlık Müsteşar Yardımcıları, Diyanet İşleri Başkan Yardımcıları, Din İşleri Yüksek Kurulu Başkanı, Mushafları İnceleme ve Kıraat Kurulu Başkanı, (25)(…)(10) Büyükelçi ve Daimi Temsilci Unvanını kazanmış olanlar, Müsteşar Yardımcıları ve Genel Müdürler, Dışişleri Bakanlığı Stratejik Araştırmalar Merkezi Başkanı,(26)Strateji Geliştirme Başkanları,(16) (…)(2), Yurtdışı Türkler ve Akraba Topluluklar Başkanlığı Başkan Yardımcısı,(24) Gelir İdaresi Başkan Yardımcısı,(18) Sosyal Güvenlik Kurumu Başkan Yardımcısı,(8)Bakanlıklar merkez teşkilatına dahil Kurul Başkanları, Bakanlık Rehberlik ve Teftiş Başkanları, Bakanlık Rehberlik ve Denetim Başkanları, (30) Bakanlık Denetim Hizmetleri Başkanları,(28) Özel Çevre Koruma Kurumu Başkanı, (…)(28)Hazine Müsteşarlığı Bankalar Yeminli Murakıpları Kurulu Başkanı, Hazine Kontrolörleri Kurulu Başkanı, (…)(28) Denizcilik Müsteşarlığı Teftiş Kurulu Başkanı (6) ile Sigorta Denetleme Kurulu Başkanı, Türk Patent Enstitüsü Başkanı,(3) Türkiye Yazma Eserler Başkanı,(27) (…)(28) (…)(31) Milli Savunma Bakanlığı Akaryakıt İkmal ve NATO POL Tesisleri İşletme Başkanı,(4) Sosyal Güvenlik Kurumu Rehberlik ve Teftiş Başkanı, Diyanet İşleri Başkanlığı Rehberlik ve Teftiş Başkanı (17)(25)(27) | B66: 1 | C66: 5500 | D66: 6400
A67: e) (...)(10) Başbakan Müşavirleri, Adalet Bakanlığı Bakanlık Yüksek Müşavirleri (…)(18) Türkiye İstatistik Kurumu Başkan Yardımcıları, Toplu Konut İdaresi Başkan Yardımcıları (13)(15)(22)(23) | B67: 1 | C67: 4500 | D67: 5300
A68: f) (…)(25)Bakanlar Kurulu Sekreteri, Başbakanlık Başkanları, Avrupa Birliği Bakanlığı Başkanları,(21)Atatürk Kültür, Dil ve Tarih Yüksek Kurumu Başkan Yardımcıları ile Atatürk Araştırma Merkezi,Türk Dil Kurumu, Türk Tarih Kurumu ve Atatürk Kültür Merkezi Başkanları, (…)(28)(29),Başbakanlık Özel Kalem Müdürü, Adli Tıp Kurumu Başkanı, Milli Kütüphane Başkanı,(7) (Başbakanlık Yüksek Denetleme Kurulu Üyesi,Yüksek Öğretim Kurulu Genel Sekreteri,Büyük Şehir Belediye Genel Sekreteri (12),Talim ve Terbiye Kurulu Üyesi, Din İşleri Yüksek Kurulu Üyesi,(25)GAP İdaresi Başkan Yardımcısı,(19) Doğu Anadolu Projesi Bölge Kalkınma İdaresi Başkan Yardımcısı, Konya Ovası Projesi Bölge Kalkınma İdaresi Başkan Yardımcısı,(28) Doğu Karadeniz Projesi Bölge Kalkınma İdaresi Başkan Yardımcısı,(29) Türk İşbirliği ve Koordinasyon Ajansı Başkan Yardımcısı(33), Vergi Dairesi Başkanı (Ankara, İstanbul, İzmir) (5)(13)(25)(29) | B68: 1 | C68: 4100 | D68: 4800
A71: (1) "Avrupa Birliği Genel Sekreteri " ibaresi, 27/6/2000 tarihli ve 4587 sayılı Kanun ile cetvele eklenmiş olup, daha sonra 3/6/2011 tarihli ve 643 sayılı KHK’nın 8 inci maddesiyle yürürlükten kaldırılmıştır.
A72: (2) "Avrupa Birliği Genel Sekreter Yardımcıları" ibaresi, 27/6/2000 tarihli ve 4587 sayılı Kanun ile cetvele eklenmiş olup, daha sonra 3/6/2011 tarihli ve 643 sayılı KHK’nın 8 inci maddesiyle yürürlükten kaldırılmıştır.
A73: (3) Bu bölümde 19/6/1994 tarih ve 544 sayılı, 25/3/1997 tarih ve 571 sayılı KHK’ler ve 9/12/1994 tarih ve 4059 Sayılı Kanun ile değiştirilen ya da eklenen unvanlar metne işlenmiştir.544 sayılı KHK ile eklenen "Türk Patent Enstitüsü Başkanı" ibaresi, 6/11/2003 tarihli ve 5000 sayılı Kanun ile Kanunlaşmıştır.
A74: (4) "Milli.S.Bak.Akaryakıt ik.ve NATO POL Tes.iş.Bşk." ibaresi , 6/7/2000 tarihli ve 613 sayılı KHK ile metne eklenmiş olup, sözkonusu KHK, 5/4/2001 tarih ve 4636 sayılı Kanun ile değiştirilmek suretiyle kanunlaştırılmıştır.
A75: (5) Türk İş Bir. Kal.İd.Baş., Başk. Yar. ibareleri; 2/5/2001 tarihli ve 4668 sayılı Kanunla eklenmiştir.
A76: (6) "Denizcilik Müsteşarlığı Teftiş Kurulu Başkanı" ibaresi, 7/2/2002 tarihli ve 4745 sayılı Kanunla eklenmiştir.
A77: (7) "Milli Kütüphane Başkanı" ibaresi, 16/4/2003 tarihli ve 4848 sayılı Kanunun 33 üncü maddesiyle eklenmiştir.
A78: (8) (1/c) bendinde yer alan, "Sosyal Güvenlik Kurumu Başkanı" ve (1/d) bendinde yer alan "Sosyal Güvenlik Kurumu Başkan Yardımcısı" ibareleri, 16/7/2003 tarihli ve 4947 sayılı Kanunun 37 nci maddesiyle eklenmiştir.
A79: (9) “Sosyal Sigortalar Kurumu Başkanı” ibaresi 29/7/2003 tarihli ve 4958 sayılı Kanunun 20 nci maddesiyle eklenmiştir.
A80: (10) 31/7/2003 tarihli ve 4969 sayılı Kanunun 5 inci maddesiyle, (I/e) bendinde yer alan "Devlet Planlama Teşkilatı Genel Sekreteri" ibaresi bu bentten çıkarılarak "Müsteşar Yardımcıları" ibaresinden sonra gelmek üzere (1/d) bendine eklenmiş olup, daha sonra 3/6/2011 tarihli ve 643 sayılı KHK’nın 8 inci maddesiyle yürürlükten kaldırılmıştır.
A81: (11) Bu arada yer alan “Kamu Ortaklığı İdaresi Başkanı”na yapılan atıfların 24/11/1994 tarihli ve 4046 sayılı Kanunun Geçici 7 nci maddesiyle Özelleştirme İdaresi Başkanına yapılmış sayılacağı, ayrıca aynı Kanunun 6 ncı maddesiyle Özelleştirme İdaresi Başkan ve başkan yardımcılarının aylık, ek gösterge,zam ve tazminatları ile statüleri bakımından Başbakanlığa bağlı müsteşarlıkların müsteşar ve müsteşar yardımcıları hakkında uygulanan hükümlere tabi olacakları hükme bağlanmıştır.
A82: (12) Büyükşehir belediye genel sekreteri ile ilgili olarak 10/7/2004 tarihli ve 5216 sayılı Kanunun 22 nci maddesine bakınız.
... A109: (35) 11/10/2011 tarihli ve 663 sayılı KHK’nin 58 inci maddesiyle bölümünün (d) bendine “Müsteşar Yardımcıları ve Genel Müdürler” ibaresinden sonra gelmek üzere “, Türkiye Halk Sağlığı Kurumu Başkanı, Türkiye İlaç ve Tıbbî Cihaz Kurumu Başkanı, Türkiye Kamu Hastaneleri Kurumu Başkanı” ibaresi eklenmiştir.
A111: UNVANI | B111: Derece | C111: 1/1/1994’den İtibaren Uygulanacak Ek Göstergeler | D111: 1/1/1995’den İtibaren Uygulanacak Ek Göstergeler
A112: g) En az üç yıl süreli yükseköğrenim veren fakülte ve yüksekokulları bitirerek mesleğe özel yarışma sınavı ile giren ve belirli süreli meslek içi eğitimden sonra özel bir yeterlik sınavı sonunda (veya yüksek öğrenimli olup,özel kanunların öngördüğü şartları taşıyanlardan en az sekiz yıl mesleki görev yaptıktan sonra yine bu kanunların öngördüğü usule göre seçilerek) atanan Başbakanlık, Bakanlık, Müsteşarlık, Diyanet İşleri Başkanlığı ve Bağımsız Genel Müdürlük ve Büyük Şehir Belediyesiyle Büyük Şehir Belediye sınırları içindeki ilçe Belediyeleri Müfettişleri, Başbakanlık Uzmanları, Kalkınma bakanlığı Planlama Uzmanları,(30)Başbakanlık Yüksek Denetleme Kurulu Uzmanları, Dışişleri Meslek Memurları, Maliye Bakanlığı Vergi Müfettişleri (32) ile Hazine Müsteşarlığı Bankalar Yeminli Murakıpları ve Hazine Kontrolörleri, Hazine Uzmanları (1) Sigorta Denetleme Uzmanları ile Aktüerleri, (…)(30) Dış Ticaret Uzmanları ve Dış Ticaret Uzmanları, (…)(36) Avrupa Birliği İşleri Uzmanları, (…)(32) Çalışma ve Sosyal Güvenlik Bakanlığı İş ve İş Güvenliği Müfettişleri ve Bakanlıkların Merkez Teşkilatına dahil Genel Müdürlükleri Kontrolörleri ve İçişleri Bakanlığı Dernekler Denetçileri ile Sosyal Güvenlik Kurumu Müfettişleri, Sosyal Güvenlik Uzmanları, Milli Savunma Bakanlığı Akaryakıt İkmal ve NATO POL Tesisleri İşletme Başkanlığı Müfettişleri, Türkiye İstatistik Kurumu Uzmanları ile 5018 sayılı Kamu Mali Yönetimi ve Kontrol Kanunu hükümlerine göre atanan İç Denetçiler, Millî Eğitim Uzmanları, Millî Eğitim Denetçileri ve İl Eğitim Denetmenleri, Aile ve Sosyal Politikalar Denetçileri (1)(9)(10)(14)(15)(16)(17) (22)(24)(30)(32)(35) | B112: 1 | C112: 3200 | D112: 3600
B113: 2 | C113: 2600 | D113: 3000
B114: 3 | C114: 1900 | D114: 2200
B115: 4 | C115: 1450 | D115: 1600
B116: 5 | C116: 1100 | D116: 1300
B117: 6 | C117: 950 | D117: 1150
B118: 7 | C118: 850 | D118: 950
B119: 8 | C119: 750 | D119: 850
A125: h) En az 3 yıl süreli yükseköğrenim veren fakülte ve yüksekokulları bitirerek mesleğe özel yarışma sınavı ile giren ve belirli süreli meslek içi eğitimden sonra özel bir yeterlik sınavı sonunda atanan Devlet Personel Uzmanları, Afet ve Acil Durum Yönetimi Uzmanları, (21) Maliye Bakanlığı Devlet Bütçe Uzmanları, Konsolosluk ve İhtisas Memurları,(26)(…)(17), Çalışma Uzmanları, Yurt Dışı İşçi Hizmetleri Uzmanları, İş Sağlığı ve Güvenliği Uzmanları, Çalışma ve Sosyal Güvenlik Eğitim Uzmanları,(7) Mali Suçları Araştırma Uzmanları Devlet Muhasebe Uzmanları, Devlet Gelir Politikaları Uzmanları, (32) Devlet Gelir Uzmanları, Devlet Malları Uzmanları, Gelir Uzmanları, İl İstihdam Uzmanları, (40) Mali Hizmetler Uzmanları,(16) Milli Emlak Uzmanları,Vergi İstihbarat Uzmanları, (…)(38), Bakanlık ve bağlı kuruluşların A.B Uzmanları, İçişleri Bakanlığı Planlama Uzmanları, (…)(5) (…)(31) (…) (13) (…)(12) (…) (11) (…)(17) ,(8) Kültür ve Turizm Uzmanları,(4) Yazma Eser Uzmanları,(28) (…)(39) Vakıf Uzmanları,(18) Tapu ve Kadastro Uzmanları,(27) Diyanet İşleri Uzmanları, Din İşleri Yüksek Kurulu Uzmanları,(25) (…)(30) (...)(2) (…)(39) (…)(30) Yurtdışı Türkler ve Akraba Topluluklar Uzmanları, (23) Ölçme, Seçme ve Yerleştirme Merkezi Uzmanları,(29) (…) (17) , TİKA Uzmanları(37), Sanayi ve Teknoloji Uzmanları, Çevre ve Şehircilik Uzmanları, Orman ve Su İşleri Uzmanları, Gençlik ve Spor Uzmanları, Aile ve Sosyal Politikalar Uzmanları, Gıda, Tarım ve Hayvancılık Uzmanları, Gümrük ve Ticaret Uzmanları, İhracatı Geliştirme Uzmanları,(30) Savunma Sanayii Uzmanları,(33) Basın ve Enformasyon Uzmanları,(34) Yüksek Kurum Uzmanları,(41) (Ek İbare: 19/6/1994-KHK-543) En az üç yıl süreli Yüksek Öğretim veren Fakülte veya Yüksekokulu bitirerek yapılacak sınav sonucunda denetmen yardımcısı kadrolarına atanmış ve en az üç yıl bu kadrolarda çalıştıktan sonra bu süredeki çalışmaları olumlu bulunmak kaydıyla Muhasebe Denetmeni (..) (32) ve Milli Emlak Denetmeni, Ürün Denetmenleri (30) , Defterdarlık Uzmanları (38) , (…)(27) İstihdam Uzmanları, (40) (6) Marka Uzmanı, Patent Uzmanı, kadrosuna atanmış olanlar. (1)(10)(20)(25)(26)(27)(28)(29)(30)(31)(32)(33)(34) (39)(40)(41) | B125: 1 | C125: 1900 | D125: 2200
...

Sheet EK GÖSTERGELER T.S.K 
A1: EK GÖSTERGE CETVELLERİ
A3: I Sayılı Ek Gösterge Cetveli (Ek: 9/4/1990 - KHK - 418/17 md.; İptal: Ana.Mah.'nin 5/2/1992 tarih ve E. 1990/22, K. 1992/6 sayılı Kararı ile; Yeniden düzenleme: 18/5/1994 -KHK - 527/14 md.)
A4: (Subaylar İçin)
A5: 1.1.1994'den 1.1.1995'den İtibaren Uy- İtibaren Uygulanacak Ek gulanacak Ek Göstergeler
A6: UNVANI | O6: DERECE | Q6: Ek Göstergeler
A7: a) Genel Kurmay Başkanı | P7: 1 | Q7: 9000
A8: b) Kuvvet Komutanları ve Jandarma Genel Komutanı (Orgeneral ve Oramiral olmak kaydıyla) | P8: 1 | Q8: 8400
A9: c) Orgeneral-Oramiral | P9: 1 | Q9: 8000
A10: d) Korgeneral-Koramiral | P10: 1 | Q10: 7600
A11: e) Tümgeneral-Tümamiral | P11: 1 | Q11: 7000
A12: f) Tuğgeneral-Tugamiral | P12: 1 | Q12: 6400
A13: g) Kıdemli Albay | P13: 1 | Q13: 5800
A14: h) Albay | P14: 1 | Q14: 4800
A15: j) Diğer Subaylar (Bu Kanunun 109 uncu maddesine göre astsubaylıktan subay olanlar dahil) | P15: 1 | Q15: 3600
P16: 2 | Q16: 3000
P17: 3 | Q17: 2200
P18: 4 | Q18: 1600
P19: 5 | Q19: 1300
P20: 6 | Q20: 1150
P21: 7 | Q21: 950
P22: 8 | Q22: 850
A24: II Sayılı Ek Gösterge Cetveli (Ek: 9/4/1990 - KHK - 418/17 md.; Mülga: 9/8/1993 - KHK - 499/36 md.)
A25: (Astsubaylıktan Subaylığa Geçenler İçin)
A26: III Sayılı Ek Gösterge Cetveli (Ek: 9/4/1990 - KHK - 418/17 md.; İptal: Ana. Mah.'nin 5/2/1992 tarih ve E. 1990/22, K. 1992/6 sayılı Kararı ile; Yeniden düzenleme: 18/5/1994 -KHK - 527/14 md.)
A27: (Astsubaylar İçin)
A28: 1.1.1994'den 1.1.1995'den itibaren itibaren Uygulanacak Uygulanacak
M29: DERECE | O29: Ek Göstergeler | Q29: Ek Göstergeler
M30: 1 | O30: 3200 | Q30: 3600
M31: 2 | O31: 2600 | Q31: 3000
M32: 3 | O32: 1900 | Q32: 2200
M33: 4 | O33: 1450 | Q33: 1600
M34: 5 | O34: 1100 | Q34: 1300
M35: 6 | O35: 950 | Q35: 1150
M36: 7 | O36: 850 | Q36: 950
M37: 8 | O37: 750 | Q37: 850
A52: IV Sayılı Ek Gösterge Cetveli (Ek: 9/4/1990 - KHK - 418/17 md.; İptal Ana. Mah.'nin 5/2/1992 tarih ve E. 1990/22, K. 1992/6 sayılı Kararı ile; Yeniden düzenleme: 18/5/1994 -KHK - 527/14 md.)
A53: (Askeri Hakim ve Savcılar İçin)
A54: 1.1.1994'den 1.1.1995'den itibaren itibaren Uygulanacak Uygulanacak gulanacak Ek gulanacak Ek
A55: UNVANI | M55: DERECE | O55: Ek Göstergeler | Q55: Ek Göstergeler
A56: a) I inci derecede 6 yılını tamamlamış ve askeri yüksek yargı organları üyeliğine seçilme hakkını kaybetmemiş olanlara, | M56: 1 | O56: 5000 | Q56: 5800
...

Sheet EK ÖDEME 375 
A1: 16 Ağustos 2008 CUMARTESİ Resmî Gazete | B1: Sayı : 26969 (Mükerrer)
A2: BAKANLAR KURULU KARARI
A3: 375 SAYILI KANUN HÜKMÜNDE KARARNAMENİN EK 3 ÜNCÜ MADDESİ
A4: UYARINCA YAPILACAK EK ÖDEMEYE İLİŞKİN KARAR
A6: Amaç ve kapsam
A7: MADDE 1 – (1) Bu Karar, 375 sayılı Kanun Hükmünde Kararnamenin ek 3 üncü maddesi uyarınca yapılacak ek ödemenin tutarı ile usul ve esaslarını düzenlemektedir.
A8: Dayanak
A9: MADDE 2 – (1) Bu Karar, 375 sayılı Kanun Hükmünde Kararnamenin ek 3 üncü maddesine dayanılarak hazırlanmıştır.
A10: Ek ödeme tutarı
A11: MADDE 3 – (1) Bu Karar uyarınca personele yapılacak ek ödeme, en yüksek Devlet memuru aylığına (ek gösterge dâhil) ekli "Ek Ödeme Cetveli"nde yer alan oranların uygulanması suretiyle hesaplanır.
A12: Ek ödemenin usul ve esasları
A13: MADDE 4 – (1) Ek ödeme, 375 sayılı Kanun Hükmünde Kararnamenin ek 3 üncü maddesi ile bu Kararda belirtilen usul ve esaslar çerçevesinde yapılır.
A14: (2) 17/4/2006 tarihli ve 2006/10344 sayılı Bakanlar Kurulu Kararı ile yürürlüğe konulan Devlet Memurlarına Ödenecek Zam ve Tazminatlara İlişkin Karara ekli (III) sayılı cetvelin "B. Din Hizmetleri Tazminatı" bölümünün (d) sırası (aynı Karara ekli (II) sayılı Özel Hizmet Tazminatı Cetvelinin "(A) Üst Yönetim ve Genel İdare Hizmetleri" bölümünün 6 ncı grubunun 7 nci sırasında, 7 nci grubunun 1 inci sırasında ve 9 uncu grubunun 7 nci sırasında sayılanlar hariç) ile aynı cetvelin "F. Adalet Hizmetleri Tazminatı" bölümünün 2 nci sırasında öngörülen tazminatlardan yararlananlara yapılacak ek ödeme, anılan sıralarda öngörülen tazminat oranı kadar eksik ödenir. Ancak, ödenecek ek ödeme hiçbir şekilde en yüksek Devlet memuru aylığının (ek gösterge dâhil) %28’inden az olamaz.
... A31: 5) Aynı Kararın eki (II) sayılı Cetvele aşağıdaki satır eklenmiştir.
A33: TÜRKİYE ADALET AKADEMİSİ BAŞKANLIĞI | B33: 23/7/2003 tarihli ve 4954 sayılı Kanunun 24. mad.
A35: 6) Aynı Karara, ekli "(III) Sayılı Cetvel" eklenmiştir.
A36: Yürürlük
A37: MADDE 6 – (1) Bu Karar 15/8/2008 tarihinde yürürlüğe girer.
A38: Yürütme
A39: MADDE 7 – (1) Bu Karar hükümlerini Bakanlar Kurulu yürütür.
A41: 12 Ocak 2010 SALI Resmî Gazete | C41: Sayı : 27460
A42: BAKANLAR KURULU KARARI
A43: Karar Sayısı : 2010/7
A44: Ekli “Kamu Personelinin Maaşlarının Hesabına Esas Tutulan Katsayıların Yeniden Tespiti ve İlgili Mevzuatı Uyarınca İstihdam Edilen Sözleşmeli Personelin Ücretlerinin Artırılması, Devlet Memurlarına Ödenecek Zam ve Tazminatlar ile Bazı Kararlarda Değişiklik Yapılmasına İlişkin Karar”ın yürürlüğe konulması; Maliye Bakanlığının 6/1/2010 tarihli ve 42 sayılı yazısı üzerine, 2010 Yılı Merkezi Yönetim Bütçe Kanununun 21 inci, 657 sayılı Devlet Memurları Kanununun 152 nci, 375 sayılı Kanun Hükmünde Kararnamenin ek 3 üncü ve 631 sayılı Kanun Hükmünde Kararnamenin 14 üncü maddeleri ile muhtelif statülerde sözleşmeli personel istihdamına imkân sağlayan mevzuat hükümlerine göre, Bakanlar Kurulu’nca 6/1/2010 tarihinde kararlaştırılmıştır.
A45: KAMU PERSONELİNİN MAAŞLARININ HESABINA ESAS TUTULAN
A46: KATSAYILARIN YENİDEN TESPİTİ VE İLGİLİ MEVZUATI UYARINCA
A47: İSTİHDAM EDİLEN SÖZLEŞMELİ PERSONELİN ÜCRETLERİNİN
A48: ARTIRILMASI, DEVLET MEMURLARINA ÖDENECEK
A49: ZAM VE TAZMİNATLAR İLE BAZI KARARLARDA
A50: DEĞİŞİKLİK YAPILMASINA İLİŞKİN KARAR
A51: Katsayıların belirlenmesi
A52: MADDE 1 – 1/1/2010 tarihinden geçerli olmak üzere, 14/7/1965 tarihli ve 657 sayılı Devlet Memurları Kanununun 154 üncü maddesi uyarınca aylık gösterge tablosunda yer alan rakamlar ile ek gösterge rakamlarının aylık tutarlara çevrilmesinde uygulanacak aylık katsayısı (0,057383), memuriyet taban aylığı göstergesine uygulanacak aylık taban katsayısı (0,76293), iş güçlüğü, iş riski, temininde güçlük ve mali sorumluluk zamlarının aylık tutarlara çevrilmesinde uygulanacak yan ödeme katsayısı ise (0,01819) olarak yeniden belirlenmiştir.
A53: Ücretlerin artırılması
... A72: MADDE 6 – Bu Karar hükümlerini Bakanlar Kurulu yürütür.
A75: 5 Ocak 2011 ÇARŞAMBA Resmî Gazete | B75: Sayı : 27806
A76: BAKANLAR KURULU KARARI
A77: Karar Sayısı : 2011/1241
A78: Ekli "Kamu Personelinin Maaşlarının Hesabına Esas Tutulan Katsayıların Yeniden Tespiti ve İlgili Mevzuatı Uyarınca İstihdam Edilen Sözleşmeli Personelin Ücretlerinin Artırılması, Devlet Memurlarına Ödenecek Zam ve Tazminatlar ile Bazı Kararlarda Değişiklik Yapılmasına İlişkin Karar"ın yürürlüğe konulması; Maliye Bakanlığının 3/1/2011 tarihli ve 1 sayılı yazısı üzerine, 2011 Yılı Merkezi Yönetim Bütçe Kanununun 21 inci maddesi, 657 sayılı Devlet Memurları Kanununun 152 ve 202 nci maddeleri, 375 sayılı Kanun Hükmünde Kararnamenin ek 3 üncü maddesi ve 631 sayılı Kanun Hükmünde Kararnamenin 14 üncü maddeleri ile muhtelif statülerde sözleşmeli personel istihdamına imkân sağlayan mevzuat hükümlerine göre, Bakanlar Kurulu'nca 3/1/2011 tarihinde kararlaştırılmıştır.
A80: KAMU PERSONELİNİN MAAŞLARININ HESABINA ESAS TUTULAN
A81: KATSAYILARIN YENİDEN TESPİTİ VE İLGİLİ MEVZUATI
...

Sheet 375 S.K. EK VE DEĞİŞ G.MEV.
A1: 451
A2: 657 SAYILI DEVLET MEMURLARI KANUNU, 926 SAYILI TÜRK SİLAHLI KUVVETLERİ PERSONEL KANUNU, 2802 SAYILI HAKİMLER VE SAVCILAR KANUNU, 2914 SAYILI YÜKSEKÖĞRETİM PERSONEL KANUNU, 5434 SAYILI T.C. EMEKLİ SANDIĞI KANUNU İLE DİĞER BAZI KANUN VE KANUN HÜKMÜNDE KARARNAMELERDE DEĞİŞİKLİK YAPILMASI,DEVLET MEMURLARI VE DİĞER KAMU GÖREVLİLERİNE MEMURİYET TABAN AYLIĞI VE KIDEM AYLIĞI İLE EK TAZMİNAT ÖDENMESİ HAKKINDA KANUN HÜKMÜNDE KARARNAME
A3: Kanun Hük. Kar.nin Tarihi : 27.6.1989 No : 375
A4: Yetki Kanununun Tarihi : 12.3.1986 No : 3268
A5: 9.4.1987 No : 3347
A6: 12.10.1988 No : 3479
A7: 1.6.1989 No : 3569
A8: Yayımlandığı R. G. Tarihi : 30.6.1989 No : Mükerrer 20211
A9: V. Tertip Düsturun Cildi : Sh.:
A10: Madde 1 – (Değişik: 5/7/1991-KHK-433/11 md.; İptal: Ana.Mah'nin 5/5/1992 tarih ve E. 1991/33, K. 1992/32 sayılı Kararı ile; Yeniden düzenleme: 18/5/1994-KHK-527/28 md.)
A11: A) Aylıklarını 657 sayılı Devlet Memurları Kanunu, 926 sayılı Türk Silahlı Kuvvetleri Personel Kanunu, 3269 sayılı Uzman Erbaş Kanunu, 3466 sayılı Uzman Jandarma Kanunu, 2914 sayılı Yükseköğretim Personel Kanunu ve 2802 sayılı Hakimler ve Savcılar Kanununa göre almakta olan personele 1000 gösterge rakamı üzerinden memuriyet taban aylığı ödenir. (1)
A12: Birinci fıkra kapsamına girenlere her bir hizmet yılı için 15 (20) gösterge rakamı karşılığı kıdem aylığı ödenir. Ancak 25 ve daha fazla hizmet yılını dolduranlar için gösterge rakamı 375 (500) olarak uygulanır. (2)
A13: Hizmet yılları itibariyle ödenecek kıdem aylığının tesbitinde kazanılmış hak aylığının hesabında değerlendirilen süreler esas alınır. Memuriyet taban ve kıdem aylığı miktarları, bunların göstergelerine 657 sayılı Devlet Memurları Kanununun 154 üncü maddesine göre tesbit olunan katsayılar uygulanmak suretiyle belirlenir. Memuriyet taban aylığı göstergesi için farklı katsayı tespit edile bilir. Kıdem ve memuriyet taban aylığı göstergelerini üç katına kadar artırmaya Bakanlar Kurulu yetkilidir.
... A44: Madde 3 – 657 sayılı Devlet Memurları Kanunu, 926 sayılı Türk Silahlı Kuvvetleri Personel Kanunu, 2914 sayılı Yükseköğretim Personel Kanunu, 2802 sayılı Hakimler ve Savcılar Kanunu ve diğer kanunlar uyarınca ek göstergeden yararlanan personelin ek gösterge rakamları aşağıdaki şekilde değiştirilmiştir.
B45: a) Genelkurmay Başkanı, | U45: 4500
B46: b) Orgeneral ve Oramiral olmak kaydıyla Kuvvet Komutanları ve Jandarma Genel Komutanı, | U46: 4200
B47: c) Orgeneral-Oramiraller, Anayasa Mahkemesi Başkanı, Yargıtay Başkanı, Danıştay Başkanı ve Başbakanlık Müsteşarı, | U47: 4000
B48: d) Korgeneral-Koramiraller, Uyuşmazlık Mahkemesi Başkanı, Sayıştay Başkanı, Yargıtay Cumhuriyet Başsavcısı, Danıştay Başsavcısı, | U48: 3800
B49: e) (Değişik: 25/1/1990-KHK-402/2 md.) Tümgeneral-Tümamiraller, Anayasa Mahkemesi, Yargıtay ve Danıştay Üyeleri, Yargıtay Cumhuriyet Başsavcısı Vekili, Birinci Sınıf Hakim ve Savcılar, Müsteşarlar, Talim ve Terbiye Kurulu Başkanı, | U49: 3500
B50: f) Başbakanlık Müsteşar yardımcıları, | U50: 2600
B51: g) (Ek: 23/10/1989-KHK-386/2 md.) Talim ve Terbiye Kurulu Üyesi | U51: 2400
A52: Yukarıda unvan olarak sayılanlar dışında kalan personelin halen uygulanmakta olan ek gösterge rakamları, aşağıda gösterildiği şekilde değiştirilmiştir.
A53: 30.6.1989 itibariyle 15.7.1989 tarihinden uygulanmakta olan itibaren uygulanacak
R54: Ek Göstergeler | U54: Ek Göstergeler
R55: 3300 | U55: 3800
R56: 3000 | U56: 3500
R57: 2700 | U57: 3200
R58: 2400 | U58: 2900
A59: 30.6.1989 itibariyle 15.7.1989 tarihinden uygulanmakta olan itibaren uygulanacak
R60: Ek Göstergeler | U60: Ek Göstergeler
R61: l950 | U61: 2400
R62: 1800 | U62: 2150
R63: 1650 | U63: 2000
R64: 1500 | U64: 1800
R65: 1200 | U65: 1500
R66: 900 | U66: 1100
