Workbook

Sheet Summary
A1: Consolidated Pricing Spreadsheet for Email as a Service BPA
A2: Summary of Pricing Offered - US | X2: Summary of Pricing Offered - Non-US
A3: Industry Partner | C3: 1a | D3: 1b | E3: 1c | F3: 1d | G3: 2a | H3: 2b | I3: 2c | J3: 2d | K3: 3a | L3: 3b | M3: 3c | N3: 3d | O3: 4a | P3: 4b | Q3: 4c | R3: 4d | S3: 5a | T3: 5b | U3: 5c | V3: 5d | X3: Industry Partner | Y3: 1a | Z3: 1b | AA3: 1c | AB3: 1d | AC3: 2a | AD3: 2b | AE3: 2c | AF3: 2d | AG3: 3a | AH3: 3b | AI3: 3c | AJ3: 3d | AK3: 4a | AL3: 4b | AM3: 4c | AN3: 4d | AO3: 5a | AP3: 5b | AQ3: 5c | AR3: 5d
A4: Accenture Federal Services LLC (G) | C4: =IF(ISBLANK('Base 2-Yr (US)'!E2),"","X") -> X | D4: =IF(ISBLANK('Base 2-Yr (US)'!$E18), "","X") | E4: =IF(ISBLANK('Base 2-Yr (US)'!$E34), "","X") | F4: =IF(ISBLANK('Base 2-Yr (US)'!$E50), "","X") -> X | G4: =IF(ISBLANK('Base 2-Yr (US)'!$E66),"","X") -> X | H4: =IF(ISBLANK('Base 2-Yr (US)'!$E73), "","X") | I4: =IF(ISBLANK('Base 2-Yr (US)'!$E80), "","X") | J4: =IF(ISBLANK('Base 2-Yr (US)'!$E87), "","X") -> X | K4: =IF(ISBLANK('Base 2-Yr (US)'!$E94), "","X") | L4: =IF(ISBLANK('Base 2-Yr (US)'!$E101), "","X") | M4: =IF(ISBLANK('Base 2-Yr (US)'!$E108), "","X") | N4: =IF(ISBLANK('Base 2-Yr (US)'!$E115), "","X") | O4: =IF(ISBLANK('Base 2-Yr (US)'!$E122), "","X") -> X | P4: =IF(ISBLANK('Base 2-Yr (US)'!$E129), "","X") | Q4: =IF(ISBLANK('Base 2-Yr (US)'!$E136), "","X") | R4: =IF(ISBLANK('Base 2-Yr (US)'!$E143), "","X") -> X | S4: =IF(ISBLANK('Base 2-Yr (US)'!$E150), "","X") -> X | T4: =IF(ISBLANK('Base 2-Yr (US)'!$E162), "","X") | U4: =IF(ISBLANK('Base 2-Yr (US)'!$E174), "","X") | V4: =IF(ISBLANK('Base 2-Yr (US)'!$E186), "","X") -> X | X4: Accenture Federal Services LLC (G) | Y4: =IF(ISBLANK('Base 2-Yr (Non-US)'!$E2),"","X") -> X | Z4: =IF(ISBLANK('Base 2-Yr (Non-US)'!$E18), "","X") | AA4: =IF(ISBLANK('Base 2-Yr (Non-US)'!$E34), "","X") | AB4: =IF(ISBLANK('Base 2-Yr (Non-US)'!$E50), "","X") -> X | AC4: =IF(ISBLANK('Base 2-Yr (Non-US)'!$E66),"","X") -> X | AD4: =IF(ISBLANK('Base 2-Yr (Non-US)'!$E73), "","X") | AE4: =IF(ISBLANK('Base 2-Yr (Non-US)'!$E80), "","X") | AF4: =IF(ISBLANK('Base 2-Yr (Non-US)'!$E87), "","X") -> X | AG4: =IF(ISBLANK('Base 2-Yr (Non-US)'!$E94), "","X") | AH4: =IF(ISBLANK('Base 2-Yr (Non-US)'!$E101), "","X") | AI4: =IF(ISBLANK('Base 2-Yr (Non-US)'!$E108), "","X") | AJ4: =IF(ISBLANK('Base 2-Yr (Non-US)'!$E115), "","X") | AK4: =IF(ISBLANK('Base 2-Yr (Non-US)'!$E122), "","X") -> X | AL4: =IF(ISBLANK('Base 2-Yr (Non-US)'!$E129), "","X") | AM4: =IF(ISBLANK('Base 2-Yr (Non-US)'!$E136), "","X") | AN4: =IF(ISBLANK('Base 2-Yr (Non-US)'!$E143), "","X") -> X | AO4: =IF(ISBLANK('Base 2-Yr (Non-US)'!$E150), "","X") -> X | AP4: =IF(ISBLANK('Base 2-Yr (Non-US)'!$E162), "","X") | AQ4: =IF(ISBLANK('Base 2-Yr (Non-US)'!$E174), "","X") | AR4: =IF(ISBLANK('Base 2-Yr (Non-US)'!$E186), "","X") -> X
A5: Accenture Federal Services LLC (365) | C5: =IF((ISBLANK('Base 2-Yr (US)'!F2)),"","X") | D5: =IF(ISBLANK('Base 2-Yr (US)'!$F18), "","X") -> X | E5: =IF(ISBLANK('Base 2-Yr (US)'!$F34), "","X") | F5: =IF(ISBLANK('Base 2-Yr (US)'!$F50), "","X") | G5: =IF((ISBLANK('Base 2-Yr (US)'!$F66)),"","X") | H5: =IF(ISBLANK('Base 2-Yr (US)'!$F73), "","X") -> X | I5: =IF(ISBLANK('Base 2-Yr (US)'!$F80), "","X") | J5: =IF(ISBLANK('Base 2-Yr (US)'!$F87), "","X") | K5: =IF(ISBLANK('Base 2-Yr (US)'!$F94), "","X") | L5: =IF(ISBLANK('Base 2-Yr (US)'!$F101), "","X") | M5: =IF(ISBLANK('Base 2-Yr (US)'!$F108), "","X") | N5: =IF(ISBLANK('Base 2-Yr (US)'!$F115), "","X") | O5: =IF(ISBLANK('Base 2-Yr (US)'!$F122), "","X") | P5: =IF(ISBLANK('Base 2-Yr (US)'!$F129), "","X") -> X | Q5: =IF(ISBLANK('Base 2-Yr (US)'!$F136), "","X") | R5: =IF(ISBLANK('Base 2-Yr (US)'!$F143), "","X") | S5: =IF(ISBLANK('Base 2-Yr (US)'!$F150), "","X") | T5: =IF(ISBLANK('Base 2-Yr (US)'!$F162), "","X") -> X | U5: =IF(ISBLANK('Base 2-Yr (US)'!$F174), "","X") | V5: =IF(ISBLANK('Base 2-Yr (US)'!$F186), "","X") | X5: Accenture Federal Services LLC (365) | Y5: =IF((ISBLANK('Base 2-Yr (Non-US)'!$F2)),"","X") -> X | Z5: =IF(ISBLANK('Base 2-Yr (Non-US)'!$F18), "","X") | AA5: =IF(ISBLANK('Base 2-Yr (Non-US)'!$F34), "","X") | AB5: =IF(ISBLANK('Base 2-Yr (Non-US)'!$F50), "","X") -> X | AC5: =IF((ISBLANK('Base 2-Yr (Non-US)'!$F66)),"","X") | AD5: =IF(ISBLANK('Base 2-Yr (Non-US)'!$F73), "","X") | AE5: =IF(ISBLANK('Base 2-Yr (Non-US)'!$F80), "","X") | AF5: =IF(ISBLANK('Base 2-Yr (Non-US)'!$F87), "","X") -> X | AG5: =IF(ISBLANK('Base 2-Yr (Non-US)'!$F94), "","X") | AH5: =IF(ISBLANK('Base 2-Yr (Non-US)'!$F101), "","X") | AI5: =IF(ISBLANK('Base 2-Yr (Non-US)'!$F108), "","X") | AJ5: =IF(ISBLANK('Base 2-Yr (Non-US)'!$F115), "","X") | AK5: =IF(ISBLANK('Base 2-Yr (Non-US)'!$F122), "","X") -> X | AL5: =IF(ISBLANK('Base 2-Yr (Non-US)'!$F129), "","X") | AM5: =IF(ISBLANK('Base 2-Yr (Non-US)'!$F136), "","X") | AN5: =IF(ISBLANK('Base 2-Yr (Non-US)'!$F143), "","X") -> X | AO5: =IF(ISBLANK('Base 2-Yr (Non-US)'!$F150), "","X") -> X | AP5: =IF(ISBLANK('Base 2-Yr (Non-US)'!$F162), "","X") | AQ5: =IF(ISBLANK('Base 2-Yr (Non-US)'!$F174), "","X") | AR5: =IF(ISBLANK('Base 2-Yr (Non-US)'!$F186), "","X") -> X
A6: Autonomic Resources LLC (EX) | C6: =IF(ISBLANK('Base 2-Yr (US)'!$G2), "","X") -> X | D6: =IF(ISBLANK('Base 2-Yr (US)'!$G18), "","X") -> X | E6: =IF(ISBLANK('Base 2-Yr (US)'!$G34), "","X") | F6: =IF(ISBLANK('Base 2-Yr (US)'!$G50), "","X") | G6: =IF(ISBLANK('Base 2-Yr (US)'!$G66), "","X") | H6: =IF(ISBLANK('Base 2-Yr (US)'!$G73), "","X") | I6: =IF(ISBLANK('Base 2-Yr (US)'!$G80), "","X") | J6: =IF(ISBLANK('Base 2-Yr (US)'!$G87), "","X") | K6: =IF(ISBLANK('Base 2-Yr (US)'!$G94), "","X") -> X | L6: =IF(ISBLANK('Base 2-Yr (US)'!$G101), "","X") -> X | M6: =IF(ISBLANK('Base 2-Yr (US)'!$G108), "","X") | N6: =IF(ISBLANK('Base 2-Yr (US)'!$G115), "","X") | O6: =IF(ISBLANK('Base 2-Yr (US)'!$G122), "","X") -> X | P6: =IF(ISBLANK('Base 2-Yr (US)'!$G129), "","X") -> X | Q6: =IF(ISBLANK('Base 2-Yr (US)'!$G136), "","X") | R6: =IF(ISBLANK('Base 2-Yr (US)'!$G143), "","X") | S6: =IF(ISBLANK('Base 2-Yr (US)'!$G150), "","X") -> X | T6: =IF(ISBLANK('Base 2-Yr (US)'!$G162), "","X") -> X | U6: =IF(ISBLANK('Base 2-Yr (US)'!$G174), "","X") | V6: =IF(ISBLANK('Base 2-Yr (US)'!$G186), "","X") | X6: Autonomic Resources LLC (EX) | Y6: =IF(ISBLANK('Base 2-Yr (Non-US)'!$G2), "","X") | Z6: =IF(ISBLANK('Base 2-Yr (Non-US)'!$G18), "","X") | AA6: =IF(ISBLANK('Base 2-Yr (Non-US)'!$G34), "","X") | AB6: =IF(ISBLANK('Base 2-Yr (Non-US)'!$G50), "","X") | AC6: =IF(ISBLANK('Base 2-Yr (Non-US)'!$G66), "","X") | AD6: =IF(ISBLANK('Base 2-Yr (Non-US)'!$G73), "","X") | AE6: =IF(ISBLANK('Base 2-Yr (Non-US)'!$G80), "","X") | AF6: =IF(ISBLANK('Base 2-Yr (Non-US)'!$G87), "","X") | AG6: =IF(ISBLANK('Base 2-Yr (Non-US)'!$G94), "","X") | AH6: =IF(ISBLANK('Base 2-Yr (Non-US)'!$G101), "","X") | AI6: =IF(ISBLANK('Base 2-Yr (Non-US)'!$G108), "","X") | AJ6: =IF(ISBLANK('Base 2-Yr (Non-US)'!$G115), "","X") | AK6: =IF(ISBLANK('Base 2-Yr (Non-US)'!$G122), "","X") | AL6: =IF(ISBLANK('Base 2-Yr (Non-US)'!$G129), "","X") | AM6: =IF(ISBLANK('Base 2-Yr (Non-US)'!$G136), "","X") | AN6: =IF(ISBLANK('Base 2-Yr (Non-US)'!$G143), "","X") | AO6: =IF(ISBLANK('Base 2-Yr (Non-US)'!$G150), "","X") | AP6: =IF(ISBLANK('Base 2-Yr (Non-US)'!$G162), "","X") | AQ6: =IF(ISBLANK('Base 2-Yr (Non-US)'!$G174), "","X") | AR6: =IF(ISBLANK('Base 2-Yr (Non-US)'!$G186), "","X")
A7: CGI Federal Inc. (Z) | C7: =IF(ISBLANK('Base 2-Yr (US)'!$H2), "","X") -> X | D7: =IF(ISBLANK('Base 2-Yr (US)'!$H18), "","X") -> X | E7: =IF(ISBLANK('Base 2-Yr (US)'!$H34), "","X") | F7: =IF(ISBLANK('Base 2-Yr (US)'!$H50), "","X") | G7: =IF(ISBLANK('Base 2-Yr (US)'!$H66), "","X") -> X | H7: =IF(ISBLANK('Base 2-Yr (US)'!$H73), "","X") -> X | I7: =IF(ISBLANK('Base 2-Yr (US)'!$H80), "","X") | J7: =IF(ISBLANK('Base 2-Yr (US)'!$H87), "","X") | K7: =IF(ISBLANK('Base 2-Yr (US)'!$H94), "","X") -> X | L7: =IF(ISBLANK('Base 2-Yr (US)'!$H101), "","X") -> X | M7: =IF(ISBLANK('Base 2-Yr (US)'!$H108), "","X") | N7: =IF(ISBLANK('Base 2-Yr (US)'!$H115), "","X") | O7: =IF(ISBLANK('Base 2-Yr (US)'!$H122), "","X") -> X | P7: =IF(ISBLANK('Base 2-Yr (US)'!$H129), "","X") -> X | Q7: =IF(ISBLANK('Base 2-Yr (US)'!$H136), "","X") | R7: =IF(ISBLANK('Base 2-Yr (US)'!$H143), "","X") | S7: =IF(ISBLANK('Base 2-Yr (US)'!$H150), "","X") -> X | T7: =IF(ISBLANK('Base 2-Yr (US)'!$H162), "","X") -> X | U7: =IF(ISBLANK('Base 2-Yr (US)'!$H174), "","X") | V7: =IF(ISBLANK('Base 2-Yr (US)'!$H186), "","X") | X7: CGI Federal Inc. (Z) | Y7: =IF(ISBLANK('Base 2-Yr (Non-US)'!$H2), "","X") | Z7: =IF(ISBLANK('Base 2-Yr (Non-US)'!$H18), "","X") | AA7: =IF(ISBLANK('Base 2-Yr (Non-US)'!$H34), "","X") | AB7: =IF(ISBLANK('Base 2-Yr (Non-US)'!$H50), "","X") | AC7: =IF(ISBLANK('Base 2-Yr (Non-US)'!$H66), "","X") | AD7: =IF(ISBLANK('Base 2-Yr (Non-US)'!$H73), "","X") | AE7: =IF(ISBLANK('Base 2-Yr (Non-US)'!$H80), "","X") | AF7: =IF(ISBLANK('Base 2-Yr (Non-US)'!$H87), "","X") | AG7: =IF(ISBLANK('Base 2-Yr (Non-US)'!$H94), "","X") | AH7: =IF(ISBLANK('Base 2-Yr (Non-US)'!$H101), "","X") | AI7: =IF(ISBLANK('Base 2-Yr (Non-US)'!$H108), "","X") | AJ7: =IF(ISBLANK('Base 2-Yr (Non-US)'!$H115), "","X") | AK7: =IF(ISBLANK('Base 2-Yr (Non-US)'!$H122), "","X") | AL7: =IF(ISBLANK('Base 2-Yr (Non-US)'!$H129), "","X") | AM7: =IF(ISBLANK('Base 2-Yr (Non-US)'!$H136), "","X") | AN7: =IF(ISBLANK('Base 2-Yr (Non-US)'!$H143), "","X") | AO7: =IF(ISBLANK('Base 2-Yr (Non-US)'!$H150), "","X") | AP7: =IF(ISBLANK('Base 2-Yr (Non-US)'!$H162), "","X") | AQ7: =IF(ISBLANK('Base 2-Yr (Non-US)'!$H174), "","X") | AR7: =IF(ISBLANK('Base 2-Yr (Non-US)'!$H186), "","X")
A8: Ciracom Inc. (EX) | C8: =IF(ISBLANK('Base 2-Yr (US)'!$I2), "","X") -> X | D8: =IF(ISBLANK('Base 2-Yr (US)'!$I18), "","X") | E8: =IF(ISBLANK('Base 2-Yr (US)'!$I34), "","X") | F8: =IF(ISBLANK('Base 2-Yr (US)'!$I50), "","X") -> X | G8: =IF(ISBLANK('Base 2-Yr (US)'!$I66), "","X") | H8: =IF(ISBLANK('Base 2-Yr (US)'!$I73), "","X") | I8: =IF(ISBLANK('Base 2-Yr (US)'!$I80), "","X") | J8: =IF(ISBLANK('Base 2-Yr (US)'!$I87), "","X") | K8: =IF(ISBLANK('Base 2-Yr (US)'!$I94), "","X") | L8: =IF(ISBLANK('Base 2-Yr (US)'!$I101), "","X") | M8: =IF(ISBLANK('Base 2-Yr (US)'!$I108), "","X") | N8: =IF(ISBLANK('Base 2-Yr (US)'!$I115), "","X") | O8: =IF(ISBLANK('Base 2-Yr (US)'!$I122), "","X") -> X | P8: =IF(ISBLANK('Base 2-Yr (US)'!$I129), "","X") | Q8: =IF(ISBLANK('Base 2-Yr (US)'!$I136), "","X") | R8: =IF(ISBLANK('Base 2-Yr (US)'!$I143), "","X") -> X | S8: =IF(ISBLANK('Base 2-Yr (US)'!$I150), "","X") -> X | T8: =IF(ISBLANK('Base 2-Yr (US)'!$I162), "","X") | U8: =IF(ISBLANK('Base 2-Yr (US)'!$I174), "","X") | V8: =IF(ISBLANK('Base 2-Yr (US)'!$I186), "","X") -> X | X8: Ciracom Inc. (EX) | Y8: =IF(ISBLANK('Base 2-Yr (Non-US)'!$I2), "","X") | Z8: =IF(ISBLANK('Base 2-Yr (Non-US)'!$I18), "","X") | AA8: =IF(ISBLANK('Base 2-Yr (Non-US)'!$I34), "","X") | AB8: =IF(ISBLANK('Base 2-Yr (Non-US)'!$I50), "","X") | AC8: =IF(ISBLANK('Base 2-Yr (Non-US)'!$I66), "","X") | AD8: =IF(ISBLANK('Base 2-Yr (Non-US)'!$I73), "","X") | AE8: =IF(ISBLANK('Base 2-Yr (Non-US)'!$I80), "","X") | AF8: =IF(ISBLANK('Base 2-Yr (Non-US)'!$I87), "","X") | AG8: =IF(ISBLANK('Base 2-Yr (Non-US)'!$I94), "","X") | AH8: =IF(ISBLANK('Base 2-Yr (Non-US)'!$I101), "","X") | AI8: =IF(ISBLANK('Base 2-Yr (Non-US)'!$I108), "","X") | AJ8: =IF(ISBLANK('Base 2-Yr (Non-US)'!$I115), "","X") | AK8: =IF(ISBLANK('Base 2-Yr (Non-US)'!$I122), "","X") | AL8: =IF(ISBLANK('Base 2-Yr (Non-US)'!$I129), "","X") | AM8: =IF(ISBLANK('Base 2-Yr (Non-US)'!$I136), "","X") | AN8: =IF(ISBLANK('Base 2-Yr (Non-US)'!$I143), "","X") | AO8: =IF(ISBLANK('Base 2-Yr (Non-US)'!$I150), "","X") | AP8: =IF(ISBLANK('Base 2-Yr (Non-US)'!$I162), "","X") | AQ8: =IF(ISBLANK('Base 2-Yr (Non-US)'!$I174), "","X") | AR8: =IF(ISBLANK('Base 2-Yr (Non-US)'!$I186), "","X")
A9: Computer Sciences Corporation (G) | C9: =IF(ISBLANK('Base 2-Yr (US)'!$J2), "","X") -> X | D9: =IF(ISBLANK('Base 2-Yr (US)'!$J18), "","X") | E9: =IF(ISBLANK('Base 2-Yr (US)'!$J34), "","X") | F9: =IF(ISBLANK('Base 2-Yr (US)'!$J50), "","X") -> X | G9: =IF(ISBLANK('Base 2-Yr (US)'!$J66), "","X") -> X | H9: =IF(ISBLANK('Base 2-Yr (US)'!$J73), "","X") | I9: =IF(ISBLANK('Base 2-Yr (US)'!$J80), "","X") | J9: =IF(ISBLANK('Base 2-Yr (US)'!$J87), "","X") -> X | K9: =IF(ISBLANK('Base 2-Yr (US)'!$J94), "","X") | L9: =IF(ISBLANK('Base 2-Yr (US)'!$J101), "","X") | M9: =IF(ISBLANK('Base 2-Yr (US)'!$J108), "","X") | N9: =IF(ISBLANK('Base 2-Yr (US)'!$J115), "","X") | O9: =IF(ISBLANK('Base 2-Yr (US)'!$J122), "","X") -> X | P9: =IF(ISBLANK('Base 2-Yr (US)'!$J129), "","X") | Q9: =IF(ISBLANK('Base 2-Yr (US)'!$J136), "","X") | R9: =IF(ISBLANK('Base 2-Yr (US)'!$J143), "","X") -> X | S9: =IF(ISBLANK('Base 2-Yr (US)'!$J150), "","X") -> X | T9: =IF(ISBLANK('Base 2-Yr (US)'!$J162), "","X") | U9: =IF(ISBLANK('Base 2-Yr (US)'!$J174), "","X") | V9: =IF(ISBLANK('Base 2-Yr (US)'!$J186), "","X") -> X | X9: Computer Sciences Corporation (G) | Y9: =IF(ISBLANK('Base 2-Yr (Non-US)'!$J2), "","X") -> X | Z9: =IF(ISBLANK('Base 2-Yr (Non-US)'!$J18), "","X") | AA9: =IF(ISBLANK('Base 2-Yr (Non-US)'!$J34), "","X") | AB9: =IF(ISBLANK('Base 2-Yr (Non-US)'!$J50), "","X") -> X | AC9: =IF(ISBLANK('Base 2-Yr (Non-US)'!$J66), "","X") -> X | AD9: =IF(ISBLANK('Base 2-Yr (Non-US)'!$J73), "","X") | AE9: =IF(ISBLANK('Base 2-Yr (Non-US)'!$J80), "","X") | AF9: =IF(ISBLANK('Base 2-Yr (Non-US)'!$J87), "","X") -> X | AG9: =IF(ISBLANK('Base 2-Yr (Non-US)'!$J94), "","X") | AH9: =IF(ISBLANK('Base 2-Yr (Non-US)'!$J101), "","X") | AI9: =IF(ISBLANK('Base 2-Yr (Non-US)'!$J108), "","X") | AJ9: =IF(ISBLANK('Base 2-Yr (Non-US)'!$J115), "","X") | AK9: =IF(ISBLANK('Base 2-Yr (Non-US)'!$J122), "","X") -> X | AL9: =IF(ISBLANK('Base 2-Yr (Non-US)'!$J129), "","X") | AM9: =IF(ISBLANK('Base 2-Yr (Non-US)'!$J136), "","X") | AN9: =IF(ISBLANK('Base 2-Yr (Non-US)'!$J143), "","X") -> X | AO9: =IF(ISBLANK('Base 2-Yr (Non-US)'!$J150), "","X") -> X | AP9: =IF(ISBLANK('Base 2-Yr (Non-US)'!$J162), "","X") | AQ9: =IF(ISBLANK('Base 2-Yr (Non-US)'!$J174), "","X") | AR9: =IF(ISBLANK('Base 2-Yr (Non-US)'!$J186), "","X") -> X
A10: Computer Sciences Corporation (EX) | C10: =IF(ISBLANK('Base 2-Yr (US)'!$K2), "","X") | D10: =IF(ISBLANK('Base 2-Yr (US)'!$K18), "","X") -> X | E10: =IF(ISBLANK('Base 2-Yr (US)'!$K34), "","X") -> X | F10: =IF(ISBLANK('Base 2-Yr (US)'!$K50), "","X") | G10: =IF(ISBLANK('Base 2-Yr (US)'!$K66), "","X") | H10: =IF(ISBLANK('Base 2-Yr (US)'!$K73), "","X") -> X | I10: =IF(ISBLANK('Base 2-Yr (US)'!$K80), "","X") -> X | J10: =IF(ISBLANK('Base 2-Yr (US)'!$K87), "","X") | K10: =IF(ISBLANK('Base 2-Yr (US)'!$K94), "","X") | L10: =IF(ISBLANK('Base 2-Yr (US)'!$K101), "","X") -> X | M10: =IF(ISBLANK('Base 2-Yr (US)'!$K108), "","X") -> X | N10: =IF(ISBLANK('Base 2-Yr (US)'!$K115), "","X") | O10: =IF(ISBLANK('Base 2-Yr (US)'!$K122), "","X") | P10: =IF(ISBLANK('Base 2-Yr (US)'!$K129), "","X") -> X | Q10: =IF(ISBLANK('Base 2-Yr (US)'!$K136), "","X") -> X | R10: =IF(ISBLANK('Base 2-Yr (US)'!$K143), "","X") | S10: =IF(ISBLANK('Base 2-Yr (US)'!$K150), "","X") | T10: =IF(ISBLANK('Base 2-Yr (US)'!$K162), "","X") -> X | U10: =IF(ISBLANK('Base 2-Yr (US)'!$K174), "","X") -> X | V10: =IF(ISBLANK('Base 2-Yr (US)'!$K186), "","X") | X10: Computer Sciences Corporation (EX) | Y10: =IF(ISBLANK('Base 2-Yr (Non-US)'!$K2), "","X") | Z10: =IF(ISBLANK('Base 2-Yr (Non-US)'!$K18), "","X") | AA10: =IF(ISBLANK('Base 2-Yr (Non-US)'!$K34), "","X") | AB10: =IF(ISBLANK('Base 2-Yr (Non-US)'!$K50), "","X") | AC10: =IF(ISBLANK('Base 2-Yr (Non-US)'!$K66), "","X") | AD10: =IF(ISBLANK('Base 2-Yr (Non-US)'!$K73), "","X") | AE10: =IF(ISBLANK('Base 2-Yr (Non-US)'!$K80), "","X") | AF10: =IF(ISBLANK('Base 2-Yr (Non-US)'!$K87), "","X") | AG10: =IF(ISBLANK('Base 2-Yr (Non-US)'!$K94), "","X") | AH10: =IF(ISBLANK('Base 2-Yr (Non-US)'!$K101), "","X") | AI10: =IF(ISBLANK('Base 2-Yr (Non-US)'!$K108), "","X") | AJ10: =IF(ISBLANK('Base 2-Yr (Non-US)'!$K115), "","X") | AK10: =IF(ISBLANK('Base 2-Yr (Non-US)'!$K122), "","X") | AL10: =IF(ISBLANK('Base 2-Yr (Non-US)'!$K129), "","X") | AM10: =IF(ISBLANK('Base 2-Yr (Non-US)'!$K136), "","X") | AN10: =IF(ISBLANK('Base 2-Yr (Non-US)'!$K143), "","X") | AO10: =IF(ISBLANK('Base 2-Yr (Non-US)'!$K150), "","X") | AP10: =IF(ISBLANK('Base 2-Yr (Non-US)'!$K162), "","X") | AQ10: =IF(ISBLANK('Base 2-Yr (Non-US)'!$K174), "","X") | AR10: =IF(ISBLANK('Base 2-Yr (Non-US)'!$K186), "","X")
A11: Dell Federal Systems L.P. (365) | C11: =IF(ISBLANK('Base 2-Yr (US)'!$L2), "","X") | D11: =IF(ISBLANK('Base 2-Yr (US)'!$L18), "","X") -> X | E11: =IF(ISBLANK('Base 2-Yr (US)'!$L34), "","X") | F11: =IF(ISBLANK('Base 2-Yr (US)'!$L50), "","X") -> X | G11: =IF(ISBLANK('Base 2-Yr (US)'!$L66), "","X") | H11: =IF(ISBLANK('Base 2-Yr (US)'!$L73), "","X") -> X | I11: =IF(ISBLANK('Base 2-Yr (US)'!$L80), "","X") | J11: =IF(ISBLANK('Base 2-Yr (US)'!$L87), "","X") -> X | K11: =IF(ISBLANK('Base 2-Yr (US)'!$L94), "","X") | L11: =IF(ISBLANK('Base 2-Yr (US)'!$L101), "","X") | M11: =IF(ISBLANK('Base 2-Yr (US)'!$L108), "","X") | N11: =IF(ISBLANK('Base 2-Yr (US)'!$L115), "","X") | O11: =IF(ISBLANK('Base 2-Yr (US)'!$L122), "","X") | P11: =IF(ISBLANK('Base 2-Yr (US)'!$L129), "","X") -> X | Q11: =IF(ISBLANK('Base 2-Yr (US)'!$L136), "","X") | R11: =IF(ISBLANK('Base 2-Yr (US)'!$L143), "","X") -> X | S11: =IF(ISBLANK('Base 2-Yr (US)'!$L150), "","X") | T11: =IF(ISBLANK('Base 2-Yr (US)'!$L162), "","X") -> X | U11: =IF(ISBLANK('Base 2-Yr (US)'!$L174), "","X") | V11: =IF(ISBLANK('Base 2-Yr (US)'!$L186), "","X") -> X | X11: Dell Federal Systems L.P. (365) | Y11: =IF(ISBLANK('Base 2-Yr (Non-US)'!$L2), "","X") | Z11: =IF(ISBLANK('Base 2-Yr (Non-US)'!$L18), "","X") -> X | AA11: =IF(ISBLANK('Base 2-Yr (Non-US)'!$L34), "","X") | AB11: =IF(ISBLANK('Base 2-Yr (Non-US)'!$L50), "","X") -> X | AC11: =IF(ISBLANK('Base 2-Yr (Non-US)'!$L66), "","X") | AD11: =IF(ISBLANK('Base 2-Yr (Non-US)'!$L73), "","X") -> X | AE11: =IF(ISBLANK('Base 2-Yr (Non-US)'!$L80), "","X") | AF11: =IF(ISBLANK('Base 2-Yr (Non-US)'!$L87), "","X") -> X | AG11: =IF(ISBLANK('Base 2-Yr (Non-US)'!$L94), "","X") | AH11: =IF(ISBLANK('Base 2-Yr (Non-US)'!$L101), "","X") | AI11: =IF(ISBLANK('Base 2-Yr (Non-US)'!$L108), "","X") | AJ11: =IF(ISBLANK('Base 2-Yr (Non-US)'!$L115), "","X") | AK11: =IF(ISBLANK('Base 2-Yr (Non-US)'!$L122), "","X") | AL11: =IF(ISBLANK('Base 2-Yr (Non-US)'!$L129), "","X") -> X | AM11: =IF(ISBLANK('Base 2-Yr (Non-US)'!$L136), "","X") | AN11: =IF(ISBLANK('Base 2-Yr (Non-US)'!$L143), "","X") -> X | AO11: =IF(ISBLANK('Base 2-Yr (Non-US)'!$L150), "","X") | AP11: =IF(ISBLANK('Base 2-Yr (Non-US)'!$L162), "","X") -> X | AQ11: =IF(ISBLANK('Base 2-Yr (Non-US)'!$L174), "","X") | AR11: =IF(ISBLANK('Base 2-Yr (Non-US)'!$L186), "","X") -> X
A12: DLT Solutions, LLC (G) | C12: =IF(ISBLANK('Base 2-Yr (US)'!$M2), "","X") -> X | D12: =IF(ISBLANK('Base 2-Yr (US)'!$M18), "","X") | E12: =IF(ISBLANK('Base 2-Yr (US)'!$M34), "","X") | F12: =IF(ISBLANK('Base 2-Yr (US)'!$M50), "","X") -> X | G12: =IF(ISBLANK('Base 2-Yr (US)'!$M66), "","X") -> X | H12: =IF(ISBLANK('Base 2-Yr (US)'!$M73), "","X") | I12: =IF(ISBLANK('Base 2-Yr (US)'!$M80), "","X") | J12: =IF(ISBLANK('Base 2-Yr (US)'!$M87), "","X") -> X | K12: =IF(ISBLANK('Base 2-Yr (US)'!$M94), "","X") | L12: =IF(ISBLANK('Base 2-Yr (US)'!$M101), "","X") | M12: =IF(ISBLANK('Base 2-Yr (US)'!$M108), "","X") | N12: =IF(ISBLANK('Base 2-Yr (US)'!$M115), "","X") | O12: =IF(ISBLANK('Base 2-Yr (US)'!$M122), "","X") -> X | P12: =IF(ISBLANK('Base 2-Yr (US)'!$M129), "","X") | Q12: =IF(ISBLANK('Base 2-Yr (US)'!$M136), "","X") | R12: =IF(ISBLANK('Base 2-Yr (US)'!$M143), "","X") -> X | S12: =IF(ISBLANK('Base 2-Yr (US)'!$M150), "","X") -> X | T12: =IF(ISBLANK('Base 2-Yr (US)'!$M162), "","X") | U12: =IF(ISBLANK('Base 2-Yr (US)'!$M174), "","X") | V12: =IF(ISBLANK('Base 2-Yr (US)'!$M186), "","X") -> X | X12: DLT Solutions, LLC (G) | Y12: =IF(ISBLANK('Base 2-Yr (Non-US)'!$M2), "","X") -> X | Z12: =IF(ISBLANK('Base 2-Yr (Non-US)'!$M18), "","X") | AA12: =IF(ISBLANK('Base 2-Yr (Non-US)'!$M34), "","X") | AB12: =IF(ISBLANK('Base 2-Yr (Non-US)'!$M50), "","X") -> X | AC12: =IF(ISBLANK('Base 2-Yr (Non-US)'!$M66), "","X") -> X | AD12: =IF(ISBLANK('Base 2-Yr (Non-US)'!$M73), "","X") | AE12: =IF(ISBLANK('Base 2-Yr (Non-US)'!$M80), "","X") | AF12: =IF(ISBLANK('Base 2-Yr (Non-US)'!$M87), "","X") -> X | AG12: =IF(ISBLANK('Base 2-Yr (Non-US)'!$M94), "","X") | AH12: =IF(ISBLANK('Base 2-Yr (Non-US)'!$M101), "","X") | AI12: =IF(ISBLANK('Base 2-Yr (Non-US)'!$M108), "","X") | AJ12: =IF(ISBLANK('Base 2-Yr (Non-US)'!$M115), "","X") | AK12: =IF(ISBLANK('Base 2-Yr (Non-US)'!$M122), "","X") -> X | AL12: =IF(ISBLANK('Base 2-Yr (Non-US)'!$M129), "","X") | AM12: =IF(ISBLANK('Base 2-Yr (Non-US)'!$M136), "","X") | AN12: =IF(ISBLANK('Base 2-Yr (Non-US)'!$M143), "","X") -> X | AO12: =IF(ISBLANK('Base 2-Yr (Non-US)'!$M150), "","X") -> X | AP12: =IF(ISBLANK('Base 2-Yr (Non-US)'!$M162), "","X") | AQ12: =IF(ISBLANK('Base 2-Yr (Non-US)'!$M174), "","X") | AR12: =IF(ISBLANK('Base 2-Yr (Non-US)'!$M186), "","X") -> X
A13: General Dynamics Information Technology, Inc. (Z) | C13: =IF(ISBLANK('Base 2-Yr (US)'!$N2), "","X") -> X | D13: =IF(ISBLANK('Base 2-Yr (US)'!$N18), "","X") -> X | E13: =IF(ISBLANK('Base 2-Yr (US)'!$N34), "","X") -> X | F13: =IF(ISBLANK('Base 2-Yr (US)'!$N50), "","X") -> X | G13: =IF(ISBLANK('Base 2-Yr (US)'!$N66), "","X") -> X | H13: =IF(ISBLANK('Base 2-Yr (US)'!$N73), "","X") -> X | I13: =IF(ISBLANK('Base 2-Yr (US)'!$N80), "","X") -> X | J13: =IF(ISBLANK('Base 2-Yr (US)'!$N87), "","X") -> X | K13: =IF(ISBLANK('Base 2-Yr (US)'!$N94), "","X") -> X | L13: =IF(ISBLANK('Base 2-Yr (US)'!$N101), "","X") -> X | M13: =IF(ISBLANK('Base 2-Yr (US)'!$N108), "","X") -> X | N13: =IF(ISBLANK('Base 2-Yr (US)'!$N115), "","X") -> X | O13: =IF(ISBLANK('Base 2-Yr (US)'!$N122), "","X") -> X | P13: =IF(ISBLANK('Base 2-Yr (US)'!$N129), "","X") -> X | Q13: =IF(ISBLANK('Base 2-Yr (US)'!$N136), "","X") -> X | R13: =IF(ISBLANK('Base 2-Yr (US)'!$N143), "","X") -> X | S13: =IF(ISBLANK('Base 2-Yr (US)'!$N150), "","X") -> X | T13: =IF(ISBLANK('Base 2-Yr (US)'!$N162), "","X") -> X | U13: =IF(ISBLANK('Base 2-Yr (US)'!$N174), "","X") -> X | V13: =IF(ISBLANK('Base 2-Yr (US)'!$N186), "","X") -> X | X13: General Dynamics Information Technology, Inc. (Z) | Y13: =IF(ISBLANK('Base 2-Yr (Non-US)'!$N2), "","X") | Z13: =IF(ISBLANK('Base 2-Yr (Non-US)'!$N18), "","X") | AA13: =IF(ISBLANK('Base 2-Yr (Non-US)'!$N34), "","X") | AB13: =IF(ISBLANK('Base 2-Yr (Non-US)'!$N50), "","X") | AC13: =IF(ISBLANK('Base 2-Yr (Non-US)'!$N66), "","X") | AD13: =IF(ISBLANK('Base 2-Yr (Non-US)'!$N73), "","X") | AE13: =IF(ISBLANK('Base 2-Yr (Non-US)'!$N80), "","X") | AF13: =IF(ISBLANK('Base 2-Yr (Non-US)'!$N87), "","X") | AG13: =IF(ISBLANK('Base 2-Yr (Non-US)'!$N94), "","X") | AH13: =IF(ISBLANK('Base 2-Yr (Non-US)'!$N101), "","X") | AI13: =IF(ISBLANK('Base 2-Yr (Non-US)'!$N108), "","X") | AJ13: =IF(ISBLANK('Base 2-Yr (Non-US)'!$N115), "","X") | AK13: =IF(ISBLANK('Base 2-Yr (Non-US)'!$N122), "","X") | AL13: =IF(ISBLANK('Base 2-Yr (Non-US)'!$N129), "","X") | AM13: =IF(ISBLANK('Base 2-Yr (Non-US)'!$N136), "","X") | AN13: =IF(ISBLANK('Base 2-Yr (Non-US)'!$N143), "","X") | AO13: =IF(ISBLANK('Base 2-Yr (Non-US)'!$N150), "","X") | AP13: =IF(ISBLANK('Base 2-Yr (Non-US)'!$N162), "","X") | AQ13: =IF(ISBLANK('Base 2-Yr (Non-US)'!$N174), "","X") | AR13: =IF(ISBLANK('Base 2-Yr (Non-US)'!$N186), "","X")
A14: Harris IT Service Corporation (Z) | C14: =IF(ISBLANK('Base 2-Yr (US)'!$O2), "","X") -> X | D14: =IF(ISBLANK('Base 2-Yr (US)'!$O18), "","X") -> X | E14: =IF(ISBLANK('Base 2-Yr (US)'!$O34), "","X") | F14: =IF(ISBLANK('Base 2-Yr (US)'!$O50), "","X") -> X | G14: =IF(ISBLANK('Base 2-Yr (US)'!$O66), "","X") -> X | H14: =IF(ISBLANK('Base 2-Yr (US)'!$O73), "","X") -> X | I14: =IF(ISBLANK('Base 2-Yr (US)'!$O80), "","X") | J14: =IF(ISBLANK('Base 2-Yr (US)'!$O87), "","X") -> X | K14: =IF(ISBLANK('Base 2-Yr (US)'!$O94), "","X") -> X | L14: =IF(ISBLANK('Base 2-Yr (US)'!$O101), "","X") -> X | M14: =IF(ISBLANK('Base 2-Yr (US)'!$O108), "","X") | N14: =IF(ISBLANK('Base 2-Yr (US)'!$O115), "","X") -> X | O14: =IF(ISBLANK('Base 2-Yr (US)'!$O122), "","X") -> X | P14: =IF(ISBLANK('Base 2-Yr (US)'!$O129), "","X") -> X | Q14: =IF(ISBLANK('Base 2-Yr (US)'!$O136), "","X") | R14: =IF(ISBLANK('Base 2-Yr (US)'!$O143), "","X") -> X | S14: =IF(ISBLANK('Base 2-Yr (US)'!$O150), "","X") -> X | T14: =IF(ISBLANK('Base 2-Yr (US)'!$O162), "","X") -> X | U14: =IF(ISBLANK('Base 2-Yr (US)'!$O174), "","X") | V14: =IF(ISBLANK('Base 2-Yr (US)'!$O186), "","X") -> X | X14: Harris IT Service Corporation (Z) | Y14: =IF(ISBLANK('Base 2-Yr (Non-US)'!$O2), "","X") | Z14: =IF(ISBLANK('Base 2-Yr (Non-US)'!$O18), "","X") | AA14: =IF(ISBLANK('Base 2-Yr (Non-US)'!$O34), "","X") | AB14: =IF(ISBLANK('Base 2-Yr (Non-US)'!$O50), "","X") | AC14: =IF(ISBLANK('Base 2-Yr (Non-US)'!$O66), "","X") | AD14: =IF(ISBLANK('Base 2-Yr (Non-US)'!$O73), "","X") | AE14: =IF(ISBLANK('Base 2-Yr (Non-US)'!$O80), "","X") | AF14: =IF(ISBLANK('Base 2-Yr (Non-US)'!$O87), "","X") | AG14: =IF(ISBLANK('Base 2-Yr (Non-US)'!$O94), "","X") | AH14: =IF(ISBLANK('Base 2-Yr (Non-US)'!$O101), "","X") | AI14: =IF(ISBLANK('Base 2-Yr (Non-US)'!$O108), "","X") | AJ14: =IF(ISBLANK('Base 2-Yr (Non-US)'!$O115), "","X") | AK14: =IF(ISBLANK('Base 2-Yr (Non-US)'!$O122), "","X") | AL14: =IF(ISBLANK('Base 2-Yr (Non-US)'!$O129), "","X") | AM14: =IF(ISBLANK('Base 2-Yr (Non-US)'!$O136), "","X") | AN14: =IF(ISBLANK('Base 2-Yr (Non-US)'!$O143), "","X") | AO14: =IF(ISBLANK('Base 2-Yr (Non-US)'!$O150), "","X") | AP14: =IF(ISBLANK('Base 2-Yr (Non-US)'!$O162), "","X") | AQ14: =IF(ISBLANK('Base 2-Yr (Non-US)'!$O174), "","X") | AR14: =IF(ISBLANK('Base 2-Yr (Non-US)'!$O186), "","X")
A15: IBM Global Business Services – U.S. Federal (DOM) | C15: =IF(ISBLANK('Base 2-Yr (US)'!$P2), "","X") -> X | D15: =IF(ISBLANK('Base 2-Yr (US)'!$P18), "","X") -> X | E15: =IF(ISBLANK('Base 2-Yr (US)'!$P34), "","X") -> X | F15: =IF(ISBLANK('Base 2-Yr (US)'!$P50), "","X") | G15: =IF(ISBLANK('Base 2-Yr (US)'!$P66), "","X") -> X | H15: =IF(ISBLANK('Base 2-Yr (US)'!$P73), "","X") -> X | I15: =IF(ISBLANK('Base 2-Yr (US)'!$P80), "","X") -> X | J15: =IF(ISBLANK('Base 2-Yr (US)'!$P87), "","X") | K15: =IF(ISBLANK('Base 2-Yr (US)'!$P94), "","X") -> X | L15: =IF(ISBLANK('Base 2-Yr (US)'!$P101), "","X") -> X | M15: =IF(ISBLANK('Base 2-Yr (US)'!$P108), "","X") -> X | N15: =IF(ISBLANK('Base 2-Yr (US)'!$P115), "","X") | O15: =IF(ISBLANK('Base 2-Yr (US)'!$P122), "","X") -> X | P15: =IF(ISBLANK('Base 2-Yr (US)'!$P129), "","X") -> X | Q15: =IF(ISBLANK('Base 2-Yr (US)'!$P136), "","X") -> X | R15: =IF(ISBLANK('Base 2-Yr (US)'!$P143), "","X") | S15: =IF(ISBLANK('Base 2-Yr (US)'!$P150), "","X") -> X | T15: =IF(ISBLANK('Base 2-Yr (US)'!$P162), "","X") -> X | U15: =IF(ISBLANK('Base 2-Yr (US)'!$P174), "","X") -> X | V15: =IF(ISBLANK('Base 2-Yr (US)'!$P186), "","X") | X15: IBM Global Business Services – U.S. Federal (DOM) | Y15: =IF(ISBLANK('Base 2-Yr (Non-US)'!$P2), "","X") | Z15: =IF(ISBLANK('Base 2-Yr (Non-US)'!$P18), "","X") | AA15: =IF(ISBLANK('Base 2-Yr (Non-US)'!$P34), "","X") | AB15: =IF(ISBLANK('Base 2-Yr (Non-US)'!$P50), "","X") | AC15: =IF(ISBLANK('Base 2-Yr (Non-US)'!$P66), "","X") | AD15: =IF(ISBLANK('Base 2-Yr (Non-US)'!$P73), "","X") | AE15: =IF(ISBLANK('Base 2-Yr (Non-US)'!$P80), "","X") | AF15: =IF(ISBLANK('Base 2-Yr (Non-US)'!$P87), "","X") | AG15: =IF(ISBLANK('Base 2-Yr (Non-US)'!$P94), "","X") | AH15: =IF(ISBLANK('Base 2-Yr (Non-US)'!$P101), "","X") | AI15: =IF(ISBLANK('Base 2-Yr (Non-US)'!$P108), "","X") | AJ15: =IF(ISBLANK('Base 2-Yr (Non-US)'!$P115), "","X") | AK15: =IF(ISBLANK('Base 2-Yr (Non-US)'!$P122), "","X") | AL15: =IF(ISBLANK('Base 2-Yr (Non-US)'!$P129), "","X") | AM15: =IF(ISBLANK('Base 2-Yr (Non-US)'!$P136), "","X") | AN15: =IF(ISBLANK('Base 2-Yr (Non-US)'!$P143), "","X") | AO15: =IF(ISBLANK('Base 2-Yr (Non-US)'!$P150), "","X") | AP15: =IF(ISBLANK('Base 2-Yr (Non-US)'!$P162), "","X") | AQ15: =IF(ISBLANK('Base 2-Yr (Non-US)'!$P174), "","X") | AR15: =IF(ISBLANK('Base 2-Yr (Non-US)'!$P186), "","X")
A16: Lockheed Martin (Z) | C16: =IF(ISBLANK('Base 2-Yr (US)'!$Q2), "","X") -> X | D16: =IF(ISBLANK('Base 2-Yr (US)'!$Q18), "","X") -> X | E16: =IF(ISBLANK('Base 2-Yr (US)'!$Q34), "","X") -> X | F16: =IF(ISBLANK('Base 2-Yr (US)'!$Q50), "","X") -> X | G16: =IF(ISBLANK('Base 2-Yr (US)'!$Q66), "","X") -> X | H16: =IF(ISBLANK('Base 2-Yr (US)'!$Q73), "","X") -> X | I16: =IF(ISBLANK('Base 2-Yr (US)'!$Q80), "","X") -> X | J16: =IF(ISBLANK('Base 2-Yr (US)'!$Q87), "","X") -> X | K16: =IF(ISBLANK('Base 2-Yr (US)'!$Q94), "","X") -> X | L16: =IF(ISBLANK('Base 2-Yr (US)'!$Q101), "","X") -> X | M16: =IF(ISBLANK('Base 2-Yr (US)'!$Q108), "","X") -> X | N16: =IF(ISBLANK('Base 2-Yr (US)'!$Q115), "","X") -> X | O16: =IF(ISBLANK('Base 2-Yr (US)'!$Q122), "","X") -> X | P16: =IF(ISBLANK('Base 2-Yr (US)'!$Q129), "","X") -> X | Q16: =IF(ISBLANK('Base 2-Yr (US)'!$Q136), "","X") -> X | R16: =IF(ISBLANK('Base 2-Yr (US)'!$Q143), "","X") -> X | S16: =IF(ISBLANK('Base 2-Yr (US)'!$Q150), "","X") -> X | T16: =IF(ISBLANK('Base 2-Yr (US)'!$Q162), "","X") -> X | U16: =IF(ISBLANK('Base 2-Yr (US)'!$Q174), "","X") -> X | V16: =IF(ISBLANK('Base 2-Yr (US)'!$Q186), "","X") -> X | X16: Lockheed Martin (Z) | Y16: =IF(ISBLANK('Base 2-Yr (Non-US)'!$Q2), "","X") -> X | Z16: =IF(ISBLANK('Base 2-Yr (Non-US)'!$Q18), "","X") -> X | AA16: =IF(ISBLANK('Base 2-Yr (Non-US)'!$Q34), "","X") | AB16: =IF(ISBLANK('Base 2-Yr (Non-US)'!$Q50), "","X") -> X | AC16: =IF(ISBLANK('Base 2-Yr (Non-US)'!$Q66), "","X") -> X | AD16: =IF(ISBLANK('Base 2-Yr (Non-US)'!$Q73), "","X") -> X | AE16: =IF(ISBLANK('Base 2-Yr (Non-US)'!$Q80), "","X") | AF16: =IF(ISBLANK('Base 2-Yr (Non-US)'!$Q87), "","X") -> X | AG16: =IF(ISBLANK('Base 2-Yr (Non-US)'!$Q94), "","X") -> X | AH16: =IF(ISBLANK('Base 2-Yr (Non-US)'!$Q101), "","X") -> X | AI16: =IF(ISBLANK('Base 2-Yr (Non-US)'!$Q108), "","X") | AJ16: =IF(ISBLANK('Base 2-Yr (Non-US)'!$Q115), "","X") -> X | AK16: =IF(ISBLANK('Base 2-Yr (Non-US)'!$Q122), "","X") -> X | AL16: =IF(ISBLANK('Base 2-Yr (Non-US)'!$Q129), "","X") -> X | AM16: =IF(ISBLANK('Base 2-Yr (Non-US)'!$Q136), "","X") | AN16: =IF(ISBLANK('Base 2-Yr (Non-US)'!$Q143), "","X") -> X | AO16: =IF(ISBLANK('Base 2-Yr (Non-US)'!$Q150), "","X") -> X | AP16: =IF(ISBLANK('Base 2-Yr (Non-US)'!$Q162), "","X") -> X | AQ16: =IF(ISBLANK('Base 2-Yr (Non-US)'!$Q174), "","X") | AR16: =IF(ISBLANK('Base 2-Yr (Non-US)'!$Q186), "","X") -> X
A17: Onix Networking Corp. (G) | C17: =IF(ISBLANK('Base 2-Yr (US)'!$R2), "","X") -> X | D17: =IF(ISBLANK('Base 2-Yr (US)'!$R18), "","X") | E17: =IF(ISBLANK('Base 2-Yr (US)'!$R34), "","X") | F17: =IF(ISBLANK('Base 2-Yr (US)'!$R50), "","X") -> X | G17: =IF(ISBLANK('Base 2-Yr (US)'!$R66), "","X") -> X | H17: =IF(ISBLANK('Base 2-Yr (US)'!$R73), "","X") | I17: =IF(ISBLANK('Base 2-Yr (US)'!$R80), "","X") | J17: =IF(ISBLANK('Base 2-Yr (US)'!$R87), "","X") -> X | K17: =IF(ISBLANK('Base 2-Yr (US)'!$R94), "","X") | L17: =IF(ISBLANK('Base 2-Yr (US)'!$R101), "","X") | M17: =IF(ISBLANK('Base 2-Yr (US)'!$R108), "","X") | N17: =IF(ISBLANK('Base 2-Yr (US)'!$R115), "","X") | O17: =IF(ISBLANK('Base 2-Yr (US)'!$R122), "","X") -> X | P17: =IF(ISBLANK('Base 2-Yr (US)'!$R129), "","X") | Q17: =IF(ISBLANK('Base 2-Yr (US)'!$R136), "","X") | R17: =IF(ISBLANK('Base 2-Yr (US)'!$R143), "","X") -> X | S17: =IF(ISBLANK('Base 2-Yr (US)'!$R150), "","X") -> X | T17: =IF(ISBLANK('Base 2-Yr (US)'!$R162), "","X") | U17: =IF(ISBLANK('Base 2-Yr (US)'!$R174), "","X") | V17: =IF(ISBLANK('Base 2-Yr (US)'!$R186), "","X") -> X | X17: Onix Networking Corp. (G) | Y17: =IF(ISBLANK('Base 2-Yr (Non-US)'!$R2), "","X") -> X | Z17: =IF(ISBLANK('Base 2-Yr (Non-US)'!$R18), "","X") | AA17: =IF(ISBLANK('Base 2-Yr (Non-US)'!$R34), "","X") | AB17: =IF(ISBLANK('Base 2-Yr (Non-US)'!$R50), "","X") -> X | AC17: =IF(ISBLANK('Base 2-Yr (Non-US)'!$R66), "","X") -> X | AD17: =IF(ISBLANK('Base 2-Yr (Non-US)'!$R73), "","X") | AE17: =IF(ISBLANK('Base 2-Yr (Non-US)'!$R80), "","X") | AF17: =IF(ISBLANK('Base 2-Yr (Non-US)'!$R87), "","X") -> X | AG17: =IF(ISBLANK('Base 2-Yr (Non-US)'!$R94), "","X") | AH17: =IF(ISBLANK('Base 2-Yr (Non-US)'!$R101), "","X") | AI17: =IF(ISBLANK('Base 2-Yr (Non-US)'!$R108), "","X") | AJ17: =IF(ISBLANK('Base 2-Yr (Non-US)'!$R115), "","X") | AK17: =IF(ISBLANK('Base 2-Yr (Non-US)'!$R122), "","X") -> X | AL17: =IF(ISBLANK('Base 2-Yr (Non-US)'!$R129), "","X") | AM17: =IF(ISBLANK('Base 2-Yr (Non-US)'!$R136), "","X") | AN17: =IF(ISBLANK('Base 2-Yr (Non-US)'!$R143), "","X") -> X | AO17: =IF(ISBLANK('Base 2-Yr (Non-US)'!$R150), "","X") -> X | AP17: =IF(ISBLANK('Base 2-Yr (Non-US)'!$R162), "","X") | AQ17: =IF(ISBLANK('Base 2-Yr (Non-US)'!$R174), "","X") | AR17: =IF(ISBLANK('Base 2-Yr (Non-US)'!$R186), "","X") -> X
A18: Science Applications International Corporation (G) | C18: =IF(ISBLANK('Base 2-Yr (US)'!$S2), "","X") -> X | D18: =IF(ISBLANK('Base 2-Yr (US)'!$S18), "","X") | E18: =IF(ISBLANK('Base 2-Yr (US)'!$S34), "","X") | F18: =IF(ISBLANK('Base 2-Yr (US)'!$S50), "","X") -> X | G18: =IF(ISBLANK('Base 2-Yr (US)'!$S66), "","X") -> X | H18: =IF(ISBLANK('Base 2-Yr (US)'!$S73), "","X") | I18: =IF(ISBLANK('Base 2-Yr (US)'!$S80), "","X") | J18: =IF(ISBLANK('Base 2-Yr (US)'!$S87), "","X") -> X | K18: =IF(ISBLANK('Base 2-Yr (US)'!$S94), "","X") | L18: =IF(ISBLANK('Base 2-Yr (US)'!$S101), "","X") | M18: =IF(ISBLANK('Base 2-Yr (US)'!$S108), "","X") | N18: =IF(ISBLANK('Base 2-Yr (US)'!$S115), "","X") | O18: =IF(ISBLANK('Base 2-Yr (US)'!$S122), "","X") -> X | P18: =IF(ISBLANK('Base 2-Yr (US)'!$S129), "","X") | Q18: =IF(ISBLANK('Base 2-Yr (US)'!$S136), "","X") | R18: =IF(ISBLANK('Base 2-Yr (US)'!$S143), "","X") -> X | S18: =IF(ISBLANK('Base 2-Yr (US)'!$S150), "","X") -> X | T18: =IF(ISBLANK('Base 2-Yr (US)'!$S162), "","X") | U18: =IF(ISBLANK('Base 2-Yr (US)'!$S174), "","X") | V18: =IF(ISBLANK('Base 2-Yr (US)'!$S186), "","X") -> X | X18: Science Applications International Corporation (G) | Y18: =IF(ISBLANK('Base 2-Yr (Non-US)'!$S2), "","X") -> X | Z18: =IF(ISBLANK('Base 2-Yr (Non-US)'!$S18), "","X") | AA18: =IF(ISBLANK('Base 2-Yr (Non-US)'!$S34), "","X") | AB18: =IF(ISBLANK('Base 2-Yr (Non-US)'!$S50), "","X") -> X | AC18: =IF(ISBLANK('Base 2-Yr (Non-US)'!$S66), "","X") -> X | AD18: =IF(ISBLANK('Base 2-Yr (Non-US)'!$S73), "","X") | AE18: =IF(ISBLANK('Base 2-Yr (Non-US)'!$S80), "","X") | AF18: =IF(ISBLANK('Base 2-Yr (Non-US)'!$S87), "","X") -> X | AG18: =IF(ISBLANK('Base 2-Yr (Non-US)'!$S94), "","X") | AH18: =IF(ISBLANK('Base 2-Yr (Non-US)'!$S101), "","X") | AI18: =IF(ISBLANK('Base 2-Yr (Non-US)'!$S108), "","X") | AJ18: =IF(ISBLANK('Base 2-Yr (Non-US)'!$S115), "","X") | AK18: =IF(ISBLANK('Base 2-Yr (Non-US)'!$S122), "","X") -> X | AL18: =IF(ISBLANK('Base 2-Yr (Non-US)'!$S129), "","X") | AM18: =IF(ISBLANK('Base 2-Yr (Non-US)'!$S136), "","X") | AN18: =IF(ISBLANK('Base 2-Yr (Non-US)'!$S143), "","X") -> X | AO18: =IF(ISBLANK('Base 2-Yr (Non-US)'!$S150), "","X") -> X | AP18: =IF(ISBLANK('Base 2-Yr (Non-US)'!$S162), "","X") | AQ18: =IF(ISBLANK('Base 2-Yr (Non-US)'!$S174), "","X") | AR18: =IF(ISBLANK('Base 2-Yr (Non-US)'!$S186), "","X") -> X
A19: Smartronix, Inc (EX) | C19: =IF(ISBLANK('Base 2-Yr (US)'!$T2), "","X") -> X | D19: =IF(ISBLANK('Base 2-Yr (US)'!$T18), "","X") -> X | E19: =IF(ISBLANK('Base 2-Yr (US)'!$T34), "","X") -> X | F19: =IF(ISBLANK('Base 2-Yr (US)'!$T50), "","X") | G19: =IF(ISBLANK('Base 2-Yr (US)'!$T66), "","X") -> X | H19: =IF(ISBLANK('Base 2-Yr (US)'!$T73), "","X") -> X | I19: =IF(ISBLANK('Base 2-Yr (US)'!$T80), "","X") -> X | J19: =IF(ISBLANK('Base 2-Yr (US)'!$T87), "","X") | K19: =IF(ISBLANK('Base 2-Yr (US)'!$T94), "","X") | L19: =IF(ISBLANK('Base 2-Yr (US)'!$T101), "","X") | M19: =IF(ISBLANK('Base 2-Yr (US)'!$T108), "","X") | N19: =IF(ISBLANK('Base 2-Yr (US)'!$T115), "","X") | O19: =IF(ISBLANK('Base 2-Yr (US)'!$T122), "","X") -> X | P19: =IF(ISBLANK('Base 2-Yr (US)'!$T129), "","X") -> X | Q19: =IF(ISBLANK('Base 2-Yr (US)'!$T136), "","X") -> X | R19: =IF(ISBLANK('Base 2-Yr (US)'!$T143), "","X") | S19: =IF(ISBLANK('Base 2-Yr (US)'!$T150), "","X") -> X | T19: =IF(ISBLANK('Base 2-Yr (US)'!$T162), "","X") -> X | U19: =IF(ISBLANK('Base 2-Yr (US)'!$T174), "","X") -> X | V19: =IF(ISBLANK('Base 2-Yr (US)'!$T186), "","X") | X19: Smartronix, Inc (EX) | Y19: =IF(ISBLANK('Base 2-Yr (Non-US)'!$T2), "","X") | Z19: =IF(ISBLANK('Base 2-Yr (Non-US)'!$T18), "","X") | AA19: =IF(ISBLANK('Base 2-Yr (Non-US)'!$T34), "","X") | AB19: =IF(ISBLANK('Base 2-Yr (Non-US)'!$T50), "","X") | AC19: =IF(ISBLANK('Base 2-Yr (Non-US)'!$T66), "","X") | AD19: =IF(ISBLANK('Base 2-Yr (Non-US)'!$T73), "","X") | AE19: =IF(ISBLANK('Base 2-Yr (Non-US)'!$T80), "","X") | AF19: =IF(ISBLANK('Base 2-Yr (Non-US)'!$T87), "","X") | AG19: =IF(ISBLANK('Base 2-Yr (Non-US)'!$T94), "","X") | AH19: =IF(ISBLANK('Base 2-Yr (Non-US)'!$T101), "","X") | AI19: =IF(ISBLANK('Base 2-Yr (Non-US)'!$T108), "","X") | AJ19: =IF(ISBLANK('Base 2-Yr (Non-US)'!$T115), "","X") | AK19: =IF(ISBLANK('Base 2-Yr (Non-US)'!$T122), "","X") | AL19: =IF(ISBLANK('Base 2-Yr (Non-US)'!$T129), "","X") | AM19: =IF(ISBLANK('Base 2-Yr (Non-US)'!$T136), "","X") | AN19: =IF(ISBLANK('Base 2-Yr (Non-US)'!$T143), "","X") | AO19: =IF(ISBLANK('Base 2-Yr (Non-US)'!$T150), "","X") | AP19: =IF(ISBLANK('Base 2-Yr (Non-US)'!$T162), "","X") | AQ19: =IF(ISBLANK('Base 2-Yr (Non-US)'!$T174), "","X") | AR19: =IF(ISBLANK('Base 2-Yr (Non-US)'!$T186), "","X")
A20: Systems Research and Applications Corporation (G) | C20: =IF(ISBLANK('Base 2-Yr (US)'!$U2), "","X") -> X | D20: =IF(ISBLANK('Base 2-Yr (US)'!$U18), "","X") | E20: =IF(ISBLANK('Base 2-Yr (US)'!$U34), "","X") | F20: =IF(ISBLANK('Base 2-Yr (US)'!$U50), "","X") | G20: =IF(ISBLANK('Base 2-Yr (US)'!$U66), "","X") -> X | H20: =IF(ISBLANK('Base 2-Yr (US)'!$U73), "","X") | I20: =IF(ISBLANK('Base 2-Yr (US)'!$U80), "","X") | J20: =IF(ISBLANK('Base 2-Yr (US)'!$U87), "","X") | K20: =IF(ISBLANK('Base 2-Yr (US)'!$U94), "","X") | L20: =IF(ISBLANK('Base 2-Yr (US)'!$U101), "","X") | M20: =IF(ISBLANK('Base 2-Yr (US)'!$U108), "","X") | N20: =IF(ISBLANK('Base 2-Yr (US)'!$U115), "","X") | O20: =IF(ISBLANK('Base 2-Yr (US)'!$U122), "","X") -> X | P20: =IF(ISBLANK('Base 2-Yr (US)'!$U129), "","X") | Q20: =IF(ISBLANK('Base 2-Yr (US)'!$U136), "","X") | R20: =IF(ISBLANK('Base 2-Yr (US)'!$U143), "","X") | S20: =IF(ISBLANK('Base 2-Yr (US)'!$U150), "","X") -> X | T20: =IF(ISBLANK('Base 2-Yr (US)'!$U162), "","X") | U20: =IF(ISBLANK('Base 2-Yr (US)'!$U174), "","X") | V20: =IF(ISBLANK('Base 2-Yr (US)'!$U186), "","X") | X20: Systems Research and Applications Corporation (G) | Y20: =IF(ISBLANK('Base 2-Yr (Non-US)'!$U2), "","X") | Z20: =IF(ISBLANK('Base 2-Yr (Non-US)'!$U18), "","X") | AA20: =IF(ISBLANK('Base 2-Yr (Non-US)'!$U34), "","X") | AB20: =IF(ISBLANK('Base 2-Yr (Non-US)'!$U50), "","X") | AC20: =IF(ISBLANK('Base 2-Yr (Non-US)'!$U66), "","X") | AD20: =IF(ISBLANK('Base 2-Yr (Non-US)'!$U73), "","X") | AE20: =IF(ISBLANK('Base 2-Yr (Non-US)'!$U80), "","X") | AF20: =IF(ISBLANK('Base 2-Yr (Non-US)'!$U87), "","X") | AG20: =IF(ISBLANK('Base 2-Yr (Non-US)'!$U94), "","X") | AH20: =IF(ISBLANK('Base 2-Yr (Non-US)'!$U101), "","X") | AI20: =IF(ISBLANK('Base 2-Yr (Non-US)'!$U108), "","X") | AJ20: =IF(ISBLANK('Base 2-Yr (Non-US)'!$U115), "","X") | AK20: =IF(ISBLANK('Base 2-Yr (Non-US)'!$U122), "","X") | AL20: =IF(ISBLANK('Base 2-Yr (Non-US)'!$U129), "","X") | AM20: =IF(ISBLANK('Base 2-Yr (Non-US)'!$U136), "","X") | AN20: =IF(ISBLANK('Base 2-Yr (Non-US)'!$U143), "","X") | AO20: =IF(ISBLANK('Base 2-Yr (Non-US)'!$U150), "","X") | AP20: =IF(ISBLANK('Base 2-Yr (Non-US)'!$U162), "","X") | AQ20: =IF(ISBLANK('Base 2-Yr (Non-US)'!$U174), "","X") | AR20: =IF(ISBLANK('Base 2-Yr (Non-US)'!$U186), "","X")
A21: Systems Research and Applications Corporation (365) | C21: =IF(ISBLANK('Base 2-Yr (US)'!$V2), "","X") | D21: =IF(ISBLANK('Base 2-Yr (US)'!$V18), "","X") -> X | E21: =IF(ISBLANK('Base 2-Yr (US)'!$V34), "","X") | F21: =IF(ISBLANK('Base 2-Yr (US)'!$V50), "","X") | G21: =IF(ISBLANK('Base 2-Yr (US)'!$V66), "","X") | H21: =IF(ISBLANK('Base 2-Yr (US)'!$V73), "","X") -> X | I21: =IF(ISBLANK('Base 2-Yr (US)'!$V80), "","X") | J21: =IF(ISBLANK('Base 2-Yr (US)'!$V87), "","X") | K21: =IF(ISBLANK('Base 2-Yr (US)'!$V94), "","X") | L21: =IF(ISBLANK('Base 2-Yr (US)'!$V101), "","X") | M21: =IF(ISBLANK('Base 2-Yr (US)'!$V108), "","X") | N21: =IF(ISBLANK('Base 2-Yr (US)'!$V115), "","X") | O21: =IF(ISBLANK('Base 2-Yr (US)'!$V122), "","X") | P21: =IF(ISBLANK('Base 2-Yr (US)'!$V129), "","X") -> X | Q21: =IF(ISBLANK('Base 2-Yr (US)'!$V136), "","X") | R21: =IF(ISBLANK('Base 2-Yr (US)'!$V143), "","X") | S21: =IF(ISBLANK('Base 2-Yr (US)'!$V150), "","X") | T21: =IF(ISBLANK('Base 2-Yr (US)'!$V162), "","X") -> X | U21: =IF(ISBLANK('Base 2-Yr (US)'!$V174), "","X") | V21: =IF(ISBLANK('Base 2-Yr (US)'!$V186), "","X") | X21: Systems Research and Applications Corporation (365) | Y21: =IF(ISBLANK('Base 2-Yr (Non-US)'!$V2), "","X") -> X | Z21: =IF(ISBLANK('Base 2-Yr (Non-US)'!$V18), "","X") | AA21: =IF(ISBLANK('Base 2-Yr (Non-US)'!$V34), "","X") | AB21: =IF(ISBLANK('Base 2-Yr (Non-US)'!$V50), "","X") -> X | AC21: =IF(ISBLANK('Base 2-Yr (Non-US)'!$V66), "","X") | AD21: =IF(ISBLANK('Base 2-Yr (Non-US)'!$V73), "","X") | AE21: =IF(ISBLANK('Base 2-Yr (Non-US)'!$V80), "","X") | AF21: =IF(ISBLANK('Base 2-Yr (Non-US)'!$V87), "","X") -> X | AG21: =IF(ISBLANK('Base 2-Yr (Non-US)'!$V94), "","X") | AH21: =IF(ISBLANK('Base 2-Yr (Non-US)'!$V101), "","X") | AI21: =IF(ISBLANK('Base 2-Yr (Non-US)'!$V108), "","X") | AJ21: =IF(ISBLANK('Base 2-Yr (Non-US)'!$V115), "","X") | AK21: =IF(ISBLANK('Base 2-Yr (Non-US)'!$V122), "","X") -> X | AL21: =IF(ISBLANK('Base 2-Yr (Non-US)'!$V129), "","X") | AM21: =IF(ISBLANK('Base 2-Yr (Non-US)'!$V136), "","X") | AN21: =IF(ISBLANK('Base 2-Yr (Non-US)'!$V143), "","X") -> X | AO21: =IF(ISBLANK('Base 2-Yr (Non-US)'!$V150), "","X") -> X | AP21: =IF(ISBLANK('Base 2-Yr (Non-US)'!$V162), "","X") | AQ21: =IF(ISBLANK('Base 2-Yr (Non-US)'!$V174), "","X") | AR21: =IF(ISBLANK('Base 2-Yr (Non-US)'!$V186), "","X") -> X
A22: Technosource LLC (365) | C22: =IF(ISBLANK('Base 2-Yr (US)'!$W2), "","X") -> X | D22: =IF(ISBLANK('Base 2-Yr (US)'!$W18), "","X") | E22: =IF(ISBLANK('Base 2-Yr (US)'!$W34), "","X") | F22: =IF(ISBLANK('Base 2-Yr (US)'!$W50), "","X") | G22: =IF(ISBLANK('Base 2-Yr (US)'!$W66), "","X") | H22: =IF(ISBLANK('Base 2-Yr (US)'!$W73), "","X") | I22: =IF(ISBLANK('Base 2-Yr (US)'!$W80), "","X") | J22: =IF(ISBLANK('Base 2-Yr (US)'!$W87), "","X") | K22: =IF(ISBLANK('Base 2-Yr (US)'!$W94), "","X") | L22: =IF(ISBLANK('Base 2-Yr (US)'!$W101), "","X") | M22: =IF(ISBLANK('Base 2-Yr (US)'!$W108), "","X") | N22: =IF(ISBLANK('Base 2-Yr (US)'!$W115), "","X") | O22: =IF(ISBLANK('Base 2-Yr (US)'!$W122), "","X") -> X | P22: =IF(ISBLANK('Base 2-Yr (US)'!$W129), "","X") | Q22: =IF(ISBLANK('Base 2-Yr (US)'!$W136), "","X") | R22: =IF(ISBLANK('Base 2-Yr (US)'!$W143), "","X") | S22: =IF(ISBLANK('Base 2-Yr (US)'!$W150), "","X") -> X | T22: =IF(ISBLANK('Base 2-Yr (US)'!$W162), "","X") | U22: =IF(ISBLANK('Base 2-Yr (US)'!$W174), "","X") | V22: =IF(ISBLANK('Base 2-Yr (US)'!$W186), "","X") | X22: Technosource LLC (365) | Y22: =IF(ISBLANK('Base 2-Yr (Non-US)'!$W2), "","X") | Z22: =IF(ISBLANK('Base 2-Yr (Non-US)'!$W18), "","X") | AA22: =IF(ISBLANK('Base 2-Yr (Non-US)'!$W34), "","X") | AB22: =IF(ISBLANK('Base 2-Yr (Non-US)'!$W50), "","X") | AC22: =IF(ISBLANK('Base 2-Yr (Non-US)'!$W66), "","X") | AD22: =IF(ISBLANK('Base 2-Yr (Non-US)'!$W73), "","X") | AE22: =IF(ISBLANK('Base 2-Yr (Non-US)'!$W80), "","X") | AF22: =IF(ISBLANK('Base 2-Yr (Non-US)'!$W87), "","X") | AG22: =IF(ISBLANK('Base 2-Yr (Non-US)'!$W94), "","X") | AH22: =IF(ISBLANK('Base 2-Yr (Non-US)'!$W101), "","X") | AI22: =IF(ISBLANK('Base 2-Yr (Non-US)'!$W108), "","X") | AJ22: =IF(ISBLANK('Base 2-Yr (Non-US)'!$W115), "","X") | AK22: =IF(ISBLANK('Base 2-Yr (Non-US)'!$W122), "","X") | AL22: =IF(ISBLANK('Base 2-Yr (Non-US)'!$W129), "","X") | AM22: =IF(ISBLANK('Base 2-Yr (Non-US)'!$W136), "","X") | AN22: =IF(ISBLANK('Base 2-Yr (Non-US)'!$W143), "","X") | AO22: =IF(ISBLANK('Base 2-Yr (Non-US)'!$W150), "","X") | AP22: =IF(ISBLANK('Base 2-Yr (Non-US)'!$W162), "","X") | AQ22: =IF(ISBLANK('Base 2-Yr (Non-US)'!$W174), "","X") | AR22: =IF(ISBLANK('Base 2-Yr (Non-US)'!$W186), "","X")
A23: Unisys (365) | C23: =IF(ISBLANK('Base 2-Yr (US)'!$X2), "","X") | D23: =IF(ISBLANK('Base 2-Yr (US)'!$X18), "","X") -> X | E23: =IF(ISBLANK('Base 2-Yr (US)'!$X34), "","X") | F23: =IF(ISBLANK('Base 2-Yr (US)'!$X50), "","X") | G23: =IF(ISBLANK('Base 2-Yr (US)'!$X66), "","X") | H23: =IF(ISBLANK('Base 2-Yr (US)'!$X73), "","X") -> X | I23: =IF(ISBLANK('Base 2-Yr (US)'!$X80), "","X") | J23: =IF(ISBLANK('Base 2-Yr (US)'!$X87), "","X") | K23: =IF(ISBLANK('Base 2-Yr (US)'!$X94), "","X") | L23: =IF(ISBLANK('Base 2-Yr (US)'!$X101), "","X") | M23: =IF(ISBLANK('Base 2-Yr (US)'!$X108), "","X") | N23: =IF(ISBLANK('Base 2-Yr (US)'!$X115), "","X") | O23: =IF(ISBLANK('Base 2-Yr (US)'!$X122), "","X") | P23: =IF(ISBLANK('Base 2-Yr (US)'!$X129), "","X") -> X | Q23: =IF(ISBLANK('Base 2-Yr (US)'!$X136), "","X") | R23: =IF(ISBLANK('Base 2-Yr (US)'!$X143), "","X") | S23: =IF(ISBLANK('Base 2-Yr (US)'!$X150), "","X") | T23: =IF(ISBLANK('Base 2-Yr (US)'!$X162), "","X") -> X | U23: =IF(ISBLANK('Base 2-Yr (US)'!$X174), "","X") | V23: =IF(ISBLANK('Base 2-Yr (US)'!$X186), "","X") | X23: Unisys (365) | Y23: =IF(ISBLANK('Base 2-Yr (Non-US)'!$X2), "","X") | Z23: =IF(ISBLANK('Base 2-Yr (Non-US)'!$X18), "","X") | AA23: =IF(ISBLANK('Base 2-Yr (Non-US)'!$X34), "","X") | AB23: =IF(ISBLANK('Base 2-Yr (Non-US)'!$X50), "","X") -> X | AC23: =IF(ISBLANK('Base 2-Yr (Non-US)'!$X66), "","X") | AD23: =IF(ISBLANK('Base 2-Yr (Non-US)'!$X73), "","X") | AE23: =IF(ISBLANK('Base 2-Yr (Non-US)'!$X80), "","X") | AF23: =IF(ISBLANK('Base 2-Yr (Non-US)'!$X87), "","X") -> X | AG23: =IF(ISBLANK('Base 2-Yr (Non-US)'!$X94), "","X") | AH23: =IF(ISBLANK('Base 2-Yr (Non-US)'!$X101), "","X") | AI23: =IF(ISBLANK('Base 2-Yr (Non-US)'!$X108), "","X") | AJ23: =IF(ISBLANK('Base 2-Yr (Non-US)'!$X115), "","X") | AK23: =IF(ISBLANK('Base 2-Yr (Non-US)'!$X122), "","X") | AL23: =IF(ISBLANK('Base 2-Yr (Non-US)'!$X129), "","X") | AM23: =IF(ISBLANK('Base 2-Yr (Non-US)'!$X136), "","X") | AN23: =IF(ISBLANK('Base 2-Yr (Non-US)'!$X143), "","X") -> X | AO23: =IF(ISBLANK('Base 2-Yr (Non-US)'!$X150), "","X") | AP23: =IF(ISBLANK('Base 2-Yr (Non-US)'!$X162), "","X") | AQ23: =IF(ISBLANK('Base 2-Yr (Non-US)'!$X174), "","X") | AR23: =IF(ISBLANK('Base 2-Yr (Non-US)'!$X186), "","X") -> X
A24: Unisys (G) | C24: =IF(ISBLANK('Base 2-Yr (US)'!$Y$2), "","X") -> X | D24: =IF(ISBLANK('Base 2-Yr (US)'!$Y$18), "","X") | E24: =IF(ISBLANK('Base 2-Yr (US)'!$Y$34), "","X") | F24: =IF(ISBLANK('Base 2-Yr (US)'!$Y$50), "","X") | G24: =IF(ISBLANK('Base 2-Yr (US)'!$Y$66), "","X") -> X | H24: =IF(ISBLANK('Base 2-Yr (US)'!$Y$73), "","X") | I24: =IF(ISBLANK('Base 2-Yr (US)'!$Y$80), "","X") | J24: =IF(ISBLANK('Base 2-Yr (US)'!$Y$87), "","X") | K24: =IF(ISBLANK('Base 2-Yr (US)'!$Y$94), "","X") | L24: =IF(ISBLANK('Base 2-Yr (US)'!$Y$101), "","X") | M24: =IF(ISBLANK('Base 2-Yr (US)'!$Y$108), "","X") | N24: =IF(ISBLANK('Base 2-Yr (US)'!$Y$115), "","X") | O24: =IF(ISBLANK('Base 2-Yr (US)'!$Y$122), "","X") -> X | P24: =IF(ISBLANK('Base 2-Yr (US)'!$Y$129), "","X") | Q24: =IF(ISBLANK('Base 2-Yr (US)'!$Y$136), "","X") | R24: =IF(ISBLANK('Base 2-Yr (US)'!$Y$143), "","X") | S24: =IF(ISBLANK('Base 2-Yr (US)'!$Y$150), "","X") -> X | T24: =IF(ISBLANK('Base 2-Yr (US)'!$Y$162), "","X") | U24: =IF(ISBLANK('Base 2-Yr (US)'!$Y$174), "","X") | V24: =IF(ISBLANK('Base 2-Yr (US)'!$Y$186), "","X") | X24: Unisys (G) | Y24: =IF(ISBLANK('Base 2-Yr (Non-US)'!$Y2), "","X") | Z24: =IF(ISBLANK('Base 2-Yr (Non-US)'!$Y18), "","X") | AA24: =IF(ISBLANK('Base 2-Yr (Non-US)'!$Y34), "","X") | AB24: =IF(ISBLANK('Base 2-Yr (Non-US)'!$Y50), "","X") -> X | AC24: =IF(ISBLANK('Base 2-Yr (Non-US)'!$Y66), "","X") | AD24: =IF(ISBLANK('Base 2-Yr (Non-US)'!$Y73), "","X") | AE24: =IF(ISBLANK('Base 2-Yr (Non-US)'!$Y80), "","X") | AF24: =IF(ISBLANK('Base 2-Yr (Non-US)'!$Y87), "","X") -> X | AG24: =IF(ISBLANK('Base 2-Yr (Non-US)'!$Y94), "","X") | AH24: =IF(ISBLANK('Base 2-Yr (Non-US)'!$Y101), "","X") | AI24: =IF(ISBLANK('Base 2-Yr (Non-US)'!$Y108), "","X") | AJ24: =IF(ISBLANK('Base 2-Yr (Non-US)'!$Y115), "","X") | AK24: =IF(ISBLANK('Base 2-Yr (Non-US)'!$Y122), "","X") | AL24: =IF(ISBLANK('Base 2-Yr (Non-US)'!$Y129), "","X") | AM24: =IF(ISBLANK('Base 2-Yr (Non-US)'!$Y136), "","X") | AN24: =IF(ISBLANK('Base 2-Yr (Non-US)'!$Y143), "","X") -> X | AO24: =IF(ISBLANK('Base 2-Yr (Non-US)'!$Y150), "","X") | AP24: =IF(ISBLANK('Base 2-Yr (Non-US)'!$Y162), "","X") | AQ24: =IF(ISBLANK('Base 2-Yr (Non-US)'!$Y174), "","X") | AR24: =IF(ISBLANK('Base 2-Yr (Non-US)'!$Y186), "","X") -> X
A25: Total | C25: =COUNTIF(C4:C24, "X") -> 16 | D25: =COUNTIF(D4:D24, "X") -> 12 | E25: =COUNTIF(E4:E24, "X") -> 5 | F25: =COUNTIF(F4:F24, "X") -> 10 | G25: =COUNTIF(G4:G24, "X") -> 13 | H25: =COUNTIF(H4:H24, "X") -> 11 | I25: =COUNTIF(I4:I24, "X") -> 5 | J25: =COUNTIF(J4:J24, "X") -> 9 | ... V25: =COUNTIF(V4:V24, "X") -> 10 | X25: Total | Y25: =COUNTIF(Y4:Y24, "X") -> 8 | Z25: =COUNTIF(Z4:Z24, "X") -> 2 | AA25: =COUNTIF(AA4:AA24, "X") -> 0 | AB25: =COUNTIF(AB4:AB24, "X") -> 11 | AC25: =COUNTIF(AC4:AC24, "X") -> 6 | AD25: =COUNTIF(AD4:AD24, "X") -> 2 | AE25: =COUNTIF(AE4:AE24, "X") -> 0 | AF25: =COUNTIF(AF4:AF24, "X") -> 11 | ... AR25: =COUNTIF(AR4:AR24, "X") -> 11
A26: "X" indicates pricing is available for that particular industry partner / sublot combination | X26: "X" indicates pricing is available for that particular industry partner / sublot combination
A28: Abbreviations & Definitions
A29: Term | B29: Definition
A30: 365 | B30: Microsoft 365 solution
A31: DOM | B31: Lotus Domino (IBM) web solution
A32: EX | B32: Microsoft Exchange solution
A33: G | B33: Google solution
A34: Z | B34: Zimbra solution
A35: US | B35: All data centers are in the US
A36: Non-US | B36: Not all data centers are in the US
A37: 1a | B37: Email as a Service, Govt. Community Cloud Delivery Model
A38: 1b | B38: Email as a Service, Private Cloud Delivery Model
A39: 1c | B39: Email as a Service, Secret Enclave Delivery Model
A40: 1d | B40: Email as a Service, Public Cloud Delivery Model
A41: 2a | B41: Office Automation, Govt. Community Cloud Delivery Model
...

Sheet Base 2-Yr (US)
A1: CLIN | B1: Delivery Model | C1: CLIN Description Prices listed are for Base Period of Two (2) Years: US Pricing | D1: Unit of Measure | E1: Accenture Federal Services LLC (G) | F1: Accenture Federal Services LLC (365) | G1: Autonomic Resources LLC (EX) | H1: CGI Federal Inc. (Z) | I1: Ciracom Inc. (EX) | J1: Computer Sciences Corporation (G) | K1: Computer Sciences Corporation (EX) | L1: Dell Federal Systems L.P. (365) | M1: DLT Solutions, LLC (G) | N1: General Dynamics Information Technology, Inc. (Z) | O1: Harris IT Service Corporation (Z) | P1: IBM Global Business Services – U.S. Federal (DOM) | Q1: Lockheed Martin (Z) | R1: Onix Networking Corp. (G) | S1: Science Applications International Corporation (G) | T1: Smartronix, Inc (EX) | U1: Systems Research and Applications Corporation (G) | V1: Systems Research and Applications Corporation (365) | W1: Technosource LLC (365) | X1: Unisys (365) | Y1: Unisys (G)
A2: 0001AA | B2: Govt. Community | C2: Mailbox Tier 1 (<10K Mbox) | D2: per Mailbox per month | E2: 3.68 | G2: 20.48 | H2: 8.45 | I2: 12.51 | J2: 3.74 | M2: 3.59 | N2: 5.09 | O2: 10.79 | P2: 22.61 | Q2: 10.53 | R2: 3.7 | S2: 3.89 | T2: 30.87 | U2: 3.68 | W2: 7.79 | Y2: 4.75
A3: 0001AB | B3: Govt. Community | C3: Mailbox Tier 2 (10K-50K Mbox) | D3: per Mailbox per month | E3: 3.68 | G3: 18.43 | H3: 7.92 | I3: 11.85 | J3: 3.72 | M3: 3.59 | N3: 4.94 | O3: 9.47 | P3: 14.39 | Q3: 6.67 | R3: 3.7 | S3: 3.85 | T3: 22.23 | U3: 3.68 | W3: 7.79 | Y3: 4.75
A4: 0001AC | B4: Govt. Community | C4: Mailbox Tier 3 (>50K Mbox) | D4: per Mailbox per month | E4: 3.68 | G4: 16.38 | H4: 6.99 | I4: 11.57 | J4: 3.68 | M4: 3.59 | N4: 4.49 | O4: 9.03 | P4: 11.3 | Q4: 6.02 | R4: 3.7 | S4: 3.81 | T4: 16.08 | U4: 3.68 | W4: 7.79 | Y4: 4.75
A5: 0001AD | B5: Govt. Community | C5: Additional GB of Mailbox Storage Tier 1 (<10K Mbox) | D5: per GB per month | E5: 0 | G5: 3.6 | H5: 0.84 | I5: 1.66 | J5: 0 | N5: 0.33 | O5: 0.63 | P5: 1.5 | Q5: 0.65 | T5: 0.48 | Y5: 0
A6: 0001AE | B6: Govt. Community | C6: Additional GB of Mailbox Storage Tier 2 (10K-50K Mbox) | D6: per GB per month | E6: 0 | G6: 3.24 | H6: 0.84 | I6: 1.45 | J6: 0 | N6: 0.14 | O6: 0.55 | P6: 1.5 | Q6: 0.65 | T6: 0.29 | Y6: 0
A7: 0001AF | B7: Govt. Community | C7: Additional GB of Mailbox Storage Tier 3 (>50K Mbox) | D7: per GB per month | E7: 0 | G7: 2.88 | H7: 0.84 | I7: 1.38 | J7: 0 | N7: 0.13 | O7: 0.43 | P7: 1.5 | Q7: 0.65 | T7: 0.24 | Y7: 0
A8: 0001AG | B8: Govt. Community | C8: Archiving per Mailbox Tier 1 (<10K Mbox) | D8: per Mailbox per month | E8: 1.38 | G8: 18.9 | H8: 3.74 | I8: 8.02 | J8: 1.85 | M8: 1.35 | N8: 12.61 | O8: 2.78 | P8: 23.6 | Q8: 1.23 | R8: 1.83 | S8: 1.92 | T8: 1.51 | U8: 1.38 | W8: 0 | Y8: 0.78
A9: 0001AH | B9: Govt. Community | C9: Archiving per Mailbox Tier 2 (10K-50K Mbox) | D9: per Mailbox per month | E9: 1.38 | G9: 17.55 | H9: 3.5 | I9: 7.26 | J9: 1.84 | M9: 1.35 | N9: 5.51 | O9: 2.78 | P9: 15.3 | Q9: 1.16 | R9: 1.83 | S9: 1.9 | T9: 1.01 | U9: 1.38 | W9: 0 | Y9: 0.78
A10: 0001AI | B10: Govt. Community | C10: Archiving per Mailbox Tier 3 (>50K Mbox) | D10: per Mailbox per month | E10: 1.38 | G10: 16.2 | H10: 2.91 | I10: 6.9 | J10: 1.82 | M10: 1.35 | N10: 4.54 | O10: 2.78 | P10: 12.09 | Q10: 1.16 | R10: 1.83 | S10: 1.88 | T10: 0.76 | U10: 1.38 | W10: 0 | Y10: 0.78
A11: 0001AJ | B11: Govt. Community | C11: Additional GB of Archiving Storage Tier 1 (<10K Mbox) | D11: per GB per month | E11: 0 | G11: 3.6 | H11: 0.67 | I11: 0 | J11: 0 | M11: 0 | N11: 0.33 | O11: 0.71 | P11: 1.5 | Q11: 0.65 | R11: 0 | T11: 0.22 | U11: 0 | Y11: 0
A12: 0001AK | B12: Govt. Community | C12: Additional GB of Archiving Storage Tier 2 (10K-50K Mbox) | D12: per GB per month | E12: 0 | G12: 3.24 | H12: 0.67 | I12: 0 | J12: 0 | M12: 0 | N12: 0.14 | O12: 0.65 | P12: 1.5 | Q12: 0.65 | R12: 0 | T12: 0.15 | U12: 0 | Y12: 0
A13: 0001AL | B13: Govt. Community | C13: Additional GB of Archiving Storage Tier 3 (>50K Mbox) | D13: per GB per month | E13: 0 | G13: 2.88 | H13: 0.67 | I13: 0 | J13: 0 | M13: 0 | N13: 0.13 | O13: 0.6 | P13: 1.5 | Q13: 0.65 | R13: 0 | T13: 0.1 | U13: 0 | Y13: 0
A14: 0001AM | B14: Govt. Community | C14: Blackberry Enterprise Server per Mailbox Tier 1 (<10K Mbox) | D14: per Mailbox per month | E14: 7.18 | G14: 4 | H14: 14.13 | I14: 9.4 | J14: 14.63 | M14: 7.07 | N14: 4.74 | O14: 5.35 | P14: 14.39 | Q14: 8.71 | R14: 6.66 | S14: 7.13 | T14: 10.08 | U14: 7.182175 | W14: 32.25 | Y14: 13.26
A15: 0001AN | B15: Govt. Community | C15: Blackberry Enterprise Server per Mailbox Tier 2 (10K-50K Mbox) | D15: per Mailbox per month | E15: 6.63 | G15: 2.1 | H15: 13.25 | I15: 8.28 | J15: 14.63 | M15: 6.53 | N15: 4.74 | O15: 5.11 | P15: 12.33 | Q15: 3.69 | R15: 6.11 | S15: 6.58 | T15: 8.56 | U15: 6.6297 | W15: 25.68 | Y15: 9.73
A16: 0001AO | B16: Govt. Community | C16: Blackberry Enterprise Server per Mailbox Tier 3 (>50K Mbox) | D16: per Mailbox per month | E16: 6.08 | G16: 2.1 | H16: 12.14 | I16: 7.09 | J16: 14.63 | M16: 5.98 | N16: 4.74 | O16: 5.11 | P16: 11.3 | Q16: 3.05 | R16: 5.55 | S16: 6.03 | T16: 7.05 | U16: 6.077225 | W16: 19.26 | Y16: 7.73
A18: 0001BA | B18: Private | C18: Mailbox Tier 1 (<10K Mbox) | D18: per Mailbox per month | F18: 20.45 | G18: 22.76 | H18: 12.3 | K18: 17 | L18: 21.56 | N18: 20.5 | O18: 12 | P18: 40.07 | Q18: 11.44 | T18: 35.73 | V18: 20.8 | X18: 22.12
A19: 0001BB | B19: Private | C19: Mailbox Tier 2 (10K-50K Mbox) | D19: per Mailbox per month | F19: 20.45 | G19: 20.49 | H19: 11.53 | K19: 12 | L19: 21.56 | N19: 11.3 | O19: 10.68 | P19: 26.72 | Q19: 7.7 | T19: 23.47 | V19: 20.8 | X19: 22.12
A20: 0001BC | B20: Private | C20: Mailbox Tier 3 (>50K Mbox) | D20: per Mailbox per month | F20: 15.34 | G20: 16.39 | H20: 10.21 | K20: 8 | L20: 16.17 | N20: 6.32 | O20: 10.2 | P20: 19.52 | Q20: 6.41 | T20: 16.34 | V20: 20.8 | X20: 22.12
A21: 0001BD | B21: Private | C21: Additional GB of Mailbox Storage Tier 1 (<10K Mbox) | D21: per GB per month | G21: 3.6 | H21: 1.22 | K21: 2.25 | N21: 0.33 | O21: 0.78 | P21: 1.5 | Q21: 0.87 | T21: 0.53
A22: 0001BE | B22: Private | C22: Additional GB of Mailbox Storage Tier 2 (10K-50K Mbox) | D22: per GB per month | G22: 3.24 | H22: 1.22 | K22: 1.75 | N22: 0.14 | O22: 0.69 | P22: 1.5 | Q22: 0.87 | T22: 0.32
A23: 0001BF | B23: Private | C23: Additional GB of Mailbox Storage Tier 3 (>50K Mbox) | D23: per GB per month | G23: 2.88 | H23: 1.22 | K23: 1.25 | N23: 0.13 | O23: 0.53 | P23: 1.5 | Q23: 0.87 | T23: 0.27
A24: 0001BG | B24: Private | C24: Archiving per Mailbox Tier 1 (<10K Mbox) | D24: per Mailbox per month | F24: 8.64 | G24: 18.9 | H24: 5.45 | K24: 8 | L24: 8.12 | N24: 12.61 | O24: 3.34 | P24: 24.9 | Q24: 1.32 | T24: 3.02 | V24: 8.79 | X24: 9.36
A25: 0001BH | B25: Private | C25: Archiving per Mailbox Tier 2 (10K-50K Mbox) | D25: per Mailbox per month | F25: 8.64 | G25: 17.55 | H25: 5.11 | K25: 6 | L25: 8.12 | N25: 5.51 | O25: 3.34 | P25: 15.56 | Q25: 1.23 | T25: 2.77 | V25: 8.79 | X25: 9.36
A26: 0001BI | B26: Private | C26: Archiving per Mailbox Tier 3 (>50K Mbox) | D26: per Mailbox per month | F26: 6.45 | G26: 16.2 | H26: 4.25 | K26: 4.5 | L26: 6.09 | N26: 4.54 | O26: 3.34 | P26: 12.45 | Q26: 1.25 | T26: 2.52 | V26: 8.79 | X26: 9.36
A27: 0001BJ | B27: Private | C27: Additional GB of Archiving Storage Tier 1 (<10K Mbox) | D27: per GB per month | G27: 3.6 | H27: 0.98 | K27: 2.25 | N27: 0.33 | O27: 0.89 | P27: 1.5 | Q27: 0.87 | T27: 0.24
A28: 0001BK | B28: Private | C28: Additional GB of Archiving Storage Tier 2 (10K-50K Mbox) | D28: per GB per month | G28: 3.24 | H28: 0.98 | K28: 1.75 | N28: 0.14 | O28: 0.81 | P28: 1.5 | Q28: 0.87 | T28: 0.16
A29: 0001BL | B29: Private | C29: Additional GB of Archiving Storage Tier 3 (>50K Mbox) | D29: per GB per month | G29: 2.88 | H29: 0.98 | K29: 1.25 | N29: 0.13 | O29: 0.74 | P29: 1.5 | Q29: 0.87 | T29: 0.11
A30: 0001BM | B30: Private | C30: Blackberry Enterprise Server per Mailbox Tier 1 (<10K Mbox) | D30: per Mailbox per month | F30: 10.88 | G30: 4 | H30: 20.76 | K30: 7 | L30: 10.24 | N30: 4.74 | O30: 5.2 | P30: 17.98 | Q30: 9.37 | T30: 10.08 | V30: 13.94 | X30: 10.23
A31: 0001BN | B31: Private | C31: Blackberry Enterprise Server per Mailbox Tier 2 (10K-50K Mbox) | D31: per Mailbox per month | F31: 10.26 | G31: 2.1 | H31: 19.47 | K31: 6 | L31: 8.59 | N31: 4.74 | O31: 5.17 | P31: 16.44 | Q31: 4.24 | T31: 8.56 | V31: 13.94 | X31: 10.23
A32: 0001BO | B32: Private | C32: Blackberry Enterprise Server per Mailbox Tier 3 (>50K Mbox) | D32: per Mailbox per month | F32: 8.62 | G32: 2.1 | H32: 17.73 | K32: 4.5 | L32: 7.17 | N32: 4.74 | O32: 5.17 | P32: 15.41 | Q32: 3.3 | T32: 7.05 | V32: 13.94 | X32: 10.23
A34: 0001CA | B34: Secret Enclave | C34: Mailbox Tier 1 (<10K Mbox) | D34: per Mailbox per month | K34: 21 | N34: 31.77 | P34: 59.18 | Q34: 16.4 | T34: 118.3
A35: 0001CB | B35: Secret Enclave | C35: Mailbox Tier 2 (10K-50K Mbox) | D35: per Mailbox per month | K35: 15 | N35: 14.08 | P35: 43.87 | Q35: 8.21 | T35: 41.51
A36: 0001CC | B36: Secret Enclave | C36: Mailbox Tier 3 (>50K Mbox) | D36: per Mailbox per month | K36: 9 | N36: 7.75 | P36: 35.72 | Q36: 6.74 | T36: 20.75
A37: 0001CD | B37: Secret Enclave | C37: Additional GB of Mailbox Storage Tier 1 (<10K Mbox) | D37: per GB per month | K37: 2.25 | N37: 0.33 | P37: 1.5 | Q37: 0.65 | T37: 1.44
A38: 0001CE | B38: Secret Enclave | C38: Additional GB of Mailbox Storage Tier 2 (10K-50K Mbox) | D38: per GB per month | K38: 1.75 | N38: 0.14 | P38: 1.5 | Q38: 0.65 | T38: 0.75
A39: 0001CF | B39: Secret Enclave | C39: Additional GB of Mailbox Storage Tier 3 (>50K Mbox) | D39: per GB per month | K39: 1.25 | N39: 0.13 | P39: 1.5 | Q39: 0.65 | T39: 0.35
A40: 0001CG | B40: Secret Enclave | C40: Archiving per Mailbox Tier 1 (<10K Mbox) | D40: per Mailbox per month | K40: 9 | N40: 12.61 | P40: 26.64 | Q40: 1.31 | T40: 3.74
