Workbook

Sheet Chapter Scoring Tool
D1: xxxx Chapter - yyyy College/University | L1: Y
D2: MCS 2011-2012 Summary | L2: N
A3: Directions
A4: 1. Please follow prompts below, filling in columns in Tier 1, Tier 2 Claimed and Tier 3 Claimed
A5: 2. Specifics regarding each Category and the points within may be found within the corresponding worksheet (worksheets are located across the bottom of the page below.)
A6: 3. Documentation requirements for each requirement are located at the end of each corresponding category's worksheet
A7: 4. Foundational Elements requirements and Tier 2 and 3 points will not count without the proper documenation accompanying the item
D8: Tier 1 Foundational Elements | E8: Tier 2 Points | G8: Tier 3 Points
A9: Category | B9: Item No. | C9: Performance Area | D9: (Y/N) | E9: Avail. | F9: Claimed | G9: Avail. | H9: Claimed | I9: Remarks
A10: Fraternity | B10: ='F Fraternity'!A4 -> F1 | C10: ='F Fraternity'!B4 -> Chapter Size (as of Fall academic term) | D10: n | E10: ='F Fraternity'!L4 -> 1 | F10: 0 | G10: ='F Fraternity'!M4 -> 1 | H10: 0
B11: ='F Fraternity'!A5 -> F2 | C11: ='F Fraternity'!B5 -> Chapter Growth | D11: n | E11: ='F Fraternity'!L5 -> 1 | F11: 0 | G11: ='F Fraternity'!M5 -> 1 | H11: 0
B12: ='F Fraternity'!A6 -> F3 | C12: ='F Fraternity'!B6 -> Recruitment | D12: n | E12: ='F Fraternity'!L6 -> 1 | F12: 0 | G12: ='F Fraternity'!M6 -> 1 | H12: 0
B13: ='F Fraternity'!A7 -> F4 | C13: ='F Fraternity'!B7 -> New Member Education | D13: n | E13: ='F Fraternity'!L7 -> 0 | G13: ='F Fraternity'!M7 -> 1 | H13: 0
B14: ='F Fraternity'!A8 -> F5 | C14: ='F Fraternity'!B8 -> Ritual | D14: n | E14: ='F Fraternity'!L8 -> 0 | G14: ='F Fraternity'!M8 -> 1 | H14: 0
B15: ='F Fraternity'!A9 -> F6 | C15: ='F Fraternity'!B9 -> Brotherhood | D15: n | E15: ='F Fraternity'!L9 -> 1 | F15: 0 | G15: ='F Fraternity'!M9 -> 1 | H15: 0
B16: ='F Fraternity'!A10 -> F7 | C16: ='F Fraternity'!B10 -> Alumni Relations | D16: n | E16: ='F Fraternity'!L10 -> 1 | F16: 0 | G16: ='F Fraternity'!M10 -> 1 | H16: 0
B17: Subtotal | E17: =SUM(E10:E16) -> 5 | F17: =SUM(F10:F16) -> 0 | G17: =SUM(G10:G16) -> 7 | H17: =SUM(H10:H16) -> 0
A19: Financial Commitment | B19: ='FC Financial Commitment'!A4 -> FC1 | C19: ='FC Financial Commitment'!B4 -> Chapter Financial Commitments | D19: n | E19: ='FC Financial Commitment'!L4 -> 1 | F19: 0 | G19: ='FC Financial Commitment'!M4 -> 0
B20: ='FC Financial Commitment'!A5 -> FC2 | C20: ='FC Financial Commitment'!B5 -> Personal Financial Commitments | D20: n | E20: ='FC Financial Commitment'!L5 -> 1 | F20: 0 | G20: ='FC Financial Commitment'!M5 -> 1 | H20: 0
B21: ='FC Financial Commitment'!A6 -> FC3 | C21: ='FC Financial Commitment'!B6 -> Financial Planning & Management | D21: n | E21: ='FC Financial Commitment'!L6 -> 1 | F21: 0 | G21: ='FC Financial Commitment'!M6 -> 1 | H21: 0
B22: ='FC Financial Commitment'!A7 -> FC4 | C22: ='FC Financial Commitment'!B7 -> Financial Reporting | D22: n | E22: ='FC Financial Commitment'!L7 -> 1 | F22: 0 | G22: ='FC Financial Commitment'!M7 -> 0
B23: ='FC Financial Commitment'!A8 -> FC5 | C23: ='FC Financial Commitment'!B8 -> Regulatory Compliance | D23: n | E23: ='FC Financial Commitment'!L8 -> 0 | G23: ='FC Financial Commitment'!M8 -> 0
B24: Subtotal | E24: =SUM(E19:E23) -> 4 | F24: =SUM(F19:F23) -> 0 | G24: =SUM(G19:G23) -> 2 | H24: =SUM(H19:H23) -> 0
A26: Personal Conduct | B26: ='PC Personal Conduct'!A4 -> PC1 | C26: ='PC Personal Conduct'!B4 -> Conduct | D26: n | E26: ='PC Personal Conduct'!L4 -> 1 | F26: 0 | G26: ='PC Personal Conduct'!M4 -> 1 | H26: 0
B27: ='PC Personal Conduct'!A5 -> PC2 | C27: ='PC Personal Conduct'!B5 -> Accountability | D27: n | E27: ='PC Personal Conduct'!L5 -> 0 | G27: ='PC Personal Conduct'!M5 -> 1 | H27: 0
B28: ='PC Personal Conduct'!A6 -> PC3 | C28: ='PC Personal Conduct'!B6 -> Risk Management | D28: n | E28: ='PC Personal Conduct'!L6 -> 1 | F28: 0 | G28: ='PC Personal Conduct'!M6 -> 1 | H28: 0
B29: Subtotal | E29: =SUM(E26:E28) -> 2 | F29: =SUM(F26:F28) -> 0 | G29: =SUM(G26:G28) -> 3 | H29: =SUM(H26:H28) -> 0
A31: Leadership | B31: ='L Leadership'!A4 -> L1 | C31: ='L Leadership'!B4 -> Chapter Organization | D31: n | E31: ='L Leadership'!L4 -> 1 | F31: 0 | G31: ='L Leadership'!M4 -> 1 | H31: 0
B32: ='L Leadership'!A5 -> L2 | C32: ='L Leadership'!B5 -> Strategic Planning | D32: n | E32: ='L Leadership'!L5 -> 1 | F32: 0 | G32: ='L Leadership'!M5 -> 0
B33: ='L Leadership'!A6 -> L3 | C33: ='L Leadership'!B6 -> Continuity | D33: n | E33: ='L Leadership'!L6 -> 1 | F33: 0 | G33: ='L Leadership'!M6 -> 1 | H33: 0
B34: ='L Leadership'!A7 -> L4 | C34: ='L Leadership'!B7 -> Advising Structure | D34: n | E34: ='L Leadership'!L7 -> 1 | F34: 0 | G34: ='L Leadership'!M7 -> 1 | H34: 0
B35: ='L Leadership'!A8 -> L5 | C35: ='L Leadership'!B8 -> Written Plans | D35: n | E35: ='L Leadership'!L8 -> 1 | F35: 0 | G35: ='L Leadership'!M8 -> 1 | H35: 0
B36: Subtotal | E36: =SUM(E31:E35) -> 5 | F36: =SUM(F31:F35) -> 0 | G36: =SUM(G31:G35) -> 4 | H36: =SUM(H31:H35) -> 0
A38: Scholarship | B38: ='S Scholarship'!A4 -> S1 | C38: ='S Scholarship'!B4 -> Academic Performance | D38: n | E38: ='S Scholarship'!L4 -> 1 | F38: 0 | G38: ='S Scholarship'!M4 -> 1 | H38: 0
B39: ='S Scholarship'!A5 -> S2 | C39: ='S Scholarship'!B5 -> Programming | D39: n | E39: ='S Scholarship'!L5 -> 1 | F39: 0 | G39: ='S Scholarship'!M5 -> 1 | H39: 0
B40: ='S Scholarship'!A6 -> S3 | C40: ='S Scholarship'!B6 -> PKS Scholarships | D40: n | E40: ='S Scholarship'!L6 -> 1 | F40: 0 | G40: ='S Scholarship'!M6 -> 1 | H40: 0
B41: Subtotal | E41: =SUM(E38:E40) -> 3 | F41: =SUM(F38:F40) -> 0 | G41: =SUM(G38:G40) -> 3 | H41: =SUM(H38:H40) -> 0
A43: Coll.- Comm. Relations | B43: ='CR Collegiate-Comm Relations'!A4 -> CR1 | C43: ='CR Collegiate-Comm Relations'!B4 -> Philanthropy | D43: n | E43: ='CR Collegiate-Comm Relations'!L4 -> 1 | F43: 0 | G43: ='CR Collegiate-Comm Relations'!M4 -> 1 | H43: 0
B44: ='CR Collegiate-Comm Relations'!A5 -> CR2 | C44: ='CR Collegiate-Comm Relations'!B5 -> Community Service | D44: n | E44: ='CR Collegiate-Comm Relations'!L5 -> 1 | F44: 0 | G44: ='CR Collegiate-Comm Relations'!M5 -> 1 | H44: 0
B45: ='CR Collegiate-Comm Relations'!A6 -> CR3 | C45: ='CR Collegiate-Comm Relations'!B6 -> Support for International Partners | D45: n | E45: ='CR Collegiate-Comm Relations'!L6 -> 1 | F45: 0 | G45: ='CR Collegiate-Comm Relations'!M6 -> 0
...

Sheet F Fraternity
A1: Fraternity | B1: is the growth, development, and interaction of the individual members in a diverse Brotherhood who are united by the Ritual of Phi Kappa Sigma and share common beliefs, goals, and values. Fraternity builds character, enhances the collegiate and life experience, provides service to the community, promotes unity, establishes eternal bonds, and creates synergy. ~Doctrine of Excellence
C2: Tier 1 | D2: Tier 2 Points | E2: Tier 3 Points | F2: Documentation Requirements | L2: Points
A3: Item No. | B3: Performance Area | C3: Foundational Elements | F3: CA Verif. | G3: GA/UO Verif. | H3: IFC Verif. | I3: Written Descript. | J3: HQ Verif. | K3: Other | L3: Std. | M3: Tier 3 | N3: Reporting Time(s) | O3: Tools | P3: Remarks
A4: F1 | B4: Chapter Size (as of Fall academic term) | C4: Active Chapter size is equal to or above 20. | D4: Active Chapter size is equal to or above 30. | E4: Active Chapter size is equal to or above 40 or the average campus size (whichever is greater). | G4: Secondary | J4: Primary | L4: 1 | M4: 1 | N4: Spring
A5: F2 | B5: Chapter Growth | C5: The number of NMs initiated is equal or above 30% of the Active Membership (based on # of actives at the beginning of each academic year) for the year (e.g. if the Chapter started the year with 30 active members and initiated 9 new members by the end of the year they would have met the 30% growth goal) | D5: Total NM's for year is equal to or greater than 15 | E5: Total NM's for year is equal to or greater than 20 or average campus size (whichever is greater) | J5: X | L5: 1 | M5: 1 | N5: Spring
A6: F3 | B6: Recruitment | C6: Chapter has a written year-round recruitment plan. | D6: Chapter has a recruitment committee established in the Chapter bylaws. | E6: Chapter provides ongoing (2 or more times/year) formal recruitment training for Members/New Members. | F6: X | I6: X | K6: Copy of Recruitment Plan; Bylaws;Training Program Materials | L6: 1 | M6: 1 | N6: Spring | P6: Year-round plan should be based on Foundations Recruitment Manual or Phired Up Dynamic Recruitment techniques. Maintain names list year-round, etc.
A7: F4 | B7: New Member Education | C7: Chapter uses the Pillars New Member Education program to educate all New Members. | E7: New members attend formal programming on recruitment, financial management, risk management or fire safety outside the chapter. | F7: X | I7: X | K7: Officer Compliance Form; Presentation materials, photos | M7: 1 | N7: Fall/Spring | O7: Sample program materials
A8: F5 | B8: Ritual | C8: The Chapter conducts one (1) Ritual meeting per month and has all Ritual Paraphernalia (e.g. Book of Ceremonies, Ritual Board, robes, insignia, etc. Call the International Headquarters if you have questions or need to order something.) | E8: National volunteer or HQ Staff delivers formal Ritual Training Pgm once per year. | F8: X | I8: X | K8: Meeting minutes, List of dates of Ritual Meetings | M8: 1 | N8: Fall/Spring | O8: Book of Ceremonies, other material re: Ritual
A9: F6 | B9: Brotherhood | C9: Chapter conducts at least one Brotherhood Building Activity per month (e.g. any sport/game the Chapter participates in together, Chapter meals/cookouts, movie/game night, Paintball, Ropes Course, etc.) | D9: Chapter conducts at least two Brotherhood Building Activities per month | E9: Chapter conducts at least three Brotherhood Building Activities per month | F9: X | I9: X | K9: List of dates, events | L9: 1 | M9: 1 | N9: Spring | O9: Ideas for Brotherhood Building Activities
A10: F7 | B10: Alumni Relations | C10: Chapter produces and distributes a newsletter once per year (electronic or hard copy) and maintains/submits to HQ a current alumni contact list. | D10: Chapter sponsors at least one properly-programmed alumni event each year. | E10: Chapter maintains a formal alumni recognition program (i.e. alumnus of the year award). | J10: X | K10: Copy of contact list, award/presentation photos; event photos, copies of newsletters | L10: 1 | M10: 1 | N10: Spring | O10: Alumni Relations Manual
A12: Notes:
A13: 1. | B13: All Foundational Elements in all Categories must be met to be eligible for points (in all Categories.)

Sheet FC Financial Commitment
A1: Financial Commitment | B1: is the effective and responsible management of income and expenses by individual members, Chapters, and the International Fraternity. Financial commitment provides the means for all fraternal operations, programs, and services as well as realistic fiscal training for members. ~Doctrine of Excellence
C2: Tier 1 | D2: Tier 2 Points | E2: Tier 3 Points | F2: Documentation Requirements | L2: Points
A3: Item No. | B3: Performance Area | C3: Foundational Elements | F3: CA Verif. | G3: GA/UO Verif. | H3: IFC Verif. | I3: Written Descript. | J3: HQ Verif. | K3: Other | L3: Std. | M3: Bonus | N3: Reporting Time(s) | O3: Tools | P3: Remarks
A4: FC1 | B4: Chapter Financial Commitments | C4: All invoices are paid no worse than Net 60 and Chapter has zero ($0) balance with International Headquarters and all other creditors at June 15th. | D4: Chapter pays all bills within 30 days of invoice: · Insurance due November 1 · Undergraduate Fee due November 1 · Chapter Assessment due February 15 · Grand Chapter Assessment due February 15 · NM Fees online within 2 wks of bid acceptance · Initiation Fees due 2 weeks prior to initiation. | J4: X | L4: 1 | N4: Fall/Spring
A5: FC2 | B5: Personal Financial Commitments | C5: Chapter has a written policy/process in bylaws to address delinquent payments by members. | D5: Chapter has an Accounts Receivable (among its members) less than 5% of total amt. owed as of May 1st. | E5: Chapter uses a 3rd party financial mgt. service (i.e. Omega Fi, Greek Bill, Bill Highway or a CPA firm) | I5: X | J5: X | K5: Tier 1: Copy of Bylaws and reference to location of policy Tier 2:monthly statements (using templates) Tier 3:documentation indicating Chapter uses a 3rd Party Financial Service. | L5: 1 | M5: 1 | N5: Spring
A6: FC3 | B6: Financial Planning & Management | C6: Chapter submits a budget at the beginning of each academic term | D6: Chapter tracks all income/expenses against budget and maintains total expenses within budgeted amount and increases reserve account by $25/member per year. Chapter evaluates lessons learned and submits an annual report. | E6: Chapter creates/maintains a long-term capital/housing fund with minimum $25/member contribution per year. | J6: X | K6: Tier 1: Budget submitted Tier 2: Chapter provides budget vs. actuals report with a written analyis of same monthly statements (using templates), proof of increase to reserve at $25 /man Tier 3: evidence of $25/man capital/housing fund being maintained | L6: 1 | M6: 1 | N6: Fall/Spring | O6: Templates
A7: FC4 | B7: Financial Reporting | C7: Chapter submits income statements and balance sheets on a monthly basis | D7: Chapter tracks budget and income/expenses using spreadsheets or other software (i.e. Quickbooks). | J7: X | K7: Monthly statements (using templates) | L7: 1 | N7: Fall/Spring | O7: Templates
A8: FC5 | B8: Regulatory Compliance | C8: Chapter completes & submits IRS Form 990 if required. | J8: X | K8: Copy of Form 990 | N8: Fall | O8: Web link; comments/ guidance on rules
A10: Notes:
A11: 1. | B11: All Foundational Elements in all Categories must be met to be eligible for points (in all Categories.)

Sheet PC Personal Conduct
A1: Personal Conduct | B1: is living as Men of Honor by embodying our Core Values. Personal conduct reflects the integrity of the Fraternity, determines future reputations within the community, and defines relationships with others. ~Doctrine of Excellence
C2: Tier 1 | D2: Tier 2 Points | E2: Tier 3 Points | F2: Documentation Requirements | L2: Points
A3: Item No. | B3: Performance Area | C3: Foundational Elements | F3: CA Verif. | G3: GA/UO Verif. | H3: IFC Verif. | I3: Written Descript. | J3: HQ Verif. | K3: Other | L3: Std. | M3: Bonus | N3: Reporting Time(s) | O3: Tools | P3: Remarks
A4: PC1 | B4: Conduct | C4: Chapter is in good standing with Phi Kappa Sigma and University with regard to Chapter conduct. | D4: Chapter has no "Show Cause" incidents for the year. | E4: For each member receiving awards/recognition for citizenship, honorable actions in the community, etc. | G4: X | I4: X | J4: X | K4: Tier 3: Photos/copies of awards/citations | L4: 1 | M4: 1 | N4: Spring
A5: PC2 | B5: Accountability | C5: Chapter has a Judicial Board process described in their bylaws and uses it to adjudicate issues with members. | E5: Chapter New Members submit completed Membership Agreements to HQ prior to initiation. | I5: X | J5: X | K5: Tier 1: Copy of Bylaws with included reference to section | M5: 1 | N5: Fall | O5: Sample Bylaws
A6: PC3 | B6: Risk Management | C6: Chapter complies with all Phi Kappa Sigma and University Risk Management policies/guidelines; Chapter submits an Officer Compliance Form to HQ in September. | D6: Chapter has a program to reinforce Phi Kappa Sigma’s policies to all members (e.g. taking time during weekly meetings to read a section of Phi Kappa Sigma’s Risk Management Policy, Constitution and Acts, Chapter By-Laws, etc. then briefly discussing its significance and how the Chapter and members can act on it) | E6: Chapter voluntarily sponsors risk management training for other campus organization(s). Training provided by qualified individual approved by HQ. | F6: X | G6: X | I6: X | J6: X | K6: Officer Compliance Forms; Presentation materials, photos | L6: 1 | M6: 1 | N6: Fall/Spring | O6: Officer Compliance Form, Sample Presentations
A8: Notes:
A9: 1. | B9: All Foundational Elements in all Categories must be met to be eligible for points (in all Categories.)

Sheet L Leadership
A1: Leadership | B1: is the ability to bring out the best in those around you through vision and initiative. Leadership is the cornerstone of a strong Chapter, encourages effective collaboration, and drives the Fraternity toward a common goal. ~Doctrine of Excellence
C2: Tier 1 | D2: Tier 2 Points | E2: Tier 3 Points | F2: Documentation Requirements | L2: Points
A3: Item No. | B3: Performance Area | C3: Foundational Elements | F3: CA Verif. | G3: GA/UO Verif. | H3: IFC Verif. | I3: Written Descript. | J3: HQ Verif. | K3: Other | L3: Std. | M3: Bonus | N3: Reporting Time(s) | O3: Tools | P3: Remarks
A4: L1 | B4: Chapter Organization | C4: Chapter conducts weekly Chapter meetings during the academic year (based on an academic year calendar). | D4: Chapter Executive Committee conducts weekly meetings during the academic year. | E4: Chapter has at least 80% attendance at all meetings. | I4: X | K4: Tier 1: Meeting Minutes Tier 2: Exec. Comm Meeting Minutes Tier 3: Attendence Sheet showing attendance record | L4: 1 | M4: 1 | N4: Fall/Spring | O4: Officer Guide
A5: L2 | B5: Strategic Planning | C5: Chapter conducts at least one (1) planning retreat each year. | D5: Chapter conducts at least one (1) planning retreat each academic term. | I5: X | J5: X | K5: Retreat materials, output materials, retreat agenda | L5: 1 | N5: Fall/Spring | O5: Officer Guide | P5: Develop and update a strategic plan including SWOT analysis, mission statement and SMART goals.
A6: L3 | B6: Continuity | C6: Officers maintain officer notebooks addressing roles/responsibilities, action plans and notes on lessons learned. | D6: Chapter conducts an Officer Training and Transition Retreat after officer elections. | E6: Chapter uses committee structure for recruitment, finance and philanthropy/community service as a minimum. Committee participation is mandatory under bylaws for 1st year after initiation. | I6: X | J6: X | K6: Officer transition forms, meeting notes;bylaws | L6: 1 | M6: 1 | N6: Fall/Spring | O6: Sample retreat agendas/transition forms
A7: L4 | B7: Advising Structure | C7: Chapter has a Chapter Advisor approved by HQ. Chapter Alpha communicates with the Chapter Advisor at least once per month. | D7: Chapter has an active Faculty Advisor appointed by the college/university. Either the Chapter Advisor or Faculty Advisor attends at least one (1) meeting per month. | E7: Chapter has an Advisory board with at least 3 alumni/faculty/university staff members (members must be approved by the Exec. Committee of International Fraternity) | F7: X | G7: X | I7: X | K7: Contact information, letter from Faculty Advisor | L7: 1 | M7: 1 | N7: Spring
A8: L5 | B8: Written Plans | C8: Chapter has current chapter-approved bylaws which have been distributed to the entire membership within the past year. | D8: Officers prepare written goals based on Doctrine Of Excellence. | E8: Chapter prepares and submits a written strategic plan addressing (minimum) recruitment, financial management, philanthropy/community service and membership development. Plan shall be prepared using template available from HQ. | I8: X | J8: X | K8: Copies of bylaws/goals/plans | L8: 1 | M8: 1 | N8: Fall | O8: Officer Guide
A10: Notes:
A11: 1. | B11: All Foundational Elements in all Categories must be met to be eligible for points (in all Categories.)

Sheet S Scholarship
A1: Scholarship | B1: is the dedication to life-long learning in the pursuit of knowledge and wisdom through the use of resources including both people and information which leads to intellectual growth and satisfaction. Scholarship opens doors to opportunities, enables one to impart insight to others, engenders progress in society, helps promote recruitment and campus relations, and makes one invaluable to their community. ~Doctrine of Excellence
C2: Tier 1 | D2: Tier 2 Points | E2: Tier 3 Points | F2: Documentation Requirements | L2: Points
A3: Item No. | B3: Performance Area | C3: Foundational Elements | F3: CA Verif. | G3: GA/UO Verif. | H3: IFC Verif. | I3: Written Descript. | J3: HQ Verif. | K3: Other | L3: Std. | M3: Bonus | N3: Reporting Time(s) | O3: Tools | P3: Remarks
A4: S1 | B4: Academic Performance | C4: At least 90% of the Chapter members have a 2.25 GPA for the academic year. | D4: No members (including new members) have below a 2.25 GPA for each academic term. | E4: Chapter GPA (including Members and New Members) is equal to or greater than the All-Fraternity or All-Mens' average for the year. | G4: X | J4: X | K4: Grade reports; transcripts (unofficial OK) Chapter generated materials WILL NOT BE ACCEPTED | L4: 1 | M4: 1 | N4: Spring
A5: S2 | B5: Programming | C5: Chapter has a program to promote scholarship among all members (e.g. using “Making the Grade”, “Grade Point League”, study tables, group/school support, incentive/point systems, etc.) | D5: Chapter bylaws make provision for a mandatory academic mentoring program for those below a 2.5 GPA. | E5: Chapter budgets for and provides cash awards or non-monetary incentives for academic performance and improvement (i.e. highest GPA, most improved GPA) each year. | I5: X | K5: Tier 1:Copy of scholarship program; Tier 2:bylaws (reference to location) Tier 3: budget; copies/photos of awards | L5: 1 | M5: 1 | N5: Fall/Spring | O5: Arches Membership Development Guide | P5: Submit academic program description and chapter budget.
A6: S3 | B6: PKS Scholarships | C6: At least one (1) member applies for a PKS Foundation scholarship | D6: At least three (3) members apply for a PKS Foundation scholarship | E6: Chapter Alumni sponsor scholarship for at least one active member in a minimum amount of $500. | J6: X | L6: 1 | M6: 1 | N6: Spring | O6: Scholarship applications
A8: Notes:
A9: 1. | B9: All Foundational Elements in all Categories must be met to be eligible for points (in all Categories.)

Sheet CR Collegiate-Comm Relations
A1: Collegiate-Community Relations | B1: include interactions with groups that coexist with the Fraternity. Collegiate and community relations create mutually beneficial working relationships that expand opportunities and generate positive perceptions. ~Doctrine of Excellence
C2: Tier 1 | D2: Tier 2 Points | E2: Tier 3 Points | F2: Documentation Requirements | L2: Points
A3: Item No. | B3: Performance Area | C3: Foundational Elements | F3: CA Verif. | G3: GA/UO Verif. | H3: IFC Verif. | I3: Written Descript. | J3: HQ Verif. | K3: Other | L3: Std. | M3: Bonus | N3: Reporting Time(s) | O3: Tools | P3: Remarks
A4: CR1 | B4: Philanthropy | C4: Chapter sponsors at least two philanthropic events (Instances of the word “sponsor” indicate that the Chapter is expected to plan, organize, and coordinate an event in the name of Phi Kappa Sigma. Merely attending an event sponsored by someone else or another organization will not satisfy these items. “Non-sponsored” events can still count towards each individual member’s community service hours. | D4: Chapter raises at least $500 for philanthropy | E4: Chapter raises at least $2,500 for philanthropy. | J4: X | K4: Tier 1: Descriptions, photos, flyers, letters from recipients Tier 2 & 3: letters from recipients, copies of checks | L4: 1 | M4: 1 | N4: Spring | O4: Guide/event ideas
A5: CR2 | B5: Community Service | C5: Chapter performs at least 16 hours of service per man during the year. | D5: Chapter performs at least 24 hours of service per man during the year. | E5: Chapter performs at least 32 hours of service per man during the year. | F5: X | G5: X | I5: X | K5: Philanthropy/Comm. Service Forms, letters from service organizations, descriptions of events, photos, dates and times of events | L5: 1 | M5: 1 | N5: Spring | O5: Guide/svc. ideas
A6: CR3 | B6: Support for International Partners | C6: Chapter sponsors at least one event benefiting the Leukemia and Lymphoma Society | D6: Chapter sponsors more than one event benefiting the Leukemia and Lymphoma Society. | J6: X | K6: Descriptions, photos, flyers, letters from recipients | L6: 1 | N6: Spring | O6: Guide/event ideas
A7: CR4 | B7: College/University Relations | C7: Chapter submits all required information and documentation to the school when requested (e.g. rosters, event planning forms, by-laws, certificate of insurance, etc.) | D7: A Chapter representative meets with the Greek Advisor at least once per month to discuss their office, Chapter operations, or another Fraternity/Chapter related topic | E7: Chapter uses campus media outlets for positive messaging regarding recruitment, philanthropy, community service events. | G7: X | I7: X | K7: Tier 1 and 2: GA verification Tier 3: Copies of print ads; audio files of radio spots | L7: 1 | M7: 1 | N7: Spring
A8: CR5 | B8: IFC/Greek Council Relations | C8: A chapter representative attends all IFC/Greek Council meetings (one excused absence permitted). | D8: A chapter member participates in an IFC/Greek Council committee. | E8: A chapter member holds a leadership/officer position in the IFC. | G8: X | H8: X | L8: 1 | M8: 1 | N8: Spring
A9: CR6 | B9: Campus Community Relations | C9: 50% or more of active Chapter members are members of another campus organization | D9: 75% or more of active Chapter members are members of another campus organization | E9: 100% of active Chapter members are members of another campus organization | G9: X | K9: Organization rosters, web page prints | L9: 1 | M9: 1 | N9: Spring
A10: CR7 | B10: Intramural Sports | D10: Chapter fields at least two officially sanctioned intramural teams per year | E10: Chapter fields at least five officially sanctioned intramural teams per year | G10: X | L10: 1 | M10: 1 | N10: Spring
A11: CR8 | B11: Properly-Programmed Events | C11: Chapter sponsors at least two properly programmed social events per year (A “properly programmed event” is an activity planned and coordinated by the Chapter that complies with ALL Phi Kappa Sigma and School Policies regarding alcohol and risk management. The event must be registered with the school. In addition, events with alcohol must follow Phi Kappa Sigma’s Third Party Vendor Guidelines and the Event Planning Form must be sent to the International Headquarters 30 days prior to the event.) | D11: Chapter sponsors a properly-programmed social event with another registered student organization. | E11: For each properly programmed parent event sponsored. | G11: X | K11: Event planning forms, flyers, photos | L11: 1 | M11: 1 | N11: Spring | O11: Event planning guide
A13: Notes:
A14: 1. | B14: All Foundational Elements in all Categories must be met to be eligible for points (in all Categories.)

Sheet PD Pers Development
A1: Personal Development | B1: is growth through applying knowledge gained from life experiences. Personal development leads to a strong foundation of character and competence, fosters balanced and focused individuals, and establishes confidence in real world situations. ~Doctrine of Excellence
C2: Tier 1 | D2: Tier 2 Points | E2: Tier 3 Points | F2: Documentation Requirements | L2: Points
A3: Item No. | B3: Performance Area | C3: Foundational Elements | F3: CA Verif. | G3: GA/UO Verif. | H3: IFC Verif. | I3: Written Descript. | J3: HQ Verif. | K3: Other | L3: Std. | M3: Bonus | N3: Reporting Time(s) | O3: Tools | P3: Remarks
A4: PD1 | B4: Fraternal Leadership Programs | C4: At least one chapter member attends the Men of Honor Leadership Institute and in Grand Chapter years at least one chapter member attends Grand Chapter. | D4: At least 3 chapter members attend the Men of Honor Leadership Institute or another Phi Kappa Sigma leadership program. | E4: At least 1 chapter member attends a nationally-recognized fraternal (greek) leadership development program (e.g.UIFI, NGLA, AFLV, SEIFC, etc.) | J4: X | K4: Tier 3: Program materials, confirmation of attendance | L4: 1 | M4: 1 | N4: Spring
A5: PD2 | B5: Non-Fraternal Leadership Programs | C5: At least one (1) chapter member attends a non-fraternal leadership retreat or conference (e.g. any non-greek sponsored leadership program). | D5: At least three (3) chapter members attend a non-fraternal leadership retreat or conference (e.g. any non-greek sponsored leadership program). | E5: At least five (5) chapter members attend a non-fraternal leadership retreat or conference (e.g. any non-greek sponsored leadership program). | G5: X | I5: X | J5: X | K5: Program materials, confirmation of attendance | L5: 1 | M5: 1 | N5: Spring
A6: PD3 | B6: Mentoring | D6: At least one (1) member participates in the Scepter Mentorship Program (must be paired with a mentee and meet with them at least twice during the year) | E6: At least three (3) members participate in the Scepter Mentorship Program (must be paired with a mentee and meet with them at least twice during the year) | J6: X | L6: 1 | M6: 1 | N6: Spring | O6: Scepter Program Guide
A7: PD4 | B7: GreekLife.edu | C7: Chapter achieves at least 90% participation level of applicable members successfully completing the GreekLife.Edu program | E7: For 100% of applicable members successfully completing Greek Life Edu. | J7: X | M7: 1 | N7: Spring | O7: GLEdu Instructions
A8: PD5 | B8: Member Development Programming | D8: Chapter plans and conducts at least one (1) formal training session for Members (with at least 50% attendance) in time management, personal finance, conflict resolution, leadership styles, etiquette or other approved subject. | E8: Chapter plans and conducts at least three (3) formal training sessions for Members (with at least 50% attendance) in time management, personal finance, conflict resolution, leadership styles, etiquette or other approved subject. | I8: X | K8: Program materials, confirmation of attendance | L8: 1 | M8: 1 | N8: Spring | O8: Sample presentations
A10: Notes:
A11: 1. | B11: All Foundational Elements in all Categories must be met to be eligible for points (in all Categories.)

Sheet IS Intl Support
A1: International Support | B1: includes Headquarters Staff and local, regional, and international volunteers who provide resources to assist Chapters in fulfilling the Objects of the Fraternity. International support creates a structure that assists in networking, maintains history, and establishes vision for the future. ~Doctrine of Excellence
C2: Tier 1 | D2: Tier 2 Points | E2: Tier 3 Points | F2: Documentation Requirements | L2: Points
A3: Item No. | B3: Performance Area | C3: Foundational Elements | F3: CA Verif. | G3: GA/UO Verif. | H3: IFC Verif. | I3: Written Descript. | J3: HQ Verif. | K3: Other | L3: Std. | M3: Bonus | N3: Reporting Time(s) | O3: Tools | P3: Remarks
A4: IS1 | B4: Communications | C4: Chapter distributes information sent from the International Headquarters that concerns the Chapter to all members (e.g. “Chapter Updates”) | D4: Chapter maintains an active website or social media (i.e. Facebook) group with link to www.pks.org that is current to the present semester and does not contain inappropriate material or photos. | E4: Chapter has contact with the International Headquarters, Executive Committee Member, or their regional Grand Delta at least once a month (e-mail or telephone). | F4: X | I4: X | J4: X | K4: Tier 3: Verification from International Headquarters staff member, Executive Committee Member, or Grand Delta submitted | L4: 1 | M4: 1 | N4: Spring
A5: IS2 | B5: Reporting | C5: Chapter submits Roster with detailed (name, addr, phone#'s, init and grad dates, etc.) Contact information (including alumni advisor(s) and housing corporation board using HQ-approved Roster template. Minimum requirement during 1st week of Each Term and Last week of Academic year. | D5: Chapter includes a transmittal with detailed explanation of contents for all submissions/payments/communication to the International Headquarters (e.g. Phi Kappa Sigma Transmittal Form, Detailed Email, etc.) | E5: Deleted (submission of meeting minutes/financial reports) - these are the documentation for other goals. | J5: X | L5: 1 | N5: Spring
A6: IS3 | B6: Expansion/Recruitment Assistance | D6: Chapter members go to another campus and actively recruit members of a Chapter, Interest Group or Colony (a minimum of 4 Chapter members must participate). | E6: Chapter serves as a “Big Brother Chapter” for a Colony (mentor officers and supervise New Member Education) | J6: X | K6: Prior HQ approval | L6: 1 | M6: 1 | N6: Spring
A7: IS4 | B7: Member Referrals | D7: Chapter refers at least one prospective member that is initiated at another Chapter (the Chapter must submit a referral form to the Int. HQ the term prior to the referral’s initiation to be eligible). | E7: Chapter refers at least three prospective member that are initiated at another Chapter (the Chapter must submit a referral form to the Int. HQ the term prior to the referral’s initiation to be eligible). | I7: X | J7: X | K7: Prior HQ approval | L7: 1 | M7: 1 | N7: Spring
A8: IS5 | B8: Volunteering/Support | D8: At least one chapter member serves as a volunteer for International Fraternity programs, committees, events or other approved HQ initiative. | E8: A chapter member that applies to work as an Educational Consultant or Intern. | J8: X | L8: 1 | M8: 1 | N8: Spring
A10: Notes:
A11: 1. | B11: All Foundational Elements in all Categories must be met to be eligible for points (in all Categories.)
