Workbook

Sheet Loans Originated
A1: FHA Loans Originated for Home Purchase & Occupation for Multnomah County: 2006-2012
A2: (By HUD MFI Groups)
A4: Loan Origination for All Households
B6: 0-30% MFI | C6: 31-50% MFI | D6: 51-80% MFI | E6: 81-95% MFI | F6: >95% MFI | G6: Total (All)
A7: 2006 | B7: 1 | C7: 6 | D7: 79 | E7: 48 | F7: 88 | G7: 225
A8: 2007 | B8: 2 | C8: 2 | D8: 62 | E8: 52 | F8: 129 | G8: 248
A9: 2008 | B9: 1 | C9: 23 | D9: 384 | E9: 282 | F9: 770 | G9: 1472
A10: 2009 | B10: 8 | C10: 225 | D10: 1036 | E10: 423 | F10: 1141 | G10: 2860
A11: 2010 | B11: 14 | C11: 267 | D11: 904 | E11: 411 | F11: 1003 | G11: 2632
A12: 2011 | B12: 16 | C12: 278 | D12: 623 | E12: 254 | F12: 628 | G12: 1823
A13: 2012 | B13: 12 | C13: 277 | D13: 663 | E13: 235 | F13: 602 | G13: 1805
A15: Loan Origination for American Indian/Alaskan Native Households
B17: 0-30% MFI | C17: 31-50% MFI | D17: 51-80% MFI | E17: 81-95% MFI | F17: >95% MFI | G17: Total (Native Americans)
A18: 2006 | B18: 0 | C18: 0 | D18: 4 | E18: 2 | F18: 5 | G18: 11
A19: 2007 | B19: 0 | C19: 0 | D19: 0 | E19: 1 | F19: 3 | G19: 4
A20: 2008 | B20: 0 | C20: 0 | D20: 4 | E20: 3 | F20: 9 | G20: 16
A21: 2009 | B21: 0 | C21: 4 | D21: 16 | E21: 3 | F21: 13 | G21: 36
A22: 2010 | B22: 1 | C22: 3 | D22: 12 | E22: 3 | F22: 9 | G22: 28
A23: 2011 | B23: 0 | C23: 4 | D23: 6 | E23: 0 | F23: 9 | G23: 19
A24: 2012 | B24: 2 | C24: 1 | D24: 14 | E24: 5 | F24: 6 | G24: 28
A26: Loan Origination for Asian Households
B28: 0-30% MFI | C28: 31-50% MFI | D28: 51-80% MFI | E28: 81-95% MFI | F28: >95% MFI | G28: Total (Asians)
A29: 2006 | B29: 1 | C29: 1 | D29: 4 | E29: 5 | F29: 4 | G29: 15
A30: 2007 | B30: 0 | C30: 0 | D30: 2 | E30: 4 | F30: 6 | G30: 12
A31: 2008 | B31: 0 | C31: 1 | D31: 15 | E31: 14 | F31: 45 | G31: 76
A32: 2009 | B32: 1 | C32: 10 | D32: 53 | E32: 19 | F32: 50 | G32: 134
A33: 2010 | B33: 2 | C33: 24 | D33: 44 | E33: 20 | F33: 29 | G33: 121
A34: 2011 | B34: 2 | C34: 23 | D34: 37 | E34: 18 | F34: 33 | G34: 113
A35: 2012 | B35: 0 | C35: 16 | D35: 51 | E35: 12 | F35: 33 | G35: 113
A37: Loan Origination for Black or African American Households
B39: 0-30% MFI | C39: 31-50% MFI | D39: 51-80% MFI | E39: 81-95% MFI | F39: >95% MFI | G39: Total (Blacks)
A40: 2006 | B40: 0 | C40: 0 | D40: 3 | E40: 1 | F40: 3 | G40: 7
A41: 2007 | B41: 0 | C41: 0 | D41: 3 | E41: 3 | F41: 5 | G41: 11
A42: 2008 | B42: 0 | C42: 0 | D42: 10 | E42: 12 | F42: 29 | G42: 51
A43: 2009 | B43: 0 | C43: 4 | D43: 28 | E43: 12 | F43: 24 | G43: 68
A44: 2010 | B44: 0 | C44: 8 | D44: 32 | E44: 10 | F44: 19 | G44: 71
A45: 2011 | B45: 0 | C45: 13 | D45: 16 | E45: 5 | F45: 14 | G45: 48
A46: 2012 | B46: 0 | C46: 7 | D46: 19 | E46: 9 | F46: 16 | G46: 52
A48: Loan Origination for Native Hawaiian or Pacific Islander Households
B50: 0-30% MFI | C50: 31-50% MFI | D50: 51-80% MFI | E50: 81-95% MFI | F50: >95% MFI | G50: Total (NHPI)
...

Sheet Loan Distribution
A1: Distribution of FHA Loan Originations in Multnomah County
A2: By Income and Race/Ethnicity: 2006-2012
A4: All households | B4: 0-30% MFI | C4: 31-50% MFI | D4: 51-80% MFI | E4: 80-95% MFI | F4: >95% MFI
A5: 2006 | B5: ='Loans Originated'!B7/'Loans Originated'!$G$7 -> 0.0044444444 | C5: ='Loans Originated'!C7/'Loans Originated'!$G$7 -> 0.026666667 | D5: ='Loans Originated'!D7/'Loans Originated'!$G$7 -> 0.35111111 | E5: ='Loans Originated'!E7/'Loans Originated'!$G$7 -> 0.21333333 | F5: ='Loans Originated'!F7/'Loans Originated'!$G$7 -> 0.39111111
A6: 2007 | B6: ='Loans Originated'!B8/'Loans Originated'!$G$8 -> 0.0080645161 | C6: ='Loans Originated'!C8/'Loans Originated'!$G$8 -> 0.0080645161 | D6: ='Loans Originated'!D8/'Loans Originated'!$G$8 -> 0.25 | E6: ='Loans Originated'!E8/'Loans Originated'!$G$8 -> 0.20967742 | F6: ='Loans Originated'!F8/'Loans Originated'!$G$8 -> 0.52016129
A7: 2008 | B7: ='Loans Originated'!B9/'Loans Originated'!$G$9 -> 0.00067934783 | C7: ='Loans Originated'!C9/'Loans Originated'!$G$9 -> 0.015625 | D7: ='Loans Originated'!D9/'Loans Originated'!$G$9 -> 0.26086957 | E7: ='Loans Originated'!E9/'Loans Originated'!$G$9 -> 0.19157609 | F7: ='Loans Originated'!F9/'Loans Originated'!$G$9 -> 0.52309783
A8: 2009 | B8: ='Loans Originated'!B10/'Loans Originated'!$G$10 -> 0.0027972028 | C8: ='Loans Originated'!C10/'Loans Originated'!$G$10 -> 0.078671329 | D8: ='Loans Originated'!D10/'Loans Originated'!$G$10 -> 0.36223776 | E8: ='Loans Originated'!E10/'Loans Originated'!$G$10 -> 0.1479021 | F8: ='Loans Originated'!F10/'Loans Originated'!$G$10 -> 0.39895105
A9: 2010 | B9: ='Loans Originated'!B11/'Loans Originated'!$G$11 -> 0.0053191489 | C9: ='Loans Originated'!C11/'Loans Originated'!$G$11 -> 0.10144377 | D9: ='Loans Originated'!D11/'Loans Originated'!$G$11 -> 0.34346505 | E9: ='Loans Originated'!E11/'Loans Originated'!$G$11 -> 0.15615502 | F9: ='Loans Originated'!F11/'Loans Originated'!$G$11 -> 0.38107903
A10: 2011 | B10: ='Loans Originated'!B12/'Loans Originated'!$G$12 -> 0.0087767416 | C10: ='Loans Originated'!C12/'Loans Originated'!$G$12 -> 0.15249589 | D10: ='Loans Originated'!D12/'Loans Originated'!$G$12 -> 0.34174438 | E10: ='Loans Originated'!E12/'Loans Originated'!$G$12 -> 0.13933077 | F10: ='Loans Originated'!F12/'Loans Originated'!$G$12 -> 0.34448711
A11: 2012 | B11: ='Loans Originated'!B13/'Loans Originated'!$G$13 -> 0.0066481994 | C11: ='Loans Originated'!C13/'Loans Originated'!$G$13 -> 0.1534626 | D11: ='Loans Originated'!D13/'Loans Originated'!$G$13 -> 0.36731302 | E11: ='Loans Originated'!E13/'Loans Originated'!$G$13 -> 0.13019391 | F11: ='Loans Originated'!F13/'Loans Originated'!$G$13 -> 0.33351801
A13: Native American HH | B13: 0-30% MFI | C13: 31-50% MFI | D13: 51-80% MFI | E13: 80-95% MFI | F13: >95% MFI
A14: 2006 | B14: ='Loans Originated'!B18/'Loans Originated'!$G$18 -> 0 | C14: ='Loans Originated'!C18/'Loans Originated'!$G$18 -> 0 | D14: ='Loans Originated'!D18/'Loans Originated'!$G$18 -> 0.36363636 | E14: ='Loans Originated'!E18/'Loans Originated'!$G$18 -> 0.18181818 | F14: ='Loans Originated'!F18/'Loans Originated'!$G$18 -> 0.45454545
A15: 2007 | B15: ='Loans Originated'!B19/'Loans Originated'!$G$19 -> 0 | C15: ='Loans Originated'!C19/'Loans Originated'!$G$19 -> 0 | D15: ='Loans Originated'!D19/'Loans Originated'!$G$19 -> 0 | E15: ='Loans Originated'!E19/'Loans Originated'!$G$19 -> 0.25 | F15: ='Loans Originated'!F19/'Loans Originated'!$G$19 -> 0.75
A16: 2008 | B16: ='Loans Originated'!B20/'Loans Originated'!$G$20 -> 0 | C16: ='Loans Originated'!C20/'Loans Originated'!$G$20 -> 0 | D16: ='Loans Originated'!D20/'Loans Originated'!$G$20 -> 0.25 | E16: ='Loans Originated'!E20/'Loans Originated'!$G$20 -> 0.1875 | F16: ='Loans Originated'!F20/'Loans Originated'!$G$20 -> 0.5625
A17: 2009 | B17: ='Loans Originated'!B21/'Loans Originated'!$G$21 -> 0 | C17: ='Loans Originated'!C21/'Loans Originated'!$G$21 -> 0.11111111 | D17: ='Loans Originated'!D21/'Loans Originated'!$G$21 -> 0.44444444 | E17: ='Loans Originated'!E21/'Loans Originated'!$G$21 -> 0.083333333 | F17: ='Loans Originated'!F21/'Loans Originated'!$G$21 -> 0.36111111
A18: 2010 | B18: ='Loans Originated'!B22/'Loans Originated'!$G$22 -> 0.035714286 | C18: ='Loans Originated'!C22/'Loans Originated'!$G$22 -> 0.10714286 | D18: ='Loans Originated'!D22/'Loans Originated'!$G$22 -> 0.42857143 | E18: ='Loans Originated'!E22/'Loans Originated'!$G$22 -> 0.10714286 | F18: ='Loans Originated'!F22/'Loans Originated'!$G$22 -> 0.32142857
A19: 2011 | B19: ='Loans Originated'!B23/'Loans Originated'!$G$23 -> 0 | C19: ='Loans Originated'!C23/'Loans Originated'!$G$23 -> 0.21052632 | D19: ='Loans Originated'!D23/'Loans Originated'!$G$23 -> 0.31578947 | E19: ='Loans Originated'!E23/'Loans Originated'!$G$23 -> 0 | F19: ='Loans Originated'!F23/'Loans Originated'!$G$23 -> 0.47368421
A20: 2012 | B20: ='Loans Originated'!B24/'Loans Originated'!$G$24 -> 0.071428571 | C20: ='Loans Originated'!C24/'Loans Originated'!$G$24 -> 0.035714286 | D20: ='Loans Originated'!D24/'Loans Originated'!$G$24 -> 0.5 | E20: ='Loans Originated'!E24/'Loans Originated'!$G$24 -> 0.17857143 | F20: ='Loans Originated'!F24/'Loans Originated'!$G$24 -> 0.21428571
A22: Asian Households | B22: 0-30% MFI | C22: 31-50% MFI | D22: 51-80% MFI | E22: 80-95% MFI | F22: >95% MFI
A23: 2006 | B23: ='Loans Originated'!B29/'Loans Originated'!$G$29 -> 0.066666667 | C23: ='Loans Originated'!C29/'Loans Originated'!$G$29 -> 0.066666667 | D23: ='Loans Originated'!D29/'Loans Originated'!$G$29 -> 0.26666667 | E23: ='Loans Originated'!E29/'Loans Originated'!$G$29 -> 0.33333333 | F23: ='Loans Originated'!F29/'Loans Originated'!$G$29 -> 0.26666667
A24: 2007 | B24: ='Loans Originated'!B30/'Loans Originated'!$G$30 -> 0 | C24: ='Loans Originated'!C30/'Loans Originated'!$G$30 -> 0 | D24: ='Loans Originated'!D30/'Loans Originated'!$G$30 -> 0.16666667 | E24: ='Loans Originated'!E30/'Loans Originated'!$G$30 -> 0.33333333 | F24: ='Loans Originated'!F30/'Loans Originated'!$G$30 -> 0.5
A25: 2008 | B25: ='Loans Originated'!B31/'Loans Originated'!$G$31 -> 0 | C25: ='Loans Originated'!C31/'Loans Originated'!$G$31 -> 0.013157895 | D25: ='Loans Originated'!D31/'Loans Originated'!$G$31 -> 0.19736842 | E25: ='Loans Originated'!E31/'Loans Originated'!$G$31 -> 0.18421053 | F25: ='Loans Originated'!F31/'Loans Originated'!$G$31 -> 0.59210526
A26: 2009 | B26: ='Loans Originated'!B32/'Loans Originated'!$G$32 -> 0.0074626866 | C26: ='Loans Originated'!C32/'Loans Originated'!$G$32 -> 0.074626866 | D26: ='Loans Originated'!D32/'Loans Originated'!$G$32 -> 0.39552239 | E26: ='Loans Originated'!E32/'Loans Originated'!$G$32 -> 0.14179104 | F26: ='Loans Originated'!F32/'Loans Originated'!$G$32 -> 0.37313433
A27: 2010 | B27: ='Loans Originated'!B33/'Loans Originated'!$G$33 -> 0.016528926 | C27: ='Loans Originated'!C33/'Loans Originated'!$G$33 -> 0.19834711 | D27: ='Loans Originated'!D33/'Loans Originated'!$G$33 -> 0.36363636 | E27: ='Loans Originated'!E33/'Loans Originated'!$G$33 -> 0.16528926 | F27: ='Loans Originated'!F33/'Loans Originated'!$G$33 -> 0.23966942
A28: 2011 | B28: ='Loans Originated'!B34/'Loans Originated'!$G$34 -> 0.017699115 | C28: ='Loans Originated'!C34/'Loans Originated'!$G$34 -> 0.20353982 | D28: ='Loans Originated'!D34/'Loans Originated'!$G$34 -> 0.32743363 | E28: ='Loans Originated'!E34/'Loans Originated'!$G$34 -> 0.15929204 | F28: ='Loans Originated'!F34/'Loans Originated'!$G$34 -> 0.2920354
A29: 2012 | B29: ='Loans Originated'!B35/'Loans Originated'!$G$35 -> 0 | C29: ='Loans Originated'!C35/'Loans Originated'!$G$35 -> 0.14159292 | D29: ='Loans Originated'!D35/'Loans Originated'!$G$35 -> 0.45132743 | E29: ='Loans Originated'!E35/'Loans Originated'!$G$35 -> 0.10619469 | F29: ='Loans Originated'!F35/'Loans Originated'!$G$35 -> 0.2920354
A31: Black Households | B31: 0-30% MFI | C31: 31-50% MFI | D31: 51-80% MFI | E31: 80-95% MFI | F31: >95% MFI
A32: 2006 | B32: ='Loans Originated'!B40/'Loans Originated'!$G$40 -> 0 | C32: ='Loans Originated'!C40/'Loans Originated'!$G$40 -> 0 | D32: ='Loans Originated'!D40/'Loans Originated'!$G$40 -> 0.42857143 | E32: ='Loans Originated'!E40/'Loans Originated'!$G$40 -> 0.14285714 | F32: ='Loans Originated'!F40/'Loans Originated'!$G$40 -> 0.42857143
A33: 2007 | B33: ='Loans Originated'!B41/'Loans Originated'!$G$41 -> 0 | C33: ='Loans Originated'!C41/'Loans Originated'!$G$41 -> 0 | D33: ='Loans Originated'!D41/'Loans Originated'!$G$41 -> 0.27272727 | E33: ='Loans Originated'!E41/'Loans Originated'!$G$41 -> 0.27272727 | F33: ='Loans Originated'!F41/'Loans Originated'!$G$41 -> 0.45454545
A34: 2008 | B34: ='Loans Originated'!B42/'Loans Originated'!$G$42 -> 0 | C34: ='Loans Originated'!C42/'Loans Originated'!$G$42 -> 0 | D34: ='Loans Originated'!D42/'Loans Originated'!$G$42 -> 0.19607843 | E34: ='Loans Originated'!E42/'Loans Originated'!$G$42 -> 0.23529412 | F34: ='Loans Originated'!F42/'Loans Originated'!$G$42 -> 0.56862745
A35: 2009 | B35: ='Loans Originated'!B43/'Loans Originated'!$G$43 -> 0 | C35: ='Loans Originated'!C43/'Loans Originated'!$G$43 -> 0.058823529 | D35: ='Loans Originated'!D43/'Loans Originated'!$G$43 -> 0.41176471 | E35: ='Loans Originated'!E43/'Loans Originated'!$G$43 -> 0.17647059 | F35: ='Loans Originated'!F43/'Loans Originated'!$G$43 -> 0.35294118
A36: 2010 | B36: ='Loans Originated'!B44/'Loans Originated'!$G$44 -> 0 | C36: ='Loans Originated'!C44/'Loans Originated'!$G$44 -> 0.11267606 | D36: ='Loans Originated'!D44/'Loans Originated'!$G$44 -> 0.45070423 | E36: ='Loans Originated'!E44/'Loans Originated'!$G$44 -> 0.14084507 | F36: ='Loans Originated'!F44/'Loans Originated'!$G$44 -> 0.26760563
A37: 2011 | B37: ='Loans Originated'!B45/'Loans Originated'!$G$45 -> 0 | C37: ='Loans Originated'!C45/'Loans Originated'!$G$45 -> 0.27083333 | D37: ='Loans Originated'!D45/'Loans Originated'!$G$45 -> 0.33333333 | E37: ='Loans Originated'!E45/'Loans Originated'!$G$45 -> 0.10416667 | F37: ='Loans Originated'!F45/'Loans Originated'!$G$45 -> 0.29166667
A38: 2012 | B38: ='Loans Originated'!B46/'Loans Originated'!$G$46 -> 0 | C38: ='Loans Originated'!C46/'Loans Originated'!$G$46 -> 0.13461538 | D38: ='Loans Originated'!D46/'Loans Originated'!$G$46 -> 0.36538462 | E38: ='Loans Originated'!E46/'Loans Originated'!$G$46 -> 0.17307692 | F38: ='Loans Originated'!F46/'Loans Originated'!$G$46 -> 0.30769231
A40: Native Hawaiian or Pacific Islander Households | B40: 0-30% MFI | C40: 31-50% MFI | D40: 51-80% MFI | E40: 80-95% MFI | F40: >95% MFI
A41: 2006 | B41: 0 | C41: 0 | D41: 0 | E41: 0 | F41: 0
A42: 2007 | B42: ='Loans Originated'!B52/'Loans Originated'!$G$52 -> 0 | C42: ='Loans Originated'!C52/'Loans Originated'!$G$52 -> 0 | D42: ='Loans Originated'!D52/'Loans Originated'!$G$52 -> 0 | E42: ='Loans Originated'!E52/'Loans Originated'!$G$52 -> 1 | F42: ='Loans Originated'!F52/'Loans Originated'!$G$52 -> 0
A43: 2008 | B43: ='Loans Originated'!B53/'Loans Originated'!$G$53 -> 0 | C43: ='Loans Originated'!C53/'Loans Originated'!$G$53 -> 0 | D43: ='Loans Originated'!D53/'Loans Originated'!$G$53 -> 0.36842105 | E43: ='Loans Originated'!E53/'Loans Originated'!$G$53 -> 0.15789474 | F43: ='Loans Originated'!F53/'Loans Originated'!$G$53 -> 0.47368421
A44: 2009 | B44: ='Loans Originated'!B54/'Loans Originated'!$G$54 -> 0 | C44: ='Loans Originated'!C54/'Loans Originated'!$G$54 -> 0.064516129 | D44: ='Loans Originated'!D54/'Loans Originated'!$G$54 -> 0.4516129 | E44: ='Loans Originated'!E54/'Loans Originated'!$G$54 -> 0.12903226 | F44: ='Loans Originated'!F54/'Loans Originated'!$G$54 -> 0.32258065
A45: 2010 | B45: ='Loans Originated'!B55/'Loans Originated'!$G$55 -> 0 | C45: ='Loans Originated'!C55/'Loans Originated'!$G$55 -> 0.125 | D45: ='Loans Originated'!D55/'Loans Originated'!$G$55 -> 0.375 | E45: ='Loans Originated'!E55/'Loans Originated'!$G$55 -> 0 | F45: ='Loans Originated'!F55/'Loans Originated'!$G$55 -> 0.5
...
