Workbook

Sheet Data
B1: Year | C1: Program | D1: Priority Campus | E1: Program Completers | F1: Respondents | G1: Respondents Employed, Related To Training | H1: Median Hourly Wage of Emp., Related To Training | I1: Respondents Employed, Unrelated To Training | J1: Total Employed | K1: Unemployed, Seeking Employment | L1: Unemployed, Not Seeking Employment | M1: Military Full-time | N1: Military Part-Time | O1: Total in Military | P1: Continuing Education (Secondary or Post-Secondary) | Q1: Apprenticeship related to FRCC training | R1: Apprenticeship unrelated to FRCC training | S1: Total in Apprenticeships | T1: Took State Licensing Exam | U1: Passed State Licensing Exam | V1: Instructional Program Met Educational Goals
A2: =C2=C34 -> TRUE | B2: 2013 | C2: Accounting | D2: Boulder County Campus | E2: 7 | F2: 5 | G2: 4 | I2: 0 | J2: 4 | K2: 0 | L2: 1 | M2: 0 | N2: 0 | O2: 0 | P2: 0 | Q2: 0 | R2: 0 | S2: 0 | T2: 0 | U2: 0 | V2: 5 | X2: =T2-F2 -> -5 | Y2: =U2-T2 -> 0
A3: =C3=C35 -> TRUE | B3: 2013 | C3: Accounting | D3: Larimer Campus | E3: 13 | F3: 9 | G3: 3 | I3: 2 | J3: 5 | K3: 0 | L3: 4 | M3: 0 | N3: 0 | O3: 0 | P3: 8 | Q3: 2 | R3: 1 | S3: 3 | T3: 0 | U3: 0 | V3: 9 | X3: =T3-F3 -> -9 | Y3: =U3-T3 -> 0
A4: =C4=C36 -> TRUE | B4: 2013 | C4: Accounting | D4: Online Campus | E4: 36 | F4: 16 | G4: 3 | I4: 5 | J4: 8 | K4: 2 | L4: 2 | M4: 0 | N4: 0 | O4: 0 | P4: 6 | Q4: 1 | R4: 0 | S4: 1 | T4: 0 | U4: 0 | V4: 9 | X4: =T4-F4 -> -16 | Y4: =U4-T4 -> 0
A5: =C5=C37 -> TRUE | B5: 2013 | C5: Accounting | D5: Westminster Campus | E5: 6 | F5: 4 | X5: =T5-F5 -> -4 | Y5: =U5-T5 -> 0
A6: =C6=C38 -> TRUE | B6: 2013 | C6: Automotive Technology | D6: Boulder County Campus | X6: =T6-F6 -> 0 | Y6: =U6-T6 -> 0
A7: =C7=C39 -> TRUE | B7: 2013 | C7: Automotive Technology | D7: Larimer Campus | E7: 32 | F7: 10 | G7: 5 | H7: 14.72 | I7: 2 | J7: 7 | K7: 1 | L7: 2 | M7: 0 | N7: 0 | O7: 0 | P7: 4 | Q7: 0 | R7: 0 | S7: 0 | T7: 2 | U7: 2 | V7: 10 | X7: =T7-F7 -> -8 | Y7: =U7-T7 -> 0
A8: =C8=C40 -> TRUE | B8: 2013 | C8: Automotive Technology | D8: Online Campus | X8: =T8-F8 -> 0 | Y8: =U8-T8 -> 0
A9: =C9=C41 -> TRUE | B9: 2013 | C9: Automotive Technology | D9: Westminster Campus | E9: 77 | F9: 33 | G9: 14 | H9: 12 | I9: 10 | J9: 24 | K9: 5 | L9: 3 | M9: 1 | N9: 0 | O9: 1 | P9: 16 | Q9: 3 | R9: 1 | S9: 4 | T9: 8 | U9: 8 | V9: 32 | X9: =T9-F9 -> -25 | Y9: =U9-T9 -> 0
A10: =C10=C42 -> TRUE | B10: 2013 | C10: Business | D10: Boulder County Campus | E10: 9 | F10: 6 | G10: 2 | I10: 3 | J10: 5 | K10: 0 | L10: 1 | M10: 0 | N10: 1 | O10: 1 | P10: 3 | Q10: 2 | R10: 0 | S10: 2 | T10: 2 | U10: 2 | V10: 6 | X10: =T10-F10 -> -4 | Y10: =U10-T10 -> 0
A11: =C11=C43 -> TRUE | B11: 2013 | C11: Business | D11: Larimer Campus | E11: 28 | F11: 19 | G11: 14 | H11: 14.75 | I11: 5 | J11: 19 | K11: 0 | L11: 0 | M11: 0 | N11: 0 | O11: 0 | P11: 12 | Q11: 2 | R11: 1 | S11: 3 | T11: 3 | U11: 3 | V11: 18 | X11: =T11-F11 -> -16 | Y11: =U11-T11 -> 0
A12: =C12=C44 -> TRUE | B12: 2013 | C12: Business | D12: Online Campus | E12: 55 | F12: 26 | G12: 13 | H12: 16 | I12: 7 | J12: 20 | K12: 3 | L12: 2 | M12: 0 | N12: 0 | O12: 0 | P12: 14 | Q12: 0 | R12: 1 | S12: 1 | T12: 2 | U12: 2 | V12: 25 | X12: =T12-F12 -> -24 | Y12: =U12-T12 -> 0
A13: =C13=C45 -> TRUE | B13: 2013 | C13: Business | D13: Westminster Campus | E13: 16 | F13: 10 | G13: 3 | I13: 1 | J13: 4 | K13: 5 | L13: 1 | M13: 0 | N13: 0 | O13: 0 | P13: 8 | Q13: 3 | R13: 1 | S13: 4 | T13: 1 | U13: 1 | V13: 8 | X13: =T13-F13 -> -9 | Y13: =U13-T13 -> 0
A14: =C14=C46 -> TRUE | B14: 2013 | C14: Computer Information Systems | D14: Boulder County Campus | E14: 31 | F14: 24 | G14: 6 | H14: 13 | I14: 10 | J14: 16 | K14: 5 | L14: 3 | M14: 0 | N14: 0 | O14: 0 | P14: 15 | Q14: 3 | R14: 1 | S14: 4 | T14: 3 | U14: 3 | V14: 18 | X14: =T14-F14 -> -21 | Y14: =U14-T14 -> 0
A15: =C15=C47 -> TRUE | B15: 2013 | C15: Computer Information Systems | D15: Larimer Campus | E15: 53 | F15: 38 | G15: 14 | H15: 17 | I15: 8 | J15: 22 | K15: 5 | L15: 11 | M15: 0 | N15: 0 | O15: 0 | P15: 24 | Q15: 1 | R15: 1 | S15: 2 | T15: 13 | U15: 11 | V15: 36 | X15: =T15-F15 -> -25 | Y15: =U15-T15 -> -2
A16: =C16=C48 -> TRUE | B16: 2013 | C16: Computer Information Systems | D16: Online Campus | E16: 55 | F16: 33 | G16: 17 | H16: 22.41 | I16: 7 | J16: 24 | K16: 8 | L16: 1 | M16: 0 | N16: 0 | O16: 0 | P16: 11 | Q16: 4 | R16: 0 | S16: 4 | T16: 3 | U16: 3 | V16: 29 | X16: =T16-F16 -> -30 | Y16: =U16-T16 -> 0
A17: =C17=C49 -> TRUE | B17: 2013 | C17: Computer Information Systems | D17: Westminster Campus | E17: 30 | F17: 17 | G17: 2 | I17: 5 | J17: 7 | K17: 7 | L17: 3 | M17: 0 | N17: 0 | O17: 0 | P17: 11 | Q17: 0 | R17: 2 | S17: 2 | T17: 4 | U17: 3 | V17: 13 | X17: =T17-F17 -> -13 | Y17: =U17-T17 -> -1
A18: =C18=C50 -> TRUE | B18: 2013 | C18: Emergency Medical Services | D18: Boulder County Campus | E18: 91 | F18: 47 | G18: 10 | H18: 12.43 | I18: 19 | J18: 29 | K18: 10 | L18: 8 | M18: 1 | N18: 1 | O18: 2 | P18: 27 | Q18: 16 | R18: 5 | S18: 21 | T18: 38 | U18: 34 | V18: 46 | X18: =T18-F18 -> -9 | Y18: =U18-T18 -> -4
A19: =C19=C51 -> TRUE | B19: 2013 | C19: Emergency Medical Services | D19: Larimer Campus | E19: 140 | F19: 66 | G19: 28 | H19: 14 | I19: 24 | J19: 52 | K19: 7 | L19: 7 | M19: 1 | N19: 1 | O19: 2 | P19: 36 | Q19: 19 | R19: 2 | S19: 21 | T19: 56 | U19: 53 | V19: 66 | X19: =T19-F19 -> -10 | Y19: =U19-T19 -> -3
A20: =C20=C52 -> TRUE | B20: 2013 | C20: Emergency Medical Services | D20: Online Campus | E20: 21 | F20: 13 | G20: 5 | H20: 13 | I20: 4 | J20: 9 | K20: 0 | L20: 0 | M20: 0 | N20: 0 | O20: 0 | P20: 6 | Q20: 2 | R20: 1 | S20: 3 | T20: 7 | U20: 7 | V20: 8 | X20: =T20-F20 -> -6 | Y20: =U20-T20 -> 0
A21: =C21=C53 -> TRUE | B21: 2013 | C21: Emergency Medical Services | D21: Westminster Campus | E21: 73 | F21: 26 | G21: 11 | H21: 12 | I21: 9 | J21: 20 | K21: 1 | L21: 3 | M21: 1 | N21: 0 | O21: 1 | P21: 14 | Q21: 6 | R21: 1 | S21: 7 | T21: 23 | U21: 23 | V21: 24 | X21: =T21-F21 -> -3 | Y21: =U21-T21 -> 0
A22: =C22=C54 -> TRUE | B22: 2013 | C22: Nurse Aide | D22: Boulder County Campus | E22: 66 | F22: 42 | G22: 16 | H22: 11.75 | I22: 12 | J22: 28 | K22: 7 | L22: 7 | M22: 0 | N22: 1 | O22: 1 | P22: 28 | Q22: 7 | R22: 3 | S22: 10 | T22: 33 | U22: 33 | V22: 41 | X22: =T22-F22 -> -9 | Y22: =U22-T22 -> 0
A23: =C23=C55 -> TRUE | B23: 2013 | C23: Nurse Aide | D23: Larimer Campus | E23: 154 | F23: 96 | G23: 49 | H23: 10.5 | I23: 29 | J23: 78 | K23: 6 | L23: 12 | M23: 0 | N23: 1 | O23: 1 | P23: 67 | Q23: 4 | R23: 17 | S23: 21 | T23: 87 | U23: 86 | V23: 95 | X23: =T23-F23 -> -9 | Y23: =U23-T23 -> -1
A24: =C24=C56 -> TRUE | B24: 2013 | C24: Nurse Aide | D24: Online Campus | E24: 67 | F24: 27 | G24: 8 | H24: 11 | I24: 9 | J24: 17 | K24: 2 | L24: 7 | M24: 0 | N24: 0 | O24: 0 | P24: 20 | Q24: 3 | R24: 0 | S24: 3 | T24: 20 | U24: 20 | V24: 25 | X24: =T24-F24 -> -7 | Y24: =U24-T24 -> 0
A25: =C25=C57 -> TRUE | B25: 2013 | C25: Nurse Aide | D25: Westminster Campus | E25: 135 | F25: 67 | G25: 24 | H25: 12 | I25: 28 | J25: 52 | K25: 7 | L25: 6 | M25: 0 | N25: 0 | O25: 0 | P25: 43 | Q25: 3 | R25: 7 | S25: 10 | T25: 50 | U25: 49 | V25: 61 | X25: =T25-F25 -> -17 | Y25: =U25-T25 -> -1
A26: =C26=C58 -> TRUE | B26: 2013 | C26: Practical Nursing | D26: Boulder County Campus | E26: 19 | F26: 10 | G26: 8 | H26: 19 | I26: 2 | J26: 10 | K26: 0 | L26: 0 | M26: 0 | N26: 0 | O26: 0 | P26: 4 | Q26: 0 | R26: 1 | S26: 1 | T26: 9 | U26: 9 | V26: 9 | X26: =T26-F26 -> -1 | Y26: =U26-T26 -> 0
A27: =C27=C59 -> TRUE | B27: 2013 | C27: Practical Nursing | D27: Larimer Campus | E27: 8 | F27: 6 | G27: 6 | H27: 25 | I27: 0 | J27: 6 | K27: 0 | L27: 0 | M27: 0 | N27: 0 | O27: 0 | P27: 3 | Q27: 0 | R27: 0 | S27: 0 | T27: 6 | U27: 6 | V27: 6 | X27: =T27-F27 -> 0 | Y27: =U27-T27 -> 0
A28: =C28=C60 -> TRUE | B28: 2013 | C28: Practical Nursing | D28: Online Campus | E28: 10 | F28: 6 | G28: 0 | I28: 0 | J28: 0 | K28: 0 | L28: 0 | M28: 0 | N28: 0 | O28: 0 | P28: 0 | Q28: 0 | R28: 0 | S28: 0 | T28: 0 | U28: 0 | V28: 0 | X28: =T28-F28 -> -6 | Y28: =U28-T28 -> 0
A29: =C29=C61 -> TRUE | B29: 2013 | C29: Practical Nursing | D29: Westminster Campus | E29: 10 | F29: 2 | X29: =T29-F29 -> -2 | Y29: =U29-T29 -> 0
A30: =C30=C62 -> TRUE | B30: 2013 | C30: Registered Nursing | D30: Boulder County Campus | E30: 18 | F30: 11 | G30: 10 | H30: 25.5 | I30: 0 | J30: 10 | K30: 1 | L30: 0 | M30: 0 | N30: 0 | O30: 0 | P30: 2 | Q30: 3 | R30: 1 | S30: 4 | T30: 11 | U30: 11 | V30: 10 | X30: =T30-F30 -> 0 | Y30: =U30-T30 -> 0
A31: =C31=C63 -> TRUE | B31: 2013 | C31: Registered Nursing | D31: Larimer Campus | E31: 64 | F31: 59 | G31: 52 | H31: 24.595 | I31: 5 | J31: 57 | K31: 0 | L31: 2 | M31: 0 | N31: 0 | O31: 0 | P31: 20 | Q31: 8 | R31: 4 | S31: 12 | T31: 59 | U31: 59 | V31: 59 | X31: =T31-F31 -> 0 | Y31: =U31-T31 -> 0
A32: =C32=C64 -> TRUE | B32: 2013 | C32: Registered Nursing | D32: Online Campus | E32: 2 | F32: 1 | X32: =T32-F32 -> -1 | Y32: =U32-T32 -> 0
A33: =C33=C65 -> TRUE | B33: 2013 | C33: Registered Nursing | D33: Westminster Campus | E33: 83 | F33: 38 | G33: 31 | I33: 3 | J33: 34 | K33: 1 | L33: 3 | M33: 0 | N33: 0 | O33: 0 | P33: 22 | Q33: 5 | R33: 1 | S33: 6 | T33: 38 | U33: 36 | V33: 37 | X33: =T33-F33 -> 0 | Y33: =U33-T33 -> -2
A34: =C34=C66 -> TRUE | B34: 2012 | C34: Accounting | D34: Boulder County Campus | E34: 12 | F34: 10 | G34: 4 | I34: 1 | J34: 5 | K34: 3 | L34: 2 | O34: 0 | P34: 4 | Q34: 1 | S34: 1 | T34: 2 | U34: 2 | V34: 8 | X34: =T34-F34 -> -8 | Y34: =U34-T34 -> 0
A35: =C35=C67 -> TRUE | B35: 2012 | C35: Accounting | D35: Larimer Campus | E35: 12 | F35: 12 | G35: 3 | I35: 8 | J35: 11 | L35: 1 | O35: 0 | P35: 2 | S35: 0 | T35: 1 | U35: 1 | V35: 12 | X35: =T35-F35 -> -11 | Y35: =U35-T35 -> 0
A36: =C36=C68 -> TRUE | B36: 2012 | C36: Accounting | D36: Online Campus | E36: 55 | F36: 40 | G36: 20 | H36: 18.2 | I36: 13 | J36: 33 | K36: 5 | L36: 2 | O36: 0 | P36: 17 | Q36: 2 | R36: 1 | S36: 3 | T36: 5 | U36: 5 | V36: 38 | X36: =T36-F36 -> -35 | Y36: =U36-T36 -> 0
A37: =C37=C69 -> TRUE | B37: 2012 | C37: Accounting | D37: Westminster Campus | E37: 9 | F37: 5 | G37: 1 | I37: 1 | J37: 2 | K37: 2 | L37: 1 | O37: 0 | P37: 3 | S37: 0 | V37: 3 | X37: =T37-F37 -> -5 | Y37: =U37-T37 -> 0
A38: =C38=C70 -> TRUE | B38: 2012 | C38: Automotive Technology | D38: Boulder County Campus | X38: =T38-F38 -> 0 | Y38: =U38-T38 -> 0
A39: =C39=C71 -> TRUE | B39: 2012 | C39: Automotive Technology | D39: Larimer Campus | E39: 48 | F39: 27 | G39: 16 | I39: 5 | J39: 21 | K39: 2 | L39: 4 | O39: 0 | P39: 6 | R39: 2 | S39: 2 | T39: 12 | U39: 12 | V39: 27 | X39: =T39-F39 -> -15 | Y39: =U39-T39 -> 0
A40: =C40=C72 -> TRUE | B40: 2012 | C40: Automotive Technology | D40: Online Campus | E40: 2 | F40: 2 | X40: =T40-F40 -> -2 | Y40: =U40-T40 -> 0
...

Sheet Pivot Table
B1: Values
A2: Row Labels | B2: Sum of Program Completers | C2: Sum of Respondents | D2: Sum of Median Hourly Wage of Emp., Related To Training | E2: Sum of Total Employed | F2: Sum of Total in Military | G2: Sum of Continuing Education (Secondary or Post-Secondary) | H2: Sum of Total in Apprenticeships | I2: Sum of Took State Licensing Exam | J2: Sum of Passed State Licensing Exam | K2: Sum of Instructional Program Met Educational Goals
A3: 2013 | B3: 1409 | C3: 767 | D3: 300.655 | E3: 567 | F3: 9 | G3: 424 | H3: 149 | I3: 478 | J3: 464 | K3: 705
A4: Accounting | B4: 62 | C4: 34 | E4: 17 | F4: 0 | G4: 14 | H4: 4 | I4: 0 | J4: 0 | K4: 23
A5: Boulder County Campus | B5: 7 | C5: 5 | E5: 4 | F5: 0 | G5: 0 | H5: 0 | I5: 0 | J5: 0 | K5: 5
A6: Larimer Campus | B6: 13 | C6: 9 | E6: 5 | F6: 0 | G6: 8 | H6: 3 | I6: 0 | J6: 0 | K6: 9
A7: Online Campus | B7: 36 | C7: 16 | E7: 8 | F7: 0 | G7: 6 | H7: 1 | I7: 0 | J7: 0 | K7: 9
A8: Westminster Campus | B8: 6 | C8: 4
A9: Automotive Technology | B9: 109 | C9: 43 | D9: 26.72 | E9: 31 | F9: 1 | G9: 20 | H9: 4 | I9: 10 | J9: 10 | K9: 42
A10: Boulder County Campus
A11: Larimer Campus | B11: 32 | C11: 10 | D11: 14.72 | E11: 7 | F11: 0 | G11: 4 | H11: 0 | I11: 2 | J11: 2 | K11: 10
A12: Online Campus
A13: Westminster Campus | B13: 77 | C13: 33 | D13: 12 | E13: 24 | F13: 1 | G13: 16 | H13: 4 | I13: 8 | J13: 8 | K13: 32
A14: Business | B14: 108 | C14: 61 | D14: 30.75 | E14: 48 | F14: 1 | G14: 37 | H14: 10 | I14: 8 | J14: 8 | K14: 57
A15: Boulder County Campus | B15: 9 | C15: 6 | E15: 5 | F15: 1 | G15: 3 | H15: 2 | I15: 2 | J15: 2 | K15: 6
A16: Larimer Campus | B16: 28 | C16: 19 | D16: 14.75 | E16: 19 | F16: 0 | G16: 12 | H16: 3 | I16: 3 | J16: 3 | K16: 18
A17: Online Campus | B17: 55 | C17: 26 | D17: 16 | E17: 20 | F17: 0 | G17: 14 | H17: 1 | I17: 2 | J17: 2 | K17: 25
A18: Westminster Campus | B18: 16 | C18: 10 | E18: 4 | F18: 0 | G18: 8 | H18: 4 | I18: 1 | J18: 1 | K18: 8
A19: Computer Information Systems | B19: 169 | C19: 112 | D19: 52.41 | E19: 69 | F19: 0 | G19: 61 | H19: 12 | I19: 23 | J19: 20 | K19: 96
A20: Boulder County Campus | B20: 31 | C20: 24 | D20: 13 | E20: 16 | F20: 0 | G20: 15 | H20: 4 | I20: 3 | J20: 3 | K20: 18
A21: Larimer Campus | B21: 53 | C21: 38 | D21: 17 | E21: 22 | F21: 0 | G21: 24 | H21: 2 | I21: 13 | J21: 11 | K21: 36
A22: Online Campus | B22: 55 | C22: 33 | D22: 22.41 | E22: 24 | F22: 0 | G22: 11 | H22: 4 | I22: 3 | J22: 3 | K22: 29
A23: Westminster Campus | B23: 30 | C23: 17 | E23: 7 | F23: 0 | G23: 11 | H23: 2 | I23: 4 | J23: 3 | K23: 13
A24: Emergency Medical Services | B24: 325 | C24: 152 | D24: 51.43 | E24: 110 | F24: 5 | G24: 83 | H24: 52 | I24: 124 | J24: 117 | K24: 144
A25: Boulder County Campus | B25: 91 | C25: 47 | D25: 12.43 | E25: 29 | F25: 2 | G25: 27 | H25: 21 | I25: 38 | J25: 34 | K25: 46
A26: Larimer Campus | B26: 140 | C26: 66 | D26: 14 | E26: 52 | F26: 2 | G26: 36 | H26: 21 | I26: 56 | J26: 53 | K26: 66
A27: Online Campus | B27: 21 | C27: 13 | D27: 13 | E27: 9 | F27: 0 | G27: 6 | H27: 3 | I27: 7 | J27: 7 | K27: 8
A28: Westminster Campus | B28: 73 | C28: 26 | D28: 12 | E28: 20 | F28: 1 | G28: 14 | H28: 7 | I28: 23 | J28: 23 | K28: 24
A29: Nurse Aide | B29: 422 | C29: 232 | D29: 45.25 | E29: 175 | F29: 2 | G29: 158 | H29: 44 | I29: 190 | J29: 188 | K29: 222
A30: Boulder County Campus | B30: 66 | C30: 42 | D30: 11.75 | E30: 28 | F30: 1 | G30: 28 | H30: 10 | I30: 33 | J30: 33 | K30: 41
A31: Larimer Campus | B31: 154 | C31: 96 | D31: 10.5 | E31: 78 | F31: 1 | G31: 67 | H31: 21 | I31: 87 | J31: 86 | K31: 95
A32: Online Campus | B32: 67 | C32: 27 | D32: 11 | E32: 17 | F32: 0 | G32: 20 | H32: 3 | I32: 20 | J32: 20 | K32: 25
A33: Westminster Campus | B33: 135 | C33: 67 | D33: 12 | E33: 52 | F33: 0 | G33: 43 | H33: 10 | I33: 50 | J33: 49 | K33: 61
A34: Practical Nursing | B34: 47 | C34: 24 | D34: 44 | E34: 16 | F34: 0 | G34: 7 | H34: 1 | I34: 15 | J34: 15 | K34: 15
A35: Boulder County Campus | B35: 19 | C35: 10 | D35: 19 | E35: 10 | F35: 0 | G35: 4 | H35: 1 | I35: 9 | J35: 9 | K35: 9
A36: Larimer Campus | B36: 8 | C36: 6 | D36: 25 | E36: 6 | F36: 0 | G36: 3 | H36: 0 | I36: 6 | J36: 6 | K36: 6
A37: Online Campus | B37: 10 | C37: 6 | E37: 0 | F37: 0 | G37: 0 | H37: 0 | I37: 0 | J37: 0 | K37: 0
A38: Westminster Campus | B38: 10 | C38: 2
A39: Registered Nursing | B39: 167 | C39: 109 | D39: 50.095 | E39: 101 | F39: 0 | G39: 44 | H39: 22 | I39: 108 | J39: 106 | K39: 106
A40: Boulder County Campus | B40: 18 | C40: 11 | D40: 25.5 | E40: 10 | F40: 0 | G40: 2 | H40: 4 | I40: 11 | J40: 11 | K40: 10
...

Sheet Options
D12: AVAILABLE PROGRAMS | E12: SELECTED PROGRAM | I12: AVAILABLE YEARS | J12: SELECTED YEAR | N12: AVAILABLE CAMPUSES | O12: SELECTED CAMPUS | T12: CHART DATA
D13: Accounting | E13: 6 | I13: 2007 | J13: 1 | N13: Boulder County Campus | O13: 4 | T13: COMPLETES | U13: RESPONDENTS | V13: RESPONSE RATE | W13: EMPLOYED | X13: EMPLOYED % | Y13: MEDIAN SALARY | Z13: MILITARY | AA13: MILITARY% | AB13: CONTINUING ED | AC13: CONTIN ED % | AD13: APPRENTICESHIPS | AE13: APPRENTICESHIP % | AF13: TOOK STATE LICENSING EXAM | AG13: TOOK EXAM % | AH13: PASSED LICENSING EXAM | AI13: PASSED EXAM % | AJ13: INSTRUCTIONAL GOALS | AK13: INSTRUCTIONALGOALS MET % | AM13: Completers Chart Title
D14: Automotive Technology | E14: =INDEX(D13:D20,E13) -> Nurse Aide | I14: 2008 | J14: =INDEX($I13:$I19,J13) -> 2007 | N14: Larimer Campus | O14: =INDEX(N13:N16,O13) -> Westminster Campus | S14: =I13 -> 2007 | T14: =GETPIVOTDATA("Sum of Program Completers",'Pivot Table'!$A$1,"Year",$S14,"Program",$E$14,"Priority Campus ",$O$14) -> 153 | U14: =GETPIVOTDATA("Sum of Respondents",'Pivot Table'!$A$1,"Year",$S14,"Program",$E$14,"Priority Campus ",$O$14) -> 84 | V14: =IF($T14>4,$U14/$T14) -> 0.54901961 | W14: =GETPIVOTDATA("Sum of Total Employed",'Pivot Table'!$A$1,"Year",$S14,"Program",$E$14,"Priority Campus ",$O$14) -> 65 | X14: =IF($U14>4,$W14/$U14) -> 0.77380952 | Y14: =GETPIVOTDATA("Sum of Median Hourly Wage of Emp., Related To Training",'Pivot Table'!$A$1,"Year",$S14,"Program",$E$14,"Priority Campus ",$O$14) -> 14.7194 | Z14: =GETPIVOTDATA("Sum of Total in Military",'Pivot Table'!$A$1,"Year",$S14,"Program",$E$14,"Priority Campus ",$O$14) -> 0 | AA14: =IF($U14>4,$Z14/$U14) -> 0 | AB14: =GETPIVOTDATA("Sum of Continuing Education (Secondary or Post-Secondary)",'Pivot Table'!$A$1,"Year",$S14,"Program",$E$14,"Priority Campus ",$O$14) -> 57 | AC14: =IF($U14>4,$AB14/$U14) -> 0.67857143 | AD14: =GETPIVOTDATA("Sum of Total in Apprenticeships",'Pivot Table'!$A$1,"Year",$S14,"Program",$E$14,"Priority Campus ",$O$14) -> 0 | AE14: =IF($U14>4,$AD14/$U14) -> 0 | AF14: =GETPIVOTDATA("Sum of Took State Licensing Exam",'Pivot Table'!$A$1,"Year",$S14,"Program",$E$14,"Priority Campus ",$O$14) -> 0 | AG14: =IF($U14>4,$AF14/$U14) -> 0 | AH14: =GETPIVOTDATA("Sum of Passed State Licensing Exam",'Pivot Table'!$A$1,"Year",$S14,"Program",$E$14,"Priority Campus ",$O$14) -> 0 | AI14: =IF($AF14>4,$AH14/$AF14) -> FALSE | AJ14: =GETPIVOTDATA("Sum of Instructional Program Met Educational Goals",'Pivot Table'!$A$1,"Year",$S14,"Program",$E$14,"Priority Campus ",$O$14) -> 80 | AK14: =IF($U14>4,$AJ14/$U14) -> 0.95238095 | AM14: ="Program Completers and Respondents" -> Program Completers and Respondents
D15: Business | I15: 2009 | N15: Online Campus | S15: =I14 -> 2008 | T15: =GETPIVOTDATA("Sum of Program Completers",'Pivot Table'!$A$1,"Year",$S15,"Program",$E$14,"Priority Campus ",$O$14) -> 141 | U15: =GETPIVOTDATA("Sum of Respondents",'Pivot Table'!$A$1,"Year",$S15,"Program",$E$14,"Priority Campus ",$O$14) -> 89 | V15: =IF($T15>4,$U15/$T15) -> 0.63120567 | W15: =GETPIVOTDATA("Sum of Total Employed",'Pivot Table'!$A$1,"Year",$S15,"Program",$E$14,"Priority Campus ",$O$14) -> 82 | X15: =IF($U15>4,$W15/$U15) -> 0.92134831 | Y15: =GETPIVOTDATA("Sum of Median Hourly Wage of Emp., Related To Training",'Pivot Table'!$A$1,"Year",$S15,"Program",$E$14,"Priority Campus ",$O$14) -> 11.860833 | Z15: =GETPIVOTDATA("Sum of Total in Military",'Pivot Table'!$A$1,"Year",$S15,"Program",$E$14,"Priority Campus ",$O$14) -> 0 | AA15: =IF($U15>4,$Z15/$U15) -> 0 | AB15: =GETPIVOTDATA("Sum of Continuing Education (Secondary or Post-Secondary)",'Pivot Table'!$A$1,"Year",$S15,"Program",$E$14,"Priority Campus ",$O$14) -> 26 | AC15: =IF($U15>4,$AB15/$U15) -> 0.29213483 | AD15: =GETPIVOTDATA("Sum of Total in Apprenticeships",'Pivot Table'!$A$1,"Year",$S15,"Program",$E$14,"Priority Campus ",$O$14) -> 12 | AE15: =IF($U15>4,$AD15/$U15) -> 0.13483146 | AF15: =GETPIVOTDATA("Sum of Took State Licensing Exam",'Pivot Table'!$A$1,"Year",$S15,"Program",$E$14,"Priority Campus ",$O$14) -> 61 | AG15: =IF($U15>4,$AF15/$U15) -> 0.68539326 | AH15: =GETPIVOTDATA("Sum of Passed State Licensing Exam",'Pivot Table'!$A$1,"Year",$S15,"Program",$E$14,"Priority Campus ",$O$14) -> 61 | AI15: =IF($AF15>4,$AH15/$AF15) -> 1 | AJ15: =GETPIVOTDATA("Sum of Instructional Program Met Educational Goals",'Pivot Table'!$A$1,"Year",$S15,"Program",$E$14,"Priority Campus ",$O$14) -> 87 | AK15: =IF($U15>4,$AJ15/$U15) -> 0.97752809 | AM15: Response Rate Chart Title
D16: Computer Information Systems | I16: 2010 | N16: Westminster Campus | S16: =I15 -> 2009 | T16: =GETPIVOTDATA("Sum of Program Completers",'Pivot Table'!$A$1,"Year",$S16,"Program",$E$14,"Priority Campus ",$O$14) -> 196 | U16: =GETPIVOTDATA("Sum of Respondents",'Pivot Table'!$A$1,"Year",$S16,"Program",$E$14,"Priority Campus ",$O$14) -> 106 | V16: =IF($T16>4,$U16/$T16) -> 0.54081633 | W16: =GETPIVOTDATA("Sum of Total Employed",'Pivot Table'!$A$1,"Year",$S16,"Program",$E$14,"Priority Campus ",$O$14) -> 82 | X16: =IF($U16>4,$W16/$U16) -> 0.77358491 | Y16: =GETPIVOTDATA("Sum of Median Hourly Wage of Emp., Related To Training",'Pivot Table'!$A$1,"Year",$S16,"Program",$E$14,"Priority Campus ",$O$14) -> 13 | Z16: =GETPIVOTDATA("Sum of Total in Military",'Pivot Table'!$A$1,"Year",$S16,"Program",$E$14,"Priority Campus ",$O$14) -> 0 | AA16: =IF($U16>4,$Z16/$U16) -> 0 | AB16: =GETPIVOTDATA("Sum of Continuing Education (Secondary or Post-Secondary)",'Pivot Table'!$A$1,"Year",$S16,"Program",$E$14,"Priority Campus ",$O$14) -> 65 | AC16: =IF($U16>4,$AB16/$U16) -> 0.61320755 | AD16: =GETPIVOTDATA("Sum of Total in Apprenticeships",'Pivot Table'!$A$1,"Year",$S16,"Program",$E$14,"Priority Campus ",$O$14) -> 17 | AE16: =IF($U16>4,$AD16/$U16) -> 0.16037736 | AF16: =GETPIVOTDATA("Sum of Took State Licensing Exam",'Pivot Table'!$A$1,"Year",$S16,"Program",$E$14,"Priority Campus ",$O$14) -> 94 | AG16: =IF($U16>4,$AF16/$U16) -> 0.88679245 | AH16: =GETPIVOTDATA("Sum of Passed State Licensing Exam",'Pivot Table'!$A$1,"Year",$S16,"Program",$E$14,"Priority Campus ",$O$14) -> 92 | AI16: =IF($AF16>4,$AH16/$AF16) -> 0.9787234 | AJ16: =GETPIVOTDATA("Sum of Instructional Program Met Educational Goals",'Pivot Table'!$A$1,"Year",$S16,"Program",$E$14,"Priority Campus ",$O$14) -> 99 | AK16: =IF($U16>4,$AJ16/$U16) -> 0.93396226 | AM16: ="Program Completers and Response Rate %" -> Program Completers and Response Rate %
D17: Emergency Medical Services | I17: 2011 | S17: =I16 -> 2010 | T17: =GETPIVOTDATA("Sum of Program Completers",'Pivot Table'!$A$1,"Year",$S17,"Program",$E$14,"Priority Campus ",$O$14) -> 148 | U17: =GETPIVOTDATA("Sum of Respondents",'Pivot Table'!$A$1,"Year",$S17,"Program",$E$14,"Priority Campus ",$O$14) -> 97 | V17: =IF($T17>4,$U17/$T17) -> 0.65540541 | W17: =GETPIVOTDATA("Sum of Total Employed",'Pivot Table'!$A$1,"Year",$S17,"Program",$E$14,"Priority Campus ",$O$14) -> 72 | X17: =IF($U17>4,$W17/$U17) -> 0.74226804 | Y17: =GETPIVOTDATA("Sum of Median Hourly Wage of Emp., Related To Training",'Pivot Table'!$A$1,"Year",$S17,"Program",$E$14,"Priority Campus ",$O$14) -> 12 | Z17: =GETPIVOTDATA("Sum of Total in Military",'Pivot Table'!$A$1,"Year",$S17,"Program",$E$14,"Priority Campus ",$O$14) -> 1 | AA17: =IF($U17>4,$Z17/$U17) -> 0.010309278 | AB17: =GETPIVOTDATA("Sum of Continuing Education (Secondary or Post-Secondary)",'Pivot Table'!$A$1,"Year",$S17,"Program",$E$14,"Priority Campus ",$O$14) -> 68 | AC17: =IF($U17>4,$AB17/$U17) -> 0.70103093 | AD17: =GETPIVOTDATA("Sum of Total in Apprenticeships",'Pivot Table'!$A$1,"Year",$S17,"Program",$E$14,"Priority Campus ",$O$14) -> 31 | AE17: =IF($U17>4,$AD17/$U17) -> 0.31958763 | AF17: =GETPIVOTDATA("Sum of Took State Licensing Exam",'Pivot Table'!$A$1,"Year",$S17,"Program",$E$14,"Priority Campus ",$O$14) -> 85 | AG17: =IF($U17>4,$AF17/$U17) -> 0.87628866 | AH17: =GETPIVOTDATA("Sum of Passed State Licensing Exam",'Pivot Table'!$A$1,"Year",$S17,"Program",$E$14,"Priority Campus ",$O$14) -> 85 | AI17: =IF($AF17>4,$AH17/$AF17) -> 1 | AJ17: =GETPIVOTDATA("Sum of Instructional Program Met Educational Goals",'Pivot Table'!$A$1,"Year",$S17,"Program",$E$14,"Priority Campus ",$O$14) -> 94 | AK17: =IF($U17>4,$AJ17/$U17) -> 0.96907216 | AM17: Employed Chart Title
D18: Nurse Aide | I18: 2012 | S18: =I17 -> 2011 | T18: =GETPIVOTDATA("Sum of Program Completers",'Pivot Table'!$A$1,"Year",$S18,"Program",$E$14,"Priority Campus ",$O$14) -> 171 | U18: =GETPIVOTDATA("Sum of Respondents",'Pivot Table'!$A$1,"Year",$S18,"Program",$E$14,"Priority Campus ",$O$14) -> 105 | V18: =IF($T18>4,$U18/$T18) -> 0.61403509 | W18: =GETPIVOTDATA("Sum of Total Employed",'Pivot Table'!$A$1,"Year",$S18,"Program",$E$14,"Priority Campus ",$O$14) -> 80 | X18: =IF($U18>4,$W18/$U18) -> 0.76190476 | Y18: =GETPIVOTDATA("Sum of Median Hourly Wage of Emp., Related To Training",'Pivot Table'!$A$1,"Year",$S18,"Program",$E$14,"Priority Campus ",$O$14) -> 13 | Z18: =GETPIVOTDATA("Sum of Total in Military",'Pivot Table'!$A$1,"Year",$S18,"Program",$E$14,"Priority Campus ",$O$14) -> 0 | AA18: =IF($U18>4,$Z18/$U18) -> 0 | AB18: =GETPIVOTDATA("Sum of Continuing Education (Secondary or Post-Secondary)",'Pivot Table'!$A$1,"Year",$S18,"Program",$E$14,"Priority Campus ",$O$14) -> 53 | AC18: =IF($U18>4,$AB18/$U18) -> 0.5047619 | AD18: =GETPIVOTDATA("Sum of Total in Apprenticeships",'Pivot Table'!$A$1,"Year",$S18,"Program",$E$14,"Priority Campus ",$O$14) -> 18 | AE18: =IF($U18>4,$AD18/$U18) -> 0.17142857 | AF18: =GETPIVOTDATA("Sum of Took State Licensing Exam",'Pivot Table'!$A$1,"Year",$S18,"Program",$E$14,"Priority Campus ",$O$14) -> 95 | AG18: =IF($U18>4,$AF18/$U18) -> 0.9047619 | AH18: =GETPIVOTDATA("Sum of Passed State Licensing Exam",'Pivot Table'!$A$1,"Year",$S18,"Program",$E$14,"Priority Campus ",$O$14) -> 93 | AI18: =IF($AF18>4,$AH18/$AF18) -> 0.97894737 | AJ18: =GETPIVOTDATA("Sum of Instructional Program Met Educational Goals",'Pivot Table'!$A$1,"Year",$S18,"Program",$E$14,"Priority Campus ",$O$14) -> 101 | AK18: =IF($U18>4,$AJ18/$U18) -> 0.96190476 | AM18: ="Total Employed %" -> Total Employed %
D19: Practical Nursing | I19: 2013 | S19: =I18 -> 2012 | T19: =GETPIVOTDATA("Sum of Program Completers",'Pivot Table'!$A$1,"Year",$S19,"Program",$E$14,"Priority Campus ",$O$14) -> 191 | U19: =GETPIVOTDATA("Sum of Respondents",'Pivot Table'!$A$1,"Year",$S19,"Program",$E$14,"Priority Campus ",$O$14) -> 112 | V19: =IF($T19>4,$U19/$T19) -> 0.58638743 | W19: =GETPIVOTDATA("Sum of Total Employed",'Pivot Table'!$A$1,"Year",$S19,"Program",$E$14,"Priority Campus ",$O$14) -> 76 | X19: =IF($U19>4,$W19/$U19) -> 0.67857143 | Y19: =GETPIVOTDATA("Sum of Median Hourly Wage of Emp., Related To Training",'Pivot Table'!$A$1,"Year",$S19,"Program",$E$14,"Priority Campus ",$O$14) -> 11.625 | Z19: =GETPIVOTDATA("Sum of Total in Military",'Pivot Table'!$A$1,"Year",$S19,"Program",$E$14,"Priority Campus ",$O$14) -> 0 | AA19: =IF($U19>4,$Z19/$U19) -> 0 | AB19: =GETPIVOTDATA("Sum of Continuing Education (Secondary or Post-Secondary)",'Pivot Table'!$A$1,"Year",$S19,"Program",$E$14,"Priority Campus ",$O$14) -> 87 | AC19: =IF($U19>4,$AB19/$U19) -> 0.77678571 | AD19: =GETPIVOTDATA("Sum of Total in Apprenticeships",'Pivot Table'!$A$1,"Year",$S19,"Program",$E$14,"Priority Campus ",$O$14) -> 12 | AE19: =IF($U19>4,$AD19/$U19) -> 0.10714286 | AF19: =GETPIVOTDATA("Sum of Took State Licensing Exam",'Pivot Table'!$A$1,"Year",$S19,"Program",$E$14,"Priority Campus ",$O$14) -> 97 | AG19: =IF($U19>4,$AF19/$U19) -> 0.86607143 | AH19: =GETPIVOTDATA("Sum of Passed State Licensing Exam",'Pivot Table'!$A$1,"Year",$S19,"Program",$E$14,"Priority Campus ",$O$14) -> 95 | AI19: =IF($AF19>4,$AH19/$AF19) -> 0.97938144 | AJ19: =GETPIVOTDATA("Sum of Instructional Program Met Educational Goals",'Pivot Table'!$A$1,"Year",$S19,"Program",$E$14,"Priority Campus ",$O$14) -> 110 | AK19: =IF($U19>4,$AJ19/$U19) -> 0.98214286 | AM19: Average Hourly Wage Chart Title
D20: Registered Nursing | S20: =I19 -> 2013 | T20: =GETPIVOTDATA("Sum of Program Completers",'Pivot Table'!$A$1,"Year",$S20,"Program",$E$14,"Priority Campus ",$O$14) -> 135 | U20: =GETPIVOTDATA("Sum of Respondents",'Pivot Table'!$A$1,"Year",$S20,"Program",$E$14,"Priority Campus ",$O$14) -> 67 | V20: =IF($T20>4,$U20/$T20) -> 0.4962963 | W20: =GETPIVOTDATA("Sum of Total Employed",'Pivot Table'!$A$1,"Year",$S20,"Program",$E$14,"Priority Campus ",$O$14) -> 52 | X20: =IF($U20>4,$W20/$U20) -> 0.7761194 | Y20: =GETPIVOTDATA("Sum of Median Hourly Wage of Emp., Related To Training",'Pivot Table'!$A$1,"Year",$S20,"Program",$E$14,"Priority Campus ",$O$14) -> 12 | Z20: =GETPIVOTDATA("Sum of Total in Military",'Pivot Table'!$A$1,"Year",$S20,"Program",$E$14,"Priority Campus ",$O$14) -> 0 | AA20: =IF($U20>4,$Z20/$U20) -> 0 | AB20: =GETPIVOTDATA("Sum of Continuing Education (Secondary or Post-Secondary)",'Pivot Table'!$A$1,"Year",$S20,"Program",$E$14,"Priority Campus ",$O$14) -> 43 | AC20: =IF($U20>4,$AB20/$U20) -> 0.64179104 | AD20: =GETPIVOTDATA("Sum of Total in Apprenticeships",'Pivot Table'!$A$1,"Year",$S20,"Program",$E$14,"Priority Campus ",$O$14) -> 10 | AE20: =IF($U20>4,$AD20/$U20) -> 0.14925373 | AF20: =GETPIVOTDATA("Sum of Took State Licensing Exam",'Pivot Table'!$A$1,"Year",$S20,"Program",$E$14,"Priority Campus ",$O$14) -> 50 | AG20: =IF($U20>4,$AF20/$U20) -> 0.74626866 | AH20: =GETPIVOTDATA("Sum of Passed State Licensing Exam",'Pivot Table'!$A$1,"Year",$S20,"Program",$E$14,"Priority Campus ",$O$14) -> 49 | AI20: =IF($AF20>4,$AH20/$AF20) -> 0.98 | AJ20: =GETPIVOTDATA("Sum of Instructional Program Met Educational Goals",'Pivot Table'!$A$1,"Year",$S20,"Program",$E$14,"Priority Campus ",$O$14) -> 61 | AK20: =IF($U20>4,$AJ20/$U20) -> 0.91044776 | AM20: ="Average Hourly Wage" -> Average Hourly Wage
AM21: Military Chart Title
AM22: ="Military : "&$E$14 -> Military : Nurse Aide
AM23: Continuing Education
AM24: ="Students Continuing their Education %" -> Students Continuing their Education %
AM25: Apprenticeships
AM26: ="Total Apprenticeships %" -> Total Apprenticeships %
AM27: Passed Exam
AM28: ="Passed Exam : "&$E$14 -> Passed Exam : Nurse Aide
AM29: Instructional Goals Met
AM30: ="Program Met Students Instructional Goals" -> Program Met Students Instructional Goals
AM31: State Licensing Exam
AM32: ="State Licensing Exam %" -> State Licensing Exam %

Sheet Introduction
B1: Introduction to the VE-135 Interactive Dashboard by Campus
B25: 1. At any time between October 1st and December 31st of (the preceding year) were you:
B26: Employed in an occupation related to your FRCC training
B27: Employed in an occupation NOT related to your FRCC training
B28: Unemployed and actively seeking employment
B29: Unemployed and NOT actively seeking employment
B31: 2. In order to help future students interested in your program know what they
B32: might expect, what is your hourly wage? (You will not be identified with this
B33: Information!)
B35: 3. Since completing your program last year (or as part of your graduation
B36: requirements), have you taken a state licensing test or an industry certification
B37: test related to your program
... B53: Not currently continuing your education

Sheet Main
D1: =Options!$E$14 -> Nurse Aide | K1: * | L1: =Options!O14 -> Westminster Campus
D31: If less than 5 respondents, no data reported.
D32: A priority campus reflects where the majority of hours are earned per term.
D33: Because the listed priority campus is based on the last term prior to graduation, it may not necessarily reflect where the majority of a degree was earned.
D34: *Priority campus may not actually have the program in existence

Sheet Success
D1: =Options!E14 -> Nurse Aide | K1: * | L1: =Options!O14 -> Westminster Campus
D31: If less than 5 respondents, no data reported.
D32: A priority campus reflects where the majority of hours are earned per term.
D33: Because the listed priority campus is based on the last term prior to graduation, it may not necessarily reflect where the majority of a degree was earned.
D34: *Priority campus may not actually have the program in existence
