Workbook

Sheet Instructions
A1: Worksheet Instructions
A3: Coversheet Tab:
A4: Step 1:
A5: Type in Business Name
A6: Type in Decision maker name | G6: Note: This spread sheet follows the guidance provided in chapeter 10 of the USDA NRCS National Engineering Handbook (NEH) Part 651, Ag Waste Management Field Handbook (AWMFH). It is flow charted on page 10-48, figure 10-33. Step by step instructions follow on pages 10-49 through 10-51. One possible outcome of the process when high nitrogen content wet material is mixed with high C:N material is that the mix will be too wet. The procedure calls for adding dry high C:N material until the ideal moisture is achieved and then possibly adding nitrogen fertilizer to finalize the batch with the proper moisture and C:N. Recommendations to add purchased nitrogen to a compost pile may not be well received by the operator. An alternative technique would be to get the C:N ratio at the 25 to 40 range on a dry weight basis, then dry the batch through the critical moisture range for the composting process to proceed without additional N. If the moisture content is too high to function as a dry litter system, then addition of N after removal from the pen may be unavoidable. Much will depend on the structure of the bulking agent; coarse wood chips will function as dry litter at higher moistures than softer smaller carbon materials. Jeffrey C. Wheaton, PE 12 March 2014
A7: Type in Address
A10: Compost Calculation Tab:
A11: Yellow boxes are input data | E11: Input Data
A12: Blue boxes are caculated for you | E12: Calculated Data
A13: Red boxes are the answers caculated for you | E13: Answer
A15: Step 2:
A16: Put in type of bulking agent
A17: Put in pen size width and length
A18: Put in thickness of bulking agent in pen
A19: Put in lb/ft3 or lb/yd3 for bulking agent
A20: See Reference tab for bulking agent information
A22: Step3:
A23: Put in moisture content % for bulking agent
A24: Put in nitrogen % for bulking agent
A25: Put in C:N Ratio for bulking agent
A26: See Reference tab for bulking agent information
A28: Step4:
... A41: See note at upper right for alternative methods to achieve an effective compost recipe without adding nitrogen (usually purchased).

Sheet Coversheet
B4: Composting Mixture
B6: Prepared for:
B8: Business name:
B9: Decision maker:
B10: Address:
B12: TMK:
B17: Prepared in cooperation with the:
B18: USDA – Natural Resources Conservation Service
B19: Edited by
B20: Resource Engineer David R. Fischer P.E. (Kealakekua S.C.)
B21: and
B22: Water Quality Specialist/Acting Agronomist Adam Reed (PIA State Office)
... B34: Revised 3/14/2014

Sheet Compost Calculation 
A2: Business name: | B2: =Coversheet!E8 -> 0
A3: Decision maker: | B3: =Coversheet!E9 -> 0
A4: Address: | B4: =Coversheet!E10 -> 0
B5: =Coversheet!E11 -> 0
A8: Determine estimated compost mix and composting time
A10: Given:
A11: Step1a:
A12: Bulking Agent:
A13: Pen Size: | C13: 'W x | E13: 'L = | F13: =B13*D13 -> 0 | G13: ft2
A14: amount: | C14: in thick x (1ft÷12in) x | D14: =$F$13 -> 0 | E14: ft2 x (1yd3÷27ft3) = | F14: =($B$14/12)*F$13*(1/27) -> 0 | G14: yd3
B15: =$F$14 -> 0 | C15: yd3 x (27ft3÷1yd3) x | D15: 0 | E15: lb/ft3 = | F15: =($F$14)*(27/1)*('Ref. Tables'!$C$7/1) -> 0 | G15: lbs/pen per day
B16: =$F$14 -> 0 | C16: yd3 x | D16: 0 | E16: lb/yd3 = | F16: =$B$16*$D$16 -> 0 | G16: lbs/pen per day
A17: Note: 12 inches in 1 foot, 27 ft3 in 1 yd3, and __lb/ft3 or _lb/yd3 for bulking agent
A18: See Ref. Tables Tab for bulking agent information
A20: Mwa% = moisture content: | D20: %
A21: % N = | C21: % | D21: C:N Ratio = | F21: :1
A22: See Ref. Tables for bulking agent information
A24: Manure:
A26: Animal Units (AU) = | D26: AU
A27: Mm% = percent moisture: | D27: %
A28: manure production: | D28: lbs/day/AU
A29: nitrogen production: | D29: lbs/day/AU | E29: See note on Instructions Tab for Nitrogen reductions that may occur because of volatilization.
B30: fixed solids: | D30: lbs/day/AU
A31: volatile solids: | D31: lbs/day/AU
A32: confined in building per day: | D32: day
B33: pens per building: | D33: pens/building
B34: hrs/day confined: | D34: hrs/day
A35: As excreted values computed separately. Use USDA NRCS National Engineering Handbook part 651, Ag Waste Management Field Handbook, ASAE Standard D384.1 Dec 93 Manure Production and Characteristics, or actual measurements and analysis (use representative sampling in sufficient numbers to justify extrapolating values, particularly if results are significantly different than book values). ASAE 1993 data includes standard deviation, useful for giving a range for evaluating reasonableness of site specific measurements.
A37: Step 1b: Determine Bulking Agent
A38: See bulking agent data above
A40: Step 2a: Determine the moisture content of the waste
A42: Wwa = wet weight of bulking agent in barn:
A43: amount: | B43: =$B$14 -> 0 | C43: in thick = | D43: =$F$14 -> 0 | E43: cu.yds = | F43: =$F$15 -> 0 | G43: lbs/pen per day
B44: =$F$43 -> 0 | C44: x pen per bld. | D44: =$C$33 -> 0 | E44: pens per bld. | F44: =$B$44*$D$44 -> 0 | G44: lbs/building per day
A46: Wm = wet weight of manure in building:
A47: Total AU *manure production*confined in building = | E47: =$C$26*$C$28*$C$32 -> 0 | F47: lbs per day
A49: Wmwa = wet weight of manure plus bulking agent
A50: Wmwa = Wwa + Wm = | C50: =$F$44+$E$47 -> 0 | D50: lbs per day
A51: determine moisture content of manure plus bulking agent:
A52: See Equation [10-11] p.10-49
...

Sheet Ref. Tables
A1: Table 4–3 Unit weights of common bedding materials 1/
C2: Loose | D2: Chopped
A3: Material | C3: - - - - - -lb/ft3- - - - - -
A4: Legume hay | C4: 4.3 | D4: 6.5
A5: Non legume hay | C5: 4 | D5: 6
A6: Straw | C6: 2.5 | D6: 7
A7: Wood shavings | C7: 9
A8: Sawdust | C8: 12
A9: Soil | C9: 75
A10: Sand | C10: 105
A11: Ground limestone | C11: 95
A12: 1/ Adapted from the 1992 version of the AWMFH
A15: Table 6–6 Plant nutrient uptake by specified crop and removed in the harvested part of the crop (Kilmer 1982; Morrison
A16: 1956; Sanchez 1976; USDA 1985)
B17: Dry wt. Typical | D17: - - Average concentration of nutrients (%) - -
B18: lb/bu | C18: yield/acre | D18: N | E18: P | F18: K
A19: Barley | B19: 48 | C19: 50 bu | D19: 1.82 | E19: 0.34 | F19: 0.43
C20: 1 T. straw | D20: 0.75 | E20: 0.11 | F20: 1.25
A21: Buckwheat | B21: 48 | C21: 30 bu | D21: 1.65 | E21: 0.31 | F21: 0.45
C22: 0.5 T. straw | D22: 0.78 | E22: 0.05 | F22: 2.26
A23: Corn | B23: 56 | C23: 120 bu | D23: 1.61 | E23: 0.28 | F23: 0.4
C24: 4.5 T. stover | D24: 1.11 | E24: 0.2 | F24: 1.34
A25: Oats | B25: 32 | C25: 80 bu | D25: 1.95 | E25: 0.34 | F25: 0.49
C26: 2 T. straw | D26: 0.63 | E26: 0.16 | F26: 1.66
A27: Rice | B27: 45 | C27: 5,500 lb | D27: 1.39 | E27: 0.24 | F27: 0.23
C28: 2.5 T. straw | D28: 0.6 | E28: 0.09 | F28: 1.16
A29: Rye | B29: 56 | C29: 30 bu | D29: 2.08 | E29: 0.26 | F29: 0.49
C30: 1.5 T. straw | D30: 0.5 | E30: 0.12 | F30: 0.69
A31: Sorghum | B31: 56 | C31: 60 bu | D31: 1.67 | E31: 0.36 | F31: 0.42
C32: 3 T. stover | D32: 1.08 | E32: 0.15 | F32: 1.31
A33: Wheat | B33: 60 | C33: 40 bu | D33: 2.08 | E33: 0.62 | F33: 0.52
C34: 1.5 T. straw | D34: 0.67 | E34: 0.07 | F34: 0.97
A35: Pulpwood | C35: 98 cords | D35: 0.12 | E35: 0.02 | F35: 0.06
C36: bark, branches | D36: 0.12 | E36: 0.02 | F36: 0.06
A37: Alfalfa | C37: 4 tons | D37: 2.25 | E37: 0.22 | F37: 1.87
A38: Guineagrass | C38: 10 tons | D38: 1.25 | E38: 0.44 | F38: 1.89
A39: Bermudagrass | C39: 8 tons | D39: 1.88 | E39: 0.19 | F39: 1.4
A40: Orchardgrass | C40: 6 tons | D40: 1.47 | E40: 0.2 | F40: 2.16
A41: Pangolagrass | C41: 10 tons | D41: 1.3 | E41: 0.47 | F41: 1.87
A42: Paragrass | C42: 10.5 tons | D42: 0.82 | E42: 0.39 | F42: 1.59
...
