Workbook

Sheet Summary
A1: Database Statistics Summary
A2: 2004-2005
A4: Database Name | B4: Vendor | C4: Sessions | D4: Searches | E4: Turnaways | F4: Successful full-text article requests | G4: Price | H4: Cost per Search
A5: ABI/INFORM Global | B5: ProQuest | C5: N/A | D5: =ProQuest!N7 -> 31305 | E5: 0 | F5: Not available | G5: =ProQuest!O7 -> 17500 | H5: =ProQuest!P7 -> 0.55901613
A6: ABI/INFORM Trade & Industry | B6: ProQuest | C6: N/A | D6: =ProQuest!N12 -> 11839 | E6: 0 | F6: Not available | G6: 0 | H6: N/A
A7: Academic Search Premier | B7: EBSCOhost | C7: =EBSCOhost!N6 -> 101876 | D7: =EBSCOhost!N7 -> 324728 | E7: 0 | F7: =EBSCOhost!N8 -> 224912 | G7: =EBSCOhost!O7 -> 18075 | H7: =EBSCOhost!P7 -> 0.055661969
A8: Alternative Press Index | B8: FirstSearch | C8: N/A | D8: =FirstSearch!N5 -> 79 | E8: 0 | F8: N/A | G8: =FirstSearch!O5 -> 79 | H8: =FirstSearch!P5 -> 1
A9: Alternative Press Index Archive | B9: FirstSearch | C9: N/A | D9: =FirstSearch!N8 -> 28 | E9: 0 | F9: N/A | G9: =FirstSearch!O8 -> 28 | H9: =FirstSearch!P8 -> 1
A10: America History & Life | B10: ABC-CLIO | C10: ='ABC-CLIO'!N8 -> 1984 | D10: ='ABC-CLIO'!N9 -> 2495 | E10: 0 | F10: N/A | G10: ='ABC-CLIO'!O9 -> 6124 | H10: ='ABC-CLIO'!P9 -> 2.454509
A11: American Humanities Index | B11: EBSCOhost | C11: =EBSCOhost!N13 -> 1392 | D11: =EBSCOhost!N14 -> 2458 | E11: 0 | F11: =EBSCOhost!N15 -> 6 | G11: 0 | H11: N/A
A12: Applied Science & Technology Abstracts | B12: WilsonWeb | C12: =WilsonWeb!N13 -> 588 | D12: =WilsonWeb!N14 -> 1993 | E12: =[1]WilsonWeb!N20 -> 0 | F12: N/A | G12: =WilsonWeb!O14 -> 5018 | H12: =WilsonWeb!P14 -> 2.5178123
A13: Art Abstracts | B13: WilsonWeb | C13: =WilsonWeb!N7 -> 791 | D13: =WilsonWeb!N8 -> 3443 | E13: =[1]WilsonWeb!N15 -> 0 | F13: N/A | G13: =WilsonWeb!O8 -> 4460 | H13: =WilsonWeb!P8 -> 1.2953819
A14: ArticleFirst* | B14: FirstSearch | C14: =FirstSearch!N11 -> 5450 | D14: =FirstSearch!N12 -> 13934 | E14: =FirstSearch!N14 -> 782 | F14: N/A | G14: 0 | H14: N/A
A15: ASFA: Aquatic Science & Fisheries Abstracts | B15: CSA | C15: N/A | D15: =CSA!N8 -> 46672 | E15: 0 | F15: N/A | G15: =CSA!O8 -> 6570 | H15: =CSA!P8 -> 0.14076963
A16: Bibliography & Index of Micropaleontology | B16: — | C16: Not avail. | D16: Not avail. | E16: Not avail. | F16: N/A | G16: 141 | H16: N/A
A17: Biological Abstracts / BIOSIS | B17: Ovid WEBSPIRS | C17: =WebSpirs!N7 -> 2083 | D17: =WebSpirs!N8 -> 7640 | E17: =WebSpirs!N9 -> 14 | F17: N/A | G17: =WebSpirs!O8 -> 21255 | H17: =WebSpirs!P8 -> 2.7820681
A18: Biological & Agricultural Index Plus* | B18: WilsonWeb | C18: =WilsonWeb!N19 -> 633 | D18: =WilsonWeb!N20 -> 2306 | E18: =WilsonWeb!N21 -> 15 | F18: N/A | G18: =WilsonWeb!O20 -> 2970 | H18: =WilsonWeb!P20 -> 1.2879445
A19: BIOSIS Previews | B19: OVID | C19: =OVID!N12 -> 55 | D19: =OVID!N13 -> 57 | E19: 0 | F19: N/A | G19: 0 | H19: N/A
A20: ChoiceReviews.online | B20: Choice | C20: Not avail. | D20: Not avail. | E20: Not avail. | F20: N/A | G20: 278.37 | H20: N/A
A21: CIAO | B21: CIAO | C21: =CIAO!N6 -> 1411 | D21: =CIAO!N7 -> 3546 | E21: 0 | F21: =CIAO!N8 -> 3994 | G21: =CIAO!O7 -> 901 | H21: =CIAO!P7 -> 0.25408911
A22: CINAHL | B22: OVID | C22: =OVID!N8 -> 7190 | D22: =OVID!N9 -> 24890 | E22: 0 | F22: Not available | G22: =OVID!O9 -> 5273 | H22: =OVID!P9 -> 0.21185215
A23: Cochrane Library | B23: Wiley InterScience | C23: Not avail. | D23: Not avail. | E23: 0 | F23: Not avail. | G23: 645 | H23: N/A
A24: CollegeSource | B24: CollegeSource | C24: N/A | D24: =CollegeSource!N7 -> 642 | E24: 0 | F24: N/A | G24: =CollegeSource!O7 -> 1263.57 | H24: =CollegeSource!P7 -> 1.9681776
A25: Communication Abstracts | B25: CSA | C25: N/A | D25: =CSA!N11 -> 9188 | E25: 0 | F25: N/A | G25: =CSA!O11 -> 2210 | H25: =CSA!P11 -> 0.24053113
A26: Compendex | B26: EI | C26: ='Compendex(EI)'!N7 -> 1712 | D26: ='Compendex(EI)'!N8 -> 4905 | E26: 0 | F26: N/A | G26: ='Compendex(EI)'!O8 -> 12800 | H26: ='Compendex(EI)'!P8 -> 2.6095821
A27: CSA (all databases) | B27: CSA | C27: =CSA!N53 -> 30084 | D27: =CSA!N54 -> 84219 | E27: 0 | F27: N/A | G27: =CSA!O54 -> 46645 | H27: =CSA!P54 -> 0.55385364
A28: EBSCO Animals | B28: EBSCOhost | C28: =EBSCOhost!N20 -> 961 | D28: =EBSCOhost!N21 -> 3026 | E28: 0 | F28: =EBSCOhost!N22 -> 355 | G28: 0 | H28: N/A
A29: EBSCOhost (all databases) | B29: EBSCOhost | C29: =EBSCOhost!N61 -> 137564 | D29: =EBSCOhost!N62 -> 342352 | E29: 0 | F29: =EBSCOhost!N63 -> 229929 | G29: =EBSCOhost!O62 -> 20775 | H29: =EBSCOhost!P62 -> 0.060683157
A30: EconLit | B30: CSA | C30: N/A | D30: =CSA!N14 -> 5447 | E30: 0 | F30: N/A | G30: =CSA!O14 -> 3990 | H30: =CSA!P14 -> 0.73251331
A31: Electronic Collections Online* | B31: FirstSearch | C31: =FirstSearch!N23 -> 1179 | D31: =FirstSearch!N24 -> 1654 | E31: =FirstSearch!N26 -> 25 | F31: URI does not subscribe to full text | G31: 0 | H31: N/A
A32: ERIC | B32: CSA | C32: N/A | D32: =CSA!N17 -> 3337 | E32: 0 | F32: N/A | G32: 0 | H32: N/A
A33: ERIC* | B33: FirstSearch | C33: =FirstSearch!N17 -> 3343 | D33: =FirstSearch!N18 -> 8594 | E33: =FirstSearch!N20 -> 880 | F33: N/A | G33: 0 | H33: N/A
A34: Family Index | B34: Family Index | C34: =FamilyIndex!N7 -> 1688 | D34: =FamilyIndex!N8 -> 1782 | E34: 0 | F34: N/A | G34: =FamilyIndex!O8 -> 313 | H34: =FamilyIndex!P8 -> 0.17564534
A35: FirstSearch (all databases) | B35: FirstSearch | C35: =FirstSearch!N89 -> 24603 | D35: =FirstSearch!N90 -> 61914 | E35: =FirstSearch!N92 -> 2908 | F35: N/A | G35: =FirstSearch!O90 -> 17051 | H35: =FirstSearch!P90 -> 0.27539813
A36: FirstSearch (“per-search” block searches) | B36: FirstSearch | C36: N/A | D36: =D8+D9+D38 -> 179 | E36: 0 | F36: N/A | G36: =G8+G9+G38 -> 179 | H36: 1
A37: Funk & Wagnall's New World Encyclopedia | B37: EBSCOhost | C37: =EBSCOhost!N27 -> 282 | D37: =EBSCOhost!N28 -> 756 | E37: 0 | F37: N/A | G37: 0 | H37: N/A
A38: GEOBASE | B38: FirstSearch | C38: N/A | D38: =FirstSearch!N29 -> 72 | E38: 0 | F38: N/A | G38: =FirstSearch!O29 -> 72 | H38: =FirstSearch!P29 -> 1
A39: GeoRef | B39: Community of Science | C39: Not avail. | D39: Not avail. | E39: Not avail. | F39: N/A | G39: 5900 | H39: N/A
A40: GPO Monthly Catalog* | B40: FirstSearch | C40: =FirstSearch!N33 -> 310 | D40: =FirstSearch!N34 -> 449 | E40: =FirstSearch!N36 -> 6 | F40: N/A | G40: 0 | H40: N/A
A41: Grove Music | B41: Oxford | C41: =GroveMusic!N6 -> 335 | D41: =GroveMusic!N7 -> 628 | E41: 0 | F41: N/A | G41: =GroveMusic!O7 -> 1386 | H41: =GroveMusic!P7 -> 2.2070064
...

Sheet ABC-CLIO
A1: ABC-CLIO Databases
A2: 2004-2005
A5: America History & Life | B5: 38169 | C5: 38200 | D5: 38231 | E5: 38261 | F5: 38292 | G5: 38322 | H5: 38353 | I5: 38384 | J5: 38412 | K5: 38443 | L5: 38473 | M5: 38504 | N5: Total | O5: 2004-2005 Price | P5: Price per search
A6: TOTAL
A7: AHL Database
A8: Sessions | B8: 60 | C8: 38 | D8: 111 | E8: 242 | F8: 355 | G8: 212 | H8: 52 | I8: 202 | J8: 269 | K8: 270 | L8: 119 | M8: 54 | N8: =SUM(B8:M8) -> 1984
A9: Searches | B9: 84 | C9: 75 | D9: 316 | E9: 303 | F9: 395 | G9: 207 | H9: 63 | I9: 218 | J9: 314 | K9: 346 | L9: 101 | M9: 73 | N9: =SUM(B9:M9) -> 2495 | O9: =12248/2 -> 6124 | P9: =O9/N9 -> 2.454509
A12: Historical Abstracts | B12: 38169 | C12: 38200 | D12: 38231 | E12: 38261 | F12: 38292 | G12: 38322 | H12: 38353 | I12: 38384 | J12: 38412 | K12: 38443 | L12: 38473 | M12: 38504 | N12: Total
A13: TOTAL
A14: HA Database
A15: Sessions | B15: 25 | C15: 6 | D15: 106 | E15: 155 | F15: 269 | G15: 83 | H15: 24 | I15: 71 | J15: 142 | K15: 144 | L15: 68 | M15: 12 | N15: =SUM(B15:M15) -> 1105
A16: Searches | B16: 18 | C16: 4 | D16: 119 | E16: 161 | F16: 337 | G16: 106 | H16: 35 | I16: 67 | J16: 163 | K16: 191 | L16: 64 | M16: 10 | N16: =SUM(B16:M16) -> 1275 | O16: =O9 -> 6124 | P16: =O16/N16 -> 4.8031373

Sheet CIAO
A1: CIAO
A2: 2004-2005
A4: Metric | B4: 38169 | C4: 38200 | D4: 38231 | E4: 38261 | F4: 38292 | G4: 38322 | H4: 38353 | I4: 38384 | J4: 38412 | K4: 38443 | L4: 38473 | M4: 38504 | N4: Total | O4: 2004-2005 Price | P4: Price per search
A5: TOTAL
A6: Sessions | B6: 4 | C6: 3 | D6: 30 | E6: 43 | F6: 144 | G6: 83 | H6: 31 | I6: 161 | J6: 337 | K6: 487 | L6: 74 | M6: 14 | N6: =SUM(B6:M6) -> 1411
A7: Searches | B7: 0 | C7: 0 | D7: 0 | E7: 0 | F7: 153 | G7: 159 | H7: 50 | I7: 643 | J7: 955 | K7: 1352 | L7: 204 | M7: 30 | N7: =SUM(B7:M7) -> 3546 | O7: 901 | P7: =O7/N7 -> 0.25408911
A8: Articles Viewed | B8: 0 | C8: 1 | D8: 23 | E8: 10 | F8: 131 | G8: 153 | H8: 48 | I8: 544 | J8: 1154 | K8: 1712 | L8: 189 | M8: 29 | N8: =SUM(B8:M8) -> 3994 | O8: 901 | P8: =O8/N8 -> 0.22558838

Sheet CollegeSource
A1: CollegeSource
A2: 2004-2005
A5: Metric | B5: 38169 | C5: 38200 | D5: 38231 | E5: 38261 | F5: 38292 | G5: 38322 | H5: 38353 | I5: 38384 | J5: 38412 | K5: 38443 | L5: 38473 | M5: 38504 | N5: Total | O5: 2004-2005 Price | P5: Price per search
A7: Searches | B7: 22 | C7: 16 | D7: 28 | E7: 75 | F7: 278 | G7: 23 | H7: 10 | I7: 33 | J7: 23 | K7: 66 | L7: 45 | M7: 23 | N7: =SUM(B7:M7) -> 642 | O7: 1263.57 | P7: =O7/N7 -> 1.9681776
A9: Service Errors | B9: 3 | C9: 2 | D9: 1 | E9: 6 | F9: 8 | G9: 2 | H9: 5 | I9: 9 | J9: 4 | K9: 85 | L9: 29 | M9: 25 | N9: =SUM(B9:M9) -> 179
A10: Turnaways | B10: 0 | C10: 0 | D10: 0 | E10: 0 | F10: 0 | G10: 0 | H10: 0 | I10: 0 | J10: 0 | K10: 0 | L10: 0 | M10: 0 | N10: =SUM(B10:M10) -> 0

Sheet Compendex(EI)
A1: Compendex (Engineering Index)
A2: 2004-2005
A5: Metric | B5: 38169 | C5: 38200 | D5: 38231 | E5: 38261 | F5: 38292 | G5: 38322 | H5: 38353 | I5: 38384 | J5: 38412 | K5: 38443 | L5: 38473 | M5: 38504 | N5: Total | O5: 2004-2005 Price | P5: Price per search
A6: TOTAL
A7: Sessions | B7: 167 | C7: 104 | D7: 128 | E7: 347 | F7: 157 | G7: 102 | H7: 87 | I7: 138 | J7: 163 | K7: 138 | L7: 103 | M7: 78 | N7: =SUM(B7:M7) -> 1712
A8: Searches | B8: 543 | C8: 229 | D8: 309 | E8: 804 | F8: 492 | G8: 332 | H8: 247 | I8: 344 | J8: 415 | K8: 579 | L8: 338 | M8: 273 | N8: =SUM(B8:M8) -> 4905 | O8: 12800 | P8: =O8/N8 -> 2.6095821
A9: Max Concurrent Users | B9: 5 | C9: 3 | D9: 30 | E9: 14 | F9: 4 | G9: 6 | H9: N/A | I9: N/A | J9: N/A | K9: N/A | L9: N/A | M9: N/A

Sheet CSA
A1: CSA Databases
A2: 2005-2006
A4: Metric | N4: Total
A5: TOTAL
O6: 2004-2005 Price | P6: Price per search
A7: ASFA | B7: 38169 | C7: 38200 | D7: 38231 | E7: 38261 | F7: 38292 | G7: 38322 | H7: 38353 | I7: 38384 | J7: 38412 | K7: 38443 | L7: 38473 | M7: 38504
A8: Searches | B8: =1073+869+4 -> 1946 | C8: =1096+1236 -> 2332 | D8: =1059+2048+2 -> 3109 | E8: =1381+3282 -> 4663 | F8: =1486+3934 -> 5420 | G8: =1130+1430 -> 2560 | H8: =1073+1293 -> 2366 | I8: =1022+2522+4 -> 3548 | J8: =1629+4709+4 -> 6342 | K8: =1476+6027+9 -> 7512 | L8: =1104+3194+6 -> 4304 | M8: =755+1812+3 -> 2570 | N8: =SUM(B8:M8) -> 46672 | O8: 6570 | P8: =O8/N8 -> 0.14076963
A10: Communication Abstracts | B10: 38169 | C10: 38200 | D10: 38231 | E10: 38261 | F10: 38292 | G10: 38322 | H10: 38353 | I10: 38384 | J10: 38412 | K10: 38443 | L10: 38473 | M10: 38504
A11: Searches | B11: =207+3+4 -> 214 | C11: =18+0 -> 18 | D11: =7+132 -> 139 | E11: =2+327 -> 329 | F11: =0+1209 -> 1209 | G11: =0+717 -> 717 | H11: =1+28 -> 29 | I11: =0+956 -> 956 | J11: =0+877+1 -> 878 | K11: =3+3215+19 -> 3237 | L11: =3+972+4 -> 979 | M11: =0+482+1 -> 483 | N11: =SUM(B11:M11) -> 9188 | O11: 2210 | P11: =O11/N11 -> 0.24053113
A13: EconLit | B13: 38169 | C13: 38200 | D13: 38231 | E13: 38261 | F13: 38292 | G13: 38322 | H13: 38353 | I13: 38384 | J13: 38412 | K13: 38443 | L13: 38473 | M13: 38504
A14: Searches | B14: =0+4+152 -> 156 | C14: =0+2+154 -> 156 | D14: =4+182+92 -> 278 | E14: =0+225+5 -> 230 | F14: =1+341+11 -> 353 | G14: =0+303+4 -> 307 | H14: =1+103+3 -> 107 | I14: =1+870+1 -> 872 | J14: =0+755+2 -> 757 | K14: =3+1327+41 -> 1371 | L14: =3+511+5 -> 519 | M14: =0+331+10 -> 341 | N14: =SUM(B14:M14) -> 5447 | O14: 3990 | P14: =O14/N14 -> 0.73251331
A16: ERIC | B16: 38169 | C16: 38200 | D16: 38231 | E16: 38261 | F16: 38292 | G16: 38322 | H16: 38353 | I16: 38384 | J16: 38412 | K16: 38443 | L16: 38473 | M16: 38504
A17: Searches | B17: =0+8+9 -> 17 | C17: =0+33 -> 33 | D17: =3+6 -> 9 | E17: =0+2 -> 2 | F17: =0+13+1 -> 14 | G17: =0+10+4 -> 14 | H17: =1+7 -> 8 | I17: =0+628 -> 628 | J17: =0+442+1 -> 443 | K17: =3+1359+18 -> 1380 | L17: =3+430+2 -> 435 | M17: =0+353+1 -> 354 | N17: =SUM(B17:M17) -> 3337 | O17: 0 | P17: N/A
A19: International Pharmaceutical Abstracts | B19: 38169 | C19: 38200 | D19: 38231 | E19: 38261 | F19: 38292 | G19: 38322 | H19: 38353 | I19: 38384 | J19: 38412 | K19: 38443 | L19: 38473 | M19: 38504
A20: Searches | B20: =0+36+2 -> 38 | C20: =0+26+1 -> 27 | D20: =4+13+116 -> 133 | E20: =0+86+63 -> 149 | F20: =1+54+144 -> 199 | G20: =8+17+79 -> 104 | H20: =89+15+84 -> 188 | I20: =237+91+53 -> 381 | J20: =256+173+147 -> 576 | K20: =166+128+317 -> 611 | L20: =200+78+72 -> 350 | M20: =127+48+63 -> 238 | N20: =SUM(B20:M20) -> 2994 | O20: 3280 | P20: =O20/N20 -> 1.0955244
A22: Meteorological & Geoastrophysical Abstracts | B22: 38169 | C22: 38200 | D22: 38231 | E22: 38261 | F22: 38292 | G22: 38322 | H22: 38353 | I22: 38384 | J22: 38412 | K22: 38443 | L22: 38473 | M22: 38504
A23: Searches | B23: =314+8+2 -> 324 | C23: =559+5+1 -> 565 | D23: =220+6 -> 226 | E23: =428+31 -> 459 | F23: =509+28 -> 537 | G23: =609+23 -> 632 | H23: =913+8 -> 921 | I23: =1014+84+4 -> 1102 | J23: =1607+135+4 -> 1746 | K23: =1273+119+6 -> 1398 | L23: =1043+63+6 -> 1112 | M23: =584+41+3 -> 628 | N23: =SUM(B23:M23) -> 9650 | O23: 3650 | P23: =O23/N23 -> 0.37823834
A25: NTIS | B25: 38169 | C25: 38200 | D25: 38231 | E25: 38261 | F25: 38292 | G25: 38322 | H25: 38353 | I25: 38384 | J25: 38412 | K25: 38443 | L25: 38473 | M25: 38504
A26: Searches | B26: 3 | C26: 0 | D26: 0 | E26: 0 | F26: 0 | G26: 0 | H26: 0 | I26: 0 | J26: 0 | K26: 0 | L26: 0 | M26: 0 | N26: =SUM(B26:M26) -> 3 | O26: 0 | P26: N/A
A28: Oceanic Abstracts | B28: 38169 | C28: 38200 | D28: 38231 | E28: 38261 | F28: 38292 | G28: 38322 | H28: 38353 | I28: 38384 | J28: 38412 | K28: 38443 | L28: 38473 | M28: 38504
A29: Searches | B29: =487+51+2 -> 540 | C29: =636+34 -> 670 | D29: =359+41 -> 400 | E29: =576+161 -> 737 | F29: =737+127 -> 864 | G29: =751+129 -> 880 | H29: =1028+15 -> 1043 | I29: =1031+163+3 -> 1197 | J29: =1614+478+3 -> 2095 | K29: =1295+399+7 -> 1701 | L29: =1050+152+5 -> 1207 | M29: =584+129+3 -> 716 | N29: =SUM(B29:M29) -> 12050 | O29: 0 | P29: N/A
O30: included with ASFA
A31: PAIS International | B31: 38169 | C31: 38200 | D31: 38231 | E31: 38261 | F31: 38292 | G31: 38322 | H31: 38353 | I31: 38384 | J31: 38412 | K31: 38443 | L31: 38473 | M31: 38504
A32: Searches | B32: =0+3+2 -> 5 | C32: =0+0+11 -> 11 | D32: =0+25+8 -> 33 | E32: =0+124+3 -> 127 | F32: =0+287+6 -> 293 | G32: =0+127+1 -> 128 | H32: =1+42+1 -> 44 | I32: =0+1984+25 -> 2009 | J32: =0+1466+10 -> 1476 | K32: =3+2337+21 -> 2361 | L32: =3+404+2 -> 409 | M32: =0+193+1 -> 194 | N32: =SUM(B32:M32) -> 7090 | O32: 4536 | P32: =O32/N32 -> 0.63977433
A34: Philosopher's Index | B34: 38169 | C34: 38200 | D34: 38231 | E34: 38261 | F34: 38292 | G34: 38322 | H34: 38353 | I34: 38384 | J34: 38412 | K34: 38443 | L34: 38473 | M34: 38504
A35: Searches | B35: =0+0 -> 0 | C35: =0+0 -> 0 | D35: =0+0 -> 0 | E35: =0+68 -> 68 | F35: =1+240 -> 241 | G35: =0+78 -> 78 | H35: =0+19 -> 19 | I35: =3+89+3 -> 95 | J35: =0+127 -> 127 | K35: =0+180 -> 180 | L35: =0+201+1 -> 202 | M35: =0+48 -> 48 | N35: =SUM(B35:M35) -> 1058 | O35: 1900 | P35: =O35/N35 -> 1.7958412
A37: Physical Education Index | B37: 38169 | C37: 38200 | D37: 38231 | E37: 38261 | F37: 38292 | G37: 38322 | H37: 38353 | I37: 38384 | J37: 38412 | K37: 38443 | L37: 38473 | M37: 38504
A38: Searches | B38: =0+5+10 -> 15 | C38: =0+4 -> 4 | D38: =3+22 -> 25 | E38: =0+20 -> 20 | F38: =0+73 -> 73 | G38: =8+45 -> 53 | H38: =90+9 -> 99 | I38: =237+717+4 -> 958 | J38: =256+583+5 -> 844 | K38: =169+1150+24 -> 1343 | L38: =203+339+8 -> 550 | M38: =126+168+4 -> 298 | N38: =SUM(B38:M38) -> 4282 | O38: 968 | P38: =O38/N38 -> 0.22606259
A40: Pollution Abstracts | B40: 38169 | C40: 38200 | D40: 38231 | E40: 38261 | F40: 38292 | G40: 38322 | H40: 38353 | I40: 38384 | J40: 38412 | K40: 38443 | L40: 38473 | M40: 38504
A41: Searches | B41: 45 | C41: =6+1 -> 7 | D41: =12+1 -> 13 | E41: 226 | F41: 42 | G41: 63 | H41: 0 | I41: =77+3 -> 80 | J41: =127+4 -> 131 | K41: =138+2 -> 140 | L41: =82+5 -> 87 | M41: =34+3 -> 37 | N41: =SUM(B41:M41) -> 871 | O41: 1585 | P41: =O41/N41 -> 1.8197474
A43: PsycINFO | B43: 38169 | C43: 38200 | D43: 38231 | E43: 38261 | F43: 38292 | G43: 38322 | H43: 38353 | I43: 38384 | J43: 38412 | K43: 38443 | L43: 38473 | M43: 38504
A44: Searches | B44: =0+1525+11 -> 1536 | C44: =1+1131+1 -> 1133 | D44: =0+2918 -> 2918 | E44: =0+4281 -> 4281 | F44: =0+5516+1 -> 5517 | G44: =0+2954 -> 2954 | H44: =1+1450 -> 1451 | I44: =0+3958+1 -> 3959 | J44: =0+4065+2 -> 4067 | K44: =3+4769+23 -> 4795 | L44: =3+2581+3 -> 2587 | M44: =0+1101+1 -> 1102 | N44: =SUM(B44:M44) -> 36300 | O44: 14263 | P44: =O44/N44 -> 0.39292011
A46: Social Services Abstracts | B46: 38169 | C46: 38200 | D46: 38231 | E46: 38261 | F46: 38292 | G46: 38322 | H46: 38353 | I46: 38384 | J46: 38412 | K46: 38443 | L46: 38473 | M46: 38504
A47: Searches | B47: =0+2+134 -> 136 | C47: =0+3+19 -> 22 | D47: =1+53+7 -> 61 | E47: =0+142+4 -> 146 | F47: =0+196+4 -> 200 | G47: =0+174 -> 174 | H47: =1+57 -> 58 | I47: =1+742+1 -> 744 | J47: =0+611+2 -> 613 | K47: =3+1145+23 -> 1171 | L47: =3+355+2 -> 360 | M47: =0+194+1 -> 195 | N47: =SUM(B47:M47) -> 3880 | O47: 0 | P47: N/A
A49: Sociological Abstracts | B49: 38169 | C49: 38200 | D49: 38231 | E49: 38261 | F49: 38292 | G49: 38322 | H49: 38353 | I49: 38384 | J49: 38412 | K49: 38443 | L49: 38473 | M49: 38504
A50: Searches | B50: =2+7+215 -> 224 | C50: =0+9+66 -> 75 | D50: =1+105+16 -> 122 | E50: =0+373+8 -> 381 | F50: =0+454+1 -> 455 | G50: =0+365+5 -> 370 | H50: =1+94+0 -> 95 | I50: =1+890+12 -> 903 | J50: =0+667+2 -> 669 | K50: =3+1464+22 -> 1489 | L50: =3+490+8 -> 501 | M50: =0+224+1 -> 225 | N50: =SUM(B50:M50) -> 5509 | O50: 3693 | P50: =O50/N50 -> 0.6703576
A52: CSA Databases total | B52: 38169 | C52: 38200 | D52: 38231 | E52: 38261 | F52: 38292 | G52: 38322 | H52: 38353 | I52: 38384 | J52: 38412 | K52: 38443 | L52: 38473 | M52: 38504
A53: Session | B53: =430+633+201 -> 1264 | C53: =342+395+94 -> 831 | D53: =444+1712+106 -> 2262 | E53: =514+2881+42 -> 3437 | F53: =499+3812+79 -> 4390 | G53: =361+1816+35 -> 2212 | H53: =382+820+33 -> 1235 | I53: =415+2964+51 -> 3430 | J53: =474+2670+103 -> 3247 | K53: =428+4066+154 -> 4648 | L53: =332+1609+45 -> 1986 | M53: =226+892+24 -> 1142 | N53: =SUM(B53:M53) -> 30084
A54: Searches | B54: =1364+1961+516 -> 3841 | C54: =1261+1608+252 -> 3121 | D54: =1143+4339+240 -> 5722 | E54: =1464+7325+83 -> 8872 | F54: =1557+9915+164 -> 11636 | G54: =1184+5397+89 -> 6670 | H54: =1118+2232+88 -> 3438 | I54: =1047+7089+91 -> 8227 | J54: =1634+7835+158 -> 9627 | K54: =1341+11791+363 -> 13495 | L54: =1068+5132+84 -> 6284 | M54: =626+2587+73 -> 3286 | N54: =SUM(B54:M54) -> 84219 | O54: =SUM(O8:O51) -> 46645 | P54: =O54/N54 -> 0.55385364
A55: Searches per Session | B55: =B54/B53 -> 3.0387658 | C55: =C54/C53 -> 3.755716 | D55: =D54/D53 -> 2.5296198 | E55: =E54/E53 -> 2.5813209 | F55: =F54/F53 -> 2.6505695 | G55: =G54/G53 -> 3.0153707 | H55: =H54/H53 -> 2.7838057 | I55: =I54/I53 -> 2.3985423 | ... M55: =M54/M53 -> 2.8774081
...

Sheet EBSCOhost
A1: EBSCO Databases
A2: 2004-2005
A4: Academic Search Premier | B4: 38169 | C4: 38200 | D4: 38231 | E4: 38261 | F4: 38292 | G4: 38322 | H4: 38353 | I4: 38384 | J4: 38412 | K4: 38443 | L4: 38473 | M4: 38504 | N4: Total | O4: 2004-2005 Price | P4: Price per unit
A5: TOTAL
A6: Sessions | B6: 8 | C6: 1224 | D6: 5858 | E6: 14893 | F6: 17666 | G6: 9894 | H6: 2281 | I6: 10084 | J6: 12403 | K6: 17208 | L6: 6952 | M6: 3405 | N6: =SUM(B6:M6) -> 101876
A7: Searches | B7: 8 | C7: 3450 | D7: 15883 | E7: 45228 | F7: 50984 | G7: 26729 | H7: 6760 | I7: 37116 | J7: 44800 | K7: 59492 | L7: 21967 | M7: 12311 | N7: =SUM(B7:M7) -> 324728 | O7: 18075 | P7: =O7/N7 -> 0.055661969
A8: Successful Full Text Article Requests | B8: 1 | C8: 2295 | D8: 10252 | E8: 27601 | F8: 35493 | G8: 21335 | H8: 5095 | I8: 23754 | J8: 31369 | K8: 43814 | L8: 16281 | M8: 7622 | N8: =SUM(B8:M8) -> 224912 | O8: 18075 | P8: =O8/N8 -> 0.080364765
A11: American Humanities Index | B11: Jul | C11: Aug | D11: Sep | E11: Oct | F11: Nov | G11: Dec | H11: Jan | I11: Feb | J11: Mar | K11: Apr | L11: May | M11: Jun | N11: Total
A12: TOTAL
A13: Sessions | B13: 0 | C13: 30 | D13: 259 | E13: 299 | F13: 369 | G13: 431 | H13: 4 | I13: 0 | J13: 0 | K13: 0 | L13: 0 | M13: 0 | N13: =SUM(B13:M13) -> 1392
A14: Searches | B14: 0 | C14: 33 | D14: 390 | E14: 535 | F14: 669 | G14: 800 | H14: 31 | I14: 0 | J14: 0 | K14: 0 | L14: 0 | M14: 0 | N14: =SUM(B14:M14) -> 2458 | O14: 0 | P14: N/A
A15: Successful Full-Text Article Requests | B15: 0 | C15: 0 | D15: 0 | E15: 0 | F15: 0 | G15: 0 | H15: 6 | I15: 0 | J15: 0 | K15: 0 | L15: 0 | M15: 0 | N15: =SUM(B15:M15) -> 6 | O15: Free trial
A19: EBSCO Animals | B19: 38169 | C19: 38200 | D19: 38231 | E19: 38261 | F19: 38292 | G19: 38322 | H19: 38353 | I19: 38384 | J19: 38412 | K19: 38443 | L19: 38473 | M19: 38504
A20: Sessions | B20: 0 | C20: 12 | D20: 60 | E20: 118 | F20: 149 | G20: 58 | H20: 18 | I20: 115 | J20: 104 | K20: 240 | L20: 73 | M20: 14 | N20: =SUM(B20:M20) -> 961
A21: Searches | B21: 0 | C21: 38 | D21: 194 | E21: 390 | F21: 510 | G21: 136 | H21: 50 | I21: 393 | J21: 323 | K21: 728 | L21: 235 | M21: 29 | N21: =SUM(B21:M21) -> 3026 | O21: 0 | P21: N/A
A22: Successful Full-Text Article Requests | B22: 0 | C22: 2 | D22: 16 | E22: 33 | F22: 16 | G22: 5 | H22: 4 | I22: 51 | J22: 27 | K22: 144 | L22: 55 | M22: 2 | N22: =SUM(B22:M22) -> 355 | O22: 0 | P22: N/A
A26: Funk & Wagnall's New World Encyclopedia | B26: 38169 | C26: 38200 | D26: 38231 | E26: 38261 | F26: 38292 | G26: 38322 | H26: 38353 | I26: 38384 | J26: 38412 | K26: 38443 | L26: 38473 | M26: 38504
A27: Sessions | B27: 0 | C27: 3 | D27: 28 | E27: 26 | F27: 40 | G27: 26 | H27: 8 | I27: 16 | J27: 39 | K27: 44 | L27: 33 | M27: 19 | N27: =SUM(B27:M27) -> 282
A28: Searches | B28: 0 | C28: 3 | D28: 75 | E28: 57 | F28: 104 | G28: 42 | H28: 21 | I28: 31 | J28: 101 | K28: 137 | L28: 122 | M28: 63 | N28: =SUM(B28:M28) -> 756 | O28: 0 | P28: N/A
A29: Successful Full-Text Article Requests | B29: N/A | C29: N/A | D29: N/A | E29: N/A | F29: N/A | G29: N/A | H29: N/A | I29: N/A | J29: N/A | K29: N/A | L29: N/A | M29: N/A | N29: N/A | O29: 0 | P29: N/A
A33: MAS Ultra - School edition | B33: 38169 | C33: 38200 | D33: 38231 | E33: 38261 | F33: 38292 | G33: 38322 | H33: 38353 | I33: 38384 | J33: 38412 | K33: 38443 | L33: 38473 | M33: 38504
A34: Sessions | B34: 0 | C34: 5 | D34: 37 | E34: 96 | F34: 91 | G34: 43 | H34: 26 | I34: 51 | J34: 51 | K34: 90 | L34: 45 | M34: 22 | N34: =SUM(B34:M34) -> 557
A35: Searches | B35: 0 | C35: 4 | D35: 134 | E35: 308 | F35: 252 | G35: 87 | H35: 53 | I35: 119 | J35: 115 | K35: 289 | L35: 160 | M35: 49 | N35: =SUM(B35:M35) -> 1570 | O35: 0 | P35: N/A
A36: Successful Full-Text Article Requests | B36: 0 | C36: 2 | D36: 77 | E36: 165 | F36: 137 | G36: 118 | H36: 39 | I36: 109 | J36: 84 | K36: 217 | L36: 77 | M36: 45 | N36: =SUM(B36:M36) -> 1070 | O36: 0 | P36: N/A
A40: Military & Govt Collection | B40: 38169 | C40: 38200 | D40: 38231 | E40: 38261 | F40: 38292 | G40: 38322 | H40: 38353 | I40: 38384 | J40: 38412 | K40: 38443 | L40: 38473 | M40: 38504
A41: Sessions | B41: 0 | C41: 1 | D41: 26 | E41: 52 | F41: 77 | G41: 51 | H41: 16 | I41: 35 | J41: 73 | K41: 167 | L41: 55 | M41: 9 | N41: =SUM(B41:M41) -> 562
A42: Searches | B42: 0 | C42: 6 | D42: 45 | E42: 135 | F42: 187 | G42: 73 | H42: 52 | I42: 98 | J42: 161 | K42: 351 | L42: 146 | M42: 21 | N42: =SUM(B42:M42) -> 1275 | O42: 0 | P42: N/A
A43: Successful Full-Text Article Requests | B43: 0 | C43: 0 | D43: 24 | E43: 67 | F43: 117 | G43: 51 | H43: 7 | I43: 33 | J43: 124 | K43: 221 | L43: 99 | M43: 9 | N43: =SUM(B43:M43) -> 752 | O43: 0 | P43: N/A
A47: Primary Search | B47: 38169 | C47: 38200 | D47: 38231 | E47: 38261 | F47: 38292 | G47: 38322 | H47: 38353 | I47: 38384 | J47: 38412 | K47: 38443 | L47: 38473 | M47: 38504
A48: Sessions | B48: 0 | C48: 7 | D48: 33 | E48: 93 | F48: 86 | G48: 52 | H48: 8 | I48: 55 | J48: 59 | K48: 90 | L48: 53 | M48: 26 | N48: =SUM(B48:M48) -> 562
A49: Searches | B49: 0 | C49: 15 | D49: 114 | E49: 321 | F49: 273 | G49: 155 | H49: 16 | I49: 243 | J49: 263 | K49: 417 | L49: 259 | M49: 103 | N49: =SUM(B49:M49) -> 2179 | O49: 0 | P49: N/A
A50: Successful Full-Text Article Requests | B50: 0 | C50: 0 | D50: 22 | E50: 47 | F50: 59 | G50: 26 | H50: 1 | I50: 35 | J50: 32 | K50: 42 | L50: 40 | M50: 14 | N50: =SUM(B50:M50) -> 318 | O50: 0 | P50: N/A
A53: Textile Technology Index | B53: 38169 | C53: 38200 | D53: 38231 | E53: 38261 | F53: 38292 | G53: 38322 | H53: 38353 | I53: 38384 | J53: 38412 | K53: 38443 | L53: 38473 | M53: 38504 | N53: Total
A54: TOTAL
A55: Sessions | B55: 1 | C55: 1 | D55: 24 | E55: 74 | F55: 39 | G55: 16 | H55: 5 | I55: 67 | J55: 26 | K55: 57 | L55: 10 | M55: 4 | N55: =SUM(B55:M55) -> 324
A56: Searches | B56: 0 | C56: 1 | D56: 53 | E56: 200 | F56: 65 | G56: 40 | H56: 5 | I56: 305 | J56: 108 | K56: 297 | L56: 33 | M56: 23 | N56: =SUM(B56:M56) -> 1130 | O56: 2700 | P56: =O56/N56 -> 2.3893805
A60: EBSCO All Databases | B60: 38169 | C60: 38200 | D60: 38231 | E60: 38261 | F60: 38292 | G60: 38322 | H60: 38353 | I60: 38384 | J60: 38412 | K60: 38443 | L60: 38473 | M60: 38504
A61: Sessions | B61: 7 | C61: 2088 | D61: 9336 | E61: 21647 | F61: 25489 | G61: 14363 | H61: 3189 | I61: 12595 | J61: 15004 | K61: 21248 | L61: 8451 | M61: 4147 | N61: =SUM(B61:M61) -> 137564
A62: Searches | B62: 5 | C62: 3587 | D62: 17273 | E62: 48446 | F62: 54942 | G62: 29279 | H62: 7012 | I62: 38317 | J62: 45911 | K62: 61901 | L62: 23008 | M62: 12671 | N62: =SUM(B62:M62) -> 342352 | O62: =O7+O56 -> 20775 | P62: =O62/N62 -> 0.060683157
A63: Successful Full-Text Article Requests | B63: 1 | C63: 2336 | D63: 10585 | E63: 28528 | F63: 36907 | G63: 22382 | H63: 5169 | I63: 23931 | J63: 31609 | K63: 44294 | L63: 16497 | M63: 7690 | N63: =SUM(B63:M63) -> 229929 | O63: =O62 -> 20775 | P63: =O63/N63 -> 0.090353979

Sheet FamilyIndex
A1: Family Index
A2: 2004-2005
A5: Metric | B5: 38169 | C5: 38200 | D5: 38231 | E5: 38261 | F5: 38292 | G5: 38322 | H5: 38353 | I5: 38384 | J5: 38412 | K5: 38443 | L5: 38473 | M5: 38504 | N5: Total | O5: Price for 2004-2005 | P5: Price per search
A6: TOTAL
A7: Sessions | B7: 55 | C7: 19 | D7: 127 | E7: 376 | F7: 151 | G7: 61 | H7: 29 | I7: 95 | J7: 369 | K7: 274 | L7: 121 | M7: 11 | N7: =SUM(B7:M7) -> 1688
A8: Searches | B8: 29 | C8: 6 | D8: 76 | E8: 247 | F8: 388 | G8: 168 | H8: 115 | I8: 239 | J8: 267 | K8: 166 | L8: 72 | M8: 9 | N8: =SUM(B8:M8) -> 1782 | O8: 313 | P8: =O8/N8 -> 0.17564534

Sheet FirstSearch
A1: FirstSearch
A2: 2004-2005
A4: Alternative Press Index | B4: 38169 | C4: 38200 | D4: 38231 | E4: 38261 | F4: 38292 | G4: 38322 | H4: 38353 | I4: 38384 | J4: 38412 | K4: 38443 | L4: 38473 | M4: 38504 | O4: Price for 2004-2005 | P4: Price per search
A5: Searches | B5: 3 | C5: 0 | D5: 13 | E5: 26 | F5: 3 | G5: 2 | H5: 0 | I5: 5 | J5: 27 | K5: 0 | L5: 0 | M5: 0 | N5: =SUM(B5:M5) -> 79 | O5: 79 | P5: 1
A7: Alternative Press Index Archive | B7: 38169 | C7: 38200 | D7: 38231 | E7: 38261 | F7: 38292 | G7: 38322 | H7: 38353 | I7: 38384 | J7: 38412 | K7: 38443 | L7: 38473 | M7: 38504
A8: Searches | B8: 1 | C8: 0 | D8: 5 | E8: 10 | F8: 0 | G8: 0 | H8: 0 | I8: 11 | J8: 1 | K8: 0 | L8: 0 | M8: 0 | N8: =SUM(B8:M8) -> 28 | O8: 28 | P8: 1
A10: ArticleFirst | B10: 38169 | C10: 38200 | D10: 38231 | E10: 38261 | F10: 38292 | G10: 38322 | H10: 38353 | I10: 38384 | J10: 38412 | K10: 38443 | L10: 38473 | M10: 38504
A11: Sessions | B11: 215 | C11: 116 | D11: 458 | E11: 671 | F11: 730 | G11: 485 | H11: 171 | I11: 505 | J11: 629 | K11: 828 | L11: 410 | M11: 232 | N11: =SUM(B11:M11) -> 5450
A12: Searches | B12: 881 | C12: 576 | D12: 1212 | E12: 1595 | F12: 1764 | G12: 912 | H12: 287 | I12: 1292 | J12: 1714 | K12: 1784 | L12: 1000 | M12: 917 | N12: =SUM(B12:M12) -> 13934 | O12: 0 | P12: N/A
A13: User Limit | B13: 2 | C13: 2 | D13: 2 | E13: 2 | F13: 2 | G13: 2 | H13: 2 | I13: 2 | J13: 2 | K13: 2 | L13: 2 | M13: 2
A14: Turnaways | B14: 6 | C14: 7 | D14: 86 | E14: 90 | F14: 86 | G14: 29 | H14: 3 | I14: 64 | J14: 181 | K14: 170 | L14: 41 | M14: 19 | N14: =SUM(B14:M14) -> 782
A16: ERIC | B16: 38169 | C16: 38200 | D16: 38231 | E16: 38261 | F16: 38292 | G16: 38322 | H16: 38353 | I16: 38384 | J16: 38412 | K16: 38443 | L16: 38473 | M16: 38504
A17: Sessions | B17: 152 | C17: 27 | D17: 281 | E17: 538 | F17: 465 | G17: 316 | H17: 86 | I17: 398 | J17: 396 | K17: 422 | L17: 144 | M17: 118 | N17: =SUM(B17:M17) -> 3343
A18: Searches | B18: 344 | C18: 57 | D18: 713 | E18: 1354 | F18: 1060 | G18: 910 | H18: 175 | I18: 1175 | J18: 1001 | K18: 1195 | L18: 335 | M18: 275 | N18: =SUM(B18:M18) -> 8594 | O18: 0 | P18: N/A
A19: User Limit | B19: 2 | C19: 2 | D19: 2 | E19: 2 | F19: 2 | G19: 2 | H19: 2 | I19: 2 | J19: 2 | K19: 2 | L19: 2 | M19: 2
A20: Turnaways | B20: 13 | C20: 1 | D20: 243 | E20: 120 | F20: 112 | G20: 56 | H20: 37 | I20: 103 | J20: 121 | K20: 54 | L20: 4 | M20: 16 | N20: =SUM(B20:M20) -> 880
A22: Electronic Collections Online | B22: 38169 | C22: 38200 | D22: 38231 | E22: 38261 | F22: 38292 | G22: 38322 | H22: 38353 | I22: 38384 | J22: 38412 | K22: 38443 | L22: 38473 | M22: 38504
A23: Sessions | B23: 42 | C23: 18 | D23: 146 | E23: 169 | F23: 157 | G23: 74 | H23: 32 | I23: 116 | J23: 134 | K23: 174 | L23: 75 | M23: 42 | N23: =SUM(B23:M23) -> 1179
A24: Searches | B24: 56 | C24: 21 | D24: 197 | E24: 273 | F24: 218 | G24: 87 | H24: 39 | I24: 185 | J24: 162 | K24: 240 | L24: 126 | M24: 50 | N24: =SUM(B24:M24) -> 1654 | O24: 0 | P24: N/A
A25: User Limit | B25: 2 | C25: 2 | D25: 2 | E25: 2 | F25: 2 | G25: 2 | H25: 2 | I25: 2 | J25: 2 | K25: 2 | L25: 2 | M25: 2
A26: Turnaways | B26: 0 | C26: 0 | D26: 5 | E26: 3 | F26: 0 | G26: 1 | H26: 6 | I26: 1 | J26: 5 | K26: 2 | L26: 2 | M26: 0 | N26: =SUM(B26:M26) -> 25
A28: GEOBASE | B28: 38169 | C28: 38200 | D28: 38231 | E28: 38261 | F28: 38292 | G28: 38322 | H28: 38353 | I28: 38384 | J28: 38412 | K28: 38443 | L28: 38473 | M28: 38504
A29: Searches | B29: 9 | C29: 7 | D29: 11 | E29: 11 | F29: 15 | G29: 2 | H29: 0 | I29: 3 | J29: 2 | K29: 8 | L29: 2 | M29: 2 | N29: =SUM(B29:M29) -> 72 | O29: 72 | P29: 1
A32: GPO Monthly Catalog | B32: 38169 | C32: 38200 | D32: 38231 | E32: 38261 | F32: 38292 | G32: 38322 | H32: 38353 | I32: 38384 | J32: 38412 | K32: 38443 | L32: 38473 | M32: 38504
A33: Sessions | B33: 14 | C33: 6 | D33: 22 | E33: 41 | F33: 42 | G33: 22 | H33: 18 | I33: 33 | J33: 45 | K33: 46 | L33: 11 | M33: 10 | N33: =SUM(B33:M33) -> 310
A34: Searches | B34: 22 | C34: 16 | D34: 36 | E34: 74 | F34: 59 | G34: 48 | H34: 28 | I34: 39 | J34: 46 | K34: 56 | L34: 17 | M34: 8 | N34: =SUM(B34:M34) -> 449 | O34: 0 | P34: N/A
A35: User Limit | B35: 2 | C35: 2 | D35: 2 | E35: 2 | F35: 2 | G35: 2 | H35: 2 | I35: 2 | J35: 2 | K35: 2 | L35: 2 | M35: 2
A36: Turnaways | B36: 2 | C36: 0 | D36: 0 | E36: 0 | F36: 4 | G36: 0 | H36: 0 | I36: 0 | J36: 0 | K36: 0 | L36: 0 | M36: 0 | N36: =SUM(B36:M36) -> 6
A39: MLA Bibliography | B39: 38169 | C39: 38200 | D39: 38231 | E39: 38261 | F39: 38292 | G39: 38322 | H39: 38353 | I39: 38384 | J39: 38412 | K39: 38443 | L39: 38473 | M39: 38504
A40: Sessions | B40: 73 | C40: 63 | D40: 265 | E40: 626 | F40: 569 | G40: 467 | H40: 124 | I40: 276 | J40: 492 | K40: 651 | L40: 395 | M40: 72 | N40: =SUM(B40:M40) -> 4073
A41: Searches | B41: 129 | C41: 187 | D41: 570 | E41: 1500 | F41: 1535 | G41: 1061 | H41: 368 | I41: 611 | J41: 1162 | K41: 1629 | L41: 936 | M41: 160 | N41: =SUM(B41:M41) -> 9848 | O41: 8596 | P41: =O41/N41 -> 0.87286759
A42: User Limit | B42: 999 | C42: 999 | D42: 999 | E42: 999 | F42: 999 | G42: 999 | H42: 999 | I42: 999 | J42: 999 | K42: 999 | L42: 999 | M42: 999
A43: Turnaways | B43: 0 | C43: 0 | D43: 0 | E43: 0 | F43: 0 | G43: 0 | H43: 0 | I43: 0 | J43: 0 | K43: 0 | L43: 0 | M43: 1 | N43: =SUM(B43:M43) -> 1
A46: MEDLINE | B46: 38169 | C46: 38200 | D46: 38231 | E46: 38261 | F46: 38292 | G46: 38322 | H46: 38353 | I46: 38384 | J46: 38412 | K46: 38443 | L46: 38473 | M46: 38504
A47: Sessions | B47: 176 | C47: 121 | D47: 503 | E47: 541 | F47: 643 | G47: 384 | H47: 227 | I47: 530 | J47: 658 | K47: 677 | L47: 294 | M47: 211 | N47: =SUM(B47:M47) -> 4965
A48: Searches | B48: 343 | C48: 260 | D48: 1437 | E48: 1213 | F48: 1341 | G48: 863 | H48: 532 | I48: 1189 | J48: 1602 | K48: 1355 | L48: 661 | M48: 467 | N48: =SUM(B48:M48) -> 11263 | O48: 0 | P48: N/A
A49: User Limit | B49: 2 | C49: 2 | D49: 2 | E49: 2 | F49: 2 | G49: 2 | H49: 2 | I49: 2 | J49: 2 | K49: 2 | L49: 2 | M49: 2
A50: Turnaways | B50: 6 | C50: 1 | D50: 201 | E50: 83 | F50: 194 | G50: 77 | H50: 18 | I50: 168 | J50: 232 | K50: 134 | L50: 51 | M50: 40 | N50: =SUM(B50:M50) -> 1205
A53: PapersFirst | B53: 38169 | C53: 38200 | D53: 38231 | E53: 38261 | F53: 38292 | G53: 38322 | H53: 38353 | I53: 38384 | J53: 38412 | K53: 38443 | L53: 38473 | M53: 38504
A54: Sessions | B54: 21 | C54: 4 | D54: 19 | E54: 20 | F54: 27 | G54: 30 | H54: 10 | I54: 23 | J54: 23 | K54: 40 | L54: 12 | M54: 14 | N54: =SUM(B54:M54) -> 243
...

Sheet InfoTrac
A1: InfoTRAC
A2: 2004-2005
A4: Metric | B4: 38169 | C4: 38200 | D4: 38231 | E4: 38261 | F4: 38292 | G4: 38322 | H4: 38353 | I4: 38384 | J4: 38412 | K4: 38443 | L4: 38473 | M4: 38504 | N4: Total | O4: Price for 2004-2005 | P4: Price per search
A5: TOTAL
A6: Sessions | B6: 0 | C6: 0 | D6: 228 | E6: 372 | F6: 380 | G6: 379 | H6: 92 | I6: 243 | J6: 452 | K6: 665 | L6: 511 | M6: 87 | N6: =SUM(B6:M6) -> 3409
A7: Searches | B7: 0 | C7: 0 | D7: 1784 | E7: 2487 | F7: 2428 | G7: 2397 | H7: 403 | I7: 1011 | J7: 2955 | K7: 4414 | L7: 3422 | M7: 460 | N7: =SUM(B7:M7) -> 21761 | O7: 4678 | P7: =O7/N7 -> 0.21497174
A8: Turnaways | B8: 0 | C8: 0 | D8: 0 | E8: 0 | F8: 0 | G8: 0 | H8: 0 | I8: 0 | J8: 0 | K8: 0 | L8: 0 | M8: 0 | N8: =SUM(B8:M8) -> 0
A9: Successful Full-Text Article Requests | B9: 0 | C9: 0 | D9: 35 | E9: 91 | F9: 86 | G9: 62 | H9: 24 | I9: 76 | J9: 176 | K9: 207 | L9: 130 | M9: 56 | N9: =SUM(B9:M9) -> 943 | O9: 4678 | P9: =O9/N9 -> 4.9607635

Sheet GroveMusic
A1: Grove Music
A2: 2004-2005
A4: Metric | B4: 38169 | C4: 38200 | D4: 38231 | E4: 38261 | F4: 38292 | G4: 38322 | H4: 38353 | I4: 38384 | J4: 38412 | K4: 38443 | L4: 38473 | M4: 38504 | N4: Total | O4: Price for 2004-2005 | P4: Price per search
A5: TOTAL
A6: Sessions | B6: 24 | C6: 7 | D6: 32 | E6: 41 | F6: 57 | G6: 33 | H6: 7 | I6: 29 | J6: 29 | K6: 47 | L6: 18 | M6: 11 | N6: =SUM(B6:M6) -> 335
A7: Searches | B7: 56 | C7: 11 | D7: 34 | E7: 68 | F7: 94 | G7: 106 | H7: 5 | I7: 47 | J7: 72 | K7: 84 | L7: 26 | M7: 25 | N7: =SUM(B7:M7) -> 628 | O7: 1386 | P7: =O7/N7 -> 2.2070064

Sheet LexisNexis
A1: LexisNexis
A2: 2004-2005
O4: Price for 2004-2005 | P4: Price per unit
A5: Academic | B5: 38169 | C5: 38200 | D5: 38231 | E5: 38261 | F5: 38292 | G5: 38322 | H5: 38353 | I5: 38384 | J5: 38412 | K5: 38443 | L5: 38473 | M5: 38504 | N5: Total
A6: TOTAL
A7: Academic
A8: Searches | B8: 4217 | C8: 2324 | D8: 10075 | E8: 12757 | F8: 11646 | G8: 8125 | H8: 7314 | I8: 12467 | J8: 8923 | K8: 11700 | L8: 5101 | M8: 2189 | N8: =SUM(B8:M8) -> 96838 | O8: 21786 | P8: =O8/N8 -> 0.22497367
A9: Documents Retrieved | B9: 6435 | C9: 3155 | D9: 9933 | E9: 14644 | F9: 13503 | G9: 9958 | H9: 9371 | I9: 16643 | J9: 11553 | K9: 15024 | L9: 7128 | M9: 3526 | N9: =SUM(B9:M9) -> 120873 | O9: 21786 | P9: =O9/N9 -> 0.18023876
A13: Congressional | B13: 38169 | C13: 38200 | D13: 38231 | E13: 38261 | F13: 38292 | G13: 38322 | H13: 38353 | I13: 38384 | J13: 38412 | K13: 38443 | L13: 38473 | M13: 38504 | N13: Total
A14: TOTAL
A15: Congressional
A16: Searches | B16: N/A | C16: N/A | D16: N/A | E16: 16 | F16: 78 | G16: 56 | H16: 58 | I16: 264 | J16: 607 | K16: 477 | L16: 66 | M16: 147 | N16: =SUM(B16:M16) -> 1769 | O16: 4947 | P16: =O16/N16 -> 2.7964952
A17: Documents Retrieved | B17: N/A | C17: N/A | D17: N/A | E17: 29 | F17: 68 | G17: 18 | H17: 36 | I17: 835 | J17: 754 | K17: 526 | L17: 40 | M17: 154 | N17: =SUM(B17:M17) -> 2460 | O17: 4947 | P17: =O17/N17 -> 2.0109756

Sheet MathSciNet
A1: MathSciNet
A2: 2004-2005
A4: Metric | B4: 38169 | C4: 38200 | D4: 38231 | E4: 38261 | F4: 38292 | G4: 38322 | H4: 38353 | I4: 38384 | J4: 38412 | K4: 38443 | L4: 38473 | M4: 38504 | N4: Total | O4: Price for 2004-2005 | P4: Price per search
A5: TOTAL
A6: Sessions | B6: 178 | C6: 40 | D6: 167 | E6: 263 | F6: 341 | G6: 255 | H6: 126 | I6: 268 | J6: 428 | K6: 514 | L6: 207 | M6: 284 | N6: =SUM(B6:M6) -> 3071
A7: Searches | B7: 351 | C7: 174 | D7: 373 | E7: 519 | F7: 1191 | G7: 424 | H7: 237 | I7: 539 | J7: 759 | K7: 775 | L7: 406 | M7: 481 | N7: =SUM(B7:M7) -> 6229 | O7: 6686 | P7: =O7/N7 -> 1.0733665

Sheet Mergent
A1: Mergent
A2: 2004-2005
A4: Metric | B4: 38169 | C4: 38200 | D4: 38231 | E4: 38261 | F4: 38292 | G4: 38322 | H4: 38353 | I4: 38384 | J4: 38412 | K4: 38443 | L4: 38473 | M4: 38504 | N4: Total | O4: Price for 2004-2005 | P4: Price per unit
A5: TOTAL
A6: Searches | B6: 59 | C6: 47 | D6: 176 | E6: 370 | F6: 150 | G6: 192 | H6: 166 | I6: 45 | J6: 126 | K6: 61 | L6: 81 | M6: 8 | N6: =SUM(B6:M6) -> 1481 | O6: 9900 | P6: =O6/N6 -> 6.6846725
A7: Companies Viewed | B7: 35 | C7: 27 | D7: 86 | E7: 202 | F7: 67 | G7: 88 | H7: 71 | I7: 27 | J7: 35 | K7: 10 | L7: 55 | M7: 0 | N7: =SUM(B7:M7) -> 703 | O7: 9900 | P7: =O7/N7 -> 14.082504

Sheet MINABS
A1: MINABS
A2: 2004-2005
A4: Metric | B4: 38169 | C4: 38200 | D4: 38231 | E4: 38261 | F4: 38292 | G4: 38322 | H4: 38353 | I4: 38384 | J4: 38412 | K4: 38443 | L4: 38473 | M4: 38504 | N4: Total | O4: Price for 2004-2005 | P4: Price per session
A5: TOTAL
A6: Sessions | B6: 2 | C6: 0 | D6: 0 | E6: 0 | F6: 0 | G6: 2 | H6: 0 | I6: 0 | J6: 0 | K6: 3 | L6: 0 | M6: 0 | N6: =SUM(B6:M6) -> 7 | O6: 401 | P6: =O6/N6 -> 57.285714

Sheet MusicIndex
A1: Music Index
A2: 2004-2005
A4: Metric | B4: 38169 | C4: 38200 | D4: 38231 | E4: 38261 | F4: 38292 | G4: 38322 | H4: 38353 | I4: 38384 | J4: 38412 | K4: 38443 | L4: 38473 | M4: 38504 | N4: Total | O4: Price for 2004-2005 | P4: Price per search
A5: TOTAL
A6: Searches | B6: 10 | C6: 14 | D6: 48 | E6: 136 | F6: 113 | G6: 261 | H6: 7 | I6: 312 | J6: 508 | K6: 166 | L6: 4 | M6: 39 | N6: =SUM(B6:M6) -> 1618 | O6: 2255 | P6: =O6/N6 -> 1.3936959

Sheet netLibrary
A1: NetLibrary
A2: 2004-2005
A4: Metric | B4: 38169 | C4: 38200 | D4: 38231 | E4: 38261 | F4: 38292 | G4: 38322 | H4: 38353 | I4: 38384 | J4: 38412 | K4: 38443 | L4: 38473 | M4: 38504 | N4: Total | O4: Price for 2004-2005 | P4: Price per access
A5: TOTAL
A6: Accesses | B6: 76 | C6: 53 | D6: 86 | E6: 143 | F6: 151 | G6: 90 | H6: 59 | I6: 94 | J6: 96 | K6: 104 | L6: 69 | M6: 50 | N6: =SUM(B6:M6) -> 1071 | O6: 0 | P6: N/A
A7: Turnaways | B7: 21 | C7: 15 | D7: 44 | E7: 4 | F7: 18 | G7: 8 | H7: 8 | I7: 14 | J7: 10 | K7: 8 | L7: 12 | M7: 4 | N7: =SUM(B7:M7) -> 166
A10: Note: We have 4,478 shared titles

Sheet OVID
A1: OVID
A2: 2004-2005
A4: Metric
A5: TOTAL
A7: CINAHL | G7: Jul/04-Dec/04 | M7: Jan/05-Jun/05 | N7: Total | O7: Price for 2004-2005 | P7: Price per search
A8: Sessions | G8: =999+2990+252+322 -> 4563 | M8: 2627 | N8: =SUM(G8:M8) -> 7190
A9: Searches | G9: =0+11606+0+0 -> 11606 | M9: 13284 | N9: =SUM(G9:M9) -> 24890 | O9: 5273 | P9: =O9/N9 -> 0.21185215
A10: Full text retrieved | G10: =0+0+0+0 -> 0 | M10: 0 | N10: 0
A11: BIOSIS Previews | G11: Jul/04-Dec/04 | M11: Jan/05-Jun/05
A12: Sessions | G12: =2+3+1+1+1+12 -> 20 | M12: 35 | N12: =SUM(G12:M12) -> 55
A13: Searches | G13: =5+0+1+0+0+41 -> 47 | M13: 10 | N13: =SUM(G13:M13) -> 57 | O13: 0 | P13: N/A
A14: Full text retrieved | G14: =0+0+0+0+0+0 -> 0 | M14: 0 | N14: 0
A16: MEDLINE | G16: Jul/04-Dec/04 | M16: Jan/05-Jun/05
A17: Sessions | G17: =1 -> 1 | M17: 1 | N17: =SUM(G17:M17) -> 2
A18: Searches | G18: =7 -> 7 | M18: 0 | N18: =SUM(G18:M18) -> 7 | O18: 0 | P18: N/A
A19: Full text retrieved | G19: =0 -> 0 | M19: 0 | N19: 0
A23: Metric | B23: 38169 | C23: 38200 | D23: 38231 | E23: 38261 | F23: 38292 | G23: 38322 | H23: 38353 | I23: 38384 | J23: 38412 | K23: 38443 | L23: 38473 | M23: 38504 | N23: Total
A24: All OVID Databases
A25: Sessions | H25: 138 | I25: 1187 | J25: 555 | K25: 1130 | L25: 255 | M25: 209 | N25: =SUM(B25:M25) -> 3474
A26: Searches | H26: 320 | I26: 4584 | J26: 4226 | K26: 2965 | L26: 930 | M26: 1056 | N26: =SUM(B26:M26) -> 14081 | O26: 5273 | P26: =O26/N26 -> 0.37447624
A27: Turnaways | H27: 0 | I27: 0 | J27: 0 | K27: 0 | L27: 0 | M27: 0 | N27: =SUM(B27:M27) -> 0

Sheet ProQuest
A1: ProQuest Databases
A2: 2004-2005
A5: ABI/INFORM Global | B5: 38169 | C5: 38200 | D5: 38231 | E5: 38261 | F5: 38292 | G5: 38322 | H5: 38353 | I5: 38384 | J5: 38412 | K5: 38443 | L5: 38473 | M5: 38504 | N5: Total | O5: 2004-2005 Price | P5: Cost per search
A6: TOTAL
A7: Searches | B7: 1099 | C7: 740 | D7: 1971 | E7: 3259 | F7: 3766 | G7: 3344 | H7: 1633 | I7: 3198 | J7: 3942 | K7: 4592 | L7: 2317 | M7: 1444 | N7: =SUM(B7:M7) -> 31305 | O7: 17500 | P7: =O7/N7 -> 0.55901613
A10: ABI/INFORM Trade & Industry | B10: 38169 | C10: 38200 | D10: 38231 | E10: 38261 | F10: 38292 | G10: 38322 | H10: 38353 | I10: 38384 | J10: 38412 | K10: 38443 | L10: 38473 | M10: 38504 | N10: Total
A11: TOTAL
A12: Searches | B12: 263 | C12: 145 | D12: 750 | E12: 1298 | F12: 1568 | G12: 1287 | H12: 466 | I12: 1435 | J12: 1784 | K12: 1583 | L12: 822 | M12: 438 | N12: =SUM(B12:M12) -> 11839 | O12: 0 | P12: N/A
A15: National Newspapers (5) | B15: 38169 | C15: 38200 | D15: 38231 | E15: 38261 | F15: 38292 | G15: 38322 | H15: 38353 | I15: 38384 | J15: 38412 | K15: 38443 | L15: 38473 | M15: 38504 | N15: Total
A16: TOTAL
A17: Searches | B17: 262 | C17: 158 | D17: 542 | E17: 1331 | F17: 1706 | G17: 1226 | H17: 462 | I17: 1405 | J17: 1550 | K17: 1623 | L17: 753 | M17: 695 | N17: =SUM(B17:M17) -> 11713 | O17: 2925 | P17: =O17/N17 -> 0.24972253
A20: ProQuest Historical Newspapers - New York Times 1851-2002 | B20: 38169 | C20: 38200 | D20: 38231 | E20: 38261 | F20: 38292 | G20: 38322 | H20: 38353 | I20: 38384 | J20: 38412 | K20: 38443 | L20: 38473 | M20: 38504 | N20: Total
A21: TOTAL
A22: Searches | B22: 7 | C22: 1 | D22: 5 | E22: 124 | F22: 82 | G22: 70 | H22: 277 | I22: 200 | J22: 332 | K22: 219 | L22: 142 | M22: 124 | N22: =SUM(B22:M22) -> 1583 | O22: 0 | P22: N/A
A25: Providence Journal-Bulletin | B25: 38169 | C25: 38200 | D25: 38231 | E25: 38261 | F25: 38292 | G25: 38322 | H25: 38353 | I25: 38384 | J25: 38412 | K25: 38443 | L25: 38473 | M25: 38504 | N25: Total
A26: TOTAL
A27: Searches | B27: 218 | C27: 139 | D27: 530 | E27: 1224 | F27: 1569 | G27: 1045 | H27: 419 | I27: 1393 | J27: 1591 | K27: 1510 | L27: 771 | M27: 587 | N27: =SUM(B27:M27) -> 10996 | O27: 1733 | P27: =O27/N27 -> 0.15760276
A30: ProQuest Dissertations & Theses | B30: 38169 | C30: 38200 | D30: 38231 | E30: 38261 | F30: 38292 | G30: 38322 | H30: 38353 | I30: 38384 | J30: 38412 | K30: 38443 | L30: 38473 | M30: 38504 | N30: Total
A31: TOTAL
A32: Searches | B32: 0 | C32: 0 | D32: 0 | E32: 0 | F32: 0 | G32: 163 | H32: 351 | I32: 1193 | J32: 1220 | K32: 1170 | L32: 524 | M32: 341 | N32: =SUM(B32:M32) -> 4962 | O32: 5215 | P32: =O32/N32 -> 1.0509875
A35: Wall Street Journal | B35: 38169 | C35: 38200 | D35: 38231 | E35: 38261 | F35: 38292 | G35: 38322 | H35: 38353 | I35: 38384 | J35: 38412 | K35: 38443 | L35: 38473 | M35: 38504 | N35: Total
A36: TOTAL
A37: Searches | B37: 215 | C37: 132 | D37: 517 | E37: 1046 | F37: 1222 | G37: 914 | H37: 382 | I37: 1229 | J37: 1276 | K37: 1276 | L37: 581 | M37: 433 | N37: =SUM(B37:M37) -> 9223 | O37: 0 | P37: N/A
A40: ProQuest ALL | B40: Jul | C40: Aug | D40: Sep | E40: Oct | F40: Nov | G40: Dec | H40: Jan | I40: Feb | J40: Mar | K40: Apr | L40: May | M40: Jun | N40: Total
A41: TOTAL
A42: Sessions | B42: 444 | C42: 316 | D42: 860 | E42: 1901 | F42: 1998 | G42: 1590 | H42: 821 | I42: 1800 | J42: 2069 | K42: 2528 | L42: 1220 | M42: 836 | N42: =SUM(B42:M42) -> 16383
A43: Searches | B43: 1311 | C43: 834 | D43: 2503 | E43: 4040 | F43: 5073 | G43: 4318 | H43: 2113 | I43: 4047 | J43: 5496 | K43: 5910 | L43: 3077 | M43: 2010 | N43: =SUM(B43:M43) -> 40732 | O43: 27373 | P43: =O43/N43 -> 0.67202691

Sheet ReferenceUSA
A1: ReferenceUSA
A2: 2004-2005
A4: Metric | B4: 38169 | C4: 38200 | D4: 38231 | E4: 38261 | F4: 38292 | G4: 38322 | H4: 38353 | I4: 38384 | J4: 38412 | K4: 38443 | L4: 38473 | M4: 38504 | N4: Total | O4: 2004-2005 Price | P4: Cost per unit
A6: Sessions | B6: 32 | C6: 28 | D6: 54 | E6: 43 | F6: 81 | G6: 62 | H6: 40 | I6: 126 | J6: 163 | K6: 111 | L6: 124 | M6: 77 | N6: =SUM(B6:M6) -> 941 | O6: 5483 | P6: =O6/N6 -> 5.82678
A7: Searches | B7: 71 | C7: 48 | D7: 99 | E7: 77 | F7: 113 | G7: 97 | H7: 90 | I7: 283 | J7: 446 | K7: 240 | L7: 349 | M7: 115 | N7: =SUM(B7:M7) -> 2028 | O7: 5483 | P7: =O7/N7 -> 2.7036489
A8: Business Searches | N8: 1499 | O8: 5483 | P8: =O8/N8 -> 3.6577718
A9: Residential Searches | N9: 518 | O9: 5483 | P9: =O9/N9 -> 10.584942
A10: Total Records printed or viewed | B10: 217 | C10: 30 | D10: 88 | E10: 36 | F10: 139 | G10: 66 | H10: 123 | I10: 468 | J10: 787 | K10: 736 | L10: 389 | M10: 504 | N10: =SUM(B10:M10) -> 3583 | O10: 5483 | P10: =O10/N10 -> 1.5302819
A11: Total records downloaded | B11: 407 | C11: 272 | D11: 23 | E11: 674 | F11: 674 | G11: 439 | H11: 0 | I11: 1630 | J11: 509 | K11: 1246 | L11: 2532 | M11: 1685 | N11: =SUM(B11:M11) -> 10091 | O11: 5483 | P11: =O11/N11 -> 0.54335547

Sheet RefWorks
A1: RefWorks (CSA)
A2: 2004-2005
A5: Metric | B5: 38169 | C5: 38200 | D5: 38231 | E5: 38261 | F5: 38292 | G5: 38322 | H5: 38353 | I5: 38384 | J5: 38412 | K5: 38443 | L5: 38473 | M5: 38504 | N5: Total | O5: 2004-2005 Price | P5: Cost per unit
A6: New Users | B6: Not avail. | C6: Not avail. | D6: Not avail. | E6: Not avail. | F6: Not avail. | G6: Not avail. | H6: Not avail. | I6: Not avail. | J6: Not avail. | K6: Not avail. | L6: Not avail. | M6: 4 | N6: =SUM(B6:M6) -> 4 | O6: 8058 | P6: N/A
A7: Repeat Users | B7: Not avail. | C7: Not avail. | D7: Not avail. | E7: Not avail. | F7: Not avail. | G7: Not avail. | H7: Not avail. | I7: Not avail. | J7: Not avail. | K7: Not avail. | L7: Not avail. | M7: 8 | N7: =SUM(B7:M7) -> 8 | O7: 8058 | P7: N/A
A8: Total Monthly Users | B8: Not avail. | C8: Not avail. | D8: Not avail. | E8: Not avail. | F8: Not avail. | G8: Not avail. | H8: Not avail. | I8: Not avail. | J8: Not avail. | K8: Not avail. | L8: Not avail. | M8: 12 | N8: =SUM(B8:M8) -> 12 | O8: 8058 | P8: N/A
A9: Total Sessions per month | B9: Not avail. | C9: Not avail. | D9: Not avail. | E9: Not avail. | F9: Not avail. | G9: Not avail. | H9: Not avail. | I9: Not avail. | J9: Not avail. | K9: Not avail. | L9: Not avail. | M9: 77 | N9: =SUM(B9:M9) -> 77 | O9: 8058 | P9: N/A
A10: Average Sessions Per User | B10: Not avail. | C10: Not avail. | D10: Not avail. | E10: Not avail. | F10: Not avail. | G10: Not avail. | H10: Not avail. | I10: Not avail. | J10: Not avail. | K10: Not avail. | L10: Not avail. | M10: 6.42 | N10: =SUM(B10:M10) -> 6.42 | O10: 8058 | P10: N/A
A11: Total Subscriber References added | B11: Not avail. | C11: Not avail. | D11: Not avail. | E11: Not avail. | F11: Not avail. | G11: Not avail. | H11: Not avail. | I11: Not avail. | J11: Not avail. | K11: Not avail. | L11: Not avail. | M11: 73 | N11: =SUM(B11:M11) -> 73 | O11: 8058 | P11: N/A
A12: Average References added per user | B12: Not avail. | C12: Not avail. | D12: Not avail. | E12: Not avail. | F12: Not avail. | G12: Not avail. | H12: Not avail. | I12: Not avail. | J12: Not avail. | K12: Not avail. | L12: Not avail. | M12: 6.08 | N12: =SUM(B12:M12) -> 6.08 | O12: 8058 | P12: N/A

Sheet SciFinderScholar
A1: SciFinder Scholar
A2: 2004-2005
A4: Metric | B4: 38169 | C4: 38200 | D4: 38231 | E4: 38261 | F4: 38292 | G4: 38322 | H4: 38353 | I4: 38384 | J4: 38412 | K4: 38443 | L4: 38473 | M4: 38504 | N4: Total | O4: 2004-2005 Price | P4: Price per search
A6: Sessions | B6: 155 | C6: 150 | D6: 227 | E6: 227 | F6: 223 | G6: 201 | H6: 246 | I6: 200 | J6: 247 | K6: 250 | L6: 243 | M6: 224 | N6: =SUM(B6:M6) -> 2593
A7: Searches | B7: 650 | C7: 580 | D7: 879 | E7: 901 | F7: 929 | G7: 789 | H7: 856 | I7: 977 | J7: 1234 | K7: 1068 | L7: 1522 | M7: 946 | N7: =SUM(B7:M7) -> 11331 | O7: 28365 | P7: =O7/N7 -> 2.5033095
A8: Turnaways | B8: 57 | C8: 47 | D8: 156 | E8: 132 | F8: 120 | G8: 77 | H8: 143 | I8: 214 | J8: 119 | K8: 182 | L8: 303 | M8: 175 | N8: =SUM(B8:M8) -> 1725
A9: Simultaneous Users | B9: 1 | C9: 1 | D9: 1 | E9: 1 | F9: 1 | G9: 1 | H9: 1 | I9: 1 | J9: 1 | K9: 1 | L9: 1 | M9: 1

Sheet WebofScience
A1: Web of Science
A2: 2004-2005
A4: Metric | B4: 38169 | C4: 38200 | D4: 38231 | E4: 38261 | F4: 38292 | G4: 38322 | H4: 38353 | I4: 38384 | J4: 38412 | K4: 38443 | L4: 38473 | M4: 38504 | N4: Total | O4: 2004-2005 Price | P4: Price per search
A6: Sessions | B6: 362 | C6: 197 | D6: 384 | E6: 491 | F6: 562 | G6: 407 | H6: 355 | I6: 390 | J6: 564 | K6: 694 | L6: 355 | M6: 482 | N6: =SUM(B6:M6) -> 5243
A7: Queries | B7: 1478 | C7: 701 | D7: 1295 | E7: 1609 | F7: 1891 | G7: 1552 | H7: 971 | I7: 1316 | J7: 2080 | K7: 2838 | L7: 1460 | M7: 1388 | N7: =SUM(B7:M7) -> 18579 | O7: 85082 | P7: =O7/N7 -> 4.5794714
A8: Maximum Contractual Users | B8: 5 | C8: 5 | D8: 5 | E8: 5 | F8: 5 | G8: 5 | H8: 5 | I8: 5 | J8: 5 | K8: 5 | L8: 5 | M8: 5
A9: Turnaways | B9: 4 | C9: 0 | D9: 32 | E9: 2 | F9: 2 | G9: 0 | H9: 0 | I9: 10 | J9: 15 | K9: 0 | L9: 0 | M9: 9 | N9: =SUM(B9:M9) -> 74

Sheet WebSpirs
A1: WebSPIRS
A2: 2004-2005
A4: Metric | B4: 38169 | C4: 38200 | D4: 38231 | E4: 38261 | F4: 38292 | G4: 38322 | H4: 38353 | I4: 38384 | J4: 38412 | K4: 38443 | L4: 38473 | M4: 38504 | N4: Total | O4: 2004-2005 Price | P4: Price per search
A5: TOTAL
A6: Biological Abstracts
A7: Sessions | B7: 76 | C7: 63 | D7: 102 | E7: 253 | F7: 293 | G7: 166 | H7: 61 | I7: 157 | J7: 277 | K7: 424 | L7: 167 | M7: 44 | N7: =SUM(B7:M7) -> 2083
A8: Searches | B8: 292 | C8: 307 | D8: 277 | E8: 816 | F8: 1265 | G8: 617 | H8: 198 | I8: 534 | J8: 956 | K8: 1504 | L8: 654 | M8: 220 | N8: =SUM(B8:M8) -> 7640 | O8: 21255 | P8: =O8/N8 -> 2.7820681
A9: Turnaways | B9: 0 | C9: 0 | D9: 0 | E9: 6 | F9: 6 | G9: 2 | H9: 0 | I9: 0 | J9: 0 | K9: 0 | L9: 0 | M9: 0 | N9: =SUM(B9:M9) -> 14
A10: Peak usage | I10: 3 | L10: 3 | M10: 1 | N10: =SUM(B10:M10) -> 7
A13: Metric | B13: 38169 | C13: 38200 | D13: 38231 | E13: 38261 | F13: 38292 | G13: 38322 | H13: 38353 | I13: 38384 | J13: 38412 | K13: 38443 | L13: 38473 | M13: 38504 | N13: Total
A14: TOTAL
A15: Philosopher's Index
A16: Sessions | B16: 12 | C16: 13 | D16: 20 | E16: 31 | F16: 4 | G16: 2 | H16: 0 | I16: 1 | J16: 1 | K16: 1 | L16: 3 | M16: 0 | N16: =SUM(B16:M16) -> 88
A17: Searches | B17: 18 | C17: 16 | D17: 29 | E17: 34 | F17: 7 | G17: 2 | H17: 0 | I17: 1 | J17: 0 | K17: 1 | L17: 22 | M17: 0 | N17: =SUM(B17:M17) -> 130 | O17: 1900 | P17: =O17/N17 -> 14.615385
A18: Turnaways | B18: 0 | C18: 0 | D18: 0 | E18: 0 | F18: 0 | G18: 0 | H18: 0 | I18: 0 | J18: 0 | K18: 0 | L18: 0 | M18: 0 | N18: =SUM(B18:M18) -> 0
A19: Peak usage | I19: 1 | L19: 1 | M19: 0 | N19: =SUM(B19:M19) -> 2

Sheet WilsonWeb
A1: WilsonWeb Databases
A2: 2004-2005
A4: Metric | B4: 38169 | C4: 38200 | D4: 38231 | E4: 38261 | F4: 38292 | G4: 38322 | H4: 38353 | I4: 38384 | J4: 38412 | K4: 38443 | L4: 38473 | M4: 38504 | N4: Total | O4: 2004-2005 Price | P4: Price per search
A5: TOTAL
A6: Art Abstracts
A7: Sessions | B7: 7 | C7: 1 | D7: 38 | E7: 108 | F7: 143 | G7: 53 | H7: 34 | I7: 80 | J7: 112 | K7: 137 | L7: 60 | M7: 18 | N7: =SUM(B7:M7) -> 791
A8: Searches | B8: 22 | C8: 1 | D8: 154 | E8: 552 | F8: 518 | G8: 177 | H8: 166 | I8: 408 | J8: 517 | K8: 643 | L8: 222 | M8: 63 | N8: =SUM(B8:M8) -> 3443 | O8: 4460 | P8: =O8/N8 -> 1.2953819
A9: Turnaways | B9: 0 | C9: 0 | D9: 0 | E9: 0 | F9: 0 | G9: 0 | H9: 0 | I9: 0 | J9: 0 | K9: 0 | L9: 0 | M9: 0 | N9: =SUM(B9:M9) -> 0
A12: Applied Science & Technology Abstracts
A13: Sessions | B13: 26 | C13: 15 | D13: 19 | E13: 87 | F13: 87 | G13: 54 | H13: 39 | I13: 55 | J13: 76 | K13: 82 | L13: 31 | M13: 17 | N13: =SUM(B13:M13) -> 588
A14: Searches | B14: 110 | C14: 34 | D14: 61 | E14: 295 | F14: 310 | G14: 180 | H14: 171 | I14: 204 | J14: 156 | K14: 275 | L14: 142 | M14: 55 | N14: =SUM(B14:M14) -> 1993 | O14: 5018 | P14: =O14/N14 -> 2.5178123
A15: Turnaways | B15: 0 | C15: 0 | D15: 0 | E15: 0 | F15: 0 | G15: 0 | H15: 0 | I15: 0 | J15: 0 | K15: 0 | L15: 0 | M15: 0 | N15: =SUM(B15:M15) -> 0
A18: Biological & Agricultural Index Plus
A19: Sessions | B19: 32 | C19: 16 | D19: 28 | E19: 91 | F19: 96 | G19: 73 | H19: 36 | I19: 56 | J19: 55 | K19: 100 | L19: 37 | M19: 13 | N19: =SUM(B19:M19) -> 633
A20: Searches | B20: 92 | C20: 32 | D20: 107 | E20: 311 | F20: 351 | G20: 236 | H20: 165 | I20: 255 | J20: 168 | K20: 374 | L20: 180 | M20: 35 | N20: =SUM(B20:M20) -> 2306 | O20: 2970 | P20: =O20/N20 -> 1.2879445
A21: Turnaways | B21: 0 | C21: 0 | D21: 0 | E21: 0 | F21: 0 | G21: 15 | H21: 0 | I21: 0 | J21: 0 | K21: 0 | L21: 0 | M21: 0 | N21: =SUM(B21:M21) -> 15
A24: Readers Guide Retrospective
A25: Sessions | B25: 14 | C25: 2 | D25: 11 | E25: 37 | F25: 51 | G25: 35 | H25: 31 | I25: 47 | J25: 27 | K25: 34 | L25: 11 | M25: 15 | N25: =SUM(B25:M25) -> 315
A26: Searches | B26: 55 | C26: 15 | D26: 314 | E26: 142 | F26: 235 | G26: 164 | H26: 143 | I26: 176 | J26: 65 | K26: 120 | L26: 19 | M26: 33 | N26: =SUM(B26:M26) -> 1481 | O26: 326 | P26: =32/N26 -> 0.021607022
A27: Turnaways | B27: 0 | C27: 0 | D27: 0 | E27: 0 | F27: 0 | G27: 0 | H27: 0 | I27: 0 | J27: 0 | K27: 0 | L27: 0 | M27: 0 | N27: =SUM(B27:M27) -> 0
A30: ALL WILSON DATABASES
A31: Sessions | B31: =B7+B13+B19+B25 -> 79 | C31: =C7+C13+C19+C25 -> 34 | D31: =D7+D13+D19+D25 -> 96 | E31: =E7+E13+E19+E25 -> 323 | F31: =F7+F13+F19+F25 -> 377 | G31: =G7+G13+G19+G25 -> 215 | H31: =H7+H13+H19+H25 -> 140 | I31: =I7+I13+I19+I25 -> 238 | ... N31: =N7+N13+N19+N25 -> 2327
A32: Searches | B32: =B8+B14+B20+B26 -> 279 | C32: =C8+C14+C20+C26 -> 82 | D32: =D8+D14+D20+D26 -> 636 | E32: =E8+E14+E20+E26 -> 1300 | F32: =F8+F14+F20+F26 -> 1414 | G32: =G8+G14+G20+G26 -> 757 | H32: =H8+H14+H20+H26 -> 645 | I32: =I8+I14+I20+I26 -> 1043 | ... N32: =N8+N14+N20+N26 -> 9223 | O32: =SUM(O7:O29) -> 12774 | P32: =O32/N32 -> 1.3850157
A33: Turnaways | B33: =B9+B15+B21+B27 -> 0 | C33: =C9+C15+C21+C27 -> 0 | D33: =D9+D15+D21+D27 -> 0 | E33: =E9+E15+E21+E27 -> 0 | F33: =F9+F15+F21+F27 -> 0 | G33: =G9+G15+G21+G27 -> 15 | H33: =H9+H15+H21+H27 -> 0 | I33: =I9+I15+I21+I27 -> 0 | ... N33: =N9+N15+N21+N27 -> 15
