Workbook

Sheet Summary
B3: Actual 2012 | C3: Projected 2011/12 | F3: 0.91666667
A4: BUDGET DIVISION | B4: BUDGET | C4: SALARIES | D4: ADMIN & SUPPORT | E4: OPERATING | F4: Formula Allocation | G4: 10/11 Expenditure | H4: +/- last year
A6: President | B6: 1715950 | C6: =Calculations!N8 -> 1033479 | D6: =INDIRECT(ADDRESS(MATCH(A6,Calculations!B:B,0),15,1,1,"Calculations")) -> 0 | E6: =INDIRECT(ADDRESS(MATCH(A6,Calculations!B:B,0),16,1,1,"Calculations")) -> 281541.74 | F6: =INDIRECT(ADDRESS(MATCH(A6,Calculations!B:B,0),17,1,1,"Calculations")) -> 1315020.7 | G6: 1866754.6 | H6: =F6-B6 -> -400929.26
A7: Provost | B7: 5616538 | C7: =Calculations!N9 -> 2932244.7 | D7: =INDIRECT(ADDRESS(MATCH(A7,Calculations!B:B,0),15,1,1,"Calculations")) -> 0 | E7: =INDIRECT(ADDRESS(MATCH(A7,Calculations!B:B,0),16,1,1,"Calculations")) -> 798806.05 | F7: =INDIRECT(ADDRESS(MATCH(A7,Calculations!B:B,0),17,1,1,"Calculations")) -> 3731050.8 | G7: 5326965.2 | H7: =F7-B7 -> -1885487.2
A8: Finance & Aministration | B8: 8646125 | C8: =Calculations!N10 -> 6191740 | D8: =INDIRECT(ADDRESS(MATCH(A8,Calculations!B:B,0),15,1,1,"Calculations")) -> 0 | E8: =INDIRECT(ADDRESS(MATCH(A8,Calculations!B:B,0),16,1,1,"Calculations")) -> 1686762.1 | F8: =INDIRECT(ADDRESS(MATCH(A8,Calculations!B:B,0),17,1,1,"Calculations")) -> 7878502.1 | G8: 5800432.3 | H8: =F8-B8 -> -767622.86
A9: Strategy, Planning & Policy | B9: 1760002 | C9: =Calculations!N11 -> 1253406 | D9: =INDIRECT(ADDRESS(MATCH(A9,Calculations!B:B,0),15,1,1,"Calculations")) -> 0 | E9: =INDIRECT(ADDRESS(MATCH(A9,Calculations!B:B,0),16,1,1,"Calculations")) -> 341454.55 | F9: =INDIRECT(ADDRESS(MATCH(A9,Calculations!B:B,0),17,1,1,"Calculations")) -> 1594860.5 | G9: 1953311.2 | H9: =F9-B9 -> -165141.45
A10: Student Services & Enrollment Management | B10: 2665119 | C10: =Calculations!N12 -> 1087604 | D10: =INDIRECT(ADDRESS(MATCH(A10,Calculations!B:B,0),15,1,1,"Calculations")) -> 0 | E10: =INDIRECT(ADDRESS(MATCH(A10,Calculations!B:B,0),16,1,1,"Calculations")) -> 296286.54 | F10: =INDIRECT(ADDRESS(MATCH(A10,Calculations!B:B,0),17,1,1,"Calculations")) -> 1383890.5 | G10: 2802905 | H10: =F10-B10 -> -1281228.5
A11: Development | B11: 449832 | C11: =Calculations!N13 -> 362804 | D11: =INDIRECT(ADDRESS(MATCH(A11,Calculations!B:B,0),15,1,1,"Calculations")) -> 0 | E11: =INDIRECT(ADDRESS(MATCH(A11,Calculations!B:B,0),16,1,1,"Calculations")) -> 98835.554 | F11: =INDIRECT(ADDRESS(MATCH(A11,Calculations!B:B,0),17,1,1,"Calculations")) -> 461639.55 | G11: 237428.81 | H11: =F11-B11 -> 11807.554
A12: Agriculture | B12: 591449 | C12: =INDIRECT(ADDRESS(MATCH(A12,Calculations!B:B,0),14,1,1,"Calculations")) -> 514875.2 | D12: =INDIRECT(ADDRESS(MATCH(A12,Calculations!B:B,0),15,1,1,"Calculations")) -> 98265.774 | E12: =INDIRECT(ADDRESS(MATCH(A12,Calculations!B:B,0),16,1,1,"Calculations")) -> 57533.288 | F12: =INDIRECT(ADDRESS(MATCH(A12,Calculations!B:B,0),17,1,1,"Calculations")) -> 670674.26 | G12: 609114.74 | H12: =F12-B12 -> 79225.26
A13: Art & Music | B13: 1229055 | C13: =INDIRECT(ADDRESS(MATCH(A13,Calculations!B:B,0),14,1,1,"Calculations")) -> 732473.25 | D13: =INDIRECT(ADDRESS(MATCH(A13,Calculations!B:B,0),15,1,1,"Calculations")) -> 98519.839 | E13: =INDIRECT(ADDRESS(MATCH(A13,Calculations!B:B,0),16,1,1,"Calculations")) -> 58628.963 | F13: =INDIRECT(ADDRESS(MATCH(A13,Calculations!B:B,0),17,1,1,"Calculations")) -> 889622.05 | G13: 1224074.3 | H13: =F13-B13 -> -339432.95
A14: Biology | B14: 1043296 | C14: =INDIRECT(ADDRESS(MATCH(A14,Calculations!B:B,0),14,1,1,"Calculations")) -> 914846.37 | D14: =INDIRECT(ADDRESS(MATCH(A14,Calculations!B:B,0),15,1,1,"Calculations")) -> 111218.26 | E14: =INDIRECT(ADDRESS(MATCH(A14,Calculations!B:B,0),16,1,1,"Calculations")) -> 113392.05 | F14: =INDIRECT(ADDRESS(MATCH(A14,Calculations!B:B,0),17,1,1,"Calculations")) -> 1139456.7 | G14: 1166095.8 | H14: =F14-B14 -> 96160.682
A15: Chemistry & Biochemistry | B15: 531545 | C15: =INDIRECT(ADDRESS(MATCH(A15,Calculations!B:B,0),14,1,1,"Calculations")) -> 458454.08 | D15: =INDIRECT(ADDRESS(MATCH(A15,Calculations!B:B,0),15,1,1,"Calculations")) -> 97187.199 | E15: =INDIRECT(ADDRESS(MATCH(A15,Calculations!B:B,0),16,1,1,"Calculations")) -> 52881.837 | F15: =INDIRECT(ADDRESS(MATCH(A15,Calculations!B:B,0),17,1,1,"Calculations")) -> 608523.11 | G15: 593342.58 | H15: =F15-B15 -> 76978.112
A16: Communication, Mass Media, & Theatre | B16: 989795 | C16: =INDIRECT(ADDRESS(MATCH(A16,Calculations!B:B,0),14,1,1,"Calculations")) -> 814244.53 | D16: =INDIRECT(ADDRESS(MATCH(A16,Calculations!B:B,0),15,1,1,"Calculations")) -> 107927.41 | E16: =INDIRECT(ADDRESS(MATCH(A16,Calculations!B:B,0),16,1,1,"Calculations")) -> 99199.958 | F16: =INDIRECT(ADDRESS(MATCH(A16,Calculations!B:B,0),17,1,1,"Calculations")) -> 1021371.9 | G16: 1270127.6 | H16: =F16-B16 -> 31576.902
A17: English & Modern Langagues | B17: 1663079 | C17: =INDIRECT(ADDRESS(MATCH(A17,Calculations!B:B,0),14,1,1,"Calculations")) -> 1326468.1 | D17: =INDIRECT(ADDRESS(MATCH(A17,Calculations!B:B,0),15,1,1,"Calculations")) -> 124544.65 | E17: =INDIRECT(ADDRESS(MATCH(A17,Calculations!B:B,0),16,1,1,"Calculations")) -> 170863.32 | F17: =INDIRECT(ADDRESS(MATCH(A17,Calculations!B:B,0),17,1,1,"Calculations")) -> 1621876 | G17: 1561307.4 | H17: =F17-B17 -> -41202.972
A18: Pol Science & Criminal Justice | B18: 0 | C18: =INDIRECT(ADDRESS(MATCH(A18,Calculations!B:B,0),14,1,1,"Calculations")) -> 265553.62 | D18: =INDIRECT(ADDRESS(MATCH(A18,Calculations!B:B,0),15,1,1,"Calculations")) -> 93172.504 | E18: =INDIRECT(ADDRESS(MATCH(A18,Calculations!B:B,0),16,1,1,"Calculations")) -> 35568.1 | F18: =INDIRECT(ADDRESS(MATCH(A18,Calculations!B:B,0),17,1,1,"Calculations")) -> 394294.23 | G18: 810604.71 | H18: =F18-B18 -> 394294.23
A19: History & Political Science | B19: 1224668 | C19: =INDIRECT(ADDRESS(MATCH(A19,Calculations!B:B,0),14,1,1,"Calculations")) -> 993969.48 | D19: =INDIRECT(ADDRESS(MATCH(A19,Calculations!B:B,0),15,1,1,"Calculations")) -> 115383.96 | E19: =INDIRECT(ADDRESS(MATCH(A19,Calculations!B:B,0),16,1,1,"Calculations")) -> 131356.99 | F19: =INDIRECT(ADDRESS(MATCH(A19,Calculations!B:B,0),17,1,1,"Calculations")) -> 1240710.4 | G19: 747226.05 | H19: =F19-B19 -> 16042.432
A20: Mathematics & Computer Science | B20: 1259999 | C20: =INDIRECT(ADDRESS(MATCH(A20,Calculations!B:B,0),14,1,1,"Calculations")) -> 1290107.5 | D20: =INDIRECT(ADDRESS(MATCH(A20,Calculations!B:B,0),15,1,1,"Calculations")) -> 124992.86 | E20: =INDIRECT(ADDRESS(MATCH(A20,Calculations!B:B,0),16,1,1,"Calculations")) -> 172796.26 | F20: =INDIRECT(ADDRESS(MATCH(A20,Calculations!B:B,0),17,1,1,"Calculations")) -> 1587896.6 | G20: 1641555.2 | H20: =F20-B20 -> 327897.63
A21: Physics | B21: 810053 | C21: =INDIRECT(ADDRESS(MATCH(A21,Calculations!B:B,0),14,1,1,"Calculations")) -> 624510.92 | D21: =INDIRECT(ADDRESS(MATCH(A21,Calculations!B:B,0),15,1,1,"Calculations")) -> 100590.7 | E21: =INDIRECT(ADDRESS(MATCH(A21,Calculations!B:B,0),16,1,1,"Calculations")) -> 67559.751 | F21: =INDIRECT(ADDRESS(MATCH(A21,Calculations!B:B,0),17,1,1,"Calculations")) -> 792661.38 | G21: 699416.9 | H21: =F21-B21 -> -17391.624
A22: Accounting, Economics, & Finance | B22: 1066854 | C22: =INDIRECT(ADDRESS(MATCH(A22,Calculations!B:B,0),14,1,1,"Calculations")) -> 701791.04 | D22: =INDIRECT(ADDRESS(MATCH(A22,Calculations!B:B,0),15,1,1,"Calculations")) -> 103634.68 | E22: =INDIRECT(ADDRESS(MATCH(A22,Calculations!B:B,0),16,1,1,"Calculations")) -> 80687.181 | F22: =INDIRECT(ADDRESS(MATCH(A22,Calculations!B:B,0),17,1,1,"Calculations")) -> 886112.9 | G22: 1231240.4 | H22: =F22-B22 -> -180741.1
A23: Aerospace Studies | B23: 44068 | C23: =INDIRECT(ADDRESS(MATCH(A23,Calculations!B:B,0),14,1,1,"Calculations")) -> 21299.855 | D23: =INDIRECT(ADDRESS(MATCH(A23,Calculations!B:B,0),15,1,1,"Calculations")) -> 85586.526 | E23: =INDIRECT(ADDRESS(MATCH(A23,Calculations!B:B,0),16,1,1,"Calculations")) -> 2852.8903 | F23: =INDIRECT(ADDRESS(MATCH(A23,Calculations!B:B,0),17,1,1,"Calculations")) -> 109739.27 | G23: 45671.08 | H23: =F23-B23 -> 65671.271
A24: Management & Marketing | B24: 1102526 | C24: =INDIRECT(ADDRESS(MATCH(A24,Calculations!B:B,0),14,1,1,"Calculations")) -> 601756.52 | D24: =INDIRECT(ADDRESS(MATCH(A24,Calculations!B:B,0),15,1,1,"Calculations")) -> 99773.383 | E24: =INDIRECT(ADDRESS(MATCH(A24,Calculations!B:B,0),16,1,1,"Calculations")) -> 64034.984 | F24: =INDIRECT(ADDRESS(MATCH(A24,Calculations!B:B,0),17,1,1,"Calculations")) -> 765564.88 | G24: 1224074.3 | H24: =F24-B24 -> -336961.12
A25: Security Studies & Criminal Justice | B25: 193510 | C25: =INDIRECT(ADDRESS(MATCH(A25,Calculations!B:B,0),14,1,1,"Calculations")) -> 387968.43 | D25: =INDIRECT(ADDRESS(MATCH(A25,Calculations!B:B,0),15,1,1,"Calculations")) -> 93865.188 | E25: =INDIRECT(ADDRESS(MATCH(A25,Calculations!B:B,0),16,1,1,"Calculations")) -> 38555.366 | F25: =INDIRECT(ADDRESS(MATCH(A25,Calculations!B:B,0),17,1,1,"Calculations")) -> 520388.98 | H25: =F25-B25 -> 326878.98
A26: Teacher Education | B26: 763138 | C26: =INDIRECT(ADDRESS(MATCH(A26,Calculations!B:B,0),14,1,1,"Calculations")) -> 317414.14 | D26: =INDIRECT(ADDRESS(MATCH(A26,Calculations!B:B,0),15,1,1,"Calculations")) -> 92108.31 | E26: =INDIRECT(ADDRESS(MATCH(A26,Calculations!B:B,0),16,1,1,"Calculations")) -> 30978.668 | F26: =INDIRECT(ADDRESS(MATCH(A26,Calculations!B:B,0),17,1,1,"Calculations")) -> 440501.12 | G26: 872026.21 | H26: =F26-B26 -> -322636.88
A27: Curriculum & Instruction | B27: 459814 | C27: =INDIRECT(ADDRESS(MATCH(A27,Calculations!B:B,0),14,1,1,"Calculations")) -> 977121.94 | D27: =INDIRECT(ADDRESS(MATCH(A27,Calculations!B:B,0),15,1,1,"Calculations")) -> 87700.533 | E27: =INDIRECT(ADDRESS(MATCH(A27,Calculations!B:B,0),16,1,1,"Calculations")) -> 11969.735 | F27: =INDIRECT(ADDRESS(MATCH(A27,Calculations!B:B,0),17,1,1,"Calculations")) -> 1076792.2 | G27: 933895.04 | H27: =F27-B27 -> 616978.2
A28: Kinesiology | B28: 578599 | C28: =INDIRECT(ADDRESS(MATCH(A28,Calculations!B:B,0),14,1,1,"Calculations")) -> 443402.66 | D28: =INDIRECT(ADDRESS(MATCH(A28,Calculations!B:B,0),15,1,1,"Calculations")) -> 95106.748 | E28: =INDIRECT(ADDRESS(MATCH(A28,Calculations!B:B,0),16,1,1,"Calculations")) -> 43909.703 | F28: =INDIRECT(ADDRESS(MATCH(A28,Calculations!B:B,0),17,1,1,"Calculations")) -> 582419.11 | G28: 836218.02 | H28: =F28-B28 -> 3820.115
A29: Nursing | B29: 2203128 | C29: =INDIRECT(ADDRESS(MATCH(A29,Calculations!B:B,0),14,1,1,"Calculations")) -> 1302907.7 | D29: =INDIRECT(ADDRESS(MATCH(A29,Calculations!B:B,0),15,1,1,"Calculations")) -> 104643.75 | E29: =INDIRECT(ADDRESS(MATCH(A29,Calculations!B:B,0),16,1,1,"Calculations")) -> 85038.872 | F29: =INDIRECT(ADDRESS(MATCH(A29,Calculations!B:B,0),17,1,1,"Calculations")) -> 1492590.3 | G29: 2598646.3 | H29: =F29-B29 -> -710537.69
A30: Athletic Training | B30: 0 | C30: =INDIRECT(ADDRESS(MATCH(A30,Calculations!B:B,0),14,1,1,"Calculations")) -> 0 | D30: =INDIRECT(ADDRESS(MATCH(A30,Calculations!B:B,0),15,1,1,"Calculations")) -> 84925 | E30: =INDIRECT(ADDRESS(MATCH(A30,Calculations!B:B,0),16,1,1,"Calculations")) -> 0 | F30: =INDIRECT(ADDRESS(MATCH(A30,Calculations!B:B,0),17,1,1,"Calculations")) -> 84925 | H30: =F30-B30 -> 84925
A31: Physical Therapy | B31: 1082098 | C31: =INDIRECT(ADDRESS(MATCH(A31,Calculations!B:B,0),14,1,1,"Calculations")) -> 0 | D31: =INDIRECT(ADDRESS(MATCH(A31,Calculations!B:B,0),15,1,1,"Calculations")) -> 84925 | E31: =INDIRECT(ADDRESS(MATCH(A31,Calculations!B:B,0),16,1,1,"Calculations")) -> 0 | F31: =INDIRECT(ADDRESS(MATCH(A31,Calculations!B:B,0),17,1,1,"Calculations")) -> 84925 | G31: 1025297.3 | H31: =F31-B31 -> -997173
A32: Psychology, Sociology & Social Work | B32: 1137342 | C32: =INDIRECT(ADDRESS(MATCH(A32,Calculations!B:B,0),14,1,1,"Calculations")) -> 1220224 | D32: =INDIRECT(ADDRESS(MATCH(A32,Calculations!B:B,0),15,1,1,"Calculations")) -> 113334.67 | E32: =INDIRECT(ADDRESS(MATCH(A32,Calculations!B:B,0),16,1,1,"Calculations")) -> 122519.24 | F32: =INDIRECT(ADDRESS(MATCH(A32,Calculations!B:B,0),17,1,1,"Calculations")) -> 1456077.9 | G32: 1229276.2 | H32: =F32-B32 -> 318735.94
A33: Academic Affairs | C33: =INDIRECT(ADDRESS(MATCH(A33,Calculations!B:B,0),14,1,1,"Calculations")) -> 150025.06 | D33: =INDIRECT(ADDRESS(MATCH(A33,Calculations!B:B,0),15,1,1,"Calculations")) -> 89584.444 | E33: =INDIRECT(ADDRESS(MATCH(A33,Calculations!B:B,0),16,1,1,"Calculations")) -> 20094.271 | F33: =INDIRECT(ADDRESS(MATCH(A33,Calculations!B:B,0),17,1,1,"Calculations")) -> 259703.78 | G33: 0 | H33: =F33-B33 -> 259703.78
A34: Facilities | C34: =INDIRECT(ADDRESS(MATCH(A34,Calculations!B:B,0),10,1,1,"Calculations")) -> 0 | D34: =INDIRECT(ADDRESS(MATCH(A34,Calculations!B:B,0),15,1,1,"Calculations")) -> 0 | E34: =INDIRECT(ADDRESS(MATCH(A34,Calculations!B:B,0),16,1,1,"Calculations")) -> 0 | F34: =INDIRECT(ADDRESS(MATCH(A34,Calculations!B:B,0),17,1,1,"Calculations")) -> 0 | G34: 4656768.8
A39: Variables
A40: Faculty (full time) | B40: 0.85
A41: Faculty (adjunct) | B41: 0.15
A42: Academic Operating | B42: 6500
A43: Required Class Size (UG) | B43: 31
A44: Required Class Size (Grad) | B44: 13
A45: Required UG Faculty Teaching Load | B45: 24
A46: Required Grad Faculty Teaching Load | B46: 18
A47: Required UG Lab (HC) | B47: 22
...

Sheet Calculations
C5: 2012 | D5: 2012 | G5: Required | H5: Required | I5: Required | J5: Required | K5: Total | L5: 2011/12 UG | M5: 2011/12 Grad | N5: 2011/12 Projected | O5: HeadCount Driven | P5: 2011/12
B6: BUDGET DIVISION | C6: UG SCH | D6: G SCH | E6: UG Lab (HC) | F6: G Lab (HC) | G6: UG Fac. FTE | H6: G Fac. FTE | I6: UG Lab Fac | J6: G Lab Fac | K6: Faculty | L6: Faculty Salaries | M6: Faculty Salaries | N6: SALARIES | O6: ADMIN & SUPPORT | P6: OPERATING | Q6: TOTAL ALLOCATION | R6: HOLD HARMLESS | S6: DIFFERENCE
B8: President | N8: 1033479 | P8: =IF(ISERROR(IF(K8>0,(K8*Summary!$B$42)+((Calculations!C8+D8)/500*Summary!$B$60),Calculations!N8/Summary!$B$55*Summary!$B$50)),"",IF(G8>0,(G8*Summary!$B$42)+(Calculations!C8/500*Summary!$B$60),Calculations!N8/Summary!$B$55*Summary!$B$50)) -> 281541.74 | Q8: =SUM(N8:P8) -> 1315020.7
B9: Provost | N9: 2932244.7 | P9: =IF(ISERROR(IF(K9>0,(K9*Summary!$B$42)+((Calculations!C9+D9)/500*Summary!$B$60),Calculations!N9/Summary!$B$55*Summary!$B$50)),"",IF(G9>0,(G9*Summary!$B$42)+(Calculations!C9/500*Summary!$B$60),Calculations!N9/Summary!$B$55*Summary!$B$50)) -> 798806.05 | Q9: =SUM(N9:P9) -> 3731050.8
B10: Finance & Aministration | N10: 6191740 | P10: =IF(ISERROR(IF(K10>0,(K10*Summary!$B$42)+((Calculations!C10+D10)/500*Summary!$B$60),Calculations!N10/Summary!$B$55*Summary!$B$50)),"",IF(G10>0,(G10*Summary!$B$42)+(Calculations!C10/500*Summary!$B$60),Calculations!N10/Summary!$B$55*Summary!$B$50)) -> 1686762.1 | Q10: =SUM(N10:P10) -> 7878502.1
B11: Strategy, Planning & Policy | N11: 1253406 | P11: =IF(ISERROR(IF(K11>0,(K11*Summary!$B$42)+((Calculations!C11+D11)/500*Summary!$B$60),Calculations!N11/Summary!$B$55*Summary!$B$50)),"",IF(G11>0,(G11*Summary!$B$42)+(Calculations!C11/500*Summary!$B$60),Calculations!N11/Summary!$B$55*Summary!$B$50)) -> 341454.55 | Q11: =SUM(N11:P11) -> 1594860.5
B12: Student Services & Enrollment Management | N12: 1087604 | P12: =IF(ISERROR(IF(K12>0,(K12*Summary!$B$42)+((Calculations!C12+D12)/500*Summary!$B$60),Calculations!N12/Summary!$B$55*Summary!$B$50)),"",IF(G12>0,(G12*Summary!$B$42)+(Calculations!C12/500*Summary!$B$60),Calculations!N12/Summary!$B$55*Summary!$B$50)) -> 296286.54 | Q12: =SUM(N12:P12) -> 1383890.5
B13: Development | N13: 362804 | P13: =IF(ISERROR(IF(K13>0,(K13*Summary!$B$42)+((Calculations!C13+D13)/500*Summary!$B$60),Calculations!N13/Summary!$B$55*Summary!$B$50)),"",IF(G13>0,(G13*Summary!$B$42)+(Calculations!C13/500*Summary!$B$60),Calculations!N13/Summary!$B$55*Summary!$B$50)) -> 98835.554 | Q13: =SUM(N13:P13) -> 461639.55
B14: Agriculture | C14: =IF(ISERROR(INDIRECT(ADDRESS(MATCH(B14,Data!B:B,0),5,1,1,"Data"))*INDIRECT(ADDRESS(MATCH(B14,'Cost Factor'!B:B,0),21,1,1,"Cost Factor"))),"",INDIRECT(ADDRESS(MATCH(B14,Data!B:B,0),5,1,1,"Data"))*INDIRECT(ADDRESS(MATCH(B14,'Cost Factor'!B:B,0),21,1,1,"Cost Factor"))) -> 5566 | D14: =IF(ISERROR(INDIRECT(ADDRESS(MATCH(B14,Data!B:B,0),6,1,1,"Data"))*INDIRECT(ADDRESS(MATCH(B14,'Cost Factor'!B:B,0),21,1,1,"Cost Factor"))),"",INDIRECT(ADDRESS(MATCH(B14,Data!B:B,0),6,1,1,"Data"))*INDIRECT(ADDRESS(MATCH(B14,'Cost Factor'!B:B,0),21,1,1,"Cost Factor"))) -> 316 | E14: =IF(ISERROR(INDIRECT(ADDRESS(MATCH(B14,Data!B:B,0),8,1,1,"Data"))*INDIRECT(ADDRESS(MATCH(B14,'Cost Factor'!B:B,0),21,1,1,"Cost Factor"))),"",INDIRECT(ADDRESS(MATCH(B14,Data!B:B,0),8,1,1,"Data"))*INDIRECT(ADDRESS(MATCH(B14,'Cost Factor'!B:B,0),21,1,1,"Cost Factor"))) -> 48 | F14: =IF(ISERROR(INDIRECT(ADDRESS(MATCH(B14,Data!B:B,0),9,1,1,"Data"))*INDIRECT(ADDRESS(MATCH(B14,'Cost Factor'!B:B,0),21,1,1,"Cost Factor"))),"",INDIRECT(ADDRESS(MATCH(B14,Data!B:B,0),9,1,1,"Data"))*INDIRECT(ADDRESS(MATCH(B14,'Cost Factor'!B:B,0),21,1,1,"Cost Factor"))) -> 0 | G14: =IF(ISERROR(C14/(Summary!$B$43*Summary!$B$45)),"",C14/(Summary!$B$43*Summary!$B$45)) -> 7.4811828 | H14: =IF(ISERROR(D14/(Summary!$B$44*Summary!$B$46)),"",D14/(Summary!$B$44*Summary!$B$46)) -> 1.3504274 | I14: =E14/(Summary!$B$47*Summary!$B$45*0.67) -> 0.13568521 | J14: =F14/(Summary!$B$46*Summary!$B$48*0.67) -> 0 | K14: =H14+G14+I14+J14 -> 8.9672954 | L14: =IF(ISERROR(((G14+I14)*Summary!$B$40*Summary!$B$53)+((Calculations!G14+I14)*Summary!$B$41*Summary!$B$54)),"",((G14+I14)*Summary!$B$40*Summary!$B$53)+((Calculations!G14+I14)*Summary!$B$41*Summary!$B$54)) -> 437337.71 | M14: =IF(ISERROR(((H14+J14)*Summary!$B$40*Summary!$B$53)+((H14+J14)*Summary!$B$41*Summary!$B$54)),"",((H14+J14)*Summary!$B$40*Summary!$B$53)+((H14+J14)*Summary!$B$41*Summary!$B$54)) -> 77537.487 | N14: =L14+M14 -> 514875.2 | O14: =IF(ISERROR(Summary!$B$55+Summary!$B$56+((Calculations!C14/30)/Summary!$B$49*Summary!$B$56)),"",Summary!$B$55+Summary!$B$56+((Calculations!C14/30)/Summary!$B$49*Summary!$B$56)) -> 98265.774 | P14: =IF(ISERROR(IF(K14>0,(K14*Summary!$B$42)+((Calculations!C14+D14)/500*Summary!$B$60),Calculations!N14/Summary!$B$55*Summary!$B$50)),"",IF(G14>0,(G14*Summary!$B$42)+(Calculations!C14/500*Summary!$B$60),Calculations!N14/Summary!$B$55*Summary!$B$50)) -> 57533.288 | Q14: =SUM(N14:P14) -> 670674.26
B15: Art & Music | C15: =IF(ISERROR(INDIRECT(ADDRESS(MATCH(B15,Data!B:B,0),5,1,1,"Data"))*INDIRECT(ADDRESS(MATCH(B15,'Cost Factor'!B:B,0),21,1,1,"Cost Factor"))),"",INDIRECT(ADDRESS(MATCH(B15,Data!B:B,0),5,1,1,"Data"))*INDIRECT(ADDRESS(MATCH(B15,'Cost Factor'!B:B,0),21,1,1,"Cost Factor"))) -> 5672 | D15: =IF(ISERROR(INDIRECT(ADDRESS(MATCH(B15,Data!B:B,0),6,1,1,"Data"))*INDIRECT(ADDRESS(MATCH(B15,'Cost Factor'!B:B,0),21,1,1,"Cost Factor"))),"",INDIRECT(ADDRESS(MATCH(B15,Data!B:B,0),6,1,1,"Data"))*INDIRECT(ADDRESS(MATCH(B15,'Cost Factor'!B:B,0),21,1,1,"Cost Factor"))) -> 0 | E15: =IF(ISERROR(INDIRECT(ADDRESS(MATCH(B15,Data!B:B,0),8,1,1,"Data"))*INDIRECT(ADDRESS(MATCH(B15,'Cost Factor'!B:B,0),21,1,1,"Cost Factor"))),"",INDIRECT(ADDRESS(MATCH(B15,Data!B:B,0),8,1,1,"Data"))*INDIRECT(ADDRESS(MATCH(B15,'Cost Factor'!B:B,0),21,1,1,"Cost Factor"))) -> 1816 | F15: =IF(ISERROR(INDIRECT(ADDRESS(MATCH(B15,Data!B:B,0),9,1,1,"Data"))*INDIRECT(ADDRESS(MATCH(B15,'Cost Factor'!B:B,0),21,1,1,"Cost Factor"))),"",INDIRECT(ADDRESS(MATCH(B15,Data!B:B,0),9,1,1,"Data"))*INDIRECT(ADDRESS(MATCH(B15,'Cost Factor'!B:B,0),21,1,1,"Cost Factor"))) -> 0 | G15: =IF(ISERROR(C15/(Summary!$B$43*Summary!$B$45)),"",C15/(Summary!$B$43*Summary!$B$45)) -> 7.6236559 | H15: =IF(ISERROR(D15/(Summary!$B$44*Summary!$B$46)),"",D15/(Summary!$B$44*Summary!$B$46)) -> 0 | I15: =E15/(Summary!$B$47*Summary!$B$45*0.67) -> 5.1334238 | J15: =F15/(Summary!$B$46*Summary!$B$48*0.67) -> 0 | K15: =H15+G15+I15+J15 -> 12.75708 | L15: =IF(ISERROR(((G15+I15)*Summary!$B$40*Summary!$B$53)+((Calculations!G15+I15)*Summary!$B$41*Summary!$B$54)),"",((G15+I15)*Summary!$B$40*Summary!$B$53)+((Calculations!G15+I15)*Summary!$B$41*Summary!$B$54)) -> 732473.25 | M15: =IF(ISERROR(((H15+J15)*Summary!$B$40*Summary!$B$53)+((H15+J15)*Summary!$B$41*Summary!$B$54)),"",((H15+J15)*Summary!$B$40*Summary!$B$53)+((H15+J15)*Summary!$B$41*Summary!$B$54)) -> 0 | N15: =L15+M15 -> 732473.25 | O15: =IF(ISERROR(Summary!$B$55+Summary!$B$56+((Calculations!C15/30)/Summary!$B$49*Summary!$B$56)),"",Summary!$B$55+Summary!$B$56+((Calculations!C15/30)/Summary!$B$49*Summary!$B$56)) -> 98519.839 | P15: =IF(ISERROR(IF(K15>0,(K15*Summary!$B$42)+((Calculations!C15+D15)/500*Summary!$B$60),Calculations!N15/Summary!$B$55*Summary!$B$50)),"",IF(G15>0,(G15*Summary!$B$42)+(Calculations!C15/500*Summary!$B$60),Calculations!N15/Summary!$B$55*Summary!$B$50)) -> 58628.963 | Q15: =SUM(N15:P15) -> 889622.05
B16: Biology | C16: =IF(ISERROR(INDIRECT(ADDRESS(MATCH(B16,Data!B:B,0),5,1,1,"Data"))*INDIRECT(ADDRESS(MATCH(B16,'Cost Factor'!B:B,0),21,1,1,"Cost Factor"))),"",INDIRECT(ADDRESS(MATCH(B16,Data!B:B,0),5,1,1,"Data"))*INDIRECT(ADDRESS(MATCH(B16,'Cost Factor'!B:B,0),21,1,1,"Cost Factor"))) -> 10970 | D16: =IF(ISERROR(INDIRECT(ADDRESS(MATCH(B16,Data!B:B,0),6,1,1,"Data"))*INDIRECT(ADDRESS(MATCH(B16,'Cost Factor'!B:B,0),21,1,1,"Cost Factor"))),"",INDIRECT(ADDRESS(MATCH(B16,Data!B:B,0),6,1,1,"Data"))*INDIRECT(ADDRESS(MATCH(B16,'Cost Factor'!B:B,0),21,1,1,"Cost Factor"))) -> 257 | E16: =IF(ISERROR(INDIRECT(ADDRESS(MATCH(B16,Data!B:B,0),8,1,1,"Data"))*INDIRECT(ADDRESS(MATCH(B16,'Cost Factor'!B:B,0),21,1,1,"Cost Factor"))),"",INDIRECT(ADDRESS(MATCH(B16,Data!B:B,0),8,1,1,"Data"))*INDIRECT(ADDRESS(MATCH(B16,'Cost Factor'!B:B,0),21,1,1,"Cost Factor"))) -> 32 | F16: =IF(ISERROR(INDIRECT(ADDRESS(MATCH(B16,Data!B:B,0),9,1,1,"Data"))*INDIRECT(ADDRESS(MATCH(B16,'Cost Factor'!B:B,0),21,1,1,"Cost Factor"))),"",INDIRECT(ADDRESS(MATCH(B16,Data!B:B,0),9,1,1,"Data"))*INDIRECT(ADDRESS(MATCH(B16,'Cost Factor'!B:B,0),21,1,1,"Cost Factor"))) -> 0 | G16: =IF(ISERROR(C16/(Summary!$B$43*Summary!$B$45)),"",C16/(Summary!$B$43*Summary!$B$45)) -> 14.744624 | H16: =IF(ISERROR(D16/(Summary!$B$44*Summary!$B$46)),"",D16/(Summary!$B$44*Summary!$B$46)) -> 1.0982906 | I16: =E16/(Summary!$B$47*Summary!$B$45*0.67) -> 0.090456807 | J16: =F16/(Summary!$B$46*Summary!$B$48*0.67) -> 0 | K16: =H16+G16+I16+J16 -> 15.933371 | L16: =IF(ISERROR(((G16+I16)*Summary!$B$40*Summary!$B$53)+((Calculations!G16+I16)*Summary!$B$41*Summary!$B$54)),"",((G16+I16)*Summary!$B$40*Summary!$B$53)+((Calculations!G16+I16)*Summary!$B$41*Summary!$B$54)) -> 851785.81 | M16: =IF(ISERROR(((H16+J16)*Summary!$B$40*Summary!$B$53)+((H16+J16)*Summary!$B$41*Summary!$B$54)),"",((H16+J16)*Summary!$B$40*Summary!$B$53)+((H16+J16)*Summary!$B$41*Summary!$B$54)) -> 63060.551 | N16: =L16+M16 -> 914846.37 | O16: =IF(ISERROR(Summary!$B$55+Summary!$B$56+((Calculations!C16/30)/Summary!$B$49*Summary!$B$56)),"",Summary!$B$55+Summary!$B$56+((Calculations!C16/30)/Summary!$B$49*Summary!$B$56)) -> 111218.26 | P16: =IF(ISERROR(IF(K16>0,(K16*Summary!$B$42)+((Calculations!C16+D16)/500*Summary!$B$60),Calculations!N16/Summary!$B$55*Summary!$B$50)),"",IF(G16>0,(G16*Summary!$B$42)+(Calculations!C16/500*Summary!$B$60),Calculations!N16/Summary!$B$55*Summary!$B$50)) -> 113392.05 | Q16: =SUM(N16:P16) -> 1139456.7
B17: Chemistry & Biochemistry | C17: =IF(ISERROR(INDIRECT(ADDRESS(MATCH(B17,Data!B:B,0),5,1,1,"Data"))*INDIRECT(ADDRESS(MATCH(B17,'Cost Factor'!B:B,0),21,1,1,"Cost Factor"))),"",INDIRECT(ADDRESS(MATCH(B17,Data!B:B,0),5,1,1,"Data"))*INDIRECT(ADDRESS(MATCH(B17,'Cost Factor'!B:B,0),21,1,1,"Cost Factor"))) -> 5116 | D17: =IF(ISERROR(INDIRECT(ADDRESS(MATCH(B17,Data!B:B,0),6,1,1,"Data"))*INDIRECT(ADDRESS(MATCH(B17,'Cost Factor'!B:B,0),21,1,1,"Cost Factor"))),"",INDIRECT(ADDRESS(MATCH(B17,Data!B:B,0),6,1,1,"Data"))*INDIRECT(ADDRESS(MATCH(B17,'Cost Factor'!B:B,0),21,1,1,"Cost Factor"))) -> 6 | E17: =IF(ISERROR(INDIRECT(ADDRESS(MATCH(B17,Data!B:B,0),8,1,1,"Data"))*INDIRECT(ADDRESS(MATCH(B17,'Cost Factor'!B:B,0),21,1,1,"Cost Factor"))),"",INDIRECT(ADDRESS(MATCH(B17,Data!B:B,0),8,1,1,"Data"))*INDIRECT(ADDRESS(MATCH(B17,'Cost Factor'!B:B,0),21,1,1,"Cost Factor"))) -> 383 | F17: =IF(ISERROR(INDIRECT(ADDRESS(MATCH(B17,Data!B:B,0),9,1,1,"Data"))*INDIRECT(ADDRESS(MATCH(B17,'Cost Factor'!B:B,0),21,1,1,"Cost Factor"))),"",INDIRECT(ADDRESS(MATCH(B17,Data!B:B,0),9,1,1,"Data"))*INDIRECT(ADDRESS(MATCH(B17,'Cost Factor'!B:B,0),21,1,1,"Cost Factor"))) -> 0 | G17: =IF(ISERROR(C17/(Summary!$B$43*Summary!$B$45)),"",C17/(Summary!$B$43*Summary!$B$45)) -> 6.8763441 | H17: =IF(ISERROR(D17/(Summary!$B$44*Summary!$B$46)),"",D17/(Summary!$B$44*Summary!$B$46)) -> 0.025641026 | I17: =E17/(Summary!$B$47*Summary!$B$45*0.67) -> 1.0826549 | J17: =F17/(Summary!$B$46*Summary!$B$48*0.67) -> 0 | K17: =H17+G17+I17+J17 -> 7.98464 | L17: =IF(ISERROR(((G17+I17)*Summary!$B$40*Summary!$B$53)+((Calculations!G17+I17)*Summary!$B$41*Summary!$B$54)),"",((G17+I17)*Summary!$B$40*Summary!$B$53)+((Calculations!G17+I17)*Summary!$B$41*Summary!$B$54)) -> 456981.85 | M17: =IF(ISERROR(((H17+J17)*Summary!$B$40*Summary!$B$53)+((H17+J17)*Summary!$B$41*Summary!$B$54)),"",((H17+J17)*Summary!$B$40*Summary!$B$53)+((H17+J17)*Summary!$B$41*Summary!$B$54)) -> 1472.2308 | N17: =L17+M17 -> 458454.08 | O17: =IF(ISERROR(Summary!$B$55+Summary!$B$56+((Calculations!C17/30)/Summary!$B$49*Summary!$B$56)),"",Summary!$B$55+Summary!$B$56+((Calculations!C17/30)/Summary!$B$49*Summary!$B$56)) -> 97187.199 | P17: =IF(ISERROR(IF(K17>0,(K17*Summary!$B$42)+((Calculations!C17+D17)/500*Summary!$B$60),Calculations!N17/Summary!$B$55*Summary!$B$50)),"",IF(G17>0,(G17*Summary!$B$42)+(Calculations!C17/500*Summary!$B$60),Calculations!N17/Summary!$B$55*Summary!$B$50)) -> 52881.837 | Q17: =SUM(N17:P17) -> 608523.11
B18: Communication, Mass Media, & Theatre | C18: =IF(ISERROR(INDIRECT(ADDRESS(MATCH(B18,Data!B:B,0),5,1,1,"Data"))*INDIRECT(ADDRESS(MATCH(B18,'Cost Factor'!B:B,0),21,1,1,"Cost Factor"))),"",INDIRECT(ADDRESS(MATCH(B18,Data!B:B,0),5,1,1,"Data"))*INDIRECT(ADDRESS(MATCH(B18,'Cost Factor'!B:B,0),21,1,1,"Cost Factor"))) -> 9597 | D18: =IF(ISERROR(INDIRECT(ADDRESS(MATCH(B18,Data!B:B,0),6,1,1,"Data"))*INDIRECT(ADDRESS(MATCH(B18,'Cost Factor'!B:B,0),21,1,1,"Cost Factor"))),"",INDIRECT(ADDRESS(MATCH(B18,Data!B:B,0),6,1,1,"Data"))*INDIRECT(ADDRESS(MATCH(B18,'Cost Factor'!B:B,0),21,1,1,"Cost Factor"))) -> 300 | E18: =IF(ISERROR(INDIRECT(ADDRESS(MATCH(B18,Data!B:B,0),8,1,1,"Data"))*INDIRECT(ADDRESS(MATCH(B18,'Cost Factor'!B:B,0),21,1,1,"Cost Factor"))),"",INDIRECT(ADDRESS(MATCH(B18,Data!B:B,0),8,1,1,"Data"))*INDIRECT(ADDRESS(MATCH(B18,'Cost Factor'!B:B,0),21,1,1,"Cost Factor"))) -> 0 | F18: =IF(ISERROR(INDIRECT(ADDRESS(MATCH(B18,Data!B:B,0),9,1,1,"Data"))*INDIRECT(ADDRESS(MATCH(B18,'Cost Factor'!B:B,0),21,1,1,"Cost Factor"))),"",INDIRECT(ADDRESS(MATCH(B18,Data!B:B,0),9,1,1,"Data"))*INDIRECT(ADDRESS(MATCH(B18,'Cost Factor'!B:B,0),21,1,1,"Cost Factor"))) -> 0 | G18: =IF(ISERROR(C18/(Summary!$B$43*Summary!$B$45)),"",C18/(Summary!$B$43*Summary!$B$45)) -> 12.899194 | H18: =IF(ISERROR(D18/(Summary!$B$44*Summary!$B$46)),"",D18/(Summary!$B$44*Summary!$B$46)) -> 1.2820513 | I18: =E18/(Summary!$B$47*Summary!$B$45*0.67) -> 0 | J18: =F18/(Summary!$B$46*Summary!$B$48*0.67) -> 0 | K18: =H18+G18+I18+J18 -> 14.181245 | L18: =IF(ISERROR(((G18+I18)*Summary!$B$40*Summary!$B$53)+((Calculations!G18+I18)*Summary!$B$41*Summary!$B$54)),"",((G18+I18)*Summary!$B$40*Summary!$B$53)+((Calculations!G18+I18)*Summary!$B$41*Summary!$B$54)) -> 740633 | M18: =IF(ISERROR(((H18+J18)*Summary!$B$40*Summary!$B$53)+((H18+J18)*Summary!$B$41*Summary!$B$54)),"",((H18+J18)*Summary!$B$40*Summary!$B$53)+((H18+J18)*Summary!$B$41*Summary!$B$54)) -> 73611.538 | N18: =L18+M18 -> 814244.53 | O18: =IF(ISERROR(Summary!$B$55+Summary!$B$56+((Calculations!C18/30)/Summary!$B$49*Summary!$B$56)),"",Summary!$B$55+Summary!$B$56+((Calculations!C18/30)/Summary!$B$49*Summary!$B$56)) -> 107927.41 | P18: =IF(ISERROR(IF(K18>0,(K18*Summary!$B$42)+((Calculations!C18+D18)/500*Summary!$B$60),Calculations!N18/Summary!$B$55*Summary!$B$50)),"",IF(G18>0,(G18*Summary!$B$42)+(Calculations!C18/500*Summary!$B$60),Calculations!N18/Summary!$B$55*Summary!$B$50)) -> 99199.958 | Q18: =SUM(N18:P18) -> 1021371.9
B19: English & Modern Langagues | C19: =IF(ISERROR(INDIRECT(ADDRESS(MATCH(B19,Data!B:B,0),5,1,1,"Data"))*INDIRECT(ADDRESS(MATCH(B19,'Cost Factor'!B:B,0),21,1,1,"Cost Factor"))),"",INDIRECT(ADDRESS(MATCH(B19,Data!B:B,0),5,1,1,"Data"))*INDIRECT(ADDRESS(MATCH(B19,'Cost Factor'!B:B,0),21,1,1,"Cost Factor"))) -> 16530 | D19: =IF(ISERROR(INDIRECT(ADDRESS(MATCH(B19,Data!B:B,0),6,1,1,"Data"))*INDIRECT(ADDRESS(MATCH(B19,'Cost Factor'!B:B,0),21,1,1,"Cost Factor"))),"",INDIRECT(ADDRESS(MATCH(B19,Data!B:B,0),6,1,1,"Data"))*INDIRECT(ADDRESS(MATCH(B19,'Cost Factor'!B:B,0),21,1,1,"Cost Factor"))) -> 207 | E19: =IF(ISERROR(INDIRECT(ADDRESS(MATCH(B19,Data!B:B,0),8,1,1,"Data"))*INDIRECT(ADDRESS(MATCH(B19,'Cost Factor'!B:B,0),21,1,1,"Cost Factor"))),"",INDIRECT(ADDRESS(MATCH(B19,Data!B:B,0),8,1,1,"Data"))*INDIRECT(ADDRESS(MATCH(B19,'Cost Factor'!B:B,0),21,1,1,"Cost Factor"))) -> 0 | F19: =IF(ISERROR(INDIRECT(ADDRESS(MATCH(B19,Data!B:B,0),9,1,1,"Data"))*INDIRECT(ADDRESS(MATCH(B19,'Cost Factor'!B:B,0),21,1,1,"Cost Factor"))),"",INDIRECT(ADDRESS(MATCH(B19,Data!B:B,0),9,1,1,"Data"))*INDIRECT(ADDRESS(MATCH(B19,'Cost Factor'!B:B,0),21,1,1,"Cost Factor"))) -> 0 | G19: =IF(ISERROR(C19/(Summary!$B$43*Summary!$B$45)),"",C19/(Summary!$B$43*Summary!$B$45)) -> 22.217742 | H19: =IF(ISERROR(D19/(Summary!$B$44*Summary!$B$46)),"",D19/(Summary!$B$44*Summary!$B$46)) -> 0.88461538 | I19: =E19/(Summary!$B$47*Summary!$B$45*0.67) -> 0 | J19: =F19/(Summary!$B$46*Summary!$B$48*0.67) -> 0 | K19: =H19+G19+I19+J19 -> 23.102357 | L19: =IF(ISERROR(((G19+I19)*Summary!$B$40*Summary!$B$53)+((Calculations!G19+I19)*Summary!$B$41*Summary!$B$54)),"",((G19+I19)*Summary!$B$40*Summary!$B$53)+((Calculations!G19+I19)*Summary!$B$41*Summary!$B$54)) -> 1275676.1 | M19: =IF(ISERROR(((H19+J19)*Summary!$B$40*Summary!$B$53)+((H19+J19)*Summary!$B$41*Summary!$B$54)),"",((H19+J19)*Summary!$B$40*Summary!$B$53)+((H19+J19)*Summary!$B$41*Summary!$B$54)) -> 50791.962 | N19: =L19+M19 -> 1326468.1 | O19: =IF(ISERROR(Summary!$B$55+Summary!$B$56+((Calculations!C19/30)/Summary!$B$49*Summary!$B$56)),"",Summary!$B$55+Summary!$B$56+((Calculations!C19/30)/Summary!$B$49*Summary!$B$56)) -> 124544.65 | P19: =IF(ISERROR(IF(K19>0,(K19*Summary!$B$42)+((Calculations!C19+D19)/500*Summary!$B$60),Calculations!N19/Summary!$B$55*Summary!$B$50)),"",IF(G19>0,(G19*Summary!$B$42)+(Calculations!C19/500*Summary!$B$60),Calculations!N19/Summary!$B$55*Summary!$B$50)) -> 170863.32 | Q19: =SUM(N19:P19) -> 1621876
B20: Pol Science & Criminal Justice | C20: =IF(ISERROR(INDIRECT(ADDRESS(MATCH(B20,Data!B:B,0),5,1,1,"Data"))*INDIRECT(ADDRESS(MATCH(B20,'Cost Factor'!B:B,0),21,1,1,"Cost Factor"))),"",INDIRECT(ADDRESS(MATCH(B20,Data!B:B,0),5,1,1,"Data"))*INDIRECT(ADDRESS(MATCH(B20,'Cost Factor'!B:B,0),21,1,1,"Cost Factor"))) -> 3441 | D20: =IF(ISERROR(INDIRECT(ADDRESS(MATCH(B20,Data!B:B,0),6,1,1,"Data"))*INDIRECT(ADDRESS(MATCH(B20,'Cost Factor'!B:B,0),21,1,1,"Cost Factor"))),"",INDIRECT(ADDRESS(MATCH(B20,Data!B:B,0),6,1,1,"Data"))*INDIRECT(ADDRESS(MATCH(B20,'Cost Factor'!B:B,0),21,1,1,"Cost Factor"))) -> 0 | E20: =IF(ISERROR(INDIRECT(ADDRESS(MATCH(B20,Data!B:B,0),8,1,1,"Data"))*INDIRECT(ADDRESS(MATCH(B20,'Cost Factor'!B:B,0),21,1,1,"Cost Factor"))),"",INDIRECT(ADDRESS(MATCH(B20,Data!B:B,0),8,1,1,"Data"))*INDIRECT(ADDRESS(MATCH(B20,'Cost Factor'!B:B,0),21,1,1,"Cost Factor"))) -> 0 | F20: =IF(ISERROR(INDIRECT(ADDRESS(MATCH(B20,Data!B:B,0),9,1,1,"Data"))*INDIRECT(ADDRESS(MATCH(B20,'Cost Factor'!B:B,0),21,1,1,"Cost Factor"))),"",INDIRECT(ADDRESS(MATCH(B20,Data!B:B,0),9,1,1,"Data"))*INDIRECT(ADDRESS(MATCH(B20,'Cost Factor'!B:B,0),21,1,1,"Cost Factor"))) -> 0 | G20: =IF(ISERROR(C20/(Summary!$B$43*Summary!$B$45)),"",C20/(Summary!$B$43*Summary!$B$45)) -> 4.625 | H20: =IF(ISERROR(D20/(Summary!$B$44*Summary!$B$46)),"",D20/(Summary!$B$44*Summary!$B$46)) -> 0 | I20: =E20/(Summary!$B$47*Summary!$B$45*0.67) -> 0 | J20: =F20/(Summary!$B$46*Summary!$B$48*0.67) -> 0 | K20: =H20+G20+I20+J20 -> 4.625 | L20: =IF(ISERROR(((G20+I20)*Summary!$B$40*Summary!$B$53)+((Calculations!G20+I20)*Summary!$B$41*Summary!$B$54)),"",((G20+I20)*Summary!$B$40*Summary!$B$53)+((Calculations!G20+I20)*Summary!$B$41*Summary!$B$54)) -> 265553.62 | M20: =IF(ISERROR(((H20+J20)*Summary!$B$40*Summary!$B$53)+((H20+J20)*Summary!$B$41*Summary!$B$54)),"",((H20+J20)*Summary!$B$40*Summary!$B$53)+((H20+J20)*Summary!$B$41*Summary!$B$54)) -> 0 | N20: =L20+M20 -> 265553.62 | O20: =IF(ISERROR(Summary!$B$55+Summary!$B$56+((Calculations!C20/30)/Summary!$B$49*Summary!$B$56)),"",Summary!$B$55+Summary!$B$56+((Calculations!C20/30)/Summary!$B$49*Summary!$B$56)) -> 93172.504 | P20: =IF(ISERROR(IF(K20>0,(K20*Summary!$B$42)+((Calculations!C20+D20)/500*Summary!$B$60),Calculations!N20/Summary!$B$55*Summary!$B$50)),"",IF(G20>0,(G20*Summary!$B$42)+(Calculations!C20/500*Summary!$B$60),Calculations!N20/Summary!$B$55*Summary!$B$50)) -> 35568.1 | Q20: =SUM(N20:P20) -> 394294.23
B21: History & Political Science | C21: =IF(ISERROR(INDIRECT(ADDRESS(MATCH(B21,Data!B:B,0),5,1,1,"Data"))*INDIRECT(ADDRESS(MATCH(B21,'Cost Factor'!B:B,0),21,1,1,"Cost Factor"))),"",INDIRECT(ADDRESS(MATCH(B21,Data!B:B,0),5,1,1,"Data"))*INDIRECT(ADDRESS(MATCH(B21,'Cost Factor'!B:B,0),21,1,1,"Cost Factor"))) -> 12708 | D21: =IF(ISERROR(INDIRECT(ADDRESS(MATCH(B21,Data!B:B,0),6,1,1,"Data"))*INDIRECT(ADDRESS(MATCH(B21,'Cost Factor'!B:B,0),21,1,1,"Cost Factor"))),"",INDIRECT(ADDRESS(MATCH(B21,Data!B:B,0),6,1,1,"Data"))*INDIRECT(ADDRESS(MATCH(B21,'Cost Factor'!B:B,0),21,1,1,"Cost Factor"))) -> 54 | E21: =IF(ISERROR(INDIRECT(ADDRESS(MATCH(B21,Data!B:B,0),8,1,1,"Data"))*INDIRECT(ADDRESS(MATCH(B21,'Cost Factor'!B:B,0),21,1,1,"Cost Factor"))),"",INDIRECT(ADDRESS(MATCH(B21,Data!B:B,0),8,1,1,"Data"))*INDIRECT(ADDRESS(MATCH(B21,'Cost Factor'!B:B,0),21,1,1,"Cost Factor"))) -> 0 | F21: =IF(ISERROR(INDIRECT(ADDRESS(MATCH(B21,Data!B:B,0),9,1,1,"Data"))*INDIRECT(ADDRESS(MATCH(B21,'Cost Factor'!B:B,0),21,1,1,"Cost Factor"))),"",INDIRECT(ADDRESS(MATCH(B21,Data!B:B,0),9,1,1,"Data"))*INDIRECT(ADDRESS(MATCH(B21,'Cost Factor'!B:B,0),21,1,1,"Cost Factor"))) -> 0 | G21: =IF(ISERROR(C21/(Summary!$B$43*Summary!$B$45)),"",C21/(Summary!$B$43*Summary!$B$45)) -> 17.080645 | H21: =IF(ISERROR(D21/(Summary!$B$44*Summary!$B$46)),"",D21/(Summary!$B$44*Summary!$B$46)) -> 0.23076923 | I21: =E21/(Summary!$B$47*Summary!$B$45*0.67) -> 0 | J21: =F21/(Summary!$B$46*Summary!$B$48*0.67) -> 0 | K21: =H21+G21+I21+J21 -> 17.311414 | L21: =IF(ISERROR(((G21+I21)*Summary!$B$40*Summary!$B$53)+((Calculations!G21+I21)*Summary!$B$41*Summary!$B$54)),"",((G21+I21)*Summary!$B$40*Summary!$B$53)+((Calculations!G21+I21)*Summary!$B$41*Summary!$B$54)) -> 980719.4 | M21: =IF(ISERROR(((H21+J21)*Summary!$B$40*Summary!$B$53)+((H21+J21)*Summary!$B$41*Summary!$B$54)),"",((H21+J21)*Summary!$B$40*Summary!$B$53)+((H21+J21)*Summary!$B$41*Summary!$B$54)) -> 13250.077 | N21: =L21+M21 -> 993969.48 | O21: =IF(ISERROR(Summary!$B$55+Summary!$B$56+((Calculations!C21/30)/Summary!$B$49*Summary!$B$56)),"",Summary!$B$55+Summary!$B$56+((Calculations!C21/30)/Summary!$B$49*Summary!$B$56)) -> 115383.96 | P21: =IF(ISERROR(IF(K21>0,(K21*Summary!$B$42)+((Calculations!C21+D21)/500*Summary!$B$60),Calculations!N21/Summary!$B$55*Summary!$B$50)),"",IF(G21>0,(G21*Summary!$B$42)+(Calculations!C21/500*Summary!$B$60),Calculations!N21/Summary!$B$55*Summary!$B$50)) -> 131356.99 | Q21: =SUM(N21:P21) -> 1240710.4
B22: Mathematics & Computer Science | C22: =IF(ISERROR(INDIRECT(ADDRESS(MATCH(B22,Data!B:B,0),5,1,1,"Data"))*INDIRECT(ADDRESS(MATCH(B22,'Cost Factor'!B:B,0),21,1,1,"Cost Factor"))),"",INDIRECT(ADDRESS(MATCH(B22,Data!B:B,0),5,1,1,"Data"))*INDIRECT(ADDRESS(MATCH(B22,'Cost Factor'!B:B,0),21,1,1,"Cost Factor"))) -> 16717 | D22: =IF(ISERROR(INDIRECT(ADDRESS(MATCH(B22,Data!B:B,0),6,1,1,"Data"))*INDIRECT(ADDRESS(MATCH(B22,'Cost Factor'!B:B,0),21,1,1,"Cost Factor"))),"",INDIRECT(ADDRESS(MATCH(B22,Data!B:B,0),6,1,1,"Data"))*INDIRECT(ADDRESS(MATCH(B22,'Cost Factor'!B:B,0),21,1,1,"Cost Factor"))) -> 0 | E22: =IF(ISERROR(INDIRECT(ADDRESS(MATCH(B22,Data!B:B,0),8,1,1,"Data"))*INDIRECT(ADDRESS(MATCH(B22,'Cost Factor'!B:B,0),21,1,1,"Cost Factor"))),"",INDIRECT(ADDRESS(MATCH(B22,Data!B:B,0),8,1,1,"Data"))*INDIRECT(ADDRESS(MATCH(B22,'Cost Factor'!B:B,0),21,1,1,"Cost Factor"))) -> 0 | F22: =IF(ISERROR(INDIRECT(ADDRESS(MATCH(B22,Data!B:B,0),9,1,1,"Data"))*INDIRECT(ADDRESS(MATCH(B22,'Cost Factor'!B:B,0),21,1,1,"Cost Factor"))),"",INDIRECT(ADDRESS(MATCH(B22,Data!B:B,0),9,1,1,"Data"))*INDIRECT(ADDRESS(MATCH(B22,'Cost Factor'!B:B,0),21,1,1,"Cost Factor"))) -> 0 | G22: =IF(ISERROR(C22/(Summary!$B$43*Summary!$B$45)),"",C22/(Summary!$B$43*Summary!$B$45)) -> 22.469086 | H22: =IF(ISERROR(D22/(Summary!$B$44*Summary!$B$46)),"",D22/(Summary!$B$44*Summary!$B$46)) -> 0 | I22: =E22/(Summary!$B$47*Summary!$B$45*0.67) -> 0 | J22: =F22/(Summary!$B$46*Summary!$B$48*0.67) -> 0 | K22: =H22+G22+I22+J22 -> 22.469086 | L22: =IF(ISERROR(((G22+I22)*Summary!$B$40*Summary!$B$53)+((Calculations!G22+I22)*Summary!$B$41*Summary!$B$54)),"",((G22+I22)*Summary!$B$40*Summary!$B$53)+((Calculations!G22+I22)*Summary!$B$41*Summary!$B$54)) -> 1290107.5 | M22: =IF(ISERROR(((H22+J22)*Summary!$B$40*Summary!$B$53)+((H22+J22)*Summary!$B$41*Summary!$B$54)),"",((H22+J22)*Summary!$B$40*Summary!$B$53)+((H22+J22)*Summary!$B$41*Summary!$B$54)) -> 0 | N22: =L22+M22 -> 1290107.5 | O22: =IF(ISERROR(Summary!$B$55+Summary!$B$56+((Calculations!C22/30)/Summary!$B$49*Summary!$B$56)),"",Summary!$B$55+Summary!$B$56+((Calculations!C22/30)/Summary!$B$49*Summary!$B$56)) -> 124992.86 | P22: =IF(ISERROR(IF(K22>0,(K22*Summary!$B$42)+((Calculations!C22+D22)/500*Summary!$B$60),Calculations!N22/Summary!$B$55*Summary!$B$50)),"",IF(G22>0,(G22*Summary!$B$42)+(Calculations!C22/500*Summary!$B$60),Calculations!N22/Summary!$B$55*Summary!$B$50)) -> 172796.26 | Q22: =SUM(N22:P22) -> 1587896.6
B23: Physics | C23: =IF(ISERROR(INDIRECT(ADDRESS(MATCH(B23,Data!B:B,0),5,1,1,"Data"))*INDIRECT(ADDRESS(MATCH(B23,'Cost Factor'!B:B,0),21,1,1,"Cost Factor"))),"",INDIRECT(ADDRESS(MATCH(B23,Data!B:B,0),5,1,1,"Data"))*INDIRECT(ADDRESS(MATCH(B23,'Cost Factor'!B:B,0),21,1,1,"Cost Factor"))) -> 6536 | D23: =IF(ISERROR(INDIRECT(ADDRESS(MATCH(B23,Data!B:B,0),6,1,1,"Data"))*INDIRECT(ADDRESS(MATCH(B23,'Cost Factor'!B:B,0),21,1,1,"Cost Factor"))),"",INDIRECT(ADDRESS(MATCH(B23,Data!B:B,0),6,1,1,"Data"))*INDIRECT(ADDRESS(MATCH(B23,'Cost Factor'!B:B,0),21,1,1,"Cost Factor"))) -> 0 | E23: =IF(ISERROR(INDIRECT(ADDRESS(MATCH(B23,Data!B:B,0),8,1,1,"Data"))*INDIRECT(ADDRESS(MATCH(B23,'Cost Factor'!B:B,0),21,1,1,"Cost Factor"))),"",INDIRECT(ADDRESS(MATCH(B23,Data!B:B,0),8,1,1,"Data"))*INDIRECT(ADDRESS(MATCH(B23,'Cost Factor'!B:B,0),21,1,1,"Cost Factor"))) -> 740 | F23: =IF(ISERROR(INDIRECT(ADDRESS(MATCH(B23,Data!B:B,0),9,1,1,"Data"))*INDIRECT(ADDRESS(MATCH(B23,'Cost Factor'!B:B,0),21,1,1,"Cost Factor"))),"",INDIRECT(ADDRESS(MATCH(B23,Data!B:B,0),9,1,1,"Data"))*INDIRECT(ADDRESS(MATCH(B23,'Cost Factor'!B:B,0),21,1,1,"Cost Factor"))) -> 0 | G23: =IF(ISERROR(C23/(Summary!$B$43*Summary!$B$45)),"",C23/(Summary!$B$43*Summary!$B$45)) -> 8.7849462 | H23: =IF(ISERROR(D23/(Summary!$B$44*Summary!$B$46)),"",D23/(Summary!$B$44*Summary!$B$46)) -> 0 | I23: =E23/(Summary!$B$47*Summary!$B$45*0.67) -> 2.0918137 | J23: =F23/(Summary!$B$46*Summary!$B$48*0.67) -> 0 | K23: =H23+G23+I23+J23 -> 10.87676 | L23: =IF(ISERROR(((G23+I23)*Summary!$B$40*Summary!$B$53)+((Calculations!G23+I23)*Summary!$B$41*Summary!$B$54)),"",((G23+I23)*Summary!$B$40*Summary!$B$53)+((Calculations!G23+I23)*Summary!$B$41*Summary!$B$54)) -> 624510.92 | M23: =IF(ISERROR(((H23+J23)*Summary!$B$40*Summary!$B$53)+((H23+J23)*Summary!$B$41*Summary!$B$54)),"",((H23+J23)*Summary!$B$40*Summary!$B$53)+((H23+J23)*Summary!$B$41*Summary!$B$54)) -> 0 | N23: =L23+M23 -> 624510.92 | O23: =IF(ISERROR(Summary!$B$55+Summary!$B$56+((Calculations!C23/30)/Summary!$B$49*Summary!$B$56)),"",Summary!$B$55+Summary!$B$56+((Calculations!C23/30)/Summary!$B$49*Summary!$B$56)) -> 100590.7 | P23: =IF(ISERROR(IF(K23>0,(K23*Summary!$B$42)+((Calculations!C23+D23)/500*Summary!$B$60),Calculations!N23/Summary!$B$55*Summary!$B$50)),"",IF(G23>0,(G23*Summary!$B$42)+(Calculations!C23/500*Summary!$B$60),Calculations!N23/Summary!$B$55*Summary!$B$50)) -> 67559.751 | Q23: =SUM(N23:P23) -> 792661.38
B24: Accounting, Economics, & Finance | C24: =IF(ISERROR(INDIRECT(ADDRESS(MATCH(B24,Data!B:B,0),5,1,1,"Data"))*INDIRECT(ADDRESS(MATCH(B24,'Cost Factor'!B:B,0),21,1,1,"Cost Factor"))),"",INDIRECT(ADDRESS(MATCH(B24,Data!B:B,0),5,1,1,"Data"))*INDIRECT(ADDRESS(MATCH(B24,'Cost Factor'!B:B,0),21,1,1,"Cost Factor"))) -> 7806 | D24: =IF(ISERROR(INDIRECT(ADDRESS(MATCH(B24,Data!B:B,0),6,1,1,"Data"))*INDIRECT(ADDRESS(MATCH(B24,'Cost Factor'!B:B,0),21,1,1,"Cost Factor"))),"",INDIRECT(ADDRESS(MATCH(B24,Data!B:B,0),6,1,1,"Data"))*INDIRECT(ADDRESS(MATCH(B24,'Cost Factor'!B:B,0),21,1,1,"Cost Factor"))) -> 405 | E24: =IF(ISERROR(INDIRECT(ADDRESS(MATCH(B24,Data!B:B,0),8,1,1,"Data"))*INDIRECT(ADDRESS(MATCH(B24,'Cost Factor'!B:B,0),21,1,1,"Cost Factor"))),"",INDIRECT(ADDRESS(MATCH(B24,Data!B:B,0),8,1,1,"Data"))*INDIRECT(ADDRESS(MATCH(B24,'Cost Factor'!B:B,0),21,1,1,"Cost Factor"))) -> 0 | F24: =IF(ISERROR(INDIRECT(ADDRESS(MATCH(B24,Data!B:B,0),9,1,1,"Data"))*INDIRECT(ADDRESS(MATCH(B24,'Cost Factor'!B:B,0),21,1,1,"Cost Factor"))),"",INDIRECT(ADDRESS(MATCH(B24,Data!B:B,0),9,1,1,"Data"))*INDIRECT(ADDRESS(MATCH(B24,'Cost Factor'!B:B,0),21,1,1,"Cost Factor"))) -> 0 | G24: =IF(ISERROR(C24/(Summary!$B$43*Summary!$B$45)),"",C24/(Summary!$B$43*Summary!$B$45)) -> 10.491935 | H24: =IF(ISERROR(D24/(Summary!$B$44*Summary!$B$46)),"",D24/(Summary!$B$44*Summary!$B$46)) -> 1.7307692 | I24: =E24/(Summary!$B$47*Summary!$B$45*0.67) -> 0 | J24: =F24/(Summary!$B$46*Summary!$B$48*0.67) -> 0 | K24: =H24+G24+I24+J24 -> 12.222705 | L24: =IF(ISERROR(((G24+I24)*Summary!$B$40*Summary!$B$53)+((Calculations!G24+I24)*Summary!$B$41*Summary!$B$54)),"",((G24+I24)*Summary!$B$40*Summary!$B$53)+((Calculations!G24+I24)*Summary!$B$41*Summary!$B$54)) -> 602415.46 | M24: =IF(ISERROR(((H24+J24)*Summary!$B$40*Summary!$B$53)+((H24+J24)*Summary!$B$41*Summary!$B$54)),"",((H24+J24)*Summary!$B$40*Summary!$B$53)+((H24+J24)*Summary!$B$41*Summary!$B$54)) -> 99375.577 | N24: =L24+M24 -> 701791.04 | O24: =IF(ISERROR(Summary!$B$55+Summary!$B$56+((Calculations!C24/30)/Summary!$B$49*Summary!$B$56)),"",Summary!$B$55+Summary!$B$56+((Calculations!C24/30)/Summary!$B$49*Summary!$B$56)) -> 103634.68 | P24: =IF(ISERROR(IF(K24>0,(K24*Summary!$B$42)+((Calculations!C24+D24)/500*Summary!$B$60),Calculations!N24/Summary!$B$55*Summary!$B$50)),"",IF(G24>0,(G24*Summary!$B$42)+(Calculations!C24/500*Summary!$B$60),Calculations!N24/Summary!$B$55*Summary!$B$50)) -> 80687.181 | Q24: =SUM(N24:P24) -> 886112.9
B25: Aerospace Studies | C25: =IF(ISERROR(INDIRECT(ADDRESS(MATCH(B25,Data!B:B,0),5,1,1,"Data"))*INDIRECT(ADDRESS(MATCH(B25,'Cost Factor'!B:B,0),21,1,1,"Cost Factor"))),"",INDIRECT(ADDRESS(MATCH(B25,Data!B:B,0),5,1,1,"Data"))*INDIRECT(ADDRESS(MATCH(B25,'Cost Factor'!B:B,0),21,1,1,"Cost Factor"))) -> 276 | D25: =IF(ISERROR(INDIRECT(ADDRESS(MATCH(B25,Data!B:B,0),6,1,1,"Data"))*INDIRECT(ADDRESS(MATCH(B25,'Cost Factor'!B:B,0),21,1,1,"Cost Factor"))),"",INDIRECT(ADDRESS(MATCH(B25,Data!B:B,0),6,1,1,"Data"))*INDIRECT(ADDRESS(MATCH(B25,'Cost Factor'!B:B,0),21,1,1,"Cost Factor"))) -> 0 | E25: =IF(ISERROR(INDIRECT(ADDRESS(MATCH(B25,Data!B:B,0),8,1,1,"Data"))*INDIRECT(ADDRESS(MATCH(B25,'Cost Factor'!B:B,0),21,1,1,"Cost Factor"))),"",INDIRECT(ADDRESS(MATCH(B25,Data!B:B,0),8,1,1,"Data"))*INDIRECT(ADDRESS(MATCH(B25,'Cost Factor'!B:B,0),21,1,1,"Cost Factor"))) -> 0 | F25: =IF(ISERROR(INDIRECT(ADDRESS(MATCH(B25,Data!B:B,0),9,1,1,"Data"))*INDIRECT(ADDRESS(MATCH(B25,'Cost Factor'!B:B,0),21,1,1,"Cost Factor"))),"",INDIRECT(ADDRESS(MATCH(B25,Data!B:B,0),9,1,1,"Data"))*INDIRECT(ADDRESS(MATCH(B25,'Cost Factor'!B:B,0),21,1,1,"Cost Factor"))) -> 0 | G25: =IF(ISERROR(C25/(Summary!$B$43*Summary!$B$45)),"",C25/(Summary!$B$43*Summary!$B$45)) -> 0.37096774 | H25: =IF(ISERROR(D25/(Summary!$B$44*Summary!$B$46)),"",D25/(Summary!$B$44*Summary!$B$46)) -> 0 | I25: =E25/(Summary!$B$47*Summary!$B$45*0.67) -> 0 | J25: =F25/(Summary!$B$46*Summary!$B$48*0.67) -> 0 | K25: =H25+G25+I25+J25 -> 0.37096774 | L25: =IF(ISERROR(((G25+I25)*Summary!$B$40*Summary!$B$53)+((Calculations!G25+I25)*Summary!$B$41*Summary!$B$54)),"",((G25+I25)*Summary!$B$40*Summary!$B$53)+((Calculations!G25+I25)*Summary!$B$41*Summary!$B$54)) -> 21299.855 | M25: =IF(ISERROR(((H25+J25)*Summary!$B$40*Summary!$B$53)+((H25+J25)*Summary!$B$41*Summary!$B$54)),"",((H25+J25)*Summary!$B$40*Summary!$B$53)+((H25+J25)*Summary!$B$41*Summary!$B$54)) -> 0 | N25: =L25+M25 -> 21299.855 | O25: =IF(ISERROR(Summary!$B$55+Summary!$B$56+((Calculations!C25/30)/Summary!$B$49*Summary!$B$56)),"",Summary!$B$55+Summary!$B$56+((Calculations!C25/30)/Summary!$B$49*Summary!$B$56)) -> 85586.526 | P25: =IF(ISERROR(IF(K25>0,(K25*Summary!$B$42)+((Calculations!C25+D25)/500*Summary!$B$60),Calculations!N25/Summary!$B$55*Summary!$B$50)),"",IF(G25>0,(G25*Summary!$B$42)+(Calculations!C25/500*Summary!$B$60),Calculations!N25/Summary!$B$55*Summary!$B$50)) -> 2852.8903 | Q25: =SUM(N25:P25) -> 109739.27
... B35: Academic Affairs | C35: =IF(ISERROR(INDIRECT(ADDRESS(MATCH(B35,Data!B:B,0),5,1,1,"Data"))*INDIRECT(ADDRESS(MATCH(B35,'Cost Factor'!B:B,0),21,1,1,"Cost Factor"))),"",INDIRECT(ADDRESS(MATCH(B35,Data!B:B,0),5,1,1,"Data"))*INDIRECT(ADDRESS(MATCH(B35,'Cost Factor'!B:B,0),21,1,1,"Cost Factor"))) -> 1944 | D35: =IF(ISERROR(INDIRECT(ADDRESS(MATCH(B35,Data!B:B,0),6,1,1,"Data"))*INDIRECT(ADDRESS(MATCH(B35,'Cost Factor'!B:B,0),21,1,1,"Cost Factor"))),"",INDIRECT(ADDRESS(MATCH(B35,Data!B:B,0),6,1,1,"Data"))*INDIRECT(ADDRESS(MATCH(B35,'Cost Factor'!B:B,0),21,1,1,"Cost Factor"))) -> 0 | E35: =IF(ISERROR(INDIRECT(ADDRESS(MATCH(B35,Data!B:B,0),8,1,1,"Data"))*INDIRECT(ADDRESS(MATCH(B35,'Cost Factor'!B:B,0),21,1,1,"Cost Factor"))),"",INDIRECT(ADDRESS(MATCH(B35,Data!B:B,0),8,1,1,"Data"))*INDIRECT(ADDRESS(MATCH(B35,'Cost Factor'!B:B,0),21,1,1,"Cost Factor"))) -> 0 | F35: =IF(ISERROR(INDIRECT(ADDRESS(MATCH(B35,Data!B:B,0),9,1,1,"Data"))*INDIRECT(ADDRESS(MATCH(B35,'Cost Factor'!B:B,0),21,1,1,"Cost Factor"))),"",INDIRECT(ADDRESS(MATCH(B35,Data!B:B,0),9,1,1,"Data"))*INDIRECT(ADDRESS(MATCH(B35,'Cost Factor'!B:B,0),21,1,1,"Cost Factor"))) -> 0 | G35: =IF(ISERROR(C35/(Summary!$B$43*Summary!$B$45)),"",C35/(Summary!$B$43*Summary!$B$45)) -> 2.6129032 | H35: =IF(ISERROR(D35/(Summary!$B$44*Summary!$B$46)),"",D35/(Summary!$B$44*Summary!$B$46)) -> 0 | I35: =E35/(Summary!$B$47*Summary!$B$45*0.67) -> 0 | J35: =F35/(Summary!$B$46*Summary!$B$48*0.67) -> 0 | K35: =H35+G35+I35+J35 -> 2.6129032 | L35: =IF(ISERROR(((G35+I35)*Summary!$B$40*Summary!$B$53)+((Calculations!G35+I35)*Summary!$B$41*Summary!$B$54)),"",((G35+I35)*Summary!$B$40*Summary!$B$53)+((Calculations!G35+I35)*Summary!$B$41*Summary!$B$54)) -> 150025.06 | M35: =IF(ISERROR(((H35+J35)*Summary!$B$40*Summary!$B$53)+((H35+J35)*Summary!$B$41*Summary!$B$54)),"",((H35+J35)*Summary!$B$40*Summary!$B$53)+((H35+J35)*Summary!$B$41*Summary!$B$54)) -> 0 | N35: =L35+M35 -> 150025.06 | O35: =IF(ISERROR(Summary!$B$55+Summary!$B$56+((Calculations!C35/30)/Summary!$B$49*Summary!$B$56)),"",Summary!$B$55+Summary!$B$56+((Calculations!C35/30)/Summary!$B$49*Summary!$B$56)) -> 89584.444 | P35: =IF(ISERROR(IF(K35>0,(K35*Summary!$B$42)+((Calculations!C35+D35)/500*Summary!$B$60),Calculations!N35/Summary!$B$55*Summary!$B$50)),"",IF(G35>0,(G35*Summary!$B$42)+(Calculations!C35/500*Summary!$B$60),Calculations!N35/Summary!$B$55*Summary!$B$50)) -> 20094.271 | Q35: =SUM(N35:P35) -> 259703.78
B36: Facilities

Sheet Cost Factor
C1: 2010/11
B2: Total Adjusted Revenues | C2: =[1]Sheet4!$M$54 -> 46865589
B3: Administrative $
B4: Facility $ (prior yr facilities allocation) | C4: 4206660
B5: Instructional Funding | C5: =C33 -> 20319210
B6: Inst. Overhead Factor | C6: =(C2-C4-C5)/C5 -> 1.0994383
I7: Not Needed
C9: 2010/11 Expenditures | D9: 2010/11 Instructional Compensation | E9: 2011/12 Total Credits | F9: Instructional Cost per Credit | G9: Departmental Cost per Credit | H9: Institutional Cost per Credit | I9: Departmental Overhead % | J9: Calculated Faculty FTE | K9: Actual Faculty FTE | L9: Faculty Instructional Hours | M9: IH_Cost | N9: Department IH_Cost | O9: Institutional IH_Cost | P9: Revenue per Credit Hour | Q9: Instructional Break-Even Class Size | R9: Departmental Break-Even Class Size | S9: Institutional Break-Even Class Size | T9: Restricted Class Size | U9: Cost Factor
B10: Agriculture | C10: =INDIRECT(ADDRESS(MATCH(B10,Summary!A:A,0),7,1,1,"Summary")) -> 609114.74 | D10: 404624.43 | E10: =INDIRECT(ADDRESS(MATCH(B10,Data!B:B,0),7,1,1,"Data")) -> 5882 | F10: =IF(ISERROR(D10/E10),"",D10/E10) -> 68.790281 | G10: =IF(ISERROR((C10)/E10),"",(C10)/E10) -> 103.55572 | H10: =IF(ISERROR(G10*(1+$C$6)),"",G10*(1+$C$6)) -> 217.40885 | I10: =IF(ISERROR((G10/F10)-1),"",(G10/F10)-1) -> 0.505383 | J10: =INDIRECT(ADDRESS(MATCH(B10,Calculations!B:B,0),11,1,1,"Calculations")) -> 8.9672954 | K10: 3.219 | L10: =IF(ISERROR(K10*Summary!$B$45),"",K10*Summary!$B$45) -> 77.256 | M10: =IF(ISERROR(D10/L10),"",D10/L10) -> 5237.4499 | N10: =IF(ISERROR((C10+D10)/L10),"",(C10+D10)/L10) -> 13121.818 | O10: =IF(ISERROR(N10*(1+$C$6)),"",N10*(1+$C$6)) -> 27548.448 | P10: =((2425.05+135)/15)+64.99 -> 235.66 | Q10: =IF(ISERROR(M10/P10),"",M10/P10) -> 22.224603 | R10: =IF(ISERROR(N10/P10),"",N10/P10) -> 55.681142 | S10: =IF(ISERROR(O10/P10),"",O10/P10) -> 116.89912 | U10: =IF(T10>0,Summary!$B$43/T10,IF(S10<Summary!$B$43,'Cost Factor'!S10/Summary!$B$43,1)) -> 1
B11: Art & Music | C11: =INDIRECT(ADDRESS(MATCH(B11,Summary!A:A,0),7,1,1,"Summary")) -> 1224074.3 | D11: 1124676.9 | E11: =INDIRECT(ADDRESS(MATCH(B11,Data!B:B,0),7,1,1,"Data")) -> 5672 | F11: =IF(ISERROR(D11/E11),"",D11/E11) -> 198.28578 | G11: =IF(ISERROR((C11)/E11),"",(C11)/E11) -> 215.80999 | H11: =IF(ISERROR(G11*(1+$C$6)),"",G11*(1+$C$6)) -> 453.07976 | I11: =IF(ISERROR((G11/F11)-1),"",(G11/F11)-1) -> 0.088378562 | J11: =INDIRECT(ADDRESS(MATCH(B11,Calculations!B:B,0),11,1,1,"Calculations")) -> 12.75708 | K11: 18 | L11: =IF(ISERROR(K11*Summary!$B$45),"",K11*Summary!$B$45) -> 432 | M11: =IF(ISERROR(D11/L11),"",D11/L11) -> 2603.4188 | N11: =IF(ISERROR((C11+D11)/L11),"",(C11+D11)/L11) -> 5436.9241 | O11: =IF(ISERROR(N11*(1+$C$6)),"",N11*(1+$C$6)) -> 11414.487 | P11: =((2425.05+135)/15)+64.99 -> 235.66 | Q11: =IF(ISERROR(M11/P11),"",M11/P11) -> 11.047351 | R11: =IF(ISERROR(N11/P11),"",N11/P11) -> 23.071052 | S11: =IF(ISERROR(O11/P11),"",O11/P11) -> 48.43625 | U11: =IF(T11>0,Summary!$B$43/T11,IF(S11<Summary!$B$43,'Cost Factor'!S11/Summary!$B$43,1)) -> 1
B12: Biology | C12: =INDIRECT(ADDRESS(MATCH(B12,Summary!A:A,0),7,1,1,"Summary")) -> 1166095.8 | D12: 996802.07 | E12: =INDIRECT(ADDRESS(MATCH(B12,Data!B:B,0),7,1,1,"Data")) -> 11227 | F12: =IF(ISERROR(D12/E12),"",D12/E12) -> 88.786147 | G12: =IF(ISERROR((C12)/E12),"",(C12)/E12) -> 103.86531 | H12: =IF(ISERROR(G12*(1+$C$6)),"",G12*(1+$C$6)) -> 218.05881 | I12: =IF(ISERROR((G12/F12)-1),"",(G12/F12)-1) -> 0.16983687 | J12: =INDIRECT(ADDRESS(MATCH(B12,Calculations!B:B,0),11,1,1,"Calculations")) -> 15.933371 | K12: 15.125 | L12: =IF(ISERROR(K12*Summary!$B$45),"",K12*Summary!$B$45) -> 363 | M12: =IF(ISERROR(D12/L12),"",D12/L12) -> 2746.0112 | N12: =IF(ISERROR((C12+D12)/L12),"",(C12+D12)/L12) -> 5958.3964 | O12: =IF(ISERROR(N12*(1+$C$6)),"",N12*(1+$C$6)) -> 12509.286 | P12: =((2425.05+135)/15)+64.99 -> 235.66 | Q12: =IF(ISERROR(M12/P12),"",M12/P12) -> 11.652428 | R12: =IF(ISERROR(N12/P12),"",N12/P12) -> 25.283868 | S12: =IF(ISERROR(O12/P12),"",O12/P12) -> 53.081922 | U12: =IF(T12>0,Summary!$B$43/T12,IF(S12<Summary!$B$43,'Cost Factor'!S12/Summary!$B$43,1)) -> 1
B13: Chemistry & Biochemistry | C13: =INDIRECT(ADDRESS(MATCH(B13,Summary!A:A,0),7,1,1,"Summary")) -> 593342.58 | D13: 514254.34 | E13: =INDIRECT(ADDRESS(MATCH(B13,Data!B:B,0),7,1,1,"Data")) -> 5122 | F13: =IF(ISERROR(D13/E13),"",D13/E13) -> 100.40108 | G13: =IF(ISERROR((C13)/E13),"",(C13)/E13) -> 115.84197 | H13: =IF(ISERROR(G13*(1+$C$6)),"",G13*(1+$C$6)) -> 243.20308 | I13: =IF(ISERROR((G13/F13)-1),"",(G13/F13)-1) -> 0.15379207 | J13: =INDIRECT(ADDRESS(MATCH(B13,Calculations!B:B,0),11,1,1,"Calculations")) -> 7.98464 | K13: 8.875 | L13: =IF(ISERROR(K13*Summary!$B$45),"",K13*Summary!$B$45) -> 213 | M13: =IF(ISERROR(D13/L13),"",D13/L13) -> 2414.3396 | N13: =IF(ISERROR((C13+D13)/L13),"",(C13+D13)/L13) -> 5199.9855 | O13: =IF(ISERROR(N13*(1+$C$6)),"",N13*(1+$C$6)) -> 10917.049 | P13: =((2425.05+135)/15)+64.99 -> 235.66 | Q13: =IF(ISERROR(M13/P13),"",M13/P13) -> 10.245012 | R13: =IF(ISERROR(N13/P13),"",N13/P13) -> 22.065626 | S13: =IF(ISERROR(O13/P13),"",O13/P13) -> 46.325422 | U13: =IF(T13>0,Summary!$B$43/T13,IF(S13<Summary!$B$43,'Cost Factor'!S13/Summary!$B$43,1)) -> 1
B14: Communication, Mass Media, & Theatre | C14: =INDIRECT(ADDRESS(MATCH(B14,Summary!A:A,0),7,1,1,"Summary")) -> 1270127.6 | D14: 981628.61 | E14: =INDIRECT(ADDRESS(MATCH(B14,Data!B:B,0),7,1,1,"Data")) -> 9897 | F14: =IF(ISERROR(D14/E14),"",D14/E14) -> 99.184461 | G14: =IF(ISERROR((C14)/E14),"",(C14)/E14) -> 128.33461 | H14: =IF(ISERROR(G14*(1+$C$6)),"",G14*(1+$C$6)) -> 269.43059 | I14: =IF(ISERROR((G14/F14)-1),"",(G14/F14)-1) -> 0.29389832 | J14: =INDIRECT(ADDRESS(MATCH(B14,Calculations!B:B,0),11,1,1,"Calculations")) -> 14.181245 | K14: 13.11 | L14: =IF(ISERROR(K14*Summary!$B$45),"",K14*Summary!$B$45) -> 314.64 | M14: =IF(ISERROR(D14/L14),"",D14/L14) -> 3119.8468 | N14: =IF(ISERROR((C14+D14)/L14),"",(C14+D14)/L14) -> 7156.6114 | O14: =IF(ISERROR(N14*(1+$C$6)),"",N14*(1+$C$6)) -> 15024.864 | P14: =((2425.05+135)/15)+64.99 -> 235.66 | Q14: =IF(ISERROR(M14/P14),"",M14/P14) -> 13.238763 | R14: =IF(ISERROR(N14/P14),"",N14/P14) -> 30.368376 | S14: =IF(ISERROR(O14/P14),"",O14/P14) -> 63.756532 | U14: =IF(T14>0,Summary!$B$43/T14,IF(S14<Summary!$B$43,'Cost Factor'!S14/Summary!$B$43,1)) -> 1
B15: English & Modern Langagues | C15: =INDIRECT(ADDRESS(MATCH(B15,Summary!A:A,0),7,1,1,"Summary")) -> 1561307.4 | D15: 1878453.3 | E15: =INDIRECT(ADDRESS(MATCH(B15,Data!B:B,0),7,1,1,"Data")) -> 16737 | F15: =IF(ISERROR(D15/E15),"",D15/E15) -> 112.23357 | G15: =IF(ISERROR((C15)/E15),"",(C15)/E15) -> 93.284783 | H15: =IF(ISERROR(G15*(1+$C$6)),"",G15*(1+$C$6)) -> 195.84565 | I15: =IF(ISERROR((G15/F15)-1),"",(G15/F15)-1) -> -0.16883352 | J15: =INDIRECT(ADDRESS(MATCH(B15,Calculations!B:B,0),11,1,1,"Calculations")) -> 23.102357 | K15: 7.5 | L15: =IF(ISERROR(K15*Summary!$B$45),"",K15*Summary!$B$45) -> 180 | M15: =IF(ISERROR(D15/L15),"",D15/L15) -> 10435.852 | N15: =IF(ISERROR((C15+D15)/L15),"",(C15+D15)/L15) -> 19109.782 | O15: =IF(ISERROR(N15*(1+$C$6)),"",N15*(1+$C$6)) -> 40119.808 | P15: =((2425.05+135)/15)+64.99 -> 235.66 | Q15: =IF(ISERROR(M15/P15),"",M15/P15) -> 44.283508 | R15: =IF(ISERROR(N15/P15),"",N15/P15) -> 81.090476 | S15: =IF(ISERROR(O15/P15),"",O15/P15) -> 170.24445 | U15: =IF(T15>0,Summary!$B$43/T15,IF(S15<Summary!$B$43,'Cost Factor'!S15/Summary!$B$43,1)) -> 1
B16: Pol Science & Criminal Justice | C16: =INDIRECT(ADDRESS(MATCH(B16,Summary!A:A,0),7,1,1,"Summary")) -> 810604.71 | D16: 762164.38 | E16: =INDIRECT(ADDRESS(MATCH(B16,Data!B:B,0),7,1,1,"Data")) -> 3441 | F16: =IF(ISERROR(D16/E16),"",D16/E16) -> 221.49502 | G16: =IF(ISERROR((C16)/E16),"",(C16)/E16) -> 235.57242 | H16: =IF(ISERROR(G16*(1+$C$6)),"",G16*(1+$C$6)) -> 494.56978 | I16: =IF(ISERROR((G16/F16)-1),"",(G16/F16)-1) -> 0.063556276 | J16: =INDIRECT(ADDRESS(MATCH(B16,Calculations!B:B,0),11,1,1,"Calculations")) -> 4.625 | K16: 10.75 | L16: =IF(ISERROR(K16*Summary!$B$45),"",K16*Summary!$B$45) -> 258 | M16: =IF(ISERROR(D16/L16),"",D16/L16) -> 2954.1255 | N16: =IF(ISERROR((C16+D16)/L16),"",(C16+D16)/L16) -> 6096.0042 | O16: =IF(ISERROR(N16*(1+$C$6)),"",N16*(1+$C$6)) -> 12798.185 | P16: =((2425.05+135)/15)+64.99 -> 235.66 | Q16: =IF(ISERROR(M16/P16),"",M16/P16) -> 12.535541 | R16: =IF(ISERROR(N16/P16),"",N16/P16) -> 25.867794 | S16: =IF(ISERROR(O16/P16),"",O16/P16) -> 54.307837 | U16: =IF(T16>0,Summary!$B$43/T16,IF(S16<Summary!$B$43,'Cost Factor'!S16/Summary!$B$43,1)) -> 1
B17: History & Political Science | C17: =INDIRECT(ADDRESS(MATCH(B17,Summary!A:A,0),7,1,1,"Summary")) -> 747226.05 | D17: 692558.3 | E17: =INDIRECT(ADDRESS(MATCH(B17,Data!B:B,0),7,1,1,"Data")) -> 12762 | F17: =IF(ISERROR(D17/E17),"",D17/E17) -> 54.267223 | G17: =IF(ISERROR((C17)/E17),"",(C17)/E17) -> 58.550858 | H17: =IF(ISERROR(G17*(1+$C$6)),"",G17*(1+$C$6)) -> 122.92392 | I17: =IF(ISERROR((G17/F17)-1),"",(G17/F17)-1) -> 0.078935954 | J17: =INDIRECT(ADDRESS(MATCH(B17,Calculations!B:B,0),11,1,1,"Calculations")) -> 17.311414 | K17: 10.625 | L17: =IF(ISERROR(K17*Summary!$B$45),"",K17*Summary!$B$45) -> 255 | M17: =IF(ISERROR(D17/L17),"",D17/L17) -> 2715.9149 | N17: =IF(ISERROR((C17+D17)/L17),"",(C17+D17)/L17) -> 5646.2131 | O17: =IF(ISERROR(N17*(1+$C$6)),"",N17*(1+$C$6)) -> 11853.876 | P17: =((2425.05+135)/15)+64.99 -> 235.66 | Q17: =IF(ISERROR(M17/P17),"",M17/P17) -> 11.524717 | R17: =IF(ISERROR(N17/P17),"",N17/P17) -> 23.959149 | S17: =IF(ISERROR(O17/P17),"",O17/P17) -> 50.300757 | U17: =IF(T17>0,Summary!$B$43/T17,IF(S17<Summary!$B$43,'Cost Factor'!S17/Summary!$B$43,1)) -> 1
B18: Mathematics & Computer Science | C18: =INDIRECT(ADDRESS(MATCH(B18,Summary!A:A,0),7,1,1,"Summary")) -> 1641555.2 | D18: 1448850.5 | E18: =INDIRECT(ADDRESS(MATCH(B18,Data!B:B,0),7,1,1,"Data")) -> 16717 | F18: =IF(ISERROR(D18/E18),"",D18/E18) -> 86.669288 | G18: =IF(ISERROR((C18)/E18),"",(C18)/E18) -> 98.196759 | H18: =IF(ISERROR(G18*(1+$C$6)),"",G18*(1+$C$6)) -> 206.15804 | I18: =IF(ISERROR((G18/F18)-1),"",(G18/F18)-1) -> 0.13300526 | J18: =INDIRECT(ADDRESS(MATCH(B18,Calculations!B:B,0),11,1,1,"Calculations")) -> 22.469086 | K18: =4.5+19 -> 23.5 | L18: =IF(ISERROR(K18*Summary!$B$45),"",K18*Summary!$B$45) -> 564 | M18: =IF(ISERROR(D18/L18),"",D18/L18) -> 2568.8838 | N18: =IF(ISERROR((C18+D18)/L18),"",(C18+D18)/L18) -> 5479.4427 | O18: =IF(ISERROR(N18*(1+$C$6)),"",N18*(1+$C$6)) -> 11503.752 | P18: =((2425.05+135)/15)+64.99 -> 235.66 | Q18: =IF(ISERROR(M18/P18),"",M18/P18) -> 10.900806 | R18: =IF(ISERROR(N18/P18),"",N18/P18) -> 23.251476 | S18: =IF(ISERROR(O18/P18),"",O18/P18) -> 48.815039 | U18: =IF(T18>0,Summary!$B$43/T18,IF(S18<Summary!$B$43,'Cost Factor'!S18/Summary!$B$43,1)) -> 1
B19: Physics | C19: =INDIRECT(ADDRESS(MATCH(B19,Summary!A:A,0),7,1,1,"Summary")) -> 699416.9 | D19: 604948.09 | E19: =INDIRECT(ADDRESS(MATCH(B19,Data!B:B,0),7,1,1,"Data")) -> 6536 | F19: =IF(ISERROR(D19/E19),"",D19/E19) -> 92.556317 | G19: =IF(ISERROR((C19)/E19),"",(C19)/E19) -> 107.00993 | H19: =IF(ISERROR(G19*(1+$C$6)),"",G19*(1+$C$6)) -> 224.66075 | I19: =IF(ISERROR((G19/F19)-1),"",(G19/F19)-1) -> 0.15616019 | J19: =INDIRECT(ADDRESS(MATCH(B19,Calculations!B:B,0),11,1,1,"Calculations")) -> 10.87676 | K19: 8 | L19: =IF(ISERROR(K19*Summary!$B$45),"",K19*Summary!$B$45) -> 192 | M19: =IF(ISERROR(D19/L19),"",D19/L19) -> 3150.7713 | N19: =IF(ISERROR((C19+D19)/L19),"",(C19+D19)/L19) -> 6793.5677 | O19: =IF(ISERROR(N19*(1+$C$6)),"",N19*(1+$C$6)) -> 14262.676 | P19: =((2425.05+135)/15)+64.99 -> 235.66 | Q19: =IF(ISERROR(M19/P19),"",M19/P19) -> 13.369988 | R19: =IF(ISERROR(N19/P19),"",N19/P19) -> 28.827835 | S19: =IF(ISERROR(O19/P19),"",O19/P19) -> 60.522262 | U19: =IF(T19>0,Summary!$B$43/T19,IF(S19<Summary!$B$43,'Cost Factor'!S19/Summary!$B$43,1)) -> 1
