Workbook
Name Boards: #REF!
Name Boards: #REF!
Name Boards: #REF!

Sheet Start Here
A1: Welcome to the West Virginia Farm and Ranch Land Protection Program (FRPP) Application Matrix
A2: Please enter the below basic information to start the application.
A3: Information from this page will auto-complete information in the following tabs.
A4: Each tab is set for quick printing as needed.
A5: On all tabs, only complete the yellow highlighted areas.
A8: Entity Name:
A9: County Name:
A10: Contact Name:
A11: Contact Title:
A12: Contact Email:
A13: Contact Phone:
A14: Contact Address: | D14: Example | E14: 123 My Street
E15: Somewhere, WV 2XXXX
A17: Chairman Name:
A18: Chairman Email:
A19: Chairman Phone:
A20: Chairman Address: | D20: Example | E20: 123 My Street
E21: Somewhere, WV 2XXXX
A23: Date of Application:
A25: 2nd Entity Name:
A26: County Name:
A27: Contact Name:
A28: Contact Title:
A29: Contact Email:
A30: Contact Phone:
A31: Contact Address: | D31: Example | E31: 123 My Street
E32: Somewhere, WV 2XXXX
A34: Participant Name: | D34: All names on the Deed | I34: Choose the most common crop type on the application
A35: 2nd Participant: | E35: must be listed. | I35: Choose the most common livestock type on the application
A36: 3rd Participant: | D36: All other names here.
A37: Executor | D37: Contact if different then name on deed
A39: Participant Phone:
A40: Mailing Address: | D40: Example | E40: 123 My Street
E41: Somewhere, WV 2XXXX
A42: Physical Address: | D42: Example | E42: 123 My Street
A43: (If different) | E43: Somewhere, WV 2XXXX
A44: Google Map Link:
C80: West Virginia Agricultural Land Protection Authority | D80: WV | G80: Barley | H80: Aquaculture
C81: Berkeley County Farmland Protection Board | D81: Berkeley | G81: Berries | H81: Beef
C82: Fayette County Farmland Protection Board | D82: Fayette | G82: Coffee | H82: Bees
...

Sheet Entity Checklist
A1: Farm and Ranch Land Protection Program (FRPP)
A2: Entity Application Checklist
A4: Entity: | C4: Contact Name:
A5: ='Start Here'!C8 -> 0 | C5: ='Start Here'!C10 -> 0
A6: Date: | C6: Phone No:
A7: ='Start Here'!C23 -> 0 | C7: ='Start Here'!C13 -> 0
A8: Please submit all information in a three ring binder using this checklist as the table of contents
A9: Primary Entity Information (The Entity that will be Accepting the Federal Contribution)
A10: 1. Evidence of an established entity (state or local government statute or ordinance or non-governmental organization mission statement attached). | C10: Enclose Exhibit A:
C11: Program documentation.
A12: 2. Evidence of a commitment to long-term conservation of agricultural or ranch lands through the use of voluntary conservation easements that protect farm lands from conversion to nonagricultural uses (list of easements acquired and held by the cooperating entity). | C12: Enclose Exhibit B:
C13: A list of closed conservation easements in the county or area
C14: Date of most recent monitoring of each easement.
C15: Entity which monitored each easement
A16: 3. Provide evidence of the entity’s policies related to title searches, title insurance and appraisal standards. | C16: Enclose Exhibit C:
C17: Policy for obtaining appraisals from a certified general appraiser using the UASFLA (Yellow Book) standard | E17: Use RFP approved by Authority and Assoc
C18: Policy for title searches and title insurance obtained for all easements.
A19: 4. Evidence of staff capability dedicated to easement monitoring and stewardship. | C19: Enclose Exhibit D:
C20: Full-time staff
C21: Part-time staff
C22: Contract staff and/or land trusts monitoring the easement
C23: Volunteers assigned to monitor easements for your entity.
A24: 5. Evidence of the availability of funds equal to at least 50 percent of the estimated fair market value of the conservation easement (including landowner donation)(State or local government appropriation or statement from non-government organization that funds are available attached). | C24: Enclose Exhibit E:
C25: Financial Position (Tab WV-300-24) completed and signed.
A26: 6. Landowner Parcel information. | C26: Enclose Exhibit F-
C27: Farm and Ranchland Protection Program- Landowner - Parcel Application
C28: Most recent county parcel application
A29: 7. Property Location is necessary for hazardous materials review and other application documentation. | C29: Enclose Exhibit G-
C30: Parcel Contact Information
A31: 8. Attach county location map of all protected parcels and indicate the location of this parcel. Indicate on the map any protected properties within a mile of the offered parcel. | C31: Enclose Exhibit H:
C32: Shape files
A33: 9. Agree to use the Model Deed of Conservation Easement | C33: Entity Signature
A34: Secondary Entity Information –Including NGO's (non-profit organizations such as land trusts) or governmental organizations
A35: Entity: | C35: Contact Name:
A36: ='Start Here'!C25 -> 0 | C36: ='Start Here'!C27 -> 0
A37: Date: | C37: Phone No:
A38: ='Start Here'!C23 -> 0 | C38: ='Start Here'!C30 -> 0
A39: Please submit all information in a three ring binder using this checklist as the table of contents
A40: A. Evidence of an established entity (state or local government statute or ordinance or non-governmental organization mission statement attached). | C40: Enclose Exhibit A:
C41: Program documentation.
...

Sheet Financial Position
A1: Farm & Ranch Land Protection Program (FRPP)
A2: Financial Position
A6: Entity: | B6: ='Start Here'!C8 -> 0
A7: County: | B7: ='Start Here'!C9 -> 0
A8: ='Entity Checklist'!A6 -> Date: | B8: ='Start Here'!C23 -> 0
A10: Cash and Investments
A11: Easement Commitments
A12: Uncommitted funds currently available | E12: =E10-E11 -> 0
A14: Estimated Operations next 12 Months:
A16: Transfer Tax Revenues
A17: Administrative & Overhead
A18: Other Easement Commitments Planned
A19: Net available | E19: =E16-(E17+E18) -> 0
A21: Available for USDA Match | E21: =E12+E19 -> 0
A25: Print Name: | C25: ='Start Here'!C10 -> 0 | E25: Title: | F25: ='Start Here'!C11 -> 0
A27: Phone: | C27: ='Start Here'!C13 -> 0 | E27: E-Mail: | F27: ='Start Here'!C12 -> 0
A30: Signature: | F30: Date: | G30: ='Start Here'!C23 -> 0

Sheet 2nd Entity Financial Position
A1: Farm & Ranch Land Protection Program (FRPP)
A2: Financial Position
A6: Entity: | B6: ='Start Here'!C25 -> 0
A7: County: | B7: ='Start Here'!C26 -> 0
A8: ='Entity Checklist'!A6 -> Date: | B8: ='Start Here'!C23 -> 0
A10: Cash and Investments
A11: Easement Commitments
A12: Uncommitted funds currently available | E12: =E10-E11 -> 0
A14: Estimated Operations next 12 Months:
A16: Transfer Tax Revenues
A17: Administrative & Overhead
A18: Other Easement Commitments Planned
A19: Net available | E19: =E16-(E17+E18) -> 0
A21: Available for USDA Match | E21: =E12+E19 -> 0
A25: Print Name: | C25: ='Start Here'!C27 -> 0 | E25: Title: | F25: ='Start Here'!C28 -> 0
A27: Phone: | C27: ='Start Here'!C30 -> 0 | E27: E-Mail: | F27: ='Start Here'!C29 -> 0
A30: Signature: | F30: Date: | G30: ='Start Here'!C23 -> 0

Sheet Parcel Application
A1: Farm and Ranch Land Protection Program (FRPP)
A2: Landowner - Parcel Application
A4: Participant Name | G4: Entity
A5: ='Start Here'!C34 -> 0 | G5: ='Start Here'!C8 -> 0
A6: Date: | G6: County
A7: ='Start Here'!C23 -> 0 | G7: ='Start Here'!C9 -> 0
A9: This application is to be submitted with the WV-300-25 (Rev. 11/2011)
A11: 1 | B11: Entity or Entities Associated with the Parcel: | G11: =G5 -> 0
G12: ='Start Here'!C25 -> 0
A14: 2 | B14: Name(s) of the landowners of the parcel as stated in the deed: (All names on the deed must become Farm Bill Eligible) | G14: =A5 -> 0
G15: ='Start Here'!C35 -> 0
G16: ='Start Here'!C36 -> 0
A17: 3 | B17: If a partnership or corporation, names of all partners or shareholders. Power of attorney or authorized agent if needed. (please attach)
A20: 4 | B20: Physical Address of the parcel: (required for Phase I) | G20: Mailing Address of landowner(s):
B21: ='Start Here'!C42 -> 0 | G21: ='Start Here'!C40 -> 0
B22: ='Start Here'!C43 -> 0 | G22: ='Start Here'!C41 -> 0
A23: 5 | B23: Legal Description of the parcel. (Attach copy of deed, deeds or will) | G23: Deed Book(s)
G24: Page Number(s)
G25: Tax Map
G26: Parcel Number
A27: 6 | B27: Size of the parcel in acres offered for easement. | I27: Notes
C28: Easement (Including Exhibit B & D) | G28: 0 | H28: Acres
C29: Residential Dwelling (Exhibit B) | G29: 0 | H29: Acres | I29: 2 ac max per & subject to easement
C30: Retained Development (Exhibit D) | G30: 0 | H30: Acres | I30: 2 ac max per & subject to easement
C31: Locally Funded Only Area | G31: 0 | H31: Acres | I31: Not funded by NRCS contribution
I32: Not subject to the easement
C33: Donated Area | G33: 0 | H33: Acres | I33: Not funded by NRCS contribution
C34: Exception Area | G34: 0 | H34: Acres | I34: Will be subdivided prior to closing - not funded.
C35: Area offered to NRCS | G35: =G28 -> 0 | H35: Acres | I35: NRCS Easement
C36: Total Area of Easement | G36: =SUM(G28+G33) -> 0 | H36: Acres
C37: Total Farm Size | G37: =SUM(G28+G31+G33+G34) -> 0 | H37: Acres
A38: 7 | B38: FSA and NRCS Forms, including: Conservation Program Application (NRCS-CPA-1200); Payment Eligibility Form (Form CCC-526); Highly Erodible Land (Form AD-1026); Freedom of Information Forms; and AGI Certification (Form specific for year) | G38: Please complete these at the local FSA service center for Farm Bill Program eligibility.
G39: Update AGI each year enrolled in program.
A40: 8 | B40: Maps of the parcel showing the proposed NRCS easement area. | G40: Attach legible color aerial photo, tax map and soil map with table identifying the prime/unique/statewide/locally important soils.
A41: 9 | B41: Acres of the prime, unique, or Statewide and locally important soil in the proposed NRCS area. (Attach soils map and table) | H41: Prime: | J41: 0 | K41: Acres
H42: Unique: | J42: 0 | K42: Acres
H43: Statewide: | J43: 0 | K43: Acres
H44: Locally Important: | J44: 0 | K44: Acres
H45: Total: | J45: =SUM(J41+J42+J43+J44) -> 0 | K45: Acres
G46: Percent of Proposed NRCS area | J46: =SUM(J45/G35) -> #DIV/0!
...

Sheet Ranking Factors
A1: Farm and Ranch Land Protection Program (FRPP)
A2: Ranking Factors
A4: Participant Name: | B4: Entity:
A5: ='Start Here'!C34 -> 0 | B5: ='Start Here'!C8 -> 0
A6: Date: | B6: County:
A7: ='Start Here'!C23 -> 0 | B7: ='Start Here'!C9 -> 0
A8: National Factors
A9: Ranking Factor and Scaling | C9: Maximum | D9: Points
A10: 1. Percent of prime, unique, and important farmland in the parcel to be protected (0 points for 50 percent or less, 2 points for every percent above 50 percent) | C10: 100 | D10: =IF(D11 =E11, C11, 0) -> #DIV/0!
A11: (Eligibility Criteria) | B11: ='Parcel Application'!J46 -> #DIV/0! | C11: =SUM((B11-0.5)*2)*100 -> #DIV/0! | D11: =IF(C11 <0, 0, C11) -> #DIV/0! | E11: =IF(C11 >100, 100, C11) -> #DIV/0!
A12: 2. Percent of cropland, pastureland, grassland in the parcel to be protected (0 points for 33 percent or less, 1.5 points for every percent above 33 percent) | C12: 100 | D12: =IF(C13 =D13, E12, 0) -> #DIV/0! | E12: =IF(D13 >100, 100, D13) -> #DIV/0! | F12: =SUM((B13-0.33)*1.5)*100 -> #DIV/0!
A13: (Eligibility Criteria) | B13: =SUM('Parcel Application'!J48:J50)/'Parcel Application'!G35 -> #DIV/0! | C13: =IF(B13 <=0.33, 0, D13) -> #DIV/0! | D13: =IF(B13 >0.33, F12, 0) -> #DIV/0!
A14: 3. Ratio of the total acres of land in the parcel to be protected to average farm size in the county according to the most recent USDA Census of Agriculture (www.agcensus.usda.gov) (0 points for a ratio of 0.5 or less; 20 points for a ratio of 0.5 and 1.0; 20 points plus 1 point per acre for a ratio of 1.0 or greater) | C14: 200 | D14: =IF(F14 <=0, 0, F14) -> #DIV/0! | E14: =IF(C15 + D15 =40, 'Parcel Application'!G36-H122+D15,C15) -> #DIV/0! | F14: =IF(E14 >200, 200, E14) -> #DIV/0!
B15: =('Parcel Application'!G36/'Ranking Factors'!H122) -> #DIV/0! | C15: =IF(B15 >0.5, 20, 0) -> #DIV/0! | D15: =IF(B15 >1, 20, 0) -> #DIV/0!
A16: 4. Decrease in the percentage of acreage of farm and ranch land in the county in which the parcel is located between the last two USDA Censuses of Agriculture (www.agcensus.usda.gov) (0 points for decrease of 0 percent or less, 1 point for every percent of decrease up to 9.9 percent. 0 points for decrease of more than 10 percent) | C16: 10 | D16: =IF(C17 =D17, B17, 0) -> 0
B17: =(100-I122) -> 100 | C17: =IF(B17 >0, B17, 0) -> 100 | D17: =IF(B17 <9.9, B17, 0) -> 0
A18: 5. Percent population growth in the county as documented by the United States Census (www.census.gov) (0 points for growth rate less than state growth rate, 5 points for growth rate 1 to 1.66 times state growth rate, 10 points for growth rate 1.67 to 2.33 times state growth rate, 15 points for growth rate 2.34 to 3 times state growth rate, 0 points for growth rate greater than 3 times state growth rate) | C18: 15 | D18: =E132 -> 0
A19: 6. Population density (population per square mile) as documented by the most recent United States Census (www.census.gov) (0 points for population density less than state population density, 10 points for population density of 1 to 2 times state population density, 15 points for population density of 2 to 3 times state population density, 5 points for population density of more than 3 times state population density) | C19: 15 | D19: =I132 -> 0
A20: Sub-total Points for National Ranking Factors | C20: =C10+C12+C14+C16+C18+C19 -> 440 | D20: =SUM(D10+D12+D14+D16+D18+D19) -> #DIV/0!
A22: Other National Criteria with no Mandate
A23: 7. Proximity of the parcel to other protected land, including military installations (0 points for no protected land within one mile of the boundaries of the parcel, 20 points for each protected parcel within one mile of the boundaries of the parcel) List protected land. (If none, leave blank)
C24: 20 | D24: =IF(A24 >0, 20, 0) -> 0
C25: 20 | D25: =IF(A25 >0, 20, 0) -> 0
C26: 20 | D26: =IF(A26 >0, 20, 0) -> 0
A27: 8. Proximity of the parcel to other agricultural operations and infrastructure (0 points for less than 250 acres of protected land within one mile of the boundaries of the parcel, 0 points for 250-500 acres of protected land within one mile of the boundaries of the parcel, 0 points for 500 acres or more of protected land within one mile of the boundaries of the parcel) | C27: 0 | D27: 0
A28: Sub-total Points for all National Ranking Factors | C28: =C20+C24+C25+C26 -> 500 | D28: =SUM(D20+D24+D25+D26+D27) -> #DIV/0!
A29: State Ranking Factors
A30: Multifunctional Benefits
A31: 1. Archaeological | C31: 20 | D31: =IF('Parcel Application'!G72 >0, 20, 0) -> 0 | E31: =IF(B7="Jefferson", 0,0) -> 0
A32: 2. Historic | C32: 20 | D32: =IF('Parcel Application'!G69 >0, 20, 0) -> 0 | E32: =IF(B7="Morgan", 0,0) -> 0
A33: Environmental Diversity | E33: =IF(B7="Berkeley", 0,0) -> 0
A34: 1. Endangered and/or threatened species | C34: 20 | D34: =IF('Parcel Application'!G75 >0, 20, 0) -> 0 | E34: =IF(B7="Mineral", 0,0) -> 0
A35: 2. Major Streams and/or Natural Springs | C35: 20 | D35: =IF('Parcel Application'!G79 >0, 20, 0) -> 0 | E35: =IF(B7="Monroe", 0,0) -> 0
A36: 3. Caves and sink-holes | C36: 20 | D36: =IF('Parcel Application'!G82 >0, 20, 0) -> 0 | E36: =IF(B7="Hampshire", 0,0) -> 0
A37: Parcel Factors | E37: =IF(B7="Hardy", 0,0) -> 0
A38: 1. Priority of farm in county ranking (total number of points available for all applications by an entity in annual offering is 100) | C38: 100 | D38: 0 | E38: =IF(B7="Grant", 0,0) -> 0
A39: 2. Chesapeake Bay Area | C39: 0 | D39: =SUM(E31:E39) -> 0 | E39: =IF(B7="Pendleton", 0,0) -> 0
A40: 3. Size relative to average farm size for the county | C40: 25 | D40: =IF(G41 <=0, 0, G41) -> 0
A41: (1 point for each acre greater than average farm size) | F41: ='Parcel Application'!G36-'Ranking Factors'!H122 -> 0 | G41: =IF(F41 >25, 25, F41) -> 0
A42: 4. Total farm offered for easement | C42: 25 | D42: =IF('Parcel Application'!G37 ='Parcel Application'!G36, 25, 0) -> 25
...

Sheet Appraiser and Surveyor Info
A1: Farm and Ranch Land Protection Program (FRPP)
A2: Appraiser and Surveyor Summary Information
A3: 1 | B3: Entity or Entities Associated with the Parcel: | G3: ='Parcel Application'!G11:K11 -> 0
G4: ='Parcel Application'!G12:K12 -> 0
G5: ='Parcel Application'!G13:K13 -> 0
A6: 2 | B6: Name(s) of the landowners of the parcel as stated in the deed: (All names on the deed must become Farm Bill Eligible) | G6: ='Parcel Application'!G14:K14 -> 0
G7: ='Start Here'!C35 -> 0
G8: ='Start Here'!C36 -> 0
A9: 3 | B9: If a partnership or corporation, names of all partners or shareholders. Power of attorney or authorized agent if needed. (please attach) | G9: ='Parcel Application'!G17:K17 -> 0
G10: ='Parcel Application'!G18:K18 -> 0
G11: ='Parcel Application'!G19:K19 -> 0
A12: 4 | B12: Physical Address of the parcel: (required for Phase I) | G12: Mailing Address of landowner(s):
B13: ='Start Here'!C42 -> 0 | G13: ='Start Here'!C40 -> 0
B14: ='Start Here'!C43 -> 0 | G14: ='Start Here'!C41 -> 0
A15: 5 | B15: Legal Description of the parcel. (Attach copy of deed, deeds or will) | G15: Deed Book(s) | I15: ='Parcel Application'!I23:K23 -> 0
G16: Page Number(s) | I16: ='Parcel Application'!I24:K24 -> 0
G17: Tax Map | I17: ='Parcel Application'!I25:K25 -> 0
G18: Parcel Number | I18: ='Parcel Application'!I26:K26 -> 0
A19: 6 | B19: Size of the parcel in acres offered for easement. | I19: Notes
C20: Easement (Including Exhibit B & D) | G20: ='Parcel Application'!G28 -> 0 | H20: Acres
C21: Residential Dwelling (Exhibit B) | G21: ='Parcel Application'!G29 -> 0 | H21: Acres | I21: 2 ac max per & subject to easement
C22: Retained Development (Exhibit D) | G22: ='Parcel Application'!G30 -> 0 | H22: Acres | I22: 2 ac max per & subject to easement
C23: Locally Funded Only Area | G23: ='Parcel Application'!G31 -> 0 | H23: Acres | I23: Not funded by NRCS contribution
C24: Donated Area | G24: ='Parcel Application'!G33 -> 0 | H24: Acres | I24: Not funded by NRCS contribution
C25: Exception Area | G25: ='Parcel Application'!G34 -> 0 | H25: Acres | I25: Will be subdivided prior to closing - not funded.
C26: Area offered to NRCS | G26: =G20 -> 0 | H26: Acres | I26: NRCS Easement
C27: Total Area of Easement | G27: =SUM(G20+G24) -> 0 | H27: Acres
C28: Total Farm Size | G28: =SUM(G20+G23+G24+G25) -> 0 | H28: Acres
