Workbook
Name Choose_Year_1____2__Management_Practice_Reenroll: existCP29!$W$21:$X$25
Name CRAS______1st_2nd_Year_MANAGEMENT_BURNING: existCP29!$W$21:$X$25

Sheet Instructions
A1: Instructions for CRP Plan Sheet Usage
A3: 1. Go to the tab named 'Signature Page'
A4: 2. Enter Contract Name, County, Contract Number and Total Acres
A5: This will transfer these items to all worksheet pages.
A6: 3. Go to the appropriate worksheet page for the planned practice
A7: 4. Enter the Tract number and acres of the practice for each component.
A8: NOTE: Some components do not have a cost shown on the worksheet I.E. Lime and Fertilizer per Soil Test.
A9: You will need to enter the cost for these items in the Component List tab.
A10: 5. Do this for each practice on the tract.
A11: 6. The spreadsheet will automatically total the cost-sharing for each practice and the total cost-share for the contract.
A13: Note: If hardwood trees are being planted over more than one year, the cost share entries and year will need to be typed in
A14: order for them to be correct.
... A32: Switching to a different mid-management practice

Sheet CRPSignature Page
A3: 1. To be completed by NRCS; check appropriate box: | D3: This transaction is for CCC. | H3: This transaction is for NRCS. | O3: OMB No. 0578-0013
A4: U.S. DEPARTMENT OF AGRICULTURE | F4: CONSERVATION PLAN | N4: 2. | O4: Page | Q4: of
F5: SCHEDULE OF OPERATIONS
A6: The above statements are made in accordance with the Privacy Act of 1974 (5 U.S.C. 522a). Furnishing this information is voluntary; however, failure to furnish correct, complete information will result in the withholding or withdrawal of such technical or financial assistance. The information may be furnished to other USDA agencies, the Internal Revenue Service, the Department of Justice, or other State or Federal law enforcement agencies, or in response to orders of a court, magistrate, or administrative tribunal.
A7: 3. NAME | D7: 4. COUNTY | G7: 5. STATE | H7: 6. CONTRACT OR | N7: 7. TOTAL ACRES UNDER
G8: WI | H8: AGREEMENT NO. | N8: CONTRACT
H9: COMPLETION SCHEDULE AND ESTIMATED
A10: ITEM | B10: FIELD | C10: PLANNED CONSERVATION | E10: ESTIMATED | F10: COST | G10: COST SHARE | H10: COST-SHARE OR PAYMENT BY YEAR
A11: NO. | C11: TREATMENT | E11: AMOUNT | F11: BASIS | G11: OR PAYMENT | H11: (For Non-Cost Share Items Show Units)
C12: (Record of Decisions) | E12: (UNITS) | F12: $ | G12: RATE
G13: % | H13: 14 | I13: 15 | J13: 16 | K13: 17 | L13: 18 | M13: 19 | N13: 20 | O13: 21 | P13: 22 | Q13: 23 | R13: REF. NO.
H14: Year | I14: Year | J14: Year | K14: Year | L14: Year | M14: Year | N14: Year | O14: Year | P14: Year | Q14: Year
H15: 2014 | I15: 2015 | J15: 2016 | K15: 2019 | L15: 2020 | M15: 2022 | N15: 2024 | O15: 2026
A16: 8 | B16: 9 | C16: 10 | E16: 11 | F16: 12 | G16: 13 | H16: 24 | I16: 25 | J16: 26 | K16: 27 | L16: 28 | M16: 29 | N16: 30 | O16: 31 | P16: 32 | Q16: 33 | R16: 34
C17: A. Total Cost-Share or Payment by Year: | H17: =existCP1!H22+existCP2!H22+existCP3!H30+existCP3A!H22+existCP21!H22+'existCP23&23ABuffer'!H22+existCP25P!H22+existCP28!H22+existCP29!H22+existCP42!H22+'CP1'!H32+'CP2'!H29+'CP3'!H40+CP3A!H39+CP4B!H34+CP4D!H34+CP5A!H25+CP8A!H18+'CP9'!H25+'CP42'!H29+CP15A!H24+CP15B!H25+CP16A!H25+CP17A!H23+'CP21'!H39+'CP22'!H42+'CP23&23A'!H25+'CP23&23ABuffer'!H30+'CP25 Prairie'!H29+'CP25 Savanna'!H31+'CP27'!H26+'CP28'!H30+'CP29'!H37+'CP30'!H45+'CP31'!H36+'CP33'!H33 -> 0 | I17: =existCP1!I22+existCP2!I22+existCP21!I22+'existCP23&23ABuffer'!I22+existCP25P!I22+existCP28!I22+existCP29!I22+existCP42!I22+'CP1'!I32+'CP2'!I29+'CP3'!I40+CP3A!I39+'CP3A year 2'!I34+CP4B!I34+CP4D!I34+CP5A!I25+CP8A!I18+'CP42'!I29+CP15A!I24+CP15B!I25+CP16A!I25+CP17A!I23+'CP21'!I39+'CP22'!I42+'CP23&23A'!I25+'CP23&23ABuffer'!I30+'CP25 Prairie'!I29+'CP25 Savanna'!I31+'CP27'!I26+'CP28'!I30+'CP29'!I37+'CP30'!I45+'CP31'!I36 -> 0 | J17: ='CP3A year 3'!J34+'CP33'!I33 -> 0 | K17: =existCP1!J22+existCP2!J22+existCP21!J22+'existCP23&23ABuffer'!J22+existCP25P!J22+existCP28!J22+existCP29!J22+existCP42!J22+'CP1'!J32+'CP2'!J29+'CP3'!J40+CP3A!J39+'CP3A year 2'!J34+CP4B!J34+CP4D!J34+CP5A!J25+CP8A!J18+'CP42'!J29+CP15A!J24+CP15B!J25+CP16A!J25+CP17A!J23+'CP21'!J39+'CP22'!J42+'CP23&23A'!J25+'CP23&23ABuffer'!J30+'CP25 Prairie'!J29+'CP25 Savanna'!J31+'CP27'!J26+'CP28'!J30+'CP29'!J37+'CP30'!J45+'CP31'!J36+'CP33'!J33 -> 0 | L17: =existCP1!K22+existCP2!K22+existCP21!K22+'existCP23&23ABuffer'!K22+existCP25P!K22+existCP28!K22+existCP29!K22+existCP42!K22+'CP1'!K32+'CP2'!K29+'CP3'!K40+CP3A!K39+'CP3A year 2'!K34+CP4B!K34+CP4D!K34+CP5A!K25+CP8A!K18+'CP42'!K29+CP15A!K24+CP15B!K25+CP16A!K25+CP17A!K23+'CP21'!K39+'CP22'!K42+'CP23&23A'!K25+'CP23&23ABuffer'!K30+'CP25 Prairie'!K29+'CP25 Savanna'!K31+'CP27'!K26+'CP28'!K30+'CP29'!K37+'CP30'!K45+'CP31'!K36 -> 0 | M17: ='CP33'!K33 -> 0 | N17: =existCP1!L22+existCP2!L22+existCP21!L22+'existCP23&23ABuffer'!L22+existCP25P!L22+existCP28!L22+existCP29!L22+existCP42!L22+'CP1'!L32+'CP2'!L29+'CP3'!L40+CP3A!L39+'CP3A year 2'!L34+CP4B!L34+CP4D!L34+CP5A!L25+CP8A!L18+'CP42'!L29+CP15A!L24+CP15B!L25+CP16A!L25+CP17A!L23+'CP21'!L39+'CP22'!L42+'CP23&23A'!L25+'CP23&23ABuffer'!L30+'CP25 Prairie'!L29+'CP25 Savanna'!L31+'CP27'!L26+'CP28'!L30+'CP29'!L37+'CP30'!L45+'CP31'!L36 -> 0 | O17: =existCP1!M22+existCP2!M22+existCP21!M22+'existCP23&23ABuffer'!M22+existCP25P!M22+existCP28!M22+existCP29!M22+existCP42!M22+'CP1'!M32+'CP2'!M29+'CP3'!M40+CP3A!M39+'CP3A year 2'!M34+CP4B!M34+CP4D!M34+CP5A!M25+CP8A!M18+'CP42'!M29+CP15A!M24+CP15B!M25+CP16A!M25+CP17A!M23+'CP21'!M39+'CP22'!M42+'CP23&23A'!M25+'CP23&23ABuffer'!M30+'CP25 Prairie'!M29+'CP25 Savanna'!M31+'CP27'!M26+'CP28'!M30+'CP29'!M37+'CP30'!M45+'CP31'!M36 -> 0
C18: B. Total Contract Payment: | D18: =H17+I17+J17+K17+L17+N17+O17+P17+Q17+M17 -> 0
A20: NOTES: | B20: A. All Items numbered in column 8 on form AD-1155 must be carried out as a part of this contract to prevent violation.
B21: B. When established, the conservation practices listed in Column 8 must be maintained by the participant at no cost to the government
B22: C. Enter total cost per unit in column 12 unless the method of cost-share is flat rate. When flat rate, enter the amount per unit to be paid to the participant
B23: D. All cost share rates in column 13 are based on average cost with the following exceptions:
B24: AA = Actual costs not to exceed average cost
B25: FR = Flat Rate
B26: NC = Non cost-shared.
B27: AM = Actual cost not to exceed a specified maximum
B28: AP = Annual Payment
B29: E. Modifications will be referenced by number in column number 34 on form AD-1155.
B30: F. By signing, the participant acknowledges receipt of this conservation plan including form AD-1155 and agrees to comply with
B31: the terms and conditions hereof.
A32: 35. CERTIFICATION OF PARTICIPANTS
A33: A. SIGNATURE | D33: B. Date | E33: C. SIGNATURE | J33: D. Date | K33: E. SIGNATURE | P33: F. Date
A35: 36. REVIEWING OFFICIALS SIGNATURE
A36: A. District Conservationist - Technical Adequacy Certification | H36: B. Date | I36: C. APPROVED BY (Conservation District Representative) | O36: D. Date
A37: SIGNATURE | I37: SIGNATURE
A39: OMB DISCLOSURE STATEMENT
A40: Federal Agencies may not conduct or sponsor, and a person is not required to respond to a collection of information unless it displays a currently valid OMB control number. Public reporting burden for this collection is estimated to average 37.5 mins. per response, including the time for reviewing instructions, searching existing data sources, gathering and maintaining the data needed, and completing and reviewing the collection of information. Send comments regarding this burden estimate or any other aspect of this collection of information, including suggestions for reducing this burden to Department of Agriculture, OIRM, Stop 7630, Wash. DC
A41: NONDISCRIMINATION STATEMENT
A42: The U.S. Department of Agriculture (USDA) prohibits discrimination in all its programs and activities on the basis of race, color, national origin, gender, religion, age, disability, and where applicable, sex, marital status, familial status, parental status, religion, sexual orientation, genetic information, political beliefs, reprisal or because all or part of an individuals income is derived from any public assistance program.. (Not all prohibited bases apply to all programs). Persons with disabilities who require alternative means for communication of program information (Braille, large print, audiotape, etc.) should contact USDA's TARGET Center at (202) 720-2600 (voice and TDD). To file a complaint of discrimination, write USDA, Director, Office of Civil Rights, 1400 Independence Avenue, SW., Washington D.C. 20250-9410, or call (800) 795-3272 (voice) or (202)720-6382 (TDD).

Sheet existCP1
A1: 1. To be completed by NRCS; check appropriate box: | D1: This transaction is for CCC. | H1: This transaction is for NRCS. | O1: OMB No. 0578-0013
A2: U.S. DEPARTMENT OF AGRICULTURE | F2: CONSERVATION PLAN | N2: 2. | O2: Page | Q2: of
F3: SCHEDULE OF OPERATIONS
A4: 1. NAME | D4: 2. COUNTY | H4: 3. STATE | J4: 4. CONTRACT OR AGREEMENT NO. | M4: 5. TOTAL ACRES UNDER CONTRACT
A5: ='CRPSignature Page'!A8 -> 0 | D5: ='CRPSignature Page'!D8 -> 0 | H5: Wisconsin | J5: ='CRPSignature Page'!I8 -> 0 | M5: ='CRPSignature Page'!P8 -> 0
A7: CRP-CP1: Permanent Introduced Grasses and Legumes. These fields are already established to permanent introduced grasses and legumes. All fields will be maintained as required by Job Sheet 397. CRP rules do not allow disturbance of cover including maintenance or required management during the primary nesting season recorded in the CRP contract (May 15 through August 1). Spot clipping or spot spraying may be done during the primary nesting season with prior approval from the local FSA Service Agency (FSA) County Committee. The CRP cover will not be harvested, and will be protected from grazing by livestock for the duration of the contract. The CP1 cover requires a management practice as specified on the CRP contract. See attached Required Management Job Sheet _____ for details.
A9: ITEM NO. | B9: FIELD | C9: PLANNED CONSERVATION TREATMENT (Record of Decisions) | D9: ESTIMATED AMOUNTS (UNITS) | F9: COST BASIS $ | G9: COST SHARE OR PAYMENT RATE % | H9: COMPLETION SCHEDULE AND ESTIMATED COST SHARE OR PAYMENT BY YEAR | R9: REF. NO.
H10: (For Non-cost-Share Items Show Units)
H11: 14 | I11: 15 | J11: 16 | K11: 17 | L11: 18 | M11: 19 | N11: 20 | O11: 21 | P11: 22 | Q11: 23
H12: Year | I12: Year | J12: Year | K12: Year | L12: Year | M12: Year | N12: Year | O12: Year | P12: Year | Q12: Year
H13: ='CRPSignature Page'!H15 -> 2014 | I13: ='CRPSignature Page'!I15 -> 2015 | J13: ='CRPSignature Page'!K15 -> 2019 | K13: ='CRPSignature Page'!L15 -> 2020 | L13: ='CRPSignature Page'!N15 -> 2024 | M13: ='CRPSignature Page'!O15 -> 2026
A14: 8 | B14: 9 | C14: 10 | D14: 11 | F14: 12 | G14: 13 | H14: 24 | I14: 25 | J14: 26 | K14: 27 | L14: 28 | M14: 29 | N14: 30 | O14: 31 | P14: 32 | Q14: 33 | R14: 34
C15: CRDA NO C/S AUTH. OR COVER ALREADY ESTAB. | E15: AC
C16: Choose Year 1 & (2) Management Practice (Reenroll) | E16: AC | F16: =VLOOKUP(C16,AE18:AF27,2) -> 0 | G16: 50 | H16: =D16*F16*G16/100 -> 0
C17: Choose Year 1 & (2) Management Practice (Reenroll) | E17: AC | F17: =VLOOKUP(C17,AE18:AF27,2) -> 0 | G17: 50 | I17: =D17*F17*G17/100 -> 0 | AE17: Column1 | AF17: Column2
C18: Choose 6th/7th Mid Management Practice | E18: AC | F18: =VLOOKUP(C18,AE28:AF37,2) -> 0 | G18: 50 | J18: =D18*F18*G18/100 -> 0 | AE18: Choose Year 1 & (2) Management Practice (Reenroll)
C19: Choose 6th/7th Mid Management Practice | E19: AC | F19: =VLOOKUP(C19,AE28:AF37,2) -> 0 | G19: 50 | K19: =D19*F19*G19/100 -> 0 | AE19: CRAQ 1st/2nd Year MANAGEMENT DISKING COOL MIX | AF19: ='Component List'!D17 -> 25.98
C20: Choose 11th/12th Year Management Practice | E20: AC | F20: =VLOOKUP(C20,AE40:AF49,2) -> 0 | G20: 50 | L20: =D20*F20*G20/100 -> 0 | AE20: CRAR 1st/2nd Year MANAGEMENT MOWING | AF20: ='Component List'!D18 -> 31.04
C21: Choose 11th/12th Year Management Practice | E21: AC | F21: =VLOOKUP(C21,AE40:AF49,2) -> 0 | G21: 50 | M21: =D21*F21*G21/100 -> 0 | AE21: CRAS *1st/2nd Year MANAGEMENT BURNING | AF21: ='Component List'!D19 -> 100
A22: Totals: | H22: =SUM(H15:H21) -> 0 | I22: =SUM(I15:I21) -> 0 | J22: =SUM(J15:J21) -> 0 | K22: =SUM(K15:K21) -> 0 | L22: =SUM(L15:L21) -> 0 | M22: =SUM(M15:M21) -> 0 | AE22: CRAV 1st/2nd Year MANAGEMENT HERBICIDE | AF22: ='Component List'!D22 -> 23.04
A23: =IF(AE52,AE54,"") | AE23: CRAW 1st/2nd Year DISK/INTERSEED COOL | AF23: ='Component List'!D23 -> 100
A24: OMB DISCLOSURE STATEMENT | AE24: CRAX 1st/2nd Year DISK/INTERSEED WARM | AF24: ='Component List'!D24 -> 100
A25: Federal Agencies may not conduct or sponsor, and a person is not required to respond to a collection of information unless it displays a currently valid OMB control number. Public reporting burden for this collection is estimated to average 37.5 mins. per response, including the time for reviewing instructions, searching existing data sources, gathering and maintaining the data needed, and completing and reviewing the collection of information. Send comments regarding this burden estimate or any other aspect of this collection of information, including suggestions for reducing this burden to Department of Agriculture, OIRM, Stop 7630, Wash. DC | AE25: CRAY *1st/2nd Year BURNING/INTERSEED COOL | AF25: ='Component List'!D25 -> 100
A26: PRIVACY ACT STATEMENT | AE26: CRAZ *1st/2nd Year BURN/INTERSEED WARM | AF26: ='Component List'!D26 -> 100
A27: The above statements are made in accordance with the Privacy Act of 1974 (5 U.S.C. 522a). Furnishing this information is voluntary; however, failure to furnish correct, complete information will result in the withholding or withdrawal of such technical or financial assistance. The information may be furnished to other USDA agencies, the Internal Revenue Service, the Department of Justice, or other State or Federal law enforcement agencies, or in response to orders of a court, magistrate, or administrative tribunal. | AE27: CRDG 1st/2nd Year HERBICIDE/INTERSEED COOL MIX | AF27: ='Component List'!D59 -> 100
A28: NONDISCRIMINATION STATEMENT | AE28: Choose 6th/7th Mid Management Practice | AF28: 0
A29: The U.S. Department of Agriculture (USDA) prohibits discrimination in all its programs and activities on the basis of race, color, national origin, gender, religion, age, disability, and where applicable, sex, marital status, familial status, parental status, religion, sexual orientation, genetic information, political beliefs, reprisal or because all or part of an individuals income is derived from any public assistance program.. (Not all prohibited bases apply to all programs). Persons with disabilities who require alternative means for communication of program information (Braille, large print, audiotape, etc.) should contact USDA's TARGET Center at (202) 720-2600 (voice and TDD). To file a complaint of discrimination, write USDA, Director, Office of Civil Rights, 1400 Independence Avenue, SW., Washington D.C. 20250-9410, or call (800) 795-3272 (voice) or (202)720-6382 (TDD). | AE29: CRAQ 6th/7th Year MANAGEMENT LIGHT DISKING | AF29: ='Component List'!D17 -> 25.98
AE30: CRAR 6th/7th Year MANAGEMENT MOWING | AF30: ='Component List'!D18 -> 31.04
AE31: CRAS *6th/7th Year MANAGEMENT BURNING | AF31: ='Component List'!D19 -> 100
AE32: CRAV 6th/7th Year MANAGEMENT HERBICIDE | AF32: ='Component List'!D22 -> 23.04
AE33: CRAW 6th/7th Year MGMT DISK/INTERSEED COOL | AF33: ='Component List'!D23 -> 100
AE34: CRAX 6th/7th Year MGMT DISK/INTERSEED WARM | AF34: ='Component List'!D24 -> 100
AE35: CRAY *6th/7th Year BURN/INTERSEED COOL | AF35: ='Component List'!D25 -> 100
AE36: CRAZ *6th/7th Year BURN/INTERSEED WARM | AF36: ='Component List'!D26 -> 100
AE37: CRDG 6th/7th Year HERBICIDE/INTERSEED (Cool Mix) | AF37: ='Component List'!D59 -> 100
AE40: Choose 11th/12th Year Management Practice | AF40: 0
AE41: CRAQ 11th/12th Year MANAGEMENT LIGHT DISKING | AF41: ='Component List'!D17 -> 25.98
AE42: CRAR 11th/12th Year MANAGEMENT MOWING | AF42: ='Component List'!D18 -> 31.04
AE43: CRAS *11th/12th Year MANAGEMENT BURNING | AF43: ='Component List'!D19 -> 100
AE44: CRAV 11th/12th Year MANAGEMENT HERBICIDE | AF44: ='Component List'!D22 -> 23.04
...

Sheet CP1
A1: 1. To be completed by NRCS; check appropriate box: | D1: This transaction is for CCC. | H1: This transaction is for NRCS. | O1: OMB No. 0578-0013
A2: U.S. DEPARTMENT OF AGRICULTURE | F2: CONSERVATION PLAN | N2: 2. | O2: Page | Q2: of
F3: SCHEDULE OF OPERATIONS
A4: 1. NAME | D4: 2. COUNTY | H4: 3. STATE | J4: 4. CONTRACT OR AGREEMENT NO. | M4: 5. TOTAL ACRES UNDER CONTRACT
A5: ='CRPSignature Page'!A8 -> 0 | D5: ='CRPSignature Page'!D8 -> 0 | H5: Wisconsin | J5: ='CRPSignature Page'!I8 -> 0 | M5: ='CRPSignature Page'!P8 -> 0
A7: CRP-CP1: Permanent Introduced Grasses and Legumes. These fields will be seeded to permanent introduced grasses or permanent introduced grasses and legumes according to Wisconsin Job Sheet 134. To establish the seeding, control weeds and brush as needed by spraying, burning, or mowing until the seeding is certified as established (may require up to 3 years of intensive management). Once the seeding is established, these fields will be maintained as required by Job Sheet 397. CRP rules do not allow disturbance of cover including maintenance or required management during the primary nesting season recorded in the CRP contract (May 15 through August 1). Spot clipping or spot spraying may be done during the primary nesting season with prior approval from the local FSA Service Agency (FSA) County Committee. The CRP cover will not be harvested, and will be protected from grazing by livestock for the duration of the contract. The CP1 cover requires a management practice as specified on the CRP contract. See attached Required Management Job Sheet _____ for details.
A9: ITEM NO. | B9: FIELD | C9: PLANNED CONSERVATION TREATMENT (Record of Decisions) | D9: ESTIMATED AMOUNTS (UNITS) | F9: COST BASIS $ | G9: COST SHARE OR PAYMENT RATE % | H9: COMPLETION SCHEDULE AND ESTIMATED COST SHARE OR PAYMENT BY YEAR | R9: REF. NO.
H10: (For Non-cost-Share Items Show Units)
H11: 14 | I11: 15 | J11: 16 | K11: 17 | L11: 18 | M11: 19 | N11: 20 | O11: 21 | P11: 22 | Q11: 23
H12: Year | I12: Year | J12: Year | K12: Year | L12: Year | M12: Year | N12: Year | O12: Year | P12: Year | Q12: Year
H13: ='CRPSignature Page'!H15 -> 2014 | I13: ='CRPSignature Page'!I15 -> 2015 | J13: ='CRPSignature Page'!K15 -> 2019 | K13: ='CRPSignature Page'!L15 -> 2020 | L13: ='CRPSignature Page'!N15 -> 2024 | M13: ='CRPSignature Page'!O15 -> 2026
A14: 8 | B14: 9 | C14: 10 | D14: 11 | F14: 12 | G14: 13 | H14: 24 | I14: 25 | J14: 26 | K14: 27 | L14: 28 | M14: 29 | N14: 30 | O14: 31 | P14: 32 | Q14: 33 | R14: 34
C15: CRAA LABORATORY SOIL ANALYSIS FEE | E15: AC | F15: ='Component List'!D2 -> 1.64 | G15: 50 | H15: =D15*F15*G15/100 -> 0
C16: CRAB LIME & FERTILIZER PER SOIL TEST | E16: AC | F16: ='Component List'!D3 -> 0 | G16: 50 | H16: =D16*F16*G16/100 -> 0
C17: CRAC SEEDBED PREPARATION | E17: AC | F17: ='Component List'!D4 -> 80.06 | G17: 50 | H17: =D17*F17*G17/100 -> 0
C18: CRAD SEEDING OPERATION >3ACRES | E18: AC | F18: ='Component List'!D5 -> 62.6 | G18: 50 | H18: =D18*F18*G18/100 -> 0
C19: CRAE CP1 SEED (SEE JOB SHEET 134) | E19: AC | F19: ='Component List'!D6 -> 52.88 | G19: 50 | H19: =D19*F19*G19/100 -> 0
C20: CRAM COMPANION CROP | E20: AC | F20: ='Component List'!D14 -> 16.08 | G20: 50 | H20: =D20*F20*G20/100 -> 0
C21: CRAO SEEDING RATE SMALL ACREAGE <3 ACRES | E21: AC | F21: ='Component List'!D16 -> 84.42 | G21: 50 | H21: =D21*F21*G21/100 -> 0
C22: CRBA TEMPORARY SEEDING | E22: AC | F22: ='Component List'!D28 -> 94.14 | G22: 50 | H22: =D22*F22*G22/100 -> 0
C23: CRAN WEED/INSECT CONTROL - GRASS | E23: AC | F23: ='Component List'!D15 -> 21.78 | G23: 50 | H23: =D23*F23*G23/100 -> 0
C24: CRBI SEEDING FIREBREAKS | E24: AC | F24: ='Component List'!D36 -> 75.36 | G24: 50 | H24: =D24*F24*G24/100 -> 0
AE27: Column1 | AF27: Column2
C28: Choose 6th/7th Mid Management Practice | E28: AC | F28: =VLOOKUP(C28,AE38:AF47,2) -> 0 | G28: 50 | J28: =D28*F28*G28/100 -> 0
C29: Choose 6th/7th Mid Management Practice | E29: AC | F29: =VLOOKUP(C29,AE38:AF47,2) -> 0 | G29: 50 | K29: =D29*F29*G29/100 -> 0
C30: Choose 11th/12th Year Management Practice | E30: AC | F30: =VLOOKUP(C30,AE50:AF59,2) -> 0 | G30: 50 | L30: =D30*F30*G30/100 -> 0
C31: Choose 11th/12th Year Management Practice | E31: AC | F31: =VLOOKUP(C31,AE50:AF59,2) -> 0 | G31: 50 | M31: =D31*F31*G31/100 -> 0
A32: Totals: | H32: =SUM(H15:H31) -> 0 | I32: =SUM(I15:I31) -> 0 | J32: =SUM(J15:J31) -> 0 | K32: =SUM(K15:K31) -> 0 | L32: =SUM(L15:L31) -> 0 | M32: =SUM(M15:M31) -> 0
A33: =IF(AE62,AE64,"")
A34: OMB DISCLOSURE STATEMENT
A35: Federal Agencies may not conduct or sponsor, and a person is not required to respond to a collection of information unless it displays a currently valid OMB control number. Public reporting burden for this collection is estimated to average 37.5 mins. per response, including the time for reviewing instructions, searching existing data sources, gathering and maintaining the data needed, and completing and reviewing the collection of information. Send comments regarding this burden estimate or any other aspect of this collection of information, including suggestions for reducing this burden to Department of Agriculture, OIRM, Stop 7630, Wash. DC
A36: PRIVACY ACT STATEMENT
A37: The above statements are made in accordance with the Privacy Act of 1974 (5 U.S.C. 522a). Furnishing this information is voluntary; however, failure to furnish correct, complete information will result in the withholding or withdrawal of such technical or financial assistance. The information may be furnished to other USDA agencies, the Internal Revenue Service, the Department of Justice, or other State or Federal law enforcement agencies, or in response to orders of a court, magistrate, or administrative tribunal.
A38: NONDISCRIMINATION STATEMENT | AE38: Choose 6th/7th Mid Management Practice | AF38: 0
A39: The U.S. Department of Agriculture (USDA) prohibits discrimination in all its programs and activities on the basis of race, color, national origin, gender, religion, age, disability, and where applicable, sex, marital status, familial status, parental status, religion, sexual orientation, genetic information, political beliefs, reprisal or because all or part of an individuals income is derived from any public assistance program.. (Not all prohibited bases apply to all programs). Persons with disabilities who require alternative means for communication of program information (Braille, large print, audiotape, etc.) should contact USDA's TARGET Center at (202) 720-2600 (voice and TDD). To file a complaint of discrimination, write USDA, Director, Office of Civil Rights, 1400 Independence Avenue, SW., Washington D.C. 20250-9410, or call (800) 795-3272 (voice) or (202)720-6382 (TDD). | AE39: CRAQ 6th/7th Year MANAGEMENT LIGHT DISKING | AF39: ='Component List'!D17 -> 25.98
AE40: CRAR 6th/7th Year MANAGEMENT MOWING | AF40: ='Component List'!D18 -> 31.04
AE41: CRAS *6th/7th Year MANAGEMENT BURNING | AF41: ='Component List'!D19 -> 100
AE42: CRAV 6th/7th Year MANAGEMENT HERBICIDE | AF42: ='Component List'!D22 -> 23.04
AE43: CRAW 6th/7th Year MGMT DISK/INTERSEED COOL | AF43: ='Component List'!D23 -> 100
AE44: CRAX 6th/7th Year MGMT DISK/INTERSEED WARM | AF44: ='Component List'!D24 -> 100
...

Sheet existCP2
A1: 1. To be completed by NRCS; check appropriate box: | D1: This transaction is for CCC. | H1: This transaction is for NRCS. | O1: OMB No. 0578-0013
A2: U.S. DEPARTMENT OF AGRICULTURE | F2: CONSERVATION PLAN | N2: 2. | O2: Page | Q2: of
F3: SCHEDULE OF OPERATIONS
A4: 1. NAME | D4: 2. COUNTY | H4: 3. STATE | J4: 4. CONTRACT OR AGREEMENT NO. | M4: 5. TOTAL ACRES UNDER CONTRACT
A5: ='CRPSignature Page'!A8 -> 0 | D5: ='CRPSignature Page'!D8 -> 0 | H5: Wisconsin | J5: ='CRPSignature Page'!I8 -> 0 | M5: ='CRPSignature Page'!P8 -> 0
A7: CRP-CP2: Establishment of Permanent Native Grasses. These fields are already established to permanent warm season grasses or warm season grasses and forbs. These fields will be maintained as required by Job Sheet 397. CRP rules do not allow disturbance of cover including maintenance or required management during the primary nesting season recorded in the CRP contract (May 15 through August 1). Spot clipping or spot spraying may be done during the primary nesting season with prior approval from the local FSA Service Agency (FSA) County Committee. The CRP cover will not be harvested, and will be protected from grazing by livestock for the duration of the contract. The CP2 cover requires a management practice as specified on the CRP contract. See attached Required Management Job Sheet _____ for details.
A9: ITEM NO. | B9: FIELD | C9: PLANNED CONSERVATION TREATMENT (Record of Decisions) | D9: ESTIMATED AMOUNTS (UNITS) | F9: COST BASIS $ | G9: COST SHARE OR PAYMENT RATE % | H9: COMPLETION SCHEDULE AND ESTIMATED COST SHARE OR PAYMENT BY YEAR | R9: REF. NO.
H10: (For Non-cost-Share Items Show Units)
H11: 14 | I11: 15 | J11: 16 | K11: 17 | L11: 18 | M11: 19 | N11: 20 | O11: 21 | P11: 22 | Q11: 23
H12: Year | I12: Year | J12: Year | K12: Year | L12: Year | M12: Year | N12: Year | O12: Year | P12: Year | Q12: Year
H13: ='CRPSignature Page'!H15 -> 2014 | I13: ='CRPSignature Page'!I15 -> 2015 | J13: ='CRPSignature Page'!K15 -> 2019 | K13: ='CRPSignature Page'!L15 -> 2020 | L13: ='CRPSignature Page'!N15 -> 2024 | M13: ='CRPSignature Page'!O15 -> 2026
A14: 8 | B14: 9 | C14: 10 | D14: 11 | F14: 12 | G14: 13 | H14: 24 | I14: 25 | J14: 26 | K14: 27 | L14: 28 | M14: 29 | N14: 30 | O14: 31 | P14: 32 | Q14: 33 | R14: 34
C15: CRDA NO C/S AUTH. OR COVER ALREADY ESTAB. | E15: AC
C16: Choose Year 1 & (2) Management Practice Reenroll | E16: AC | F16: =VLOOKUP(C16,AA29:AB33,2) -> 0 | G16: 50 | H16: =D16*F16*G16/100 -> 0
C17: Choose Year 1 & (2) Management Practice Reenroll | E17: AC | F17: =VLOOKUP(C17,AA29:AB33,2) -> 0 | G17: 50 | I17: =D17*F17*G17/100 -> 0
C18: Choose 6th/7th Mid Management Practice | E18: AC | F18: =VLOOKUP(C18,AA37:AB41,2,TRUE) -> 0 | G18: 50 | J18: =D18*F18*G18/100 -> 0
C19: Choose 6th/7th Mid Management Practice | E19: AC | F19: =VLOOKUP(C19,AA37:AB41,2,TRUE) -> 0 | G19: 50 | K19: =D19*F19*G19/100 -> 0
C20: Choose 11th/12thYear Management Practice | E20: AC | F20: =VLOOKUP(C20,AA44:AB48,2,TRUE) -> 0 | G20: 50 | L20: =D20*F20*G20/100 -> 0
C21: Choose 11th/12thYear Management Practice | E21: AC | F21: =VLOOKUP(C21,AA44:AB48,2,TRUE) -> 0 | G21: 50 | M21: =D21*F21*G21/100 -> 0
A22: Totals: | H22: =SUM(H15:H21) -> 0 | I22: =SUM(I15:I21) -> 0 | J22: =SUM(J15:J21) -> 0 | K22: =SUM(K15:K21) -> 0 | L22: =SUM(L15:L21) -> 0 | M22: =SUM(M15:M21) -> 0
A23: =IF(AA50,AA52,"")
A24: OMB DISCLOSURE STATEMENT
A25: Federal Agencies may not conduct or sponsor, and a person is not required to respond to a collection of information unless it displays a currently valid OMB control number. Public reporting burden for this collection is estimated to average 37.5 mins. per response, including the time for reviewing instructions, searching existing data sources, gathering and maintaining the data needed, and completing and reviewing the collection of information. Send comments regarding this burden estimate or any other aspect of this collection of information, including suggestions for reducing this burden to Department of Agriculture, OIRM, Stop 7630, Wash. DC
A26: PRIVACY ACT STATEMENT
A27: The above statements are made in accordance with the Privacy Act of 1974 (5 U.S.C. 522a). Furnishing this information is voluntary; however, failure to furnish correct, complete information will result in the withholding or withdrawal of such technical or financial assistance. The information may be furnished to other USDA agencies, the Internal Revenue Service, the Department of Justice, or other State or Federal law enforcement agencies, or in response to orders of a court, magistrate, or administrative tribunal.
A28: NONDISCRIMINATION STATEMENT
A29: The U.S. Department of Agriculture (USDA) prohibits discrimination in all its programs and activities on the basis of race, color, national origin, gender, religion, age, disability, and where applicable, sex, marital status, familial status, parental status, religion, sexual orientation, genetic information, political beliefs, reprisal or because all or part of an individuals income is derived from any public assistance program.. (Not all prohibited bases apply to all programs). Persons with disabilities who require alternative means for communication of program information (Braille, large print, audiotape, etc.) should contact USDA's TARGET Center at (202) 720-2600 (voice and TDD). To file a complaint of discrimination, write USDA, Director, Office of Civil Rights, 1400 Independence Avenue, SW., Washington D.C. 20250-9410, or call (800) 795-3272 (voice) or (202)720-6382 (TDD). | AA29: Choose Year 1 & (2) Management Practice Reenroll | AB29: 0
AA30: CRAR 1st/2nd Year MANAGEMENT MOWING | AB30: ='Component List'!D18 -> 31.04
AA31: CRAS *1st/2nd Year MANAGEMENT BURNING | AB31: ='Component List'!D19 -> 100
AA32: CRAV 1st/2nd Year MANAGEMENT HERBICIDE | AB32: ='Component List'!D22 -> 23.04
AA33: CRAZ *1st/2nd Year BURN/INTERSEED WARM | AB33: ='Component List'!D26 -> 100
AA37: Choose 6th/7th Mid Management Practice | AB37: 0
AA38: CRAR 6th/7th Year MANAGEMENT MOWING | AB38: ='Component List'!D18 -> 31.04
AA39: CRAS *6th/7th Year MANAGEMENT BURNING | AB39: ='Component List'!D19 -> 100
AA40: CRAV 6th/7th Year MANAGEMENT HERBICIDE | AB40: ='Component List'!D22 -> 23.04
AA41: CRAZ *6th/7th Year BURN/INTERSEED WARM | AB41: ='Component List'!D26 -> 100
AA44: Choose 11th/12thYear Management Practice | AB44: 0
AA45: CRAR 11th/12th Year MANAGEMENT MOWING | AB45: ='Component List'!D18 -> 31.04
AA46: CRAS *11th/12th Year MANAGEMENT BURNING | AB46: ='Component List'!D19 -> 100
AA47: CRAV 11th/12th Year MANAGEMENT HERBICIDE | AB47: ='Component List'!D22 -> 23.04
...

Sheet CP2
A1: 1. To be completed by NRCS; check appropriate box: | D1: This transaction is for CCC. | H1: This transaction is for NRCS. | O1: OMB No. 0578-0013
A2: U.S. DEPARTMENT OF AGRICULTURE | F2: CONSERVATION PLAN | N2: 2. | O2: Page | Q2: of
F3: SCHEDULE OF OPERATIONS
A4: 1. NAME | D4: 2. COUNTY | H4: 3. STATE | J4: 4. CONTRACT OR AGREEMENT NO. | M4: 5. TOTAL ACRES UNDER CONTRACT
A5: ='CRPSignature Page'!A8 -> 0 | D5: ='CRPSignature Page'!D8 -> 0 | H5: Wisconsin | J5: ='CRPSignature Page'!I8 -> 0 | M5: ='CRPSignature Page'!P8 -> 0
A7: CRP-CP2: Establishment of Permanent Native Grasses. These fields will be seeded to permanent warm season grasses or warm season grasses and forbs according to Wisconsin Job Sheet 135. To establish the seeding, control weeds and brush as needed by spraying, burning, or mowing until the seeding is certified as established (may require up to 3 years of intensive management). Once the seeding is established, these fields will be maintained as required by Job Sheet 397. CRP rules do not allow disturbance of cover including maintenance or required management during the primary nesting season recorded in the CRP contract (May 15 through August 1). Spot clipping or spot spraying may be done during the primary nesting season with prior approval from the local FSA Service Agency (FSA) County Committee. The CRP cover will not be harvested, and will be protected from grazing by livestock for the duration of the contract. The CP2 cover requires a management practice as specified on the CRP contract. See attached Required Management Job Sheet _____ for details.
A9: ITEM NO. | B9: FIELD | C9: PLANNED CONSERVATION TREATMENT (Record of Decisions) | D9: ESTIMATED AMOUNTS (UNITS) | F9: COST BASIS $ | G9: COST SHARE OR PAYMENT RATE % | H9: COMPLETION SCHEDULE AND ESTIMATED COST SHARE OR PAYMENT BY YEAR | R9: REF. NO.
H10: (For Non-cost-Share Items Show Units)
H11: 14 | I11: 15 | J11: 16 | K11: 17 | L11: 18 | M11: 19 | N11: 20 | O11: 21 | P11: 22 | Q11: 23
H12: Year | I12: Year | J12: Year | K12: Year | L12: Year | M12: Year | N12: Year | O12: Year | P12: Year | Q12: Year
H13: ='CRPSignature Page'!H15 -> 2014 | I13: ='CRPSignature Page'!I15 -> 2015 | J13: ='CRPSignature Page'!K15 -> 2019 | K13: ='CRPSignature Page'!L15 -> 2020 | L13: ='CRPSignature Page'!N15 -> 2024 | M13: ='CRPSignature Page'!O15 -> 2026
A14: 8 | B14: 9 | C14: 10 | D14: 11 | F14: 12 | G14: 13 | H14: 24 | I14: 25 | J14: 26 | K14: 27 | L14: 28 | M14: 29 | N14: 30 | O14: 31 | P14: 32 | Q14: 33 | R14: 34
C15: CRAA LABORATORY SOIL ANALYSIS FEE | E15: AC | F15: ='Component List'!D2 -> 1.64 | G15: 50 | H15: =D15*F15*G15/100 -> 0
C16: CRAB LIME & FERTILIZER PER SOIL TEST | E16: AC | F16: ='Component List'!D3 -> 0 | G16: 50 | H16: =D16*F16*G16/100 -> 0
C17: CRAC SEEDBED PREPARATION | E17: AC | F17: ='Component List'!D4 -> 80.06 | G17: 50 | H17: =D17*F17*G17/100 -> 0
C18: CRAD SEEDING OPERATION >3 ACRES | E18: AC | F18: ='Component List'!D5 -> 62.6 | G18: 50 | H18: =D18*F18*G18/100 -> 0
C19: CRAF CP2 SEED (SEE JOB SHEET 135) | E19: AC | F19: ='Component List'!D7 -> 214.1 | G19: 50 | H19: =D19*F19*G19/100 -> 0
C20: CRAO SEEDING RATE SMALL ACREAGE <3 ACRES | E20: AC | F20: ='Component List'!D16 -> 84.42 | G20: 50 | H20: =D20*F20*G20/100 -> 0
C21: CRBA TEMPORARY SEEDING | E21: AC | F21: ='Component List'!D28 -> 94.14 | G21: 50 | H21: =D21*F21*G21/100 -> 0
C22: CRAN WEED/INSECT CONTROL - GRASS | E22: AC | F22: ='Component List'!D15 -> 21.78 | G22: 50 | H22: =D22*F22*G22/100 -> 0
C23: CRBI SEEDING FIREBREAKS | E23: AC | F23: ='Component List'!D36 -> 75.36 | G23: 50 | H23: =D23*F23*G23/100 -> 0
E24: AC
C25: Choose 6th/7th Mid Management Practice | E25: AC | F25: =VLOOKUP(C25,AA44:AB48,2,TRUE) -> 0 | G25: 50 | J25: =D25*F25*G25/100 -> 0
C26: Choose 6th/7th Mid Management Practice | E26: AC | F26: =VLOOKUP(C26,AA44:AB48,2,TRUE) -> 0 | G26: 50 | K26: =D26*F26*G26/100 -> 0
C27: Choose 11th/12thYear Management Practice | E27: AC | F27: =VLOOKUP(C27,AA51:AB55,2,TRUE) -> 0 | G27: 50 | L27: =D27*F27*G27/100 -> 0
C28: Choose 11th/12thYear Management Practice | E28: AC | F28: =VLOOKUP(C28,AA51:AB55,2,TRUE) -> 0 | G28: 50 | M28: =D28*F28*G28/100 -> 0
A29: Totals: | H29: =SUM(H15:H28) -> 0 | I29: =SUM(I15:I28) -> 0 | J29: =SUM(J15:J28) -> 0 | K29: =SUM(K15:K28) -> 0 | L29: =SUM(L15:L28) -> 0 | M29: =SUM(M15:M28) -> 0
A30: =IF(AA57,AA59,"")
A31: OMB DISCLOSURE STATEMENT
A32: Federal Agencies may not conduct or sponsor, and a person is not required to respond to a collection of information unless it displays a currently valid OMB control number. Public reporting burden for this collection is estimated to average 37.5 mins. per response, including the time for reviewing instructions, searching existing data sources, gathering and maintaining the data needed, and completing and reviewing the collection of information. Send comments regarding this burden estimate or any other aspect of this collection of information, including suggestions for reducing this burden to Department of Agriculture, OIRM, Stop 7630, Wash. DC
A33: PRIVACY ACT STATEMENT
A34: The above statements are made in accordance with the Privacy Act of 1974 (5 U.S.C. 522a). Furnishing this information is voluntary; however, failure to furnish correct, complete information will result in the withholding or withdrawal of such technical or financial assistance. The information may be furnished to other USDA agencies, the Internal Revenue Service, the Department of Justice, or other State or Federal law enforcement agencies, or in response to orders of a court, magistrate, or administrative tribunal.
A35: NONDISCRIMINATION STATEMENT
A36: The U.S. Department of Agriculture (USDA) prohibits discrimination in all its programs and activities on the basis of race, color, national origin, gender, religion, age, disability, and where applicable, sex, marital status, familial status, parental status, religion, sexual orientation, genetic information, political beliefs, reprisal or because all or part of an individuals income is derived from any public assistance program.. (Not all prohibited bases apply to all programs). Persons with disabilities who require alternative means for communication of program information (Braille, large print, audiotape, etc.) should contact USDA's TARGET Center at (202) 720-2600 (voice and TDD). To file a complaint of discrimination, write USDA, Director, Office of Civil Rights, 1400 Independence Avenue, SW., Washington D.C. 20250-9410, or call (800) 795-3272 (voice) or (202)720-6382 (TDD). | AA36: Choose Year 1 & (2) Management Practice Reenroll | AB36: 0
AA37: CRAR 1st/2nd Year MANAGEMENT MOWING | AB37: ='Component List'!D18 -> 31.04
AA38: CRAS *1st/2nd Year MANAGEMENT BURNING | AB38: ='Component List'!D19 -> 100
AA39: CRAV 1st/2nd Year MANAGEMENT HERBICIDE | AB39: ='Component List'!D22 -> 23.04
AA40: CRAZ *1st/2nd Year BURN/INTERSEED WARM | AB40: ='Component List'!D26 -> 100
AA44: Choose 6th/7th Mid Management Practice | AB44: 0
AA45: CRAR 6th/7th Year MANAGEMENT MOWING | AB45: ='Component List'!D18 -> 31.04
...

Sheet existCP3
A1: 1. To be completed by NRCS; check appropriate box: | D1: This transaction is for CCC. | H1: This transaction is for NRCS. | O1: OMB No. 0578-0013
A2: U.S. DEPARTMENT OF AGRICULTURE | F2: CONSERVATION PLAN | N2: 2. | O2: Page | Q2: of
F3: SCHEDULE OF OPERATIONS
A4: 1. NAME | D4: 2. COUNTY | H4: 3. STATE | J4: 4. CONTRACT OR AGREEMENT NO. | M4: 5. TOTAL ACRES UNDER CONTRACT
A5: ='CRPSignature Page'!A8 -> 0 | D5: ='CRPSignature Page'!D8 -> 0 | H5: Wisconsin | J5: ='CRPSignature Page'!I8 -> 0 | M5: ='CRPSignature Page'!P8 -> 0
A7: CRP-CP3: Tree Planting (Softwoods). These fields are already established to sofwood trees according to the tree-planting plan prepared by the DNR Forester or NRCS. These fields will not be managed for Christmas trees and will be maintained as required by Job Sheet 397. CRP rules do not allow disturbance of cover including maintenance or required management during the primary nesting season recorded in the CRP contract (May 15 through August 1). Spot clipping or spot spraying may be done during the primary nesting season with prior approval from the local FSA Service Agency (FSA) County Committee. The CRP cover will not be harvested, and will be protected from grazing by livestock for the duration of the contract. Refer to Job Sheet 626 for Woodland Opening Requirements.
A9: ITEM NO. | B9: FIELD | C9: PLANNED CONSERVATION TREATMENT (Record of Decisions) | D9: ESTIMATED AMOUNTS (UNITS) | F9: COST BASIS $ | G9: COST SHARE OR PAYMENT RATE % | H9: COMPLETION SCHEDULE AND ESTIMATED COST SHARE OR PAYMENT BY YEAR | R9: REF. NO.
H10: (For Non-cost-Share Items Show Units)
H11: 14 | I11: 15 | J11: 16 | K11: 17 | L11: 18 | M11: 19 | N11: 20 | O11: 21 | P11: 22 | Q11: 23
H12: Year | I12: Year | J12: Year | K12: Year | L12: Year | M12: Year | N12: Year | O12: Year | P12: Year | Q12: Year
H13: ='CRPSignature Page'!H15 -> 2014 | I13: ='CRPSignature Page'!I15 -> 2015 | J13: ='CRPSignature Page'!K15 -> 2019 | K13: ='CRPSignature Page'!L15 -> 2020 | L13: ='CRPSignature Page'!N15 -> 2024 | M13: ='CRPSignature Page'!O15 -> 2026
A14: 8 | B14: 9 | C14: 10 | D14: 11 | F14: 12 | G14: 13 | H14: 24 | I14: 25 | J14: 26 | K14: 27 | L14: 28 | M14: 29 | N14: 30 | O14: 31 | P14: 32 | Q14: 33 | R14: 34
C15: CRDA NO C/S AUTH. OR COVER ALREADY ESTAB. | E15: AC
C16: CRDH CROP TREE RELEASE - SLASH LEFT | E16: AC | F16: ='Component List'!D60 -> 100 | G16: 50 | H16: =D16*F16*G16/100 -> 0
C17: CRDI THINNING - SLASH LEFT | E17: AC | F17: ='Component List'!D61 -> 450 | G17: 50 | H17: =D17*F17*G17/100 -> 0
C18: CRDJ THINNING - SLASH REMOVED | E18: AC | F18: ='Component List'!D62 -> 500 | G18: 50 | H18: =D18*F18*G18/100 -> 0
C19: CRDK PRUNING UP TO 12 FT | E19: AC | F19: ='Component List'!D63 -> 90 | G19: 50 | H19: =D19*F19*G19/100 -> 0
C20: CRDL PRUNING UP TO 17 FT | E20: AC | F20: ='Component List'!D64 -> 180 | G20: 50 | H20: =D20*F20*G20/100 -> 0
C21: Grass Planting
C22: CRAA LABORATORY SOIL ANALYSIS FEE | E22: AC | F22: ='Component List'!D2 -> 1.64 | G22: 50 | H22: =D22*F22*G22/100 -> 0
C23: CRAB LIME & FERTILIZER PER SOIL TEST | E23: AC | F23: ='Component List'!D3 -> 0 | G23: 50 | H23: =D23*F23*G23/100 -> 0
C24: CRAC SEEDBED PREPARATION | E24: AC | F24: ='Component List'!D4 -> 80.06 | G24: 50 | H24: =D24*F24*G24/100 -> 0
C25: CRAD SEEDING OPERATION>3 AC | E25: AC | F25: ='Component List'!D5 -> 62.6 | G25: 50 | H25: =D25*F25*G25/100 -> 0
C26: CRAE CP1 SEED (SEE JOB SHEET 134) | E26: AC | F26: ='Component List'!D6 -> 52.88 | G26: 50 | H26: =D26*F26*G26/100 -> 0
C27: CRAG CP4D SEED (SEE JOB SHEET 135) | E27: AC | F27: ='Component List'!D8 -> 214.1 | G27: 50 | H27: =D27*F27*G27/100 -> 0
C28: CRAO SEEDING RATE SMALL ACREAGE <3 ACRES | E28: AC | F28: ='Component List'!D16 -> 84.42 | G28: 50 | H28: =D28*F28*G28/100 -> 0
C29: CRBA TEMPORARY SEEDING | E29: AC | F29: ='Component List'!D28 -> 94.14 | G29: 50 | H29: =D29*F29*G29/100 -> 0
A30: Totals: | H30: =SUM(H15:H29) -> 0 | I30: =SUM(I15:I29) -> 0 | J30: =SUM(J15:J29) -> 0 | K30: =SUM(K15:K29) -> 0 | L30: =SUM(L15:L29) -> 0 | M30: =SUM(M15:M29) -> 0
A31: =IF(AE60,AE62,"")
A32: OMB DISCLOSURE STATEMENT
A33: Federal Agencies may not conduct or sponsor, and a person is not required to respond to a collection of information unless it displays a currently valid OMB control number. Public reporting burden for this collection is estimated to average 37.5 mins. per response, including the time for reviewing instructions, searching existing data sources, gathering and maintaining the data needed, and completing and reviewing the collection of information. Send comments regarding this burden estimate or any other aspect of this collection of information, including suggestions for reducing this burden to Department of Agriculture, OIRM, Stop 7630, Wash. DC
A34: PRIVACY ACT STATEMENT
A35: The above statements are made in accordance with the Privacy Act of 1974 (5 U.S.C. 522a). Furnishing this information is voluntary; however, failure to furnish correct, complete information will result in the withholding or withdrawal of such technical or financial assistance. The information may be furnished to other USDA agencies, the Internal Revenue Service, the Department of Justice, or other State or Federal law enforcement agencies, or in response to orders of a court, magistrate, or administrative tribunal.
A36: NONDISCRIMINATION STATEMENT
A37: The U.S. Department of Agriculture (USDA) prohibits discrimination in all its programs and activities on the basis of race, color, national origin, gender, religion, age, disability, and where applicable, sex, marital status, familial status, parental status, religion, sexual orientation, genetic information, political beliefs, reprisal or because all or part of an individuals income is derived from any public assistance program.. (Not all prohibited bases apply to all programs). Persons with disabilities who require alternative means for communication of program information (Braille, large print, audiotape, etc.) should contact USDA's TARGET Center at (202) 720-2600 (voice and TDD). To file a complaint of discrimination, write USDA, Director, Office of Civil Rights, 1400 Independence Avenue, SW., Washington D.C. 20250-9410, or call (800) 795-3272 (voice) or (202)720-6382 (TDD).

Sheet CP3
A1: 1. To be completed by NRCS; check appropriate box: | D1: This transaction is for CCC. | H1: This transaction is for NRCS. | O1: OMB No. 0578-0013
A2: U.S. DEPARTMENT OF AGRICULTURE | F2: CONSERVATION PLAN | N2: 2. | O2: Page | Q2: of
F3: SCHEDULE OF OPERATIONS
A4: 1. NAME | D4: 2. COUNTY | H4: 3. STATE | J4: 4. CONTRACT OR AGREEMENT NO. | M4: 5. TOTAL ACRES UNDER CONTRACT
A5: ='CRPSignature Page'!A8 -> 0 | D5: ='CRPSignature Page'!D8 -> 0 | H5: Wisconsin | J5: ='CRPSignature Page'!I8 -> 0 | M5: ='CRPSignature Page'!P8 -> 0
A7: CRP-CP3: Tree Planting (Softwoods). These fields will be planted to softwood trees according to the tree-planting plan prepared by the DNR Forester or Wisconsin NRCS Job Sheets 623 and 143. The planted acreage will not be managed for Christmas trees. To establish the seeding, control weeds and brush as needed by spraying, burning, or mowing until the seeding is certified as established (may require up to 3 years of intensive management). Once the seeding is established, the entire contract acreage and type of permanent cover will be maintained as required by Job Sheet 397. CRP rules do not allow disturbance of cover including maintenance or required management during the primary nesting season recorded in the CRP contract (May 15 through August 1). Spot clipping or spot spraying may be done during the primary nesting season with prior approval from the local FSA Service Agency (FSA) County Committee. The CRP cover will not be harvested, and will be protected from grazing by livestock for the duration of the contract. Refer to Job Sheet 626 for Woodland Opening Requirements.
A9: ITEM NO. | B9: FIELD | C9: PLANNED CONSERVATION TREATMENT (Record of Decisions) | D9: ESTIMATED AMOUNTS (UNITS) | F9: COST BASIS $ | G9: COST SHARE OR PAYMENT RATE % | H9: COMPLETION SCHEDULE AND ESTIMATED COST SHARE OR PAYMENT BY YEAR | R9: REF. NO.
H10: (For Non-cost-Share Items Show Units)
H11: 14 | I11: 15 | J11: 16 | K11: 17 | L11: 18 | M11: 19 | N11: 20 | O11: 21 | P11: 22 | Q11: 23
H12: Year | I12: Year | J12: Year | K12: Year | L12: Year | M12: Year | N12: Year | O12: Year | P12: Year | Q12: Year
H13: ='CRPSignature Page'!H15 -> 2014 | I13: ='CRPSignature Page'!I15 -> 2015 | J13: ='CRPSignature Page'!K15 -> 2019 | K13: ='CRPSignature Page'!L15 -> 2020 | L13: ='CRPSignature Page'!N15 -> 2024 | M13: ='CRPSignature Page'!O15 -> 2026
A14: 8 | B14: 9 | C14: 10 | D14: 11 | F14: 12 | G14: 13 | H14: 24 | I14: 25 | J14: 26 | K14: 27 | L14: 28 | M14: 29 | N14: 30 | O14: 31 | P14: 32 | Q14: 33 | R14: 34
C15: Tree And Shrub Planting
C16: CRBB LIGHT SITE PREPARATION | E16: AC | F16: ='Component List'!D29 -> 74.12 | G16: 50 | H16: =D16*F16*G16/100 -> 0
C17: CRBC MEDIUM SITE PREPARATION | E17: AC | F17: ='Component List'!D30 -> 149.58 | G17: 50 | H17: =D17*F17*G17/100 -> 0
C18: CRBD TREE/SHRUB PLANTING (HAND OR MACHINE) | E18: 100 | F18: ='Component List'!D31 -> 56.58 | G18: 50 | H18: =D18*F18*G18/100 -> 0
C19: CRBJ WEED/INSECT CONTROL - TREES | E19: AC | F19: ='Component List'!D37 -> 59.48 | G19: 50 | H19: =D19*F19*G19/100 -> 0
C20: CRBI SEEDING FIREBREAKS | E20: AC | F20: ='Component List'!D36 -> 75.36 | G20: 50 | H20: =D20*F20*G20/100 -> 0
C21: CRBE DNR TREES/SHRUBS | E21: 100 | F21: ='Component List'!D32 -> 70.2 | G21: 50 | H21: =D21*F21*G21/100 -> 0
C22: CRBF PRIVATE NURSERY TREES/SHRUBS | E22: 100 | F22: ='Component List'!D33 -> 117.6 | G22: 50 | H22: =D22*F22*G22/100 -> 0
C23: CRBH CUTTINGS AND TRANSPLANTS | E23: 100 | F23: ='Component List'!D35 -> 214.5 | G23: 50 | H23: =D23*F23*G23/100 -> 0
C24: CRBA TEMPORARY SEEDING | E24: AC | F24: ='Component List'!D28 -> 94.14 | G24: 50 | H24: =D24*F24*G24/100 -> 0
C25: CRBG CONTAINERIZED TREES | E25: 100 | F25: ='Component List'!D34 -> 200 | G25: 50 | H25: =D25*F25*G25/100 -> 0
C26: CRDH CROP TREE RELEASE - SLASH LEFT | E26: AC | F26: ='Component List'!D60 -> 100 | G26: 50 | H26: =D26*F26*G26/100 -> 0
C27: CRDI THINNING - SLASH LEFT | E27: AC | F27: ='Component List'!D61 -> 450 | G27: 50 | H27: =D27*F27*G27/100 -> 0
C28: CRDJ THINNING - SLASH REMOVED | E28: AC | F28: ='Component List'!D62 -> 500 | G28: 50 | H28: =D28*F28*G28/100 -> 0
C29: CRDK PRUNING UP TO 12 FT | E29: AC | F29: ='Component List'!D63 -> 90 | G29: 50 | H29: =D29*F29*G29/100 -> 0
C30: CRDL PRUNING UP TO 17 FT | E30: AC | F30: ='Component List'!D64 -> 180 | G30: 50 | H30: =D30*F30*G30/100 -> 0
C31: Grass Planting
C32: CRAA LABORATORY SOIL ANALYSIS FEE | E32: AC | F32: ='Component List'!D2 -> 1.64 | G32: 50 | H32: =D32*F32*G32/100 -> 0
C33: CRAB LIME & FERTILIZER PER SOIL TEST | E33: AC | F33: ='Component List'!D3 -> 0 | G33: 50 | H33: =D33*F33*G33/100 -> 0
C34: CRAC SEEDBED PREPARATION | E34: AC | F34: ='Component List'!D4 -> 80.06 | G34: 50 | H34: =D34*F34*G34/100 -> 0
C35: CRAD SEEDING OPERATION>3 AC | E35: AC | F35: ='Component List'!D5 -> 62.6 | G35: 50 | H35: =D35*F35*G35/100 -> 0
C36: CRAE CP1 SEED (SEE JOB SHEET 134) | E36: AC | F36: ='Component List'!D6 -> 52.88 | G36: 50 | H36: =D36*F36*G36/100 -> 0
C37: CRAG CP4D SEED (SEE JOB SHEET 135) | E37: AC | F37: ='Component List'!D8 -> 214.1 | G37: 50 | H37: =D37*F37*G37/100 -> 0
C38: CRAO SEEDING RATE SMALL ACREAGE <3 ACRES | E38: AC | F38: ='Component List'!D16 -> 84.42 | G38: 50 | H38: =D38*F38*G38/100 -> 0
C39: CRBA TEMPORARY SEEDING | E39: AC | F39: ='Component List'!D28 -> 94.14 | G39: 50 | H39: =D39*F39*G39/100 -> 0
A40: Totals: | H40: =SUM(H15:H39) -> 0 | I40: =SUM(I15:I39) -> 0 | J40: =SUM(J15:J39) -> 0 | K40: =SUM(K15:K39) -> 0 | L40: =SUM(L15:L39) -> 0 | M40: =SUM(M15:M39) -> 0
A41: =IF(AE70,AE72,"")
A42: OMB DISCLOSURE STATEMENT
...

Sheet existCP3A
A1: 1. To be completed by NRCS; check appropriate box: | D1: This transaction is for CCC. | H1: This transaction is for NRCS. | O1: OMB No. 0578-0013
A2: U.S. DEPARTMENT OF AGRICULTURE | F2: CONSERVATION PLAN | N2: 2. | O2: Page | Q2: of
F3: SCHEDULE OF OPERATIONS
A4: 1. NAME | D4: 2. COUNTY | H4: 3. STATE | J4: 4. CONTRACT OR AGREEMENT NO. | M4: 5. TOTAL ACRES UNDER CONTRACT
A5: ='CRPSignature Page'!A8 -> 0 | D5: ='CRPSignature Page'!D8 -> 0 | H5: Wisconsin | J5: ='CRPSignature Page'!I8 -> 0 | M5: ='CRPSignature Page'!P8 -> 0
A7: CRP-CP3A: Hardwood Tree Planting. These fields are already established according to the tree-planting plan prepared by the local DNR forester or NRCS. These fields will not be managed for Christmas trees and will be maintained as required by Job Sheet 397. CRP rules do not allow disturbance of cover including maintenance or required management during the primary nesting season recorded in the CRP contract (May 15 through August 1). Spot clipping or spot spraying may be done during the primary nesting season with prior approval from the local FSA Service Agency (FSA) County Committee. The CRP cover will not be harvested, and will be protected from grazing by livestock for the duration of the contract.
A9: ITEM NO. | B9: FIELD | C9: PLANNED CONSERVATION TREATMENT (Record of Decisions) | D9: ESTIMATED AMOUNTS (UNITS) | F9: COST BASIS $ | G9: COST SHARE OR PAYMENT RATE % | H9: COMPLETION SCHEDULE AND ESTIMATED COST SHARE OR PAYMENT BY YEAR | R9: REF. NO.
H10: (For Non-cost-Share Items Show Units)
H11: 14 | I11: 15 | J11: 16 | K11: 17 | L11: 18 | M11: 19 | N11: 20 | O11: 21 | P11: 22 | Q11: 23
H12: Year | I12: Year | J12: Year | K12: Year | L12: Year | M12: Year | N12: Year | O12: Year | P12: Year | Q12: Year
H13: ='CRPSignature Page'!H15 -> 2014 | I13: ='CRPSignature Page'!I15 -> 2015 | J13: ='CRPSignature Page'!K15 -> 2019 | K13: ='CRPSignature Page'!L15 -> 2020 | L13: ='CRPSignature Page'!N15 -> 2024 | M13: ='CRPSignature Page'!O15 -> 2026
A14: 8 | B14: 9 | C14: 10 | D14: 11 | F14: 12 | G14: 13 | H14: 24 | I14: 25 | J14: 26 | K14: 27 | L14: 28 | M14: 29 | N14: 30 | O14: 31 | P14: 32 | Q14: 33 | R14: 34
C15: Tree Planting
C16: CRDA NO C/S AUTH. OR COVER ALREADY ESTAB. | E16: AC
C17: CRDH CROP TREE RELEASE - SLASH LEFT | E17: AC | F17: ='Component List'!D60 -> 100 | G17: 50 | H17: =D17*F17*G17/100 -> 0
C18: CRDI THINNING - SLASH LEFT | E18: AC | F18: ='Component List'!D61 -> 450 | G18: 50 | H18: =D18*F18*G18/100 -> 0
C19: CRDJ THINNING - SLASH REMOVED | E19: AC | F19: ='Component List'!D62 -> 500 | G19: 50 | H19: =D19*F19*G19/100 -> 0
C20: CRDK PRUNING UP TO 12 FT | E20: AC | F20: ='Component List'!D63 -> 90 | G20: 50 | H20: =D20*F20*G20/100 -> 0
C21: CRDL PRUNING UP TO 17 FT | E21: AC | F21: ='Component List'!D64 -> 180 | G21: 50 | H21: =D21*F21*G21/100 -> 0
A22: Totals: | H22: =SUM(H15:H21) -> 0 | I22: =SUM(I15:I21) -> 0 | J22: =SUM(J15:J21) -> 0 | K22: =SUM(K15:K21) -> 0 | L22: =SUM(L15:L21) -> 0 | M22: =SUM(M15:M21) -> 0
A23: =IF(AE52,AE54,"")
A24: OMB DISCLOSURE STATEMENT
A25: Federal Agencies may not conduct or sponsor, and a person is not required to respond to a collection of information unless it displays a currently valid OMB control number. Public reporting burden for this collection is estimated to average 37.5 mins. per response, including the time for reviewing instructions, searching existing data sources, gathering and maintaining the data needed, and completing and reviewing the collection of information. Send comments regarding this burden estimate or any other aspect of this collection of information, including suggestions for reducing this burden to Department of Agriculture, OIRM, Stop 7630, Wash. DC
A26: PRIVACY ACT STATEMENT
A27: The above statements are made in accordance with the Privacy Act of 1974 (5 U.S.C. 522a). Furnishing this information is voluntary; however, failure to furnish correct, complete information will result in the withholding or withdrawal of such technical or financial assistance. The information may be furnished to other USDA agencies, the Internal Revenue Service, the Department of Justice, or other State or Federal law enforcement agencies, or in response to orders of a court, magistrate, or administrative tribunal.
A28: NONDISCRIMINATION STATEMENT
A29: The U.S. Department of Agriculture (USDA) prohibits discrimination in all its programs and activities on the basis of race, color, national origin, gender, religion, age, disability, and where applicable, sex, marital status, familial status, parental status, religion, sexual orientation, genetic information, political beliefs, reprisal or because all or part of an individuals income is derived from any public assistance program.. (Not all prohibited bases apply to all programs). Persons with disabilities who require alternative means for communication of program information (Braille, large print, audiotape, etc.) should contact USDA's TARGET Center at (202) 720-2600 (voice and TDD). To file a complaint of discrimination, write USDA, Director, Office of Civil Rights, 1400 Independence Avenue, SW., Washington D.C. 20250-9410, or call (800) 795-3272 (voice) or (202)720-6382 (TDD).

Sheet CP3A
A1: 1. To be completed by NRCS; check appropriate box: | D1: This transaction is for CCC. | H1: This transaction is for NRCS. | O1: OMB No. 0578-0013
A2: U.S. DEPARTMENT OF AGRICULTURE | F2: CONSERVATION PLAN | N2: 2. | O2: Page | Q2: of
F3: SCHEDULE OF OPERATIONS
A4: 1. NAME | D4: 2. COUNTY | H4: 3. STATE | J4: 4. CONTRACT OR AGREEMENT NO. | M4: 5. TOTAL ACRES UNDER CONTRACT
A5: ='CRPSignature Page'!A8 -> 0 | D5: ='CRPSignature Page'!D8 -> 0 | H5: Wisconsin | J5: ='CRPSignature Page'!I8 -> 0 | M5: ='CRPSignature Page'!P8 -> 0
A7: CRP-CP3A: Hardwood Tree Planting. These fields will be planted to hardwood trees according to the tree-planting plan prepared by the local DNR forester or Wisconsin NRCS Job Sheets 624 and 143. The planted acreage will not be managed for Christmas trees. To establish the seeding, control weeds and brush as needed by spraying, burning, or mowing until the seeding is certified as established (may require up to 3 years of intensive management). Once the seeding is established, these fields will be maintained as required by Job Sheet 397. CRP rules do not allow disturbance of cover including maintenance or required management during the primary nesting season recorded in the CRP contract (May 15 through August 1). Spot clipping or spot spraying may be done during the primary nesting season with prior approval from the local FSA Service Agency (FSA) County Committee. The CRP cover will not be harvested, and will be protected from grazing by livestock for the duration of the contract.
A9: ITEM NO. | B9: FIELD | C9: PLANNED CONSERVATION TREATMENT (Record of Decisions) | D9: ESTIMATED AMOUNTS (UNITS) | F9: COST BASIS $ | G9: COST SHARE OR PAYMENT RATE % | H9: COMPLETION SCHEDULE AND ESTIMATED COST SHARE OR PAYMENT BY YEAR | R9: REF. NO.
H10: (For Non-cost-Share Items Show Units)
H11: 14 | I11: 15 | J11: 16 | K11: 17 | L11: 18 | M11: 19 | N11: 20 | O11: 21 | P11: 22 | Q11: 23
H12: Year | I12: Year | J12: Year | K12: Year | L12: Year | M12: Year | N12: Year | O12: Year | P12: Year | Q12: Year
H13: ='CRPSignature Page'!H15 -> 2014 | I13: ='CRPSignature Page'!I15 -> 2015 | J13: ='CRPSignature Page'!K15 -> 2019 | K13: ='CRPSignature Page'!L15 -> 2020 | L13: ='CRPSignature Page'!N15 -> 2024 | M13: ='CRPSignature Page'!O15 -> 2026
A14: 8 | B14: 9 | C14: 10 | D14: 11 | F14: 12 | G14: 13 | H14: 24 | I14: 25 | J14: 26 | K14: 27 | L14: 28 | M14: 29 | N14: 30 | O14: 31 | P14: 32 | Q14: 33 | R14: 34
C15: Tree Planting
C16: CRBB LIGHT SITE PREPARATION | E16: AC | F16: ='Component List'!D29 -> 74.12 | G16: 50 | H16: =D16*F16*G16/100 -> 0
C17: CRBC MEDIUM SITE PREPARATION | E17: AC | F17: ='Component List'!D30 -> 149.58 | G17: 50 | H17: =D17*F17*G17/100 -> 0
C18: CRBD TREE/SHRUB PLANTING (HAND OR MACHINE) | E18: 100 | F18: ='Component List'!D31 -> 56.58 | G18: 50 | H18: =D18*F18*G18/100 -> 0
C19: CRBJ WEED/INSECT CONTROL - TREES | E19: AC | F19: ='Component List'!D37 -> 59.48 | G19: 50 | H19: =D19*F19*G19/100 -> 0
C20: CRBE DNR TREES/SHRUBS | E20: 100 | F20: ='Component List'!D32 -> 70.2 | G20: 50 | H20: =D20*F20*G20/100 -> 0
C21: CRBF PRIVATE NURSERY TREES/SHRUBS | E21: 100 | F21: ='Component List'!D33 -> 117.6 | G21: 50 | H21: =D21*F21*G21/100 -> 0
C22: CRBG CONTAINERIZED TREES | E22: 100 | F22: ='Component List'!D34 -> 200 | G22: 50 | H22: =D22*F22*G22/100 -> 0
C23: CRBH CUTTINGS & TRANSPLANTS, ASPEN | E23: 100 | F23: ='Component List'!D35 -> 214.5 | G23: 50 | H23: =D23*F23*G23/100 -> 0
C24: CRBL ANIMAL CONTROL DEVICE (STC APPROVAL) | E24: No | F24: ='Component List'!D39 -> 6.38 | G24: 50 | H24: =D24*F24*G24/100 -> 0
C25: CRBO DIRECT SEED BROADCAST TREE SEED | E25: AC | F25: ='Component List'!D42 -> 46.42 | G25: 50 | H25: =D25*F25*G25/100 -> 0
C26: CRBN TREE SEED/LIGHT SEEDED | E26: LB | F26: ='Component List'!D41 -> 85 | G26: 50 | H26: =D26*F26*G26/100 -> 0
C27: CRBM TREE SEED/HEAVY SEEDED | E27: BU | F27: ='Component List'!D40 -> 35.26 | G27: 50 | H27: =D27*F27*G27/100 -> 0
C28: CRDH CROP TREE RELEASE - SLASH LEFT | E28: AC | F28: ='Component List'!D60 -> 100 | G28: 50 | H28: =D28*F28*G28/100 -> 0
C29: CRDI THINNING - SLASH LEFT | E29: AC | F29: ='Component List'!D61 -> 450 | G29: 50 | H29: =D29*F29*G29/100 -> 0
C30: CRDJ THINNING - SLASH REMOVED | E30: AC | F30: ='Component List'!D62 -> 500 | G30: 50 | H30: =D30*F30*G30/100 -> 0
C31: CRDK PRUNING UP TO 12 FT | E31: AC | F31: ='Component List'!D63 -> 90 | G31: 50 | H31: =D31*F31*G31/100 -> 0
C32: CRDL PRUNING UP TO 17 FT | E32: AC | F32: ='Component List'!D64 -> 180 | G32: 50 | H32: =D32*F32*G32/100 -> 0
C33: Grass Planting
C34: CRAD SEEDING OPERATION >3AC | E34: AC | F34: ='Component List'!D5 -> 62.6 | G34: 50 | H34: =D34*F34*G34/100 -> 0
C35: CRAO SEEDING RATE SMALL ACREAGE <3 ACRES | E35: AC | F35: ='Component List'!D16 -> 84.42 | G35: 50 | H35: =D35*F35*G35/100 -> 0
C36: CRAE CP1 SEED | E36: AC | F36: ='Component List'!D6 -> 52.88 | G36: 50 | H36: =D36*F36*G36/100 -> 0
C37: CRBA TEMPORARY SEEDING | E37: AC | F37: ='Component List'!D28 -> 94.14 | G37: 50 | H37: =D37*F37*G37/100 -> 0
C38: CRBI SEEDING FIREBREAKS | E38: AC | F38: ='Component List'!D36 -> 75.36 | G38: 50 | H38: =D38*F38*G38/100 -> 0
A39: Totals: | H39: =SUM(H15:H38) -> 0 | I39: =SUM(I15:I38) -> 0 | J39: =SUM(J15:J38) -> 0 | K39: =SUM(K15:K38) -> 0 | L39: =SUM(L15:L38) -> 0 | M39: =SUM(M15:M38) -> 0
A40: =IF(AE69,AE71,"")
A41: OMB DISCLOSURE STATEMENT
