Workbook
Name MATCHINST: #REF!
Name MATCHINST: #REF!
Name MATCHINST: #REF!
Name MATCHINST: #REF!
Name MATCHINST: #REF!
Name MATCHINST: #REF!

Sheet Comparisons
B1: Outcomes-Based Funding Comparisons to Instruction and Operations Distribution
F2: Option 1 - As proposed for 2014-2015 Compared to Total I&O | J2: Option 1 - As proposed for 2014-2015 Compared to Undergraduate I&O | N2: Option 2 - Option 1 Weighted by Accountability Group | R2: Option 3 - Option 2 with Graduate Degrees | V2: Option 4 - Option 1 Weighted by Carnegie Classification | Z2: Option 5 - Option 4 with Graduate Degrees
A3: FICE | C3: 2014-2015 Instruction and Operations Percent of Total | D3: 2014-2015 Undergraduate Instruction and Operations Percent of Total | F3: 2014-2015 Proposed Model | G3: Percent Difference From 2014-2015 I&O | H3: Difference (Millions) | J3: 2014-2015 Proposed Model | K3: Percent Difference From 2014-2015 Undergraduate I&O | L3: Difference (Millions) | N3: Option 1 Scaled, Weighted, and Monetized by Accountability Group Percent of Total | O3: Percent Difference From 2014-2015 I&O | P3: Difference (Millions) | R3: Option 2 with Graduate Degrees Percent of Total | S3: Percent Difference From 2014-2015 I&O | T3: Difference (Millions) | V3: Option 1 Scaled, Weighted, and Monetized by SREB Carnegie Classification Percent of Total | W3: Percent Difference From 2014-2015 I&O | X3: Difference (Millions) | Z3: Option 4 with Graduate Degrees Percent of Total | AA3: Percent Difference From 2014-2015 I&O | AB3: Difference (Millions)
A4: 3656 | B4: UTA | C4: 0.055594621 | D4: 0.053941374 | F4: ='Option 1'!C5/'Option 1'!$C$43 -> 0.05743312 | G4: =F4-$C4 -> 0.0018384992 | H4: =G4*'Option 1'!$C$43/1000000 -> 0.4320473 | J4: =F4 -> 0.05743312 | K4: =J4-$D4 -> 0.0034917461 | L4: =K4*'Option 2'!$C$43/1000000 -> 0.82056032 | N4: ='Option 2'!C5/'Option 2'!$C$43 -> 0.068730704 | O4: =N4-$D4 -> 0.01478933 | P4: =O4*'Option 2'!$C$43/1000000 -> 3.4754926 | R4: ='Option 3'!C5/'Option 3'!$C$43 -> 0.069265607 | S4: =R4-$D4 -> 0.015324233 | T4: =S4*'Option 3'!$C$43/1000000 -> 3.6011948 | V4: ='Option 4'!C5/'Option 4'!$C$43 -> 0.05735313 | W4: =V4-$D4 -> 0.0034117557 | X4: =W4*'Option 4'!$C$43/1000000 -> 0.80176258 | Z4: ='Option 5'!C5/'Option 5'!$C$43 -> 0.058402527 | AA4: =Z4-$D4 -> 0.0044611533 | AB4: =AA4*'Option 5'!$C$43/1000000 -> 1.048371
A5: 3658 | B5: UT | C5: 0.1201911 | D5: 0.097535368 | F5: ='Option 1'!C6/'Option 1'!$C$43 -> 0.1074438 | G5: =F5-$C5 -> -0.012747303 | H5: =G5*'Option 1'!$C$43/1000000 -> -2.9956163 | J5: =F5 -> 0.1074438 | K5: =J5-$D5 -> 0.0099084331 | L5: =K5*'Option 2'!$C$43/1000000 -> 2.3284818 | N5: ='Option 2'!C6/'Option 2'!$C$43 -> 0.10417329 | O5: =N5-$D5 -> 0.006637918 | P5: =O5*'Option 2'!$C$43/1000000 -> 1.5599107 | R5: ='Option 3'!C6/'Option 3'!$C$43 -> 0.11732626 | S5: =R5-$D5 -> 0.019790889 | T5: =S5*'Option 3'!$C$43/1000000 -> 4.6508589 | V5: ='Option 4'!C6/'Option 4'!$C$43 -> 0.11095472 | W5: =V5-$D5 -> 0.013419351 | X5: =W5*'Option 4'!$C$43/1000000 -> 3.1535474 | Z5: ='Option 5'!C6/'Option 5'!$C$43 -> 0.12592857 | AA5: =Z5-$D5 -> 0.028393203 | AB5: =AA5*'Option 5'!$C$43/1000000 -> 6.6724027
A6: 9741 | B6: UTD | C6: 0.04471444 | D6: 0.030845131 | F6: ='Option 1'!C7/'Option 1'!$C$43 -> 0.02796093 | G6: =F6-$C6 -> -0.01675351 | H6: =G6*'Option 1'!$C$43/1000000 -> -3.9370748 | J6: =F6 -> 0.02796093 | K6: =J6-$D6 -> -0.0028842008 | L6: =K6*'Option 2'!$C$43/1000000 -> -0.67778718 | N6: ='Option 2'!C7/'Option 2'!$C$43 -> 0.034842871 | O6: =N6-$D6 -> 0.00399774 | P6: =O6*'Option 2'!$C$43/1000000 -> 0.93946891 | R6: ='Option 3'!C7/'Option 3'!$C$43 -> 0.040582548 | S6: =R6-$D6 -> 0.0097374167 | T6: =S6*'Option 3'!$C$43/1000000 -> 2.2882929 | V6: ='Option 4'!C7/'Option 4'!$C$43 -> 0.030295854 | W6: =V6-$D6 -> -0.00054927733 | X6: =W6*'Option 4'!$C$43/1000000 -> -0.12908017 | Z6: ='Option 5'!C7/'Option 5'!$C$43 -> 0.036704219 | AA6: =Z6-$D6 -> 0.0058590882 | AB6: =AA6*'Option 5'!$C$43/1000000 -> 1.3768857
A7: 3661 | B7: UTEP | C7: 0.033143125 | D7: 0.0380679 | F7: ='Option 1'!C8/'Option 1'!$C$43 -> 0.0378017 | G7: =F7-$C7 -> 0.004658575 | H7: =G7*'Option 1'!$C$43/1000000 -> 1.0947651 | J7: =F7 -> 0.0378017 | K7: =J7-$D7 -> -0.00026619948 | L7: =K7*'Option 2'!$C$43/1000000 -> -0.062556878 | N7: ='Option 2'!C8/'Option 2'!$C$43 -> 0.03320388 | O7: =N7-$D7 -> -0.0048640201 | P7: =O7*'Option 2'!$C$43/1000000 -> -1.1430447 | R7: ='Option 3'!C8/'Option 3'!$C$43 -> 0.030961007 | S7: =R7-$D7 -> -0.0071068926 | T7: =S7*'Option 3'!$C$43/1000000 -> -1.6701198 | V7: ='Option 4'!C8/'Option 4'!$C$43 -> 0.035365373 | W7: =V7-$D7 -> -0.0027025267 | X7: =W7*'Option 4'!$C$43/1000000 -> -0.63509378 | Z7: ='Option 5'!C8/'Option 5'!$C$43 -> 0.033231056 | AA7: =Z7-$D7 -> -0.0048368439 | AB7: =AA7*'Option 5'!$C$43/1000000 -> -1.1366583
A8: 3599 | B8: UTPA | C8: 0.027407848 | D8: 0.036041181 | F8: ='Option 1'!C9/'Option 1'!$C$43 -> 0.033414305 | G8: =F8-$C8 -> 0.0060064575 | H8: =G8*'Option 1'!$C$43/1000000 -> 1.4115175 | J8: =F8 -> 0.033414305 | K8: =J8-$D8 -> -0.0026268755 | L8: =K8*'Option 2'!$C$43/1000000 -> -0.61731575 | N8: ='Option 2'!C9/'Option 2'!$C$43 -> 0.027727596 | O8: =N8-$D8 -> -0.0083135849 | P8: =O8*'Option 2'!$C$43/1000000 -> -1.9536924 | R8: ='Option 3'!C9/'Option 3'!$C$43 -> 0.024458088 | S8: =R8-$D8 -> -0.011583093 | T8: =S8*'Option 3'!$C$43/1000000 -> -2.7220268 | V8: ='Option 4'!C9/'Option 4'!$C$43 -> 0.029532596 | W8: =V8-$D8 -> -0.0065085845 | X8: =W8*'Option 4'!$C$43/1000000 -> -1.5295173 | Z8: ='Option 5'!C9/'Option 5'!$C$43 -> 0.026251346 | AA8: =Z8-$D8 -> -0.0097898353 | AB8: =AA8*'Option 5'!$C$43/1000000 -> -2.3006113
A9: 30646 | B9: UTB | C9: 0.0098207333 | D9: 0.013127311 | F9: ='Option 1'!C10/'Option 1'!$C$43 -> 0.011024062 | G9: =F9-$C9 -> 0.0012033289 | H9: =G9*'Option 1'!$C$43/1000000 -> 0.28278228 | J9: =F9 -> 0.011024062 | K9: =J9-$D9 -> -0.0021032491 | L9: =K9*'Option 2'!$C$43/1000000 -> -0.49426354 | N9: ='Option 2'!C10/'Option 2'!$C$43 -> 0.011084062 | O9: =N9-$D9 -> -0.0020432496 | P9: =O9*'Option 2'!$C$43/1000000 -> -0.48016367 | R9: ='Option 3'!C10/'Option 3'!$C$43 -> 0.0098077039 | S9: =R9-$D9 -> -0.0033196073 | T9: =S9*'Option 3'!$C$43/1000000 -> -0.78010772 | V9: ='Option 4'!C10/'Option 4'!$C$43 -> 0.011805608 | W9: =V9-$D9 -> -0.0013217037 | X9: =W9*'Option 4'!$C$43/1000000 -> -0.31060036 | Z9: ='Option 5'!C10/'Option 5'!$C$43 -> 0.010051137 | AA9: =Z9-$D9 -> -0.0030761738 | AB9: =AA9*'Option 5'!$C$43/1000000 -> -0.72290085
A10: 9930 | B10: UTPB | C10: 0.0050772741 | D10: 0.006658598 | F10: ='Option 1'!C11/'Option 1'!$C$43 -> 0.0058857016 | G10: =F10-$C10 -> 0.00080842752 | H10: =G10*'Option 1'!$C$43/1000000 -> 0.18998047 | J10: =F10 -> 0.0058857016 | K10: =J10-$D10 -> -0.00077289639 | L10: =K10*'Option 2'!$C$43/1000000 -> -0.18163065 | N10: ='Option 2'!C11/'Option 2'!$C$43 -> 0.0060194865 | O10: =N10-$D10 -> -0.00063911151 | P10: =O10*'Option 2'!$C$43/1000000 -> -0.15019121 | R10: ='Option 3'!C11/'Option 3'!$C$43 -> 0.0055169267 | S10: =R10-$D10 -> -0.0011416713 | T10: =S10*'Option 3'!$C$43/1000000 -> -0.26829275 | V10: ='Option 4'!C11/'Option 4'!$C$43 -> 0.0064113407 | W10: =V10-$D10 -> -0.0002472573 | X10: =W10*'Option 4'!$C$43/1000000 -> -0.058105464 | Z10: ='Option 5'!C11/'Option 5'!$C$43 -> 0.0055276514 | AA10: =Z10-$D10 -> -0.0011309466 | AB10: =AA10*'Option 5'!$C$43/1000000 -> -0.26577245
A11: 10115 | B11: UTSA | C11: 0.044912894 | D11: 0.051993931 | F11: ='Option 1'!C12/'Option 1'!$C$43 -> 0.050267953 | G11: =F11-$C11 -> 0.0053550593 | H11: =G11*'Option 1'!$C$43/1000000 -> 1.2584389 | J11: =F11 -> 0.050267953 | K11: =J11-$D11 -> -0.0017259779 | L11: =K11*'Option 2'!$C$43/1000000 -> -0.40560481 | N11: ='Option 2'!C12/'Option 2'!$C$43 -> 0.043095631 | O11: =N11-$D11 -> -0.0088983006 | P11: =O11*'Option 2'!$C$43/1000000 -> -2.0911006 | R11: ='Option 3'!C12/'Option 3'!$C$43 -> 0.038576311 | S11: =R11-$D11 -> -0.013417621 | T11: =S11*'Option 3'!$C$43/1000000 -> -3.1531408 | V11: ='Option 4'!C12/'Option 4'!$C$43 -> 0.045901054 | W11: =V11-$D11 -> -0.0060928778 | X11: =W11*'Option 4'!$C$43/1000000 -> -1.4318263 | Z11: ='Option 5'!C12/'Option 5'!$C$43 -> 0.041404711 | AA11: =Z11-$D11 -> -0.010589221 | AB11: =AA11*'Option 5'!$C$43/1000000 -> -2.4884669
A12: 11163 | B12: UTT | C12: 0.010834468 | D12: 0.012069402 | F12: ='Option 1'!C13/'Option 1'!$C$43 -> 0.013484386 | G12: =F12-$C12 -> 0.002649918 | H12: =G12*'Option 1'!$C$43/1000000 -> 0.62273073 | J12: =F12 -> 0.013484386 | K12: =J12-$D12 -> 0.0014149841 | L12: =K12*'Option 2'!$C$43/1000000 -> 0.33252127 | N12: ='Option 2'!C13/'Option 2'!$C$43 -> 0.012763807 | O12: =N12-$D12 -> 0.00069440541 | P12: =O12*'Option 2'!$C$43/1000000 -> 0.16318527 | R12: ='Option 3'!C13/'Option 3'!$C$43 -> 0.012123756 | S12: =R12-$D12 -> 5.4354351e-05 | T12: =S12*'Option 3'!$C$43/1000000 -> 0.012773272 | V12: ='Option 4'!C13/'Option 4'!$C$43 -> 0.0135947 | W12: =V12-$D12 -> 0.0015252988 | X12: =W12*'Option 4'!$C$43/1000000 -> 0.35844522 | Z12: ='Option 5'!C13/'Option 5'!$C$43 -> 0.012257064 | AA12: =Z12-$D12 -> 0.00018766267 | AB12: =AA12*'Option 5'!$C$43/1000000 -> 0.044100727
A13: 3632 | B13: TAMU | C13: 0.12924678 | D13: 0.10514316 | F13: ='Option 1'!C14/'Option 1'!$C$43 -> 0.1086895 | G13: =F13-$C13 -> -0.020557277 | H13: =G13*'Option 1'!$C$43/1000000 -> -4.8309601 | J13: =F13 -> 0.1086895 | K13: =J13-$D13 -> 0.0035463352 | L13: =K13*'Option 2'!$C$43/1000000 -> 0.83338876 | N13: ='Option 2'!C14/'Option 2'!$C$43 -> 0.10482702 | O13: =N13-$D13 -> -0.00031614231 | P13: =O13*'Option 2'!$C$43/1000000 -> -0.074293443 | R13: ='Option 3'!C14/'Option 3'!$C$43 -> 0.10194245 | S13: =R13-$D13 -> -0.0032007146 | T13: =S13*'Option 3'!$C$43/1000000 -> -0.75216794 | V13: ='Option 4'!C14/'Option 4'!$C$43 -> 0.11165101 | W13: =V13-$D13 -> 0.0065078469 | X13: =W13*'Option 4'!$C$43/1000000 -> 1.529344 | Z13: ='Option 5'!C14/'Option 5'!$C$43 -> 0.10941683 | AA13: =Z13-$D13 -> 0.004273665 | AB13: =AA13*'Option 5'!$C$43/1000000 -> 1.0043113
A14: 10298 | B14: TAMUG | C14: 0.0051146603 | D14: 0.0070859753 | F14: ='Option 1'!C15/'Option 1'!$C$43 -> 0.0059921021 | G14: =F14-$C14 -> 0.00087744178 | H14: =G14*'Option 1'!$C$43/1000000 -> 0.20619882 | J14: =F14 -> 0.0059921021 | K14: =J14-$D14 -> -0.0010938731 | L14: =K14*'Option 2'!$C$43/1000000 -> -0.25706019 | N14: ='Option 2'!C15/'Option 2'!$C$43 -> 0.009023132 | O14: =N14-$D14 -> 0.0019371568 | P14: =O14*'Option 2'!$C$43/1000000 -> 0.45523184 | R14: ='Option 3'!C15/'Option 3'!$C$43 -> 0.0072996992 | S14: =R14-$D14 -> 0.0002137239 | T14: =S14*'Option 3'!$C$43/1000000 -> 0.050225117 | V14: ='Option 4'!C15/'Option 4'!$C$43 -> 0.010508201 | W14: =V14-$D14 -> 0.003422226 | X14: =W14*'Option 4'!$C$43/1000000 -> 0.80422311 | Z14: ='Option 5'!C15/'Option 5'!$C$43 -> 0.0091573236 | AA14: =Z14-$D14 -> 0.0020713483 | AB14: =AA14*'Option 5'!$C$43/1000000 -> 0.48676686
A15: 3630 | B15: Prairie View | C15: 0.012996729 | D15: 0.015279411 | F15: ='Option 1'!C16/'Option 1'!$C$43 -> 0.013402905 | G15: =F15-$C15 -> 0.00040617689 | H15: =G15*'Option 1'!$C$43/1000000 -> 0.095451569 | J15: =F15 -> 0.013402905 | K15: =J15-$D15 -> -0.0018765054 | L15: =K15*'Option 2'!$C$43/1000000 -> -0.44097876 | N15: ='Option 2'!C16/'Option 2'!$C$43 -> 0.011525931 | O15: =N15-$D15 -> -0.0037534796 | P15: =O15*'Option 2'!$C$43/1000000 -> -0.88206771 | R15: ='Option 3'!C16/'Option 3'!$C$43 -> 0.011332473 | S15: =R15-$D15 -> -0.0039469378 | T15: =S15*'Option 3'!$C$43/1000000 -> -0.92753039 | V15: ='Option 4'!C16/'Option 4'!$C$43 -> 0.012276242 | W15: =V15-$D15 -> -0.003003169 | X15: =W15*'Option 4'!$C$43/1000000 -> -0.70574471 | Z15: ='Option 5'!C16/'Option 5'!$C$43 -> 0.011777012 | AA15: =Z15-$D15 -> -0.0035023988 | AB15: =AA15*'Option 5'!$C$43/1000000 -> -0.82306372
... A41: 20 | B41: SRRG | C41: 0.0011186188 | D41: 0.0014792799 | F41: ='Option 1'!C42/'Option 1'!$C$43 -> 0.0015991513 | G41: =F41-$C41 -> 0.00048053254 | H41: =G41*'Option 1'!$C$43/1000000 -> 0.11292515 | J41: =F41 -> 0.0015991513 | K41: =J41-$D41 -> 0.00011987141 | L41: =K41*'Option 2'!$C$43/1000000 -> 0.028169781 | N41: ='Option 2'!C42/'Option 2'!$C$43 -> 0.0031780346 | O41: =N41-$D41 -> 0.0016987547 | P41: =O41*'Option 2'!$C$43/1000000 -> 0.39920736 | R41: ='Option 3'!C42/'Option 3'!$C$43 -> 0.0025786324 | S41: =R41-$D41 -> 0.0010993524 | T41: =S41*'Option 3'!$C$43/1000000 -> 0.25834782 | V41: ='Option 4'!C42/'Option 4'!$C$43 -> 0.0033849171 | W41: =V41-$D41 -> 0.0019056372 | X41: =W41*'Option 4'!$C$43/1000000 -> 0.44782475 | Z41: ='Option 5'!C42/'Option 5'!$C$43 -> 0.0027676967 | AA41: =Z41-$D41 -> 0.0012884167 | AB41: =AA41*'Option 5'!$C$43/1000000 -> 0.30277793
B42: Total | C42: =SUM(C4:C41) -> 1 | D42: =SUM(D4:D41) -> 1 | F42: =SUM(F4:F41) -> 1 | G42: =F42-$C42 -> 0 | H42: =SUM(H4:H41) -> 7.0402018e-14 | J42: =SUM(J4:J41) -> 1 | K42: =J42-$D42 -> 0 | L42: =SUM(L4:L41) -> 1.1370072e-13 | N42: ='Option 2'!C43/'Option 2'!$C$43 -> 1 | O42: =N42-$D42 -> 0 | P42: =SUM(P4:P41) -> -1.1934898e-14 | R42: =SUM(R4:R41) -> 1 | S42: =R42-$D42 -> 0 | T42: =SUM(T4:T41) -> 6.7834627e-14 | V42: =SUM(V4:V41) -> 1 | W42: =V42-$D42 -> 0 | X42: =SUM(X4:X41) -> 1.1712853e-14 | Z42: =SUM(Z4:Z41) -> 1 | AA42: =Z42-$D42 -> 0 | AB42: =SUM(AB4:AB41) -> 2.2537527e-14
B44: Total Losses | G44: =SUMIF(H4:H41,"<0") -> -22.19944 | K44: =SUMIF(L4:L41,"<0") -> -8.1746703 | P44: =SUMIF(P4:P41,"<0") -> -16.935703 | S44: =SUMIF(T4:T41,"<0") -> -23.579271 | W44: =SUMIF(X4:X41,"<0") -> -13.340664 | AA44: =SUMIF(AB4:AB41,"<0") -> -18.541714

Sheet Option 1
A1: Option 1 - Outcomes Based Funding (FY 2010 - FY 2012 Averaged) with Total Degrees adjusted by Six-Year Graduation Rate (3-Year Rate for Upper-Levels), Total Degrees per 100 FTSE, Critical Field Degrees (weighted 2), At-Risk Degrees, Retention Metrics of 30, 60, and 90 hours, and Total Degrees adjusted by Cost Based Weights. Funded at 10 percent of undergraduate formula funding.
A3: FICE | B3: Name | C3: Funding | D3: Total Undergraduate Degrees | H3: Undergraduate Critical Field Degrees | I3: Math and Science Teaching Certificates | J3: At-Risk Degrees | K3: Retention Metrics
E4: Adjusted by 6-Year Graduation Rate | F4: per 100 FTSE | G4: Cost Weighted | K4: 30 Hours | L4: 60 Hours | M4: 90 Hours
A5: 3656 | B5: UTA | C5: =C49/$C$87*$C$43 -> 13496783 | D5: =D49/$C$87*$C$43 -> 1841931 | E5: =E49/$C$87*$C$43 -> 954734.24 | F5: =F49/$C$87*$C$43 -> 10866.508 | G5: =G49/$C$87*$C$43 -> 3824283.9 | H5: =H49/$C$87*$C$43 -> 1124197 | I5: =I49/$C$87*$C$43 -> 25694.534 | J5: =J49/$C$87*$C$43 -> 1143773.8 | ... M5: =M49/$C$87*$C$43 -> 654721.19
A6: 3658 | B6: UT | C6: =C50/$C$87*$C$43 -> 25249293 | D6: =D50/$C$87*$C$43 -> 3283883.8 | E6: =E50/$C$87*$C$43 -> 2722339.6 | F6: =F50/$C$87*$C$43 -> 9726.3692 | G6: =G50/$C$87*$C$43 -> 7120450.8 | H6: =H50/$C$87*$C$43 -> 1377471.7 | I6: =I50/$C$87*$C$43 -> 48452.549 | J6: =J50/$C$87*$C$43 -> 1273837.1 | ... M6: =M50/$C$87*$C$43 -> 2584258.3
A7: 9741 | B7: UTD | C7: =C51/$C$87*$C$43 -> 6570818.6 | D7: =D51/$C$87*$C$43 -> 878385.99 | E7: =E51/$C$87*$C$43 -> 617505.35 | F7: =F51/$C$87*$C$43 -> 9848.2598 | G7: =G51/$C$87*$C$43 -> 1872472 | H7: =H51/$C$87*$C$43 -> 309557.95 | I7: =I51/$C$87*$C$43 -> 23492.145 | J7: =J51/$C$87*$C$43 -> 484403.14 | ... M7: =M51/$C$87*$C$43 -> 374895.48
A8: 3661 | B8: UTEP | C8: =C52/$C$87*$C$43 -> 8883399.6 | D8: =D52/$C$87*$C$43 -> 1122117 | E8: =E52/$C$87*$C$43 -> 437625.63 | F8: =F52/$C$87*$C$43 -> 8395.0996 | G8: =G52/$C$87*$C$43 -> 2311802 | H8: =H52/$C$87*$C$43 -> 480854.85 | I8: =I52/$C$87*$C$43 -> 66071.658 | J8: =J52/$C$87*$C$43 -> 904569.94 | ... M8: =M52/$C$87*$C$43 -> 717978.69
A9: 3599 | B9: UTPA | C9: =C53/$C$87*$C$43 -> 7852361.8 | D9: =D53/$C$87*$C$43 -> 947027.1 | E9: =E53/$C$87*$C$43 -> 408168.68 | F9: =F53/$C$87*$C$43 -> 7522.0713 | G9: =G53/$C$87*$C$43 -> 1884571.7 | H9: =H53/$C$87*$C$43 -> 381992.07 | I9: =I53/$C$87*$C$43 -> 20555.627 | J9: =J53/$C$87*$C$43 -> 858319.78 | ... M9: =M53/$C$87*$C$43 -> 711860.94
A10: 30646 | B10: UTB | C10: =C54/$C$87*$C$43 -> 2590654.6 | D10: =D54/$C$87*$C$43 -> 400834.73 | E10: =E54/$C$87*$C$43 -> 230579.41 | F10: =F54/$C$87*$C$43 -> 12649.506 | G10: =G54/$C$87*$C$43 -> 770026.02 | H10: =H54/$C$87*$C$43 -> 91276.772 | I10: =I54/$C$87*$C$43 -> 13459.041 | J10: =J54/$C$87*$C$43 -> 343817.33 | ... M10: =M54/$C$87*$C$43 -> 36951.187
A11: 9930 | B11: UTPB | C11: =C55/$C$87*$C$43 -> 1383139.9 | D11: =D55/$C$87*$C$43 -> 195767.88 | E11: =E55/$C$87*$C$43 -> 86920.937 | F11: =F55/$C$87*$C$43 -> 8488.4369 | G11: =G55/$C$87*$C$43 -> 367621.48 | H11: =H55/$C$87*$C$43 -> 30344.021 | I11: =I55/$C$87*$C$43 -> 7341.2953 | J11: =J55/$C$87*$C$43 -> 146458.84 | ... M11: =M55/$C$87*$C$43 -> 71332.92
A12: 10115 | B12: UTSA | C12: =C56/$C$87*$C$43 -> 11812969 | D12: =D56/$C$87*$C$43 -> 1512184.5 | E12: =E56/$C$87*$C$43 -> 637637.79 | F12: =F56/$C$87*$C$43 -> 7429.7705 | G12: =G56/$C$87*$C$43 -> 3088561.3 | H12: =H56/$C$87*$C$43 -> 287778.78 | I12: =I56/$C$87*$C$43 -> 36461.767 | J12: =J56/$C$87*$C$43 -> 1146588 | ... M12: =M56/$C$87*$C$43 -> 960119.08
A13: 11163 | B13: UTT | C13: =C57/$C$87*$C$43 -> 3168830.6 | D13: =D57/$C$87*$C$43 -> 436807.07 | E13: =E57/$C$87*$C$43 -> 225246.85 | F13: =F57/$C$87*$C$43 -> 10738.752 | G13: =G57/$C$87*$C$43 -> 867249.24 | H13: =H57/$C$87*$C$43 -> 276522.12 | I13: =I57/$C$87*$C$43 -> 10277.813 | J13: =J57/$C$87*$C$43 -> 345897.37 | ... M13: =M57/$C$87*$C$43 -> 142176.42
A14: 3632 | B14: TAMU | C14: =C58/$C$87*$C$43 -> 25542032 | D14: =D58/$C$87*$C$43 -> 3208023.7 | E14: =E58/$C$87*$C$43 -> 2696878.6 | F14: =F58/$C$87*$C$43 -> 9265.4072 | G14: =G58/$C$87*$C$43 -> 7379769.9 | H14: =H58/$C$87*$C$43 -> 1294270.4 | I14: =I58/$C$87*$C$43 -> 92500.321 | J14: =J58/$C$87*$C$43 -> 1366949.2 | ... M14: =M58/$C$87*$C$43 -> 2531890.4
A15: 10298 | B15: TAMUG | C15: =C59/$C$87*$C$43 -> 1408144 | D15: =D59/$C$87*$C$43 -> 151597.75 | E15: =E59/$C$87*$C$43 -> 95102.321 | F15: =F59/$C$87*$C$43 -> 9029.4085 | G15: =G59/$C$87*$C$43 -> 387635.08 | H15: =H59/$C$87*$C$43 -> 41111.254 | I15: =I59/$C$87*$C$43 -> 0 | J15: =J59/$C$87*$C$43 -> 86994.35 | ... M15: =M59/$C$87*$C$43 -> 135446.9
A16: 3630 | B16: Prairie View | C16: =C60/$C$87*$C$43 -> 3149682.8 | D16: =D60/$C$87*$C$43 -> 343694.98 | E16: =E60/$C$87*$C$43 -> 127739.97 | F16: =F60/$C$87*$C$43 -> 5808.3184 | G16: =G60/$C$87*$C$43 -> 760888.56 | H16: =H60/$C$87*$C$43 -> 231740.22 | I16: =I60/$C$87*$C$43 -> 7096.5855 | J16: =J60/$C$87*$C$43 -> 294630.65 | ... M16: =M60/$C$87*$C$43 -> 332315.97
... A42: 20 | B42: SRRG | C42: =C86/$C$87*$C$43 -> 375800.56 | D42: =D86/$C$87*$C$43 -> 59342.137 | E42: =E86/$C$87*$C$43 -> 18854.64 | F42: =F86/$C$87*$C$43 -> 13433.252 | G42: =G86/$C$87*$C$43 -> 102473.47 | H42: =H86/$C$87*$C$43 -> 4649.4871 | I42: =I86/$C$87*$C$43 -> 4160.0674 | J42: =J86/$C$87*$C$43 -> 52857.327 | ... M42: =M86/$C$87*$C$43 -> 1590.614
B43: Total | C43: ='Option 2'!C43 -> 235000000 | D43: =SUM(D5:D42) -> 30999904 | E43: =SUM(E5:E42) -> 18029549 | F43: =SUM(F5:F42) -> 376487.21 | G43: =SUM(G5:G42) -> 63433620 | H43: =SUM(H5:H42) -> 10257258 | I43: =SUM(I5:I42) -> 879731.89 | J43: =SUM(J5:J42) -> 20014390 | K43: =SUM(K5:K42) -> 42032158 | ... M43: =SUM(M5:M42) -> 18692773
C44: 0.1 | D44: Percent of Undergraduate Funding
A45: Points Weighted Three-Year Average
A46: FICE | B46: Name | C46: Total Points | D46: Total Undergraduate Degrees | H46: Undergraduate Critical Field Degrees | I46: Math and Science Teaching Certificates | J46: At-Risk Degrees | K46: Retention Metrics
E47: Adjusted by 6-Year Graduation Rate | F47: per 100 FTSE | G47: Cost Weighted | K47: 30 Hours | L47: 60 Hours | M47: 90 Hours
A48: Weights | D48: 1 | E48: 1 | F48: 1 | G48: 1 | H48: 2 | I48: 2 | J48: 1 | K48: 1 | L48: 1 | M48: 1
A49: =A5 -> 3656 | B49: =B5 -> UTA | C49: =SUM(D49:M49) -> 36769.487 | D49: =D91*D$48 -> 5018 | E49: =D91*E91*E$48 -> 2600.9967 | F49: =IFERROR(D91/F91*100*F$48,0) -> 29.603788 | G49: =G91*G$48 -> 10418.553 | H49: =H91*H$48 -> 3062.6667 | I49: =I91*I$48 -> 70 | J49: =J91*J$48 -> 3116 | K49: =K91*K$48 -> 6836.3333 | L49: =L91*L$48 -> 3833.6667 | M49: =M91*M$48 -> 1783.6667
A50: =A6 -> 3658 | B50: =B6 -> UT | C50: =SUM(D50:M50) -> 68787.025 | D50: =D92*D$48 -> 8946.3333 | E50: =D92*E92*E$48 -> 7416.5103 | F50: =IFERROR(D92/F92*100*F$48,0) -> 26.497692 | G50: =G92*G$48 -> 19398.35 | H50: =H92*H$48 -> 3752.6667 | I50: =I92*I$48 -> 132 | J50: =J92*J$48 -> 3470.3333 | K50: =K92*K$48 -> 9598.3333 | L50: =L92*L$48 -> 9005.6667 | M50: =M92*M$48 -> 7040.3333
A51: =A7 -> 9741 | B51: =B7 -> UTD | C51: =SUM(D51:M51) -> 17900.979 | D51: =D93*D$48 -> 2393 | E51: =D93*E93*E$48 -> 1682.279 | F51: =IFERROR(D93/F93*100*F$48,0) -> 26.829761 | G51: =G93*G$48 -> 5101.2033 | H51: =H93*H$48 -> 843.33333 | I51: =I93*I$48 -> 64 | J51: =J93*J$48 -> 1319.6667 | K51: =K93*K$48 -> 3315 | L51: =L93*L$48 -> 2134.3333 | M51: =M93*M$48 -> 1021.3333
A52: =A8 -> 3661 | B52: =B8 -> UTEP | C52: =SUM(D52:M52) -> 24201.178 | D52: =D94*D$48 -> 3057 | E52: =D94*E94*E$48 -> 1192.23 | F52: =IFERROR(D94/F94*100*F$48,0) -> 22.870895 | G52: =G94*G$48 -> 6298.0767 | H52: =H94*H$48 -> 1310 | I52: =I94*I$48 -> 180 | J52: =J94*J$48 -> 2464.3333 | K52: =K94*K$48 -> 4362.6667 | L52: =L94*L$48 -> 3358 | M52: =M94*M$48 -> 1956
A53: =A9 -> 3599 | B53: =B9 -> UTPA | C53: =SUM(D53:M53) -> 21392.306 | D53: =D95*D$48 -> 2580 | E53: =D95*E95*E$48 -> 1111.98 | F53: =IFERROR(D95/F95*100*F$48,0) -> 20.49249 | G53: =G95*G$48 -> 5134.1667 | H53: =H95*H$48 -> 1040.6667 | I53: =I95*I$48 -> 56 | J53: =J95*J$48 -> 2338.3333 | K53: =K95*K$48 -> 4075.3333 | L53: =L95*L$48 -> 3096 | M53: =M95*M$48 -> 1939.3333
A54: =A10 -> 30646 | B54: =B10 -> UTB | C54: =SUM(D54:M54) -> 7057.7588 | D54: =D96*D$48 -> 1092 | E54: =D96*E96*E$48 -> 628.17092 | F54: =IFERROR(D96/F96*100*F$48,0) -> 34.461236 | G54: =G96*G$48 -> 2097.7933 | H54: =H96*H$48 -> 248.66667 | I54: =I96*I$48 -> 36.666667 | J54: =J96*J$48 -> 936.66667 | K54: =K96*K$48 -> 1326.3333 | L54: =L96*L$48 -> 556.33333 | M54: =M96*M$48 -> 100.66667
A55: =A11 -> 9930 | B55: =B11 -> UTPB | C55: =SUM(D55:M55) -> 3768.1085 | D55: =D97*D$48 -> 533.33333 | E55: =D97*E97*E$48 -> 236.8 | F55: =IFERROR(D97/F97*100*F$48,0) -> 23.125175 | G55: =G97*G$48 -> 1001.5167 | H55: =H97*H$48 -> 82.666667 | I55: =I97*I$48 -> 20 | J55: =J97*J$48 -> 399 | K55: =K97*K$48 -> 785.66667 | L55: =L97*L$48 -> 491.66667 | M55: =M97*M$48 -> 194.33333
A56: =A12 -> 10115 | B56: =B12 -> UTSA | C56: =SUM(D56:M56) -> 32182.247 | D56: =D98*D$48 -> 4119.6667 | E56: =D98*E98*E$48 -> 1737.1261 | F56: =IFERROR(D98/F98*100*F$48,0) -> 20.241034 | G56: =G98*G$48 -> 8414.2133 | H56: =H98*H$48 -> 784 | I56: =I98*I$48 -> 99.333333 | J56: =J98*J$48 -> 3123.6667 | K56: =K98*K$48 -> 6809.6667 | L56: =L98*L$48 -> 4458.6667 | M56: =M98*M$48 -> 2615.6667
A57: =A13 -> 11163 | B57: =B13 -> UTT | C57: =SUM(D57:M57) -> 8632.8924 | D57: =D99*D$48 -> 1190 | E57: =D99*E99*E$48 -> 613.64333 | F57: =IFERROR(D99/F99*100*F$48,0) -> 29.255741 | G57: =G99*G$48 -> 2362.66 | H57: =H99*H$48 -> 753.33333 | I57: =I99*I$48 -> 28 | J57: =J99*J$48 -> 942.33333 | K57: =K99*K$48 -> 1436.3333 | L57: =L99*L$48 -> 890 | M57: =M99*M$48 -> 387.33333
A58: =A14 -> 3632 | B58: =B14 -> TAMU | C58: =SUM(D58:M58) -> 69584.538 | D58: =D100*D$48 -> 8739.6667 | E58: =D100*E100*E$48 -> 7347.1464 | F58: =IFERROR(D100/F100*100*F$48,0) -> 25.241887 | G58: =G100*G$48 -> 20104.817 | H58: =H100*H$48 -> 3526 | I58: =I100*I$48 -> 252 | J58: =J100*J$48 -> 3724 | K58: =K100*K$48 -> 10060.667 | L58: =L100*L$48 -> 8907.3333 | M58: =M100*M$48 -> 6897.6667
A59: =A15 -> 10298 | B59: =B15 -> TAMUG | C59: =SUM(D59:M59) -> 3836.2276 | D59: =D101*D$48*1.5 -> 413 | E59: =D101*E101*E$48*1.5 -> 259.08867 | F59: =IFERROR(D101/F101*100*F$48,0)*1.5 -> 24.598952 | G59: =G101*G$48*1.5 -> 1056.04 | H59: =H101*H$48*1.5 -> 112 | I59: =I101*I$48*1.5 -> 0 | J59: =J101*J$48*1.5 -> 237 | K59: =K101*K$48*1.5 -> 888.5 | L59: =L101*L$48*1.5 -> 477 | M59: =M101*M$48*1.5 -> 369
A60: =A16 -> 3630 | B60: =B16 -> Prairie View | C60: =SUM(D60:M60) -> 8580.7276 | D60: =D102*D$48 -> 936.33333 | E60: =D102*E102*E$48 -> 348.00389 | F60: =IFERROR(D102/F102*100*F$48,0) -> 15.823688 | G60: =G102*G$48 -> 2072.9 | H60: =H102*H$48 -> 631.33333 | I60: =I102*I$48 -> 19.333333 | J60: =J102*J$48 -> 802.66667 | K60: =K102*K$48 -> 1668 | L60: =L102*L$48 -> 1181 | M60: =M102*M$48 -> 905.33333
A61: =A17 -> 3631 | B61: =B17 -> Tarleton | C61: =SUM(D61:M61) -> 11473.106 | D61: =D103*D$48 -> 1545.3333 | E61: =D103*E103*E$48 -> 738.66933 | F61: =IFERROR(D103/F103*100*F$48,0) -> 24.559768 | G61: =G103*G$48 -> 3122.5433 | H61: =H103*H$48 -> 406 | I61: =I103*I$48 -> 95.333333 | J61: =J103*J$48 -> 1195 | K61: =K103*K$48 -> 2154.3333 | L61: =L103*L$48 -> 1328.6667 | M61: =M103*M$48 -> 862.66667
A62: =A18 -> 103631 | B62: =B18 -> TAMUCT | C62: =SUM(D62:M62) -> 2671.9105 | D62: =D104*D$48 -> 460.33333 | E62: =D104*E104*E$48 -> 220.03933 | F62: =IFERROR(D104/F104*100*F$48,0) -> 67.58785 | G62: =G104*G$48 -> 853.61667 | H62: =H104*H$48 -> 81.333333 | I62: =I104*I$48 -> 0 | J62: =J104*J$48 -> 327 | K62: =K104*K$48 -> 495 | L62: =L104*L$48 -> 133 | M62: =M104*M$48 -> 34
A63: =A19 -> 11161 | B63: =B19 -> TAMUCC | C63: =SUM(D63:M63) -> 10983.517 | D63: =D105*D$48 -> 1388.3333 | E63: =D105*E105*E$48 -> 705.27333 | F63: =IFERROR(D105/F105*100*F$48,0) -> 21.376514 | G63: =G105*G$48 -> 2804.2 | H63: =H105*H$48 -> 532.66667 | I63: =I105*I$48 -> 51.333333 | J63: =J105*J$48 -> 1080 | K63: =K105*K$48 -> 2054 | L63: =L105*L$48 -> 1468 | M63: =M105*M$48 -> 878.33333
A64: =A20 -> 3639 | B64: =B20 -> TAMUK | C64: =SUM(D64:M64) -> 6696.7767 | D64: =D106*D$48 -> 761.66667 | E64: =D106*E106*E$48 -> 306.44389 | F64: =IFERROR(D106/F106*100*F$48,0) -> 17.879499 | G64: =G106*G$48 -> 1763.4533 | H64: =H106*H$48 -> 520 | I64: =I106*I$48 -> 33.333333 | J64: =J106*J$48 -> 648.33333 | K64: =K106*K$48 -> 1227.3333 | L64: =L106*L$48 -> 859.66667 | M64: =M106*M$48 -> 558.66667
A65: =A21 -> 103639 | B65: =B21 -> TAMUSA | C65: =SUM(D65:M65) -> 3205.7164 | D65: =D107*D$48 -> 587.66667 | E65: =D107*E107*E$48 -> 236.43789 | F65: =IFERROR(D107/F107*100*F$48,0) -> 41.598502 | G65: =G107*G$48 -> 1026.0133 | H65: =H107*H$48 -> 10 | I65: =I107*I$48 -> 4 | J65: =J107*J$48 -> 490.33333 | K65: =K107*K$48 -> 729.66667 | L65: =L107*L$48 -> 77.333333 | M65: =M107*M$48 -> 2.6666667
A66: =A22 -> 9651 | B66: =B22 -> TAMI | C66: =SUM(D66:M66) -> 6525.9317 | D66: =D108*D$48 -> 789.66667 | E66: =D108*E108*E$48 -> 373.77556 | F66: =IFERROR(D108/F108*100*F$48,0) -> 19.326154 | G66: =G108*G$48 -> 1458.4967 | H66: =H108*H$48 -> 231.33333 | I66: =I108*I$48 -> 44.666667 | J66: =J108*J$48 -> 712.66667 | K66: =K108*K$48 -> 1406.6667 | L66: =L108*L$48 -> 1015.6667 | M66: =M108*M$48 -> 473.66667
...

Sheet Option 2
A1: Option 2 - Outcomes Based Funding (FY 2010 - FY 2012 Averaged) with Total Degrees adjusted by Six-Year Graduation Rate (3-Year Rate for Upper-Levels), Total Degrees per 100 FTSE, Critical Field Degrees (weighted 2), At-Risk Degrees, Retention Metrics of 30, 60, and 90 hours, and Total Degrees adjusted by Cost Based Weights. Metrics scaled for mathematical comparability, weighted by accountability group, and monetized using SREB salaries by Carnegie classifications. Funded at 10 percent of undergraduate formula funding.
A3: FICE | B3: Name | C3: Funding | D3: Total Undergraduate Degrees | H3: Undergraduate Critical Field Degrees | I3: Math and Science Teaching Certificates | J3: At-Risk Degrees | K3: Retention Metrics
E4: Adjusted by 6-Year Graduation Rate | F4: per 100 FTSE | G4: Cost Weighted | K4: 30 Hours | L4: 60 Hours | M4: 90 Hours
A5: 3656 | B5: UTA | C5: =SUM(D5:M5) -> 16151716 | D5: =D48*$O48*$C$44 -> 3405453.2 | E5: =E48*$O48*$C$44 -> 1176773.3 | F5: =F48*$O48*$C$44 -> 669684.58 | G5: =G48*$O48*$C$44 -> 7070525.3 | H5: =H48*$O48*$C$44 -> 1039235.6 | I5: =I48*$O48*$C$44 -> 23752.663 | J5: =J48*$O48*$C$44 -> 338346.5 | K5: =K48*$O48*$C$44 -> 1082540.8 | ... M5: =M48*$O48*$C$44 -> 564891.11
A6: 3658 | B6: UT | C6: =SUM(D6:M6) -> 24480722 | D6: =D49*$O49*$C$44 -> 4047604.6 | E6: =E49*$O49*$C$44 -> 4194330.2 | F6: =F49*$O49*$C$44 -> 749274.7 | G6: =G49*$O49*$C$44 -> 8776428 | H6: =H49*$O49*$C$44 -> 848912.63 | I6: =I49*$O49*$C$44 -> 29860.491 | J6: =J49*$O49*$C$44 -> 251214.2 | K6: =K49*$O49*$C$44 -> 1519906.5 | ... M6: =M49*$O49*$C$44 -> 2229688.9
A7: 9741 | B7: UTD | C7: =SUM(D7:M7) -> 8188074.7 | D7: =D50*$O50*$C$44 -> 1624003.5 | E7: =E50*$O50*$C$44 -> 761116.31 | F7: =F50*$O50*$C$44 -> 606931.67 | G7: =G50*$O50*$C$44 -> 3461919 | H7: =H50*$O50*$C$44 -> 286163.03 | I7: =I50*$O50*$C$44 -> 21716.72 | J7: =J50*$O50*$C$44 -> 143294.16 | K7: =K50*$O50*$C$44 -> 524933.85 | ... M7: =M50*$O50*$C$44 -> 323458.49
A8: 3661 | B8: UTEP | C8: =SUM(D8:M8) -> 7802911.8 | D8: =D51*$O51*$C$44 -> 1591325.2 | E8: =E51*$O51*$C$44 -> 413744.55 | F8: =F51*$O51*$C$44 -> 396849.1 | G8: =G51*$O51*$C$44 -> 3278471.7 | H8: =H51*$O51*$C$44 -> 340961.08 | I8: =I51*$O51*$C$44 -> 46849.613 | J8: =J51*$O51*$C$44 -> 205249.89 | K8: =K51*$O51*$C$44 -> 529898.05 | ... M8: =M51*$O51*$C$44 -> 475159.19
A9: 3599 | B9: UTPA | C9: =SUM(D9:M9) -> 6515985.1 | D9: =D52*$O52*$C$44 -> 1244914.2 | E9: =E52*$O52*$C$44 -> 268279.01 | F9: =F52*$O52*$C$44 -> 247203.42 | G9: =G52*$O52*$C$44 -> 2477363.2 | H9: =H52*$O52*$C$44 -> 251073.79 | I9: =I52*$O52*$C$44 -> 13510.697 | J9: =J52*$O52*$C$44 -> 180528.65 | K9: =K52*$O52*$C$44 -> 655483.26 | ... M9: =M52*$O52*$C$44 -> 530273.41
A10: 30646 | B10: UTB | C10: =SUM(D10:M10) -> 2604754.5 | D10: =D53*$O53*$C$44 -> 526917.18 | E10: =E53*$O53*$C$44 -> 151554.05 | F10: =F53*$O53*$C$44 -> 415710.11 | G10: =G53*$O53*$C$44 -> 1012237.5 | H10: =H53*$O53*$C$44 -> 59993.928 | I10: =I53*$O53*$C$44 -> 8846.2897 | J10: =J53*$O53*$C$44 -> 72314.397 | K10: =K53*$O53*$C$44 -> 213329.62 | ... M10: =M53*$O53*$C$44 -> 27525.364
A11: 9930 | B11: UTPB | C11: =SUM(D11:M11) -> 1414579.3 | D11: =D54*$O54*$C$44 -> 257346.61 | E11: =E54*$O54*$C$44 -> 57130.947 | F11: =F54*$O54*$C$44 -> 278961.81 | G11: =G54*$O54*$C$44 -> 483256.72 | H11: =H54*$O54*$C$44 -> 19944.362 | I11: =I54*$O54*$C$44 -> 4825.2489 | J11: =J54*$O54*$C$44 -> 30804.389 | K11: =K54*$O54*$C$44 -> 126367.91 | ... M11: =M54*$O54*$C$44 -> 53136.713
A12: 10115 | B12: UTSA | C12: =SUM(D12:M12) -> 10127473 | D12: =D55*$O55*$C$44 -> 2144497.7 | E12: =E55*$O55*$C$44 -> 602842.12 | F12: =F55*$O55*$C$44 -> 351216.53 | G12: =G55*$O55*$C$44 -> 4380029.4 | H12: =H55*$O55*$C$44 -> 204056.09 | I12: =I55*$O55*$C$44 -> 25854.046 | J12: =J55*$O55*$C$44 -> 260164.58 | K12: =K55*$O55*$C$44 -> 827115.46 | ... M12: =M55*$O55*$C$44 -> 635408
A13: 11163 | B13: UTT | C13: =SUM(D13:M13) -> 2999494.6 | D13: =D56*$O56*$C$44 -> 574204.62 | E13: =E56*$O56*$C$44 -> 148049.09 | F13: =F56*$O56*$C$44 -> 352915.58 | G13: =G56*$O56*$C$44 -> 1140042.3 | H13: =H56*$O56*$C$44 -> 181751.04 | I13: =I56*$O56*$C$44 -> 6755.3485 | J13: =J56*$O56*$C$44 -> 72751.886 | K13: =K56*$O56*$C$44 -> 231022.2 | ... M13: =M56*$O56*$C$44 -> 105908.85
A14: 3632 | B14: TAMU | C14: =SUM(D14:M14) -> 24634350 | D14: =D57*$O57*$C$44 -> 3954102 | E14: =E57*$O57*$C$44 -> 4155102.2 | F14: =F57*$O57*$C$44 -> 713764.31 | G14: =G57*$O57*$C$44 -> 9096055.9 | H14: =H57*$O57*$C$44 -> 797637.04 | I14: =I57*$O57*$C$44 -> 57006.391 | J14: =J57*$O57*$C$44 -> 269576.89 | K14: =K57*$O57*$C$44 -> 1593117.5 | ... M14: =M57*$O57*$C$44 -> 2184506
A15: 10298 | B15: TAMUG | C15: =SUM(D15:M15) -> 2120436 | D15: =D58*$O58*$C$44 -> 290033.48 | E15: =E58*$O58*$C$44 -> 90973.835 | F15: =F58*$O58*$C$44 -> 431871.64 | G15: =G58*$O58*$C$44 -> 741614.9 | H15: =H58*$O58*$C$44 -> 39326.573 | I15: =I58*$O58*$C$44 -> 0 | J15: =J58*$O58*$C$44 -> 26629.708 | K15: =K58*$O58*$C$44 -> 207986.07 | ... M15: =M58*$O58*$C$44 -> 146842.62
A16: 3630 | B16: Prairie View | C16: =SUM(D16:M16) -> 2708593.8 | D16: =D59*$O59*$C$44 -> 451804.14 | E16: =E59*$O59*$C$44 -> 83960.269 | F16: =F59*$O59*$C$44 -> 190883.08 | G16: =G59*$O59*$C$44 -> 1000225.8 | H16: =H59*$O59*$C$44 -> 152317.02 | I16: =I59*$O59*$C$44 -> 4664.4073 | J16: =J59*$O59*$C$44 -> 61969.063 | K16: =K59*$O59*$C$44 -> 268283.84 | ... M16: =M59*$O59*$C$44 -> 247545.99
... A42: 20 | B42: SRRG | C42: =SUM(D42:M42) -> 746838.14 | D42: =D85*$O85*$C$44 -> 78618.928 | E42: =E85*$O85*$C$44 -> 12489.705 | F42: =F85*$O85*$C$44 -> 444923.26 | G42: =G85*$O85*$C$44 -> 135761.11 | H42: =H85*$O85*$C$44 -> 3079.9168 | I42: =I85*$O85*$C$44 -> 2755.715 | J42: =J85*$O85*$C$44 -> 11204.413 | K42: =K85*$O85*$C$44 -> 37283.203 | ... M42: =M85*$O85*$C$44 -> 1194.1432
B43: Total | C43: =SUM(C5:C42) -> 235000000 | D43: =SUM(D5:D42) -> 45295282 | E43: =SUM(E5:E42) -> 20226054 | F43: =SUM(F5:F42) -> 15241093 | G43: =SUM(G5:G42) -> 92637820 | H43: =SUM(H5:H42) -> 7454821.4 | I43: =SUM(I5:I42) -> 625871.21 | J43: =SUM(J5:J42) -> 4687317.2 | ... M43: =SUM(M5:M42) -> 14870536
C44: =235000000/P86 -> 0.025080188 | D44: Percent Funded
A45: Points Three-Year Average - Scaled and Weighted
A46: FICE | B46: Name | C46: Total Points | D46: Total Undergraduate Degrees | H46: Undergraduate Critical Field Degrees | I46: Math and Science Teaching Certificates | J46: At-Risk Degrees | K46: Retention Metrics | N46: SREB Carnegie 2011-12 Classification | O46: Texas SREB Carnegie Salaries 2011-2012 | P46: Texas SREB Carnegie Salary Times Total Points
E47: Adjusted by 6-Year Graduation Rate | F47: per 100 FTSE | G47: Cost Weighted | K47: 30 Hours | L47: 60 Hours | M47: 90 Hours
A48: =A5 -> 3656 | B48: =B5 -> UTA | C48: =SUM(D48:M48) -> 7139.9579 | D48: =D90*D140 -> 1505.4 | E48: =E90*E140 -> 520.19933 | F48: =F90*F140 -> 296.03788 | G48: =G90*G140 -> 3125.566 | H48: =H90*H140 -> 459.4 | I48: =I90*I140 -> 10.5 | J48: =J90*J140 -> 149.568 | K48: =K90*K140 -> 478.54333 | ... M48: =M90*M140 -> 249.71333 | N48: 1 | O48: 90197.028 | P48: =O48*C48 -> 6.4400298e+08
A49: =A6 -> 3658 | B49: =B6 -> UT | C49: =SUM(D49:M49) -> 10821.843 | D49: =D91*D141 -> 1789.2667 | E49: =E91*E141 -> 1854.1276 | F49: =F91*F141 -> 331.22115 | G49: =G91*G141 -> 3879.67 | H49: =H91*H141 -> 375.26667 | I49: =I91*I141 -> 13.2 | J49: =J91*J141 -> 111.05067 | K49: =K91*K141 -> 671.88333 | ... M49: =M91*M141 -> 985.64667 | N49: 1 | O49: 90197.028 | P49: =O49*C49 -> 9.7609805e+08
A50: =A7 -> 9741 | B50: =B7 -> UTD | C50: =SUM(D50:M50) -> 3619.5851 | D50: =D92*D142 -> 717.9 | E50: =E92*E142 -> 336.4558 | F50: =F92*F142 -> 268.29761 | G50: =G92*G142 -> 1530.361 | H50: =H92*H142 -> 126.5 | I50: =I92*I142 -> 9.6 | J50: =J92*J142 -> 63.344 | K50: =K92*K142 -> 232.05 | ... M50: =M92*M142 -> 142.98667 | N50: 1 | O50: 90197.028 | P50: =O50*C50 -> 3.2647582e+08
A51: =A8 -> 3661 | B51: =B8 -> UTEP | C51: =SUM(D51:M51) -> 4496.9126 | D51: =D93*D143 -> 917.1 | E51: =E93*E143 -> 238.446 | F51: =F93*F143 -> 228.70895 | G51: =G93*G143 -> 1889.423 | H51: =H93*H143 -> 196.5 | I51: =I93*I143 -> 27 | J51: =J93*J143 -> 118.288 | K51: =K93*K143 -> 305.38667 | ... M51: =M93*M143 -> 273.84 | N51: 2 | O51: 69184.924 | P51: =O51*C51 -> 3.1111856e+08
A52: =A9 -> 3599 | B52: =B9 -> UTPA | C52: =SUM(D52:M52) -> 4051.1807 | D52: =D94*D144 -> 774 | E52: =E94*E144 -> 166.797 | F52: =F94*F144 -> 153.69368 | G52: =G94*G144 -> 1540.25 | H52: =H94*H144 -> 156.1 | I52: =I94*I144 -> 8.4 | J52: =J94*J144 -> 112.24 | K52: =K94*K144 -> 407.53333 | ... M52: =M94*M144 -> 329.68667 | N52: 3 | O52: 64130.952 | P52: =O52*C52 -> 2.5980607e+08
A53: =A10 -> 30646 | B53: =B10 -> UTB | C53: =SUM(D53:M53) -> 1619.4529 | D53: =D95*D145 -> 327.6 | E53: =E95*E145 -> 94.225639 | F53: =F95*F145 -> 258.45927 | G53: =G95*G145 -> 629.338 | H53: =H95*H145 -> 37.3 | I53: =I95*I145 -> 5.5 | J53: =J95*J145 -> 44.96 | K53: =K95*K145 -> 132.63333 | ... M53: =M95*M145 -> 17.113333 | N53: 3 | O53: 64130.952 | P53: =O53*C53 -> 1.0385706e+08
A54: =A11 -> 9930 | B54: =B11 -> UTPB | C54: =SUM(D54:M54) -> 879.48581 | D54: =D96*D146 -> 160 | E54: =E96*E146 -> 35.52 | F54: =F96*F146 -> 173.43881 | G54: =G96*G146 -> 300.455 | H54: =H96*H146 -> 12.4 | I54: =I96*I146 -> 3 | J54: =J96*J146 -> 19.152 | K54: =K96*K146 -> 78.566667 | ... M54: =M96*M146 -> 33.036667 | N54: 3 | O54: 64130.952 | P54: =O54*C54 -> 56402262
A55: =A12 -> 10115 | B55: =B12 -> UTSA | C55: =SUM(D55:M55) -> 5836.5856 | D55: =D97*D147 -> 1235.9 | E55: =E97*E147 -> 347.42522 | F55: =F97*F147 -> 202.41034 | G55: =G97*G147 -> 2524.264 | H55: =H97*H147 -> 117.6 | I55: =I97*I147 -> 14.9 | J55: =J97*J147 -> 149.936 | K55: =K97*K147 -> 476.67667 | ... M55: =M97*M147 -> 366.19333 | N55: 2 | O55: 69184.924 | P55: =O55*C55 -> 4.0380373e+08
A56: =A13 -> 11163 | B56: =B13 -> UTT | C56: =SUM(D56:M56) -> 1864.8746 | D56: =D98*D148 -> 357 | E56: =E98*E148 -> 92.0465 | F56: =F98*F148 -> 219.41805 | G56: =G98*G148 -> 708.798 | H56: =H98*H148 -> 113 | I56: =I98*I148 -> 4.2 | J56: =J98*J148 -> 45.232 | K56: =K98*K148 -> 143.63333 | ... M56: =M98*M148 -> 65.846667 | N56: 3 | O56: 64130.952 | P56: =O56*C56 -> 1.1959618e+08
A57: =A14 -> 3632 | B57: =B14 -> TAMU | C57: =SUM(D57:M57) -> 10889.755 | D57: =D99*D149 -> 1747.9333 | E57: =E99*E149 -> 1836.7866 | F57: =F99*F149 -> 315.52358 | G57: =G99*G149 -> 4020.9633 | H57: =H99*H149 -> 352.6 | I57: =I99*I149 -> 25.2 | J57: =J99*J149 -> 119.168 | K57: =K99*K149 -> 704.24667 | ... M57: =M99*M149 -> 965.67333 | N57: 1 | O57: 90197.028 | P57: =O57*C57 -> 9.8222352e+08
A58: =A15 -> 10298 | B58: =B15 -> TAMUG | C58: =SUM(D58:M58) -> 1358.7502 | D58: =D100*D150 -> 185.85 | E58: =E100*E150 -> 58.29495 | F58: =F100*F150 -> 276.73821 | G58: =G100*G150 -> 475.218 | H58: =H100*H150 -> 25.2 | I58: =I100*I150 -> 0 | J58: =J100*J150 -> 17.064 | K58: =K100*K150 -> 133.275 | ... M58: =M100*M150 -> 94.095 | N58: 6 | O58: 62223.55 | P58: =O58*C58 -> 84546259
A59: =A16 -> 3630 | B59: =B16 -> Prairie View | C59: =SUM(D59:M59) -> 1684.0129 | D59: =D101*D151 -> 280.9 | E59: =E101*E151 -> 52.200583 | F59: =F101*F151 -> 118.67766 | G59: =G101*G151 -> 621.87 | H59: =H101*H151 -> 94.7 | I59: =I101*I151 -> 2.9 | J59: =J101*J151 -> 38.528 | K59: =K101*K151 -> 166.8 | ... M59: =M101*M151 -> 153.90667 | N59: 3 | O59: 64130.952 | P59: =O59*C59 -> 1.0799735e+08
... A74: =A31 -> 3594 | B74: =B31 -> UNT | C74: =SUM(D74:M74) -> 8003.7332 | D74: =D116*D166 -> 1805 | E74: =E116*E166 -> 693.52111 | F74: =F116*F166 -> 258.86945 | G74: =G116*G166 -> 3423.466 | H74: =H116*H166 -> 101 | I74: =I116*I166 -> 13 | J74: =J116*J166 -> 183.36 | K74: =K116*K166 -> 550.52667 | ... M74: =M116*M166 -> 467.18 | N74: 1 | O74: 90197.028 | P74: =O74*C74 -> 7.2191295e+08
A75: =A32 -> 113594 | B75: =B32 -> UNTD | C75: =SUM(D75:M75) -> 764.98868 | D75: =D117*D167 -> 121.05 | E75: =E117*E167 -> 34.953187 | F75: =F117*F167 -> 319.8545 | G75: =G117*G167 -> 211.758 | H75: =H117*H167 -> 3.6 | I75: =I117*I167 -> 0 | J75: =J117*J167 -> 14.808 | K75: =K117*K167 -> 47.8 | ... M75: =M117*M167 -> 1.87 | N75: NR | O75: 62223.55 | P75: =O75*C75 -> 47600312
A76: =A33 -> 3624 | B76: =B33 -> SFA | C76: =SUM(D76:M76) -> 2946.7691 | D76: =D118*D168 -> 576.5 | E76: =E118*E168 -> 159.6905 | F76: =F118*F168 -> 151.93158 | G76: =G118*G168 -> 1116.521 | H76: =H118*H168 -> 74.4 | I76: =I118*I168 -> 13.4 | J76: =J118*J168 -> 70.096 | K76: =K118*K168 -> 276.93333 | ... M76: =M118*M168 -> 237.54667 | N76: 3 | O76: 64130.952 | P76: =O76*C76 -> 1.8897911e+08
A77: =A34 -> 3642 | B77: =B34 -> TSU | C77: =SUM(D77:M77) -> 1315.9214 | D77: =D119*D169 -> 227.5 | E77: =E119*E169 -> 16.342083 | F77: =F119*F169 -> 97.002608 | G77: =G119*G169 -> 446.596 | H77: =H119*H169 -> 40.3 | I77: =I119*I169 -> 0.9 | J77: =J119*J169 -> 31.984 | K77: =K119*K169 -> 163.73333 | ... M77: =M119*M169 -> 144.27333 | N77: 3 | O77: 64130.952 | P77: =O77*C77 -> 84391289
A78: =A35 -> 3644 | B78: =B35 -> TTU | C78: =SUM(D78:M78) -> 7185.6807 | D78: =D120*D170 -> 1402.2 | E78: =E120*E170 -> 684.2736 | F78: =F120*F170 -> 210.61243 | G78: =G120*G170 -> 3038.434 | H78: =H120*H170 -> 218.2 | I78: =I120*I170 -> 17.2 | J78: =J120*J170 -> 133.344 | K78: =K120*K170 -> 453.97333 | ... M78: =M120*M170 -> 552.39333 | N78: 1 | O78: 90197.028 | P78: =O78*C78 -> 6.4812704e+08
A79: =A36 -> 3541 | B79: =B36 -> Angelo | C79: =SUM(D79:M79) -> 1622.1399 | D79: =D121*D171 -> 297.4 | E79: =E121*E171 -> 63.891433 | F79: =F121*F171 -> 152.29276 | G79: =G121*G171 -> 593.205 | H79: =H121*H171 -> 76.3 | I79: =I121*I171 -> 5.8 | J79: =J121*J171 -> 34.704 | K79: =K121*K171 -> 143.86667 | ... M79: =M121*M171 -> 120.30333 | N79: 3 | O79: 64130.952 | P79: =O79*C79 -> 1.0402937e+08
A80: =A37 -> 3646 | B80: =B37 -> TWU | C80: =SUM(D80:M80) -> 2665.809 | D80: =D122*D172 -> 541.8 | E80: =E122*E172 -> 141.8613 | F80: =F122*F172 -> 206.59203 | G80: =G122*G172 -> 1035.653 | H80: =H122*H172 -> 170.8 | I80: =I122*I172 -> 9.5 | J80: =J122*J172 -> 59.856 | K80: =K122*K172 -> 219.6 | ... M80: =M122*M172 -> 112.14333 | N80: 2 | O80: 69184.924 | P80: =O80*C80 -> 1.8443379e+08
...

Sheet Option 3
A1: Option 3 - Outcomes Based Funding (FY 2010 - FY 2012 Averaged) with Total Degrees adjusted by Six-Year Graduation Rate (3-Year Rate for Upper-Levels), Total Degrees per 100 FTSE, Critical Field Degrees (weighted 2), At-Risk Degrees, Retention Metrics of 30, 60, and 90 hours, Total Degrees adjusted by Cost Based Weights, and Total Graduate Degrees. Metrics scaled for mathematical comparability, weighted by accountability group, and monetized using SREB salaries by Carnegie classifications. Funded at 10 percent of undergraduate formula funding.
A3: FICE | B3: Name | C3: Funding | D3: Total Undergraduate Degrees | H3: Master's | I3: Doctoral and Professional Practice | J3: Undergraduate Critical Field Degrees | K3: Math and Science Teaching Certificates | L3: At-Risk Degrees | M3: Retention Metrics
E4: Adjusted by 6-Year Graduation Rate | F4: per 100 FTSE | G4: Cost Weighted | M4: 30 Hours | N4: 60 Hours | O4: 90 Hours
A5: 3656 | B5: UTA | C5: =SUM(D5:O5) -> 16277418 | D5: =D48*$Q48*$C$44 -> 2832096.7 | E5: =E48*$Q48*$C$44 -> 880782.09 | F5: =F48*$Q48*$C$44 -> 501240.29 | G5: =G48*$Q48*$C$44 -> 5880101.8 | H5: =H48*$Q48*$C$44 -> 2843384.5 | I5: =I48*$Q48*$C$44 -> 635124.13 | J5: =J48*$Q48*$C$44 -> 864265.47 | K5: =K48*$Q48*$C$44 -> 19753.564 | ... O5: =O48*$Q48*$C$44 -> 402671.71
A6: 3658 | B6: UT | C6: =SUM(D6:O6) -> 27571670 | D6: =D49*$Q49*$C$44 -> 3029519.5 | E6: =E49*$Q49*$C$44 -> 3348628.9 | F6: =F49*$Q49*$C$44 -> 598198.7 | G6: =G49*$Q49*$C$44 -> 6568912.4 | H6: =H49*$Q49*$C$44 -> 3392721.7 | I6: =I49*$Q49*$C$44 -> 6111940.9 | J6: =J49*$Q49*$C$44 -> 635387.51 | K6: =K49*$Q49*$C$44 -> 22349.747 | ... O6: =O49*$Q49*$C$44 -> 1589390.6
A7: 9741 | B7: UTD | C7: =SUM(D7:O7) -> 9536898.7 | D7: =D50*$Q50*$C$44 -> 1350579.4 | E7: =E50*$Q50*$C$44 -> 569674.4 | F7: =F50*$Q50*$C$44 -> 454271.49 | G7: =G50*$Q50*$C$44 -> 2879055.7 | H7: =H50*$Q50*$C$44 -> 2264322.9 | I7: =I50*$Q50*$C$44 -> 824758.34 | J7: =J50*$Q50*$C$44 -> 237983.42 | K7: =K50*$Q50*$C$44 -> 18060.402 | ... O7: =O50*$Q50*$C$44 -> 230571.13
A8: 3661 | B8: UTEP | C8: =SUM(D8:O8) -> 7275836.7 | D8: =D51*$Q51*$C$44 -> 1323403 | E8: =E51*$Q51*$C$44 -> 309676.3 | F8: =F51*$Q51*$C$44 -> 297030.52 | G8: =G51*$Q51*$C$44 -> 2726494.4 | H8: =H51*$Q51*$C$44 -> 892658.47 | I8: =I51*$Q51*$C$44 -> 243583.49 | J8: =J51*$Q51*$C$44 -> 283555.43 | K8: =K51*$Q51*$C$44 -> 38961.815 | ... O8: =O51*$Q51*$C$44 -> 338708.04
A9: 3599 | B9: UTPA | C9: =SUM(D9:O9) -> 5747650.8 | D9: =D52*$Q52*$C$44 -> 1035315.2 | E9: =E52*$Q52*$C$44 -> 178488.34 | F9: =F52*$Q52*$C$44 -> 164466.57 | G9: =G52*$Q52*$C$44 -> 2060263.9 | H9: =H52*$Q52*$C$44 -> 574105.02 | I9: =I52*$Q52*$C$44 -> 39593.45 | J9: =J52*$Q52*$C$44 -> 208801.94 | K9: =K52*$Q52*$C$44 -> 11235.979 | ... O9: =O52*$Q52*$C$44 -> 435806.17
A10: 30646 | B10: UTB | C10: =SUM(D10:O10) -> 2304810.4 | D10: =D53*$Q53*$C$44 -> 438203.18 | E10: =E53*$Q53*$C$44 -> 100830.22 | F10: =F53*$Q53*$C$44 -> 276575.52 | G10: =G53*$Q53*$C$44 -> 841812.92 | H10: =H53*$Q53*$C$44 -> 228286.56 | I10: =I53*$Q53*$C$44 -> 0 | J10: =J53*$Q53*$C$44 -> 49893.097 | K10: =K53*$Q53*$C$44 -> 7356.891 | ... O10: =O53*$Q53*$C$44 -> 24237.612
A11: 9930 | B11: UTPB | C11: =SUM(D11:O11) -> 1296477.8 | D11: =D54*$Q54*$C$44 -> 214018.65 | E11: =E54*$Q54*$C$44 -> 38009.712 | F11: =F54*$Q54*$C$44 -> 185595.7 | G11: =G54*$Q54*$C$44 -> 401893.58 | H11: =H54*$Q54*$C$44 -> 168361.34 | I11: =I54*$Q54*$C$44 -> 0 | J11: =J54*$Q54*$C$44 -> 16586.445 | K11: =K54*$Q54*$C$44 -> 4012.8496 | ... O11: =O54*$Q54*$C$44 -> 46789.827
A12: 10115 | B12: UTSA | C12: =SUM(D12:O12) -> 9065433 | D12: =D55*$Q55*$C$44 -> 1783441 | E12: =E55*$Q55*$C$44 -> 451210.57 | F12: =F55*$Q55*$C$44 -> 262875.81 | G12: =G55*$Q55*$C$44 -> 3642589.1 | H12: =H55*$Q55*$C$44 -> 890926.83 | I12: =I55*$Q55*$C$44 -> 238965.8 | J12: =J55*$Q55*$C$44 -> 169700.35 | K12: =K55*$Q55*$C$44 -> 21501.15 | ... O12: =O55*$Q55*$C$44 -> 452938.31
A13: 11163 | B13: UTT | C13: =SUM(D13:O13) -> 2849082.6 | D13: =D56*$Q56*$C$44 -> 477529.11 | E13: =E56*$Q56*$C$44 -> 98498.337 | F13: =F56*$Q56*$C$44 -> 234797.78 | G13: =G56*$Q56*$C$44 -> 948099.94 | H13: =H56*$Q56*$C$44 -> 423756.92 | I13: =I56*$Q56*$C$44 -> 0 | J13: =J56*$Q56*$C$44 -> 151150.67 | K13: =K56*$Q56*$C$44 -> 5617.9895 | ... O13: =O56*$Q56*$C$44 -> 93258.626
A14: 3632 | B14: TAMU | C14: =SUM(D14:O14) -> 23956476 | D14: =D57*$Q57*$C$44 -> 2959535.5 | E14: =E57*$Q57*$C$44 -> 3317310.4 | F14: =F57*$Q57*$C$44 -> 569848.26 | G14: =G57*$Q57*$C$44 -> 6808145 | H14: =H57*$Q57*$C$44 -> 2403162.2 | I14: =I57*$Q57*$C$44 -> 3384820.3 | J14: =J57*$Q57*$C$44 -> 597009.15 | K14: =K57*$Q57*$C$44 -> 42667.699 | ... O14: =O57*$Q57*$C$44 -> 1557182.9
A15: 10298 | B15: TAMUG | C15: =SUM(D15:O15) -> 1715429.3 | D15: =D58*$Q58*$C$44 -> 241202.22 | E15: =E58*$Q58*$C$44 -> 60525.677 | F15: =F58*$Q58*$C$44 -> 287327.93 | G15: =G58*$Q58*$C$44 -> 616753.49 | H15: =H58*$Q58*$C$44 -> 25697.089 | I15: =I58*$Q58*$C$44 -> 0 | J15: =J58*$Q58*$C$44 -> 32705.386 | K15: =K58*$Q58*$C$44 -> 0 | ... O15: =O58*$Q58*$C$44 -> 129303.08
A16: 3630 | B16: Prairie View | C16: =SUM(D16:O16) -> 2663131.1 | D16: =D59*$Q59*$C$44 -> 375736.49 | E16: =E59*$Q59*$C$44 -> 55859.491 | F16: =F59*$Q59*$C$44 -> 126996.16 | G16: =G59*$Q59*$C$44 -> 831823.6 | H16: =H59*$Q59*$C$44 -> 409578.19 | I16: =I59*$Q59*$C$44 -> 21401.865 | J16: =J59*$Q59*$C$44 -> 126672.29 | K16: =K59*$Q59*$C$44 -> 3879.088 | ... O16: =O59*$Q59*$C$44 -> 217977.99
... A42: 20 | B42: SRRG | C42: =SUM(D42:O42) -> 605978.6 | D42: =D85*$Q85*$C$44 -> 65382.313 | E42: =E85*$Q85*$C$44 -> 8309.5086 | F42: =F85*$Q85*$C$44 -> 296011.28 | G42: =G85*$Q85*$C$44 -> 112903.8 | H42: =H85*$Q85*$C$44 -> 60394.384 | I42: =I85*$Q85*$C$44 -> 0 | J42: =J85*$Q85*$C$44 -> 2561.369 | K42: =K85*$Q85*$C$44 -> 2291.7512 | ... O42: =O85*$Q85*$C$44 -> 1051.5094
B43: Total | C43: =SUM(C5:C42) -> 2.35e+08 | D43: =SUM(D5:D42) -> 37003726 | E43: =SUM(E5:E42) -> 15266142 | F43: =SUM(F5:F42) -> 10663025 | G43: =SUM(G5:G42) -> 75554586 | H43: =SUM(H5:H42) -> 31176688 | I43: =SUM(I5:I42) -> 20505212 | J43: =SUM(J5:J42) -> 6062763.3 | ... O43: =SUM(O5:O42) -> 11216073
C44: =235000000/R86 -> 0.025029098 | D44: Percent Funded
A45: Points Three-Year Average - Scaled and Weighted
A46: FICE | B46: Name | C46: Total Points | D46: Total Undergraduate Degrees | H46: =H3 -> Master's | I46: =I3 -> Doctoral and Professional Practice | J46: Undergraduate Critical Field Degrees | K46: Math and Science Teaching Certificates | L46: At-Risk Degrees | M46: Retention Metrics | P46: SREB Carnegie 2011-12 Classification | Q46: Texas SREB Carnegie Salaries 2011-2012 | R46: Texas SREB Carnegie Salary Times Total Points
E47: Adjusted by 6-Year Graduation Rate | F47: per 100 FTSE | G47: Cost Weighted | M47: 30 Hours | N47: 60 Hours | O47: 90 Hours
A48: =A5 -> 3656 | B48: =B5 -> UTA | C48: =SUM(D48:O48) -> 7210.2129 | D48: =D90*D140 -> 1254.5 | E48: =E90*E140 -> 390.1495 | F48: =F90*F140 -> 222.02841 | G48: =G90*G140 -> 2604.6383 | H48: =H90*H140 -> 1259.5 | I48: =I90*I140 -> 281.33333 | J48: =J90*J140 -> 382.83333 | K48: =K90*K140 -> 8.75 | ... O48: =O90*O140 -> 178.36667 | P48: 1 | Q48: 90197.028 | R48: =Q48*C48 -> 6.5033977e+08
A49: =A6 -> 3658 | B49: =B6 -> UT | C49: =SUM(D49:O49) -> 12213.093 | D49: =D91*D141 -> 1341.95 | E49: =E91*E141 -> 1483.3021 | F49: =F91*F141 -> 264.97692 | G49: =G91*G141 -> 2909.7525 | H49: =H91*H141 -> 1502.8333 | I49: =I91*I141 -> 2707.3333 | J49: =J91*J141 -> 281.45 | K49: =K91*K141 -> 9.9 | ... O49: =O91*O141 -> 704.03333 | P49: 1 | Q49: 90197.028 | R49: =Q49*C49 -> 1.1015847e+09
A50: =A7 -> 9741 | B50: =B7 -> UTD | C50: =SUM(D50:O50) -> 4224.4459 | D50: =D92*D142 -> 598.25 | E50: =E92*E142 -> 252.34185 | F50: =F92*F142 -> 201.2232 | G50: =G92*G142 -> 1275.3008 | H50: =H92*H142 -> 1003 | I50: =I92*I142 -> 365.33333 | J50: =J92*J142 -> 105.41667 | K50: =K92*K142 -> 8 | ... O50: =O92*O142 -> 102.13333 | P50: 1 | Q50: 90197.028 | R50: =Q50*C50 -> 3.8103246e+08
A51: =A8 -> 3661 | B51: =B8 -> UTEP | C51: =SUM(D51:O51) -> 4201.712 | D51: =D93*D143 -> 764.25 | E51: =E93*E143 -> 178.8345 | F51: =F93*F143 -> 171.53171 | G51: =G93*G143 -> 1574.5192 | H51: =H93*H143 -> 515.5 | I51: =I93*I143 -> 140.66667 | J51: =J93*J143 -> 163.75 | K51: =K93*K143 -> 22.5 | ... O51: =O93*O143 -> 195.6 | P51: 2 | Q51: 69184.924 | R51: =Q51*C51 -> 2.9069513e+08
A52: =A9 -> 3599 | B52: =B9 -> UTPA | C52: =SUM(D52:O52) -> 3580.7788 | D52: =D94*D144 -> 645 | E52: =E94*E144 -> 111.198 | F52: =F94*F144 -> 102.46245 | G52: =G94*G144 -> 1283.5417 | H52: =H94*H144 -> 357.66667 | I52: =I94*I144 -> 24.666667 | J52: =J94*J144 -> 130.08333 | K52: =K94*K144 -> 7 | ... O52: =O94*O144 -> 271.50667 | P52: 3 | Q52: 64130.952 | R52: =Q52*C52 -> 2.2963875e+08
A53: =A10 -> 30646 | B53: =B10 -> UTB | C53: =SUM(D53:O53) -> 1435.8938 | D53: =D95*D145 -> 273 | E53: =E95*E145 -> 62.817092 | F53: =F95*F145 -> 172.30618 | G53: =G95*G145 -> 524.44833 | H53: =H95*H145 -> 142.22222 | I53: =I95*I145 -> 0 | J53: =J95*J145 -> 31.083333 | K53: =K95*K145 -> 4.5833333 | ... O53: =O95*O145 -> 15.1 | P53: 3 | Q53: 64130.952 | R53: =Q53*C53 -> 92085238
A54: =A11 -> 9930 | B54: =B11 -> UTPB | C54: =SUM(D54:O54) -> 807.70393 | D54: =D96*D146 -> 133.33333 | E54: =E96*E146 -> 23.68 | F54: =F96*F146 -> 115.62587 | G54: =G96*G146 -> 250.37917 | H54: =H96*H146 -> 104.88889 | I54: =I96*I146 -> 0 | J54: =J96*J146 -> 10.333333 | K54: =K96*K146 -> 2.5 | ... O54: =O96*O146 -> 29.15 | P54: 3 | Q54: 64130.952 | R54: =Q54*C54 -> 51798822
A55: =A12 -> 10115 | B55: =B12 -> UTSA | C55: =SUM(D55:O55) -> 5235.1833 | D55: =D97*D147 -> 1029.9167 | E55: =E97*E147 -> 260.56892 | F55: =F97*F147 -> 151.80776 | G55: =G97*G147 -> 2103.5533 | H55: =H97*H147 -> 514.5 | I55: =I97*I147 -> 138 | J55: =J97*J147 -> 98 | K55: =K97*K147 -> 12.416667 | ... O55: =O97*O147 -> 261.56667 | P55: 2 | Q55: 69184.924 | R55: =Q55*C55 -> 3.6219576e+08
A56: =A13 -> 11163 | B56: =B13 -> UTT | C56: =SUM(D56:O56) -> 1774.9747 | D56: =D98*D148 -> 297.5 | E56: =E98*E148 -> 61.364333 | F56: =F98*F148 -> 146.2787 | G56: =G98*G148 -> 590.665 | H56: =H98*H148 -> 264 | I56: =I98*I148 -> 0 | J56: =J98*J148 -> 94.166667 | K56: =K98*K148 -> 3.5 | ... O56: =O98*O148 -> 58.1 | P56: 3 | Q56: 64130.952 | R56: =Q56*C56 -> 1.1383082e+08
A57: =A14 -> 3632 | B57: =B14 -> TAMU | C57: =SUM(D57:O57) -> 10611.713 | D57: =D99*D149 -> 1310.95 | E57: =E99*E149 -> 1469.4293 | F57: =F99*F149 -> 252.41887 | G57: =G99*G149 -> 3015.7225 | H57: =H99*H149 -> 1064.5 | I57: =I99*I149 -> 1499.3333 | J57: =J99*J149 -> 264.45 | K57: =K99*K149 -> 18.9 | ... O57: =O99*O149 -> 689.76667 | P57: 1 | Q57: 90197.028 | R57: =Q57*C57 -> 9.57145e+08
A58: =A15 -> 10298 | B58: =B15 -> TAMUG | C58: =SUM(D58:O58) -> 1101.4704 | D58: =D100*D150 -> 154.875 | E58: =E100*E150 -> 38.8633 | F58: =F100*F150 -> 184.49214 | G58: =G100*G150 -> 396.015 | H58: =H100*H150 -> 16.5 | I58: =I100*I150 -> 0 | J58: =J100*J150 -> 21 | K58: =K100*K150 -> 0 | ... O58: =O100*O150 -> 83.025 | P58: 6 | Q58: 62223.55 | R58: =Q58*C58 -> 68537401
A59: =A16 -> 3630 | B59: =B16 -> Prairie View | C59: =SUM(D59:O59) -> 1659.1272 | D59: =D101*D151 -> 234.08333 | E59: =E101*E151 -> 34.800389 | F59: =F101*F151 -> 79.11844 | G59: =G101*G151 -> 518.225 | H59: =H101*H151 -> 255.16667 | I59: =I101*I151 -> 13.333333 | J59: =J101*J151 -> 78.916667 | K59: =K101*K151 -> 2.4166667 | ... O59: =O101*O151 -> 135.8 | P59: 3 | Q59: 64130.952 | R59: =Q59*C59 -> 1.064014e+08
... A74: =A31 -> 3594 | B74: =B31 -> UNT | C74: =SUM(D74:O74) -> 7675.8079 | D74: =D116*D166 -> 1504.1667 | E74: =E116*E166 -> 520.14083 | F74: =F116*F166 -> 194.15208 | G74: =G116*G166 -> 2852.8883 | H74: =H116*H166 -> 915.16667 | I74: =I116*I166 -> 454.66667 | J74: =J116*J166 -> 84.166667 | K74: =K116*K166 -> 10.833333 | ... O74: =O116*O166 -> 333.7 | P74: 1 | Q74: 90197.028 | R74: =Q74*C74 -> 6.9233506e+08
A75: =A32 -> 113594 | B75: =B32 -> UNTD | C75: =SUM(D75:O75) -> 577.68846 | D75: =D117*D167 -> 100.875 | E75: =E117*E167 -> 23.302125 | F75: =F117*F167 -> 213.23633 | G75: =G117*G167 -> 176.465 | H75: =H117*H167 -> 0 | I75: =I117*I167 -> 0 | J75: =J117*J167 -> 3 | K75: =K117*K167 -> 0 | ... O75: =O117*O167 -> 1.65 | P75: NR | Q75: 62223.55 | R75: =Q75*C75 -> 35945827
A76: =A33 -> 3624 | B76: =B33 -> SFA | C76: =SUM(D76:O76) -> 2662.6589 | D76: =D118*D168 -> 480.41667 | E76: =E118*E168 -> 106.46033 | F76: =F118*F168 -> 101.28772 | G76: =G118*G168 -> 930.43417 | H76: =H118*H168 -> 219.33333 | I76: =I118*I168 -> 13 | J76: =J118*J168 -> 62 | K76: =K118*K168 -> 11.166667 | ... O76: =O118*O168 -> 209.6 | P76: 3 | Q76: 64130.952 | R76: =Q76*C76 -> 1.7075885e+08
A77: =A34 -> 3642 | B77: =B34 -> TSU | C77: =SUM(D77:O77) -> 1717.9831 | D77: =D119*D169 -> 189.58333 | E77: =E119*E169 -> 10.894722 | F77: =F119*F169 -> 64.668405 | G77: =G119*G169 -> 372.16333 | H77: =H119*H169 -> 116.66667 | I77: =I119*I169 -> 572.66667 | J77: =J119*J169 -> 33.583333 | K77: =K119*K169 -> 0.75 | ... O77: =O119*O169 -> 118.81333 | P77: 3 | Q77: 64130.952 | R77: =Q77*C77 -> 1.1017589e+08
A78: =A35 -> 3644 | B78: =B35 -> TTU | C78: =SUM(D78:O78) -> 7261.4929 | D78: =D120*D170 -> 1168.5 | E78: =E120*E170 -> 513.2052 | F78: =F120*F170 -> 157.95932 | G78: =G120*G170 -> 2532.0283 | H78: =H120*H170 -> 687.83333 | I78: =I120*I170 -> 924 | J78: =J120*J170 -> 181.83333 | K78: =K120*K170 -> 14.333333 | ... O78: =O120*O170 -> 394.56667 | P78: 1 | Q78: 90197.028 | R78: =Q78*C78 -> 6.5496507e+08
A79: =A36 -> 3541 | B79: =B36 -> Angelo | C79: =SUM(D79:O79) -> 1461.1358 | D79: =D121*D171 -> 247.83333 | E79: =E121*E171 -> 42.594289 | F79: =F121*F171 -> 101.5285 | G79: =G121*G171 -> 494.3375 | H79: =H121*H171 -> 132.22222 | I79: =I121*I171 -> 0 | J79: =J121*J171 -> 63.583333 | K79: =K121*K171 -> 4.8333333 | ... O79: =O121*O171 -> 106.15 | P79: 3 | Q79: 64130.952 | R79: =Q79*C79 -> 93704033
A80: =A37 -> 3646 | B80: =B37 -> TWU | C80: =SUM(D80:O80) -> 3304.3231 | D80: =D122*D172 -> 451.5 | E80: =E122*E172 -> 94.5742 | F80: =F122*F172 -> 137.72802 | G80: =G122*G172 -> 863.04417 | H80: =H122*H172 -> 764 | I80: =I122*I172 -> 440 | J80: =J122*J172 -> 142.33333 | K80: =K122*K172 -> 7.9166667 | ... O80: =O122*O172 -> 92.353333 | P80: 2 | Q80: 69184.924 | R80: =Q80*C80 -> 2.2860934e+08
...

Sheet Option 4
A1: Option 4 - Outcomes Based Funding (FY 2010 - FY 2012 Averaged) with Total Degrees adjusted by Six-Year Graduation Rate (3-Year Rate for Upper-Levels), Total Degrees per 100 FTSE, Critical Field Degrees (weighted 2), At-Risk Degrees, Retention Metrics of 30, 60, and 90 hours, and Total Degrees adjusted by Cost Based Weights. Metrics scaled for mathematical comparability, weighted by Carnegie classifications, and monetized using SREB salaries by Carnegie classifications. Funded at 10 percent of undergraduate formula funding.
A3: FICE | B3: Name | C3: Funding | D3: Total Undergraduate Degrees | H3: Undergraduate Critical Field Degrees | I3: Math and Science Teaching Certificates | J3: At-Risk Degrees | K3: Retention Metrics
E4: Adjusted by 6-Year Graduation Rate | F4: per 100 FTSE | G4: Cost Weighted | K4: 30 Hours | L4: 60 Hours | M4: 90 Hours
A5: 3656 | B5: UTA | C5: =SUM(D5:M5) -> 13477985 | D5: =D48*$O48*$C$44 -> 2418093.4 | E5: =E48*$O48*$C$44 -> 1566723 | F5: =F48*$O48*$C$44 -> 891599.31 | G5: =G48*$O48*$C$44 -> 5020533.1 | H5: =H48*$O48*$C$44 -> 737924.88 | I5: =I48*$O48*$C$44 -> 16865.936 | J5: =J48*$O48*$C$44 -> 240248.04 | K5: =K48*$O48*$C$44 -> 1153011.6 | ... M5: =M48*$O48*$C$44 -> 601664.17
A6: 3658 | B6: UT | C6: =SUM(D6:M6) -> 26074359 | D6: =D49*$O49*$C$44 -> 4311094 | E6: =E49*$O49*$C$44 -> 4467371.1 | F6: =F49*$O49*$C$44 -> 798050.7 | G6: =G49*$O49*$C$44 -> 9347752.5 | H6: =H49*$O49*$C$44 -> 904174.82 | I6: =I49*$O49*$C$44 -> 31804.337 | J6: =J49*$O49*$C$44 -> 267567.64 | K6: =K49*$O49*$C$44 -> 1618848.8 | ... M6: =M49*$O49*$C$44 -> 2374836.3
A7: 9741 | B7: UTD | C7: =SUM(D7:M7) -> 7119525.6 | D7: =D50*$O50*$C$44 -> 1153148.2 | E7: =E50*$O50*$C$44 -> 1013329 | F7: =F50*$O50*$C$44 -> 808051.85 | G7: =G50*$O50*$C$44 -> 2458187.8 | H7: =H50*$O50*$C$44 -> 203194.38 | I7: =I50*$O50*$C$44 -> 15420.285 | J7: =J50*$O50*$C$44 -> 101748.18 | K7: =K50*$O50*$C$44 -> 559105.79 | ... M7: =M50*$O50*$C$44 -> 344514.86
A8: 3661 | B8: UTEP | C8: =SUM(D8:M8) -> 8310862.7 | D8: =D51*$O51*$C$44 -> 1694916.7 | E8: =E51*$O51*$C$44 -> 440678.34 | F8: =F51*$O51*$C$44 -> 422683.03 | G8: =G51*$O51*$C$44 -> 3491892.4 | H8: =H51*$O51*$C$44 -> 363156.83 | I8: =I51*$O51*$C$44 -> 49899.412 | J8: =J51*$O51*$C$44 -> 218611.17 | K8: =K51*$O51*$C$44 -> 564393.15 | ... M8: =M51*$O51*$C$44 -> 506090.92
A9: 3599 | B9: UTPA | C9: =SUM(D9:M9) -> 6940160.2 | D9: =D52*$O52*$C$44 -> 1325955.2 | E9: =E52*$O52*$C$44 -> 285743.34 | F9: =F52*$O52*$C$44 -> 263295.77 | G9: =G52*$O52*$C$44 -> 2638633.7 | H9: =H52*$O52*$C$44 -> 267418.09 | I9: =I52*$O52*$C$44 -> 14390.211 | J9: =J52*$O52*$C$44 -> 192280.63 | K9: =K52*$O52*$C$44 -> 698153.66 | ... M9: =M52*$O52*$C$44 -> 564792.95
A10: 30646 | B10: UTB | C10: =SUM(D10:M10) -> 2774317.8 | D10: =D53*$O53*$C$44 -> 561218.23 | E10: =E53*$O53*$C$44 -> 161419.86 | F10: =F53*$O53*$C$44 -> 442771.85 | G10: =G53*$O53*$C$44 -> 1078131.8 | H10: =H53*$O53*$C$44 -> 63899.39 | I10: =I53*$O53*$C$44 -> 9422.1621 | J10: =J53*$O53*$C$44 -> 77021.892 | K10: =K53*$O53*$C$44 -> 227216.87 | ... M10: =M53*$O53*$C$44 -> 29317.2
A11: 9930 | B11: UTPB | C11: =SUM(D11:M11) -> 1506665.1 | D11: =D54*$O54*$C$44 -> 274099.26 | E11: =E54*$O54*$C$44 -> 60850.036 | F11: =F54*$O54*$C$44 -> 297121.56 | G11: =G54*$O54*$C$44 -> 514715.58 | H11: =H54*$O54*$C$44 -> 21242.693 | I11: =I54*$O54*$C$44 -> 5139.3611 | J11: =J54*$O54*$C$44 -> 32809.681 | K11: =K54*$O54*$C$44 -> 134594.16 | ... M11: =M54*$O54*$C$44 -> 56595.787
A12: 10115 | B12: UTSA | C12: =SUM(D12:M12) -> 10786748 | D12: =D55*$O55*$C$44 -> 2284099.4 | E12: =E55*$O55*$C$44 -> 642085.71 | F12: =F55*$O55*$C$44 -> 374079.89 | G12: =G55*$O55*$C$44 -> 4665158.8 | H12: =H55*$O55*$C$44 -> 217339.66 | I12: =I55*$O55*$C$44 -> 27537.083 | J12: =J55*$O55*$C$44 -> 277100.67 | K12: =K55*$O55*$C$44 -> 880958.71 | ... M12: =M55*$O55*$C$44 -> 676771.55
A13: 11163 | B13: UTT | C13: =SUM(D13:M13) -> 3194754.6 | D13: =D56*$O56*$C$44 -> 611583.97 | E13: =E56*$O56*$C$44 -> 157686.73 | F13: =F56*$O56*$C$44 -> 375889.54 | G13: =G56*$O56*$C$44 -> 1214256.3 | H13: =H56*$O56*$C$44 -> 193582.6 | I13: =I56*$O56*$C$44 -> 7195.1056 | J13: =J56*$O56*$C$44 -> 77487.861 | K13: =K56*$O56*$C$44 -> 246061.19 | ... M13: =M56*$O56*$C$44 -> 112803.27
A14: 3632 | B14: TAMU | C14: =SUM(D14:M14) -> 26237988 | D14: =D57*$O57*$C$44 -> 4211504.6 | E14: =E57*$O57*$C$44 -> 4425589.5 | F14: =F57*$O57*$C$44 -> 760228.67 | G14: =G57*$O57*$C$44 -> 9688187.4 | H14: =H57*$O57*$C$44 -> 849561.31 | I14: =I57*$O57*$C$44 -> 60717.371 | J14: =J57*$O57*$C$44 -> 287125.7 | K14: =K57*$O57*$C$44 -> 1696825.6 | ... M14: =M57*$O57*$C$44 -> 2326712.2
A15: 10298 | B15: TAMUG | C15: =SUM(D15:M15) -> 2469427.3 | D15: =D58*$O58*$C$44 -> 360399.63 | E15: =E58*$O58*$C$44 -> 51677.874 | F15: =F58*$O58*$C$44 -> 521316.85 | G15: =G58*$O58*$C$44 -> 921540.98 | H15: =H58*$O58*$C$44 -> 48867.746 | I15: =I58*$O58*$C$44 -> 0 | J15: =J58*$O58*$C$44 -> 33090.445 | K15: =K58*$O58*$C$44 -> 221525.47 | ... M15: =M58*$O58*$C$44 -> 156401.72
