Workbook
Name IBreakfast: 'Travel Form'!$E$64
Name IDinner: 'Travel Form'!$E$66
Name ILunch: 'Travel Form'!$E$65
Name In_State: Codes!$B$6:$B$9
Name IOCells: 'Travel Form'!$Q$50:$Q$60,'Travel Form'!$Q$72:$Q$124
Name IOList: Macros!$B$17:$B$19
Name OBreakfast: 'Travel Form'!$F$64
Name ODinner: 'Travel Form'!$F$66
Name OLunch: 'Travel Form'!$F$65
Name OUT_OF_COUNTRY: Codes!#REF!
Name OUT_OF_STATE: Codes!$B$10:$B$15
Name rate: 0.22
Name TRAVEL: 'Travel Form'!$J$134:$K$217
Name TYPE: 'Travel Form'!$C$134:$C$134

Sheet Travel Form
A1: NORTH CAROLINA CENTRAL UNIVERSITY
A3: Request For Reimbursement Of Travel And Other Expenses
A4: Incurred In The Discharge Of Official Duty - Including Per Diem
A8: INSTRUCTIONS TO CLAIMANT: Prepare two (2) copies. Attach all necessary receipts and other supporting documents
A9: to this form and submit the original and one (1) copy to the Travel Office.
A11: Payee's Name | J11: Banner ID | O11: Date of this Request
A14: Payee's Address | J14: Period Covered by this Voucher (from/to, date and time left and returned)
A17: Department | J17: Title | R17: Campus Phone
A21: Account Number | R21: Controller's
E22: IN STATE | G22: OUT OF STATE | O22: Amount | R22: use only
A24: Air Transportation | E24: =VLOOKUP(CONCATENATE($E$22," ",$A24),Codes!B19:'Codes'!C83,2,) -> 731111 | F24: =H129 -> 0 | G24: =VLOOKUP(CONCATENATE($G$22," ",$A24),Codes!$B$19:'Codes'!$C$83,2,) -> 731211 | H24: =J129 -> 0 | J24: Total Expense | O24: =F32+H32 -> 0 | R24: $
A25: Ground Transportation | E25: =VLOOKUP(CONCATENATE($E$22," ",$A25),Codes!B20:'Codes'!C84,2,) -> 731121 | F25: =H128 -> 0 | G25: =VLOOKUP(CONCATENATE($G$22," ",$A25),Codes!$B$19:'Codes'!$C$83,2,) -> 731221 | H25: =J128 -> 0 | J25: Deduct: Advance | O25: 0
A26: Hotel | E26: =VLOOKUP(CONCATENATE($E$22," ",$A26),Codes!B22:'Codes'!C86,2,) -> 731141 | F26: =N$129 -> 0 | G26: =VLOOKUP(CONCATENATE($G$22," ",$A26),Codes!$B$19:'Codes'!$C$83,2,) -> 731241 | H26: =O$129 -> 0 | J26: Deduct: | O26: 0
A27: Meals | E27: =VLOOKUP(CONCATENATE($E$22," ",$A27),Codes!B23:'Codes'!C87,2,) -> 731151 | F27: =N$128 -> 0 | G27: =VLOOKUP(CONCATENATE($G$22," ",$A27),Codes!$B$19:'Codes'!$C$83,2,) -> 731251 | H27: =O$128 -> 0 | J27: Amount Due NCCU | O27: =IF(O24-O25-O26<0,O24-O25-O26,0) -> 0
A28: Other Travel Expense | E28: =VLOOKUP(CONCATENATE($E$22," ",$A28),Codes!B24:'Codes'!C88,2,) -> 731160 | F28: =S$128 -> 0 | G28: =VLOOKUP(CONCATENATE($G$22," ",$A28),Codes!$B$19:'Codes'!$C$83,2,) -> 731260 | H28: =S$129 -> 0 | J28: Amount Due Claimant | O28: =IF(O24-O25-O26>0,O24-O25-O26,0) -> 0
A29: Registration | E29: =VLOOKUP(CONCATENATE($E$22," ",$A29),Codes!B26:'Codes'!C90,2,) -> 731190 | F29: =H$46 -> 0 | G29: =VLOOKUP(CONCATENATE($G$22," ",$A29),Codes!$B$19:'Codes'!$C$83,2,) -> 731290 | H29: =J$46 -> 0
A32: Total Expense | F32: =SUM(F24:F29) -> 0 | H32: =SUM(H24:H29) -> 0 | J32: Amount subject to Federal and
A33: =" "& E22 &" and " & G22 -> IN STATE and OUT OF STATE | J33: State Income Tax Law
A35: Under penalties of perjury, I certify this is a true and accurate | J35: I have examined this reimbursement request and certify
A36: statement of the lodging expenses and allowances incurred in | J36: that it is just and reasonable.
A37: the service of the State.
A39: =IF(SUM(S50:S60,S72:S124)=S130,"","WARNING! Some Other Expenses items have not been designated as In-State or Out-Of-State.")
A40: (Claimant) | J40: (Supervisor) | Q40: Bud Auth Code
A42: Date | B42: Registration | H42: In-State | J42: Out-of-State
A46: Total | H46: =SUM(H43:H45) -> 0 | J46: =SUM(J43:J45) -> 0
B48: Travel (show each city visited) | G48: Transportation | M48: Subsistence | Q48: Other Expenses
A49: Date | B49: From/To: | H49: In-State | J49: Out-of-State | N49: In-State | O49: Out-of-State | Q49: I/O | R49: Explain | S49: Amount
G50: R | M50: B | O50: 0
G51: A | J51: 0 | M51: L | O51: 0
G52: O | M52: D | O52: 0
B53: Departed | G53: P | H53: =$D54*Codes!$H$2 -> 0 | J53: =$D55*Codes!$H$4 -> 0 | M53: H | O53: 0
A54: Daily Priv Car Mileage | D54: 0 | E54: ="miles @ "&TEXT(Codes!H$2,"$0.00")&"/mile for In-State miles" -> miles @ $0.30/mile for In-State miles | M54: Total | N54: =SUM(N50:N53) -> 0 | O54: =SUM(O50:O53) -> 0
A55: Daily Priv Car Mileage | E55: ="miles @ "&TEXT(Codes!H$4,"$0.00")&"/mile for Out-of-State miles" -> miles @ $0.30/mile for Out-of-State miles
G56: R | M56: B | O56: 0 | S56: 0
G57: A | M57: L | O57: 0
G58: O | M58: D | O58: 0
G59: P | H59: =$D60*Codes!$H$2 -> 0 | J59: =$D61*Codes!$H$4 -> 0 | M59: H | O59: 0
A60: Daily Priv Car Mileage | E60: ="miles @ "&TEXT(Codes!H$2,"$0.00")&"/mile for In-State miles" -> miles @ $0.30/mile for In-State miles | M60: Total | N60: =SUM(N56:N59) -> 0 | O60: =SUM(O56:O59) -> 0
A61: Daily Priv Car Mileage | E61: ="miles @ "&TEXT(Codes!H$4,"$0.00")&"/mile for Out-of-State miles" -> miles @ $0.30/mile for Out-of-State miles | N61: Total | O61: Total | S61: Sutotal
A62: Mode of Travel | D62: Type of Subsistence | H62: Total | J62: Total | N62: Authorized | O62: Authorized | S62: Other
...

Sheet Codes
G2: ="In State Mileage Rate per Mile" &" " -> In State Mileage Rate per Mile | H2: 0.3
G4: ="Out of State Mileage Rate per Mile" & " " -> Out of State Mileage Rate per Mile | H4: 0.3
B6: IN STATE
B7: C&G IN STATE | E7: Breakfast | F7: 8.2 | G7: 8.2
B8: BRD/NONEMP | E8: Lunch | F8: 10.7 | G8: 10.7
B9: C&G BRD/NONEMP | E9: Dinner | F9: 18.4 | G9: 20.9
B10: OUT OF STATE
B11: C&G OUT OF STATE
B12: BRD/NONEMP
B13: C&G BRD/NONEMP
B14: OUT OF COUNTRY
B15: C&G OUT OF COUNTRY
B19: IN STATE Air Transportation | C19: 731111
B20: IN STATE Ground Transportation | C20: 731121
B21: IN STATE Transportation Other | C21: 731130
B22: IN STATE Hotel | C22: 731141
B23: IN STATE Meals | C23: 731151
B24: IN STATE Other Travel Expense | C24: 731160
B25: IN STATE Trans Ground Motor Fleet | C25: 731170
B26: IN STATE Registration | C26: 731190
B27: OUT OF STATE Air Transportation | C27: 731211
B28: OUT OF STATE Ground Transportation | C28: 731221
B29: OUT OF STATE Transportation Other | C29: 731230
B30: OUT OF STATE Hotel | C30: 731241
... B32: OUT OF STATE Other Travel Expense | C32: 731260
B33: OUT OF STATE Trans Ground Motor Fleet | C33: N/A
B34: OUT OF STATE Registration | C34: 731290
B35: OUT OF COUNTRY Air Transportation | C35: 731311
B36: OUT OF COUNTRY Ground Transportation | C36: 731320
B37: OUT OF COUNTRY Transportation Other | C37: 731330
B38: OUT OF COUNTRY Hotel | C38: 731341
B39: OUT OF COUNTRY Meals | C39: 731351
B40: OUT OF COUNTRY Other Travel Expense | C40: 731360
B41: OUT OF COUNTRY Registration | C41: 731390
B42: OUT OF COUNTRY Trans Ground Motor Fleet | C42: N/A
B43: BRD/NONEMP Air Transportation | C43: 731411
B44: BRD/NONEMP Ground Transportation | C44: 731421
B45: BRD/NONEMP Transportation Other | C45: 731431
B46: BRD/NONEMP Meals | C46: 731452
B47: BRD/NONEMP Other Travel Expense | C47: 731461
...

Sheet Macros
B1: Auto_Open
B8: Auto_Close
B16: IOList
B17: I
B18: O
