Workbook

Sheet instruction-districts
B2: District | C2: INSTRUCTION | K2: SUPPORT
C3: CLASSROOM TEACHERS | I3: Instructional Aides | J3: Instructional Coordinators / Supervisors | K3: Elementary Guidance Counselor | L3: Seccondary Guidance Counselor | M3: Library / Media Specialist | N3: Library / Media Support Staff
C4: Pre-Kindergarten | E4: Kindergarten | F4: Elementary | G4: Secondary | H4: Special Education
C5: Regular Education | D5: Special Education
C6: CACTUS Database | D6: CACTUS Database | E6: CACTUS Database | F6: CACTUS Database | G6: CACTUS Database | H6: CACTUS Database | I6: Classified Personnel Report | J6: CACTUS Database | K6: CACTUS Database | L6: CACTUS Database | M6: CACTUS Database | N6: Classified Personnel Report
A7: 1 | B7: Alpine | C7: 9.7 | D7: 24.43 | E7: 120.64 | F7: 1360.38 | G7: 1038.96 | H7: 266.69 | I7: 907.65 | J7: 140.14 | K7: 0 | L7: 78.76 | M7: 21.74 | N7: 61.25 | O7: =SUM(C7:N7) -> 4030.34
A8: 2 | B8: Beaver | C8: 0.5 | D8: 0 | E8: 2.94 | F8: 35.32 | G8: 30.56 | H8: 6.44 | I8: 33.12 | J8: 1.43 | K8: 0 | L8: 1.87 | M8: 0 | N8: 2.18 | O8: =SUM(C8:N8) -> 114.36
A9: 3 | B9: Box Elder | C9: 1 | D9: 8 | E9: 26.03 | F9: 189.72 | G9: 221.34 | H9: 50.08 | I9: 145 | J9: 17.01 | K9: 2.5 | L9: 12.84 | M9: 4.9 | N9: 7 | O9: =SUM(C9:N9) -> 685.42
A10: 4 | B10: Cache | C10: 0 | D10: 8.38 | E10: 29 | F10: 249.5 | G10: 287.36 | H10: 50.71 | I10: 367.17 | J10: 44.8 | K10: 1.28 | L10: 18.4 | M10: 19.85 | N10: 0 | O10: =SUM(C10:N10) -> 1076.45
A11: 42 | B11: Canyons | C11: 0 | D11: 12 | E11: 63 | F11: 642.91 | G11: 588.56 | H11: 140.13 | I11: 129.98 | J11: 101.8 | K11: 0.5 | L11: 41.68 | M11: 10.88 | N11: 30.31 | O11: =SUM(C11:N11) -> 1761.75
A12: 5 | B12: Carbon | C12: 0 | D12: 2 | E12: 14 | F12: 74.43 | G12: 70.63 | H12: 17.99 | I12: 88.68 | J12: 14.39 | K12: 2.9 | L12: 4.94 | M12: 1 | N12: 4.03 | O12: =SUM(C12:N12) -> 294.99
A13: 6 | B13: Daggett | C13: 0 | D13: 0 | E13: 0.83 | F13: 4.55 | G13: 8.75 | H13: 0.83 | I13: 6.79 | J13: 1.97 | K13: 0 | L13: 0 | M13: 0.03 | N13: 0 | O13: =SUM(C13:N13) -> 23.75
A14: 7 | B14: Davis | C14: 1 | D14: 28.42 | E14: 137.78 | F14: 1300.44 | G14: 1032.55 | H14: 292.25 | I14: 1026 | J14: 206.72 | K14: 34.2 | L14: 83.95 | M14: 20.21 | N14: 51.54 | O14: =SUM(C14:N14) -> 4215.06
A15: 8 | B15: Duchesne | C15: 0 | D15: 3 | E15: 12.5 | F15: 93.17 | G15: 86.32 | H15: 27.45 | I15: 92.18 | J15: 6.31 | K15: 0 | L15: 5 | M15: 5.17 | N15: 4.4 | O15: =SUM(C15:N15) -> 335.5
A16: 9 | B16: Emery | C16: 0 | D16: 1 | E16: 7.5 | F16: 54.64 | G16: 53.46 | H16: 13.17 | I16: 42.76 | J16: 1 | K16: 0 | L16: 0.5 | M16: 1.16 | N16: 8.5 | O16: =SUM(C16:N16) -> 183.69
A17: 10 | B17: Garfield | C17: 0.5 | D17: 0 | E17: 2.74 | F17: 22.72 | G17: 26.47 | H17: 4.4 | I17: 24.03 | J17: 0.13 | K17: 0 | L17: 1.5 | M17: 0 | N17: 0.86 | O17: =SUM(C17:N17) -> 83.35
A18: 11 | B18: Grand | C18: 0 | D18: 1 | E18: 5 | F18: 32 | G18: 35.31 | H18: 8.4 | I18: 29.29 | J18: 1.35 | K18: 0 | L18: 2 | M18: 1 | N18: 2.25 | O18: =SUM(C18:N18) -> 117.6
... A47: 35 | B47: Weber | C47: 0 | D47: 8.81 | E47: 63.01 | F47: 571.76 | G47: 528.18 | H47: 162.08 | I47: 379.66 | J47: 85.64 | K47: 20.8 | L47: 36.66 | M47: 13.83 | N47: 27.7 | O47: =SUM(C47:N47) -> 1898.13
B48: DISTRICT TOTAL | C48: =SUM(C7:C47) -> 30.3 | D48: =SUM(D7:D47) -> 225.87 | E48: =SUM(E7:E47) -> 1196.1 | F48: =SUM(F7:F47) -> 10522.56 | G48: =SUM(G7:G47) -> 9524.06 | H48: =SUM(H7:H47) -> 2447.8 | I48: =SUM(I7:I47) -> 7480.26 | J48: =SUM(J7:J47) -> 1713.89 | ... N48: =SUM(N7:N47) -> 420.35
B49: CHARTER TOTAL | C49: ='instruction-charters'!D89 -> 2 | D49: ='instruction-charters'!E89 -> 0 | E49: ='instruction-charters'!F89 -> 102.23 | F49: ='instruction-charters'!G89 -> 953.17 | G49: ='instruction-charters'!H89 -> 808.49 | H49: ='instruction-charters'!I89 -> 157.07 | I49: ='instruction-charters'!J89 -> 592.35 | J49: ='instruction-charters'!K89 -> 30.64 | ... N49: ='instruction-charters'!O89 -> 14.25
B50: GRAND TOTAL | C50: =SUM(C48:C49) -> 32.3 | D50: =SUM(D48:D49) -> 225.87 | E50: =SUM(E48:E49) -> 1298.33 | F50: =SUM(F48:F49) -> 11475.73 | G50: =SUM(G48:G49) -> 10332.55 | H50: =SUM(H48:H49) -> 2604.87 | I50: =SUM(I48:I49) -> 8072.61 | J50: =SUM(J48:J49) -> 1744.53 | ... N50: =SUM(N48:N49) -> 434.6

Sheet support-districts
B4: District | C4: SUPPORT | M4: TOTAL FTEs
C5: LEA Administrators | E5: LEA Administrative Support Staff | F5: School Administrators | G5: School Administrative Support Staff | H5: Student Support Services Staff
H6: Student Support Services | I6: Student Transportation Supervisors | J6: School Food Services Supervisors | K6: School Nurses | L6: Other Support Staff
C7: CACTUS Database | D7: Classified Personnel Report | E7: Classified Personnel Report | F7: CACTUS Database | G7: Classified Personnel Report | H7: CACTUS Database | I7: Classified Personnel Report | J7: Classified Personnel Report | K7: Classified Personnel Report | L7: Classified Personnel Report
A8: 1 | B8: Alpine | C8: 23 | D8: 1 | E8: 97.46 | F8: 119.29 | G8: 254.25 | H8: 99.45 | I8: 4 | J8: 5 | K8: 0 | L8: 961.54 | M8: =SUM(N8:O8) -> 5595.33 | N8: ='instruction-districts'!O7 -> 4030.34 | O8: =SUM(C8:L8) -> 1564.99
A9: 2 | B9: Beaver | C9: 2.5 | D9: 0 | E9: 0.8 | F9: 4.04 | G9: 7.1 | H9: 1 | I9: 0 | J9: 0 | K9: 0.2 | L9: 24.58 | M9: =SUM(N9:O9) -> 154.58 | N9: ='instruction-districts'!O8 -> 114.36 | O9: =SUM(C9:L9) -> 40.22
A10: 3 | B10: Box Elder | C10: 5 | D10: 1 | E10: 9 | F10: 25.3 | G10: 34 | H10: 22.4 | I10: 1 | J10: 1 | K10: 2 | L10: 228 | M10: =SUM(N10:O10) -> 1014.12 | N10: ='instruction-districts'!O9 -> 685.42 | O10: =SUM(C10:L10) -> 328.7
A11: 4 | B11: Cache | C11: 2.5 | D11: 1 | E11: 5.86 | F11: 32.61 | G11: 54.64 | H11: 34.93 | I11: 3.66 | J11: 25 | K11: 2.5 | L11: 270.89 | M11: =SUM(N11:O11) -> 1510.04 | N11: ='instruction-districts'!O10 -> 1076.45 | O11: =SUM(C11:L11) -> 433.59
A12: 42 | B12: Canyons | C12: 19 | D12: 1.5 | E12: 63 | F12: 83 | G12: 109.1 | H12: 80.7 | I12: 1.25 | J12: 1 | K12: 7 | L12: 451.5 | M12: =SUM(N12:O12) -> 2578.8 | N12: ='instruction-districts'!O11 -> 1761.75 | O12: =SUM(C12:L12) -> 817.05
A13: 5 | B13: Carbon | C13: 4.5 | D13: 1 | E13: 13.51 | F13: 12 | G13: 17.05 | H13: 4 | I13: 0 | J13: 0.5 | K13: 0.62 | L13: 70.03 | M13: =SUM(N13:O13) -> 418.2 | N13: ='instruction-districts'!O12 -> 294.99 | O13: =SUM(C13:L13) -> 123.21
A14: 6 | B14: Daggett | C14: 0.8 | D14: 0.85 | E14: 0.85 | F14: 0.86 | G14: 2.5 | H14: 0 | I14: 0 | J14: 0.13 | K14: 0 | L14: 8.8 | M14: =SUM(N14:O14) -> 38.54 | N14: ='instruction-districts'!O13 -> 23.75 | O14: =SUM(C14:L14) -> 14.79
A15: 7 | B15: Davis | C15: 16 | D15: 1 | E15: 65.91 | F15: 174.98 | G15: 234.36 | H15: 114.6 | I15: 1 | J15: 4 | K15: 15.67 | L15: 1035.37 | M15: =SUM(N15:O15) -> 5877.95 | N15: ='instruction-districts'!O14 -> 4215.06 | O15: =SUM(C15:L15) -> 1662.89
A16: 8 | B16: Duchesne | C16: 0.5 | D16: 1 | E16: 8.5 | F16: 14.25 | G16: 21.23 | H16: 4 | I16: 1 | J16: 1 | K16: 0.5 | L16: 91.03 | M16: =SUM(N16:O16) -> 478.51 | N16: ='instruction-districts'!O15 -> 335.5 | O16: =SUM(C16:L16) -> 143.01
A17: 9 | B17: Emery | C17: 3.5 | D17: 1 | E17: 3 | F17: 10 | G17: 12 | H17: 2 | I17: 1 | J17: 1 | K17: 0 | L17: 54.89 | M17: =SUM(N17:O17) -> 272.08 | N17: ='instruction-districts'!O16 -> 183.69 | O17: =SUM(C17:L17) -> 88.39
A18: 10 | B18: Garfield | C18: 1 | D18: 1 | E18: 5 | F18: 4.2 | G18: 6.2 | H18: 1 | I18: 0 | J18: 0 | K18: 0 | L18: 17.73 | M18: =SUM(N18:O18) -> 119.48 | N18: ='instruction-districts'!O17 -> 83.35 | O18: =SUM(C18:L18) -> 36.13
A19: 11 | B19: Grand | C19: 2 | D19: 0 | E19: 5.25 | F19: 5 | G19: 7 | H19: 2 | I19: 1 | J19: 1 | K19: 0 | L19: 45.61 | M19: =SUM(N19:O19) -> 186.46 | N19: ='instruction-districts'!O18 -> 117.6 | O19: =SUM(C19:L19) -> 68.86
... A48: 35 | B48: Weber | C48: 13 | D48: 0 | E48: 13.94 | F48: 63 | G48: 78.67 | H48: 44.29 | I48: 2 | J48: 3 | K48: 12.65 | L48: 436.67 | M48: =SUM(N48:O48) -> 2565.35 | N48: ='instruction-districts'!O47 -> 1898.13 | O48: =SUM(C48:L48) -> 667.22
B49: DISTRICT TOTAL | C49: =SUM(C8:C48) -> 258.1 | D49: =SUM(D8:D48) -> 42.7 | E49: =SUM(E8:E48) -> 617.4 | F49: =SUM(F8:F48) -> 1220.33 | G49: =SUM(G8:G48) -> 1949.33 | H49: =SUM(H8:H48) -> 955.27 | I49: =SUM(I8:I48) -> 40.46 | J49: =SUM(J8:J48) -> 123.31 | ... M49: =SUM(M8:M48) -> 48651.51
B50: CHARTER TOTAL | C50: ='support-charters'!C88 -> 28.57 | D50: ='support-charters'!D88 -> 15.37 | E50: ='support-charters'!E88 -> 37.7 | F50: ='support-charters'!F88 -> 111.33 | G50: ='support-charters'!G88 -> 147.12 | H50: ='support-charters'!H88 -> 16.58 | I50: ='support-charters'!I88 -> 0 | J50: ='support-charters'!J88 -> 17.34 | ... M50: ='support-charters'!M88 -> 3283.82
B51: GRAND TOTAL | C51: =SUM(C49:C50) -> 286.67 | D51: =SUM(D49:D50) -> 58.07 | E51: =SUM(E49:E50) -> 655.1 | F51: =SUM(F49:F50) -> 1331.66 | G51: =SUM(G49:G50) -> 2096.45 | H51: =SUM(H49:H50) -> 971.85 | I51: =SUM(I49:I50) -> 40.46 | J51: =SUM(J49:J50) -> 140.65 | ... M51: =SUM(M49:M50) -> 51935.33

Sheet instruction-charters
C4: Charter School | D4: INSTRUCTION | L4: SUPPORT
D5: CLASSROOM TEACHERS | J5: Instructional Aides | K5: Instructional Coordinators / Supervisors | L5: Elementary Guidance Counselor | M5: Seccondary Guidance Counselor | N5: Library / Media Specialist | O5: Library / Media Support Staff
D6: Pre-Kindergarten | F6: Kindergarten | G6: Elementary | H6: Secondary | I6: Special Education
D7: Regular Education | E7: Special Education
D8: CACTUS Database | E8: CACTUS Database | F8: CACTUS Database | G8: CACTUS Database | H8: CACTUS Database | I8: CACTUS Database | J8: Classified Personnel Report | K8: CACTUS Database | L8: CACTUS Database | M8: CACTUS Database | N8: CACTUS Database | O8: Classified Personnel Report
B9: 83 | C9: ACADEMY FOR MATH ENGINEERING & SCIENCE (AMES) | D9: 0 | E9: 0 | F9: 0 | G9: 0 | H9: 20.02 | I9: 1 | J9: 2.55 | K9: 0 | L9: 0 | M9: 3 | N9: 0 | O9: 0 | P9: =SUM(D9:O9) -> 26.57
B10: 9G | C10: ALIANZA ACADEMY | D10: 0 | E10: 0 | F10: 2 | G10: 6.4 | H10: 0.6 | I10: 2 | J10: 12 | K10: 0 | L10: 0 | M10: 0 | N10: 0 | O10: 0 | P10: =SUM(D10:O10) -> 23
B11: 8B | C11: AMERICAN LEADERSHIP ACADEMY | D11: 0 | E11: 0 | F11: 3 | G11: 25 | H11: 34.72 | I11: 6.64 | J11: 21 | K11: 2.24 | L11: 0.25 | M11: 2 | N11: 0.6 | O11: 0 | P11: =SUM(D11:O11) -> 95.45
B12: 74 | C12: AMERICAN PREPARATORY ACADEMY | D12: 0 | E12: 0 | F12: 5 | G12: 39.27 | H12: 35.02 | I12: 2.68 | J12: 0 | K12: 0 | L12: 0.85 | M12: 1.35 | N12: 0 | O12: 0 | P12: =SUM(D12:O12) -> 84.17
B13: 1H | C13: BAER CANYON HS FOR SPORTS & MEDICAL SCIENCES | D13: 0 | E13: 0 | F13: 0 | G13: 0 | H13: 0 | I13: 0 | J13: † | K13: 0 | L13: 0 | M13: 0 | N13: 0 | O13: † | P13: =SUM(D13:O13) -> 0
B14: 3G | C14: BEAR RIVER CHARTER SCHOOL | D14: 0 | E14: 0 | F14: 0 | G14: 5.9 | H14: 3.69 | I14: 1 | J14: 3 | K14: 0 | L14: 0 | M14: 0.17 | N14: 0 | O14: 0 | P14: =SUM(D14:O14) -> 13.76
B15: 3B | C15: BEEHIVE SCIENCE & TECHNOLOGY ACADEMY (BSTA) | D15: 0 | E15: 0 | F15: 0 | G15: 0 | H15: 10.82 | I15: 1.28 | J15: 0 | K15: 0 | L15: 0 | M15: 0.5 | N15: 0.11 | O15: 0 | P15: =SUM(D15:O15) -> 12.71
B16: 9D | C16: CANYON RIM ACADEMY | D16: 0 | E16: 0 | F16: 2 | G16: 19 | H16: 0 | I16: 1 | J16: 0 | K16: 0.33 | L16: 0 | M16: 0 | N16: 0 | O16: 0 | P16: =SUM(D16:O16) -> 22.33
B17: 2D | C17: CHANNING HALL | D17: 0 | E17: 0 | F17: 2 | G17: 19.85 | H17: 9.15 | I17: 2.51 | J17: 10.4 | K17: 0 | L17: 0 | M17: 0 | N17: 0 | O17: 1.4 | P17: =SUM(D17:O17) -> 45.31
B18: 87 | C18: CITY ACADEMY | D18: 0 | E18: 0 | F18: 0 | G18: 0 | H18: 14.58 | I18: 0.11 | J18: 0 | K18: 0 | L18: 0 | M18: 0.5 | N18: 0 | O18: 0 | P18: =SUM(D18:O18) -> 15.19
B19: 3E | C19: CS LEWIS ACADEMY | D19: 0 | E19: 0 | F19: 3 | G19: 11.1 | H19: 1 | I19: 1 | J19: 2.5 | K19: 1.2 | L19: 0 | M19: 0 | N19: 0 | O19: 0 | P19: =SUM(D19:O19) -> 19.8
B20: A3 | C20: DAVINCI ACADEMY | D20: 0 | E20: 0 | F20: 0 | G20: 4 | H20: 19.15 | I20: 3 | J20: 1.72 | K20: 0 | L20: 0 | M20: 1 | N20: 0.23 | O20: 0 | P20: =SUM(D20:O20) -> 29.1
B21: 4E | C21: DUAL IMMERSION ACADEMY | D21: 0 | E21: 0 | F21: 4 | G21: 12.64 | H21: 4.28 | I21: 3.13 | J21: 2.55 | K21: 1.06 | L21: 0 | M21: 0 | N21: 0.92 | O21: 0 | P21: =SUM(D21:O21) -> 28.58
B22: 6F | C22: EARLY LIGHT ACADEMY AT DAYBREAK | D22: 0 | E22: 0 | F22: 1.5 | G22: 18.92 | H22: 11.96 | I22: 2 | J22: 14.91 | K22: 0 | L22: 0.5 | M22: 0.5 | N22: 1 | O22: 0 | P22: =SUM(D22:O22) -> 51.29
B23: A8 | C23: EAST HOLLYWOOD HIGH | D23: 0 | E23: 0 | F23: 0 | G23: 0 | H23: 14.23 | I23: 2 | J23: 3 | K23: 0.75 | L23: 0 | M23: 1 | N23: 0 | O23: 1 | P23: =SUM(D23:O23) -> 21.98
B24: 5E | C24: EDITH BOWEN LABORATORY SCHOOL | D24: 0 | E24: 0 | F24: 1.03 | G24: 13.39 | H24: 0 | I24: 1.03 | J24: 0.71 | K24: 1.03 | L24: 0.77 | M24: 0 | N24: 2.6 | O24: 0 | P24: =SUM(D24:O24) -> 20.56
B25: 3H | C25: ENDEAVOR HALL | D25: 0 | E25: 0 | F25: 0 | G25: 13 | H25: 0 | I25: 0 | J25: 5.25 | K25: 0.5 | L25: 0 | M25: 0 | N25: 1 | O25: 0 | P25: =SUM(D25:O25) -> 19.75
B26: 3C | C26: ENTHEOS ACADEMY | D26: 0 | E26: 0 | F26: 1.08 | G26: 14.75 | H26: 8.52 | I26: 2.57 | J26: 5.4 | K26: 0 | L26: 0.5 | M26: 0.5 | N26: 0 | O26: 0.6 | P26: =SUM(D26:O26) -> 33.92
B27: 7F | C27: EXCELSIOR ACADEMY | D27: 0 | E27: 0 | F27: 2 | G27: 17.34 | H27: 7 | I27: 1.16 | J27: 0.75 | K27: 1 | L27: 0 | M27: 0 | N27: 0 | O27: 0.59 | P27: =SUM(D27:O27) -> 29.84
B28: 98 | C28: FAST FORWARD HIGH | D28: 0 | E28: 0 | F28: 0 | G28: 0 | H28: 12.25 | I28: 0.33 | J28: 4 | K28: 0.78 | L28: 0 | M28: 1.08 | N28: 0 | O28: 0 | P28: =SUM(D28:O28) -> 18.44
B29: 82 | C29: FREEDOM ACADEMY | D29: 0 | E29: 0 | F29: 2 | G29: 19.43 | H29: 9.66 | I29: 1.9 | J29: 0.4 | K29: 0.9 | L29: 0 | M29: 0 | N29: 0 | O29: 0 | P29: =SUM(D29:O29) -> 34.29
B30: 7E | C30: GATEWAY PREPARATORY ACADEMY | D30: 0 | E30: 0 | F30: 1.5 | G30: 13.78 | H30: 7.15 | I30: 3.21 | J30: 18.33 | K30: 0 | L30: 0 | M30: 0 | N30: 0.53 | O30: 0.73 | P30: =SUM(D30:O30) -> 45.23
B31: 5D | C31: GEORGE WASHINGTON ACADEMY | D31: 0 | E31: 0 | F31: 5 | G31: 35.22 | H31: 0.5 | I31: 2.1 | J31: 7.48 | K31: 0 | L31: 0.5 | M31: 0 | N31: 1.3 | O31: 0 | P31: =SUM(D31:O31) -> 52.1
B32: 8G | C32: GOOD FOUNDATIONS ACADEMY | D32: 0 | E32: 0 | F32: 2 | G32: 17.34 | H32: 0 | I32: 1 | J32: 3 | K32: 0 | L32: 0 | M32: 0 | N32: 0.67 | O32: 0 | P32: =SUM(D32:O32) -> 24.01
B33: 1E | C33: GUADALUPE SCHOOL | D33: 2 | E33: 0 | F33: 1 | G33: 4.59 | H33: 0 | I33: 0.5 | J33: 6.5 | K33: 0 | L33: 0 | M33: 0 | N33: 0 | O33: 0.5 | P33: =SUM(D33:O33) -> 15.09
B34: 8F | C34: HAWTHORN ACADEMY | D34: 0 | E34: 0 | F34: 2 | G34: 19.5 | H34: 11.78 | I34: 1.5 | J34: 10.11 | K34: 1 | L34: 0 | M34: 1 | N34: 0.45 | O34: 0 | P34: =SUM(D34:O34) -> 47.34
B35: 5H | C35: HIGHMARK CHARTER SCHOOL | D35: 0 | E35: 0 | F35: 0 | G35: 0 | H35: 0 | I35: 0 | J35: † | K35: 0 | L35: 0 | M35: 0 | N35: 0 | O35: † | P35: =SUM(D35:O35) -> 0
B36: 2C | C36: INTECH COLLEGIATE HIGH SCHOOL | D36: 0 | E36: 0 | F36: 0 | G36: 0 | H36: 7.51 | I36: 0 | J36: 0.81 | K36: 0.54 | L36: 0 | M36: 0.75 | N36: 0 | O36: 0 | P36: =SUM(D36:O36) -> 9.61
B37: A5 | C37: ITINERIS EARLY COLLEGE HIGH | D37: 0 | E37: 0 | F37: 0 | G37: 0 | H37: 11.52 | I37: 0 | J37: 0 | K37: 0 | L37: 0 | M37: 2 | N37: 0 | O37: 0 | P37: =SUM(D37:O37) -> 13.52
B38: 93 | C38: JOHN HANCOCK CHARTER SCHOOL | D38: 0 | E38: 0 | F38: 0.72 | G38: 8.34 | H38: 1.38 | I38: 1 | J38: 4.18 | K38: 0 | L38: 0 | M38: 0 | N38: 0 | O38: 0 | P38: =SUM(D38:O38) -> 15.62
B39: 2E | C39: KARL G MAESER PREPARATORY ACADEMY | D39: 0 | E39: 0 | F39: 0 | G39: 0 | H39: 29.72 | I39: 0.5 | J39: ‡ | K39: 1.5 | L39: 0 | M39: 1 | N39: 0.75 | O39: ‡ | P39: =SUM(D39:O39) -> 33.47
B40: 4C | C40: LAKEVIEW ACADEMY | D40: 0 | E40: 0 | F40: 2 | G40: 22.3 | H40: 8.83 | I40: 2.84 | J40: 15 | K40: 0 | L40: 0.25 | M40: 0.25 | N40: 1 | O40: 0 | P40: =SUM(D40:O40) -> 52.47
B41: 5C | C41: LEGACY PREPARATORY ACADEMY | D41: 0 | E41: 0 | F41: 1.5 | G41: 16 | H41: 25.91 | I41: 2.35 | J41: 30.4 | K41: 1.8 | L41: 0.17 | M41: 0.98 | N41: 0 | O41: 0.58 | P41: =SUM(D41:O41) -> 79.69
B42: 6C | C42: LIBERTY ACADEMY | D42: 0 | E42: 0 | F42: 3.6 | G42: 10.4 | H42: 6.2 | I42: 1.45 | J42: 0 | K42: 1 | L42: 0 | M42: 0 | N42: 0 | O42: 0 | P42: =SUM(D42:O42) -> 22.65
B43: 2B | C43: LINCOLN ACADEMY | D43: 0 | E43: 0 | F43: 1 | G43: 15.21 | H43: 12.15 | I43: 3.09 | J43: 22.82 | K43: 0 | L43: 0 | M43: 0.53 | N43: 0 | O43: 0.75 | P43: =SUM(D43:O43) -> 55.55
...

Sheet support-charters
B4: Local Education Agencies | C4: SUPPORT | M4: TOTAL FTEs
C5: LEA Administrators | E5: LEA Administrative Support Staff | F5: School Administra-tors | G5: School Administrative Support Staff | H5: Student Support Services Staff
H6: Student Support Services | I6: Student Transportation Supervisors | J6: School Food Services Supervisors | K6: School Nurses | L6: Other Support Staff
C7: CACTUS Database | D7: Classified Personnel Report | E7: Classified Personnel Report | F7: CACTUS Database | G7: Classified Personnel Report | H7: CACTUS Database | I7: Classified Personnel Report | J7: Classified Personnel Report | K7: Classified Personnel Report | L7: Classified Personnel Report
A8: 83 | B8: ACADEMY FOR MATH ENGINEERING & SCIENCE (AMES) | C8: 0 | D8: 0.25 | E8: 1.17 | F8: 1 | G8: 1 | H8: 0 | I8: 0 | J8: 0 | K8: 0 | L8: 0 | M8: =SUM(N8:O8) -> 29.99 | N8: ='instruction-charters'!P9 -> 26.57 | O8: =SUM(C8:L8) -> 3.42
A9: 9G | B9: ALIANZA ACADEMY | C9: 1 | D9: 0 | E9: 0 | F9: 0 | G9: 3 | H9: 0 | I9: 0 | J9: 0 | K9: 0 | L9: 2.5 | M9: =SUM(N9:O9) -> 29.5 | N9: ='instruction-charters'!P10 -> 23 | O9: =SUM(C9:L9) -> 6.5
A10: 8B | B10: AMERICAN LEADERSHIP ACADEMY | C10: 1 | D10: 0 | E10: 0 | F10: 3.5 | G10: 10 | H10: 0 | I10: 0 | J10: 0 | K10: 1 | L10: 10 | M10: =SUM(N10:O10) -> 120.95 | N10: ='instruction-charters'!P11 -> 95.45 | O10: =SUM(C10:L10) -> 25.5
A11: 74 | B11: AMERICAN PREPARATORY ACADEMY | C11: 3.1 | D11: 0 | E11: 0 | F11: 7 | G11: 0 | H11: 2.36 | I11: 0 | J11: 0 | K11: 0 | L11: 0 | M11: =SUM(N11:O11) -> 96.63 | N11: ='instruction-charters'!P12 -> 84.17 | O11: =SUM(C11:L11) -> 12.46
A12: 1H | B12: BAER CANYON HS FOR SPORTS & MEDICAL SCIENCES | C12: 0 | D12: † | E12: † | F12: 0.5 | G12: † | H12: 0 | I12: † | J12: † | K12: † | L12: † | M12: =SUM(N12:O12) -> 0.5 | N12: ='instruction-charters'!P13 -> 0 | O12: =SUM(C12:L12) -> 0.5
A13: 3G | B13: BEAR RIVER CHARTER SCHOOL | C13: 1 | D13: 0 | E13: 0.25 | F13: 0 | G13: 1 | H13: 0 | I13: 0 | J13: 0 | K13: 0 | L13: 2.25 | M13: =SUM(N13:O13) -> 18.26 | N13: ='instruction-charters'!P14 -> 13.76 | O13: =SUM(C13:L13) -> 4.5
A14: 3B | B14: BEEHIVE SCIENCE & TECHNOLOGY ACADEMY (BSTA) | C14: 1.8 | D14: 0 | E14: 0 | F14: 0 | G14: 2.09 | H14: 0 | I14: 0 | J14: 0 | K14: 0 | L14: 0 | M14: =SUM(N14:O14) -> 16.6 | N14: ='instruction-charters'!P15 -> 12.71 | O14: =SUM(C14:L14) -> 3.89
A15: 9D | B15: CANYON RIM ACADEMY | C15: 0.67 | D15: 0 | E15: 0 | F15: 1 | G15: 0 | H15: 0.53 | I15: 0 | J15: 0 | K15: 0 | L15: 0 | M15: =SUM(N15:O15) -> 24.53 | N15: ='instruction-charters'!P16 -> 22.33 | O15: =SUM(C15:L15) -> 2.2
A16: 2D | B16: CHANNING HALL | C16: 0 | D16: 1 | E16: 1.5 | F16: 2.25 | G16: 2 | H16: 1 | I16: 0 | J16: 1 | K16: 0 | L16: 3.47 | M16: =SUM(N16:O16) -> 57.53 | N16: ='instruction-charters'!P17 -> 45.31 | O16: =SUM(C16:L16) -> 12.22
A17: 87 | B17: CITY ACADEMY | C17: 1 | D17: 1 | E17: 2 | F17: 0.9 | G17: 1.54 | H17: 0 | I17: 0 | J17: 0 | K17: 0 | L17: 1 | M17: =SUM(N17:O17) -> 22.63 | N17: ='instruction-charters'!P18 -> 15.19 | O17: =SUM(C17:L17) -> 7.44
A18: 3E | B18: C.S. LEWIS ACADEMY | C18: 0.3 | D18: 0 | E18: 0 | F18: 0 | G18: 1 | H18: 0.6 | I18: 0 | J18: 0 | K18: 0 | L18: 3 | M18: =SUM(N18:O18) -> 24.7 | N18: ='instruction-charters'!P19 -> 19.8 | O18: =SUM(C18:L18) -> 4.9
A19: A3 | B19: DAVINCI ACADEMY | C19: 0 | D19: 0 | E19: 0 | F19: 2 | G19: 1.9 | H19: 0 | I19: 0 | J19: 0 | K19: 0 | L19: 3.73 | M19: =SUM(N19:O19) -> 36.73 | N19: ='instruction-charters'!P20 -> 29.1 | O19: =SUM(C19:L19) -> 7.63
A20: 4E | B20: DUAL IMMERSION ACADEMY | C20: 0 | D20: 0 | E20: 1 | F20: 0.17 | G20: 1 | H20: 0 | I20: 0 | J20: 0 | K20: 0 | L20: 2 | M20: =SUM(N20:O20) -> 32.75 | N20: ='instruction-charters'!P21 -> 28.58 | O20: =SUM(C20:L20) -> 4.17
A21: 6F | B21: EARLY LIGHT ACADEMY AT DAYBREAK | C21: 0.5 | D21: 0 | E21: 0 | F21: 1.9 | G21: 2.48 | H21: 0.5 | I21: 0 | J21: 0 | K21: 0 | L21: 0 | M21: =SUM(N21:O21) -> 56.67 | N21: ='instruction-charters'!P22 -> 51.29 | O21: =SUM(C21:L21) -> 5.38
A22: A8 | B22: EAST HOLLYWOOD HIGH | C22: 0 | D22: 0.5 | E22: 0.5 | F22: 0 | G22: 0 | H22: 0 | I22: 0 | J22: 0 | K22: 0 | L22: 1.3 | M22: =SUM(N22:O22) -> 24.28 | N22: ='instruction-charters'!P23 -> 21.98 | O22: =SUM(C22:L22) -> 2.3
A23: 5E | B23: EDITH BOWEN LABORATORY SCHOOL | C23: 0 | D23: 1 | E23: 1 | F23: 1.3 | G23: 1 | H23: 0.51 | I23: 0 | J23: 1 | K23: 0 | L23: 0.22 | M23: =SUM(N23:O23) -> 26.59 | N23: ='instruction-charters'!P24 -> 20.56 | O23: =SUM(C23:L23) -> 6.03
A24: 3H | B24: ENDEAVOR HALL | C24: 0 | D24: 0 | E24: 0 | F24: 0.5 | G24: 1 | H24: 0 | I24: 0 | J24: 0 | K24: 0 | L24: 2 | M24: =SUM(N24:O24) -> 23.25 | N24: ='instruction-charters'!P25 -> 19.75 | O24: =SUM(C24:L24) -> 3.5
A25: 3C | B25: ENTHEOS ACADEMY | C25: 0 | D25: 0 | E25: 0 | F25: 0 | G25: 3 | H25: 0.21 | I25: 0 | J25: 0 | K25: 0 | L25: 3.4 | M25: =SUM(N25:O25) -> 40.53 | N25: ='instruction-charters'!P26 -> 33.92 | O25: =SUM(C25:L25) -> 6.61
A26: 7F | B26: EXCELSIOR ACADEMY | C26: 0 | D26: 0 | E26: 0 | F26: 1.75 | G26: 0.96 | H26: 0 | I26: 0 | J26: 1 | K26: 0 | L26: 0.99 | M26: =SUM(N26:O26) -> 34.54 | N26: ='instruction-charters'!P27 -> 29.84 | O26: =SUM(C26:L26) -> 4.7
A27: 98 | B27: FAST FORWARD HIGH | C27: 0 | D27: 0.5 | E27: 0.5 | F27: 1.17 | G27: 0 | H27: 0 | I27: 0 | J27: 0 | K27: 0 | L27: 1.5 | M27: =SUM(N27:O27) -> 22.11 | N27: ='instruction-charters'!P28 -> 18.44 | O27: =SUM(C27:L27) -> 3.67
A28: 82 | B28: FREEDOM ACADEMY | C28: 0 | D28: 0 | E28: 1.8 | F28: 1.18 | G28: 0 | H28: 0.25 | I28: 0 | J28: 0.8 | K28: 0 | L28: 2.2 | M28: =SUM(N28:O28) -> 40.52 | N28: ='instruction-charters'!P29 -> 34.29 | O28: =SUM(C28:L28) -> 6.23
A29: 7E | B29: GATEWAY PREPARATORY ACADEMY | C29: 1.11 | D29: 0 | E29: 0 | F29: 1 | G29: 2.16 | H29: 0 | I29: 0 | J29: 0 | K29: 0 | L29: 3.37 | M29: =SUM(N29:O29) -> 52.87 | N29: ='instruction-charters'!P30 -> 45.23 | O29: =SUM(C29:L29) -> 7.64
A30: 5D | B30: GEORGE WASHINGTON ACADEMY | C30: 0 | D30: 0 | E30: 0 | F30: 1.5 | G30: 5.26 | H30: 0.75 | I30: 0 | J30: 0 | K30: 0 | L30: 1.38 | M30: =SUM(N30:O30) -> 60.99 | N30: ='instruction-charters'!P31 -> 52.1 | O30: =SUM(C30:L30) -> 8.89
A31: 8G | B31: GOOD FOUNDATIONS ACADEMY | C31: 0 | D31: 0 | E31: 0 | F31: 1 | G31: 1.5 | H31: 0 | I31: 0 | J31: 0 | K31: 0 | L31: 1.25 | M31: =SUM(N31:O31) -> 27.76 | N31: ='instruction-charters'!P32 -> 24.01 | O31: =SUM(C31:L31) -> 3.75
A32: 1E | B32: GUADALUPE SCHOOL | C32: 0 | D32: 0.75 | E32: 1.5 | F32: 1 | G32: 0.8 | H32: 0 | I32: 0 | J32: 0 | K32: 0 | L32: 3.58 | M32: =SUM(N32:O32) -> 22.72 | N32: ='instruction-charters'!P33 -> 15.09 | O32: =SUM(C32:L32) -> 7.63
A33: 8F | B33: HAWTHORN ACADEMY | C33: 0 | D33: 0 | E33: 0 | F33: 1.9 | G33: 1.86 | H33: 0 | I33: 0 | J33: 0 | K33: 0 | L33: 0.25 | M33: =SUM(N33:O33) -> 51.35 | N33: ='instruction-charters'!P34 -> 47.34 | O33: =SUM(C33:L33) -> 4.01
A34: 5H | B34: HIGHMARK CHARTER SCHOOL | C34: 0 | D34: † | E34: † | F34: 1 | G34: † | H34: 0 | I34: † | J34: † | K34: † | L34: † | M34: =SUM(N34:O34) -> 1 | N34: ='instruction-charters'!P35 -> 0 | O34: =SUM(C34:L34) -> 1
A35: 2C | B35: INTECH COLLEGIATE HIGH SCHOOL | C35: 0 | D35: 0 | E35: 0 | F35: 1 | G35: 0.83 | H35: 0 | I35: 0 | J35: 0 | K35: 0 | L35: 0.38 | M35: =SUM(N35:O35) -> 11.82 | N35: ='instruction-charters'!P36 -> 9.61 | O35: =SUM(C35:L35) -> 2.21
A36: A5 | B36: ITINERIS EARLY COLLEGE HIGH | C36: 0 | D36: 0 | E36: 0.5 | F36: 0.95 | G36: 1 | H36: 0 | I36: 0 | J36: 0 | K36: 0 | L36: 0 | M36: =SUM(N36:O36) -> 15.97 | N36: ='instruction-charters'!P37 -> 13.52 | O36: =SUM(C36:L36) -> 2.45
A37: 93 | B37: JOHN HANCOCK CHARTER SCHOOL | C37: 0 | D37: 1 | E37: 1 | F37: 1 | G37: 1 | H37: 0 | I37: 0 | J37: 0 | K37: 0 | L37: 0 | M37: =SUM(N37:O37) -> 19.62 | N37: ='instruction-charters'!P38 -> 15.62 | O37: =SUM(C37:L37) -> 4
A38: 2E | B38: KARL G. MAESER PREPARATORY ACADEMY | C38: 1 | D38: ‡ | E38: ‡ | F38: 1.5 | G38: ‡ | H38: 0 | I38: ‡ | J38: ‡ | K38: ‡ | L38: ‡ | M38: =SUM(N38:O38) -> 35.97 | N38: ='instruction-charters'!P39 -> 33.47 | O38: =SUM(C38:L38) -> 2.5
A39: 4C | B39: LAKEVIEW ACADEMY | C39: 1 | D39: 0 | E39: 0 | F39: 0 | G39: 2 | H39: 0 | I39: 0 | J39: 1 | K39: 0 | L39: 4.6 | M39: =SUM(N39:O39) -> 61.07 | N39: ='instruction-charters'!P40 -> 52.47 | O39: =SUM(C39:L39) -> 8.6
A40: 5C | B40: LEGACY PREPARATORY ACADEMY | C40: 1.4 | D40: 1 | E40: 3 | F40: 2 | G40: 5 | H40: 0 | I40: 0 | J40: 0 | K40: 0 | L40: 10.13 | M40: =SUM(N40:O40) -> 102.22 | N40: ='instruction-charters'!P41 -> 79.69 | O40: =SUM(C40:L40) -> 22.53
A41: 6C | B41: LIBERTY ACADEMY | C41: 0 | D41: 0 | E41: 0 | F41: 1.28 | G41: 0 | H41: 0 | I41: 0 | J41: 0 | K41: 0 | L41: 0 | M41: =SUM(N41:O41) -> 23.93 | N41: ='instruction-charters'!P42 -> 22.65 | O41: =SUM(C41:L41) -> 1.28
A42: 2B | B42: LINCOLN ACADEMY | C42: 0.5 | D42: 0.7 | E42: 1.45 | F42: 1 | G42: 3 | H42: 0.32 | I42: 0 | J42: 0 | K42: 0 | L42: 0.37 | M42: =SUM(N42:O42) -> 62.89 | N42: ='instruction-charters'!P43 -> 55.55 | O42: =SUM(C42:L42) -> 7.34
A43: 4G | B43: MARIA MONTESSORI ACADEMY | C43: 0 | D43: 0 | E43: 0 | F43: 1 | G43: 2.18 | H43: 0 | I43: 0 | J43: 0 | K43: 0 | L43: 0 | M43: =SUM(N43:O43) -> 35.34 | N43: ='instruction-charters'!P44 -> 32.16 | O43: =SUM(C43:L43) -> 3.18
...
