Workbook

Sheet INPUT
A1: CONCRETE BATCH PLANT EMISSIONS CALCULATOR - INPUT SCREEN
A2: REVISION A; Issued 01/23/2006
C3: Instructions: Enter emission source / facility data on the "INPUT" tab/screen. The air emission results and summary of input data are viewed / printed on the "OUTPUT" tab/screen. The different tabs are on the bottom of this screen.
C6: This spreadsheet is for your use only and should be used with caution. DENR does not guarantee the accuracy of the information contained. This spreadsheet is subject to continual revision and updating. It is your responsibility to be aware of the most current information available. DENR is not responsible for errors or omissions that may be contained herein.
A11: Directions: Enter and select information in the boxes that are highlighted in blue:
A13: General Facility Information
A14: COMPANY NAME: | F14: Company Name
A15: FACILITY ID NUMBER: | F15: 04/01/12345
A16: PERMIT NUMBER | F16: 01234R00
A17: FACILITY CITY: | F17: City
A18: FACILITY COUNTY: | F18: County
A19: SPREADSHEET PREPARED BY: | F19: Your Name
A21: General Facility Information
A22: MAXIMUM HOURLY THROUGHPUT AT TRUCK LOAD OUT | F22: 1 | G22: (yd3/hour)
A23: IS THE MAXIMUM THROUGHPUT A SYNTHETIC LIMIT? | F23: 1 | G23: (1=No, 2=Yes)
A24: ACTUAL ANNUAL PRODUCTION | F24: 1 | G24: (yd3/year)
A26: Facility Production Information
A27: PERCENT OF ANNUAL LOADOUT THROUGH TRUCK MIX | F27: 100 | G27: (% by volume)
A28: PERCENT OF ANNUAL LOADOUT THROUGH CENTRAL MIX | F28: 0 | G28: (% by volume)
A30: Facility Emissions Control Information
A31: IS THERE A CONTROL DEVICE ON THE TRUCK MIX? | F31: 1 | G31: (1=No, 2=Yes)
A32: IS THERE A CONTROL DEVICE ON THE CENTRAL MIX? | F32: 1 | G32: (1=No, 2=Yes)
A34: Material Composition Information | H34: Typical NC Comp.*
A35: Cement | F35: 410 | G35: lbs | H35: 410 lbs
A36: Supplement | F36: 120 | G36: lbs | H36: 120 lbs
A37: Coarse Aggregate | F37: 1884 | G37: lbs | H37: 1884 lbs
A38: Sand | F38: 1443 | G38: lbs | H38: 1443 lbs
A39: Water | F39: 167 | G39: lbs | H39: 167 lbs
A40: Total | F40: 4024 | G40: lbs | H40: 4024 lbs
A41: * North Carolina typical material composition is based on data from industry contacts. User may enter site-specific data.

Sheet OUTPUT
A1: CONCRETE BATCH PLANT EMISSIONS CALCULATOR - OUTPUT SCREEN
A2: =INPUT!A2 -> REVISION A; Issued 01/23/2006
C3: =INPUT!C6 -> This spreadsheet is for your use only and should be used with caution. DENR does not guarantee the accuracy of the information contained. This spreadsheet is subject to continual revision and updating. It is your responsibility to be aware of the most current information available. DENR is not responsible for errors or omissions that may be contained herein.
A10: SOURCE / FACILITY / USER INPUT SUMMARY (FROM INPUT SCREEN)
A11: General Facility Information
A12: COMPANY NAME: | F12: =INPUT!F14 -> Company Name
A13: FACILITY ID NUMBER: | F13: =INPUT!F15 -> 04/01/12345
A14: PERMIT NUMBER | F14: =INPUT!F16 -> 01234R00
A15: FACILITY CITY: | F15: =INPUT!F17 -> City
A16: FACILITY COUNTY: | F16: =INPUT!F18 -> County
A17: SPREADSHEET PREPARED BY: | F17: =INPUT!F19 -> Your Name
A19: General Facility Information
A20: MAXIMUM HOURLY THROUGHPUT AT TRUCK LOAD OUT | F20: =INPUT!F22 -> 1 | G20: (yd3/hour)
A21: IS THE MAXIMUM THROUGHPUT A SYNTHETIC LIMIT? | F21: =INPUT!F23 -> 1 | G21: (1=No, 2=Yes)
A22: ACTUAL ANNUAL PRODUCTION | F22: =INPUT!F24 -> 1 | G22: (yd3/year)
A24: Facility Production Information
A25: PERCENT OF ANNUAL LOADOUT THROUGH TRUCK MIX | F25: =INPUT!F27 -> 100 | G25: (% by volume)
A26: PERCENT OF ANNUAL LOADOUT THROUGH CENTRAL MIX | F26: =INPUT!F28 -> 0 | G26: (% by volume)
A28: Facility Emissions Control Information
A29: IS THERE A CONTROL DEVICE ON THE TRUCK MIX? | F29: =INPUT!F31 -> 1 | G29: (1=No, 2=Yes)
A30: IS THERE A CONTROL DEVICE ON THE CENTRAL MIX? | F30: =INPUT!F32 -> 1 | G30: (1=No, 2=Yes)
A32: Material Composition Information | H32: Typical NC Comp.*
A33: Cement | F33: =INPUT!F35 -> 410 | G33: lbs | H33: 410 lbs
A34: Supplement | F34: =INPUT!F36 -> 120 | G34: lbs | H34: 120 lbs
A35: Coarse Aggregate | F35: =INPUT!F37 -> 1884 | G35: lbs | H35: 1884 lbs
A36: Sand | F36: =INPUT!F38 -> 1443 | G36: lbs | H36: 1443 lbs
A37: Water | F37: =INPUT!F39 -> 167 | G37: lbs | H37: 167 lbs
A38: Total | F38: =INPUT!F40 -> 4024 | G38: lbs | H38: 4024 lbs
A39: * North Carolina typical material composition is based on data from industry contacts. User may enter site-specific data.
A42: PARTICULATE MATTER EMISSIONS INFORMATION
A43: PARTICULATE EMISSIONS | D43: Expected Actual | G43: Potential Emissions
D44: After Controls/Limit | F44: Before Controls/Limit | H44: After Controls/Limit
A45: Source | C45: Pollutant | D45: lb/hr | E45: tons/yr | F45: lb/hr | G45: tons/yr | H45: lb/hr | I45: tons/yr
A46: truck mix | C46: PM | D46: =INPUT!$F$22*2.012*INPUT!$F$27/100*CHOOSE(INPUT!$F$31,FACTORS!$B$10,FACTORS!$B$11)*(INPUT!$F$35+INPUT!$F$36)/INPUT!$F$40 -> 0.3869 | E46: =INPUT!$F$24*2.012*INPUT!$F$27/100*CHOOSE(INPUT!$F$31,FACTORS!$B$10,FACTORS!$B$11)*(INPUT!$F$35+INPUT!$F$36)/INPUT!$F$40/2000 -> 0.00019345 | F46: =INPUT!$F$22*2.012*INPUT!$F$27/100*FACTORS!$B$10*(INPUT!$F$35+INPUT!$F$36)/INPUT!$F$40 -> 0.3869 | G46: =INPUT!$F$22*2.012*INPUT!$F$27/100*FACTORS!$B$10*(INPUT!$F$35+INPUT!$F$36)/INPUT!$F$40*8760/2000 -> 1.694622 | H46: =CHOOSE(INPUT!$F$23,INPUT!$F$22,FACTORS!$C$44)*2.012*INPUT!$F$27/100*CHOOSE(INPUT!$F$31,FACTORS!$B$10,FACTORS!$B$11)*(INPUT!$F$35+INPUT!$F$36)/INPUT!$F$40 -> 0.3869 | I46: =CHOOSE(INPUT!$F$23,INPUT!$F$22,FACTORS!$C$44)*2.012*INPUT!$F$27/100*CHOOSE(INPUT!$F$31,FACTORS!$B$10,FACTORS!$B$11)*(INPUT!$F$35+INPUT!$F$36)/INPUT!$F$40*8760/2000 -> 1.694622
C47: PM10 | D47: =INPUT!$F$22*2.012*INPUT!$F$27/100*CHOOSE(INPUT!$F$31,FACTORS!$D$10,FACTORS!$D$11)*(INPUT!$F$35+INPUT!$F$36)/INPUT!$F$40 -> 0.110505 | E47: =INPUT!$F$24*2.012*INPUT!$F$27/100*CHOOSE(INPUT!$F$31,FACTORS!$D$10,FACTORS!$D$11)*(INPUT!$F$35+INPUT!$F$36)/INPUT!$F$40/2000 -> 5.52525e-05 | F47: =INPUT!$F$22*2.012*INPUT!$F$27/100*FACTORS!$D$10*(INPUT!$F$35+INPUT!$F$36)/INPUT!$F$40 -> 0.110505 | G47: =INPUT!$F$22*2.012*INPUT!$F$27/100*FACTORS!$D$10*(INPUT!$F$35+INPUT!$F$36)/INPUT!$F$40*8760/2000 -> 0.4840119 | H47: =CHOOSE(INPUT!$F$23,INPUT!$F$22,FACTORS!$C$44)*2.012*INPUT!$F$27/100*CHOOSE(INPUT!$F$31,FACTORS!$D$10,FACTORS!$D$11)*(INPUT!$F$35+INPUT!$F$36)/INPUT!$F$40 -> 0.110505 | I47: =CHOOSE(INPUT!$F$23,INPUT!$F$22,FACTORS!$C$44)*2.012*INPUT!$F$27/100*CHOOSE(INPUT!$F$31,FACTORS!$D$10,FACTORS!$D$11)*(INPUT!$F$35+INPUT!$F$36)/INPUT!$F$40*8760/2000 -> 0.4840119
A48: central mix | C48: PM | D48: =INPUT!$F$22*2.012*INPUT!$F$28/100*CHOOSE(INPUT!$F$32,FACTORS!$B$12,FACTORS!$B$13)*(INPUT!$F$35+INPUT!$F$36)/INPUT!$F$40 -> 0 | E48: =INPUT!$F$24*2.012*INPUT!$F$28/100*CHOOSE(INPUT!$F$32,FACTORS!$B$12,FACTORS!$B$13)*(INPUT!$F$35+INPUT!$F$36)/INPUT!$F$40/2000 -> 0 | F48: =INPUT!$F$22*2.012*INPUT!$F$28/100*FACTORS!$B$12*(INPUT!$F$35+INPUT!$F$36)/INPUT!$F$40 -> 0 | G48: =INPUT!$F$22*2.012*INPUT!$F$28/100*FACTORS!$B$12*(INPUT!$F$35+INPUT!$F$36)/INPUT!$F$40*8760/2000 -> 0 | H48: =CHOOSE(INPUT!$F$23,INPUT!$F$22,FACTORS!$C$44)*2.012*INPUT!$F$28/100*CHOOSE(INPUT!$F$32,FACTORS!$B$12,FACTORS!$B$13)*(INPUT!$F$35+INPUT!$F$36)/INPUT!$F$40 -> 0 | I48: =CHOOSE(INPUT!$F$23,INPUT!$F$22,FACTORS!$C$44)*2.012*INPUT!$F$28/100*CHOOSE(INPUT!$F$32,FACTORS!$B$12,FACTORS!$B$13)*(INPUT!$F$35+INPUT!$F$36)/INPUT!$F$40*8760/2000 -> 0
C49: PM10 | D49: =INPUT!$F$22*2.012*INPUT!$F$28/100*CHOOSE(INPUT!$F$32,FACTORS!$D$12,FACTORS!$D$13)*(INPUT!$F$35+INPUT!$F$36)/INPUT!$F$40 -> 0 | E49: =INPUT!$F$24*2.012*INPUT!$F$28/100*CHOOSE(INPUT!$F$32,FACTORS!$D$12,FACTORS!$D$13)*(INPUT!$F$35+INPUT!$F$36)/INPUT!$F$40/2000 -> 0 | F49: =INPUT!$F$22*2.012*INPUT!$F$28/100*FACTORS!$D$12*(INPUT!$F$35+INPUT!$F$36)/INPUT!$F$40 -> 0 | G49: =INPUT!$F$22*2.012*INPUT!$F$28/100*FACTORS!$D$12*(INPUT!$F$35+INPUT!$F$36)/INPUT!$F$40*8760/2000 -> 0 | H49: =CHOOSE(INPUT!$F$23,INPUT!$F$22,FACTORS!$C$44)*2.012*INPUT!$F$28/100*CHOOSE(INPUT!$F$32,FACTORS!$D$12,FACTORS!$D$13)*(INPUT!$F$35+INPUT!$F$36)/INPUT!$F$40 -> 0 | I49: =CHOOSE(INPUT!$F$23,INPUT!$F$22,FACTORS!$C$44)*2.012*INPUT!$F$28/100*CHOOSE(INPUT!$F$32,FACTORS!$D$12,FACTORS!$D$13)*(INPUT!$F$35+INPUT!$F$36)/INPUT!$F$40*8760/2000 -> 0
A50: cement silo | C50: PM | D50: =INPUT!$F$22*2.012*FACTORS!$B$5*INPUT!$F$35/INPUT!$F$40 -> 0.00020295 | E50: =INPUT!$F$24*2.012*FACTORS!$B$5*INPUT!$F$35/INPUT!$F$40/2000 -> 1.01475e-07 | F50: =INPUT!$F$22*2.012*FACTORS!$B$4*INPUT!$F$35/INPUT!$F$40 -> 0.1476 | G50: =INPUT!$F$22*2.012*FACTORS!$B$4*INPUT!$F$35/INPUT!$F$40*8760/2000 -> 0.646488 | H50: =CHOOSE(INPUT!$F$23,INPUT!$F$22,FACTORS!$C$44)*2.012*FACTORS!$B$5*INPUT!$F$35/INPUT!$F$40 -> 0.00020295 | I50: =CHOOSE(INPUT!$F$23,INPUT!$F$22,FACTORS!$C$44)*2.012*FACTORS!$B$5*INPUT!$F$35/INPUT!$F$40*8760/2000 -> 0.000888921
C51: PM10 | D51: =INPUT!$F$22*2.012*FACTORS!$D$5*INPUT!$F$35/INPUT!$F$40 -> 6.97e-05 | E51: =INPUT!$F$24*2.012*FACTORS!$D$5*INPUT!$F$35/INPUT!$F$40/2000 -> 3.485e-08 | F51: =INPUT!$F$22*2.012*FACTORS!$D$4*INPUT!$F$35/INPUT!$F$40 -> 0.0943 | G51: =INPUT!$F$22*2.012*FACTORS!$D$4*INPUT!$F$35/INPUT!$F$40*8760/2000 -> 0.413034 | H51: =CHOOSE(INPUT!$F$23,INPUT!$F$22,FACTORS!$C$44)*2.012*FACTORS!$D$5*INPUT!$F$35/INPUT!$F$40 -> 6.97e-05 | I51: =CHOOSE(INPUT!$F$23,INPUT!$F$22,FACTORS!$C$44)*2.012*FACTORS!$D$5*INPUT!$F$35/INPUT!$F$40*8760/2000 -> 0.000305286
A52: suppl. Silo | C52: PM | D52: =INPUT!$F$22*2.012*FACTORS!$B$7*INPUT!$F$36/INPUT!$F$40 -> 0.000534 | E52: =INPUT!$F$24*2.012*FACTORS!$B$7*INPUT!$F$36/INPUT!$F$40/2000 -> 2.67e-07 | F52: =INPUT!$F$22*2.012*FACTORS!$B$6*INPUT!$F$36/INPUT!$F$40 -> 0.1884 | G52: =INPUT!$F$22*2.012*FACTORS!$B$6*INPUT!$F$36/INPUT!$F$40*8760/2000 -> 0.825192 | H52: =CHOOSE(INPUT!$F$23,INPUT!$F$22,FACTORS!$C$44)*2.012*FACTORS!$B$7*INPUT!$F$36/INPUT!$F$40 -> 0.000534 | I52: =CHOOSE(INPUT!$F$23,INPUT!$F$22,FACTORS!$C$44)*2.012*FACTORS!$B$7*INPUT!$F$36/INPUT!$F$40*8760/2000 -> 0.00233892
...

Sheet FACTORS
A1: EMISSION FACTOR SUMMARY FOR READY-MIXED CONCRETE BATCH FACILITIES
A3: Emission Source Description | B3: PM Emission Factors | D3: PM10 Emission Factors | F3: Arsenic Emission Factors | H3: References
A4: Cement Silo without controls | B4: 0.72 | C4: lb/ton cement | D4: 0.46 | E4: lb/ton cement | F4: 1.68e-06 | G4: lb/ton cement | H4: U.S. EPA, Office of Air Quality Planning and Standards. AP-42; Chapter 11.12 (Oct. 2001), Table 11.12-2 (PM/PM10) & Table 11.12-6 (As)
A5: Cement Silo with controls | B5: 0.00099 | C5: lb/ton cement | D5: 0.00034 | E5: lb/ton cement | F5: 4.24e-09 | G5: lb/ton cement | H5: U.S. EPA, Office of Air Quality Planning and Standards. AP-42; Chapter 11.12 (Oct. 2001), Table 11.12-2 (PM/PM10) & Table 11.12-6 (As)
A6: Suppl Silo without controls | B6: 3.14 | C6: lb/ton suppl | D6: 1.1 | E6: lb/ton suppl | F6: No Data | G6: - | H6: U.S. EPA, Office of Air Quality Planning and Standards. AP-42; Chapter 11.12 (Oct. 2001), Table 11.12-2 (PM/PM10)
A7: Suppl Silo with controls | B7: 0.0089 | C7: lb/ton suppl | D7: 0.0049 | E7: lb/ton suppl | F7: 1e-06 | G7: lb/ton suppl | H7: U.S. EPA, Office of Air Quality Planning and Standards. AP-42; Chapter 11.12 (Oct. 2001), Table 11.12-2 (PM/PM10) & Table 11.12-6 (As)
A8: Weigh Hopper without controls | B8: 0.0051 | C8: lb/ton aggr+sand | D8: 0.0024 | E8: lb/ton aggr+sand | F8: No Data | G8: - | H8: U.S. EPA, Office of Air Quality Planning and Standards. AP-42; Chapter 11.12 (Oct. 2001), Table 11.12-2 (PM/PM10)
A9: Weigh Hopper with controls | B9: No Data | C9: - | D9: No Data | E9: - | F9: No Data | G9: - | H9: -
A10: Truck Mix without controls | B10: 1.46 | C10: lb/ton cement+suppl | D10: 0.417 | E10: lb/ton cement+suppl | F10: 6.8e-05 | G10: lb/ton cement+suppl | H10: Memorandum, Emission Factors for Ready-Mixed Concrete Facilities. From Mr. Keith Overcash (NC DAQ, Director) to Section Chiefs/Regional Supervisors. June 8, 2005.
A11: Truck Mix with controls | B11: 0.028 | C11: lb/ton cement+suppl | D11: 0.0105 | E11: lb/ton cement+suppl | F11: 1.59e-06 | G11: lb/ton cement+suppl | H11: Memorandum, Emission Factors for Ready-Mixed Concrete Facilities. From Mr. Keith Overcash (NC DAQ, Director) to Section Chiefs/Regional Supervisors. June 8, 2005.
A12: Central Mix without controls | B12: 0.683 | C12: lb/ton cement+suppl | D12: 0.181 | E12: lb/ton cement+suppl | F12: 2.8e-05 | G12: lb/ton cement+suppl | H12: Memorandum, Emission Factors for Ready-Mixed Concrete Facilities. From Mr. Keith Overcash (NC DAQ, Director) to Section Chiefs/Regional Supervisors. June 8, 2005.
A13: Central Mix with controls | B13: 0.0212 | C13: lb/ton cement+suppl | D13: 0.00577 | E13: lb/ton cement+suppl | F13: 8.85e-07 | G13: lb/ton cement+suppl | H13: Memorandum, Emission Factors for Ready-Mixed Concrete Facilities. From Mr. Keith Overcash (NC DAQ, Director) to Section Chiefs/Regional Supervisors. June 8, 2005.
A14: Sand & Aggr Plant-Wide | B14: 0.0237 | C14: lb/yd3 concrete | D14: 0.0114 | E14: lb/yd3 concrete | F14: No Data | G14: - | H14: U.S. EPA, Office of Air Quality Planning and Standards. AP-42; Chapter 11.12 (Oct. 2001), Table 11.12-3 (PM/PM10)
A16: Emission Source Description | B16: Beryllium Emission Factors | D16: Cadmium Emission Factors | F16: Chromium Emission Factors | H16: Lead Emission Factors | J16: References
A17: Cement Silo without controls | B17: 1.79e-08 | C17: lb/ton cement | D17: 2.34e-07 | E17: lb/ton cement | F17: 2.52e-07 | G17: lb/ton cement | H17: 7.36e-07 | I17: lb/ton cement | J17: U.S. EPA, Office of Air Quality Planning and Standards. AP-42; Chapter 11.12 (Oct. 2001), Table 11.12-6
A18: Cement Silo with controls | B18: 4.86e-10 | C18: lb/ton cement | D18: 4.86e-10 | E18: lb/ton cement | F18: 2.9e-08 | G18: lb/ton cement | H18: 1.09e-08 | I18: lb/ton cement | J18: U.S. EPA, Office of Air Quality Planning and Standards. AP-42; Chapter 11.12 (Oct. 2001), Table 11.12-6
A19: Suppl Silo without controls | B19: No Data | C19: - | D19: No Data | E19: - | F19: No Data | G19: - | H19: No Data | I19: - | J19: U.S. EPA, Office of Air Quality Planning and Standards. AP-42; Chapter 11.12 (Oct. 2001), Table 11.12-6
A20: Suppl Silo with controls | B20: 9.04e-08 | C20: lb/ton suppl | D20: 1.98e-08 | E20: lb/ton suppl | F20: 1.22e-06 | G20: lb/ton suppl | H20: 5.2e-07 | I20: lb/ton suppl | J20: U.S. EPA, Office of Air Quality Planning and Standards. AP-42; Chapter 11.12 (Oct. 2001), Table 11.12-6
A21: Weigh Hopper without controls | B21: No Data | C21: - | D21: No Data | E21: - | F21: No Data | G21: - | H21: No Data | I21: - | J21: -
A22: Weigh Hopper with controls | B22: No Data | C22: - | D22: No Data | E22: - | F22: No Data | G22: - | H22: No Data | I22: - | J22: -
A23: Truck Mix without controls | B23: 2.44e-07 | C23: lb/ton cement+suppl | D23: 3.42e-08 | E23: lb/ton cement+suppl | F23: 1.14e-05 | G23: lb/ton cement+suppl | H23: 3.62e-05 | I23: lb/ton cement+suppl | J23: U.S. EPA, Office of Air Quality Planning and Standards. AP-42; Chapter 11.12 (Oct. 2001), Table 11.12-6
A24: Truck Mix with controls | B24: 1.04e-07 | C24: lb/ton cement+suppl | D24: 9.06e-09 | E24: lb/ton cement+suppl | F24: 4.1e-06 | G24: lb/ton cement+suppl | H24: 1.53e-06 | I24: lb/ton cement+suppl | J24: U.S. EPA, Office of Air Quality Planning and Standards. AP-42; Chapter 11.12 (Oct. 2001), Table 11.12-6
A25: Central Mix without controls | B25: No Data | C25: - | D25: 1.18e-08 | E25: lb/ton cement+suppl | F25: 1.42e-06 | G25: lb/ton cement+suppl | H25: 3.82e-07 | I25: lb/ton cement+suppl | J25: U.S. EPA, Office of Air Quality Planning and Standards. AP-42; Chapter 11.12 (Oct. 2001), Table 11.12-6
A26: Central Mix with controls | B26: No Data | C26: - | D26: 7.1e-10 | E26: lb/ton cement+suppl | F26: 1.27e-07 | G26: lb/ton cement+suppl | H26: 3.66e-08 | I26: lb/ton cement+suppl | J26: U.S. EPA, Office of Air Quality Planning and Standards. AP-42; Chapter 11.12 (Oct. 2001), Table 11.12-6
A27: Sand & Aggr Plant-Wide | B27: No Data | C27: - | D27: No Data | E27: - | F27: No Data | G27: - | H27: No Data | I27: - | J27: -
A30: Emission Source Description | B30: Manganese Emission Factors | D30: Nickel Emission Factors | F30: Phosporous Emission Factors | H30: Selenium Emission Factors | J30: References
A31: Cement Silo without controls | B31: 0.000204 | C31: lb/ton cement | D31: 1.76e-05 | E31: lb/ton cement | F31: 1.18e-05 | G31: lb/ton cement | H31: No Data | I31: - | J31: U.S. EPA, Office of Air Quality Planning and Standards. AP-42; Chapter 11.12 (Oct. 2001), Table 11.12-6
A32: Cement Silo with controls | B32: 1.17e-07 | C32: lb/ton cement | D32: 4.18e-08 | E32: lb/ton cement | F32: No Data | G32: - | H32: No Data | I32: - | J32: U.S. EPA, Office of Air Quality Planning and Standards. AP-42; Chapter 11.12 (Oct. 2001), Table 11.12-6
A33: Suppl Silo without controls | B33: No Data | C33: - | D33: No Data | E33: - | F33: No Data | G33: - | H33: No Data | I33: - | J33: -
A34: Suppl Silo with controls | B34: 2.56e-07 | C34: lb/ton suppl | D34: 2.28e-06 | E34: lb/ton suppl | F34: 3.54e-06 | G34: lb/ton suppl | H34: 7.24e-08 | I34: lb/ton suppl | J34: U.S. EPA, Office of Air Quality Planning and Standards. AP-42; Chapter 11.12 (Oct. 2001), Table 11.12-6
A35: Weigh Hopper without controls | B35: No Data | C35: - | D35: No Data | E35: - | F35: No Data | G35: - | H35: No Data | I35: - | J35: -
A36: Weigh Hopper with controls | B36: No Data | C36: - | D36: No Data | E36: - | F36: No Data | G36: - | H36: No Data | I36: - | J36: -
A37: Truck Mix without controls | B37: 6.12e-05 | C37: lb/ton cement+suppl | D37: 1.19e-05 | E37: lb/ton cement+suppl | F37: 3.84e-05 | G37: lb/ton cement+suppl | H37: 2.62e-06 | I37: lb/ton cement+suppl | J37: U.S. EPA, Office of Air Quality Planning and Standards. AP-42; Chapter 11.12 (Oct. 2001), Table 11.12-6
A38: Truck Mix with controls | B38: 2.08e-05 | C38: lb/ton cement+suppl | D38: 4.78e-06 | E38: lb/ton cement+suppl | F38: 1.23e-05 | G38: lb/ton cement+suppl | H38: 1.13e-07 | I38: lb/ton cement+suppl | J38: U.S. EPA, Office of Air Quality Planning and Standards. AP-42; Chapter 11.12 (Oct. 2001), Table 11.12-6
A39: Central Mix without controls | B39: 6.12e-05 | C39: lb/ton cement+suppl | D39: 3.28e-06 | E39: lb/ton cement+suppl | F39: 2.02e-05 | G39: lb/ton cement+suppl | H39: No Data | I39: - | J39: U.S. EPA, Office of Air Quality Planning and Standards. AP-42; Chapter 11.12 (Oct. 2001), Table 11.12-6
A40: Central Mix with controls | B40: 3.78e-06 | C40: lb/ton cement+suppl | D40: 2.48e-07 | E40: lb/ton cement+suppl | F40: 1.2e-06 | G40: lb/ton cement+suppl | H40: No Data | I40: - | J40: U.S. EPA, Office of Air Quality Planning and Standards. AP-42; Chapter 11.12 (Oct. 2001), Table 11.12-6
A41: Sand & Aggr Plant-Wide | B41: No Data | C41: - | D41: No Data | E41: - | F41: No Data | G41: - | H41: No Data | I41: - | J41: -
A44: Syn Minor Cutoff for typical NC | C44: 138.966 | D44: yd3/hr

Sheet REVISIONS
A1: CONCRETE BATCH PLANT EMISSIONS CALCULATOR - REVISIONS SCREEN
A2: =INPUT!A2 -> REVISION A; Issued 01/23/2006
B6: Version | C6: Date | D6: Author | E6: Revisions
B7: N/A | C7: 37330 | D7: Ken Lumsden, P.E. | E7: Added metals listed in U.S. EPA's AP-42, Table 11.12-6.
B9: Revision A | C9: 38740 | D9: Tom McKinney | E9: Revised emission factors for PM, PM10, and Arsenic based on memorandum from DAQ's Keith Overcash, dated June 8, 2005.
E10: Revised formatting to be consistent with DAQ protocol.
