Workbook
Name MATCHINST: #REF!
Name MATCHINST: #REF!
Name MATCHINST: #REF!
Name MATCHINST: #REF!
Name MATCHINST: #REF!
Name MATCHINST: #REF!
Name MATCHINST: #REF!
Name MATCHINST: #REF!
Name MATCHINST: #REF!

Sheet Comparison to Option 1
B1: Outcomes-Based Funding Comparisons to Option 1 - With Phase-In
F2: Option2 | J2: Option 6 | N2: Option 7 | R2: Option 8 | V2: Option 9 | Z2: Option 10
A3: FICE | D3: Option 1 - As proposed for 2014-2015 | F3: Option 2 - Option 1 Scaled, Weighted, and Monetized by Accountability Group | G3: Difference From Option 1 | H3: Percent | J3: Option 6 - Option 2 without Monetization, At-Risk Weight of 1 | K3: Difference From Option 1 | L3: Percent | N3: Option 7 - Option 6 with Optimal Weights | O3: Difference From Option 1 | P3: Percent | R3: Option 8 - Option 7 with Student Characteristic Adjusted (SAT or GPA) | S3: Difference From Option 1 | T3: Percent | V3: Option 9 - Option 7 with Transfer Grads | W3: Difference From Option 1 | X3: Percent | Z3: Option 10 - Option 7 with Modified Scaling | AA3: Difference From Option 1 | AB3: Percent
A4: 3656 | B4: UTA | D4: ='Option 1'!C5 -> 13496783 | F4: ='Option 2'!C5 -> 16200442 | G4: =F4-$D4 -> 2703658.5 | H4: =G4/$D4 -> 0.20031873 | J4: ='Option 6'!Q5 -> 13517160 | K4: =J4-$D4 -> 20376.659 | L4: =K4/$D4 -> 0.0015097419 | N4: ='Option 7'!Q5 -> 11118077 | O4: =N4-$D4 -> -2378706.6 | P4: =O4/$D4 -> -0.17624248 | R4: ='Option 8'!R5 -> 13294588 | S4: =R4-$D4 -> -202194.89 | T4: =S4/$D4 -> -0.014980969 | V4: ='Option 9'!R5 -> 13624730 | W4: =V4-$D4 -> 127946.55 | X4: =W4/$D4 -> 0.0094797813 | Z4: ='Option 10'!Q5 -> 13587702 | AA4: =Z4-$D4 -> 90918.306 | AB4: =AA4/$D4 -> 0.0067362944
A5: 3658 | B5: UT | D5: ='Option 1'!C6 -> 25249293 | F5: ='Option 2'!C6 -> 24554575 | G5: =F5-$D5 -> -694717.97 | H5: =G5/$D5 -> -0.027514353 | J5: ='Option 6'!Q6 -> 21368342 | K5: =J5-$D5 -> -3880951.5 | L5: =K5/$D5 -> -0.15370535 | N5: ='Option 7'!Q6 -> 25128709 | O5: =N5-$D5 -> -120584.63 | P5: =O5/$D5 -> -0.0047757628 | R5: ='Option 8'!R6 -> 24078647 | S5: =R5-$D5 -> -1170646.5 | T5: =S5/$D5 -> -0.046363536 | V5: ='Option 9'!R6 -> 25267701 | W5: =V5-$D5 -> 18407.867 | X5: =W5/$D5 -> 0.00072904484 | Z5: ='Option 10'!Q6 -> 25281149 | AA5: =Z5-$D5 -> 31855.328 | AB5: =AA5/$D5 -> 0.0012616324
A6: 9741 | B6: UTD | D6: ='Option 1'!C7 -> 6570818.6 | F6: ='Option 2'!C7 -> 8212776.3 | G6: =F6-$D6 -> 1641957.7 | H6: =G6/$D6 -> 0.24988633 | J6: ='Option 6'!Q7 -> 6818134.7 | K6: =J6-$D6 -> 247316.08 | L6: =K6/$D6 -> 0.037638549 | N6: ='Option 7'!Q7 -> 5888056.1 | O6: =N6-$D6 -> -682762.5 | P6: =O6/$D6 -> -0.10390829 | R6: ='Option 8'!R7 -> 6642844.6 | S6: =R6-$D6 -> 72026.011 | T6: =S6/$D6 -> 0.010961497 | V6: ='Option 9'!R7 -> 6904301.7 | W6: =V6-$D6 -> 333483.12 | X6: =W6/$D6 -> 0.050752142 | Z6: ='Option 10'!Q7 -> 6893754.8 | AA6: =Z6-$D6 -> 322936.19 | AB6: =AA6/$D6 -> 0.049147025
A7: 3661 | B7: UTEP | D7: ='Option 1'!C8 -> 8883399.6 | F7: ='Option 2'!C8 -> 7826451.5 | G7: =F7-$D7 -> -1056948.2 | H7: =G7/$D7 -> -0.11898014 | J7: ='Option 6'!Q8 -> 8579739.9 | K7: =J7-$D7 -> -303659.69 | L7: =K7/$D7 -> -0.034182824 | N7: ='Option 7'!Q8 -> 7597492.5 | O7: =N7-$D7 -> -1285907.1 | P7: =O7/$D7 -> -0.14475394 | R7: ='Option 8'!R8 -> 8821676.3 | S7: =R7-$D7 -> -61723.308 | T7: =S7/$D7 -> -0.0069481629 | V7: ='Option 9'!R8 -> 8133051.9 | W7: =V7-$D7 -> -750347.73 | X7: =W7/$D7 -> -0.084466281 | Z7: ='Option 10'!Q8 -> 8144354.9 | AA7: =Z7-$D7 -> -739044.75 | AB7: =AA7/$D7 -> -0.08319391
A8: 3599 | B8: UTPA | D8: ='Option 1'!C9 -> 7852361.8 | F8: ='Option 2'!C9 -> 6535642.4 | G8: =F8-$D8 -> -1316719.4 | H8: =G8/$D8 -> -0.1676845 | J8: ='Option 6'!Q9 -> 7744949.2 | K8: =J8-$D8 -> -107412.55 | L8: =K8/$D8 -> -0.013679011 | N8: ='Option 7'!Q9 -> 7064082.9 | O8: =N8-$D8 -> -788278.83 | P8: =O8/$D8 -> -0.10038748 | R8: ='Option 8'!R9 -> 7749796.1 | S8: =R8-$D8 -> -102565.71 | T8: =S8/$D8 -> -0.013061766 | V8: ='Option 9'!R9 -> 7526727.7 | W8: =V8-$D8 -> -325634.05 | X8: =W8/$D8 -> -0.041469568 | Z8: ='Option 10'!Q9 -> 7513586.6 | AA8: =Z8-$D8 -> -338775.12 | AB8: =AA8/$D8 -> -0.043143086
A9: 30646 | B9: UTB | D9: ='Option 1'!C10 -> 2590654.6 | F9: ='Option 2'!C10 -> 2612612.5 | G9: =F9-$D9 -> 21957.852 | H9: =G9/$D9 -> 0.0084757928 | J9: ='Option 6'!Q10 -> 3096284.9 | K9: =J9-$D9 -> 505630.26 | L9: =K9/$D9 -> 0.19517471 | N9: ='Option 7'!Q10 -> 3765595.4 | O9: =N9-$D9 -> 1174940.8 | P9: =O9/$D9 -> 0.45353047 | R9: ='Option 8'!R10 -> 2825898.7 | S9: =R9-$D9 -> 235244.07 | T9: =S9/$D9 -> 0.090804875 | V9: ='Option 9'!R10 -> 2915926 | W9: =V9-$D9 -> 325271.37 | X9: =W9/$D9 -> 0.12555567 | Z9: ='Option 10'!Q10 -> 2917013.8 | AA9: =Z9-$D9 -> 326359.18 | AB9: =AA9/$D9 -> 0.12597557
A10: 9930 | B10: UTPB | D10: ='Option 1'!C11 -> 1383139.9 | F10: ='Option 2'!C11 -> 1418846.8 | G10: =F10-$D10 -> 35706.926 | H10: =G10/$D10 -> 0.025815846 | J10: ='Option 6'!Q11 -> 1667022.6 | K10: =J10-$D10 -> 283882.77 | L10: =K10/$D10 -> 0.20524516 | N10: ='Option 7'!Q11 -> 2141129.2 | O10: =N10-$D10 -> 757989.31 | P10: =O10/$D10 -> 0.54802072 | R10: ='Option 8'!R11 -> 1452715.6 | S10: =R10-$D10 -> 69575.706 | T10: =S10/$D10 -> 0.050302726 | V10: ='Option 9'!R11 -> 1443317 | W10: =V10-$D10 -> 60177.136 | X10: =W10/$D10 -> 0.043507629 | Z10: ='Option 10'!Q11 -> 1445036 | AA10: =Z10-$D10 -> 61896.134 | AB10: =AA10/$D10 -> 0.044750452
A11: 10115 | B11: UTSA | D11: ='Option 1'!C12 -> 11812969 | F11: ='Option 2'!C12 -> 10158026 | G11: =F11-$D11 -> -1654943.4 | H11: =G11/$D11 -> -0.14009547 | J11: ='Option 6'!Q12 -> 11125839 | K11: =J11-$D11 -> -687130.4 | L11: =K11/$D11 -> -0.058167459 | N11: ='Option 7'!Q12 -> 10655166 | O11: =N11-$D11 -> -1157802.6 | P11: =O11/$D11 -> -0.098011144 | R11: ='Option 8'!R12 -> 12359127 | S11: =R11-$D11 -> 546157.74 | T11: =S11/$D11 -> 0.04623374 | V11: ='Option 9'!R12 -> 11562256 | W11: =V11-$D11 -> -250713.52 | X11: =W11/$D11 -> -0.021223582 | Z11: ='Option 10'!Q12 -> 11568221 | AA11: =Z11-$D11 -> -244747.87 | AB11: =AA11/$D11 -> -0.020718573
A12: 11163 | B12: UTT | D12: ='Option 1'!C13 -> 3168830.6 | F12: ='Option 2'!C13 -> 3008543.5 | G12: =F12-$D12 -> -160287.17 | H12: =G12/$D12 -> -0.050582435 | J12: ='Option 6'!Q13 -> 3547504.1 | K12: =J12-$D12 -> 378673.5 | L12: =K12/$D12 -> 0.11949944 | N12: ='Option 7'!Q13 -> 3610320.1 | O12: =N12-$D12 -> 441489.45 | P12: =O12/$D12 -> 0.13932251 | R12: ='Option 8'!R13 -> 3132120 | S12: =R12-$D12 -> -36710.655 | T12: =S12/$D12 -> -0.011584922 | V12: ='Option 9'!R13 -> 3127819.3 | W12: =V12-$D12 -> -41011.373 | X12: =W12/$D12 -> -0.012942116 | Z12: ='Option 10'!Q13 -> 3128223.8 | AA12: =Z12-$D12 -> -40606.805 | AB12: =AA12/$D12 -> -0.012814445
A13: 3632 | B13: TAMU | D13: ='Option 1'!C14 -> 25542032 | F13: ='Option 2'!C14 -> 24708667 | G13: =F13-$D13 -> -833365.68 | H13: =G13/$D13 -> -0.032627227 | J13: ='Option 6'!Q14 -> 23153423 | K13: =J13-$D13 -> -2388609.6 | L13: =K13/$D13 -> -0.093516819 | N13: ='Option 7'!Q14 -> 24741373 | O13: =N13-$D13 -> -800659.46 | P13: =O13/$D13 -> -0.031346741 | R13: ='Option 8'!R14 -> 24717598 | S13: =R13-$D13 -> -824434.5 | T13: =S13/$D13 -> -0.032277561 | V13: ='Option 9'!R14 -> 25182991 | W13: =V13-$D13 -> -359040.97 | X13: =W13/$D13 -> -0.014056868 | Z13: ='Option 10'!Q14 -> 25181222 | AA13: =Z13-$D13 -> -360810.26 | AB13: =AA13/$D13 -> -0.014126137
A14: 10298 | B14: TAMUG | D14: ='Option 1'!C15 -> 1408144 | F14: ='Option 2'!C15 -> 1417888.6 | G14: =F14-$D14 -> 9744.6158 | H14: =G14/$D14 -> 0.0069201842 | J14: ='Option 6'!Q15 -> 1693974.4 | K14: =J14-$D14 -> 285830.38 | L14: =K14/$D14 -> 0.20298377 | N14: ='Option 7'!Q15 -> 1992543.7 | O14: =N14-$D14 -> 584399.75 | P14: =O14/$D14 -> 0.41501419 | R14: ='Option 8'!R15 -> 1472585.1 | S14: =R14-$D14 -> 64441.103 | T14: =S14/$D14 -> 0.045763148 | V14: ='Option 9'!R15 -> 1345133.7 | W14: =V14-$D14 -> -63010.293 | X14: =W14/$D14 -> -0.044747052 | Z14: ='Option 10'!Q15 -> 1344340.5 | AA14: =Z14-$D14 -> -63803.452 | AB14: =AA14/$D14 -> -0.045310318
A15: 3630 | B15: Prairie View | D15: ='Option 1'!C16 -> 3149682.8 | F15: ='Option 2'!C16 -> 2716765.1 | G15: =F15-$D15 -> -432917.7 | H15: =G15/$D15 -> -0.13744803 | J15: ='Option 6'!Q16 -> 3197075.6 | K15: =J15-$D15 -> 47392.834 | L15: =K15/$D15 -> 0.015046859 | N15: ='Option 7'!Q16 -> 3168391.6 | O15: =N15-$D15 -> 18708.844 | P15: =O15/$D15 -> 0.0059399138 | R15: ='Option 8'!R16 -> 3094010.1 | S15: =R15-$D15 -> -55672.683 | T15: =S15/$D15 -> -0.017675648 | V15: ='Option 9'!R16 -> 2868100.6 | W15: =V15-$D15 -> -281582.14 | X15: =W15/$D15 -> -0.089400158 | Z15: ='Option 10'!Q16 -> 2862344.1 | AA15: =Z15-$D15 -> -287338.7 | AB15: =AA15/$D15 -> -0.091227822
... A41: 20 | B41: SRRG | D41: ='Option 1'!C42 -> 375800.56 | F41: ='Option 2'!C42 -> 749091.19 | G41: =F41-$D41 -> 373290.63 | H41: =G41/$D41 -> 0.99332111 | J41: ='Option 6'!Q42 -> 864687.93 | K41: =J41-$D41 -> 488887.36 | L41: =K41/$D41 -> 1.3009224 | N41: ='Option 7'!Q42 -> 2291934.6 | O41: =N41-$D41 -> 1916134 | P41: =O41/$D41 -> 5.0988056 | R41: ='Option 8'!R42 -> 419625.37 | S41: =R41-$D41 -> 43824.813 | T41: =S41/$D41 -> 0.11661721 | V41: ='Option 9'!R42 -> 414690.37 | W41: =V41-$D41 -> 38889.808 | X41: =W41/$D41 -> 0.10348523 | Z41: ='Option 10'!Q42 -> 422737.52 | AA41: =Z41-$D41 -> 46936.958 | AB41: =AA41/$D41 -> 0.12489858
B42: Total | D42: =SUM(D4:D41) -> 2.35e+08 | F42: ='Option 2'!C43 -> 2.35e+08 | G42: =F42-$D42 -> 0 | H42: =G42/$D42 -> 0 | J42: ='Option 6'!Q43 -> 235000000 | K42: =J42-$D42 -> 0 | L42: =K42/$D42 -> 0 | N42: ='Option 7'!Q43 -> 235000000 | O42: =N42-$D42 -> 0 | P42: =O42/$D42 -> 0 | R42: ='Option 8'!R43 -> 235000000 | S42: =R42-$D42 -> 0 | T42: =S42/$D42 -> 0 | V42: ='Option 9'!R43 -> 235000000 | W42: =V42-$D42 -> 0 | X42: =W42/$D42 -> 0 | Z42: ='Option 10'!Q43 -> 235000000 | AA42: =Z42-$D42 -> 0 | AB42: =AA42/$D42 -> 0

Sheet Comparison to IO
B1: Outcomes-Based Funding Comparisons to Instruction and Operations Distribution - With Phase-In
F2: Option 1 - As proposed for 2014-2015 Compared to Total I&O | J2: Option 1 - As proposed for 2014-2015 Compared to Undergraduate I&O | N2: Option2 | R2: Option 6 | V2: Option 7 | Z2: Option 8 | AD2: Option 9 | AH2: Option 10
A3: FICE | C3: 2014-2015 Instruction and Operations Percent of Total | D3: 2014-2015 Undergraduate Instruction and Operations Percent of Total | F3: 2014-2015 Proposed Model | G3: Percent Difference From 2014-2015 I&O | H3: Difference (Millions) | J3: 2014-2015 Proposed Model | K3: Percent Difference From 2014-2015 Undergraduate I&O | L3: Difference (Millions) | N3: Option 2 - Option 1 Scaled, Weighted, and Monetized by Accountability Group Percent of Total | O3: Percent Difference From 2014-2015 I&O | P3: Difference (Millions) | R3: Option 6 - Option 2 without Monetization, At-Risk Weight of 1 | S3: Percent Difference From 2014-2015 I&O | T3: Difference (Millions) | V3: Option 7 - Option 6 with Optimal Weights | W3: Percent Difference From 2014-2015 I&O | X3: Difference (Millions) | Z3: Option 8 - Option 7 with Student Characteristic Adjusted (SAT or GPA) | AA3: Percent Difference From 2014-2015 I&O | AB3: Difference (Millions) | AD3: Option 9 - Option 7 with Transfer Grads | AE3: Percent Difference From 2014-2015 I&O | AF3: Difference (Millions) | AH3: Option 10 - Option 7 with Modified Weights | AI3: Percent Difference From 2014-2015 I&O | AJ3: Difference (Millions)
A4: 3656 | B4: UTA | C4: 0.055594621 | D4: 0.053941374 | F4: ='Option 1'!C5/'Option 1'!$C$43 -> 0.05743312 | G4: =F4-$C4 -> 0.0018384992 | H4: =G4*'Option 1'!$C$43/1000000 -> 0.4320473 | J4: =F4 -> 0.05743312 | K4: =J4-$D4 -> 0.0034917461 | L4: =K4*'Option 2'!$C$43/1000000 -> 0.82056032 | N4: ='Option 2'!C5/'Option 2'!$C$43 -> 0.06893805 | O4: =N4-$D4 -> 0.014996676 | P4: =O4*'Option 2'!$C$43/1000000 -> 3.5242189 | R4: ='Option 6'!Q5/'Option 6'!$Q$43 -> 0.057519829 | S4: =R4-$D4 -> 0.0035784552 | T4: =S4*'Option 6'!$Q$43/1000000 -> 0.84093698 | V4: ='Option 7'!Q5/'Option 7'!$Q$43 -> 0.047310965 | W4: =V4-$D4 -> -0.0066304095 | X4: =W4*'Option 7'!$Q$43/1000000 -> -1.5581462 | Z4: ='Option 8'!R5/'Option 8'!$R$43 -> 0.056572716 | AA4: =Z4-$D4 -> 0.0026313423 | AB4: =AA4*'Option 8'!$R$43/1000000 -> 0.61836543 | AD4: ='Option 9'!R5/'Option 9'!$R$43 -> 0.057977574 | AE4: =AD4-$D4 -> 0.0040361995 | AF4: =AE4*'Option 9'!$R$43/1000000 -> 0.94850688 | AH4: ='Option 10'!Q5/'Option 10'!$Q$43 -> 0.057820007 | AI4: =AH4-$D4 -> 0.0038786325 | AJ4: =AI4*'Option 10'!$Q$43/1000000 -> 0.91147863
A5: 3658 | B5: UT | C5: 0.1201911 | D5: 0.097535368 | F5: ='Option 1'!C6/'Option 1'!$C$43 -> 0.1074438 | G5: =F5-$C5 -> -0.012747303 | H5: =G5*'Option 1'!$C$43/1000000 -> -2.9956163 | J5: =F5 -> 0.1074438 | K5: =J5-$D5 -> 0.0099084331 | L5: =K5*'Option 2'!$C$43/1000000 -> 2.3284818 | N5: ='Option 2'!C6/'Option 2'!$C$43 -> 0.10448755 | O5: =N5-$D5 -> 0.0069521864 | P5: =O5*'Option 2'!$C$43/1000000 -> 1.6337638 | R5: ='Option 6'!Q6/'Option 6'!$Q$43 -> 0.090929114 | S5: =R5-$D5 -> -0.0066062541 | T5: =S5*'Option 6'!$Q$43/1000000 -> -1.5524697 | V5: ='Option 7'!Q6/'Option 7'!$Q$43 -> 0.10693067 | W5: =V5-$D5 -> 0.0093953069 | X5: =W5*'Option 7'!$Q$43/1000000 -> 2.2078971 | Z5: ='Option 8'!R6/'Option 8'!$R$43 -> 0.10246233 | AA5: =Z5-$D5 -> 0.0049269585 | AB5: =AA5*'Option 8'!$R$43/1000000 -> 1.1578352 | AD5: ='Option 9'!R6/'Option 9'!$R$43 -> 0.10752213 | AE5: =AD5-$D5 -> 0.0099867644 | AF5: =AE5*'Option 9'!$R$43/1000000 -> 2.3468896 | AH5: ='Option 10'!Q6/'Option 10'!$Q$43 -> 0.10757936 | AI5: =AH5-$D5 -> 0.010043988 | AJ5: =AI5*'Option 10'!$Q$43/1000000 -> 2.3603371
A6: 9741 | B6: UTD | C6: 0.04471444 | D6: 0.030845131 | F6: ='Option 1'!C7/'Option 1'!$C$43 -> 0.02796093 | G6: =F6-$C6 -> -0.01675351 | H6: =G6*'Option 1'!$C$43/1000000 -> -3.9370748 | J6: =F6 -> 0.02796093 | K6: =J6-$D6 -> -0.0028842008 | L6: =K6*'Option 2'!$C$43/1000000 -> -0.67778718 | N6: ='Option 2'!C7/'Option 2'!$C$43 -> 0.034947984 | O6: =N6-$D6 -> 0.0041028535 | P6: =O6*'Option 2'!$C$43/1000000 -> 0.96417056 | R6: ='Option 6'!Q7/'Option 6'!$Q$43 -> 0.029013339 | S6: =R6-$D6 -> -0.0018317919 | T6: =S6*'Option 6'!$Q$43/1000000 -> -0.4304711 | V6: ='Option 7'!Q7/'Option 7'!$Q$43 -> 0.025055558 | W6: =V6-$D6 -> -0.0057895731 | X6: =W6*'Option 7'!$Q$43/1000000 -> -1.3605497 | Z6: ='Option 8'!R7/'Option 8'!$R$43 -> 0.028267424 | AA6: =Z6-$D6 -> -0.0025777071 | AB6: =AA6*'Option 8'!$R$43/1000000 -> -0.60576117 | AD6: ='Option 9'!R7/'Option 9'!$R$43 -> 0.029380007 | AE6: =AD6-$D6 -> -0.0014651237 | AF6: =AE6*'Option 9'!$R$43/1000000 -> -0.34430406 | AH6: ='Option 10'!Q7/'Option 10'!$Q$43 -> 0.029335127 | AI6: =AH6-$D6 -> -0.0015100042 | AJ6: =AI6*'Option 10'!$Q$43/1000000 -> -0.35485099
A7: 3661 | B7: UTEP | C7: 0.033143125 | D7: 0.0380679 | F7: ='Option 1'!C8/'Option 1'!$C$43 -> 0.0378017 | G7: =F7-$C7 -> 0.004658575 | H7: =G7*'Option 1'!$C$43/1000000 -> 1.0947651 | J7: =F7 -> 0.0378017 | K7: =J7-$D7 -> -0.00026619948 | L7: =K7*'Option 2'!$C$43/1000000 -> -0.062556878 | N7: ='Option 2'!C8/'Option 2'!$C$43 -> 0.033304049 | O7: =N7-$D7 -> -0.0047638512 | P7: =O7*'Option 2'!$C$43/1000000 -> -1.119505 | R7: ='Option 6'!Q8/'Option 6'!$Q$43 -> 0.036509532 | S7: =R7-$D7 -> -0.0015583684 | T7: =S7*'Option 6'!$Q$43/1000000 -> -0.36621656 | V7: ='Option 7'!Q8/'Option 7'!$Q$43 -> 0.032329755 | W7: =V7-$D7 -> -0.0057381445 | X7: =W7*'Option 7'!$Q$43/1000000 -> -1.348464 | Z7: ='Option 8'!R8/'Option 8'!$R$43 -> 0.037539048 | AA7: =Z7-$D7 -> -0.00052885185 | AB7: =AA7*'Option 8'!$R$43/1000000 -> -0.12428019 | AD7: ='Option 9'!R8/'Option 9'!$R$43 -> 0.034608731 | AE7: =AD7-$D7 -> -0.0034591686 | AF7: =AE7*'Option 9'!$R$43/1000000 -> -0.81290461 | AH7: ='Option 10'!Q8/'Option 10'!$Q$43 -> 0.034656829 | AI7: =AH7-$D7 -> -0.0034110708 | AJ7: =AI7*'Option 10'!$Q$43/1000000 -> -0.80160163
A8: 3599 | B8: UTPA | C8: 0.027407848 | D8: 0.036041181 | F8: ='Option 1'!C9/'Option 1'!$C$43 -> 0.033414305 | G8: =F8-$C8 -> 0.0060064575 | H8: =G8*'Option 1'!$C$43/1000000 -> 1.4115175 | J8: =F8 -> 0.033414305 | K8: =J8-$D8 -> -0.0026268755 | L8: =K8*'Option 2'!$C$43/1000000 -> -0.61731575 | N8: ='Option 2'!C9/'Option 2'!$C$43 -> 0.027811244 | O8: =N8-$D8 -> -0.0082299367 | P8: =O8*'Option 2'!$C$43/1000000 -> -1.9340351 | R8: ='Option 6'!Q9/'Option 6'!$Q$43 -> 0.032957231 | S8: =R8-$D8 -> -0.0030839502 | T8: =S8*'Option 6'!$Q$43/1000000 -> -0.72472829 | V8: ='Option 7'!Q9/'Option 7'!$Q$43 -> 0.030059927 | W8: =V8-$D8 -> -0.0059812535 | X8: =W8*'Option 7'!$Q$43/1000000 -> -1.4055946 | Z8: ='Option 8'!R9/'Option 8'!$R$43 -> 0.032977856 | AA8: =Z8-$D8 -> -0.0030633253 | AB8: =AA8*'Option 8'!$R$43/1000000 -> -0.71988146 | AD8: ='Option 9'!R9/'Option 9'!$R$43 -> 0.032028629 | AE8: =AD8-$D8 -> -0.0040125523 | AF8: =AE8*'Option 9'!$R$43/1000000 -> -0.9429498 | AH8: ='Option 10'!Q9/'Option 10'!$Q$43 -> 0.031972709 | AI8: =AH8-$D8 -> -0.0040684718 | AJ8: =AI8*'Option 10'!$Q$43/1000000 -> -0.95609087
A9: 30646 | B9: UTB | C9: 0.0098207333 | D9: 0.013127311 | F9: ='Option 1'!C10/'Option 1'!$C$43 -> 0.011024062 | G9: =F9-$C9 -> 0.0012033289 | H9: =G9*'Option 1'!$C$43/1000000 -> 0.28278228 | J9: =F9 -> 0.011024062 | K9: =J9-$D9 -> -0.0021032491 | L9: =K9*'Option 2'!$C$43/1000000 -> -0.49426354 | N9: ='Option 2'!C10/'Option 2'!$C$43 -> 0.0111175 | O9: =N9-$D9 -> -0.0020098114 | P9: =O9*'Option 2'!$C$43/1000000 -> -0.47230568 | R9: ='Option 6'!Q10/'Option 6'!$Q$43 -> 0.01317568 | S9: =R9-$D9 -> 4.8369039e-05 | T9: =S9*'Option 6'!$Q$43/1000000 -> 0.011366724 | V9: ='Option 7'!Q10/'Option 7'!$Q$43 -> 0.01602381 | W9: =V9-$D9 -> 0.002896499 | X9: =W9*'Option 7'!$Q$43/1000000 -> 0.68067727 | Z9: ='Option 8'!R10/'Option 8'!$R$43 -> 0.012025101 | AA9: =Z9-$D9 -> -0.0011022105 | AB9: =AA9*'Option 8'!$R$43/1000000 -> -0.25901947 | AD9: ='Option 9'!R10/'Option 9'!$R$43 -> 0.012408196 | AE9: =AD9-$D9 -> -0.00071911561 | AF9: =AE9*'Option 9'!$R$43/1000000 -> -0.16899217 | AH9: ='Option 10'!Q10/'Option 10'!$Q$43 -> 0.012412825 | AI9: =AH9-$D9 -> -0.0007144866 | AJ9: =AI9*'Option 10'!$Q$43/1000000 -> -0.16790435
A10: 9930 | B10: UTPB | C10: 0.0050772741 | D10: 0.006658598 | F10: ='Option 1'!C11/'Option 1'!$C$43 -> 0.0058857016 | G10: =F10-$C10 -> 0.00080842752 | H10: =G10*'Option 1'!$C$43/1000000 -> 0.18998047 | J10: =F10 -> 0.0058857016 | K10: =J10-$D10 -> -0.00077289639 | L10: =K10*'Option 2'!$C$43/1000000 -> -0.18163065 | N10: ='Option 2'!C11/'Option 2'!$C$43 -> 0.006037646 | O10: =N10-$D10 -> -0.00062095202 | P10: =O10*'Option 2'!$C$43/1000000 -> -0.14592372 | R10: ='Option 6'!Q11/'Option 6'!$Q$43 -> 0.0070937134 | S10: =R10-$D10 -> 0.00043511538 | T10: =S10*'Option 6'!$Q$43/1000000 -> 0.10225211 | V10: ='Option 7'!Q11/'Option 7'!$Q$43 -> 0.009111188 | W10: =V10-$D10 -> 0.00245259 | X10: =W10*'Option 7'!$Q$43/1000000 -> 0.57635865 | Z10: ='Option 8'!R11/'Option 8'!$R$43 -> 0.0061817684 | AA10: =Z10-$D10 -> -0.00047682955 | AB10: =AA10*'Option 8'!$R$43/1000000 -> -0.11205495 | AD10: ='Option 9'!R11/'Option 9'!$R$43 -> 0.0061417745 | AE10: =AD10-$D10 -> -0.00051682347 | AF10: =AE10*'Option 9'!$R$43/1000000 -> -0.12145351 | AH10: ='Option 10'!Q11/'Option 10'!$Q$43 -> 0.0061490894 | AI10: =AH10-$D10 -> -0.00050950858 | AJ10: =AI10*'Option 10'!$Q$43/1000000 -> -0.11973452
A11: 10115 | B11: UTSA | C11: 0.044912894 | D11: 0.051993931 | F11: ='Option 1'!C12/'Option 1'!$C$43 -> 0.050267953 | G11: =F11-$C11 -> 0.0053550593 | H11: =G11*'Option 1'!$C$43/1000000 -> 1.2584389 | J11: =F11 -> 0.050267953 | K11: =J11-$D11 -> -0.0017259779 | L11: =K11*'Option 2'!$C$43/1000000 -> -0.40560481 | N11: ='Option 2'!C12/'Option 2'!$C$43 -> 0.043225641 | O11: =N11-$D11 -> -0.0087682904 | P11: =O11*'Option 2'!$C$43/1000000 -> -2.0605482 | R11: ='Option 6'!Q12/'Option 6'!$Q$43 -> 0.047343994 | S11: =R11-$D11 -> -0.0046499371 | T11: =S11*'Option 6'!$Q$43/1000000 -> -1.0927352 | V11: ='Option 7'!Q12/'Option 7'!$Q$43 -> 0.045341134 | W11: =V11-$D11 -> -0.0066527975 | X11: =W11*'Option 7'!$Q$43/1000000 -> -1.5634074 | Z11: ='Option 8'!R12/'Option 8'!$R$43 -> 0.052592029 | AA11: =Z11-$D11 -> 0.00059809756 | AB11: =AA11*'Option 8'!$R$43/1000000 -> 0.14055293 | AD11: ='Option 9'!R12/'Option 9'!$R$43 -> 0.049201087 | AE11: =AD11-$D11 -> -0.002792844 | AF11: =AE11*'Option 9'!$R$43/1000000 -> -0.65631833 | AH11: ='Option 10'!Q12/'Option 10'!$Q$43 -> 0.049226473 | AI11: =AH11-$D11 -> -0.0027674582 | AJ11: =AI11*'Option 10'!$Q$43/1000000 -> -0.65035268
A12: 11163 | B12: UTT | C12: 0.010834468 | D12: 0.012069402 | F12: ='Option 1'!C13/'Option 1'!$C$43 -> 0.013484386 | G12: =F12-$C12 -> 0.002649918 | H12: =G12*'Option 1'!$C$43/1000000 -> 0.62273073 | J12: =F12 -> 0.013484386 | K12: =J12-$D12 -> 0.0014149841 | L12: =K12*'Option 2'!$C$43/1000000 -> 0.33252127 | N12: ='Option 2'!C13/'Option 2'!$C$43 -> 0.012802313 | O12: =N12-$D12 -> 0.00073291106 | P12: =O12*'Option 2'!$C$43/1000000 -> 0.1722341 | R12: ='Option 6'!Q13/'Option 6'!$Q$43 -> 0.015095762 | S12: =R12-$D12 -> 0.0030263607 | T12: =S12*'Option 6'!$Q$43/1000000 -> 0.71119477 | V12: ='Option 7'!Q13/'Option 7'!$Q$43 -> 0.015363064 | W12: =V12-$D12 -> 0.0032936627 | X12: =W12*'Option 7'!$Q$43/1000000 -> 0.77401073 | Z12: ='Option 8'!R13/'Option 8'!$R$43 -> 0.01332817 | AA12: =Z12-$D12 -> 0.0012587686 | AB12: =AA12*'Option 8'!$R$43/1000000 -> 0.29581062 | AD12: ='Option 9'!R13/'Option 9'!$R$43 -> 0.013309869 | AE12: =AD12-$D12 -> 0.0012404677 | AF12: =AE12*'Option 9'!$R$43/1000000 -> 0.2915099 | AH12: ='Option 10'!Q13/'Option 10'!$Q$43 -> 0.013311591 | AI12: =AH12-$D12 -> 0.0012421892 | AJ12: =AI12*'Option 10'!$Q$43/1000000 -> 0.29191447
A13: 3632 | B13: TAMU | C13: 0.12924678 | D13: 0.10514316 | F13: ='Option 1'!C14/'Option 1'!$C$43 -> 0.1086895 | G13: =F13-$C13 -> -0.020557277 | H13: =G13*'Option 1'!$C$43/1000000 -> -4.8309601 | J13: =F13 -> 0.1086895 | K13: =J13-$D13 -> 0.0035463352 | L13: =K13*'Option 2'!$C$43/1000000 -> 0.83338876 | N13: ='Option 2'!C14/'Option 2'!$C$43 -> 0.10514326 | O13: =N13-$D13 -> 9.8200533e-08 | P13: =O13*'Option 2'!$C$43/1000000 -> 2.3077125e-05 | R13: ='Option 6'!Q14/'Option 6'!$Q$43 -> 0.098525203 | S13: =R13-$D13 -> -0.0066179611 | T13: =S13*'Option 6'!$Q$43/1000000 -> -1.5552209 | V13: ='Option 7'!Q14/'Option 7'!$Q$43 -> 0.10528244 | W13: =V13-$D13 -> 0.0001392736 | X13: =W13*'Option 7'!$Q$43/1000000 -> 0.032729297 | Z13: ='Option 8'!R14/'Option 8'!$R$43 -> 0.10518127 | AA13: =Z13-$D13 -> 3.8103251e-05 | AB13: =AA13*'Option 8'!$R$43/1000000 -> 0.008954264 | AD13: ='Option 9'!R14/'Option 9'!$R$43 -> 0.10716167 | AE13: =AD13-$D13 -> 0.0020185012 | AF13: =AE13*'Option 9'!$R$43/1000000 -> 0.47434779 | AH13: ='Option 10'!Q14/'Option 10'!$Q$43 -> 0.10715414 | AI13: =AH13-$D13 -> 0.0020109723 | AJ13: =AI13*'Option 10'!$Q$43/1000000 -> 0.4725785
A14: 10298 | B14: TAMUG | C14: 0.0051146603 | D14: 0.0070859753 | F14: ='Option 1'!C15/'Option 1'!$C$43 -> 0.0059921021 | G14: =F14-$C14 -> 0.00087744178 | H14: =G14*'Option 1'!$C$43/1000000 -> 0.20619882 | J14: =F14 -> 0.0059921021 | K14: =J14-$D14 -> -0.0010938731 | L14: =K14*'Option 2'!$C$43/1000000 -> -0.25706019 | N14: ='Option 2'!C15/'Option 2'!$C$43 -> 0.0060335686 | O14: =N14-$D14 -> -0.0010524067 | P14: =O14*'Option 2'!$C$43/1000000 -> -0.24731557 | R14: ='Option 6'!Q15/'Option 6'!$Q$43 -> 0.0072084016 | S14: =R14-$D14 -> 0.00012242635 | T14: =S14*'Option 6'!$Q$43/1000000 -> 0.028770191 | V14: ='Option 7'!Q15/'Option 7'!$Q$43 -> 0.0084789096 | W14: =V14-$D14 -> 0.0013929343 | X14: =W14*'Option 7'!$Q$43/1000000 -> 0.32733956 | Z14: ='Option 8'!R15/'Option 8'!$R$43 -> 0.0062663196 | AA14: =Z14-$D14 -> -0.00081965567 | AB14: =AA14*'Option 8'!$R$43/1000000 -> -0.19261908 | AD14: ='Option 9'!R15/'Option 9'!$R$43 -> 0.0057239732 | AE14: =AD14-$D14 -> -0.001362002 | AF14: =AE14*'Option 9'!$R$43/1000000 -> -0.32007048 | AH14: ='Option 10'!Q15/'Option 10'!$Q$43 -> 0.0057205981 | AI14: =AH14-$D14 -> -0.0013653772 | AJ14: =AI14*'Option 10'!$Q$43/1000000 -> -0.32086364
A15: 3630 | B15: Prairie View | C15: 0.012996729 | D15: 0.015279411 | F15: ='Option 1'!C16/'Option 1'!$C$43 -> 0.013402905 | G15: =F15-$C15 -> 0.00040617689 | H15: =G15*'Option 1'!$C$43/1000000 -> 0.095451569 | J15: =F15 -> 0.013402905 | K15: =J15-$D15 -> -0.0018765054 | L15: =K15*'Option 2'!$C$43/1000000 -> -0.44097876 | N15: ='Option 2'!C16/'Option 2'!$C$43 -> 0.011560702 | O15: =N15-$D15 -> -0.0037187084 | P15: =O15*'Option 2'!$C$43/1000000 -> -0.87389646 | R15: ='Option 6'!Q16/'Option 6'!$Q$43 -> 0.013604577 | S15: =R15-$D15 -> -0.0016748337 | T15: =S15*'Option 6'!$Q$43/1000000 -> -0.39358593 | V15: ='Option 7'!Q16/'Option 7'!$Q$43 -> 0.013482518 | W15: =V15-$D15 -> -0.0017968933 | X15: =W15*'Option 7'!$Q$43/1000000 -> -0.42226992 | Z15: ='Option 8'!R16/'Option 8'!$R$43 -> 0.013166 | AA15: =Z15-$D15 -> -0.0021134104 | AB15: =AA15*'Option 8'!$R$43/1000000 -> -0.49665144 | AD15: ='Option 9'!R16/'Option 9'!$R$43 -> 0.012204684 | AE15: =AD15-$D15 -> -0.0030747272 | AF15: =AE15*'Option 9'!$R$43/1000000 -> -0.7225609 | AH15: ='Option 10'!Q16/'Option 10'!$Q$43 -> 0.012180188 | AI15: =AH15-$D15 -> -0.0030992232 | AJ15: =AI15*'Option 10'!$Q$43/1000000 -> -0.72831746
... A41: 20 | B41: SRRG | C41: 0.0011186188 | D41: 0.0014792799 | F41: ='Option 1'!C42/'Option 1'!$C$43 -> 0.0015991513 | G41: =F41-$C41 -> 0.00048053254 | H41: =G41*'Option 1'!$C$43/1000000 -> 0.11292515 | J41: =F41 -> 0.0015991513 | K41: =J41-$D41 -> 0.00011987141 | L41: =K41*'Option 2'!$C$43/1000000 -> 0.028169781 | N41: ='Option 2'!C42/'Option 2'!$C$43 -> 0.0031876221 | O41: =N41-$D41 -> 0.0017083422 | P41: =O41*'Option 2'!$C$43/1000000 -> 0.40146041 | R41: ='Option 6'!Q42/'Option 6'!$Q$43 -> 0.0036795231 | S41: =R41-$D41 -> 0.0022002432 | T41: =S41*'Option 6'!$Q$43/1000000 -> 0.51705715 | V41: ='Option 7'!Q42/'Option 7'!$Q$43 -> 0.009752913 | W41: =V41-$D41 -> 0.0082736331 | X41: =W41*'Option 7'!$Q$43/1000000 -> 1.9443038 | Z41: ='Option 8'!R42/'Option 8'!$R$43 -> 0.0017856399 | AA41: =Z41-$D41 -> 0.00030635998 | AB41: =AA41*'Option 8'!$R$43/1000000 -> 0.071994595 | AD41: ='Option 9'!R42/'Option 9'!$R$43 -> 0.0017646399 | AE41: =AD41-$D41 -> 0.00028535995 | AF41: =AE41*'Option 9'!$R$43/1000000 -> 0.067059589 | AH41: ='Option 10'!Q42/'Option 10'!$Q$43 -> 0.0017988831 | AI41: =AH41-$D41 -> 0.00031960315 | AJ41: =AI41*'Option 10'!$Q$43/1000000 -> 0.075106739
B42: Total | C42: =SUM(C4:C41) -> 1 | D42: =SUM(D4:D41) -> 1 | F42: =SUM(F4:F41) -> 1 | G42: =F42-$C42 -> 0 | H42: =SUM(H4:H41) -> 7.170653e-14 | J42: =SUM(J4:J41) -> 1 | K42: =J42-$D42 -> 0 | L42: =SUM(L4:L41) -> 1.1392276e-13 | N42: ='Option 2'!C43/'Option 2'!$C$43 -> 1 | O42: =N42-$D42 -> 0 | P42: =SUM(P4:P41) -> -4.7961635e-14 | R42: =SUM(R4:R41) -> 1 | S42: =R42-$D42 -> 0 | T42: =SUM(T4:T41) -> 8.5043084e-14 | V42: =SUM(V4:V41) -> 1 | W42: =V42-$D42 -> 0 | X42: =SUM(X4:X41) -> 4.8183679e-14 | Z42: =SUM(Z4:Z41) -> 1 | AA42: =Z42-$D42 -> 0 | AB42: =SUM(AB4:AB41) -> 6.9402817e-14 | AD42: =SUM(AD4:AD41) -> 1 | AE42: =AD42-$D42 -> 0 | AF42: =SUM(AF4:AF41) -> -5.281886e-14 | AH42: =SUM(AH4:AH41) -> 1 | AI42: =AH42-$D42 -> 0 | AJ42: =SUM(AJ4:AJ41) -> 2.0095037e-14
B44: Total Losses | H44: =SUMIF(H4:H41,"<0") -> -22.19944 | L44: =SUMIF(L4:L41,"<0") -> -8.1746703 | P44: =SUMIF(P4:P41,"<0") -> -16.848984 | T44: =SUMIF(T4:T41,"<0") -> -11.069811 | X44: =SUMIF(X4:X41,"<0") -> -21.004629 | AB44: =SUMIF(AB4:AB41,"<0") -> -7.464013 | AF44: =SUMIF(AF4:AF41,"<0") -> -10.435244 | AJ44: =SUMIF(AJ4:AJ41,"<0") -> -10.453903

Sheet Option 1
A1: Option 1 - Outcomes Based Funding (FY 2010 - FY 2012 Averaged) with Total Degrees adjusted by Six-Year Graduation Rate (3-Year Rate for Upper-Levels), Total Degrees per 100 FTSE, Critical Field Degrees (weighted 2), At-Risk Degrees, Retention Metrics of 30, 60, and 90 hours, and Total Degrees adjusted by Cost Based Weights. Funded at 10 percent of undergraduate formula funding.
A3: FICE | B3: Name | C3: Funding | D3: Total Undergraduate Degrees | H3: Undergraduate Critical Field Degrees | I3: Math and Science Teaching Certificates | J3: At-Risk Degrees | K3: Retention Metrics
E4: Adjusted by 6-Year Graduation Rate | F4: per 100 FTSE | G4: Cost Weighted | K4: 30 Hours | L4: 60 Hours | M4: 90 Hours
A5: 3656 | B5: UTA | C5: =C49/$C$87*$C$43 -> 13496783 | D5: =D49/$C$87*$C$43 -> 1841931 | E5: =E49/$C$87*$C$43 -> 954734.24 | F5: =F49/$C$87*$C$43 -> 10866.508 | G5: =G49/$C$87*$C$43 -> 3824283.9 | H5: =H49/$C$87*$C$43 -> 1124197 | I5: =I49/$C$87*$C$43 -> 25694.534 | J5: =J49/$C$87*$C$43 -> 1143773.8 | ... M5: =M49/$C$87*$C$43 -> 654721.19
A6: 3658 | B6: UT | C6: =C50/$C$87*$C$43 -> 25249293 | D6: =D50/$C$87*$C$43 -> 3283883.8 | E6: =E50/$C$87*$C$43 -> 2722339.6 | F6: =F50/$C$87*$C$43 -> 9726.3692 | G6: =G50/$C$87*$C$43 -> 7120450.8 | H6: =H50/$C$87*$C$43 -> 1377471.7 | I6: =I50/$C$87*$C$43 -> 48452.549 | J6: =J50/$C$87*$C$43 -> 1273837.1 | ... M6: =M50/$C$87*$C$43 -> 2584258.3
A7: 9741 | B7: UTD | C7: =C51/$C$87*$C$43 -> 6570818.6 | D7: =D51/$C$87*$C$43 -> 878385.99 | E7: =E51/$C$87*$C$43 -> 617505.35 | F7: =F51/$C$87*$C$43 -> 9848.2598 | G7: =G51/$C$87*$C$43 -> 1872472 | H7: =H51/$C$87*$C$43 -> 309557.95 | I7: =I51/$C$87*$C$43 -> 23492.145 | J7: =J51/$C$87*$C$43 -> 484403.14 | ... M7: =M51/$C$87*$C$43 -> 374895.48
A8: 3661 | B8: UTEP | C8: =C52/$C$87*$C$43 -> 8883399.6 | D8: =D52/$C$87*$C$43 -> 1122117 | E8: =E52/$C$87*$C$43 -> 437625.63 | F8: =F52/$C$87*$C$43 -> 8395.0996 | G8: =G52/$C$87*$C$43 -> 2311802 | H8: =H52/$C$87*$C$43 -> 480854.85 | I8: =I52/$C$87*$C$43 -> 66071.658 | J8: =J52/$C$87*$C$43 -> 904569.94 | ... M8: =M52/$C$87*$C$43 -> 717978.69
A9: 3599 | B9: UTPA | C9: =C53/$C$87*$C$43 -> 7852361.8 | D9: =D53/$C$87*$C$43 -> 947027.1 | E9: =E53/$C$87*$C$43 -> 408168.68 | F9: =F53/$C$87*$C$43 -> 7522.0713 | G9: =G53/$C$87*$C$43 -> 1884571.7 | H9: =H53/$C$87*$C$43 -> 381992.07 | I9: =I53/$C$87*$C$43 -> 20555.627 | J9: =J53/$C$87*$C$43 -> 858319.78 | ... M9: =M53/$C$87*$C$43 -> 711860.94
A10: 30646 | B10: UTB | C10: =C54/$C$87*$C$43 -> 2590654.6 | D10: =D54/$C$87*$C$43 -> 400834.73 | E10: =E54/$C$87*$C$43 -> 230579.41 | F10: =F54/$C$87*$C$43 -> 12649.506 | G10: =G54/$C$87*$C$43 -> 770026.02 | H10: =H54/$C$87*$C$43 -> 91276.772 | I10: =I54/$C$87*$C$43 -> 13459.041 | J10: =J54/$C$87*$C$43 -> 343817.33 | ... M10: =M54/$C$87*$C$43 -> 36951.187
A11: 9930 | B11: UTPB | C11: =C55/$C$87*$C$43 -> 1383139.9 | D11: =D55/$C$87*$C$43 -> 195767.88 | E11: =E55/$C$87*$C$43 -> 86920.937 | F11: =F55/$C$87*$C$43 -> 8488.4369 | G11: =G55/$C$87*$C$43 -> 367621.48 | H11: =H55/$C$87*$C$43 -> 30344.021 | I11: =I55/$C$87*$C$43 -> 7341.2953 | J11: =J55/$C$87*$C$43 -> 146458.84 | ... M11: =M55/$C$87*$C$43 -> 71332.92
A12: 10115 | B12: UTSA | C12: =C56/$C$87*$C$43 -> 11812969 | D12: =D56/$C$87*$C$43 -> 1512184.5 | E12: =E56/$C$87*$C$43 -> 637637.79 | F12: =F56/$C$87*$C$43 -> 7429.7705 | G12: =G56/$C$87*$C$43 -> 3088561.3 | H12: =H56/$C$87*$C$43 -> 287778.78 | I12: =I56/$C$87*$C$43 -> 36461.767 | J12: =J56/$C$87*$C$43 -> 1146588 | ... M12: =M56/$C$87*$C$43 -> 960119.08
A13: 11163 | B13: UTT | C13: =C57/$C$87*$C$43 -> 3168830.6 | D13: =D57/$C$87*$C$43 -> 436807.07 | E13: =E57/$C$87*$C$43 -> 225246.85 | F13: =F57/$C$87*$C$43 -> 10738.752 | G13: =G57/$C$87*$C$43 -> 867249.24 | H13: =H57/$C$87*$C$43 -> 276522.12 | I13: =I57/$C$87*$C$43 -> 10277.813 | J13: =J57/$C$87*$C$43 -> 345897.37 | ... M13: =M57/$C$87*$C$43 -> 142176.42
A14: 3632 | B14: TAMU | C14: =C58/$C$87*$C$43 -> 25542032 | D14: =D58/$C$87*$C$43 -> 3208023.7 | E14: =E58/$C$87*$C$43 -> 2696878.6 | F14: =F58/$C$87*$C$43 -> 9265.4072 | G14: =G58/$C$87*$C$43 -> 7379769.9 | H14: =H58/$C$87*$C$43 -> 1294270.4 | I14: =I58/$C$87*$C$43 -> 92500.321 | J14: =J58/$C$87*$C$43 -> 1366949.2 | ... M14: =M58/$C$87*$C$43 -> 2531890.4
A15: 10298 | B15: TAMUG | C15: =C59/$C$87*$C$43 -> 1408144 | D15: =D59/$C$87*$C$43 -> 151597.75 | E15: =E59/$C$87*$C$43 -> 95102.321 | F15: =F59/$C$87*$C$43 -> 9029.4085 | G15: =G59/$C$87*$C$43 -> 387635.08 | H15: =H59/$C$87*$C$43 -> 41111.254 | I15: =I59/$C$87*$C$43 -> 0 | J15: =J59/$C$87*$C$43 -> 86994.35 | ... M15: =M59/$C$87*$C$43 -> 135446.9
A16: 3630 | B16: Prairie View | C16: =C60/$C$87*$C$43 -> 3149682.8 | D16: =D60/$C$87*$C$43 -> 343694.98 | E16: =E60/$C$87*$C$43 -> 127739.97 | F16: =F60/$C$87*$C$43 -> 5808.3184 | G16: =G60/$C$87*$C$43 -> 760888.56 | H16: =H60/$C$87*$C$43 -> 231740.22 | I16: =I60/$C$87*$C$43 -> 7096.5855 | J16: =J60/$C$87*$C$43 -> 294630.65 | ... M16: =M60/$C$87*$C$43 -> 332315.97
... A42: 20 | B42: SRRG | C42: =C86/$C$87*$C$43 -> 375800.56 | D42: =D86/$C$87*$C$43 -> 59342.137 | E42: =E86/$C$87*$C$43 -> 18854.64 | F42: =F86/$C$87*$C$43 -> 13433.252 | G42: =G86/$C$87*$C$43 -> 102473.47 | H42: =H86/$C$87*$C$43 -> 4649.4871 | I42: =I86/$C$87*$C$43 -> 4160.0674 | J42: =J86/$C$87*$C$43 -> 52857.327 | ... M42: =M86/$C$87*$C$43 -> 1590.614
B43: Total | C43: ='Option 2'!C43 -> 2.35e+08 | D43: =SUM(D5:D42) -> 30999904 | E43: =SUM(E5:E42) -> 18029549 | F43: =SUM(F5:F42) -> 376487.21 | G43: =SUM(G5:G42) -> 63433620 | H43: =SUM(H5:H42) -> 10257258 | I43: =SUM(I5:I42) -> 879731.89 | J43: =SUM(J5:J42) -> 20014390 | K43: =SUM(K5:K42) -> 42032158 | ... M43: =SUM(M5:M42) -> 18692773
C44: 0.1 | D44: Percent of Undergraduate Funding
A45: Points Weighted Three-Year Average
A46: FICE | B46: Name | C46: Total Points | D46: Total Undergraduate Degrees | H46: Undergraduate Critical Field Degrees | I46: Math and Science Teaching Certificates | J46: At-Risk Degrees | K46: Retention Metrics
E47: Adjusted by 6-Year Graduation Rate | F47: per 100 FTSE | G47: Cost Weighted | K47: 30 Hours | L47: 60 Hours | M47: 90 Hours
A48: Weights | D48: 1 | E48: 1 | F48: 1 | G48: 1 | H48: 2 | I48: 2 | J48: 1 | K48: 1 | L48: 1 | M48: 1
A49: =A5 -> 3656 | B49: =B5 -> UTA | C49: =SUM(D49:M49) -> 36769.487 | D49: =D91*D$48 -> 5018 | E49: =D91*E91*E$48 -> 2600.9967 | F49: =IFERROR(D91/F91*100*F$48,0) -> 29.603788 | G49: =G91*G$48 -> 10418.553 | H49: =H91*H$48 -> 3062.6667 | I49: =I91*I$48 -> 70 | J49: =J91*J$48 -> 3116 | K49: =K91*K$48 -> 6836.3333 | L49: =L91*L$48 -> 3833.6667 | M49: =M91*M$48 -> 1783.6667
A50: =A6 -> 3658 | B50: =B6 -> UT | C50: =SUM(D50:M50) -> 68787.025 | D50: =D92*D$48 -> 8946.3333 | E50: =D92*E92*E$48 -> 7416.5103 | F50: =IFERROR(D92/F92*100*F$48,0) -> 26.497692 | G50: =G92*G$48 -> 19398.35 | H50: =H92*H$48 -> 3752.6667 | I50: =I92*I$48 -> 132 | J50: =J92*J$48 -> 3470.3333 | K50: =K92*K$48 -> 9598.3333 | L50: =L92*L$48 -> 9005.6667 | M50: =M92*M$48 -> 7040.3333
A51: =A7 -> 9741 | B51: =B7 -> UTD | C51: =SUM(D51:M51) -> 17900.979 | D51: =D93*D$48 -> 2393 | E51: =D93*E93*E$48 -> 1682.279 | F51: =IFERROR(D93/F93*100*F$48,0) -> 26.829761 | G51: =G93*G$48 -> 5101.2033 | H51: =H93*H$48 -> 843.33333 | I51: =I93*I$48 -> 64 | J51: =J93*J$48 -> 1319.6667 | K51: =K93*K$48 -> 3315 | L51: =L93*L$48 -> 2134.3333 | M51: =M93*M$48 -> 1021.3333
A52: =A8 -> 3661 | B52: =B8 -> UTEP | C52: =SUM(D52:M52) -> 24201.178 | D52: =D94*D$48 -> 3057 | E52: =D94*E94*E$48 -> 1192.23 | F52: =IFERROR(D94/F94*100*F$48,0) -> 22.870895 | G52: =G94*G$48 -> 6298.0767 | H52: =H94*H$48 -> 1310 | I52: =I94*I$48 -> 180 | J52: =J94*J$48 -> 2464.3333 | K52: =K94*K$48 -> 4362.6667 | L52: =L94*L$48 -> 3358 | M52: =M94*M$48 -> 1956
A53: =A9 -> 3599 | B53: =B9 -> UTPA | C53: =SUM(D53:M53) -> 21392.306 | D53: =D95*D$48 -> 2580 | E53: =D95*E95*E$48 -> 1111.98 | F53: =IFERROR(D95/F95*100*F$48,0) -> 20.49249 | G53: =G95*G$48 -> 5134.1667 | H53: =H95*H$48 -> 1040.6667 | I53: =I95*I$48 -> 56 | J53: =J95*J$48 -> 2338.3333 | K53: =K95*K$48 -> 4075.3333 | L53: =L95*L$48 -> 3096 | M53: =M95*M$48 -> 1939.3333
A54: =A10 -> 30646 | B54: =B10 -> UTB | C54: =SUM(D54:M54) -> 7057.7588 | D54: =D96*D$48 -> 1092 | E54: =D96*E96*E$48 -> 628.17092 | F54: =IFERROR(D96/F96*100*F$48,0) -> 34.461236 | G54: =G96*G$48 -> 2097.7933 | H54: =H96*H$48 -> 248.66667 | I54: =I96*I$48 -> 36.666667 | J54: =J96*J$48 -> 936.66667 | K54: =K96*K$48 -> 1326.3333 | L54: =L96*L$48 -> 556.33333 | M54: =M96*M$48 -> 100.66667
A55: =A11 -> 9930 | B55: =B11 -> UTPB | C55: =SUM(D55:M55) -> 3768.1085 | D55: =D97*D$48 -> 533.33333 | E55: =D97*E97*E$48 -> 236.8 | F55: =IFERROR(D97/F97*100*F$48,0) -> 23.125175 | G55: =G97*G$48 -> 1001.5167 | H55: =H97*H$48 -> 82.666667 | I55: =I97*I$48 -> 20 | J55: =J97*J$48 -> 399 | K55: =K97*K$48 -> 785.66667 | L55: =L97*L$48 -> 491.66667 | M55: =M97*M$48 -> 194.33333
A56: =A12 -> 10115 | B56: =B12 -> UTSA | C56: =SUM(D56:M56) -> 32182.247 | D56: =D98*D$48 -> 4119.6667 | E56: =D98*E98*E$48 -> 1737.1261 | F56: =IFERROR(D98/F98*100*F$48,0) -> 20.241034 | G56: =G98*G$48 -> 8414.2133 | H56: =H98*H$48 -> 784 | I56: =I98*I$48 -> 99.333333 | J56: =J98*J$48 -> 3123.6667 | K56: =K98*K$48 -> 6809.6667 | L56: =L98*L$48 -> 4458.6667 | M56: =M98*M$48 -> 2615.6667
A57: =A13 -> 11163 | B57: =B13 -> UTT | C57: =SUM(D57:M57) -> 8632.8924 | D57: =D99*D$48 -> 1190 | E57: =D99*E99*E$48 -> 613.64333 | F57: =IFERROR(D99/F99*100*F$48,0) -> 29.255741 | G57: =G99*G$48 -> 2362.66 | H57: =H99*H$48 -> 753.33333 | I57: =I99*I$48 -> 28 | J57: =J99*J$48 -> 942.33333 | K57: =K99*K$48 -> 1436.3333 | L57: =L99*L$48 -> 890 | M57: =M99*M$48 -> 387.33333
A58: =A14 -> 3632 | B58: =B14 -> TAMU | C58: =SUM(D58:M58) -> 69584.538 | D58: =D100*D$48 -> 8739.6667 | E58: =D100*E100*E$48 -> 7347.1464 | F58: =IFERROR(D100/F100*100*F$48,0) -> 25.241887 | G58: =G100*G$48 -> 20104.817 | H58: =H100*H$48 -> 3526 | I58: =I100*I$48 -> 252 | J58: =J100*J$48 -> 3724 | K58: =K100*K$48 -> 10060.667 | L58: =L100*L$48 -> 8907.3333 | M58: =M100*M$48 -> 6897.6667
A59: =A15 -> 10298 | B59: =B15 -> TAMUG | C59: =SUM(D59:M59) -> 3836.2276 | D59: =D101*D$48*1.5 -> 413 | E59: =D101*E101*E$48*1.5 -> 259.08867 | F59: =IFERROR(D101/F101*100*F$48,0)*1.5 -> 24.598952 | G59: =G101*G$48*1.5 -> 1056.04 | H59: =H101*H$48*1.5 -> 112 | I59: =I101*I$48*1.5 -> 0 | J59: =J101*J$48*1.5 -> 237 | K59: =K101*K$48*1.5 -> 888.5 | L59: =L101*L$48*1.5 -> 477 | M59: =M101*M$48*1.5 -> 369
A60: =A16 -> 3630 | B60: =B16 -> Prairie View | C60: =SUM(D60:M60) -> 8580.7276 | D60: =D102*D$48 -> 936.33333 | E60: =D102*E102*E$48 -> 348.00389 | F60: =IFERROR(D102/F102*100*F$48,0) -> 15.823688 | G60: =G102*G$48 -> 2072.9 | H60: =H102*H$48 -> 631.33333 | I60: =I102*I$48 -> 19.333333 | J60: =J102*J$48 -> 802.66667 | K60: =K102*K$48 -> 1668 | L60: =L102*L$48 -> 1181 | M60: =M102*M$48 -> 905.33333
A61: =A17 -> 3631 | B61: =B17 -> Tarleton | C61: =SUM(D61:M61) -> 11473.106 | D61: =D103*D$48 -> 1545.3333 | E61: =D103*E103*E$48 -> 738.66933 | F61: =IFERROR(D103/F103*100*F$48,0) -> 24.559768 | G61: =G103*G$48 -> 3122.5433 | H61: =H103*H$48 -> 406 | I61: =I103*I$48 -> 95.333333 | J61: =J103*J$48 -> 1195 | K61: =K103*K$48 -> 2154.3333 | L61: =L103*L$48 -> 1328.6667 | M61: =M103*M$48 -> 862.66667
A62: =A18 -> 103631 | B62: =B18 -> TAMUCT | C62: =SUM(D62:M62) -> 2671.9105 | D62: =D104*D$48 -> 460.33333 | E62: =D104*E104*E$48 -> 220.03933 | F62: =IFERROR(D104/F104*100*F$48,0) -> 67.58785 | G62: =G104*G$48 -> 853.61667 | H62: =H104*H$48 -> 81.333333 | I62: =I104*I$48 -> 0 | J62: =J104*J$48 -> 327 | K62: =K104*K$48 -> 495 | L62: =L104*L$48 -> 133 | M62: =M104*M$48 -> 34
A63: =A19 -> 11161 | B63: =B19 -> TAMUCC | C63: =SUM(D63:M63) -> 10983.517 | D63: =D105*D$48 -> 1388.3333 | E63: =D105*E105*E$48 -> 705.27333 | F63: =IFERROR(D105/F105*100*F$48,0) -> 21.376514 | G63: =G105*G$48 -> 2804.2 | H63: =H105*H$48 -> 532.66667 | I63: =I105*I$48 -> 51.333333 | J63: =J105*J$48 -> 1080 | K63: =K105*K$48 -> 2054 | L63: =L105*L$48 -> 1468 | M63: =M105*M$48 -> 878.33333
A64: =A20 -> 3639 | B64: =B20 -> TAMUK | C64: =SUM(D64:M64) -> 6696.7767 | D64: =D106*D$48 -> 761.66667 | E64: =D106*E106*E$48 -> 306.44389 | F64: =IFERROR(D106/F106*100*F$48,0) -> 17.879499 | G64: =G106*G$48 -> 1763.4533 | H64: =H106*H$48 -> 520 | I64: =I106*I$48 -> 33.333333 | J64: =J106*J$48 -> 648.33333 | K64: =K106*K$48 -> 1227.3333 | L64: =L106*L$48 -> 859.66667 | M64: =M106*M$48 -> 558.66667
A65: =A21 -> 103639 | B65: =B21 -> TAMUSA | C65: =SUM(D65:M65) -> 3205.7164 | D65: =D107*D$48 -> 587.66667 | E65: =D107*E107*E$48 -> 236.43789 | F65: =IFERROR(D107/F107*100*F$48,0) -> 41.598502 | G65: =G107*G$48 -> 1026.0133 | H65: =H107*H$48 -> 10 | I65: =I107*I$48 -> 4 | J65: =J107*J$48 -> 490.33333 | K65: =K107*K$48 -> 729.66667 | L65: =L107*L$48 -> 77.333333 | M65: =M107*M$48 -> 2.6666667
A66: =A22 -> 9651 | B66: =B22 -> TAMI | C66: =SUM(D66:M66) -> 6525.9317 | D66: =D108*D$48 -> 789.66667 | E66: =D108*E108*E$48 -> 373.77556 | F66: =IFERROR(D108/F108*100*F$48,0) -> 19.326154 | G66: =G108*G$48 -> 1458.4967 | H66: =H108*H$48 -> 231.33333 | I66: =I108*I$48 -> 44.666667 | J66: =J108*J$48 -> 712.66667 | K66: =K108*K$48 -> 1406.6667 | L66: =L108*L$48 -> 1015.6667 | M66: =M108*M$48 -> 473.66667
...

Sheet Option 2
A1: Option 2 - Outcomes Based Funding (FY 2010 - FY 2012 Averaged) with Total Degrees adjusted by Six-Year Graduation Rate (3-Year Rate for Upper-Levels), Total Degrees per 100 FTSE, Critical Field Degrees, At-Risk Degrees, Retention Metrics of 30, 60, and 90 hours, and Total Degrees adjusted by Cost Based Weights. Metrics scaled for mathematical comparability, weighted by accountability group, and monetized using SREB salaries by Carnegie classifications. Funded at 10 percent of undergraduate formula funding.
A3: FICE | B3: Name | C3: Funding | D3: Total Undergraduate Degrees | H3: Undergraduate Critical Field Degrees | I3: Math and Science Teaching Certificates | J3: At-Risk Degrees | K3: Retention Metrics
E4: Adjusted by 6-Year Graduation Rate | F4: per 100 FTSE | G4: Cost Weighted | K4: 30 Hours | L4: 60 Hours | M4: 90 Hours
A5: 3656 | B5: UTA | C5: =SUM(D5:M5) -> 16200442 | D5: =D48*$O48*$C$44 -> 3415726.7 | E5: =E48*$O48*$C$44 -> 1180323.4 | F5: =F48*$O48*$C$44 -> 671704.87 | G5: =G48*$O48*$C$44 -> 7091855.6 | H5: =H48*$O48*$C$44 -> 1042370.7 | I5: =I48*$O48*$C$44 -> 23824.32 | J5: =J48*$O48*$C$44 -> 339367.22 | K5: =K48*$O48*$C$44 -> 1085806.6 | ... M5: =M48*$O48*$C$44 -> 566595.26
A6: 3658 | B6: UT | C6: =SUM(D6:M6) -> 24554575 | D6: =D49*$O49*$C$44 -> 4059815.3 | E6: =E49*$O49*$C$44 -> 4206983.6 | F6: =F49*$O49*$C$44 -> 751535.1 | G6: =G49*$O49*$C$44 -> 8802904.6 | H6: =H49*$O49*$C$44 -> 851473.62 | I6: =I49*$O49*$C$44 -> 29950.573 | J6: =J49*$O49*$C$44 -> 251972.05 | K6: =K49*$O49*$C$44 -> 1524491.7 | ... M6: =M49*$O49*$C$44 -> 2236415.4
A7: 9741 | B7: UTD | C7: =SUM(D7:M7) -> 8212776.3 | D7: =D50*$O50*$C$44 -> 1628902.8 | E7: =E50*$O50*$C$44 -> 763412.43 | F7: =F50*$O50*$C$44 -> 608762.66 | G7: =G50*$O50*$C$44 -> 3472362.8 | H7: =H50*$O50*$C$44 -> 287026.33 | I7: =I50*$O50*$C$44 -> 21782.235 | J7: =J50*$O50*$C$44 -> 143726.45 | K7: =K50*$O50*$C$44 -> 526517.46 | ... M7: =M50*$O50*$C$44 -> 324434.29
A8: 3661 | B8: UTEP | C8: =SUM(D8:M8) -> 7826451.5 | D8: =D51*$O51*$C$44 -> 1596125.9 | E8: =E51*$O51*$C$44 -> 414992.73 | F8: =F51*$O51*$C$44 -> 398046.31 | G8: =G51*$O51*$C$44 -> 3288362.2 | H8: =H51*$O51*$C$44 -> 341989.68 | I8: =I51*$O51*$C$44 -> 46990.949 | J8: =J51*$O51*$C$44 -> 205869.09 | K8: =K51*$O51*$C$44 -> 531496.64 | ... M8: =M51*$O51*$C$44 -> 476592.64
A9: 3599 | B9: UTPA | C9: =SUM(D9:M9) -> 6535642.4 | D9: =D52*$O52*$C$44 -> 1248669.9 | E9: =E52*$O52*$C$44 -> 269088.35 | F9: =F52*$O52*$C$44 -> 247949.18 | G9: =G52*$O52*$C$44 -> 2484836.9 | H9: =H52*$O52*$C$44 -> 251831.22 | I9: =I52*$O52*$C$44 -> 13551.456 | J9: =J52*$O52*$C$44 -> 181073.26 | K9: =K52*$O52*$C$44 -> 657460.71 | ... M9: =M52*$O52*$C$44 -> 531873.13
A10: 30646 | B10: UTB | C10: =SUM(D10:M10) -> 2612612.5 | D10: =D53*$O53*$C$44 -> 528506.78 | E10: =E53*$O53*$C$44 -> 152011.26 | F10: =F53*$O53*$C$44 -> 416964.22 | G10: =G53*$O53*$C$44 -> 1015291.2 | H10: =H53*$O53*$C$44 -> 60174.917 | I10: =I53*$O53*$C$44 -> 8872.977 | J10: =J53*$O53*$C$44 -> 72532.554 | K10: =K53*$O53*$C$44 -> 213973.19 | ... M10: =M53*$O53*$C$44 -> 27608.402
A11: 9930 | B11: UTPB | C11: =SUM(D11:M11) -> 1418846.8 | D11: =D54*$O54*$C$44 -> 258122.97 | E11: =E54*$O54*$C$44 -> 57303.299 | F11: =F54*$O54*$C$44 -> 279803.38 | G11: =G54*$O54*$C$44 -> 484714.6 | H11: =H54*$O54*$C$44 -> 20004.53 | I11: =I54*$O54*$C$44 -> 4839.8057 | J11: =J54*$O54*$C$44 -> 30897.319 | K11: =K54*$O54*$C$44 -> 126749.13 | ... M11: =M54*$O54*$C$44 -> 53297.015
A12: 10115 | B12: UTSA | C12: =SUM(D12:M12) -> 10158026 | D12: =D55*$O55*$C$44 -> 2150967.2 | E12: =E55*$O55*$C$44 -> 604660.77 | F12: =F55*$O55*$C$44 -> 352276.07 | G12: =G55*$O55*$C$44 -> 4393243 | H12: =H55*$O55*$C$44 -> 204671.69 | I12: =I55*$O55*$C$44 -> 25932.042 | J12: =J55*$O55*$C$44 -> 260949.44 | K12: =K55*$O55*$C$44 -> 829610.69 | ... M12: =M55*$O55*$C$44 -> 637324.89
A13: 11163 | B13: UTT | C13: =SUM(D13:M13) -> 3008543.5 | D13: =D56*$O56*$C$44 -> 575936.87 | E13: =E56*$O56*$C$44 -> 148495.72 | F13: =F56*$O56*$C$44 -> 353980.25 | G13: =G56*$O56*$C$44 -> 1143481.5 | H13: =H56*$O56*$C$44 -> 182299.35 | I13: =I56*$O56*$C$44 -> 6775.7279 | J13: =J56*$O56*$C$44 -> 72971.363 | K13: =K56*$O56*$C$44 -> 231719.14 | ... M13: =M56*$O56*$C$44 -> 106228.36
A14: 3632 | B14: TAMU | C14: =SUM(D14:M14) -> 24708667 | D14: =D57*$O57*$C$44 -> 3966030.7 | E14: =E57*$O57*$C$44 -> 4167637.3 | F14: =F57*$O57*$C$44 -> 715917.59 | G14: =G57*$O57*$C$44 -> 9123496.7 | H14: =H57*$O57*$C$44 -> 800043.34 | I14: =I57*$O57*$C$44 -> 57178.367 | J14: =J57*$O57*$C$44 -> 270390.14 | K14: =K57*$O57*$C$44 -> 1597923.6 | ... M14: =M57*$O57*$C$44 -> 2191096.2
A15: 10298 | B15: TAMUG | C15: =SUM(D15:M15) -> 1417888.6 | D15: =D58*$O58*$C$44 -> 193938.96 | E15: =E58*$O58*$C$44 -> 60832.189 | F15: =F58*$O58*$C$44 -> 288783 | G15: =G58*$O58*$C$44 -> 495901.46 | H15: =H58*$O58*$C$44 -> 26296.809 | I15: =I58*$O58*$C$44 -> 0 | J15: =J58*$O58*$C$44 -> 17806.696 | K15: =K58*$O58*$C$44 -> 139075.68 | ... M15: =M58*$O58*$C$44 -> 98190.406
A16: 3630 | B16: Prairie View | C16: =SUM(D16:M16) -> 2716765.1 | D16: =D59*$O59*$C$44 -> 453167.14 | E16: =E59*$O59*$C$44 -> 84213.56 | F16: =F59*$O59*$C$44 -> 191458.94 | G16: =G59*$O59*$C$44 -> 1003243.3 | H16: =H59*$O59*$C$44 -> 152776.53 | I16: =I59*$O59*$C$44 -> 4678.4788 | J16: =J59*$O59*$C$44 -> 62156.011 | K16: =K59*$O59*$C$44 -> 269093.19 | ... M16: =M59*$O59*$C$44 -> 248292.79
... A42: 20 | B42: SRRG | C42: =SUM(D42:M42) -> 749091.19 | D42: =D85*$O85*$C$44 -> 78856.104 | E42: =E85*$O85*$C$44 -> 12527.384 | F42: =F85*$O85*$C$44 -> 446265.49 | G42: =G85*$O85*$C$44 -> 136170.67 | H42: =H85*$O85*$C$44 -> 3089.2082 | I42: =I85*$O85*$C$44 -> 2764.0284 | J42: =J85*$O85*$C$44 -> 11238.214 | K42: =K85*$O85*$C$44 -> 37395.678 | ... M42: =M85*$O85*$C$44 -> 1197.7456
B43: Total | C43: =SUM(C5:C42) -> 2.35e+08 | D43: =SUM(D5:D42) -> 45334958 | E43: =SUM(E5:E42) -> 20256656 | F43: =SUM(F5:F42) -> 15142681 | G43: =SUM(G5:G42) -> 92669338 | H43: =SUM(H5:H42) -> 7464162.6 | I43: =SUM(I5:I42) -> 627759.33 | J43: =SUM(J5:J42) -> 4692554.5 | ... M43: =SUM(M5:M42) -> 14866302
C44: =235000000/P86 -> 0.025155849 | D44: Percent Funded
A45: Points Three-Year Average - Scaled and Weighted
A46: FICE | B46: Name | C46: Total Points | D46: Total Undergraduate Degrees | H46: Undergraduate Critical Field Degrees | I46: Math and Science Teaching Certificates | J46: At-Risk Degrees | K46: Retention Metrics | N46: SREB Carnegie 2011-12 Classification | O46: Texas SREB Carnegie Salaries 2011-2012 | P46: Texas SREB Carnegie Salary Times Total Points
E47: Adjusted by 6-Year Graduation Rate | F47: per 100 FTSE | G47: Cost Weighted | K47: 30 Hours | L47: 60 Hours | M47: 90 Hours
A48: =A5 -> 3656 | B48: =B5 -> UTA | C48: =SUM(D48:M48) -> 7139.9579 | D48: =D90*D140 -> 1505.4 | E48: =E90*E140 -> 520.19933 | F48: =F90*F140 -> 296.03788 | G48: =G90*G140 -> 3125.566 | H48: =H90*H140 -> 459.4 | I48: =I90*I140 -> 10.5 | J48: =J90*J140 -> 149.568 | K48: =K90*K140 -> 478.54333 | ... M48: =M90*M140 -> 249.71333 | N48: 1 | O48: 90197.028 | P48: =O48*C48 -> 6.4400298e+08
A49: =A6 -> 3658 | B49: =B6 -> UT | C49: =SUM(D49:M49) -> 10821.843 | D49: =D91*D141 -> 1789.2667 | E49: =E91*E141 -> 1854.1276 | F49: =F91*F141 -> 331.22115 | G49: =G91*G141 -> 3879.67 | H49: =H91*H141 -> 375.26667 | I49: =I91*I141 -> 13.2 | J49: =J91*J141 -> 111.05067 | K49: =K91*K141 -> 671.88333 | ... M49: =M91*M141 -> 985.64667 | N49: 1 | O49: 90197.028 | P49: =O49*C49 -> 9.7609805e+08
A50: =A7 -> 9741 | B50: =B7 -> UTD | C50: =SUM(D50:M50) -> 3619.5851 | D50: =D92*D142 -> 717.9 | E50: =E92*E142 -> 336.4558 | F50: =F92*F142 -> 268.29761 | G50: =G92*G142 -> 1530.361 | H50: =H92*H142 -> 126.5 | I50: =I92*I142 -> 9.6 | J50: =J92*J142 -> 63.344 | K50: =K92*K142 -> 232.05 | ... M50: =M92*M142 -> 142.98667 | N50: 1 | O50: 90197.028 | P50: =O50*C50 -> 3.2647582e+08
A51: =A8 -> 3661 | B51: =B8 -> UTEP | C51: =SUM(D51:M51) -> 4496.9126 | D51: =D93*D143 -> 917.1 | E51: =E93*E143 -> 238.446 | F51: =F93*F143 -> 228.70895 | G51: =G93*G143 -> 1889.423 | H51: =H93*H143 -> 196.5 | I51: =I93*I143 -> 27 | J51: =J93*J143 -> 118.288 | K51: =K93*K143 -> 305.38667 | ... M51: =M93*M143 -> 273.84 | N51: 2 | O51: 69184.924 | P51: =O51*C51 -> 3.1111856e+08
A52: =A9 -> 3599 | B52: =B9 -> UTPA | C52: =SUM(D52:M52) -> 4051.1807 | D52: =D94*D144 -> 774 | E52: =E94*E144 -> 166.797 | F52: =F94*F144 -> 153.69368 | G52: =G94*G144 -> 1540.25 | H52: =H94*H144 -> 156.1 | I52: =I94*I144 -> 8.4 | J52: =J94*J144 -> 112.24 | K52: =K94*K144 -> 407.53333 | ... M52: =M94*M144 -> 329.68667 | N52: 3 | O52: 64130.952 | P52: =O52*C52 -> 2.5980607e+08
A53: =A10 -> 30646 | B53: =B10 -> UTB | C53: =SUM(D53:M53) -> 1619.4529 | D53: =D95*D145 -> 327.6 | E53: =E95*E145 -> 94.225639 | F53: =F95*F145 -> 258.45927 | G53: =G95*G145 -> 629.338 | H53: =H95*H145 -> 37.3 | I53: =I95*I145 -> 5.5 | J53: =J95*J145 -> 44.96 | K53: =K95*K145 -> 132.63333 | ... M53: =M95*M145 -> 17.113333 | N53: 3 | O53: 64130.952 | P53: =O53*C53 -> 1.0385706e+08
A54: =A11 -> 9930 | B54: =B11 -> UTPB | C54: =SUM(D54:M54) -> 879.48581 | D54: =D96*D146 -> 160 | E54: =E96*E146 -> 35.52 | F54: =F96*F146 -> 173.43881 | G54: =G96*G146 -> 300.455 | H54: =H96*H146 -> 12.4 | I54: =I96*I146 -> 3 | J54: =J96*J146 -> 19.152 | K54: =K96*K146 -> 78.566667 | ... M54: =M96*M146 -> 33.036667 | N54: 3 | O54: 64130.952 | P54: =O54*C54 -> 56402262
A55: =A12 -> 10115 | B55: =B12 -> UTSA | C55: =SUM(D55:M55) -> 5836.5856 | D55: =D97*D147 -> 1235.9 | E55: =E97*E147 -> 347.42522 | F55: =F97*F147 -> 202.41034 | G55: =G97*G147 -> 2524.264 | H55: =H97*H147 -> 117.6 | I55: =I97*I147 -> 14.9 | J55: =J97*J147 -> 149.936 | K55: =K97*K147 -> 476.67667 | ... M55: =M97*M147 -> 366.19333 | N55: 2 | O55: 69184.924 | P55: =O55*C55 -> 4.0380373e+08
A56: =A13 -> 11163 | B56: =B13 -> UTT | C56: =SUM(D56:M56) -> 1864.8746 | D56: =D98*D148 -> 357 | E56: =E98*E148 -> 92.0465 | F56: =F98*F148 -> 219.41805 | G56: =G98*G148 -> 708.798 | H56: =H98*H148 -> 113 | I56: =I98*I148 -> 4.2 | J56: =J98*J148 -> 45.232 | K56: =K98*K148 -> 143.63333 | ... M56: =M98*M148 -> 65.846667 | N56: 3 | O56: 64130.952 | P56: =O56*C56 -> 1.1959618e+08
A57: =A14 -> 3632 | B57: =B14 -> TAMU | C57: =SUM(D57:M57) -> 10889.755 | D57: =D99*D149 -> 1747.9333 | E57: =E99*E149 -> 1836.7866 | F57: =F99*F149 -> 315.52358 | G57: =G99*G149 -> 4020.9633 | H57: =H99*H149 -> 352.6 | I57: =I99*I149 -> 25.2 | J57: =J99*J149 -> 119.168 | K57: =K99*K149 -> 704.24667 | ... M57: =M99*M149 -> 965.67333 | N57: 1 | O57: 90197.028 | P57: =O57*C57 -> 9.8222352e+08
A58: =A15 -> 10298 | B58: =B15 -> TAMUG | C58: =SUM(D58:M58) -> 905.83344 | D58: =D100*D150 -> 123.9 | E58: =E100*E150 -> 38.8633 | F58: =F100*F150 -> 184.49214 | G58: =G100*G150 -> 316.812 | H58: =H100*H150 -> 16.8 | I58: =I100*I150 -> 0 | J58: =J100*J150 -> 11.376 | K58: =K100*K150 -> 88.85 | ... M58: =M100*M150 -> 62.73 | N58: 6 | O58: 62223.55 | P58: =O58*C58 -> 56364172
A59: =A16 -> 3630 | B59: =B16 -> Prairie View | C59: =SUM(D59:M59) -> 1684.0129 | D59: =D101*D151 -> 280.9 | E59: =E101*E151 -> 52.200583 | F59: =F101*F151 -> 118.67766 | G59: =G101*G151 -> 621.87 | H59: =H101*H151 -> 94.7 | I59: =I101*I151 -> 2.9 | J59: =J101*J151 -> 38.528 | K59: =K101*K151 -> 166.8 | ... M59: =M101*M151 -> 153.90667 | N59: 3 | O59: 64130.952 | P59: =O59*C59 -> 1.0799735e+08
... A74: =A31 -> 3594 | B74: =B31 -> UNT | C74: =SUM(D74:M74) -> 8003.7332 | D74: =D116*D166 -> 1805 | E74: =E116*E166 -> 693.52111 | F74: =F116*F166 -> 258.86945 | G74: =G116*G166 -> 3423.466 | H74: =H116*H166 -> 101 | I74: =I116*I166 -> 13 | J74: =J116*J166 -> 183.36 | K74: =K116*K166 -> 550.52667 | ... M74: =M116*M166 -> 467.18 | N74: 1 | O74: 90197.028 | P74: =O74*C74 -> 7.2191295e+08
A75: =A32 -> 113594 | B75: =B32 -> UNTD | C75: =SUM(D75:M75) -> 764.98868 | D75: =D117*D167 -> 121.05 | E75: =E117*E167 -> 34.953187 | F75: =F117*F167 -> 319.8545 | G75: =G117*G167 -> 211.758 | H75: =H117*H167 -> 3.6 | I75: =I117*I167 -> 0 | J75: =J117*J167 -> 14.808 | K75: =K117*K167 -> 47.8 | ... M75: =M117*M167 -> 1.87 | N75: NR | O75: 62223.55 | P75: =O75*C75 -> 47600312
A76: =A33 -> 3624 | B76: =B33 -> SFA | C76: =SUM(D76:M76) -> 2946.7691 | D76: =D118*D168 -> 576.5 | E76: =E118*E168 -> 159.6905 | F76: =F118*F168 -> 151.93158 | G76: =G118*G168 -> 1116.521 | H76: =H118*H168 -> 74.4 | I76: =I118*I168 -> 13.4 | J76: =J118*J168 -> 70.096 | K76: =K118*K168 -> 276.93333 | ... M76: =M118*M168 -> 237.54667 | N76: 3 | O76: 64130.952 | P76: =O76*C76 -> 1.8897911e+08
A77: =A34 -> 3642 | B77: =B34 -> TSU | C77: =SUM(D77:M77) -> 1315.9214 | D77: =D119*D169 -> 227.5 | E77: =E119*E169 -> 16.342083 | F77: =F119*F169 -> 97.002608 | G77: =G119*G169 -> 446.596 | H77: =H119*H169 -> 40.3 | I77: =I119*I169 -> 0.9 | J77: =J119*J169 -> 31.984 | K77: =K119*K169 -> 163.73333 | ... M77: =M119*M169 -> 144.27333 | N77: 3 | O77: 64130.952 | P77: =O77*C77 -> 84391289
A78: =A35 -> 3644 | B78: =B35 -> TTU | C78: =SUM(D78:M78) -> 7185.6807 | D78: =D120*D170 -> 1402.2 | E78: =E120*E170 -> 684.2736 | F78: =F120*F170 -> 210.61243 | G78: =G120*G170 -> 3038.434 | H78: =H120*H170 -> 218.2 | I78: =I120*I170 -> 17.2 | J78: =J120*J170 -> 133.344 | K78: =K120*K170 -> 453.97333 | ... M78: =M120*M170 -> 552.39333 | N78: 1 | O78: 90197.028 | P78: =O78*C78 -> 6.4812704e+08
A79: =A36 -> 3541 | B79: =B36 -> Angelo | C79: =SUM(D79:M79) -> 1622.1399 | D79: =D121*D171 -> 297.4 | E79: =E121*E171 -> 63.891433 | F79: =F121*F171 -> 152.29276 | G79: =G121*G171 -> 593.205 | H79: =H121*H171 -> 76.3 | I79: =I121*I171 -> 5.8 | J79: =J121*J171 -> 34.704 | K79: =K121*K171 -> 143.86667 | ... M79: =M121*M171 -> 120.30333 | N79: 3 | O79: 64130.952 | P79: =O79*C79 -> 1.0402937e+08
A80: =A37 -> 3646 | B80: =B37 -> TWU | C80: =SUM(D80:M80) -> 2665.809 | D80: =D122*D172 -> 541.8 | E80: =E122*E172 -> 141.8613 | F80: =F122*F172 -> 206.59203 | G80: =G122*G172 -> 1035.653 | H80: =H122*H172 -> 170.8 | I80: =I122*I172 -> 9.5 | J80: =J122*J172 -> 59.856 | K80: =K122*K172 -> 219.6 | ... M80: =M122*M172 -> 112.14333 | N80: 2 | O80: 69184.924 | P80: =O80*C80 -> 1.8443379e+08
...

Sheet Option 6
A1: Option 6 - Outcomes Based Funding (FY 2010 - FY 2012 Averaged) with Total Degrees adjusted by Six-Year Graduation Rate (3-Year Rate for Upper-Levels), Total Degrees per 100 FTSE, Critical Field Degrees, At-Risk Degrees, Retention Metrics of 30, 60, and 90 hours, and Total Degrees adjusted by Cost Based Weights. Metrics scaled for mathematical comparability and weighted by accountability group. Funded at 10 percent of undergraduate formula funding.
A3: FICE | B3: Name | C3: Funding | D3: Total Undergraduate Degrees | H3: Undergraduate Critical Field Degrees | I3: Math and Science Teaching Certificates | J3: At-Risk Degrees | K3: Retention Metrics | O3: Phase-In Adjustment
E4: Adjusted by 6-Year Graduation Rate | F4: per 100 FTSE | G4: Cost Weighted | K4: 30 Hours | L4: 60 Hours | M4: 90 Hours | O4: 2014-2015 Undergraduate Instruction and Operations Percent of Total | P4: Phase-In Set-Asides | Q4: Funding After Set-Asides
A5: 3656 | B5: UTA | C5: =SUM(D5:M5) -> 13517160 | D5: =D48/$C$86*$C$43 -> 2763155.4 | E5: =E48/$C$86*$C$43 -> 954823.69 | F5: =F48/$C$86*$C$43 -> 543376.29 | G5: =G48/$C$86*$C$43 -> 5736963.3 | H5: =H48/$C$86*$C$43 -> 843226.77 | I5: =I48/$C$86*$C$43 -> 19272.706 | J5: =J48/$C$86*$C$43 -> 686328.59 | K5: =K48/$C$86*$C$43 -> 878364.28 | ... M5: =M48/$C$86*$C$43 -> 458347.78 | O5: 0.053941374 | P5: =MIN(0,C48/$C$86-O5+$P$44)*-1*$Q$43 -> 0 | Q5: =C5+P5 -> 13517160
A6: 3658 | B6: UT | C6: =SUM(D6:M6) -> 20169196 | D6: =D49/$C$86*$C$43 -> 3284191.5 | E6: =E49/$C$86*$C$43 -> 3403243.4 | F6: =F49/$C$86*$C$43 -> 607955.03 | G6: =G49/$C$86*$C$43 -> 7121118 | H6: =H49/$C$86*$C$43 -> 688800.39 | I6: =I49/$C$86*$C$43 -> 24228.545 | J6: =J49/$C$86*$C$43 -> 509582.58 | K6: =K49/$C$86*$C$43 -> 1233239 | ... M6: =M49/$C$86*$C$43 -> 1809150.3 | O6: 0.097535368 | P6: =MIN(0,C49/$C$86-O6+$P$44)*-1*$Q$43 -> 1199145.3 | Q6: =C6+P6 -> 21368342
A7: 9741 | B7: UTD | C7: =SUM(D7:M7) -> 6818134.7 | D7: =D50/$C$86*$C$43 -> 1317702.4 | E7: =E50/$C$86*$C$43 -> 617563.21 | F7: =F50/$C$86*$C$43 -> 492459.13 | G7: =G50/$C$86*$C$43 -> 2808971.2 | H7: =H50/$C$86*$C$43 -> 232190.22 | I7: =I50/$C$86*$C$43 -> 17620.76 | J7: =J50/$C$86*$C$43 -> 290669.12 | K7: =K50/$C$86*$C$43 -> 425926.8 | ... M7: =M50/$C$86*$C$43 -> 262451.43 | O7: 0.030845131 | P7: =MIN(0,C50/$C$86-O7+$P$44)*-1*$Q$43 -> 0 | Q7: =C7+P7 -> 6818134.7
A8: 3661 | B8: UTEP | C8: =SUM(D8:M8) -> 8579739.9 | D8: =D51/$C$86*$C$43 -> 1683333.2 | E8: =E51/$C$86*$C$43 -> 437666.63 | F8: =F51/$C$86*$C$43 -> 419794.31 | G8: =G51/$C$86*$C$43 -> 3468028 | H8: =H51/$C$86*$C$43 -> 360674.93 | I8: =I51/$C$86*$C$43 -> 49558.387 | J8: =J51/$C$86*$C$43 -> 542792.82 | K8: =K51/$C$86*$C$43 -> 560535.95 | ... M8: =M51/$C$86*$C$43 -> 502632.17 | O8: 0.0380679 | P8: =MIN(0,C51/$C$86-O8+$P$44)*-1*$Q$43 -> 0 | Q8: =C8+P8 -> 8579739.9
A9: 3599 | B9: UTPA | C9: =SUM(D9:M9) -> 7744949.2 | D9: =D52/$C$86*$C$43 -> 1420673.8 | E9: =E52/$C$86*$C$43 -> 306155.19 | F9: =F52/$C$86*$C$43 -> 282104.1 | G9: =G52/$C$86*$C$43 -> 2827122.4 | H9: =H52/$C$86*$C$43 -> 286520.9 | I9: =I52/$C$86*$C$43 -> 15418.165 | J9: =J52/$C$86*$C$43 -> 515040.12 | K9: =K52/$C$86*$C$43 -> 748025.72 | ... M9: =M52/$C$86*$C$43 -> 605138.49 | O9: 0.036041181 | P9: =MIN(0,C52/$C$86-O9+$P$44)*-1*$Q$43 -> 0 | Q9: =C9+P9 -> 7744949.2
A10: 30646 | B10: UTB | C10: =SUM(D10:M10) -> 3096284.9 | D10: =D53/$C$86*$C$43 -> 601308.43 | E10: =E53/$C$86*$C$43 -> 172950.76 | F10: =F53/$C$86*$C$43 -> 474400.91 | G10: =G53/$C$86*$C$43 -> 1155147.3 | H10: =H53/$C$86*$C$43 -> 68463.994 | I10: =I53/$C$86*$C$43 -> 10095.227 | J10: =J53/$C$86*$C$43 -> 206309.73 | K10: =K53/$C$86*$C$43 -> 243447.93 | ... M10: =M53/$C$86*$C$43 -> 31411.452 | O10: 0.013127311 | P10: =MIN(0,C53/$C$86-O10+$P$44)*-1*$Q$43 -> 0 | Q10: =C10+P10 -> 3096284.9
A11: 9930 | B11: UTPB | C11: =SUM(D11:M11) -> 1667022.6 | D11: =D54/$C$86*$C$43 -> 293679.33 | E11: =E54/$C$86*$C$43 -> 65196.811 | F11: =F54/$C$86*$C$43 -> 318346.21 | G11: =G54/$C$86*$C$43 -> 551483.89 | H11: =H54/$C$86*$C$43 -> 22760.148 | I11: =I54/$C$86*$C$43 -> 5506.4874 | J11: =J54/$C$86*$C$43 -> 87883.539 | K11: =K54/$C$86*$C$43 -> 144208.79 | ... M11: =M54/$C$86*$C$43 -> 60638.663 | O11: 0.006658598 | P11: =MIN(0,C54/$C$86-O11+$P$44)*-1*$Q$43 -> 0 | Q11: =C11+P11 -> 1667022.6
A12: 10115 | B12: UTSA | C12: =SUM(D12:M12) -> 11125839 | D12: =D55/$C$86*$C$43 -> 2268489.3 | E12: =E55/$C$86*$C$43 -> 637697.54 | F12: =F55/$C$86*$C$43 -> 371523.33 | G12: =G55/$C$86*$C$43 -> 4633276 | H12: =H55/$C$86*$C$43 -> 215854.31 | I12: =I55/$C$86*$C$43 -> 27348.887 | J12: =J55/$C$86*$C$43 -> 688017.25 | K12: =K55/$C$86*$C$43 -> 874938.02 | ... M12: =M55/$C$86*$C$43 -> 672146.33 | O12: 0.051993931 | P12: =MIN(0,C55/$C$86-O12+$P$44)*-1*$Q$43 -> 0 | Q12: =C12+P12 -> 11125839
A13: 11163 | B13: UTT | C13: =SUM(D13:M13) -> 3547504.1 | D13: =D56/$C$86*$C$43 -> 655272 | E13: =E56/$C$86*$C$43 -> 168950.96 | F13: =F56/$C$86*$C$43 -> 402740.92 | G13: =G56/$C$86*$C$43 -> 1300995.8 | H13: =H56/$C$86*$C$43 -> 207411.03 | I13: =I56/$C$86*$C$43 -> 7709.0824 | J13: =J56/$C$86*$C$43 -> 207557.87 | K13: =K56/$C$86*$C$43 -> 263638.38 | ... M13: =M56/$C$86*$C$43 -> 120861.28 | O13: 0.012069402 | P13: =MIN(0,C56/$C$86-O13+$P$44)*-1*$Q$43 -> 0 | Q13: =C13+P13 -> 3547504.1
