Workbook
Name Input: Bioretention!$C$11:$C$13,Bioretention!$C$16,Bioretention!$C$20,Bioretention!$C$25,Bioretention!$C$34:$C$36,Bioretention!$C$39,Bioretention!$C$43,Bioretention!$C$48
Name Input: 'Buffer Strip'!$C$9
Name Input: 'Detention Pond'!$C$9,'Detention Pond'!$C$13:$C$16
Name Input: 'Detention Vault'!$C$10:$C$12,'Detention Vault'!$C$23:$C$24
Name Input: 'Infiltration Basin'!$C$9:$C$10,'Infiltration Basin'!$C$15:$C$16,'Infiltration Basin'!$C$18
Name Input: 'Media Filter'!$C$10:$C$13,'Media Filter'!$C$17,'Media Filter'!$C$24,'Media Filter'!$C$27,'Media Filter'!$C$35:$C$36
Name Input: 'Permeable Pavement'!$C$10:$C$12,'Permeable Pavement'!$C$15,'Permeable Pavement'!$C$21:$C$22,'Permeable Pavement'!$C$27
Name Input: 'Swales-Flow'!$C$10:$C$13,'Swales-Flow'!$C$22:$C$23,'Swales-Flow'!$C$30
Name Input: 'Swales-Volume'!$C$10:$C$14,'Swales-Volume'!$C$17,'Swales-Volume'!$C$25,'Swales-Volume'!$C$31:$C$32
Name Input: VRF!$C$10,VRF!$C$16,VRF!$C$20,VRF!$C$26,VRF!$C$39,VRF!$C$41
Name Input: 'Wet Ponds_Wetlands'!$C$9,'Wet Ponds_Wetlands'!$C$12,'Wet Ponds_Wetlands'!$C$17:$C$18,'Wet Ponds_Wetlands'!$C$20:$C$22

Sheet Readme
A1: Introduction to the Non-Potable Water Calculator
B3: PURPOSE OF THE CALCULATOR TOOL
B4: The SFPUC has developed this tool to estimate a building's onsite:
B5: A) Non-potable water demands
B6: B) Onsite supplies that can be generated through collection and reuse of rainwater, stormwater, graywater, blackwater, and/or foundation drainage
B8: This calculator is designed primarily for the following new building types which make up the majority of projected future development in the San Francisco Planning Department's Pipeline Report: ● Multi-family residential ● Mixed Use (e.g. residential uses and multiple commercial uses are present within a building) ● Typical urban commercial uses (e.g. office, retail, services, restaurants and hotels)
B14: This calculator may also be applied in other building uses not listed above; however buildings with unique water use profiles (e.g. significantly high water demands or specific water quality requirements for end uses) should conduct an independent water accounting analysis.
B17: Note that this calculator is meant for water budget accounting purposes only and should not be used as a design or optimization tool.
B19: The NP Calculator is intended to help generate initial estimates. The Users should verify the assumptions provided when generating specific
B20: project demands and update assumptions as appropriate.
B22: The NP Calculator will be updated as more user feedback is collected. A future version of the tool will allow for the inclusion of hotel guest demands
B23: along with the typical commercial demand assumptions and calculations.
B25: HOW TO USE THE CALCULATOR TOOL
... B33: This calculator is laid out in seven (8) worksheets. The worksheets are summarized below:
B35: Worksheet No. | C35: Description
B36: Step 1 | C36: Enter Project Information
B37: Step 2 | C37: Calculate Indoor Water Demand (Indoor Fixtures and Fittings)
B38: Step 3 | C38: Calculate Indoor Non-Potable Supply (Graywater, Blackwater, Foundation Drainage)
B39: Step 4 | C39: Calculate Outdoor Water Demand (Landscape Irrigation, Outdoor Water Features)
B40: Step 5 | C40: Calculate Outdoor Water Supply (Rainwater and Stormwater Harvesting)
B41: Step 6 | C41: Summary of Building Potential
B42: Step 7 | C42: Define Project Non-Potable Demands and Supplies
B43: Step 8 | C43: Printable Summary of Building Information, Site Demands, and Site Supplies
B45: CALCULATOR USE ASSUMPTIONS
B47: 1. It is assumed that the main users of this calculator will be designated project team members (e.g. project engineer or manager) and SFPUC review staff with basic knowledge of Microsoft Excel.
B49: 2. The level of detail required for building information inputs into the calculator assumes that the project is at a schematic or design development phase.
B51: 3. The estimated level of effort for a user to enter information in this calculator is approximately 4 to 6 hours, depending on the complexity of the project. Note that this estimate does not include the time taken to consolidate relevant building information, or conduct external analysis of other specified demands or supplies not included in the default calculations provided in the calculator.
B55: >>> Click on the next tab "1. Building Information" to begin

Sheet 1. Building Information
A1: NON-POTABLE WATER CALCULATOR
A2: Step 1 of 7: Enter Project Information
B4: Instructions: | G4: LEGEND:
B5: This page includes general project information, building use description, site coverage and project location. Please fill in all user input fields in Sections A, B, C and D of this page before proceeding to the next page. Instructions for user input for each section are noted below in red italics. | G5: User Input
G6: Default Value
G7: Autogenerated Value
B9: A. GENERAL INFORMATION
B10: User Input Instructions:
B11: Enter general project information below.
B13: Project Name: | C13: ABC Building | E13: <-- Name of Project
B15: Project Address: | E15: <--Address of Project
B19: Block Lot(s): | E19: <--4-digit assessor block + 3-digit assessor's lot number
B21: Project Date: | D21: Estimated project construction date
B23: Project Contact: | E23: <--Name
E24: <--Contact No.
E25: <--E-mail Address
B27: Total Lot Size (ft2) | D27: <--Total area of lot/parcel
B29: Total Building Size (gross square footage/GSF) | D29: <--Total gross square footage of building
B31: No. of Building Operation Days in a Year | D31: <--No. of days the building is operational (typically 365 days for residential, 250-260 days for 5-day work week facilities)
B33: B. BUILDING USE
B34: User Input Instructions:
B35: Select building use type based on the definitions provided in Table 1.
B37: Land Use: | C37: Select One Land Use | D37: <--Select from dropdown menu - see definitions in Table 1
B39: Table 1. Land Use Categories (Source: SF Planning Department Pipeline Report Development Profile)
B40: Select One Land Use | C40: DEFINITION
B41: CIE | C41: CIE - Cultural, Institutional, Educational includes educational services, social services, museums, zoos, and membership organizations.
B42: MED | C42: MED - Medical includes health services offices and hospitals and laboratories throughout the City.
B43: MIPS | C43: MIPS - Largely any activity where information is the chief commodity that is processed (managerial, information, professional, business services, multi-media).
B44: PDF | C44: PDF - Production, Distribution and Repair includes automobile and other repair services throughout the City, plus construction, transportation, communications, utilities, agriculture mining, manufacturing, wholesale trade, and motion picture production distribution, and services located outside of the downtown, transbay, and Northeast Districts. Does not include undeveloped or vacant land area used for PDR activities such as construction yards or open storage areas.
B45: Retail/Ent | C45: Retail/Ent - Retail includes retail trade, amusement and recreation services, and personal services throughout the City.
B46: Visitor/Hotel | C46: Visitor (or Hotel) includes hotels and other lodging located throughout the City.
B47: Mixres | C47: Mixres (when both commercial and residential uses are proposed).
B48: Mixed | C48: Mixed (when no residential use present and when multiple commercial uses are proposed and not one is dominating (>80% of commercial square feet).
B49: Resident | C49: Resident is used to denote any residential project where there is no commercial component.
B52: COMMERCIAL
B53: User Input Instructions:
B54: Provide a breakdown of project square footage based on the space types within the building. Projects must utilize the default gross square footage (GSF) occupancy counts provided in Columns D and E in the table below. Where the provided space types are not applicable, please indicate the space type or types in your building and the associated occupancy counts. Gross Area (GSF) = Net Usable Area + Structural Space
B56: Source: LEED Reference Guide for Green Building Design and Construction, 2009 Edition. Core & Shell Appendix 1 - Default Occupancy Counts.
B58: COMMERCIAL USE BREAKDOWN | F58: COMMERCIAL USE OCCUPANCY
B60: A | C60: B | E60: C | G60: D | I60: E | K60: F | L60: G
...

Sheet 2. Indoor Water Demand
A1: NON-POTABLE WATER CALCULATOR
A2: Step 2 of 7: Calculate Indoor Water Demand (Indoor Fixtures and Fittings)
B4: Project Name: | G4: LEGEND:
B5: ='1. Building Information'!$C$13 -> ABC Building | G5: User Input
G6: Linked from User Input
B7: Instructions: | G7: Default Value
B8: Annual indoor water demand is calculated based on water demand from domestic fixtures and fittings, using assumed usage rates based on the building uses and occupancy profiles entered in Step 1. User input is required in Section D at the end of this page. | G8: Autogenerated Value
B13: A. COMMERCIAL WATER DEMAND (No user input needed - auto-calculated from Step 1 inputs)
B15: Total Water Demand (gpd) = (Flow Rate x Duration x Ave Daily Use x No. of FTEs) + (Flow Rate x Duration x Ave Daily Use (Transient FTE) x No. of Transient FTEs)
B17: Fixture Type | C17: Flow Rate | D17: Unit | E17: Duration(7) | F17: Unit | G17: Ave Daily Use (7) | H17: No. of FTEs | I17: Ave Daily Use (Transient) (6)(7) | J17: No. of Transient FTEs | K17: Total Water Demand (gpd) | L17: Allowable End Use for Non-Potable? | N17: Total Potable Demand (gpd) | O17: Total Potential Non-Potable Demand (gpd)
B18: Showerhead (1)(2)(7)(8) | C18: 2 | D18: gpm | E18: 5 | F18: min | G18: 0.65 | H18: ='1. Building Information'!K72+0.5%*'1. Building Information'!K63 -> 2e-05 | I18: 0 | J18: ='1. Building Information'!L72+0.5%*'1. Building Information'!L63 -> 0 | K18: =(C18*E18*G18*H18)+(C18*E18*I18*J18) -> 0.00013 | L18: No | N18: =IF(L18="No",K18,0) -> 0.00013 | O18: =IF(L18="No",0,K18) -> 0
B19: Lavatory Faucet (2) | C19: 0.4 | D19: gpm | E19: 0.25 | F19: min | G19: 3 | H19: ='1. Building Information'!K79 -> 0.004 | I19: 0.5 | J19: ='1. Building Information'!L79 -> 0 | K19: =(C19*E19*G19*H19)+(C19*E19*I19*J19) -> 0.0012 | L19: No | N19: =IF(L19="No",K19,0) -> 0.0012 | O19: =IF(L19="No",0,K19) -> 0
B20: Urinals (2)(3) | C20: 0.5 | D20: gpf | E20: 1 | F20: flush | G20: 1.74 | H20: ='1. Building Information'!K79*0.5 -> 0.002 | I20: 0.4 | J20: ='1. Building Information'!L79*0.5 -> 0 | K20: =(C20*E20*G20*H20)+(C20*E20*I20*J20) -> 0.00174 | L20: Yes | N20: =IF(L20="No",K20,0) -> 0 | O20: =IF(L20="No",0,K20) -> 0.00174
B21: Toilet (Water Closet) (2)(3) | C21: 1.28 | D21: gpf | E21: 1 | F21: flush | G21: 1.74 | H21: ='1. Building Information'!K79 -> 0.004 | I21: 0.5 | J21: ='1. Building Information'!L79 -> 0 | K21: =(C21*E21*G21*H21)+(C21*E21*I21*J21) -> 0.0089088 | L21: Yes | N21: =IF(L21="No",K21,0) -> 0 | O21: =IF(L21="No",0,K21) -> 0.0089088
B22: Kitchen Faucet (2)(4) | C22: 1.8 | D22: gpm | E22: =15/60 -> 0.25 | F22: min | G22: 1 | H22: ='1. Building Information'!K63+'1. Building Information'!K67+'1. Building Information'!K68+'1. Building Information'!K69+'1. Building Information'!K73+'1. Building Information'!K74+'1. Building Information'!K75 -> 0.004 | I22: 0 | J22: ='1. Building Information'!L63+'1. Building Information'!L67+'1. Building Information'!L68+'1. Building Information'!L69+'1. Building Information'!L73+'1. Building Information'!L74+'1. Building Information'!L75 -> 0 | K22: =(C22*E22*G22*H22)+(C22*E22*I22*J22) -> 0.0018 | L22: No | N22: =IF(L22="No",K22,0) -> 0.0018 | O22: =IF(L22="No",0,K22) -> 0
B23: Low Flow Sprayer - Restaurants (5) | C23: 82.51 | D23: gal/emp/day | E23: 1 | F23: - | G23: 1 | H23: ='1. Building Information'!K66 -> 0 | I23: 0 | J23: ='1. Building Information'!L66 -> 0 | K23: =(C23*E23*G23*H23)+(C23*E23*I23*J23) -> 0 | L23: No | N23: =IF(L23="No",K23,0) -> 0 | O23: =IF(L23="No",0,K23) -> 0
B24: TOTAL | K24: =SUM(K18:K23) -> 0.0137788 | N24: =SUM(N18:N23) -> 0.00313 | O24: =SUM(O18:O23) -> 0.0106488
B26: Notes: | J26: Key
B27: (1) Applied to 0.5% of FTEs in Hotel and General Office uses. | J27: gpm: gallons per minute
B28: (2) Flow rate based on maximum flow rate prescribed by 2011 SF Green Building Requirements for the Prescriptive Approach (Table 13C.5.303.2.3). | J28: gpf: gallons per flush
B29: (3) Durations and Ave Daily Use (FTE) from 2011 SFPUC Water Demand Conservation Model (Retail Model for Non-Residential). | J29: gal/emp/day: gallons per employee per day
B30: (4) Applied to General Office, Grocery Store, Medical Office, R&D or Laboratory, and Educational Facilities.
B31: (5) From 2011 SFPUC Water Demand Conservation Model (Retail Model for Non-Residential), Estimated Usage for Nonresidential Low-Flow Sprayers in Restaurants.
B32: (6) From LEED 2009 Water Use Reduction Additional Guidance (Revision 3). Updated July 14, 2011. Table 1. Non-residential Default Fixture Usage Rates
B33: (7) Hotel property developers may need to manually increase the default values of Duration and Average Daily Use for showerheads to account for transients (hotel guests).
B34: A future version of the NP Calculator will enable for separation of hotel information.
B35: (8) Ave. Daily Use value from 2011 SFPUC Water Demand Conservation Model.
B37: B. MULTI-FAMILY RESIDENTIAL WATER DEMAND (No user input needed - auto-calculated from Step 1 inputs)
B39: Total Water Demand (gpd) = Flow Rate x Duration x Ave Daily Use x No. of Occupants
B41: Fixture Type (Daily Use) | C41: Flow Rate | D41: Unit | E41: Duration (4) | F41: Unit | G41: Ave Daily Use (4) | H41: No. of occupants | I41: Total Water Demand (gpd) | J41: Allowable End Use for Non-Potable? | N41: Total Potable Demand (gpd) | O41: Total Potential Non-Potable Demand (gpd)
B42: Showerhead (1) | C42: 2 | D42: gpm | E42: 8.2 | F42: min | G42: 0.65 | H42: ='1. Building Information'!$D$92 -> 2.01 | I42: =C42*E42*G42*H42 -> 21.4266 | J42: No | N42: =IF(J42="No",I42,0) -> 21.4266 | O42: =IF(J42="No",0,I42) -> 0
B43: Bathroom Faucet (2) | C43: 1.3 | D43: gpm | E43: 1.5 | F43: min | G43: 1 | H43: ='1. Building Information'!$D$92 -> 2.01 | I43: =C43*E43*G43*H43 -> 3.9195 | J43: No | N43: =IF(J43="No",I43,0) -> 3.9195 | O43: =IF(J43="No",0,I43) -> 0
B44: Bath (2) | C44: 25 | D44: gal/bath | E44: 1 | F44: bath | G44: 0.1 | H44: ='1. Building Information'!$D$92 -> 2.01 | I44: =C44*E44*G44*H44 -> 5.025 | J44: No | N44: =IF(J44="No",I44,0) -> 5.025 | O44: =IF(J44="No",0,I44) -> 0
B45: Washing Machine (3) | C45: 36.9 | D45: gal/cycle | E45: 1 | G45: 0.31 | H45: ='1. Building Information'!$D$92 -> 2.01 | I45: =C45*E45*G45*H45 -> 22.99239 | J45: No | N45: =IF(J45="No",I45,0) -> 22.99239 | O45: =IF(J45="No",0,I45) -> 0
B46: Toilet (Water Closet) (1) | C46: 1.28 | D46: gpf | E46: 1 | F46: flush | G46: 4.75 | H46: ='1. Building Information'!$D$92 -> 2.01 | I46: =C46*E46*G46*H46 -> 12.2208 | J46: Yes | N46: =IF(J46="No",I46,0) -> 0 | O46: =IF(J46="No",0,I46) -> 12.2208
B47: Kitchen Faucet (1) | C47: 1.8 | D47: gpm | E47: 7.82 | F47: min | G47: 1 | H47: ='1. Building Information'!$D$92 -> 2.01 | I47: =C47*E47*G47*H47 -> 28.29276 | J47: No | N47: =IF(J47="No",I47,0) -> 28.29276 | O47: =IF(J47="No",0,I47) -> 0
B48: Dishwasher (3) | C48: 11.15 | D48: gal/cycle | E48: 1 | G48: 0.04 | H48: ='1. Building Information'!$D$92 -> 2.01 | I48: =C48*E48*G48*H48 -> 0.89646 | J48: No | N48: =IF(J48="No",I48,0) -> 0.89646 | O48: =IF(J48="No",0,I48) -> 0
B49: TOTAL | I49: =SUM(I42:I48) -> 94.77351 | N49: =SUM(N42:N48) -> 82.55271 | O49: =SUM(O42:O48) -> 12.2208
B51: Notes: | J51: Key
B52: (1) Flow rate based on maximum flow rate prescribed by 2011 SF Green Building Requirements (Table 13C.5.303.2.3). | J52: gpm: gallons per minute
...

Sheet 3. Indoor Nonpotable Supply
A1: NON-POTABLE WATER CALCULATOR
A2: Step 3 of 7: Calculate Indoor Non-Potable Supply (Graywater, Blackwater, Foundation Drainage)
B4: Project Name: | G4: LEGEND:
B5: ='1. Building Information'!$C$13 -> ABC Building | G5: User Input
G6: Linked from User Input
B7: Instructions: | G7: Default Value
B8: Annual indoor water supply is calculated based on supply from collection of graywater, blackwater collection and other sources including foundation drainage. User input is required in Section D at the end of this page. | G8: Autogenerated Value
B12: A. COMMERCIAL (No user input needed - auto-calculated from Step 2)
C14: Graywater Supply (gpd) | D14: % Graywater Supply Available (1) | E14: Graywater Available for Reuse (gpd) | F14: Blackwater Supply (gpd) | G14: % Blackwater Supply Available (1) | H14: Blackwater Available for Reuse (gpd) | J14: Key
B15: Fixture Type (Daily Use) | J15: gpd: gallons per day
B16: Showerhead | C16: ='2. Indoor Water Demand'!K18 -> 0.00013 | D16: 0.9 | E16: =C16*D16 -> 0.000117 | F16: N/A | G16: N/A | H16: N/A
B17: Lavatory Faucet | C17: ='2. Indoor Water Demand'!K19 -> 0.0012 | D17: 0.9 | E17: =C17*D17 -> 0.00108 | F17: N/A | G17: N/A | H17: N/A
B18: Commercial Laundry | C18: ='2. Indoor Water Demand'!C95 -> 34 | D18: 0.9 | E18: =C18*D18 -> 30.6 | F18: N/A | G18: N/A | H18: N/A
B19: Urinals | C19: N/A | D19: N/A | E19: N/A | F19: ='2. Indoor Water Demand'!K20 -> 0.00174 | G19: 0.9 | H19: =F19*G19 -> 0.001566
B20: Toilet (Water Closet) | C20: N/A | D20: N/A | E20: N/A | F20: ='2. Indoor Water Demand'!K21 -> 0.0089088 | G20: 0.9 | H20: =F20*G20 -> 0.00801792
B21: Kitchen Faucet | C21: N/A | D21: N/A | E21: N/A | F21: ='2. Indoor Water Demand'!K22 -> 0.0018 | G21: 0.9 | H21: =F21*G21 -> 0.00162
B22: Low Flow Sprayer - Restaurants | C22: N/A | D22: N/A | E22: N/A | F22: ='2. Indoor Water Demand'!K23 -> 0 | G22: 0.9 | H22: =F22*G22 -> 0
B23: TOTAL | C23: =SUM(C16:C22) -> 34.00133 | E23: =SUM(E16:E22) -> 30.601197 | F23: =SUM(F16:F22) -> 0.0124488 | H23: =SUM(H16:H22) -> 0.01120392
B25: Notes:
B26: (1) Graywater and blackwater supply availability are estimated assuming a 10% treatment loss.
B28: B. MULTI-FAMILY RESIDENTIAL (No user input needed - auto-calculated from Step 2)
C30: Graywater Supply (gpd) | D30: % Graywater Supply Available (1) | E30: Graywater Available for Reuse (gpd) | F30: Blackwater Supply (gpd) | G30: % Blackwater Supply Available (1) | H30: Blackwater Available for Reuse (gpd) | J30: Key
B31: Fixture Type (Daily Use) | J31: gpd: gallons per day
B32: Showerhead | C32: ='2. Indoor Water Demand'!I42 -> 21.4266 | D32: 0.9 | E32: =C32*D32 -> 19.28394 | F32: N/A | G32: N/A | H32: N/A
B33: Bathroom Faucet | C33: ='2. Indoor Water Demand'!I43 -> 3.9195 | D33: 0.9 | E33: =C33*D33 -> 3.52755 | F33: N/A | G33: N/A | H33: N/A
B34: Bath | C34: ='2. Indoor Water Demand'!I44 -> 5.025 | D34: 0.9 | E34: =C34*D34 -> 4.5225 | F34: N/A | G34: N/A | H34: N/A
B35: Washing Machine | C35: ='2. Indoor Water Demand'!I45 -> 22.99239 | D35: 0.9 | E35: =C35*D35 -> 20.693151 | F35: N/A | G35: N/A | H35: N/A
B36: Toilet (Water Closet) | C36: N/A | D36: N/A | E36: N/A | F36: ='2. Indoor Water Demand'!I46 -> 12.2208 | G36: 0.9 | H36: =F36*G36 -> 10.99872
B37: Kitchen Faucet | C37: N/A | D37: N/A | E37: N/A | F37: ='2. Indoor Water Demand'!I47 -> 28.29276 | G37: 0.9 | H37: =F37*G37 -> 25.463484
B38: Dishwasher | C38: N/A | D38: N/A | E38: N/A | F38: ='2. Indoor Water Demand'!I48 -> 0.89646 | G38: 0.9 | H38: =F38*G38 -> 0.806814
B39: TOTAL | C39: =SUM(C32:C38) -> 53.36349 | E39: =SUM(E32:E38) -> 48.027141 | F39: =SUM(F32:F38) -> 41.41002 | H39: =SUM(H32:H38) -> 37.269018
B41: Notes:
B42: (1) Graywater and blackwater supply availability are estimated assuming a 10% treatment loss.
B44: C. COOLING TOWER DISCHARGE (No user input needed - auto-calculated from Step 2)
B46: Month | C46: Cooling Demand (gpd) from Step 2. | D46: Cooling Demand (gal/mth) from Step 2. | E46: Treatment Recovery Rate (1) (%) | F46: Estimated Cooling Tower Discharge (gpd) (2) | G46: Estimated Cooling Tower Discharge (gal/mth)
B47: January | C47: ='2. Indoor Water Demand'!E63 -> 0 | D47: ='2. Indoor Water Demand'!F63 -> 0 | E47: 0.9 | F47: =C47*E47 -> 0 | G47: =D47*E47 -> 0
B48: February | C48: ='2. Indoor Water Demand'!E64 -> 0 | D48: ='2. Indoor Water Demand'!F64 -> 0 | E48: 0.9 | F48: =C48*E48 -> 0 | G48: =D48*E48 -> 0
B49: March | C49: ='2. Indoor Water Demand'!E65 -> 0 | D49: ='2. Indoor Water Demand'!F65 -> 0 | E49: 0.9 | F49: =C49*E49 -> 0 | G49: =D49*E49 -> 0
B50: April | C50: ='2. Indoor Water Demand'!E66 -> 0 | D50: ='2. Indoor Water Demand'!F66 -> 0 | E50: 0.9 | F50: =C50*E50 -> 0 | G50: =D50*E50 -> 0
B51: May | C51: ='2. Indoor Water Demand'!E67 -> 0 | D51: ='2. Indoor Water Demand'!F67 -> 0 | E51: 0.9 | F51: =C51*E51 -> 0 | G51: =D51*E51 -> 0
...

Sheet 4. Outdoor Water Demand
A1: NON-POTABLE WATER CALCULATOR
A2: Step 4 of 7: Calculate Outdoor Water Demand (Landscape Irrigation, Outdoor Water Features)
B4: Project Name: | F4: LEGEND:
B5: ='1. Building Information'!$C$13 -> ABC Building | F5: User Input
F6: Linked from User Input
B7: Instructions: | F7: Default Value
B8: Annual outdoor water demand is calculated based on landscape irrigation demand and demand associated with other outdoor features such as decorative fountains. User input is required in Sections A and B. This step also includes information on compliance with the City's landscape irrigation ordinance in Section C. | F8: Autogenerated Value
B13: A. LANDSCAPE IRRIGATION DEMAND
B14: User Input Instructions:
B15: Default irrigation factors are provided in the cells below; refine default values as appropriate
B17: ='1. Building Information'!B111 -> Turfgrass | C17: ='1. Building Information'!$C$111 -> 1 | D17: ft2 | I17: Definitions - For more guidance, refer to: | L17: The Guide to Estimating Water Needs of Landscape Plantings in CA
B18: Crop Coefficient - Kc | C18: 0.7 | D18: [Refine as appropriate] Cool season grasses = 0.8, Warm season grasses = 0.6 | I18: Crop Coefficient (KC):
B19: ='1. Building Information'!B112 -> Landscaped Area | C19: ='1. Building Information'!$C$112 -> 0 | D19: ft2 | I19: Water loss from turfgrass or a crop.
B20: Species Factor - ks | C20: 0.5 | D20: [Refine as appropriate] <0.1 for very low, 0.1-0.3 for low, 0.4-0.6 for medium, 0.7-0.9 for high
B21: Density Factor - kd | C21: 1 | D21: [Refine as appropriate] 0.5-0.9 for low, 1 for average, 1.1-1.3 for high. | I21: Landscape Coefficient (KL):
B22: Microclimate Factor - kmc | C22: 1 | D22: [Refine as appropriate] 0.5-0.9 for low, 1 for average, 1.1-1.4 for high. | I22: Water loss from landscape plantings based on species, density and microclimate factors.
B23: Landscape Coefficient - KL | C23: =C20*C21*C22 -> 0.5 | D23: KL = ks*kd*kmc
B24: ='1. Building Information'!$B$113 -> Green Roof | C24: ='1. Building Information'!$C$113 -> 0 | D24: ft2 | I24: Species Factor (ks):
B25: Species Factor - ks | C25: 0.1 | D25: [Refine as appropriate] <0.1 for very low, 0.1-0.3 for low, 0.4-0.6 for medium, 0.7-0.9 for high. | I25: Used to account for differences in species' water needs. Refer to Pg. 12 of the Guide to Estimating Water Needs of Landscape Plantings in CA to determine species factors.
B26: Density Factor - kd | C26: 1 | D26: [Refine as appropriate] 0.5-0.9 for low, 1 for average, 1.1-1.3 for high.
B27: Microclimate Factor - kmc | C27: 1.2 | D27: [Refine as appropriate] 0.5-0.9 for low, 1 for average, 1.1-1.4 for high.
B28: Landscape Coefficient - KL | C28: =C25*C26*C27 -> 0.12 | D28: KL = ks*kd*kmc | I28: Density Factor (kd):
B29: ='1. Building Information'!$B$114 -> Other <Please Specify> | C29: ='1. Building Information'!C114 -> 0 | D29: ft2 | I29: Used to account for differences in vegetation density among landscape plantings. Refer to Pg. 18 of the Guide to Estimating Water Needs of Landscape Plantings in CA on how to determine density factors.
B30: Species Factor - ks | C30: 0 | D30: [Refine as appropriate] <0.1 for very low, 0.1-0.3 for low, 0.4-0.6 for medium, 0.7-0.9 for high.
B31: Density Factor - kd | C31: 0 | D31: [Refine as appropriate] 0.5-0.9 for low, 1 for average, 1.1-1.3 for high.
B32: Microclimate Factor - kmc | C32: 0 | D32: [Refine as appropriate] 0.5-0.9 for low, 1 for average, 1.1-1.4 for high.
B33: Landscape Coefficient - KL | C33: =C30*C31*C32 -> 0 | D33: KL = ks*kd*kmc | I33: Microclimate Factor (kmc):
B34: Total Irrigation Area | C34: =SUM(C19,C17,C24,C29) -> 1 | D34: ft2 | I34: Used to account for differences in microclimate in every landscape. An "average" microclimate condition is equivalent to reference evapotranspiration conditions. This microclimate is not substantially affected by nearby buildings, structures, pavements, slopes or reflective surfaces.
B35: Average Coefficient | C35: =IF(C34>0,(C17*C18+C19*C23+C24*C28+C29*C33)/C34,0) -> 0.7
B36: Irrigation Efficiency | C36: 0.9 | D36: [Refine as appropriate] Estimated efficiencies are 0.70 to 0.85 for spray, 0.9 for drip, 0.95 for subsurface drip.
B37: Site Location (ET0 Zone) | C37: ='1. Building Information'!$C$122 -> Eastern SF
B40: Month | C40: Ave. Monthly Rainfall | D40: Reference Evapotranspiration | E40: Actual Evapotranspiration | F40: Irrigation Demand | I40: % of Annual
C41: in/month | D41: ET0 | E41: ETL | F41: ft3/month | G41: gal/mo | H41: gpd | K41: Month | L41: (in/unit area) | M41: days/mo
B42: January | C42: 4.5616 | D42: =IF($C$37="Western SF",'Climate Data'!D27,'Climate Data'!D8) -> 1.24 | E42: =D42*$C$35 -> 0.868 | F42: =(L42/12)*$C$34 -> 0 | K42: January | L42: =IF(E42-C42>0, (E42-C42)/$C$36,0) -> 0 | M42: 31
B43: February | C43: 3.845 | D43: =IF($C$37="Western SF",'Climate Data'!D28,'Climate Data'!D9) -> 1.68 | E43: =D43*$C$35 -> 1.176 | F43: =(L43/12)*$C$34 -> 0 | K43: February | L43: =IF(E43-C43>0, (E43-C43)/$C$36,0) -> 0 | M43: 28
B44: March | C44: 2.9074 | D44: =IF($C$37="Western SF",'Climate Data'!D29,'Climate Data'!D10) -> 3.1 | E44: =D44*$C$35 -> 2.17 | F44: =(L44/12)*$C$34 -> 0 | K44: March | L44: =IF(E44-C44>0, (E44-C44)/$C$36,0) -> 0 | M44: 31
B45: April | C45: 1.4120619 | D45: =IF($C$37="Western SF",'Climate Data'!D30,'Climate Data'!D11) -> 3.9 | E45: =D45*$C$35 -> 2.73 | F45: =(L45/12)*$C$34 -> 0.12203131 | G45: =(F45*7.48) -> 0.9127942 | H45: =(G45)/M45 -> 0.030426473 | I45: =G45/$G$54 -> 0.076883136 | K45: April | L45: =IF(E45-C45>0, (E45-C45)/$C$36,0) -> 1.4643757 | M45: 30
B46: May | C46: 0.62825581 | D46: =IF($C$37="Western SF",'Climate Data'!D31,'Climate Data'!D12) -> 4.65 | E46: =D46*$C$35 -> 3.255 | F46: =(L46/12)*$C$34 -> 0.24321705 | G46: =(F46*7.48) -> 1.8192636 | H46: =(G46)/M46 -> 0.058685921 | I46: =G46/$G$54 -> 0.15323354 | K46: May | L46: =IF(E46-C46>0, (E46-C46)/$C$36,0) -> 2.9186047 | M46: 31
B47: June | C47: 0.22030303 | D47: =IF($C$37="Western SF",'Climate Data'!D32,'Climate Data'!D13) -> 5.1 | E47: =D47*$C$35 -> 3.57 | F47: =(L47/12)*$C$34 -> 0.31015713 | G47: =(F47*7.48) -> 2.3199753 | H47: =(G47)/M47 -> 0.07733251 | I47: =G47/$G$54 -> 0.19540766 | K47: June | L47: =IF(E47-C47>0, (E47-C47)/$C$36,0) -> 3.7218855 | M47: 30
B48: July | C48: 0.049722222 | D48: =IF($C$37="Western SF",'Climate Data'!D33,'Climate Data'!D14) -> 4.96 | E48: =D48*$C$35 -> 3.472 | F48: =(L48/12)*$C$34 -> 0.31687757 | G48: =(F48*7.48) -> 2.3702442 | H48: =(G48)/M48 -> 0.076459492 | I48: =G48/$G$54 -> 0.19964173 | K48: July | L48: =IF(E48-C48>0, (E48-C48)/$C$36,0) -> 3.8025309 | M48: 31
...

Sheet 5. Outdoor Water Supply
A1: NON-POTABLE WATER CALCULATOR
A2: Step 5 of 7: Calculate Outdoor Water Supply (Rainwater and Stormwater Harvesting)
B4: Project Name: | F4: LEGEND:
B5: ='1. Building Information'!$C$13 -> ABC Building | F5: User Input
F6: Linked from User Input
B7: Instructions: | F7: Default Value
B8: Annual outdoor water supply is calculated based on the amount of rainwater and/or stormwater captured. User input is required in Sections A and B. | F8: Autogenerated Value
B11: A. RAINWATER SUPPLY (Runoff harvested above grade, e.g. rooftops)
B12: User Input Instructions:
B13: Default Rainwater Supply coefficients are entered below; refine default coefficients as appropriate
B15: ='1. Building Information'!B100 -> Roof (Conventional) | C15: ='1. Building Information'!C100 -> 1 | D15: ft2
B16: Roof Runoff Coefficient | C16: 0.85 | D16: [Refine as appropriate] Conventional roof runoff coefficient = 0.85
B17: ='1. Building Information'!B101 -> Other <Please Specify> | C17: ='1. Building Information'!C101 -> 0 | D17: ft2
B18: Runoff Coefficient | C18: 0.7 | D18: [Refine as appropriate]
B19: Total Above Grade Capture Area | C19: =C15+C17 -> 1 | D19: ft2
B20: Average Runoff Coefficient | C20: =IF(C19>0,(C15*C16+C17*C18)/C19,0) -> 0.85
B22: Rainfall Capture Factor | C22: 0.8 | D22: [Refine as appropriate]
B24: Month | C24: Ave. Monthly Rainfall | D24: Days in Month | E24: Total Rainwater Supply (with Rainfall Capture Factor Applied)
C25: in/mth | E25: gal/month | F25: gpd
B26: January | C26: ='Climate Data'!C8 -> 4.5616 | D26: 31 | E26: =((C26/12)*$C$19*$C$20)*7.48*$C$22 -> 1.9335102 | F26: =E26/D26 -> 0.062371296
B27: February | C27: ='Climate Data'!C9 -> 3.845 | D27: 28 | E27: =((C27/12)*$C$19*$C$20)*7.48*$C$22 -> 1.6297673 | F27: =E27/D27 -> 0.058205976
B28: March | C28: ='Climate Data'!C10 -> 2.9074 | D28: 31 | E28: =((C28/12)*$C$19*$C$20)*7.48*$C$22 -> 1.2323499 | F28: =E28/D28 -> 0.039753224
B29: April | C29: ='Climate Data'!C11 -> 1.4120619 | D29: 30 | E29: =((C29/12)*$C$19*$C$20)*7.48*$C$22 -> 0.59852595 | F29: =E29/D29 -> 0.019950865
B30: May | C30: ='Climate Data'!C12 -> 0.62825581 | D30: 31 | E30: =((C30/12)*$C$19*$C$20)*7.48*$C$22 -> 0.2662967 | F30: =E30/D30 -> 0.0085902161
B31: June | C31: ='Climate Data'!C13 -> 0.22030303 | D31: 30 | E31: =((C31/12)*$C$19*$C$20)*7.48*$C$22 -> 0.093379111 | F31: =E31/D31 -> 0.003112637
B32: July | C32: ='Climate Data'!C14 -> 0.049722222 | D32: 31 | E32: =((C32/12)*$C$19*$C$20)*7.48*$C$22 -> 0.021075593 | F32: =E32/D32 -> 0.00067985783
B33: August | C33: ='Climate Data'!C15 -> 0.1076087 | D33: 31 | E33: =((C33/12)*$C$19*$C$20)*7.48*$C$22 -> 0.045611739 | F33: =E33/D33 -> 0.0014713464
B34: September | C34: ='Climate Data'!C16 -> 0.3703125 | D34: 30 | E34: =((C34/12)*$C$19*$C$20)*7.48*$C$22 -> 0.15696312 | F34: =E34/D34 -> 0.0052321042
B35: October | C35: ='Climate Data'!C17 -> 1.0346392 | D35: 31 | E35: =((C35/12)*$C$19*$C$20)*7.48*$C$22 -> 0.43854906 | F35: =E35/D35 -> 0.014146744
B36: November | C36: ='Climate Data'!C18 -> 2.6849485 | D36: 30 | E36: =((C36/12)*$C$19*$C$20)*7.48*$C$22 -> 1.1380602 | F36: =E36/D36 -> 0.037935338
B37: December | C37: ='Climate Data'!C19 -> 4.0832323 | D37: 31 | E37: =((C37/12)*$C$19*$C$20)*7.48*$C$22 -> 1.7307461 | F37: =E37/D37 -> 0.055830519
B38: TOTAL | C38: =SUM(C26:C37) -> 21.905084 | D38: =SUM(D26:D37) -> 365 | E38: =SUM(E26:E37) -> 9.284835
B40: TOTAL RAINWATER SUPPLY | C40: =E38 -> 9.284835 | D40: gpy
B42: B. STORMWATER SUPPLY (Runoff harvested at or below grade, e.g. paved plazas, sidewalks or roads)
B43: User Input Instructions:
B44: Default Stormwater Supply coefficients are entered below; refine default coefficients as appropriate
B46: ='1. Building Information'!B105 -> Pavement (Conventional) | C46: ='1. Building Information'!C105 -> 1 | D46: ft2
B47: Runoff Coefficient | C47: 0.9 | D47: [Refine as appropriate] Typical impervious surface runoff coefficient = 0.90
B48: ='1. Building Information'!B106 -> Other <Please Specify> | C48: ='1. Building Information'!C106 -> 0 | D48: ft2
B49: Runoff Coefficient | C49: 0.8 | D49: [Refine as appropriate]
...

Sheet 1. WQv and WQf
A1: WATER QUALITY VOLUME AND WATER QUALITY FLOW RATE CALCULATOR
A2: This work sheet calculates the Water Quality Flow Rates or Water Quality Volumes for each drainage management area on your site.
A4: CALCULATOR
A5: Step 1 | C5: Total Site Area | E5: square feet
A6: Step 2 | C6: # of DMAs
A8: Step 3 | C8: Step 4 | E8: Step 5 | I8: Step 6 | K8: Step 7 | M8: Step 8 | T8: Step 9 | U8: Step 10
D9: Area Impervious (all in square feet) | J9: Area Pervious (all in square feet)
A10: Drainage Management Areas | C10: Drainage Management Area (square feet) | D10: TOTAL | E10: Standard Roof | F10: Asphalt | G10: Concrete | H10: Brick/Pavers | I10: Other | J10: TOTAL | K10: Permeable Pavementa | L10: Vegetated Roofb | M10: Gravelc | N10: Landscaping | O10: Grass Pavers/Turf Blocks | P10: Lawns/grass, sandy soil, slope<2% | Q10: Lawns/grass, sandy soil, slope>7% | R10: Lawns/grass, heavy soil, slope<2% | S10: Lawns/grass, heavy soil, slope>7% | T10: Other | U10: Total Area Check
A12: A | D12: =SUM(E12:I12) -> 0 | J12: =SUM(K12:T12) -> 0 | U12: =IF(J12+D12=C12,"Okay","Check Areas!") -> Okay
A13: B | D13: =SUM(E13:I13) -> 0 | J13: =SUM(K13:T13) -> 0 | U13: =IF(J13+D13=C13,"Okay","Check Areas!") -> Okay
A14: C | D14: =SUM(E14:I14) -> 0 | J14: =SUM(K14:T14) -> 0 | U14: =IF(J14+D14=C14,"Okay","Check Areas!") -> Okay
A15: D | D15: =SUM(E15:I15) -> 0 | J15: =SUM(K15:T15) -> 0 | U15: =IF(J15+D15=C15,"Okay","Check Areas!") -> Okay
A16: E | D16: =SUM(E16:I16) -> 0 | J16: =SUM(K16:T16) -> 0 | U16: =IF(J16+D16=C16,"Okay","Check Areas!") -> Okay
A17: F | D17: =SUM(E17:I17) -> 0 | J17: =SUM(K17:T17) -> 0 | U17: =IF(J17+D17=C17,"Okay","Check Areas!") -> Okay
A18: G | D18: =SUM(E18:I18) -> 0 | J18: =SUM(K18:T18) -> 0 | U18: =IF(J18+D18=C18,"Okay","Check Areas!") -> Okay
A19: H | D19: =SUM(E19:I19) -> 0 | J19: =SUM(K19:T19) -> 0 | U19: =IF(J19+D19=C19,"Okay","Check Areas!") -> Okay
A20: I | D20: =SUM(E20:I20) -> 0 | J20: =SUM(K20:T20) -> 0 | U20: =IF(J20+D20=C20,"Okay","Check Areas!") -> Okay | AD20: Comp | AE20: Unit Basin Storage - inches
A21: J | D21: =SUM(E21:I21) -> 0 | J21: =SUM(K21:T21) -> 0 | U21: =IF(J21+D21=C21,"Okay","Check Areas!") -> Okay | AD21: C' | AE21: 24 hr drawdown | AG21: 48 hr drawdown
B22: Total | C22: =SUM(C12:C21) -> 0 | AD22: Factor | AE22: 0.8 | AF22: 0.9 | AG22: 0.8 | AH22: 0.9
B23: Total Area Check | C23: =IF(C22=D5,"Okay","Check Total and DMA Areas!") -> Okay | E23: Impervious Runoff Coefficients | M23: Pervious Runoff Coefficients | AD23: 0.05 | AE23: 0.025 | AF23: 0.04 | AG23: 0.04 | AH23: 0.055
B24: Number of DMAs Check | C24: =IF(COUNTA(C12:C21)=D6,"Okay","Check Number of DMAs!") -> Okay | E24: Standard Roof | H24: 0.85 | M24: Permeable Pavement a | Q24: NA | AD24: 0.1 | AE24: 0.06 | AF24: 0.075 | AG24: 0.075 | AH24: 0.105
E25: Asphalt | H25: 0.8 | M25: Vegetated Roof b | Q25: NA | AD25: 0.15 | AE25: 0.085 | AF25: 0.12 | AG25: 0.11 | AH25: 0.15
E26: Concrete | H26: 0.9 | M26: Gravel c | Q26: 0.25 | AD26: 0.2 | AE26: 0.11 | AF26: 0.1525 | AG26: 0.1475 | AH26: 0.2
E27: Brick/Pavers | H27: 0.75 | M27: Landscaping | Q27: 0.2 | AD27: 0.25 | AE27: 0.135 | AF27: 0.19 | AG27: 0.185 | AH27: 0.2525
E28: Other | I28: Step 6 | M28: Grass Pavers/Turf Blocks | Q28: 0.35 | AD28: 0.3 | AE28: 0.1625 | AF28: 0.23 | AG28: 0.2275 | AH28: 0.305
M29: Lawns/grass, sandy soil, slope<2% | Q29: 0.08 | AD29: 0.35 | AE29: 0.19 | AF29: 0.26 | AG29: 0.26 | AH29: 0.3575
C30: Step 11 | M30: Lawns/grass, sandy soil, slope>7% | Q30: 0.17 | AD30: 0.4 | AE30: 0.215 | AF30: 0.3 | AG30: 0.2975 | AH30: 0.4075
A31: Drainage Management Area | C31: Composite Runoff Coefficient | M31: Lawns/grass, heavy soil, slope<2% | Q31: 0.15 | AD31: 0.45 | AE31: 0.24 | AF31: 0.325 | AG31: 0.3325 | AH31: 0.46
A32: A | B32: =B12 -> 0 | D32: =(E12*$H$24+F12*$H$25+G12*$H$26+H12*$H$27+I12*$H$28+K12*0+L12*0+M12*$Q$26+N12*$Q$27+O12*$Q$28+P12*$Q$29+Q12*$Q$30+R12*$Q$31+S12*$Q$32+T12*$Q$33)/(J12+D12) -> #DIV/0! | M32: Lawns/grass, heavy soil, slope>7% | Q32: 0.3 | AD32: 0.5 | AE32: 0.27 | AF32: 0.375 | AG32: 0.37 | AH32: 0.51
A33: B | B33: =B13 -> 0 | D33: =(E13*$H$24+F13*$H$25+G13*$H$26+H13*$H$27+I13*$H$28+K13*0+L13*0+M13*$Q$26+N13*$Q$27+O13*$Q$28+P13*$Q$29+Q13*$Q$30+R13*$Q$31+S13*$Q$32+T13*$Q$33)/(J13+D13) -> #DIV/0! | M33: Other | R33: Step 9 | AD33: 0.55 | AE33: 0.3 | AF33: 0.42 | AG33: 0.4075 | AH33: 0.5605
A34: C | B34: =B14 -> 0 | D34: =(E14*$H$24+F14*$H$25+G14*$H$26+H14*$H$27+I14*$H$28+K14*0+L14*0+M14*$Q$26+N14*$Q$27+O14*$Q$28+P14*$Q$29+Q14*$Q$30+R14*$Q$31+S14*$Q$32+T14*$Q$33)/(J14+D14) -> #DIV/0! | AD34: 0.6 | AE34: 0.325 | AF34: 0.4525 | AG34: 0.44 | AH34: 0.615
A35: D | B35: =B15 -> 0 | D35: =(E15*$H$24+F15*$H$25+G15*$H$26+H15*$H$27+I15*$H$28+K15*0+L15*0+M15*$Q$26+N15*$Q$27+O15*$Q$28+P15*$Q$29+Q15*$Q$30+R15*$Q$31+S15*$Q$32+T15*$Q$33)/(J15+D15) -> #DIV/0! | H35: Chose Jurisdiction for WQv Performance Measure | R35: Step 12 | AD35: 0.65 | AE35: 0.35 | AF35: 0.495 | AG35: 0.48 | AH35: 0.665
A36: E | B36: =B16 -> 0 | D36: =(E16*$H$24+F16*$H$25+G16*$H$26+H16*$H$27+I16*$H$28+K16*0+L16*0+M16*$Q$26+N16*$Q$27+O16*$Q$28+P16*$Q$29+Q16*$Q$30+R16*$Q$31+S16*$Q$32+T16*$Q$33)/(J16+D16) -> #DIV/0! | H36: 1. | I36: Port of San Francisco jurisdiction: 48 hour, 80% capture. Enter "1" in Step 12. | AD36: 0.7 | AE36: 0.38 | AF36: 0.53 | AG36: 0.515 | AH36: 0.72
A37: F | B37: =B17 -> 0 | D37: =(E17*$H$24+F17*$H$25+G17*$H$26+H17*$H$27+I17*$H$28+K17*0+L17*0+M17*$Q$26+N17*$Q$27+O17*$Q$28+P17*$Q$29+Q17*$Q$30+R17*$Q$31+S17*$Q$32+T17*$Q$33)/(J17+D17) -> #DIV/0! | H37: 2. | I37: SFPUC jurisdiction: 0.75 inch rainfall depth. Enter "2" in Step 12. | AD37: 0.75 | AE37: 0.41 | AF37: 0.565 | AG37: 0.5525 | AH37: 0.77
A38: G | B38: =B18 -> 0 | D38: =(E18*$H$24+F18*$H$25+G18*$H$26+H18*$H$27+I18*$H$28+K18*0+L18*0+M18*$Q$26+N18*$Q$27+O18*$Q$28+P18*$Q$29+Q18*$Q$30+R18*$Q$31+S18*$Q$32+T18*$Q$33)/(J18+D18) -> #DIV/0! | AD38: 0.8 | AE38: 0.43 | AF38: 0.605 | AG38: 0.59 | AH38: 0.82
A39: H | B39: =B19 -> 0 | D39: =(E19*$H$24+F19*$H$25+G19*$H$26+H19*$H$27+I19*$H$28+K19*0+L19*0+M19*$Q$26+N19*$Q$27+O19*$Q$28+P19*$Q$29+Q19*$Q$30+R19*$Q$31+S19*$Q$32+T19*$Q$33)/(J19+D19) -> #DIV/0! | H39: WQf Performance Measure | AD39: 0.85 | AE39: 0.465 | AF39: 0.645 | AG39: 0.625 | AH39: 0.87
A40: I | B40: =B20 -> 0 | D40: =(E20*$H$24+F20*$H$25+G20*$H$26+H20*$H$27+I20*$H$28+K20*0+L20*0+M20*$Q$26+N20*$Q$27+O20*$Q$28+P20*$Q$29+Q20*$Q$30+R20*$Q$31+S20*$Q$32+T20*$Q$33)/(J20+D20) -> #DIV/0! | H40: Design Rainfall Intensity (in/hr) | Q40: 0.2 | AD40: 0.9 | AE40: 0.49 | AF40: 0.685 | AG40: 0.66 | AH40: 0.92
A41: J | B41: =B21 -> 0 | D41: =(E21*$H$24+F21*$H$25+G21*$H$26+H21*$H$27+I21*$H$28+K21*0+L21*0+M21*$Q$26+N21*$Q$27+O21*$Q$28+P21*$Q$29+Q21*$Q$30+R21*$Q$31+S21*$Q$32+T21*$Q$33)/(J21+D21) -> #DIV/0! | H41: Note: For both the Port of San Francisco and the SFPUC, the WQf performance measure is based on a 0.2 in/hr rainfall intensity. | AD41: 0.95 | AE41: 0.515 | AF41: 0.72 | AG41: 0.695 | AH41: 0.97
AD42: 1 | AE42: 0.54 | AF42: 0.755 | AG42: 0.735 | AH42: 1.025
C43: Step 13 | F43: Step 14 | J43: Step 15
...

Sheet Infiltration Trench_Dry Well
A1: INFILTRATION TRENCH/DRY WELL CALCULATOR
A2: These calculators size an infiltration trench or drywell to treat the Water Quality Volume (WQv), or calculate the volume of water treated given user entered available dimensions.
A8: CALCULATOR
A9: Infiltration Trench/Dry Well Calculator - by Water Quality Volume
A10: 1 | B10: Water Quality Volume - WQv | E10: cubic feet
A11: 2 | B11: Porosity - n | C11: 0.35 | E11: recommend 0.35 for coarse aggregate
A12: 3 | B12: Infiltration Rate - f | E12: inches/hour (generally require f ≥0.5"/hr)
B13: Safety Factor | C13: 2 | E13: recommend 2
B14: Fill time - T | C14: 2 | E14: hours (1 to 2 hours, recommend 2)
B15: Max Drain Time - t | C15: 48 | E15: hours (recommend 48)
A16: 4 | B16: Depth to GW/Bedrock | E16: feet
A18: 5 | B18: Max Allowable Depth - dmax | C18: =IF(C12/C13*C15/12/C11<C16-4,ROUND(C12/C13*C15/12/C11,1),ROUND(C16-4,1)) -> -4 | E18: feet
B19: Design Trench Depth - d | E19: feet (between 3 to 8 feet)
B20: Check Depth | C20: =IF(AND(C19<=C18, C19<=8),"Okay","Error, reduce depth") -> Error, reduce depth
A22: 6 | B22: Base Area Calculator | C22: =$C$10/(($C$11*$C$19)+(($C$12/C13*$C$14)/12)) -> #DIV/0! | E22: square feet
A23: 7 | B23: Width of Trench | E23: feet (should be less than 25 feet)
A25: 8 | B25: Dimension Calculator
B26: Depth | C26: =C19 -> 0 | E26: feet
B27: Width | C27: =C23 -> 0 | E27: feet
B28: Length | C28: =C22/C23 -> #DIV/0! | E28: feet
B29: Dry Well Diameter | C29: =((C22/PI())^0.5)*2 -> #DIV/0! | E29: feet
B30: Estimated Drainage Area | C30: =C10/0.9/(0.75/12) -> 0 | E30: sf
B31: BMP Area/Drainage Area | C31: =C22/C30 -> #DIV/0!
A33: Infiltration Trench/Dry Well Calculator - by Available Dimensions
A34: 9 | B34: Available Length (or Diameter for Dry Well) | E34: feet
A35: 10 | B35: Available Width | E35: feet (should be less than 25 feet)
A36: 11 | B36: Porosity - n | E36: recommend 0.35
A37: 12 | B37: Infiltration Rate - f | E37: inches/hour (generally require f ≥0.5"/hr)
B38: Safety Factor | C38: 2 | E38: recommend 2
B39: Fill Time - T | C39: 2 | E39: hours (1 to 2 hours, recommend 2)
B40: Max Drain Time - t | C40: 48 | E40: hours (recommend 48)
A41: 13 | B41: Depth to GW/Bedrock | E41: feet
A43: 14 | B43: Max Allowable Depth - dmax | C43: =IF(C37/C38*C40/12/C36<C41-4,ROUND(C37/C38*C40/12/C36,1),ROUND(C41-4,1)) -> #DIV/0! | E43: feet
B44: Design Trench Depth - d | E44: feet (between 3 to 8 feet)
B45: Check Depth | C45: =IF(AND(C44<=C43, C44<=8),"Okay","Error, reduce depth") -> #DIV/0!
A47: 15 | B47: Treated Volume - Infiltration Trench | C47: =$C$34*$C$35*(($C$36*$C$44)+($C$37/C38*$C$39/12)) -> 0 | E47: cubic feet
B48: Treated Volume - Dry Well | C48: =PI()*((C34/2)^2)*(($C$36*$C$44)+($C$37/2*$C$39/12)) -> 0 | E48: cubic feet
A50: INSTRUCTIONS
A51: Use either steps 1 through 8 to determine the required size of your trench. Or use steps 9 through 15 to check what volume of water is treated given the available dimensions of your trench.
A53: To Determine The Required Size of the Infiltration Trench/Dry Well
...

Sheet Infiltration Basin
A1: INFILTRATION BASIN CALCULATOR
A2: This calculator sizes an infiltration basin to treat the Water Quality Volume (WQv).
A7: CALCULATOR
A8: Infiltration Basin Calculator - by Water Quality Volume
A9: 1 | B9: Water Quality Volume - WQv | E9: cubic feet
A10: 2 | B10: Infiltration rate - f | E10: inches/hour (generally require f>0.5"/hr)
A11: 3 | B11: Safety Factor | C11: 2 | E11: recommend 2
A12: 4 | B12: Max drawdown time - t | C12: 48 | E12: hours (recommend between 24 and 48 hours)
A13: 5 | B13: Base Area Calculator | C13: =C9/(C12*C10/2/12) -> #DIV/0! | E13: square feet
A15: 6 | B15: Side Slope | E15: feet/feet (ratio of horizontal to vertical, for example, 3 for 3H:1V)
A16: 7 | B16: Width of Basin Bottom | E16: feet
A17: 8 | B17: Length of Basin Bottom | C17: =C13/C16 -> #DIV/0! | E17: feet
A18: 9 | B18: Depth at WQv - d | E18: feet (generally between 1 and 3 feet, recommend 2 feet)
A19: 10 | B19: Width of Basin at WQv Depth | C19: =C16+C15*C18*2 -> 0 | E19: feet
B20: Length of Basin at WQv Depth | C20: =C17+C15*C18*2 -> #DIV/0! | E20: feet
A21: 11 | B21: Storage Volume | C21: =C18*(C16*C17+C19*C20+SQRT(C16*C17*C19*C20))/3 -> #DIV/0! | E21: cubic feet (adjust depth in Step 9 until storage volume is greater than WQv)
A22: 12 | B22: Check of Volume | C22: =IF(C21>C9,"Okay", "Error, increase depth") -> #DIV/0!
B23: Est. Impervious DMA | C23: =C9/(0.75/12)/0.9 -> 0 | E23: ft2
B24: Sizing Ratio (BMP/DMA) | C24: =C20*C19/C23 -> #DIV/0!
A26: INSTRUCTIONS
A27: Follow the steps below to determine the required size of your basin.
A29: Step
A30: 1 | B30: Enter the Water Quality Volume (WQv) for the DMA. The WQv is calculated in Step 14 of the Water Quality Volume and Water Quality Flow Rate Calculator.
A31: 2 | B31: Enter the infiltration rate of the underlying soils. This should be determined by geotechnical testing or, for conceptual studies, soil infiltration maps.
A32: 3 | B32: A recommended safety factor of 2 will be applied to the infiltration rate to account for the inherent uncertainties in rate measurement and the decrease in infiltration rate over time.
A33: 4 | B33: The recommended maximum drawdown time for the infiltration basin is 48 hours.
A34: 5 | B34: The minimum base area of the infiltration basin is calculated here based on infiltrating the entire WQv within the maximum drawdown time.
A35: 6 | B35: Enter the side slope of the basin. The slope of earthen side walls should be no steeper than 3:1 (i.e., at least 3 feet horizontal for each 1 foot vertical). Enter 0 for vertical sidewalls.
A36: 7 | B36: Enter the width of the basin bottom.
A37: 8 | B37: The length of the basin bottom is calculated based on the base area and width.
A38: 9 | B38: Enter the design water depth of the infiltration basin (i.e., the water depth when the basin has completely captured the WQv event). Depths are typically between 1 and 3 feet. This depth DOES NOT include freeboard, which is typically 1 foot above the design depth (freeboard should be added in actual design).
A39: 10 | B39: The width and length of the basin at the design water depth (i.e., WQv depth) are calculated here.
A40: 11 | B40: The storage volume in the basin is calculated here. If the volume is less than the WQv entered in Step 1, increase the basin depth.
A41: 12 | B41: This step checks that the storage volume is greater than the WQv entered in Step 1.
A43: DEFINITIONS
B44: Water Quality Volume (WQv) | C44: The runoff volume to be managed by the stormwater BMP such that treatment requirements are met. The WQv is calculated by the Water Quality Volume and Water Quality Flow Rate Calculator.
B45: Infiltration Rate (f) | C45: The rate of water entry into the soil, generally expressed as inches/hour, and determined by geotechnical tests or estimated from soil maps. It equals the hydraulic conductivity of the soil times the hydraulic gradient.
B46: Drain Time (t) | C46: The time for the storage area to drain the water quality volume.
B47: Depth at WQv (d) | C47: The depth of the basin from the design water level to the invert of the basin. Does not include freeboard.
B48: Freeboard | C48: The vertical distance between the maximum design water depth and the top of the basin embankments.

Sheet Permeable Pavement
A1: PERMEABLE PAVEMENT CALCULATOR
A2: These calculators size the area of permeable pavement to treat the Water Quality Volume (WQv). The calculator can be used for underdrained installations or infiltration installations.
A8: CALCULATOR
A9: Permeable Pavement Calculator - by Water Quality Volume
A10: 1 | B10: Water Quality Volume - WQv | E10: cubic feet
A11: 2 | B11: Drainage Management Area | E11: square feet (include the area planned for permeable pavement)
A12: 3 | B12: Permeable Pavement (PP) Type | E12: select pavement type
A13: 4 | B13: PP Area as % of Total Drainage Area | C13: =IF(C12="Permeable Pavers", 40%,40%) -> 0.4 | E13: min allowable is 40%, i.e., 1 part permeable pavement to 1.5 parts impermeable paved drainage area
A14: 5 | B14: Minimum PP Area | C14: =C11*C13 -> 0 | E14: square feet
A15: 6 | B15: Infiltration Rate of In Situ Soils - f | E15: inches/hour (enter 0 if system will be lined due to subsurface constraints)
B16: Safety Factor | C16: 2 | E16: recommend 2 to account for decline over time and uncertainty in measurement
A17: 7 | B17: Underdrains Required | C17: =IF(C15/C16<0.25,"Yes", "No") -> Yes | E17: required if f ≤ 0.5 inches/hour
A18: 8 | B18: Porosity of Storage Media - n | C18: 0.35 | E18: recommend 0.35
B19: Fill Time - T | C19: 2 | E19: hours (generally 2)
A21: 9 | B21: Depth of Bedding Layer | E21: inches (generally 2")
B22: Depth of Transition Layer | E22: inches (generally 3 to 4")
B23: Depth Needed to Store WQv | C23: =(C$10-C$15/C$16/12*C$14*C$19)/(C$14*C$18)*12 -> #DIV/0! | E23: inches
A24: 10 | B24: Minimum Depth of Storage Layer | C24: =MAX((C$10-C$15/C$16/12*C$14*C$19)/(C$14*C$18)*12,6) -> #DIV/0! | E24: inches (as needed to store the WQv, minimum of 6")
A26: 11 | B26: Time Needed to Infiltrate WQV (no underdrain) | C26: =IF(C17="No",C10/(C15/C16/12)/C14,"N/A") -> N/A | E26: hours (if greater than 48 hours, install underdrains)
A27: 12 | B27: Drain Time (for underdrained systems) - t | E27: hours (24 to 48, recommend 48)
A28: 13 | B28: Ave. Discharge Rate for Drain Time | C28: =IF(C17="No", "N/A",(C10/(C27*60*60))*7.48*60) -> #DIV/0! | E28: gpm (use orifice or other means to control discharge rate)
B29: Estimated Drainage Area | C29: =C10/0.9/(0.75/12) -> 0 | E29: ft2
B30: Sizing Ratio (BMP Area/Drainage Area) | C30: =C14/C29 -> #DIV/0!
A32: INSTRUCTIONS
A33: Use steps 1 through 13 to determine the required area and drain rate for permeable pavement.
A35: Step
A36: 1 | B36: Enter the Water Quality Volume (WQv) for the drainage management area (DMA). The WQv is calculated in Step 14 of the Water Quality Volume and Water Quality Flow Rate Calculator.
A37: 2 | B37: Enter the square footage of the DMA draining to the Permeable Pavement (PP). The DMA includes the area planned for PP. Only impervious surfaces should drain to PP.
A38: 3 | B38: Select the type of PP system: permeable pavers, pervious concrete, or porous asphalt.
A39: 4 | B39: The allowable PP area as a percent of the total drainage area is given here. To reduce pollutant loadings and extend the expected life of the system, the area of the permeable pavement system must be 40% or more of the total drainage area (i.e., 1 part permeable pavement facility area to 1.5 parts impervious paved drainage area). To allow run-on to permeable pavers, they must have 20% or more of their surface area open. See the PP fact sheet for more information regarding design requirements.
A40: 5 | B40: The minimum PP area required is calculated here.
A41: 6 | B41: Enter the infiltration rate of the underlying soils. This should be determined by geotechnical testing or, for conceptual studies, soil infiltration maps. If the PP is going to be underdrained and lined to prevent infiltration, then use 0. A default safety factor of two will be applied to the infiltration rate to account for soils compaction and clogging, as well as the inherent uncertainty in rate measurement.
A42: 7 | B42: The need for underdrains is determined based on the infiltration rate. If other constraints require underdrains, such as high groundwater or bedrock, set the infiltration rate in Step 6 to 0. See the PP fact sheet for infiltration constraints.
A43: 8 | B43: The default porosity of the media and the fill time have been entered. Adjusting these values is not recommended.
A44: 9 | B44: Enter the depths of the subsurface media layers. Layers include the bedding layer, transition (i.e., base) layer, and storage (i.e., subbase) layer. Recommend using a 2" deep bedding layer and a 3 or 4" deep transition layer. The required depth of the underlying storage layer is calculated in Step 10. See the Permeable Pavement fact sheet for more information on the media layers.
A45: 10 | B45: The required depth of the storage layer is calculated here. The depth is as needed to store the WQv, with a minimum depth of 6".
A46: 11 | B46: If the system is not underdrained, the time to infiltrate the WQv is calculated here.
A47: 12 | B47: For underdrained systems, specify the desired drain time. For the full benefit of pollutant reduction through detention, 48 hours is recommended.
A48: 13 | B48: The average rate at which the underdrain system must drain the media layers is calculated here. During design, outlet controls must be sized accordingly to achieve the desired WQv drain time.
A50: DEFINITIONS
...

Sheet Detention Pond
A1: DETENTION POND CALCULATOR
A2: This calculator sizes volumetrically a detention pond such that it treats the Water Quality Volume (WQv).
A7: CALCULATOR
A8: Detention Pond Calculator - by Water Quality Volume
A9: 1 | B9: Water Quality Volume - WQv | E9: cubic feet
A10: 2 | B10: Forebay Volume Calculator | C10: =C9*0.1 -> 0 | E10: cubic feet
A12: 3 | B12: Dimensions Calculator
A13: 4 | B13: Depth at WQv - d | E13: feet (generally between 2 and 5 feet, recommend 3 feet)
A14: 5 | B14: Pond Length to Width Ratio (L/W) | E14: generally between 2 and 4
A15: 6 | B15: Pond Side Slope | E15: feet/feet (ratio of horizontal to vertical, for example, 3 for 3H:1V)
A16: 7 | B16: Width of Pond Bottom | E16: feet (adjust width until storage volume in Step 10 is greater than WQv)
A17: 8 | B17: Length of Pond Bottom | C17: =C16*C14 -> 0 | E17: feet
A18: 9 | B18: Width of Pond at WQv Depth | C18: =C16+C15*C13*2 -> 0 | E18: feet
B19: Length of Pond at WQv Depth | C19: =C17+C15*C13*2 -> 0 | E19: feet
A20: 10 | B20: Storage Volume | C20: =C13*(C16*C17+C18*C19+SQRT(C16*C17*C18*C19))/3 -> 0 | E20: cubic feet (must be greater than WQv)
A21: 11 | B21: Check of Volume | C21: =IF(C20>C9,"Okay", "Error, increase pond width or depth") -> Error, increase pond width or depth
A23: 12 | B23: Drain time - t | C23: 48 | E23: hours (recommend 48 hours)
B24: Surface Area at Mid Elevation | C24: =(C16+C15*C13)*(C17+C15*C13) -> 0 | E24: square feet
B25: Orifice Area | C25: =(2*C24*(C13)^0.5)/(3600*0.66*C23*(2*32.2)^0.5) -> 0 | E25: square feet
A26: 13 | B26: Approx. Orifice Diameter for Drain Time | C26: =12*(4*C25/PI())^0.5 -> 0 | E26: inches (refine outlet control sizing and configuration during design)
A27: 14 | B27: Flow Rate thru Orifice | C27: =449*0.66*C25*(2*32.2*C13)^0.5 -> 0 | E27: gpm (flow rate when basin is at WQv depth)
B28: Est. Impervious DMA | C28: =C9/(0.75/12)/0.9 -> 0 | E28: ft2
B29: Sizing Ratio (BMP/DMA) | C29: =C19*C18/C28 -> #DIV/0!
B30: DP + Forebay | C30: =((C19*C18)+C10/1.5)/C28 -> #DIV/0!
A32: INSTRUCTIONS
A33: Follow the steps below to determine the required size of your detention pond.
A35: Step
A36: 1 | B36: Enter the Water Quality Volume (WQv) for the DMA. The WQv is calculated in Step 14 of the Water Quality Volume and Water Quality Flow Rate Calculator.
A37: 2 | B37: The required volume for the forebay is shown here (typically 10 to 25% of the WQv).
A38: 3 | B38: Use the following steps of the Dimensions Calculator to determine the configuration of the detention pond.
A39: 4 | B39: Enter the design water depth of the detention pond (i.e., the water depth when the basin has completely captured the WQv event). Depths are typically between 2 and 5 feet. This depth DOES NOT include freeboard, which is typically 1 foot above the maximum design depth (freeboard should be added in actual design).
A40: 5 | B40: Enter the length to width ratio of the detention pond. A ratio between 2 and 4 is recommended.
A41: 6 | B41: Enter the side slope of the pond. The slope of earthen side walls should be no steeper than 3:1 (i.e., at least 3 feet horizontal for each 1 foot vertical). Enter 0 for vertical hardscaped sidewalls.
A42: 7 | B42: Enter the width of the pond bottom at the invert of the detention pond.
A43: 8 | B43: The length of the pond bottom is calculated here.
A44: 9 | B44: The width and length of the pond at the design water depth (i.e., WQv depth) are calculated here.
A45: 10 | B45: The storage volume in the pond is calculated here. Adjust the basin depth and/or width (entered in Steps 4 and 7, respectively) until the volume is greater than or equal to the WQv entered in Step 1.
A46: 11 | B46: This step checks that the storage volume is greater than the WQv entered in Step1. If the volume is less than the WQv, increase the pond width or depth.
A47: 12 | B47: The recommended design drain time for the basin is 48 hours.
... A49: 14 | B49: The estimated flow rate through the orifice when the water level is at the WQv depth is calculated here.
...

Sheet Detention Vault
A1: DETENTION VAULT CALCULATOR
A2: These calculators size a detention vault to treat the Water Quality Volume (WQv), or calculate the volume of water treated given user entered available dimensions.
A8: CALCULATOR
A9: Detention Vault Calculator - by Water Quality Volume
A10: 1 | B10: Water Quality Volume - WQv | E10: cubic feet
A11: 2 | B11: Available Live Storage Depth | E11: feet (typically between 3 and 7 ft)
A12: 3 | B12: Length to Width Ratio (L/W) | E12: typically between 2 and 4
A14: 4 | B14: Length | C14: =C15*C12 -> #DIV/0! | E14: feet
B15: Width | C15: =(C10/C11/C12)^0.5 -> #DIV/0! | E15: feet
A17: 5 | B17: Drain Time | C17: 48 | E17: hrs (recommend 48 hrs)
A18: 6 | B18: Ave. Discharge Rate for Drain Time | C18: =C10/C17/3600*449 -> 0 | E18: gpm
B19: Estimated Imp. Drainage Area | C19: =C10/(0.75/12)/0.9 -> 0 | E19: ft2
B20: Sizing Ratio (BMP/DMA) | C20: =C14*C15/C19 -> #DIV/0!
A22: Detention Vault Calculator - by Available Area
A23: 7 | B23: Available Base Area | E23: square feet
A24: 8 | B24: Design Live Storage Depth | E24: feet
A25: 9 | B25: Treated Volume | C25: =$C$23*$C$24 -> 0 | E25: cubic feet
A27: INSTRUCTIONS
A28: Use either steps 1 through 6 to determine the required dimensions of the vault. Or use steps 7 through 9 to check what volume of water is treated given the available area for a vault.
A30: Step
A31: To Determine The Required Dimensions for the Vault
A32: 1 | B32: Enter the Water Quality Volume (WQv) for the drainage management area (DMA). The WQv is calculated in Step 14 of the Water Quality Volume and Water Quality Flow Rate Calculator.
A33: 2 | B33: Enter the proposed live storage depth of the vault. This is typically between 3 to 7 feet not including freeboard. This depth also does not include the depth of the permanent wet pool. It is recommended that the wet pool depth be greater than 3 feet.
A34: 3 | B34: Enter the proposed length to width ratio of the vault. A ratio > 2:1 is preferred. A 2:1 ratio should be entered as "2", a 3:1 as "3", etc.
A35: 4 | B35: The length and width of the vault are calculated.
A36: 5 | B36: Enter the drawdown time for the vault (48 hrs is recommended).
A37: 6 | B37: The average discharge rate from the vault to obtain the desired drain time is calculated. During design, outlet controls must be sized accordingly to achieve the desired WQv drain time.
A39: To Determine the Volume of Water Treated by an Available Area
A40: 7 | B40: Enter the available area to install the vault (base area).
A41: 8 | B41: Enter the proposed live storage depth of the vault. Generally 5 feet not including freeboard.
A42: 9 | B42: The volume of water treated by the proposed detention vault is shown here. If this volume is less than the required WQv then additional treatments will likely be required.
A44: DEFINITIONS
B45: Water Quality Volume (WQv) | C45: The runoff volume to be managed by the stormwater BMP such that treatment requirements are met. The WQv is calculated by the Water Quality Volume and Water Quality Flow Rate Calculator.
B46: Live Storage Depth | C46: The depth of water storage in the vault. Does not include freeboard or depth of permanent pool.
B47: Length | C47: The longitudinal length of the vault
B48: Width | C48: The width of the vault
B49: Base Area | C49: The area of the base of the vault
B50: Drain Time (t) | C50: The time for the storage area to drain the water quality volume.

Sheet Wet Ponds_Wetlands
A1: WET POND/WETLAND CALCULATOR
A2: This calculator sizes the components of a wet pond or wetland such that it treats the Water Quality Volume (WQv).
A7: CALCULATOR
A8: Wet Ponds and Wetlands Calculator - by Water Quality Volume
A9: 1 | B9: Water Quality Volume - WQv | E9: cubic feet
A11: 2 | B11: Forebay volume calculator (min size) | C11: =C14*0.1 -> 0 | E11: cubic feet
A12: 3 | B12: Wet Pond or Wetland
A13: 4 | B13: Permanent pool volume calculator | C13: =IF(C12="Wet Pond", $C$9*2, C9) -> 0 | E13: cubic feet
A14: 5 | B14: Live storage volume calculator | C14: =$C$9 -> 0 | E14: cubic feet
A16: 6 | B16: Dimensions Calculator
A17: 7 | B17: Permanent Pool Depth | E17: feet (typically 1.5 to 2 feet average depth for wetlands, 4 to 6 feet for wet pond)
A18: 8 | B18: Live Storage Volume Depth | E18: feet (typically 1 to 2 feet for wetlands, 1 to 3 feet for wet pond)
A19: 9 | B19: Total Depth at WQv - d | C19: =C18+C17 -> 0 | E19: feet
A20: 10 | B20: Basin Length to Width Ratio (L/W) | E20: generally between 2 and 4
A21: 11 | B21: Basin Side Slope | E21: feet/feet (ratio of horizontal to vertical, for example, 3 for 3H:1V)
A22: 12 | B22: Width of Basin Bottom | E22: feet
A23: 13 | B23: Length of Basin Bottom | C23: =C22*C20 -> 0 | E23: feet
A24: 14 | B24: Width of Basin at Permanent Pool Depth | C24: =C22+C21*C17*2 -> 0 | E24: feet
B25: Length of Basin at Permanent Pool Depth | C25: =C23+C21*C17*2 -> 0 | E25: feet
