Workbook

Sheet TABLE
A1: #1 Access | B1: 7 Year MSJC Data | P1: Service Area | R1: Gap vs.
B2: AY07-08 | D2: AY08-09 | F2: AY09-10 | H2: AY10-11 | J2: AY11-12 | L2: AY12-13 | N2: AY13-14 | P2: 2010 Census | R2: Recent AY
A3: Gender | B3: # | C3: % | D3: # | E3: % | F3: # | G3: % | H3: # | I3: % | J3: # | K3: % | L3: # | M3: % | N3: # | O3: % | P3: # | Q3: % | R3: %
A4: Female | B4: 12909 | C4: 0.60614171 | D4: 14479 | E4: 0.59318284 | F4: 13953 | G4: 0.57975651 | H4: 12000 | I4: 0.57110223 | J4: 11055 | K4: 0.56593632 | L4: 10248 | M4: 0.56958648 | N4: 10301 | O4: 0.5656782 | P4: 425726 | Q4: 0.50871709 | R4: 0.057219228
A5: Male | B5: 8196 | C5: 0.38484294 | D5: 9592 | E5: 0.39296981 | F5: 9853 | G5: 0.40939876 | H5: 8784 | I5: 0.41804683 | J5: 8299 | K5: 0.42484898 | L5: 7605 | M5: 0.42268786 | N5: 7787 | O5: 0.42 | P5: 411136 | Q5: 0.49128291 | R5: -0.06643393
A6: Unknown | B6: 192 | C6: 0.0090153543 | D6: 338 | E6: 0.013847351 | F6: 261 | G6: 0.010844725 | H6: 228 | I6: 0.010850942 | J6: 180 | K6: 0.0092147026 | L6: 139 | M6: 0.0077256558 | N6: 122 | O6: 0.0066996156 | P6: 0 | Q6: 0 | R6: 0.0092147026
A7: Total | B7: 21297 | D7: 24409 | F7: 24067 | H7: 21012 | J7: 19534 | L7: 17992 | N7: 18210 | P7: 836862
A8: click here for graph
B10: 7 Year MSJC Data | P10: Service Area | R10: Gap vs.
B11: AY07-08 | D11: AY08-09 | F11: AY09-10 | H11: AY10-11 | J11: AY11-12 | L11: AY12-13 | N11: AY13-14 | P11: 2010 Census | R11: Recent AY
A12: Ethnicity | B12: # | C12: % | D12: # | E12: % | F12: # | G12: % | H12: # | I12: % | J12: # | K12: % | L12: # | M12: % | N12: # | O12: % | P12: # | Q12: % | R12: %
A13: White | B13: 9963 | C13: 0.46781237 | D13: 10935 | E13: 0.4479905 | F13: 10427 | G13: 0.43324885 | H13: 8877 | I13: 0.42247287 | J13: 7806 | K13: 0.39961093 | L13: 6734 | M13: 0.37427746 | N13: 6413 | O13: 0.35216914 | P13: 398271 | Q13: 0.47591001 | R13: -0.076299072
A14: Hispanic | B14: 6040 | C14: 0.28360802 | D14: 7149 | E14: 0.29288377 | F14: 7520 | G14: 0.31246105 | H14: 7022 | I14: 0.33418999 | J14: 7295 | K14: 0.37345142 | L14: 7334 | M14: 0.40762561 | N14: 7891 | O14: 0.43333333 | P14: 318674 | Q14: 0.38079636 | R14: -0.0073449379
A15: African American | B15: 1547 | C15: 0.072639339 | D15: 1956 | E15: 0.080134377 | F15: 1913 | G15: 0.079486434 | H15: 1641 | I15: 0.07809823 | J15: 1507 | K15: 0.077147538 | L15: 1389 | M15: 0.077200978 | N15: 1490 | O15: 0.081823174 | P15: 43085 | Q15: 0.051483996 | R15: 0.025663541
A16: Asian | B16: 609 | C16: 0.028595577 | D16: 718 | E16: 0.02941538 | F16: 635 | G16: 0.026384676 | H16: 583 | I16: 0.02774605 | J16: 478 | K16: 0.024470155 | L16: 420 | M16: 0.023343708 | N16: 389 | O16: 0.021361889 | P16: 21251 | Q16: 0.025393673 | R16: -0.00092351843
A17: Native American | B17: 254 | C17: 0.011926562 | D17: 294 | E17: 0.012044738 | F17: 250 | G17: 0.010387668 | H17: 182 | I17: 0.0086617171 | J17: 141 | K17: 0.0072181837 | L17: 98 | M17: 0.0054468653 | N17: 89 | O17: 0.0048874245 | P17: 6071 | Q17: 0.0072544816 | R17: -3.6297943e-05
A18: Filipino | B18: 813 | C18: 0.038174391 | D18: 840 | E18: 0.034413536 | F18: 816 | G18: 0.033905348 | H18: 671 | I18: 0.031934133 | J18: 599 | K18: 0.030664482 | L18: 561 | M18: 0.031180525 | N18: 523 | O18: 0.028720483 | P18: 23365 | Q18: 0.027919776 | R18: 0.0027447059
A19: Pacific Islander | B19: 151 | C19: 0.0070902005 | D19: 183 | E19: 0.0074972346 | F19: 159 | G19: 0.0066065567 | H19: 124 | I19: 0.0059013897 | J19: 90 | K19: 0.0046073513 | L19: 77 | M19: 0.0042796799 | N19: 71 | O19: 0.0038989566 | P19: 2305 | Q19: 0.002754337 | R19: 0.0018530142
A20: Multi-Race | B20: 330 | C20: 0.01549514 | D20: 399 | E20: 0.01634643 | F20: 657 | G20: 0.027298791 | H20: 833 | I20: 0.039644013 | J20: 908 | K20: 0.046483055 | L20: 945 | M20: 0.052523344 | N20: 1069 | O20: 0.058704009 | P20: 22553 | Q20: 0.026949485 | R20: 0.01953357
A21: Unknown | B21: 1590 | C21: 0.074658403 | D21: 1935 | E21: 0.079274038 | F21: 1690 | G21: 0.070220634 | H21: 1079 | I21: 0.051351609 | J21: 710 | K21: 0.036346882 | L21: 434 | M21: 0.024121832 | N21: 275 | O21: 0.015101593 | P21: 1287 | Q21: 0.001537888 | R21: 0.034808994
A22: click here for graph
B24: 7 Year MSJC Data | P24: Service Area | R24: Gap vs.
B25: AY07-08 | D25: AY08-09 | F25: AY09-10 | H25: AY10-11 | J25: AY11-12 | L25: AY12-13 | N25: AY13-14 | P25: 2010 Census | R25: Recent AY
A26: Age | B26: # | C26: % | D26: # | E26: % | F26: # | G26: % | H26: # | I26: % | J26: # | K26: % | L26: # | M26: % | N26: # | O26: % | P26: # | Q26: % | R26: %
A27: <18 | B27: 733 | C27: 0.034417993 | D27: 1026 | E27: 0.042033676 | F27: 743 | G27: 0.030872149 | H27: 336 | I27: 0.015990862 | J27: 196 | K27: 0.010033787 | L27: 555 | M27: 0.02869255 | N27: 477 | O27: 0.026194399 | P27: 245217 | Q27: 0.29301964 | R27: -0.28298585
A28: 18 & 19 | B28: 4893 | C28: 0.22975067 | D28: 5828 | E28: 0.23876439 | F28: 5660 | G28: 0.2351768 | H28: 4488 | I28: 0.21359223 | J28: 4057 | K28: 0.20768916 | L28: 4732 | M28: 0.2446363 | N28: 4686 | O28: 0.25733114 | P28: 25706 | Q28: 0.030717131 | R28: 0.17697203
A29: 20 to 24 | B29: 6750 | C29: 0.31694605 | D29: 7632 | E29: 0.31267156 | F29: 7750 | G29: 0.3220177 | H29: 7563 | I29: 0.35993718 | J29: 7524 | K29: 0.38517457 | L29: 7164 | M29: 0.37036654 | N29: 7286 | O29: 0.40010983 | P29: 52893 | Q29: 0.063203969 | R29: 0.3219706
A30: 25 to 29 | B30: 2617 | C30: 0.12288116 | D30: 2960 | E30: 0.12126675 | F30: 3092 | G30: 0.12847467 | H30: 2847 | I30: 0.135494 | J30: 2625 | K30: 0.13438108 | L30: 2467 | M30: 0.12753968 | N30: 2563 | O30: 0.14074684 | P30: 52166 | Q30: 0.062335248 | R30: 0.072045832
A31: 30 to 34 | B31: 1668 | C31: 0.07832089 | D31: 1886 | E31: 0.077266582 | F31: 1849 | G31: 0.076827191 | H31: 1632 | I31: 0.077669903 | J31: 1536 | K31: 0.078632129 | L31: 1385 | M31: 0.07160213 | N31: 1428 | O31: 0.078418451 | P31: 52145 | Q31: 0.062310154 | R31: 0.016321975
A32: 35 to 39 | B32: 1354 | C32: 0.06357703 | D32: 1507 | E32: 0.061739522 | F32: 1438 | G32: 0.059749865 | H32: 1186 | I32: 0.056443937 | J32: 1074 | K32: 0.054981059 | L32: 894 | M32: 0.04621827 | N32: 924 | O32: 0.050741351 | P32: 55384 | Q32: 0.066180565 | R32: -0.011199506
A33: 40 to 49 | B33: 2065 | C33: 0.096962013 | D33: 2241 | E33: 0.091810398 | F33: 2282 | G33: 0.094818631 | H33: 1900 | I33: 0.090424519 | J33: 1573 | K33: 0.080526262 | L33: 1336 | M33: 0.069068914 | N33: 1303 | O33: 0.071554091 | P33: 116401 | Q33: 0.13909223 | R33: -0.058565966
A34: 50 + | B34: 1213 | C34: 0.056956379 | D34: 1329 | E34: 0.05444713 | F34: 1250 | G34: 0.051938339 | H34: 1058 | I34: 0.05035218 | J34: 947 | K34: 0.048479574 | L34: 809 | M34: 0.041823916 | N34: 831 | O34: 0.045634267 | P34: 236950 | Q34: 0.28314107 | R34: -0.23466149
A35: Unknown | B35: 4 | C35: 0.00018781988 | D35: 0 | E35: 0 | F35: 3 | G35: 0.00012465201 | H35: 2 | I35: 9.5183705e-05 | J35: 2 | K35: 0.00010238558 | L35: 1 | M35: 5.1698289e-05 | N35: 1 | O35: 5.4914882e-05 | P35: 0 | Q35: 0 | R35: 0.00010238558
A36: Average Age | B36: 27.085805 | D36: 26.740922 | F36: 26.808412 | H36: 26.616662 | J36: 26.219426 | L36: 25.3 | N36: 24.9
A37: Median Age | B37: 22 | D37: 22 | F37: 22 | H37: 22 | J37: 22 | L37: 25 | N37: 25
A38: click here for graph
B40: 7 Year MSJC Data | P40: Riverside County | R40: Gap vs.
B41: AY07-08 | D41: AY08-09 | F41: AY09-10 | H41: AY10-11 | J41: AY11-12 | L41: AY12-13 | N41: AY13-14 | P41: 2010 ACS* | R41: Recent AY
A42: DSPS | B42: # | C42: % | D42: # | E42: % | F42: # | G42: % | H42: # | I42: % | J42: # | K42: % | L42: # | M42: % | N42: # | O42: % | P42: # | Q42: % | R42: #
A43: Disabilities | B43: 649 | C43: 0.030473776 | D43: 963 | E43: 0.039452661 | F43: 1178 | G43: 0.04894669 | H43: 1155 | I43: 0.054968589 | J43: 1132 | K43: 0.057950241 | L43: 1129 | M43: 0.062750111 | N43: 808 | O43: 0.044371225 | P43: 105412 | Q43: 0.081095074 | R43: -0.023144834
...

Sheet gender
A1: AY07-08 | B1: AY08-09 | C1: AY09-10 | D1: AY10-11 | E1: AY11-12
A2: 2007 | B2: 2008 | C2: 2009 | D2: 2010 | E2: 2011
A3: =VLOOKUP($F3,'[3]gender heads'!$A:$G,HLOOKUP(A$2,'[3]gender heads'!$1:$2,2,FALSE),FALSE) -> 12909 | B3: =VLOOKUP($F3,'[3]gender heads'!$A:$G,HLOOKUP(B$2,'[3]gender heads'!$1:$2,2,FALSE),FALSE) -> 14479 | C3: =VLOOKUP($F3,'[3]gender heads'!$A:$G,HLOOKUP(C$2,'[3]gender heads'!$1:$2,2,FALSE),FALSE) -> 13953 | D3: =VLOOKUP($F3,'[3]gender heads'!$A:$G,HLOOKUP(D$2,'[3]gender heads'!$1:$2,2,FALSE),FALSE) -> 12000 | E3: =VLOOKUP($F3,'[3]gender heads'!$A:$G,HLOOKUP(E$2,'[3]gender heads'!$1:$2,2,FALSE),FALSE) -> 11055 | F3: F
A4: =VLOOKUP($F4,'[3]gender heads'!$A:$G,HLOOKUP(A$2,'[3]gender heads'!$1:$2,2,FALSE),FALSE) -> 8196 | B4: =VLOOKUP($F4,'[3]gender heads'!$A:$G,HLOOKUP(B$2,'[3]gender heads'!$1:$2,2,FALSE),FALSE) -> 9592 | C4: =VLOOKUP($F4,'[3]gender heads'!$A:$G,HLOOKUP(C$2,'[3]gender heads'!$1:$2,2,FALSE),FALSE) -> 9853 | D4: =VLOOKUP($F4,'[3]gender heads'!$A:$G,HLOOKUP(D$2,'[3]gender heads'!$1:$2,2,FALSE),FALSE) -> 8784 | E4: =VLOOKUP($F4,'[3]gender heads'!$A:$G,HLOOKUP(E$2,'[3]gender heads'!$1:$2,2,FALSE),FALSE) -> 8299 | F4: M
A5: =VLOOKUP($F5,'[3]gender heads'!$A:$G,HLOOKUP(A$2,'[3]gender heads'!$1:$2,2,FALSE),FALSE) -> 192 | B5: =VLOOKUP($F5,'[3]gender heads'!$A:$G,HLOOKUP(B$2,'[3]gender heads'!$1:$2,2,FALSE),FALSE) -> 338 | C5: =VLOOKUP($F5,'[3]gender heads'!$A:$G,HLOOKUP(C$2,'[3]gender heads'!$1:$2,2,FALSE),FALSE) -> 261 | D5: =VLOOKUP($F5,'[3]gender heads'!$A:$G,HLOOKUP(D$2,'[3]gender heads'!$1:$2,2,FALSE),FALSE) -> 228 | E5: =VLOOKUP($F5,'[3]gender heads'!$A:$G,HLOOKUP(E$2,'[3]gender heads'!$1:$2,2,FALSE),FALSE) -> 180 | F5: (blank)

Sheet ethnic
A1: AY07-08 | B1: AY08-09 | C1: AY09-10 | D1: AY10-11 | E1: AY11-12
A2: 2007 | B2: 2008 | C2: 2009 | D2: 2010 | E2: 2011
A3: =VLOOKUP($F3,'[4]Primary Races'!$A:$G,HLOOKUP(A$2,'[4]Primary Races'!$1:$2,2,FALSE),FALSE) -> 9963 | B3: =VLOOKUP($F3,'[4]Primary Races'!$A:$G,HLOOKUP(B$2,'[4]Primary Races'!$1:$2,2,FALSE),FALSE) -> 10935 | C3: =VLOOKUP($F3,'[4]Primary Races'!$A:$G,HLOOKUP(C$2,'[4]Primary Races'!$1:$2,2,FALSE),FALSE) -> 10427 | D3: =VLOOKUP($F3,'[4]Primary Races'!$A:$G,HLOOKUP(D$2,'[4]Primary Races'!$1:$2,2,FALSE),FALSE) -> 8877 | E3: =VLOOKUP($F3,'[4]Primary Races'!$A:$G,HLOOKUP(E$2,'[4]Primary Races'!$1:$2,2,FALSE),FALSE) -> 7806 | F3: =MID(G3,1,1) -> W | G3: White | I3: White
A4: =VLOOKUP($G4,'[4]hispanic total'!$A:$F,HLOOKUP(A$2,'[4]hispanic total'!$1:$2,2,FALSE),FALSE) -> 6040 | B4: =VLOOKUP($G4,'[4]hispanic total'!$A:$F,HLOOKUP(B$2,'[4]hispanic total'!$1:$2,2,FALSE),FALSE) -> 7149 | C4: =VLOOKUP($G4,'[4]hispanic total'!$A:$F,HLOOKUP(C$2,'[4]hispanic total'!$1:$2,2,FALSE),FALSE) -> 7520 | D4: =VLOOKUP($G4,'[4]hispanic total'!$A:$F,HLOOKUP(D$2,'[4]hispanic total'!$1:$2,2,FALSE),FALSE) -> 7022 | E4: =VLOOKUP($G4,'[4]hispanic total'!$A:$F,HLOOKUP(E$2,'[4]hispanic total'!$1:$2,2,FALSE),FALSE) -> 7295 | F4: =MID(G4,1,1) -> H | G4: Hispanic | I4: Hispanic
A5: =VLOOKUP($F5,'[4]Primary Races'!$A:$G,HLOOKUP(A$2,'[4]Primary Races'!$1:$2,2,FALSE),FALSE) -> 1547 | B5: =VLOOKUP($F5,'[4]Primary Races'!$A:$G,HLOOKUP(B$2,'[4]Primary Races'!$1:$2,2,FALSE),FALSE) -> 1956 | C5: =VLOOKUP($F5,'[4]Primary Races'!$A:$G,HLOOKUP(C$2,'[4]Primary Races'!$1:$2,2,FALSE),FALSE) -> 1913 | D5: =VLOOKUP($F5,'[4]Primary Races'!$A:$G,HLOOKUP(D$2,'[4]Primary Races'!$1:$2,2,FALSE),FALSE) -> 1641 | E5: =VLOOKUP($F5,'[4]Primary Races'!$A:$G,HLOOKUP(E$2,'[4]Primary Races'!$1:$2,2,FALSE),FALSE) -> 1507 | F5: B | G5: African American | I5: African American
A6: =VLOOKUP($F6,'[4]Primary Races'!$A:$G,HLOOKUP(A$2,'[4]Primary Races'!$1:$2,2,FALSE),FALSE) -> 609 | B6: =VLOOKUP($F6,'[4]Primary Races'!$A:$G,HLOOKUP(B$2,'[4]Primary Races'!$1:$2,2,FALSE),FALSE) -> 718 | C6: =VLOOKUP($F6,'[4]Primary Races'!$A:$G,HLOOKUP(C$2,'[4]Primary Races'!$1:$2,2,FALSE),FALSE) -> 635 | D6: =VLOOKUP($F6,'[4]Primary Races'!$A:$G,HLOOKUP(D$2,'[4]Primary Races'!$1:$2,2,FALSE),FALSE) -> 583 | E6: =VLOOKUP($F6,'[4]Primary Races'!$A:$G,HLOOKUP(E$2,'[4]Primary Races'!$1:$2,2,FALSE),FALSE) -> 478 | F6: =MID(G6,1,1) -> A | G6: Asian | I6: Asian
A7: =VLOOKUP($F7,'[4]Primary Races'!$A:$G,HLOOKUP(A$2,'[4]Primary Races'!$1:$2,2,FALSE),FALSE) -> 254 | B7: =VLOOKUP($F7,'[4]Primary Races'!$A:$G,HLOOKUP(B$2,'[4]Primary Races'!$1:$2,2,FALSE),FALSE) -> 294 | C7: =VLOOKUP($F7,'[4]Primary Races'!$A:$G,HLOOKUP(C$2,'[4]Primary Races'!$1:$2,2,FALSE),FALSE) -> 250 | D7: =VLOOKUP($F7,'[4]Primary Races'!$A:$G,HLOOKUP(D$2,'[4]Primary Races'!$1:$2,2,FALSE),FALSE) -> 182 | E7: =VLOOKUP($F7,'[4]Primary Races'!$A:$G,HLOOKUP(E$2,'[4]Primary Races'!$1:$2,2,FALSE),FALSE) -> 141 | F7: =MID(G7,1,1) -> N | G7: Native American | I7: Native American
A8: =VLOOKUP($F8,'[4]Primary Races'!$A:$G,HLOOKUP(A$2,'[4]Primary Races'!$1:$2,2,FALSE),FALSE) -> 813 | B8: =VLOOKUP($F8,'[4]Primary Races'!$A:$G,HLOOKUP(B$2,'[4]Primary Races'!$1:$2,2,FALSE),FALSE) -> 840 | C8: =VLOOKUP($F8,'[4]Primary Races'!$A:$G,HLOOKUP(C$2,'[4]Primary Races'!$1:$2,2,FALSE),FALSE) -> 816 | D8: =VLOOKUP($F8,'[4]Primary Races'!$A:$G,HLOOKUP(D$2,'[4]Primary Races'!$1:$2,2,FALSE),FALSE) -> 671 | E8: =VLOOKUP($F8,'[4]Primary Races'!$A:$G,HLOOKUP(E$2,'[4]Primary Races'!$1:$2,2,FALSE),FALSE) -> 599 | F8: =MID(G8,1,1) -> F | G8: Filipino | I8: Filipino
A9: =VLOOKUP($F9,'[4]Primary Races'!$A:$G,HLOOKUP(A$2,'[4]Primary Races'!$1:$2,2,FALSE),FALSE) -> 151 | B9: =VLOOKUP($F9,'[4]Primary Races'!$A:$G,HLOOKUP(B$2,'[4]Primary Races'!$1:$2,2,FALSE),FALSE) -> 183 | C9: =VLOOKUP($F9,'[4]Primary Races'!$A:$G,HLOOKUP(C$2,'[4]Primary Races'!$1:$2,2,FALSE),FALSE) -> 159 | D9: =VLOOKUP($F9,'[4]Primary Races'!$A:$G,HLOOKUP(D$2,'[4]Primary Races'!$1:$2,2,FALSE),FALSE) -> 124 | E9: =VLOOKUP($F9,'[4]Primary Races'!$A:$G,HLOOKUP(E$2,'[4]Primary Races'!$1:$2,2,FALSE),FALSE) -> 90 | F9: =MID(G9,1,1) -> P | G9: Pacific Islander | I9: Pacific Islander
A10: =VLOOKUP($F10,'[4]multi race'!$A:$G,HLOOKUP(A$2,'[4]multi race'!$1:$2,2,FALSE),FALSE) -> 330 | B10: =VLOOKUP($F10,'[4]multi race'!$A:$G,HLOOKUP(B$2,'[4]multi race'!$1:$2,2,FALSE),FALSE) -> 399 | C10: =VLOOKUP($F10,'[4]multi race'!$A:$G,HLOOKUP(C$2,'[4]multi race'!$1:$2,2,FALSE),FALSE) -> 657 | D10: =VLOOKUP($F10,'[4]multi race'!$A:$G,HLOOKUP(D$2,'[4]multi race'!$1:$2,2,FALSE),FALSE) -> 833 | E10: =VLOOKUP($F10,'[4]multi race'!$A:$G,HLOOKUP(E$2,'[4]multi race'!$1:$2,2,FALSE),FALSE) -> 908 | F10: =MID(G10,1,1) -> M | G10: Multi-Race | I10: Multi-Race
A11: =VLOOKUP($F11,[4]unknown!$A:$G,HLOOKUP(A$2,[4]unknown!$1:$2,2,FALSE),FALSE) -> 1590 | B11: =VLOOKUP($F11,[4]unknown!$A:$G,HLOOKUP(B$2,[4]unknown!$1:$2,2,FALSE),FALSE) -> 1935 | C11: =VLOOKUP($F11,[4]unknown!$A:$G,HLOOKUP(C$2,[4]unknown!$1:$2,2,FALSE),FALSE) -> 1690 | D11: =VLOOKUP($F11,[4]unknown!$A:$G,HLOOKUP(D$2,[4]unknown!$1:$2,2,FALSE),FALSE) -> 1079 | E11: =VLOOKUP($F11,[4]unknown!$A:$G,HLOOKUP(E$2,[4]unknown!$1:$2,2,FALSE),FALSE) -> 710 | F11: =MID(G11,1,1) -> U | G11: Unknown | I11: Unknown

Sheet Sheet2
B1: 2007 | D1: 2008 | F1: 2009 | H1: 2010 | J1: 2011

Sheet graph base
A1: #1 Access | B1: 5 Year MSJC Data | L1: Service Area
B2: AY07-08 | D2: AY08-09 | F2: AY09-10 | H2: AY10-11 | J2: AY11-12 | L2: 2010 Census
A3: Gender | B3: # | C3: % | D3: # | E3: % | F3: # | G3: % | H3: # | I3: % | J3: # | K3: % | L3: # | M3: %
A4: =A3 -> Gender | B4: =CONCATENATE(B2,B3) -> AY07-08# | C4: =CONCATENATE(B2,C3) -> AY07-08% | D4: =CONCATENATE(D2,D3) -> AY08-09# | E4: =CONCATENATE(D2,E3) -> AY08-09% | F4: =CONCATENATE(F2,F3) -> AY09-10# | G4: =CONCATENATE(F2,G3) -> AY09-10% | H4: =CONCATENATE(H2,H3) -> AY10-11# | I4: =CONCATENATE(H2,I3) -> AY10-11% | J4: =CONCATENATE(J2,J3) -> AY11-12# | K4: =CONCATENATE(J2,K3) -> AY11-12% | L4: =CONCATENATE(L2,L3) -> 2010 Census# | M4: =CONCATENATE(L2,M3) -> 2010 Census%
A5: Female | B5: =gender!A3 -> 12909 | C5: =B5/B$8 -> 0.60614171 | D5: =gender!B3 -> 14479 | E5: =D5/D$8 -> 0.59318284 | F5: =gender!C3 -> 13953 | G5: =F5/F$8 -> 0.57975651 | H5: =gender!D3 -> 12000 | I5: =H5/H$8 -> 0.57110223 | J5: =gender!E3 -> 11055 | K5: =J5/J$8 -> 0.56593632 | L5: 425726 | M5: =L5/L$8 -> 0.50871709
A6: Male | B6: =gender!A4 -> 8196 | C6: =B6/B$8 -> 0.38484294 | D6: =gender!B4 -> 9592 | E6: =D6/D$8 -> 0.39296981 | F6: =gender!C4 -> 9853 | G6: =F6/F$8 -> 0.40939876 | H6: =gender!D4 -> 8784 | I6: =H6/H$8 -> 0.41804683 | J6: =gender!E4 -> 8299 | K6: =J6/J$8 -> 0.42484898 | L6: 411136 | M6: =L6/L$8 -> 0.49128291
A7: Unknown | B7: =gender!A5 -> 192 | C7: =B7/B$8 -> 0.0090153543 | D7: =gender!B5 -> 338 | E7: =D7/D$8 -> 0.013847351 | F7: =gender!C5 -> 261 | G7: =F7/F$8 -> 0.010844725 | H7: =gender!D5 -> 228 | I7: =H7/H$8 -> 0.010850942 | J7: =gender!E5 -> 180 | K7: =J7/J$8 -> 0.0092147026 | L7: 0 | M7: =L7/L$8 -> 0
A8: Total | B8: =SUM(B5:B7) -> 21297 | D8: =SUM(D5:D7) -> 24409 | F8: =SUM(F5:F7) -> 24067 | H8: =SUM(H5:H7) -> 21012 | J8: =SUM(J5:J7) -> 19534 | L8: =SUM(L5:L7) -> 836862
B10: 5 Year MSJC Data | L10: Service Area
B11: AY07-08 | D11: AY08-09 | F11: AY09-10 | H11: AY10-11 | J11: AY11-12 | L11: 2010 Census
A12: Ethnicity | B12: # | C12: % | D12: # | E12: % | F12: # | G12: % | H12: # | I12: % | J12: # | K12: % | L12: # | M12: %
A13: =A12 -> Ethnicity | B13: =B4 -> AY07-08# | C13: =C4 -> AY07-08% | D13: =D4 -> AY08-09# | E13: =E4 -> AY08-09% | F13: =F4 -> AY09-10# | G13: =G4 -> AY09-10% | H13: =H4 -> AY10-11# | I13: =I4 -> AY10-11% | ... M13: =M4 -> 2010 Census%
A14: White | B14: =ethnic!A3 -> 9963 | C14: =B14/(SUM(B$14:B$22)) -> 0.46781237 | D14: =ethnic!B3 -> 10935 | E14: =D14/(SUM(D$14:D$22)) -> 0.4479905 | F14: =ethnic!C3 -> 10427 | G14: =F14/(SUM(F$14:F$22)) -> 0.43324885 | H14: =ethnic!D3 -> 8877 | I14: =H14/(SUM(H$14:H$22)) -> 0.42247287 | J14: =ethnic!E3 -> 7806 | K14: =J14/(SUM(J$14:J$22)) -> 0.39961093 | L14: 398271 | M14: =L14/(SUM(L$14:L$22)) -> 0.47591001
A15: Hispanic | B15: =ethnic!A4 -> 6040 | C15: =B15/(SUM(B$14:B$22)) -> 0.28360802 | D15: =ethnic!B4 -> 7149 | E15: =D15/(SUM(D$14:D$22)) -> 0.29288377 | F15: =ethnic!C4 -> 7520 | G15: =F15/(SUM(F$14:F$22)) -> 0.31246105 | H15: =ethnic!D4 -> 7022 | I15: =H15/(SUM(H$14:H$22)) -> 0.33418999 | J15: =ethnic!E4 -> 7295 | K15: =J15/(SUM(J$14:J$22)) -> 0.37345142 | L15: 318674 | M15: =L15/(SUM(L$14:L$22)) -> 0.38079636
A16: African American | B16: =ethnic!A5 -> 1547 | C16: =B16/(SUM(B$14:B$22)) -> 0.072639339 | D16: =ethnic!B5 -> 1956 | E16: =D16/(SUM(D$14:D$22)) -> 0.080134377 | F16: =ethnic!C5 -> 1913 | G16: =F16/(SUM(F$14:F$22)) -> 0.079486434 | H16: =ethnic!D5 -> 1641 | I16: =H16/(SUM(H$14:H$22)) -> 0.07809823 | J16: =ethnic!E5 -> 1507 | K16: =J16/(SUM(J$14:J$22)) -> 0.077147538 | L16: 43085 | M16: =L16/(SUM(L$14:L$22)) -> 0.051483996
A17: Asian | B17: =ethnic!A6 -> 609 | C17: =B17/(SUM(B$14:B$22)) -> 0.028595577 | D17: =ethnic!B6 -> 718 | E17: =D17/(SUM(D$14:D$22)) -> 0.02941538 | F17: =ethnic!C6 -> 635 | G17: =F17/(SUM(F$14:F$22)) -> 0.026384676 | H17: =ethnic!D6 -> 583 | I17: =H17/(SUM(H$14:H$22)) -> 0.02774605 | J17: =ethnic!E6 -> 478 | K17: =J17/(SUM(J$14:J$22)) -> 0.024470155 | L17: 21251 | M17: =L17/(SUM(L$14:L$22)) -> 0.025393673
A18: Native American | B18: =ethnic!A7 -> 254 | C18: =B18/(SUM(B$14:B$22)) -> 0.011926562 | D18: =ethnic!B7 -> 294 | E18: =D18/(SUM(D$14:D$22)) -> 0.012044738 | F18: =ethnic!C7 -> 250 | G18: =F18/(SUM(F$14:F$22)) -> 0.010387668 | H18: =ethnic!D7 -> 182 | I18: =H18/(SUM(H$14:H$22)) -> 0.0086617171 | J18: =ethnic!E7 -> 141 | K18: =J18/(SUM(J$14:J$22)) -> 0.0072181837 | L18: 6071 | M18: =L18/(SUM(L$14:L$22)) -> 0.0072544816
A19: Filipino | B19: =ethnic!A8 -> 813 | C19: =B19/(SUM(B$14:B$22)) -> 0.038174391 | D19: =ethnic!B8 -> 840 | E19: =D19/(SUM(D$14:D$22)) -> 0.034413536 | F19: =ethnic!C8 -> 816 | G19: =F19/(SUM(F$14:F$22)) -> 0.033905348 | H19: =ethnic!D8 -> 671 | I19: =H19/(SUM(H$14:H$22)) -> 0.031934133 | J19: =ethnic!E8 -> 599 | K19: =J19/(SUM(J$14:J$22)) -> 0.030664482 | L19: 23365 | M19: =L19/(SUM(L$14:L$22)) -> 0.027919776
A20: Pacific Islander | B20: =ethnic!A9 -> 151 | C20: =B20/(SUM(B$14:B$22)) -> 0.0070902005 | D20: =ethnic!B9 -> 183 | E20: =D20/(SUM(D$14:D$22)) -> 0.0074972346 | F20: =ethnic!C9 -> 159 | G20: =F20/(SUM(F$14:F$22)) -> 0.0066065567 | H20: =ethnic!D9 -> 124 | I20: =H20/(SUM(H$14:H$22)) -> 0.0059013897 | J20: =ethnic!E9 -> 90 | K20: =J20/(SUM(J$14:J$22)) -> 0.0046073513 | L20: 2305 | M20: =L20/(SUM(L$14:L$22)) -> 0.002754337
A21: Multi-Race | B21: =ethnic!A10 -> 330 | C21: =B21/(SUM(B$14:B$22)) -> 0.01549514 | D21: =ethnic!B10 -> 399 | E21: =D21/(SUM(D$14:D$22)) -> 0.01634643 | F21: =ethnic!C10 -> 657 | G21: =F21/(SUM(F$14:F$22)) -> 0.027298791 | H21: =ethnic!D10 -> 833 | I21: =H21/(SUM(H$14:H$22)) -> 0.039644013 | J21: =ethnic!E10 -> 908 | K21: =J21/(SUM(J$14:J$22)) -> 0.046483055 | L21: 22553 | M21: =L21/(SUM(L$14:L$22)) -> 0.026949485
A22: Unknown | B22: =ethnic!A11 -> 1590 | C22: =B22/(SUM(B$14:B$22)) -> 0.074658403 | D22: =ethnic!B11 -> 1935 | E22: =D22/(SUM(D$14:D$22)) -> 0.079274038 | F22: =ethnic!C11 -> 1690 | G22: =F22/(SUM(F$14:F$22)) -> 0.070220634 | H22: =ethnic!D11 -> 1079 | I22: =H22/(SUM(H$14:H$22)) -> 0.051351609 | J22: =ethnic!E11 -> 710 | K22: =J22/(SUM(J$14:J$22)) -> 0.036346882 | L22: 1287 | M22: =L22/(SUM(L$14:L$22)) -> 0.001537888
B24: 5 Year MSJC Data | L24: Service Area
B25: AY07-08 | D25: AY08-09 | F25: AY09-10 | H25: AY10-11 | J25: AY11-12 | L25: 2010 Census
A26: Age | B26: # | C26: % | D26: # | E26: % | F26: # | G26: % | H26: # | I26: % | J26: # | K26: % | L26: # | M26: %
A27: =A26 -> Age | B27: =B13 -> AY07-08# | C27: =C13 -> AY07-08% | D27: =D13 -> AY08-09# | E27: =E13 -> AY08-09% | F27: =F13 -> AY09-10# | G27: =G13 -> AY09-10% | H27: =H13 -> AY10-11# | I27: =I13 -> AY10-11% | ... M27: =M13 -> 2010 Census%
A28: <18 | B28: =VLOOKUP($A28,'[1]age headcounts'!$A:$G,HLOOKUP(Sheet2!B$1,'[1]age headcounts'!$1:$2,2,FALSE),FALSE) -> 733 | C28: =B28/(SUM(B$28:B$36)) -> 0.034417993 | D28: =VLOOKUP($A28,'[1]age headcounts'!$A:$G,HLOOKUP(Sheet2!D$1,'[1]age headcounts'!$1:$2,2,FALSE),FALSE) -> 1026 | E28: =D28/(SUM(D$28:D$36)) -> 0.042033676 | F28: =VLOOKUP($A28,'[1]age headcounts'!$A:$G,HLOOKUP(Sheet2!F$1,'[1]age headcounts'!$1:$2,2,FALSE),FALSE) -> 743 | G28: =F28/(SUM(F$28:F$36)) -> 0.030872149 | H28: =VLOOKUP($A28,'[1]age headcounts'!$A:$G,HLOOKUP(Sheet2!H$1,'[1]age headcounts'!$1:$2,2,FALSE),FALSE) -> 336 | I28: =H28/(SUM(H$28:H$36)) -> 0.015990862 | J28: =VLOOKUP($A28,'[1]age headcounts'!$A:$G,HLOOKUP(Sheet2!J$1,'[1]age headcounts'!$1:$2,2,FALSE),FALSE) -> 196 | K28: =J28/(SUM(J$28:J$36)) -> 0.010033787 | L28: 245217 | M28: =L28/SUM(L$28:L$36) -> 0.29301964
A29: 18 & 19 | B29: =VLOOKUP($A29,'[1]age headcounts'!$A:$G,HLOOKUP(Sheet2!B$1,'[1]age headcounts'!$1:$2,2,FALSE),FALSE) -> 4893 | C29: =B29/(SUM(B$28:B$36)) -> 0.22975067 | D29: =VLOOKUP($A29,'[1]age headcounts'!$A:$G,HLOOKUP(Sheet2!D$1,'[1]age headcounts'!$1:$2,2,FALSE),FALSE) -> 5828 | E29: =D29/(SUM(D$28:D$36)) -> 0.23876439 | F29: =VLOOKUP($A29,'[1]age headcounts'!$A:$G,HLOOKUP(Sheet2!F$1,'[1]age headcounts'!$1:$2,2,FALSE),FALSE) -> 5660 | G29: =F29/(SUM(F$28:F$36)) -> 0.2351768 | H29: =VLOOKUP($A29,'[1]age headcounts'!$A:$G,HLOOKUP(Sheet2!H$1,'[1]age headcounts'!$1:$2,2,FALSE),FALSE) -> 4488 | I29: =H29/(SUM(H$28:H$36)) -> 0.21359223 | J29: =VLOOKUP($A29,'[1]age headcounts'!$A:$G,HLOOKUP(Sheet2!J$1,'[1]age headcounts'!$1:$2,2,FALSE),FALSE) -> 4057 | K29: =J29/(SUM(J$28:J$36)) -> 0.20768916 | L29: 25706 | M29: =L29/SUM(L$28:L$36) -> 0.030717131
A30: 20 to 24 | B30: =VLOOKUP($A30,'[1]age headcounts'!$A:$G,HLOOKUP(Sheet2!B$1,'[1]age headcounts'!$1:$2,2,FALSE),FALSE) -> 6750 | C30: =B30/(SUM(B$28:B$36)) -> 0.31694605 | D30: =VLOOKUP($A30,'[1]age headcounts'!$A:$G,HLOOKUP(Sheet2!D$1,'[1]age headcounts'!$1:$2,2,FALSE),FALSE) -> 7632 | E30: =D30/(SUM(D$28:D$36)) -> 0.31267156 | F30: =VLOOKUP($A30,'[1]age headcounts'!$A:$G,HLOOKUP(Sheet2!F$1,'[1]age headcounts'!$1:$2,2,FALSE),FALSE) -> 7750 | G30: =F30/(SUM(F$28:F$36)) -> 0.3220177 | H30: =VLOOKUP($A30,'[1]age headcounts'!$A:$G,HLOOKUP(Sheet2!H$1,'[1]age headcounts'!$1:$2,2,FALSE),FALSE) -> 7563 | I30: =H30/(SUM(H$28:H$36)) -> 0.35993718 | J30: =VLOOKUP($A30,'[1]age headcounts'!$A:$G,HLOOKUP(Sheet2!J$1,'[1]age headcounts'!$1:$2,2,FALSE),FALSE) -> 7524 | K30: =J30/(SUM(J$28:J$36)) -> 0.38517457 | L30: 52893 | M30: =L30/SUM(L$28:L$36) -> 0.063203969
A31: 25 to 29 | B31: =VLOOKUP($A31,'[1]age headcounts'!$A:$G,HLOOKUP(Sheet2!B$1,'[1]age headcounts'!$1:$2,2,FALSE),FALSE) -> 2617 | C31: =B31/(SUM(B$28:B$36)) -> 0.12288116 | D31: =VLOOKUP($A31,'[1]age headcounts'!$A:$G,HLOOKUP(Sheet2!D$1,'[1]age headcounts'!$1:$2,2,FALSE),FALSE) -> 2960 | E31: =D31/(SUM(D$28:D$36)) -> 0.12126675 | F31: =VLOOKUP($A31,'[1]age headcounts'!$A:$G,HLOOKUP(Sheet2!F$1,'[1]age headcounts'!$1:$2,2,FALSE),FALSE) -> 3092 | G31: =F31/(SUM(F$28:F$36)) -> 0.12847467 | H31: =VLOOKUP($A31,'[1]age headcounts'!$A:$G,HLOOKUP(Sheet2!H$1,'[1]age headcounts'!$1:$2,2,FALSE),FALSE) -> 2847 | I31: =H31/(SUM(H$28:H$36)) -> 0.135494 | J31: =VLOOKUP($A31,'[1]age headcounts'!$A:$G,HLOOKUP(Sheet2!J$1,'[1]age headcounts'!$1:$2,2,FALSE),FALSE) -> 2625 | K31: =J31/(SUM(J$28:J$36)) -> 0.13438108 | L31: 52166 | M31: =L31/SUM(L$28:L$36) -> 0.062335248
A32: 30 to 34 | B32: =VLOOKUP($A32,'[1]age headcounts'!$A:$G,HLOOKUP(Sheet2!B$1,'[1]age headcounts'!$1:$2,2,FALSE),FALSE) -> 1668 | C32: =B32/(SUM(B$28:B$36)) -> 0.07832089 | D32: =VLOOKUP($A32,'[1]age headcounts'!$A:$G,HLOOKUP(Sheet2!D$1,'[1]age headcounts'!$1:$2,2,FALSE),FALSE) -> 1886 | E32: =D32/(SUM(D$28:D$36)) -> 0.077266582 | F32: =VLOOKUP($A32,'[1]age headcounts'!$A:$G,HLOOKUP(Sheet2!F$1,'[1]age headcounts'!$1:$2,2,FALSE),FALSE) -> 1849 | G32: =F32/(SUM(F$28:F$36)) -> 0.076827191 | H32: =VLOOKUP($A32,'[1]age headcounts'!$A:$G,HLOOKUP(Sheet2!H$1,'[1]age headcounts'!$1:$2,2,FALSE),FALSE) -> 1632 | I32: =H32/(SUM(H$28:H$36)) -> 0.077669903 | J32: =VLOOKUP($A32,'[1]age headcounts'!$A:$G,HLOOKUP(Sheet2!J$1,'[1]age headcounts'!$1:$2,2,FALSE),FALSE) -> 1536 | K32: =J32/(SUM(J$28:J$36)) -> 0.078632129 | L32: 52145 | M32: =L32/SUM(L$28:L$36) -> 0.062310154
A33: 35 to 39 | B33: =VLOOKUP($A33,'[1]age headcounts'!$A:$G,HLOOKUP(Sheet2!B$1,'[1]age headcounts'!$1:$2,2,FALSE),FALSE) -> 1354 | C33: =B33/(SUM(B$28:B$36)) -> 0.06357703 | D33: =VLOOKUP($A33,'[1]age headcounts'!$A:$G,HLOOKUP(Sheet2!D$1,'[1]age headcounts'!$1:$2,2,FALSE),FALSE) -> 1507 | E33: =D33/(SUM(D$28:D$36)) -> 0.061739522 | F33: =VLOOKUP($A33,'[1]age headcounts'!$A:$G,HLOOKUP(Sheet2!F$1,'[1]age headcounts'!$1:$2,2,FALSE),FALSE) -> 1438 | G33: =F33/(SUM(F$28:F$36)) -> 0.059749865 | H33: =VLOOKUP($A33,'[1]age headcounts'!$A:$G,HLOOKUP(Sheet2!H$1,'[1]age headcounts'!$1:$2,2,FALSE),FALSE) -> 1186 | I33: =H33/(SUM(H$28:H$36)) -> 0.056443937 | J33: =VLOOKUP($A33,'[1]age headcounts'!$A:$G,HLOOKUP(Sheet2!J$1,'[1]age headcounts'!$1:$2,2,FALSE),FALSE) -> 1074 | K33: =J33/(SUM(J$28:J$36)) -> 0.054981059 | L33: 55384 | M33: =L33/SUM(L$28:L$36) -> 0.066180565
A34: 40 to 49 | B34: =VLOOKUP($A34,'[1]age headcounts'!$A:$G,HLOOKUP(Sheet2!B$1,'[1]age headcounts'!$1:$2,2,FALSE),FALSE) -> 2065 | C34: =B34/(SUM(B$28:B$36)) -> 0.096962013 | D34: =VLOOKUP($A34,'[1]age headcounts'!$A:$G,HLOOKUP(Sheet2!D$1,'[1]age headcounts'!$1:$2,2,FALSE),FALSE) -> 2241 | E34: =D34/(SUM(D$28:D$36)) -> 0.091810398 | F34: =VLOOKUP($A34,'[1]age headcounts'!$A:$G,HLOOKUP(Sheet2!F$1,'[1]age headcounts'!$1:$2,2,FALSE),FALSE) -> 2282 | G34: =F34/(SUM(F$28:F$36)) -> 0.094818631 | H34: =VLOOKUP($A34,'[1]age headcounts'!$A:$G,HLOOKUP(Sheet2!H$1,'[1]age headcounts'!$1:$2,2,FALSE),FALSE) -> 1900 | I34: =H34/(SUM(H$28:H$36)) -> 0.090424519 | J34: =VLOOKUP($A34,'[1]age headcounts'!$A:$G,HLOOKUP(Sheet2!J$1,'[1]age headcounts'!$1:$2,2,FALSE),FALSE) -> 1573 | K34: =J34/(SUM(J$28:J$36)) -> 0.080526262 | L34: 116401 | M34: =L34/SUM(L$28:L$36) -> 0.13909223
A35: 50 + | B35: =VLOOKUP($A35,'[1]age headcounts'!$A:$G,HLOOKUP(Sheet2!B$1,'[1]age headcounts'!$1:$2,2,FALSE),FALSE) -> 1213 | C35: =B35/(SUM(B$28:B$36)) -> 0.056956379 | D35: =VLOOKUP($A35,'[1]age headcounts'!$A:$G,HLOOKUP(Sheet2!D$1,'[1]age headcounts'!$1:$2,2,FALSE),FALSE) -> 1329 | E35: =D35/(SUM(D$28:D$36)) -> 0.05444713 | F35: =VLOOKUP($A35,'[1]age headcounts'!$A:$G,HLOOKUP(Sheet2!F$1,'[1]age headcounts'!$1:$2,2,FALSE),FALSE) -> 1250 | G35: =F35/(SUM(F$28:F$36)) -> 0.051938339 | H35: =VLOOKUP($A35,'[1]age headcounts'!$A:$G,HLOOKUP(Sheet2!H$1,'[1]age headcounts'!$1:$2,2,FALSE),FALSE) -> 1058 | I35: =H35/(SUM(H$28:H$36)) -> 0.05035218 | J35: =VLOOKUP($A35,'[1]age headcounts'!$A:$G,HLOOKUP(Sheet2!J$1,'[1]age headcounts'!$1:$2,2,FALSE),FALSE) -> 947 | K35: =J35/(SUM(J$28:J$36)) -> 0.048479574 | L35: 236950 | M35: =L35/SUM(L$28:L$36) -> 0.28314107
A36: Unknown | B36: =VLOOKUP($A36,'[1]age headcounts'!$A:$G,HLOOKUP(Sheet2!B$1,'[1]age headcounts'!$1:$2,2,FALSE),FALSE) -> 4 | C36: =B36/(SUM(B$28:B$36)) -> 0.00018781988 | D36: =VLOOKUP($A36,'[1]age headcounts'!$A:$G,HLOOKUP(Sheet2!D$1,'[1]age headcounts'!$1:$2,2,FALSE),FALSE) -> 0 | E36: =D36/(SUM(D$28:D$36)) -> 0 | F36: =VLOOKUP($A36,'[1]age headcounts'!$A:$G,HLOOKUP(Sheet2!F$1,'[1]age headcounts'!$1:$2,2,FALSE),FALSE) -> 3 | G36: =F36/(SUM(F$28:F$36)) -> 0.00012465201 | H36: =VLOOKUP($A36,'[1]age headcounts'!$A:$G,HLOOKUP(Sheet2!H$1,'[1]age headcounts'!$1:$2,2,FALSE),FALSE) -> 2 | I36: =H36/(SUM(H$28:H$36)) -> 9.5183705e-05 | J36: =VLOOKUP($A36,'[1]age headcounts'!$A:$G,HLOOKUP(Sheet2!J$1,'[1]age headcounts'!$1:$2,2,FALSE),FALSE) -> 2 | K36: =J36/(SUM(J$28:J$36)) -> 0.00010238558 | L36: 0 | M36: =L36/SUM(L$28:L$36) -> 0
A37: Average Age | B37: 27.085805 | D37: 26.740922 | F37: 26.808412 | H37: 26.616662 | J37: 26.219426
A38: Median Age | B38: 22 | D38: 22 | F38: 22 | H38: 22 | J38: 22
B40: 5 Year MSJC Data | L40: Riverside County
B41: AY07-08 | D41: AY08-09 | F41: AY09-10 | H41: AY10-11 | J41: AY11-12 | L41: 2010 ACS*
A42: DSPS | B42: # | C42: % | D42: # | E42: % | F42: # | G42: % | H42: # | I42: % | J42: # | K42: % | L42: # | M42: %
A43: =A42 -> DSPS | B43: =B27 -> AY07-08# | C43: =C27 -> AY07-08% | D43: =D27 -> AY08-09# | E43: =E27 -> AY08-09% | F43: =F27 -> AY09-10# | G43: =G27 -> AY09-10% | H43: =H27 -> AY10-11# | I43: =I27 -> AY10-11% | ... M43: =M27 -> 2010 Census%
...

Sheet gender graph
A1: back to tables | AB1: Column Labels
AA2: Values | AB2: Female | AC2: Male | AD2: Unknown | AE2: Grand Total
AA3: AY07-08# | AB3: 12909 | AC3: 8196 | AD3: 192 | AE3: 21297
AA4: AY08-09# | AB4: 14479 | AC4: 9592 | AD4: 338 | AE4: 24409
AA5: AY09-10# | AB5: 13953 | AC5: 9853 | AD5: 261 | AE5: 24067
AA6: AY10-11# | AB6: 12000 | AC6: 8784 | AD6: 228 | AE6: 21012
AA7: AY11-12# | AB7: 11055 | AC7: 8299 | AD7: 180 | AE7: 19534

Sheet ethnicity graph
A1: back to tables | AB1: Column Labels
AA2: Values | AB2: White | AC2: Hispanic | AD2: Unknown | AE2: African American | AF2: Filipino | AG2: Asian | AH2: Multi-Race | AI2: Native American | AJ2: Pacific Islander | AK2: Grand Total
AA3: AY07-08# | AB3: 9963 | AC3: 6040 | AD3: 1590 | AE3: 1547 | AF3: 813 | AG3: 609 | AH3: 330 | AI3: 254 | AJ3: 151 | AK3: 21297
AA4: AY08-09# | AB4: 10935 | AC4: 7149 | AD4: 1935 | AE4: 1956 | AF4: 840 | AG4: 718 | AH4: 399 | AI4: 294 | AJ4: 183 | AK4: 24409
AA5: AY09-10# | AB5: 10427 | AC5: 7520 | AD5: 1690 | AE5: 1913 | AF5: 816 | AG5: 635 | AH5: 657 | AI5: 250 | AJ5: 159 | AK5: 24067
AA6: AY10-11# | AB6: 8877 | AC6: 7022 | AD6: 1079 | AE6: 1641 | AF6: 671 | AG6: 583 | AH6: 833 | AI6: 182 | AJ6: 124 | AK6: 21012
AA7: AY11-12# | AB7: 7806 | AC7: 7295 | AD7: 710 | AE7: 1507 | AF7: 599 | AG7: 478 | AH7: 908 | AI7: 141 | AJ7: 90 | AK7: 19534

Sheet age graph
A1: back to tables | AB1: Column Labels
AA2: Values | AB2: <18 | AC2: 18 & 19 | AD2: 20 to 24 | AE2: 25 to 29 | AF2: 30 to 34 | AG2: 35 to 39 | AH2: 40 to 49 | AI2: 50 + | AJ2: Unknown | AK2: Grand Total
AA3: AY07-08# | AB3: 733 | AC3: 4893 | AD3: 6750 | AE3: 2617 | AF3: 1668 | AG3: 1354 | AH3: 2065 | AI3: 1213 | AJ3: 4 | AK3: 21297
AA4: AY08-09# | AB4: 1026 | AC4: 5828 | AD4: 7632 | AE4: 2960 | AF4: 1886 | AG4: 1507 | AH4: 2241 | AI4: 1329 | AJ4: 0 | AK4: 24409
AA5: AY09-10# | AB5: 743 | AC5: 5660 | AD5: 7750 | AE5: 3092 | AF5: 1849 | AG5: 1438 | AH5: 2282 | AI5: 1250 | AJ5: 3 | AK5: 24067
AA6: AY10-11# | AB6: 336 | AC6: 4488 | AD6: 7563 | AE6: 2847 | AF6: 1632 | AG6: 1186 | AH6: 1900 | AI6: 1058 | AJ6: 2 | AK6: 21012
AA7: AY11-12# | AB7: 196 | AC7: 4057 | AD7: 7524 | AE7: 2625 | AF7: 1536 | AG7: 1074 | AH7: 1573 | AI7: 947 | AJ7: 2 | AK7: 19534
