Workbook

Sheet Cover

Sheet Introduction
A4: American Indian Higher Education Consortium
A5: American Indian Measures for Success (AIHEC-AIMS)
A7: AIMS Key Indicator System 2012 (AKIS 2012)

Sheet INSTRUCTIONS
A1: American Indian Higher Education Consortium
A2: American Indian Measures for Success (AIMS)
A4: AIMS-Key Indicator System 2012 (AKIS-2012)
A6: INSTRUCTIONS

Sheet 1.1a Overall Instit. Profile
A1: Institution | B1: =B5 -> Oglala Lakota College | K1: degree
A2: Indicator 1: Overall Institution Profile | K2: 4-year & master's
A3: Table 1.1a: Institution Profile, Contact Information, and Data Sources / AY 2011-12 | K3: 4-year& doctoral
A4: Institution Profile | K4: 4-year undergraduate
A5: Institution Name | B5: Oglala Lakota College | G5: Web Address | H5: www.olc.edu | K5: 2-year
A6: Address 1 | B6: Piya Wiconi - Three Mile Creek Road | G6: Highest Degree Offered | H6: 4-year & master's | I6: Academic Term | J6: semester
A7: Address 2 | B7: P.O. Box 490 | G7: Year Founded | H7: 1971 | I7: Land Granted Status | J7: yes | K7: academic term
A8: City | B8: Kyle | C8: State | D8: SD | E8: Zip | F8: 57752 | G8: Chartering Tribe | H8: Oglala Sioux Tribal Council | K8: quarter
A9: Telephone | B9: 605-455-6000 | G9: Operational Funding Source(s) | H9: Title I | K9: semester
A10: Main Campus Location | B10: Piya Wiconi - Three Mile Creek | C10: On/Off Reservation | G10: on | H10: Administrative Headquarters
A11: Additional Location (town, state) | B11: Allen, SD | C11: On/Off Reservation | G11: on | H11: Instructional Site
A12: Additional Location (town, state) | B12: Batesland, SD | C12: On/Off Reservation | G12: on | H12: Instructional Site
A13: Additional Location (town, state) | B13: Eagle Butte, SD | C13: On/Off Reservation | G13: on | H13: Instructional Site
A14: Additional Location (town, state) | B14: Manderson, SD | C14: On/Off Reservation | G14: on | H14: Instructional Site
A15: Additional Location (town, state) | B15: Martin, SD | C15: On/Off Reservation | G15: on | H15: Instructional Site
A16: Additional Location (town, state) | B16: Oglala, SD | C16: On/Off Reservation | G16: on | H16: Instructional Site
A17: Additional Location (town, state) | B17: Pine Ridge, SD | C17: On/Off Reservation | G17: on | H17: Instructional Site
A18: Additional Location (town, state) | B18: Porcupine, SD | C18: On/Off Reservation | G18: on | H18: Instructional Site
A19: Additional Location (town, state) | B19: Rapid City, SD | C19: On/Off Reservation | G19: off | H19: Instructional Site
A20: Additional Location (town, state) | B20: Wanblee, SD | C20: On/Off Reservation | G20: on | H20: Instructional Site
A21: Additional Location (town, state) | B21: Kyle, SD | C21: On/Off Reservation | G21: on | H21: Instructional Site
A22: Person(s) Responsible for this Report | K22: trimester
A23: Name | B23: Title | D23: Telephone | G23: Email Address | K23: other
A24: Ursula R. Gaertner | B24: Vice President for Instruction | D24: 605-455-6035 | H24: ugaertner@olc.edu
K25: land granted status
K26: yes
A27: Data Sources | K27: no
D28: Person(s) Responsible | G28: Notes
A29: Indicator 1: Overall Institution Profile | D29: Ursula Gaertner | K29: location
A30: Indicator 2: Financial Resources and Student Costs | D30: Eric Christensen | G30: Eric provided the information but resigned effective September 30, 2012 | K30: on reservation
A31: Indicator 3: Physical Resources | D31: Eric Christensen | G31: Eric provided the information but resigned effective September 30, 2012 | K31: off reservation
A32: Indicator 4: Student Enrollment and Graduation by Major Group | D32: Leslie Mesteth
A33: Indicator 5: Course Enrollment and Completion | D33: Leslie Mesteth
A34: Indicator 6: Student Activities | D34: Billi Hornbeck
A35: Indicator 7: Personnel Demographics, Professional Development, Research, and Outcomes | D35: Faith Richards
A36: Indicator 8: Students with Disabilities Enrollment and Graduation | D36: Leslie Heathershaw
A37: Notes: At the request of the Cheyenne River Sioux Tribe in Eagle Butte, SD, OLC also operates an Instructional Site at that location. Some functions are combined into one position.
A39: Please certify that your institution's President has seen and approved this submission.
A40: Thomas Shortbull, President | D40: Ursula R. Gaertner | H40: 41257
A41: President's Name & Signature | D41: Certified By | H41: Date

Sheet 1.1b Administration
A1: Institution | B1: ='1.1a Overall Instit. Profile'!$B$1 -> Oglala Lakota College
A2: Indicator 1: Overall Institution Profile
A3: Table 1.1b: Administration / AY 2012-13
A4: Please list the following administrators as of October 15, 2012 -- CURRENT Administration.
A5: Position | B5: Name | C5: Title | D5: Telephone | E5: E-mail
A6: President | B6: Thomas Shortbull | C6: President | D6: 605-455-6020 | E6: tshortb@olc.edu
A7: Assistant to President | B7: Diane Winters | C7: Assistant to President | D7: 605-455-6020 | E7: dwinters@olc.edu
A8: Chief Financial/ Business Officer | B8: vacant
A9: Chief Academic Officer | B9: Ursula R. Gaertner | C9: Vice President for Instruction | D9: 605-455-6035 | E9: ugaertner@olc.edu
A10: Chief Student Service Officer | B10: Billi Hornbeck | C10: Student Support Service Coordinator | D10: 605-455-6037 | E10: bhornbeck@olc.edu
A11: Registrar | B11: Leslie Mesteth | C11: Registrar | D11: 605-455-6033 | E11: lmesteth@olc.edu
A12: Financial Aid Officer | B12: Billi Hornbeck | C12: Financial Aid Officer | D12: 605-455-6037 | E12: bhornbeck@olc.edu
A13: Info. Tech. (MIS) | B13: Clifford DeLong | C13: Director, Infroamtion Technology | D13: 605-455-6079 | E13: cdelong@olc.edu
A14: Institutional Research | B14: vacant
A15: Assessment Officer | B15: vacant
A16: Development/Fundraising | B16: Marilyn Pourier | C16: Director of Development | D16: 605-455-6045 | E16: mpourier@olc.edu
A17: Office of Sponsored Programs | B17: N.A.
A18: Public Relations/ Communications | B18: Marilyn Pourier | C18: Director of Development | D18: 605-455-6045 | E18: mpourier@olc.edu
A19: Faculty Development Officer | B19: Ursula R. Gaertner | C19: Vice President for Instruction | D19: 605-455-6035 | E19: ugaertner@olc.edu

Sheet 1.2a Institution Profile
A1: Institution | D1: ='1.1a Overall Instit. Profile'!$B$1 -> Oglala Lakota College
A2: Indicator 1: Overall Institution Profile
A3: Table 1.2a: Institution Indian Student Count, Full Time Equivalent, and Tribal Affiliations / AY 2011-12
A4: Please enter the institution's Indian Student Count and Full time Equivalent (FTE) and five largest tribal affiliations of enrolled students.
A5: Student ISC and FTE Counts
B6: AY 2003-04 | E6: AY 2004-05 | H6: AY 2005-06 | K6: AY 2006-07 | N6: AY 2007-08
B7: Total | E7: Total | H7: Total | K7: Total | N7: Total
B8: 1126.4 | E8: 1202.51 | H8: 1131.51 | K8: 1069.8 | N8: 1069.63
B9: AY 2008-09
B10: Total
B11: 1046.35
A12: Full Time Equivalent (FTE)
C13: AY 2003-04 | H13: AY 2004-05 | M13: AY 2005-06
A14: American Indian | C14: Non-Indian | E14: FTE | F14: American Indian | H14: Non-Indian | J14: FTE | K14: American Indian | M14: Non-Indian
A15: M | B15: F | C15: M | D15: F | E15: Total | F15: M | G15: F | H15: M | I15: F | J15: Total | K15: M | L15: F | M15: M | N15: F
A16: 0 | B16: 0 | C16: 0 | D16: 0 | E16: =SUM(A16:D16) -> 0 | F16: 0 | G16: 0 | H16: 0 | I16: 0 | J16: =SUM(F16:I16) -> 0 | K16: 0 | L16: 0 | M16: 0 | N16: 0
C17: AY 2006-07 | H17: AY 2007-08 | M17: AY 2008-09
A18: American Indian | C18: Non-Indian | E18: FTE | F18: American Indian | H18: Non-Indian | J18: FTE | K18: American Indian | M18: Non-Indian
A19: M | B19: F | C19: M | D19: F | E19: Total | F19: M | G19: F | H19: M | I19: F | J19: Total | K19: M | L19: F | M19: M | N19: F
A20: 0 | B20: 0 | C20: 0 | D20: 0 | E20: =SUM(A20:D20) -> 0 | F20: 0 | G20: 0 | H20: 0 | I20: 0 | J20: =SUM(F20:I20) -> 0 | K20: 0 | L20: 0 | M20: 0 | N20: 0
A21: AY 2011-12 | C21: Part-Time AI Students | D21: Part-Time Non-AI Students | E21: Full-Time AI Students | F21: Full-Time Non-AI Students | G21: Part-Time AI Credits | H21: Part-Time Non-AI Credits | I21: Full-Time AI Credits | J21: Full-Time Non-AI Credits | K21: CEU AI Credits TOTAL | L21: ISC (see note) | M21: FTE (see note)
A22: Summer 2011 | C22: 172 | D22: 8 | E22: 21 | F22: 0 | G22: 891 | H22: 42 | I22: 282 | J22: 0 | K22: 25.9
A23: Fall 2011 | C23: 629 | D23: 67 | E23: 957 | F23: 35 | G23: 3961 | H23: 360 | I23: 11965 | J23: 439 | K23: 18.33
A24: Winter 2012 | C24: n.a. | D24: n.a. | E24: n.a. | F24: n.a. | G24: n.a. | H24: n.a. | I24: n.a. | J24: n.a. | K24: n.a.
A25: Spring 2012 | C25: 685 | D25: 81 | E25: 1016 | F25: 33 | G25: 4202 | H25: 382 | I25: 12805 | J25: 429 | K25: 23.13
A26: TOTAL | C26: =SUM(C22:C25) -> 1486 | D26: =SUM(D22:D25) -> 156 | E26: =SUM(E22:E25) -> 1994 | F26: =SUM(F22:F25) -> 68 | G26: =SUM(G22:G25) -> 9054 | H26: =SUM(H22:H25) -> 784 | I26: =SUM(I22:I25) -> 25052 | J26: =SUM(J22:J25) -> 868 | K26: =SUM(K22:K25) -> 67.36 | L26: =(SUM(G26,I26,)/24)+(K26*0.1) -> 1427.8193 | M26: =SUM(G26:J26)/24 -> 1489.9167
A27: ISC-- See glossary for full definition. ISC=((FTAICR+PTAICR)/24)+CEUs (or divided by 36 if on a quarter system), where CEUs used in calculation are limited to 10 percent.
A28: FTE--The sum of credits enrolled in by all students divided by 24 equals the full-time equivalency. FTE=(FTCR+PTCR)/24 (or divided by 36 if on a quarter system).
C29: Part-Time AI Students | D29: Part-Time Non-AI Students | E29: Full-Time AI Students | F29: Full-Time Non-AI Students | G29: Part-Time AI Credits | H29: Part-Time Non-AI Credits | I29: Full-Time AI Credits | J29: Full-Time Non-AI Credits | K29: CEU AI Credits TOTAL
A30: Fall 2012 | C30: 637 | D30: 60 | E30: 863 | F30: 29 | G30: 4050 | H30: 315 | I30: 10693 | J30: 378 | K30: 67.36
I31: Tribal Affiliations of Faculty, Staff, and Administrators at Tribal College
A32: Five Largest Tribal Affiliations of Students Enrolled at Tribal College
A33: Please list the five largest federally recognized tribes served by your institution. Total should not exceed total number of American Indian students enrolled (please see Table 4.2). | I33: Please list all federally recognized tribes for faculty, staff, and administrators represented at your institution. If more space is needed, please insert more lines.
A34: Fall 2011 (October 15, 2011) | I34: Oglala Sioux Tribe 115
A35: Tribe | F35: # Enrolled | G35: % of Enrollment | I35: Cheyenne River Sioux Tribe 6
A36: Oglala Sioux Tribe | F36: 1036 | G36: =SUM(F36/SUM('4.2 Major Group Totals'!D$10:'4.2 Major Group Totals'!E$10)) -> 0.64669164 | I36: Rosebud Sioux Tribe 3
A37: Cheyenne River Sioux Tribe | F37: 273 | G37: =SUM(F37/SUM('4.2 Major Group Totals'!D$10:'4.2 Major Group Totals'!E$10)) -> 0.17041199 | I37: Cherokee 1
A38: Rosebud Sioux Tribe | F38: 69 | G38: =SUM(F38/SUM('4.2 Major Group Totals'!D$10:'4.2 Major Group Totals'!E$10)) -> 0.043071161 | I38: Pueblo 1
A39: Standing Rock Sioux Tribe | F39: 36 | G39: =SUM(F39/SUM('4.2 Major Group Totals'!D$10:'4.2 Major Group Totals'!E$10)) -> 0.02247191 | I39: Tribe unknown 2
A40: Navajo Tribe | F40: 13 | G40: =SUM(F40/SUM('4.2 Major Group Totals'!D$10:'4.2 Major Group Totals'!E$10)) -> 0.0081148564

Sheet 1.2b Institutionial Narrative
A1: Institution | B1: ='1.1a Overall Instit. Profile'!$B$1 -> Oglala Lakota College | C1: ='1.1a Overall Instit. Profile'!$B$1 -> Oglala Lakota College | D1: ='1.1a Overall Instit. Profile'!$B$1 -> Oglala Lakota College | E1: ='1.1a Overall Instit. Profile'!$B$1 -> Oglala Lakota College | F1: ='1.1a Overall Instit. Profile'!$B$1 -> Oglala Lakota College | G1: ='1.1a Overall Instit. Profile'!$B$1 -> Oglala Lakota College | H1: ='1.1a Overall Instit. Profile'!$B$1 -> Oglala Lakota College | I1: ='1.1a Overall Instit. Profile'!$B$1 -> Oglala Lakota College | J1: ='1.1a Overall Instit. Profile'!$B$1 -> Oglala Lakota College
A2: Indicator 1: Overall Institution Profile
A3: Table 1.2b: Institutional Narrative / AY 2011-12
A4: Please insert a profile/description of your institution. Include, but do not limit the profile to, details about the institution’s location, land mass, population, establishment, programs, and what makes the institution unique. (See sample documents for examples.)
A5: Pine Ridge Reservation in South Dakota was established in 1889 after breaking up the Great Sioux Nation in 1868. The Pine Ridge Reservation has a population of 32,892 persons (HUD, 2012) who live in an area of over 3,648 square miles (larger than Delaware and Rhode Island together). The Bureau of Indian Affairs in its latest report, estimates that there are 46,855 members enrolled in the Oglala Sioux (Lakota) Tribe who live in the service area, which includes the Pine Ridge Reservation, Rapid City, and adjacent areas (BIA Labor Force Report, 2005). The only major city within a couple of hours driving distance from Pine Ridge is Rapid City (population 78,000). Chadron, Gordon and Rushville, NE are all within an hour of the southern Reservation boundary. None have a population over 5,000. The Pine Ridge Reservation has a representative government operating under a 1936 Indian Reorganization Act constitution. The legislative body is the 19 member Oglala Sioux Tribal Council. President and Vice-President are elected at large, and there is a five member Executive board. The Tribe is regarded as a sovereign nation according to US laws and treaties. The Tribe charters independent organizations like Oglala Lakota College, Oglala Sioux Department of Public Safety and Oglala Sioux (Lakota) Housing. The reservation is divided into nine districts with each having an elected district government and each electing representatives to the Tribal Council (www.oglalalakotanation.org). The state of South Dakota has divided the reservation into counties: Shannon is entirely within the reservation. Bennett and Jackson counties include three of the reservation districts and state jurisdiction areas as well. Distance, weather conditions, and the lack of serviceable automobiles are major transportation barriers with which reservation residents contend. Public transportation has just started on the reservation, and has limited service. Isolated homes and communities are served by gravel roads. Many homes on the reservation are inaccessible during periods of blizzards or heavy rain. Poverty has always been a feature of the Pine Ridge population. According to the 2010 U.S. Census, the Oglala Lakota per capita income was $7,772 and the poverty level was 53.5% for Shannon County, (four times the national average). The median income of residents in Shannon County from 2006 to 2010 was $24,392, almost half of that of the median of the country as a whole (US Census, Quickfacts). The number of persons living in a housing unit is nearly double the national median. It is common for multiple families to live in a two bedroom house. 87% of K/12 students on the Reservation receive free or reduced price lunches. 16.1% of adults over 25 are college graduates compared with 25.3% of the US population (US Census, Quickfacts). The BIA (2012a) gives the unemployment rate on the Reservation to be 89% with 34% of those employed still living below the poverty line. The State of South Dakota Office of Tribal Relations says that in 2000 33.4% of the labor force was unemployed, and that in 2005, 89% of Oglala Lakota tribal members were unemployed (SD Tribal Relations). This variation in numbers is the results of different definitions of unemployment as used by the US Census and other agencies. The Indian Health Service (IHS) US Department of Health and Human Services Report – Regional Differences in Indian Health 2002-2003 - the latest data collected - showed that the Aberdeen Area (which includes the Reservation) had the following death rates above the US average. Alcohol related +1290% Tuberculosis + 262% Homicide + 87% Heart disease + 50% Suicide + 212% Diabetes + 514% Native Americans smoke at twice the rate (46.5%) of other races, and infant mortality is over double that of the US average (Argus Leader (2007). Alcoholism affects 85% of families on the reservation (Woodward, 2012). Life expectancy for males on the reservation is 56.5 years and women 66 years (Kukarni et al, 2011). Scores on the standardized tests given as part of the federal No Child Left Behind effort in Spring 2011showed all students in South Dakota were 75% proficient in reading while 48% of Native Americans were proficient. The same ratio was true for math. 83% of all students starting the 9th grade graduated from high school in South Dakota, while 49% of Native-Americans did (Achievement Gap, 2012). OLC started offering classes at Mother Butler Center in Rapid City, SD at the request of the Indian community in 1985. In 1990 OLC built the He Sapa Instructional Center and has expanded the building twice since then. Many people from the Pine Ridge and Cheyenne River Reservation move to Rapid City for jobs and housing. The US Census put the Indian population of Rapid City at about 12,000 but as with the Reservation, Indian people are undercounted in the Census.
A8: Please share one or two significant challenges faced by your institution in AY 2011-12 (e.g., faculty changes, natural disaster, funding cuts, etc.).
A9: 1. Time spent on the road; all OLC faculty drive significatn distance4s to get to their classes and to the main administrative site. Many employees have a round trip of 180 to 200 miles a day. Traveling in bad weather is hazardous. 2. Student attendance in classes is a challenge; OLC policy allows four absenses (between 25 and 30% of the semester); homework is not turned in on time.

Sheet 1.3a First Time Students
A1: Institution | D1: ='1.1a Overall Instit. Profile'!$B$1 -> Oglala Lakota College
A2: Indicator 1: Overall Institution Profile
A3: Table 1.3a: First Time Entering Students Demographics / AY 2011-12
A4: Please enter the institution's first time entering student enrollment, background, and characteristics, including first-time freshman and transfer-in students. All data on this page are for the first time entering students only- not the entire institution.
A5: Time period: AY 2011 (Summer 2011 to Spring 2012)
A6: First Time Entering Student Enrollment
D7: American Indian | F7: Non-Indian | H7: Total | L7: Number of students who are | R7: American Indian | T7: Non-Indian
D8: M | E8: F | F8: M | G8: F | H8: M | I8: F | J8: Total | R8: M | S8: F | T8: M | U8: F
A9: Full Time | D9: 165 | E9: 202 | F9: 2 | G9: 3 | H9: =SUM(D9,F9) -> 167 | I9: =SUM(E9,G9) -> 205 | J9: =SUM(H9:I9) -> 372 | L9: Single - No Children | R9: 120 | S9: 145 | T9: 1 | U9: 6
A10: Part Time | D10: 43 | E10: 59 | F10: 3 | G10: 9 | H10: =SUM(D10,F10) -> 46 | I10: =SUM(E10,G10) -> 68 | J10: =SUM(H10:I10) -> 114 | L10: Single with dependent children | R10: 67 | S10: 92 | T10: 2 | U10: 3
A11: Total | D11: =SUM(D9:D10) -> 208 | E11: =SUM(E9:E10) -> 261 | F11: =SUM(F9:F10) -> 5 | G11: =SUM(G9:G10) -> 12 | H11: =SUM(D11,F11) -> 213 | I11: =SUM(E11,G11) -> 273 | J11: =SUM(H11:I11) -> 486 | L11: Married - No Children | R11: 5 | S11: 5 | T11: 0 | U11: 0
L12: Married with dependent children | R12: 18 | S12: 22 | T12: 0 | U12: 0
A13: First Time Entering Students Pre-College Preparation | L13: Responsible for elderly family members in home | R13: m | S13: m | T13: m | U13: m
A14: Number of students who | F14: American Indian | H14: Non-Indian | J14: Total
F15: M | G15: F | H15: M | I15: F | L15: Number of students who are | R15: American Indian | T15: Non-Indian
A16: Graduated High School with Diploma | F16: 142 | G16: 191 | H16: 2 | I16: 9 | J16: =SUM(H16:I16) -> 11 | R16: M | S16: F | T16: M | U16: F
B17: Number of HS graduates who graduated from | L17: First Generation Students | R17: m | S17: m | T17: m | U17: m
B18: Public High School not located on a reservation | F18: 0 | G18: 0 | H18: 0 | I18: o | J18: =SUM(H18:I18) -> 0 | L18: Not First Generation Students | R18: m | S18: m | T18: m | U18: m
B19: Reservation-based public High School | F19: 11 | G19: 33 | H19: 1 | I19: 2 | J19: =SUM(H19:I19) -> 3
B20: BIA school | F20: 44 | G20: 49 | H20: 0 | I20: 0 | J20: =SUM(H20:I20) -> 0 | L20: Primary residence is | R20: American Indian | T20: Non-Indian
B21: Tribal or Contract High School | F21: 33 | G21: 30 | H21: 0 | I21: 0 | J21: =SUM(H21:I21) -> 0 | R21: M | S21: F | T21: M | U21: F
B22: Other High School | F22: 54 | G22: 79 | H22: 1 | I22: 7 | J22: =SUM(H22:I22) -> 8 | L22: On / near reservation (within 60 miles) | R22: m | S22: m | T22: m | U22: m
A23: Earned GED | F23: 61 | G23: 55 | H23: 2 | I23: 3 | J23: =SUM(H23:I23) -> 5 | L23: In-State | R23: 206 | S23: 258 | T23: 5 | U23: 11
A24: Enrolled under Ability to Benefit provision | F24: 0 | G24: 0 | H24: 0 | I24: 0 | J24: =SUM(H24:I24) -> 0 | L24: Out-of-State | R24: 0 | S24: 0 | T24: 2 | U24: 4
A25: Dual enrolled High School and College | F25: 6 | G25: 14 | H25: 1 | I25: 0 | J25: =SUM(H25:I25) -> 1
A26: Have No High School Diploma or GED | F26: 0 | G26: 0 | H26: 0 | I26: 0 | J26: =SUM(H26:I26) -> 0 | L26: Financial Background | R26: American Indian | T26: Non-Indian
R27: M | S27: F | T27: M | U27: F
A28: Age range of students | L28: Average family income ($) in student's household | R28: 13328 | S28: 12797 | T28: 3000 | U28: 34482
A29: Number of students who are: | D29: 15-17 | E29: 18-21 | F29: 22-24 | G29: 25-34 | H29: 35-49 | I29: 50-64 | J29: 65 & over | L29: # of students employed less than 20 hrs/week (excluding work / study) | R29: m | S29: m | T29: m | U29: m
A30: American Indian | C30: M | D30: 3 | E30: 96 | F30: 34 | G30: 43 | H30: 26 | I30: 5 | J30: 1 | L30: # of students employed 20 or more hrs/week (excluding work / study) | R30: m | S30: m | T30: m | U30: m
C31: F | D31: 14 | E31: 125 | F31: 38 | G31: 45 | H31: 31 | I31: 6 | J31: 2 | L31: Number of students eligible for federal financial aid | R31: 75 | S31: 120 | T31: 1 | U31: 1
A32: Non-Indian | C32: M | D32: 1 | E32: 0 | F32: 2 | G32: 0 | H32: 1 | I32: 0 | J32: 1 | L32: Number of students in need, but not eligible for federal financial aid | R32: 4 | S32: 4 | T32: 0 | U32: 0
C33: F | D33: 0 | E33: 2 | F33: 4 | G33: 1 | H33: 5 | I33: 0 | J33: 0
L34: Number of students who | R34: American Indian | T34: Non-Indian
A35: Speakers of American Indian Languages | E35: None | F35: Limited | G35: Conversa-tional | H35: Fluent | R35: M | S35: F | T35: M | U35: F
A36: American Indian | C36: M | E36: 178 | F36: 33 | G36: m | H36: m | L36: Are Veterans | R36: 16 | S36: 11 | T36: 2 | U36: 1
C37: F | E37: 228 | F37: 30 | G37: m | H37: m | L37: Participated in a Head Start Program | R37: m | S37: m | T37: m | U37: m
A38: Non-Indian | C38: M | E38: 5 | F38: m | G38: m | H38: m
C39: F | E39: 12 | F39: m | G39: m | H39: m
A41: Skill Assessment / Placement Test Results
...

Sheet 1.3b General Student Pop
A1: Institution | D1: ='1.1a Overall Instit. Profile'!$B$1 -> Oglala Lakota College
A2: Indicator 1: Overall Institution Profile
A3: Table 1.3b: General Student Population Demographics / AY 2011-12
A4: Time period: Fall 2011 (October 15, 2011)
A5: Please enter the institution's general student population background, and characteristics, including first-time entering students.
A6: Age range of students
A7: Number of students who are: | D7: 15-17 | E7: 18-21 | F7: 22-24 | G7: 25-34 | H7: 35-49 | I7: 50-64 | J7: 65 & over
A8: American Indian | C8: M | D8: 0 | E8: 115 | F8: 83 | G8: 185 | H8: 119 | I8: 27 | J8: 2
C9: F | D9: 7 | E9: 206 | F9: 157 | G9: 341 | H9: 233 | I9: 100 | J9: 11
A10: Non-Indian | C10: M | D10: 1 | E10: 2 | F10: 4 | G10: 10 | H10: 10 | I10: 5 | J10: 2
C11: F | D11: 0 | E11: 6 | F11: 7 | G11: 20 | H11: 22 | I11: 12 | J11: 1
A13: Speakers of American Indian Languages | E13: None | F13: Limited | G13: Conversational | H13: Fluent
A14: American Indian | C14: M | E14: 444 | F14: 87 | G14: m | H14: m
C15: F | E15: 913 | F15: 142 | G15: m | H15: m
A16: Non-Indian | C16: M | E16: 34 | F16: m | G16: m | H16: m
C17: F | E17: 66 | F17: 2 | G17: m | H17: m
A19: Number of students who are | G19: American Indian | I19: Non-Indian
G20: M | H20: F | I20: M | J20: F
A21: Single - No Children | G21: 255 | H21: 335 | I21: 15 | J21: 20
A22: Single with dependent children | G22: 209 | H22: 556 | I22: 7 | J22: 18
A23: Married - No Children | G23: 8 | H23: 16 | I23: 3 | J23: 5
A24: Married with dependent children | G24: 59 | H24: 148 | I24: 9 | J24: 25
A25: Responsible for elderly family members in home | G25: m | H25: m | I25: m | J25: m
A27: Number of students who are | G27: American Indian | I27: Non-Indian
G28: M | H28: F | I28: M | J28: F
A29: First Generation Students | G29: m | H29: m | I29: m | J29: m
A30: Not First Generation Students | G30: m | H30: m | I30: m | J30: m
A32: Primary residence is | G32: American Indian | I32: Non-Indian
G33: M | H33: F | I33: M | J33: F
A34: On / near reservation (within 60 miles) | G34: m | H34: m | I34: m | J34: m
A35: In-State | G35: 527 | H35: 1037 | I35: 30 | J35: 58
A36: Out-of-State | G36: 4 | H36: 18 | I36: 4 | J36: 10
A38: Financial Background | G38: American Indian | I38: Non-Indian
G39: M | H39: F | I39: M | J39: F
A40: Average family income ($) in student's household | G40: 11743 | H40: 13019 | I40: 14903 | J40: 21099
A41: Number of students employed less than 20 hrs/week (excluding work / study) | G41: m | H41: m | I41: m | J41: m
A42: Number of students employed 20 or more hrs/week (excluding work / study) | G42: m | H42: m | I42: m | J42: m
A43: Number of students eligible for financial aid | G43: 381 | H43: 741 | I43: 16 | J43: 33
A44: Number of students in need, but not eligible for financial aid | G44: 47 | H44: 99 | I44: 0 | J44: 3
A46: Number of students who | G46: American Indian | I46: Non-Indian
...

Sheet 1.4 Institution Retention
A1: Institution | B1: ='1.1a Overall Instit. Profile'!$B$1 -> Oglala Lakota College
A2: Indicator 1: Overall Institution Profile
A3: Table 1.4: Institution Student Retention and Completion
A4: Please enter the total number of students entering the institution for the first time in fall 2009, including transfers.
A5: First-time entering students in fall 2009 | B5: 205
A6: Returned in fall 2011 | B6: 74
A7: Graduated in AY 2011-12 | B7: 6 | C7: # of Certificates | D7: 0 | E7: # of Associate's | F7: 6 | G7: # of Bachelor's | H7: 0 | I7: # of Master's | J7: 0
A8: Transferred to another college or university in AY 2011-12 | B8: 0 | D8: # of graduates who returned to pursue another certificate or degree** | I8: 6
A9: Withdrew or stopped out in AY 2011-12 | B9: 149
A10: Other Exclusions in 2011-12* | B10: 0
A11: Returned in fall 2012 | B11: 56
A13: Please enter the total number of students entering the institution for the first time in fall 2010, including transfers.
A14: First-time entering students in fall 2010 | B14: 228
A15: Returned in fall 2011 | B15: 96
A16: Graduated in AY 2011-12 | B16: 0 | C16: # of Certificates | D16: 0 | E16: # of Associate's | F16: 0 | G16: # of Bachelor's | H16: 0 | I16: # of Master's | J16: 0
A17: Transferred to another college or university in AY 2011-12 | B17: 0 | D17: # of graduates who returned to pursue another certificate or degree** | I17: 0
A18: Withdrew or stopped out in AY 2011-12 | B18: 164
A19: Other Exclusions in 2011-12* | B19: 0
A20: Returned in fall 2012 | B20: 64
A22: Please enter the total number of students entering the institution for the first time in fall 2011, including transfers.
A23: First-time entering students in fall 2011 | B23: 218
A24: Graduated in AY 2011-12 | B24: 0 | C24: # of Certificates | D24: 0 | E24: # of Associate's | F24: 0 | G24: # of Bachelor's | H24: 0 | I24: # of Master's | J24: 0
A25: Transferred to another college or university in AY 2011-12 | B25: 0 | D25: # of graduates who returned to pursue another certificate or degree** | I25: 0
A26: Withdrew or stopped out in AY 2011-12 | B26: 121
A27: Other Exclusions in 2011-12* | B27: 0
A28: Returned in fall 2012 | B28: 97
A29: * Exclusions include students who are deceased, permanently disabled, have joined armed forces, and are on official church missions. ** Please note that these graduates should not be counted as returning in fall 2012 students for purposes of retention. Once they've graduated, they are not longer first-time students.
A31: Successful Course Completion
A32: Please enter the total number of students.
B33: Non-Degree Seeking or Undeclared | F33: Certificate or Degree-Seeking | J33: Total
B34: Summer 2011 | C34: Fall 2011 | D34: Winter 2011 | E34: Spring 2012 | F34: Summer 2011 | G34: Fall 2011 | H34: Winter 2011 | I34: Spring 2012 | J34: Non-Degree Total | K34: Certificate/Degree Total | L34: AY 11-12 Total
A35: Total Number of Course Enrollments* | B35: 90 | C35: 475 | D35: n.a. | E35: 500 | F35: 495 | G35: 6297 | H35: n.a. | I35: 6503 | J35: =SUM(B35:G35) -> 7857 | K35: =SUM(F35:I35) -> 13295 | L35: =SUM(J35:K35) -> 21152
A36: Total Number of Successful Course Completions** | B36: 39 | C36: 128 | D36: n.a. | E36: 150 | F36: 447 | G36: 4104 | H36: n.a. | I36: 4069 | J36: =SUM(B36:F36) -> 764 | K36: =SUM(F36:I36) -> 8620 | L36: =SUM(J36:K36) -> 9384
A37: Successful Course Completion Rate | B37: =B36/B35 -> 0.43333333 | C37: =C36/C35 -> 0.26947368 | D37: =D36/D35 -> #VALUE! | E37: =E36/E35 -> 0.3 | F37: =F36/F35 -> 0.9030303 | G37: =G36/G35 -> 0.65173892 | H37: =H36/H35 -> #VALUE! | I37: =I36/I35 -> 0.62571121 | ... L37: =L36/L35 -> 0.44364599
A38: * This will count students multiple times.
A39: ** Successful completion means passing with a grade of A, B, C, CR (credit), or P (pass)
A41: NOTES

Sheet 1.5 Community Education
B1: Institution | C1: ='1.1a Overall Instit. Profile'!$B$1 -> Oglala Lakota College
A2: Indicator 1: Overall Institution Profile
A3: Table 1.5: Community Education Participation / AY 2011-12
A4: Please enter the institution's participation in community education programs
A5: Community Education Participation: (Summer 2011 - Spring 2012)
A6: Target Audience | B6: Program Name | C6: Funding Source | D6: Number of Participants
A7: Elementary (K-8)
A18: Secondary (9-12)
B31: Program Name | C31: Funding Source | D31: Number of Participants | E31: Type of Community Education
A32: Adult | E32: Employment Specific Training | F32: Other Adult Community Education*
B33: Community/Continuing Education Department | C33: BIA/ABE | D33: 665 | E33: 266 | F33: G.E.D.
B34: Nursing Department - Certified Nursing Assistant | C34: no cost to students | D34: 22 | E34: 22 | F34: Nursing Assistant
B35: Credit where Credit is Due | C35: Lakota Fund | D35: 10 | E35: 0 | F35: Banking
B36: Financial Literacy | C36: Lakota Fund | D36: 16 | F36: Budgeting
B37: Tax Preparation | C37: Lakota Fund | D37: 25 | F37: Taxes
B38: Home Buyers Class | C38: Lakota Fund | D38: 10 | F38: Home buyers
B39: Job Corps | C39: Job Corps | D39: 50 | F39: Workplace development
B40: Public Safety | C40: Oglala Sioux Tribe | D40: 15 | E40: 15
B41: Mind/Body Medicine | C41: none | D41: 6 | F41: Physical well being
B42: Strong Heart | C42: Indian Health Service | D42: 30 | F42: Heart health
B43: OST Fire Department | C43: Oglala Sioux Tribe | D43: 15 | E43: 15 | F43: Prevention
B44: Maza Ska | C44: Oglala Sioux Tribe | D44: 20 | F44: Money Management
B45: Tom Boy Tools | C45: none | D45: 15 | F45: development
B46: Obama Care | C46: Soc. Security Admiln. | D46: 20 | F46: Health Care
B47: Northern PlainsTrib C HB | C47: n.a. | D47: 1350 | F47: Cancer Awareness
B48: Diabetic Screening | C48: n.a. | D48: 140 | F48: Screening & Education
B49: Diabetic & Nutritional Program | C49: n.a. | D49: 32 | F49: Nutrition $ Wellness
B50: HIS Wellness Lectures | C50: n.a. | D50: 120 | F50: Flu Shots
B51: HIS Education Program | C51: n.a. | D51: 250 | F51: General Information
B52: Veteran's Vol Program | C52: n.a. | D52: 50 | F52: Veteran's Benefit by VA
D61: =SUM(D7:D60) -> 2861
A62: * Computer skills, financial literacy, parenting skills, etc.
A63: Notes:
A64: Attachment for tab 1.5 for the Math & Science department and the Agriculture Extension Department

Sheet 2.1 Student Tuition & Costs
A1: Institution | C1: ='1.1a Overall Instit. Profile'!B1 -> Oglala Lakota College
A2: Indicator 2: Financial Resources and Student Costs
A3: Table 2.1: Student Tuition, Financial Aid, and Costs / AY 2011-12
A4: Please enter the tuition cost per credit hour, the total amount of financial aid received and the number of students receiving aid, and undergraduate student costs.
A5: Sources and Amount of Financial Aid | D5: AY 11-12
A6: American Indian College Fund Scholarship | C6: Total Dollar Amount | D6: 154132
C7: Total Number of Recipients | D7: 291
A8: American Indian College Fund Full Circle Scholarship | C8: Total Dollar Amount | D8: 131500
C9: Total Number of Recipients | D9: 46
A10: Federal Pell Grants | C10: Total Dollar Amount | D10: 5216170
C11: Total Number of Recipients | D11: 1519
A12: Federal Supplemental Educational Opportunity Grant | C12: Total Dollar Amount | D12: 88400
C13: Total Number of Recipients | D13: 203
A14: Direct Federal Student Loans | C14: Total Dollar Amount | D14: 0
C15: Total Number of Recipients | D15: 0
A16: State Scholarships/Grants | C16: Total Dollar Amount | D16: 65599
C17: Total Number of Recipients | D17: 152
A18: Academic Competitiveness Grant | C18: Total Dollar Amount | D18: 0
C19: Total Number of Recipients | D19: 0
A20: School-to-Work | C20: Total Dollar Amount | D20: 0
C21: Total Number of Recipients | D21: 0
A22: Tribal Scholarships | C22: Total Dollar Amount | D22: 847479
C23: Total Number of Recipients | D23: 407
A24: TCU-based Tuition Waiver/Discount | C24: Total Dollar Amount | D24: 23477
C25: Total Number of Recipients | D25: 39
A26: Other Scholarships | C26: Total Dollar Amount | D26: 759645
C27: Total Number of Recipients | D27: 1358
A28: Federal College Work Study | C28: Total Dollar Amount | D28: 82599
C29: Total Number of Recipients | D29: 64
A30: State Work Study | C30: Total Dollar Amount | D30: 0
C31: Total Number of Recipients | D31: 0
A32: Institutional Work Study | C32: Total Dollar Amount | D32: 0
C33: Total Number of Recipients | D33: 0
A35: Cost per Credit Hour (CURRENT Academic Year):
A36: Undergraduate American Indian, In-State | C36: 80
A37: Undergraduate American Indian, Out-of-State | C37: 80
A38: Undergraduate Non-Indian, In-State | C38: 98
A39: Undergraduate Non-Indian, Out-of-State | C39: 98
A40: Graduate American Indian, In-State | C40: 115
A41: Graduate American Indian, Out-of-State | C41: 115
...

Sheet 2.2 Non-Fed Operational Funding
A1: Institution | C1: ='1.1a Overall Instit. Profile'!B1 -> Oglala Lakota College
A2: Indicator 2: Financial Resources and Student Costs
A3: Table 2.2: Non-Federal Operational Funding / AY 2011-12
A4: Tribal Funding
A5: Current Academic Year (AY 12-13) Operational Funding from the Tribe (non-scholarship) | D5: 0
A6: Current Academic Year (AY 12-13) Construction Funding from the Tribe | D6: 0
A7: State Funding
A8: Current Fiscal Year (FY 12-13) Operational Funding Received from the State (Perkins money) | D8: 78000
A9: Current Fiscal Year (FY 12-13) Non-Beneficiary Funding Received from the State | D9: 0

Sheet 3.1 Academic Building
A1: Institution | B1: ='1.1a Overall Instit. Profile'!B1 -> Oglala Lakota College
A2: Indicator 3: Physical Resources
A3: Table 3.1: Building Facilities
A4: Please briefly summarize the institution's buildings. Identify building usage by main function. Reproduce this work sheet as needed. If building is used for multiple purposes (e.g. classroom and laboratory) please list building name as many times as necessary and identify total square feet for each main function.
A5: Does your institution have daycare or other early childhood learning facilities? | C5: yes
A6: If so, how many children are served? | B6: Main Campus | C6: Age range | D6: m | F6: What is the cost to attend? | G6: m
A7: Whose children attend (Students, Faculty/Staff, General Community)? | B7: Students, General Community | F7: Who operates the facility? (TCU, Tribe, Independent non-tribal organization) | H7: Oglala Sioux Tribe
A8: Do TCU students work in the facility? | B8: m
A9: If so, in what capacity? Please place an X by response(s).
A10: Interns, teaching aides, or other capacity tied to the students' studies | C10: m | D10: Hired employees | F10: m | G10: Volunteers | H10: m
A11: Existing Buildings
A12: Building Name | B12: Campus Site | C12: Year Built / Acquired | D12: No. of Stories | E12: Total sq. ft. | F12: Main Function | G12: Own / Lease | H12: Note | J12: Campus Site
A13: Piya Wiconi | B13: Main Campus | C13: 1980 | D13: 2 | E13: 24800 | F13: Administration/Office | G13: Own | J13: Main Campus
A14: Pine Ridge House 1 | B14: Satellite Site | C14: 1939 | D14: 1 | E14: 1700 | F14: Auxiliary | G14: Own | J14: Branch Campus
A15: Pine Ridge House 2 | B15: Satellite Site | C15: 1939 | D15: 1 | E15: 1700 | F15: Auxiliary | G15: Own | J15: Satellite Site
A16: Classrooms | B16: Satellite Site | C16: 1970 | D16: 1 | E16: 3080 | F16: Classroom | G16: Own
A17: Martin Building | B17: Satellite Site | C17: 1947 | D17: 1 | E17: 2500 | F17: Auxiliary | G17: Own | J17: Main Function
A18: Voc-Ed Building Metal Building | B18: Main Campus | C18: 1981 | D18: 1 | E18: 8400 | F18: Administration/Office | G18: Own | J18: Administration/Office
A19: Wooden Building | B19: Main Campus | C19: 1988 | D19: 1 | E19: 2100 | F19: Administration/Office | G19: Own | J19: Auxiliary
A20: Kyle Center | B20: Satellite Site | C20: 1994 | D20: 1 | E20: m | F20: Administration/Office | G20: Own | J20: Classroom
A21: Batesland Center | B21: Satellite Site | C21: 1994 | D21: 1 | E21: 5000 | F21: Administration/Office | G21: Own | J21: Cultural Center/Museum
A22: Porcupine Center | B22: Satellite Site | C22: 1997 | D22: 1 | E22: 6582 | F22: Classroom | G22: Own | J22: Distance Learning
A23: Pine Ridge Center | B23: Satellite Site | C23: 1997 | D23: 1 | E23: 12150 | F23: Classroom | G23: Own | J23: Laboratory
A24: Manderson Center | B24: Satellite Site | C24: 1998 | D24: 1 | E24: m | F24: Classroom | G24: Own | J24: Library
A25: Wanblee Center | B25: Satellite Site | C25: 1998 | D25: 1 | E25: m | F25: Classroom | G25: Own | J25: Research
A26: Oglala Center | B26: Satellite Site | C26: 1998 | D26: 1 | E26: m | F26: Classroom | G26: Own | J26: Residence
A27: Allen Center | B27: Satellite Site | C27: 1999 | D27: 1 | E27: m | F27: Classroom | G27: Own | J27: Student Services/Recreation
A28: Martin Center | B28: Satellite Site | C28: 1999 | D28: 1 | E28: m | F28: Classroom | G28: Own
A29: Rapid City Center | B29: Satellite Site | C29: 1999 | D29: 1 | E29: m | F29: Classroom | G29: Own | J29: Own/Lease
A30: Kyle Center Addition | B30: Satellite Site | C30: 2001 | D30: 1 | E30: m | F30: Classroom | G30: Own | J30: Assigned by Tribe
A31: Pine Ridge Log Cabin | B31: Satellite Site | C31: m | D31: 1 | E31: 4526 | F31: Auxiliary | G31: Own | J31: Donated
A32: Nursing Dorm | B32: Satellite Site | C32: 2003 | D32: 1 | E32: m | F32: Residence | G32: Own | J32: Lease/Rent
A33: Lakota Center for Science & Technology | B33: Main Campus | C33: 2003 | D33: 1 | E33: 6000 | F33: Laboratory | G33: Own | J33: Own
A34: Nursing Building | B34: Satellite Site | C34: 2004 | D34: 1 | E34: 8000 | F34: Classroom | G34: Own
A35: Pine Ridge College Center Expansion | B35: Satellite Site | C35: 2004 | D35: 1 | E35: 4500 | F35: Classroom | G35: Own
A36: He Sapa College Center Expansion | B36: Satellite Site | C36: 2006 | D36: 1 | E36: 6500 | F36: Classroom | G36: Own
A37: Cheyenne River College Center | B37: Satellite Site | C37: 2000 | D37: 1 | E37: 25000 | F37: Classroom | G37: Assigned by Tribe
A38: Pine Ridge Dorms | B38: Satellite Site | C38: 2006 | D38: 1 | E38: 4200 | F38: Residence | G38: Own
A39: Pole Barn Building | B39: Main Campus | C39: 2008 | D39: 1 | E39: 2040 | F39: Administration/Office | G39: Own
A40: Bookstore | B40: Main Campus | C40: 2008 | D40: 1 | E40: 3625 | F40: Administration/Office | G40: Own
...

Sheet 3.2 Library Fac & Res Equipment
A1: Institution | D1: ='1.1a Overall Instit. Profile'!B1 -> Oglala Lakota College
A2: Indicator 3: Physical Resources | N2: Inter-Library System
A3: Table 3.2: Library Facilities / AY 2011-12 | N3: Computer Lab w/ Internet
A4: Please briefly summarize the current status of library facilities. | N4: <select one>
A5: Library Facility | N5: Yes
A6: Library Name | C6: Total sq. ft. | D6: Year Built / Remodeled | E6: Volumes | F6: Periodicals | H6: Catalogue On-line Access | I6: Inter-Library System | J6: Computer Lab w/ Internet | K6: Community Library Status | L6: Community Learning Center | N6: No
F7: Print | G7: Electronic
A8: Woksape Tipi | C8: 18000 | D8: 1997 | E8: 49000 | F8: 60 | G8: 80* | H8: Yes | I8: Yes | J8: Yes | K8: Community Library | L8: Yes | N8: Community Library Status
N9: <select one>
N10: Community Library
A11: Special Cultural Collections: Please briefly describe any cultural or tribal museum/archival collections housed in library or other building.
A12: Museum, Archival Collections; - Lakota Artifacts (e.g. head dresses, pipes, moccasins), - manuscripts, microfilm, video, audio, photographs, maps, posters, rare books, publications covering broad spectrum of Lakota history, society, culture, and institutions; - institutional records of Oglala Lakota College and Oglala Sioux Tribe; - Artwork by Oglala Lakota artists (contemporary).
A13: Library Improvements / Acquisitions during academic year
A14: AY 11-12 | B14: m
A15: Notes:
A16: * w/3000+ titles

Sheet 3.3 Research Equipment
A1: Institution | B1: ='1.1a Overall Instit. Profile'!B1 -> Oglala Lakota College
A2: Indicator 3: Physical Resources
A3: Table 3.3: Instructional/ Research Equipment and Facilities Acquired /AY 2011-12
A4: Please enter major instructional/ research equipment and facilities acquired during the academic year
A5: Major Instructional/ Research Equipment and Facilities Acquisition
B6: AY 11-12
A7: Equipment or Facility Name | B7: Oglala Lakota College Center for Science and Technology
A8: Purchase Cost | B8: 436697
A9: Number of Units | B9: 22 museum cabinets, 5 hoods, 8 cabinets, 2 sinks, 2 tables, UV disinfector, labor, miscelleaneous
A10: Purpose | B10: Laboratory renovations and Tribal Reposistory
A11: Equipment or Facility Name | B11: Department of Math, Science, and Technology
A12: Purchase Cost | B12: $4,900 + installation
A13: Number of Units | B13: 1
A14: Purpose | B14: Multi-site polycom and smart board for departmental use
A15: Equipment or Facility Name | B15: Piya Wiconi Campus, 3 instructional sites, Rapid City server station
A16: Purchase Cost | B16: 140000
A17: Number of Units | B17: 1 and various and multiple
A18: Purpose | B18: Polycom bridge and upgrades to computing infrastructure
A19: Equipment or Facility Name
A20: Purchase Cost
A21: Number of Units
A22: Purpose
A23: Equipment or Facility Name
A24: Purchase Cost
A25: Number of Units
A26: Purpose
A27: Equipment or Facility Name
A28: Purchase Cost
A29: Number of Units
A30: Purpose
... A87: Notes:
A88: 0

Sheet 4.1 Majors
B1: Institution | C1: ='1.1a Overall Instit. Profile'!$B$1 -> Oglala Lakota College | E1: Major Group ID/Major Groups
A2: Indicator 4: Student Enrollment and Graduation by Major Group | E2: AC - Accounting
A3: Table 4.1: Major Groups | E3: AG - Agriculture and Farming
A4: Please identify your institution's specific majors and degrees offered by major group. If you have additional majors, please add them as needed. | E4: AL - American Indian Languages
A5: Major Groups | E5: AS - American Indian Studies
A6: I.D. | B6: Major Groups | C6: Specific Majors (and Degrees Offered) | E6: AR - Art
A7: AC | B7: Accounting | C7: Accounting (AA) | E7: AU - Automotive Technology
A8: AL | B8: American Indian Languages | C8: Lakota Language (CT) | E8: BI - Biology
A9: AS | B9: American Indian Studies | C9: Lakota Studies (AA, BA); K-12 Lakota Studies Education (BS); Tribal Law (AA); | E9: BT - Building Trades
A10: AR | B10: Art | C10: Fine Art (AA) | E10: BU - Business
A11: AU | B11: Automotive Technology | C11: Automotive Technology (AAS) | E11: CH - Chemistry
A12: BT | B12: Building Trades | C12: Electrical Technology (AAS); General Construction (CT, AAS); Plumbing Technology (CT, AAS), HVAC ((AAS) | E12: CS - Computer Science
A13: BU | B13: Business | C13: Business Administration (BS); Business (AA), Entrepreneurship (AAS) | E13: CT - Computer Technology
A14: CS | B14: Computer Science | C14: Information Technology (AA, BS) | E14: CL - Corrections/Law Enforcement
A15: EA | B15: Education-Paraprofessional | C15: Child Development Associate (CT); Early Childhood (AA); Elementary Education (AA) | E15: EA - Education-Paraprofessional
A16: EO | B16: Education-Professional | C16: Early Childhood (BA); K-8 Elementary Education (BS); K-12:Lakota Studeis (BS), 7-12 Secondary Education Physical Science (BS), | E16: EO - Education-Professional
A17: ES | B17: Environmental Science/Natural Resources | C17: Natural Science (BS), Natural Reources (AA, BS), Science, Eng., Math (SEM) (AA); Life Science, (AA) | E17: EN - English
... A28: UN | B28: Undeclared/Nondeclared | C28: Undeclared (Core) | E28: NU - Nursing
E29: OA - Office Administration/Technology
E30: PA - Paralegal
E31: PE - Pre-Engineering/Engineering
E32: PV - Pre-Veterinary Science
E33: SC - Science
E34: SS - Social Science
A35: Notes: | E35: VC - Vocational/Career Programs
E36: UN - Undeclared/Nondeclared
E37: MS - Master Degree Programs

Sheet 4.2(AC) Major Group Enroll-Grad
A1: Institution | D1: ='1.1a Overall Instit. Profile'!B1 -> Oglala Lakota College
A2: Indicator 4: Student Enrollment and Graduation by Major Group
A3: Table 4.2(AC): Major Group Fall Enrollment, Graduation & Post-Graduate / AY 2011-12
B4: Major Group | C4: AC - Accounting
B5: Please enter the number of students enrolled in this major group for the fall semester.
F6: Fall 2011 (October 15, 2011)
B7: Fall Enrollment (Snapshot) | D7: American Indian | F7: Non-Indian
D8: M | E8: F | F8: M | G8: F | H8: Total
C9: Full Time | D9: 0 | E9: 0 | F9: 0 | G9: 0 | H9: =SUM(D9:G9) -> 0
C10: Part Time | D10: 0 | E10: 1 | F10: 0 | G10: 0 | H10: =SUM(D10:G10) -> 1
C11: Total | D11: =SUM(D9:D10) -> 0 | E11: =SUM(E9:E10) -> 1 | F11: =SUM(F9:F10) -> 0 | G11: =SUM(G9:G10) -> 0 | H11: =SUM(D11:G11) -> 1
B12: Please enter the number of diploma, certificates, and degrees earned in this major group. Also enter the number of students who were admitted to a 4 year (Associate degree graduates), or graduate school (Bachelor's degree graduates). Lastly, enter the number of all graduating students(certificate or degree) who secured gainful employment after graduation.
F13: July 1, 2011- June 30, 2012
B14: Graduation | D14: American Indian | F14: Non-Indian
D15: M | E15: F | F15: M | G15: F | H15: Total
A16: Apprenticeship/Occupational Program | D16: na | E16: na | F16: na | G16: na | H16: =SUM(D16:G16) -> 0
B17: App. graduates admitted to a college program | D17: na | E17: na | F17: na | G17: na | H17: =SUM(D17:G17) -> 0
A18: Diploma | D18: na | E18: na | F18: na | G18: na | H18: =SUM(D18:G18) -> 0
B19: Dip. graduates admitted to a college program | D19: na | E19: na | F19: na | G19: na | H19: =SUM(D19:G19) -> 0
A20: Certificate | D20: na | E20: na | F20: na | G20: na | H20: =SUM(D20:G20) -> 0
B21: Cert. graduates admitted to a college program | D21: na | E21: na | F21: na | G21: na | H21: =SUM(D21:G21) -> 0
A22: Associate Degree | D22: 1 | E22: 3 | F22: 0 | G22: 0 | H22: =SUM(D22:G22) -> 4
B23: Assoc. graduates admitted to four-year program | D23: 0 | E23: 0 | F23: 0 | G23: 0 | H23: =SUM(D23:G23) -> 0
A24: Bachelor's Degree | D24: na | E24: na | F24: na | G24: na | H24: =SUM(D24:G24) -> 0
B25: Bach. graduates admitted to graduate school | D25: na | E25: na | F25: na | G25: na | H25: =SUM(D25:G25) -> 0
A26: Master's Degree | D26: na | E26: na | F26: na | G26: na | H26: =SUM(D26:G26) -> 0
A27: Gainfully Employed after graduation | D27: m | E27: m | F27: m | G27: m | H27: =SUM(D27:G27) -> 0
A28: Graduates who completed remedial courses during their time at the TCU | D28: m | E28: m | F28: m | G28: m | H28: =SUM(D28:G28) -> 0
A29: Graduates who received A*CF support at some point during their coursework | D29: m | E29: m | F29: m | G29: m | H29: =SUM(D29:G29) -> 0
A31: Notes:
A32: Graduates are not tracked after graduation. Graduates who took remedial courses are not tracked. Graduates who received ACF are not tracked.

Sheet 4.2(AG) Major Group Enroll-Grad
A1: Institution | D1: ='1.1a Overall Instit. Profile'!B1 -> Oglala Lakota College
A2: Indicator 4: Student Enrollment and Graduation by Major Group
A3: Table 4.2(AG): Major Group Fall Enrollment, Graduation & Post-Graduate / AY 20010-11
B4: Major Group | C4: AG - Agriculture and Farming
B5: Please enter the number of students enrolled in this major group for the fall semester.
F6: Fall 2011 (October 15, 2011)
B7: Fall Enrollment (Snapshot) | D7: American Indian | F7: Non-Indian
D8: M | E8: F | F8: M | G8: F | H8: Total
C9: Full Time | D9: na | E9: na | F9: na | G9: na | H9: =SUM(D9:G9) -> 0
C10: Part Time | D10: na | E10: na | F10: na | G10: na | H10: =SUM(D10:G10) -> 0
C11: Total | D11: =SUM(D9:D10) -> 0 | E11: =SUM(E9:E10) -> 0 | F11: =SUM(F9:F10) -> 0 | G11: =SUM(G9:G10) -> 0 | H11: =SUM(D11:G11) -> 0
B12: Please enter the number of diploma, certificates, and degrees earned in this major group. Also enter the number of students who were admitted to a 4 year (Associate degree graduates), or graduate school (Bachelor's degree graduates). Lastly, enter the number of all graduating students(certificate or degree) who secured gainful employment after graduation.
F13: July 1, 2011- June 30, 2012
B14: Graduation | D14: American Indian | F14: Non-Indian
D15: M | E15: F | F15: M | G15: F | H15: Total
A16: Apprenticeship/Occupational Program | D16: na | E16: na | F16: na | G16: na | H16: =SUM(D16:G16) -> 0
B17: App. graduates admitted to a college program | D17: na | E17: na | F17: na | G17: na | H17: =SUM(D17:G17) -> 0
A18: Diploma | D18: na | E18: na | F18: na | G18: na | H18: =SUM(D18:G18) -> 0
B19: Dip. graduates admitted to a college program | D19: na | E19: na | F19: na | G19: na | H19: =SUM(D19:G19) -> 0
A20: Certificate | D20: na | E20: na | F20: na | G20: na | H20: =SUM(D20:G20) -> 0
B21: Cert. graduates admitted to a college program | D21: na | E21: na | F21: na | G21: na | H21: =SUM(D21:G21) -> 0
A22: Associate Degree | D22: na | E22: na | F22: na | G22: na | H22: =SUM(D22:G22) -> 0
B23: Assoc. graduates admitted to four-year program | D23: na | E23: na | F23: na | G23: na | H23: =SUM(D23:G23) -> 0
A24: Bachelor's Degree | D24: na | E24: na | F24: na | G24: na | H24: =SUM(D24:G24) -> 0
B25: Bach. graduates admitted to graduate school | D25: na | E25: na | F25: na | G25: na | H25: =SUM(D25:G25) -> 0
A26: Master's Degree | D26: na | E26: na | F26: na | G26: na | H26: =SUM(D26:G26) -> 0
A27: Gainfully Employed after graduation | D27: na | E27: na | F27: na | G27: na | H27: =SUM(D27:G27) -> 0
A28: Graduates who completed remedial courses during their time at the TCU | D28: na | E28: na | F28: na | G28: na | H28: =SUM(D28:G28) -> 0
A29: Graduates who received A*CF support at some point during their coursework | D29: na | E29: na | F29: na | G29: na | H29: =SUM(D29:G29) -> 0
A31: Notes:

Sheet 4.2(AL) Major Group Enroll-Grad
A1: Institution | D1: ='1.1a Overall Instit. Profile'!B1 -> Oglala Lakota College
A2: Indicator 4: Student Enrollment and Graduation by Major Group
A3: Table 4.2(AL): Major Group Fall Enrollment, Graduation & Post-Graduate / AY 2011-12
B4: Major Group | C4: AL - American Indian Languages
B5: Please enter the number of students enrolled in this major group for the fall semester.
F6: Fall 2011 (October 15, 2011)
B7: Fall Enrollment (Snapshot) | D7: American Indian | F7: Non-Indian
D8: M | E8: F | F8: M | G8: F | H8: Total
C9: Full Time | D9: 0 | E9: 0 | F9: 0 | G9: 0 | H9: =SUM(D9:G9) -> 0
C10: Part Time | D10: 1 | E10: 0 | F10: 0 | G10: 0 | H10: =SUM(D10:G10) -> 1
C11: Total | D11: =SUM(D9:D10) -> 1 | E11: =SUM(E9:E10) -> 0 | F11: =SUM(F9:F10) -> 0 | G11: =SUM(G9:G10) -> 0 | H11: =SUM(D11:G11) -> 1
B12: Please enter the number of diploma, certificates, and degrees earned in this major group. Also enter the number of students who were admitted to a 4 year (Associate degree graduates), or graduate school (Bachelor's degree graduates). Lastly, enter the number of all graduating students(certificate or degree) who secured gainful employment after graduation.
F13: July 1, 2011- June 30, 2012
B14: Graduation | D14: American Indian | F14: Non-Indian
D15: M | E15: F | F15: M | G15: F | H15: Total
A16: Apprenticeship/Occupational Program | D16: na | E16: na | F16: na | G16: na | H16: =SUM(D16:G16) -> 0
B17: App. graduates admitted to a college program | D17: na | E17: na | F17: na | G17: na | H17: =SUM(D17:G17) -> 0
A18: Diploma | D18: na | E18: na | F18: na | G18: na | H18: =SUM(D18:G18) -> 0
B19: Dip. graduates admitted to a college program | D19: na | E19: na | F19: na | G19: na | H19: =SUM(D19:G19) -> 0
A20: Certificate | D20: 1 | E20: 0 | F20: 0 | G20: 0 | H20: =SUM(D20:G20) -> 1
B21: Cert. graduates admitted to a college program | D21: 0 | E21: 0 | F21: 0 | G21: 0 | H21: =SUM(D21:G21) -> 0
A22: Associate Degree | D22: na | E22: na | F22: na | G22: na | H22: =SUM(D22:G22) -> 0
B23: Assoc. graduates admitted to four-year program | D23: na | E23: na | F23: na | G23: na | H23: =SUM(D23:G23) -> 0
A24: Bachelor's Degree | D24: na | E24: na | F24: na | G24: na | H24: =SUM(D24:G24) -> 0
B25: Bach. graduates admitted to graduate school | D25: na | E25: na | F25: na | G25: na | H25: =SUM(D25:G25) -> 0
A26: Master's Degree | D26: na | E26: na | F26: na | G26: na | H26: =SUM(D26:G26) -> 0
A27: Gainfully Employed after graduation | D27: m | E27: m | F27: m | G27: m | H27: =SUM(D27:G27) -> 0
A28: Graduates who completed remedial courses during their time at the TCU | D28: m | E28: m | F28: m | G28: m | H28: =SUM(D28:G28) -> 0
A29: Graduates who received A*CF support at some point during their coursework | D29: m | E29: m | F29: m | G29: m | H29: =SUM(D29:G29) -> 0
A31: Notes:
A32: Students are not tracked after graduation. OLC does not offer apprenticeships, associate or bachelor degrees in Lakota language.

Sheet 4.2(AS) Major Group Enroll-Grad
A1: Institution | D1: ='1.1a Overall Instit. Profile'!B1 -> Oglala Lakota College
A2: Indicator 4: Student Enrollment and Graduation by Major Group
A3: Table 4.2(AS): Major Group Fall Enrollment, Graduation & Post-Graduate / AY 2011-12
B4: Major Group | C4: AS - American Indian Studies
B5: Please enter the number of students enrolled in this major group for the fall semester.
F6: Fall 2011 (October 15, 2011)
B7: Fall Enrollment (Snapshot) | D7: American Indian | F7: Non-Indian
D8: M | E8: F | F8: M | G8: F | H8: Total
C9: Full Time | D9: 33 | E9: 40 | F9: 0 | G9: 0 | H9: =SUM(D9:G9) -> 73
C10: Part Time | D10: 15 | E10: 24 | F10: 1 | G10: 1 | H10: =SUM(D10:G10) -> 41
C11: Total | D11: =SUM(D9:D10) -> 48 | E11: =SUM(E9:E10) -> 64 | F11: =SUM(F9:F10) -> 1 | G11: =SUM(G9:G10) -> 1 | H11: =SUM(D11:G11) -> 114
B12: Please enter the number of diploma, certificates, and degrees earned in this major group. Also enter the number of students who were admitted to a 4 year (Associate degree graduates), or graduate school (Bachelor's degree graduates). Lastly, enter the number of all graduating students(certificate or degree) who secured gainful employment after graduation.
F13: July 1, 2011- June 30, 2012
B14: Graduation | D14: American Indian | F14: Non-Indian
D15: M | E15: F | F15: M | G15: F | H15: Total
A16: Apprenticeship/Occupational Program | D16: na | E16: na | F16: na | G16: na | H16: =SUM(D16:G16) -> 0
B17: App. graduates admitted to a college program | D17: na | E17: na | F17: na | G17: na | H17: =SUM(D17:G17) -> 0
A18: Diploma | D18: na | E18: na | F18: na | G18: na | H18: =SUM(D18:G18) -> 0
B19: Dip. graduates admitted to a college program | D19: na | E19: na | F19: na | G19: na | H19: =SUM(D19:G19) -> 0
A20: Certificate | D20: na | E20: na | F20: na | G20: na | H20: =SUM(D20:G20) -> 0
B21: Cert. graduates admitted to a college program | D21: na | E21: na | F21: na | G21: na | H21: =SUM(D21:G21) -> 0
A22: Associate Degree | D22: 7 | E22: 14 | F22: 0 | G22: 1 | H22: =SUM(D22:G22) -> 22
B23: Assoc. graduates admitted to four-year program | D23: 0 | E23: 0 | F23: 0 | G23: 0 | H23: =SUM(D23:G23) -> 0
A24: Bachelor's Degree | D24: 4 | E24: 3 | F24: 0 | G24: 1 | H24: =SUM(D24:G24) -> 8
B25: Bach. graduates admitted to graduate school | D25: 0 | E25: 0 | F25: 0 | G25: 0 | H25: =SUM(D25:G25) -> 0
A26: Master's Degree | D26: na | E26: na | F26: na | G26: na | H26: =SUM(D26:G26) -> 0
A27: Gainfully Employed after graduation | D27: m | E27: m | F27: m | G27: m | H27: =SUM(D27:G27) -> 0
A28: Graduates who completed remedial courses during their time at the TCU | D28: m | E28: m | F28: m | G28: m | H28: =SUM(D28:G28) -> 0
A29: Graduates who received A*CF support at some point during their coursework | D29: m | E29: m | F29: m | G29: m | H29: =SUM(D29:G29) -> 0
A31: Notes:
A32: OLC does not offer apprenticeships, Diplomas, or Certificates or a master's degree in this discipline. OLC does not track graduates, nor who received ACF or took remedial courses.

Sheet 4.2(AR) Major Group Enroll-Grad
A1: Institution | D1: ='1.1a Overall Instit. Profile'!B1 -> Oglala Lakota College
A2: Indicator 4: Student Enrollment and Graduation by Major Group
A3: Table 4.2(AR): Major Group Fall Enrollment, Graduation & Post-Graduate / AY 2011-12
B4: Major Group | C4: AR - Art
B5: Please enter the number of students enrolled in this major group for the fall semester.
F6: Fall 2011 (October 15, 2011)
B7: Fall Enrollment (Snapshot) | D7: American Indian | F7: Non-Indian
D8: M | E8: F | F8: M | G8: F | H8: Total
C9: Full Time | D9: 9 | E9: 12 | F9: 0 | G9: 0 | H9: =SUM(D9:G9) -> 21
C10: Part Time | D10: 4 | E10: 0 | F10: 0 | G10: 0 | H10: =SUM(D10:G10) -> 4
C11: Total | D11: =SUM(D9:D10) -> 13 | E11: =SUM(E9:E10) -> 12 | F11: =SUM(F9:F10) -> 0 | G11: =SUM(G9:G10) -> 0 | H11: =SUM(D11:G11) -> 25
B12: Please enter the number of diploma, certificates, and degrees earned in this major group. Also enter the number of students who were admitted to a 4 year (Associate degree graduates), or graduate school (Bachelor's degree graduates). Lastly, enter the number of all graduating students(certificate or degree) who secured gainful employment after graduation.
F13: July 1, 2011- June 30, 2012
B14: Graduation | D14: American Indian | F14: Non-Indian
D15: M | E15: F | F15: M | G15: F | H15: Total
A16: Apprenticeship/Occupational Program | D16: na | E16: na | F16: na | G16: na | H16: =SUM(D16:G16) -> 0
B17: App. graduates admitted to a college program | D17: na | E17: na | F17: na | G17: na | H17: =SUM(D17:G17) -> 0
A18: Diploma | D18: na | E18: na | F18: na | G18: na | H18: =SUM(D18:G18) -> 0
B19: Dip. graduates admitted to a college program | D19: na | E19: na | F19: na | G19: na | H19: =SUM(D19:G19) -> 0
A20: Certificate | D20: na | E20: na | F20: na | G20: na | H20: =SUM(D20:G20) -> 0
B21: Cert. graduates admitted to a college program | D21: na | E21: na | F21: na | G21: na | H21: =SUM(D21:G21) -> 0
A22: Associate Degree | D22: 0 | E22: 1 | F22: 0 | G22: 0 | H22: =SUM(D22:G22) -> 1
B23: Assoc. graduates admitted to four-year program | D23: 0 | E23: 0 | F23: 0 | G23: 0 | H23: =SUM(D23:G23) -> 0
A24: Bachelor's Degree | D24: na | E24: na | F24: na | G24: na | H24: =SUM(D24:G24) -> 0
B25: Bach. graduates admitted to graduate school | D25: na | E25: na | F25: na | G25: na | H25: =SUM(D25:G25) -> 0
A26: Master's Degree | D26: na | E26: na | F26: na | G26: na | H26: =SUM(D26:G26) -> 0
A27: Gainfully Employed after graduation | D27: m | E27: m | F27: m | G27: m | H27: =SUM(D27:G27) -> 0
A28: Graduates who completed remedial courses during their time at the TCU | D28: m | E28: m | F28: m | G28: m | H28: =SUM(D28:G28) -> 0
