Workbook

Sheet mRNA data actual expression val
A1: probeid | B1: geneid | C1: Cs | D1: Cn | E1: Cb | F1: Cm | G1: Vs | H1: Vn | I1: Vb | J1: Vm | L1: deaf.loci | M1: Matisse module 7
A2: LECT1 | B2: 16840 | C2: =2^mRNA.data.anova.results_filtere!C2 -> 2005.8528 | D2: =2^mRNA.data.anova.results_filtere!D2 -> 120.25891 | E2: =2^mRNA.data.anova.results_filtere!E2 -> 108.3834 | F2: =2^mRNA.data.anova.results_filtere!F2 -> 106.89125 | G2: =2^mRNA.data.anova.results_filtere!G2 -> 1226.2182 | H2: =2^mRNA.data.anova.results_filtere!H2 -> 106.89125 | I2: =2^mRNA.data.anova.results_filtere!I2 -> 97.00586 | J2: =2^mRNA.data.anova.results_filtere!J2 -> 137.187 | L2: AUNA1
A3: THSD1 | B3: 56229 | C3: =2^mRNA.data.anova.results_filtere!C3 -> 111.43047 | D3: =2^mRNA.data.anova.results_filtere!D3 -> 117.78402 | E3: =2^mRNA.data.anova.results_filtere!E3 -> 709.17605 | F3: =2^mRNA.data.anova.results_filtere!F3 -> 105.41965 | G3: =2^mRNA.data.anova.results_filtere!G3 -> 129.78681 | H3: =2^mRNA.data.anova.results_filtere!H3 -> 116.16245 | I3: =2^mRNA.data.anova.results_filtere!I3 -> 714.10876 | J3: =2^mRNA.data.anova.results_filtere!J3 -> 134.36374 | L3: AUNA1
A4: DIAP3 | B4: 56419 | C4: =2^mRNA.data.anova.results_filtere!C4 -> 106.1529 | D4: =2^mRNA.data.anova.results_filtere!D4 -> 202.25058 | E4: =2^mRNA.data.anova.results_filtere!E4 -> 117.78402 | F4: =2^mRNA.data.anova.results_filtere!F4 -> 101.12529 | G4: =2^mRNA.data.anova.results_filtere!G4 -> 107.63474 | H4: =2^mRNA.data.anova.results_filtere!H4 -> 170.07178 | I4: =2^mRNA.data.anova.results_filtere!I4 -> 117.78402 | J4: =2^mRNA.data.anova.results_filtere!J4 -> 93.701485 | L4: AUNA1
A5: TRIM13 | B5: 66597 | C5: =2^mRNA.data.anova.results_filtere!C5 -> 117.78402 | D5: =2^mRNA.data.anova.results_filtere!D5 -> 218.27453 | E5: =2^mRNA.data.anova.results_filtere!E5 -> 104.69146 | F5: =2^mRNA.data.anova.results_filtere!F5 -> 99.04416 | G5: =2^mRNA.data.anova.results_filtere!G5 -> 112.20553 | H5: =2^mRNA.data.anova.results_filtere!H5 -> 227.54373 | I5: =2^mRNA.data.anova.results_filtere!I5 -> 107.63474 | J5: =2^mRNA.data.anova.results_filtere!J5 -> 104.69146 | L5: AUNA1
A6: P2RY5 | B6: 67168 | C6: =2^mRNA.data.anova.results_filtere!C6 -> 167.73036 | D6: =2^mRNA.data.anova.results_filtere!D6 -> 140.06959 | E6: =2^mRNA.data.anova.results_filtere!E6 -> 533.74247 | F6: =2^mRNA.data.anova.results_filtere!F6 -> 240.51782 | G6: =2^mRNA.data.anova.results_filtere!G6 -> 265.02782 | H6: =2^mRNA.data.anova.results_filtere!H6 -> 136.23938 | I6: =2^mRNA.data.anova.results_filtere!I6 -> 661.68465 | J6: =2^mRNA.data.anova.results_filtere!J6 -> 280.13919 | L6: AUNA1
A7: CAB39L | B7: 69008 | C7: =2^mRNA.data.anova.results_filtere!C7 -> 826.00116 | D7: =2^mRNA.data.anova.results_filtere!D7 -> 657.11406 | E7: =2^mRNA.data.anova.results_filtere!E7 -> 340.14357 | F7: =2^mRNA.data.anova.results_filtere!F7 -> 337.79403 | G7: =2^mRNA.data.anova.results_filtere!G7 -> 643.59085 | H7: =2^mRNA.data.anova.results_filtere!H7 -> 754.82584 | I7: =2^mRNA.data.anova.results_filtere!I7 -> 337.79403 | J7: =2^mRNA.data.anova.results_filtere!J7 -> 312.99591 | L7: AUNA1
A8: CKAP2 | B8: 80986 | C8: =2^mRNA.data.anova.results_filtere!C8 -> 85.627364 | D8: =2^mRNA.data.anova.results_filtere!D8 -> 232.3249 | E8: =2^mRNA.data.anova.results_filtere!E8 -> 308.6868 | F8: =2^mRNA.data.anova.results_filtere!F8 -> 147.03339 | G8: =2^mRNA.data.anova.results_filtere!G8 -> 103.96831 | H8: =2^mRNA.data.anova.results_filtere!H8 -> 235.56804 | I8: =2^mRNA.data.anova.results_filtere!I8 -> 172.4459 | J8: =2^mRNA.data.anova.results_filtere!J8 -> 118.60327 | L8: AUNA1
A9: PCDH17 | B9: 219228 | C9: =2^mRNA.data.anova.results_filtere!C9 -> 430.53896 | D9: =2^mRNA.data.anova.results_filtere!D9 -> 445.72189 | E9: =2^mRNA.data.anova.results_filtere!E9 -> 1698.4464 | F9: =2^mRNA.data.anova.results_filtere!F9 -> 537.45494 | G9: =2^mRNA.data.anova.results_filtere!G9 -> 515.56124 | H9: =2^mRNA.data.anova.results_filtere!H9 -> 484.38152 | I9: =2^mRNA.data.anova.results_filtere!I9 -> 1770.5722 | J9: =2^mRNA.data.anova.results_filtere!J9 -> 315.17297 | L9: AUNA1
A10: PCDH20 | B10: 219257 | C10: =2^mRNA.data.anova.results_filtere!C10 -> 123.63985 | D10: =2^mRNA.data.anova.results_filtere!D10 -> 92.411469 | E10: =2^mRNA.data.anova.results_filtere!E10 -> 88.647006 | F10: =2^mRNA.data.anova.results_filtere!F10 -> 87.426576 | G10: =2^mRNA.data.anova.results_filtere!G10 -> 424.61161 | H10: =2^mRNA.data.anova.results_filtere!H10 -> 148.05609 | I10: =2^mRNA.data.anova.results_filtere!I10 -> 91.773136 | J10: =2^mRNA.data.anova.results_filtere!J10 -> 88.034676 | L10: AUNA1
A11: BMX | B11: 12169 | C11: =2^mRNA.data.anova.results_filtere!C11 -> 96.335792 | D11: =2^mRNA.data.anova.results_filtere!D11 -> 94.35323 | E11: =2^mRNA.data.anova.results_filtere!E11 -> 156.49796 | F11: =2^mRNA.data.anova.results_filtere!F11 -> 93.701485 | G11: =2^mRNA.data.anova.results_filtere!G11 -> 98.360012 | H11: =2^mRNA.data.anova.results_filtere!H11 -> 95.009509 | I11: =2^mRNA.data.anova.results_filtere!I11 -> 230.72012 | J11: =2^mRNA.data.anova.results_filtere!J11 -> 93.054241 | L11: DFN6
A12: GPM6B | B12: 14758 | C12: =2^mRNA.data.anova.results_filtere!C12 -> 584.07102 | D12: =2^mRNA.data.anova.results_filtere!D12 -> 1595.7291 | E12: =2^mRNA.data.anova.results_filtere!E12 -> 298.1718 | F12: =2^mRNA.data.anova.results_filtere!F12 -> 955.42578 | G12: =2^mRNA.data.anova.results_filtere!G12 -> 448.82213 | H12: =2^mRNA.data.anova.results_filtere!H12 -> 1488.8679 | I12: =2^mRNA.data.anova.results_filtere!I12 -> 296.11218 | J12: =2^mRNA.data.anova.results_filtere!J12 -> 1089.9151 | L12: DFN6
A13: RAI2 | B13: 24004 | C13: =2^mRNA.data.anova.results_filtere!C13 -> 237.20654 | D13: =2^mRNA.data.anova.results_filtere!D13 -> 233.94085 | E13: =2^mRNA.data.anova.results_filtere!E13 -> 91.773136 | F13: =2^mRNA.data.anova.results_filtere!F13 -> 430.53896 | G13: =2^mRNA.data.anova.results_filtere!G13 -> 149.0859 | H13: =2^mRNA.data.anova.results_filtere!H13 -> 191.3407 | I13: =2^mRNA.data.anova.results_filtere!I13 -> 113.77186 | J13: =2^mRNA.data.anova.results_filtere!J13 -> 809.0023 | L13: DFN6
... A33: PTPRG | B33: 19270 | C33: =2^mRNA.data.anova.results_filtere!C33 -> 203.65734 | D33: =2^mRNA.data.anova.results_filtere!D33 -> 190.01902 | E33: =2^mRNA.data.anova.results_filtere!E33 -> 410.14778 | F33: =2^mRNA.data.anova.results_filtere!F33 -> 177.29401 | G33: =2^mRNA.data.anova.results_filtere!G33 -> 176.06935 | H33: =2^mRNA.data.anova.results_filtere!H33 -> 149.0859 | I33: =2^mRNA.data.anova.results_filtere!I33 -> 413.00058 | J33: =2^mRNA.data.anova.results_filtere!J33 -> 187.40297 | L33: DFNA18
A34: ROBO1 | B34: 19876 | C34: =2^mRNA.data.anova.results_filtere!C34 -> 792.35328 | D34: =2^mRNA.data.anova.results_filtere!D34 -> 190.01902 | E34: =2^mRNA.data.anova.results_filtere!E34 -> 630.34594 | F34: =2^mRNA.data.anova.results_filtere!F34 -> 1152.0599 | G34: =2^mRNA.data.anova.results_filtere!G34 -> 770.68633 | H34: =2^mRNA.data.anova.results_filtere!H34 -> 166.57176 | I34: =2^mRNA.data.anova.results_filtere!I34 -> 298.1718 | J34: =2^mRNA.data.anova.results_filtere!J34 -> 770.68633 | L34: DFNA18 | M34: Yes
A35: SEMA3B | B35: 20347 | C35: =2^mRNA.data.anova.results_filtere!C35 -> 182.27843 | D35: =2^mRNA.data.anova.results_filtere!D35 -> 380.03803 | E35: =2^mRNA.data.anova.results_filtere!E35 -> 108.3834 | F35: =2^mRNA.data.anova.results_filtere!F35 -> 99.733066 | G35: =2^mRNA.data.anova.results_filtere!G35 -> 213.78251 | H35: =2^mRNA.data.anova.results_filtere!H35 -> 442.64306 | I35: =2^mRNA.data.anova.results_filtere!I35 -> 108.3834 | J35: =2^mRNA.data.anova.results_filtere!J35 -> 100.42676 | L35: DFNA18
A36: SEMA3F | B36: 20350 | C36: =2^mRNA.data.anova.results_filtere!C36 -> 427.56501 | D36: =2^mRNA.data.anova.results_filtere!D36 -> 112.20553 | E36: =2^mRNA.data.anova.results_filtere!E36 -> 268.72747 | F36: =2^mRNA.data.anova.results_filtere!F36 -> 233.94085 | G36: =2^mRNA.data.anova.results_filtere!G36 -> 256 | H36: =2^mRNA.data.anova.results_filtere!H36 -> 111.43047 | I36: =2^mRNA.data.anova.results_filtere!I36 -> 213.78251 | J36: =2^mRNA.data.anova.results_filtere!J36 -> 304.43702 | L36: DFNA18
A37: SEMA5B | B37: 20357 | C37: =2^mRNA.data.anova.results_filtere!C37 -> 630.34594 | D37: =2^mRNA.data.anova.results_filtere!D37 -> 724.07734 | E37: =2^mRNA.data.anova.results_filtere!E37 -> 102.53694 | F37: =2^mRNA.data.anova.results_filtere!F37 -> 330.84232 | G37: =2^mRNA.data.anova.results_filtere!G37 -> 272.47877 | H37: =2^mRNA.data.anova.results_filtere!H37 -> 630.34594 | I37: =2^mRNA.data.anova.results_filtere!I37 -> 100.42676 | J37: =2^mRNA.data.anova.results_filtere!J37 -> 227.54373 | L37: DFNA18
A38: TRF | B38: 22041 | C38: =2^mRNA.data.anova.results_filtere!C38 -> 97.680589 | D38: =2^mRNA.data.anova.results_filtere!D38 -> 167.73036 | E38: =2^mRNA.data.anova.results_filtere!E38 -> 786.88009 | F38: =2^mRNA.data.anova.results_filtere!F38 -> 167.73036 | G38: =2^mRNA.data.anova.results_filtere!G38 -> 121.93766 | H38: =2^mRNA.data.anova.results_filtere!H38 -> 257.78062 | I38: =2^mRNA.data.anova.results_filtere!I38 -> 504.95114 | J38: =2^mRNA.data.anova.results_filtere!J38 -> 608.87404 | L38: DFNA18
A39: WNT5A | B39: 22418 | C39: =2^mRNA.data.anova.results_filtere!C39 -> 809.0023 | D39: =2^mRNA.data.anova.results_filtere!D39 -> 139.10206 | E39: =2^mRNA.data.anova.results_filtere!E39 -> 98.360012 | F39: =2^mRNA.data.anova.results_filtere!F39 -> 634.73034 | G39: =2^mRNA.data.anova.results_filtere!G39 -> 352.13871 | H39: =2^mRNA.data.anova.results_filtere!H39 -> 163.14376 | I39: =2^mRNA.data.anova.results_filtere!I39 -> 155.41695 | J39: =2^mRNA.data.anova.results_filtere!J39 -> 1305.1501 | L39: DFNA18
A40: FAIM | B40: 23873 | C40: =2^mRNA.data.anova.results_filtere!C40 -> 410.14778 | D40: =2^mRNA.data.anova.results_filtere!D40 -> 364.55685 | E40: =2^mRNA.data.anova.results_filtere!E40 -> 526.39428 | F40: =2^mRNA.data.anova.results_filtere!F40 -> 265.02782 | G40: =2^mRNA.data.anova.results_filtere!G40 -> 377.41292 | H40: =2^mRNA.data.anova.results_filtere!H40 -> 335.46071 | I40: =2^mRNA.data.anova.results_filtere!I40 -> 504.95114 | J40: =2^mRNA.data.anova.results_filtere!J40 -> 290.01827 | L40: DFNA18
A41: NEK4 | B41: 23955 | C41: =2^mRNA.data.anova.results_filtere!C41 -> 458.25284 | D41: =2^mRNA.data.anova.results_filtere!D41 -> 512 | E41: =2^mRNA.data.anova.results_filtere!E41 -> 165.42116 | F41: =2^mRNA.data.anova.results_filtere!F41 -> 413.00058 | G41: =2^mRNA.data.anova.results_filtere!G41 -> 592.22435 | H41: =2^mRNA.data.anova.results_filtere!H41 -> 584.07102 | I41: =2^mRNA.data.anova.results_filtere!I41 -> 245.57161 | J41: =2^mRNA.data.anova.results_filtere!J41 -> 442.64306 | L41: DFNA18
A42: TWF2 | B42: 23999 | C42: =2^mRNA.data.anova.results_filtere!C42 -> 154.3434 | D42: =2^mRNA.data.anova.results_filtere!D42 -> 172.4459 | E42: =2^mRNA.data.anova.results_filtere!E42 -> 306.55455 | F42: =2^mRNA.data.anova.results_filtere!F42 -> 157.58648 | G42: =2^mRNA.data.anova.results_filtere!G42 -> 274.37401 | H42: =2^mRNA.data.anova.results_filtere!H42 -> 142.02489 | I42: =2^mRNA.data.anova.results_filtere!I42 -> 347.29071 | J42: =2^mRNA.data.anova.results_filtere!J42 -> 167.73036 | L42: DFNA18
A43: SLCO2A1 | B43: 24059 | C43: =2^mRNA.data.anova.results_filtere!C43 -> 90.509668 | D43: =2^mRNA.data.anova.results_filtere!D43 -> 92.411469 | E43: =2^mRNA.data.anova.results_filtere!E43 -> 245.57161 | F43: =2^mRNA.data.anova.results_filtere!F43 -> 92.411469 | G43: =2^mRNA.data.anova.results_filtere!G43 -> 243.87533 | H43: =2^mRNA.data.anova.results_filtere!H43 -> 93.701485 | I43: =2^mRNA.data.anova.results_filtere!I43 -> 369.64587 | J43: =2^mRNA.data.anova.results_filtere!J43 -> 121.93766 | L43: DFNA18
A44: IL17RB | B44: 50905 | C44: =2^mRNA.data.anova.results_filtere!C44 -> 132.51391 | D44: =2^mRNA.data.anova.results_filtere!D44 -> 98.360012 | E44: =2^mRNA.data.anova.results_filtere!E44 -> 86.822677 | F44: =2^mRNA.data.anova.results_filtere!F44 -> 95.009509 | G44: =2^mRNA.data.anova.results_filtere!G44 -> 177.29401 | H44: =2^mRNA.data.anova.results_filtere!H44 -> 91.139213 | I44: =2^mRNA.data.anova.results_filtere!I44 -> 93.701485 | J44: =2^mRNA.data.anova.results_filtere!J44 -> 93.054241 | L44: DFNA18
A45: ST3GAL6 | B45: 54613 | C45: =2^mRNA.data.anova.results_filtere!C45 -> 106.89125 | D45: =2^mRNA.data.anova.results_filtere!D45 -> 98.360012 | E45: =2^mRNA.data.anova.results_filtere!E45 -> 477.71289 | F45: =2^mRNA.data.anova.results_filtere!F45 -> 118.60327 | G45: =2^mRNA.data.anova.results_filtere!G45 -> 101.82867 | H45: =2^mRNA.data.anova.results_filtere!H45 -> 95.009509 | I45: =2^mRNA.data.anova.results_filtere!I45 -> 455.08745 | J45: =2^mRNA.data.anova.results_filtere!J45 -> 119.42822 | L45: DFNA18
A46: PDZRN3 | B46: 55983 | C46: =2^mRNA.data.anova.results_filtere!C46 -> 165.42116 | D46: =2^mRNA.data.anova.results_filtere!D46 -> 680.28714 | E46: =2^mRNA.data.anova.results_filtere!E46 -> 112.98598 | F46: =2^mRNA.data.anova.results_filtere!F46 -> 380.03803 | G46: =2^mRNA.data.anova.results_filtere!G46 -> 259.57363 | H46: =2^mRNA.data.anova.results_filtere!H46 -> 519.14725 | I46: =2^mRNA.data.anova.results_filtere!I46 -> 109.89638 | J46: =2^mRNA.data.anova.results_filtere!J46 -> 544.95753 | L46: DFNA18
... A80: ROBO2 | B80: 268902 | C80: =2^mRNA.data.anova.results_filtere!C80 -> 225.97197 | D80: =2^mRNA.data.anova.results_filtere!D80 -> 103.96831 | E80: =2^mRNA.data.anova.results_filtere!E80 -> 95.670352 | F80: =2^mRNA.data.anova.results_filtere!F80 -> 268.72747 | G80: =2^mRNA.data.anova.results_filtere!G80 -> 104.69146 | H80: =2^mRNA.data.anova.results_filtere!H80 -> 99.04416 | I80: =2^mRNA.data.anova.results_filtere!I80 -> 97.680589 | J80: =2^mRNA.data.anova.results_filtere!J80 -> 165.42116 | L80: DFNA18
A81: EPHB1 | B81: 270190 | C81: =2^mRNA.data.anova.results_filtere!C81 -> 625.99182 | D81: =2^mRNA.data.anova.results_filtere!D81 -> 564.17542 | E81: =2^mRNA.data.anova.results_filtere!E81 -> 474.41309 | F81: =2^mRNA.data.anova.results_filtere!F81 -> 200.85353 | G81: =2^mRNA.data.anova.results_filtere!G81 -> 968.76303 | H81: =2^mRNA.data.anova.results_filtere!H81 -> 533.74247 | I81: =2^mRNA.data.anova.results_filtere!I81 -> 294.06678 | J81: =2^mRNA.data.anova.results_filtere!J81 -> 203.65734 | L81: DFNA18 | M81: Yes
A82: FLNB | B82: 286940 | C82: =2^mRNA.data.anova.results_filtere!C82 -> 1398.8252 | D82: =2^mRNA.data.anova.results_filtere!D82 -> 948.82618 | E82: =2^mRNA.data.anova.results_filtere!E82 -> 1488.8679 | F82: =2^mRNA.data.anova.results_filtere!F82 -> 404.50115 | G82: =2^mRNA.data.anova.results_filtere!G82 -> 1287.1817 | H82: =2^mRNA.data.anova.results_filtere!H82 -> 803.41412 | I82: =2^mRNA.data.anova.results_filtere!I82 -> 1584.7066 | J82: =2^mRNA.data.anova.results_filtere!J82 -> 315.17297 | L82: DFNA18
A83: PARP14 | B83: 547253 | C83: =2^mRNA.data.anova.results_filtere!C83 -> 99.04416 | D83: =2^mRNA.data.anova.results_filtere!D83 -> 145.00914 | E83: =2^mRNA.data.anova.results_filtere!E83 -> 248.99967 | F83: =2^mRNA.data.anova.results_filtere!F83 -> 89.263595 | G83: =2^mRNA.data.anova.results_filtere!G83 -> 97.680589 | H83: =2^mRNA.data.anova.results_filtere!H83 -> 225.97197 | I83: =2^mRNA.data.anova.results_filtere!I83 -> 270.59662 | J83: =2^mRNA.data.anova.results_filtere!J83 -> 94.35323 | L83: DFNA18
A84: EDN1 | B84: 13614 | C84: =2^mRNA.data.anova.results_filtere!C84 -> 116.16245 | D84: =2^mRNA.data.anova.results_filtere!D84 -> 99.04416 | E84: =2^mRNA.data.anova.results_filtere!E84 -> 274.37401 | F84: =2^mRNA.data.anova.results_filtere!F84 -> 89.263595 | G84: =2^mRNA.data.anova.results_filtere!G84 -> 114.56321 | H84: =2^mRNA.data.anova.results_filtere!H84 -> 136.23938 | I84: =2^mRNA.data.anova.results_filtere!I84 -> 398.93226 | J84: =2^mRNA.data.anova.results_filtere!J84 -> 86.822677 | L84: DFNA21
A85: ID4 | B85: 15904 | C85: =2^mRNA.data.anova.results_filtere!C85 -> 424.61161 | D85: =2^mRNA.data.anova.results_filtere!D85 -> 464.64981 | E85: =2^mRNA.data.anova.results_filtere!E85 -> 118.60327 | F85: =2^mRNA.data.anova.results_filtere!F85 -> 104.69146 | G85: =2^mRNA.data.anova.results_filtere!G85 -> 519.14725 | H85: =2^mRNA.data.anova.results_filtere!H85 -> 359.53789 | I85: =2^mRNA.data.anova.results_filtere!I85 -> 122.78581 | J85: =2^mRNA.data.anova.results_filtere!J85 -> 110.66077 | L85: DFNA21
A86: ATXN1 | B86: 20238 | C86: =2^mRNA.data.anova.results_filtere!C86 -> 464.64981 | D86: =2^mRNA.data.anova.results_filtere!D86 -> 168.89701 | E86: =2^mRNA.data.anova.results_filtere!E86 -> 424.61161 | F86: =2^mRNA.data.anova.results_filtere!F86 -> 319.57262 | G86: =2^mRNA.data.anova.results_filtere!G86 -> 448.82213 | H86: =2^mRNA.data.anova.results_filtere!H86 -> 152.21851 | I86: =2^mRNA.data.anova.results_filtere!I86 -> 448.82213 | J86: =2^mRNA.data.anova.results_filtere!J86 -> 302.33412 | L86: DFNA21
A87: MBOAT1 | B87: 218121 | C87: =2^mRNA.data.anova.results_filtere!C87 -> 136.23938 | D87: =2^mRNA.data.anova.results_filtere!D87 -> 182.27843 | E87: =2^mRNA.data.anova.results_filtere!E87 -> 103.25015 | F87: =2^mRNA.data.anova.results_filtere!F87 -> 96.335792 | G87: =2^mRNA.data.anova.results_filtere!G87 -> 192.67158 | H87: =2^mRNA.data.anova.results_filtere!H87 -> 227.54373 | I87: =2^mRNA.data.anova.results_filtere!I87 -> 114.56321 | J87: =2^mRNA.data.anova.results_filtere!J87 -> 115.36006 | L87: DFNA21
A88: OTX2 | B88: 18424 | C88: =2^mRNA.data.anova.results_filtere!C88 -> 372.21696 | D88: =2^mRNA.data.anova.results_filtere!D88 -> 93.054241 | E88: =2^mRNA.data.anova.results_filtere!E88 -> 95.009509 | F88: =2^mRNA.data.anova.results_filtere!F88 -> 93.054241 | G88: =2^mRNA.data.anova.results_filtere!G88 -> 396.17664 | H88: =2^mRNA.data.anova.results_filtere!H88 -> 89.263595 | I88: =2^mRNA.data.anova.results_filtere!I88 -> 97.00586 | J88: =2^mRNA.data.anova.results_filtere!J88 -> 86.822677 | L88: DFNA23
A89: PRKCH | B89: 18755 | C89: =2^mRNA.data.anova.results_filtere!C89 -> 163.14376 | D89: =2^mRNA.data.anova.results_filtere!D89 -> 99.733066 | E89: =2^mRNA.data.anova.results_filtere!E89 -> 552.56486 | F89: =2^mRNA.data.anova.results_filtere!F89 -> 111.43047 | G89: =2^mRNA.data.anova.results_filtere!G89 -> 122.78581 | H89: =2^mRNA.data.anova.results_filtere!H89 -> 102.53694 | I89: =2^mRNA.data.anova.results_filtere!I89 -> 584.07102 | J89: =2^mRNA.data.anova.results_filtere!J89 -> 102.53694 | L89: DFNA23
A90: SIX1 | B90: 20471 | C90: =2^mRNA.data.anova.results_filtere!C90 -> 1067.4849 | D90: =2^mRNA.data.anova.results_filtere!D90 -> 144.00749 | E90: =2^mRNA.data.anova.results_filtere!E90 -> 97.00586 | F90: =2^mRNA.data.anova.results_filtere!F90 -> 734.18509 | G90: =2^mRNA.data.anova.results_filtere!G90 -> 704.27741 | H90: =2^mRNA.data.anova.results_filtere!H90 -> 116.97043 | I90: =2^mRNA.data.anova.results_filtere!I90 -> 95.670352 | J90: =2^mRNA.data.anova.results_filtere!J90 -> 458.25284 | L90: DFNA23
A91: 3632451O06RIK | B91: 67419 | C91: =2^mRNA.data.anova.results_filtere!C91 -> 136.23938 | D91: =2^mRNA.data.anova.results_filtere!D91 -> 166.57176 | E91: =2^mRNA.data.anova.results_filtere!E91 -> 97.680589 | F91: =2^mRNA.data.anova.results_filtere!F91 -> 259.57363 | G91: =2^mRNA.data.anova.results_filtere!G91 -> 181.01934 | H91: =2^mRNA.data.anova.results_filtere!H91 -> 216.7668 | I91: =2^mRNA.data.anova.results_filtere!I91 -> 97.00586 | J91: =2^mRNA.data.anova.results_filtere!J91 -> 471.13608 | L91: DFNA23
A92: RHOJ | B92: 80837 | C92: =2^mRNA.data.anova.results_filtere!C92 -> 144.00749 | D92: =2^mRNA.data.anova.results_filtere!D92 -> 487.75065 | E92: =2^mRNA.data.anova.results_filtere!E92 -> 1595.7291 | F92: =2^mRNA.data.anova.results_filtere!F92 -> 982.28646 | G92: =2^mRNA.data.anova.results_filtere!G92 -> 143.01275 | H92: =2^mRNA.data.anova.results_filtere!H92 -> 494.5594 | I92: =2^mRNA.data.anova.results_filtere!I92 -> 1389.1628 | J92: =2^mRNA.data.anova.results_filtere!J92 -> 1002.9264 | L92: DFNA23
...

Sheet Differentially exp in M7
A1: probeid | B1: geneid | C1: Cs | D1: Cn | E1: Cb | F1: Cm | G1: Vs | H1: Vn | I1: Vb | J1: Vm | L1: deaf.loci | M1: Matisse module 7
A2: ROBO1 | B2: 19876 | C2: =2^mRNA.data.anova.results_filtere!C34 -> 792.35328 | D2: =2^mRNA.data.anova.results_filtere!D34 -> 190.01902 | E2: =2^mRNA.data.anova.results_filtere!E34 -> 630.34594 | F2: =2^mRNA.data.anova.results_filtere!F34 -> 1152.0599 | G2: =2^mRNA.data.anova.results_filtere!G34 -> 770.68633 | H2: =2^mRNA.data.anova.results_filtere!H34 -> 166.57176 | I2: =2^mRNA.data.anova.results_filtere!I34 -> 298.1718 | J2: =2^mRNA.data.anova.results_filtere!J34 -> 770.68633 | L2: DFNA18 | M2: Yes
A3: EPHB1 | B3: 270190 | C3: =2^mRNA.data.anova.results_filtere!C81 -> 625.99182 | D3: =2^mRNA.data.anova.results_filtere!D81 -> 564.17542 | E3: =2^mRNA.data.anova.results_filtere!E81 -> 474.41309 | F3: =2^mRNA.data.anova.results_filtere!F81 -> 200.85353 | G3: =2^mRNA.data.anova.results_filtere!G81 -> 968.76303 | H3: =2^mRNA.data.anova.results_filtere!H81 -> 533.74247 | I3: =2^mRNA.data.anova.results_filtere!I81 -> 294.06678 | J3: =2^mRNA.data.anova.results_filtere!J81 -> 203.65734 | L3: DFNA18 | M3: Yes
A4: ANPEP | B4: 16790 | C4: =2^mRNA.data.anova.results_filtere!C104 -> 221.32153 | D4: =2^mRNA.data.anova.results_filtere!D104 -> 116.16245 | E4: =2^mRNA.data.anova.results_filtere!E104 -> 95.670352 | F4: =2^mRNA.data.anova.results_filtere!F104 -> 173.64535 | G4: =2^mRNA.data.anova.results_filtere!G104 -> 494.5594 | H4: =2^mRNA.data.anova.results_filtere!H104 -> 131.59857 | I4: =2^mRNA.data.anova.results_filtere!I104 -> 95.009509 | J4: =2^mRNA.data.anova.results_filtere!J104 -> 183.54627 | L4: DFNA30 | M4: Yes
A5: GAD1 | B5: 14415 | C5: =2^mRNA.data.anova.results_filtere!C144 -> 212.3058 | D5: =2^mRNA.data.anova.results_filtere!D144 -> 91.139213 | E5: =2^mRNA.data.anova.results_filtere!E144 -> 94.35323 | F5: =2^mRNA.data.anova.results_filtere!F144 -> 88.647006 | G5: =2^mRNA.data.anova.results_filtere!G144 -> 206.50029 | H5: =2^mRNA.data.anova.results_filtere!H144 -> 91.139213 | I5: =2^mRNA.data.anova.results_filtere!I144 -> 92.411469 | J5: =2^mRNA.data.anova.results_filtere!J144 -> 97.00586 | L5: DFNA43 | M5: Yes
A6: PKP4 | B6: 227937 | C6: =2^mRNA.data.anova.results_filtere!C187 -> 1478.5835 | D6: =2^mRNA.data.anova.results_filtere!D187 -> 227.54373 | E6: =2^mRNA.data.anova.results_filtere!E187 -> 576.02994 | F6: =2^mRNA.data.anova.results_filtere!F187 -> 292.03551 | G6: =2^mRNA.data.anova.results_filtere!G187 -> 657.11406 | H6: =2^mRNA.data.anova.results_filtere!H187 -> 192.67158 | I6: =2^mRNA.data.anova.results_filtere!I187 -> 630.34594 | J6: =2^mRNA.data.anova.results_filtere!J187 -> 415.87323 | L6: DFNA43 | M6: Yes
A7: FOXG1 | B7: 15228 | C7: =2^mRNA.data.anova.results_filtere!C201 -> 1640.5911 | D7: =2^mRNA.data.anova.results_filtere!D201 -> 143.01275 | E7: =2^mRNA.data.anova.results_filtere!E201 -> 96.335792 | F7: =2^mRNA.data.anova.results_filtere!F201 -> 144.00749 | G7: =2^mRNA.data.anova.results_filtere!G201 -> 233.94085 | H7: =2^mRNA.data.anova.results_filtere!H201 -> 88.034676 | I7: =2^mRNA.data.anova.results_filtere!I201 -> 88.034676 | J7: =2^mRNA.data.anova.results_filtere!J201 -> 90.509668 | L7: DFNA53 | M7: Yes
A8: ATP1B1 | B8: 11931 | C8: =2^mRNA.data.anova.results_filtere!C219 -> 3373.4288 | D8: =2^mRNA.data.anova.results_filtere!D219 -> 1200.983 | E8: =2^mRNA.data.anova.results_filtere!E219 -> 212.3058 | F8: =2^mRNA.data.anova.results_filtere!F219 -> 556.40825 | G8: =2^mRNA.data.anova.results_filtere!G219 -> 2336.2841 | H8: =2^mRNA.data.anova.results_filtere!H219 -> 781.44471 | I8: =2^mRNA.data.anova.results_filtere!I219 -> 349.70631 | J8: =2^mRNA.data.anova.results_filtere!J219 -> 955.42578 | L8: DFNA7 | M8: Yes
A9: NME7 | B9: 171567 | C9: =2^mRNA.data.anova.results_filtere!C232 -> 1910.8516 | D9: =2^mRNA.data.anova.results_filtere!D232 -> 885.28612 | E9: =2^mRNA.data.anova.results_filtere!E232 -> 247.2797 | F9: =2^mRNA.data.anova.results_filtere!F232 -> 501.46319 | G9: =2^mRNA.data.anova.results_filtere!G232 -> 1341.8428 | H9: =2^mRNA.data.anova.results_filtere!H232 -> 724.07734 | I9: =2^mRNA.data.anova.results_filtere!I232 -> 317.36517 | J9: =2^mRNA.data.anova.results_filtere!J232 -> 729.1137 | L9: DFNA7 | M9: Yes
A10: PFN2 | B10: 18645 | C10: =2^mRNA.data.anova.results_filtere!C243 -> 942.27215 | D10: =2^mRNA.data.anova.results_filtere!D243 -> 652.57504 | E10: =2^mRNA.data.anova.results_filtere!E243 -> 319.57262 | F10: =2^mRNA.data.anova.results_filtere!F243 -> 873.09813 | G10: =2^mRNA.data.anova.results_filtere!G243 -> 837.53171 | H10: =2^mRNA.data.anova.results_filtere!H243 -> 522.75821 | I10: =2^mRNA.data.anova.results_filtere!I243 -> 344.8918 | J10: =2^mRNA.data.anova.results_filtere!J243 -> 1031.1225 | L10: DFNB15 | M10: Yes
A11: SMARCA5 | B11: 93762 | C11: =2^mRNA.data.anova.results_filtere!C270 -> 1573.7602 | D11: =2^mRNA.data.anova.results_filtere!D270 -> 1722.1559 | E11: =2^mRNA.data.anova.results_filtere!E270 -> 879.17101 | F11: =2^mRNA.data.anova.results_filtere!F270 -> 1663.4929 | G11: =2^mRNA.data.anova.results_filtere!G270 -> 1652.0023 | H11: =2^mRNA.data.anova.results_filtere!H270 -> 1541.3727 | I11: =2^mRNA.data.anova.results_filtere!I270 -> 826.00116 | J11: =2^mRNA.data.anova.results_filtere!J270 -> 1269.4607 | L11: DFNB26 | M11: Yes
A12: EPB4.1L3 | B12: 13823 | C12: =2^mRNA.data.anova.results_filtere!C316 -> 427.56501 | D12: =2^mRNA.data.anova.results_filtere!D316 -> 494.5594 | E12: =2^mRNA.data.anova.results_filtere!E316 -> 103.96831 | F12: =2^mRNA.data.anova.results_filtere!F316 -> 377.41292 | G12: =2^mRNA.data.anova.results_filtere!G316 -> 240.51782 | H12: =2^mRNA.data.anova.results_filtere!H316 -> 467.8817 | I12: =2^mRNA.data.anova.results_filtere!I316 -> 101.82867 | J12: =2^mRNA.data.anova.results_filtere!J316 -> 515.56124 | L12: DFNB46 | M12: Yes
A13: RCN2 | B13: 26611 | C13: =2^mRNA.data.anova.results_filtere!C332 -> 436.54906 | D13: =2^mRNA.data.anova.results_filtere!D332 -> 280.13919 | E13: =2^mRNA.data.anova.results_filtere!E332 -> 210.8393 | F13: =2^mRNA.data.anova.results_filtere!F332 -> 410.14778 | G13: =2^mRNA.data.anova.results_filtere!G332 -> 364.55685 | H13: =2^mRNA.data.anova.results_filtere!H332 -> 227.54373 | I13: =2^mRNA.data.anova.results_filtere!I332 -> 213.78251 | J13: =2^mRNA.data.anova.results_filtere!J332 -> 410.14778 | L13: DFNB48 | M13: Yes
A14: BBS4 | B14: 102774 | C14: =2^mRNA.data.anova.results_filtere!C339 -> 580.03655 | D14: =2^mRNA.data.anova.results_filtere!D339 -> 344.8918 | E14: =2^mRNA.data.anova.results_filtere!E339 -> 233.94085 | F14: =2^mRNA.data.anova.results_filtere!F339 -> 533.74247 | G14: =2^mRNA.data.anova.results_filtere!G339 -> 526.39428 | H14: =2^mRNA.data.anova.results_filtere!H339 -> 328.55703 | I14: =2^mRNA.data.anova.results_filtere!I339 -> 192.67158 | J14: =2^mRNA.data.anova.results_filtere!J339 -> 625.99182 | L14: DFNB48 | M14: Yes
A15: GRIP1 | B15: 74053 | C15: =2^mRNA.data.anova.results_filtere!C381 -> 194.01172 | D15: =2^mRNA.data.anova.results_filtere!D381 -> 140.06959 | E15: =2^mRNA.data.anova.results_filtere!E381 -> 106.1529 | F15: =2^mRNA.data.anova.results_filtere!F381 -> 324.03369 | G15: =2^mRNA.data.anova.results_filtere!G381 -> 218.27453 | H15: =2^mRNA.data.anova.results_filtere!H381 -> 130.68955 | I15: =2^mRNA.data.anova.results_filtere!I381 -> 96.335792 | J15: =2^mRNA.data.anova.results_filtere!J381 -> 261.3791 | L15: DFNB74 | M15: Yes
A17: LECT1 | B17: 16840 | C17: =2^mRNA.data.anova.results_filtere!C2 -> 2005.8528 | D17: =2^mRNA.data.anova.results_filtere!D2 -> 120.25891 | E17: =2^mRNA.data.anova.results_filtere!E2 -> 108.3834 | F17: =2^mRNA.data.anova.results_filtere!F2 -> 106.89125 | G17: =2^mRNA.data.anova.results_filtere!G2 -> 1226.2182 | H17: =2^mRNA.data.anova.results_filtere!H2 -> 106.89125 | I17: =2^mRNA.data.anova.results_filtere!I2 -> 97.00586 | J17: =2^mRNA.data.anova.results_filtere!J2 -> 137.187 | L17: AUNA1 | M17: No
A18: THSD1 | B18: 56229 | C18: =2^mRNA.data.anova.results_filtere!C3 -> 111.43047 | D18: =2^mRNA.data.anova.results_filtere!D3 -> 117.78402 | E18: =2^mRNA.data.anova.results_filtere!E3 -> 709.17605 | F18: =2^mRNA.data.anova.results_filtere!F3 -> 105.41965 | G18: =2^mRNA.data.anova.results_filtere!G3 -> 129.78681 | H18: =2^mRNA.data.anova.results_filtere!H3 -> 116.16245 | I18: =2^mRNA.data.anova.results_filtere!I3 -> 714.10876 | J18: =2^mRNA.data.anova.results_filtere!J3 -> 134.36374 | L18: AUNA1 | M18: No
A19: DIAP3 | B19: 56419 | C19: =2^mRNA.data.anova.results_filtere!C4 -> 106.1529 | D19: =2^mRNA.data.anova.results_filtere!D4 -> 202.25058 | E19: =2^mRNA.data.anova.results_filtere!E4 -> 117.78402 | F19: =2^mRNA.data.anova.results_filtere!F4 -> 101.12529 | G19: =2^mRNA.data.anova.results_filtere!G4 -> 107.63474 | H19: =2^mRNA.data.anova.results_filtere!H4 -> 170.07178 | I19: =2^mRNA.data.anova.results_filtere!I4 -> 117.78402 | J19: =2^mRNA.data.anova.results_filtere!J4 -> 93.701485 | L19: AUNA1 | M19: No
A20: TRIM13 | B20: 66597 | C20: =2^mRNA.data.anova.results_filtere!C5 -> 117.78402 | D20: =2^mRNA.data.anova.results_filtere!D5 -> 218.27453 | E20: =2^mRNA.data.anova.results_filtere!E5 -> 104.69146 | F20: =2^mRNA.data.anova.results_filtere!F5 -> 99.04416 | G20: =2^mRNA.data.anova.results_filtere!G5 -> 112.20553 | H20: =2^mRNA.data.anova.results_filtere!H5 -> 227.54373 | I20: =2^mRNA.data.anova.results_filtere!I5 -> 107.63474 | J20: =2^mRNA.data.anova.results_filtere!J5 -> 104.69146 | L20: AUNA1 | M20: No
A21: P2RY5 | B21: 67168 | C21: =2^mRNA.data.anova.results_filtere!C6 -> 167.73036 | D21: =2^mRNA.data.anova.results_filtere!D6 -> 140.06959 | E21: =2^mRNA.data.anova.results_filtere!E6 -> 533.74247 | F21: =2^mRNA.data.anova.results_filtere!F6 -> 240.51782 | G21: =2^mRNA.data.anova.results_filtere!G6 -> 265.02782 | H21: =2^mRNA.data.anova.results_filtere!H6 -> 136.23938 | I21: =2^mRNA.data.anova.results_filtere!I6 -> 661.68465 | J21: =2^mRNA.data.anova.results_filtere!J6 -> 280.13919 | L21: AUNA1 | M21: No
A22: CAB39L | B22: 69008 | C22: =2^mRNA.data.anova.results_filtere!C7 -> 826.00116 | D22: =2^mRNA.data.anova.results_filtere!D7 -> 657.11406 | E22: =2^mRNA.data.anova.results_filtere!E7 -> 340.14357 | F22: =2^mRNA.data.anova.results_filtere!F7 -> 337.79403 | G22: =2^mRNA.data.anova.results_filtere!G7 -> 643.59085 | H22: =2^mRNA.data.anova.results_filtere!H7 -> 754.82584 | I22: =2^mRNA.data.anova.results_filtere!I7 -> 337.79403 | J22: =2^mRNA.data.anova.results_filtere!J7 -> 312.99591 | L22: AUNA1 | M22: No
A23: CKAP2 | B23: 80986 | C23: =2^mRNA.data.anova.results_filtere!C8 -> 85.627364 | D23: =2^mRNA.data.anova.results_filtere!D8 -> 232.3249 | E23: =2^mRNA.data.anova.results_filtere!E8 -> 308.6868 | F23: =2^mRNA.data.anova.results_filtere!F8 -> 147.03339 | G23: =2^mRNA.data.anova.results_filtere!G8 -> 103.96831 | H23: =2^mRNA.data.anova.results_filtere!H8 -> 235.56804 | I23: =2^mRNA.data.anova.results_filtere!I8 -> 172.4459 | J23: =2^mRNA.data.anova.results_filtere!J8 -> 118.60327 | L23: AUNA1 | M23: No
A24: PCDH17 | B24: 219228 | C24: =2^mRNA.data.anova.results_filtere!C9 -> 430.53896 | D24: =2^mRNA.data.anova.results_filtere!D9 -> 445.72189 | E24: =2^mRNA.data.anova.results_filtere!E9 -> 1698.4464 | F24: =2^mRNA.data.anova.results_filtere!F9 -> 537.45494 | G24: =2^mRNA.data.anova.results_filtere!G9 -> 515.56124 | H24: =2^mRNA.data.anova.results_filtere!H9 -> 484.38152 | I24: =2^mRNA.data.anova.results_filtere!I9 -> 1770.5722 | J24: =2^mRNA.data.anova.results_filtere!J9 -> 315.17297 | L24: AUNA1 | M24: No
A25: PCDH20 | B25: 219257 | C25: =2^mRNA.data.anova.results_filtere!C10 -> 123.63985 | D25: =2^mRNA.data.anova.results_filtere!D10 -> 92.411469 | E25: =2^mRNA.data.anova.results_filtere!E10 -> 88.647006 | F25: =2^mRNA.data.anova.results_filtere!F10 -> 87.426576 | G25: =2^mRNA.data.anova.results_filtere!G10 -> 424.61161 | H25: =2^mRNA.data.anova.results_filtere!H10 -> 148.05609 | I25: =2^mRNA.data.anova.results_filtere!I10 -> 91.773136 | J25: =2^mRNA.data.anova.results_filtere!J10 -> 88.034676 | L25: AUNA1 | M25: No
A26: BMX | B26: 12169 | C26: =2^mRNA.data.anova.results_filtere!C11 -> 96.335792 | D26: =2^mRNA.data.anova.results_filtere!D11 -> 94.35323 | E26: =2^mRNA.data.anova.results_filtere!E11 -> 156.49796 | F26: =2^mRNA.data.anova.results_filtere!F11 -> 93.701485 | G26: =2^mRNA.data.anova.results_filtere!G11 -> 98.360012 | H26: =2^mRNA.data.anova.results_filtere!H11 -> 95.009509 | I26: =2^mRNA.data.anova.results_filtere!I11 -> 230.72012 | J26: =2^mRNA.data.anova.results_filtere!J11 -> 93.054241 | L26: DFN6 | M26: No
A27: GPM6B | B27: 14758 | C27: =2^mRNA.data.anova.results_filtere!C12 -> 584.07102 | D27: =2^mRNA.data.anova.results_filtere!D12 -> 1595.7291 | E27: =2^mRNA.data.anova.results_filtere!E12 -> 298.1718 | F27: =2^mRNA.data.anova.results_filtere!F12 -> 955.42578 | G27: =2^mRNA.data.anova.results_filtere!G12 -> 448.82213 | H27: =2^mRNA.data.anova.results_filtere!H12 -> 1488.8679 | I27: =2^mRNA.data.anova.results_filtere!I12 -> 296.11218 | J27: =2^mRNA.data.anova.results_filtere!J12 -> 1089.9151 | L27: DFN6 | M27: No
A28: RAI2 | B28: 24004 | C28: =2^mRNA.data.anova.results_filtere!C13 -> 237.20654 | D28: =2^mRNA.data.anova.results_filtere!D13 -> 233.94085 | E28: =2^mRNA.data.anova.results_filtere!E13 -> 91.773136 | F28: =2^mRNA.data.anova.results_filtere!F13 -> 430.53896 | G28: =2^mRNA.data.anova.results_filtere!G13 -> 149.0859 | H28: =2^mRNA.data.anova.results_filtere!H13 -> 191.3407 | I28: =2^mRNA.data.anova.results_filtere!I13 -> 113.77186 | J28: =2^mRNA.data.anova.results_filtere!J13 -> 809.0023 | L28: DFN6 | M28: No
... A48: PTPRG | B48: 19270 | C48: =2^mRNA.data.anova.results_filtere!C33 -> 203.65734 | D48: =2^mRNA.data.anova.results_filtere!D33 -> 190.01902 | E48: =2^mRNA.data.anova.results_filtere!E33 -> 410.14778 | F48: =2^mRNA.data.anova.results_filtere!F33 -> 177.29401 | G48: =2^mRNA.data.anova.results_filtere!G33 -> 176.06935 | H48: =2^mRNA.data.anova.results_filtere!H33 -> 149.0859 | I48: =2^mRNA.data.anova.results_filtere!I33 -> 413.00058 | J48: =2^mRNA.data.anova.results_filtere!J33 -> 187.40297 | L48: DFNA18 | M48: No
A49: SEMA3B | B49: 20347 | C49: =2^mRNA.data.anova.results_filtere!C35 -> 182.27843 | D49: =2^mRNA.data.anova.results_filtere!D35 -> 380.03803 | E49: =2^mRNA.data.anova.results_filtere!E35 -> 108.3834 | F49: =2^mRNA.data.anova.results_filtere!F35 -> 99.733066 | G49: =2^mRNA.data.anova.results_filtere!G35 -> 213.78251 | H49: =2^mRNA.data.anova.results_filtere!H35 -> 442.64306 | I49: =2^mRNA.data.anova.results_filtere!I35 -> 108.3834 | J49: =2^mRNA.data.anova.results_filtere!J35 -> 100.42676 | L49: DFNA18 | M49: No
A50: SEMA3F | B50: 20350 | C50: =2^mRNA.data.anova.results_filtere!C36 -> 427.56501 | D50: =2^mRNA.data.anova.results_filtere!D36 -> 112.20553 | E50: =2^mRNA.data.anova.results_filtere!E36 -> 268.72747 | F50: =2^mRNA.data.anova.results_filtere!F36 -> 233.94085 | G50: =2^mRNA.data.anova.results_filtere!G36 -> 256 | H50: =2^mRNA.data.anova.results_filtere!H36 -> 111.43047 | I50: =2^mRNA.data.anova.results_filtere!I36 -> 213.78251 | J50: =2^mRNA.data.anova.results_filtere!J36 -> 304.43702 | L50: DFNA18 | M50: No
A51: SEMA5B | B51: 20357 | C51: =2^mRNA.data.anova.results_filtere!C37 -> 630.34594 | D51: =2^mRNA.data.anova.results_filtere!D37 -> 724.07734 | E51: =2^mRNA.data.anova.results_filtere!E37 -> 102.53694 | F51: =2^mRNA.data.anova.results_filtere!F37 -> 330.84232 | G51: =2^mRNA.data.anova.results_filtere!G37 -> 272.47877 | H51: =2^mRNA.data.anova.results_filtere!H37 -> 630.34594 | I51: =2^mRNA.data.anova.results_filtere!I37 -> 100.42676 | J51: =2^mRNA.data.anova.results_filtere!J37 -> 227.54373 | L51: DFNA18 | M51: No
A52: TRF | B52: 22041 | C52: =2^mRNA.data.anova.results_filtere!C38 -> 97.680589 | D52: =2^mRNA.data.anova.results_filtere!D38 -> 167.73036 | E52: =2^mRNA.data.anova.results_filtere!E38 -> 786.88009 | F52: =2^mRNA.data.anova.results_filtere!F38 -> 167.73036 | G52: =2^mRNA.data.anova.results_filtere!G38 -> 121.93766 | H52: =2^mRNA.data.anova.results_filtere!H38 -> 257.78062 | I52: =2^mRNA.data.anova.results_filtere!I38 -> 504.95114 | J52: =2^mRNA.data.anova.results_filtere!J38 -> 608.87404 | L52: DFNA18 | M52: No
A53: WNT5A | B53: 22418 | C53: =2^mRNA.data.anova.results_filtere!C39 -> 809.0023 | D53: =2^mRNA.data.anova.results_filtere!D39 -> 139.10206 | E53: =2^mRNA.data.anova.results_filtere!E39 -> 98.360012 | F53: =2^mRNA.data.anova.results_filtere!F39 -> 634.73034 | G53: =2^mRNA.data.anova.results_filtere!G39 -> 352.13871 | H53: =2^mRNA.data.anova.results_filtere!H39 -> 163.14376 | I53: =2^mRNA.data.anova.results_filtere!I39 -> 155.41695 | J53: =2^mRNA.data.anova.results_filtere!J39 -> 1305.1501 | L53: DFNA18 | M53: No
A54: FAIM | B54: 23873 | C54: =2^mRNA.data.anova.results_filtere!C40 -> 410.14778 | D54: =2^mRNA.data.anova.results_filtere!D40 -> 364.55685 | E54: =2^mRNA.data.anova.results_filtere!E40 -> 526.39428 | F54: =2^mRNA.data.anova.results_filtere!F40 -> 265.02782 | G54: =2^mRNA.data.anova.results_filtere!G40 -> 377.41292 | H54: =2^mRNA.data.anova.results_filtere!H40 -> 335.46071 | I54: =2^mRNA.data.anova.results_filtere!I40 -> 504.95114 | J54: =2^mRNA.data.anova.results_filtere!J40 -> 290.01827 | L54: DFNA18 | M54: No
A55: NEK4 | B55: 23955 | C55: =2^mRNA.data.anova.results_filtere!C41 -> 458.25284 | D55: =2^mRNA.data.anova.results_filtere!D41 -> 512 | E55: =2^mRNA.data.anova.results_filtere!E41 -> 165.42116 | F55: =2^mRNA.data.anova.results_filtere!F41 -> 413.00058 | G55: =2^mRNA.data.anova.results_filtere!G41 -> 592.22435 | H55: =2^mRNA.data.anova.results_filtere!H41 -> 584.07102 | I55: =2^mRNA.data.anova.results_filtere!I41 -> 245.57161 | J55: =2^mRNA.data.anova.results_filtere!J41 -> 442.64306 | L55: DFNA18 | M55: No
A56: TWF2 | B56: 23999 | C56: =2^mRNA.data.anova.results_filtere!C42 -> 154.3434 | D56: =2^mRNA.data.anova.results_filtere!D42 -> 172.4459 | E56: =2^mRNA.data.anova.results_filtere!E42 -> 306.55455 | F56: =2^mRNA.data.anova.results_filtere!F42 -> 157.58648 | G56: =2^mRNA.data.anova.results_filtere!G42 -> 274.37401 | H56: =2^mRNA.data.anova.results_filtere!H42 -> 142.02489 | I56: =2^mRNA.data.anova.results_filtere!I42 -> 347.29071 | J56: =2^mRNA.data.anova.results_filtere!J42 -> 167.73036 | L56: DFNA18 | M56: No
A57: SLCO2A1 | B57: 24059 | C57: =2^mRNA.data.anova.results_filtere!C43 -> 90.509668 | D57: =2^mRNA.data.anova.results_filtere!D43 -> 92.411469 | E57: =2^mRNA.data.anova.results_filtere!E43 -> 245.57161 | F57: =2^mRNA.data.anova.results_filtere!F43 -> 92.411469 | G57: =2^mRNA.data.anova.results_filtere!G43 -> 243.87533 | H57: =2^mRNA.data.anova.results_filtere!H43 -> 93.701485 | I57: =2^mRNA.data.anova.results_filtere!I43 -> 369.64587 | J57: =2^mRNA.data.anova.results_filtere!J43 -> 121.93766 | L57: DFNA18 | M57: No
A58: IL17RB | B58: 50905 | C58: =2^mRNA.data.anova.results_filtere!C44 -> 132.51391 | D58: =2^mRNA.data.anova.results_filtere!D44 -> 98.360012 | E58: =2^mRNA.data.anova.results_filtere!E44 -> 86.822677 | F58: =2^mRNA.data.anova.results_filtere!F44 -> 95.009509 | G58: =2^mRNA.data.anova.results_filtere!G44 -> 177.29401 | H58: =2^mRNA.data.anova.results_filtere!H44 -> 91.139213 | I58: =2^mRNA.data.anova.results_filtere!I44 -> 93.701485 | J58: =2^mRNA.data.anova.results_filtere!J44 -> 93.054241 | L58: DFNA18 | M58: No
A59: ST3GAL6 | B59: 54613 | C59: =2^mRNA.data.anova.results_filtere!C45 -> 106.89125 | D59: =2^mRNA.data.anova.results_filtere!D45 -> 98.360012 | E59: =2^mRNA.data.anova.results_filtere!E45 -> 477.71289 | F59: =2^mRNA.data.anova.results_filtere!F45 -> 118.60327 | G59: =2^mRNA.data.anova.results_filtere!G45 -> 101.82867 | H59: =2^mRNA.data.anova.results_filtere!H45 -> 95.009509 | I59: =2^mRNA.data.anova.results_filtere!I45 -> 455.08745 | J59: =2^mRNA.data.anova.results_filtere!J45 -> 119.42822 | L59: DFNA18 | M59: No
A60: PDZRN3 | B60: 55983 | C60: =2^mRNA.data.anova.results_filtere!C46 -> 165.42116 | D60: =2^mRNA.data.anova.results_filtere!D46 -> 680.28714 | E60: =2^mRNA.data.anova.results_filtere!E46 -> 112.98598 | F60: =2^mRNA.data.anova.results_filtere!F46 -> 380.03803 | G60: =2^mRNA.data.anova.results_filtere!G46 -> 259.57363 | H60: =2^mRNA.data.anova.results_filtere!H46 -> 519.14725 | I60: =2^mRNA.data.anova.results_filtere!I46 -> 109.89638 | J60: =2^mRNA.data.anova.results_filtere!J46 -> 544.95753 | L60: DFNA18 | M60: No
...

Sheet mRNA.data.anova.results_filtere
A1: probeid | B1: geneid | C1: Cs | D1: Cn | E1: Cb | F1: Cm | G1: Vs | H1: Vn | I1: Vb | J1: Vm | L1: deaf.loci
A2: LECT1 | B2: 16840 | C2: 10.97 | D2: 6.91 | E2: 6.76 | F2: 6.74 | G2: 10.26 | H2: 6.74 | I2: 6.6 | J2: 7.1 | L2: AUNA1
A3: THSD1 | B3: 56229 | C3: 6.8 | D3: 6.88 | E3: 9.47 | F3: 6.72 | G3: 7.02 | H3: 6.86 | I3: 9.48 | J3: 7.07 | L3: AUNA1
A4: DIAP3 | B4: 56419 | C4: 6.73 | D4: 7.66 | E4: 6.88 | F4: 6.66 | G4: 6.75 | H4: 7.41 | I4: 6.88 | J4: 6.55 | L4: AUNA1
A5: TRIM13 | B5: 66597 | C5: 6.88 | D5: 7.77 | E5: 6.71 | F5: 6.63 | G5: 6.81 | H5: 7.83 | I5: 6.75 | J5: 6.71 | L5: AUNA1
A6: P2RY5 | B6: 67168 | C6: 7.39 | D6: 7.13 | E6: 9.06 | F6: 7.91 | G6: 8.05 | H6: 7.09 | I6: 9.37 | J6: 8.13 | L6: AUNA1
A7: CAB39L | B7: 69008 | C7: 9.69 | D7: 9.36 | E7: 8.41 | F7: 8.4 | G7: 9.33 | H7: 9.56 | I7: 8.4 | J7: 8.29 | L7: AUNA1
A8: CKAP2 | B8: 80986 | C8: 6.42 | D8: 7.86 | E8: 8.27 | F8: 7.2 | G8: 6.7 | H8: 7.88 | I8: 7.43 | J8: 6.89 | L8: AUNA1
A9: PCDH17 | B9: 219228 | C9: 8.75 | D9: 8.8 | E9: 10.73 | F9: 9.07 | G9: 9.01 | H9: 8.92 | I9: 10.79 | J9: 8.3 | L9: AUNA1
A10: PCDH20 | B10: 219257 | C10: 6.95 | D10: 6.53 | E10: 6.47 | F10: 6.45 | G10: 8.73 | H10: 7.21 | I10: 6.52 | J10: 6.46 | L10: AUNA1
A11: BMX | B11: 12169 | C11: 6.59 | D11: 6.56 | E11: 7.29 | F11: 6.55 | G11: 6.62 | H11: 6.57 | I11: 7.85 | J11: 6.54 | L11: DFN6
A12: GPM6B | B12: 14758 | C12: 9.19 | D12: 10.64 | E12: 8.22 | F12: 9.9 | G12: 8.81 | H12: 10.54 | I12: 8.21 | J12: 10.09 | L12: DFN6
A13: RAI2 | B13: 24004 | C13: 7.89 | D13: 7.87 | E13: 6.52 | F13: 8.75 | G13: 7.22 | H13: 7.58 | I13: 6.83 | J13: 9.66 | L13: DFN6
... A385: D8ERTD82E | B385: 244418 | C385: 7.37 | D385: 7.78 | E385: 7.63 | F385: 6.89 | G385: 7.46 | H385: 8.09 | I385: 7.73 | J385: 6.83 | L385: DFNM2
