Workbook

Sheet Total per Region
A1: District # | B1: Type | C1: District Name | D1: Metro | E1: EconDev | F1: EconDev
G4: A | H4: B | I4: C | J4: D | K4: E | L4: F | M4: G | N4: H | O4: I | P4: J | Q4: K | R4: L
J9: K FRL | L9: Compensatory | Q9: Funding for | R9: Funding for
G10: Ktotal | H10: K Free | I10: K Reduced | J10: =+"= "&+H4&"+"&+I4 -> = B+C | K10: =+"= "&+J4&"/"&+G4 -> = D/A | L10: Pupil Units | O10: Funding | P10: 8% Admin | Q10: Pathway I | R10: Pathway II
G12: =SUM(G28:G360) -> 61266 | H12: =SUM(H28:H360) -> 21349 | I12: =SUM(I28:I360) -> 4364 | J12: =SUM(J28:J360) -> 23531 | K12: =IF(G12=0,0,J12/G12) -> 0.38407926 | L12: =SUM(L14:L26) -> 10795.958 | N12: 4057 | O12: =23000000-950000 -> 22050000 | P12: =SUM(P14:P26) -> 1764000 | Q12: =SUM(Q14:Q26) -> 10143000 | R12: =(22050000*0.92)/2 -> 10143000
F14: 1 | G14: =SUMIF($F$28:$F$360,$F14,G$28:G$360) -> 1084 | H14: =SUMIF($F$28:$F$360,$F14,H$28:H$360) -> 396 | I14: =SUMIF($F$28:$F$360,$F14,I$28:I$360) -> 121 | J14: =SUMIF($F$28:$F$360,$F14,J$28:J$360) -> 456.5 | K14: =IF(G14=0,0,J14/G14) -> 0.42112546 | L14: ='Region 1'!$K$14 -> 207.68154 | M14: =L14/$L$12 -> 0.019236973 | N14: =$N$12*M14 -> 78.044399 | O14: =M14*$O$12 -> 424175.25 | P14: =O14*0.08 -> 33934.02 | Q14: =(O14-P14)/2 -> 195120.61 | R14: =M14*$Q$12 -> 195120.61
F15: 2 | G15: =SUMIF($F$28:$F$360,$F15,G$28:G$360) -> 1106 | H15: =SUMIF($F$28:$F$360,$F15,H$28:H$360) -> 608 | I15: =SUMIF($F$28:$F$360,$F15,I$28:I$360) -> 98 | J15: =SUMIF($F$28:$F$360,$F15,J$28:J$360) -> 657 | K15: =IF(G15=0,0,J15/G15) -> 0.59403255 | L15: ='Region 2'!$K$14 -> 402.86008 | M15: =L15/$L$12 -> 0.037315827 | N15: =$N$12*M15 -> 151.39031 | O15: =M15*$O$12 -> 822813.98 | P15: =O15*0.08 -> 65825.118 | Q15: =(O15-P15)/2 -> 378494.43 | R15: =M15*$Q$12 -> 378494.43
F16: 3 | G16: =SUMIF($F$28:$F$360,$F16,G$28:G$360) -> 3234 | H16: =SUMIF($F$28:$F$360,$F16,H$28:H$360) -> 1324 | I16: =SUMIF($F$28:$F$360,$F16,I$28:I$360) -> 248 | J16: =SUMIF($F$28:$F$360,$F16,J$28:J$360) -> 1448 | K16: =IF(G16=0,0,J16/G16) -> 0.44774273 | L16: ='Region 3'!$K$14 -> 697.17879 | M16: =L16/$L$12 -> 0.064577763 | N16: =$N$12*M16 -> 261.99199 | O16: =M16*$O$12 -> 1423939.7 | P16: =O16*0.08 -> 113915.17 | Q16: =(O16-P16)/2 -> 655012.25 | R16: =M16*$Q$12 -> 655012.25
F17: 4 | G17: =SUMIF($F$28:$F$360,$F17,G$28:G$360) -> 2521 | H17: =SUMIF($F$28:$F$360,$F17,H$28:H$360) -> 832 | I17: =SUMIF($F$28:$F$360,$F17,I$28:I$360) -> 268 | J17: =SUMIF($F$28:$F$360,$F17,J$28:J$360) -> 966 | K17: =IF(G17=0,0,J17/G17) -> 0.38318128 | L17: ='Region 4'!$K$14 -> 396.07593 | M17: =L17/$L$12 -> 0.036687429 | N17: =$N$12*M17 -> 148.8409 | O17: =M17*$O$12 -> 808957.81 | P17: =O17*0.08 -> 64716.625 | Q17: =(O17-P17)/2 -> 372120.59 | R17: =M17*$Q$12 -> 372120.59
F18: 5 | G18: =SUMIF($F$28:$F$360,$F18,G$28:G$360) -> 1949 | H18: =SUMIF($F$28:$F$360,$F18,H$28:H$360) -> 870 | I18: =SUMIF($F$28:$F$360,$F18,I$28:I$360) -> 220 | J18: =SUMIF($F$28:$F$360,$F18,J$28:J$360) -> 980 | K18: =IF(G18=0,0,J18/G18) -> 0.50282196 | L18: ='Region 5'!$K$14 -> 531.15859 | M18: =L18/$L$12 -> 0.049199766 | N18: =$N$12*M18 -> 199.60345 | O18: =M18*$O$12 -> 1084854.8 | P18: =O18*0.08 -> 86788.388 | Q18: =(O18-P18)/2 -> 499033.23 | R18: =M18*$Q$12 -> 499033.23
F19: 6.1 | G19: =SUMIF($F$28:$F$360,$F19,G$28:G$360) -> 1243 | H19: =SUMIF($F$28:$F$360,$F19,H$28:H$360) -> 512 | I19: =SUMIF($F$28:$F$360,$F19,I$28:I$360) -> 116 | J19: =SUMIF($F$28:$F$360,$F19,J$28:J$360) -> 570 | K19: =IF(G19=0,0,J19/G19) -> 0.45856798 | L19: ='Region 6E'!$K$14 -> 281.41289 | M19: =L19/$L$12 -> 0.026066506 | N19: =$N$12*M19 -> 105.75181 | O19: =M19*$O$12 -> 574766.45 | P19: =O19*0.08 -> 45981.316 | Q19: =(O19-P19)/2 -> 264392.57 | R19: =M19*$Q$12 -> 264392.57
F20: 6.2 | G20: =SUMIF($F$28:$F$360,$F20,G$28:G$360) -> 573 | H20: =SUMIF($F$28:$F$360,$F20,H$28:H$360) -> 216 | I20: =SUMIF($F$28:$F$360,$F20,I$28:I$360) -> 84 | J20: =SUMIF($F$28:$F$360,$F20,J$28:J$360) -> 258 | K20: =IF(G20=0,0,J20/G20) -> 0.45026178 | L20: ='Region 6W'!$K$14 -> 119.08681 | M20: =L20/$L$12 -> 0.011030685 | N20: =$N$12*M20 -> 44.751488 | O20: =M20*$O$12 -> 243226.6 | P20: =O20*0.08 -> 19458.128 | Q20: =(O20-P20)/2 -> 111884.24 | R20: =M20*$Q$12 -> 111884.24
F21: 7.1 | G21: =SUMIF($F$28:$F$360,$F21,G$28:G$360) -> 1928 | H21: =SUMIF($F$28:$F$360,$F21,H$28:H$360) -> 688 | I21: =SUMIF($F$28:$F$360,$F21,I$28:I$360) -> 146 | J21: =SUMIF($F$28:$F$360,$F21,J$28:J$360) -> 761 | K21: =IF(G21=0,0,J21/G21) -> 0.39470954 | L21: ='Region 7E'!$K$14 -> 327.43034 | M21: =L21/$L$12 -> 0.030328976 | N21: =$N$12*M21 -> 123.04466 | O21: =M21*$O$12 -> 668753.93 | P21: =O21*0.08 -> 53500.314 | Q21: =(O21-P21)/2 -> 307626.81 | R21: =M21*$Q$12 -> 307626.81
F22: 7.2 | G22: =SUMIF($F$28:$F$360,$F22,G$28:G$360) -> 5573 | H22: =SUMIF($F$28:$F$360,$F22,H$28:H$360) -> 1434 | I22: =SUMIF($F$28:$F$360,$F22,I$28:I$360) -> 403 | J22: =SUMIF($F$28:$F$360,$F22,J$28:J$360) -> 1635.5 | K22: =IF(G22=0,0,J22/G22) -> 0.29346851 | L22: ='Region 7W'!$K$14 -> 578.42094 | M22: =L22/$L$12 -> 0.053577548 | N22: =$N$12*M22 -> 217.36411 | O22: =M22*$O$12 -> 1181384.9 | P22: =O22*0.08 -> 94510.795 | Q22: =(O22-P22)/2 -> 543437.07 | R22: =M22*$Q$12 -> 543437.07
F23: 8 | G23: =SUMIF($F$28:$F$360,$F23,G$28:G$360) -> 1500 | H23: =SUMIF($F$28:$F$360,$F23,H$28:H$360) -> 624 | I23: =SUMIF($F$28:$F$360,$F23,I$28:I$360) -> 157 | J23: =SUMIF($F$28:$F$360,$F23,J$28:J$360) -> 702.5 | K23: =IF(G23=0,0,J23/G23) -> 0.46833333 | L23: ='Region 8'!$K$14 -> 357.09583 | M23: =L23/$L$12 -> 0.033076809 | N23: =$N$12*M23 -> 134.19261 | O23: =M23*$O$12 -> 729343.64 | P23: =O23*0.08 -> 58347.491 | Q23: =(O23-P23)/2 -> 335498.07 | R23: =M23*$Q$12 -> 335498.07
F24: 9 | G24: =SUMIF($F$28:$F$360,$F24,G$28:G$360) -> 2614 | H24: =SUMIF($F$28:$F$360,$F24,H$28:H$360) -> 954 | I24: =SUMIF($F$28:$F$360,$F24,I$28:I$360) -> 209 | J24: =SUMIF($F$28:$F$360,$F24,J$28:J$360) -> 1058.5 | K24: =IF(G24=0,0,J24/G24) -> 0.40493497 | L24: ='Region 9'!$K$14 -> 449.49911 | M24: =L24/$L$12 -> 0.041635872 | N24: =$N$12*M24 -> 168.91673 | O24: =M24*$O$12 -> 918070.97 | P24: =O24*0.08 -> 73445.678 | Q24: =(O24-P24)/2 -> 422312.65 | R24: =M24*$Q$12 -> 422312.65
F25: 10 | G25: =SUMIF($F$28:$F$360,$F25,G$28:G$360) -> 5481 | H25: =SUMIF($F$28:$F$360,$F25,H$28:H$360) -> 1879 | I25: =SUMIF($F$28:$F$360,$F25,I$28:I$360) -> 406 | J25: =SUMIF($F$28:$F$360,$F25,J$28:J$360) -> 2082 | K25: =IF(G25=0,0,J25/G25) -> 0.37985769 | L25: ='Region 10'!$K$14 -> 882.10684 | M25: =L25/$L$12 -> 0.081707142 | N25: =$N$12*M25 -> 331.48588 | O25: =M25*$O$12 -> 1801642.5 | P25: =O25*0.08 -> 144131.4 | Q25: =(O25-P25)/2 -> 828755.54 | R25: =M25*$Q$12 -> 828755.54
F26: 11 | G26: =SUMIF($F$28:$F$360,$F26,G$28:G$360) -> 32460 | H26: =SUMIF($F$28:$F$360,$F26,H$28:H$360) -> 11012 | I26: =SUMIF($F$28:$F$360,$F26,I$28:I$360) -> 1888 | J26: =SUMIF($F$28:$F$360,$F26,J$28:J$360) -> 11956 | K26: =IF(G26=0,0,J26/G26) -> 0.36833025 | L26: ='Region 11'!$K$14 -> 5565.9499 | M26: =L26/$L$12 -> 0.5155587 | N26: =$N$12*M26 -> 2091.6217 | O26: =M26*$O$12 -> 11368069 | P26: =O26*0.08 -> 909445.55 | Q26: =(O26-P26)/2 -> 5229311.9 | R26: =M26*$Q$12 -> 5229311.9
A28: 1 | B28: 1 | C28: AITKIN PUBLIC SCHOOL DISTRICT | D28: 0 | E28: 03 | F28: 3 | G28: 93 | H28: 39 | I28: 13 | J28: =H28+I28*0.5 -> 45.5 | K28: =IF(G28=0,0,J28/G28) -> 0.48924731
A29: 1.2 | B29: 3 | C29: MINNEAPOLIS PUBLIC SCHOOL DIST. | D29: 1 | E29: 11 | F29: 11 | G29: 3450 | H29: 1992 | I29: 206 | J29: =H29+I29*0.5 -> 2095 | K29: =IF(G29=0,0,J29/G29) -> 0.60724638
A30: 2 | B30: 1 | C30: HILL CITY PUBLIC SCHOOL DISTRICT | D30: 0 | E30: 03 | F30: 3 | G30: 20 | H30: 10 | I30: 1 | J30: =H30+I30*0.5 -> 10.5 | K30: =IF(G30=0,0,J30/G30) -> 0.525
A31: 4 | B31: 1 | C31: MCGREGOR PUBLIC SCHOOL DISTRICT | D31: 0 | E31: 03 | F31: 3 | G31: 39 | H31: 21 | I31: 8 | J31: =H31+I31*0.5 -> 25 | K31: =IF(G31=0,0,J31/G31) -> 0.64102564
A32: 6 | B32: 3 | C32: SOUTH ST. PAUL PUBLIC SCHOOL DIST. | D32: 1 | E32: 11 | F32: 11 | G32: 284 | H32: 111 | I32: 21 | J32: =H32+I32*0.5 -> 121.5 | K32: =IF(G32=0,0,J32/G32) -> 0.4278169
A33: 11 | B33: 1 | C33: ANOKA-HENNEPIN PUBLIC SCHOOL DIST. | D33: 1 | E33: 11 | F33: 11 | G33: 2681 | H33: 763 | I33: 195 | J33: =H33+I33*0.5 -> 860.5 | K33: =IF(G33=0,0,J33/G33) -> 0.32096233
A34: 12 | B34: 1 | C34: CENTENNIAL PUBLIC SCHOOL DISTRICT | D34: 1 | E34: 11 | F34: 11 | G34: 450 | H34: 77 | I34: 17 | J34: =H34+I34*0.5 -> 85.5 | K34: =IF(G34=0,0,J34/G34) -> 0.19
A35: 13 | B35: 1 | C35: COLUMBIA HEIGHTS PUBLIC SCHOOL DIST | D35: 1 | E35: 11 | F35: 11 | G35: 271 | H35: 189 | I35: 27 | J35: =H35+I35*0.5 -> 202.5 | K35: =IF(G35=0,0,J35/G35) -> 0.74723247
A36: 14 | B36: 1 | C36: FRIDLEY PUBLIC SCHOOL DISTRICT | D36: 1 | E36: 11 | F36: 11 | G36: 237 | H36: 143 | I36: 19 | J36: =H36+I36*0.5 -> 152.5 | K36: =IF(G36=0,0,J36/G36) -> 0.64345992
A37: 15 | B37: 1 | C37: ST. FRANCIS PUBLIC SCHOOL DISTRICT | D37: 1 | E37: 11 | F37: 11 | G37: 318 | H37: 66 | I37: 29 | J37: =H37+I37*0.5 -> 80.5 | K37: =IF(G37=0,0,J37/G37) -> 0.25314465
A38: 16 | B38: 1 | C38: SPRING LAKE PARK PUBLIC SCHOOLS | D38: 1 | E38: 11 | F38: 11 | G38: 484 | H38: 134 | I38: 23 | J38: =H38+I38*0.5 -> 145.5 | K38: =IF(G38=0,0,J38/G38) -> 0.30061983
A39: 22 | B39: 1 | C39: DETROIT LAKES PUBLIC SCHOOL DIST. | D39: 0 | E39: 04 | F39: 4 | G39: 225 | H39: 95 | I39: 27 | J39: =H39+I39*0.5 -> 108.5 | K39: =IF(G39=0,0,J39/G39) -> 0.48222222
... A360: 2905 | B360: 1 | C360: TRI-CITY UNITED SCHOOL DISTRICT | D360: 0 | E360: 09 | F360: 9 | G360: 163 | H360: 51 | I360: 10 | J360: =H360+I360*0.5 -> 56 | K360: =IF(G360=0,0,J360/G360) -> 0.34355828

Sheet Region 1
A1: Early Scholars by Region
A3: Inputs: | C3: Compensatory Multiplier | D3: 0.39
E5: A | F5: B | G5: C | H5: D | I5: E | J5: F | K5: G | L5: H | M5: I | N5: J | O5: K | P5: L | Q5: M | R5: N | S5: O
K6: Enrollment | O6: Portion of
H7: Enrollment | J7: Capped | K7: Adjusted | M7: Initial | N7: Cumulative | O7: Available | P7: Pathway II
H8: KGN | J8: Poverty | K8: For Low | M8: Scholarship | N8: Scholarships | O8: Pathway II | P8: Total Amount | Q8: Existence of
E9: Enrollment | F9: Enrollment | G9: Enrollment | H9: Low | I9: Poverty | J9: Portion | K9: Income | L9: Compensatory | M9: Count | N9: Until Cap of | O9: Scholarships | P9: for all 4 Star | Q9: City of 1st Class (C),
E10: KGN | F10: KGN | G10: KGN | H10: Income | I10: Concentration | J10: = Lesser of | K10: Portion | L10: Multiplier | M10: =Greater of | N10: =ROUND(N13,0) -> 78 | O10: After Adjusting | P10: Programs within | Q10: FY13 Scholarships (S), | S10: Parent
A11: District # | B11: Type | C11: District Name | D11: EconDev | E11: Total | F11: Free | G11: Reduced | H11: =E+F*0.5 | I11: =D/A | J11: E or .8 | K11: =D*F | L11: * G | M11: 10 or G | N11: is Reached | O11: for Cap | P11: District Boundary | Q11: or Priority School (P) | R11: County | S11: Aware
N13: ='Total per Region'!N14 -> 78.044399
K14: =SUM(K15:K39) -> 207.68154
A15: 592 | B15: 1 | C15: CLIMAX PUBLIC SCHOOL DISTRICT | D15: 01 | E15: 13 | F15: 8 | G15: 3 | H15: =F15+0.5*G15 -> 9.5 | I15: =H15/E15 -> 0.73076923 | J15: =MIN(I15,0.8) -> 0.73076923 | K15: =J15*H15 -> 6.9423077 | L15: =(0.39)*K15 -> 2.7075 | M15: =MAX(L15,10) -> 10 | N15: =M15 -> 10 | O15: =(N15-N14)/2 -> 5 | P15: =(2*O15)/$N$13*'Total per Region'!$R$14 -> 25001.232 | R15: Polk | S15: 13
A16: 2215 | B16: 1 | C16: NORMAN COUNTY EAST SCHOOL DISTRICT | D16: 01 | E16: 19 | F16: 11 | G16: 3 | H16: =F16+0.5*G16 -> 12.5 | I16: =H16/E16 -> 0.65789474 | J16: =MIN(I16,0.8) -> 0.65789474 | K16: =J16*H16 -> 8.2236842 | L16: =(0.39)*K16 -> 3.2072368 | M16: =MAX(L16,10) -> 10 | N16: =MIN('Total per Region'!$N$14,N15+M16) -> 20 | O16: =(N16-N15)/2 -> 5 | P16: =(2*O16)/$N$13*'Total per Region'!$R$14 -> 25001.232 | R16: Norman | S16: 14
A17: 601 | B17: 1 | C17: FOSSTON PUBLIC SCHOOL DISTRICT | D17: 01 | E17: 44 | F17: 24 | G17: 5 | H17: =F17+0.5*G17 -> 26.5 | I17: =H17/E17 -> 0.60227273 | J17: =MIN(I17,0.8) -> 0.60227273 | K17: =J17*H17 -> 15.960227 | L17: =(0.39)*K17 -> 6.2244886 | M17: =MAX(L17,10) -> 10 | N17: =MIN('Total per Region'!$N$14,N16+M17) -> 30 | O17: =(N17-N16)/2 -> 5 | P17: =(2*O17)/$N$13*'Total per Region'!$R$14 -> 25001.232 | R17: Polk | S17: 14
A18: 2609 | B18: 1 | C18: WIN-E-MAC SCHOOL DISTRICT | D18: 01 | E18: 36 | F18: 19 | G18: 5 | H18: =F18+0.5*G18 -> 21.5 | I18: =H18/E18 -> 0.59722222 | J18: =MIN(I18,0.8) -> 0.59722222 | K18: =J18*H18 -> 12.840278 | L18: =(0.39)*K18 -> 5.0077083 | M18: =MAX(L18,10) -> 10 | N18: =MIN('Total per Region'!$N$14,N17+M18) -> 40 | O18: =(N18-N17)/2 -> 5 | P18: =(2*O18)/$N$13*'Total per Region'!$R$14 -> 25001.232 | R18: Polk | S18: 13
A19: 2527 | B19: 1 | C19: NORMAN COUNTY WEST SCHOOL DISTRICT | D19: 01 | E19: 24 | F19: 11 | G19: 6 | H19: =F19+0.5*G19 -> 14 | I19: =H19/E19 -> 0.58333333 | J19: =MIN(I19,0.8) -> 0.58333333 | K19: =J19*H19 -> 8.1666667 | L19: =(0.39)*K19 -> 3.185 | M19: =MAX(L19,10) -> 10 | N19: =MIN('Total per Region'!$N$14,N18+M19) -> 50 | O19: =(N19-N18)/2 -> 5 | P19: =(2*O19)/$N$13*'Total per Region'!$R$14 -> 25001.232 | R19: Norman | S19: 13
A20: 593 | B20: 1 | C20: CROOKSTON PUBLIC SCHOOL DISTRICT | D20: 01 | E20: 107 | F20: 58 | G20: 8 | H20: =F20+0.5*G20 -> 62 | I20: =H20/E20 -> 0.57943925 | J20: =MIN(I20,0.8) -> 0.57943925 | K20: =J20*H20 -> 35.925234 | L20: =(0.39)*K20 -> 14.010841 | M20: =MAX(L20,10) -> 14.010841 | N20: =MIN('Total per Region'!$N$14,N19+M20) -> 64.010841 | O20: =(N20-N19)/2 -> 7.0054206 | P20: =(2*O20)/$N$13*'Total per Region'!$R$14 -> 35028.83 | R20: Polk | S20: 13
A21: 628 | B21: 1 | C21: PLUMMER PUBLIC SCHOOL DISTRICT | D21: 01 | E21: 34 | F21: 15 | G21: 5 | H21: =F21+0.5*G21 -> 17.5 | I21: =H21/E21 -> 0.51470588 | J21: =MIN(I21,0.8) -> 0.51470588 | K21: =J21*H21 -> 9.0073529 | L21: =(0.39)*K21 -> 3.5128676 | M21: =MAX(L21,10) -> 10 | N21: =MIN('Total per Region'!$N$14,N20+M21) -> 74.010841 | O21: =(N21-N20)/2 -> 5 | P21: =(2*O21)/$N$13*'Total per Region'!$R$14 -> 25001.232 | R21: Red Lake | S21: 14
A22: 690 | B22: 1 | C22: WARROAD PUBLIC SCHOOL DISTRICT | D22: 01 | E22: 66 | F22: 27 | G22: 11 | H22: =F22+0.5*G22 -> 32.5 | I22: =H22/E22 -> 0.49242424 | J22: =MIN(I22,0.8) -> 0.49242424 | K22: =J22*H22 -> 16.003788 | L22: =(0.39)*K22 -> 6.2414773 | M22: =MAX(L22,10) -> 10 | N22: =MIN('Total per Region'!$N$14,N21+M22) -> 78.044399 | O22: =(N22-N21)/2 -> 2.0167787 | P22: =(2*O22)/$N$13*'Total per Region'!$R$14 -> 10084.391 | R22: Roseau | S22: 15
A23: 561 | B23: 1 | C23: GOODRIDGE PUBLIC SCHOOL DISTRICT | D23: 01 | E23: 18 | F23: 8 | G23: 1 | H23: =F23+0.5*G23 -> 8.5 | I23: =H23/E23 -> 0.47222222 | J23: =MIN(I23,0.8) -> 0.47222222 | K23: =J23*H23 -> 4.0138889 | L23: =(0.39)*K23 -> 1.5654167 | M23: =MAX(L23,10) -> 10 | N23: =MIN('Total per Region'!$N$14,N22+M23) -> 78.044399 | O23: =(N23-N22)/2 -> 0 | P23: =(2*O23)/$N$13*'Total per Region'!$R$14 -> 0 | R23: Kittson | S23: 15
A24: 2176 | B24: 1 | C24: WARREN-ALVARADO-OSLO SCHOOL DIST. | D24: 01 | E24: 43 | F24: 17 | G24: 5 | H24: =F24+0.5*G24 -> 19.5 | I24: =H24/E24 -> 0.45348837 | J24: =MIN(I24,0.8) -> 0.45348837 | K24: =J24*H24 -> 8.8430233 | L24: =(0.39)*K24 -> 3.4487791 | M24: =MAX(L24,10) -> 10 | N24: =MIN('Total per Region'!$N$14,N23+M24) -> 78.044399 | O24: =(N24-N23)/2 -> 0 | P24: =(2*O24)/$N$13*'Total per Region'!$R$14 -> 0 | R24: Marshall | S24: 14
A25: 2856 | B25: 1 | C25: STEPHEN-ARGYLE CENTRAL SCHOOLS | D25: 01 | E25: 18 | F25: 8 | G25: 0 | H25: =F25+0.5*G25 -> 8 | I25: =H25/E25 -> 0.44444444 | J25: =MIN(I25,0.8) -> 0.44444444 | K25: =J25*H25 -> 3.5555556 | L25: =(0.39)*K25 -> 1.3866667 | M25: =MAX(L25,10) -> 10 | N25: =MIN('Total per Region'!$N$14,N24+M25) -> 78.044399 | O25: =(N25-N24)/2 -> 0 | P25: =(2*O25)/$N$13*'Total per Region'!$R$14 -> 0 | R25: Marshall | S25: 14
A26: 600 | B26: 1 | C26: FISHER PUBLIC SCHOOL DISTRICT | D26: 01 | E26: 25 | F26: 9 | G26: 4 | H26: =F26+0.5*G26 -> 11 | I26: =H26/E26 -> 0.44 | J26: =MIN(I26,0.8) -> 0.44 | K26: =J26*H26 -> 4.84 | L26: =(0.39)*K26 -> 1.8876 | M26: =MAX(L26,10) -> 10 | N26: =MIN('Total per Region'!$N$14,N25+M26) -> 78.044399 | O26: =(N26-N25)/2 -> 0 | P26: =(2*O26)/$N$13*'Total per Region'!$R$14 -> 0 | R26: Polk | S26: 13
A27: 2358 | B27: 1 | C27: TRI-COUNTY SCHOOL DISTRICT | D27: 01 | E27: 16 | F27: 5 | G27: 3 | H27: =F27+0.5*G27 -> 6.5 | I27: =H27/E27 -> 0.40625 | J27: =MIN(I27,0.8) -> 0.40625 | K27: =J27*H27 -> 2.640625 | L27: =(0.39)*K27 -> 1.0298437 | M27: =MAX(L27,10) -> 10 | N27: =MIN('Total per Region'!$N$14,N26+M27) -> 78.044399 | O27: =(N27-N26)/2 -> 0 | P27: =(2*O27)/$N$13*'Total per Region'!$R$14 -> 0 | R27: Kittson | S27: 15
... A39: 2171 | B39: 1 | C39: KITTSON CENTRAL SCHOOL DISTRICT | D39: 01 | E39: 30 | F39: 5 | G39: 4 | H39: =F39+0.5*G39 -> 7 | I39: =H39/E39 -> 0.23333333 | J39: =MIN(I39,0.8) -> 0.23333333 | K39: =J39*H39 -> 1.6333333 | L39: =(0.39)*K39 -> 0.637 | M39: =MAX(L39,10) -> 10 | N39: =MIN('Total per Region'!$N$14,N38+M39) -> 78.044399 | O39: =(N39-N38)/2 -> 0 | P39: =(2*O39)/$N$13*'Total per Region'!$R$14 -> 0 | R39: Kittson | S39: 15
O40: =SUM(O15:O39) -> 39.022199 | P40: =SUM(P15:P39) -> 195120.61

Sheet Region 2
A1: Early Scholars by Region
A3: Inputs: | C3: Compensatory Multiplier | D3: 0.39
E5: A | F5: B | G5: C | H5: D | I5: E | J5: F | K5: G | L5: H | M5: I | N5: J | O5: K | P5: L | Q5: M | R5: N | S5: O
K6: Enrollment | O6: Portion of
H7: Enrollment | J7: Capped | K7: Adjusted | M7: Initial | N7: Cumulative | O7: Available | P7: Pathway II
H8: KGN | J8: Poverty | K8: For Low | M8: Scholarship | N8: Scholarships | O8: Pathway II | P8: Total Amount | Q8: Existence of
E9: Enrollment | F9: Enrollment | G9: Enrollment | H9: Low | I9: Poverty | J9: Portion | K9: Income | L9: Compensatory | M9: Count | N9: Until Cap of | O9: Scholarships | P9: for all 4 Star | Q9: City of 1st Class (C),
E10: KGN | F10: KGN | G10: KGN | H10: Income | I10: Concentration | J10: = Lesser of | K10: Portion | L10: Multiplier | M10: =Greater of | N10: =ROUND(N13,0) -> 151 | O10: After Adjusting | P10: Programs within | Q10: FY13 Scholarships (S), | S10: Parent
A11: District # | B11: Type | C11: District Name | D11: EconDev | E11: Total | F11: Free | G11: Reduced | H11: =E+F*0.5 | I11: =D/A | J11: E or .8 | K11: =D*F | L11: * G | M11: 10 or G | N11: is Reached | O11: for Cap | P11: District Boundary | Q11: or Priority School (P) | R11: County | S11: Aware
N13: ='Total per Region'!N15 -> 151.39031
K14: =SUM(K15:K62) -> 402.86008
A15: 162 | B15: 1 | C15: BAGLEY PUBLIC SCHOOL DISTRICT | D15: 02 | E15: 100 | F15: 53 | G15: 9 | H15: =F15+0.5*G15 -> 57.5 | I15: =H15/E15 -> 0.575 | J15: =MIN(I15,0.8) -> 0.575 | K15: =J15*H15 -> 33.0625 | L15: =(0.39)*K15 -> 12.894375 | M15: =MAX(L15,10) -> 12.894375 | N15: =M15 -> 12.894375 | O15: =(N15-N14)/2 -> 6.4471875 | P15: =(2*O15)/$N$13*'Total per Region'!$R$15 -> 32237.527 | Q15: S | R15: Clearwater | S15: 12
A16: 2311 | B16: 1 | C16: CLEARBROOK-GONVICK SCHOOL DISTRICT | D16: 02 | E16: 28 | F16: 13 | G16: 4 | H16: =F16+0.5*G16 -> 15 | I16: =H16/E16 -> 0.53571429 | J16: =MIN(I16,0.8) -> 0.53571429 | K16: =J16*H16 -> 8.0357143 | L16: =(0.39)*K16 -> 3.1339286 | M16: =MAX(L16,10) -> 10 | N16: =MIN('Total per Region'!$N$15,N15+M16) -> 22.894375 | O16: =(N16-N15)/2 -> 5 | P16: =(2*O16)/$N$13*'Total per Region'!$R$15 -> 25001.232 | Q16: S | R16: Clearwater | S16: 12
A17: 38 | B17: 1 | C17: RED LAKE PUBLIC SCHOOL DISTRICT | D17: 02 | E17: 169 | F17: 144 | G17: 3 | H17: =F17+0.5*G17 -> 145.5 | I17: =H17/E17 -> 0.86094675 | J17: =MIN(I17,0.8) -> 0.8 | K17: =J17*H17 -> 116.4 | L17: =(0.39)*K17 -> 45.396 | M17: =MAX(L17,10) -> 45.396 | N17: =MIN('Total per Region'!$N$15,N16+M17) -> 68.290375 | O17: =(N17-N16)/2 -> 22.698 | P17: =(2*O17)/$N$13*'Total per Region'!$R$15 -> 113495.59 | Q17: P | R17: Beltrami | S17: 14
A18: 432 | B18: 1 | C18: MAHNOMEN PUBLIC SCHOOL DISTRICT | D18: 02 | E18: 47 | F18: 33 | G18: 2 | H18: =F18+0.5*G18 -> 34 | I18: =H18/E18 -> 0.72340426 | J18: =MIN(I18,0.8) -> 0.72340426 | K18: =J18*H18 -> 24.595745 | L18: =(0.39)*K18 -> 9.5923404 | M18: =MAX(L18,10) -> 10 | N18: =MIN('Total per Region'!$N$15,N17+M18) -> 78.290375 | O18: =(N18-N17)/2 -> 5 | P18: =(2*O18)/$N$13*'Total per Region'!$R$15 -> 25001.232 | Q18: P | R18: Mahnomen | S18: 12
A19: 36 | B19: 1 | C19: KELLIHER PUBLIC SCHOOL DISTRICT | D19: 02 | E19: 20 | F19: 13 | G19: 4 | H19: =F19+0.5*G19 -> 15 | I19: =H19/E19 -> 0.75 | J19: =MIN(I19,0.8) -> 0.75 | K19: =J19*H19 -> 11.25 | L19: =(0.39)*K19 -> 4.3875 | M19: =MAX(L19,10) -> 10 | N19: =MIN('Total per Region'!$N$15,N18+M19) -> 88.290375 | O19: =(N19-N18)/2 -> 5 | P19: =(2*O19)/$N$13*'Total per Region'!$R$15 -> 25001.232 | R19: Beltrami | S19: 14
A20: 435 | B20: 1 | C20: WAUBUN PUBLIC SCHOOL DISTRICT | D20: 02 | E20: 47 | F20: 33 | G20: 4 | H20: =F20+0.5*G20 -> 35 | I20: =H20/E20 -> 0.74468085 | J20: =MIN(I20,0.8) -> 0.74468085 | K20: =J20*H20 -> 26.06383 | L20: =(0.39)*K20 -> 10.164894 | M20: =MAX(L20,10) -> 10.164894 | N20: =MIN('Total per Region'!$N$15,N19+M20) -> 98.455269 | O20: =(N20-N19)/2 -> 5.0824468 | P20: =(2*O20)/$N$13*'Total per Region'!$R$15 -> 25413.487 | R20: Mahnomen | S20: 12
A21: 32 | B21: 1 | C21: BLACKDUCK PUBLIC SCHOOL DISTRICT | D21: 02 | E21: 48 | F21: 27 | G21: 9 | H21: =F21+0.5*G21 -> 31.5 | I21: =H21/E21 -> 0.65625 | J21: =MIN(I21,0.8) -> 0.65625 | K21: =J21*H21 -> 20.671875 | L21: =(0.39)*K21 -> 8.0620313 | M21: =MAX(L21,10) -> 10 | N21: =MIN('Total per Region'!$N$15,N20+M21) -> 108.45527 | O21: =(N21-N20)/2 -> 5 | P21: =(2*O21)/$N$13*'Total per Region'!$R$15 -> 25001.232 | R21: Beltrami | S21: 14
A22: 309 | B22: 1 | C22: PARK RAPIDS PUBLIC SCHOOL DISTRICT | D22: 02 | E22: 125 | F22: 59 | G22: 11 | H22: =F22+0.5*G22 -> 64.5 | I22: =H22/E22 -> 0.516 | J22: =MIN(I22,0.8) -> 0.516 | K22: =J22*H22 -> 33.282 | L22: =(0.39)*K22 -> 12.97998 | M22: =MAX(L22,10) -> 12.97998 | N22: =MIN('Total per Region'!$N$15,N21+M22) -> 121.43525 | O22: =(N22-N21)/2 -> 6.48999 | P22: =(2*O22)/$N$13*'Total per Region'!$R$15 -> 32451.55 | R22: Hubbard | S22: 15
A23: 31 | B23: 1 | C23: BEMIDJI PUBLIC SCHOOL DISTRICT | D23: 02 | E23: 420 | F23: 195 | G23: 40 | H23: =F23+0.5*G23 -> 215 | I23: =H23/E23 -> 0.51190476 | J23: =MIN(I23,0.8) -> 0.51190476 | K23: =J23*H23 -> 110.05952 | L23: =(0.39)*K23 -> 42.923214 | M23: =MAX(L23,10) -> 42.923214 | N23: =MIN('Total per Region'!$N$15,N22+M23) -> 151.39031 | O23: =(N23-N22)/2 -> 14.97753 | P23: =(2*O23)/$N$13*'Total per Region'!$R$15 -> 74891.343 | R23: Beltrami | S23: 14
A24: 308 | B24: 1 | C24: NEVIS PUBLIC SCHOOL DISTRICT | D24: 02 | E24: 42 | F24: 19 | G24: 4 | H24: =F24+0.5*G24 -> 21 | I24: =H24/E24 -> 0.5 | J24: =MIN(I24,0.8) -> 0.5 | K24: =J24*H24 -> 10.5 | L24: =(0.39)*K24 -> 4.095 | M24: =MAX(L24,10) -> 10 | N24: =MIN('Total per Region'!$N$15,N23+M24) -> 151.39031 | O24: =(N24-N23)/2 -> 0 | P24: =(2*O24)/$N$13*'Total per Region'!$R$15 -> 0 | R24: Hubbard | S24: 15
A25: 390 | B25: 1 | C25: LAKE OF THE WOODS SCHOOL DISTRICT | D25: 02 | E25: 37 | F25: 14 | G25: 3 | H25: =F25+0.5*G25 -> 15.5 | I25: =H25/E25 -> 0.41891892 | J25: =MIN(I25,0.8) -> 0.41891892 | K25: =J25*H25 -> 6.4932432 | L25: =(0.39)*K25 -> 2.5323649 | M25: =MAX(L25,10) -> 10 | N25: =MIN('Total per Region'!$N$15,N24+M25) -> 151.39031 | O25: =(N25-N24)/2 -> 0 | P25: =(2*O25)/$N$13*'Total per Region'!$R$15 -> 0 | R25: Lake of the Woods | S25: 15
A26: 306 | B26: 1 | C26: LAPORTE PUBLIC SCHOOL DISTRICT | D26: 02 | E26: 23 | F26: 5 | G26: 5 | H26: =F26+0.5*G26 -> 7.5 | I26: =H26/E26 -> 0.32608696 | J26: =MIN(I26,0.8) -> 0.32608696 | K26: =J26*H26 -> 2.4456522 | L26: =(0.39)*K26 -> 0.95380435 | M26: =MAX(L26,10) -> 10 | N26: =MIN('Total per Region'!$N$15,N25+M26) -> 151.39031 | O26: =(N26-N25)/2 -> 0 | P26: =(2*O26)/$N$13*'Total per Region'!$R$15 -> 0 | R26: Hubbard | S26: 15
O27: =SUM(O15:O26) -> 75.695155 | P27: =SUM(P15:P26) -> 378494.43

Sheet Region 3
A1: Early Scholars by Region
A3: Inputs: | C3: Compensatory Multiplier | D3: 0.39
E5: A | F5: B | G5: C | H5: D | I5: E | J5: F | K5: G | L5: H | M5: I | N5: J | O5: K | P5: L | Q5: M | R5: N | S5: O
K6: Enrollment | O6: Portion of
H7: Enrollment | J7: Capped | K7: Adjusted | M7: Initial | N7: Cumulative | O7: Available | P7: Pathway II
H8: KGN | J8: Poverty | K8: For Low | M8: Scholarship | N8: Scholarships | O8: Pathway II | P8: Total Amount | Q8: Existence of
E9: Enrollment | F9: Enrollment | G9: Enrollment | H9: Low | I9: Poverty | J9: Portion | K9: Income | L9: Compensatory | M9: Count | N9: Until Cap of | O9: Scholarships | P9: for all 4 Star | Q9: City of 1st Class (C),
E10: KGN | F10: KGN | G10: KGN | H10: Income | I10: Concentration | J10: = Lesser of | K10: Portion | L10: Multiplier | M10: =Greater of | N10: =ROUND(N13,0) -> 262 | O10: After Adjusting | P10: Programs within | Q10: FY13 Scholarships (S), | S10: Parent
A11: District # | B11: Type | C11: District Name | D11: EconDev | E11: Total | F11: Free | G11: Reduced | H11: =E+F*0.5 | I11: =D/A | J11: E or .8 | K11: =D*F | L11: * G | M11: 10 or G | N11: is Reached | O11: for Cap | P11: District Boundary | Q11: or Priority School (P) | R11: County | S11: Aware
N13: ='Total per Region'!N16 -> 261.99199
K14: =SUM(K15:K62) -> 697.17879
A15: 319 | B15: 1 | C15: NASHWAUK-KEEWATIN SCHOOL DISTRICT | D15: 3 | E15: 44 | F15: 24 | G15: 0 | H15: =F15+0.5*G15 -> 24 | I15: =H15/E15 -> 0.54545455 | J15: =MIN(I15,0.8) -> 0.54545455 | K15: =J15*H15 -> 13.090909 | L15: =(0.39)*K15 -> 5.1054545 | M15: =MAX(L15,10) -> 10 | N15: =M15 -> 10 | O15: =(N15-N14)/2 -> 5 | P15: =(2*O15)/$N$13*'Total per Region'!$R$16 -> 25001.232 | Q15: P | R15: Itasca | S15: 12
A16: 709 | B16: 1 | C16: DULUTH PUBLIC SCHOOL DISTRICT | D16: 3 | E16: 704 | F16: 333 | G16: 42 | H16: =F16+0.5*G16 -> 354 | I16: =H16/E16 -> 0.50284091 | J16: =MIN(I16,0.8) -> 0.50284091 | K16: =J16*H16 -> 178.00568 | L16: =(0.39)*K16 -> 69.422216 | M16: =MAX(L16,10) -> 69.422216 | N16: =MIN('Total per Region'!$N$16,N15+M16) -> 79.422216 | O16: =(N16-N15)/2 -> 34.711108 | P16: =(2*O16)/$N$13*'Total per Region'!$R$16 -> 173564.1 | Q16: P | R16: St. Louis | S16: 13
A17: 704 | B17: 1 | C17: PROCTOR PUBLIC SCHOOL DISTRICT | D17: 3 | E17: 111 | F17: 20 | G17: 4 | H17: =F17+0.5*G17 -> 22 | I17: =H17/E17 -> 0.1981982 | J17: =MIN(I17,0.8) -> 0.1981982 | K17: =J17*H17 -> 4.3603604 | L17: =(0.39)*K17 -> 1.7005405 | M17: =MAX(L17,10) -> 10 | N17: =MIN('Total per Region'!$N$16,N16+M17) -> 89.422216 | O17: =(N17-N16)/2 -> 5 | P17: =(2*O17)/$N$13*'Total per Region'!$R$16 -> 25001.232 | Q17: P | R17: St. Louis | S17: 13
A18: 707 | B18: 1 | C18: NETT LAKE PUBLIC SCHOOL DISTRICT | D18: 3 | E18: 9 | F18: 6 | G18: 1 | H18: =F18+0.5*G18 -> 6.5 | I18: =H18/E18 -> 0.72222222 | J18: =MIN(I18,0.8) -> 0.72222222 | K18: =J18*H18 -> 4.6944444 | L18: =(0.39)*K18 -> 1.8308333 | M18: =MAX(L18,10) -> 10 | N18: =MIN('Total per Region'!$N$16,N17+M18) -> 99.422216 | O18: =(N18-N17)/2 -> 5 | P18: =(2*O18)/$N$13*'Total per Region'!$R$16 -> 25001.232 | R18: St. Louis | S18: 13
A19: 317 | B19: 1 | C19: DEER RIVER PUBLIC SCHOOL DISTRICT | D19: 3 | E19: 90 | F19: 61 | G19: 6 | H19: =F19+0.5*G19 -> 64 | I19: =H19/E19 -> 0.71111111 | J19: =MIN(I19,0.8) -> 0.71111111 | K19: =J19*H19 -> 45.511111 | L19: =(0.39)*K19 -> 17.749333 | M19: =MAX(L19,10) -> 17.749333 | N19: =MIN('Total per Region'!$N$16,N18+M19) -> 117.17155 | O19: =(N19-N18)/2 -> 8.8746667 | P19: =(2*O19)/$N$13*'Total per Region'!$R$16 -> 44375.521 | R19: Itasca | S19: 12
A20: 4 | B20: 1 | C20: MCGREGOR PUBLIC SCHOOL DISTRICT | D20: 3 | E20: 39 | F20: 21 | G20: 8 | H20: =F20+0.5*G20 -> 25 | I20: =H20/E20 -> 0.64102564 | J20: =MIN(I20,0.8) -> 0.64102564 | K20: =J20*H20 -> 16.025641 | L20: =(0.39)*K20 -> 6.25 | M20: =MAX(L20,10) -> 10 | N20: =MIN('Total per Region'!$N$16,N19+M20) -> 127.17155 | O20: =(N20-N19)/2 -> 5 | P20: =(2*O20)/$N$13*'Total per Region'!$R$16 -> 25001.232 | R20: Aitkin | S20: 15
A21: 701 | B21: 1 | C21: HIBBING PUBLIC SCHOOL DISTRICT | D21: 3 | E21: 212 | F21: 128 | G21: 14 | H21: =F21+0.5*G21 -> 135 | I21: =H21/E21 -> 0.63679245 | J21: =MIN(I21,0.8) -> 0.63679245 | K21: =J21*H21 -> 85.966981 | L21: =(0.39)*K21 -> 33.527123 | M21: =MAX(L21,10) -> 33.527123 | N21: =MIN('Total per Region'!$N$16,N20+M21) -> 160.69867 | O21: =(N21-N20)/2 -> 16.763561 | P21: =(2*O21)/$N$13*'Total per Region'!$R$16 -> 83821.939 | R21: St. Louis | S21: 13
A22: 363 | B22: 1 | C22: SOUTH KOOCHICHING SCHOOL DISTRICT | D22: 3 | E22: 21 | F22: 11 | G22: 2 | H22: =F22+0.5*G22 -> 12 | I22: =H22/E22 -> 0.57142857 | J22: =MIN(I22,0.8) -> 0.57142857 | K22: =J22*H22 -> 6.8571429 | L22: =(0.39)*K22 -> 2.6742857 | M22: =MAX(L22,10) -> 10 | N22: =MIN('Total per Region'!$N$16,N21+M22) -> 170.69867 | O22: =(N22-N21)/2 -> 5 | P22: =(2*O22)/$N$13*'Total per Region'!$R$16 -> 25001.232 | R22: Koochiching | S22: 15
A23: 316 | B23: 1 | C23: GREENWAY PUBLIC SCHOOL DISTRICT | D23: 3 | E23: 79 | F23: 39 | G23: 9 | H23: =F23+0.5*G23 -> 43.5 | I23: =H23/E23 -> 0.55063291 | J23: =MIN(I23,0.8) -> 0.55063291 | K23: =J23*H23 -> 23.952532 | L23: =(0.39)*K23 -> 9.3414873 | M23: =MAX(L23,10) -> 10 | N23: =MIN('Total per Region'!$N$16,N22+M23) -> 180.69867 | O23: =(N23-N22)/2 -> 5 | P23: =(2*O23)/$N$13*'Total per Region'!$R$16 -> 25001.232 | R23: Itasca | S23: 12
A24: 698 | B24: 1 | C24: FLOODWOOD PUBLIC SCHOOL DISTRICT | D24: 3 | E24: 14 | F24: 7 | G24: 1 | H24: =F24+0.5*G24 -> 7.5 | I24: =H24/E24 -> 0.53571429 | J24: =MIN(I24,0.8) -> 0.53571429 | K24: =J24*H24 -> 4.0178571 | L24: =(0.39)*K24 -> 1.5669643 | M24: =MAX(L24,10) -> 10 | N24: =MIN('Total per Region'!$N$16,N23+M24) -> 190.69867 | O24: =(N24-N23)/2 -> 5 | P24: =(2*O24)/$N$13*'Total per Region'!$R$16 -> 25001.232 | R24: St. Louis | S24: 13
A25: 2 | B25: 1 | C25: HILL CITY PUBLIC SCHOOL DISTRICT | D25: 3 | E25: 20 | F25: 10 | G25: 1 | H25: =F25+0.5*G25 -> 10.5 | I25: =H25/E25 -> 0.525 | J25: =MIN(I25,0.8) -> 0.525 | K25: =J25*H25 -> 5.5125 | L25: =(0.39)*K25 -> 2.149875 | M25: =MAX(L25,10) -> 10 | N25: =MIN('Total per Region'!$N$16,N24+M25) -> 200.69867 | O25: =(N25-N24)/2 -> 5 | P25: =(2*O25)/$N$13*'Total per Region'!$R$16 -> 25001.232 | R25: Aitkin | S25: 15
A26: 1 | B26: 1 | C26: AITKIN PUBLIC SCHOOL DISTRICT | D26: 3 | E26: 93 | F26: 39 | G26: 13 | H26: =F26+0.5*G26 -> 45.5 | I26: =H26/E26 -> 0.48924731 | J26: =MIN(I26,0.8) -> 0.48924731 | K26: =J26*H26 -> 22.260753 | L26: =(0.39)*K26 -> 8.6816935 | M26: =MAX(L26,10) -> 10 | N26: =MIN('Total per Region'!$N$16,N25+M26) -> 210.69867 | O26: =(N26-N25)/2 -> 5 | P26: =(2*O26)/$N$13*'Total per Region'!$R$16 -> 25001.232 | R26: Aitkin | S26: 15
A27: 706 | B27: 1 | C27: VIRGINIA PUBLIC SCHOOL DISTRICT | D27: 3 | E27: 168 | F27: 74 | G27: 10 | H27: =F27+0.5*G27 -> 79 | I27: =H27/E27 -> 0.4702381 | J27: =MIN(I27,0.8) -> 0.4702381 | K27: =J27*H27 -> 37.14881 | L27: =(0.39)*K27 -> 14.488036 | M27: =MAX(L27,10) -> 14.488036 | N27: =MIN('Total per Region'!$N$16,N26+M27) -> 225.18671 | O27: =(N27-N26)/2 -> 7.2440179 | P27: =(2*O27)/$N$13*'Total per Region'!$R$16 -> 36221.875 | R27: St. Louis | S27: 13
A28: 100 | B28: 1 | C28: WRENSHALL PUBLIC SCHOOL DISTRICT | D28: 3 | E28: 15 | F28: 5 | G28: 4 | H28: =F28+0.5*G28 -> 7 | I28: =H28/E28 -> 0.46666667 | J28: =MIN(I28,0.8) -> 0.46666667 | K28: =J28*H28 -> 3.2666667 | L28: =(0.39)*K28 -> 1.274 | M28: =MAX(L28,10) -> 10 | N28: =MIN('Total per Region'!$N$16,N27+M28) -> 235.18671 | O28: =(N28-N27)/2 -> 5 | P28: =(2*O28)/$N$13*'Total per Region'!$R$16 -> 25001.232 | R28: Carlton | S28: 14
A29: 361 | B29: 1 | C29: INTERNATIONAL FALLS SCHOOL DISTRICT | D29: 3 | E29: 78 | F29: 31 | G29: 9 | H29: =F29+0.5*G29 -> 35.5 | I29: =H29/E29 -> 0.45512821 | J29: =MIN(I29,0.8) -> 0.45512821 | K29: =J29*H29 -> 16.157051 | L29: =(0.39)*K29 -> 6.30125 | M29: =MAX(L29,10) -> 10 | N29: =MIN('Total per Region'!$N$16,N28+M29) -> 245.18671 | O29: =(N29-N28)/2 -> 5 | P29: =(2*O29)/$N$13*'Total per Region'!$R$16 -> 25001.232 | R29: Koochiching | S29: 15
... A46: 99 | B46: 1 | C46: ESKO PUBLIC SCHOOL DISTRICT | D46: 3 | E46: 85 | F46: 7 | G46: 2 | H46: =F46+0.5*G46 -> 8 | I46: =H46/E46 -> 0.094117647 | J46: =MIN(I46,0.8) -> 0.094117647 | K46: =J46*H46 -> 0.75294118 | L46: =(0.39)*K46 -> 0.29364706 | M46: =MAX(L46,10) -> 10 | N46: =MIN('Total per Region'!$N$16,N45+M46) -> 261.99199 | O46: =(N46-N45)/2 -> 0 | P46: =(2*O46)/$N$13*'Total per Region'!$R$16 -> 0 | R46: Carlton | S46: 14
O47: =SUM(O15:O46) -> 130.99599 | P47: =SUM(P15:P46) -> 655012.25

Sheet Region 4
A1: Early Scholars by Region
A3: Inputs: | C3: Compensatory Multiplier | D3: 0.39
E5: A | F5: B | G5: C | H5: D | I5: E | J5: F | K5: G | L5: H | M5: I | N5: J | O5: K | P5: L | Q5: M | R5: N | S5: O
K6: Enrollment | O6: Portion of
H7: Enrollment | J7: Capped | K7: Adjusted | M7: Initial | N7: Cumulative | O7: Available | P7: Pathway II
H8: KGN | J8: Poverty | K8: For Low | M8: Scholarship | N8: Scholarships | O8: Pathway II | P8: Total Amount | Q8: Existence of
E9: Enrollment | F9: Enrollment | G9: Enrollment | H9: Low | I9: Poverty | J9: Portion | K9: Income | L9: Compensatory | M9: Count | N9: Until Cap of | O9: Scholarships | P9: for all 4 Star | Q9: City of 1st Class (C),
E10: KGN | F10: KGN | G10: KGN | H10: Income | I10: Concentration | J10: = Lesser of | K10: Portion | L10: Multiplier | M10: =Greater of | N10: =ROUND(N13,0) -> 149 | O10: After Adjusting | P10: Programs within | Q10: FY13 Scholarships (S), | S10: Parent
A11: District # | B11: Type | C11: District Name | D11: EconDev | E11: Total | F11: Free | G11: Reduced | H11: =E+F*0.5 | I11: =D/A | J11: E or .8 | K11: =D*F | L11: * G | M11: 10 or G | N11: is Reached | O11: for Cap | P11: District Boundary | Q11: or Priority School (P) | R11: County | S11: Aware
N13: ='Total per Region'!N17 -> 148.8409
K14: =SUM(K15:K62) -> 396.07593
A15: 25 | B15: 1 | C15: PINE POINT PUBLIC SCHOOL DISTRICT | D15: 04 | E15: 10 | F15: 10 | G15: 0 | H15: =F15+0.5*G15 -> 10 | I15: =H15/E15 -> 1 | J15: =MIN(I15,0.8) -> 0.8 | K15: =J15*H15 -> 8 | L15: =(0.39)*K15 -> 3.12 | M15: =MAX(L15,10) -> 10 | N15: =M15 -> 10 | O15: =(N15-N14)/2 -> 5 | P15: =(2*O15)/$N$13*'Total per Region'!$R$17 -> 25001.232 | Q15: S | R15: Becker | S15: 12
A16: 801 | B16: 1 | C16: BROWNS VALLEY PUBLIC SCHOOL DIST. | D16: 04 | E16: 15 | F16: 11 | G16: 2 | H16: =F16+0.5*G16 -> 12 | I16: =H16/E16 -> 0.8 | J16: =MIN(I16,0.8) -> 0.8 | K16: =J16*H16 -> 9.6 | L16: =(0.39)*K16 -> 3.744 | M16: =MAX(L16,10) -> 10 | N16: =MIN('Total per Region'!$N$17,N15+M16) -> 20 | O16: =(N16-N15)/2 -> 5 | P16: =(2*O16)/$N$13*'Total per Region'!$R$17 -> 25001.232 | R16: Traverse | S16: 15
A17: 771 | B17: 1 | C17: CHOKIO-ALBERTA PUBLIC SCHOOL DIST. | D17: 04 | E17: 12 | F17: 7 | G17: 1 | H17: =F17+0.5*G17 -> 7.5 | I17: =H17/E17 -> 0.625 | J17: =MIN(I17,0.8) -> 0.625 | K17: =J17*H17 -> 4.6875 | L17: =(0.39)*K17 -> 1.828125 | M17: =MAX(L17,10) -> 10 | N17: =MIN('Total per Region'!$N$17,N16+M17) -> 30 | O17: =(N17-N16)/2 -> 5 | P17: =(2*O17)/$N$13*'Total per Region'!$R$17 -> 25001.232 | R17: Stevens | S17: 15
A18: 548 | B18: 1 | C18: PELICAN RAPIDS PUBLIC SCHOOL DIST. | D18: 04 | E18: 72 | F18: 39 | G18: 10 | H18: =F18+0.5*G18 -> 44 | I18: =H18/E18 -> 0.61111111 | J18: =MIN(I18,0.8) -> 0.61111111 | K18: =J18*H18 -> 26.888889 | L18: =(0.39)*K18 -> 10.486667 | M18: =MAX(L18,10) -> 10.486667 | N18: =MIN('Total per Region'!$N$17,N17+M18) -> 40.486667 | O18: =(N18-N17)/2 -> 5.2433333 | P18: =(2*O18)/$N$13*'Total per Region'!$R$17 -> 26217.959 | R18: Otter Tail | S18: 14
A19: 550 | B19: 1 | C19: UNDERWOOD PUBLIC SCHOOL DISTRICT | D19: 04 | E19: 39 | F19: 20 | G19: 4 | H19: =F19+0.5*G19 -> 22 | I19: =H19/E19 -> 0.56410256 | J19: =MIN(I19,0.8) -> 0.56410256 | K19: =J19*H19 -> 12.410256 | L19: =(0.39)*K19 -> 4.84 | M19: =MAX(L19,10) -> 10 | N19: =MIN('Total per Region'!$N$17,N18+M19) -> 50.486667 | O19: =(N19-N18)/2 -> 5 | P19: =(2*O19)/$N$13*'Total per Region'!$R$17 -> 25001.232 | R19: Otter Tail | S19: 14
A20: 549 | B20: 1 | C20: PERHAM PUBLIC SCHOOL DISTRICT | D20: 04 | E20: 88 | F20: 38 | G20: 10 | H20: =F20+0.5*G20 -> 43 | I20: =H20/E20 -> 0.48863636 | J20: =MIN(I20,0.8) -> 0.48863636 | K20: =J20*H20 -> 21.011364 | L20: =(0.39)*K20 -> 8.1944318 | M20: =MAX(L20,10) -> 10 | N20: =MIN('Total per Region'!$N$17,N19+M20) -> 60.486667 | O20: =(N20-N19)/2 -> 5 | P20: =(2*O20)/$N$13*'Total per Region'!$R$17 -> 25001.232 | R20: Otter Tail | S20: 14
A21: 22 | B21: 1 | C21: DETROIT LAKES PUBLIC SCHOOL DIST. | D21: 04 | E21: 225 | F21: 95 | G21: 27 | H21: =F21+0.5*G21 -> 108.5 | I21: =H21/E21 -> 0.48222222 | J21: =MIN(I21,0.8) -> 0.48222222 | K21: =J21*H21 -> 52.321111 | L21: =(0.39)*K21 -> 20.405233 | M21: =MAX(L21,10) -> 20.405233 | N21: =MIN('Total per Region'!$N$17,N20+M21) -> 80.8919 | O21: =(N21-N20)/2 -> 10.202617 | P21: =(2*O21)/$N$13*'Total per Region'!$R$17 -> 51015.598 | R21: Becker | S21: 12
A22: 2889 | B22: 1 | C22: LAKE PARK AUDUBON SCHOOL DISTRICT | D22: 04 | E22: 61 | F22: 25 | G22: 7 | H22: =F22+0.5*G22 -> 28.5 | I22: =H22/E22 -> 0.46721311 | J22: =MIN(I22,0.8) -> 0.46721311 | K22: =J22*H22 -> 13.315574 | L22: =(0.39)*K22 -> 5.1930738 | M22: =MAX(L22,10) -> 10 | N22: =MIN('Total per Region'!$N$17,N21+M22) -> 90.8919 | O22: =(N22-N21)/2 -> 5 | P22: =(2*O22)/$N$13*'Total per Region'!$R$17 -> 25001.232 | R22: Becker | S22: 12
A23: 553 | B23: 1 | C23: NEW YORK MILLS PUBLIC SCHOOL DIST. | D23: 04 | E23: 71 | F23: 26 | G23: 13 | H23: =F23+0.5*G23 -> 32.5 | I23: =H23/E23 -> 0.45774648 | J23: =MIN(I23,0.8) -> 0.45774648 | K23: =J23*H23 -> 14.876761 | L23: =(0.39)*K23 -> 5.8019366 | M23: =MAX(L23,10) -> 10 | N23: =MIN('Total per Region'!$N$17,N22+M23) -> 100.8919 | O23: =(N23-N22)/2 -> 5 | P23: =(2*O23)/$N$13*'Total per Region'!$R$17 -> 25001.232 | R23: Otter Tail | S23: 14
A24: 914 | B24: 1 | C24: ULEN-HITTERDAL PUBLIC SCHOOL DIST | D24: 04 | E24: 22 | F24: 9 | G24: 2 | H24: =F24+0.5*G24 -> 10 | I24: =H24/E24 -> 0.45454545 | J24: =MIN(I24,0.8) -> 0.45454545 | K24: =J24*H24 -> 4.5454545 | L24: =(0.39)*K24 -> 1.7727273 | M24: =MAX(L24,10) -> 10 | N24: =MIN('Total per Region'!$N$17,N23+M24) -> 110.8919 | O24: =(N24-N23)/2 -> 5 | P24: =(2*O24)/$N$13*'Total per Region'!$R$17 -> 25001.232 | R24: Otter Tail | S24: 14
A25: 23 | B25: 1 | C25: FRAZEE-VERGAS PUBLIC SCHOOL DIST. | D25: 04 | E25: 72 | F25: 26 | G25: 11 | H25: =F25+0.5*G25 -> 31.5 | I25: =H25/E25 -> 0.4375 | J25: =MIN(I25,0.8) -> 0.4375 | K25: =J25*H25 -> 13.78125 | L25: =(0.39)*K25 -> 5.3746875 | M25: =MAX(L25,10) -> 10 | N25: =MIN('Total per Region'!$N$17,N24+M25) -> 120.8919 | O25: =(N25-N24)/2 -> 5 | P25: =(2*O25)/$N$13*'Total per Region'!$R$17 -> 25001.232 | R25: Becker | S25: 12
A26: 846 | B26: 1 | C26: BRECKENRIDGE PUBLIC SCHOOL DISTRICT | D26: 04 | E26: 45 | F26: 17 | G26: 5 | H26: =F26+0.5*G26 -> 19.5 | I26: =H26/E26 -> 0.43333333 | J26: =MIN(I26,0.8) -> 0.43333333 | K26: =J26*H26 -> 8.45 | L26: =(0.39)*K26 -> 3.2955 | M26: =MAX(L26,10) -> 10 | N26: =MIN('Total per Region'!$N$17,N25+M26) -> 130.8919 | O26: =(N26-N25)/2 -> 5 | P26: =(2*O26)/$N$13*'Total per Region'!$R$17 -> 25001.232 | R26: Wilkin | S26: 15
A27: 850 | B27: 1 | C27: ROTHSAY PUBLIC SCHOOL DISTRICT | D27: 04 | E27: 28 | F27: 11 | G27: 2 | H27: =F27+0.5*G27 -> 12 | I27: =H27/E27 -> 0.42857143 | J27: =MIN(I27,0.8) -> 0.42857143 | K27: =J27*H27 -> 5.1428571 | L27: =(0.39)*K27 -> 2.0057143 | M27: =MAX(L27,10) -> 10 | N27: =MIN('Total per Region'!$N$17,N26+M27) -> 140.8919 | O27: =(N27-N26)/2 -> 5 | P27: =(2*O27)/$N$13*'Total per Region'!$R$17 -> 25001.232 | R27: Wilkin | S27: 15
... A48: 768 | B48: 1 | C48: HANCOCK PUBLIC SCHOOL DISTRICT | D48: 04 | E48: 24 | F48: 2 | G48: 2 | H48: =F48+0.5*G48 -> 3 | I48: =H48/E48 -> 0.125 | J48: =MIN(I48,0.8) -> 0.125 | K48: =J48*H48 -> 0.375 | L48: =(0.39)*K48 -> 0.14625 | M48: =MAX(L48,10) -> 10 | N48: =MIN('Total per Region'!$N$17,N47+M48) -> 148.8409 | O48: =(N48-N47)/2 -> 0 | P48: =(2*O48)/$N$13*'Total per Region'!$R$17 -> 0 | R48: Stevens | S48: 15
O49: =SUM(O15:O48) -> 74.42045 | P49: =SUM(P15:P48) -> 372120.59

Sheet Region 5
A1: Early Scholars by Region
A3: Inputs: | C3: Compensatory Multiplier | D3: 0.39
E5: A | F5: B | G5: C | H5: D | I5: E | J5: F | K5: G | L5: H | M5: I | N5: J | O5: K | P5: L | Q5: M | R5: N | S5: O
K6: Enrollment | O6: Portion of
H7: Enrollment | J7: Capped | K7: Adjusted | M7: Initial | N7: Cumulative | O7: Available | P7: Pathway II
H8: KGN | J8: Poverty | K8: For Low | M8: Scholarship | N8: Scholarships | O8: Pathway II | P8: Total Amount | Q8: Existence of
E9: Enrollment | F9: Enrollment | G9: Enrollment | H9: Low | I9: Poverty | J9: Portion | K9: Income | L9: Compensatory | M9: Count | N9: Until Cap of | O9: Scholarships | P9: for all 4 Star | Q9: City of 1st Class (C),
E10: KGN | F10: KGN | G10: KGN | H10: Income | I10: Concentration | J10: = Lesser of | K10: Portion | L10: Multiplier | M10: =Greater of | N10: =ROUND(N13,0) -> 200 | O10: After Adjusting | P10: Programs within | Q10: FY13 Scholarships (S), | S10: Parent
A11: District # | B11: Type | C11: District Name | D11: EconDev | E11: Total | F11: Free | G11: Reduced | H11: =E+F*0.5 | I11: =D/A | J11: E or .8 | K11: =D*F | L11: * G | M11: 10 or G | N11: is Reached | O11: for Cap | P11: District Boundary | Q11: or Priority School (P) | R11: County | S11: Aware
N13: ='Total per Region'!N18 -> 199.60345
K14: =SUM(K15:K62) -> 531.15859
A15: 115 | B15: 1 | C15: CASS LAKE-BENA PUBLIC SCHOOLS | D15: 05 | E15: 120 | F15: 105 | G15: 1 | H15: =F15+0.5*G15 -> 105.5 | I15: =H15/E15 -> 0.87916667 | J15: =MIN(I15,0.8) -> 0.8 | K15: =J15*H15 -> 84.4 | L15: =(0.39)*K15 -> 32.916 | M15: =MAX(L15,10) -> 32.916 | N15: =M15 -> 32.916 | O15: =(N15-N14)/2 -> 16.458 | P15: =(2*O15)/$N$13*'Total per Region'!$R$18 -> 82294.057 | R15: Cass | S15: 13
A16: 118 | B16: 1 | C16: NORTHLAND COMMUNITY SCHOOLS | D16: 05 | E16: 25 | F16: 19 | G16: 2 | H16: =F16+0.5*G16 -> 20 | I16: =H16/E16 -> 0.8 | J16: =MIN(I16,0.8) -> 0.8 | K16: =J16*H16 -> 16 | L16: =(0.39)*K16 -> 6.24 | M16: =MAX(L16,10) -> 10 | N16: =MIN('Total per Region'!$N$18,N15+M16) -> 42.916 | O16: =(N16-N15)/2 -> 5 | P16: =(2*O16)/$N$13*'Total per Region'!$R$18 -> 25001.232 | R16: Cass | S16: 13
A17: 2174 | B17: 1 | C17: PINE RIVER-BACKUS SCHOOL DISTRICT | D17: 05 | E17: 70 | F17: 41 | G17: 11 | H17: =F17+0.5*G17 -> 46.5 | I17: =H17/E17 -> 0.66428571 | J17: =MIN(I17,0.8) -> 0.66428571 | K17: =J17*H17 -> 30.889286 | L17: =(0.39)*K17 -> 12.046821 | M17: =MAX(L17,10) -> 12.046821 | N17: =MIN('Total per Region'!$N$18,N16+M17) -> 54.962821 | O17: =(N17-N16)/2 -> 6.0234107 | P17: =(2*O17)/$N$13*'Total per Region'!$R$18 -> 30118.538 | R17: Cass | S17: 13
A18: 182 | B18: 1 | C18: CROSBY-IRONTON PUBLIC SCHOOL DIST. | D18: 05 | E18: 96 | F18: 57 | G18: 11 | H18: =F18+0.5*G18 -> 62.5 | I18: =H18/E18 -> 0.65104167 | J18: =MIN(I18,0.8) -> 0.65104167 | K18: =J18*H18 -> 40.690104 | L18: =(0.39)*K18 -> 15.869141 | M18: =MAX(L18,10) -> 15.869141 | N18: =MIN('Total per Region'!$N$18,N17+M18) -> 70.831962 | O18: =(N18-N17)/2 -> 7.9345703 | P18: =(2*O18)/$N$13*'Total per Region'!$R$18 -> 39674.807 | R18: Crow Wing | S18: 14
A19: 786 | B19: 1 | C19: BERTHA-HEWITT PUBLIC SCHOOL DIST. | D19: 05 | E19: 31 | F19: 16 | G19: 7 | H19: =F19+0.5*G19 -> 19.5 | I19: =H19/E19 -> 0.62903226 | J19: =MIN(I19,0.8) -> 0.62903226 | K19: =J19*H19 -> 12.266129 | L19: =(0.39)*K19 -> 4.7837903 | M19: =MAX(L19,10) -> 10 | N19: =MIN('Total per Region'!$N$18,N18+M19) -> 80.831962 | O19: =(N19-N18)/2 -> 5 | P19: =(2*O19)/$N$13*'Total per Region'!$R$18 -> 25001.232 | R19: Todd | S19: 15
A20: 818 | B20: 1 | C20: VERNDALE PUBLIC SCHOOL DISTRICT | D20: 05 | E20: 49 | F20: 26 | G20: 8 | H20: =F20+0.5*G20 -> 30 | I20: =H20/E20 -> 0.6122449 | J20: =MIN(I20,0.8) -> 0.6122449 | K20: =J20*H20 -> 18.367347 | L20: =(0.39)*K20 -> 7.1632653 | M20: =MAX(L20,10) -> 10 | N20: =MIN('Total per Region'!$N$18,N19+M20) -> 90.831962 | O20: =(N20-N19)/2 -> 5 | P20: =(2*O20)/$N$13*'Total per Region'!$R$18 -> 25001.232 | R20: Wadena | S20: 13
A21: 2753 | B21: 1 | C21: LONG PRAIRIE-GREY EAGLE SCHOOL DIST | D21: 05 | E21: 64 | F21: 33 | G21: 11 | H21: =F21+0.5*G21 -> 38.5 | I21: =H21/E21 -> 0.6015625 | J21: =MIN(I21,0.8) -> 0.6015625 | K21: =J21*H21 -> 23.160156 | L21: =(0.39)*K21 -> 9.0324609 | M21: =MAX(L21,10) -> 10 | N21: =MIN('Total per Region'!$N$18,N20+M21) -> 100.83196 | O21: =(N21-N20)/2 -> 5 | P21: =(2*O21)/$N$13*'Total per Region'!$R$18 -> 25001.232 | R21: Todd | S21: 15
A22: 2155 | B22: 1 | C22: WADENA-DEER CREEK SCHOOL DISTRICT | D22: 05 | E22: 87 | F22: 48 | G22: 8 | H22: =F22+0.5*G22 -> 52 | I22: =H22/E22 -> 0.59770115 | J22: =MIN(I22,0.8) -> 0.59770115 | K22: =J22*H22 -> 31.08046 | L22: =(0.39)*K22 -> 12.121379 | M22: =MAX(L22,10) -> 12.121379 | N22: =MIN('Total per Region'!$N$18,N21+M22) -> 112.95334 | O22: =(N22-N21)/2 -> 6.0606897 | P22: =(2*O22)/$N$13*'Total per Region'!$R$18 -> 30304.942 | R22: Wadena | S22: 13
A23: 113 | B23: 1 | C23: WALKER-HACKENSACK-AKELEY SCHL. DIST | D23: 05 | E23: 63 | F23: 33 | G23: 6 | H23: =F23+0.5*G23 -> 36 | I23: =H23/E23 -> 0.57142857 | J23: =MIN(I23,0.8) -> 0.57142857 | K23: =J23*H23 -> 20.571429 | L23: =(0.39)*K23 -> 8.0228571 | M23: =MAX(L23,10) -> 10 | N23: =MIN('Total per Region'!$N$18,N22+M23) -> 122.95334 | O23: =(N23-N22)/2 -> 5 | P23: =(2*O23)/$N$13*'Total per Region'!$R$18 -> 25001.232 | R23: Cass | S23: 13
A24: 2170 | B24: 1 | C24: STAPLES-MOTLEY SCHOOL DISTRICT | D24: 05 | E24: 107 | F24: 55 | G24: 8 | H24: =F24+0.5*G24 -> 59 | I24: =H24/E24 -> 0.55140187 | J24: =MIN(I24,0.8) -> 0.55140187 | K24: =J24*H24 -> 32.53271 | L24: =(0.39)*K24 -> 12.687757 | M24: =MAX(L24,10) -> 12.687757 | N24: =MIN('Total per Region'!$N$18,N23+M24) -> 135.6411 | O24: =(N24-N23)/2 -> 6.3438785 | P24: =(2*O24)/$N$13*'Total per Region'!$R$18 -> 31720.956 | R24: Todd | S24: 15
A25: 482 | B25: 1 | C25: LITTLE FALLS PUBLIC SCHOOL DISTRICT | D25: 05 | E25: 185 | F25: 92 | G25: 18 | H25: =F25+0.5*G25 -> 101 | I25: =H25/E25 -> 0.54594595 | J25: =MIN(I25,0.8) -> 0.54594595 | K25: =J25*H25 -> 55.140541 | L25: =(0.39)*K25 -> 21.504811 | M25: =MAX(L25,10) -> 21.504811 | N25: =MIN('Total per Region'!$N$18,N24+M25) -> 157.14591 | O25: =(N25-N24)/2 -> 10.752405 | P25: =(2*O25)/$N$13*'Total per Region'!$R$18 -> 53764.677 | R25: Morrison | S25: 14
A26: 116 | B26: 1 | C26: PILLAGER PUBLIC SCHOOL DISTRICT | D26: 05 | E26: 74 | F26: 26 | G26: 16 | H26: =F26+0.5*G26 -> 34 | I26: =H26/E26 -> 0.45945946 | J26: =MIN(I26,0.8) -> 0.45945946 | K26: =J26*H26 -> 15.621622 | L26: =(0.39)*K26 -> 6.0924324 | M26: =MAX(L26,10) -> 10 | N26: =MIN('Total per Region'!$N$18,N25+M26) -> 167.14591 | O26: =(N26-N25)/2 -> 5 | P26: =(2*O26)/$N$13*'Total per Region'!$R$18 -> 25001.232 | R26: Cass | S26: 13
A27: 181 | B27: 1 | C27: BRAINERD PUBLIC SCHOOL DISTRICT | D27: 05 | E27: 467 | F27: 180 | G27: 50 | H27: =F27+0.5*G27 -> 205 | I27: =H27/E27 -> 0.43897216 | J27: =MIN(I27,0.8) -> 0.43897216 | K27: =J27*H27 -> 89.989293 | L27: =(0.39)*K27 -> 35.095824 | M27: =MAX(L27,10) -> 35.095824 | N27: =MIN('Total per Region'!$N$18,N26+M27) -> 199.60345 | O27: =(N27-N26)/2 -> 16.228771 | P27: =(2*O27)/$N$13*'Total per Region'!$R$18 -> 81147.856 | R27: Crow Wing | S27: 14
... A36: 186 | B36: 1 | C36: PEQUOT LAKES PUBLIC SCHOOLS | D36: 05 | E36: 111 | F36: 20 | G36: 12 | H36: =F36+0.5*G36 -> 26 | I36: =H36/E36 -> 0.23423423 | J36: =MIN(I36,0.8) -> 0.23423423 | K36: =J36*H36 -> 6.0900901 | L36: =(0.39)*K36 -> 2.3751351 | M36: =MAX(L36,10) -> 10 | N36: =MIN('Total per Region'!$N$18,N35+M36) -> 199.60345 | O36: =(N36-N35)/2 -> 0 | P36: =(2*O36)/$N$13*'Total per Region'!$R$18 -> 0 | R36: Crow Wing | S36: 14
O37: =SUM(O15:O36) -> 99.801726 | P37: =SUM(P15:P36) -> 499033.23

Sheet Region 6E
A1: Early Scholars by Region
A3: Inputs: | C3: Compensatory Multiplier | D3: 0.39
E5: A | F5: B | G5: C | H5: D | I5: E | J5: F | K5: G | L5: H | M5: I | N5: J | O5: K | P5: L | Q5: M | R5: N | S5: O
K6: Enrollment | O6: Portion of
H7: Enrollment | J7: Capped | K7: Adjusted | M7: Initial | N7: Cumulative | O7: Available | P7: Pathway II
H8: KGN | J8: Poverty | K8: For Low | M8: Scholarship | N8: Scholarships | O8: Pathway II | P8: Total Amount | Q8: Existence of
E9: Enrollment | F9: Enrollment | G9: Enrollment | H9: Low | I9: Poverty | J9: Portion | K9: Income | L9: Compensatory | M9: Count | N9: Until Cap of | O9: Scholarships | P9: for all 4 Star | Q9: City of 1st Class (C),
E10: KGN | F10: KGN | G10: KGN | H10: Income | I10: Concentration | J10: = Lesser of | K10: Portion | L10: Multiplier | M10: =Greater of | N10: =ROUND(N13,0) -> 106 | O10: After Adjusting | P10: Programs within | Q10: FY13 Scholarships (S), | S10: Parent
A11: District # | B11: Type | C11: District Name | D11: EconDev | E11: Total | F11: Free | G11: Reduced | H11: =E+F*0.5 | I11: =D/A | J11: E or .8 | K11: =D*F | L11: * G | M11: 10 or G | N11: is Reached | O11: for Cap | P11: District Boundary | Q11: or Priority School (P) | R11: County | S11: Aware
N13: ='Total per Region'!N19 -> 105.75181
K14: =SUM(K15:K62) -> 281.41289
A15: 347 | B15: 1 | C15: WILLMAR PUBLIC SCHOOL DISTRICT | D15: 06E | E15: 333 | F15: 198 | G15: 26 | H15: =F15+0.5*G15 -> 211 | I15: =H15/E15 -> 0.63363363 | J15: =MIN(I15,0.8) -> 0.63363363 | K15: =J15*H15 -> 133.6967 | L15: =(0.39)*K15 -> 52.141712 | M15: =MAX(L15,10) -> 52.141712 | N15: =MIN('Total per Region'!$N$19,N14+M15) -> 52.141712 | O15: =(N15-N14)/2 -> 26.070856 | P15: =(2*O15)/$N$13*'Total per Region'!$R$19 -> 130360.71 | Q15: P | R15: Kandiyohi | S15: 14
A16: 2396 | B16: 1 | C16: A.C.G.C. | D16: 06E | E16: 78 | F16: 30 | G16: 10 | H16: =F16+0.5*G16 -> 35 | I16: =H16/E16 -> 0.44871795 | J16: =MIN(I16,0.8) -> 0.44871795 | K16: =J16*H16 -> 15.705128 | L16: =(0.39)*K16 -> 6.125 | M16: =MAX(L16,10) -> 10 | N16: =MIN('Total per Region'!$N$19,N15+M16) -> 62.141712 | O16: =(N16-N15)/2 -> 5 | P16: =(2*O16)/$N$13*'Total per Region'!$R$19 -> 25001.232 | Q16: P | R16: Meeker | S16: 13
A17: 2890 | B17: 1 | C17: RENVILLE COUNTY WEST SCHOOL DIST. | D17: 06E | E17: 44 | F17: 26 | G17: 3 | H17: =F17+0.5*G17 -> 27.5 | I17: =H17/E17 -> 0.625 | J17: =MIN(I17,0.8) -> 0.625 | K17: =J17*H17 -> 17.1875 | L17: =(0.39)*K17 -> 6.703125 | M17: =MAX(L17,10) -> 10 | N17: =MIN('Total per Region'!$N$19,N16+M17) -> 72.141712 | O17: =(N17-N16)/2 -> 5 | P17: =(2*O17)/$N$13*'Total per Region'!$R$19 -> 25001.232 | R17: Renville | S17: 15
A18: 2534 | B18: 1 | C18: BIRD ISLAND-OLIVIA-LAKE LILLIAN | D18: 06E | E18: 51 | F18: 20 | G18: 10 | H18: =F18+0.5*G18 -> 25 | I18: =H18/E18 -> 0.49019608 | J18: =MIN(I18,0.8) -> 0.49019608 | K18: =J18*H18 -> 12.254902 | L18: =(0.39)*K18 -> 4.7794118 | M18: =MAX(L18,10) -> 10 | N18: =MIN('Total per Region'!$N$19,N17+M18) -> 82.141712 | O18: =(N18-N17)/2 -> 5 | P18: =(2*O18)/$N$13*'Total per Region'!$R$19 -> 25001.232 | R18: Renville | S18: 15
A19: 465 | B19: 1 | C19: LITCHFIELD PUBLIC SCHOOL DISTRICT | D19: 06E | E19: 128 | F19: 51 | G19: 15 | H19: =F19+0.5*G19 -> 58.5 | I19: =H19/E19 -> 0.45703125 | J19: =MIN(I19,0.8) -> 0.45703125 | K19: =J19*H19 -> 26.736328 | L19: =(0.39)*K19 -> 10.427168 | M19: =MAX(L19,10) -> 10.427168 | N19: =MIN('Total per Region'!$N$19,N18+M19) -> 92.56888 | O19: =(N19-N18)/2 -> 5.213584 | P19: =(2*O19)/$N$13*'Total per Region'!$R$19 -> 26069.205 | R19: Meeker | S19: 13
A20: 2859 | B20: 1 | C20: GLENCOE-SILVER LAKE SCHOOL DISTRICT | D20: 06E | E20: 137 | F20: 49 | G20: 16 | H20: =F20+0.5*G20 -> 57 | I20: =H20/E20 -> 0.41605839 | J20: =MIN(I20,0.8) -> 0.41605839 | K20: =J20*H20 -> 23.715328 | L20: =(0.39)*K20 -> 9.2489781 | M20: =MAX(L20,10) -> 10 | N20: =MIN('Total per Region'!$N$19,N19+M20) -> 102.56888 | O20: =(N20-N19)/2 -> 5 | P20: =(2*O20)/$N$13*'Total per Region'!$R$19 -> 25001.232 | R20: McLeod | S20: 15
A21: 463 | B21: 1 | C21: EDEN VALLEY-WATKINS SCHOOL DISTRICT | D21: 06E | E21: 72 | F21: 23 | G21: 10 | H21: =F21+0.5*G21 -> 28 | I21: =H21/E21 -> 0.38888889 | J21: =MIN(I21,0.8) -> 0.38888889 | K21: =J21*H21 -> 10.888889 | L21: =(0.39)*K21 -> 4.2466667 | M21: =MAX(L21,10) -> 10 | N21: =MIN('Total per Region'!$N$19,N20+M21) -> 105.75181 | O21: =(N21-N20)/2 -> 1.5914666 | P21: =(2*O21)/$N$13*'Total per Region'!$R$19 -> 7957.7251 | R21: Meeker | S21: 13
A22: 2159 | B22: 1 | C22: BUFFALO LAKE-HECTOR SCHOOL DISTRICT | D22: 06E | E22: 40 | F22: 14 | G22: 2 | H22: =F22+0.5*G22 -> 15 | I22: =H22/E22 -> 0.375 | J22: =MIN(I22,0.8) -> 0.375 | K22: =J22*H22 -> 5.625 | L22: =(0.39)*K22 -> 2.19375 | M22: =MAX(L22,10) -> 10 | N22: =MIN('Total per Region'!$N$19,N21+M22) -> 105.75181 | O22: =(N22-N21)/2 -> 0 | P22: =(2*O22)/$N$13*'Total per Region'!$R$19 -> 0 | R22: Renville | S22: 15
A23: 423 | B23: 1 | C23: HUTCHINSON PUBLIC SCHOOL DISTRICT | D23: 06E | E23: 214 | F23: 63 | G23: 15 | H23: =F23+0.5*G23 -> 70.5 | I23: =H23/E23 -> 0.32943925 | J23: =MIN(I23,0.8) -> 0.32943925 | K23: =J23*H23 -> 23.225467 | L23: =(0.39)*K23 -> 9.0579322 | M23: =MAX(L23,10) -> 10 | N23: =MIN('Total per Region'!$N$19,N22+M23) -> 105.75181 | O23: =(N23-N22)/2 -> 0 | P23: =(2*O23)/$N$13*'Total per Region'!$R$19 -> 0 | R23: McLeod | S23: 15
A24: 424 | B24: 1 | C24: LESTER PRAIRIE PUBLIC SCHOOL DIST. | D24: 06E | E24: 33 | F24: 10 | G24: 0 | H24: =F24+0.5*G24 -> 10 | I24: =H24/E24 -> 0.3030303 | J24: =MIN(I24,0.8) -> 0.3030303 | K24: =J24*H24 -> 3.030303 | L24: =(0.39)*K24 -> 1.1818182 | M24: =MAX(L24,10) -> 10 | N24: =MIN('Total per Region'!$N$19,N23+M24) -> 105.75181 | O24: =(N24-N23)/2 -> 0 | P24: =(2*O24)/$N$13*'Total per Region'!$R$19 -> 0 | R24: McLeod | S24: 15
A25: 345 | B25: 1 | C25: NEW LONDON-SPICER SCHOOL DISTRICT | D25: 06E | E25: 113 | F25: 28 | G25: 9 | H25: =F25+0.5*G25 -> 32.5 | I25: =H25/E25 -> 0.28761062 | J25: =MIN(I25,0.8) -> 0.28761062 | K25: =J25*H25 -> 9.3473451 | L25: =(0.39)*K25 -> 3.6454646 | M25: =MAX(L25,10) -> 10 | N25: =MIN('Total per Region'!$N$19,N24+M25) -> 105.75181 | O25: =(N25-N24)/2 -> 0 | P25: =(2*O25)/$N$13*'Total per Region'!$R$19 -> 0 | R25: Kandiyohi | S25: 14
O26: =SUM(O15:O25) -> 52.875906 | P26: =SUM(P15:P25) -> 264392.57

Sheet Region 6W
A1: Early Scholars by Region
A3: Inputs: | C3: Compensatory Multiplier | D3: 0.39
E5: A | F5: B | G5: C | H5: D | I5: E | J5: F | K5: G | L5: H | M5: I | N5: J | O5: K | P5: L | Q5: M | R5: N | S5: O
K6: Enrollment | O6: Portion of
H7: Enrollment | J7: Capped | K7: Adjusted | M7: Initial | N7: Cumulative | O7: Available | P7: Pathway II
H8: KGN | J8: Poverty | K8: For Low | M8: Scholarship | N8: Scholarships | O8: Pathway II | P8: Total Amount | Q8: Existence of
E9: Enrollment | F9: Enrollment | G9: Enrollment | H9: Low | I9: Poverty | J9: Portion | K9: Income | L9: Compensatory | M9: Count | N9: Until Cap of | O9: Scholarships | P9: for all 4 Star | Q9: City of 1st Class (C),
E10: KGN | F10: KGN | G10: KGN | H10: Income | I10: Concentration | J10: = Lesser of | K10: Portion | L10: Multiplier | M10: =Greater of | N10: =ROUND(N13,0) -> 45 | O10: After Adjusting | P10: Programs within | Q10: FY13 Scholarships (S), | S10: Parent
A11: District # | B11: Type | C11: District Name | D11: EconDev | E11: Total | F11: Free | G11: Reduced | H11: =E+F*0.5 | I11: =D/A | J11: E or .8 | K11: =D*F | L11: * G | M11: 10 or G | N11: is Reached | O11: for Cap | P11: District Boundary | Q11: or Priority School (P) | R11: County | S11: Aware
N13: ='Total per Region'!N20 -> 44.751488
K14: =SUM(K15:K62) -> 119.08681
A15: 2190 | B15: 1 | C15: YELLOW MEDICINE EAST | D15: 06W | E15: 62 | F15: 36 | G15: 5 | H15: =F15+0.5*G15 -> 38.5 | I15: =H15/E15 -> 0.62096774 | J15: =MIN(I15,0.8) -> 0.62096774 | K15: =J15*H15 -> 23.907258 | L15: =(0.39)*K15 -> 9.3238306 | M15: =MAX(L15,10) -> 10 | N15: =M15 -> 10 | O15: =(N15-N14)/2 -> 5 | P15: =(2*O15)/$N$13*'Total per Region'!$R$20 -> 25001.232 | R15: Yellow Medicine | S15: 14
A16: 775 | B16: 1 | C16: KERKHOVEN-MURDOCK-SUNBURG | D16: 06W | E16: 59 | F16: 25 | G16: 11 | H16: =F16+0.5*G16 -> 30.5 | I16: =H16/E16 -> 0.51694915 | J16: =MIN(I16,0.8) -> 0.51694915 | K16: =J16*H16 -> 15.766949 | L16: =(0.39)*K16 -> 6.1491102 | M16: =MAX(L16,10) -> 10 | N16: =MIN('Total per Region'!$N$20,N15+M16) -> 20 | O16: =(N16-N15)/2 -> 5 | P16: =(2*O16)/$N$13*'Total per Region'!$R$20 -> 25001.232 | R16: Swift | S16: 14
A17: 2180 | B17: 1 | C17: M.A.C.C.R.A.Y. SCHOOL DISTRICT | D17: 06W | E17: 65 | F17: 26 | G17: 7 | H17: =F17+0.5*G17 -> 29.5 | I17: =H17/E17 -> 0.45384615 | J17: =MIN(I17,0.8) -> 0.45384615 | K17: =J17*H17 -> 13.388462 | L17: =(0.39)*K17 -> 5.2215 | M17: =MAX(L17,10) -> 10 | N17: =MIN('Total per Region'!$N$20,N16+M17) -> 30 | O17: =(N17-N16)/2 -> 5 | P17: =(2*O17)/$N$13*'Total per Region'!$R$20 -> 25001.232 | R17: Chippewa | S17: 13
A18: 129 | B18: 1 | C18: MONTEVIDEO PUBLIC SCHOOL DISTRICT | D18: 06W | E18: 103 | F18: 38 | G18: 17 | H18: =F18+0.5*G18 -> 46.5 | I18: =H18/E18 -> 0.45145631 | J18: =MIN(I18,0.8) -> 0.45145631 | K18: =J18*H18 -> 20.992718 | L18: =(0.39)*K18 -> 8.1871602 | M18: =MAX(L18,10) -> 10 | N18: =MIN('Total per Region'!$N$20,N17+M18) -> 40 | O18: =(N18-N17)/2 -> 5 | P18: =(2*O18)/$N$13*'Total per Region'!$R$20 -> 25001.232 | R18: Chippewa | S18: 13
A19: 2903 | B19: 1 | C19: ORTONVILLE PUBLIC SCHOOLS | D19: 06W | E19: 35 | F19: 12 | G19: 5 | H19: =F19+0.5*G19 -> 14.5 | I19: =H19/E19 -> 0.41428571 | J19: =MIN(I19,0.8) -> 0.41428571 | K19: =J19*H19 -> 6.0071429 | L19: =(0.39)*K19 -> 2.3427857 | M19: =MAX(L19,10) -> 10 | N19: =MIN('Total per Region'!$N$20,N18+M19) -> 44.751488 | O19: =(N19-N18)/2 -> 2.3757441 | P19: =(2*O19)/$N$13*'Total per Region'!$R$20 -> 11879.306 | R19: Big Stone | S19: 15
A20: 2853 | B20: 1 | C20: LAC QUI PARLE VALLEY SCHOOL DIST. | D20: 06W | E20: 80 | F20: 27 | G20: 12 | H20: =F20+0.5*G20 -> 33 | I20: =H20/E20 -> 0.4125 | J20: =MIN(I20,0.8) -> 0.4125 | K20: =J20*H20 -> 13.6125 | L20: =(0.39)*K20 -> 5.308875 | M20: =MAX(L20,10) -> 10 | N20: =MIN('Total per Region'!$N$20,N19+M20) -> 44.751488 | O20: =(N20-N19)/2 -> 0 | P20: =(2*O20)/$N$13*'Total per Region'!$R$20 -> 0 | R20: Lac qui Parle | S20: 15
A21: 891 | B21: 1 | C21: CANBY PUBLIC SCHOOL DISTRICT | D21: 06W | E21: 37 | F21: 12 | G21: 6 | H21: =F21+0.5*G21 -> 15 | I21: =H21/E21 -> 0.40540541 | J21: =MIN(I21,0.8) -> 0.40540541 | K21: =J21*H21 -> 6.0810811 | L21: =(0.39)*K21 -> 2.3716216 | M21: =MAX(L21,10) -> 10 | N21: =MIN('Total per Region'!$N$20,N20+M21) -> 44.751488 | O21: =(N21-N20)/2 -> 0 | P21: =(2*O21)/$N$13*'Total per Region'!$R$20 -> 0 | R21: Yellow Medicine | S21: 14
A22: 378 | B22: 1 | C22: DAWSON-BOYD PUBLIC SCHOOL DISTRICT | D22: 06W | E22: 42 | F22: 13 | G22: 7 | H22: =F22+0.5*G22 -> 16.5 | I22: =H22/E22 -> 0.39285714 | J22: =MIN(I22,0.8) -> 0.39285714 | K22: =J22*H22 -> 6.4821429 | L22: =(0.39)*K22 -> 2.5280357 | M22: =MAX(L22,10) -> 10 | N22: =MIN('Total per Region'!$N$20,N21+M22) -> 44.751488 | O22: =(N22-N21)/2 -> 0 | P22: =(2*O22)/$N$13*'Total per Region'!$R$20 -> 0 | R22: Lac qui Parle | S22: 15
A23: 2888 | B23: 1 | C23: CLINTON-GRACEVILLE-BEARDSLEY | D23: 06W | E23: 31 | F23: 9 | G23: 6 | H23: =F23+0.5*G23 -> 12 | I23: =H23/E23 -> 0.38709677 | J23: =MIN(I23,0.8) -> 0.38709677 | K23: =J23*H23 -> 4.6451613 | L23: =(0.39)*K23 -> 1.8116129 | M23: =MAX(L23,10) -> 10 | N23: =MIN('Total per Region'!$N$20,N22+M23) -> 44.751488 | O23: =(N23-N22)/2 -> 0 | P23: =(2*O23)/$N$13*'Total per Region'!$R$20 -> 0 | R23: Big Stone | S23: 15
A24: 777 | B24: 1 | C24: BENSON PUBLIC SCHOOL DISTRICT | D24: 06W | E24: 59 | F24: 18 | G24: 8 | H24: =F24+0.5*G24 -> 22 | I24: =H24/E24 -> 0.37288136 | J24: =MIN(I24,0.8) -> 0.37288136 | K24: =J24*H24 -> 8.2033898 | L24: =(0.39)*K24 -> 3.199322 | M24: =MAX(L24,10) -> 10 | N24: =MIN('Total per Region'!$N$20,N23+M24) -> 44.751488 | O24: =(N24-N23)/2 -> 0 | P24: =(2*O24)/$N$13*'Total per Region'!$R$20 -> 0 | R24: Swift | S24: 14
O25: =SUM(O15:O24) -> 22.375744 | P25: =SUM(P15:P24) -> 111884.24

Sheet Region 7E
A1: Early Scholars by Region
A3: Inputs: | C3: Compensatory Multiplier | D3: 0.39
E5: A | F5: B | G5: C | H5: D | I5: E | J5: F | K5: G | L5: H | M5: I | N5: J | O5: K | P5: L | Q5: M | R5: N | S5: O
K6: Enrollment | O6: Portion of
H7: Enrollment | J7: Capped | K7: Adjusted | M7: Initial | N7: Cumulative | O7: Available | P7: Pathway II
H8: KGN | J8: Poverty | K8: For Low | M8: Scholarship | N8: Scholarships | O8: Pathway II | P8: Total Amount | Q8: Existence of
