Workbook

Sheet Sheet1
A1: Agency | B1: Last Name | C1: First Name | D1: E-mail Address
A2: Bonneville Power Administration | B2: Marino | C2: Stan | D2: SCMARINO@BPA.GOV
A3: Court Services and Offender Supervision Agency | B3: Bein | C3: Joyce | D3: Joyce.Bein@csosa.gov
A4: Court Services and Offender Supervision Agency | B4: Nelson | C4: Susan | D4: susan.nelson@csosa.gov
A5: Court Services and Offender Supervision Agency | B5: Stegman | C5: Wikita | D5: Wikita.Stegman@csosa.gov
A6: International Monetary Fund | B6: Messer | C6: Connie | D6: cmesser@imf.org
A7: International Monetary Fund | B7: Sakach | C7: Stephen | D7: SSakach@imf.org
A8: Medicare Payment Advisory Commission | B8: Broadnax | C8: Rita | D8: rbroadnax@medpac.gov
A9: U.S General Accountability Office | B9: Clements | C9: Michael | D9: clementsmd@gao.gov
A10: U.S. Agency for International Development | B10: Brock | C10: Alfred | D10: ABrock@usaid.gov
A11: U.S. Agency for International Development | B11: Taylor | C11: Nicholas D | D11: nitaylor@usaid.gov
A12: U.S. Commodity Futures Trading Commission | B12: Hamm | C12: Denise | D12: dhamm@cftc.gov
... A201: U.S. Social Security Administration | B201: Hull | C201: Stephen | D201: Stephen.Hull@ssa.gov

Sheet Sheet2

Sheet Sheet3

Sheet DV-IDENTITY-0
A1: =IF(Sheet1!1:1,"RGhoPg3/XQA=",0) -> #VALUE! | B1: =AND(Sheet1!A1,"RGhoPg3/XQE=") -> #VALUE! | C1: =AND(Sheet1!B1,"RGhoPg3/XQI=") -> #VALUE! | D1: =AND(Sheet1!C1,"RGhoPg3/XQM=") -> #VALUE! | E1: =AND(Sheet1!D1,"RGhoPg3/XQQ=") -> #VALUE! | F1: =IF(Sheet1!2:2,"RGhoPg3/XQU=",0) -> 0 | G1: =AND(Sheet1!A2,"RGhoPg3/XQY=") -> #VALUE! | H1: =AND(Sheet1!B2,"RGhoPg3/XQc=") -> #VALUE! | I1: =AND(Sheet1!C2,"RGhoPg3/XQg=") -> #VALUE! | J1: =AND(Sheet1!D2,"RGhoPg3/XQk=") -> #VALUE! | K1: =IF(Sheet1!3:3,"RGhoPg3/XQo=",0) -> 0 | L1: =AND(Sheet1!A3,"RGhoPg3/XQs=") -> #VALUE! | M1: =AND(Sheet1!B3,"RGhoPg3/XQw=") -> #VALUE! | N1: =AND(Sheet1!C3,"RGhoPg3/XQ0=") -> #VALUE! | O1: =AND(Sheet1!D3,"RGhoPg3/XQ4=") -> #VALUE! | P1: =IF(Sheet1!4:4,"RGhoPg3/XQ8=",0) -> 0 | Q1: =AND(Sheet1!A4,"RGhoPg3/XRA=") -> #VALUE! | R1: =AND(Sheet1!B4,"RGhoPg3/XRE=") -> #VALUE! | S1: =AND(Sheet1!C4,"RGhoPg3/XRI=") -> #VALUE! | T1: =AND(Sheet1!D4,"RGhoPg3/XRM=") -> #VALUE! | U1: =IF(Sheet1!5:5,"RGhoPg3/XRQ=",0) -> 0 | V1: =AND(Sheet1!A5,"RGhoPg3/XRU=") -> #VALUE! | W1: =AND(Sheet1!B5,"RGhoPg3/XRY=") -> #VALUE! | X1: =AND(Sheet1!C5,"RGhoPg3/XRc=") -> #VALUE! | Y1: =AND(Sheet1!D5,"RGhoPg3/XRg=") -> #VALUE! | Z1: =IF(Sheet1!6:6,"RGhoPg3/XRk=",0) -> 0 | AA1: =AND(Sheet1!A6,"RGhoPg3/XRo=") -> #VALUE! | AB1: =AND(Sheet1!B6,"RGhoPg3/XRs=") -> #VALUE! | AC1: =AND(Sheet1!C6,"RGhoPg3/XRw=") -> #VALUE! | AD1: =AND(Sheet1!D6,"RGhoPg3/XR0=") -> #VALUE! | AE1: =IF(Sheet1!7:7,"RGhoPg3/XR4=",0) -> 0 | AF1: =AND(Sheet1!A7,"RGhoPg3/XR8=") -> #VALUE! | AG1: =AND(Sheet1!B7,"RGhoPg3/XSA=") -> #VALUE! | AH1: =AND(Sheet1!C7,"RGhoPg3/XSE=") -> #VALUE! | AI1: =AND(Sheet1!D7,"RGhoPg3/XSI=") -> #VALUE! | AJ1: =IF(Sheet1!8:8,"RGhoPg3/XSM=",0) -> 0 | AK1: =AND(Sheet1!A8,"RGhoPg3/XSQ=") -> #VALUE! | AL1: =AND(Sheet1!B8,"RGhoPg3/XSU=") -> #VALUE! | AM1: =AND(Sheet1!C8,"RGhoPg3/XSY=") -> #VALUE! | AN1: =AND(Sheet1!D8,"RGhoPg3/XSc=") -> #VALUE! | AO1: =IF(Sheet1!#REF!,"RGhoPg3/XSg=",0) -> #REF! | AP1: =AND(Sheet1!#REF!,"RGhoPg3/XSk=") -> #REF! | AQ1: =AND(Sheet1!#REF!,"RGhoPg3/XSo=") -> #REF! | AR1: =AND(Sheet1!#REF!,"RGhoPg3/XSs=") -> #REF! | AS1: =AND(Sheet1!#REF!,"RGhoPg3/XSw=") -> #REF! | AT1: =IF(Sheet1!9:9,"RGhoPg3/XS0=",0) -> 0 | AU1: =AND(Sheet1!A9,"RGhoPg3/XS4=") -> #VALUE! | AV1: =AND(Sheet1!B9,"RGhoPg3/XS8=") -> #VALUE! | AW1: =AND(Sheet1!C9,"RGhoPg3/XTA=") -> #VALUE! | AX1: =AND(Sheet1!D9,"RGhoPg3/XTE=") -> #VALUE! | AY1: =IF(Sheet1!10:10,"RGhoPg3/XTI=",0) -> 0 | AZ1: =AND(Sheet1!A10,"RGhoPg3/XTM=") -> #VALUE! | BA1: =AND(Sheet1!B10,"RGhoPg3/XTQ=") -> #VALUE! | BB1: =AND(Sheet1!C10,"RGhoPg3/XTU=") -> #VALUE! | BC1: =AND(Sheet1!D10,"RGhoPg3/XTY=") -> #VALUE! | BD1: =IF(Sheet1!11:11,"RGhoPg3/XTc=",0) -> 0 | BE1: =AND(Sheet1!A11,"RGhoPg3/XTg=") -> #VALUE! | BF1: =AND(Sheet1!B11,"RGhoPg3/XTk=") -> #VALUE! | BG1: =AND(Sheet1!C11,"RGhoPg3/XTo=") -> #VALUE! | BH1: =AND(Sheet1!D11,"RGhoPg3/XTs=") -> #VALUE! | BI1: =IF(Sheet1!12:12,"RGhoPg3/XTw=",0) -> 0 | BJ1: =AND(Sheet1!A12,"RGhoPg3/XT0=") -> #VALUE! | BK1: =AND(Sheet1!B12,"RGhoPg3/XT4=") -> #VALUE! | BL1: =AND(Sheet1!C12,"RGhoPg3/XT8=") -> #VALUE! | BM1: =AND(Sheet1!D12,"RGhoPg3/XUA=") -> #VALUE! | BN1: =IF(Sheet1!13:13,"RGhoPg3/XUE=",0) -> 0 | BO1: =AND(Sheet1!A13,"RGhoPg3/XUI=") -> #VALUE! | BP1: =AND(Sheet1!B13,"RGhoPg3/XUM=") -> #VALUE! | BQ1: =AND(Sheet1!C13,"RGhoPg3/XUQ=") -> #VALUE! | BR1: =AND(Sheet1!D13,"RGhoPg3/XUU=") -> #VALUE! | BS1: =IF(Sheet1!14:14,"RGhoPg3/XUY=",0) -> 0 | BT1: =AND(Sheet1!A14,"RGhoPg3/XUc=") -> #VALUE! | BU1: =AND(Sheet1!B14,"RGhoPg3/XUg=") -> #VALUE! | BV1: =AND(Sheet1!C14,"RGhoPg3/XUk=") -> #VALUE! | BW1: =AND(Sheet1!D14,"RGhoPg3/XUo=") -> #VALUE! | BX1: =IF(Sheet1!15:15,"RGhoPg3/XUs=",0) -> 0 | BY1: =AND(Sheet1!A15,"RGhoPg3/XUw=") -> #VALUE! | BZ1: =AND(Sheet1!B15,"RGhoPg3/XU0=") -> #VALUE! | CA1: =AND(Sheet1!C15,"RGhoPg3/XU4=") -> #VALUE! | CB1: =AND(Sheet1!D15,"RGhoPg3/XU8=") -> #VALUE! | CC1: =IF(Sheet1!16:16,"RGhoPg3/XVA=",0) -> 0 | CD1: =AND(Sheet1!A16,"RGhoPg3/XVE=") -> #VALUE! | CE1: =AND(Sheet1!B16,"RGhoPg3/XVI=") -> #VALUE! | CF1: =AND(Sheet1!C16,"RGhoPg3/XVM=") -> #VALUE! | CG1: =AND(Sheet1!D16,"RGhoPg3/XVQ=") -> #VALUE! | CH1: =IF(Sheet1!17:17,"RGhoPg3/XVU=",0) -> 0 | CI1: =AND(Sheet1!A17,"RGhoPg3/XVY=") -> #VALUE! | CJ1: =AND(Sheet1!B17,"RGhoPg3/XVc=") -> #VALUE! | CK1: =AND(Sheet1!C17,"RGhoPg3/XVg=") -> #VALUE! | CL1: =AND(Sheet1!D17,"RGhoPg3/XVk=") -> #VALUE! | CM1: =IF(Sheet1!18:18,"RGhoPg3/XVo=",0) -> 0 | CN1: =AND(Sheet1!A18,"RGhoPg3/XVs=") -> #VALUE! | CO1: =AND(Sheet1!B18,"RGhoPg3/XVw=") -> #VALUE! | CP1: =AND(Sheet1!C18,"RGhoPg3/XV0=") -> #VALUE! | CQ1: =AND(Sheet1!D18,"RGhoPg3/XV4=") -> #VALUE! | CR1: =IF(Sheet1!#REF!,"RGhoPg3/XV8=",0) -> #REF! | CS1: =AND(Sheet1!#REF!,"RGhoPg3/XWA=") -> #REF! | CT1: =AND(Sheet1!#REF!,"RGhoPg3/XWE=") -> #REF! | CU1: =AND(Sheet1!#REF!,"RGhoPg3/XWI=") -> #REF! | CV1: =AND(Sheet1!#REF!,"RGhoPg3/XWM=") -> #REF! | CW1: =IF(Sheet1!#REF!,"RGhoPg3/XWQ=",0) -> #REF! | CX1: =AND(Sheet1!#REF!,"RGhoPg3/XWU=") -> #REF! | CY1: =AND(Sheet1!#REF!,"RGhoPg3/XWY=") -> #REF! | CZ1: =AND(Sheet1!#REF!,"RGhoPg3/XWc=") -> #REF! | DA1: =AND(Sheet1!#REF!,"RGhoPg3/XWg=") -> #REF! | DB1: =IF(Sheet1!#REF!,"RGhoPg3/XWk=",0) -> #REF! | DC1: =AND(Sheet1!#REF!,"RGhoPg3/XWo=") -> #REF! | DD1: =AND(Sheet1!#REF!,"RGhoPg3/XWs=") -> #REF! | DE1: =AND(Sheet1!#REF!,"RGhoPg3/XWw=") -> #REF! | DF1: =AND(Sheet1!#REF!,"RGhoPg3/XW0=") -> #REF! | DG1: =IF(Sheet1!20:20,"RGhoPg3/XW4=",0) -> 0 | DH1: =AND(Sheet1!A20,"RGhoPg3/XW8=") -> #VALUE! | DI1: =AND(Sheet1!B20,"RGhoPg3/XXA=") -> #VALUE! | DJ1: =AND(Sheet1!C20,"RGhoPg3/XXE=") -> #VALUE! | DK1: =AND(Sheet1!D20,"RGhoPg3/XXI=") -> #VALUE! | DL1: =IF(Sheet1!21:21,"RGhoPg3/XXM=",0) -> 0 | DM1: =AND(Sheet1!A21,"RGhoPg3/XXQ=") -> #VALUE! | DN1: =AND(Sheet1!B21,"RGhoPg3/XXU=") -> #VALUE! | DO1: =AND(Sheet1!C21,"RGhoPg3/XXY=") -> #VALUE! | DP1: =AND(Sheet1!D21,"RGhoPg3/XXc=") -> #VALUE! | DQ1: =IF(Sheet1!22:22,"RGhoPg3/XXg=",0) -> 0 | DR1: =AND(Sheet1!A22,"RGhoPg3/XXk=") -> #VALUE! | DS1: =AND(Sheet1!B22,"RGhoPg3/XXo=") -> #VALUE! | DT1: =AND(Sheet1!C22,"RGhoPg3/XXs=") -> #VALUE! | DU1: =AND(Sheet1!D22,"RGhoPg3/XXw=") -> #VALUE! | DV1: =IF(Sheet1!#REF!,"RGhoPg3/XX0=",0) -> #REF! | DW1: =AND(Sheet1!#REF!,"RGhoPg3/XX4=") -> #REF! | DX1: =AND(Sheet1!#REF!,"RGhoPg3/XX8=") -> #REF! | DY1: =AND(Sheet1!#REF!,"RGhoPg3/XYA=") -> #REF! | DZ1: =AND(Sheet1!#REF!,"RGhoPg3/XYE=") -> #REF! | EA1: =IF(Sheet1!#REF!,"RGhoPg3/XYI=",0) -> #REF! | EB1: =AND(Sheet1!#REF!,"RGhoPg3/XYM=") -> #REF! | EC1: =AND(Sheet1!#REF!,"RGhoPg3/XYQ=") -> #REF! | ED1: =AND(Sheet1!#REF!,"RGhoPg3/XYU=") -> #REF! | EE1: =AND(Sheet1!#REF!,"RGhoPg3/XYY=") -> #REF! | EF1: =IF(Sheet1!23:23,"RGhoPg3/XYc=",0) -> 0 | EG1: =AND(Sheet1!A23,"RGhoPg3/XYg=") -> #VALUE! | EH1: =AND(Sheet1!B23,"RGhoPg3/XYk=") -> #VALUE! | EI1: =AND(Sheet1!C23,"RGhoPg3/XYo=") -> #VALUE! | EJ1: =AND(Sheet1!D23,"RGhoPg3/XYs=") -> #VALUE! | EK1: =IF(Sheet1!24:24,"RGhoPg3/XYw=",0) -> 0 | EL1: =AND(Sheet1!A24,"RGhoPg3/XY0=") -> #VALUE! | EM1: =AND(Sheet1!B24,"RGhoPg3/XY4=") -> #VALUE! | EN1: =AND(Sheet1!C24,"RGhoPg3/XY8=") -> #VALUE! | EO1: =AND(Sheet1!D24,"RGhoPg3/XZA=") -> #VALUE! | EP1: =IF(Sheet1!26:26,"RGhoPg3/XZE=",0) -> 0 | EQ1: =AND(Sheet1!A26,"RGhoPg3/XZI=") -> #VALUE! | ER1: =AND(Sheet1!B26,"RGhoPg3/XZM=") -> #VALUE! | ES1: =AND(Sheet1!C26,"RGhoPg3/XZQ=") -> #VALUE! | ET1: =AND(Sheet1!D26,"RGhoPg3/XZU=") -> #VALUE! | EU1: =IF(Sheet1!27:27,"RGhoPg3/XZY=",0) -> 0 | EV1: =AND(Sheet1!A27,"RGhoPg3/XZc=") -> #VALUE! | EW1: =AND(Sheet1!B27,"RGhoPg3/XZg=") -> #VALUE! | EX1: =AND(Sheet1!C27,"RGhoPg3/XZk=") -> #VALUE! | EY1: =AND(Sheet1!D27,"RGhoPg3/XZo=") -> #VALUE! | EZ1: =IF(Sheet1!28:28,"RGhoPg3/XZs=",0) -> 0 | FA1: =AND(Sheet1!A28,"RGhoPg3/XZw=") -> #VALUE! | FB1: =AND(Sheet1!B28,"RGhoPg3/XZ0=") -> #VALUE! | FC1: =AND(Sheet1!C28,"RGhoPg3/XZ4=") -> #VALUE! | FD1: =AND(Sheet1!D28,"RGhoPg3/XZ8=") -> #VALUE! | FE1: =IF(Sheet1!29:29,"RGhoPg3/XaA=",0) -> 0 | FF1: =AND(Sheet1!A29,"RGhoPg3/XaE=") -> #VALUE! | FG1: =AND(Sheet1!B29,"RGhoPg3/XaI=") -> #VALUE! | FH1: =AND(Sheet1!C29,"RGhoPg3/XaM=") -> #VALUE! | FI1: =AND(Sheet1!D29,"RGhoPg3/XaQ=") -> #VALUE! | FJ1: =IF(Sheet1!30:30,"RGhoPg3/XaU=",0) -> 0 | FK1: =AND(Sheet1!A30,"RGhoPg3/XaY=") -> #VALUE! | FL1: =AND(Sheet1!B30,"RGhoPg3/Xac=") -> #VALUE! | FM1: =AND(Sheet1!C30,"RGhoPg3/Xag=") -> #VALUE! | FN1: =AND(Sheet1!D30,"RGhoPg3/Xak=") -> #VALUE! | FO1: =IF(Sheet1!31:31,"RGhoPg3/Xao=",0) -> 0 | FP1: =AND(Sheet1!A31,"RGhoPg3/Xas=") -> #VALUE! | FQ1: =AND(Sheet1!B31,"RGhoPg3/Xaw=") -> #VALUE! | FR1: =AND(Sheet1!C31,"RGhoPg3/Xa0=") -> #VALUE! | FS1: =AND(Sheet1!D31,"RGhoPg3/Xa4=") -> #VALUE! | FT1: =IF(Sheet1!32:32,"RGhoPg3/Xa8=",0) -> 0 | FU1: =AND(Sheet1!A32,"RGhoPg3/XbA=") -> #VALUE! | FV1: =AND(Sheet1!B32,"RGhoPg3/XbE=") -> #VALUE! | FW1: =AND(Sheet1!C32,"RGhoPg3/XbI=") -> #VALUE! | FX1: =AND(Sheet1!D32,"RGhoPg3/XbM=") -> #VALUE! | FY1: =IF(Sheet1!33:33,"RGhoPg3/XbQ=",0) -> 0 | FZ1: =AND(Sheet1!A33,"RGhoPg3/XbU=") -> #VALUE! | GA1: =AND(Sheet1!B33,"RGhoPg3/XbY=") -> #VALUE! | GB1: =AND(Sheet1!C33,"RGhoPg3/Xbc=") -> #VALUE! | GC1: =AND(Sheet1!D33,"RGhoPg3/Xbg=") -> #VALUE! | GD1: =IF(Sheet1!34:34,"RGhoPg3/Xbk=",0) -> 0 | GE1: =AND(Sheet1!A34,"RGhoPg3/Xbo=") -> #VALUE! | GF1: =AND(Sheet1!B34,"RGhoPg3/Xbs=") -> #VALUE! | GG1: =AND(Sheet1!C34,"RGhoPg3/Xbw=") -> #VALUE! | GH1: =AND(Sheet1!D34,"RGhoPg3/Xb0=") -> #VALUE! | GI1: =IF(Sheet1!35:35,"RGhoPg3/Xb4=",0) -> 0 | GJ1: =AND(Sheet1!A35,"RGhoPg3/Xb8=") -> #VALUE! | GK1: =AND(Sheet1!B35,"RGhoPg3/XcA=") -> #VALUE! | GL1: =AND(Sheet1!C35,"RGhoPg3/XcE=") -> #VALUE! | GM1: =AND(Sheet1!D35,"RGhoPg3/XcI=") -> #VALUE! | GN1: =IF(Sheet1!37:37,"RGhoPg3/XcM=",0) -> 0 | GO1: =AND(Sheet1!A37,"RGhoPg3/XcQ=") -> #VALUE! | GP1: =AND(Sheet1!B37,"RGhoPg3/XcU=") -> #VALUE! | GQ1: =AND(Sheet1!C37,"RGhoPg3/XcY=") -> #VALUE! | GR1: =AND(Sheet1!D37,"RGhoPg3/Xcc=") -> #VALUE! | GS1: =IF(Sheet1!38:38,"RGhoPg3/Xcg=",0) -> 0 | GT1: =AND(Sheet1!A38,"RGhoPg3/Xck=") -> #VALUE! | GU1: =AND(Sheet1!B38,"RGhoPg3/Xco=") -> #VALUE! | GV1: =AND(Sheet1!C38,"RGhoPg3/Xcs=") -> #VALUE! | GW1: =AND(Sheet1!D38,"RGhoPg3/Xcw=") -> #VALUE! | GX1: =IF(Sheet1!39:39,"RGhoPg3/Xc0=",0) -> 0 | GY1: =AND(Sheet1!A39,"RGhoPg3/Xc4=") -> #VALUE! | GZ1: =AND(Sheet1!B39,"RGhoPg3/Xc8=") -> #VALUE! | HA1: =AND(Sheet1!C39,"RGhoPg3/XdA=") -> #VALUE! | HB1: =AND(Sheet1!D39,"RGhoPg3/XdE=") -> #VALUE! | HC1: =IF(Sheet1!#REF!,"RGhoPg3/XdI=",0) -> #REF! | HD1: =AND(Sheet1!#REF!,"RGhoPg3/XdM=") -> #REF! | HE1: =AND(Sheet1!#REF!,"RGhoPg3/XdQ=") -> #REF! | HF1: =AND(Sheet1!#REF!,"RGhoPg3/XdU=") -> #REF! | HG1: =AND(Sheet1!#REF!,"RGhoPg3/XdY=") -> #REF! | HH1: =IF(Sheet1!40:40,"RGhoPg3/Xdc=",0) -> 0 | HI1: =AND(Sheet1!A40,"RGhoPg3/Xdg=") -> #VALUE! | HJ1: =AND(Sheet1!B40,"RGhoPg3/Xdk=") -> #VALUE! | HK1: =AND(Sheet1!C40,"RGhoPg3/Xdo=") -> #VALUE! | HL1: =AND(Sheet1!D40,"RGhoPg3/Xds=") -> #VALUE! | HM1: =IF(Sheet1!41:41,"RGhoPg3/Xdw=",0) -> 0 | HN1: =AND(Sheet1!A41,"RGhoPg3/Xd0=") -> #VALUE! | HO1: =AND(Sheet1!B41,"RGhoPg3/Xd4=") -> #VALUE! | HP1: =AND(Sheet1!C41,"RGhoPg3/Xd8=") -> #VALUE! | HQ1: =AND(Sheet1!D41,"RGhoPg3/XeA=") -> #VALUE! | HR1: =IF(Sheet1!42:42,"RGhoPg3/XeE=",0) -> 0 | HS1: =AND(Sheet1!A42,"RGhoPg3/XeI=") -> #VALUE! | HT1: =AND(Sheet1!B42,"RGhoPg3/XeM=") -> #VALUE! | HU1: =AND(Sheet1!C42,"RGhoPg3/XeQ=") -> #VALUE! | HV1: =AND(Sheet1!D42,"RGhoPg3/XeU=") -> #VALUE! | HW1: =IF(Sheet1!43:43,"RGhoPg3/XeY=",0) -> 0 | HX1: =AND(Sheet1!A43,"RGhoPg3/Xec=") -> #VALUE! | HY1: =AND(Sheet1!B43,"RGhoPg3/Xeg=") -> #VALUE! | HZ1: =AND(Sheet1!C43,"RGhoPg3/Xek=") -> #VALUE! | IA1: =AND(Sheet1!D43,"RGhoPg3/Xeo=") -> #VALUE! | IB1: =IF(Sheet1!#REF!,"RGhoPg3/Xes=",0) -> #REF! | IC1: =AND(Sheet1!#REF!,"RGhoPg3/Xew=") -> #REF! | ID1: =AND(Sheet1!#REF!,"RGhoPg3/Xe0=") -> #REF! | IE1: =AND(Sheet1!#REF!,"RGhoPg3/Xe4=") -> #REF! | IF1: =AND(Sheet1!#REF!,"RGhoPg3/Xe8=") -> #REF! | IG1: =IF(Sheet1!44:44,"RGhoPg3/XfA=",0) -> 0 | IH1: =AND(Sheet1!A44,"RGhoPg3/XfE=") -> #VALUE! | II1: =AND(Sheet1!B44,"RGhoPg3/XfI=") -> #VALUE! | IJ1: =AND(Sheet1!C44,"RGhoPg3/XfM=") -> #VALUE! | IK1: =AND(Sheet1!D44,"RGhoPg3/XfQ=") -> #VALUE! | IL1: =IF(Sheet1!#REF!,"RGhoPg3/XfU=",0) -> #REF! | IM1: =AND(Sheet1!#REF!,"RGhoPg3/XfY=") -> #REF! | IN1: =AND(Sheet1!#REF!,"RGhoPg3/Xfc=") -> #REF! | IO1: =AND(Sheet1!#REF!,"RGhoPg3/Xfg=") -> #REF! | IP1: =AND(Sheet1!#REF!,"RGhoPg3/Xfk=") -> #REF! | IQ1: =IF(Sheet1!45:45,"RGhoPg3/Xfo=",0) -> 0 | IR1: =AND(Sheet1!A45,"RGhoPg3/Xfs=") -> #VALUE! | IS1: =AND(Sheet1!B45,"RGhoPg3/Xfw=") -> #VALUE! | IT1: =AND(Sheet1!C45,"RGhoPg3/Xf0=") -> #VALUE! | IU1: =AND(Sheet1!D45,"RGhoPg3/Xf4=") -> #VALUE! | IV1: =IF(Sheet1!46:46,"RGhoPg3/Xf8=",0) -> 0
A2: =AND(Sheet1!A46,"crMNOgtODgA=") -> #VALUE! | B2: =AND(Sheet1!B46,"crMNOgtODgE=") -> #VALUE! | C2: =AND(Sheet1!C46,"crMNOgtODgI=") -> #VALUE! | D2: =AND(Sheet1!D46,"crMNOgtODgM=") -> #VALUE! | E2: =IF(Sheet1!47:47,"crMNOgtODgQ=",0) -> 0 | F2: =AND(Sheet1!A47,"crMNOgtODgU=") -> #VALUE! | G2: =AND(Sheet1!B47,"crMNOgtODgY=") -> #VALUE! | H2: =AND(Sheet1!C47,"crMNOgtODgc=") -> #VALUE! | I2: =AND(Sheet1!D47,"crMNOgtODgg=") -> #VALUE! | J2: =IF(Sheet1!#REF!,"crMNOgtODgk=",0) -> #REF! | K2: =AND(Sheet1!#REF!,"crMNOgtODgo=") -> #REF! | L2: =AND(Sheet1!#REF!,"crMNOgtODgs=") -> #REF! | M2: =AND(Sheet1!#REF!,"crMNOgtODgw=") -> #REF! | N2: =AND(Sheet1!#REF!,"crMNOgtODg0=") -> #REF! | O2: =IF(Sheet1!48:48,"crMNOgtODg4=",0) -> 0 | P2: =AND(Sheet1!A48,"crMNOgtODg8=") -> #VALUE! | Q2: =AND(Sheet1!B48,"crMNOgtODhA=") -> #VALUE! | R2: =AND(Sheet1!C48,"crMNOgtODhE=") -> #VALUE! | S2: =AND(Sheet1!D48,"crMNOgtODhI=") -> #VALUE! | T2: =IF(Sheet1!49:49,"crMNOgtODhM=",0) -> 0 | U2: =AND(Sheet1!A49,"crMNOgtODhQ=") -> #VALUE! | V2: =AND(Sheet1!B49,"crMNOgtODhU=") -> #VALUE! | W2: =AND(Sheet1!C49,"crMNOgtODhY=") -> #VALUE! | X2: =AND(Sheet1!D49,"crMNOgtODhc=") -> #VALUE! | Y2: =IF(Sheet1!#REF!,"crMNOgtODhg=",0) -> #REF! | Z2: =AND(Sheet1!#REF!,"crMNOgtODhk=") -> #REF! | AA2: =AND(Sheet1!#REF!,"crMNOgtODho=") -> #REF! | AB2: =AND(Sheet1!#REF!,"crMNOgtODhs=") -> #REF! | AC2: =AND(Sheet1!#REF!,"crMNOgtODhw=") -> #REF! | AD2: =IF(Sheet1!50:50,"crMNOgtODh0=",0) -> 0 | AE2: =AND(Sheet1!A50,"crMNOgtODh4=") -> #VALUE! | AF2: =AND(Sheet1!B50,"crMNOgtODh8=") -> #VALUE! | AG2: =AND(Sheet1!C50,"crMNOgtODiA=") -> #VALUE! | AH2: =AND(Sheet1!D50,"crMNOgtODiE=") -> #VALUE! | AI2: =IF(Sheet1!#REF!,"crMNOgtODiI=",0) -> #REF! | AJ2: =AND(Sheet1!#REF!,"crMNOgtODiM=") -> #REF! | AK2: =AND(Sheet1!#REF!,"crMNOgtODiQ=") -> #REF! | AL2: =AND(Sheet1!#REF!,"crMNOgtODiU=") -> #REF! | AM2: =AND(Sheet1!#REF!,"crMNOgtODiY=") -> #REF! | AN2: =IF(Sheet1!51:51,"crMNOgtODic=",0) -> 0 | AO2: =AND(Sheet1!A51,"crMNOgtODig=") -> #VALUE! | AP2: =AND(Sheet1!B51,"crMNOgtODik=") -> #VALUE! | AQ2: =AND(Sheet1!C51,"crMNOgtODio=") -> #VALUE! | AR2: =AND(Sheet1!D51,"crMNOgtODis=") -> #VALUE! | AS2: =IF(Sheet1!52:52,"crMNOgtODiw=",0) -> 0 | AT2: =AND(Sheet1!A52,"crMNOgtODi0=") -> #VALUE! | AU2: =AND(Sheet1!B52,"crMNOgtODi4=") -> #VALUE! | AV2: =AND(Sheet1!C52,"crMNOgtODi8=") -> #VALUE! | AW2: =AND(Sheet1!D52,"crMNOgtODjA=") -> #VALUE! | AX2: =IF(Sheet1!#REF!,"crMNOgtODjE=",0) -> #REF! | AY2: =AND(Sheet1!#REF!,"crMNOgtODjI=") -> #REF! | AZ2: =AND(Sheet1!#REF!,"crMNOgtODjM=") -> #REF! | BA2: =AND(Sheet1!#REF!,"crMNOgtODjQ=") -> #REF! | BB2: =AND(Sheet1!#REF!,"crMNOgtODjU=") -> #REF! | BC2: =IF(Sheet1!53:53,"crMNOgtODjY=",0) -> 0 | BD2: =AND(Sheet1!A53,"crMNOgtODjc=") -> #VALUE! | BE2: =AND(Sheet1!B53,"crMNOgtODjg=") -> #VALUE! | BF2: =AND(Sheet1!C53,"crMNOgtODjk=") -> #VALUE! | BG2: =AND(Sheet1!D53,"crMNOgtODjo=") -> #VALUE! | BH2: =IF(Sheet1!54:54,"crMNOgtODjs=",0) -> 0 | BI2: =AND(Sheet1!A54,"crMNOgtODjw=") -> #VALUE! | BJ2: =AND(Sheet1!B54,"crMNOgtODj0=") -> #VALUE! | BK2: =AND(Sheet1!C54,"crMNOgtODj4=") -> #VALUE! | BL2: =AND(Sheet1!D54,"crMNOgtODj8=") -> #VALUE! | BM2: =IF(Sheet1!55:55,"crMNOgtODkA=",0) -> 0 | BN2: =AND(Sheet1!A55,"crMNOgtODkE=") -> #VALUE! | BO2: =AND(Sheet1!B55,"crMNOgtODkI=") -> #VALUE! | BP2: =AND(Sheet1!C55,"crMNOgtODkM=") -> #VALUE! | BQ2: =AND(Sheet1!D55,"crMNOgtODkQ=") -> #VALUE! | BR2: =IF(Sheet1!56:56,"crMNOgtODkU=",0) -> 0 | BS2: =AND(Sheet1!A56,"crMNOgtODkY=") -> #VALUE! | BT2: =AND(Sheet1!B56,"crMNOgtODkc=") -> #VALUE! | BU2: =AND(Sheet1!C56,"crMNOgtODkg=") -> #VALUE! | BV2: =AND(Sheet1!D56,"crMNOgtODkk=") -> #VALUE! | BW2: =IF(Sheet1!57:57,"crMNOgtODko=",0) -> 0 | BX2: =AND(Sheet1!A57,"crMNOgtODks=") -> #VALUE! | BY2: =AND(Sheet1!B57,"crMNOgtODkw=") -> #VALUE! | BZ2: =AND(Sheet1!C57,"crMNOgtODk0=") -> #VALUE! | CA2: =AND(Sheet1!D57,"crMNOgtODk4=") -> #VALUE! | CB2: =IF(Sheet1!58:58,"crMNOgtODk8=",0) -> 0 | CC2: =AND(Sheet1!A58,"crMNOgtODlA=") -> #VALUE! | CD2: =AND(Sheet1!B58,"crMNOgtODlE=") -> #VALUE! | CE2: =AND(Sheet1!C58,"crMNOgtODlI=") -> #VALUE! | CF2: =AND(Sheet1!D58,"crMNOgtODlM=") -> #VALUE! | CG2: =IF(Sheet1!#REF!,"crMNOgtODlQ=",0) -> #REF! | CH2: =AND(Sheet1!#REF!,"crMNOgtODlU=") -> #REF! | CI2: =AND(Sheet1!#REF!,"crMNOgtODlY=") -> #REF! | CJ2: =AND(Sheet1!#REF!,"crMNOgtODlc=") -> #REF! | CK2: =AND(Sheet1!#REF!,"crMNOgtODlg=") -> #REF! | CL2: =IF(Sheet1!60:60,"crMNOgtODlk=",0) -> 0 | CM2: =AND(Sheet1!A60,"crMNOgtODlo=") -> #VALUE! | CN2: =AND(Sheet1!B60,"crMNOgtODls=") -> #VALUE! | CO2: =AND(Sheet1!C60,"crMNOgtODlw=") -> #VALUE! | CP2: =AND(Sheet1!D60,"crMNOgtODl0=") -> #VALUE! | CQ2: =IF(Sheet1!61:61,"crMNOgtODl4=",0) -> 0 | CR2: =AND(Sheet1!A61,"crMNOgtODl8=") -> #VALUE! | CS2: =AND(Sheet1!B61,"crMNOgtODmA=") -> #VALUE! | CT2: =AND(Sheet1!C61,"crMNOgtODmE=") -> #VALUE! | CU2: =AND(Sheet1!D61,"crMNOgtODmI=") -> #VALUE! | CV2: =IF(Sheet1!62:62,"crMNOgtODmM=",0) -> 0 | CW2: =AND(Sheet1!A62,"crMNOgtODmQ=") -> #VALUE! | CX2: =AND(Sheet1!B62,"crMNOgtODmU=") -> #VALUE! | CY2: =AND(Sheet1!C62,"crMNOgtODmY=") -> #VALUE! | CZ2: =AND(Sheet1!D62,"crMNOgtODmc=") -> #VALUE! | DA2: =IF(Sheet1!63:63,"crMNOgtODmg=",0) -> 0 | DB2: =AND(Sheet1!A63,"crMNOgtODmk=") -> #VALUE! | DC2: =AND(Sheet1!B63,"crMNOgtODmo=") -> #VALUE! | DD2: =AND(Sheet1!C63,"crMNOgtODms=") -> #VALUE! | DE2: =AND(Sheet1!D63,"crMNOgtODmw=") -> #VALUE! | DF2: =IF(Sheet1!#REF!,"crMNOgtODm0=",0) -> #REF! | DG2: =AND(Sheet1!#REF!,"crMNOgtODm4=") -> #REF! | DH2: =AND(Sheet1!#REF!,"crMNOgtODm8=") -> #REF! | DI2: =AND(Sheet1!#REF!,"crMNOgtODnA=") -> #REF! | DJ2: =AND(Sheet1!#REF!,"crMNOgtODnE=") -> #REF! | DK2: =IF(Sheet1!64:64,"crMNOgtODnI=",0) -> 0 | DL2: =AND(Sheet1!A64,"crMNOgtODnM=") -> #VALUE! | DM2: =AND(Sheet1!B64,"crMNOgtODnQ=") -> #VALUE! | DN2: =AND(Sheet1!C64,"crMNOgtODnU=") -> #VALUE! | DO2: =AND(Sheet1!D64,"crMNOgtODnY=") -> #VALUE! | DP2: =IF(Sheet1!65:65,"crMNOgtODnc=",0) -> 0 | DQ2: =AND(Sheet1!A65,"crMNOgtODng=") -> #VALUE! | DR2: =AND(Sheet1!B65,"crMNOgtODnk=") -> #VALUE! | DS2: =AND(Sheet1!C65,"crMNOgtODno=") -> #VALUE! | DT2: =AND(Sheet1!D65,"crMNOgtODns=") -> #VALUE! | DU2: =IF(Sheet1!#REF!,"crMNOgtODnw=",0) -> #REF! | DV2: =AND(Sheet1!#REF!,"crMNOgtODn0=") -> #REF! | DW2: =AND(Sheet1!#REF!,"crMNOgtODn4=") -> #REF! | DX2: =AND(Sheet1!#REF!,"crMNOgtODn8=") -> #REF! | DY2: =AND(Sheet1!#REF!,"crMNOgtODoA=") -> #REF! | DZ2: =IF(Sheet1!#REF!,"crMNOgtODoE=",0) -> #REF! | EA2: =AND(Sheet1!#REF!,"crMNOgtODoI=") -> #REF! | EB2: =AND(Sheet1!#REF!,"crMNOgtODoM=") -> #REF! | EC2: =AND(Sheet1!#REF!,"crMNOgtODoQ=") -> #REF! | ED2: =AND(Sheet1!#REF!,"crMNOgtODoU=") -> #REF! | EE2: =IF(Sheet1!#REF!,"crMNOgtODoY=",0) -> #REF! | EF2: =AND(Sheet1!#REF!,"crMNOgtODoc=") -> #REF! | EG2: =AND(Sheet1!#REF!,"crMNOgtODog=") -> #REF! | EH2: =AND(Sheet1!#REF!,"crMNOgtODok=") -> #REF! | EI2: =AND(Sheet1!#REF!,"crMNOgtODoo=") -> #REF! | EJ2: =IF(Sheet1!#REF!,"crMNOgtODos=",0) -> #REF! | EK2: =AND(Sheet1!#REF!,"crMNOgtODow=") -> #REF! | EL2: =AND(Sheet1!#REF!,"crMNOgtODo0=") -> #REF! | EM2: =AND(Sheet1!#REF!,"crMNOgtODo4=") -> #REF! | EN2: =AND(Sheet1!#REF!,"crMNOgtODo8=") -> #REF! | EO2: =IF(Sheet1!#REF!,"crMNOgtODpA=",0) -> #REF! | EP2: =AND(Sheet1!#REF!,"crMNOgtODpE=") -> #REF! | EQ2: =AND(Sheet1!#REF!,"crMNOgtODpI=") -> #REF! | ER2: =AND(Sheet1!#REF!,"crMNOgtODpM=") -> #REF! | ES2: =AND(Sheet1!#REF!,"crMNOgtODpQ=") -> #REF! | ET2: =IF(Sheet1!66:66,"crMNOgtODpU=",0) -> 0 | EU2: =AND(Sheet1!A66,"crMNOgtODpY=") -> #VALUE! | EV2: =AND(Sheet1!B66,"crMNOgtODpc=") -> #VALUE! | EW2: =AND(Sheet1!C66,"crMNOgtODpg=") -> #VALUE! | EX2: =AND(Sheet1!D66,"crMNOgtODpk=") -> #VALUE! | EY2: =IF(Sheet1!67:67,"crMNOgtODpo=",0) -> 0 | EZ2: =AND(Sheet1!A67,"crMNOgtODps=") -> #VALUE! | FA2: =AND(Sheet1!B67,"crMNOgtODpw=") -> #VALUE! | FB2: =AND(Sheet1!C67,"crMNOgtODp0=") -> #VALUE! | FC2: =AND(Sheet1!D67,"crMNOgtODp4=") -> #VALUE! | FD2: =IF(Sheet1!68:68,"crMNOgtODp8=",0) -> 0 | FE2: =AND(Sheet1!A68,"crMNOgtODqA=") -> #VALUE! | FF2: =AND(Sheet1!B68,"crMNOgtODqE=") -> #VALUE! | FG2: =AND(Sheet1!C68,"crMNOgtODqI=") -> #VALUE! | FH2: =AND(Sheet1!D68,"crMNOgtODqM=") -> #VALUE! | FI2: =IF(Sheet1!69:69,"crMNOgtODqQ=",0) -> 0 | FJ2: =AND(Sheet1!A69,"crMNOgtODqU=") -> #VALUE! | FK2: =AND(Sheet1!B69,"crMNOgtODqY=") -> #VALUE! | FL2: =AND(Sheet1!C69,"crMNOgtODqc=") -> #VALUE! | FM2: =AND(Sheet1!D69,"crMNOgtODqg=") -> #VALUE! | FN2: =IF(Sheet1!70:70,"crMNOgtODqk=",0) -> 0 | FO2: =AND(Sheet1!A70,"crMNOgtODqo=") -> #VALUE! | FP2: =AND(Sheet1!B70,"crMNOgtODqs=") -> #VALUE! | FQ2: =AND(Sheet1!C70,"crMNOgtODqw=") -> #VALUE! | FR2: =AND(Sheet1!D70,"crMNOgtODq0=") -> #VALUE! | FS2: =IF(Sheet1!#REF!,"crMNOgtODq4=",0) -> #REF! | FT2: =AND(Sheet1!#REF!,"crMNOgtODq8=") -> #REF! | FU2: =AND(Sheet1!#REF!,"crMNOgtODrA=") -> #REF! | FV2: =AND(Sheet1!#REF!,"crMNOgtODrE=") -> #REF! | FW2: =AND(Sheet1!#REF!,"crMNOgtODrI=") -> #REF! | FX2: =IF(Sheet1!71:71,"crMNOgtODrM=",0) -> 0 | FY2: =AND(Sheet1!A71,"crMNOgtODrQ=") -> #VALUE! | FZ2: =AND(Sheet1!B71,"crMNOgtODrU=") -> #VALUE! | GA2: =AND(Sheet1!C71,"crMNOgtODrY=") -> #VALUE! | GB2: =AND(Sheet1!D71,"crMNOgtODrc=") -> #VALUE! | GC2: =IF(Sheet1!72:72,"crMNOgtODrg=",0) -> 0 | GD2: =AND(Sheet1!A72,"crMNOgtODrk=") -> #VALUE! | GE2: =AND(Sheet1!B72,"crMNOgtODro=") -> #VALUE! | GF2: =AND(Sheet1!C72,"crMNOgtODrs=") -> #VALUE! | GG2: =AND(Sheet1!D72,"crMNOgtODrw=") -> #VALUE! | GH2: =IF(Sheet1!73:73,"crMNOgtODr0=",0) -> 0 | GI2: =AND(Sheet1!A73,"crMNOgtODr4=") -> #VALUE! | GJ2: =AND(Sheet1!B73,"crMNOgtODr8=") -> #VALUE! | GK2: =AND(Sheet1!C73,"crMNOgtODsA=") -> #VALUE! | GL2: =AND(Sheet1!D73,"crMNOgtODsE=") -> #VALUE! | GM2: =IF(Sheet1!74:74,"crMNOgtODsI=",0) -> 0 | GN2: =AND(Sheet1!A74,"crMNOgtODsM=") -> #VALUE! | GO2: =AND(Sheet1!B74,"crMNOgtODsQ=") -> #VALUE! | GP2: =AND(Sheet1!C74,"crMNOgtODsU=") -> #VALUE! | GQ2: =AND(Sheet1!D74,"crMNOgtODsY=") -> #VALUE! | GR2: =IF(Sheet1!75:75,"crMNOgtODsc=",0) -> 0 | GS2: =AND(Sheet1!A75,"crMNOgtODsg=") -> #VALUE! | GT2: =AND(Sheet1!B75,"crMNOgtODsk=") -> #VALUE! | GU2: =AND(Sheet1!C75,"crMNOgtODso=") -> #VALUE! | GV2: =AND(Sheet1!D75,"crMNOgtODss=") -> #VALUE! | GW2: =IF(Sheet1!76:76,"crMNOgtODsw=",0) -> 0 | GX2: =AND(Sheet1!A76,"crMNOgtODs0=") -> #VALUE! | GY2: =AND(Sheet1!B76,"crMNOgtODs4=") -> #VALUE! | GZ2: =AND(Sheet1!C76,"crMNOgtODs8=") -> #VALUE! | HA2: =AND(Sheet1!D76,"crMNOgtODtA=") -> #VALUE! | HB2: =IF(Sheet1!77:77,"crMNOgtODtE=",0) -> 0 | HC2: =AND(Sheet1!A77,"crMNOgtODtI=") -> #VALUE! | HD2: =AND(Sheet1!B77,"crMNOgtODtM=") -> #VALUE! | HE2: =AND(Sheet1!C77,"crMNOgtODtQ=") -> #VALUE! | HF2: =AND(Sheet1!D77,"crMNOgtODtU=") -> #VALUE! | HG2: =IF(Sheet1!78:78,"crMNOgtODtY=",0) -> 0 | HH2: =AND(Sheet1!A78,"crMNOgtODtc=") -> #VALUE! | HI2: =AND(Sheet1!B78,"crMNOgtODtg=") -> #VALUE! | HJ2: =AND(Sheet1!C78,"crMNOgtODtk=") -> #VALUE! | HK2: =AND(Sheet1!D78,"crMNOgtODto=") -> #VALUE! | HL2: =IF(Sheet1!#REF!,"crMNOgtODts=",0) -> #REF! | HM2: =AND(Sheet1!#REF!,"crMNOgtODtw=") -> #REF! | HN2: =AND(Sheet1!#REF!,"crMNOgtODt0=") -> #REF! | HO2: =AND(Sheet1!#REF!,"crMNOgtODt4=") -> #REF! | HP2: =AND(Sheet1!#REF!,"crMNOgtODt8=") -> #REF! | HQ2: =IF(Sheet1!79:79,"crMNOgtODuA=",0) -> 0 | HR2: =AND(Sheet1!A79,"crMNOgtODuE=") -> #VALUE! | HS2: =AND(Sheet1!B79,"crMNOgtODuI=") -> #VALUE! | HT2: =AND(Sheet1!C79,"crMNOgtODuM=") -> #VALUE! | HU2: =AND(Sheet1!D79,"crMNOgtODuQ=") -> #VALUE! | HV2: =IF(Sheet1!#REF!,"crMNOgtODuU=",0) -> #REF! | HW2: =AND(Sheet1!#REF!,"crMNOgtODuY=") -> #REF! | HX2: =AND(Sheet1!#REF!,"crMNOgtODuc=") -> #REF! | HY2: =AND(Sheet1!#REF!,"crMNOgtODug=") -> #REF! | HZ2: =AND(Sheet1!#REF!,"crMNOgtODuk=") -> #REF! | IA2: =IF(Sheet1!80:80,"crMNOgtODuo=",0) -> 0 | IB2: =AND(Sheet1!A80,"crMNOgtODus=") -> #VALUE! | IC2: =AND(Sheet1!B80,"crMNOgtODuw=") -> #VALUE! | ID2: =AND(Sheet1!C80,"crMNOgtODu0=") -> #VALUE! | IE2: =AND(Sheet1!D80,"crMNOgtODu4=") -> #VALUE! | IF2: =IF(Sheet1!81:81,"crMNOgtODu8=",0) -> 0 | IG2: =AND(Sheet1!A81,"crMNOgtODvA=") -> #VALUE! | IH2: =AND(Sheet1!B81,"crMNOgtODvE=") -> #VALUE! | II2: =AND(Sheet1!C81,"crMNOgtODvI=") -> #VALUE! | IJ2: =AND(Sheet1!D81,"crMNOgtODvM=") -> #VALUE! | IK2: =IF(Sheet1!82:82,"crMNOgtODvQ=",0) -> 0 | IL2: =AND(Sheet1!A82,"crMNOgtODvU=") -> #VALUE! | IM2: =AND(Sheet1!B82,"crMNOgtODvY=") -> #VALUE! | IN2: =AND(Sheet1!C82,"crMNOgtODvc=") -> #VALUE! | IO2: =AND(Sheet1!D82,"crMNOgtODvg=") -> #VALUE! | IP2: =IF(Sheet1!83:83,"crMNOgtODvk=",0) -> 0 | IQ2: =AND(Sheet1!A83,"crMNOgtODvo=") -> #VALUE! | IR2: =AND(Sheet1!B83,"crMNOgtODvs=") -> #VALUE! | IS2: =AND(Sheet1!C83,"crMNOgtODvw=") -> #VALUE! | IT2: =AND(Sheet1!D83,"crMNOgtODv0=") -> #VALUE! | IU2: =IF(Sheet1!84:84,"crMNOgtODv4=",0) -> 0 | IV2: =AND(Sheet1!A84,"crMNOgtODv8=") -> #VALUE!
A3: =AND(Sheet1!B84,"TJ52PmPGJwA=") -> #VALUE! | B3: =AND(Sheet1!C84,"TJ52PmPGJwE=") -> #VALUE! | C3: =AND(Sheet1!D84,"TJ52PmPGJwI=") -> #VALUE! | D3: =IF(Sheet1!85:85,"TJ52PmPGJwM=",0) -> #VALUE! | E3: =AND(Sheet1!A85,"TJ52PmPGJwQ=") -> #VALUE! | F3: =AND(Sheet1!B85,"TJ52PmPGJwU=") -> #VALUE! | G3: =AND(Sheet1!C85,"TJ52PmPGJwY=") -> #VALUE! | H3: =AND(Sheet1!D85,"TJ52PmPGJwc=") -> #VALUE! | I3: =IF(Sheet1!86:86,"TJ52PmPGJwg=",0) -> 0 | J3: =AND(Sheet1!A86,"TJ52PmPGJwk=") -> #VALUE! | K3: =AND(Sheet1!B86,"TJ52PmPGJwo=") -> #VALUE! | L3: =AND(Sheet1!C86,"TJ52PmPGJws=") -> #VALUE! | M3: =AND(Sheet1!D86,"TJ52PmPGJww=") -> #VALUE! | N3: =IF(Sheet1!87:87,"TJ52PmPGJw0=",0) -> 0 | O3: =AND(Sheet1!A87,"TJ52PmPGJw4=") -> #VALUE! | P3: =AND(Sheet1!B87,"TJ52PmPGJw8=") -> #VALUE! | Q3: =AND(Sheet1!C87,"TJ52PmPGJxA=") -> #VALUE! | R3: =AND(Sheet1!D87,"TJ52PmPGJxE=") -> #VALUE! | S3: =IF(Sheet1!88:88,"TJ52PmPGJxI=",0) -> 0 | T3: =AND(Sheet1!A88,"TJ52PmPGJxM=") -> #VALUE! | U3: =AND(Sheet1!B88,"TJ52PmPGJxQ=") -> #VALUE! | V3: =AND(Sheet1!C88,"TJ52PmPGJxU=") -> #VALUE! | W3: =AND(Sheet1!D88,"TJ52PmPGJxY=") -> #VALUE! | X3: =IF(Sheet1!89:89,"TJ52PmPGJxc=",0) -> 0 | Y3: =AND(Sheet1!A89,"TJ52PmPGJxg=") -> #VALUE! | Z3: =AND(Sheet1!B89,"TJ52PmPGJxk=") -> #VALUE! | AA3: =AND(Sheet1!C89,"TJ52PmPGJxo=") -> #VALUE! | AB3: =AND(Sheet1!D89,"TJ52PmPGJxs=") -> #VALUE! | AC3: =IF(Sheet1!90:90,"TJ52PmPGJxw=",0) -> 0 | AD3: =AND(Sheet1!A90,"TJ52PmPGJx0=") -> #VALUE! | AE3: =AND(Sheet1!B90,"TJ52PmPGJx4=") -> #VALUE! | AF3: =AND(Sheet1!C90,"TJ52PmPGJx8=") -> #VALUE! | AG3: =AND(Sheet1!D90,"TJ52PmPGJyA=") -> #VALUE! | AH3: =IF(Sheet1!#REF!,"TJ52PmPGJyE=",0) -> #REF! | AI3: =AND(Sheet1!#REF!,"TJ52PmPGJyI=") -> #REF! | AJ3: =AND(Sheet1!#REF!,"TJ52PmPGJyM=") -> #REF! | AK3: =AND(Sheet1!#REF!,"TJ52PmPGJyQ=") -> #REF! | AL3: =AND(Sheet1!#REF!,"TJ52PmPGJyU=") -> #REF! | AM3: =IF(Sheet1!91:91,"TJ52PmPGJyY=",0) -> 0 | AN3: =AND(Sheet1!A91,"TJ52PmPGJyc=") -> #VALUE! | AO3: =AND(Sheet1!B91,"TJ52PmPGJyg=") -> #VALUE! | AP3: =AND(Sheet1!C91,"TJ52PmPGJyk=") -> #VALUE! | AQ3: =AND(Sheet1!D91,"TJ52PmPGJyo=") -> #VALUE! | AR3: =IF(Sheet1!#REF!,"TJ52PmPGJys=",0) -> #REF! | AS3: =AND(Sheet1!#REF!,"TJ52PmPGJyw=") -> #REF! | AT3: =AND(Sheet1!#REF!,"TJ52PmPGJy0=") -> #REF! | AU3: =AND(Sheet1!#REF!,"TJ52PmPGJy4=") -> #REF! | AV3: =AND(Sheet1!#REF!,"TJ52PmPGJy8=") -> #REF! | AW3: =IF(Sheet1!92:92,"TJ52PmPGJzA=",0) -> 0 | AX3: =AND(Sheet1!A92,"TJ52PmPGJzE=") -> #VALUE! | AY3: =AND(Sheet1!B92,"TJ52PmPGJzI=") -> #VALUE! | AZ3: =AND(Sheet1!C92,"TJ52PmPGJzM=") -> #VALUE! | BA3: =AND(Sheet1!D92,"TJ52PmPGJzQ=") -> #VALUE! | BB3: =IF(Sheet1!93:93,"TJ52PmPGJzU=",0) -> 0 | BC3: =AND(Sheet1!A93,"TJ52PmPGJzY=") -> #VALUE! | BD3: =AND(Sheet1!B93,"TJ52PmPGJzc=") -> #VALUE! | BE3: =AND(Sheet1!C93,"TJ52PmPGJzg=") -> #VALUE! | BF3: =AND(Sheet1!D93,"TJ52PmPGJzk=") -> #VALUE! | BG3: =IF(Sheet1!94:94,"TJ52PmPGJzo=",0) -> 0 | BH3: =AND(Sheet1!A94,"TJ52PmPGJzs=") -> #VALUE! | BI3: =AND(Sheet1!B94,"TJ52PmPGJzw=") -> #VALUE! | BJ3: =AND(Sheet1!C94,"TJ52PmPGJz0=") -> #VALUE! | BK3: =AND(Sheet1!D94,"TJ52PmPGJz4=") -> #VALUE! | BL3: =IF(Sheet1!95:95,"TJ52PmPGJz8=",0) -> 0 | BM3: =AND(Sheet1!A95,"TJ52PmPGJ0A=") -> #VALUE! | BN3: =AND(Sheet1!B95,"TJ52PmPGJ0E=") -> #VALUE! | BO3: =AND(Sheet1!C95,"TJ52PmPGJ0I=") -> #VALUE! | BP3: =AND(Sheet1!D95,"TJ52PmPGJ0M=") -> #VALUE! | BQ3: =IF(Sheet1!96:96,"TJ52PmPGJ0Q=",0) -> 0 | BR3: =AND(Sheet1!A96,"TJ52PmPGJ0U=") -> #VALUE! | BS3: =AND(Sheet1!B96,"TJ52PmPGJ0Y=") -> #VALUE! | BT3: =AND(Sheet1!C96,"TJ52PmPGJ0c=") -> #VALUE! | BU3: =AND(Sheet1!D96,"TJ52PmPGJ0g=") -> #VALUE! | BV3: =IF(Sheet1!97:97,"TJ52PmPGJ0k=",0) -> 0 | BW3: =AND(Sheet1!A97,"TJ52PmPGJ0o=") -> #VALUE! | BX3: =AND(Sheet1!B97,"TJ52PmPGJ0s=") -> #VALUE! | BY3: =AND(Sheet1!C97,"TJ52PmPGJ0w=") -> #VALUE! | BZ3: =AND(Sheet1!D97,"TJ52PmPGJ00=") -> #VALUE! | CA3: =IF(Sheet1!98:98,"TJ52PmPGJ04=",0) -> 0 | CB3: =AND(Sheet1!A98,"TJ52PmPGJ08=") -> #VALUE! | CC3: =AND(Sheet1!B98,"TJ52PmPGJ1A=") -> #VALUE! | CD3: =AND(Sheet1!C98,"TJ52PmPGJ1E=") -> #VALUE! | CE3: =AND(Sheet1!D98,"TJ52PmPGJ1I=") -> #VALUE! | CF3: =IF(Sheet1!99:99,"TJ52PmPGJ1M=",0) -> 0 | CG3: =AND(Sheet1!A99,"TJ52PmPGJ1Q=") -> #VALUE! | CH3: =AND(Sheet1!B99,"TJ52PmPGJ1U=") -> #VALUE! | CI3: =AND(Sheet1!C99,"TJ52PmPGJ1Y=") -> #VALUE! | CJ3: =AND(Sheet1!D99,"TJ52PmPGJ1c=") -> #VALUE! | CK3: =IF(Sheet1!#REF!,"TJ52PmPGJ1g=",0) -> #REF! | CL3: =AND(Sheet1!#REF!,"TJ52PmPGJ1k=") -> #REF! | CM3: =AND(Sheet1!#REF!,"TJ52PmPGJ1o=") -> #REF! | CN3: =AND(Sheet1!#REF!,"TJ52PmPGJ1s=") -> #REF! | CO3: =AND(Sheet1!#REF!,"TJ52PmPGJ1w=") -> #REF! | CP3: =IF(Sheet1!100:100,"TJ52PmPGJ10=",0) -> 0 | CQ3: =AND(Sheet1!A100,"TJ52PmPGJ14=") -> #VALUE! | CR3: =AND(Sheet1!B100,"TJ52PmPGJ18=") -> #VALUE! | CS3: =AND(Sheet1!C100,"TJ52PmPGJ2A=") -> #VALUE! | CT3: =AND(Sheet1!D100,"TJ52PmPGJ2E=") -> #VALUE! | CU3: =IF(Sheet1!102:102,"TJ52PmPGJ2I=",0) -> 0 | CV3: =AND(Sheet1!A102,"TJ52PmPGJ2M=") -> #VALUE! | CW3: =AND(Sheet1!B102,"TJ52PmPGJ2Q=") -> #VALUE! | CX3: =AND(Sheet1!C102,"TJ52PmPGJ2U=") -> #VALUE! | CY3: =AND(Sheet1!D102,"TJ52PmPGJ2Y=") -> #VALUE! | CZ3: =IF(Sheet1!103:103,"TJ52PmPGJ2c=",0) -> 0 | DA3: =AND(Sheet1!A103,"TJ52PmPGJ2g=") -> #VALUE! | DB3: =AND(Sheet1!B103,"TJ52PmPGJ2k=") -> #VALUE! | DC3: =AND(Sheet1!C103,"TJ52PmPGJ2o=") -> #VALUE! | DD3: =AND(Sheet1!D103,"TJ52PmPGJ2s=") -> #VALUE! | DE3: =IF(Sheet1!104:104,"TJ52PmPGJ2w=",0) -> 0 | DF3: =AND(Sheet1!A104,"TJ52PmPGJ20=") -> #VALUE! | DG3: =AND(Sheet1!B104,"TJ52PmPGJ24=") -> #VALUE! | DH3: =AND(Sheet1!C104,"TJ52PmPGJ28=") -> #VALUE! | DI3: =AND(Sheet1!D104,"TJ52PmPGJ3A=") -> #VALUE! | DJ3: =IF(Sheet1!105:105,"TJ52PmPGJ3E=",0) -> 0 | DK3: =AND(Sheet1!A105,"TJ52PmPGJ3I=") -> #VALUE! | DL3: =AND(Sheet1!B105,"TJ52PmPGJ3M=") -> #VALUE! | DM3: =AND(Sheet1!C105,"TJ52PmPGJ3Q=") -> #VALUE! | DN3: =AND(Sheet1!D105,"TJ52PmPGJ3U=") -> #VALUE! | DO3: =IF(Sheet1!#REF!,"TJ52PmPGJ3Y=",0) -> #REF! | DP3: =AND(Sheet1!#REF!,"TJ52PmPGJ3c=") -> #REF! | DQ3: =AND(Sheet1!#REF!,"TJ52PmPGJ3g=") -> #REF! | DR3: =AND(Sheet1!#REF!,"TJ52PmPGJ3k=") -> #REF! | DS3: =AND(Sheet1!#REF!,"TJ52PmPGJ3o=") -> #REF! | DT3: =IF(Sheet1!106:106,"TJ52PmPGJ3s=",0) -> 0 | DU3: =AND(Sheet1!A106,"TJ52PmPGJ3w=") -> #VALUE! | DV3: =AND(Sheet1!B106,"TJ52PmPGJ30=") -> #VALUE! | DW3: =AND(Sheet1!C106,"TJ52PmPGJ34=") -> #VALUE! | DX3: =AND(Sheet1!D106,"TJ52PmPGJ38=") -> #VALUE! | DY3: =IF(Sheet1!#REF!,"TJ52PmPGJ4A=",0) -> #REF! | DZ3: =AND(Sheet1!#REF!,"TJ52PmPGJ4E=") -> #REF! | EA3: =AND(Sheet1!#REF!,"TJ52PmPGJ4I=") -> #REF! | EB3: =AND(Sheet1!#REF!,"TJ52PmPGJ4M=") -> #REF! | EC3: =AND(Sheet1!#REF!,"TJ52PmPGJ4Q=") -> #REF! | ED3: =IF(Sheet1!107:107,"TJ52PmPGJ4U=",0) -> 0 | EE3: =AND(Sheet1!A107,"TJ52PmPGJ4Y=") -> #VALUE! | EF3: =AND(Sheet1!B107,"TJ52PmPGJ4c=") -> #VALUE! | EG3: =AND(Sheet1!C107,"TJ52PmPGJ4g=") -> #VALUE! | EH3: =AND(Sheet1!D107,"TJ52PmPGJ4k=") -> #VALUE! | EI3: =IF(Sheet1!108:108,"TJ52PmPGJ4o=",0) -> 0 | EJ3: =AND(Sheet1!A108,"TJ52PmPGJ4s=") -> #VALUE! | EK3: =AND(Sheet1!B108,"TJ52PmPGJ4w=") -> #VALUE! | EL3: =AND(Sheet1!C108,"TJ52PmPGJ40=") -> #VALUE! | EM3: =AND(Sheet1!D108,"TJ52PmPGJ44=") -> #VALUE! | EN3: =IF(Sheet1!#REF!,"TJ52PmPGJ48=",0) -> #REF! | EO3: =AND(Sheet1!#REF!,"TJ52PmPGJ5A=") -> #REF! | EP3: =AND(Sheet1!#REF!,"TJ52PmPGJ5E=") -> #REF! | EQ3: =AND(Sheet1!#REF!,"TJ52PmPGJ5I=") -> #REF! | ER3: =AND(Sheet1!#REF!,"TJ52PmPGJ5M=") -> #REF! | ES3: =IF(Sheet1!109:109,"TJ52PmPGJ5Q=",0) -> 0 | ET3: =AND(Sheet1!A109,"TJ52PmPGJ5U=") -> #VALUE! | EU3: =AND(Sheet1!B109,"TJ52PmPGJ5Y=") -> #VALUE! | EV3: =AND(Sheet1!C109,"TJ52PmPGJ5c=") -> #VALUE! | EW3: =AND(Sheet1!D109,"TJ52PmPGJ5g=") -> #VALUE! | EX3: =IF(Sheet1!110:110,"TJ52PmPGJ5k=",0) -> 0 | EY3: =AND(Sheet1!A110,"TJ52PmPGJ5o=") -> #VALUE! | EZ3: =AND(Sheet1!B110,"TJ52PmPGJ5s=") -> #VALUE! | FA3: =AND(Sheet1!C110,"TJ52PmPGJ5w=") -> #VALUE! | FB3: =AND(Sheet1!D110,"TJ52PmPGJ50=") -> #VALUE! | FC3: =IF(Sheet1!111:111,"TJ52PmPGJ54=",0) -> 0 | FD3: =AND(Sheet1!A111,"TJ52PmPGJ58=") -> #VALUE! | FE3: =AND(Sheet1!B111,"TJ52PmPGJ6A=") -> #VALUE! | FF3: =AND(Sheet1!C111,"TJ52PmPGJ6E=") -> #VALUE! | FG3: =AND(Sheet1!D111,"TJ52PmPGJ6I=") -> #VALUE! | FH3: =IF(Sheet1!112:112,"TJ52PmPGJ6M=",0) -> 0 | FI3: =AND(Sheet1!A112,"TJ52PmPGJ6Q=") -> #VALUE! | FJ3: =AND(Sheet1!B112,"TJ52PmPGJ6U=") -> #VALUE! | FK3: =AND(Sheet1!C112,"TJ52PmPGJ6Y=") -> #VALUE! | FL3: =AND(Sheet1!D112,"TJ52PmPGJ6c=") -> #VALUE! | FM3: =IF(Sheet1!113:113,"TJ52PmPGJ6g=",0) -> 0 | FN3: =AND(Sheet1!A113,"TJ52PmPGJ6k=") -> #VALUE! | FO3: =AND(Sheet1!B113,"TJ52PmPGJ6o=") -> #VALUE! | FP3: =AND(Sheet1!C113,"TJ52PmPGJ6s=") -> #VALUE! | FQ3: =AND(Sheet1!D113,"TJ52PmPGJ6w=") -> #VALUE! | FR3: =IF(Sheet1!114:114,"TJ52PmPGJ60=",0) -> 0 | FS3: =AND(Sheet1!A114,"TJ52PmPGJ64=") -> #VALUE! | FT3: =AND(Sheet1!B114,"TJ52PmPGJ68=") -> #VALUE! | FU3: =AND(Sheet1!C114,"TJ52PmPGJ7A=") -> #VALUE! | FV3: =AND(Sheet1!D114,"TJ52PmPGJ7E=") -> #VALUE! | FW3: =IF(Sheet1!115:115,"TJ52PmPGJ7I=",0) -> 0 | FX3: =AND(Sheet1!A115,"TJ52PmPGJ7M=") -> #VALUE! | FY3: =AND(Sheet1!B115,"TJ52PmPGJ7Q=") -> #VALUE! | FZ3: =AND(Sheet1!C115,"TJ52PmPGJ7U=") -> #VALUE! | GA3: =AND(Sheet1!D115,"TJ52PmPGJ7Y=") -> #VALUE! | GB3: =IF(Sheet1!116:116,"TJ52PmPGJ7c=",0) -> 0 | GC3: =AND(Sheet1!A116,"TJ52PmPGJ7g=") -> #VALUE! | GD3: =AND(Sheet1!B116,"TJ52PmPGJ7k=") -> #VALUE! | GE3: =AND(Sheet1!C116,"TJ52PmPGJ7o=") -> #VALUE! | GF3: =AND(Sheet1!D116,"TJ52PmPGJ7s=") -> #VALUE! | GG3: =IF(Sheet1!118:118,"TJ52PmPGJ7w=",0) -> 0 | GH3: =AND(Sheet1!A118,"TJ52PmPGJ70=") -> #VALUE! | GI3: =AND(Sheet1!B118,"TJ52PmPGJ74=") -> #VALUE! | GJ3: =AND(Sheet1!C118,"TJ52PmPGJ78=") -> #VALUE! | GK3: =AND(Sheet1!D118,"TJ52PmPGJ8A=") -> #VALUE! | GL3: =IF(Sheet1!119:119,"TJ52PmPGJ8E=",0) -> 0 | GM3: =AND(Sheet1!A119,"TJ52PmPGJ8I=") -> #VALUE! | GN3: =AND(Sheet1!B119,"TJ52PmPGJ8M=") -> #VALUE! | GO3: =AND(Sheet1!C119,"TJ52PmPGJ8Q=") -> #VALUE! | GP3: =AND(Sheet1!D119,"TJ52PmPGJ8U=") -> #VALUE! | GQ3: =IF(Sheet1!120:120,"TJ52PmPGJ8Y=",0) -> 0 | GR3: =AND(Sheet1!A120,"TJ52PmPGJ8c=") -> #VALUE! | GS3: =AND(Sheet1!B120,"TJ52PmPGJ8g=") -> #VALUE! | GT3: =AND(Sheet1!C120,"TJ52PmPGJ8k=") -> #VALUE! | GU3: =AND(Sheet1!D120,"TJ52PmPGJ8o=") -> #VALUE! | GV3: =IF(Sheet1!#REF!,"TJ52PmPGJ8s=",0) -> #REF! | GW3: =AND(Sheet1!#REF!,"TJ52PmPGJ8w=") -> #REF! | GX3: =AND(Sheet1!#REF!,"TJ52PmPGJ80=") -> #REF! | GY3: =AND(Sheet1!#REF!,"TJ52PmPGJ84=") -> #REF! | GZ3: =AND(Sheet1!#REF!,"TJ52PmPGJ88=") -> #REF! | HA3: =IF(Sheet1!121:121,"TJ52PmPGJ9A=",0) -> 0 | HB3: =AND(Sheet1!A121,"TJ52PmPGJ9E=") -> #VALUE! | HC3: =AND(Sheet1!B121,"TJ52PmPGJ9I=") -> #VALUE! | HD3: =AND(Sheet1!C121,"TJ52PmPGJ9M=") -> #VALUE! | HE3: =AND(Sheet1!D121,"TJ52PmPGJ9Q=") -> #VALUE! | HF3: =IF(Sheet1!122:122,"TJ52PmPGJ9U=",0) -> 0 | HG3: =AND(Sheet1!A122,"TJ52PmPGJ9Y=") -> #VALUE! | HH3: =AND(Sheet1!B122,"TJ52PmPGJ9c=") -> #VALUE! | HI3: =AND(Sheet1!C122,"TJ52PmPGJ9g=") -> #VALUE! | HJ3: =AND(Sheet1!D122,"TJ52PmPGJ9k=") -> #VALUE! | HK3: =IF(Sheet1!123:123,"TJ52PmPGJ9o=",0) -> 0 | HL3: =AND(Sheet1!A123,"TJ52PmPGJ9s=") -> #VALUE! | HM3: =AND(Sheet1!B123,"TJ52PmPGJ9w=") -> #VALUE! | HN3: =AND(Sheet1!C123,"TJ52PmPGJ90=") -> #VALUE! | HO3: =AND(Sheet1!D123,"TJ52PmPGJ94=") -> #VALUE! | HP3: =IF(Sheet1!#REF!,"TJ52PmPGJ98=",0) -> #REF! | HQ3: =AND(Sheet1!#REF!,"TJ52PmPGJ+A=") -> #REF! | HR3: =AND(Sheet1!#REF!,"TJ52PmPGJ+E=") -> #REF! | HS3: =AND(Sheet1!#REF!,"TJ52PmPGJ+I=") -> #REF! | HT3: =AND(Sheet1!#REF!,"TJ52PmPGJ+M=") -> #REF! | HU3: =IF(Sheet1!124:124,"TJ52PmPGJ+Q=",0) -> 0 | HV3: =AND(Sheet1!A124,"TJ52PmPGJ+U=") -> #VALUE! | HW3: =AND(Sheet1!B124,"TJ52PmPGJ+Y=") -> #VALUE! | HX3: =AND(Sheet1!C124,"TJ52PmPGJ+c=") -> #VALUE! | HY3: =AND(Sheet1!D124,"TJ52PmPGJ+g=") -> #VALUE! | HZ3: =IF(Sheet1!125:125,"TJ52PmPGJ+k=",0) -> 0 | IA3: =AND(Sheet1!A125,"TJ52PmPGJ+o=") -> #VALUE! | IB3: =AND(Sheet1!B125,"TJ52PmPGJ+s=") -> #VALUE! | IC3: =AND(Sheet1!C125,"TJ52PmPGJ+w=") -> #VALUE! | ID3: =AND(Sheet1!D125,"TJ52PmPGJ+0=") -> #VALUE! | IE3: =IF(Sheet1!#REF!,"TJ52PmPGJ+4=",0) -> #REF! | IF3: =AND(Sheet1!#REF!,"TJ52PmPGJ+8=") -> #REF! | IG3: =AND(Sheet1!#REF!,"TJ52PmPGJ/A=") -> #REF! | IH3: =AND(Sheet1!#REF!,"TJ52PmPGJ/E=") -> #REF! | II3: =AND(Sheet1!#REF!,"TJ52PmPGJ/I=") -> #REF! | IJ3: =IF(Sheet1!126:126,"TJ52PmPGJ/M=",0) -> 0 | IK3: =AND(Sheet1!A126,"TJ52PmPGJ/Q=") -> #VALUE! | IL3: =AND(Sheet1!B126,"TJ52PmPGJ/U=") -> #VALUE! | IM3: =AND(Sheet1!C126,"TJ52PmPGJ/Y=") -> #VALUE! | IN3: =AND(Sheet1!D126,"TJ52PmPGJ/c=") -> #VALUE! | IO3: =IF(Sheet1!128:128,"TJ52PmPGJ/g=",0) -> 0 | IP3: =AND(Sheet1!A128,"TJ52PmPGJ/k=") -> #VALUE! | IQ3: =AND(Sheet1!B128,"TJ52PmPGJ/o=") -> #VALUE! | IR3: =AND(Sheet1!C128,"TJ52PmPGJ/s=") -> #VALUE! | IS3: =AND(Sheet1!D128,"TJ52PmPGJ/w=") -> #VALUE! | IT3: =IF(Sheet1!#REF!,"TJ52PmPGJ/0=",0) -> #REF! | IU3: =AND(Sheet1!#REF!,"TJ52PmPGJ/4=") -> #REF! | IV3: =AND(Sheet1!#REF!,"TJ52PmPGJ/8=") -> #REF!
A4: =AND(Sheet1!#REF!,"fcaKe1x6ogA=") -> #REF! | B4: =AND(Sheet1!#REF!,"fcaKe1x6ogE=") -> #REF! | C4: =IF(Sheet1!129:129,"fcaKe1x6ogI=",0) -> #VALUE! | D4: =AND(Sheet1!A129,"fcaKe1x6ogM=") -> #VALUE! | E4: =AND(Sheet1!B129,"fcaKe1x6ogQ=") -> #VALUE! | F4: =AND(Sheet1!C129,"fcaKe1x6ogU=") -> #VALUE! | G4: =AND(Sheet1!D129,"fcaKe1x6ogY=") -> #VALUE! | H4: =IF(Sheet1!130:130,"fcaKe1x6ogc=",0) -> 0 | I4: =AND(Sheet1!A130,"fcaKe1x6ogg=") -> #VALUE! | J4: =AND(Sheet1!B130,"fcaKe1x6ogk=") -> #VALUE! | K4: =AND(Sheet1!C130,"fcaKe1x6ogo=") -> #VALUE! | L4: =AND(Sheet1!D130,"fcaKe1x6ogs=") -> #VALUE! | M4: =IF(Sheet1!131:131,"fcaKe1x6ogw=",0) -> 0 | N4: =AND(Sheet1!A131,"fcaKe1x6og0=") -> #VALUE! | O4: =AND(Sheet1!B131,"fcaKe1x6og4=") -> #VALUE! | P4: =AND(Sheet1!C131,"fcaKe1x6og8=") -> #VALUE! | Q4: =AND(Sheet1!D131,"fcaKe1x6ohA=") -> #VALUE! | R4: =IF(Sheet1!132:132,"fcaKe1x6ohE=",0) -> 0 | S4: =AND(Sheet1!A132,"fcaKe1x6ohI=") -> #VALUE! | T4: =AND(Sheet1!B132,"fcaKe1x6ohM=") -> #VALUE! | U4: =AND(Sheet1!C132,"fcaKe1x6ohQ=") -> #VALUE! | V4: =AND(Sheet1!D132,"fcaKe1x6ohU=") -> #VALUE! | W4: =IF(Sheet1!133:133,"fcaKe1x6ohY=",0) -> 0 | X4: =AND(Sheet1!A133,"fcaKe1x6ohc=") -> #VALUE! | Y4: =AND(Sheet1!B133,"fcaKe1x6ohg=") -> #VALUE! | Z4: =AND(Sheet1!C133,"fcaKe1x6ohk=") -> #VALUE! | AA4: =AND(Sheet1!D133,"fcaKe1x6oho=") -> #VALUE! | AB4: =IF(Sheet1!134:134,"fcaKe1x6ohs=",0) -> 0 | AC4: =AND(Sheet1!A134,"fcaKe1x6ohw=") -> #VALUE! | AD4: =AND(Sheet1!B134,"fcaKe1x6oh0=") -> #VALUE! | AE4: =AND(Sheet1!C134,"fcaKe1x6oh4=") -> #VALUE! | AF4: =AND(Sheet1!D134,"fcaKe1x6oh8=") -> #VALUE! | AG4: =IF(Sheet1!135:135,"fcaKe1x6oiA=",0) -> 0 | AH4: =AND(Sheet1!A135,"fcaKe1x6oiE=") -> #VALUE! | AI4: =AND(Sheet1!B135,"fcaKe1x6oiI=") -> #VALUE! | AJ4: =AND(Sheet1!C135,"fcaKe1x6oiM=") -> #VALUE! | AK4: =AND(Sheet1!D135,"fcaKe1x6oiQ=") -> #VALUE! | AL4: =IF(Sheet1!136:136,"fcaKe1x6oiU=",0) -> 0 | AM4: =AND(Sheet1!A136,"fcaKe1x6oiY=") -> #VALUE! | AN4: =AND(Sheet1!B136,"fcaKe1x6oic=") -> #VALUE! | AO4: =AND(Sheet1!C136,"fcaKe1x6oig=") -> #VALUE! | AP4: =AND(Sheet1!D136,"fcaKe1x6oik=") -> #VALUE! | AQ4: =IF(Sheet1!137:137,"fcaKe1x6oio=",0) -> 0 | AR4: =AND(Sheet1!A137,"fcaKe1x6ois=") -> #VALUE! | AS4: =AND(Sheet1!B137,"fcaKe1x6oiw=") -> #VALUE! | AT4: =AND(Sheet1!C137,"fcaKe1x6oi0=") -> #VALUE! | AU4: =AND(Sheet1!D137,"fcaKe1x6oi4=") -> #VALUE! | AV4: =IF(Sheet1!138:138,"fcaKe1x6oi8=",0) -> 0 | AW4: =AND(Sheet1!A138,"fcaKe1x6ojA=") -> #VALUE! | AX4: =AND(Sheet1!B138,"fcaKe1x6ojE=") -> #VALUE! | AY4: =AND(Sheet1!C138,"fcaKe1x6ojI=") -> #VALUE! | AZ4: =AND(Sheet1!D138,"fcaKe1x6ojM=") -> #VALUE! | BA4: =IF(Sheet1!139:139,"fcaKe1x6ojQ=",0) -> 0 | BB4: =AND(Sheet1!A139,"fcaKe1x6ojU=") -> #VALUE! | BC4: =AND(Sheet1!B139,"fcaKe1x6ojY=") -> #VALUE! | BD4: =AND(Sheet1!C139,"fcaKe1x6ojc=") -> #VALUE! | BE4: =AND(Sheet1!D139,"fcaKe1x6ojg=") -> #VALUE! | BF4: =IF(Sheet1!140:140,"fcaKe1x6ojk=",0) -> 0 | BG4: =AND(Sheet1!A140,"fcaKe1x6ojo=") -> #VALUE! | BH4: =AND(Sheet1!B140,"fcaKe1x6ojs=") -> #VALUE! | BI4: =AND(Sheet1!C140,"fcaKe1x6ojw=") -> #VALUE! | BJ4: =AND(Sheet1!D140,"fcaKe1x6oj0=") -> #VALUE! | BK4: =IF(Sheet1!141:141,"fcaKe1x6oj4=",0) -> 0 | BL4: =AND(Sheet1!A141,"fcaKe1x6oj8=") -> #VALUE! | BM4: =AND(Sheet1!B141,"fcaKe1x6okA=") -> #VALUE! | BN4: =AND(Sheet1!C141,"fcaKe1x6okE=") -> #VALUE! | BO4: =AND(Sheet1!D141,"fcaKe1x6okI=") -> #VALUE! | BP4: =IF(Sheet1!142:142,"fcaKe1x6okM=",0) -> 0 | BQ4: =AND(Sheet1!A142,"fcaKe1x6okQ=") -> #VALUE! | BR4: =AND(Sheet1!B142,"fcaKe1x6okU=") -> #VALUE! | BS4: =AND(Sheet1!C142,"fcaKe1x6okY=") -> #VALUE! | BT4: =AND(Sheet1!D142,"fcaKe1x6okc=") -> #VALUE! | BU4: =IF(Sheet1!143:143,"fcaKe1x6okg=",0) -> 0 | BV4: =AND(Sheet1!A143,"fcaKe1x6okk=") -> #VALUE! | BW4: =AND(Sheet1!B143,"fcaKe1x6oko=") -> #VALUE! | BX4: =AND(Sheet1!C143,"fcaKe1x6oks=") -> #VALUE! | BY4: =AND(Sheet1!D143,"fcaKe1x6okw=") -> #VALUE! | BZ4: =IF(Sheet1!144:144,"fcaKe1x6ok0=",0) -> 0 | CA4: =AND(Sheet1!A144,"fcaKe1x6ok4=") -> #VALUE! | CB4: =AND(Sheet1!B144,"fcaKe1x6ok8=") -> #VALUE! | CC4: =AND(Sheet1!C144,"fcaKe1x6olA=") -> #VALUE! | CD4: =AND(Sheet1!D144,"fcaKe1x6olE=") -> #VALUE! | CE4: =IF(Sheet1!#REF!,"fcaKe1x6olI=",0) -> #REF! | CF4: =AND(Sheet1!#REF!,"fcaKe1x6olM=") -> #REF! | CG4: =AND(Sheet1!#REF!,"fcaKe1x6olQ=") -> #REF! | CH4: =AND(Sheet1!#REF!,"fcaKe1x6olU=") -> #REF! | CI4: =AND(Sheet1!#REF!,"fcaKe1x6olY=") -> #REF! | CJ4: =IF(Sheet1!145:145,"fcaKe1x6olc=",0) -> 0 | CK4: =AND(Sheet1!A145,"fcaKe1x6olg=") -> #VALUE! | CL4: =AND(Sheet1!B145,"fcaKe1x6olk=") -> #VALUE! | CM4: =AND(Sheet1!C145,"fcaKe1x6olo=") -> #VALUE! | CN4: =AND(Sheet1!D145,"fcaKe1x6ols=") -> #VALUE! | CO4: =IF(Sheet1!#REF!,"fcaKe1x6olw=",0) -> #REF! | CP4: =AND(Sheet1!#REF!,"fcaKe1x6ol0=") -> #REF! | CQ4: =AND(Sheet1!#REF!,"fcaKe1x6ol4=") -> #REF! | CR4: =AND(Sheet1!#REF!,"fcaKe1x6ol8=") -> #REF! | CS4: =AND(Sheet1!#REF!,"fcaKe1x6omA=") -> #REF! | CT4: =IF(Sheet1!146:146,"fcaKe1x6omE=",0) -> 0 | CU4: =AND(Sheet1!A146,"fcaKe1x6omI=") -> #VALUE! | CV4: =AND(Sheet1!B146,"fcaKe1x6omM=") -> #VALUE! | CW4: =AND(Sheet1!C146,"fcaKe1x6omQ=") -> #VALUE! | CX4: =AND(Sheet1!D146,"fcaKe1x6omU=") -> #VALUE! | CY4: =IF(Sheet1!147:147,"fcaKe1x6omY=",0) -> 0 | CZ4: =AND(Sheet1!A147,"fcaKe1x6omc=") -> #VALUE! | DA4: =AND(Sheet1!B147,"fcaKe1x6omg=") -> #VALUE! | DB4: =AND(Sheet1!C147,"fcaKe1x6omk=") -> #VALUE! | DC4: =AND(Sheet1!D147,"fcaKe1x6omo=") -> #VALUE! | DD4: =IF(Sheet1!148:148,"fcaKe1x6oms=",0) -> 0 | DE4: =AND(Sheet1!A148,"fcaKe1x6omw=") -> #VALUE! | DF4: =AND(Sheet1!B148,"fcaKe1x6om0=") -> #VALUE! | DG4: =AND(Sheet1!C148,"fcaKe1x6om4=") -> #VALUE! | DH4: =AND(Sheet1!D148,"fcaKe1x6om8=") -> #VALUE! | DI4: =IF(Sheet1!#REF!,"fcaKe1x6onA=",0) -> #REF! | DJ4: =AND(Sheet1!#REF!,"fcaKe1x6onE=") -> #REF! | DK4: =AND(Sheet1!#REF!,"fcaKe1x6onI=") -> #REF! | DL4: =AND(Sheet1!#REF!,"fcaKe1x6onM=") -> #REF! | DM4: =AND(Sheet1!#REF!,"fcaKe1x6onQ=") -> #REF! | DN4: =IF(Sheet1!149:149,"fcaKe1x6onU=",0) -> 0 | DO4: =AND(Sheet1!A149,"fcaKe1x6onY=") -> #VALUE! | DP4: =AND(Sheet1!B149,"fcaKe1x6onc=") -> #VALUE! | DQ4: =AND(Sheet1!C149,"fcaKe1x6ong=") -> #VALUE! | DR4: =AND(Sheet1!D149,"fcaKe1x6onk=") -> #VALUE! | DS4: =IF(Sheet1!150:150,"fcaKe1x6ono=",0) -> 0 | DT4: =AND(Sheet1!A150,"fcaKe1x6ons=") -> #VALUE! | DU4: =AND(Sheet1!B150,"fcaKe1x6onw=") -> #VALUE! | DV4: =AND(Sheet1!C150,"fcaKe1x6on0=") -> #VALUE! | DW4: =AND(Sheet1!D150,"fcaKe1x6on4=") -> #VALUE! | DX4: =IF(Sheet1!151:151,"fcaKe1x6on8=",0) -> 0 | DY4: =AND(Sheet1!A151,"fcaKe1x6ooA=") -> #VALUE! | DZ4: =AND(Sheet1!B151,"fcaKe1x6ooE=") -> #VALUE! | EA4: =AND(Sheet1!C151,"fcaKe1x6ooI=") -> #VALUE! | EB4: =AND(Sheet1!D151,"fcaKe1x6ooM=") -> #VALUE! | EC4: =IF(Sheet1!152:152,"fcaKe1x6ooQ=",0) -> 0 | ED4: =AND(Sheet1!A152,"fcaKe1x6ooU=") -> #VALUE! | EE4: =AND(Sheet1!B152,"fcaKe1x6ooY=") -> #VALUE! | EF4: =AND(Sheet1!C152,"fcaKe1x6ooc=") -> #VALUE! | EG4: =AND(Sheet1!D152,"fcaKe1x6oog=") -> #VALUE! | EH4: =IF(Sheet1!#REF!,"fcaKe1x6ook=",0) -> #REF! | EI4: =AND(Sheet1!#REF!,"fcaKe1x6ooo=") -> #REF! | EJ4: =AND(Sheet1!#REF!,"fcaKe1x6oos=") -> #REF! | EK4: =AND(Sheet1!#REF!,"fcaKe1x6oow=") -> #REF! | EL4: =AND(Sheet1!#REF!,"fcaKe1x6oo0=") -> #REF! | EM4: =IF(Sheet1!153:153,"fcaKe1x6oo4=",0) -> 0 | EN4: =AND(Sheet1!A153,"fcaKe1x6oo8=") -> #VALUE! | EO4: =AND(Sheet1!B153,"fcaKe1x6opA=") -> #VALUE! | EP4: =AND(Sheet1!C153,"fcaKe1x6opE=") -> #VALUE! | EQ4: =AND(Sheet1!D153,"fcaKe1x6opI=") -> #VALUE! | ER4: =IF(Sheet1!154:154,"fcaKe1x6opM=",0) -> 0 | ES4: =AND(Sheet1!A154,"fcaKe1x6opQ=") -> #VALUE! | ET4: =AND(Sheet1!B154,"fcaKe1x6opU=") -> #VALUE! | EU4: =AND(Sheet1!C154,"fcaKe1x6opY=") -> #VALUE! | EV4: =AND(Sheet1!D154,"fcaKe1x6opc=") -> #VALUE! | EW4: =IF(Sheet1!155:155,"fcaKe1x6opg=",0) -> 0 | EX4: =AND(Sheet1!A155,"fcaKe1x6opk=") -> #VALUE! | EY4: =AND(Sheet1!B155,"fcaKe1x6opo=") -> #VALUE! | EZ4: =AND(Sheet1!C155,"fcaKe1x6ops=") -> #VALUE! | FA4: =AND(Sheet1!D155,"fcaKe1x6opw=") -> #VALUE! | FB4: =IF(Sheet1!#REF!,"fcaKe1x6op0=",0) -> #REF! | FC4: =AND(Sheet1!#REF!,"fcaKe1x6op4=") -> #REF! | FD4: =AND(Sheet1!#REF!,"fcaKe1x6op8=") -> #REF! | FE4: =AND(Sheet1!#REF!,"fcaKe1x6oqA=") -> #REF! | FF4: =AND(Sheet1!#REF!,"fcaKe1x6oqE=") -> #REF! | FG4: =IF(Sheet1!156:156,"fcaKe1x6oqI=",0) -> 0 | FH4: =AND(Sheet1!A156,"fcaKe1x6oqM=") -> #VALUE! | FI4: =AND(Sheet1!B156,"fcaKe1x6oqQ=") -> #VALUE! | FJ4: =AND(Sheet1!C156,"fcaKe1x6oqU=") -> #VALUE! | FK4: =AND(Sheet1!D156,"fcaKe1x6oqY=") -> #VALUE! | FL4: =IF(Sheet1!#REF!,"fcaKe1x6oqc=",0) -> #REF! | FM4: =AND(Sheet1!#REF!,"fcaKe1x6oqg=") -> #REF! | FN4: =AND(Sheet1!#REF!,"fcaKe1x6oqk=") -> #REF! | FO4: =AND(Sheet1!#REF!,"fcaKe1x6oqo=") -> #REF! | FP4: =AND(Sheet1!#REF!,"fcaKe1x6oqs=") -> #REF! | FQ4: =IF(Sheet1!#REF!,"fcaKe1x6oqw=",0) -> #REF! | FR4: =AND(Sheet1!#REF!,"fcaKe1x6oq0=") -> #REF! | FS4: =AND(Sheet1!#REF!,"fcaKe1x6oq4=") -> #REF! | FT4: =AND(Sheet1!#REF!,"fcaKe1x6oq8=") -> #REF! | FU4: =AND(Sheet1!#REF!,"fcaKe1x6orA=") -> #REF! | FV4: =IF(Sheet1!157:157,"fcaKe1x6orE=",0) -> 0 | FW4: =AND(Sheet1!A157,"fcaKe1x6orI=") -> #VALUE! | FX4: =AND(Sheet1!B157,"fcaKe1x6orM=") -> #VALUE! | FY4: =AND(Sheet1!C157,"fcaKe1x6orQ=") -> #VALUE! | FZ4: =AND(Sheet1!D157,"fcaKe1x6orU=") -> #VALUE! | GA4: =IF(Sheet1!#REF!,"fcaKe1x6orY=",0) -> #REF! | GB4: =AND(Sheet1!#REF!,"fcaKe1x6orc=") -> #REF! | GC4: =AND(Sheet1!#REF!,"fcaKe1x6org=") -> #REF! | GD4: =AND(Sheet1!#REF!,"fcaKe1x6ork=") -> #REF! | GE4: =AND(Sheet1!#REF!,"fcaKe1x6oro=") -> #REF! | GF4: =IF(Sheet1!158:158,"fcaKe1x6ors=",0) -> 0 | GG4: =AND(Sheet1!A158,"fcaKe1x6orw=") -> #VALUE! | GH4: =AND(Sheet1!B158,"fcaKe1x6or0=") -> #VALUE! | GI4: =AND(Sheet1!C158,"fcaKe1x6or4=") -> #VALUE! | GJ4: =AND(Sheet1!D158,"fcaKe1x6or8=") -> #VALUE! | GK4: =IF(Sheet1!#REF!,"fcaKe1x6osA=",0) -> #REF! | GL4: =AND(Sheet1!#REF!,"fcaKe1x6osE=") -> #REF! | GM4: =AND(Sheet1!#REF!,"fcaKe1x6osI=") -> #REF! | GN4: =AND(Sheet1!#REF!,"fcaKe1x6osM=") -> #REF! | GO4: =AND(Sheet1!#REF!,"fcaKe1x6osQ=") -> #REF! | GP4: =IF(Sheet1!159:159,"fcaKe1x6osU=",0) -> 0 | GQ4: =AND(Sheet1!A159,"fcaKe1x6osY=") -> #VALUE! | GR4: =AND(Sheet1!B159,"fcaKe1x6osc=") -> #VALUE! | GS4: =AND(Sheet1!C159,"fcaKe1x6osg=") -> #VALUE! | GT4: =AND(Sheet1!D159,"fcaKe1x6osk=") -> #VALUE! | GU4: =IF(Sheet1!#REF!,"fcaKe1x6oso=",0) -> #REF! | GV4: =AND(Sheet1!#REF!,"fcaKe1x6oss=") -> #REF! | GW4: =AND(Sheet1!#REF!,"fcaKe1x6osw=") -> #REF! | GX4: =AND(Sheet1!#REF!,"fcaKe1x6os0=") -> #REF! | GY4: =AND(Sheet1!#REF!,"fcaKe1x6os4=") -> #REF! | GZ4: =IF(Sheet1!160:160,"fcaKe1x6os8=",0) -> 0 | HA4: =AND(Sheet1!A160,"fcaKe1x6otA=") -> #VALUE! | HB4: =AND(Sheet1!B160,"fcaKe1x6otE=") -> #VALUE! | HC4: =AND(Sheet1!C160,"fcaKe1x6otI=") -> #VALUE! | HD4: =AND(Sheet1!D160,"fcaKe1x6otM=") -> #VALUE! | HE4: =IF(Sheet1!#REF!,"fcaKe1x6otQ=",0) -> #REF! | HF4: =AND(Sheet1!#REF!,"fcaKe1x6otU=") -> #REF! | HG4: =AND(Sheet1!#REF!,"fcaKe1x6otY=") -> #REF! | HH4: =AND(Sheet1!#REF!,"fcaKe1x6otc=") -> #REF! | HI4: =AND(Sheet1!#REF!,"fcaKe1x6otg=") -> #REF! | HJ4: =IF(Sheet1!#REF!,"fcaKe1x6otk=",0) -> #REF! | HK4: =AND(Sheet1!#REF!,"fcaKe1x6oto=") -> #REF! | HL4: =AND(Sheet1!#REF!,"fcaKe1x6ots=") -> #REF! | HM4: =AND(Sheet1!#REF!,"fcaKe1x6otw=") -> #REF! | HN4: =AND(Sheet1!#REF!,"fcaKe1x6ot0=") -> #REF! | HO4: =IF(Sheet1!#REF!,"fcaKe1x6ot4=",0) -> #REF! | HP4: =AND(Sheet1!#REF!,"fcaKe1x6ot8=") -> #REF! | HQ4: =AND(Sheet1!#REF!,"fcaKe1x6ouA=") -> #REF! | HR4: =AND(Sheet1!#REF!,"fcaKe1x6ouE=") -> #REF! | HS4: =AND(Sheet1!#REF!,"fcaKe1x6ouI=") -> #REF! | HT4: =IF(Sheet1!#REF!,"fcaKe1x6ouM=",0) -> #REF! | HU4: =AND(Sheet1!#REF!,"fcaKe1x6ouQ=") -> #REF! | HV4: =AND(Sheet1!#REF!,"fcaKe1x6ouU=") -> #REF! | HW4: =AND(Sheet1!#REF!,"fcaKe1x6ouY=") -> #REF! | HX4: =AND(Sheet1!#REF!,"fcaKe1x6ouc=") -> #REF! | HY4: =IF(Sheet1!#REF!,"fcaKe1x6oug=",0) -> #REF! | HZ4: =AND(Sheet1!#REF!,"fcaKe1x6ouk=") -> #REF! | IA4: =AND(Sheet1!#REF!,"fcaKe1x6ouo=") -> #REF! | IB4: =AND(Sheet1!#REF!,"fcaKe1x6ous=") -> #REF! | IC4: =AND(Sheet1!#REF!,"fcaKe1x6ouw=") -> #REF! | ID4: =IF(Sheet1!#REF!,"fcaKe1x6ou0=",0) -> #REF! | IE4: =AND(Sheet1!#REF!,"fcaKe1x6ou4=") -> #REF! | IF4: =AND(Sheet1!#REF!,"fcaKe1x6ou8=") -> #REF! | IG4: =AND(Sheet1!#REF!,"fcaKe1x6ovA=") -> #REF! | IH4: =AND(Sheet1!#REF!,"fcaKe1x6ovE=") -> #REF! | II4: =IF(Sheet1!#REF!,"fcaKe1x6ovI=",0) -> #REF! | IJ4: =AND(Sheet1!#REF!,"fcaKe1x6ovM=") -> #REF! | IK4: =AND(Sheet1!#REF!,"fcaKe1x6ovQ=") -> #REF! | IL4: =AND(Sheet1!#REF!,"fcaKe1x6ovU=") -> #REF! | IM4: =AND(Sheet1!#REF!,"fcaKe1x6ovY=") -> #REF! | IN4: =IF(Sheet1!#REF!,"fcaKe1x6ovc=",0) -> #REF! | IO4: =AND(Sheet1!#REF!,"fcaKe1x6ovg=") -> #REF! | IP4: =AND(Sheet1!#REF!,"fcaKe1x6ovk=") -> #REF! | IQ4: =AND(Sheet1!#REF!,"fcaKe1x6ovo=") -> #REF! | IR4: =AND(Sheet1!#REF!,"fcaKe1x6ovs=") -> #REF! | IS4: =IF(Sheet1!161:161,"fcaKe1x6ovw=",0) -> 0 | IT4: =AND(Sheet1!A161,"fcaKe1x6ov0=") -> #VALUE! | IU4: =AND(Sheet1!B161,"fcaKe1x6ov4=") -> #VALUE! | IV4: =AND(Sheet1!C161,"fcaKe1x6ov8=") -> #VALUE!
