Workbook

Sheet Exh 1
B1: Expected | D1: Expected | E1: Booked | F1: Estimated | G1: Premium
A2: Policy | B2: Future Loss | D2: Future | E2: Prem From | F2: Total | G2: Booked @ | H2: Premium
A3: Period | B3: Emergence | C3: CPDLD | D3: Premium | E3: Prior Adj. | F3: Premium | G3: 34699 | H3: Asset
A4: 1987.1 to 1987.4 | B4: ='Exh 2'!J7 -> -262 | C4: ='Exh 3'!H12 -> 0 | D4: =B4*C4 -> 0 | E4: =SUM('Exh 4'!C18:C21,'Exh 4'!G18:G21,'Exh 4'!K18:K21,'Exh 4'!O18:O21,'Exh 4'!S18:S21,'Exh 4'!W18:W21) -> 494928 | F4: =D4+E4 -> 494928 | G4: ='Exh 6'!AD21+'Exh 6'!AD20+'Exh 6'!AD19+'Exh 6'!AD18 -> 494928 | H4: =F4-G4 -> 0
A5: 1988.1 to 1988.4 | B5: ='Exh 2'!J11 -> 3438.1712 | C5: ='Exh 3'!H11 -> 0.31785967 | D5: =B5*C5 -> 1092.856 | E5: =SUM('Exh 4'!C22:C25,'Exh 4'!G22:G25,'Exh 4'!K22:K25,'Exh 4'!O22:O25,'Exh 4'!S22:S25) -> 467489 | F5: =D5+E5 -> 468581.86 | G5: ='Exh 6'!Z25+'Exh 6'!AA24+'Exh 6'!AB23+'Exh 6'!AC22 -> 467896 | H5: =F5-G5 -> 685.85597
A6: 1989.1 to 1989.4 | B6: ='Exh 2'!J15 -> 9254.3045 | C6: ='Exh 3'!H10 -> 0.36660132 | D6: =B6*C6 -> 3392.6403 | E6: =SUM('Exh 4'!C26:C29,'Exh 4'!G26:G29,'Exh 4'!K26:K29,'Exh 4'!O26:O29) -> 460659 | F6: =D6+E6 -> 464051.64 | G6: ='Exh 6'!V29+'Exh 6'!W28+'Exh 6'!X27+'Exh 6'!Y26 -> 460716 | H6: =F6-G6 -> 3335.6403
A7: 1990.1 to 1990.4 | B7: ='Exh 2'!J19 -> 21508.951 | C7: ='Exh 3'!H9 -> 0.3963196 | D7: =B7*C7 -> 8524.4189 | E7: =SUM('Exh 4'!C30:C33)+SUM('Exh 4'!G30:G33)+SUM('Exh 4'!K30:K33) -> 453525 | F7: =D7+E7 -> 462049.42 | G7: ='Exh 6'!R33+'Exh 6'!S32+'Exh 6'!T31+'Exh 6'!U30 -> 452519 | H7: =F7-G7 -> 9530.4189
A8: 1991.1 to 1991.4 | B8: ='Exh 2'!J23 -> 25022.628 | C8: ='Exh 3'!H8 -> 0.45237038 | D8: =B8*C8 -> 11319.496 | E8: =SUM('Exh 4'!C34:C37)+SUM('Exh 4'!G34:G37) -> 336654 | F8: =D8+E8 -> 347973.5 | G8: ='Exh 6'!N37+'Exh 6'!O36+'Exh 6'!P35+'Exh 6'!Q34 -> 337966 | H8: =F8-G8 -> 10007.496
A9: 1992.1 to 1992.4 | B9: ='Exh 2'!J27 -> 56244.492 | C9: ='Exh 3'!H7 -> 0.55808169 | D9: =B9*C9 -> 31389.021 | E9: =SUM('Exh 4'!C38:C41) -> 328777 | F9: =D9+E9 -> 360166.02 | G9: ='Exh 6'!J41+'Exh 6'!K40+'Exh 6'!L39+'Exh 6'!M38 -> 330216 | H9: =F9-G9 -> 29950.021
A10: 1993.1 to 1994.4 | B10: ='Exh 2'!J31+'Exh 2'!J35 -> 279947.89 | C10: ='Exh 3'!H6 -> 1.4970786 | D10: =B10*C10 -> 419104.01 | F10: =D10+E10 -> 419104.01 | G10: ='Exh 6'!B49+'Exh 6'!C48+'Exh 6'!D47+'Exh 6'!E46+'Exh 6'!F45+'Exh 6'!G44+'Exh 6'!H43+'Exh 6'!I42 -> 425591 | H10: =F10-G10 -> -6486.9898

Sheet Exh 2
A1: Policy | B1: Reported | D1: % Earned | G1: Reported | I1: Expected
A2: Effective | B2: Losses @ | C2: LDF | D2: at | E2: Ultimate | F2: Annual | G2: Losses @ | H2: Annual | I2: Loss | J2: Annual
A3: Quarter | B3: 34699 | C3: to Ult | D3: 34699 | E3: Losses | F3: Total | G3: Prior Retro Adj. | H3: Total | I3: Emergence | J3: Total
A4: 1987.1 | B4: ='Exh 7'!AD18 -> 102064 | C4: =C5 -> 1 | D4: 1 | E4: =B4*C4*D4 -> 102064 | G4: ='Exh 7'!AA18 -> 102059 | I4: =E4-G4 -> 5
A5: 1987.2 | B5: ='Exh 7'!AD19 -> 65339 | C5: =C6 -> 1 | D5: 1 | E5: =B5*C5*D5 -> 65339 | G5: ='Exh 7'!AA19 -> 65264 | I5: =E5-G5 -> 75
A6: 1987.3 | B6: ='Exh 7'!AD20 -> 155738 | C6: ='Exh 7'!AE55 -> 1 | D6: 1 | E6: =B6*C6*D6 -> 155738 | G6: ='Exh 7'!AA20 -> 155950 | I6: =E6-G6 -> -212
A7: 1987.4 | B7: ='Exh 7'!AD21 -> 94067 | C7: ='Exh 7'!AD55 -> 1 | D7: 1 | E7: =B7*C7*D7 -> 94067 | F7: =SUM(E4:E7) -> 417208 | G7: ='Exh 7'!AA21 -> 94197 | H7: =SUM(G4:G7) -> 417470 | I7: =E7-G7 -> -130 | J7: =SUM(I4:I7) -> -262
A8: 1988.1 | B8: ='Exh 7'!AC22 -> 88908 | C8: ='Exh 7'!AC55 -> 1.0017099 | D8: 1 | E8: =B8*C8*D8 -> 89060.021 | G8: ='Exh 7'!W22 -> 87781 | I8: =E8-G8 -> 1279.0213
A9: 1988.2 | B9: ='Exh 7'!AB23 -> 57763 | C9: ='Exh 7'!AB55 -> 1.0023314 | D9: 1 | E9: =B9*C9*D9 -> 57897.67 | G9: ='Exh 7'!W23 -> 58054 | I9: =E9-G9 -> -156.3298
A10: 1988.3 | B10: ='Exh 7'!AA24 -> 152121 | C10: ='Exh 7'!AA55 -> 1.0041694 | D10: 1 | E10: =B10*C10*D10 -> 152755.25 | G10: ='Exh 7'!W24 -> 151031 | I10: =E10-G10 -> 1724.2493
A11: 1988.4 | B11: ='Exh 7'!Z25 -> 96809 | C11: ='Exh 7'!Z55 -> 1.0100324 | D11: 1 | E11: =B11*C11*D11 -> 97780.23 | F11: =SUM(E8:E11) -> 397493.17 | G11: ='Exh 7'!W25 -> 97189 | H11: =SUM(G8:G11) -> 394055 | I11: =E11-G11 -> 591.23041 | J11: =SUM(I8:I11) -> 3438.1712
A12: 1989.1 | B12: ='Exh 7'!Y26 -> 81384 | C12: ='Exh 7'!Y55 -> 1.0105316 | D12: 1 | E12: =B12*C12*D12 -> 82241.104 | G12: ='Exh 7'!S26 -> 80475 | I12: =E12-G12 -> 1766.1036
A13: 1989.2 | B13: ='Exh 7'!X27 -> 55898 | C13: ='Exh 7'!X55 -> 1.0126993 | D13: 1 | E13: =B13*C13*D13 -> 56607.864 | G13: ='Exh 7'!S27 -> 55541 | I13: =E13-G13 -> 1066.8635
A14: 1989.3 | B14: ='Exh 7'!W28 -> 131539 | C14: ='Exh 7'!W55 -> 1.0206366 | D14: 1 | E14: =B14*C14*D14 -> 134253.52 | G14: ='Exh 7'!S28 -> 130944 | I14: =E14-G14 -> 3309.5203
A15: 1989.4 | B15: ='Exh 7'!V29 -> 91423 | C15: ='Exh 7'!V55 -> 1.0300451 | D15: 1 | E15: =B15*C15*D15 -> 94169.817 | F15: =SUM(E12:E15) -> 367272.3 | G15: ='Exh 7'!S29 -> 91058 | H15: =SUM(G12:G15) -> 358018 | I15: =E15-G15 -> 3111.8171 | J15: =SUM(I12:I15) -> 9254.3045
A16: 1990.1 | B16: ='Exh 7'!U30 -> 89715 | C16: ='Exh 7'!U55 -> 1.0326155 | D16: 1 | E16: =B16*C16*D16 -> 92641.101 | G16: ='Exh 7'!O30 -> 87639 | I16: =E16-G16 -> 5002.1008
A17: 1990.2 | B17: ='Exh 7'!T31 -> 56032 | C17: ='Exh 7'!T55 -> 1.039864 | D17: 1 | E17: =B17*C17*D17 -> 58265.657 | G17: ='Exh 7'!O31 -> 54473 | I17: =E17-G17 -> 3792.6569
A18: 1990.3 | B18: ='Exh 7'!S32 -> 118268 | C18: ='Exh 7'!S55 -> 1.0523295 | D18: 1 | E18: =B18*C18*D18 -> 124456.9 | G18: ='Exh 7'!O32 -> 117202 | I18: =E18-G18 -> 7254.901
A19: 1990.4 | B19: ='Exh 7'!R33 -> 73037 | C19: ='Exh 7'!R55 -> 1.0637799 | D19: 1 | E19: =B19*C19*D19 -> 77695.292 | F19: =SUM(E16:E19) -> 353058.95 | G19: ='Exh 7'!O33 -> 72236 | H19: =SUM(G16:G19) -> 331550 | I19: =E19-G19 -> 5459.2923 | J19: =SUM(I16:I19) -> 21508.951
A20: 1991.1 | B20: ='Exh 7'!Q34 -> 60399 | C20: ='Exh 7'!Q55 -> 1.064944 | D20: 1 | E20: =B20*C20*D20 -> 64321.553 | G20: ='Exh 7'!K34 -> 57620 | I20: =E20-G20 -> 6701.5531
A21: 1991.2 | B21: ='Exh 7'!P35 -> 34136 | C21: ='Exh 7'!P55 -> 1.0663544 | D21: 1 | E21: =B21*C21*D21 -> 36401.073 | G21: ='Exh 7'!K35 -> 33064 | I21: =E21-G21 -> 3337.0727
A22: 1991.3 | B22: ='Exh 7'!O36 -> 60696 | C22: ='Exh 7'!O55 -> 1.0837254 | D22: 1 | E22: =B22*C22*D22 -> 65777.797 | G22: ='Exh 7'!K36 -> 58493 | I22: =E22-G22 -> 7284.7972
A23: 1991.4 | B23: ='Exh 7'!N37 -> 61068 | C23: ='Exh 7'!N55 -> 1.0984346 | D23: 1 | E23: =B23*C23*D23 -> 67079.205 | F23: =SUM(E20:E23) -> 233579.63 | G23: ='Exh 7'!K37 -> 59380 | H23: =SUM(G20:G23) -> 208557 | I23: =E23-G23 -> 7699.2054 | J23: =SUM(I20:I23) -> 25022.628
A24: 1992.1 | B24: ='Exh 7'!M38 -> 53455 | C24: ='Exh 7'!M55 -> 1.1048098 | D24: 1 | E24: =B24*C24*D24 -> 59057.608 | G24: ='Exh 7'!G38 -> 49161 | I24: =E24-G24 -> 9896.6084
A25: 1992.2 | B25: ='Exh 7'!L39 -> 37393 | C25: ='Exh 7'!L55 -> 1.110285 | D25: 1 | E25: =B25*C25*D25 -> 41516.885 | G25: ='Exh 7'!G39 -> 33060 | I25: =E25-G25 -> 8456.8851
A26: 1992.3 | B26: ='Exh 7'!K40 -> 62118 | C26: ='Exh 7'!K55 -> 1.1384485 | D26: 1 | E26: =B26*C26*D26 -> 70718.144 | G26: ='Exh 7'!G40 -> 53069 | I26: =E26-G26 -> 17649.144
A27: 1992.4 | B27: ='Exh 7'!J41 -> 50766 | C27: ='Exh 7'!J55 -> 1.2809135 | D27: 1 | E27: =B27*C27*D27 -> 65026.854 | F27: =SUM(E24:E27) -> 236319.49 | G27: ='Exh 7'!G41 -> 44785 | H27: =SUM(G24:G27) -> 180075 | I27: =E27-G27 -> 20241.854 | J27: =SUM(I24:I27) -> 56244.492
A28: 1993.1 | B28: ='Exh 7'!I42 -> 39519 | C28: ='Exh 7'!I55 -> 1.1782597 | D28: 1 | E28: =B28*C28*D28 -> 46563.644 | G28: 0 | I28: =E28-G28 -> 46563.644
A29: 1993.2 | B29: ='Exh 7'!H43 -> 30286 | C29: ='Exh 7'!H55 -> 1.2087398 | D29: 1 | E29: =B29*C29*D29 -> 36607.895 | G29: 0 | I29: =E29-G29 -> 36607.895
A30: 1993.3 | B30: ='Exh 7'!G44 -> 51005 | C30: ='Exh 7'!G55 -> 1.2693527 | D30: 1 | E30: =B30*C30*D30 -> 64743.335 | G30: 0 | I30: =E30-G30 -> 64743.335
A31: 1993.4 | B31: ='Exh 7'!F45 -> 34516 | C31: ='Exh 7'!F55 -> 1.386046 | D31: 1 | E31: =B31*C31*D31 -> 47840.762 | F31: =SUM(E28:E31) -> 195755.64 | G31: 0 | H31: =SUM(G28:G31) -> 0 | I31: =E31-G31 -> 47840.762 | J31: =SUM(I28:I31) -> 195755.64
A32: 1994.1 | B32: ='Exh 7'!E46 -> 21189 | C32: ='Exh 7'!E55 -> 1.6525483 | D32: 0.9 | E32: =B32*C32*D32 -> 31514.26 | G32: 0 | I32: =E32-G32 -> 31514.26
A33: 1994.2 | B33: ='Exh 7'!D47 -> 11381 | C33: ='Exh 7'!D55 -> 2.464806 | D33: 0.7 | E33: =B33*C33*D33 -> 19636.37 | G33: 0 | I33: =E33-G33 -> 19636.37
A34: 1994.3 | B34: ='Exh 7'!C48 -> 14339 | C34: ='Exh 7'!C55 -> 4.3718972 | D34: 0.45 | E34: =B34*C34*D34 -> 28209.885 | G34: 0 | I34: =E34-G34 -> 28209.885
A35: 1994.4 | B35: ='Exh 7'!B49 -> 1862 | C35: ='Exh 7'!B55 -> 12.974603 | D35: 0.2 | E35: =B35*C35*D35 -> 4831.7423 | F35: =SUM(E32:E35) -> 84192.258 | G35: 0 | H35: =SUM(G32:G35) -> 0 | I35: =E35-G35 -> 4831.7423 | J35: =SUM(I32:I35) -> 84192.258
A37: Total | B37: =SUM(B4:B35) -> 2134233 | E37: =SUM(E4:E35) -> 2284879.4 | F37: =SUM(F4:F35) -> 2284879.4 | G37: =SUM(G4:G35) -> 1889725 | H37: =SUM(H4:H35) -> 1889725 | I37: =SUM(I4:I35) -> 395154.44 | J37: =SUM(J4:J35) -> 395154.44

Sheet Exh 3
D2: Quick | E2: Slow
A3: Retro | F3: Prior Col. | G3: % Loss
A4: Adj. | B4: Selected | C4: % Loss | E4: PDLD x | F4: Upward | G4: Upward
A5: Periods | B5: PDLD | C5: Emerged | D5: CPDLD | E5: Loss Emg | F5: Cumulative | G5: Cumulative | H5: CPDLD
A6: 1 | B6: ='Exh 4'!D55 -> 1.75 | C6: ='Exh 5'!C6 -> 0.7878031 | D6: =SUMPRODUCT(B6:$B$12,C6:$C$12)/SUM(C6:$C$12) -> 1.4970786 | E6: =B6*C6 -> 1.3786554 | F6: =F7+E6 -> 1.4970786 | G6: =G7+C6 -> 1 | H6: =F6/G6 -> 1.4970786
A7: 2 | B7: ='Exh 4'!H55 -> 0.7 | C7: ='Exh 5'!C7-'Exh 5'!C6 -> 0.090585334 | D7: =SUMPRODUCT(B7:$B$12,C7:$C$12)/SUM(C7:$C$12) -> 0.55808169 | E7: =B7*C7 -> 0.063409734 | F7: =F8+E7 -> 0.11842321 | G7: =G8+C7 -> 0.2121969 | H7: =F7/G7 -> 0.55808169
A8: 3 | B8: ='Exh 4'!L55 -> 0.55 | C8: ='Exh 5'!C8-'Exh 5'!C7 -> 0.044354539 | D8: =SUMPRODUCT(B8:$B$12,C8:$C$12)/SUM(C8:$C$12) -> 0.45237038 | E8: =B8*C8 -> 0.024394997 | F8: =F9+E8 -> 0.055013472 | G8: =G9+C8 -> 0.12161157 | H8: =F8/G8 -> 0.45237038
A9: 4 | B9: ='Exh 4'!P55 -> 0.45 | C9: ='Exh 5'!C9-'Exh 5'!C8 -> 0.027529766 | D9: =SUMPRODUCT(B9:$B$12,C9:$C$12)/SUM(C9:$C$12) -> 0.3963196 | E9: =B9*C9 -> 0.012388395 | F9: =F10+E9 -> 0.030618475 | G9: =G10+C9 -> 0.077257029 | H9: =F9/G9 -> 0.3963196
A10: 5 | B10: ='Exh 4'!T55 -> 0.4 | C10: ='Exh 5'!C10-'Exh 5'!C9 -> 0.029507903 | D10: =SUMPRODUCT(B10:$B$12,C10:$C$12)/SUM(C10:$C$12) -> 0.36660132 | E10: =B10*C10 -> 0.011803161 | F10: =F11+E10 -> 0.01823008 | G10: =G11+C10 -> 0.049727263 | H10: =F10/G10 -> 0.36660132
A11: 6 | B11: ='Exh 4'!X55 -> 0.4 | C11: ='Exh 5'!C11-'Exh 5'!C10 -> 0.016067298 | D11: =SUMPRODUCT(B11:$B$12,C11:$C$12)/SUM(C11:$C$12) -> 0.31785967 | E11: =B11*C11 -> 0.0064269192 | F11: =F12+E11 -> 0.0064269192 | G11: =G12+C11 -> 0.02021936 | H11: =F11/G11 -> 0.31785967
A12: 7+ | B12: 0 | C12: ='Exh 5'!C12-'Exh 5'!C11 -> 0.0041520621 | D12: =SUMPRODUCT(B12:$B$12,C12:$C$12)/SUM(C12:$C$12) -> 0 | E12: =B12*C12 -> 0 | F12: =E12 -> 0 | G12: =C12 -> 0.0041520621 | H12: =F12/G12 -> 0

Sheet Exh 4
A1: Policy | B1: First Adjustment | F1: Second Adjustment | J1: Third Adjustment | N1: Fourth Adjustment | R1: Fifth Adjustment | V1: Sixth Adjustment
A2: Effective | B2: Loss | C2: Prem | F2: Loss | G2: Prem | J2: Loss | K2: Prem | N2: Loss | O2: Prem | R2: Loss | S2: Prem | V2: Loss | W2: Prem
A3: Quarter | B3: 0-18 | C3: 0-27 | D3: PDLD | F3: 19-30 | G3: 28-39 | H3: PDLD | J3: 31-42 | K3: 40-51 | L3: PDLD | N3: 43-54 | O3: 52-63 | P3: PDLD | R3: 55-66 | S3: 64-75 | T3: PDLD | V3: 67-78 | W3: 76-87 | X3: PDLD
A4: 1983.3 | B4: ='Exh 7'!G4 -> 42461 | C4: ='Exh 6'!J4 -> 52436 | D4: =C4/B4 -> 1.2349215 | F4: ='Exh 7'!K4-'Exh 7'!G4 -> 5515 | G4: ='Exh 6'!N4-'Exh 6'!J4 -> 4012 | H4: =G4/F4 -> 0.72747053 | J4: ='Exh 7'!O4-'Exh 7'!K4 -> 4532 | K4: ='Exh 6'!R4-'Exh 6'!N4 -> 2351 | L4: =K4/J4 -> 0.51875552 | N4: ='Exh 7'!S4-'Exh 7'!O4 -> 1925 | O4: ='Exh 6'!V4-'Exh 6'!R4 -> 763 | P4: =O4/N4 -> 0.39636364 | R4: ='Exh 7'!W4-'Exh 7'!S4 -> 2056 | S4: ='Exh 6'!Z4-'Exh 6'!V4 -> 713 | T4: =S4/R4 -> 0.34678988 | V4: ='Exh 7'!AA4-'Exh 7'!W4 -> 1171 | W4: ='Exh 6'!AD4-'Exh 6'!Z4 -> 255 | X4: =W4/V4 -> 0.2177626
A5: 1983.4 | B5: ='Exh 7'!G5 -> 20151 | C5: ='Exh 6'!J5 -> 26222 | D5: =C5/B5 -> 1.3012754 | F5: ='Exh 7'!K5-'Exh 7'!G5 -> 2738 | G5: ='Exh 6'!N5-'Exh 6'!J5 -> 2722 | H5: =G5/F5 -> 0.99415632 | J5: ='Exh 7'!O5-'Exh 7'!K5 -> 1480 | K5: ='Exh 6'!R5-'Exh 6'!N5 -> 576 | L5: =K5/J5 -> 0.38918919 | N5: ='Exh 7'!S5-'Exh 7'!O5 -> 1078 | O5: ='Exh 6'!V5-'Exh 6'!R5 -> 662 | P5: =O5/N5 -> 0.61410019 | R5: ='Exh 7'!W5-'Exh 7'!S5 -> 64 | S5: ='Exh 6'!Z5-'Exh 6'!V5 -> 56 | T5: =S5/R5 -> 0.875 | V5: ='Exh 7'!AA5-'Exh 7'!W5 -> 525 | W5: ='Exh 6'!AD5-'Exh 6'!Z5 -> 186 | X5: =W5/V5 -> 0.35428571
A6: 1984.1 | B6: ='Exh 7'!G6 -> 23076 | C6: ='Exh 6'!J6 -> 29189 | D6: =C6/B6 -> 1.2649073 | F6: ='Exh 7'!K6-'Exh 7'!G6 -> 2142 | G6: ='Exh 6'!N6-'Exh 6'!J6 -> 1927 | H6: =G6/F6 -> 0.89962652 | J6: ='Exh 7'!O6-'Exh 7'!K6 -> 2076 | K6: ='Exh 6'!R6-'Exh 6'!N6 -> 1086 | L6: =K6/J6 -> 0.52312139 | N6: ='Exh 7'!S6-'Exh 7'!O6 -> 1139 | O6: ='Exh 6'!V6-'Exh 6'!R6 -> 883 | P6: =O6/N6 -> 0.77524144 | R6: ='Exh 7'!W6-'Exh 7'!S6 -> 828 | S6: ='Exh 6'!Z6-'Exh 6'!V6 -> 527 | T6: =S6/R6 -> 0.63647343 | V6: ='Exh 7'!AA6-'Exh 7'!W6 -> 1123 | W6: ='Exh 6'!AD6-'Exh 6'!Z6 -> -103 | X6: =W6/V6 -> -0.091718611
A7: 1984.2 | B7: ='Exh 7'!G7 -> 19243 | C7: ='Exh 6'!J7 -> 23422 | D7: =C7/B7 -> 1.2171699 | F7: ='Exh 7'!K7-'Exh 7'!G7 -> 1133 | G7: ='Exh 6'!N7-'Exh 6'!J7 -> 1904 | H7: =G7/F7 -> 1.6804943 | J7: ='Exh 7'!O7-'Exh 7'!K7 -> 406 | K7: ='Exh 6'!R7-'Exh 6'!N7 -> 740 | L7: =K7/J7 -> 1.8226601 | N7: ='Exh 7'!S7-'Exh 7'!O7 -> 1137 | O7: ='Exh 6'!V7-'Exh 6'!R7 -> 573 | P7: =O7/N7 -> 0.50395778 | R7: ='Exh 7'!W7-'Exh 7'!S7 -> 906 | S7: ='Exh 6'!Z7-'Exh 6'!V7 -> 593 | T7: =S7/R7 -> 0.65452539 | V7: ='Exh 7'!AA7-'Exh 7'!W7 -> 165 | W7: ='Exh 6'!AD7-'Exh 6'!Z7 -> 15 | X7: =W7/V7 -> 0.090909091
A8: 1984.3 | B8: ='Exh 7'!G8 -> 54927 | C8: ='Exh 6'!J8 -> 69310 | D8: =C8/B8 -> 1.2618566 | F8: ='Exh 7'!K8-'Exh 7'!G8 -> 8900 | G8: ='Exh 6'!N8-'Exh 6'!J8 -> 6371 | H8: =G8/F8 -> 0.7158427 | J8: ='Exh 7'!O8-'Exh 7'!K8 -> 3804 | K8: ='Exh 6'!R8-'Exh 6'!N8 -> 3432 | L8: =K8/J8 -> 0.9022082 | N8: ='Exh 7'!S8-'Exh 7'!O8 -> 2950 | O8: ='Exh 6'!V8-'Exh 6'!R8 -> 1159 | P8: =O8/N8 -> 0.39288136 | R8: ='Exh 7'!W8-'Exh 7'!S8 -> 2618 | S8: ='Exh 6'!Z8-'Exh 6'!V8 -> 635 | T8: =S8/R8 -> 0.24255157 | V8: ='Exh 7'!AA8-'Exh 7'!W8 -> 2476 | W8: ='Exh 6'!AD8-'Exh 6'!Z8 -> 137 | X8: =W8/V8 -> 0.055331179
A9: 1984.4 | B9: ='Exh 7'!G9 -> 33393 | C9: ='Exh 6'!J9 -> 43305 | D9: =C9/B9 -> 1.2968287 | F9: ='Exh 7'!K9-'Exh 7'!G9 -> 4308 | G9: ='Exh 6'!N9-'Exh 6'!J9 -> 3190 | H9: =G9/F9 -> 0.74048282 | J9: ='Exh 7'!O9-'Exh 7'!K9 -> 2819 | K9: ='Exh 6'!R9-'Exh 6'!N9 -> 1273 | L9: =K9/J9 -> 0.45157857 | N9: ='Exh 7'!S9-'Exh 7'!O9 -> 1424 | O9: ='Exh 6'!V9-'Exh 6'!R9 -> 206 | P9: =O9/N9 -> 0.14466292 | R9: ='Exh 7'!W9-'Exh 7'!S9 -> 1379 | S9: ='Exh 6'!Z9-'Exh 6'!V9 -> 46 | T9: =S9/R9 -> 0.033357505 | V9: ='Exh 7'!AA9-'Exh 7'!W9 -> 1329 | W9: ='Exh 6'!AD9-'Exh 6'!Z9 -> 86 | X9: =W9/V9 -> 0.064710309
A10: 1985.1 | B10: ='Exh 7'!G10 -> 46100 | C10: ='Exh 6'!J10 -> 59203 | D10: =C10/B10 -> 1.2842299 | F10: ='Exh 7'!K10-'Exh 7'!G10 -> 3385 | G10: ='Exh 6'!N10-'Exh 6'!J10 -> 3349 | H10: =G10/F10 -> 0.98936484 | J10: ='Exh 7'!O10-'Exh 7'!K10 -> 2311 | K10: ='Exh 6'!R10-'Exh 6'!N10 -> 1347 | L10: =K10/J10 -> 0.58286456 | N10: ='Exh 7'!S10-'Exh 7'!O10 -> 1538 | O10: ='Exh 6'!V10-'Exh 6'!R10 -> 267 | P10: =O10/N10 -> 0.17360208 | R10: ='Exh 7'!W10-'Exh 7'!S10 -> 2266 | S10: ='Exh 6'!Z10-'Exh 6'!V10 -> 120 | T10: =S10/R10 -> 0.052956752 | V10: ='Exh 7'!AA10-'Exh 7'!W10 -> 528 | W10: ='Exh 6'!AD10-'Exh 6'!Z10 -> 615 | X10: =W10/V10 -> 1.1647727
A11: 1985.2 | B11: ='Exh 7'!G11 -> 27696 | C11: ='Exh 6'!J11 -> 38717 | D11: =C11/B11 -> 1.3979275 | F11: ='Exh 7'!K11-'Exh 7'!G11 -> 2679 | G11: ='Exh 6'!N11-'Exh 6'!J11 -> 2119 | H11: =G11/F11 -> 0.79096678 | J11: ='Exh 7'!O11-'Exh 7'!K11 -> 2676 | K11: ='Exh 6'!R11-'Exh 6'!N11 -> 1687 | L11: =K11/J11 -> 0.63041854 | N11: ='Exh 7'!S11-'Exh 7'!O11 -> 2026 | O11: ='Exh 6'!V11-'Exh 6'!R11 -> 773 | P11: =O11/N11 -> 0.38153998 | R11: ='Exh 7'!W11-'Exh 7'!S11 -> 1729 | S11: ='Exh 6'!Z11-'Exh 6'!V11 -> 189 | T11: =S11/R11 -> 0.10931174 | V11: ='Exh 7'!AA11-'Exh 7'!W11 -> 1072 | W11: ='Exh 6'!AD11-'Exh 6'!Z11 -> 210 | X11: =W11/V11 -> 0.19589552
A12: 1985.3 | B12: ='Exh 7'!G12 -> 96041 | C12: ='Exh 6'!J12 -> 133094 | D12: =C12/B12 -> 1.385804 | F12: ='Exh 7'!K12-'Exh 7'!G12 -> 9717 | G12: ='Exh 6'!N12-'Exh 6'!J12 -> 7926 | H12: =G12/F12 -> 0.81568385 | J12: ='Exh 7'!O12-'Exh 7'!K12 -> 6465 | K12: ='Exh 6'!R12-'Exh 6'!N12 -> 3053 | L12: =K12/J12 -> 0.47223511 | N12: ='Exh 7'!S12-'Exh 7'!O12 -> 6526 | O12: ='Exh 6'!V12-'Exh 6'!R12 -> 2670 | P12: =O12/N12 -> 0.4091327 | R12: ='Exh 7'!W12-'Exh 7'!S12 -> 6603 | S12: ='Exh 6'!Z12-'Exh 6'!V12 -> 2611 | T12: =S12/R12 -> 0.39542632 | V12: ='Exh 7'!AA12-'Exh 7'!W12 -> 3566 | W12: ='Exh 6'!AD12-'Exh 6'!Z12 -> 155 | X12: =W12/V12 -> 0.043466068
A13: 1985.4 | B13: ='Exh 7'!G13 -> 49481 | C13: ='Exh 6'!J13 -> 66351 | D13: =C13/B13 -> 1.3409389 | F13: ='Exh 7'!K13-'Exh 7'!G13 -> 7193 | G13: ='Exh 6'!N13-'Exh 6'!J13 -> 4063 | H13: =G13/F13 -> 0.56485472 | J13: ='Exh 7'!O13-'Exh 7'!K13 -> 4268 | K13: ='Exh 6'!R13-'Exh 6'!N13 -> 2560 | L13: =K13/J13 -> 0.59981256 | N13: ='Exh 7'!S13-'Exh 7'!O13 -> 3050 | O13: ='Exh 6'!V13-'Exh 6'!R13 -> 1196 | P13: =O13/N13 -> 0.39213115 | R13: ='Exh 7'!W13-'Exh 7'!S13 -> 2194 | S13: ='Exh 6'!Z13-'Exh 6'!V13 -> 1091 | T13: =S13/R13 -> 0.49726527 | V13: ='Exh 7'!AA13-'Exh 7'!W13 -> 2533 | W13: ='Exh 6'!AD13-'Exh 6'!Z13 -> 958 | X13: =W13/V13 -> 0.37820766
A14: 1986.1 | B14: ='Exh 7'!G14 -> 63095 | C14: ='Exh 6'!J14 -> 87173 | D14: =C14/B14 -> 1.381615 | F14: ='Exh 7'!K14-'Exh 7'!G14 -> 5865 | G14: ='Exh 6'!N14-'Exh 6'!J14 -> 4249 | H14: =G14/F14 -> 0.72446718 | J14: ='Exh 7'!O14-'Exh 7'!K14 -> 4045 | K14: ='Exh 6'!R14-'Exh 6'!N14 -> 2298 | L14: =K14/J14 -> 0.56810878 | N14: ='Exh 7'!S14-'Exh 7'!O14 -> 1699 | O14: ='Exh 6'!V14-'Exh 6'!R14 -> 1243 | P14: =O14/N14 -> 0.73160683 | R14: ='Exh 7'!W14-'Exh 7'!S14 -> 3519 | S14: ='Exh 6'!Z14-'Exh 6'!V14 -> 874 | T14: =S14/R14 -> 0.24836601 | V14: ='Exh 7'!AA14-'Exh 7'!W14 -> 1477 | W14: ='Exh 6'!AD14-'Exh 6'!Z14 -> 621 | X14: =W14/V14 -> 0.42044685
A15: 1986.2 | B15: ='Exh 7'!G15 -> 42163 | C15: ='Exh 6'!J15 -> 57654 | D15: =C15/B15 -> 1.3674074 | F15: ='Exh 7'!K15-'Exh 7'!G15 -> 3904 | G15: ='Exh 6'!N15-'Exh 6'!J15 -> 2283 | H15: =G15/F15 -> 0.58478484 | J15: ='Exh 7'!O15-'Exh 7'!K15 -> 3882 | K15: ='Exh 6'!R15-'Exh 6'!N15 -> 1982 | L15: =K15/J15 -> 0.51056157 | N15: ='Exh 7'!S15-'Exh 7'!O15 -> 2480 | O15: ='Exh 6'!V15-'Exh 6'!R15 -> 63 | P15: =O15/N15 -> 0.025403226 | R15: ='Exh 7'!W15-'Exh 7'!S15 -> 1476 | S15: ='Exh 6'!Z15-'Exh 6'!V15 -> 887 | T15: =S15/R15 -> 0.60094851 | V15: ='Exh 7'!AA15-'Exh 7'!W15 -> 1969 | W15: ='Exh 6'!AD15-'Exh 6'!Z15 -> 195 | X15: =W15/V15 -> 0.099035043
... A21: 1987.4 | B21: ='Exh 7'!G21 -> 73502 | C21: ='Exh 6'!J21 -> 101483 | D21: =C21/B21 -> 1.3806835 | F21: ='Exh 7'!K21-'Exh 7'!G21 -> 7479 | G21: ='Exh 6'!N21-'Exh 6'!J21 -> 5701 | H21: =G21/F21 -> 0.76226768 | J21: ='Exh 7'!O21-'Exh 7'!K21 -> 5101 | K21: ='Exh 6'!R21-'Exh 6'!N21 -> 2290 | L21: =K21/J21 -> 0.44893158 | N21: ='Exh 7'!S21-'Exh 7'!O21 -> 4456 | O21: ='Exh 6'!V21-'Exh 6'!R21 -> 1199 | P21: =O21/N21 -> 0.2690754 | R21: ='Exh 7'!W21-'Exh 7'!S21 -> 3277 | S21: ='Exh 6'!Z21-'Exh 6'!V21 -> 572 | T21: =S21/R21 -> 0.17454989 | V21: ='Exh 7'!AA21-'Exh 7'!W21 -> 382 | W21: ='Exh 6'!AD21-'Exh 6'!Z21 -> 227 | X21: =W21/V21 -> 0.59424084
A22: 1988.1 | B22: ='Exh 7'!G22 -> 71999 | C22: ='Exh 6'!J22 -> 98806 | D22: =C22/B22 -> 1.3723246 | F22: ='Exh 7'!K22-'Exh 7'!G22 -> 6083 | G22: ='Exh 6'!N22-'Exh 6'!J22 -> 4745 | H22: =G22/F22 -> 0.78004274 | J22: ='Exh 7'!O22-'Exh 7'!K22 -> 4138 | K22: ='Exh 6'!R22-'Exh 6'!N22 -> 1006 | L22: =K22/J22 -> 0.24311261 | N22: ='Exh 7'!S22-'Exh 7'!O22 -> 3267 | O22: ='Exh 6'!V22-'Exh 6'!R22 -> 1498 | P22: =O22/N22 -> 0.45852464 | R22: ='Exh 7'!W22-'Exh 7'!S22 -> 2294 | S22: ='Exh 6'!Z22-'Exh 6'!V22 -> 82 | T22: =S22/R22 -> 0.035745423
A23: 1988.2 | B23: ='Exh 7'!G23 -> 45861 | C23: ='Exh 6'!J23 -> 63885 | D23: =C23/B23 -> 1.3930137 | F23: ='Exh 7'!K23-'Exh 7'!G23 -> 5253 | G23: ='Exh 6'!N23-'Exh 6'!J23 -> 2688 | H23: =G23/F23 -> 0.5117076 | J23: ='Exh 7'!O23-'Exh 7'!K23 -> 3393 | K23: ='Exh 6'!R23-'Exh 6'!N23 -> 853 | L23: =K23/J23 -> 0.25139994 | N23: ='Exh 7'!S23-'Exh 7'!O23 -> 2461 | O23: ='Exh 6'!V23-'Exh 6'!R23 -> 894 | P23: =O23/N23 -> 0.36326696 | R23: ='Exh 7'!W23-'Exh 7'!S23 -> 1086 | S23: ='Exh 6'!Z23-'Exh 6'!V23 -> 102 | T23: =S23/R23 -> 0.093922652
A24: 1988.3 | B24: ='Exh 7'!G24 -> 115461 | C24: ='Exh 6'!J24 -> 161154 | D24: =C24/B24 -> 1.395744 | F24: ='Exh 7'!K24-'Exh 7'!G24 -> 13461 | G24: ='Exh 6'!N24-'Exh 6'!J24 -> 6642 | H24: =G24/F24 -> 0.49342545 | J24: ='Exh 7'!O24-'Exh 7'!K24 -> 7128 | K24: ='Exh 6'!R24-'Exh 6'!N24 -> 2854 | L24: =K24/J24 -> 0.40039282 | N24: ='Exh 7'!S24-'Exh 7'!O24 -> 6284 | O24: ='Exh 6'!V24-'Exh 6'!R24 -> 3014 | P24: =O24/N24 -> 0.47963081 | R24: ='Exh 7'!W24-'Exh 7'!S24 -> 8697 | S24: ='Exh 6'!Z24-'Exh 6'!V24 -> 108 | T24: =S24/R24 -> 0.012418075
A25: 1988.4 | B25: ='Exh 7'!G25 -> 79063 | C25: ='Exh 6'!J25 -> 109253 | D25: =C25/B25 -> 1.3818474 | F25: ='Exh 7'!K25-'Exh 7'!G25 -> 7723 | G25: ='Exh 6'!N25-'Exh 6'!J25 -> 3974 | H25: =G25/F25 -> 0.51456688 | J25: ='Exh 7'!O25-'Exh 7'!K25 -> 5082 | K25: ='Exh 6'!R25-'Exh 6'!N25 -> 2604 | L25: =K25/J25 -> 0.51239669 | N25: ='Exh 7'!S25-'Exh 7'!O25 -> 4351 | O25: ='Exh 6'!V25-'Exh 6'!R25 -> 2529 | P25: =O25/N25 -> 0.58124569 | R25: ='Exh 7'!W25-'Exh 7'!S25 -> 970 | S25: ='Exh 6'!Z25-'Exh 6'!V25 -> 798 | T25: =S25/R25 -> 0.82268041
A26: 1989.1 | B26: ='Exh 7'!G26 -> 71471 | C26: ='Exh 6'!J26 -> 99777 | D26: =C26/B26 -> 1.3960487 | F26: ='Exh 7'!K26-'Exh 7'!G26 -> 3744 | G26: ='Exh 6'!N26-'Exh 6'!J26 -> 914 | H26: =G26/F26 -> 0.24412393 | J26: ='Exh 7'!O26-'Exh 7'!K26 -> 4462 | K26: ='Exh 6'!R26-'Exh 6'!N26 -> 2131 | L26: =K26/J26 -> 0.47758853 | N26: ='Exh 7'!S26-'Exh 7'!O26 -> 798 | O26: ='Exh 6'!V26-'Exh 6'!R26 -> 339 | P26: =O26/N26 -> 0.42481203
A27: 1989.2 | B27: ='Exh 7'!G27 -> 49486 | C27: ='Exh 6'!J27 -> 67553 | D27: =C27/B27 -> 1.3650932 | F27: ='Exh 7'!K27-'Exh 7'!G27 -> 2976 | G27: ='Exh 6'!N27-'Exh 6'!J27 -> 2923 | H27: =G27/F27 -> 0.98219086 | J27: ='Exh 7'!O27-'Exh 7'!K27 -> 2834 | K27: ='Exh 6'!R27-'Exh 6'!N27 -> 1906 | L27: =K27/J27 -> 0.67254764 | N27: ='Exh 7'!S27-'Exh 7'!O27 -> 245 | O27: ='Exh 6'!V27-'Exh 6'!R27 -> 147 | P27: =O27/N27 -> 0.6
A28: 1989.3 | B28: ='Exh 7'!G28 -> 108330 | C28: ='Exh 6'!J28 -> 153443 | D28: =C28/B28 -> 1.4164405 | F28: ='Exh 7'!K28-'Exh 7'!G28 -> 12886 | G28: ='Exh 6'!N28-'Exh 6'!J28 -> 6525 | H28: =G28/F28 -> 0.5063635 | J28: ='Exh 7'!O28-'Exh 7'!K28 -> 6733 | K28: ='Exh 6'!R28-'Exh 6'!N28 -> 5732 | L28: =K28/J28 -> 0.85132927 | N28: ='Exh 7'!S28-'Exh 7'!O28 -> 2995 | O28: ='Exh 6'!V28-'Exh 6'!R28 -> 1043 | P28: =O28/N28 -> 0.34824708
A29: 1989.4 | B29: ='Exh 7'!G29 -> 72082 | C29: ='Exh 6'!J29 -> 104838 | D29: =C29/B29 -> 1.4544269 | F29: ='Exh 7'!K29-'Exh 7'!G29 -> 10903 | G29: ='Exh 6'!N29-'Exh 6'!J29 -> 8693 | H29: =G29/F29 -> 0.79730349 | J29: ='Exh 7'!O29-'Exh 7'!K29 -> 7288 | K29: ='Exh 6'!R29-'Exh 6'!N29 -> 4223 | L29: =K29/J29 -> 0.57944566 | N29: ='Exh 7'!S29-'Exh 7'!O29 -> 785 | O29: ='Exh 6'!V29-'Exh 6'!R29 -> 472 | P29: =O29/N29 -> 0.60127389
A30: 1990.1 | B30: ='Exh 7'!G30 -> 76452 | C30: ='Exh 6'!J30 -> 107468 | D30: =C30/B30 -> 1.4056925 | F30: ='Exh 7'!K30-'Exh 7'!G30 -> 8988 | G30: ='Exh 6'!N30-'Exh 6'!J30 -> 7055 | H30: =G30/F30 -> 0.78493547 | J30: ='Exh 7'!O30-'Exh 7'!K30 -> 2199 | K30: ='Exh 6'!R30-'Exh 6'!N30 -> 319 | L30: =K30/J30 -> 0.14506594
A31: 1990.2 | B31: ='Exh 7'!G31 -> 46393 | C31: ='Exh 6'!J31 -> 70127 | D31: =C31/B31 -> 1.5115858 | F31: ='Exh 7'!K31-'Exh 7'!G31 -> 6513 | G31: ='Exh 6'!N31-'Exh 6'!J31 -> 5695 | H31: =G31/F31 -> 0.87440504 | J31: ='Exh 7'!O31-'Exh 7'!K31 -> 1567 | K31: ='Exh 6'!R31-'Exh 6'!N31 -> 1159 | L31: =K31/J31 -> 0.73962987
A32: 1990.3 | B32: ='Exh 7'!G32 -> 102035 | C32: ='Exh 6'!J32 -> 158027 | D32: =C32/B32 -> 1.5487529 | F32: ='Exh 7'!K32-'Exh 7'!G32 -> 13486 | G32: ='Exh 6'!N32-'Exh 6'!J32 -> 6788 | H32: =G32/F32 -> 0.50333679 | J32: ='Exh 7'!O32-'Exh 7'!K32 -> 1681 | K32: ='Exh 6'!R32-'Exh 6'!N32 -> 901 | L32: =K32/J32 -> 0.53599048
A33: 1990.4 | B33: ='Exh 7'!G33 -> 57548 | C33: ='Exh 6'!J33 -> 91918 | D33: =C33/B33 -> 1.5972406 | F33: ='Exh 7'!K33-'Exh 7'!G33 -> 8522 | G33: ='Exh 6'!N33-'Exh 6'!J33 -> 2841 | H33: =G33/F33 -> 0.33337245 | J33: ='Exh 7'!O33-'Exh 7'!K33 -> 6166 | K33: ='Exh 6'!R33-'Exh 6'!N33 -> 1227 | L33: =K33/J33 -> 0.19899449
A34: 1991.1 | B34: ='Exh 7'!G34 -> 54037 | C34: ='Exh 6'!J34 -> 81901 | D34: =C34/B34 -> 1.5156467 | F34: ='Exh 7'!K34-'Exh 7'!G34 -> 3583 | G34: ='Exh 6'!N34-'Exh 6'!J34 -> 2596 | H34: =G34/F34 -> 0.72453251
A35: 1991.2 | B35: ='Exh 7'!G35 -> 30240 | C35: ='Exh 6'!J35 -> 54045 | D35: =C35/B35 -> 1.7872024 | F35: ='Exh 7'!K35-'Exh 7'!G35 -> 2824 | G35: ='Exh 6'!N35-'Exh 6'!J35 -> 666 | H35: =G35/F35 -> 0.23583569
A36: 1991.3 | B36: ='Exh 7'!G36 -> 55325 | C36: ='Exh 6'!J36 -> 94797 | D36: =C36/B36 -> 1.7134568 | F36: ='Exh 7'!K36-'Exh 7'!G36 -> 3168 | G36: ='Exh 6'!N36-'Exh 6'!J36 -> 2551 | H36: =G36/F36 -> 0.8052399
A37: 1991.4 | B37: ='Exh 7'!G37 -> 54602 | C37: ='Exh 6'!J37 -> 97560 | D37: =C37/B37 -> 1.7867477 | F37: ='Exh 7'!K37-'Exh 7'!G37 -> 4778 | G37: ='Exh 6'!N37-'Exh 6'!J37 -> 2538 | H37: =G37/F37 -> 0.5311846
A38: 1992.1 | B38: ='Exh 7'!G38 -> 49161 | C38: ='Exh 6'!J38 -> 82057 | D38: =C38/B38 -> 1.6691483
A39: 1992.2 | B39: ='Exh 7'!G39 -> 33060 | C39: ='Exh 6'!J39 -> 59279 | D39: =C39/B39 -> 1.7930732
A40: 1992.3 | B40: ='Exh 7'!G40 -> 53069 | C40: ='Exh 6'!J40 -> 99074 | D40: =C40/B40 -> 1.8668903
A41: 1992.4 | B41: ='Exh 7'!G41 -> 44785 | C41: ='Exh 6'!J41 -> 88367 | D41: =C41/B41 -> 1.9731383
A43: Empirical
A44: Average All | D44: =AVERAGE(D4:D41) -> 1.458959 | H44: =AVERAGE(H4:H37) -> 0.72157874 | L44: =AVERAGE(L4:L33) -> 0.56615157 | P44: =AVERAGE(P4:P29) -> 0.40421086 | T44: =AVERAGE(T4:T25) -> 0.34497321 | X44: =AVERAGE(X4:X20) -> 0.20885936
A45: Weighted Avg All | D45: =SUM(C4:C41)/SUM(B4:B41) -> 1.4543053 | H45: =SUM(G4:G37)/SUM(F4:F37) -> 0.68126071 | L45: =SUM(K4:K33)/SUM(J4:J33) -> 0.53266227 | P45: =SUM(O4:O29)/SUM(N4:N29) -> 0.38510455 | T45: =SUM(S4:S25)/SUM(R4:R25) -> 0.2673159 | X45: =SUM(W4:W21)/SUM(V4:V21) -> 0.18863581
A47: Retro Formula
...

Sheet Exh 5
A3: Retro | B3: Ultimate | H3: Selected
A4: Adj. | B4: SP | C4: % of Total | D4: Emerged | E4: Table M Stuff in Between Not Relevant For Exam | F4: Cumulative | G4: Increm | H4: Increm
A5: Periods | B5: Loss Ratio | C5: Loss Emerged | D5: LR | F5: CL/L | G5: CL/L | H5: CL/L
A6: 1 | B6: 0.7 | C6: ='Exh 7'!G57 -> 0.7878031 | D6: =B6*C6 -> 0.55146217 | F6: 0.849 | G6: =F6 -> 0.849 | H6: 0.85
A7: 2 | B7: 0.7 | C7: ='Exh 7'!K57 -> 0.87838843 | D7: =B7*C7 -> 0.6148719 | F7: 0.82 | G7: =(F7*D7-F6*D6)/(D7-D6) -> 0.56779262 | H7: 0.58
A8: 3 | B8: 0.7 | C8: ='Exh 7'!O57 -> 0.92274297 | D8: =B8*C8 -> 0.64592008 | F8: 0.802 | G8: =(F8*D8-F7*D7)/(D8-D7) -> 0.4455316 | H8: 0.45
A9: 4 | B9: 0.7 | C9: ='Exh 7'!S57 -> 0.95027274 | D9: =B9*C9 -> 0.66519092 | F9: 0.79 | G9: =(F9*D9-F8*D8)/(D9-D8) -> 0.38778388 | H9: 0.4
A10: 5 | B10: 0.7 | C10: ='Exh 7'!W57 -> 0.97978064 | D10: =B10*C10 -> 0.68584645 | F10: 0.778 | G10: =(F10*D10-F9*D9)/(D10-D9) -> 0.3915519 | H10: 0.4
A11: 6 | B11: 0.7 | C11: ='Exh 7'!AA57 -> 0.99584794 | D11: =B11*C11 -> 0.69709356 | F11: 0.772 | G11: =(F11*D11-F10*D10)/(D11-D10) -> 0.40612119 | H11: 0.4
A12: 7+ | B12: 0.7 | C12: ='Exh 7'!AE57 -> 1 | D12: =B12*C12 -> 0.7 | F12: 0.769 | G12: =(F12*D12-F11*D11)/(D12-D11) -> 0.049467455 | H12: 0

Sheet Exh 6
A1: Booked Premium Development
B3: 3 | C3: =B3+3 -> 6 | D3: =C3+3 -> 9 | E3: =D3+3 -> 12 | F3: =E3+3 -> 15 | G3: =F3+3 -> 18 | H3: =G3+3 -> 21 | I3: =H3+3 -> 24 | J3: =I3+3 -> 27 | ... AD3: =AC3+3 -> 87
A4: 1983.3 | B4: 18087 | C4: 23481 | D4: 33550 | E4: 40867 | F4: 45075 | G4: 49911 | H4: 50174 | I4: 50629 | J4: 52436 | K4: 52388 | L4: 52428 | M4: 53735 | N4: 56448 | O4: 56442 | P4: 56698 | Q4: 57448 | R4: 58799 | S4: 58904 | T4: 58875 | U4: 59306 | V4: 59562 | W4: 59301 | X4: 59335 | Y4: 59492 | Z4: 60275 | AA4: 60309 | AB4: 60321 | AC4: 60221 | AD4: 60530
A5: 1983.4 | B5: 7545 | C5: 10684 | D5: 15697 | E5: 19696 | F5: 22407 | G5: 24608 | H5: 25438 | I5: 25367 | J5: 26222 | K5: 26135 | L5: 26109 | M5: 16653 | N5: 28944 | O5: 28886 | P5: 28923 | Q5: 29122 | R5: 29520 | S5: 19490 | T5: 29463 | U5: 29492 | V5: 30182 | W5: 30048 | X5: 30048 | Y5: 30204 | Z5: 30238 | AA5: 30172 | AB5: 30164 | AC5: 30041 | AD5: 30424
A6: 1984.1 | B6: 7930 | C6: 13516 | D6: 19135 | E6: 24101 | F6: 25408 | G6: 28018 | H6: 28777 | I6: 28947 | J6: 29189 | K6: 28967 | L6: 28960 | M6: 29563 | N6: 31116 | O6: 32031 | P6: 31993 | Q6: 31896 | R6: 32202 | S6: 32473 | T6: 32489 | U6: 32513 | V6: 33085 | W6: 32997 | X6: 33046 | Y6: 33223 | Z6: 33612 | AA6: 33612 | AB6: 33612 | AC6: 33735 | AD6: 33509
A7: 1984.2 | B7: 6277 | C7: 10386 | D7: 14770 | E7: 18422 | F7: 20366 | G7: 22441 | H7: 22258 | I7: 23261 | J7: 23422 | K7: 23608 | L7: 23714 | M7: 24239 | N7: 25326 | O7: 25319 | P7: 25433 | Q7: 25717 | R7: 26066 | S7: 26095 | T7: 26330 | U7: 26365 | V7: 26639 | W7: 26622 | X7: 26944 | Y7: 26961 | Z7: 27232 | AA7: 27241 | AB7: 27070 | AC7: 27086 | AD7: 27247
A8: 1984.3 | B8: 20221 | C8: 31438 | D8: 45913 | E8: 56490 | F8: 61851 | G8: 66697 | H8: 67910 | I8: 68094 | J8: 69310 | K8: 69648 | L8: 69804 | M8: 73363 | N8: 75681 | O8: 75727 | P8: 76163 | Q8: 77812 | R8: 79113 | S8: 79140 | T8: 79358 | U8: 79730 | V8: 80272 | W8: 79940 | X8: 80017 | Y8: 80328 | Z8: 80907 | AA8: 80813 | AB8: 80850 | AC8: 80934 | AD8: 81044
A9: 1984.4 | B9: 9581 | C9: 21089 | D9: 29224 | E9: 38056 | F9: 41299 | G9: 43344 | H9: 43489 | I9: 43897 | J9: 43305 | K9: 43851 | L9: 43794 | M9: 44982 | N9: 46495 | O9: 46645 | P9: 46535 | Q9: 47060 | R9: 47768 | S9: 47815 | T9: 47798 | U9: 47833 | V9: 47974 | W9: 47844 | X9: 47424 | Y9: 47527 | Z9: 48020 | AA9: 47977 | AB9: 47971 | AC9: 47873 | AD9: 48106
A10: 1985.1 | B10: 15110 | C10: 28734 | D10: 40623 | E10: 49872 | F10: 52336 | G10: 57881 | H10: 58742 | I10: 56075 | J10: 59203 | K10: 59164 | L10: 59814 | M10: 60692 | N10: 62552 | O10: 62780 | P10: 62880 | Q10: 63239 | R10: 63899 | S10: 64075 | T10: 64072 | U10: 63911 | V10: 64166 | W10: 63818 | X10: 63785 | Y10: 63794 | Z10: 64286 | AA10: 64360 | AB10: 64348 | AC10: 64502 | AD10: 64901
A11: 1985.2 | B11: 9345 | C11: 19304 | D11: 26189 | E11: 33115 | F11: 37010 | G11: 37650 | H11: 39114 | I11: 40131 | J11: 38717 | K11: 38855 | L11: 39247 | M11: 39753 | N11: 40836 | O11: 40780 | P11: 41156 | Q11: 41412 | R11: 42523 | S11: 42446 | T11: 42635 | U11: 42814 | V11: 43296 | W11: 42989 | X11: 42975 | Y11: 43080 | Z11: 43485 | AA11: 43517 | AB11: 43371 | AC11: 43682 | AD11: 43695
A12: 1985.3 | B12: 43187 | C12: 69712 | D12: 99219 | E12: 120931 | F12: 128832 | G12: 138488 | H12: 138401 | I12: 132641 | J12: 133094 | K12: 134019 | L12: 134241 | M12: 138147 | N12: 141020 | O12: 141198 | P12: 141185 | Q12: 143140 | R12: 144073 | S12: 144137 | T12: 144236 | U12: 145032 | V12: 146743 | W12: 146395 | X12: 146591 | Y12: 147980 | Z12: 149354 | AA12: 149163 | AB12: 149109 | AC12: 149224 | AD12: 149509
A13: 1985.4 | B13: 18627 | C13: 36106 | D13: 51122 | E13: 61567 | F13: 63169 | G13: 67119 | H13: 68046 | I13: 67651 | J13: 66351 | K13: 67117 | L13: 67131 | M13: 68357 | N13: 70414 | O13: 70703 | P13: 70606 | Q13: 71420 | R13: 72974 | S13: 72741 | T13: 73185 | U13: 73342 | V13: 74170 | W13: 73882 | X13: 73688 | Y13: 74169 | Z13: 75261 | AA13: 75226 | AB13: 74893 | AC13: 75060 | AD13: 76219
A14: 1986.1 | B14: 27390 | C14: 46056 | D14: 62065 | E14: 76616 | F14: 79958 | G14: 83746 | H14: 88382 | I14: 83949 | J14: 87173 | K14: 68630 | L14: 67438 | M14: 88964 | N14: 91422 | O14: 91780 | P14: 91767 | Q14: 92532 | R14: 93720 | S14: 94000 | T14: 93988 | U14: 94319 | V14: 94963 | W14: 94514 | X14: 94611 | Y14: 94869 | Z14: 95837 | AA14: 95762 | AB14: 95762 | AC14: 96108 | AD14: 96458
A15: 1986.2 | B15: 15906 | C15: 28997 | D15: 39082 | E15: 48402 | F15: 53764 | G15: 56713 | H15: 59748 | I15: 58482 | J15: 57654 | K15: 57171 | L15: 57156 | M15: 57801 | N15: 59937 | O15: 59994 | P15: 60463 | Q15: 61202 | R15: 61919 | S15: 61909 | T15: 61941 | U15: 61664 | V15: 61982 | W15: 61909 | X15: 62439 | Y15: 62630 | Z15: 62869 | AA15: 63097 | AB15: 63109 | AC15: 63093 | AD15: 63064
... A21: 1987.4 | B21: 40213 | C21: 56338 | D21: 71591 | E21: 88365 | F21: 91969 | G21: 98370 | H21: 99258 | I21: 99738 | J21: 101483 | K21: 101762 | L21: 101940 | M21: 104615 | N21: 107184 | O21: 107014 | P21: 106769 | Q21: 108691 | R21: 109474 | S21: 109590 | T21: 109674 | U21: 109553 | V21: 110673 | W21: 110406 | X21: 110472 | Y21: 110766 | Z21: 111245 | AA21: 111243 | AB21: 111236 | AC21: 111279 | AD21: 111472
A22: 1988.1 | B22: 42723 | C22: 54489 | D22: 70630 | E22: 85547 | F22: 90156 | G22: 96939 | H22: 97210 | I22: 97349 | J22: 98806 | K22: 99398 | L22: 99426 | M22: 101516 | N22: 103551 | O22: 103824 | P22: 103719 | Q22: 103937 | R22: 104557 | S22: 104769 | T22: 104822 | U22: 104662 | V22: 106055 | W22: 105656 | X22: 105466 | Y22: 105683 | Z22: 106137 | AA22: 106218 | AB22: 106230 | AC22: 106292
A23: 1988.2 | B23: 22257 | C23: 34740 | D23: 43526 | E23: 53014 | F23: 58682 | G23: 62781 | H23: 62671 | I23: 62232 | J23: 63885 | K23: 63771 | L23: 63912 | M23: 66090 | N23: 66573 | O23: 66593 | P23: 66453 | Q23: 66542 | R23: 67426 | S23: 67585 | T23: 67579 | U23: 68302 | V23: 68320 | W23: 68055 | X23: 67964 | Y23: 67923 | Z23: 68422 | AA23: 68448 | AB23: 68462
A24: 1988.3 | B24: 72106 | C24: 88814 | D24: 119264 | E24: 144686 | F24: 150957 | G24: 155317 | H24: 157645 | I24: 167669 | J24: 161154 | K24: 159634 | L24: 159056 | M24: 163070 | N24: 167796 | O24: 167503 | P24: 167539 | Q24: 168059 | R24: 170650 | S24: 172206 | T24: 172539 | U24: 172583 | V24: 173664 | W24: 172956 | X24: 172995 | Y24: 172960 | Z24: 173772 | AA24: 173984
A25: 1988.4 | B25: 39617 | C25: 54419 | D25: 70154 | E25: 90176 | F25: 96199 | G25: 100143 | H25: 101400 | I25: 103318 | J25: 109253 | K25: 109553 | L25: 109928 | M25: 111601 | N25: 113227 | O25: 113259 | P25: 113947 | Q25: 114158 | R25: 115831 | S25: 115967 | T25: 115909 | U25: 116218 | V25: 118360 | W25: 117566 | X25: 117541 | Y25: 117189 | Z25: 119158
A26: 1989.1 | B26: 39587 | C26: 52001 | D26: 70440 | E26: 86851 | F26: 90443 | G26: 92953 | H26: 95370 | I26: 95048 | J26: 99777 | K26: 99118 | L26: 98874 | M26: 99321 | N26: 100691 | O26: 100996 | P26: 101165 | Q26: 102126 | R26: 102822 | S26: 102919 | T26: 102750 | U26: 102955 | V26: 103161 | W26: 103367 | X26: 103574 | Y26: 103781
A27: 1989.2 | B27: 22202 | C27: 34226 | D27: 45230 | E27: 58091 | F27: 61548 | G27: 63860 | H27: 65452 | I27: 65312 | J27: 67553 | K27: 67514 | L27: 67325 | M27: 68442 | N27: 70476 | O27: 70691 | P27: 70687 | Q27: 72016 | R27: 72382 | S27: 72362 | T27: 72385 | U27: 72457 | V27: 72529 | W27: 72602 | X27: 72675
A28: 1989.3 | B28: 65381 | C28: 57768 | D28: 116546 | E28: 143674 | F28: 150281 | G28: 154254 | H28: 155500 | I28: 153310 | J28: 153443 | K28: 152289 | L28: 151898 | M28: 153635 | N28: 159968 | O28: 162505 | P28: 162799 | Q28: 163947 | R28: 165700 | S28: 166040 | T28: 165811 | U28: 165390 | V28: 166743 | W28: 166034
A29: 1989.4 | B29: 38328 | C29: 59317 | D29: 79875 | E29: 101224 | F29: 107600 | G29: 109565 | H29: 108541 | I29: 107785 | J29: 104838 | K29: 105096 | L29: 106006 | M29: 106285 | N29: 113531 | O29: 113513 | P29: 113494 | Q29: 115806 | R29: 117754 | S29: 117872 | T29: 117990 | U29: 118108 | V29: 118226
A30: 1990.1 | B30: 41480 | C30: 58916 | D30: 82540 | E30: 101782 | F30: 105099 | G30: 109581 | H30: 107738 | I30: 108319 | J30: 107468 | K30: 108595 | L30: 108481 | M30: 112426 | N30: 114523 | O30: 114013 | P30: 114032 | Q30: 114738 | R30: 114842 | S30: 113920 | T30: 113959 | U30: 113443
A31: 1990.2 | B31: 24980 | C31: 44112 | D31: 57612 | E31: 69544 | F31: 72525 | G31: 73996 | H31: 74014 | I31: 72759 | J31: 70127 | K31: 71153 | L31: 71796 | M31: 73669 | N31: 75822 | O31: 75729 | P31: 75670 | Q31: 76523 | R31: 76981 | S31: 77086 | T31: 76983
A32: 1990.3 | B32: 63128 | C32: 90937 | D32: 124828 | E32: 150974 | F32: 157555 | G32: 164785 | H32: 161333 | I32: 157804 | J32: 158027 | K32: 154559 | L32: 155939 | M32: 161526 | N32: 164815 | O32: 164057 | P32: 164447 | Q32: 164886 | R32: 165716 | S32: 166107
A33: 1990.4 | B33: 39431 | C33: 56685 | D33: 75859 | E33: 96782 | F33: 102985 | G33: 103811 | H33: 105995 | I33: 102283 | J33: 91918 | K33: 90293 | L33: 89057 | M33: 92789 | N33: 94759 | O33: 94621 | P33: 94655 | Q33: 94805 | R33: 95986
A34: 1991.1 | B34: 33478 | C34: 44023 | D34: 65178 | E34: 77912 | F34: 80929 | G34: 82418 | H34: 85231 | I34: 83748 | J34: 81901 | K34: 81593 | L34: 81741 | M34: 83321 | N34: 84497 | O34: 84444 | P34: 84616 | Q34: 85643
A35: 1991.2 | B35: 14280 | C35: 28297 | D35: 40717 | E35: 52368 | F35: 56505 | G35: 57790 | H35: 58229 | I35: 54008 | J35: 54045 | K35: 53647 | L35: 53094 | M35: 54363 | N35: 54711 | O35: 54940 | P35: 54874
A36: 1991.3 | B36: 45699 | C36: 57962 | D36: 76470 | E36: 90684 | F36: 94509 | G36: 99243 | H36: 96431 | I36: 97296 | J36: 94797 | K36: 95483 | L36: 95037 | M36: 95884 | N36: 97348 | O36: 97351
A37: 1991.4 | B37: 40472 | C37: 55839 | D37: 71234 | E37: 96004 | F37: 113650 | G37: 110764 | H37: 108317 | I37: 107345 | J37: 97560 | K37: 97275 | L37: 97453 | M37: 98816 | N37: 100098
A38: 1992.1 | B38: 33004 | C38: 48424 | D38: 63007 | E38: 77569 | F38: 80923 | G38: 83160 | H38: 82743 | I38: 79436 | J38: 82057 | K38: 81207 | L38: 82305 | M38: 83654
A39: 1992.2 | B39: 15320 | C39: 28687 | D39: 42953 | E39: 55414 | F39: 59215 | G39: 59989 | H39: 61432 | I39: 62709 | J39: 59279 | K39: 59531 | L39: 59450
A40: 1992.3 | B40: 4357 | C40: 62779 | D40: 79724 | E40: 96319 | F40: 102225 | G40: 102001 | H40: 100433 | I40: 101661 | J40: 99074 | K40: 98745
A41: 1992.4 | B41: 39809 | C41: 55591 | D41: 64921 | E41: 84643 | F41: 91176 | G41: 95711 | H41: 95421 | I41: 96272 | J41: 88367
A42: 1993.1 | B42: 23915 | C42: 33188 | D42: 43949 | E42: 53188 | F42: 56028 | G42: 57200 | H42: 57259 | I42: 57304
A43: 1993.2 | B43: 18976 | C43: 30311 | D43: 39234 | E43: 46519 | F43: 49357 | G43: 50776 | H43: 50887
A44: 1993.3 | B44: 45269 | C44: 55794 | D44: 70411 | E44: 84974 | F44: 87886 | G44: 89838
A45: 1993.4 | B45: 28913 | C45: 40173 | D45: 51901 | E45: 64487 | F45: 69025
A46: 1994.1 | B46: 24902 | C46: 33572 | D46: 41305 | E46: 49737
...

Sheet Exh 7
A1: Reported Loss Development
B3: 3 | C3: =B3+3 -> 6 | D3: =C3+3 -> 9 | E3: =D3+3 -> 12 | F3: =E3+3 -> 15 | G3: =F3+3 -> 18 | H3: =G3+3 -> 21 | I3: =H3+3 -> 24 | J3: =I3+3 -> 27 | ... AD3: =AC3+3 -> 87
A4: 1983.3 | B4: 5121 | C4: 15662 | D4: 24950 | E4: 36667 | F4: 41044 | G4: 42461 | H4: 44191 | I4: 45528 | J4: 46321 | K4: 47976 | L4: 48898 | M4: 49439 | N4: 50413 | O4: 52508 | P4: 53010 | Q4: 52952 | R4: 52987 | S4: 54433 | T4: 54844 | U4: 54908 | V4: 55464 | W4: 56489 | X4: 56740 | Y4: 56907 | Z4: 56968 | AA4: 57660 | AB4: 58013 | AC4: 58319 | AD4: 58893
A5: 1983.4 | B5: 1336 | C5: 5853 | D5: 10153 | E5: 15218 | F5: 18928 | G5: 20151 | H5: 21293 | I5: 21821 | J5: 22244 | K5: 22889 | L5: 23270 | M5: 23466 | N5: 23802 | O5: 24369 | P5: 24713 | Q5: 24840 | R5: 25085 | S5: 25447 | T5: 25598 | U5: 25913 | V5: 25430 | W5: 25511 | X5: 25527 | Y5: 25784 | Z5: 25905 | AA5: 26036 | AB5: 26257 | AC5: 26439 | AD5: 26396
A6: 1984.1 | B6: 2746 | C6: 6798 | D6: 11408 | E6: 17227 | F6: 20523 | G6: 23076 | H6: 23954 | I6: 24351 | J6: 24730 | K6: 25218 | L6: 25765 | M6: 26065 | N6: 26897 | O6: 27294 | P6: 27873 | Q6: 28168 | R6: 28054 | S6: 28433 | T6: 28783 | U6: 28888 | V6: 28887 | W6: 29261 | X6: 29942 | Y6: 29959 | Z6: 29857 | AA6: 30384 | AB6: 30332 | AC6: 30414 | AD6: 30496
A7: 1984.2 | B7: 1393 | C7: 5284 | D7: 8929 | E7: 14264 | F7: 18651 | G7: 19243 | H7: 20080 | I7: 20759 | J7: 20954 | K7: 20376 | L7: 20143 | M7: 20504 | N7: 20549 | O7: 20782 | P7: 21110 | Q7: 21056 | R7: 21408 | S7: 21919 | T7: 22129 | U7: 22130 | V7: 22260 | W7: 22825 | X7: 22942 | Y7: 22721 | Z7: 22697 | AA7: 22990 | AB7: 23351 | AC7: 23331 | AD7: 23639
A8: 1984.3 | B8: 6618 | C8: 17632 | D8: 31538 | E8: 46077 | F8: 51318 | G8: 54927 | H8: 58153 | I8: 59814 | J8: 61636 | K8: 63827 | L8: 65053 | M8: 65301 | N8: 66273 | O8: 67631 | P8: 68177 | Q8: 68656 | R8: 69571 | S8: 70581 | T8: 70598 | U8: 70630 | V8: 70699 | W8: 73199 | X8: 73429 | Y8: 73673 | Z8: 74127 | AA8: 75675 | AB8: 76027 | AC8: 76207 | AD8: 76291
A9: 1984.4 | B9: 2417 | C9: 9115 | D9: 17939 | E9: 24030 | F9: 30204 | G9: 33393 | H9: 35277 | I9: 36237 | J9: 36887 | K9: 37701 | L9: 38636 | M9: 39640 | N9: 29583 | O9: 40520 | P9: 41687 | Q9: 41786 | R9: 41658 | S9: 41944 | T9: 42229 | U9: 42602 | V9: 42760 | W9: 43323 | X9: 43870 | Y9: 44107 | Z9: 44278 | AA9: 44652 | AB9: 45046 | AC9: 45296 | AD9: 45746
A10: 1985.1 | B10: 3847 | C10: 13981 | D10: 22896 | E10: 34132 | F10: 41523 | G10: 46100 | H10: 46809 | I10: 47718 | J10: 48853 | K10: 49485 | L10: 50490 | M10: 50804 | N10: 50749 | O10: 51796 | P10: 52028 | Q10: 52557 | R10: 52925 | S10: 53334 | T10: 54047 | U10: 54796 | V10: 55246 | W10: 55600 | X10: 55619 | Y10: 55744 | Z10: 55635 | AA10: 56128 | AB10: 56031 | AC10: 56762 | AD10: 56822
A11: 1985.2 | B11: 2164 | C11: 6559 | D11: 12772 | E11: 20433 | F11: 26052 | G11: 27696 | H11: 28720 | I11: 29155 | J11: 29654 | K11: 30375 | L11: 31281 | M11: 31597 | N11: 32095 | O11: 33051 | P11: 33713 | Q11: 33797 | R11: 34161 | S11: 35077 | T11: 35629 | U11: 35888 | V11: 35816 | W11: 36806 | X11: 37422 | Y11: 37734 | Z11: 37721 | AA11: 37878 | AB11: 37977 | AC11: 38073 | AD11: 38029
A12: 1985.3 | B12: 11514 | C12: 34201 | D12: 57070 | E12: 84782 | F12: 92911 | G12: 96041 | H12: 98225 | I12: 101501 | J12: 103660 | K12: 105758 | L12: 106336 | M12: 108721 | N12: 110196 | O12: 112223 | P12: 113596 | Q12: 114633 | R12: 115792 | S12: 118749 | T12: 120458 | U12: 121027 | V12: 121826 | W12: 125352 | X12: 126865 | Y12: 127252 | Z12: 127387 | AA12: 128918 | AB12: 129448 | AC12: 129815 | AD12: 130355
A13: 1985.4 | B13: 1252 | C13: 14692 | D13: 28032 | E13: 38282 | F13: 46101 | G13: 49481 | H13: 52737 | I13: 54006 | J13: 55152 | K13: 56674 | L13: 58126 | M13: 59382 | N13: 59953 | O13: 60942 | P13: 61543 | Q13: 62769 | R13: 63048 | S13: 63992 | T13: 64759 | U13: 56053 | V13: 65140 | W13: 66186 | X13: 67419 | Y13: 68036 | Z13: 68140 | AA13: 68719 | AB13: 69068 | AC13: 69417 | AD13: 69467
A14: 1986.1 | B14: 6670 | C14: 20522 | D14: 32059 | E14: 46939 | F14: 56233 | G14: 63095 | H14: 63724 | I14: 65004 | J14: 65887 | K14: 68960 | L14: 69613 | M14: 70522 | N14: 71368 | O14: 73005 | P14: 73711 | Q14: 73961 | R14: 73350 | S14: 74704 | T14: 76207 | U14: 76344 | V14: 77005 | W14: 78223 | X14: 79734 | Y14: 80044 | Z14: 80055 | AA14: 79700 | AB14: 79826 | AC14: 80048 | AD14: 80598
A15: 1986.2 | B15: 3531 | C15: 10914 | D15: 19770 | E15: 31772 | F15: 40050 | G15: 42163 | H15: 43055 | I15: 43374 | J15: 44117 | K15: 46067 | L15: 46648 | M15: 47551 | N15: 47994 | O15: 49949 | P15: 50459 | Q15: 50798 | R15: 51492 | S15: 52429 | T15: 52185 | U15: 52937 | V15: 53475 | W15: 53905 | X15: 54533 | Y15: 54659 | Z15: 54858 | AA15: 55874 | AB15: 55290 | AC15: 55033 | AD15: 55170
... A21: 1987.4 | B21: 6190 | C21: 20923 | D21: 41460 | E21: 56846 | F21: 67724 | G21: 73502 | H21: 76331 | I21: 76489 | J21: 78388 | K21: 80981 | L21: 82914 | M21: 84044 | N21: 84277 | O21: 86082 | P21: 88294 | Q21: 89146 | R21: 89288 | S21: 90538 | T21: 92262 | U21: 92860 | V21: 93825 | W21: 93815 | X21: 93787 | Y21: 93977 | Z21: 93987 | AA21: 94197 | AB21: 94251 | AC21: 94124 | AD21: 94067
A22: 1988.1 | B22: 6916 | C22: 20545 | D22: 34772 | E22: 50554 | F22: 63347 | G22: 71999 | H22: 73728 | I22: 74396 | J22: 75834 | K22: 78082 | L22: 79412 | M22: 80223 | N22: 80531 | O22: 82220 | P22: 83299 | Q22: 83605 | R22: 84078 | S22: 85487 | T22: 85962 | U22: 86393 | V22: 86795 | W22: 87781 | X22: 89697 | Y22: 89780 | Z22: 89457 | AA22: 89473 | AB22: 89042 | AC22: 88908
A23: 1988.2 | B23: 4087 | C23: 11179 | D23: 21183 | E23: 34005 | F23: 44314 | G23: 45861 | H23: 46854 | I23: 47968 | J23: 49482 | K23: 51114 | L23: 52248 | M23: 53089 | N23: 53407 | O23: 54507 | P23: 55421 | Q23: 55937 | R23: 56157 | S23: 56968 | T23: 57732 | U23: 57913 | V23: 57606 | W23: 58054 | X23: 58287 | Y23: 58285 | Z23: 57871 | AA23: 57691 | AB23: 57763
A24: 1988.3 | B24: 12952 | C24: 35571 | D24: 63806 | E24: 98684 | F24: 110159 | G24: 115461 | H24: 120036 | I24: 123446 | J24: 124724 | K24: 128922 | L24: 131384 | M24: 133661 | N24: 134948 | O24: 136050 | P24: 139179 | Q24: 139464 | R24: 140598 | S24: 142334 | T24: 145198 | U24: 150268 | V24: 150526 | W24: 151031 | X24: 151733 | Y24: 151487 | Z24: 151590 | AA24: 152121
A25: 1988.4 | B25: 5451 | C25: 22014 | D25: 40250 | E25: 57358 | F25: 71190 | G25: 79063 | H25: 85346 | I25: 85263 | J25: 86493 | K25: 86786 | L25: 88053 | M25: 88746 | N25: 89616 | O25: 91868 | P25: 92734 | Q25: 93316 | R25: 94645 | S25: 96219 | T25: 97757 | U25: 97788 | V25: 97436 | W25: 97189 | X25: 97467 | Y25: 97076 | Z25: 96809
A26: 1989.1 | B26: 7869 | C26: 21725 | D26: 34204 | E26: 50512 | F26: 62907 | G26: 71471 | H26: 71946 | I26: 72275 | J26: 72442 | K26: 75215 | L26: 76405 | M26: 77279 | N26: 77522 | O26: 79677 | P26: 80263 | Q26: 79879 | R26: 79483 | S26: 80475 | T26: 81137 | U26: 81113 | V26: 80897 | W26: 81253 | X26: 81546 | Y26: 81384
A27: 1989.2 | B27: 3615 | C27: 12348 | D27: 23914 | E27: 36257 | F27: 46573 | G27: 49486 | H27: 50566 | I27: 50507 | J27: 51567 | K27: 52462 | L27: 54081 | M27: 54467 | N27: 54940 | O27: 55296 | P27: 55591 | Q27: 55467 | R27: 55322 | S27: 55541 | T27: 55780 | U27: 55751 | V27: 55663 | W27: 55652 | X27: 55898
A28: 1989.3 | B28: 11397 | C28: 33593 | D28: 61655 | E28: 92142 | F28: 102949 | G28: 108330 | H28: 112488 | I28: 116584 | J28: 119203 | K28: 121216 | L28: 124649 | M28: 125375 | N28: 126285 | O28: 127949 | P28: 129957 | Q28: 129598 | R28: 129944 | S28: 130944 | T28: 131516 | U28: 131650 | V28: 131233 | W28: 131539
A29: 1989.4 | B29: 4842 | C29: 19715 | D29: 39063 | E29: 52236 | F29: 64224 | G29: 72082 | H29: 76852 | I29: 78864 | J29: 80320 | K29: 82985 | L29: 89691 | M29: 88199 | N29: 88955 | O29: 90273 | P29: 91621 | Q29: 91261 | R29: 91296 | S29: 91058 | T29: 91020 | U29: 91296 | V29: 91423
A30: 1990.1 | B30: 9511 | C30: 25559 | D30: 39469 | E30: 56952 | F30: 68215 | G30: 76452 | H30: 78668 | I30: 79502 | J30: 81249 | K30: 85440 | L30: 86905 | M30: 86250 | N30: 86565 | O30: 87639 | P30: 91060 | Q30: 90996 | R30: 90437 | S30: 89844 | T30: 89689 | U30: 89715
A31: 1990.2 | B31: 3836 | C31: 12606 | D31: 22351 | E31: 33833 | F31: 42925 | G31: 46393 | H31: 48984 | I31: 50954 | J31: 52012 | K31: 52906 | L31: 53893 | M31: 53431 | N31: 53847 | O31: 54473 | P31: 55529 | Q31: 55502 | R31: 55535 | S31: 55556 | T31: 56032
A32: 1990.3 | B32: 11677 | C32: 32321 | D32: 57374 | E32: 83863 | F32: 94633 | G32: 102035 | H32: 106144 | I32: 109426 | J32: 12652 | K32: 115521 | L32: 116449 | M32: 116762 | N32: 116920 | O32: 117202 | P32: 117673 | Q32: 117528 | R32: 117746 | S32: 118268
A33: 1990.4 | B33: 5196 | C33: 14997 | D33: 30880 | E33: 42939 | F33: 52459 | G33: 57548 | H33: 62316 | I33: 63183 | J33: 64537 | K33: 66070 | L33: 70479 | M33: 70789 | N33: 71707 | O33: 72236 | P33: 73643 | Q33: 73101 | R33: 73037
A34: 1991.1 | B34: 7133 | C34: 19024 | D34: 29513 | E34: 39914 | F34: 47837 | G34: 54037 | H34: 56184 | I34: 56093 | J34: 56697 | K34: 57620 | L34: 59265 | M34: 59537 | N34: 59577 | O34: 60025 | P34: 60440 | Q34: 60399
A35: 1991.2 | B35: 2129 | C35: 6883 | D35: 13419 | E35: 20833 | F35: 28953 | G35: 30240 | H35: 31317 | I35: 32484 | J35: 32779 | K35: 33064 | L35: 33768 | M35: 33584 | N35: 33779 | O35: 33771 | P35: 34136
A36: 1991.3 | B36: 5053 | C36: 14983 | D36: 30591 | E36: 47533 | F36: 53959 | G36: 55325 | H36: 55647 | I36: 57417 | J36: 59666 | K36: 58493 | L36: 59106 | M36: 59916 | N36: 59814 | O36: 60696
A37: 1991.4 | B37: 3797 | C37: 14259 | D37: 28024 | E37: 40545 | F37: 48147 | G37: 54602 | H37: 58775 | I37: 58620 | J37: 58270 | K37: 59380 | L37: 59800 | M37: 60963 | N37: 61068
A38: 1992.1 | B38: 5135 | C38: 16850 | D38: 27327 | E38: 36669 | F38: 43512 | G38: 49161 | H38: 51595 | I38: 52060 | J38: 51888 | K38: 52340 | L38: 53333 | M38: 53455
A39: 1992.2 | B39: 3052 | C39: 8282 | D39: 16036 | E39: 24417 | F39: 31064 | G39: 33060 | H39: 35210 | I39: 35543 | J39: 36320 | K39: 36680 | L39: 37393
A40: 1992.3 | B40: 4619 | C40: 15383 | D40: 21122 | E40: 45310 | F40: 50764 | G40: 53069 | H40: 55737 | I40: 59254 | J40: 60047 | K40: 62118
A41: 1992.4 | B41: 3596 | C41: 12562 | D41: 23922 | E41: 33822 | F41: 41006 | G41: 44785 | H41: 47814 | I41: 49581 | J41: 50766
A42: 1993.1 | B42: 3786 | C42: 12318 | D42: 18973 | E42: 26870 | F42: 31880 | G42: 34297 | H42: 36340 | I42: 39519
A43: 1993.2 | B43: 2091 | C43: 7172 | D43: 12834 | E43: 20247 | F43: 24915 | G43: 27847 | H43: 30286
A44: 1993.3 | B44: 5349 | C44: 14393 | D44: 25756 | E44: 40138 | F44: 46561 | G44: 51005
A45: 1993.4 | B45: 2881 | C45: 10585 | D45: 20030 | E45: 27906 | F45: 34516
A46: 1994.1 | B46: 6241 | C46: 9031 | D46: 14755 | E46: 21189
...
