Workbook

Sheet Title
B1: Financial Allocations Committee (FAC) Campus Clubs & Student Programs Budget Proposal Form 2013-2014
B5: Directions for completing: Enter information into the cells that are shaded pale yellow (be sure to complete all of the yellow cells in the Title Tab; utilize those appropriate to your specific budget needs for the General Costs and Travel tabs). Provide as much detail as possible so that the committee has a clear understanding of why you are participating in events and how the money your club receives directly relates to your group achieving its mission and objectives/goals. The budget request amounts will tally for you as you enter information. If there is a cell that is not open to enter information into, that is because the cell is locked. These cells are locked for specific functions, and should not be tampered with. If you have any questions about completing the form, contact Patrick Oswald in the ASOIT office at 541-885-1830 or email patrick.oswald@oit.edu.
B10: NOTE THAT THERE ARE TABS AT THE BOTTOM OF THE SPREADSHEET. Once your form is complete, send it as an email attachment to asoit@oit.edu.
B12: Campus Clubs are able to request funding between $300 - $1,500 total per academic year.
D14: Name of organization:
D15: SAC #:
D16: Contact person(s):
D17: Email:
D18: Name of Advisor:
D19: Are you a currently active/registered club or program?
D20: Number of ACTIVE student members:
D21: Number of members particiapting in community service:
D22: Does your club collect dues? If so, how much?
E24: Proposed Budget
E26: Printing & Mailing | F26: ='General costs'!A9 -> 0 | G26: Speaker/Performers | H26: ='General costs'!A69 -> 0
E27: Student Leader Wages | F27: ='General costs'!A24 -> 0 | G27: Capital Expenditures | H27: ='General costs'!A83 -> 0
E28: Supplies | F28: ='General costs'!A37 -> 0 | G28: Miscellaneous | H28: ='General costs'!A101 -> 0
E29: Food | F29: ='General costs'!A60 -> 0 | G29: Travel | H29: =Travel!I91 -> 0
E31: Grand Total Requested: | H31: =F26+F27+F28+F29+H26+H27+H28+H29 -> 0
E32: Grand Total Allocated: | H32: ='General costs'!G106+Travel!J91 -> 0

Sheet General costs
A1: GENERAL COSTS
A4: Printing & Mailing | F4: $ Requested | G4: $ Allocated
B5: Walk-up copying ($25 will cover about 350 copies)
B6: Postage - please describe need/use for postage in cell below.
A9: =SUM(F5:F6) -> 0
A11: Notes from Fee Committee:
A14: Student Leader Wages (Student Programs) | B14: Position Title | C14: Hourly Rate | D14: Hours per week | E14: # of weeks | F14: $ Requested | G14: $ Allocated
F15: =C15*D15*E15 -> 0
F16: =C16*D16*E16 -> 0
F17: =C17*D17*E17 -> 0
F18: =C18*D18*E18 -> 0
F19: =C19*D19*E19 -> 0
F20: =C20*D20*E20 -> 0
F21: =C21*D21*E21 -> 0
F22: =C22*D22*E22 -> 0
F23: =C23*D23*E23 -> 0
A24: =SUM(F15:F24) -> 0 | F24: =C24*D24*E24 -> 0
A26: Notes from Fee Committee:
A29: Supplies | B29: Description of Supplies | F29: $ Requested | G29: $ Allocated
A37: =SUM(F30:F37) -> 0
A39: Notes from Fee Committee:
A42: Food | D42: Price per person | E42: # of people | F42: $ Requested | G42: $ Allocated
B43: Food for 1st meeting of Fall quarter | F43: =D43*E43 -> 0
B44: Food for 1st meeting of Spring quarter | F44: =D44*E44 -> 0
B45: Food for end of year celebration | F45: =D45*E45 -> 0
B46: Food for campus-wide events (all students invited) - Fall quarter | F46: =D46*E46 -> 0
B47: Description of Fall events where food is requested:
B51: Food for campus-wide events (all students invited) - Winter quarter | F51: =D51*E51 -> 0
B52: Description of Winter events where food is requested:
B56: Food for campus-wide events (all students invited) - Spring quarter | F56: =D56*E56 -> 0
B57: Description of Spring events where food is requested:
A60: =SUM(F43:F56) -> 0
A62: Notes from Fee Committee:
A65: Speaker/Performer Fees Description of Speaker/Performer | F65: $ Requested | G65: $ Allocated
A69: =F66 -> 0
A71: Notes from Fee Committee:
A74: Capital Expenditures
A75: Items that will be used for more than one year | F75: $ Requested | G75: $ Allocated
A83: =SUM(F76:F82) -> 0
A85: Notes from Fee Committee:
...

Sheet Travel
A1: Travel
A3: Maximum meal allowance for travel is $52 per person per day. Groups may request lower food allowance in order to prioritze budget to other areas as desired.
A6: Trip #1
A7: Detailed description of conference/travel event (including who would be traveling)
A15: Travel | B15: Purpose | C15: # | D15: of | E15: $$ | F15: per | G15: # | H15: of | I15: $ Requested | J15: $ Allocated
B16: Transportation (air) | D16: travelers | F16: airline ticket | I16: =C16*E16 -> 0
B17: Airport shuttle | D17: travelers | F17: shuttle ticket | I17: =C17*E17 -> 0
B18: Transportation (ground) | D18: vehicles | E18: 0.565 | F18: per mile | H18: round-trip mileage | I18: =C18*E18*G18 -> 0
B19: Registration fee for conference | D19: travelers | F19: per person | I19: =C19*E19 -> 0
B20: Meals | D20: travelers | F20: per person | H20: days | I20: =C20*E20*G20 -> 0
B21: Hotel | D21: rooms | F21: per room | H21: nights | I21: =C21*E21*G21 -> 0
A22: =SUM(I16:I22) -> 0 | B22: Other (rental vehicle, gas, etc.):
A24: Notes from Fee Committee:
A27: Trip #2
A28: Detailed description of conference/travel event (including who would be traveling)
A36: Travel | B36: Purpose | C36: # | D36: of | E36: $$ | F36: per | G36: # | H36: of | I36: $ Requested | J36: $ Allocated
B37: Transportation (air) | D37: travelers | F37: airline ticket | I37: =C37*E37 -> 0
B38: Airport shuttle | D38: travelers | F38: shuttle ticket | I38: =C38*E38 -> 0
B39: Transportation (ground) | D39: vehicles | E39: 0.565 | F39: per mile | H39: round-trip mileage | I39: =C39*E39*G39 -> 0
B40: Registration fee for conference | D40: travelers | F40: per person | I40: =C40*E40 -> 0
B41: Meals | D41: travelers | F41: per person | H41: days | I41: =C41*E41*G41 -> 0
B42: Hotel | D42: rooms | F42: per room | H42: nights | I42: =C42*E42*G42 -> 0
A43: =SUM(I37:I43) -> 0 | B43: Other (rental vehicle, gas, etc.):
A45: Notes from Fee Committee:
A48: Trip #3
A49: Detailed description of conference/travel event (including who would be traveling)
A57: Travel | B57: Purpose | C57: # | D57: of | E57: $$ | F57: per | G57: # | H57: of | I57: $ Requested | J57: $ Allocated
B58: Transportation (air) | D58: travelers | F58: airline ticket | I58: =C58*E58 -> 0
B59: Airport shuttle | D59: travelers | F59: shuttle ticket | I59: =C59*E59 -> 0
B60: Transportation (ground) | D60: vehicles | E60: 0.565 | F60: per mile | H60: round-trip mileage | I60: =C60*E60*G60 -> 0
B61: Registration fee for conference | D61: travelers | F61: per person | I61: =C61*E61 -> 0
B62: Meals | D62: travelers | F62: per person | H62: days | I62: =C62*E62*G62 -> 0
B63: Hotel | D63: rooms | F63: per room | H63: nights | I63: =C63*E63*G63 -> 0
A64: =SUM(I58:I64) -> 0 | B64: Other (rental vehicle, gas, etc.):
A66: Notes from Fee Committee:
A69: Trip #4
A70: Detailed description of conference/travel event (including who would be traveling)
A78: Travel | B78: Purpose | C78: # | D78: of | E78: $$ | F78: per | G78: # | H78: of | I78: $ Requested | J78: $ Allocated
B79: Transportation (air) | D79: travelers | F79: airline ticket | I79: =C79*E79 -> 0
B80: Airport shuttle | D80: travelers | F80: shuttle ticket | I80: =C80*E80 -> 0
...
