Workbook

Sheet January 2012 - Data
A1: Meter Read On: | B1: 41305
A2: Department | B2: General Ledger | C2: GL Description | D2: Building | E2: Room | F2: Model | G2: Device Type | H2: Ricoh Tag | I2: Total BW Click Count | J2: Total Color Click Count | K2: BW Click Charge | L2: Color Click Charge | M2: Device Total Click Charge | N2: Serial Number | O2: IP Address | P2: CPC BW | Q2: CPC Color | R2: Prev BW Click Count | S2: Current BW Click Count | T2: Prev Color Click Count | U2: Current Color Click Count
A3: Academic Advising | B3: 10_07_205_90300_5521 | C3: Academic Advising | D3: Shell Hall | E3: 301 | F3: AF SPC242DN | G3: =VLOOKUP(F3,Tables!D$9:E$17,2,FALSE) -> PTR | H3: 17099684 | I3: =SUM(S3-R3) -> 653 | J3: =SUM(U3-T3) -> 6 | K3: =SUM(I3*$P3) -> 17.1086 | L3: =SUM(J3*$Q3) -> 0.708 | M3: =K3+L3 -> 17.8166 | N3: T202P700442 | O3: 144.75.180.103 | P3: =IF(G3="MFP",Tables!B$2,Tables!B$5) -> 0.0262 | Q3: =IF(G3="MFP",Tables!B$3,Tables!B$6) -> 0.118 | R3: 1269 | S3: 1922 | T3: 320 | U3: 326
A4: Academic Advising Total | M4: =SUBTOTAL(9,M3:M3) -> 17.8166 | BC4: =SUBTOTAL(9,BC3:BC3) -> 0
A5: Admissions | B5: 10_03_054_01100_5521 | C5: Admissions | D5: 307 Letcher | E5: 204 | F5: AF MPC3502 | G5: =VLOOKUP(F5,Tables!D$9:E$17,2,FALSE) -> MFP | H5: 17099493 | I5: =SUM(S5-R5) -> 5305 | J5: =SUM(U5-T5) -> 1727 | K5: =SUM(I5*$P5) -> 109.8135 | L5: =SUM(J5*$Q5) -> 150.249 | M5: =K5+L5 -> 260.0625 | N5: W502L600872 | O5: 144.75.215.48 | P5: =IF(G5="MFP",Tables!B$2,Tables!B$5) -> 0.0207 | Q5: =IF(G5="MFP",Tables!B$3,Tables!B$6) -> 0.087 | R5: 22152 | S5: 27457 | T5: 9277 | U5: 11004
A6: Admissions | B6: 10_03_054_01100_5521 | C6: Admissions | D6: 309 Letcher | E6: 201 | F6: AF SP4310N | G6: =VLOOKUP(F6,Tables!D$9:E$17,2,FALSE) -> PTR | H6: 17099780 | I6: =SUM(S6-R6) -> 86 | J6: =SUM(U6-T6) -> 0 | K6: =SUM(I6*$P6) -> 2.2532 | L6: =SUM(J6*$Q6) -> 0 | M6: =K6+L6 -> 2.2532 | N6: T1128911219 | O6: 144.75.215.43 | P6: =IF(G6="MFP",Tables!B$2,Tables!B$5) -> 0.0262 | Q6: =IF(G6="MFP",Tables!B$3,Tables!B$6) -> 0.118 | R6: 313 | S6: 399 | T6: 0 | U6: 0
A7: Admissions | B7: 10_03_054_01100_5521 | C7: Admissions | D7: 309 Letcher | E7: 201 | F7: AF SP4310N | G7: =VLOOKUP(F7,Tables!D$9:E$17,2,FALSE) -> PTR | H7: 17099512 | I7: =SUM(S7-R7) -> 0 | J7: =SUM(U7-T7) -> 0 | K7: =SUM(I7*$P7) -> 0 | L7: =SUM(J7*$Q7) -> 0 | M7: =K7+L7 -> 0 | N7: T1129010877 | O7: 144.75.186.30 | P7: =IF(G7="MFP",Tables!B$2,Tables!B$5) -> 0.0262 | Q7: =IF(G7="MFP",Tables!B$3,Tables!B$6) -> 0.118 | R7: 48 | S7: 48 | T7: 0 | U7: 0
A8: Admissions | B8: 10_03_054_01100_5521 | C8: Admissions | D8: 309 Letcher | E8: 207 | F8: AF SP4310N | G8: =VLOOKUP(F8,Tables!D$9:E$17,2,FALSE) -> PTR | H8: 17099440 | I8: =SUM(S8-R8) -> 0 | J8: =SUM(U8-T8) -> 0 | K8: =SUM(I8*$P8) -> 0 | L8: =SUM(J8*$Q8) -> 0 | M8: =K8+L8 -> 0 | N8: T1129010899 | O8: 144.75.178.24 | P8: =IF(G8="MFP",Tables!B$2,Tables!B$5) -> 0.0262 | Q8: =IF(G8="MFP",Tables!B$3,Tables!B$6) -> 0.118 | R8: 471 | S8: 471 | T8: 0 | U8: 0
A9: Admissions | B9: 10_03_054_01100_5521 | C9: Admissions | D9: 309 Letcher | E9: 301 | F9: AF SPC242DN | G9: =VLOOKUP(F9,Tables!D$9:E$17,2,FALSE) -> PTR | H9: 17099522 | I9: =SUM(S9-R9) -> 0 | J9: =SUM(U9-T9) -> 0 | K9: =SUM(I9*$P9) -> 0 | L9: =SUM(J9*$Q9) -> 0 | M9: =K9+L9 -> 0 | N9: T202P700447 | O9: 144.75.186.28 | P9: =IF(G9="MFP",Tables!B$2,Tables!B$5) -> 0.0262 | Q9: =IF(G9="MFP",Tables!B$3,Tables!B$6) -> 0.118 | R9: 716 | S9: 716 | T9: 141 | U9: 141
A10: Admissions | B10: 10_03_054_01100_5521 | C10: Admissions | D10: 309 Letcher | E10: 302 | F10: AF SPC242DN | G10: =VLOOKUP(F10,Tables!D$9:E$17,2,FALSE) -> PTR | H10: 17099423 | I10: =SUM(S10-R10) -> 43 | J10: =SUM(U10-T10) -> 17 | K10: =SUM(I10*$P10) -> 1.1266 | L10: =SUM(J10*$Q10) -> 2.006 | M10: =K10+L10 -> 3.1326 | N10: T202P700463 | O10: 144.75.186.29 | P10: =IF(G10="MFP",Tables!B$2,Tables!B$5) -> 0.0262 | Q10: =IF(G10="MFP",Tables!B$3,Tables!B$6) -> 0.118 | R10: 47 | S10: 90 | T10: 197 | U10: 214
A11: Admissions | B11: 10_03_054_01100_5521 | C11: Admissions | D11: 309 Letcher | E11: 306 | F11: AF SPC242DN | G11: =VLOOKUP(F11,Tables!D$9:E$17,2,FALSE) -> PTR | H11: 17099511 | I11: =SUM(S11-R11) -> 65 | J11: =SUM(U11-T11) -> 120 | K11: =SUM(I11*$P11) -> 1.703 | L11: =SUM(J11*$Q11) -> 14.16 | M11: =K11+L11 -> 15.863 | N11: T202P700465 | O11: 144.75.186.25 | P11: =IF(G11="MFP",Tables!B$2,Tables!B$5) -> 0.0262 | Q11: =IF(G11="MFP",Tables!B$3,Tables!B$6) -> 0.118 | R11: 215 | S11: 280 | T11: 154 | U11: 274
A12: Admissions | B12: 10_03_054_01100_5521 | C12: Admissions | D12: 309 Letcher | E12: 306 | F12: AF SPC242DN | G12: =VLOOKUP(F12,Tables!D$9:E$17,2,FALSE) -> PTR | H12: 17099731 | I12: =SUM(S12-R12) -> 413 | J12: =SUM(U12-T12) -> 100 | K12: =SUM(I12*$P12) -> 10.8206 | L12: =SUM(J12*$Q12) -> 11.8 | M12: =K12+L12 -> 22.6206 | N12: T202P600637 | O12: 144.75.186.28 | P12: =IF(G12="MFP",Tables!B$2,Tables!B$5) -> 0.0262 | Q12: =IF(G12="MFP",Tables!B$3,Tables!B$6) -> 0.118 | R12: 561 | S12: 974 | T12: 125 | U12: 225
A13: Admissions Total | M13: =SUBTOTAL(9,M5:M12) -> 303.9319 | BC13: =SUBTOTAL(9,BC5:BC12) -> 0
A14: ADV | B14: 10_03_064_50550_5521 | C14: Printer Services | D14: Carroll Hall | E14: 210C | F14: AF SP4310N | G14: =VLOOKUP(F14,Tables!D$9:E$17,2,FALSE) -> PTR | H14: 17099562 | I14: =SUM(S14-R14) -> 1887 | J14: =SUM(U14-T14) -> 0 | K14: =SUM(I14*$P14) -> 49.4394 | L14: =SUM(J14*$Q14) -> 0 | M14: =K14+L14 -> 49.4394 | N14: T1128911292 | O14: 144.75.195.20 | P14: =IF(G14="MFP",Tables!B$2,Tables!B$5) -> 0.0262 | Q14: =IF(G14="MFP",Tables!B$3,Tables!B$6) -> 0.118 | R14: 1410 | S14: 3297 | T14: 0 | U14: 0
A15: ADV Total | M15: =SUBTOTAL(9,M14:M14) -> 49.4394 | BC15: =SUBTOTAL(9,BC14:BC14) -> 0
A16: Air Force Rotc | B16: 10_03_011_02100_5521 | C16: ROTC-Air Force | D16: Kilbourne Hall | E16: 2012 | F16: AF SP4310N | G16: =VLOOKUP(F16,Tables!D$9:E$17,2,FALSE) -> PTR | H16: 17099443 | I16: =SUM(S16-R16) -> 0 | J16: =SUM(U16-T16) -> 0 | K16: =SUM(I16*$P16) -> 0 | L16: =SUM(J16*$Q16) -> 0 | M16: =K16+L16 -> 0 | N16: T1129010871 | O16: 144.75.187.135 | P16: =IF(G16="MFP",Tables!B$2,Tables!B$5) -> 0.0262 | Q16: =IF(G16="MFP",Tables!B$3,Tables!B$6) -> 0.118 | R16: 319 | S16: 319 | T16: 0 | U16: 0
A17: Air Force Rotc | B17: 10_03_011_02100_5521 | C17: ROTC-Air Force | D17: Kilbourne Hall | E17: 2018 | F17: AF SP4310N | G17: =VLOOKUP(F17,Tables!D$9:E$17,2,FALSE) -> PTR | H17: 17099438 | I17: =SUM(S17-R17) -> 0 | J17: =SUM(U17-T17) -> 0 | K17: =SUM(I17*$P17) -> 0 | L17: =SUM(J17*$Q17) -> 0 | M17: =K17+L17 -> 0 | N17: T1129010832 | O17: 144.75.187.138 | P17: =IF(G17="MFP",Tables!B$2,Tables!B$5) -> 0.0262 | Q17: =IF(G17="MFP",Tables!B$3,Tables!B$6) -> 0.118 | R17: 834 | S17: 834 | T17: 0 | U17: 0
A18: Air Force Rotc Total | M18: =SUBTOTAL(9,M16:M17) -> 0 | BC18: =SUBTOTAL(9,BC16:BC17) -> 0
A19: Army Rotc | B19: 10_03_011_04100_5521 | C19: ROTC-Army | D19: Kilbourne Hall | E19: 2022 | F19: AF MPC3502 | G19: =VLOOKUP(F19,Tables!D$9:E$17,2,FALSE) -> MFP | H19: 17099434 | I19: =SUM(S19-R19) -> 11367 | J19: =SUM(U19-T19) -> 1929 | K19: =SUM(I19*$P19) -> 235.2969 | L19: =SUM(J19*$Q19) -> 167.823 | M19: =K19+L19 -> 403.1199 | N19: W502L600854 | O19: 144.75.187.122 | P19: =IF(G19="MFP",Tables!B$2,Tables!B$5) -> 0.0207 | Q19: =IF(G19="MFP",Tables!B$3,Tables!B$6) -> 0.087 | R19: 53336 | S19: 64703 | T19: 3726 | U19: 5655
A20: Army Rotc | B20: 10_03_011_04100_5521 | C20: ROTC-Army | D20: Kilbourne Hall | E20: 2023 | F20: AF SP4310N | G20: =VLOOKUP(F20,Tables!D$9:E$17,2,FALSE) -> PTR | H20: 17099435 | I20: =SUM(S20-R20) -> 88 | J20: =SUM(U20-T20) -> 0 | K20: =SUM(I20*$P20) -> 2.3056 | L20: =SUM(J20*$Q20) -> 0 | M20: =K20+L20 -> 2.3056 | N20: T1129010902 | O20: 144.75.187.16 | P20: =IF(G20="MFP",Tables!B$2,Tables!B$5) -> 0.0262 | Q20: =IF(G20="MFP",Tables!B$3,Tables!B$6) -> 0.118 | R20: 280 | S20: 368 | T20: 0 | U20: 0
A21: Army Rotc | B21: 10_03_011_04100_5521 | C21: ROTC-Army | D21: Kilbourne Hall | E21: 2029 | F21: AF SP4310N | G21: =VLOOKUP(F21,Tables!D$9:E$17,2,FALSE) -> PTR | H21: 17099446 | I21: =SUM(S21-R21) -> 20 | J21: =SUM(U21-T21) -> 0 | K21: =SUM(I21*$P21) -> 0.524 | L21: =SUM(J21*$Q21) -> 0 | M21: =K21+L21 -> 0.524 | N21: T1129010869 | O21: 144.75.187.137 | P21: =IF(G21="MFP",Tables!B$2,Tables!B$5) -> 0.0262 | Q21: =IF(G21="MFP",Tables!B$3,Tables!B$6) -> 0.118 | R21: 256 | S21: 276 | T21: 0 | U21: 0
A22: Army Rotc | B22: 10_03_011_04100_5521 | C22: ROTC-Army | D22: Kilbourne Hall | E22: 2053 | F22: AF SP4310N | G22: =VLOOKUP(F22,Tables!D$9:E$17,2,FALSE) -> PTR | H22: 17099437 | I22: =SUM(S22-R22) -> 566 | J22: =SUM(U22-T22) -> 0 | K22: =SUM(I22*$P22) -> 14.8292 | L22: =SUM(J22*$Q22) -> 0 | M22: =K22+L22 -> 14.8292 | N22: T1129010748 | O22: 144.75.187.112 | P22: =IF(G22="MFP",Tables!B$2,Tables!B$5) -> 0.0262 | Q22: =IF(G22="MFP",Tables!B$3,Tables!B$6) -> 0.118 | R22: 520 | S22: 1086 | T22: 0 | U22: 0
A23: Army Rotc | B23: 10_03_011_04100_5521 | C23: ROTC-Army | D23: Kilbourne Hall | E23: 2056 | F23: AF SP4310N | G23: =VLOOKUP(F23,Tables!D$9:E$17,2,FALSE) -> PTR | H23: 17099436 | I23: =SUM(S23-R23) -> 446 | J23: =SUM(U23-T23) -> 0 | K23: =SUM(I23*$P23) -> 11.6852 | L23: =SUM(J23*$Q23) -> 0 | M23: =K23+L23 -> 11.6852 | N23: T1129010837 | O23: 144.75.187.131 | P23: =IF(G23="MFP",Tables!B$2,Tables!B$5) -> 0.0262 | Q23: =IF(G23="MFP",Tables!B$3,Tables!B$6) -> 0.118 | R23: 1170 | S23: 1616 | T23: 0 | U23: 0
A24: Army Rotc | B24: 10_03_011_04100_5521 | C24: ROTC-Army | D24: Kilbourne Hall | E24: 2057 | F24: AF SP4310N | G24: =VLOOKUP(F24,Tables!D$9:E$17,2,FALSE) -> PTR | H24: 17099444 | I24: =SUM(S24-R24) -> 818 | J24: =SUM(U24-T24) -> 0 | K24: =SUM(I24*$P24) -> 21.4316 | L24: =SUM(J24*$Q24) -> 0 | M24: =K24+L24 -> 21.4316 | N24: T1129010677 | O24: 144.75.187.133 | P24: =IF(G24="MFP",Tables!B$2,Tables!B$5) -> 0.0262 | Q24: =IF(G24="MFP",Tables!B$3,Tables!B$6) -> 0.118 | R24: 1743 | S24: 2561 | T24: 0 | U24: 0
A25: Army Rotc | B25: 10_03_011_04100_5521 | C25: ROTC-Army | D25: Kilbourne Hall | E25: 2060 | F25: AF SP4310N | G25: =VLOOKUP(F25,Tables!D$9:E$17,2,FALSE) -> PTR | H25: 17099430 | I25: =SUM(S25-R25) -> 68 | J25: =SUM(U25-T25) -> 0 | K25: =SUM(I25*$P25) -> 1.7816 | L25: =SUM(J25*$Q25) -> 0 | M25: =K25+L25 -> 1.7816 | N25: T1129010760 | O25: 144.75.187.119 | P25: =IF(G25="MFP",Tables!B$2,Tables!B$5) -> 0.0262 | Q25: =IF(G25="MFP",Tables!B$3,Tables!B$6) -> 0.118 | R25: 219 | S25: 287 | T25: 0 | U25: 0
A26: Army Rotc | B26: 10_03_011_04100_5521 | C26: ROTC-Army | D26: Kilbourne Hall | E26: 2061 | F26: AF SP4310N | G26: =VLOOKUP(F26,Tables!D$9:E$17,2,FALSE) -> PTR | H26: 17099442 | I26: =SUM(S26-R26) -> 157 | J26: =SUM(U26-T26) -> 0 | K26: =SUM(I26*$P26) -> 4.1134 | L26: =SUM(J26*$Q26) -> 0 | M26: =K26+L26 -> 4.1134 | N26: T1129010681 | O26: 144.75.187.136 | P26: =IF(G26="MFP",Tables!B$2,Tables!B$5) -> 0.0262 | Q26: =IF(G26="MFP",Tables!B$3,Tables!B$6) -> 0.118 | R26: 346 | S26: 503 | T26: 0 | U26: 0
A27: Army Rotc | B27: 10_03_011_04100_5521 | C27: ROTC-Army | D27: Kilbourne Hall | E27: 2063 | F27: AF SP4310N | G27: =VLOOKUP(F27,Tables!D$9:E$17,2,FALSE) -> PTR | H27: 17099427 | I27: =SUM(S27-R27) -> 309 | J27: =SUM(U27-T27) -> 0 | K27: =SUM(I27*$P27) -> 8.0958 | L27: =SUM(J27*$Q27) -> 0 | M27: =K27+L27 -> 8.0958 | N27: T1129010874 | O27: 144.75.187.118 | P27: =IF(G27="MFP",Tables!B$2,Tables!B$5) -> 0.0262 | Q27: =IF(G27="MFP",Tables!B$3,Tables!B$6) -> 0.118 | R27: 750 | S27: 1059 | T27: 0 | U27: 0
A28: Army Rotc | B28: 10_03_011_04100_5521 | C28: ROTC-Army | D28: Kilbourne Hall | E28: 2064 | F28: AF SP4310N | G28: =VLOOKUP(F28,Tables!D$9:E$17,2,FALSE) -> PTR | H28: 17099439 | I28: =SUM(S28-R28) -> 96 | J28: =SUM(U28-T28) -> 0 | K28: =SUM(I28*$P28) -> 2.5152 | L28: =SUM(J28*$Q28) -> 0 | M28: =K28+L28 -> 2.5152 | N28: T1129010823 | O28: 144.75.187.140 | P28: =IF(G28="MFP",Tables!B$2,Tables!B$5) -> 0.0262 | Q28: =IF(G28="MFP",Tables!B$3,Tables!B$6) -> 0.118 | R28: 651 | S28: 747 | T28: 0 | U28: 0
A29: Army Rotc | B29: 10_03_011_04100_5521 | C29: ROTC-Army | D29: Kilbourne Hall | E29: 2066 | F29: AF SP4310N | G29: =VLOOKUP(F29,Tables!D$9:E$17,2,FALSE) -> PTR | H29: 17099426 | I29: =SUM(S29-R29) -> 109 | J29: =SUM(U29-T29) -> 0 | K29: =SUM(I29*$P29) -> 2.8558 | L29: =SUM(J29*$Q29) -> 0 | M29: =K29+L29 -> 2.8558 | N29: T1129010820 | O29: 144.75.187.121 | P29: =IF(G29="MFP",Tables!B$2,Tables!B$5) -> 0.0262 | Q29: =IF(G29="MFP",Tables!B$3,Tables!B$6) -> 0.118 | R29: 220 | S29: 329 | T29: 0 | U29: 0
A30: Army Rotc | B30: 10_03_011_04100_5521 | C30: ROTC-Army | D30: Kilbourne Hall | E30: 2067 | F30: AF SP4310N | G30: =VLOOKUP(F30,Tables!D$9:E$17,2,FALSE) -> PTR | H30: 17099425 | I30: =SUM(S30-R30) -> 116 | J30: =SUM(U30-T30) -> 0 | K30: =SUM(I30*$P30) -> 3.0392 | L30: =SUM(J30*$Q30) -> 0 | M30: =K30+L30 -> 3.0392 | N30: T1129010889 | O30: 144.75.187.123 | P30: =IF(G30="MFP",Tables!B$2,Tables!B$5) -> 0.0262 | Q30: =IF(G30="MFP",Tables!B$3,Tables!B$6) -> 0.118 | R30: 645 | S30: 761 | T30: 0 | U30: 0
A31: Army Rotc | B31: 10_03_011_04100_5521 | C31: ROTC-Army | D31: Kilbourne Hall | E31: 2070 | F31: AF SP4310N | G31: =VLOOKUP(F31,Tables!D$9:E$17,2,FALSE) -> PTR | H31: 17099428 | I31: =SUM(S31-R31) -> 196 | J31: =SUM(U31-T31) -> 0 | K31: =SUM(I31*$P31) -> 5.1352 | L31: =SUM(J31*$Q31) -> 0 | M31: =K31+L31 -> 5.1352 | N31: T1129010900 | O31: 144.75.187.132 | P31: =IF(G31="MFP",Tables!B$2,Tables!B$5) -> 0.0262 | Q31: =IF(G31="MFP",Tables!B$3,Tables!B$6) -> 0.118 | R31: 846 | S31: 1042 | T31: 0 | U31: 0
A32: Army Rotc Total | M32: =SUBTOTAL(9,M19:M31) -> 481.4317 | BC32: =SUBTOTAL(9,BC19:BC31) -> 0
A33: Athletic | B33: 30_00_310_06110_5521 | C33: Administrative | D33: Cameron Hall | E33: 241 | F33: AF SP4310N | G33: =VLOOKUP(F33,Tables!D$9:E$17,2,FALSE) -> PTR | H33: 17099552 | I33: =SUM(S33-R33) -> 1148 | J33: =SUM(U33-T33) -> 0 | K33: =SUM(I33*$P33) -> 30.0776 | L33: =SUM(J33*$Q33) -> 0 | M33: =K33+L33 -> 30.0776 | N33: T1129010427 | O33: 144.75.183.9 | P33: =IF(G33="MFP",Tables!B$2,Tables!B$5) -> 0.0262 | Q33: =IF(G33="MFP",Tables!B$3,Tables!B$6) -> 0.118 | R33: 1961 | S33: 3109 | T33: 0 | U33: 0
A34: Athletic Total | M34: =SUBTOTAL(9,M33:M33) -> 30.0776 | BC34: =SUBTOTAL(9,BC33:BC33) -> 0
A35: Athletic Advising | B35: 40_00_052_06550_5521 | C35: NCAA Enhancement | D35: Carroll Hall | E35: 210 | F35: AF MPC2051 | G35: =VLOOKUP(F35,Tables!D$9:E$17,2,FALSE) -> MFP | H35: 17099459 | I35: =SUM(S35-R35) -> 4476 | J35: =SUM(U35-T35) -> 207 | K35: =SUM(I35*$P35) -> 92.6532 | L35: =SUM(J35*$Q35) -> 18.009 | M35: =K35+L35 -> 110.6622 | N35: V9725401429 | O35: 144.75.195.41 | P35: =IF(G35="MFP",Tables!B$2,Tables!B$5) -> 0.0207 | Q35: =IF(G35="MFP",Tables!B$3,Tables!B$6) -> 0.087 | R35: 19611 | S35: 24087 | T35: 2882 | U35: 3089
A36: Athletic Advising Total | M36: =SUBTOTAL(9,M35:M35) -> 110.6622 | BC36: =SUBTOTAL(9,BC35:BC35) -> 0
A37: Athletic Communications | B37: 30_00_310_06104_5521 | C37: Athletic Communications | D37: Smith Hall | E37: 116 | F37: AF MP301SP | G37: =VLOOKUP(F37,Tables!D$9:E$17,2,FALSE) -> MFP | H37: 17099531 | I37: =SUM(S37-R37) -> 1173 | J37: =SUM(U37-T37) -> 0 | K37: =SUM(I37*$P37) -> 24.2811 | L37: =SUM(J37*$Q37) -> 0 | M37: =K37+L37 -> 24.2811 | N37: W912P602286 | O37: 144.75.179.49 | P37: =IF(G37="MFP",Tables!B$2,Tables!B$5) -> 0.0207 | Q37: =IF(G37="MFP",Tables!B$3,Tables!B$6) -> 0.087 | R37: 2520 | S37: 3693 | T37: 0 | U37: 0
A38: Athletic Communications Total | M38: =SUBTOTAL(9,M37:M37) -> 24.2811 | BC38: =SUBTOTAL(9,BC37:BC37) -> 0
A39: Athletics | B39: 30_00_310_06020_5521 | C39: Track & Cross Country | D39: Cameron Hall | E39: 231 | F39: AF SP4310N | G39: =VLOOKUP(F39,Tables!D$9:E$17,2,FALSE) -> PTR | H39: 17099560 | I39: =SUM(S39-R39) -> 709 | J39: =SUM(U39-T39) -> 0 | K39: =SUM(I39*$P39) -> 18.5758 | L39: =SUM(J39*$Q39) -> 0 | M39: =K39+L39 -> 18.5758 | N39: T1129010426 | O39: 144.75.183.68 | P39: =IF(G39="MFP",Tables!B$2,Tables!B$5) -> 0.0262 | Q39: =IF(G39="MFP",Tables!B$3,Tables!B$6) -> 0.118 | R39: 1543 | S39: 2252 | T39: 0 | U39: 0
A40: Athletics | B40: 30_00_310_06090_5521 | C40: Athletics | D40: Cameron Hall | E40: 245 | F40: AF SP4310N | G40: =VLOOKUP(F40,Tables!D$9:E$17,2,FALSE) -> PTR | H40: 17099557 | I40: =SUM(S40-R40) -> 296 | J40: =SUM(U40-T40) -> 0 | K40: =SUM(I40*$P40) -> 7.7552 | L40: =SUM(J40*$Q40) -> 0 | M40: =K40+L40 -> 7.7552 | N40: T1129010429 | O40: 144.75.183.65 | P40: =IF(G40="MFP",Tables!B$2,Tables!B$5) -> 0.0262 | Q40: =IF(G40="MFP",Tables!B$3,Tables!B$6) -> 0.118 | R40: 396 | S40: 692 | T40: 0 | U40: 0
...

Sheet January 2013 - HP Toner
A1: Department | B1: General Ledger | C1: GL Description | D1: Building | E1: Room | F1: Model | G1: Device Type | H1: Ricoh Tag | I1: Toner Type | J1: Quantity | K1: Toner Cost Ea. | L1: Total Toner Cost | M1: Serial Number | N1: IP Address
A2: Superintendents House | B2: 10_03_061_94100_5521 | D2: Superintendents House | F2: M2727 | G2: HP-MFP | H2: 17099735 | I2: Black | K2: 25.32 | L2: =SUM(J2*K2) -> 0 | M2: CNG8961SWT | N2: 144.75.156.35
A3: Protocol | B3: 10_03_065_84100_5521 | C3: Protocol | D3: 303 Ltecher | F3: 4650 | G3: HP-PTR | H3: 17099-732 | I3: Black | J3: 2 | K3: 58.48 | L3: =SUM(J3*K3) -> 116.96 | M3: JPKAC48117 | N3: 144.75.178.14
A4: Protocol | B4: 10_03_065_84100_5521 | C4: Protocol | D4: 303 Ltecher | F4: 4650 | G4: HP-PTR | H4: 17099-732 | I4: Cyan | J4: 2 | K4: 58.48 | L4: =SUM(J4*K4) -> 116.96 | M4: JPKAC48117 | N4: 144.75.178.14
A5: Protocol | B5: 10_03_065_84100_5521 | C5: Protocol | D5: 303 Ltecher | F5: 4650 | G5: HP-PTR | H5: 17099-732 | I5: Magenta | J5: 2 | K5: 58.48 | L5: =SUM(J5*K5) -> 116.96 | M5: JPKAC48117 | N5: 144.75.178.14
A6: Protocol | B6: 10_03_065_84100_5521 | C6: Protocol | D6: 303 Ltecher | F6: 4650 | G6: HP-PTR | H6: 17099-732 | I6: Yellow | J6: 2 | K6: 58.48 | L6: =SUM(J6*K6) -> 116.96 | M6: JPKAC48117 | N6: 144.75.178.14
A7: Admissions | B7: 10_03_054_01100_5521 | C7: Admissions | D7: 307 Ltecher | F7: CP4025 | G7: HP-PTR | H7: 17099781 | I7: Black | K7: 89.75 | L7: =SUM(J7*K7) -> 0 | M7: JPBCBBMOSG | N7: 144.75.215.29
A8: Admissions | B8: 10_03_054_01100_5521 | C8: Admissions | D8: 307 Ltecher | F8: CP4025 | G8: HP-PTR | H8: 17099781 | I8: Cyan | K8: 91.49 | L8: =SUM(J8*K8) -> 0 | M8: JPBCBBMOSG | N8: 144.75.215.29
A9: Admissions | B9: 10_03_054_01100_5521 | C9: Admissions | D9: 307 Ltecher | F9: CP4025 | G9: HP-PTR | H9: 17099781 | I9: Magenta | K9: 91.49 | L9: =SUM(J9*K9) -> 0 | M9: JPBCBBMOSG | N9: 144.75.215.29
A10: Admissions | B10: 10_03_054_01100_5521 | C10: Admissions | D10: 307 Ltecher | F10: CP4025 | G10: HP-PTR | H10: 17099781 | I10: Yellow | K10: 91.49 | L10: =SUM(J10*K10) -> 0 | M10: JPBCBBMOSG | N10: 144.75.215.29
A11: Media Services | B11: 10_03_041_62100_5304 | C11: Media Services | D11: Preston Library | E11: 406 | F11: LJ3600 | G11: HP-PTR | H11: 17099815 | I11: Black | K11: 53.82 | L11: =SUM(J11*K11) -> 0 | M11: CNWDF12176 | N11: 144.75.196.251
A12: Media Services | B12: 10_03_041_62100_5304 | C12: Media Services | D12: Preston Library | E12: 406 | F12: LJ3600 | G12: HP-PTR | H12: 17099815 | I12: Cyan | K12: 61.89 | L12: =SUM(J12*K12) -> 0 | M12: CNWDF12177 | N12: 144.75.196.251
A13: Media Services | B13: 10_03_041_62100_5304 | C13: Media Services | D13: Preston Library | E13: 406 | F13: LJ3600 | G13: HP-PTR | H13: 17099815 | I13: Magenta | K13: 61.89 | L13: =SUM(J13*K13) -> 0 | M13: CNWDF12178 | N13: 144.75.196.251
A14: Media Services | B14: 10_03_041_62100_5304 | C14: Media Services | D14: Preston Library | E14: 406 | F14: LJ3600 | G14: HP-PTR | H14: 17099815 | I14: Yellow | K14: 61.89 | L14: =SUM(J14*K14) -> 0 | M14: CNWDF12179 | N14: 144.75.196.251
A15: Psychology & Philosophy | B15: 10_03_011_86100_5521 | C15: Psychology & Philosophy | D15: Carroll Hall | E15: 403 | F15: LJ4005 | G15: HP-PTR | H15: 17099728 | I15: Black | K15: 74.18 | L15: =SUM(J15*K15) -> 0 | M15: JPRLB46624 | N15: 144.75.195.232
A16: Psychology & Philosophy | B16: 10_03_011_86100_5521 | C16: Psychology & Philosophy | D16: Carroll Hall | E16: 403 | F16: LJ4005 | G16: HP-PTR | H16: 17099728 | I16: Cyan | K16: 76.19 | L16: =SUM(J16*K16) -> 0 | M16: JPRLB46625 | N16: 144.75.195.232
A17: Psychology & Philosophy | B17: 10_03_011_86100_5521 | C17: Psychology & Philosophy | D17: Carroll Hall | E17: 403 | F17: LJ4005 | G17: HP-PTR | H17: 17099728 | I17: Magenta | K17: 76.19 | L17: =SUM(J17*K17) -> 0 | M17: JPRLB46626 | N17: 144.75.195.232
A18: Psychology & Philosophy | B18: 10_03_011_86100_5521 | C18: Psychology & Philosophy | D18: Carroll Hall | E18: 403 | F18: LJ4005 | G18: HP-PTR | H18: 17099728 | I18: Yellow | K18: 76.19 | L18: =SUM(J18*K18) -> 0 | M18: JPRLB46627 | N18: 144.75.195.232
A19: Athletics | B19: 30_00_310_06090_5521 | C19: Administrative | D19: Cameron Hall | E19: 345 | F19: LJ4005 | G19: HP-PTR | H19: 17099-828 | I19: Black | K19: 74.18 | L19: =SUM(J19*K19) -> 0 | M19: JP4LC17284 | N19: Not on network
A20: Athletics | B20: 30_00_310_06090_5521 | C20: Administrative | D20: Cameron Hall | E20: 345 | F20: LJ4005 | G20: HP-PTR | H20: 17099-828 | I20: Cyan | K20: 76.19 | L20: =SUM(J20*K20) -> 0 | M20: JP4LC17284 | N20: Not on network
A21: Athletics | B21: 30_00_310_06090_5521 | C21: Administrative | D21: Cameron Hall | E21: 345 | F21: LJ4005 | G21: HP-PTR | H21: 17099-828 | I21: Magenta | K21: 76.19 | L21: =SUM(J21*K21) -> 0 | M21: JP4LC17284 | N21: Not on network
A22: Athletics | B22: 30_00_310_06090_5521 | C22: Administrative | D22: Cameron Hall | E22: 345 | F22: LJ4005 | G22: HP-PTR | H22: 17099-828 | I22: Yellow | K22: 76.19 | L22: =SUM(J22*K22) -> 0 | M22: JP4LC17284 | N22: Not on network
A23: Comptrollers | B23: 10_03_062_32100_5521 | C23: Comptroller's Office | D23: Smith Hall | E23: 311 | F23: P3010 | G23: HP-PTR | I23: Black | J23: 3 | K23: 32.03 | L23: =SUM(J23*K23) -> 96.09 | M23: VNBCC4L0MD | N23: 144.75.179.5
A24: Comptrollers | B24: 10_03_062_32100_5521 | C24: Comptroller's Office | D24: Smith Hall | E24: 320 | F24: P3010 | G24: HP-PTR | I24: Black | J24: 3 | K24: 32.03 | L24: =SUM(J24*K24) -> 96.09 | M24: VNBCC4L0M6 | N24: 144.75.179.31
L25: =SUM(L2:L24) -> 660.02
K26: Credit | L26: 155.73
K27: Total | L27: =660.02-155.73 -> 504.29

Sheet Tables
A1: Rates
A2: MFP B&W | B2: 0.0207
A3: MFP Color | B3: 0.087
A5: Printer B&W | B5: 0.0262
A6: Printer Color | B6: 0.118
D8: Devices | E8: Type
D9: AF MP301SP | E9: MFP
D10: AF MP4002 | E10: MFP
D11: AF MP6001 | E11: MFP
D12: AF MPC2051 | E12: MFP
D13: AF MPC3502 | E13: MFP
D14: AF MPC4502 | E14: MFP
D15: AF MPC6501 | E15: MFP
D16: AF SP4310N | E16: PTR
D17: AF SPC242DN | E17: PTR
A23: Meter Read on: | B23: 41274

Sheet Totals
D2: B&W MFP | E2: Color MFP | F2: B/W MFD | G2: Color MFD | J2: B&W MFP | K2: Color MFP
C3: MFP: | D3: =SUMIF('January 2012 - Data'!G$3:$G$295,"MFP",'January 2012 - Data'!I$3:I$295) -> 413231 | E3: =SUMIF('January 2012 - Data'!G$3:$G$295,"MFP",'January 2012 - Data'!J$3:J$295) -> 52007.1 | F3: =SUM(D3)*D14 -> 8553.8817 | G3: =SUM(E3)*E14 -> 4524.6177 | J3: =SUMIF('January 2012 - Data'!$G$3:G$295,"MFP",'January 2012 - Data'!K$3:K$295) -> 8553.8817 | K3: =SUMIF('January 2012 - Data'!$G$3:$G$295,"MFP",'January 2012 - Data'!L$3:L$295) -> 4524.6177
D5: B&W Printer | E5: Color Printer | F5: B/W Printer | G5: Color Printer | J5: B&W Printer | K5: Color Printer
C6: Printer: | D6: =SUMIF('January 2012 - Data'!G$3:$G$295,"PTR",'January 2012 - Data'!I$3:I$295) -> 102480 | E6: =SUMIF('January 2012 - Data'!G$3:$G$295,"PTR",'January 2012 - Data'!J$3:J$295) -> 932 | F6: =SUM(D6)*D15 -> 2684.976 | G6: =SUM(E6)*E15 -> 109.976 | J6: =SUMIF('January 2012 - Data'!$G$3:$G$295,"Ptr",'January 2012 - Data'!K$3:K$295) -> 2684.976 | K6: =SUMIF('January 2012 - Data'!$G$3:$G$295,"PTR",'January 2012 - Data'!L$3:L$295) -> 109.976
D8: Total B&W | E8: Total Color | F8: Total B&W | G8: Total Color | J8: Total B&W | K8: Total Color
C9: Total: | D9: =SUM(D3,D6) -> 515711 | E9: =SUM(E3,E6) -> 52939.1 | F9: =SUM(F3,F6) -> 11238.858 | G9: =SUM(G3,G6) -> 4634.5937 | J9: =SUM(J3,J6) -> 11238.858 | K9: =SUM(K3,K6) -> 4634.5937
F11: Total This Invoice: | G11: =SUM(F9:G9) -> 15873.451 | J11: Total This Invoice: | K11: =SUM(J9+K9) -> 15873.451
F12: HP Toner | G12: =+'January 2013 - HP Toner'!L27 -> 504.29 | J12: Total Invoice After Credit: | K12: =G13 -> 16377.741
F13: Invoice Total | G13: =SUM(G11+G12) -> 16377.741
C14: MFP | D14: =Tables!B2 -> 0.0207 | E14: =Tables!B3 -> 0.087
C15: Printer | D15: =Tables!B5 -> 0.0262 | E15: =Tables!B6 -> 0.118
F18: MFP Total: | G18: =COUNTIF('January 2012 - Data'!G3:G295,"MFP") -> 59
F19: Printer Total: | G19: =COUNTIF('January 2012 - Data'!G3:G295,"PTR") -> 163
F20: Device Total: | G20: =SUM(G18:G19) -> 222
