Workbook

Sheet Color Targets
F1: GCD xyY Target locations | J1: zoyd@avsforum | AA1: 2
A2: 100% Y [cd/m2] | B2: 124.54 | C2: <-Enter 100% white Y | AA2: 1 | AF2: Flat gamma | AG2: BT.709
A3: display gamma | B3: 2.3 | C3: =IF(AA1=1,"<-Enter average gamma","Using measured gamma") -> Using measured gamma | F3: Primaries/Secondaries | AF3: Measured gamma | AG3: BT.601
A4: 100L,100S | B4: x | C4: y | D4: Y [%] | E4: Y [cd/m2] | F4: 100L,75S | G4: x | H4: y | I4: Y [%] | J4: Y [cd/m2] | K4: 100L,50S | L4: x | M4: y | N4: Y [%] | O4: Y [cd/m2]
A5: R | B5: {=TRANSPOSE(Calculation!AD9:AJ11)} -> 0.63999993 | C5: 0.33000007 | D5: 0.2126729 | E5: =D5*$B$2 -> 26.486283 | F5: R | G5: {=TRANSPOSE(Calculation!AD14:AJ16)} -> 0.56044462 | H5: 0.32976259 | I5: 0.2115402 | J5: =I5*$B$2 -> 26.345216 | K5: R | L5: {=TRANSPOSE(Calculation!AD19:AJ21)} -> 0.48524771 | M5: 0.32953813 | N5: 0.20500129 | O5: =N5*$B$2 -> 25.530861
A6: G | B6: 0.30000001 | C6: 0.60000002 | D6: 0.7151522 | E6: =D6*$B$2 -> 89.065055 | F6: G | G6: 0.30297708 | H6: 0.53661173 | I6: 0.71507898 | J6: =I6*$B$2 -> 89.055936 | K6: G | L6: 0.30625756 | M6: 0.46676321 | N6: 0.70594629 | O6: =N6*$B$2 -> 87.918551
A7: B | B7: 0.15000001 | C7: 0.060000003 | D7: 0.072175 | E7: =D7*$B$2 -> 8.9886745 | F7: B | G7: 0.19040771 | H7: 0.12680289 | I7: 0.069820838 | J7: =I7*$B$2 -> 8.6954872 | K7: B | L7: 0.2274604 | M7: 0.18805921 | N7: 0.066436703 | O7: =N7*$B$2 -> 8.274027
A8: Y | B8: 0.41932009 | C8: 0.50524583 | D8: 0.9278251 | E8: =D8*$B$2 -> 115.55134 | F8: Y | G8: 0.39443192 | H8: 0.46410016 | I8: 0.91970268 | J8: =I8*$B$2 -> 114.53977 | K8: Y | L8: 0.36718822 | M8: 0.41906027 | N8: 0.93461746 | O8: =N8*$B$2 -> 116.39726
A9: C | B9: 0.22465563 | C9: 0.32876026 | D9: 0.7873272 | E9: =D9*$B$2 -> 98.053729 | F9: C | G9: 0.24543158 | H9: 0.32882228 | I9: 0.79499155 | J9: =I9*$B$2 -> 99.008248 | K9: C | L9: 0.26838801 | M9: 0.3288908 | N9: 0.7832059 | O9: =N9*$B$2 -> 97.540463
A10: M | B10: 0.32093774 | C10: 0.15419022 | D10: 0.2848479 | E10: =D10*$B$2 -> 35.474957 | F10: M | G10: 0.31901596 | H10: 0.19510902 | I10: 0.27479065 | J10: =I10*$B$2 -> 34.222427 | K10: M | L10: 0.31688663 | M10: 0.24044721 | N10: 0.27795722 | O10: =N10*$B$2 -> 34.616793
A11: W | B11: 0.3127266 | C11: 0.32902315 | D11: 1.0000001 | E11: =D11*$B$2 -> 124.54001 | F11: W | G11: 0.3127266 | H11: 0.32902315 | I11: 1.0000001 | J11: =I11*$B$2 -> 124.54001 | K11: W | L11: 0.3127266 | M11: 0.32902315 | N11: 1.0000001 | O11: =N11*$B$2 -> 124.54001
A13: 75L,100S | B13: x | C13: y | D13: Y [%] | E13: Y [cd/m2] | F13: 75L,75S | G13: x | H13: y | I13: Y [%] | J13: Y [cd/m2] | K13: 75L,50S | L13: x | M13: y | N13: Y [%] | O13: Y [cd/m2]
A14: R | B14: {=TRANSPOSE(Calculation!AD24:AJ26)} -> 0.63999993 | C14: 0.33000007 | D14: 0.11046403 | E14: =D14*$B$2 -> 13.75719 | F14: R | G14: {=TRANSPOSE(Calculation!AD29:AJ31)} -> 0.55424423 | H14: 0.32974409 | I14: 0.11092736 | J14: =I14*$B$2 -> 13.814894 | K14: R | L14: {=TRANSPOSE(Calculation!AD34:AJ36)} -> 0.48129346 | M14: 0.32952633 | N14: 0.10596346 | O14: =N14*$B$2 -> 13.19669
A15: G | B15: 0.30000001 | C15: 0.60000002 | D15: 0.37145585 | E15: =D15*$B$2 -> 46.261111 | F15: G | G15: 0.30311775 | H15: 0.53361644 | I15: 0.36629869 | J15: =I15*$B$2 -> 45.618838 | K15: G | L15: 0.30623308 | M15: 0.4672843 | N15: 0.36006191 | O15: =N15*$B$2 -> 44.842111
A16: B | B16: 0.15000001 | C16: 0.060000003 | D16: 0.03748828 | E16: =D16*$B$2 -> 4.6687904 | F16: B | G16: 0.1931885 | H16: 0.13140016 | I16: 0.039385092 | J16: =I16*$B$2 -> 4.9050194 | K16: B | L16: 0.23195368 | M16: 0.19548759 | N16: 0.036659149 | O16: =N16*$B$2 -> 4.5655305
A17: Y | B17: 0.41932009 | C17: 0.50524583 | D17: 0.48191988 | E17: =D17*$B$2 -> 60.018301 | F17: Y | G17: 0.39516492 | H17: 0.46531197 | I17: 0.48755853 | J17: =I17*$B$2 -> 60.720539 | K17: Y | L17: 0.3665712 | M17: 0.4180402 | N17: 0.48179758 | O17: =N17*$B$2 -> 60.003071
A18: C | B18: 0.22465563 | C18: 0.32876026 | D18: 0.40894413 | E18: =D18*$B$2 -> 50.929902 | F18: C | G18: 0.24561185 | H18: 0.32882281 | I18: 0.40649858 | J18: =I18*$B$2 -> 50.625333 | K18: C | L18: 0.26792112 | M18: 0.32888941 | N18: 0.39918404 | O18: =N18*$B$2 -> 49.714381
A19: M | B19: 0.32093774 | C19: 0.15419022 | D19: 0.14795231 | E19: =D19*$B$2 -> 18.42598 | F19: M | G19: 0.3188933 | H19: 0.19772086 | I19: 0.14527379 | J19: =I19*$B$2 -> 18.092398 | K19: M | L19: 0.31698397 | M19: 0.23837457 | N19: 0.14562268 | O19: =N19*$B$2 -> 18.135849
A20: W | B20: 0.3127266 | C20: 0.32902315 | D20: 0.51940816 | E20: =D20*$B$2 -> 64.687092 | F20: W | G20: 0.3127266 | H20: 0.32902315 | I20: 0.52008254 | J20: =I20*$B$2 -> 64.771079 | K20: W | L20: 0.3127266 | M20: 0.32902315 | N20: 0.52008254 | O20: =N20*$B$2 -> 64.771079
A22: 50L,100S | B22: x | C22: y | D22: Y [%] | E22: Y [cd/m2] | F22: 50L,75S | G22: x | H22: y | I22: Y [%] | J22: Y [cd/m2] | K22: 50L,50S | L22: x | M22: y | N22: Y [%] | O22: Y [cd/m2]
A23: R | B23: {=TRANSPOSE(Calculation!AD39:AJ41)} -> 0.63999993 | C23: 0.33000007 | D23: 0.044494375 | E23: =D23*$B$2 -> 5.5413295 | F23: R | G23: {=TRANSPOSE(Calculation!AD44:AJ47)} -> 0.54906457 | H23: 0.32972862 | I23: 0.044505974 | J23: =I23*$B$2 -> 5.5427741 | K23: R | L23: {=TRANSPOSE(Calculation!AD49:AJ51)} -> 0.47009869 | M23: 0.32949291 | N23: 0.044618426 | O23: =N23*$B$2 -> 5.5567787
A24: G | B24: 0.30000001 | C24: 0.60000002 | D24: 0.14962062 | E24: =D24*$B$2 -> 18.633751 | F24: G | G24: 0.30358775 | H24: 0.52360914 | I24: 0.14775543 | J24: =I24*$B$2 -> 18.401461 | K24: G | L24: 0.3062319 | M24: 0.46730957 | N24: 0.14881519 | O24: =N24*$B$2 -> 18.533444
A25: B | B25: 0.15000001 | C25: 0.060000003 | D25: 0.015100097 | E25: =D25*$B$2 -> 1.8805661 | F25: B | G25: 0.20232407 | H25: 0.14650329 | I25: 0.017087883 | J25: =I25*$B$2 -> 2.1281249 | K25: B | L25: 0.24219126 | M25: 0.21241258 | N25: 0.017477654 | O25: =N25*$B$2 -> 2.176667
A26: Y | B26: 0.41932009 | C26: 0.50524583 | D26: 0.19411499 | E26: =D26*$B$2 -> 24.175081 | F26: Y | G26: 0.39329834 | H26: 0.4622261 | I26: 0.19658049 | J26: =I26*$B$2 -> 24.482134 | K26: Y | L26: 0.36640007 | M26: 0.41775729 | N26: 0.18730843 | O26: =N26*$B$2 -> 23.327392
A27: C | B27: 0.22465563 | C27: 0.32876026 | D27: 0.16472071 | E27: =D27*$B$2 -> 20.514318 | F27: C | G27: 0.24697413 | H27: 0.32882688 | I27: 0.16326346 | J27: =I27*$B$2 -> 20.332831 | K27: C | L27: 0.26650073 | M27: 0.32888517 | N27: 0.16435938 | O27: =N27*$B$2 -> 20.469317
A28: M | B28: 0.32093774 | C28: 0.15419022 | D28: 0.059594472 | E28: =D28*$B$2 -> 7.4218956 | F28: M | G28: 0.31875144 | H28: 0.2007414 | I28: 0.059975652 | J28: =I28*$B$2 -> 7.4693677 | K28: M | L28: 0.31661172 | M28: 0.2463006 | N28: 0.058821211 | O28: =N28*$B$2 -> 7.3255937
A29: W | B29: 0.3127266 | C29: 0.32902315 | D29: 0.20973231 | E29: =D29*$B$2 -> 26.120062 | F29: W | G29: 0.3127266 | H29: 0.32902315 | I29: 0.20973231 | J29: =I29*$B$2 -> 26.120062 | K29: W | L29: 0.3127266 | M29: 0.32902315 | N29: 0.20973231 | O29: =N29*$B$2 -> 26.120062
A32: 12 pt Color Checker Palette
B33: x | C33: y | D33: Y [%] | E33: Y [cd/m2] | G33: Measured | H33: x | I33: y | J33: Y [%] | K33: Y [cd/m2] | L33: ΔL | M33: ΔC | N33: ΔH | O33: ΔE94 | P33: ΔE2000
A34: dark skin | B34: {=TRANSPOSE(Calculation!AY55:BJ57)} -> 0.40321384 | C34: 0.35684804 | D34: 0.093552266 | E34: =D34*$B$2 -> 11.650999 | G34: dark skin | H34: 0.408419 | I34: 0.360653 | J34: =K34/$B$2 -> 0.09161573 | K34: 11.409823 | L34: =Calculation!K130-Calculation!K115 -> -0.36588717 | M34: =SQRT(Calculation!L130^2+Calculation!M130^2)-SQRT(Calculation!L115^2+Calculation!M115^2) -> 0.8844092 | N34: =SQRT((Calculation!L115-Calculation!L130)^2+(Calculation!M115-Calculation!M130)^2-M34^2) -> 0.73545039 | O34: =SQRT(L34^2+(M34/Calculation!O115)^2+(N34/Calculation!P115)^2) -> 0.82929872 | P34: =Calculation!Z143 -> 0.84581604
A35: light skin | B35: 0.39039075 | C35: 0.3523353 | D35: 0.33962994 | E35: =D35*$B$2 -> 42.297512 | G35: light skin | H35: 0.39773 | I35: 0.352444 | J35: =K35/$B$2 -> 0.32272382 | K35: 40.192025 | L35: =Calculation!K131-Calculation!K116 -> -1.3658181 | M35: =SQRT(Calculation!L131^2+Calculation!M131^2)-SQRT(Calculation!L116^2+Calculation!M116^2) -> 1.9986989 | N35: =SQRT((Calculation!L116-Calculation!L131)^2+(Calculation!M116-Calculation!M131)^2-M35^2) -> 0.64167165 | O35: =SQRT(L35^2+(M35/Calculation!O116)^2+(N35/Calculation!P116)^2) -> 1.7197206 | P35: =Calculation!Z144 -> 1.5871792
A36: blue sky | B36: 0.24573825 | C36: 0.26550553 | D36: 0.17780171 | E36: =D36*$B$2 -> 22.143425 | G36: blue sky | H36: 0.242143 | I36: 0.264637 | J36: =K36/$B$2 -> 0.16743286 | K36: 20.852089 | L36: =Calculation!K132-Calculation!K117 -> -1.293452 | M36: =SQRT(Calculation!L132^2+Calculation!M132^2)-SQRT(Calculation!L117^2+Calculation!M117^2) -> 0.25035809 | N36: =SQRT((Calculation!L117-Calculation!L132)^2+(Calculation!M117-Calculation!M132)^2-M36^2) -> 0.96733066 | O36: =SQRT(L36^2+(M36/Calculation!O117)^2+(N36/Calculation!P117)^2) -> 1.4907088 | P36: =Calculation!Z145 -> 1.5828795
A37: foliage | B37: 0.34001315 | C37: 0.43110873 | D37: 0.12468343 | E37: =D37*$B$2 -> 15.528074 | G37: foliage | H37: 0.34057 | I37: 0.441484 | J37: =K37/$B$2 -> 0.12188947 | K37: 15.180115 | L37: =Calculation!K133-Calculation!K118 -> -0.43613718 | M37: =SQRT(Calculation!L133^2+Calculation!M133^2)-SQRT(Calculation!L118^2+Calculation!M118^2) -> 2.3212346 | N37: =SQRT((Calculation!L118-Calculation!L133)^2+(Calculation!M118-Calculation!M133)^2-M37^2) -> 0.30492126 | O37: =SQRT(L37^2+(M37/Calculation!O118)^2+(N37/Calculation!P118)^2) -> 1.1744726 | P37: =Calculation!Z146 -> 1.1636935
A38: blue flower | B38: 0.26747954 | C38: 0.25241969 | D38: 0.22545804 | E38: =D38*$B$2 -> 28.078544 | G38: blue flower | H38: 0.266168 | I38: 0.247941 | J38: =K38/$B$2 -> 0.21021229 | K38: 26.179839 | L38: =Calculation!K134-Calculation!K119 -> -1.6286658 | M38: =SQRT(Calculation!L134^2+Calculation!M134^2)-SQRT(Calculation!L119^2+Calculation!M119^2) -> 1.2347754 | N38: =SQRT((Calculation!L119-Calculation!L134)^2+(Calculation!M119-Calculation!M134)^2-M38^2) -> 0.61486544 | O38: =SQRT(L38^2+(M38/Calculation!O119)^2+(N38/Calculation!P119)^2) -> 1.7748167 | P38: =Calculation!Z147 -> 1.7225651
A39: bluish green | B39: 0.25592802 | C39: 0.35785158 | D39: 0.41108937 | E39: =D39*$B$2 -> 51.19707 | G39: bluish green | H39: 0.257224 | I39: 0.357795 | J39: =K39/$B$2 -> 0.39088513 | K39: 48.680834 | L39: =Calculation!K135-Calculation!K120 -> -1.436845 | M39: =SQRT(Calculation!L135^2+Calculation!M135^2)-SQRT(Calculation!L120^2+Calculation!M120^2) -> -1.1357742 | N39: =SQRT((Calculation!L120-Calculation!L135)^2+(Calculation!M120-Calculation!M135)^2-M39^2) -> 0.15864104 | O39: =SQRT(L39^2+(M39/Calculation!O120)^2+(N39/Calculation!P120)^2) -> 1.5099162 | P39: =Calculation!Z148 -> 1.2196245
A40: orange | B40: 0.51215226 | C40: 0.40055341 | D40: 0.29738541 | E40: =D40*$B$2 -> 37.036379 | G40: orange | H40: 0.509411 | I40: 0.399923 | J40: =K40/$B$2 -> 0.2974972 | K40: 37.050301 | L40: =Calculation!K136-Calculation!K121 -> 0.0097005725 | M40: =SQRT(Calculation!L136^2+Calculation!M136^2)-SQRT(Calculation!L121^2+Calculation!M121^2) -> -1.1153377 | N40: =SQRT((Calculation!L121-Calculation!L136)^2+(Calculation!M121-Calculation!M136)^2-M40^2) -> 0.15559725 | O40: =SQRT(L40^2+(M40/Calculation!O121)^2+(N40/Calculation!P121)^2) -> 0.29384259 | P40: =Calculation!Z149 -> 0.29829962
A41: purplish blue | B41: 0.2061789 | C41: 0.17618446 | D41: 0.10906319 | E41: =D41*$B$2 -> 13.582729 | G41: purplish blue | H41: 0.207919 | I41: 0.176846 | J41: =K41/$B$2 -> 0.10534646 | K41: 13.119848 | L41: =Calculation!K137-Calculation!K122 -> -0.63686239 | M41: =SQRT(Calculation!L137^2+Calculation!M137^2)-SQRT(Calculation!L122^2+Calculation!M122^2) -> -0.75028328 | N41: =SQRT((Calculation!L122-Calculation!L137)^2+(Calculation!M122-Calculation!M137)^2-M41^2) -> 0.49687523 | O41: =SQRT(L41^2+(M41/Calculation!O122)^2+(N41/Calculation!P122)^2) -> 0.7371592 | P41: =Calculation!Z150 -> 0.65472156
A42: moderate red | B42: 0.47543058 | C42: 0.31126718 | D42: 0.18424455 | E42: =D42*$B$2 -> 22.945816 | G42: moderate red | H42: 0.471151 | I42: 0.309233 | J42: =K42/$B$2 -> 0.18527007 | K42: 23.073534 | L42: =Calculation!K138-Calculation!K123 -> 0.12224017 | M42: =SQRT(Calculation!L138^2+Calculation!M138^2)-SQRT(Calculation!L123^2+Calculation!M123^2) -> -0.5276164 | N42: =SQRT((Calculation!L123-Calculation!L138)^2+(Calculation!M123-Calculation!M138)^2-M42^2) -> 1.0280451 | O42: =SQRT(L42^2+(M42/Calculation!O123)^2+(N42/Calculation!P123)^2) -> 0.61429804 | P42: =Calculation!Z151 -> 0.73816313
A43: purple | B43: 0.29368184 | C43: 0.22066105 | D43: 0.061107966 | E43: =D43*$B$2 -> 7.6103861 | G43: purple | H43: 0.293227 | I43: 0.213986 | J43: =K43/$B$2 -> 0.057424787 | K43: 7.151683 | L43: =Calculation!K139-Calculation!K124 -> -0.93705487 | M43: =SQRT(Calculation!L139^2+Calculation!M139^2)-SQRT(Calculation!L124^2+Calculation!M124^2) -> 1.9205646 | N43: =SQRT((Calculation!L124-Calculation!L139)^2+(Calculation!M124-Calculation!M139)^2-M43^2) -> 0.28523991 | O43: =SQRT(L43^2+(M43/Calculation!O124)^2+(N43/Calculation!P124)^2) -> 1.2454565 | P43: =Calculation!Z152 -> 1.0852469
A44: yellow green | B44: 0.37467418 | C44: 0.49875393 | D44: 0.43565985 | E44: =D44*$B$2 -> 54.257078 | G44: yellow green | H44: 0.374033 | I44: 0.493785 | J44: =K44/$B$2 -> 0.42397947 | K44: 52.802403 | L44: =Calculation!K140-Calculation!K125 -> -0.79302066 | M44: =SQRT(Calculation!L140^2+Calculation!M140^2)-SQRT(Calculation!L125^2+Calculation!M125^2) -> -2.4995921 | N44: =SQRT((Calculation!L125-Calculation!L140)^2+(Calculation!M125-Calculation!M140)^2-M44^2) -> 0.13577172 | O44: =SQRT(L44^2+(M44/Calculation!O125)^2+(N44/Calculation!P125)^2) -> 1.0196669 | P44: =Calculation!Z153 -> 0.88586988
...

Sheet Gamma Target
A1: BT.1886 Caculator | D1: a | E1: b | G1: vc | H1: a1 | I1: a2 | J1: k | K1: gamma
D2: =(C9^(1/K2)-C10^(1/K2))^K2 -> 114.3243 | E2: =C10^(1/K2)/(C9^(1/K2)-C10^(1/K2)) -> 0.036305068 | G2: 0.35 | H2: 2.6 | I2: 3 | J2: =100/(1+C11)^H2 -> 87.004879 | K2: 2.4
A4: Enter Peak white and mll values and then
A5: adjust 10 pt controls to hit L primary targets
C8: Y [cd/m2] | J8: Enter 10 or 20 step grey scale Y's here
B9: White | C9: 124.54 | E9: L(1.83%)
B10: Black | C10: 0.04 | E10: =$J$2*($G$2+$C$11)^($H$2-$I$2)*(0.0183+$C$11)^$I$2 -> 0.049189626
B11: Alt_b | C11: 0.055 | D11: <-Adjust this to get luminance of measured
D12: 1.83% pattern for alternate CRT emulation
C13: Stimulus[%*] | D13: L Primary | E13: L Alternate | F13: L Power | G13: gamma [primary] | H13: gamma [alternate] | I13: gamma [power] | J13: Measured luminance | K13: Normalized | L13: Measured gamma
C14: 0.01 | D14: =$D$2*(C14+$E$2)^$K$2 -> 0.071721116 | E14: =IF(C14<$G$2,$J$2*($G$2+$C$11)^($H$2-$I$2)*(C14+$C$11)^$I$2,$J$2*(C14+$C$11)^$H$2) -> 0.034300596 | F14: =$C$9*(C14)^'Color Targets'!$B$3 -> 0.0031283034 | G14: =LOG(D14/$C$9)/LOG(C14) -> 1.6198309 | H14: =LOG(E14/100)/LOG(C14) -> 1.7323492 | I14: =LOG(F14/$C$9)/LOG(C14) -> 2.3 | K14: =IF(J14=0,"",J14/$J$37) | L14: =IFERROR(LOG(K14)/LOG(C14),"")
C15: 0.02 | D15: =$D$2*(C15+$E$2)^$K$2 -> 0.11467072 | E15: =IF(C15<$G$2,$J$2*($G$2+$C$11)^($H$2-$I$2)*(C15+$C$11)^$I$2,$J$2*(C15+$C$11)^$H$2) -> 0.052692085 | F15: =$C$9*(C15)^'Color Targets'!$B$3 -> 0.015405573 | G15: =LOG(D15/$C$9)/LOG(C15) -> 1.7868805 | H15: =LOG(E15/100)/LOG(C15) -> 1.9295541 | I15: =LOG(F15/$C$9)/LOG(C15) -> 2.3 | K15: =IF(J15=0,"",J15/$J$37) | L15: =IFERROR(LOG(K15)/LOG(C15),"")
C16: 0.03 | D16: =$D$2*(C16+$E$2)^$K$2 -> 0.169766 | E16: =IF(C16<$G$2,$J$2*($G$2+$C$11)^($H$2-$I$2)*(C16+$C$11)^$I$2,$J$2*(C16+$C$11)^$H$2) -> 0.076704064 | F16: =$C$9*(C16)^'Color Targets'!$B$3 -> 0.039146032 | G16: =LOG(D16/$C$9)/LOG(C16) -> 1.8816062 | H16: =LOG(E16/100)/LOG(C16) -> 2.0455874 | I16: =LOG(F16/$C$9)/LOG(C16) -> 2.3 | K16: =IF(J16=0,"",J16/$J$37) | L16: =IFERROR(LOG(K16)/LOG(C16),"")
C17: 0.04 | D17: =$D$2*(C17+$E$2)^$K$2 -> 0.23783003 | E17: =IF(C17<$G$2,$J$2*($G$2+$C$11)^($H$2-$I$2)*(C17+$C$11)^$I$2,$J$2*(C17+$C$11)^$H$2) -> 0.10708593 | F17: =$C$9*(C17)^'Color Targets'!$B$3 -> 0.07586594 | G17: =LOG(D17/$C$9)/LOG(C17) -> 1.9450349 | H17: =LOG(E17/100)/LOG(C17) -> 2.1247461 | I17: =LOG(F17/$C$9)/LOG(C17) -> 2.3 | K17: =IF(J17=0,"",J17/$J$37) | L17: =IFERROR(LOG(K17)/LOG(C17),"")
C18: 0.050228311 | D18: =$D$2*(C18+$E$2)^$K$2 -> 0.32164689 | E18: =IF(C18<$G$2,$J$2*($G$2+$C$11)^($H$2-$I$2)*(C18+$C$11)^$I$2,$J$2*(C18+$C$11)^$H$2) -> 0.1455323 | F18: =$C$9*(C18)^'Color Targets'!$B$3 -> 0.12808273 | G18: =LOG(D18/$C$9)/LOG(C18) -> 1.9921686 | H18: =LOG(E18/100)/LOG(C18) -> 2.1839325 | I18: =LOG(F18/$C$9)/LOG(C18) -> 2.3 | K18: =IF(J18=0,"",J18/$J$37) | L18: =IFERROR(LOG(K18)/LOG(C18),"")
C19: 0.10045662 | D19: =$D$2*(C19+$E$2)^$K$2 -> 0.96483548 | E19: =IF(C19<$G$2,$J$2*($G$2+$C$11)^($H$2-$I$2)*(C19+$C$11)^$I$2,$J$2*(C19+$C$11)^$H$2) -> 0.46923378 | F19: =$C$9*(C19)^'Color Targets'!$B$3 -> 0.63075335 | G19: =LOG(D19/$C$9)/LOG(C19) -> 2.1150403 | H19: =LOG(E19/100)/LOG(C19) -> 2.3332272 | I19: =LOG(F19/$C$9)/LOG(C19) -> 2.3 | J19: 0.942 | K19: =IF(J19=0,"",J19/$J$37) -> 0.007564005 | L19: =IFERROR(LOG(K19)/LOG(C19),"") -> 2.1254535
C20: 0.15068493 | D20: =$D$2*(C20+$E$2)^$K$2 -> 2.0441026 | E20: =IF(C20<$G$2,$J$2*($G$2+$C$11)^($H$2-$I$2)*(C20+$C$11)^$I$2,$J$2*(C20+$C$11)^$H$2) -> 1.0868485 | F20: =$C$9*(C20)^'Color Targets'!$B$3 -> 1.6027636 | G20: =LOG(D20/$C$9)/LOG(C20) -> 2.1714815 | H20: =LOG(E20/100)/LOG(C20) -> 2.3892917 | I20: =LOG(F20/$C$9)/LOG(C20) -> 2.3 | K20: =IF(J20=0,"",J20/$J$37) | L20: =IFERROR(LOG(K20)/LOG(C20),"")
C21: 0.20091324 | D21: =$D$2*(C21+$E$2)^$K$2 -> 3.6182142 | E21: =IF(C21<$G$2,$J$2*($G$2+$C$11)^($H$2-$I$2)*(C21+$C$11)^$I$2,$J$2*(C21+$C$11)^$H$2) -> 2.0933405 | F21: =$C$9*(C21)^'Color Targets'!$B$3 -> 3.1061938 | G21: =LOG(D21/$C$9)/LOG(C21) -> 2.2049261 | H21: =LOG(E21/100)/LOG(C21) -> 2.4091546 | I21: =LOG(F21/$C$9)/LOG(C21) -> 2.3 | J21: 3.5246 | K21: =IF(J21=0,"",J21/$J$37) -> 0.028301584 | L21: =IFERROR(LOG(K21)/LOG(C21),"") -> 2.2212457
C22: 0.25114155 | D22: =$D$2*(C22+$E$2)^$K$2 -> 5.7368813 | E22: =IF(C22<$G$2,$J$2*($G$2+$C$11)^($H$2-$I$2)*(C22+$C$11)^$I$2,$J$2*(C22+$C$11)^$H$2) -> 3.5836735 | F22: =$C$9*(C22)^'Color Targets'!$B$3 -> 5.189453 | G22: =LOG(D22/$C$9)/LOG(C22) -> 2.2274194 | H22: =LOG(E22/100)/LOG(C22) -> 2.4091257 | I22: =LOG(F22/$C$9)/LOG(C22) -> 2.3 | K22: =IF(J22=0,"",J22/$J$37) | L22: =IFERROR(LOG(K22)/LOG(C22),"")
C23: 0.30136986 | D23: =$D$2*(C23+$E$2)^$K$2 -> 8.4437572 | E23: =IF(C23<$G$2,$J$2*($G$2+$C$11)^($H$2-$I$2)*(C23+$C$11)^$I$2,$J$2*(C23+$C$11)^$H$2) -> 5.6528115 | F23: =$C$9*(C23)^'Color Targets'!$B$3 -> 7.8929336 | G23: =LOG(D23/$C$9)/LOG(C23) -> 2.2437564 | H23: =LOG(E23/100)/LOG(C23) -> 2.3953447 | I23: =LOG(F23/$C$9)/LOG(C23) -> 2.3 | J23: 7.9661 | K23: =IF(J23=0,"",J23/$J$37) -> 0.063965626 | L23: =IFERROR(LOG(K23)/LOG(C23),"") -> 2.2922882
C24: 0.35159817 | D24: =$D$2*(C24+$E$2)^$K$2 -> 11.778087 | E24: =IF(C24<$G$2,$J$2*($G$2+$C$11)^($H$2-$I$2)*(C24+$C$11)^$I$2,$J$2*(C24+$C$11)^$H$2) -> 8.3825028 | F24: =$C$9*(C24)^'Color Targets'!$B$3 -> 11.251646 | G24: =LOG(D24/$C$9)/LOG(C24) -> 2.2562539 | H24: =LOG(E24/100)/LOG(C24) -> 2.371667 | I24: =LOG(F24/$C$9)/LOG(C24) -> 2.3 | K24: =IF(J24=0,"",J24/$J$37) | L24: =IFERROR(LOG(K24)/LOG(C24),"")
C25: 0.40182648 | D25: =$D$2*(C25+$E$2)^$K$2 -> 15.775729 | E25: =IF(C25<$G$2,$J$2*($G$2+$C$11)^($H$2-$I$2)*(C25+$C$11)^$I$2,$J$2*(C25+$C$11)^$H$2) -> 11.347414 | F25: =$C$9*(C25)^'Color Targets'!$B$3 -> 15.296693 | G25: =LOG(D25/$C$9)/LOG(C25) -> 2.2661788 | H25: =LOG(E25/100)/LOG(C25) -> 2.3868563 | I25: =LOG(F25/$C$9)/LOG(C25) -> 2.3 | J25: 15.4681 | K25: =IF(J25=0,"",J25/$J$37) -> 0.12420466 | L25: =IFERROR(LOG(K25)/LOG(C25),"") -> 2.2877534
C26: 0.45205479 | D26: =$D$2*(C26+$E$2)^$K$2 -> 20.469841 | E26: =IF(C26<$G$2,$J$2*($G$2+$C$11)^($H$2-$I$2)*(C26+$C$11)^$I$2,$J$2*(C26+$C$11)^$H$2) -> 14.882858 | F26: =$C$9*(C26)^'Color Targets'!$B$3 -> 20.056186 | G26: =LOG(D26/$C$9)/LOG(C26) -> 2.2742868 | H26: =LOG(E26/100)/LOG(C26) -> 2.3993395 | I26: =LOG(F26/$C$9)/LOG(C26) -> 2.3 | K26: =IF(J26=0,"",J26/$J$37) | L26: =IFERROR(LOG(K26)/LOG(C26),"")
C27: 0.50228311 | D27: =$D$2*(C27+$E$2)^$K$2 -> 25.891363 | E27: =IF(C27<$G$2,$J$2*($G$2+$C$11)^($H$2-$I$2)*(C27+$C$11)^$I$2,$J$2*(C27+$C$11)^$H$2) -> 19.025711 | F27: =$C$9*(C27)^'Color Targets'!$B$3 -> 25.555864 | G27: =LOG(D27/$C$9)/LOG(C27) -> 2.281059 | H27: =LOG(E27/100)/LOG(C27) -> 2.4098167 | I27: =LOG(F27/$C$9)/LOG(C27) -> 2.3 | J27: 26.0908 | K27: =IF(J27=0,"",J27/$J$37) -> 0.20950206 | L27: =IFERROR(LOG(K27)/LOG(C27),"") -> 2.2698828
C28: 0.54794521 | D28: =$D$2*(C28+$E$2)^$K$2 -> 31.475743 | E28: =IF(C28<$G$2,$J$2*($G$2+$C$11)^($H$2-$I$2)*(C28+$C$11)^$I$2,$J$2*(C28+$C$11)^$H$2) -> 23.348877 | F28: =$C$9*(C28)^'Color Targets'!$B$3 -> 31.217942 | G28: =LOG(D28/$C$9)/LOG(C28) -> 2.286329 | H28: =LOG(E28/100)/LOG(C28) -> 2.4180014 | I28: =LOG(F28/$C$9)/LOG(C28) -> 2.3 | K28: =IF(J28=0,"",J28/$J$37) | L28: =IFERROR(LOG(K28)/LOG(C28),"")
C29: 0.59817352 | D29: =$D$2*(C29+$E$2)^$K$2 -> 38.365361 | E29: =IF(C29<$G$2,$J$2*($G$2+$C$11)^($H$2-$I$2)*(C29+$C$11)^$I$2,$J$2*(C29+$C$11)^$H$2) -> 28.748678 | F29: =$C$9*(C29)^'Color Targets'!$B$3 -> 38.195428 | G29: =LOG(D29/$C$9)/LOG(C29) -> 2.2913613 | H29: =LOG(E29/100)/LOG(C29) -> 2.4258425 | I29: =LOG(F29/$C$9)/LOG(C29) -> 2.3 | J29: 38.3606 | K29: =IF(J29=0,"",J29/$J$37) -> 0.30802523 | L29: =IFERROR(LOG(K29)/LOG(C29),"") -> 2.2915591
C30: 0.64840183 | D30: =$D$2*(C30+$E$2)^$K$2 -> 46.062749 | E30: =IF(C30<$G$2,$J$2*($G$2+$C$11)^($H$2-$I$2)*(C30+$C$11)^$I$2,$J$2*(C30+$C$11)^$H$2) -> 34.85561 | F30: =$C$9*(C30)^'Color Targets'!$B$3 -> 45.978054 | G30: =LOG(D30/$C$9)/LOG(C30) -> 2.2957521 | H30: =LOG(E30/100)/LOG(C30) -> 2.4327041 | I30: =LOG(F30/$C$9)/LOG(C30) -> 2.3 | K30: =IF(J30=0,"",J30/$J$37) | L30: =IFERROR(LOG(K30)/LOG(C30),"")
C31: 0.69863014 | D31: =$D$2*(C31+$E$2)^$K$2 -> 54.592916 | E31: =IF(C31<$G$2,$J$2*($G$2+$C$11)^($H$2-$I$2)*(C31+$C$11)^$I$2,$J$2*(C31+$C$11)^$H$2) -> 41.701826 | F31: =$C$9*(C31)^'Color Targets'!$B$3 -> 54.58555 | G31: =LOG(D31/$C$9)/LOG(C31) -> 2.2996237 | H31: =LOG(E31/100)/LOG(C31) -> 2.4387697 | I31: =LOG(F31/$C$9)/LOG(C31) -> 2.3 | J31: 54.8273 | K31: =IF(J31=0,"",J31/$J$37) -> 0.44024838 | L31: =IFERROR(LOG(K31)/LOG(C31),"") -> 2.2876154
C32: 0.74885845 | D32: =$D$2*(C32+$E$2)^$K$2 -> 63.979794 | E32: =IF(C32<$G$2,$J$2*($G$2+$C$11)^($H$2-$I$2)*(C32+$C$11)^$I$2,$J$2*(C32+$C$11)^$H$2) -> 49.318574 | F32: =$C$9*(C32)^'Color Targets'!$B$3 -> 64.036597 | G32: =LOG(D32/$C$9)/LOG(C32) -> 2.3030686 | H32: =LOG(E32/100)/LOG(C32) -> 2.4441786 | I32: =LOG(F32/$C$9)/LOG(C32) -> 2.3 | K32: =IF(J32=0,"",J32/$J$37) | L32: =IFERROR(LOG(K32)/LOG(C32),"")
C33: 0.79908676 | D33: =$D$2*(C33+$E$2)^$K$2 -> 74.246349 | E33: =IF(C33<$G$2,$J$2*($G$2+$C$11)^($H$2-$I$2)*(C33+$C$11)^$I$2,$J$2*(C33+$C$11)^$H$2) -> 57.736277 | F33: =$C$9*(C33)^'Color Targets'!$B$3 -> 74.348962 | G33: =LOG(D33/$C$9)/LOG(C33) -> 2.3061578 | H33: =LOG(E33/100)/LOG(C33) -> 2.4490387 | I33: =LOG(F33/$C$9)/LOG(C33) -> 2.3 | J33: 75.4554 | K33: =IF(J33=0,"",J33/$J$37) -> 0.60588643 | L33: =IFERROR(LOG(K33)/LOG(C33),"") -> 2.2340372
C34: 0.84931507 | D34: =$D$2*(C34+$E$2)^$K$2 -> 85.414682 | E34: =IF(C34<$G$2,$J$2*($G$2+$C$11)^($H$2-$I$2)*(C34+$C$11)^$I$2,$J$2*(C34+$C$11)^$H$2) -> 66.984605 | F34: =$C$9*(C34)^'Color Targets'!$B$3 -> 85.539591 | G34: =LOG(D34/$C$9)/LOG(C34) -> 2.3089473 | H34: =LOG(E34/100)/LOG(C34) -> 2.4534348 | I34: =LOG(F34/$C$9)/LOG(C34) -> 2.3 | K34: =IF(J34=0,"",J34/$J$37) | L34: =IFERROR(LOG(K34)/LOG(C34),"")
C35: 0.89954338 | D35: =$D$2*(C35+$E$2)^$K$2 -> 97.506109 | E35: =IF(C35<$G$2,$J$2*($G$2+$C$11)^($H$2-$I$2)*(C35+$C$11)^$I$2,$J$2*(C35+$C$11)^$H$2) -> 77.092538 | F35: =$C$9*(C35)^'Color Targets'!$B$3 -> 97.624701 | G35: =LOG(D35/$C$9)/LOG(C35) -> 2.3114814 | H35: =LOG(E35/100)/LOG(C35) -> 2.4574346 | I35: =LOG(F35/$C$9)/LOG(C35) -> 2.3 | J35: 97.9357 | K35: =IF(J35=0,"",J35/$J$37) -> 0.78639716 | L35: =IFERROR(LOG(K35)/LOG(C35),"") -> 2.2697446
C36: 0.94977169 | D36: =$D$2*(C36+$E$2)^$K$2 -> 110.54123 | E36: =IF(C36<$G$2,$J$2*($G$2+$C$11)^($H$2-$I$2)*(C36+$C$11)^$I$2,$J$2*(C36+$C$11)^$H$2) -> 88.08842 | F36: =$C$9*(C36)^'Color Targets'!$B$3 -> 110.61985 | G36: =LOG(D36/$C$9)/LOG(C36) -> 2.313796 | H36: =LOG(E36/100)/LOG(C36) -> 2.461093 | I36: =LOG(F36/$C$9)/LOG(C36) -> 2.3 | K36: =IF(J36=0,"",J36/$J$37) | L36: =IFERROR(LOG(K36)/LOG(C36),"")
C37: 1 | D37: =$D$2*(C37+$E$2)^$K$2 -> 124.54 | E37: =IF(C37<$G$2,$J$2*($G$2+$C$11)^($H$2-$I$2)*(C37+$C$11)^$I$2,$J$2*(C37+$C$11)^$H$2) -> 100 | F37: =$C$9*(C37)^'Color Targets'!$B$3 -> 124.54 | J37: 124.5372 | K37: =IF(J37=0,"",J37/$J$37) -> 1 | L37: =AVERAGE(L19:L36) -> 2.2532867 | M37: average
M38: 10-100%
A41: Note: If black levels are < 0.01 cd/m^2 BT.1886 recommends setting Black=0.0 cd/m^2
A42: Peak white of alternate is fixed at 100 cd/m^2 reference
A43: http://www.itu.int/dms_pubrec/itu-r/rec/bt/R-REC-BT.1886-0-201103-I!!PDF-E.pdf
A45: *Stimulus levels 5%-100% use exact GCD encodings

Sheet Calculation
M1: gamma | N1: ='Color Targets'!B3 -> 2.3
B2: =IF('Color Targets'!$AA$2=1,E68,I68) -> BT.709 color matrix
B3: =IF('Color Targets'!$AA$2=1,E69,I69) -> 0.4124564 | C3: =IF('Color Targets'!$AA$2=1,F69,J69) -> 0.3575761 | D3: =IF('Color Targets'!$AA$2=1,G69,K69) -> 0.1804375
B4: =IF('Color Targets'!$AA$2=1,E70,I70) -> 0.2126729 | C4: =IF('Color Targets'!$AA$2=1,F70,J70) -> 0.7151522 | D4: =IF('Color Targets'!$AA$2=1,G70,K70) -> 0.072175
B5: =IF('Color Targets'!$AA$2=1,E71,I71) -> 0.0193339 | C5: =IF('Color Targets'!$AA$2=1,F71,J71) -> 0.119192 | D5: =IF('Color Targets'!$AA$2=1,G71,K71) -> 0.9503041
A6: Companded
A7: Vectors | I7: Normalized | P7: gammafied | W7: XYZ | AD7: xyY
A8: 100/100 | B8: R | C8: G | D8: B | E8: Y | F8: C | G8: M | H8: W | I8: R | J8: G | K8: B | L8: Y | M8: C | N8: M | O8: W | P8: R | Q8: G | R8: B | S8: Y | T8: C | U8: M | V8: W | W8: R | X8: G | Y8: B | Z8: Y | AA8: C | AB8: M | AC8: W | AD8: R | AE8: G | AF8: B | AG8: Y | AH8: C | AI8: M | AJ8: W
A9: R' | B9: 235 | C9: 16 | D9: 16 | E9: 235 | F9: 16 | G9: 235 | H9: 235 | I9: =(B9-16)/219 -> 1 | J9: =(C9-16)/219 -> 0 | K9: =(D9-16)/219 -> 0 | L9: =(E9-16)/219 -> 1 | M9: =(F9-16)/219 -> 0 | N9: =(G9-16)/219 -> 1 | O9: =(H9-16)/219 -> 1 | P9: =I9^$N$1 -> 1 | Q9: =J9^$N$1 -> 0 | R9: =K9^$N$1 -> 0 | S9: =L9^$N$1 -> 1 | T9: =M9^$N$1 -> 0 | U9: =N9^$N$1 -> 1 | V9: =O9^$N$1 -> 1 | W9: {=MMULT($B$3:$D$5,P9:P11)} -> 0.4124564 | X9: {=MMULT($B$3:$D$5,Q9:Q11)} -> 0.3575761 | Y9: {=MMULT($B$3:$D$5,R9:R11)} -> 0.1804375 | Z9: {=MMULT($B$3:$D$5,S9:S11)} -> 0.7700325 | AA9: {=MMULT($B$3:$D$5,T9:T11)} -> 0.5380136 | AB9: {=MMULT($B$3:$D$5,U9:U11)} -> 0.5928939 | AC9: {=MMULT($B$3:$D$5,V9:V11)} -> 0.95047 | AD9: =W9/(W9+W10+W11) -> 0.63999993 | AE9: =X9/(X9+X10+X11) -> 0.30000001 | AF9: =Y9/(Y9+Y10+Y11) -> 0.15000001 | AG9: =Z9/(Z9+Z10+Z11) -> 0.41932009 | AH9: =AA9/(AA9+AA10+AA11) -> 0.22465563 | AI9: =AB9/(AB9+AB10+AB11) -> 0.32093774 | AJ9: =AC9/(AC9+AC10+AC11) -> 0.3127266
A10: G' | B10: 16 | C10: 235 | D10: 16 | E10: 235 | F10: 235 | G10: 16 | H10: 235 | I10: =(B10-16)/219 -> 0 | J10: =(C10-16)/219 -> 1 | K10: =(D10-16)/219 -> 0 | L10: =(E10-16)/219 -> 1 | M10: =(F10-16)/219 -> 1 | N10: =(G10-16)/219 -> 0 | O10: =(H10-16)/219 -> 1 | P10: =I10^$N$1 -> 0 | Q10: =J10^$N$1 -> 1 | R10: =K10^$N$1 -> 0 | S10: =L10^$N$1 -> 1 | T10: =M10^$N$1 -> 1 | U10: =N10^$N$1 -> 0 | V10: =O10^$N$1 -> 1 | W10: 0.2126729 | X10: 0.7151522 | Y10: 0.072175 | Z10: 0.9278251 | AA10: 0.7873272 | AB10: 0.2848479 | AC10: 1.0000001 | AD10: =W10/(W9+W10+W11) -> 0.33000007 | AE10: =X10/(X9+X10+X11) -> 0.60000002 | AF10: =Y10/(Y9+Y10+Y11) -> 0.060000003 | AG10: =Z10/(Z9+Z10+Z11) -> 0.50524583 | AH10: =AA10/(AA9+AA10+AA11) -> 0.32876026 | AI10: =AB10/(AB9+AB10+AB11) -> 0.15419022 | AJ10: =AC10/(AC9+AC10+AC11) -> 0.32902315
A11: B' | B11: 16 | C11: 16 | D11: 235 | E11: 16 | F11: 235 | G11: 235 | H11: 235 | I11: =(B11-16)/219 -> 0 | J11: =(C11-16)/219 -> 0 | K11: =(D11-16)/219 -> 1 | L11: =(E11-16)/219 -> 0 | M11: =(F11-16)/219 -> 1 | N11: =(G11-16)/219 -> 1 | O11: =(H11-16)/219 -> 1 | P11: =I11^$N$1 -> 0 | Q11: =J11^$N$1 -> 0 | R11: =K11^$N$1 -> 1 | S11: =L11^$N$1 -> 0 | T11: =M11^$N$1 -> 1 | U11: =N11^$N$1 -> 1 | V11: =O11^$N$1 -> 1 | W11: 0.0193339 | X11: 0.119192 | Y11: 0.9503041 | Z11: 0.1385259 | AA11: 1.0694961 | AB11: 0.969638 | AC11: 1.08883 | AD11: =W10 -> 0.2126729 | AE11: =X10 -> 0.7151522 | AF11: =Y10 -> 0.072175 | AG11: =Z10 -> 0.9278251 | AH11: =AA10 -> 0.7873272 | AI11: =AB10 -> 0.2848479 | AJ11: =AC10 -> 1.0000001
A13: 100/75
A14: R' | B14: 215 | C14: 97 | D14: 71 | E14: 233 | F14: 121 | G14: 202 | H14: 235 | I14: =(B14-16)/219 -> 0.9086758 | J14: =(C14-16)/219 -> 0.36986301 | K14: =(D14-16)/219 -> 0.25114155 | L14: =(E14-16)/219 -> 0.99086758 | M14: =(F14-16)/219 -> 0.47945205 | N14: =(G14-16)/219 -> 0.84931507 | O14: =(H14-16)/219 -> 1 | P14: =I14^IF('Color Targets'!$AA$1=1,$N$1,INDEX(Calculation!$G$263:$G$372,MATCH(I14,Calculation!$H$263:$H$372))) -> 0.8047326 | Q14: =J14^IF('Color Targets'!$AA$1=1,$N$1,INDEX(Calculation!$G$263:$G$372,MATCH(J14,Calculation!$H$263:$H$372))) -> 0.10256449 | R14: =K14^IF('Color Targets'!$AA$1=1,$N$1,INDEX(Calculation!$G$263:$G$372,MATCH(K14,Calculation!$H$263:$H$372))) -> 0.04498709 | S14: =L14^IF('Color Targets'!$AA$1=1,$N$1,INDEX(Calculation!$G$263:$G$372,MATCH(L14,Calculation!$H$263:$H$372))) -> 0.97940319 | T14: =M14^IF('Color Targets'!$AA$1=1,$N$1,INDEX(Calculation!$G$263:$G$372,MATCH(M14,Calculation!$H$263:$H$372))) -> 0.18765307 | U14: =N14^IF('Color Targets'!$AA$1=1,$N$1,INDEX(Calculation!$G$263:$G$372,MATCH(N14,Calculation!$H$263:$H$372))) -> 0.69239978 | V14: =O14^$N$1 -> 1 | W14: {=MMULT($B$3:$D$5,P14:P16)} -> 0.35952096 | X14: {=MMULT($B$3:$D$5,Q14:Q16)} -> 0.40374171 | Y14: {=MMULT($B$3:$D$5,R14:R16)} -> 0.10484324 | Z14: {=MMULT($B$3:$D$5,S14:S16)} -> 0.78164182 | AA14: {=MMULT($B$3:$D$5,T14:T16)} -> 0.59337838 | AB14: {=MMULT($B$3:$D$5,U14:U16)} -> 0.44930062 | AC14: {=MMULT($B$3:$D$5,V14:V16)} -> 0.95047 | AD14: =W14/(W14+W15+W16) -> 0.56044462 | AE14: =X14/(X14+X15+X16) -> 0.30297708 | AF14: =Y14/(Y14+Y15+Y16) -> 0.19040771 | AG14: =Z14/(Z14+Z15+Z16) -> 0.39443192 | AH14: =AA14/(AA14+AA15+AA16) -> 0.24543158 | AI14: =AB14/(AB14+AB15+AB16) -> 0.31901596 | AJ14: =AC14/(AC14+AC15+AC16) -> 0.3127266
A15: G' | B15: 75 | C15: 231 | D15: 71 | E15: 233 | F15: 231 | G15: 99 | H15: 235 | I15: =(B15-16)/219 -> 0.26940639 | J15: =(C15-16)/219 -> 0.98173516 | K15: =(D15-16)/219 -> 0.25114155 | L15: =(E15-16)/219 -> 0.99086758 | M15: =(F15-16)/219 -> 0.98173516 | N15: =(G15-16)/219 -> 0.37899543 | O15: =(H15-16)/219 -> 1 | P15: =I15^IF('Color Targets'!$AA$1=1,$N$1,INDEX(Calculation!$G$263:$G$372,MATCH(I15,Calculation!$H$263:$H$372))) -> 0.05130698 | Q15: =J15^IF('Color Targets'!$AA$1=1,$N$1,INDEX(Calculation!$G$263:$G$372,MATCH(J15,Calculation!$H$263:$H$372))) -> 0.95904578 | R15: =K15^IF('Color Targets'!$AA$1=1,$N$1,INDEX(Calculation!$G$263:$G$372,MATCH(K15,Calculation!$H$263:$H$372))) -> 0.04498709 | S15: =L15^IF('Color Targets'!$AA$1=1,$N$1,INDEX(Calculation!$G$263:$G$372,MATCH(L15,Calculation!$H$263:$H$372))) -> 0.97940319 | T15: =M15^IF('Color Targets'!$AA$1=1,$N$1,INDEX(Calculation!$G$263:$G$372,MATCH(M15,Calculation!$H$263:$H$372))) -> 0.95904578 | U15: =N15^IF('Color Targets'!$AA$1=1,$N$1,INDEX(Calculation!$G$263:$G$372,MATCH(N15,Calculation!$H$263:$H$372))) -> 0.10845527 | V15: =O15^$N$1 -> 1 | W15: 0.2115402 | X15: 0.71507898 | Y15: 0.069820838 | Z15: 0.91970268 | AA15: 0.79499155 | AB15: 0.27479065 | AC15: 1.0000001 | AD15: =W15/(W14+W15+W16) -> 0.32976259 | AE15: =X15/(X14+X15+X16) -> 0.53661173 | AF15: =Y15/(Y14+Y15+Y16) -> 0.12680289 | AG15: =Z15/(Z14+Z15+Z16) -> 0.46410016 | AH15: =AA15/(AA14+AA15+AA16) -> 0.32882228 | AI15: =AB15/(AB14+AB15+AB16) -> 0.19510902 | AJ15: =AC15/(AC14+AC15+AC16) -> 0.32902315
A16: B' | B16: 75 | C16: 97 | D16: 161 | E16: 112 | F16: 231 | G16: 202 | H16: 235 | I16: =(B16-16)/219 -> 0.26940639 | J16: =(C16-16)/219 -> 0.36986301 | K16: =(D16-16)/219 -> 0.66210046 | L16: =(E16-16)/219 -> 0.43835616 | M16: =(F16-16)/219 -> 0.98173516 | N16: =(G16-16)/219 -> 0.84931507 | O16: =(H16-16)/219 -> 1 | P16: =I16^IF('Color Targets'!$AA$1=1,$N$1,INDEX(Calculation!$G$263:$G$372,MATCH(I16,Calculation!$H$263:$H$372))) -> 0.05130698 | Q16: =J16^IF('Color Targets'!$AA$1=1,$N$1,INDEX(Calculation!$G$263:$G$372,MATCH(J16,Calculation!$H$263:$H$372))) -> 0.10256449 | R16: =K16^IF('Color Targets'!$AA$1=1,$N$1,INDEX(Calculation!$G$263:$G$372,MATCH(K16,Calculation!$H$263:$H$372))) -> 0.3890639 | S16: =L16^IF('Color Targets'!$AA$1=1,$N$1,INDEX(Calculation!$G$263:$G$372,MATCH(L16,Calculation!$H$263:$H$372))) -> 0.15223849 | T16: =M16^IF('Color Targets'!$AA$1=1,$N$1,INDEX(Calculation!$G$263:$G$372,MATCH(M16,Calculation!$H$263:$H$372))) -> 0.95904578 | U16: =N16^IF('Color Targets'!$AA$1=1,$N$1,INDEX(Calculation!$G$263:$G$372,MATCH(N16,Calculation!$H$263:$H$372))) -> 0.69239978 | V16: =O16^$N$1 -> 1 | W16: 0.070431235 | X16: 0.21376101 | Y16: 0.37596089 | Z16: 0.28034557 | AA16: 1.0293238 | AB16: 0.68430414 | AC16: 1.08883 | AD16: =W15 -> 0.2115402 | AE16: =X15 -> 0.71507898 | AF16: =Y15 -> 0.069820838 | AG16: =Z15 -> 0.91970268 | AH16: =AA15 -> 0.79499155 | AI16: =AB15 -> 0.27479065 | AJ16: =AC15 -> 1.0000001
A18: 100/50
A19: R' | B19: 191 | C19: 134 | D19: 77 | E19: 233 | F19: 161 | G19: 178 | H19: 235 | I19: =(B19-16)/219 -> 0.79908676 | J19: =(C19-16)/219 -> 0.53881279 | K19: =(D19-16)/219 -> 0.27853881 | L19: =(E19-16)/219 -> 0.99086758 | M19: =(F19-16)/219 -> 0.66210046 | N19: =(G19-16)/219 -> 0.73972603 | O19: =(H19-16)/219 -> 1 | P19: =I19^IF('Color Targets'!$AA$1=1,$N$1,INDEX(Calculation!$G$263:$G$372,MATCH(I19,Calculation!$H$263:$H$372))) -> 0.60562774 | Q19: =J19^IF('Color Targets'!$AA$1=1,$N$1,INDEX(Calculation!$G$263:$G$372,MATCH(J19,Calculation!$H$263:$H$372))) -> 0.24467718 | R19: =K19^IF('Color Targets'!$AA$1=1,$N$1,INDEX(Calculation!$G$263:$G$372,MATCH(K19,Calculation!$H$263:$H$372))) -> 0.055330046 | S19: =L19^IF('Color Targets'!$AA$1=1,$N$1,INDEX(Calculation!$G$263:$G$372,MATCH(L19,Calculation!$H$263:$H$372))) -> 0.97940319 | T19: =M19^IF('Color Targets'!$AA$1=1,$N$1,INDEX(Calculation!$G$263:$G$372,MATCH(M19,Calculation!$H$263:$H$372))) -> 0.3890639 | U19: =N19^IF('Color Targets'!$AA$1=1,$N$1,INDEX(Calculation!$G$263:$G$372,MATCH(N19,Calculation!$H$263:$H$372))) -> 0.50467887 | V19: =O19^$N$1 -> 1 | W19: {=MMULT($B$3:$D$5,P19:P21)} -> 0.30186615 | X19: {=MMULT($B$3:$D$5,Q19:Q21)} -> 0.46319286 | Y19: {=MMULT($B$3:$D$5,R19:R21)} -> 0.080356177 | Z19: {=MMULT($B$3:$D$5,S19:S21)} -> 0.81892878 | AA19: {=MMULT($B$3:$D$5,T19:T21)} -> 0.63912725 | AB19: {=MMULT($B$3:$D$5,U19:U21)} -> 0.36632128 | AC19: {=MMULT($B$3:$D$5,V19:V21)} -> 0.95047 | AD19: =W19/(W19+W20+W21) -> 0.48524771 | AE19: =X19/(X19+X20+X21) -> 0.30625756 | AF19: =Y19/(Y19+Y20+Y21) -> 0.2274604 | AG19: =Z19/(Z19+Z20+Z21) -> 0.36718822 | AH19: =AA19/(AA19+AA20+AA21) -> 0.26838801 | AI19: =AB19/(AB19+AB20+AB21) -> 0.31688663 | AJ19: =AC19/(AC19+AC20+AC21) -> 0.3127266
A20: G' | B20: 95 | C20: 224 | D20: 77 | E20: 233 | F20: 224 | G20: 121 | H20: 235 | I20: =(B20-16)/219 -> 0.36073059 | J20: =(C20-16)/219 -> 0.94977169 | K20: =(D20-16)/219 -> 0.27853881 | L20: =(E20-16)/219 -> 0.99086758 | M20: =(F20-16)/219 -> 0.94977169 | N20: =(G20-16)/219 -> 0.47945205 | O20: =(H20-16)/219 -> 1 | P20: =I20^IF('Color Targets'!$AA$1=1,$N$1,INDEX(Calculation!$G$263:$G$372,MATCH(I20,Calculation!$H$263:$H$372))) -> 0.096784013 | Q20: =J20^IF('Color Targets'!$AA$1=1,$N$1,INDEX(Calculation!$G$263:$G$372,MATCH(J20,Calculation!$H$263:$H$372))) -> 0.88967148 | R20: =K20^IF('Color Targets'!$AA$1=1,$N$1,INDEX(Calculation!$G$263:$G$372,MATCH(K20,Calculation!$H$263:$H$372))) -> 0.055330046 | S20: =L20^IF('Color Targets'!$AA$1=1,$N$1,INDEX(Calculation!$G$263:$G$372,MATCH(L20,Calculation!$H$263:$H$372))) -> 0.97940319 | T20: =M20^IF('Color Targets'!$AA$1=1,$N$1,INDEX(Calculation!$G$263:$G$372,MATCH(M20,Calculation!$H$263:$H$372))) -> 0.88967148 | U20: =N20^IF('Color Targets'!$AA$1=1,$N$1,INDEX(Calculation!$G$263:$G$372,MATCH(N20,Calculation!$H$263:$H$372))) -> 0.18765307 | V20: =O20^$N$1 -> 1 | W20: 0.20500129 | X20: 0.70594629 | Y20: 0.066436703 | Z20: 0.93461746 | AA20: 0.7832059 | AB20: 0.27795722 | AC20: 1.0000001 | AD20: =W20/(W19+W20+W21) -> 0.32953813 | AE20: =X20/(X19+X20+X21) -> 0.46676321 | AF20: =Y20/(Y19+Y20+Y21) -> 0.18805921 | AG20: =Z20/(Z19+Z20+Z21) -> 0.41906027 | AH20: =AA20/(AA19+AA20+AA21) -> 0.3288908 | AI20: =AB20/(AB19+AB20+AB21) -> 0.24044721 | AJ20: =AC20/(AC19+AC20+AC21) -> 0.32902315
A21: B' | B21: 95 | C21: 134 | D21: 126 | E21: 156 | F21: 224 | G21: 178 | H21: 235 | I21: =(B21-16)/219 -> 0.36073059 | J21: =(C21-16)/219 -> 0.53881279 | K21: =(D21-16)/219 -> 0.50228311 | L21: =(E21-16)/219 -> 0.63926941 | M21: =(F21-16)/219 -> 0.94977169 | N21: =(G21-16)/219 -> 0.73972603 | O21: =(H21-16)/219 -> 1 | P21: =I21^IF('Color Targets'!$AA$1=1,$N$1,INDEX(Calculation!$G$263:$G$372,MATCH(I21,Calculation!$H$263:$H$372))) -> 0.096784013 | Q21: =J21^IF('Color Targets'!$AA$1=1,$N$1,INDEX(Calculation!$G$263:$G$372,MATCH(J21,Calculation!$H$263:$H$372))) -> 0.24467718 | R21: =K21^IF('Color Targets'!$AA$1=1,$N$1,INDEX(Calculation!$G$263:$G$372,MATCH(K21,Calculation!$H$263:$H$372))) -> 0.20921507 | S21: =L21^IF('Color Targets'!$AA$1=1,$N$1,INDEX(Calculation!$G$263:$G$372,MATCH(L21,Calculation!$H$263:$H$372))) -> 0.35888598 | T21: =M21^IF('Color Targets'!$AA$1=1,$N$1,INDEX(Calculation!$G$263:$G$372,MATCH(M21,Calculation!$H$263:$H$372))) -> 0.88967148 | U21: =N21^IF('Color Targets'!$AA$1=1,$N$1,INDEX(Calculation!$G$263:$G$372,MATCH(N21,Calculation!$H$263:$H$372))) -> 0.50467887 | V21: =O21^$N$1 -> 1 | W21: 0.11521927 | X21: 0.34329001 | Y21: 0.20648258 | Z21: 0.47672353 | AA21: 0.9590223 | AB21: 0.51172255 | AC21: 1.08883 | AD21: =W20 -> 0.20500129 | AE21: =X20 -> 0.70594629 | AF21: =Y20 -> 0.066436703 | AG21: =Z20 -> 0.93461746 | AH21: =AA20 -> 0.7832059 | AI21: =AB20 -> 0.27795722 | AJ21: =AC20 -> 1.0000001
A23: 75/100
A24: R' | B24: 180 | C24: 16 | D24: 16 | E24: 180 | F24: 16 | G24: 180 | H24: 180 | I24: =(B24-16)/219 -> 0.74885845 | J24: =(C24-16)/219 -> 0 | K24: =(D24-16)/219 -> 0 | L24: =(E24-16)/219 -> 0.74885845 | M24: =(F24-16)/219 -> 0 | N24: =(G24-16)/219 -> 0.74885845 | O24: =(H24-16)/219 -> 0.74885845 | P24: =I24^IF('Color Targets'!$AA$1=1,$N$1,INDEX(Calculation!$G$263:$G$372,MATCH(I24,Calculation!$H$263:$H$372))) -> 0.5194081 | Q24: =J24^$N$1 -> 0 | R24: =K24^$N$1 -> 0 | S24: =L24^IF('Color Targets'!$AA$1=1,$N$1,INDEX(Calculation!$G$263:$G$372,MATCH(L24,Calculation!$H$263:$H$372))) -> 0.5194081 | T24: =M24^$N$1 -> 0 | U24: =N24^IF('Color Targets'!$AA$1=1,$N$1,INDEX(Calculation!$G$263:$G$372,MATCH(N24,Calculation!$H$263:$H$372))) -> 0.5194081 | V24: =O24^IF('Color Targets'!$AA$1=1,$N$1,INDEX(Calculation!$G$263:$G$372,MATCH(O24,Calculation!$H$263:$H$372))) -> 0.5194081 | W24: {=MMULT($B$3:$D$5,P24:P26)} -> 0.2142332 | X24: {=MMULT($B$3:$D$5,Q24:Q26)} -> 0.18572792 | Y24: {=MMULT($B$3:$D$5,R24:R26)} -> 0.0937207 | Z24: {=MMULT($B$3:$D$5,S24:S26)} -> 0.39996112 | AA24: {=MMULT($B$3:$D$5,T24:T26)} -> 0.27944862 | AB24: {=MMULT($B$3:$D$5,U24:U26)} -> 0.3079539 | AC24: {=MMULT($B$3:$D$5,V24:V26)} -> 0.49368182 | AD24: =W24/(W24+W25+W26) -> 0.63999993 | AE24: =X24/(X24+X25+X26) -> 0.30000001 | AF24: =Y24/(Y24+Y25+Y26) -> 0.15000001 | AG24: =Z24/(Z24+Z25+Z26) -> 0.41932009 | AH24: =AA24/(AA24+AA25+AA26) -> 0.22465563 | AI24: =AB24/(AB24+AB25+AB26) -> 0.32093774 | AJ24: =AC24/(AC24+AC25+AC26) -> 0.3127266
A25: G' | B25: 16 | C25: 180 | D25: 16 | E25: 180 | F25: 180 | G25: 16 | H25: 180 | I25: =(B25-16)/219 -> 0 | J25: =(C25-16)/219 -> 0.74885845 | K25: =(D25-16)/219 -> 0 | L25: =(E25-16)/219 -> 0.74885845 | M25: =(F25-16)/219 -> 0.74885845 | N25: =(G25-16)/219 -> 0 | O25: =(H25-16)/219 -> 0.74885845 | P25: =I25^$N$1 -> 0 | Q25: =J25^IF('Color Targets'!$AA$1=1,$N$1,INDEX(Calculation!$G$263:$G$372,MATCH(J25,Calculation!$H$263:$H$372))) -> 0.5194081 | R25: =K25^$N$1 -> 0 | S25: =L25^IF('Color Targets'!$AA$1=1,$N$1,INDEX(Calculation!$G$263:$G$372,MATCH(L25,Calculation!$H$263:$H$372))) -> 0.5194081 | T25: =M25^IF('Color Targets'!$AA$1=1,$N$1,INDEX(Calculation!$G$263:$G$372,MATCH(M25,Calculation!$H$263:$H$372))) -> 0.5194081 | U25: =N25^$N$1 -> 0 | V25: =O25^IF('Color Targets'!$AA$1=1,$N$1,INDEX(Calculation!$G$263:$G$372,MATCH(O25,Calculation!$H$263:$H$372))) -> 0.5194081 | W25: 0.11046403 | X25: 0.37145585 | Y25: 0.03748828 | Z25: 0.48191988 | AA25: 0.40894413 | AB25: 0.14795231 | AC25: 0.51940816 | AD25: =W25/(W24+W25+W26) -> 0.33000007 | AE25: =X25/(X24+X25+X26) -> 0.60000002 | AF25: =Y25/(Y24+Y25+Y26) -> 0.060000003 | AG25: =Z25/(Z24+Z25+Z26) -> 0.50524583 | AH25: =AA25/(AA24+AA25+AA26) -> 0.32876026 | AI25: =AB25/(AB24+AB25+AB26) -> 0.15419022 | AJ25: =AC25/(AC24+AC25+AC26) -> 0.32902315
A26: B' | B26: 16 | C26: 16 | D26: 180 | E26: 16 | F26: 180 | G26: 180 | H26: 180 | I26: =(B26-16)/219 -> 0 | J26: =(C26-16)/219 -> 0 | K26: =(D26-16)/219 -> 0.74885845 | L26: =(E26-16)/219 -> 0 | M26: =(F26-16)/219 -> 0.74885845 | N26: =(G26-16)/219 -> 0.74885845 | O26: =(H26-16)/219 -> 0.74885845 | P26: =I26^$N$1 -> 0 | Q26: =J26^$N$1 -> 0 | R26: =K26^IF('Color Targets'!$AA$1=1,$N$1,INDEX(Calculation!$G$263:$G$372,MATCH(K26,Calculation!$H$263:$H$372))) -> 0.5194081 | S26: =L26^$N$1 -> 0 | T26: =M26^IF('Color Targets'!$AA$1=1,$N$1,INDEX(Calculation!$G$263:$G$372,MATCH(M26,Calculation!$H$263:$H$372))) -> 0.5194081 | U26: =N26^IF('Color Targets'!$AA$1=1,$N$1,INDEX(Calculation!$G$263:$G$372,MATCH(N26,Calculation!$H$263:$H$372))) -> 0.5194081 | V26: =O26^IF('Color Targets'!$AA$1=1,$N$1,INDEX(Calculation!$G$263:$G$372,MATCH(O26,Calculation!$H$263:$H$372))) -> 0.5194081 | W26: 0.010042184 | X26: 0.061909291 | Y26: 0.49359565 | Z26: 0.071951475 | AA26: 0.55550494 | AB26: 0.50363784 | AC26: 0.56554713 | AD26: =W25 -> 0.11046403 | AE26: =X25 -> 0.37145585 | AF26: =Y25 -> 0.03748828 | AG26: =Z25 -> 0.48191988 | AH26: =AA25 -> 0.40894413 | AI26: =AB25 -> 0.14795231 | AJ26: =AC25 -> 0.51940816
A28: 75/75
A29: R' | B29: 165 | C29: 77 | D29: 58 | E29: 180 | F29: 95 | G29: 156 | H29: 180 | I29: =(B29-16)/219 -> 0.6803653 | J29: =(C29-16)/219 -> 0.27853881 | K29: =(D29-16)/219 -> 0.19178082 | L29: =(E29-16)/219 -> 0.74885845 | M29: =(F29-16)/219 -> 0.36073059 | N29: =(G29-16)/219 -> 0.63926941 | O29: =(H29-16)/219 -> 0.74885845 | P29: =I29^IF('Color Targets'!$AA$1=1,$N$1,INDEX(Calculation!$G$263:$G$372,MATCH(I29,Calculation!$H$263:$H$372))) -> 0.41421658 | Q29: =J29^IF('Color Targets'!$AA$1=1,$N$1,INDEX(Calculation!$G$263:$G$372,MATCH(J29,Calculation!$H$263:$H$372))) -> 0.055330046 | R29: =K29^IF('Color Targets'!$AA$1=1,$N$1,INDEX(Calculation!$G$263:$G$372,MATCH(K29,Calculation!$H$263:$H$372))) -> 0.026174108 | S29: =L29^IF('Color Targets'!$AA$1=1,$N$1,INDEX(Calculation!$G$263:$G$372,MATCH(L29,Calculation!$H$263:$H$372))) -> 0.5194081 | T29: =M29^IF('Color Targets'!$AA$1=1,$N$1,INDEX(Calculation!$G$263:$G$372,MATCH(M29,Calculation!$H$263:$H$372))) -> 0.096784013 | U29: =N29^IF('Color Targets'!$AA$1=1,$N$1,INDEX(Calculation!$G$263:$G$372,MATCH(N29,Calculation!$H$263:$H$372))) -> 0.35888598 | V29: =O29^IF('Color Targets'!$AA$1=1,$N$1,INDEX(Calculation!$G$274:$G$372,MATCH(O29,Calculation!$A$274:$A$372))) -> 0.52008248 | W29: {=MMULT($B$3:$D$5,P29:P31)} -> 0.1864502 | X29: {=MMULT($B$3:$D$5,Q29:Q31)} -> 0.20807387 | Y29: {=MMULT($B$3:$D$5,R29:R31)} -> 0.057905158 | Z29: {=MMULT($B$3:$D$5,S29:S31)} -> 0.41405775 | AA29: {=MMULT($B$3:$D$5,T29:T31)} -> 0.30363121 | AB29: {=MMULT($B$3:$D$5,U29:U31)} -> 0.23430424 | AC29: {=MMULT($B$3:$D$5,V29:V31)} -> 0.4943228 | AD29: =W29/(W29+W30+W31) -> 0.55424423 | AE29: =X29/(X29+X30+X31) -> 0.30311775 | AF29: =Y29/(Y29+Y30+Y31) -> 0.1931885 | AG29: =Z29/(Z29+Z30+Z31) -> 0.39516492 | AH29: =AA29/(AA29+AA30+AA31) -> 0.24561185 | AI29: =AB29/(AB29+AB30+AB31) -> 0.3188933 | AJ29: =AC29/(AC29+AC30+AC31) -> 0.3127266
A30: G' | B30: 60 | C30: 176 | D30: 58 | E30: 180 | F30: 176 | G30: 80 | H30: 180 | I30: =(B30-16)/219 -> 0.20091324 | J30: =(C30-16)/219 -> 0.73059361 | K30: =(D30-16)/219 -> 0.19178082 | L30: =(E30-16)/219 -> 0.74885845 | M30: =(F30-16)/219 -> 0.73059361 | N30: =(G30-16)/219 -> 0.29223744 | O30: =(H30-16)/219 -> 0.74885845 | P30: =I30^IF('Color Targets'!$AA$1=1,$N$1,INDEX(Calculation!$G$263:$G$372,MATCH(I30,Calculation!$H$263:$H$372))) -> 0.029002836 | Q30: =J30^IF('Color Targets'!$AA$1=1,$N$1,INDEX(Calculation!$G$263:$G$372,MATCH(J30,Calculation!$H$263:$H$372))) -> 0.49015865 | R30: =K30^IF('Color Targets'!$AA$1=1,$N$1,INDEX(Calculation!$G$263:$G$372,MATCH(K30,Calculation!$H$263:$H$372))) -> 0.026174108 | S30: =L30^IF('Color Targets'!$AA$1=1,$N$1,INDEX(Calculation!$G$263:$G$372,MATCH(L30,Calculation!$H$263:$H$372))) -> 0.5194081 | T30: =M30^IF('Color Targets'!$AA$1=1,$N$1,INDEX(Calculation!$G$263:$G$372,MATCH(M30,Calculation!$H$263:$H$372))) -> 0.49015865 | U30: =N30^IF('Color Targets'!$AA$1=1,$N$1,INDEX(Calculation!$G$263:$G$372,MATCH(N30,Calculation!$H$263:$H$372))) -> 0.060191203 | V30: =O30^IF('Color Targets'!$AA$1=1,$N$1,INDEX(Calculation!$G$274:$G$372,MATCH(O30,Calculation!$A$274:$A$372))) -> 0.52008248 | W30: 0.11092736 | X30: 0.36629869 | Y30: 0.039385092 | Z30: 0.48755853 | AA30: 0.40649858 | AB30: 0.14527379 | AC30: 0.52008254 | AD30: =W30/(W29+W30+W31) -> 0.32974409 | AE30: =X30/(X29+X30+X31) -> 0.53361644 | AF30: =Y30/(Y29+Y30+Y31) -> 0.13140016 | AG30: =Z30/(Z29+Z30+Z31) -> 0.46531197 | AH30: =AA30/(AA29+AA30+AA31) -> 0.32882281 | AI30: =AB30/(AB29+AB30+AB31) -> 0.19772086 | AJ30: =AC30/(AC29+AC30+AC31) -> 0.32902315
A31: B' | B31: 60 | C31: 77 | D31: 126 | E31: 88 | F31: 176 | G31: 156 | H31: 180 | I31: =(B31-16)/219 -> 0.20091324 | J31: =(C31-16)/219 -> 0.27853881 | K31: =(D31-16)/219 -> 0.50228311 | L31: =(E31-16)/219 -> 0.32876712 | M31: =(F31-16)/219 -> 0.73059361 | N31: =(G31-16)/219 -> 0.63926941 | O31: =(H31-16)/219 -> 0.74885845 | P31: =I31^IF('Color Targets'!$AA$1=1,$N$1,INDEX(Calculation!$G$263:$G$372,MATCH(I31,Calculation!$H$263:$H$372))) -> 0.029002836 | Q31: =J31^IF('Color Targets'!$AA$1=1,$N$1,INDEX(Calculation!$G$263:$G$372,MATCH(J31,Calculation!$H$263:$H$372))) -> 0.055330046 | R31: =K31^IF('Color Targets'!$AA$1=1,$N$1,INDEX(Calculation!$G$263:$G$372,MATCH(K31,Calculation!$H$263:$H$372))) -> 0.20921507 | S31: =L31^IF('Color Targets'!$AA$1=1,$N$1,INDEX(Calculation!$G$263:$G$372,MATCH(L31,Calculation!$H$263:$H$372))) -> 0.078124706 | T31: =M31^IF('Color Targets'!$AA$1=1,$N$1,INDEX(Calculation!$G$263:$G$372,MATCH(M31,Calculation!$H$263:$H$372))) -> 0.49015865 | U31: =N31^IF('Color Targets'!$AA$1=1,$N$1,INDEX(Calculation!$G$263:$G$372,MATCH(N31,Calculation!$H$263:$H$372))) -> 0.35888598 | V31: =O31^IF('Color Targets'!$AA$1=1,$N$1,INDEX(Calculation!$G$274:$G$372,MATCH(O31,Calculation!$A$274:$A$372))) -> 0.52008248 | W31: 0.039026841 | X31: 0.11207311 | Y31: 0.20244373 | Z31: 0.1461937 | AA31: 0.52609398 | AB31: 0.35516379 | AC31: 0.56628141 | AD31: =W30 -> 0.11092736 | AE31: =X30 -> 0.36629869 | AF31: =Y30 -> 0.039385092 | AG31: =Z30 -> 0.48755853 | AH31: =AA30 -> 0.40649858 | AI31: =AB30 -> 0.14527379 | AJ31: =AC30 -> 0.52008254
A33: 75/50
A34: R' | B34: 147 | C34: 104 | D34: 62 | E34: 178 | F34: 123 | G34: 139 | H34: 180 | I34: =(B34-16)/219 -> 0.59817352 | J34: =(C34-16)/219 -> 0.40182648 | K34: =(D34-16)/219 -> 0.21004566 | L34: =(E34-16)/219 -> 0.73972603 | M34: =(F34-16)/219 -> 0.48858447 | N34: =(G34-16)/219 -> 0.56164384 | O34: =(H34-16)/219 -> 0.74885845 | P34: =I34^IF('Color Targets'!$AA$1=1,$N$1,INDEX(Calculation!$G$263:$G$372,MATCH(I34,Calculation!$H$263:$H$372))) -> 0.30830484 | Q34: =J34^IF('Color Targets'!$AA$1=1,$N$1,INDEX(Calculation!$G$263:$G$372,MATCH(J34,Calculation!$H$263:$H$372))) -> 0.12416882 | R34: =K34^IF('Color Targets'!$AA$1=1,$N$1,INDEX(Calculation!$G$263:$G$372,MATCH(K34,Calculation!$H$263:$H$372))) -> 0.031074165 | S34: =L34^IF('Color Targets'!$AA$1=1,$N$1,INDEX(Calculation!$G$263:$G$372,MATCH(L34,Calculation!$H$263:$H$372))) -> 0.50467887 | T34: =M34^IF('Color Targets'!$AA$1=1,$N$1,INDEX(Calculation!$G$263:$G$372,MATCH(M34,Calculation!$H$263:$H$372))) -> 0.19618172 | U34: =N34^IF('Color Targets'!$AA$1=1,$N$1,INDEX(Calculation!$G$263:$G$372,MATCH(N34,Calculation!$H$263:$H$372))) -> 0.26823923 | V34: =O34^IF('Color Targets'!$AA$1=1,$N$1,INDEX(Calculation!$G$274:$G$372,MATCH(O34,Calculation!$A$274:$A$372))) -> 0.52008248 | W34: {=MMULT($B$3:$D$5,P34:P36)} -> 0.15476616 | X34: {=MMULT($B$3:$D$5,Q34:Q36)} -> 0.23596528 | Y34: {=MMULT($B$3:$D$5,R34:R36)} -> 0.043497515 | Z34: {=MMULT($B$3:$D$5,S34:S36)} -> 0.42247878 | AA34: {=MMULT($B$3:$D$5,T34:T36)} -> 0.3251848 | AB34: {=MMULT($B$3:$D$5,U34:U36)} -> 0.19364505 | AC34: {=MMULT($B$3:$D$5,V34:V36)} -> 0.4943228 | AD34: =W34/(W34+W35+W36) -> 0.48129346 | AE34: =X34/(X34+X35+X36) -> 0.30623308 | AF34: =Y34/(Y34+Y35+Y36) -> 0.23195368 | AG34: =Z34/(Z34+Z35+Z36) -> 0.3665712 | AH34: =AA34/(AA34+AA35+AA36) -> 0.26792112 | AI34: =AB34/(AB34+AB35+AB36) -> 0.31698397 | AJ34: =AC34/(AC34+AC35+AC36) -> 0.3127266
A35: G' | B35: 75 | C35: 171 | D35: 62 | E35: 178 | F35: 171 | G35: 95 | H35: 180 | I35: =(B35-16)/219 -> 0.26940639 | J35: =(C35-16)/219 -> 0.70776256 | K35: =(D35-16)/219 -> 0.21004566 | L35: =(E35-16)/219 -> 0.73972603 | M35: =(F35-16)/219 -> 0.70776256 | N35: =(G35-16)/219 -> 0.36073059 | O35: =(H35-16)/219 -> 0.74885845 | P35: =I35^IF('Color Targets'!$AA$1=1,$N$1,INDEX(Calculation!$G$263:$G$372,MATCH(I35,Calculation!$H$263:$H$372))) -> 0.05130698 | Q35: =J35^IF('Color Targets'!$AA$1=1,$N$1,INDEX(Calculation!$G$263:$G$372,MATCH(J35,Calculation!$H$263:$H$372))) -> 0.454019 | R35: =K35^IF('Color Targets'!$AA$1=1,$N$1,INDEX(Calculation!$G$263:$G$372,MATCH(K35,Calculation!$H$263:$H$372))) -> 0.031074165 | S35: =L35^IF('Color Targets'!$AA$1=1,$N$1,INDEX(Calculation!$G$263:$G$372,MATCH(L35,Calculation!$H$263:$H$372))) -> 0.50467887 | T35: =M35^IF('Color Targets'!$AA$1=1,$N$1,INDEX(Calculation!$G$263:$G$372,MATCH(M35,Calculation!$H$263:$H$372))) -> 0.454019 | U35: =N35^IF('Color Targets'!$AA$1=1,$N$1,INDEX(Calculation!$G$263:$G$372,MATCH(N35,Calculation!$H$263:$H$372))) -> 0.096784013 | V35: =O35^IF('Color Targets'!$AA$1=1,$N$1,INDEX(Calculation!$G$274:$G$372,MATCH(O35,Calculation!$A$274:$A$372))) -> 0.52008248 | W35: 0.10596346 | X35: 0.36006191 | Y35: 0.036659149 | Z35: 0.48179758 | AA35: 0.39918404 | AB35: 0.14562268 | AC35: 0.52008254 | AD35: =W35/(W34+W35+W36) -> 0.32952633 | AE35: =X35/(X34+X35+X36) -> 0.4672843 | AF35: =Y35/(Y34+Y35+Y36) -> 0.19548759 | AG35: =Z35/(Z34+Z35+Z36) -> 0.4180402 | AH35: =AA35/(AA34+AA35+AA36) -> 0.32888941 | AI35: =AB35/(AB34+AB35+AB36) -> 0.23837457 | AJ35: =AC35/(AC34+AC35+AC36) -> 0.32902315
A36: B' | B36: 75 | C36: 104 | D36: 99 | E36: 121 | F36: 171 | G36: 139 | H36: 180 | I36: =(B36-16)/219 -> 0.26940639 | J36: =(C36-16)/219 -> 0.40182648 | K36: =(D36-16)/219 -> 0.37899543 | L36: =(E36-16)/219 -> 0.47945205 | M36: =(F36-16)/219 -> 0.70776256 | N36: =(G36-16)/219 -> 0.56164384 | O36: =(H36-16)/219 -> 0.74885845 | P36: =I36^IF('Color Targets'!$AA$1=1,$N$1,INDEX(Calculation!$G$263:$G$372,MATCH(I36,Calculation!$H$263:$H$372))) -> 0.05130698 | Q36: =J36^IF('Color Targets'!$AA$1=1,$N$1,INDEX(Calculation!$G$263:$G$372,MATCH(J36,Calculation!$H$263:$H$372))) -> 0.12416882 | R36: =K36^IF('Color Targets'!$AA$1=1,$N$1,INDEX(Calculation!$G$263:$G$372,MATCH(K36,Calculation!$H$263:$H$372))) -> 0.10845527 | S36: =L36^IF('Color Targets'!$AA$1=1,$N$1,INDEX(Calculation!$G$263:$G$372,MATCH(L36,Calculation!$H$263:$H$372))) -> 0.18765307 | T36: =M36^IF('Color Targets'!$AA$1=1,$N$1,INDEX(Calculation!$G$263:$G$372,MATCH(M36,Calculation!$H$263:$H$372))) -> 0.454019 | U36: =N36^IF('Color Targets'!$AA$1=1,$N$1,INDEX(Calculation!$G$263:$G$372,MATCH(N36,Calculation!$H$263:$H$372))) -> 0.26823923 | V36: =O36^IF('Color Targets'!$AA$1=1,$N$1,INDEX(Calculation!$G$274:$G$372,MATCH(O36,Calculation!$A$274:$A$372))) -> 0.52008248 | W36: 0.06083335 | X36: 0.17451424 | Y36: 0.10737007 | Z36: 0.24823858 | AA36: 0.48936451 | AB36: 0.27163083 | AC36: 0.56628141 | AD36: =W35 -> 0.10596346 | AE36: =X35 -> 0.36006191 | AF36: =Y35 -> 0.036659149 | AG36: =Z35 -> 0.48179758 | AH36: =AA35 -> 0.39918404 | AI36: =AB35 -> 0.14562268 | AJ36: =AC35 -> 0.52008254
A38: 50/100
A39: R' | B39: 126 | C39: 16 | D39: 16 | E39: 126 | F39: 16 | G39: 126 | H39: 126 | I39: =(B39-16)/219 -> 0.50228311 | J39: =(C39-16)/219 -> 0 | K39: =(D39-16)/219 -> 0 | L39: =(E39-16)/219 -> 0.50228311 | M39: =(F39-16)/219 -> 0 | N39: =(G39-16)/219 -> 0.50228311 | O39: =(H39-16)/219 -> 0.50228311 | P39: =I39^IF('Color Targets'!$AA$1=1,$N$1,INDEX(Calculation!$G$263:$G$372,MATCH(I39,Calculation!$H$263:$H$372))) -> 0.20921507 | Q39: =J39^$N$1 -> 0 | R39: =K39^$N$1 -> 0 | S39: =L39^IF('Color Targets'!$AA$1=1,$N$1,INDEX(Calculation!$G$263:$G$372,MATCH(L39,Calculation!$H$263:$H$372))) -> 0.20921507 | T39: =M39^$N$1 -> 0 | U39: =N39^IF('Color Targets'!$AA$1=1,$N$1,INDEX(Calculation!$G$263:$G$372,MATCH(N39,Calculation!$H$263:$H$372))) -> 0.20921507 | V39: =O39^IF('Color Targets'!$AA$1=1,$N$1,INDEX(Calculation!$G$263:$G$372,MATCH(O39,Calculation!$A$263:$A$372))) -> 0.20973229 | W39: {=MMULT($B$3:$D$5,P39:P41)} -> 0.086292093 | X39: {=MMULT($B$3:$D$5,Q39:Q41)} -> 0.074810308 | Y39: {=MMULT($B$3:$D$5,R39:R41)} -> 0.037750244 | Z39: {=MMULT($B$3:$D$5,S39:S41)} -> 0.1611024 | AA39: {=MMULT($B$3:$D$5,T39:T41)} -> 0.11256055 | AB39: {=MMULT($B$3:$D$5,U39:U41)} -> 0.12404234 | AC39: {=MMULT($B$3:$D$5,V39:V41)} -> 0.19934425 | AD39: =W39/(W39+W40+W41) -> 0.63999993 | AE39: =X39/(X39+X40+X41) -> 0.30000001 | AF39: =Y39/(Y39+Y40+Y41) -> 0.15000001 | AG39: =Z39/(Z39+Z40+Z41) -> 0.41932009 | AH39: =AA39/(AA39+AA40+AA41) -> 0.22465563 | AI39: =AB39/(AB39+AB40+AB41) -> 0.32093774 | AJ39: =AC39/(AC39+AC40+AC41) -> 0.3127266
A40: G' | B40: 16 | C40: 126 | D40: 16 | E40: 126 | F40: 126 | G40: 16 | H40: 126 | I40: =(B40-16)/219 -> 0 | J40: =(C40-16)/219 -> 0.50228311 | K40: =(D40-16)/219 -> 0 | L40: =(E40-16)/219 -> 0.50228311 | M40: =(F40-16)/219 -> 0.50228311 | N40: =(G40-16)/219 -> 0 | O40: =(H40-16)/219 -> 0.50228311 | P40: =I40^$N$1 -> 0 | Q40: =J40^IF('Color Targets'!$AA$1=1,$N$1,INDEX(Calculation!$G$263:$G$372,MATCH(J40,Calculation!$H$263:$H$372))) -> 0.20921507 | R40: =K40^$N$1 -> 0 | S40: =L40^IF('Color Targets'!$AA$1=1,$N$1,INDEX(Calculation!$G$263:$G$372,MATCH(L40,Calculation!$H$263:$H$372))) -> 0.20921507 | T40: =M40^IF('Color Targets'!$AA$1=1,$N$1,INDEX(Calculation!$G$263:$G$372,MATCH(M40,Calculation!$H$263:$H$372))) -> 0.20921507 | U40: =N40^$N$1 -> 0 | V40: =O40^IF('Color Targets'!$AA$1=1,$N$1,INDEX(Calculation!$G$263:$G$372,MATCH(O40,Calculation!$A$263:$A$372))) -> 0.20973229 | W40: 0.044494375 | X40: 0.14962062 | Y40: 0.015100097 | Z40: 0.19411499 | AA40: 0.16472071 | AB40: 0.059594472 | AC40: 0.20973231 | AD40: =W40/(W39+W40+W41) -> 0.33000007 | AE40: =X40/(X39+X40+X41) -> 0.60000002 | AF40: =Y40/(Y39+Y40+Y41) -> 0.060000003 | AG40: =Z40/(Z39+Z40+Z41) -> 0.50524583 | AH40: =AA40/(AA39+AA40+AA41) -> 0.32876026 | AI40: =AB40/(AB39+AB40+AB41) -> 0.15419022 | AJ40: =AC40/(AC39+AC40+AC41) -> 0.32902315
A41: B' | B41: 16 | C41: 16 | D41: 126 | E41: 16 | F41: 126 | G41: 126 | H41: 126 | I41: =(B41-16)/219 -> 0 | J41: =(C41-16)/219 -> 0 | K41: =(D41-16)/219 -> 0.50228311 | L41: =(E41-16)/219 -> 0 | M41: =(F41-16)/219 -> 0.50228311 | N41: =(G41-16)/219 -> 0.50228311 | O41: =(H41-16)/219 -> 0.50228311 | P41: =I41^$N$1 -> 0 | Q41: =J41^$N$1 -> 0 | R41: =K41^IF('Color Targets'!$AA$1=1,$N$1,INDEX(Calculation!$G$263:$G$372,MATCH(K41,Calculation!$H$263:$H$372))) -> 0.20921507 | S41: =L41^$N$1 -> 0 | T41: =M41^IF('Color Targets'!$AA$1=1,$N$1,INDEX(Calculation!$G$263:$G$372,MATCH(M41,Calculation!$H$263:$H$372))) -> 0.20921507 | U41: =N41^IF('Color Targets'!$AA$1=1,$N$1,INDEX(Calculation!$G$263:$G$372,MATCH(N41,Calculation!$H$263:$H$372))) -> 0.20921507 | V41: =O41^IF('Color Targets'!$AA$1=1,$N$1,INDEX(Calculation!$G$263:$G$372,MATCH(O41,Calculation!$A$263:$A$372))) -> 0.20973229 | W41: 0.0040449432 | X41: 0.024936762 | Y41: 0.19881794 | Z41: 0.028981705 | AA41: 0.2237547 | AB41: 0.20286288 | AC41: 0.22836281 | AD41: =W40 -> 0.044494375 | AE41: =X40 -> 0.14962062 | AF41: =Y40 -> 0.015100097 | AG41: =Z40 -> 0.19411499 | AH41: =AA40 -> 0.16472071 | AI41: =AB40 -> 0.059594472 | AJ41: =AC40 -> 0.20973231
A43: 50/75
A44: R' | B44: 115 | C44: 58 | D44: 44 | E44: 126 | F44: 69 | G44: 110 | H44: 126 | I44: =(B44-16)/219 -> 0.45205479 | J44: =(C44-16)/219 -> 0.19178082 | K44: =(D44-16)/219 -> 0.12785388 | L44: =(E44-16)/219 -> 0.50228311 | M44: =(F44-16)/219 -> 0.24200913 | N44: =(G44-16)/219 -> 0.42922374 | O44: =(H44-16)/219 -> 0.50228311 | P44: =I44^IF('Color Targets'!$AA$1=1,$N$1,INDEX(Calculation!$G$263:$G$372,MATCH(I44,Calculation!$H$263:$H$372))) -> 0.16358674 | Q44: =J44^IF('Color Targets'!$AA$1=1,$N$1,INDEX(Calculation!$G$263:$G$372,MATCH(J44,Calculation!$H$263:$H$372))) -> 0.026174108 | R44: =K44^IF('Color Targets'!$AA$1=1,$N$1,INDEX(Calculation!$G$263:$G$372,MATCH(K44,Calculation!$H$263:$H$372))) -> 0.01233986 | S44: =L44^IF('Color Targets'!$AA$1=1,$N$1,INDEX(Calculation!$G$263:$G$372,MATCH(L44,Calculation!$H$263:$H$372))) -> 0.20921507 | T44: =M44^IF('Color Targets'!$AA$1=1,$N$1,INDEX(Calculation!$G$263:$G$372,MATCH(M44,Calculation!$H$263:$H$372))) -> 0.041398085 | U44: =N44^IF('Color Targets'!$AA$1=1,$N$1,INDEX(Calculation!$G$263:$G$372,MATCH(N44,Calculation!$H$263:$H$372))) -> 0.14483934 | V44: =O44^IF('Color Targets'!$AA$1=1,$N$1,INDEX(Calculation!$G$274:$G$372,MATCH(O44,Calculation!$A$274:$A$372))) -> 0.20973229 | W44: {=MMULT($B$3:$D$5,P44:P46)} -> 0.074111411 | X44: {=MMULT($B$3:$D$5,Q44:Q46)} -> 0.085668364 | Y44: {=MMULT($B$3:$D$5,R44:R46)} -> 0.02359872 | Z44: {=MMULT($B$3:$D$5,S44:S46)} -> 0.16726615 | AA44: {=MMULT($B$3:$D$5,T44:T46)} -> 0.12262334 | AB44: {=MMULT($B$3:$D$5,U44:U46)} -> 0.095233595 | AC44: {=MMULT($B$3:$D$5,V44:V46)} -> 0.19934425 | AD44: =W44/(W44+W45+W46) -> 0.54906457 | AE44: =X44/(X44+X45+X46) -> 0.30358775 | AF44: =Y44/(Y44+Y45+Y46) -> 0.20232407 | AG44: =Z44/(Z44+Z45+Z46) -> 0.39329834 | AH44: =AA44/(AA44+AA45+AA46) -> 0.24697413 | AI44: =AB44/(AB44+AB45+AB46) -> 0.31875144 | AJ44: =AC44/(AC44+AC45+AC46) -> 0.3127266
A45: G' | B45: 44 | C45: 123 | D45: 44 | E45: 126 | F45: 123 | G45: 58 | H45: 126 | I45: =(B45-16)/219 -> 0.12785388 | J45: =(C45-16)/219 -> 0.48858447 | K45: =(D45-16)/219 -> 0.12785388 | L45: =(E45-16)/219 -> 0.50228311 | M45: =(F45-16)/219 -> 0.48858447 | N45: =(G45-16)/219 -> 0.19178082 | O45: =(H45-16)/219 -> 0.50228311 | P45: =I45^IF('Color Targets'!$AA$1=1,$N$1,INDEX(Calculation!$G$263:$G$372,MATCH(I45,Calculation!$H$263:$H$372))) -> 0.01233986 | Q45: =J45^IF('Color Targets'!$AA$1=1,$N$1,INDEX(Calculation!$G$263:$G$372,MATCH(J45,Calculation!$H$263:$H$372))) -> 0.19618172 | R45: =K45^IF('Color Targets'!$AA$1=1,$N$1,INDEX(Calculation!$G$263:$G$372,MATCH(K45,Calculation!$H$263:$H$372))) -> 0.01233986 | S45: =L45^IF('Color Targets'!$AA$1=1,$N$1,INDEX(Calculation!$G$263:$G$372,MATCH(L45,Calculation!$H$263:$H$372))) -> 0.20921507 | T45: =M45^IF('Color Targets'!$AA$1=1,$N$1,INDEX(Calculation!$G$263:$G$372,MATCH(M45,Calculation!$H$263:$H$372))) -> 0.19618172 | U45: =N45^IF('Color Targets'!$AA$1=1,$N$1,INDEX(Calculation!$G$263:$G$372,MATCH(N45,Calculation!$H$263:$H$372))) -> 0.026174108 | V45: =O45^IF('Color Targets'!$AA$1=1,$N$1,INDEX(Calculation!$G$274:$G$372,MATCH(O45,Calculation!$A$274:$A$372))) -> 0.20973229 | W45: 0.044505974 | X45: 0.14775543 | Y45: 0.017087883 | Z45: 0.19658049 | AA45: 0.16326346 | AB45: 0.059975652 | AC45: 0.20973231 | AD45: =W45/(W44+W45+W46) -> 0.32972862 | AE45: =X45/(X44+X45+X46) -> 0.52360914 | AF45: =Y45/(Y44+Y45+Y46) -> 0.14650329 | AG45: =Z45/(Z44+Z45+Z46) -> 0.4622261 | AH45: =AA45/(AA44+AA45+AA46) -> 0.32882688 | AI45: =AB45/(AB44+AB45+AB46) -> 0.2007414 | AJ45: =AC45/(AC44+AC45+AC46) -> 0.32902315
