Workbook

Sheet Summary
A1: Reference Database Statistics Summary
A2: 2010-2011
A4: * usage constrained by limitations on concurrent users
A5: Database Name | B5: Vendor / Platform | C5: COUNTER-compliant? | D5: Sessions | E5: Searches | F5: Searches, prev. yr | G5: % change | H5: Turnaways | I5: Successful full-text article requests | J5: 2010/11 Price | K5: Cost per Search
A6: ABI/INFORM Dateline | B6: ProQuest | C6: Yes | D6: =ProQuest!N9 -> 4004 | E6: =ProQuest!N8 -> 11634 | H6: 0 | I6: N/A | J6: 6440 | K6: N/A
A7: ABI/INFORM Global | B7: ProQuest | C7: Yes | D7: =ProQuest!N15 -> 5554 | E7: =ProQuest!N14 -> 17551 | H7: 0 | I7: N/A | J7: 6440 | K7: =J7/E7 -> 0.36693066
A8: ABI/INFORM Trade & Industry | B8: ProQuest | C8: Yes | D8: =ProQuest!N21 -> 4013 | E8: =ProQuest!N20 -> 12029 | H8: 0 | I8: N/A | J8: 6440 | K8: N/A
A9: Academic Search Complete (statewide database trial) | B9: EBSCOhost | C9: Yes | D9: =EBSCOhost!N8 -> 57015 | E9: =EBSCOhost!N9 -> 186507 | H9: 0 | I9: N/A | J9: 0 | K9: N/A
A10: Academic Search Premier | B10: EBSCOhost | C10: Yes | D10: =EBSCOhost!N14 -> 28242 | E10: =EBSCOhost!N15 -> 48546 | H10: 0 | I10: N/A | J10: 21582 | K10: =J10/E10 -> 0.44456804
A11: ALA Guide to Reference | B11: ALA Editions | C11: No | D11: ='ALA Guide to Reference'!N8 -> 11 | E11: N/A | H11: N/A | I11: N/A | J11: 1238 | K11: N/A
A12: Alternative Press Index | B12: FirstSearch | C12: Yes | D12: N/A | E12: =FirstSearch!N8 -> 0 | H12: 0 | I12: N/A | J12: N/A | K12: N/A
A13: Alternative Press Index Archive | B13: FirstSearch | C13: Yes | D13: N/A | E13: =FirstSearch!N13 -> 0 | H13: 0 | I13: N/A | J13: N/A | K13: N/A
A14: America History & Life | B14: EBSCOhost | C14: Yes | D14: =EBSCOhost!N20 -> 2255 | E14: =EBSCOhost!N21 -> 10227 | H14: 0 | I14: N/A | J14: 8117 | K14: =J14/E14 -> 0.79368339
A15: American State Papers, 1789-1838 | B15: Newsbank | C15: Yes (R2) | D15: N/A | E15: =Newsbank!N8 -> 12 | H15: 0 | I15: N/A | J15: 583.33 | K15: N/A
A16: ARBA Online | B16: Greenwood Press | C16: Yes (R2) | D16: =Greenwood!N9 -> 9 | E16: =Greenwood!N8 -> 0 | H16: 0 | I16: N/A | J16: 239 | K16: N/A
A17: Art Abstracts | B17: WilsonWeb | C17: Yes (R2) | D17: =WilsonWeb!N8 -> 602 | E17: =WilsonWeb!N9 -> 2678 | H17: =WilsonWeb!N11 -> N/A | I17: N/A | J17: 6480 | K17: =J17/E17 -> 2.4197162
A18: Art Index Retrospective* | B18: WilsonWeb | C18: Yes (R2) | D18: =WilsonWeb!N16 -> 169 | E18: =WilsonWeb!N17 -> 530 | H18: =WilsonWeb!N18 -> 10 | I18: N/A | J18: 581 | K18: =J18/E18 -> 1.0962264
A19: ArticleFirst* | B19: FirstSearch | C19: Yes | D19: =FirstSearch!N18 -> 1097 | E19: =FirstSearch!N19 -> 4977 | H19: =FirstSearch!N21 -> 31 | I19: N/A | J19: 0 | K19: N/A
A20: ARTstor | B20: ArtSTOR | C20: No | D20: =ARTstor!N9 -> 2602 | E20: N/A | H20: N/A | I20: N/A | J20: 13432.5 | K20: N/A
A21: ASFA 1 (Biosciences...) | B21: CSA | C21: Yes (R3) | D21: N/A | E21: =CSA!N13 -> 1988 | H21: 0 | I21: N/A | J21: 1377.5 | K21: =J21/E21 -> 0.69290744
A22: ASFA 2 (Ocean Technology...) | B22: CSA | C22: Yes (R3) | D22: N/A | E22: =CSA!N18 -> 972 | H22: 0 | I22: N/A | J22: 1377.5 | K22: =J22/E22 -> 1.4171811
A23: ASFA 3 (Aquatic Pollution...) | B23: CSA | C23: Yes (R3) | D23: N/A | E23: =CSA!N23 -> 1260 | H23: 0 | I23: N/A | J23: 1377.5 | K23: =J23/E23 -> 1.093254
A24: ASFA Aquaculture Abstracts | B24: CSA | C24: Yes (R3) | D24: N/A | E24: =CSA!N28 -> 1437 | H24: 0 | I24: N/A | J24: 1377.5 | K24: =J24/E24 -> 0.95859429
A25: ASFA Marine Biotechnology Abstracts | B25: CSA | C25: Yes (R3) | D25: N/A | E25: =CSA!N33 -> 1158 | H25: 0 | I25: N/A | J25: 1377.5 | K25: =J25/E25 -> 1.1895509
A26: ASFA: Aquatic Science & Fisheries Abstracts (all) | B26: CSA | C26: Yes (R3) | D26: N/A | E26: =CSA!N8 -> 5663 | H26: 0 | I26: N/A | J26: 1377.5 | K26: =J26/E26 -> 0.24324563
A27: Bacteriology Abstracts (Microbiology B) | B27: CSA | C27: Yes (R3) | D27: N/A | E27: =CSA!N38 -> 0 | H27: N/A | I27: N/A | J27: 0 | K27: N/A
A28: Baptisteria Sacra Index | B28: ITER | D28: =ITER!N8 -> 0 | E28: =ITER!N9 -> 0 | J28: 0 | K28: N/A
A29: Biography Index Retrospective* | B29: WilsonWeb | C29: Yes (R2) | D29: N/A | E29: N/A | H29: N/A | I29: N/A | J29: 59 | K29: N/A
A30: Biological Abstracts | B30: Ovid | C30: Yes (R3) | D30: =OVID!N9 -> 7 | E30: =OVID!N8 -> 17 | H30: =OVID!N10 -> 0 | I30: N/A | J30: 0 | K30: N/A
A31: Biological & Agricultural Index Plus | B31: WilsonWeb | C31: Yes (R2) | D31: =WilsonWeb!N32 -> 461 | E31: =WilsonWeb!N33 -> 1089 | H31: =WilsonWeb!N34 -> 0 | I31: N/A | J31: =WilsonWeb!O33 -> 0 | K31: =WilsonWeb!P33 -> 0
A32: BIOSIS Previews | B32: Ovid | C32: Yes | D32: =OVID!N16 -> 0 | E32: =OVID!N15 -> 0 | H32: =OVID!N17 -> 0 | I32: N/A | J32: 0 | K32: N/A
A33: BIOSIS Previews | B33: Web of Science | C33: Yes | D33: =WebofScience!N8 -> 745 | E33: =WebofScience!N9 -> 2989 | H33: 0 | I33: N/A | J33: 30545 | K33: =J33/E33 -> 10.219137
A34: Biotechnology Research Abstracts | B34: CSA | C34: Yes (R3) | D34: N/A | E34: =CSA!N43 -> 0 | H34: 0 | I34: N/A | J34: 0 | K34: N/A
A35: Book Review Digest Retrospective* | B35: WilsonWeb | C35: Yes (R2) | D35: N/A | E35: N/A | H35: N/A | I35: N/A | J35: 96.82 | K35: N/A
A36: CIAO | B36: CIAO | C36: No | D36: =CIAO!N9 -> 6 | E36: =CIAO!N10 -> 15 | H36: N/A | I36: =CIAO!N8 -> 6 | J36: 1035 | K36: =J36/E36 -> 69
A37: CINAHL | B37: EBSCOhost | C37: Yes | D37: =EBSCOhost!N26 -> 14567 | E37: =EBSCOhost!N27 -> 73212 | H37: 0 | I37: N/A | J37: 6046 | K37: =J37/E37 -> 0.08258209
A38: Clase and Periodica* | B38: FirstSearch | C38: Yes | D38: =FirstSearch!N26 -> 97 | E38: =FirstSearch!N27 -> 98 | H38: =FirstSearch!N29 -> 1 | I38: N/A | J38: 0 | K38: N/A
A39: Cochrane Library | B39: Wiley InterScience | C39: No | D39: =Cochrane!N8 -> 97 | E39: =Cochrane!N9 -> 3851 | H39: N/A | I39: N/A | J39: 3596 | K39: =J39/E39 -> 0.93378343
A40: ComDisDome | B40: CSA | C40: Yes (R3) | D40: N/A | E40: =CSA!N48 -> 3754 | I40: N/A | J40: 2370 | K40: =J40/E40 -> 0.63132658
A41: Communication Abstracts | B41: EBSCOhost | C41: Yes (R3) | D41: =EBSCOhost!N32 -> 2759 | E41: =EBSCOhost!N33 -> 14027 | I41: N/A | J41: 3025 | K41: =J41/E41 -> 0.21565552
...

Sheet ALA Guide to Reference
A1: ALA Guide to Reference
A2: 2010-2011
A4: COUNTER-Compliant?: | B4: No
B6: Jul-2010 | C6: Aug-2010 | D6: Sep-2010 | E6: Oct-2010 | F6: Nov-2010 | G6: Dec-2010 | H6: Jan-2011 | I6: Feb-2011 | J6: Mar-2011 | K6: Apr-2011 | L6: May-2011 | M6: Jun-2011 | N6: Total | O6: 2010-2011 price | P6: Price per unit
A7: ALA Guide to Reference
A8: Logins | B8: 2 | C8: 0 | D8: 1 | E8: 3 | F8: 0 | G8: 1 | H8: 0 | I8: 2 | J8: 2 | K8: 0 | L8: 0 | M8: 0 | N8: =SUM(B8:M8) -> 11 | O8: 0 | P8: =O8/N8 -> 0

Sheet ARTstor
A1: ARTstor
A2: 2010-2011
A4: COUNTER-Compliant?: | B4: No
B6: 40360 | C6: 40391 | D6: 40422 | E6: 40452 | F6: 40483 | G6: 40513 | H6: 40544 | I6: 40575 | J6: 40603 | K6: 40634 | L6: 40664 | M6: 40695 | N6: Total | O6: 2010-2011 Price | P6: Price per unit
A7: ARTstor
A8: Events | B8: 2349 | C8: 3501 | D8: 4489 | E8: 12379 | F8: 13198 | G8: 18428 | H8: 1188 | I8: 3405 | J8: 7485 | K8: 9511 | L8: 956 | M8: 946 | N8: =SUM(B8:M8) -> 77835 | O8: 13102.5 | P8: =O8/N8 -> 0.16833687
A9: Sessions | B9: 35 | C9: 22 | D9: 154 | E9: 539 | F9: 502 | G9: 596 | H9: 45 | I9: 165 | J9: 189 | K9: 259 | L9: 58 | M9: 38 | N9: =SUM(B9:M9) -> 2602 | P9: =O9/N9 -> #VALUE!
A10: Users | B10: 0 | C10: 0 | D10: 0 | E10: 0 | F10: 0 | G10: n/a | H10: n/a | I10: n/a | J10: n/a | K10: n/a | L10: n/a | M10: n/a | N10: =SUM(B10:M10) -> 0 | P10: =O10/N10 -> #VALUE!
A11: Minutes | B11: 0 | C11: 0 | D11: 0 | E11: 0 | F11: 0 | G11: n/a | H11: n/a | I11: n/a | J11: n/a | K11: n/a | L11: n/a | M11: n/a | N11: =SUM(B11:M11) -> 0 | P11: =O11/N11 -> #VALUE!
A12: Registrations | B12: 1 | C12: 1 | D12: 42 | E12: 112 | F12: 12 | G12: 14 | H12: 2 | I12: 4 | J12: 2 | K12: 10 | L12: 1 | M12: 1 | N12: =SUM(B12:M12) -> 202 | P12: =O12/N12 -> #VALUE!
A15: Events: | B15: Number of events.
A17: Sessions: | B17: Number of sessions.
A19: Users: | B19: Number of unique users who logged in during the time period. All users who did not log in are counted as one additional users. The numbers of monthly users are not additive, i.e. the sum of monthly users is not equal to the total number of unique users for all time.
A21: Minutes: | B21: Total minutes used by all sessions.
A23: Registrations: | B23: Number of new registrations.

Sheet CIAO
A1: CIAO
A2: 2010-2011
A4: COUNTER-Compliant?: | B4: No
B6: 40360 | C6: 40391 | D6: 40422 | E6: 40452 | F6: 40483 | G6: 40513 | H6: 40544 | I6: 40575 | J6: 40603 | K6: 40634 | L6: 40664 | M6: 40695 | N6: Total | O6: 2010-2011 Price | P6: Price per unit
A7: CIAO
A8: No of Visitors | B8: 0 | C8: 0 | D8: 0 | E8: 1 | F8: 0 | G8: 0 | H8: 0 | I8: 1 | J8: 4 | K8: 0 | L8: 0 | M8: 0 | N8: =SUM(B8:M8) -> 6 | O8: 0 | P8: =O8/N8 -> 0
A9: No of Visits | B9: 0 | C9: 0 | D9: 0 | E9: 1 | F9: 0 | G9: 0 | H9: 0 | I9: 1 | J9: 4 | K9: 0 | L9: 0 | M9: 0 | N9: =SUM(B9:M9) -> 6 | O9: 0 | P9: =O9/N9 -> 0
A10: No of Views | B10: 0 | C10: 0 | D10: 0 | E10: 8 | F10: 0 | G10: 0 | H10: 0 | I10: 1 | J10: 6 | K10: 0 | L10: 0 | M10: 0 | N10: =SUM(B10:M10) -> 15 | O10: 0 | P10: =O10/N10 -> 0
A11: No of Google Searches | B11: 0 | C11: 0 | D11: 0 | E11: 0 | F11: 0 | G11: 0 | H11: 0 | I11: 0 | J11: 0 | K11: 0 | L11: 0 | M11: 0 | N11: =SUM(B11:M11) -> 0 | O11: 0 | P11: N/A
A12: Articles Viewed | B12: 0 | C12: 0 | D12: 0 | E12: 2 | F12: 0 | G12: 0 | H12: 0 | I12: 1 | J12: 0 | K12: 0 | L12: 0 | M12: 0 | N12: =SUM(B12:M12) -> 3 | O12: 0 | P12: =O12/N12 -> 0
A13: Average Visit Duration | B13: 0 | C13: 0 | D13: 0 | E13: 4m49sec | F13: 0 | G13: 0 | H13: 0 | I13: 0 | J13: 1m28sec | K13: 0 | L13: 0 | M13: 0 | N13: —

Sheet Cochrane
A1: Cochrane Library (Wiley)
A2: 2010-2011
A4: COUNTER-Compliant?: | B4: No
B6: 40360 | C6: 6614756 | D6: 40422 | E6: 40452 | F6: 40483 | G6: 40513 | H6: 40544 | I6: 40575 | J6: 40603 | K6: 40634 | L6: 40664 | M6: 40695 | N6: Total | O6: 2010-2011 Price | P6: Price per unit
A7: Cochrane Library
A8: User Sessions | B8: 97 | C8: N/A | D8: N/A | E8: N/A | F8: N/A | G8: N/A | H8: N/A | I8: N/A | J8: N/A | K8: N/A | L8: N/A | M8: N/A | N8: =SUM(B8:M8) -> 97
A9: Searches (Total) | B9: 27 | C9: 0 | D9: 0 | E9: 469 | F9: 717 | G9: 313 | H9: 453 | I9: 360 | J9: 563 | K9: 631 | L9: 161 | M9: 157 | N9: =SUM(B9:M9) -> 3851 | O9: 3494 | P9: =O9/N9 -> 0.90729681
A10: Full-Text (Total) | B10: 84 | C10: 20 | D10: 122 | E10: 224 | F10: 342 | G10: 126 | H10: 143 | I10: 180 | J10: 276 | K10: 290 | L10: 92 | M10: 64 | N10: =SUM(B10:M10) -> 1963
A11: Access Denied | B11: 0 | C11: N/A | D11: N/A | E11: N/A | F11: N/A | G11: N/A | H11: N/A | I11: N/A | J11: N/A | K11: N/A | L11: N/A | M11: N/A | N11: =SUM(B11:M11) -> 0

Sheet Compendex(EI)
A1: Compendex (Engineering Index)
A2: 2010-2011
A4: COUNTER-Compliant?: | B4: Yes (R2)
B6: 40360 | C6: 40391 | D6: 40422 | E6: 40452 | F6: 40483 | G6: 40513 | H6: 40544 | I6: 40575 | J6: 40603 | K6: 40634 | L6: 40664 | M6: 40695 | N6: Total | O6: 2010-2011 Price | P6: Price per unit
A7: Compendex
A8: Sessions | B8: 40 | C8: 54 | D8: 91 | E8: 409 | F8: 86 | G8: 60 | H8: 30 | I8: 48 | J8: 68 | K8: 59 | L8: 48 | M8: 62 | N8: =SUM(B8:M8) -> 1055
A9: Searches | B9: 146 | C9: 198 | D9: 339 | E9: 3319 | F9: 325 | G9: 187 | H9: 162 | I9: 136 | J9: 198 | K9: 199 | L9: 189 | M9: 281 | N9: =SUM(B9:M9) -> 5679 | O9: 17805 | P9: =O9/N9 -> 3.1352351

Sheet CQ Researcher
A1: CQ Researcher
A2: 2010-2011
A4: COUNTER-compliant? | B4: Yes
B6: 40360 | C6: 40391 | D6: 6614787 | E6: 40452 | F6: 40483 | G6: 40513 | H6: 40544 | I6: 40575 | J6: 40603 | K6: 40634 | L6: 40664 | M6: 40695 | N6: Total | O6: 2010-2011 Price | P6: Price per unit
A7: CQ Researcher
A8: Sessions | B8: 75 | C8: 2 | D8: 100 | E8: 126 | F8: 292 | G8: 100 | H8: 11 | I8: 99 | J8: 172 | K8: 127 | L8: 41 | M8: 82 | N8: =SUM(B8:M8) -> 1227
A9: Searches | B9: 93 | C9: 0 | D9: 112 | E9: 163 | F9: 302 | G9: 77 | H9: 7 | I9: 103 | J9: 265 | K9: 159 | L9: 55 | M9: 98 | N9: =SUM(B9:M9) -> 1434 | O9: 0 | P9: =O9/N9 -> 0
A10: Full Text Downloads | B10: 120 | C10: 0 | D10: 180 | E10: 200 | F10: 447 | G10: 141 | H10: 4 | I10: 137 | J10: 423 | K10: 265 | L10: 142 | M10: 176 | N10: =SUM(B10:M10) -> 2235 | O10: 0 | P10: =O10/N10 -> 0
A11: Turnaways | B11: 0 | C11: 0 | D11: 0 | E11: 0 | F11: 0 | G11: 0 | H11: 0 | I11: 0 | J11: 0 | K11: 0 | L11: 0 | M11: 0 | N11: =SUM(B11:M11) -> 0
A13: SIMULTANEOUS USERS: | B13: 10

Sheet CSA
A1: CSA Databases
A2: 2010-2011
A4: COUNTER-Compliant?: | B4: Yes (R3)
B6: 40360 | C6: 40391 | D6: 6614787 | E6: 40452 | F6: 40483 | G6: 40513 | H6: 40544 | I6: 40575 | J6: 40603 | K6: 40634 | L6: 40664 | M6: 40695 | N6: Total | O6: 2010-2011 Price | P6: Price per unit
A7: ASFA (all)
A8: Searches | B8: 250 | C8: 206 | D8: 616 | E8: 855 | F8: 763 | G8: 259 | H8: 386 | I8: 612 | J8: 600 | K8: 676 | L8: 382 | M8: 58 | N8: =SUM(B8:M8) -> 5663 | O8: 0 | P8: =O8/N8 -> 0
B11: 40360 | C11: 40391 | D11: 6614787 | E11: 40452 | F11: 40483 | G11: 40513 | H11: 40544 | I11: 40575 | J11: 40603 | K11: 40634 | L11: 40664 | M11: 40695 | N11: Total | O11: 2010-2011 Price | P11: Price per unit
A12: ASFA 1 (Biosciences...)
A13: Searches | B13: 43 | C13: 30 | D13: 189 | E13: 374 | F13: 304 | G13: 98 | H13: 74 | I13: 211 | J13: 348 | K13: 241 | L13: 70 | M13: 6 | N13: =SUM(B13:M13) -> 1988 | O13: 0 | P13: N/A
B16: 40360 | C16: 40391 | D16: 6614787 | E16: 40452 | F16: 40483 | G16: 40513 | H16: 40544 | I16: 40575 | J16: 40603 | K16: 40634 | L16: 40664 | M16: 40695 | N16: Total | O16: 2010-2011 Price | P16: Price per unit
A17: ASFA 2 (Ocean Technology…)
A18: Searches | B18: 23 | C18: 18 | D18: 80 | E18: 141 | F18: 134 | G18: 42 | H18: 62 | I18: 112 | J18: 187 | K18: 120 | L18: 51 | M18: 2 | N18: =SUM(B18:M18) -> 972 | O18: 0 | P18: N/A
B21: 40360 | C21: 40391 | D21: 6614787 | E21: 40452 | F21: 40483 | G21: 40513 | H21: 40544 | I21: 40575 | J21: 40603 | K21: 40634 | L21: 40664 | M21: 40695 | N21: Total | O21: 2010-2011 Price | P21: Price per unit
A22: ASFA 3 (Aquatic Pollution…)
A23: Searches | B23: 40 | C23: 25 | D23: 105 | E23: 171 | F23: 193 | G23: 52 | H23: 67 | I23: 139 | J23: 241 | K23: 164 | L23: 61 | M23: 2 | N23: =SUM(B23:M23) -> 1260 | O23: 0 | P23: N/A
B26: 40360 | C26: 40391 | D26: 6614787 | E26: 40452 | F26: 40483 | G26: 40513 | H26: 40544 | I26: 40575 | J26: 40603 | K26: 40634 | L26: 40664 | M26: 40695 | N26: Total | O26: 2010-2011 Price | P26: Price per unit
A27: ASFA Aquaculture Abstracts
A28: Searches | B28: 25 | C28: 25 | D28: 99 | E28: 187 | F28: 236 | G28: 73 | H28: 114 | I28: 186 | J28: 263 | K28: 165 | L28: 59 | M28: 5 | N28: =SUM(B28:M28) -> 1437 | O28: 0 | P28: N/A
B31: 40360 | C31: 40391 | D31: 6614787 | E31: 40452 | F31: 40483 | G31: 40513 | H31: 40544 | I31: 40575 | J31: 40603 | K31: 40634 | L31: 40664 | M31: 40695 | N31: Total | O31: 2010-2011 Price | P31: Price per unit
A32: ASFA Marine Biotechnology Abstracts
A33: Searches | B33: 25 | C33: 25 | D33: 123 | E33: 157 | F33: 156 | G33: 49 | H33: 65 | I33: 138 | J33: 219 | K33: 142 | L33: 57 | M33: 2 | N33: =SUM(B33:M33) -> 1158 | O33: 0 | P33: N/A
B36: 40360 | C36: 40391 | D36: 6614787 | E36: 40452 | F36: 40483 | G36: 40513 | H36: 40544 | I36: 40575 | J36: 40603 | K36: 40634 | L36: 40664 | M36: 40695 | N36: Total | O36: 2010-2011 Price | P36: Price per unit
A37: Bacteriology Abstracts (Microbiology B)
A38: Searches | B38: 0 | C38: 0 | D38: 0 | E38: 0 | F38: 0 | G38: 0 | H38: N/A | I38: N/A | J38: N/A | K38: N/A | L38: N/A | M38: N/A | N38: =SUM(B38:M38) -> 0 | O38: 0 | P38: N/A
B41: 40360 | C41: 40391 | D41: 6614787 | E41: 40452 | F41: 40483 | G41: 40513 | H41: 40544 | I41: 40575 | J41: 40603 | K41: 40634 | L41: 40664 | M41: 40695 | N41: Total | O41: 2010-2011 Price | P41: Price per unit
A42: Biotechnology Research Abstracts
A43: Searches | B43: 0 | C43: 0 | D43: 0 | E43: 0 | F43: 0 | G43: 0 | H43: N/A | I43: N/A | J43: N/A | K43: N/A | L43: N/A | M43: N/A | N43: =SUM(B43:M43) -> 0 | O43: 0 | P43: N/A
B46: 40360 | C46: 40391 | D46: 6614787 | E46: 40452 | F46: 40483 | G46: 40513 | H46: 40544 | I46: 40575 | J46: 40603 | K46: 40634 | L46: 40664 | M46: 40695 | N46: Total | O46: 2010-2011 Price | P46: Price per unit
A47: ComDisDome
A48: Searches | B48: 291 | C48: 92 | D48: 219 | E48: 597 | F48: 487 | G48: 205 | H48: 96 | I48: 471 | J48: 602 | K48: 508 | L48: 153 | M48: 33 | N48: =SUM(B48:M48) -> 3754 | O48: 0 | P48: =O48/N48 -> 0
B51: 40360 | C51: 40391 | D51: 6614787 | E51: 40452 | F51: 40483 | G51: 40513 | H51: 40544 | I51: 40575 | J51: 40603 | K51: 40634 | L51: 40664 | M51: 40695 | N51: Total | O51: 2010-2011 Price | P51: Price per unit
A52: Conference Papers Index
A53: Searches | B53: 0 | C53: 0 | D53: 0 | E53: 0 | F53: 0 | G53: 0 | H53: N/A | I53: N/A | J53: N/A | K53: N/A | L53: N/A | M53: N/A | N53: =SUM(B53:M53) -> 0 | O53: 0 | P53: =O53/N53 -> #DIV/0!
B56: 40360 | C56: 40391 | D56: 6614787 | E56: 40452 | F56: 40483 | G56: 40513 | H56: 40544 | I56: 40575 | J56: 40603 | K56: 40634 | L56: 40664 | M56: 40695 | N56: Total | O56: 2010-2011 Price | P56: Price per unit
A57: EIS: Digests of Environmental Impact Statements
A58: Searches | B58: 26 | C58: 25 | D58: 95 | E58: 154 | F58: 164 | G58: 53 | H58: 65 | I58: 137 | J58: 214 | K58: 143 | L58: 58 | M58: 2 | N58: =SUM(B58:M58) -> 1136 | O58: 0 | P58: N/A
B61: 40360 | C61: 40391 | D61: 6614787 | E61: 40452 | F61: 40483 | G61: 40513 | H61: 40544 | I61: 40575 | J61: 40603 | K61: 40634 | L61: 40664 | M61: 40695 | N61: Total | O61: 2010-2011 Price | P61: Price per unit
A62: Ecology Abstracts
A63: Searches | B63: 0 | C63: 0 | D63: 0 | E63: 0 | F63: 0 | G63: 0 | H63: N/A | I63: N/A | J63: N/A | K63: N/A | L63: N/A | M63: N/A | N63: =SUM(B63:M63) -> 0 | O63: 0 | P63: N/A
B66: 40360 | C66: 40391 | D66: 6614787 | E66: 40452 | F66: 40483 | G66: 40513 | H66: 40544 | I66: 40575 | J66: 40603 | K66: 40634 | L66: 40664 | M66: 40695 | N66: Total | O66: 2010-2011 Price | P66: Price per unit
...

Sheet EBSCOhost
A1: EBSCOhost Databases
A2: 2010-2011
A4: COUNTER-Compliant?: | B4: Yes
B6: 40360 | C6: 40391 | D6: 6614787 | E6: 40452 | F6: 40483 | G6: 40513 | H6: 40544 | I6: 40575 | J6: 40603 | K6: 40634 | L6: 40664 | M6: 40695 | N6: Total | O6: 2010-2011 Price | P6: Price per unit
A7: Academic Search Complete (statewide database trial) | O7: Free
A8: Sessions | B8: 2635 | C8: 597 | D8: 2968 | E8: 8402 | F8: 9486 | G8: 3995 | H8: 889 | I8: 5213 | J8: 9379 | K8: 9135 | L8: 2289 | M8: 2027 | N8: =SUM(B8:M8) -> 57015
A9: Searches | B9: 9510 | C9: 1344 | D9: 10726 | E9: 32364 | F9: 30096 | G9: 12410 | H9: 2922 | I9: 19183 | J9: 31757 | K9: 23328 | L9: 6343 | M9: 6524 | N9: =SUM(B9:M9) -> 186507 | O9: 0 | P9: N/A
B12: 40360 | C12: 40391 | D12: 6614787 | E12: 40452 | F12: 40483 | G12: 40513 | H12: 40544 | I12: 40575 | J12: 40603 | K12: 40634 | L12: 40664 | M12: 40695 | N12: Total | O12: 2010-2011 Price | P12: Price per unit
A13: Academic Search Premier
A14: Sessions | B14: 1880 | C14: 783 | D14: 1823 | E14: 3719 | F14: 4331 | G14: 2363 | H14: 1139 | I14: 2852 | J14: 3775 | K14: 2865 | L14: 1479 | M14: 1233 | N14: =SUM(B14:M14) -> 28242
A15: Searches | B15: 3335 | C15: 625 | D15: 2434 | E15: 6877 | F15: 7663 | G15: 4857 | H15: 1002 | I15: 4443 | J15: 6357 | K15: 6302 | L15: 2533 | M15: 2118 | N15: =SUM(B15:M15) -> 48546 | O15: 0 | P15: =O15/N15 -> 0
B18: 40360 | C18: 40391 | D18: 6614787 | E18: 40452 | F18: 40483 | G18: 40513 | H18: 40544 | I18: 40575 | J18: 40603 | K18: 40634 | L18: 40664 | M18: 40695 | N18: Total | O18: 2010-2011 Price | P18: Price per unit
A19: America History & Life
A20: Sessions | B20: 87 | C20: 15 | D20: 102 | E20: 308 | F20: 357 | G20: 182 | H20: 37 | I20: 220 | J20: 366 | K20: 360 | L20: 149 | M20: 72 | N20: =SUM(B20:M20) -> 2255
A21: Searches | B21: 395 | C21: 67 | D21: 410 | E21: 1469 | F21: 1494 | G21: 951 | H21: 162 | I21: 953 | J21: 1503 | K21: 1901 | L21: 610 | M21: 312 | N21: =SUM(B21:M21) -> 10227 | O21: 0 | P21: =O21/N21 -> 0
B24: 40360 | C24: 40391 | D24: 6614787 | E24: 40452 | F24: 40483 | G24: 40513 | H24: 40544 | I24: 40575 | J24: 40603 | K24: 40634 | L24: 40664 | M24: 40695 | N24: Total | O24: 2010-2011 Price | P24: Price per unit
A25: CINAHL
A26: Sessions | B26: 577 | C26: 117 | D26: 839 | E26: 1735 | F26: 2461 | G26: 1016 | H26: 261 | I26: 1544 | J26: 2147 | K26: 3251 | L26: 316 | M26: 303 | N26: =SUM(B26:M26) -> 14567
A27: Searches | B27: 2051 | C27: 569 | D27: 4005 | E27: 8578 | F27: 13359 | G27: 5196 | H27: 1115 | I27: 7698 | J27: 11332 | K27: 16788 | L27: 1320 | M27: 1201 | N27: =SUM(B27:M27) -> 73212 | O27: 0 | P27: =O27/N27 -> 0
B30: 40360 | C30: 40391 | D30: 6614787 | E30: 40452 | F30: 40483 | G30: 40513 | H30: 40544 | I30: 40575 | J30: 40603 | K30: 40634 | L30: 40664 | M30: 40695 | N30: Total | O30: 2010-2011 Price | P30: Price per unit
A31: Communication Abstracts
A32: Sessions | B32: 74 | C32: 17 | D32: 166 | E32: 318 | F32: 446 | G32: 248 | H32: 42 | I32: 430 | J32: 408 | K32: 390 | L32: 112 | M32: 108 | N32: =SUM(B32:M32) -> 2759
A33: Searches | B33: 184 | C33: 50 | D33: 757 | E33: 1359 | F33: 1960 | G33: 1328 | H33: 245 | I33: 3264 | J33: 2030 | K33: 1927 | L33: 430 | M33: 493 | N33: =SUM(B33:M33) -> 14027 | O33: 0 | P33: =O33/N33 -> 0
B36: 40360 | C36: 40391 | D36: 6614787 | E36: 40452 | F36: 40483 | G36: 40513 | H36: 40544 | I36: 40575 | J36: 40603 | K36: 40634 | L36: 40664 | M36: 40695 | N36: Total | O36: 2010-2011 Price | P36: Price per unit
A37: Criminal Justice Abstracts
A38: Sessions | B38: 44 | C38: 9 | D38: 50 | E38: 122 | F38: 194 | G38: 109 | H38: 24 | I38: 119 | J38: 189 | K38: 174 | L38: 68 | M38: 42 | N38: =SUM(B38:M38) -> 1144
A39: Searches | B39: 165 | C39: 27 | D39: 236 | E39: 592 | F39: 874 | G39: 694 | H39: 110 | I39: 538 | J39: 748 | K39: 875 | L39: 308 | M39: 202 | N39: =SUM(B39:M39) -> 5369 | O39: 0 | P39: =O39/N39 -> 0
B42: 40360 | C42: 40391 | D42: 6614787 | E42: 40452 | F42: 40483 | G42: 40513 | H42: 40544 | I42: 40575 | J42: 40603 | K42: 40634 | L42: 40664 | M42: 40695 | N42: Total | O42: 2010-2011 Price | P42: Price per unit
A43: EconLit
A44: Sessions | B44: 146 | C44: 33 | D44: 128 | E44: 236 | F44: 306 | G44: 154 | H44: 68 | I44: 157 | J44: 232 | K44: 242 | L44: 111 | M44: 94 | N44: =SUM(B44:M44) -> 1907
A45: Searches | B45: 552 | C45: 125 | D45: 481 | E45: 1223 | F45: 1275 | G45: 939 | H45: 233 | I45: 676 | J45: 917 | K45: 1118 | L45: 444 | M45: 438 | N45: =SUM(B45:M45) -> 8421 | O45: 0 | P45: =O45/N45 -> 0
B48: 40360 | C48: 40391 | D48: 6614787 | E48: 40452 | F48: 40483 | G48: 40513 | H48: 40544 | I48: 40575 | J48: 40603 | K48: 40634 | L48: 40664 | M48: 40695 | N48: Total | O48: 2010-2011 Price | P48: Price per unit
A49: ERIC (free)
A50: Sessions | B50: 96 | C50: 9 | D50: 54 | E50: 150 | F50: 239 | G50: 124 | H50: 30 | I50: 144 | J50: 185 | K50: 177 | L50: 92 | M50: 68 | N50: =SUM(B50:M50) -> 1368
A51: Searches | B51: 423 | C51: 24 | D51: 253 | E51: 748 | F51: 1201 | G51: 854 | H51: 151 | I51: 683 | J51: 862 | K51: 1039 | L51: 522 | M51: 341 | N51: =SUM(B51:M51) -> 7101 | O51: 0 | P51: N/A
B54: 40360 | C54: 40391 | D54: 6614787 | E54: 40452 | F54: 40483 | G54: 40513 | H54: 40544 | I54: 40575 | J54: 40603 | K54: 40634 | L54: 40664 | M54: 40695 | N54: Total | O54: 2010-2011 Price | P54: Price per unit
A55: Film & Television Literature Index
A56: Sessions | B56: 66 | C56: 9 | D56: 60 | E56: 168 | F56: 207 | G56: 141 | H56: 35 | I56: 130 | J56: 144 | K56: 198 | L56: 81 | M56: 52 | N56: =SUM(B56:M56) -> 1291
A57: Searches | B57: 246 | C57: 29 | D57: 249 | E57: 798 | F57: 962 | G57: 875 | H57: 145 | I57: 564 | J57: 590 | K57: 1034 | L57: 327 | M57: 243 | N57: =SUM(B57:M57) -> 6062 | O57: 0 | P57: =O57/N57 -> 0
B60: 40360 | C60: 40391 | D60: 6614787 | E60: 40452 | F60: 40483 | G60: 40513 | H60: 40544 | I60: 40575 | J60: 40603 | K60: 40634 | L60: 40664 | M60: 40695 | N60: Total | O60: 2010-2011 Price | P60: Price per unit
...

Sheet Elsevier
A1: Elsevier
A2: 2010-2011
A4: COUNTER-Compliant?: | B4: No
B6: 40360 | C6: 40391 | D6: 6614787 | E6: 40452 | F6: 40483 | G6: 40513 | H6: 40544 | I6: 40575 | J6: 40603 | K6: 40634 | L6: 40664 | M6: 40695 | N6: Total | O6: 2010-2011 Price | P6: Price per unit
A7: Clinical Pharmacology
A8: Sessions | B8: N/A | C8: N/A | D8: N/A | E8: N/A | F8: N/A | G8: N/A | H8: N/A | I8: N/A | J8: N/A | K8: N/A | L8: N/A | M8: N/A | N8: =SUM(B8:M8) -> 0
A9: Searches | B9: N/A | C9: N/A | D9: N/A | E9: N/A | F9: N/A | G9: N/A | H9: N/A | I9: N/A | J9: N/A | K9: N/A | L9: N/A | M9: N/A | N9: =SUM(B9:M9) -> 0 | O9: 0 | P9: N/A
B11: 40360 | C11: 40391 | D11: 6614787 | E11: 40452 | F11: 40483 | G11: 40513 | H11: 40544 | I11: 40575 | J11: 40603 | K11: 40634 | L11: 40664 | M11: 40695 | N11: Total | O11: 2010-2011 Price | P11: Price per unit
A12: Encyclopedia of Ocean Sciences
A13: Requests for full text chapters | B13: 0 | C13: 0 | D13: 0 | E13: 0 | F13: 0 | G13: 0 | H13: 0 | I13: 0 | J13: 0 | K13: 0 | L13: 0 | M13: 0 | N13: =SUM(B13:M13) -> 0 | O13: 0 | P13: =O13/N13 -> #DIV/0!
B16: 40360 | C16: 40391 | D16: 6614787 | E16: 40452 | F16: 40483 | G16: 40513 | H16: 40544 | I16: 40575 | J16: 40603 | K16: 40634 | L16: 40664 | M16: 40695 | N16: Total | O16: 2010-2011 Price | P16: Price per unit
A17: Encyclopedia of Ocean Sciences, second ed. | O17: One-time purchase.
A18: Requests for full text chapters | B18: 1 | C18: 0 | D18: 14 | E18: 2 | F18: 9 | G18: 5 | H18: 1 | I18: 5 | J18: 11 | K18: 19 | L18: 0 | M18: 1 | N18: =SUM(B18:M18) -> 68 | O18: 0 | P18: =O18/N18 -> 0

Sheet EMBASE
A1: EMBASE
A2: 2010-2011
A4: COUNTER-Compliant?: | B4: No
B6: 40360 | C6: 40391 | D6: 6614787 | E6: 40452 | F6: 40483 | G6: 40513 | H6: 40544 | I6: 40575 | J6: 40603 | K6: 40634 | L6: 40664 | M6: 40695 | N6: Total | O6: 2010-2011 Price | P6: Price per unit
A7: EMBASE.com
A8: Sessions | B8: 172 | C8: 65 | D8: 207 | E8: 220 | F8: 191 | G8: 79 | H8: 67 | I8: 405 | J8: 578 | K8: 331 | L8: 154 | M8: 160 | N8: =SUM(B8:M8) -> 2629
A9: Searches | B9: 517 | C9: 143 | D9: 640 | E9: 647 | F9: 598 | G9: 184 | H9: 326 | I9: 2139 | J9: 2191 | K9: 1047 | L9: 499 | M9: 550 | N9: =SUM(B9:M9) -> 9481 | O9: 11528 | P9: =O9/N9 -> 1.2159055

Sheet FirstSearch
A1: FirstSearch
A2: 2010-2011
A4: COUNTER-Compliant?: | B4: Yes
B6: 40360 | C6: 40391 | D6: 6614787 | E6: 40452 | F6: 40483 | G6: 40513 | H6: 40544 | I6: 40575 | J6: 40603 | K6: 40634 | L6: 40664 | M6: 40695 | N6: Total | O6: 2010-2011 Price | P6: Price per unit
A7: Alternative Press Index
A8: Searches | B8: 0 | C8: 0 | D8: 0 | E8: 0 | F8: 0 | G8: 0 | H8: N/A | I8: N/A | J8: N/A | K8: N/A | L8: N/A | M8: N/A | N8: =SUM(B8:M8) -> 0 | O8: 0 | P8: N/A
B11: 40360 | C11: 40391 | D11: 6614787 | E11: 40452 | F11: 40483 | G11: 40513 | H11: 40544 | I11: 40575 | J11: 40603 | K11: 40634 | L11: 40664 | M11: 40695 | N11: Total | O11: 2010-2011 Price | P11: Price per unit
A12: Alternative Press Index Archive
A13: Searches | B13: 0 | C13: 0 | D13: 0 | E13: 0 | F13: 0 | G13: 0 | H13: N/A | I13: N/A | J13: N/A | K13: N/A | L13: N/A | M13: N/A | N13: =SUM(B13:M13) -> 0 | O13: 0 | P13: N/A
B16: 40360 | C16: 40391 | D16: 6614787 | E16: 40452 | F16: 40483 | G16: 40513 | H16: 40544 | I16: 40575 | J16: 40603 | K16: 40634 | L16: 40664 | M16: 40695 | N16: Total | O16: 2010-2011 Price | P16: Price per unit
A17: ArticleFirst
A18: Logons | B18: 101 | C18: 26 | D18: 103 | E18: 158 | F18: 168 | G18: 104 | H18: 46 | I18: 91 | J18: 121 | K18: 88 | L18: 48 | M18: 43 | N18: =SUM(B18:M18) -> 1097
A19: Searches | B19: 521 | C19: 43 | D19: 616 | E19: 274 | F19: 694 | G19: 669 | H19: 374 | I19: 302 | J19: 230 | K19: 484 | L19: 297 | M19: 473 | N19: =SUM(B19:M19) -> 4977 | O19: 0 | P19: N/A
A20: User Limit | B20: 2 | C20: 2 | D20: 2 | E20: 2 | F20: 2 | G20: 2 | H20: 2 | I20: 2 | J20: 2 | K20: 2 | L20: 2 | M20: 2
A21: Turnaways | B21: 5 | C21: 0 | D21: 8 | E21: 6 | F21: 2 | G21: 4 | H21: 0 | I21: 2 | J21: 4 | K21: 0 | L21: 0 | M21: 0 | N21: =SUM(B21:M21) -> 31
B24: 40360 | C24: 40391 | D24: 6614787 | E24: 40452 | F24: 40483 | G24: 40513 | H24: 40544 | I24: 40575 | J24: 40603 | K24: 40634 | L24: 40664 | M24: 40695 | N24: Total | O24: 2010-2011 Price | P24: Price per unit
A25: Clase and Periodica
A26: Logons | B26: 6 | C26: 0 | D26: 4 | E26: 13 | F26: 11 | G26: 20 | H26: 5 | I26: 5 | J26: 7 | K26: 16 | L26: 6 | M26: 4 | N26: =SUM(B26:M26) -> 97
A27: Searches | B27: 3 | C27: 0 | D27: 3 | E27: 11 | F27: 14 | G27: 26 | H27: 1 | I27: 5 | J27: 10 | K27: 18 | L27: 6 | M27: 1 | N27: =SUM(B27:M27) -> 98 | O27: 0 | P27: N/A
A28: User Limit | B28: 2 | C28: 0 | D28: 2 | E28: 2 | F28: 2 | G28: 2 | H28: 2 | I28: 2 | J28: 2 | K28: 2 | L28: 2 | M28: 2
A29: Turnaways | B29: 0 | C29: 0 | D29: 0 | E29: 0 | F29: 0 | G29: 1 | H29: 0 | I29: 0 | J29: 0 | K29: 0 | L29: 0 | M29: 0 | N29: =SUM(B29:M29) -> 1
B32: 40360 | C32: 40391 | D32: 6614787 | E32: 40452 | F32: 40483 | G32: 40513 | H32: 40544 | I32: 40575 | J32: 40603 | K32: 40634 | L32: 40664 | M32: 40695 | N32: Total | O32: 2010-2011 Price | P32: Price per unit
A33: ERIC (free)
A34: Logons | B34: 113 | C34: 14 | D34: 34 | E34: 88 | F34: 96 | G34: 29 | H34: 13 | I34: 51 | J34: 73 | K34: 60 | L34: 19 | M34: 15 | N34: =SUM(B34:M34) -> 605
A35: Searches | B35: 196 | C35: 11 | D35: 48 | E35: 189 | F35: 222 | G35: 29 | H35: 18 | I35: 166 | J35: 149 | K35: 139 | L35: 40 | M35: 22 | N35: =SUM(B35:M35) -> 1229 | O35: 0 | P35: N/A
A36: User Limit | B36: 2 | C36: 2 | D36: 2 | E36: 2 | F36: 2 | G36: 2 | H36: 2 | I36: 2 | J36: 2 | K36: 2 | L36: 2 | M36: 2
A37: Turnaways | B37: 10 | C37: 2 | D37: 1 | E37: 5 | F37: 2 | G37: 0 | H37: 0 | I37: 1 | J37: 1 | K37: 4 | L37: 0 | M37: 0 | N37: =SUM(B37:M37) -> 26
B40: 40360 | C40: 40391 | D40: 6614787 | E40: 40452 | F40: 40483 | G40: 40513 | H40: 40544 | I40: 40575 | J40: 40603 | K40: 40634 | L40: 40664 | M40: 40695 | N40: Total | O40: 2010-2011 Price | P40: Price per unit
A41: GEOBASE
A42: Searches | B42: 20 | C42: 1 | D42: 1 | E42: 3 | F42: 0 | G42: 3 | H42: 4 | I42: 2 | J42: 1 | K42: 1 | L42: 3 | M42: 5 | N42: =SUM(B42:M42) -> 44 | O42: 0 | P42: N/A
B45: 40360 | C45: 40391 | D45: 6614787 | E45: 40452 | F45: 40483 | G45: 40513 | H45: 40544 | I45: 40575 | J45: 40603 | K45: 40634 | L45: 40664 | M45: 40695 | N45: Total | O45: 2010-2011 Price | P45: Price per unit
A46: GPO Monthly Catalog
A47: Logons | B47: 6 | C47: 3 | D47: 5 | E47: 5 | F47: 14 | G47: 4 | H47: 0 | I47: 7 | J47: 8 | K47: 3 | L47: 2 | M47: 0 | N47: =SUM(B47:M47) -> 57
A48: Searches | B48: 5 | C48: 2 | D48: 1 | E48: 7 | F48: 23 | G48: 9 | H48: 0 | I48: 5 | J48: 12 | K48: 2 | L48: 9 | M48: 0 | N48: =SUM(B48:M48) -> 75 | O48: 0 | P48: N/A
A49: User Limit | B49: 2 | C49: 2 | D49: 2 | E49: 2 | F49: 2 | G49: 2 | H49: 0 | I49: 2 | J49: 2 | K49: 2 | L49: 2 | M49: 0
A50: Turnaways | B50: 0 | C50: 0 | D50: 1 | E50: 0 | F50: 0 | G50: 0 | H50: 0 | I50: 0 | J50: 0 | K50: 0 | L50: 0 | M50: 0 | N50: =SUM(B50:M50) -> 1
B53: 40360 | C53: 40391 | D53: 6614787 | E53: 40452 | F53: 40483 | G53: 40513 | H53: 40544 | I53: 40575 | J53: 40603 | K53: 40634 | L53: 40664 | M53: 40695 | N53: Total | O53: 2010-2011 Price | P53: Price per unit
A54: MEDLINE (free)
A55: Logons | B55: 205 | C55: 72 | D55: 183 | E55: 381 | F55: 349 | G55: 160 | H55: 166 | I55: 362 | J55: 403 | K55: 461 | L55: 130 | M55: 166 | N55: =SUM(B55:M55) -> 3038
A56: Searches | B56: 457 | C56: 151 | D56: 500 | E56: 742 | F56: 576 | G56: 254 | H56: 533 | I56: 688 | J56: 782 | K56: 717 | L56: 248 | M56: 227 | N56: =SUM(B56:M56) -> 5875 | O56: 0 | P56: N/A
...

Sheet Greenwood
A1: Greenwood Press
A2: 2010-2011
A4: COUNTER-compliant? | B4: Yes (R2)
B6: 40360 | C6: 40391 | D6: 6614787 | E6: 40452 | F6: 40483 | G6: 40513 | H6: 40544 | I6: 40575 | J6: 40603 | K6: 40634 | L6: 40664 | M6: 40695 | N6: Total | O6: 2010-2011 Price | P6: Price per unit
A7: ARBA Online
A8: Searches Run | B8: 0 | C8: 0 | D8: 0 | E8: 0 | F8: 0 | G8: 0 | H8: 0 | I8: 0 | J8: 0 | K8: 0 | L8: 0 | M8: 0 | N8: =SUM(B8:M8) -> 0 | O8: 0 | P8: =O8/N8 -> #DIV/0!
A9: Sessions Run | B9: 1 | C9: 0 | D9: 0 | E9: 1 | F9: 0 | G9: 2 | H9: 1 | I9: 0 | J9: 0 | K9: 4 | L9: 0 | M9: 0 | N9: =SUM(B9:M9) -> 9

Sheet InfoTrac
A1: InfoTRAC
A2: 2010-2011
A4: COUNTER-Compliant?: | B4: Yes
B6: 40360 | C6: 40391 | D6: 6614787 | E6: 40452 | F6: 40483 | G6: 40513 | H6: 40544 | I6: 40575 | J6: 40603 | K6: 40634 | L6: 40664 | M6: 40695 | N6: Total | O6: 2010-2011 Price | P6: Price per unit
A7: Literature Resource Center | O7: Access fee only.
A8: Searches Run | B8: 162 | C8: 85 | D8: 421 | E8: 527 | F8: 974 | G8: 1013 | H8: 242 | I8: 406 | J8: 772 | K8: 1082 | L8: 407 | M8: 154 | N8: =SUM(B8:M8) -> 6245 | O8: 2105 | P8: =O8/N8 -> 0.33706966
A9: Sessions | B9: 69 | C9: 28 | D9: 123 | E9: 182 | F9: 256 | G9: 251 | H9: 81 | I9: 145 | J9: 219 | K9: 246 | L9: 123 | M9: 42 | N9: =SUM(B9:M9) -> 1765
A10: Turnaways | B10: 0 | C10: 0 | D10: 0 | E10: 0 | F10: 0 | G10: 0 | H10: 0 | I10: 0 | J10: 0 | K10: 0 | L10: 0 | M10: 0 | N10: =SUM(B10:M10) -> 0
A11: Successful Full-Text Article Requests | B11: 65 | C11: 65 | D11: 92 | E11: 146 | F11: 282 | G11: 284 | H11: 115 | I11: 126 | J11: 310 | K11: 360 | L11: 289 | M11: 81 | N11: =SUM(B11:M11) -> 2215

Sheet ICPSR
A1: ICPSR
A2: 2010-2011
A4: COUNTER-Compliant?: | B4: No
B6: 40360 | C6: 40391 | D6: 6614787 | E6: 40452 | F6: 40483 | G6: 40513 | H6: 40544 | I6: 40575 | J6: 40603 | K6: 40634 | L6: 40664 | M6: 40695 | N6: Total | O6: 2010-2011 Price | P6: Price per unit
A7: ICPSR
A8: Unique files downloaded | B8: 29 | C8: 0 | D8: 5 | E8: 19 | F8: 57 | G8: 16 | H8: 0 | I8: 2 | J8: 0 | K8: 7 | L8: 3 | M8: 0 | N8: =SUM(B8:M8) -> 138 | O8: 15000 | P8: =O8/N8 -> 108.69565
A9: Total files downloaded | B9: 29 | C9: 0 | D9: 7 | E9: 28 | F9: 64 | G9: 32 | H9: 0 | I9: 4 | J9: 0 | K9: 7 | L9: 3 | M9: 0 | N9: =SUM(B9:M9) -> 174
A10: Members-only files downloaded | B10: 13 | C10: 0 | D10: 7 | E10: 15 | F10: 42 | G10: 32 | H10: 0 | I10: 0 | J10: 0 | K10: 7 | L10: 3 | M10: 0 | N10: =SUM(B10:M10) -> 119
A11: Unique datasets downloaded | B11: 5 | C11: 0 | D11: 3 | E11: 13 | F11: 13 | G11: 8 | H11: 0 | I11: 1 | J11: 0 | K11: 3 | L11: 1 | M11: 0 | N11: =SUM(B11:M11) -> 47
A12: Total datasets downloaded | B12: 5 | C12: 0 | D12: 3 | E12: 13 | F12: 13 | G12: 8 | H12: 0 | I12: 1 | J12: 0 | K12: 3 | L12: 1 | M12: 0 | N12: =SUM(B12:M12) -> 47
A13: Members-only datasets downloaded | B13: 1 | C13: 0 | D13: 3 | E13: 2 | F13: 9 | G13: 8 | H13: 0 | I13: 0 | J13: 0 | K13: 3 | L13: 1 | M13: 0 | N13: =SUM(B13:M13) -> 27
A14: Unique studies downloaded | B14: 3 | C14: 0 | D14: 2 | E14: 4 | F14: 5 | G14: 1 | H14: 0 | I14: 1 | J14: 0 | K14: 3 | L14: 1 | M14: 0 | N14: =SUM(B14:M14) -> 20
A15: Total studies downloaded | B15: 3 | C15: 0 | D15: 2 | E15: 4 | F15: 5 | G15: 1 | H15: 0 | I15: 1 | J15: 0 | K15: 3 | L15: 1 | M15: 0 | N15: =SUM(B15:M15) -> 20
A16: Members-only studies downloaded | B16: 1 | C16: 0 | D16: 2 | E16: 2 | F16: 3 | G16: 1 | H16: 0 | I16: 0 | J16: 0 | K16: 3 | L16: 1 | M16: 0 | N16: =SUM(B16:M16) -> 13
A17: Unique users | B17: 1 | C17: 0 | D17: 1 | E17: 3 | F17: 3 | G17: 1 | H17: 0 | I17: 1 | J17: 0 | K17: 2 | L17: 1 | M17: 0 | N17: =SUM(B17:M17) -> 13
A20: Median for other institutions in Classification Category
A21: Members-only files downloaded | B21: 0 | C21: 0 | D21: 0 | E21: 0 | F21: 0 | G21: 0 | H21: 0 | I21: 0 | J21: 0 | K21: 0 | L21: 0 | M21: 0 | N21: 3039
A22: Unique datasets downloaded | B22: 0 | C22: 0 | D22: 0 | E22: 0 | F22: 0 | G22: 0 | H22: 0 | I22: 0 | J22: 0 | K22: 0 | L22: 0 | M22: 0 | N22: 1157
A23: Total datasets downloaded | B23: 0 | C23: 0 | D23: 0 | E23: 0 | F23: 0 | G23: 0 | H23: 0 | I23: 0 | J23: 0 | K23: 0 | L23: 0 | M23: 0 | N23: 1553
A24: Members-only datasets downloaded | B24: 0 | C24: 0 | D24: 0 | E24: 0 | F24: 0 | G24: 0 | H24: 0 | I24: 0 | J24: 0 | K24: 0 | L24: 0 | M24: 0 | N24: 758
A25: Unique studies downloaded | B25: 0 | C25: 0 | D25: 0 | E25: 0 | F25: 0 | G25: 0 | H25: 0 | I25: 0 | J25: 0 | K25: 0 | L25: 0 | M25: 0 | N25: 197
A26: Total studies downloaded | B26: 0 | C26: 0 | D26: 0 | E26: 0 | F26: 0 | G26: 0 | H26: 0 | I26: 0 | J26: 0 | K26: 0 | L26: 0 | M26: 0 | N26: 322
A27: Members-only studies downloaded | B27: 0 | C27: 0 | D27: 0 | E27: 0 | F27: 0 | G27: 0 | H27: 0 | I27: 0 | J27: 0 | K27: 0 | L27: 0 | M27: 0 | N27: 148
A28: Unique users | B28: 0 | C28: 0 | D28: 0 | E28: 0 | F28: 0 | G28: 0 | H28: 0 | I28: 0 | J28: 0 | K28: 0 | L28: 0 | M28: 0 | N28: 66
A30: Note: Subscription started November 19, 2009. Price was pro-rated.

Sheet ITER
A1: ITER Databases
A2: 2010-2011
A4: COUNTER-Compliant?: | B4: ?
B6: 40360 | C6: 40391 | D6: 6614787 | E6: 40452 | F6: 40483 | G6: 40513 | H6: 40544 | I6: 40575 | J6: 40603 | K6: 40634 | L6: 40664 | M6: 40695 | N6: Total | O6: 2010-2011 Price | P6: Price per unit
A7: Baptisteria Sacra Index | O7: Free
A8: Sessions | B8: N/A | C8: N/A | D8: N/A | E8: N/A | F8: N/A | G8: N/A | H8: N/A | I8: N/A | J8: N/A | K8: N/A | L8: N/A | M8: N/A | N8: =SUM(B8:M8) -> 0
A9: Searches | B9: N/A | C9: N/A | D9: N/A | E9: N/A | F9: N/A | G9: N/A | H9: N/A | I9: N/A | J9: N/A | K9: N/A | L9: N/A | M9: N/A | N9: =SUM(B9:M9) -> 0 | O9: 0 | P9: =O9/N9 -> #DIV/0!
B12: 40360 | C12: 40391 | D12: 6614787 | E12: 40452 | F12: 40483 | G12: 40513 | H12: 40544 | I12: 40575 | J12: 40603 | K12: 40634 | L12: 40664 | M12: 40695 | N12: Total | O12: 2010-2011 Price | P12: Price per unit
A13: ITER Bibliography
A14: Sessions | B14: 0 | C14: 2 | D14: 42 | E14: 47 | F14: 64 | G14: 416 | H14: 5 | I14: 11 | J14: 25 | K14: 13 | L14: 12 | M14: 3 | N14: =SUM(B14:M14) -> 640
A15: Searches | B15: 0 | C15: 0 | D15: 126 | E15: 210 | F15: 296 | G15: 93 | H15: 13 | I15: 44 | J15: 89 | K15: 40 | L15: 27 | M15: 3 | N15: =SUM(B15:M15) -> 941 | O15: 545.4 | P15: =O15/N15 -> 0.57959617
B18: 40360 | C18: 40391 | D18: 6614787 | E18: 40452 | F18: 40483 | G18: 40513 | H18: 40544 | I18: 40575 | J18: 40603 | K18: 40634 | L18: 40664 | M18: 40695 | N18: Total | O18: 2010-2011 Price | P18: Price per unit
A19: Gateway to the Middle Ages
A20: Sessions | B20: N/A | C20: N/A | D20: N/A | E20: N/A | F20: N/A | G20: N/A | H20: N/A | I20: N/A | J20: N/A | K20: N/A | L20: N/A | M20: N/A | N20: =SUM(B20:M20) -> 0
A21: Searches | B21: N/A | C21: N/A | D21: N/A | E21: N/A | F21: N/A | G21: N/A | H21: N/A | I21: N/A | J21: N/A | K21: N/A | L21: N/A | M21: N/A | N21: =SUM(B21:M21) -> 0 | O21: 0 | P21: =O21/N21 -> #DIV/0!
B24: 40360 | C24: 40391 | D24: 6614787 | E24: 40452 | F24: 40483 | G24: 40513 | H24: 40544 | I24: 40575 | J24: 40603 | K24: 40634 | L24: 40664 | M24: 40695 | N24: Total | O24: 2010-2011 Price | P24: Price per unit
A25: Medici Archives Project | O25: Free
A26: Sessions | B26: N/A | C26: N/A | D26: N/A | E26: N/A | F26: N/A | G26: N/A | H26: N/A | I26: N/A | J26: N/A | K26: N/A | L26: N/A | M26: N/A | N26: =SUM(B26:M26) -> 0
A27: Searches | B27: N/A | C27: N/A | D27: N/A | E27: N/A | F27: N/A | G27: N/A | H27: N/A | I27: N/A | J27: N/A | K27: N/A | L27: N/A | M27: N/A | N27: =SUM(B27:M27) -> 0 | O27: 0 | P27: =O27/N27 -> #DIV/0!

Sheet JSTOR
A1: JSTOR
A2: 2010-2011
A4: COUNTER-compliant: Yes
B6: 40360 | C6: 40391 | D6: 6614787 | E6: 40452 | F6: 40483 | G6: 40513 | H6: 40544 | I6: 40575 | J6: 40603 | K6: 40634 | L6: 40664 | M6: 40695 | N6: Total | O6: 2010-2011 Price | P6: Price per unit
A7: JSTOR
A8: Sessions | B8: 2378 | C8: 902 | D8: 3248 | E8: 5673 | F8: 7947 | G8: 6019 | H8: 1500 | I8: 5271 | J8: 6532 | K8: 8607 | L8: 4514 | M8: 1715 | N8: =SUM(B8:M8) -> 54306
A9: Searches | B9: 3339 | C9: 882 | D9: 4491 | E9: 9690 | F9: 16186 | G9: 9976 | H9: 2158 | I9: 8144 | J9: 11260 | K9: 13432 | L9: 6950 | M9: 2162 | N9: =SUM(B9:M9) -> 88670 | O9: 0 | P9: =O9/N9 -> 0
A10: Turnaways | B10: N/A | C10: N/A | D10: N/A | E10: N/A | F10: N/A | G10: N/A | H10: N/A | I10: N/A | J10: N/A | K10: N/A | L10: N/A | M10: N/A | N10: =SUM(B10:M10) -> 0

Sheet KCDL
A1: KCDL Online
A2: 2010-2011
A4: COUNTER-Compliant? | B4: No
B6: 40360 | C6: 40391 | D6: 6614787 | E6: 40452 | F6: 40483 | G6: 40513 | H6: 40544 | I6: 40575 | J6: 40603 | K6: 40634 | L6: 40664 | M6: 40695 | N6: Total | O6: 2010-2011 Price | P6: Price per unit
A7: KCDL Online
A8: Searches | B8: 5 | C8: 0 | D8: 0 | E8: 25 | F8: 12 | G8: 5 | H8: 3 | I8: 6 | J8: 1 | K8: 18 | L8: 0 | M8: 3 | N8: =SUM(B8:M8) -> 78 | O8: 0 | P8: =O8/N8 -> 0
A9: Web Pages Delivered | B9: 12 | C9: 1 | D9: 4 | E9: 64 | F9: 32 | G9: 11 | H9: 7 | I9: 10 | J9: 13 | K9: 28 | L9: 1 | M9: 18 | N9: =SUM(B9:M9) -> 201

Sheet Lexi-Comp
A1: Lexi-Comp
A2: 2010-2011
A4: COUNTER-Compliant?: | B4: No
B6: 40360 | C6: 40391 | D6: 6614787 | E6: 40452 | F6: 40483 | G6: 40513 | H6: 40544 | I6: 40575 | J6: 40603 | K6: 40634 | L6: 40664 | M6: 40695 | N6: Total | O6: 2009-2010 Price | P6: Price per unit
A7: Lexi-Comp Online
A8: Logins | B8: 771 | C8: 561 | D8: 689 | E8: 859 | F8: 755 | G8: 510 | H8: 802 | I8: 1062 | J8: 1366 | K8: 877 | L8: 534 | M8: 1032 | N8: =SUM(B8:M8) -> 9818 | O8: 0 | P8: N/A
A9: Searches | B9: 1765 | C9: 1292 | D9: 1568 | E9: 2044 | F9: 1465 | G9: 1375 | H9: 1840 | I9: 2134 | J9: 2396 | K9: 1658 | L9: 127 | M9: 3073 | N9: =SUM(B9:M9) -> 20737 | O9: 0 | P9: N/A
A10: Documents Retrieved | B10: 2527 | C10: 1768 | D10: 2046 | E10: 2869 | F10: 2045 | G10: 1594 | H10: 2519 | I10: 2999 | J10: 3142 | K10: 2241 | L10: 1675 | M10: 4108 | N10: =SUM(B10:M10) -> 29533 | O10: 0 | P10: N/A

Sheet LexisNexis
A1: LexisNexis
A2: 2010-2011
A4: COUNTER-Compliant?: | B4: Yes
B6: 40360 | C6: 40391 | D6: 6614787 | E6: 40452 | F6: 40483 | G6: 40513 | H6: 40544 | I6: 40575 | J6: 40603 | K6: 40634 | L6: 40664 | M6: 40695 | N6: Total | O6: 2010-2011 Price | P6: Price per unit
A7: Academic
A8: Sessions | B8: 1379 | C8: 620 | D8: 1680 | E8: 2891 | F8: 2891 | G8: 1893 | H8: 810 | I8: 1834 | J8: 4160 | K8: 4868 | L8: 1222 | M8: 539 | N8: =SUM(B8:M8) -> 24787
A9: Searches | B9: 1116 | C9: 539 | D9: 1538 | E9: 2521 | F9: 2476 | G9: 1770 | H9: 778 | I9: 1426 | J9: 3634 | K9: 4394 | L9: 1058 | M9: 560 | N9: =SUM(B9:M9) -> 21810 | O9: 0 | P9: =O9/N9 -> 0
B12: 40360 | C12: 40391 | D12: 6614787 | E12: 40452 | F12: 40483 | G12: 40513 | H12: 40544 | I12: 40575 | J12: 40603 | K12: 40634 | L12: 40664 | M12: 40695 | N12: Total | O12: 2010-2011 Price | P12: Price per unit
A13: Congressional
A14: Sessions | B14: 6 | C14: 5 | D14: 13 | E14: 16 | F14: 35 | G14: 19 | H14: 4 | I14: 17 | J14: 48 | K14: 36 | L14: 21 | M14: 2 | N14: =SUM(B14:M14) -> 222
A15: Searches | B15: 13 | C15: 6 | D15: 18 | E15: 33 | F15: 57 | G15: 43 | H15: 7 | I15: 41 | J15: 165 | K15: 87 | L15: 74 | M15: 2 | N15: =SUM(B15:M15) -> 546 | O15: 0 | P15: =O15/N15 -> 0

Sheet MathSciNet
A1: MathSciNet
A2: 2010-2011
A4: COUNTER-Compliant?: | B4: No
B6: 40360 | C6: 40391 | D6: 6614787 | E6: 40452 | F6: 40483 | G6: 40513 | H6: 40544 | I6: 40575 | J6: 40603 | K6: 40634 | L6: 40664 | M6: 40695 | N6: Total | O6: 2010-2011 Price | P6: Price per unit
A7: MathSciNet
A8: Sessions | B8: 269 | C8: 202 | D8: 513 | E8: 509 | F8: 692 | G8: 697 | H8: 814 | I8: 482 | J8: 729 | K8: 484 | L8: 547 | M8: 446 | N8: =SUM(B8:M8) -> 6384
A9: Queries | B9: 533 | C9: 534 | D9: 901 | E9: 1024 | F9: 1325 | G9: 1304 | H9: 1496 | I9: 814 | J9: 1196 | K9: 1079 | L9: 984 | M9: 1004 | N9: =SUM(B9:M9) -> 12194 | O9: 7906.3 | P9: =O9/N9 -> 0.64837625

Sheet Mergent
A1: Mergent
A2: 2010-2011
A4: COUNTER-Compliant?: | B4: No
B6: 40360 | C6: 40391 | D6: 6614787 | E6: 40452 | F6: 40483 | G6: 40513 | H6: 40544 | I6: 40575 | J6: 40603 | K6: 40634 | L6: 40664 | M6: 40695 | N6: Total | O6: 2010-2011 Price | P6: Price per unit
A7: MergentOnline
A8: Logins | B8: 11 | C8: 17 | D8: 25 | E8: 27 | F8: 69 | G8: 58 | H8: 14 | I8: 31 | J8: 73 | K8: 84 | L8: 46 | M8: 17 | N8: =SUM(B8:M8) -> 472
A9: Searched | B9: 42 | C9: 38 | D9: 48 | E9: 47 | F9: 163 | G9: 90 | H9: 38 | I9: 128 | J9: 393 | K9: 249 | L9: 139 | M9: 87 | N9: =SUM(B9:M9) -> 1462 | O9: 0 | P9: =O9/N9 -> 0
A10: Companies Viewed | B10: 21 | C10: 7 | D10: 21 | E10: 28 | F10: 95 | G10: 69 | H10: 6 | I10: 34 | J10: 186 | K10: 1624 | L10: 124 | M10: 39 | N10: =SUM(B10:M10) -> 2254 | O10: 0 | P10: =O10/N10 -> 0
B13: 40360 | C13: 40391 | D13: 6614787 | E13: 40452 | F13: 40483 | G13: 40513 | H13: 40544 | I13: 40575 | J13: 40603 | K13: 40634 | L13: 40664 | M13: 40695 | N13: Total | O13: 2010-2011 Price | P13: Price per unit
A14: Mergent WebReports
A15: Logins | B15: N/A | C15: N/A | D15: N/A | E15: N/A | F15: N/A | G15: N/A | H15: N/A | I15: N/A | J15: N/A | K15: N/A | L15: N/A | M15: N/A | N15: =SUM(B15:M15) -> 0
A16: Searched | B16: N/A | C16: N/A | D16: N/A | E16: N/A | F16: N/A | G16: N/A | H16: N/A | I16: N/A | J16: N/A | K16: N/A | L16: N/A | M16: N/A | N16: =SUM(B16:M16) -> 0 | O16: 1000 | P16: N/A
A17: Companies Viewed | B17: N/A | C17: N/A | D17: N/A | E17: N/A | F17: N/A | G17: N/A | H17: N/A | I17: N/A | J17: N/A | K17: N/A | L17: N/A | M17: N/A | N17: =SUM(B17:M17) -> 0 | P17: N/A
A18: Time in database | B18: N/A | C18: N/A | D18: N/A | E18: N/A | F18: N/A | G18: N/A | H18: N/A | I18: N/A | J18: N/A | K18: N/A | L18: N/A | M18: N/A | N18: —
A21: Mergent WebReports purchased 4/2010.

Sheet netLibrary
A1: NetLibrary
A2: 2010-2011
A4: COUNTER-Compliant?: | B4: No
B6: 40360 | C6: 40391 | D6: 6614787 | E6: 40452 | F6: 40483 | G6: 40513 | H6: 40544 | I6: 40575 | J6: 40603 | K6: 40634 | L6: 40664 | M6: 40695 | N6: Total | O6: 2010-2011 Price | P6: Price per unit
A7: NetLibrary
A8: Total Accesses | B8: 31 | C8: 6 | D8: 36 | E8: 77 | F8: 67 | G8: 21 | H8: 21 | I8: 33 | J8: 26 | K8: 32 | L8: 24 | M8: 48 | N8: =SUM(B8:M8) -> 422 | O8: 0 | P8: N/A
A9: Turnaways | B9: 37 | C9: 0 | D9: 12 | E9: 3 | F9: 7 | G9: 0 | H9: 5 | I9: 1 | J9: 0 | K9: 17 | L9: 10 | M9: 22 | N9: =SUM(B9:M9) -> 114
A12: Note: We have 4,478 shared titles

Sheet Newsbank
A1: Newsbank (Readex)
A2: 2010-2011
A4: COUNTER-Compliant?: | B4: Yes (R2)
B6: 40360 | C6: 40391 | D6: 6614787 | E6: 40452 | F6: 40483 | G6: 40513 | H6: 40544 | I6: 40575 | J6: 40603 | K6: 40634 | L6: 40664 | M6: 40695 | N6: Total | O6: 2009-2010 Price | P6: Price per unit
A7: American State Papers, 1789-1838 | O7: Access fee only
A8: Searches run | B8: 3 | C8: 0 | D8: 2 | E8: 0 | F8: 1 | G8: 0 | H8: 0 | I8: 0 | J8: 0 | K8: 0 | L8: 6 | M8: 0 | N8: =SUM(B8:M8) -> 12
A9: Sessions | B9: N/A | C9: N/A | D9: N/A | E9: N/A | F9: N/A | G9: N/A | H9: N/A | I9: N/A | J9: N/A | K9: N/A | L9: N/A | M9: N/A | N9: N/A
B12: 40360 | C12: 40391 | D12: 6614787 | E12: 40452 | F12: 40483 | G12: 40513 | H12: 40544 | I12: 40575 | J12: 40603 | K12: 40634 | L12: 40664 | M12: 40695 | N12: Total | O12: 2009-2010 Price | P12: Price per unit
A13: Serial Set Maps | O13: Access fee only
A14: Searches run | B14: 0 | C14: 12 | D14: 0 | E14: 0 | F14: 0 | G14: 1 | H14: 0 | I14: 15 | J14: 0 | K14: 0 | L14: 2 | M14: 0 | N14: =SUM(B14:M14) -> 30
A15: Sessions | B15: N/A | C15: N/A | D15: N/A | E15: N/A | F15: N/A | G15: N/A | H15: N/A | I15: N/A | J15: N/A | K15: N/A | L15: N/A | M15: N/A | N15: N/A
B18: 40360 | C18: 40391 | D18: 6614787 | E18: 40452 | F18: 40483 | G18: 40513 | H18: 40544 | I18: 40575 | J18: 40603 | K18: 40634 | L18: 40664 | M18: 40695 | N18: Total | O18: 2010-2011 Price | P18: Price per unit
A19: U.S. Congressional Serial Set 1817-1994 | O19: Access fee only
A20: Searches run | B20: 1 | C20: 0 | D20: 32 | E20: 6 | F20: 0 | G20: 0 | H20: 0 | I20: 29 | J20: 11 | K20: 9 | L20: 3 | M20: 14 | N20: =SUM(B20:M20) -> 105
A21: Sessions | B21: N/A | C21: N/A | D21: N/A | E21: N/A | F21: N/A | G21: N/A | H21: N/A | I21: N/A | J21: N/A | K21: N/A | L21: N/A | M21: N/A | N21: N/A
B24: 40360 | C24: 40391 | D24: 6614787 | E24: 40452 | F24: 40483 | G24: 40513 | H24: 40544 | I24: 40575 | J24: 40603 | K24: 40634 | L24: 40664 | M24: 40695 | N24: Total | O24: 2010-2011 Price | P24: Price per unit
A25: Total for Service Newsbank | O25: Access fee only
A26: Searches run | B26: 4 | C26: 12 | D26: 34 | E26: 6 | F26: 1 | G26: 6 | H26: 0 | I26: 239 | J26: 253 | K26: 14 | L26: 11 | M26: 19 | N26: =SUM(B26:M26) -> 599
A27: Sessions | B27: 20 | C27: 13 | D27: 45 | E27: 9 | F27: 42 | G27: 22 | H27: 6 | I27: 127 | J27: 247 | K27: 33 | L27: 18 | M27: 21 | N27: =SUM(B27:M27) -> 603

Sheet OVID
A1: OvidSP
A2: 2010-2011
A4: COUNTER-Compliant?: | B4: Yes (R3)
B6: 40360 | C6: 40391 | D6: 6614787 | E6: 40452 | F6: 40483 | G6: 40513 | H6: 40544 | I6: 40575 | J6: 40603 | K6: 40634 | L6: 40664 | M6: 40695 | N6: Total | O6: 2010-2011 Price | P6: Price per unit
A7: Biological Abstracts
A8: Total Searches Run | B8: 0 | C8: 0 | D8: 1 | E8: 0 | F8: 0 | G8: 12 | H8: N/A | I8: N/A | J8: 4 | K8: 0 | L8: 0 | M8: 0 | N8: =SUM(B8:M8) -> 17 | O8: N/A | P8: N/A
A9: Total Sessions | B9: 0 | C9: 0 | D9: 1 | E9: 0 | F9: 1 | G9: 3 | H9: N/A | I9: N/A | J9: 2 | K9: 0 | L9: 0 | M9: 0 | N9: =SUM(B9:M9) -> 7
A10: Turnaways | B10: 0 | C10: 0 | D10: 0 | E10: 0 | F10: 0 | G10: 0 | H10: 0 | I10: 0 | J10: 0 | K10: 0 | L10: 0 | M10: 0 | N10: =SUM(B10:M10) -> 0
B13: 40360 | C13: 40391 | D13: 6614787 | E13: 40452 | F13: 40483 | G13: 40513 | H13: 40544 | I13: 40575 | J13: 40603 | K13: 40634 | L13: 40664 | M13: 40695 | N13: Total | O13: 2010-2011 Price | P13: Price per unit
A14: BIOSIS Previews
A15: Total Searches Run | B15: N/A | C15: N/A | D15: N/A | E15: N/A | F15: N/A | G15: N/A | H15: N/A | I15: N/A | J15: N/A | K15: N/A | L15: N/A | M15: N/A | N15: =SUM(B15:M15) -> 0 | O15: N/A | P15: N/A
A16: Total Sessions | B16: N/A | C16: N/A | D16: N/A | E16: N/A | F16: N/A | G16: N/A | H16: N/A | I16: N/A | J16: N/A | K16: N/A | L16: N/A | M16: N/A | N16: =SUM(B16:M16) -> 0
A17: Turnaways | B17: N/A | C17: N/A | D17: N/A | E17: N/A | F17: N/A | G17: N/A | H17: N/A | I17: N/A | J17: N/A | K17: N/A | L17: N/A | M17: N/A | N17: =SUM(B17:M17) -> 0
B20: 40360 | C20: 40391 | D20: 6614787 | E20: 40452 | F20: 40483 | G20: 40513 | H20: 40544 | I20: 40575 | J20: 40603 | K20: 40634 | L20: 40664 | M20: 40695 | N20: Total | O20: 2010-2011 Price | P20: Price per unit
A21: Ovid MEDLINE (free) | O21: Free
A22: Total Searches Run | B22: 0 | C22: 0 | D22: 0 | E22: 0 | F22: 1 | G22: 12 | H22: 0 | I22: 0 | J22: 4 | K22: 0 | L22: 0 | M22: 0 | N22: =SUM(B22:M22) -> 17 | O22: N/A | P22: N/A
A23: Total Sessions | B23: 0 | C23: 0 | D23: 1 | E23: 0 | F23: 2 | G23: 3 | H23: 0 | I23: 1 | J23: 3 | K23: 0 | L23: 0 | M23: 0 | N23: =SUM(B23:M23) -> 10
A24: Turnaways | B24: 0 | C24: 0 | D24: 0 | E24: 0 | F24: 0 | G24: 0 | H24: 0 | I24: 0 | J24: 0 | K24: 0 | L24: 0 | M24: 0 | N24: =SUM(B24:M24) -> 0
B27: 40360 | C27: 40391 | D27: 6614787 | E27: 40452 | F27: 40483 | G27: 40513 | H27: 40544 | I27: 40575 | J27: 40603 | K27: 40634 | L27: 40664 | M27: 40695 | N27: Total | O27: 2010-2011 Price | P27: Price per unit
A28: Journals@Ovid Full Text
A29: Total Searches Run | B29: 389 | C29: 131 | D29: 450 | E29: 633 | F29: 676 | G29: 348 | H29: 402 | I29: 485 | J29: 718 | K29: 813 | L29: 201 | M29: 217 | N29: =SUM(B29:M29) -> 5463
A30: Total Sessions | B30: 335 | C30: 120 | D30: 362 | E30: 545 | F30: 596 | G30: 277 | H30: 297 | I30: 439 | J30: 655 | K30: 735 | L30: 180 | M30: 225 | N30: =SUM(B30:M30) -> 4766
A31: Turnaways | B31: 0 | C31: 0 | D31: 0 | E31: 0 | F31: 0 | G31: 0 | H31: 0 | I31: 0 | J31: 0 | K31: 0 | L31: 0 | M31: 0 | N31: =SUM(B31:M31) -> 0
B35: 40360 | C35: 40391 | D35: 6614787 | E35: 40452 | F35: 40483 | G35: 40513 | H35: 40544 | I35: 40575 | J35: 40603 | K35: 40634 | L35: 40664 | M35: 40695 | N35: Total | O35: 2010-2011 Price | P35: Price per unit
A36: Your Journals@Ovid
A37: Total Searches Run | B37: 0 | C37: 0 | D37: 2 | E37: 28 | F37: 110 | G37: 46 | H37: 35 | I37: 22 | J37: 54 | K37: 79 | L37: 8 | M37: 39 | N37: =SUM(B37:M37) -> 423
A38: Total Sessions | B38: 0 | C38: 1 | D38: 3 | E38: 28 | F38: 105 | G38: 37 | H38: 28 | I38: 47 | J38: 59 | K38: 55 | L38: 7 | M38: 31 | N38: =SUM(B38:M38) -> 401
A39: Turnaways | B39: 0 | C39: 0 | D39: 0 | E39: 0 | F39: 0 | G39: 0 | H39: 0 | I39: 0 | J39: 0 | K39: 0 | L39: 0 | M39: 0 | N39: =SUM(B39:M39) -> 0
B42: 40360 | C42: 40391 | D42: 6614787 | E42: 40452 | F42: 40483 | G42: 40513 | H42: 40544 | I42: 40575 | J42: 40603 | K42: 40634 | L42: 40664 | M42: 40695 | N42: Total | O42: 2010-2011 Price | P42: Price per unit
A43: Total for Service Ovid
A44: Total Searches Run | B44: 389 | C44: 131 | D44: 453 | E44: 661 | F44: 787 | G44: 380 | H44: 437 | I44: 507 | J44: 768 | K44: 892 | L44: 209 | M44: 256 | N44: =SUM(B44:M44) -> 5870 | O44: N/A | P44: N/A
A45: Total Sessions | B45: 335 | C45: 121 | D45: 363 | E45: 557 | F45: 641 | G45: 296 | H45: 314 | I45: 487 | J45: 687 | K45: 761 | L45: 184 | M45: 234 | N45: =SUM(B45:M45) -> 4980
A46: Turnaways | B46: 0 | C46: 0 | D46: 0 | E46: 0 | F46: 0 | G46: 0 | H46: 0 | I46: 0 | J46: 0 | K46: 0 | L46: 0 | M46: 0 | N46: =SUM(B46:M46) -> 0

Sheet Oxford
A1: Oxford
A2: 2010-2011
A4: COUNTER-Compliant?: | B4: No
B6: 40360 | C6: 40391 | D6: 6614787 | E6: 40452 | F6: 40483 | G6: 40513 | H6: 40544 | I6: 40575 | J6: 40603 | K6: 40634 | L6: 40664 | M6: 40695 | N6: Total | O6: 2010-2011 Price | P6: Price per unit
A7: Grove Music Online
A8: Session (Logins) | B8: 13 | C8: 13 | D8: 18 | E8: 26 | F8: 28 | G8: 16 | H8: 12 | I8: 49 | J8: 188 | K8: 78 | L8: 15 | M8: 4 | N8: =SUM(B8:M8) -> 460
A9: Full-Content Units Requested | B9: 8 | C9: 6 | D9: 37 | E9: 59 | F9: 82 | G9: 18 | H9: 9 | I9: 93 | J9: 124 | K9: 72 | L9: 23 | M9: 5 | N9: =SUM(B9:M9) -> 536
A10: Queries (Searches) | B10: 4 | C10: 13 | D10: 31 | E10: 61 | F10: 72 | G10: 36 | H10: 20 | I10: 71 | J10: 77 | K10: 35 | L10: 23 | M10: 4 | N10: =SUM(B10:M10) -> 447 | O10: 0 | P10: =O10/N10 -> 0
A11: Turnaways | B11: 0 | C11: 0 | D11: 0 | E11: 1 | F11: 0 | G11: 0 | H11: 0 | I11: 0 | J11: 16 | K11: 0 | L11: 0 | M11: 0 | N11: =SUM(B11:M11) -> 17
B13: 40360 | C13: 40391 | D13: 6614787 | E13: 40452 | F13: 40483 | G13: 40513 | H13: 40544 | I13: 40575 | J13: 40603 | K13: 40634 | L13: 40664 | M13: 40695 | N13: Total | O13: 2010-2011 Price | P13: Price per unit
A14: Oxford Art Online
A15: Session (Logins) | B15: N/A | C15: N/A | D15: N/A | E15: N/A | F15: N/A | G15: N/A | H15: N/A | I15: N/A | J15: N/A | K15: N/A | L15: N/A | M15: N/A | N15: =SUM(B15:M15) -> 0
A16: Full-Content Units Requested | B16: N/A | C16: N/A | D16: N/A | E16: N/A | F16: N/A | G16: N/A | H16: N/A | I16: N/A | J16: N/A | K16: N/A | L16: N/A | M16: N/A | N16: =SUM(B16:M16) -> 0
A17: Queries (Searches) | B17: N/A | C17: N/A | D17: N/A | E17: N/A | F17: N/A | G17: N/A | H17: N/A | I17: N/A | J17: N/A | K17: N/A | L17: N/A | M17: N/A | N17: =SUM(B17:M17) -> 0 | O17: 0 | P17: =O17/N17 -> #DIV/0!
A18: Turnaways | B18: N/A | C18: N/A | D18: N/A | E18: N/A | F18: N/A | G18: N/A | H18: N/A | I18: N/A | J18: N/A | K18: N/A | L18: N/A | M18: N/A | N18: =SUM(B18:M18) -> 0
A20: Oxford English Dictionary
A21: Session (Logins) | B21: 68 | C21: 43 | D21: 254 | E21: 252 | F21: 195 | G21: 238 | H21: 133 | I21: 717 | J21: 405 | K21: 347 | L21: 215 | M21: 65 | N21: =SUM(B21:M21) -> 2932
A22: Full-Content Units Requested | B22: 149 | C22: 81 | D22: 916 | E22: 941 | F22: 745 | G22: 44 | H22: 181 | I22: 1115 | J22: 1146 | K22: 952 | L22: 583 | M22: 185 | N22: =SUM(B22:M22) -> 7038
A23: Queries (Searches) | B23: 162 | C23: 92 | D23: 824 | E23: 946 | F23: 785 | G23: 370 | H23: 165 | I23: 1103 | J23: 1050 | K23: 664 | L23: 584 | M23: 153 | N23: =SUM(B23:M23) -> 6898 | O23: 0 | P23: =O23/N23 -> 0
A24: Turnaways | B24: 0 | C24: 0 | D24: 0 | E24: 0 | F24: 0 | G24: 0 | H24: 0 | I24: 0 | J24: 0 | K24: 0 | L24: 0 | M24: 0 | N24: =SUM(B24:M24) -> 0

Sheet ProQuest
A1: ProQuest databases
A2: 2010-2011
A4: COUNTER-Compliant?: | B4: Yes
B6: 40360 | C6: 40391 | D6: 6614787 | E6: 40452 | F6: 40483 | G6: 40513 | H6: 40544 | I6: 40575 | J6: 40603 | K6: 40634 | L6: 40664 | M6: 40695 | N6: Total | O6: 2010-2011 Price | P6: Price per unit
A7: ABI/INFORM Dateline
A8: Searches | B8: 700 | C8: 329 | D8: 777 | E8: 1351 | F8: 1660 | G8: 879 | H8: 426 | I8: 1098 | J8: 1402 | K8: 1876 | L8: 970 | M8: 166 | N8: =SUM(B8:M8) -> 11634 | O8: 0 | P8: N/A
A9: Sessions | B9: 290 | C9: 97 | D9: 294 | E9: 488 | F9: 599 | G9: 304 | H9: 158 | I9: 370 | J9: 480 | K9: 527 | L9: 293 | M9: 104 | N9: =SUM(B9:M9) -> 4004
B12: 40360 | C12: 40391 | D12: 6614787 | E12: 40452 | F12: 40483 | G12: 40513 | H12: 40544 | I12: 40575 | J12: 40603 | K12: 40634 | L12: 40664 | M12: 40695 | N12: Total | O12: 2010-2011 Price | P12: Price per unit
A13: ABI/INFORM Global
A14: Searches | B14: 939 | C14: 505 | D14: 1078 | E14: 1943 | F14: 2644 | G14: 1343 | H14: 623 | I14: 1787 | J14: 2411 | K14: 2791 | L14: 1290 | M14: 197 | N14: =SUM(B14:M14) -> 17551 | O14: 0 | P14: =O14/N14 -> 0
A15: Sessions | B15: 352 | C15: 159 | D15: 350 | E15: 612 | F15: 836 | G15: 444 | H15: 224 | I15: 584 | J15: 717 | K15: 766 | L15: 391 | M15: 119 | N15: =SUM(B15:M15) -> 5554
B18: 40360 | C18: 40391 | D18: 6614787 | E18: 40452 | F18: 40483 | G18: 40513 | H18: 40544 | I18: 40575 | J18: 40603 | K18: 40634 | L18: 40664 | M18: 40695 | N18: Total | O18: 2010-2011 Price | P18: Price per unit
A19: ABI/INFORM Trade & Industry
A20: Searches | B20: 760 | C20: 342 | D20: 733 | E20: 1296 | F20: 1606 | G20: 936 | H20: 406 | I20: 1307 | J20: 1550 | K20: 1894 | L20: 1030 | M20: 169 | N20: =SUM(B20:M20) -> 12029 | O20: 0 | P20: N/A
A21: Sessions | B21: 305 | C21: 101 | D21: 272 | E21: 440 | F21: 562 | G21: 311 | H21: 153 | I21: 429 | J21: 500 | K21: 534 | L21: 300 | M21: 106 | N21: =SUM(B21:M21) -> 4013
B24: 40360 | C24: 40391 | D24: 6614787 | E24: 40452 | F24: 40483 | G24: 40513 | H24: 40544 | I24: 40575 | J24: 40603 | K24: 40634 | L24: 40664 | M24: 40695 | N24: Total | O24: 2010-2011 Price | P24: Price per unit
A25: Dissertations & Theses
A26: Searches | B26: 753 | C26: 404 | D26: 866 | E26: 1590 | F26: 1652 | G26: 786 | H26: 502 | I26: 1310 | J26: 1576 | K26: 1886 | L26: 1111 | M26: 197 | N26: =SUM(B26:M26) -> 12633 | O26: 0 | P26: N/A
B29: 40360 | C29: 40391 | D29: 6614787 | E29: 40452 | F29: 40483 | G29: 40513 | H29: 40544 | I29: 40575 | J29: 40603 | K29: 40634 | L29: 40664 | M29: 40695 | N29: Total | O29: 2010-2011 Price | P29: Price per unit
A30: Dissertations & Theses: A&I
A31: Searches | B31: 675 | C31: 389 | D31: 802 | E31: 1460 | F31: 1575 | G31: 740 | H31: 460 | I31: 1227 | J31: 1468 | K31: 1768 | L31: 1028 | M31: 180 | N31: =SUM(B31:M31) -> 11772 | O31: 0 | P31: =O31/N31 -> 0
A32: Sessions | B32: 283 | C32: 126 | D32: 295 | E32: 488 | F32: 573 | G32: 301 | H32: 180 | I32: 409 | J32: 532 | K32: 552 | L32: 346 | M32: 116 | N32: =SUM(B32:M32) -> 4201
B35: 40360 | C35: 40391 | D35: 6614787 | E35: 40452 | F35: 40483 | G35: 40513 | H35: 40544 | I35: 40575 | J35: 40603 | K35: 40634 | L35: 40664 | M35: 40695 | N35: Total | O35: 2010-2011 Price | P35: Price per unit
A36: Dissertations & Theses @ University of Rhode Island / Rhode Island College
A37: Searches | B37: 753 | C37: 404 | D37: 863 | E37: 1589 | F37: 1652 | G37: 786 | H37: 502 | I37: 1310 | J37: 1571 | K37: 1886 | L37: 1111 | M37: 197 | N37: =SUM(B37:M37) -> 12624 | O37: 0 | P37: N/A
A38: Sessions | B38: 317 | C38: 132 | D38: 318 | E38: 523 | F38: 604 | G38: 316 | H38: 198 | I38: 431 | J38: 578 | K38: 596 | L38: 374 | M38: 130 | N38: =SUM(B38:M38) -> 4517
B41: 40360 | C41: 40391 | D41: 6614787 | E41: 40452 | F41: 40483 | G41: 40513 | H41: 40544 | I41: 40575 | J41: 40603 | K41: 40634 | L41: 40664 | M41: 40695 | N41: Total | O41: 2010-2011 Price | P41: Price per unit
A42: Gender Watch
A43: Searches | B43: 446 | C43: 287 | D43: 683 | E43: 1154 | F43: 1470 | G43: 751 | H43: 356 | I43: 145 | J43: 1317 | K43: 1769 | L43: 911 | M43: 162 | N43: =SUM(B43:M43) -> 9451 | O43: 0 | P43: N/A
A44: Sessions | B44: 207 | C44: 91 | D44: 249 | E44: 415 | F44: 527 | G44: 280 | H44: 147 | I44: 364 | J44: 441 | K44: 508 | L44: 283 | M44: 103 | N44: =SUM(B44:M44) -> 3615
B47: 40360 | C47: 40391 | D47: 6614787 | E47: 40452 | F47: 40483 | G47: 40513 | H47: 40544 | I47: 40575 | J47: 40603 | K47: 40634 | L47: 40664 | M47: 40695 | N47: Total | O47: 2010-2011 Price | P47: Price per unit
A48: Los Angeles Times
A49: Searches | B49: N/A | C49: N/A | D49: N/A | E49: N/A | F49: N/A | G49: N/A | H49: N/A | I49: N/A | J49: N/A | K49: N/A | L49: N/A | M49: N/A | N49: =SUM(B49:M49) -> 0 | O49: 0 | P49: N/A
A50: Sessions | B50: N/A | C50: N/A | D50: N/A | E50: N/A | F50: N/A | G50: N/A | H50: N/A | I50: N/A | J50: N/A | K50: N/A | L50: N/A | M50: N/A | N50: =SUM(B50:M50) -> 0
