Workbook

Sheet Summary
A1: Community and Technical Colleges, Report of Fundable Operating Expenses, Fiscal Year (FY) 2003
A2: Summary of Expense divided Contact Hours
A3: Contact Hours for fall 2002 and spring and summer 2003
A4: Fund | B4: Total Expense by Discipline | D4: Contact Hours | E4: Expense | F4: Expense per Contact Hour
A5: 1 | B5: Agriculture | D5: =D36 -> 1453684 | E5: =E36+E67+IFERROR($E$105/$D$105*D5,0) -> 11467160 | F5: =F36+F67+$F$105 -> 7.18
A6: 2 | B6: Architecture and Precision Production Trades | D6: =D37 -> 5177312 | E6: =E37+E68+IFERROR($E$105/$D$105*D6,0) -> 39964845 | F6: =F37+F68+$F$105 -> 7.31
A7: 3 | B7: Biology, Physical Sciences, and Science Technology | D7: =D38 -> 24397771 | E7: =E38+E69+IFERROR($E$105/$D$105*D7,0) -> 1.5302773e+08 | F7: =F38+F69+$F$105 -> 5.86
A8: 4 | B8: Business Management, Marketing, and Administrative Services | D8: =D39 -> 17218154 | E8: =E39+E70+IFERROR($E$105/$D$105*D8,0) -> 1.2136754e+08 | F8: =F39+F70+$F$105 -> 6.69
A9: 5 | B9: Career Pilot | D9: =D40 -> 246311 | E9: =E40+E71+IFERROR($E$105/$D$105*D9,0) -> 4756451.7 | F9: =F40+F71+$F$105 -> 13.77
A10: 6 | B10: Communications | D10: =D41 -> 2136055 | E10: =E41+E72+IFERROR($E$105/$D$105*D10,0) -> 19691532 | F10: =F41+F72+$F$105 -> 7.21
A11: 7 | B11: Computer and Information Sciences | D11: =D42 -> 13099478 | E11: =E42+E73+IFERROR($E$105/$D$105*D11,0) -> 1.0402098e+08 | F11: =F42+F73+$F$105 -> 6.94
A12: 8 | B12: Construction Trades | D12: =D43 -> 2308884 | E12: =E43+E74+IFERROR($E$105/$D$105*D12,0) -> 17328739 | F12: =F43+F74+$F$105 -> 7.36
A13: 9 | B13: Consumer and Homemaking Education | D13: =D44 -> 8616348 | E13: =E44+E75+IFERROR($E$105/$D$105*D13,0) -> 52268890 | F13: =F44+F75+$F$105 -> 5.49
A14: 10 | B14: Engineering | D14: =D45 -> 133459 | E14: =E45+E76+IFERROR($E$105/$D$105*D14,0) -> 1669985.7 | F14: =F45+F76+$F$105 -> 8.92
A15: 11 | B15: Engineering Related | D15: =D46 -> 5809798 | E15: =E46+E77+IFERROR($E$105/$D$105*D15,0) -> 47059576 | F15: =F46+F77+$F$105 -> 7.23
A16: 12 | B16: English Language, Lit, Philosophy, Humanities, & Interdisciplinary | D16: =D47 -> 40067445 | E16: =E47+E78+IFERROR($E$105/$D$105*D16,0) -> 2.6192029e+08 | F16: =F47+F78+$F$105 -> 5.83
... A30: 26 | B30: Visual and Performing Arts | D30: =D61 -> 11252211 | E30: =E61+E92+IFERROR($E$105/$D$105*D30,0) -> 90047895 | F30: =F61+F92+$F$105 -> 7.18
A31: 28 | B31: Developmental Education - Math | D31: =D62 -> 0 | E31: =E62+E93+IFERROR($E$105/$D$105*D31,0) -> 0
A32: 29 | B32: Developmental Education - Reading/Writing | D32: =D63 -> 0 | E32: =E63+E94+IFERROR($E$105/$D$105*D32,0) -> 0
B33: Total | D33: =SUM(D5:D32) -> 244475951 | E33: =SUM(E5:E32) -> 1.6735867e+09 | F33: =F64+F95+$F$105 -> 6.37
A35: Fund | B35: Departmental Operating Expense by Discipline | D35: Contact Hours | E35: Expense | F35: Expense per Contact Hour
A36: 1 | B36: Agriculture | D36: =SUM('1:57'!D36) -> 1453684 | E36: =SUM('1:57'!E36) -> 2143915 | F36: =ROUND(MEDIAN('1:57'!F36),2) -> 0.83
A37: 2 | B37: Architecture and Precision Production Trades | D37: =SUM('1:57'!D37) -> 5177312 | E37: =SUM('1:57'!E37) -> 6365960 | F37: =ROUND(MEDIAN('1:57'!F37),2) -> 1.1
A38: 3 | B38: Biology, Physical Sciences, and Science Technology | D38: =SUM('1:57'!D38) -> 24397771 | E38: =SUM('1:57'!E38) -> 15911781 | F38: =ROUND(MEDIAN('1:57'!F38),2) -> 0.42
A39: 4 | B39: Business Management, Marketing, and Administrative Services | D39: =SUM('1:57'!D39) -> 17218154 | E39: =SUM('1:57'!E39) -> 16118594 | F39: =ROUND(MEDIAN('1:57'!F39),2) -> 0.66
A40: 5 | B40: Career Pilot | D40: =SUM('1:57'!D40) -> 246311 | E40: =SUM('1:57'!E40) -> 2344165 | F40: =ROUND(MEDIAN('1:57'!F40),2) -> 3.76
A41: 6 | B41: Communications | D41: =SUM('1:57'!D41) -> 2136055 | E41: =SUM('1:57'!E41) -> 6239768 | F41: =ROUND(MEDIAN('1:57'!F41),2) -> 1.05
A42: 7 | B42: Computer and Information Sciences | D42: =SUM('1:57'!D42) -> 13099478 | E42: =SUM('1:57'!E42) -> 19134340 | F42: =ROUND(MEDIAN('1:57'!F42),2) -> 0.8
A43: 8 | B43: Construction Trades | D43: =SUM('1:57'!D43) -> 2308884 | E43: =SUM('1:57'!E43) -> 3781358 | F43: =ROUND(MEDIAN('1:57'!F43),2) -> 1.04
A44: 9 | B44: Consumer and Homemaking Education | D44: =SUM('1:57'!D44) -> 8616348 | E44: =SUM('1:57'!E44) -> 6592363 | F44: =ROUND(MEDIAN('1:57'!F44),2) -> 0.59
A45: 10 | B45: Engineering | D45: =SUM('1:57'!D45) -> 133459 | E45: =SUM('1:57'!E45) -> 297288 | F45: =ROUND(MEDIAN('1:57'!F45),2) -> 0.98
A46: 11 | B46: Engineering Related | D46: =SUM('1:57'!D46) -> 5809798 | E46: =SUM('1:57'!E46) -> 7856737 | F46: =ROUND(MEDIAN('1:57'!F46),2) -> 0.91
A47: 12 | B47: English Language, Lit, Philosophy, Humanities, & Interdisciplinary | D47: =SUM('1:57'!D47) -> 40067445 | E47: =SUM('1:57'!E47) -> 20882179 | F47: =ROUND(MEDIAN('1:57'!F47),2) -> 0.33
... A61: 26 | B61: Visual and Performing Arts | D61: =SUM('1:57'!D61) -> 11252211 | E61: =SUM('1:57'!E61) -> 11229779 | F61: =ROUND(MEDIAN('1:57'!F61),2) -> 0.84
A62: 28 | B62: Developmental Education - Math | D62: =SUM('1:57'!D62) -> 0 | E62: =SUM('1:57'!E62) -> 0
A63: 29 | B63: Developmental Education - Reading/Writing | D63: =SUM('1:57'!D63) -> 0 | E63: =SUM('1:57'!E63) -> 0
C64: Total | D64: =SUM(D36:D63) -> 244475951 | E64: =SUM(E36:E63) -> 192319415 | F64: =ROUND(MEDIAN('1:57'!F64),2) -> 0.66
A66: Fund | B66: Faculty Salaries by Discipline | D66: Contact Hours | E66: Expense | F66: Expense per Contact Hour
A67: 1 | B67: Agriculture | D67: =D36 -> 1453684 | E67: =SUM('1:57'!E67) -> 4699157 | F67: =ROUND(MEDIAN('1:57'!F67),2) -> 3.41
A68: 2 | B68: Architecture and Precision Production Trades | D68: =D37 -> 5177312 | E68: =SUM('1:57'!E68) -> 17130142 | F68: =ROUND(MEDIAN('1:57'!F68),2) -> 3.27
...

Sheet Rate History
A1: =Summary!A1 -> Community and Technical Colleges, Report of Fundable Operating Expenses, Fiscal Year (FY) 2003
A2: Rate History | I2: Year over Year Change
A3: Fund | B3: Expense per Contact Hour by Discipline | C3: 2003 | D3: 2002 | E3: 2001 | F3: 2000 | G3: 1999 | I3: 2003 | J3: 2002 | K3: 2001 | L3: 2000
A4: 1 | B4: Agriculture | C4: =Summary!F5 -> 7.18 | D4: 7.58 | E4: 7 | F4: 6.67 | G4: 6.81 | I4: =IFERROR(C4/D4-1,"") -> -0.052770449 | J4: =IFERROR(D4/E4-1,"") -> 0.082857143 | K4: =IFERROR(E4/F4-1,"") -> 0.049475262 | L4: =IFERROR(F4/G4-1,"") -> -0.020558003
A5: 2 | B5: Architecture and Precision Production Trades | C5: =Summary!F6 -> 7.31 | D5: 7.27 | E5: 7.56 | F5: 6.83 | G5: 6.64 | I5: =IFERROR(C5/D5-1,"") -> 0.0055020633 | J5: =IFERROR(D5/E5-1,"") -> -0.038359788 | K5: =IFERROR(E5/F5-1,"") -> 0.10688141 | L5: =IFERROR(F5/G5-1,"") -> 0.028614458
A6: 3 | B6: Biology, Physical Sciences, and Science Technology | C6: =Summary!F7 -> 5.86 | D6: 6.04 | E6: 5.9 | F6: 5.69 | G6: 5.51 | I6: =IFERROR(C6/D6-1,"") -> -0.029801325 | J6: =IFERROR(D6/E6-1,"") -> 0.023728814 | K6: =IFERROR(E6/F6-1,"") -> 0.036906854 | L6: =IFERROR(F6/G6-1,"") -> 0.032667877
A7: 4 | B7: Business Management, Marketing, and Administrative Services | C7: =Summary!F8 -> 6.69 | D7: 6.46 | E7: 6.07 | F7: 6.13 | G7: 6.22 | I7: =IFERROR(C7/D7-1,"") -> 0.035603715 | J7: =IFERROR(D7/E7-1,"") -> 0.064250412 | K7: =IFERROR(E7/F7-1,"") -> -0.0097879282 | L7: =IFERROR(F7/G7-1,"") -> -0.014469453
A8: 5 | B8: Career Pilot | C8: =Summary!F9 -> 13.77 | D8: 11.03 | E8: 16.04 | F8: 19.42 | G8: 18.69 | I8: =IFERROR(C8/D8-1,"") -> 0.24841342 | J8: =IFERROR(D8/E8-1,"") -> -0.31234414 | K8: =IFERROR(E8/F8-1,"") -> -0.17404737 | L8: =IFERROR(F8/G8-1,"") -> 0.03905832
A9: 6 | B9: Communications | C9: =Summary!F10 -> 7.21 | D9: 7.26 | E9: 6.99 | F9: 9.21 | G9: 8.21 | I9: =IFERROR(C9/D9-1,"") -> -0.0068870523 | J9: =IFERROR(D9/E9-1,"") -> 0.038626609 | K9: =IFERROR(E9/F9-1,"") -> -0.24104235 | L9: =IFERROR(F9/G9-1,"") -> 0.12180268
A10: 7 | B10: Computer and Information Sciences | C10: =Summary!F11 -> 6.94 | D10: 6.92 | E10: 6.69 | F10: 6.32 | G10: 5.44 | I10: =IFERROR(C10/D10-1,"") -> 0.0028901734 | J10: =IFERROR(D10/E10-1,"") -> 0.034379671 | K10: =IFERROR(E10/F10-1,"") -> 0.058544304 | L10: =IFERROR(F10/G10-1,"") -> 0.16176471
A11: 8 | B11: Construction Trades | C11: =Summary!F12 -> 7.36 | D11: 6.75 | E11: 6.12 | F11: 6.42 | G11: 5.99 | I11: =IFERROR(C11/D11-1,"") -> 0.09037037 | J11: =IFERROR(D11/E11-1,"") -> 0.10294118 | K11: =IFERROR(E11/F11-1,"") -> -0.046728972 | L11: =IFERROR(F11/G11-1,"") -> 0.071786311
A12: 9 | B12: Consumer and Homemaking Education | C12: =Summary!F13 -> 5.49 | D12: 5.51 | E12: 5.52 | F12: 5.14 | G12: 5.35 | I12: =IFERROR(C12/D12-1,"") -> -0.0036297641 | J12: =IFERROR(D12/E12-1,"") -> -0.0018115942 | K12: =IFERROR(E12/F12-1,"") -> 0.073929961 | L12: =IFERROR(F12/G12-1,"") -> -0.039252336
A13: 10 | B13: Engineering | C13: =Summary!F14 -> 8.92 | D13: 8.54 | E13: 11.49 | F13: 9.83 | G13: 7.64 | I13: =IFERROR(C13/D13-1,"") -> 0.044496487 | J13: =IFERROR(D13/E13-1,"") -> -0.256745 | K13: =IFERROR(E13/F13-1,"") -> 0.1688708 | L13: =IFERROR(F13/G13-1,"") -> 0.28664921
A14: 11 | B14: Engineering Related | C14: =Summary!F15 -> 7.23 | D14: 6.89 | E14: 6.58 | F14: 6.71 | G14: 6.42 | I14: =IFERROR(C14/D14-1,"") -> 0.04934688 | J14: =IFERROR(D14/E14-1,"") -> 0.047112462 | K14: =IFERROR(E14/F14-1,"") -> -0.019374069 | L14: =IFERROR(F14/G14-1,"") -> 0.04517134
A15: 12 | B15: English Language, Lit, Philosophy, Humanities, & Interdisciplinary | C15: =Summary!F16 -> 5.83 | D15: 5.94 | E15: 5.75 | F15: 5.68 | G15: 5.26 | I15: =IFERROR(C15/D15-1,"") -> -0.018518519 | J15: =IFERROR(D15/E15-1,"") -> 0.033043478 | K15: =IFERROR(E15/F15-1,"") -> 0.012323944 | L15: =IFERROR(F15/G15-1,"") -> 0.079847909
... A31: 29 | B31: Developmental Education - Reading/Writing | C31: =Summary!F32 -> 0 | D31: 0 | E31: 0 | F31: 0 | G31: 0 | I31: =IFERROR(C31/D31-1,"") | J31: =IFERROR(D31/E31-1,"") | K31: =IFERROR(E31/F31-1,"") | L31: =IFERROR(F31/G31-1,"")
B32: Average | C32: =AVERAGE(C4:C31) -> 6.9428571 | D32: =AVERAGE(D4:D31) -> 7.0071429 | E32: =AVERAGE(E4:E31) -> 7.0107143 | F32: =AVERAGE(F4:F31) -> 7.0171429 | G32: =AVERAGE(G4:G31) -> 6.5617857 | I32: =IFERROR(C32/D32-1,"") -> -0.0091743119 | J32: =IFERROR(D32/E32-1,"") -> -0.00050942435 | K32: =IFERROR(E32/F32-1,"") -> -0.00091612378 | L32: =IFERROR(F32/G32-1,"") -> 0.069395308
B33: Median | C33: =MEDIAN(C4:C31) -> 6.995 | D33: =MEDIAN(D4:D31) -> 6.905 | E33: =MEDIAN(E4:E31) -> 6.69 | F33: =MEDIAN(F4:F31) -> 6.69 | G33: =MEDIAN(G4:G31) -> 6.32 | I33: =IFERROR(C33/D33-1,"") -> 0.013034033 | J33: =IFERROR(D33/E33-1,"") -> 0.032137519 | K33: =IFERROR(E33/F33-1,"") -> 0 | L33: =IFERROR(F33/G33-1,"") -> 0.058544304
B34: Standard Deviation | C34: =STDEV(C4:C31) -> 2.7509808 | D34: =STDEV(D4:D31) -> 2.6772026 | E34: =STDEV(E4:E31) -> 3.0868058 | F34: =STDEV(F4:F31) -> 3.4645516 | G34: =STDEV(G4:G31) -> 3.2525364 | I34: =IFERROR(C34/D34-1,"") -> 0.027557936 | J34: =IFERROR(D34/E34-1,"") -> -0.13269483 | K34: =IFERROR(E34/F34-1,"") -> -0.10903165 | L34: =IFERROR(F34/G34-1,"") -> 0.065184562

Sheet FTSE Summary
A1: =Summary!A1 -> Community and Technical Colleges, Report of Fundable Operating Expenses, Fiscal Year (FY) 2003
A2: Average Total Expenditure per Full-Time Student Equivalent (FTSE)
A3: Institution | B3: Annual State Funded Semester Credit Hours | C3: Total FTSE | D3: Total Expenditure | E3: Average Expenditure per FTSE
A4: Alamo | B4: 937642 | C4: =B4/30 -> 31254.733 | D4: ='1'!$E$33 -> 1.4244558e+08 | E4: =IFERROR(D4/C4,"") -> 4557.5684
A5: Alvin | B5: 99534 | C5: =B5/30 -> 3317.8 | D5: ='2'!$E$33 -> 16388766 | E5: =IFERROR(D5/C5,"") -> 4939.6486
A6: Amarillo | B6: 176266 | C6: =B6/30 -> 5875.5333 | D6: ='3'!$E$33 -> 30374840 | E6: =IFERROR(D6/C6,"") -> 5169.7162
A7: Angelina | B7: 104820 | C7: =B7/30 -> 3494 | D7: ='4'!$E$33 -> 11784710 | E7: =IFERROR(D7/C7,"") -> 3372.842
A8: Austin | B8: 576968 | C8: =B8/30 -> 19232.267 | D8: ='5'!$E$33 -> 90033991 | E8: =IFERROR(D8/C8,"") -> 4681.403
A9: Blinn | B9: 313619 | C9: =B9/30 -> 10453.967 | D9: ='6'!$E$33 -> 31537669 | E9: =IFERROR(D9/C9,"") -> 3016.8136
A10: Brazosport | B10: 69794 | C10: =B10/30 -> 2326.4667 | D10: ='7'!$E$33 -> 11264114 | E10: =IFERROR(D10/C10,"") -> 4841.7259
A11: Central Texas | B11: 233899 | C11: =B11/30 -> 7796.6333 | D11: ='8'!$E$33 -> 28479940 | E11: =IFERROR(D11/C11,"") -> 3652.851
A12: Cisco | B12: 65749 | C12: =B12/30 -> 2191.6333 | D12: ='9'!$E$33 -> 5709200 | E12: =IFERROR(D12/C12,"") -> 2604.9978
A13: Clarendon | B13: 20192 | C13: =B13/30 -> 673.06667 | D13: ='10'!$E$33 -> 2960451 | E13: =IFERROR(D13/C13,"") -> 4398.4514
A14: Coastal Bend | B14: 77831 | C14: =B14/30 -> 2594.3667 | D14: ='11'!$E$33 -> 10871274 | E14: =IFERROR(D14/C14,"") -> 4190.3383
A15: College Of The Mainland | B15: 77885 | C15: =B15/30 -> 2596.1667 | D15: ='12'!$E$33 -> 16899288 | E15: =IFERROR(D15/C15,"") -> 6509.3232
A16: Collin | B16: 319356 | C16: =B16/30 -> 10645.2 | D16: ='13'!$E$33 -> 44821329 | E16: =IFERROR(D16/C16,"") -> 4210.4732
A17: Dallas | B17: 1127974 | C17: =B17/30 -> 37599.133 | D17: ='14'!$E$33 -> 1.8229215e+08 | E17: =IFERROR(D17/C17,"") -> 4848.3071
A18: Del Mar | B18: 222402 | C18: =B18/30 -> 7413.4 | D18: ='15'!$E$33 -> 45788300 | E18: =IFERROR(D18/C18,"") -> 6176.4238
A19: El Paso | B19: 422079 | C19: =B19/30 -> 14069.3 | D19: ='16'!$E$33 -> 62585427 | E19: =IFERROR(D19/C19,"") -> 4448.3682
A20: Frank Phillips | B20: 26266 | C20: =B20/30 -> 875.53333 | D20: ='17'!$E$33 -> 4835883 | E20: =IFERROR(D20/C20,"") -> 5523.3568
A21: Galveston | B21: 42732 | C21: =B21/30 -> 1424.4 | D21: ='18'!$E$33 -> 9697114 | E21: =IFERROR(D21/C21,"") -> 6807.8587
A22: Grayson | B22: 79353 | C22: =B22/30 -> 2645.1 | D22: ='19'!$E$33 -> 9836812 | E22: =IFERROR(D22/C22,"") -> 3718.8809
A23: Hill | B23: 64451 | C23: =B23/30 -> 2148.3667 | D23: ='20'!$E$33 -> 7715563 | E23: =IFERROR(D23/C23,"") -> 3591.3623
A24: Houston | B24: 777341 | C24: =B24/30 -> 25911.367 | D24: ='21'!$E$33 -> 1.5008447e+08 | E24: =IFERROR(D24/C24,"") -> 5792.2252
A25: Howard | B25: 56174 | C25: =B25/30 -> 1872.4667 | D25: ='22'!$E$33 -> 13649317 | E25: =IFERROR(D25/C25,"") -> 7289.4846
A26: Kilgore | B26: 108677 | C26: =B26/30 -> 3622.5667 | D26: ='23'!$E$33 -> 16036109 | E26: =IFERROR(D26/C26,"") -> 4426.7257
A27: Laredo | B27: 158108 | C27: =B27/30 -> 5270.2667 | D27: ='24'!$E$33 -> 24781083 | E27: =IFERROR(D27/C27,"") -> 4702.0549
A28: Lee | B28: 129653 | C28: =B28/30 -> 4321.7667 | D28: ='25'!$E$33 -> 22440330 | E28: =IFERROR(D28/C28,"") -> 5192.3974
A29: Lonestar | B29: 625611 | C29: =B29/30 -> 20853.7 | D29: ='26'!$E$33 -> 95199422 | E29: =IFERROR(D29/C29,"") -> 4565.1094
A30: Mclennan | B30: 153965 | C30: =B30/30 -> 5132.1667 | D30: ='27'!$E$33 -> 21526573 | E30: =IFERROR(D30/C30,"") -> 4194.4415
A31: Midland | B31: 104040 | C31: =B31/30 -> 3468 | D31: ='28'!$E$33 -> 18714675 | E31: =IFERROR(D31/C31,"") -> 5396.3884
A32: Navarro | B32: 121632 | C32: =B32/30 -> 4054.4 | D32: ='29'!$E$33 -> 13432088 | E32: =IFERROR(D32/C32,"") -> 3312.9657
A33: North Central Texas | B33: 122817 | C33: =B33/30 -> 4093.9 | D33: ='30'!$E$33 -> 10944802 | E33: =IFERROR(D33/C33,"") -> 2673.4415
A34: Northeast Texas | B34: 54488 | C34: =B34/30 -> 1816.2667 | D34: ='31'!$E$33 -> 7044285 | E34: =IFERROR(D34/C34,"") -> 3878.442
A35: Odessa | B35: 101046 | C35: =B35/30 -> 3368.2 | D35: ='32'!$E$33 -> 15638498 | E35: =IFERROR(D35/C35,"") -> 4642.9838
A36: Panola | B36: 40517 | C36: =B36/30 -> 1350.5667 | D36: ='33'!$E$33 -> 7648703 | E36: =IFERROR(D36/C36,"") -> 5663.3287
A37: Paris | B37: 80121 | C37: =B37/30 -> 2670.7 | D37: ='34'!$E$33 -> 13377921 | E37: =IFERROR(D37/C37,"") -> 5009.144
A38: Ranger | B38: 20490 | C38: =B38/30 -> 683 | D38: ='35'!$E$33 -> 2698348 | E38: =IFERROR(D38/C38,"") -> 3950.7291
A39: San Jacinto | B39: 456117 | C39: =B39/30 -> 15203.9 | D39: ='36'!$E$33 -> 68488942 | E39: =IFERROR(D39/C39,"") -> 4504.6956
A40: South Plains | B40: 192571 | C40: =B40/30 -> 6419.0333 | D40: ='37'!$E$33 -> 23387310 | E40: =IFERROR(D40/C40,"") -> 3643.4318
...

Sheet Discipline Summary
A1: =Summary!A1 -> Community and Technical Colleges, Report of Fundable Operating Expenses, Fiscal Year (FY) 2003
A2: Discipline Summary of Expense per Contact Hour by Institution
A3: Institution | B3: AG | C3: ARCH | D3: SCI | E3: BA | F3: CP | G3: COMM | H3: CS | I3: CNSTR | J3: HE | K3: ENG | L3: ENGR | M3: LA | N3: FL | O3: HODA | P3: HODH | Q3: HOO | R3: HORT | S3: NUR | T3: MATH | U3: AUTO | V3: MECH | W3: ELECT | X3: PE | Y3: PA | Z3: SS | AA3: FA | AB3: DEM | AC3: DER | AD3: Total
A4: Alamo | B4: ='1'!$F$5 -> 5.78 | C4: ='1'!$F$6 -> 7.22 | D4: ='1'!$F$7 -> 7.47 | E4: ='1'!$F$8 -> 8.53 | F4: ='1'!$F$9 -> 14.18 | G4: ='1'!$F$10 -> 8.26 | H4: ='1'!$F$11 -> 8.58 | I4: ='1'!$F$12 -> 8.13 | J4: ='1'!$F$13 -> 7.65 | K4: ='1'!$F$14 -> 19.93 | L4: ='1'!$F$15 -> 14.68 | M4: ='1'!$F$16 -> 6.65 | N4: ='1'!$F$17 -> 7.91 | O4: ='1'!$F$18 -> 12.13 | P4: ='1'!$F$19 | Q4: ='1'!$F$20 -> 7.39 | R4: ='1'!$F$21 -> 15.14 | S4: ='1'!$F$22 -> 8.41 | T4: ='1'!$F$23 -> 6.76 | U4: ='1'!$F$24 -> 4.82 | V4: ='1'!$F$25 -> 11.88 | W4: ='1'!$F$26 -> 3.87 | X4: ='1'!$F$27 -> 8.27 | Y4: ='1'!$F$28 -> 6.52 | Z4: ='1'!$F$29 -> 6.81 | AA4: ='1'!$F$30 -> 9.46 | AB4: ='1'!$F$31 | AC4: ='1'!$F$32 | AD4: ='1'!$F$33 -> 7.55
A5: Alvin | B5: ='2'!$F$5 -> 5.26 | C5: ='2'!$F$6 -> 7.07 | D5: ='2'!$F$7 -> 6.59 | E5: ='2'!$F$8 -> 7.42 | F5: ='2'!$F$9 | G5: ='2'!$F$10 -> 6.5 | H5: ='2'!$F$11 -> 6.37 | I5: ='2'!$F$12 | J5: ='2'!$F$13 -> 6.81 | K5: ='2'!$F$14 | L5: ='2'!$F$15 -> 5.45 | M5: ='2'!$F$16 -> 6.96 | N5: ='2'!$F$17 -> 7.63 | O5: ='2'!$F$18 -> 10.25 | P5: ='2'!$F$19 | Q5: ='2'!$F$20 -> 7.11 | R5: ='2'!$F$21 -> 11.59 | S5: ='2'!$F$22 -> 6.63 | T5: ='2'!$F$23 -> 5.84 | U5: ='2'!$F$24 -> 5.14 | V5: ='2'!$F$25 | W5: ='2'!$F$26 | X5: ='2'!$F$27 -> 7.76 | Y5: ='2'!$F$28 -> 6.05 | Z5: ='2'!$F$29 -> 6.2 | AA5: ='2'!$F$30 -> 8.54 | AB5: ='2'!$F$31 | AC5: ='2'!$F$32 | AD5: ='2'!$F$33 -> 6.84
A6: Amarillo | B6: ='3'!$F$5 -> 6.42 | C6: ='3'!$F$6 -> 6.96 | D6: ='3'!$F$7 -> 6.14 | E6: ='3'!$F$8 -> 6.8 | F6: ='3'!$F$9 | G6: ='3'!$F$10 -> 6.89 | H6: ='3'!$F$11 -> 6.67 | I6: ='3'!$F$12 -> 7.23 | J6: ='3'!$F$13 -> 5.74 | K6: ='3'!$F$14 -> 6.12 | L6: ='3'!$F$15 -> 6.71 | M6: ='3'!$F$16 -> 6.99 | N6: ='3'!$F$17 -> 7.09 | O6: ='3'!$F$18 -> 7.46 | P6: ='3'!$F$19 -> 7.68 | Q6: ='3'!$F$20 -> 7.6 | R6: ='3'!$F$21 -> 7.65 | S6: ='3'!$F$22 -> 7.3 | T6: ='3'!$F$23 -> 6.18 | U6: ='3'!$F$24 -> 6.97 | V6: ='3'!$F$25 -> 6.97 | W6: ='3'!$F$26 -> 6.83 | X6: ='3'!$F$27 -> 5.26 | Y6: ='3'!$F$28 -> 7.66 | Z6: ='3'!$F$29 -> 5.42 | AA6: ='3'!$F$30 -> 6.91 | AB6: ='3'!$F$31 | AC6: ='3'!$F$32 | AD6: ='3'!$F$33 -> 6.66
A7: Angelina | B7: ='4'!$F$5 -> 3.38 | C7: ='4'!$F$6 -> 7.02 | D7: ='4'!$F$7 -> 4.35 | E7: ='4'!$F$8 -> 5.31 | F7: ='4'!$F$9 | G7: ='4'!$F$10 -> 5.78 | H7: ='4'!$F$11 -> 7.82 | I7: ='4'!$F$12 -> 7.69 | J7: ='4'!$F$13 -> 5.14 | K7: ='4'!$F$14 -> 8.19 | L7: ='4'!$F$15 -> 7.69 | M7: ='4'!$F$16 -> 4.13 | N7: ='4'!$F$17 -> 4.62 | O7: ='4'!$F$18 -> 6.6 | P7: ='4'!$F$19 | Q7: ='4'!$F$20 -> 5.07 | R7: ='4'!$F$21 -> 8.48 | S7: ='4'!$F$22 -> 3.52 | T7: ='4'!$F$23 -> 4.19 | U7: ='4'!$F$24 -> 8.76 | V7: ='4'!$F$25 -> 6.76 | W7: ='4'!$F$26 -> 5.95 | X7: ='4'!$F$27 -> 5.88 | Y7: ='4'!$F$28 -> 3.95 | Z7: ='4'!$F$29 -> 3.74 | AA7: ='4'!$F$30 -> 5.47 | AB7: ='4'!$F$31 | AC7: ='4'!$F$32 | AD7: ='4'!$F$33 -> 4.82
A8: Austin | B8: ='5'!$F$5 -> 8.27 | C8: ='5'!$F$6 -> 11.07 | D8: ='5'!$F$7 -> 7.78 | E8: ='5'!$F$8 -> 9.09 | F8: ='5'!$F$9 | G8: ='5'!$F$10 -> 9.26 | H8: ='5'!$F$11 -> 8.62 | I8: ='5'!$F$12 -> 10.8 | J8: ='5'!$F$13 -> 9.02 | K8: ='5'!$F$14 -> 17.7 | L8: ='5'!$F$15 -> 12.5 | M8: ='5'!$F$16 -> 7.42 | N8: ='5'!$F$17 -> 6.71 | O8: ='5'!$F$18 -> 12.9 | P8: ='5'!$F$19 | Q8: ='5'!$F$20 -> 10.04 | R8: ='5'!$F$21 | S8: ='5'!$F$22 -> 12.16 | T8: ='5'!$F$23 -> 6.77 | U8: ='5'!$F$24 -> 10.51 | V8: ='5'!$F$25 -> 8.59 | W8: ='5'!$F$26 -> 9.11 | X8: ='5'!$F$27 -> 7.68 | Y8: ='5'!$F$28 -> 8.55 | Z8: ='5'!$F$29 -> 6.1 | AA8: ='5'!$F$30 -> 9.01 | AB8: ='5'!$F$31 | AC8: ='5'!$F$32 | AD8: ='5'!$F$33 -> 7.85
A9: Blinn | B9: ='6'!$F$5 -> 6.72 | C9: ='6'!$F$6 -> 22.29 | D9: ='6'!$F$7 -> 4.21 | E9: ='6'!$F$8 -> 6.61 | F9: ='6'!$F$9 | G9: ='6'!$F$10 -> 4.82 | H9: ='6'!$F$11 -> 8.16 | I9: ='6'!$F$12 -> 20.08 | J9: ='6'!$F$13 -> 3.37 | K9: ='6'!$F$14 | L9: ='6'!$F$15 -> 23.56 | M9: ='6'!$F$16 -> 5.78 | N9: ='6'!$F$17 -> 4.71 | O9: ='6'!$F$18 -> 9.13 | P9: ='6'!$F$19 -> 18.38 | Q9: ='6'!$F$20 -> 4.21 | R9: ='6'!$F$21 | S9: ='6'!$F$22 -> 6.76 | T9: ='6'!$F$23 -> 5.26 | U9: ='6'!$F$24 -> 21.21 | V9: ='6'!$F$25 | W9: ='6'!$F$26 | X9: ='6'!$F$27 -> 5.94 | Y9: ='6'!$F$28 -> 3.72 | Z9: ='6'!$F$29 -> 4.38 | AA9: ='6'!$F$30 -> 6.42 | AB9: ='6'!$F$31 | AC9: ='6'!$F$32 | AD9: ='6'!$F$33 -> 5.19
A10: Brazosport | B10: ='7'!$F$5 | C10: ='7'!$F$6 -> 6.78 | D10: ='7'!$F$7 -> 6.91 | E10: ='7'!$F$8 -> 8.5 | F10: ='7'!$F$9 | G10: ='7'!$F$10 -> 6.13 | H10: ='7'!$F$11 -> 8.02 | I10: ='7'!$F$12 -> 7.2 | J10: ='7'!$F$13 -> 5.39 | K10: ='7'!$F$14 | L10: ='7'!$F$15 -> 5.75 | M10: ='7'!$F$16 -> 6.49 | N10: ='7'!$F$17 -> 12.28 | O10: ='7'!$F$18 | P10: ='7'!$F$19 | Q10: ='7'!$F$20 -> 9.37 | R10: ='7'!$F$21 | S10: ='7'!$F$22 -> 7.98 | T10: ='7'!$F$23 -> 6.04 | U10: ='7'!$F$24 -> 10.09 | V10: ='7'!$F$25 -> 9.61 | W10: ='7'!$F$26 | X10: ='7'!$F$27 -> 7.85 | Y10: ='7'!$F$28 -> 6 | Z10: ='7'!$F$29 -> 6.6 | AA10: ='7'!$F$30 -> 9.1 | AB10: ='7'!$F$31 | AC10: ='7'!$F$32 | AD10: ='7'!$F$33 -> 7.01
A11: Central Texas | B11: ='8'!$F$5 -> 5.18 | C11: ='8'!$F$6 -> 6.53 | D11: ='8'!$F$7 -> 6.01 | E11: ='8'!$F$8 -> 6.01 | F11: ='8'!$F$9 -> 30.96 | G11: ='8'!$F$10 -> 4.41 | H11: ='8'!$F$11 -> 4.13 | I11: ='8'!$F$12 -> 4.64 | J11: ='8'!$F$13 -> 4.39 | K11: ='8'!$F$14 | L11: ='8'!$F$15 -> 4.7 | M11: ='8'!$F$16 -> 4.93 | N11: ='8'!$F$17 -> 4.83 | O11: ='8'!$F$18 -> 8.64 | P11: ='8'!$F$19 | Q11: ='8'!$F$20 -> 8.24 | R11: ='8'!$F$21 | S11: ='8'!$F$22 -> 7.24 | T11: ='8'!$F$23 -> 4.45 | U11: ='8'!$F$24 -> 6.91 | V11: ='8'!$F$25 -> 6.16 | W11: ='8'!$F$26 -> 4.88 | X11: ='8'!$F$27 -> 6.26 | Y11: ='8'!$F$28 -> 4.28 | Z11: ='8'!$F$29 -> 4.08 | AA11: ='8'!$F$30 -> 5.37 | AB11: ='8'!$F$31 | AC11: ='8'!$F$32 | AD11: ='8'!$F$33 -> 5.26
A12: Cisco | B12: ='9'!$F$5 -> 8.86 | C12: ='9'!$F$6 -> 5.36 | D12: ='9'!$F$7 -> 3.28 | E12: ='9'!$F$8 -> 3.54 | F12: ='9'!$F$9 | G12: ='9'!$F$10 | H12: ='9'!$F$11 -> 4.64 | I12: ='9'!$F$12 -> 5.39 | J12: ='9'!$F$13 -> 3.4 | K12: ='9'!$F$14 | L12: ='9'!$F$15 -> 5.36 | M12: ='9'!$F$16 -> 3.67 | N12: ='9'!$F$17 -> 5.74 | O12: ='9'!$F$18 -> 6.5 | P12: ='9'!$F$19 | Q12: ='9'!$F$20 -> 3.61 | R12: ='9'!$F$21 | S12: ='9'!$F$22 -> 4.16 | T12: ='9'!$F$23 -> 3.82 | U12: ='9'!$F$24 -> 4.77 | V12: ='9'!$F$25 -> 2.71 | W12: ='9'!$F$26 -> 44.81 | X12: ='9'!$F$27 -> 9.42 | Y12: ='9'!$F$28 -> 7.02 | Z12: ='9'!$F$29 -> 3.17 | AA12: ='9'!$F$30 -> 7 | AB12: ='9'!$F$31 | AC12: ='9'!$F$32 | AD12: ='9'!$F$33 -> 4.2
A13: Clarendon | B13: ='10'!$F$5 -> 10.33 | C13: ='10'!$F$6 -> 6.47 | D13: ='10'!$F$7 -> 5.25 | E13: ='10'!$F$8 -> 8.79 | F13: ='10'!$F$9 | G13: ='10'!$F$10 -> 6.33 | H13: ='10'!$F$11 -> 7.75 | I13: ='10'!$F$12 | J13: ='10'!$F$13 -> 3.82 | K13: ='10'!$F$14 | L13: ='10'!$F$15 -> 6.48 | M13: ='10'!$F$16 -> 6.1 | N13: ='10'!$F$17 -> 4.32 | O13: ='10'!$F$18 | P13: ='10'!$F$19 | Q13: ='10'!$F$20 -> 3.97 | R13: ='10'!$F$21 | S13: ='10'!$F$22 -> 6.48 | T13: ='10'!$F$23 -> 4.63 | U13: ='10'!$F$24 | V13: ='10'!$F$25 | W13: ='10'!$F$26 | X13: ='10'!$F$27 -> 11.65 | Y13: ='10'!$F$28 -> 6.02 | Z13: ='10'!$F$29 -> 5.7 | AA13: ='10'!$F$30 -> 6.97 | AB13: ='10'!$F$31 | AC13: ='10'!$F$32 | AD13: ='10'!$F$33 -> 6.54
A14: Coastal Bend | B14: ='11'!$F$5 -> 3.06 | C14: ='11'!$F$6 -> 4.95 | D14: ='11'!$F$7 -> 5.14 | E14: ='11'!$F$8 -> 6.66 | F14: ='11'!$F$9 | G14: ='11'!$F$10 -> 4.63 | H14: ='11'!$F$11 -> 4.63 | I14: ='11'!$F$12 -> 4.91 | J14: ='11'!$F$13 -> 5.01 | K14: ='11'!$F$14 | L14: ='11'!$F$15 -> 3.82 | M14: ='11'!$F$16 -> 4.86 | N14: ='11'!$F$17 -> 5.41 | O14: ='11'!$F$18 -> 4.41 | P14: ='11'!$F$19 -> 10.18 | Q14: ='11'!$F$20 -> 3.91 | R14: ='11'!$F$21 | S14: ='11'!$F$22 -> 4.49 | T14: ='11'!$F$23 -> 4.25 | U14: ='11'!$F$24 -> 5.64 | V14: ='11'!$F$25 -> 21.61 | W14: ='11'!$F$26 -> 5.05 | X14: ='11'!$F$27 -> 4.9 | Y14: ='11'!$F$28 -> 7.44 | Z14: ='11'!$F$29 -> 4.61 | AA14: ='11'!$F$30 -> 6.94 | AB14: ='11'!$F$31 | AC14: ='11'!$F$32 | AD14: ='11'!$F$33 -> 5.02
A15: College Of The Mainland | B15: ='12'!$F$5 -> 12.62 | C15: ='12'!$F$6 -> 22.57 | D15: ='12'!$F$7 -> 7.95 | E15: ='12'!$F$8 -> 10.84 | F15: ='12'!$F$9 | G15: ='12'!$F$10 -> 58.86 | H15: ='12'!$F$11 -> 15.65 | I15: ='12'!$F$12 -> 9.81 | J15: ='12'!$F$13 -> 11.42 | K15: ='12'!$F$14 | L15: ='12'!$F$15 -> 10.1 | M15: ='12'!$F$16 -> 8.38 | N15: ='12'!$F$17 -> 8.21 | O15: ='12'!$F$18 -> 33.22 | P15: ='12'!$F$19 | Q15: ='12'!$F$20 -> 9.12 | R15: ='12'!$F$21 | S15: ='12'!$F$22 | T15: ='12'!$F$23 -> 7.89 | U15: ='12'!$F$24 | V15: ='12'!$F$25 -> 22.93 | W15: ='12'!$F$26 | X15: ='12'!$F$27 -> 10.67 | Y15: ='12'!$F$28 -> 8.07 | Z15: ='12'!$F$29 -> 8.56 | AA15: ='12'!$F$30 -> 12.22 | AB15: ='12'!$F$31 | AC15: ='12'!$F$32 | AD15: ='12'!$F$33 -> 10.12
A16: Collin | B16: ='13'!$F$5 -> 5.74 | C16: ='13'!$F$6 -> 9.98 | D16: ='13'!$F$7 -> 5.96 | E16: ='13'!$F$8 -> 7.4 | F16: ='13'!$F$9 -> 7.87 | G16: ='13'!$F$10 -> 7.36 | H16: ='13'!$F$11 -> 5.89 | I16: ='13'!$F$12 -> 7.87 | J16: ='13'!$F$13 -> 6.1 | K16: ='13'!$F$14 | L16: ='13'!$F$15 -> 12 | M16: ='13'!$F$16 -> 6.01 | N16: ='13'!$F$17 -> 6.79 | O16: ='13'!$F$18 -> 9.23 | P16: ='13'!$F$19 -> 19.95 | Q16: ='13'!$F$20 -> 6.62 | R16: ='13'!$F$21 -> 9.33 | S16: ='13'!$F$22 | T16: ='13'!$F$23 -> 5.11 | U16: ='13'!$F$24 | V16: ='13'!$F$25 | W16: ='13'!$F$26 -> 6.28 | X16: ='13'!$F$27 -> 7.42 | Y16: ='13'!$F$28 -> 8.24 | Z16: ='13'!$F$29 -> 5.18 | AA16: ='13'!$F$30 -> 8.28 | AB16: ='13'!$F$31 | AC16: ='13'!$F$32 | AD16: ='13'!$F$33 -> 6.37
A17: Dallas | B17: ='14'!$F$5 -> 15.4 | C17: ='14'!$F$6 -> 5.44 | D17: ='14'!$F$7 -> 6.4 | E17: ='14'!$F$8 -> 7.39 | F17: ='14'!$F$9 -> 9.74 | G17: ='14'!$F$10 -> 11.86 | H17: ='14'!$F$11 -> 8.52 | I17: ='14'!$F$12 -> 13.7 | J17: ='14'!$F$13 -> 5.45 | K17: ='14'!$F$14 -> 5.71 | L17: ='14'!$F$15 -> 5.57 | M17: ='14'!$F$16 -> 6.93 | N17: ='14'!$F$17 -> 6.81 | O17: ='14'!$F$18 -> 10.96 | P17: ='14'!$F$19 | Q17: ='14'!$F$20 -> 6.97 | R17: ='14'!$F$21 -> 31.43 | S17: ='14'!$F$22 -> 11.37 | T17: ='14'!$F$23 -> 6.01 | U17: ='14'!$F$24 -> 8.94 | V17: ='14'!$F$25 -> 5.29 | W17: ='14'!$F$26 -> 32.09 | X17: ='14'!$F$27 -> 8.1 | Y17: ='14'!$F$28 -> 5.78 | Z17: ='14'!$F$29 -> 5.88 | AA17: ='14'!$F$30 -> 8.54 | AB17: ='14'!$F$31 | AC17: ='14'!$F$32 | AD17: ='14'!$F$33 -> 7.02
A18: Del Mar | B18: ='15'!$F$5 | C18: ='15'!$F$6 -> 6.93 | D18: ='15'!$F$7 -> 7.47 | E18: ='15'!$F$8 -> 8.74 | F18: ='15'!$F$9 | G18: ='15'!$F$10 -> 8.17 | H18: ='15'!$F$11 -> 7.88 | I18: ='15'!$F$12 -> 6.26 | J18: ='15'!$F$13 -> 7.58 | K18: ='15'!$F$14 -> 7.54 | L18: ='15'!$F$15 -> 8.1 | M18: ='15'!$F$16 -> 9.02 | N18: ='15'!$F$17 -> 7.59 | O18: ='15'!$F$18 -> 9.65 | P18: ='15'!$F$19 -> 14.19 | Q18: ='15'!$F$20 -> 7.98 | R18: ='15'!$F$21 -> 13.29 | S18: ='15'!$F$22 -> 9.44 | T18: ='15'!$F$23 -> 7.74 | U18: ='15'!$F$24 -> 8.32 | V18: ='15'!$F$25 -> 7.99 | W18: ='15'!$F$26 -> 8.56 | X18: ='15'!$F$27 -> 8.09 | Y18: ='15'!$F$28 -> 7.02 | Z18: ='15'!$F$29 -> 7.58 | AA18: ='15'!$F$30 -> 11.76 | AB18: ='15'!$F$31 | AC18: ='15'!$F$32 | AD18: ='15'!$F$33 -> 8.31
A19: El Paso | B19: ='16'!$F$5 | C19: ='16'!$F$6 -> 19.8 | D19: ='16'!$F$7 -> 6.16 | E19: ='16'!$F$8 -> 6.58 | F19: ='16'!$F$9 | G19: ='16'!$F$10 -> 19.34 | H19: ='16'!$F$11 -> 8.26 | I19: ='16'!$F$12 | J19: ='16'!$F$13 -> 4.61 | K19: ='16'!$F$14 | L19: ='16'!$F$15 | M19: ='16'!$F$16 -> 7.09 | N19: ='16'!$F$17 -> 8.78 | O19: ='16'!$F$18 -> 14.18 | P19: ='16'!$F$19 -> 14.19 | Q19: ='16'!$F$20 -> 9.84 | R19: ='16'!$F$21 | S19: ='16'!$F$22 | T19: ='16'!$F$23 -> 5.8 | U19: ='16'!$F$24 -> 10.71 | V19: ='16'!$F$25 | W19: ='16'!$F$26 -> 6.09 | X19: ='16'!$F$27 -> 15.65 | Y19: ='16'!$F$28 -> 7.04 | Z19: ='16'!$F$29 -> 6.15 | AA19: ='16'!$F$30 -> 6.59 | AB19: ='16'!$F$31 | AC19: ='16'!$F$32 | AD19: ='16'!$F$33 -> 7.02
A20: Frank Phillips | B20: ='17'!$F$5 -> 8.14 | C20: ='17'!$F$6 -> 4.12 | D20: ='17'!$F$7 -> 7.29 | E20: ='17'!$F$8 -> 5.47 | F20: ='17'!$F$9 | G20: ='17'!$F$10 | H20: ='17'!$F$11 -> 11.63 | I20: ='17'!$F$12 -> 16.84 | J20: ='17'!$F$13 -> 4.81 | K20: ='17'!$F$14 | L20: ='17'!$F$15 -> 4 | M20: ='17'!$F$16 -> 4.89 | N20: ='17'!$F$17 -> 5.21 | O20: ='17'!$F$18 | P20: ='17'!$F$19 | Q20: ='17'!$F$20 -> 7.76 | R20: ='17'!$F$21 | S20: ='17'!$F$22 -> 9.26 | T20: ='17'!$F$23 -> 5.06 | U20: ='17'!$F$24 -> 5.87 | V20: ='17'!$F$25 -> 8.89 | W20: ='17'!$F$26 -> 21 | X20: ='17'!$F$27 -> 8.33 | Y20: ='17'!$F$28 -> 6.71 | Z20: ='17'!$F$29 -> 6.22 | AA20: ='17'!$F$30 -> 6.45 | AB20: ='17'!$F$31 | AC20: ='17'!$F$32 | AD20: ='17'!$F$33 -> 6.65
A21: Galveston | B21: ='18'!$F$5 | C21: ='18'!$F$6 -> 7.48 | D21: ='18'!$F$7 -> 8.08 | E21: ='18'!$F$8 -> 10.57 | F21: ='18'!$F$9 | G21: ='18'!$F$10 -> 1087.17 | H21: ='18'!$F$11 -> 12.64 | I21: ='18'!$F$12 | J21: ='18'!$F$13 -> 9.58 | K21: ='18'!$F$14 | L21: ='18'!$F$15 -> 27.33 | M21: ='18'!$F$16 -> 6.71 | N21: ='18'!$F$17 -> 5.69 | O21: ='18'!$F$18 -> 10.87 | P21: ='18'!$F$19 | Q21: ='18'!$F$20 -> 8.45 | R21: ='18'!$F$21 | S21: ='18'!$F$22 -> 8.65 | T21: ='18'!$F$23 -> 6.06 | U21: ='18'!$F$24 | V21: ='18'!$F$25 -> 15.39 | W21: ='18'!$F$26 | X21: ='18'!$F$27 -> 9.42 | Y21: ='18'!$F$28 -> 6.72 | Z21: ='18'!$F$29 -> 7.53 | AA21: ='18'!$F$30 -> 8.82 | AB21: ='18'!$F$31 | AC21: ='18'!$F$32 | AD21: ='18'!$F$33 -> 8.36
A22: Grayson | B22: ='19'!$F$5 -> 6.4 | C22: ='19'!$F$6 -> 7.84 | D22: ='19'!$F$7 -> 4.71 | E22: ='19'!$F$8 -> 6.29 | F22: ='19'!$F$9 | G22: ='19'!$F$10 -> 2.41 | H22: ='19'!$F$11 -> 7.46 | I22: ='19'!$F$12 | J22: ='19'!$F$13 -> 4.24 | K22: ='19'!$F$14 -> 2.41 | L22: ='19'!$F$15 -> 6.38 | M22: ='19'!$F$16 -> 5.22 | N22: ='19'!$F$17 -> 6.69 | O22: ='19'!$F$18 -> 7.75 | P22: ='19'!$F$19 | Q22: ='19'!$F$20 -> 6.13 | R22: ='19'!$F$21 | S22: ='19'!$F$22 -> 5.74 | T22: ='19'!$F$23 -> 4.69 | U22: ='19'!$F$24 -> 9.47 | V22: ='19'!$F$25 | W22: ='19'!$F$26 -> 7.52 | X22: ='19'!$F$27 -> 10.85 | Y22: ='19'!$F$28 -> 14.74 | Z22: ='19'!$F$29 -> 4.68 | AA22: ='19'!$F$30 -> 5.91 | AB22: ='19'!$F$31 | AC22: ='19'!$F$32 | AD22: ='19'!$F$33 -> 5.77
A23: Hill | B23: ='20'!$F$5 -> 7.86 | C23: ='20'!$F$6 -> 6.08 | D23: ='20'!$F$7 -> 4.3 | E23: ='20'!$F$8 -> 2.89 | F23: ='20'!$F$9 | G23: ='20'!$F$10 -> 11.62 | H23: ='20'!$F$11 -> 5.39 | I23: ='20'!$F$12 -> 13.74 | J23: ='20'!$F$13 -> 3.47 | K23: ='20'!$F$14 | L23: ='20'!$F$15 -> 6.05 | M23: ='20'!$F$16 -> 4.03 | N23: ='20'!$F$17 -> 4.31 | O23: ='20'!$F$18 | P23: ='20'!$F$19 | Q23: ='20'!$F$20 -> 3.62 | R23: ='20'!$F$21 | S23: ='20'!$F$22 -> 6.05 | T23: ='20'!$F$23 -> 3.84 | U23: ='20'!$F$24 -> 6.06 | V23: ='20'!$F$25 | W23: ='20'!$F$26 -> 39.92 | X23: ='20'!$F$27 -> 6.09 | Y23: ='20'!$F$28 -> 5.03 | Z23: ='20'!$F$29 -> 4.23 | AA23: ='20'!$F$30 -> 4.93 | AB23: ='20'!$F$31 | AC23: ='20'!$F$32 | AD23: ='20'!$F$33 -> 4.5
A24: Houston | B24: ='21'!$F$5 -> 8.13 | C24: ='21'!$F$6 -> 5.57 | D24: ='21'!$F$7 -> 7.13 | E24: ='21'!$F$8 -> 7.63 | F24: ='21'!$F$9 | G24: ='21'!$F$10 -> 13.93 | H24: ='21'!$F$11 -> 23.62 | I24: ='21'!$F$12 -> 7.42 | J24: ='21'!$F$13 -> 7.3 | K24: ='21'!$F$14 -> 11.93 | L24: ='21'!$F$15 -> 12.23 | M24: ='21'!$F$16 -> 7.12 | N24: ='21'!$F$17 -> 7.45 | O24: ='21'!$F$18 -> 12.58 | P24: ='21'!$F$19 | Q24: ='21'!$F$20 -> 8.51 | R24: ='21'!$F$21 -> 16.04 | S24: ='21'!$F$22 -> 11.69 | T24: ='21'!$F$23 -> 6.9 | U24: ='21'!$F$24 -> 9.74 | V24: ='21'!$F$25 -> 10.93 | W24: ='21'!$F$26 -> 23.41 | X24: ='21'!$F$27 -> 11.46 | Y24: ='21'!$F$28 -> 12.31 | Z24: ='21'!$F$29 -> 6.76 | AA24: ='21'!$F$30 -> 9.09 | AB24: ='21'!$F$31 | AC24: ='21'!$F$32 | AD24: ='21'!$F$33 -> 8.26
A25: Howard | B25: ='22'!$F$5 -> 6.7 | C25: ='22'!$F$6 -> 5.82 | D25: ='22'!$F$7 -> 6.74 | E25: ='22'!$F$8 -> 5.5 | F25: ='22'!$F$9 | G25: ='22'!$F$10 -> 3.6 | H25: ='22'!$F$11 -> 6.3 | I25: ='22'!$F$12 -> 6 | J25: ='22'!$F$13 -> 5.53 | K25: ='22'!$F$14 -> 8.31 | L25: ='22'!$F$15 -> 6.39 | M25: ='22'!$F$16 -> 5.35 | N25: ='22'!$F$17 -> 7.08 | O25: ='22'!$F$18 -> 12.62 | P25: ='22'!$F$19 -> 14.31 | Q25: ='22'!$F$20 -> 6.06 | R25: ='22'!$F$21 -> 8.88 | S25: ='22'!$F$22 -> 7.72 | T25: ='22'!$F$23 -> 5.72 | U25: ='22'!$F$24 -> 5.52 | V25: ='22'!$F$25 -> 5.16 | W25: ='22'!$F$26 -> 3.94 | X25: ='22'!$F$27 -> 13.67 | Y25: ='22'!$F$28 -> 4.65 | Z25: ='22'!$F$29 -> 5.18 | AA25: ='22'!$F$30 -> 6.87 | AB25: ='22'!$F$31 | AC25: ='22'!$F$32 | AD25: ='22'!$F$33 -> 6.07
A26: Kilgore | B26: ='23'!$F$5 -> 9.12 | C26: ='23'!$F$6 -> 6.07 | D26: ='23'!$F$7 -> 5.29 | E26: ='23'!$F$8 -> 5.2 | F26: ='23'!$F$9 | G26: ='23'!$F$10 -> 12.16 | H26: ='23'!$F$11 -> 4.64 | I26: ='23'!$F$12 -> 7.82 | J26: ='23'!$F$13 -> 3.44 | K26: ='23'!$F$14 -> 29.84 | L26: ='23'!$F$15 -> 5.92 | M26: ='23'!$F$16 -> 4.46 | N26: ='23'!$F$17 -> 9.36 | O26: ='23'!$F$18 -> 7.95 | P26: ='23'!$F$19 | Q26: ='23'!$F$20 -> 5.53 | R26: ='23'!$F$21 | S26: ='23'!$F$22 -> 5.03 | T26: ='23'!$F$23 -> 4.17 | U26: ='23'!$F$24 -> 5.66 | V26: ='23'!$F$25 -> 10.21 | W26: ='23'!$F$26 | X26: ='23'!$F$27 -> 6.79 | Y26: ='23'!$F$28 -> 7.06 | Z26: ='23'!$F$29 -> 4.1 | AA26: ='23'!$F$30 -> 6.01 | AB26: ='23'!$F$31 | AC26: ='23'!$F$32 | AD26: ='23'!$F$33 -> 5.27
A27: Laredo | B27: ='24'!$F$5 | C27: ='24'!$F$6 | D27: ='24'!$F$7 -> 7.1 | E27: ='24'!$F$8 -> 8.02 | F27: ='24'!$F$9 | G27: ='24'!$F$10 -> 6.76 | H27: ='24'!$F$11 -> 7.65 | I27: ='24'!$F$12 -> 11.49 | J27: ='24'!$F$13 | K27: ='24'!$F$14 | L27: ='24'!$F$15 | M27: ='24'!$F$16 -> 7.9 | N27: ='24'!$F$17 -> 7.43 | O27: ='24'!$F$18 -> 12.76 | P27: ='24'!$F$19 | Q27: ='24'!$F$20 -> 8.94 | R27: ='24'!$F$21 | S27: ='24'!$F$22 -> 10.84 | T27: ='24'!$F$23 -> 6.61 | U27: ='24'!$F$24 -> 9.17 | V27: ='24'!$F$25 | W27: ='24'!$F$26 -> 7.65 | X27: ='24'!$F$27 -> 6.46 | Y27: ='24'!$F$28 -> 7.74 | Z27: ='24'!$F$29 -> 6.21 | AA27: ='24'!$F$30 -> 8.08 | AB27: ='24'!$F$31 | AC27: ='24'!$F$32 | AD27: ='24'!$F$33 -> 7.65
A28: Lee | B28: ='25'!$F$5 -> 5.83 | C28: ='25'!$F$6 -> 22.83 | D28: ='25'!$F$7 -> 7.79 | E28: ='25'!$F$8 -> 7.07 | F28: ='25'!$F$9 -> 12.89 | G28: ='25'!$F$10 -> 5.12 | H28: ='25'!$F$11 -> 8.12 | I28: ='25'!$F$12 -> 5.79 | J28: ='25'!$F$13 -> 8.17 | K28: ='25'!$F$14 | L28: ='25'!$F$15 | M28: ='25'!$F$16 -> 8.96 | N28: ='25'!$F$17 -> 8.48 | O28: ='25'!$F$18 -> 9.6 | P28: ='25'!$F$19 | Q28: ='25'!$F$20 -> 8.32 | R28: ='25'!$F$21 | S28: ='25'!$F$22 -> 9.81 | T28: ='25'!$F$23 -> 7.97 | U28: ='25'!$F$24 -> 6.03 | V28: ='25'!$F$25 -> 6.03 | W28: ='25'!$F$26 -> 6.22 | X28: ='25'!$F$27 -> 7.94 | Y28: ='25'!$F$28 -> 7.77 | Z28: ='25'!$F$29 -> 7.06 | AA28: ='25'!$F$30 -> 9.02 | AB28: ='25'!$F$31 | AC28: ='25'!$F$32 | AD28: ='25'!$F$33 -> 7.72
A29: Lonestar | B29: ='26'!$F$5 -> 7.23 | C29: ='26'!$F$6 -> 9.25 | D29: ='26'!$F$7 -> 7.12 | E29: ='26'!$F$8 -> 8.74 | F29: ='26'!$F$9 -> 11.77 | G29: ='26'!$F$10 -> 7.56 | H29: ='26'!$F$11 -> 8.29 | I29: ='26'!$F$12 -> 8.83 | J29: ='26'!$F$13 -> 6.29 | K29: ='26'!$F$14 -> 8.83 | L29: ='26'!$F$15 -> 8.83 | M29: ='26'!$F$16 -> 7.02 | N29: ='26'!$F$17 -> 5.98 | O29: ='26'!$F$18 -> 12.76 | P29: ='26'!$F$19 | Q29: ='26'!$F$20 -> 7.08 | R29: ='26'!$F$21 -> 13.13 | S29: ='26'!$F$22 -> 7.85 | T29: ='26'!$F$23 -> 6.14 | U29: ='26'!$F$24 -> 7.22 | V29: ='26'!$F$25 -> 12.09 | W29: ='26'!$F$26 -> 11.77 | X29: ='26'!$F$27 -> 7.94 | Y29: ='26'!$F$28 -> 7.8 | Z29: ='26'!$F$29 -> 6.17 | AA29: ='26'!$F$30 -> 8.3 | AB29: ='26'!$F$31 | AC29: ='26'!$F$32 | AD29: ='26'!$F$33 -> 7.17
A30: Mclennan | B30: ='27'!$F$5 | C30: ='27'!$F$6 -> 59.51 | D30: ='27'!$F$7 -> 4.55 | E30: ='27'!$F$8 -> 5.24 | F30: ='27'!$F$9 | G30: ='27'!$F$10 -> 4.24 | H30: ='27'!$F$11 -> 11.37 | I30: ='27'!$F$12 -> 26.68 | J30: ='27'!$F$13 -> 7.69 | K30: ='27'!$F$14 | L30: ='27'!$F$15 | M30: ='27'!$F$16 -> 5.78 | N30: ='27'!$F$17 -> 4.8 | O30: ='27'!$F$18 -> 8.87 | P30: ='27'!$F$19 | Q30: ='27'!$F$20 -> 6.2 | R30: ='27'!$F$21 -> 7.26 | S30: ='27'!$F$22 -> 4.73 | T30: ='27'!$F$23 -> 4.72 | U30: ='27'!$F$24 | V30: ='27'!$F$25 -> 2.36 | W30: ='27'!$F$26 | X30: ='27'!$F$27 -> 8.36 | Y30: ='27'!$F$28 -> 7.28 | Z30: ='27'!$F$29 -> 3.94 | AA30: ='27'!$F$30 -> 6.31 | AB30: ='27'!$F$31 | AC30: ='27'!$F$32 | AD30: ='27'!$F$33 -> 6.04
A31: Midland | B31: ='28'!$F$5 -> 10.54 | C31: ='28'!$F$6 -> 8.94 | D31: ='28'!$F$7 -> 6.33 | E31: ='28'!$F$8 -> 7.65 | F31: ='28'!$F$9 -> 13.8 | G31: ='28'!$F$10 -> 15.39 | H31: ='28'!$F$11 -> 7.72 | I31: ='28'!$F$12 | J31: ='28'!$F$13 -> 5.52 | K31: ='28'!$F$14 -> 4.66 | L31: ='28'!$F$15 -> 11.06 | M31: ='28'!$F$16 -> 7.55 | N31: ='28'!$F$17 -> 6.48 | O31: ='28'!$F$18 -> 9.85 | P31: ='28'!$F$19 | Q31: ='28'!$F$20 -> 8.51 | R31: ='28'!$F$21 -> 10.98 | S31: ='28'!$F$22 -> 10.95 | T31: ='28'!$F$23 -> 6.7 | U31: ='28'!$F$24 -> 8.2 | V31: ='28'!$F$25 -> 13.75 | W31: ='28'!$F$26 | X31: ='28'!$F$27 -> 11.28 | Y31: ='28'!$F$28 -> 6.78 | Z31: ='28'!$F$29 -> 6.65 | AA31: ='28'!$F$30 -> 8.68 | AB31: ='28'!$F$31 | AC31: ='28'!$F$32 | AD31: ='28'!$F$33 -> 7.84
A32: Navarro | B32: ='29'!$F$5 -> 11.12 | C32: ='29'!$F$6 -> 4.74 | D32: ='29'!$F$7 -> 4.25 | E32: ='29'!$F$8 -> 4.6 | F32: ='29'!$F$9 | G32: ='29'!$F$10 -> 6.95 | H32: ='29'!$F$11 -> 4.54 | I32: ='29'!$F$12 -> 4.08 | J32: ='29'!$F$13 -> 4.4 | K32: ='29'!$F$14 -> 14.44 | L32: ='29'!$F$15 -> 3.91 | M32: ='29'!$F$16 -> 4.35 | N32: ='29'!$F$17 -> 3.92 | O32: ='29'!$F$18 -> 8.56 | P32: ='29'!$F$19 | Q32: ='29'!$F$20 -> 5.42 | R32: ='29'!$F$21 | S32: ='29'!$F$22 -> 5.63 | T32: ='29'!$F$23 -> 4.48 | U32: ='29'!$F$24 | V32: ='29'!$F$25 -> 7.06 | W32: ='29'!$F$26 | X32: ='29'!$F$27 -> 5.27 | Y32: ='29'!$F$28 -> 5.84 | Z32: ='29'!$F$29 -> 4.33 | AA32: ='29'!$F$30 -> 6.03 | AB32: ='29'!$F$31 | AC32: ='29'!$F$32 | AD32: ='29'!$F$33 -> 4.87
A33: North Central Texas | B33: ='30'!$F$5 -> 8.43 | C33: ='30'!$F$6 -> 9.45 | D33: ='30'!$F$7 -> 4.03 | E33: ='30'!$F$8 -> 4.23 | F33: ='30'!$F$9 | G33: ='30'!$F$10 -> 22.77 | H33: ='30'!$F$11 -> 7.53 | I33: ='30'!$F$12 | J33: ='30'!$F$13 -> 3.3 | K33: ='30'!$F$14 | L33: ='30'!$F$15 -> 3.48 | M33: ='30'!$F$16 -> 4.54 | N33: ='30'!$F$17 -> 5.6 | O33: ='30'!$F$18 -> 6.1 | P33: ='30'!$F$19 | Q33: ='30'!$F$20 -> 6.53 | R33: ='30'!$F$21 | S33: ='30'!$F$22 -> 4.77 | T33: ='30'!$F$23 -> 3.98 | U33: ='30'!$F$24 | V33: ='30'!$F$25 | W33: ='30'!$F$26 | X33: ='30'!$F$27 -> 5.91 | Y33: ='30'!$F$28 -> 5.81 | Z33: ='30'!$F$29 -> 3.7 | AA33: ='30'!$F$30 -> 4.79 | AB33: ='30'!$F$31 | AC33: ='30'!$F$32 | AD33: ='30'!$F$33 -> 4.66
A34: Northeast Texas | B34: ='31'!$F$5 -> 5.9 | C34: ='31'!$F$6 -> 33.16 | D34: ='31'!$F$7 -> 3.15 | E34: ='31'!$F$8 -> 6.23 | F34: ='31'!$F$9 | G34: ='31'!$F$10 -> 12.56 | H34: ='31'!$F$11 -> 7.55 | I34: ='31'!$F$12 -> 112.33 | J34: ='31'!$F$13 -> 3.95 | K34: ='31'!$F$14 | L34: ='31'!$F$15 | M34: ='31'!$F$16 -> 5.33 | N34: ='31'!$F$17 -> 6.88 | O34: ='31'!$F$18 -> 9.08 | P34: ='31'!$F$19 | Q34: ='31'!$F$20 -> 4.12 | R34: ='31'!$F$21 | S34: ='31'!$F$22 -> 7 | T34: ='31'!$F$23 -> 5.71 | U34: ='31'!$F$24 -> 9.11 | V34: ='31'!$F$25 -> 9.11 | W34: ='31'!$F$26 -> 8.43 | X34: ='31'!$F$27 -> 5.79 | Y34: ='31'!$F$28 -> 7.31 | Z34: ='31'!$F$29 -> 4.87 | AA34: ='31'!$F$30 -> 9.28 | AB34: ='31'!$F$31 | AC34: ='31'!$F$32 | AD34: ='31'!$F$33 -> 6.37
A35: Odessa | B35: ='32'!$F$5 -> 7.03 | C35: ='32'!$F$6 -> 7.48 | D35: ='32'!$F$7 -> 5.09 | E35: ='32'!$F$8 -> 6.19 | F35: ='32'!$F$9 | G35: ='32'!$F$10 -> 6.81 | H35: ='32'!$F$11 -> 5.87 | I35: ='32'!$F$12 -> 6.29 | J35: ='32'!$F$13 -> 5.71 | K35: ='32'!$F$14 -> 7.01 | L35: ='32'!$F$15 -> 6.79 | M35: ='32'!$F$16 -> 5.24 | N35: ='32'!$F$17 -> 5.73 | O35: ='32'!$F$18 -> 9.22 | P35: ='32'!$F$19 | Q35: ='32'!$F$20 -> 6.9 | R35: ='32'!$F$21 -> 10.81 | S35: ='32'!$F$22 -> 5.77 | T35: ='32'!$F$23 -> 5.5 | U35: ='32'!$F$24 -> 7.64 | V35: ='32'!$F$25 -> 7.51 | W35: ='32'!$F$26 -> 7.73 | X35: ='32'!$F$27 -> 5.35 | Y35: ='32'!$F$28 -> 5.62 | Z35: ='32'!$F$29 -> 5.46 | AA35: ='32'!$F$30 -> 9.04 | AB35: ='32'!$F$31 | AC35: ='32'!$F$32 | AD35: ='32'!$F$33 -> 6.07
A36: Panola | B36: ='33'!$F$5 -> 11.35 | C36: ='33'!$F$6 -> 10.94 | D36: ='33'!$F$7 -> 6.53 | E36: ='33'!$F$8 -> 10.1 | F36: ='33'!$F$9 | G36: ='33'!$F$10 -> 13.02 | H36: ='33'!$F$11 -> 9.11 | I36: ='33'!$F$12 -> 6.81 | J36: ='33'!$F$13 -> 7.02 | K36: ='33'!$F$14 | L36: ='33'!$F$15 -> 28.98 | M36: ='33'!$F$16 -> 6.69 | N36: ='33'!$F$17 -> 8.12 | O36: ='33'!$F$18 -> 11.28 | P36: ='33'!$F$19 | Q36: ='33'!$F$20 -> 8.55 | R36: ='33'!$F$21 | S36: ='33'!$F$22 -> 7.27 | T36: ='33'!$F$23 -> 7.44 | U36: ='33'!$F$24 | V36: ='33'!$F$25 | W36: ='33'!$F$26 -> 36.13 | X36: ='33'!$F$27 -> 7.45 | Y36: ='33'!$F$28 -> 7.57 | Z36: ='33'!$F$29 -> 6.5 | AA36: ='33'!$F$30 -> 9.15 | AB36: ='33'!$F$31 | AC36: ='33'!$F$32 | AD36: ='33'!$F$33 -> 8.01
A37: Paris | B37: ='34'!$F$5 -> 11.15 | C37: ='34'!$F$6 -> 7.73 | D37: ='34'!$F$7 -> 5.17 | E37: ='34'!$F$8 -> 5.6 | F37: ='34'!$F$9 | G37: ='34'!$F$10 -> 28.84 | H37: ='34'!$F$11 -> 5.3 | I37: ='34'!$F$12 | J37: ='34'!$F$13 -> 7.64 | K37: ='34'!$F$14 | L37: ='34'!$F$15 -> 5.87 | M37: ='34'!$F$16 -> 5.93 | N37: ='34'!$F$17 -> 5.54 | O37: ='34'!$F$18 -> 12.88 | P37: ='34'!$F$19 | Q37: ='34'!$F$20 -> 4.85 | R37: ='34'!$F$21 | S37: ='34'!$F$22 -> 8.94 | T37: ='34'!$F$23 -> 4.96 | U37: ='34'!$F$24 | V37: ='34'!$F$25 -> 18.93 | W37: ='34'!$F$26 -> 7.47 | X37: ='34'!$F$27 -> 6.01 | Y37: ='34'!$F$28 -> 3.78 | Z37: ='34'!$F$29 -> 5.35 | AA37: ='34'!$F$30 -> 7.14 | AB37: ='34'!$F$31 | AC37: ='34'!$F$32 | AD37: ='34'!$F$33 -> 6.16
A38: Ranger | B38: ='35'!$F$5 | C38: ='35'!$F$6 -> 6.74 | D38: ='35'!$F$7 -> 4.68 | E38: ='35'!$F$8 -> 6.84 | F38: ='35'!$F$9 | G38: ='35'!$F$10 -> 3.5 | H38: ='35'!$F$11 -> 5.82 | I38: ='35'!$F$12 | J38: ='35'!$F$13 -> 5.34 | K38: ='35'!$F$14 | L38: ='35'!$F$15 | M38: ='35'!$F$16 -> 5.14 | N38: ='35'!$F$17 -> 19.71 | O38: ='35'!$F$18 | P38: ='35'!$F$19 | Q38: ='35'!$F$20 -> 5 | R38: ='35'!$F$21 | S38: ='35'!$F$22 -> 4.92 | T38: ='35'!$F$23 -> 5.52 | U38: ='35'!$F$24 -> 9.89 | V38: ='35'!$F$25 | W38: ='35'!$F$26 | X38: ='35'!$F$27 -> 12.93 | Y38: ='35'!$F$28 | Z38: ='35'!$F$29 -> 4.23 | AA38: ='35'!$F$30 -> 6.31 | AB38: ='35'!$F$31 | AC38: ='35'!$F$32 | AD38: ='35'!$F$33 -> 5.88
A39: San Jacinto | B39: ='36'!$F$5 -> 12.47 | C39: ='36'!$F$6 -> 5.02 | D39: ='36'!$F$7 -> 5.91 | E39: ='36'!$F$8 -> 6.85 | F39: ='36'!$F$9 -> 19.02 | G39: ='36'!$F$10 -> 9.43 | H39: ='36'!$F$11 -> 7.93 | I39: ='36'!$F$12 -> 4.93 | J39: ='36'!$F$13 -> 6.94 | K39: ='36'!$F$14 -> 11.74 | L39: ='36'!$F$15 -> 10.89 | M39: ='36'!$F$16 -> 6.45 | N39: ='36'!$F$17 -> 6.13 | O39: ='36'!$F$18 -> 8.76 | P39: ='36'!$F$19 | Q39: ='36'!$F$20 -> 8 | R39: ='36'!$F$21 -> 9.72 | S39: ='36'!$F$22 -> 6.76 | T39: ='36'!$F$23 -> 6.26 | U39: ='36'!$F$24 -> 8.55 | V39: ='36'!$F$25 -> 11.13 | W39: ='36'!$F$26 -> 3.94 | X39: ='36'!$F$27 -> 7.53 | Y39: ='36'!$F$28 -> 7.27 | Z39: ='36'!$F$29 -> 5.88 | AA39: ='36'!$F$30 -> 7.51 | AB39: ='36'!$F$31 | AC39: ='36'!$F$32 | AD39: ='36'!$F$33 -> 6.89
A40: South Plains | B40: ='37'!$F$5 -> 9.92 | C40: ='37'!$F$6 -> 8.27 | D40: ='37'!$F$7 -> 4.98 | E40: ='37'!$F$8 -> 7.02 | F40: ='37'!$F$9 | G40: ='37'!$F$10 -> 6.74 | H40: ='37'!$F$11 -> 4.78 | I40: ='37'!$F$12 -> 5.88 | J40: ='37'!$F$13 -> 4.93 | K40: ='37'!$F$14 -> 11.66 | L40: ='37'!$F$15 -> 8.31 | M40: ='37'!$F$16 -> 5.04 | N40: ='37'!$F$17 -> 4.92 | O40: ='37'!$F$18 -> 6.77 | P40: ='37'!$F$19 | Q40: ='37'!$F$20 -> 6.1 | R40: ='37'!$F$21 -> 6.42 | S40: ='37'!$F$22 -> 5.38 | T40: ='37'!$F$23 -> 5.59 | U40: ='37'!$F$24 -> 4.97 | V40: ='37'!$F$25 -> 20.39 | W40: ='37'!$F$26 -> 26.44 | X40: ='37'!$F$27 -> 7.77 | Y40: ='37'!$F$28 -> 6.97 | Z40: ='37'!$F$29 -> 4.92 | AA40: ='37'!$F$30 -> 7.96 | AB40: ='37'!$F$31 | AC40: ='37'!$F$32 | AD40: ='37'!$F$33 -> 5.78
...

Sheet Discipline Analysis
A1: =Summary!A1 -> Community and Technical Colleges, Report of Fundable Operating Expenses, Fiscal Year (FY) 2003
A2: Discipline Analysis by Institution | X2: Discipline
A3: 29 | X3: Agriculture
X4: Architecture and Precision Production Trades
A5: Institution | B5: Contact Hours | C5: Total | E5: Faculty Salaries | G5: Library | I5: Institutional Support | K5: Student Services | M5: Departmental Operating Expense | O5: Instructional Administration | Q5: Organized Activities | S5: Equipment Depreciation | U5: Local Benefits | X5: Biology, Physical Sciences, and Science Technology
C6: Expense | D6: per Hour | E6: Expense | F6: per Hour | G6: Expense | H6: per Hour | I6: Expense | J6: per Hour | K6: Expense | L6: per Hour | M6: Expense | N6: per Hour | O6: Expense | P6: per Hour | Q6: Expense | R6: per Hour | S6: Expense | T6: per Hour | U6: Expense | V6: per Hour | X6: Business Management, Marketing, and Administrative Services
A7: Alamo | B7: =OFFSET('1'!$D$4,$A$3,0) -> 18861353 | C7: =OFFSET('1'!$E$4,$A$3,0) -> 1.4244558e+08 | D7: =OFFSET('1'!$F$4,$A$3,0) -> 7.55 | E7: =OFFSET('1'!$E$66,$A$3,0) -> 64902131 | F7: =OFFSET('1'!$F$66,$A$3,0) -> 3.44 | G7: =IFERROR('1'!$F$100*'Discipline Analysis'!$B7,"") -> 5847019.4 | H7: ='1'!$F$100 -> 0.31 | I7: =IFERROR('1'!$F$98*'Discipline Analysis'!$B7,"") -> 25651440 | J7: ='1'!$F$98 -> 1.36 | K7: =IFERROR('1'!$F$99*'Discipline Analysis'!$B7,"") -> 15089082 | L7: ='1'!$F$99 -> 0.8 | M7: =OFFSET('1'!$E$35,$A$3,0) -> 10718146 | N7: =OFFSET('1'!$F$35,$A$3,0) -> 0.57 | O7: =IFERROR('1'!$F$101*'Discipline Analysis'!$B7,"") -> 8298995.3 | P7: ='1'!$F$101 -> 0.44 | Q7: =IFERROR('1'!$F$102*'Discipline Analysis'!$B7,"") -> 377227.06 | R7: ='1'!$F$102 -> 0.02 | S7: =IFERROR('1'!$F$103*'Discipline Analysis'!$B7,"") -> 0 | T7: ='1'!$F$103 -> 0 | U7: =IFERROR('1'!$F$104*'Discipline Analysis'!$B7,"") -> 11694039 | V7: ='1'!$F$104 -> 0.62 | X7: Career Pilot
A8: Alvin | B8: =OFFSET('2'!$D$4,$A$3,0) -> 2395700 | C8: =OFFSET('2'!$E$4,$A$3,0) -> 16388766 | D8: =OFFSET('2'!$F$4,$A$3,0) -> 6.84 | E8: =OFFSET('2'!$E$66,$A$3,0) -> 7270811 | F8: =OFFSET('2'!$F$66,$A$3,0) -> 3.03 | G8: =IFERROR('2'!$F$100*'Discipline Analysis'!$B8,"") -> 479140 | H8: ='2'!$F$100 -> 0.2 | I8: =IFERROR('2'!$F$98*'Discipline Analysis'!$B8,"") -> 4120604 | J8: ='2'!$F$98 -> 1.72 | K8: =IFERROR('2'!$F$99*'Discipline Analysis'!$B8,"") -> 1317635 | L8: ='2'!$F$99 -> 0.55 | M8: =OFFSET('2'!$E$35,$A$3,0) -> 1592853 | N8: =OFFSET('2'!$F$35,$A$3,0) -> 0.66 | O8: =IFERROR('2'!$F$101*'Discipline Analysis'!$B8,"") -> 862452 | P8: ='2'!$F$101 -> 0.36 | Q8: =IFERROR('2'!$F$102*'Discipline Analysis'!$B8,"") | R8: ='2'!$F$102 | S8: =IFERROR('2'!$F$103*'Discipline Analysis'!$B8,"") | T8: ='2'!$F$103 | U8: =IFERROR('2'!$F$104*'Discipline Analysis'!$B8,"") -> 742667 | V8: ='2'!$F$104 -> 0.31 | X8: Communications
A9: Amarillo | B9: =OFFSET('3'!$D$4,$A$3,0) -> 4557502 | C9: =OFFSET('3'!$E$4,$A$3,0) -> 30374840 | D9: =OFFSET('3'!$F$4,$A$3,0) -> 6.66 | E9: =OFFSET('3'!$E$66,$A$3,0) -> 12143913 | F9: =OFFSET('3'!$F$66,$A$3,0) -> 2.66 | G9: =IFERROR('3'!$F$100*'Discipline Analysis'!$B9,"") -> 1093800.5 | H9: ='3'!$F$100 -> 0.24 | I9: =IFERROR('3'!$F$98*'Discipline Analysis'!$B9,"") -> 6790678 | J9: ='3'!$F$98 -> 1.49 | K9: =IFERROR('3'!$F$99*'Discipline Analysis'!$B9,"") -> 2688926.2 | L9: ='3'!$F$99 -> 0.59 | M9: =OFFSET('3'!$E$35,$A$3,0) -> 3477282 | N9: =OFFSET('3'!$F$35,$A$3,0) -> 0.76 | O9: =IFERROR('3'!$F$101*'Discipline Analysis'!$B9,"") -> 1184950.5 | P9: ='3'!$F$101 -> 0.26 | Q9: =IFERROR('3'!$F$102*'Discipline Analysis'!$B9,"") -> 319025.14 | R9: ='3'!$F$102 -> 0.07 | S9: =IFERROR('3'!$F$103*'Discipline Analysis'!$B9,"") | T9: ='3'!$F$103 | U9: =IFERROR('3'!$F$104*'Discipline Analysis'!$B9,"") -> 2643351.2 | V9: ='3'!$F$104 -> 0.58 | X9: Computer and Information Sciences
A10: Angelina | B10: =OFFSET('4'!$D$4,$A$3,0) -> 2446951 | C10: =OFFSET('4'!$E$4,$A$3,0) -> 11784710 | D10: =OFFSET('4'!$F$4,$A$3,0) -> 4.82 | E10: =OFFSET('4'!$E$66,$A$3,0) -> 6677243 | F10: =OFFSET('4'!$F$66,$A$3,0) -> 2.73 | G10: =IFERROR('4'!$F$100*'Discipline Analysis'!$B10,"") -> 342573.14 | H10: ='4'!$F$100 -> 0.14 | I10: =IFERROR('4'!$F$98*'Discipline Analysis'!$B10,"") -> 1541579.1 | J10: ='4'!$F$98 -> 0.63 | K10: =IFERROR('4'!$F$99*'Discipline Analysis'!$B10,"") -> 685146.28 | L10: ='4'!$F$99 -> 0.28 | M10: =OFFSET('4'!$E$35,$A$3,0) -> 839955 | N10: =OFFSET('4'!$F$35,$A$3,0) -> 0.34 | O10: =IFERROR('4'!$F$101*'Discipline Analysis'!$B10,"") -> 1296884 | P10: ='4'!$F$101 -> 0.53 | Q10: =IFERROR('4'!$F$102*'Discipline Analysis'!$B10,"") | R10: ='4'!$F$102 | S10: =IFERROR('4'!$F$103*'Discipline Analysis'!$B10,"") | T10: ='4'!$F$103 | U10: =IFERROR('4'!$F$104*'Discipline Analysis'!$B10,"") -> 367042.65 | V10: ='4'!$F$104 -> 0.15 | X10: Construction Trades
A11: Austin | B11: =OFFSET('5'!$D$4,$A$3,0) -> 11470713 | C11: =OFFSET('5'!$E$4,$A$3,0) -> 90033991 | D11: =OFFSET('5'!$F$4,$A$3,0) -> 7.85 | E11: =OFFSET('5'!$E$66,$A$3,0) -> 40874224 | F11: =OFFSET('5'!$F$66,$A$3,0) -> 3.56 | G11: =IFERROR('5'!$F$100*'Discipline Analysis'!$B11,"") -> 2523556.9 | H11: ='5'!$F$100 -> 0.22 | I11: =IFERROR('5'!$F$98*'Discipline Analysis'!$B11,"") -> 17894312 | J11: ='5'!$F$98 -> 1.56 | K11: =IFERROR('5'!$F$99*'Discipline Analysis'!$B11,"") -> 7685377.7 | L11: ='5'!$F$99 -> 0.67 | M11: =OFFSET('5'!$E$35,$A$3,0) -> 6573136 | N11: =OFFSET('5'!$F$35,$A$3,0) -> 0.57 | O11: =IFERROR('5'!$F$101*'Discipline Analysis'!$B11,"") -> 11011884 | P11: ='5'!$F$101 -> 0.96 | Q11: =IFERROR('5'!$F$102*'Discipline Analysis'!$B11,"") | R11: ='5'!$F$102 | S11: =IFERROR('5'!$F$103*'Discipline Analysis'!$B11,"") | T11: ='5'!$F$103 | U11: =IFERROR('5'!$F$104*'Discipline Analysis'!$B11,"") -> 3441213.9 | V11: ='5'!$F$104 -> 0.3 | X11: Consumer and Homemaking Education
A12: Blinn | B12: =OFFSET('6'!$D$4,$A$3,0) -> 6073151 | C12: =OFFSET('6'!$E$4,$A$3,0) -> 31537669 | D12: =OFFSET('6'!$F$4,$A$3,0) -> 5.19 | E12: =OFFSET('6'!$E$66,$A$3,0) -> 15468195 | F12: =OFFSET('6'!$F$66,$A$3,0) -> 2.55 | G12: =IFERROR('6'!$F$100*'Discipline Analysis'!$B12,"") -> 1032435.7 | H12: ='6'!$F$100 -> 0.17 | I12: =IFERROR('6'!$F$98*'Discipline Analysis'!$B12,"") -> 4190474.2 | J12: ='6'!$F$98 -> 0.69 | K12: =IFERROR('6'!$F$99*'Discipline Analysis'!$B12,"") -> 2732918 | L12: ='6'!$F$99 -> 0.45 | M12: =OFFSET('6'!$E$35,$A$3,0) -> 3094687 | N12: =OFFSET('6'!$F$35,$A$3,0) -> 0.51 | O12: =IFERROR('6'!$F$101*'Discipline Analysis'!$B12,"") -> 2550723.4 | P12: ='6'!$F$101 -> 0.42 | Q12: =IFERROR('6'!$F$102*'Discipline Analysis'!$B12,"") | R12: ='6'!$F$102 | S12: =IFERROR('6'!$F$103*'Discipline Analysis'!$B12,"") | T12: ='6'!$F$103 | U12: =IFERROR('6'!$F$104*'Discipline Analysis'!$B12,"") -> 2550723.4 | V12: ='6'!$F$104 -> 0.42 | X12: Engineering
A13: Brazosport | B13: =OFFSET('7'!$D$4,$A$3,0) -> 1607150 | C13: =OFFSET('7'!$E$4,$A$3,0) -> 11264114 | D13: =OFFSET('7'!$F$4,$A$3,0) -> 7.01 | E13: =OFFSET('7'!$E$66,$A$3,0) -> 4755920 | F13: =OFFSET('7'!$F$66,$A$3,0) -> 2.96 | G13: =IFERROR('7'!$F$100*'Discipline Analysis'!$B13,"") -> 610717 | H13: ='7'!$F$100 -> 0.38 | I13: =IFERROR('7'!$F$98*'Discipline Analysis'!$B13,"") -> 2844655.5 | J13: ='7'!$F$98 -> 1.77 | K13: =IFERROR('7'!$F$99*'Discipline Analysis'!$B13,"") -> 1125005 | L13: ='7'!$F$99 -> 0.7 | M13: =OFFSET('7'!$E$35,$A$3,0) -> 1160087 | N13: =OFFSET('7'!$F$35,$A$3,0) -> 0.72 | O13: =IFERROR('7'!$F$101*'Discipline Analysis'!$B13,"") -> 321430 | P13: ='7'!$F$101 -> 0.2 | Q13: =IFERROR('7'!$F$102*'Discipline Analysis'!$B13,"") | R13: ='7'!$F$102 | S13: =IFERROR('7'!$F$103*'Discipline Analysis'!$B13,"") | T13: ='7'!$F$103 | U13: =IFERROR('7'!$F$104*'Discipline Analysis'!$B13,"") -> 433930.5 | V13: ='7'!$F$104 -> 0.27 | X13: Engineering Related
A14: Central Texas | B14: =OFFSET('8'!$D$4,$A$3,0) -> 5416865 | C14: =OFFSET('8'!$E$4,$A$3,0) -> 28479940 | D14: =OFFSET('8'!$F$4,$A$3,0) -> 5.26 | E14: =OFFSET('8'!$E$66,$A$3,0) -> 9680820 | F14: =OFFSET('8'!$F$66,$A$3,0) -> 1.79 | G14: =IFERROR('8'!$F$100*'Discipline Analysis'!$B14,"") -> 920867.05 | H14: ='8'!$F$100 -> 0.17 | I14: =IFERROR('8'!$F$98*'Discipline Analysis'!$B14,"") -> 7746116.9 | J14: ='8'!$F$98 -> 1.43 | K14: =IFERROR('8'!$F$99*'Discipline Analysis'!$B14,"") -> 2925107.1 | L14: ='8'!$F$99 -> 0.54 | M14: =OFFSET('8'!$E$35,$A$3,0) -> 3397070 | N14: =OFFSET('8'!$F$35,$A$3,0) -> 0.63 | O14: =IFERROR('8'!$F$101*'Discipline Analysis'!$B14,"") -> 325011.9 | P14: ='8'!$F$101 -> 0.06 | Q14: =IFERROR('8'!$F$102*'Discipline Analysis'!$B14,"") -> 162505.95 | R14: ='8'!$F$102 -> 0.03 | S14: =IFERROR('8'!$F$103*'Discipline Analysis'!$B14,"") | T14: ='8'!$F$103 | U14: =IFERROR('8'!$F$104*'Discipline Analysis'!$B14,"") -> 3304287.6 | V14: ='8'!$F$104 -> 0.61 | X14: English Language, Lit, Philosophy, Humanities, & Interdisciplinary
A15: Cisco | B15: =OFFSET('9'!$D$4,$A$3,0) -> 1358099 | C15: =OFFSET('9'!$E$4,$A$3,0) -> 5709200 | D15: =OFFSET('9'!$F$4,$A$3,0) -> 4.2 | E15: =OFFSET('9'!$E$66,$A$3,0) -> 3167320 | F15: =OFFSET('9'!$F$66,$A$3,0) -> 2.33 | G15: =IFERROR('9'!$F$100*'Discipline Analysis'!$B15,"") -> 176552.87 | H15: ='9'!$F$100 -> 0.13 | I15: =IFERROR('9'!$F$98*'Discipline Analysis'!$B15,"") -> 1072898.2 | J15: ='9'!$F$98 -> 0.79 | K15: =IFERROR('9'!$F$99*'Discipline Analysis'!$B15,"") -> 624725.54 | L15: ='9'!$F$99 -> 0.46 | M15: =OFFSET('9'!$E$35,$A$3,0) -> 270635 | N15: =OFFSET('9'!$F$35,$A$3,0) -> 0.2 | O15: =IFERROR('9'!$F$101*'Discipline Analysis'!$B15,"") -> 217295.84 | P15: ='9'!$F$101 -> 0.16 | Q15: =IFERROR('9'!$F$102*'Discipline Analysis'!$B15,"") | R15: ='9'!$F$102 | S15: =IFERROR('9'!$F$103*'Discipline Analysis'!$B15,"") | T15: ='9'!$F$103 | U15: =IFERROR('9'!$F$104*'Discipline Analysis'!$B15,"") -> 190133.86 | V15: ='9'!$F$104 -> 0.14 | X15: Foreign Languages
A16: Clarendon | B16: =OFFSET('10'!$D$4,$A$3,0) -> 452668 | C16: =OFFSET('10'!$E$4,$A$3,0) -> 2960451 | D16: =OFFSET('10'!$F$4,$A$3,0) -> 6.54 | E16: =OFFSET('10'!$E$66,$A$3,0) -> 1374066 | F16: =OFFSET('10'!$F$66,$A$3,0) -> 3.04 | G16: =IFERROR('10'!$F$100*'Discipline Analysis'!$B16,"") -> 95060.28 | H16: ='10'!$F$100 -> 0.21 | I16: =IFERROR('10'!$F$98*'Discipline Analysis'!$B16,"") -> 751428.88 | J16: ='10'!$F$98 -> 1.66 | K16: =IFERROR('10'!$F$99*'Discipline Analysis'!$B16,"") -> 298760.88 | L16: ='10'!$F$99 -> 0.66 | M16: =OFFSET('10'!$E$35,$A$3,0) -> 182011 | N16: =OFFSET('10'!$F$35,$A$3,0) -> 0.4 | O16: =IFERROR('10'!$F$101*'Discipline Analysis'!$B16,"") -> 153907.12 | P16: ='10'!$F$101 -> 0.34 | Q16: =IFERROR('10'!$F$102*'Discipline Analysis'!$B16,"") | R16: ='10'!$F$102 | S16: =IFERROR('10'!$F$103*'Discipline Analysis'!$B16,"") | T16: ='10'!$F$103 | U16: =IFERROR('10'!$F$104*'Discipline Analysis'!$B16,"") -> 104113.64 | V16: ='10'!$F$104 -> 0.23 | X16: Health Occupations - Dental Assistants, Medical Lab, and Assoc. Degree Nursing
A17: Coastal Bend | B17: =OFFSET('11'!$D$4,$A$3,0) -> 2165992 | C17: =OFFSET('11'!$E$4,$A$3,0) -> 10871274 | D17: =OFFSET('11'!$F$4,$A$3,0) -> 5.02 | E17: =OFFSET('11'!$E$66,$A$3,0) -> 5227816 | F17: =OFFSET('11'!$F$66,$A$3,0) -> 2.41 | G17: =IFERROR('11'!$F$100*'Discipline Analysis'!$B17,"") -> 584817.84 | H17: ='11'!$F$100 -> 0.27 | I17: =IFERROR('11'!$F$98*'Discipline Analysis'!$B17,"") -> 2014372.6 | J17: ='11'!$F$98 -> 0.93 | K17: =IFERROR('11'!$F$99*'Discipline Analysis'!$B17,"") -> 823076.96 | L17: ='11'!$F$99 -> 0.38 | M17: =OFFSET('11'!$E$35,$A$3,0) -> 971794 | N17: =OFFSET('11'!$F$35,$A$3,0) -> 0.45 | O17: =IFERROR('11'!$F$101*'Discipline Analysis'!$B17,"") -> 801417.04 | P17: ='11'!$F$101 -> 0.37 | Q17: =IFERROR('11'!$F$102*'Discipline Analysis'!$B17,"") | R17: ='11'!$F$102 | S17: =IFERROR('11'!$F$103*'Discipline Analysis'!$B17,"") | T17: ='11'!$F$103 | U17: =IFERROR('11'!$F$104*'Discipline Analysis'!$B17,"") -> 454858.32 | V17: ='11'!$F$104 -> 0.21 | X17: Health Occupations - Dental Hygiene
A18: College Of The Mainland | B18: =OFFSET('12'!$D$4,$A$3,0) -> 1670139 | C18: =OFFSET('12'!$E$4,$A$3,0) -> 16899288 | D18: =OFFSET('12'!$F$4,$A$3,0) -> 10.12 | E18: =OFFSET('12'!$E$66,$A$3,0) -> 6143655 | F18: =OFFSET('12'!$F$66,$A$3,0) -> 3.68 | G18: =IFERROR('12'!$F$100*'Discipline Analysis'!$B18,"") -> 668055.6 | H18: ='12'!$F$100 -> 0.4 | I18: =IFERROR('12'!$F$98*'Discipline Analysis'!$B18,"") -> 4492673.9 | J18: ='12'!$F$98 -> 2.69 | K18: =IFERROR('12'!$F$99*'Discipline Analysis'!$B18,"") -> 1720243.2 | L18: ='12'!$F$99 -> 1.03 | M18: =OFFSET('12'!$E$35,$A$3,0) -> 1650735 | N18: =OFFSET('12'!$F$35,$A$3,0) -> 0.99 | O18: =IFERROR('12'!$F$101*'Discipline Analysis'!$B18,"") -> 450937.53 | P18: ='12'!$F$101 -> 0.27 | Q18: =IFERROR('12'!$F$102*'Discipline Analysis'!$B18,"") | R18: ='12'!$F$102 | S18: =IFERROR('12'!$F$103*'Discipline Analysis'!$B18,"") | T18: ='12'!$F$103 | U18: =IFERROR('12'!$F$104*'Discipline Analysis'!$B18,"") -> 1770347.3 | V18: ='12'!$F$104 -> 1.06 | X18: Health Occupations - Other
A19: Collin | B19: =OFFSET('13'!$D$4,$A$3,0) -> 7038051 | C19: =OFFSET('13'!$E$4,$A$3,0) -> 44821329 | D19: =OFFSET('13'!$F$4,$A$3,0) -> 6.37 | E19: =OFFSET('13'!$E$66,$A$3,0) -> 16757763 | F19: =OFFSET('13'!$F$66,$A$3,0) -> 2.38 | G19: =IFERROR('13'!$F$100*'Discipline Analysis'!$B19,"") -> 2955981.4 | H19: ='13'!$F$100 -> 0.42 | I19: =IFERROR('13'!$F$98*'Discipline Analysis'!$B19,"") -> 8445661.2 | J19: ='13'!$F$98 -> 1.2 | K19: =IFERROR('13'!$F$99*'Discipline Analysis'!$B19,"") -> 4504352.6 | L19: ='13'!$F$99 -> 0.64 | M19: =OFFSET('13'!$E$35,$A$3,0) -> 7914615 | N19: =OFFSET('13'!$F$35,$A$3,0) -> 1.12 | O19: =IFERROR('13'!$F$101*'Discipline Analysis'!$B19,"") -> 2815220.4 | P19: ='13'!$F$101 -> 0.4 | Q19: =IFERROR('13'!$F$102*'Discipline Analysis'!$B19,"") | R19: ='13'!$F$102 | S19: =IFERROR('13'!$F$103*'Discipline Analysis'!$B19,"") | T19: ='13'!$F$103 | U19: =IFERROR('13'!$F$104*'Discipline Analysis'!$B19,"") -> 1407610.2 | V19: ='13'!$F$104 -> 0.2 | X19: Health Occupations - Respiratory Therapy
A20: Dallas | B20: =OFFSET('14'!$D$4,$A$3,0) -> 25958904 | C20: =OFFSET('14'!$E$4,$A$3,0) -> 1.8229215e+08 | D20: =OFFSET('14'!$F$4,$A$3,0) -> 7.02 | E20: =OFFSET('14'!$E$66,$A$3,0) -> 68400835 | F20: =OFFSET('14'!$F$66,$A$3,0) -> 2.63 | G20: =IFERROR('14'!$F$100*'Discipline Analysis'!$B20,"") -> 7528082.2 | H20: ='14'!$F$100 -> 0.29 | I20: =IFERROR('14'!$F$98*'Discipline Analysis'!$B20,"") -> 40236301 | J20: ='14'!$F$98 -> 1.55 | K20: =IFERROR('14'!$F$99*'Discipline Analysis'!$B20,"") -> 18950000 | L20: ='14'!$F$99 -> 0.73 | M20: =OFFSET('14'!$E$35,$A$3,0) -> 32071549 | N20: =OFFSET('14'!$F$35,$A$3,0) -> 1.24 | O20: =IFERROR('14'!$F$101*'Discipline Analysis'!$B20,"") -> 5970547.9 | P20: ='14'!$F$101 -> 0.23 | Q20: =IFERROR('14'!$F$102*'Discipline Analysis'!$B20,"") -> 778767.12 | R20: ='14'!$F$102 -> 0.03 | S20: =IFERROR('14'!$F$103*'Discipline Analysis'!$B20,"") | T20: ='14'!$F$103 | U20: =IFERROR('14'!$F$104*'Discipline Analysis'!$B20,"") -> 8826027.4 | V20: ='14'!$F$104 -> 0.34 | X20: Health Occupations - Vocational Nursing
A21: Del Mar | B21: =OFFSET('15'!$D$4,$A$3,0) -> 5507011 | C21: =OFFSET('15'!$E$4,$A$3,0) -> 45788300 | D21: =OFFSET('15'!$F$4,$A$3,0) -> 8.31 | E21: =OFFSET('15'!$E$66,$A$3,0) -> 20193185 | F21: =OFFSET('15'!$F$66,$A$3,0) -> 3.67 | G21: =IFERROR('15'!$F$100*'Discipline Analysis'!$B21,"") -> 2312944.6 | H21: ='15'!$F$100 -> 0.42 | I21: =IFERROR('15'!$F$98*'Discipline Analysis'!$B21,"") -> 9031498 | J21: ='15'!$F$98 -> 1.64 | K21: =IFERROR('15'!$F$99*'Discipline Analysis'!$B21,"") -> 4846169.7 | L21: ='15'!$F$99 -> 0.88 | M21: =OFFSET('15'!$E$35,$A$3,0) -> 2291446 | N21: =OFFSET('15'!$F$35,$A$3,0) -> 0.42 | O21: =IFERROR('15'!$F$101*'Discipline Analysis'!$B21,"") -> 3138996.3 | P21: ='15'!$F$101 -> 0.57 | Q21: =IFERROR('15'!$F$102*'Discipline Analysis'!$B21,"") | R21: ='15'!$F$102 | S21: =IFERROR('15'!$F$103*'Discipline Analysis'!$B21,"") | T21: ='15'!$F$103 | U21: =IFERROR('15'!$F$104*'Discipline Analysis'!$B21,"") -> 4020118 | V21: ='15'!$F$104 -> 0.73 | X21: Mathematics
