Workbook

Sheet Calculator
B2: HP | C2: Atk | D2: Def | E2: SpA | F2: SpD | G2: Spe | I2: SF | J2: BST | L2: PT | M2: ST | N2: PS | O2: SS | Q2: BSR
A4: 1 | B4: 1 | C4: 1 | D4: 1 | E4: 1 | F4: 1 | G4: 1 | I4: =INDEX('Speed Factors'!$A$2:$B$256,(G4),2) -> 0 | J4: =SUM(B4:G4) -> 6 | L4: =((((B4*2)+141)*((D4*2)+36))/(402.744996))-24.57966407 -> -11.087256 | M4: =((((B4*2)+141)*((F4*2)+36))/(416.310724))-19.16575597 -> -6.1130055 | N4: =(((((C4*2)+36)*((((C4*2)+36)*(I4/672))+415))/((((C4*2)+36)*(1-(I4/672)))+415))/(1.92306))-3.576327284 -> 14.52626 | O4: =(((((E4*2)+36)*((((E4*2)+36)*(I4/672))+415))/((((E4*2)+36)*(1-(I4/672)))+415))/(1.980931))+4.9921912 -> 22.565929 | Q4: =((((L4+M4)+N4)+O4)/(1.535645))-60.47703745 -> -47.52357 | S4: PT / ST / PS / SS Range | T4: Description
A5: 2 | B5: 1 | C5: 1 | D5: 1 | E5: 1 | F5: 1 | G5: 1 | I5: =INDEX('Speed Factors'!$A$2:$B$256,(G5),2) -> 0 | J5: =SUM(B5:G5) -> 6 | L5: =((((B5*2)+141)*((D5*2)+36))/(402.744996))-24.57966407 -> -11.087256 | M5: =((((B5*2)+141)*((F5*2)+36))/(416.310724))-19.16575597 -> -6.1130055 | N5: =(((((C5*2)+36)*((((C5*2)+36)*(I5/672))+415))/((((C5*2)+36)*(1-(I5/672)))+415))/(1.92306))-3.576327284 -> 14.52626 | O5: =(((((E5*2)+36)*((((E5*2)+36)*(I5/672))+415))/((((E5*2)+36)*(1-(I5/672)))+415))/(1.980931))+4.9921912 -> 22.565929 | Q5: =((((L5+M5)+N5)+O5)/(1.535645))-60.47703745 -> -47.52357 | S5: x < 25 | T5: Horrible
A6: 3 | B6: 1 | C6: 1 | D6: 1 | E6: 1 | F6: 1 | G6: 1 | I6: =INDEX('Speed Factors'!$A$2:$B$256,(G6),2) -> 0 | J6: =SUM(B6:G6) -> 6 | L6: =((((B6*2)+141)*((D6*2)+36))/(402.744996))-24.57966407 -> -11.087256 | M6: =((((B6*2)+141)*((F6*2)+36))/(416.310724))-19.16575597 -> -6.1130055 | N6: =(((((C6*2)+36)*((((C6*2)+36)*(I6/672))+415))/((((C6*2)+36)*(1-(I6/672)))+415))/(1.92306))-3.576327284 -> 14.52626 | O6: =(((((E6*2)+36)*((((E6*2)+36)*(I6/672))+415))/((((E6*2)+36)*(1-(I6/672)))+415))/(1.980931))+4.9921912 -> 22.565929 | Q6: =((((L6+M6)+N6)+O6)/(1.535645))-60.47703745 -> -47.52357 | S6: 25 < x < 50 | T6: Bad
A7: 4 | B7: 1 | C7: 1 | D7: 1 | E7: 1 | F7: 1 | G7: 1 | I7: =INDEX('Speed Factors'!$A$2:$B$256,(G7),2) -> 0 | J7: =SUM(B7:G7) -> 6 | L7: =((((B7*2)+141)*((D7*2)+36))/(402.744996))-24.57966407 -> -11.087256 | M7: =((((B7*2)+141)*((F7*2)+36))/(416.310724))-19.16575597 -> -6.1130055 | N7: =(((((C7*2)+36)*((((C7*2)+36)*(I7/672))+415))/((((C7*2)+36)*(1-(I7/672)))+415))/(1.92306))-3.576327284 -> 14.52626 | O7: =(((((E7*2)+36)*((((E7*2)+36)*(I7/672))+415))/((((E7*2)+36)*(1-(I7/672)))+415))/(1.980931))+4.9921912 -> 22.565929 | Q7: =((((L7+M7)+N7)+O7)/(1.535645))-60.47703745 -> -47.52357 | S7: 50 < x < 75 | T7: Poor
A8: 5 | B8: 1 | C8: 1 | D8: 1 | E8: 1 | F8: 1 | G8: 1 | I8: =INDEX('Speed Factors'!$A$2:$B$256,(G8),2) -> 0 | J8: =SUM(B8:G8) -> 6 | L8: =((((B8*2)+141)*((D8*2)+36))/(402.744996))-24.57966407 -> -11.087256 | M8: =((((B8*2)+141)*((F8*2)+36))/(416.310724))-19.16575597 -> -6.1130055 | N8: =(((((C8*2)+36)*((((C8*2)+36)*(I8/672))+415))/((((C8*2)+36)*(1-(I8/672)))+415))/(1.92306))-3.576327284 -> 14.52626 | O8: =(((((E8*2)+36)*((((E8*2)+36)*(I8/672))+415))/((((E8*2)+36)*(1-(I8/672)))+415))/(1.980931))+4.9921912 -> 22.565929 | Q8: =((((L8+M8)+N8)+O8)/(1.535645))-60.47703745 -> -47.52357 | S8: 75 < x < 100 | T8: Below Average
A9: 6 | B9: 1 | C9: 1 | D9: 1 | E9: 1 | F9: 1 | G9: 1 | I9: =INDEX('Speed Factors'!$A$2:$B$256,(G9),2) -> 0 | J9: =SUM(B9:G9) -> 6 | L9: =((((B9*2)+141)*((D9*2)+36))/(402.744996))-24.57966407 -> -11.087256 | M9: =((((B9*2)+141)*((F9*2)+36))/(416.310724))-19.16575597 -> -6.1130055 | N9: =(((((C9*2)+36)*((((C9*2)+36)*(I9/672))+415))/((((C9*2)+36)*(1-(I9/672)))+415))/(1.92306))-3.576327284 -> 14.52626 | O9: =(((((E9*2)+36)*((((E9*2)+36)*(I9/672))+415))/((((E9*2)+36)*(1-(I9/672)))+415))/(1.980931))+4.9921912 -> 22.565929 | Q9: =((((L9+M9)+N9)+O9)/(1.535645))-60.47703745 -> -47.52357 | S9: 100 < x < 125 | T9: Above Average
A10: 7 | B10: 1 | C10: 1 | D10: 1 | E10: 1 | F10: 1 | G10: 1 | I10: =INDEX('Speed Factors'!$A$2:$B$256,(G10),2) -> 0 | J10: =SUM(B10:G10) -> 6 | L10: =((((B10*2)+141)*((D10*2)+36))/(402.744996))-24.57966407 -> -11.087256 | M10: =((((B10*2)+141)*((F10*2)+36))/(416.310724))-19.16575597 -> -6.1130055 | N10: =(((((C10*2)+36)*((((C10*2)+36)*(I10/672))+415))/((((C10*2)+36)*(1-(I10/672)))+415))/(1.92306))-3.576327284 -> 14.52626 | O10: =(((((E10*2)+36)*((((E10*2)+36)*(I10/672))+415))/((((E10*2)+36)*(1-(I10/672)))+415))/(1.980931))+4.9921912 -> 22.565929 | Q10: =((((L10+M10)+N10)+O10)/(1.535645))-60.47703745 -> -47.52357 | S10: 125 < x < 150 | T10: Good
A11: 8 | B11: 1 | C11: 1 | D11: 1 | E11: 1 | F11: 1 | G11: 1 | I11: =INDEX('Speed Factors'!$A$2:$B$256,(G11),2) -> 0 | J11: =SUM(B11:G11) -> 6 | L11: =((((B11*2)+141)*((D11*2)+36))/(402.744996))-24.57966407 -> -11.087256 | M11: =((((B11*2)+141)*((F11*2)+36))/(416.310724))-19.16575597 -> -6.1130055 | N11: =(((((C11*2)+36)*((((C11*2)+36)*(I11/672))+415))/((((C11*2)+36)*(1-(I11/672)))+415))/(1.92306))-3.576327284 -> 14.52626 | O11: =(((((E11*2)+36)*((((E11*2)+36)*(I11/672))+415))/((((E11*2)+36)*(1-(I11/672)))+415))/(1.980931))+4.9921912 -> 22.565929 | Q11: =((((L11+M11)+N11)+O11)/(1.535645))-60.47703745 -> -47.52357 | S11: 150 < x < 175 | T11: Very Good
A12: 9 | B12: 1 | C12: 1 | D12: 1 | E12: 1 | F12: 1 | G12: 1 | I12: =INDEX('Speed Factors'!$A$2:$B$256,(G12),2) -> 0 | J12: =SUM(B12:G12) -> 6 | L12: =((((B12*2)+141)*((D12*2)+36))/(402.744996))-24.57966407 -> -11.087256 | M12: =((((B12*2)+141)*((F12*2)+36))/(416.310724))-19.16575597 -> -6.1130055 | N12: =(((((C12*2)+36)*((((C12*2)+36)*(I12/672))+415))/((((C12*2)+36)*(1-(I12/672)))+415))/(1.92306))-3.576327284 -> 14.52626 | O12: =(((((E12*2)+36)*((((E12*2)+36)*(I12/672))+415))/((((E12*2)+36)*(1-(I12/672)))+415))/(1.980931))+4.9921912 -> 22.565929 | Q12: =((((L12+M12)+N12)+O12)/(1.535645))-60.47703745 -> -47.52357 | S12: 175 < x < 200 | T12: Excellent
A13: 10 | B13: 1 | C13: 1 | D13: 1 | E13: 1 | F13: 1 | G13: 1 | I13: =INDEX('Speed Factors'!$A$2:$B$256,(G13),2) -> 0 | J13: =SUM(B13:G13) -> 6 | L13: =((((B13*2)+141)*((D13*2)+36))/(402.744996))-24.57966407 -> -11.087256 | M13: =((((B13*2)+141)*((F13*2)+36))/(416.310724))-19.16575597 -> -6.1130055 | N13: =(((((C13*2)+36)*((((C13*2)+36)*(I13/672))+415))/((((C13*2)+36)*(1-(I13/672)))+415))/(1.92306))-3.576327284 -> 14.52626 | O13: =(((((E13*2)+36)*((((E13*2)+36)*(I13/672))+415))/((((E13*2)+36)*(1-(I13/672)))+415))/(1.980931))+4.9921912 -> 22.565929 | Q13: =((((L13+M13)+N13)+O13)/(1.535645))-60.47703745 -> -47.52357 | S13: 200 < x < 225 | T13: Fantastic
A14: 11 | B14: 1 | C14: 1 | D14: 1 | E14: 1 | F14: 1 | G14: 1 | I14: =INDEX('Speed Factors'!$A$2:$B$256,(G14),2) -> 0 | J14: =SUM(B14:G14) -> 6 | L14: =((((B14*2)+141)*((D14*2)+36))/(402.744996))-24.57966407 -> -11.087256 | M14: =((((B14*2)+141)*((F14*2)+36))/(416.310724))-19.16575597 -> -6.1130055 | N14: =(((((C14*2)+36)*((((C14*2)+36)*(I14/672))+415))/((((C14*2)+36)*(1-(I14/672)))+415))/(1.92306))-3.576327284 -> 14.52626 | O14: =(((((E14*2)+36)*((((E14*2)+36)*(I14/672))+415))/((((E14*2)+36)*(1-(I14/672)))+415))/(1.980931))+4.9921912 -> 22.565929 | Q14: =((((L14+M14)+N14)+O14)/(1.535645))-60.47703745 -> -47.52357 | S14: 225 < x | T14: Amazing
A15: 12 | B15: 1 | C15: 1 | D15: 1 | E15: 1 | F15: 1 | G15: 1 | I15: =INDEX('Speed Factors'!$A$2:$B$256,(G15),2) -> 0 | J15: =SUM(B15:G15) -> 6 | L15: =((((B15*2)+141)*((D15*2)+36))/(402.744996))-24.57966407 -> -11.087256 | M15: =((((B15*2)+141)*((F15*2)+36))/(416.310724))-19.16575597 -> -6.1130055 | N15: =(((((C15*2)+36)*((((C15*2)+36)*(I15/672))+415))/((((C15*2)+36)*(1-(I15/672)))+415))/(1.92306))-3.576327284 -> 14.52626 | O15: =(((((E15*2)+36)*((((E15*2)+36)*(I15/672))+415))/((((E15*2)+36)*(1-(I15/672)))+415))/(1.980931))+4.9921912 -> 22.565929 | Q15: =((((L15+M15)+N15)+O15)/(1.535645))-60.47703745 -> -47.52357
A16: 13 | B16: 1 | C16: 1 | D16: 1 | E16: 1 | F16: 1 | G16: 1 | I16: =INDEX('Speed Factors'!$A$2:$B$256,(G16),2) -> 0 | J16: =SUM(B16:G16) -> 6 | L16: =((((B16*2)+141)*((D16*2)+36))/(402.744996))-24.57966407 -> -11.087256 | M16: =((((B16*2)+141)*((F16*2)+36))/(416.310724))-19.16575597 -> -6.1130055 | N16: =(((((C16*2)+36)*((((C16*2)+36)*(I16/672))+415))/((((C16*2)+36)*(1-(I16/672)))+415))/(1.92306))-3.576327284 -> 14.52626 | O16: =(((((E16*2)+36)*((((E16*2)+36)*(I16/672))+415))/((((E16*2)+36)*(1-(I16/672)))+415))/(1.980931))+4.9921912 -> 22.565929 | Q16: =((((L16+M16)+N16)+O16)/(1.535645))-60.47703745 -> -47.52357 | S16: BSR Range | T16: Description
A17: 14 | B17: 1 | C17: 1 | D17: 1 | E17: 1 | F17: 1 | G17: 1 | I17: =INDEX('Speed Factors'!$A$2:$B$256,(G17),2) -> 0 | J17: =SUM(B17:G17) -> 6 | L17: =((((B17*2)+141)*((D17*2)+36))/(402.744996))-24.57966407 -> -11.087256 | M17: =((((B17*2)+141)*((F17*2)+36))/(416.310724))-19.16575597 -> -6.1130055 | N17: =(((((C17*2)+36)*((((C17*2)+36)*(I17/672))+415))/((((C17*2)+36)*(1-(I17/672)))+415))/(1.92306))-3.576327284 -> 14.52626 | O17: =(((((E17*2)+36)*((((E17*2)+36)*(I17/672))+415))/((((E17*2)+36)*(1-(I17/672)))+415))/(1.980931))+4.9921912 -> 22.565929 | Q17: =((((L17+M17)+N17)+O17)/(1.535645))-60.47703745 -> -47.52357 | S17: x < 50 | T17: Horrible
A18: 15 | B18: 1 | C18: 1 | D18: 1 | E18: 1 | F18: 1 | G18: 1 | I18: =INDEX('Speed Factors'!$A$2:$B$256,(G18),2) -> 0 | J18: =SUM(B18:G18) -> 6 | L18: =((((B18*2)+141)*((D18*2)+36))/(402.744996))-24.57966407 -> -11.087256 | M18: =((((B18*2)+141)*((F18*2)+36))/(416.310724))-19.16575597 -> -6.1130055 | N18: =(((((C18*2)+36)*((((C18*2)+36)*(I18/672))+415))/((((C18*2)+36)*(1-(I18/672)))+415))/(1.92306))-3.576327284 -> 14.52626 | O18: =(((((E18*2)+36)*((((E18*2)+36)*(I18/672))+415))/((((E18*2)+36)*(1-(I18/672)))+415))/(1.980931))+4.9921912 -> 22.565929 | Q18: =((((L18+M18)+N18)+O18)/(1.535645))-60.47703745 -> -47.52357 | S18: 50 < x < 100 | T18: Bad
A19: 16 | B19: 1 | C19: 1 | D19: 1 | E19: 1 | F19: 1 | G19: 1 | I19: =INDEX('Speed Factors'!$A$2:$B$256,(G19),2) -> 0 | J19: =SUM(B19:G19) -> 6 | L19: =((((B19*2)+141)*((D19*2)+36))/(402.744996))-24.57966407 -> -11.087256 | M19: =((((B19*2)+141)*((F19*2)+36))/(416.310724))-19.16575597 -> -6.1130055 | N19: =(((((C19*2)+36)*((((C19*2)+36)*(I19/672))+415))/((((C19*2)+36)*(1-(I19/672)))+415))/(1.92306))-3.576327284 -> 14.52626 | O19: =(((((E19*2)+36)*((((E19*2)+36)*(I19/672))+415))/((((E19*2)+36)*(1-(I19/672)))+415))/(1.980931))+4.9921912 -> 22.565929 | Q19: =((((L19+M19)+N19)+O19)/(1.535645))-60.47703745 -> -47.52357 | S19: 100 < x < 150 | T19: Poor
A20: 17 | B20: 1 | C20: 1 | D20: 1 | E20: 1 | F20: 1 | G20: 1 | I20: =INDEX('Speed Factors'!$A$2:$B$256,(G20),2) -> 0 | J20: =SUM(B20:G20) -> 6 | L20: =((((B20*2)+141)*((D20*2)+36))/(402.744996))-24.57966407 -> -11.087256 | M20: =((((B20*2)+141)*((F20*2)+36))/(416.310724))-19.16575597 -> -6.1130055 | N20: =(((((C20*2)+36)*((((C20*2)+36)*(I20/672))+415))/((((C20*2)+36)*(1-(I20/672)))+415))/(1.92306))-3.576327284 -> 14.52626 | O20: =(((((E20*2)+36)*((((E20*2)+36)*(I20/672))+415))/((((E20*2)+36)*(1-(I20/672)))+415))/(1.980931))+4.9921912 -> 22.565929 | Q20: =((((L20+M20)+N20)+O20)/(1.535645))-60.47703745 -> -47.52357 | S20: 150 < x < 200 | T20: Below Average
A21: 18 | B21: 1 | C21: 1 | D21: 1 | E21: 1 | F21: 1 | G21: 1 | I21: =INDEX('Speed Factors'!$A$2:$B$256,(G21),2) -> 0 | J21: =SUM(B21:G21) -> 6 | L21: =((((B21*2)+141)*((D21*2)+36))/(402.744996))-24.57966407 -> -11.087256 | M21: =((((B21*2)+141)*((F21*2)+36))/(416.310724))-19.16575597 -> -6.1130055 | N21: =(((((C21*2)+36)*((((C21*2)+36)*(I21/672))+415))/((((C21*2)+36)*(1-(I21/672)))+415))/(1.92306))-3.576327284 -> 14.52626 | O21: =(((((E21*2)+36)*((((E21*2)+36)*(I21/672))+415))/((((E21*2)+36)*(1-(I21/672)))+415))/(1.980931))+4.9921912 -> 22.565929 | Q21: =((((L21+M21)+N21)+O21)/(1.535645))-60.47703745 -> -47.52357 | S21: 200 < x < 250 | T21: Above Average
A22: 19 | B22: 1 | C22: 1 | D22: 1 | E22: 1 | F22: 1 | G22: 1 | I22: =INDEX('Speed Factors'!$A$2:$B$256,(G22),2) -> 0 | J22: =SUM(B22:G22) -> 6 | L22: =((((B22*2)+141)*((D22*2)+36))/(402.744996))-24.57966407 -> -11.087256 | M22: =((((B22*2)+141)*((F22*2)+36))/(416.310724))-19.16575597 -> -6.1130055 | N22: =(((((C22*2)+36)*((((C22*2)+36)*(I22/672))+415))/((((C22*2)+36)*(1-(I22/672)))+415))/(1.92306))-3.576327284 -> 14.52626 | O22: =(((((E22*2)+36)*((((E22*2)+36)*(I22/672))+415))/((((E22*2)+36)*(1-(I22/672)))+415))/(1.980931))+4.9921912 -> 22.565929 | Q22: =((((L22+M22)+N22)+O22)/(1.535645))-60.47703745 -> -47.52357 | S22: 250 < x < 300 | T22: Good
A23: 20 | B23: 1 | C23: 1 | D23: 1 | E23: 1 | F23: 1 | G23: 1 | I23: =INDEX('Speed Factors'!$A$2:$B$256,(G23),2) -> 0 | J23: =SUM(B23:G23) -> 6 | L23: =((((B23*2)+141)*((D23*2)+36))/(402.744996))-24.57966407 -> -11.087256 | M23: =((((B23*2)+141)*((F23*2)+36))/(416.310724))-19.16575597 -> -6.1130055 | N23: =(((((C23*2)+36)*((((C23*2)+36)*(I23/672))+415))/((((C23*2)+36)*(1-(I23/672)))+415))/(1.92306))-3.576327284 -> 14.52626 | O23: =(((((E23*2)+36)*((((E23*2)+36)*(I23/672))+415))/((((E23*2)+36)*(1-(I23/672)))+415))/(1.980931))+4.9921912 -> 22.565929 | Q23: =((((L23+M23)+N23)+O23)/(1.535645))-60.47703745 -> -47.52357 | S23: 300 < x < 350 | T23: Very Good
S24: 350 < x < 400 | T24: Excellent
B25: Hello, and welcome to CAP's Base Stat Rating Calculator! This calculator will perform all the tricky mathematics for you, and rate your Pokemon's stat spread relative to all other Pokemon in the game. To get started, here's what to do: | S25: 400 < x < 450 | T25: Fantastic
S26: 450 < x | T26: Amazing
B28: 1. Enter your stat spread into the pink table under any of the rows - there are twenty in total, so you can compare different stat spreads. This is all you need to add - the calculator will do everything else for you.
B30: 2. If you prefer, you can copy and paste the data of an existing Pokemon in to see its stat ratings (look under the "BSR of All Pokemon" tab at the bottom of the screen).
B32: 3. Copy and paste your calculated stat ratings anywhere you want to. If you enter an official CAP stat spread competition, you'll need to include these values for your submission to be legal.
B34: Oh, and one last thing - don't mess about with the formulae if you don't know what they do! These are quite complicated, so we'd recommend reading up on them if you want to fiddle with them.

Sheet Speed Factors
A1: Speed | B1: Speed Factor
A2: 1 | B2: 0
A3: 2 | B3: 0
A4: 3 | B4: 0
A5: 4 | B5: 0
A6: 5 | B6: 0
A7: 6 | B7: 2
A8: 7 | B8: 2
A9: 8 | B9: 2
A10: 9 | B10: 2
A11: 10 | B11: 2
A12: 11 | B12: 5
A13: 12 | B13: 5
... A256: 255 | B256: 672

Sheet BSR of OU+CAP Pokemon
B2: HP | C2: Atk | D2: Def | E2: SpA | F2: SpD | G2: Spe | I2: SF | J2: BST | L2: PT | M2: ST | N2: PS | O2: SS | Q2: BSR
A4: Abomasnow | B4: 90 | C4: 92 | D4: 75 | E4: 92 | F4: 85 | G4: 60 | I4: =INDEX('Speed Factors'!$A$2:$B$256,(G4),2) -> 274 | J4: =SUM(B4:G4) -> 494 | L4: =((((B4*2)+141)*((D4*2)+36))/(402.744996))-24.57966407 -> 123.66799 | M4: =((((B4*2)+141)*((F4*2)+36))/(416.310724))-19.16575597 -> 139.67233 | N4: =(((((C4*2)+36)*((((C4*2)+36)*(I4/672))+415))/((((C4*2)+36)*(1-(I4/672)))+415))/(1.92306))-3.576327284 -> 102.30798 | O4: =(((((E4*2)+36)*((((E4*2)+36)*(I4/672))+415))/((((E4*2)+36)*(1-(I4/672)))+415))/(1.980931))+4.9921912 -> 107.78319 | Q4: =((((L4+M4)+N4)+O4)/(1.535645))-60.47703745 -> 247.81784
A5: Alakazam | B5: 55 | C5: 50 | D5: 45 | E5: 135 | F5: 85 | G5: 120 | I5: =INDEX('Speed Factors'!$A$2:$B$256,(G5),2) -> 652 | J5: =SUM(B5:G5) -> 490 | L5: =((((B5*2)+141)*((D5*2)+36))/(402.744996))-24.57966407 -> 53.946451 | M5: =((((B5*2)+141)*((F5*2)+36))/(416.310724))-19.16575597 -> 105.03474 | N5: =(((((C5*2)+36)*((((C5*2)+36)*(I5/672))+415))/((((C5*2)+36)*(1-(I5/672)))+415))/(1.92306))-3.576327284 -> 88.730158 | O5: =(((((E5*2)+36)*((((E5*2)+36)*(I5/672))+415))/((((E5*2)+36)*(1-(I5/672)))+415))/(1.980931))+4.9921912 -> 264.28539 | Q5: =((((L5+M5)+N5)+O5)/(1.535645))-60.47703745 -> 272.93123
A6: Blissey | B6: 255 | C6: 10 | D6: 10 | E6: 75 | F6: 135 | G6: 55 | I6: =INDEX('Speed Factors'!$A$2:$B$256,(G6),2) -> 233 | J6: =SUM(B6:G6) -> 540 | L6: =((((B6*2)+141)*((D6*2)+36))/(402.744996))-24.57966407 -> 65.939151 | M6: =((((B6*2)+141)*((F6*2)+36))/(416.310724))-19.16575597 -> 459.33741 | N6: =(((((C6*2)+36)*((((C6*2)+36)*(I6/672))+415))/((((C6*2)+36)*(1-(I6/672)))+415))/(1.92306))-3.576327284 -> 24.43694 | O6: =(((((E6*2)+36)*((((E6*2)+36)*(I6/672))+415))/((((E6*2)+36)*(1-(I6/672)))+415))/(1.980931))+4.9921912 -> 88.908653 | Q6: =((((L6+M6)+N6)+O6)/(1.535645))-60.47703745 -> 355.38871 | S6: PT / ST / PS / SS Range | T6: Description
A7: Breloom | B7: 60 | C7: 130 | D7: 80 | E7: 60 | F7: 60 | G7: 70 | I7: =INDEX('Speed Factors'!$A$2:$B$256,(G7),2) -> 369 | J7: =SUM(B7:G7) -> 460 | L7: =((((B7*2)+141)*((D7*2)+36))/(402.744996))-24.57966407 -> 102.43867 | M7: =((((B7*2)+141)*((F7*2)+36))/(416.310724))-19.16575597 -> 78.636193 | N7: =(((((C7*2)+36)*((((C7*2)+36)*(I7/672))+415))/((((C7*2)+36)*(1-(I7/672)))+415))/(1.92306))-3.576327284 -> 158.50365 | O7: =(((((E7*2)+36)*((((E7*2)+36)*(I7/672))+415))/((((E7*2)+36)*(1-(I7/672)))+415))/(1.980931))+4.9921912 -> 86.229087 | Q7: =((((L7+M7)+N7)+O7)/(1.535645))-60.47703745 -> 216.80554 | S7: x < 25 | T7: Horrible
A8: Celebi | B8: 100 | C8: 100 | D8: 100 | E8: 100 | F8: 100 | G8: 100 | I8: =INDEX('Speed Factors'!$A$2:$B$256,(G8),2) -> 577 | J8: =SUM(B8:G8) -> 600 | L8: =((((B8*2)+141)*((D8*2)+36))/(402.744996))-24.57966407 -> 175.23908 | M8: =((((B8*2)+141)*((F8*2)+36))/(416.310724))-19.16575597 -> 174.14178 | N8: =(((((C8*2)+36)*((((C8*2)+36)*(I8/672))+415))/((((C8*2)+36)*(1-(I8/672)))+415))/(1.92306))-3.576327284 -> 165.47654 | O8: =(((((E8*2)+36)*((((E8*2)+36)*(I8/672))+415))/((((E8*2)+36)*(1-(I8/672)))+415))/(1.980931))+4.9921912 -> 169.10634 | Q8: =((((L8+M8)+N8)+O8)/(1.535645))-60.47703745 -> 384.9148 | S8: 25 < x < 50 | T8: Bad
A9: Chansey | B9: 250 | C9: 5 | D9: 5 | E9: 35 | F9: 105 | G9: 50 | I9: =INDEX('Speed Factors'!$A$2:$B$256,(G9),2) -> 189 | J9: =SUM(B9:G9) -> 450 | L9: =((((B9*2)+141)*((D9*2)+36))/(402.744996))-24.57966407 -> 48.632915 | M9: =((((B9*2)+141)*((F9*2)+36))/(416.310724))-19.16575597 -> 359.60421 | N9: =(((((C9*2)+36)*((((C9*2)+36)*(I9/672))+415))/((((C9*2)+36)*(1-(I9/672)))+415))/(1.92306))-3.576327284 -> 19.269492 | O9: =(((((E9*2)+36)*((((E9*2)+36)*(I9/672))+415))/((((E9*2)+36)*(1-(I9/672)))+415))/(1.980931))+4.9921912 -> 53.45027 | Q9: =((((L9+M9)+N9)+O9)/(1.535645))-60.47703745 -> 252.71832 | S9: 50 < x < 75 | T9: Poor
A10: Cloyster | B10: 50 | C10: 95 | D10: 180 | E10: 85 | F10: 45 | G10: 70 | I10: =INDEX('Speed Factors'!$A$2:$B$256,(G10),2) -> 369 | J10: =SUM(B10:G10) -> 525 | L10: =((((B10*2)+141)*((D10*2)+36))/(402.744996))-24.57966407 -> 212.38417 | M10: =((((B10*2)+141)*((F10*2)+36))/(416.310724))-19.16575597 -> 53.774955 | N10: =(((((C10*2)+36)*((((C10*2)+36)*(I10/672))+415))/((((C10*2)+36)*(1-(I10/672)))+415))/(1.92306))-3.576327284 -> 118.99121 | O10: =(((((E10*2)+36)*((((E10*2)+36)*(I10/672))+415))/((((E10*2)+36)*(1-(I10/672)))+415))/(1.980931))+4.9921912 -> 113.12632 | Q10: =((((L10+M10)+N10)+O10)/(1.535645))-60.47703745 -> 263.99682 | S10: 75 < x < 100 | T10: Below Average
A11: Conkeldurr | B11: 105 | C11: 140 | D11: 95 | E11: 55 | F11: 65 | G11: 45 | I11: =INDEX('Speed Factors'!$A$2:$B$256,(G11),2) -> 154 | J11: =SUM(B11:G11) -> 505 | L11: =((((B11*2)+141)*((D11*2)+36))/(402.744996))-24.57966407 -> 172.38368 | M11: =((((B11*2)+141)*((F11*2)+36))/(416.310724))-19.16575597 -> 120.7922 | N11: =(((((C11*2)+36)*((((C11*2)+36)*(I11/672))+415))/((((C11*2)+36)*(1-(I11/672)))+415))/(1.92306))-3.576327284 -> 118.03776 | O11: =(((((E11*2)+36)*((((E11*2)+36)*(I11/672))+415))/((((E11*2)+36)*(1-(I11/672)))+415))/(1.980931))+4.9921912 -> 67.646196 | Q11: =((((L11+M11)+N11)+O11)/(1.535645))-60.47703745 -> 251.35274 | S11: 100 < x < 125 | T11: Above Average
A12: Deoxys-D | B12: 50 | C12: 70 | D12: 160 | E12: 70 | F12: 160 | G12: 90 | I12: =INDEX('Speed Factors'!$A$2:$B$256,(G12),2) -> 503 | J12: =SUM(B12:G12) -> 600 | L12: =((((B12*2)+141)*((D12*2)+36))/(402.744996))-24.57966407 -> 188.44843 | M12: =((((B12*2)+141)*((F12*2)+36))/(416.310724))-19.16575597 -> 186.9207 | N12: =(((((C12*2)+36)*((((C12*2)+36)*(I12/672))+415))/((((C12*2)+36)*(1-(I12/672)))+415))/(1.92306))-3.576327284 -> 105.37656 | O12: =(((((E12*2)+36)*((((E12*2)+36)*(I12/672))+415))/((((E12*2)+36)*(1-(I12/672)))+415))/(1.980931))+4.9921912 -> 110.76212 | Q12: =((((L12+M12)+N12)+O12)/(1.535645))-60.47703745 -> 324.70822 | S12: 125 < x < 150 | T12: Good
A13: Donphan | B13: 90 | C13: 120 | D13: 120 | E13: 60 | F13: 60 | G13: 50 | I13: =INDEX('Speed Factors'!$A$2:$B$256,(G13),2) -> 189 | J13: =SUM(B13:G13) -> 500 | L13: =((((B13*2)+141)*((D13*2)+36))/(402.744996))-24.57966407 -> 195.40072 | M13: =((((B13*2)+141)*((F13*2)+36))/(416.310724))-19.16575597 -> 101.1194 | N13: =(((((C13*2)+36)*((((C13*2)+36)*(I13/672))+415))/((((C13*2)+36)*(1-(I13/672)))+415))/(1.92306))-3.576327284 -> 111.69111 | O13: =(((((E13*2)+36)*((((E13*2)+36)*(I13/672))+415))/((((E13*2)+36)*(1-(I13/672)))+415))/(1.980931))+4.9921912 -> 73.546702 | Q13: =((((L13+M13)+N13)+O13)/(1.535645))-60.47703745 -> 253.23995 | S13: 150 < x < 175 | T13: Very Good
A14: Dragonite | B14: 91 | C14: 134 | D14: 95 | E14: 100 | F14: 100 | G14: 80 | I14: =INDEX('Speed Factors'!$A$2:$B$256,(G14),2) -> 432 | J14: =SUM(B14:G14) -> 600 | L14: =((((B14*2)+141)*((D14*2)+36))/(402.744996))-24.57966407 -> 156.6715 | M14: =((((B14*2)+141)*((F14*2)+36))/(416.310724))-19.16575597 -> 163.93786 | N14: =(((((C14*2)+36)*((((C14*2)+36)*(I14/672))+415))/((((C14*2)+36)*(1-(I14/672)))+415))/(1.92306))-3.576327284 -> 180.72975 | O14: =(((((E14*2)+36)*((((E14*2)+36)*(I14/672))+415))/((((E14*2)+36)*(1-(I14/672)))+415))/(1.980931))+4.9921912 -> 140.2174 | Q14: =((((L14+M14)+N14)+O14)/(1.535645))-60.47703745 -> 357.29955 | S14: 175 < x < 200 | T14: Excellent
A15: Dugtrio | B15: 35 | C15: 80 | D15: 50 | E15: 50 | F15: 70 | G15: 120 | I15: =INDEX('Speed Factors'!$A$2:$B$256,(G15),2) -> 652 | J15: =SUM(B15:G15) -> 405 | L15: =((((B15*2)+141)*((D15*2)+36))/(402.744996))-24.57966407 -> 46.671376 | M15: =((((B15*2)+141)*((F15*2)+36))/(416.310724))-19.16575597 -> 70.036846 | N15: =(((((C15*2)+36)*((((C15*2)+36)*(I15/672))+415))/((((C15*2)+36)*(1-(I15/672)))+415))/(1.92306))-3.576327284 -> 142.98794 | O15: =(((((E15*2)+36)*((((E15*2)+36)*(I15/672))+415))/((((E15*2)+36)*(1-(I15/672)))+415))/(1.980931))+4.9921912 -> 94.602031 | Q15: =((((L15+M15)+N15)+O15)/(1.535645))-60.47703745 -> 170.23917 | S15: 200 < x < 225 | T15: Fantastic
A16: Espeon | B16: 65 | C16: 65 | D16: 60 | E16: 130 | F16: 95 | G16: 110 | I16: =INDEX('Speed Factors'!$A$2:$B$256,(G16),2) -> 627 | J16: =SUM(B16:G16) -> 525 | L16: =((((B16*2)+141)*((D16*2)+36))/(402.744996))-24.57966407 -> 80.389983 | M16: =((((B16*2)+141)*((F16*2)+36))/(416.310724))-19.16575597 -> 127.95032 | N16: =(((((C16*2)+36)*((((C16*2)+36)*(I16/672))+415))/((((C16*2)+36)*(1-(I16/672)))+415))/(1.92306))-3.576327284 -> 111.86831 | O16: =(((((E16*2)+36)*((((E16*2)+36)*(I16/672))+415))/((((E16*2)+36)*(1-(I16/672)))+415))/(1.980931))+4.9921912 -> 242.51301 | Q16: =((((L16+M16)+N16)+O16)/(1.535645))-60.47703745 -> 305.96288 | S16: 225 < x | T16: Amazing
A17: Ferrothorn | B17: 74 | C17: 94 | D17: 131 | E17: 54 | F17: 116 | G17: 20 | I17: =INDEX('Speed Factors'!$A$2:$B$256,(G17),2) -> 14 | J17: =SUM(B17:G17) -> 489 | L17: =((((B17*2)+141)*((D17*2)+36))/(402.744996))-24.57966407 -> 189.25788 | M17: =((((B17*2)+141)*((F17*2)+36))/(416.310724))-19.16575597 -> 166.87797 | N17: =(((((C17*2)+36)*((((C17*2)+36)*(I17/672))+415))/((((C17*2)+36)*(1-(I17/672)))+415))/(1.92306))-3.576327284 -> 73.486001 | O17: =(((((E17*2)+36)*((((E17*2)+36)*(I17/672))+415))/((((E17*2)+36)*(1-(I17/672)))+415))/(1.980931))+4.9921912 -> 59.642753 | Q17: =((((L17+M17)+N17)+O17)/(1.535645))-60.47703745 -> 258.12824
A18: Forretress | B18: 75 | C18: 90 | D18: 140 | E18: 60 | F18: 60 | G18: 40 | I18: =INDEX('Speed Factors'!$A$2:$B$256,(G18),2) -> 111 | J18: =SUM(B18:G18) -> 465 | L18: =((((B18*2)+141)*((D18*2)+36))/(402.744996))-24.57966407 -> 203.74347 | M18: =((((B18*2)+141)*((F18*2)+36))/(416.310724))-19.16575597 -> 89.877796 | N18: =(((((C18*2)+36)*((((C18*2)+36)*(I18/672))+415))/((((C18*2)+36)*(1-(I18/672)))+415))/(1.92306))-3.576327284 -> 81.454482 | O18: =(((((E18*2)+36)*((((E18*2)+36)*(I18/672))+415))/((((E18*2)+36)*(1-(I18/672)))+415))/(1.980931))+4.9921912 -> 68.654695 | Q18: =((((L18+M18)+N18)+O18)/(1.535645))-60.47703745 -> 228.47675 | S18: BSR Range | T18: Description
A19: Garchomp | B19: 108 | C19: 130 | D19: 95 | E19: 80 | F19: 85 | G19: 102 | I19: =INDEX('Speed Factors'!$A$2:$B$256,(G19),2) -> 607 | J19: =SUM(B19:G19) -> 600 | L19: =((((B19*2)+141)*((D19*2)+36))/(402.744996))-24.57966407 -> 175.75057 | M19: =((((B19*2)+141)*((F19*2)+36))/(416.310724))-19.16575597 -> 157.48595 | N19: =(((((C19*2)+36)*((((C19*2)+36)*(I19/672))+415))/((((C19*2)+36)*(1-(I19/672)))+415))/(1.92306))-3.576327284 -> 233.17714 | O19: =(((((E19*2)+36)*((((E19*2)+36)*(I19/672))+415))/((((E19*2)+36)*(1-(I19/672)))+415))/(1.980931))+4.9921912 -> 139.97889 | Q19: =((((L19+M19)+N19)+O19)/(1.535645))-60.47703745 -> 399.52026 | S19: x < 50 | T19: Horrible
A20: Gastrodon | B20: 111 | C20: 83 | D20: 68 | E20: 92 | F20: 82 | G20: 39 | I20: =INDEX('Speed Factors'!$A$2:$B$256,(G20),2) -> 110 | J20: =SUM(B20:G20) -> 475 | L20: =((((B20*2)+141)*((D20*2)+36))/(402.744996))-24.57966407 -> 130.44647 | M20: =((((B20*2)+141)*((F20*2)+36))/(416.310724))-19.16575597 -> 155.22322 | N20: =(((((C20*2)+36)*((((C20*2)+36)*(I20/672))+415))/((((C20*2)+36)*(1-(I20/672)))+415))/(1.92306))-3.576327284 -> 77.023825 | O20: =(((((E20*2)+36)*((((E20*2)+36)*(I20/672))+415))/((((E20*2)+36)*(1-(I20/672)))+415))/(1.980931))+4.9921912 -> 88.614691 | Q20: =((((L20+M20)+N20)+O20)/(1.535645))-60.47703745 -> 233.41133 | S20: 50 < x < 100 | T20: Bad
A21: Genesect | B21: 71 | C21: 120 | D21: 95 | E21: 120 | F21: 95 | G21: 99 | I21: =INDEX('Speed Factors'!$A$2:$B$256,(G21),2) -> 576 | J21: =SUM(B21:G21) -> 600 | L21: =((((B21*2)+141)*((D21*2)+36))/(402.744996))-24.57966407 -> 134.22554 | M21: =((((B21*2)+141)*((F21*2)+36))/(416.310724))-19.16575597 -> 134.46468 | N21: =(((((C21*2)+36)*((((C21*2)+36)*(I21/672))+415))/((((C21*2)+36)*(1-(I21/672)))+415))/(1.92306))-3.576327284 -> 202.20817 | O21: =(((((E21*2)+36)*((((E21*2)+36)*(I21/672))+415))/((((E21*2)+36)*(1-(I21/672)))+415))/(1.980931))+4.9921912 -> 204.76489 | Q21: =((((L21+M21)+N21)+O21)/(1.535645))-60.47703745 -> 379.5096 | S21: 100 < x < 150 | T21: Poor
A22: Gengar | B22: 60 | C22: 65 | D22: 60 | E22: 130 | F22: 75 | G22: 110 | I22: =INDEX('Speed Factors'!$A$2:$B$256,(G22),2) -> 627 | J22: =SUM(B22:G22) -> 500 | L22: =((((B22*2)+141)*((D22*2)+36))/(402.744996))-24.57966407 -> 76.516564 | M22: =((((B22*2)+141)*((F22*2)+36))/(416.310724))-19.16575597 -> 97.44426 | N22: =(((((C22*2)+36)*((((C22*2)+36)*(I22/672))+415))/((((C22*2)+36)*(1-(I22/672)))+415))/(1.92306))-3.576327284 -> 111.86831 | O22: =(((((E22*2)+36)*((((E22*2)+36)*(I22/672))+415))/((((E22*2)+36)*(1-(I22/672)))+415))/(1.980931))+4.9921912 -> 242.51301 | Q22: =((((L22+M22)+N22)+O22)/(1.535645))-60.47703745 -> 283.57523 | S22: 150 < x < 200 | T22: Below Average
A23: Gliscor | B23: 75 | C23: 95 | D23: 125 | E23: 45 | F23: 75 | G23: 95 | I23: =INDEX('Speed Factors'!$A$2:$B$256,(G23),2) -> 542 | J23: =SUM(B23:G23) -> 510 | L23: =((((B23*2)+141)*((D23*2)+36))/(402.744996))-24.57966407 -> 182.06722 | M23: =((((B23*2)+141)*((F23*2)+36))/(416.310724))-19.16575597 -> 110.84771 | N23: =(((((C23*2)+36)*((((C23*2)+36)*(I23/672))+415))/((((C23*2)+36)*(1-(I23/672)))+415))/(1.92306))-3.576327284 -> 149.44272 | O23: =(((((E23*2)+36)*((((E23*2)+36)*(I23/672))+415))/((((E23*2)+36)*(1-(I23/672)))+415))/(1.980931))+4.9921912 -> 79.781802 | Q23: =((((L23+M23)+N23)+O23)/(1.535645))-60.47703745 -> 279.53609 | S23: 200 < x < 250 | T23: Above Average
A24: Gyarados | B24: 95 | C24: 125 | D24: 79 | E24: 60 | F24: 100 | G24: 81 | I24: =INDEX('Speed Factors'!$A$2:$B$256,(G24),2) -> 461 | J24: =SUM(B24:G24) -> 540 | L24: =((((B24*2)+141)*((D24*2)+36))/(402.744996))-24.57966407 -> 134.86117 | M24: =((((B24*2)+141)*((F24*2)+36))/(416.310724))-19.16575597 -> 168.47294 | N24: =(((((C24*2)+36)*((((C24*2)+36)*(I24/672))+415))/((((C24*2)+36)*(1-(I24/672)))+415))/(1.92306))-3.576327284 -> 176.49156 | O24: =(((((E24*2)+36)*((((E24*2)+36)*(I24/672))+415))/((((E24*2)+36)*(1-(I24/672)))+415))/(1.980931))+4.9921912 -> 93.593338 | Q24: =((((L24+M24)+N24)+O24)/(1.535645))-60.47703745 -> 312.92893 | S24: 250 < x < 300 | T24: Good
A25: Haxorus | B25: 76 | C25: 147 | D25: 90 | E25: 60 | F25: 70 | G25: 97 | I25: =INDEX('Speed Factors'!$A$2:$B$256,(G25),2) -> 568 | J25: =SUM(B25:G25) -> 540 | L25: =((((B25*2)+141)*((D25*2)+36))/(402.744996))-24.57966407 -> 132.56195 | M25: =((((B25*2)+141)*((F25*2)+36))/(416.310724))-19.16575597 -> 104.70326 | N25: =(((((C25*2)+36)*((((C25*2)+36)*(I25/672))+415))/((((C25*2)+36)*(1-(I25/672)))+415))/(1.92306))-3.576327284 -> 251.91925 | O25: =(((((E25*2)+36)*((((E25*2)+36)*(I25/672))+415))/((((E25*2)+36)*(1-(I25/672)))+415))/(1.980931))+4.9921912 -> 103.05929 | Q25: =((((L25+M25)+N25)+O25)/(1.535645))-60.47703745 -> 325.18746 | S25: 300 < x < 350 | T25: Very Good
A26: Heatran | B26: 91 | C26: 90 | D26: 106 | E26: 130 | F26: 106 | G26: 77 | I26: =INDEX('Speed Factors'!$A$2:$B$256,(G26),2) -> 427 | J26: =SUM(B26:G26) -> 600 | L26: =((((B26*2)+141)*((D26*2)+36))/(402.744996))-24.57966407 -> 174.31542 | M26: =((((B26*2)+141)*((F26*2)+36))/(416.310724))-19.16575597 -> 173.24822 | N26: =(((((C26*2)+36)*((((C26*2)+36)*(I26/672))+415))/((((C26*2)+36)*(1-(I26/672)))+415))/(1.92306))-3.576327284 -> 122.05257 | O26: =(((((E26*2)+36)*((((E26*2)+36)*(I26/672))+415))/((((E26*2)+36)*(1-(I26/672)))+415))/(1.980931))+4.9921912 -> 177.3247 | Q26: =((((L26+M26)+N26)+O26)/(1.535645))-60.47703745 -> 360.80581 | S26: 350 < x < 400 | T26: Excellent
A27: Hippowdon | B27: 108 | C27: 112 | D27: 118 | E27: 68 | F27: 72 | G27: 47 | I27: =INDEX('Speed Factors'!$A$2:$B$256,(G27),2) -> 182 | J27: =SUM(B27:G27) -> 525 | L27: =((((B27*2)+141)*((D27*2)+36))/(402.744996))-24.57966407 -> 216.52575 | M27: =((((B27*2)+141)*((F27*2)+36))/(416.310724))-19.16575597 -> 135.1901 | N27: =(((((C27*2)+36)*((((C27*2)+36)*(I27/672))+415))/((((C27*2)+36)*(1-(I27/672)))+415))/(1.92306))-3.576327284 -> 104.97597 | O27: =(((((E27*2)+36)*((((E27*2)+36)*(I27/672))+415))/((((E27*2)+36)*(1-(I27/672)))+415))/(1.980931))+4.9921912 -> 79.154029 | Q27: =((((L27+M27)+N27)+O27)/(1.535645))-60.47703745 -> 288.46159 | S27: 400 < x < 450 | T27: Fantastic
A28: Hydreigon | B28: 92 | C28: 105 | D28: 90 | E28: 125 | F28: 90 | G28: 98 | I28: =INDEX('Speed Factors'!$A$2:$B$256,(G28),2) -> 572 | J28: =SUM(B28:G28) -> 600 | L28: =((((B28*2)+141)*((D28*2)+36))/(402.744996))-24.57966407 -> 149.72418 | M28: =((((B28*2)+141)*((F28*2)+36))/(416.310724))-19.16575597 -> 149.45829 | N28: =(((((C28*2)+36)*((((C28*2)+36)*(I28/672))+415))/((((C28*2)+36)*(1-(I28/672)))+415))/(1.92306))-3.576327284 -> 173.28765 | O28: =(((((E28*2)+36)*((((E28*2)+36)*(I28/672))+415))/((((E28*2)+36)*(1-(I28/672)))+415))/(1.980931))+4.9921912 -> 212.75395 | Q28: =((((L28+M28)+N28)+O28)/(1.535645))-60.47703745 -> 385.73551 | S28: 450 < x | T28: Amazing
A29: Infernape | B29: 76 | C29: 104 | D29: 71 | E29: 104 | F29: 71 | G29: 108 | I29: =INDEX('Speed Factors'!$A$2:$B$256,(G29),2) -> 620 | J29: =SUM(B29:G29) -> 534 | L29: =((((B29*2)+141)*((D29*2)+36))/(402.744996))-24.57966407 -> 104.91667 | M29: =((((B29*2)+141)*((F29*2)+36))/(416.310724))-19.16575597 -> 106.11086 | N29: =(((((C29*2)+36)*((((C29*2)+36)*(I29/672))+415))/((((C29*2)+36)*(1-(I29/672)))+415))/(1.92306))-3.576327284 -> 183.61562 | O29: =(((((E29*2)+36)*((((E29*2)+36)*(I29/672))+415))/((((E29*2)+36)*(1-(I29/672)))+415))/(1.980931))+4.9921912 -> 186.7155 | Q29: =((((L29+M29)+N29)+O29)/(1.535645))-60.47703745 -> 318.09917
A30: Jellicent | B30: 100 | C30: 60 | D30: 70 | E30: 85 | F30: 105 | G30: 60 | I30: =INDEX('Speed Factors'!$A$2:$B$256,(G30),2) -> 274 | J30: =SUM(B30:G30) -> 480 | L30: =((((B30*2)+141)*((D30*2)+36))/(402.744996))-24.57966407 -> 124.43771 | M30: =((((B30*2)+141)*((F30*2)+36))/(416.310724))-19.16575597 -> 182.33278 | N30: =(((((C30*2)+36)*((((C30*2)+36)*(I30/672))+415))/((((C30*2)+36)*(1-(I30/672)))+415))/(1.92306))-3.576327284 -> 72.942198 | O30: =(((((E30*2)+36)*((((E30*2)+36)*(I30/672))+415))/((((E30*2)+36)*(1-(I30/672)))+415))/(1.980931))+4.9921912 -> 101.62267 | Q30: =((((L30+M30)+N30)+O30)/(1.535645))-60.47703745 -> 252.96477
A31: Jirachi | B31: 100 | C31: 100 | D31: 100 | E31: 100 | F31: 100 | G31: 100 | I31: =INDEX('Speed Factors'!$A$2:$B$256,(G31),2) -> 577 | J31: =SUM(B31:G31) -> 600 | L31: =((((B31*2)+141)*((D31*2)+36))/(402.744996))-24.57966407 -> 175.23908 | M31: =((((B31*2)+141)*((F31*2)+36))/(416.310724))-19.16575597 -> 174.14178 | N31: =(((((C31*2)+36)*((((C31*2)+36)*(I31/672))+415))/((((C31*2)+36)*(1-(I31/672)))+415))/(1.92306))-3.576327284 -> 165.47654 | O31: =(((((E31*2)+36)*((((E31*2)+36)*(I31/672))+415))/((((E31*2)+36)*(1-(I31/672)))+415))/(1.980931))+4.9921912 -> 169.10634 | Q31: =((((L31+M31)+N31)+O31)/(1.535645))-60.47703745 -> 384.9148
A32: Jolteon | B32: 65 | C32: 65 | D32: 60 | E32: 110 | F32: 95 | G32: 130 | I32: =INDEX('Speed Factors'!$A$2:$B$256,(G32),2) -> 662 | J32: =SUM(B32:G32) -> 525 | L32: =((((B32*2)+141)*((D32*2)+36))/(402.744996))-24.57966407 -> 80.389983 | M32: =((((B32*2)+141)*((F32*2)+36))/(416.310724))-19.16575597 -> 127.95032 | N32: =(((((C32*2)+36)*((((C32*2)+36)*(I32/672))+415))/((((C32*2)+36)*(1-(I32/672)))+415))/(1.92306))-3.576327284 -> 116.04688 | O32: =(((((E32*2)+36)*((((E32*2)+36)*(I32/672))+415))/((((E32*2)+36)*(1-(I32/672)))+415))/(1.980931))+4.9921912 -> 210.86733 | Q32: =((((L32+M32)+N32)+O32)/(1.535645))-60.47703745 -> 288.07651
A33: Keldeo | B33: 91 | C33: 72 | D33: 90 | E33: 129 | F33: 90 | G33: 108 | I33: =INDEX('Speed Factors'!$A$2:$B$256,(G33),2) -> 620 | J33: =SUM(B33:G33) -> 580 | L33: =((((B33*2)+141)*((D33*2)+36))/(402.744996))-24.57966407 -> 148.65154 | M33: =((((B33*2)+141)*((F33*2)+36))/(416.310724))-19.16575597 -> 148.42061 | N33: =(((((C33*2)+36)*((((C33*2)+36)*(I33/672))+415))/((((C33*2)+36)*(1-(I33/672)))+415))/(1.92306))-3.576327284 -> 123.22512 | O33: =(((((E33*2)+36)*((((E33*2)+36)*(I33/672))+415))/((((E33*2)+36)*(1-(I33/672)))+415))/(1.980931))+4.9921912 -> 237.65887 | Q33: =((((L33+M33)+N33)+O33)/(1.535645))-60.47703745 -> 367.97885
A34: Landorus | B34: 89 | C34: 125 | D34: 90 | E34: 115 | F34: 80 | G34: 101 | I34: =INDEX('Speed Factors'!$A$2:$B$256,(G34),2) -> 602 | J34: =SUM(B34:G34) -> 600 | L34: =((((B34*2)+141)*((D34*2)+36))/(402.744996))-24.57966407 -> 146.50626 | M34: =((((B34*2)+141)*((F34*2)+36))/(416.310724))-19.16575597 -> 131.02014 | N34: =(((((C34*2)+36)*((((C34*2)+36)*(I34/672))+415))/((((C34*2)+36)*(1-(I34/672)))+415))/(1.92306))-3.576327284 -> 220.85005 | O34: =(((((E34*2)+36)*((((E34*2)+36)*(I34/672))+415))/((((E34*2)+36)*(1-(I34/672)))+415))/(1.980931))+4.9921912 -> 203.14567 | Q34: =((((L34+M34)+N34)+O34)/(1.535645))-60.47703745 -> 396.34868
A35: Landorus-T | B35: 89 | C35: 145 | D35: 90 | E35: 105 | F35: 80 | G35: 91 | I35: =INDEX('Speed Factors'!$A$2:$B$256,(G35),2) -> 532 | J35: =SUM(B35:G35) -> 600 | L35: =((((B35*2)+141)*((D35*2)+36))/(402.744996))-24.57966407 -> 146.50626 | M35: =((((B35*2)+141)*((F35*2)+36))/(416.310724))-19.16575597 -> 131.02014 | N35: =(((((C35*2)+36)*((((C35*2)+36)*(I35/672))+415))/((((C35*2)+36)*(1-(I35/672)))+415))/(1.92306))-3.576327284 -> 232.70065 | O35: =(((((E35*2)+36)*((((E35*2)+36)*(I35/672))+415))/((((E35*2)+36)*(1-(I35/672)))+415))/(1.980931))+4.9921912 -> 167.39694 | Q35: =((((L35+M35)+N35)+O35)/(1.535645))-60.47703745 -> 380.7864
A36: Latias | B36: 80 | C36: 80 | D36: 90 | E36: 110 | F36: 130 | G36: 110 | I36: =INDEX('Speed Factors'!$A$2:$B$256,(G36),2) -> 627 | J36: =SUM(B36:G36) -> 600 | L36: =((((B36*2)+141)*((D36*2)+36))/(402.744996))-24.57966407 -> 136.85251 | M36: =((((B36*2)+141)*((F36*2)+36))/(416.310724))-19.16575597 -> 194.84747 | N36: =(((((C36*2)+36)*((((C36*2)+36)*(I36/672))+415))/((((C36*2)+36)*(1-(I36/672)))+415))/(1.92306))-3.576327284 -> 138.75583 | O36: =(((((E36*2)+36)*((((E36*2)+36)*(I36/672))+415))/((((E36*2)+36)*(1-(I36/672)))+415))/(1.980931))+4.9921912 -> 200.52793 | Q36: =((((L36+M36)+N36)+O36)/(1.535645))-60.47703745 -> 376.46232
A37: Latios | B37: 80 | C37: 90 | D37: 80 | E37: 130 | F37: 110 | G37: 110 | I37: =INDEX('Speed Factors'!$A$2:$B$256,(G37),2) -> 627 | J37: =SUM(B37:G37) -> 600 | L37: =((((B37*2)+141)*((D37*2)+36))/(402.744996))-24.57966407 -> 121.90509 | M37: =((((B37*2)+141)*((F37*2)+36))/(416.310724))-19.16575597 -> 165.92676 | N37: =(((((C37*2)+36)*((((C37*2)+36)*(I37/672))+415))/((((C37*2)+36)*(1-(I37/672)))+415))/(1.92306))-3.576327284 -> 157.67084 | O37: =(((((E37*2)+36)*((((E37*2)+36)*(I37/672))+415))/((((E37*2)+36)*(1-(I37/672)))+415))/(1.980931))+4.9921912 -> 242.51301 | Q37: =((((L37+M37)+N37)+O37)/(1.535645))-60.47703745 -> 387.5534
A38: Lucario | B38: 70 | C38: 110 | D38: 70 | E38: 115 | F38: 70 | G38: 90 | I38: =INDEX('Speed Factors'!$A$2:$B$256,(G38),2) -> 503 | J38: =SUM(B38:G38) -> 525 | L38: =((((B38*2)+141)*((D38*2)+36))/(402.744996))-24.57966407 -> 98.217641 | M38: =((((B38*2)+141)*((F38*2)+36))/(416.310724))-19.16575597 -> 99.630127 | N38: =(((((C38*2)+36)*((((C38*2)+36)*(I38/672))+415))/((((C38*2)+36)*(1-(I38/672)))+415))/(1.92306))-3.576327284 -> 164.87809 | O38: =(((((E38*2)+36)*((((E38*2)+36)*(I38/672))+415))/((((E38*2)+36)*(1-(I38/672)))+415))/(1.980931))+4.9921912 -> 176.11234 | Q38: =((((L38+M38)+N38)+O38)/(1.535645))-60.47703745 -> 290.41018
A39: Magnezone | B39: 70 | C39: 70 | D39: 115 | E39: 130 | F39: 90 | G39: 60 | I39: =INDEX('Speed Factors'!$A$2:$B$256,(G39),2) -> 274 | J39: =SUM(B39:G39) -> 535 | L39: =((((B39*2)+141)*((D39*2)+36))/(402.744996))-24.57966407 -> 161.01172 | M39: =((((B39*2)+141)*((F39*2)+36))/(416.310724))-19.16575597 -> 126.62919 | N39: =(((((C39*2)+36)*((((C39*2)+36)*(I39/672))+415))/((((C39*2)+36)*(1-(I39/672)))+415))/(1.92306))-3.576327284 -> 82.220231 | O39: =(((((E39*2)+36)*((((E39*2)+36)*(I39/672))+415))/((((E39*2)+36)*(1-(I39/672)))+415))/(1.980931))+4.9921912 -> 140.59119 | Q39: =((((L39+M39)+N39)+O39)/(1.535645))-60.47703745 -> 271.92553
A40: Mamoswine | B40: 110 | C40: 130 | D40: 80 | E40: 70 | F40: 60 | G40: 80 | I40: =INDEX('Speed Factors'!$A$2:$B$256,(G40),2) -> 432 | J40: =SUM(B40:G40) -> 530 | L40: =((((B40*2)+141)*((D40*2)+36))/(402.744996))-24.57966407 -> 151.1047 | M40: =((((B40*2)+141)*((F40*2)+36))/(416.310724))-19.16575597 -> 116.1082 | N40: =(((((C40*2)+36)*((((C40*2)+36)*(I40/672))+415))/((((C40*2)+36)*(1-(I40/672)))+415))/(1.92306))-3.576327284 -> 175.34405 | O40: =(((((E40*2)+36)*((((E40*2)+36)*(I40/672))+415))/((((E40*2)+36)*(1-(I40/672)))+415))/(1.980931))+4.9921912 -> 103.18884 | Q40: =((((L40+M40)+N40)+O40)/(1.535645))-60.47703745 -> 294.90835
... A74: Aurumoth | B74: 110 | C74: 120 | D74: 99 | E74: 117 | F74: 60 | G74: 94 | I74: =INDEX('Speed Factors'!$A$2:$B$256,(G74),2) -> 542 | J74: =SUM(B74:G74) -> 600 | L74: =((((B74*2)+141)*((D74*2)+36))/(402.744996))-24.57966407 -> 185.16596 | M74: =((((B74*2)+141)*((F74*2)+36))/(416.310724))-19.16575597 -> 116.1082 | N74: =(((((C74*2)+36)*((((C74*2)+36)*(I74/672))+415))/((((C74*2)+36)*(1-(I74/672)))+415))/(1.92306))-3.576327284 -> 191.79425 | O74: =(((((E74*2)+36)*((((E74*2)+36)*(I74/672))+415))/((((E74*2)+36)*(1-(I74/672)))+415))/(1.980931))+4.9921912 -> 189.58132 | Q74: =((((L74+M74)+N74)+O74)/(1.535645))-60.47703745 -> 384.05912

Sheet BSR of All Pokemon
A2: Species Name | B2: HP | C2: Atk | D2: Def | E2: SpA | F2: SpD | G2: Spe | I2: SF | J2: BST | L2: PT | M2: ST | N2: PS | O2: SS | Q2: BSR
A4: Bulbasaur | B4: 45 | C4: 49 | D4: 49 | E4: 65 | F4: 65 | G4: 45 | I4: =INDEX('Speed Factors'!$A$2:$B$256,(G4),2) -> 154 | J4: =SUM(B4:G4) -> 318 | L4: =((((B4*2)+141)*((D4*2)+36))/(402.744996))-24.57966407 -> 52.277902 | M4: =((((B4*2)+141)*((F4*2)+36))/(416.310724))-19.16575597 -> 72.943329 | N4: =(((((C4*2)+36)*((((C4*2)+36)*(I4/672))+415))/((((C4*2)+36)*(1-(I4/672)))+415))/(1.92306))-3.576327284 -> 56.345975 | O4: =(((((E4*2)+36)*((((E4*2)+36)*(I4/672))+415))/((((E4*2)+36)*(1-(I4/672)))+415))/(1.980931))+4.9921912 -> 74.913634 | Q4: =((((L4+M4)+N4)+O4)/(1.535645))-60.47703745 -> 106.54128
A5: Ivysaur | B5: 60 | C5: 62 | D5: 63 | E5: 80 | F5: 80 | G5: 60 | I5: =INDEX('Speed Factors'!$A$2:$B$256,(G5),2) -> 274 | J5: =SUM(B5:G5) -> 405 | L5: =((((B5*2)+141)*((D5*2)+36))/(402.744996))-24.57966407 -> 80.404881 | M5: =((((B5*2)+141)*((F5*2)+36))/(416.310724))-19.16575597 -> 103.71362 | N5: =(((((C5*2)+36)*((((C5*2)+36)*(I5/672))+415))/((((C5*2)+36)*(1-(I5/672)))+415))/(1.92306))-3.576327284 -> 74.80568 | O5: =(((((E5*2)+36)*((((E5*2)+36)*(I5/672))+415))/((((E5*2)+36)*(1-(I5/672)))+415))/(1.980931))+4.9921912 -> 97.197543 | Q5: =((((L5+M5)+N5)+O5)/(1.535645))-60.47703745 -> 171.42664 | S5: PT / ST / PS / SS Range | T5: Description
A6: Venusaur | B6: 80 | C6: 82 | D6: 83 | E6: 100 | F6: 100 | G6: 80 | I6: =INDEX('Speed Factors'!$A$2:$B$256,(G6),2) -> 432 | J6: =SUM(B6:G6) -> 525 | L6: =((((B6*2)+141)*((D6*2)+36))/(402.744996))-24.57966407 -> 126.38931 | M6: =((((B6*2)+141)*((F6*2)+36))/(416.310724))-19.16575597 -> 151.46641 | N6: =(((((C6*2)+36)*((((C6*2)+36)*(I6/672))+415))/((((C6*2)+36)*(1-(I6/672)))+415))/(1.92306))-3.576327284 -> 112.64202 | O6: =(((((E6*2)+36)*((((E6*2)+36)*(I6/672))+415))/((((E6*2)+36)*(1-(I6/672)))+415))/(1.980931))+4.9921912 -> 140.2174 | Q6: =((((L6+M6)+N6)+O6)/(1.535645))-60.47703745 -> 285.12051 | S6: x < 25 | T6: Horrible
A7: Charmander | B7: 39 | C7: 52 | D7: 43 | E7: 60 | F7: 50 | G7: 65 | I7: =INDEX('Speed Factors'!$A$2:$B$256,(G7),2) -> 321 | J7: =SUM(B7:G7) -> 309 | L7: =((((B7*2)+141)*((D7*2)+36))/(402.744996))-24.57966407 -> 41.76008 | M7: =((((B7*2)+141)*((F7*2)+36))/(416.310724))-19.16575597 -> 52.37696 | N7: =(((((C7*2)+36)*((((C7*2)+36)*(I7/672))+415))/((((C7*2)+36)*(1-(I7/672)))+415))/(1.92306))-3.576327284 -> 68.292167 | O7: =(((((E7*2)+36)*((((E7*2)+36)*(I7/672))+415))/((((E7*2)+36)*(1-(I7/672)))+415))/(1.980931))+4.9921912 -> 82.638382 | Q7: =((((L7+M7)+N7)+O7)/(1.535645))-60.47703745 -> 99.109058 | S7: 25 < x < 50 | T7: Bad
A8: Charmeleon | B8: 58 | C8: 64 | D8: 58 | E8: 80 | F8: 65 | G8: 80 | I8: =INDEX('Speed Factors'!$A$2:$B$256,(G8),2) -> 432 | J8: =SUM(B8:G8) -> 405 | L8: =((((B8*2)+141)*((D8*2)+36))/(402.744996))-24.57966407 -> 72.414713 | M8: =((((B8*2)+141)*((F8*2)+36))/(416.310724))-19.16575597 -> 83.310586 | N8: =(((((C8*2)+36)*((((C8*2)+36)*(I8/672))+415))/((((C8*2)+36)*(1-(I8/672)))+415))/(1.92306))-3.576327284 -> 90.142458 | O8: =(((((E8*2)+36)*((((E8*2)+36)*(I8/672))+415))/((((E8*2)+36)*(1-(I8/672)))+415))/(1.980931))+4.9921912 -> 115.35996 | Q8: =((((L8+M8)+N8)+O8)/(1.535645))-60.47703745 -> 174.75162 | S8: 50 < x < 75 | T8: Poor
A9: Charizard | B9: 78 | C9: 84 | D9: 78 | E9: 109 | F9: 85 | G9: 100 | I9: =INDEX('Speed Factors'!$A$2:$B$256,(G9),2) -> 577 | J9: =SUM(B9:G9) -> 534 | L9: =((((B9*2)+141)*((D9*2)+36))/(402.744996))-24.57966407 -> 117.00869 | M9: =((((B9*2)+141)*((F9*2)+36))/(416.310724))-19.16575597 -> 127.79659 | N9: =(((((C9*2)+36)*((((C9*2)+36)*(I9/672))+415))/((((C9*2)+36)*(1-(I9/672)))+415))/(1.92306))-3.576327284 -> 137.47653 | O9: =(((((E9*2)+36)*((((E9*2)+36)*(I9/672))+415))/((((E9*2)+36)*(1-(I9/672)))+415))/(1.980931))+4.9921912 -> 185.0217 | Q9: =((((L9+M9)+N9)+O9)/(1.535645))-60.47703745 -> 308.94656 | S9: 75 < x < 100 | T9: Below Average
A10: Squirtle | B10: 44 | C10: 48 | D10: 65 | E10: 50 | F10: 64 | G10: 43 | I10: =INDEX('Speed Factors'!$A$2:$B$256,(G10),2) -> 149 | J10: =SUM(B10:G10) -> 314 | L10: =((((B10*2)+141)*((D10*2)+36))/(402.744996))-24.57966407 -> 69.807604 | M10: =((((B10*2)+141)*((F10*2)+36))/(416.310724))-19.16575597 -> 71.045708 | N10: =(((((C10*2)+36)*((((C10*2)+36)*(I10/672))+415))/((((C10*2)+36)*(1-(I10/672)))+415))/(1.92306))-3.576327284 -> 55.324428 | O10: =(((((E10*2)+36)*((((E10*2)+36)*(I10/672))+415))/((((E10*2)+36)*(1-(I10/672)))+415))/(1.980931))+4.9921912 -> 63.669729 | Q10: =((((L10+M10)+N10)+O10)/(1.535645))-60.47703745 -> 108.7336 | S10: 100 < x < 125 | T10: Above Average
A11: Wartortle | B11: 59 | C11: 63 | D11: 80 | E11: 65 | F11: 80 | G11: 58 | I11: =INDEX('Speed Factors'!$A$2:$B$256,(G11),2) -> 267 | J11: =SUM(B11:G11) -> 405 | L11: =((((B11*2)+141)*((D11*2)+36))/(402.744996))-24.57966407 -> 101.46535 | M11: =((((B11*2)+141)*((F11*2)+36))/(416.310724))-19.16575597 -> 102.77201 | N11: =(((((C11*2)+36)*((((C11*2)+36)*(I11/672))+415))/((((C11*2)+36)*(1-(I11/672)))+415))/(1.92306))-3.576327284 -> 75.197533 | O11: =(((((E11*2)+36)*((((E11*2)+36)*(I11/672))+415))/((((E11*2)+36)*(1-(I11/672)))+415))/(1.980931))+4.9921912 -> 83.244765 | Q11: =((((L11+M11)+N11)+O11)/(1.535645))-60.47703745 -> 175.69712 | S11: 125 < x < 150 | T11: Good
A12: Blastoise | B12: 79 | C12: 83 | D12: 100 | E12: 85 | F12: 105 | G12: 78 | I12: =INDEX('Speed Factors'!$A$2:$B$256,(G12),2) -> 429 | J12: =SUM(B12:G12) -> 530 | L12: =((((B12*2)+141)*((D12*2)+36))/(402.744996))-24.57966407 -> 150.62798 | M12: =((((B12*2)+141)*((F12*2)+36))/(416.310724))-19.16575597 -> 157.51478 | N12: =(((((C12*2)+36)*((((C12*2)+36)*(I12/672))+415))/((((C12*2)+36)*(1-(I12/672)))+415))/(1.92306))-3.576327284 -> 113.49815 | O12: =(((((E12*2)+36)*((((E12*2)+36)*(I12/672))+415))/((((E12*2)+36)*(1-(I12/672)))+415))/(1.980931))+4.9921912 -> 121.09704 | Q12: =((((L12+M12)+N12)+O12)/(1.535645))-60.47703745 -> 292.94966 | S12: 150 < x < 175 | T12: Very Good
A13: Caterpie | B13: 45 | C13: 30 | D13: 35 | E13: 20 | F13: 20 | G13: 45 | I13: =INDEX('Speed Factors'!$A$2:$B$256,(G13),2) -> 154 | J13: =SUM(B13:G13) -> 195 | L13: =((((B13*2)+141)*((D13*2)+36))/(402.744996))-24.57966407 -> 36.218112 | M13: =((((B13*2)+141)*((F13*2)+36))/(416.310724))-19.16575597 -> 23.004669 | N13: =(((((C13*2)+36)*((((C13*2)+36)*(I13/672))+415))/((((C13*2)+36)*(1-(I13/672)))+415))/(1.92306))-3.576327284 -> 41.035599 | O13: =(((((E13*2)+36)*((((E13*2)+36)*(I13/672))+415))/((((E13*2)+36)*(1-(I13/672)))+415))/(1.980931))+4.9921912 -> 40.023008 | Q13: =((((L13+M13)+N13)+O13)/(1.535645))-60.47703745 -> 30.873103 | S13: 175 < x < 200 | T13: Excellent
A14: Metapod | B14: 50 | C14: 20 | D14: 55 | E14: 25 | F14: 25 | G14: 30 | I14: =INDEX('Speed Factors'!$A$2:$B$256,(G14),2) -> 44 | J14: =SUM(B14:G14) -> 205 | L14: =((((B14*2)+141)*((D14*2)+36))/(402.744996))-24.57966407 -> 62.785791 | M14: =((((B14*2)+141)*((F14*2)+36))/(416.310724))-19.16575597 -> 30.619173 | N14: =(((((C14*2)+36)*((((C14*2)+36)*(I14/672))+415))/((((C14*2)+36)*(1-(I14/672)))+415))/(1.92306))-3.576327284 -> 30.573451 | O14: =(((((E14*2)+36)*((((E14*2)+36)*(I14/672))+415))/((((E14*2)+36)*(1-(I14/672)))+415))/(1.980931))+4.9921912 -> 41.856107 | Q14: =((((L14+M14)+N14)+O14)/(1.535645))-60.47703745 -> 47.513105 | S14: 200 < x < 225 | T14: Fantastic
A15: Butterfree | B15: 60 | C15: 45 | D15: 50 | E15: 80 | F15: 80 | G15: 70 | I15: =INDEX('Speed Factors'!$A$2:$B$256,(G15),2) -> 369 | J15: =SUM(B15:G15) -> 385 | L15: =((((B15*2)+141)*((D15*2)+36))/(402.744996))-24.57966407 -> 63.555509 | M15: =((((B15*2)+141)*((F15*2)+36))/(416.310724))-19.16575597 -> 103.71362 | N15: =(((((C15*2)+36)*((((C15*2)+36)*(I15/672))+415))/((((C15*2)+36)*(1-(I15/672)))+415))/(1.92306))-3.576327284 -> 63.662765 | O15: =(((((E15*2)+36)*((((E15*2)+36)*(I15/672))+415))/((((E15*2)+36)*(1-(I15/672)))+415))/(1.980931))+4.9921912 -> 107.71935 | Q15: =((((L15+M15)+N15)+O15)/(1.535645))-60.47703745 -> 160.05 | S15: 225 < x | T15: Amazing
A16: Weedle | B16: 40 | C16: 35 | D16: 30 | E16: 20 | F16: 20 | G16: 50 | I16: =INDEX('Speed Factors'!$A$2:$B$256,(G16),2) -> 189 | J16: =SUM(B16:G16) -> 195 | L16: =((((B16*2)+141)*((D16*2)+36))/(402.744996))-24.57966407 -> 28.09883 | M16: =((((B16*2)+141)*((F16*2)+36))/(416.310724))-19.16575597 -> 21.179109 | N16: =(((((C16*2)+36)*((((C16*2)+36)*(I16/672))+415))/((((C16*2)+36)*(1-(I16/672)))+415))/(1.92306))-3.576327284 -> 46.34001 | O16: =(((((E16*2)+36)*((((E16*2)+36)*(I16/672))+415))/((((E16*2)+36)*(1-(I16/672)))+415))/(1.980931))+4.9921912 -> 40.641646 | Q16: =((((L16+M16)+N16)+O16)/(1.535645))-60.47703745 -> 28.254144
A17: Kakuna | B17: 45 | C17: 25 | D17: 50 | E17: 25 | F17: 25 | G17: 35 | I17: =INDEX('Speed Factors'!$A$2:$B$256,(G17),2) -> 84 | J17: =SUM(B17:G17) -> 205 | L17: =((((B17*2)+141)*((D17*2)+36))/(402.744996))-24.57966407 -> 53.42503 | M17: =((((B17*2)+141)*((F17*2)+36))/(416.310724))-19.16575597 -> 28.553409 | N17: =(((((C17*2)+36)*((((C17*2)+36)*(I17/672))+415))/((((C17*2)+36)*(1-(I17/672)))+415))/(1.92306))-3.576327284 -> 35.260404 | O17: =(((((E17*2)+36)*((((E17*2)+36)*(I17/672))+415))/((((E17*2)+36)*(1-(I17/672)))+415))/(1.980931))+4.9921912 -> 42.694345 | Q17: =((((L17+M17)+N17)+O17)/(1.535645))-60.47703745 -> 43.670202 | S17: BSR Range | T17: Description
A18: Beedrill | B18: 65 | C18: 80 | D18: 40 | E18: 45 | F18: 80 | G18: 75 | I18: =INDEX('Speed Factors'!$A$2:$B$256,(G18),2) -> 413 | J18: =SUM(B18:G18) -> 385 | L18: =((((B18*2)+141)*((D18*2)+36))/(402.744996))-24.57966407 -> 53.474689 | M18: =((((B18*2)+141)*((F18*2)+36))/(416.310724))-19.16575597 -> 108.42164 | N18: =(((((C18*2)+36)*((((C18*2)+36)*(I18/672))+415))/((((C18*2)+36)*(1-(I18/672)))+415))/(1.92306))-3.576327284 -> 107.677 | O18: =(((((E18*2)+36)*((((E18*2)+36)*(I18/672))+415))/((((E18*2)+36)*(1-(I18/672)))+415))/(1.980931))+4.9921912 -> 72.560651 | Q18: =((((L18+M18)+N18)+O18)/(1.535645))-60.47703745 -> 162.31793 | S18: x < 50 | T18: Horrible
A19: Pidgey | B19: 40 | C19: 45 | D19: 40 | E19: 35 | F19: 35 | G19: 56 | I19: =INDEX('Speed Factors'!$A$2:$B$256,(G19),2) -> 262 | J19: =SUM(B19:G19) -> 251 | L19: =((((B19*2)+141)*((D19*2)+36))/(402.744996))-24.57966407 -> 39.073517 | M19: =((((B19*2)+141)*((F19*2)+36))/(416.310724))-19.16575597 -> 37.104714 | N19: =(((((C19*2)+36)*((((C19*2)+36)*(I19/672))+415))/((((C19*2)+36)*(1-(I19/672)))+415))/(1.92306))-3.576327284 -> 58.24779 | O19: =(((((E19*2)+36)*((((E19*2)+36)*(I19/672))+415))/((((E19*2)+36)*(1-(I19/672)))+415))/(1.980931))+4.9921912 -> 55.898091 | Q19: =((((L19+M19)+N19)+O19)/(1.535645))-60.47703745 -> 63.460533 | S19: 50 < x < 100 | T19: Bad
A20: Pidgeotto | B20: 63 | C20: 60 | D20: 55 | E20: 50 | F20: 50 | G20: 71 | I20: =INDEX('Speed Factors'!$A$2:$B$256,(G20),2) -> 405 | J20: =SUM(B20:G20) -> 349 | L20: =((((B20*2)+141)*((D20*2)+36))/(402.744996))-24.57966407 -> 72.21111 | M20: =((((B20*2)+141)*((F20*2)+36))/(416.310724))-19.16575597 -> 68.057556 | N20: =(((((C20*2)+36)*((((C20*2)+36)*(I20/672))+415))/((((C20*2)+36)*(1-(I20/672)))+415))/(1.92306))-3.576327284 -> 82.992725 | O20: =(((((E20*2)+36)*((((E20*2)+36)*(I20/672))+415))/((((E20*2)+36)*(1-(I20/672)))+415))/(1.980931))+4.9921912 -> 77.734792 | Q20: =((((L20+M20)+N20)+O20)/(1.535645))-60.47703745 -> 135.52932 | S20: 100 < x < 150 | T20: Poor
A21: Pidgeot | B21: 83 | C21: 80 | D21: 75 | E21: 70 | F21: 70 | G21: 91 | I21: =INDEX('Speed Factors'!$A$2:$B$256,(G21),2) -> 532 | J21: =SUM(B21:G21) -> 469 | L21: =((((B21*2)+141)*((D21*2)+36))/(402.744996))-24.57966407 -> 117.20236 | M21: =((((B21*2)+141)*((F21*2)+36))/(416.310724))-19.16575597 -> 110.62192 | N21: =(((((C21*2)+36)*((((C21*2)+36)*(I21/672))+415))/((((C21*2)+36)*(1-(I21/672)))+415))/(1.92306))-3.576327284 -> 123.90864 | O21: =(((((E21*2)+36)*((((E21*2)+36)*(I21/672))+415))/((((E21*2)+36)*(1-(I21/672)))+415))/(1.980931))+4.9921912 -> 114.03481 | Q21: =((((L21+M21)+N21)+O21)/(1.535645))-60.47703745 -> 242.82726 | S21: 150 < x < 200 | T21: Below Average
A22: Rattata | B22: 30 | C22: 56 | D22: 35 | E22: 25 | F22: 35 | G22: 72 | I22: =INDEX('Speed Factors'!$A$2:$B$256,(G22),2) -> 408 | J22: =SUM(B22:G22) -> 253 | L22: =((((B22*2)+141)*((D22*2)+36))/(402.744996))-24.57966407 -> 28.322297 | M22: =((((B22*2)+141)*((F22*2)+36))/(416.310724))-19.16575597 -> 32.012364 | N22: =(((((C22*2)+36)*((((C22*2)+36)*(I22/672))+415))/((((C22*2)+36)*(1-(I22/672)))+415))/(1.92306))-3.576327284 -> 78.542946 | O22: =(((((E22*2)+36)*((((E22*2)+36)*(I22/672))+415))/((((E22*2)+36)*(1-(I22/672)))+415))/(1.980931))+4.9921912 -> 50.188836 | Q22: =((((L22+M22)+N22)+O22)/(1.535645))-60.47703745 -> 62.641549 | S22: 200 < x < 250 | T22: Above Average
A23: Raticate | B23: 55 | C23: 81 | D23: 60 | E23: 50 | F23: 70 | G23: 97 | I23: =INDEX('Speed Factors'!$A$2:$B$256,(G23),2) -> 568 | J23: =SUM(B23:G23) -> 413 | L23: =((((B23*2)+141)*((D23*2)+36))/(402.744996))-24.57966407 -> 72.643145 | M23: =((((B23*2)+141)*((F23*2)+36))/(416.310724))-19.16575597 -> 86.947292 | N23: =(((((C23*2)+36)*((((C23*2)+36)*(I23/672))+415))/((((C23*2)+36)*(1-(I23/672)))+415))/(1.92306))-3.576327284 -> 130.97092 | O23: =(((((E23*2)+36)*((((E23*2)+36)*(I23/672))+415))/((((E23*2)+36)*(1-(I23/672)))+415))/(1.980931))+4.9921912 -> 88.431844 | Q23: =((((L23+M23)+N23)+O23)/(1.535645))-60.47703745 -> 186.32037 | S23: 250 < x < 300 | T23: Good
A24: Spearow | B24: 40 | C24: 60 | D24: 30 | E24: 31 | F24: 31 | G24: 70 | I24: =INDEX('Speed Factors'!$A$2:$B$256,(G24),2) -> 369 | J24: =SUM(B24:G24) -> 262 | L24: =((((B24*2)+141)*((D24*2)+36))/(402.744996))-24.57966407 -> 28.09883 | M24: =((((B24*2)+141)*((F24*2)+36))/(416.310724))-19.16575597 -> 32.857886 | N24: =(((((C24*2)+36)*((((C24*2)+36)*(I24/672))+415))/((((C24*2)+36)*(1-(I24/672)))+415))/(1.92306))-3.576327284 -> 80.105245 | O24: =(((((E24*2)+36)*((((E24*2)+36)*(I24/672))+415))/((((E24*2)+36)*(1-(I24/672)))+415))/(1.980931))+4.9921912 -> 55.500852 | Q24: =((((L24+M24)+N24)+O24)/(1.535645))-60.47703745 -> 67.523127 | S24: 300 < x < 350 | T24: Very Good
A25: Fearow | B25: 65 | C25: 90 | D25: 65 | E25: 61 | F25: 61 | G25: 100 | I25: =INDEX('Speed Factors'!$A$2:$B$256,(G25),2) -> 577 | J25: =SUM(B25:G25) -> 442 | L25: =((((B25*2)+141)*((D25*2)+36))/(402.744996))-24.57966407 -> 87.118806 | M25: =((((B25*2)+141)*((F25*2)+36))/(416.310724))-19.16575597 -> 83.685306 | N25: =(((((C25*2)+36)*((((C25*2)+36)*(I25/672))+415))/((((C25*2)+36)*(1-(I25/672)))+415))/(1.92306))-3.576327284 -> 147.80265 | O25: =(((((E25*2)+36)*((((E25*2)+36)*(I25/672))+415))/((((E25*2)+36)*(1-(I25/672)))+415))/(1.980931))+4.9921912 -> 105.42108 | Q25: =((((L25+M25)+N25)+O25)/(1.535645))-60.47703745 -> 215.64657 | S25: 350 < x < 400 | T25: Excellent
A26: Ekans | B26: 35 | C26: 60 | D26: 44 | E26: 40 | F26: 54 | G26: 55 | I26: =INDEX('Speed Factors'!$A$2:$B$256,(G26),2) -> 233 | J26: =SUM(B26:G26) -> 288 | L26: =((((B26*2)+141)*((D26*2)+36))/(402.744996))-24.57966407 -> 40.38452 | M26: =((((B26*2)+141)*((F26*2)+36))/(416.310724))-19.16575597 -> 53.818191 | N26: =(((((C26*2)+36)*((((C26*2)+36)*(I26/672))+415))/((((C26*2)+36)*(1-(I26/672)))+415))/(1.92306))-3.576327284 -> 70.039593 | O26: =(((((E26*2)+36)*((((E26*2)+36)*(I26/672))+415))/((((E26*2)+36)*(1-(I26/672)))+415))/(1.980931))+4.9921912 -> 59.307663 | Q26: =((((L26+M26)+N26)+O26)/(1.535645))-60.47703745 -> 85.096951 | S26: 400 < x < 450 | T26: Fantastic
A27: Arbok | B27: 60 | C27: 85 | D27: 69 | E27: 65 | F27: 79 | G27: 80 | I27: =INDEX('Speed Factors'!$A$2:$B$256,(G27),2) -> 432 | J27: =SUM(B27:G27) -> 438 | L27: =((((B27*2)+141)*((D27*2)+36))/(402.744996))-24.57966407 -> 88.181513 | M27: =((((B27*2)+141)*((F27*2)+36))/(416.310724))-19.16575597 -> 102.45974 | N27: =(((((C27*2)+36)*((((C27*2)+36)*(I27/672))+415))/((((C27*2)+36)*(1-(I27/672)))+415))/(1.92306))-3.576327284 -> 116.44924 | O27: =(((((E27*2)+36)*((((E27*2)+36)*(I27/672))+415))/((((E27*2)+36)*(1-(I27/672)))+415))/(1.980931))+4.9921912 -> 97.171071 | Q27: =((((L27+M27)+N27)+O27)/(1.535645))-60.47703745 -> 202.77493 | S27: 450 < x | T27: Amazing
A28: Pikachu | B28: 35 | C28: 55 | D28: 30 | E28: 50 | F28: 40 | G28: 90 | I28: =INDEX('Speed Factors'!$A$2:$B$256,(G28),2) -> 503 | J28: =SUM(B28:G28) -> 300 | L28: =((((B28*2)+141)*((D28*2)+36))/(402.744996))-24.57966407 -> 25.715188 | M28: =((((B28*2)+141)*((F28*2)+36))/(416.310724))-19.16575597 -> 39.626868 | N28: =(((((C28*2)+36)*((((C28*2)+36)*(I28/672))+415))/((((C28*2)+36)*(1-(I28/672)))+415))/(1.92306))-3.576327284 -> 84.540508 | O28: =(((((E28*2)+36)*((((E28*2)+36)*(I28/672))+415))/((((E28*2)+36)*(1-(I28/672)))+415))/(1.980931))+4.9921912 -> 83.977808 | Q28: =((((L28+M28)+N28)+O28)/(1.535645))-60.47703745 -> 91.811006
A29: Raichu | B29: 60 | C29: 90 | D29: 55 | E29: 90 | F29: 80 | G29: 100 | I29: =INDEX('Speed Factors'!$A$2:$B$256,(G29),2) -> 577 | J29: =SUM(B29:G29) -> 475 | L29: =((((B29*2)+141)*((D29*2)+36))/(402.744996))-24.57966407 -> 70.036037 | M29: =((((B29*2)+141)*((F29*2)+36))/(416.310724))-19.16575597 -> 103.71362 | N29: =(((((C29*2)+36)*((((C29*2)+36)*(I29/672))+415))/((((C29*2)+36)*(1-(I29/672)))+415))/(1.92306))-3.576327284 -> 147.80265 | O29: =(((((E29*2)+36)*((((E29*2)+36)*(I29/672))+415))/((((E29*2)+36)*(1-(I29/672)))+415))/(1.980931))+4.9921912 -> 151.94878 | Q29: =((((L29+M29)+N29)+O29)/(1.535645))-60.47703745 -> 247.86316
A30: Sandshrew | B30: 50 | C30: 75 | D30: 85 | E30: 20 | F30: 30 | G30: 40 | I30: =INDEX('Speed Factors'!$A$2:$B$256,(G30),2) -> 111 | J30: =SUM(B30:G30) -> 300 | L30: =((((B30*2)+141)*((D30*2)+36))/(402.744996))-24.57966407 -> 98.689403 | M30: =((((B30*2)+141)*((F30*2)+36))/(416.310724))-19.16575597 -> 36.408119 | N30: =(((((C30*2)+36)*((((C30*2)+36)*(I30/672))+415))/((((C30*2)+36)*(1-(I30/672)))+415))/(1.92306))-3.576327284 -> 72.019821 | O30: =(((((E30*2)+36)*((((E30*2)+36)*(I30/672))+415))/((((E30*2)+36)*(1-(I30/672)))+415))/(1.980931))+4.9921912 -> 39.276979 | Q30: =((((L30+M30)+N30)+O30)/(1.535645))-60.47703745 -> 99.973016
A31: Sandslash | B31: 75 | C31: 100 | D31: 110 | E31: 45 | F31: 55 | G31: 65 | I31: =INDEX('Speed Factors'!$A$2:$B$256,(G31),2) -> 321 | J31: =SUM(B31:G31) -> 450 | L31: =((((B31*2)+141)*((D31*2)+36))/(402.744996))-24.57966407 -> 160.39098 | M31: =((((B31*2)+141)*((F31*2)+36))/(416.310724))-19.16575597 -> 82.887825 | N31: =(((((C31*2)+36)*((((C31*2)+36)*(I31/672))+415))/((((C31*2)+36)*(1-(I31/672)))+415))/(1.92306))-3.576327284 -> 116.74269 | O31: =(((((E31*2)+36)*((((E31*2)+36)*(I31/672))+415))/((((E31*2)+36)*(1-(I31/672)))+415))/(1.980931))+4.9921912 -> 67.854518 | Q31: =((((L31+M31)+N31)+O31)/(1.535645))-60.47703745 -> 218.15247
A32: Nidoran-f | B32: 55 | C32: 47 | D32: 52 | E32: 40 | F32: 40 | G32: 41 | I32: =INDEX('Speed Factors'!$A$2:$B$256,(G32),2) -> 142 | J32: =SUM(B32:G32) -> 275 | L32: =((((B32*2)+141)*((D32*2)+36))/(402.744996))-24.57966407 -> 62.671575 | M32: =((((B32*2)+141)*((F32*2)+36))/(416.310724))-19.16575597 -> 50.77239 | N32: =(((((C32*2)+36)*((((C32*2)+36)*(I32/672))+415))/((((C32*2)+36)*(1-(I32/672)))+415))/(1.92306))-3.576327284 -> 54.219868 | O32: =(((((E32*2)+36)*((((E32*2)+36)*(I32/672))+415))/((((E32*2)+36)*(1-(I32/672)))+415))/(1.980931))+4.9921912 -> 55.80697 | Q32: =((((L32+M32)+N32)+O32)/(1.535645))-60.47703745 -> 85.0454
A33: Nidorina | B33: 70 | C33: 62 | D33: 67 | E33: 55 | F33: 55 | G33: 56 | I33: =INDEX('Speed Factors'!$A$2:$B$256,(G33),2) -> 262 | J33: =SUM(B33:G33) -> 365 | L33: =((((B33*2)+141)*((D33*2)+36))/(402.744996))-24.57966407 -> 94.031369 | M33: =((((B33*2)+141)*((F33*2)+36))/(416.310724))-19.16575597 -> 79.380829 | N33: =(((((C33*2)+36)*((((C33*2)+36)*(I33/672))+415))/((((C33*2)+36)*(1-(I33/672)))+415))/(1.92306))-3.576327284 -> 73.905079 | O33: =(((((E33*2)+36)*((((E33*2)+36)*(I33/672))+415))/((((E33*2)+36)*(1-(I33/672)))+415))/(1.980931))+4.9921912 -> 73.993462 | Q33: =((((L33+M33)+N33)+O33)/(1.535645))-60.47703745 -> 148.758
A34: Nidoqueen | B34: 90 | C34: 82 | D34: 87 | E34: 75 | F34: 85 | G34: 76 | I34: =INDEX('Speed Factors'!$A$2:$B$256,(G34),2) -> 424 | J34: =SUM(B34:G34) -> 495 | L34: =((((B34*2)+141)*((D34*2)+36))/(402.744996))-24.57966407 -> 142.79672 | M34: =((((B34*2)+141)*((F34*2)+36))/(416.310724))-19.16575597 -> 139.67233 | N34: =(((((C34*2)+36)*((((C34*2)+36)*(I34/672))+415))/((((C34*2)+36)*(1-(I34/672)))+415))/(1.92306))-3.576327284 -> 111.56935 | O34: =(((((E34*2)+36)*((((E34*2)+36)*(I34/672))+415))/((((E34*2)+36)*(1-(I34/672)))+415))/(1.980931))+4.9921912 -> 108.34491 | Q34: =((((L34+M34)+N34)+O34)/(1.535645))-60.47703745 -> 266.67104
