Workbook

Sheet Sheet1
A1: Eberspächer
A2: Bilvarmere
A3: Veiledende utsalgspriser pr. 1. september 2012
A5: Type | B5: Artikkelnr | C5: Bruttopris | D5: Bruttopris
C6: ekskl. moms | D6: inkl. moms
A7: Hydronic vannvarmere – Person- og varebiler
A8: bensin
A10: Varmer B 4 W-SC HYDRONIC, 12 volt
A11: Kun varmer | B11: 201824050000 | C11: =VLOOKUP(B11,'Ark1'!$A$2:$B$2165, 2, FALSE) -> 5550 | D11: =C11*1.25 -> 6937.5
A12: Komplettsats med varmer, unikit, tankuttak | B12: 201861050000 | C12: =VLOOKUP(B12,'Ark1'!$A$2:$B$2165, 2, FALSE) -> 7950 | D12: =C12*1.25 -> 9937.5
A14: Varmer B 4 W-S HYDRONIC, 12 volt
A15: Kun varmer | B15: 201852050000 | C15: =VLOOKUP(B15,'Ark1'!$A$2:$B$2165, 2, FALSE) -> 5550 | D15: =C15*1.25 -> 6937.5
A16: Komplettsats med varmer, unikit, tankuttak | B16: 201866050000 | C16: =VLOOKUP(B16,'Ark1'!$A$2:$B$2165, 2, FALSE) -> 7950 | D16: =C16*1.25 -> 9937.5
A18: Varmer B 5 W-SC HYDRONIC, 12 volt
A19: Kun varmer | B19: 201820050000 | C19: =VLOOKUP(B19,'Ark1'!$A$2:$B$2165, 2, FALSE) -> 7150 | D19: =C19*1.25 -> 8937.5
A20: Komplettsats med varmer, unikit, tankuttak | B20: 201863050000 | C20: =VLOOKUP(B20,'Ark1'!$A$2:$B$2165, 2, FALSE) -> 9650 | D20: =C20*1.25 -> 12062.5
A22: Varmer B 5 W-S Hydronic, 12 volt
A23: Kun varmer | B23: 201819050000 | C23: =VLOOKUP(B23,'Ark1'!$A$2:$B$2165, 2, FALSE) -> 7150 | D23: =C23*1.25 -> 8937.5
A24: Komplettsats med varmer, unikit, tankuttak | B24: 201862050000 | C24: =VLOOKUP(B24,'Ark1'!$A$2:$B$2165, 2, FALSE) -> 9650 | D24: =C24*1.25 -> 12062.5
A26: Varmere Hydronic II
A27: Hydronic B4S 12 v Economy (Unikit, se diesel) | B27: 201909050000 | C27: =VLOOKUP(B27,'Ark1'!$A$2:$B$2165, 2, FALSE) -> 4900 | D27: =C27*1.25 -> 6125
A28: Hydronic B5S 12 v Economy (Unikit, se diesel) | B28: 201904050000 | C28: =VLOOKUP(B28,'Ark1'!$A$2:$B$2165, 2, FALSE) -> 7850 | D28: =C28*1.25 -> 9812.5
A30: Diesel
A32: Varmer D 4 W-SC HYDRONIC, 12 volt
A33: Kun varmer | B33: 252257050000 | C33: =VLOOKUP(B33,'Ark1'!$A$2:$B$2165, 2, FALSE) -> 5550 | D33: =C33*1.25 -> 6937.5
A34: Komplettsats med varmer, unikit, tankuttak | B34: 252385050000 | C34: =VLOOKUP(B34,'Ark1'!$A$2:$B$2165, 2, FALSE) -> 7950 | D34: =C34*1.25 -> 9937.5
A36: Varmer D 4 W-S HYDRONIC, 12 volt
A37: Kun varmer | B37: 252355050000 | C37: =VLOOKUP(B37,'Ark1'!$A$2:$B$2165, 2, FALSE) -> 5550 | D37: =C37*1.25 -> 6937.5
A38: Komplettsats med varmer, unikit, tankuttak | B38: 252418050000 | C38: =VLOOKUP(B38,'Ark1'!$A$2:$B$2165, 2, FALSE) -> 7950 | D38: =C38*1.25 -> 9937.5
A40: Varmer D 5 W-SC HYDRONIC, 12 volt
A41: Kun varmer | B41: 252219050000 | C41: =VLOOKUP(B41,'Ark1'!$A$2:$B$2165, 2, FALSE) -> 7150 | D41: =C41*1.25 -> 8937.5
A42: Komplettsats med varmer, unikit, tankuttak | B42: 252390050000 | C42: =VLOOKUP(B42,'Ark1'!$A$2:$B$2165, 2, FALSE) -> 9650 | D42: =C42*1.25 -> 12062.5
A44: Varmer D 5 W-S HYDRONIC, 12 volt
A45: Kun varmer | B45: 252217050000 | C45: =VLOOKUP(B45,'Ark1'!$A$2:$B$2165, 2, FALSE) -> 7150 | D45: =C45*1.25 -> 8937.5
A46: Komplettsats med varmer, unikit, tankuttak | B46: 252386050000 | C46: =VLOOKUP(B46,'Ark1'!$A$2:$B$2165, 2, FALSE) -> 9650 | D46: =C46*1.25 -> 12062.5
A48: Varmere Hydronic II
A49: Hydronic D4S, 12V, Economy | B49: 252554050000 | C49: =VLOOKUP(B49,'Ark1'!$A$2:$B$2165, 2, FALSE) -> 4900 | D49: =C49*1.25 -> 6125
A50: Hydronic D5S, 12V, Economy | B50: 252526050000 | C50: =VLOOKUP(B50,'Ark1'!$A$2:$B$2165, 2, FALSE) -> 7850 | D50: =C50*1.25 -> 9812.5
A51: Unikit Hyd B/D 4/5S Eco | B51: 252526800000 | C51: =VLOOKUP(B51,'Ark1'!$A$2:$B$2165, 2, FALSE) -> 2540 | D51: =C51*1.25 -> 3175
A52: Hydronic D5S, 12V, Commercial | B52: 252506050000 | C52: =VLOOKUP(B52,'Ark1'!$A$2:$B$2165, 2, FALSE) -> 9350 | D52: =C52*1.25 -> 11687.5
...

Sheet Ark1
A1: Material | B1: Amount
A2: 102067016025 | B2: 10
A3: 102114310100 | B3: 123
A4: 10010258 | B4: 36
A5: 10010350 | B5: 18
A6: 10061317 | B6: 10
A7: 10210302 | B7: 18
A8: 10310348 | B8: 7
A9: 10310349 | B9: 7
A10: 10609002 | B10: 17
A11: 10709001 | B11: 18
A12: 10900043 | B12: 8
A13: 10909009 | B13: 7
... A2250: 991201465329 | B2250: 2600
