Workbook

Sheet Color Targets
F1: GCD xyY Target locations | J1: zoyd@avsforum | AA1: 2
A2: 100% Y [cd/m2] | B2: 121.5 | C2: <-Enter 100% white Y | AA2: 1 | AF2: Flat gamma | AG2: BT.709
A3: display gamma | B3: 2.22 | C3: =IF(AA1=1,"<-Enter average gamma","Using measured gamma") -> Using measured gamma | F3: Primaries/Secondaries | AF3: Measured gamma | AG3: BT.601
A4: 100L,100S | B4: x | C4: y | D4: Y [%] | E4: Y [cd/m2] | F4: 100L,75S | G4: x | H4: y | I4: Y [%] | J4: Y [cd/m2] | K4: 100L,50S | L4: x | M4: y | N4: Y [%] | O4: Y [cd/m2]
A5: R | B5: {=TRANSPOSE(Calculation!AD9:AJ11)} -> 0.63999993 | C5: 0.33000007 | D5: 0.2126729 | E5: =D5*$B$2 -> 25.839757 | F5: R | G5: {=TRANSPOSE(Calculation!AD14:AJ16)} -> 0.55955161 | H5: 0.32975993 | I5: 0.21076653 | J5: =I5*$B$2 -> 25.608133 | K5: R | L5: {=TRANSPOSE(Calculation!AD19:AJ21)} -> 0.48286114 | M5: 0.32953101 | N5: 0.20273712 | O5: =N5*$B$2 -> 24.63256
A6: G | B6: 0.30000001 | C6: 0.60000002 | D6: 0.7151522 | E6: =D6*$B$2 -> 86.890992 | F6: G | G6: 0.30298298 | H6: 0.53648602 | I6: 0.71427725 | J6: =I6*$B$2 -> 86.784685 | K6: G | L6: 0.30624233 | M6: 0.46708752 | N6: 0.70330905 | O6: =N6*$B$2 -> 85.45205
A7: B | B7: 0.15000001 | C7: 0.060000003 | D7: 0.072175 | E7: =D7*$B$2 -> 8.7692625 | F7: B | G7: 0.19118098 | H7: 0.12808127 | I7: 0.068886057 | J7: =I7*$B$2 -> 8.3696559 | K7: B | L7: 0.22855412 | M7: 0.18986737 | N7: 0.066670294 | O7: =N7*$B$2 -> 8.1004408
A8: Y | B8: 0.41932009 | C8: 0.50524583 | D8: 0.9278251 | E8: =D8*$B$2 -> 112.73075 | F8: Y | G8: 0.39440398 | H8: 0.46405397 | I8: 0.91915969 | J8: =I8*$B$2 -> 111.6779 | K8: Y | L8: 0.36807729 | M8: 0.42053011 | N8: 0.93350664 | O8: =N8*$B$2 -> 113.42106
A9: C | B9: 0.22465563 | C9: 0.32876026 | D9: 0.7873272 | E9: =D9*$B$2 -> 95.660255 | F9: C | G9: 0.245363 | H9: 0.32882207 | I9: 0.79388671 | J9: =I9*$B$2 -> 96.457236 | K9: C | L9: 0.26747726 | M9: 0.32888808 | N9: 0.77863255 | O9: =N9*$B$2 -> 94.603854
A10: M | B10: 0.32093774 | C10: 0.15419022 | D10: 0.2848479 | E10: =D10*$B$2 -> 34.60902 | F10: M | G10: 0.31899996 | H10: 0.19544988 | I10: 0.27328809 | J10: =I10*$B$2 -> 33.204502 | K10: M | L10: 0.31687393 | M10: 0.24071763 | N10: 0.2761004 | O10: =N10*$B$2 -> 33.546199
A11: W | B11: 0.3127266 | C11: 0.32902315 | D11: 1.0000001 | E11: =D11*$B$2 -> 121.50001 | F11: W | G11: 0.3127266 | H11: 0.32902315 | I11: 1.0000001 | J11: =I11*$B$2 -> 121.50001 | K11: W | L11: 0.3127266 | M11: 0.32902315 | N11: 1.0000001 | O11: =N11*$B$2 -> 121.50001
A13: 75L,100S | B13: x | C13: y | D13: Y [%] | E13: Y [cd/m2] | F13: 75L,75S | G13: x | H13: y | I13: Y [%] | J13: Y [cd/m2] | K13: 75L,50S | L13: x | M13: y | N13: Y [%] | O13: Y [cd/m2]
A14: R | B14: {=TRANSPOSE(Calculation!AD24:AJ26)} -> 0.63999993 | C14: 0.33000007 | D14: 0.10963914 | E14: =D14*$B$2 -> 13.321156 | F14: R | G14: {=TRANSPOSE(Calculation!AD29:AJ31)} -> 0.55288461 | H14: 0.32974003 | I14: 0.10896669 | J14: =I14*$B$2 -> 13.239452 | K14: R | L14: {=TRANSPOSE(Calculation!AD34:AJ36)} -> 0.47976872 | M14: 0.32952178 | N14: 0.10574448 | O14: =N14*$B$2 -> 12.847955
A15: G | B15: 0.30000001 | C15: 0.60000002 | D15: 0.36868201 | E15: =D15*$B$2 -> 44.794865 | F15: G | G15: 0.30316986 | H15: 0.53250691 | I15: 0.36240192 | J15: =I15*$B$2 -> 44.031833 | K15: G | L15: 0.30629863 | M15: 0.4658887 | N15: 0.35479191 | O15: =N15*$B$2 -> 43.107217
A16: B | B16: 0.15000001 | C16: 0.060000003 | D16: 0.037208337 | E16: =D16*$B$2 -> 4.520813 | F16: B | G16: 0.19353865 | H16: 0.13197904 | I16: 0.039156122 | J16: =I16*$B$2 -> 4.7574689 | K16: B | L16: 0.23233741 | M16: 0.19612198 | N16: 0.036892934 | O16: =N16*$B$2 -> 4.4824915
A17: Y | B17: 0.41932009 | C17: 0.50524583 | D17: 0.47832116 | E17: =D17*$B$2 -> 58.11602 | F17: Y | G17: 0.39423385 | H17: 0.4637727 | I17: 0.48415558 | J17: =I17*$B$2 -> 58.824903 | K17: Y | L17: 0.36640631 | M17: 0.41776761 | N17: 0.4777341 | O17: =N17*$B$2 -> 58.044694
A18: C | B18: 0.22465563 | C18: 0.32876026 | D18: 0.40589035 | E18: =D18*$B$2 -> 49.315678 | F18: C | G18: 0.24592773 | H18: 0.32882376 | I18: 0.40215688 | J18: =I18*$B$2 -> 48.86206 | K18: C | L18: 0.2682247 | M18: 0.32889031 | N18: 0.39308296 | O18: =N18*$B$2 -> 47.75958
A19: M | B19: 0.32093774 | C19: 0.15419022 | D19: 0.14684748 | E19: =D19*$B$2 -> 17.841969 | F19: M | G19: 0.31879018 | H19: 0.19991654 | I19: 0.144495 | J19: =I19*$B$2 -> 17.556143 | K19: M | L19: 0.3169549 | M19: 0.2389936 | N19: 0.14554797 | O19: =N19*$B$2 -> 17.684078
A20: W | B20: 0.3127266 | C20: 0.32902315 | D20: 0.51552949 | E20: =D20*$B$2 -> 62.636833 | F20: W | G20: 0.3127266 | H20: 0.32902315 | I20: 0.51141488 | J20: =I20*$B$2 -> 62.136909 | K20: W | L20: 0.3127266 | M20: 0.32902315 | N20: 0.51141488 | O20: =N20*$B$2 -> 62.136909
A22: 50L,100S | B22: x | C22: y | D22: Y [%] | E22: Y [cd/m2] | F22: 50L,75S | G22: x | H22: y | I22: Y [%] | J22: Y [cd/m2] | K22: 50L,50S | L22: x | M22: y | N22: Y [%] | O22: Y [cd/m2]
A23: R | B23: {=TRANSPOSE(Calculation!AD39:AJ41)} -> 0.63999993 | C23: 0.33000007 | D23: 0.043973481 | E23: =D23*$B$2 -> 5.342778 | F23: R | G23: {=TRANSPOSE(Calculation!AD44:AJ47)} -> 0.55075733 | H23: 0.32973368 | I23: 0.044338447 | J23: =I23*$B$2 -> 5.3871213 | K23: R | L23: {=TRANSPOSE(Calculation!AD49:AJ51)} -> 0.47217761 | M23: 0.32949912 | N23: 0.044187356 | O23: =N23*$B$2 -> 5.3687638
A24: G | B24: 0.30000001 | C24: 0.60000002 | D24: 0.14786901 | E24: =D24*$B$2 -> 17.966085 | F24: G | G24: 0.3036064 | H24: 0.52321201 | I24: 0.14656409 | J24: =I24*$B$2 -> 17.807538 | K24: G | L24: 0.30628544 | M24: 0.46616949 | N24: 0.14829652 | O24: =N24*$B$2 -> 18.018027
A25: B | B25: 0.15000001 | C25: 0.060000003 | D25: 0.014923321 | E25: =D25*$B$2 -> 1.8131835 | F25: B | G25: 0.19997472 | H25: 0.14261929 | I25: 0.017028063 | J25: =I25*$B$2 -> 2.0689096 | K25: B | L25: 0.24116896 | M25: 0.2107225 | N25: 0.017160766 | O25: =N25*$B$2 -> 2.0850331
A26: Y | B26: 0.41932009 | C26: 0.50524583 | D26: 0.1918425 | E26: =D26*$B$2 -> 23.308863 | F26: Y | G26: 0.39283986 | H26: 0.46146813 | I26: 0.19432674 | J26: =I26*$B$2 -> 23.610699 | K26: Y | L26: 0.36452997 | M26: 0.41466561 | N26: 0.18597187 | O26: =N26*$B$2 -> 22.595582
A27: C | B27: 0.22465563 | C27: 0.32876026 | D27: 0.16279234 | E27: =D27*$B$2 -> 19.779269 | F27: C | G27: 0.24705317 | H27: 0.32882712 | I27: 0.16192846 | J27: =I27*$B$2 -> 19.674307 | K27: C | L27: 0.26798458 | M27: 0.3288896 | N27: 0.164244 | O27: =N27*$B$2 -> 19.955646
A28: M | B28: 0.32093774 | C28: 0.15419022 | D28: 0.058896803 | E28: =D28*$B$2 -> 7.1559615 | F28: M | G28: 0.31875522 | H28: 0.20066077 | I28: 0.059926507 | J28: =I28*$B$2 -> 7.2810706 | K28: M | L28: 0.31663149 | M28: 0.24587965 | N28: 0.058715067 | O28: =N28*$B$2 -> 7.1338806
A29: W | B29: 0.3127266 | C29: 0.32902315 | D29: 0.20566254 | E29: =D29*$B$2 -> 24.987999 | F29: W | G29: 0.3127266 | H29: 0.32902315 | I29: 0.20566254 | J29: =I29*$B$2 -> 24.987999 | K29: W | L29: 0.3127266 | M29: 0.32902315 | N29: 0.20566254 | O29: =N29*$B$2 -> 24.987999
A32: Color Checker Palette
B33: x | C33: y | D33: Y [%] | E33: Y [cd/m2] | G33: Measured | H33: x | I33: y | J33: Y [%] | K33: Y [cd/m2] | L33: ΔL | M33: ΔC | N33: ΔH | O33: ΔE94 | P33: ΔE2000
A34: dark skin | B34: {=TRANSPOSE(Calculation!AY55:BJ57)} -> 0.40166373 | C34: 0.3591997 | D34: 0.095533415 | E34: =D34*$B$2 -> 11.60731 | G34: dark skin | H34: 0.408419 | I34: 0.360653 | J34: =K34/$B$2 -> 0.093908008 | K34: 11.409823 | L34: =Calculation!K97-Calculation!K81 -> -0.30246483 | M34: =SQRT(Calculation!L97^2+Calculation!M97^2)-SQRT(Calculation!L81^2+Calculation!M81^2) -> 1.3116143 | N34: =SQRT((Calculation!L81-Calculation!L97)^2+(Calculation!M81-Calculation!M97)^2-M34^2) -> 0.068816829 | O34: =SQRT(L34^2+(M34/Calculation!O81)^2+(N34/Calculation!P81)^2) -> 0.77420625 | P34: =Calculation!Z111 -> 0.80704164
A35: light skin | B35: 0.38996525 | C35: 0.35300025 | D35: 0.33613486 | E35: =D35*$B$2 -> 40.840385 | G35: light skin | H35: 0.39773 | I35: 0.352444 | J35: =K35/$B$2 -> 0.33079856 | K35: 40.192025 | L35: =Calculation!K98-Calculation!K82 -> -0.42908842 | M35: =SQRT(Calculation!L98^2+Calculation!M98^2)-SQRT(Calculation!L82^2+Calculation!M82^2) -> 2.4929569 | N35: =SQRT((Calculation!L82-Calculation!L98)^2+(Calculation!M82-Calculation!M98)^2-M35^2) -> 0.98982745 | O35: =SQRT(L35^2+(M35/Calculation!O82)^2+(N35/Calculation!P82)^2) -> 1.4422098 | P35: =Calculation!Z112 -> 1.5166278
A36: blue sky | B36: 0.24636328 | C36: 0.26619356 | D36: 0.17702899 | E36: =D36*$B$2 -> 21.509022 | G36: blue sky | H36: 0.242143 | I36: 0.264637 | J36: =K36/$B$2 -> 0.17162213 | K36: 20.852089 | L36: =Calculation!K99-Calculation!K83 -> -0.66997745 | M36: =SQRT(Calculation!L99^2+Calculation!M99^2)-SQRT(Calculation!L83^2+Calculation!M83^2) -> 0.69606827 | N36: =SQRT((Calculation!L83-Calculation!L99)^2+(Calculation!M83-Calculation!M99)^2-M36^2) -> 0.93355051 | O36: =SQRT(L36^2+(M36/Calculation!O83)^2+(N36/Calculation!P83)^2) -> 1.0364251 | P36: =Calculation!Z113 -> 1.1693022
A37: foliage | B37: 0.34053582 | C37: 0.43148158 | D37: 0.12472423 | E37: =D37*$B$2 -> 15.153994 | G37: foliage | H37: 0.34057 | I37: 0.441484 | J37: =K37/$B$2 -> 0.12493922 | K37: 15.180115 | L37: =Calculation!K100-Calculation!K84 -> 0.033280991 | M37: =SQRT(Calculation!L100^2+Calculation!M100^2)-SQRT(Calculation!L84^2+Calculation!M84^2) -> 2.4810126 | N37: =SQRT((Calculation!L84-Calculation!L100)^2+(Calculation!M84-Calculation!M100)^2-M37^2) -> 0.42728556 | O37: =SQRT(L37^2+(M37/Calculation!O84)^2+(N37/Calculation!P84)^2) -> 1.1810546 | P37: =Calculation!Z114 -> 1.1877132
A38: blue flower | B38: 0.26792958 | C38: 0.25334782 | D38: 0.22245296 | E38: =D38*$B$2 -> 27.028035 | G38: blue flower | H38: 0.266168 | I38: 0.247941 | J38: =K38/$B$2 -> 0.21547193 | K38: 26.179839 | L38: =Calculation!K101-Calculation!K85 -> -0.74307155 | M38: =SQRT(Calculation!L101^2+Calculation!M101^2)-SQRT(Calculation!L85^2+Calculation!M85^2) -> 1.9680444 | N38: =SQRT((Calculation!L85-Calculation!L101)^2+(Calculation!M85-Calculation!M101)^2-M38^2) -> 0.6727195 | O38: =SQRT(L38^2+(M38/Calculation!O85)^2+(N38/Calculation!P85)^2) -> 1.2563662 | P38: =Calculation!Z115 -> 1.2390504
A39: bluish green | B39: 0.2568823 | C39: 0.35973617 | D39: 0.40741259 | E39: =D39*$B$2 -> 49.500629 | G39: bluish green | H39: 0.257224 | I39: 0.357795 | J39: =K39/$B$2 -> 0.4006653 | K39: 48.680834 | L39: =Calculation!K102-Calculation!K86 -> -0.47737099 | M39: =SQRT(Calculation!L102^2+Calculation!M102^2)-SQRT(Calculation!L86^2+Calculation!M86^2) -> -0.95213324 | N39: =SQRT((Calculation!L86-Calculation!L102)^2+(Calculation!M86-Calculation!M102)^2-M39^2) -> 0.45051548 | O39: =SQRT(L39^2+(M39/Calculation!O86)^2+(N39/Calculation!P86)^2) -> 0.6785826 | P39: =Calculation!Z116 -> 0.60915918
A40: orange | B40: 0.51215757 | C40: 0.40038682 | D40: 0.29509378 | E40: =D40*$B$2 -> 35.853894 | G40: orange | H40: 0.509411 | I40: 0.399923 | J40: =K40/$B$2 -> 0.30494075 | K40: 37.050301 | L40: =Calculation!K103-Calculation!K87 -> 0.84963056 | M40: =SQRT(Calculation!L103^2+Calculation!M103^2)-SQRT(Calculation!L87^2+Calculation!M87^2) -> -0.39351363 | N40: =SQRT((Calculation!L87-Calculation!L103)^2+(Calculation!M87-Calculation!M103)^2-M40^2) -> 0.08080293 | O40: =SQRT(L40^2+(M40/Calculation!O87)^2+(N40/Calculation!P87)^2) -> 0.85647715 | P40: =Calculation!Z117 -> 0.73870333
A41: purplish blue | B41: 0.20760649 | C41: 0.17897257 | D41: 0.10870481 | E41: =D41*$B$2 -> 13.207634 | G41: purplish blue | H41: 0.207919 | I41: 0.176846 | J41: =K41/$B$2 -> 0.10798229 | K41: 13.119848 | L41: =Calculation!K104-Calculation!K88 -> -0.12292842 | M41: =SQRT(Calculation!L104^2+Calculation!M104^2)-SQRT(Calculation!L88^2+Calculation!M88^2) -> 0.95006207 | N41: =SQRT((Calculation!L88-Calculation!L104)^2+(Calculation!M88-Calculation!M104)^2-M41^2) -> 0.82462744 | O41: =SQRT(L41^2+(M41/Calculation!O88)^2+(N41/Calculation!P88)^2) -> 0.58275558 | P41: =Calculation!Z118 -> 0.53732001
A42: moderate red | B42: 0.47303641 | C42: 0.31269382 | D42: 0.18447485 | E42: =D42*$B$2 -> 22.413694 | G42: moderate red | H42: 0.471151 | I42: 0.309233 | J42: =K42/$B$2 -> 0.18990563 | K42: 23.073534 | L42: =Calculation!K105-Calculation!K89 -> 0.64174216 | M42: =SQRT(Calculation!L105^2+Calculation!M105^2)-SQRT(Calculation!L89^2+Calculation!M89^2) -> 0.88257293 | N42: =SQRT((Calculation!L89-Calculation!L105)^2+(Calculation!M89-Calculation!M105)^2-M42^2) -> 1.3648447 | O42: =SQRT(L42^2+(M42/Calculation!O89)^2+(N42/Calculation!P89)^2) -> 1.0435153 | P42: =Calculation!Z119 -> 1.1729238
A43: purple | B43: 0.29386113 | C43: 0.22047901 | D43: 0.060982867 | E43: =D43*$B$2 -> 7.4094184 | G43: purple | H43: 0.293227 | I43: 0.213986 | J43: =K43/$B$2 -> 0.058861588 | K43: 7.151683 | L43: =Calculation!K106-Calculation!K90 -> -0.53567455 | M43: =SQRT(Calculation!L106^2+Calculation!M106^2)-SQRT(Calculation!L90^2+Calculation!M90^2) -> 2.1198062 | N43: =SQRT((Calculation!L90-Calculation!L106)^2+(Calculation!M90-Calculation!M106)^2-M43^2) -> 0.2356263 | O43: =SQRT(L43^2+(M43/Calculation!O90)^2+(N43/Calculation!P90)^2) -> 1.0414073 | P43: =Calculation!Z120 -> 0.97520281
A44: yellow green | B44: 0.37426932 | C44: 0.49893305 | D44: 0.43154229 | E44: =D44*$B$2 -> 52.432389 | G44: yellow green | H44: 0.374033 | I44: 0.493785 | J44: =K44/$B$2 -> 0.43458768 | K44: 52.802403 | L44: =Calculation!K107-Calculation!K91 -> 0.20572065 | M44: =SQRT(Calculation!L107^2+Calculation!M107^2)-SQRT(Calculation!L91^2+Calculation!M91^2) -> -1.8122747 | N44: =SQRT((Calculation!L91-Calculation!L107)^2+(Calculation!M91-Calculation!M107)^2-M44^2) -> 0.30373196 | O44: =SQRT(L44^2+(M44/Calculation!O91)^2+(N44/Calculation!P91)^2) -> 0.52950086 | P44: =Calculation!Z121 -> 0.51114426
...

Sheet Gamma Target
A1: BT.1886 Caculator | D1: a | E1: b | F1: vc | G1: a1 | H1: a2 | I1: k | J1: gamma
D2: =(C9^(1/J2)-C10^(1/J2))^J2 -> 112.54489 | E2: =C10^(1/J2)/(C9^(1/J2)-C10^(1/J2)) -> 0.032415156 | F2: 0.35 | G2: 2.6 | H2: 3 | I2: =100/(1+C11)^G2 -> 88.086189 | J2: 2.4
A4: Enter Peak white and mll values and then
A5: adjust 10 pt controls to hit L primary targets
C8: Y [cd/m2] | H8: Enter 10 or 20 step grey scale Y's here
B9: White | C9: 121.5 | E9: L(1.83%)
B10: Black | C10: 0.03 | E10: =$I$2*($F$2+$C$11)^($G$2-$H$2)*(0.0183+$C$11)^$H$2 -> 0.040489828
B11: Alt_b | C11: 0.05 | D11: <-Adjust this to get luminance of measured
D12: 1.83% pattern for alternate CRT emulation
C13: Stimulus[%] | D13: L Primary | E13: L Alternate | F13: gamma [primary] | G13: gamma [alternate] | H13: Measured luminance | I13: Normalized | J13: Measured gamma
C14: 0.01 | D14: =$D$2*(C14+$E$2)^$J$2 -> 0.057197407 | E14: =IF(C14<$F$2,$I$2*($F$2+$C$11)^($G$2-$H$2)*(C14+$C$11)^$H$2,$I$2*(C14+$C$11)^$G$2) -> 0.027449698 | F14: =LOG(D14/$C$9)/LOG(C14) -> 1.6636 | G14: =LOG(E14/100)/LOG(C14) -> 1.7807312 | H14: 0.041703 | I14: =IF(H14=0,"",H14/$H$37) -> 0.0003432285 | J14: =IFERROR(LOG(I14)/LOG(C14),"") -> 1.7322083
C15: 0.02 | D15: =$D$2*(C15+$E$2)^$J$2 -> 0.09506536 | E15: =IF(C15<$F$2,$I$2*($F$2+$C$11)^($G$2-$H$2)*(C15+$C$11)^$H$2,$I$2*(C15+$C$11)^$G$2) -> 0.043589104 | F15: =LOG(D15/$C$9)/LOG(C15) -> 1.8284925 | G15: =LOG(E15/100)/LOG(C15) -> 1.978035 | H15: 0.067194 | I15: =IF(H15=0,"",H15/$H$37) -> 0.00055302726 | J15: =IFERROR(LOG(I15)/LOG(C15),"") -> 1.917193
C16: 0.03 | D16: =$D$2*(C16+$E$2)^$J$2 -> 0.14455127 | E16: =IF(C16<$F$2,$I$2*($F$2+$C$11)^($G$2-$H$2)*(C16+$C$11)^$H$2,$I$2*(C16+$C$11)^$G$2) -> 0.065065952 | F16: =LOG(D16/$C$9)/LOG(C16) -> 1.9204118 | G16: =LOG(E16/100)/LOG(C16) -> 2.0925147 | H16: 0.113235 | I16: =IF(H16=0,"",H16/$H$37) -> 0.00093195884 | J16: =IFERROR(LOG(I16)/LOG(C16),"") -> 1.990049
C17: 0.04 | D17: =$D$2*(C17+$E$2)^$J$2 -> 0.20649831 | E17: =IF(C17<$F$2,$I$2*($F$2+$C$11)^($G$2-$H$2)*(C17+$C$11)^$H$2,$I$2*(C17+$C$11)^$G$2) -> 0.092642732 | F17: =LOG(D17/$C$9)/LOG(C17) -> 1.9812437 | G17: =LOG(E17/100)/LOG(C17) -> 2.1697559 | H17: 0.168965 | I17: =IF(H17=0,"",H17/$H$37) -> 0.0013906339 | J17: =IFERROR(LOG(I17)/LOG(C17),"") -> 2.0435692
C18: 0.050228311 | D18: =$D$2*(C18+$E$2)^$J$2 -> 0.28354778 | E18: =IF(C18<$F$2,$I$2*($F$2+$C$11)^($G$2-$H$2)*(C18+$C$11)^$H$2,$I$2*(C18+$C$11)^$G$2) -> 0.12795435 | F18: =LOG(D18/$C$9)/LOG(C18) -> 2.0260553 | G18: =LOG(E18/100)/LOG(C18) -> 2.2269672 | H18: 0.25991 | I18: =IF(H18=0,"",H18/$H$37) -> 0.0021391392 | J18: =IFERROR(LOG(I18)/LOG(C18),"") -> 2.0551619
C19: 0.10045662 | D19: =$D$2*(C19+$E$2)^$J$2 -> 0.88626657 | E19: =IF(C19<$F$2,$I$2*($F$2+$C$11)^($G$2-$H$2)*(C19+$C$11)^$H$2,$I$2*(C19+$C$11)^$G$2) -> 0.43283038 | F19: =LOG(D19/$C$9)/LOG(C19) -> 2.1412485 | G19: =LOG(E19/100)/LOG(C19) -> 2.3683682 | H19: 0.906863 | I19: =IF(H19=0,"",H19/$H$37) -> 0.0074637611 | J19: =IFERROR(LOG(I19)/LOG(C19),"") -> 2.1312591
C20: 0.15068493 | D20: =$D$2*(C20+$E$2)^$J$2 -> 1.913279 | E20: =IF(C20<$F$2,$I$2*($F$2+$C$11)^($G$2-$H$2)*(C20+$C$11)^$H$2,$I$2*(C20+$C$11)^$G$2) -> 1.0271364 | F20: =LOG(D20/$C$9)/LOG(C20) -> 2.1933712 | G20: =LOG(E20/100)/LOG(C20) -> 2.4191494 | H20: 1.939177 | I20: =IF(H20=0,"",H20/$H$37) -> 0.015960023 | J20: =IFERROR(LOG(I20)/LOG(C20),"") -> 2.1862763
C21: 0.20091324 | D21: =$D$2*(C21+$E$2)^$J$2 -> 3.4233241 | E21: =IF(C21<$F$2,$I$2*($F$2+$C$11)^($G$2-$H$2)*(C21+$C$11)^$H$2,$I$2*(C21+$C$11)^$G$2) -> 2.0074955 | F21: =LOG(D21/$C$9)/LOG(C21) -> 2.2240277 | G21: =LOG(E21/100)/LOG(C21) -> 2.4352457 | H21: 3.470132 | I21: =IF(H21=0,"",H21/$H$37) -> 0.028560253 | J21: =IFERROR(LOG(I21)/LOG(C21),"") -> 2.2155767
C22: 0.25114155 | D22: =$D$2*(C22+$E$2)^$J$2 -> 5.4658991 | E22: =IF(C22<$F$2,$I$2*($F$2+$C$11)^($G$2-$H$2)*(C22+$C$11)^$H$2,$I$2*(C22+$C$11)^$G$2) -> 3.4705306 | F22: =LOG(D22/$C$9)/LOG(C22) -> 2.2445532 | G22: =LOG(E22/100)/LOG(C22) -> 2.4323434 | H22: 5.35542 | I22: =IF(H22=0,"",H22/$H$37) -> 0.044076752 | J22: =IFERROR(LOG(I22)/LOG(C22),"") -> 2.2593441
C23: 0.30136986 | D23: =$D$2*(C23+$E$2)^$J$2 -> 8.0843704 | E23: =IF(C23<$F$2,$I$2*($F$2+$C$11)^($G$2-$H$2)*(C23+$C$11)^$H$2,$I$2*(C23+$C$11)^$G$2) -> 5.512865 | F23: =LOG(D23/$C$9)/LOG(C23) -> 2.2594158 | G23: =LOG(E23/100)/LOG(C23) -> 2.4162454 | H23: 8.107444 | I23: =IF(H23=0,"",H23/$H$37) -> 0.066726755 | J23: =IFERROR(LOG(I23)/LOG(C23),"") -> 2.2570543
C24: 0.35159817 | D24: =$D$2*(C24+$E$2)^$J$2 -> 11.317667 | E24: =IF(C24<$F$2,$I$2*($F$2+$C$11)^($G$2-$H$2)*(C24+$C$11)^$H$2,$I$2*(C24+$C$11)^$G$2) -> 8.2180034 | F24: =LOG(D24/$C$9)/LOG(C24) -> 2.2707604 | G24: =LOG(E24/100)/LOG(C24) -> 2.390628 | H24: 11.115225 | I24: =IF(H24=0,"",H24/$H$37) -> 0.091481717 | J24: =IFERROR(LOG(I24)/LOG(C24),"") -> 2.2880448
C25: 0.40182648 | D25: =$D$2*(C25+$E$2)^$J$2 -> 15.20132 | E25: =IF(C25<$F$2,$I$2*($F$2+$C$11)^($G$2-$H$2)*(C25+$C$11)^$H$2,$I$2*(C25+$C$11)^$G$2) -> 11.164369 | F25: =LOG(D25/$C$9)/LOG(C25) -> 2.2797547 | G25: =LOG(E25/100)/LOG(C25) -> 2.4046932 | H25: 15.064519 | I25: =IF(H25=0,"",H25/$H$37) -> 0.12398562 | J25: =IFERROR(LOG(I25)/LOG(C25),"") -> 2.2896893
... C35: 0.89954338 | D35: =$D$2*(C35+$E$2)^$J$2 -> 95.033692 | E35: =IF(C35<$F$2,$I$2*($F$2+$C$11)^($G$2-$H$2)*(C35+$C$11)^$H$2,$I$2*(C35+$C$11)^$G$2) -> 76.992129 | F35: =LOG(D35/$C$9)/LOG(C35) -> 2.3206519 | G35: =LOG(E35/100)/LOG(C35) -> 2.4697452 | H35: 94.892588 | I35: =IF(H35=0,"",H35/$H$37) -> 0.78099515 | J35: =IFERROR(LOG(I35)/LOG(C35),"") -> 2.3348541
C36: 0.94977169 | D36: =$D$2*(C36+$E$2)^$J$2 -> 107.79327 | E36: =IF(C36<$F$2,$I$2*($F$2+$C$11)^($G$2-$H$2)*(C36+$C$11)^$H$2,$I$2*(C36+$C$11)^$G$2) -> 88.03391 | F36: =LOG(D36/$C$9)/LOG(C36) -> 2.3227349 | G36: =LOG(E36/100)/LOG(C36) -> 2.4731045 | I36: =IF(H36=0,"",H36/$H$37) | J36: =IFERROR(LOG(I36)/LOG(C36),"")
C37: 1 | D37: =$D$2*(C37+$E$2)^$J$2 -> 121.5 | E37: =IF(C37<$F$2,$I$2*($F$2+$C$11)^($G$2-$H$2)*(C37+$C$11)^$H$2,$I$2*(C37+$C$11)^$G$2) -> 100 | H37: 121.50215 | I37: =IF(H37=0,"",H37/$H$37) -> 1 | J37: =AVERAGE(J19:J36) -> 2.2782959 | K37: average
K38: 10-100%
A41: Note: If black levels are < 0.01 cd/m^2 BT.1886 recommends setting Black=0.0 cd/m^2 | H41: 0.873804 | I41: 3.42218 | J41: 7.817614 | K41: 14.622611 | L41: 24.161513 | M41: 36.417416 | N41: 51.441887 | O41: 70.169922 | P41: 92.890071 | Q41: 119.05182
A42: Peak white of alternate is fixed at 100 cd/m^2 reference
A43: http://www.itu.int/dms_pubrec/itu-r/rec/bt/R-REC-BT.1886-0-201103-I!!PDF-E.pdf

Sheet Calculation
M1: gamma | N1: ='Color Targets'!B3 -> 2.22
B2: =IF('Color Targets'!$AA$2=1,E62,I62) -> BT.709 color matrix
B3: =IF('Color Targets'!$AA$2=1,E63,I63) -> 0.4124564 | C3: =IF('Color Targets'!$AA$2=1,F63,J63) -> 0.3575761 | D3: =IF('Color Targets'!$AA$2=1,G63,K63) -> 0.1804375
B4: =IF('Color Targets'!$AA$2=1,E64,I64) -> 0.2126729 | C4: =IF('Color Targets'!$AA$2=1,F64,J64) -> 0.7151522 | D4: =IF('Color Targets'!$AA$2=1,G64,K64) -> 0.072175
B5: =IF('Color Targets'!$AA$2=1,E65,I65) -> 0.0193339 | C5: =IF('Color Targets'!$AA$2=1,F65,J65) -> 0.119192 | D5: =IF('Color Targets'!$AA$2=1,G65,K65) -> 0.9503041
A6: Companded
A7: Vectors | I7: Normalized | P7: gammafied | W7: XYZ | AD7: xyY
A8: 100/100 | B8: R | C8: G | D8: B | E8: Y | F8: C | G8: M | H8: W | I8: R | J8: G | K8: B | L8: Y | M8: C | N8: M | O8: W | P8: R | Q8: G | R8: B | S8: Y | T8: C | U8: M | V8: W | W8: R | X8: G | Y8: B | Z8: Y | AA8: C | AB8: M | AC8: W | AD8: R | AE8: G | AF8: B | AG8: Y | AH8: C | AI8: M | AJ8: W
A9: R' | B9: 235 | C9: 16 | D9: 16 | E9: 235 | F9: 16 | G9: 235 | H9: 235 | I9: =(B9-16)/219 -> 1 | J9: =(C9-16)/219 -> 0 | K9: =(D9-16)/219 -> 0 | L9: =(E9-16)/219 -> 1 | M9: =(F9-16)/219 -> 0 | N9: =(G9-16)/219 -> 1 | O9: =(H9-16)/219 -> 1 | P9: =I9^$N$1 -> 1 | Q9: =J9^$N$1 -> 0 | R9: =K9^$N$1 -> 0 | S9: =L9^$N$1 -> 1 | T9: =M9^$N$1 -> 0 | U9: =N9^$N$1 -> 1 | V9: =O9^$N$1 -> 1 | W9: {=MMULT($B$3:$D$5,P9:P11)} -> 0.4124564 | X9: {=MMULT($B$3:$D$5,Q9:Q11)} -> 0.3575761 | Y9: {=MMULT($B$3:$D$5,R9:R11)} -> 0.1804375 | Z9: {=MMULT($B$3:$D$5,S9:S11)} -> 0.7700325 | AA9: {=MMULT($B$3:$D$5,T9:T11)} -> 0.5380136 | AB9: {=MMULT($B$3:$D$5,U9:U11)} -> 0.5928939 | AC9: {=MMULT($B$3:$D$5,V9:V11)} -> 0.95047 | AD9: =W9/(W9+W10+W11) -> 0.63999993 | AE9: =X9/(X9+X10+X11) -> 0.30000001 | AF9: =Y9/(Y9+Y10+Y11) -> 0.15000001 | AG9: =Z9/(Z9+Z10+Z11) -> 0.41932009 | AH9: =AA9/(AA9+AA10+AA11) -> 0.22465563 | AI9: =AB9/(AB9+AB10+AB11) -> 0.32093774 | AJ9: =AC9/(AC9+AC10+AC11) -> 0.3127266
A10: G' | B10: 16 | C10: 235 | D10: 16 | E10: 235 | F10: 235 | G10: 16 | H10: 235 | I10: =(B10-16)/219 -> 0 | J10: =(C10-16)/219 -> 1 | K10: =(D10-16)/219 -> 0 | L10: =(E10-16)/219 -> 1 | M10: =(F10-16)/219 -> 1 | N10: =(G10-16)/219 -> 0 | O10: =(H10-16)/219 -> 1 | P10: =I10^$N$1 -> 0 | Q10: =J10^$N$1 -> 1 | R10: =K10^$N$1 -> 0 | S10: =L10^$N$1 -> 1 | T10: =M10^$N$1 -> 1 | U10: =N10^$N$1 -> 0 | V10: =O10^$N$1 -> 1 | W10: 0.2126729 | X10: 0.7151522 | Y10: 0.072175 | Z10: 0.9278251 | AA10: 0.7873272 | AB10: 0.2848479 | AC10: 1.0000001 | AD10: =W10/(W9+W10+W11) -> 0.33000007 | AE10: =X10/(X9+X10+X11) -> 0.60000002 | AF10: =Y10/(Y9+Y10+Y11) -> 0.060000003 | AG10: =Z10/(Z9+Z10+Z11) -> 0.50524583 | AH10: =AA10/(AA9+AA10+AA11) -> 0.32876026 | AI10: =AB10/(AB9+AB10+AB11) -> 0.15419022 | AJ10: =AC10/(AC9+AC10+AC11) -> 0.32902315
A11: B' | B11: 16 | C11: 16 | D11: 235 | E11: 16 | F11: 235 | G11: 235 | H11: 235 | I11: =(B11-16)/219 -> 0 | J11: =(C11-16)/219 -> 0 | K11: =(D11-16)/219 -> 1 | L11: =(E11-16)/219 -> 0 | M11: =(F11-16)/219 -> 1 | N11: =(G11-16)/219 -> 1 | O11: =(H11-16)/219 -> 1 | P11: =I11^$N$1 -> 0 | Q11: =J11^$N$1 -> 0 | R11: =K11^$N$1 -> 1 | S11: =L11^$N$1 -> 0 | T11: =M11^$N$1 -> 1 | U11: =N11^$N$1 -> 1 | V11: =O11^$N$1 -> 1 | W11: 0.0193339 | X11: 0.119192 | Y11: 0.9503041 | Z11: 0.1385259 | AA11: 1.0694961 | AB11: 0.969638 | AC11: 1.08883 | AD11: =W10 -> 0.2126729 | AE11: =X10 -> 0.7151522 | AF11: =Y10 -> 0.072175 | AG11: =Z10 -> 0.9278251 | AH11: =AA10 -> 0.7873272 | AI11: =AB10 -> 0.2848479 | AJ11: =AC10 -> 1.0000001
A13: 100/75
A14: R' | B14: 215 | C14: 97 | D14: 71 | E14: 233 | F14: 121 | G14: 202 | H14: 235 | I14: =(B14-16)/219 -> 0.9086758 | J14: =(C14-16)/219 -> 0.36986301 | K14: =(D14-16)/219 -> 0.25114155 | L14: =(E14-16)/219 -> 0.99086758 | M14: =(F14-16)/219 -> 0.47945205 | N14: =(G14-16)/219 -> 0.84931507 | O14: =(H14-16)/219 -> 1 | P14: =I14^IF('Color Targets'!$AA$1=1,$N$1,INDEX(Calculation!$G$128:$G$237,MATCH(I14,Calculation!$H$128:$H$237))) -> 0.7996636 | Q14: =J14^IF('Color Targets'!$AA$1=1,$N$1,INDEX(Calculation!$G$128:$G$237,MATCH(J14,Calculation!$H$128:$H$237))) -> 0.10267674 | R14: =K14^IF('Color Targets'!$AA$1=1,$N$1,INDEX(Calculation!$G$128:$G$237,MATCH(K14,Calculation!$H$128:$H$237))) -> 0.044782682 | S14: =L14^IF('Color Targets'!$AA$1=1,$N$1,INDEX(Calculation!$G$128:$G$237,MATCH(L14,Calculation!$H$128:$H$237))) -> 0.97881049 | T14: =M14^IF('Color Targets'!$AA$1=1,$N$1,INDEX(Calculation!$G$128:$G$237,MATCH(M14,Calculation!$H$128:$H$237))) -> 0.18677383 | U14: =N14^IF('Color Targets'!$AA$1=1,$N$1,INDEX(Calculation!$G$128:$G$237,MATCH(N14,Calculation!$H$128:$H$237))) -> 0.68683412 | V14: =O14^$N$1 -> 1 | W14: {=MMULT($B$3:$D$5,P14:P16)} -> 0.35763821 | X14: {=MMULT($B$3:$D$5,Q14:Q16)} -> 0.40339141 | Y14: {=MMULT($B$3:$D$5,R14:R16)} -> 0.10282302 | Z14: {=MMULT($B$3:$D$5,S14:S16)} -> 0.78120276 | AA14: {=MMULT($B$3:$D$5,T14:T16)} -> 0.59238853 | AB14: {=MMULT($B$3:$D$5,U14:U16)} -> 0.44604217 | AC14: {=MMULT($B$3:$D$5,V14:V16)} -> 0.95047 | AD14: =W14/(W14+W15+W16) -> 0.55955161 | AE14: =X14/(X14+X15+X16) -> 0.30298298 | AF14: =Y14/(Y14+Y15+Y16) -> 0.19118098 | AG14: =Z14/(Z14+Z15+Z16) -> 0.39440398 | AH14: =AA14/(AA14+AA15+AA16) -> 0.245363 | AI14: =AB14/(AB14+AB15+AB16) -> 0.31899996 | AJ14: =AC14/(AC14+AC15+AC16) -> 0.3127266
A15: G' | B15: 75 | C15: 231 | D15: 71 | E15: 233 | F15: 231 | G15: 99 | H15: 235 | I15: =(B15-16)/219 -> 0.26940639 | J15: =(C15-16)/219 -> 0.98173516 | K15: =(D15-16)/219 -> 0.25114155 | L15: =(E15-16)/219 -> 0.99086758 | M15: =(F15-16)/219 -> 0.98173516 | N15: =(G15-16)/219 -> 0.37899543 | O15: =(H15-16)/219 -> 1 | P15: =I15^IF('Color Targets'!$AA$1=1,$N$1,INDEX(Calculation!$G$128:$G$237,MATCH(I15,Calculation!$H$128:$H$237))) -> 0.05169357 | Q15: =J15^IF('Color Targets'!$AA$1=1,$N$1,INDEX(Calculation!$G$128:$G$237,MATCH(J15,Calculation!$H$128:$H$237))) -> 0.95788 | R15: =K15^IF('Color Targets'!$AA$1=1,$N$1,INDEX(Calculation!$G$128:$G$237,MATCH(K15,Calculation!$H$128:$H$237))) -> 0.044782682 | S15: =L15^IF('Color Targets'!$AA$1=1,$N$1,INDEX(Calculation!$G$128:$G$237,MATCH(L15,Calculation!$H$128:$H$237))) -> 0.97881049 | T15: =M15^IF('Color Targets'!$AA$1=1,$N$1,INDEX(Calculation!$G$128:$G$237,MATCH(M15,Calculation!$H$128:$H$237))) -> 0.95788 | U15: =N15^IF('Color Targets'!$AA$1=1,$N$1,INDEX(Calculation!$G$128:$G$237,MATCH(N15,Calculation!$H$128:$H$237))) -> 0.10857106 | V15: =O15^$N$1 -> 1 | W15: 0.21076653 | X15: 0.71427725 | Y15: 0.068886057 | Z15: 0.91915969 | AA15: 0.79388671 | AB15: 0.27328809 | AC15: 1.0000001 | AD15: =W15/(W14+W15+W16) -> 0.32975993 | AE15: =X15/(X14+X15+X16) -> 0.53648602 | AF15: =Y15/(Y14+Y15+Y16) -> 0.12808127 | AG15: =Z15/(Z14+Z15+Z16) -> 0.46405397 | AH15: =AA15/(AA14+AA15+AA16) -> 0.32882207 | AI15: =AB15/(AB14+AB15+AB16) -> 0.19544988 | AJ15: =AC15/(AC14+AC15+AC16) -> 0.32902315
A16: B' | B16: 75 | C16: 97 | D16: 161 | E16: 112 | F16: 231 | G16: 202 | H16: 235 | I16: =(B16-16)/219 -> 0.26940639 | J16: =(C16-16)/219 -> 0.36986301 | K16: =(D16-16)/219 -> 0.66210046 | L16: =(E16-16)/219 -> 0.43835616 | M16: =(F16-16)/219 -> 0.98173516 | N16: =(G16-16)/219 -> 0.84931507 | O16: =(H16-16)/219 -> 1 | P16: =I16^IF('Color Targets'!$AA$1=1,$N$1,INDEX(Calculation!$G$128:$G$237,MATCH(I16,Calculation!$H$128:$H$237))) -> 0.05169357 | Q16: =J16^IF('Color Targets'!$AA$1=1,$N$1,INDEX(Calculation!$G$128:$G$237,MATCH(J16,Calculation!$H$128:$H$237))) -> 0.10267674 | R16: =K16^IF('Color Targets'!$AA$1=1,$N$1,INDEX(Calculation!$G$128:$G$237,MATCH(K16,Calculation!$H$128:$H$237))) -> 0.37874001 | S16: =L16^IF('Color Targets'!$AA$1=1,$N$1,INDEX(Calculation!$G$128:$G$237,MATCH(L16,Calculation!$H$128:$H$237))) -> 0.15233459 | T16: =M16^IF('Color Targets'!$AA$1=1,$N$1,INDEX(Calculation!$G$128:$G$237,MATCH(M16,Calculation!$H$128:$H$237))) -> 0.95788 | U16: =N16^IF('Color Targets'!$AA$1=1,$N$1,INDEX(Calculation!$G$128:$G$237,MATCH(N16,Calculation!$H$128:$H$237))) -> 0.68683412 | V16: =O16^$N$1 -> 1 | W16: 0.070746688 | X16: 0.2137309 | Y16: 0.36612174 | Z16: 0.28035479 | AA16: 1.02806 | AB16: 0.67892126 | AC16: 1.08883 | AD16: =W15 -> 0.21076653 | AE16: =X15 -> 0.71427725 | AF16: =Y15 -> 0.068886057 | AG16: =Z15 -> 0.91915969 | AH16: =AA15 -> 0.79388671 | AI16: =AB15 -> 0.27328809 | AJ16: =AC15 -> 1.0000001
A18: 100/50
A19: R' | B19: 191 | C19: 134 | D19: 77 | E19: 233 | F19: 161 | G19: 178 | H19: 235 | I19: =(B19-16)/219 -> 0.79908676 | J19: =(C19-16)/219 -> 0.53881279 | K19: =(D19-16)/219 -> 0.27853881 | L19: =(E19-16)/219 -> 0.99086758 | M19: =(F19-16)/219 -> 0.66210046 | N19: =(G19-16)/219 -> 0.73972603 | O19: =(H19-16)/219 -> 1 | P19: =I19^IF('Color Targets'!$AA$1=1,$N$1,INDEX(Calculation!$G$128:$G$237,MATCH(I19,Calculation!$H$128:$H$237))) -> 0.59346637 | Q19: =J19^IF('Color Targets'!$AA$1=1,$N$1,INDEX(Calculation!$G$128:$G$237,MATCH(J19,Calculation!$H$128:$H$237))) -> 0.24300095 | R19: =K19^IF('Color Targets'!$AA$1=1,$N$1,INDEX(Calculation!$G$128:$G$237,MATCH(K19,Calculation!$H$128:$H$237))) -> 0.055772336 | S19: =L19^IF('Color Targets'!$AA$1=1,$N$1,INDEX(Calculation!$G$128:$G$237,MATCH(L19,Calculation!$H$128:$H$237))) -> 0.97881049 | T19: =M19^IF('Color Targets'!$AA$1=1,$N$1,INDEX(Calculation!$G$128:$G$237,MATCH(M19,Calculation!$H$128:$H$237))) -> 0.37874001 | U19: =N19^IF('Color Targets'!$AA$1=1,$N$1,INDEX(Calculation!$G$128:$G$237,MATCH(N19,Calculation!$H$128:$H$237))) -> 0.50036769 | V19: =O19^$N$1 -> 1 | W19: {=MMULT($B$3:$D$5,P19:P21)} -> 0.29707031 | X19: {=MMULT($B$3:$D$5,Q19:Q21)} -> 0.46111915 | Y19: {=MMULT($B$3:$D$5,R19:R21)} -> 0.080254815 | Z19: {=MMULT($B$3:$D$5,S19:S21)} -> 0.81707014 | AA19: {=MMULT($B$3:$D$5,T19:T21)} -> 0.63324428 | AB19: {=MMULT($B$3:$D$5,U19:U21)} -> 0.36345081 | AC19: {=MMULT($B$3:$D$5,V19:V21)} -> 0.95047 | AD19: =W19/(W19+W20+W21) -> 0.48286114 | AE19: =X19/(X19+X20+X21) -> 0.30624233 | AF19: =Y19/(Y19+Y20+Y21) -> 0.22855412 | AG19: =Z19/(Z19+Z20+Z21) -> 0.36807729 | AH19: =AA19/(AA19+AA20+AA21) -> 0.26747726 | AI19: =AB19/(AB19+AB20+AB21) -> 0.31687393 | AJ19: =AC19/(AC19+AC20+AC21) -> 0.3127266
A20: G' | B20: 95 | C20: 224 | D20: 77 | E20: 233 | F20: 224 | G20: 121 | H20: 235 | I20: =(B20-16)/219 -> 0.36073059 | J20: =(C20-16)/219 -> 0.94977169 | K20: =(D20-16)/219 -> 0.27853881 | L20: =(E20-16)/219 -> 0.99086758 | M20: =(F20-16)/219 -> 0.94977169 | N20: =(G20-16)/219 -> 0.47945205 | O20: =(H20-16)/219 -> 1 | P20: =I20^IF('Color Targets'!$AA$1=1,$N$1,INDEX(Calculation!$G$128:$G$237,MATCH(I20,Calculation!$H$128:$H$237))) -> 0.097193274 | Q20: =J20^IF('Color Targets'!$AA$1=1,$N$1,INDEX(Calculation!$G$128:$G$237,MATCH(J20,Calculation!$H$128:$H$237))) -> 0.88665146 | R20: =K20^IF('Color Targets'!$AA$1=1,$N$1,INDEX(Calculation!$G$128:$G$237,MATCH(K20,Calculation!$H$128:$H$237))) -> 0.055772336 | S20: =L20^IF('Color Targets'!$AA$1=1,$N$1,INDEX(Calculation!$G$128:$G$237,MATCH(L20,Calculation!$H$128:$H$237))) -> 0.97881049 | T20: =M20^IF('Color Targets'!$AA$1=1,$N$1,INDEX(Calculation!$G$128:$G$237,MATCH(M20,Calculation!$H$128:$H$237))) -> 0.88665146 | U20: =N20^IF('Color Targets'!$AA$1=1,$N$1,INDEX(Calculation!$G$128:$G$237,MATCH(N20,Calculation!$H$128:$H$237))) -> 0.18677383 | V20: =O20^$N$1 -> 1 | W20: 0.20273712 | X20: 0.70330905 | Y20: 0.066670294 | Z20: 0.93350664 | AA20: 0.77863255 | AB20: 0.2761004 | AC20: 1.0000001 | AD20: =W20/(W19+W20+W21) -> 0.32953101 | AE20: =X20/(X19+X20+X21) -> 0.46708752 | AF20: =Y20/(Y19+Y20+Y21) -> 0.18986737 | AG20: =Z20/(Z19+Z20+Z21) -> 0.42053011 | AH20: =AA20/(AA19+AA20+AA21) -> 0.32888808 | AI20: =AB20/(AB19+AB20+AB21) -> 0.24071763 | AJ20: =AC20/(AC19+AC20+AC21) -> 0.32902315
A21: B' | B21: 95 | C21: 134 | D21: 126 | E21: 156 | F21: 224 | G21: 178 | H21: 235 | I21: =(B21-16)/219 -> 0.36073059 | J21: =(C21-16)/219 -> 0.53881279 | K21: =(D21-16)/219 -> 0.50228311 | L21: =(E21-16)/219 -> 0.63926941 | M21: =(F21-16)/219 -> 0.94977169 | N21: =(G21-16)/219 -> 0.73972603 | O21: =(H21-16)/219 -> 1 | P21: =I21^IF('Color Targets'!$AA$1=1,$N$1,INDEX(Calculation!$G$128:$G$237,MATCH(I21,Calculation!$H$128:$H$237))) -> 0.097193274 | Q21: =J21^IF('Color Targets'!$AA$1=1,$N$1,INDEX(Calculation!$G$128:$G$237,MATCH(J21,Calculation!$H$128:$H$237))) -> 0.24300095 | R21: =K21^IF('Color Targets'!$AA$1=1,$N$1,INDEX(Calculation!$G$128:$G$237,MATCH(K21,Calculation!$H$128:$H$237))) -> 0.2067658 | S21: =L21^IF('Color Targets'!$AA$1=1,$N$1,INDEX(Calculation!$G$128:$G$237,MATCH(L21,Calculation!$H$128:$H$237))) -> 0.35111462 | T21: =M21^IF('Color Targets'!$AA$1=1,$N$1,INDEX(Calculation!$G$128:$G$237,MATCH(M21,Calculation!$H$128:$H$237))) -> 0.88665146 | U21: =N21^IF('Color Targets'!$AA$1=1,$N$1,INDEX(Calculation!$G$128:$G$237,MATCH(N21,Calculation!$H$128:$H$237))) -> 0.50036769 | V21: =O21^$N$1 -> 1 | W21: 0.11542185 | X21: 0.34130472 | Y21: 0.2042163 | Z21: 0.46925627 | AA21: 0.9555928 | AB21: 0.50743747 | AC21: 1.08883 | AD21: =W20 -> 0.20273712 | AE21: =X20 -> 0.70330905 | AF21: =Y20 -> 0.066670294 | AG21: =Z20 -> 0.93350664 | AH21: =AA20 -> 0.77863255 | AI21: =AB20 -> 0.2761004 | AJ21: =AC20 -> 1.0000001
A23: 75/100
A24: R' | B24: 180 | C24: 16 | D24: 16 | E24: 180 | F24: 16 | G24: 180 | H24: 180 | I24: =(B24-16)/219 -> 0.74885845 | J24: =(C24-16)/219 -> 0 | K24: =(D24-16)/219 -> 0 | L24: =(E24-16)/219 -> 0.74885845 | M24: =(F24-16)/219 -> 0 | N24: =(G24-16)/219 -> 0.74885845 | O24: =(H24-16)/219 -> 0.74885845 | P24: =I24^IF('Color Targets'!$AA$1=1,$N$1,INDEX(Calculation!$G$128:$G$237,MATCH(I24,Calculation!$H$128:$H$237))) -> 0.51552944 | Q24: =J24^$N$1 -> 0 | R24: =K24^$N$1 -> 0 | S24: =L24^IF('Color Targets'!$AA$1=1,$N$1,INDEX(Calculation!$G$128:$G$237,MATCH(L24,Calculation!$H$128:$H$237))) -> 0.51552944 | T24: =M24^$N$1 -> 0 | U24: =N24^IF('Color Targets'!$AA$1=1,$N$1,INDEX(Calculation!$G$128:$G$237,MATCH(N24,Calculation!$H$128:$H$237))) -> 0.51552944 | V24: =O24^IF('Color Targets'!$AA$1=1,$N$1,INDEX(Calculation!$G$128:$G$237,MATCH(O24,Calculation!$H$128:$H$237))) -> 0.51552944 | W24: {=MMULT($B$3:$D$5,P24:P26)} -> 0.21263342 | X24: {=MMULT($B$3:$D$5,Q24:Q26)} -> 0.18434101 | Y24: {=MMULT($B$3:$D$5,R24:R26)} -> 0.093020844 | Z24: {=MMULT($B$3:$D$5,S24:S26)} -> 0.39697443 | AA24: {=MMULT($B$3:$D$5,T24:T26)} -> 0.27736185 | AB24: {=MMULT($B$3:$D$5,U24:U26)} -> 0.30565426 | AC24: {=MMULT($B$3:$D$5,V24:V26)} -> 0.48999527 | AD24: =W24/(W24+W25+W26) -> 0.63999993 | AE24: =X24/(X24+X25+X26) -> 0.30000001 | AF24: =Y24/(Y24+Y25+Y26) -> 0.15000001 | AG24: =Z24/(Z24+Z25+Z26) -> 0.41932009 | AH24: =AA24/(AA24+AA25+AA26) -> 0.22465563 | AI24: =AB24/(AB24+AB25+AB26) -> 0.32093774 | AJ24: =AC24/(AC24+AC25+AC26) -> 0.3127266
A25: G' | B25: 16 | C25: 180 | D25: 16 | E25: 180 | F25: 180 | G25: 16 | H25: 180 | I25: =(B25-16)/219 -> 0 | J25: =(C25-16)/219 -> 0.74885845 | K25: =(D25-16)/219 -> 0 | L25: =(E25-16)/219 -> 0.74885845 | M25: =(F25-16)/219 -> 0.74885845 | N25: =(G25-16)/219 -> 0 | O25: =(H25-16)/219 -> 0.74885845 | P25: =I25^$N$1 -> 0 | Q25: =J25^IF('Color Targets'!$AA$1=1,$N$1,INDEX(Calculation!$G$128:$G$237,MATCH(J25,Calculation!$H$128:$H$237))) -> 0.51552944 | R25: =K25^$N$1 -> 0 | S25: =L25^IF('Color Targets'!$AA$1=1,$N$1,INDEX(Calculation!$G$128:$G$237,MATCH(L25,Calculation!$H$128:$H$237))) -> 0.51552944 | T25: =M25^IF('Color Targets'!$AA$1=1,$N$1,INDEX(Calculation!$G$128:$G$237,MATCH(M25,Calculation!$H$128:$H$237))) -> 0.51552944 | U25: =N25^$N$1 -> 0 | V25: =O25^IF('Color Targets'!$AA$1=1,$N$1,INDEX(Calculation!$G$128:$G$237,MATCH(O25,Calculation!$H$128:$H$237))) -> 0.51552944 | W25: 0.10963914 | X25: 0.36868201 | Y25: 0.037208337 | Z25: 0.47832116 | AA25: 0.40589035 | AB25: 0.14684748 | AC25: 0.51552949 | AD25: =W25/(W24+W25+W26) -> 0.33000007 | AE25: =X25/(X24+X25+X26) -> 0.60000002 | AF25: =Y25/(Y24+Y25+Y26) -> 0.060000003 | AG25: =Z25/(Z24+Z25+Z26) -> 0.50524583 | AH25: =AA25/(AA24+AA25+AA26) -> 0.32876026 | AI25: =AB25/(AB24+AB25+AB26) -> 0.15419022 | AJ25: =AC25/(AC24+AC25+AC26) -> 0.32902315
A26: B' | B26: 16 | C26: 16 | D26: 180 | E26: 16 | F26: 180 | G26: 180 | H26: 180 | I26: =(B26-16)/219 -> 0 | J26: =(C26-16)/219 -> 0 | K26: =(D26-16)/219 -> 0.74885845 | L26: =(E26-16)/219 -> 0 | M26: =(F26-16)/219 -> 0.74885845 | N26: =(G26-16)/219 -> 0.74885845 | O26: =(H26-16)/219 -> 0.74885845 | P26: =I26^$N$1 -> 0 | Q26: =J26^$N$1 -> 0 | R26: =K26^IF('Color Targets'!$AA$1=1,$N$1,INDEX(Calculation!$G$128:$G$237,MATCH(K26,Calculation!$H$128:$H$237))) -> 0.51552944 | S26: =L26^$N$1 -> 0 | T26: =M26^IF('Color Targets'!$AA$1=1,$N$1,INDEX(Calculation!$G$128:$G$237,MATCH(M26,Calculation!$H$128:$H$237))) -> 0.51552944 | U26: =N26^IF('Color Targets'!$AA$1=1,$N$1,INDEX(Calculation!$G$128:$G$237,MATCH(N26,Calculation!$H$128:$H$237))) -> 0.51552944 | V26: =O26^IF('Color Targets'!$AA$1=1,$N$1,INDEX(Calculation!$G$128:$G$237,MATCH(O26,Calculation!$H$128:$H$237))) -> 0.51552944 | W26: 0.0099671947 | X26: 0.061446985 | Y26: 0.48990974 | Z26: 0.07141418 | AA26: 0.55135673 | AB26: 0.49987694 | AC26: 0.56132392 | AD26: =W25 -> 0.10963914 | AE26: =X25 -> 0.36868201 | AF26: =Y25 -> 0.037208337 | AG26: =Z25 -> 0.47832116 | AH26: =AA25 -> 0.40589035 | AI26: =AB25 -> 0.14684748 | AJ26: =AC25 -> 0.51552949
A28: 75/75
A29: R' | B29: 165 | C29: 77 | D29: 58 | E29: 180 | F29: 95 | G29: 156 | H29: 180 | I29: =(B29-16)/219 -> 0.6803653 | J29: =(C29-16)/219 -> 0.27853881 | K29: =(D29-16)/219 -> 0.19178082 | L29: =(E29-16)/219 -> 0.74885845 | M29: =(F29-16)/219 -> 0.36073059 | N29: =(G29-16)/219 -> 0.63926941 | O29: =(H29-16)/219 -> 0.74885845 | P29: =I29^IF('Color Targets'!$AA$1=1,$N$1,INDEX(Calculation!$G$128:$G$237,MATCH(I29,Calculation!$H$128:$H$237))) -> 0.40522163 | Q29: =J29^IF('Color Targets'!$AA$1=1,$N$1,INDEX(Calculation!$G$128:$G$237,MATCH(J29,Calculation!$H$128:$H$237))) -> 0.055772336 | R29: =K29^IF('Color Targets'!$AA$1=1,$N$1,INDEX(Calculation!$G$128:$G$237,MATCH(K29,Calculation!$H$128:$H$237))) -> 0.026117855 | S29: =L29^IF('Color Targets'!$AA$1=1,$N$1,INDEX(Calculation!$G$128:$G$237,MATCH(L29,Calculation!$H$128:$H$237))) -> 0.51552944 | T29: =M29^IF('Color Targets'!$AA$1=1,$N$1,INDEX(Calculation!$G$128:$G$237,MATCH(M29,Calculation!$H$128:$H$237))) -> 0.097193274 | U29: =N29^IF('Color Targets'!$AA$1=1,$N$1,INDEX(Calculation!$G$128:$G$237,MATCH(N29,Calculation!$H$128:$H$237))) -> 0.35111462 | V29: =O29^IF('Color Targets'!$AA$1=1,$N$1,INDEX(Calculation!$G$139:$G$237,MATCH(O29,Calculation!$A$139:$A$237))) -> 0.51141483 | W29: {=MMULT($B$3:$D$5,P29:P31)} -> 0.18270758 | X29: {=MMULT($B$3:$D$5,Q29:Q31)} -> 0.20632472 | Y29: {=MMULT($B$3:$D$5,R29:R31)} -> 0.0574199 | Z29: {=MMULT($B$3:$D$5,S29:S31)} -> 0.41156048 | AA29: {=MMULT($B$3:$D$5,T29:T31)} -> 0.30077367 | AB29: {=MMULT($B$3:$D$5,U29:U31)} -> 0.23041409 | AC29: {=MMULT($B$3:$D$5,V29:V31)} -> 0.48608446 | AD29: =W29/(W29+W30+W31) -> 0.55288461 | AE29: =X29/(X29+X30+X31) -> 0.30316986 | AF29: =Y29/(Y29+Y30+Y31) -> 0.19353865 | AG29: =Z29/(Z29+Z30+Z31) -> 0.39423385 | AH29: =AA29/(AA29+AA30+AA31) -> 0.24592773 | AI29: =AB29/(AB29+AB30+AB31) -> 0.31879018 | AJ29: =AC29/(AC29+AC30+AC31) -> 0.3127266
A30: G' | B30: 60 | C30: 176 | D30: 58 | E30: 180 | F30: 176 | G30: 80 | H30: 180 | I30: =(B30-16)/219 -> 0.20091324 | J30: =(C30-16)/219 -> 0.73059361 | K30: =(D30-16)/219 -> 0.19178082 | L30: =(E30-16)/219 -> 0.74885845 | M30: =(F30-16)/219 -> 0.73059361 | N30: =(G30-16)/219 -> 0.29223744 | O30: =(H30-16)/219 -> 0.74885845 | P30: =I30^IF('Color Targets'!$AA$1=1,$N$1,INDEX(Calculation!$G$128:$G$237,MATCH(I30,Calculation!$H$128:$H$237))) -> 0.028942257 | Q30: =J30^IF('Color Targets'!$AA$1=1,$N$1,INDEX(Calculation!$G$128:$G$237,MATCH(J30,Calculation!$H$128:$H$237))) -> 0.48453362 | R30: =K30^IF('Color Targets'!$AA$1=1,$N$1,INDEX(Calculation!$G$128:$G$237,MATCH(K30,Calculation!$H$128:$H$237))) -> 0.026117855 | S30: =L30^IF('Color Targets'!$AA$1=1,$N$1,INDEX(Calculation!$G$128:$G$237,MATCH(L30,Calculation!$H$128:$H$237))) -> 0.51552944 | T30: =M30^IF('Color Targets'!$AA$1=1,$N$1,INDEX(Calculation!$G$128:$G$237,MATCH(M30,Calculation!$H$128:$H$237))) -> 0.48453362 | U30: =N30^IF('Color Targets'!$AA$1=1,$N$1,INDEX(Calculation!$G$128:$G$237,MATCH(N30,Calculation!$H$128:$H$237))) -> 0.062197582 | V30: =O30^IF('Color Targets'!$AA$1=1,$N$1,INDEX(Calculation!$G$139:$G$237,MATCH(O30,Calculation!$A$139:$A$237))) -> 0.51141483 | W30: 0.10896669 | X30: 0.36240192 | Y30: 0.039156122 | Z30: 0.48415558 | AA30: 0.40215688 | AB30: 0.144495 | AC30: 0.51141488 | AD30: =W30/(W29+W30+W31) -> 0.32974003 | AE30: =X30/(X29+X30+X31) -> 0.53250691 | AF30: =Y30/(Y29+Y30+Y31) -> 0.13197904 | AG30: =Z30/(Z29+Z30+Z31) -> 0.4637727 | AH30: =AA30/(AA29+AA30+AA31) -> 0.32882376 | AI30: =AB30/(AB29+AB30+AB31) -> 0.19991654 | AJ30: =AC30/(AC29+AC30+AC31) -> 0.32902315
A31: B' | B31: 60 | C31: 77 | D31: 126 | E31: 88 | F31: 176 | G31: 156 | H31: 180 | I31: =(B31-16)/219 -> 0.20091324 | J31: =(C31-16)/219 -> 0.27853881 | K31: =(D31-16)/219 -> 0.50228311 | L31: =(E31-16)/219 -> 0.32876712 | M31: =(F31-16)/219 -> 0.73059361 | N31: =(G31-16)/219 -> 0.63926941 | O31: =(H31-16)/219 -> 0.74885845 | P31: =I31^IF('Color Targets'!$AA$1=1,$N$1,INDEX(Calculation!$G$128:$G$237,MATCH(I31,Calculation!$H$128:$H$237))) -> 0.028942257 | Q31: =J31^IF('Color Targets'!$AA$1=1,$N$1,INDEX(Calculation!$G$128:$G$237,MATCH(J31,Calculation!$H$128:$H$237))) -> 0.055772336 | R31: =K31^IF('Color Targets'!$AA$1=1,$N$1,INDEX(Calculation!$G$128:$G$237,MATCH(K31,Calculation!$H$128:$H$237))) -> 0.2067658 | S31: =L31^IF('Color Targets'!$AA$1=1,$N$1,INDEX(Calculation!$G$128:$G$237,MATCH(L31,Calculation!$H$128:$H$237))) -> 0.080837183 | T31: =M31^IF('Color Targets'!$AA$1=1,$N$1,INDEX(Calculation!$G$128:$G$237,MATCH(M31,Calculation!$H$128:$H$237))) -> 0.48453362 | U31: =N31^IF('Color Targets'!$AA$1=1,$N$1,INDEX(Calculation!$G$128:$G$237,MATCH(N31,Calculation!$H$128:$H$237))) -> 0.35111462 | V31: =O31^IF('Color Targets'!$AA$1=1,$N$1,INDEX(Calculation!$G$139:$G$237,MATCH(O31,Calculation!$A$139:$A$237))) -> 0.51141483 | W31: 0.038788145 | X31: 0.11183151 | Y31: 0.20010838 | Z31: 0.14823409 | AA31: 0.52008594 | AB31: 0.34786754 | AC31: 0.55684381 | AD31: =W30 -> 0.10896669 | AE31: =X30 -> 0.36240192 | AF31: =Y30 -> 0.039156122 | AG31: =Z30 -> 0.48415558 | AH31: =AA30 -> 0.40215688 | AI31: =AB30 -> 0.144495 | AJ31: =AC30 -> 0.51141488
A33: 75/50
A34: R' | B34: 147 | C34: 104 | D34: 62 | E34: 178 | F34: 123 | G34: 139 | H34: 180 | I34: =(B34-16)/219 -> 0.59817352 | J34: =(C34-16)/219 -> 0.40182648 | K34: =(D34-16)/219 -> 0.21004566 | L34: =(E34-16)/219 -> 0.73972603 | M34: =(F34-16)/219 -> 0.48858447 | N34: =(G34-16)/219 -> 0.56164384 | O34: =(H34-16)/219 -> 0.74885845 | P34: =I34^IF('Color Targets'!$AA$1=1,$N$1,INDEX(Calculation!$G$128:$G$237,MATCH(I34,Calculation!$H$128:$H$237))) -> 0.305844 | Q34: =J34^IF('Color Targets'!$AA$1=1,$N$1,INDEX(Calculation!$G$128:$G$237,MATCH(J34,Calculation!$H$128:$H$237))) -> 0.12400842 | R34: =K34^IF('Color Targets'!$AA$1=1,$N$1,INDEX(Calculation!$G$128:$G$237,MATCH(K34,Calculation!$H$128:$H$237))) -> 0.031317129 | S34: =L34^IF('Color Targets'!$AA$1=1,$N$1,INDEX(Calculation!$G$128:$G$237,MATCH(L34,Calculation!$H$128:$H$237))) -> 0.50036769 | T34: =M34^IF('Color Targets'!$AA$1=1,$N$1,INDEX(Calculation!$G$128:$G$237,MATCH(M34,Calculation!$H$128:$H$237))) -> 0.19453828 | U34: =N34^IF('Color Targets'!$AA$1=1,$N$1,INDEX(Calculation!$G$128:$G$237,MATCH(N34,Calculation!$H$128:$H$237))) -> 0.26694943 | V34: =O34^IF('Color Targets'!$AA$1=1,$N$1,INDEX(Calculation!$G$139:$G$237,MATCH(O34,Calculation!$A$139:$A$237))) -> 0.51141483 | W34: {=MMULT($B$3:$D$5,P34:P36)} -> 0.15395916 | X34: {=MMULT($B$3:$D$5,Q34:Q36)} -> 0.23325802 | Y34: {=MMULT($B$3:$D$5,R34:R36)} -> 0.043705497 | Z34: {=MMULT($B$3:$D$5,S34:S36)} -> 0.41900039 | AA34: {=MMULT($B$3:$D$5,T34:T36)} -> 0.32057667 | AB34: {=MMULT($B$3:$D$5,U34:U36)} -> 0.19302668 | AC34: {=MMULT($B$3:$D$5,V34:V36)} -> 0.48608446 | AD34: =W34/(W34+W35+W36) -> 0.47976872 | AE34: =X34/(X34+X35+X36) -> 0.30629863 | AF34: =Y34/(Y34+Y35+Y36) -> 0.23233741 | AG34: =Z34/(Z34+Z35+Z36) -> 0.36640631 | AH34: =AA34/(AA34+AA35+AA36) -> 0.2682247 | AI34: =AB34/(AB34+AB35+AB36) -> 0.3169549 | AJ34: =AC34/(AC34+AC35+AC36) -> 0.3127266
A35: G' | B35: 75 | C35: 171 | D35: 62 | E35: 178 | F35: 171 | G35: 95 | H35: 180 | I35: =(B35-16)/219 -> 0.26940639 | J35: =(C35-16)/219 -> 0.70776256 | K35: =(D35-16)/219 -> 0.21004566 | L35: =(E35-16)/219 -> 0.73972603 | M35: =(F35-16)/219 -> 0.70776256 | N35: =(G35-16)/219 -> 0.36073059 | O35: =(H35-16)/219 -> 0.74885845 | P35: =I35^IF('Color Targets'!$AA$1=1,$N$1,INDEX(Calculation!$G$128:$G$237,MATCH(I35,Calculation!$H$128:$H$237))) -> 0.05169357 | Q35: =J35^IF('Color Targets'!$AA$1=1,$N$1,INDEX(Calculation!$G$128:$G$237,MATCH(J35,Calculation!$H$128:$H$237))) -> 0.44671382 | R35: =K35^IF('Color Targets'!$AA$1=1,$N$1,INDEX(Calculation!$G$128:$G$237,MATCH(K35,Calculation!$H$128:$H$237))) -> 0.031317129 | S35: =L35^IF('Color Targets'!$AA$1=1,$N$1,INDEX(Calculation!$G$128:$G$237,MATCH(L35,Calculation!$H$128:$H$237))) -> 0.50036769 | T35: =M35^IF('Color Targets'!$AA$1=1,$N$1,INDEX(Calculation!$G$128:$G$237,MATCH(M35,Calculation!$H$128:$H$237))) -> 0.44671382 | U35: =N35^IF('Color Targets'!$AA$1=1,$N$1,INDEX(Calculation!$G$128:$G$237,MATCH(N35,Calculation!$H$128:$H$237))) -> 0.097193274 | V35: =O35^IF('Color Targets'!$AA$1=1,$N$1,INDEX(Calculation!$G$139:$G$237,MATCH(O35,Calculation!$A$139:$A$237))) -> 0.51141483 | W35: 0.10574448 | X35: 0.35479191 | Y35: 0.036892934 | Z35: 0.4777341 | AA35: 0.39308296 | AB35: 0.14554797 | AC35: 0.51141488 | AD35: =W35/(W34+W35+W36) -> 0.32952178 | AE35: =X35/(X34+X35+X36) -> 0.4658887 | AF35: =Y35/(Y34+Y35+Y36) -> 0.19612198 | AG35: =Z35/(Z34+Z35+Z36) -> 0.41776761 | AH35: =AA35/(AA34+AA35+AA36) -> 0.32889031 | AI35: =AB35/(AB34+AB35+AB36) -> 0.2389936 | AJ35: =AC35/(AC34+AC35+AC36) -> 0.32902315
A36: B' | B36: 75 | C36: 104 | D36: 99 | E36: 121 | F36: 171 | G36: 139 | H36: 180 | I36: =(B36-16)/219 -> 0.26940639 | J36: =(C36-16)/219 -> 0.40182648 | K36: =(D36-16)/219 -> 0.37899543 | L36: =(E36-16)/219 -> 0.47945205 | M36: =(F36-16)/219 -> 0.70776256 | N36: =(G36-16)/219 -> 0.56164384 | O36: =(H36-16)/219 -> 0.74885845 | P36: =I36^IF('Color Targets'!$AA$1=1,$N$1,INDEX(Calculation!$G$128:$G$237,MATCH(I36,Calculation!$H$128:$H$237))) -> 0.05169357 | Q36: =J36^IF('Color Targets'!$AA$1=1,$N$1,INDEX(Calculation!$G$128:$G$237,MATCH(J36,Calculation!$H$128:$H$237))) -> 0.12400842 | R36: =K36^IF('Color Targets'!$AA$1=1,$N$1,INDEX(Calculation!$G$128:$G$237,MATCH(K36,Calculation!$H$128:$H$237))) -> 0.10857106 | S36: =L36^IF('Color Targets'!$AA$1=1,$N$1,INDEX(Calculation!$G$128:$G$237,MATCH(L36,Calculation!$H$128:$H$237))) -> 0.18677383 | T36: =M36^IF('Color Targets'!$AA$1=1,$N$1,INDEX(Calculation!$G$128:$G$237,MATCH(M36,Calculation!$H$128:$H$237))) -> 0.44671382 | U36: =N36^IF('Color Targets'!$AA$1=1,$N$1,INDEX(Calculation!$G$128:$G$237,MATCH(N36,Calculation!$H$128:$H$237))) -> 0.26694943 | V36: =O36^IF('Color Targets'!$AA$1=1,$N$1,INDEX(Calculation!$G$139:$G$237,MATCH(O36,Calculation!$A$139:$A$237))) -> 0.51141483 | W36: 0.061199229 | X36: 0.17348799 | Y36: 0.10751375 | Z36: 0.24680582 | AA36: 0.48151987 | AB36: 0.27042897 | AC36: 0.55684381 | AD36: =W35 -> 0.10574448 | AE36: =X35 -> 0.35479191 | AF36: =Y35 -> 0.036892934 | AG36: =Z35 -> 0.4777341 | AH36: =AA35 -> 0.39308296 | AI36: =AB35 -> 0.14554797 | AJ36: =AC35 -> 0.51141488
A38: 50/100
A39: R' | B39: 126 | C39: 16 | D39: 16 | E39: 126 | F39: 16 | G39: 126 | H39: 126 | I39: =(B39-16)/219 -> 0.50228311 | J39: =(C39-16)/219 -> 0 | K39: =(D39-16)/219 -> 0 | L39: =(E39-16)/219 -> 0.50228311 | M39: =(F39-16)/219 -> 0 | N39: =(G39-16)/219 -> 0.50228311 | O39: =(H39-16)/219 -> 0.50228311 | P39: =I39^IF('Color Targets'!$AA$1=1,$N$1,INDEX(Calculation!$G$128:$G$237,MATCH(I39,Calculation!$H$128:$H$237))) -> 0.2067658 | Q39: =J39^$N$1 -> 0 | R39: =K39^$N$1 -> 0 | S39: =L39^IF('Color Targets'!$AA$1=1,$N$1,INDEX(Calculation!$G$128:$G$237,MATCH(L39,Calculation!$H$128:$H$237))) -> 0.2067658 | T39: =M39^$N$1 -> 0 | U39: =N39^IF('Color Targets'!$AA$1=1,$N$1,INDEX(Calculation!$G$128:$G$237,MATCH(N39,Calculation!$H$128:$H$237))) -> 0.2067658 | V39: =O39^IF('Color Targets'!$AA$1=1,$N$1,INDEX(Calculation!$G$128:$G$237,MATCH(O39,Calculation!$A$128:$A$237))) -> 0.20566252 | W39: {=MMULT($B$3:$D$5,P39:P41)} -> 0.085281876 | X39: {=MMULT($B$3:$D$5,Q39:Q41)} -> 0.073934507 | Y39: {=MMULT($B$3:$D$5,R39:R41)} -> 0.037308303 | Z39: {=MMULT($B$3:$D$5,S39:S41)} -> 0.15921638 | AA39: {=MMULT($B$3:$D$5,T39:T41)} -> 0.11124281 | AB39: {=MMULT($B$3:$D$5,U39:U41)} -> 0.12259018 | AC39: {=MMULT($B$3:$D$5,V39:V41)} -> 0.19547606 | AD39: =W39/(W39+W40+W41) -> 0.63999993 | AE39: =X39/(X39+X40+X41) -> 0.30000001 | AF39: =Y39/(Y39+Y40+Y41) -> 0.15000001 | AG39: =Z39/(Z39+Z40+Z41) -> 0.41932009 | AH39: =AA39/(AA39+AA40+AA41) -> 0.22465563 | AI39: =AB39/(AB39+AB40+AB41) -> 0.32093774 | AJ39: =AC39/(AC39+AC40+AC41) -> 0.3127266
A40: G' | B40: 16 | C40: 126 | D40: 16 | E40: 126 | F40: 126 | G40: 16 | H40: 126 | I40: =(B40-16)/219 -> 0 | J40: =(C40-16)/219 -> 0.50228311 | K40: =(D40-16)/219 -> 0 | L40: =(E40-16)/219 -> 0.50228311 | M40: =(F40-16)/219 -> 0.50228311 | N40: =(G40-16)/219 -> 0 | O40: =(H40-16)/219 -> 0.50228311 | P40: =I40^$N$1 -> 0 | Q40: =J40^IF('Color Targets'!$AA$1=1,$N$1,INDEX(Calculation!$G$128:$G$237,MATCH(J40,Calculation!$H$128:$H$237))) -> 0.2067658 | R40: =K40^$N$1 -> 0 | S40: =L40^IF('Color Targets'!$AA$1=1,$N$1,INDEX(Calculation!$G$128:$G$237,MATCH(L40,Calculation!$H$128:$H$237))) -> 0.2067658 | T40: =M40^IF('Color Targets'!$AA$1=1,$N$1,INDEX(Calculation!$G$128:$G$237,MATCH(M40,Calculation!$H$128:$H$237))) -> 0.2067658 | U40: =N40^$N$1 -> 0 | V40: =O40^IF('Color Targets'!$AA$1=1,$N$1,INDEX(Calculation!$G$128:$G$237,MATCH(O40,Calculation!$A$128:$A$237))) -> 0.20566252 | W40: 0.043973481 | X40: 0.14786901 | Y40: 0.014923321 | Z40: 0.1918425 | AA40: 0.16279234 | AB40: 0.058896803 | AC40: 0.20566254 | AD40: =W40/(W39+W40+W41) -> 0.33000007 | AE40: =X40/(X39+X40+X41) -> 0.60000002 | AF40: =Y40/(Y39+Y40+Y41) -> 0.060000003 | AG40: =Z40/(Z39+Z40+Z41) -> 0.50524583 | AH40: =AA40/(AA39+AA40+AA41) -> 0.32876026 | AI40: =AB40/(AB39+AB40+AB41) -> 0.15419022 | AJ40: =AC40/(AC39+AC40+AC41) -> 0.32902315
A41: B' | B41: 16 | C41: 16 | D41: 126 | E41: 16 | F41: 126 | G41: 126 | H41: 126 | I41: =(B41-16)/219 -> 0 | J41: =(C41-16)/219 -> 0 | K41: =(D41-16)/219 -> 0.50228311 | L41: =(E41-16)/219 -> 0 | M41: =(F41-16)/219 -> 0.50228311 | N41: =(G41-16)/219 -> 0.50228311 | O41: =(H41-16)/219 -> 0.50228311 | P41: =I41^$N$1 -> 0 | Q41: =J41^$N$1 -> 0 | R41: =K41^IF('Color Targets'!$AA$1=1,$N$1,INDEX(Calculation!$G$128:$G$237,MATCH(K41,Calculation!$H$128:$H$237))) -> 0.2067658 | S41: =L41^$N$1 -> 0 | T41: =M41^IF('Color Targets'!$AA$1=1,$N$1,INDEX(Calculation!$G$128:$G$237,MATCH(M41,Calculation!$H$128:$H$237))) -> 0.2067658 | U41: =N41^IF('Color Targets'!$AA$1=1,$N$1,INDEX(Calculation!$G$128:$G$237,MATCH(N41,Calculation!$H$128:$H$237))) -> 0.2067658 | V41: =O41^IF('Color Targets'!$AA$1=1,$N$1,INDEX(Calculation!$G$128:$G$237,MATCH(O41,Calculation!$A$128:$A$237))) -> 0.20566252 | W41: 0.0039975892 | X41: 0.024644829 | Y41: 0.19649038 | Z41: 0.028642418 | AA41: 0.22113521 | AB41: 0.20048797 | AC41: 0.22393153 | AD41: =W40 -> 0.043973481 | AE41: =X40 -> 0.14786901 | AF41: =Y40 -> 0.014923321 | AG41: =Z40 -> 0.1918425 | AH41: =AA40 -> 0.16279234 | AI41: =AB40 -> 0.058896803 | AJ41: =AC40 -> 0.20566254
A43: 50/75
A44: R' | B44: 115 | C44: 58 | D44: 44 | E44: 126 | F44: 69 | G44: 110 | H44: 126 | I44: =(B44-16)/219 -> 0.45205479 | J44: =(C44-16)/219 -> 0.19178082 | K44: =(D44-16)/219 -> 0.12785388 | L44: =(E44-16)/219 -> 0.50228311 | M44: =(F44-16)/219 -> 0.24200913 | N44: =(G44-16)/219 -> 0.42922374 | O44: =(H44-16)/219 -> 0.50228311 | P44: =I44^IF('Color Targets'!$AA$1=1,$N$1,INDEX(Calculation!$G$128:$G$237,MATCH(I44,Calculation!$H$128:$H$237))) -> 0.16381884 | Q44: =J44^IF('Color Targets'!$AA$1=1,$N$1,INDEX(Calculation!$G$128:$G$237,MATCH(J44,Calculation!$H$128:$H$237))) -> 0.026117855 | R44: =K44^IF('Color Targets'!$AA$1=1,$N$1,INDEX(Calculation!$G$128:$G$237,MATCH(K44,Calculation!$H$128:$H$237))) -> 0.012064385 | S44: =L44^IF('Color Targets'!$AA$1=1,$N$1,INDEX(Calculation!$G$128:$G$237,MATCH(L44,Calculation!$H$128:$H$237))) -> 0.2067658 | T44: =M44^IF('Color Targets'!$AA$1=1,$N$1,INDEX(Calculation!$G$128:$G$237,MATCH(M44,Calculation!$H$128:$H$237))) -> 0.041204954 | U44: =N44^IF('Color Targets'!$AA$1=1,$N$1,INDEX(Calculation!$G$128:$G$237,MATCH(N44,Calculation!$H$128:$H$237))) -> 0.14480804 | V44: =O44^IF('Color Targets'!$AA$1=1,$N$1,INDEX(Calculation!$G$139:$G$237,MATCH(O44,Calculation!$A$139:$A$237))) -> 0.20566252 | W44: {=MMULT($B$3:$D$5,P44:P46)} -> 0.074058934 | X44: {=MMULT($B$3:$D$5,Q44:Q46)} -> 0.085047356 | Y44: {=MMULT($B$3:$D$5,R44:R46)} -> 0.023876027 | Z44: {=MMULT($B$3:$D$5,S44:S46)} -> 0.16542701 | AA44: {=MMULT($B$3:$D$5,T44:T46)} -> 0.12165949 | AB44: {=MMULT($B$3:$D$5,U44:U46)} -> 0.095194923 | AC44: {=MMULT($B$3:$D$5,V44:V46)} -> 0.19547606 | AD44: =W44/(W44+W45+W46) -> 0.55075733 | AE44: =X44/(X44+X45+X46) -> 0.3036064 | AF44: =Y44/(Y44+Y45+Y46) -> 0.19997472 | AG44: =Z44/(Z44+Z45+Z46) -> 0.39283986 | AH44: =AA44/(AA44+AA45+AA46) -> 0.24705317 | AI44: =AB44/(AB44+AB45+AB46) -> 0.31875522 | AJ44: =AC44/(AC44+AC45+AC46) -> 0.3127266
A45: G' | B45: 44 | C45: 123 | D45: 44 | E45: 126 | F45: 123 | G45: 58 | H45: 126 | I45: =(B45-16)/219 -> 0.12785388 | J45: =(C45-16)/219 -> 0.48858447 | K45: =(D45-16)/219 -> 0.12785388 | L45: =(E45-16)/219 -> 0.50228311 | M45: =(F45-16)/219 -> 0.48858447 | N45: =(G45-16)/219 -> 0.19178082 | O45: =(H45-16)/219 -> 0.50228311 | P45: =I45^IF('Color Targets'!$AA$1=1,$N$1,INDEX(Calculation!$G$128:$G$237,MATCH(I45,Calculation!$H$128:$H$237))) -> 0.012064385 | Q45: =J45^IF('Color Targets'!$AA$1=1,$N$1,INDEX(Calculation!$G$128:$G$237,MATCH(J45,Calculation!$H$128:$H$237))) -> 0.19453828 | R45: =K45^IF('Color Targets'!$AA$1=1,$N$1,INDEX(Calculation!$G$128:$G$237,MATCH(K45,Calculation!$H$128:$H$237))) -> 0.012064385 | S45: =L45^IF('Color Targets'!$AA$1=1,$N$1,INDEX(Calculation!$G$128:$G$237,MATCH(L45,Calculation!$H$128:$H$237))) -> 0.2067658 | T45: =M45^IF('Color Targets'!$AA$1=1,$N$1,INDEX(Calculation!$G$128:$G$237,MATCH(M45,Calculation!$H$128:$H$237))) -> 0.19453828 | U45: =N45^IF('Color Targets'!$AA$1=1,$N$1,INDEX(Calculation!$G$128:$G$237,MATCH(N45,Calculation!$H$128:$H$237))) -> 0.026117855 | V45: =O45^IF('Color Targets'!$AA$1=1,$N$1,INDEX(Calculation!$G$139:$G$237,MATCH(O45,Calculation!$A$139:$A$237))) -> 0.20566252 | W45: 0.044338447 | X45: 0.14656409 | Y45: 0.017028063 | Z45: 0.19432674 | AA45: 0.16192846 | AB45: 0.059926507 | AC45: 0.20566254 | AD45: =W45/(W44+W45+W46) -> 0.32973368 | AE45: =X45/(X44+X45+X46) -> 0.52321201 | AF45: =Y45/(Y44+Y45+Y46) -> 0.14261929 | AG45: =Z45/(Z44+Z45+Z46) -> 0.46146813 | AH45: =AA45/(AA44+AA45+AA46) -> 0.32882712 | AI45: =AB45/(AB44+AB45+AB46) -> 0.20066077 | AJ45: =AC45/(AC44+AC45+AC46) -> 0.32902315
A46: B' | B46: 44 | C46: 58 | D46: 88 | E46: 64 | F46: 123 | G46: 110 | H46: 126 | I46: =(B46-16)/219 -> 0.12785388 | J46: =(C46-16)/219 -> 0.19178082 | K46: =(D46-16)/219 -> 0.32876712 | L46: =(E46-16)/219 -> 0.21917808 | M46: =(F46-16)/219 -> 0.48858447 | N46: =(G46-16)/219 -> 0.42922374 | O46: =(H46-16)/219 -> 0.50228311 | P46: =I46^IF('Color Targets'!$AA$1=1,$N$1,INDEX(Calculation!$G$128:$G$237,MATCH(I46,Calculation!$H$128:$H$237))) -> 0.012064385 | Q46: =J46^IF('Color Targets'!$AA$1=1,$N$1,INDEX(Calculation!$G$128:$G$237,MATCH(J46,Calculation!$H$128:$H$237))) -> 0.026117855 | R46: =K46^IF('Color Targets'!$AA$1=1,$N$1,INDEX(Calculation!$G$128:$G$237,MATCH(K46,Calculation!$H$128:$H$237))) -> 0.080837183 | S46: =L46^IF('Color Targets'!$AA$1=1,$N$1,INDEX(Calculation!$G$128:$G$237,MATCH(L46,Calculation!$H$128:$H$237))) -> 0.034419805 | T46: =M46^IF('Color Targets'!$AA$1=1,$N$1,INDEX(Calculation!$G$128:$G$237,MATCH(M46,Calculation!$H$128:$H$237))) -> 0.19453828 | U46: =N46^IF('Color Targets'!$AA$1=1,$N$1,INDEX(Calculation!$G$128:$G$237,MATCH(N46,Calculation!$H$128:$H$237))) -> 0.14480804 | V46: =O46^IF('Color Targets'!$AA$1=1,$N$1,INDEX(Calculation!$G$139:$G$237,MATCH(O46,Calculation!$A$139:$A$237))) -> 0.20566252 | W46: 0.016070069 | X46: 0.048512271 | Y46: 0.078491136 | Z46: 0.0613517 | AA46: 0.20885458 | AB46: 0.14352442 | AC46: 0.22393153 | AD46: =W45 -> 0.044338447 | AE46: =X45 -> 0.14656409 | AF46: =Y45 -> 0.017028063 | AG46: =Z45 -> 0.19432674 | AH46: =AA45 -> 0.16192846 | AI46: =AB45 -> 0.059926507 | AJ46: =AC45 -> 0.20566254
A48: 50/50
...

Sheet Worksheet
