Workbook

Sheet Summary
A1: Budget Summary
A3: Grant #:
A5: Title:
A7: Organization:
B10: Except for the exchange rate, cost share percentage and the information above, do not enter information on this page. It will populate authomatically as you fill in the next sheet: Detailed Budget
B14: Exchange rate 1 USD = ……[local currency)
C16: Budget sections | F16: Amount
C17: 1. Staff Salaries | F17: ='Detailed Budget'!E23 -> 0
C18: 2. Staff Fringe Benefits | F18: ='Detailed Budget'!E28 -> 0
C19: 3. Consultants | F19: ='Detailed Budget'!E34 -> 0
C20: 4. Office Supplies | F20: ='Detailed Budget'!E42 -> 0
C21: 5. Rent and Utilities | F21: ='Detailed Budget'!E51 -> 0
C22: 6. Communications | F22: ='Detailed Budget'!E59 -> 0
C23: 7. Equipment | F23: ='Detailed Budget'!E67 -> 0
C24: 8. Travel Expenses | F24: ='Detailed Budget'!E75 -> 0
C25: 9. Other Expenses | F25: ='Detailed Budget'!E83 -> 0
C26: 10. Indirect Costs | F26: ='Detailed Budget'!E92 -> 0
C28: PROGRAM TOTAL | F28: =SUM(F17:H26) -> 0
C29: TOTAL IIE FUNDED EXPENSES | F29: =(F28-F31) -> 0
C30: COST SHARE PERCENTAGE | F30: 0
C31: COST SHARE AMOUNT | F31: =(F28*F30) -> 0

Sheet Detailed Budget
A1: [Grantee Name/Project Title] Detailed Budget
A2: Submitted to: | B2: IIE
A4: Date Submitted: | F4: Budget Total
A6: Period of Performance: | B6: From: | D6: To: | F6: 0
A8: Organization:
A11: US Organizations: Enter cost in USD. Non-US Organizations: Use local currency
A12: Enter data into yellow shaded cells only. You may add rows as necessary.
A13: Exchange rate 1 UDS=…[local currency]
A15: Budget Section | B15: Cost Per Unit | C15: Unit Type | D15: # of Units | E15: TOTAL | F15: Budget Notes
A17: 1. Staff Salaries | C17: Day/Hour | F17: Gross annual salary divided by 260=daily rate; or divided by 2080 hours=hourly rate
A18: a. | E18: =(B18*D18) -> 0
A19: b. | E19: =(B19*D19) -> 0
A20: c. | E20: =(B20*D20) -> 0
A21: d. | E21: =(B21*D21) -> 0
A22: e. | E22: =(B22*D22) -> 0
A23: Sub-total: | E23: =SUM(E18:E22) -> 0
A25: 2. Staff Fringe Benefits | B25: Total Salary | C25: % | F25: If your organization does not have a NICRA, calculate leave and frige benefits as % of salary.
A26: a. Leave | B26: =E23 -> 0 | E26: =(B26*C26) -> 0
A27: b. Fringe | B27: =E23 -> 0 | E27: =(B27*C27) -> 0
A28: Sub-total: | E28: =SUM(E26:E27) -> 0
A30: 3. Consultants | B30: Rate | C30: Day/Hour
A31: a. | E31: =(B31*D31) -> 0
A32: b. | E32: =(B32*D32) -> 0
A33: c. | E33: =(B33*D33) -> 0
A34: Sub-total: | E34: =SUM(E31:E33) -> 0
A36: 4. Office Supplies
A37: a. | E37: =(B37*D37) -> 0
A38: b. | E38: =(B38*D38) -> 0
A39: c. | E39: =(B39*D39) -> 0
A40: d. | E40: =(B40*D40) -> 0
A41: e. | E41: =(B41*D41) -> 0
A42: Sub-total: | E42: =SUM(E37:E41) -> 0
A44: 5. Rent and Utilities
A45: Office rent | E45: =(B45*D45) -> 0
A46: Office utilities (list separately)
A47: Electricity | E47: =(B47*D47) -> 0
A48: Other (describe below)
A49: a. | E49: =(B49*D49) -> 0
A50: b. | E50: =(B50*D50) -> 0
A51: Sub-total: | E51: =SUM(E45:E50) -> 0
...

Sheet Fringe Calculation
A1: Illustrative Computation of Fringe Benefit in the Absence of an approved NICRA
A2: Applicant may be authorized to assess fringe benefits provided the documentation properly supports these costs
A3: All costs must be reasonable, allocable, and allowable.
A4: As a part of the cost proposal , applicant must provide detailed information
A5: as to how it calculates its fringe benefits.
A6: For that reason, please list the items that make up your corporate fringe benefit pool
A7: Additionally, please provide a written explanation of exactly how your
A8: rates are determined.
A9: You must substantiate these costs with your organization's policy and financial statement(s).
A10: Below is an example of what costs might be included in your employees fringe benefits
A11: Include only those costs you can substantiate.
B12: PERCENTAGES
B13: Estimate | C13: Actual | D13: Actual
A14: FRINGE BENEFITS: | B14: 2009 | C14: 2010 | D14: 2011
A15: Leave: | B15: in % | C15: in % | D15: in %
A16: Vacation (e.g. 10 days out of 260 work days/yr) | B16: 0.0385 | C16: 0.0385 | D16: 0.0385
A17: Sick Leave (e.g. 5 days out of 260 work days/yr) | B17: 0.0192 | C17: 0.0192 | D17: 0.0192
A18: Holidays (.e.g 10 days out of 260 work days/yr) | B18: 0.0385 | C18: 0.0385 | D18: 0.0385
A19: Admin Leave (e.g. 2 days out of 260 work days/yr) | B19: 0.0077 | C19: 0.0077 | D19: 0.0077
A20: TOTAL ANNUAL LEAVE | B20: 0.1038 | C20: 0.1038 | D20: 0.1038
A22: Other Fringe Benefits:
A23: Health Insurance | B23: 0 | C23: 0 | D23: 0
A24: Pension | B24: 0 | C24: 0 | D24: 0
A25: Disability Insurance | B25: 0 | C25: 0 | D25: 0
A26: Unemployment | B26: 0 | C26: 0 | D26: 0
A27: Employer FICA | B27: 0 | C27: 0 | D27: 0
A28: Other:specify | B28: 0 | C28: 0 | D28: 0
A29: fr | B29: 0 | C29: 0 | D29: 0
A30: Other: | B30: 0 | C30: 0 | D30: 0
A31: TOTAL OTHER FRINGE BENEFITS % | B31: 0 | C31: 0 | D31: 0
A33: Proposed Fringe rate for this application
A35: An alternative method can be provided by using costs
A37: Direct Cost Base
A38: Total Direct Labor costs to which fringe is applied | B38: 30000 | C38: 32000 | D38: 29000
A39: Finge costs applied to direct labor | B39: 5000 | C39: 5000 | D39: 5000
A41: Fringe Rate | B41: 0.17 | C41: 0.16 | D41: 0.17
A43: Proposed Fringe rate for this application | B43: 0.17
