Workbook
Name CREATION: #REF!
Name CREATION: #REF!
Name CREATION: #REF!
Name CREATION: #REF!
Name CREATION: #REF!
Name HELP: #REF!
Name HELP: #REF!
Name HELP: #REF!
Name HELP: #REF!
Name HELP: #REF!
Name Print_Area_MI: 'FEB04 TEMPLATE'!$A$1:$F$69
Name Print_Area_MI: 'TRA RED FOR CHT'!$A$1:$G$12

Sheet Pupil Data
A1: Pupil Data: FEB 2011 CSA VS. NOV 2010 CSA
C3: School District | D3: SD Fudge | E3: Charter Sch | F3: CH Fudge | G3: Subtotal | H3: Private Alt | I3: College PSEO | J3: Total
A5: FEB 2011 FORECAST
A7: AADM-1.0
B8: FY 2003 | C8: 817235 | D8: 0 | E8: 11991 | F8: 0 | G8: =SUM(C8:F8) -> 829226 | H8: 2331 | I8: 3669 | J8: =SUM(G8:I8) -> 835226
B9: FY 2004 | C9: 810532 | D9: 0 | E9: 13948 | F9: 0 | G9: =SUM(C9:F9) -> 824480 | H9: 2013 | I9: 3331 | J9: =SUM(G9:I9) -> 829824
B10: FY 2005 | C10: 803304 | D10: 0 | E10: 17121 | F10: 0 | G10: =SUM(C10:F10) -> 820425 | H10: 1975 | I10: 3443 | J10: =SUM(G10:I10) -> 825843
B11: FY 2006 | C11: 801109 | D11: 0 | E11: 20307 | F11: 0 | G11: =SUM(C11:F11) -> 821416 | H11: 1898 | I11: 3229 | J11: =SUM(G11:I11) -> 826543
B12: FY 2007 | C12: 798335 | D12: 405 | E12: 23588 | F12: 0 | G12: =SUM(C12:F12) -> 822328 | H12: 1701 | I12: 3168 | J12: =SUM(G12:I12) -> 827197
B13: FY 2008 | C13: 791357 | D13: 326 | E13: 27753 | F13: 0 | G13: =SUM(C13:F13) -> 819436 | H13: 1389 | I13: 2930 | J13: =SUM(G13:I13) -> 823755
B14: FY 2009 | C14: 784790 | D14: 240 | E14: 31687 | F14: 0 | G14: =SUM(C14:F14) -> 816717 | H14: 1266 | I14: 3038 | J14: =SUM(G14:I14) -> 821021
B15: FY 2010 | C15: 783128 | D15: 0 | E15: 34463 | F15: 0 | G15: =SUM(C15:F15) -> 817591 | H15: 1243 | I15: 3089 | J15: =SUM(G15:I15) -> 821923
B16: FY 2011 | C16: 780826 | D16: 1613 | E16: 37204 | F16: 0 | G16: =SUM(C16:F16) -> 819643 | H16: 1409 | I16: =I15 -> 3089 | J16: =SUM(G16:I16) -> 824141
B17: FY 2012 | C17: 777060 | D17: 6127 | E17: 39724 | F17: 1746 | G17: =SUM(C17:F17) -> 824657 | H17: =H16 -> 1409 | I17: =I16 -> 3089 | J17: =SUM(G17:I17) -> 829155
B18: FY 2013 | C18: 773087 | D18: 13683 | E18: 40819 | F18: 4932 | G18: =SUM(C18:F18) -> 832521 | H18: =H17 -> 1409 | I18: =I17 -> 3089 | J18: =SUM(G18:I18) -> 837019 | K18: =SUM(J8:J18) -> 9101647
B19: FY 2014 | C19: 770380 | D19: 20057 | E19: 40819 | F19: 9551 | G19: =SUM(C19:F19) -> 840807 | H19: =H18 -> 1409 | I19: =I18 -> 3089 | J19: =SUM(G19:I19) -> 845305
B20: FY 2015 | C20: 768720 | D20: 24650 | E20: 40819 | F20: 14535 | G20: =SUM(C20:F20) -> 848724 | H20: =H19 -> 1409 | I20: =I19 -> 3089 | J20: =SUM(G20:I20) -> 853222
A21: AWADM-1.0
B22: FY 2003 | C22: 945648 | D22: 0 | E22: 13552 | F22: 0 | G22: =SUM(C22:F22) -> 959200 | H22: 2956 | I22: 4770 | J22: =SUM(G22:I22) -> 966926
B23: FY 2004 | C23: 937828 | D23: 0 | E23: 15841 | F23: 0 | G23: =SUM(C23:F23) -> 953669 | H23: 2550 | I23: 4330 | J23: =SUM(G23:I23) -> 960549
B24: FY 2005 | C24: 930314 | D24: 0 | E24: 19451 | F24: 0 | G24: =SUM(C24:F24) -> 949765 | H24: 2499 | I24: 4477 | J24: =SUM(G24:I24) -> 956741
B25: FY 2006 | C25: 927594 | D25: 0 | E25: 22936 | F25: 0 | G25: =SUM(C25:F25) -> 950530 | H25: 2397 | I25: 4198 | J25: =SUM(G25:I25) -> 957125
B26: FY 2007 | C26: 924184 | D26: 0 | E26: 26680 | F26: 0 | G26: =SUM(C26:F26) -> 950864 | H26: 2166 | I26: 4119 | J26: =SUM(G26:I26) -> 957149
B27: FY 2008 | C27: 918166 | D27: 388 | E27: 31619 | F27: 0 | G27: =SUM(C27:F27) -> 950173 | H27: 1787 | I27: 3808 | J27: =SUM(G27:I27) -> 955768
B28: FY 2009 | C28: 908899 | D28: 274 | E28: 36020 | F28: 0 | G28: =SUM(C28:F28) -> 945193 | H28: 1619 | I28: 3949 | J28: =SUM(G28:I28) -> 950761
B29: FY 2010 | C29: 905826 | D29: 0 | E29: 39107 | F29: 0 | G29: =SUM(C29:F29) -> 944933 | H29: 1586 | I29: 4015 | J29: =SUM(G29:I29) -> 950534
B30: FY 2011 | C30: 901859 | D30: 1839 | E30: 42157 | F30: 0 | G30: =SUM(C30:F30) -> 945855 | H30: 1795 | I30: =I29 -> 4015 | J30: =SUM(G30:I30) -> 951665
B31: FY 2012 | C31: 896895 | D31: 6113 | E31: 45224 | F31: 1767 | G31: =SUM(C31:F31) -> 949999 | H31: =H30 -> 1795 | I31: =I30 -> 4015 | J31: =SUM(G31:I31) -> 955809
B32: FY 2013 | C32: 891855 | D32: 14471 | E32: 46516 | F32: 5325 | G32: =SUM(C32:F32) -> 958167 | H32: =H31 -> 1795 | I32: =I31 -> 4015 | J32: =SUM(G32:I32) -> 963977 | K32: =SUM(J22:J32) -> 10527004
B33: FY 2014 | C33: 888543 | D33: 22468 | E33: 46516 | F33: 10559 | G33: =SUM(C33:F33) -> 968086 | H33: =H32 -> 1795 | I33: =I32 -> 4015 | J33: =SUM(G33:I33) -> 973896
B34: FY 2015 | C34: 886378 | D34: 28835 | E34: 46516 | F34: 16206 | G34: =SUM(C34:F34) -> 977935 | H34: =H33 -> 1795 | I34: =I33 -> 4015 | J34: =SUM(G34:I34) -> 983745
A35: AMCPU-1.0
B36: FY 2003 | C36: 948532 | D36: 0 | E36: 13614 | F36: 0 | G36: =SUM(C36:F36) -> 962146 | H36: 2956 | I36: 4770 | J36: =SUM(G36:I36) -> 969872
B37: FY 2004 | C37: 941129 | D37: 0 | E37: 15967 | F37: 0 | G37: =SUM(C37:F37) -> 957096 | H37: 2550 | I37: 4330 | J37: =SUM(G37:I37) -> 963976
B38: FY 2005 | C38: 933497 | D38: 0 | E38: 19538 | F38: 0 | G38: =SUM(C38:F38) -> 953035 | H38: 2499 | I38: 4477 | J38: =SUM(G38:I38) -> 960011
B39: FY 2006 | C39: 929990 | D39: 0 | E39: 23051 | F39: 0 | G39: =SUM(C39:F39) -> 953041 | H39: 2397 | I39: 4198 | J39: =SUM(G39:I39) -> 959636
B40: FY 2007 | C40: 926532 | D40: 0 | E40: 26756 | F40: 0 | G40: =SUM(C40:F40) -> 953288 | H40: 2397 | I40: 4198 | J40: =SUM(G40:I40) -> 959883
B41: FY 2008 | C41: 921287 | D41: 412 | E41: 31733 | F41: 0 | G41: =SUM(C41:F41) -> 953432 | H41: =H27 -> 1787 | I41: =I27 -> 3808 | J41: =SUM(G41:I41) -> 959027 | K41: 956680.63
B42: FY 2009 | C42: 912029 | D42: 301 | E42: 36257 | F42: 0 | G42: =SUM(C42:F42) -> 948587 | H42: =H28 -> 1619 | I42: =I28 -> 3949 | J42: =SUM(G42:I42) -> 954155 | K42: =G41-K41 -> -3248.63
B43: FY 2010 | C43: 907892 | D43: 0 | E43: 39318 | F43: 0 | G43: =SUM(C43:F43) -> 947210 | H43: =H29 -> 1586 | I43: =I29 -> 4015 | J43: =SUM(G43:I43) -> 952811
...

Sheet SUMMARY-ALL YEARS
A1: FEB 2011 VS. NOV 2010
A3: FEBRUARY 2011 FORECAST | D3: FY 2003 | E3: FY 2004 | F3: FY 2005 | G3: FY 2006 | H3: FY 2007 | I3: FY 2008 | J3: FY 2009 | K3: FY 2010 | L3: FY 2011 | M3: FY 2012 | N3: FY 2013 | O3: FY 2014 | P3: FY 2015
A5: 1 | B5: AMCPU | D5: ='FY 2003'!I5 -> 962146 | E5: ='FY 2004'!I5 -> 957096 | F5: ='FY 2005'!I5 -> 953035 | G5: ='FY 2006'!I5 -> 953041 | H5: ='FY 2007'!I5 -> 953288 | I5: ='FY 2008'!I5 -> 953432 | J5: ='FY 2009'!$I5 -> 948587 | K5: ='FY 2010'!$J5 -> 947210 | L5: ='FY 2011'!$J5 -> 948097 | M5: ='FY 2012'!$J5 -> 951670 | N5: ='FY 2013'!$J5 -> 959454 | O5: ='FY 2014'!$J5 -> 969398 | P5: ='FY 2015'!$J5 -> 979275
B7: REVENUES
A8: =A5+1 -> 2 | B8: Basic | D8: ='FY 2003'!I8 -> 4490060320 | E8: ='FY 2004'!I8 -> 4403575277 | F8: ='FY 2005'!I8 -> 4384973848 | G8: ='FY 2006'!I8 -> 4558383720 | H8: ='FY 2007'!I8 -> 4741676895 | I8: ='FY 2008'!I8 -> 4837724471 | J8: ='FY 2009'!$I8 -> 4.8605747e+09 | K8: ='FY 2010'!$J8 -> 4853494920 | L8: ='FY 2011'!$J8 -> 4858048057 | M8: ='FY 2012'!$J8 -> 4876357232 | N8: ='FY 2013'!$J8 -> 4916240193 | O8: ='FY 2014'!$J8 -> 4967199144 | P8: ='FY 2015'!$J8 -> 5017805352
A9: =A8+1 -> 3 | B9: Additional $51 | F9: 0 | G9: 0 | H9: 0 | I9: 0 | J9: ='FY 2009'!$I9 -> 48378085 | K9: 0 | L9: 0 | M9: 0 | N9: 0 | O9: 0 | P9: 0
A10: =A9+1 -> 4 | B10: Gifted & Talented | D10: ='FY 2003'!I9 -> 0 | E10: ='FY 2004'!I9 -> 0 | F10: ='FY 2005'!I9 -> 0 | G10: ='FY 2006'!I9 -> 3812154 | H10: ='FY 2007'!I9 -> 8579632 | I10: ='FY 2008'!I9 -> 11441209 | J10: ='FY 2009'!$I10 -> 11383079 | K10: ='FY 2010'!$J9 -> 11365913 | L10: ='FY 2011'!$J9 -> 11377163 | M10: ='FY 2012'!$J9 -> 11420040 | N10: ='FY 2013'!$J9 -> 11513446 | O10: ='FY 2014'!$J9 -> 11632780 | P10: ='FY 2015'!$J9 -> 11751302
A11: =A10+1 -> 5 | B11: Extended time | D11: ='FY 2003'!I10 -> 0 | E11: ='FY 2004'!I10 -> 50351550 | F11: ='FY 2005'!I10 -> 52327357 | G11: ='FY 2006'!I10 -> 52766200 | H11: ='FY 2007'!I10 -> 55436989 | I11: ='FY 2008'!I10 -> 59590817 | J11: ='FY 2009'!$I11 -> 60995641 | K11: ='FY 2010'!$J10 -> 64565373 | L11: ='FY 2011'!$J10 -> 69073025 | M11: ='FY 2012'!$J10 -> 71777949 | N11: ='FY 2013'!$J10 -> 76066766 | O11: ='FY 2014'!$J10 -> 80441305 | P11: ='FY 2015'!$J10 -> 84903317
B12: Basic Skills:
A13: =A11+1 -> 6 | C13: Compensatory | D13: ='FY 2003'!I12 -> 262694686 | E13: ='FY 2004'!I12 -> 249146954 | F13: ='FY 2005'!I12 -> 2.650745e+08 | G13: ='FY 2006'!I12 -> 292547478 | H13: ='FY 2007'!I12 -> 315471905 | I13: ='FY 2008'!I12 -> 333928094 | J13: ='FY 2009'!$I13 -> 3.4851069e+08 | K13: ='FY 2010'!$J12 -> 361157268 | L13: ='FY 2011'!$J12 -> 414260438 | M13: ='FY 2012'!$J12 -> 432960450 | N13: ='FY 2013'!$J12 -> 452559914 | O13: ='FY 2014'!$J12 -> 473621032 | P13: ='FY 2015'!$J12 -> 495561060
A14: =A13+1 -> 7 | C14: LEP | D14: ='FY 2003'!I13 -> 36857227 | E14: ='FY 2004'!I13 -> 28818713 | F14: ='FY 2005'!I13 -> 29477721 | G14: ='FY 2006'!I13 -> 30912658 | H14: ='FY 2007'!I13 -> 31474254 | I14: ='FY 2008'!I13 -> 32316781 | J14: ='FY 2009'!$I14 -> 32058187 | K14: ='FY 2010'!$J13 -> 31807937 | L14: ='FY 2011'!$J13 -> 31673120 | M14: ='FY 2012'!$J13 -> 31709920 | N14: ='FY 2013'!$J13 -> 31866994 | O14: ='FY 2014'!$J13 -> 32179350 | P14: ='FY 2015'!$J13 -> 32479973
A15: =A14+1 -> 8 | C15: LEP Concentration | D15: ='FY 2003'!I14 -> 9779108 | E15: ='FY 2004'!I14 -> 7276758 | F15: ='FY 2005'!I14 -> 7434285 | G15: ='FY 2006'!I14 -> 7883168 | H15: ='FY 2007'!I14 -> 8057613 | I15: ='FY 2008'!I14 -> 8306508 | J15: ='FY 2009'!$I15 -> 8316835 | K15: ='FY 2010'!$J14 -> 8258276 | L15: ='FY 2011'!$J14 -> 8387524 | M15: ='FY 2012'!$J14 -> 8406807 | N15: ='FY 2013'!$J14 -> 8500212 | O15: ='FY 2014'!$J14 -> 8579432 | P15: ='FY 2015'!$J14 -> 8651657
A16: =A15+1 -> 9 | B16: Sparsity | D16: ='FY 2003'!I15 -> 16471551 | E16: ='FY 2004'!I15 -> 16909578 | F16: ='FY 2005'!I15 -> 17548649 | G16: ='FY 2006'!I15 -> 18853061 | H16: ='FY 2007'!I15 -> 20254233 | I16: ='FY 2008'!I15 -> 21637534 | J16: ='FY 2009'!$I16 -> 22898807 | K16: ='FY 2010'!$J15 -> 23368633 | L16: ='FY 2011'!$J15 -> 23511161 | M16: ='FY 2012'!$J15 -> 24128678 | N16: ='FY 2013'!$J15 -> 24366756 | O16: ='FY 2014'!$J15 -> 24637073 | P16: ='FY 2015'!$J15 -> 25012252
A17: =A16+1 -> 10 | B17: Transport Sparsity | D17: ='FY 2003'!I16 -> 56478364 | E17: ='FY 2004'!I16 -> 55913098 | F17: ='FY 2005'!I16 -> 55511195 | G17: ='FY 2006'!I16 -> 57332807 | H17: ='FY 2007'!I16 -> 59221788 | I17: ='FY 2008'!I16 -> 60083765 | J17: ='FY 2009'!$I17 -> 60159097 | K17: ='FY 2010'!$J16 -> 59833229 | L17: ='FY 2011'!$J16 -> 60371479 | M17: ='FY 2012'!$J16 -> 60249583 | N17: ='FY 2013'!$J16 -> 60009213 | O17: ='FY 2014'!$J16 -> 59809879 | P17: ='FY 2015'!$J16 -> 59683844
A18: =A17+1 -> 11 | B18: Training & Experience | D18: ='FY 2003'!I17 -> 25114308 | E18: ='FY 2004'!I17 -> 18869558 | F18: ='FY 2005'!I17 -> 12876818 | G18: ='FY 2006'!I17 -> 8213502 | H18: ='FY 2007'!I17 -> 4354428 | I18: ='FY 2008'!I17 -> 2146056 | J18: ='FY 2009'!$I18 -> 1207447.6 | K18: ='FY 2010'!$J17 -> 675850 | L18: ='FY 2011'!$J17 -> 373228 | M18: ='FY 2012'!$J17 -> 223163 | N18: ='FY 2013'!$J17 -> 158920 | O18: ='FY 2014'!$J17 -> 128753 | P18: ='FY 2015'!$J17 -> 104189
A19: =A18+1 -> 12 | B19: Late Contract Penalty | D19: ='FY 2003'!I18 -> 0 | E19: ='FY 2004'!I18 -> 0 | F19: ='FY 2005'!I18 -> 0 | G19: ='FY 2006'!I18 -> -344932 | H19: ='FY 2007'!I18 -> 0 | I19: ='FY 2008'!I18 -> -730496 | J19: ='FY 2009'!$I19 -> 0 | K19: ='FY 2010'!$J18 -> -2507070 | L19: ='FY 2011'!$J18 -> 0 | M19: ='FY 2012'!$J18 -> -700000 | N19: ='FY 2013'!$J18 -> 0 | O19: ='FY 2014'!$J18 -> -700000 | P19: ='FY 2015'!$J18 -> 0
A20: =A19+1 -> 13 | B20: One-time Reduction | H20: 0 | I20: 0 | J20: 0 | K20: ='FY 2010'!$J19 -> -500000000 | L20: 0 | M20: 0 | N20: 0 | O20: 0 | P20: 0
A21: =A20+1 -> 14 | B21: Operating Capital | D21: ='FY 2003'!I19 -> 198438434 | E21: ='FY 2004'!I19 -> 194217096 | F21: ='FY 2005'!I19 -> 193697081 | G21: ='FY 2006'!I19 -> 194018388 | H21: ='FY 2007'!I19 -> 194117024 | I21: ='FY 2008'!I19 -> 194635565 | J21: ='FY 2009'!$I20 -> 1.9429911e+08 | K21: ='FY 2010'!$J20 -> 194409760 | L21: ='FY 2011'!$J19 -> 194612210 | M21: ='FY 2012'!$J19 -> 195303133 | N21: ='FY 2013'!$J19 -> 196865845 | O21: ='FY 2014'!$J19 -> 198885121 | P21: ='FY 2015'!$J19 -> 200893938
A22: =A21+1 -> 15 | B22: Equity | D22: ='FY 2003'!I20 -> 34642490 | E22: ='FY 2004'!I20 -> 32112369 | F22: ='FY 2005'!I20 -> 41731237 | G22: ='FY 2006'!I20 -> 50999434 | H22: ='FY 2007'!I20 -> 94274069 | I22: ='FY 2008'!I20 -> 95708805 | J22: ='FY 2009'!$I21 -> 93361990 | K22: ='FY 2010'!$J21 -> 92518770 | L22: ='FY 2011'!$J20 -> 92334012 | M22: ='FY 2012'!$J20 -> 93367180 | N22: ='FY 2013'!$J20 -> 94481702 | O22: ='FY 2014'!$J20 -> 96337072 | P22: ='FY 2015'!$J20 -> 98582671
A23: =A22+1 -> 16 | B23: Transition | D23: ='FY 2003'!I21 -> 0 | E23: ='FY 2004'!I21 -> 31986524 | F23: ='FY 2005'!I21 -> 31326609 | G23: ='FY 2006'!I21 -> 31033742 | H23: ='FY 2007'!I21 -> 30462514 | I23: ='FY 2008'!I21 -> 30143318 | J23: ='FY 2009'!$I22 -> 29711997 | K23: ='FY 2010'!$J22 -> 29453149 | L23: ='FY 2011'!$J21 -> 29215443 | M23: ='FY 2012'!$J21 -> 29101965 | N23: ='FY 2013'!$J21 -> 29294337 | O23: ='FY 2014'!$J21 -> 29613757 | P23: ='FY 2015'!$J21 -> 29884371
A24: =A23+1 -> 17 | B24: Q Comp | D24: ='FY 2003'!I22 -> 0 | E24: ='FY 2004'!I22 -> 0 | F24: ='FY 2005'!I22 -> 0 | G24: ='FY 2006'!I22 -> 16348850 | H24: ='FY 2007'!I22 -> 48603714 | I24: ='FY 2008'!I22 -> 60763648 | J24: ='FY 2009'!$I23 -> 63348360 | K24: ='FY 2010'!$J23 -> 58291520 | L24: ='FY 2011'!$J22 -> 63056932 | M24: ='FY 2012'!$J22 -> 79031161 | N24: ='FY 2013'!$J22 -> 81908545 | O24: ='FY 2014'!$J22 -> 83976748 | P24: ='FY 2015'!$J22 -> 86016276
A25: =A24+1 -> 18 | B25: Referendum Revenue | D25: ='FY 2003'!I23 -> 291708358 | E25: ='FY 2004'!I23 -> 426336542 | F25: ='FY 2005'!I23 -> 504721085 | G25: ='FY 2006'!I23 -> 534314512 | H25: ='FY 2007'!I23 -> 598966155 | I25: ='FY 2008'!I23 -> 644192179 | J25: ='FY 2009'!$I24 -> 7.2056718e+08 | K25: ='FY 2010'!$J24 -> 781675140 | L25: ='FY 2011'!$J23 -> 804832265 | M25: ='FY 2012'!$J23 -> 822497449 | N25: ='FY 2013'!$J23 -> 895212966 | O25: ='FY 2014'!$J23 -> 945891076 | P25: ='FY 2015'!$J23 -> 1016293443
B26: Alternative Attendance Adj:
A27: =A25+1 -> 19 | C27: Open Enroll/Charter Refer | D27: ='FY 2003'!I25 -> 1341221 | E27: ='FY 2004'!I25 -> -679857 | F27: ='FY 2005'!I25 -> -1089963.9 | G27: ='FY 2006'!I25 -> -895441.79 | H27: ='FY 2007'!I25 -> -885672 | I27: ='FY 2008'!I25 -> -181964 | J27: ='FY 2009'!$I26 -> 262096 | K27: ='FY 2010'!$J26 -> 607348 | L27: ='FY 2011'!$J25 -> 657596 | M27: ='FY 2012'!$J25 -> 309694 | N27: ='FY 2013'!$J25 -> -191472 | O27: ='FY 2014'!$J25 -> -284009 | P27: ='FY 2015'!$J25 -> -369316
A28: =A27+1 -> 20 | C28: Charter Basic Transport | D28: ='FY 2003'!I26 -> -1804253 | E28: ='FY 2004'!I26 -> 1059 | F28: ='FY 2005'!I26 -> 0 | G28: ='FY 2006'!I26 -> 0.44 | H28: ='FY 2007'!I26 -> 0 | I28: ='FY 2008'!I26 -> 0 | J28: ='FY 2009'!$I27 -> -0.0099999995 | K28: ='FY 2010'!$J27 -> 0 | L28: ='FY 2011'!$J26 -> 32 | M28: ='FY 2012'!$J26 -> -780 | N28: ='FY 2013'!$J26 -> 745 | O28: ='FY 2014'!$J26 -> 99 | P28: ='FY 2015'!$J26 -> 99
A29: =A28+1 -> 21 | C29: Charter Ext TimeTransport | D29: ='FY 2003'!I27 -> 0 | E29: ='FY 2004'!I27 -> 0 | F29: ='FY 2005'!I27 -> 0 | G29: ='FY 2006'!I27 -> -0.18 | H29: ='FY 2007'!I27 -> 0 | I29: ='FY 2008'!I27 -> 0 | J29: ='FY 2009'!$I28 -> 0 | K29: ='FY 2010'!$J28 -> 0 | L29: ='FY 2011'!$J27 -> 777 | M29: ='FY 2012'!$J27 -> 0 | N29: ='FY 2013'!$J27 -> 0 | O29: ='FY 2014'!$J27 -> 0 | P29: ='FY 2015'!$J27 -> 0
A30: =A29+1 -> 22 | C30: Charter Transport Sparsity | D30: ='FY 2003'!I28 -> 0 | E30: ='FY 2004'!I28 -> 0 | F30: ='FY 2005'!I28 -> 0 | G30: ='FY 2006'!I28 -> 0.44 | H30: ='FY 2007'!I28 -> 0 | I30: ='FY 2008'!I28 -> 0 | J30: ='FY 2009'!$I29 -> -0.01 | K30: ='FY 2010'!$J29 -> 4 | L30: ='FY 2011'!$J28 -> 165 | M30: ='FY 2012'!$J28 -> 29792 | N30: ='FY 2013'!$J28 -> 45882 | O30: ='FY 2014'!$J28 -> 51212 | P30: ='FY 2015'!$J28 -> 54447
A31: =A30+1 -> 23 | C31: Faribault Alternative Attend Adj | D31: 0 | E31: 0 | F31: 0 | G31: ='FY 2006'!I29 -> 0 | H31: ='FY 2007'!$I29 -> -398 | I31: ='FY 2008'!$I29 -> -355.18 | J31: ='FY 2009'!$I30 -> -461.16 | K31: ='FY 2010'!$J30 -> -449 | L31: ='FY 2011'!$J29 -> -195 | M31: ='FY 2012'!$J29 -> -195 | N31: ='FY 2013'!$J29 -> -195 | O31: ='FY 2014'!$J29 -> -195 | P31: ='FY 2015'!$J29 -> -195
A34: =A31+1 -> 24 | B34: TOTAL REVENUE | D34: =SUM(D8:D31) -> 5421781814 | E34: =SUM(E8:E31) -> 5514835219 | F34: =SUM(F8:F31) -> 5.5956104e+09 | G34: =SUM(G8:G31) -> 5.8561793e+09 | H34: =SUM(H8:H31) -> 6210065143 | I34: =SUM(I8:I31) -> 6.3917059e+09 | J34: =SUM(J8:J31) -> 6.5560328e+09 | K34: =SUM(K8:K31) -> 6068975571 | ... P34: =SUM(P8:P31) -> 7167308680
B36: LEVIES
A37: =A34+1 -> 25 | B37: Operating Capital Levy | D37: ='FY 2003'!I33 -> 0 | E37: ='FY 2004'!I33 -> 0 | F37: ='FY 2005'!I33 -> 40007254 | G37: ='FY 2006'!I34 -> 44268155 | H37: ='FY 2007'!I34 -> 101934454 | I37: ='FY 2008'!I34 -> 111830374 | J37: ='FY 2009'!$I35 -> 1.2125304e+08 | K37: ='FY 2010'!$J35 -> 124276595 | L37: ='FY 2011'!$J34 -> 124623859 | M37: ='FY 2012'!$J34 -> 120033819 | N37: ='FY 2013'!$J34 -> 113554245 | O37: ='FY 2014'!$J34 -> 113404094 | P37: ='FY 2015'!$J34 -> 114314879
A38: =A37+1 -> 26 | B38: Equity Levy | D38: ='FY 2003'!I34 -> 0 | E38: ='FY 2004'!I34 -> 0 | F38: ='FY 2005'!I34 -> 22380297 | G38: ='FY 2006'!I35 -> 25083314 | H38: ='FY 2007'!I35 -> 63740065 | I38: ='FY 2008'!I35 -> 70604296 | J38: ='FY 2009'!$I36 -> 73701614 | K38: ='FY 2010'!$J36 -> 75798743 | L38: ='FY 2011'!$J35 -> 76305360 | M38: ='FY 2012'!$J35 -> 75373928 | N38: ='FY 2013'!$J35 -> 73497205 | O38: ='FY 2014'!$J35 -> 74047041 | P38: ='FY 2015'!$J35 -> 75353828
A39: =A38+1 -> 27 | B39: Transition Levy | D39: ='FY 2003'!I35 -> 0 | E39: ='FY 2004'!I35 -> 0 | F39: ='FY 2005'!I35 -> 18540609 | G39: ='FY 2006'!I36 -> 20383544 | H39: ='FY 2007'!I36 -> 21830489 | I39: ='FY 2008'!I36 -> 23010395 | J39: ='FY 2009'!$I37 -> 24292897 | K39: ='FY 2010'!$J37 -> 25195534 | L39: ='FY 2011'!$J36 -> 25244531 | M39: ='FY 2012'!$J36 -> 24570084 | N39: ='FY 2013'!$J36 -> 23754209 | O39: ='FY 2014'!$J36 -> 23723108 | P39: ='FY 2015'!$J36 -> 23821586
A40: =A39+1 -> 28 | B40: Q Comp | D40: ='FY 2003'!I36 -> 0 | E40: ='FY 2004'!I36 -> 0 | F40: ='FY 2005'!I36 -> 0 | G40: ='FY 2006'!I37 -> 0 | H40: ='FY 2007'!I37 -> 9695468 | I40: ='FY 2008'!I37 -> 12779741 | J40: ='FY 2009'!$I38 -> 13353371 | K40: ='FY 2010'!$J38 -> 16807134 | L40: ='FY 2011'!$J37 -> 18158004 | M40: ='FY 2012'!$J37 -> 22046270 | N40: ='FY 2013'!$J37 -> 21813521 | O40: ='FY 2014'!$J37 -> 22270667 | P40: ='FY 2015'!$J37 -> 22847474
A41: =A40+1 -> 29 | B41: Referendum Levy | D41: ='FY 2003'!I37 -> 224945858 | E41: ='FY 2004'!I37 -> 351087875 | F41: ='FY 2005'!I37 -> 379954471 | G41: ='FY 2006'!I38 -> 410867894 | H41: ='FY 2007'!I38 -> 482421730 | I41: ='FY 2008'!I38 -> 540184289 | J41: ='FY 2009'!$I39 -> 6.3533353e+08 | K41: ='FY 2010'!$J39 -> 712334239 | L41: ='FY 2011'!$J38 -> 737629396 | M41: ='FY 2012'!$J38 -> 745650749 | N41: ='FY 2013'!$J38 -> 801706175 | O41: ='FY 2014'!$J38 -> 847429732 | P41: ='FY 2015'!$J38 -> 914688821
A43: =A41+1 -> 30 | B43: TOTAL LEVY | D43: =SUM(D37:D41) -> 224945858 | E43: =SUM(E37:E41) -> 351087875 | F43: =SUM(F37:F41) -> 460882631 | G43: =SUM(G37:G41) -> 500602907 | H43: =SUM(H37:H41) -> 679622206 | I43: =SUM(I37:I41) -> 758409095 | J43: =SUM(J37:J41) -> 8.6793445e+08 | K43: =SUM(K37:K41) -> 954412245 | ... P43: =SUM(P37:P41) -> 1151026588
B45: AID ENTITLEMENTS
A46: =A43+1 -> 31 | B46: Basic | D46: =D8 -> 4490060320 | E46: =E8 -> 4403575277 | F46: =F8 -> 4384973848 | G46: =G8 -> 4558383720 | H46: =H8 -> 4741676895 | I46: =I8 -> 4837724471 | J46: =J8 -> 4.8605747e+09 | K46: =K8 -> 4853494920 | ... P46: =P8 -> 5017805352
A47: =A46+1 -> 32 | B47: Additional $51 | F47: =F9 -> 0 | G47: =G9 -> 0 | H47: =H9 -> 0 | I47: =I9 -> 0 | J47: =J9 -> 48378085 | K47: =K9 -> 0 | L47: =L9 -> 0 | M47: =M9 -> 0 | ... P47: =P9 -> 0
A48: =A47+1 -> 33 | B48: Gifted & Talented | D48: =D10 -> 0 | E48: =E10 -> 0 | F48: =F10 -> 0 | G48: =G10 -> 3812154 | H48: =H10 -> 8579632 | I48: =I10 -> 11441209 | J48: =J10 -> 11383079 | K48: =K10 -> 11365913 | ... P48: =P10 -> 11751302
...

Sheet FEB04 TEMPLATE
A1: GENERAL ED REVENUE PROJECTIONS: FY 2002
A2: NOVEMBER 2003 FORECAST VS END OF SESSION 2003
B4: AMCPU: | C4: DISTRICT | D4: CHARTER | E4: TOTAL
B5: DEPT. ESTIMATE | C5: 968211 | D5: 0 | E5: =C5+D5 -> 968211
B6: DIST. ESTIMATE | C6: 967747 | D6: 0 | E6: =C6+D6 -> 967747
B7: ADJUSTMENT | C7: =C5-C6 -> 464 | D7: =D5-D6 -> 0 | E7: =E5-E6 -> 464
C8: AID | D8: LEVY | E8: TOTAL | F8: /PU
A9: NOVEMBER | B9: A. BASIC | E9: BSREV$$ | F9: =E9/C$6 -> 0
A10: FORECAST | B10: B. EXTENDED TIME | E10: EXDAYR$$
A11: 2003 | B11: C. BASIC SKILLS | F11: =E11/C$6 -> 0
B12: * COMPENSATORY | E12: CPSREV$$
B13: * LEP | E13: LEPREV$$
B14: * LEP CONC | E14: LEPCRV$$
B15: * AOM | E15: AOMREV$$
B16: D. SPARSITY | E16: TOTSRS$$ | F16: =E16/C$6 -> 0
B17: E. TRANSPORT SPARSITY | E17: TSRSRV$$ | F17: =E17/C$6 -> 0
B18: F. OPER CAPITAL | C18: CEXAID$$ | D18: CEXLVY$$ | E18: OCEXRV$$ | F18: =E18/C$6 -> 0
B19: G. TRAIN & EXPER | E19: TNEREV$$ | F19: =E19/C$6 -> 0
B20: H. EQUITY | C20: EQAID$$ | D20: EQLVY$$ | E20: EQREV$$ | F20: =E20/C$6 -> 0
B21: I. REDUCTION
B22: J. A THROUGH H | C22: TOTAID$$ | D22: TOTLVY$$ | E22: TOTREV$$ | F22: =E22/C$6 -> 0
B23: K. TRANSITION | C23: TRSAID$$ | D23: TRSLVY$$ | E23: TRSREV$$ | F23: =E23/C$6 -> 0
B24: L. SUPPLEMENTAL | C24: SLPAID$$ | D24: SLPLVY$$ | E24: SLPREV$$ | F24: =E24/C$6 -> 0
B25: M. REFERENDUM | C25: REFAID$$ | D25: RFLVYN$$ | E25: REFREV$$ | F25: =E25/C$6 -> 0
B26: N. TAX BSE REPL | C26: REPAID$$
B27: O. ALT ATT ADJ | C27: OPTADJ$$ | E27: OPTADJ$$ | F27: =E27/C$6 -> 0
B28: P. I+J+K+L+M+N | C28: GRDAID$$ | D28: GRDLVY$$ | E28: GRDREV$$ | F28: =E28/C$6 -> 0
A29: END OF | B29: A. BASIC | E29: BSREV4E | F29: =E29/D$6 -> #DIV/0!
A30: SESSION | B30: B. EXTENDED TIME | E30: EXDAYR4E
A31: 2003 | B31: C. BASIC SKILLS | F31: =E31/D$6 -> #DIV/0!
B32: * COMPENSATORY | E32: CPSREV4E
B33: * LEP | E33: LEPREV4E
B34: * LEP CONC | E34: LEPCRV4E
B35: * AOM | E35: AOMREV4E
B36: D. SPARSITY | E36: TOTSRS4E | F36: =E36/D$6 -> #DIV/0!
B37: E. TRANSPORT SPARSITY | E37: TSRSRV4E | F37: =E37/D$6 -> #DIV/0!
B38: F. OPER CAPITAL | C38: CEXAID4E | D38: CEXLVY4E | E38: OCEXRV4E | F38: =E38/D$6 -> #DIV/0!
B39: G. TRAIN & EXPER | E39: TNEREV4E | F39: =E39/D$6 -> #DIV/0!
B40: H. EQUITY | C40: EQAID4E | D40: EQLVY4E | E40: EQREV4E | F40: =E40/D$6 -> #DIV/0!
B41: I. REDUCTION
...

Sheet SUMMARY-Approp Table
A1: FEB 2011 VS. NOV 2010
A3: FEBRUARY 2011 FORECAST | D3: FY 2003 | E3: FY 2004 | F3: FY 2005 | G3: FY 2006 | H3: FY 2007 | I3: FY 2008 | J3: FY 2009 | K3: FY 2010 | L3: FY 2011 | M3: FY 2012 | N3: FY 2013 | O3: FY 2014 | P3: FY 2015 | Q3: 2008-09 | R3: 2010-11 | S3: 2012-13 | T3: 2014-15 | U3: Chg from 2008-09 | V3: % chg | W3: Chg from 2010-11 | X3: % chg | Y3: Chg from 2012-13 | Z3: % chg
A5: 1 | B5: AMCPU | D5: ='FY 2003'!I5 -> 962146 | E5: ='FY 2004'!I5 -> 957096 | F5: ='FY 2005'!I5 -> 953035 | G5: ='FY 2006'!I5 -> 953041 | H5: ='FY 2007'!I5 -> 953288 | I5: ='FY 2008'!I5 -> 953432 | J5: ='FY 2009'!$I5 -> 948587 | K5: ='FY 2010'!$J5 -> 947210 | L5: ='FY 2011'!$J5 -> 948097 | M5: ='FY 2012'!$J5 -> 951670 | N5: ='FY 2013'!$J5 -> 959454 | O5: ='FY 2014'!$J5 -> 969398 | P5: ='FY 2015'!$J5 -> 979275
B7: REVENUES
A8: =A5+1 -> 2 | B8: Basic | D8: ='FY 2003'!I8 -> 4490060320 | E8: ='FY 2004'!I8 -> 4403575277 | F8: =ROUND('SUMMARY-ALL YEARS'!F8/1000,1) -> 4384973.8 | G8: =ROUND('SUMMARY-ALL YEARS'!G8/1000,1) -> 4558383.7 | H8: =ROUND('SUMMARY-ALL YEARS'!H8/1000,1) -> 4741676.9 | I8: =ROUND('SUMMARY-ALL YEARS'!I8/1000,1) -> 4837724.5 | J8: =ROUND('SUMMARY-ALL YEARS'!J8/1000,1) -> 4860574.7 | K8: =ROUND('SUMMARY-ALL YEARS'!K8/1000,1) -> 4853494.9 | L8: =ROUND('SUMMARY-ALL YEARS'!L8/1000,1) -> 4858048.1 | M8: =ROUND('SUMMARY-ALL YEARS'!M8/1000,1) -> 4876357.2 | ... P8: =ROUND('SUMMARY-ALL YEARS'!P8/1000,1) -> 5017805.4 | Q8: =SUM(I8:J8) -> 9698299.2 | R8: =SUM(K8:L8) -> 9711543 | S8: =SUM(M8:N8) -> 9792597.4 | T8: =SUM(O8:P8) -> 9985004.5 | U8: =R8-Q8 -> 13243.8 | V8: =U8/Q8 -> 0.0013655796 | W8: =S8-R8 -> 81054.4 | X8: =W8/R8 -> 0.0083461917 | Y8: =T8-S8 -> 192407.1 | Z8: =Y8/S8 -> 0.019648219
A9: =A8+1 -> 3 | B9: Additional $51 | F9: 0 | G9: 0 | H9: 0 | I9: 0 | J9: =ROUND('SUMMARY-ALL YEARS'!J9/1000,1) -> 48378.1 | K9: 0 | L9: 0 | M9: 0 | N9: 0 | O9: 0 | P9: 0 | Q9: =SUM(I9:J9) -> 48378.1 | R9: =SUM(K9:L9) -> 0 | S9: =SUM(M9:N9) -> 0 | T9: =SUM(O9:P9) -> 0 | U9: =R9-Q9 -> -48378.1 | V9: =U9/Q9 -> -1 | W9: =S9-R9 -> 0 | X9: =W9/R9 -> #DIV/0! | Y9: =T9-S9 -> 0 | Z9: =Y9/S9 -> #DIV/0!
A10: =A9+1 -> 4 | B10: Gifted & Talented | D10: ='FY 2003'!I9 -> 0 | E10: ='FY 2004'!I9 -> 0 | F10: =ROUND('SUMMARY-ALL YEARS'!F10/1000,1) -> 0 | G10: =ROUND('SUMMARY-ALL YEARS'!G10/1000,1) -> 3812.2 | H10: =ROUND('SUMMARY-ALL YEARS'!H10/1000,1) -> 8579.6 | I10: =ROUND('SUMMARY-ALL YEARS'!I10/1000,1) -> 11441.2 | J10: =ROUND('SUMMARY-ALL YEARS'!J10/1000,1) -> 11383.1 | K10: =ROUND('SUMMARY-ALL YEARS'!K10/1000,1) -> 11365.9 | L10: =ROUND('SUMMARY-ALL YEARS'!L10/1000,1) -> 11377.2 | M10: =ROUND('SUMMARY-ALL YEARS'!M10/1000,1) -> 11420 | ... P10: =ROUND('SUMMARY-ALL YEARS'!P10/1000,1) -> 11751.3 | Q10: =SUM(I10:J10) -> 22824.3 | R10: =SUM(K10:L10) -> 22743.1 | S10: =SUM(M10:N10) -> 22933.4 | T10: =SUM(O10:P10) -> 23384.1 | U10: =R10-Q10 -> -81.2 | V10: =U10/Q10 -> -0.0035576118 | W10: =S10-R10 -> 190.3 | X10: =W10/R10 -> 0.008367373 | Y10: =T10-S10 -> 450.7 | Z10: =Y10/S10 -> 0.019652559
A11: =A10+1 -> 5 | B11: Extended time | D11: ='FY 2003'!I10 -> 0 | E11: ='FY 2004'!I10 -> 50351550 | F11: =ROUND('SUMMARY-ALL YEARS'!F11/1000,1) -> 52327.4 | G11: =ROUND('SUMMARY-ALL YEARS'!G11/1000,1) -> 52766.2 | H11: =ROUND('SUMMARY-ALL YEARS'!H11/1000,1) -> 55437 | I11: =ROUND('SUMMARY-ALL YEARS'!I11/1000,1) -> 59590.8 | J11: =ROUND('SUMMARY-ALL YEARS'!J11/1000,1) -> 60995.6 | K11: =ROUND('SUMMARY-ALL YEARS'!K11/1000,1) -> 64565.4 | L11: =ROUND('SUMMARY-ALL YEARS'!L11/1000,1) -> 69073 | M11: =ROUND('SUMMARY-ALL YEARS'!M11/1000,1) -> 71777.9 | ... P11: =ROUND('SUMMARY-ALL YEARS'!P11/1000,1) -> 84903.3 | Q11: =SUM(I11:J11) -> 120586.4 | R11: =SUM(K11:L11) -> 133638.4 | S11: =SUM(M11:N11) -> 147844.7 | T11: =SUM(O11:P11) -> 165344.6 | U11: =R11-Q11 -> 13052 | V11: =U11/Q11 -> 0.10823774 | W11: =S11-R11 -> 14206.3 | X11: =W11/R11 -> 0.10630403 | Y11: =T11-S11 -> 17499.9 | Z11: =Y11/S11 -> 0.11836677
B12: Basic Skills:
A13: =A11+1 -> 6 | C13: Compensatory | D13: ='FY 2003'!I12 -> 262694686 | E13: ='FY 2004'!I12 -> 249146954 | F13: =ROUND('SUMMARY-ALL YEARS'!F13/1000,1) -> 265074.5 | G13: =ROUND('SUMMARY-ALL YEARS'!G13/1000,1) -> 292547.5 | H13: =ROUND('SUMMARY-ALL YEARS'!H13/1000,1) -> 315471.9 | I13: =ROUND('SUMMARY-ALL YEARS'!I13/1000,1) -> 333928.1 | J13: =ROUND('SUMMARY-ALL YEARS'!J13/1000,1) -> 348510.7 | K13: =ROUND('SUMMARY-ALL YEARS'!K13/1000,1) -> 361157.3 | L13: =ROUND('SUMMARY-ALL YEARS'!L13/1000,1) -> 414260.4 | M13: =ROUND('SUMMARY-ALL YEARS'!M13/1000,1) -> 432960.5 | ... P13: =ROUND('SUMMARY-ALL YEARS'!P13/1000,1) -> 495561.1 | Q13: =SUM(I13:J13) -> 682438.8 | R13: =SUM(K13:L13) -> 775417.7 | S13: =SUM(M13:N13) -> 885520.4 | T13: =SUM(O13:P13) -> 969182.1 | U13: =R13-Q13 -> 92978.9 | V13: =U13/Q13 -> 0.13624504 | W13: =S13-R13 -> 110102.7 | X13: =W13/R13 -> 0.14199147 | Y13: =T13-S13 -> 83661.7 | Z13: =Y13/S13 -> 0.094477439
A14: =A13+1 -> 7 | C14: LEP | D14: ='FY 2003'!I13 -> 36857227 | E14: ='FY 2004'!I13 -> 28818713 | F14: =ROUND('SUMMARY-ALL YEARS'!F14/1000,1) -> 29477.7 | G14: =ROUND('SUMMARY-ALL YEARS'!G14/1000,1) -> 30912.7 | H14: =ROUND('SUMMARY-ALL YEARS'!H14/1000,1) -> 31474.3 | I14: =ROUND('SUMMARY-ALL YEARS'!I14/1000,1) -> 32316.8 | J14: =ROUND('SUMMARY-ALL YEARS'!J14/1000,1) -> 32058.2 | K14: =ROUND('SUMMARY-ALL YEARS'!K14/1000,1) -> 31807.9 | L14: =ROUND('SUMMARY-ALL YEARS'!L14/1000,1) -> 31673.1 | M14: =ROUND('SUMMARY-ALL YEARS'!M14/1000,1) -> 31709.9 | ... P14: =ROUND('SUMMARY-ALL YEARS'!P14/1000,1) -> 32480 | Q14: =SUM(I14:J14) -> 64375 | R14: =SUM(K14:L14) -> 63481 | S14: =SUM(M14:N14) -> 63576.9 | T14: =SUM(O14:P14) -> 64659.4 | U14: =R14-Q14 -> -894 | V14: =U14/Q14 -> -0.013887379 | W14: =S14-R14 -> 95.9 | X14: =W14/R14 -> 0.0015106882 | Y14: =T14-S14 -> 1082.5 | Z14: =Y14/S14 -> 0.017026624
A15: =A14+1 -> 8 | C15: LEP Concentration | D15: ='FY 2003'!I14 -> 9779108 | E15: ='FY 2004'!I14 -> 7276758 | F15: =ROUND('SUMMARY-ALL YEARS'!F15/1000,1) -> 7434.3 | G15: =ROUND('SUMMARY-ALL YEARS'!G15/1000,1) -> 7883.2 | H15: =ROUND('SUMMARY-ALL YEARS'!H15/1000,1) -> 8057.6 | I15: =ROUND('SUMMARY-ALL YEARS'!I15/1000,1) -> 8306.5 | J15: =ROUND('SUMMARY-ALL YEARS'!J15/1000,1) -> 8316.8 | K15: =ROUND('SUMMARY-ALL YEARS'!K15/1000,1) -> 8258.3 | L15: =ROUND('SUMMARY-ALL YEARS'!L15/1000,1) -> 8387.5 | M15: =ROUND('SUMMARY-ALL YEARS'!M15/1000,1) -> 8406.8 | ... P15: =ROUND('SUMMARY-ALL YEARS'!P15/1000,1) -> 8651.7 | Q15: =SUM(I15:J15) -> 16623.3 | R15: =SUM(K15:L15) -> 16645.8 | S15: =SUM(M15:N15) -> 16907 | T15: =SUM(O15:P15) -> 17231.1 | U15: =R15-Q15 -> 22.5 | V15: =U15/Q15 -> 0.0013535219 | W15: =S15-R15 -> 261.2 | X15: =W15/R15 -> 0.015691646 | Y15: =T15-S15 -> 324.1 | Z15: =Y15/S15 -> 0.019169575
A16: =A15+1 -> 9 | B16: Sparsity | D16: ='FY 2003'!I15 -> 16471551 | E16: ='FY 2004'!I15 -> 16909578 | F16: =ROUND('SUMMARY-ALL YEARS'!F16/1000,1) -> 17548.6 | G16: =ROUND('SUMMARY-ALL YEARS'!G16/1000,1) -> 18853.1 | H16: =ROUND('SUMMARY-ALL YEARS'!H16/1000,1) -> 20254.2 | I16: =ROUND('SUMMARY-ALL YEARS'!I16/1000,1) -> 21637.5 | J16: =ROUND('SUMMARY-ALL YEARS'!J16/1000,1) -> 22898.8 | K16: =ROUND('SUMMARY-ALL YEARS'!K16/1000,1) -> 23368.6 | L16: =ROUND('SUMMARY-ALL YEARS'!L16/1000,1) -> 23511.2 | M16: =ROUND('SUMMARY-ALL YEARS'!M16/1000,1) -> 24128.7 | ... P16: =ROUND('SUMMARY-ALL YEARS'!P16/1000,1) -> 25012.3 | Q16: =SUM(I16:J16) -> 44536.3 | R16: =SUM(K16:L16) -> 46879.8 | S16: =SUM(M16:N16) -> 48495.5 | T16: =SUM(O16:P16) -> 49649.4 | U16: =R16-Q16 -> 2343.5 | V16: =U16/Q16 -> 0.052619998 | W16: =S16-R16 -> 1615.7 | X16: =W16/R16 -> 0.034464737 | Y16: =T16-S16 -> 1153.9 | Z16: =Y16/S16 -> 0.02379396
A17: =A16+1 -> 10 | B17: Transport Sparsity | D17: ='FY 2003'!I16 -> 56478364 | E17: ='FY 2004'!I16 -> 55913098 | F17: =ROUND('SUMMARY-ALL YEARS'!F17/1000,1) -> 55511.2 | G17: =ROUND('SUMMARY-ALL YEARS'!G17/1000,1) -> 57332.8 | H17: =ROUND('SUMMARY-ALL YEARS'!H17/1000,1) -> 59221.8 | I17: =ROUND('SUMMARY-ALL YEARS'!I17/1000,1) -> 60083.8 | J17: =ROUND('SUMMARY-ALL YEARS'!J17/1000,1) -> 60159.1 | K17: =ROUND('SUMMARY-ALL YEARS'!K17/1000,1) -> 59833.2 | L17: =ROUND('SUMMARY-ALL YEARS'!L17/1000,1) -> 60371.5 | M17: =ROUND('SUMMARY-ALL YEARS'!M17/1000,1) -> 60249.6 | ... P17: =ROUND('SUMMARY-ALL YEARS'!P17/1000,1) -> 59683.8 | Q17: =SUM(I17:J17) -> 120242.9 | R17: =SUM(K17:L17) -> 120204.7 | S17: =SUM(M17:N17) -> 120258.8 | T17: =SUM(O17:P17) -> 119493.7 | U17: =R17-Q17 -> -38.2 | V17: =U17/Q17 -> -0.00031769028 | W17: =S17-R17 -> 54.1 | X17: =W17/R17 -> 0.0004500656 | Y17: =T17-S17 -> -765.1 | Z17: =Y17/S17 -> -0.0063621124
A18: =A17+1 -> 11 | B18: Training & Experience | D18: ='FY 2003'!I17 -> 25114308 | E18: ='FY 2004'!I17 -> 18869558 | F18: =ROUND('SUMMARY-ALL YEARS'!F18/1000,1) -> 12876.8 | G18: =ROUND('SUMMARY-ALL YEARS'!G18/1000,1) -> 8213.5 | H18: =ROUND('SUMMARY-ALL YEARS'!H18/1000,1) -> 4354.4 | I18: =ROUND('SUMMARY-ALL YEARS'!I18/1000,1) -> 2146.1 | J18: =ROUND('SUMMARY-ALL YEARS'!J18/1000,1) -> 1207.4 | K18: =ROUND('SUMMARY-ALL YEARS'!K18/1000,1) -> 675.9 | L18: =ROUND('SUMMARY-ALL YEARS'!L18/1000,1) -> 373.2 | M18: =ROUND('SUMMARY-ALL YEARS'!M18/1000,1) -> 223.2 | ... P18: =ROUND('SUMMARY-ALL YEARS'!P18/1000,1) -> 104.2 | Q18: =SUM(I18:J18) -> 3353.5 | R18: =SUM(K18:L18) -> 1049.1 | S18: =SUM(M18:N18) -> 382.1 | T18: =SUM(O18:P18) -> 233 | U18: =R18-Q18 -> -2304.4 | V18: =U18/Q18 -> -0.68716267 | W18: =S18-R18 -> -667 | X18: =W18/R18 -> -0.63578305 | Y18: =T18-S18 -> -149.1 | Z18: =Y18/S18 -> -0.39021199
A19: =A18+1 -> 12 | B19: Late Contract Penalty | D19: ='FY 2003'!I18 -> 0 | E19: ='FY 2004'!I18 -> 0 | F19: =ROUND('SUMMARY-ALL YEARS'!F19/1000,1) -> 0 | G19: =ROUND('SUMMARY-ALL YEARS'!G19/1000,1) -> -344.9 | H19: =ROUND('SUMMARY-ALL YEARS'!H19/1000,1) -> 0 | I19: =ROUND('SUMMARY-ALL YEARS'!I19/1000,1) -> -730.5 | J19: =ROUND('SUMMARY-ALL YEARS'!J19/1000,1) -> 0 | K19: =ROUND('SUMMARY-ALL YEARS'!K19/1000,1) -> -2507.1 | L19: =ROUND('SUMMARY-ALL YEARS'!L19/1000,1) -> 0 | M19: =ROUND('SUMMARY-ALL YEARS'!M19/1000,1) -> -700 | ... P19: =ROUND('SUMMARY-ALL YEARS'!P19/1000,1) -> 0 | Q19: =SUM(I19:J19) -> -730.5 | R19: =SUM(K19:L19) -> -2507.1 | S19: =SUM(M19:N19) -> -700 | T19: =SUM(O19:P19) -> -700 | U19: =R19-Q19 -> -1776.6 | V19: =U19/Q19 -> 2.4320329 | W19: =S19-R19 -> 1807.1 | X19: =W19/R19 -> -0.72079295 | Y19: =T19-S19 -> 0 | Z19: =Y19/S19 -> 0
A20: =A19+1 -> 13 | B20: One-time Reduction | H20: 0 | I20: 0 | J20: 0 | K20: =ROUND('SUMMARY-ALL YEARS'!K20/1000,1) -> -500000 | L20: 0 | M20: 0 | N20: 0 | O20: 0 | P20: 0 | Q20: =SUM(I20:J20) -> 0 | R20: =SUM(K20:L20) -> -500000 | S20: =SUM(M20:N20) -> 0 | T20: =SUM(O20:P20) -> 0 | U20: =R20-Q20 -> -500000 | V20: =U20/Q20 -> #DIV/0! | W20: =S20-R20 -> 500000 | X20: =W20/R20 -> -1 | Y20: =T20-S20 -> 0 | Z20: =Y20/S20 -> #DIV/0!
A21: =A20+1 -> 14 | B21: Operating Capital | D21: ='FY 2003'!I19 -> 198438434 | E21: ='FY 2004'!I19 -> 194217096 | F21: =ROUND('SUMMARY-ALL YEARS'!F21/1000,1) -> 193697.1 | G21: =ROUND('SUMMARY-ALL YEARS'!G21/1000,1) -> 194018.4 | H21: =ROUND('SUMMARY-ALL YEARS'!H21/1000,1) -> 194117 | I21: =ROUND('SUMMARY-ALL YEARS'!I21/1000,1) -> 194635.6 | J21: =ROUND('SUMMARY-ALL YEARS'!J21/1000,1) -> 194299.1 | K21: =ROUND('SUMMARY-ALL YEARS'!K21/1000,1) -> 194409.8 | L21: =ROUND('SUMMARY-ALL YEARS'!L21/1000,1) -> 194612.2 | M21: =ROUND('SUMMARY-ALL YEARS'!M21/1000,1) -> 195303.1 | ... P21: =ROUND('SUMMARY-ALL YEARS'!P21/1000,1) -> 200893.9 | Q21: =SUM(I21:J21) -> 388934.7 | R21: =SUM(K21:L21) -> 389022 | S21: =SUM(M21:N21) -> 392168.9 | T21: =SUM(O21:P21) -> 399779 | U21: =R21-Q21 -> 87.3 | V21: =U21/Q21 -> 0.00022445927 | W21: =S21-R21 -> 3146.9 | X21: =W21/R21 -> 0.0080892597 | Y21: =T21-S21 -> 7610.1 | Z21: =Y21/S21 -> 0.019405159
A22: =A21+1 -> 15 | B22: Equity | D22: ='FY 2003'!I20 -> 34642490 | E22: ='FY 2004'!I20 -> 32112369 | F22: =ROUND('SUMMARY-ALL YEARS'!F22/1000,1) -> 41731.2 | G22: =ROUND('SUMMARY-ALL YEARS'!G22/1000,1) -> 50999.4 | H22: =ROUND('SUMMARY-ALL YEARS'!H22/1000,1) -> 94274.1 | I22: =ROUND('SUMMARY-ALL YEARS'!I22/1000,1) -> 95708.8 | J22: =ROUND('SUMMARY-ALL YEARS'!J22/1000,1) -> 93362 | K22: =ROUND('SUMMARY-ALL YEARS'!K22/1000,1) -> 92518.8 | L22: =ROUND('SUMMARY-ALL YEARS'!L22/1000,1) -> 92334 | M22: =ROUND('SUMMARY-ALL YEARS'!M22/1000,1) -> 93367.2 | ... P22: =ROUND('SUMMARY-ALL YEARS'!P22/1000,1) -> 98582.7 | Q22: =SUM(I22:J22) -> 189070.8 | R22: =SUM(K22:L22) -> 184852.8 | S22: =SUM(M22:N22) -> 187848.9 | T22: =SUM(O22:P22) -> 194919.8 | U22: =R22-Q22 -> -4218 | V22: =U22/Q22 -> -0.022309103 | W22: =S22-R22 -> 2996.1 | X22: =W22/R22 -> 0.016208031 | Y22: =T22-S22 -> 7070.9 | Z22: =Y22/S22 -> 0.037641424
A23: =A22+1 -> 16 | B23: Transition | D23: ='FY 2003'!I21 -> 0 | E23: ='FY 2004'!I21 -> 31986524 | F23: =ROUND('SUMMARY-ALL YEARS'!F23/1000,1) -> 31326.6 | G23: =ROUND('SUMMARY-ALL YEARS'!G23/1000,1) -> 31033.7 | H23: =ROUND('SUMMARY-ALL YEARS'!H23/1000,1) -> 30462.5 | I23: =ROUND('SUMMARY-ALL YEARS'!I23/1000,1) -> 30143.3 | J23: =ROUND('SUMMARY-ALL YEARS'!J23/1000,1) -> 29712 | K23: =ROUND('SUMMARY-ALL YEARS'!K23/1000,1) -> 29453.1 | L23: =ROUND('SUMMARY-ALL YEARS'!L23/1000,1) -> 29215.4 | M23: =ROUND('SUMMARY-ALL YEARS'!M23/1000,1) -> 29102 | ... P23: =ROUND('SUMMARY-ALL YEARS'!P23/1000,1) -> 29884.4 | Q23: =SUM(I23:J23) -> 59855.3 | R23: =SUM(K23:L23) -> 58668.5 | S23: =SUM(M23:N23) -> 58396.3 | T23: =SUM(O23:P23) -> 59498.2 | U23: =R23-Q23 -> -1186.8 | V23: =U23/Q23 -> -0.019827818 | W23: =S23-R23 -> -272.2 | X23: =W23/R23 -> -0.0046396277 | Y23: =T23-S23 -> 1101.9 | Z23: =Y23/S23 -> 0.018869346
A24: =A23+1 -> 17 | B24: Q Comp | D24: ='FY 2003'!I22 -> 0 | E24: ='FY 2004'!I22 -> 0 | F24: =ROUND('SUMMARY-ALL YEARS'!F24/1000,1) -> 0 | G24: =ROUND('SUMMARY-ALL YEARS'!G24/1000,1) -> 16348.9 | H24: =ROUND('SUMMARY-ALL YEARS'!H24/1000,1) -> 48603.7 | I24: =ROUND('SUMMARY-ALL YEARS'!I24/1000,1) -> 60763.6 | J24: =ROUND('SUMMARY-ALL YEARS'!J24/1000,1) -> 63348.4 | K24: =ROUND('SUMMARY-ALL YEARS'!K24/1000,1) -> 58291.5 | L24: =ROUND('SUMMARY-ALL YEARS'!L24/1000,1) -> 63056.9 | M24: =ROUND('SUMMARY-ALL YEARS'!M24/1000,1) -> 79031.2 | ... P24: =ROUND('SUMMARY-ALL YEARS'!P24/1000,1) -> 86016.3 | Q24: =SUM(I24:J24) -> 124112 | R24: =SUM(K24:L24) -> 121348.4 | S24: =SUM(M24:N24) -> 160939.7 | T24: =SUM(O24:P24) -> 169993 | U24: =R24-Q24 -> -2763.6 | V24: =U24/Q24 -> -0.022266985 | W24: =S24-R24 -> 39591.3 | X24: =W24/R24 -> 0.32626141 | Y24: =T24-S24 -> 9053.3 | Z24: =Y24/S24 -> 0.056252746
A25: =A24+1 -> 18 | B25: Referendum Revenue | D25: ='FY 2003'!I23 -> 291708358 | E25: ='FY 2004'!I23 -> 426336542 | F25: =ROUND('SUMMARY-ALL YEARS'!F25/1000,1) -> 504721.1 | G25: =ROUND('SUMMARY-ALL YEARS'!G25/1000,1) -> 534314.5 | H25: =ROUND('SUMMARY-ALL YEARS'!H25/1000,1) -> 598966.2 | I25: =ROUND('SUMMARY-ALL YEARS'!I25/1000,1) -> 644192.2 | J25: =ROUND('SUMMARY-ALL YEARS'!J25/1000,1) -> 720567.2 | K25: =ROUND('SUMMARY-ALL YEARS'!K25/1000,1) -> 781675.1 | L25: =ROUND('SUMMARY-ALL YEARS'!L25/1000,1) -> 804832.3 | M25: =ROUND('SUMMARY-ALL YEARS'!M25/1000,1) -> 822497.4 | ... P25: =ROUND('SUMMARY-ALL YEARS'!P25/1000,1) -> 1016293.4 | Q25: =SUM(I25:J25) -> 1364759.4 | R25: =SUM(K25:L25) -> 1586507.4 | S25: =SUM(M25:N25) -> 1717710.4 | T25: =SUM(O25:P25) -> 1962184.5 | U25: =R25-Q25 -> 221748 | V25: =U25/Q25 -> 0.16248139 | W25: =S25-R25 -> 131203 | X25: =W25/R25 -> 0.082699268 | Y25: =T25-S25 -> 244474.1 | Z25: =Y25/S25 -> 0.14232556
B27: Alternative Attendance Adj:
A28: =A25+1 -> 19 | C28: All Categories | D28: ='FY 2003'!I25 -> 1341221 | E28: ='FY 2004'!I25 -> -679857 | F28: =ROUND(SUM('SUMMARY-ALL YEARS'!F27:F31)/1000,1) -> -1090 | G28: =ROUND(SUM('SUMMARY-ALL YEARS'!G27:G31)/1000,1) -> -895.4 | H28: =ROUND(SUM('SUMMARY-ALL YEARS'!H27:H31)/1000,1) -> -886.1 | I28: =ROUND(SUM('SUMMARY-ALL YEARS'!I27:I31)/1000,1) -> -182.3 | J28: =ROUND(SUM('SUMMARY-ALL YEARS'!J27:J31)/1000,1) -> 261.6 | K28: =ROUND(SUM('SUMMARY-ALL YEARS'!K27:K31)/1000,1) -> 606.9 | L28: =ROUND(SUM('SUMMARY-ALL YEARS'!L27:L31)/1000,1) -> 658.4 | M28: =ROUND(SUM('SUMMARY-ALL YEARS'!M27:M31)/1000,1) -> 338.5 | ... P28: =ROUND(SUM('SUMMARY-ALL YEARS'!P27:P31)/1000,1) -> -315 | Q28: =SUM(I28:J28) -> 79.3 | R28: =SUM(K28:L28) -> 1265.3 | S28: =SUM(M28:N28) -> 193.5 | T28: =SUM(O28:P28) -> -547.9 | U28: =R28-Q28 -> 1186 | V28: =U28/Q28 -> 14.955864 | W28: =S28-R28 -> -1071.8 | X28: =W28/R28 -> -0.84707184 | Y28: =T28-S28 -> -741.4 | Z28: =Y28/S28 -> -3.8315245
A29: =A28+1 -> 20 | D29: ='FY 2003'!I26 -> -1804253 | E29: ='FY 2004'!I26 -> 1059 | F29: 0 | G29: 0 | H29: 0 | I29: 0 | J29: 0 | K29: 0 | L29: 0 | M29: 0 | N29: 0 | O29: 0 | P29: 0
A30: =A29+1 -> 21 | D30: ='FY 2003'!I27 -> 0 | E30: ='FY 2004'!I27 -> 0 | F30: 0 | G30: 0 | H30: 0 | I30: 0 | J30: 0 | K30: 0 | L30: 0 | M30: 0 | N30: 0 | O30: 0 | P30: 0
A31: =A30+1 -> 22 | D31: ='FY 2003'!I28 -> 0 | E31: ='FY 2004'!I28 -> 0 | F31: 0 | G31: 0 | H31: 0 | I31: 0 | J31: 0 | K31: 0 | L31: 0 | M31: 0 | N31: 0 | O31: 0 | P31: 0
A32: =A31+1 -> 23 | D32: 0 | E32: 0 | F32: 0 | G32: 0 | H32: 0 | I32: 0 | J32: 0 | K32: 0 | L32: 0 | M32: 0 | N32: 0 | O32: 0 | P32: 0
A34: =A32+1 -> 24 | B34: TOTAL REVENUE | D34: =SUM(D8:D32) -> 5421781814 | E34: =SUM(E8:E32) -> 5514835219 | F34: =SUM(F8:F32) -> 5595610.3 | G34: =SUM(G8:G32) -> 5856179.5 | H34: =SUM(H8:H32) -> 6210065.1 | I34: =SUM(I8:I32) -> 6391706 | J34: =SUM(J8:J32) -> 6556032.8 | K34: =SUM(K8:K32) -> 6068975.5 | ... P34: =SUM(P8:P32) -> 7167308.8 | Q34: =SUM(I34:J34) -> 12947739 | R34: =SUM(K34:L34) -> 12730760 | S34: =SUM(M34:N34) -> 13615074 | T34: =SUM(O34:P34) -> 14179308 | U34: =R34-Q34 -> -216978.9 | V34: =U34/Q34 -> -0.016758054 | W34: =S34-R34 -> 884314 | X34: =W34/R34 -> 0.069462782 | Y34: =T34-S34 -> 564234.6 | Z34: =Y34/S34 -> 0.041441905
B36: LEVIES
A37: =A34+1 -> 25 | B37: Operating Capital Levy | D37: ='FY 2003'!I33 -> 0 | E37: ='FY 2004'!I33 -> 0 | F37: =ROUND('SUMMARY-ALL YEARS'!F37/1000,1) -> 40007.3 | G37: =ROUND('SUMMARY-ALL YEARS'!G37/1000,1) -> 44268.2 | H37: =ROUND('SUMMARY-ALL YEARS'!H37/1000,1) -> 101934.5 | I37: =ROUND('SUMMARY-ALL YEARS'!I37/1000,1) -> 111830.4 | J37: =ROUND('SUMMARY-ALL YEARS'!J37/1000,1) -> 121253 | K37: =ROUND('SUMMARY-ALL YEARS'!K37/1000,1) -> 124276.6 | L37: =ROUND('SUMMARY-ALL YEARS'!L37/1000,1) -> 124623.9 | M37: =ROUND('SUMMARY-ALL YEARS'!M37/1000,1) -> 120033.8 | ... P37: =ROUND('SUMMARY-ALL YEARS'!P37/1000,1) -> 114314.9 | Q37: =SUM(I37:J37) -> 233083.4 | R37: =SUM(K37:L37) -> 248900.5 | S37: =SUM(M37:N37) -> 233588 | T37: =SUM(O37:P37) -> 227719 | U37: =R37-Q37 -> 15817.1 | V37: =U37/Q37 -> 0.067860259 | W37: =S37-R37 -> -15312.5 | X37: =W37/R37 -> -0.061520567 | Y37: =T37-S37 -> -5869 | Z37: =Y37/S37 -> -0.025125435
A38: =A37+1 -> 26 | B38: Equity Levy | D38: ='FY 2003'!I34 -> 0 | E38: ='FY 2004'!I34 -> 0 | F38: =ROUND('SUMMARY-ALL YEARS'!F38/1000,1) -> 22380.3 | G38: =ROUND('SUMMARY-ALL YEARS'!G38/1000,1) -> 25083.3 | H38: =ROUND('SUMMARY-ALL YEARS'!H38/1000,1) -> 63740.1 | I38: =ROUND('SUMMARY-ALL YEARS'!I38/1000,1) -> 70604.3 | J38: =ROUND('SUMMARY-ALL YEARS'!J38/1000,1) -> 73701.6 | K38: =ROUND('SUMMARY-ALL YEARS'!K38/1000,1) -> 75798.7 | L38: =ROUND('SUMMARY-ALL YEARS'!L38/1000,1) -> 76305.4 | M38: =ROUND('SUMMARY-ALL YEARS'!M38/1000,1) -> 75373.9 | ... P38: =ROUND('SUMMARY-ALL YEARS'!P38/1000,1) -> 75353.8 | Q38: =SUM(I38:J38) -> 144305.9 | R38: =SUM(K38:L38) -> 152104.1 | S38: =SUM(M38:N38) -> 148871.1 | T38: =SUM(O38:P38) -> 149400.8 | U38: =R38-Q38 -> 7798.2 | V38: =U38/Q38 -> 0.054039371 | W38: =S38-R38 -> -3233 | X38: =W38/R38 -> -0.02125518 | Y38: =T38-S38 -> 529.7 | Z38: =Y38/S38 -> 0.0035581117
A39: =A38+1 -> 27 | B39: Transition Levy | D39: ='FY 2003'!I35 -> 0 | E39: ='FY 2004'!I35 -> 0 | F39: =ROUND('SUMMARY-ALL YEARS'!F39/1000,1) -> 18540.6 | G39: =ROUND('SUMMARY-ALL YEARS'!G39/1000,1) -> 20383.5 | H39: =ROUND('SUMMARY-ALL YEARS'!H39/1000,1) -> 21830.5 | I39: =ROUND('SUMMARY-ALL YEARS'!I39/1000,1) -> 23010.4 | J39: =ROUND('SUMMARY-ALL YEARS'!J39/1000,1) -> 24292.9 | K39: =ROUND('SUMMARY-ALL YEARS'!K39/1000,1) -> 25195.5 | L39: =ROUND('SUMMARY-ALL YEARS'!L39/1000,1) -> 25244.5 | M39: =ROUND('SUMMARY-ALL YEARS'!M39/1000,1) -> 24570.1 | ... P39: =ROUND('SUMMARY-ALL YEARS'!P39/1000,1) -> 23821.6 | Q39: =SUM(I39:J39) -> 47303.3 | R39: =SUM(K39:L39) -> 50440 | S39: =SUM(M39:N39) -> 48324.3 | T39: =SUM(O39:P39) -> 47544.7 | U39: =R39-Q39 -> 3136.7 | V39: =U39/Q39 -> 0.066310384 | W39: =S39-R39 -> -2115.7 | X39: =W39/R39 -> -0.041944885 | Y39: =T39-S39 -> -779.6 | Z39: =Y39/S39 -> -0.01613267
A40: =A39+1 -> 28 | B40: Q Comp | D40: ='FY 2003'!I36 -> 0 | E40: ='FY 2004'!I36 -> 0 | F40: =ROUND('SUMMARY-ALL YEARS'!F40/1000,1) -> 0 | G40: =ROUND('SUMMARY-ALL YEARS'!G40/1000,1) -> 0 | H40: =ROUND('SUMMARY-ALL YEARS'!H40/1000,1) -> 9695.5 | I40: =ROUND('SUMMARY-ALL YEARS'!I40/1000,1) -> 12779.7 | J40: =ROUND('SUMMARY-ALL YEARS'!J40/1000,1) -> 13353.4 | K40: =ROUND('SUMMARY-ALL YEARS'!K40/1000,1) -> 16807.1 | L40: =ROUND('SUMMARY-ALL YEARS'!L40/1000,1) -> 18158 | M40: =ROUND('SUMMARY-ALL YEARS'!M40/1000,1) -> 22046.3 | ... P40: =ROUND('SUMMARY-ALL YEARS'!P40/1000,1) -> 22847.5 | Q40: =SUM(I40:J40) -> 26133.1 | R40: =SUM(K40:L40) -> 34965.1 | S40: =SUM(M40:N40) -> 43859.8 | T40: =SUM(O40:P40) -> 45118.2 | U40: =R40-Q40 -> 8832 | V40: =U40/Q40 -> 0.3379622 | W40: =S40-R40 -> 8894.7 | X40: =W40/R40 -> 0.25438795 | Y40: =T40-S40 -> 1258.4 | Z40: =Y40/S40 -> 0.028691421
A41: =A40+1 -> 29 | B41: Referendum Levy | D41: ='FY 2003'!I37 -> 224945858 | E41: ='FY 2004'!I37 -> 351087875 | F41: =ROUND('SUMMARY-ALL YEARS'!F41/1000,1) -> 379954.5 | G41: =ROUND('SUMMARY-ALL YEARS'!G41/1000,1) -> 410867.9 | H41: =ROUND('SUMMARY-ALL YEARS'!H41/1000,1) -> 482421.7 | I41: =ROUND('SUMMARY-ALL YEARS'!I41/1000,1) -> 540184.3 | J41: =ROUND('SUMMARY-ALL YEARS'!J41/1000,1) -> 635333.5 | K41: =ROUND('SUMMARY-ALL YEARS'!K41/1000,1) -> 712334.2 | L41: =ROUND('SUMMARY-ALL YEARS'!L41/1000,1) -> 737629.4 | M41: =ROUND('SUMMARY-ALL YEARS'!M41/1000,1) -> 745650.7 | ... P41: =ROUND('SUMMARY-ALL YEARS'!P41/1000,1) -> 914688.8 | Q41: =SUM(I41:J41) -> 1175517.8 | R41: =SUM(K41:L41) -> 1449963.6 | S41: =SUM(M41:N41) -> 1547356.9 | T41: =SUM(O41:P41) -> 1762118.5 | U41: =R41-Q41 -> 274445.8 | V41: =U41/Q41 -> 0.23346801 | W41: =S41-R41 -> 97393.3 | X41: =W41/R41 -> 0.067169479 | Y41: =T41-S41 -> 214761.6 | Z41: =Y41/S41 -> 0.13879254
A43: =A41+1 -> 30 | B43: TOTAL LEVY | D43: =SUM(D37:D41) -> 224945858 | E43: =SUM(E37:E41) -> 351087875 | F43: =SUM(F37:F41) -> 460882.7 | G43: =SUM(G37:G41) -> 500602.9 | H43: =SUM(H37:H41) -> 679622.3 | I43: =SUM(I37:I41) -> 758409.1 | J43: =SUM(J37:J41) -> 867934.4 | K43: =SUM(K37:K41) -> 954412.1 | ... P43: =SUM(P37:P41) -> 1151026.6 | Q43: =SUM(I43:J43) -> 1626343.5 | R43: =SUM(K43:L43) -> 1936373.3 | S43: =SUM(M43:N43) -> 2022000.1 | T43: =SUM(O43:P43) -> 2231901.2 | U43: =R43-Q43 -> 310029.8 | V43: =U43/Q43 -> 0.19062996 | W43: =S43-R43 -> 85626.8 | X43: =W43/R43 -> 0.044220192 | Y43: =T43-S43 -> 209901.1 | Z43: =Y43/S43 -> 0.10380865
B45: AID ENTITLEMENTS
A46: =A43+1 -> 31 | B46: Basic | D46: =D8 -> 4490060320 | E46: =E8 -> 4403575277 | F46: =F8 -> 4384973.8 | G46: =G8 -> 4558383.7 | H46: =H8 -> 4741676.9 | I46: =I8 -> 4837724.5 | J46: =J8 -> 4860574.7 | K46: =K8 -> 4853494.9 | ... P46: =P8 -> 5017805.4 | Q46: =SUM(I46:J46) -> 9698299.2 | R46: =SUM(K46:L46) -> 9711543 | S46: =SUM(M46:N46) -> 9792597.4 | T46: =SUM(O46:P46) -> 9985004.5 | U46: =R46-Q46 -> 13243.8 | V46: =U46/Q46 -> 0.0013655796 | W46: =S46-R46 -> 81054.4 | X46: =W46/R46 -> 0.0083461917 | Y46: =T46-S46 -> 192407.1 | Z46: =Y46/S46 -> 0.019648219
A47: =A46+1 -> 32 | B47: Additional $51 | G47: =G9 -> 0 | H47: =H9 -> 0 | I47: =I9 -> 0 | J47: =J9 -> 48378.1 | K47: =K9 -> 0 | L47: =L9 -> 0 | M47: =M9 -> 0 | N47: =N9 -> 0 | ... P47: =P9 -> 0 | Q47: =SUM(I47:J47) -> 48378.1 | R47: =SUM(K47:L47) -> 0 | S47: =SUM(M47:N47) -> 0 | T47: =SUM(O47:P47) -> 0 | U47: =R47-Q47 -> -48378.1 | V47: =U47/Q47 -> -1 | W47: =S47-R47 -> 0 | X47: =W47/R47 -> #DIV/0! | Y47: =T47-S47 -> 0 | Z47: =Y47/S47 -> #DIV/0!
A48: =A47+1 -> 33 | B48: Gifted & Talented | D48: =D10 -> 0 | E48: =E10 -> 0 | F48: =F10 -> 0 | G48: =G10 -> 3812.2 | H48: =H10 -> 8579.6 | I48: =I10 -> 11441.2 | J48: =J10 -> 11383.1 | K48: =K10 -> 11365.9 | ... P48: =P10 -> 11751.3 | Q48: =SUM(I48:J48) -> 22824.3 | R48: =SUM(K48:L48) -> 22743.1 | S48: =SUM(M48:N48) -> 22933.4 | T48: =SUM(O48:P48) -> 23384.1 | U48: =R48-Q48 -> -81.2 | V48: =U48/Q48 -> -0.0035576118 | W48: =S48-R48 -> 190.3 | X48: =W48/R48 -> 0.008367373 | Y48: =T48-S48 -> 450.7 | Z48: =Y48/S48 -> 0.019652559
...

Sheet FY 2003
A1: FY 2003: FEB 2007 VS. NOV 2006 CSA
A3: FEBRUARY 2007 FORECAST | D3: School District | E3: New Refer | F3: SD Fudge | G3: Charter Sch | H3: CH Fudge | I3: Total
A5: 1 | B5: AMCPU | D5: ='Pupil Data'!C36 -> 948532 | E5: 0 | F5: ='Pupil Data'!D36 -> 0 | G5: ='Pupil Data'!E36 -> 13614 | H5: ='Pupil Data'!F36 -> 0 | I5: =SUM(D5:H5) -> 962146
B7: REVENUES
A8: =A5+1 -> 2 | B8: Basic | D8: 4426308266 | E8: 0 | F8: 0 | G8: 63752054 | H8: 0 | I8: =SUM(D8:H8) -> 4490060320
A9: =A8+1 -> 3 | B9: Gifted & Talented | D9: 0 | E9: 0 | F9: 0 | G9: 0 | H9: 0 | I9: =SUM(D9:H9) -> 0
A10: =A9+1 -> 4 | B10: Extended time | D10: 0 | E10: 0 | F10: 0 | G10: 0 | H10: 0 | I10: =SUM(D10:H10) -> 0
B11: Basic Skills:
A12: =A10+1 -> 5 | C12: Compensatory | D12: 250666023 | E12: 0 | F12: 0 | G12: 12028663 | H12: 0 | I12: =SUM(D12:H12) -> 262694686
A13: =A12+1 -> 6 | C13: LEP | D13: 35700072 | E13: 0 | F13: 0 | G13: 1157155 | H13: 0 | I13: =SUM(D13:H13) -> 36857227
A14: =A13+1 -> 7 | C14: LEP Concentration | D14: 9436234 | E14: 0 | F14: 0 | G14: 342874 | H14: 0 | I14: =SUM(D14:H14) -> 9779108
A15: =A14+1 -> 8 | B15: Sparsity | D15: 16237664 | E15: 0 | F15: 0 | G15: 233887 | H15: 0 | I15: =SUM(D15:H15) -> 16471551
A16: =A15+1 -> 9 | B16: Transport Sparsity | D16: 56116444 | E16: 0 | F16: 0 | G16: 361920 | H16: 0 | I16: =SUM(D16:H16) -> 56478364
A17: =A16+1 -> 10 | B17: Training & Experience | D17: 24757826 | E17: 0 | F17: 0 | G17: 356482 | H17: 0 | I17: =SUM(D17:H17) -> 25114308
A18: =A17+1 -> 11 | B18: Late Contract Penalty | D18: 0 | E18: 0 | F18: 0 | G18: 0 | H18: 0 | I18: =SUM(D18:H18) -> 0
A19: =A18+1 -> 12 | B19: Operating Capital | D19: 195620930 | E19: 0 | F19: 0 | G19: 2817504 | H19: 0 | I19: =SUM(D19:H19) -> 198438434
A20: =A19+1 -> 13 | B20: Equity | D20: 34150600 | E20: 0 | F20: 0 | G20: 491890 | H20: 0 | I20: =SUM(D20:H20) -> 34642490
A21: =A20+1 -> 14 | B21: Transition | D21: 0 | E21: 0 | F21: 0 | G21: 0 | H21: 0 | I21: =SUM(D21:H21) -> 0
A22: =A21+1 -> 15 | B22: Q Comp | D22: 0 | E22: 0 | F22: 0 | G22: 0 | H22: 0 | I22: =SUM(D22:H22) -> 0
A23: =A22+1 -> 16 | B23: Referendum Revenue | D23: 291708358 | E23: 0 | F23: 0 | G23: 0 | H23: 0 | I23: =SUM(D23:H23) -> 291708358
B24: Alternative Attendance Adj:
A25: =A23+1 -> 17 | C25: Open Enroll/Charter Refer | D25: 824218 | E25: 0 | F25: 0 | G25: 517003 | H25: 0 | I25: =SUM(D25:H25) -> 1341221
A26: =A25+1 -> 18 | C26: Charter Basic Transport | D26: 0 | E26: 0 | F26: 0 | G26: -1804253 | H26: 0 | I26: =SUM(D26:H26) -> -1804253
A27: =A26+1 -> 19 | C27: Charter Ext TimeTransport | D27: 0 | E27: 0 | F27: 0 | G27: 0 | H27: 0 | I27: =SUM(D27:H27) -> 0
A28: =A27+1 -> 20 | C28: Charter Transport Sparsity | D28: 0 | E28: 0 | F28: 0 | G28: 0 | H28: 0 | I28: =SUM(D28:H28) -> 0
A30: =A28+1 -> 21 | B30: TOTAL REVENUE | D30: =SUM(D8:D28) -> 5341526635 | E30: =SUM(E8:E28) -> 0 | F30: =SUM(F8:F28) -> 0 | G30: =SUM(G8:G28) -> 80255179 | H30: =SUM(H8:H28) -> 0 | I30: =SUM(I8:I28) -> 5421781814
B32: LEVIES
A33: =A30+1 -> 22 | B33: Operating Capital Levy | D33: 0 | E33: 0 | F33: 0 | G33: 0 | H33: 0 | I33: =SUM(D33:H33) -> 0
A34: =A33+1 -> 23 | B34: Equity Levy | D34: 0 | E34: 0 | F34: 0 | G34: 0 | H34: 0 | I34: =SUM(D34:H34) -> 0
A35: =A34+1 -> 24 | B35: Transition Levy | D35: 0 | E35: 0 | F35: 0 | G35: 0 | H35: 0 | I35: =SUM(D35:H35) -> 0
A36: =A35+1 -> 25 | B36: Q Comp | D36: 0 | E36: 0 | F36: 0 | G36: 0 | H36: 0 | I36: =SUM(D36:H36) -> 0
A37: =A36+1 -> 26 | B37: Referendum Levy | D37: 224945858 | E37: 0 | F37: 0 | G37: 0 | H37: 0 | I37: =SUM(D37:H37) -> 224945858
A39: =A37+1 -> 27 | B39: TOTAL LEVY | D39: =SUM(D33:D37) -> 224945858 | E39: =SUM(E33:E37) -> 0 | F39: =SUM(F33:F37) -> 0 | G39: =SUM(G33:G37) -> 0 | H39: =SUM(H33:H37) -> 0 | I39: =SUM(I33:I37) -> 224945858
B41: AID ENTITLEMENTS
A42: =A39+1 -> 28 | B42: Basic | D42: =D8 -> 4426308266 | E42: =E8 -> 0 | F42: =F8 -> 0 | G42: =G8 -> 63752054 | H42: =H8 -> 0 | I42: =SUM(D42:H42) -> 4490060320
A43: =A42+1 -> 29 | B43: Gifted & Talented | D43: =D9 -> 0 | E43: =E9 -> 0 | F43: =F9 -> 0 | G43: =G9 -> 0 | H43: =H9 -> 0 | I43: =SUM(D43:H43) -> 0
A44: =A43+1 -> 30 | B44: Extended time | D44: =D10 -> 0 | E44: =E10 -> 0 | F44: =F10 -> 0 | G44: =G10 -> 0 | H44: =H10 -> 0 | I44: =SUM(D44:H44) -> 0
B45: Basic Skills:
A46: =A44+1 -> 31 | C46: Compensatory | D46: =D12 -> 250666023 | E46: =E12 -> 0 | F46: =F12 -> 0 | G46: =G12 -> 12028663 | H46: =H12 -> 0 | I46: =SUM(D46:H46) -> 262694686
A47: =A46+1 -> 32 | C47: LEP | D47: =D13 -> 35700072 | E47: =E13 -> 0 | F47: =F13 -> 0 | G47: =G13 -> 1157155 | H47: =H13 -> 0 | I47: =SUM(D47:H47) -> 36857227
...

Sheet FY 2004
A1: FY 2004: FEB 2007 VS. NOV 2006 CSA
A3: FEBRUARY 2007 FORECAST | D3: School District | E3: New Refer | F3: SD Fudge | G3: Charter Sch | H3: CH Fudge | I3: Total
A5: 1 | B5: AMCPU | D5: ='Pupil Data'!C37 -> 941129 | E5: 0 | F5: ='Pupil Data'!D37 -> 0 | G5: ='Pupil Data'!E37 -> 15967 | H5: ='Pupil Data'!F37 -> 0 | I5: =SUM(D5:H5) -> 957096
B7: REVENUES
A8: =A5+1 -> 2 | B8: Basic | D8: 4330167150 | E8: 0 | F8: 0 | G8: 73408127 | H8: 0 | I8: =SUM(D8:H8) -> 4403575277
A9: =A8+1 -> 3 | B9: Gifted & Talented | D9: 0 | E9: 0 | F9: 0 | G9: 0 | H9: 0 | I9: =SUM(D9:H9) -> 0
A10: =A9+1 -> 4 | B10: Extended time | D10: 49465489 | E10: 0 | F10: 0 | G10: 886061 | H10: 0 | I10: =SUM(D10:H10) -> 50351550
B11: Basic Skills:
A12: =A10+1 -> 5 | C12: Compensatory | D12: 235489836 | E12: 0 | F12: 0 | G12: 13657118 | H12: 0 | I12: =SUM(D12:H12) -> 249146954
A13: =A12+1 -> 6 | C13: LEP | D13: 27431166 | E13: 0 | F13: 0 | G13: 1387547 | H13: 0 | I13: =SUM(D13:H13) -> 28818713
A14: =A13+1 -> 7 | C14: LEP Concentration | D14: 6822038 | E14: 0 | F14: 0 | G14: 454720 | H14: 0 | I14: =SUM(D14:H14) -> 7276758
A15: =A14+1 -> 8 | B15: Sparsity | D15: 16628454 | E15: 0 | F15: 0 | G15: 281124 | H15: 0 | I15: =SUM(D15:H15) -> 16909578
A16: =A15+1 -> 9 | B16: Transport Sparsity | D16: 55468090 | E16: 0 | F16: 0 | G16: 445008 | H16: 0 | I16: =SUM(D16:H16) -> 55913098
A17: =A16+1 -> 10 | B17: Training & Experience | D17: 18554929 | E17: 0 | F17: 0 | G17: 314629 | H17: 0 | I17: =SUM(D17:H17) -> 18869558
A18: =A17+1 -> 11 | B18: Late Contract Penalty | D18: 0 | E18: 0 | F18: 0 | G18: 0 | H18: 0 | I18: =SUM(D18:H18) -> 0
A19: =A18+1 -> 12 | B19: Operating Capital | D19: 190979544 | E19: 0 | F19: 0 | G19: 3237552 | H19: 0 | I19: =SUM(D19:H19) -> 194217096
A20: =A19+1 -> 13 | B20: Equity | D20: 31577083 | E20: 0 | F20: 0 | G20: 535286 | H20: 0 | I20: =SUM(D20:H20) -> 32112369
A21: =A20+1 -> 14 | B21: Transition | D21: 31095752 | E21: 0 | F21: 0 | G21: 890772 | H21: 0 | I21: =SUM(D21:H21) -> 31986524
A22: =A21+1 -> 15 | B22: Q Comp | D22: 0 | E22: 0 | F22: 0 | G22: 0 | H22: 0 | I22: =SUM(D22:H22) -> 0
A23: =A22+1 -> 16 | B23: Referendum Revenue | D23: 426336542 | E23: 0 | F23: 0 | G23: 0 | H23: 0 | I23: =SUM(D23:H23) -> 426336542
B24: Alternative Attendance Adj:
A25: =A23+1 -> 17 | C25: Open Enroll/Charter Refer | D25: -1687931 | E25: 0 | F25: 0 | G25: 1008074 | H25: 0 | I25: =SUM(D25:H25) -> -679857
A26: =A25+1 -> 18 | C26: Charter Basic Transport | D26: 2039421 | E26: 0 | F26: 0 | G26: -2038362 | H26: 0 | I26: =SUM(D26:H26) -> 1059
A27: =A26+1 -> 19 | C27: Charter Ext TimeTransport | D27: 0 | E27: 0 | F27: 0 | G27: 0 | H27: 0 | I27: =SUM(D27:H27) -> 0
A28: =A27+1 -> 20 | C28: Charter Transport Sparsity | D28: 0 | E28: 0 | F28: 0 | G28: 0 | H28: 0 | I28: =SUM(D28:H28) -> 0
A30: =A28+1 -> 21 | B30: TOTAL REVENUE | D30: =SUM(D8:D28) -> 5420367563 | E30: =SUM(E8:E28) -> 0 | F30: =SUM(F8:F28) -> 0 | G30: =SUM(G8:G28) -> 94467656 | H30: =SUM(H8:H28) -> 0 | I30: =SUM(I8:I28) -> 5514835219
B32: LEVIES
A33: =A30+1 -> 22 | B33: Operating Capital Levy | D33: 0 | E33: 0 | F33: 0 | G33: 0 | H33: 0 | I33: =SUM(D33:H33) -> 0
A34: =A33+1 -> 23 | B34: Equity Levy | D34: 0 | E34: 0 | F34: 0 | G34: 0 | H34: 0 | I34: =SUM(D34:H34) -> 0
A35: =A34+1 -> 24 | B35: Transition Levy | D35: 0 | E35: 0 | F35: 0 | G35: 0 | H35: 0 | I35: =SUM(D35:H35) -> 0
A36: =A35+1 -> 25 | B36: Q Comp | D36: 0 | E36: 0 | F36: 0 | G36: 0 | H36: 0 | I36: =SUM(D36:H36) -> 0
A37: =A36+1 -> 26 | B37: Referendum Levy | D37: 351087875 | E37: 0 | F37: 0 | G37: 0 | H37: 0 | I37: =SUM(D37:H37) -> 351087875
A39: =A37+1 -> 27 | B39: TOTAL LEVY | D39: =SUM(D33:D37) -> 351087875 | E39: =SUM(E33:E37) -> 0 | F39: =SUM(F33:F37) -> 0 | G39: =SUM(G33:G37) -> 0 | H39: =SUM(H33:H37) -> 0 | I39: =SUM(I33:I37) -> 351087875
B41: AID ENTITLEMENTS
A42: =A39+1 -> 28 | B42: Basic | D42: =D8 -> 4330167150 | E42: =E8 -> 0 | F42: =F8 -> 0 | G42: =G8 -> 73408127 | H42: =H8 -> 0 | I42: =SUM(D42:H42) -> 4403575277
A43: =A42+1 -> 29 | B43: Gifted & Talented | D43: =D9 -> 0 | E43: =E9 -> 0 | F43: =F9 -> 0 | G43: =G9 -> 0 | H43: =H9 -> 0 | I43: =SUM(D43:H43) -> 0
A44: =A43+1 -> 30 | B44: Extended time | D44: =D10 -> 49465489 | E44: =E10 -> 0 | F44: =F10 -> 0 | G44: =G10 -> 886061 | H44: =H10 -> 0 | I44: =SUM(D44:H44) -> 50351550
B45: Basic Skills:
A46: =A44+1 -> 31 | C46: Compensatory | D46: =D12 -> 235489836 | E46: =E12 -> 0 | F46: =F12 -> 0 | G46: =G12 -> 13657118 | H46: =H12 -> 0 | I46: =SUM(D46:H46) -> 249146954
A47: =A46+1 -> 32 | C47: LEP | D47: =D13 -> 27431166 | E47: =E13 -> 0 | F47: =F13 -> 0 | G47: =G13 -> 1387547 | H47: =H13 -> 0 | I47: =SUM(D47:H47) -> 28818713
...

Sheet FY 2005
A1: FY 2005: FINAL
A3: FEBRUARY 2007 FORECAST | D3: School District | E3: New Refer | F3: SD Fudge | G3: Charter Sch | H3: CH Fudge | I3: Total
A5: 1 | B5: AMCPU | D5: ='Pupil Data'!C38 -> 933497 | E5: 0 | F5: ='Pupil Data'!D38 -> 0 | G5: ='Pupil Data'!E38 -> 19538 | H5: ='Pupil Data'!F38 -> 0 | I5: =SUM(D5:H5) -> 953035
B7: REVENUES
A8: =A5+1 -> 2 | B8: Basic | D8: 4295078866 | E8: 0 | F8: 0 | G8: 89894982 | H8: 0 | I8: =SUM(D8:H8) -> 4384973848
A9: =A8+1 -> 3 | B9: Gifted & Talented | D9: 0 | E9: 0 | F9: 0 | G9: 0 | H9: 0 | I9: =SUM(D9:H9) -> 0
A10: =A9+1 -> 4 | B10: Extended time | D10: 51404903 | E10: 0 | F10: 0 | G10: 922454 | H10: 0 | I10: =SUM(D10:H10) -> 52327357
B11: Basic Skills:
A12: =A10+1 -> 5 | C12: Compensatory | D12: 2.4805985e+08 | E12: 0 | F12: 0 | G12: 17014654 | H12: 0 | I12: =SUM(D12:H12) -> 2.650745e+08
A13: =A12+1 -> 6 | C13: LEP | D13: 27623554 | E13: 0 | F13: 0 | G13: 1854167 | H13: 0 | I13: =SUM(D13:H13) -> 29477721
A14: =A13+1 -> 7 | C14: LEP Concentration | D14: 6850350 | E14: 0 | F14: 0 | G14: 583935 | H14: 0 | I14: =SUM(D14:H14) -> 7434285
A15: =A14+1 -> 8 | B15: Sparsity | D15: 17189203 | E15: 0 | F15: 0 | G15: 359446 | H15: 0 | I15: =SUM(D15:H15) -> 17548649
A16: =A15+1 -> 9 | B16: Transport Sparsity | D16: 55015180 | E16: 0 | F16: 0 | G16: 496015 | H16: 0 | I16: =SUM(D16:H16) -> 55511195
A17: =A16+1 -> 10 | B17: Training & Experience | D17: 12612785 | E17: 0 | F17: 0 | G17: 264033 | H17: 0 | I17: =SUM(D17:H17) -> 12876818
A18: =A17+1 -> 11 | B18: Late Contract Penalty | D18: 0 | E18: 0 | F18: 0 | G18: 0 | H18: 0 | I18: =SUM(D18:H18) -> 0
A19: =A18+1 -> 12 | B19: Operating Capital | D19: 189726063 | E19: 0 | F19: 0 | G19: 3971018 | H19: 0 | I19: =SUM(D19:H19) -> 193697081
A20: =A19+1 -> 13 | B20: Equity | D20: 40875645 | E20: 0 | F20: 0 | G20: 855592 | H20: 0 | I20: =SUM(D20:H20) -> 41731237
A21: =A20+1 -> 14 | B21: Transition | D21: 30347062 | E21: 0 | F21: 0 | G21: 979547 | H21: 0 | I21: =SUM(D21:H21) -> 31326609
A22: =A21+1 -> 15 | B22: Q Comp | D22: 0 | E22: 0 | F22: 0 | G22: 0 | H22: 0 | I22: =SUM(D22:H22) -> 0
A23: =A22+1 -> 16 | B23: Referendum Revenue | D23: 504721085 | E23: =E58 -> 0 | F23: 0 | G23: 0 | H23: 0 | I23: =SUM(D23:H23) -> 504721085
B24: Alternative Attendance Adj:
A25: =A23+1 -> 17 | C25: Open Enroll/Charter Refer | D25: -3408464.9 | E25: 0 | F25: 0 | G25: 2318501 | H25: 0 | I25: =SUM(D25:H25) -> -1089963.9
A26: =A25+1 -> 18 | C26: Charter Basic Transport | D26: =2300872-D28 -> 1987072 | E26: 0 | F26: 0 | G26: -1987072 | H26: 0 | I26: =SUM(D26:H26) -> 0
A27: =A26+1 -> 19 | C27: Charter Ext TimeTransport | D27: 0 | E27: 0 | F27: 0 | G27: 0 | H27: 0 | I27: =SUM(D27:H27) -> 0
A28: =A27+1 -> 20 | C28: Charter Transport Sparsity | D28: 313800 | E28: 0 | F28: 0 | G28: -313800 | H28: 0 | I28: =SUM(D28:H28) -> 0
A30: =A28+1 -> 21 | B30: TOTAL REVENUE | D30: =SUM(D8:D28) -> 5.478397e+09 | E30: =SUM(E8:E28) -> 0 | F30: =SUM(F8:F28) -> 0 | G30: =SUM(G8:G28) -> 117213472 | H30: =SUM(H8:H28) -> 0 | I30: =SUM(I8:I28) -> 5.5956104e+09
B32: LEVIES
A33: =A30+1 -> 22 | B33: Operating Capital Levy | D33: 40007254 | E33: 0 | F33: 0 | G33: 0 | H33: 0 | I33: =SUM(D33:H33) -> 40007254
A34: =A33+1 -> 23 | B34: Equity Levy | D34: 22380297 | E34: 0 | F34: 0 | G34: 0 | H34: 0 | I34: =SUM(D34:H34) -> 22380297
A35: =A34+1 -> 24 | B35: Transition Levy | D35: 18540609 | E35: 0 | F35: 0 | G35: 0 | H35: 0 | I35: =SUM(D35:H35) -> 18540609
A36: =A35+1 -> 25 | B36: Q Comp | D36: 0 | E36: 0 | F36: 0 | G36: 0 | H36: 0 | I36: =SUM(D36:H36) -> 0
A37: =A36+1 -> 26 | B37: Referendum Levy | D37: 379954471 | E37: 0 | F37: 0 | G37: 0 | H37: 0 | I37: =SUM(D37:H37) -> 379954471
