Workbook
Name OLE_LINK1: Data!#REF!

Sheet GTR Wheat Table

Sheet US
A1: US | D1: Unshipped Balance | F1: Accumulated Exports | H1: Total Commitments | J1: net sales
B2: unshpd/cmts | D2: this year | E2: last year | F2: this year | G2: last year | H2: this year | I2: last year | J2: % change | N2: 2006/07
A3: 38855 | D3: 1821.2 | E3: 1864.7 | F3: 24408.4 | G3: 25531 | H3: 26229.6 | I3: 27395.6 | J3: =+(H3/I3-1)*100 -> -4.2561579 | L3: 2087.6 | M3: 1945.6
A4: =+A3+7 -> 38862 | D4: 1341.4 | E4: 1350.7 | F4: 24828.1 | G4: 26116.5 | H4: =+D4+F4 -> 26169.5 | I4: =+E4+G4 -> 27467.2 | J4: =+(H4/I4-1)*100 -> -4.7245442 | L4: 2500 | M4: 2304.2
A5: 38869 | D5: 3651.1 | E5: 3648.7 | F5: 35.8 | G5: 105.1 | H5: =+D5+F5 -> 3686.9 | I5: =+E5+G5 -> 3753.8 | J5: =+(H5/I5-1)*100 -> -1.782194
A6: =+A5+7 -> 38876 | D6: 3724.1 | E6: 3590.3 | F6: 424 | G6: 493.4 | H6: =+D6+F6 -> 4148.1 | I6: =+E6+G6 -> 4083.7 | J6: =+(H6/I6-1)*100 -> 1.5770012 | O6: =+H6-H5 -> 461.2 | P6: =+I6-I5 -> 329.9
A7: =+A6+7 -> 38883 | D7: 3600.1 | E7: 3775.1 | F7: 864.2 | G7: 821 | H7: =+D7+F7 -> 4464.3 | I7: =+E7+G7 -> 4596.1 | J7: =+(H7/I7-1)*100 -> -2.8676487 | O7: =+H7-H6 -> 316.2 | P7: =+I7-I6 -> 512.4 | Q7: =+O7+O6 -> 777.4 | R7: =+P7+P6 -> 842.3
A8: =+A7+7 -> 38890 | D8: 3769.6 | E8: 3945.6 | F8: 1237.2 | G8: 1238 | H8: =+D8+F8 -> 5006.8 | I8: =+E8+G8 -> 5183.6 | J8: =+(H8/I8-1)*100 -> -3.410757 | N8: 24490 | O8: =+H8-H7 -> 542.5 | P8: =+I8-I7 -> 587.5 | Q8: =+O8+O7 -> 858.7 | R8: =+P8+P7 -> 1099.9
A9: =+A8+7 -> 38897 | D9: 3686.3 | E9: 4119.1 | F9: 1619.2 | G9: 1694.3 | H9: =+D9+F9 -> 5305.5 | I9: =+E9+G9 -> 5813.4 | J9: =+(H9/I9-1)*100 -> -8.7367117 | O9: =+H9-H8 -> 298.7 | P9: =+I9-I8 -> 629.8 | Q9: =+O9+O8 -> 841.2 | R9: =+P9+P8 -> 1217.3
A10: =+A9+7 -> 38904 | D10: 3592.4 | E10: 4125.5 | F10: 1914.4 | G10: 1996.4 | H10: =+D10+F10 -> 5506.8 | I10: =+E10+G10 -> 6121.9 | J10: =+(H10/I10-1)*100 -> -10.047534 | O10: =+H10-H9 -> 201.3 | P10: =+I10-I9 -> 308.5 | Q10: =+O10+O9 -> 500 | R10: =+P10+P9 -> 938.3
A11: =+A10+7 -> 38911 | D11: 3461.2 | E11: 4286.3 | F11: 2374.8 | G11: 2424.6 | H11: =+D11+F11 -> 5836 | I11: =+E11+G11 -> 6710.9 | J11: =+(H11/I11-1)*100 -> -13.037 | O11: =+H11-H10 -> 329.2 | P11: =+I11-I10 -> 589 | Q11: =+O11+O10 -> 530.5 | R11: =+P11+P10 -> 897.5
A12: =+A11+7 -> 38918 | D12: 3399.1 | E12: 4331.2 | F12: 2901.6 | G12: 2902.6 | H12: =+D12+F12 -> 6300.7 | I12: =+E12+G12 -> 7233.8 | J12: =+(H12/I12-1)*100 -> -12.899168 | O12: =+H12-H11 -> 464.7 | P12: =+I12-I11 -> 522.9 | Q12: =+O12+O11 -> 793.9 | R12: =+P12+P11 -> 1111.9
A13: =+A12+7 -> 38925 | D13: 3611.8 | E13: 4569.4 | F13: 3272.2 | G13: 3526.7 | H13: =+D13+F13 -> 6884 | I13: =+E13+G13 -> 8096.1 | J13: =+(H13/I13-1)*100 -> -14.971406 | O13: =+H13-H12 -> 583.3 | P13: =+I13-I12 -> 862.3 | Q13: =+O13+O12 -> 1048 | R13: =+P13+P12 -> 1385.2
A14: =+A13+7 -> 38932 | D14: 3451.1 | E14: 4450.3 | F14: 3828.6 | G14: 4266.7 | H14: =+D14+F14 -> 7279.7 | I14: =+E14+G14 -> 8717 | J14: =+(H14/I14-1)*100 -> -16.488471 | O14: =+H14-H13 -> 395.7 | P14: =+I14-I13 -> 620.9 | Q14: =+O14+O13 -> 979 | R14: =+P14+P13 -> 1483.2
A15: =+A14+7 -> 38939 | D15: 3451.1 | E15: 4350 | F15: 4216.3 | G15: 4835.4 | H15: =+D15+F15 -> 7667.4 | I15: =+E15+G15 -> 9185.4 | J15: =+(H15/I15-1)*100 -> -16.526226 | O15: =+H15-H14 -> 387.7 | P15: =+I15-I14 -> 468.4 | Q15: =+O15+O14 -> 783.4 | R15: =+P15+P14 -> 1089.3
A16: =+A15+7 -> 38946 | D16: 3454 | E16: 4815.1 | F16: 4607 | G16: 5223.7 | H16: =+D16+F16 -> 8061 | I16: =+E16+G16 -> 10038.8 | J16: =+(H16/I16-1)*100 -> -19.701558 | O16: =+H16-H15 -> 393.6 | P16: =+I16-I15 -> 853.4 | Q16: =+O16+O15 -> 781.3 | R16: =+P16+P15 -> 1321.8
A17: =+A16+7 -> 38953 | D17: 3463.9 | E17: 4644.9 | F17: 5032.5 | G17: 5790.7 | H17: =+D17+F17 -> 8496.4 | I17: =+E17+G17 -> 10435.6 | J17: =+(H17/I17-1)*100 -> -18.582544 | O17: =+H17-H16 -> 435.4 | P17: =+I17-I16 -> 396.8 | Q17: =+O17+O16 -> 829 | R17: =+P17+P16 -> 1250.2
A18: =+A17+7 -> 38960 | D18: 3222.1 | E18: 5066.7 | F18: 5657.7 | G18: 6222.9 | H18: =+D18+F18 -> 8879.8 | I18: =+E18+G18 -> 11289.6 | J18: =+(H18/I18-1)*100 -> -21.345309 | O18: =+H18-H17 -> 383.4 | P18: =+I18-I17 -> 854 | Q18: =+O18+O17 -> 818.8 | R18: =+P18+P17 -> 1250.8
A19: =+A18+7 -> 38967 | D19: 3343.4 | E19: 5263 | F19: 5873.7 | G19: 6610.9 | H19: =+D19+F19 -> 9217.1 | I19: =+E19+G19 -> 11873.9 | J19: =+(H19/I19-1)*100 -> -22.375125 | O19: =+H19-H18 -> 337.3 | P19: =+I19-I18 -> 584.3 | Q19: =+O19+O18 -> 720.7 | R19: =+P19+P18 -> 1438.3
A20: =+A19+7 -> 38974 | D20: 3334 | E20: 5252.4 | F20: 6402.6 | G20: 7416.5 | H20: =+D20+F20 -> 9736.6 | I20: =+E20+G20 -> 12668.9 | J20: =+(H20/I20-1)*100 -> -23.145656 | O20: =+H20-H19 -> 519.5 | P20: =+I20-I19 -> 795 | Q20: =+O20+O19 -> 856.8 | R20: =+P20+P19 -> 1379.3
... A22: =+A21+7 -> 38988 | D22: 3303.9 | E22: 5128.1 | F22: 7218.8 | G22: 8607.5 | H22: =+D22+F22 -> 10522.7 | I22: =+E22+G22 -> 13735.6 | J22: =+(H22/I22-1)*100 -> -23.391042 | O22: =+H22-H21 -> 377.7 | P22: =+I22-I21 -> 475.6 | Q22: =+O22+O21 -> 786.1 | R22: =+P22+P21 -> 1066.7
A23: =+A22+7 -> 38995 | D23: 3544.6 | E23: 4807.8 | F23: 7670.5 | G23: 9285 | H23: =+D23+F23 -> 11215.1 | I23: =+E23+G23 -> 14092.8 | J23: =+(H23/I23-1)*100 -> -20.419647 | K23: 25180 | L23: =+K23-H23 -> 13964.9 | O23: =+H23-H22 -> 692.4 | P23: =+I23-I22 -> 357.2 | Q23: =+O23+O22 -> 1070.1 | R23: =+P23+P22 -> 832.8
A24: =+A23+7 -> 39002 | D24: 3405.4 | E24: 4651.4 | F24: 8247 | G24: 9836.7 | H24: =+D24+F24 -> 11652.4 | I24: =+E24+G24 -> 14488.1 | J24: =+(H24/I24-1)*100 -> -19.572615 | K24: 25180 | L24: =+K24-H24 -> 13527.6 | M24: =+L23/33 -> 423.17879 | N24: =+H24-H23 -> 437.3 | O24: =+H24-H23 -> 437.3 | P24: =+I24-I23 -> 395.3 | Q24: =+O24+O23 -> 1129.7 | R24: =+P24+P23 -> 752.5
A25: =+A24+7 -> 39009 | D25: 3438 | E25: 4332 | F25: 8675.2 | G25: 10535.2 | H25: =+D25+F25 -> 12113.2 | I25: =+E25+G25 -> 14867.2 | J25: =+(H25/I25-1)*100 -> -18.523999 | M25: =+L24/33 -> 409.92727 | O25: =+H25-H24 -> 460.8 | P25: =+I25-I24 -> 379.1 | Q25: =+O25+O24 -> 898.1 | R25: =+P25+P24 -> 774.4
A26: =+A25+7 -> 39016 | D26: 4028.2 | E26: 4218.9 | F26: 9023.7 | G26: 11082.2 | H26: =+D26+F26 -> 13051.9 | I26: =+E26+G26 -> 15301.1 | J26: =+(H26/I26-1)*100 -> -14.699597 | O26: =+H26-H25 -> 938.7 | P26: =+I26-I25 -> 433.9 | Q26: =+O26+O25 -> 1399.5 | R26: =+P26+P25 -> 813
A27: =+A26+7 -> 39023 | D27: 4344.2 | E27: 5169 | F27: 9280.7 | G27: 11514.2 | H27: =+D27+F27 -> 13624.9 | I27: =+E27+G27 -> 16683.2 | J27: =+(H27/I27-1)*100 -> -18.331615 | O27: =+H27-H26 -> 573 | P27: =+I27-I26 -> 1382.1 | Q27: =+O27+O26 -> 1511.7 | R27: =+P27+P26 -> 1816
A28: =+A27+7 -> 39030 | D28: 4327.2 | E28: 5355.9 | F28: 9620.8 | G28: 11891.5 | H28: =+D28+F28 -> 13948 | I28: =+E28+G28 -> 17247.4 | J28: =+(H28/I28-1)*100 -> -19.12984 | O28: =+H28-H27 -> 323.1 | P28: =+I28-I27 -> 564.2 | Q28: =+O28+O27 -> 896.1 | R28: =+P28+P27 -> 1946.3
A29: =+A28+7 -> 39037 | D29: 4373.1 | E29: 5336.9 | F29: 9936.3 | G29: 12343.1 | H29: =+D29+F29 -> 14309.4 | I29: =+E29+G29 -> 17680 | J29: =+(H29/I29-1)*100 -> -19.06448 | O29: =+H29-H28 -> 361.4 | P29: =+I29-I28 -> 432.6 | Q29: =+O29+O28 -> 684.5 | R29: =+P29+P28 -> 996.8
A30: =+A29+7 -> 39044 | D30: 4511.7 | E30: 5040.9 | F30: 10344.9 | G30: 12889.8 | H30: =+D30+F30 -> 14856.6 | I30: =+E30+G30 -> 17930.7 | J30: =+(H30/I30-1)*100 -> -17.144339 | O30: =+H30-H29 -> 547.2 | P30: =+I30-I29 -> 250.7 | Q30: =+O30+O29 -> 908.6 | R30: =+P30+P29 -> 683.3
A31: =+A30+7 -> 39051 | D31: 4417.2 | E31: 5001.4 | F31: 10843.3 | G31: 13362.7 | H31: =+D31+F31 -> 15260.5 | I31: =+E31+G31 -> 18364.1 | J31: =+(H31/I31-1)*100 -> -16.900365 | K31: 24490 | L31: 900 | M31: =+K31/L31 -> 27.211111 | O31: =+H31-H30 -> 403.9 | P31: =+I31-I30 -> 433.4 | Q31: =+O31+O30 -> 951.1 | R31: =+P31+P30 -> 684.1
A32: =+A31+7 -> 39058 | D32: 4475.4 | E32: 5018.3 | F32: 11256.2 | G32: 14058.5 | H32: =+D32+F32 -> 15731.6 | I32: =+E32+G32 -> 19076.8 | J32: =+(H32/I32-1)*100 -> -17.535436 | O32: =+H32-H31 -> 471.1 | P32: =+I32-I31 -> 712.7 | Q32: =+O32+O31 -> 875 | R32: =+P32+P31 -> 1146.1
A33: =+A32+7 -> 39065 | D33: 4568 | E33: 5115.7 | F33: 11618.7 | G33: 14483.8 | H33: =+D33+F33 -> 16186.7 | I33: =+E33+G33 -> 19599.5 | J33: =+(H33/I33-1)*100 -> -17.412689 | O33: =+H33-H32 -> 455.1 | P33: =+I33-I32 -> 522.7 | Q33: =+O33+O32 -> 926.2 | R33: =+P33+P32 -> 1235.4
A34: =+A33+7 -> 39072 | D34: 4630.1 | E34: 4833.6 | F34: 11910.7 | G34: 15122.4 | H34: =+D34+F34 -> 16540.8 | I34: =+E34+G34 -> 19956 | J34: =+(H34/I34-1)*100 -> -17.11365 | O34: =+H34-H33 -> 354.1 | P34: =+I34-I33 -> 356.5 | Q34: =+O34+O33 -> 809.2 | R34: =+P34+P33 -> 879.2
A35: =+A34+7 -> 39079 | D35: 4277.2 | E35: 4727.2 | F35: 12398.7 | G35: 15453.2 | H35: =+D35+F35 -> 16675.9 | I35: =+E35+G35 -> 20180.4 | J35: =+(H35/I35-1)*100 -> -17.36586 | O35: =+H35-H34 -> 135.1 | P35: =+I35-I34 -> 224.4 | Q35: =+O35+O34 -> 489.2 | R35: =+P35+P34 -> 580.9
A36: =+A35+7 -> 39086 | D36: 4027.5 | E36: 4493.6 | F36: 12892.8 | G36: 16028.8 | H36: =+D36+F36 -> 16920.3 | I36: =+E36+G36 -> 20522.4 | J36: =+(H36/I36-1)*100 -> -17.552041 | K36: 23810 | L36: 875 | O36: =+H36-H35 -> 244.4 | P36: =+I36-I35 -> 342 | Q36: =+O36+O35 -> 379.5 | R36: =+P36+P35 -> 566.4
A37: =+A36+7 -> 39093 | D37: 4468.4 | E37: 4524.5 | F37: 13276.6 | G37: 16349.7 | H37: =+D37+F37 -> 17745 | I37: =+E37+G37 -> 20874.2 | J37: =+(H37/I37-1)*100 -> -14.990754 | L37: =+L36/L31 -> 0.97222222 | O37: =+H37-H36 -> 824.7 | P37: =+I37-I36 -> 351.8 | Q37: =+O37+O36 -> 1069.1 | R37: =+P37+P36 -> 693.8
A38: =+A37+7 -> 39100 | D38: 4183.8 | E38: 4409.5 | F38: 13807.3 | G38: 16839.7 | H38: =+D38+F38 -> 17991.1 | I38: =+E38+G38 -> 21249.2 | J38: =+(H38/I38-1)*100 -> -15.332813 | O38: =+H38-H37 -> 246.1 | P38: =+I38-I37 -> 375 | Q38: =+O38+O37 -> 1070.8 | R38: =+P38+P37 -> 726.8
A39: =+A38+7 -> 39107 | D39: 4169.7 | E39: 4185.4 | F39: 14381.9 | G39: 17416.5 | H39: =+D39+F39 -> 18551.6 | I39: =+E39+G39 -> 21601.9 | J39: =+(H39/I39-1)*100 -> -14.120517 | O39: =+H39-H38 -> 560.5 | P39: =+I39-I38 -> 352.7 | Q39: =+O39+O38 -> 806.6 | R39: =+P39+P38 -> 727.7
A40: =+A39+7 -> 39114 | D40: 4312.8 | E40: 3897.8 | F40: 14971.4 | G40: 18054.8 | H40: =+D40+F40 -> 19284.2 | I40: =+E40+G40 -> 21952.6 | J40: =+(H40/I40-1)*100 -> -12.15528 | O40: =+H40-H39 -> 732.6 | P40: =+I40-I39 -> 350.7 | Q40: =+O40+O39 -> 1293.1 | R40: =+P40+P39 -> 703.4
A41: =+A40+7 -> 39121 | D41: 4265.2 | E41: 3999.4 | F41: 15380.4 | G41: 18546.9 | H41: =+D41+F41 -> 19645.6 | I41: =+E41+G41 -> 22546.3 | J41: =+(H41/I41-1)*100 -> -12.865526 | O41: =+H41-H40 -> 361.4 | P41: =+I41-I40 -> 593.7 | Q41: =+O41+O40 -> 1094 | R41: =+P41+P40 -> 944.4
...

Sheet Nigeria
A1: NIGERIA | B1: Unshipped Balance | D1: Accumulated Exports | F1: Total Commitments | K1: 4 Not included - FAS Press Release: 300,000 mt on 05/07 to Iraq for 2008/09.
A2: EXPORT SALES, Nigeria | B2: this year | C2: last year | D2: this year | E2: last year | F2: this year | G2: last year | H2: % change | I2: 2006
A3: =Japan!A3 -> 38855 | B3: 203.9 | C3: 154.4 | D3: 2957.1 | E3: 2434.4 | F3: =+B3+D3 -> 3161 | G3: =+C3+E3 -> 2588.8 | H3: =+(F3/G3-1)*100 -> 22.102905 | I3: 91.5
A4: =Japan!A4 -> 38862 | B4: 134.2 | C4: 120.9 | D4: 3003.6 | E4: 2496.2 | F4: =+B4+D4 -> 3137.8 | G4: =+C4+E4 -> 2617.1 | H4: =+(F4/G4-1)*100 -> 19.896068 | I4: 111.8
A5: =+A4+7 -> 38869 | B5: 215 | C5: 499.8 | D5: 29.7 | E5: 47.6 | F5: =+B5+D5 -> 244.7 | G5: =+C5+E5 -> 547.4 | H5: =+(F5/G5-1)*100 -> -55.297771
A6: =+A5+7 -> 38876 | B6: 203.3 | C6: 463.4 | D6: 59.3 | E6: 117 | F6: =+B6+D6 -> 262.6 | G6: =+C6+E6 -> 580.4 | H6: =+(F6/G6-1)*100 -> -54.755341
A7: =+A6+7 -> 38883 | B7: 272.7 | C7: 482.6 | D7: 98 | E7: 118.7 | F7: =+B7+D7 -> 370.7 | G7: =+C7+E7 -> 601.3 | H7: =+(F7/G7-1)*100 -> -38.350241
A8: =+A7+7 -> 38890 | B8: 248.7 | C8: 517 | D8: 147.3 | E8: 195.1 | F8: =+B8+D8 -> 396 | G8: =+C8+E8 -> 712.1 | H8: =+(F8/G8-1)*100 -> -44.389833
A9: =+A8+7 -> 38897 | B9: 305.7 | C9: 539.8 | D9: 184.6 | E9: 244.3 | F9: =+B9+D9 -> 490.3 | G9: =+C9+E9 -> 784.1 | H9: =+(F9/G9-1)*100 -> -37.46971
A10: =+A9+7 -> 38904 | B10: 297.7 | C10: 516.6 | D10: 206.4 | E10: 331.7 | F10: =+B10+D10 -> 504.1 | G10: =+C10+E10 -> 848.3 | H10: =+(F10/G10-1)*100 -> -40.575268
A11: =+A10+7 -> 38911 | B11: 275.1 | C11: 563.7 | D11: 300.3 | E11: 400.5 | F11: =+B11+D11 -> 575.4 | G11: =+C11+E11 -> 964.2 | H11: =+(F11/G11-1)*100 -> -40.323584
A12: =+A11+7 -> 38918 | B12: 250.1 | C12: 552 | D12: 330.2 | E12: 412.2 | F12: =+B12+D12 -> 580.3 | G12: =+C12+E12 -> 964.2 | H12: =+(F12/G12-1)*100 -> -39.815391
A13: =+A12+7 -> 38925 | B13: 360.8 | C13: 724.4 | D13: 435 | E13: 532.7 | F13: =+B13+D13 -> 795.8 | G13: =+C13+E13 -> 1257.1 | H13: =+(F13/G13-1)*100 -> -36.695569
A14: =+A13+7 -> 38932 | B14: 280 | C14: 642.3 | D14: 544.7 | E14: 696.6 | F14: =+B14+D14 -> 824.7 | G14: =+C14+E14 -> 1338.9 | H14: =+(F14/G14-1)*100 -> -38.404661
A15: =+A14+7 -> 38939 | B15: 284.2 | C15: 594.8 | D15: 560.5 | E15: 810.6 | F15: =+B15+D15 -> 844.7 | G15: =+C15+E15 -> 1405.4 | H15: =+(F15/G15-1)*100 -> -39.896115
A16: =+A15+7 -> 38946 | B16: 306.1 | C16: 671.9 | D16: 663 | E16: 879.1 | F16: =+B16+D16 -> 969.1 | G16: =+C16+E16 -> 1551 | H16: =+(F16/G16-1)*100 -> -37.51773
... A52: =+A51+7 -> 39198 | B52: 232.3 | C52: 226 | D52: 2260.4 | E52: 2840.4 | F52: =+B52+D52 -> 2492.7 | G52: =+C52+E52 -> 3066.4 | H52: =+(F52/G52-1)*100 -> -18.709236
A53: =+A52+7 -> 39205 | B53: 214.2 | C53: 246.9 | D53: 2293.4 | E53: 2864.5 | F53: =+B53+D53 -> 2507.6 | G53: =+C53+E53 -> 3111.4 | H53: =+(F53/G53-1)*100 -> -19.406055 | I53: 114.5
A54: =+A53+7 -> 39212 | B54: 210.1 | C54: 261.8 | D54: 2311 | E54: 2915.6 | F54: =+B54+D54 -> 2521.1 | G54: =+C54+E54 -> 3177.4 | H54: =+(F54/G54-1)*100 -> -20.655253 | I54: 114.5
A55: =+A54+7 -> 39219 | B55: 241.6 | C55: 203.9 | D55: 2362.5 | E55: 2957.1 | F55: =+B55+D55 -> 2604.1 | G55: =+C55+E55 -> 3161 | H55: =+(F55/G55-1)*100 -> -17.617842 | I55: 144.5
A56: =+A55+7 -> 39226 | B56: 218.5 | C56: 134.2 | D56: 2387.8 | E56: 3003.6 | F56: =+B56+D56 -> 2606.3 | G56: =+C56+E56 -> 3137.8 | H56: =+(F56/G56-1)*100 -> -16.938619 | I56: 144.5
A57: =+A56+7 -> 39233 | D57: 2441.2 | E57: 3035.6 | F57: 2441.2 | G57: 3035.6 | H57: =+(F57/G57-1)*100 -> -19.580972
A58: =+A57+7 -> 39240 | B58: 423.7 | C58: 203.3 | D58: 25.5 | E58: 59.3 | F58: =+B58+D58 -> 449.2 | G58: =+C58+E58 -> 262.6 | H58: =+(F58/G58-1)*100 -> 71.058644
A59: =+A58+7 -> 39247 | B59: 410.7 | C59: 272.7 | D59: 104.4 | E59: 59.3 | F59: =+B59+D59 -> 515.1 | G59: =+C59+E59 -> 332 | H59: =+(F59/G59-1)*100 -> 55.150602
A60: =+A59+7 -> 39254 | B60: 410.8 | C60: 248.7 | D60: 104.4 | E60: 147.3 | F60: =+B60+D60 -> 515.2 | G60: =+C60+E60 -> 396 | H60: =+(F60/G60-1)*100 -> 30.10101
A61: =+A60+7 -> 39261 | B61: 375 | C61: 305.7 | D61: 165.7 | E61: 184.6 | F61: =+B61+D61 -> 540.7 | G61: =+C61+E61 -> 490.3 | H61: =+(F61/G61-1)*100 -> 10.279421
A62: =+A61+7 -> 39268 | B62: 400 | C62: 297.7 | D62: 192.3 | E62: 206.4 | F62: =+B62+D62 -> 592.3 | G62: =+C62+E62 -> 504.1 | H62: =+(F62/G62-1)*100 -> 17.496528
A63: =+A62+7 -> 39275 | B63: 474.4 | C63: 275.1 | D63: 257.9 | E63: 300.3 | F63: =+B63+D63 -> 732.3 | G63: =+C63+E63 -> 575.4 | H63: =+(F63/G63-1)*100 -> 27.267987
A64: =+A63+7 -> 39282 | B64: 434.1 | C64: 250.1 | D64: 359.9 | E64: 330.2 | F64: =+B64+D64 -> 794 | G64: =+C64+E64 -> 580.3 | H64: =+(F64/G64-1)*100 -> 36.82578
A65: =+A64+7 -> 39289 | B65: 462.6 | C65: 360.8 | D65: 378.9 | E65: 435 | F65: =+B65+D65 -> 841.5 | G65: =+C65+E65 -> 795.8 | H65: =+(F65/G65-1)*100 -> 5.7426489
A66: =+A65+7 -> 39296 | B66: 411.9 | C66: 280 | D66: 478.5 | E66: 544.7 | F66: =+B66+D66 -> 890.4 | G66: =+C66+E66 -> 824.7 | H66: =+(F66/G66-1)*100 -> 7.9665333
A67: =+A66+7 -> 39303 | B67: 470.6 | C67: 284.2 | D67: 550.4 | E67: 560.5 | F67: =+B67+D67 -> 1021 | G67: =+C67+E67 -> 844.7 | H67: =+(F67/G67-1)*100 -> 20.871315
A68: =+A67+7 -> 39310 | B68: 462.7 | C68: 306.1 | D68: 619.6 | E68: 663 | F68: =+B68+D68 -> 1082.3 | G68: =+C68+E68 -> 969.1 | H68: =+(F68/G68-1)*100 -> 11.680941
A69: =+A68+7 -> 39317 | B69: 408.8 | C69: 337.1 | D69: 742.8 | E69: 687 | F69: =+B69+D69 -> 1151.6 | G69: =+C69+E69 -> 1024.1 | H69: =+(F69/G69-1)*100 -> 12.449956 | I69: 6
A70: =+A69+7 -> 39324 | B70: 393.8 | C70: 261.7 | D70: 763.9 | E70: 794.3 | F70: =+B70+D70 -> 1157.7 | G70: =+C70+E70 -> 1056 | H70: =+(F70/G70-1)*100 -> 9.6306818
A71: =+A70+7 -> 39331 | B71: 444.5 | C71: 279.7 | D71: 835.3 | E71: 794.3 | F71: =+B71+D71 -> 1279.8 | G71: =+C71+E71 -> 1074 | H71: =+(F71/G71-1)*100 -> 19.162011
A72: =+A71+7 -> 39338 | B72: 619.6 | C72: 237.9 | D72: 842.6 | E72: 877.8 | F72: =+B72+D72 -> 1462.2 | G72: =+C72+E72 -> 1115.7 | H72: =+(F72/G72-1)*100 -> 31.056736
A73: =+A72+7 -> 39345 | B73: 584.5 | C73: 295.9 | D73: 939.5 | E73: 879.4 | F73: =+B73+D73 -> 1524 | G73: =+C73+E73 -> 1175.3 | H73: =+(F73/G73-1)*100 -> 29.669021
A74: =+A73+7 -> 39352 | B74: 636.7 | C74: 255.4 | D74: 997.3 | E74: 973.1 | F74: =+B74+D74 -> 1634 | G74: =+C74+E74 -> 1228.5 | H74: =+(F74/G74-1)*100 -> 33.007733
A75: =+A74+7 -> 39359 | B75: 579 | C75: 233.4 | D75: 1050.8 | E75: 999.6 | F75: =+B75+D75 -> 1629.8 | G75: =+C75+E75 -> 1233 | H75: =+(F75/G75-1)*100 -> 32.181671
...

Sheet Japan
A1: JAPAN | B1: Unshipped Balance | D1: Accumulated Exports | F1: Total Commitments
A2: EXPORT SALES, Japan | B2: this year | C2: last year | D2: this year | E2: last year | F2: this year | G2: last year | H2: % change
A3: 38855 | B3: 193.7 | C3: 207.1 | D3: 2907.4 | E3: 2957.3 | F3: =+B3+D3 -> 3101.1 | G3: =+C3+E3 -> 3164.4 | H3: =+(F3/G3-1)*100 -> -2.0003792 | I3: 314.9
A4: =+A3+7 -> 38862 | B4: 131.9 | C4: 139.3 | D4: 2928 | E4: 3067.4 | F4: =+B4+D4 -> 3059.9 | G4: =+C4+E4 -> 3206.7 | H4: =+(F4/G4-1)*100 -> -4.577915 | I4: 452.9
A5: =+A4+7 -> 38869 | B5: 548.3 | C5: 387.3 | D5: 0 | E5: 20.6 | F5: =+B5+D5 -> 548.3 | G5: =+C5+E5 -> 407.9 | H5: =+(F5/G5-1)*100 -> 34.420201
A6: =+A5+7 -> 38876 | B6: 604.7 | C6: 500.4 | D6: 35 | E6: 49.1 | F6: =+B6+D6 -> 639.7 | G6: =+C6+E6 -> 549.5 | H6: =+(F6/G6-1)*100 -> 16.414923
A7: =+A6+7 -> 38883 | B7: 586.1 | C7: 520.7 | D7: 84.9 | E7: 95.3 | F7: =+B7+D7 -> 671 | G7: =+C7+E7 -> 616 | H7: =+(F7/G7-1)*100 -> 8.9285714
A8: =+A7+7 -> 38890 | B8: 534.2 | C8: 520.7 | D8: 202.1 | E8: 115.8 | F8: =+B8+D8 -> 736.3 | G8: =+C8+E8 -> 636.5 | H8: =+(F8/G8-1)*100 -> 15.679497
A9: =+A8+7 -> 38897 | B9: 537.4 | C9: 580.7 | D9: 263.2 | E9: 136.4 | F9: =+B9+D9 -> 800.6 | G9: =+C9+E9 -> 717.1 | H9: =+(F9/G9-1)*100 -> 11.644122
A10: =+A9+7 -> 38904 | B10: 505.8 | C10: 514.9 | D10: 341.3 | E10: 244.3 | F10: =+B10+D10 -> 847.1 | G10: =+C10+E10 -> 759.2 | H10: =+(F10/G10-1)*100 -> 11.577977
A11: =+A10+7 -> 38911 | B11: 517.1 | C11: 468.9 | D11: 392.1 | E11: 290.5 | F11: =+B11+D11 -> 909.2 | G11: =+C11+E11 -> 759.4 | H11: =+(F11/G11-1)*100 -> 19.7261
A12: =+A11+7 -> 38918 | B12: 495.5 | C12: 473.6 | D12: 464.2 | E12: 336.9 | F12: =+B12+D12 -> 959.7 | G12: =+C12+E12 -> 810.5 | H12: =+(F12/G12-1)*100 -> 18.40839
A13: =+A12+7 -> 38925 | B13: 495.5 | C13: 588.3 | D13: 485.6 | E13: 365.6 | F13: =+B13+D13 -> 981.1 | G13: =+C13+E13 -> 953.9 | H13: =+(F13/G13-1)*100 -> 2.8514519
A14: =+A13+7 -> 38932 | B14: 494.8 | C14: 542.7 | D14: 545.9 | E14: 453.2 | F14: =+B14+D14 -> 1040.7 | G14: =+C14+E14 -> 995.9 | H14: =+(F14/G14-1)*100 -> 4.4984436
A15: =+A14+7 -> 38939 | B15: 575.7 | C15: 506.4 | D15: 587.6 | E15: 561.2 | F15: =+B15+D15 -> 1163.3 | G15: =+C15+E15 -> 1067.6 | H15: =+(F15/G15-1)*100 -> 8.9640315
A16: =+A15+7 -> 38946 | B16: 532.9 | C16: 487.4 | D16: 608.2 | E16: 602.4 | F16: =+B16+D16 -> 1141.1 | G16: =+C16+E16 -> 1089.8 | H16: =+(F16/G16-1)*100 -> 4.7072857
... A53: =+A52+7 -> 39205 | B53: 569.6 | C53: 508.8 | D53: 2884.4 | E53: 2643.9 | F53: =+B53+D53 -> 3454 | G53: =+C53+E53 -> 3152.7 | H53: =+(F53/G53-1)*100 -> 9.5568877
A54: =+A53+7 -> 39212 | B54: 451.4 | C54: 358.3 | D54: 3052.3 | E54: 2791.2 | F54: =+B54+D54 -> 3503.7 | G54: =+C54+E54 -> 3149.5 | H54: =+(F54/G54-1)*100 -> 11.24623 | I54: 20
A55: =+A54+7 -> 39219 | B55: 399.5 | C55: 193.7 | D55: 3130.3 | E55: 2907.4 | F55: =+B55+D55 -> 3529.8 | G55: =+C55+E55 -> 3101.1 | H55: =+(F55/G55-1)*100 -> 13.824127 | I55: 70.9
A56: =+A55+7 -> 39226 | B56: 250.8 | C56: 131.9 | D56: 3181.3 | E56: 2928 | F56: =+B56+D56 -> 3432.1 | G56: =+C56+E56 -> 3059.9 | H56: =+(F56/G56-1)*100 -> 12.163796 | I56: 204.3
A57: =+A56+7 -> 39233 | F57: 3227.7 | G57: 2965.7 | H57: =+(F57/G57-1)*100 -> 8.8343393
A58: =+A57+7 -> 39240 | B58: 449.2 | C58: 604.7 | D58: 57 | E58: 35 | F58: =+B58+D58 -> 506.2 | G58: =+C58+E58 -> 639.7 | H58: =+(F58/G58-1)*100 -> -20.869157
A59: =+A58+7 -> 39247 | B59: 419.9 | C59: 586.1 | D59: 132.9 | E59: 84.9 | F59: =+B59+D59 -> 552.8 | G59: =+C59+E59 -> 671 | H59: =+(F59/G59-1)*100 -> -17.615499
A60: =+A59+7 -> 39254 | B60: 424.9 | C60: 534.2 | D60: 153.5 | E60: 202.1 | F60: =+B60+D60 -> 578.4 | G60: =+C60+E60 -> 736.3 | H60: =+(F60/G60-1)*100 -> -21.445063
A61: =+A60+7 -> 39261 | B61: 393.1 | C61: 537.4 | D61: 214.6 | E61: 263.2 | F61: =+B61+D61 -> 607.7 | G61: =+C61+E61 -> 800.6 | H61: =+(F61/G61-1)*100 -> -24.094429
A62: =+A61+7 -> 39268 | B62: 363 | C62: 505.8 | D62: 245.6 | E62: 341.3 | F62: =+B62+D62 -> 608.6 | G62: =+C62+E62 -> 847.1 | H62: =+(F62/G62-1)*100 -> -28.154881
A63: =+A62+7 -> 39275 | B63: 404.2 | C63: 517.1 | D63: 286.8 | E63: 392.1 | F63: =+B63+D63 -> 691 | G63: =+C63+E63 -> 909.2 | H63: =+(F63/G63-1)*100 -> -23.99912
A64: =+A63+7 -> 39282 | B64: 438.7 | C64: 495.5 | D64: 340.3 | E64: 464.2 | F64: =+B64+D64 -> 779 | G64: =+C64+E64 -> 959.7 | H64: =+(F64/G64-1)*100 -> -18.828801
A65: =+A64+7 -> 39289 | B65: 357.6 | C65: 495.8 | D65: 428.4 | E65: 485.6 | F65: =+B65+D65 -> 786 | G65: =+C65+E65 -> 981.4 | H65: =+(F65/G65-1)*100 -> -19.910332
A66: =+A65+7 -> 39296 | B66: 387.6 | C66: 494.8 | D66: 495.3 | E66: 545.9 | F66: =+B66+D66 -> 882.9 | G66: =+C66+E66 -> 1040.7 | H66: =+(F66/G66-1)*100 -> -15.162871
A67: =+A66+7 -> 39303 | B67: 431.4 | C67: 575.7 | D67: 583.5 | E67: 587.6 | F67: =+B67+D67 -> 1014.9 | G67: =+C67+E67 -> 1163.3 | H67: =+(F67/G67-1)*100 -> -12.756813
A68: =+A67+7 -> 39310 | B68: 445.8 | C68: 532.9 | D68: 614.5 | E68: 608.2 | F68: =+B68+D68 -> 1060.3 | G68: =+C68+E68 -> 1141.1 | H68: =+(F68/G68-1)*100 -> -7.0808869
A69: =+A68+7 -> 39317 | B69: 404.6 | C69: 536.7 | D69: 676.3 | E69: 649.4 | F69: =+B69+D69 -> 1080.9 | G69: =+C69+E69 -> 1186.1 | H69: =+(F69/G69-1)*100 -> -8.8694039
... A104: =+A103+7 -> 39562 | B104: 560.9 | C104: 635.6 | D104: 2811.9 | E104: 2817.5 | F104: =+B104+D104 -> 3372.8 | G104: =+C104+E104 -> 3453.1 | H104: =+(F104/G104-1)*100 -> -2.3254467
A105: =+A104+7 -> 39569 | B105: 452.6 | C105: 569.6 | D105: 2949.6 | E105: 2884.4 | F105: =+B105+D105 -> 3402.2 | G105: =+C105+E105 -> 3454 | H105: =+(F105/G105-1)*100 -> -1.4997105 | I105: 187.5
A106: =+A105+7 -> 39576 | B106: 383.4 | C106: 451.4 | D106: 3040.7 | E106: 3052.3 | F106: =+B106+D106 -> 3424.1 | G106: =+C106+E106 -> 3503.7 | H106: =+(F106/G106-1)*100 -> -2.271884 | I106: 187.5
A107: =+A106+7 -> 39583 | B107: 354.4 | C107: 399.5 | D107: 3112.6 | E107: 3130.3 | F107: =+B107+D107 -> 3467 | G107: =+C107+E107 -> 3529.8 | H107: =+(F107/G107-1)*100 -> -1.7791376 | I107: 216.3
A108: =+A107+7 -> 39590 | B108: 284.8 | C108: 250.8 | D108: 3180.3 | E108: 3181.3 | F108: =+B108+D108 -> 3465.1 | G108: =+C108+E108 -> 3432.1 | H108: =+(F108/G108-1)*100 -> 0.96151045 | I108: 242.9
A109: =+A108+7 -> 39597 | B109: 177.6 | C109: 205.2 | D109: 3319.4 | E109: 3227.7 | F109: =+B109+D109 -> 3497 | G109: =+C109+E109 -> 3432.9 | H109: =+(F109/G109-1)*100 -> 1.867226 | I109: 262.8
A110: =+A109+7 -> 39604 | B110: 501.5 | C110: 449.2 | D110: 97.8 | E110: 57 | F110: =+B110+D110 -> 599.3 | G110: =+C110+E110 -> 506.2 | H110: =+(F110/G110-1)*100 -> 18.39194
...

Sheet Mexico
A1: MEXICO | B1: Unshipped Balance | D1: Accumulated Exports | F1: Total Commitments
A2: EXPORT SALES, Mexico | B2: this year | C2: last year | D2: this year | E2: last year | F2: this year | G2: last year | H2: % change
A3: 38855 | B3: 107.8 | C3: 159.6 | D3: 2500.9 | E3: 2657.7 | F3: =+B3+D3 -> 2608.7 | G3: =+C3+E3 -> 2817.3 | H3: =+(F3/G3-1)*100 -> -7.4042523 | I3: 359
A4: =+Japan!A4 -> 38862 | B4: 82 | C4: 141.2 | D4: 2536.8 | E4: 2676.4 | F4: =+B4+D4 -> 2618.8 | G4: =+C4+E4 -> 2817.6 | H4: =+(F4/G4-1)*100 -> -7.0556502 | I4: 392.4
A5: =+A4+7 -> 38869 | B5: 465.6 | C5: 354.8 | D5: 0.8 | E5: 6.9 | F5: =+B5+D5 -> 466.4 | G5: =+C5+E5 -> 361.7 | H5: =+(F5/G5-1)*100 -> 28.946641
A6: =+A5+7 -> 38876 | B6: 447 | C6: 347.7 | D6: 49.1 | E6: 34.9 | F6: =+B6+D6 -> 496.1 | G6: =+C6+E6 -> 382.6 | H6: =(F6/G6-1)*100 -> 29.665447
A7: =+A6+7 -> 38883 | B7: 419 | C7: 334.5 | D7: 90 | E7: 67.4 | F7: =+B7+D7 -> 509 | G7: =+C7+E7 -> 401.9 | H7: =(F7/G7-1)*100 -> 26.64842
A8: =+A7+7 -> 38890 | B8: 519.7 | C8: 377.7 | D8: 126.1 | E8: 90.6 | F8: =+B8+D8 -> 645.8 | G8: =+C8+E8 -> 468.3 | H8: =(F8/G8-1)*100 -> 37.903054
A9: =+A8+7 -> 38897 | B9: 508.7 | C9: 401.3 | D9: 154.9 | E9: 142.7 | F9: =+B9+D9 -> 663.6 | G9: =+C9+E9 -> 544 | H9: =(F9/G9-1)*100 -> 21.985294
A10: =+A9+7 -> 38904 | B10: 515.8 | C10: 417.1 | D10: 180.9 | E10: 167.2 | F10: =+B10+D10 -> 696.7 | G10: =+C10+E10 -> 584.3 | H10: =(F10/G10-1)*100 -> 19.236693
A11: =+A10+7 -> 38911 | B11: 489.4 | C11: 456.6 | D11: 233.6 | E11: 125.3 | F11: =+B11+D11 -> 723 | G11: =+C11+E11 -> 581.9 | H11: =(F11/G11-1)*100 -> 24.248153
A12: =+A11+7 -> 38918 | B12: 549.6 | C12: 442.6 | D12: 247.9 | E12: 273 | F12: =+B12+D12 -> 797.5 | G12: =+C12+E12 -> 715.6 | H12: =(F12/G12-1)*100 -> 11.444941
A13: =+A12+7 -> 38925 | B13: 415.5 | C13: 435.3 | D13: 321.6 | E13: 358.3 | F13: =+B13+D13 -> 737.1 | G13: =+C13+E13 -> 793.6 | H13: =(F13/G13-1)*100 -> -7.1194556
A14: =+A13+7 -> 38932 | B14: 378.4 | C14: 528.9 | D14: 373 | E14: 446.4 | F14: =+B14+D14 -> 751.4 | G14: =+C14+E14 -> 975.3 | H14: =(F14/G14-1)*100 -> -22.957039
A15: =+A14+7 -> 38939 | B15: 365.1 | C15: 543.5 | D15: 407 | E15: 529.5 | F15: =+B15+D15 -> 772.1 | G15: =+C15+E15 -> 1073 | H15: =(F15/G15-1)*100 -> -28.04287
A16: =+A15+7 -> 38946 | B16: 322 | C16: 515.6 | D16: 464.8 | E16: 594.6 | F16: =+B16+D16 -> 786.8 | G16: =+C16+E16 -> 1110.2 | H16: =(F16/G16-1)*100 -> -29.129887
A17: =+A16+7 -> 38953 | B17: 311.8 | C17: 496.2 | D17: 513.2 | E17: 673.3 | F17: =+B17+D17 -> 825 | G17: =+C17+E17 -> 1169.5 | H17: =(F17/G17-1)*100 -> -29.457033
... A25: =+A24+7 -> 39009 | B25: 325.2 | C25: 357.5 | D25: 850.5 | E25: 1140.2 | F25: =+B25+D25 -> 1175.7 | G25: =+C25+E25 -> 1497.7 | H25: =(F25/G25-1)*100 -> -21.499633
A26: =+A25+7 -> 39016 | B26: 379.9 | C26: 324.8 | D26: 882 | E26: 1171.5 | F26: =+B26+D26 -> 1261.9 | G26: =+C26+E26 -> 1496.3 | H26: =(F26/G26-1)*100 -> -15.665308 | I26: 24.1
A27: =+A26+7 -> 39023 | B27: 358.2 | C27: 327.3 | D27: 920.5 | E27: 1206.4 | F27: =+B27+D27 -> 1278.7 | G27: =+C27+E27 -> 1533.7 | H27: =(F27/G27-1)*100 -> -16.626459 | I27: 24.1
A28: =+A27+7 -> 39030 | B28: 356.9 | C28: 306.3 | D28: 957.5 | E28: 1237.1 | F28: =+B28+D28 -> 1314.4 | G28: =+C28+E28 -> 1543.4 | H28: =(F28/G28-1)*100 -> -14.837372 | I28: 24.1
A29: =+A28+7 -> 39037 | B29: 375.4 | C29: 306.1 | D29: 966 | E29: 1270.6 | F29: =+B29+D29 -> 1341.4 | G29: =+C29+E29 -> 1576.7 | H29: =(F29/G29-1)*100 -> -14.923575 | I29: 24.1
A30: =+A29+7 -> 39044 | B30: 348.8 | C30: 310.2 | D30: 1001.8 | E30: 1322.4 | F30: =+B30+D30 -> 1350.6 | G30: =+C30+E30 -> 1632.6 | H30: =(F30/G30-1)*100 -> -17.273061 | I30: 24.1
A31: =+A30+7 -> 39051 | B31: 359.8 | C31: 297 | D31: 1027.6 | E31: 1390.8 | F31: =+B31+D31 -> 1387.4 | G31: =+C31+E31 -> 1687.8 | H31: =(F31/G31-1)*100 -> -17.798317 | I31: 24.1
A32: =+A31+7 -> 39058 | B32: 363 | C32: 333 | D32: 1072 | E32: 1426.7 | F32: =+B32+D32 -> 1435 | G32: =+C32+E32 -> 1759.7 | H32: =(F32/G32-1)*100 -> -18.452009
A33: =+A32+7 -> 39065 | B33: 355.1 | C33: 324.1 | D33: 1104.2 | E33: 1486.3 | F33: =+B33+D33 -> 1459.3 | G33: =+C33+E33 -> 1810.4 | H33: =(F33/G33-1)*100 -> -19.393504
A34: =+A33+7 -> 39072 | B34: 382.1 | C34: 273.7 | D34: 1127.1 | E34: 1556.5 | F34: =+B34+D34 -> 1509.2 | G34: =+C34+E34 -> 1830.2 | H34: =(F34/G34-1)*100 -> -17.539067
A35: =+A34+7 -> 39079 | B35: 355.3 | C35: 253.7 | D35: 1155.4 | E35: 1590 | F35: =+B35+D35 -> 1510.7 | G35: =+C35+E35 -> 1843.7 | H35: =(F35/G35-1)*100 -> -18.061507 | I35: 38
A36: =+A35+7 -> 39086 | B36: 319.8 | C36: 329.5 | D36: 1204.7 | E36: 1626.9 | F36: =+B36+D36 -> 1524.5 | G36: =+C36+E36 -> 1956.4 | H36: =(F36/G36-1)*100 -> -22.076263
A37: =+A36+7 -> 39093 | B37: 320.5 | C37: 347.2 | D37: 1227.9 | E37: 1659.1 | F37: =+B37+D37 -> 1548.4 | G37: =+C37+E37 -> 2006.3 | H37: =(F37/G37-1)*100 -> -22.823107
A38: =+A37+7 -> 39100 | B38: 331 | C38: 353 | D38: 1272.9 | E38: 1739.9 | F38: =+B38+D38 -> 1603.9 | G38: =+C38+E38 -> 2092.9 | H38: =(F38/G38-1)*100 -> -23.364709
A39: =+A38+7 -> 39107 | B39: 327.8 | C39: 373.3 | D39: 1308.4 | E39: 1771.8 | F39: =+B39+D39 -> 1636.2 | G39: =+C39+E39 -> 2145.1 | H39: =(F39/G39-1)*100 -> -23.723836
A40: =+A39+7 -> 39114 | B40: 319.8 | C40: 286.1 | D40: 1335 | E40: 1893.6 | F40: =+B40+D40 -> 1654.8 | G40: =+C40+E40 -> 2179.7 | H40: =(F40/G40-1)*100 -> -24.081296
A41: =+A40+7 -> 39121 | B41: 290.2 | C41: 267.5 | D41: 1385.4 | E41: 1925.7 | F41: =+B41+D41 -> 1675.6 | G41: =+C41+E41 -> 2193.2 | H41: =(F41/G41-1)*100 -> -23.600219
A42: =+A41+7 -> 39128 | B42: 317.2 | C42: 328.6 | D42: 1397.2 | E42: 1988 | F42: =+B42+D42 -> 1714.4 | G42: =+C42+E42 -> 2316.6 | H42: =(F42/G42-1)*100 -> -25.994993
A43: =+A42+7 -> 39135 | B43: 282.3 | C43: 317.8 | D43: 1467.1 | E43: 2028.9 | F43: =+B43+D43 -> 1749.4 | G43: =+C43+E43 -> 2346.7 | H43: =(F43/G43-1)*100 -> -25.452763
A44: =+A43+7 -> 39142 | B44: 380.3 | C44: 309.4 | D44: 1477.7 | E44: 2067.8 | F44: =+B44+D44 -> 1858 | G44: =+C44+E44 -> 2377.2 | H44: =(F44/G44-1)*100 -> -21.840821
A45: =+A44+7 -> 39149 | B45: 383.4 | C45: 286.8 | D45: 1539 | E45: 2109.6 | F45: =+B45+D45 -> 1922.4 | G45: =+C45+E45 -> 2396.4 | H45: =(F45/G45-1)*100 -> -19.77967
A46: =+A45+7 -> 39156 | B46: 373.9 | C46: 256.7 | D46: 1592.6 | E46: 2169.6 | F46: =+B46+D46 -> 1966.5 | G46: =+C46+E46 -> 2426.3 | H46: =(F46/G46-1)*100 -> -18.950666
A47: =+A46+7 -> 39163 | B47: 345.3 | C47: 231.3 | D47: 1651.9 | E47: 2226.1 | F47: =+B47+D47 -> 1997.2 | G47: =+C47+E47 -> 2457.4 | H47: =(F47/G47-1)*100 -> -18.72711
...

Sheet Phil
B1: Unshipped Balance | D1: Accumulated Exports | F1: Total Commitments
A2: EXPORT SALES, Philippines | B2: this year | C2: last year | D2: this year | E2: last year | F2: this year | G2: last year | H2: % change
A3: =Japan!A3 -> 38855 | B3: 174.9 | C3: 223.5 | D3: 1538 | E3: 1653.7 | F3: =+B3+D3 -> 1712.9 | G3: =+C3+E3 -> 1877.2 | H3: =+(F3/G3-1)*100 -> -8.7523972 | I3: 500.1
A4: =Japan!A4 -> 38862 | B4: 131.8 | C4: 92.1 | D4: 1585.2 | E4: 1786.2 | F4: =+B4+D4 -> 1717 | G4: =+C4+E4 -> 1878.3 | H4: =+(F4/G4-1)*100 -> -8.5875526 | I4: 530.1
A5: =+A4+7 -> 38869 | B5: 627.3 | C5: 298.1 | D5: 0 | E5: 0 | F5: =+B5+D5 -> 627.3 | G5: =+C5+E5 -> 298.1 | H5: =+(F5/G5-1)*100 -> 110.43274
A6: =+A5+7 -> 38876 | B6: 578.1 | C6: 296.1 | D6: 51.5 | E6: 0 | F6: =+B6+D6 -> 629.6 | G6: =+C6+E6 -> 296.1 | H6: =+(F6/G6-1)*100 -> 112.63087
A7: =+A6+7 -> 38883 | B7: 556.1 | C7: 281.6 | D7: 75.7 | E7: 14.3 | F7: =+B7+D7 -> 631.8 | G7: =+C7+E7 -> 295.9 | H7: =+(F7/G7-1)*100 -> 113.51808
A8: =+A7+7 -> 38890 | B8: 563.6 | C8: 297.1 | D8: 109.3 | E8: 41.6 | F8: =+B8+D8 -> 672.9 | G8: =+C8+E8 -> 338.7 | H8: =+(F8/G8-1)*100 -> 98.671391
A9: =+A8+7 -> 38897 | B9: 520.6 | C9: 286.8 | D9: 151.8 | E9: 79.3 | F9: =+B9+D9 -> 672.4 | G9: =+C9+E9 -> 366.1 | H9: =+(F9/G9-1)*100 -> 83.665665
A10: =+A9+7 -> 38904 | B10: 571.6 | C10: 336.8 | D10: 151.8 | E10: 79.3 | F10: =+B10+D10 -> 723.4 | G10: =+C10+E10 -> 416.1 | H10: =+(F10/G10-1)*100 -> 73.852439
A11: =+A10+7 -> 38911 | B11: 606.1 | C11: 279.3 | D11: 197.3 | E11: 139.5 | F11: =+B11+D11 -> 803.4 | G11: =+C11+E11 -> 418.8 | H11: =+(F11/G11-1)*100 -> 91.833811
A12: =+A11+7 -> 38918 | B12: 588.1 | C12: 286.3 | D12: 241 | E12: 139.5 | F12: =+B12+D12 -> 829.1 | G12: =+C12+E12 -> 425.8 | H12: =+(F12/G12-1)*100 -> 94.715829
A13: =+A12+7 -> 38925 | B13: 609.9 | C13: 262.3 | D13: 241 | E13: 188.1 | F13: =+B13+D13 -> 850.9 | G13: =+C13+E13 -> 450.4 | H13: =+(F13/G13-1)*100 -> 88.920959
A14: =+A13+7 -> 38932 | B14: 609.5 | C14: 292.3 | D14: 291.2 | E14: 188.1 | F14: =+B14+D14 -> 900.7 | G14: =+C14+E14 -> 480.4 | H14: =+(F14/G14-1)*100 -> 87.489592
A15: =+A14+7 -> 38939 | B15: 567.4 | C15: 305.8 | D15: 332.3 | E15: 209.1 | F15: =+B15+D15 -> 899.7 | G15: =+C15+E15 -> 514.9 | H15: =+(F15/G15-1)*100 -> 74.732958
A16: =+A15+7 -> 38946 | B16: 571.8 | C16: 353.9 | D16: 377.8 | E16: 258.3 | F16: =+B16+D16 -> 949.6 | G16: =+C16+E16 -> 612.2 | H16: =+(F16/G16-1)*100 -> 55.112708
... A21: =+A20+7 -> 38981 | B21: 499.4 | C21: 327 | D21: 535.2 | E21: 411.5 | F21: =+B21+D21 -> 1034.6 | G21: =+C21+E21 -> 738.5 | H21: =+(F21/G21-1)*100 -> 40.094787
A22: =+A21+7 -> 38988 | B22: 499.4 | C22: 263 | D22: 535.2 | E22: 521.2 | F22: =+B22+D22 -> 1034.6 | G22: =+C22+E22 -> 784.2 | H22: =+(F22/G22-1)*100 -> 31.93063 | I22: 42
A23: =+A22+7 -> 38995 | B23: 463.4 | C23: 280.1 | D23: 623.5 | E23: 521.2 | F23: =+B23+D23 -> 1086.9 | G23: =+C23+E23 -> 801.3 | H23: =+(F23/G23-1)*100 -> 35.642082
A24: =+A23+7 -> 39002 | B24: 410.9 | C24: 310.6 | D24: 716.3 | E24: 579.5 | F24: =+B24+D24 -> 1127.2 | G24: =+C24+E24 -> 890.1 | H24: =+(F24/G24-1)*100 -> 26.637456 | I24: 42
A25: =+A24+7 -> 39009 | B25: 418.4 | C25: 372.1 | D25: 756.9 | E25: 604.1 | F25: =+B25+D25 -> 1175.3 | G25: =+C25+E25 -> 976.2 | H25: =+(F25/G25-1)*100 -> 20.395411
A26: =+A25+7 -> 39016 | B26: 523.4 | C26: 457.1 | D26: 773.7 | E26: 604.1 | F26: =+B26+D26 -> 1297.1 | G26: =+C26+E26 -> 1061.2 | H26: =+(F26/G26-1)*100 -> 22.229551 | I26: 42
A27: =+A26+7 -> 39023 | B27: 530.9 | C27: 407.2 | D27: 773.7 | E27: 651.5 | F27: =+B27+D27 -> 1304.6 | G27: =+C27+E27 -> 1058.7 | H27: =+(F27/G27-1)*100 -> 23.226599 | I27: 42
A28: =+A27+7 -> 39030 | B28: 488.1 | C28: 438.2 | D28: 819.2 | E28: 651.5 | F28: =+B28+D28 -> 1307.3 | G28: =+C28+E28 -> 1089.7 | H28: =+(F28/G28-1)*100 -> 19.968799 | I28: 42
A29: =+A28+7 -> 39037 | B29: 474.6 | C29: 438.2 | D29: 856 | E29: 651.5 | F29: =+B29+D29 -> 1330.6 | G29: =+C29+E29 -> 1089.7 | H29: =+(F29/G29-1)*100 -> 22.107002
A30: =+A29+7 -> 39044 | B30: 524.6 | C30: 395.7 | D30: 856 | E30: 705.6 | F30: =+B30+D30 -> 1380.6 | G30: =+C30+E30 -> 1101.3 | H30: =+(F30/G30-1)*100 -> 25.360937
A31: =+A30+7 -> 39051 | B31: 498.2 | C31: 428.3 | D31: 905.8 | E31: 753.2 | F31: =+B31+D31 -> 1404 | G31: =+C31+E31 -> 1181.5 | H31: =+(F31/G31-1)*100 -> 18.831993
A32: =+A31+7 -> 39058 | B32: 481.2 | C32: 442.3 | D32: 929.3 | E32: 820.3 | F32: =+B32+D32 -> 1410.5 | G32: =+C32+E32 -> 1262.6 | H32: =+(F32/G32-1)*100 -> 11.713924
A33: =+A32+7 -> 39065 | B33: 473.7 | C33: 445.7 | D33: 935.6 | E33: 837.2 | F33: =+B33+D33 -> 1409.3 | G33: =+C33+E33 -> 1282.9 | H33: =+(F33/G33-1)*100 -> 9.8526775
A34: =+A33+7 -> 39072 | B34: 449.7 | C34: 455.7 | D34: 960.8 | E34: 837.2 | F34: =+B34+D34 -> 1410.5 | G34: =+C34+E34 -> 1292.9 | H34: =+(F34/G34-1)*100 -> 9.0958311 | I34: 49.5
A35: =+A34+7 -> 39079 | B35: 396.3 | C35: 455.7 | D35: 1015 | E35: 837.2 | F35: =+B35+D35 -> 1411.3 | G35: =+C35+E35 -> 1292.9 | H35: =+(F35/G35-1)*100 -> 9.1577075 | I35: 49.5
A36: =+A35+7 -> 39086 | B36: 325 | C36: 485 | D36: 1088.3 | E36: 879.9 | F36: =+B36+D36 -> 1413.3 | G36: =+C36+E36 -> 1364.9 | H36: =+(F36/G36-1)*100 -> 3.5460473 | I36: 49.5
A37: =+A36+7 -> 39093 | B37: 400.7 | C37: 536 | D37: 1088.6 | E37: 879.9 | F37: =+B37+D37 -> 1489.3 | G37: =+C37+E37 -> 1415.9 | H37: =+(F37/G37-1)*100 -> 5.1839819
A38: =+A37+7 -> 39100 | B38: 369.7 | C38: 614 | D38: 1120.1 | E38: 879.9 | F38: =+B38+D38 -> 1489.8 | G38: =+C38+E38 -> 1493.9 | H38: =+(F38/G38-1)*100 -> -0.27444943
A39: =+A38+7 -> 39107 | B39: 325.2 | C39: 387.6 | D39: 1168.1 | E39: 1041.6 | F39: =+B39+D39 -> 1493.3 | G39: =+C39+E39 -> 1429.2 | H39: =+(F39/G39-1)*100 -> 4.4850266
A40: =+A39+7 -> 39114 | B40: 267.2 | C40: 436.6 | D40: 1236.4 | E40: 1061.5 | F40: =+B40+D40 -> 1503.6 | G40: =+C40+E40 -> 1498.1 | H40: =+(F40/G40-1)*100 -> 0.3671317
A41: =+A40+7 -> 39121 | B41: 338 | C41: 550.5 | D41: 1237 | E41: 1085.7 | F41: =+B41+D41 -> 1575 | G41: =+C41+E41 -> 1636.2 | H41: =+(F41/G41-1)*100 -> -3.740374
A42: =+A41+7 -> 39128 | B42: 362.7 | C42: 438.9 | D42: 1237.7 | E42: 1164.4 | F42: =+B42+D42 -> 1600.4 | G42: =+C42+E42 -> 1603.3 | H42: =+(F42/G42-1)*100 -> -0.18087694
A43: =+A42+7 -> 39135 | B43: 305.9 | C43: 433.9 | D43: 1293.1 | E43: 1164.4 | F43: =+B43+D43 -> 1599 | G43: =+C43+E43 -> 1598.3 | H43: =+(F43/G43-1)*100 -> 0.043796534
A44: =+A43+7 -> 39142 | B44: 285.8 | C44: 416.8 | D44: 1329.3 | E44: 1182.1 | F44: =+B44+D44 -> 1615.1 | G44: =+C44+E44 -> 1598.9 | H44: =+(F44/G44-1)*100 -> 1.0131966
...

Sheet Korea
B1: Unshipped Balance | D1: Accumulated Exports | F1: Total Commitments
A2: EXPORT SALES, Korea | B2: this year | C2: last year | D2: this year | E2: last year | F2: this year | G2: last year | H2: % change | I2: 2006
A3: =Japan!A3 -> 38855 | B3: 73 | C3: 104.3 | D3: 1107.7 | E3: 1258.5 | F3: =+B3+D3 -> 1180.7 | G3: =+C3+E3 -> 1362.8 | H3: =+(F3/G3-1)*100 -> -13.362195 | I3: 46.1
A4: =Japan!A4 -> 38862 | B4: 51.5 | C4: 87.5 | D4: 1130.1 | E4: 1275.9 | F4: =+B4+D4 -> 1181.6 | G4: =+C4+E4 -> 1363.4 | H4: =+(F4/G4-1)*100 -> -13.334311 | I4: 90
A5: =+A4+7 -> 38869 | B5: 155.5 | C5: 162.1 | D5: 3.8 | E5: 0.3 | F5: =+B5+D5 -> 159.3 | G5: =+C5+E5 -> 162.4 | H5: =+(F5/G5-1)*100 -> -1.908867
A6: =+A5+7 -> 38876 | B6: 131.9 | C6: 167.5 | D6: 44.1 | E6: 22.4 | F6: =+B6+D6 -> 176 | G6: =+C6+E6 -> 189.9 | H6: =+(F6/G6-1)*100 -> -7.3196419
A7: =+A6+7 -> 38883 | B7: 158.9 | C7: 177.9 | D7: 56.4 | E7: 34.3 | F7: =+B7+D7 -> 215.3 | G7: =+C7+E7 -> 212.2 | H7: =+(F7/G7-1)*100 -> 1.460886
A8: =+A7+7 -> 38890 | B8: 180.4 | C8: 141.4 | D8: 68.1 | E8: 82.1 | F8: =+B8+D8 -> 248.5 | G8: =+C8+E8 -> 223.5 | H8: =+(F8/G8-1)*100 -> 11.185682
A9: =+A8+7 -> 38897 | B9: 146.9 | C9: 157.2 | D9: 105.5 | E9: 103 | F9: =+B9+D9 -> 252.4 | G9: =+C9+E9 -> 260.2 | H9: =+(F9/G9-1)*100 -> -2.9976941
A10: =+A9+7 -> 38904 | B10: 139 | C10: 180.7 | D10: 114.2 | E10: 103.2 | F10: =+B10+D10 -> 253.2 | G10: =+C10+E10 -> 283.9 | H10: =+(F10/G10-1)*100 -> -10.813667
A11: =+A10+7 -> 38911 | B11: 138.3 | C11: 240.4 | D11: 114.9 | E11: 106.5 | F11: =+B11+D11 -> 253.2 | G11: =+C11+E11 -> 346.9 | H11: =+(F11/G11-1)*100 -> -27.010666
A12: =+A11+7 -> 38918 | B12: 125.1 | C12: 196 | D12: 163.3 | E12: 151.6 | F12: =+B12+D12 -> 288.4 | G12: =+C12+E12 -> 347.6 | H12: =+(F12/G12-1)*100 -> -17.03107
A13: =+A12+7 -> 38925 | B13: 144.7 | C13: 173.6 | D13: 189.1 | E13: 196.6 | F13: =+B13+D13 -> 333.8 | G13: =+C13+E13 -> 370.2 | H13: =+(F13/G13-1)*100 -> -9.832523
A14: =+A13+7 -> 38932 | B14: 154.5 | C14: 194.4 | D14: 204.6 | E14: 222.6 | F14: =+B14+D14 -> 359.1 | G14: =+C14+E14 -> 417 | H14: =+(F14/G14-1)*100 -> -13.884892
A15: =+A14+7 -> 38939 | B15: 212.1 | C15: 195.5 | D15: 246.9 | E15: 222.9 | F15: =+B15+D15 -> 459 | G15: =+C15+E15 -> 418.4 | H15: =+(F15/G15-1)*100 -> 9.7036329
A16: =+A15+7 -> 38946 | B16: 214.3 | C16: 196.5 | D16: 247.8 | E16: 222.9 | F16: =+B16+D16 -> 462.1 | G16: =+C16+E16 -> 419.4 | H16: =+(F16/G16-1)*100 -> 10.181211
... A52: =+A51+7 -> 39198 | B52: 155.3 | C52: 129.9 | D52: 1052.1 | E52: 1045.4 | F52: =+B52+D52 -> 1207.4 | G52: =+C52+E52 -> 1175.3 | H52: =+(F52/G52-1)*100 -> 2.7312176
A53: =+A52+7 -> 39205 | B53: 111.6 | C53: 107.6 | D53: 1098.9 | E53: 1069.1 | F53: =+B53+D53 -> 1210.5 | G53: =+C53+E53 -> 1176.7 | H53: =+(F53/G53-1)*100 -> 2.8724399 | I53: 21.8
A54: =+A53+7 -> 39212 | B54: 94.4 | C54: 86 | D54: 1117.9 | E54: 1092 | F54: =+B54+D54 -> 1212.3 | G54: =+C54+E54 -> 1178 | H54: =+(F54/G54-1)*100 -> 2.9117148 | I54: 22.3
A55: =+A54+7 -> 39219 | B55: 45.9 | C55: 73 | D55: 1144.8 | E55: 1107.7 | F55: =+B55+D55 -> 1190.7 | G55: =+C55+E55 -> 1180.7 | H55: =+(F55/G55-1)*100 -> 0.8469552 | I55: 64.2
A56: =+A55+7 -> 39226 | B56: 47.3 | C56: 51.5 | D56: 1145 | E56: 1130.1 | F56: =+B56+D56 -> 1192.3 | G56: =+C56+E56 -> 1181.6 | H56: =+(F56/G56-1)*100 -> 0.90555179 | I56: 91.5
A57: =+A56+7 -> 39233 | F57: 1191.4 | G57: 1142.5 | H57: =+(F57/G57-1)*100 -> 4.2800875
A58: =+A57+7 -> 39240 | B58: 118.2 | C58: 131.9 | D58: 0 | E58: 44.1 | F58: =+B58+D58 -> 118.2 | G58: =+C58+E58 -> 176 | H58: =+(F58/G58-1)*100 -> -32.840909
A59: =+A58+7 -> 39247 | B59: 117 | C59: 158.9 | D59: 26.6 | E59: 56.4 | F59: =+B59+D59 -> 143.6 | G59: =+C59+E59 -> 215.3 | H59: =+(F59/G59-1)*100 -> -33.302369
A60: =+A59+7 -> 39254 | B60: 148.9 | C60: 180.4 | D60: 38.6 | E60: 68.1 | F60: =+B60+D60 -> 187.5 | G60: =+C60+E60 -> 248.5 | H60: =+(F60/G60-1)*100 -> -24.547284
A61: =+A60+7 -> 39261 | B61: 139.6 | C61: 146.9 | D61: 50.8 | E61: 105.5 | F61: =+B61+D61 -> 190.4 | G61: =+C61+E61 -> 252.4 | H61: =+(F61/G61-1)*100 -> -24.564184
A62: =+A61+7 -> 39268 | B62: 205.7 | C62: 139 | D62: 72.3 | E62: 114.2 | F62: =+B62+D62 -> 278 | G62: =+C62+E62 -> 253.2 | H62: =+(F62/G62-1)*100 -> 9.7946288
A63: =+A62+7 -> 39275 | B63: 183.2 | C63: 138.3 | D63: 95.3 | E63: 114.9 | F63: =+B63+D63 -> 278.5 | G63: =+C63+E63 -> 253.2 | H63: =+(F63/G63-1)*100 -> 9.9921011
A64: =+A63+7 -> 39282 | B64: 183.4 | C64: 125.1 | D64: 95.7 | E64: 163.3 | F64: =+B64+D64 -> 279.1 | G64: =+C64+E64 -> 288.4 | H64: =+(F64/G64-1)*100 -> -3.2246879
A65: =+A64+7 -> 39289 | B65: 158.9 | C65: 144.7 | D65: 119.9 | E65: 189.1 | F65: =+B65+D65 -> 278.8 | G65: =+C65+E65 -> 333.8 | H65: =+(F65/G65-1)*100 -> -16.476932
A66: =+A65+7 -> 39296 | B66: 183.2 | C66: 154.5 | D66: 147.2 | E66: 204.6 | F66: =+B66+D66 -> 330.4 | G66: =+C66+E66 -> 359.1 | H66: =+(F66/G66-1)*100 -> -7.9922027
A67: =+A66+7 -> 39303 | B67: 183 | C67: 212.1 | D67: 169.8 | E67: 246.9 | F67: =+B67+D67 -> 352.8 | G67: =+C67+E67 -> 459 | H67: =+(F67/G67-1)*100 -> -23.137255
A68: =+A67+7 -> 39310 | B68: 178.9 | C68: 214.3 | D68: 219 | E68: 249.1 | F68: 377.8 | G68: =+C68+E68 -> 463.4 | H68: =+(F68/G68-1)*100 -> -18.472162
A69: =+A68+7 -> 39317 | B69: 157.4 | C69: 232.4 | D69: 243.6 | E69: 249.1 | F69: =+B69+D69 -> 401 | G69: =+C69+E69 -> 481.5 | H69: =+(F69/G69-1)*100 -> -16.718588
A70: =+A69+7 -> 39324 | B70: 115.3 | C70: 177.1 | D70: 289.5 | E70: 306.7 | F70: =+B70+D70 -> 404.8 | G70: =+C70+E70 -> 483.8 | H70: =+(F70/G70-1)*100 -> -16.329062
A71: =+A70+7 -> 39331 | B71: 202.7 | C71: 201.1 | D71: 290 | E71: 307.1 | F71: =+B71+D71 -> 492.7 | G71: =+C71+E71 -> 508.2 | H71: =+(F71/G71-1)*100 -> -3.0499803
A72: =+A71+7 -> 39338 | B72: 236.9 | C72: 156.2 | D72: 290 | E72: 355.6 | F72: =+B72+D72 -> 526.9 | G72: =+C72+E72 -> 511.8 | H72: =+(F72/G72-1)*100 -> 2.9503712
A73: =+A72+7 -> 39345 | B73: 270.9 | C73: 179 | D73: 341.7 | E73: 356.5 | F73: =+B73+D73 -> 612.6 | G73: =+C73+E73 -> 535.5 | H73: =+(F73/G73-1)*100 -> 14.397759
A74: =+A73+7 -> 39352 | B74: 251.7 | C74: 219.7 | D74: 363.9 | E74: 379.6 | F74: =+B74+D74 -> 615.6 | G74: =+C74+E74 -> 599.3 | H74: =+(F74/G74-1)*100 -> 2.7198398
A75: =+A74+7 -> 39359 | B75: 301.8 | C75: 197.6 | D75: 386.6 | E75: 402.5 | F75: =+B75+D75 -> 688.4 | G75: =+C75+E75 -> 600.1 | H75: =+(F75/G75-1)*100 -> 14.714214
...

Sheet Taiwan
B1: Unshipped Balance | D1: Accumulated Exports | F1: Total Commitments
A2: EXPORT SALES, Taiwan | B2: this year | C2: last year | D2: this year | E2: last year | F2: this year | G2: last year | H2: % change | I2: 2006
A3: =Japan!A3 -> 38855 | B3: 79 | C3: 32.3 | D3: 872 | E3: 926.7 | F3: =+B3+D3 -> 951 | G3: =+C3+E3 -> 959 | H3: =+(F3/G3-1)*100 -> -0.83420229 | I3: 40
A4: =Japan!A4 -> 38862 | B4: 38.9 | C4: 32.3 | D4: 914 | E4: 926.7 | F4: =+B4+D4 -> 952.9 | G4: =+C4+E4 -> 959 | H4: =+(F4/G4-1)*100 -> -0.63607925 | I4: 85.5
A5: =+A4+7 -> 38869 | B5: 124.4 | C5: 130.8 | D5: 0 | E5: 0 | F5: =+B5+D5 -> 124.4 | G5: =+C5+E5 -> 130.8 | H5: =+(F5/G5-1)*100 -> -4.8929664
A6: =+A5+7 -> 38876 | B6: 194.9 | C6: 86 | D6: 0 | E6: 47.1 | F6: =+B6+D6 -> 194.9 | G6: =+C6+E6 -> 133.1 | H6: =+(F6/G6-1)*100 -> 46.431255
A7: =+A6+7 -> 38883 | B7: 116 | C7: 102 | D7: 82.8 | E7: 47.1 | F7: =+B7+D7 -> 198.8 | G7: =+C7+E7 -> 149.1 | H7: =+(F7/G7-1)*100 -> 33.333333
A8: =+A7+7 -> 38890 | B8: 116 | C8: 102 | D8: 82.8 | E8: 47.1 | F8: =+B8+D8 -> 198.8 | G8: =+C8+E8 -> 149.1 | H8: =+(F8/G8-1)*100 -> 33.333333
A9: =+A8+7 -> 38897 | B9: 156.5 | C9: 102 | D9: 82.8 | E9: 41.1 | F9: =+B9+D9 -> 239.3 | G9: =+C9+E9 -> 143.1 | H9: =+(F9/G9-1)*100 -> 67.225716
A10: =+A9+7 -> 38904 | B10: 111 | C10: 102 | D10: 126.9 | E10: 47.1 | F10: =+B10+D10 -> 237.9 | G10: =+C10+E10 -> 149.1 | H10: =+(F10/G10-1)*100 -> 59.557344
A11: =+A10+7 -> 38911 | B11: 111 | C11: 194.2 | D11: 126.9 | E11: 47.1 | F11: =+B11+D11 -> 237.9 | G11: =+C11+E11 -> 241.3 | H11: =+(F11/G11-1)*100 -> -1.4090344
A12: =+A11+7 -> 38918 | B12: 111 | C12: 194.2 | D12: 126.9 | E12: 47.1 | F12: =+B12+D12 -> 237.9 | G12: =+C12+E12 -> 241.3 | H12: =+(F12/G12-1)*100 -> -1.4090344
A13: =+A12+7 -> 38925 | B13: 41 | C13: 92.2 | D13: 198.5 | E13: 135 | F13: =+B13+D13 -> 239.5 | G13: =+C13+E13 -> 227.2 | H13: =+(F13/G13-1)*100 -> 5.4137324
A14: =+A13+7 -> 38932 | B14: 41 | C14: 92.2 | D14: 198.5 | E14: 135 | F14: =+B14+D14 -> 239.5 | G14: =+C14+E14 -> 227.2 | H14: =+(F14/G14-1)*100 -> 5.4137324
A15: =+A14+7 -> 38939 | B15: 137.3 | C15: 92.2 | D15: 198.5 | E15: 135 | F15: =+B15+D15 -> 335.8 | G15: =+C15+E15 -> 227.2 | H15: =+(F15/G15-1)*100 -> 47.799296
A16: =+A15+7 -> 38946 | B16: 96.8 | C16: 194.1 | D16: 241 | E16: 135 | F16: =+B16+D16 -> 337.8 | G16: =+C16+E16 -> 329.1 | H16: =+(F16/G16-1)*100 -> 2.6435734
... A52: =+A51+7 -> 39198 | B52: 124.6 | C52: 79 | D52: 873.1 | E52: 872 | F52: =+B52+D52 -> 997.7 | G52: =+C52+E52 -> 951 | H52: =+(F52/G52-1)*100 -> 4.9106204
A53: =+A52+7 -> 39205 | B53: 155.6 | C53: 79 | D53: 874 | E53: 872 | F53: =+B53+D53 -> 1029.6 | G53: =+C53+E53 -> 951 | H53: =+(F53/G53-1)*100 -> 8.2649842 | I53: 5.2
A54: =+A53+7 -> 39212 | B54: 114 | C54: 79 | D54: 917.7 | E54: 872 | F54: =+B54+D54 -> 1031.7 | G54: =+C54+E54 -> 951 | H54: =+(F54/G54-1)*100 -> 8.4858044 | I54: 5.2
A55: =+A54+7 -> 39219 | B55: 82 | C55: 79 | D55: 917.8 | E55: 872 | F55: =+B55+D55 -> 999.8 | G55: =+C55+E55 -> 951 | H55: =+(F55/G55-1)*100 -> 5.1314406 | I55: 46.4
A56: =+A55+7 -> 39226 | B56: 37.9 | C56: 38.9 | D56: 964 | E56: 914 | F56: =+B56+D56 -> 1001.9 | G56: =+C56+E56 -> 952.9 | H56: =+(F56/G56-1)*100 -> 5.1421975 | I56: 129.9
A57: =+A56+7 -> 39233 | F57: 999 | G57: 914 | H57: =+(F57/G57-1)*100 -> 9.2997812
A58: =+A57+7 -> 39240 | B58: 131.6 | C58: 194.9 | D58: 1.5 | E58: 0 | F58: =+B58+D58 -> 133.1 | G58: =+C58+E58 -> 194.9 | H58: =+(F58/G58-1)*100 -> -31.708568
A59: =+A58+7 -> 39247 | B59: 131 | C59: 116 | D59: 2.2 | E59: 82.8 | F59: =+B59+D59 -> 133.2 | G59: =+C59+E59 -> 198.8 | H59: =+(F59/G59-1)*100 -> -32.997988
A60: =+A59+7 -> 39254 | B60: 220.6 | C60: 116 | D60: 3 | E60: 82.8 | F60: =+B60+D60 -> 223.6 | G60: =+C60+E60 -> 198.8 | H60: =+(F60/G60-1)*100 -> 12.474849
A61: =+A60+7 -> 39261 | B61: 179.3 | C61: 156.5 | D61: 46.3 | E61: 82.8 | F61: =+B61+D61 -> 225.6 | G61: =+C61+E61 -> 239.3 | H61: =+(F61/G61-1)*100 -> -5.7250313
A62: =+A61+7 -> 39268 | B62: 177.6 | C62: 111 | D62: 48 | E62: 126.9 | F62: =+B62+D62 -> 225.6 | G62: =+C62+E62 -> 237.9 | H62: =+(F62/G62-1)*100 -> -5.1702396
A63: =+A62+7 -> 39275 | B63: 146.1 | C63: 111 | D63: 90.9 | E63: 126.9 | F63: =+B63+D63 -> 237 | G63: =+C63+E63 -> 237.9 | H63: =+(F63/G63-1)*100 -> -0.37831021
A64: =+A63+7 -> 39282 | B64: 144.6 | C64: 111 | D64: 92.7 | E64: 126.9 | F64: =+B64+D64 -> 237.3 | G64: =+C64+E64 -> 237.9 | H64: =+(F64/G64-1)*100 -> -0.25220681
A65: =+A64+7 -> 39289 | B65: 139.8 | C65: 41 | D65: 99.3 | E65: 198.5 | F65: =+B65+D65 -> 239.1 | G65: =+C65+E65 -> 239.5 | H65: =+(F65/G65-1)*100 -> -0.16701461
A66: =+A65+7 -> 39296 | B66: 189.4 | C66: 41 | D66: 152.1 | E66: 198.5 | F66: =+B66+D66 -> 341.5 | G66: =+C66+E66 -> 239.5 | H66: =+(F66/G66-1)*100 -> 42.588727
A67: =+A66+7 -> 39303 | B67: 162.3 | C67: 137.3 | D67: 180.9 | E67: 198.5 | F67: =+B67+D67 -> 343.2 | G67: =+C67+E67 -> 335.8 | H67: =+(F67/G67-1)*100 -> 2.2036927
A68: =+A67+7 -> 39310 | B68: 114.4 | C68: 93.8 | D68: 231.2 | E68: 241 | F68: =+B68+D68 -> 345.6 | G68: =+C68+E68 -> 334.8 | H68: =+(F68/G68-1)*100 -> 3.2258065
A69: =+A68+7 -> 39317 | B69: 114.4 | C69: 97 | D69: 231.8 | E69: 241 | F69: =+B69+D69 -> 346.2 | G69: =+C69+E69 -> 338 | H69: =+(F69/G69-1)*100 -> 2.4260355
... A77: =+A76+7 -> 39373 | B77: 251.3 | C77: 95.8 | D77: 382.2 | E77: 340.9 | F77: =+B77+D77 -> 633.5 | G77: =+C77+E77 -> 436.7 | H77: =+(F77/G77-1)*100 -> 45.065262
A78: =+A77+7 -> 39380 | B78: 209.5 | C78: 51.2 | D78: 431.8 | E78: 385.5 | F78: =+B78+D78 -> 641.3 | G78: =+C78+E78 -> 436.7 | H78: =+(F78/G78-1)*100 -> 46.851385 | I78: 1.8
A79: =+A78+7 -> 39387 | B79: 209.9 | C79: 95.3 | D79: 434.7 | E79: 391.4 | F79: =+B79+D79 -> 644.6 | G79: =+C79+E79 -> 486.7 | H79: =+(F79/G79-1)*100 -> 32.442983
A80: =+A79+7 -> 39394 | B80: 245.6 | C80: 94.7 | D80: 480.1 | E80: 392 | F80: =+B80+D80 -> 725.7 | G80: =+C80+E80 -> 486.7 | H80: =+(F80/G80-1)*100 -> 49.106226
A81: =+A80+7 -> 39401 | B81: 203.2 | C81: 95.2 | D81: 525.9 | E81: 392 | F81: =+B81+D81 -> 729.1 | G81: =+C81+E81 -> 487.2 | H81: =+(F81/G81-1)*100 -> 49.651067
A82: =+A81+7 -> 39408 | B82: 205.2 | C82: 96.2 | D82: 528.6 | E82: 392 | F82: =+B82+D82 -> 733.8 | G82: =+C82+E82 -> 488.2 | H82: =+(F82/G82-1)*100 -> 50.307251
...

Sheet Egypt
A1: EGYPT | B1: Unshipped Balance | D1: Accumulated Exports | F1: Total Commitments
A2: EXPORT SALES, Egypt | B2: this year | C2: last year | D2: this year | E2: last year | F2: this year | G2: last year | H2: % change | I2: 2006
A3: 38855 | B3: 115 | C3: 55 | D3: 1123.6 | E3: 1896.6 | F3: =+B3+D3 -> 1238.6 | G3: =+C3+E3 -> 1951.6 | H3: =+(F3/G3-1)*100 -> -36.534126 | I3: 0
A4: =Japan!A4 -> 38862 | B4: 115 | C4: 55 | D4: 1123.6 | E4: 1896.6 | F4: =+B4+D4 -> 1238.6 | G4: =+C4+E4 -> 1951.6 | H4: =+(F4/G4-1)*100 -> -36.534126 | I4: 0
A5: =+A4+7 -> 38869 | B5: 55 | C5: 165 | D5: 0 | E5: 0 | F5: =+B5+D5 -> 55 | G5: =+C5+E5 -> 165 | H5: =+(F5/G5-1)*100 -> -66.666667
A6: =+A5+7 -> 38876 | B6: 55 | C6: 110 | D6: 0 | E6: 57.8 | F6: =+B6+D6 -> 55 | G6: =+C6+E6 -> 167.8 | H6: =+(F6/G6-1)*100 -> -67.222884
A7: =+A6+7 -> 38883 | B7: 55 | C7: 110 | D7: 0 | E7: 57.8 | F7: =+B7+D7 -> 55 | G7: =+C7+E7 -> 167.8 | H7: =+(F7/G7-1)*100 -> -67.222884
A8: =+A7+7 -> 38890 | B8: 175 | C8: 110 | D8: 57.8 | E8: 57.8 | F8: =+B8+D8 -> 232.8 | G8: =+C8+E8 -> 167.8 | H8: =+(F8/G8-1)*100 -> 38.736591
A9: =+A8+7 -> 38897 | B9: 175 | C9: 170 | D9: 57.8 | E9: 57.8 | F9: =+B9+D9 -> 232.8 | G9: =+C9+E9 -> 227.8 | H9: =+(F9/G9-1)*100 -> 2.1949078
A10: =+A9+7 -> 38904 | B10: 175 | C10: 170 | D10: 57.8 | E10: 57.8 | F10: =+B10+D10 -> 232.8 | G10: =+C10+E10 -> 227.8 | H10: =+(F10/G10-1)*100 -> 2.1949078
A11: =+A10+7 -> 38911 | B11: 175 | C11: 170 | D11: 57.8 | E11: 57.8 | F11: =+B11+D11 -> 232.8 | G11: =+C11+E11 -> 227.8 | H11: =+(F11/G11-1)*100 -> 2.1949078
A12: =+A11+7 -> 38918 | B12: 235 | C12: 230 | D12: 116.3 | E12: 115.5 | F12: =+B12+D12 -> 351.3 | G12: =+C12+E12 -> 345.5 | H12: =+(F12/G12-1)*100 -> 1.6787265
A13: =+A12+7 -> 38925 | B13: 350 | C13: 170 | D13: 116.3 | E13: 178.5 | F13: =+B13+D13 -> 466.3 | G13: =+C13+E13 -> 348.5 | H13: =+(F13/G13-1)*100 -> 33.802009
A14: =+A13+7 -> 38932 | B14: 235 | C14: 175 | D14: 230.5 | E14: 236.3 | F14: =+B14+D14 -> 465.5 | G14: =+C14+E14 -> 411.3 | H14: =+(F14/G14-1)*100 -> 13.177729
A15: =+A14+7 -> 38939 | B15: 235 | C15: 175 | D15: 230.5 | E15: 236.3 | F15: =+B15+D15 -> 465.5 | G15: =+C15+E15 -> 411.3 | H15: =+(F15/G15-1)*100 -> 13.177729
A16: =+A15+7 -> 38946 | B16: 290 | C16: 290 | D16: 290.5 | E16: 236.3 | F16: =+B16+D16 -> 580.5 | G16: =+C16+E16 -> 526.3 | H16: =+(F16/G16-1)*100 -> 10.298309
... A54: =+A53+7 -> 39212 | B54: 110 | C54: 115 | D54: 1981.5 | E54: 1123.6 | F54: =+B54+D54 -> 2091.5 | G54: =+C54+E54 -> 1238.6 | H54: =+(F54/G54-1)*100 -> 68.860003
A55: =+A54+7 -> 39219 | B55: 110 | C55: 115 | D55: 1981.5 | E55: 1123.6 | F55: =+B55+D55 -> 2091.5 | G55: =+C55+E55 -> 1238.6 | H55: =+(F55/G55-1)*100 -> 68.860003 | I55: 60
A56: =+A55+7 -> 39226 | B56: 110 | C56: 115 | D56: 1981.5 | E56: 1123.6 | F56: =+B56+D56 -> 2091.5 | G56: =+C56+E56 -> 1238.6 | H56: =+(F56/G56-1)*100 -> 68.860003 | I56: 120
A57: =+A56+7 -> 39233 | F57: 1981.5 | G57: 1181.3 | H57: =+(F57/G57-1)*100 -> 67.738932
A58: =+A57+7 -> 39240 | B58: 275 | C58: 55 | D58: 0 | E58: 0 | F58: =+B58+D58 -> 275 | G58: =+C58+E58 -> 55 | H58: =+(F58/G58-1)*100 -> 400
A59: =+A58+7 -> 39247 | B59: 275 | C59: 55 | D59: 0 | E59: 0 | F59: =+B59+D59 -> 275 | G59: =+C59+E59 -> 55 | H59: =+(F59/G59-1)*100 -> 400
A60: =+A59+7 -> 39254 | B60: 100 | C60: 175 | D60: 186.8 | E60: 57.8 | F60: =+B60+D60 -> 286.8 | G60: =+C60+E60 -> 232.8 | H60: =+(F60/G60-1)*100 -> 23.195876
A61: =+A60+7 -> 39261 | B61: 110 | C61: 175 | D61: 295.2 | E61: 57.8 | F61: =+B61+D61 -> 405.2 | G61: =+C61+E61 -> 232.8 | H61: =+(F61/G61-1)*100 -> 74.054983
A62: =+A61+7 -> 39268 | B62: 340 | C62: 175 | D62: 355.3 | E62: 57.8 | F62: =+B62+D62 -> 695.3 | G62: =+C62+E62 -> 232.8 | H62: =+(F62/G62-1)*100 -> 198.66838
A63: =+A62+7 -> 39275 | B63: 457 | C63: 175 | D63: 355.3 | E63: 57.8 | F63: =+B63+D63 -> 812.3 | G63: =+C63+E63 -> 232.8 | H63: =+(F63/G63-1)*100 -> 248.92612
A64: =+A63+7 -> 39282 | B64: 826 | C64: 235 | D64: 414.5 | E64: 116.3 | F64: =+B64+D64 -> 1240.5 | G64: =+C64+E64 -> 351.3 | H64: =+(F64/G64-1)*100 -> 253.11699
A65: =+A64+7 -> 39289 | B65: 892 | C65: 350 | D65: 414.5 | E65: 116.3 | F65: =+B65+D65 -> 1306.5 | G65: =+C65+E65 -> 466.3 | H65: =+(F65/G65-1)*100 -> 180.18443
A66: =+A65+7 -> 39296 | B66: 785 | C66: 235 | D66: 535.3 | E66: 230.5 | F66: =+B66+D66 -> 1320.3 | G66: =+C66+E66 -> 465.5 | H66: =+(F66/G66-1)*100 -> 183.6305
A67: =+A66+7 -> 39303 | B67: 825 | C67: 235 | D67: 669.9 | E67: 230.5 | F67: =+B67+D67 -> 1494.9 | G67: =+C67+E67 -> 465.5 | H67: =+(F67/G67-1)*100 -> 221.13856
A68: =+A67+7 -> 39310 | B68: 915 | C68: 290 | D68: 855.5 | E68: 290 | F68: =+B68+D68 -> 1770.5 | G68: =+C68+E68 -> 580 | H68: =+(F68/G68-1)*100 -> 205.25862
A69: =+A68+7 -> 39317 | B69: 1055.5 | C69: 170 | D69: 1037 | E69: 407.4 | F69: =+B69+D69 -> 2092.5 | G69: =+C69+E69 -> 577.4 | H69: =+(F69/G69-1)*100 -> 262.40042
... A89: =+A88+7 -> 39457 | B89: 120 | C89: 295 | D89: 2625 | E89: 1214.8 | F89: =+B89+D89 -> 2745 | G89: =+C89+E89 -> 1509.8 | H89: =+(F89/G89-1)*100 -> 81.812161
A90: =+A89+7 -> 39464 | B90: 60 | C90: 175 | D90: 2625 | E90: 1335.2 | F90: =+B90+D90 -> 2685 | G90: =+C90+E90 -> 1510.2 | H90: =+(F90/G90-1)*100 -> 77.791021 | I90: 120
A91: =+A90+7 -> 39471 | B91: 60 | C91: 170 | D91: 2625 | E91: 1393.2 | F91: =+B91+D91 -> 2685 | G91: =+C91+E91 -> 1563.2 | H91: =+(F91/G91-1)*100 -> 71.76305 | I91: 120
A92: =+A91+7 -> 39478 | B92: 60 | C92: 235 | D92: 2625 | E92: 1450.8 | F92: =+B92+D92 -> 2685 | G92: =+C92+E92 -> 1685.8 | H92: =+(F92/G92-1)*100 -> 59.271562 | I92: 120
A93: =+A92+7 -> 39485 | B93: 60 | C93: 230 | D93: 2625 | E93: 1509.8 | F93: =+B93+D93 -> 2685 | G93: =+C93+E93 -> 1739.8 | H93: =+(F93/G93-1)*100 -> 54.328084
A94: =+A93+7 -> 39492 | B94: 60 | C94: 230 | D94: 2625 | E94: 1572.8 | F94: =+B94+D94 -> 2685 | G94: =+C94+E94 -> 1802.8 | H94: =+(F94/G94-1)*100 -> 48.93499
A95: =+A94+7 -> 39499 | B95: 115 | C95: 230 | D95: 2625 | E95: 1602.8 | F95: =+B95+D95 -> 2740 | G95: =+C95+E95 -> 1832.8 | H95: =+(F95/G95-1)*100 -> 49.498036
A96: =+A95+7 -> 39506 | B96: 175 | C96: 230 | D96: 2625 | E96: 1602.8 | F96: =+B96+D96 -> 2800 | G96: =+C96+E96 -> 1832.8 | H96: =+(F96/G96-1)*100 -> 52.771715
...

Sheet Venezuela
B1: Unshipped Balance | D1: Accumulated Exports | F1: Total Commitments
A2: EXPORT SALES, China | B2: 2005 | C2: 2004 | D2: 2005 | E2: 2004 | F2: 2005 | G2: 2004 | H2: % change | I2: 2006
A3: 38855 | B3: 0 | C3: 72.1 | D3: 373 | E3: 2015 | F3: =+B3+D3 -> 373 | G3: =+C3+E3 -> 2087.1 | H3: =+(F3/G3-1)*100 -> -82.128312 | I3: 0
A4: =Japan!A4 -> 38862 | B4: 0 | C4: 72 | D4: 373 | E4: 2015.1 | F4: =+B4+D4 -> 373 | G4: =+C4+E4 -> 2087.1 | H4: =+(F4/G4-1)*100 -> -82.128312
A5: IRAQ 06/07 | B5: Unshipped Balance | D5: Accumulated Exports | F5: Total Commitments
B6: this year | C6: last year | D6: this year | E6: last year | F6: this year | G6: last year | H6: % change
A7: =+A4+7 -> 38869 | B7: 0 | C7: 157.5 | D7: 0 | E7: 0 | F7: =+B7+D7 -> 0 | G7: =+C7+E7 -> 157.5 | H7: =+(F7/G7-1)*100 -> -100
A8: =+A7+7 -> 38876 | B8: 0 | C8: 157.5 | D8: 0 | E8: 0 | F8: =+B8+D8 -> 0 | G8: =+C8+E8 -> 157.5 | H8: =+(F8/G8-1)*100 -> -100
A9: =+A8+7 -> 38883 | B9: 0 | C9: 157.5 | D9: 0 | E9: 0 | F9: =+B9+D9 -> 0 | G9: =+C9+E9 -> 157.5 | H9: =+(F9/G9-1)*100 -> -100
A10: =+A9+7 -> 38890 | B10: 0 | C10: 157.5 | D10: 0 | E10: 0 | F10: =+B10+D10 -> 0 | G10: =+C10+E10 -> 157.5 | H10: =+(F10/G10-1)*100 -> -100
A11: =+A10+7 -> 38897 | B11: 0 | C11: 212.5 | D11: 0 | E11: 0 | F11: =+B11+D11 -> 0 | G11: =+C11+E11 -> 212.5 | H11: =+(F11/G11-1)*100 -> -100
A12: =+A11+7 -> 38904 | B12: 0 | C12: 267.5 | D12: 0 | E12: 0 | F12: =+B12+D12 -> 0 | G12: =+C12+E12 -> 267.5 | H12: =+(F12/G12-1)*100 -> -100
A13: =+A12+7 -> 38911 | B13: 0 | C13: 267.5 | D13: 0 | E13: 0 | F13: =+B13+D13 -> 0 | G13: =+C13+E13 -> 267.5 | H13: =+(F13/G13-1)*100 -> -100
A14: =+A13+7 -> 38918 | B14: 0 | C14: 267.5 | D14: 0 | E14: 0 | F14: =+B14+D14 -> 0 | G14: =+C14+E14 -> 267.5 | H14: =+(F14/G14-1)*100 -> -100
A15: =+A14+7 -> 38925 | B15: 0 | C15: 322.5 | D15: 0 | E15: 59.9 | F15: =+B15+D15 -> 0 | G15: =+C15+E15 -> 382.4 | H15: =+(F15/G15-1)*100 -> -100
A16: =+A15+7 -> 38932 | B16: 0 | C16: 377.5 | D16: 0 | E16: 599.9 | F16: =+B16+D16 -> 0 | G16: =+C16+E16 -> 977.4 | H16: =+(F16/G16-1)*100 -> -100
A17: =+A16+7 -> 38939 | B17: 0 | C17: 377.5 | D17: 0 | E17: 117.6 | F17: =+B17+D17 -> 0 | G17: =+C17+E17 -> 495.1 | H17: =+(F17/G17-1)*100 -> -100 | I17: ??? Why the change last year?
A18: =+A17+7 -> 38946 | B18: 0 | C18: 627.5 | D18: 0 | E18: 117.6 | F18: =+B18+D18 -> 0 | G18: =+C18+E18 -> 745.1 | H18: =+(F18/G18-1)*100 -> -100 | I18: ??? Good question -- may not have actually shipped, some was put back into unshipped balance - very strange?
A19: =+A18+7 -> 38953 | B19: 0 | C19: 627.5 | D19: 0 | E19: 174.6 | F19: =+B19+D19 -> 0 | G19: =+C19+E19 -> 802.1 | H19: =+(F19/G19-1)*100 -> -100
A20: =+A19+7 -> 38960 | B20: 0 | C20: 627.5 | D20: 0 | E20: 174.6 | F20: =+B20+D20 -> 0 | G20: =+C20+E20 -> 802.1 | H20: =+(F20/G20-1)*100 -> -100
A21: =+A20+7 -> 38967 | B21: 0 | C21: 627.5 | D21: 0 | E21: 174.6 | F21: =+B21+D21 -> 0 | G21: =+C21+E21 -> 802.1 | H21: =+(F21/G21-1)*100 -> -100
A22: =+A21+7 -> 38974 | B22: 0 | C22: 520.1 | D22: 0 | E22: 282.6 | F22: =+B22+D22 -> 0 | G22: =+C22+E22 -> 802.7 | H22: =+(F22/G22-1)*100 -> -100
A23: =+A22+7 -> 38981 | B23: 0 | C23: 670.1 | D23: 0 | E23: 388.5 | F23: =+B23+D23 -> 0 | G23: =+C23+E23 -> 1058.6 | H23: =+(F23/G23-1)*100 -> -100
A24: =+A23+7 -> 38988 | B24: 0 | C24: 670.1 | D24: 0 | E24: 388.5 | F24: =+B24+D24 -> 0 | G24: =+C24+E24 -> 1058.6 | H24: =+(F24/G24-1)*100 -> -100
A25: =+A24+7 -> 38995 | B25: 300 | C25: 615.1 | D25: 0 | E25: 443.4 | F25: =+B25+D25 -> 300 | G25: =+C25+E25 -> 1058.5 | H25: =+(F25/G25-1)*100 -> -71.658007
A26: =+A25+7 -> 39002 | B26: 300 | C26: 577.5 | D26: 0 | E26: 496 | F26: =+B26+D26 -> 300 | G26: =+C26+E26 -> 1073.5 | H26: =+(F26/G26-1)*100 -> -72.054029
A27: =+A26+7 -> 39009 | B27: 300 | C27: 481.9 | D27: 0 | E27: 592.8 | F27: =+B27+D27 -> 300 | G27: =+C27+E27 -> 1074.7 | H27: =+(F27/G27-1)*100 -> -72.085233
A28: =+A27+7 -> 39016 | B28: 700 | C28: 426.6 | D28: 0 | E28: 648 | F28: =+B28+D28 -> 700 | G28: =+C28+E28 -> 1074.6 | H28: =+(F28/G28-1)*100 -> -34.859483
A29: =+A28+7 -> 39023 | B29: 700 | C29: 1226.6 | D29: 0 | E29: 648 | F29: =+B29+D29 -> 700 | G29: =+C29+E29 -> 1874.6 | H29: =+(F29/G29-1)*100 -> -62.658701
A30: =+A29+7 -> 39030 | B30: 700 | C30: 1281.6 | D30: 0 | E30: 648 | F30: =+B30+D30 -> 700 | G30: =+C30+E30 -> 1929.6 | H30: =+(F30/G30-1)*100 -> -63.723051
... A56: =+A55+7 -> 39212 | B56: 200 | C56: 149.1 | D56: 698.6 | E56: 2185.4 | F56: =+B56+D56 -> 898.6 | G56: =+C56+E56 -> 2334.5 | H56: =+(F56/G56-1)*100 -> -61.507818
A57: =+A56+7 -> 39219 | B57: 200 | C57: 149.1 | D57: 698.6 | E57: 2185.4 | F57: =+B57+D57 -> 898.6 | G57: =+C57+E57 -> 2334.5 | H57: =+(F57/G57-1)*100 -> -61.507818 | I57: 200
