Workbook

Sheet Summary
A1: Reference Database Statistics Summary
A2: 2008-2009
A4: * usage constrained by limitations on concurrent users
A5: Database Name | B5: Vendor / Platform | C5: COUNTER-compliant? | D5: Sessions | E5: Searches | F5: Turnaways | G5: 2008/09 Price | H5: Cost per Search
A6: ABI/INFORM Dateline | B6: ProQuest | D6: N/A | E6: N/A | F6: 0 | G6: 0 | H6: N/A
A7: ABI/INFORM Global | B7: ProQuest | D7: N/A | E7: N/A | F7: 0 | G7: 18757 | H7: N/A
A8: ABI/INFORM Trade & Industry | B8: ProQuest | D8: N/A | E8: N/A | F8: 0 | G8: 0 | H8: N/A
A9: Abstracts in Anthropology | B9: MetaPress | D9: N/A | E9: N/A | F9: N/A | G9: 366.28 | H9: N/A
A10: Academic Search Premier | B10: EBSCOhost | D10: 63572 | E10: 207218 | F10: 0 | G10: 20342.75 | H10: =G10/E10 -> 0.098170767
A11: Alternative Press Index | B11: FirstSearch | D11: N/A | E11: 39 | F11: 0 | G11: 0 | H11: 1
A12: Alternative Press Index Archive | B12: FirstSearch | D12: N/A | E12: 15 | F12: 0 | G12: 0 | H12: 1
A13: America History & Life | B13: EBSCOhost | D13: 1758 | E13: 7433 | F13: 0 | G13: 0 | H13: 1.03
A14: ARBA Online | B14: Greenwood Press | D14: 13 | E14: 2 | F14: 0 | G14: 338 | H14: =G14/E14 -> 169
A15: Art Abstracts | B15: WilsonWeb | C15: Yes (R2) | D15: 627 | E15: 2373 | F15: 0 | G15: 5989.5 | H15: =G15/E15 -> 2.5240202
A16: Art Index Retrospective* | B16: WilsonWeb | C16: Yes (R2) | D16: 140 | E16: 427 | F16: 7 | G16: 581 | H16: =G16/E16 -> 1.3606557
A17: ArticleFirst* | B17: FirstSearch | D17: 1308 | E17: 5490 | F17: 0 | G17: 0 | H17: N/A
A18: ARTstor | B18: ARTstor | D18: 21 | E18: 152 | F18: 0 | G18: 12940 | H18: =G18/E18 -> 85.131579
A19: ASFA 1 | B19: CSA | D19: N/A | E19: 1917 | F19: 0 | G19: 0 | H19: N/A
A20: ASFA 2 | B20: CSA | D20: N/A | E20: 304 | F20: 0 | G20: 0 | H20: N/A
A21: ASFA 3 | B21: CSA | D21: N/A | E21: 1042 | F21: 0 | G21: 0 | H21: N/A
A22: ASFA Aquaculture Abstracts | B22: CSA | D22: N/A | E22: 1051 | F22: 0 | G22: 0 | H22: N/A
A23: ASFA Marine Biotechnology Abstracts | B23: CSA | D23: N/A | E23: 828 | F23: 0 | G23: 0 | H23: N/A
A24: ASFA: Aquatic Science & Fisheries Abstracts | B24: CSA | D24: N/A | E24: N/A | F24: 0 | G24: 8025 | H24: N/A
A25: Bibliography & Index of Micropaleontology | B25: Micropress | D25: N/A | E25: N/A | F25: N/A | G25: 146.04 | H25: N/A
A26: Biological & Agricultural Index Plus | B26: WilsonWeb | C26: Yes (R2) | D26: 370 | E26: 1002 | F26: 0 | G26: 3411 | H26: =G26/E26 -> 3.4041916
A27: Biological Abstracts | B27: WebSPIRS | C27: Yes | D27: 627 | E27: 2485 | F27: 5 | G27: 0 | H27: N/A
A28: Biological Abstracts (2/2009-) | B28: OVID | D28: 277 | E28: 538 | F28: 0 | G28: 0 | H28: N/A
A29: BIOSIS Previews | B29: OVID | D29: 2 | E29: 2 | F29: 0 | G29: 0 | H29: N/A
A30: BIOSIS Previews | B30: Web of Science | C30: Yes | D30: 6 | E30: 8 | F30: 0 | G30: 26110.5 | H30: =G30/E30 -> 3263.8125
A31: ChoiceReviews.online | B31: Choice | D31: N/A | E31: N/A | F31: N/A | G31: 0 | H31: N/A
A32: CIAO | B32: CIAO | D32: 63 | E32: N/A | F32: 0 | G32: 0 | H32: N/A
A33: CINAHL | B33: EBSCOhost | D33: 11985 | E33: 60685 | F33: N/A | G33: 5699 | H33: =G33/E33 -> 0.093911181
A34: Clase and Periodica* | B34: FirstSearch | D34: 111 | E34: 152 | F34: 0 | G34: 0 | H34: N/A
A35: Classification Web* | B35: Library of Congress | D35: N/A | E35: N/A | F35: N/A | G35: 594.69 | H35: N/A
A36: Cochrane Library | B36: Wiley InterScience | D36: 1404 | E36: 416 | F36: 0 | G36: 3042.5 | H36: =G36/E36 -> 7.3137019
A37: Communication Abstracts | B37: CSA | D37: N/A | E37: 6047 | F37: 0 | G37: 3025 | H37: =G37/E37 -> 0.50024806
A38: Compendex | B38: EI | D38: 1471 | E38: 7270 | F38: 0 | G38: 16073 | H38: =G38/E38 -> 2.2108666
A39: CQ Researcher | B39: CQ | C39: No | D39: 579 | E39: 678 | F39: 0 | G39: 1613 | H39: =G39/E39 -> 2.379056
A40: CSA (all databases) | B40: CSA | D40: N/A | E40: 14903 | F40: 0 | G40: 65124 | H40: =G40/E40 -> 4.3698584
A41: Dissertations & Theses | B41: ProQuest | D41: N/A | E41: N/A | F41: 0 | G41: 0 | H41: N/A
...

Sheet ClassificationWeb
A1: ClassificationWeb
A2: 2008-2009
B4: 39630 | C4: 39661 | D4: 39692 | E4: 39722 | F4: 39753 | G4: 39783 | H4: 39814 | I4: 39845 | J4: 39873 | K4: 39904 | L4: 39934 | M4: 39965 | N4: Total | O4: 2008-2009 Price | P4: Price per unit
A5: ClassificationWeb
A6: Sessions (no. days used) | B6: N/A | C6: N/A | D6: N/A | E6: N/A | F6: N/A | G6: N/A | H6: N/A | I6: N/A | J6: N/A | K6: N/A | L6: N/A | M6: N/A | N6: =SUM(B6:M6) -> 0
A7: Maximum users | B7: N/A | C7: N/A | D7: N/A | E7: N/A | F7: N/A | G7: N/A | H7: N/A | I7: N/A | J7: N/A | K7: N/A | L7: N/A | M7: N/A
A8: Total records | B8: N/A | C8: N/A | D8: N/A | E8: N/A | F8: N/A | G8: N/A | H8: N/A | I8: N/A | J8: N/A | K8: N/A | L8: N/A | M8: N/A | N8: =SUM(B8:M8) -> 0 | O8: 594.69
A9: Next/prev records | B9: N/A | C9: N/A | D9: N/A | E9: N/A | F9: N/A | G9: N/A | H9: N/A | I9: N/A | J9: N/A | K9: N/A | L9: N/A | M9: N/A | N9: =SUM(B9:M9) -> 0
A11: COUNTER-Compliant?: | B11: No

Sheet ARTstor
A1: ARTstor
A2: 2008-2009
B4: 39630 | C4: 39661 | D4: 39692 | E4: 39722 | F4: 39753 | G4: 39783 | H4: 39814 | I4: 39845 | J4: 39873 | K4: 39904 | L4: 39934 | M4: 39965 | N4: Total | O4: 2008-2009 Price | P4: Price per access
A5: ARTstor
A6: Events | B6: N/A | C6: N/A | D6: N/A | E6: N/A | F6: N/A | G6: N/A | H6: N/A | I6: N/A | J6: N/A | K6: 92 | L6: 35 | M6: 25 | N6: =SUM(B6:M6) -> 152
A7: Sessions | B7: N/A | C7: N/A | D7: N/A | E7: N/A | F7: N/A | G7: N/A | H7: N/A | I7: N/A | J7: N/A | K7: 10 | L7: 5 | M7: 6 | N7: =SUM(B7:M7) -> 21 | O7: 12940
A8: Users | B8: N/A | C8: N/A | D8: N/A | E8: N/A | F8: N/A | G8: N/A | H8: N/A | I8: N/A | J8: N/A | K8: 6 | L8: 1 | M8: N/A | N8: =SUM(B8:M8) -> 7
A9: Minutes | B9: N/A | C9: N/A | D9: N/A | E9: N/A | F9: N/A | G9: N/A | H9: N/A | I9: N/A | J9: N/A | K9: 4681 | L9: 2078 | M9: N/A | N9: =SUM(B9:M9) -> 6759
A10: Registrations | B10: N/A | C10: N/A | D10: N/A | E10: N/A | F10: N/A | G10: N/A | H10: N/A | I10: N/A | J10: N/A | K10: 5 | L10: 0 | M10: 1 | N10: =SUM(B10:M10) -> 6
A14: Note: We purchased ARTstor in April 2008.
A15: COUNTER-Compliant?: | B15: No
A16: Note: Data through April 2008 is not correct, because ARTstor was not tracking URI IP addresses separately.
A19: Events: | B19: Number of events.
A21: Sessions: | B21: Number of sessions.
A23: Users: | B23: Number of unique users who logged in during the time period. All users who did not log in are counted as one additional users. The numbers of monthly users are not additive, i.e. the sum of monthly users is not equal to the total number of unique users for all time.
A25: Minutes: | B25: Total minutes used by all sessions.
A27: Registrations: | B27: Number of new registrations.

Sheet CIAO
A1: CIAO
A2: 2008-2009
B4: 39630 | C4: 39661 | D4: 39692 | E4: 39722 | F4: 39753 | G4: 39783 | H4: 39814 | I4: 39845 | J4: 39873 | K4: 39904 | L4: 39934 | M4: 39965 | N4: Total | O4: 2008-2009 price | P4: Price per unit
A5: TOTAL
A6: Unique Visitors | B6: 4 | C6: 1 | D6: 6 | E6: 5 | F6: 7 | G6: 7 | H6: 12 | I6: 15 | J6: 11 | K6: 8 | L6: 7 | M6: 3 | N6: =SUM(B6:M6) -> 63
A7: No of Visits | B7: 4 | C7: 1 | D7: 11 | E7: 7 | F7: 8 | G7: 7 | H7: 16 | I7: 22 | J7: 17 | K7: 8 | L7: 16 | M7: 5 | N7: =SUM(B7:M7) -> 91
A8: No of Views | B8: 9 | C8: 2 | D8: 67 | E8: 80 | F8: 19 | G8: 18 | H8: 74 | I8: 63 | J8: 55 | K8: 15 | L8: 20 | M8: 6 | N8: =SUM(B8:M8) -> 251
A9: No of Searches | B9: N/A | C9: N/A | D9: N/A | E9: N/A | F9: N/A | G9: N/A | H9: N/A | I9: N/A | J9: N/A | K9: N/A | L9: N/A | M9: N/A | N9: =SUM(B9:M9) -> 0
A10: Articles Viewed | B10: 7 | C10: 0 | D10: 24 | E10: 39 | F10: 7 | G10: 12 | H10: 34 | I10: 24 | J10: 51 | K10: 12 | L10: 16 | M10: 3 | N10: =SUM(B10:M10) -> 152
A11: Average Visit Duration | B11: 0:8:17 | C11: 0:0:18 | D11: 0:5:41 | E11: 0:10:58 | F11: 0:0:12 | G11: 0.0038888889 | H11: 0:6:55 | I11: 0:1:24 | J11: 0:5:44 | K11: 0:1:55 | L11: 0:1:12 | M11: 0:0:45 | N11: —
A13: Counter-Compliant?: | B13: No
A15: Unique Visitors (compilation) | N15: =SUM(B15:M15) -> 0

Sheet Cochrane
A1: Cochrane Library
A2: 2008-2009
B4: 39630 | C4: 39661 | D4: 39692 | E4: 39722 | F4: 39753 | G4: 39783 | H4: 39814 | I4: 39845 | J4: 39873 | K4: 39904 | L4: 39934 | M4: 39965 | N4: Total | O4: 2008-2009 price | P4: Price per unit
A5: Cochrane Library
A6: Sessions | B6: 51 | C6: 39 | D6: 101 | E6: 179 | F6: 179 | G6: 50 | H6: 53 | I6: 233 | J6: 263 | K6: 157 | L6: 61 | M6: 38 | N6: =SUM(B6:M6) -> 1404
A7: Searches | B7: 8 | C7: 12 | D7: 22 | E7: 31 | F7: 59 | G7: 9 | H7: 8 | I7: 105 | J7: 97 | K7: 31 | L7: 29 | M7: 5 | N7: =SUM(B7:M7) -> 416 | O7: 3042.5
A8: Full-Text Articles Downloaded | B8: 46 | C8: 22 | D8: 77 | E8: 153 | F8: 198 | G8: 48 | H8: 38 | I8: 193 | J8: 182 | K8: 94 | L8: 35 | M8: 24 | N8: =SUM(B8:M8) -> 1110 | O8: 3042.5
A9: Turnaways | B9: 0 | C9: 0 | D9: 0 | E9: 0 | F9: 0 | G9: 0 | H9: 0 | I9: 0 | J9: 0 | K9: 0 | L9: 0 | M9: 0
A12: COUNTER-Compliant?: | B12: Yes

Sheet Compendex(EI)
A1: Compendex (Engineering Index)
A2: 2008-2009
B4: 39630 | C4: 39661 | D4: 39692 | E4: 39722 | F4: 39753 | G4: 39783 | H4: 39814 | I4: 39845 | J4: 39873 | K4: 39904 | L4: 39934 | M4: 39965 | N4: Total | O4: 2008-2009 Price | P4: Price per search
A5: Compendex
A6: Sessions | B6: 111 | C6: 76 | D6: 88 | E6: 497 | F6: 97 | G6: 113 | H6: 72 | I6: 49 | J6: 107 | K6: 143 | L6: 49 | M6: 69 | N6: =SUM(B6:M6) -> 1471
A7: Searches | B7: 363 | C7: 386 | D7: 243 | E7: 3830 | F7: 349 | G7: 302 | H7: 300 | I7: 193 | J7: 365 | K7: 424 | L7: 233 | M7: 282 | N7: =SUM(B7:M7) -> 7270 | O7: 16073
A10: COUNTER-Compliant?: | B10: No

Sheet CQ Researcher
A1: CQ Researcher
A2: 2008-2009
B6: 39630 | C6: 39661 | D6: 39692 | E6: 39722 | F6: 39753 | G6: 39783 | H6: 39814 | I6: 39845 | J6: 39873 | K6: 39904 | L6: 39934 | M6: 39965 | N6: Total | O6: 2008-2009 Price | P6: Price per search
A7: CQ Researcher*
A8: Total sessions | B8: N/A | C8: N/A | D8: N/A | E8: N/A | F8: N/A | G8: N/A | H8: 38 | I8: 91 | J8: 216 | K8: 199 | L8: 4 | M8: 31 | N8: =SUM(B8:M8) -> 579
A9: Average session length | B9: N/A | C9: N/A | D9: N/A | E9: N/A | F9: N/A | G9: N/A | H9: N/A | I9: N/A | J9: N/A | K9: N/A | L9: N/A | M9: N/A | N9: =SUM(B9:M9) -> 0 | O9: 1613
A10: Total session length | B10: N/A | C10: N/A | D10: N/A | E10: N/A | F10: N/A | G10: N/A | H10: N/A | I10: N/A | J10: N/A | K10: N/A | L10: N/A | M10: N/A | N10: =SUM(B10:M10) -> 0
A11: Searches | B11: N/A | C11: N/A | D11: N/A | E11: N/A | F11: N/A | G11: N/A | H11: 48 | I11: 149 | J11: 219 | K11: 217 | L11: 6 | M11: 39 | N11: =SUM(B11:M11) -> 678
A12: Total documents (unique titles) | B12: N/A | C12: N/A | D12: N/A | E12: N/A | F12: N/A | G12: N/A | H12: N/A | I12: N/A | J12: N/A | K12: N/A | L12: N/A | M12: N/A | N12: =SUM(B12:M12) -> 0
A13: Total hits (document views) | B13: N/A | C13: N/A | D13: N/A | E13: N/A | F13: N/A | G13: N/A | H13: N/A | I13: N/A | J13: N/A | K13: N/A | L13: N/A | M13: N/A | N13: =SUM(B13:M13) -> 0
A16: SIMULTANEOUS USERS: | B16: 10
A18: COUNTER-compliant? | B18: No

Sheet Greenwood
A1: Greenwood Press
A2: 2008-2009
B4: 39630 | C4: 39661 | D4: 39692 | E4: 39722 | F4: 39753 | G4: 39783 | H4: 39814 | I4: 39845 | J4: 39873 | K4: 39904 | L4: 39934 | M4: 39965 | N4: Total | O4: 2008-2009 Price | P4: Price per search
A5: ARBA Online
A6: Searches | B6: 0 | C6: 1 | D6: 0 | E6: 0 | F6: 1 | G6: 0 | H6: 0 | I6: 0 | J6: 0 | K6: 0 | L6: 0 | M6: 0 | N6: =SUM(B6:M6) -> 2
A7: Sessions | B7: 2 | C7: 1 | D7: 0 | E7: 4 | F7: 3 | G7: 0 | H7: 1 | I7: 0 | J7: 0 | K7: 2 | L7: 0 | M7: 0 | N7: =SUM(B7:M7) -> 13 | O7: 338
A11: COUNTER-compliant? | B11: Yes

Sheet CSA
A1: CSA Databases
A2: 2008-2009
B4: 39630 | C4: 39661 | D4: 39692 | E4: 39722 | F4: 39753 | G4: 39783 | H4: 39814 | I4: 39845 | J4: 39873 | K4: 39904 | L4: 39934 | M4: 39965 | N4: Total | O4: 2008-2009 Price | P4: Price per search
A5: ASFA (all)
A6: Searches | B6: N/A | C6: N/A | D6: N/A | E6: N/A | F6: N/A | G6: N/A | H6: N/A | I6: N/A | J6: N/A | K6: N/A | L6: N/A | M6: N/A | N6: N/A | O6: 8025
B9: 39630 | C9: 39661 | D9: 39692 | E9: 39722 | F9: 39753 | G9: 39783 | H9: 39814 | I9: 39845 | J9: 39873 | K9: 39904 | L9: 39934 | M9: 39965 | N9: Total | O9: 2008-2009 Price | P9: Price per search
A10: ASFA 1 (Biosciences...)
A11: Searches | B11: 90 | C11: 49 | D11: 259 | E11: 341 | F11: 237 | G11: 185 | H11: 46 | I11: 190 | J11: 164 | K11: 210 | L11: 73 | M11: 73 | N11: =SUM(B11:M11) -> 1917 | O11: 0
B14: 39630 | C14: 39661 | D14: 39692 | E14: 39722 | F14: 39753 | G14: 39783 | H14: 39814 | I14: 39845 | J14: 39873 | K14: 39904 | L14: 39934 | M14: 39965 | N14: Total | O14: 2008-2009 Price | P14: Price per search
A15: ASFA 2 (Ocean Technology…)
A16: Searches | B16: 12 | C16: 64 | D16: 16 | E16: 13 | F16: 12 | G16: 5 | H16: 3 | I16: 69 | J16: 47 | K16: 45 | L16: 4 | M16: 14 | N16: =SUM(B16:M16) -> 304 | O16: 0
B19: 39630 | C19: 39661 | D19: 39692 | E19: 39722 | F19: 39753 | G19: 39783 | H19: 39814 | I19: 39845 | J19: 39873 | K19: 39904 | L19: 39934 | M19: 39965 | N19: Total | O19: 2008-2009 Price | P19: Price per search
A20: ASFA 3 (Aquatic Pollution…)
A21: Searches | B21: 57 | C21: 42 | D21: 122 | E21: 144 | F21: 143 | G21: 85 | H21: 15 | I21: 144 | J21: 63 | K21: 135 | L21: 36 | M21: 56 | N21: =SUM(B21:M21) -> 1042 | O21: 0
B24: 39630 | C24: 39661 | D24: 39692 | E24: 39722 | F24: 39753 | G24: 39783 | H24: 39814 | I24: 39845 | J24: 39873 | K24: 39904 | L24: 39934 | M24: 39965 | N24: Total | O24: 2008-2009 Price | P24: Price per search
A25: ASFA Aquaculture Abstracts
A26: Searches | B26: 56 | C26: 45 | D26: 106 | E26: 147 | F26: 170 | G26: 49 | H26: 13 | I26: 173 | J26: 71 | K26: 113 | L26: 38 | M26: 70 | N26: =SUM(B26:M26) -> 1051 | O26: 0
B29: 39630 | C29: 39661 | D29: 39692 | E29: 39722 | F29: 39753 | G29: 39783 | H29: 39814 | I29: 39845 | J29: 39873 | K29: 39904 | L29: 39934 | M29: 39965 | N29: Total | O29: 2008-2009 Price | P29: Price per search
A30: ASFA Marine Biotechnology Abstracts
A31: Searches | B31: 57 | C31: 39 | D31: 91 | E31: 92 | F31: 121 | G31: 45 | H31: 14 | I31: 119 | J31: 52 | K31: 101 | L31: 36 | M31: 61 | N31: =SUM(B31:M31) -> 828 | O31: 0
B34: 39630 | C34: 39661 | D34: 39692 | E34: 39722 | F34: 39753 | G34: 39783 | H34: 39814 | I34: 39845 | J34: 39873 | K34: 39904 | L34: 39934 | M34: 39965 | N34: Total | O34: 2008-2009 Price | P34: Price per search
A35: ComDisDome
A36: Searches | B36: 165 | C36: 107 | D36: 279 | E36: 416 | F36: 535 | G36: 145 | H36: 104 | I36: 338 | J36: 384 | K36: 324 | L36: 153 | M36: 165 | N36: =SUM(B36:M36) -> 3115
B39: 39630 | C39: 39661 | D39: 39692 | E39: 39722 | F39: 39753 | G39: 39783 | H39: 39814 | I39: 39845 | J39: 39873 | K39: 39904 | L39: 39934 | M39: 39965 | N39: Total | O39: 2008-2009 Price | P39: Price per search
A40: Communication Abstracts
A41: Searches | B41: 363 | C41: 65 | D41: 433 | E41: 532 | F41: 1229 | G41: 676 | H41: 201 | I41: 608 | J41: 602 | K41: 809 | L41: 370 | M41: 159 | N41: =SUM(B41:M41) -> 6047 | O41: 3025
B44: 39630 | C44: 39661 | D44: 39692 | E44: 39722 | F44: 39753 | G44: 39783 | H44: 39814 | I44: 39845 | J44: 39873 | K44: 39904 | L44: 39934 | M44: 39965 | N44: Total | O44: 2008-2009 Price | P44: Price per search
A45: EconLit
A46: Searches | B46: 12 | C46: 0 | D46: 0 | E46: 0 | F46: 0 | G46: 0 | H46: N/A | I46: N/A | J46: N/A | K46: N/A | L46: N/A | M46: N/A | N46: =SUM(B46:M46) -> 12 | O46: 3161
A47: Note: EconLit has switched to EBSCOhost for 08/09
B49: 39630 | C49: 39661 | D49: 39692 | E49: 39722 | F49: 39753 | G49: 39783 | H49: 39814 | I49: 39845 | J49: 39873 | K49: 39904 | L49: 39934 | M49: 39965 | N49: Total | O49: 2008-2009 Price | P49: Price per search
A50: ERIC (free)
A51: Searches | B51: 194 | C51: 102 | D51: 357 | E51: 590 | F51: 441 | G51: 146 | H51: 92 | I51: 415 | J51: 430 | K51: 357 | L51: 121 | M51: 175 | N51: =SUM(B51:M51) -> 3420 | O51: 0
B54: 39630 | C54: 39661 | D54: 39692 | E54: 39722 | F54: 39753 | G54: 39783 | H54: 39814 | I54: 39845 | J54: 39873 | K54: 39904 | L54: 39934 | M54: 39965 | N54: Total | O54: 2008-2009 Price | P54: Price per search
A55: GeoRef
A56: Searches | B56: 103 | C56: 140 | D56: 267 | E56: 242 | F56: 310 | G56: 78 | H56: 98 | I56: 258 | J56: 151 | K56: 259 | L56: 107 | M56: 143 | N56: =SUM(B56:M56) -> 2156 | O56: 6142
B59: 39630 | C59: 39661 | D59: 39692 | E59: 39722 | F59: 39753 | G59: 39783 | H59: 39814 | I59: 39845 | J59: 39873 | K59: 39904 | L59: 39934 | M59: 39965 | N59: Total | O59: 2008-2009 Price | P59: Price per search
A60: GeoRef in Process
A61: Searches | B61: 57 | C61: 101 | D61: 83 | E61: 68 | F61: 110 | G61: 41 | H61: 14 | I61: 116 | J61: 39 | K61: 92 | L61: 37 | M61: 61 | N61: =SUM(B61:M61) -> 819 | O61: 0
B64: 39630 | C64: 39661 | D64: 39692 | E64: 39722 | F64: 39753 | G64: 39783 | H64: 39814 | I64: 39845 | J64: 39873 | K64: 39904 | L64: 39934 | M64: 39965 | N64: Total | O64: 2008-2009 Price | P64: Price per search
...

Sheet EBSCOhost
A1: EBSCOhost Databases
A2: 2008-2009
B4: 39630 | C4: 39661 | D4: 39692 | E4: 39722 | F4: 39753 | G4: 39783 | H4: 39814 | I4: 39845 | J4: 39873 | K4: 39904 | L4: 39934 | M4: 39965 | N4: Total | O4: 2008-2009 Price | P4: Price per search
A5: Academic Search Complete (statewide database trial)
A6: Sessions | B6: 0 | C6: 0 | D6: 0 | E6: 1315 | F6: 1868 | G6: 980 | H6: 593 | I6: 1491 | J6: 2019 | K6: 5203 | L6: 1406 | M6: 1369 | N6: =SUM(B6:M6) -> 16244
A7: Searches | B7: 0 | C7: 0 | D7: 0 | E7: 1727 | F7: 2533 | G7: 1912 | H7: 1017 | I7: 1686 | J7: 2919 | K7: 16227 | L7: 5528 | M7: 4548 | N7: =SUM(B7:M7) -> 38097 | O7: 0
B10: 39630 | C10: 39661 | D10: 39692 | E10: 39722 | F10: 39753 | G10: 39783 | H10: 39814 | I10: 39845 | J10: 39873 | K10: 39904 | L10: 39934 | M10: 39965 | N10: Total | O10: 2008-2009 Price | P10: Price per search
A11: Academic Search Premier
A12: Sessions | B12: 4100 | C12: 1387 | D12: 5073 | E12: 10620 | F12: 9378 | G12: 4833 | H12: 1382 | I12: 6534 | J12: 9826 | K12: 7458 | L12: 1478 | M12: 1503 | N12: =SUM(B12:M12) -> 63572
A13: Searches | B13: 11521 | C13: 2352 | D13: 15524 | E13: 42240 | F13: 31101 | G13: 16152 | H13: 2503 | I13: 21860 | J13: 36352 | K13: 20261 | L13: 3221 | M13: 4131 | N13: =SUM(B13:M13) -> 207218 | O13: 20342.75
B16: 39630 | C16: 39661 | D16: 39692 | E16: 39722 | F16: 39753 | G16: 39783 | H16: 39814 | I16: 39845 | J16: 39873 | K16: 39904 | L16: 39934 | M16: 39965 | N16: Total | O16: 2008-2009 Price | P16: Price per search
A17: America History & Life
A18: Sessions | B18: 60 | C18: 18 | D18: 137 | E18: 265 | F18: 261 | G18: 120 | H18: 71 | I18: 223 | J18: 208 | K18: 263 | L18: 69 | M18: 63 | N18: =SUM(B18:M18) -> 1758
A19: Searches | B19: 219 | C19: 67 | D19: 510 | E19: 1095 | F19: 1000 | G19: 413 | H19: 256 | I19: 877 | J19: 863 | K19: 1316 | L19: 431 | M19: 386 | N19: =SUM(B19:M19) -> 7433
A20: Simultaneous users | B20: 2 to 6 | C20: 2 to 6 | D20: 2 to 6 | E20: 2 to 6 | F20: 2 to 6 | G20: 2 to 6 | H20: 2 to 6 | I20: 2 to 6 | J20: 2 to 6 | K20: 2 to 6 | L20: 2 to 6 | M20: 2 to 6
A21: Turnaways? | B21: 0 | C21: 0 | D21: 0 | E21: 0 | F21: 0 | G21: 0 | H21: 0 | I21: 0 | J21: 0 | K21: 0 | L21: 0 | M21: 0
B24: 39630 | C24: 39661 | D24: 39692 | E24: 39722 | F24: 39753 | G24: 39783 | H24: 39814 | I24: 39845 | J24: 39873 | K24: 39904 | L24: 39934 | M24: 39965 | N24: Total | O24: 2008-2009 Price | P24: Price per search
A25: CINAHL
A26: Sessions | B26: 596 | C26: 94 | D26: 879 | E26: 1513 | F26: 1672 | G26: 547 | H26: 277 | I26: 1569 | J26: 1897 | K26: 2316 | L26: 325 | M26: 300 | N26: =SUM(B26:M26) -> 11985
A27: Searches | B27: 2482 | C27: 303 | D27: 4014 | E27: 7263 | F27: 9166 | G27: 2786 | H27: 1009 | I27: 8028 | J27: 9342 | K27: 12946 | L27: 1530 | M27: 1816 | N27: =SUM(B27:M27) -> 60685 | O27: 5533
B30: 39630 | C30: 39661 | D30: 39692 | E30: 39722 | F30: 39753 | G30: 39783 | H30: 39814 | I30: 39845 | J30: 39873 | K30: 39904 | L30: 39934 | M30: 39965 | N30: Total | O30: 2008-2009 Price | P30: Price per search
A31: EBSCO Animals (free)
A32: Sessions | B32: N/A | C32: N/A | D32: N/A | E32: N/A | F32: N/A | G32: N/A | H32: N/A | I32: N/A | J32: N/A | K32: N/A | L32: N/A | M32: N/A | N32: =SUM(B32:M32) -> 0
A33: Searches | B33: N/A | C33: N/A | D33: N/A | E33: N/A | F33: N/A | G33: N/A | H33: N/A | I33: N/A | J33: N/A | K33: N/A | L33: N/A | M33: N/A | N33: =SUM(B33:M33) -> 0 | O33: 0
B36: 39630 | C36: 39661 | D36: 39692 | E36: 39722 | F36: 39753 | G36: 39783 | H36: 39814 | I36: 39845 | J36: 39873 | K36: 39904 | L36: 39934 | M36: 39965 | N36: Total | O36: 2008-2009 Price | P36: Price per search
A37: EconLit
A38: Sessions | B38: 50 | C38: 45 | D38: 168 | E38: 261 | F38: 248 | G38: 152 | H38: 51 | I38: 174 | J38: 246 | K38: 259 | L38: 79 | M38: 116 | N38: =SUM(B38:M38) -> 1849
A39: Searches | B39: 192 | C39: 173 | D39: 672 | E39: 987 | F39: 966 | G39: 568 | H39: 244 | I39: 621 | J39: 1115 | K39: 1170 | L39: 413 | M39: 463 | N39: =SUM(B39:M39) -> 7584 | O39: 3161
B42: 39630 | C42: 39661 | D42: 39692 | E42: 39722 | F42: 39753 | G42: 39783 | H42: 39814 | I42: 39845 | J42: 39873 | K42: 39904 | L42: 39934 | M42: 39965 | N42: Total | O42: 2008-2009 Price | P42: Price per search
A43: ERIC (free)
A44: Sessions | B44: 16 | C44: 3 | D44: 13 | E44: 123 | F44: 169 | G44: 86 | H44: 26 | I44: 82 | J44: 160 | K44: 186 | L44: 56 | M44: 59 | N44: =SUM(B44:M44) -> 979
A45: Searches | B45: 91 | C45: 10 | D45: 73 | E45: 574 | F45: 710 | G45: 337 | H45: 127 | I45: 342 | J45: 855 | K45: 1055 | L45: 404 | M45: 378 | N45: =SUM(B45:M45) -> 4956 | O45: 0
B48: 39630 | C48: 39661 | D48: 39692 | E48: 39722 | F48: 39753 | G48: 39783 | H48: 39814 | I48: 39845 | J48: 39873 | K48: 39904 | L48: 39934 | M48: 39965 | N48: Total | O48: 2008-2009 Price | P48: Price per search
A49: Film & Television Literature Index
A50: Sessions | B50: 19 | C50: 9 | D50: 57 | E50: 170 | F50: 156 | G50: 137 | H50: 24 | I50: 67 | J50: 148 | K50: 209 | L50: 85 | M50: 52 | N50: =SUM(B50:M50) -> 1133
A51: Searches | B51: 69 | C51: 24 | D51: 269 | E51: 720 | F51: 652 | G51: 442 | H51: 114 | I51: 275 | J51: 662 | K51: 969 | L51: 459 | M51: 294 | N51: =SUM(B51:M51) -> 4949 | O51: 1363
B54: 39630 | C54: 39661 | D54: 39692 | E54: 39722 | F54: 39753 | G54: 39783 | H54: 39814 | I54: 39845 | J54: 39873 | K54: 39904 | L54: 39934 | M54: 39965 | N54: Total | O54: 2008-2009 Price | P54: Price per search
A55: Funk & Wagnall's New World Encyclopedia (free)
A56: Sessions | B56: 18 | C56: 7 | D56: 58 | E56: 128 | F56: 158 | G56: 89 | H56: 23 | I56: 113 | J56: 142 | K56: 167 | L56: 68 | M56: 54 | N56: =SUM(B56:M56) -> 1025
A57: Searches | B57: 71 | C57: 22 | D57: 260 | E57: 478 | F57: 597 | G57: 301 | H57: 114 | I57: 380 | J57: 618 | K57: 772 | L57: 388 | M57: 290 | N57: =SUM(B57:M57) -> 4291 | O57: 0
...

Sheet Elsevier
A1: Elsevier
A2: 2008-2009
B4: 39630 | C4: 39661 | D4: 39692 | E4: 39722 | F4: 39753 | G4: 39783 | H4: 39814 | I4: 39845 | J4: 39873 | K4: 39904 | L4: 39934 | M4: 39965 | N4: Total | O4: 2008-2009 Price | P4: Price per unit
A5: EMBASE.com
A6: Sessions | B6: 45 | C6: N/A | D6: NA/ | E6: N/A | F6: N/A | G6: N/A | H6: N/A | I6: N/A | J6: N/A | K6: N/A | L6: N/A | M6: N/A | N6: =SUM(B6:M6) -> 45
A7: Searches | B7: 104 | C7: N/A | D7: N/A | E7: N/A | F7: N/A | G7: N/A | H7: N/A | I7: N/A | J7: N/A | K7: N/A | L7: N/A | M7: N/A | N7: =SUM(B7:M7) -> 104 | O7: 10260
A9: Encyclopedia of Ocean Science
A10: Requests for full text chapters | B10: N/A | C10: N/A | D10: N/A | E10: N/A | F10: N/A | G10: N/A | H10: N/A | I10: N/A | J10: N/A | K10: N/A | L10: 5 | M10: N/A | N10: =SUM(B10:M10) -> 5 | O10: 727.65
A13: COUNTER-Compliant?: | B13: No

Sheet FirstSearch
A1: FirstSearch
A2: 2008-2009
B4: 39630 | C4: 39661 | D4: 39692 | E4: 39722 | F4: 39753 | G4: 39783 | H4: 39814 | I4: 39845 | J4: 39873 | K4: 39904 | L4: 39934 | M4: 39965 | N4: Total | O4: 2008-2009 Price | P4: Price per search
A5: Alternative Press Index
A6: Searches | B6: 0 | C6: 0 | D6: 0 | E6: 4 | F6: 1 | G6: 6 | H6: 7 | I6: 12 | J6: 3 | K6: 1 | L6: 0 | M6: 5 | N6: =SUM(B6:M6) -> 39
B9: 39630 | C9: 39661 | D9: 39692 | E9: 39722 | F9: 39753 | G9: 39783 | H9: 39814 | I9: 39845 | J9: 39873 | K9: 39904 | L9: 39934 | M9: 39965 | N9: Total | O9: 2008-2009 Price | P9: Price per search
A10: Alternative Press Index Archive
A11: Searches | B11: 0 | C11: 0 | D11: 0 | E11: 0 | F11: 0 | G11: 2 | H11: 10 | I11: 0 | J11: 0 | K11: 1 | L11: 0 | M11: 2 | N11: =SUM(B11:M11) -> 15
B14: 39630 | C14: 39661 | D14: 39692 | E14: 39722 | F14: 39753 | G14: 39783 | H14: 39814 | I14: 39845 | J14: 39873 | K14: 39904 | L14: 39934 | M14: 39965 | N14: Total | O14: 2008-2009 Price | P14: Price per search
A15: ArticleFirst
A16: Sessions | B16: 101 | C16: 33 | D16: 115 | E16: 218 | F16: 180 | G16: 113 | H16: 33 | I16: 146 | J16: 159 | K16: 114 | L16: 51 | M16: 45 | N16: =SUM(B16:M16) -> 1308
A17: Searches | B17: 497 | C17: 493 | D17: 644 | E17: 696 | F17: 422 | G17: 155 | H17: 295 | I17: 519 | J17: 578 | K17: 501 | L17: 163 | M17: 527 | N17: =SUM(B17:M17) -> 5490 | O17: 0 | P17: N/A
A18: User Limit | B18: 2 | C18: 2 | D18: 2 | E18: 2 | F18: 2 | G18: 2 | H18: 2 | I18: 2 | J18: 2 | K18: 2 | L18: 2 | M18: 2
A19: Turnaways | B19: 2 | C19: 2 | D19: 0 | E19: 8 | F19: 0 | G19: 8 | H19: 0 | I19: 5 | J19: 6 | K19: 2 | L19: 0 | M19: 1 | N19: =SUM(B19:M19) -> 34
B22: 39630 | C22: 39661 | D22: 39692 | E22: 39722 | F22: 39753 | G22: 39783 | H22: 39814 | I22: 39845 | J22: 39873 | K22: 39904 | L22: 39934 | M22: 39965 | N22: Total | O22: 2008-2009 Price | P22: Price per search
A23: Clase and Periodica
A24: Sessions | B24: 0 | C24: 0 | D24: 0 | E24: 18 | F24: 11 | G24: 21 | H24: 4 | I24: 20 | J24: 12 | K24: 18 | L24: 5 | M24: 2 | N24: =SUM(B24:M24) -> 111
A25: Searches | B25: 0 | C25: 0 | D25: 0 | E25: 28 | F25: 7 | G25: 34 | H25: 6 | I25: 34 | J25: 15 | K25: 20 | L25: 6 | M25: 2 | N25: =SUM(B25:M25) -> 152 | O25: 0 | P25: N/A
A26: User Limit | B26: 2 | C26: 2 | D26: 2 | E26: 2 | F26: 2 | G26: 2 | H26: 0 | I26: 2 | J26: 2 | K26: 2 | L26: 2 | M26: 2
A27: Turnaways | B27: 0 | C27: 0 | D27: 0 | E27: 0 | F27: 2 | G27: 0 | H27: 1 | I27: 0 | J27: 1 | K27: 0 | L27: 0 | M27: 0 | N27: =SUM(B27:M27) -> 4
B30: 39630 | C30: 39661 | D30: 39692 | E30: 39722 | F30: 39753 | G30: 39783 | H30: 39814 | I30: 39845 | J30: 39873 | K30: 39904 | L30: 39934 | M30: 39965 | N30: Total | O30: 2008-2009 Price | P30: Price per search
A31: ERIC (free)
A32: Sessions | B32: 75 | C32: 15 | D32: 87 | E32: 180 | F32: 55 | G32: 45 | H32: 36 | I32: 75 | J32: 67 | K32: 69 | L32: 21 | M32: 68 | N32: =SUM(B32:M32) -> 793
A33: Searches | B33: 172 | C33: 39 | D33: 194 | E33: 458 | F33: 92 | G33: 91 | H33: 68 | I33: 132 | J33: 114 | K33: 115 | L33: 36 | M33: 139 | N33: =SUM(B33:M33) -> 1650 | O33: 0 | P33: N/A
A34: User Limit | B34: 2 | C34: 2 | D34: 2 | E34: 2 | F34: 2 | G34: 2 | H34: 2 | I34: 2 | J34: 2 | K34: 2 | L34: 2 | M34: 2
A35: Turnaways | B35: 0 | C35: 0 | D35: 3 | E35: 21 | F35: 0 | G35: 0 | H35: 0 | I35: 7 | J35: 6 | K35: 0 | L35: 2 | M35: 0 | N35: =SUM(B35:M35) -> 39
B38: 39630 | C38: 39661 | D38: 39692 | E38: 39722 | F38: 39753 | G38: 39783 | H38: 39814 | I38: 39845 | J38: 39873 | K38: 39904 | L38: 39934 | M38: 39965 | N38: Total | O38: 2008-2009 Price | P38: Price per search
A39: GEOBASE
A40: Searches | B40: 0 | C40: 3 | D40: 0 | E40: 0 | F40: 15 | G40: 7 | H40: 0 | I40: 2 | J40: 0 | K40: 7 | L40: 0 | M40: 0 | N40: =SUM(B40:M40) -> 34 | O40: 0
B43: 39630 | C43: 39661 | D43: 39692 | E43: 39722 | F43: 39753 | G43: 39783 | H43: 39814 | I43: 39845 | J43: 39873 | K43: 39904 | L43: 39934 | M43: 39965 | N43: Total | O43: 2008-2009 Price | P43: Price per search
A44: GPO Monthly Catalog
A45: Sessions | B45: 9 | C45: 2 | D45: 10 | E45: 23 | F45: 9 | G45: 6 | H45: 0 | I45: 8 | J45: 12 | K45: 14 | L45: 3 | M45: 2 | N45: =SUM(B45:M45) -> 98
A46: Searches | B46: 12 | C46: 3 | D46: 19 | E46: 34 | F46: 12 | G46: 9 | H46: 0 | I46: 12 | J46: 14 | K46: 21 | L46: 5 | M46: 3 | N46: =SUM(B46:M46) -> 144 | O46: 0 | P46: N/A
A47: User Limit | B47: 2 | C47: 2 | D47: 2 | E47: 2 | F47: 2 | G47: 2 | H47: 2 | I47: 2 | J47: 2 | K47: 2 | L47: 2 | M47: 2
A48: Turnaways | B48: 0 | C48: 0 | D48: 0 | E48: 0 | F48: 0 | G48: 0 | H48: 0 | I48: 0 | J48: 0 | K48: 0 | L48: 0 | M48: 0 | N48: =SUM(B48:M48) -> 0
B51: 39630 | C51: 39661 | D51: 39692 | E51: 39722 | F51: 39753 | G51: 39783 | H51: 39814 | I51: 39845 | J51: 39873 | K51: 39904 | L51: 39934 | M51: 39965 | N51: Total | O51: 2008-2009 Price | P51: Price per search
A52: MEDLINE (free)
A53: Sessions | B53: 271 | C53: 124 | D53: 305 | E53: 447 | F53: 402 | G53: 164 | H53: 132 | I53: 366 | J53: 398 | K53: 410 | L53: 101 | M53: 111 | N53: =SUM(B53:M53) -> 3231
A54: Searches | B54: 703 | C54: 566 | D54: 817 | E54: 1072 | F54: 917 | G54: 462 | H54: 394 | I54: 803 | J54: 1120 | K54: 831 | L54: 163 | M54: 307 | N54: =SUM(B54:M54) -> 8155 | O54: 0 | P54: N/A
A55: User Limit | B55: 2 | C55: 2 | D55: 2 | E55: 2 | F55: 2 | G55: 2 | H55: 2 | I55: 2 | J55: 2 | K55: 2 | L55: 2 | M55: 2
...

Sheet FSTA
A1: FSTA Direct (IFIS)
A2: 2008-2009
B4: 39630 | C4: 39661 | D4: 39692 | E4: 39722 | F4: 39753 | G4: 39783 | H4: 39814 | I4: 39845 | J4: 39873 | K4: 39904 | L4: 39934 | M4: 39965 | N4: Total | O4: 2008-2009 Price | P4: Price per unit
A5: FSTA Direct
A6: Abstracts viewed | B6: N/A | C6: N/A | D6: N/A | E6: N/A | F6: N/A | G6: N/A | H6: N/A | I6: N/A | J6: N/A | K6: N/A | L6: N/A | M6: N/A | N6: =SUM(B6:M6) -> 0
A9: COUNTER-Compliant?: | B9: No

Sheet InfoTrac
A1: InfoTRAC
A2: 2008-2009
B4: 39630 | C4: 39661 | D4: 39692 | E4: 39722 | F4: 39753 | G4: 39783 | H4: 39814 | I4: 39845 | J4: 39873 | K4: 39904 | L4: 39934 | M4: 39965 | N4: Total | O4: 2008-2009 Price | P4: Price per unit
A5: Literature Resource Center
A6: Sessions | B6: N/A | C6: N/A | D6: N/A | E6: N/A | F6: N/A | G6: N/A | H6: 101 | I6: 256 | J6: 527 | K6: 725 | L6: 441 | N6: =SUM(B6:M6) -> 2050
A7: Searches | B7: N/A | C7: N/A | D7: N/A | E7: N/A | F7: N/A | G7: N/A | H7: 585 | I7: 1245 | J7: 3185 | K7: 1618 | L7: 665 | N7: =SUM(B7:M7) -> 7298 | O7: 1874
A8: Turnaways | B8: N/A | C8: N/A | D8: N/A | E8: N/A | F8: N/A | G8: N/A | H8: 0 | I8: 0 | J8: 0 | K8: 0 | L8: 0 | N8: =SUM(B8:M8) -> 0
A9: Successful Full-Text Article Requests | B9: N/A | C9: N/A | D9: N/A | E9: N/A | F9: N/A | G9: N/A | H9: 249 | I9: 230 | J9: 794 | K9: 845 | L9: 613 | N9: =SUM(B9:M9) -> 2731 | O9: 1874
A12: COUNTER-Compliant?: | B12: Yes

Sheet KCDL
A1: KCDL Online
A2: 2008-2009
B4: 39630 | C4: 39661 | D4: 39692 | E4: 39722 | F4: 39753 | G4: 39783 | H4: 39814 | I4: 39845 | J4: 39873 | K4: 39904 | L4: 39934 | M4: 39965 | N4: Total | O4: 2008-2009 Price | P4: Price per unit
A5: KCDL Online
A6: Searches | B6: 10 | C6: 1 | D6: 96 | E6: 252 | F6: 20 | G6: 1 | H6: 8 | I6: 87 | J6: 14 | K6: 2 | L6: 1 | M6: 14 | N6: =SUM(B6:M6) -> 506 | O6: =3515/2 -> 1757.5
A7: Web Pages Delivered | B7: 30 | C7: 2 | D7: 207 | E7: 645 | F7: 57 | G7: 2 | H7: 13 | I7: 213 | J7: 37 | K7: 6 | L7: 3 | M7: 40 | N7: =SUM(B7:M7) -> 1255
A9: COUNTER-Compliant? | B9: No
A98: COUNTER com

Sheet Lexi-Comp
A1: Lexi-Comp
A2: 2008-2009
B4: 39630 | C4: 39661 | D4: 39692 | E4: 39722 | F4: 39753 | G4: 39783 | H4: 39814 | I4: 39845 | J4: 39873 | K4: 39904 | L4: 39934 | M4: 39965 | N4: Total | O4: 2008-2009 Price | P4: Price per unit
A5: Lexi-Comp Online
A6: Logins | B6: 150 | C6: 27 | D6: 80 | E6: 77 | F6: 153 | G6: 44 | H6: 201 | I6: 175 | J6: 407 | K6: 165 | L6: 61 | M6: 82 | N6: =SUM(B6:M6) -> 1622 | O6: 0
A7: Searches | B7: 274 | C7: 109 | D7: 428 | E7: 457 | F7: 497 | G7: 330 | H7: 770 | I7: 678 | J7: 1403 | K7: 651 | L7: 567 | M7: 964 | N7: =SUM(B7:M7) -> 7128 | O7: 0
A8: Documents Retrieved | B8: 381 | C8: 138 | D8: 533 | E8: 616 | F8: 872 | G8: 403 | H8: 934 | I8: 822 | J8: 1653 | K8: 869 | L8: 632 | M8: 1385 | N8: =SUM(B8:M8) -> 9238 | O8: 0
A11: COUNTER-Compliant?: | B11: No
A14: Stats are e-mailed monthly from tiffany.cobb@lexi.com to andree@uri.edu

Sheet LexisNexis
A1: LexisNexis
A2: 2008-2009
B4: 39630 | C4: 39661 | D4: 39692 | E4: 39722 | F4: 39753 | G4: 39783 | H4: 39814 | I4: 39845 | J4: 39873 | K4: 39904 | L4: 39934 | M4: 39965 | N4: Total | O4: 2008-2009 Price | P4: Price per unit
A5: Academic
A6: Sessions | B6: N/A | C6: N/A | D6: N/A | E6: N/A | F6: N/A | G6: 452 | H6: 802 | I6: 3478 | J6: 5889 | K6: 5764 | L6: 1220 | M6: 971 | N6: =SUM(B6:M6) -> 18576
A7: Searches | B7: 1304 | C7: 533 | D7: 2429 | E7: 4756 | F7: 3962 | G7: 2391 | H7: 624 | I7: 2418 | J7: 4091 | K7: 3839 | L7: 882 | M7: 563 | N7: =SUM(B7:M7) -> 27792 | O7: 22063.1
A9: Congressional
A10: Sessions | B10: N/A | C10: N/A | D10: N/A | E10: N/A | F10: N/A | G10: 2 | H10: 7 | I10: 43 | J10: 125 | K10: 42 | L10: 28 | M10: 13 | N10: =SUM(B10:M10) -> 260
A11: Searches | B11: 12 | C11: 5 | D11: 78 | E11: 167 | F11: 66 | G11: 29 | H11: 18 | I11: 108 | J11: 0 | K11: 78 | L11: 80 | M11: 46 | N11: =SUM(B11:M11) -> 687 | O11: 7446.6
A15: COUNTER-Compliant?: | B15: Yes (R3)
A17: Updated 5/18/10 ajr

Sheet MathSciNet
A1: MathSciNet
A2: 2008-2009
B4: 39630 | C4: 39661 | D4: 39692 | E4: 39722 | F4: 39753 | G4: 39783 | H4: 39814 | I4: 39845 | J4: 39873 | K4: 39904 | L4: 39934 | M4: 39965 | N4: Total | O4: 2008-2009 Price | P4: Price per search
A5: MathSciNet
A6: Sessions | B6: 317 | C6: 105 | D6: 393 | E6: 311 | F6: 837 | G6: 659 | H6: 563 | I6: 747 | J6: 695 | K6: 987 | L6: 791 | M6: 735 | N6: =SUM(B6:M6) -> 7140
A7: Searches | B7: 380 | C7: 204 | D7: 609 | E7: 532 | F7: 968 | G7: 868 | H7: 731 | I7: 1076 | J7: 850 | K7: 1226 | L7: 920 | M7: 952 | N7: =SUM(B7:M7) -> 9316 | O7: 7567.5
A10: COUNTER-Compliant?: | B10: No

Sheet Mergent
A1: Mergent
A2: 2008-2009
B4: 39630 | C4: 39661 | D4: 39692 | E4: 39722 | F4: 39753 | G4: 39783 | H4: 39814 | I4: 39845 | J4: 39873 | K4: 39904 | L4: 39934 | M4: 39965 | N4: Total | O4: 2008-2009 Price | P4: Price per unit
A5: MergentOnline
A6: Logins | B6: 10 | C6: 1 | D6: 101 | E6: 148 | F6: 487 | G6: 124 | H6: 17 | I6: 57 | J6: 40 | K6: 190 | L6: 9 | M6: 10 | N6: =SUM(B6:M6) -> 1194
A7: Searches | B7: 20 | C7: 0 | D7: 401 | E7: 495 | F7: 1717 | G7: 700 | H7: 326 | I7: 258 | J7: 132 | K7: 347 | L7: 11 | M7: 32 | N7: =SUM(B7:M7) -> 4439 | O7: 13750
A8: Companies Viewed | B8: 7 | C8: 0 | D8: 250 | E8: 174 | F8: 678 | G8: 410 | H8: 130 | I8: 158 | J8: 109 | K8: 1279 | L8: 1 | M8: 7 | N8: =SUM(B8:M8) -> 3203
A11: COUNTER-Compliant?: | B11: No

Sheet MetaPress
A1: MetaPress
A2: 2008-2009
B4: 39630 | C4: 39661 | D4: 39692 | E4: 39722 | F4: 39753 | G4: 39783 | H4: 39814 | I4: 39845 | J4: 39873 | K4: 39904 | L4: 39934 | M4: 39965 | N4: Total | O4: 2008-2009 Price | P4: Price per search
A5: Abstracts in Anthropology
A6: Number of Successful Article Requests | B6: 0 | C6: 0 | D6: 0 | E6: 0 | F6: 0 | G6: 0 | H6: 0 | I6: 0 | J6: 0 | K6: 0 | L6: 0 | N6: =SUM(B6:M6) -> 0 | O6: 366.28
A8: Note: This subscription allows users to search a database, yet MetaPress usage statistics only measure "article requests," not searches.
A9: Thus these numbers mean nothing. They do NOT mean that the resource was not used.
A11: COUNTER-Compliant?: | B11: Yes

Sheet netLibrary
A1: NetLibrary
A2: 2008-2009
B4: 39630 | C4: 39661 | D4: 39692 | E4: 39722 | F4: 39753 | G4: 39783 | H4: 39814 | I4: 39845 | J4: 39873 | K4: 39904 | L4: 39934 | M4: 39965 | N4: Total | O4: 2008-2009 Price | P4: Price per access
A5: NetLibrary
A6: Accesses | B6: 59 | C6: 16 | D6: 79 | E6: 153 | F6: 55 | G6: 51 | H6: 18 | I6: 31 | J6: 40 | K6: 41 | L6: 48 | M6: 66 | N6: =SUM(B6:M6) -> 657 | O6: 0
A7: Turnaways | B7: 12 | C7: 0 | D7: 14 | E7: 107 | F7: 9 | G7: 20 | H7: 0 | I7: 16 | J7: 0 | K7: 0 | L7: 7 | M7: 40 | N7: =SUM(B7:M7) -> 225
A10: Note: We have 4,478 shared titles
A11: COUNTER-Compliant?: | B11: No

Sheet Newsbank
A1: Newsbank (Readex)
A2: 2008-2009
B4: 39630 | C4: 39661 | D4: 39692 | E4: 39722 | F4: 39753 | G4: 39783 | H4: 39814 | I4: 39845 | J4: 39873 | K4: 39904 | L4: 39934 | M4: 39965 | N4: Total | O4: 2008-2009 Price | P4: Price per access
A5: Serial Set Maps
A6: Searches | B6: N/A | C6: N/A | D6: N/A | E6: N/A | F6: N/A | G6: N/A | H6: N/A | I6: N/A | J6: N/A | K6: N/A | L6: N/A | M6: N/A | N6: =SUM(B6:M6) -> 0 | O6: N/A
A7: Sessions | B7: N/A | C7: N/A | D7: N/A | E7: N/A | F7: N/A | G7: N/A | H7: N/A | I7: N/A | J7: N/A | K7: N/A | L7: N/A | M7: N/A | N7: =SUM(B7:M7) -> 0 | O7: N/A
B10: 39630 | C10: 39661 | D10: 39692 | E10: 39722 | F10: 39753 | G10: 39783 | H10: 39814 | I10: 39845 | J10: 39873 | K10: 39904 | L10: 39934 | M10: 39965 | N10: Total | O10: 2008-2009 Price | P10: Price per access
A11: Full-text downloads | B11: N/A | C11: N/A | D11: N/A | E11: N/A | F11: N/A | G11: N/A | H11: N/A | I11: N/A | J11: N/A | K11: N/A | L11: N/A | M11: N/A | N11: =SUM(B11:M11) -> 0
B14: 39630 | C14: 39661 | D14: 39692 | E14: 39722 | F14: 39753 | G14: 39783 | H14: 39814 | I14: 39845 | J14: 39873 | K14: 39904 | L14: 39934 | M14: 39965 | N14: Total | O14: 2008-2009 Price | P14: Price per access
A15: All databases
A16: Searches | B16: N/A | C16: N/A | D16: N/A | E16: N/A | F16: N/A | G16: N/A | H16: N/A | I16: N/A | J16: N/A | K16: N/A | L16: N/A | M16: N/A | N16: =SUM(B16:M16) -> 0
A17: Sessions | B17: N/A | C17: N/A | D17: N/A | E17: N/A | F17: N/A | G17: N/A | H17: N/A | I17: N/A | J17: N/A | K17: N/A | L17: N/A | M17: N/A | N17: =SUM(B17:M17) -> 0 | O17: 2250
A20: Note: We purchased these backfiles in April 2008. The annual access fee does not begin until the second year.
A21: COUNTER-Compliant?: | B21: Yes
A23: Note: if the stats turn out to have data on full-text records retrieved, please add lines for it. 4/2008 ajr

Sheet OVID
A1: OvidSP
A2: 2008-2009
B4: 39630 | C4: 39661 | D4: 39692 | E4: 39722 | F4: 39753 | G4: 39783 | H4: 39814 | I4: 39845 | J4: 39873 | K4: 39904 | L4: 39934 | M4: 39965 | N4: Total | O4: 2008-2009 Price | P4: Price per search
A5: BIOSIS Previews
A6: Sessions | B6: 0 | C6: 0 | D6: 0 | E6: 0 | F6: 0 | G6: 0 | H6: 1 | I6: 0 | J6: 0 | K6: 0 | L6: 1 | M6: 0 | N6: =SUM(B6:M6) -> 2
A7: Searches | B7: 0 | C7: 0 | D7: 0 | E7: 0 | F7: 0 | G7: 0 | H7: 1 | I7: 0 | J7: 0 | K7: 0 | L7: 1 | M7: 0 | N7: =SUM(B7:M7) -> 2 | O7: 0
A8: Turnaways | B8: 0 | C8: 0 | D8: 0 | E8: 0 | F8: 0 | G8: 0 | H8: 0 | I8: 0 | J8: 0 | K8: 0 | L8: 0 | M8: 0 | N8: =SUM(B8:M8) -> 0
B11: 39630 | C11: 39661 | D11: 39692 | E11: 39722 | F11: 39753 | G11: 39783 | H11: 39814 | I11: 39845 | J11: 39873 | K11: 39904 | L11: 39934 | M11: 39965 | N11: Total | O11: 2008-2009 Price | P11: Price per search
A12: Biological Abstracts
A13: Sessions | B13: N/A | C13: N/A | D13: N/A | E13: N/A | F13: N/A | G13: N/A | H13: 0 | I13: 26 | J13: 76 | K13: 106 | L13: 43 | M13: 26 | N13: =SUM(B13:M13) -> 277
A14: Searches | B14: N/A | C14: N/A | D14: N/A | E14: N/A | F14: N/A | G14: N/A | H14: 0 | I14: 23 | J14: 139 | K14: 227 | L14: 104 | M14: 45 | N14: =SUM(B14:M14) -> 538 | O14: 0
A15: Turnaways | B15: N/A | C15: N/A | D15: N/A | E15: N/A | F15: N/A | G15: N/A | H15: N/A | I15: N/A | J15: N/A | K15: N/A | L15: N/A | M15: N/A | N15: =SUM(B15:M15) -> 0
B18: 39630 | C18: 39661 | D18: 39692 | E18: 39722 | F18: 39753 | G18: 39783 | H18: 39814 | I18: 39845 | J18: 39873 | K18: 39904 | L18: 39934 | M18: 39965 | N18: Total | O18: 2008-2009 Price | P18: Price per search
A19: Ovid MEDLINE (free)
A20: Sessions | B20: 1 | C20: 0 | D20: 2 | E20: 2 | F20: 3 | G20: 0 | H20: 1 | I20: 8 | J20: 3 | K20: 11 | L20: 0 | M20: 1 | N20: =SUM(B20:M20) -> 32
A21: Searches | B21: 0 | C21: 0 | D21: 2 | E21: 4 | F21: 2 | G21: 0 | H21: 1 | I21: 17 | J21: 10 | K21: 37 | L21: 0 | M21: 4 | N21: =SUM(B21:M21) -> 77 | O21: 0 | P21: N/A
A22: Turnaways | B22: 0 | C22: 0 | D22: 0 | E22: 0 | F22: 0 | G22: 0 | H22: 0 | I22: 0 | J22: 0 | K22: 0 | L22: 0 | M22: 0 | N22: =SUM(B22:M22) -> 0
B25: 39630 | C25: 39661 | D25: 39692 | E25: 39722 | F25: 39753 | G25: 39783 | H25: 39814 | I25: 39845 | J25: 39873 | K25: 39904 | L25: 39934 | M25: 39965 | N25: Total | O25: 2008-2009 Price | P25: Price per search
A26: Ovid MEDLINE In-Process (free)
A27: Sessions | B27: 0 | C27: 0 | D27: 0 | E27: 0 | F27: 0 | G27: 0 | H27: N/A | I27: N/A | J27: N/A | K27: N/A | L27: N/A | M27: N/A | N27: =SUM(B27:M27) -> 0
A28: Searches | B28: 0 | C28: 0 | D28: 0 | E28: 0 | F28: 0 | G28: 0 | H28: N/A | I28: N/A | J28: N/A | K28: N/A | L28: N/A | M28: N/A | N28: =SUM(B28:M28) -> 0 | O28: 0 | P28: N/A
A29: Turnaways | B29: 0 | C29: 0 | D29: 0 | E29: 0 | F29: 0 | G29: 0 | H29: N/A | I29: N/A | J29: N/A | K29: N/A | L29: N/A | M29: N/A | N29: =SUM(B29:M29) -> 0
B32: 39630 | C32: 39661 | D32: 39692 | E32: 39722 | F32: 39753 | G32: 39783 | H32: 39814 | I32: 39845 | J32: 39873 | K32: 39904 | L32: 39934 | M32: 39965 | N32: Total | O32: 2008-2009 Price | P32: Price per search
A33: Ovid OLDMEDLINE (free)
A34: Sessions | B34: N/A | C34: N/A | D34: N/A | E34: N/A | F34: N/A | G34: N/A | H34: N/A | I34: N/A | J34: N/A | K34: N/A | L34: N/A | M34: N/A | N34: =SUM(B34:M34) -> 0
A35: Searches | B35: N/A | C35: N/A | D35: N/A | E35: N/A | F35: N/A | G35: N/A | H35: N/A | I35: N/A | J35: N/A | K35: N/A | L35: N/A | M35: N/A | N35: =SUM(B35:M35) -> 0 | O35: 0 | P35: N/A
A36: Turnaways | B36: N/A | C36: N/A | D36: N/A | E36: N/A | F36: N/A | G36: N/A | H36: N/A | I36: N/A | J36: N/A | K36: N/A | L36: N/A | M36: N/A | N36: =SUM(B36:M36) -> 0
B39: 39630 | C39: 39661 | D39: 39692 | E39: 39722 | F39: 39753 | G39: 39783 | H39: 39814 | I39: 39845 | J39: 39873 | K39: 39904 | L39: 39934 | M39: 39965 | N39: Total | O39: 2008-2009 Price | P39: Price per search
A40: Journals@Ovid Full Text
A41: Sessions | B41: 180 | C41: 136 | D41: 347 | E41: 458 | F41: 378 | G41: 198 | H41: 143 | I41: 671 | J41: 637 | K41: 634 | L41: 277 | M41: 217 | N41: =SUM(B41:M41) -> 4276
A42: Searches | B42: 178 | C42: 143 | D42: 352 | E42: 493 | F42: 490 | G42: 204 | H42: 146 | I42: 689 | J42: 698 | K42: 699 | L42: 276 | M42: 221 | N42: =SUM(B42:M42) -> 4589 | O42: 13849
A43: Turnaways | B43: 0 | C43: 0 | D43: 0 | E43: 0 | F43: 0 | G43: 0 | H43: 0 | I43: 0 | J43: 0 | K43: 0 | L43: 0 | M43: 0 | N43: =SUM(B43:M43) -> 0
B47: 39630 | C47: 39661 | D47: 39692 | E47: 39722 | F47: 39753 | G47: 39783 | H47: 39814 | I47: 39845 | J47: 39873 | K47: 39904 | L47: 39934 | M47: 39965 | N47: Total | O47: 2008-2009 Price | P47: Price per search
A48: All OVID Databases
A49: Sessions | B49: 189 | C49: 144 | D49: 391 | E49: 501 | F49: 409 | G49: 206 | H49: 155 | I49: 759 | J49: 745 | K49: 777 | L49: 321 | M49: 249 | N49: =SUM(B49:M49) -> 4846
A50: Searches | B50: 194 | C50: 155 | D50: 414 | E50: 573 | F50: 547 | G50: 218 | H50: 159 | I50: 810 | J50: 902 | K50: 1006 | L50: 411 | M50: 280 | N50: =SUM(B50:M50) -> 5669 | O50: =SUM(O6:O43) -> 13849
A51: Turnaways | B51: 0 | C51: 0 | D51: 0 | E51: 0 | F51: 0 | G51: 0 | H51: 0 | I51: 0 | J51: 0 | K51: 0 | L51: 0 | M51: 0 | N51: =SUM(B51:M51) -> 0
A54: COUNTER-Compliant?: | B54: Yes
A56: Note: The platform for Biological Abstracts switched from WebSPIRS to OvidSP in February 2009. There was a one-month overlap between the two platforms.

Sheet WebofScience
A1: Web of Science
A2: 2008-2009
A4: COUNTER-Compliant?: | B4: Yes
B6: 39630 | C6: 39661 | D6: 39692 | E6: 39722 | F6: 39753 | G6: 39783 | H6: 39814 | I6: 39845 | J6: 39873 | K6: 39904 | L6: 39934 | M6: 39965 | N6: Total | O6: 2008-2009 Price | P6: Price per unit
A7: BIOSIS Previews
A8: Sessions | B8: N/A | C8: N/A | D8: N/A | E8: N/A | F8: N/A | G8: N/A | H8: N/A | I8: 0 | J8: 0 | K8: 0 | L8: 2 | M8: 4 | N8: =SUM(B8:M8) -> 6
A9: Queries | B9: N/A | C9: N/A | D9: N/A | E9: N/A | F9: N/A | G9: N/A | H9: N/A | I9: 0 | J9: 0 | K9: 0 | L9: 2 | M9: 6 | N9: =SUM(B9:M9) -> 8 | O9: =(24867+27354)/2 -> 26110.5
A11: See also: WebSpirs, OVID.
B14: 39630 | C14: 39661 | D14: 39692 | E14: 39722 | F14: 39753 | G14: 39783 | H14: 39814 | I14: 39845 | J14: 39873 | K14: 39904 | L14: 39934 | M14: 39965 | N14: Total | O14: 2008-2009 Price | P14: Price per unit
A15: Web of Knowledge
A16: Sessions | B16: 895 | C16: 539 | D16: 969 | E16: 1241 | F16: 1055 | G16: 631 | H16: 687 | I16: 980 | J16: 895 | K16: 869 | L16: 914 | M16: 653 | N16: =SUM(B16:M16) -> 10328 | O16: N/A | P16: N/A
B19: 39630 | C19: 39661 | D19: 39692 | E19: 39722 | F19: 39753 | G19: 39783 | H19: 39814 | I19: 39845 | J19: 39873 | K19: 39904 | L19: 39934 | M19: 39965 | N19: Total | O19: 2008-2009 Price | P19: Price per unit
A20: Web of Science
A21: Sessions | B21: 413 | C21: 293 | D21: 707 | E21: 860 | F21: 766 | G21: 493 | H21: 293 | I21: 318 | J21: 632 | K21: 639 | L21: 406 | M21: 467 | N21: =SUM(B21:M21) -> 6287
A22: Queries | B22: 1860 | C22: 1427 | D22: 2916 | E22: 3517 | F22: 4285 | G22: 2412 | H22: 1807 | I22: 1331 | J22: 3190 | K22: 3332 | L22: 2168 | M22: 2664 | N22: =SUM(B22:M22) -> 30909 | O22: 104394 | P22: =O22/N22 -> 3.3774629
B25: 39630 | C25: 39661 | D25: 39692 | E25: 39722 | F25: 39753 | G25: 39783 | H25: 39814 | I25: 39845 | J25: 39873 | K25: 39904 | L25: 39934 | M25: 39965 | N25: Total
A26: EndNote Web
A27: Logins | B27: 9 | C27: 1 | D27: 20 | E27: 30 | F27: 8 | G27: 2 | H27: 6 | I27: 8 | J27: 12 | K27: 2 | L27: 0 | M27: 2 | N27: =SUM(B27:M27) -> 100
A28: New Users | B28: 0 | C28: 0 | D28: 0 | E28: 0 | F28: 0 | G28: 0 | H28: 5 | I28: 0 | J28: 0 | K28: 0 | L28: 0 | M28: 0 | N28: =SUM(B28:M28) -> 5
A29: New References | B29: 0 | C29: 0 | D29: 40 | E29: 160 | F29: 0 | G29: 0 | H29: 20 | I29: 4 | J29: 0 | K29: 0 | L29: 0 | M29: 0 | N29: =SUM(B29:M29) -> 224
A30: Exports | B30: 0 | C30: 0 | D30: 0 | E30: 1 | F30: 3 | G30: 0 | H30: 0 | I30: 1 | J30: 4 | K30: 0 | L30: 1 | M30: 2 | N30: =SUM(B30:M30) -> 12
A31: Imports | B31: 0 | C31: 1 | D31: 0 | E31: 8 | F31: 0 | G31: 0 | H31: 5 | I31: 1 | J31: 1 | K31: 7 | L31: 0 | M31: 0 | N31: =SUM(B31:M31) -> 23
A32: Searches | B32: 3 | C32: 0 | D32: 4 | E32: 2 | F32: 15 | G32: 1 | H32: 3 | I32: 3 | J32: 1 | K32: 0 | L32: 0 | M32: 1 | N32: =SUM(B32:M32) -> 33
A33: Captures | B33: 0 | C33: 0 | D33: 0 | E33: 0 | F33: 0 | G33: 0 | H33: 0 | I33: 0 | J33: 0 | K33: 0 | L33: 0 | M33: 0 | N33: =SUM(B33:M33) -> 0
A34: CWYW Format Bibliography | B34: 0 | C34: 0 | D34: 0 | E34: 0 | F34: 0 | G34: 0 | H34: 1 | I34: 0 | J34: 0 | K34: 0 | L34: 0 | M34: 0 | N34: =SUM(B34:M34) -> 1
A35: CWYW Traveling Library | B35: 0 | C35: 0 | D35: 0 | E35: 0 | F35: 0 | G35: 0 | H35: 0 | I35: 0 | J35: 0 | K35: 0 | L35: 0 | M35: 0 | N35: =SUM(B35:M35) -> 0
A36: Total Pages Served | B36: 12 | C36: 2 | D36: 64 | E36: 201 | F36: 26 | G36: 3 | H36: 40 | I36: 17 | J36: 18 | K36: 9 | L36: 1 | M36: 5 | N36: =SUM(B36:M36) -> 398

Sheet Oxford
A1: Oxford
A2: 2008-2009
B4: 39630 | C4: 39661 | D4: 39692 | E4: 39722 | F4: 39753 | G4: 39783 | H4: 39814 | I4: 39845 | J4: 39873 | K4: 39904 | L4: 39934 | M4: 39965 | N4: Total | O4: 2008-2009 Price | P4: Price per unit
A5: Oxford Music Online
A6: Sessions | B6: 22 | C6: 12 | D6: 87 | E6: 59 | F6: 33 | G6: 15 | H6: 35 | I6: 85 | J6: 41 | K6: 74 | L6: 39 | M6: 16 | N6: =SUM(B6:M6) -> 518
A7: Searches | B7: 36 | C7: 20 | D7: 148 | E7: 154 | F7: 69 | G7: 22 | H7: 64 | I7: 129 | J7: 120 | K7: 228 | L7: 112 | M7: 47 | N7: =SUM(B7:M7) -> 1149 | O7: 1597.5
A8: Turnaways | B8: 2 | C8: 0 | D8: 6 | E8: 0 | F8: 0 | G8: 0 | H8: 0 | I8: 0 | J8: 0 | K8: 74 | L8: 33 | M8: 0 | N8: =SUM(B8:M8) -> 115
A10: Oxford English Dictionary
A11: Sessions | B11: 149 | C11: 110 | D11: 568 | E11: 1062 | F11: 613 | G11: 397 | H11: 192 | I11: 505 | J11: 592 | K11: 727 | L11: 454 | M11: 298 | N11: =SUM(B11:M11) -> 5667
A12: Searches | B12: 275 | C12: 378 | D12: 3283 | E12: 4912 | F12: 2100 | G12: 1427 | H12: 743 | I12: 2077 | J12: 1575 | K12: 2282 | L12: 2090 | M12: 826 | N12: =SUM(B12:M12) -> 21968 | O12: 3033.8
A13: Turnaways | B13: 0 | C13: 0 | D13: 0 | E13: 0 | F13: 0 | G13: 0 | H13: 0 | I13: 0 | J13: 0 | K13: 0 | L13: 0 | M13: 0 | N13: =SUM(B13:M13) -> 0
A15: Treaties & International Agreements Online (Oceana)
A16: Sessions | B16: N/A | C16: N/A | D16: N/A | E16: N/A | F16: N/A | G16: N/A | H16: N/A | I16: N/A | J16: N/A | K16: N/A | L16: N/A | M16: N/A | N16: =SUM(B16:M16) -> 0
A17: Minutes | B17: N/A | C17: N/A | D17: N/A | E17: N/A | F17: N/A | G17: N/A | H17: N/A | I17: N/A | J17: N/A | K17: N/A | L17: N/A | M17: N/A | N17: =SUM(B17:M17) -> 0 | O17: 1314.25
A18: Turnaways | B18: N/A | C18: N/A | D18: N/A | E18: N/A | F18: N/A | G18: N/A | H18: N/A | I18: N/A | J18: N/A | K18: N/A | L18: N/A | M18: N/A | N18: =SUM(B18:M18) -> 0
A22: COUNTER-Compliant?: | B22: No

Sheet ProQuest
A1: ProQuest databases
A2: 2008-2009
B4: 39630 | C4: 39661 | D4: 39692 | E4: 39722 | F4: 39753 | G4: 39783 | H4: 39814 | I4: 39845 | J4: 39873 | K4: 39904 | L4: 39934 | M4: 39965 | N4: Total | O4: 2008-2009 Price | P4: Price per search
A5: ABI/INFORM Dateline
A6: Searches | N6: =SUM(B6:M6) -> 0 | O6: 0 | P6: N/A
B9: 39630 | C9: 39661 | D9: 39692 | E9: 39722 | F9: 39753 | G9: 39783 | H9: 39814 | I9: 39845 | J9: 39873 | K9: 39904 | L9: 39934 | M9: 39965 | N9: Total | O9: 2008-2009 Price | P9: Price per search
A10: ABI/INFORM Global
A11: Searches | N11: =SUM(B11:M11) -> 0 | O11: 18757
B14: 39630 | C14: 39661 | D14: 39692 | E14: 39722 | F14: 39753 | G14: 39783 | H14: 39814 | I14: 39845 | J14: 39873 | K14: 39904 | L14: 39934 | M14: 39965 | N14: Total | O14: 2008-2009 Price | P14: Price per search
A15: ABI/INFORM Trade & Industry
A16: Searches | N16: =SUM(B16:M16) -> 0 | O16: 0 | P16: N/A
B19: 39630 | C19: 39661 | D19: 39692 | E19: 39722 | F19: 39753 | G19: 39783 | H19: 39814 | I19: 39845 | J19: 39873 | K19: 39904 | L19: 39934 | M19: 39965 | N19: Total | O19: 2008-2009 Price | P19: Price per search
A20: Dissertations & Theses
A21: Searches | N21: =SUM(B21:M21) -> 0 | O21: 0
B24: 39630 | C24: 39661 | D24: 39692 | E24: 39722 | F24: 39753 | G24: 39783 | H24: 39814 | I24: 39845 | J24: 39873 | K24: 39904 | L24: 39934 | M24: 39965 | N24: Total | O24: 2008-2009 Price | P24: Price per search
A25: National Newspapers (5)
A26: Searches | N26: =SUM(B26:M26) -> 0 | O26: 0
B29: 39630 | C29: 39661 | D29: 39692 | E29: 39722 | F29: 39753 | G29: 39783 | H29: 39814 | I29: 39845 | J29: 39873 | K29: 39904 | L29: 39934 | M29: 39965 | N29: Total | O29: 2008-2009 Price | P29: Price per search
A30: Los Angeles Times
A31: Searches | N31: =SUM(B31:M31) -> 0 | O31: 0 | P31: N/A
B34: 39630 | C34: 39661 | D34: 39692 | E34: 39722 | F34: 39753 | G34: 39783 | H34: 39814 | I34: 39845 | J34: 39873 | K34: 39904 | L34: 39934 | M34: 39965 | N34: Total | O34: 2008-2009 Price | P34: Price per search
A35: Providence Journal-Bulletin
A36: Searches | N36: =SUM(B36:M36) -> 0 | O36: 0
B39: 39630 | C39: 39661 | D39: 39692 | E39: 39722 | F39: 39753 | G39: 39783 | H39: 39814 | I39: 39845 | J39: 39873 | K39: 39904 | L39: 39934 | M39: 39965 | N39: Total | O39: 2008-2009 Price | P39: Price per search
A40: Wall Street Journal
A41: Searches | N41: =SUM(B41:M41) -> 0 | O41: 0 | P41: N/A
B44: 39630 | C44: 39661 | D44: 39692 | E44: 39722 | F44: 39753 | G44: 39783 | H44: 39814 | I44: 39845 | J44: 39873 | K44: 39904 | L44: 39934 | M44: 39965 | N44: Total | O44: 2008-2009 Price | P44: Price per search
A45: ProQuest Historical Newspapers The New York Times (1851-2002)
A46: Searches | N46: =SUM(B46:M46) -> 0 | O46: 0 | P46: N/A
B50: 39630 | C50: 39661 | D50: 39692 | E50: 39722 | F50: 39753 | G50: 39783 | H50: 39814 | I50: 39845 | J50: 39873 | K50: 39904 | L50: 39934 | M50: 39965 | N50: Total | O50: 2008-2009 Price | P50: Price per unit
A51: ProQuest (all databases)
A52: Sessions | N52: =SUM(B52:M52) -> 0
A53: Searches | N53: =SUM(B53:M53) -> 0 | O53: =SUM(O11:O46) -> 18757
A54: Successful full-text downloads | N54: =SUM(B54:M54) -> 0
A57: COUNTER-Compliant?: | B57: Yes

Sheet ReferenceUSA
A1: ReferenceUSA
A2: 2008-2009
A4: COUNTER-Compliant?: | B4: No
B6: 39630 | C6: 39661 | D6: 39692 | E6: 39722 | F6: 39753 | G6: 39783 | H6: 39814 | I6: 39845 | J6: 39873 | K6: 39904 | L6: 39934 | M6: 39965 | N6: Total
A7: U.S. Business
A8: Logins | B8: 108 | C8: 37 | D8: 188 | E8: 154 | F8: 79 | G8: 50 | H8: 41 | I8: 108 | J8: 58 | K8: 100 | L8: 68 | M8: 59 | N8: =SUM(B8:M8) -> 1050
A9: # of Searches | B9: 363 | C9: 133 | D9: =12+352 -> 364 | E9: 141 | F9: 78 | G9: 62 | H9: 28 | I9: 135 | J9: 75 | K9: 161 | L9: 125 | M9: =86+4 -> 90 | N9: =SUM(B9:M9) -> 1755
A10: # of Result Pages | B10: 800 | C10: 253 | D10: =18+642 -> 660 | E10: 307 | F10: 171 | G10: 130 | H10: 53 | I10: 344 | J10: =128+5 -> 133 | K10: 461 | L10: 1071 | M10: =122+4 -> 126 | N10: =SUM(B10:M10) -> 4509
A11: Total Records on Results | B11: 8266 | C11: 2509 | D11: =419+11222 -> 11641 | E11: =6086+24 -> 6110 | F11: 3029 | G11: 1813 | H11: =856+144 -> 1000 | I11: =7066+24 -> 7090 | J11: 1773 | K11: 8510 | L11: 23216 | M11: =1593+56 -> 1649 | N11: =SUM(B11:M11) -> 76606
A12: # of Detail Views | B12: 0 | C12: 0 | D12: 0 | E12: 0 | F12: 0 | G12: 0 | H12: 0 | I12: 0 | J12: 0 | K12: 0 | L12: 0 | M12: 0 | N12: =SUM(B12:M12) -> 0
A13: Total Detail Records Viewed | B13: 0 | C13: 0 | D13: 0 | E13: 0 | F13: 0 | G13: 0 | H13: 0 | I13: 0 | J13: 0 | K13: 0 | L13: 0 | M13: 0 | N13: =SUM(B13:M13) -> 0
A14: # of Prints | B14: 885 | C14: 166 | D14: =26+324 -> 350 | E14: 247 | F14: 99 | G14: 125 | H14: =23+6 -> 29 | I14: 149 | J14: 145 | K14: 156 | L14: 179 | M14: 150 | N14: =SUM(B14:M14) -> 2680
A15: Total Records Printed | B15: 895 | C15: 190 | D15: =26+975 -> 1001 | E15: 247 | F15: 99 | G15: 125 | H15: 29 | I15: 149 | J15: 145 | K15: 156 | L15: 179 | M15: 150 | N15: =SUM(B15:M15) -> 3365
A16: # of Downloads | B16: 34 | C16: 12 | D16: 10 | E16: 3 | F16: 0 | G16: 6 | H16: 0 | I16: 15 | J16: 0 | K16: 14 | L16: 792 | M16: 4 | N16: =SUM(B16:M16) -> 890
A17: Total Records Downloaded | B17: 993 | C17: 139 | D17: 178 | E17: 51 | F17: 0 | G17: 32 | H17: 0 | I17: 688 | J17: 0 | K17: 206 | L17: 21541 | M17: 76 | N17: =SUM(B17:M17) -> 23904
A18: # of Emails | B18: 0 | C18: 0 | D18: 0 | E18: 0 | F18: 0 | G18: 0 | H18: 0 | I18: 0 | J18: 0 | K18: 0 | L18: 0 | M18: 0 | N18: =SUM(B18:M18) -> 0
A19: Total Records Emailed | B19: 0 | C19: 0 | D19: 0 | E19: 0 | F19: 0 | G19: 0 | H19: 0 | I19: 0 | J19: 0 | K19: 0 | L19: 0 | M19: 0 | N19: =SUM(B19:M19) -> 0
A20: # of Purchases | B20: 0 | C20: 0 | D20: 0 | E20: 0 | F20: 0 | G20: 0 | H20: 0 | I20: 0 | J20: 0 | K20: 0 | L20: 0 | M20: 0 | N20: =SUM(B20:M20) -> 0
A21: Total Records Purchased | B21: 0 | C21: 0 | D21: 0 | E21: 0 | F21: 0 | G21: 0 | H21: 0 | I21: 0 | J21: 0 | K21: 0 | L21: 0 | M21: 0 | N21: =SUM(B21:M21) -> 0
B24: 39630 | C24: 39661 | D24: 39692 | E24: 39722 | F24: 39753 | G24: 39783 | H24: 39814 | I24: 39845 | J24: 39873 | K24: 39904 | L24: 39934 | M24: 39965 | N24: Total
A25: U.S. Residential
A26: Logins | B26: 108 | C26: 37 | D26: 188 | E26: 154 | F26: 79 | G26: 50 | H26: 41 | I26: 108 | J26: 58 | K26: 100 | L26: 68 | M26: 59 | N26: =SUM(B26:M26) -> 1050
A27: # of Searches | B27: 26 | C27: 3 | D27: 20 | E27: 15 | F27: 17 | G27: 24 | H27: 21 | I27: 32 | J27: 9 | K27: 24 | L27: 17 | M27: 14 | N27: =SUM(B27:M27) -> 222
A28: # of Result Pages | B28: 94 | C28: 3 | D28: 23 | E28: 15 | F28: 18 | G28: 29 | H28: 25 | I28: 55 | J28: 16 | K28: 25 | L28: 20 | M28: 15 | N28: =SUM(B28:M28) -> 338
A29: Total Records on Results | B29: 2090 | C29: 5 | D29: 249 | E29: 51 | F29: 156 | G29: 405 | H29: 242 | I29: 1157 | J29: 284 | K29: 202 | L29: 164 | M29: 179 | N29: =SUM(B29:M29) -> 5184
A30: # of Detail Views | B30: 0 | C30: 0 | D30: 0 | E30: 0 | F30: 0 | G30: 0 | H30: 0 | I30: 0 | J30: 0 | K30: 0 | L30: 0 | M30: 0 | N30: =SUM(B30:M30) -> 0
A31: Total Detail Records Viewed | B31: 0 | C31: 0 | D31: 0 | E31: 0 | F31: 0 | G31: 0 | H31: 0 | I31: 0 | J31: 0 | K31: 0 | L31: 0 | M31: 0 | N31: =SUM(B31:M31) -> 0
A32: # of Prints | B32: 5 | C32: 1 | D32: 10 | E32: 7 | F32: 11 | G32: 5 | H32: 11 | I32: 12 | J32: 4 | K32: 13 | L32: 2 | M32: 17 | N32: =SUM(B32:M32) -> 98
A33: Total Records Printed | B33: 5 | C33: 1 | D33: 10 | E33: 7 | F33: 11 | G33: 5 | H33: 14 | I33: 12 | J33: 4 | K33: 13 | L33: 2 | M33: 17 | N33: =SUM(B33:M33) -> 101
A34: # of Downloads | B34: 15 | C34: 0 | D34: 0 | E34: 0 | F34: 0 | G34: 0 | H34: 0 | I34: 0 | J34: 0 | K34: 0 | L34: 0 | M34: 0 | N34: =SUM(B34:M34) -> 15
A35: Total Records Downloaded | B35: 375 | C35: 0 | D35: 0 | E35: 0 | F35: 0 | G35: 0 | H35: 0 | I35: 0 | J35: 0 | K35: 0 | L35: 0 | M35: 0 | N35: =SUM(B35:M35) -> 375
A36: # of Emails | B36: 0 | C36: 0 | D36: 0 | E36: 0 | F36: 0 | G36: 0 | H36: 0 | I36: 0 | J36: 0 | K36: 0 | L36: 0 | M36: 0 | N36: =SUM(B36:M36) -> 0
A37: Total Records Emailed | B37: 0 | C37: 0 | D37: 0 | E37: 0 | F37: 0 | G37: 0 | H37: 0 | I37: 0 | J37: 0 | K37: 0 | L37: 0 | M37: 0 | N37: =SUM(B37:M37) -> 0
... A39: Total Records Purchased | B39: 0 | C39: 0 | D39: 0 | E39: 0 | F39: 0 | G39: 0 | H39: 0 | I39: 0 | J39: 0 | K39: 0 | L39: 0 | M39: 0 | N39: =SUM(B39:M39) -> 0
B42: 39630 | C42: 39661 | D42: 39692 | E42: 39722 | F42: 39753 | G42: 39783 | H42: 39814 | I42: 39845 | J42: 39873 | K42: 39904 | L42: 39934 | M42: 39965 | N42: Total | O42: 2008-2009 Price | P42: Price per unit
A43: Summary
A44: Logins | B44: =B26 -> 108 | C44: =C26 -> 37 | D44: =D26 -> 188 | E44: =E26 -> 154 | F44: =F26 -> 79 | G44: =G26 -> 50 | H44: =H26 -> 41 | I44: =I26 -> 108 | ... M44: =M26 -> 59 | N44: =SUM(B44:M44) -> 1050
A45: # of Searches | B45: =B9+B27 -> 389 | C45: =C9+C27 -> 136 | D45: =D9+D27 -> 384 | E45: =E9+E27 -> 156 | F45: =F9+F27 -> 95 | G45: =G9+G27 -> 86 | H45: =H9+H27 -> 49 | I45: =I9+I27 -> 167 | ... M45: =M9+M27 -> 104 | N45: =SUM(B45:M45) -> 1977 | O45: 11907
A46: # of Result Pages | B46: =B10+B28 -> 894 | C46: =C10+C28 -> 256 | D46: =D10+D28 -> 683 | E46: =E10+E28 -> 322 | F46: =F10+F28 -> 189 | G46: =G10+G28 -> 159 | H46: =H10+H28 -> 78 | I46: =I10+I28 -> 399 | ... M46: =M10+M28 -> 141 | N46: =SUM(B46:M46) -> 4847
A47: Total Records on Results | B47: =B11+B29 -> 10356 | C47: =C11+C29 -> 2514 | D47: =D11+D29 -> 11890 | E47: =E11+E29 -> 6161 | F47: =F11+F29 -> 3185 | G47: =G11+G29 -> 2218 | H47: =H11+H29 -> 1242 | I47: =I11+I29 -> 8247 | ... M47: =M11+M29 -> 1828 | N47: =SUM(B47:M47) -> 81790
...

Sheet RefWorks
A1: RefWorks
A2: 2008-2009
A4: COUNTER-Compliant?: | B4: No
B6: 39630 | C6: 39661 | D6: 39692 | E6: 39722 | F6: 39753 | G6: 39783 | H6: 39814 | I6: 39845 | J6: 39873 | K6: 39904 | L6: 39934 | M6: 39965 | N6: Total | O6: 2008-2009 Price | P6: Price per unit
A7: RefWorks
A8: New Users | B8: 7 | C8: 7 | D8: 52 | E8: 36 | F8: 11 | G8: 18 | H8: 10 | I8: 66 | J8: 14 | K8: 12 | L8: 7 | M8: 2 | N8: =SUM(B8:M8) -> 242 | O8: 13360 | P8: =O8/N8 -> 55.206612
A9: Repeat Users | B9: 22 | C9: 21 | D9: 41 | E9: 80 | F9: 85 | G9: 58 | H9: 44 | I9: 58 | J9: 86 | K9: 90 | L9: 38 | M9: 21 | N9: =SUM(B9:M9) -> 644 | O9: 13360 | P9: =O9/N9 -> 20.745342
A10: Total Monthly Users | B10: 29 | C10: 28 | D10: 93 | E10: 116 | F10: 96 | G10: 76 | H10: 54 | I10: 124 | J10: 100 | K10: 102 | L10: 45 | M10: 23 | N10: =SUM(B10:M10) -> 886 | O10: 13360 | P10: =O10/N10 -> 15.079007
A11: Total Sessions per month | B11: 194 | C11: 201 | D11: 384 | E11: 454 | F11: 352 | G11: 270 | H11: 234 | I11: 516 | J11: 427 | K11: 473 | L11: 179 | M11: 201 | N11: =SUM(B11:M11) -> 3885 | O11: 13360 | P11: =O11/N11 -> 3.4388674
A12: Average Sessions Per User | B12: 6.69 | C12: 7.18 | D12: 4.13 | E12: 3.91 | F12: 3.67 | G12: 3.55 | H12: 4.33 | I12: 4.16 | J12: 4.27 | K12: 4.64 | L12: 3.98 | M12: 8.74 | N12: =SUM(B12:M12) -> 59.25 | O12: 13360 | P12: =O12/N12 -> 225.48523
A13: Total Subscriber References added | B13: 592 | C13: 4526 | D13: 1182 | E13: 1856 | F13: 1134 | G13: 2369 | H13: 3348 | I13: 2898 | J13: 1106 | K13: 1448 | L13: 1908 | M13: 629 | N13: =SUM(B13:M13) -> 22996 | O13: 13360 | P13: =O13/N13 -> 0.5809706
A14: Average References added per user | B14: 20.41 | C14: 161.64 | D14: 12.71 | E14: 16 | F14: 11.81 | G14: 31.17 | H14: 62 | I14: 23.37 | J14: 11.06 | K14: 14.2 | L14: 42.4 | M14: 27.35 | N14: =SUM(B14:M14) -> 434.12 | O14: 13360 | P14: =O14/N14 -> 30.774901
A17: See more extensive statistics at http://digitalcommons.uri.edu/ts_rpts/55/.

Sheet SciFinderScholar
A1: SciFinder Scholar
A2: 2008-2009
A4: COUNTER-Compliant?: | B4: No
B6: 39630 | C6: 39661 | D6: 39692 | E6: 39722 | F6: 39753 | G6: 39783 | H6: 39814 | I6: 39845 | J6: 39873 | K6: 39904 | L6: 39934 | M6: 39965 | N6: Total | O6: 2008-2009 Price | P6: Price per unit
A7: SciFinder Scholar - Desktop
A8: Sessions | B8: Not avail. | C8: Not avail. | D8: Not avail. | E8: Not avail. | F8: Not avail. | G8: Not avail. | H8: 101 | I8: 102 | J8: 129 | K8: 92 | L8: 0 | M8: 0 | N8: =SUM(B8:M8) -> 424
