Workbook
Name dropdown: 'Section D'!$D$424:$D$433

Sheet CoverSheet
C2: Click Here to complete your agency's Final IS Report
C4: State of Colorado Department of Local Affairs Community Services Block Grant Quarterly Performance Report
C6: Agency Name:
C8: Title and Name of Person Completing this Report:
C10: Phone:
C11: email:
C13: Reporting Period: (Check which reporting period this report is applicable to)
C14: December 1 through February 28
C15: March 1 through May 31
C16: June 1 through August 31
C17: September 1 through November 30
C18: Final "IS" Report (March 31)
... C32: 1. How many participants were served during this reporting period:
E34: Yes | F34: No
C35: 2. Is this number on track with the “projected” number of clients from your application and plan?
C37: 3. On what date/s did your tri-partite board meet during this reporting period? (Include a copy of all meeting minutes that occurred during the reporting quarter in your email.)
C40: 4. Were there updates or changes to the Tripartite Board during this reporting period, if so please explain:
C44: 5. For “Linkages” programs, provide specific activities undertaken, the purpose of the activity and the outcome for the client or community. Describe what kinds of new collaborative partnerships were formed (or strengthened) between your agency and other organizations as a result of the activity. Simply providing a list of meetings attended is not sufficient.
C48: 6. Please identify any problems encountered during the reporting period, and include what actions your organization has taken or plans to take to resolve the issue:
C52: 7. If you need training or technical assistance from DOLA, you may request it here. Please be specific.
C56: I hereby certify to the best of my knowledge and belief that the information in this report, including any supplemental information, is true and correct.
C58: Signature of Responsible Administrator | F58: Date
C59: Print Name of Responsible Administrator | F59: Date
C62: Stop - Next Section is for your Agency's Final IS Report - Stop
C64: CSBG FINAL IS PROGRAM REPORT DUE MARCH 31 EACH YEAR MUST BE COMPLETED AND ACCOMPANIED WITH: NATIONAL INDICATORS FORMS, SECTIONS D. E. F. AND G.
C67: Agency Name: | D67: =D6 -> 0
C69: Period Ending
C71: NATIONAL INDICATORS:
D72: This must match with the one identified in the application and plan.
C74: Program:
C76: Actual Amount of the CSBG spent: $
C78: Name & Title of Person Filling this Report: | D78: =D8 -> 0
C80: Address:
C82: Phone Number:
C84: Program Director Signature (please type your name authorizing submission of this report):
C85: Program Director’s Name and Title:
C87: Please remember that the answers to these questions must relate to your original application and current grant contract.
C89: 7. What services/assistance did you provide your clients? List all that apply (separate services by commas). For example: mortgage/rent assistance, homeownership counseling services, food boxes, job readiness, etc.
C93: 8. What was the outcome for the client as a result of the service? (separate outcomes by commas). For example: unemployed & obtained a job, removed barriers to education, maintained an independent living situation, etc.
C98: 9. How many Persons are more self-sufficient as a result of your services?
...

Sheet Section D
C2: Agency Name: | D2: =CoverSheet!D6 -> 0
B3: Section D: Accomplishments and Coordination of Funds
B6: Ø Use a separate sheet for your answers, or enter them here. Please do not use acronyms.
B11: 1. Strategic Thinking for Long-Term Solutions
C12: a. Please describe an agency strategy which addresses a long-term solution to a persistent problem affecting members of the low-income community. Address the following questions:
B14: i. How did the agency identify the community need?
A15: Sec D 1.a1
B16: ii. How were CSBG funds used to plan, manage, and/or develop the approach?
A17: Sec D 1.a2
B18: iii. What local partners were involved, and how did each contribute to the program?
A19: Sec D 1.a3
B20: iv. What outcome indicators did the agency use to measure success?
A21: Sec D 1.a4
B22: v. What outcomes have resulted in PY 2012? If no outcomes yet, when?
A23: Sec D 1.a5
B27: 2. Delivering High-Quality, Accessible, and Well-Managed Services
C28: a. Please describe what you consider to be the top management accomplishment achieved by your State CSBG office during PY 2012. Show how responsible, informed leadership led to effective and efficient management of CSBG.
D30: Top State Management Accomplishment:
A31: Sec D 2.a
C33: b. Please describe what you consider to be the top three management accomplishments achieved by your agencies during PY 2012. Show how responsible, informed leadership and effective, efficient processes led to high-quality, accessible, and well-managed services.
D35: Top Three Agency Management Accomplishments:
A37: Sec D 2.b1 | B37: 1.
A39: Sec D 2.b1 | B39: 2.
A41: Sec D 2.b1 | B41: 3.
B45: 3. Mobilizing Resources to Support Innovative Solutions
B46: a. Please describe how your agency addressed a cause or condition of poverty in the community using an innovative or creative approach. Showcase how your agency relied on mobilization and coordination of resources to help reach interim and final outcomes. Demonstrate how CSBG “works” as it funds staff activities, investments, or services to meet a community need. Include the following elements: | C46: a. Please describe how your agency addressed a cause or condition of poverty in the community using an innovative or creative approach. Showcase how your agency relied on mobilization and coordination of resources to help reach interim and final outcomes. Demonstrate how CSBG “works” as it funds staff activities, investments, or services to meet a community need. Include the following elements:
B48: i. Agency name (no acronyms please)
A49: Sec D 3.a1
B50: ii. Program name
A51: Sec D 3.a2
B52: iii. CSBG service category
A53: Sec D 3.a3 | F53: Choose From The Dropdown | P53: Ø Click on the Cell, and then click on arrow to the right of the Cell.
B54: iv. Description of program (capacity, duration, targeted population, etc)
A55: Sec D 3.a4
B56: v. How was the agency’s approach innovative or creative? Please be specific.
A57: Sec D 3.a5
B58: vi. Outcomes achieved (include the number of people enrolled and areas affected)
A59: Sec D 3.a6
B60: vii. How were CSBG funds used? Please be specific.
A61: Sec D 3.a7
...

Sheet Section E
B2: Section E: CSBG Expenditures by Service Category
B4: Agency Reporting: | C4: =CoverSheet!D6 -> 0
B7: Table 1: Total amount of CSBG funds expended in Program Year 2012 by Service Category
B9: Service Category | E9: CSBG Funds
A13: Sec E 1.1 | B13: 1. Employment
A15: Sec E 1.2 | B15: 2. Education
A17: Sec E 1.3 | B17: 3. Income Management
A19: Sec E 1.4 | B19: 4. Housing
A21: Sec E 1.5 | B21: 5. Emergency Services
A23: Sec E 1.6 | B23: 6. Nutrition
A25: Sec E 1.7 | B25: 7. Linkages
A27: Sec E 1.8 | B27: 8. Self Sufficiency
A29: Sec E 1.9 | B29: 9. Health
A31: Sec E 1.10 | B31: 10. Other
B33: Totals | E33: =SUM(E13:F32) -> 0
D37: Of the CSBG funds reported above *** | G37: *** were for administration.
B39: Please consult the instructions regarding what constitutes "administration."
B43: Table 2: Of the funding listed in Table 1: Funds for Services by Demographic Category, PY 2012
B45: Demographic Category | E45: CSBG Funds
A49: Sec E 2.1 | B49: 1. Youth
B50: (Individuals aged 12 to 18)
A51: Sec E 2.2 | B51: 2. Seniors
B52: (Individuals aged 55 and up)
C56: Next

Sheet Section F
C3: Section F. Resources Administered and Generated by the CSBG Network
A5: Sec F 1 | B5: 1. | C5: Name of Local Agency Reporting | H5: 1 | I5: =CoverSheet!D6 -> 0
L7: ARRA ONLY
A8: Sec F 2 | B8: 2. | C8: Amount of PY 2012 CSBG allocated to reporting agencies | I8: 2
C10: Federal Resources (Other than CSBG)
A11: Sec F 3 | B11: 3. | C11: Weatherization (DOE) (include oil overcharge $$) | I11: 3.
B12: 4. | C12: Health and Human Services (HHS)
A13: Sec F 4a | C13: a. LIHEAP - Fuel Assistance (include oil overcharge $$) | I13: 4a.
A14: Sec F 4b | C14: b. LIHEAP - Weatherization (include oil overcharge $$) | I14: 4b.
A15: Sec F 4c | C15: c. Head Start | I15: 4c.
A16: Sec F 4d | C16: d. Early Head Start | I16: 4d.
A17: Sec F 4e | C17: e. Older Americans Act | I17: 4e.
A18: Sec F 4f | C18: f. Social Services Block Grant (SSBG) | I18: 4f.
A19: Sec F 4g | C19: g. Medicare/Medicaid | I19: 4g.
A20: Sec F 4h | C20: h. Assets for Independence (AFI) | I20: 4h.
A21: Sec F 4i | C21: i. Temporary Assistance for Needy Families (TANF) | I21: 4i.
A22: Sec F 4j | C22: j. Child Care Development Block Grant (CCDBG) | I22: 4j.
C24: k. Other HHS Resources:
A26: Sec F 4k.1 | B26: i. | G26: CFDA #: | I26: 4k.i
A27: Sec F 4k.2 | B27: ii. | G27: CFDA #: | I27: 4k.ii
A28: Sec F 4k.3 | B28: iii. | G28: CFDA #: | I28: 4k.iii
A29: Sec F 4k.4 | B29: iv. | G29: CFDA #: | I29: 4k.iv
A31: Sec F 4k.total | G31: Total Other HHS Resources | I31: 4k. | J31: =SUM(J26:J29) -> 0 | L31: =SUM(L26:L29) -> 0
B33: 5. | C33: Department of Agriculture (USDA)
A34: Sec F 5a | C34: a. Special Supplemental Nutrition for Women, Infants, and Children (WIC) | I34: 5a.
A35: Sec F 5b | C35: b. All USDA Non-Food programs (e.g. rural development) | I35: 5b.
A36: Sec F 5c | C36: c. All other USDA Food programs | I36: 5c.
B37: 6. | C37: Department of Housing and Urban Development (HUD)
A38: Sec F 6a | C38: a. Community Development Block Grant (CDBG) - Fed., State, and local | I38: 6a.
A39: Sec F 6b | C39: b. Section 8 | I39: 6b.
A40: Sec F 6c | C40: c. Section 202 | I40: 6c.
A41: Sec F 6d | C41: d. Home tenant based assistance | I41: 6d.
A42: Sec F 6e | C42: e. HOPE for Homeowners Program (H4H) | I42: 6e.
A43: Sec F 6f | C43: f. Emergency Shelter Grant Program (ESGP) | I43: 6f.
A44: Sec F 6g | C44: g. Continum of Care (CofC) | I44: 6g.
A45: Sec F 6h | C45: h. All other HUD including homeless programs | I45: 6h.
B46: 7. | C46: Department of Labor (DOL)
A47: Sec F 7a | C47: a. Workforce Investment Act (WIA) | I47: 7a.
A48: Sec F 7b | C48: b. Other DOL Employment and training programs | I48: 7b.
A49: Sec F 7c | C49: c. All other DOL programs | I49: 7c.
...

Sheet Section G
B3: Section G Program Participant Characteristics
B5: 1. Name of Agency Reporting | E5: =CoverSheet!D6 -> 0
A8: Sec G 2a | B8: 2a. Total Non CSBG Resources Reported in Section F
I9: 3
A10: Sec G 2a | B10: 2b. Total amount of CSBG Funds allocated
B12: Total Resourcs for FY 2012 (2a + 2b) | I12: =I8+I10 -> 0
A14: Sec G 3 | B14: 3. Total unduplicated number of persons about whom one or more characteristics were obtained: | M14: 10
A15: Sec G 4 | B15: 4. Total unduplicated number of persons about whom no characteristics were obtained:
A16: Sec G 5 | B16: 5. Total unduplicated number of families about whom one or more characteristics were obtained: | M16: 10
A17: Sec G 6 | B17: 6. Total unduplicated number of families about whom no characteristics were obtained:
B19: 7. Gender | E19: Number of Persons* | J19: 13. Family Size | M19: Number of Families***
A20: Sec G 7a | B20: a. Male | I20: a. One | M20: =E69 -> 0 | N20: ççThis field has been prepopulated from cell 12d | O20: Sec G 13a
A21: Sec G 7b | B21: b. Female | I21: b. Two | O21: Sec G 13b
A22: Sec G 7 Total | B22: TOTAL* | E22: =SUM(E20:E21) -> 0 | I22: c. Three | O22: Sec G 13c
I23: d. Four | O23: Sec G 13d
B24: 8. Age | E24: Number of Persons* | I24: e. Five | O24: Sec G 13e
A25: Sec G 8a | B25: a. 0 - 5 | I25: f. Six | O25: Sec G 13f
A26: Sec G 8b | B26: b. 6 - 11 | I26: g. Seven | O26: Sec G 13g
A27: Sec G 8c | B27: c. 12 - 17 | I27: h. Eight or more | O27: Sec G 13h
A28: Sec G 8d | B28: d. 18 - 23 | I28: TOTAL*** | M28: =SUM(M20:M27) -> 0 | O28: Sec G 13 Total
A29: Sec G 8e | B29: e. 24 - 44
A30: Sec G 8f | B30: f. 45 - 54 | I30: 14. Source of Family Income | M30: Number of Families
A31: Sec G 8g | B31: g. 55 - 69 | F31: Total: 24 Yrs + | I31: a. Unduplicated # Families Reporting | O31: Sec G 14 a
A32: Sec G 8h | B32: h. 70 + | F32: =SUM(E29:E32) -> 0 | I32: One or More Sources of Income
A33: Sec G 8 Total | B33: TOTAL* | E33: =SUM(E25:E32) -> 0 | I33: b. Unduplicated # Families Reporting | O33: Sec G 14 b
I34: Zero Income
B35: 9. Ethnicity/Race | E35: Number of Persons* | I35: TOTAL Unduplicated # Families Reporting One or More Sources of Income or Zero Income.***
B36: I. Ethnicity | M36: =SUM(M31:M34) -> 0 | O36: Sec G 14 Total
A37: Sec G 9.1a | B37: a. Hispanic, Latino or Spanish Origin
A38: Sec G 9.1b | B38: b. Not Hispanic, Latino, or Spanish Origin
A39: Sec G 9.1 Total | B39: TOTAL* | E39: =SUM(E37:E38) -> 0 | I39: Below please report the total # of families
I40: identifying the applicable sources of income
B41: II. Race | I41: c. TANF | O41: Sec G 14c
A42: Sec G 9.2a | B42: a. White | I42: d. SSI | O42: Sec G 14d
A43: Sec G 9.2b | B43: b. Black or African American | I43: e. Social Security | O43: Sec G 14e
A44: Sec G 9.2c | B44: c. American Indian and Alaska Native | I44: f. Pension | O44: Sec G 14f
A45: Sec G 9.2d | B45: d. Asian | I45: g. General Assistance | O45: Sec G 14g
A46: Sec G 9.2e | B46: e. Native Hawaiian and Other Pacific Islander | I46: h. Unemployment Insurance | O46: Sec G 14h
A47: Sec G 9.2f | B47: f. Other | I47: i. Employment + Other Source | O47: Sec G 14i
A48: Sec G 9.2g | B48: g. Multi-Race (any two or more of the above) | I48: j. Employment Only | O48: Sec G 14j
...

Sheet Goal 1
B1: PY 2012
B2: National Performance Indicators - Agency Level Forms
B3: Agency Name | E3: =CoverSheet!D6 -> 0
B5: Goal 1: Low-income people become more self-sufficient.
B7: National Performance Indicator 1.1 | F7: I.) Number of Participants Enrolled in Program(s) | G7: II.) Number of Participants Expected to Achieve Outcome in Reporting Period (Target) | H7: III.) Number of Participants Achieving Outcome in Reporting Period (Actual) | I7: IV.) Percentage Achieving Outcome in Reporting Period [III / II = IV]
B8: Employment
B9: The number and percentage of low-income
B10: participants who get a job or become
B11: self-employed, as a result of Community
B12: Action Assistance, as measured by
B13: one or more of the following:
A17: 1.1 A | B17: A. Unemployed and obtained a job | I17: =(H17/G17) -> #DIV/0!
A18: 1.1 B | B18: B. Employed and maintained a job for at least 90 days | I18: =H18/G18 -> #DIV/0!
A19: 1.1 C | B19: C. Employed and obtained an increase in employment income and/or benefits | I19: =(H19/G19) -> #DIV/0!
A20: 1.1 D | B20: D. Achieved "living wage" employment and/or benefits | I20: =(H20/G20) -> #DIV/0!
B21: In the rows below, please include any additional indicators that were not captured above.
A22: 1.1 new 1 | I22: =(H22/G22) -> #DIV/0!
A23: 1.1 new 2 | I23: =(H23/G23) -> #DIV/0!
A24: 1.1 new 3 | I24: =(H24/G24) -> #DIV/0!
B26: National Performance Indicator 1.2
I27: II.) Number of
B28: Employment Supports | I28: Participants
H29: I.) Number of | I29: Achieving
B30: The number of low-income participants for whom | H30: Participants | I30: Outcome in
B31: barriers to initial or continuous employment | H31: Enrolled in | I31: Reporting
B32: are reduced or eliminated through assistance from | H32: Program(s) | I32: Period
B33: Community Action, as measured by one or more of
B34: the following: | H34: (#) | I34: (#)
A35: 1.2 A | B35: A. Obtained skills/competencies required for employment
A36: 1.2 B | B36: B. Completed ABE/GED and received certificate or diploma
A37: 1.2 C | B37: C. Completed post-secondary education program and obtained certificate or diploma
A38: 1.2 D | B38: D. Enrolled children in before or after school programs
A39: 1.2 E | B39: E. Obtained care for child or other dependant
A40: 1.2 F | B40: F. Obtained access to reliable transportation and/or driver's license
A41: 1.2 G | B41: G. Obtained health care services for themselves or family member
A42: 1.2 H | B42: H. Obtained and/or maintained safe and affordable housing
A43: 1.2 I | B43: I. Obtained food assistance
A44: 1.2 J | B44: J. Obtained non-emergency LIHEAP energy assistance
A45: 1.2 K | B45: K. Obtained non-emergency WX energy assistance
A46: 1.2 L | B46: L. Obtained other non-emergency energy assistance (State/local/private energy programs. Do Not Include LIHEAP or WX)
...

Sheet Goal 1 Notes
A1: Agency Notes and Clarifications on Goal 1:
A2: Low-income people become more self-sufficient.

Sheet Goal 2
B2: Agency Name | E2: =CoverSheet!D6 -> 0
B5: Goal 2: The conditions in which low-income people live are improved.
I7: II.) Number of
B8: National Performance Indicator 2.1 | I8: Opportunities
I9: and/or Community
B10: Community Improvement and Revitalization | H10: I. ) Number of | I10: Resources
H11: Projects or | I11: Preserved or
B12: Increase in, or safeguarding of, threatened opportunities and community resources or services | H12: Initiatives | I12: Increased
B13: for low-income people in the community as a result of Community Action projects/initiatives
B14: or advocacy with other public and private agencies, as measured by one or more of the following: | H14: (#) | I14: (#)
A15: 2.1 A | B15: A. Jobs created, or saved, from reduction or elimination in the community
A16: 2.1 B | B16: B. Accessible "living wage" jobs created, or saved, from reduction or elimination in the community
A17: 2.1 C | B17: C. Safe and affordable housing units created in the community
A18: 2.1 D | B18: D. Safe and affordable housing units in the community preserved or improved through construction, weatherization or rehabilitation achieved byCommunity Action activity or advocacy
A19: 2.1 E | B19: E. Accessible safe and affordable health care services/facilities for low-income people created, or saved from reduction or elimination
A20: 2.1 F | B20: F. Accessible safe and affordable child care or child development placement opportunities for low-income families created, or saved from reduction or elimination
A21: 2.1 G | B21: G. Accessible before-school and after-school program placement opportunities for low-income families created, or saved from reduction or elimination
A22: 2.1 H | B22: H. Accessible new or expanded transportation resources, or those that are saved from reduction or elimination, that are available to low-income people, including public or private transportation
A23: 2.1 I | B23: I. Accessible or increased educational and training placement opportunities, or those that are saved from reduction or elimination, that are available for low-income people in the community, including vocational, literacy, and life skill training, ABE/GED, and post secondary education
B24: In the rows below, please include any additional indicators that were not captured above.
B30: National Performance Indicator 2.2 | I30: II.) Number of
H31: I.) Number of | I31: Community Assets,
B32: Community Quality of Life and Assets | H32: Program | I32: Services or
H33: Initiatives or | I33: Facilities Preserved
B34: The quality of life and assets in low-income neighborhoods are | H34: Advocacy Efforts | I34: or Increased
B35: improved by Community Action initiative or advocacy, as
B36: measured by one or more of the following: | H36: (#) | I36: (#)
A37: 2.2 A | B37: A. Increases in community assets as a result of a change in law, regulation or policy, which results in improvements in quality of life and assets
A38: 2.2 B | B38: B. Increase in the availability or preservation of community facilities
A39: 2.2 C | B39: C. Increase in the availability or preservation of community services to improve public health and safety
A40: 2.2 D | B40: D. Increase in the availability or preservation of commercial services within low-income neighborhoods
A41: 2.2 E | B41: E. Increase in or preservation of neighborhood quality-of-life resources
B42: In the rows below, please include any additional indicators that were not captured above.
A43: 2.2 new 1
A44: 2.2 new 2
A45: 2.2 new 3
B48: National Performance Indicator 2.3
H49: I.) Total
B50: Community Engagement | H50: Contribution by
H51: Community
...

Sheet Goal 2 Notes
A1: Agency Notes and Clarifications on Goal 2:
A2: The conditions in which low-income people live are improved.

Sheet Goal 3
B2: Agency Name | C2: =CoverSheet!D6 -> 0
B5: Goal 3: Low-income people own a stake in their community.
B8: National Performance Indicator 3.1
G9: I.) Total Number of
B10: Community Enhancement through Maximum Feasible Participation | G10: Volunteer Hours
B12: The number of volunteer hours donated to Community Action. | G12: (#)
A13: 3.1 A | B13: A. Total number of volunteer hours donated by low-income individuals to Community Action (This is ONLY the number ofvolunteer hours from individuals who are low-income)
B14: In the rows below, please include any additional indicators that were not captured above.
A15: 3.1 new 1
A16: 3.1 new 2
B19: National Performance Indicator 3.2
B21: Community Empowerment through Maximum Feasible
B22: Participation
G23: I.) Number of
B24: The number low-income people mobilized as a direct | G24: Low-Income
B25: result of Community Action initiative to engage in activities | G25: People
B26: that support and promote their own well-being and that of
B27: their community, as measured by one or more of the following: | G27: (#)
A28: 3.2 A | B28: A. Number of low-income people participating in formal community organizations, government, boards or councils that provide input to decision-making and policy-setting through Community Action efforts
A29: 3.2 B | B29: B. Number of low-income people acquiring businesses in their community as a result of Community Action assistance
A30: 3.2 C | B30: C. Number of low-income people purchasing their own home in their community as a result of Community Action assistance
A31: 3.2 D | B31: D. Number of low-income people engaged in non-governance community activities or groups created or supported by Community Action
B32: In the rows below, please include any additional indicators that were not captured above.
A33: 3.2 new 1
A34: 3.2 new 2
B38: Next

Sheet Goal 3 Notes
A1: Agency Notes and Clarifications on Goal 3:
A2: Low-income people own stake in their community.

Sheet Goal 4
B2: Agency Name | C2: =CoverSheet!D6 -> 0
B5: Goal 4: Partnerships among supporters and providers of services to low-income people are achieved.
B8: National Performance Indicator 4.1
B10: Expanding Opportunities through
B11: Community-Wide Partnerships
B13: The number of organizations, both public and private, | G13: I.) Number of | H13: II.) Number of
B14: that Community Action actively works with to expand | G14: Organizations | H14: Partnerships
B15: resources and opportunities in order to achieve family
B16: and community outcomes.
G17: (#) | H17: (#)
A18: 4.1 A | B18: A. Nonprofit
A19: 4.1 B | B19: B. Faith Based
A20: 4.1 C | B20: C. Local Government
A21: 4.1 D | B21: D. State Government
A22: 4.1 E | B22: E. Federal Government
A23: 4.1 F | B23: F. For-Profit Business or Corporation
A24: 4.1 G | B24: G. Consortiums/Collaboration
A25: 4.1 H | B25: H. Housing Consortiums/Collaboration
A26: 4.1 I | B26: I. School Districts
A27: 4.1 J | B27: J. Institutions of post secondary education/training
A28: 4.1 K | B28: K. Financial/Banking Institutions
A29: 4.1 L | B29: L. Health Service Institutions
A30: 4.1 M | B30: M. State wide associations or collaborations
B31: In the rows below, please add other types of partners with which your CAA has formed relationships that were not captured above. Please describe these partnerships in Goal 4 Notes.
A32: 4.1 new 1
A33: 4.1 new 2
A34: 4.1 new 3
A35: 4.1 N | B35: N. The total number of organizations and total number of partnerships CAAs work with to promote family and community outcomes (automatically calculates) | G35: =SUM(G32:G34,G18:G30) -> 0 | H35: =SUM(H32:H34,H18:H30) -> 0
B38: Next

Sheet Goal 4 Notes
A1: Agency Notes and Clarifications on Goal 4:
A2: Partnerships among supporters and providers of services
A3: to low-income people are achieved.

Sheet Goal 5
B2: Agency Name | C2: =CoverSheet!D6 -> 0
B5: Goal 5: Agencies increase their capacity to achieve results.
B8: National Performance Indicator 5.1
B10: Agency Development
B12: The number of human capital resources available to | G12: I.) Resources
B13: Community Action that increase agency capacity to | G13: in
B14: achieve family and community outcomes, as measured | G14: Agency
B15: by one or more of the following:
G16: (#)
A17: 5.1 A | B17: A. Number of Certified Community Action Professionals
A18: 5.1 B | B18: B. Number of Nationally Certified ROMA Trainers
A19: 5.1 C | B19: C. Number of Family Development Certified Staff
A20: 5.1 D | B20: D. Number of Child Development Certified Staff
A22: 5.1 E | B22: E. Number of staff attending trainings
A23: 5.1 F | B23: F. Number of board members attending trainings
A25: 5.1 G | B25: G. Hours of staff in trainings
A26: 5.1 H | B26: H. Hours of board members in trainings
B28: In the rows below, please include any additional indicators that were not captured above. Please describe these measures in Goal 5 Notes.
A30: 5.1 new 1
A31: 5.1 new 2
A32: 5.1 new 3
B35: Next

Sheet Goal 5 Notes
A1: Agency Notes and Clarifications on Goal 5:
A2: Agencies increase their capacity to achieve results.

Sheet Goal 6
B2: Agency Name | C2: =CoverSheet!D6 -> 0
B5: Goal 6: Low-income people, especially vulnerable populations, achieve their potential by strengthening family and other supportive environments.
I7: I.) Number of
B8: National Performance Indicator 6.1 | I8: Vulnerable
I9: Individuals
B10: Independent Living | I10: Living
I11: Independently
B12: The number of vulnerable individuals receiving services from Community Action
B13: who maintain an independent living situation as a result of those services: | I13: (#)
A14: 6.1 A | B14: A. Senior Citizens(seniors can be reported twice, once under Senior Citizens and again if they are disabled under Individuals with Disabilities, ages 55-over)
A15: 6.1 B | B15: B. Individuals with Disabilities Ages:
B16: 0-17
B17: 18-54
B18: 55-over
B19: Age Unknown
B20: TOTAL Individuals with disabilities (automatically calculates) | I20: =SUM(I16:I19) -> 0
B21: In the rows below, please include any additional indicators that were not captured above.
A22: 6.1 new 1
A23: 6.1 new 2
A24: 6.1 new 3
B27: National Performance Indicator 6.2
B29: Emergency Assistance | G29: I.) Number | H29: II.) Number
G30: of Individuals | H30: of Individuals
B31: The number of low-income individuals served by | G31: Seeking | H31: Receiving
B32: Community Action who sought emergency assistance | G32: Assistance | H32: Assistance
B33: and the number of those individuals for whom
B34: assistance was provided, including such services as: | G34: (#) | H34: (#)
A35: 6.2 A | B35: A. Emergency Food
A36: 6.2 B | B36: B. Emergency fuel or utility payments funded by LIHEAP or other public and private funding sources
A37: 6.2 C | B37: C. Emergency Rent or Mortgage Assistance
A38: 6.2 D | B38: D. Emergency Car or Home Repair (i.e. structural, appliance, heating system, etc.)
A39: 6.2 E | B39: E. Emergency Temporary Shelter
A40: 6.2 F | B40: F. Emergency Medical Care
A41: 6.2 G | B41: G. Emergency Protection from Violence
A42: 6.2 H | B42: H. Emergency Legal Assistance
A43: 6.2 I | B43: I. Emergency Transportation
A44: 6.2 J | B44: J. Emergency Disaster Relief
A45: 6.2 K | B45: K. Emergency Clothing
B46: In the rows below, please include any additional indicators that were not captured above.
A47: 6.2 new 1
...

Sheet Goal 6 Notes
A1: Agency Notes and Clarifications on Goal 6:
A2: Low-income people, especially vulnerable populations, achieve their
A3: potential by strengthening family and other supportive environments.
