Workbook
Name ACHI: PLANTA!$Q$4:$Q$15
Name ALTOS: PLANTA!$Q$17:$Q$18
Name ALTOSDELROSARIO: PLANTA!$Q$17:$Q$18
Name ARENAL: PLANTA!$Q$20:$Q$21
Name ARJONA: PLANTA!$Q$23:$Q$33
Name ARROYOHONDO: PLANTA!$Q$35:$Q$36
Name BARRANCODELOBA: PLANTA!$Q$38:$Q$42
Name CALAMAR: PLANTA!$Q$51:$Q$55
Name CANTAGALLO: PLANTA!$Q$57:$Q$58
Name CENTRO_EDUCATIVO__DE_CASTAÂ¿AL: PLANTA!$R$502:$R$506
Name CENTRO_EDUCATIVO__DE_LA_VENTURA: PLANTA!$R$1506:$R$1516
Name CENTRO_EDUCATIVO_ALTA_MONTAÑA: PLANTA!$R$447:$R$456
Name CENTRO_EDUCATIVO_ANTONIO_NARIÑO: PLANTA!$R$997:$R$1003
Name CENTRO_EDUCATIVO_BUENAVISTA: PLANTA!$R$1305:$R$1323
Name CENTRO_EDUCATIVO_CARACOLI: PLANTA!$R$410:$R$416
Name CENTRO_EDUCATIVO_CORCOVADO: PLANTA!$R$740:$R$754
Name CENTRO_EDUCATIVO_DE_AGUAS_PRIETAS: PLANTA!$R$1544:$R$1547
Name CENTRO_EDUCATIVO_DE_CHIRICOCO: PLANTA!$R$1231:$R$1234
Name CENTRO_EDUCATIVO_DE_FATIMA: PLANTA!$R$1276:$R$1286
Name CENTRO_EDUCATIVO_DE_GALLEGO: PLANTA!$R$4:$R$9
Name CENTRO_EDUCATIVO_DE_REGENCIA: PLANTA!$R$715:$R$738
Name CENTRO_EDUCATIVO_DE_RIO_NUEVO: PLANTA!$R$36:$R$43
Name CENTRO_EDUCATIVO_DE_VIOLO: PLANTA!$R$513:$R$518
Name CENTRO_EDUCATIVO_EL_PARAISO: PLANTA!$R$1009:$R$1022
Name CENTRO_EDUCATIVO_LA_CHAPETONA: PLANTA!$R$481:$R$484
Name CENTRO_EDUCATIVO_LA_ORIGINAL_DE_LAS_BRISAS: PLANTA!$R$1403:$R$1409
Name CENTRO_EDUCATIVO_LA_VICTORIA: PLANTA!$R$289:$R$315
Name CENTRO_EDUCATIVO_LAS_DELICIAS_MINAS_DE_SANTA_CRUZ: PLANTA!$R$212:$R$214
Name CENTRO_EDUCATIVO_MAMON_DE_MARIA: PLANTA!$R$457:$R$465
Name CENTRO_EDUCATIVO_POZO_AZUL: PLANTA!$R$1151:$R$1178
Name CENTRO_EDUCATIVO_RUFINA_VIEJA: PLANTA!$R$894:$R$897
Name CENTRO_EDUCATIVO_SAN_AGUSTIN: PLANTA!$R$1067:$R$1072
Name CENTRO_EDUCATIVO_SAN_BENITO: PLANTA!$R$1287:$R$1297
Name CENTRO_EDUCATIVO_SAN_BLAS: PLANTA!$R$1395:$R$1402
Name CENTRO_EDUCATIVO_SAN_FRANCISCO: PLANTA!$R$1261:$R$1275
Name CENTRO_EDUCATIVO_SAN_ISIDRO: PLANTA!$R$393:$R$399
Name CENTRO_EDUCATIVO_SAN_JOAQUIN: PLANTA!$R$1365:$R$1371
Name CENTRO_EDUCATIVO_SAN_JOSE_DE_CHIQUITO: PLANTA!$R$1561:$R$1565
Name CENTRO_EDUCATIVO_SAN_LUCAS: PLANTA!$R$1242:$R$1260
Name CENTRO_EDUCATIVO_SAN_LUIS_GONZAGA: PLANTA!$R$1025:$R$1026
Name CENTRO_EDUCATIVO_SANTA_FE_ICOTEA: PLANTA!$R$580:$R$583
Name CENTRO_EDUCATIVO_SANTA_LUCIA: PLANTA!$R$1023:$R$1024
Name CENTRO_EDUCATIVO_SEGUNDO_BENIGNO_DE_LA_PEÂ¿A: PLANTA!$R$1477:$R$1480
Name CENTRO_EDUCATIVO_VILLA_FLOR: PLANTA!$R$1351:$R$1363
Name CICUCO: PLANTA!$Q$60:$Q$62
Name CLEMENCIA: PLANTA!$Q$64:$Q$65
Name CORDOBA: PLANTA!$Q$44:$Q$49
Name ELCARMENDEBOLIVAR: PLANTA!$Q$67:$Q$80
Name ELGUAMO: PLANTA!$Q$82:$Q$83
Name ELPEÑON: PLANTA!$Q$86:$Q$90
Name HATILLODELOBA: PLANTA!$Q$92:$Q$95
Name INSTITUCION__EDUCATIVA__TECNICA__AGROPECUARIA_EZEQUIEL_MARTELO_PIMIENTA_DE_SAN_JOAQUIN: PLANTA!$R$555:$R$557
Name INSTITUCION__EDUCATIVA_DE_EL_PEÑONCITO: PLANTA!$R$492:$R$501
Name INSTITUCION__EDUCATIVA_DOMINGO_TARRA_GUARDO: PLANTA!$R$145:$R$148
Name INSTITUCION__EDUCATIVA_MANUEL_EDMUNDO_MENDOZA: PLANTA!$R$400:$R$403
Name INSTITUCION__EDUCATIVA_SAGRADO_CORAZON_DE_JESUS: PLANTA!$R$93:$R$102
Name INSTITUCION__EDUCATIVA_TECNICA_AGROPECUARIA_DE_EL_GUAMO: PLANTA!$R$474:$R$479
Name INSTITUCION__EDUCATIVA_TECNICA_AGROPECUAROA_DE_EL_GUAMO: PLANTA!$R$474:$R$479
Name INSTITUCION_EDU_TEC_AGROPECUARIA_Y_BACHILLER_ACADEMICO_PARA_LA_JORN_NOCTURNA_RODOLFO_BARRIOS_CABRERA: PLANTA!$R$1086:$R$1089
Name INSTITUCION_EDUCACATIVA_TECNICA_AGROPECUARIA_DE_VILLANUEVA: PLANTA!$R$1592:$R$1598

Sheet Hoja1
A1: CODEMPLEADO
A2: 1 | B2: BERNABE FRANCO RODRIGUEZ | D2: Docente de aula
A3: 8395 | B3: AGUSTIN MATEOS RODRIGUEZ | D3: Docente de aula (Encargado como Rector)
A4: 9889 | B4: JAVIER CIRIACO CIRUJANO ARJONA | D4: Docente de aula (Encargado como Coordinador)
A5: 10870 | B5: ARTURO GARCIA NUÑEZ | D5: Coordinador
A6: 32150 | B6: HILDEGAR BINDER SCHLAGER | D6: Coordinador (Encargado como Rector)
A7: 73236 | B7: MARLON DIAZ PEREZ | D7: Rector
A8: 109241 | B8: JESUS TOMAS ZAPATA MALDONADO | D8: Director de Nucleo
A9: 124517 | B9: FRANCESCO PODAVINI CAVAGNINI | D9: Director Rural
A10: 130139 | B10: CARLOS JULIO CANAS FONTALVO | D10: Supervisor
A11: 135231 | B11: JAIME PADILLA MANRIQUE | D11: Profesional Universitario
A12: 151298 | B12: FRANCISCO JOSE ALFREDO GIORGI CONTRERAS | D12: Tecnico Operativo
A13: 202947 | B13: LUIS ALFONSO SERRANO GOMEZ | D13: Auxiliar Administrativo
... A21: 809205 | B21: MARCIAL ENRIQUE PEREZ FERNANDEZ | D21: Operario
A22: 813894 | B22: EUSEBIO ATENCIO RODRIGUEZ
A23: 836096 | B23: LUIS RAFAEL DIZES PARRA
A24: 836239 | B24: ADOLFO ANTONIO PEREZ MORENO
A25: 857925 | B25: NICANOR PARRA PEREZ
A26: 861771 | B26: DIOGENES ALFREDO BUSTILLO OCHOA
A27: 876100 | B27: ANDRES CONTRERAS PRENS
A28: 876643 | B28: FRANCISCO ABRAHAM NAVARRO MIRANDA
A29: 876677 | B29: ALBERTO GOMEZ MONTERO
A30: 876783 | B30: RAUL ALFONSO MARRUGO CUENTAS
A31: 878044 | B31: NIEVES UBALDO DIAZ CARDENAS
A32: 879752 | B32: EDUARDO VICTOR BETANCOURT VILLADIEGO
A33: 879854 | B33: DORMELINO JOSE FLOREZ GARCERANT
... A17094: 1143358436 | B17094: OTILIA MARGARITA CABARCAS AYALA

Sheet INDICACIONES
B1: INSTRUCCIONES PARA DILIGENCIAR EL FORMATO
B2: TODOS LOS CAMPOS DEBEN SER DILIGENCIADOS OBLIGATORIAMENTE
A3: 1 | B3: SELECCIONAR EN LA PARTE DE ABAJO LA HOJA PLANTA
A4: 2 | B4: INGRESAR EL NUMERO DE CEDULA, EL ARCHIVO MOSTRARA AUTOMATICAMENTE EL NOMBRE DEL FUNCIONARIO
A5: NOTA | B5: SI SE LLEGA A INGRESAR EL NUMERO DE CEDULA Y NO SE CARGA EL NOMBRE VERIFIQUE HABER INGRESADO CORRECTAMENTE EL NUMERO DE CEDULA (EL ARCHIVO CUENTA CON LA
B6: BASE DE DATOS ACTUALIZADA DE LOS FUNCIONARIOS QUE HACEN PARTE DE LA SECRETARIA DE EDUCACION DE Bolívar).
A7: 3 | B7: SELECCIONAR LA COLUMNA DE CARGO HACER CLICK EN EL BOTON (COMO LO INDICA LA IMAGEN), Y SELECCIONAR EL CARGO DEL FUNCIONARIO
A8: 4 | B8: SELECCIONAR LA COLUMNA DEL MUNICIPIO HACER CLICK EN EL BOTON Y SELECCIONAR EL MUNICIPIO DE LA I.E.
A9: NOTA | B9: CUANDO SELECCIONA EL MUNICIPIO EN LA COLUMNA DE LA I.E., SE CARGAN LAS I.E. QUE HACEN PARTE DEL MUNICIPIO SELECCIONADO ANTERIORMENTE
A10: 5 | B10: SELECCIONAR LA INSTITUCION EDUCATIVA
A11: NOTA | B11: CUANDO SELECCIONA LA I.E. EN LA SIGUIENTE COLUMNA SE CARGAN LAS SEDES QUE TIENE LA INSTITUCION EDUCATIVA
A12: 6 | B12: SELECCIONAR LA SEDE DE LA I.E.
A13: 7 | B13: SELECCIONAR EL AREA QUE DICTA
A14: 8 | B14: SELECCIONAR EL NIVEL QUE DICTA
A15: 9 | B15: EN OBSERVACIONES REDACTAR BREVEMENTE ALGUN COMENTARIO (SI ES NECESARIO)
B18: ACLARACION
B19: LAS INSTITUCIONES Y LAS SEDES QUE SE ENCUENTRAN CARGADAS EN EL ARCHIVO, ESTA BASADO EN EL DIRECTORIO UNICO DE ESTABLECIMIENTOS (DUE) DE 2011,
B20: SI SU INSTITUCION Y/O SEDE NO LLEGA APARECER, ESTAS PUEDEN SER ESCRITAS EN LOS 2 CAMPOS QUE SE ENCUENTRAN DESPUES DE LA COLUMNA DE
B21: OBSERVACIONES.
B22: EN CASO DE ALGUNA DUDA ESCRIBIR AL CORREO: dflorez@sedbolivar.gov.co

Sheet PLANTA
A2: No | B2: CEDULA | C2: NOMBRE Y APELLIDOS | D2: CARGO | E2: MUNICIPIO | F2: INSTITUCION EDUCATIVA | G2: SEDE | H2: AREA EDUCATIVA | I2: NIVEL DICTA | J2: OBSERVACIONES | K2: I.E. | L2: SEDE2
A3: 1 | C3: =VLOOKUP(Tabla1[[#This Row],[CEDULA]],Hoja1!$A$2:$B$17094,2,0) -> #N/A | M3: Docente de aula | O3: PREESCOLAR | P3: ACHI | Q3: ACHI | R3: ACHI
A4: 2 | C4: =VLOOKUP(Tabla1[[#This Row],[CEDULA]],Hoja1!$A$2:$B$17094,2,0) -> #N/A | M4: Docente de aula (Encargado como Rector) | N4: PREESCOLAR | O4: PRIMARIA | P4: ALTOSDELROSARIO | Q4: CENTRO_EDUCATIVO_DE_GALLEGO | R4: CENTRO EDUCATIVO DE GALLEGO
A5: =A4+1 -> 3 | C5: =VLOOKUP(Tabla1[[#This Row],[CEDULA]],Hoja1!$A$2:$B$17094,2,0) -> #N/A | M5: Docente de aula (Encargado como Coordinador) | N5: PRIMARIA | O5: SECUNDARIA | P5: ARENAL | Q5: INSTITUCION_EDUCATIVA_DE_BUENAVISTA | R5: SEDE PRINCIPAL - CENTRO EDUCATIVO DE GALLEGO
A6: =A5+1 -> 4 | C6: =VLOOKUP(Tabla1[[#This Row],[CEDULA]],Hoja1!$A$2:$B$17094,2,0) -> #N/A | M6: Docente de Apoyo | N6: CIENCIAS NATURALES Y EDUCACION AMBIENTAL | O6: NO APLICA | P6: ARJONA | Q6: INSTITUCION_EDUCATIVA_TECNICA_DE__PUERTO_VENECIA | R6: SEDE - ESC RUR MIX DE GALLEGO ABAJO
A7: =A6+1 -> 5 | C7: =VLOOKUP(Tabla1[[#This Row],[CEDULA]],Hoja1!$A$2:$B$17094,2,0) -> #N/A | M7: Coordinador | N7: CIENCIAS SOCIALES | P7: ARROYOHONDO | Q7: INSTITUCION_EDUCATIVA_DE_GUACAMAYO | R7: SEDE - ESC RUR MIX DEL GUAYABO
A8: =A7+1 -> 6 | C8: =VLOOKUP(Tabla1[[#This Row],[CEDULA]],Hoja1!$A$2:$B$17094,2,0) -> #N/A | M8: Coordinador (Encargado como Rector) | N8: EDUC. ARTISTICA - ARTES PLASTICAS | P8: BARRANCODELOBA | Q8: CENTRO_EDUCATIVO_DE_RIO_NUEVO | R8: SEDE - ESC NVA DE LAS POZONAS
A9: =A8+1 -> 7 | C9: =VLOOKUP(Tabla1[[#This Row],[CEDULA]],Hoja1!$A$2:$B$17094,2,0) -> #N/A | M9: Rector | N9: EDUC. ARTISTICA - MUSICA | P9: CORDOBA | Q9: INSTITUCION_EDUCATIVA_TECNICA_DE_PROMOCION_SOCIAL | R9: SEDE - ESCUELA NUEVA DE OJO LARGO
A10: =A9+1 -> 8 | C10: =VLOOKUP(Tabla1[[#This Row],[CEDULA]],Hoja1!$A$2:$B$17094,2,0) -> #N/A | M10: Director de Nucleo | N10: EDUC. ARTISTICA - ARTES ESCENICA | P10: CALAMAR | Q10: INSTITUCION_EDUCATIVA_TECNICA_DE_PLAYA_ALTA | R10: INSTITUCION EDUCATIVA DE BUENAVISTA
A11: =A10+1 -> 9 | C11: =VLOOKUP(Tabla1[[#This Row],[CEDULA]],Hoja1!$A$2:$B$17094,2,0) -> #N/A | M11: Director Rural | N11: EDUC. ARTISTICA - DANZAS | P11: CANTAGALLO | Q11: INSTITUCION_EDUCATIVA_DE_SAN_MIGUEL_DE_TRES_CRUCES | R11: SEDE PRINCIPAL - INSTITUCION EDUCATIVA DE BUENAVISTA
A12: =A11+1 -> 10 | C12: =VLOOKUP(Tabla1[[#This Row],[CEDULA]],Hoja1!$A$2:$B$17094,2,0) -> #N/A | M12: Supervisor | N12: EDUC. FISICA, RECREACION Y DEPORTE | P12: CICUCO | Q12: INSTITUCION_EDUCATIVA_TECNICA_AGROPECUARIA_RICARDO_CASTELLAR_BARRIOS | R12: SEDE - ESC NUEVA DEL ROSARIO
A13: =A12+1 -> 11 | C13: =VLOOKUP(Tabla1[[#This Row],[CEDULA]],Hoja1!$A$2:$B$17094,2,0) -> #N/A | M13: Profesional Universitario | N13: EDUC. ETICA Y EN VALORES | P13: CLEMENCIA | Q13: INSTITUCION_EDUCATIVA_SAN_JOSE_DE_ACHI | R13: SEDE - ESCUELA NUEVA CENTRO ALEGRE CAUCA
A14: =A13+1 -> 12 | C14: =VLOOKUP(Tabla1[[#This Row],[CEDULA]],Hoja1!$A$2:$B$17094,2,0) -> #N/A | M14: Tecnico Operativo | N14: EDUC. RELIGIOSA | P14: ELCARMENDEBOLIVAR | Q14: INSTITUCION_EDUCATIVA_SANTA_LUCIA | R14: SEDE - ESCUELA NUEVA DE PALMIRA
A15: =A14+1 -> 13 | C15: =VLOOKUP(Tabla1[[#This Row],[CEDULA]],Hoja1!$A$2:$B$17094,2,0) -> #N/A | M15: Auxiliar Administrativo | N15: HUMANIDADES Y LENGUA CASTELLANA | P15: ELGUAMO | Q15: INSTITUCION_EDUCATIVA_LOS_NISPEROS | R15: SEDE - CENTRO EDUCATIVO PUERTO ISABEL
A16: =A15+1 -> 14 | C16: =VLOOKUP(Tabla1[[#This Row],[CEDULA]],Hoja1!$A$2:$B$17094,2,0) -> #N/A | M16: Auxiliar Area de Salud | N16: IDIOMA EXTRANJERO FRANCES | P16: ELPEÑON | Q16: ALTOS_DEL_ROSARIO | R16: SEDE - ESCUELA RURAL MIXTA LA FRONTERA
A17: =A16+1 -> 15 | C17: =VLOOKUP(Tabla1[[#This Row],[CEDULA]],Hoja1!$A$2:$B$17094,2,0) -> #N/A | M17: Secretario Ejecutivo | N17: IDIOMA EXTRANJERO INGLES | P17: HATILLODELOBA | Q17: INSTITUCION__EDUCATIVA_SAGRADO_CORAZON_DE_JESUS | R17: INSTITUCION EDUCATIVA TECNICA DE PUERTO VENECIA
A18: =A17+1 -> 16 | C18: =VLOOKUP(Tabla1[[#This Row],[CEDULA]],Hoja1!$A$2:$B$17094,2,0) -> #N/A | M18: Secretario | N18: MATEMATICAS | P18: MAHATES | Q18: INSTITUCION_EDUCATIVA_ALEJANDRO_DURAN_DIAZ | R18: SEDE PRINCIPAL - INSTITUCION EDUCATIVA TECNICA DE PUERTO VENECIA
... A23: =A22+1 -> 21 | C23: =VLOOKUP(Tabla1[[#This Row],[CEDULA]],Hoja1!$A$2:$B$17094,2,0) -> #N/A | M23: Operario | N23: CIENCIAS ECONOMICAS Y POLITICAS | P23: MORALES | Q23: INSTITUCION_EDUCATIVA_FRANCISCO_DE_PAULA_SANTANDER | R23: SEDE - ESC NVA DE NUEVO ORIENTE
A24: =A23+1 -> 22 | C24: =VLOOKUP(Tabla1[[#This Row],[CEDULA]],Hoja1!$A$2:$B$17094,2,0) -> #N/A | N24: AREAS DE APOYO PARA EDUCACION ESPECIAL | P24: NOROSI | Q24: INSTITUCION__EDUCATIVA_DOMINGO_TARRA_GUARDO | R24: SEDE - ESC NVA DE BOYACA
A25: =A24+1 -> 23 | C25: =VLOOKUP(Tabla1[[#This Row],[CEDULA]],Hoja1!$A$2:$B$17094,2,0) -> #N/A | N25: OTRAS | P25: PINILLOS | Q25: INSTITUCION_EDUCATIVA__TECNICA__INDUSTRIAL_DON_BOSCO | R25: SEDE - ESC NVA DE BUENOS AIRES
A26: =A25+1 -> 24 | C26: =VLOOKUP(Tabla1[[#This Row],[CEDULA]],Hoja1!$A$2:$B$17094,2,0) -> #N/A | P26: RIOVIEJO | Q26: INSTITUCION_EDUCATIVA_MARIA_MICHELSEN_DE_LOPEZ | R26: SEDE - ESC NVA MIX LA CEIBA
A27: =A26+1 -> 25 | C27: =VLOOKUP(Tabla1[[#This Row],[CEDULA]],Hoja1!$A$2:$B$17094,2,0) -> #N/A | P27: REGIDOR | Q27: INSTITUCION_EDUCATIVA_DE_GAMBOTE | R27: SEDE - ESC NVA CENTRO ALEGRE
A28: =A27+1 -> 26 | C28: =VLOOKUP(Tabla1[[#This Row],[CEDULA]],Hoja1!$A$2:$B$17094,2,0) -> #N/A | P28: SANCRISTOBAL | Q28: INTITUCION_EDUCATIVA_TECNICA_AGROINDUSTRIAL_REPUBLICA_DE_COLOMBIA | R28: SEDE - ESC NVA DE SAN ROQUE
A29: =A28+1 -> 27 | C29: =VLOOKUP(Tabla1[[#This Row],[CEDULA]],Hoja1!$A$2:$B$17094,2,0) -> #N/A | P29: SANESTANISLAO | Q29: INSTITUCION_EDUCATIVA__DE_SINCERIN | R29: SEDE - ESCUELA NUEVA BELEN DE LA BETA
A30: =A29+1 -> 28 | C30: =VLOOKUP(Tabla1[[#This Row],[CEDULA]],Hoja1!$A$2:$B$17094,2,0) -> #N/A | P30: SANFERNANDO | Q30: INSTITUCION_EDUCATIVA_BENJAMIN_HERRERA | R30: SEDE - ESC NVA MIXTA LAS TIJERAS
A31: =A30+1 -> 29 | C31: =VLOOKUP(Tabla1[[#This Row],[CEDULA]],Hoja1!$A$2:$B$17094,2,0) -> #N/A | P31: SANJACINTO | Q31: INSTITUCION_EDUCATIVA_CATALINA_HERRERA | R31: SEDE - ESC RUR MIX DE SOL Y SOMBRA
A32: =A31+1 -> 30 | C32: =VLOOKUP(Tabla1[[#This Row],[CEDULA]],Hoja1!$A$2:$B$17094,2,0) -> #N/A | P32: SANJACINTODELCAUCA | Q32: INSTITUCION_EDUCATIVA_DE_ROCHA | R32: INSTITUCION EDUCATIVA DE GUACAMAYO
A33: =A32+1 -> 31 | C33: =VLOOKUP(Tabla1[[#This Row],[CEDULA]],Hoja1!$A$2:$B$17094,2,0) -> #N/A | P33: SANJUANNEPOMUCENO | Q33: INSTITUCION_EDUCATIVA_DE_PUERTO_BADEL | R33: SEDE PRINCIPAL - INSTITUCION EDUCATIVA DE GUACAMAYO
A34: =A33+1 -> 32 | C34: =VLOOKUP(Tabla1[[#This Row],[CEDULA]],Hoja1!$A$2:$B$17094,2,0) -> #N/A | P34: SANMARTINDELOBA | Q34: ARROYOHONDO | R34: SEDE - ESC NVA DE LA LUCHA
A35: =A34+1 -> 33 | C35: =VLOOKUP(Tabla1[[#This Row],[CEDULA]],Hoja1!$A$2:$B$17094,2,0) -> #N/A | P35: SANPABLO | Q35: INSTITUCION_EDUCATIVA_DE_ARROYO_HONDO_ROBERTO_BOTERO_MORALES | R35: SEDE - COLEGIO DPTAL. DE BTO. GUACAMAYO
A36: =A35+1 -> 34 | C36: =VLOOKUP(Tabla1[[#This Row],[CEDULA]],Hoja1!$A$2:$B$17094,2,0) -> #N/A | P36: SANTACATALINA | Q36: INSTITUCION_EDUCATIVA_DE_MACHADO | R36: CENTRO EDUCATIVO DE RIO NUEVO
A37: =A36+1 -> 35 | C37: =VLOOKUP(Tabla1[[#This Row],[CEDULA]],Hoja1!$A$2:$B$17094,2,0) -> #N/A | P37: SANTAROSA | Q37: BARRANCODELOBA | R37: SEDE PRINCIPAL - CENTRO EDUCATIVO DE RIO NUEVO
... A46: =A45+1 -> 44 | C46: =VLOOKUP(Tabla1[[#This Row],[CEDULA]],Hoja1!$A$2:$B$17094,2,0) -> #N/A | P46: ZAMBRANO | Q46: INSTITUCION_EDUCATIVA_TECNICA__DE_TACAMOCHO | R46: SEDE - CENTRO EDUCATIVO ARENAS
A47: =A46+1 -> 45 | C47: =VLOOKUP(Tabla1[[#This Row],[CEDULA]],Hoja1!$A$2:$B$17094,2,0) -> #N/A | Q47: INSTITUCION_EDUCATIVA_TECNICA_AGROPECUARIA_LUIS_VILLAFAÑE_PAREJA | R47: INSTITUCION EDUCATIVA TECNICA DE PLAYA ALTA
A48: =A47+1 -> 46 | C48: =VLOOKUP(Tabla1[[#This Row],[CEDULA]],Hoja1!$A$2:$B$17094,2,0) -> #N/A | Q48: INSTITUCION_EDUCATIVA_RAFAEL_NUÑEZ_DE_SAN_ANDRES | R48: SEDE PRINCIPAL - INSTITUCION EDUCATIVA TECNICA DE PLAYA ALTA
A49: =A48+1 -> 47 | C49: =VLOOKUP(Tabla1[[#This Row],[CEDULA]],Hoja1!$A$2:$B$17094,2,0) -> #N/A | Q49: INSTITUCION_EDUCATIVA_DE_SINCELEJITO | R49: SEDE - ESC NVA LA GOLOSINA
A50: =A49+1 -> 48 | C50: =VLOOKUP(Tabla1[[#This Row],[CEDULA]],Hoja1!$A$2:$B$17094,2,0) -> #N/A | Q50: CALAMAR | R50: SEDE - ESCUELA RURAL MIXTA BRISAS DEL CAUCA
A51: =A50+1 -> 49 | C51: =VLOOKUP(Tabla1[[#This Row],[CEDULA]],Hoja1!$A$2:$B$17094,2,0) -> #N/A | Q51: INSTITUCION_EDUCATIVA_TECNICA_AGROPECUARIA_DE_EL_YUCAL | R51: INSTITUCION EDUCATIVA DE SAN MIGUEL DE TRES CRUCES
A52: =A51+1 -> 50 | C52: =VLOOKUP(Tabla1[[#This Row],[CEDULA]],Hoja1!$A$2:$B$17094,2,0) -> #N/A | Q52: INSTITUCION_EDUCATIVA_FRANCISCO_DE_PAULA_SANTANDER___BARRIO_SUR | R52: SEDE PRINCIPAL - INSTITUCION EDUCATIVA DE SAN MIGUEL DE TRES CRUCES
A53: =A52+1 -> 51 | C53: =VLOOKUP(Tabla1[[#This Row],[CEDULA]],Hoja1!$A$2:$B$17094,2,0) -> #N/A | Q53: INSTITUCION_EDUCATIVA_GUSTAVO_SALOM_DE_BARRANCA_NUEVA | R53: SEDE - ESCUELA NUEVA DEL PARAISO
...

Sheet DUE
A1: ACHI
A2: CENTRO EDUCATIVO DE GALLEGO
A3: SEDE PRINCIPAL - CENTRO EDUCATIVO DE GALLEGO
A4: SEDE - ESC RUR MIX DE GALLEGO ABAJO
A5: SEDE - ESC RUR MIX DEL GUAYABO
A6: SEDE - ESC NVA DE LAS POZONAS
A7: SEDE - ESCUELA NUEVA DE OJO LARGO
A8: INSTITUCION EDUCATIVA DE BUENAVISTA
A9: SEDE PRINCIPAL - INSTITUCION EDUCATIVA DE BUENAVISTA
A10: SEDE - ESC NUEVA DEL ROSARIO
A11: SEDE - ESCUELA NUEVA CENTRO ALEGRE CAUCA
A12: SEDE - ESCUELA NUEVA DE PALMIRA
... A1625: SEDE - ESC NVA LA ESPERANZA
