Workbook

Sheet Calendario
B2: Andata 23/08/09 | D2: 1a giornata | F2: Ritorno 17/01/10 | I2: Andata 18/10/09 | K2: 8a giornata | M2: Ritorno 07/03/10 | P2: Andata 29/11/09 | R2: 14a giornata | T2: Ritorno 11/04/10
B3: 1 | C3: 1 | D3: Bologna | E3: Fiorentina | K3: Catania | L3: Cagliari | R3: Atalanta | S3: Roma
B4: 1 | C4: 2 | D4: Catania | E4: Sampdoria | K4: Chievo | L4: Bari | R4: Bari | S4: Siena
B5: 3 | C5: 2 | D5: Genoa | E5: Roma | K5: Genoa | L5: Inter | R5: Cagliari | S5: Juventus
B6: 1 | C6: 1 | D6: Inter | E6: Bari | K6: Juventus | L6: Fiorentina | R6: Catania | S6: Milan
B7: 1 | C7: 0 | D7: Juventus | E7: Chievo | K7: Lazio | L7: Sampdoria | R7: Chievo | S7: Palermo
B8: 1 | C8: 0 | D8: Lazio | E8: Atalanta | K8: Livorno | L8: Palermo | R8: Genoa | S8: Sampdoria
B9: 0 | C9: 0 | D9: Livorno | E9: Cagliari | K9: Milan | L9: Roma | R9: Inter | S9: Fiorentina
B10: 2 | C10: 1 | D10: Palermo | E10: Napoli | K10: Napoli | L10: Bologna | R10: Lazio | S10: Bologna
B11: 1 | C11: 2 | D11: Siena | E11: Milan | K11: Parma | L11: Siena | R11: Parma | S11: Napoli
B12: 2 | C12: 2 | D12: Udinese | E12: Parma | K12: Udinese | L12: Atalanta | R12: Udinese | S12: Livorno
B14: Andata 30/08/09 | D14: 2a giornata | F14: Ritorno 24/01/10 | I14: Andata 25/10/09 | K14: 9a giornata | M14: Ritorno 14/03/10 | P14: Andata 06/12/09 | R14: 15a giornata | T14: Ritorno 18/04/10
D15: Atalanta | E15: Genoa | K15: Atalanta | L15: Parma | R15: Bologna | S15: Udinese
D16: Bari | E16: Bologna | K16: Bari | L16: Lazio | R16: Fiorentina | S16: Atalanta
D17: Cagliari | E17: Siena | K17: Cagliari | L17: Genoa | R17: Genoa | S17: Parma
D18: Chievo | E18: Lazio | K18: Chievo | L18: Milan | R18: Juventus | S18: Inter
D19: Fiorentina | E19: Palermo | K19: Fiorentina | L19: Napoli | R19: Livorno | S19: Chievo
D20: Milan | E20: Inter | K20: Inter | L20: Catania | R20: Milan | S20: Sampdoria
D21: Napoli | E21: Livorno | K21: Palermo | L21: Udinese | R21: Napoli | S21: Bari
D22: Parma | E22: Catania | K22: Roma | L22: Livorno | R22: Palermo | S22: Cagliari
D23: Roma | E23: Juventus | K23: Sampdoria | L23: Bologna | R23: Roma | S23: Lazio
D24: Sampdoria | E24: Udinese | K24: Siena | L24: Juventus | R24: Siena | S24: Catania
B26: Andata 13/09/09 | D26: 3a giornata | F26: Ritorno 31/01/10 | I26: Andata 28/10/09 | K26: 10a giornata | M26: Ritorno 21/03/10 | P26: Andata 13/12/09 | R26: 16a giornata | T26: Ritorno 25/04/10
D27: Atalanta | E27: Sampdoria | K27: Bologna | L27: Siena | R27: Atalanta | S27: Inter
D28: Bologna | E28: Chievo | K28: Catania | L28: Chievo | R28: Bari | S28: Juventus
D29: Fiorentina | E29: Cagliari | K29: Genoa | L29: Fiorentina | R29: Cagliari | S29: Napoli
D30: Genoa | E30: Napoli | K30: Inter | L30: Palermo | R30: Catania | S30: Livorno
D31: Inter | E31: Parma | K31: Juventus | L31: Sampdoria | R31: Chievo | S31: Fiorentina
D32: Lazio | E32: Juventus | K32: Lazio | L32: Cagliari | R32: Lazio | S32: Genoa
D33: Livorno | E33: Milan | K33: Livorno | L33: Atalanta | R33: Milan | S33: Palermo
D34: Palermo | E34: Bari | K34: Napoli | L34: Milan | R34: Parma | S34: Bologna
D35: Siena | E35: Roma | K35: Parma | L35: Bari | R35: Sampdoria | S35: Roma
D36: Udinese | E36: Catania | K36: Udinese | L36: Roma | R36: Siena | S36: Udinese
B38: Andata 20/09/09 | D38: 4a giornata | F38: Ritorno 07/02/10 | I38: Andata 01/11/09 | K38: 11a giornata | M38: Ritorno 24/03/10 | P38: Andata 20/12/09 | R38: 17a giornata | T38: Ritorno 02/05/10
D39: Bari | E39: Atalanta | K39: Cagliari | L39: Atalanta | R39: Bologna | S39: Atalanta
D40: Cagliari | E40: Inter | K40: Chievo | L40: Udinese | R40: Fiorentina | S40: Milan
D41: Catania | E41: Lazio | K41: Fiorentina | L41: Catania | R41: Genoa | S41: Bari
D42: Chievo | E42: Genoa | K42: Juventus | L42: Napoli | R42: Inter | S42: Lazio
D43: Juventus | E43: Livorno | K43: Livorno | L43: Inter | R43: Juventus | S43: Catania
D44: Milan | E44: Bologna | K44: Milan | L44: Parma | R44: Livorno | S44: Sampdoria
...

Sheet Classifica
D2: Totale | H2: In casa | L2: Fuori casa | P2: Reti | S2: Media inglese
B3: Squadra | C3: Punti | D3: Giocate | E3: Vinte | F3: Nulle | G3: Perse | H3: Giocate | I3: Vinte | J3: Nulle | K3: Perse | L3: Giocate | M3: Vinte | N3: Nulle | O3: Perse | P3: Fatte | Q3: Subite | R3: Diff.
B4: Genoa | C4: =SUM((E4*3)+(F4)) -> 3 | D4: =SUM(E4:G4) -> 1 | E4: =SUM(I4,M4) -> 1 | F4: =SUM(J4,N4) -> 0 | G4: =SUM(K4,O4) -> 0 | H4: =SUM(I4:K4) -> 1 | I4: 1 | J4: 0 | K4: 0 | L4: =SUM(M4:O4) -> 0 | M4: 0 | N4: 0 | O4: 0 | P4: =SUM(Calendario!B5,Calendario!F5,Calendario!I5,Calendario!M5,Calendario!P8,Calendario!T8,Calendario!C15,Calendario!G15,Calendario!J17,Calendario!N17,Calendario!P17,Calendario!T17,Calendario!B30,Calendario!F30,Calendario!I29,Calendario!M29,Calendario!Q32,Calendario!U32,Calendario!C42,Calendario!G42,Calendario!J45,Calendario!N45,Calendario!P41,Calendario!T41,Calendario!B55,Calendario!F55,Calendario!I56,Calendario!M56,Calendario!Q57,Calendario!U57,Calendario!C72,Calendario!G72,Calendario!J66,Calendario!N66,Calendario!P65,Calendario!T65,Calendario!C77,Calendario!G77) -> 3 | Q4: =SUM(Calendario!C5,Calendario!G5,Calendario!J5,Calendario!N5,Calendario!Q8,Calendario!U8,Calendario!B15,Calendario!F15,Calendario!I17,Calendario!M17,Calendario!Q17,Calendario!U17,Calendario!C30,Calendario!G30,Calendario!J29,Calendario!N29,Calendario!P32,Calendario!T32,Calendario!B42,Calendario!F42,Calendario!I45,Calendario!M45,Calendario!Q41,Calendario!U41,Calendario!C55,Calendario!G55,Calendario!J56,Calendario!N56,Calendario!P57,Calendario!T57,Calendario!B72,Calendario!F72,Calendario!I66,Calendario!M66,Calendario!Q65,Calendario!U65,Calendario!B77,Calendario!F77) -> 2 | R4: =(P4-Q4) -> 1 | S4: =SUM((-2*J4)+(-3*K4)+(2*M4)+(-1*O4)) -> 0
B5: Milan | C5: =SUM((E5*3)+(F5)) -> 3 | D5: =SUM(E5:G5) -> 1 | E5: =SUM(I5,M5) -> 1 | F5: =SUM(J5,N5) -> 0 | G5: =SUM(K5,O5) -> 0 | H5: =SUM(I5:K5) -> 0 | I5: 0 | J5: 0 | K5: 0 | L5: =SUM(M5:O5) -> 1 | M5: 1 | N5: 0 | O5: 0 | P5: =SUM(Calendario!C11,Calendario!G11,Calendario!I9,Calendario!M9,Calendario!Q6,Calendario!U6,Calendario!B20,Calendario!F20,Calendario!J18,Calendario!N18,Calendario!P20,Calendario!T20,Calendario!C33,Calendario!G33,Calendario!J34,Calendario!N34,Calendario!P33,Calendario!T33,Calendario!B44,Calendario!F44,Calendario!I44,Calendario!M44,Calendario!Q40,Calendario!U40,Calendario!C60,Calendario!G60,Calendario!J58,Calendario!N58,Calendario!P57,Calendario!T57,Calendario!B68,Calendario!F68,Calendario!I67,Calendario!M67,Calendario!Q67,Calendario!U67,Calendario!C75,Calendario!G75) -> 2 | Q5: =SUM(Calendario!B11,Calendario!F11,Calendario!J9,Calendario!N9,Calendario!P6,Calendario!T6,Calendario!C20,Calendario!G20,Calendario!I18,Calendario!M18,Calendario!Q20,Calendario!U20,Calendario!B33,Calendario!F33,Calendario!I34,Calendario!M34,Calendario!Q33,Calendario!U33,Calendario!C44,Calendario!G44,Calendario!J44,Calendario!N44,Calendario!P40,Calendario!T40,Calendario!B60,Calendario!F60,Calendario!I58,Calendario!M58,Calendario!Q57,Calendario!U57,Calendario!C68,Calendario!G68,Calendario!J67,Calendario!N67,Calendario!P67,Calendario!T67,Calendario!B75,Calendario!F75) -> 1 | R5: =(P5-Q5) -> 1 | S5: =SUM((-2*J5)+(-3*K5)+(2*M5)+(-1*O5)) -> 2
B6: Palermo | C6: =SUM((E6*3)+(F6)) -> 3 | D6: =SUM(E6:G6) -> 1 | E6: =SUM(I6,M6) -> 1 | F6: =SUM(J6,N6) -> 0 | G6: =SUM(K6,O6) -> 0 | H6: =SUM(I6:K6) -> 1 | I6: 1 | J6: 0 | K6: 0 | L6: =SUM(M6:O6) -> 0 | M6: 0 | N6: 0 | O6: 0 | P6: =SUM(Calendario!B10,Calendario!F10,Calendario!J8,Calendario!N8,Calendario!Q7,Calendario!U7,Calendario!C19,Calendario!G19,Calendario!I21,Calendario!M21,Calendario!P22,Calendario!T22,Calendario!B34,Calendario!F34,Calendario!J30,Calendario!N30,Calendario!Q33,Calendario!U33,Calendario!C46,Calendario!G46,Calendario!I45,Calendario!M45,Calendario!P46,Calendario!T46,Calendario!B58,Calendario!F58,Calendario!J53,Calendario!N53,Calendario!Q59,Calendario!U59,Calendario!C66,Calendario!G66,Calendario!I69,Calendario!M69,Calendario!P70,Calendario!T70,Calendario!B81,Calendario!F81) -> 2 | Q6: =SUM(Calendario!C10,Calendario!G10,Calendario!I8,Calendario!M8,Calendario!P7,Calendario!T7,Calendario!B19,Calendario!F19,Calendario!J21,Calendario!N21,Calendario!Q22,Calendario!U22,Calendario!C34,Calendario!G34,Calendario!I30,Calendario!M30,Calendario!P33,Calendario!T33,Calendario!B46,Calendario!F46,Calendario!J45,Calendario!N45,Calendario!Q46,Calendario!U46,Calendario!C58,Calendario!G58,Calendario!I53,Calendario!M53,Calendario!P59,Calendario!T59,Calendario!B66,Calendario!F66,Calendario!J69,Calendario!N69,Calendario!Q70,Calendario!U70,Calendario!C81,Calendario!G81) -> 1 | R6: =(P6-Q6) -> 1 | S6: =SUM((-2*J6)+(-3*K6)+(2*M6)+(-1*O6)) -> 0
B7: Sampdoria | C7: =SUM((E7*3)+(F7)) -> 3 | D7: =SUM(E7:G7) -> 1 | E7: =SUM(I7,M7) -> 1 | F7: =SUM(J7,N7) -> 0 | G7: =SUM(K7,O7) -> 0 | H7: =SUM(I7:K7) -> 0 | I7: 0 | J7: 0 | K7: 0 | L7: =SUM(M7:O7) -> 1 | M7: 1 | N7: 0 | O7: 0 | P7: =SUM(Calendario!C4,Calendario!G4,Calendario!J7,Calendario!N7,Calendario!Q8,Calendario!U8,Calendario!B24,Calendario!F24,Calendario!I23,Calendario!M23,Calendario!Q20,Calendario!U20,Calendario!C27,Calendario!G27,Calendario!J31,Calendario!N31,Calendario!P35,Calendario!T35,Calendario!B48,Calendario!F48,Calendario!I47,Calendario!M47,Calendario!Q44,Calendario!U44,Calendario!C54,Calendario!G54,Calendario!J54,Calendario!N54,Calendario!P59,Calendario!T59,Calendario!B71,Calendario!F71,Calendario!I71,Calendario!M71,Calendario!Q69,Calendario!U69,Calendario!B83,Calendario!F83) -> 2 | Q7: =SUM(Calendario!B4,Calendario!F4,Calendario!I7,Calendario!M7,Calendario!P8,Calendario!T8,Calendario!C24,Calendario!G24,Calendario!J23,Calendario!N23,Calendario!P20,Calendario!T20,Calendario!B27,Calendario!F27,Calendario!I31,Calendario!M31,Calendario!Q35,Calendario!U35,Calendario!C48,Calendario!G48,Calendario!J47,Calendario!N47,Calendario!P44,Calendario!T44,Calendario!B54,Calendario!F54,Calendario!I54,Calendario!M54,Calendario!Q59,Calendario!U59,Calendario!C71,Calendario!G71,Calendario!J71,Calendario!N71,Calendario!P69,Calendario!T69,Calendario!C83,Calendario!G83) -> 1 | R7: =(P7-Q7) -> 1 | S7: =SUM((-2*J7)+(-3*K7)+(2*M7)+(-1*O7)) -> 2
B8: Juventus | C8: =SUM((E8*3)+(F8)) -> 3 | D8: =SUM(E8:G8) -> 1 | E8: =SUM(I8,M8) -> 1 | F8: =SUM(J8,N8) -> 0 | G8: =SUM(K8,O8) -> 0 | H8: =SUM(I8:K8) -> 1 | I8: 1 | J8: 0 | K8: 0 | L8: =SUM(M8:O8) -> 0 | M8: 0 | N8: 0 | O8: 0 | P8: =SUM(Calendario!B7,Calendario!F7,Calendario!I6,Calendario!M6,Calendario!Q5,Calendario!U5,Calendario!C23,Calendario!G23,Calendario!J24,Calendario!N24,Calendario!P18,Calendario!T18,Calendario!C32,Calendario!G32,Calendario!I31,Calendario!M31,Calendario!Q28,Calendario!U28,Calendario!B43,Calendario!F43,Calendario!I42,Calendario!M42,Calendario!P43,Calendario!T43,Calendario!C55,Calendario!G55,Calendario!J51,Calendario!N51,Calendario!Q58,Calendario!U58,Calendario!B65,Calendario!F65,Calendario!I65,Calendario!M65,Calendario!P67,Calendario!T67,Calendario!C81,Calendario!G81) -> 1 | Q8: =SUM(Calendario!C7,Calendario!G7,Calendario!J6,Calendario!N6,Calendario!P5,Calendario!T5,Calendario!B23,Calendario!F23,Calendario!I24,Calendario!M24,Calendario!Q18,Calendario!U18,Calendario!B32,Calendario!F32,Calendario!J31,Calendario!N31,Calendario!P28,Calendario!T28,Calendario!C43,Calendario!G43,Calendario!J42,Calendario!N42,Calendario!Q43,Calendario!U43,Calendario!B55,Calendario!F55,Calendario!I51,Calendario!M51,Calendario!P58,Calendario!T58,Calendario!C65,Calendario!G65,Calendario!J65,Calendario!N65,Calendario!Q67,Calendario!U67,Calendario!B81,Calendario!F81) -> 0 | R8: =(P8-Q8) -> 1 | S8: =SUM((-2*J8)+(-3*K8)+(2*M8)+(-1*O8)) -> 0
B9: Lazio | C9: =SUM((E9*3)+(F9)) -> 3 | D9: =SUM(E9:G9) -> 1 | E9: =SUM(I9,M9) -> 1 | F9: =SUM(J9,N9) -> 0 | G9: =SUM(K9,O9) -> 0 | H9: =SUM(I9:K9) -> 1 | I9: 1 | J9: 0 | K9: 0 | L9: =SUM(M9:O9) -> 0 | M9: 0 | N9: 0 | O9: 0 | P9: =SUM(Calendario!B8,Calendario!F8,Calendario!I7,Calendario!M7,Calendario!P10,Calendario!T10,Calendario!C18,Calendario!G18,Calendario!J16,Calendario!N16,Calendario!Q23,Calendario!U23,Calendario!B32,Calendario!F32,Calendario!I32,Calendario!M32,Calendario!P32,Calendario!T32,Calendario!C41,Calendario!G41,Calendario!J48,Calendario!N48,Calendario!Q42,Calendario!U42,Calendario!B57,Calendario!F57,Calendario!I58,Calendario!M58,Calendario!P56,Calendario!T56,Calendario!B66,Calendario!F66,Calendario!J68,Calendario!N68,Calendario!Q72,Calendario!U72,Calendario!C79,Calendario!G79) -> 1 | Q9: =SUM(Calendario!C8,Calendario!G8,Calendario!J7,Calendario!N7,Calendario!Q10,Calendario!U10,Calendario!B18,Calendario!F18,Calendario!I16,Calendario!M16,Calendario!P23,Calendario!T23,Calendario!C32,Calendario!G32,Calendario!J32,Calendario!N32,Calendario!Q32,Calendario!U32,Calendario!B41,Calendario!F41,Calendario!I48,Calendario!M48,Calendario!P42,Calendario!T42,Calendario!C57,Calendario!G57,Calendario!J58,Calendario!N58,Calendario!Q56,Calendario!U56,Calendario!C66,Calendario!G66,Calendario!I68,Calendario!M68,Calendario!P72,Calendario!T72,Calendario!B79,Calendario!F79) -> 0 | R9: =(P9-Q9) -> 1 | S9: =SUM((-2*J9)+(-3*K9)+(2*M9)+(-1*O9)) -> 0
B10: Parma | C10: =SUM((E10*3)+(F10)) -> 1 | D10: =SUM(E10:G10) -> 1 | E10: =SUM(I10,M10) -> 0 | F10: =SUM(J10,N10) -> 1 | G10: =SUM(K10,O10) -> 0 | H10: =SUM(I10:K10) -> 0 | I10: 0 | J10: 0 | K10: 0 | L10: =SUM(M10:O10) -> 1 | M10: 0 | N10: 1 | O10: 0 | P10: =SUM(Calendario!C12,Calendario!G12,Calendario!I11,Calendario!M11,Calendario!P11,Calendario!T11,Calendario!B22,Calendario!F22,Calendario!J15,Calendario!N15,Calendario!Q17,Calendario!U17,Calendario!C31,Calendario!G31,Calendario!I35,Calendario!M35,Calendario!P34,Calendario!T34,Calendario!B46,Calendario!F46,Calendario!J44,Calendario!N44,Calendario!Q47,Calendario!U47,Calendario!C57,Calendario!G57,Calendario!I59,Calendario!M59,Calendario!P58,Calendario!T58,Calendario!B70,Calendario!F70,Calendario!J64,Calendario!N64,Calendario!Q68,Calendario!U68,Calendario!C83,Calendario!G83) -> 2 | Q10: =SUM(Calendario!B12,Calendario!F12,Calendario!J11,Calendario!N11,Calendario!Q11,Calendario!U11,Calendario!C22,Calendario!G22,Calendario!I15,Calendario!M15,Calendario!P17,Calendario!T17,Calendario!B31,Calendario!F31,Calendario!J35,Calendario!N35,Calendario!Q34,Calendario!U34,Calendario!C46,Calendario!G46,Calendario!I44,Calendario!M44,Calendario!P47,Calendario!T47,Calendario!B57,Calendario!F57,Calendario!J59,Calendario!N59,Calendario!Q58,Calendario!U58,Calendario!C70,Calendario!G70,Calendario!I64,Calendario!M64,Calendario!P68,Calendario!T68,Calendario!B83,Calendario!F83) -> 2 | R10: =(P10-Q10) -> 0 | S10: =SUM((-2*J10)+(-3*K10)+(2*M10)+(-1*O10)) -> 0
B11: Udinese | C11: =SUM((E11*3)+(F11)) -> 1 | D11: =SUM(E11:G11) -> 1 | E11: =SUM(I11,M11) -> 0 | F11: =SUM(J11,N11) -> 1 | G11: =SUM(K11,O11) -> 0 | H11: =SUM(I11:K11) -> 1 | I11: 0 | J11: 1 | K11: 0 | L11: =SUM(M11:O11) -> 0 | M11: 0 | N11: 0 | O11: 0 | P11: =SUM(Calendario!B12,Calendario!F12,Calendario!I12,Calendario!M12,Calendario!P12,Calendario!T12,Calendario!C24,Calendario!G24,Calendario!J21,Calendario!N21,Calendario!Q15,Calendario!U15,Calendario!B36,Calendario!F36,Calendario!I36,Calendario!M36,Calendario!Q36,Calendario!U36,Calendario!C45,Calendario!G45,Calendario!J40,Calendario!N40,Calendario!P48,Calendario!T48,Calendario!B60,Calendario!F60,Calendario!I60,Calendario!M60,Calendario!Q52,Calendario!U52,Calendario!B72,Calendario!F72,Calendario!J65,Calendario!N65,Calendario!P72,Calendario!T72,Calendario!C80,Calendario!G80) -> 2 | Q11: =SUM(Calendario!C12,Calendario!G12,Calendario!J12,Calendario!N12,Calendario!Q12,Calendario!U12,Calendario!B24,Calendario!F24,Calendario!I21,Calendario!M21,Calendario!P15,Calendario!T15,Calendario!C36,Calendario!G36,Calendario!J36,Calendario!N36,Calendario!P36,Calendario!T36,Calendario!B45,Calendario!F45,Calendario!I40,Calendario!M40,Calendario!Q48,Calendario!U48,Calendario!C60,Calendario!G60,Calendario!J60,Calendario!N60,Calendario!P52,Calendario!T52,Calendario!C72,Calendario!G72,Calendario!I65,Calendario!M65,Calendario!Q72,Calendario!U72,Calendario!B80,Calendario!F80) -> 2 | R11: =(P11-Q11) -> 0 | S11: =SUM((-2*J11)+(-3*K11)+(2*M11)+(-1*O11)) -> -2
B12: Bologna | C12: =SUM((E12*3)+(F12)) -> 1 | D12: =SUM(E12:G12) -> 1 | E12: =SUM(I12,M12) -> 0 | F12: =SUM(J12,N12) -> 1 | G12: =SUM(K12,O12) -> 0 | H12: =SUM(I12:K12) -> 1 | I12: 0 | J12: 1 | K12: 0 | L12: =SUM(M12:O12) -> 0 | M12: 0 | N12: 0 | O12: 0 | P12: =SUM(Calendario!B3,Calendario!F3,Calendario!J10,Calendario!N10,Calendario!Q10,Calendario!U10,Calendario!C16,Calendario!G16,Calendario!J23,Calendario!N23,Calendario!P15,Calendario!T15,Calendario!B28,Calendario!F28,Calendario!I27,Calendario!M27,Calendario!Q34,Calendario!U34,Calendario!C44,Calendario!G44,Calendario!J46,Calendario!N46,Calendario!P39,Calendario!T39,Calendario!B53,Calendario!F53,Calendario!I53,Calendario!M53,Calendario!Q54,Calendario!U54,Calendario!C65,Calendario!G65,Calendario!I63,Calendario!M63,Calendario!P63,Calendario!T63,Calendario!B77,Calendario!F77) -> 1 | Q12: =SUM(Calendario!C3,Calendario!G3,Calendario!I10,Calendario!M10,Calendario!P10,Calendario!T10,Calendario!B16,Calendario!F16,Calendario!I23,Calendario!M23,Calendario!Q15,Calendario!U15,Calendario!C28,Calendario!G28,Calendario!J27,Calendario!N27,Calendario!P34,Calendario!T34,Calendario!B44,Calendario!F44,Calendario!I46,Calendario!M46,Calendario!Q39,Calendario!U39,Calendario!C53,Calendario!G53,Calendario!J53,Calendario!N53,Calendario!P54,Calendario!T54,Calendario!B65,Calendario!F65,Calendario!J63,Calendario!N63,Calendario!Q63,Calendario!U63,Calendario!C77,Calendario!G77) -> 1 | R12: =(P12-Q12) -> 0 | S12: =SUM((-2*J12)+(-3*K12)+(2*M12)+(-1*O12)) -> -2
B13: Fiorentina | C13: =SUM((E13*3)+(F13)) -> 1 | D13: =SUM(E13:G13) -> 1 | E13: =SUM(I13,M13) -> 0 | F13: =SUM(J13,N13) -> 1 | G13: =SUM(K13,O13) -> 0 | H13: =SUM(I13:K13) -> 0 | I13: 0 | J13: 0 | K13: 0 | L13: =SUM(M13:O13) -> 1 | M13: 0 | N13: 1 | O13: 0 | P13: =SUM(Calendario!C3,Calendario!G3,Calendario!J6,Calendario!N6,Calendario!Q9,Calendario!U9,Calendario!B19,Calendario!F19,Calendario!I19,Calendario!M19,Calendario!P16,Calendario!T16,Calendario!B29,Calendario!F29,Calendario!J29,Calendario!N29,Calendario!Q31,Calendario!U31,Calendario!C47,Calendario!G47,Calendario!I41,Calendario!M41,Calendario!P40,Calendario!T40,Calendario!B54,Calendario!F54,Calendario!J60,Calendario!N60,Calendario!Q60,Calendario!U60,Calendario!C67,Calendario!G67,Calendario!I64,Calendario!M64,Calendario!P64,Calendario!T64,Calendario!B79,Calendario!F79) -> 1 | Q13: =SUM(Calendario!B3,Calendario!F3,Calendario!I6,Calendario!M6,Calendario!P9,Calendario!T9,Calendario!C19,Calendario!G19,Calendario!J19,Calendario!N19,Calendario!Q16,Calendario!U16,Calendario!C29,Calendario!G29,Calendario!I29,Calendario!M29,Calendario!P31,Calendario!T31,Calendario!B47,Calendario!F47,Calendario!J41,Calendario!N41,Calendario!Q40,Calendario!U40,Calendario!C54,Calendario!G54,Calendario!I60,Calendario!M60,Calendario!P60,Calendario!T60,Calendario!B67,Calendario!F67,Calendario!J64,Calendario!N64,Calendario!Q64,Calendario!U64,Calendario!C79,Calendario!G79) -> 1 | R13: =(P13-Q13) -> 0 | S13: =SUM((-2*J13)+(-3*K13)+(2*M13)+(-1*O13)) -> 0
B14: Bari | C14: =SUM((E14*3)+(F14)) -> 1 | D14: =SUM(E14:G14) -> 1 | E14: =SUM(I14,M14) -> 0 | F14: =SUM(J14,N14) -> 1 | G14: =SUM(K14,O14) -> 0 | H14: =SUM(I14:K14) -> 0 | I14: 0 | J14: 0 | K14: 0 | L14: =SUM(M14:O14) -> 1 | M14: 0 | N14: 1 | O14: 0 | P14: =SUM(Calendario!C6,Calendario!G6,Calendario!J4,Calendario!N4,Calendario!P4,Calendario!T4,Calendario!B16,Calendario!F16,Calendario!I16,Calendario!M16,Calendario!Q21,Calendario!U21,Calendario!C34,Calendario!G34,Calendario!J35,Calendario!N35,Calendario!P28,Calendario!T28,Calendario!B39,Calendario!F39,Calendario!J47,Calendario!N47,Calendario!Q41,Calendario!U41,Calendario!B52,Calendario!F52,Calendario!I52,Calendario!M52,Calendario!P52,Calendario!T52,Calendario!C68,Calendario!G68,Calendario!J70,Calendario!N70,Calendario!Q64,Calendario!U64,Calendario!B76,Calendario!F76) -> 1 | Q14: =SUM(Calendario!B6,Calendario!F6,Calendario!I4,Calendario!M4,Calendario!Q4,Calendario!U4,Calendario!C16,Calendario!G16,Calendario!J16,Calendario!N16,Calendario!P21,Calendario!T21,Calendario!B34,Calendario!F34,Calendario!I35,Calendario!M35,Calendario!Q28,Calendario!U28,Calendario!C39,Calendario!G39,Calendario!I47,Calendario!M47,Calendario!P41,Calendario!T41,Calendario!C52,Calendario!G52,Calendario!J52,Calendario!N52,Calendario!Q52,Calendario!U52,Calendario!B68,Calendario!F68,Calendario!I70,Calendario!M70,Calendario!P64,Calendario!T64,Calendario!C76,Calendario!G76) -> 1 | R14: =(P14-Q14) -> 0 | S14: =SUM((-2*J14)+(-3*K14)+(2*M14)+(-1*O14)) -> 0
B15: Inter | C15: =SUM((E15*3)+(F15)) -> 1 | D15: =SUM(E15:G15) -> 1 | E15: =SUM(I15,M15) -> 0 | F15: =SUM(J15,N15) -> 1 | G15: =SUM(K15,O15) -> 0 | H15: =SUM(I15:K15) -> 1 | I15: 0 | J15: 1 | K15: 0 | L15: =SUM(M15:O15) -> 0 | M15: 0 | N15: 0 | O15: 0 | P15: =SUM(Calendario!B6,Calendario!F6,Calendario!J5,Calendario!N5,Calendario!P9,Calendario!T9,Calendario!C20,Calendario!G20,Calendario!I20,Calendario!M20,Calendario!Q18,Calendario!U18,Calendario!B31,Calendario!F31,Calendario!I30,Calendario!M30,Calendario!Q27,Calendario!U27,Calendario!C40,Calendario!G40,Calendario!J43,Calendario!N43,Calendario!P42,Calendario!T42,Calendario!B56,Calendario!F56,Calendario!I57,Calendario!M57,Calendario!Q55,Calendario!U55,Calendario!C71,Calendario!G71,Calendario!J63,Calendario!N63,Calendario!P66,Calendario!T66,Calendario!B80,Calendario!F80) -> 1 | Q15: =SUM(Calendario!C6,Calendario!G6,Calendario!I5,Calendario!M5,Calendario!Q9,Calendario!U9,Calendario!B20,Calendario!F20,Calendario!J20,Calendario!N20,Calendario!P18,Calendario!T18,Calendario!C31,Calendario!G31,Calendario!J30,Calendario!N30,Calendario!P27,Calendario!T27,Calendario!B40,Calendario!F40,Calendario!I43,Calendario!M43,Calendario!Q42,Calendario!U42,Calendario!C56,Calendario!G56,Calendario!J57,Calendario!N57,Calendario!P55,Calendario!T55,Calendario!B71,Calendario!F71,Calendario!I63,Calendario!M63,Calendario!Q66,Calendario!U66,Calendario!C80,Calendario!G80) -> 1 | R15: =(P15-Q15) -> 0 | S15: =SUM((-2*J15)+(-3*K15)+(2*M15)+(-1*O15)) -> -2
B16: Cagliari | C16: =SUM((E16*3)+(F16)) -> 1 | D16: =SUM(E16:G16) -> 1 | E16: =SUM(I16,M16) -> 0 | F16: =SUM(J16,N16) -> 1 | G16: =SUM(K16,O16) -> 0 | H16: =SUM(I16:K16) -> 0 | I16: 0 | J16: 0 | K16: 0 | L16: =SUM(M16:O16) -> 1 | M16: 0 | N16: 1 | O16: 0 | P16: =SUM(Calendario!C9,Calendario!G9,Calendario!J3,Calendario!N3,Calendario!P5,Calendario!T5,Calendario!B17,Calendario!F17,Calendario!I17,Calendario!M17,Calendario!Q22,Calendario!U22,Calendario!C29,Calendario!G29,Calendario!J32,Calendario!N32,Calendario!P29,Calendario!T29,Calendario!B40,Calendario!F40,Calendario!I39,Calendario!M39,Calendario!Q48,Calendario!U48,Calendario!C52,Calendario!G52,Calendario!I54,Calendario!M54,Calendario!P53,Calendario!T53,Calendario!C70,Calendario!G70,Calendario!J67,Calendario!N67,Calendario!Q63,Calendario!U63,Calendario!B78,Calendario!F78) -> 0 | Q16: =SUM(Calendario!B9,Calendario!F9,Calendario!I3,Calendario!M3,Calendario!Q5,Calendario!U5,Calendario!C17,Calendario!G17,Calendario!J17,Calendario!N17,Calendario!P22,Calendario!T22,Calendario!B29,Calendario!F29,Calendario!I32,Calendario!M32,Calendario!Q29,Calendario!U29,Calendario!C40,Calendario!G40,Calendario!J39,Calendario!N39,Calendario!P48,Calendario!T48,Calendario!B52,Calendario!F52,Calendario!J54,Calendario!N54,Calendario!Q53,Calendario!U53,Calendario!B70,Calendario!F70,Calendario!I67,Calendario!M67,Calendario!P63,Calendario!T63,Calendario!C78,Calendario!G78) -> 0 | R16: =(P16-Q16) -> 0 | S16: =SUM((-2*J16)+(-3*K16)+(2*M16)+(-1*O16)) -> 0
B17: Livorno | C17: =SUM((E17*3)+(F17)) -> 1 | D17: =SUM(E17:G17) -> 1 | E17: =SUM(I17,M17) -> 0 | F17: =SUM(J17,N17) -> 1 | G17: =SUM(K17,O17) -> 0 | H17: =SUM(I17:K17) -> 1 | I17: 0 | J17: 1 | K17: 0 | L17: =SUM(M17:O17) -> 0 | M17: 0 | N17: 0 | O17: 0 | P17: =SUM(Calendario!B9,Calendario!F9,Calendario!I8,Calendario!M8,Calendario!Q12,Calendario!U12,Calendario!C21,Calendario!G21,Calendario!J22,Calendario!N22,Calendario!P19,Calendario!T19,Calendario!B33,Calendario!F33,Calendario!I33,Calendario!M33,Calendario!Q30,Calendario!U30,Calendario!C43,Calendario!G43,Calendario!I43,Calendario!M43,Calendario!P44,Calendario!T44,Calendario!C53,Calendario!G53,Calendario!J52,Calendario!N52,Calendario!Q56,Calendario!U56,Calendario!B67,Calendario!F67,Calendario!I66,Calendario!M66,Calendario!P68,Calendario!T68,Calendario!C84,Calendario!G84) -> 0 | Q17: =SUM(Calendario!C9,Calendario!G9,Calendario!J8,Calendario!N8,Calendario!P12,Calendario!T12,Calendario!B21,Calendario!F21,Calendario!I22,Calendario!M22,Calendario!Q19,Calendario!U19,Calendario!C33,Calendario!G33,Calendario!J33,Calendario!N33,Calendario!P30,Calendario!T30,Calendario!B43,Calendario!F43,Calendario!J43,Calendario!N43,Calendario!Q44,Calendario!U44,Calendario!B53,Calendario!F53,Calendario!I52,Calendario!M52,Calendario!P56,Calendario!T56,Calendario!C67,Calendario!G67,Calendario!J66,Calendario!N66,Calendario!Q68,Calendario!U68,Calendario!B84,Calendario!F84) -> 0 | R17: =(P17-Q17) -> 0 | S17: =SUM((-2*J17)+(-3*K17)+(2*M17)+(-1*O17)) -> -2
B18: Roma | C18: =SUM((E18*3)+(F18)) -> 0 | D18: =SUM(E18:G18) -> 1 | E18: =SUM(I18,M18) -> 0 | F18: =SUM(J18,N18) -> 0 | G18: =SUM(K18,O18) -> 1 | H18: =SUM(I18:K18) -> 0 | I18: 0 | J18: 0 | K18: 0 | L18: =SUM(M18:O18) -> 1 | M18: 0 | N18: 0 | O18: 1 | P18: =SUM(Calendario!C5,Calendario!G5,Calendario!J9,Calendario!N9,Calendario!Q3,Calendario!U3,Calendario!B23,Calendario!F23,Calendario!I22,Calendario!M22,Calendario!P23,Calendario!T23,Calendario!C35,Calendario!G35,Calendario!J36,Calendario!N36,Calendario!Q35,Calendario!U35,Calendario!B47,Calendario!F47,Calendario!I46,Calendario!M46,Calendario!P47,Calendario!T47,Calendario!C58,Calendario!G58,Calendario!J57,Calendario!N57,Calendario!Q53,Calendario!U53,Calendario!C63,Calendario!G63,Calendario!I70,Calendario!M70,Calendario!P71,Calendario!T71,Calendario!B82,Calendario!F82) -> 2 | Q18: =SUM(Calendario!B5,Calendario!F5,Calendario!I9,Calendario!M9,Calendario!P3,Calendario!T3,Calendario!C23,Calendario!G23,Calendario!J22,Calendario!N22,Calendario!Q23,Calendario!U23,Calendario!B35,Calendario!F35,Calendario!I36,Calendario!M36,Calendario!P35,Calendario!T35,Calendario!C47,Calendario!G47,Calendario!J46,Calendario!N46,Calendario!Q47,Calendario!U47,Calendario!B58,Calendario!F58,Calendario!I57,Calendario!M57,Calendario!P53,Calendario!T53,Calendario!B63,Calendario!F63,Calendario!J70,Calendario!N70,Calendario!Q71,Calendario!U71,Calendario!C82,Calendario!G82) -> 3 | R18: =(P18-Q18) -> -1 | S18: =SUM((-2*J18)+(-3*K18)+(2*M18)+(-1*O18)) -> -1
B19: Catania | C19: =SUM((E19*3)+(F19)) -> 0 | D19: =SUM(E19:G19) -> 1 | E19: =SUM(I19,M19) -> 0 | F19: =SUM(J19,N19) -> 0 | G19: =SUM(K19,O19) -> 1 | H19: =SUM(I19:K19) -> 1 | I19: 0 | J19: 0 | K19: 1 | L19: =SUM(M19:O19) -> 0 | M19: 0 | N19: 0 | O19: 0 | P19: =SUM(Calendario!B4,Calendario!F4,Calendario!I3,Calendario!M3,Calendario!P6,Calendario!T6,Calendario!C22,Calendario!G22,Calendario!J20,Calendario!N20,Calendario!Q24,Calendario!U24,Calendario!C36,Calendario!G36,Calendario!I28,Calendario!M28,Calendario!P30,Calendario!T30,Calendario!B41,Calendario!F41,Calendario!J41,Calendario!N41,Calendario!Q43,Calendario!U43,Calendario!C51,Calendario!G51,Calendario!I55,Calendario!M55,Calendario!P54,Calendario!T54,Calendario!B63,Calendario!F63,Calendario!J69,Calendario!N69,Calendario!Q65,Calendario!U65,Calendario!C76,Calendario!G76) -> 1 | Q19: =SUM(Calendario!C4,Calendario!G4,Calendario!J3,Calendario!N3,Calendario!Q6,Calendario!U6,Calendario!B22,Calendario!F22,Calendario!I20,Calendario!M20,Calendario!P24,Calendario!T24,Calendario!B36,Calendario!F36,Calendario!J28,Calendario!N28,Calendario!Q30,Calendario!U30,Calendario!C41,Calendario!G41,Calendario!I41,Calendario!M41,Calendario!P43,Calendario!T43,Calendario!B51,Calendario!F51,Calendario!J55,Calendario!N55,Calendario!Q54,Calendario!U54,Calendario!C63,Calendario!G63,Calendario!I69,Calendario!M69,Calendario!P65,Calendario!T65,Calendario!B76,Calendario!F76) -> 2 | R19: =(P19-Q19) -> -1 | S19: =SUM((-2*J19)+(-3*K19)+(2*M19)+(-1*O19)) -> -3
B20: Napoli | C20: =SUM((E20*3)+(F20)) -> 0 | D20: =SUM(E20:G20) -> 1 | E20: =SUM(I20,M20) -> 0 | F20: =SUM(J20,N20) -> 0 | G20: =SUM(K20,O20) -> 1 | H20: =SUM(I20:K20) -> 0 | I20: 0 | J20: 0 | K20: 0 | L20: =SUM(M20:O20) -> 1 | M20: 0 | N20: 0 | O20: 1 | P20: =SUM(Calendario!C10,Calendario!G10,Calendario!I10,Calendario!M10,Calendario!Q11,Calendario!U11,Calendario!B21,Calendario!F21,Calendario!J19,Calendario!N19,Calendario!P21,Calendario!T21,Calendario!C30,Calendario!G30,Calendario!I34,Calendario!M34,Calendario!Q29,Calendario!U29,Calendario!B45,Calendario!F45,Calendario!J42,Calendario!N42,Calendario!P45,Calendario!T45,Calendario!C56,Calendario!G56,Calendario!J55,Calendario!N55,Calendario!Q51,Calendario!U51,Calendario!B69,Calendario!F69,Calendario!I68,Calendario!M68,Calendario!P69,Calendario!T69,Calendario!C82,Calendario!G82) -> 1 | Q20: =SUM(Calendario!B10,Calendario!F10,Calendario!J10,Calendario!N10,Calendario!P11,Calendario!T11,Calendario!C21,Calendario!G21,Calendario!I19,Calendario!M19,Calendario!Q21,Calendario!U21,Calendario!B30,Calendario!F30,Calendario!J34,Calendario!N34,Calendario!P29,Calendario!T29,Calendario!C45,Calendario!G45,Calendario!I42,Calendario!M42,Calendario!Q45,Calendario!U45,Calendario!B56,Calendario!F56,Calendario!I55,Calendario!M55,Calendario!P51,Calendario!T51,Calendario!C69,Calendario!G69,Calendario!J68,Calendario!N68,Calendario!Q69,Calendario!U69,Calendario!B82,Calendario!F82) -> 2 | R20: =(P20-Q20) -> -1 | S20: =SUM((-2*J20)+(-3*K20)+(2*M20)+(-1*O20)) -> -1
B21: Siena | C21: =SUM((E21*3)+(F21)) -> 0 | D21: =SUM(E21:G21) -> 1 | E21: =SUM(I21,M21) -> 0 | F21: =SUM(J21,N21) -> 0 | G21: =SUM(K21,O21) -> 1 | H21: =SUM(I21:K21) -> 1 | I21: 0 | J21: 0 | K21: 1 | L21: =SUM(M21:O21) -> 0 | M21: 0 | N21: 0 | O21: 0 | P21: =SUM(Calendario!B11,Calendario!F11,Calendario!J11,Calendario!N11,Calendario!Q4,Calendario!U4,Calendario!C17,Calendario!G17,Calendario!I24,Calendario!M24,Calendario!P24,Calendario!T24,Calendario!B35,Calendario!F35,Calendario!J27,Calendario!N27,Calendario!P36,Calendario!T36,Calendario!C48,Calendario!G48,Calendario!I48,Calendario!M48,Calendario!Q46,Calendario!U46,Calendario!B59,Calendario!F59,Calendario!J56,Calendario!N56,Calendario!P60,Calendario!T60,Calendario!C69,Calendario!G69,Calendario!I72,Calendario!M72,Calendario!Q66,Calendario!U66,Calendario!B84,Calendario!F84) -> 1 | Q21: =SUM(Calendario!C11,Calendario!G11,Calendario!I11,Calendario!M11,Calendario!P4,Calendario!T4,Calendario!B17,Calendario!F17,Calendario!J24,Calendario!N24,Calendario!Q24,Calendario!U24,Calendario!C35,Calendario!G35,Calendario!I27,Calendario!M27,Calendario!Q36,Calendario!U36,Calendario!B48,Calendario!F48,Calendario!J48,Calendario!N48,Calendario!P46,Calendario!T46,Calendario!C59,Calendario!G59,Calendario!I56,Calendario!M56,Calendario!Q60,Calendario!U60,Calendario!B69,Calendario!F69,Calendario!J72,Calendario!N72,Calendario!P66,Calendario!T66,Calendario!C84,Calendario!G84) -> 2 | R21: =(P21-Q21) -> -1 | S21: =SUM((-2*J21)+(-3*K21)+(2*M21)+(-1*O21)) -> -3
B22: Atalanta | C22: =SUM((E22*3)+(F22)) -> 0 | D22: =SUM(E22:G22) -> 1 | E22: =SUM(I22,M22) -> 0 | F22: =SUM(J22,N22) -> 0 | G22: =SUM(K22,O22) -> 1 | H22: =SUM(I22:K22) -> 0 | I22: 0 | J22: 0 | K22: 0 | L22: =SUM(M22:O22) -> 1 | M22: 0 | N22: 0 | O22: 1 | P22: =SUM(Calendario!C8,Calendario!G8,Calendario!J12,Calendario!N12,Calendario!P3,Calendario!T3,Calendario!B15,Calendario!F15,Calendario!I15,Calendario!M15,Calendario!Q16,Calendario!U16,Calendario!B27,Calendario!F27,Calendario!J33,Calendario!N33,Calendario!P27,Calendario!T27,Calendario!C39,Calendario!G39,Calendario!J39,Calendario!N39,Calendario!Q39,Calendario!U39,Calendario!B51,Calendario!F51,Calendario!I51,Calendario!M51,Calendario!P51,Calendario!T51,Calendario!C64,Calendario!G64,Calendario!J72,Calendario!N72,Calendario!Q70,Calendario!U70,Calendario!B75,Calendario!F75) -> 0 | Q22: =SUM(Calendario!B8,Calendario!F8,Calendario!I12,Calendario!M12,Calendario!Q3,Calendario!U3,Calendario!C15,Calendario!G15,Calendario!J15,Calendario!N15,Calendario!P16,Calendario!T16,Calendario!C27,Calendario!G27,Calendario!I33,Calendario!M33,Calendario!Q27,Calendario!U27,Calendario!B39,Calendario!F39,Calendario!I39,Calendario!M39,Calendario!P39,Calendario!T39,Calendario!C51,Calendario!G51,Calendario!J51,Calendario!N51,Calendario!Q51,Calendario!U51,Calendario!B64,Calendario!F64,Calendario!I72,Calendario!M72,Calendario!P70,Calendario!T70,Calendario!C75,Calendario!G75) -> 1 | R22: =(P22-Q22) -> -1 | S22: =SUM((-2*J22)+(-3*K22)+(2*M22)+(-1*O22)) -> -1
B23: Chievo | C23: =SUM((E23*3)+(F23)) -> 0 | D23: =SUM(E23:G23) -> 1 | E23: =SUM(I23,M23) -> 0 | F23: =SUM(J23,N23) -> 0 | G23: =SUM(K23,O23) -> 1 | H23: =SUM(I23:K23) -> 0 | I23: 0 | J23: 0 | K23: 0 | L23: =SUM(M23:O23) -> 1 | M23: 0 | N23: 0 | O23: 1 | P23: =SUM(Calendario!C7,Calendario!G7,Calendario!I4,Calendario!M4,Calendario!P7,Calendario!T7,Calendario!B18,Calendario!F18,Calendario!I18,Calendario!M18,Calendario!Q19,Calendario!U19,Calendario!C28,Calendario!G28,Calendario!J28,Calendario!N28,Calendario!P31,Calendario!T31,Calendario!B42,Calendario!F42,Calendario!I40,Calendario!M40,Calendario!Q45,Calendario!U45,Calendario!C59,Calendario!G59,Calendario!J59,Calendario!N59,Calendario!P55,Calendario!T55,Calendario!B64,Calendario!F64,Calendario!J71,Calendario!N71,Calendario!Q71,Calendario!U71,Calendario!C78,Calendario!G78) -> 0 | Q23: =SUM(Calendario!B7,Calendario!F7,Calendario!J4,Calendario!N4,Calendario!Q7,Calendario!U7,Calendario!C18,Calendario!G18,Calendario!J18,Calendario!N18,Calendario!P19,Calendario!T19,Calendario!B28,Calendario!F28,Calendario!I28,Calendario!M28,Calendario!Q31,Calendario!U31,Calendario!C42,Calendario!G42,Calendario!J40,Calendario!N40,Calendario!P45,Calendario!T45,Calendario!B59,Calendario!F59,Calendario!I59,Calendario!M59,Calendario!Q55,Calendario!U55,Calendario!C64,Calendario!G64,Calendario!I71,Calendario!M71,Calendario!P71,Calendario!T71,Calendario!B78,Calendario!F78) -> 1 | R23: =(P23-Q23) -> -1 | S23: =SUM((-2*J23)+(-3*K23)+(2*M23)+(-1*O23)) -> -1
C25: Legenda
D26: Campione d'Italia (accesso diretto alla "Champions League")
D27: Accesso diretto alla "Champions League"
D28: Preliminari di "Champions League"
D29: "Europa League"
D30: Retrocessione in Serie B
