Workbook

Sheet Bill
A1: Dept. | B1: General Ledger # | C1: GL Description | D1: Building | E1: Address | F1: City | G1: State | H1: Zip | I1: Floor | J1: Room | K1: Model | L1: ROOM2 | M1: Ricoh Tag # | N1: Serial Number | O1: IP Address | P1: Device Type | Q1: Total B&W Click Count | R1: Total Color Click Count | S1: CPC B/W | T1: CPC Color | U1: Prev B&W Click Count | V1: Current B&W Click Count | W1: Prev Color Click Count | X1: Current Color Click Count | Y1: B&W Click Charge | Z1: Color Click Charge | AA1: Device Total Click Charge | AB1: GL Sub Total
A2: Academic Advising | B2: 10_07_205_90300_5521 | C2: Academic Advising | D2: Carroll Hall | E2: VMI | F2: Lexington | G2: Virginia | H2: 24450 | I2: 2 | J2: 210 | K2: AF MPC2051 | L2: 210 | M2: 17099459 | N2: V9725401429 | O2: 144.75.195.41 | P2: MFP | Q2: 11459 | R2: 2435 | S2: 0.0207 | T2: 0.087 | U2: 0 | V2: 11459 | W2: 0 | X2: 2435 | Y2: =ROUND((Q2*S2),2) -> 237.2 | Z2: =ROUND((R2*T2),2) -> 211.85 | AA2: =Y2+Z2 -> 449.05 | AB2: =Table14[[#This Row],[Device Total Click Charge]] -> 449.05
A3: Admissions | B3: 10_03_054_01100_5521 | C3: Admissions | D3: 307 Letcher | E3: VMI | F3: Lexington | G3: Virginia | H3: 24450 | I3: 1 | J3: 201 | K3: AF MPC3502 | L3: 201 | M3: 17099493 | N3: W502L600872 | O3: 144.75.215.48 | P3: MFP | Q3: 14954 | R3: 5607 | S3: 0.0207 | T3: 0.087 | U3: 0 | V3: 14954 | W3: 0 | X3: 5607 | Y3: =ROUND((Q3*S3),2) -> 309.55 | Z3: =ROUND((R3*T3),2) -> 487.81 | AA3: =Y3+Z3 -> 797.36
A4: Admissions | B4: 10_03_054_01100_5521 | C4: Admissions | D4: Letcher Hall | E4: 301 Letcher Avenue | F4: Lexington | G4: Virginia | H4: 22450 | I4: 2 | J4: 205 | K4: AF SPC242DN | L4: 301 | M4: 17099513 | N4: T202P700462 | O4: 144.75.186.31 | P4: Printer | Q4: 795 | R4: 418 | S4: 0.0262 | T4: 0.118 | U4: 0 | V4: 795 | W4: 0 | X4: 418 | Y4: =ROUND((Q4*S4),2) -> 20.83 | Z4: =ROUND((R4*T4),2) -> 49.32 | AA4: =Y4+Z4 -> 70.15
A5: Admissions | B5: 10_03_054_01100_5521 | C5: Admissions | D5: Letcher Hall | E5: 301 Letcher Avenue | F5: Lexington | G5: Virginia | H5: 22450 | I5: 2 | J5: 207 | K5: AF SP4310N | L5: 207 | M5: 17099440 | N5: T1129010899 | O5: 144.75.178.24 | P5: Printer | Q5: 471 | R5: 0 | S5: 0.0262 | T5: 0.118 | U5: 0 | V5: 471 | W5: 0 | X5: 0 | Y5: =ROUND((Q5*S5),2) -> 12.34 | Z5: =ROUND((R5*T5),2) -> 0 | AA5: =Y5+Z5 -> 12.34
A6: Admissions | B6: 10_03_054_01100_5521 | C6: Admissions | D6: Letcher Hall | E6: 301 Letcher Avenue | F6: Lexington | G6: Virginia | H6: 22450 | I6: 3 | J6: 301 | K6: AF SPC242DN | L6: 202 | M6: 17099522 | N6: T202P700447 | O6: 144.75.186.28 | P6: Printer | Q6: 716 | R6: 141 | S6: 0.0262 | T6: 0.118 | U6: 0 | V6: 716 | W6: 0 | X6: 141 | Y6: =ROUND((Q6*S6),2) -> 18.76 | Z6: =ROUND((R6*T6),2) -> 16.64 | AA6: =Y6+Z6 -> 35.4
A7: Admissions | B7: 10_03_054_01100_5521 | C7: Admissions | D7: Letcher Hall | E7: 301 Letcher Avenue | F7: Lexington | G7: Virginia | H7: 22450 | I7: 3 | J7: 302 | K7: AF SPC242DN | L7: 205 | M7: 17099423 | N7: T202P700463 | O7: 144.75.186.29 | P7: Printer | Q7: 47 | R7: 197 | S7: 0.0262 | T7: 0.118 | U7: 0 | V7: 47 | W7: 0 | X7: 197 | Y7: =ROUND((Q7*S7),2) -> 1.23 | Z7: =ROUND((R7*T7),2) -> 23.25 | AA7: =Y7+Z7 -> 24.48
A8: Admissions | B8: 10_03_054_01100_5521 | C8: Admissions | D8: Letcher Hall | E8: 301 Letcher Avenue | F8: Lexington | G8: Virginia | H8: 22450 | I8: 3 | J8: 306 | K8: AF SPC242DN | L8: 302 | M8: 17099511 | N8: T202P700465 | O8: 144.75.186.25 | P8: Printer | Q8: 89 | R8: 3 | S8: 0.0262 | T8: 0.118 | U8: 0 | V8: 89 | W8: 0 | X8: 3 | Y8: =ROUND((Q8*S8),2) -> 2.33 | Z8: =ROUND((R8*T8),2) -> 0.35 | AA8: =Y8+Z8 -> 2.68
A9: Admissions | B9: 10_03_054_01100_5521 | C9: Admissions | D9: Letcher Hall | E9: 301 Letcher Avenue | F9: Lexington | G9: Virginia | H9: 22450 | I9: 2 | J9: 201 | K9: AF SP4310N | L9: 201 | M9: 17099512 | N9: T1129010877 | O9: 144.75.186.30 | P9: Printer | Q9: 48 | R9: 0 | S9: 0.0262 | T9: 0.118 | U9: 0 | V9: 48 | W9: 0 | X9: 0 | Y9: =ROUND((Q9*S9),2) -> 1.26 | Z9: =ROUND((R9*T9),2) -> 0 | AA9: =Y9+Z9 -> 1.26 | AB9: =SUM(AA3:AA9) -> 943.67
A10: ADV | B10: 10_03_064_50550_5521 | C10: Printer Services | D10: Carroll Hall | E10: VMI | F10: Lexington | G10: Virginia | H10: 24450 | I10: 2 | J10: 210C | K10: AF SP4310N | L10: 210C | M10: 17099562 | N10: T1128911292 | O10: 144.75.195.20 | P10: Printer | Q10: 650 | R10: 0 | S10: 0.0262 | T10: 0.118 | U10: 0 | V10: 650 | W10: 0 | X10: 0 | Y10: =ROUND((Q10*S10),2) -> 17.03 | Z10: =ROUND((R10*T10),2) -> 0 | AA10: =Y10+Z10 -> 17.03 | AB10: =Table14[[#This Row],[Device Total Click Charge]] -> 17.03
A11: Air Force Rotc | B11: 10_03_011_02100_5521 | C11: ROTC-Air Force | D11: Kilbourne Hall | E11: VMI | F11: Lexington | G11: Virginia | H11: 24450 | I11: 2 | J11: 2012 | K11: AF SP4310N | L11: 2012 | M11: 17099443 | N11: T1129010871 | O11: 144.75.187.135 | P11: Printer | Q11: 309 | R11: 0 | S11: 0.0262 | T11: 0.118 | U11: 0 | V11: 309 | W11: 0 | X11: 0 | Y11: =ROUND((Q11*S11),2) -> 8.1 | Z11: =ROUND((R11*T11),2) -> 0 | AA11: =Y11+Z11 -> 8.1
A12: Air Force Rotc | B12: 10_03_011_02100_5521 | C12: ROTC-Air Force | D12: Kilbourne Hall | E12: VMI | F12: Lexington | G12: Virginia | H12: 24450 | I12: 2 | J12: 2018 | K12: AF SP4310N | L12: 2018 | M12: 17099438 | N12: T1129010832 | O12: 144.75.187.138 | P12: Printer | Q12: 824 | R12: 0 | S12: 0.0262 | T12: 0.118 | U12: 0 | V12: 824 | W12: 0 | X12: 0 | Y12: =ROUND((Q12*S12),2) -> 21.59 | Z12: =ROUND((R12*T12),2) -> 0 | AA12: =Y12+Z12 -> 21.59 | AB12: =SUM(AA11:AA12) -> 29.69
A13: Archives/Undergraduate Research | B13: 10_03_041_62100_5521 | C13: Libraries | D13: Preston Library | E13: VMI | F13: Lexington | G13: Virginia | H13: 24450 | I13: 3 | J13: 400 | K13: AF MPC3502 | L13: Main | M13: 17099489 | N13: W502L700081 | O13: 144.75.197.69 | P13: MFP | Q13: 1248 | R13: 87 | S13: 0.0207 | T13: 0.087 | U13: 0 | V13: 1248 | W13: 0 | X13: 87 | Y13: =ROUND((Q13*S13),2) -> 25.83 | Z13: =ROUND((R13*T13),2) -> 7.57 | AA13: =Y13+Z13 -> 33.4 | AB13: =Table14[[#This Row],[Device Total Click Charge]] -> 33.4
A14: Army Rotc | B14: 10_03_011_04100_5521 | C14: ROTC-Army | D14: Kilbourne Hall | E14: VMI | F14: Lexington | G14: Virginia | H14: 24450 | I14: 2 | J14: 2057 | K14: AF SP4310N | L14: 2057 | M14: 17099444 | N14: T1129010677 | O14: 144.75.187.133 | P14: Printer | Q14: 1043 | R14: 0 | S14: 0.0262 | T14: 0.118 | U14: 0 | V14: 1043 | W14: 0 | X14: 0 | Y14: =ROUND((Q14*S14),2) -> 27.33 | Z14: =ROUND((R14*T14),2) -> 0 | AA14: =Y14+Z14 -> 27.33
A15: Army Rotc | B15: 10_03_011_04100_5521 | C15: ROTC-Army | D15: Kilbourne Hall | E15: VMI | F15: Lexington | G15: Virginia | H15: 24450 | I15: 2 | J15: 2029 | K15: AF SP4310N | L15: 2029 | M15: 17099446 | N15: T1129010869 | O15: 144.75.187.137 | P15: Printer | Q15: 149 | R15: 0 | S15: 0.0262 | T15: 0.118 | U15: 0 | V15: 149 | W15: 0 | X15: 0 | Y15: =ROUND((Q15*S15),2) -> 3.9 | Z15: =ROUND((R15*T15),2) -> 0 | AA15: =Y15+Z15 -> 3.9
A16: Army Rotc | B16: 10_03_011_04100_5521 | C16: ROTC-Army | D16: Kilbourne Hall | E16: VMI | F16: Lexington | G16: Virginia | H16: 24450 | I16: 2 | J16: 2067 | K16: AF SP4310N | L16: 2067 | M16: 17099425 | N16: T1129010889 | O16: 144.75.187.123 | P16: Printer | Q16: 436 | R16: 0 | S16: 0.0262 | T16: 0.118 | U16: 0 | V16: 436 | W16: 0 | X16: 0 | Y16: =ROUND((Q16*S16),2) -> 11.42 | Z16: =ROUND((R16*T16),2) -> 0 | AA16: =Y16+Z16 -> 11.42
A17: Army Rotc | B17: 10_03_011_04100_5521 | C17: ROTC-Army | D17: Kilbourne Hall | E17: VMI | F17: Lexington | G17: Virginia | H17: 24450 | I17: 2 | J17: 2061 | K17: AF SP4310N | L17: 2061 | M17: 17099442 | N17: T1129010681 | O17: 144.75.187.136 | P17: Printer | Q17: 263 | R17: 0 | S17: 0.0262 | T17: 0.118 | U17: 0 | V17: 263 | W17: 0 | X17: 0 | Y17: =ROUND((Q17*S17),2) -> 6.89 | Z17: =ROUND((R17*T17),2) -> 0 | AA17: =Y17+Z17 -> 6.89
A18: Army Rotc | B18: 10_03_011_04100_5521 | C18: ROTC-Army | D18: Kilbourne Hall | E18: VMI | F18: Lexington | G18: Virginia | H18: 24450 | I18: 2 | J18: 2056 | K18: AF SP4310N | L18: 2056 | M18: 17099436 | N18: T1129010837 | O18: 144.75.187.131 | P18: Printer | Q18: 798 | R18: 0 | S18: 0.0262 | T18: 0.118 | U18: 0 | V18: 798 | W18: 0 | X18: 0 | Y18: =ROUND((Q18*S18),2) -> 20.91 | Z18: =ROUND((R18*T18),2) -> 0 | AA18: =Y18+Z18 -> 20.91
A19: Army Rotc | B19: 10_03_011_04100_5521 | C19: ROTC-Army | D19: Kilbourne Hall | E19: VMI | F19: Lexington | G19: Virginia | H19: 24450 | I19: 2 | J19: 2066 | K19: AF SP4310N | L19: 2066 | M19: 17099426 | N19: T1129010820 | O19: 144.75.187.121 | P19: Printer | Q19: 139 | R19: 0 | S19: 0.0262 | T19: 0.118 | U19: 0 | V19: 139 | W19: 0 | X19: 0 | Y19: =ROUND((Q19*S19),2) -> 3.64 | Z19: =ROUND((R19*T19),2) -> 0 | AA19: =Y19+Z19 -> 3.64
A20: Army Rotc | B20: 10_03_011_04100_5521 | C20: ROTC-Army | D20: Kilbourne Hall | E20: VMI | F20: Lexington | G20: Virginia | H20: 24450 | I20: 2 | J20: 2060 | K20: AF SP4310N | L20: 2060 | M20: 17099430 | N20: T1129010760 | O20: 144.75.187.119 | P20: Printer | Q20: 118 | R20: 0 | S20: 0.0262 | T20: 0.118 | U20: 0 | V20: 118 | W20: 0 | X20: 0 | Y20: =ROUND((Q20*S20),2) -> 3.09 | Z20: =ROUND((R20*T20),2) -> 0 | AA20: =Y20+Z20 -> 3.09
A21: Army Rotc | B21: 10_03_011_04100_5521 | C21: ROTC-Army | D21: Kilbourne Hall | E21: VMI | F21: Lexington | G21: Virginia | H21: 24450 | I21: 2 | J21: 2070 | K21: AF SP4310N | L21: 2070 | M21: 17099428 | N21: T1129010900 | O21: 144.75.187.132 | P21: Printer | Q21: 592 | R21: 0 | S21: 0.0262 | T21: 0.118 | U21: 0 | V21: 592 | W21: 0 | X21: 0 | Y21: =ROUND((Q21*S21),2) -> 15.51 | Z21: =ROUND((R21*T21),2) -> 0 | AA21: =Y21+Z21 -> 15.51
A22: Army Rotc | B22: 10_03_011_04100_5521 | C22: ROTC-Army | D22: Kilbourne Hall | E22: VMI | F22: Lexington | G22: Virginia | H22: 24450 | I22: 2 | J22: 2053 | K22: AF SP4310N | L22: 2053 | M22: 17099437 | N22: T1129010748 | O22: 144.75.187.112 | P22: Printer | Q22: 400 | R22: 0 | S22: 0.0262 | T22: 0.118 | U22: 0 | V22: 400 | W22: 0 | X22: 0 | Y22: =ROUND((Q22*S22),2) -> 10.48 | Z22: =ROUND((R22*T22),2) -> 0 | AA22: =Y22+Z22 -> 10.48
A23: Army Rotc | B23: 10_03_011_04100_5521 | C23: ROTC-Army | D23: Kilbourne Hall | E23: VMI | F23: Lexington | G23: Virginia | H23: 24450 | I23: 2 | J23: 2023 | K23: AF SP4310N | L23: 2023 | M23: 17099435 | N23: T1129010902 | O23: 144.75.187.16 | P23: Printer | Q23: 214 | R23: 0 | S23: 0.0262 | T23: 0.118 | U23: 0 | V23: 214 | W23: 0 | X23: 0 | Y23: =ROUND((Q23*S23),2) -> 5.61 | Z23: =ROUND((R23*T23),2) -> 0 | AA23: =Y23+Z23 -> 5.61
A24: Army Rotc | B24: 10_03_011_04100_5521 | C24: ROTC-Army | D24: Kilbourne Hall | E24: VMI | F24: Lexington | G24: Virginia | H24: 24450 | I24: 2 | J24: 2063 | K24: AF SP4310N | L24: Admin | M24: 17099427 | N24: T1129010874 | O24: 144.75.187.118 | P24: Printer | Q24: 563 | R24: 0 | S24: 0.0262 | T24: 0.118 | U24: 0 | V24: 563 | W24: 0 | X24: 0 | Y24: =ROUND((Q24*S24),2) -> 14.75 | Z24: =ROUND((R24*T24),2) -> 0 | AA24: =Y24+Z24 -> 14.75
A25: Army Rotc | B25: 10_03_011_04100_5521 | C25: ROTC-Army | D25: Kilbourne Hall | E25: VMI | F25: Lexington | G25: Virginia | H25: 24450 | I25: 2 | J25: 2064 | K25: AF SP4310N | L25: 2064 | M25: 17099439 | N25: T1129010823 | O25: 144.75.187.140 | P25: Printer | Q25: 446 | R25: 0 | S25: 0.0262 | T25: 0.118 | U25: 0 | V25: 446 | W25: 0 | X25: 0 | Y25: =ROUND((Q25*S25),2) -> 11.69 | Z25: =ROUND((R25*T25),2) -> 0 | AA25: =Y25+Z25 -> 11.69
A26: Army Rotc | B26: 10_03_011_04100_5521 | C26: ROTC-Army | D26: Kilbourne Hall | E26: VMI | F26: Lexington | G26: Virginia | H26: 24450 | I26: 2 | J26: 2022 | K26: AF MPC3502 | L26: 2022 | M26: 17099434 | N26: W502L600854 | O26: 144.75.187.122 | P26: MFP | Q26: 41179 | R26: 2092 | S26: 0.0207 | T26: 0.087 | U26: 0 | V26: 41179 | W26: 0 | X26: 2092 | Y26: =ROUND((Q26*S26),2) -> 852.41 | Z26: =ROUND((R26*T26),2) -> 182 | AA26: =Y26+Z26 -> 1034.41 | AB26: =SUM(AA14:AA26) -> 1169.63
A27: Athletic Director | B27: 30_00_310_06110_5521 | C27: Administrative | D27: Cameron Hall | E27: VMI | F27: Lexington | G27: Virginia | H27: 22450 | I27: 2 | J27: 241 | K27: AF SP4310N | L27: 241 | M27: 17099552 | N27: T1129010427 | O27: 144.75.183.9 | P27: Printer | Q27: 1199 | R27: 0 | S27: 0.0262 | T27: 0.118 | U27: 0 | V27: 1199 | W27: 0 | X27: 0 | Y27: =ROUND((Q27*S27),2) -> 31.41 | Z27: =ROUND((R27*T27),2) -> 0 | AA27: =Y27+Z27 -> 31.41
A28: Athletics | B28: 30_00_310_06110_5521 | C28: Administrative | D28: Cameron Hall | E28: VMI | F28: Lexington | G28: Virginia | H28: 22450 | I28: 1 | J28: Main | K28: AF SP4310N | L28: Main | M28: 17099554 | N28: T1129010385 | O28: 144.75.183.63 | P28: Printer | Q28: 282 | R28: 0 | S28: 0.0262 | T28: 0.118 | U28: 0 | V28: 282 | W28: 0 | X28: 0 | Y28: =ROUND((Q28*S28),2) -> 7.39 | Z28: =ROUND((R28*T28),2) -> 0 | AA28: =Y28+Z28 -> 7.39
A29: Athletics | B29: 30_00_310_06110_5521 | C29: Administrative | D29: Cameron Hall | E29: VMI | F29: Lexington | G29: Virginia | H29: 22450 | I29: 2 | J29: 242 | K29: AF SP4310N | L29: 242 | M29: 17099553 | N29: T1129010420 | O29: 144.75.183.64 | P29: Printer | Q29: 491 | R29: 0 | S29: 0.0262 | T29: 0.118 | U29: 0 | V29: 491 | W29: 0 | X29: 0 | Y29: =ROUND((Q29*S29),2) -> 12.86 | Z29: =ROUND((R29*T29),2) -> 0 | AA29: =Y29+Z29 -> 12.86
A30: Athletics | B30: 30_00_310_06110_5521 | C30: Administrative | D30: Cameron Hall | E30: VMI | F30: Lexington | G30: Virginia | H30: 22450 | I30: 1 | J30: 302 | K30: AF MPC2051 | L30: Athletic Director | M30: 17099722 | N30: V9725401418 | O30: 144.75.183.52 | P30: MFP | Q30: 3285 | R30: 6416 | S30: 0.0207 | T30: 0.087 | U30: 0 | V30: 3285 | W30: 0 | X30: 6416 | Y30: =ROUND((Q30*S30),2) -> 68 | Z30: =ROUND((R30*T30),2) -> 558.19 | AA30: =Y30+Z30 -> 626.19
A31: Athletics | B31: 30_00_310_06110_5521 | C31: Administrative | D31: Cameron Hall | E31: VMI | F31: Lexington | G31: Virginia | H31: 22450 | I31: 2 | J31: 235 | K31: AF MPC6501 | L31: 235 | M31: 17099490 | N31: V7620400078 | O31: 144.75.183.56 | P31: MFP | Q31: 15315 | R31: 2952 | S31: 0.0207 | T31: 0.087 | U31: 0 | V31: 15315 | W31: 0 | X31: 2952 | Y31: =ROUND((Q31*S31),2) -> 317.02 | Z31: =ROUND((R31*T31),2) -> 256.82 | AA31: =Y31+Z31 -> 573.84
A32: Athletics | B32: 30_00_310_06110_5521 | C32: Administrative | D32: Cameron Hall | E32: VMI | F32: Lexington | G32: Virginia | H32: 22450 | I32: 1 | J32: 312 | K32: AF SP4310N | L32: 312 | M32: 17099555 | N32: T1129010428 | O32: 144.75.183.67 | P32: Printer | Q32: 480 | R32: 0 | S32: 0.0262 | T32: 0.118 | U32: 0 | V32: 480 | W32: 0 | X32: 0 | Y32: =ROUND((Q32*S32),2) -> 12.58 | Z32: =ROUND((R32*T32),2) -> 0 | AA32: =Y32+Z32 -> 12.58
A33: Athletics Basketball Office | B33: 30_00_310_06110_5521 | C33: Administrative | D33: Cameron Hall | E33: VMI | F33: Lexington | G33: Virginia | H33: 22450 | I33: 2 | J33: 204 | K33: AF MP301SP | L33: 204 | M33: 17099507 | N33: W912P602280 | O33: 144.75.183.73 | P33: MFP | Q33: 4886 | R33: 0 | S33: 0.0207 | T33: 0.087 | U33: 0 | V33: 4886 | W33: 0 | X33: 0 | Y33: =ROUND((Q33*S33),2) -> 101.14 | Z33: =ROUND((R33*T33),2) -> 0 | AA33: =Y33+Z33 -> 101.14 | AB33: =SUM(AA27:AA33) -> 1365.41
A34: Athletics TRAC | B34: 30_00_310_06020_5521 | C34: Track & Cross Country | D34: Cameron Hall | E34: VMI | F34: Lexington | G34: Virginia | H34: 22450 | I34: 2 | J34: 231 | K34: AF SP4310N | L34: 231 | M34: 17099560 | N34: T1129010426 | O34: 144.75.183.68 | P34: Printer | Q34: 845 | R34: 0 | S34: 0.0262 | T34: 0.118 | U34: 0 | V34: 845 | W34: 0 | X34: 0 | Y34: =ROUND((Q34*S34),2) -> 22.14 | Z34: =ROUND((R34*T34),2) -> 0 | AA34: =Y34+Z34 -> 22.14 | AB34: =Table14[[#This Row],[Device Total Click Charge]] -> 22.14
A35: Athletics Women's Soccer | B35: 30_00_310_06095_5521 | C35: Soccer - Women | D35: Cameron Hall | E35: VMI | F35: Lexington | G35: Virginia | H35: 22450 | I35: 2 | J35: 239 | K35: AF SP4310N | L35: 239 | M35: 17099565 | N35: T1129010419 | O35: 144.75.183.69 | P35: Printer | Q35: 192 | R35: 0 | S35: 0.0262 | T35: 0.118 | U35: 0 | V35: 192 | W35: 0 | X35: 0 | Y35: =ROUND((Q35*S35),2) -> 5.03 | Z35: =ROUND((R35*T35),2) -> 0 | AA35: =Y35+Z35 -> 5.03 | AB35: =Table14[[#This Row],[Device Total Click Charge]] -> 5.03
A36: Auxiliary Services | B36: 10_08_309_82115_5521 | C36: Auxiliary Administration | D36: Cocke Hall | E36: VMI | F36: Lexington | G36: Virginia | H36: 24450 | I36: 5 | J36: 201 | K36: AF MPC2051 | L36: 201 | M36: 17099424 | N36: V9725500651 | O36: 144.75.177.32 | P36: MFP | Q36: 1697 | R36: 361 | S36: 0.0207 | T36: 0.087 | U36: 0 | V36: 1697 | W36: 0 | X36: 361 | Y36: =ROUND((Q36*S36),2) -> 35.13 | Z36: =ROUND((R36*T36),2) -> 31.41 | AA36: =Y36+Z36 -> 66.54 | AB36: =Table14[[#This Row],[Device Total Click Charge]] -> 66.54
A37: Band | B37: 10_07_205_30200_5521 | C37: UMA-Band | D37: Shell Hall | E37: VMI | F37: Lexington | G37: Virginia | H37: 24450 | I37: 2 | J37: 207 | K37: AF MP301SP | L37: 312 | M37: 17099460 | N37: W912P602276 | O37: 144.75.180.76 | P37: Printer | Q37: 2983 | R37: 0 | S37: 0.0262 | T37: 0.118 | U37: 0 | V37: 2983 | W37: 0 | X37: 0 | Y37: =ROUND((Q37*S37),2) -> 78.15 | Z37: =ROUND((R37*T37),2) -> 0 | AA37: =Y37+Z37 -> 78.15 | AB37: =Table14[[#This Row],[Device Total Click Charge]] -> 78.15
A38: Barracks Study Room | B38: 10_03_064_50550_5521 | C38: Printer Services | D38: New Barracks | E38: VMI | F38: Lexington | G38: Virginia | H38: 23350 | I38: 1 | J38: C11 | K38: AF MP4002 | L38: C11 | M38: 17099483 | N38: W522L700693 | O38: 144.75.188.60 | P38: MFP | Q38: 68697 | R38: 0 | S38: 0.0207 | T38: 0.087 | U38: 0 | V38: 68697 | W38: 0 | X38: 0 | Y38: =ROUND((Q38*S38),2) -> 1422.03 | Z38: =ROUND((R38*T38),2) -> 0 | AA38: =Y38+Z38 -> 1422.03
A39: Barracks Study Room | B39: 10_03_064_50550_5521 | C39: Printer Services | D39: New Barracks | E39: VMI | F39: Lexington | G39: Virginia | H39: 23350 | I39: 1 | J39: C11 | K39: AF MP4002 | L39: 303E | M39: 17099482 | N39: W522L700688 | O39: 144.75.188.50 | P39: MFP | Q39: 142699 | R39: 0 | S39: 0.0207 | T39: 0.087 | U39: 0 | V39: 142699 | W39: 0 | X39: 0 | Y39: =ROUND((Q39*S39),2) -> 2953.87 | Z39: =ROUND((R39*T39),2) -> 0 | AA39: =Y39+Z39 -> 2953.87 | AB39: =SUM(AA38:AA39) -> 4375.9
A40: Biology | B40: 10_03_011_10100_5521 | C40: Biology | D40: Maury Brooke | E40: VMI | F40: Lexington | G40: Virginia | H40: 24450 | I40: 2 | J40: 203 | K40: AF SP4310N | L40: 203B | M40: 17099613 | N40: T1129011365 | O40: 144.75.202.56 | P40: Printer | Q40: 1725 | R40: 0 | S40: 0.0262 | T40: 0.118 | U40: 0 | V40: 1725 | W40: 0 | X40: 0 | Y40: =ROUND((Q40*S40),2) -> 45.2 | Z40: =ROUND((R40*T40),2) -> 0 | AA40: =Y40+Z40 -> 45.2
...

Sheet VIM Bill
A1: Meter Read on: 11-28-2012 ============= Department | B1: General Ledger | C1: GL Description | D1: Building | E1: Room | F1: Model | G1: Device Type | H1: Ricoh Tag | I1: Total BW Click Count | J1: Total Color Click Count | K1: BW Click Charge | L1: Color Click Charge | M1: Device Total Click Charge | N1: Serial Number | O1: IP Address | P1: CPC BW | Q1: CPC Color | R1: Prev BW Click Count | S1: Current BW Click Count | T1: Prev Color Click Count | U1: Current Color Click Count
A3: Academic Advising | B3: 10_07_205_90300_5521 | C3: Academic Advising | D3: Shell Hall | E3: 301 | F3: AF SPC242DN | G3: =VLOOKUP(F3,Tables!D$9:E$17,2,FALSE) -> PTR | H3: 17099684 | I3: =S3-R3 -> 846 | J3: =U3-T3 -> 310 | K3: =I3*$P3 -> 22.1652 | L3: =J3*$Q3 -> 36.58 | M3: =K3+L3 -> 58.7452 | N3: T202P700442 | O3: 144.75.180.103 | P3: =IF(G3="MFP",Tables!B$2,Tables!B$5) -> 0.0262 | Q3: =IF(G3="MFP",Tables!B$3,Tables!B$6) -> 0.118 | R3: 0 | S3: 846 | T3: 0 | U3: 310
B4: 10_07_205_90300_5521 Total | M4: =SUBTOTAL(9,M3:M3) -> 58.7452
A5: Admissions | B5: 10_03_054_01100_5521 | C5: Admissions | D5: 307 Letcher Ave. | E5: 204 | F5: AF MPC3502 | G5: =VLOOKUP(F5,Tables!D$9:E$17,2,FALSE) -> MFP | H5: 17099493 | I5: =S5-R5 -> 14954 | J5: =U5-T5 -> 5607 | K5: =I5*$P5 -> 309.5478 | L5: =J5*$Q5 -> 487.809 | M5: =K5+L5 -> 797.3568 | N5: W502L600872 | O5: 144.75.215.48 | P5: =IF(G5="MFP",Tables!B$2,Tables!B$5) -> 0.0207 | Q5: =IF(G5="MFP",Tables!B$3,Tables!B$6) -> 0.087 | R5: 0 | S5: 14954 | T5: 0 | U5: 5607
A6: Admissions | B6: 10_03_054_01100_5521 | C6: Admissions | D6: 309 Letcher Ave. | E6: 201 | F6: AF SP4310N | G6: =VLOOKUP(F6,Tables!D$9:E$17,2,FALSE) -> PTR | H6: 17099512 | I6: =S6-R6 -> 48 | J6: =U6-T6 -> 0 | K6: =I6*$P6 -> 1.2576 | L6: =J6*$Q6 -> 0 | M6: =K6+L6 -> 1.2576 | N6: T1129010877 | O6: 144.75.186.30 | P6: =IF(G6="MFP",Tables!B$2,Tables!B$5) -> 0.0262 | Q6: =IF(G6="MFP",Tables!B$3,Tables!B$6) -> 0.118 | R6: 0 | S6: 48 | T6: 0 | U6: 0
A7: Admissions | B7: 10_03_054_01100_5521 | C7: Admissions | D7: 309 Letcher Ave. | E7: 205 | F7: AF SPC242DN | G7: =VLOOKUP(F7,Tables!D$9:E$17,2,FALSE) -> PTR | H7: 17099513 | I7: =S7-R7 -> 795 | J7: =U7-T7 -> 418 | K7: =I7*$P7 -> 20.829 | L7: =J7*$Q7 -> 49.324 | M7: =K7+L7 -> 70.153 | N7: T202P700462 | O7: 144.75.186.31 | P7: =IF(G7="MFP",Tables!B$2,Tables!B$5) -> 0.0262 | Q7: =IF(G7="MFP",Tables!B$3,Tables!B$6) -> 0.118 | R7: 0 | S7: 795 | T7: 0 | U7: 418
A8: Admissions | B8: 10_03_054_01100_5521 | C8: Admissions | D8: 309 Letcher Ave. | E8: 207 | F8: AF SP4310N | G8: =VLOOKUP(F8,Tables!D$9:E$17,2,FALSE) -> PTR | H8: 17099440 | I8: =S8-R8 -> 471 | J8: =U8-T8 -> 0 | K8: =I8*$P8 -> 12.3402 | L8: =J8*$Q8 -> 0 | M8: =K8+L8 -> 12.3402 | N8: T1129010899 | O8: 144.75.178.24 | P8: =IF(G8="MFP",Tables!B$2,Tables!B$5) -> 0.0262 | Q8: =IF(G8="MFP",Tables!B$3,Tables!B$6) -> 0.118 | R8: 0 | S8: 471 | T8: 0 | U8: 0
A9: Admissions | B9: 10_03_054_01100_5521 | C9: Admissions | D9: 309 Letcher Ave. | E9: 301 | F9: AF SPC242DN | G9: =VLOOKUP(F9,Tables!D$9:E$17,2,FALSE) -> PTR | H9: 17099522 | I9: =S9-R9 -> 716 | J9: =U9-T9 -> 141 | K9: =I9*$P9 -> 18.7592 | L9: =J9*$Q9 -> 16.638 | M9: =K9+L9 -> 35.3972 | N9: T202P700447 | O9: 144.75.186.28 | P9: =IF(G9="MFP",Tables!B$2,Tables!B$5) -> 0.0262 | Q9: =IF(G9="MFP",Tables!B$3,Tables!B$6) -> 0.118 | R9: 0 | S9: 716 | T9: 0 | U9: 141
A10: Admissions | B10: 10_03_054_01100_5521 | C10: Admissions | D10: 309 Letcher Ave. | E10: 302 | F10: AF SPC242DN | G10: =VLOOKUP(F10,Tables!D$9:E$17,2,FALSE) -> PTR | H10: 17099423 | I10: =S10-R10 -> 47 | J10: =U10-T10 -> 197 | K10: =I10*$P10 -> 1.2314 | L10: =J10*$Q10 -> 23.246 | M10: =K10+L10 -> 24.4774 | N10: T202P700463 | O10: 144.75.186.29 | P10: =IF(G10="MFP",Tables!B$2,Tables!B$5) -> 0.0262 | Q10: =IF(G10="MFP",Tables!B$3,Tables!B$6) -> 0.118 | R10: 0 | S10: 47 | T10: 0 | U10: 197
A11: Admissions | B11: 10_03_054_01100_5521 | C11: Admissions | D11: 309 Letcher Ave. | E11: 306 | F11: AF SPC242DN | G11: =VLOOKUP(F11,Tables!D$9:E$17,2,FALSE) -> PTR | H11: 17099511 | I11: =S11-R11 -> 89 | J11: =U11-T11 -> 3 | K11: =I11*$P11 -> 2.3318 | L11: =J11*$Q11 -> 0.354 | M11: =K11+L11 -> 2.6858 | N11: T202P700465 | O11: 144.75.186.25 | P11: =IF(G11="MFP",Tables!B$2,Tables!B$5) -> 0.0262 | Q11: =IF(G11="MFP",Tables!B$3,Tables!B$6) -> 0.118 | R11: 0 | S11: 89 | T11: 0 | U11: 3
B12: 10_03_054_01100_5521 Total | M12: =SUBTOTAL(9,M5:M11) -> 943.668
A13: ADV | B13: 10_03_064_50550_5521 | C13: Cadet Printer Services | D13: Carroll Hall | E13: 210C | F13: AF SP4310N | G13: =VLOOKUP(F13,Tables!D$9:E$17,2,FALSE) -> PTR | H13: 17099562 | I13: =S13-R13 -> 650 | J13: =U13-T13 -> 0 | K13: =I13*$P13 -> 17.03 | L13: =J13*$Q13 -> 0 | M13: =K13+L13 -> 17.03 | N13: T1128911292 | O13: 144.75.195.20 | P13: =IF(G13="MFP",Tables!B$2,Tables!B$5) -> 0.0262 | Q13: =IF(G13="MFP",Tables!B$3,Tables!B$6) -> 0.118 | R13: 0 | S13: 650 | T13: 0 | U13: 0
B14: 10_03_064_50550_5521 Total | M14: =SUBTOTAL(9,M13:M13) -> 17.03
A15: AFO-Athletic Advising | B15: 40_00_052_06550_5521 | C15: AFO-Athletic Advising | D15: Carroll Hall | E15: 210 | F15: AF MPC2051 | G15: =VLOOKUP(F15,Tables!D$9:E$17,2,FALSE) -> MFP | H15: 17099459 | I15: =S15-R15 -> 11459 | J15: =U15-T15 -> 2435 | K15: =I15*$P15 -> 237.2013 | L15: =J15*$Q15 -> 211.845 | M15: =K15+L15 -> 449.0463 | N15: V9725401429 | O15: 144.75.195.41 | P15: =IF(G15="MFP",Tables!B$2,Tables!B$5) -> 0.0207 | Q15: =IF(G15="MFP",Tables!B$3,Tables!B$6) -> 0.087 | R15: 0 | S15: 11459 | T15: 0 | U15: 2435
B16: 40_00_052_06550_5521 Total | M16: =SUBTOTAL(9,M15:M15) -> 449.0463
A17: Air Force Rotc | B17: 10_03_011_02100_5521 | C17: ROTC-Air Force | D17: Kilbourne Hall | E17: 2012 | F17: AF SP4310N | G17: =VLOOKUP(F17,Tables!D$9:E$17,2,FALSE) -> PTR | H17: 17099443 | I17: =S17-R17 -> 309 | J17: =U17-T17 -> 0 | K17: =I17*$P17 -> 8.0958 | L17: =J17*$Q17 -> 0 | M17: =K17+L17 -> 8.0958 | N17: T1129010871 | O17: 144.75.187.135 | P17: =IF(G17="MFP",Tables!B$2,Tables!B$5) -> 0.0262 | Q17: =IF(G17="MFP",Tables!B$3,Tables!B$6) -> 0.118 | R17: 0 | S17: 309 | T17: 0 | U17: 0
A18: Air Force Rotc | B18: 10_03_011_02100_5521 | C18: ROTC-Air Force | D18: Kilbourne Hall | E18: 2018 | F18: AF SP4310N | G18: =VLOOKUP(F18,Tables!D$9:E$17,2,FALSE) -> PTR | H18: 17099438 | I18: =S18-R18 -> 824 | J18: =U18-T18 -> 0 | K18: =I18*$P18 -> 21.5888 | L18: =J18*$Q18 -> 0 | M18: =K18+L18 -> 21.5888 | N18: T1129010832 | O18: 144.75.187.138 | P18: =IF(G18="MFP",Tables!B$2,Tables!B$5) -> 0.0262 | Q18: =IF(G18="MFP",Tables!B$3,Tables!B$6) -> 0.118 | R18: 0 | S18: 824 | T18: 0 | U18: 0
B19: 10_03_011_02100_5521 Total | M19: =SUBTOTAL(9,M17:M18) -> 29.6846
A20: Army Rotc | B20: 10_03_011_04100_5521 | C20: ROTC-Army | D20: Kilbourne Hall | E20: 2022 | F20: AF MPC3502 | G20: =VLOOKUP(F20,Tables!D$9:E$17,2,FALSE) -> MFP | H20: 17099434 | I20: =S20-R20 -> 41179 | J20: =U20-T20 -> 2092 | K20: =I20*$P20 -> 852.4053 | L20: =J20*$Q20 -> 182.004 | M20: =K20+L20 -> 1034.4093 | N20: W502L600854 | O20: 144.75.187.122 | P20: =IF(G20="MFP",Tables!B$2,Tables!B$5) -> 0.0207 | Q20: =IF(G20="MFP",Tables!B$3,Tables!B$6) -> 0.087 | R20: 0 | S20: 41179 | T20: 0 | U20: 2092
A21: Army Rotc | B21: 10_03_011_04100_5521 | C21: ROTC-Army | D21: Kilbourne Hall | E21: 2023 | F21: AF SP4310N | G21: =VLOOKUP(F21,Tables!D$9:E$17,2,FALSE) -> PTR | H21: 17099435 | I21: =S21-R21 -> 214 | J21: =U21-T21 -> 0 | K21: =I21*$P21 -> 5.6068 | L21: =J21*$Q21 -> 0 | M21: =K21+L21 -> 5.6068 | N21: T1129010902 | O21: 144.75.187.16 | P21: =IF(G21="MFP",Tables!B$2,Tables!B$5) -> 0.0262 | Q21: =IF(G21="MFP",Tables!B$3,Tables!B$6) -> 0.118 | R21: 0 | S21: 214 | T21: 0 | U21: 0
A22: Army Rotc | B22: 10_03_011_04100_5521 | C22: ROTC-Army | D22: Kilbourne Hall | E22: 2029 | F22: AF SP4310N | G22: =VLOOKUP(F22,Tables!D$9:E$17,2,FALSE) -> PTR | H22: 17099446 | I22: =S22-R22 -> 149 | J22: =U22-T22 -> 0 | K22: =I22*$P22 -> 3.9038 | L22: =J22*$Q22 -> 0 | M22: =K22+L22 -> 3.9038 | N22: T1129010869 | O22: 144.75.187.137 | P22: =IF(G22="MFP",Tables!B$2,Tables!B$5) -> 0.0262 | Q22: =IF(G22="MFP",Tables!B$3,Tables!B$6) -> 0.118 | R22: 0 | S22: 149 | T22: 0 | U22: 0
A23: Army Rotc | B23: 10_03_011_04100_5521 | C23: ROTC-Army | D23: Kilbourne Hall | E23: 2053 | F23: AF SP4310N | G23: =VLOOKUP(F23,Tables!D$9:E$17,2,FALSE) -> PTR | H23: 17099437 | I23: =S23-R23 -> 400 | J23: =U23-T23 -> 0 | K23: =I23*$P23 -> 10.48 | L23: =J23*$Q23 -> 0 | M23: =K23+L23 -> 10.48 | N23: T1129010748 | O23: 144.75.187.112 | P23: =IF(G23="MFP",Tables!B$2,Tables!B$5) -> 0.0262 | Q23: =IF(G23="MFP",Tables!B$3,Tables!B$6) -> 0.118 | R23: 0 | S23: 400 | T23: 0 | U23: 0
A24: Army Rotc | B24: 10_03_011_04100_5521 | C24: ROTC-Army | D24: Kilbourne Hall | E24: 2056 | F24: AF SP4310N | G24: =VLOOKUP(F24,Tables!D$9:E$17,2,FALSE) -> PTR | H24: 17099436 | I24: =S24-R24 -> 798 | J24: =U24-T24 -> 0 | K24: =I24*$P24 -> 20.9076 | L24: =J24*$Q24 -> 0 | M24: =K24+L24 -> 20.9076 | N24: T1129010837 | O24: 144.75.187.131 | P24: =IF(G24="MFP",Tables!B$2,Tables!B$5) -> 0.0262 | Q24: =IF(G24="MFP",Tables!B$3,Tables!B$6) -> 0.118 | R24: 0 | S24: 798 | T24: 0 | U24: 0
A25: Army Rotc | B25: 10_03_011_04100_5521 | C25: ROTC-Army | D25: Kilbourne Hall | E25: 2057 | F25: AF SP4310N | G25: =VLOOKUP(F25,Tables!D$9:E$17,2,FALSE) -> PTR | H25: 17099444 | I25: =S25-R25 -> 1043 | J25: =U25-T25 -> 0 | K25: =I25*$P25 -> 27.3266 | L25: =J25*$Q25 -> 0 | M25: =K25+L25 -> 27.3266 | N25: T1129010677 | O25: 144.75.187.133 | P25: =IF(G25="MFP",Tables!B$2,Tables!B$5) -> 0.0262 | Q25: =IF(G25="MFP",Tables!B$3,Tables!B$6) -> 0.118 | R25: 0 | S25: 1043 | T25: 0 | U25: 0
A26: Army Rotc | B26: 10_03_011_04100_5521 | C26: ROTC-Army | D26: Kilbourne Hall | E26: 2060 | F26: AF SP4310N | G26: =VLOOKUP(F26,Tables!D$9:E$17,2,FALSE) -> PTR | H26: 17099430 | I26: =S26-R26 -> 118 | J26: =U26-T26 -> 0 | K26: =I26*$P26 -> 3.0916 | L26: =J26*$Q26 -> 0 | M26: =K26+L26 -> 3.0916 | N26: T1129010760 | O26: 144.75.187.119 | P26: =IF(G26="MFP",Tables!B$2,Tables!B$5) -> 0.0262 | Q26: =IF(G26="MFP",Tables!B$3,Tables!B$6) -> 0.118 | R26: 0 | S26: 118 | T26: 0 | U26: 0
A27: Army Rotc | B27: 10_03_011_04100_5521 | C27: ROTC-Army | D27: Kilbourne Hall | E27: 2061 | F27: AF SP4310N | G27: =VLOOKUP(F27,Tables!D$9:E$17,2,FALSE) -> PTR | H27: 17099442 | I27: =S27-R27 -> 263 | J27: =U27-T27 -> 0 | K27: =I27*$P27 -> 6.8906 | L27: =J27*$Q27 -> 0 | M27: =K27+L27 -> 6.8906 | N27: T1129010681 | O27: 144.75.187.136 | P27: =IF(G27="MFP",Tables!B$2,Tables!B$5) -> 0.0262 | Q27: =IF(G27="MFP",Tables!B$3,Tables!B$6) -> 0.118 | R27: 0 | S27: 263 | T27: 0 | U27: 0
A28: Army Rotc | B28: 10_03_011_04100_5521 | C28: ROTC-Army | D28: Kilbourne Hall | E28: 2063 | F28: AF SP4310N | G28: =VLOOKUP(F28,Tables!D$9:E$17,2,FALSE) -> PTR | H28: 17099427 | I28: =S28-R28 -> 563 | J28: =U28-T28 -> 0 | K28: =I28*$P28 -> 14.7506 | L28: =J28*$Q28 -> 0 | M28: =K28+L28 -> 14.7506 | N28: T1129010874 | O28: 144.75.187.118 | P28: =IF(G28="MFP",Tables!B$2,Tables!B$5) -> 0.0262 | Q28: =IF(G28="MFP",Tables!B$3,Tables!B$6) -> 0.118 | R28: 0 | S28: 563 | T28: 0 | U28: 0
A29: Army Rotc | B29: 10_03_011_04100_5521 | C29: ROTC-Army | D29: Kilbourne Hall | E29: 2064 | F29: AF SP4310N | G29: =VLOOKUP(F29,Tables!D$9:E$17,2,FALSE) -> PTR | H29: 17099439 | I29: =S29-R29 -> 446 | J29: =U29-T29 -> 0 | K29: =I29*$P29 -> 11.6852 | L29: =J29*$Q29 -> 0 | M29: =K29+L29 -> 11.6852 | N29: T1129010823 | O29: 144.75.187.140 | P29: =IF(G29="MFP",Tables!B$2,Tables!B$5) -> 0.0262 | Q29: =IF(G29="MFP",Tables!B$3,Tables!B$6) -> 0.118 | R29: 0 | S29: 446 | T29: 0 | U29: 0
A30: Army Rotc | B30: 10_03_011_04100_5521 | C30: ROTC-Army | D30: Kilbourne Hall | E30: 2066 | F30: AF SP4310N | G30: =VLOOKUP(F30,Tables!D$9:E$17,2,FALSE) -> PTR | H30: 17099426 | I30: =S30-R30 -> 139 | J30: =U30-T30 -> 0 | K30: =I30*$P30 -> 3.6418 | L30: =J30*$Q30 -> 0 | M30: =K30+L30 -> 3.6418 | N30: T1129010820 | O30: 144.75.187.121 | P30: =IF(G30="MFP",Tables!B$2,Tables!B$5) -> 0.0262 | Q30: =IF(G30="MFP",Tables!B$3,Tables!B$6) -> 0.118 | R30: 0 | S30: 139 | T30: 0 | U30: 0
A31: Army Rotc | B31: 10_03_011_04100_5521 | C31: ROTC-Army | D31: Kilbourne Hall | E31: 2067 | F31: AF SP4310N | G31: =VLOOKUP(F31,Tables!D$9:E$17,2,FALSE) -> PTR | H31: 17099425 | I31: =S31-R31 -> 436 | J31: =U31-T31 -> 0 | K31: =I31*$P31 -> 11.4232 | L31: =J31*$Q31 -> 0 | M31: =K31+L31 -> 11.4232 | N31: T1129010889 | O31: 144.75.187.123 | P31: =IF(G31="MFP",Tables!B$2,Tables!B$5) -> 0.0262 | Q31: =IF(G31="MFP",Tables!B$3,Tables!B$6) -> 0.118 | R31: 0 | S31: 436 | T31: 0 | U31: 0
A32: Army Rotc | B32: 10_03_011_04100_5521 | C32: ROTC-Army | D32: Kilbourne Hall | E32: 2070 | F32: AF SP4310N | G32: =VLOOKUP(F32,Tables!D$9:E$17,2,FALSE) -> PTR | H32: 17099428 | I32: =S32-R32 -> 592 | J32: =U32-T32 -> 0 | K32: =I32*$P32 -> 15.5104 | L32: =J32*$Q32 -> 0 | M32: =K32+L32 -> 15.5104 | N32: T1129010900 | O32: 144.75.187.132 | P32: =IF(G32="MFP",Tables!B$2,Tables!B$5) -> 0.0262 | Q32: =IF(G32="MFP",Tables!B$3,Tables!B$6) -> 0.118 | R32: 0 | S32: 592 | T32: 0 | U32: 0
B33: 10_03_011_04100_5521 Total | M33: =SUBTOTAL(9,M20:M32) -> 1169.6275
A34: Athletic Communications | B34: 30_00_310_06104_5521 | C34: Athletic Communications | D34: Smith Hall | E34: 116 | F34: AF MP301SP | G34: =VLOOKUP(F34,Tables!D$9:E$17,2,FALSE) -> MFP | H34: 17099531 | I34: =S34-R34 -> 2029 | J34: =U34-T34 -> 0 | K34: =I34*$P34 -> 42.0003 | L34: =J34*$Q34 -> 0 | M34: =K34+L34 -> 42.0003 | N34: W912P602286 | O34: 144.75.179.49 | P34: =IF(G34="MFP",Tables!B$2,Tables!B$5) -> 0.0207 | Q34: =IF(G34="MFP",Tables!B$3,Tables!B$6) -> 0.087 | R34: 0 | S34: 2029 | T34: 0 | U34: 0
B35: 30_00_310_06104_5521 Total | M35: =SUBTOTAL(9,M34:M34) -> 42.0003
A36: Athletics | B36: 30_00_310_06110_5521 | C36: Administrative | D36: Cameron Hall | E36: 235 | F36: AF MPC6501 | G36: =VLOOKUP(F36,Tables!D$9:E$17,2,FALSE) -> MFP | H36: 17099490 | I36: =S36-R36 -> 15315 | J36: =U36-T36 -> 2952 | K36: =I36*$P36 -> 317.0205 | L36: =J36*$Q36 -> 256.824 | M36: =K36+L36 -> 573.8445 | N36: V7620400078 | O36: 144.75.183.56 | P36: =IF(G36="MFP",Tables!B$2,Tables!B$5) -> 0.0207 | Q36: =IF(G36="MFP",Tables!B$3,Tables!B$6) -> 0.087 | R36: 0 | S36: 15315 | T36: 0 | U36: 2952
A37: Athletics | B37: 30_00_310_06110_5521 | C37: Administrative | D37: Cameron Hall | E37: 241 | F37: AF SP4310N | G37: =VLOOKUP(F37,Tables!D$9:E$17,2,FALSE) -> PTR | H37: 17099552 | I37: =S37-R37 -> 1199 | J37: =U37-T37 -> 0 | K37: =I37*$P37 -> 31.4138 | L37: =J37*$Q37 -> 0 | M37: =K37+L37 -> 31.4138 | N37: T1129010427 | O37: 144.75.183.9 | P37: =IF(G37="MFP",Tables!B$2,Tables!B$5) -> 0.0262 | Q37: =IF(G37="MFP",Tables!B$3,Tables!B$6) -> 0.118 | R37: 0 | S37: 1199 | T37: 0 | U37: 0
A38: Athletics | B38: 30_00_310_06110_5521 | C38: Administrative | D38: Cameron Hall | E38: 242 | F38: AF SP4310N | G38: =VLOOKUP(F38,Tables!D$9:E$17,2,FALSE) -> PTR | H38: 17099553 | I38: =S38-R38 -> 491 | J38: =U38-T38 -> 0 | K38: =I38*$P38 -> 12.8642 | L38: =J38*$Q38 -> 0 | M38: =K38+L38 -> 12.8642 | N38: T1129010420 | O38: 144.75.183.64 | P38: =IF(G38="MFP",Tables!B$2,Tables!B$5) -> 0.0262 | Q38: =IF(G38="MFP",Tables!B$3,Tables!B$6) -> 0.118 | R38: 0 | S38: 491 | T38: 0 | U38: 0
A39: Athletics | B39: 30_00_310_06110_5521 | C39: Administrative | D39: Cameron Hall | E39: 302 | F39: AF MPC2051 | G39: =VLOOKUP(F39,Tables!D$9:E$17,2,FALSE) -> MFP | H39: 17099722 | I39: =S39-R39 -> 3285 | J39: =U39-T39 -> 6416 | K39: =I39*$P39 -> 67.9995 | L39: =J39*$Q39 -> 558.192 | M39: =K39+L39 -> 626.1915 | N39: V9725401418 | O39: 144.75.183.52 | P39: =IF(G39="MFP",Tables!B$2,Tables!B$5) -> 0.0207 | Q39: =IF(G39="MFP",Tables!B$3,Tables!B$6) -> 0.087 | R39: 0 | S39: 3285 | T39: 0 | U39: 6416
A40: Athletics | B40: 30_00_310_06110_5521 | C40: Administrative | D40: Cameron Hall | E40: 312 | F40: AF SP4310N | G40: =VLOOKUP(F40,Tables!D$9:E$17,2,FALSE) -> PTR | H40: 17099555 | I40: =S40-R40 -> 480 | J40: =U40-T40 -> 0 | K40: =I40*$P40 -> 12.576 | L40: =J40*$Q40 -> 0 | M40: =K40+L40 -> 12.576 | N40: T1129010428 | O40: 144.75.183.67 | P40: =IF(G40="MFP",Tables!B$2,Tables!B$5) -> 0.0262 | Q40: =IF(G40="MFP",Tables!B$3,Tables!B$6) -> 0.118 | R40: 0 | S40: 480 | T40: 0 | U40: 0
A41: Athletics | B41: 30_00_310_06110_5521 | C41: Administrative | D41: Cameron Hall | E41: Main | F41: AF SP4310N | G41: =VLOOKUP(F41,Tables!D$9:E$17,2,FALSE) -> PTR | H41: 17099554 | I41: =S41-R41 -> 282 | J41: =U41-T41 -> 0 | K41: =I41*$P41 -> 7.3884 | L41: =J41*$Q41 -> 0 | M41: =K41+L41 -> 7.3884 | N41: T1129010385 | O41: 144.75.183.63 | P41: =IF(G41="MFP",Tables!B$2,Tables!B$5) -> 0.0262 | Q41: =IF(G41="MFP",Tables!B$3,Tables!B$6) -> 0.118 | R41: 0 | S41: 282 | T41: 0 | U41: 0
...

Sheet Tables
A1: Rates
A2: MFP B&W | B2: 0.0207
A3: MFP Color | B3: 0.087
A5: Printer B&W | B5: 0.0262
A6: Printer Color | B6: 0.118
D8: Devices | E8: Type
D9: AF MP301SP | E9: MFP
D10: AF MP4002 | E10: MFP
D11: AF MP6001 | E11: MFP
D12: AF MPC2051 | E12: MFP
D13: AF MPC3502 | E13: MFP
D14: AF MPC4502 | E14: MFP
D15: AF MPC6501 | E15: MFP
D16: AF SP4310N | E16: PTR
D17: AF SPC242DN | E17: PTR

Sheet Totals
B1: Printer B&W | C1: =Tables!B5 -> 0.0262 | E1: B&W Printer | F1: Color Printer | G1: B/W Printer | H1: Color Printer
B2: Printer Color | C2: =Tables!B6 -> 0.118 | D2: Printer: | E2: =SUMIF('VIM Bill'!G3:G296,"PTR",'VIM Bill'!I3:I296) -> 269007 | F2: =SUMIF('VIM Bill'!G3:G296,"PTR",'VIM Bill'!J3:J296) -> 2225 | G2: =E2*C1 -> 7047.9834 | H2: =F2*C2 -> 262.55
B4: MFP B&W | C4: =Tables!B2 -> 0.0207 | E4: B&W MFP | F4: Color MFP | G4: B/W MFP | H4: Color MFP
B5: MFP Color | C5: =Tables!B3 -> 0.087 | D5: MFP: | E5: =SUMIF('VIM Bill'!G3:G296,"MFP",'VIM Bill'!I3:I296) -> 863265 | F5: =SUMIF('VIM Bill'!G3:G296,"MFP",'VIM Bill'!J3:J296) -> 130005 | G5: =SUM(E5)*C4 -> 17869.586 | H5: =F5*C5 -> 11310.435
E8: Total B&W | F8: Total Color | G8: Total B&W | H8: Total Color
A9: MFP Total: | B9: =COUNTIF('VIM Bill'!G3:G296,"MFP") -> 59 | D9: Total: | E9: =E2+E5 -> 1132272 | F9: =F2+F5 -> 132230 | G9: =G2+G5 -> 24917.569 | H9: =H2+H5 -> 11572.985
A10: Printer Total: | B10: =COUNTIF('VIM Bill'!G3:G296,"PTR") -> 158
A11: Device Total: | B11: =SUM(B9:B10) -> 217 | G11: Total This Invoice: | H11: =H9+G9 -> 36490.554

Sheet Additional Printers
A1: Department | B1: General Ledger | C1: GL Description | D1: Building | E1: Room | F1: Model | G1: Device Type | H1: Ricoh Tag
A2: Cadet Life | B2: 10_08_307_18380_5521 | C2: Student Union | D2: Lejuene Hall | E2: 3-117 | H2: 17099-486
A3: Cadet Life | B3: 10_08_307_18380_5521 | C3: Student Union | D3: Lejuene Hall | E3: 3-117 | H3: 17099-717
A4: Writing Center | B4: 10_03_045_99200_5521 | C4: Writing Center | D4: Carroll Hall | H4: 17099-453
A5: Cadet Counseling | B5: 10_08_308_52175_5521 | D5: Infirmiry | H5: 17099-636
A6: Cadet Counseling | B6: 10_08_308_52175_5521 | D6: Infirmiry | H6: 17099-603
A7: Cadet Counseling | B7: 10_08_308_52175_5521 | D7: Infirmiry | H7: 17099-604
