Workbook
Name Fridays: 'CFP Log'!$W$11:$W$62

Sheet Progress Invoice Request
B2: Proc Form | D2: PROGRESS INVOICE REQUEST | P2: Progress Invoice No.:
B3: PROC-2123 | D3: FOR CONSTRUCTION SUBCONTRACTS | P3: Subcontractor Invoice No.:
B4: (rev. 07-11) | D4: PROJECT TITLE: | G4: =T('Schedule Of Values'!D4:K4) | P4: Invoice(s) Attached: | T4: =IF(T3>=1,"Attached", "Required") -> Required
B5: Subcontractor: | D5: =T('Schedule Of Values'!C5:E5) | L5: Contract No.: | N5: =IF('Schedule Of Values'!H5>0,'Schedule Of Values'!H5,"") | P5: Original Contract Amount: | T5: ='Schedule Of Values'!K5 -> 0
B6: Address: | D6: =T('Schedule Of Values'!C6:E6) | L6: Subcontract Start Date: | N6: =IF('Schedule Of Values'!H6>0,'Schedule Of Values'!H6,"") | P6: Subcontract Completion Date: | T6: =IF('Schedule Of Values'!K6>0,'Schedule Of Values'!K6,"")
B8: Request for Payment | M8: Amendment(s) Summary
B10: 1- | C10: ORIGINAL CONTRACT AMOUNT | I10: =T5 -> 0 | R10: Additions | U10: Deductions
B11: 2- | C11: Net Approved Amendment(s) | I11: =R19 -> 0 | M11: Total changes approved in previous months by BEA via Amendment(s)
B12: 3- | C12: CONTRACT SUM TO DATE | I12: =I10+I11 -> 0
B13: 4- | C13: TOTAL COMPLETED & STORED TO DATE | I13: ='Progress Invoice Estimate'!H37 -> 0
B14: 5- | C14: RETAINAGE: | M14: Total changes approved by BEA via Amendment(s) this month
C15: a. % of Completed Work | G15: ='Progress Invoice Estimate'!I37 -> 0 | H15: ='Progress Invoice Estimate'!E37+'Progress Invoice Estimate'!F37 -> 0
C16: (Column D + E on Progress Invoice Estimate)
C17: b. % of Stored Material | G17: =IF('Progress Invoice Estimate'!G37=0,0,'Progress Invoice Estimate'!G37/'Progress Invoice Estimate'!D37) -> 0 | H17: ='Progress Invoice Estimate'!G37 -> 0 | M17: Total approved schedule impacts | R17: ='CFP Log'!P45 -> 0 | U17: Days
C18: (Column F on Progress Invoice Estimate)
C19: Total in Column J on Progress Invoice Estimate | I19: ='Progress Invoice Estimate'!K37 -> 0 | M19: NET CHANGES by Amendment(s) | R19: =(R11+U11)+(R14+U14) -> 0
B20: 6- | C20: TOTAL EARNED LESS RETAINAGE | I20: =I12-I19 -> 0
B22: 7- | C22: LESS PREVIOUS PAYMENT REQUEST(S) | G22: ='Progress Invoice Estimate'!E37+'Progress Invoice Estimate'!G37+(R11+U11) -> 0
B24: 8- | C24: CURRENT PAYMENT REQUEST | G24: ='Progress Invoice Estimate'!F37+'Progress Invoice Estimate'!G37+(R14-R11) -> 0 | M24: RELEASE OF CLAIMS
B25: 9- | C25: BALANCE TO FINISH, INCLUDING RETAINAGE | I25: =I12-I20 -> 0 | M25: As consideration for the issuance of this progress payment, the Subcontractor for itself, its predecessors, successors, and assigns, hereby releases and forever discharges BEA, the U.S. Government and their respective officers, agents, employees, successors, and assigns, jointly and severally, from any and all liabilities, claims, demands, losses, costs, expenses, actions or causes of action of whatever kind or character arising under or in connection with this Contract on or before the date of preparation as noted on this progress invoice. Any pending claims shall be listed in the area below, for future resolution between the parties. Any future discussions pertaining to claims already released, shall be considered as settlement discussions and not as reopening of a claim issue.
B28: CERTIFICATE OF THE SUBCONTRACTOR
B29: I hereby certify that the work performed and the materials supplied to date, as shown on the above represent the actual value of accomplishment under the terms of the Contract (and all authorized changes thereto) between the undersigned and Battelle Energy Alliance, LLC (BEA), and their respective officers, agents, employees, successors relating to the above referenced contract. I also certify that all laborers, materialmen, suppliers, contractors, and subcontractors used on or in connection with the performance of this contract have been paid in full, except as noted. I further certify that I have complied with all Federal, State, and Local tax laws, including Social Security laws and Unemployment Compensation laws and Workmen's Compensation laws insofar as applicable to the performance of this Contract. I further certify I have complied with all provisions relating to labor laws and regulations (including current Certified Payrolls) applicable to the work under this Subcontract.
M33: NOTED CLAIM(S)
H39: Subcontractor Signature | N39: Date
B41: BEA Approvals
C43: CERTIFICATION BY CFR:
C44: Scheduled % Complete | E44: =G15 -> 0 | G44: Actual % Completed | M44: =G24 -> 0 | P44: =I19 -> 0 | S44: =G24-P44 -> 0
M45: Total Request | P45: (Retainage) | S45: Authorized Amount to be Paid
C46: Vendor Data Current/Accepted | F46: Yes | H46: No
M48: Pay Authorization No. | P48: Please Pay Subcontractor by | S48: Final Payment
B49: Construction Field Representative Approval Signature | I49: Date
B51: Project Manager Approval Signature | I51: Date | M51: Subcontract Administrator Approval Signature | T51: Date

Sheet Progress Invoice Estimate
B2: Proc Form | C2: PROGRESS INVOICE ESTIMATE | I2: Progress Invoice No.: | K2: =N('Progress Invoice Request'!T2:U2) -> 0
B3: PROC - 2123 | C3: FOR | I3: Subcontractor Invoice No.: | K3: =N('Progress Invoice Request'!T3:U3) -> 0
B4: (rev. 07-11) | C4: CONSTRUCTION SUBCONTRACTS | I4: Invoice(s) Attached: | K4: =IF(K3,"Attached","Required") -> Required
B5: Subcontractor: | C5: =T('Progress Invoice Request'!D5:K5) | F5: Contract No.: | H5: =IF('Schedule Of Values'!H5>0,'Schedule Of Values'!H5,"") | I5: Original Contract Amount: | K5: ='Schedule Of Values'!K5 -> 0
B6: Project Title: | C6: =T('Progress Invoice Request'!G4:O4) | F6: Subcontract Start Date: | H6: =IF('Schedule Of Values'!H6>0,'Schedule Of Values'!H6,"") | I6: Subcontract Completion Date: | K6: =IF('Schedule Of Values'!K6>0,'Schedule Of Values'!K6,"")
B8: A | C8: B | D8: C | E8: D | F8: E | G8: F | H8: G | I8: H | J8: I | K8: J
B9: Code of Account | C9: Activity Description | D9: Scheduled Value | E9: Work Completed | G9: Material Dollars Presently Stored | H9: Total Completed to Date | I9: % | J9: Balance to Finish | K9: Retainage
E10: Previous Request | F10: Current Period
E12: (D + E) | G12: (NOT IN D OR E) | H12: (D + E + F) | I12: (G / C) | J12: (C - G)
B13: ='Schedule Of Values'!B10 -> WBS 1 | C13: =IF('Schedule Of Values'!C10>0,'Schedule Of Values'!C10,"") | D13: ='Schedule Of Values'!K10 -> 0 | H13: =E13+F13+G13 -> 0 | I13: =IF(H13=0,0,H13/D13) -> 0 | J13: =D13-H13 -> 0 | K13: =(F13+G13)*$K$12 -> 0
B14: ='Schedule Of Values'!B19 -> WBS 2 | C14: =IF('Schedule Of Values'!C19>0,'Schedule Of Values'!C19,"") | D14: ='Schedule Of Values'!K19 -> 0 | H14: =E14+F14+G14 -> 0 | I14: =IF(H14=0,0,H14/D14) -> 0 | J14: =D14-H14 -> 0 | K14: =(F14+G14)*$K$12 -> 0
B15: ='Schedule Of Values'!B27 -> WBS 3 | C15: =IF('Schedule Of Values'!C27>0,'Schedule Of Values'!C27,"") | D15: ='Schedule Of Values'!K27 -> 0 | H15: =E15+F15+G15 -> 0 | I15: =IF(H15=0,0,H15/D15) -> 0 | J15: =D15-H15 -> 0 | K15: =(F15+G15)*$K$12 -> 0
B16: ='Schedule Of Values'!B31 -> WBS 4 | C16: =IF('Schedule Of Values'!C31>0,'Schedule Of Values'!C31,"") | D16: ='Schedule Of Values'!K31 -> 0 | H16: =E16+F16+G16 -> 0 | I16: =IF(H16=0,0,H16/D16) -> 0 | J16: =D16-H16 -> 0 | K16: =(F16+G16)*$K$12 -> 0
B17: ='Schedule Of Values'!B35 -> WBS 5 | C17: =IF('Schedule Of Values'!C35>0,'Schedule Of Values'!C35,"") | D17: ='Schedule Of Values'!K35 -> 0 | H17: =E17+F17+G17 -> 0 | I17: =IF(H17=0,0,H17/D17) -> 0 | J17: =D17-H17 -> 0 | K17: =(F17+G17)*$K$12 -> 0
B18: ='Schedule Of Values'!B39 -> WBS 6 | C18: =IF('Schedule Of Values'!C39>0,'Schedule Of Values'!C39,"") | D18: ='Schedule Of Values'!K39 -> 0 | H18: =E18+F18+G18 -> 0 | I18: =IF(H18=0,0,H18/D18) -> 0 | J18: =D18-H18 -> 0 | K18: =(F18+G18)*$K$12 -> 0
B19: ='Schedule Of Values'!B43 -> WBS 7 | C19: =IF('Schedule Of Values'!C43>0,'Schedule Of Values'!C43,"") | D19: ='Schedule Of Values'!K43 -> 0 | H19: =E19+F19+G19 -> 0 | I19: =IF(H19=0,0,H19/D19) -> 0 | J19: =D19-H19 -> 0 | K19: =(F19+G19)*$K$12 -> 0
B20: ='Schedule Of Values'!B47 -> WBS 8 | C20: =IF('Schedule Of Values'!C47>0,'Schedule Of Values'!C47,"") | D20: ='Schedule Of Values'!K47 -> 0 | H20: =E20+F20+G20 -> 0 | I20: =IF(H20=0,0,H20/D20) -> 0 | J20: =D20-H20 -> 0 | K20: =(F20+G20)*$K$12 -> 0
B21: ='Schedule Of Values'!B51 -> WBS 9 | C21: =IF('Schedule Of Values'!C51>0,'Schedule Of Values'!C51,"") | D21: ='Schedule Of Values'!K51 -> 0 | H21: =E21+F21+G21 -> 0 | I21: =IF(H21=0,0,H21/D21) -> 0 | J21: =D21-H21 -> 0 | K21: =(F21+G21)*$K$12 -> 0
B22: ='Schedule Of Values'!B55 -> WBS 10 | C22: =IF('Schedule Of Values'!C55>0,'Schedule Of Values'!C55,"") | D22: ='Schedule Of Values'!K55 -> 0 | H22: =E22+F22+G22 -> 0 | I22: =IF(H22=0,0,H22/D22) -> 0 | J22: =D22-H22 -> 0 | K22: =(F22+G22)*$K$12 -> 0
B23: ='Schedule Of Values'!B59 -> WBS 11 | C23: =IF('Schedule Of Values'!C59>0,'Schedule Of Values'!C59,"") | D23: ='Schedule Of Values'!K59 -> 0 | H23: =E23+F23+G23 -> 0 | I23: =IF(H23=0,0,H23/D23) -> 0 | J23: =D23-H23 -> 0 | K23: =(F23+G23)*$K$12 -> 0
B24: ='Schedule Of Values'!B63 -> WBS 12 | C24: =IF('Schedule Of Values'!C63>0,'Schedule Of Values'!C63,"") | D24: ='Schedule Of Values'!K63 -> 0 | H24: =E24+F24+G24 -> 0 | I24: =IF(H24=0,0,H24/D24) -> 0 | J24: =D24-H24 -> 0 | K24: =(F24+G24)*$K$12 -> 0
B25: ='Schedule Of Values'!B67 -> WBS 13 | C25: =IF('Schedule Of Values'!C67>0,'Schedule Of Values'!C67,"") | D25: ='Schedule Of Values'!K67 -> 0 | H25: =E25+F25+G25 -> 0 | I25: =IF(H25=0,0,H25/D25) -> 0 | J25: =D25-H25 -> 0 | K25: =(F25+G25)*$K$12 -> 0
B26: ='Schedule Of Values'!B71 -> WBS 14 | C26: =IF('Schedule Of Values'!C71>0,'Schedule Of Values'!C71,"") | D26: ='Schedule Of Values'!K71 -> 0 | H26: =E26+F26+G26 -> 0 | I26: =IF(H26=0,0,H26/D26) -> 0 | J26: =D26-H26 -> 0 | K26: =(F26+G26)*$K$12 -> 0
B27: ='Schedule Of Values'!B75 -> WBS 15 | C27: =IF('Schedule Of Values'!C75>0,'Schedule Of Values'!C75,"") | D27: ='Schedule Of Values'!K75 -> 0 | H27: =E27+F27+G27 -> 0 | I27: =IF(H27=0,0,H27/D27) -> 0 | J27: =D27-H27 -> 0 | K27: =(F27+G27)*$K$12 -> 0
B28: ='Schedule Of Values'!B79 -> WBS 16 | C28: =IF('Schedule Of Values'!C79>0,'Schedule Of Values'!C79,"") | D28: ='Schedule Of Values'!K79 -> 0 | H28: =E28+F28+G28 -> 0 | I28: =IF(H28=0,0,H28/D28) -> 0 | J28: =D28-H28 -> 0 | K28: =(F28+G28)*$K$12 -> 0
B29: ='Schedule Of Values'!B83 -> WBS 17 | C29: =IF('Schedule Of Values'!C83>0,'Schedule Of Values'!C83,"") | D29: ='Schedule Of Values'!K83 -> 0 | H29: =E29+F29+G29 -> 0 | I29: =IF(H29=0,0,H29/D29) -> 0 | J29: =D29-H29 -> 0 | K29: =(F29+G29)*$K$12 -> 0
H30: =E30+F30+G30 -> 0 | I30: =IF(H30=0,0,H30/D30) -> 0 | J30: =D30-H30 -> 0 | K30: =(F30+G30)*$K$12 -> 0
H31: =E31+F31+G31 -> 0 | I31: =IF(H31=0,0,H31/D31) -> 0 | J31: =D31-H31 -> 0 | K31: =(F31+G31)*$K$12 -> 0
H32: =E32+F32+G32 -> 0 | I32: =IF(H32=0,0,H32/D32) -> 0 | J32: =D32-H32 -> 0 | K32: =(F32+G32)*$K$12 -> 0
H33: =E33+F33+G33 -> 0 | I33: =IF(H33=0,0,H33/D33) -> 0 | J33: =D33-H33 -> 0 | K33: =(F33+G33)*$K$12 -> 0
H34: =E34+F34+G34 -> 0 | I34: =IF(H34=0,0,H34/D34) -> 0 | J34: =D34-H34 -> 0 | K34: =(F34+G34)*$K$12 -> 0
H35: =E35+F35+G35 -> 0 | I35: =IF(H35=0,0,H35/D35) -> 0 | J35: =D35-H35 -> 0 | K35: =(F35+G35)*$K$12 -> 0
H36: =E36+F36+G36 -> 0 | I36: =IF(H36=0,0,H36/D36) -> 0 | J36: =D36-H36 -> 0 | K36: =(F36+G36)*$K$12 -> 0
B37: TOTALS | D37: =SUM(D13:D36) -> 0 | E37: =SUM(E13:E36) -> 0 | F37: =SUM(F13:F36) -> 0 | G37: =SUM(G13:G36) -> 0 | H37: =SUM(H13:H36) -> 0 | I37: =IF(H37=0,0,H37/D37) -> 0 | J37: =SUM(J13:J36) -> 0 | K37: =SUM(K13:K36) -> 0

Sheet Schedule Of Values
B2: SCHEDULE OF VALUES
B3: FOR CONSTRUCTION SUBCONTRACTS
B4: Project Title:
B5: Subcontractor: | F5: Contract No.: | I5: Original Contract Amount:
B6: Address: | F6: Subcontract Start Date: | I6: Subcontract Completion Date:
B8: Code of Account | C8: Activity Description | D8: UOM | E8: Quantity | F8: Work Hours | G8: Labor Dollars | H8: Permanent Material Dollars | I8: Other Dollars | J8: % of Total | K8: Total Value
B10: WBS 1 | E10: =SUM(E11:E17) -> 0 | F10: =SUM(F11:F17) -> 0 | G10: =SUM(G11:G17) -> 0 | H10: =SUM(H11:H17) -> 0 | I10: =SUM(I11:I17) -> 0 | J10: =IF(K10=0,0,K10/SUM(G10:I10)) -> 0 | K10: =G10+H10+I10 -> 0
J11: =IF($K$10=0,0,SUM(G11:I11)/$K$10) -> 0 | K11: =G11+H11+I11 -> 0
J12: =IF($K$10=0,0,SUM(G12:I12)/$K$10) -> 0 | K12: =G12+H12+I12 -> 0
J13: =IF($K$10=0,0,SUM(G13:I13)/$K$10) -> 0 | K13: =G13+H13+I13 -> 0
J14: =IF($K$10=0,0,SUM(G14:I14)/$K$10) -> 0 | K14: =G14+H14+I14 -> 0
J15: =IF($K$10=0,0,SUM(G15:I15)/$K$10) -> 0 | K15: =G15+H15+I15 -> 0
J16: =IF($K$10=0,0,SUM(G16:I16)/$K$10) -> 0 | K16: =G16+H16+I16 -> 0
J17: =IF($K$10=0,0,SUM(G17:I17)/$K$10) -> 0 | K17: =G17+H17+I17 -> 0
B18: (if more lines are needed, right-click mouse ON LAST CATEGORY ROW, "copy" and "insert copied cells" in same row as copied, this will update all necessary formulas)
B19: WBS 2 | E19: =SUM(E20:E25) -> 0 | F19: =SUM(F20:F25) -> 0 | G19: =SUM(G20:G25) -> 0 | H19: =SUM(H20:H25) -> 0 | I19: =SUM(I20:I25) -> 0 | J19: =IF(K19=0,0,K19/SUM(G19:I19)) -> 0 | K19: =G19+H19+I19 -> 0
J20: =IF($K$19=0,0,SUM(G20:I20)/$K$19) -> 0 | K20: =G20+H20+I20 -> 0
J21: =IF($K$19=0,0,SUM(G21:I21)/$K$19) -> 0 | K21: =G21+H21+I21 -> 0
J22: =IF($K$19=0,0,SUM(G22:I22)/$K$19) -> 0 | K22: =G22+H22+I22 -> 0
J23: =IF($K$19=0,0,SUM(G23:I23)/$K$19) -> 0 | K23: =G23+H23+I23 -> 0
J24: =IF($K$19=0,0,SUM(G24:I24)/$K$19) -> 0 | K24: =G24+H24+I24 -> 0
J25: =IF($K$19=0,0,SUM(G25:I25)/$K$19) -> 0 | K25: =G25+H25+I25 -> 0
B26: (if more lines are needed, right-click mouse ON LAST CATEGORY ROW, "copy" and "insert copied cells" in same row as copied, this will update all necessary formulas)
B27: WBS 3 | E27: =SUM(E28:E29) -> 0 | F27: =SUM(F28:F29) -> 0 | G27: =SUM(G28:G29) -> 0 | H27: =SUM(H28:H29) -> 0 | I27: =SUM(I28:I29) -> 0 | J27: =IF(K27=0,0,K27/SUM(G27:I27)) -> 0 | K27: =G27+H27+I27 -> 0
J28: =IF($K$27=0,0,SUM(G28:I28)/$K$27) -> 0 | K28: =G28+H28+I28 -> 0
J29: =IF($K$27=0,0,SUM(G29:I29)/$K$27) -> 0 | K29: =G29+H29+I29 -> 0
B30: (if more lines are needed, right-click mouse ON LAST CATEGORY ROW, "copy" and "insert copied cells" in same row as copied, this will update all necessary formulas)
B31: WBS 4 | E31: =SUM(E32:E33) -> 0 | F31: =SUM(F32:F33) -> 0 | G31: =SUM(G32:G33) -> 0 | H31: =SUM(H32:H33) -> 0 | I31: =SUM(I32:I33) -> 0 | J31: =IF(K31=0,0,K31/SUM(G31:I31)) -> 0 | K31: =G31+H31+I31 -> 0
J32: =IF($K$31=0,0,SUM(G32:I32)/$K$31) -> 0 | K32: =G32+H32+I32 -> 0
J33: =IF($K$31=0,0,SUM(G33:I33)/$K$31) -> 0 | K33: =G33+H33+I33 -> 0
B34: (if more lines are needed, right-click mouse ON LAST CATEGORY ROW, "copy" and "insert copied cells" in same row as copied, this will update all necessary formulas)
B35: WBS 5 | E35: =SUM(E36:E37) -> 0 | F35: =SUM(F36:F37) -> 0 | G35: =SUM(G36:G37) -> 0 | H35: =SUM(H36:H37) -> 0 | I35: =SUM(I36:I37) -> 0 | J35: =IF(K35=0,0,K35/SUM(G35:I35)) -> 0 | K35: =G35+H35+I35 -> 0
J36: =IF($K$35=0,0,SUM(G36:I36)/$K$35) -> 0 | K36: =G36+H36+I36 -> 0
J37: =IF($K$35=0,0,SUM(G37:I37)/$K$35) -> 0 | K37: =G37+H37+I37 -> 0
B38: (if more lines are needed, right-click mouse ON LAST CATEGORY ROW, "copy" and "insert copied cells" in same row as copied, this will update all necessary formulas)
B39: WBS 6 | E39: =SUM(E40:E41) -> 0 | F39: =SUM(F40:F41) -> 0 | G39: =SUM(G40:G41) -> 0 | H39: =SUM(H40:H41) -> 0 | I39: =SUM(I40:I41) -> 0 | J39: =IF(K39=0,0,K39/SUM(G39:I39)) -> 0 | K39: =G39+H39+I39 -> 0
J40: =IF($K$39=0,0,SUM(G40:I40)/$K$39) -> 0 | K40: =G40+H40+I40 -> 0
J41: =IF($K$39=0,0,SUM(G41:I41)/$K$39) -> 0 | K41: =G41+H41+I41 -> 0
B42: (if more lines are needed, right-click mouse ON LAST CATEGORY ROW, "copy" and "insert copied cells" in same row as copied, this will update all necessary formulas)
B43: WBS 7 | E43: =SUM(E44:E45) -> 0 | F43: =SUM(F44:F45) -> 0 | G43: =SUM(G44:G45) -> 0 | H43: =SUM(H44:H45) -> 0 | I43: =SUM(I44:I45) -> 0 | J43: =IF(K43=0,0,K43/SUM(G43:I43)) -> 0 | K43: =G43+H43+I43 -> 0
...

Sheet CFP Log
B2: CONSTRUCTION FIELD CHANGE/PROBLEM LOG
B4: Project Title: | F4: =T('Schedule Of Values'!D4:H4)
B5: Subcontractor: | E5: =T('Schedule Of Values'!C5:E5) | G5: Contract No.: | H5: =IF('Schedule Of Values'!H5>0,'Schedule Of Values'!H5,"") | M5: Original Contract Amount: | O5: ='Schedule Of Values'!K5 -> 0
B6: Address: | E6: =T('Schedule Of Values'!C6:E6) | G6: Subcontract Start Date: | H6: =IF('Schedule Of Values'!H6>0,'Schedule Of Values'!H6,"") | M6: Revised Completion Date: | O6: =IF('Schedule Of Values'!K6>0,WORKDAY('Schedule Of Values'!K6,P45,Fridays),"")
B8: CFP/C No. | C8: Originator | E8: Date Submitted | F8: Subject | G8: Proposed Cost | H8: Negotiated Price | K8: Date Approved | M8: Date Declined | N8: Amendment No. | O8: WBS No. | P8: Schedule Impact
C9: BEA | D9: SUB | I9: Accepted Cost | J9: Accepted Total | L9: Declined Total | P9: (+/-)
B10: 001 | Q10: Days | W10: Fridays
B11: 2 | I11: =IF(H11>0,H11,G11) -> 0 | J11: =IF(K11>0,I11,"") | Q11: Days | W11: 40550
B12: 3 | I12: =IF(H12>0,H12,G12) -> 0 | J12: =IF(K12>0,I12,"") | Q12: Days | W12: 40557
B13: 4 | I13: =IF(H13>0,H13,G13) -> 0 | J13: =IF(K13>0,I13,"") | L13: =IF(M13>0,G13,"") | Q13: Days | W13: 40564
B14: 5 | I14: =IF(H14>0,H14,G14) -> 0 | J14: =IF(K14>0,I14,"") | L14: =IF(M14>0,G14,"") | Q14: Days | W14: 40571
B15: 6 | I15: =IF(H15>0,H15,G15) -> 0 | J15: =IF(K15>0,I15,"") | L15: =IF(M15>0,G15,"") | Q15: Days | W15: 40578
B16: 7 | I16: =IF(H16>0,H16,G16) -> 0 | J16: =IF(K16>0,I16,"") | L16: =IF(M16>0,G16,"") | Q16: Days | W16: 40585
B17: 8 | I17: =IF(H17>0,H17,G17) -> 0 | J17: =IF(K17>0,I17,"") | L17: =IF(M17>0,G17,"") | Q17: Days | W17: 40592
B18: 9 | I18: =IF(H18>0,H18,G18) -> 0 | J18: =IF(K18>0,I18,"") | L18: =IF(M18>0,G18,"") | Q18: Days | W18: 40599
B19: 10 | I19: =IF(H19>0,H19,G19) -> 0 | J19: =IF(K19>0,I19,"") | L19: =IF(M19>0,G19,"") | Q19: Days | W19: 40606
B20: 11 | I20: =IF(H20>0,H20,G20) -> 0 | J20: =IF(K20>0,I20,"") | L20: =IF(M20>0,G20,"") | Q20: Days | W20: 40613
B21: 12 | I21: =IF(H21>0,H21,G21) -> 0 | J21: =IF(K21>0,I21,"") | L21: =IF(M21>0,G21,"") | Q21: Days | W21: 40620
B22: 13 | I22: =IF(H22>0,H22,G22) -> 0 | J22: =IF(K22>0,I22,"") | L22: =IF(M22>0,G22,"") | Q22: Days | W22: 40627
B23: 14 | I23: =IF(H23>0,H23,G23) -> 0 | J23: =IF(K23>0,I23,"") | L23: =IF(M23>0,G23,"") | Q23: Days | W23: 40634
B24: 15 | I24: =IF(H24>0,H24,G24) -> 0 | J24: =IF(K24>0,I24,"") | L24: =IF(M24>0,G24,"") | Q24: Days | W24: 40641
... B28: 19 | I28: =IF(H28>0,H28,G28) -> 0 | J28: =IF(K28>0,I28,"") | L28: =IF(M28>0,G28,"") | Q28: Days | W28: 40669
B29: 20 | I29: =IF(H29>0,H29,G29) -> 0 | J29: =IF(K29>0,I29,"") | L29: =IF(#REF!>0,G29,"") -> #REF! | Q29: Days | W29: 40676
B30: 21 | I30: =IF(H30>0,H30,G30) -> 0 | J30: =IF(K30>0,I30,"") | L30: =IF(M30>0,G30,"") | Q30: Days | W30: 40683
B31: 22 | I31: =IF(H31>0,H31,G31) -> 0 | J31: =IF(K31>0,I31,"") | L31: =IF(M31>0,G31,"") | Q31: Days | W31: 40690
B32: 23 | I32: =IF(H32>0,H32,G32) -> 0 | J32: =IF(K32>0,I32,"") | L32: =IF(M32>0,G32,"") | Q32: Days | W32: 40697
B33: 24 | I33: =IF(H33>0,H33,G33) -> 0 | J33: =IF(K33>0,I33,"") | L33: =IF(M33>0,G33,"") | Q33: Days | W33: 40704
B34: 25 | I34: =IF(H34>0,H34,G34) -> 0 | J34: =IF(K34>0,I34,"") | L34: =IF(M34>0,G34,"") | Q34: Days | W34: 40711
B35: 26 | I35: =IF(H35>0,H35,G35) -> 0 | J35: =IF(K35>0,I35,"") | L35: =IF(M35>0,G35,"") | Q35: Days | W35: 40718
B36: 27 | I36: =IF(H36>0,H36,G36) -> 0 | J36: =IF(K36>0,I36,"") | L36: =IF(M36>0,G36,"") | Q36: Days | W36: 40725
B37: 28 | I37: =IF(H37>0,H37,G37) -> 0 | J37: =IF(K37>0,I37,"") | L37: =IF(M37>0,G37,"") | Q37: Days | W37: 40732
B38: 29 | I38: =IF(H38>0,H38,G38) -> 0 | J38: =IF(K38>0,I38,"") | L38: =IF(M38>0,G38,"") | Q38: Days | W38: 40739
B39: 30 | I39: =IF(H39>0,H39,G39) -> 0 | J39: =IF(K39>0,I39,"") | L39: =IF(M39>0,G39,"") | Q39: Days | W39: 40746
B40: 31 | I40: =IF(H40>0,H40,G40) -> 0 | J40: =IF(K40>0,I40,"") | L40: =IF(M40>0,G40,"") | Q40: Days | W40: 40753
B41: 32 | I41: =IF(H41>0,H41,G41) -> 0 | J41: =IF(K41>0,I41,"") | L41: =IF(M41>0,G41,"") | Q41: Days | W41: 40760
... B43: 34 | I43: =IF(H43>0,H43,G43) -> 0 | J43: =IF(K43>0,I43,"") | L43: =IF(M43>0,G43,"") | Q43: Days | W43: 40774
B44: (if more lines are needed, right-click mouse ON LAST ROW, "copy" and "insert copied cells" in same row as copied, this will update all necessary formulas) | W44: 40781
B45: TOTALS | G45: =SUM(G10:G44) -> 0 | H45: =SUM(H10:H44) -> 0 | J45: =SUM(J10:J43) -> 0 | K45: =COUNT(K10:K43) -> 0 | L45: =SUM(L10:L43) -> #REF! | M45: =COUNT(M10:M43) -> 0 | P45: =SUM(P10:P44) -> 0 | Q45: Days | W45: 40788
W46: 40795
W47: 40802
...
