Workbook
Name factype: CSSF!$A$4:$A$22

Sheet ACSSF
A1: Texas Higher Education Coordinating Board
A2: Standard Construction Cost - Adjusted for Future Inflation
A4: Update the blue shaded areas to calculate the Standard Construction Cost - Adjusted for Future Inflation per THECB rule 17.30 (2) (b)
B7: Daily Treasury Yield Curve Rates
B8: 40787 | C8: Yield Rate | D8: As of Date
B9: =DATE(YEAR($B$8),MONTH($B$8)+1,1) -> 40817 | C9: One-Month | D9: 0.02
B10: =DATE(YEAR($B$8),MONTH($B$8)+3,1) -> 40878 | C10: Three-Month | D10: 0.02
B11: =DATE(YEAR($B$8),MONTH($B$8)+6,1) -> 40969 | C11: Six-Month | D11: 0.05
B12: =DATE(YEAR($B$8)+1,MONTH($B$8),1) -> 41153 | C12: One-Year | D12: 0.1
B13: =DATE(YEAR($B$8)+2,MONTH($B$8),1) -> 41518 | C13: Two-Year | D13: 0.19
B14: =DATE(YEAR($B$8)+3,MONTH($B$8),1) -> 41883 | C14: Three-Year | D14: 0.31
B15: =DATE(YEAR($B$8)+5,MONTH($B$8),1) -> 42614 | C15: Five-Year | D15: 0.9
B16: =DATE(YEAR($B$8)+7,MONTH($B$8),1) -> 43344 | C16: Seven-Year | D16: 1.49
B17: =DATE(YEAR($B$8)+10,MONTH($B$8),1) -> 44440 | C17: Ten-Year | D17: 2.15
B18: =DATE(YEAR($B$8)+20,MONTH($B$8),1) -> 48092 | C18: Twenty-Year | D18: 3.1
B19: =DATE(YEAR($B$8)+30,MONTH($B$8),1) -> 51745 | C19: Thirty-Year | D19: 3.51
A21: Construction Type | D21: New Construction
A23: Facility Type | D23: Athletic
A25: Start Date (MM/1/YYYY) | D25: 39783
A27: Finish Date (MM/1/YYYY) | D27: 40057
A29: Calculated Project Midpoint | D29: =D25+(D27-D25)/2 -> 39920
A31: ="Cost per Square Foot as Reported "&TEXT(CSSF!B2,"MMMM YYYY") -> Cost per Square Foot as Reported October 2011 | D31: =VLOOKUP(D23,CSSF!A4:C22,IF(ACSSF!D21="new construction",2,3)) -> 315
A33: ="ENR Construction Index "&TEXT(CSSF!B2,"MMMM YYYY") -> ENR Construction Index October 2011 | D33: 5104
A35: ENR Construction Index Last Reported Month (MM/1/YYYY) | D35: 40817
A37: ="ENR Construction Index as of "&TEXT(D35,"MMMM YYYY") -> ENR Construction Index as of October 2011 | D37: 5104
A39: ="ENR Construction Index to "&TEXT(D35,"MMMM YYYY") -> ENR Construction Index to October 2011 | D39: =D37/D33 -> 1
A41: ="Treasury Yield Adjustment to "&IF(ISERROR(VLOOKUP($D$29,ACSSF!$B$9:$D$19,1,TRUE)),TEXT(B8,"MMMM YYYY"),TEXT(VLOOKUP($D$29,ACSSF!$B$9:$D$19,1,TRUE),"MMMM YYYY"))&" using the "&IF(ISERROR(VLOOKUP($D$29,ACSSF!$B$9:$D$19,2,TRUE)),"current day",VLOOKUP($D$29,ACSSF!$B$9:$D$19,2,TRUE))&" yield rate" -> Treasury Yield Adjustment to September 2011 using the current day yield rate | D41: =(1+IF(ISERROR(VLOOKUP($D$29,ACSSF!$B$9:$D$19,3,TRUE)),0,VLOOKUP($D$29,ACSSF!$B$9:$D$19,3,TRUE))/100) -> 1
A44: Overall Adjustment Factor | D44: =D39*D41 -> 1
A46: Adjusted Cost per Square Foot | D46: =D44*D31 -> 315
A48: This calculator uses the Treasury Bill yield and ICPS application start and finish dates to project future construction costs. The published construction costs standards are inflated to the latest ENR index and then projected using the latest Treasury Bill Yield Curve.
D52: =NOW() -> 40813.627
A63: Facility Type
A64: Athletic
A65: Auditorium/Theater
A66: Childcare
A67: Classroom, General
A68: Classroom, Medical/Healthcare
A69: Food Service
A70: Healthcare Facility, Clinic
A71: Healthcare Facility, Hospital
...

Sheet CSSF
A1: Cost per Square Foot
A2: Month Reported | B2: 40817
A3: Facility Type | B3: NC AVG + 1STD | C3: RR AVG + 1STD
A4: Athletic | B4: 315 | C4: 188
A5: Auditorium/Theater | B5: 536 | C5: 359
A6: Classroom, General | B6: 393 | C6: 221
A7: Classroom, Medical/Healthcare | B7: 364 | C7: 255
A8: Food Service | B8: 313 | C8: 226
A9: Healthcare Facility, Clinic | B9: 398 | C9: 167
A10: Healthcare Facility, Hospital | B10: 426 | C10: 340
A11: Housing, Apartments | B11: 170 | C11: 81
A12: Housing, Dormitory | B12: 233 | C12: 154
A13: Laboratory, General | B13: 484 | C13: 374
A14: Laboratory, Medical/Healthcare | B14: 644 | C14: 534
A15: Library/Study Facilities | B15: 317 | C15: 183
... A22: Student Center | B22: 393 | C22: 141

Sheet Instructions
A1: Instructions for Use of Construction Cost Calculator
A3: The cells highlighted yellow and green provide links to the sources used to determine inflation. The Daily Treasury yield will be used to predict future inflation, whereas the ENR Construction Index provides actual inflation history. The dates in cells 8B and 35D need to be the same, so it may sometimes be necessary to use the previous month's data for the Treasury Yield rate if the ENR BCI is not yet available.
A7: Step 1- Click on the yellow highlighted "Daily Treasury" cell to find the 30 yr inflation projection. Copy data into the spreadsheet.
A9: Step 2- Choose the appropriate construction and facility type as well as start and end date from the project application.
A11: Step 3- Making sure that the dates in 8B and 35D match, click on the green highlighted ENR Index cell. Click on the Building Cost Index History. Username: “capital” Password: “planning”. Find the corresponding ENR Cost Index for the month you are using and put that number in cell 37D.
A14: All other fields are auto-calculated. For reference, the second tab in the workbook has the annual calculations for the cost per square foot (the average plus one standard deviation) by category (which are linked to the first worksheet).
