Workbook
Name _Toc443301354: 'SF Residential - COS'!#REF!
Name _Toc443301354: 'SF Residential - Linear'!#REF!
Name Print_Area_MI: 'SF Residential - COS'!#REF!
Name Print_Area_MI: 'SF Residential - Linear'!#REF!

Sheet Totals
A1: Totals Worksheet
A3: Potential Contractor's Proposed Annual Solid Waste Collection Fee Revenue
A4: Base Proposal | G4: Enhancements Proposals
B5: Proposal Total for Basic Solid Waste Collection Services | C5: Proposal Total for Other Collection Services | D5: Proposal Total | G5: Revenue Increase/(Decrease) for Collection Service Enhancements
G6: Saturday | H6: Single-family | J6: Multifamily On-Call | K6: Organics | L6: In-City Customer
G7: Collection | H7: Additional | I7: Unlimited | J7: Small Appliance, | K7: Recycling - | L7: Service
G8: for Friday | H8: Recyclables | I8: Commercial | J8: Electronics, | K8: 1 96 Gallon | L8: Opportunities
G9: Single-family | H9: Where | I9: Recycling | J9: & Textiles | K9: Cart/Week | L9: per Contract
G10: Misses | H10: Feasible | J10: Recycling | K10: Limit | L10: Section 3.3.2.1
A11: SF Residential - COS Rates | B11: ='SF Residential - COS'!F20 -> 0 | C11: ='SF Residential - COS'!F42 -> 0 | D11: ='SF Residential - COS'!F44 -> 0 | G11: ='SF Residential - COS'!K44 -> 0 | H11: ='SF Residential - COS'!L44 -> 0 | I11: Not Applicable | J11: Not Applicable | K11: Not Applicable | L11: ='SF Residential - COS'!M44 -> 0
A12: Commercial/Multifamily Cart/Container | B12: =Commercial!F99 -> 0 | C12: =Commercial!F155 -> 0 | D12: =Commercial!F157 -> 0 | G12: Not Applicable | H12: Not Applicable | I12: =Commercial!K157 -> 0 | J12: =Commercial!L157 -> 0 | K12: =Commercial!M157 -> 0 | L12: =Commercial!N157 -> 0
A13: Commercial/Multifamily Drop-box | B13: ='Drop-box'!D37 -> 0 | C13: ='Drop-box'!D74 -> 0 | D13: ='Drop-box'!D76 -> 0 | G13: Not Applicable | H13: Not Applicable | I13: ='Drop-box'!I37 -> 0 | J13: ='Drop-box'!J37 -> 0 | K13: ='Drop-box'!K37 -> 0 | L13: ='Drop-box'!L37 -> 0
A14: Proposal Total | B14: =SUM(B11:B13) -> 0 | C14: =SUM(C11:C13) -> 0 | D14: =SUM(D11:D13) -> 0 | G14: =SUM(G11:G13) -> 0 | H14: =SUM(H11:H13) -> 0 | I14: =SUM(I11:I13) -> 0 | J14: =SUM(J11:J13) -> 0 | K14: =SUM(K11:K13) -> 0 | L14: =SUM(L11:L13) -> 0
A15: Note: Green shaded cell shows proponent's total revenue proposal.
A18: Residential Linear Rates Structure Proposal | G18: Enhancements Proposals for Residential Linear Rates Structure
A19: SF Residential - Linear Rates | B19: ='SF Residential - Linear'!F20 -> 0 | C19: ='SF Residential - Linear'!F42 -> 0 | D19: ='SF Residential - Linear'!F44 -> 0 | G19: ='SF Residential - Linear'!K44 -> 0 | H19: ='SF Residential - Linear'!L44 -> 0 | I19: Not Applicable | J19: Not Applicable | K19: Not Applicable | L19: ='SF Residential - Linear'!M44 -> 0

Sheet Drop-box
A1: Drop-box Worksheet
A3: CITY OF BELLEVUE
A4: Garbage and Organics Service Fees
A5: yellow is a contractor modifiable field | I5: Haul Fee Increase/(Decrease) for Service Enhancements
J6: Multifamily On-Call | K6: Organics | L6: In-City Customer
I7: Unlimited | J7: Small Appliance, | K7: Recycling - | L7: Service
D8: Proposed | I8: Commercial | J8: Electronics, | K8: 1 96 Gallon | L8: Opportunities
A9: COMMERCIAL/MULTIFAMILY SERVICES | D9: Haul | I9: Recycling | J9: & Textiles | K9: Cart/Week | L9: per Contract
A10: Noncompacted Permanent Service | B10: # of Customers | C10: Hauls/Month | D10: Fee | J10: Recycling | K10: Limit | L10: Section 3.3.2.1
A11: 1 10 Cu. Yd. Container | B11: 1 | C11: =1*2 -> 2 | D11: 0 | I11: 0 | J11: 0 | K11: 0 | L11: 0
A12: 1 12 Cu. Yd. Container | B12: 4 | C12: =11*2 -> 22 | D12: 0 | I12: 0 | J12: 0 | K12: 0 | L12: 0
A13: 1 15 Cu. Yd. Container | B13: 3 | C13: =3*2 -> 6 | D13: 0 | I13: 0 | J13: 0 | K13: 0 | L13: 0
A14: 1 20 Cu. Yd. Container | B14: 3 | C14: =3*2 -> 6 | D14: 0 | I14: 0 | J14: 0 | K14: 0 | L14: 0
A15: 1 25 Cu. Yd. Container | B15: =24+6+1+1 -> 32 | C15: =24*2+6*(52/12)+1*3*(52/12)+1*5*(52/12) -> 108.66667 | D15: 0 | I15: 0 | J15: 0 | K15: 0 | L15: 0
A16: 1 30 Cu. Yd. Container | B16: 1 | C16: =1*2 -> 2 | D16: 0 | I16: 0 | J16: 0 | K16: 0 | L16: 0
A17: 1 35 Cu. Yd. Container | B17: 1 | C17: 1 | D17: 0 | I17: 0 | J17: 0 | K17: 0 | L17: 0
A18: 1 40 Cu. Yd. Container | B18: =7+1 -> 8 | C18: =7*2+1*(52/12) -> 18.333333 | D18: 0 | I18: 0 | J18: 0 | K18: 0 | L18: 0
A19: Noncompacted Permanent Vactor/Street Sweeping Wastes Service
A20: 1 12 Cu. Yd. Container | B20: 1 | C20: 25.9 | D20: 0 | I20: 0 | J20: 0 | K20: 0 | L20: 0
A21: Compacted Permanent Service
A22: 1 10 Cu. Yd. Container | B22: 1 | C22: =1*22 -> 22 | D22: 0 | I22: 0 | J22: 0 | K22: 0 | L22: 0
A23: 1 15 Cu. Yd. Container | B23: =2+3+1 -> 6 | C23: =2*(52/48)+3*(26/12)+1*(52/12) -> 13 | D23: 0 | I23: 0 | J23: 0 | K23: 0 | L23: 0
A24: 1 20 Cu. Yd. Container | B24: =11+2+5+13 -> 31 | C24: =11*2+2*(52/48)+5*(26/12)+13*(52/12) -> 91.333333 | D24: 0 | I24: 0 | J24: 0 | K24: 0 | L24: 0
A25: 1 25 Cu. Yd. Container | B25: =8+8+1+3+11+3+1 -> 35 | C25: =8*2+8*(26/12)+1*(52/36)+3*(52/48)+11*(52/12)+3*2*(52/12)+1*3*(52/12) -> 124.69444 | D25: 0 | I25: 0 | J25: 0 | K25: 0 | L25: 0
A26: 1 30 Cu. Yd. Container | B26: =16+1+4+6+7+1 -> 35 | C26: =16*2+1*(52/36)+4*(52/48)+6*(26/12)+7*(52/12)+1*6*(52/12) -> 107.11111 | D26: 0 | I26: 0 | J26: 0 | K26: 0 | L26: 0
A27: 1 40 Cu. Yd. Container | B27: =5+1 -> 6 | C27: =5*2+1*3*(52/12) -> 23 | D27: 0 | I27: 0 | J27: 0 | K27: 0 | L27: 0
A28: Permanent Drop-box Rental | C28: # Containers | D28: Monthly Rental Fee
A29: 1 10 Cu. Yd. Container | B29: 1 | C29: 1 | D29: 0
A30: 1 12 Cu. Yd. Container | B30: 5 | C30: 21 | D30: 0
A31: 1 15 Cu. Yd. Container | B31: 3 | C31: 3 | D31: 0
A32: 1 20 Cu. Yd. Container | B32: 3 | C32: 3 | D32: 0
A33: 1 25 Cu. Yd. Container | B33: 32 | C33: 32 | D33: 0
A34: 1 30 Cu. Yd. Container | B34: 1 | C34: 1 | D34: 0
A35: 1 35 Cu. Yd. Container | B35: 1 | C35: 1 | D35: 0
A36: 1 40 Cu. Yd. Container | B36: 8 | C36: 8 | D36: 0
A37: Subtotal: Annual Revenue for Basic Services | D37: =12*SUMPRODUCT($C$11:$C$27*D11:D27)+12*SUMPRODUCT(C29:C36*D29:D36) -> 0 | E37: Annual Revenue Increase/(Decrease) | I37: =12*SUMPRODUCT($C$11:$C$27*I11:I27) -> 0 | J37: =12*SUMPRODUCT($C$11:$C$27*J11:J27) -> 0 | K37: =12*SUMPRODUCT($C$11:$C$27*K11:K27) -> 0 | L37: =12*SUMPRODUCT($C$11:$C$27*L11:L27) -> 0
F39: WUTC Fee
F40: for Other
A41: Organics Drop-box Haul | C41: Hauls/Month | D41: Fee/Haul | F41: Services
A42: 1 10 Cu. Yd. Non-compacted Container | B42: 1 | C42: 1 | D42: 0
...

Sheet Commercial
A1: Commercial/Multifamily Worksheet
A3: CITY OF BELLEVUE
A4: Garbage and Organics Service Fees
A5: yellow is a contractor modifiable field | K5: Service Fee Increase/(Decrease) for Service Enhancements
L6: Multifamily On-Call | M6: Organics | N6: In-City Customer
F7: Proposed | K7: Unlimited | L7: Small Appliance, | M7: Recycling - | N7: Service
D8: Proposed | E8: Proposed | F8: Total | K8: Commercial | L8: Electronics, | M8: 1 96 Gallon | N8: Opportunities
A9: COMMERCIAL/MULTIFAMILY SERVICES | D9: Disposal | E9: Collection | F9: Service | K9: Recycling | L9: & Textiles | M9: Cart/Week | N9: per Contract
A10: Monthly Rates | B10: # of Customers | C10: # of Containers | D10: Fee | E10: Fee | F10: Fee | L10: Recycling | M10: Limit | N10: Section 3.3.2.1
A11: 1 32 Gal Can (first can) | B11: 26 | C11: 26 | D11: 0 | E11: 0 | F11: =ROUND(D11+E11,2) -> 0 | K11: 0 | L11: 0 | M11: 0 | N11: 0
A12: each additional can | B12: 29 | C12: 429 | D12: 0 | E12: 0 | F12: =ROUND(D12+E12,2) -> 0 | K12: 0 | L12: 0 | M12: 0 | N12: 0
A13: 1 32 Gal Cart (first cart) | B13: 14 | C13: 14 | D13: 0 | E13: 0 | F13: =ROUND(D13+E13,2) -> 0 | K13: 0 | L13: 0 | M13: 0 | N13: 0
A14: each additional cart | B14: 14 | C14: 166 | D14: 0 | E14: 0 | F14: =ROUND(D14+E14,2) -> 0 | K14: 0 | L14: 0 | M14: 0 | N14: 0
A15: 1 45 Gal Cart (first cart) | B15: 1 | C15: 1 | D15: 0 | E15: 0 | F15: =ROUND(D15+E15,2) -> 0 | K15: 0 | L15: 0 | M15: 0 | N15: 0
A16: each additional cart | B16: 1 | C16: 1 | D16: 0 | E16: 0 | F16: =ROUND(D16+E16,2) -> 0 | K16: 0 | L16: 0 | M16: 0 | N16: 0
A17: 1 64 Gal Cart (first cart) | B17: 62 | C17: 62 | D17: 0 | E17: 0 | F17: =ROUND(D17+E17,2) -> 0 | K17: 0 | L17: 0 | M17: 0 | N17: 0
A18: each additional cart | B18: 62 | C18: 124 | D18: 0 | E18: 0 | F18: =ROUND(D18+E18,2) -> 0 | K18: 0 | L18: 0 | M18: 0 | N18: 0
A19: 1 96 Gal Cart (first cart) | B19: 248 | C19: 248 | D19: 0 | E19: 0 | F19: =ROUND(D19+E19,2) -> 0 | K19: 0 | L19: 0 | M19: 0 | N19: 0
A20: each additional cart | B20: 248 | C20: 261 | D20: 0 | E20: 0 | F20: =ROUND(D20+E20,2) -> 0 | K20: 0 | L20: 0 | M20: 0 | N20: 0
C21: Extras/Month | F21: Fee/Extra
A22: Extra 32 Gal can/bag or overweight (each/pickup) | B22: 0 | C22: 163 | D22: 0 | E22: 0 | F22: =ROUND(D22+E22,2) -> 0
A23: Extra Uncompacted Cu Yard or overweight (each/pickup) | B23: 0 | C23: 190 | D23: 0 | E23: 0 | F23: =ROUND(D23+E23,2) -> 0
A24: 1 Yard
A25: 1 yard (on call, per pickup) | B25: 6 | C25: 6 | D25: 0 | E25: 0 | F25: =ROUND(D25+E25,2) -> 0 | K25: 0 | L25: 0 | M25: 0 | N25: 0
A26: 1 pickup weekly (per container) | B26: 46 | C26: 46 | D26: 0 | E26: 0 | F26: =ROUND(D26+E26,2) -> 0 | K26: 0 | L26: 0 | M26: 0 | N26: 0
A27: 2 pickups weekly (per container) | B27: 1 | C27: 2 | D27: 0 | E27: 0 | F27: =ROUND(D27+E27,2) -> 0 | K27: 0 | L27: 0 | M27: 0 | N27: 0
A28: 3 pickups weekly (per container) | B28: 1 | C28: 1 | D28: 0 | E28: 0 | F28: =ROUND(D28+E28,2) -> 0 | K28: 0 | L28: 0 | M28: 0 | N28: 0
A29: 4 pickups weekly (per container) | B29: 1 | C29: 1 | D29: 0 | E29: 0 | F29: =ROUND(D29+E29,2) -> 0 | K29: 0 | L29: 0 | M29: 0 | N29: 0
A30: 5 pickups weekly (per container) | B30: 1 | C30: 1 | D30: 0 | E30: 0 | F30: =ROUND(D30+E30,2) -> 0 | K30: 0 | L30: 0 | M30: 0 | N30: 0
A31: 6 pickups weekly (per container) | B31: 1 | C31: 1 | D31: 0 | E31: 0 | F31: =ROUND(D31+E31,2) -> 0 | K31: 0 | L31: 0 | M31: 0 | N31: 0
A32: 1.25 Yard
A33: 1.25 yard (on call, per pickup) | B33: 5 | C33: 5 | D33: 0 | E33: 0 | F33: =ROUND(D33+E33,2) -> 0 | K33: 0 | L33: 0 | M33: 0 | N33: 0
A34: 1 pickup weekly (per container) | B34: 82 | C34: 85 | D34: 0 | E34: 0 | F34: =ROUND(D34+E34,2) -> 0 | K34: 0 | L34: 0 | M34: 0 | N34: 0
A35: 2 pickups weekly (per container) | B35: 7 | C35: 8 | D35: 0 | E35: 0 | F35: =ROUND(D35+E35,2) -> 0 | K35: 0 | L35: 0 | M35: 0 | N35: 0
A36: 3 pickups weekly (per container) | B36: 1 | C36: 1 | D36: 0 | E36: 0 | F36: =ROUND(D36+E36,2) -> 0 | K36: 0 | L36: 0 | M36: 0 | N36: 0
A37: 4 pickups weekly (per container) | B37: 1 | C37: 1 | D37: 0 | E37: 0 | F37: =ROUND(D37+E37,2) -> 0 | K37: 0 | L37: 0 | M37: 0 | N37: 0
A38: 5 pickups weekly (per container) | B38: 1 | C38: 1 | D38: 0 | E38: 0 | F38: =ROUND(D38+E38,2) -> 0 | K38: 0 | L38: 0 | M38: 0 | N38: 0
A39: 6 pickups weekly (per container) | B39: 1 | C39: 1 | D39: 0 | E39: 0 | F39: =ROUND(D39+E39,2) -> 0 | K39: 0 | L39: 0 | M39: 0 | N39: 0
A40: 2 Yard
A41: 2 yard (on call, per pickup) | B41: 7 | C41: 7 | D41: 0 | E41: 0 | F41: =ROUND(D41+E41,2) -> 0 | K41: 0 | L41: 0 | M41: 0 | N41: 0
...

Sheet SF Residential - COS
A1: Single-family Residential -- Cost-of-Service Rates Worksheet
A3: CITY OF BELLEVUE | B3: Single-family Cost-of-Service
A4: Garbage Service Fees
A5: yellow is a contractor modifiable field | K5: Service Fee Increase/(Decrease) for Service Enhancements
L6: Collect | M6: In-City Customer
F7: Proposed | K7: Saturday | L7: Additional | M7: Service
B8: Current | C8: Proposed | D8: Proposed | E8: Proposed | F8: Total | K8: Collection | L8: Recyclables | M8: Opportunities
A9: RESIDENTIAL SERVICES | B9: Container | C9: Container | D9: Disposal | E9: Collection | F9: Service | K9: for Friday | L9: Where | M9: per Contract
A10: Monthly Rates for Weekly Service, except where noted | B10: Count | C10: Count | D10: Fee | E10: Fee | F10: Fee | K10: Misses | L10: Feasible | M10: Section 3.3.2.1
A11: 1 10 Gallon Micro-Can | C11: 0 | D11: 0 | E11: 0 | F11: =ROUND(D11+E11,2) -> 0 | K11: 0 | L11: 0 | M11: 0
A12: 1 20 Gallon Cart | B12: 6046 | C12: 0 | D12: 0 | E12: 0 | F12: =ROUND(D12+E12,2) -> 0 | K12: 0 | L12: 0 | M12: 0
A13: 1 32 Gallon Cart | B13: =13361+471+184*2+6*3+1*4 -> 14222 | C13: =29176-SUM(C14:C16)-C11-C12 -> 29176 | D13: 0 | E13: 0 | F13: =ROUND(D13+E13,2) -> 0 | K13: 0 | L13: 0 | M13: 0
A14: 1 45 Gallon Cart | C14: 0 | D14: 0 | E14: 0 | F14: =ROUND(D14+E14,2) -> 0 | K14: 0 | L14: 0 | M14: 0
A15: 1 64 Gallon Cart | B15: 6424 | C15: 0 | D15: 0 | E15: 0 | F15: =ROUND(D15+E15,2) -> 0 | K15: 0 | L15: 0 | M15: 0
A16: 1 96 Gallon Cart | B16: 2484 | C16: 0 | D16: 0 | E16: 0 | F16: =ROUND(D16+E16,2) -> 0 | K16: 0 | L16: 0 | M16: 0
A17: Owner-used garbage can surcharge (per can per month) | B17: =471+2*184+6*3+1*4 -> 861 | C17: 861 | D17: - | E17: 0 | F17: =ROUND(D17+E17,2) -> 0
C18: Extras/Month | F18: Fee/Extra
A19: 1 32 gallon equivalent "extra" or overweight, per item | B19: 1778 | C19: 1778 | D19: 0 | E19: 0 | F19: =ROUND(D19+E19,2) -> 0
A20: Subtotal: Annual Revenue for Basic Services | F20: =12*SUMPRODUCT($C$11:$C$17*F11:F17)+12*C19*F19 -> 0 | G20: Annual Revenue Increase/(Decrease) | K20: =12*SUMPRODUCT($C$11:$C$17*K11:K17) -> 0 | L20: =12*SUMPRODUCT($C$11:$C$17*L11:L17) -> 0 | M20: =12*SUMPRODUCT($C$11:$C$17*M11:M17) -> 0
H22: WUTC Fee
H23: for Other
A24: Extra Organics Service: | C24: Items/Month | F24: Fee/Item | H24: Services
A25: Extra Can/Bag/Bundle >6 units per week, per unit | B25: =1248/12 -> 104 | C25: =1248/12 -> 104 | E25: 0 | F25: =ROUND(D25+E25,2) -> 0 | H25: 2.86
A26: Extra 96 Gallon Organics Cart rental, per month | B26: 1579 | C26: 1579 | E26: 0 | F26: =ROUND(D26+E26,2) -> 0 | H26: 1.6
A27: Recycling Only/Organics Only Weekly Services:
A28: Recycling Only | B28: 63 | C28: 63 | E28: 0 | F28: =ROUND(D28+E28,2) -> 0 | H28: 10.2
A29: Organics Only | B29: 87 | C29: 87 | D29: 0 | E29: 0 | F29: =ROUND(D29+E29,2) -> 0 | H29: 9.6
A30: Recycling & Organics Only | B30: 1 | C30: 1 | D30: 0 | E30: 0 | F30: =ROUND(D30+E30,2) -> 0
A31: Miscellaneous Fees per item:
A32: Return Trip | B32: =156/12 -> 13 | C32: =156/12 -> 13 | E32: 0 | F32: =ROUND(D32+E32,2) -> 0 | H32: 5.73
A33: Drive-in - monthly fee | B33: 21 | C33: 21 | E33: 0 | F33: =ROUND(D33+E33,2) -> 0 | H33: 5.25
A34: Carryout (each 25') - monthly fee | B34: 31 | C34: 31 | E34: 0 | F34: =ROUND(D34+E34,2) -> 0 | H34: 0.55
A35: Bear-Proof Cart Surcharge (per cart per month) | B35: 1 | C35: 1 | E35: 0 | F35: =ROUND(D35+E35,2) -> 0
A36: Pressure Washing (per yard) | B36: 1 | C36: 1 | E36: 0 | F36: =ROUND(D36+E36,2) -> 0 | H36: 2.1
A37: Steam Cleaning (per yard) | B37: 1 | C37: 1 | E37: 0 | F37: =ROUND(D37+E37,2) -> 0 | H37: 1.51
A38: Redelivery Fee (carts) | B38: =226/12 -> 18.833333 | C38: =226/12 -> 18.833333 | E38: 0 | F38: =ROUND(D38+E38,2) -> 0 | H38: 16.7
A39: Bulky Waste Collection:
A40: On Call - per item per pickup | B40: 1 | C40: 1 | E40: 0 | F40: =ROUND(D40+E40,2) -> 0
A41: Quarterly Bulky Waste Pickup - per item, four or fewer items | B41: 1 | C41: 1 | E41: 0 | F41: =ROUND(D41+E41,2) -> 0
A42: Subtotal: Annual Revenue for Other Services | F42: =12*SUMPRODUCT(C25:C41*F25:F41) -> 0
...

Sheet SF Residential - Linear
A1: Single-family Residential -- Linear Rates Worksheet
A3: CITY OF BELLEVUE | B3: Single-family Linear
A4: Garbage Service Fees
A5: yellow is a contractor modifiable field | K5: Service Fee Increase/(Decrease) for Service Enhancements
L6: Collect | M6: In-City Customer
F7: Proposed | K7: Saturday | L7: Additional | M7: Service
B8: Current | C8: Proposed | D8: Proposed | E8: Proposed | F8: Total | K8: Collection | L8: Recyclables | M8: Opportunities
A9: RESIDENTIAL SERVICES | B9: Container | C9: Container | D9: Disposal | E9: Collection | F9: Service | K9: for Friday | L9: Where | M9: per Contract
A10: Monthly Rates for Weekly Service, except where noted | B10: Count | C10: Count | D10: Fee | E10: Fee | F10: Fee | K10: Misses | L10: Feasible | M10: Section 3.3.2.1
A11: 1 10 Gallon Micro-Can | C11: 0 | D11: =(10/32)*D13 -> 0 | E11: =(10/32)*E13 -> 0 | F11: =ROUND(D11+E11,2) -> 0 | K11: 0 | L11: 0 | M11: 0
A12: 1 20 Gallon Cart | B12: 6046 | C12: 0 | D12: =(20/32)*D13 -> 0 | E12: =(20/32)*E13 -> 0 | F12: =ROUND(D12+E12,2) -> 0 | K12: 0 | L12: 0 | M12: 0
A13: 1 32 Gallon Cart | B13: =13361+471+184*2+6*3+1*4 -> 14222 | C13: =29176-SUM(C14:C16)-C11-C12 -> 29176 | D13: 0 | E13: 0 | F13: =ROUND(D13+E13,2) -> 0 | K13: 0 | L13: 0 | M13: 0
A14: 1 45 Gallon Cart | C14: 0 | D14: =(45/32)*D13 -> 0 | E14: =(45/32)*E13 -> 0 | F14: =ROUND(D14+E14,2) -> 0 | K14: 0 | L14: 0 | M14: 0
A15: 1 64 Gallon Cart | B15: 6424 | C15: 0 | D15: =(64/32)*D13 -> 0 | E15: =(64/32)*E13 -> 0 | F15: =ROUND(D15+E15,2) -> 0 | K15: 0 | L15: 0 | M15: 0
A16: 1 96 Gallon Cart | B16: 2484 | C16: 0 | D16: =(96/32)*D13 -> 0 | E16: =(96/32)*E13 -> 0 | F16: =ROUND(D16+E16,2) -> 0 | K16: 0 | L16: 0 | M16: 0
A17: Owner-used garbage can surcharge (per can per month) | B17: =471+2*184+6*3+1*4 -> 861 | C17: 861 | D17: - | E17: 0 | F17: =ROUND(D17+E17,2) -> 0
C18: Extras/Month | F18: Fee/Extra
A19: 1 32 gallon equivalent "extra" or overweight, per item | B19: 1778 | C19: 1778 | D19: =D13/(52/12) -> 0 | E19: 0 | F19: =ROUND(D19+E19,2) -> 0
A20: Subtotal: Annual Revenue for Basic Services | F20: =12*SUMPRODUCT($C$11:$C$17*F11:F17)+12*C19*F19 -> 0 | G20: Annual Revenue Increase/(Decrease) | K20: =12*SUMPRODUCT($C$11:$C$17*K11:K17) -> 0 | L20: =12*SUMPRODUCT($C$11:$C$17*L11:L17) -> 0 | M20: =12*SUMPRODUCT($C$11:$C$17*M11:M17) -> 0
H22: WUTC Fee
H23: for Other
A24: Extra Organics Service: | C24: Items/Month | F24: Fee/Item | H24: Services
A25: Extra Can/Bag/Bundle >6 units per week, per unit | B25: =1248/12 -> 104 | C25: =1248/12 -> 104 | E25: 0 | F25: =ROUND(D25+E25,2) -> 0 | H25: 2.86
A26: Extra 96 Gallon Organics Cart rental, per month | B26: 1579 | C26: 1579 | E26: 0 | F26: =ROUND(D26+E26,2) -> 0 | H26: 1.6
A27: Recycling Only/Organics Only Weekly Services:
A28: Recycling Only | B28: 63 | C28: 63 | E28: 0 | F28: =ROUND(D28+E28,2) -> 0 | H28: 10.2
A29: Organics Only | B29: 87 | C29: 87 | D29: 0 | E29: 0 | F29: =ROUND(D29+E29,2) -> 0 | H29: 9.6
A30: Recycling & Organics Only | B30: 1 | C30: 1 | D30: 0 | E30: 0 | F30: =ROUND(D30+E30,2) -> 0
A31: Miscellaneous Fees per item:
A32: Return Trip | B32: =156/12 -> 13 | C32: =156/12 -> 13 | E32: 0 | F32: =ROUND(D32+E32,2) -> 0 | H32: 5.73
A33: Drive-in - monthly fee | B33: 21 | C33: 21 | E33: 0 | F33: =ROUND(D33+E33,2) -> 0 | H33: 5.25
A34: Carryout (each 25') - monthly fee | B34: 31 | C34: 31 | E34: 0 | F34: =ROUND(D34+E34,2) -> 0 | H34: 0.55
A35: Bear-Proof Cart Surcharge (per cart per month) | B35: 1 | C35: 1 | E35: 0 | F35: =ROUND(D35+E35,2) -> 0
A36: Pressure Washing (per yard) | B36: 1 | C36: 1 | E36: 0 | F36: =ROUND(D36+E36,2) -> 0 | H36: 2.1
A37: Steam Cleaning (per yard) | B37: 1 | C37: 1 | E37: 0 | F37: =ROUND(D37+E37,2) -> 0 | H37: 1.51
A38: Redelivery Fee (carts) | B38: =226/12 -> 18.833333 | C38: =226/12 -> 18.833333 | E38: 0 | F38: =ROUND(D38+E38,2) -> 0 | H38: 16.7
A39: Bulky Waste Collection:
A40: On Call - per item per pickup | B40: 1 | C40: 1 | E40: 0 | F40: =ROUND(D40+E40,2) -> 0
A41: Quarterly Bulky Waste Pickup - per item, four or fewer items | B41: 1 | C41: 1 | E41: 0 | F41: =ROUND(D41+E41,2) -> 0
A42: Subtotal: Annual Revenue for Other Services | F42: =12*SUMPRODUCT(C25:C41*F25:F41) -> 0
...
