Workbook

Sheet Summary
A1: Community and Technical Colleges, Report of Fundable Operating Expenses, Fiscal Year (FY) 2012
A2: Summary of Expense divided Contact Hours
A3: Contact Hours for fall 2011 and spring and summer 2012
A4: Fund | B4: Total Expense by Discipline | D4: Contact Hours | E4: Expense | F4: Expense per Contact Hour
A5: 1 | B5: Agriculture | D5: =D36 -> 1622682 | E5: =E36+E67+IFERROR($E$105/$D$105*D5,0) -> 14698531 | F5: =IFERROR(E5/D5,"") -> 9.058171
A6: 2 | B6: Architecture and Precision Production Trades | D6: =D37 -> 4408564 | E6: =E37+E68+IFERROR($E$105/$D$105*D6,0) -> 41437241 | F6: =IFERROR(E6/D6,"") -> 9.3992604
A7: 3 | B7: Biology, Physical Sciences, and Science Technology | D7: =D38 -> 38841237 | E7: =E38+E69+IFERROR($E$105/$D$105*D7,0) -> 3.031945e+08 | F7: =IFERROR(E7/D7,"") -> 7.805995
A8: 4 | B8: Business Management, Marketing, and Administrative Services | D8: =D39 -> 21395229 | E8: =E39+E70+IFERROR($E$105/$D$105*D8,0) -> 1.6629155e+08 | F8: =IFERROR(E8/D8,"") -> 7.7723659
A9: 5 | B9: Career Pilot | D9: =D40 -> 198523 | E9: =E40+E71+IFERROR($E$105/$D$105*D9,0) -> 5811341.2 | F9: =IFERROR(E9/D9,"") -> 29.272886
A10: 6 | B10: Communications | D10: =D41 -> 3948618 | E10: =E41+E72+IFERROR($E$105/$D$105*D10,0) -> 34998289 | F10: =IFERROR(E10/D10,"") -> 8.8634273
A11: 7 | B11: Computer and Information Sciences | D11: =D42 -> 12167284 | E11: =E42+E73+IFERROR($E$105/$D$105*D11,0) -> 1.1539888e+08 | F11: =IFERROR(E11/D11,"") -> 9.4843582
A12: 8 | B12: Construction Trades | D12: =D43 -> 1877680 | E12: =E43+E74+IFERROR($E$105/$D$105*D12,0) -> 17801770 | F12: =IFERROR(E12/D12,"") -> 9.4807263
A13: 9 | B13: Consumer and Homemaking Education | D13: =D44 -> 10305568 | E13: =E44+E75+IFERROR($E$105/$D$105*D13,0) -> 85748387 | F13: =IFERROR(E13/D13,"") -> 8.3205882
A14: 10 | B14: Engineering | D14: =D45 -> 275947 | E14: =E45+E76+IFERROR($E$105/$D$105*D14,0) -> 4317775.5 | F14: =IFERROR(E14/D14,"") -> 15.647119
A15: 11 | B15: Engineering Related | D15: =D46 -> 8000857 | E15: =E46+E77+IFERROR($E$105/$D$105*D15,0) -> 70430093 | F15: =IFERROR(E15/D15,"") -> 8.8028186
A16: 12 | B16: English Language, Lit, Philosophy, Humanities, & Interdisciplinary | D16: =D47 -> 34525850 | E16: =E47+E78+IFERROR($E$105/$D$105*D16,0) -> 2.9311839e+08 | F16: =IFERROR(E16/D16,"") -> 8.4898241
... A32: 29 | B32: Developmental Education - Reading/Writing | D32: =D63 -> 16713968 | E32: =E63+E94+IFERROR($E$105/$D$105*D32,0) -> 1.2580564e+08 | F32: =IFERROR(E32/D32,"") -> 7.5269762
B33: Total | D33: =SUM(D5:D32) -> 320121176 | E33: =SUM(E5:E32) -> 2696113474 | F33: =IFERROR(E33/D33,"") -> 8.4221653
A35: Fund | B35: Departmental Operating Expense by Discipline | D35: Contact Hours | E35: Expense | F35: Expense per Contact Hour
A36: 1 | B36: Agriculture | D36: =SUM('1:57'!D36) -> 1622682 | E36: =SUM('1:57'!E36) -> 3193312 | F36: =IFERROR(E36/D36,"") -> 1.9679222
A37: 2 | B37: Architecture and Precision Production Trades | D37: =SUM('1:57'!D37) -> 4408564 | E37: =SUM('1:57'!E37) -> 8584755 | F37: =IFERROR(E37/D37,"") -> 1.9472905
A38: 3 | B38: Biology, Physical Sciences, and Science Technology | D38: =SUM('1:57'!D38) -> 38841237 | E38: =SUM('1:57'!E38) -> 43857452 | F38: =IFERROR(E38/D38,"") -> 1.1291466
A39: 4 | B39: Business Management, Marketing, and Administrative Services | D39: =SUM('1:57'!D39) -> 21395229 | E39: =SUM('1:57'!E39) -> 24714644 | F39: =IFERROR(E39/D39,"") -> 1.1551474
A40: 5 | B40: Career Pilot | D40: =SUM('1:57'!D40) -> 198523 | E40: =SUM('1:57'!E40) -> 3353138 | F40: =IFERROR(E40/D40,"") -> 16.890426
A41: 6 | B41: Communications | D41: =SUM('1:57'!D41) -> 3948618 | E41: =SUM('1:57'!E41) -> 9450129 | F41: =IFERROR(E41/D41,"") -> 2.3932751
A42: 7 | B42: Computer and Information Sciences | D42: =SUM('1:57'!D42) -> 12167284 | E42: =SUM('1:57'!E42) -> 21169024 | F42: =IFERROR(E42/D42,"") -> 1.7398315
A43: 8 | B43: Construction Trades | D43: =SUM('1:57'!D43) -> 1877680 | E43: =SUM('1:57'!E43) -> 4109900 | F43: =IFERROR(E43/D43,"") -> 2.1888181
A44: 9 | B44: Consumer and Homemaking Education | D44: =SUM('1:57'!D44) -> 10305568 | E44: =SUM('1:57'!E44) -> 16817152 | F44: =IFERROR(E44/D44,"") -> 1.6318511
A45: 10 | B45: Engineering | D45: =SUM('1:57'!D45) -> 275947 | E45: =SUM('1:57'!E45) -> 855492 | F45: =IFERROR(E45/D45,"") -> 3.100204
A46: 11 | B46: Engineering Related | D46: =SUM('1:57'!D46) -> 8000857 | E46: =SUM('1:57'!E46) -> 14710708 | F46: =IFERROR(E46/D46,"") -> 1.8386415
A47: 12 | B47: English Language, Lit, Philosophy, Humanities, & Interdisciplinary | D47: =SUM('1:57'!D47) -> 34525850 | E47: =SUM('1:57'!E47) -> 38273619 | F47: =IFERROR(E47/D47,"") -> 1.1085497
... A63: 29 | B63: Developmental Education - Reading/Writing | D63: =SUM('1:57'!D63) -> 16713968 | E63: =SUM('1:57'!E63) -> 12942992 | F63: =IFERROR(E63/D63,"") -> 0.77438176
C64: Total | D64: =SUM(D36:D63) -> 320121176 | E64: =SUM(E36:E63) -> 409822393 | F64: =IFERROR(E64/D64,"") -> 1.2802102
A66: Fund | B66: Faculty Salaries by Discipline | D66: Contact Hours | E66: Expense | F66: Expense per Contact Hour
A67: 1 | B67: Agriculture | D67: =D36 -> 1622682 | E67: =SUM('1:57'!E67) -> 5259237 | F67: =IFERROR(E67/D67,"") -> 3.2410768
A68: 2 | B68: Architecture and Precision Production Trades | D68: =D37 -> 4408564 | E68: =SUM('1:57'!E68) -> 15883165 | F68: =IFERROR(E68/D68,"") -> 3.6027979
A69: 3 | B69: Biology, Physical Sciences, and Science Technology | D69: =D38 -> 38841237 | E69: =SUM('1:57'!E69) -> 109830449 | F69: =IFERROR(E69/D69,"") -> 2.8276764
A70: 4 | B70: Business Management, Marketing, and Administrative Services | D70: =D39 -> 21395229 | E70: =SUM('1:57'!E70) -> 59222988 | F70: =IFERROR(E70/D70,"") -> 2.7680465
A71: 5 | B71: Career Pilot | D71: =D40 -> 198523 | E71: =SUM('1:57'!E71) -> 1694054 | F71: =IFERROR(E71/D71,"") -> 8.5332883
A72: 6 | B72: Communications | D72: =D41 -> 3948618 | E72: =SUM('1:57'!E72) -> 10349250 | F72: =IFERROR(E72/D72,"") -> 2.6209803
...

Sheet Rate History
A1: =Summary!A1 -> Community and Technical Colleges, Report of Fundable Operating Expenses, Fiscal Year (FY) 2012
A2: Rate History | R2: Year over Year Change
A3: Fund | B3: Expense per Contact Hour by Discipline | C3: 2012 | D3: 2011 | E3: 2010 | F3: 2009 | G3: 2008 | H3: 2007 | I3: 2006 | J3: 2005 | K3: 2004 | L3: 2003 | M3: 2002 | N3: 2001 | O3: 2000 | P3: 1999 | R3: 2012 | S3: 2011 | T3: 2010 | U3: 2009 | V3: 2008 | W3: 2007 | X3: 2006 | Y3: 2005 | Z3: 2004 | AA3: 2003 | AB3: 2002 | AC3: 2001 | AD3: 2000
A4: 1 | B4: Agriculture | C4: =Summary!F5 -> 9.058171 | D4: 8.6593499 | E4: =[1]Summary!F5 -> 8.3546442 | F4: 8.9459924 | G4: 7.7 | H4: 7.37 | J4: 7.25 | K4: 9.82 | L4: 7.18 | M4: 7.58 | N4: 7 | O4: 6.67 | P4: 6.81 | R4: =IFERROR(C4/D4-1,"") -> 0.046056706 | S4: =IFERROR(D4/E4-1,"") -> 0.036471411 | T4: =IFERROR(E4/F4-1,"") -> -0.066102019 | U4: =IFERROR(F4/G4-1,"") -> 0.16181719 | V4: =IFERROR(G4/H4-1,"") -> 0.044776119 | W4: =IFERROR(H4/I4-1,"") | X4: =IFERROR(I4/J4-1,"") -> -1 | Y4: =IFERROR(J4/K4-1,"") -> -0.26171079 | ... AD4: =IFERROR(O4/P4-1,"") -> -0.020558003
A5: 2 | B5: Architecture and Precision Production Trades | C5: =Summary!F6 -> 9.3992604 | D5: 9.1845421 | E5: =[1]Summary!F6 -> 9.1518481 | F5: 9.8950421 | G5: 8.88 | H5: 10.29 | J5: 8.82 | K5: 11.31 | L5: 7.31 | M5: 7.27 | N5: 7.56 | O5: 6.83 | P5: 6.64 | R5: =IFERROR(C5/D5-1,"") -> 0.023378221 | S5: =IFERROR(D5/E5-1,"") -> 0.0035723939 | T5: =IFERROR(E5/F5-1,"") -> -0.075107712 | U5: =IFERROR(F5/G5-1,"") -> 0.11430654 | V5: =IFERROR(G5/H5-1,"") -> -0.13702624 | W5: =IFERROR(H5/I5-1,"") | X5: =IFERROR(I5/J5-1,"") -> -1 | Y5: =IFERROR(J5/K5-1,"") -> -0.22015915 | ... AD5: =IFERROR(O5/P5-1,"") -> 0.028614458
A6: 3 | B6: Biology, Physical Sciences, and Science Technology | C6: =Summary!F7 -> 7.805995 | D6: 7.4925174 | E6: =[1]Summary!F7 -> 7.4246458 | F6: 7.7869597 | G6: 6.85 | H6: 6.65 | J6: 6.19 | K6: 7.98 | L6: 5.86 | M6: 6.04 | N6: 5.9 | O6: 5.69 | P6: 5.51 | R6: =IFERROR(C6/D6-1,"") -> 0.041838759 | S6: =IFERROR(D6/E6-1,"") -> 0.0091413881 | T6: =IFERROR(E6/F6-1,"") -> -0.046528286 | U6: =IFERROR(F6/G6-1,"") -> 0.13678244 | V6: =IFERROR(G6/H6-1,"") -> 0.030075188 | W6: =IFERROR(H6/I6-1,"") | X6: =IFERROR(I6/J6-1,"") -> -1 | Y6: =IFERROR(J6/K6-1,"") -> -0.22431078 | ... AD6: =IFERROR(O6/P6-1,"") -> 0.032667877
A7: 4 | B7: Business Management, Marketing, and Administrative Services | C7: =Summary!F8 -> 7.7723659 | D7: 7.45609 | E7: =[1]Summary!F8 -> 7.5459726 | F7: 7.9514488 | G7: 7.11 | H7: 6.97 | J7: 6.58 | K7: 8.86 | L7: 6.69 | M7: 6.46 | N7: 6.07 | O7: 6.13 | P7: 6.22 | R7: =IFERROR(C7/D7-1,"") -> 0.042418463 | S7: =IFERROR(D7/E7-1,"") -> -0.011911328 | T7: =IFERROR(E7/F7-1,"") -> -0.050994005 | U7: =IFERROR(F7/G7-1,"") -> 0.11834723 | V7: =IFERROR(G7/H7-1,"") -> 0.020086083 | W7: =IFERROR(H7/I7-1,"") | X7: =IFERROR(I7/J7-1,"") -> -1 | Y7: =IFERROR(J7/K7-1,"") -> -0.25733634 | ... AD7: =IFERROR(O7/P7-1,"") -> -0.014469453
A8: 5 | B8: Career Pilot | C8: =Summary!F9 -> 29.272886 | D8: 32.970588 | E8: =[1]Summary!F9 -> 31.732203 | F8: 35.064016 | G8: 33.87 | H8: 30.76 | J8: 23.45 | K8: 25.28 | L8: 13.77 | M8: 11.03 | N8: 16.04 | O8: 19.42 | P8: 18.69 | R8: =IFERROR(C8/D8-1,"") -> -0.11215153 | S8: =IFERROR(D8/E8-1,"") -> 0.039026116 | T8: =IFERROR(E8/F8-1,"") -> -0.095020844 | U8: =IFERROR(F8/G8-1,"") -> 0.035252899 | V8: =IFERROR(G8/H8-1,"") -> 0.10110533 | W8: =IFERROR(H8/I8-1,"") | X8: =IFERROR(I8/J8-1,"") -> -1 | Y8: =IFERROR(J8/K8-1,"") -> -0.072389241 | ... AD8: =IFERROR(O8/P8-1,"") -> 0.03905832
A9: 6 | B9: Communications | C9: =Summary!F10 -> 8.8634273 | D9: 8.8221233 | E9: =[1]Summary!F10 -> 8.5415949 | F9: 8.913555 | G9: 7.65 | H9: 7.3 | J9: 7.3 | K9: 10.01 | L9: 7.21 | M9: 7.26 | N9: 6.99 | O9: 9.21 | P9: 8.21 | R9: =IFERROR(C9/D9-1,"") -> 0.0046818681 | S9: =IFERROR(D9/E9-1,"") -> 0.032842631 | T9: =IFERROR(E9/F9-1,"") -> -0.041729716 | U9: =IFERROR(F9/G9-1,"") -> 0.16517059 | V9: =IFERROR(G9/H9-1,"") -> 0.047945205 | W9: =IFERROR(H9/I9-1,"") | X9: =IFERROR(I9/J9-1,"") -> -1 | Y9: =IFERROR(J9/K9-1,"") -> -0.27072927 | ... AD9: =IFERROR(O9/P9-1,"") -> 0.12180268
A10: 7 | B10: Computer and Information Sciences | C10: =Summary!F11 -> 9.4843582 | D10: 9.2148507 | E10: =[1]Summary!F11 -> 9.0091907 | F10: 9.8773789 | G10: 8.52 | H10: 8.44 | J10: 7.57 | K10: 9.93 | L10: 6.94 | M10: 6.92 | N10: 6.69 | O10: 6.32 | P10: 5.44 | R10: =IFERROR(C10/D10-1,"") -> 0.029247076 | S10: =IFERROR(D10/E10-1,"") -> 0.022827808 | T10: =IFERROR(E10/F10-1,"") -> -0.087896624 | U10: =IFERROR(F10/G10-1,"") -> 0.15931678 | V10: =IFERROR(G10/H10-1,"") -> 0.009478673 | W10: =IFERROR(H10/I10-1,"") | X10: =IFERROR(I10/J10-1,"") -> -1 | Y10: =IFERROR(J10/K10-1,"") -> -0.23766365 | ... AD10: =IFERROR(O10/P10-1,"") -> 0.16176471
A11: 8 | B11: Construction Trades | C11: =Summary!F12 -> 9.4807263 | D11: 9.4265511 | E11: =[1]Summary!F12 -> 9.1499254 | F11: 10.673804 | G11: 8.03 | H11: 7.77 | J11: 8.2 | K11: 10.92 | L11: 7.36 | M11: 6.75 | N11: 6.12 | O11: 6.42 | P11: 5.99 | R11: =IFERROR(C11/D11-1,"") -> 0.0057470876 | S11: =IFERROR(D11/E11-1,"") -> 0.030232561 | T11: =IFERROR(E11/F11-1,"") -> -0.14276812 | U11: =IFERROR(F11/G11-1,"") -> 0.32924089 | V11: =IFERROR(G11/H11-1,"") -> 0.033462033 | W11: =IFERROR(H11/I11-1,"") | X11: =IFERROR(I11/J11-1,"") -> -1 | Y11: =IFERROR(J11/K11-1,"") -> -0.24908425 | ... AD11: =IFERROR(O11/P11-1,"") -> 0.071786311
A12: 9 | B12: Consumer and Homemaking Education | C12: =Summary!F13 -> 8.3205882 | D12: 7.5205661 | E12: =[1]Summary!F13 -> 7.5340118 | F12: 7.7785582 | G12: 6.75 | H12: 6.49 | J12: 6.14 | K12: 8.08 | L12: 5.49 | M12: 5.51 | N12: 5.52 | O12: 5.14 | P12: 5.35 | R12: =IFERROR(C12/D12-1,"") -> 0.1063779 | S12: =IFERROR(D12/E12-1,"") -> -0.001784662 | T12: =IFERROR(E12/F12-1,"") -> -0.03143852 | U12: =IFERROR(F12/G12-1,"") -> 0.15237899 | V12: =IFERROR(G12/H12-1,"") -> 0.040061633 | W12: =IFERROR(H12/I12-1,"") | X12: =IFERROR(I12/J12-1,"") -> -1 | Y12: =IFERROR(J12/K12-1,"") -> -0.24009901 | ... AD12: =IFERROR(O12/P12-1,"") -> -0.039252336
A13: 10 | B13: Engineering | C13: =Summary!F14 -> 15.647119 | D13: 14.989516 | E13: =[1]Summary!F14 -> 10.569021 | F13: 11.277206 | G13: 7.86 | H13: 7.53 | J13: 10.3 | K13: 11.38 | L13: 8.92 | M13: 8.54 | N13: 11.49 | O13: 9.83 | P13: 7.64 | R13: =IFERROR(C13/D13-1,"") -> 0.043870843 | S13: =IFERROR(D13/E13-1,"") -> 0.41825015 | T13: =IFERROR(E13/F13-1,"") -> -0.062797855 | U13: =IFERROR(F13/G13-1,"") -> 0.43475898 | V13: =IFERROR(G13/H13-1,"") -> 0.043824701 | W13: =IFERROR(H13/I13-1,"") | X13: =IFERROR(I13/J13-1,"") -> -1 | Y13: =IFERROR(J13/K13-1,"") -> -0.094903339 | ... AD13: =IFERROR(O13/P13-1,"") -> 0.28664921
A14: 11 | B14: Engineering Related | C14: =Summary!F15 -> 8.8028186 | D14: 8.2751104 | E14: =[1]Summary!F15 -> 8.1538555 | F14: 8.4264374 | G14: 7.41 | H14: 7.09 | J14: 6.82 | K14: 9.52 | L14: 7.23 | M14: 6.89 | N14: 6.58 | O14: 6.71 | P14: 6.42 | R14: =IFERROR(C14/D14-1,"") -> 0.063770529 | S14: =IFERROR(D14/E14-1,"") -> 0.014870862 | T14: =IFERROR(E14/F14-1,"") -> -0.032348416 | U14: =IFERROR(F14/G14-1,"") -> 0.13717104 | V14: =IFERROR(G14/H14-1,"") -> 0.045133992 | W14: =IFERROR(H14/I14-1,"") | X14: =IFERROR(I14/J14-1,"") -> -1 | Y14: =IFERROR(J14/K14-1,"") -> -0.28361345 | ... AD14: =IFERROR(O14/P14-1,"") -> 0.04517134
A15: 12 | B15: English Language, Lit, Philosophy, Humanities, & Interdisciplinary | C15: =Summary!F16 -> 8.4898241 | D15: 8.1700753 | E15: =[1]Summary!F16 -> 7.8328441 | F15: 8.2593827 | G15: 7.31 | H15: 7.08 | J15: 6.48 | K15: 8.33 | L15: 5.83 | M15: 5.94 | N15: 5.75 | O15: 5.68 | P15: 5.26 | R15: =IFERROR(C15/D15-1,"") -> 0.039136571 | S15: =IFERROR(D15/E15-1,"") -> 0.043053489 | T15: =IFERROR(E15/F15-1,"") -> -0.051642922 | U15: =IFERROR(F15/G15-1,"") -> 0.12987452 | V15: =IFERROR(G15/H15-1,"") -> 0.032485876 | W15: =IFERROR(H15/I15-1,"") | X15: =IFERROR(I15/J15-1,"") -> -1 | Y15: =IFERROR(J15/K15-1,"") -> -0.22208884 | ... AD15: =IFERROR(O15/P15-1,"") -> 0.079847909
... A31: 29 | B31: Developmental Education - Reading/Writing | C31: =Summary!F32 -> 7.5269762 | D31: 7.0255507 | E31: =[1]Summary!F32 -> 0 | F31: 0 | G31: 0 | H31: 0 | J31: 0 | K31: 0 | L31: 0 | M31: 0 | N31: 0 | O31: 0 | P31: 0 | R31: =IFERROR(C31/D31-1,"") -> 0.071371699 | S31: =IFERROR(D31/E31-1,"") | T31: =IFERROR(E31/F31-1,"") | U31: =IFERROR(F31/G31-1,"") | V31: =IFERROR(G31/H31-1,"") | W31: =IFERROR(H31/I31-1,"") | X31: =IFERROR(I31/J31-1,"") | Y31: =IFERROR(J31/K31-1,"") | ... AD31: =IFERROR(O31/P31-1,"")
B32: Average | C32: =AVERAGE(C4:C31) -> 10.458596 | D32: =AVERAGE(D4:D31) -> 10.221252 | E32: =AVERAGE(E4:E31) -> 9.374184 | F32: =AVERAGE(F4:F31) -> 9.871227 | G32: =AVERAGE(G4:G31) -> 8.67 | H32: =AVERAGE(H4:H31) -> 8.4635714 | J32: =AVERAGE(J4:J31) -> 7.7992857 | K32: =AVERAGE(K4:K31) -> 9.7525 | L32: =AVERAGE(L4:L31) -> 6.9428571 | M32: =AVERAGE(M4:M31) -> 7.0071429 | N32: =AVERAGE(N4:N31) -> 7.0107143 | O32: =AVERAGE(O4:O31) -> 7.0171429 | P32: =AVERAGE(P4:P31) -> 6.5617857 | R32: =IFERROR(C32/D32-1,"") -> 0.023220596 | S32: =IFERROR(D32/E32-1,"") -> 0.090361818 | T32: =IFERROR(E32/F32-1,"") -> -0.050352708 | U32: =IFERROR(F32/G32-1,"") -> 0.13854982 | V32: =IFERROR(G32/H32-1,"") -> 0.024390244 | W32: =IFERROR(H32/I32-1,"") | X32: =IFERROR(I32/J32-1,"") -> -1 | Y32: =IFERROR(J32/K32-1,"") -> -0.20027832 | ... AD32: =IFERROR(O32/P32-1,"") -> 0.069395308
B33: Median | C33: =MEDIAN(C4:C31) -> 9.2287157 | D33: =MEDIAN(D4:D31) -> 8.8781082 | E33: =MEDIAN(E4:E31) -> 8.8678181 | F33: =MEDIAN(F4:F31) -> 9.3311851 | G33: =MEDIAN(G4:G31) -> 7.78 | H33: =MEDIAN(H4:H31) -> 7.525 | J33: =MEDIAN(J4:J31) -> 7.345 | K33: =MEDIAN(K4:K31) -> 9.615 | L33: =MEDIAN(L4:L31) -> 6.995 | M33: =MEDIAN(M4:M31) -> 6.905 | N33: =MEDIAN(N4:N31) -> 6.69 | O33: =MEDIAN(O4:O31) -> 6.69 | P33: =MEDIAN(P4:P31) -> 6.32 | R33: =IFERROR(C33/D33-1,"") -> 0.039491244 | S33: =IFERROR(D33/E33-1,"") -> 0.0011603792 | T33: =IFERROR(E33/F33-1,"") -> -0.049657886 | U33: =IFERROR(F33/G33-1,"") -> 0.19938111 | V33: =IFERROR(G33/H33-1,"") -> 0.033887043 | W33: =IFERROR(H33/I33-1,"") | X33: =IFERROR(I33/J33-1,"") -> -1 | Y33: =IFERROR(J33/K33-1,"") -> -0.23608944 | ... AD33: =IFERROR(O33/P33-1,"") -> 0.058544304
B34: Standard Deviation | C34: =STDEV(C4:C31) -> 4.5646175 | D34: =STDEV(D4:D31) -> 5.1894911 | E34: =STDEV(E4:E31) -> 5.450075 | F34: =STDEV(F4:F31) -> 5.9203334 | G34: =STDEV(G4:G31) -> 5.7536855 | H34: =STDEV(H4:H31) -> 5.2587227 | J34: =STDEV(J4:J31) -> 4.1137528 | K34: =STDEV(K4:K31) -> 4.4105653 | L34: =STDEV(L4:L31) -> 2.7509808 | M34: =STDEV(M4:M31) -> 2.6772026 | N34: =STDEV(N4:N31) -> 3.0868058 | O34: =STDEV(O4:O31) -> 3.4645516 | P34: =STDEV(P4:P31) -> 3.2525364 | R34: =IFERROR(C34/D34-1,"") -> -0.12041134 | S34: =IFERROR(D34/E34-1,"") -> -0.047812889 | T34: =IFERROR(E34/F34-1,"") -> -0.079431073 | U34: =IFERROR(F34/G34-1,"") -> 0.028963686 | V34: =IFERROR(G34/H34-1,"") -> 0.094122236 | W34: =IFERROR(H34/I34-1,"") | X34: =IFERROR(I34/J34-1,"") -> -1 | Y34: =IFERROR(J34/K34-1,"") -> -0.067295782 | ... AD34: =IFERROR(O34/P34-1,"") -> 0.065184562

Sheet FTSE Summary
A1: =Summary!A1 -> Community and Technical Colleges, Report of Fundable Operating Expenses, Fiscal Year (FY) 2012
A2: Average Total Expenditure per Full-Time Student Equivalent (FTSE)
A3: Institution | B3: Annual State Funded Semester Credit Hours | C3: Total FTSE | D3: Total Expenditure | E3: Average Expenditure per FTSE
A4: Alamo | B4: 1152210 | C4: =B4/30 -> 38407 | D4: ='1'!$E$33 -> 209097769 | E4: =IFERROR(D4/C4,"") -> 5444.262
A5: Alvin | B5: 102531 | C5: =B5/30 -> 3417.7 | D5: ='2'!$E$33 -> 23163486 | E5: =IFERROR(D5/C5,"") -> 6777.5071
A6: Amarillo | B6: 204401 | C6: =B6/30 -> 6813.3667 | D6: ='3'!$E$33 -> 42811410 | E6: =IFERROR(D6/C6,"") -> 6283.4443
A7: Angelina | B7: 110577 | C7: =B7/30 -> 3685.9 | D7: ='4'!$E$33 -> 16986394 | E7: =IFERROR(D7/C7,"") -> 4608.4793
A8: Austin | B8: 807288 | C8: =B8/30 -> 26909.6 | D8: ='5'!$E$33 -> 186729556 | E8: =IFERROR(D8/C8,"") -> 6939.1428
A9: Blinn | B9: 401913 | C9: =B9/30 -> 13397.1 | D9: ='6'!$E$33 -> 50415846 | E9: =IFERROR(D9/C9,"") -> 3763.191
A10: Brazosport | B10: 79245 | C10: =B10/30 -> 2641.5 | D10: ='7'!$E$33 -> 17727779 | E10: =IFERROR(D10/C10,"") -> 6711.2546
A11: Central Texas | B11: 316196 | C11: =B11/30 -> 10539.867 | D11: ='8'!$E$33 -> 45639875 | E11: =IFERROR(D11/C11,"") -> 4330.2137
A12: Cisco | B12: 89266 | C12: =B12/30 -> 2975.5333 | D12: ='9'!$E$33 -> 11535601 | E12: =IFERROR(D12/C12,"") -> 3876.8179
A13: Clarendon | B13: 32284 | C13: =B13/30 -> 1076.1333 | D13: ='10'!$E$33 -> 4943342 | E13: =IFERROR(D13/C13,"") -> 4593.6148
A14: Coastal Bend | B14: 72723 | C14: =B14/30 -> 2424.1 | D14: ='11'!$E$33 -> 16124744 | E14: =IFERROR(D14/C14,"") -> 6651.8477
A15: College Of The Mainland | B15: 84095 | C15: =B15/30 -> 2803.1667 | D15: ='12'!$E$33 -> 27041085 | E15: =IFERROR(D15/C15,"") -> 9646.6205
A16: Collin | B16: 533689 | C16: =B16/30 -> 17789.633 | D16: ='13'!$E$33 -> 80980073 | E16: =IFERROR(D16/C16,"") -> 4552.0934
A17: Dallas | B17: 1402650 | C17: =B17/30 -> 46755 | D17: ='14'!$E$33 -> 2.4382815e+08 | E17: =IFERROR(D17/C17,"") -> 5215.0176
A18: Del Mar | B18: 221332 | C18: =B18/30 -> 7377.7333 | D18: ='15'!$E$33 -> 55245804 | E18: =IFERROR(D18/C18,"") -> 7488.1812
A19: El Paso | B19: 573271 | C19: =B19/30 -> 19109.033 | D19: ='16'!$E$33 -> 93518766 | E19: =IFERROR(D19/C19,"") -> 4893.9559
A20: Frank Phillips | B20: 20815 | C20: =B20/30 -> 693.83333 | D20: ='17'!$E$33 -> 5960329 | E20: =IFERROR(D20/C20,"") -> 8590.4333
A21: Galveston | B21: 46907 | C21: =B21/30 -> 1563.5667 | D21: ='18'!$E$33 -> 12223267 | E21: =IFERROR(D21/C21,"") -> 7817.5541
A22: Grayson | B22: 111186 | C22: =B22/30 -> 3706.2 | D22: ='19'!$E$33 -> 17909955 | E22: =IFERROR(D22/C22,"") -> 4832.4308
A23: Hill | B23: 93510 | C23: =B23/30 -> 3117 | D23: ='20'!$E$33 -> 13657092 | E23: =IFERROR(D23/C23,"") -> 4381.486
A24: Houston | B24: 1154606 | C24: =B24/30 -> 38486.867 | D24: ='21'!$E$33 -> 193030817 | E24: =IFERROR(D24/C24,"") -> 5015.4984
A25: Howard | B25: 82200 | C25: =B25/30 -> 2740 | D25: ='22'!$E$33 -> 18554773 | E25: =IFERROR(D25/C25,"") -> 6771.815
A26: Kilgore | B26: 134874 | C26: =B26/30 -> 4495.8 | D26: ='23'!$E$33 -> 24659540 | E26: =IFERROR(D26/C26,"") -> 5485.0171
A27: Laredo | B27: 184628 | C27: =B27/30 -> 6154.2667 | D27: ='24'!$E$33 -> 40632446 | E27: =IFERROR(D27/C27,"") -> 6602.3213
A28: Lee | B28: 129970 | C28: =B28/30 -> 4332.3333 | D28: ='25'!$E$33 -> 29010292 | E28: =IFERROR(D28/C28,"") -> 6696.2281
A29: Lonestar | B29: 1158780 | C29: =B29/30 -> 38626 | D29: ='26'!$E$33 -> 2.0700706e+08 | E29: =IFERROR(D29/C29,"") -> 5359.2673
A30: Mclennan | B30: 215595 | C30: =B30/30 -> 7186.5 | D30: ='27'!$E$33 -> 42200548 | E30: =IFERROR(D30/C30,"") -> 5872.1976
A31: Midland | B31: 119553 | C31: =B31/30 -> 3985.1 | D31: ='28'!$E$33 -> 29785137 | E31: =IFERROR(D31/C31,"") -> 7474.1254
A32: Navarro | B32: 236739 | C32: =B32/30 -> 7891.3 | D32: ='29'!$E$33 -> 27300540 | E32: =IFERROR(D32/C32,"") -> 3459.5745
A33: North Central Texas | B33: 189523 | C33: =B33/30 -> 6317.4333 | D33: ='30'!$E$33 -> 23292997 | E33: =IFERROR(D33/C33,"") -> 3687.0982
A34: Northeast Texas | B34: 72930 | C34: =B34/30 -> 2431 | D34: ='31'!$E$33 -> 11625103 | E34: =IFERROR(D34/C34,"") -> 4782.0251
A35: Odessa | B35: 95324 | C35: =B35/30 -> 3177.4667 | D35: ='32'!$E$33 -> 26076034 | E35: =IFERROR(D35/C35,"") -> 8206.5484
A36: Panola | B36: 52818 | C36: =B36/30 -> 1760.6 | D36: ='33'!$E$33 -> 11034987 | E36: =IFERROR(D36/C36,"") -> 6267.7422
A37: Paris | B37: 125940 | C37: =B37/30 -> 4198 | D37: ='34'!$E$33 -> 16489054 | E37: =IFERROR(D37/C37,"") -> 3927.8356
A38: Ranger | B38: 38899 | C38: =B38/30 -> 1296.6333 | D38: ='35'!$E$33 -> 4578438 | E38: =IFERROR(D38/C38,"") -> 3531.0198
A39: San Jacinto | B39: 590220 | C39: =B39/30 -> 19674 | D39: ='36'!$E$33 -> 1.1044721e+08 | E39: =IFERROR(D39/C39,"") -> 5613.8667
A40: South Plains | B40: 213116 | C40: =B40/30 -> 7103.8667 | D40: ='37'!$E$33 -> 37245853 | E40: =IFERROR(D40/C40,"") -> 5243.0394
...

Sheet Discipline Summary
A1: =Summary!A1 -> Community and Technical Colleges, Report of Fundable Operating Expenses, Fiscal Year (FY) 2012
A2: Discipline Summary of Expense per Contact Hour by Institution
A3: Institution | B3: AG | C3: ARCH | D3: SCI | E3: BA | F3: CP | G3: COMM | H3: CS | I3: CNSTR | J3: HE | K3: ENG | L3: ENGR | M3: LA | N3: FL | O3: HODA | P3: HODH | Q3: HOO | R3: HORT | S3: NUR | T3: MATH | U3: AUTO | V3: MECH | W3: ELECT | X3: PE | Y3: PA | Z3: SS | AA3: FA | AB3: DEM | AC3: DER | AD3: Total
A4: Alamo | B4: ='1'!$F$5 -> 6.5219432 | C4: ='1'!$F$6 -> 10.071416 | D4: ='1'!$F$7 -> 8.7560484 | E4: ='1'!$F$8 -> 9.128574 | F4: ='1'!$F$9 -> 36.093933 | G4: ='1'!$F$10 -> 8.848294 | H4: ='1'!$F$11 -> 11.964128 | I4: ='1'!$F$12 -> 9.2635351 | J4: ='1'!$F$13 -> 8.6868189 | K4: ='1'!$F$14 -> 16.0307 | L4: ='1'!$F$15 -> 10.990392 | M4: ='1'!$F$16 -> 8.5975772 | N4: ='1'!$F$17 -> 8.2445898 | O4: ='1'!$F$18 -> 16.117754 | P4: ='1'!$F$19 | Q4: ='1'!$F$20 -> 9.9100058 | R4: ='1'!$F$21 -> 13.76094 | S4: ='1'!$F$22 -> 13.507538 | T4: ='1'!$F$23 -> 8.178886 | U4: ='1'!$F$24 -> 9.9351227 | V4: ='1'!$F$25 -> 8.6963294 | W4: ='1'!$F$26 -> 6.3442274 | X4: ='1'!$F$27 -> 9.5827268 | Y4: ='1'!$F$28 -> 8.5695727 | Z4: ='1'!$F$29 -> 7.7354521 | AA4: ='1'!$F$30 -> 9.8060239 | AB4: ='1'!$F$31 -> 7.611667 | AC4: ='1'!$F$32 -> 8.1002669 | AD4: ='1'!$F$33 -> 8.9002933
A5: Alvin | B5: ='2'!$F$5 -> 10.343713 | C5: ='2'!$F$6 -> 11.070997 | D5: ='2'!$F$7 -> 6.4783442 | E5: ='2'!$F$8 -> 9.0742023 | F5: ='2'!$F$9 -> 4.1040666 | G5: ='2'!$F$10 -> 13.130688 | H5: ='2'!$F$11 -> 18.943358 | I5: ='2'!$F$12 -> 4.5883911 | J5: ='2'!$F$13 -> 9.1492701 | K5: ='2'!$F$14 | L5: ='2'!$F$15 -> 13.268211 | M5: ='2'!$F$16 -> 8.0579116 | N5: ='2'!$F$17 -> 7.6928692 | O5: ='2'!$F$18 -> 12.199741 | P5: ='2'!$F$19 | Q5: ='2'!$F$20 -> 10.766218 | R5: ='2'!$F$21 -> 19.243442 | S5: ='2'!$F$22 -> 12.595659 | T5: ='2'!$F$23 -> 8.8350715 | U5: ='2'!$F$24 -> 10.765599 | V5: ='2'!$F$25 | W5: ='2'!$F$26 -> 4.3634062 | X5: ='2'!$F$27 -> 13.901829 | Y5: ='2'!$F$28 -> 9.5590831 | Z5: ='2'!$F$29 -> 8.1644058 | AA5: ='2'!$F$30 -> 15.1414 | AB5: ='2'!$F$31 -> 8.5828599 | AC5: ='2'!$F$32 -> 9.9382504 | AD5: ='2'!$F$33 -> 9.7497831
A6: Amarillo | B6: ='3'!$F$5 -> 8.696281 | C6: ='3'!$F$6 -> 10.009047 | D6: ='3'!$F$7 -> 8.0919282 | E6: ='3'!$F$8 -> 8.4139606 | F6: ='3'!$F$9 -> 10.010037 | G6: ='3'!$F$10 -> 8.9330666 | H6: ='3'!$F$11 -> 8.3377964 | I6: ='3'!$F$12 -> 10.042889 | J6: ='3'!$F$13 -> 7.4299042 | K6: ='3'!$F$14 -> 8.091396 | L6: ='3'!$F$15 -> 9.2023274 | M6: ='3'!$F$16 -> 8.6678078 | N6: ='3'!$F$17 -> 8.0658455 | O6: ='3'!$F$18 -> 10.200288 | P6: ='3'!$F$19 -> 8.5941653 | Q6: ='3'!$F$20 -> 8.6723012 | R6: ='3'!$F$21 -> 8.6188041 | S6: ='3'!$F$22 -> 10.525112 | T6: ='3'!$F$23 -> 8.3249001 | U6: ='3'!$F$24 -> 10.009041 | V6: ='3'!$F$25 -> 10.05203 | W6: ='3'!$F$26 -> 9.5722389 | X6: ='3'!$F$27 -> 6.358428 | Y6: ='3'!$F$28 -> 8.703965 | Z6: ='3'!$F$29 -> 6.5972224 | AA6: ='3'!$F$30 -> 8.0290018 | AB6: ='3'!$F$31 -> 8.324896 | AC6: ='3'!$F$32 -> 8.6678101 | AD6: ='3'!$F$33 -> 8.4342468
A7: Angelina | B7: ='4'!$F$5 | C7: ='4'!$F$6 -> 8.6595054 | D7: ='4'!$F$7 -> 5.6761265 | E7: ='4'!$F$8 -> 6.5461664 | F7: ='4'!$F$9 -> 12.005646 | G7: ='4'!$F$10 -> 11.765993 | H7: ='4'!$F$11 -> 13.644237 | I7: ='4'!$F$12 -> 7.1030541 | J7: ='4'!$F$13 -> 7.2103076 | K7: ='4'!$F$14 -> 206.75044 | L7: ='4'!$F$15 -> 7.1060966 | M7: ='4'!$F$16 -> 5.7577061 | N7: ='4'!$F$17 -> 5.6233817 | O7: ='4'!$F$18 -> 9.0435833 | P7: ='4'!$F$19 | Q7: ='4'!$F$20 -> 8.1622339 | R7: ='4'!$F$21 -> 12.534675 | S7: ='4'!$F$22 -> 5.5744461 | T7: ='4'!$F$23 -> 6.8765963 | U7: ='4'!$F$24 -> 6.2911925 | V7: ='4'!$F$25 -> 8.7493722 | W7: ='4'!$F$26 -> 7.0997676 | X7: ='4'!$F$27 -> 7.6610487 | Y7: ='4'!$F$28 -> 6.6466965 | Z7: ='4'!$F$29 -> 5.8939433 | AA7: ='4'!$F$30 -> 7.6294205 | AB7: ='4'!$F$31 -> 6.8766858 | AC7: ='4'!$F$32 -> 5.731069 | AD7: ='4'!$F$33 -> 6.8336158
A8: Austin | B8: ='5'!$F$5 -> 8.2986123 | C8: ='5'!$F$6 -> 17.564607 | D8: ='5'!$F$7 -> 11.589608 | E8: ='5'!$F$8 -> 10.14773 | F8: ='5'!$F$9 | G8: ='5'!$F$10 -> 8.3980086 | H8: ='5'!$F$11 -> 16.975317 | I8: ='5'!$F$12 -> 5.7469094 | J8: ='5'!$F$13 -> 15.014823 | K8: ='5'!$F$14 -> 15.694387 | L8: ='5'!$F$15 -> 13.30228 | M8: ='5'!$F$16 -> 10.442438 | N8: ='5'!$F$17 -> 10.358199 | O8: ='5'!$F$18 -> 17.820209 | P8: ='5'!$F$19 -> 35.264738 | Q8: ='5'!$F$20 -> 16.143989 | R8: ='5'!$F$21 | S8: ='5'!$F$22 -> 20.208627 | T8: ='5'!$F$23 -> 9.6479515 | U8: ='5'!$F$24 -> 16.331196 | V8: ='5'!$F$25 -> 23.903615 | W8: ='5'!$F$26 -> 37.308562 | X8: ='5'!$F$27 -> 10.244921 | Y8: ='5'!$F$28 -> 9.5013883 | Z8: ='5'!$F$29 -> 9.0710837 | AA8: ='5'!$F$30 -> 15.081343 | AB8: ='5'!$F$31 -> 9.7502305 | AC8: ='5'!$F$32 -> 10.752457 | AD8: ='5'!$F$33 -> 11.470022
A9: Blinn | B9: ='6'!$F$5 -> 8.0617658 | C9: ='6'!$F$6 -> 10.53795 | D9: ='6'!$F$7 -> 4.8068864 | E9: ='6'!$F$8 -> 6.8141194 | F9: ='6'!$F$9 | G9: ='6'!$F$10 -> 3.5824527 | H9: ='6'!$F$11 -> 16.115688 | I9: ='6'!$F$12 -> 8.9368365 | J9: ='6'!$F$13 -> 3.5209144 | K9: ='6'!$F$14 | L9: ='6'!$F$15 -> 7.4676269 | M9: ='6'!$F$16 -> 6.6750958 | N9: ='6'!$F$17 -> 7.0192074 | O9: ='6'!$F$18 -> 14.715109 | P9: ='6'!$F$19 -> 26.100696 | Q9: ='6'!$F$20 -> 8.9428308 | R9: ='6'!$F$21 | S9: ='6'!$F$22 -> 11.013357 | T9: ='6'!$F$23 -> 5.9320671 | U9: ='6'!$F$24 -> 8.9345607 | V9: ='6'!$F$25 -> 8.9370282 | W9: ='6'!$F$26 -> 8.9369284 | X9: ='6'!$F$27 -> 7.8143595 | Y9: ='6'!$F$28 -> 9.8782838 | Z9: ='6'!$F$29 -> 4.9999061 | AA9: ='6'!$F$30 -> 6.7609019 | AB9: ='6'!$F$31 -> 5.9320691 | AC9: ='6'!$F$32 -> 6.6750965 | AD9: ='6'!$F$33 -> 6.3978721
A10: Brazosport | B10: ='7'!$F$5 -> 6.5153114 | C10: ='7'!$F$6 -> 9.9731761 | D10: ='7'!$F$7 -> 9.9269028 | E10: ='7'!$F$8 -> 11.875574 | F10: ='7'!$F$9 | G10: ='7'!$F$10 -> 5.3472496 | H10: ='7'!$F$11 -> 11.003575 | I10: ='7'!$F$12 -> 10.045943 | J10: ='7'!$F$13 -> 9.9116179 | K10: ='7'!$F$14 | L10: ='7'!$F$15 -> 8.8611876 | M10: ='7'!$F$16 -> 9.699947 | N10: ='7'!$F$17 -> 9.5648787 | O10: ='7'!$F$18 -> 13.845884 | P10: ='7'!$F$19 | Q10: ='7'!$F$20 -> 13.77261 | R10: ='7'!$F$21 | S10: ='7'!$F$22 -> 18.197155 | T10: ='7'!$F$23 -> 9.0123541 | U10: ='7'!$F$24 -> 11.064539 | V10: ='7'!$F$25 | W10: ='7'!$F$26 -> 8.7963568 | X10: ='7'!$F$27 | Y10: ='7'!$F$28 -> 9.2388388 | Z10: ='7'!$F$29 -> 10.225757 | AA10: ='7'!$F$30 -> 12.252516 | AB10: ='7'!$F$31 -> 9.01235 | AC10: ='7'!$F$32 -> 9.6998649 | AD10: ='7'!$F$33 -> 10.332891
A11: Central Texas | B11: ='8'!$F$5 -> 5.7119477 | C11: ='8'!$F$6 -> 5.8323166 | D11: ='8'!$F$7 -> 6.2577389 | E11: ='8'!$F$8 -> 6.2865037 | F11: ='8'!$F$9 -> 41.533857 | G11: ='8'!$F$10 -> 28.21467 | H11: ='8'!$F$11 -> 6.8412521 | I11: ='8'!$F$12 -> 4.3478174 | J11: ='8'!$F$13 -> 9.9888424 | K11: ='8'!$F$14 -> 5.7542575 | L11: ='8'!$F$15 -> 4.2116307 | M11: ='8'!$F$16 -> 6.8497965 | N11: ='8'!$F$17 -> 5.8936348 | O11: ='8'!$F$18 -> 10.987729 | P11: ='8'!$F$19 | Q11: ='8'!$F$20 -> 12.174939 | R11: ='8'!$F$21 | S11: ='8'!$F$22 -> 10.247112 | T11: ='8'!$F$23 -> 6.4059484 | U11: ='8'!$F$24 -> 8.5084939 | V11: ='8'!$F$25 -> 5.9643143 | W11: ='8'!$F$26 -> 5.8709123 | X11: ='8'!$F$27 -> 6.7574153 | Y11: ='8'!$F$28 -> 6.4786476 | Z11: ='8'!$F$29 -> 5.1611214 | AA11: ='8'!$F$30 -> 5.6828897 | AB11: ='8'!$F$31 -> 4.7115101 | AC11: ='8'!$F$32 -> 4.8669308 | AD11: ='8'!$F$33 -> 6.6203312
A12: Cisco | B12: ='9'!$F$5 -> 11.946924 | C12: ='9'!$F$6 -> 9.2203759 | D12: ='9'!$F$7 -> 5.389229 | E12: ='9'!$F$8 -> 5.0979898 | F12: ='9'!$F$9 | G12: ='9'!$F$10 | H12: ='9'!$F$11 -> 14.848485 | I12: ='9'!$F$12 -> 7.6692086 | J12: ='9'!$F$13 -> 5.1136507 | K12: ='9'!$F$14 | L12: ='9'!$F$15 -> 5.7386365 | M12: ='9'!$F$16 -> 6.0010827 | N12: ='9'!$F$17 -> 4.1988797 | O12: ='9'!$F$18 -> 8.4617609 | P12: ='9'!$F$19 | Q12: ='9'!$F$20 -> 5.4367112 | R12: ='9'!$F$21 -> 8.7814972 | S12: ='9'!$F$22 -> 9.6208145 | T12: ='9'!$F$23 -> 5.1189859 | U12: ='9'!$F$24 -> 6.6310422 | V12: ='9'!$F$25 | W12: ='9'!$F$26 -> 5.4383284 | X12: ='9'!$F$27 -> 13.510841 | Y12: ='9'!$F$28 -> 7.6038052 | Z12: ='9'!$F$29 -> 5.1075796 | AA12: ='9'!$F$30 -> 6.6554998 | AB12: ='9'!$F$31 -> 6.7314656 | AC12: ='9'!$F$32 -> 6.665598 | AD12: ='9'!$F$33 -> 6.3060055
A13: Clarendon | B13: ='10'!$F$5 -> 8.5934687 | C13: ='10'!$F$6 -> 7.2038554 | D13: ='10'!$F$7 -> 5.8444132 | E13: ='10'!$F$8 -> 8.6928727 | F13: ='10'!$F$9 | G13: ='10'!$F$10 | H13: ='10'!$F$11 -> 9.9000799 | I13: ='10'!$F$12 | J13: ='10'!$F$13 -> 5.4085988 | K13: ='10'!$F$14 | L13: ='10'!$F$15 -> 6.3912039 | M13: ='10'!$F$16 -> 5.7354621 | N13: ='10'!$F$17 -> 5.1206133 | O13: ='10'!$F$18 | P13: ='10'!$F$19 | Q13: ='10'!$F$20 -> 4.8647356 | R13: ='10'!$F$21 | S13: ='10'!$F$22 -> 7.2720723 | T13: ='10'!$F$23 -> 7.5989367 | U13: ='10'!$F$24 | V13: ='10'!$F$25 | W13: ='10'!$F$26 | X13: ='10'!$F$27 -> 11.740245 | Y13: ='10'!$F$28 -> 6.2144003 | Z13: ='10'!$F$29 -> 5.4998383 | AA13: ='10'!$F$30 -> 5.3235885 | AB13: ='10'!$F$31 -> 6.152708 | AC13: ='10'!$F$32 -> 5.4460515 | AD13: ='10'!$F$33 -> 6.7304978
A14: Coastal Bend | B14: ='11'!$F$5 -> 9.2544136 | C14: ='11'!$F$6 -> 9.584667 | D14: ='11'!$F$7 -> 8.1919752 | E14: ='11'!$F$8 -> 9.3606409 | F14: ='11'!$F$9 | G14: ='11'!$F$10 -> 15.439995 | H14: ='11'!$F$11 -> 9.6319645 | I14: ='11'!$F$12 | J14: ='11'!$F$13 -> 9.796438 | K14: ='11'!$F$14 | L14: ='11'!$F$15 -> 9.1432381 | M14: ='11'!$F$16 -> 7.239567 | N14: ='11'!$F$17 -> 7.156023 | O14: ='11'!$F$18 -> 29.16995 | P14: ='11'!$F$19 -> 19.149286 | Q14: ='11'!$F$20 -> 9.4056519 | R14: ='11'!$F$21 | S14: ='11'!$F$22 -> 9.8764023 | T14: ='11'!$F$23 -> 8.2581282 | U14: ='11'!$F$24 -> 8.7434833 | V14: ='11'!$F$25 -> 10.04911 | W14: ='11'!$F$26 -> 14.812097 | X14: ='11'!$F$27 -> 10.411058 | Y14: ='11'!$F$28 -> 10.201589 | Z14: ='11'!$F$29 -> 7.3183201 | AA14: ='11'!$F$30 -> 8.678719 | AB14: ='11'!$F$31 -> 8.039914 | AC14: ='11'!$F$32 -> 7.8750191 | AD14: ='11'!$F$33 -> 9.1202529
A15: College Of The Mainland | B15: ='12'!$F$5 -> 27.725463 | C15: ='12'!$F$6 -> 21.11428 | D15: ='12'!$F$7 -> 10.315733 | E15: ='12'!$F$8 -> 10.871102 | F15: ='12'!$F$9 | G15: ='12'!$F$10 -> 13.800268 | H15: ='12'!$F$11 -> 19.187868 | I15: ='12'!$F$12 -> 8.7445736 | J15: ='12'!$F$13 -> 16.446824 | K15: ='12'!$F$14 | L15: ='12'!$F$15 -> 7.3759759 | M15: ='12'!$F$16 -> 15.090014 | N15: ='12'!$F$17 -> 13.011413 | O15: ='12'!$F$18 -> 17.05091 | P15: ='12'!$F$19 | Q15: ='12'!$F$20 -> 14.650519 | R15: ='12'!$F$21 | S15: ='12'!$F$22 -> 18.380482 | T15: ='12'!$F$23 -> 14.037207 | U15: ='12'!$F$24 | V15: ='12'!$F$25 | W15: ='12'!$F$26 -> 10.84756 | X15: ='12'!$F$27 -> 12.409324 | Y15: ='12'!$F$28 -> 16.570437 | Z15: ='12'!$F$29 -> 11.416778 | AA15: ='12'!$F$30 -> 16.032004 | AB15: ='12'!$F$31 -> 10.772026 | AC15: ='12'!$F$32 -> 14.81608 | AD15: ='12'!$F$33 -> 13.421712
A16: Collin | B16: ='13'!$F$5 -> 6.3280943 | C16: ='13'!$F$6 -> 3.3940303 | D16: ='13'!$F$7 -> 7.5241072 | E16: ='13'!$F$8 -> 6.4857674 | F16: ='13'!$F$9 -> 3.3910226 | G16: ='13'!$F$10 -> 5.2722709 | H16: ='13'!$F$11 -> 7.8063402 | I16: ='13'!$F$12 -> 3.3902604 | J16: ='13'!$F$13 -> 6.4130349 | K16: ='13'!$F$14 -> 19.385347 | L16: ='13'!$F$15 -> 8.9248148 | M16: ='13'!$F$16 -> 6.9754622 | N16: ='13'!$F$17 -> 5.1330632 | O16: ='13'!$F$18 -> 20.447108 | P16: ='13'!$F$19 -> 22.990522 | Q16: ='13'!$F$20 -> 5.6195968 | R16: ='13'!$F$21 -> 18.951789 | S16: ='13'!$F$22 | T16: ='13'!$F$23 -> 6.5740788 | U16: ='13'!$F$24 | V16: ='13'!$F$25 -> 3.3916752 | W16: ='13'!$F$26 -> 3.3916144 | X16: ='13'!$F$27 -> 7.8020781 | Y16: ='13'!$F$28 -> 9.5425776 | Z16: ='13'!$F$29 -> 6.3718372 | AA16: ='13'!$F$30 -> 8.6325457 | AB16: ='13'!$F$31 -> 6.476204 | AC16: ='13'!$F$32 -> 7.2586729 | AD16: ='13'!$F$33 -> 7.217813
A17: Dallas | B17: ='14'!$F$5 -> 17.093046 | C17: ='14'!$F$6 -> 8.8055314 | D17: ='14'!$F$7 -> 7.5475849 | E17: ='14'!$F$8 -> 7.5111984 | F17: ='14'!$F$9 -> 16.81923 | G17: ='14'!$F$10 -> 8.9873231 | H17: ='14'!$F$11 -> 7.5715205 | I17: ='14'!$F$12 -> 13.049596 | J17: ='14'!$F$13 -> 7.1326407 | K17: ='14'!$F$14 -> 9.7679608 | L17: ='14'!$F$15 -> 6.5220504 | M17: ='14'!$F$16 -> 9.8651015 | N17: ='14'!$F$17 -> 6.9070911 | O17: ='14'!$F$18 -> 11.357149 | P17: ='14'!$F$19 | Q17: ='14'!$F$20 -> 7.7047482 | R17: ='14'!$F$21 -> 18.172187 | S17: ='14'!$F$22 -> 18.06386 | T17: ='14'!$F$23 -> 6.7948826 | U17: ='14'!$F$24 -> 9.439785 | V17: ='14'!$F$25 -> 5.2808973 | W17: ='14'!$F$26 -> 9.6455626 | X17: ='14'!$F$27 -> 9.5846671 | Y17: ='14'!$F$28 -> 7.1046935 | Z17: ='14'!$F$29 -> 6.586765 | AA17: ='14'!$F$30 -> 8.3085216 | AB17: ='14'!$F$31 -> 7.2419807 | AC17: ='14'!$F$32 -> 5.6653704 | AD17: ='14'!$F$33 -> 7.6776755
A18: Del Mar | B18: ='15'!$F$5 -> 5.3016629 | C18: ='15'!$F$6 -> 8.0079287 | D18: ='15'!$F$7 -> 8.2802773 | E18: ='15'!$F$8 -> 10.479156 | F18: ='15'!$F$9 | G18: ='15'!$F$10 -> 10.466116 | H18: ='15'!$F$11 -> 10.158772 | I18: ='15'!$F$12 -> 5.1560122 | J18: ='15'!$F$13 -> 9.516769 | K18: ='15'!$F$14 -> 6.4454946 | L18: ='15'!$F$15 -> 8.9607028 | M18: ='15'!$F$16 -> 12.312635 | N18: ='15'!$F$17 -> 8.6884305 | O18: ='15'!$F$18 -> 14.179397 | P18: ='15'!$F$19 -> 19.432521 | Q18: ='15'!$F$20 -> 11.027284 | R18: ='15'!$F$21 -> 15.974721 | S18: ='15'!$F$22 -> 14.528481 | T18: ='15'!$F$23 -> 10.685502 | U18: ='15'!$F$24 -> 12.863142 | V18: ='15'!$F$25 -> 8.7395647 | W18: ='15'!$F$26 -> 10.0525 | X18: ='15'!$F$27 -> 9.5642065 | Y18: ='15'!$F$28 -> 11.888675 | Z18: ='15'!$F$29 -> 8.5509666 | AA18: ='15'!$F$30 -> 9.7081155 | AB18: ='15'!$F$31 -> 10.946995 | AC18: ='15'!$F$32 -> 10.649169 | AD18: ='15'!$F$33 -> 10.223075
A19: El Paso | B19: ='16'!$F$5 -> 5.6357007 | C19: ='16'!$F$6 -> 7.4389768 | D19: ='16'!$F$7 -> 6.6305458 | E19: ='16'!$F$8 -> 10.063899 | F19: ='16'!$F$9 | G19: ='16'!$F$10 -> 14.518709 | H19: ='16'!$F$11 -> 7.8215325 | I19: ='16'!$F$12 -> 9.720769 | J19: ='16'!$F$13 -> 8.157025 | K19: ='16'!$F$14 -> 7.3200106 | L19: ='16'!$F$15 -> 7.5501585 | M19: ='16'!$F$16 -> 7.1053402 | N19: ='16'!$F$17 -> 8.129902 | O19: ='16'!$F$18 -> 16.127969 | P19: ='16'!$F$19 -> 26.942426 | Q19: ='16'!$F$20 -> 11.066422 | R19: ='16'!$F$21 -> 15.591998 | S19: ='16'!$F$22 -> 11.229051 | T19: ='16'!$F$23 -> 7.0607968 | U19: ='16'!$F$24 -> 7.8739234 | V19: ='16'!$F$25 -> 16.286018 | W19: ='16'!$F$26 -> 11.598481 | X19: ='16'!$F$27 -> 18.301662 | Y19: ='16'!$F$28 -> 7.568605 | Z19: ='16'!$F$29 -> 6.3949222 | AA19: ='16'!$F$30 -> 7.8974745 | AB19: ='16'!$F$31 -> 6.4156479 | AC19: ='16'!$F$32 -> 7.764393 | AD19: ='16'!$F$33 -> 7.7743912
A20: Frank Phillips | B20: ='17'!$F$5 -> 15.544913 | C20: ='17'!$F$6 -> 10.203326 | D20: ='17'!$F$7 -> 10.293752 | E20: ='17'!$F$8 -> 10.940532 | F20: ='17'!$F$9 | G20: ='17'!$F$10 | H20: ='17'!$F$11 -> 8.9805256 | I20: ='17'!$F$12 -> 6.1869172 | J20: ='17'!$F$13 -> 10.043164 | K20: ='17'!$F$14 | L20: ='17'!$F$15 -> 10.170192 | M20: ='17'!$F$16 -> 9.9343835 | N20: ='17'!$F$17 -> 9.5377983 | O20: ='17'!$F$18 -> 13.284825 | P20: ='17'!$F$19 | Q20: ='17'!$F$20 -> 10.424881 | R20: ='17'!$F$21 | S20: ='17'!$F$22 -> 10.39145 | T20: ='17'!$F$23 -> 10.395487 | U20: ='17'!$F$24 | V20: ='17'!$F$25 -> 5.6022772 | W20: ='17'!$F$26 -> 53.084035 | X20: ='17'!$F$27 -> 9.5952375 | Y20: ='17'!$F$28 -> 7.7219064 | Z20: ='17'!$F$29 -> 10.035405 | AA20: ='17'!$F$30 -> 8.0933068 | AB20: ='17'!$F$31 -> 10.730399 | AC20: ='17'!$F$32 -> 10.389857 | AD20: ='17'!$F$33 -> 10.174648
A21: Galveston | B21: ='18'!$F$5 -> 10.647999 | C21: ='18'!$F$6 -> 11.157174 | D21: ='18'!$F$7 -> 10.279924 | E21: ='18'!$F$8 -> 10.09986 | F21: ='18'!$F$9 | G21: ='18'!$F$10 | H21: ='18'!$F$11 -> 12.762953 | I21: ='18'!$F$12 | J21: ='18'!$F$13 -> 11.072514 | K21: ='18'!$F$14 | L21: ='18'!$F$15 -> 13.285666 | M21: ='18'!$F$16 -> 9.8377772 | N21: ='18'!$F$17 -> 7.3267775 | O21: ='18'!$F$18 -> 19.156557 | P21: ='18'!$F$19 | Q21: ='18'!$F$20 -> 11.648394 | R21: ='18'!$F$21 | S21: ='18'!$F$22 -> 14.027333 | T21: ='18'!$F$23 -> 10.931916 | U21: ='18'!$F$24 -> 16.522114 | V21: ='18'!$F$25 -> 13.181114 | W21: ='18'!$F$26 | X21: ='18'!$F$27 -> 14.700029 | Y21: ='18'!$F$28 -> 11.637956 | Z21: ='18'!$F$29 -> 9.3734096 | AA21: ='18'!$F$30 -> 11.642538 | AB21: ='18'!$F$31 -> 8.8317656 | AC21: ='18'!$F$32 -> 11.956623 | AD21: ='18'!$F$33 -> 11.389891
A22: Grayson | B22: ='19'!$F$5 -> 7.1008676 | C22: ='19'!$F$6 -> 6.8135853 | D22: ='19'!$F$7 -> 6.8170116 | E22: ='19'!$F$8 -> 8.0608432 | F22: ='19'!$F$9 | G22: ='19'!$F$10 | H22: ='19'!$F$11 -> 7.4416932 | I22: ='19'!$F$12 -> 4.7867777 | J22: ='19'!$F$13 -> 6.7449536 | K22: ='19'!$F$14 -> 11.031388 | L22: ='19'!$F$15 -> 9.3387826 | M22: ='19'!$F$16 -> 5.6226884 | N22: ='19'!$F$17 -> 8.1240671 | O22: ='19'!$F$18 -> 10.01487 | P22: ='19'!$F$19 | Q22: ='19'!$F$20 -> 8.2002769 | R22: ='19'!$F$21 | S22: ='19'!$F$22 -> 7.1351984 | T22: ='19'!$F$23 -> 6.2582833 | U22: ='19'!$F$24 -> 8.214931 | V22: ='19'!$F$25 -> 2.9305107 | W22: ='19'!$F$26 -> 10.74754 | X22: ='19'!$F$27 -> 3.5285075 | Y22: ='19'!$F$28 -> 7.4728657 | Z22: ='19'!$F$29 -> 5.9061961 | AA22: ='19'!$F$30 -> 6.8648886 | AB22: ='19'!$F$31 -> 5.5141334 | AC22: ='19'!$F$32 -> 6.882798 | AD22: ='19'!$F$33 -> 7.0353753
A23: Hill | B23: ='20'!$F$5 -> 8.1165648 | C23: ='20'!$F$6 -> 7.0960201 | D23: ='20'!$F$7 -> 5.969324 | E23: ='20'!$F$8 -> 3.4086908 | F23: ='20'!$F$9 | G23: ='20'!$F$10 -> 4.7929674 | H23: ='20'!$F$11 -> 17.426127 | I23: ='20'!$F$12 -> 12.759504 | J23: ='20'!$F$13 -> 5.5724691 | K23: ='20'!$F$14 -> 4.4976457 | L23: ='20'!$F$15 -> 4.8068957 | M23: ='20'!$F$16 -> 4.948342 | N23: ='20'!$F$17 -> 4.6522589 | O23: ='20'!$F$18 -> 8.3489928 | P23: ='20'!$F$19 | Q23: ='20'!$F$20 -> 6.8251232 | R23: ='20'!$F$21 | S23: ='20'!$F$22 -> 8.0498258 | T23: ='20'!$F$23 -> 4.8088858 | U23: ='20'!$F$24 -> 7.5052634 | V23: ='20'!$F$25 | W23: ='20'!$F$26 | X23: ='20'!$F$27 -> 11.433846 | Y23: ='20'!$F$28 -> 6.4165167 | Z23: ='20'!$F$29 -> 5.1109359 | AA23: ='20'!$F$30 -> 6.1848954 | AB23: ='20'!$F$31 -> 4.7164463 | AC23: ='20'!$F$32 -> 4.9205893 | AD23: ='20'!$F$33 -> 5.9307518
A24: Houston | B24: ='21'!$F$5 -> 6.8367271 | C24: ='21'!$F$6 -> 10.007252 | D24: ='21'!$F$7 -> 6.9735462 | E24: ='21'!$F$8 -> 6.3981656 | F24: ='21'!$F$9 | G24: ='21'!$F$10 -> 5.999455 | H24: ='21'!$F$11 -> 14.628804 | I24: ='21'!$F$12 -> 8.752119 | J24: ='21'!$F$13 -> 7.0158781 | K24: ='21'!$F$14 -> 6.6994726 | L24: ='21'!$F$15 -> 6.6994763 | M24: ='21'!$F$16 -> 8.0386044 | N24: ='21'!$F$17 -> 7.1070843 | O24: ='21'!$F$18 -> 10.458052 | P24: ='21'!$F$19 -> 18.060693 | Q24: ='21'!$F$20 -> 9.4792134 | R24: ='21'!$F$21 -> 18.074046 | S24: ='21'!$F$22 -> 12.329301 | T24: ='21'!$F$23 -> 6.7621515 | U24: ='21'!$F$24 -> 8.569123 | V24: ='21'!$F$25 -> 14.131471 | W24: ='21'!$F$26 -> 7.7067216 | X24: ='21'!$F$27 -> 10.156315 | Y24: ='21'!$F$28 -> 10.355787 | Z24: ='21'!$F$29 -> 6.4047737 | AA24: ='21'!$F$30 -> 8.0180562 | AB24: ='21'!$F$31 -> 6.7621522 | AC24: ='21'!$F$32 -> 8.0386044 | AD24: ='21'!$F$33 -> 7.4988708
A25: Howard | B25: ='22'!$F$5 -> 9.0880857 | C25: ='22'!$F$6 -> 6.0773495 | D25: ='22'!$F$7 -> 7.5509798 | E25: ='22'!$F$8 -> 7.5800023 | F25: ='22'!$F$9 -> 7.7403414 | G25: ='22'!$F$10 -> 6.106786 | H25: ='22'!$F$11 -> 9.5263176 | I25: ='22'!$F$12 -> 5.6855803 | J25: ='22'!$F$13 -> 8.2532399 | K25: ='22'!$F$14 | L25: ='22'!$F$15 -> 6.6918256 | M25: ='22'!$F$16 -> 7.3693608 | N25: ='22'!$F$17 -> 7.4756774 | O25: ='22'!$F$18 -> 15.006583 | P25: ='22'!$F$19 -> 21.673264 | Q25: ='22'!$F$20 -> 7.116626 | R25: ='22'!$F$21 -> 18.228912 | S25: ='22'!$F$22 -> 9.7851472 | T25: ='22'!$F$23 -> 8.7576328 | U25: ='22'!$F$24 -> 6.092292 | V25: ='22'!$F$25 -> 6.5687017 | W25: ='22'!$F$26 -> 5.3949366 | X25: ='22'!$F$27 -> 38.317242 | Y25: ='22'!$F$28 -> 6.2193037 | Z25: ='22'!$F$29 -> 6.6422507 | AA25: ='22'!$F$30 -> 9.0028362 | AB25: ='22'!$F$31 -> 7.0959567 | AC25: ='22'!$F$32 -> 7.1072658 | AD25: ='22'!$F$33 -> 7.865038
A26: Kilgore | B26: ='23'!$F$5 -> 5.1687223 | C26: ='23'!$F$6 -> 6.8380901 | D26: ='23'!$F$7 -> 7.3545665 | E26: ='23'!$F$8 -> 6.5467961 | F26: ='23'!$F$9 | G26: ='23'!$F$10 -> 11.211345 | H26: ='23'!$F$11 -> 6.8611077 | I26: ='23'!$F$12 -> 45.535125 | J26: ='23'!$F$13 -> 6.012862 | K26: ='23'!$F$14 -> 12.765463 | L26: ='23'!$F$15 -> 6.6784019 | M26: ='23'!$F$16 -> 6.7265379 | N26: ='23'!$F$17 -> 8.2311738 | O26: ='23'!$F$18 -> 9.3255158 | P26: ='23'!$F$19 | Q26: ='23'!$F$20 -> 7.5770462 | R26: ='23'!$F$21 | S26: ='23'!$F$22 -> 7.2167159 | T26: ='23'!$F$23 -> 6.0796865 | U26: ='23'!$F$24 -> 8.2867696 | V26: ='23'!$F$25 -> 5.1459559 | W26: ='23'!$F$26 -> 3.1009279 | X26: ='23'!$F$27 -> 8.8290602 | Y26: ='23'!$F$28 -> 7.819075 | Z26: ='23'!$F$29 -> 5.7285441 | AA26: ='23'!$F$30 -> 8.1207731 | AB26: ='23'!$F$31 -> 6.2166172 | AC26: ='23'!$F$32 -> 5.0206017 | AD26: ='23'!$F$33 -> 6.9945526
A27: Laredo | B27: ='24'!$F$5 -> 5.386017 | C27: ='24'!$F$6 -> 5.386017 | D27: ='24'!$F$7 -> 9.7457455 | E27: ='24'!$F$8 -> 10.857436 | F27: ='24'!$F$9 | G27: ='24'!$F$10 -> 8.0217047 | H27: ='24'!$F$11 -> 13.758038 | I27: ='24'!$F$12 -> 30.892489 | J27: ='24'!$F$13 -> 5.386017 | K27: ='24'!$F$14 | L27: ='24'!$F$15 -> 5.386017 | M27: ='24'!$F$16 -> 14.367375 | N27: ='24'!$F$17 -> 33.020467 | O27: ='24'!$F$18 -> 17.030067 | P27: ='24'!$F$19 | Q27: ='24'!$F$20 -> 10.459222 | R27: ='24'!$F$21 | S27: ='24'!$F$22 -> 19.750446 | T27: ='24'!$F$23 -> 9.7240793 | U27: ='24'!$F$24 -> 10.081239 | V27: ='24'!$F$25 -> 12.051543 | W27: ='24'!$F$26 -> 17.965047 | X27: ='24'!$F$27 -> 12.415977 | Y27: ='24'!$F$28 -> 10.599319 | Z27: ='24'!$F$29 -> 8.0949392 | AA27: ='24'!$F$30 -> 12.013273 | AB27: ='24'!$F$31 -> 9.7237984 | AC27: ='24'!$F$32 -> 8.0159158 | AD27: ='24'!$F$33 -> 10.788772
A28: Lee | B28: ='25'!$F$5 -> 6.1735628 | C28: ='25'!$F$6 -> 13.355632 | D28: ='25'!$F$7 -> 8.4029531 | E28: ='25'!$F$8 -> 9.4532329 | F28: ='25'!$F$9 -> 15.644658 | G28: ='25'!$F$10 -> 10.005484 | H28: ='25'!$F$11 -> 11.061245 | I28: ='25'!$F$12 -> 13.585678 | J28: ='25'!$F$13 -> 7.6856358 | K28: ='25'!$F$14 | L28: ='25'!$F$15 -> 8.7059293 | M28: ='25'!$F$16 -> 11.535144 | N28: ='25'!$F$17 -> 14.066331 | O28: ='25'!$F$18 -> 14.512986 | P28: ='25'!$F$19 | Q28: ='25'!$F$20 -> 12.804973 | R28: ='25'!$F$21 | S28: ='25'!$F$22 -> 11.863625 | T28: ='25'!$F$23 -> 9.0823779 | U28: ='25'!$F$24 -> 7.8444383 | V28: ='25'!$F$25 -> 9.4036719 | W28: ='25'!$F$26 -> 4.4066008 | X28: ='25'!$F$27 -> 19.610136 | Y28: ='25'!$F$28 -> 7.2448301 | Z28: ='25'!$F$29 -> 8.25761 | AA28: ='25'!$F$30 -> 11.486209 | AB28: ='25'!$F$31 -> 8.7009646 | AC28: ='25'!$F$32 -> 9.7367419 | AD28: ='25'!$F$33 -> 10.044798
A29: Lonestar | B29: ='26'!$F$5 -> 6.7729659 | C29: ='26'!$F$6 -> 10.378859 | D29: ='26'!$F$7 -> 8.0207125 | E29: ='26'!$F$8 -> 8.5341 | F29: ='26'!$F$9 -> 9.6312361 | G29: ='26'!$F$10 -> 7.0583943 | H29: ='26'!$F$11 -> 8.6744007 | I29: ='26'!$F$12 -> 9.5013367 | J29: ='26'!$F$13 -> 9.3043779 | K29: ='26'!$F$14 | L29: ='26'!$F$15 -> 10.000561 | M29: ='26'!$F$16 -> 8.8413176 | N29: ='26'!$F$17 -> 7.498634 | O29: ='26'!$F$18 -> 13.178399 | P29: ='26'!$F$19 -> 23.070413 | Q29: ='26'!$F$20 -> 10.901054 | R29: ='26'!$F$21 -> 14.421637 | S29: ='26'!$F$22 -> 10.496624 | T29: ='26'!$F$23 -> 8.7797363 | U29: ='26'!$F$24 -> 9.2528018 | V29: ='26'!$F$25 -> 11.600873 | W29: ='26'!$F$26 -> 9.9390635 | X29: ='26'!$F$27 -> 8.7495642 | Y29: ='26'!$F$28 -> 8.6003874 | Z29: ='26'!$F$29 -> 7.3754692 | AA29: ='26'!$F$30 -> 9.9387695 | AB29: ='26'!$F$31 -> 6.590473 | AC29: ='26'!$F$32 -> 7.3342293 | AD29: ='26'!$F$33 -> 8.4013413
A30: Mclennan | B30: ='27'!$F$5 -> 10.810868 | C30: ='27'!$F$6 | D30: ='27'!$F$7 -> 7.1721217 | E30: ='27'!$F$8 -> 8.8585347 | F30: ='27'!$F$9 | G30: ='27'!$F$10 -> 3.8564796 | H30: ='27'!$F$11 -> 11.965887 | I30: ='27'!$F$12 -> 3.1763993 | J30: ='27'!$F$13 -> 11.829414 | K30: ='27'!$F$14 -> 3.0653067 | L30: ='27'!$F$15 -> 13.171487 | M30: ='27'!$F$16 -> 10.290766 | N30: ='27'!$F$17 -> 7.0613589 | O30: ='27'!$F$18 -> 15.951753 | P30: ='27'!$F$19 | Q30: ='27'!$F$20 -> 9.95925 | R30: ='27'!$F$21 -> 12.152206 | S30: ='27'!$F$22 -> 8.4202799 | T30: ='27'!$F$23 -> 8.4633112 | U30: ='27'!$F$24 | V30: ='27'!$F$25 -> 13.534588 | W30: ='27'!$F$26 -> 3.0696794 | X30: ='27'!$F$27 -> 8.8221794 | Y30: ='27'!$F$28 -> 8.2147938 | Z30: ='27'!$F$29 -> 6.4959354 | AA30: ='27'!$F$30 -> 10.697654 | AB30: ='27'!$F$31 -> 8.0424318 | AC30: ='27'!$F$32 -> 3.7716615 | AD30: ='27'!$F$33 -> 8.9204867
A31: Midland | B31: ='28'!$F$5 -> 9.4961276 | C31: ='28'!$F$6 -> 10.340389 | D31: ='28'!$F$7 -> 10.024933 | E31: ='28'!$F$8 -> 9.02221 | F31: ='28'!$F$9 -> 98.679214 | G31: ='28'!$F$10 -> 27.305379 | H31: ='28'!$F$11 -> 15.38693 | I31: ='28'!$F$12 -> 6.2902899 | J31: ='28'!$F$13 -> 12.240151 | K31: ='28'!$F$14 -> 5.7586635 | L31: ='28'!$F$15 -> 16.422991 | M31: ='28'!$F$16 -> 9.9138903 | N31: ='28'!$F$17 -> 6.4499435 | O31: ='28'!$F$18 -> 13.029904 | P31: ='28'!$F$19 | Q31: ='28'!$F$20 -> 11.321056 | R31: ='28'!$F$21 -> 14.295897 | S31: ='28'!$F$22 -> 11.331994 | T31: ='28'!$F$23 -> 10.003144 | U31: ='28'!$F$24 -> 17.305238 | V31: ='28'!$F$25 -> 19.644836 | W31: ='28'!$F$26 -> 13.244941 | X31: ='28'!$F$27 -> 11.342409 | Y31: ='28'!$F$28 -> 8.8115274 | Z31: ='28'!$F$29 -> 9.1445063 | AA31: ='28'!$F$30 -> 11.381972 | AB31: ='28'!$F$31 -> 9.6018845 | AC31: ='28'!$F$32 -> 9.5629899 | AD31: ='28'!$F$33 -> 10.449426
A32: Navarro | B32: ='29'!$F$5 -> 10.61014 | C32: ='29'!$F$6 -> 3.8267987 | D32: ='29'!$F$7 -> 4.7690485 | E32: ='29'!$F$8 -> 5.8223744 | F32: ='29'!$F$9 | G32: ='29'!$F$10 -> 6.4593493 | H32: ='29'!$F$11 -> 4.1775792 | I32: ='29'!$F$12 -> 7.4598755 | J32: ='29'!$F$13 -> 2.8211081 | K32: ='29'!$F$14 -> 2.8944708 | L32: ='29'!$F$15 -> 4.6049975 | M32: ='29'!$F$16 -> 5.2291646 | N32: ='29'!$F$17 -> 3.7754211 | O32: ='29'!$F$18 -> 9.2016734 | P32: ='29'!$F$19 | Q32: ='29'!$F$20 -> 5.1039519 | R32: ='29'!$F$21 | S32: ='29'!$F$22 -> 7.8885853 | T32: ='29'!$F$23 -> 5.7836594 | U32: ='29'!$F$24 | V32: ='29'!$F$25 -> 2.6651552 | W32: ='29'!$F$26 -> 4.6124842 | X32: ='29'!$F$27 -> 5.3492164 | Y32: ='29'!$F$28 -> 4.4335319 | Z32: ='29'!$F$29 -> 4.8268825 | AA32: ='29'!$F$30 -> 5.6561068 | AB32: ='29'!$F$31 -> 4.6608651 | AC32: ='29'!$F$32 -> 4.2700681 | AD32: ='29'!$F$33 -> 4.9226315
A33: North Central Texas | B33: ='30'!$F$5 -> 8.1300939 | C33: ='30'!$F$6 -> 17.354871 | D33: ='30'!$F$7 -> 5.8422062 | E33: ='30'!$F$8 -> 4.9642061 | F33: ='30'!$F$9 | G33: ='30'!$F$10 -> 6.7558766 | H33: ='30'!$F$11 -> 14.781138 | I33: ='30'!$F$12 | J33: ='30'!$F$13 -> 5.8518481 | K33: ='30'!$F$14 | L33: ='30'!$F$15 -> 5.7642024 | M33: ='30'!$F$16 -> 6.6918392 | N33: ='30'!$F$17 -> 4.8115991 | O33: ='30'!$F$18 -> 9.6745379 | P33: ='30'!$F$19 | Q33: ='30'!$F$20 -> 8.4734791 | R33: ='30'!$F$21 | S33: ='30'!$F$22 -> 7.348304 | T33: ='30'!$F$23 -> 5.2872987 | U33: ='30'!$F$24 | V33: ='30'!$F$25 -> 10.837079 | W33: ='30'!$F$26 -> 7.0273071 | X33: ='30'!$F$27 -> 6.7045524 | Y33: ='30'!$F$28 -> 6.9071539 | Z33: ='30'!$F$29 -> 5.3445277 | AA33: ='30'!$F$30 -> 6.2744781 | AB33: ='30'!$F$31 -> 5.9548644 | AC33: ='30'!$F$32 -> 6.6070668 | AD33: ='30'!$F$33 -> 6.3247154
A34: Northeast Texas | B34: ='31'!$F$5 -> 16.912566 | C34: ='31'!$F$6 -> 6.2442586 | D34: ='31'!$F$7 -> 7.3298568 | E34: ='31'!$F$8 -> 7.21419 | F34: ='31'!$F$9 | G34: ='31'!$F$10 -> 12.749562 | H34: ='31'!$F$11 -> 11.987734 | I34: ='31'!$F$12 -> 10.501106 | J34: ='31'!$F$13 -> 5.6752674 | K34: ='31'!$F$14 | L34: ='31'!$F$15 -> 12.959875 | M34: ='31'!$F$16 -> 5.880576 | N34: ='31'!$F$17 -> 8.0679425 | O34: ='31'!$F$18 -> 8.4445349 | P34: ='31'!$F$19 -> 16.280953 | Q34: ='31'!$F$20 -> 8.8984827 | R34: ='31'!$F$21 | S34: ='31'!$F$22 -> 11.950779 | T34: ='31'!$F$23 -> 7.7694006 | U34: ='31'!$F$24 -> 12.533184 | V34: ='31'!$F$25 | W34: ='31'!$F$26 | X34: ='31'!$F$27 -> 6.1278944 | Y34: ='31'!$F$28 -> 9.2179678 | Z34: ='31'!$F$29 -> 5.9811002 | AA34: ='31'!$F$30 -> 9.559986 | AB34: ='31'!$F$31 -> 4.8910674 | AC34: ='31'!$F$32 -> 6.1299668 | AD34: ='31'!$F$33 -> 7.5647327
A35: Odessa | B35: ='32'!$F$5 -> 9.4216299 | C35: ='32'!$F$6 -> 12.330741 | D35: ='32'!$F$7 -> 9.7287775 | E35: ='32'!$F$8 -> 11.708731 | F35: ='32'!$F$9 | G35: ='32'!$F$10 -> 6.179641 | H35: ='32'!$F$11 -> 6.7683258 | I35: ='32'!$F$12 -> 6.4667529 | J35: ='32'!$F$13 -> 9.7228169 | K35: ='32'!$F$14 | L35: ='32'!$F$15 -> 10.56465 | M35: ='32'!$F$16 -> 10.707443 | N35: ='32'!$F$17 -> 10.838546 | O35: ='32'!$F$18 -> 14.974901 | P35: ='32'!$F$19 | Q35: ='32'!$F$20 -> 12.922722 | R35: ='32'!$F$21 | S35: ='32'!$F$22 -> 11.12038 | T35: ='32'!$F$23 -> 10.699444 | U35: ='32'!$F$24 -> 7.9617306 | V35: ='32'!$F$25 -> 28.05475 | W35: ='32'!$F$26 -> 13.55785 | X35: ='32'!$F$27 -> 10.692568 | Y35: ='32'!$F$28 -> 12.464223 | Z35: ='32'!$F$29 -> 9.3588625 | AA35: ='32'!$F$30 -> 11.039387 | AB35: ='32'!$F$31 -> 9.6302227 | AC35: ='32'!$F$32 -> 11.709524 | AD35: ='32'!$F$33 -> 10.931152
A36: Panola | B36: ='33'!$F$5 -> 19.512195 | C36: ='33'!$F$6 -> 15.61884 | D36: ='33'!$F$7 -> 7.3282486 | E36: ='33'!$F$8 -> 8.9492674 | F36: ='33'!$F$9 | G36: ='33'!$F$10 -> 24.75804 | H36: ='33'!$F$11 -> 11.099293 | I36: ='33'!$F$12 -> 12.662287 | J36: ='33'!$F$13 -> 6.682898 | K36: ='33'!$F$14 | L36: ='33'!$F$15 -> 6.2360171 | M36: ='33'!$F$16 -> 8.2336753 | N36: ='33'!$F$17 -> 9.0611184 | O36: ='33'!$F$18 -> 13.503623 | P36: ='33'!$F$19 | Q36: ='33'!$F$20 -> 9.0284371 | R36: ='33'!$F$21 | S36: ='33'!$F$22 -> 9.1874923 | T36: ='33'!$F$23 -> 13.536777 | U36: ='33'!$F$24 -> 12.6634 | V36: ='33'!$F$25 -> 35.704441 | W36: ='33'!$F$26 -> 19.512382 | X36: ='33'!$F$27 -> 9.5275866 | Y36: ='33'!$F$28 -> 8.1253463 | Z36: ='33'!$F$29 -> 6.7474025 | AA36: ='33'!$F$30 -> 9.2294536 | AB36: ='33'!$F$31 -> 6.5822207 | AC36: ='33'!$F$32 -> 6.5822102 | AD36: ='33'!$F$33 -> 8.9573771
A37: Paris | B37: ='34'!$F$5 | C37: ='34'!$F$6 -> 6.8438596 | D37: ='34'!$F$7 -> 4.4116518 | E37: ='34'!$F$8 -> 4.357372 | F37: ='34'!$F$9 | G37: ='34'!$F$10 -> 5.5845942 | H37: ='34'!$F$11 -> 4.9235552 | I37: ='34'!$F$12 -> 8.2591193 | J37: ='34'!$F$13 -> 6.3922439 | K37: ='34'!$F$14 -> 8.2585055 | L37: ='34'!$F$15 -> 4.0666074 | M37: ='34'!$F$16 -> 5.2124593 | N37: ='34'!$F$17 -> 5.0421167 | O37: ='34'!$F$18 -> 11.659048 | P37: ='34'!$F$19 | Q37: ='34'!$F$20 -> 6.7608943 | R37: ='34'!$F$21 | S37: ='34'!$F$22 -> 8.3979495 | T37: ='34'!$F$23 -> 6.6808038 | U37: ='34'!$F$24 | V37: ='34'!$F$25 -> 8.2585994 | W37: ='34'!$F$26 | X37: ='34'!$F$27 -> 5.958247 | Y37: ='34'!$F$28 -> 6.4550925 | Z37: ='34'!$F$29 -> 5.0350167 | AA37: ='34'!$F$30 -> 5.9445659 | AB37: ='34'!$F$31 -> 4.2713312 | AC37: ='34'!$F$32 -> 6.0281624 | AD37: ='34'!$F$33 -> 5.4778599
A38: Ranger | B38: ='35'!$F$5 -> 5.5042266 | C38: ='35'!$F$6 -> 4.288402 | D38: ='35'!$F$7 -> 4.2908284 | E38: ='35'!$F$8 -> 5.7470148 | F38: ='35'!$F$9 | G38: ='35'!$F$10 | H38: ='35'!$F$11 -> 3.7116888 | I38: ='35'!$F$12 | J38: ='35'!$F$13 -> 4.5205315 | K38: ='35'!$F$14 | L38: ='35'!$F$15 -> 11.86155 | M38: ='35'!$F$16 -> 5.0904863 | N38: ='35'!$F$17 -> 4.7595685 | O38: ='35'!$F$18 -> 11.216066 | P38: ='35'!$F$19 | Q38: ='35'!$F$20 -> 3.5683804 | R38: ='35'!$F$21 | S38: ='35'!$F$22 -> 4.595866 | T38: ='35'!$F$23 -> 4.92645 | U38: ='35'!$F$24 | V38: ='35'!$F$25 -> 2.8400044 | W38: ='35'!$F$26 | X38: ='35'!$F$27 -> 14.458223 | Y38: ='35'!$F$28 -> 2.6058348 | Z38: ='35'!$F$29 -> 3.2021446 | AA38: ='35'!$F$30 -> 5.0566189 | AB38: ='35'!$F$31 -> 4.5957696 | AC38: ='35'!$F$32 -> 4.5413951 | AD38: ='35'!$F$33 -> 5.1007269
A39: San Jacinto | B39: ='36'!$F$5 -> 4.5951511 | C39: ='36'!$F$6 -> 7.6513921 | D39: ='36'!$F$7 -> 7.2386345 | E39: ='36'!$F$8 -> 7.2359245 | F39: ='36'!$F$9 -> 23.312448 | G39: ='36'!$F$10 -> 7.4562139 | H39: ='36'!$F$11 -> 9.423425 | I39: ='36'!$F$12 -> 4.9824822 | J39: ='36'!$F$13 -> 9.5288752 | K39: ='36'!$F$14 -> 1305.4685 | L39: ='36'!$F$15 -> 8.0038967 | M39: ='36'!$F$16 -> 7.6614864 | N39: ='36'!$F$17 -> 7.7941974 | O39: ='36'!$F$18 -> 11.518159 | P39: ='36'!$F$19 | Q39: ='36'!$F$20 -> 10.973496 | R39: ='36'!$F$21 -> 11.626409 | S39: ='36'!$F$22 -> 11.283653 | T39: ='36'!$F$23 -> 8.0991814 | U39: ='36'!$F$24 -> 10.850504 | V39: ='36'!$F$25 -> 9.740499 | W39: ='36'!$F$26 -> 6.5026573 | X39: ='36'!$F$27 -> 8.4375081 | Y39: ='36'!$F$28 -> 9.3715154 | Z39: ='36'!$F$29 -> 7.7156204 | AA39: ='36'!$F$30 -> 9.9451672 | AB39: ='36'!$F$31 -> 8.0991811 | AC39: ='36'!$F$32 -> 7.6614853 | AD39: ='36'!$F$33 -> 8.5203562
A40: South Plains | B40: ='37'!$F$5 -> 12.932416 | C40: ='37'!$F$6 -> 9.5337086 | D40: ='37'!$F$7 -> 6.7269633 | E40: ='37'!$F$8 -> 6.0943626 | F40: ='37'!$F$9 | G40: ='37'!$F$10 -> 10.400987 | H40: ='37'!$F$11 -> 23.643843 | I40: ='37'!$F$12 -> 7.2514743 | J40: ='37'!$F$13 -> 6.4628175 | K40: ='37'!$F$14 -> 17.628085 | L40: ='37'!$F$15 -> 10.18552 | M40: ='37'!$F$16 -> 6.0704197 | N40: ='37'!$F$17 -> 7.1117507 | O40: ='37'!$F$18 -> 10.444058 | P40: ='37'!$F$19 | Q40: ='37'!$F$20 -> 13.093648 | R40: ='37'!$F$21 -> 8.0578668 | S40: ='37'!$F$22 -> 4.4671854 | T40: ='37'!$F$23 -> 6.4563734 | U40: ='37'!$F$24 -> 6.7993831 | V40: ='37'!$F$25 -> 5.9898657 | W40: ='37'!$F$26 -> 14.896114 | X40: ='37'!$F$27 -> 12.762079 | Y40: ='37'!$F$28 -> 4.6928877 | Z40: ='37'!$F$29 -> 7.537152 | AA40: ='37'!$F$30 -> 12.22181 | AB40: ='37'!$F$31 -> 6.8250084 | AC40: ='37'!$F$32 -> 13.176033 | AD40: ='37'!$F$33 -> 7.9040838
...

Sheet Discipline Analysis
A1: =Summary!A1 -> Community and Technical Colleges, Report of Fundable Operating Expenses, Fiscal Year (FY) 2012
A2: Discipline Analysis by Institution | X2: Discipline
A3: 1 | X3: Agriculture
X4: Architecture and Precision Production Trades
A5: Institution | B5: Contact Hours | C5: Total | E5: Faculty Salaries | G5: Academic Support | I5: Institutional Support | K5: Student Services | M5: Departmental Operating Expense | O5: Research | Q5: Scholarships and Fellowships | S5: Equipment Depreciation | U5: Local Benefits | X5: Biology, Physical Sciences, and Science Technology
C6: Expense | D6: per Hour | E6: Expense | F6: per Hour | G6: Expense | H6: per Hour | I6: Expense | J6: per Hour | K6: Expense | L6: per Hour | M6: Expense | N6: per Hour | O6: Expense | P6: per Hour | Q6: Expense | R6: per Hour | S6: Expense | T6: per Hour | U6: Expense | V6: per Hour | X6: Business Management, Marketing, and Administrative Services
A7: Alamo | B7: =OFFSET('1'!$D$4,$A$3,0) -> 88855 | C7: =OFFSET('1'!$E$4,$A$3,0) -> 579507.26 | D7: =IFERROR(C7/$B7,"") -> 6.5219432 | E7: =OFFSET('1'!$E$66,$A$3,0) -> 115581 | F7: =IFERROR(E7/$B7,"") -> 1.3007822 | G7: ='1'!$F$100*B7 -> 68826.942 | H7: =IFERROR(G7/$B7,"") -> 0.77459841 | I7: ='1'!$F$98*'Discipline Analysis'!B7 -> 167105.78 | J7: =IFERROR(I7/$B7,"") -> 1.880657 | K7: ='1'!$F$99*'Discipline Analysis'!B7 -> 80983.005 | L7: =IFERROR(K7/$B7,"") -> 0.91140628 | M7: =OFFSET('1'!$E$35,$A$3,0) -> 90393 | N7: =IFERROR(M7/$B7,"") -> 1.0173091 | O7: ='1'!$F$101*'Discipline Analysis'!B7 -> 0 | P7: =IFERROR(O7/$B7,"") -> 0 | Q7: ='1'!$F$102*'Discipline Analysis'!B7 -> 1134.326 | R7: =IFERROR(Q7/$B7,"") -> 0.012766034 | S7: ='1'!$F$103*'Discipline Analysis'!B7 -> 18389.218 | T7: =IFERROR(S7/$B7,"") -> 0.20695761 | U7: ='1'!$F$104*'Discipline Analysis'!B7 -> 37093.991 | V7: =IFERROR(U7/$B7,"") -> 0.41746656 | X7: Career Pilot
A8: Alvin | B8: =OFFSET('2'!$D$4,$A$3,0) -> 1152 | C8: =OFFSET('2'!$E$4,$A$3,0) -> 11915.957 | D8: =IFERROR(C8/$B8,"") -> 10.343713 | E8: =OFFSET('2'!$E$66,$A$3,0) -> 6395 | F8: =IFERROR(E8/$B8,"") -> 5.5512153 | G8: ='2'!$F$100*B8 -> 1387.9903 | H8: =IFERROR(G8/$B8,"") -> 1.2048527 | I8: ='2'!$F$98*'Discipline Analysis'!B8 -> 1572.1803 | J8: =IFERROR(I8/$B8,"") -> 1.3647398 | K8: ='2'!$F$99*'Discipline Analysis'!B8 -> 997.74475 | L8: =IFERROR(K8/$B8,"") -> 0.86609787 | M8: =OFFSET('2'!$E$35,$A$3,0) -> 1013 | N8: =IFERROR(M8/$B8,"") -> 0.87934028 | O8: ='2'!$F$101*'Discipline Analysis'!B8 -> 0 | P8: =IFERROR(O8/$B8,"") -> 0 | Q8: ='2'!$F$102*'Discipline Analysis'!B8 -> 0 | R8: =IFERROR(Q8/$B8,"") -> 0 | S8: ='2'!$F$103*'Discipline Analysis'!B8 -> 185.56074 | T8: =IFERROR(S8/$B8,"") -> 0.16107703 | U8: ='2'!$F$104*'Discipline Analysis'!B8 -> 364.48139 | V8: =IFERROR(U8/$B8,"") -> 0.31639009 | X8: Communications
A9: Amarillo | B9: =OFFSET('3'!$D$4,$A$3,0) -> 13888 | C9: =OFFSET('3'!$E$4,$A$3,0) -> 120773.95 | D9: =IFERROR(C9/$B9,"") -> 8.696281 | E9: =OFFSET('3'!$E$66,$A$3,0) -> 42588 | F9: =IFERROR(E9/$B9,"") -> 3.0665323 | G9: ='3'!$F$100*B9 -> 5744.2271 | H9: =IFERROR(G9/$B9,"") -> 0.41361082 | I9: ='3'!$F$98*'Discipline Analysis'!B9 -> 26815.348 | J9: =IFERROR(I9/$B9,"") -> 1.9308286 | K9: ='3'!$F$99*'Discipline Analysis'!B9 -> 8391.6467 | L9: =IFERROR(K9/$B9,"") -> 0.60423724 | M9: =OFFSET('3'!$E$35,$A$3,0) -> 24761 | N9: =IFERROR(M9/$B9,"") -> 1.7829061 | O9: ='3'!$F$101*'Discipline Analysis'!B9 -> 0 | P9: =IFERROR(O9/$B9,"") -> 0 | Q9: ='3'!$F$102*'Discipline Analysis'!B9 -> 0 | R9: =IFERROR(Q9/$B9,"") -> 0 | S9: ='3'!$F$103*'Discipline Analysis'!B9 -> 4602.2098 | T9: =IFERROR(S9/$B9,"") -> 0.33138031 | U9: ='3'!$F$104*'Discipline Analysis'!B9 -> 7871.518 | V9: =IFERROR(U9/$B9,"") -> 0.56678557 | X9: Computer and Information Sciences
A10: Angelina | B10: =OFFSET('4'!$D$4,$A$3,0) -> 0 | C10: =OFFSET('4'!$E$4,$A$3,0) -> 0 | D10: =IFERROR(C10/$B10,"") | E10: =OFFSET('4'!$E$66,$A$3,0) -> 0 | F10: =IFERROR(E10/$B10,"") | G10: ='4'!$F$100*B10 -> 0 | H10: =IFERROR(G10/$B10,"") | I10: ='4'!$F$98*'Discipline Analysis'!B10 -> 0 | J10: =IFERROR(I10/$B10,"") | K10: ='4'!$F$99*'Discipline Analysis'!B10 -> 0 | L10: =IFERROR(K10/$B10,"") | M10: =OFFSET('4'!$E$35,$A$3,0) -> 0 | N10: =IFERROR(M10/$B10,"") | O10: ='4'!$F$101*'Discipline Analysis'!B10 -> 0 | P10: =IFERROR(O10/$B10,"") | Q10: ='4'!$F$102*'Discipline Analysis'!B10 -> 0 | R10: =IFERROR(Q10/$B10,"") | S10: ='4'!$F$103*'Discipline Analysis'!B10 -> 0 | T10: =IFERROR(S10/$B10,"") | U10: ='4'!$F$104*'Discipline Analysis'!B10 -> 0 | V10: =IFERROR(U10/$B10,"") | X10: Construction Trades
