Workbook
Name a: #REF!
Name aaa: #REF!
Name asdf: #REF!
Name asdf: #REF!
Name asdf: #REF!
Name bnm: #REF!
Name bnm: #REF!
Name bnm: #REF!
Name Initial: #REF!
Name Initial: #REF!
Name Initial: #REF!
Name MSN_MoneyCentral_Investor_Stock_Quotes: 'Holdings Pull Sheet'!$C$9:$R$47
Name portbeg: #REF!
Name portbeg: #REF!
Name portbeg: #REF!
Name qwer: #REF!
Name qwer: #REF!
Name qwer: #REF!
Name s: #REF!
Name Sheet: #REF!
Name Sheet: #REF!
Name Sheet: #REF!
Name SP: #REF!
Name SP: #REF!
Name SP: #REF!
Name spbeg: #REF!
Name spbeg: #REF!
Name spbeg: #REF!
Name vb: #REF!
Name vb: #REF!
Name vb: #REF!
Name WINBEG: #REF!
Name WINBEG: #REF!
Name WINBEG: #REF!
Name WINSP: #REF!
Name WINSP: #REF!
Name WINSP: #REF!
Name zxc: #REF!
Name zxc: #REF!
Name zxc: #REF!

Sheet Summary
L3: School Year | S3: 1 Week | Z3: Today | AG3: IPO Return since 5/02/03 | AH3: =Holdings!$I$24/Data!$D$3 -> 2.6733485
L4: IPO | M4: =Holdings!$S$24 -> 0.18318074 | S4: IPO | T4: ='V.P. of PM'!E21 -> -0.018396275 | Z4: IPO | AA4: =Holdings!$U$24 -> -0.016800915 | AG4: S&P 500 since 5/02/03 | AH4: ='Holdings Pull Sheet'!$F$14/Data!$L$3 -> 2.0731657
L6: S&P 500 | M6: =('Holdings Pull Sheet'!$F$14/Data!$L$530)-1 -> 0.16502526 | S6: S&P 500 | T6: ='V.P. of PM'!F21 -> -0.012270234 | Z6: S&P 500 | AA6: =('Holdings Pull Sheet'!$F$14/'Holdings Pull Sheet'!$G$14)-1 -> -0.020661388 | AG6: Total IPO Portfolio Value | AH6: =Holdings!$I$24 -> 61101.652
L8: Dow Jones | M8: =('Holdings Pull Sheet'!$F$12/Data!$S$530)-1 -> 0.11526509 | S8: Dow Jones | T8: =OFFSET(Data!T3,MATCH('V.P. of PM'!H3,Data!B3:B1000,0)-1,,) -> -0.0040915924 | Z8: Dow Jones | AA8: =('Holdings Pull Sheet'!$F$12/'Holdings Pull Sheet'!$G$12)-1 -> -0.019710819 | AE8: Cash Availailable | AH8: =Holdings!$I$4 -> 8050.26
AE9: % of Portfolio | AH9: =Holdings!$W$4 -> 0.13175192
C13: =Holdings!$C$5 -> Berkshire Hathaway | F13: =Holdings!$E$5 -> 137.09 | J13: =Holdings!$C$9 -> Delta Airlines | M13: =Holdings!$E$9 -> 33.71 | Q13: =Holdings!$C$13 -> Intel | T13: =Holdings!$E$13 -> 33.62 | X13: =Holdings!$C$17 -> Range Resources | AA13: =Holdings!$E$17 -> 63.46 | AE13: =Holdings!$C$21 -> Wells Fargo | AH13: =Holdings!$E$21 -> 51.12
C15: =Holdings!$D$5 -> BRK.B | E15: Today | F15: =Holdings!$U$5 -> -0.020365871 | J15: =Holdings!$D$9 -> DAL | L15: Today | M15: =Holdings!$U$9 -> -0.031600115 | Q15: =Holdings!$D$13 -> INTC | S15: Today | T15: =Holdings!$U$13 -> -0.018967027 | X15: =Holdings!$D$17 -> RRC | Z15: Today | AA15: =Holdings!$U$17 -> -0.032636877 | AE15: =Holdings!$D$21 -> WFC | AG15: Today | AH15: =Holdings!$U$21 -> -0.019750719
E16: 1 Week | F16: =Holdings!$T$5 -> 0.062219123 | L16: 1 Week | M16: =Holdings!$T$9 -> -0.090110729 | S16: 1 Week | T16: =Holdings!$T$13 -> 0.27943797 | Z16: 1 Week | AA16: =Holdings!$T$17 -> -0.28880421 | AG16: 1 Week | AH16: =Holdings!$T$21 -> 0.038410396
E17: =L3 -> School Year | F17: =Holdings!$S$5 -> 0.2210742 | L17: =$E$17 -> School Year | M17: =Holdings!$S$9 -> 0.6757893 | S17: =$E$17 -> School Year | T17: =Holdings!$S$13 -> 0.52561959 | Z17: =$E$17 -> School Year | AA17: =Holdings!$S$17 -> -0.26524604 | AG17: =$E$17 -> School Year | AH17: =Holdings!$S$21 -> 0.24902756
E18: Total Gain | F18: =Holdings!$P$5 -> 0.75144097 | L18: Total Gain | M18: =Holdings!$P$9 -> 1.0508584 | S18: Total Gain | T18: =Holdings!$P$13 -> 0.40864565 | Z18: Total Gain | AA18: =Holdings!$P$17 -> -0.26524604 | AG18: Total Gain | AH18: =Holdings!$P$21 -> 1.2920531
C20: =IF(C21=0,"NA", IF(C21<2,"Small", IF(C21<10, "Mid", IF(C21>10, "Large")))) -> Large | E20: Value | F20: =Holdings!$I$5 -> 3564.34 | J20: =IF(J21=0,"NA", IF(J21<2,"Small", IF(J21<10, "Mid", IF(J21>10, "Large")))) -> Large | L20: Value | M20: =Holdings!$I$9 -> 5090.21 | Q20: =IF(Q21=0,"NA", IF(Q21<2,"Small", IF(Q21<10, "Mid", IF(Q21>10, "Large")))) -> Large | S20: Value | T20: =Holdings!$I$13 -> 3899.92 | X20: =IF(X21=0,"NA", IF(X21<2,"Small", IF(X21<10, "Mid", IF(X21>10, "Large")))) -> Large | Z20: Value | AA20: =Holdings!$I$17 -> 2665.32 | AE20: =IF(AE21=0,"NA", IF(AE21<2,"Small", IF(AE21<10, "Mid", IF(AE21>10, "Large")))) -> Large | AG20: Value | AH20: =Holdings!$I$21 -> 2760.48
C21: =Holdings!$X$5 -> 319.36477 | E21: Cost | F21: =Holdings!$H$5 -> 2035.09 | J21: =Holdings!$X$9 -> 28.24913 | L21: Cost | M21: =Holdings!$H$9 -> 2481.99 | Q21: =Holdings!$X$13 -> 166.45262 | S21: Cost | T21: =Holdings!$H$13 -> 2768.56 | X21: =Holdings!$X$17 -> 10.700487 | Z21: Cost | AA21: =Holdings!$H$17 -> 3627.5 | AE21: =Holdings!$X$21 -> 266.97162 | AG21: Cost | AH21: =Holdings!$H$21 -> 1204.37
E23: % of Portfolio | F23: =F20/$AH$6 -> 0.058334593 | L23: % of Portfolio | M23: =M20/$AH$6 -> 0.08330724 | S23: % of Portfolio | T23: =T20/$AH$6 -> 0.063826752 | Z23: % of Portfolio | AA23: =AA20/$AH$6 -> 0.043621079 | AG23: % of Portfolio | AH23: =AH20/$AH$6 -> 0.045178484
C27: =Holdings!$C$6 -> BlackRock Global | F27: =Holdings!$E$6 -> 20.42 | J27: =Holdings!$C$10 -> Gentex | M27: =Holdings!$E$10 -> 27.61 | Q27: =Holdings!$C$14 -> Medtronic | T27: =Holdings!$E$14 -> 63.65 | X27: =Holdings!$C$18 -> Tutor Perini | AA27: =Holdings!$E$18 -> 24.07 | AE27: =Holdings!$C$22 -> Yahoo | AH27: =Holdings!$E$22 -> 41.1
C29: =Holdings!$D$6 -> MCLOX | E29: Today | F29: =Holdings!$U$6 -> -0.013561025 | J29: =Holdings!$D$10 -> GNTX | L29: Today | M29: =Holdings!$U$10 -> -0.024036762 | Q29: =Holdings!$D$14 -> MDT | S29: Today | T29: =Holdings!$U$14 -> -0.031644607 | X29: =Holdings!$D$18 -> TPC | Z29: Today | AA29: =Holdings!$U$18 -> -0.026688233 | AE29: =Holdings!$D$22 -> YHOO | AG29: Today | AH29: =Holdings!$U$22 -> 0.00048685492
E30: 1 Week | F30: =Holdings!$T$6 -> 0.029847908 | L30: 1 Week | M30: =Holdings!$T$10 -> -0.044735959 | S30: 1 Week | T30: =Holdings!$T$14 -> 0.082527699 | Z30: 1 Week | AA30: =Holdings!$T$18 -> -0.1982012 | AG30: 1 Week | AH30: =Holdings!$T$22 -> 0.12571898
E31: =$E$17 -> School Year | F31: =Holdings!$S$6 -> 0.10967687 | L31: =$E$17 -> School Year | M31: =Holdings!$S$10 -> 0.15972247 | S31: =$E$17 -> School Year | T31: =Holdings!$S$14 -> 0.20613582 | Z31: =$E$17 -> School Year | AA31: =Holdings!$S$18 -> 0.2885439 | AG31: =$E$17 -> School Year | AH31: =Holdings!$S$22 -> 0.45589798
E32: Total Gain | F32: =Holdings!$P$6 -> 0.25222698 | L32: Total Gain | M32: =Holdings!$P$10 -> 0.74589809 | S32: Total Gain | T32: =Holdings!$P$14 -> 0.38711665 | Z32: Total Gain | AA32: =Holdings!$P$18 -> 0.74912072 | AG32: Total Gain | AH32: =Holdings!$P$22 -> 0.88966386
C34: =IF(C35=0,"NA", IF(C35<2,"Small", IF(C35<10, "Mid", IF(C35>10, "Large")))) -> NA | E34: Value | F34: =Holdings!$I$6 -> 1932.7122 | J34: =IF(J35=0,"NA", IF(J35<2,"Small", IF(J35<10, "Mid", IF(J35>10, "Large")))) -> Mid | L34: Value | M34: =Holdings!$I$10 -> 2622.95 | Q34: =IF(Q35=0,"NA", IF(Q35<2,"Small", IF(Q35<10, "Mid", IF(Q35>10, "Large")))) -> Large | S34: Value | T34: =Holdings!$I$14 -> 1845.85 | X34: =IF(X35=0,"NA", IF(X35<2,"Small", IF(X35<10, "Mid", IF(X35>10, "Large")))) -> Small | Z34: Value | AA34: =Holdings!$I$18 -> 4814 | AE34: =IF(AE35=0,"NA", IF(AE35<2,"Small", IF(AE35<10, "Mid", IF(AE35>10, "Large")))) -> Large | AG34: Value | AH34: =Holdings!$I$22 -> 4110
C35: =Holdings!$X$6 -> 0 | E35: Cost | F35: =Holdings!$H$6 -> 1543.42 | J35: =Holdings!$X$10 -> 4.0367771 | L35: Cost | M35: =Holdings!$H$10 -> 1502.35 | Q35: =Holdings!$X$14 -> 62.356015 | S35: Cost | T35: =Holdings!$H$14 -> 1330.71 | X35: =Holdings!$X$18 -> 1.1691218 | Z35: Cost | AA35: =Holdings!$H$18 -> 2752.24 | AE35: =Holdings!$X$22 -> 40.878216 | AG35: Cost | AH35: =Holdings!$H$22 -> 2174.99
E37: % of Portfolio | F37: =F34/$AH$6 -> 0.031631095 | L37: % of Portfolio | M37: =M34/$AH$6 -> 0.042927644 | S37: % of Portfolio | T37: =T34/$AH$6 -> 0.030209494 | Z37: % of Portfolio | AA37: =AA34/$AH$6 -> 0.07878674 | AG37: % of Portfolio | AH37: =AH34/$AH$6 -> 0.067264957
C41: =Holdings!$C$7 -> Cemex | F41: =Holdings!$E$7 -> 12.2 | J41: =Holdings!$C$11 -> Home Depot | M41: =Holdings!$E$11 -> 93.07 | Q41: =Holdings!$C$15 -> Natural Grocers | T41: =Holdings!$E$15 -> 16.19 | X41: =Holdings!$C$19 -> Tyson Foods | AA41: =Holdings!$E$19 -> 40.96
C43: =Holdings!$D$7 -> CX | E43: Today | F43: =Holdings!$U$7 -> -0.026336792 | J43: =Holdings!$D$11 -> HD | L43: Today | M43: =Holdings!$U$11 -> -0.010840684 | Q43: =Holdings!$D$15 -> NGVC | S43: Today | T43: =Holdings!$U$15 -> -0.040876777 | X43: =Holdings!$D$19 -> TSN | Z43: Today | AA43: =Holdings!$U$19 -> -0.013487476
E44: 1 Week | F44: =Holdings!$T$7 -> -0.0079749805 | L44: 1 Week | M44: =Holdings!$T$11 -> 0.18731205 | S44: 1 Week | T44: =Holdings!$T$15 -> -0.55643836 | Z44: 1 Week | AA44: =Holdings!$T$19 -> -0.02999621
E45: =$E$17 -> School Year | F45: =Holdings!$S$7 -> 0.14409378 | L45: =$E$17 -> School Year | M45: =Holdings!$S$11 -> 0.30319975 | S45: =$E$17 -> School Year | T45: =Holdings!$S$15 -> -0.56243243 | Z45: =$E$17 -> School Year | AA45: =Holdings!$S$19 -> 0.38094724
E46: Total Gain | F46: =Holdings!$P$7 -> 0.13363449 | L46: Total Gain | M46: =Holdings!$P$11 -> 2.4021094 | S46: Total Gain | T46: =Holdings!$P$15 -> -0.17493375 | Z46: Total Gain | AA46: =Holdings!$P$19 -> 1.4943551
C48: =IF(C49=0,"NA", IF(C49<2,"Small", IF(C49<10, "Mid", IF(C49>10, "Large")))) -> Large | E48: Value | F48: =Holdings!$I$7 -> 3172 | J48: =IF(J49=0,"NA", IF(J49<2,"Small", IF(J49<10, "Mid", IF(J49>10, "Large")))) -> Large | L48: Value | M48: =Holdings!$I$11 -> 5677.27 | Q48: =IF(Q49=0,"NA", IF(Q49<2,"Small", IF(Q49<10, "Mid", IF(Q49>10, "Large")))) -> Small | S48: Value | T48: =Holdings!$I$15 -> 1214.25 | X48: =IF(X49=0,"NA", IF(X49<2,"Small", IF(X49<10, "Mid", IF(X49>10, "Large")))) -> Large | Z48: Value | AA48: =Holdings!$I$19 -> 4177.92
C49: =Holdings!$X$7 -> 14.494177 | E49: Cost | F49: =Holdings!$H$7 -> 2798.08 | J49: =Holdings!$X$11 -> 125.26492 | L49: Cost | M49: =Holdings!$H$11 -> 1668.75 | Q49: =Holdings!$X$15 -> 0.36391769 | S49: Cost | T49: =Holdings!$H$15 -> 1471.7 | X49: =Holdings!$X$19 -> 14.405563 | Z49: Cost | AA49: =Holdings!$H$19 -> 1674.95
E51: % of Portfolio | F51: =F48/$AH$6 -> 0.05191349 | L51: % of Portfolio | M51: =M48/$AH$6 -> 0.092915163 | S51: % of Portfolio | T51: =T48/$AH$6 -> 0.019872621 | Z51: % of Portfolio | AA51: =AA48/$AH$6 -> 0.068376547
C55: =Holdings!$C$8 -> Cisco | F55: =Holdings!$E$8 -> 24.19 | J55: =Holdings!$C$12 -> Immersion | M55: =Holdings!$E$12 -> 7.91 | Q55: =Holdings!$C$16 -> Perrigo | T55: =Holdings!$E$16 -> 152.39
C57: =Holdings!$D$8 -> CSCO | E57: Today | F57: =Holdings!$U$8 -> -0.019059205 | J57: =Holdings!$D$12 -> IMMR | L57: Today | M57: =Holdings!$U$12 -> -0.035365854 | Q57: =Holdings!$D$16 -> PRGO | S57: Today | T57: =Holdings!$U$16 -> 0.0063395628
E58: 1 Week | F58: =Holdings!$T$8 -> 0.057992748 | L58: 1 Week | M58: =Holdings!$T$12 -> -0.26623377 | S58: 1 Week | T58: =Holdings!$T$16 -> 0.043044692
E59: =$E$17 -> School Year | F59: =Holdings!$S$8 -> 0.043267944 | L59: =$E$17 -> School Year | M59: =Holdings!$S$12 -> -0.40926064 | S59: =$E$17 -> School Year | T59: =Holdings!$S$16 -> 0.24323883
E60: Total Gain | F60: =Holdings!$P$8 -> 0.35669132 | L60: Total Gain | M60: =Holdings!$P$12 -> -0.47430217 | S60: Total Gain | T60: =Holdings!$P$16 -> 0.24323883
C62: =IF(C63=0,"NA", IF(C63<2,"Small", IF(C63<10, "Mid", IF(C63>10, "Large")))) -> Large | E62: Value | F62: =Holdings!$I$8 -> 1693.3 | J62: =IF(J63=0,"NA", IF(J63<2,"Small", IF(J63<10, "Mid", IF(J63>10, "Large")))) -> Small | L62: Value | M62: =Holdings!$I$12 -> 1067.85 | Q62: =IF(Q63=0,"NA", IF(Q63<2,"Small", IF(Q63<10, "Mid", IF(Q63>10, "Large")))) -> Large | S62: Value | T62: =Holdings!$I$16 -> 2743.02
C63: =Holdings!$X$8 -> 123.34972 | E63: Cost | F63: =Holdings!$H$8 -> 1248.11 | J63: =Holdings!$X$12 -> 0.22590436 | L63: Cost | M63: =Holdings!$H$12 -> 2031.3 | Q63: =Holdings!$X$16 -> 20.392487 | S63: Cost | T63: =Holdings!$H$16 -> 2206.35
E65: % of Portfolio | F65: =F62/$AH$6 -> 0.027712835 | L65: % of Portfolio | M65: =M62/$AH$6 -> 0.017476614 | S65: % of Portfolio | T65: =T62/$AH$6 -> 0.04489273
C69: Bought This Year | Q69: Sold This Year
F71: Date Bought | J71: Buy Price* | L71: Current Price | M71: Change** | T71: Date Sold | X71: Sell Price* | Z71: Current Price | AA71: Change**
D72: =Holdings!C28 -> Tyson Foods | F72: =Holdings!E28 -> 41530 | J72: =Holdings!H28 -> 16.89 | L72: =Holdings!I28 -> 40.96 | M72: =L72/J72-1 -> 1.4251036 | R72: =Holdings!C34 -> Caterpillar | T72: =Holdings!E34 -> 41551 | X72: =Holdings!H34 -> 83.94 | Y72: 19.71 | Z72: =Holdings!I34 -> 93.5 | AA72: =IFERROR((Z72/X72)-1,"NA") -> 0.11389087
...

Sheet Sortable Performnce
C3: 2013 Fall Semester Portfolio Performance
C4: Name | D4: Ticker | E4: Value | F4: % of Port | G4: Today | I4: 1 Week | J4: 2013-2014 School Year | K4: Summer 2013 | L4: Since 4/25/13 | M4: 2012-2013 School Year | N4: Since 9/6/12
C5: =Holdings!#REF! -> #REF! | D5: =IF(Holdings!#REF!=0,"NA",Holdings!#REF!) -> #REF! | E5: =Holdings!#REF! -> #REF! | F5: =Holdings!#REF! -> #REF! | G5: =Holdings!#REF! -> #REF! | H5: =(F5*G5) -> #REF! | I5: =Holdings!#REF! -> #REF! | J5: =Holdings!#REF! -> #REF! | K5: =Holdings!#REF! -> #REF! | L5: =($E5/Holdings!#REF!)-1 -> #REF! | M5: =Holdings!#REF! -> #REF! | N5: =($E5/Holdings!#REF!)-1 -> #REF!
C6: =Holdings!C9 -> Delta Airlines | D6: =IF(Holdings!D9=0,"NA",Holdings!D9) -> DAL | E6: =Holdings!I9 -> 5090.21 | F6: =Holdings!W9 -> 0.08330724 | G6: =Holdings!U9 -> -0.031600115 | H6: =(F6*G6) -> -0.0026325184 | I6: =Holdings!T9 -> -0.090110729 | J6: =Holdings!S9 -> 0.6757893 | K6: =Holdings!R9 -> 0.24309392 | L6: =($E6/Holdings!L9)-1 -> 1.0831635 | M6: =Holdings!Q9 -> -0.015507718 | N6: =($E6/Holdings!K9)-1 -> 1.0508584
C7: =Holdings!C21 -> Wells Fargo | D7: =IF(Holdings!D22=0,"NA",Holdings!D22) -> YHOO | E7: =Holdings!I21 -> 2760.48 | F7: =Holdings!W21 -> 0.045178484 | G7: =Holdings!U21 -> -0.019750719 | H7: =(F7*G7) -> -0.00089230754 | I7: =Holdings!T21 -> 0.038410396 | J7: =Holdings!S21 -> 0.24902756 | K7: =Holdings!R21 -> 0.1265926 | L7: =($E7/Holdings!L21)-1 -> 0.40714521 | M7: =Holdings!Q21 -> 0.10318505 | N7: =($E7/Holdings!K21)-1 -> 0.55234155
C8: =Holdings!C17 -> Range Resources | D8: =IF(Holdings!D18=0,"NA",Holdings!D18) -> TPC | E8: =Holdings!I17 -> 2665.32 | F8: =Holdings!W17 -> 0.043621079 | G8: =Holdings!U17 -> -0.032636877 | H8: =(F8*G8) -> -0.0014236558 | I8: =Holdings!T17 -> -0.28880421 | J8: =Holdings!S17 -> -0.26524604 | K8: =Holdings!R17 -> -0.24713715 | L8: =($E8/Holdings!L17)-1 -> -0.26524604 | M8: =Holdings!Q17 -> 0 | N8: =(($E8/Holdings!K17)-1)*(2/3) -> -0.17683069
C9: =Holdings!C16 -> Perrigo | D9: =IF(Holdings!D16=0,"NA",Holdings!D16) -> PRGO | E9: =Holdings!I16 -> 2743.02 | F9: =Holdings!W16 -> 0.04489273 | G9: =Holdings!U16 -> 0.0063395628 | H9: =(F9*G9) -> 0.00028460029 | I9: =Holdings!T16 -> 0.043044692 | J9: =Holdings!S16 -> 0.24323883 | K9: =Holdings!R16 -> 0 | L9: =($E9/Holdings!L16)-1 -> 0.24323883 | M9: =Holdings!Q16 -> 0 | N9: =($E9/Holdings!K16)-1 -> 0.24323883
C10: =Holdings!C10 -> Gentex | D10: =IF(Holdings!D10=0,"NA",Holdings!D10) -> GNTX | E10: =Holdings!I10 -> 2622.95 | F10: =Holdings!W10 -> 0.042927644 | G10: =Holdings!U10 -> -0.024036762 | H10: =(F10*G10) -> -0.0010318416 | I10: =Holdings!T10 -> -0.044735959 | J10: =Holdings!S10 -> 0.15972247 | K10: =Holdings!R10 -> 0.075185858 | L10: =($E10/Holdings!L10)-1 -> 0.2469172 | M10: =Holdings!Q10 -> 0.2598419 | N10: =($E10/Holdings!K10)-1 -> 0.57091853
C11: =Holdings!C18 -> Tutor Perini | D11: =IF(Holdings!D19=0,"NA",Holdings!D19) -> TSN | E11: =Holdings!I18 -> 4814 | F11: =Holdings!W18 -> 0.07878674 | G11: =Holdings!U18 -> -0.026688233 | H11: =(F11*G11) -> -0.0021026789 | I11: =Holdings!T18 -> -0.1982012 | J11: =Holdings!S18 -> 0.2885439 | K11: =Holdings!R18 -> 0.50130601 | L11: =($E11/Holdings!L18)-1 -> 0.93449869 | M11: =Holdings!Q18 -> 0.32758943 | N11: =($E11/Holdings!K18)-1 -> 1.56822
C12: =Holdings!C11 -> Home Depot | D12: =IF(Holdings!D11=0,"NA",Holdings!D11) -> HD | E12: =Holdings!I11 -> 5677.27 | F12: =Holdings!W11 -> 0.092915163 | G12: =Holdings!U11 -> -0.010840684 | H12: =(F12*G12) -> -0.001007264 | I12: =Holdings!T11 -> 0.18731205 | J12: =Holdings!S11 -> 0.30319975 | K12: =Holdings!R11 -> 0.0056889862 | L12: =($E12/Holdings!L11)-1 -> 0.31061363 | M12: =Holdings!Q11 -> 0.28488899 | N12: =($E12/Holdings!K11)-1 -> 0.68399302
C13: =Holdings!C13 -> Intel | D13: =IF(Holdings!D13=0,"NA",Holdings!D13) -> INTC | E13: =Holdings!I13 -> 3899.92 | F13: =Holdings!W13 -> 0.063826752 | G13: =Holdings!U13 -> -0.018967027 | H13: =(F13*G13) -> -0.0012106037 | I13: =Holdings!T13 -> 0.27943797 | J13: =Holdings!S13 -> 0.52561959 | K13: =Holdings!R13 -> -0.076673072 | L13: =($E13/Holdings!L13)-1 -> 0.40864565 | M13: =Holdings!Q13 -> 0 | N13: =($E13/Holdings!K13)-1 -> 0.40864565
C14: =Holdings!C19 -> Tyson Foods | D14: =IF(Holdings!D20=0,"NA",Holdings!D20) -> NA | E14: =Holdings!I19 -> 4177.92 | F14: =Holdings!W19 -> 0.068376547 | G14: =Holdings!U19 -> -0.013487476 | H14: =(F14*G14) -> -0.00092222703 | I14: =Holdings!T19 -> -0.02999621 | J14: =Holdings!S19 -> 0.38094724 | K14: =Holdings!R19 -> 0.20431557 | L14: =($E14/Holdings!L19)-1 -> 0.66309626 | M14: =Holdings!Q19 -> 0.50878895 | N14: =($E14/Holdings!K19)-1 -> 1.5092613
C15: =Holdings!C14 -> Medtronic | D15: =IF(Holdings!D14=0,"NA",Holdings!D14) -> MDT | E15: =Holdings!I14 -> 1845.85 | F15: =Holdings!W14 -> 0.030209494 | G15: =Holdings!U14 -> -0.031644607 | H15: =(F15*G15) -> -0.00095596756 | I15: =Holdings!T14 -> 0.082527699 | J15: =Holdings!S14 -> 0.20613582 | K15: =Holdings!R14 -> 0.15314413 | L15: =($E15/Holdings!L14)-1 -> 0.39084844 | M15: =Holdings!Q14 -> 0.14552407 | N15: =($E15/Holdings!K14)-1 -> 0.59325037
C16: =Holdings!C6 -> BlackRock Global | D16: =IF(Holdings!D6=0,"NA",Holdings!D6) -> MCLOX | E16: =Holdings!I6 -> 1932.7122 | F16: =Holdings!W6 -> 0.031631095 | G16: =Holdings!U6 -> -0.013561025 | H16: =(F16*G16) -> -0.00042895006 | I16: =Holdings!T6 -> 0.029847908 | J16: =Holdings!S6 -> 0.10967687 | K16: =Holdings!R6 -> 0.0038438462 | L16: =($E16/Holdings!L6)-1 -> 0.11394229 | M16: =Holdings!Q6 -> 0.083002976 | N16: =($E16/Holdings!K6)-1 -> 0.20640282
C17: =Holdings!C20 -> 0 | D17: =IF(Holdings!D21=0,"NA",Holdings!D21) -> WFC | E17: =Holdings!I20 -> 0 | F17: =Holdings!W20 -> 0 | G17: =Holdings!U20 -> 0 | H17: =(F17*G17) -> 0 | I17: =Holdings!T20 -> 0 | J17: =Holdings!S20 -> 0 | K17: =Holdings!R20 -> 0 | L17: =($E17/Holdings!L20)-1 -> #DIV/0! | M17: =Holdings!Q20 -> 0 | N17: =($E17/Holdings!K20)-1 -> #DIV/0!
C18: =Holdings!C15 -> Natural Grocers | D18: =IF(Holdings!D15=0,"NA",Holdings!D15) -> NGVC | E18: =Holdings!I15 -> 1214.25 | F18: =Holdings!W15 -> 0.019872621 | G18: =Holdings!U15 -> -0.040876777 | H18: =(F18*G18) -> -0.00081232872 | I18: =Holdings!T15 -> -0.55643836 | J18: =Holdings!S15 -> -0.56243243 | K18: =Holdings!R15 -> 0.48773623 | L18: =($E18/Holdings!L15)-1 -> -0.34901488 | M18: =Holdings!Q15 -> 0.26741184 | N18: =($E18/Holdings!K15)-1 -> -0.17493375
C19: =Holdings!C5 -> Berkshire Hathaway | D19: =IF(Holdings!D5=0,"NA",Holdings!D5) -> BRK.B | E19: =Holdings!I5 -> 3564.34 | F19: =Holdings!W5 -> 0.058334593 | G19: =Holdings!U5 -> -0.020365871 | H19: =(F19*G19) -> -0.0011880348 | I19: =Holdings!T5 -> 0.062219123 | J19: =Holdings!S5 -> 0.2210742 | K19: =Holdings!R5 -> 0.044663627 | L19: =($E19/Holdings!L5)-1 -> 0.2756118 | M19: =Holdings!Q5 -> 0.24285878 | N19: =($E19/Holdings!K5)-1 -> 0.58540532
C20: =Holdings!C7 -> Cemex | D20: =IF(Holdings!D7=0,"NA",Holdings!D7) -> CX | E20: =Holdings!I7 -> 3172 | F20: =Holdings!W7 -> 0.05191349 | G20: =Holdings!U7 -> -0.026336792 | H20: =(F20*G20) -> -0.0013672348 | I20: =Holdings!T7 -> -0.0079749805 | J20: =Holdings!S7 -> 0.14409378 | K20: =Holdings!R7 -> -0.0091419831 | L20: =($E20/Holdings!L7)-1 -> 0.13363449 | M20: =Holdings!Q7 -> 0 | N20: =($E20/Holdings!K7)-1 -> 0.13363449
C21: =Holdings!C8 -> Cisco | D21: =IF(Holdings!D8=0,"NA",Holdings!D8) -> CSCO | E21: =Holdings!I8 -> 1693.3 | F21: =Holdings!W8 -> 0.027712835 | G21: =Holdings!U8 -> -0.019059205 | H21: =(F21*G21) -> -0.00052818461 | I21: =Holdings!T8 -> 0.057992748 | J21: =Holdings!S8 -> 0.043267944 | K21: =Holdings!R8 -> 0.16496187 | L21: =($E21/Holdings!L8)-1 -> 0.21536738 | M21: =Holdings!Q8 -> 0.062202357 | N21: =($E21/Holdings!K8)-1 -> 0.29096609
C22: =Holdings!C12 -> Immersion | D22: =IF(Holdings!D12=0,"NA",Holdings!D12) -> IMMR | E22: =Holdings!I12 -> 1067.85 | F22: =Holdings!W12 -> 0.017476614 | G22: =Holdings!U12 -> -0.035365854 | H22: =(F22*G22) -> -0.00061807538 | I22: =Holdings!T12 -> -0.26623377 | J22: =Holdings!S12 -> -0.40926064 | K22: =Holdings!R12 -> -0.11010191 | L22: =($E22/Holdings!L12)-1 -> -0.47430217 | M22: =Holdings!Q12 -> 0 | N22: =($E22/Holdings!K12)-1 -> -0.47430217
C23: !Cash | D23: =IF(Holdings!D4=0,"NA",Holdings!D4) -> NA | E23: =Holdings!I4 -> 8050.26 | F23: =Holdings!W4 -> 0.13175192 | G23: 0 | H23: =(F23*G23) -> 0
E24: =SUM(E5:E23) -> #REF! | H24: =SUM(H5:H22) -> #REF!

Sheet Long Term Chart

Sheet Holdings
C3: Name | D3: Ticker | E3: Price | F3: Paid | G3: Shares | H3: Initial Cost | I3: Value | J3: Value 1 Week Ago | K3: Value on 9/6/12 | L3: Value on 4/25/13 | M3: Value on 9/5/13 | O3: Total Gain $ | P3: Total Gain | Q3: 2012-2013 School Year | R3: 2013 Summer | S3: 2013-2014 School Year | T3: 1 Week | U3: Today | V3: Sector | W3: Portfolio Weight | X3: Market Cap (Billions) | Z3: PE | AA3: EPS | AE3: % of Weekly Portfolio Return | AF3: % of Daily Portfolio Return
C4: Cash | E4: 1 | F4: 1 | G4: 8050.26 | H4: 0 | I4: =E4*G4 -> 8050.26 | J4: 5786.22 | K4: 4804 | L4: 4361.76 | M4: 7658.58 | V4: Cash | W4: =I4/$I$24 -> 0.13175192 | X4: 0 | Y4: Cash | Z4: 0 | AA4: 0 | AE4: 0 | AF4: =(0.01/365)*W4 -> 3.6096416e-06
C5: Berkshire Hathaway | D5: ='Holdings Pull Sheet'!B16 -> BRK.B | E5: 137.09 | F5: 77.89 | G5: 26 | H5: 2035.09 | I5: =E5*G5 -> 3564.34 | J5: 3355.56 | K5: 2248.22 | L5: 2794.22 | M5: 2919.02 | O5: =I5-H5 -> 1529.25 | P5: =(I5/H5)-1 -> 0.75144097 | Q5: =(L5/K5)-1 -> 0.24285878 | R5: =(M5/L5)-1 -> 0.044663627 | S5: =(I5/M5)-1 -> 0.2210742 | T5: =(I5/J5)-1 -> 0.062219123 | U5: =('Holdings Pull Sheet'!F16/'Holdings Pull Sheet'!G16)-1 -> -0.020365871 | V5: Financial | W5: =I5/$I$24 -> 0.058334593 | X5: ='Holdings Pull Sheet'!O16/1000000000 -> 319.36477 | Y5: =IF(X5<2,"Small", IF(X5<10, "Mid", IF(X5>10, "Large"))) -> Large | Z5: ='Holdings Pull Sheet'!Q16 -> 15.19 | AA5: ='Holdings Pull Sheet'!P16 -> 9 | AE5: =W5*T5 -> 0.0036295272 | AF5: =W5*U5 -> -0.0011880348
C6: BlackRock Global | D6: ='Holdings Pull Sheet'!B17 -> MCLOX | E6: 20.42 | F6: 17.23 | G6: 94.648 | H6: 1543.42 | I6: =E6*G6 -> 1932.7122 | J6: 1876.6967 | K6: 1602.0455 | L6: 1735.02 | M6: 1741.6891 | O6: =I6-H6 -> 389.29216 | P6: =(I6/H6)-1 -> 0.25222698 | Q6: =(L6/K6)-1 -> 0.083002976 | R6: =(M6/L6)-1 -> 0.0038438462 | S6: =(I6/M6)-1 -> 0.10967687 | T6: =(I6/J6)-1 -> 0.029847908 | U6: =('Holdings Pull Sheet'!F17/'Holdings Pull Sheet'!G17)-1 -> -0.013561025 | V6: Misc | W6: =I6/$I$24 -> 0.031631095 | X6: ='Holdings Pull Sheet'!O17/1000000000 -> 0 | Y6: Bond | Z6: ='Holdings Pull Sheet'!Q17 -> 0 | AA6: ='Holdings Pull Sheet'!P17 -> 0 | AE6: =W6*T6 -> 0.00094412201 | AF6: =W6*U6 -> -0.00042895006
C7: Cemex | D7: ='Holdings Pull Sheet'!B18 -> CX | E7: 12.2 | F7: 11.15 | G7: 260 | H7: 2798.08 | I7: =E7*G7 -> 3172 | J7: 3197.5 | K7: 2798.08 | L7: 2798.08 | M7: 2772.5 | O7: =I7-H7 -> 373.92 | P7: =(I7/H7)-1 -> 0.13363449 | Q7: =(L7/K7)-1 -> 0 | R7: =(M7/L7)-1 -> -0.0091419831 | S7: =(I7/M7)-1 -> 0.14409378 | T7: =(I7/J7)-1 -> -0.0079749805 | U7: =('Holdings Pull Sheet'!F18/'Holdings Pull Sheet'!G18)-1 -> -0.026336792 | V7: Industrials | W7: =I7/$I$24 -> 0.05191349 | X7: ='Holdings Pull Sheet'!O18/1000000000 -> 14.494177 | Y7: =IF(X7<2,"Small", IF(X7<10, "Mid", IF(X7>10, "Large"))) -> Large | Z7: ='Holdings Pull Sheet'!Q18 -> -25.33 | AA7: ='Holdings Pull Sheet'!P18 -> -6.46 | AE7: =W7*T7 -> -0.00041400907 | AF7: =W7*U7 -> -0.0013672348
C8: Cisco | D8: ='Holdings Pull Sheet'!B19 -> CSCO | E8: 24.19 | F8: 18.67 | G8: 70 | H8: 1248.11 | I8: =E8*G8 -> 1693.3 | J8: 1600.4836 | K8: 1311.6534 | L8: 1393.2413 | M8: 1623.073 | O8: =I8-H8 -> 445.19 | P8: =(I8/H8)-1 -> 0.35669132 | Q8: =(L8/K8)-1 -> 0.062202357 | R8: =(M8/L8)-1 -> 0.16496187 | S8: =(I8/M8)-1 -> 0.043267944 | T8: =(I8/J8)-1 -> 0.057992748 | U8: =('Holdings Pull Sheet'!F19/'Holdings Pull Sheet'!G19)-1 -> -0.019059205 | V8: Information Technology | W8: =I8/$I$24 -> 0.027712835 | X8: ='Holdings Pull Sheet'!O19/1000000000 -> 123.34972 | Y8: =IF(X8<2,"Small", IF(X8<10, "Mid", IF(X8>10, "Large"))) -> Large | Z8: ='Holdings Pull Sheet'!Q19 -> 16.27 | AA8: ='Holdings Pull Sheet'!P19 -> 1.49 | AE8: =W8*T8 -> 0.0016071435 | AF8: =W8*U8 -> -0.00052818461
C9: Delta Airlines | D9: ='Holdings Pull Sheet'!B20 -> DAL | E9: 33.71 | F9: 16.58 | G9: 151 | H9: 2481.99 | I9: =E9*G9 -> 5090.21 | J9: 5594.3181 | K9: 2481.99 | L9: 2443.5 | M9: 3037.5 | O9: =I9-H9 -> 2608.22 | P9: =(I9/H9)-1 -> 1.0508584 | Q9: =(L9/K9)-1 -> -0.015507718 | R9: =(M9/L9)-1 -> 0.24309392 | S9: =(I9/M9)-1 -> 0.6757893 | T9: =(I9/J9)-1 -> -0.090110729 | U9: =('Holdings Pull Sheet'!F20/'Holdings Pull Sheet'!G20)-1 -> -0.031600115 | V9: Consumer Discretionary | W9: =I9/$I$24 -> 0.08330724 | X9: ='Holdings Pull Sheet'!O20/1000000000 -> 28.24913 | Y9: =IF(X9<2,"Small", IF(X9<10, "Mid", IF(X9>10, "Large"))) -> Large | Z9: ='Holdings Pull Sheet'!Q20 -> 2.64 | AA9: ='Holdings Pull Sheet'!P20 -> 12.69 | AE9: =W9*T9 -> -0.0075068761 | AF9: =W9*U9 -> -0.0026325184
C10: Gentex | D10: ='Holdings Pull Sheet'!B21 -> GNTX | E10: 27.61 | F10: 17.06 | G10: 95 | H10: 1502.35 | I10: =E10*G10 -> 2622.95 | J10: 2745.7853 | K10: 1669.6919 | L10: 2103.5478 | M10: 2261.7049 | O10: =I10-H10 -> 1120.6 | P10: =(I10/H10)-1 -> 0.74589809 | Q10: =(L10/K10)-1 -> 0.2598419 | R10: =(M10/L10)-1 -> 0.075185858 | S10: =(I10/M10)-1 -> 0.15972247 | T10: =(I10/J10)-1 -> -0.044735959 | U10: =('Holdings Pull Sheet'!F21/'Holdings Pull Sheet'!G21)-1 -> -0.024036762 | V10: Consumer Discretionary | W10: =I10/$I$24 -> 0.042927644 | X10: ='Holdings Pull Sheet'!O21/1000000000 -> 4.0367771 | Y10: =IF(X10<2,"Small", IF(X10<10, "Mid", IF(X10>10, "Large"))) -> Mid | Z10: ='Holdings Pull Sheet'!Q21 -> 14.87 | AA10: ='Holdings Pull Sheet'!P21 -> 1.86 | AE10: =W10*T10 -> -0.0019204093 | AF10: =W10*U10 -> -0.0010318416
C11: Home Depot | D11: ='Holdings Pull Sheet'!B22 -> HD | E11: 93.07 | F11: 31.22 | G11: 61 | H11: 1668.75 | I11: =E11*G11 -> 5677.27 | J11: 4781.6157 | K11: 3371.3144 | L11: 4331.7648 | M11: 4356.4082 | O11: =I11-H11 -> 4008.52 | P11: =(I11/H11)-1 -> 2.4021094 | Q11: =(L11/K11)-1 -> 0.28488899 | R11: =(M11/L11)-1 -> 0.0056889862 | S11: =(I11/M11)-1 -> 0.30319975 | T11: =(I11/J11)-1 -> 0.18731205 | U11: =('Holdings Pull Sheet'!F22/'Holdings Pull Sheet'!G22)-1 -> -0.010840684 | V11: Consumer Discretionary | W11: =I11/$I$24 -> 0.092915163 | X11: ='Holdings Pull Sheet'!O22/1000000000 -> 125.26492 | Y11: =IF(X11<2,"Small", IF(X11<10, "Mid", IF(X11>10, "Large"))) -> Large | Z11: ='Holdings Pull Sheet'!Q22 -> 22.26 | AA11: ='Holdings Pull Sheet'!P22 -> 4.18 | AE11: =W11*T11 -> 0.01740413 | AF11: =W11*U11 -> -0.001007264
C12: Immersion | D12: ='Holdings Pull Sheet'!B23 -> IMMR | E12: 7.91 | F12: 15.05 | G12: 135 | H12: 2031.3 | I12: =E12*G12 -> 1067.85 | J12: 1455.3 | K12: 2031.3 | L12: 2031.3 | M12: 1807.65 | O12: =I12-H12 -> -963.45 | P12: =(I12/H12)-1 -> -0.47430217 | Q12: =(L12/K12)-1 -> 0 | R12: =(M12/L12)-1 -> -0.11010191 | S12: =(I12/M12)-1 -> -0.40926064 | T12: =(I12/J12)-1 -> -0.26623377 | U12: =('Holdings Pull Sheet'!F23/'Holdings Pull Sheet'!G23)-1 -> -0.035365854 | V12: Information Technology | W12: =I12/$I$24 -> 0.017476614 | X12: ='Holdings Pull Sheet'!O23/1000000000 -> 0.22590436 | Y12: =IF(X12<2,"Small", IF(X12<10, "Mid", IF(X12>10, "Large"))) -> Small | Z12: ='Holdings Pull Sheet'!Q23 -> 5.84 | AA12: ='Holdings Pull Sheet'!P23 -> 1.35 | AE12: =W12*T12 -> -0.0046528648 | AF12: =W12*U12 -> -0.00061807538
C13: Intel | D13: ='Holdings Pull Sheet'!B24 -> INTC | E13: 33.62 | F13: 24.77 | G13: 116 | H13: 2768.56 | I13: =E13*G13 -> 3899.92 | J13: 3048.1509 | K13: 2768.56 | L13: 2768.56 | M13: 2556.286 | O13: =I13-H13 -> 1131.36 | P13: =(I13/H13)-1 -> 0.40864565 | Q13: =(L13/K13)-1 -> 0 | R13: =(M13/L13)-1 -> -0.076673072 | S13: =(I13/M13)-1 -> 0.52561959 | T13: =(I13/J13)-1 -> 0.27943797 | U13: =('Holdings Pull Sheet'!F24/'Holdings Pull Sheet'!G24)-1 -> -0.018967027 | V13: Information Technology | W13: =I13/$I$24 -> 0.063826752 | X13: ='Holdings Pull Sheet'!O24/1000000000 -> 166.45262 | Y13: =IF(X13<2,"Small", IF(X13<10, "Mid", IF(X13>10, "Large"))) -> Large | Z13: ='Holdings Pull Sheet'!Q24 -> 16.68 | AA13: ='Holdings Pull Sheet'!P24 -> 2.02 | AE13: =W13*T13 -> 0.017835618 | AF13: =W13*U13 -> -0.0012106037
C14: Medtronic | D14: ='Holdings Pull Sheet'!B25 -> MDT | E14: 63.65 | F14: 46.97 | G14: 29 | H14: 1330.71 | I14: =E14*G14 -> 1845.85 | J14: 1705.1296 | K14: 1158.5436 | L14: 1327.1396 | M14: 1530.3832 | O14: =I14-H14 -> 515.14 | P14: =(I14/H14)-1 -> 0.38711665 | Q14: =(L14/K14)-1 -> 0.14552407 | R14: =(M14/L14)-1 -> 0.15314413 | S14: =(I14/M14)-1 -> 0.20613582 | T14: =(I14/J14)-1 -> 0.082527699 | U14: =('Holdings Pull Sheet'!F25/'Holdings Pull Sheet'!G25)-1 -> -0.031644607 | V14: Healthcare | W14: =I14/$I$24 -> 0.030209494 | X14: ='Holdings Pull Sheet'!O25/1000000000 -> 62.356015 | Y14: =IF(X14<2,"Small", IF(X14<10, "Mid", IF(X14>10, "Large"))) -> Large | Z14: ='Holdings Pull Sheet'!Q25 -> 21.55 | AA14: ='Holdings Pull Sheet'!P25 -> 2.95 | AE14: =W14*T14 -> 0.00249312 | AF14: =W14*U14 -> -0.00095596756
C15: Natural Grocers | D15: ='Holdings Pull Sheet'!B26 -> NGVC | E15: 16.19 | F15: 19.49 | G15: 75 | H15: 1471.7 | I15: =E15*G15 -> 1214.25 | J15: 2737.5 | K15: 1471.7 | L15: 1865.25 | M15: 2775 | O15: =I15-H15 -> -257.45 | P15: =(I15/H15)-1 -> -0.17493375 | Q15: =(L15/K15)-1 -> 0.26741184 | R15: =(M15/L15)-1 -> 0.48773623 | S15: =(I15/M15)-1 -> -0.56243243 | T15: =(I15/J15)-1 -> -0.55643836 | U15: =('Holdings Pull Sheet'!F26/'Holdings Pull Sheet'!G26)-1 -> -0.040876777 | V15: Consumer Staples | W15: =I15/$I$24 -> 0.019872621 | X15: ='Holdings Pull Sheet'!O26/1000000000 -> 0.36391769 | Y15: =IF(X15<2,"Small", IF(X15<10, "Mid", IF(X15>10, "Large"))) -> Small | Z15: ='Holdings Pull Sheet'!Q26 -> 29.08 | AA15: ='Holdings Pull Sheet'!P26 -> 0.56 | AE15: =W15*T15 -> -0.011057889 | AF15: =W15*U15 -> -0.00081232872
C16: Perrigo | D16: ='Holdings Pull Sheet'!B27 -> PRGO | E16: 152.39 | F16: 167.85 | G16: 18 | H16: 2206.35 | I16: =E16*G16 -> 2743.02 | J16: 2629.8202 | K16: 2206.35 | L16: 2206.35 | M16: 2206.35 | O16: =I16-H16 -> 536.67 | P16: =(I16/H16)-1 -> 0.24323883 | Q16: =(L16/K16)-1 -> 0 | R16: =(M16/L16)-1 -> 0 | S16: =(I16/M16)-1 -> 0.24323883 | T16: =(I16/J16)-1 -> 0.043044692 | U16: =('Holdings Pull Sheet'!F27/'Holdings Pull Sheet'!G27)-1 -> 0.0063395628 | V16: Healthcare | W16: =I16/$I$24 -> 0.04489273 | X16: ='Holdings Pull Sheet'!O27/1000000000 -> 20.392487 | Y16: =IF(X16<2,"Small", IF(X16<10, "Mid", IF(X16>10, "Large"))) -> Large | Z16: ='Holdings Pull Sheet'!Q27 -> 86.1 | AA16: ='Holdings Pull Sheet'!P27 -> 1.77 | AE16: =W16*T16 -> 0.0019323937 | AF16: =W16*U16 -> 0.00028460029
C17: Range Resources | D17: ='Holdings Pull Sheet'!B28 -> RRC | E17: 63.46 | F17: 86.37 | G17: 42 | H17: 3627.5 | I17: =E17*G17 -> 2665.32 | J17: 3747.66 | K17: 3627.5 | L17: 3627.5 | M17: 3627.5 | O17: =I17-H17 -> -962.18 | P17: =(I17/H17)-1 -> -0.26524604 | Q17: =(L17/K17)-1 -> 0 | R17: =((M17-896.49)/L17)-1 -> -0.24713715 | S17: =(I17/M17)-1 -> -0.26524604 | T17: =(I17/J17)-1 -> -0.28880421 | U17: =('Holdings Pull Sheet'!F28/'Holdings Pull Sheet'!G28)-1 -> -0.032636877 | V17: Energy | W17: =I17/$I$24 -> 0.043621079 | X17: ='Holdings Pull Sheet'!O28/1000000000 -> 10.700487 | Y17: =IF(X17<2,"Small", IF(X17<10, "Mid", IF(X17>10, "Large"))) -> Large | Z17: ='Holdings Pull Sheet'!Q28 -> 40.89 | AA17: ='Holdings Pull Sheet'!P28 -> 1.55 | AE17: =W17*T17 -> -0.012597951 | AF17: =W17*U17 -> -0.0014236558
C18: Tutor Perini | D18: ='Holdings Pull Sheet'!B29 -> TPC | E18: 24.07 | F18: 13.76 | G18: 200 | H18: 2752.24 | I18: =E18*G18 -> 4814 | J18: 6004 | K18: 1874.45 | L18: 2488.5 | M18: 3736 | O18: =I18-H18 -> 2061.76 | P18: =(I18/H18)-1 -> 0.74912072 | Q18: =(L18/K18)-1 -> 0.32758943 | R18: =(M18/L18)-1 -> 0.50130601 | S18: =(I18/M18)-1 -> 0.2885439 | T18: =(I18/J18)-1 -> -0.1982012 | U18: =('Holdings Pull Sheet'!F29/'Holdings Pull Sheet'!G29)-1 -> -0.026688233 | V18: Industrials | W18: =I18/$I$24 -> 0.07878674 | X18: ='Holdings Pull Sheet'!O29/1000000000 -> 1.1691218 | Y18: =IF(X18<2,"Small", IF(X18<10, "Mid", IF(X18>10, "Large"))) -> Small | Z18: ='Holdings Pull Sheet'!Q29 -> 11.57 | AA18: ='Holdings Pull Sheet'!P29 -> 2.08 | AE18: =W18*T18 -> -0.015615626 | AF18: =W18*U18 -> -0.0021026789
C19: Tyson Foods | D19: ='Holdings Pull Sheet'!B30 -> TSN | E19: 40.96 | F19: 16.89 | G19: 102 | H19: 1674.95 | I19: =E19*G19 -> 4177.92 | J19: 4307.1172 | K19: 1665 | L19: 2512.1336 | M19: 3025.4016 | O19: =I19-H19 -> 2502.97 | P19: =(I19/H19)-1 -> 1.4943551 | Q19: =(L19/K19)-1 -> 0.50878895 | R19: =(M19/L19)-1 -> 0.20431557 | S19: =(I19/M19)-1 -> 0.38094724 | T19: =(I19/J19)-1 -> -0.02999621 | U19: =('Holdings Pull Sheet'!F30/'Holdings Pull Sheet'!G30)-1 -> -0.013487476 | V19: Consumer Staples | W19: =I19/$I$24 -> 0.068376547 | X19: ='Holdings Pull Sheet'!O30/1000000000 -> 14.405563 | Y19: =IF(X19<2,"Small", IF(X19<10, "Mid", IF(X19>10, "Large"))) -> Large | Z19: ='Holdings Pull Sheet'!Q30 -> 14.87 | AA19: ='Holdings Pull Sheet'!P30 -> 2.75 | AE19: =W19*T19 -> -0.0020510372 | AF19: =W19*U19 -> -0.00092222703
C21: Wells Fargo | D21: ='Holdings Pull Sheet'!B32 -> WFC | E21: 51.12 | F21: 24.69 | G21: 54 | H21: 1204.37 | I21: =E21*G21 -> 2760.48 | J21: 2658.3709 | K21: 1778.2684 | L21: 1961.7592 | M21: 2210.1034 | O21: =I21-H21 -> 1556.11 | P21: =(I21/H21)-1 -> 1.2920531 | Q21: =(L21/K21)-1 -> 0.10318505 | R21: =(M21/L21)-1 -> 0.1265926 | S21: =(I21/M21)-1 -> 0.24902756 | T21: =(I21/J21)-1 -> 0.038410396 | U21: =('Holdings Pull Sheet'!F32/'Holdings Pull Sheet'!G32)-1 -> -0.019750719 | V21: Financial | W21: =I21/$I$24 -> 0.045178484 | X21: ='Holdings Pull Sheet'!O32/1000000000 -> 266.97162 | Y21: =IF(X21<2,"Small", IF(X21<10, "Mid", IF(X21>10, "Large"))) -> Large | Z21: ='Holdings Pull Sheet'!Q32 -> 12.63 | AA21: ='Holdings Pull Sheet'!P32 -> 4.05 | AE21: =W21*T21 -> 0.0017353235 | AF21: =W21*U21 -> -0.00089230754
C22: Yahoo | D22: ='Holdings Pull Sheet'!B33 -> YHOO | E22: 41.1 | F22: 21.75 | G22: 100 | H22: 2174.99 | I22: =E22*G22 -> 4110 | J22: 3651 | K22: 2174.99 | L22: 2520 | M22: 2823 | O22: =I22-H22 -> 1935.01 | P22: =(I22/H22)-1 -> 0.88966386 | Q22: =(L22/K22)-1 -> 0.15862602 | R22: =(M22/L22)-1 -> 0.1202381 | S22: =(I22/M22)-1 -> 0.45589798 | T22: =(I22/J22)-1 -> 0.12571898 | U22: =('Holdings Pull Sheet'!F33/'Holdings Pull Sheet'!G33)-1 -> 0.00048685492 | V22: Information Technology | W22: =I22/$I$24 -> 0.067264957 | X22: ='Holdings Pull Sheet'!O33/1000000000 -> 40.878216 | Y22: =IF(X22<2,"Small", IF(X22<10, "Mid", IF(X22>10, "Large"))) -> Large | Z22: ='Holdings Pull Sheet'!Q33 -> 34.59 | AA22: ='Holdings Pull Sheet'!P33 -> 1.19 | AE22: =W22*T22 -> 0.0084564818 | AF22: =W22*U22 -> 3.2748275e-05
H24: =SUM(H4:H22) -> 34520.46 | I24: =SUM(I4:I22) -> 61101.652 | J24: 62601.628 | K24: 40381.87 | L24: 46519.794 | M24: 51641.858 | O24: =SUM(O5:O22) -> 18530.932 | P24: =(I24/H24)-1 -> 0.77001269 | Q24: =(L24/K24)-1 -> 0.15199701 | R24: =(M24/L24)-1 -> 0.11010505 | S24: =(I24/M24)-1 -> 0.18318074 | T24: =(I24/J24)-1 -> -0.023960656 | U24: =AF24 -> -0.016800915 | W24: =SUM(W4:W22) -> 1 | AE24: =SUM(AE4:AE22) -> 0.00022119633 | AF24: =SUM(AF4:AF22) -> -0.016800915
C27: Bought This Year | E27: Date Bought | H27: Buy Price | I27: Current Price | J27: % Change
C28: =C19 -> Tyson Foods | D28: =D20 -> 0 | E28: =Transactions!B145 -> 41530 | H28: =F19 -> 16.89 | I28: =E19 -> 40.96 | J28: =(I28/H28)-1 -> 1.4251036
C29: =C16 -> Perrigo | D29: =D16 -> PRGO | E29: =Transactions!B147 -> 41544 | H29: =F16 -> 167.85 | I29: =E16 -> 152.39 | J29: =(I29/H29)-1 -> -0.092106047
C30: =C17 -> Range Resources | D30: =D17 -> RRC | E30: 41698 | H30: =F17 -> 86.37 | I30: =E17 -> 63.46 | J30: =(I30/H30)-1 -> -0.26525414
C33: Sold This Year | E33: Date Sold | H33: Sell Price | I33: Current Price | J33: % Change
C34: Caterpillar | D34: ='Holdings Pull Sheet'!B35 -> 0 | E34: =Transactions!B149 -> 41551 | H34: =Transactions!E149 -> 83.94 | I34: ='Holdings Pull Sheet'!F35 -> 93.5 | J34: =(I34/H34)-1 -> 0.11389087
C35: YRC Worldwide | D35: ='Holdings Pull Sheet'!B36 -> 0 | E35: =Transactions!B151 -> 41576 | H35: 9.58 | I35: ='Holdings Pull Sheet'!F36 -> 17.3 | J35: =(I35/H35)-1 -> 0.80584551
C36: AAPL 515 Apr19 C | D36: ='Holdings Pull Sheet'!B37 -> 0 | E36: =Transactions!B155 -> 41614 | H36: 65.8 | I36: ='Holdings Pull Sheet'!F37 -> 0 | J36: =(I36/H36)-1 -> -1
C38: Proposed Buys This Year | E38: Date Pitched | H38: Pitch Price | I38: Current Price | J38: % Change
C39: NA | D39: NA | E39: NA | H39: NA | I39: NA | J39: =(I39/H39)-1 -> #VALUE!
C41: Proposed Sells This Year | E41: Date Pitched | H41: Pitch Price | I41: Current Price | J41: % Change
C42: NA | D42: NA | E42: NA | H42: NA | I42: NA | J42: =(I42/H42)-1 -> #VALUE!

Sheet Holdings Pull Sheet
C5: Stock Quote Symbols | D5: $INDU,$COMP,$INX,$COMPX,BRK.B,MCLOX,CX,CSCO,DAL,GNTX,HD,IMMR,INTC,MDT,NGVC,PRGO,RRC,TPC,TSN,ULTA,WFC,YHOO,GE,CAT,YRCW,126.2.AAPL4DJC515000
C9: Stock Quotes Provided by MSN Money
C10: Click here to visit MSN Money
F11: Last | G11: Previous Close | H11: High | I11: Low | J11: Volume | K11: Change | L11: % Change | M11: 52 Wk High | N11: 52 Wk Low | O11: Market Cap | P11: EPS | Q11: P/E Ratio | R11: # Shares Out
C12: DJ Industrial Average | D12: Chart | E12: News | F12: 16659.25 | G12: 16994.22 | H12: 16989.37 | I12: 16649.04 | J12: 93214073 | K12: -334.97 | L12: -0.0197 | M12: 17350.64 | N12: 14806.39 | O12: 0 | P12: 0 | Q12: 0 | R12: 0
C13: NASDAQ Composite | D13: Chart | E13: News | F13: 4378.34 | G13: 4468.59 | H13: 4464.13 | I13: 4377.28 | J13: 0 | K13: -90.26 | L13: -0.0202 | M13: 4610.57 | N13: 3721.11 | O13: 0 | P13: 0 | Q13: 0 | R13: 0
C14: S&P 500 Index | D14: Chart | E14: News | F14: 1928.21 | G14: 1968.89 | H14: 1967.68 | I14: 1927.56 | J14: 604573274 | K14: -40.68 | L14: -0.0207 | M14: 2019.26 | N14: 1660.88 | O14: 0 | P14: 0 | Q14: 0 | R14: 0
C15: NASDAQ Composite | D15: Chart | E15: News | F15: 4378.34 | G15: 4468.59 | H15: 4464.13 | I15: 4377.28 | J15: 0 | K15: -90.26 | L15: -0.0202 | M15: 4610.57 | N15: 3721.11 | O15: 0 | P15: 0 | Q15: 0 | R15: 0
B16: BRK.B | C16: BERKSHIRE HATHAWAY CLASS B | D16: Chart | E16: News | F16: 137.09 | G16: 139.94 | H16: 140.29 | I16: 137.07 | J16: 6592808 | K16: -2.85 | L16: -0.0204 | M16: 142.45 | N16: 108.12 | O16: 319364766003 | P16: 9 | Q16: 15.19 | R16: 2334708429
B17: MCLOX | C17: BlackRock Global Allocation Inv C | D17: Chart | E17: News | F17: 19.64 | G17: 19.91 | H17: 19.64 | I17: 19.64 | J17: 0 | K17: -0.27 | L17: -0.0136 | M17: 0 | N17: 0 | O17: 0 | P17: 0 | Q17: 0 | R17: 0
B18: CX | C18: CEMEX S.A.B. DE C.V. | D18: Chart | E18: News | F18: 12.2 | G18: 12.53 | H18: 12.54 | I18: 12.07 | J18: 13180275 | K18: -0.33 | L18: -0.0263 | M18: 14.37 | N18: 9.81 | O18: 14494176889 | P18: -6.46 | Q18: -25.33 | R18: 1188047286
B19: CSCO | C19: CISCO SYSTEMS INC | D19: Chart | E19: News | F19: 24.19 | G19: 24.66 | H19: 24.64 | I19: 24.18 | J19: 29340068 | K19: -0.47 | L19: -0.0191 | M19: 26.08 | N19: 20.22 | O19: 123349724658 | P19: 1.49 | Q19: 16.27 | R19: 5099203169
B20: DAL | C20: DELTA AIR LINES Inc | D20: Chart | E20: News | F20: 33.71 | G20: 34.81 | H20: 35.94 | I20: 33.61 | J20: 28215542 | K20: -1.1 | L20: -0.0316 | M20: 42.66 | N20: 23.72 | O20: 28249129921 | P20: 12.69 | Q20: 2.64 | R20: 843005966
B21: GNTX | C21: GENTEX CORP | D21: Chart | E21: News | F21: 27.61 | G21: 28.29 | H21: 28.32 | I21: 27.36 | J21: 1397926 | K21: -0.68 | L21: -0.024 | M21: 34.41 | N21: 24.63 | O21: 4036777120 | P21: 1.86 | Q21: 14.87 | R21: 146207067
B22: HD | C22: HOME DEPOT Inc | D22: Chart | E22: News | F22: 93.07 | G22: 94.09 | H22: 94.79 | I22: 93.02 | J22: 6674794 | K22: -1.02 | L22: -0.0108 | M22: 94.79 | N22: 73.74 | O22: 125264919496 | P22: 4.18 | Q22: 22.26 | R22: 1345921559
B23: IMMR | C23: IMMERSION CORP | D23: Chart | E23: News | F23: 7.91 | G23: 8.2 | H23: 8.2 | I23: 7.9 | J23: 297585 | K23: -0.29 | L23: -0.0354 | M23: 14.72 | N23: 7.86 | O23: 225904356 | P23: 1.35 | Q23: 5.84 | R23: 28559337
B24: INTC | C24: INTEL CORP | D24: Chart | E24: News | F24: 33.62 | G24: 34.27 | H24: 34.43 | I24: 33.58 | J24: 28157325 | K24: -0.65 | L24: -0.019 | M24: 35.56 | N24: 22.48 | O24: 166452620000 | P24: 2.02 | Q24: 16.68 | R24: 4951000000
B25: MDT | C25: MEDTRONIC Inc | D25: Chart | E25: News | F25: 63.65 | G25: 65.73 | H25: 65.6 | I25: 63.64 | J25: 9472607 | K25: -2.08 | L25: -0.0316 | M25: 67.11 | N25: 52.53 | O25: 62356014852 | P25: 2.95 | Q25: 21.55 | R25: 979516413
B26: NGVC | C26: NATURAL GROCERS BY VITAMIN COTTAGE INC | D26: Chart | E26: News | F26: 16.19 | G26: 16.88 | H26: 16.73 | I26: 16.17 | J26: 69324 | K26: -0.69 | L26: -0.0409 | M26: 44.6 | N26: 15.89 | O26: 363917687 | P26: 0.56 | Q26: 29.08 | R26: 22477930
B27: PRGO | C27: PERRIGO COMPANY PLC (IRELAND) | D27: Chart | E27: News | F27: 152.39 | G27: 151.43 | H27: 153.87 | I27: 150.5 | J27: 1099984 | K27: 0.96 | L27: 0.0063 | M27: 168.39 | N27: 125.37 | O27: 20392486923 | P27: 1.77 | Q27: 86.1 | R27: 133817750
... B30: TSN | C30: TYSON FOODS Inc | D30: Chart | E30: News | F30: 40.96 | G30: 41.52 | H30: 42.1 | I30: 40.83 | J30: 3822251 | K30: -0.56 | L30: -0.0135 | M30: 44.24 | N30: 27.33 | O30: 14405562696 | P30: 2.75 | Q30: 14.87 | R30: 351698308
C31: ULTA SALON COSMETICS & FRAGRANCE Inc | D31: Chart | E31: News | F31: 114.77 | G31: 114.87 | H31: 115.75 | I31: 113.57 | J31: 750290 | K31: -0.1 | L31: -0.0009 | M31: 132.72 | N31: 80.35 | O31: 7388523500 | P31: 3.51 | Q31: 32.68 | R31: 64376784
B32: WFC | C32: WELLS FARGO & CO. | D32: Chart | E32: News | F32: 51.12 | G32: 52.15 | H32: 52.21 | I32: 51.03 | J32: 18744179 | K32: -1.03 | L32: -0.0198 | M32: 53.8 | N32: 40.07 | O32: 266971616384 | P32: 4.05 | Q32: 12.63 | R32: 5220407047
B33: YHOO | C33: YAHOO INC | D33: Chart | E33: News | F33: 41.1 | G33: 41.08 | H33: 41.25 | I33: 40.42 | J33: 33515066 | K33: 0.02 | L33: 0.0005 | M33: 44.01 | N33: 31.7 | O33: 40878215687 | P33: 1.19 | Q33: 34.59 | R33: 994603788
C34: GENERAL ELECTRIC | D34: Chart | E34: News | F34: 24.78 | G34: 25.25 | H34: 25.31 | I34: 24.73 | J34: 34012297 | K34: -0.47 | L34: -0.0186 | M34: 28.09 | N34: 23.5 | O34: 248539795987 | P34: 1.46 | Q34: 16.95 | R34: 10033903754
C35: CATERPILLAR Inc | D35: Chart | E35: News | F35: 93.5 | G35: 96.65 | H35: 96.52 | I35: 93.24 | J35: 6414828 | K35: -3.15 | L35: -0.0326 | M35: 111.46 | N35: 81.87 | O35: 58703657287 | P35: 6 | Q35: 15.58 | R35: 627846602
C36: YRC WORLDWIDE Inc | D36: Chart | E36: News | F36: 17.3 | G36: 18.91 | H36: 18.84 | I36: 16.95 | J36: 1147246 | K36: -1.61 | L36: -0.0851 | M36: 29.21 | N36: 7.06 | O36: 540487240 | P36: -7.5 | Q36: -2.31 | R36: 31242037
C38: Symbol Lookup | E38: MSN Money Home | I38: Microsoft Office Tools on the Web
C39: Find stocks, mutual funds, options, indices, and currencies. | E39: Discover MSN Money's tools, columns, and more! | I39: Get the latest from Microsoft Office
C41: Terms of Use. © 2014 Microsoft Corporation and/or its suppliers. All rights reserved.
C42: DATA PROVIDERS
C44: Copyright © 2014 Microsoft. All rights reserved.
C46: Fundamental company data and historical chart data provided by Morningstar Inc. Real-time index quotes and delayed quotes supplied by Morningstar Inc. Quotes delayed by up to 15 minutes, except where indicated otherwise. Fund summary, fund performance and dividend data provided by Morningstar Inc. Analyst recommendations provided by Zacks Investment Research. StockScouter data provided by Verus Analytics. IPO data provided by Hoover's Inc. Index membership data provided by Morningstar Inc.

Sheet Data
D1: IPO Portfolio | L1: S&P 500 Index | S1: Dow Jones Index
A2: Week # | B2: Date | D2: Portfolio Value | E2: Adjusted Portfolio Value | F2: Weekly +/- | G2: Weekly % Change | H2: Inception +/- | I2: Inception % Change | L2: S&P Close | M2: S&P Weekly % Change | N2: S&P Inception % Change | O2: Outperformed S&P 500? | P2: 1 = Yes, 0 = No | Q2: % IPO Outperforemed S&P 500 | S2: Dow Close | T2: Dow Weekly % Change | U2: Dow Inception % Change | V2: Outperformed Dow? | W2: 1 = Yes, 0 = No | X2: % IPO Outperforemed Dow | Z2: Nasdaq Close | AA2: Nasdaq Weekly % Change | AB2: Nasdaq Inception % Change
A3: 1 | B3: 37743 | D3: 22855.85 | E3: =D3 -> 22855.85 | F3: - | G3: - | H3: - | I3: - | L3: 930.08 | M3: - | N3: - | S3: 8582.68 | T3: - | U3: - | Z3: 1502.88 | AA3: - | AB3: -
A4: =A3+1 -> 2 | B4: 37750 | D4: 23075.51 | E4: =D4 -> 23075.51 | F4: =D4-D3 -> 219.66 | G4: =(D4/D3)-1 -> 0.0096106686 | H4: =D4-$D$3 -> 219.66 | I4: =(D4/$D$3)-1 -> 0.0096106686 | L4: 933.41 | M4: =(L4/L3)-1 -> 0.0035803372 | N4: =(L4/$L$3)-1 -> 0.0035803372 | O4: =IF(G4>M4,"Yes","No") -> Yes | P4: =IF(O4="Yes",1,0) -> 1 | Q4: =SUM(P4)/COUNT(P4) -> 1 | S4: 8604.6 | T4: =(S4/S3)-1 -> 0.0025539808 | U4: =(S4/$S$3)-1 -> 0.0025539808 | V4: =IF(G4>T4,"Yes","No") -> Yes | W4: =IF(V4="Yes",1,0) -> 1 | X4: =SUM(W4)/COUNT(W4) -> 1 | Z4: 1520.15 | AA4: =(Z4/Z3)-1 -> 0.01149127 | AB4: =(Z4/$Z$3)-1 -> 0.01149127
A5: =A4+1 -> 3 | B5: =B4+7 -> 37757 | D5: 23259.78 | E5: =D5 -> 23259.78 | F5: =D5-D4 -> 184.27 | G5: =(D5/D4)-1 -> 0.0079855223 | H5: =D5-$D$3 -> 403.93 | I5: =(D5/$D$3)-1 -> 0.017672937 | L5: 944.3 | M5: =(L5/L4)-1 -> 0.011666899 | N5: =(L5/$L$3)-1 -> 0.015289007 | O5: =IF(G5>M5,"Yes","No") -> No | P5: =IF(O5="Yes",1,0) -> 0 | Q5: =SUM($P$4:P5)/COUNT($P$4:P5) -> 0.5 | S5: 8678.97 | T5: =(S5/S4)-1 -> 0.0086430514 | U5: =(S5/$S$3)-1 -> 0.011219106 | V5: =IF(G5>T5,"Yes","No") -> No | W5: =IF(V5="Yes",1,0) -> 0 | X5: =SUM($W$4:W5)/COUNT($W$4:W5) -> 0.5 | Z5: 1538.53 | AA5: =(Z5/Z4)-1 -> 0.012090912 | AB5: =(Z5/$Z$3)-1 -> 0.023721122
A6: =A5+1 -> 4 | B6: =B5+7 -> 37764 | D6: 22880.42 | E6: =D6 -> 22880.42 | F6: =D6-D5 -> -379.36 | G6: =(D6/D5)-1 -> -0.016309699 | H6: =D6-$D$3 -> 24.57 | I6: =(D6/$D$3)-1 -> 0.0010749983 | L6: 921.29 | M6: =(L6/L5)-1 -> -0.024367256 | N6: =(L6/$L$3)-1 -> -0.0094507999 | O6: =IF(G6>M6,"Yes","No") -> Yes | P6: =IF(O6="Yes",1,0) -> 1 | Q6: =SUM($P$4:P6)/COUNT($P$4:P6) -> 0.66666667 | S6: 8497.59 | T6: =(S6/S5)-1 -> -0.020898793 | U6: =(S6/$S$3)-1 -> -0.0099141527 | V6: =IF(G6>T6,"Yes","No") -> Yes | W6: =IF(V6="Yes",1,0) -> 1 | X6: =SUM($W$4:W6)/COUNT($W$4:W6) -> 0.66666667 | Z6: 1483.2 | AA6: =(Z6/Z5)-1 -> -0.0359629 | AB6: =(Z6/$Z$3)-1 -> -0.013094858
A7: =A6+1 -> 5 | B7: =B6+7 -> 37771 | D7: 24142.6 | E7: =D7 -> 24142.6 | F7: =D7-D6 -> 1262.18 | G7: =(D7/D6)-1 -> 0.055164197 | H7: =D7-$D$3 -> 1286.75 | I7: =(D7/$D$3)-1 -> 0.056298497 | L7: 963.59 | M7: =(L7/L6)-1 -> 0.045913882 | N7: =(L7/$L$3)-1 -> 0.036029159 | O7: =IF(G7>M7,"Yes","No") -> Yes | P7: =IF(O7="Yes",1,0) -> 1 | Q7: =SUM($P$4:P7)/COUNT($P$4:P7) -> 0.75 | S7: 8850.26 | T7: =(S7/S6)-1 -> 0.041502355 | U7: =(S7/$S$3)-1 -> 0.031176742 | V7: =IF(G7>T7,"Yes","No") -> Yes | W7: =IF(V7="Yes",1,0) -> 1 | X7: =SUM($W$4:W7)/COUNT($W$4:W7) -> 0.75 | Z7: 1595.91 | AA7: =(Z7/Z6)-1 -> 0.0759911 | AB7: =(Z7/$Z$3)-1 -> 0.06190115
A8: =A7+1 -> 6 | B8: =B7+7 -> 37778 | D8: 24843.31 | E8: =D8 -> 24843.31 | F8: =D8-D7 -> 700.71 | G8: =(D8/D7)-1 -> 0.0290238 | H8: =D8-$D$3 -> 1987.46 | I8: =(D8/$D$3)-1 -> 0.086956293 | L8: 987.76 | M8: =(L8/L7)-1 -> 0.025083282 | N8: =(L8/$L$3)-1 -> 0.062016171 | O8: =IF(G8>M8,"Yes","No") -> Yes | P8: =IF(O8="Yes",1,0) -> 1 | Q8: =SUM($P$4:P8)/COUNT($P$4:P8) -> 0.8 | S8: 9062.79 | T8: =(S8/S7)-1 -> 0.024013984 | U8: =(S8/$S$3)-1 -> 0.055939404 | V8: =IF(G8>T8,"Yes","No") -> Yes | W8: =IF(V8="Yes",1,0) -> 1 | X8: =SUM($W$4:W8)/COUNT($W$4:W8) -> 0.8 | Z8: 1627.42 | AA8: =(Z8/Z7)-1 -> 0.019744221 | AB8: =(Z8/$Z$3)-1 -> 0.082867561
A9: =A8+1 -> 7 | B9: =B8+7 -> 37785 | D9: 24777.34 | E9: =D9 -> 24777.34 | F9: =D9-D8 -> -65.97 | G9: =(D9/D8)-1 -> -0.0026554433 | H9: =D9-$D$3 -> 1921.49 | I9: =(D9/$D$3)-1 -> 0.084069943 | L9: =995.16-6.55 -> 988.61 | M9: =(L9/L8)-1 -> 0.00086053292 | N9: =(L9/$L$3)-1 -> 0.062930071 | O9: =IF(G9>M9,"Yes","No") -> No | P9: =IF(O9="Yes",1,0) -> 0 | Q9: =SUM($P$4:P9)/COUNT($P$4:P9) -> 0.66666667 | S9: =9176.41-59.29 -> 9117.12 | T9: =(S9/S8)-1 -> 0.0059948426 | U9: =(S9/$S$3)-1 -> 0.062269594 | V9: =IF(G9>T9,"Yes","No") -> No | W9: =IF(V9="Yes",1,0) -> 0 | X9: =SUM($W$4:W9)/COUNT($W$4:W9) -> 0.66666667 | Z9: =1637.82-11.33 -> 1626.49 | AA9: =(Z9/Z8)-1 -> -0.00057145666 | AB9: =(Z9/$Z$3)-1 -> 0.082248749
A10: =A9+1 -> 8 | B10: =B9+7 -> 37792 | D10: 25072.64 | E10: =D10 -> 25072.64 | F10: =D10-D9 -> 295.3 | G10: =(D10/D9)-1 -> 0.011918148 | H10: =D10-$D$3 -> 2216.79 | I10: =(D10/$D$3)-1 -> 0.096990048 | L10: 995.69 | M10: =(L10/L9)-1 -> 0.0071615703 | N10: =(L10/$L$3)-1 -> 0.070542319 | O10: =IF(G10>M10,"Yes","No") -> Yes | P10: =IF(O10="Yes",1,0) -> 1 | Q10: =SUM($P$4:P10)/COUNT($P$4:P10) -> 0.71428571 | S10: 9200.75 | T10: =(S10/S9)-1 -> 0.0091728528 | U10: =(S10/$S$3)-1 -> 0.072013637 | V10: =IF(G10>T10,"Yes","No") -> Yes | W10: =IF(V10="Yes",1,0) -> 1 | X10: =SUM($W$4:W10)/COUNT($W$4:W10) -> 0.71428571 | Z10: 1644.72 | AA10: =(Z10/Z9)-1 -> 0.011208184 | AB10: =(Z10/$Z$3)-1 -> 0.094378793
A11: =A10+1 -> 9 | B11: =B10+7 -> 37799 | D11: 24857.12 | E11: =D11 -> 24857.12 | F11: =D11-D10 -> -215.52 | G11: =(D11/D10)-1 -> -0.008595824 | H11: =D11-$D$3 -> 2001.27 | I11: =(D11/$D$3)-1 -> 0.087560515 | L11: 976.22 | M11: =(L11/L10)-1 -> -0.019554279 | N11: =(L11/$L$3)-1 -> 0.049608636 | O11: =IF(G11>M11,"Yes","No") -> Yes | P11: =IF(O11="Yes",1,0) -> 1 | Q11: =SUM($P$4:P11)/COUNT($P$4:P11) -> 0.75 | S11: 8989.05 | T11: =(S11/S10)-1 -> -0.023008994 | U11: =(S11/$S$3)-1 -> 0.047347682 | V11: =IF(G11>T11,"Yes","No") -> Yes | W11: =IF(V11="Yes",1,0) -> 1 | X11: =SUM($W$4:W11)/COUNT($W$4:W11) -> 0.75 | Z11: 1625.26 | AA11: =(Z11/Z10)-1 -> -0.011831801 | AB11: =(Z11/$Z$3)-1 -> 0.08143032
A12: =A11+1 -> 10 | B12: =B11+7 -> 37806 | D12: 24907.37 | E12: =D12 -> 24907.37 | F12: =D12-D11 -> 50.25 | G12: =(D12/D11)-1 -> 0.0020215536 | H12: =D12-$D$3 -> 2051.52 | I12: =(D12/$D$3)-1 -> 0.089759077 | L12: 991.66 | M12: =(L12/L11)-1 -> 0.015816107 | N12: =(L12/$L$3)-1 -> 0.066209358 | O12: =IF(G12>M12,"Yes","No") -> No | P12: =IF(O12="Yes",1,0) -> 0 | Q12: =SUM($P$4:P12)/COUNT($P$4:P12) -> 0.66666667 | S12: 9070.21 | T12: =(S12/S11)-1 -> 0.0090287628 | U12: =(S12/$S$3)-1 -> 0.056803935 | V12: =IF(G12>T12,"Yes","No") -> No | W12: =IF(V12="Yes",1,0) -> 0 | X12: =SUM($W$4:W12)/COUNT($W$4:W12) -> 0.66666667 | Z12: 1663.46 | AA12: =(Z12/Z11)-1 -> 0.023503932 | AB12: =(Z12/$Z$3)-1 -> 0.10684818
A13: =A12+1 -> 11 | B13: =B12+7 -> 37813 | D13: 25578.29 | E13: =D13 -> 25578.29 | F13: =D13-D12 -> 670.92 | G13: =(D13/D12)-1 -> 0.026936606 | H13: =D13-$D$3 -> 2722.44 | I13: =(D13/$D$3)-1 -> 0.11911349 | L13: 998.14 | M13: =(L13/L12)-1 -> 0.0065344977 | N13: =(L13/$L$3)-1 -> 0.073176501 | O13: =IF(G13>M13,"Yes","No") -> Yes | P13: =IF(O13="Yes",1,0) -> 1 | Q13: =SUM($P$4:P13)/COUNT($P$4:P13) -> 0.7 | S13: 9119.59 | T13: =(S13/S12)-1 -> 0.0054441959 | U13: =(S13/$S$3)-1 -> 0.062557383 | V13: =IF(G13>T13,"Yes","No") -> Yes | W13: =IF(V13="Yes",1,0) -> 1 | X13: =SUM($W$4:W13)/COUNT($W$4:W13) -> 0.7 | Z13: 1733.93 | AA13: =(Z13/Z12)-1 -> 0.042363507 | AB13: =(Z13/$Z$3)-1 -> 0.15373816
A14: =A13+1 -> 12 | B14: =B13+7 -> 37820 | D14: 25192.44 | E14: =D14 -> 25192.44 | F14: =D14-D13 -> -385.85 | G14: =(D14/D13)-1 -> -0.015085058 | H14: =D14-$D$3 -> 2336.59 | I14: =(D14/$D$3)-1 -> 0.10223159 | L14: 993.32 | M14: =(L14/L13)-1 -> -0.0048289819 | N14: =(L14/$L$3)-1 -> 0.067994151 | O14: =IF(G14>M14,"Yes","No") -> No | P14: =IF(O14="Yes",1,0) -> 0 | Q14: =SUM($P$4:P14)/COUNT($P$4:P14) -> 0.63636364 | S14: 9188.15 | T14: =(S14/S13)-1 -> 0.0075178818 | U14: =(S14/$S$3)-1 -> 0.070545564 | V14: =IF(G14>T14,"Yes","No") -> No | W14: =IF(V14="Yes",1,0) -> 0 | X14: =SUM($W$4:W14)/COUNT($W$4:W14) -> 0.63636364 | Z14: 1708.5 | AA14: =(Z14/Z13)-1 -> -0.014666105 | AB14: =(Z14/$Z$3)-1 -> 0.13681731
A15: =A14+1 -> 13 | B15: =B14+7 -> 37827 | D15: 25421.8 | E15: =D15 -> 25421.8 | F15: =D15-D14 -> 229.36 | G15: =(D15/D14)-1 -> 0.0091043186 | H15: =D15-$D$3 -> 2565.95 | I15: =(D15/$D$3)-1 -> 0.11226666 | L15: 998.68 | M15: =(L15/L14)-1 -> 0.0053960456 | N15: =(L15/$L$3)-1 -> 0.073757096 | O15: =IF(G15>M15,"Yes","No") -> Yes | P15: =IF(O15="Yes",1,0) -> 1 | Q15: =SUM($P$4:P15)/COUNT($P$4:P15) -> 0.66666667 | S15: 9284.57 | T15: =(S15/S14)-1 -> 0.010493951 | U15: =(S15/$S$3)-1 -> 0.081779817 | V15: =IF(G15>T15,"Yes","No") -> No | W15: =IF(V15="Yes",1,0) -> 0 | X15: =SUM($W$4:W15)/COUNT($W$4:W15) -> 0.58333333 | Z15: 1730.7 | AA15: =(Z15/Z14)-1 -> 0.012993854 | AB15: =(Z15/$Z$3)-1 -> 0.15158895
A16: =A15+1 -> 14 | B16: =B15+7 -> 37834 | D16: 25266.57 | E16: =D16 -> 25266.57 | F16: =D16-D15 -> -155.23 | G16: =(D16/D15)-1 -> -0.0061061766 | H16: =D16-$D$3 -> 2410.72 | I16: =(D16/$D$3)-1 -> 0.10547497 | L16: 980.15 | M16: =(L16/L15)-1 -> -0.018554492 | N16: =(L16/$L$3)-1 -> 0.053834079 | O16: =IF(G16>M16,"Yes","No") -> Yes | P16: =IF(O16="Yes",1,0) -> 1 | Q16: =SUM($P$4:P16)/COUNT($P$4:P16) -> 0.69230769 | S16: 9153.97 | T16: =(S16/S15)-1 -> -0.014066349 | U16: =(S16/$S$3)-1 -> 0.066563125 | V16: =IF(G16>T16,"Yes","No") -> Yes | W16: =IF(V16="Yes",1,0) -> 1 | X16: =SUM($W$4:W16)/COUNT($W$4:W16) -> 0.61538462 | Z16: 1715.62 | AA16: =(Z16/Z15)-1 -> -0.0087132374 | AB16: =(Z16/$Z$3)-1 -> 0.14155488
A17: =A16+1 -> 15 | B17: =B16+7 -> 37841 | D17: 25228.34 | E17: =D17 -> 25228.34 | F17: =D17-D16 -> -38.23 | G17: =(D17/D16)-1 -> -0.0015130665 | H17: =D17-$D$3 -> 2372.49 | I17: =(D17/$D$3)-1 -> 0.10380231 | L17: 977.59 | M17: =(L17/L16)-1 -> -0.0026118451 | N17: =(L17/$L$3)-1 -> 0.051081627 | O17: =IF(G17>M17,"Yes","No") -> Yes | P17: =IF(O17="Yes",1,0) -> 1 | Q17: =SUM($P$4:P17)/COUNT($P$4:P17) -> 0.71428571 | S17: 9191.09 | T17: =(S17/S16)-1 -> 0.0040550712 | U17: =(S17/$S$3)-1 -> 0.070888114 | V17: =IF(G17>T17,"Yes","No") -> No | W17: =IF(V17="Yes",1,0) -> 0 | X17: =SUM($W$4:W17)/COUNT($W$4:W17) -> 0.57142857 | Z17: 1644.03 | AA17: =(Z17/Z16)-1 -> -0.041728355 | AB17: =(Z17/$Z$3)-1 -> 0.093919674
A18: =A17+1 -> 16 | B18: =B17+7 -> 37848 | D18: 24951.71 | E18: =D18 -> 24951.71 | F18: =D18-D17 -> -276.63 | G18: =(D18/D17)-1 -> -0.01096505 | H18: =D18-$D$3 -> 2095.86 | I18: =(D18/$D$3)-1 -> 0.091699062 | L18: 990.67 | M18: =(L18/L17)-1 -> 0.013379842 | N18: =(L18/$L$3)-1 -> 0.065144934 | O18: =IF(G18>M18,"Yes","No") -> No | P18: =IF(O18="Yes",1,0) -> 0 | Q18: =SUM($P$4:P18)/COUNT($P$4:P18) -> 0.66666667 | S18: 9321.69 | T18: =(S18/S17)-1 -> 0.014209414 | U18: =(S18/$S$3)-1 -> 0.086104806 | V18: =IF(G18>T18,"Yes","No") -> No | W18: =IF(V18="Yes",1,0) -> 0 | X18: =SUM($W$4:W18)/COUNT($W$4:W18) -> 0.53333333 | Z18: 1702.01 | AA18: =(Z18/Z17)-1 -> 0.035266996 | AB18: =(Z18/$Z$3)-1 -> 0.13249894
A19: =A18+1 -> 17 | B19: =B18+7 -> 37855 | D19: 25454.04 | E19: =D19 -> 25454.04 | F19: =D19-D18 -> 502.33 | G19: =(D19/D18)-1 -> 0.020132087 | H19: =D19-$D$3 -> 2598.19 | I19: =(D19/$D$3)-1 -> 0.11367724 | L19: 993.06 | M19: =(L19/L18)-1 -> 0.0024125087 | N19: =(L19/$L$3)-1 -> 0.067714605 | O19: =IF(G19>M19,"Yes","No") -> Yes | P19: =IF(O19="Yes",1,0) -> 1 | Q19: =SUM($P$4:P19)/COUNT($P$4:P19) -> 0.6875 | S19: 9348.87 | T19: =(S19/S18)-1 -> 0.0029157803 | U19: =(S19/$S$3)-1 -> 0.089271649 | V19: =IF(G19>T19,"Yes","No") -> Yes | W19: =IF(V19="Yes",1,0) -> 1 | X19: =SUM($W$4:W19)/COUNT($W$4:W19) -> 0.5625 | Z19: 1765.32 | AA19: =(Z19/Z18)-1 -> 0.037197196 | AB19: =(Z19/$Z$3)-1 -> 0.17462472
A20: =A19+1 -> 18 | B20: =B19+7 -> 37862 | D20: 26198.38 | E20: =D20 -> 26198.38 | F20: =D20-D19 -> 744.34 | G20: =(D20/D19)-1 -> 0.029242509 | H20: =D20-$D$3 -> 3342.53 | I20: =(D20/$D$3)-1 -> 0.14624396 | L20: 1008.01 | M20: =(L20/L19)-1 -> 0.015054478 | N20: =(L20/$L$3)-1 -> 0.083788491 | O20: =IF(G20>M20,"Yes","No") -> Yes | P20: =IF(O20="Yes",1,0) -> 1 | Q20: =SUM($P$4:P20)/COUNT($P$4:P20) -> 0.70588235 | S20: 9415.82 | T20: =(S20/S19)-1 -> 0.0071612933 | U20: =(S20/$S$3)-1 -> 0.097072243 | V20: =IF(G20>T20,"Yes","No") -> Yes | W20: =IF(V20="Yes",1,0) -> 1 | X20: =SUM($W$4:W20)/COUNT($W$4:W20) -> 0.58823529 | Z20: 1810.45 | AA20: =(Z20/Z19)-1 -> 0.02556477 | AB20: =(Z20/$Z$3)-1 -> 0.20465373
A21: =A20+1 -> 19 | B21: =B20+7 -> 37869 | D21: 26545.65 | E21: =D21 -> 26545.65 | F21: =D21-D20 -> 347.27 | G21: =(D21/D20)-1 -> 0.0132554 | H21: =D21-$D$3 -> 3689.8 | I21: =(D21/$D$3)-1 -> 0.16143788 | L21: 1021.39 | M21: =(L21/L20)-1 -> 0.013273678 | N21: =(L21/$L$3)-1 -> 0.098174351 | O21: =IF(G21>M21,"Yes","No") -> No | P21: =IF(O21="Yes",1,0) -> 0 | Q21: =SUM($P$4:P21)/COUNT($P$4:P21) -> 0.66666667 | S21: 9503.34 | T21: =(S21/S20)-1 -> 0.009294995 | U21: =(S21/$S$3)-1 -> 0.10726952 | V21: =IF(G21>T21,"Yes","No") -> Yes | W21: =IF(V21="Yes",1,0) -> 1 | X21: =SUM($W$4:W21)/COUNT($W$4:W21) -> 0.61111111 | Z21: 1858.24 | AA21: =(Z21/Z20)-1 -> 0.026396752 | AB21: =(Z21/$Z$3)-1 -> 0.23645268
... A37: =A36+1 -> 35 | B37: =B36+7 -> 37981 | D37: 29690.49 | E37: =D37 -> 29690.49 | F37: =D37-D36 -> 362.49 | G37: =(D37/D36)-1 -> 0.012359861 | H37: =D37-$D$3 -> 6834.64 | I37: =(D37/$D$3)-1 -> 0.29903241 | L37: 1095.89 | M37: =(L37/L36)-1 -> 0.0066411919 | N37: =(L37/$L$3)-1 -> 0.17827499 | O37: =IF(G37>M37,"Yes","No") -> Yes | P37: =IF(O37="Yes",1,0) -> 1 | Q37: =SUM($P$4:P37)/COUNT($P$4:P37) -> 0.67647059 | S37: 10324.67 | T37: =(S37/S36)-1 -> 0.004519265 | U37: =(S37/$S$3)-1 -> 0.20296574 | V37: =IF(G37>T37,"Yes","No") -> Yes | W37: =IF(V37="Yes",1,0) -> 1 | X37: =SUM($W$4:W37)/COUNT($W$4:W37) -> 0.61764706 | Z37: 1973.14 | AA37: =(Z37/Z36)-1 -> 0.0082370134 | AB37: =(Z37/$Z$3)-1 -> 0.31290589
A38: =A37+1 -> 36 | B38: =B37+7 -> 37988 | D38: 30649.47 | E38: =D38 -> 30649.47 | F38: =D38-D37 -> 958.98 | G38: =(D38/D37)-1 -> 0.032299231 | H38: =D38-$D$3 -> 7793.62 | I38: =(D38/$D$3)-1 -> 0.34099016 | J38: 0 | L38: 1108.48 | M38: =(L38/L37)-1 -> 0.011488379 | N38: =(L38/$L$3)-1 -> 0.19181146 | O38: =IF(G38>M38,"Yes","No") -> Yes | P38: =IF(O38="Yes",1,0) -> 1 | Q38: =SUM($P$4:P38)/COUNT($P$4:P38) -> 0.68571429 | R38: 0 | S38: 10409.85 | T38: =(S38/S37)-1 -> 0.0082501426 | U38: =(S38/$S$3)-1 -> 0.21289038 | V38: =IF(G38>T38,"Yes","No") -> Yes | W38: =IF(V38="Yes",1,0) -> 1 | X38: =SUM($W$4:W38)/COUNT($W$4:W38) -> 0.62857143 | Z38: 2006.68 | AA38: =(Z38/Z37)-1 -> 0.016998287 | AB38: =(Z38/$Z$3)-1 -> 0.33522304
A39: =A38+1 -> 37 | B39: =B38+7 -> 37995 | D39: 30712.11 | E39: =D39 -> 30712.11 | F39: =D39-D38 -> 62.64 | G39: =(D39/D38)-1 -> 0.0020437548 | H39: =D39-$D$3 -> 7856.26 | I39: =(D39/$D$3)-1 -> 0.34373082 | J39: =(E39/$E$38)-1 -> 0.0020437548 | L39: 1121.86 | M39: =(L39/L38)-1 -> 0.012070583 | N39: =(L39/$L$3)-1 -> 0.20619732 | O39: =IF(G39>M39,"Yes","No") -> No | P39: =IF(O39="Yes",1,0) -> 0 | Q39: =SUM($P$4:P39)/COUNT($P$4:P39) -> 0.66666667 | R39: =(L39/$L$38)-1 -> 0.012070583 | S39: 10458.89 | T39: =(S39/S38)-1 -> 0.0047109228 | U39: =(S39/$S$3)-1 -> 0.21860421 | V39: =IF(G39>T39,"Yes","No") -> No | W39: =IF(V39="Yes",1,0) -> 0 | X39: =SUM($W$4:W39)/COUNT($W$4:W39) -> 0.61111111 | Z39: 2086.92 | AA39: =(Z39/Z38)-1 -> 0.039986445 | AB39: =(Z39/$Z$3)-1 -> 0.38861386
