Workbook
Name Account_Type: page1!$A$1:$K$60
Name Applicant_is_married: page1!$B$90:$B$92
Name Bank: page1!$B$74:$B$78
Name Financial_Condition_as_of: page1!$B$95
Name Jointly_Individually: page1!$B$66:$B$67
Name Margin_Pledged: page1!$B$81:$B$82
Name Pledged_For_A_Loan: page1!$B$81:$B$82
Name Registered_In_Name_Of: page1!$B$98:$B$99
Name Registered_In_Name_Of_page2: page2!$A$64:$A$65
Name Type_of_Property: page2!$A$58:$A$61
Name Year: page1!$B$85:$B$87
Name Yes_No: page3!$B$78:$B$79

Sheet INSTRUCTIONS
D1: INSTRUCTIONS
A4: 1. Input in all yellow shaded areas.
A5: 2. Use the 'TAB' or the '←, ↑, →, ↓' keys to move through the worksheet.
A6: 3. Note there are three pages where information should be entered.
A7: Click on the tabs at the bottom of the screen to goto page 2 and 3.
A8: 4. Print out all 3 pages and sign page 3.
A9: 5. If you have questions, please call.
A11: Complete this form for :
A12: 1. Each proprietor
A13: 2. Each general partner and each limited partner with 20% or more interest
A14: 3. Each stockholder owning 20% or more of voting stock
A15: 4. Any person(s) providing a guaranty on a loan

Sheet page1
A2: PERSONAL FINANCIAL STATEMENT
A5: Applicant Name | I5: Home Phone
A6: Street Address | I6: Business Phone
A7: City, State, Zip | I7: Date of Birth
A10: Applicant is applying: | E10: Individually, without a co-signer or guaranty of a relative or other person(s) or entity.
E12: Jointly, with the co-signature or guaranty of one or more persons or entities (including existing guarantors).
C14: NOTE: | D14: (if jointly, BOTH INITIAL HERE)
G16: Applicant's Initials
A20: Financial Condition as of (Date):
A22: ASSETS | G22: LIABILITIES
A23: Cash | C23: Section 1 | E23: =E51 -> 0
A24: Stocks & Bonds | C24: Section 2 | E24: =J60 -> 0
A25: Closely Held Business | C25: Section 2a | E25: =page2!L6 -> 0 | G25: Notes Payable | I25: Section 8 | K25: =page3!J8 -> 0
A26: Tax | C26: Section 3 | E26: =page2!H11 -> 0 | G26: Taxes Owed | I26: Section 3 | K26: =+page2!I11 -> 0
A27: Insurance (Cash Value) | C27: Section 4 | E27: =page2!I20 -> 0 | G27: Insurance Loan | I27: Section 4 | K27: =page2!J20 -> 0
A28: Notes Receivable | C28: Section 5 | E28: =page2!M29 -> 0 | G28: Accounts Payable | I28: Section 9 | K28: =page3!J17 -> 0
A29: Real Estate | C29: Section 6 | E29: =page2!P38 -> 0 | G29: Real Estate Payable | I29: Section 6 | K29: =page2!P43 -> 0
A30: Other Assets | C30: Section 7 | E30: =page2!M52 -> 0 | G30: Other Liabilities | I30: Section 10 | K30: =page3!I24 -> 0
C31: TOTAL ASSETS | E31: =SUM(E23:E30) -> 0 | H31: TOTAL LIABILITIES | K31: =SUM(K25:K30) -> 0
H32: NET WORTH | K32: =E31-K31 -> 0
A34: INCOME AND EXPENSES
A35: Alimony, child support or separate maintenance payment income need not be revealed if you do not wish to have it considered as a basis for repaying this obligation.
A36: Year | E36: Year | I36: Contigent Liabilities
A37: Salary or Wages | E37: Property Tax & Assessment | I37: Endorser on Notes/Contracts
A38: Dividends or Interest | E38: Fed & State Income Tax | I38: Legal Claims & Judgements
A39: Rentals (Gross Income) | E39: Real Estate Loan Payments | I39: Provision For Taxes
A40: Business (Net Income) | E40: Payments on Contract/Notes | I40: Other Special Debt (Describe)
A41: Other Income (Describe) | E41: Estimated Living Expenses
E42: Other:
A43: TOTAL INCOME | C43: =SUM(C37:C42) -> 0 | E43: TOTAL EXPENSES | G43: =SUM(G37:G42) -> 0 | H43: TOTAL | K43: =SUM(K37:K42) -> 0
A45: Section 1 | D45: CASH
A46: Account Type | B46: Bank | E46: Balance | F46: Pledged for a loan?
C51: Total | E51: =SUM(E47:E50) -> 0
A53: Section 2 | D53: STOCKS AND BONDS
E54: Registered in | I54: Purchased on | J54: Total
A55: Description | C55: No. Shares | E55: Name of | F55: Price per share | I55: Margin/Pledged | J55: Value
J56: =F56*C56 -> 0
J57: =F57*C57 -> 0
J58: =F58*C58 -> 0
J59: =F59*C59 -> 0
...

Sheet page2
A1: Section 2a | H1: INTERESTS IN CLOSELY HELD BUSINESS
H2: Registered in | J2: Source and Date | L2: Total
A3: Description | E3: Value of Business | H3: Name of | J3: of Valuation | L3: Value
E4: 0 | K4: 1 | L4: =K4*E4 -> 0
E5: 0 | K5: 1 | L5: =K5*E5 -> 0
L6: =SUM(L4:L5) -> 0
A8: Section 3 | E8: TAXES
H9: Amount of Tax | I9: Amount of Tax
H10: Refund Due | I10: Owed
A13: Section 4 | E13: LIFE INSURANCE
M14: Location of
A15: Insured | E15: Primary Beneficiary | H15: Face Amount | I15: Actual Cash Value | J15: Loans on Policy | K15: Name of Company | M15: Office
J16: 0
J17: 0
J18: 0
J19: 0
F20: Total | H20: =SUM(H16:H19) -> 0 | I20: =SUM(I16:I19) -> 0 | J20: =SUM(J16:J19) -> 0
A22: Section 5 | E22: ACCOUNTS AND NOTES RECEIVABLE
L23: How Payable
A24: Owners | D24: Due From | F24: Address | I24: Collateral | J24: Maturity Date | L24: $ per month | M24: Balance Due
L29: =SUM(L25:L28) -> 0 | M29: =SUM(M25:M28) -> 0
A31: Section 6 | E31: REAL ESTATE OWNED
E32: Property A | H32: Property B | J32: Property C | L32: Property D
A33: Type of Property
A34: Address
A35: Owner
A36: Date Purchased
A37: Original Cost
A38: Present Market Value | P38: =SUM(E38:M38) -> 0
A39: Mortgage Holder
A40: Annual Taxes
A41: Monthly Income
A42: Monthly Payments
A43: Mortgage Balance | P43: =SUM(E43:M43) -> 0
A45: Section 7 | E45: OTHER ASSETS AND PERSONAL PROPERTY
A46: Automobiles | F46: RV / Boats
A47: Year/Make | D47: Value | F47: Year/Make | H47: Value | I47: Personal Prop. | J47: Value | L47: Totals
I48: Furniture | L48: Autos | M48: =D52 -> 0
I49: Jewelry | L49: R/V's | M49: =H52 -> 0
I50: Equipment | L50: Per. Prop. | M50: =J52 -> 0
...

Sheet page3
A1: Section 8 | E1: NOTES AND LOANS PAYABLE TO OTHERS (EXCLUDED REAL ESTATE)
I2: How Payable
A3: Payable To | C3: Address | E3: Collateral | F3: Person(s) Liable | H3: Maturity Date | I3: $ per month | J3: Balance Due
I8: Totals | J8: =SUM(J4:K7) -> 0
A10: Section 9 | E10: ACCOUNTS AND BILLS PAYABLE (Including Bank Cards)
C11: Payable to | E11: Account Number | G11: Person (s) Liable | H11: How Payable $ per month | J11: Balance Due
A12: Bank charge cards
A13: Bank charge cards
A14: Open & Revolving Accts
A15: Open & Revolving Accts
A16: Other
I17: Total | J17: =SUM(J12:K16) -> 0
A19: Section 10 | E19: OTHER LIABILITIES
A20: Payable To | C20: Person(s) Liable | E20: Collateral | G20: How Payable per Month | I20: Balance Due
I24: =SUM(I21:K23) -> 0
A26: APPLICANT INFORMATION
A27: Social Security Number | D27: Employer | F27: Salary | H27: Occupation | K27: No of Years
A31: Alimony, child support or separate maintenance payment income need not be revealed if you do not wish to have it considered as a basis for repaying this obligation.
A32: Alimony - Do you have alimony payments?( yes/no) | G32: Amount?
A34: Have you established a trust? (yes/no)
A36: Have you made a will? (yes/no) | I36: Have you guaranteed or endorsed the notes of any other person ? (yes/ no)
A38: Have any actions or suits been filed against you or are there any unsatisfied judgements or decrees entered against
A39: you, or have you ever been adjudged bankrupt or made any assigments for creditors? (yes/no) | I39: If answered "Yes", please explain:
A41: Explanation:
A43: CO-APPLICANT INFORMATION
A44: Social Security Number | D44: Employer | F44: Salary | H44: Occupation | K44: No of Years
A47: Alimony, child support or separate maintenance payment income need not be revealed if you do not wish to have it considered as a basis for repaying this obligation.
A48: Alimony - Do you have alimony payments?( yes/no)
A50: Have you established a trust? (yes/no)
A52: Have you made a will? (yes/no) | I52: Have you guaranteed or endorsed the notes of any other person ? (yes/ no)
A54: Have any actions or suits been filed against you or are there any unsatisfied judgements or decrees entered against
A55: you, or have you ever been adjudged bankrupt or made any assigments for creditors? (yes/no) | I55: If answered "Yes", please explain:
A57: Explanation:
A59: SIGNATURES
A61: I authorize lender to make inquiries as necessary to verify the accuracy of the statements made and to determine my creditworthiness. I certify the above and the
A62: statements contained in the attachments are true and accurate as of the stated date(s). I understand that Premier Community Bank is relying on this statement
A63: of my financial condition in making loan(s). Premier Community Bank may disclose to any other interested party Lender's experience with this account.
A64: I agree to inform the Lender immediately of any matter which will cause any significant change in my financial condition. I understand that Lender will retain this
A65: financial statement whether or not credit is granted.
B73: Applicant's Signature | E73: Date | G73: Co-Applicant's Signature | J73: Date
...
