Workbook

Sheet Quarterly ProForma Results
A1: Rent-A-Center, Inc.
A2: ProForma Quarterly Financials (10Q Format)
A3: (dollars in thousands, except per share data)
A4: Updated: September 30, 2012
B6: Quarter Ended | J6: FYE | L6: Quarter Ended | T6: FYE | V6: Quarter Ended | AD6: FYE | AF6: Quarter Ended | AN6: FYE | AP6: Quarter Ended | AX6: FYE | AZ6: Quarter Ended | BH6: FYE | BJ6: Quarter Ended | BR6: FYE | BT6: Quarter Ended | CB6: FYE | CD6: Quarter Ended | CL6: FYE | CN6: Quarter Ended | CV6: FYE | CX6: Quarter Ended | DF6: FYE | DH6: Quarter Ended | DP6: FYE | DR6: Quarter Ended | DZ6: FYE | EB6: Quarter Ended | EJ6: FYE
B7: 36250 | D7: 36341 | F7: 36433 | H7: 36525 | J7: 1999 | L7: 36616 | N7: 36707 | P7: 36799 | R7: 36891 | T7: 2000 | V7: 36981 | X7: 37072 | Z7: 37164 | AB7: 37256 | AD7: 2001 | AF7: 37346 | AH7: 37437 | AJ7: 37529 | AL7: 37621 | AN7: 2002 | AP7: 37711 | AR7: 37802 | AT7: 37894 | AV7: 37986 | AX7: 2003 | AZ7: 38077 | BB7: 38168 | BD7: 38260 | BF7: 38352 | BH7: 2004 | BJ7: 38442 | BL7: 38533 | BN7: 38625 | BP7: 38717 | BR7: 2005 | BT7: 38807 | BV7: 38898 | BX7: 38990 | BZ7: 39082 | CB7: 2006 | CD7: 39172 | CF7: 39263 | CH7: 39355 | CJ7: 39447 | CL7: 2007 | CN7: =EOMONTH(CJ7,3) -> 39538 | CP7: =EOMONTH(CN7,3) -> 39629 | CR7: =EOMONTH(CP7,3) -> 39721 | CT7: =EOMONTH(CR7,3) -> 39813 | CV7: 2008 | CX7: =EOMONTH(CT7,3) -> 39903 | CZ7: =EOMONTH(CX7,3) -> 39994 | DB7: =EOMONTH(CZ7,3) -> 40086 | DD7: =EOMONTH(DB7,3) -> 40178 | DF7: =YEAR(DD7) -> 2009 | DH7: =EOMONTH(DD7,3) -> 40268 | DJ7: =EOMONTH(DH7,3) -> 40359 | DL7: =EOMONTH(DJ7,3) -> 40451 | DN7: =EOMONTH(DL7,3) -> 40543 | DP7: =YEAR(DN7) -> 2010 | DR7: =EOMONTH(DN7,3) -> 40633 | DT7: =EOMONTH(DR7,3) -> 40724 | DV7: =EOMONTH(DT7,3) -> 40816 | DX7: =EOMONTH(DV7,3) -> 40908 | DZ7: =YEAR(DX7) -> 2011 | EB7: =EOMONTH(DX7,3) -> 40999 | ED7: =EOMONTH(EB7,3) -> 41090 | EF7: =EOMONTH(ED7,3) -> 41182 | EH7: =EOMONTH(EF7,3) -> 41274 | EJ7: =YEAR(EH7) -> 2012
A8: Store Revenue:
A9: Rentals & Fees | B9: 301707 | D9: 316159 | F9: 318119.1 | H9: 334899.6 | J9: =B9+D9+F9+H9 -> 1270884.7 | L9: 350320.39 | N9: 360227 | P9: 372402 | R9: 376715 | T9: =L9+N9+P9+R9-0.4 -> 1459664 | V9: 393122.91 | X9: 409023.4 | Z9: 411241 | AB9: 437464 | AD9: =V9+X9+Z9+AB9-0.5 -> 1650850.8 | AF9: 443705 | AH9: 456149 | AJ9: 456208 | AL9: 472472 | AN9: =AF9+AH9+AJ9+AL9 -> 1828534 | AP9: 493419 | AR9: 504352 | AT9: 497881 | AV9: 503300 | AX9: =AP9+AR9+AT9+AV9 -> 1998952 | AZ9: 504290 | BB9: 520593 | BD9: 516576 | BF9: 530407 | BH9: =AZ9+BB9+BD9+BF9 -> 2071866 | BJ9: 518622 | BL9: 526639 | BN9: 516433 | BP9: 523063 | BR9: =BJ9+BL9+BN9+BP9 -> 2084757 | BT9: 520383 | BV9: 527076 | BX9: 532260 | BZ9: 594520 | CB9: =BT9+BV9+BX9+BZ9 -> 2174239 | CD9: 660113 | CF9: 662096 | CH9: 631132 | CJ9: 640720 | CL9: =CD9+CF9+CH9+CJ9 -> 2594061 | CN9: 640686 | CP9: 634618 | CR9: 621290 | CT9: 608674 | CV9: =CN9+CP9+CR9+CT9 -> 2505268 | CX9: 597607 | CZ9: 589468 | DB9: 576124 | DD9: 583650 | DF9: =CX9+CZ9+DB9+DD9 -> 2346849 | DH9: 583848 | DJ9: 586523 | DL9: 576019 | DN9: 589106 | DP9: =DH9+DJ9+DL9+DN9 -> 2335496 | DR9: 610428 | DT9: 617796 | DV9: 622474 | DX9: 646165 | DZ9: =DR9+DT9+DV9+DX9 -> 2496863 | EB9: 677981 | ED9: 658987 | EF9: 652059 | EJ9: =EB9+ED9+EF9+EH9 -> 1989027
A10: Merchandise Sales | B10: 31886 | D10: 20293 | F10: 18662.051 | H10: 17675.283 | J10: =B10+D10+F10+H10 -> 88516.334 | L10: 27339.014 | N10: 17680 | P10: 18887 | R10: 17260 | T10: =L10+N10+P10+R10 -> 81166.014 | V10: 30759.44 | X10: 20111.783 | Z10: 21569 | AB10: 22293 | AD10: =V10+X10+Z10+AB10 -> 94733.223 | AF10: 39605 | AH10: 23994 | AJ10: 24710 | AL10: 27169 | AN10: =AF10+AH10+AJ10+AL10 -> 115478 | AP10: 52664 | AR10: 32528 | AT10: 34453 | AV10: 33339 | AX10: =AP10+AR10+AT10+AV10 -> 152984 | AZ10: 59423 | BB10: 34599 | BD10: 36265 | BF10: 36307 | BH10: =AZ10+BB10+BD10+BF10 -> 166594 | BJ10: 62770 | BL10: 37498 | BN10: 39212 | BP10: 37812 | BR10: =BJ10+BL10+BN10+BP10 -> 177292 | BT10: 64163 | BV10: 38428 | BX10: 36343 | BZ10: 37020 | CB10: =BT10+BV10+BX10+BZ10 -> 175954 | CD10: 68337 | CF10: 39584 | CH10: 53574 | CJ10: 47494 | CL10: =CD10+CF10+CH10+CJ10 -> 208989 | CN10: 85339 | CP10: 55703 | CR10: 57062 | CT10: 58627 | CV10: =CN10+CP10+CR10+CT10 -> 256731 | CX10: 95782 | CZ10: 56959 | DB10: 59085 | DD10: 49805 | DF10: =CX10+CZ10+DB10+DD10 -> 261631 | DH10: 89397 | DJ10: 43031 | DL10: 44352 | DN10: 43549 | DP10: =DH10+DJ10+DL10+DN10 -> 220329 | DR10: 99266 | DT10: 50973 | DV10: 52802 | DX10: 56755 | DZ10: =DR10+DT10+DV10+DX10 -> 259796 | EB10: 122859 | ED10: 60622 | EF10: 58854 | EJ10: =EB10+ED10+EF10+EH10 -> 242335
A11: Installment Sales | J11: =B11+D11+F11+H11 -> 0 | T11: =L11+N11+P11+R11 -> 0 | AD11: =V11+X11+Z11+AB11 -> 0 | AL11: 6137 | AN11: =AF11+AH11+AJ11+AL11 -> 6137 | AP11: 6045 | AR11: 4745 | AT11: 4633 | AV11: 6780 | AX11: =AP11+AR11+AT11+AV11 -> 22203 | AZ11: 6698 | BB11: 5801 | BD11: 5469 | BF11: 6336 | BH11: =AZ11+BB11+BD11+BF11 -> 24304 | BJ11: 6584 | BL11: 6618 | BN11: 6372 | BP11: 6566 | BR11: =BJ11+BL11+BN11+BP11 -> 26140 | BT11: 5851 | BV11: 5728 | BX11: 6798 | BZ11: 8500 | CB11: =BT11+BV11+BX11+BZ11 -> 26877 | CD11: 8410 | CF11: 7646 | CH11: 8593 | CJ11: 9927 | CL11: =CD11+CF11+CH11+CJ11 -> 34576 | CN11: 9885 | CP11: 9246 | CR11: 10554 | CT11: 11508 | CV11: =CN11+CP11+CR11+CT11 -> 41193 | CX11: 12426 | CZ11: 12290 | DB11: 12983 | DD11: 15336 | DF11: =CX11+CZ11+DB11+DD11 -> 53035 | DH11: 15137 | DJ11: 14503 | DL11: 15599 | DN11: 18594 | DP11: =DH11+DJ11+DL11+DN11 -> 63833 | DR11: 16687 | DT11: 16571 | DV11: 16348 | DX11: 19011 | DZ11: =DR11+DT11+DV11+DX11 -> 68617 | EB11: 17495 | ED11: 16170 | EF11: 15560 | EJ11: =EB11+ED11+EF11+EH11 -> 49225
A12: Other | B12: 858 | D12: 462 | F12: 404.188 | H12: 452.932 | J12: =B12+D12+F12+H12 -> 2177.12 | L12: 492.11491 | N12: 502 | P12: 922 | R12: 1102 | T12: =L12+N12+P12+R12 -> 3018.1149 | V12: 1329.9978 | X12: 908.14399 | Z12: 640 | AB12: 598 | AD12: =V12+X12+Z12+AB12 -> 3476.1418 | AF12: 614 | AH12: 567 | AJ12: 561 | AL12: 847 | AN12: =AF12+AH12+AJ12+AL12 -> 2589 | AP12: 715 | AR12: 812 | AT12: 697 | AV12: 859 | AX12: =AP12+AR12+AT12+AV12 -> 3083 | AZ12: 1080 | BB12: 967 | BD12: 919 | BF12: 602 | BH12: =AZ12+BB12+BD12+BF12 -> 3568 | BJ12: 1078 | BL12: 997 | BN12: 2938 | BP12: 2889 | BR12: =BJ12+BL12+BN12+BP12 -> 7902 | BT12: 3286 | BV12: 3254 | BX12: 3723 | BZ12: 5344 | CB12: =BT12+BV12+BX12+BZ12 -> 15607 | CD12: 7176 | CF12: 6570 | CH12: 3940 | CJ12: 7796 | CL12: =CD12+CF12+CH12+CJ12 -> 25482 | CN12: 9619 | CP12: 10589 | CR12: 10704 | CT12: 11847 | CV12: =CN12+CP12+CR12+CT12 -> 42759 | CX12: 13139 | CZ12: 13443 | DB12: 15236 | DD12: 15783 | DF12: =CX12+CZ12+DB12+DD12 -> 57601 | DH12: 20336 | DJ12: 19523 | DL12: 20413 | DN12: 16270 | DP12: =DH12+DJ12+DL12+DN12 -> 76542 | DR12: 5339 | DT12: 4143 | DV12: 4147 | DX12: 4296 | DZ12: =DR12+DT12+DV12+DX12 -> 17925 | EB12: 4932 | ED12: 4537 | EF12: 2811 | EJ12: =EB12+ED12+EF12+EH12 -> 12280
A13: Total Store Revenue | B13: =SUM(B9:B12) -> 334451 | D13: =SUM(D9:D12) -> 336914 | F13: =SUM(F9:F12) -> 337185.34 | H13: =SUM(H9:H12) -> 353027.81 | J13: =SUM(J9:J12) -> 1361578.2 | L13: =SUM(L9:L12) -> 378151.52 | N13: =SUM(N9:N12) -> 378409 | P13: =SUM(P9:P12) -> 392211 | R13: =SUM(R9:R12) -> 395077 | T13: =SUM(T9:T12) -> 1543848.1 | V13: =SUM(V9:V12) -> 425212.35 | X13: =SUM(X9:X12) -> 430043.33 | Z13: =SUM(Z9:Z12) -> 433450 | AB13: =SUM(AB9:AB12) -> 460355 | AD13: =SUM(AD9:AD12) -> 1749060.2 | AF13: =SUM(AF9:AF12) -> 483924 | AH13: =SUM(AH9:AH12) -> 480710 | AJ13: =SUM(AJ9:AJ12) -> 481479 | AL13: =SUM(AL9:AL12) -> 506625 | AN13: =SUM(AN9:AN12) -> 1952738 | AP13: =SUM(AP9:AP12) -> 552843 | AR13: =SUM(AR9:AR12) -> 542437 | AT13: =SUM(AT9:AT12) -> 537664 | AV13: =SUM(AV9:AV12) -> 544278 | AX13: =SUM(AX9:AX12) -> 2177222 | AZ13: =SUM(AZ9:AZ12) -> 571491 | BB13: =SUM(BB9:BB12) -> 561960 | BD13: =SUM(BD9:BD12) -> 559229 | BF13: =SUM(BF9:BF12) -> 573652 | BH13: =SUM(BH9:BH12) -> 2266332 | BJ13: =SUM(BJ9:BJ12) -> 589054 | BL13: =SUM(BL9:BL12) -> 571752 | BN13: =SUM(BN9:BN12) -> 564955 | BP13: =SUM(BP9:BP12) -> 570330 | BR13: =SUM(BR9:BR12) -> 2296091 | BT13: =SUM(BT9:BT12) -> 593683 | BV13: =SUM(BV9:BV12) -> 574486 | BX13: =SUM(BX9:BX12) -> 579124 | BZ13: =SUM(BZ9:BZ12) -> 645384 | CB13: =SUM(CB9:CB12) -> 2392677 | CD13: =SUM(CD9:CD12) -> 744036 | CF13: =SUM(CF9:CF12) -> 715896 | CH13: =SUM(CH9:CH12) -> 697239 | CJ13: =SUM(CJ9:CJ12) -> 705937 | CL13: =SUM(CL9:CL12) -> 2863108 | CN13: =SUM(CN9:CN12) -> 745529 | CP13: =SUM(CP9:CP12) -> 710156 | CR13: =SUM(CR9:CR12) -> 699610 | CT13: =SUM(CT9:CT12) -> 690656 | CV13: =SUM(CV9:CV12) -> 2845951 | CX13: =SUM(CX9:CX12) -> 718954 | CZ13: =SUM(CZ9:CZ12) -> 672160 | DB13: =SUM(DB9:DB12) -> 663428 | DD13: =SUM(DD9:DD12) -> 664574 | DF13: =SUM(DF9:DF12) -> 2719116 | DH13: =SUM(DH9:DH12) -> 708718 | DJ13: =SUM(DJ9:DJ12) -> 663580 | DL13: =SUM(DL9:DL12) -> 656383 | DN13: =SUM(DN9:DN12) -> 667519 | DP13: =SUM(DP9:DP12) -> 2696200 | DR13: =SUM(DR9:DR12) -> 731720 | DT13: =SUM(DT9:DT12) -> 689483 | DV13: =SUM(DV9:DV12) -> 695771 | DX13: =SUM(DX9:DX12) -> 726227 | DZ13: =SUM(DZ9:DZ12) -> 2843201 | EB13: =SUM(EB9:EB12) -> 823267 | ED13: =SUM(ED9:ED12) -> 740316 | EF13: =SUM(EF9:EF12) -> 729284 | EH13: =SUM(EH9:EH12) -> 0 | EJ13: =SUM(EJ9:EJ12) -> 2292867
A15: Franchise Revenue:
A16: Merchandise Sales | B16: 8821 | D16: 13000 | F16: 11678.597 | H16: 16195.564 | J16: =B16+D16+F16+H16+0.5 -> 49695.661 | L16: 12890.63 | N16: 12321 | P16: 11143 | R16: 15414 | T16: =L16+N16+P16+R16 -> 51768.63 | V16: 13026.887 | X16: 11231.709 | Z16: 12087 | AB16: 17238 | AD16: =V16+X16+Z16+AB16 -> 53583.596 | AF16: 13253 | AH16: 12486 | AJ16: 11566 | AL16: 14209 | AN16: =AF16+AH16+AJ16+AL16 -> 51514 | AP16: 12072 | AR16: 9261 | AT16: 10754 | AV16: 12970 | AX16: =AP16+AR16+AT16+AV16 -> 45057 | AZ16: 12464 | BB16: 9668 | BD16: 8967 | BF16: 10299 | BH16: =AZ16+BB16+BD16+BF16 -> 41398 | BJ16: 11344 | BL16: 7443 | BN16: 7245 | BP16: 11762 | BR16: =BJ16+BL16+BN16+BP16 -> 37794 | BT16: 12081 | BV16: 7892 | BX16: 6779 | BZ16: 9625 | CB16: =BT16+BV16+BX16+BZ16 -> 36377 | CD16: 9925 | CF16: 6955 | CH16: 7376 | CJ16: 9973 | CL16: =CD16+CF16+CH16+CJ16 -> 34229 | CN16: 9767 | CP16: 7650 | CR16: 7969 | CT16: 7897 | CV16: =CN16+CP16+CR16+CT16 -> 33283 | CX16: 7958 | CZ16: 6251 | DB16: 6663 | DD16: 7193 | DF16: =CX16+CZ16+DB16+DD16 -> 28065 | DH16: 8425 | DJ16: 6755 | DL16: 6975 | DN16: 8420 | DP16: =DH16+DJ16+DL16+DN16 -> 30575 | DR16: 9146 | DT16: 7525 | DV16: 7250 | DX16: 10051 | DZ16: =DR16+DT16+DV16+DX16 -> 33972 | EB16: 10613 | ED16: 8022 | EF16: 8697 | EJ16: =EB16+ED16+EF16+EH16 -> 27332
A17: Royalty Income and Fees | B17: 1425 | D17: 1507 | F17: 1555.673 | H17: 1405.327 | J17: =B17+D17+F17+H17 -> 5893 | L17: 1484.0533 | N17: 1515 | P17: 1614 | R17: 1384 | T17: =L17+N17+P17+R17 -> 5997.0533 | V17: 1463.112 | X17: 1483.718 | Z17: 1537 | AB17: 1400 | AD17: =V17+X17+Z17+AB17 -> 5883.83 | AF17: 1433 | AH17: 1464 | AJ17: 1516 | AL17: 1379 | AN17: =AF17+AH17+AJ17+AL17 -> 5792 | AP17: 1491 | AR17: 1562 | AT17: 1407 | AV17: 1411 | AX17: =AP17+AR17+AT17+AV17 -> 5871 | AZ17: 1425 | BB17: 1357 | BD17: 1411 | BF17: 1332 | BH17: =AZ17+BB17+BD17+BF17 -> 5525 | BJ17: 1411 | BL17: 1383 | BN17: 1307 | BP17: 1121 | BR17: =BJ17+BL17+BN17+BP17 -> 5222 | BT17: 1211 | BV17: 1245 | BX17: 1281 | BZ17: 1117 | CB17: =BT17+BV17+BX17+BZ17 -> 4854 | CD17: 1338 | CF17: 1307 | CH17: =5086-3900 -> 1186 | CI17: (2) | CJ17: 1053 | CL17: =CD17+CF17+CH17+CJ17 -> 4884 | CM17: (2) | CN17: 1340 | CP17: 1225 | CR17: 1176 | CT17: 1197 | CV17: =CN17+CP17+CR17+CT17 -> 4938 | CX17: 1271 | CZ17: 1198 | DB17: 1160 | DD17: 1146 | DF17: =CX17+CZ17+DB17+DD17 -> 4775 | DH17: 1276 | DJ17: 1208 | DL17: 1222 | DN17: 1151 | DP17: =DH17+DJ17+DL17+DN17 -> 4857 | DR17: 1312 | DT17: 1245 | DV17: 1250 | DX17: 1204 | DZ17: =DR17+DT17+DV17+DX17 -> 5011 | EB17: 1374 | ED17: 1360 | EF17: 1333 | EJ17: =EB17+ED17+EF17+EH17 -> 4067
A19: Total Revenue | B19: =B13+B16+B17 -> 344697 | D19: =D13+D16+D17 -> 351421 | F19: =F13+F16+F17 -> 350419.61 | H19: =H13+H16+H17 -> 370628.7 | J19: =J13+J16+J17 -> 1417166.8 | L19: =L13+L16+L17 -> 392526.21 | N19: =N13+N16+N17 -> 392245 | P19: =P13+P16+P17 -> 404968 | R19: =R13+R16+R17 -> 411875 | T19: =T13+T16+T17 -> 1601613.8 | V19: =V13+V16+V17 -> 439702.34 | X19: =X13+X16+X17 -> 442758.75 | Z19: =Z13+Z16+Z17 -> 447074 | AB19: =AB13+AB16+AB17 -> 478993 | AD19: =AD13+AD16+AD17 -> 1808527.6 | AF19: =AF13+AF16+AF17 -> 498610 | AH19: =AH13+AH16+AH17 -> 494660 | AJ19: =AJ13+AJ16+AJ17 -> 494561 | AL19: =AL13+AL16+AL17 -> 522213 | AN19: =AN13+AN16+AN17 -> 2010044 | AP19: =AP13+AP16+AP17 -> 566406 | AR19: =AR13+AR16+AR17 -> 553260 | AT19: =AT13+AT16+AT17 -> 549825 | AV19: =AV13+AV16+AV17 -> 558659 | AX19: =AX13+AX16+AX17 -> 2228150 | AZ19: =AZ13+AZ16+AZ17 -> 585380 | BB19: =BB13+BB16+BB17 -> 572985 | BD19: =BD13+BD16+BD17 -> 569607 | BF19: =BF13+BF16+BF17 -> 585283 | BH19: =BH13+BH16+BH17 -> 2313255 | BJ19: =BJ13+BJ16+BJ17 -> 601809 | BL19: =BL13+BL16+BL17 -> 580578 | BN19: =BN13+BN16+BN17 -> 573507 | BP19: =BP13+BP16+BP17 -> 583213 | BR19: =BR13+BR16+BR17 -> 2339107 | BT19: =BT13+BT16+BT17 -> 606975 | BV19: =BV13+BV16+BV17 -> 583623 | BX19: =BX13+BX16+BX17 -> 587184 | BZ19: =BZ13+BZ16+BZ17 -> 656126 | CB19: =CB13+CB16+CB17 -> 2433908 | CD19: =CD13+CD16+CD17 -> 755299 | CF19: =CF13+CF16+CF17 -> 724158 | CH19: =CH13+CH16+CH17 -> 705801 | CJ19: =CJ13+CJ16+CJ17 -> 716963 | CL19: =CL13+CL16+CL17 -> 2902221 | CN19: =CN13+CN16+CN17 -> 756636 | CP19: =CP13+CP16+CP17 -> 719031 | CR19: =CR13+CR16+CR17 -> 708755 | CT19: =CT13+CT16+CT17 -> 699750 | CV19: =CV13+CV16+CV17 -> 2884172 | CX19: =CX13+CX16+CX17 -> 728183 | CZ19: =CZ13+CZ16+CZ17 -> 679609 | DB19: =DB13+DB16+DB17 -> 671251 | DD19: =DD13+DD16+DD17 -> 672913 | DF19: =DF13+DF16+DF17 -> 2751956 | DH19: =DH13+DH16+DH17 -> 718419 | DJ19: =DJ13+DJ16+DJ17 -> 671543 | DL19: =DL13+DL16+DL17 -> 664580 | DN19: =DN13+DN16+DN17 -> 677090 | DP19: =DP13+DP16+DP17 -> 2731632 | DR19: =DR13+DR16+DR17 -> 742178 | DT19: =DT13+DT16+DT17 -> 698253 | DV19: =DV13+DV16+DV17 -> 704271 | DX19: =DX13+DX16+DX17 -> 737482 | DZ19: =DZ13+DZ16+DZ17 -> 2882184 | EB19: =EB13+EB16+EB17 -> 835254 | ED19: =ED13+ED16+ED17 -> 749698 | EF19: =EF13+EF16+EF17 -> 739314 | EH19: =EH13+EH16+EH17 -> 0 | EJ19: =EJ13+EJ16+EJ17 -> 2324266
A21: Operating Expenses:
A22: Direct Store Expenses
A23: Cost of Rental and Fees | B23: 64466 | D23: 66438 | F23: 65910.653 | H23: 68671.347 | J23: =B23+D23+F23+H23 -> 265486 | L23: 71728.338 | N23: 73803 | P23: 77014 | R23: 76753 | T23: =L23+N23+P23+R23-0.4 -> 299297.94 | V23: 80812.117 | X23: 84276.018 | Z23: 86198 | AB23: 91911 | AD23: =V23+X23+Z23+AB23 -> 343197.14 | AF23: 92223 | AH23: 94354 | AJ23: 95508 | AL23: 101315 | AN23: =AF23+AH23+AJ23+AL23 -> 383400 | AP23: 106660 | AR23: 109341 | AT23: 107777 | AV23: 108918 | AX23: =AP23+AR23+AT23+AV23 -> 432696 | AZ23: 108543 | BB23: 112743 | BD23: 112582 | BF23: 116167 | BH23: =AZ23+BB23+BD23+BF23 -> 450035 | BJ23: 112468 | BL23: 114068 | BN23: 112174 | BP23: 113873 | BR23: =BJ23+BL23+BN23+BP23 -> 452583 | BT23: 112767 | BV23: 114733 | BX23: 117018 | BZ23: 131944 | CB23: =BT23+BV23+BX23+BZ23 -> 476462 | CD23: 143069 | CF23: 145927 | CH23: 140219 | CJ23: 144798 | CL23: =CD23+CF23+CH23+CJ23 -> 574013 | CN23: 146162 | CP23: 145511 | CR23: 142314 | CT23: 138913 | CV23: =CN23+CP23+CR23+CT23 -> 572900 | CX23: 135139 | CZ23: 132956 | DB23: 130183 | DD23: 131740 | DF23: =CX23+CZ23+DB23+DD23 -> 530018 | DH23: 130114 | DJ23: 129818 | DL23: 127573 | DN23: 131777 | DP23: =DH23+DJ23+DL23+DN23 -> 519282 | DR23: 135649 | DT23: 139295 | DV23: 142796 | DX23: 152753 | DZ23: =DR23+DT23+DV23+DX23 -> 570493 | EB23: 163359 | ED23: 159790 | EF23: 158805 | EJ23: =EB23+ED23+EF23+EH23 -> 481954
A24: Cost of Merchandise Sold | B24: 25916 | D24: 17422 | F24: 15664.141 | H24: 15025.125 | J24: =B24+D24+F24+H24 -> 74027.266 | L24: 22830.329 | N24: 14566 | P24: 14348 | R24: 13588 | T24: =L24+N24+P24+R24 -> 65332.329 | V24: 21555.25 | X24: 15444.749 | Z24: 17176 | AB24: 18363 | AD24: =V24+X24+Z24+AB24 -> 72538.999 | AF24: 26982 | AH24: 17497 | AJ24: 18471 | AL24: 21678 | AN24: =AF24+AH24+AJ24+AL24 -> 84628 | AP24: 36548 | AR24: 24235 | AT24: 25901 | AV24: 25599 | AX24: =AP24+AR24+AT24+AV24 -> 112283 | AZ24: 39383 | BB24: 24720 | BD24: 26978 | BF24: 28017 | BH24: =AZ24+BB24+BD24+BF24 -> 119098 | BJ24: 42067 | BL24: 28225 | BN24: 30314 | BP24: 29018 | BR24: =BJ24+BL24+BN24+BP24 -> 129624 | BT24: 44130 | BV24: 28403 | BX24: 28422 | BZ24: 30473 | CB24: =BT24+BV24+BX24+BZ24 -> 131428 | CD24: 46030 | CF24: 29948 | CH24: 41065 | CJ24: 39460 | CL24: =CD24+CF24+CH24+CJ24 -> 156503 | CN24: 63325 | CP24: 45167 | CR24: 44714 | CT24: 41389 | CV24: =CN24+CP24+CR24+CT24 -> 194595 | CX24: 65767 | CZ24: 41997 | DB24: 42940 | DD24: 37729 | DF24: =CX24+CZ24+DB24+DD24 -> 188433 | DH24: 61811 | DJ24: 32603 | DL24: 34807 | DN24: 34912 | DP24: =DH24+DJ24+DL24+DN24 -> 164133 | DR24: 68579 | DT24: 39510 | DV24: 43170 | DX24: 50595 | DZ24: =DR24+DT24+DV24+DX24 -> 201854 | EB24: 95016 | ED24: 49525 | EF24: 47497 | EJ24: =EB24+ED24+EF24+EH24 -> 192038
A25: Cost of Installment Sales | J25: =B25+D25+F25+H25 -> 0 | T25: =L25+N25+P25+R25 -> 0 | AD25: =V25+X25+Z25+AB25 -> 0 | AL25: 3776 | AN25: =AF25+AH25+AJ25+AL25 -> 3776 | AP25: 3231 | AR25: 2090 | AT25: 2120 | AV25: 3198 | AX25: =AP25+AR25+AT25+AV25 -> 10639 | AZ25: 3145 | BB25: 2477 | BD25: 2180 | BF25: 2710 | BH25: =AZ25+BB25+BD25+BF25 -> 10512 | BJ25: 2863 | BL25: 2750 | BN25: 2556 | BP25: 2720 | BR25: =BJ25+BL25+BN25+BP25 -> 10889 | BT25: 2423 | BV25: 2398 | BX25: 2856 | BZ25: 3669 | CB25: =BT25+BV25+BX25+BZ25 -> 11346 | CD25: 3545 | CF25: 3129 | CH25: 2822 | CJ25: 3774 | CL25: =CD25+CF25+CH25+CJ25 -> 13270 | CN25: 4020 | CP25: 3790 | CR25: 4065 | CT25: 4745 | CV25: =CN25+CP25+CR25+CT25 -> 16620 | CX25: 4431 | CZ25: 4259 | DB25: 4511 | DD25: 5486 | DF25: =CX25+CZ25+DB25+DD25 -> 18687 | DH25: 5426 | DJ25: 5003 | DL25: 5507 | DN25: 7367 | DP25: =DH25+DJ25+DL25+DN25 -> 23303 | DR25: 6048 | DT25: 5898 | DV25: 5655 | DX25: 7233 | DZ25: =DR25+DT25+DV25+DX25 -> 24834 | EB25: 6298 | ED25: 5728 | EF25: 5376 | EJ25: =EB25+ED25+EF25+EH25 -> 17402
A26: Salaries and Other Expenses | B26: 186430 | D26: 191682 | F26: 191803.95 | H26: 200657.05 | J26: =B26+D26+F26+H26-0.6 -> 770572.4 | L26: 208524.9 | N26: 211321 | P26: 219195 | R26: 227193 | T26: =L26+N26+P26+R26 -> 866233.9 | V26: 242218.5 | X26: 244365 | Z26: 261992 | AB26: 270826 | AD26: =V26+X26+Z26+AB26-0.5 -> 1019401 | AF26: 262619 | AH26: 264478 | AJ26: 268552 | AL26: 274616 | AN26: =AF26+AH26+AJ26+AL26 -> 1070265 | AP26: 292496 | AR26: 291726 | AT26: 296427 | AV26: 299466 | AX26: =AP26+AR26+AT26+AV26 -> 1180115 | AZ26: 309084 | BB26: 311058 | BD26: 326410 | BF26: 331374 | BH26: =AZ26+BB26+BD26+BF26 -> 1277926 | BJ26: 334041 | BL26: 332939 | BN26: =350389-4075 -> 346314 | BO26: -3 | BP26: =341391-1124 -> 340267 | BQ26: -5 | BR26: =BJ26+BL26+BN26+BP26 -> 1353561 | BS26: (3) (5) | BT26: 338771 | BV26: 333113 | BX26: 340379 | BZ26: 373174 | CB26: =BT26+BV26+BX26+BZ26 -> 1385437 | CD26: 420727 | CF26: 417114 | CH26: 422294 | CJ26: 424830 | CL26: =CD26+CF26+CH26+CJ26 -> 1684965 | CN26: 417414 | CP26: 406572 | CR26: 417354 | CT26: 410465 | CV26: =CN26+CP26+CR26+CT26 -> 1651805 | CX26: 401508 | CZ26: 384910 | DB26: 389573 | DD26: 380083 | DF26: =CX26+CZ26+DB26+DD26 -> 1556074 | DH26: 391471 | DJ26: 381121 | DL26: 389295 | DN26: 381504 | DP26: =DH26+DJ26+DL26+DN26 -> 1543391 | DR26: 397198 | DT26: 395091 | DV26: 405633 | DX26: 396558 | DZ26: =DR26+DT26+DV26+DX26 -> 1594480 | EB26: 430803 | ED26: 412035 | EF26: 412567 | EJ26: =EB26+ED26+EF26+EH26 -> 1255405
A27: Franchise Operating Expenses
A28: Cost of Merchandise Sales | B28: 8542 | D28: 12635 | F28: 11316 | H28: 15420 | J28: =B28+D28+F28+H28+0.5 -> 47913.5 | L28: 12441.322 | N28: 11793 | P28: 10815 | R28: 14675 | T28: =L28+N28+P28+R28 -> 49724.322 | V28: 12494.066 | X28: 10703.138 | Z28: 11624 | AB28: 16430 | AD28: =V28+X28+Z28+AB28 -> 51251.204 | AF28: 12653 | AH28: 11884 | AJ28: 11061 | AL28: 13587 | AN28: =AF28+AH28+AJ28+AL28 -> 49185 | AP28: 11551 | AR28: 8946 | AT28: 10298 | AV28: 12453 | AX28: =AP28+AR28+AT28+AV28 -> 43248 | AZ28: 11892 | BB28: 9214 | BD28: 8585 | BF28: 9781 | BH28: =AZ28+BB28+BD28+BF28 -> 39472 | BJ28: 10866 | BL28: 7163 | BN28: 6964 | BP28: 11326 | BR28: =BJ28+BL28+BN28+BP28 -> 36319 | BT28: 11556 | BV28: 7580 | BX28: 6523 | BZ28: 9203 | CB28: =BT28+BV28+BX28+BZ28 -> 34862 | CD28: 9487 | CF28: 6663 | CH28: 7072 | CJ28: 9511 | CL28: =CD28+CF28+CH28+CJ28 -> 32733 | CN28: 9396 | CP28: 7234 | CR28: 7640 | CT28: 7435 | CV28: =CN28+CP28+CR28+CT28 -> 31705 | CX28: 7634 | CZ28: 5975 | DB28: 6378 | DD28: 6833 | DF28: =CX28+CZ28+DB28+DD28 -> 26820 | DH28: 8068 | DJ28: 6454 | DL28: 6680 | DN28: 8040 | DP28: =DH28+DJ28+DL28+DN28 -> 29242 | DR28: 8754 | DT28: 7195 | DV28: 6926 | DX28: 9612 | DZ28: =DR28+DT28+DV28+DX28 -> 32487 | EB28: 10164 | ED28: 7682 | EF28: 8295 | EJ28: =EB28+ED28+EF28+EH28 -> 26141
A30: Significant Items | B30: 0 | D30: 0 | F30: 0 | H30: 0 | J30: =B30+D30+F30+H30 -> 0 | L30: 0 | N30: 0 | O30: (1) | P30: 0 | R30: 0 | T30: =L30+N30+P30+R30 -> 0 | U30: (1) | V30: 0 | X30: 0 | Z30: 0 | AA30: (1) | AB30: 0 | AC30: (2) | AD30: =V30+X30+Z30+AB30 -> 0 | AE30: (1)(2) | AF30: 0 | AH30: 0 | AJ30: 0 | AL30: 0 | AN30: =AF30+AH30+AJ30+AL30 -> 0 | AP30: 0 | AR30: 0 | AT30: 0 | AV30: 0 | AX30: =AP30+AR30+AT30+AV30 -> 0 | AZ30: 0 | BB30: 0 | BD30: 0 | BF30: 0 | BH30: =AZ30+BB30+BD30+BF30 -> 0 | BJ30: 0 | BK30: -1 | BL30: 0 | BN30: 0 | BO30: -4 | BP30: 0 | BQ30: -6 | BR30: =BJ30+BL30+BN30+BP30 -> 0 | BS30: (1) (4) (6) | BT30: 0 | BV30: 0 | BX30: 0 | BY30: (1) (2) | CA30: -4 | CB30: =BT30+BV30+BX30+BZ30 -> 0 | CC30: (1) (2) (4) | CD30: 0 | CE30: -1 | CF30: 0 | CH30: 0 | CJ30: 0 | CK30: (3)(4) | CL30: =CD30+CF30+CH30+CJ30 -> 0 | CM30: (1)(3)(4) | CN30: 0 | CO30: (1) | CP30: 0 | CQ30: (2) | CR30: 0 | CS30: (3) | CU30: (4)(5) | CV30: =CN30+CP30+CR30+CT30 -> 0 | CW30: (1)(2)(3)(4)(5) | CX30: 0 | CY30: (1) | CZ30: 0 | DA30: (2) | DB30: 0 | DD30: 0 | DF30: =CX30+CZ30+DB30+DD30 -> 0 | DG30: (1)(2) | DH30: 0 | DJ30: 0 | DL30: 0 | DN30: 0 | DO30: (1) | DP30: =DH30+DJ30+DL30+DN30 -> 0 | DQ30: (1) | DR30: 0 | DS30: (1)(2) | DT30: 0 | DU30: (3) | DV30: 0 | DW30: (4) | DX30: 0 | DY30: (5) | DZ30: =DR30+DT30+DV30+DX30 -> 0 | EA30: (1,2,3,4,5) | EB30: 0 | EJ30: =EB30+ED30+EF30+EH30 -> 0
A31: General & Administrative Expenses | B31: 11251 | D31: 10600 | F31: 9920 | H31: 10257.63 | J31: =B31+D31+F31+H31 -> 42028.63 | L31: 11475.058 | N31: 12006 | P31: 12708 | R31: 11904 | T31: =L31+N31+P31+R31 -> 48093.058 | V31: 12869.114 | X31: 13934.133 | Z31: 13974 | AB31: 14582 | AD31: =V31+X31+Z31+AB31 -> 55359.247 | AF31: 15117 | AH31: 15285 | AI31: (1) | AJ31: 15325 | AL31: 15569 | AN31: =AF31+AH31+AJ31+AL31 -> 61296 | AO31: (1) | AP31: 16756 | AR31: 16388 | AT31: 16617 | AV31: 16874 | AX31: =AP31+AR31+AT31+AV31 -> 66635 | AZ31: 18186 | BB31: 19392 | BD31: 18772 | BF31: 19131 | BH31: =AZ31+BB31+BD31+BF31 -> 75481 | BJ31: 19215 | BL31: 20290 | BN31: =21176 -> 21176 | BP31: 21609 | BR31: =BJ31+BL31+BN31+BP31 -> 82290 | BT31: 20958 | BV31: 21253 | BX31: 23806 | BZ31: 27539 | CB31: =BT31+BV31+BX31+BZ31 -> 93556 | CD31: 30998 | CF31: 30419 | CH31: 31701 | CJ31: 30585 | CL31: =CD31+CF31+CH31+CJ31 -> 123703 | CN31: 30949 | CP31: 32676 | CR31: 30361 | CT31: 31646 | CV31: =CN31+CP31+CR31+CT31 -> 125632 | CX31: 34275 | CZ31: 34592 | DB31: 32714 | DD31: 36045 | DF31: =CX31+CZ31+DB31+DD31 -> 137626 | DH31: 31775 | DJ31: 32173 | DL31: 30796 | DN31: 31575 | DP31: =DH31+DJ31+DL31+DN31 -> 126319 | DR31: 34553 | DT31: 32047 | DV31: 33448 | DX31: 36093 | DZ31: =DR31+DT31+DV31+DX31 -> 136141 | EB31: 36245 | ED31: 34430 | EF31: 36214 | EJ31: =EB31+ED31+EF31+EH31 -> 106889
A32: Amortization & Write-down of Intangibles | B32: 6390 | D32: 6856 | F32: 6845.349 | H32: 7024.651 | J32: =B32+D32+F32+H32 -> 27116 | L32: 6974.5302 | N32: 6955 | P32: 7168 | R32: 7205 | T32: =L32+N32+P32+R32 -> 28302.53 | V32: 7268 | X32: 7396.1364 | Z32: 7738 | AB32: 7792 | AD32: =V32+X32+Z32+AB32 -> 30194.136 | AF32: 720 | AH32: 922 | AJ32: 1557 | AL32: 1846 | AN32: =AF32+AH32+AJ32+AL32 -> 5045 | AP32: 2873 | AR32: 3296 | AT32: 3183 | AV32: 3160 | AX32: =AP32+AR32+AT32+AV32 -> 12512 | AZ32: 2488 | BB32: 3158 | BD32: 2756 | BF32: 2378 | BH32: =AZ32+BB32+BD32+BF32 -> 10780 | BJ32: 2297 | BL32: 2155 | BN32: 2259 | BO32: -3 | BP32: =1327 -> 1327 | BR32: =BJ32+BL32+BN32+BP32 -> 8038 | BS32: -3 | BT32: 886 | BV32: 950 | BX32: 1009 | BZ32: 2728 | CB32: =BT32+BV32+BX32+BZ32 -> 5573 | CD32: 4038 | CF32: 3934 | CH32: 3953 | CJ32: 3809 | CL32: =CD32+CF32+CH32+CJ32 -> 15734 | CN32: 4930 | CP32: 3662 | CR32: 3545 | CT32: 4500 | CV32: =CN32+CP32+CR32+CT32 -> 16637 | CX32: 337 | CZ32: 1506 | DB32: 585 | DD32: 415 | DF32: =CX32+CZ32+DB32+DD32 -> 2843 | DH32: 1051 | DJ32: 1540 | DL32: 529 | DN32: 134 | DP32: =DH32+DJ32+DL32+DN32 -> 3254 | DR32: 858 | DT32: 1132 | DV32: 1261 | DX32: 1424 | DZ32: =DR32+DT32+DV32+DX32 -> 4675 | EB32: 1335 | ED32: 1481 | EF32: 2447 | EJ32: =EB32+ED32+EF32+EH32 -> 5263
A34: Total Operating Expenses | B34: =SUM(B23:B32) -> 302995 | D34: =SUM(D23:D32) -> 305633 | F34: =SUM(F23:F32) -> 301460.09 | H34: =SUM(H23:H32) -> 317055.8 | J34: =SUM(J23:J32) -> 1227143.8 | L34: =SUM(L23:L32) -> 333974.48 | N34: =SUM(N23:N32) -> 330444 | P34: =SUM(P23:P32) -> 341248 | R34: =SUM(R23:R32) -> 351318 | T34: =SUM(T23:T32) -> 1356984.1 | V34: =SUM(V23:V32) -> 377217.05 | X34: =SUM(X23:X32) -> 376119.17 | Z34: =SUM(Z23:Z32) -> 398702 | AB34: =SUM(AB23:AB32) -> 419904 | AD34: =SUM(AD23:AD32) -> 1571941.7 | AF34: =SUM(AF23:AF32) -> 410314 | AH34: =SUM(AH23:AH32) -> 404420 | AJ34: =SUM(AJ23:AJ32) -> 410474 | AL34: =SUM(AL23:AL32) -> 432387 | AN34: =SUM(AN23:AN32) -> 1657595 | AP34: =SUM(AP23:AP32) -> 470115 | AR34: =SUM(AR23:AR32) -> 456022 | AT34: =SUM(AT23:AT32) -> 462323 | AV34: =SUM(AV23:AV32) -> 469668 | AX34: =SUM(AX23:AX32) -> 1858128 | AZ34: =SUM(AZ23:AZ32) -> 492721 | BB34: =SUM(BB23:BB32) -> 482762 | BD34: =SUM(BD23:BD32) -> 498263 | BE34: (1) | BF34: =SUM(BF23:BF32) -> 509558 | BH34: =SUM(BH23:BH32) -> 1983304 | BI34: (1) | BJ34: =SUM(BJ23:BJ32) -> 523817 | BL34: =SUM(BL23:BL32) -> 507590 | BN34: =SUM(BN23:BN32) -> 521757 | BP34: =SUM(BP23:BP32) -> 520140 | BR34: =SUM(BR23:BR32) -> 2073304 | BT34: =SUM(BT23:BT32) -> 531491 | BV34: =SUM(BV23:BV32) -> 508430 | BX34: =SUM(BX23:BX32) -> 520013 | BZ34: =SUM(BZ23:BZ32) -> 578730 | CB34: =SUM(CB23:CB32) -> 2138664 | CD34: =SUM(CD23:CD32) -> 657894 | CF34: =SUM(CF23:CF32) -> 637134 | CH34: =SUM(CH23:CH32) -> 649126 | CJ34: =SUM(CJ23:CJ32) -> 656767 | CL34: =SUM(CL23:CL32) -> 2600921 | CN34: =SUM(CN23:CN32) -> 676196 | CP34: =SUM(CP23:CP32) -> 644612 | CR34: =SUM(CR23:CR32) -> 649993 | CT34: =SUM(CT23:CT32) -> 639093 | CV34: =SUM(CV23:CV32) -> 2609894 | CX34: =SUM(CX23:CX32) -> 649091 | CZ34: =SUM(CZ23:CZ32) -> 606195 | DB34: =SUM(DB23:DB32) -> 606884 | DD34: =SUM(DD23:DD32) -> 598331 | DF34: =SUM(DF23:DF32) -> 2460501 | DH34: =SUM(DH23:DH32) -> 629716 | DJ34: =SUM(DJ23:DJ32) -> 588712 | DL34: =SUM(DL23:DL32) -> 595187 | DN34: =SUM(DN23:DN32) -> 595309 | DP34: =SUM(DP23:DP32) -> 2408924 | DR34: =SUM(DR23:DR32) -> 651639 | DT34: =SUM(DT23:DT32) -> 620168 | DV34: =SUM(DV23:DV32) -> 638889 | DX34: =SUM(DX23:DX32) -> 654268 | DZ34: =SUM(DZ23:DZ32) -> 2564964 | EB34: =SUM(EB23:EB32) -> 743220 | ED34: =SUM(ED23:ED32) -> 670671 | EF34: =SUM(EF23:EF32) -> 671201 | EH34: =SUM(EH23:EH32) -> 0 | EJ34: =SUM(EJ23:EJ32) -> 2085092
A36: Operating Profit | B36: =B19-B34 -> 41702 | D36: =D19-D34 -> 45788 | F36: =F19-F34 -> 48959.514 | H36: =H19-H34 -> 53572.902 | J36: =J19-J34 -> 190023.02 | L36: =L19-L34 -> 58551.729 | N36: =N19-N34 -> 61801 | P36: =P19-P34 -> 63720 | R36: =R19-R34 -> 60557 | T36: =T19-T34 -> 244629.73 | V36: =V19-V34 -> 62485.298 | X36: =X19-X34 -> 66639.579 | Z36: =Z19-Z34 -> 48372 | AB36: =AB19-AB34 -> 59089 | AD36: =AD19-AD34 -> 236585.88 | AF36: =AF19-AF34 -> 88296 | AH36: =AH19-AH34 -> 90240 | AJ36: =AJ19-AJ34 -> 84087 | AL36: =AL19-AL34 -> 89826 | AN36: =AN19-AN34 -> 352449 | AP36: =AP19-AP34 -> 96291 | AR36: =AR19-AR34 -> 97238 | AT36: =AT19-AT34 -> 87502 | AV36: =AV19-AV34 -> 88991 | AX36: =AX19-AX34 -> 370022 | AZ36: =AZ19-AZ34 -> 92659 | BB36: =BB19-BB34 -> 90223 | BD36: =BD19-BD34 -> 71344 | BF36: =BF19-BF34 -> 75725 | BH36: =BH19-BH34 -> 329951 | BJ36: =BJ19-BJ34 -> 77992 | BL36: =BL19-BL34 -> 72988 | BN36: =BN19-BN34 -> 51750 | BP36: =BP19-BP34 -> 63073 | BR36: =BR19-BR34 -> 265803 | BT36: =BT19-BT34 -> 75484 | BV36: =BV19-BV34 -> 75193 | BX36: =BX19-BX34 -> 67171 | BZ36: =BZ19-BZ34 -> 77396 | CB36: =CB19-CB34 -> 295244 | CD36: =CD19-CD34 -> 97405 | CF36: =CF19-CF34 -> 87024 | CH36: =CH19-CH34 -> 56675 | CJ36: =CJ19-CJ34 -> 60196 | CL36: =CL19-CL34 -> 301300 | CN36: =CN19-CN34 -> 80440 | CP36: =CP19-CP34 -> 74419 | CR36: =CR19-CR34 -> 58762 | CT36: =CT19-CT34 -> 60657 | CV36: =CV19-CV34 -> 274278 | CX36: =CX19-CX34 -> 79092 | CZ36: =CZ19-CZ34 -> 73414 | DB36: =DB19-DB34 -> 64367 | DD36: =DD19-DD34 -> 74582 | DF36: =DF19-DF34 -> 291455 | DH36: =DH19-DH34 -> 88703 | DJ36: =DJ19-DJ34 -> 82831 | DL36: =DL19-DL34 -> 69393 | DN36: =DN19-DN34 -> 81781 | DP36: =DP19-DP34 -> 322708 | DR36: =DR19-DR34 -> 90539 | DT36: =DT19-DT34 -> 78085 | DV36: =DV19-DV34 -> 65382 | DX36: =DX19-DX34 -> 83214 | DZ36: =DZ19-DZ34 -> 317220 | EB36: =EB19-EB34 -> 92034 | ED36: =ED19-ED34 -> 79027 | EF36: =EF19-EF34 -> 68113 | EH36: =EH19-EH34 -> 0 | EJ36: =EJ19-EJ34 -> 239174
A38: Interest Income | B38: -286 | D38: -50 | F38: -54.184 | H38: -513.383 | J38: =B38+D38+F38+H38 -> -903.567 | L38: -256.96936 | N38: -117 | P38: -720 | R38: -612 | T38: =L38+N38+P38+R38 -> -1705.9694 | V38: -361.49 | X38: -226.98483 | Z38: -282 | AB38: -223.53962 | AD38: =V38+X38+Z38+AB38 -> -1094.0144 | AF38: -723 | AH38: -705 | AJ38: -588 | AL38: -660 | AN38: =AF38+AH38+AJ38+AL38 -> -2676 | AP38: -771 | AR38: -1208 | AT38: -1305 | AV38: -1361 | AX38: =AP38+AR38+AT38+AV38 -> -4645 | AZ38: -1503 | BB38: -1488 | BD38: -1391 | BF38: -1255 | BH38: =AZ38+BB38+BD38+BF38 -> -5637 | BJ38: -1402 | BL38: -1351 | BN38: -1331 | BP38: -1408 | BR38: =BJ38+BL38+BN38+BP38 -> -5492 | BT38: -1460 | BV38: -1399 | BX38: -1335 | BZ38: -1362 | CB38: =BT38+BV38+BX38+BZ38 -> -5556 | CD38: -1761 | CF38: -1473 | CH38: -1703 | CJ38: -1890 | CL38: =CD38+CF38+CH38+CJ38 -> -6827 | CN38: -1864 | CP38: -2289 | CR38: -2073 | CT38: -2634 | CV38: =CN38+CP38+CR38+CT38 -> -8860 | CX38: -269 | CZ38: -267 | DB38: -153 | DD38: -148 | DF38: =CX38+CZ38+DB38+DD38 -> -837 | DH38: -168 | DJ38: -156 | DL38: -282 | DN38: -248 | DP38: =DH38+DJ38+DL38+DN38 -> -854 | DR38: -154 | DT38: -237 | DV38: -91 | DX38: -145 | DZ38: =DR38+DT38+DV38+DX38 -> -627 | EB38: -181 | ED38: -122 | EF38: -167 | EJ38: =EB38+ED38+EF38+EH38 -> -470
A39: Interest Expense | B39: 18642 | D39: 18865 | F39: 18717.045 | H39: 19448.752 | J39: =B39+D39+F39+H39 -> 75672.797 | L39: 19008 | N39: 18361 | P39: 18915 | R39: 18040 | T39: =L39+N39+P39+R39 -> 74324 | V39: 16510.443 | X39: 15868 | Z39: 14837 | AB39: 13659 | AD39: =V39+X39+Z39+AB39 -> 60874.443 | AF39: 15798 | AH39: 15557 | AJ39: 15301 | AL39: 15117 | AN39: =AF39+AH39+AJ39+AL39 -> 61773 | AP39: 13523 | AR39: 13070 | AT39: 11565 | AV39: 10419 | AX39: =AP39+AR39+AT39+AV39 -> 48577 | AZ39: 10359 | BB39: 10252 | BD39: 9914 | BF39: 10435 | BH39: =AZ39+BB39+BD39+BF39 -> 40960 | BJ39: 10868 | BL39: 10786 | BN39: 11802 | BP39: 12739 | BR39: =BJ39+BL39+BN39+BP39 -> 46195 | BT39: 13023 | BV39: 13301 | BX39: 13322 | BZ39: 18913 | CB39: =BT39+BV39+BX39+BZ39 -> 58559 | CD39: 24096 | CF39: 23431 | CH39: 23419 | CJ39: 23832 | CL39: =CD39+CF39+CH39+CJ39 -> 94778 | CN39: 20927 | CP39: 16739 | CR39: 15040 | CT39: 13535 | CV39: =CN39+CP39+CR39+CT39 -> 66241 | CX39: 9232 | CZ39: 8045 | DB39: 4866 | DD39: 4648 | DF39: =CX39+CZ39+DB39+DD39 -> 26791 | DH39: 6083 | DJ39: 6051 | DL39: 6085 | DN39: 8547 | DP39: =DH39+DJ39+DL39+DN39 -> 26766 | DR39: 9760 | DT39: 9613 | DV39: 8811 | DX39: 9050 | DZ39: =DR39+DT39+DV39+DX39 -> 37234 | EB39: 8977 | ED39: 8343 | EF39: 8096 | EJ39: =EB39+ED39+EF39+EH39 -> 25416
A40: Significant Items | B40: 0 | D40: 0 | F40: 0 | H40: 0 | J40: =B40+D40+F40+H40 -> 0 | L40: 0 | N40: 0 | P40: 0 | R40: 0 | T40: =L40+N40+P40+R40 -> 0 | V40: 0 | X40: 0 | Z40: 0 | AB40: 0 | AD40: =V40+X40+Z40+AB40 -> 0 | AF40: 0 | AH40: 0 | AI40: (2) | AJ40: 0 | AL40: 0 | AN40: =AF40+AH40+AJ40+AL40 -> 0 | AO40: (2) | AP40: 0 | AR40: 0 | AT40: 0 | AU40: (1) | AV40: 0 | AX40: =AP40+AR40+AT40+AV40 -> 0 | AY40: (1) | AZ40: 0 | BB40: 0 | BD40: 0 | BF40: 0 | BG40: -2 | BH40: =AZ40+BB40+BD40+BF40 -> 0 | BI40: -2 | BJ40: 0 | BL40: 0 | BN40: 0 | BP40: 0 | BR40: =BJ40+BL40+BN40+BP40 -> 0 | BT40: 0 | BV40: 0 | BX40: 0 | BY40: -3 | BZ40: 0 | CA40: -5 | CB40: =BT40+BV40+BX40+BZ40 -> 0 | CC40: (3) (5) | CD40: 0 | CF40: 0 | CH40: 0 | CJ40: 0 | CL40: =CD40+CF40+CH40+CJ40 -> 0 | CN40: 0 | CP40: 0 | CR40: 0 | CT40: 0 | CU40: (6) | CV40: =CN40+CP40+CR40+CT40 -> 0 | CW40: (6) | CX40: 0 | CZ40: 0 | DB40: 0 | DD40: 0 | DF40: =CX40+CZ40+DB40+DD40 -> 0 | DH40: 0 | DJ40: 0 | DL40: 0 | DN40: 0 | DO40: (2) | DP40: =DH40+DJ40+DL40+DN40 -> 0 | DQ40: (2) | DR40: 0 | DT40: 0 | DV40: 0 | DX40: 0 | DZ40: =DR40+DT40+DV40+DX40 -> 0 | EB40: 0 | ED40: 0 | EF40: 0 | EJ40: =EB40+ED40+EF40+EH40 -> 0
A42: Earnings Before Income Taxes | B42: =B36-B38-B39-B40 -> 23346 | D42: =D36-D38-D39-D40 -> 26973 | F42: =F36-F38-F39-F40 -> 30296.653 | H42: =H36-H38-H39-H40 -> 34637.533 | J42: =J36-J38-J39-J40 -> 115253.79 | L42: =L36-L38-L39-L40 -> 39800.698 | N42: =N36-N38-N39-N40 -> 43557 | P42: =P36-P38-P39-P40 -> 45525 | R42: =R36-R38-R39-R40 -> 43129 | T42: =T36-T38-T39-T40 -> 172011.7 | V42: =V36-V38-V39-V40 -> 46336.345 | X42: =X36-X38-X39-X40 -> 50998.563 | Z42: =Z36-Z38-Z39-Z40 -> 33817 | AB42: =AB36-AB38-AB39-AB40 -> 45653.54 | AD42: =AD36-AD38-AD39-AD40 -> 176805.45 | AF42: =AF36-AF38-AF39-AF40 -> 73221 | AH42: =AH36-AH38-AH39-AH40 -> 75388 | AJ42: =AJ36-AJ38-AJ39-AJ40 -> 69374 | AL42: =AL36-AL38-AL39-AL40 -> 75369 | AN42: =AN36-AN38-AN39-AN40 -> 293352 | AP42: =AP36-AP38-AP39-AP40 -> 83539 | AR42: =AR36-AR38-AR39-AR40 -> 85376 | AT42: =AT36-AT38-AT39-AT40 -> 77242 | AV42: =AV36-AV38-AV39-AV40 -> 79933 | AX42: =AX36-AX38-AX39-AX40 -> 326090 | AZ42: =AZ36-AZ38-AZ39-AZ40 -> 83803 | BB42: =BB36-BB38-BB39-BB40 -> 81459 | BD42: =BD36-BD38-BD39-BD40 -> 62821 | BF42: =BF36-BF38-BF39-BF40 -> 66545 | BH42: =BH36-BH38-BH39-BH40 -> 294628 | BJ42: =BJ36-BJ38-BJ39-BJ40 -> 68526 | BL42: =BL36-BL38-BL39-BL40 -> 63553 | BN42: =BN36-BN38-BN39-BN40 -> 41279 | BP42: =BP36-BP38-BP39-BP40 -> 51742 | BR42: =BR36-BR38-BR39-BR40 -> 225100 | BT42: =BT36-BT38-BT39-BT40 -> 63921 | BV42: =BV36-BV38-BV39-BV40 -> 63291 | BX42: =BX36-BX38-BX39-BX40 -> 55184 | BZ42: =BZ36-BZ38-BZ39-BZ40 -> 59845 | CB42: =CB36-CB38-CB39-CB40 -> 242241 | CD42: =CD36-CD38-CD39-CD40 -> 75070 | CF42: =CF36-CF38-CF39-CF40 -> 65066 | CH42: =CH36-CH38-CH39-CH40 -> 34959 | CJ42: =CJ36-CJ38-CJ39-CJ40 -> 38254 | CL42: =CL36-CL38-CL39-CL40 -> 213349 | CN42: =CN36-CN38-CN39-CN40 -> 61377 | CP42: =CP36-CP38-CP39-CP40 -> 59969 | CR42: =CR36-CR38-CR39-CR40 -> 45795 | CT42: =CT36-CT38-CT39-CT40 -> 49756 | CV42: =CV36-CV38-CV39-CV40 -> 216897 | CX42: =CX36-CX38-CX39-CX40 -> 70129 | CZ42: =CZ36-CZ38-CZ39-CZ40 -> 65636 | DB42: =DB36-DB38-DB39-DB40 -> 59654 | DD42: =DD36-DD38-DD39-DD40 -> 70082 | DF42: =DF36-DF38-DF39-DF40 -> 265501 | DH42: =DH36-DH38-DH39-DH40 -> 82788 | DJ42: =DJ36-DJ38-DJ39-DJ40 -> 76936 | DL42: =DL36-DL38-DL39-DL40 -> 63590 | DN42: =DN36-DN38-DN39-DN40 -> 73482 | DP42: =DP36-DP38-DP39-DP40 -> 296796 | DR42: =DR36-DR38-DR39-DR40 -> 80933 | DT42: =DT36-DT38-DT39-DT40 -> 68709 | DV42: =DV36-DV38-DV39-DV40 -> 56662 | DX42: =DX36-DX38-DX39-DX40 -> 74309 | DZ42: =DZ36-DZ38-DZ39-DZ40 -> 280613 | EB42: =EB36-EB38-EB39-EB40 -> 83238 | ED42: =ED36-ED38-ED39-ED40 -> 70806 | EF42: =EF36-EF38-EF39-EF40 -> 60184 | EH42: =EH36-EH38-EH39-EH40 -> 0 | EJ42: =EJ36-EJ38-EJ39-EJ40 -> 214228
A44: Income Tax Expense | B44: 11319 | D44: 13082 | F44: 14700 | H44: 16798.095 | J44: =B44+D44+F44+H44 -> 55899.095 | L44: 18912 | N44: 20687 | P44: 21624.375 | R44: 19513 | T44: =L44+N44+P44+R44+109 -> 80845.375 | V44: 21338 | X44: 23454 | Z44: 14883 | AB44: 19634 | AD44: =V44+X44+Z44+AB44-0.5 -> 79308.5 | AF44: 29658 | AH44: 30524 | AJ44: 27925 | AL44: 30151 | AN44: =AF44+AH44+AJ44+AL44 -> 118258 | AP44: 32580 | AR44: 33083 | AT44: 28773 | AV44: 28434 | AX44: =AP44+AR44+AT44+AV44 -> 122870 | AZ44: 31594 | BB44: 30265 | BD44: 25269 | BF44: 24831 | BH44: =AZ44+BB44+BD44+BF44 -> 111959 | BJ44: =BJ42*(28857/76526)+1 -> 25841.3 | BL44: =21811+2122 -> 23933 | BM44: -2 | BN44: 15294 | BP44: 18146 | BQ44: -7 | BR44: =BJ44+BL44+BN44+BP44 -> 83214.3 | BS44: (2) (7) | BT44: 23593 | BV44: 23448 | BX44: 18804 | BZ44: 24249 | CB44: =BT44+BV44+BX44+BZ44 -> 90094 | CD44: 27158 | CF44: 23815 | CH44: 12236 | CJ44: 10183 | CL44: =CD44+CF44+CH44+CJ44 -> 73392 | CN44: 23216 | CP44: 22228 | CR44: 16264 | CT44: 18370 | CV44: =CN44+CP44+CR44+CT44 -> 80078 | CX44: 26614 | CZ44: 24841 | DB44: 22824 | DD44: 26399 | DF44: =CX44+CZ44+DB44+DD44 -> 100678 | DH44: 31327 | DJ44: 29106 | DL44: 23093 | DN44: 27862 | DP44: =DH44+DJ44+DL44+DN44 -> 111388 | DR44: 30382 | DT44: 25734 | DV44: 20629 | DX44: 23799 | DZ44: =DR44+DT44+DV44+DX44 -> 100544 | EB44: 31297 | ED44: 26624 | EF44: 20274 | EJ44: =EB44+ED44+EF44+EH44 -> 78195
A45: Net Earnings | B45: =B42-B44 -> 12027 | D45: =D42-D44 -> 13891 | F45: =F42-F44 -> 15596.653 | H45: =H42-H44 -> 17839.438 | J45: =J42-J44 -> 59354.691 | L45: =L42-L44 -> 20888.698 | N45: =N42-N44 -> 22870 | P45: =P42-P44 -> 23900.625 | R45: =R42-R44 -> 23616 | T45: =T42-T44 -> 91166.323 | V45: =V42-V44 -> 24998.345 | X45: =X42-X44 -> 27544.563 | Z45: =Z42-Z44 -> 18934 | AB45: =AB42-AB44 -> 26019.54 | AD45: =AD42-AD44 -> 97496.948 | AF45: =AF42-AF44 -> 43563 | AH45: =AH42-AH44 -> 44864 | AJ45: =AJ42-AJ44 -> 41449 | AL45: =AL42-AL44 -> 45218 | AN45: =AN42-AN44 -> 175094 | AP45: =AP42-AP44 -> 50959 | AR45: =AR42-AR44 -> 52293 | AT45: =AT42-AT44 -> 48469 | AV45: =AV42-AV44 -> 51499 | AX45: =AX42-AX44 -> 203220 | AZ45: =AZ42-AZ44 -> 52209 | BB45: =BB42-BB44 -> 51194 | BD45: =BD42-BD44 -> 37552 | BF45: =BF42-BF44 -> 41714 | BH45: =BH42-BH44 -> 182669 | BJ45: =BJ42-BJ44 -> 42684.7 | BL45: =BL42-BL44 -> 39620 | BN45: =BN42-BN44 -> 25985 | BP45: =BP42-BP44 -> 33596 | BR45: =BR42-BR44 -> 141885.7 | BT45: =BT42-BT44 -> 40328 | BV45: =BV42-BV44 -> 39843 | BX45: =BX42-BX44 -> 36380 | BZ45: =BZ42-BZ44 -> 35596 | CB45: =CB42-CB44 -> 152147 | CD45: =CD42-CD44 -> 47912 | CF45: =CF42-CF44 -> 41251 | CH45: =CH42-CH44 -> 22723 | CJ45: =CJ42-CJ44 -> 28071 | CL45: =CL42-CL44 -> 139957 | CN45: =CN42-CN44 -> 38161 | CP45: =CP42-CP44 -> 37741 | CR45: =CR42-CR44 -> 29531 | CT45: =CT42-CT44 -> 31386 | CV45: =CV42-CV44 -> 136819 | CX45: =CX42-CX44 -> 43515 | CZ45: =CZ42-CZ44 -> 40795 | DB45: =DB42-DB44 -> 36830 | DD45: =DD42-DD44 -> 43683 | DF45: =DF42-DF44 -> 164823 | DH45: =DH42-DH44 -> 51461 | DJ45: =DJ42-DJ44 -> 47830 | DL45: =DL42-DL44 -> 40497 | DN45: =DN42-DN44 -> 45620 | DP45: =DP42-DP44 -> 185408 | DR45: =DR42-DR44 -> 50551 | DT45: =DT42-DT44 -> 42975 | DV45: =DV42-DV44 -> 36033 | DX45: =DX42-DX44 -> 50510 | DZ45: =DZ42-DZ44 -> 180069 | EB45: =EB42-EB44 -> 51941 | ED45: =ED42-ED44 -> 44182 | EF45: =EF42-EF44 -> 39910 | EH45: =EH42-EH44 -> 0 | EJ45: =EJ42-EJ44 -> 136033
A47: Preferred Dividends | B47: 2441 | D47: 2490 | F47: 2541.519 | H47: 2566.481 | J47: =B47+D47+F47+H47 -> 10039 | L47: 2554 | N47: 2579 | P47: 2631 | R47: 2656 | T47: =L47+N47+P47+R47 -> 10420 | V47: 4325 | X47: 5053 | Z47: 2709 | AB47: 3321 | AD47: =V47+X47+Z47+AB47 -> 15408 | AF47: 4992 | AH47: 3898 | AJ47: 1321 | AL47: 1 | AN47: =AF47+AH47+AJ47+AL47 -> 10212 | AP47: 0 | AR47: 0 | AT47: 0 | AV47: 0 | AX47: =AP47+AR47+AT47+AV47 -> 0 | AZ47: 0 | BB47: 0 | BD47: 0 | BF47: 0 | BH47: =AZ47+BB47+BD47+BF47 -> 0 | BJ47: 0 | BL47: 0 | BN47: 0 | BP47: 0 | BR47: =BJ47+BL47+BN47+BP47 -> 0 | BT47: 0 | BV47: 0 | BX47: 0 | BZ47: 0 | CB47: =BT47+BV47+BX47+BZ47 -> 0 | CD47: 0 | CF47: 0 | CH47: 0 | CJ47: 0 | CL47: =CD47+CF47+CH47+CJ47 -> 0 | CN47: 0 | CP47: 0 | CR47: 0 | CT47: 0 | CV47: =CN47+CP47+CR47+CT47 -> 0 | CX47: 0 | CZ47: 0 | DB47: 0 | DD47: 0 | DF47: =CX47+CZ47+DB47+DD47 -> 0 | DH47: 0 | DJ47: 0 | DL47: 0 | DN47: 0 | DP47: =DH47+DJ47+DL47+DN47 -> 0 | DR47: 0 | DT47: 0 | DZ47: =DR47+DT47+DV47+DX47 -> 0 | EB47: 0 | EJ47: =EB47+ED47+EF47+EH47 -> 0
A48: Net Earnings to Common | B48: =B45-B47 -> 9586 | D48: =D45-D47 -> 11401 | F48: =F45-F47 -> 13055.134 | H48: =H45-H47 -> 15272.957 | J48: =J45-J47 -> 49315.691 | L48: =L45-L47 -> 18334.698 | N48: =N45-N47 -> 20291 | P48: =P45-P47 -> 21269.625 | R48: =R45-R47 -> 20960 | T48: =T45-T47 -> 80746.323 | V48: =V45-V47 -> 20673.345 | X48: =X45-X47 -> 22491.563 | Z48: =Z45-Z47 -> 16225 | AB48: =AB45-AB47 -> 22698.54 | AD48: =AD45-AD47 -> 82088.948 | AF48: =AF45-AF47 -> 38571 | AH48: =AH45-AH47 -> 40966 | AJ48: =AJ45-AJ47 -> 40128 | AL48: =AL45-AL47 -> 45217 | AN48: =AN45-AN47 -> 164882 | AP48: =AP45-AP47 -> 50959 | AR48: =AR45-AR47 -> 52293 | AT48: =AT45-AT47 -> 48469 | AV48: =AV45-AV47 -> 51499 | AX48: =AX45-AX47 -> 203220 | AZ48: =AZ45-AZ47 -> 52209 | BB48: =BB45-BB47 -> 51194 | BD48: =BD45-BD47 -> 37552 | BF48: =BF45-BF47 -> 41714 | BH48: =BH45-BH47 -> 182669 | BJ48: =BJ45-BJ47 -> 42684.7 | BL48: =BL45-BL47 -> 39620 | BN48: =BN45-BN47 -> 25985 | BP48: =BP45-BP47 -> 33596 | BR48: =BR45-BR47 -> 141885.7 | BT48: =BT45-BT47 -> 40328 | BV48: =BV45-BV47 -> 39843 | BX48: =BX45-BX47 -> 36380 | BZ48: =BZ45-BZ47 -> 35596 | CB48: =CB45-CB47 -> 152147 | CD48: =CD45-CD47 -> 47912 | CF48: =CF45-CF47 -> 41251 | CH48: =CH45-CH47 -> 22723 | CJ48: =CJ45-CJ47 -> 28071 | CL48: =CL45-CL47 -> 139957 | CN48: =CN45-CN47 -> 38161 | CP48: =CP45-CP47 -> 37741 | CR48: =CR45-CR47 -> 29531 | CT48: =CT45-CT47 -> 31386 | CV48: =CV45-CV47 -> 136819 | CX48: =CX45-CX47 -> 43515 | CZ48: =CZ45-CZ47 -> 40795 | DB48: =DB45-DB47 -> 36830 | DD48: =DD45-DD47 -> 43683 | DF48: =DF45-DF47 -> 164823 | DH48: =DH45-DH47 -> 51461 | DJ48: =DJ45-DJ47 -> 47830 | DL48: =DL45-DL47 -> 40497 | DN48: =DN45-DN47 -> 45620 | DP48: =DP45-DP47 -> 185408 | DR48: =DR45-DR47 -> 50551 | DT48: =DT45-DT47 -> 42975 | DV48: =DV45-DV47 -> 36033 | DX48: =DX45-DX47 -> 50510 | DZ48: =DZ45-DZ47 -> 180069 | EB48: =EB45-EB47 -> 51941 | ED48: =ED45-ED47 -> 44182 | EF48: =EF45-EF47 -> 39910 | EH48: =EH45-EH47 -> 0 | EJ48: =EJ45-EJ47 -> 136033
A50: Basic EPS | B50: =B48/B53 -> 0.15900477 | D50: =D48/D53 -> 0.18844628 | F50: =F48/F53 -> 0.21494355 | H50: =H48/H53 -> 0.25136532 | J50: =J48/J53 -> 0.81415974 | L50: =L48/L53 -> 0.30166917 | N50: =N48/N53 -> 0.33365124 | P50: =P48/P53 -> 0.34862523 | R50: =R48/R53 -> 0.33959819 | T50: =T48/T53 -> 1.3330525 | V50: =V48/V53 -> 0.33132186 | X50: =X48/X53 -> 0.35044505 | Z50: =Z48/Z53 -> 0.24337842 | AB50: =AB48/AB53 -> 0.34804369 | AD50: =AD48/AD53 -> 1.2704318 | AF50: =AF48/AF53 -> 0.6293453 | AH50: =AH48/AH53 -> 0.6374047 | AJ50: =AJ48/AJ53 -> 0.52161705 | AL50: =AL48/AL53 -> 0.51743098 | AN50: =AN48/AN53 -> 2.2445904 | AP50: =AP48/AP53 -> 0.58412425 | AR50: =AR48/AR53 -> 0.59765136 | AT50: =AT48/AT53 -> 0.59651951 | AV50: =AV48/AV53 -> 0.63924679 | AX50: =AX48/AX53 -> 2.415289 | AZ50: =AZ48/AZ53 -> 0.65029582 | BB50: =BB48/BB53 -> 0.64424142 | BD50: =BD48/BD53 -> 0.4815038 | BF50: =BF48/BF53 -> 0.55720449 | BH50: =BH48/BH53 -> 2.3374152 | BJ50: =BJ48/BJ53 -> 0.57250329 | BL50: =BL48/BL53 -> 0.53005472 | BN50: =BN48/BN53 -> 0.35680938 | BP50: =BP48/BP53 -> 0.48034085 | BR50: =BR48/BR53 -> 1.9431539 | BT50: =BT48/BT53 -> 0.58230334 | BV50: =BV48/BV53 -> 0.57290963 | BX50: =BX48/BX53 -> 0.52114371 | BZ50: =BZ48/BZ53 -> 0.50782509 | CB50: =CB48/CB53 -> 2.1836357 | CD50: =CD48/CD53 -> 0.68167203 | CF50: =IF(ISERROR(CF48/CF53),0,(CF48/CF53)) -> 0.59080233 | CH50: =IF(ISERROR(CH48/CH53),0,(CH48/CH53)) -> 0.3344618 | CJ50: =IF(ISERROR(CJ48/CJ53),0,(CJ48/CJ53)) -> 0.4203567 | CL50: =CL48/CL53 -> 2.0370271 | CN50: =CN48/CN53 -> 0.57204317 | CP50: =IF(ISERROR(CP48/CP53),0,(CP48/CP53)) -> 0.56596785 | CR50: =IF(ISERROR(CR48/CR53),0,(CR48/CR53)) -> 0.44277018 | CT50: =IF(ISERROR(CT48/CT53),0,(CT48/CT53)) -> 0.47316529 | CV50: =CV48/CV53 -> 2.0541697 | CX50: =CX48/CX53 -> 0.65936813 | CZ50: =IF(ISERROR(CZ48/CZ53),0,(CZ48/CZ53)) -> 0.61784394 | DB50: =IF(ISERROR(DB48/DB53),0,(DB48/DB53)) -> 0.55738003 | DD50: =IF(ISERROR(DD48/DD53),0,(DD48/DD53)) -> 0.66343175 | DF50: =DF48/DF53 -> 2.497848 | DH50: =DH48/DH53 -> 0.78328437 | DJ50: =IF(ISERROR(DJ48/DJ53),0,(DJ48/DJ53)) -> 0.72530139 | DL50: =IF(ISERROR(DL48/DL53),0,(DL48/DL53)) -> 0.62213107 | DN50: =IF(ISERROR(DN48/DN53),0,(DN48/DN53)) -> 0.71641697 | DP50: =DP48/DP53 -> 2.8478742 | DR50: =DR48/DR53 -> 0.79792591 | DT50: =IF(ISERROR(DT48/DT53),0,(DT48/DT53)) -> 0.68815052 | DV50: =IF(ISERROR(DV48/DV53),0,(DV48/DV53)) -> 0.60024988 | DX50: =IF(ISERROR(DX48/DX53),0,(DX48/DX53)) -> 0.85730774 | DZ50: =DZ48/DZ53 -> 2.942905 | EB50: =EB48/EB53 -> 0.87661176 | ED50: =IF(ISERROR(ED48/ED53),0,(ED48/ED53)) -> 0.74682218 | EF50: =IF(ISERROR(EF48/EF53),0,(EF48/EF53)) -> 0.67779627 | EH50: =IF(ISERROR(EH48/EH53),0,(EH48/EH53)) -> 0 | EJ50: =EJ48/EJ53 -> 2.3018207
A51: Diluted EPS | B51: =B45/B54 -> 0.14105502 | D51: =D45/D54 -> 0.16275337 | F51: =F45/F54 -> 0.18287027 | H51: =H45/H54 -> 0.2088866 | J51: =J45/J54 -> 0.69562017 | L51: =L45/L54 -> 0.24405536 | N51: =N45/N54 -> 0.26481401 | P51: =P45/P54 -> 0.27227095 | R51: =R45/R54 -> 0.26720978 | T51: =T45/T54 -> 1.0482294 | V51: =V45/V54 -> 0.27489616 | X51: =X45/X54 -> 0.29621792 | Z51: =Z45/Z54 -> 0.20047058 | AB51: =AB45/AB54 -> 0.28155866 | AD51: =AD45/AD54 -> 1.0517754 | AF51: =AF45/AF54 -> 0.47975551 | AH51: =AH45/AH54 -> 0.48878115 | AJ51: =AJ45/AJ54 -> 0.45509593 | AL51: =AL45/AL54 -> 0.50358326 | AN51: =AN45/AN54 -> 1.9269686 | AP51: =AP45/AP54 -> 0.5672195 | AR51: =AR45/AR54 -> 0.57612031 | AT51: =AT45/AT54 -> 0.57423643 | AV51: =AV45/AV54 -> 0.61684314 | AX51: =AX45/AX54 -> 2.3302908 | AZ51: =AZ45/AZ54 -> 0.62988165 | BB51: =BB45/BB54 -> 0.62446938 | BD51: =BD45/BD54 -> 0.46982284 | BF51: =BF45/BF54 -> 0.54580188 | BH51: =BH45/BH54 -> 2.2763343 | BJ51: =BJ45/BJ54 -> 0.56110922 | BL51: =BL45/BL54 -> 0.52130893 | BN51: =BN45/BN54 -> 0.35251584 | BP51: =BP45/BP54 -> 0.47554744 | BR51: =BR45/BR54 -> 1.9145736 | BT51: =BT45/BT54 -> 0.57406406 | BV51: =BV45/BV54 -> 0.56402888 | BX51: =BX45/BX54 -> 0.51345744 | BZ51: =BZ45/BZ54 -> 0.50000702 | CB51: =CB45/CB54 -> 2.1510045 | CD51: =CD45/CD54 -> 0.67161961 | CF51: =IF(ISERROR(CF45/CF54),0,(CF45/CF54)) -> 0.58293765 | CH51: =IF(ISERROR(CH45/CH54),0,(CH45/CH54)) -> 0.33130185 | CJ51: =IF(ISERROR(CJ45/CJ54),0,(CJ45/CJ54)) -> 0.41764242 | CL51: =CL45/CL54 -> 2.0145089 | CN51: =CN45/CN54 -> 0.56808336 | CP51: =IF(ISERROR(CP45/CP54),0,(CP45/CP54)) -> 0.560288 | CR51: =IF(ISERROR(CR45/CR54),0,(CR45/CR54)) -> 0.43767136 | CT51: =IF(ISERROR(CT45/CT54),0,(CT45/CT54)) -> 0.47016703 | CV51: =CV45/CV54 -> 2.0362773 | CX51: =CX45/CX54 -> 0.65441011 | CZ51: =IF(ISERROR(CZ45/CZ54),0,(CZ45/CZ54)) -> 0.61210557 | DB51: =IF(ISERROR(DB45/DB54),0,(DB45/DB54)) -> 0.55223187 | DD51: =IF(ISERROR(DD45/DD54),0,(DD45/DD54)) -> 0.65754971 | DF51: =DF45/DF54 -> 2.4760467 | DH51: =DH45/DH54 -> 0.77365185 | DJ51: =IF(ISERROR(DJ45/DJ54),0,(DJ45/DJ54)) -> 0.71630749 | DL51: =IF(ISERROR(DL45/DL54),0,(DL45/DL54)) -> 0.61596143 | DN51: =IF(ISERROR(DN45/DN54),0,(DN45/DN54)) -> 0.70646535 | DP51: =DP45/DP54 -> 2.8133576 | DR51: =DR45/DR54 -> 0.78627201 | DT51: =IF(ISERROR(DT45/DT54),0,(DT45/DT54)) -> 0.68054412 | DV51: =IF(ISERROR(DV45/DV54),0,(DV45/DV54)) -> 0.5955474 | DX51: =IF(ISERROR(DX45/DX54),0,(DX45/DX54)) -> 0.84732684 | DZ51: =DZ45/DZ54 -> 2.9095595 | EB51: =EB45/EB54 -> 0.86662217 | ED51: =IF(ISERROR(ED45/ED54),0,(ED45/ED54)) -> 0.74158246 | EF51: =IF(ISERROR(EF45/EF54),0,(EF45/EF54)) -> 0.67288238 | EH51: =IF(ISERROR(EH45/EH54),0,(EH45/EH54)) -> 0 | EJ51: =EJ45/EJ54 -> 2.2821138
A53: Basic Shares Outstanding | B53: =24115*5/2 -> 60287.5 | D53: =24200*5/2 -> 60500 | F53: =24295*5/2 -> 60737.5 | H53: =24304*5/2 -> 60760 | J53: =24229*5/2 -> 60572.5 | L53: =24311*5/2 -> 60777.5 | N53: =24326*5/2 -> 60815 | P53: =24404*5/2 -> 61010 | R53: =24688*5/2 -> 61720 | T53: =24229*5/2 -> 60572.5 | V53: =24958.625*5/2 -> 62396.562 | X53: =25672*5/2 -> 64180 | Z53: =26666.292*5/2 -> 66665.73 | AB53: =26087*5/2 -> 65217.5 | AD53: =25846*5/2 -> 64615 | AF53: =24515*5/2 -> 61287.5 | AH53: =25708*5/2 -> 64270 | AJ53: 76930 | AL53: =34955*5/2 -> 87387.5 | AN53: =29383*5/2 -> 73457.5 | AP53: =34896*5/2 -> 87240 | AR53: =34999*5/2 -> 87497.5 | AT53: 81253 | AV53: 80562 | AX53: 84139 | AZ53: 80285 | BB53: 79464 | BD53: 77989 | BF53: 74863 | BH53: 78150 | BJ53: 74558 | BL53: 74747 | BN53: 72826 | BP53: 69942 | BR53: =AVERAGE(BJ53:BP53) -> 73018.25 | BT53: 69256 | BV53: 69545 | BX53: 69808 | BZ53: 70095 | CB53: =AVERAGE(BT53:BZ53) -> 69676 | CD53: 70286 | CF53: 69822 | CH53: 67939 | CJ53: 66779 | CL53: =AVERAGE(CD53:CJ53) -> 68706.5 | CN53: 66710 | CP53: 66684 | CR53: 66696 | CT53: 66332 | CV53: =AVERAGE(CN53:CT53) -> 66605.5 | CX53: 65995 | CZ53: 66028 | DB53: 66077 | DD53: 65844 | DF53: =AVERAGE(CX53:DD53) -> 65986 | DH53: 65699 | DJ53: 65945 | DL53: 65094 | DN53: 63678 | DP53: =AVERAGE(DH53:DN53) -> 65104 | DR53: 63353 | DT53: 62450 | DV53: 60030 | DX53: 58917 | DZ53: =AVERAGE(DR53:DX53) -> 61187.5 | EB53: 59252 | ED53: 59160 | EF53: 58882 | EJ53: =AVERAGE(EB53:EH53) -> 59098
...

Sheet EPS Contribution
A1: Rent-A-Center, Inc.
A2: Proforma Diluted EPS Quarterly Contribution 2009 - Q3 2012
C5: 1Q | F5: 2Q | I5: 3Q | L5: 4Q | O5: Annual | Q5: STORES BY SEGMENT
A6: Year | C6: Diluted EPS | D6: % of Total | F6: Diluted EPS | G6: % of Total | I6: Diluted EPS | J6: % of Total | L6: Diluted EPS | M6: % of Total | O6: Diluted EPS | Q6: CORE US (1)(2) | R6: RACA | S6: MEX | T6: CAN | U6: TOTAL
A7: 2009 | C7: ='Quarterly ProForma Results'!CX51 -> 0.65441011 | D7: =C7/O7 -> 0.26429635 | F7: ='Quarterly ProForma Results'!CZ51 -> 0.61210557 | G7: =F7/O7 -> 0.24721084 | I7: ='Quarterly ProForma Results'!DB51 -> 0.55223187 | J7: =I7/O7 -> 0.22302967 | L7: ='Quarterly ProForma Results'!DD51 -> 0.65754971 | M7: =L7/O7 -> 0.26556434 | O7: ='Quarterly ProForma Results'!DF51 -> 2.4760467 | Q7: 2989 | R7: 82 | S7: 0 | T7: 18 | U7: =SUM(Q7:T7) -> 3089
A8: 2010 | C8: ='Quarterly ProForma Results'!DH51 -> 0.77365185 | D8: =C8/O8 -> 0.27499236 | F8: ='Quarterly ProForma Results'!DJ51 -> 0.71630749 | G8: =F8/O8 -> 0.25460947 | I8: ='Quarterly ProForma Results'!DL51 -> 0.61596143 | J8: =I8/O8 -> 0.21894175 | L8: ='Quarterly ProForma Results'!DN51 -> 0.70646535 | M8: =L8/O8 -> 0.25111111 | O8: ='Quarterly ProForma Results'!DP51 -> 2.8133576 | Q8: 2985 | R8: 384 | S8: 5 | T8: 18 | U8: =SUM(Q8:T8) -> 3392
A9: 2011 | C9: ='Quarterly ProForma Results'!DR51 -> 0.78627201 | D9: =C9/O9 -> 0.27023747 | F9: ='Quarterly ProForma Results'!DT51 -> 0.68054412 | G9: =F9/O9 -> 0.23389937 | I9: ='Quarterly ProForma Results'!DV51 -> 0.5955474 | J9: =I9/O9 -> 0.20468645 | L9: ='Quarterly ProForma Results'!DX51 -> 0.84732684 | M9: =L9/O9 -> 0.29122169 | O9: ='Quarterly ProForma Results'!DZ51 -> 2.9095595 | Q9: 2994 | R9: 750 | S9: 52 | T9: 28 | U9: =SUM(Q9:T9) -> 3824
A10: 2012 | C10: ='Quarterly ProForma Results'!EB51 -> 0.86662217 | F10: ='Quarterly ProForma Results'!ED51 -> 0.74158246 | I10: ='Quarterly ProForma Results'!EF51 -> 0.67288238 | Q10: 2983 | R10: 882 | S10: 81 | T10: 33 | U10: =SUM(Q10:T10) -> 3979
A12: (1) Primarily includes rent-to-own stores in the U.S. & Puerto Rico and GIN/Home Choice
A13: (2) Exludes Financial Services (2009 - 353; 2010 - 111)
