Workbook

Sheet Instructions
A1: CHARTER SCHOOL BUDGET INSTRUCTIONS
A3: Per NAC 387.730:
B5: TENTATIVE budget is due to the clerk or secretary of the Charter School Governing Body and Nevada Department
C6: of Education (NDE) by April 15 annually.
B8: FINAL budget must be adopted on or before June 8 Annually. Copies of the approved final budget are then
C9: SUBMITTED by the Charter School Governing Body to NDE, Program Analyst - Fiscal Analysis Division -
C10: Legislative Counsel Bureau and the Charter School sponsor.
B12: The preferred method of submitting the Tentative and Final budgets to the NDE, is electronically.
B13: The signed cover page (Form 1) for the final budget, can be scanned and sent electronically, faxed, or mailed.
A15: FORM 1 COVER PAGE
A16: 1 | B16: Enter the name of the charter school in "Charter School - fill in the name of your school".
A17: 2 | B17: Enter the number of governmental fund types. You will most likely have one (General Fund) or two (also Special Education).
A18: 3 | B18: Enter the total estimated expenditures for governmental funds. This amount must agree with "TOTAL ALL
B19: EXPENDITURES" on Form 4 Expenses, page 10.
A20: 4 | B20: If you have a proprietary fund(s), enter the number of funds and estimated expenses. It is unusual for
B21: Charter Schools to have proprietary funds. This total must agree with "TOTAL EXPENSES" on Form 6
B22: Proprietary, page 10.
A23: 5 | B23: Fill in the certification information on the lower left side of the page, prior to submitting the tentative
B24: budget.
A25: 6 | B25: Fill in the "Scheduled Public Hearing:" information at the bottom of the page for the tentative budget.
A26: 7 | B26: Fill in the certification information on the lower portion of the page, including the board members, prior to
B27: submitting the final budget. The certification needs to be signed by the charter school principal or
B28: administrator and all members of the governing board.
A29: 8 | B29: Fill in the actual public hearing information under "Scheduled Public Hearing:" prior to submitting the
B30: final budget.
A32: FORM 2 ENROLLMENT-DSA
A33: 1 | B33: Enter data in the yellow cells only.
A34: 2 | B34: Enter the enrollments for both "Actual Year Ending 06/30/XX" (columns D/F & H/J) for categories #1-5, 7-8.
A35: 3 | B35: Enter the enrollments for "Estimated Year Ending 06/30/XX" for the budget submission year in #1-5, 7-8.
A36: 4 | B36: Enter the Hold Harmless amount in #10. You will be eligible to receive the Hold Harmless enrollments:
B37: a. IF: enrollment decreases less than 5%, use highest enrollment of current or prior year.
B38: b. IF: enrollment decreases more than 5%, use highest enrollment of current or either of the two prior
B39: consecutive years.
B40: c. IF: the Charter School is multidistrict, Hold Harmless is based on the TOTAL Statewide enrollment.
B41: d. New Charter Schools are not eligible for Hold Harmless.
A42: 5 | B42: Enter the WEIGHTED student enrollments based on School District of residence in #11. If the pupils only
B43: reside in one School District, enter the total number of students (WEIGHTED) next to that district. If they
B44: reside in more than one district, allocate the enrollment to the correct school districts. The rate for basic
B45: support will automatically calculate for you.
A46: 6 | B46: Enter an estimated "Outside Revenue" amount in #12. The prior year amounts are listed at the far right
...

Sheet Form 1 Cover
A16: Charter School Budget
A20: Charter School - fill in the name of your school | F20: herewith submits the | H20: TENTATIVE or FINAL or AMENDED FINAL
A21: budget for the fiscal year ending | D21: =C138 -> June 30, 2015
A23: This budget contains | D23: governmental fund types with estimated expenditures of $ | K23: and
B24: proprietary funds with estimated expenses of $ | H24: .
A26: Per NAC 387.730:
B28: TENTATIVE budget is due to the clerk or secretary of the Charter School Governing Body and Nevada Department
C29: of Education (NDE) by April 15 annually.
B31: FINAL budget must be adopted on or before June 8 Annually. Copies of the approved final budget are
C32: SUBMITTED by the Charter School Governing Body to NDE, Legislative Council Bureau and the
C33: Charter School sponsor if other than the Department of Education.
A36: CERTIFICATION | G36: APPROVED BY THE GOVERNING BOARD
A38: I,
B39: (Print Name of Governing Board President)
B41: (Signature of Governing Board President)
B43: certify that all applicable funds and financial
B44: operations of this Local Government are
B45: listed herein
B47: Signed
B50: Dated:
A56: SCHEDULED PUBLIC HEARING:
A58: Date and Time: | G58: Publication Date
A60: Place:
J61: Form 1
J62: =C146 -> 41703
A126: Update all fiscal year reference to the appropriate fiscal year.
A130: Actual Prior Year | C130: 41455 | D130: Last day of FY | F130: - Estimated
A133: Estimated Current | C133: 2013/2014
A134: Current yr ending | C134: 41820
A137: Budget Year | C137: 2014-2015
A138: Budget yr ending | C138: June 30, 2015
A139: Budget yr ending | C139: 42185
A142: Form 6 | C142: July 1, 2014 | E142: 1st day of budget year
C143: 41821
A146: Updated on | C146: 41703 | D146: =C146 -> 41703

Sheet Form 2 Enrollment-DSA
A1: ENROLLMENT AND BASIC SUPPORT GUARANTEE INFORMATION
N2: WEIGHTED
F3: WEIGHTED | J3: WEIGHTED | N3: ESTIMATED
F4: ACTUAL PRIOR YEAR | J4: ACTUAL CURRENT YEAR | N4: YEAR
F5: ="ENDING "&TEXT('Form 1 Cover'!C130,"MM/DD/YY") -> ENDING 06/30/13 | J5: ="ENDING "&TEXT('Form 1 Cover'!C134, "MM/DD/YY") -> ENDING 06/30/14 | N5: ="ENDING "&TEXT('Form 1 Cover'!C139, "MM/DD/YY") -> ENDING 06/30/15
A7: 1. | B7: Pre-kindergarten
B8: (NRS 388.490) | E8: x .6 = | F8: =D8*0.6 -> 0 | I8: x .6 = | J8: =H8*0.6 -> 0 | M8: x .6 = | N8: =L8*0.6 -> 0
A10: 2. | B10: Kindergarten | E10: x .6 = | F10: =D10*0.6 -> 0 | I10: x .6 = | J10: =H10*0.6 -> 0 | M10: x .6 = | N10: =L10*0.6 -> 0
A12: 3. | B12: Elementary
A14: 4. | B14: Secondary
A16: 5. | B16: Ungraded
A18: 6. | B18: Subtotal | F18: =F8+F10+F12+F14+F16 -> 0 | J18: =J8+J10+J12+J14+J16 -> 0 | N18: =N8+N10+N12+N14+N16 -> 0
A20: 7. | B20: Students transported into
B21: Nevada from out-of-state
A23: 8. | B23: Students transported to
B24: another state
A26: 9. | B26: Total WEIGHTED enrollment | F26: =F18+F21-F24 -> 0 | J26: =J18+J21-J24 -> 0 | N26: =N18+N21-N24 -> 0
A28: 10. | B28: Hold Harmless
A31: 11. | B31: ="Basic support per pupil amount, Year " &PROPER(N5) -> Basic support per pupil amount, Year Ending 06/30/15 | J31: =L53 -> #DIV/0!
B32: Estimated per SB522 77th session | H32: WEIGHTED | L32: Use rates below:
B33: Fill in information for each district: | F33: ='Form 1 Cover'!C137 -> 2014-2015 | H33: ='Form 1 Cover'!C137 -> 2014-2015 | N33: Reference amounts for #12
D34: School District | F34: Rate revised 5/24/2013 | H34: Enrollment | J34: Subtotal | N34: Estimate: "Outside Revenue"
D35: Carson City | F35: 6643 | H35: 0 | J35: =F35*H35 -> 0 | N35: 1086
D36: Churchill | F36: 6629 | H36: 0 | J36: =F36*H36 -> 0 | N36: 1069
D37: Clark | F37: 5544 | H37: 0 | J37: =F37*H37 -> 0 | N37: 997
D38: Douglas | F38: 5998 | H38: 0 | J38: =F38*H38 -> 0 | N38: 2386
D39: Elko | F39: 6692 | H39: 0 | J39: =F39*H39 -> 0 | N39: 1113
D40: Esmeralda | F40: 15798 | H40: 0 | J40: =F40*H40 -> 0 | N40: 8308
D41: Eureka | F41: 100 | H41: 0 | J41: =F41*H41 -> 0 | N41: =43970-100 -> 43870
D42: Humboldt | F42: 5409 | H42: 0 | J42: =F42*H42 -> 0 | N42: 2047
D43: Lander | F43: 385 | H43: 0 | J43: =F43*H43 -> 0 | N43: =9984-100 -> 9884
D44: Lincoln | F44: 10500 | H44: 0 | J44: =F44*H44 -> 0 | N44: 1295
D45: Lyon | F45: 7186 | H45: 0 | J45: =F45*H45 -> 0 | N45: 922
D46: Mineral | F46: 9622 | H46: 0 | J46: =F46*H46 -> 0 | N46: 1683
D47: Nye | F47: 7085 | H47: 0 | J47: =F47*H47 -> 0 | N47: 1368
D48: Pershing | F48: 8738 | H48: 0 | J48: =F48*H48 -> 0 | N48: 2272
D49: Storey | F49: 8455 | H49: 0 | J49: =F49*H49 -> 0 | N49: 6494
D50: Washoe | F50: 5585 | H50: 0 | J50: =F50*H50 -> 0 | N50: 1138
D51: White Pine | F51: 7315 | H51: 0 | J51: =F51*H51 -> 0 | N51: 1902
D53: Multidistict | H53: =SUM(H35:H51) -> 0 | J53: =SUM(J35:J52) -> 0 | L53: =J53/H53 -> #DIV/0!
...

Sheet Form 3 Revenues
A1: Form 3 | D1: -1 | E1: -2 | F1: -3 | G1: -4 | H1: -4
E2: ESTIMATED | F2: ="BUDGET YEAR ENDING "&TEXT('Form 1 Cover'!C139, "MM/DD/YY") -> BUDGET YEAR ENDING 06/30/15
A3: ='Form 1 Cover'!A20 -> Charter School - fill in the name of your school | D3: ACTUAL PRIOR | E3: CURRENT | H3: AMENDED
C4: REVENUE | D4: YEAR ENDING | E4: YEAR ENDING | F4: TENTATIVE | G4: FINAL | H4: FINAL
D5: ='Form 1 Cover'!C130 -> 41455 | E5: ='Form 1 Cover'!C134 -> 41820 | F5: APPROVED | G5: APPROVED | H5: APPROVED
A6: 1000 | C6: LOCAL SOURCES
A7: 1100 | C7: Taxes
B8: 1110 | C8: Ad Valorem Taxes
B9: 1111 | C9: Net Proceed of Mines
B10: 1120 | C10: Sales & Use/School Support Taxes
B11: 1140 | C11: Penalties & Interest on Tax
B12: 1150 | C12: Residential Construction Tax
B13: 1190 | C13: Other
A14: 1200 | C14: Revenue from Local Govmt Units other than School Districts
A15: 1300 | C15: Tuition
B16: 1310 | C16: Tuition from Individuals
B17: 1320 | C17: Tuition-other Govt sources within State
B18: 1330 | C18: Tuition-other Govt sources out of State
A19: 1400 | C19: Transportation Fees
B20: 1410 | C20: Trans Fees from Individuals
B21: 1420 | C21: Trans Fees - other Govt within State
B22: 1430 | C22: Trans Fees - other Govt out of State
B23: 1440 | C23: Trans Fees - Other Private Sources
A24: 1500 | C24: Investment Income
A25: 1600 | C25: Food Services
B26: 1610 | C26: Daily Sales - Reimbursable Program
B27: 1620 | C27: Daily Sales - Non-Reimbursable Progrm
B28: 1630 | C28: Special Functions
B29: 1650 | C29: Daily Sales - Summer Food Program
A30: 1700 | C30: Direct Activities
A31: 1800 | C31: Community Service Activities
A32: 1900 | C32: Other Revenues
B33: 1910 | C33: Rent
B34: 1920 | C34: Donations
B35: 1930 | C35: Gains/Loss on Sales of Capital Assets
B36: 1940 | C36: Textbook Sales & Rentals
B37: 1950 | C37: Misc Revenues from Other Districts
B38: 1960 | C38: Misc Revenues from Other Local Govt
B39: 1970 | C39: Operating Revenues
B40: 1980 | C40: Refund of Prior Year's Expenditures
...

Sheet Form 4 Expenses
A1: ='Form 1 Cover'!A20 -> Charter School - fill in the name of your school | E1: -1 | F1: -2 | G1: -3 | H1: -4 | I1: -5
B2: Form 4 | F2: ESTIMATED | G2: ="BUDGET YEAR ENDING "&TEXT('Form 1 Cover'!C139, "MM/DD/YY") -> BUDGET YEAR ENDING 06/30/15
E3: ACTUAL PRIOR | F3: CURRENT | I3: AMENDED
B4: PROGRAM FUNCTION OBJECT | E4: YEAR ENDING | F4: YEAR ENDING | G4: TENTATIVE | H4: FINAL | I4: FINAL
E5: ='Form 1 Cover'!C130 -> 41455 | F5: ='Form 1 Cover'!C134 -> 41820 | G5: APPROVED | H5: APPROVED | I5: APPROVED
A6: 100 | C6: REGULAR PROGRAMS
B7: 1000 | D7: Instruction
C8: 100 | D8: Salaries
C9: 200 | D9: Benefits
C10: 300/400/500 Purchased Services
C11: 600 | D11: Supplies
C12: 700 | D12: Property
C13: 800 | D13: Other
B14: 2100-2600, 2900 Other Support Services
C15: 100 | D15: Salaries
C16: 200 | D16: Benefits
C17: 300/400/500 Purchased Services
C18: 600 | D18: Supplies
C19: 700 | D19: Property
C20: 800 | D20: Other
B21: 2700 Student Transportation
C22: 100 | D22: Salaries
C23: 200 | D23: Benefits
C24: 300/400/500 Purchased Services
C25: 600 | D25: Supplies
C26: 700 | D26: Property
C27: 800 | D27: Other
A28: 100 TOTAL REGULAR PROGRAMS | E28: =SUM(E8:E27) -> 0 | F28: =SUM(F8:F27) -> 0 | G28: =SUM(G8:G27) -> 0 | H28: =SUM(H8:H27) -> 0 | I28: =SUM(I8:I27) -> 0
A29: 140 | C29: Summer School for Reg Programs
B30: 1000 | D30: Instruction
C31: 100 | D31: Salaries
C32: 200 | D32: Benefits
C33: 300/400/500 Purchased Services
C34: 600 | D34: Supplies
C35: 700 | D35: Property
C36: 800 | D36: Other
B37: 2100-2600, 2900 Other Support Services
C38: 100 | D38: Salaries
C39: 200 | D39: Benefits
C40: 300/400/500 Purchased Services
...

Sheet Form 5 Exp Summary
A1: ="TENTATIVE BUDGET "&TEXT('Form 1 Cover'!C137, "MM/DD/YY") -> TENTATIVE BUDGET 2014-2015 | C1: Obj 100 | D1: Obj 200 | E1: Obj 300-900
A2: (1) PROGRAM OR FUNCTION | C2: (2) SALARIES AND WAGES | D2: (3) EMPLOYEE BENEFITS | E2: (4) SERVICES SUPPLIES AND OTHER | F2: (5) SUB-TOTAL REQUIRE- MENTS
A3: PROGRAM EXPENDITURES
A4: 100 | B4: Regular | C4: ='Form 4 Expenses'!G8+'Form 4 Expenses'!G15+'Form 4 Expenses'!G22+'Form 4 Expenses'!G31+'Form 4 Expenses'!G38+'Form 4 Expenses'!G45 -> 0 | D4: ='Form 4 Expenses'!G9+'Form 4 Expenses'!G16+'Form 4 Expenses'!G23+'Form 4 Expenses'!G32+'Form 4 Expenses'!G39+'Form 4 Expenses'!G46 -> 0 | E4: ='Form 4 Expenses'!G28+'Form 4 Expenses'!G51-'Form 5 Exp Summary'!C4-'Form 5 Exp Summary'!D4 -> 0 | F4: =SUM(C4:E4) -> 0
A5: 200 | B5: Special | C5: ='Form 4 Expenses'!G65+'Form 4 Expenses'!G72+'Form 4 Expenses'!G79+'Form 4 Expenses'!G88+'Form 4 Expenses'!G95+'Form 4 Expenses'!G102+'Form 4 Expenses'!G122+'Form 4 Expenses'!G129+'Form 4 Expenses'!G136 -> 0 | D5: ='Form 4 Expenses'!G66+'Form 4 Expenses'!G73+'Form 4 Expenses'!G80+'Form 4 Expenses'!G89+'Form 4 Expenses'!G96+'Form 4 Expenses'!G103+'Form 4 Expenses'!G123+'Form 4 Expenses'!G130+'Form 4 Expenses'!G137 -> 0 | E5: ='Form 4 Expenses'!G85+'Form 4 Expenses'!G108+'Form 4 Expenses'!G142-'Form 5 Exp Summary'!C5-'Form 5 Exp Summary'!D5 -> 0 | F5: =SUM(C5:E5) -> 0
A6: 300 | B6: Vocational | C6: ='Form 4 Expenses'!G145+'Form 4 Expenses'!G152+'Form 4 Expenses'!G159+'Form 4 Expenses'!G180+'Form 4 Expenses'!G187+'Form 4 Expenses'!G194 -> 0 | D6: ='Form 4 Expenses'!G146+'Form 4 Expenses'!G153+'Form 4 Expenses'!G160+'Form 4 Expenses'!G181+'Form 4 Expenses'!G188+'Form 4 Expenses'!G195 -> 0 | E6: ='Form 4 Expenses'!G165+'Form 4 Expenses'!G200-'Form 5 Exp Summary'!C6-'Form 5 Exp Summary'!D6 -> 0 | F6: =SUM(C6:E6) -> 0
A7: 400 | B7: Other PK-12 | C7: ='Form 4 Expenses'!G203+'Form 4 Expenses'!G210+'Form 4 Expenses'!G217+'Form 4 Expenses'!G238+'Form 4 Expenses'!G245+'Form 4 Expenses'!G252+'Form 4 Expenses'!G261+'Form 4 Expenses'!G268+'Form 4 Expenses'!G275 -> 0 | D7: ='Form 4 Expenses'!G204+'Form 4 Expenses'!G211+'Form 4 Expenses'!G218+'Form 4 Expenses'!G239+'Form 4 Expenses'!G246+'Form 4 Expenses'!G253+'Form 4 Expenses'!G262+'Form 4 Expenses'!G269+'Form 4 Expenses'!G276 -> 0 | E7: ='Form 4 Expenses'!G223+'Form 4 Expenses'!G258+'Form 4 Expenses'!G281-'Form 5 Exp Summary'!C7-'Form 5 Exp Summary'!D7 -> 0 | F7: =SUM(C7:E7) -> 0
A8: 500 | B8: Nonpublic School | F8: =SUM(C8:E8) -> 0
A9: 600 | B9: Adult Education | F9: =SUM(C9:E9) -> 0
A10: 800 | B10: Community Services | C10: ='Form 4 Expenses'!G296+'Form 4 Expenses'!G303+'Form 4 Expenses'!G310 -> 0 | D10: ='Form 4 Expenses'!G297+'Form 4 Expenses'!G304+'Form 4 Expenses'!G311 -> 0 | E10: ='Form 4 Expenses'!G316-'Form 5 Exp Summary'!C10-'Form 5 Exp Summary'!D10 -> 0 | F10: =SUM(C10:E10) -> 0
A11: 900 | B11: Co-Curricular/Extra Curricular | C11: ='Form 4 Expenses'!G319+'Form 4 Expenses'!G326+'Form 4 Expenses'!G333 -> 0 | D11: ='Form 4 Expenses'!G320+'Form 4 Expenses'!G327+'Form 4 Expenses'!G334 -> 0 | E11: ='Form 4 Expenses'!G339-'Form 5 Exp Summary'!C11-'Form 5 Exp Summary'!D11 -> 0 | F11: =SUM(C11:E11) -> 0
A12: PROGRAM TOTALS | C12: =SUM(C4:C11) -> 0 | D12: =SUM(D4:D11) -> 0 | E12: =SUM(E4:E11) -> 0 | F12: =SUM(F4:F11) -> 0
A14: 000 | B14: Undistributed Expenditures
A15: 2000 | B15: Support Services | C15: ='Form 4 Expenses'!G351+'Form 4 Expenses'!G359+'Form 4 Expenses'!G367+'Form 4 Expenses'!G375+'Form 4 Expenses'!G383+'Form 4 Expenses'!G403+'Form 4 Expenses'!G411+'Form 4 Expenses'!G419 -> 0 | D15: ='Form 4 Expenses'!G352+'Form 4 Expenses'!G360+'Form 4 Expenses'!G368+'Form 4 Expenses'!G376+'Form 4 Expenses'!G384+'Form 4 Expenses'!G404+'Form 4 Expenses'!G412+'Form 4 Expenses'!G420 -> 0 | E15: ='Form 4 Expenses'!G426-'Form 5 Exp Summary'!C15-'Form 5 Exp Summary'!D15 -> 0 | F15: =SUM(C15:E15) -> 0
A16: 3100 | B16: Food Service | C16: ='Form 4 Expenses'!G428 -> 0 | D16: ='Form 4 Expenses'!G429 -> 0 | E16: ='Form 4 Expenses'!G434-C16-D16 -> 0 | F16: =SUM(C16:E16) -> 0
A17: 4000 | B17: Facility Acquisition and Construction | E17: ='Form 4 Expenses'!G520 -> 0 | F17: =SUM(C17:E17) -> 0
A18: 5000 | B18: Debt Service | E18: ='Form 4 Expenses'!G521 -> 0 | F18: =SUM(C18:E18) -> 0
A19: 6300 | B19: Contingency | F19: ='Form 4 Expenses'!G524 -> 0
A20: 8000 | B20: Ending Balance | F20: ='Form 4 Expenses'!G526+'Form 4 Expenses'!G527 -> 0
A21: UNDISTRIBUTED TOTALS | C21: =SUM(C15:C20) -> 0 | D21: =SUM(D15:D20) -> 0 | E21: =SUM(E15:E20) -> 0 | F21: =SUM(F15:F20) -> 0
A22: TOTAL ALL FUNDS TENTATIVE | C22: =C12+C21 -> 0 | D22: =D12+D21 -> 0 | E22: =E12+E21 -> 0 | F22: =F12+F21 -> 0
A24: ="FINAL BUDGET "&TEXT('Form 1 Cover'!C137, "MM/DD/YY") -> FINAL BUDGET 2014-2015 | C24: Obj 100 | D24: Obj 200 | E24: Obj 300-900
A25: (1) PROGRAM OR FUNCTION | C25: (2) SALARIES AND WAGES | D25: (3) EMPLOYEE BENEFITS | E25: (4) SERVICES SUPPLIES AND OTHER | F25: (5) SUB-TOTAL REQUIRE- MENTS
A26: PROGRAM EXPENDITURES
A27: 100 | B27: Regular | C27: ='Form 4 Expenses'!H8+'Form 4 Expenses'!H15+'Form 4 Expenses'!H22+'Form 4 Expenses'!H31+'Form 4 Expenses'!H38+'Form 4 Expenses'!H45 -> 0 | D27: ='Form 4 Expenses'!H9+'Form 4 Expenses'!H16+'Form 4 Expenses'!H23+'Form 4 Expenses'!H32+'Form 4 Expenses'!H39+'Form 4 Expenses'!H46 -> 0 | E27: ='Form 4 Expenses'!H28+'Form 4 Expenses'!H51-'Form 5 Exp Summary'!C27-'Form 5 Exp Summary'!D27 -> 0 | F27: =SUM(C27:E27) -> 0
A28: 200 | B28: Special | C28: ='Form 4 Expenses'!H65+'Form 4 Expenses'!H72+'Form 4 Expenses'!H79+'Form 4 Expenses'!H88+'Form 4 Expenses'!H95+'Form 4 Expenses'!H102+'Form 4 Expenses'!H122+'Form 4 Expenses'!H129+'Form 4 Expenses'!H136 -> 0 | D28: ='Form 4 Expenses'!H66+'Form 4 Expenses'!H73+'Form 4 Expenses'!H80+'Form 4 Expenses'!H89+'Form 4 Expenses'!H96+'Form 4 Expenses'!H103+'Form 4 Expenses'!H123+'Form 4 Expenses'!H130+'Form 4 Expenses'!H137 -> 0 | E28: ='Form 4 Expenses'!H85+'Form 4 Expenses'!H108+'Form 4 Expenses'!H142-'Form 5 Exp Summary'!C28-'Form 5 Exp Summary'!D28 -> 0 | F28: =SUM(C28:E28) -> 0
A29: 300 | B29: Vocational | C29: ='Form 4 Expenses'!H145+'Form 4 Expenses'!H152+'Form 4 Expenses'!H159+'Form 4 Expenses'!H180+'Form 4 Expenses'!H187+'Form 4 Expenses'!H194 -> 0 | D29: ='Form 4 Expenses'!H146+'Form 4 Expenses'!H153+'Form 4 Expenses'!H160+'Form 4 Expenses'!H181+'Form 4 Expenses'!H188+'Form 4 Expenses'!H195 -> 0 | E29: ='Form 4 Expenses'!H165+'Form 4 Expenses'!H200-'Form 5 Exp Summary'!C29-'Form 5 Exp Summary'!D29 -> 0 | F29: =SUM(C29:E29) -> 0
A30: 400 | B30: Other PK-12 | C30: ='Form 4 Expenses'!H203+'Form 4 Expenses'!H210+'Form 4 Expenses'!H217+'Form 4 Expenses'!H238+'Form 4 Expenses'!H245+'Form 4 Expenses'!H252+'Form 4 Expenses'!H261+'Form 4 Expenses'!H268+'Form 4 Expenses'!H275 -> 0 | D30: ='Form 4 Expenses'!H204+'Form 4 Expenses'!H211+'Form 4 Expenses'!H218+'Form 4 Expenses'!H239+'Form 4 Expenses'!H246+'Form 4 Expenses'!H253+'Form 4 Expenses'!H262+'Form 4 Expenses'!H269+'Form 4 Expenses'!H276 -> 0 | E30: ='Form 4 Expenses'!H223+'Form 4 Expenses'!H258+'Form 4 Expenses'!H281-'Form 5 Exp Summary'!C30-'Form 5 Exp Summary'!D30 -> 0 | F30: =SUM(C30:E30) -> 0
A31: 500 | B31: Nonpublic School | C31: 0 | D31: 0 | E31: 0 | F31: =SUM(C31:E31) -> 0
A32: 600 | B32: Adult Education | C32: 0 | D32: 0 | E32: 0 | F32: =SUM(C32:E32) -> 0
A33: 800 | B33: Community Services | C33: ='Form 4 Expenses'!H296+'Form 4 Expenses'!H303+'Form 4 Expenses'!H310 -> 0 | D33: ='Form 4 Expenses'!H297+'Form 4 Expenses'!H304+'Form 4 Expenses'!H311 -> 0 | E33: ='Form 4 Expenses'!H316-'Form 5 Exp Summary'!C33-'Form 5 Exp Summary'!D33 -> 0 | F33: =SUM(C33:E33) -> 0
A34: 900 | B34: Co-Curricular/Extra Curricular | C34: ='Form 4 Expenses'!H319+'Form 4 Expenses'!H326+'Form 4 Expenses'!H333 -> 0 | D34: ='Form 4 Expenses'!H320+'Form 4 Expenses'!H327+'Form 4 Expenses'!H334 -> 0 | E34: ='Form 4 Expenses'!H339-'Form 5 Exp Summary'!C34-'Form 5 Exp Summary'!D34 -> 0 | F34: =SUM(C34:E34) -> 0
A35: PROGRAM TOTALS | C35: =SUM(C27:C34) -> 0 | D35: =SUM(D27:D34) -> 0 | E35: =SUM(E27:E34) -> 0 | F35: =SUM(F27:F34) -> 0
A37: 000 | B37: Undistributed Expenditures
A38: 2000 | B38: Support Services | C38: ='Form 4 Expenses'!H351+'Form 4 Expenses'!H359+'Form 4 Expenses'!H367+'Form 4 Expenses'!H375+'Form 4 Expenses'!H383+'Form 4 Expenses'!H403+'Form 4 Expenses'!H411+'Form 4 Expenses'!H419 -> 0 | D38: ='Form 4 Expenses'!H352+'Form 4 Expenses'!H360+'Form 4 Expenses'!H368+'Form 4 Expenses'!H376+'Form 4 Expenses'!H384+'Form 4 Expenses'!H404+'Form 4 Expenses'!H412+'Form 4 Expenses'!H420 -> 0 | E38: ='Form 4 Expenses'!H426-'Form 5 Exp Summary'!C38-'Form 5 Exp Summary'!D38 -> 0 | F38: =SUM(C38:E38) -> 0
A39: 3100 | B39: Food Service | C39: ='Form 4 Expenses'!H428 -> 0 | D39: ='Form 4 Expenses'!H429 -> 0 | E39: ='Form 4 Expenses'!H434-'Form 5 Exp Summary'!C39-'Form 5 Exp Summary'!D39 -> 0 | F39: =SUM(C39:E39) -> 0
A40: 4000 | B40: Facility Acquisition and Construction | E40: ='Form 4 Expenses'!H520 -> 0 | F40: =SUM(C40:E40) -> 0
A41: 5000 | B41: Debt Service | E41: ='Form 4 Expenses'!H521 -> 0 | F41: =SUM(C41:E41) -> 0
A42: 6300 | B42: Contingency | F42: ='Form 4 Expenses'!H524 -> 0
A43: 8000 | B43: Ending Balance | F43: ='Form 4 Expenses'!H526+'Form 4 Expenses'!H527 -> 0
...

Sheet Form 6 Proprietary-Enterprise
A1: Form 6 | D1: PROPRIETARY OR ENTERPRISE FUND
A3: ='Form 1 Cover'!A20 -> Charter School - fill in the name of your school
D4: -1 | E4: -2 | F4: -3 | G4: -4
B5: Fund: | E5: ESTIMATED | F5: ="BUDGET YEAR ENDING "&TEXT('Form 1 Cover'!C139, "MM/DD/YY") -> BUDGET YEAR ENDING 06/30/15
D6: ACTUAL PRIOR | E6: CURRENT
C7: REVENUE | D7: YEAR ENDING | E7: YEAR ENDING | F7: TENTATIVE | G7: FINAL
D8: ='Form 1 Cover'!C130 -> 41455 | E8: ='Form 1 Cover'!C134 -> 41820 | F8: APPROVED | G8: APPROVED
A9: 1000 | C9: LOCAL SOURCES
A10: 1300 | C10: Tuition
A11: 1400 | C11: Transportation Fees
A12: 1500 | C12: Investment Income
A13: 1600 | C13: Food Services
A14: 1700 | C14: Direct Activities
A15: 1800 | C15: Community Service Activities
A16: 1900 | C16: Other Revenues
A17: TOTAL LOCAL SOURCES | D17: =SUM(D10:D16) -> 0 | E17: =SUM(E10:E16) -> 0 | F17: =SUM(F10:F16) -> 0 | G17: =SUM(G10:G16) -> 0
A18: 3000 | C18: REVENUE FROM STATE SOURCES
A19: 3100 | C19: Unrestricted Grants-in-Aid
A20: 3200 | C20: State Govt Restricted Funding
A21: TOTAL STATE SOURCES | D21: =SUM(D19:D20) -> 0 | E21: =SUM(E19:E20) -> 0 | F21: =SUM(F19:F20) -> 0 | G21: =SUM(G19:G20) -> 0
A22: 4000 | C22: FEDERAL SOURCES
A23: 4100 | C23: Unrestricted Grants-in-Aid DIRECT from Fed Govt
A24: 4200 | C24: Unrestricted Grants-in-Aid from Fed Govt pass thru the State
A25: 4300 | C25: Restricted Grants-in-Aid Direct - Fed
A26: 4500 | C26: Restricted Grants-in-Aid Fed Govnt pass-thru the State
A27: 4700 | C27: Grants-in-Aid from Fed Govt Thru Other Intermediate Agencies
A28: TOTAL FEDERAL SOURCES | D28: =SUM(D23:D27) -> 0 | E28: =SUM(E23:E27) -> 0 | F28: =SUM(F23:F27) -> 0 | G28: =SUM(G23:G27) -> 0
A29: 5000 | C29: OTHER FINANCING SOURCES
A30: 5200 | C30: Fund Transfers In
A31: 5300 | C31: Proceeds from the Disposal of Real or Personal Property
A32: 5400 | C32: Loan Proceeds
A33: 5500 | C33: Capital Lease Proceeds
A34: 5600 | C34: Other Long-Term Debt Proceeds
A35: 6000 | C35: Other Items
A36: TOTAL OTHER SOURCES | D36: =SUM(D30:D35) -> 0 | E36: =SUM(E30:E35) -> 0 | F36: =SUM(F30:F35) -> 0 | G36: =SUM(G30:G35) -> 0
A37: 8000 OPENING FUND BALANCE
B38: Reserved Opening Balance
B39: Unreserved Opening Balance
A40: TOTAL OPENING FUND BALANCE | D40: =SUM(D38:D39) -> 0 | E40: =SUM(E38:E39) -> 0 | F40: =SUM(F38:F39) -> 0 | G40: =SUM(G38:G39) -> 0
A41: TOTAL ALL RESOURCES | D41: =D17+D21+D28+D36+D40 -> 0 | E41: =E17+E21+E28+E36+E40 -> 0 | F41: =F17+F21+F28+F36+F40 -> 0 | G41: =G17+G21+G28+G36+G40 -> 0
...

Sheet Form 7 Debt
A2: ='Form 1 Cover'!A20 -> Charter School - fill in the name of your school | F2: * - Type - use codes 1-11 | I2: 6 - Medium-Term Financing - Lease Purchase
F3: 1 - General Obligation Bonds | I3: 7 - Capital Leases
A4: ALL EXISTING OR PROPOSED | F4: 2 - G. O. Revenue Supported Bonds | I4: 8 - Special Assessment Bonds
F5: 3 - G. O. Special Assessment Bonds | I5: 9 - Mortgages
F6: 4 - Revenue Bonds | I6: 10 - Other (Specify Type)
F7: 5 - Medium-Term Financing | I7: 11 - Proposed (Specify Type)
A10: (1) | B10: (2) | C10: (3) | D10: (4) | E10: (5) | F10: (6) | G10: (7) | H10: (8) | I10: (9) | J10: (10) | K10: (11)
C11: Number | I11: REQUIREMENTS FOR FISCAL | K11: (9) + (10)
C12: of | H12: BEGINNING | I12: ="YEAR ENDING "&TEXT('Form 1 Cover'!C139, "MM/DD/YY") -> YEAR ENDING 06/30/15
C13: Months | D13: ORIGINAL | F13: FINAL | H13: OUTSTANDING
A14: NAME OF LOAN | B14: Type | C14: of | D14: AMOUNT OF | E14: ISSUE | F14: PAYMENT | G14: INTEREST | H14: BALANCE | I14: INTEREST | J14: PRINCIPAL | K14: ='Form 1 Cover'!C139 -> 42185
A15: List and Subtotal By Fund | B15: * | C15: TERM | D15: ISSUE | E15: DATE | F15: DATE | G15: RATE | H15: ='Form 1 Cover'!C143 -> 41821 | I15: PAYABLE | J15: PAYABLE | K15: TOTAL
A16: FUND:
K17: =I17+J17 -> 0
K18: =I18+J18 -> 0
K19: =I19+J19 -> 0
K20: =I20+J20 -> 0
K21: =I21+J21 -> 0
K22: =I22+J22 -> 0
K23: =I23+J23 -> 0
K24: =I24+J24 -> 0
K25: =I25+J25 -> 0
K26: =I26+J26 -> 0
K27: =I27+J27 -> 0
K28: =I28+J28 -> 0
... K31: =I31+J31 -> 0
A32: TOTAL ALL DEBT SERVICE | D32: =SUM(D17:D31) -> 0 | H32: =SUM(H16:H31) -> 0 | I32: =SUM(I17:I31) -> 0 | J32: =SUM(J17:J31) -> 0 | K32: =SUM(K17:K31) -> 0
A34: ='Form 1 Cover'!A20 -> Charter School - fill in the name of your school | J34: ="Budget Fiscal Year "&TEXT('Form 1 Cover'!$C$137, "mm/dd/yy") -> Budget Fiscal Year 2014-2015
A36: Form 7 INDEBTEDNESS | K36: ='Form 1 Cover'!$C$146 -> 41703

Sheet Form 8 Tuition, Transportation
B1: ='Form 1 Cover'!A20 -> Charter School - fill in the name of your school
D3: FROM DISTRICTS WITHIN NEVADA | F3: FROM DISTRICTS OUTSIDE NEVADA
A4: REPORT FOR ALL FUNDS | C4: ='Form 1 Cover'!C137 -> 2014-2015 | D4: (1) | E4: (2) | F4: (3) | G4: (4)
D5: TUITION | E5: TRANSPORTATION | F5: TUITION | G5: TRANSPORTATION
C6: Revenue | D6: 1310 NV Individual | E6: 1410 NV Individual | F6: 1310 Out-of-state Ind | G6: 1410 Out-of-state Ind
A7: REVENUES | C7: CODES | D7: 1321 NV School Dist | E7: 1421 NV School Dist | F7: 1331 Out-of-state SD | G7: 1431 Out-of-state SD
B8: Nevada Individuals | C8: 1310/1410
B9: Nevada School Districts | C9: 1321/1421
B10: Out-of-state Individuals | C10: 1310/1410
B11: Out-of-State School Districts | C11: 1331/1431
D12: =SUM(D8:D11) -> 0 | E12: =SUM(E8:E11) -> 0 | F12: =SUM(F8:F11) -> 0 | G12: =SUM(G8:G11) -> 0
D14: TO DISTRICTS WITHIN NEVADA | F14: TO DISTRICTS OUTSIDE NEVADA
A15: EXPENDITURES | C15: Object Codes | D15: 561 | E15: 511 | F15: 562 | G15: 512
B16: 100 - Regular Programs
B18: 200 - Special Programs
B20: 300 - Vocational Programs
B22: 400 - Other PK-12 Programs
B24: 500 - Nonpublic Programs
B26: 600 - Adult Programs
B27: TOTALS | D27: =SUM(D16:D26) -> 0 | E27: =SUM(E16:E26) -> 0 | F27: =SUM(F16:F26) -> 0 | G27: =SUM(G16:G26) -> 0
A29: ='Form 1 Cover'!A20 -> Charter School - fill in the name of your school | F29: ="Budget Fiscal Year "&TEXT('Form 1 Cover'!$C$137, "mm/dd/yy") -> Budget Fiscal Year 2014-2015
A33: FORM 8 - TUITION and TRANSPORTATION | G33: ='Form 1 Cover'!$C$146 -> 41703

Sheet FORM 9 Fund Transfers
A1: ='Form 1 Cover'!A20 -> Charter School - fill in the name of your school
A3: ="FUND TRANSFERS "&TEXT('Form 1 Cover'!C137, "MM/DD/YY") -> FUND TRANSFERS 2014-2015 | B3: T R A N S F E R S I N | E3: T R A N S F E R S O U T
A5: =-1 -> -1 | B5: =A5-1 -> -2 | C5: -3 | E5: =C5-1 -> -4 | F5: -5
A6: FUND TYPE | B6: FROM FUND | C6: AMOUNT | E6: TO FUND | F6: AMOUNT
A7: GENERAL FUND
A19: SUBTOTAL | B19: =SUM(B8:B18) -> 0 | C19: =SUM(C8:C18) -> 0 | E19: =SUM(E8:E18) -> 0 | F19: =SUM(F8:F18) -> 0
A20: SPECIAL REVENUE FUNDS
A32: SUBTOTAL | B32: =SUM(B21:B31) -> 0 | C32: =SUM(C21:C31) -> 0 | E32: =SUM(E21:E31) -> 0 | F32: =SUM(F21:F31) -> 0
A33: TOTAL TRANSFERS | B33: =B19+B32 -> 0 | C33: =C19+C32 -> 0 | E33: =E19+E32 -> 0 | F33: =F19+F32 -> 0
A35: ='Form 1 Cover'!A20 -> Charter School - fill in the name of your school | E35: ="Budget Fiscal Year "&TEXT('Form 1 Cover'!$C$137, "mm/dd/yy") -> Budget Fiscal Year 2014-2015
A37: FORM 9 FUND TRANSFERS | F37: ='Form 1 Cover'!$C$146 -> 41703

Sheet FORM 10 Lobby Expense
A1: ="L O B B Y E X P E N S E S "&TEXT('Form 1 Cover'!C137, "MM/DD/YY") -> L O B B Y E X P E N S E S 2014-2015
A3: Pursuant to NRS 354.600 (3), each (emphasis added) local government budget must obtain a
A4: separate statement of anticipated expenses relating to activities designed to influence the passage
A5: or defeat of legislation in an upcoming legislative session.
A9: 1. Activity:
A11: 2. Funding Source:
A13: 3. Transportation | I13: $
A15: 4. Lodging and meals | I15: $
A17: 5. Salaries and Wages | I17: $
A19: 6. Compensation to lobbyists | I19: $
A21: 7. Entertainment | I21: $
A23: 8. Supplies, equipment & facilities; other personnel and | I23: $
A24: services spent in Carson City
A26: Total | I26: $ | J26: =SUM(J13,J15,J17,J19,J21,J23) -> 0
A31: Entity:
A33: Lobbying Expense Estimate,
A36: ='Form 1 Cover'!A20 -> Charter School - fill in the name of your school | H36: ="Budget Fiscal Year "&TEXT('Form 1 Cover'!$C$137, "mm/dd/yy") -> Budget Fiscal Year 2014-2015
A40: Form 10 LOBBY EXPENSE | J40: ='Form 1 Cover'!$C$146 -> 41703

Sheet FORM 11 Cash Flow
A1: ='Form 1 Cover'!A20 -> Charter School - fill in the name of your school | F1: CASH FLOW STATEMENT
A3: ='Form 1 Cover'!C137 -> 2014-2015 | C3: PROJECTED | D3: PROJECTED | E3: PROJECTED | F3: PROJECTED | G3: PROJECTED | H3: PROJECTED | I3: PROJECTED | J3: PROJECTED | K3: PROJECTED | L3: PROJECTED | M3: PROJECTED | N3: PROJECTED | O3: Total Projected | P3: Final Approved Budget
C4: July | D4: August | E4: September | F4: October | G4: November | H4: December | I4: January | J4: February | K4: March | L4: April | M4: May | N4: June | Q4: Variance
A5: REVENUES
A6: Type:
A7: Distributive School Acct | O7: =SUM(C7:N7) -> 0 | Q7: =O7-P7 -> 0
A8: Donations | O8: =SUM(C8:N8) -> 0 | Q8: =O8-P8 -> 0
A9: Federal Grant A | O9: =SUM(C9:N9) -> 0 | Q9: =O9-P9 -> 0
O10: =SUM(C10:N10) -> 0 | Q10: =O10-P10 -> 0
O11: =SUM(C11:N11) -> 0 | Q11: =O11-P11 -> 0
O12: =SUM(C12:N12) -> 0 | Q12: =O12-P12 -> 0
O13: =SUM(C13:N13) -> 0 | Q13: =O13-P13 -> 0
O14: =SUM(C14:N14) -> 0 | Q14: =O14-P14 -> 0
A15: Total Revenues | C15: =SUM(C7:C14) -> 0 | D15: =SUM(D7:D14) -> 0 | E15: =SUM(E7:E14) -> 0 | F15: =SUM(F7:F14) -> 0 | G15: =SUM(G7:G14) -> 0 | H15: =SUM(H7:H14) -> 0 | I15: =SUM(I7:I14) -> 0 | J15: =SUM(J7:J14) -> 0 | ... Q15: =SUM(Q7:Q14) -> 0
A16: Total Revenues Y-T-D | C16: =C15 -> 0 | D16: =C16+D15 -> 0 | E16: =D16+E15 -> 0 | F16: =E16+F15 -> 0 | G16: =F16+G15 -> 0 | H16: =G16+H15 -> 0 | I16: =H16+I15 -> 0 | J16: =I16+J15 -> 0 | K16: =J16+K15 -> 0 | ... N16: =M16+N15 -> 0
A18: EXPENDITURES
A19: Salaries & Benefits
A20: Salaries | O20: =SUM(C20:N20) -> 0 | Q20: =-O20+P20 -> 0
A21: Benefits | O21: =SUM(C21:N21) -> 0 | Q21: =-O21+P21 -> 0
A22: Total Salaries & Ben | C22: =C20+C21 -> 0 | D22: =D20+D21 -> 0 | E22: =E20+E21 -> 0 | F22: =F20+F21 -> 0 | G22: =G20+G21 -> 0 | H22: =H20+H21 -> 0 | I22: =I20+I21 -> 0 | J22: =J20+J21 -> 0 | ... O22: =O20+O21 -> 0 | P22: =SUM(P20:P21) -> 0 | Q22: =SUM(Q20:Q21) -> 0
A24: Operating
A25: Supplies | O25: =SUM(C25:N25) -> 0 | Q25: =-O25+P25 -> 0
A26: Rent | O26: =SUM(C26:N26) -> 0 | Q26: =-O26+P26 -> 0
A27: Utilities | O27: =SUM(C27:N27) -> 0 | Q27: =-O27+P27 -> 0
A28: Contracts | O28: =SUM(C28:N28) -> 0 | Q28: =-O28+P28 -> 0
A29: Textbooks | O29: =SUM(C29:N29) -> 0 | Q29: =-O29+P29 -> 0
A30: Equipment | O30: =SUM(C30:N30) -> 0 | Q30: =-O30+P30 -> 0
O31: =SUM(C31:N31) -> 0 | Q31: =-O31+P31 -> 0
O32: =SUM(C32:N32) -> 0 | Q32: =-O32+P32 -> 0
O33: =SUM(C33:N33) -> 0 | Q33: =-O33+P33 -> 0
O34: =SUM(C34:N34) -> 0 | Q34: =-O34+P34 -> 0
O35: =SUM(C35:N35) -> 0 | Q35: =-O35+P35 -> 0
O36: =SUM(C36:N36) -> 0 | Q36: =-O36+P36 -> 0
O37: =SUM(C37:N37) -> 0 | Q37: =-O37+P37 -> 0
O38: =SUM(C38:N38) -> 0 | Q38: =-O38+P38 -> 0
O39: =SUM(C39:N39) -> 0 | Q39: =-O39+P39 -> 0
O40: =SUM(C40:N40) -> 0 | Q40: =-O40+P40 -> 0
O41: =SUM(C41:N41) -> 0 | Q41: =-O41+P41 -> 0
O42: =SUM(C42:N42) -> 0 | Q42: =-O42+P42 -> 0
N43: W
...
