Workbook
Name Misc_gear: Gear!$O$1:$S$100

Sheet Spell Data
A1: Spell | B1: Rank | C1: Level obtained | D1: Effect
A2: Faerie Fire Feral | B2: 1 | C2: 30 | D2: 175 | E2: Armor reduction
A3: Faerie Fire Feral | B3: 2 | C3: 40 | D3: 285 | E3: Armor reduction
A4: Faerie Fire Feral | B4: 3 | C4: 50 | D4: 395 | E4: Armor reduction
A5: Faerie Fire Feral | B5: 4 | C5: 60 | D5: 505 | E5: Armor reduction
A6: Faerie Fire Feral | B6: 5 | C6: 70 | D6: 610 | E6: Armor reduction
A7: Mangle | B7: 1 | C7: 50 | D7: 158 | E7: Extra damage
A8: Mangle | B8: 2 | C8: 58 | D8: 205 | E8: Extra damage
A9: Mangle | B9: 3 | C9: 68 | D9: 264 | E9: Extra damage
A10: Rip | B10: 1 | C10: 20 | D10: 197 | E10: Base dot
A11: Rip | B11: 2 | C11: 28 | D11: 335 | E11: Base dot
A12: Rip | B12: 3 | C12: 36 | D12: 438 | E12: Base dot
A13: Rip | B13: 4 | C13: 44 | D13: 678 | E13: Base dot
... A23: Shred | B23: 7 | C23: 70 | D23: 405 | E23: Extra damage
A24: ZZZ ---end of list. do not remove this line, and ensure spells are in alphabetical order

Sheet Basic
A1: Parameter | B1: Value
A2: Character Race | B2: Night Elf | C2: No effect yet
A3: Character Level | B3: 70
A4: Target Level | B4: 73
A5: Level Difference | B5: =B4-B3 -> 3
A6: Weapon skill deficit | B6: =B5*5 -> 15
A7: Attacking from behind | B7: 1 | C7: 1 for yes, 0 for no - only 1 properly supported
A8: Damage reduction | B8: 0.8 | C8: 0.8 means 20% damage reduction from boss armor
A9: Energy refund on miss | B9: 0.82 | C9: You get 82% of your energy refunded on a special that doesn't connect
A10: Kings | B10: 1.05 | C10: Blessing of kings multiplier: 1.1 or 1

Sheet Spell Ranks
A1: Spell | B1: Rank | C1: Effect | F1: Start-index | G1: End-index | H1: Rank Range | I1: Value Range
A2: Faerie Fire Feral | B2: =N(MATCH(basic!B3,INDIRECT(H2),1)) -> 5 | C2: =IF(ISNA(B2),0,INDEX(INDIRECT(I2),B2,1)) -> 610 | D2: =IF(ISNA(B2),"",INDEX(INDIRECT(I2),B2,2)) -> Armor reduction | F2: =MATCH(A2,'spell data'!A:A,0) -> 2 | G2: =(MATCH(A2,INDIRECT(CONCATENATE("'Spell Data'!A",(F2-1),":A999"),1),1)+F2)-2 -> 6 | H2: =CONCATENATE("'Spell Data'!C",F2,":C",G2) -> 'Spell Data'!C2:C6 | I2: =CONCATENATE("'Spell Data'!D",F2,":E",G2) -> 'Spell Data'!D2:E6
A3: Mangle | B3: =N(MATCH(basic!B3,INDIRECT(H3),1)) -> 3 | C3: =IF(ISNA(B3),0,INDEX(INDIRECT(I3),B3,1)) -> 264 | D3: =IF(ISNA(B3),"",INDEX(INDIRECT(I3),B3,2)) -> Extra damage | F3: =MATCH(A3,'spell data'!A:A,0) -> 7 | G3: =(MATCH(A3,INDIRECT(CONCATENATE("'Spell Data'!A",F3,":A999"),1))+F3)-1 -> 9 | H3: =CONCATENATE("'Spell Data'!C",F3,":C",G3) -> 'Spell Data'!C7:C9 | I3: =CONCATENATE("'Spell Data'!D",F3,":E",G3) -> 'Spell Data'!D7:E9
A4: Rip | B4: =N(MATCH(basic!B3,INDIRECT(H4),1)) -> 7 | C4: =IF(ISNA(B4),0,INDEX(INDIRECT(I4),B4,1)) -> 1562 | D4: =IF(ISNA(B4),"",INDEX(INDIRECT(I4),B4,2)) -> Base dot | F4: =MATCH(A4,'spell data'!A:A,0) -> 10 | G4: =(MATCH(A4,INDIRECT(CONCATENATE("'Spell Data'!A",F4,":A999"),1))+F4)-1 -> 16 | H4: =CONCATENATE("'Spell Data'!C",F4,":C",G4) -> 'Spell Data'!C10:C16 | I4: =CONCATENATE("'Spell Data'!D",F4,":E",G4) -> 'Spell Data'!D10:E16
A5: Shred | B5: =N(MATCH(basic!B3,INDIRECT(H5),1)) -> 7 | C5: =IF(ISNA(B5),0,INDEX(INDIRECT(I5),B5,1)) -> 405 | D5: =IF(ISNA(B5),"",INDEX(INDIRECT(I5),B5,2)) -> Extra damage | F5: =MATCH(A5,'spell data'!A:A,0) -> 17 | G5: =(MATCH(A5,INDIRECT(CONCATENATE("'Spell Data'!A",F5,":A999"),1))+F5)-1 -> 23 | H5: =CONCATENATE("'Spell Data'!C",F5,":C",G5) -> 'Spell Data'!C17:C23 | I5: =CONCATENATE("'Spell Data'!D",F5,":E",G5) -> 'Spell Data'!D17:E23

Sheet Gear
A1: Slot | B1: Name | C1: STR | D1: AGI | E1: STA | F1: INT | G1: SPI | H1: '+AP | I1: Hit | J1: Crit | K1: Feral | L1: Haste | M1: Wdmg | N1: Misc
A2: Head | B2: Stag-Helm of Malorne | C2: 53 | D2: 55 | E2: 49 | F2: 20 | I2: 4 | N2: relentless | O2: =IF(ISNUMBER(SEARCH(" ",$N2)),LEFT($N2,(SEARCH(" ",$N2)-1)),$N2) -> relentless | P2: =IF((LEN($N2)=((LEN(CONCATENATE($O2:O2))+COUNTA($O2:O2))-1)), "", IF( ISNUMBER(SEARCH(" ",$N2,((1+COUNTA($O2:O2))+LEN(CONCATENATE($O2:O2))))), MID($N2,((1+COUNTA($O2:O2))+LEN(CONCATENATE($O2:O2))),(((SEARCH(" ",$N2,((1+COUNTA($O2:O2))+LEN(CONCATENATE($O2:O2))))-1)-COUNTA($O2:O2))-LEN(CONCATENATE($O2:O2)))), RIGHT($N2,((((1+LEN($N2))-1)-COUNTA($O2:O2))-LEN(CONCATENATE($O2:O2)))))) | Q2: =IF((LEN($N2)=((LEN(CONCATENATE($O2:P2))+COUNTA($O2:P2))-1)), "", IF( ISNUMBER(SEARCH(" ",$N2,((1+COUNTA($O2:P2))+LEN(CONCATENATE($O2:P2))))), MID($N2,((1+COUNTA($O2:P2))+LEN(CONCATENATE($O2:P2))),(((SEARCH(" ",$N2,((1+COUNTA($O2:P2))+LEN(CONCATENATE($O2:P2))))-1)-COUNTA($O2:P2))-LEN(CONCATENATE($O2:P2)))), RIGHT($N2,((((1+LEN($N2))-1)-COUNTA($O2:P2))-LEN(CONCATENATE($O2:P2)))))) | R2: =IF((LEN($N2)=((LEN(CONCATENATE($O2:Q2))+COUNTA($O2:Q2))-1)), "", IF( ISNUMBER(SEARCH(" ",$N2,((1+COUNTA($O2:Q2))+LEN(CONCATENATE($O2:Q2))))), MID($N2,((1+COUNTA($O2:Q2))+LEN(CONCATENATE($O2:Q2))),(((SEARCH(" ",$N2,((1+COUNTA($O2:Q2))+LEN(CONCATENATE($O2:Q2))))-1)-COUNTA($O2:Q2))-LEN(CONCATENATE($O2:Q2)))), RIGHT($N2,((((1+LEN($N2))-1)-COUNTA($O2:Q2))-LEN(CONCATENATE($O2:Q2)))))) | S2: =IF((LEN($N2)=((LEN(CONCATENATE($O2:R2))+COUNTA($O2:R2))-1)), "", IF( ISNUMBER(SEARCH(" ",$N2,((1+COUNTA($O2:R2))+LEN(CONCATENATE($O2:R2))))), MID($N2,((1+COUNTA($O2:R2))+LEN(CONCATENATE($O2:R2))),(((SEARCH(" ",$N2,((1+COUNTA($O2:R2))+LEN(CONCATENATE($O2:R2))))-1)-COUNTA($O2:R2))-LEN(CONCATENATE($O2:R2)))), RIGHT($N2,((((1+LEN($N2))-1)-COUNTA($O2:R2))-LEN(CONCATENATE($O2:R2))))))
A3: Head Enchant | B3: Glyph of Ferocity | H3: 34 | I3: 16 | O3: =IF(ISNUMBER(SEARCH(" ",$N3)),LEFT($N3,(SEARCH(" ",$N3)-1)),$N3) | P3: =IF((LEN($N3)=((LEN(CONCATENATE($O3:O3))+COUNTA($O3:O3))-1)), "", IF( ISNUMBER(SEARCH(" ",$N3,((1+COUNTA($O3:O3))+LEN(CONCATENATE($O3:O3))))), MID($N3,((1+COUNTA($O3:O3))+LEN(CONCATENATE($O3:O3))),(((SEARCH(" ",$N3,((1+COUNTA($O3:O3))+LEN(CONCATENATE($O3:O3))))-1)-COUNTA($O3:O3))-LEN(CONCATENATE($O3:O3)))), RIGHT($N3,((((1+LEN($N3))-1)-COUNTA($O3:O3))-LEN(CONCATENATE($O3:O3)))))) | Q3: =IF((LEN($N3)=((LEN(CONCATENATE($O3:P3))+COUNTA($O3:P3))-1)), "", IF( ISNUMBER(SEARCH(" ",$N3,((1+COUNTA($O3:P3))+LEN(CONCATENATE($O3:P3))))), MID($N3,((1+COUNTA($O3:P3))+LEN(CONCATENATE($O3:P3))),(((SEARCH(" ",$N3,((1+COUNTA($O3:P3))+LEN(CONCATENATE($O3:P3))))-1)-COUNTA($O3:P3))-LEN(CONCATENATE($O3:P3)))), RIGHT($N3,((((1+LEN($N3))-1)-COUNTA($O3:P3))-LEN(CONCATENATE($O3:P3)))))) | R3: =IF((LEN($N3)=((LEN(CONCATENATE($O3:Q3))+COUNTA($O3:Q3))-1)), "", IF( ISNUMBER(SEARCH(" ",$N3,((1+COUNTA($O3:Q3))+LEN(CONCATENATE($O3:Q3))))), MID($N3,((1+COUNTA($O3:Q3))+LEN(CONCATENATE($O3:Q3))),(((SEARCH(" ",$N3,((1+COUNTA($O3:Q3))+LEN(CONCATENATE($O3:Q3))))-1)-COUNTA($O3:Q3))-LEN(CONCATENATE($O3:Q3)))), RIGHT($N3,((((1+LEN($N3))-1)-COUNTA($O3:Q3))-LEN(CONCATENATE($O3:Q3)))))) | S3: =IF((LEN($N3)=((LEN(CONCATENATE($O3:R3))+COUNTA($O3:R3))-1)), "", IF( ISNUMBER(SEARCH(" ",$N3,((1+COUNTA($O3:R3))+LEN(CONCATENATE($O3:R3))))), MID($N3,((1+COUNTA($O3:R3))+LEN(CONCATENATE($O3:R3))),(((SEARCH(" ",$N3,((1+COUNTA($O3:R3))+LEN(CONCATENATE($O3:R3))))-1)-COUNTA($O3:R3))-LEN(CONCATENATE($O3:R3)))), RIGHT($N3,((((1+LEN($N3))-1)-COUNTA($O3:R3))-LEN(CONCATENATE($O3:R3))))))
A4: Neck | B4: Mithril Chain of Heroism | C4: 28 | D4: 22 | E4: 22 | O4: =IF(ISNUMBER(SEARCH(" ",$N4)),LEFT($N4,(SEARCH(" ",$N4)-1)),$N4) | P4: =IF((LEN($N4)=((LEN(CONCATENATE($O4:O4))+COUNTA($O4:O4))-1)), "", IF( ISNUMBER(SEARCH(" ",$N4,((1+COUNTA($O4:O4))+LEN(CONCATENATE($O4:O4))))), MID($N4,((1+COUNTA($O4:O4))+LEN(CONCATENATE($O4:O4))),(((SEARCH(" ",$N4,((1+COUNTA($O4:O4))+LEN(CONCATENATE($O4:O4))))-1)-COUNTA($O4:O4))-LEN(CONCATENATE($O4:O4)))), RIGHT($N4,((((1+LEN($N4))-1)-COUNTA($O4:O4))-LEN(CONCATENATE($O4:O4)))))) | Q4: =IF((LEN($N4)=((LEN(CONCATENATE($O4:P4))+COUNTA($O4:P4))-1)), "", IF( ISNUMBER(SEARCH(" ",$N4,((1+COUNTA($O4:P4))+LEN(CONCATENATE($O4:P4))))), MID($N4,((1+COUNTA($O4:P4))+LEN(CONCATENATE($O4:P4))),(((SEARCH(" ",$N4,((1+COUNTA($O4:P4))+LEN(CONCATENATE($O4:P4))))-1)-COUNTA($O4:P4))-LEN(CONCATENATE($O4:P4)))), RIGHT($N4,((((1+LEN($N4))-1)-COUNTA($O4:P4))-LEN(CONCATENATE($O4:P4)))))) | R4: =IF((LEN($N4)=((LEN(CONCATENATE($O4:Q4))+COUNTA($O4:Q4))-1)), "", IF( ISNUMBER(SEARCH(" ",$N4,((1+COUNTA($O4:Q4))+LEN(CONCATENATE($O4:Q4))))), MID($N4,((1+COUNTA($O4:Q4))+LEN(CONCATENATE($O4:Q4))),(((SEARCH(" ",$N4,((1+COUNTA($O4:Q4))+LEN(CONCATENATE($O4:Q4))))-1)-COUNTA($O4:Q4))-LEN(CONCATENATE($O4:Q4)))), RIGHT($N4,((((1+LEN($N4))-1)-COUNTA($O4:Q4))-LEN(CONCATENATE($O4:Q4)))))) | S4: =IF((LEN($N4)=((LEN(CONCATENATE($O4:R4))+COUNTA($O4:R4))-1)), "", IF( ISNUMBER(SEARCH(" ",$N4,((1+COUNTA($O4:R4))+LEN(CONCATENATE($O4:R4))))), MID($N4,((1+COUNTA($O4:R4))+LEN(CONCATENATE($O4:R4))),(((SEARCH(" ",$N4,((1+COUNTA($O4:R4))+LEN(CONCATENATE($O4:R4))))-1)-COUNTA($O4:R4))-LEN(CONCATENATE($O4:R4)))), RIGHT($N4,((((1+LEN($N4))-1)-COUNTA($O4:R4))-LEN(CONCATENATE($O4:R4))))))
A5: Shoulder | B5: Mantle of Malorne | C5: 39 | D5: 44 | E5: 40 | F5: 12 | I5: 4 | O5: =IF(ISNUMBER(SEARCH(" ",$N5)),LEFT($N5,(SEARCH(" ",$N5)-1)),$N5) | P5: =IF((LEN($N5)=((LEN(CONCATENATE($O5:O5))+COUNTA($O5:O5))-1)), "", IF( ISNUMBER(SEARCH(" ",$N5,((1+COUNTA($O5:O5))+LEN(CONCATENATE($O5:O5))))), MID($N5,((1+COUNTA($O5:O5))+LEN(CONCATENATE($O5:O5))),(((SEARCH(" ",$N5,((1+COUNTA($O5:O5))+LEN(CONCATENATE($O5:O5))))-1)-COUNTA($O5:O5))-LEN(CONCATENATE($O5:O5)))), RIGHT($N5,((((1+LEN($N5))-1)-COUNTA($O5:O5))-LEN(CONCATENATE($O5:O5)))))) | Q5: =IF((LEN($N5)=((LEN(CONCATENATE($O5:P5))+COUNTA($O5:P5))-1)), "", IF( ISNUMBER(SEARCH(" ",$N5,((1+COUNTA($O5:P5))+LEN(CONCATENATE($O5:P5))))), MID($N5,((1+COUNTA($O5:P5))+LEN(CONCATENATE($O5:P5))),(((SEARCH(" ",$N5,((1+COUNTA($O5:P5))+LEN(CONCATENATE($O5:P5))))-1)-COUNTA($O5:P5))-LEN(CONCATENATE($O5:P5)))), RIGHT($N5,((((1+LEN($N5))-1)-COUNTA($O5:P5))-LEN(CONCATENATE($O5:P5)))))) | R5: =IF((LEN($N5)=((LEN(CONCATENATE($O5:Q5))+COUNTA($O5:Q5))-1)), "", IF( ISNUMBER(SEARCH(" ",$N5,((1+COUNTA($O5:Q5))+LEN(CONCATENATE($O5:Q5))))), MID($N5,((1+COUNTA($O5:Q5))+LEN(CONCATENATE($O5:Q5))),(((SEARCH(" ",$N5,((1+COUNTA($O5:Q5))+LEN(CONCATENATE($O5:Q5))))-1)-COUNTA($O5:Q5))-LEN(CONCATENATE($O5:Q5)))), RIGHT($N5,((((1+LEN($N5))-1)-COUNTA($O5:Q5))-LEN(CONCATENATE($O5:Q5)))))) | S5: =IF((LEN($N5)=((LEN(CONCATENATE($O5:R5))+COUNTA($O5:R5))-1)), "", IF( ISNUMBER(SEARCH(" ",$N5,((1+COUNTA($O5:R5))+LEN(CONCATENATE($O5:R5))))), MID($N5,((1+COUNTA($O5:R5))+LEN(CONCATENATE($O5:R5))),(((SEARCH(" ",$N5,((1+COUNTA($O5:R5))+LEN(CONCATENATE($O5:R5))))-1)-COUNTA($O5:R5))-LEN(CONCATENATE($O5:R5)))), RIGHT($N5,((((1+LEN($N5))-1)-COUNTA($O5:R5))-LEN(CONCATENATE($O5:R5))))))
A6: Shoulder Enchant | B6: Aldor Melee Exalted | H6: 30 | J6: 10 | O6: =IF(ISNUMBER(SEARCH(" ",$N6)),LEFT($N6,(SEARCH(" ",$N6)-1)),$N6) | P6: =IF((LEN($N6)=((LEN(CONCATENATE($O6:O6))+COUNTA($O6:O6))-1)), "", IF( ISNUMBER(SEARCH(" ",$N6,((1+COUNTA($O6:O6))+LEN(CONCATENATE($O6:O6))))), MID($N6,((1+COUNTA($O6:O6))+LEN(CONCATENATE($O6:O6))),(((SEARCH(" ",$N6,((1+COUNTA($O6:O6))+LEN(CONCATENATE($O6:O6))))-1)-COUNTA($O6:O6))-LEN(CONCATENATE($O6:O6)))), RIGHT($N6,((((1+LEN($N6))-1)-COUNTA($O6:O6))-LEN(CONCATENATE($O6:O6)))))) | Q6: =IF((LEN($N6)=((LEN(CONCATENATE($O6:P6))+COUNTA($O6:P6))-1)), "", IF( ISNUMBER(SEARCH(" ",$N6,((1+COUNTA($O6:P6))+LEN(CONCATENATE($O6:P6))))), MID($N6,((1+COUNTA($O6:P6))+LEN(CONCATENATE($O6:P6))),(((SEARCH(" ",$N6,((1+COUNTA($O6:P6))+LEN(CONCATENATE($O6:P6))))-1)-COUNTA($O6:P6))-LEN(CONCATENATE($O6:P6)))), RIGHT($N6,((((1+LEN($N6))-1)-COUNTA($O6:P6))-LEN(CONCATENATE($O6:P6)))))) | R6: =IF((LEN($N6)=((LEN(CONCATENATE($O6:Q6))+COUNTA($O6:Q6))-1)), "", IF( ISNUMBER(SEARCH(" ",$N6,((1+COUNTA($O6:Q6))+LEN(CONCATENATE($O6:Q6))))), MID($N6,((1+COUNTA($O6:Q6))+LEN(CONCATENATE($O6:Q6))),(((SEARCH(" ",$N6,((1+COUNTA($O6:Q6))+LEN(CONCATENATE($O6:Q6))))-1)-COUNTA($O6:Q6))-LEN(CONCATENATE($O6:Q6)))), RIGHT($N6,((((1+LEN($N6))-1)-COUNTA($O6:Q6))-LEN(CONCATENATE($O6:Q6)))))) | S6: =IF((LEN($N6)=((LEN(CONCATENATE($O6:R6))+COUNTA($O6:R6))-1)), "", IF( ISNUMBER(SEARCH(" ",$N6,((1+COUNTA($O6:R6))+LEN(CONCATENATE($O6:R6))))), MID($N6,((1+COUNTA($O6:R6))+LEN(CONCATENATE($O6:R6))),(((SEARCH(" ",$N6,((1+COUNTA($O6:R6))+LEN(CONCATENATE($O6:R6))))-1)-COUNTA($O6:R6))-LEN(CONCATENATE($O6:R6)))), RIGHT($N6,((((1+LEN($N6))-1)-COUNTA($O6:R6))-LEN(CONCATENATE($O6:R6))))))
A7: Back | B7: Vengeance Wrap | D7: 8 | H7: 52 | I7: 2 | J7: 23 | O7: =IF(ISNUMBER(SEARCH(" ",$N7)),LEFT($N7,(SEARCH(" ",$N7)-1)),$N7) | P7: =IF((LEN($N7)=((LEN(CONCATENATE($O7:O7))+COUNTA($O7:O7))-1)), "", IF( ISNUMBER(SEARCH(" ",$N7,((1+COUNTA($O7:O7))+LEN(CONCATENATE($O7:O7))))), MID($N7,((1+COUNTA($O7:O7))+LEN(CONCATENATE($O7:O7))),(((SEARCH(" ",$N7,((1+COUNTA($O7:O7))+LEN(CONCATENATE($O7:O7))))-1)-COUNTA($O7:O7))-LEN(CONCATENATE($O7:O7)))), RIGHT($N7,((((1+LEN($N7))-1)-COUNTA($O7:O7))-LEN(CONCATENATE($O7:O7)))))) | Q7: =IF((LEN($N7)=((LEN(CONCATENATE($O7:P7))+COUNTA($O7:P7))-1)), "", IF( ISNUMBER(SEARCH(" ",$N7,((1+COUNTA($O7:P7))+LEN(CONCATENATE($O7:P7))))), MID($N7,((1+COUNTA($O7:P7))+LEN(CONCATENATE($O7:P7))),(((SEARCH(" ",$N7,((1+COUNTA($O7:P7))+LEN(CONCATENATE($O7:P7))))-1)-COUNTA($O7:P7))-LEN(CONCATENATE($O7:P7)))), RIGHT($N7,((((1+LEN($N7))-1)-COUNTA($O7:P7))-LEN(CONCATENATE($O7:P7)))))) | R7: =IF((LEN($N7)=((LEN(CONCATENATE($O7:Q7))+COUNTA($O7:Q7))-1)), "", IF( ISNUMBER(SEARCH(" ",$N7,((1+COUNTA($O7:Q7))+LEN(CONCATENATE($O7:Q7))))), MID($N7,((1+COUNTA($O7:Q7))+LEN(CONCATENATE($O7:Q7))),(((SEARCH(" ",$N7,((1+COUNTA($O7:Q7))+LEN(CONCATENATE($O7:Q7))))-1)-COUNTA($O7:Q7))-LEN(CONCATENATE($O7:Q7)))), RIGHT($N7,((((1+LEN($N7))-1)-COUNTA($O7:Q7))-LEN(CONCATENATE($O7:Q7)))))) | S7: =IF((LEN($N7)=((LEN(CONCATENATE($O7:R7))+COUNTA($O7:R7))-1)), "", IF( ISNUMBER(SEARCH(" ",$N7,((1+COUNTA($O7:R7))+LEN(CONCATENATE($O7:R7))))), MID($N7,((1+COUNTA($O7:R7))+LEN(CONCATENATE($O7:R7))),(((SEARCH(" ",$N7,((1+COUNTA($O7:R7))+LEN(CONCATENATE($O7:R7))))-1)-COUNTA($O7:R7))-LEN(CONCATENATE($O7:R7)))), RIGHT($N7,((((1+LEN($N7))-1)-COUNTA($O7:R7))-LEN(CONCATENATE($O7:R7))))))
A8: Back Enchant | B8: Greater Agility | D8: 12 | O8: =IF(ISNUMBER(SEARCH(" ",$N8)),LEFT($N8,(SEARCH(" ",$N8)-1)),$N8) | P8: =IF((LEN($N8)=((LEN(CONCATENATE($O8:O8))+COUNTA($O8:O8))-1)), "", IF( ISNUMBER(SEARCH(" ",$N8,((1+COUNTA($O8:O8))+LEN(CONCATENATE($O8:O8))))), MID($N8,((1+COUNTA($O8:O8))+LEN(CONCATENATE($O8:O8))),(((SEARCH(" ",$N8,((1+COUNTA($O8:O8))+LEN(CONCATENATE($O8:O8))))-1)-COUNTA($O8:O8))-LEN(CONCATENATE($O8:O8)))), RIGHT($N8,((((1+LEN($N8))-1)-COUNTA($O8:O8))-LEN(CONCATENATE($O8:O8)))))) | Q8: =IF((LEN($N8)=((LEN(CONCATENATE($O8:P8))+COUNTA($O8:P8))-1)), "", IF( ISNUMBER(SEARCH(" ",$N8,((1+COUNTA($O8:P8))+LEN(CONCATENATE($O8:P8))))), MID($N8,((1+COUNTA($O8:P8))+LEN(CONCATENATE($O8:P8))),(((SEARCH(" ",$N8,((1+COUNTA($O8:P8))+LEN(CONCATENATE($O8:P8))))-1)-COUNTA($O8:P8))-LEN(CONCATENATE($O8:P8)))), RIGHT($N8,((((1+LEN($N8))-1)-COUNTA($O8:P8))-LEN(CONCATENATE($O8:P8)))))) | R8: =IF((LEN($N8)=((LEN(CONCATENATE($O8:Q8))+COUNTA($O8:Q8))-1)), "", IF( ISNUMBER(SEARCH(" ",$N8,((1+COUNTA($O8:Q8))+LEN(CONCATENATE($O8:Q8))))), MID($N8,((1+COUNTA($O8:Q8))+LEN(CONCATENATE($O8:Q8))),(((SEARCH(" ",$N8,((1+COUNTA($O8:Q8))+LEN(CONCATENATE($O8:Q8))))-1)-COUNTA($O8:Q8))-LEN(CONCATENATE($O8:Q8)))), RIGHT($N8,((((1+LEN($N8))-1)-COUNTA($O8:Q8))-LEN(CONCATENATE($O8:Q8)))))) | S8: =IF((LEN($N8)=((LEN(CONCATENATE($O8:R8))+COUNTA($O8:R8))-1)), "", IF( ISNUMBER(SEARCH(" ",$N8,((1+COUNTA($O8:R8))+LEN(CONCATENATE($O8:R8))))), MID($N8,((1+COUNTA($O8:R8))+LEN(CONCATENATE($O8:R8))),(((SEARCH(" ",$N8,((1+COUNTA($O8:R8))+LEN(CONCATENATE($O8:R8))))-1)-COUNTA($O8:R8))-LEN(CONCATENATE($O8:R8)))), RIGHT($N8,((((1+LEN($N8))-1)-COUNTA($O8:R8))-LEN(CONCATENATE($O8:R8))))))
A9: Chest | B9: Primalstrike Vest | D9: 38 | E9: 39 | H9: 108 | I9: 12 | N9: primalstrike | O9: =IF(ISNUMBER(SEARCH(" ",$N9)),LEFT($N9,(SEARCH(" ",$N9)-1)),$N9) -> primalstrike | P9: =IF((LEN($N9)=((LEN(CONCATENATE($O9:O9))+COUNTA($O9:O9))-1)), "", IF( ISNUMBER(SEARCH(" ",$N9,((1+COUNTA($O9:O9))+LEN(CONCATENATE($O9:O9))))), MID($N9,((1+COUNTA($O9:O9))+LEN(CONCATENATE($O9:O9))),(((SEARCH(" ",$N9,((1+COUNTA($O9:O9))+LEN(CONCATENATE($O9:O9))))-1)-COUNTA($O9:O9))-LEN(CONCATENATE($O9:O9)))), RIGHT($N9,((((1+LEN($N9))-1)-COUNTA($O9:O9))-LEN(CONCATENATE($O9:O9)))))) | Q9: =IF((LEN($N9)=((LEN(CONCATENATE($O9:P9))+COUNTA($O9:P9))-1)), "", IF( ISNUMBER(SEARCH(" ",$N9,((1+COUNTA($O9:P9))+LEN(CONCATENATE($O9:P9))))), MID($N9,((1+COUNTA($O9:P9))+LEN(CONCATENATE($O9:P9))),(((SEARCH(" ",$N9,((1+COUNTA($O9:P9))+LEN(CONCATENATE($O9:P9))))-1)-COUNTA($O9:P9))-LEN(CONCATENATE($O9:P9)))), RIGHT($N9,((((1+LEN($N9))-1)-COUNTA($O9:P9))-LEN(CONCATENATE($O9:P9)))))) | R9: =IF((LEN($N9)=((LEN(CONCATENATE($O9:Q9))+COUNTA($O9:Q9))-1)), "", IF( ISNUMBER(SEARCH(" ",$N9,((1+COUNTA($O9:Q9))+LEN(CONCATENATE($O9:Q9))))), MID($N9,((1+COUNTA($O9:Q9))+LEN(CONCATENATE($O9:Q9))),(((SEARCH(" ",$N9,((1+COUNTA($O9:Q9))+LEN(CONCATENATE($O9:Q9))))-1)-COUNTA($O9:Q9))-LEN(CONCATENATE($O9:Q9)))), RIGHT($N9,((((1+LEN($N9))-1)-COUNTA($O9:Q9))-LEN(CONCATENATE($O9:Q9)))))) | S9: =IF((LEN($N9)=((LEN(CONCATENATE($O9:R9))+COUNTA($O9:R9))-1)), "", IF( ISNUMBER(SEARCH(" ",$N9,((1+COUNTA($O9:R9))+LEN(CONCATENATE($O9:R9))))), MID($N9,((1+COUNTA($O9:R9))+LEN(CONCATENATE($O9:R9))),(((SEARCH(" ",$N9,((1+COUNTA($O9:R9))+LEN(CONCATENATE($O9:R9))))-1)-COUNTA($O9:R9))-LEN(CONCATENATE($O9:R9)))), RIGHT($N9,((((1+LEN($N9))-1)-COUNTA($O9:R9))-LEN(CONCATENATE($O9:R9))))))
A10: Chest Enchant | B10: Exceptional Stats | C10: 6 | D10: 6 | E10: 6 | F10: 6 | G10: 6 | H10: 6 | O10: =IF(ISNUMBER(SEARCH(" ",$N10)),LEFT($N10,(SEARCH(" ",$N10)-1)),$N10) | P10: =IF((LEN($N10)=((LEN(CONCATENATE($O10:O10))+COUNTA($O10:O10))-1)), "", IF( ISNUMBER(SEARCH(" ",$N10,((1+COUNTA($O10:O10))+LEN(CONCATENATE($O10:O10))))), MID($N10,((1+COUNTA($O10:O10))+LEN(CONCATENATE($O10:O10))),(((SEARCH(" ",$N10,((1+COUNTA($O10:O10))+LEN(CONCATENATE($O10:O10))))-1)-COUNTA($O10:O10))-LEN(CONCATENATE($O10:O10)))), RIGHT($N10,((((1+LEN($N10))-1)-COUNTA($O10:O10))-LEN(CONCATENATE($O10:O10)))))) | Q10: =IF((LEN($N10)=((LEN(CONCATENATE($O10:P10))+COUNTA($O10:P10))-1)), "", IF( ISNUMBER(SEARCH(" ",$N10,((1+COUNTA($O10:P10))+LEN(CONCATENATE($O10:P10))))), MID($N10,((1+COUNTA($O10:P10))+LEN(CONCATENATE($O10:P10))),(((SEARCH(" ",$N10,((1+COUNTA($O10:P10))+LEN(CONCATENATE($O10:P10))))-1)-COUNTA($O10:P10))-LEN(CONCATENATE($O10:P10)))), RIGHT($N10,((((1+LEN($N10))-1)-COUNTA($O10:P10))-LEN(CONCATENATE($O10:P10)))))) | R10: =IF((LEN($N10)=((LEN(CONCATENATE($O10:Q10))+COUNTA($O10:Q10))-1)), "", IF( ISNUMBER(SEARCH(" ",$N10,((1+COUNTA($O10:Q10))+LEN(CONCATENATE($O10:Q10))))), MID($N10,((1+COUNTA($O10:Q10))+LEN(CONCATENATE($O10:Q10))),(((SEARCH(" ",$N10,((1+COUNTA($O10:Q10))+LEN(CONCATENATE($O10:Q10))))-1)-COUNTA($O10:Q10))-LEN(CONCATENATE($O10:Q10)))), RIGHT($N10,((((1+LEN($N10))-1)-COUNTA($O10:Q10))-LEN(CONCATENATE($O10:Q10)))))) | S10: =IF((LEN($N10)=((LEN(CONCATENATE($O10:R10))+COUNTA($O10:R10))-1)), "", IF( ISNUMBER(SEARCH(" ",$N10,((1+COUNTA($O10:R10))+LEN(CONCATENATE($O10:R10))))), MID($N10,((1+COUNTA($O10:R10))+LEN(CONCATENATE($O10:R10))),(((SEARCH(" ",$N10,((1+COUNTA($O10:R10))+LEN(CONCATENATE($O10:R10))))-1)-COUNTA($O10:R10))-LEN(CONCATENATE($O10:R10)))), RIGHT($N10,((((1+LEN($N10))-1)-COUNTA($O10:R10))-LEN(CONCATENATE($O10:R10))))))
A11: Wrist | B11: Primalstrike Bracers | D11: 15 | E11: 21 | H11: 64 | N11: primalstrike | O11: =IF(ISNUMBER(SEARCH(" ",$N11)),LEFT($N11,(SEARCH(" ",$N11)-1)),$N11) -> primalstrike | P11: =IF((LEN($N11)=((LEN(CONCATENATE($O11:O11))+COUNTA($O11:O11))-1)), "", IF( ISNUMBER(SEARCH(" ",$N11,((1+COUNTA($O11:O11))+LEN(CONCATENATE($O11:O11))))), MID($N11,((1+COUNTA($O11:O11))+LEN(CONCATENATE($O11:O11))),(((SEARCH(" ",$N11,((1+COUNTA($O11:O11))+LEN(CONCATENATE($O11:O11))))-1)-COUNTA($O11:O11))-LEN(CONCATENATE($O11:O11)))), RIGHT($N11,((((1+LEN($N11))-1)-COUNTA($O11:O11))-LEN(CONCATENATE($O11:O11)))))) | Q11: =IF((LEN($N11)=((LEN(CONCATENATE($O11:P11))+COUNTA($O11:P11))-1)), "", IF( ISNUMBER(SEARCH(" ",$N11,((1+COUNTA($O11:P11))+LEN(CONCATENATE($O11:P11))))), MID($N11,((1+COUNTA($O11:P11))+LEN(CONCATENATE($O11:P11))),(((SEARCH(" ",$N11,((1+COUNTA($O11:P11))+LEN(CONCATENATE($O11:P11))))-1)-COUNTA($O11:P11))-LEN(CONCATENATE($O11:P11)))), RIGHT($N11,((((1+LEN($N11))-1)-COUNTA($O11:P11))-LEN(CONCATENATE($O11:P11)))))) | R11: =IF((LEN($N11)=((LEN(CONCATENATE($O11:Q11))+COUNTA($O11:Q11))-1)), "", IF( ISNUMBER(SEARCH(" ",$N11,((1+COUNTA($O11:Q11))+LEN(CONCATENATE($O11:Q11))))), MID($N11,((1+COUNTA($O11:Q11))+LEN(CONCATENATE($O11:Q11))),(((SEARCH(" ",$N11,((1+COUNTA($O11:Q11))+LEN(CONCATENATE($O11:Q11))))-1)-COUNTA($O11:Q11))-LEN(CONCATENATE($O11:Q11)))), RIGHT($N11,((((1+LEN($N11))-1)-COUNTA($O11:Q11))-LEN(CONCATENATE($O11:Q11)))))) | S11: =IF((LEN($N11)=((LEN(CONCATENATE($O11:R11))+COUNTA($O11:R11))-1)), "", IF( ISNUMBER(SEARCH(" ",$N11,((1+COUNTA($O11:R11))+LEN(CONCATENATE($O11:R11))))), MID($N11,((1+COUNTA($O11:R11))+LEN(CONCATENATE($O11:R11))),(((SEARCH(" ",$N11,((1+COUNTA($O11:R11))+LEN(CONCATENATE($O11:R11))))-1)-COUNTA($O11:R11))-LEN(CONCATENATE($O11:R11)))), RIGHT($N11,((((1+LEN($N11))-1)-COUNTA($O11:R11))-LEN(CONCATENATE($O11:R11))))))
A12: Wrist Enchant | B12: Brawn | C12: 12 | O12: =IF(ISNUMBER(SEARCH(" ",$N12)),LEFT($N12,(SEARCH(" ",$N12)-1)),$N12) | P12: =IF((LEN($N12)=((LEN(CONCATENATE($O12:O12))+COUNTA($O12:O12))-1)), "", IF( ISNUMBER(SEARCH(" ",$N12,((1+COUNTA($O12:O12))+LEN(CONCATENATE($O12:O12))))), MID($N12,((1+COUNTA($O12:O12))+LEN(CONCATENATE($O12:O12))),(((SEARCH(" ",$N12,((1+COUNTA($O12:O12))+LEN(CONCATENATE($O12:O12))))-1)-COUNTA($O12:O12))-LEN(CONCATENATE($O12:O12)))), RIGHT($N12,((((1+LEN($N12))-1)-COUNTA($O12:O12))-LEN(CONCATENATE($O12:O12)))))) | Q12: =IF((LEN($N12)=((LEN(CONCATENATE($O12:P12))+COUNTA($O12:P12))-1)), "", IF( ISNUMBER(SEARCH(" ",$N12,((1+COUNTA($O12:P12))+LEN(CONCATENATE($O12:P12))))), MID($N12,((1+COUNTA($O12:P12))+LEN(CONCATENATE($O12:P12))),(((SEARCH(" ",$N12,((1+COUNTA($O12:P12))+LEN(CONCATENATE($O12:P12))))-1)-COUNTA($O12:P12))-LEN(CONCATENATE($O12:P12)))), RIGHT($N12,((((1+LEN($N12))-1)-COUNTA($O12:P12))-LEN(CONCATENATE($O12:P12)))))) | R12: =IF((LEN($N12)=((LEN(CONCATENATE($O12:Q12))+COUNTA($O12:Q12))-1)), "", IF( ISNUMBER(SEARCH(" ",$N12,((1+COUNTA($O12:Q12))+LEN(CONCATENATE($O12:Q12))))), MID($N12,((1+COUNTA($O12:Q12))+LEN(CONCATENATE($O12:Q12))),(((SEARCH(" ",$N12,((1+COUNTA($O12:Q12))+LEN(CONCATENATE($O12:Q12))))-1)-COUNTA($O12:Q12))-LEN(CONCATENATE($O12:Q12)))), RIGHT($N12,((((1+LEN($N12))-1)-COUNTA($O12:Q12))-LEN(CONCATENATE($O12:Q12)))))) | S12: =IF((LEN($N12)=((LEN(CONCATENATE($O12:R12))+COUNTA($O12:R12))-1)), "", IF( ISNUMBER(SEARCH(" ",$N12,((1+COUNTA($O12:R12))+LEN(CONCATENATE($O12:R12))))), MID($N12,((1+COUNTA($O12:R12))+LEN(CONCATENATE($O12:R12))),(((SEARCH(" ",$N12,((1+COUNTA($O12:R12))+LEN(CONCATENATE($O12:R12))))-1)-COUNTA($O12:R12))-LEN(CONCATENATE($O12:R12)))), RIGHT($N12,((((1+LEN($N12))-1)-COUNTA($O12:R12))-LEN(CONCATENATE($O12:R12))))))
A13: Hands | B13: Gloves of Dexterous Manipulation (8str, 4agi/6sta, +3crit) | D13: 43 | E13: 28 | H13: 42 | I13: 4 | J13: 3 | O13: =IF(ISNUMBER(SEARCH(" ",$N13)),LEFT($N13,(SEARCH(" ",$N13)-1)),$N13) | P13: =IF((LEN($N13)=((LEN(CONCATENATE($O13:O13))+COUNTA($O13:O13))-1)), "", IF( ISNUMBER(SEARCH(" ",$N13,((1+COUNTA($O13:O13))+LEN(CONCATENATE($O13:O13))))), MID($N13,((1+COUNTA($O13:O13))+LEN(CONCATENATE($O13:O13))),(((SEARCH(" ",$N13,((1+COUNTA($O13:O13))+LEN(CONCATENATE($O13:O13))))-1)-COUNTA($O13:O13))-LEN(CONCATENATE($O13:O13)))), RIGHT($N13,((((1+LEN($N13))-1)-COUNTA($O13:O13))-LEN(CONCATENATE($O13:O13)))))) | Q13: =IF((LEN($N13)=((LEN(CONCATENATE($O13:P13))+COUNTA($O13:P13))-1)), "", IF( ISNUMBER(SEARCH(" ",$N13,((1+COUNTA($O13:P13))+LEN(CONCATENATE($O13:P13))))), MID($N13,((1+COUNTA($O13:P13))+LEN(CONCATENATE($O13:P13))),(((SEARCH(" ",$N13,((1+COUNTA($O13:P13))+LEN(CONCATENATE($O13:P13))))-1)-COUNTA($O13:P13))-LEN(CONCATENATE($O13:P13)))), RIGHT($N13,((((1+LEN($N13))-1)-COUNTA($O13:P13))-LEN(CONCATENATE($O13:P13)))))) | R13: =IF((LEN($N13)=((LEN(CONCATENATE($O13:Q13))+COUNTA($O13:Q13))-1)), "", IF( ISNUMBER(SEARCH(" ",$N13,((1+COUNTA($O13:Q13))+LEN(CONCATENATE($O13:Q13))))), MID($N13,((1+COUNTA($O13:Q13))+LEN(CONCATENATE($O13:Q13))),(((SEARCH(" ",$N13,((1+COUNTA($O13:Q13))+LEN(CONCATENATE($O13:Q13))))-1)-COUNTA($O13:Q13))-LEN(CONCATENATE($O13:Q13)))), RIGHT($N13,((((1+LEN($N13))-1)-COUNTA($O13:Q13))-LEN(CONCATENATE($O13:Q13)))))) | S13: =IF((LEN($N13)=((LEN(CONCATENATE($O13:R13))+COUNTA($O13:R13))-1)), "", IF( ISNUMBER(SEARCH(" ",$N13,((1+COUNTA($O13:R13))+LEN(CONCATENATE($O13:R13))))), MID($N13,((1+COUNTA($O13:R13))+LEN(CONCATENATE($O13:R13))),(((SEARCH(" ",$N13,((1+COUNTA($O13:R13))+LEN(CONCATENATE($O13:R13))))-1)-COUNTA($O13:R13))-LEN(CONCATENATE($O13:R13)))), RIGHT($N13,((((1+LEN($N13))-1)-COUNTA($O13:R13))-LEN(CONCATENATE($O13:R13))))))
A14: Hands Enchant | B14: Superior Agility | D14: 15 | O14: =IF(ISNUMBER(SEARCH(" ",$N14)),LEFT($N14,(SEARCH(" ",$N14)-1)),$N14) | P14: =IF((LEN($N14)=((LEN(CONCATENATE($O14:O14))+COUNTA($O14:O14))-1)), "", IF( ISNUMBER(SEARCH(" ",$N14,((1+COUNTA($O14:O14))+LEN(CONCATENATE($O14:O14))))), MID($N14,((1+COUNTA($O14:O14))+LEN(CONCATENATE($O14:O14))),(((SEARCH(" ",$N14,((1+COUNTA($O14:O14))+LEN(CONCATENATE($O14:O14))))-1)-COUNTA($O14:O14))-LEN(CONCATENATE($O14:O14)))), RIGHT($N14,((((1+LEN($N14))-1)-COUNTA($O14:O14))-LEN(CONCATENATE($O14:O14)))))) | Q14: =IF((LEN($N14)=((LEN(CONCATENATE($O14:P14))+COUNTA($O14:P14))-1)), "", IF( ISNUMBER(SEARCH(" ",$N14,((1+COUNTA($O14:P14))+LEN(CONCATENATE($O14:P14))))), MID($N14,((1+COUNTA($O14:P14))+LEN(CONCATENATE($O14:P14))),(((SEARCH(" ",$N14,((1+COUNTA($O14:P14))+LEN(CONCATENATE($O14:P14))))-1)-COUNTA($O14:P14))-LEN(CONCATENATE($O14:P14)))), RIGHT($N14,((((1+LEN($N14))-1)-COUNTA($O14:P14))-LEN(CONCATENATE($O14:P14)))))) | R14: =IF((LEN($N14)=((LEN(CONCATENATE($O14:Q14))+COUNTA($O14:Q14))-1)), "", IF( ISNUMBER(SEARCH(" ",$N14,((1+COUNTA($O14:Q14))+LEN(CONCATENATE($O14:Q14))))), MID($N14,((1+COUNTA($O14:Q14))+LEN(CONCATENATE($O14:Q14))),(((SEARCH(" ",$N14,((1+COUNTA($O14:Q14))+LEN(CONCATENATE($O14:Q14))))-1)-COUNTA($O14:Q14))-LEN(CONCATENATE($O14:Q14)))), RIGHT($N14,((((1+LEN($N14))-1)-COUNTA($O14:Q14))-LEN(CONCATENATE($O14:Q14)))))) | S14: =IF((LEN($N14)=((LEN(CONCATENATE($O14:R14))+COUNTA($O14:R14))-1)), "", IF( ISNUMBER(SEARCH(" ",$N14,((1+COUNTA($O14:R14))+LEN(CONCATENATE($O14:R14))))), MID($N14,((1+COUNTA($O14:R14))+LEN(CONCATENATE($O14:R14))),(((SEARCH(" ",$N14,((1+COUNTA($O14:R14))+LEN(CONCATENATE($O14:R14))))-1)-COUNTA($O14:R14))-LEN(CONCATENATE($O14:R14)))), RIGHT($N14,((((1+LEN($N14))-1)-COUNTA($O14:R14))-LEN(CONCATENATE($O14:R14))))))
A15: Waist | B15: Primalstrike Belt | D15: 20 | E15: 32 | H15: 58 | I15: 84 | N15: primalstrike | O15: =IF(ISNUMBER(SEARCH(" ",$N15)),LEFT($N15,(SEARCH(" ",$N15)-1)),$N15) -> primalstrike | P15: =IF((LEN($N15)=((LEN(CONCATENATE($O15:O15))+COUNTA($O15:O15))-1)), "", IF( ISNUMBER(SEARCH(" ",$N15,((1+COUNTA($O15:O15))+LEN(CONCATENATE($O15:O15))))), MID($N15,((1+COUNTA($O15:O15))+LEN(CONCATENATE($O15:O15))),(((SEARCH(" ",$N15,((1+COUNTA($O15:O15))+LEN(CONCATENATE($O15:O15))))-1)-COUNTA($O15:O15))-LEN(CONCATENATE($O15:O15)))), RIGHT($N15,((((1+LEN($N15))-1)-COUNTA($O15:O15))-LEN(CONCATENATE($O15:O15)))))) | Q15: =IF((LEN($N15)=((LEN(CONCATENATE($O15:P15))+COUNTA($O15:P15))-1)), "", IF( ISNUMBER(SEARCH(" ",$N15,((1+COUNTA($O15:P15))+LEN(CONCATENATE($O15:P15))))), MID($N15,((1+COUNTA($O15:P15))+LEN(CONCATENATE($O15:P15))),(((SEARCH(" ",$N15,((1+COUNTA($O15:P15))+LEN(CONCATENATE($O15:P15))))-1)-COUNTA($O15:P15))-LEN(CONCATENATE($O15:P15)))), RIGHT($N15,((((1+LEN($N15))-1)-COUNTA($O15:P15))-LEN(CONCATENATE($O15:P15)))))) | R15: =IF((LEN($N15)=((LEN(CONCATENATE($O15:Q15))+COUNTA($O15:Q15))-1)), "", IF( ISNUMBER(SEARCH(" ",$N15,((1+COUNTA($O15:Q15))+LEN(CONCATENATE($O15:Q15))))), MID($N15,((1+COUNTA($O15:Q15))+LEN(CONCATENATE($O15:Q15))),(((SEARCH(" ",$N15,((1+COUNTA($O15:Q15))+LEN(CONCATENATE($O15:Q15))))-1)-COUNTA($O15:Q15))-LEN(CONCATENATE($O15:Q15)))), RIGHT($N15,((((1+LEN($N15))-1)-COUNTA($O15:Q15))-LEN(CONCATENATE($O15:Q15)))))) | S15: =IF((LEN($N15)=((LEN(CONCATENATE($O15:R15))+COUNTA($O15:R15))-1)), "", IF( ISNUMBER(SEARCH(" ",$N15,((1+COUNTA($O15:R15))+LEN(CONCATENATE($O15:R15))))), MID($N15,((1+COUNTA($O15:R15))+LEN(CONCATENATE($O15:R15))),(((SEARCH(" ",$N15,((1+COUNTA($O15:R15))+LEN(CONCATENATE($O15:R15))))-1)-COUNTA($O15:R15))-LEN(CONCATENATE($O15:R15)))), RIGHT($N15,((((1+LEN($N15))-1)-COUNTA($O15:R15))-LEN(CONCATENATE($O15:R15))))))
A16: Legs | B16: Clefthoof Hide Leggings | C16: 30 | D16: 30 | E16: 24 | I16: 17 | K16: 18 | O16: =IF(ISNUMBER(SEARCH(" ",$N16)),LEFT($N16,(SEARCH(" ",$N16)-1)),$N16) | P16: =IF((LEN($N16)=((LEN(CONCATENATE($O16:O16))+COUNTA($O16:O16))-1)), "", IF( ISNUMBER(SEARCH(" ",$N16,((1+COUNTA($O16:O16))+LEN(CONCATENATE($O16:O16))))), MID($N16,((1+COUNTA($O16:O16))+LEN(CONCATENATE($O16:O16))),(((SEARCH(" ",$N16,((1+COUNTA($O16:O16))+LEN(CONCATENATE($O16:O16))))-1)-COUNTA($O16:O16))-LEN(CONCATENATE($O16:O16)))), RIGHT($N16,((((1+LEN($N16))-1)-COUNTA($O16:O16))-LEN(CONCATENATE($O16:O16)))))) | Q16: =IF((LEN($N16)=((LEN(CONCATENATE($O16:P16))+COUNTA($O16:P16))-1)), "", IF( ISNUMBER(SEARCH(" ",$N16,((1+COUNTA($O16:P16))+LEN(CONCATENATE($O16:P16))))), MID($N16,((1+COUNTA($O16:P16))+LEN(CONCATENATE($O16:P16))),(((SEARCH(" ",$N16,((1+COUNTA($O16:P16))+LEN(CONCATENATE($O16:P16))))-1)-COUNTA($O16:P16))-LEN(CONCATENATE($O16:P16)))), RIGHT($N16,((((1+LEN($N16))-1)-COUNTA($O16:P16))-LEN(CONCATENATE($O16:P16)))))) | R16: =IF((LEN($N16)=((LEN(CONCATENATE($O16:Q16))+COUNTA($O16:Q16))-1)), "", IF( ISNUMBER(SEARCH(" ",$N16,((1+COUNTA($O16:Q16))+LEN(CONCATENATE($O16:Q16))))), MID($N16,((1+COUNTA($O16:Q16))+LEN(CONCATENATE($O16:Q16))),(((SEARCH(" ",$N16,((1+COUNTA($O16:Q16))+LEN(CONCATENATE($O16:Q16))))-1)-COUNTA($O16:Q16))-LEN(CONCATENATE($O16:Q16)))), RIGHT($N16,((((1+LEN($N16))-1)-COUNTA($O16:Q16))-LEN(CONCATENATE($O16:Q16)))))) | S16: =IF((LEN($N16)=((LEN(CONCATENATE($O16:R16))+COUNTA($O16:R16))-1)), "", IF( ISNUMBER(SEARCH(" ",$N16,((1+COUNTA($O16:R16))+LEN(CONCATENATE($O16:R16))))), MID($N16,((1+COUNTA($O16:R16))+LEN(CONCATENATE($O16:R16))),(((SEARCH(" ",$N16,((1+COUNTA($O16:R16))+LEN(CONCATENATE($O16:R16))))-1)-COUNTA($O16:R16))-LEN(CONCATENATE($O16:R16)))), RIGHT($N16,((((1+LEN($N16))-1)-COUNTA($O16:R16))-LEN(CONCATENATE($O16:R16))))))
A17: Legs Enchant | B17: Cobrahide Armor Kit | H17: 40 | J17: 10 | O17: =IF(ISNUMBER(SEARCH(" ",$N17)),LEFT($N17,(SEARCH(" ",$N17)-1)),$N17) | P17: =IF((LEN($N17)=((LEN(CONCATENATE($O17:O17))+COUNTA($O17:O17))-1)), "", IF( ISNUMBER(SEARCH(" ",$N17,((1+COUNTA($O17:O17))+LEN(CONCATENATE($O17:O17))))), MID($N17,((1+COUNTA($O17:O17))+LEN(CONCATENATE($O17:O17))),(((SEARCH(" ",$N17,((1+COUNTA($O17:O17))+LEN(CONCATENATE($O17:O17))))-1)-COUNTA($O17:O17))-LEN(CONCATENATE($O17:O17)))), RIGHT($N17,((((1+LEN($N17))-1)-COUNTA($O17:O17))-LEN(CONCATENATE($O17:O17)))))) | Q17: =IF((LEN($N17)=((LEN(CONCATENATE($O17:P17))+COUNTA($O17:P17))-1)), "", IF( ISNUMBER(SEARCH(" ",$N17,((1+COUNTA($O17:P17))+LEN(CONCATENATE($O17:P17))))), MID($N17,((1+COUNTA($O17:P17))+LEN(CONCATENATE($O17:P17))),(((SEARCH(" ",$N17,((1+COUNTA($O17:P17))+LEN(CONCATENATE($O17:P17))))-1)-COUNTA($O17:P17))-LEN(CONCATENATE($O17:P17)))), RIGHT($N17,((((1+LEN($N17))-1)-COUNTA($O17:P17))-LEN(CONCATENATE($O17:P17)))))) | R17: =IF((LEN($N17)=((LEN(CONCATENATE($O17:Q17))+COUNTA($O17:Q17))-1)), "", IF( ISNUMBER(SEARCH(" ",$N17,((1+COUNTA($O17:Q17))+LEN(CONCATENATE($O17:Q17))))), MID($N17,((1+COUNTA($O17:Q17))+LEN(CONCATENATE($O17:Q17))),(((SEARCH(" ",$N17,((1+COUNTA($O17:Q17))+LEN(CONCATENATE($O17:Q17))))-1)-COUNTA($O17:Q17))-LEN(CONCATENATE($O17:Q17)))), RIGHT($N17,((((1+LEN($N17))-1)-COUNTA($O17:Q17))-LEN(CONCATENATE($O17:Q17)))))) | S17: =IF((LEN($N17)=((LEN(CONCATENATE($O17:R17))+COUNTA($O17:R17))-1)), "", IF( ISNUMBER(SEARCH(" ",$N17,((1+COUNTA($O17:R17))+LEN(CONCATENATE($O17:R17))))), MID($N17,((1+COUNTA($O17:R17))+LEN(CONCATENATE($O17:R17))),(((SEARCH(" ",$N17,((1+COUNTA($O17:R17))+LEN(CONCATENATE($O17:R17))))-1)-COUNTA($O17:R17))-LEN(CONCATENATE($O17:R17)))), RIGHT($N17,((((1+LEN($N17))-1)-COUNTA($O17:R17))-LEN(CONCATENATE($O17:R17))))))
A18: Feet | B18: Boots of Natural Grace | C18: 33 | D18: 26 | E18: 37 | F18: 13 | I18: 14 | O18: =IF(ISNUMBER(SEARCH(" ",$N18)),LEFT($N18,(SEARCH(" ",$N18)-1)),$N18) | P18: =IF((LEN($N18)=((LEN(CONCATENATE($O18:O18))+COUNTA($O18:O18))-1)), "", IF( ISNUMBER(SEARCH(" ",$N18,((1+COUNTA($O18:O18))+LEN(CONCATENATE($O18:O18))))), MID($N18,((1+COUNTA($O18:O18))+LEN(CONCATENATE($O18:O18))),(((SEARCH(" ",$N18,((1+COUNTA($O18:O18))+LEN(CONCATENATE($O18:O18))))-1)-COUNTA($O18:O18))-LEN(CONCATENATE($O18:O18)))), RIGHT($N18,((((1+LEN($N18))-1)-COUNTA($O18:O18))-LEN(CONCATENATE($O18:O18)))))) | Q18: =IF((LEN($N18)=((LEN(CONCATENATE($O18:P18))+COUNTA($O18:P18))-1)), "", IF( ISNUMBER(SEARCH(" ",$N18,((1+COUNTA($O18:P18))+LEN(CONCATENATE($O18:P18))))), MID($N18,((1+COUNTA($O18:P18))+LEN(CONCATENATE($O18:P18))),(((SEARCH(" ",$N18,((1+COUNTA($O18:P18))+LEN(CONCATENATE($O18:P18))))-1)-COUNTA($O18:P18))-LEN(CONCATENATE($O18:P18)))), RIGHT($N18,((((1+LEN($N18))-1)-COUNTA($O18:P18))-LEN(CONCATENATE($O18:P18)))))) | R18: =IF((LEN($N18)=((LEN(CONCATENATE($O18:Q18))+COUNTA($O18:Q18))-1)), "", IF( ISNUMBER(SEARCH(" ",$N18,((1+COUNTA($O18:Q18))+LEN(CONCATENATE($O18:Q18))))), MID($N18,((1+COUNTA($O18:Q18))+LEN(CONCATENATE($O18:Q18))),(((SEARCH(" ",$N18,((1+COUNTA($O18:Q18))+LEN(CONCATENATE($O18:Q18))))-1)-COUNTA($O18:Q18))-LEN(CONCATENATE($O18:Q18)))), RIGHT($N18,((((1+LEN($N18))-1)-COUNTA($O18:Q18))-LEN(CONCATENATE($O18:Q18)))))) | S18: =IF((LEN($N18)=((LEN(CONCATENATE($O18:R18))+COUNTA($O18:R18))-1)), "", IF( ISNUMBER(SEARCH(" ",$N18,((1+COUNTA($O18:R18))+LEN(CONCATENATE($O18:R18))))), MID($N18,((1+COUNTA($O18:R18))+LEN(CONCATENATE($O18:R18))),(((SEARCH(" ",$N18,((1+COUNTA($O18:R18))+LEN(CONCATENATE($O18:R18))))-1)-COUNTA($O18:R18))-LEN(CONCATENATE($O18:R18)))), RIGHT($N18,((((1+LEN($N18))-1)-COUNTA($O18:R18))-LEN(CONCATENATE($O18:R18))))))
A19: Feet Enchant | B19: Dexterity | D19: 12 | O19: =IF(ISNUMBER(SEARCH(" ",$N19)),LEFT($N19,(SEARCH(" ",$N19)-1)),$N19) | P19: =IF((LEN($N19)=((LEN(CONCATENATE($O19:O19))+COUNTA($O19:O19))-1)), "", IF( ISNUMBER(SEARCH(" ",$N19,((1+COUNTA($O19:O19))+LEN(CONCATENATE($O19:O19))))), MID($N19,((1+COUNTA($O19:O19))+LEN(CONCATENATE($O19:O19))),(((SEARCH(" ",$N19,((1+COUNTA($O19:O19))+LEN(CONCATENATE($O19:O19))))-1)-COUNTA($O19:O19))-LEN(CONCATENATE($O19:O19)))), RIGHT($N19,((((1+LEN($N19))-1)-COUNTA($O19:O19))-LEN(CONCATENATE($O19:O19)))))) | Q19: =IF((LEN($N19)=((LEN(CONCATENATE($O19:P19))+COUNTA($O19:P19))-1)), "", IF( ISNUMBER(SEARCH(" ",$N19,((1+COUNTA($O19:P19))+LEN(CONCATENATE($O19:P19))))), MID($N19,((1+COUNTA($O19:P19))+LEN(CONCATENATE($O19:P19))),(((SEARCH(" ",$N19,((1+COUNTA($O19:P19))+LEN(CONCATENATE($O19:P19))))-1)-COUNTA($O19:P19))-LEN(CONCATENATE($O19:P19)))), RIGHT($N19,((((1+LEN($N19))-1)-COUNTA($O19:P19))-LEN(CONCATENATE($O19:P19)))))) | R19: =IF((LEN($N19)=((LEN(CONCATENATE($O19:Q19))+COUNTA($O19:Q19))-1)), "", IF( ISNUMBER(SEARCH(" ",$N19,((1+COUNTA($O19:Q19))+LEN(CONCATENATE($O19:Q19))))), MID($N19,((1+COUNTA($O19:Q19))+LEN(CONCATENATE($O19:Q19))),(((SEARCH(" ",$N19,((1+COUNTA($O19:Q19))+LEN(CONCATENATE($O19:Q19))))-1)-COUNTA($O19:Q19))-LEN(CONCATENATE($O19:Q19)))), RIGHT($N19,((((1+LEN($N19))-1)-COUNTA($O19:Q19))-LEN(CONCATENATE($O19:Q19)))))) | S19: =IF((LEN($N19)=((LEN(CONCATENATE($O19:R19))+COUNTA($O19:R19))-1)), "", IF( ISNUMBER(SEARCH(" ",$N19,((1+COUNTA($O19:R19))+LEN(CONCATENATE($O19:R19))))), MID($N19,((1+COUNTA($O19:R19))+LEN(CONCATENATE($O19:R19))),(((SEARCH(" ",$N19,((1+COUNTA($O19:R19))+LEN(CONCATENATE($O19:R19))))-1)-COUNTA($O19:R19))-LEN(CONCATENATE($O19:R19)))), RIGHT($N19,((((1+LEN($N19))-1)-COUNTA($O19:R19))-LEN(CONCATENATE($O19:R19))))))
A20: Ring 1 | B20: Adal's Command | C20: 29 | D20: 16 | E20: 18 | O20: =IF(ISNUMBER(SEARCH(" ",$N20)),LEFT($N20,(SEARCH(" ",$N20)-1)),$N20) | P20: =IF((LEN($N20)=((LEN(CONCATENATE($O20:O20))+COUNTA($O20:O20))-1)), "", IF( ISNUMBER(SEARCH(" ",$N20,((1+COUNTA($O20:O20))+LEN(CONCATENATE($O20:O20))))), MID($N20,((1+COUNTA($O20:O20))+LEN(CONCATENATE($O20:O20))),(((SEARCH(" ",$N20,((1+COUNTA($O20:O20))+LEN(CONCATENATE($O20:O20))))-1)-COUNTA($O20:O20))-LEN(CONCATENATE($O20:O20)))), RIGHT($N20,((((1+LEN($N20))-1)-COUNTA($O20:O20))-LEN(CONCATENATE($O20:O20)))))) | Q20: =IF((LEN($N20)=((LEN(CONCATENATE($O20:P20))+COUNTA($O20:P20))-1)), "", IF( ISNUMBER(SEARCH(" ",$N20,((1+COUNTA($O20:P20))+LEN(CONCATENATE($O20:P20))))), MID($N20,((1+COUNTA($O20:P20))+LEN(CONCATENATE($O20:P20))),(((SEARCH(" ",$N20,((1+COUNTA($O20:P20))+LEN(CONCATENATE($O20:P20))))-1)-COUNTA($O20:P20))-LEN(CONCATENATE($O20:P20)))), RIGHT($N20,((((1+LEN($N20))-1)-COUNTA($O20:P20))-LEN(CONCATENATE($O20:P20)))))) | R20: =IF((LEN($N20)=((LEN(CONCATENATE($O20:Q20))+COUNTA($O20:Q20))-1)), "", IF( ISNUMBER(SEARCH(" ",$N20,((1+COUNTA($O20:Q20))+LEN(CONCATENATE($O20:Q20))))), MID($N20,((1+COUNTA($O20:Q20))+LEN(CONCATENATE($O20:Q20))),(((SEARCH(" ",$N20,((1+COUNTA($O20:Q20))+LEN(CONCATENATE($O20:Q20))))-1)-COUNTA($O20:Q20))-LEN(CONCATENATE($O20:Q20)))), RIGHT($N20,((((1+LEN($N20))-1)-COUNTA($O20:Q20))-LEN(CONCATENATE($O20:Q20)))))) | S20: =IF((LEN($N20)=((LEN(CONCATENATE($O20:R20))+COUNTA($O20:R20))-1)), "", IF( ISNUMBER(SEARCH(" ",$N20,((1+COUNTA($O20:R20))+LEN(CONCATENATE($O20:R20))))), MID($N20,((1+COUNTA($O20:R20))+LEN(CONCATENATE($O20:R20))),(((SEARCH(" ",$N20,((1+COUNTA($O20:R20))+LEN(CONCATENATE($O20:R20))))-1)-COUNTA($O20:R20))-LEN(CONCATENATE($O20:R20)))), RIGHT($N20,((((1+LEN($N20))-1)-COUNTA($O20:R20))-LEN(CONCATENATE($O20:R20))))))
A21: Ring 1 Enchant | O21: =IF(ISNUMBER(SEARCH(" ",$N21)),LEFT($N21,(SEARCH(" ",$N21)-1)),$N21) | P21: =IF((LEN($N21)=((LEN(CONCATENATE($O21:O21))+COUNTA($O21:O21))-1)), "", IF( ISNUMBER(SEARCH(" ",$N21,((1+COUNTA($O21:O21))+LEN(CONCATENATE($O21:O21))))), MID($N21,((1+COUNTA($O21:O21))+LEN(CONCATENATE($O21:O21))),(((SEARCH(" ",$N21,((1+COUNTA($O21:O21))+LEN(CONCATENATE($O21:O21))))-1)-COUNTA($O21:O21))-LEN(CONCATENATE($O21:O21)))), RIGHT($N21,((((1+LEN($N21))-1)-COUNTA($O21:O21))-LEN(CONCATENATE($O21:O21)))))) | Q21: =IF((LEN($N21)=((LEN(CONCATENATE($O21:P21))+COUNTA($O21:P21))-1)), "", IF( ISNUMBER(SEARCH(" ",$N21,((1+COUNTA($O21:P21))+LEN(CONCATENATE($O21:P21))))), MID($N21,((1+COUNTA($O21:P21))+LEN(CONCATENATE($O21:P21))),(((SEARCH(" ",$N21,((1+COUNTA($O21:P21))+LEN(CONCATENATE($O21:P21))))-1)-COUNTA($O21:P21))-LEN(CONCATENATE($O21:P21)))), RIGHT($N21,((((1+LEN($N21))-1)-COUNTA($O21:P21))-LEN(CONCATENATE($O21:P21)))))) | R21: =IF((LEN($N21)=((LEN(CONCATENATE($O21:Q21))+COUNTA($O21:Q21))-1)), "", IF( ISNUMBER(SEARCH(" ",$N21,((1+COUNTA($O21:Q21))+LEN(CONCATENATE($O21:Q21))))), MID($N21,((1+COUNTA($O21:Q21))+LEN(CONCATENATE($O21:Q21))),(((SEARCH(" ",$N21,((1+COUNTA($O21:Q21))+LEN(CONCATENATE($O21:Q21))))-1)-COUNTA($O21:Q21))-LEN(CONCATENATE($O21:Q21)))), RIGHT($N21,((((1+LEN($N21))-1)-COUNTA($O21:Q21))-LEN(CONCATENATE($O21:Q21)))))) | S21: =IF((LEN($N21)=((LEN(CONCATENATE($O21:R21))+COUNTA($O21:R21))-1)), "", IF( ISNUMBER(SEARCH(" ",$N21,((1+COUNTA($O21:R21))+LEN(CONCATENATE($O21:R21))))), MID($N21,((1+COUNTA($O21:R21))+LEN(CONCATENATE($O21:R21))),(((SEARCH(" ",$N21,((1+COUNTA($O21:R21))+LEN(CONCATENATE($O21:R21))))-1)-COUNTA($O21:R21))-LEN(CONCATENATE($O21:R21)))), RIGHT($N21,((((1+LEN($N21))-1)-COUNTA($O21:R21))-LEN(CONCATENATE($O21:R21))))))
A22: Ring 2 | B22: Ancestral Ring of Conquest | C22: 32 | D22: 21 | E22: 30 | O22: =IF(ISNUMBER(SEARCH(" ",$N22)),LEFT($N22,(SEARCH(" ",$N22)-1)),$N22) | P22: =IF((LEN($N22)=((LEN(CONCATENATE($O22:O22))+COUNTA($O22:O22))-1)), "", IF( ISNUMBER(SEARCH(" ",$N22,((1+COUNTA($O22:O22))+LEN(CONCATENATE($O22:O22))))), MID($N22,((1+COUNTA($O22:O22))+LEN(CONCATENATE($O22:O22))),(((SEARCH(" ",$N22,((1+COUNTA($O22:O22))+LEN(CONCATENATE($O22:O22))))-1)-COUNTA($O22:O22))-LEN(CONCATENATE($O22:O22)))), RIGHT($N22,((((1+LEN($N22))-1)-COUNTA($O22:O22))-LEN(CONCATENATE($O22:O22)))))) | Q22: =IF((LEN($N22)=((LEN(CONCATENATE($O22:P22))+COUNTA($O22:P22))-1)), "", IF( ISNUMBER(SEARCH(" ",$N22,((1+COUNTA($O22:P22))+LEN(CONCATENATE($O22:P22))))), MID($N22,((1+COUNTA($O22:P22))+LEN(CONCATENATE($O22:P22))),(((SEARCH(" ",$N22,((1+COUNTA($O22:P22))+LEN(CONCATENATE($O22:P22))))-1)-COUNTA($O22:P22))-LEN(CONCATENATE($O22:P22)))), RIGHT($N22,((((1+LEN($N22))-1)-COUNTA($O22:P22))-LEN(CONCATENATE($O22:P22)))))) | R22: =IF((LEN($N22)=((LEN(CONCATENATE($O22:Q22))+COUNTA($O22:Q22))-1)), "", IF( ISNUMBER(SEARCH(" ",$N22,((1+COUNTA($O22:Q22))+LEN(CONCATENATE($O22:Q22))))), MID($N22,((1+COUNTA($O22:Q22))+LEN(CONCATENATE($O22:Q22))),(((SEARCH(" ",$N22,((1+COUNTA($O22:Q22))+LEN(CONCATENATE($O22:Q22))))-1)-COUNTA($O22:Q22))-LEN(CONCATENATE($O22:Q22)))), RIGHT($N22,((((1+LEN($N22))-1)-COUNTA($O22:Q22))-LEN(CONCATENATE($O22:Q22)))))) | S22: =IF((LEN($N22)=((LEN(CONCATENATE($O22:R22))+COUNTA($O22:R22))-1)), "", IF( ISNUMBER(SEARCH(" ",$N22,((1+COUNTA($O22:R22))+LEN(CONCATENATE($O22:R22))))), MID($N22,((1+COUNTA($O22:R22))+LEN(CONCATENATE($O22:R22))),(((SEARCH(" ",$N22,((1+COUNTA($O22:R22))+LEN(CONCATENATE($O22:R22))))-1)-COUNTA($O22:R22))-LEN(CONCATENATE($O22:R22)))), RIGHT($N22,((((1+LEN($N22))-1)-COUNTA($O22:R22))-LEN(CONCATENATE($O22:R22))))))
A23: Ring 2 Enchant | O23: =IF(ISNUMBER(SEARCH(" ",$N23)),LEFT($N23,(SEARCH(" ",$N23)-1)),$N23) | P23: =IF((LEN($N23)=((LEN(CONCATENATE($O23:O23))+COUNTA($O23:O23))-1)), "", IF( ISNUMBER(SEARCH(" ",$N23,((1+COUNTA($O23:O23))+LEN(CONCATENATE($O23:O23))))), MID($N23,((1+COUNTA($O23:O23))+LEN(CONCATENATE($O23:O23))),(((SEARCH(" ",$N23,((1+COUNTA($O23:O23))+LEN(CONCATENATE($O23:O23))))-1)-COUNTA($O23:O23))-LEN(CONCATENATE($O23:O23)))), RIGHT($N23,((((1+LEN($N23))-1)-COUNTA($O23:O23))-LEN(CONCATENATE($O23:O23)))))) | Q23: =IF((LEN($N23)=((LEN(CONCATENATE($O23:P23))+COUNTA($O23:P23))-1)), "", IF( ISNUMBER(SEARCH(" ",$N23,((1+COUNTA($O23:P23))+LEN(CONCATENATE($O23:P23))))), MID($N23,((1+COUNTA($O23:P23))+LEN(CONCATENATE($O23:P23))),(((SEARCH(" ",$N23,((1+COUNTA($O23:P23))+LEN(CONCATENATE($O23:P23))))-1)-COUNTA($O23:P23))-LEN(CONCATENATE($O23:P23)))), RIGHT($N23,((((1+LEN($N23))-1)-COUNTA($O23:P23))-LEN(CONCATENATE($O23:P23)))))) | R23: =IF((LEN($N23)=((LEN(CONCATENATE($O23:Q23))+COUNTA($O23:Q23))-1)), "", IF( ISNUMBER(SEARCH(" ",$N23,((1+COUNTA($O23:Q23))+LEN(CONCATENATE($O23:Q23))))), MID($N23,((1+COUNTA($O23:Q23))+LEN(CONCATENATE($O23:Q23))),(((SEARCH(" ",$N23,((1+COUNTA($O23:Q23))+LEN(CONCATENATE($O23:Q23))))-1)-COUNTA($O23:Q23))-LEN(CONCATENATE($O23:Q23)))), RIGHT($N23,((((1+LEN($N23))-1)-COUNTA($O23:Q23))-LEN(CONCATENATE($O23:Q23)))))) | S23: =IF((LEN($N23)=((LEN(CONCATENATE($O23:R23))+COUNTA($O23:R23))-1)), "", IF( ISNUMBER(SEARCH(" ",$N23,((1+COUNTA($O23:R23))+LEN(CONCATENATE($O23:R23))))), MID($N23,((1+COUNTA($O23:R23))+LEN(CONCATENATE($O23:R23))),(((SEARCH(" ",$N23,((1+COUNTA($O23:R23))+LEN(CONCATENATE($O23:R23))))-1)-COUNTA($O23:R23))-LEN(CONCATENATE($O23:R23)))), RIGHT($N23,((((1+LEN($N23))-1)-COUNTA($O23:R23))-LEN(CONCATENATE($O23:R23))))))
A24: Trinket 1 | B24: Crystalforged Trinket | H24: 36 | M24: 7 | O24: =IF(ISNUMBER(SEARCH(" ",$N24)),LEFT($N24,(SEARCH(" ",$N24)-1)),$N24) | P24: =IF((LEN($N24)=((LEN(CONCATENATE($O24:O24))+COUNTA($O24:O24))-1)), "", IF( ISNUMBER(SEARCH(" ",$N24,((1+COUNTA($O24:O24))+LEN(CONCATENATE($O24:O24))))), MID($N24,((1+COUNTA($O24:O24))+LEN(CONCATENATE($O24:O24))),(((SEARCH(" ",$N24,((1+COUNTA($O24:O24))+LEN(CONCATENATE($O24:O24))))-1)-COUNTA($O24:O24))-LEN(CONCATENATE($O24:O24)))), RIGHT($N24,((((1+LEN($N24))-1)-COUNTA($O24:O24))-LEN(CONCATENATE($O24:O24)))))) | Q24: =IF((LEN($N24)=((LEN(CONCATENATE($O24:P24))+COUNTA($O24:P24))-1)), "", IF( ISNUMBER(SEARCH(" ",$N24,((1+COUNTA($O24:P24))+LEN(CONCATENATE($O24:P24))))), MID($N24,((1+COUNTA($O24:P24))+LEN(CONCATENATE($O24:P24))),(((SEARCH(" ",$N24,((1+COUNTA($O24:P24))+LEN(CONCATENATE($O24:P24))))-1)-COUNTA($O24:P24))-LEN(CONCATENATE($O24:P24)))), RIGHT($N24,((((1+LEN($N24))-1)-COUNTA($O24:P24))-LEN(CONCATENATE($O24:P24)))))) | R24: =IF((LEN($N24)=((LEN(CONCATENATE($O24:Q24))+COUNTA($O24:Q24))-1)), "", IF( ISNUMBER(SEARCH(" ",$N24,((1+COUNTA($O24:Q24))+LEN(CONCATENATE($O24:Q24))))), MID($N24,((1+COUNTA($O24:Q24))+LEN(CONCATENATE($O24:Q24))),(((SEARCH(" ",$N24,((1+COUNTA($O24:Q24))+LEN(CONCATENATE($O24:Q24))))-1)-COUNTA($O24:Q24))-LEN(CONCATENATE($O24:Q24)))), RIGHT($N24,((((1+LEN($N24))-1)-COUNTA($O24:Q24))-LEN(CONCATENATE($O24:Q24)))))) | S24: =IF((LEN($N24)=((LEN(CONCATENATE($O24:R24))+COUNTA($O24:R24))-1)), "", IF( ISNUMBER(SEARCH(" ",$N24,((1+COUNTA($O24:R24))+LEN(CONCATENATE($O24:R24))))), MID($N24,((1+COUNTA($O24:R24))+LEN(CONCATENATE($O24:R24))),(((SEARCH(" ",$N24,((1+COUNTA($O24:R24))+LEN(CONCATENATE($O24:R24))))-1)-COUNTA($O24:R24))-LEN(CONCATENATE($O24:R24)))), RIGHT($N24,((((1+LEN($N24))-1)-COUNTA($O24:R24))-LEN(CONCATENATE($O24:R24))))))
A25: Trinket 2 | B25: Bloodlust Brooch | H25: =72+(278/6) -> 118.33333 | O25: =IF(ISNUMBER(SEARCH(" ",$N25)),LEFT($N25,(SEARCH(" ",$N25)-1)),$N25) | P25: =IF((LEN($N25)=((LEN(CONCATENATE($O25:O25))+COUNTA($O25:O25))-1)), "", IF( ISNUMBER(SEARCH(" ",$N25,((1+COUNTA($O25:O25))+LEN(CONCATENATE($O25:O25))))), MID($N25,((1+COUNTA($O25:O25))+LEN(CONCATENATE($O25:O25))),(((SEARCH(" ",$N25,((1+COUNTA($O25:O25))+LEN(CONCATENATE($O25:O25))))-1)-COUNTA($O25:O25))-LEN(CONCATENATE($O25:O25)))), RIGHT($N25,((((1+LEN($N25))-1)-COUNTA($O25:O25))-LEN(CONCATENATE($O25:O25)))))) | Q25: =IF((LEN($N25)=((LEN(CONCATENATE($O25:P25))+COUNTA($O25:P25))-1)), "", IF( ISNUMBER(SEARCH(" ",$N25,((1+COUNTA($O25:P25))+LEN(CONCATENATE($O25:P25))))), MID($N25,((1+COUNTA($O25:P25))+LEN(CONCATENATE($O25:P25))),(((SEARCH(" ",$N25,((1+COUNTA($O25:P25))+LEN(CONCATENATE($O25:P25))))-1)-COUNTA($O25:P25))-LEN(CONCATENATE($O25:P25)))), RIGHT($N25,((((1+LEN($N25))-1)-COUNTA($O25:P25))-LEN(CONCATENATE($O25:P25)))))) | R25: =IF((LEN($N25)=((LEN(CONCATENATE($O25:Q25))+COUNTA($O25:Q25))-1)), "", IF( ISNUMBER(SEARCH(" ",$N25,((1+COUNTA($O25:Q25))+LEN(CONCATENATE($O25:Q25))))), MID($N25,((1+COUNTA($O25:Q25))+LEN(CONCATENATE($O25:Q25))),(((SEARCH(" ",$N25,((1+COUNTA($O25:Q25))+LEN(CONCATENATE($O25:Q25))))-1)-COUNTA($O25:Q25))-LEN(CONCATENATE($O25:Q25)))), RIGHT($N25,((((1+LEN($N25))-1)-COUNTA($O25:Q25))-LEN(CONCATENATE($O25:Q25)))))) | S25: =IF((LEN($N25)=((LEN(CONCATENATE($O25:R25))+COUNTA($O25:R25))-1)), "", IF( ISNUMBER(SEARCH(" ",$N25,((1+COUNTA($O25:R25))+LEN(CONCATENATE($O25:R25))))), MID($N25,((1+COUNTA($O25:R25))+LEN(CONCATENATE($O25:R25))),(((SEARCH(" ",$N25,((1+COUNTA($O25:R25))+LEN(CONCATENATE($O25:R25))))-1)-COUNTA($O25:R25))-LEN(CONCATENATE($O25:R25)))), RIGHT($N25,((((1+LEN($N25))-1)-COUNTA($O25:R25))-LEN(CONCATENATE($O25:R25))))))
A26: Main Hand | B26: Merciless Gladiator's Maul | C26: 42 | E26: 55 | H26: 788 | I26: 18 | J26: 42 | O26: =IF(ISNUMBER(SEARCH(" ",$N26)),LEFT($N26,(SEARCH(" ",$N26)-1)),$N26) | P26: =IF((LEN($N26)=((LEN(CONCATENATE($O26:O26))+COUNTA($O26:O26))-1)), "", IF( ISNUMBER(SEARCH(" ",$N26,((1+COUNTA($O26:O26))+LEN(CONCATENATE($O26:O26))))), MID($N26,((1+COUNTA($O26:O26))+LEN(CONCATENATE($O26:O26))),(((SEARCH(" ",$N26,((1+COUNTA($O26:O26))+LEN(CONCATENATE($O26:O26))))-1)-COUNTA($O26:O26))-LEN(CONCATENATE($O26:O26)))), RIGHT($N26,((((1+LEN($N26))-1)-COUNTA($O26:O26))-LEN(CONCATENATE($O26:O26)))))) | Q26: =IF((LEN($N26)=((LEN(CONCATENATE($O26:P26))+COUNTA($O26:P26))-1)), "", IF( ISNUMBER(SEARCH(" ",$N26,((1+COUNTA($O26:P26))+LEN(CONCATENATE($O26:P26))))), MID($N26,((1+COUNTA($O26:P26))+LEN(CONCATENATE($O26:P26))),(((SEARCH(" ",$N26,((1+COUNTA($O26:P26))+LEN(CONCATENATE($O26:P26))))-1)-COUNTA($O26:P26))-LEN(CONCATENATE($O26:P26)))), RIGHT($N26,((((1+LEN($N26))-1)-COUNTA($O26:P26))-LEN(CONCATENATE($O26:P26)))))) | R26: =IF((LEN($N26)=((LEN(CONCATENATE($O26:Q26))+COUNTA($O26:Q26))-1)), "", IF( ISNUMBER(SEARCH(" ",$N26,((1+COUNTA($O26:Q26))+LEN(CONCATENATE($O26:Q26))))), MID($N26,((1+COUNTA($O26:Q26))+LEN(CONCATENATE($O26:Q26))),(((SEARCH(" ",$N26,((1+COUNTA($O26:Q26))+LEN(CONCATENATE($O26:Q26))))-1)-COUNTA($O26:Q26))-LEN(CONCATENATE($O26:Q26)))), RIGHT($N26,((((1+LEN($N26))-1)-COUNTA($O26:Q26))-LEN(CONCATENATE($O26:Q26)))))) | S26: =IF((LEN($N26)=((LEN(CONCATENATE($O26:R26))+COUNTA($O26:R26))-1)), "", IF( ISNUMBER(SEARCH(" ",$N26,((1+COUNTA($O26:R26))+LEN(CONCATENATE($O26:R26))))), MID($N26,((1+COUNTA($O26:R26))+LEN(CONCATENATE($O26:R26))),(((SEARCH(" ",$N26,((1+COUNTA($O26:R26))+LEN(CONCATENATE($O26:R26))))-1)-COUNTA($O26:R26))-LEN(CONCATENATE($O26:R26)))), RIGHT($N26,((((1+LEN($N26))-1)-COUNTA($O26:R26))-LEN(CONCATENATE($O26:R26))))))
A27: Main Hand enchant | B27: Greater Agility | D27: 35 | O27: =IF(ISNUMBER(SEARCH(" ",$N27)),LEFT($N27,(SEARCH(" ",$N27)-1)),$N27) | P27: =IF((LEN($N27)=((LEN(CONCATENATE($O27:O27))+COUNTA($O27:O27))-1)), "", IF( ISNUMBER(SEARCH(" ",$N27,((1+COUNTA($O27:O27))+LEN(CONCATENATE($O27:O27))))), MID($N27,((1+COUNTA($O27:O27))+LEN(CONCATENATE($O27:O27))),(((SEARCH(" ",$N27,((1+COUNTA($O27:O27))+LEN(CONCATENATE($O27:O27))))-1)-COUNTA($O27:O27))-LEN(CONCATENATE($O27:O27)))), RIGHT($N27,((((1+LEN($N27))-1)-COUNTA($O27:O27))-LEN(CONCATENATE($O27:O27)))))) | Q27: =IF((LEN($N27)=((LEN(CONCATENATE($O27:P27))+COUNTA($O27:P27))-1)), "", IF( ISNUMBER(SEARCH(" ",$N27,((1+COUNTA($O27:P27))+LEN(CONCATENATE($O27:P27))))), MID($N27,((1+COUNTA($O27:P27))+LEN(CONCATENATE($O27:P27))),(((SEARCH(" ",$N27,((1+COUNTA($O27:P27))+LEN(CONCATENATE($O27:P27))))-1)-COUNTA($O27:P27))-LEN(CONCATENATE($O27:P27)))), RIGHT($N27,((((1+LEN($N27))-1)-COUNTA($O27:P27))-LEN(CONCATENATE($O27:P27)))))) | R27: =IF((LEN($N27)=((LEN(CONCATENATE($O27:Q27))+COUNTA($O27:Q27))-1)), "", IF( ISNUMBER(SEARCH(" ",$N27,((1+COUNTA($O27:Q27))+LEN(CONCATENATE($O27:Q27))))), MID($N27,((1+COUNTA($O27:Q27))+LEN(CONCATENATE($O27:Q27))),(((SEARCH(" ",$N27,((1+COUNTA($O27:Q27))+LEN(CONCATENATE($O27:Q27))))-1)-COUNTA($O27:Q27))-LEN(CONCATENATE($O27:Q27)))), RIGHT($N27,((((1+LEN($N27))-1)-COUNTA($O27:Q27))-LEN(CONCATENATE($O27:Q27)))))) | S27: =IF((LEN($N27)=((LEN(CONCATENATE($O27:R27))+COUNTA($O27:R27))-1)), "", IF( ISNUMBER(SEARCH(" ",$N27,((1+COUNTA($O27:R27))+LEN(CONCATENATE($O27:R27))))), MID($N27,((1+COUNTA($O27:R27))+LEN(CONCATENATE($O27:R27))),(((SEARCH(" ",$N27,((1+COUNTA($O27:R27))+LEN(CONCATENATE($O27:R27))))-1)-COUNTA($O27:R27))-LEN(CONCATENATE($O27:R27)))), RIGHT($N27,((((1+LEN($N27))-1)-COUNTA($O27:R27))-LEN(CONCATENATE($O27:R27))))))
A28: Off Hand | O28: =IF(ISNUMBER(SEARCH(" ",$N28)),LEFT($N28,(SEARCH(" ",$N28)-1)),$N28) | P28: =IF((LEN($N28)=((LEN(CONCATENATE($O28:O28))+COUNTA($O28:O28))-1)), "", IF( ISNUMBER(SEARCH(" ",$N28,((1+COUNTA($O28:O28))+LEN(CONCATENATE($O28:O28))))), MID($N28,((1+COUNTA($O28:O28))+LEN(CONCATENATE($O28:O28))),(((SEARCH(" ",$N28,((1+COUNTA($O28:O28))+LEN(CONCATENATE($O28:O28))))-1)-COUNTA($O28:O28))-LEN(CONCATENATE($O28:O28)))), RIGHT($N28,((((1+LEN($N28))-1)-COUNTA($O28:O28))-LEN(CONCATENATE($O28:O28)))))) | Q28: =IF((LEN($N28)=((LEN(CONCATENATE($O28:P28))+COUNTA($O28:P28))-1)), "", IF( ISNUMBER(SEARCH(" ",$N28,((1+COUNTA($O28:P28))+LEN(CONCATENATE($O28:P28))))), MID($N28,((1+COUNTA($O28:P28))+LEN(CONCATENATE($O28:P28))),(((SEARCH(" ",$N28,((1+COUNTA($O28:P28))+LEN(CONCATENATE($O28:P28))))-1)-COUNTA($O28:P28))-LEN(CONCATENATE($O28:P28)))), RIGHT($N28,((((1+LEN($N28))-1)-COUNTA($O28:P28))-LEN(CONCATENATE($O28:P28)))))) | R28: =IF((LEN($N28)=((LEN(CONCATENATE($O28:Q28))+COUNTA($O28:Q28))-1)), "", IF( ISNUMBER(SEARCH(" ",$N28,((1+COUNTA($O28:Q28))+LEN(CONCATENATE($O28:Q28))))), MID($N28,((1+COUNTA($O28:Q28))+LEN(CONCATENATE($O28:Q28))),(((SEARCH(" ",$N28,((1+COUNTA($O28:Q28))+LEN(CONCATENATE($O28:Q28))))-1)-COUNTA($O28:Q28))-LEN(CONCATENATE($O28:Q28)))), RIGHT($N28,((((1+LEN($N28))-1)-COUNTA($O28:Q28))-LEN(CONCATENATE($O28:Q28)))))) | S28: =IF((LEN($N28)=((LEN(CONCATENATE($O28:R28))+COUNTA($O28:R28))-1)), "", IF( ISNUMBER(SEARCH(" ",$N28,((1+COUNTA($O28:R28))+LEN(CONCATENATE($O28:R28))))), MID($N28,((1+COUNTA($O28:R28))+LEN(CONCATENATE($O28:R28))),(((SEARCH(" ",$N28,((1+COUNTA($O28:R28))+LEN(CONCATENATE($O28:R28))))-1)-COUNTA($O28:R28))-LEN(CONCATENATE($O28:R28)))), RIGHT($N28,((((1+LEN($N28))-1)-COUNTA($O28:R28))-LEN(CONCATENATE($O28:R28))))))
A29: Relic | B29: Idol of the Wild | N29: wild | O29: =IF(ISNUMBER(SEARCH(" ",$N29)),LEFT($N29,(SEARCH(" ",$N29)-1)),$N29) -> wild | P29: =IF((LEN($N29)=((LEN(CONCATENATE($O29:O29))+COUNTA($O29:O29))-1)), "", IF( ISNUMBER(SEARCH(" ",$N29,((1+COUNTA($O29:O29))+LEN(CONCATENATE($O29:O29))))), MID($N29,((1+COUNTA($O29:O29))+LEN(CONCATENATE($O29:O29))),(((SEARCH(" ",$N29,((1+COUNTA($O29:O29))+LEN(CONCATENATE($O29:O29))))-1)-COUNTA($O29:O29))-LEN(CONCATENATE($O29:O29)))), RIGHT($N29,((((1+LEN($N29))-1)-COUNTA($O29:O29))-LEN(CONCATENATE($O29:O29)))))) | Q29: =IF((LEN($N29)=((LEN(CONCATENATE($O29:P29))+COUNTA($O29:P29))-1)), "", IF( ISNUMBER(SEARCH(" ",$N29,((1+COUNTA($O29:P29))+LEN(CONCATENATE($O29:P29))))), MID($N29,((1+COUNTA($O29:P29))+LEN(CONCATENATE($O29:P29))),(((SEARCH(" ",$N29,((1+COUNTA($O29:P29))+LEN(CONCATENATE($O29:P29))))-1)-COUNTA($O29:P29))-LEN(CONCATENATE($O29:P29)))), RIGHT($N29,((((1+LEN($N29))-1)-COUNTA($O29:P29))-LEN(CONCATENATE($O29:P29)))))) | R29: =IF((LEN($N29)=((LEN(CONCATENATE($O29:Q29))+COUNTA($O29:Q29))-1)), "", IF( ISNUMBER(SEARCH(" ",$N29,((1+COUNTA($O29:Q29))+LEN(CONCATENATE($O29:Q29))))), MID($N29,((1+COUNTA($O29:Q29))+LEN(CONCATENATE($O29:Q29))),(((SEARCH(" ",$N29,((1+COUNTA($O29:Q29))+LEN(CONCATENATE($O29:Q29))))-1)-COUNTA($O29:Q29))-LEN(CONCATENATE($O29:Q29)))), RIGHT($N29,((((1+LEN($N29))-1)-COUNTA($O29:Q29))-LEN(CONCATENATE($O29:Q29)))))) | S29: =IF((LEN($N29)=((LEN(CONCATENATE($O29:R29))+COUNTA($O29:R29))-1)), "", IF( ISNUMBER(SEARCH(" ",$N29,((1+COUNTA($O29:R29))+LEN(CONCATENATE($O29:R29))))), MID($N29,((1+COUNTA($O29:R29))+LEN(CONCATENATE($O29:R29))),(((SEARCH(" ",$N29,((1+COUNTA($O29:R29))+LEN(CONCATENATE($O29:R29))))-1)-COUNTA($O29:R29))-LEN(CONCATENATE($O29:R29)))), RIGHT($N29,((((1+LEN($N29))-1)-COUNTA($O29:R29))-LEN(CONCATENATE($O29:R29))))))
A30: Test | B30: Stat changes to evaluate various stats | C30: ='Stat values'!C5*10 -> 0 | D30: ='Stat values'!D5*10 -> 0 | E30: ='Stat values'!E5*10 -> 0 | H30: ='Stat values'!F5*10 -> 0 | I30: ='Stat values'!G5*5 -> 0 | J30: ='Stat values'!H5*10 -> 0 | K30: ='Stat values'!I5*8 -> 0 | L30: ='Stat values'!J5*10 -> 0 | M30: ='stat values'!K5*3 -> 0 | N30: ='stat values'!L5 | O30: =IF(ISNUMBER(SEARCH(" ",$N30)),LEFT($N30,(SEARCH(" ",$N30)-1)),$N30) | P30: =IF((LEN($N30)=((LEN(CONCATENATE($O30:O30))+COUNTA($O30:O30))-1)), "", IF( ISNUMBER(SEARCH(" ",$N30,((1+COUNTA($O30:O30))+LEN(CONCATENATE($O30:O30))))), MID($N30,((1+COUNTA($O30:O30))+LEN(CONCATENATE($O30:O30))),(((SEARCH(" ",$N30,((1+COUNTA($O30:O30))+LEN(CONCATENATE($O30:O30))))-1)-COUNTA($O30:O30))-LEN(CONCATENATE($O30:O30)))), RIGHT($N30,((((1+LEN($N30))-1)-COUNTA($O30:O30))-LEN(CONCATENATE($O30:O30)))))) | Q30: =IF((LEN($N30)=((LEN(CONCATENATE($O30:P30))+COUNTA($O30:P30))-1)), "", IF( ISNUMBER(SEARCH(" ",$N30,((1+COUNTA($O30:P30))+LEN(CONCATENATE($O30:P30))))), MID($N30,((1+COUNTA($O30:P30))+LEN(CONCATENATE($O30:P30))),(((SEARCH(" ",$N30,((1+COUNTA($O30:P30))+LEN(CONCATENATE($O30:P30))))-1)-COUNTA($O30:P30))-LEN(CONCATENATE($O30:P30)))), RIGHT($N30,((((1+LEN($N30))-1)-COUNTA($O30:P30))-LEN(CONCATENATE($O30:P30)))))) | R30: =IF((LEN($N30)=((LEN(CONCATENATE($O30:Q30))+COUNTA($O30:Q30))-1)), "", IF( ISNUMBER(SEARCH(" ",$N30,((1+COUNTA($O30:Q30))+LEN(CONCATENATE($O30:Q30))))), MID($N30,((1+COUNTA($O30:Q30))+LEN(CONCATENATE($O30:Q30))),(((SEARCH(" ",$N30,((1+COUNTA($O30:Q30))+LEN(CONCATENATE($O30:Q30))))-1)-COUNTA($O30:Q30))-LEN(CONCATENATE($O30:Q30)))), RIGHT($N30,((((1+LEN($N30))-1)-COUNTA($O30:Q30))-LEN(CONCATENATE($O30:Q30)))))) | S30: =IF((LEN($N30)=((LEN(CONCATENATE($O30:R30))+COUNTA($O30:R30))-1)), "", IF( ISNUMBER(SEARCH(" ",$N30,((1+COUNTA($O30:R30))+LEN(CONCATENATE($O30:R30))))), MID($N30,((1+COUNTA($O30:R30))+LEN(CONCATENATE($O30:R30))),(((SEARCH(" ",$N30,((1+COUNTA($O30:R30))+LEN(CONCATENATE($O30:R30))))-1)-COUNTA($O30:R30))-LEN(CONCATENATE($O30:R30)))), RIGHT($N30,((((1+LEN($N30))-1)-COUNTA($O30:R30))-LEN(CONCATENATE($O30:R30))))))
A31: Set bonuses | H31: =if((COUNTIF(misc_gear,"primalstrike")>=3),40,0) -> 40
A32: Total | C32: =SUM(C2:C31) -> 304 | D32: =SUM(D2:D31) -> 418 | E32: =SUM(E2:E31) -> 401 | F32: =SUM(F2:F31) -> 51 | G32: =SUM(G2:G31) -> 6 | H32: =SUM(H2:H31) -> 1416.3333 | I32: =SUM(I2:I31) -> 175 | J32: =SUM(J2:J31) -> 88 | ... M32: =SUM(M2:M31) -> 7

Sheet Talents
B1: Talent | C1: Points | D1: Effect
B2: Feral
B3: Ferocity | C3: 5 | D3: =-C3 -> -5 | E3: energy for claw, rake, mangle
B4: Sharpened Claws | C4: 3 | D4: =0.02*C4 -> 0.06 | E4: crit chance
B5: Shredding Attacks | C5: 2 | D5: =-9*C5 -> -18 | E5: energy for shred
B6: Predatory Strikes | C6: 3 | D6: =(0.5*C6)*basic!B3 -> 105 | E6: attack power
B7: Primal Fury | C7: 2 | D7: =0.5*C7 -> 1 | E7: chance for extra combo point on crit
B8: Savage Fury | C8: 2 | D8: =1 +( 0.1*C8) -> 1.2 | E8: damage multiplier on claw rake and mangle
B9: Faerie Fire Feral | C9: 1 | D9: =-VLOOKUP(B9,'Spell Ranks'!A:C,3,FALSE) -> -610 | E9: armor to target
B10: Heart of the Wild | C10: 5 | D10: =1 +( 0.04*C10) -> 1.2 | E10: multiplier to INT and STR
B11: Leader of the Pack | C11: 1 | D11: =0.05*C11 -> 0.05 | E11: crit chance
B12: Predatory Instincts | C12: 5 | D12: =1 +( 0.02*C12) -> 1.1 | E12: damage multiplier on crits
B13: Survival of the Fittest | C13: 3 | D13: =1 +( 0.01*C13) -> 1.03 | E13: multiplier to STR, AGI, STA, INT, SPI
B14: Mangle | C14: 1 | D14: =C14>0 -> TRUE | E14: can use Mangle (Cat)
B15: Restoration
B16: Naturalist | C16: 5 | D16: =1+(0.02*C16) -> 1.1 | E16: damage multiplier
B17: Omen of clarity | C17: 1 | D17: =C17/30 -> 0.033333333 | E17: chance of a clearcast per attack (modeled as global energy reduction)

Sheet Stats
A1: Base stats | B1: Base | C1: Gear | D1: Buffs | E1: Combined | F1: Total
A2: STR | B2: 73 | C2: =gear!C32 -> 304 | E2: =(B2+C2)+D2 -> 377 | F2: =((E2*VLOOKUP("Survival of the Fittest",Talents!B:D,3,0))*VLOOKUP("Heart of the Wild",Talents!B:D,3,0))*basic!B10 -> 489.2706
A3: AGI | B3: 75 | C3: =gear!D32 -> 418 | E3: =(B3+C3)+D3 -> 493 | F3: =(E3*VLOOKUP("Survival of the Fittest",Talents!B:D,3,0))*basic!B10 -> 533.1795
A4: STA | B4: 82 | C4: =gear!E32 -> 401 | E4: =(B4+C4)+D4 -> 483 | F4: =(E4*VLOOKUP("Survival of the Fittest",Talents!B:D,3,0))*basic!B10 -> 522.3645
A5: INT | B5: 120 | C5: =gear!F32 -> 51 | E5: =(B5+C5)+D5 -> 171 | F5: =((E5*VLOOKUP("Survival of the Fittest",Talents!B:D,3,0))*VLOOKUP("Heart of the Wild",Talents!B:D,3,0))*basic!B10 -> 221.9238
A6: SPI | B6: 132 | C6: =gear!G32 -> 6 | E6: =(B6+C6)+D6 -> 138 | F6: =(E6*VLOOKUP("Survival of the Fittest",Talents!B:D,3,0))*basic!B10 -> 149.247
A7: Increased AP | B7: -20 | C7: =gear!H32 -> 1416.3333 | E7: =(B7+C7)+D7 -> 1396.3333 | F7: =(E7+VLOOKUP("Predatory Strikes",Talents!B:D,3,0))+(2*basic!B3) -> 1641.3333
A8: Hit rating | C8: =gear!I32 -> 175 | E8: =(B8+C8)+D8 -> 175 | F8: =E8 -> 175
A9: Crit rating | C9: =gear!J32 -> 88 | E9: =(B9+C9)+D9 -> 88 | F9: =E9 -> 88
A10: Feral skill rating | C10: =gear!K32 -> 18 | E10: =(B10+C10)+D10 -> 18 | F10: =E10 -> 18
A11: Haste rating | C11: =gear!L32 -> 0 | E11: =(B11+C11)+D11 -> 0 | F11: =E11 -> 0
A12: Weapon damage | B12: 55 | C12: =gear!M32 -> 7 | E12: =(B12+C12)+D12 -> 62 | F12: =E12 -> 62
A13: Critical multiplier | B13: =1*VLOOKUP("Predatory Instincts",talents!B:D,3,0) -> 1.1 | C13: =1+(COUNTIF(Misc_gear,"relentless")*0.03) -> 1.03 | D13: 1 | E13: =(B13*C13)*D13 -> 1.133 | F13: =E13 -> 1.133
A14: Shred bonus | B14: =VLOOKUP("Shred",'spell ranks'!A:C,3,0) -> 405 | C14: =COUNTIF(gear!N:N,"everbloom")*88 -> 0 | E14: =(B14+C14)+D14 -> 405 | F14: =E14 -> 405
A15: Rip bonus | B15: =VLOOKUP("Rip",'spell ranks'!A:C,3,0) -> 1562 | C15: =COUNTIF(Misc_gear,"shadows")*12 -> 0 | E15: =(B15+C15)+D15 -> 1562 | F15: =E15 -> 1562
A16: Mangle bonus | B16: =VLOOKUP("Mangle",'spell ranks'!A:C,3,0) -> 264 | C16: =COUNTIF(Misc_gear,"wild")*54 -> 54 | E16: =(B16+C16)+D16 -> 318 | F16: =E16 -> 318
A17: Derived stats
A18: Feral skill increase | B18: =TRUNC((F10/3.94)) -> 4 | C18: =MAX(0,MIN((basic!B6-10),B18)) -> 4 | D18: =MAX(0,MIN(basic!B6,(B18-C18))) -> 0 | E18: =(B18-C18)-D18 -> 0
