Workbook
Name _ZZ65536: [1]TotalExpenses!#REF!
Name _ZZ65536: [1]TotalExpenses!#REF!
Name _ZZ65536: [1]TotalExpenses!#REF!
Name _ZZ65536: [1]TotalExpenses!#REF!
Name a: [1]TotalExpenses!#REF!
Name a: [1]TotalExpenses!#REF!
Name July_99: #REF!
Name July_99: #REF!
Name PrintArea: #REF!
Name PrintArea: #REF!
Name Report: #REF!
Name Report: #REF!
Name spec: #REF!
Name spec: #REF!

Sheet summary
A1: Project Title | B1: LifeWeb | C1: New Coalitions for Biodiversity - Developing public-private partnerships within protected areas in five countries of the South East Europe - Budget
A2: Duration | B2: 3 Years
A3: Prepared by: | B3: Marzia Ventimiglia | C3: Date: | D3: 40366
A5: Summary per country | B5: YEAR 1 | E5: YEAR 2 | H5: YEAR 3 | L5: TOTAL 3 YEARS
A6: Category | B6: Donor | C6: WWF MEDPO | D6: Total | E6: Donor | F6: WWF MEDPO | G6: Total | H6: Donor | I6: WWF MEDPO | J6: Total | L6: Donor | M6: WWF MEDPO | N6: Total
A7: Project Staff
A8: REGIONAL PROJECT TEAM | B8: ='REGIONAL PROJECT TEAM 3 years'!C17 -> 253364.4 | C8: ='REGIONAL PROJECT TEAM 3 years'!D17 -> 0 | D8: =SUM(B8:C8) -> 253364.4 | E8: ='REGIONAL PROJECT TEAM 3 years'!F17 -> 266032.62 | F8: ='REGIONAL PROJECT TEAM 3 years'!G17 -> 0 | G8: =SUM(E8:F8) -> 266032.62 | H8: ='REGIONAL PROJECT TEAM 3 years'!I17 -> 271065.5 | I8: ='REGIONAL PROJECT TEAM 3 years'!J17 -> 0 | J8: =SUM(H8:I8) -> 271065.5 | L8: =SUM(B8,E8,H8) -> 790462.52 | M8: =SUM(C8,F8,I8) -> 0 | N8: =SUM(L8:M8) -> 790462.52
A9: COMMUNICATIONS & WSHOPS | B9: =SUM('COMMUNICATIONS & WSHOPS'!C11) -> 0 | C9: =SUM('COMMUNICATIONS & WSHOPS'!D11) -> 0 | D9: =SUM(B9:C9) -> 0 | E9: =SUM('COMMUNICATIONS & WSHOPS'!F11) -> 0 | F9: =SUM('COMMUNICATIONS & WSHOPS'!G11) -> 0 | G9: =SUM(E9:F9) -> 0 | H9: =SUM('COMMUNICATIONS & WSHOPS'!I11) -> 0 | I9: =SUM('CROATIA 3 years'!J11) -> 0 | J9: =SUM(H9:I9) -> 0 | L9: =SUM(B9,E9,H9) -> 0 | M9: =SUM(C9,F9,I9) -> 0 | N9: =SUM(L9:M9) -> 0
A10: CROATIA | B10: =SUM('CROATIA 3 years'!C11) -> 7580.5 | C10: =SUM('CROATIA 3 years'!D11) -> 0 | D10: =SUM(B10:C10) -> 7580.5 | E10: =SUM('CROATIA 3 years'!F11) -> 5333.3333 | F10: =SUM('CROATIA 3 years'!G11) -> 0 | G10: =SUM(E10:F10) -> 5333.3333 | H10: =SUM('CROATIA 3 years'!I11) -> 5333.3333 | I10: =SUM('CROATIA 3 years'!J11) -> 0 | J10: =SUM(H10:I10) -> 5333.3333 | L10: =SUM(B10,E10,H10) -> 18247.167 | M10: =SUM(C10,F10,I10) -> 0 | N10: =SUM(L10:M10) -> 18247.167
A11: B&H | B11: ='B&H 3 years'!$C$11 -> 14321 | C11: ='B&H 3 years'!$D$11 -> 0 | D11: =SUM(B11:C11) -> 14321 | E11: ='B&H 3 years'!$F$11 -> 10666.667 | F11: ='B&H 3 years'!$G$11 -> 0 | G11: =SUM(E11:F11) -> 10666.667 | H11: ='B&H 3 years'!$I$11 -> 10666.667 | I11: ='B&H 3 years'!$J$11 -> 0 | J11: =SUM(H11:I11) -> 10666.667 | L11: =SUM(B11,E11,H11) -> 35654.333 | M11: =SUM(C11,F11,I11) -> 0 | N11: =SUM(L11:M11) -> 35654.333
A12: SERBIA | B12: ='SERBIA 3 years'!$C$11 -> 7580.5 | C12: ='SERBIA 3 years'!$D$11 -> 0 | D12: =SUM(B12:C12) -> 7580.5 | E12: ='SERBIA 3 years'!$F$11 -> 7333.3333 | F12: ='SERBIA 3 years'!$G$11 -> 0 | G12: =SUM(E12:F12) -> 7333.3333 | H12: ='SERBIA 3 years'!$I$11 -> 5333.3333 | I12: ='SERBIA 3 years'!$J$11 -> 0 | J12: =SUM(H12:I12) -> 5333.3333 | L12: =SUM(B12,E12,H12) -> 20247.167 | M12: =SUM(C12,F12,I12) -> 0 | N12: =SUM(L12:M12) -> 20247.167
A13: MONTENEGRO | B13: ='MONTENEGRO 3 years'!$C$11 -> 7580.5 | C13: ='MONTENEGRO 3 years'!$D$11 -> 0 | D13: =SUM(B13:C13) -> 7580.5 | E13: ='MONTENEGRO 3 years'!$F$11 -> 5333.3333 | F13: ='MONTENEGRO 3 years'!$G$11 -> 0 | G13: =SUM(E13:F13) -> 5333.3333 | H13: ='MONTENEGRO 3 years'!$I$11 -> 5333.3333 | I13: ='MONTENEGRO 3 years'!$J$11 -> 0 | J13: =SUM(H13:I13) -> 5333.3333 | L13: =SUM(B13,E13,H13) -> 18247.167 | M13: =SUM(C13,F13,I13) -> 0 | N13: =SUM(L13:M13) -> 18247.167
A14: ALBANIA | B14: ='ALBANIA 3 years'!$C$11 -> 7580.5 | C14: ='ALBANIA 3 years'!$D$11 -> 0 | D14: =SUM(B14:C14) -> 7580.5 | E14: ='ALBANIA 3 years'!$F$11 -> 5333.3333 | F14: ='ALBANIA 3 years'!$G$11 -> 0 | G14: =SUM(E14:F14) -> 5333.3333 | H14: ='ALBANIA 3 years'!$I$11 -> 5333.3333 | I14: ='ALBANIA 3 years'!$J$11 -> 0 | J14: =SUM(H14:I14) -> 5333.3333 | L14: =SUM(B14,E14,H14) -> 18247.167 | M14: =SUM(C14,F14,I14) -> 0 | N14: =SUM(L14:M14) -> 18247.167
A15: Total 1 | B15: =SUM(B8:B14) -> 298007.4 | C15: =SUM(C8:C14) -> 0 | D15: =SUM(D8:D14) -> 298007.4 | E15: =SUM(E8:E14) -> 300032.62 | F15: =SUM(F8:F14) -> 0 | G15: =SUM(G8:G14) -> 300032.62 | H15: =SUM(H8:H14) -> 303065.5 | I15: =SUM(I8:I14) -> 0 | J15: =SUM(J8:J14) -> 303065.5 | L15: =SUM(L8:L14) -> 901105.52 | M15: =SUM(M8:M14) -> 0 | N15: =SUM(N8:N14) -> 901105.52
A16: Studies, publications and workshops
A17: REGIONAL PROJECT TEAM | B17: ='REGIONAL PROJECT TEAM 3 years'!C23 -> 0 | C17: ='REGIONAL PROJECT TEAM 3 years'!D23 -> 0 | D17: =SUM(B17:C17) -> 0 | E17: ='REGIONAL PROJECT TEAM 3 years'!F23 -> 0 | F17: ='REGIONAL PROJECT TEAM 3 years'!G23 -> 0 | G17: =SUM(E17:F17) -> 0 | H17: ='REGIONAL PROJECT TEAM 3 years'!I23 -> 0 | I17: ='REGIONAL PROJECT TEAM 3 years'!J23 -> 0 | J17: =SUM(H17:I17) -> 0 | L17: =SUM(B17,E17,H17) -> 0 | M17: =SUM(C17,F17,I17) -> 0 | N17: =SUM(L17:M17) -> 0
A18: COMMUNICATIONS & WORK-SHOPS | B18: =SUM('COMMUNICATIONS & WSHOPS'!$C$22) -> 58000 | C18: =SUM('COMMUNICATIONS & WSHOPS'!$D$22) -> 0 | D18: =SUM(B18:C18) -> 58000 | E18: =SUM('COMMUNICATIONS & WSHOPS'!$F$22) -> 48000 | F18: =SUM('COMMUNICATIONS & WSHOPS'!$G$22) -> 0 | G18: =SUM(E18:F18) -> 48000 | H18: =SUM('COMMUNICATIONS & WSHOPS'!$I$22) -> 39000 | I18: =SUM('COMMUNICATIONS & WSHOPS'!$J$22) -> 0 | J18: =SUM(H18:I18) -> 39000 | L18: =SUM(B18,E18,H18) -> 145000 | M18: =SUM(C18,F18,I18) -> 0 | N18: =SUM(L18:M18) -> 145000
A19: CROATIA | B19: =SUM('CROATIA 3 years'!$C$17) -> 6941 | C19: =SUM('CROATIA 3 years'!$D$17) -> 0 | D19: =SUM(B19:C19) -> 6941 | E19: =SUM('CROATIA 3 years'!$F$17) -> 12607.667 | F19: =SUM('CROATIA 3 years'!$G$17) -> 0 | G19: =SUM(E19:F19) -> 12607.667 | H19: =SUM('CROATIA 3 years'!$I$17) -> 1666.6667 | I19: =SUM('CROATIA 3 years'!$J$17) -> 0 | J19: =SUM(H19:I19) -> 1666.6667 | L19: =SUM(B19,E19,H19) -> 21215.333 | M19: =SUM(C19,F19,I19) -> 0 | N19: =SUM(L19:M19) -> 21215.333
A20: B&H | B20: =SUM('B&H 3 years'!$C$17) -> 3135 | C20: =SUM('B&H 3 years'!$D$17) -> 0 | D20: =SUM(B20:C20) -> 3135 | E20: =SUM('B&H 3 years'!$F$17) -> 16468.333 | F20: =SUM('B&H 3 years'!$G$17) -> 0 | G20: =SUM(E20:F20) -> 16468.333 | H20: =SUM('B&H 3 years'!$I$17) -> 7333.3333 | I20: =SUM('B&H 3 years'!$J$17) -> 0 | J20: =SUM(H20:I20) -> 7333.3333 | L20: =SUM(B20,E20,H20) -> 26936.667 | M20: =SUM(C20,F20,I20) -> 0 | N20: =SUM(L20:M20) -> 26936.667
A21: SERBIA | B21: =SUM('SERBIA 3 years'!$C$17) -> 3794 | C21: =SUM('SERBIA 3 years'!$D$17) -> 0 | D21: =SUM(B21:C21) -> 3794 | E21: =SUM('SERBIA 3 years'!$F$17) -> 11460.667 | F21: =SUM('SERBIA 3 years'!$G$17) -> 0 | G21: =SUM(E21:F21) -> 11460.667 | H21: =SUM('SERBIA 3 years'!$I$17) -> 3666.6667 | I21: =SUM('SERBIA 3 years'!$J$17) -> 0 | J21: =SUM(H21:I21) -> 3666.6667 | L21: =SUM(B21,E21,H21) -> 18921.333 | M21: =SUM(C21,F21,I21) -> 0 | N21: =SUM(L21:M21) -> 18921.333
A22: MONTENEGRO | B22: =SUM('MONTENEGRO 3 years'!$C$17) -> 5182 | C22: =SUM('MONTENEGRO 3 years'!$D$17) -> 0 | D22: =SUM(B22:C22) -> 5182 | E22: =SUM('MONTENEGRO 3 years'!$F$17) -> 12848.667 | F22: =SUM('MONTENEGRO 3 years'!$G$17) -> 0 | G22: =SUM(E22:F22) -> 12848.667 | H22: =SUM('MONTENEGRO 3 years'!$I$17) -> 3666.6667 | I22: =SUM('MONTENEGRO 3 years'!$J$17) -> 0 | J22: =SUM(H22:I22) -> 3666.6667 | L22: =SUM(B22,E22,H22) -> 21697.333 | M22: =SUM(C22,F22,I22) -> 0 | N22: =SUM(L22:M22) -> 21697.333
A23: ALBANIA | B23: =SUM('ALBANIA 3 years'!$C$17) -> 6352 | C23: =SUM('ALBANIA 3 years'!$D$17) -> 0 | D23: =SUM(B23:C23) -> 6352 | E23: =SUM('ALBANIA 3 years'!$F$17) -> 12018.667 | F23: =SUM('ALBANIA 3 years'!$G$17) -> 0 | G23: =SUM(E23:F23) -> 12018.667 | H23: =SUM('ALBANIA 3 years'!$I$17) -> 3666.6667 | I23: =SUM('ALBANIA 3 years'!$J$17) -> 0 | J23: =SUM(H23:I23) -> 3666.6667 | L23: =SUM(B23,E23,H23) -> 22037.333 | M23: =SUM(C23,F23,I23) -> 0 | N23: =SUM(L23:M23) -> 22037.333
A25: Total 2 | B25: =SUM(B17:B24) -> 83404 | C25: =SUM(C17:C24) -> 0 | D25: =SUM(D17:D24) -> 83404 | E25: =SUM(E17:E24) -> 113404 | F25: =SUM(F17:F24) -> 0 | G25: =SUM(G17:G24) -> 113404 | H25: =SUM(H17:H24) -> 59000 | I25: =SUM(I17:I24) -> 0 | J25: =SUM(J17:J24) -> 59000 | L25: =SUM(L17:L24) -> 255808 | M25: =SUM(M17:M24) -> 0 | N25: =SUM(N17:N24) -> 255808
A26: Travel
A27: REGIONAL PROJECT TEAM | B27: ='REGIONAL PROJECT TEAM 3 years'!C29 -> 16864 | C27: ='REGIONAL PROJECT TEAM 3 years'!D29 -> 0 | D27: =SUM(B27:C27) -> 16864 | E27: ='REGIONAL PROJECT TEAM 3 years'!F29 -> 14864 | F27: ='REGIONAL PROJECT TEAM 3 years'!G29 -> 0 | G27: =SUM(E27:F27) -> 14864 | H27: ='REGIONAL PROJECT TEAM 3 years'!I29 -> 14364 | I27: ='REGIONAL PROJECT TEAM 3 years'!J29 -> 0 | J27: =SUM(H27:I27) -> 14364 | L27: =SUM(B27,E27,H27) -> 46092 | M27: =SUM(C27,F27,I27) -> 0 | N27: =SUM(L27:M27) -> 46092
A28: COMMUNICATIONS & WSHOPS | B28: ='COMMUNICATIONS & WSHOPS'!C28 -> 0 | C28: ='COMMUNICATIONS & WSHOPS'!D28 -> 0 | D28: =SUM(B28:C28) -> 0 | E28: ='COMMUNICATIONS & WSHOPS'!F28 -> 0 | F28: ='COMMUNICATIONS & WSHOPS'!G28 -> 0 | G28: =SUM(E28:F28) -> 0 | H28: ='COMMUNICATIONS & WSHOPS'!I28 -> 0 | I28: ='COMMUNICATIONS & WSHOPS'!J28 -> 0 | J28: =SUM(H28:I28) -> 0 | L28: =SUM(B28,E28,H28) -> 0 | M28: =SUM(C28,F28,I28) -> 0 | N28: =SUM(L28:M28) -> 0
A29: CROATIA | B29: ='CROATIA 3 years'!$C$23 -> 4035.7778 | C29: ='CROATIA 3 years'!$D$23 -> 0 | D29: =SUM(B29:C29) -> 4035.7778 | E29: =SUM('CROATIA 3 years'!$F$23) -> 3576.2222 | F29: =SUM('CROATIA 3 years'!$G$23) -> 0 | G29: =SUM(E29:F29) -> 3576.2222 | H29: =SUM('CROATIA 3 years'!$I$23) -> 2604 | I29: =SUM('CROATIA 3 years'!$J$23) -> 0 | J29: =SUM(H29:I29) -> 2604 | L29: =SUM(B29,E29,H29) -> 10216 | M29: =SUM(C29,F29,I29) -> 0 | N29: =SUM(L29:M29) -> 10216
A30: B&H | B30: ='B&H 3 years'!$C$23 -> 6263.5556 | C30: ='B&H 3 years'!$D$23 -> 0 | D30: =SUM(B30:C30) -> 6263.5556 | E30: =SUM('B&H 3 years'!$F$23) -> 5248.4444 | F30: =SUM('B&H 3 years'!$G$23) -> 0 | G30: =SUM(E30:F30) -> 5248.4444 | H30: =SUM('B&H 3 years'!$I$23) -> 3304 | I30: =SUM('B&H 3 years'!$J$23) -> 0 | J30: =SUM(H30:I30) -> 3304 | L30: =SUM(B30,E30,H30) -> 14816 | M30: =SUM(C30,F30,I30) -> 0 | N30: =SUM(L30:M30) -> 14816
A31: SERBIA | B31: ='SERBIA 3 years'!$C$23 -> 4235.7778 | C31: ='SERBIA 3 years'!$D$23 -> 0 | D31: =SUM(B31:C31) -> 4235.7778 | E31: =SUM('SERBIA 3 years'!$F$23) -> 3776.2222 | F31: =SUM('SERBIA 3 years'!$G$23) -> 0 | G31: =SUM(E31:F31) -> 3776.2222 | H31: =SUM('SERBIA 3 years'!$I$23) -> 2804 | I31: =SUM('SERBIA 3 years'!$J$23) -> 0 | J31: =SUM(H31:I31) -> 2804 | L31: =SUM(B31,E31,H31) -> 10816 | M31: =SUM(C31,F31,I31) -> 0 | N31: =SUM(L31:M31) -> 10816
A32: MONTENEGRO | B32: ='MONTENEGRO 3 years'!$C$23 -> 4235.7778 | C32: ='MONTENEGRO 3 years'!$D$23 -> 0 | D32: =SUM(B32:C32) -> 4235.7778 | E32: =SUM('MONTENEGRO 3 years'!$F$23) -> 3776.2222 | F32: =SUM('MONTENEGRO 3 years'!$G$23) -> 0 | G32: =SUM(E32:F32) -> 3776.2222 | H32: =SUM('MONTENEGRO 3 years'!$I$23) -> 2804 | I32: =SUM('MONTENEGRO 3 years'!$J$23) -> 0 | J32: =SUM(H32:I32) -> 2804 | L32: =SUM(B32,E32,H32) -> 10816 | M32: =SUM(C32,F32,I32) -> 0 | N32: =SUM(L32:M32) -> 10816
A33: ALBANIA | B33: ='ALBANIA 3 years'!$C$23 -> 4235.7778 | C33: ='ALBANIA 3 years'!$D$23 -> 0 | D33: =SUM(B33:C33) -> 4235.7778 | E33: =SUM('ALBANIA 3 years'!$F$23) -> 3776.2222 | F33: =SUM('ALBANIA 3 years'!$G$23) -> 0 | G33: =SUM(E33:F33) -> 3776.2222 | H33: =SUM('ALBANIA 3 years'!$I$23) -> 2804 | I33: =SUM('ALBANIA 3 years'!$J$23) -> 0 | J33: =SUM(H33:I33) -> 2804 | L33: =SUM(B33,E33,H33) -> 10816 | M33: =SUM(C33,F33,I33) -> 0 | N33: =SUM(L33:M33) -> 10816
G34: =SUM(E34:F34) -> 0
A35: Total 3 | B35: =SUM(B27:B34) -> 39870.667 | C35: =SUM(C27:C34) -> 0 | D35: =SUM(D27:D34) -> 39870.667 | E35: =SUM(E27:E34) -> 35017.333 | F35: =SUM(F27:F34) -> 0 | G35: =SUM(G27:G34) -> 35017.333 | H35: =SUM(H27:H34) -> 28684 | I35: =SUM(I27:I34) -> 0 | J35: =SUM(J27:J34) -> 28684 | L35: =SUM(L27:L34) -> 103572 | M35: =SUM(M27:M34) -> 0 | N35: =SUM(N27:N34) -> 103572
A36: Local Office Running Costs
A37: REGIONAL PROJECT TEAM | B37: ='REGIONAL PROJECT TEAM 3 years'!C36 -> 13200 | C37: ='REGIONAL PROJECT TEAM 3 years'!D36 -> 0 | D37: =SUM(B37:C37) -> 13200 | E37: ='REGIONAL PROJECT TEAM 3 years'!F36 -> 7560 | F37: ='REGIONAL PROJECT TEAM 3 years'!G36 -> 0 | G37: =SUM(E37:F37) -> 7560 | H37: ='REGIONAL PROJECT TEAM 3 years'!I36 -> 7938 | I37: ='REGIONAL PROJECT TEAM 3 years'!J36 -> 0 | J37: =SUM(H37:I37) -> 7938 | L37: =SUM(B37,E37,H37) -> 28698 | M37: =SUM(C37,F37,I37) -> 0 | N37: =SUM(L37:M37) -> 28698
A38: COMMUNICATIONS & WSHOPS | B38: ='COMMUNICATIONS & WSHOPS'!C37 -> 0 | C38: ='COMMUNICATIONS & WSHOPS'!D37 -> 0 | D38: =SUM(B38:C38) -> 0 | E38: ='COMMUNICATIONS & WSHOPS'!F37 -> 0 | F38: ='COMMUNICATIONS & WSHOPS'!G37 -> 0 | G38: =SUM(E38:F38) -> 0 | H38: ='COMMUNICATIONS & WSHOPS'!I37 -> 0 | I38: ='COMMUNICATIONS & WSHOPS'!J37 -> 0 | J38: =SUM(H38:I38) -> 0 | L38: =SUM(B38,E38,H38) -> 0 | M38: =SUM(C38,F38,I38) -> 0 | N38: =SUM(L38:M38) -> 0
A39: CROATIA | B39: =SUM('CROATIA 3 years'!$C$26) -> 0 | C39: =SUM('CROATIA 3 years'!$D$26) -> 0 | D39: =SUM(B39:C39) -> 0 | E39: =SUM('CROATIA 3 years'!$F$26) -> 0 | F39: =SUM('CROATIA 3 years'!$G$26) -> 0 | G39: =SUM(E39:F39) -> 0 | H39: =SUM('CROATIA 3 years'!$I$26) -> 0 | I39: =SUM('CROATIA 3 years'!$J$26) -> 0 | J39: =SUM(H39:I39) -> 0 | L39: =SUM(B39,E39,H39) -> 0 | M39: =SUM(C39,F39,I39) -> 0 | N39: =SUM(L39:M39) -> 0
A40: B&H | B40: =SUM('B&H 3 years'!$C$26) -> 0 | C40: =SUM('B&H 3 years'!$D$26) -> 0 | D40: =SUM(B40:C40) -> 0 | E40: =SUM('B&H 3 years'!$F$26) -> 0 | F40: =SUM('B&H 3 years'!$G$26) -> 0 | G40: =SUM(E40:F40) -> 0 | H40: =SUM('B&H 3 years'!$I$26) -> 0 | I40: =SUM('B&H 3 years'!$J$26) -> 0 | J40: =SUM(H40:I40) -> 0 | L40: =SUM(B40,E40,H40) -> 0 | M40: =SUM(C40,F40,I40) -> 0 | N40: =SUM(L40:M40) -> 0
A41: SERBIA | B41: =SUM('SERBIA 3 years'!$C$26) -> 0 | C41: =SUM('SERBIA 3 years'!$D$26) -> 0 | D41: =SUM(B41:C41) -> 0 | E41: =SUM('SERBIA 3 years'!$F$26) -> 0 | F41: =SUM('SERBIA 3 years'!$G$26) -> 0 | G41: =SUM(E41:F41) -> 0 | H41: =SUM('SERBIA 3 years'!$I$26) -> 0 | I41: =SUM('SERBIA 3 years'!$J$26) -> 0 | J41: =SUM(H41:I41) -> 0 | L41: =SUM(B41,E41,H41) -> 0 | M41: =SUM(C41,F41,I41) -> 0 | N41: =SUM(L41:M41) -> 0
A42: MONTENEGRO | B42: =SUM('MONTENEGRO 3 years'!$C$26) -> 0 | C42: =SUM('MONTENEGRO 3 years'!$D$26) -> 0 | D42: =SUM(B42:C42) -> 0 | E42: =SUM('MONTENEGRO 3 years'!$F$26) -> 0 | F42: =SUM('MONTENEGRO 3 years'!$G$26) -> 0 | G42: =SUM(E42:F42) -> 0 | H42: =SUM('MONTENEGRO 3 years'!$I$26) -> 0 | I42: =SUM('MONTENEGRO 3 years'!$J$26) -> 0 | J42: =SUM(H42:I42) -> 0 | L42: =SUM(B42,E42,H42) -> 0 | M42: =SUM(C42,F42,I42) -> 0 | N42: =SUM(L42:M42) -> 0
...

Sheet REGIONAL PROJECT TEAM 3 years
B1: Project Title: | C1: LifeWeb | D1: New Coalitions for Biodiversity - Developing public-private partnerships within protected areas in five countries of the South East Europe - Budget
B2: Project Activities: | C2: REGIONAL PROJECT TEAM
C5: YEAR 1 - 2011 | F5: YEAR 2 - 2012 | I5: YEAR 3 -2013 | M5: TOTAL 3 YEARS
B6: Category | C6: Donor | D6: WWF MEDPO | E6: Total | F6: Donor | G6: WWF MEDPO | H6: Total | I6: Donor | J6: WWF MEDPO | K6: Total | M6: Donor | N6: WWF MEDPO | O6: Total
A7: 1 | B7: Project Staff
A8: 1.1 | B8: Regional Project leader (36 month - 100%) | C8: 50000 | E8: =SUM(C8:D8) -> 50000 | F8: =C8+(C8*0.05) -> 52500 | H8: =SUM(F8:G8) -> 52500 | I8: =F8+(F8*0.05) -> 55125 | K8: =SUM(I8:J8) -> 55125 | M8: =SUM(C8,F8,I8) -> 157625 | N8: =SUM(D8,G8,J8) -> 0 | O8: =SUM(M8:N8) -> 157625
A9: 1.2 | B9: Assistant to Project Leader (36 month - 100%) | C9: =1000*12 -> 12000 | E9: =SUM(C9:D9) -> 12000 | F9: =+C9*1.05 -> 12600 | H9: =SUM(F9:G9) -> 12600 | I9: =+F9*1.05 -> 13230 | K9: =SUM(I9:J9) -> 13230 | M9: =SUM(C9,F9,I9) -> 37830 | N9: =SUM(D9,G9,J9) -> 0 | O9: =SUM(M9:N9) -> 37830
A10: 1.3 | B10: Director of Conservation WWF-MEDPO | C10: =SUM(30000/30/3*12)*3 -> 12000 | E10: =SUM(C10:D10) -> 12000 | F10: =C10+(C10*0.05) -> 12600 | H10: =SUM(F10:G10) -> 12600 | I10: =F10+(F10*0.05) -> 13230 | K10: =SUM(I10:J10) -> 13230 | M10: =SUM(C10,F10,I10) -> 37830 | N10: =SUM(D10,G10,J10) -> 0 | O10: =SUM(M10:N10) -> 37830
A11: 1.4 | B11: Project Administration Staff: 1. WWF-MEDPO administrator 2. Local administrator) | C11: =(52291.520526/0.8) -> 65364.401 | E11: =SUM(C11:D11) -> 65364.401 | F11: =C11+(C11*0.05) -> 68632.621 | H11: =SUM(F11:G11) -> 68632.621 | I11: =F11+(F11*0.05) -> 72064.252 | K11: =SUM(I11:J11) -> 72064.252 | M11: =SUM(C11,F11,I11) -> 206061.27 | N11: =SUM(D11,G11,J11) -> 0 | O11: =SUM(M11:N11) -> 206061.27
A12: 1.5 | B12: BP development lead local (36 month - 100%) | C12: =30000 -> 30000 | E12: =SUM(C12:D12) -> 30000 | F12: =+C12*1.05 -> 31500 | H12: =SUM(F12:G12) -> 31500 | I12: =+F12*1.05 -> 33075 | K12: =SUM(I12:J12) -> 33075 | M12: =SUM(C12,F12,I12) -> 94575 | N12: =SUM(D12,G12,J12) -> 0 | O12: =SUM(M12:N12) -> 94575
A13: 1.6 | B13: PPP Regional Leader (36 month - 100% ) | C13: =(2500*12) -> 30000 | E13: =SUM(C13:D13) -> 30000 | F13: =+C13*1.05 -> 31500 | H13: =SUM(F13:G13) -> 31500 | I13: =F13+(F13*0.05) -> 33075 | K13: =SUM(I13:J13) -> 33075 | M13: =SUM(C13,F13,I13) -> 94575 | N13: =SUM(D13,G13,J13) -> 0 | O13: =SUM(M13:N13) -> 94575
A14: 1.7 | B14: PPP Regional Leader Assistant (36 month - 100%) | C14: =1500*12 -> 18000 | E14: =SUM(C14:D14) -> 18000 | F14: =+C14*1.05 -> 18900 | H14: =SUM(F14:G14) -> 18900 | I14: =+F14*1.05 -> 19845 | K14: =SUM(I14:J14) -> 19845 | M14: =SUM(C14,F14,I14) -> 56745 | N14: =SUM(D14,G14,J14) -> 0 | O14: =SUM(M14:N14) -> 56745
A15: 1.8 | B15: PPP development international support: 30% /Year, Director of Comms WWF-MEDPO | C15: 28500 | E15: =SUM(C15:D15) -> 28500 | F15: =C15+(C15*0.05) -> 29925 | H15: =SUM(F15:G15) -> 29925 | I15: =F15+(F15*0.05) -> 31421.25 | K15: =SUM(I15:J15) -> 31421.25 | M15: =SUM(C15,F15,I15) -> 89846.25 | N15: =SUM(D15,G15,J15) -> 0 | O15: =SUM(M15:N15) -> 89846.25
A16: 1.9 | B16: PPP capacity building international support: 10% of Education & Capacity Building Manager WWF- MEDPO | C16: =75000*0.1 -> 7500 | E16: =SUM(C16:D16) -> 7500 | F16: =C16*1.05 -> 7875 | H16: =SUM(F16:G16) -> 7875 | K16: =SUM(I16:J16) -> 0 | M16: =SUM(C16,F16,I16) -> 15375 | N16: =SUM(D16,G16,J16) -> 0 | O16: =SUM(M16:N16) -> 15375
B17: Total 1 | C17: =SUM(C8:C16) -> 253364.4 | D17: =SUM(D8:D16) -> 0 | E17: =SUM(C17:D17) -> 253364.4 | F17: =SUM(F8:F16) -> 266032.62 | G17: =SUM(G8:G16) -> 0 | H17: =SUM(F17:G17) -> 266032.62 | I17: =SUM(I8:I16) -> 271065.5 | J17: =SUM(J8:J16) -> 0 | K17: =SUM(I17:J17) -> 271065.5 | M17: =SUM(M8:M16) -> 790462.52 | N17: =SUM(N8:N16) -> 0 | O17: =SUM(M17:N17) -> 790462.52
E19: =SUM(C19:D19) -> 0 | H19: =SUM(F19:G19) -> 0 | K19: =SUM(I19:J19) -> 0 | M19: =SUM(C19,F19,I19) -> 0 | N19: =SUM(D19,G19,J19) -> 0 | O19: =SUM(M19:N19) -> 0
E20: =SUM(C20:D20) -> 0 | H20: =SUM(F20:G20) -> 0 | K20: =SUM(I20:J20) -> 0 | M20: =SUM(C20,F20,I20) -> 0 | N20: =SUM(D20,G20,J20) -> 0 | O20: =SUM(M20:N20) -> 0
E21: =SUM(C21:D21) -> 0 | H21: =SUM(F21:G21) -> 0 | K21: =SUM(I21:J21) -> 0 | M21: =SUM(C21,F21,I21) -> 0 | N21: =SUM(D21,G21,J21) -> 0 | O21: =SUM(M21:N21) -> 0 | P21: =12000+20000+15000+10000 -> 57000 | Q21: 12000
E22: =SUM(C22:D22) -> 0 | H22: =SUM(F22:G22) -> 0 | K22: =SUM(I22:J22) -> 0 | M22: =SUM(C22,F22,I22) -> 0 | N22: =SUM(D22,G22,J22) -> 0 | O22: =SUM(M22:N22) -> 0 | Q22: -10000
B23: Total 2 | C23: =SUM(C19:C22) -> 0 | D23: =SUM(D19:D22) -> 0 | E23: =SUM(C23:D23) -> 0 | F23: =SUM(F19:F22) -> 0 | G23: =SUM(G19:G22) -> 0 | H23: =SUM(F23:G23) -> 0 | I23: =SUM(I19:I22) -> 0 | J23: =SUM(J19:J22) -> 0 | K23: =SUM(I23:J23) -> 0 | M23: =SUM(M19:M22) -> 0 | N23: =SUM(N19:N22) -> 0 | O23: =SUM(M23:N23) -> 0
A24: 3 | B24: Travel
A25: 3.1 | B25: Travel project regional Leader | C25: 1000 | E25: =SUM(C25:D25) -> 1000 | F25: 1000 | H25: =SUM(F25:G25) -> 1000 | I25: 1000 | K25: =SUM(I25:J25) -> 1000 | M25: =SUM(C25,F25,I25) -> 3000 | N25: =SUM(D25,G25,J25) -> 0 | O25: =SUM(M25:N25) -> 3000
A26: 3.2 | B26: Travel project supervision team (BP component) | C26: =3000+(8*483) -> 6864 | E26: =SUM(C26:D26) -> 6864 | F26: =3000+(8*483) -> 6864 | H26: =SUM(F26:G26) -> 6864 | I26: =2500+(8*483) -> 6364 | K26: =SUM(I26:J26) -> 6364 | M26: =SUM(C26,F26,I26) -> 20092 | N26: =SUM(D26,G26,J26) -> 0 | O26: =SUM(M26:N26) -> 20092
A27: 3.3 | B27: Travel costs for PPP staff selection | C27: 2000 | E27: =SUM(C27:D27) -> 2000 | H27: =SUM(F27:G27) -> 0 | K27: =SUM(I27:J27) -> 0 | M27: =SUM(C27,F27,I27) -> 2000 | N27: =SUM(D27,G27,J27) -> 0 | O27: =SUM(M27:N27) -> 2000
A28: 3.4 | B28: Travel project supervision team (PPP component) | C28: 7000 | E28: =SUM(C28:D28) -> 7000 | F28: 7000 | H28: =SUM(F28:G28) -> 7000 | I28: 7000 | K28: =SUM(I28:J28) -> 7000 | M28: =SUM(C28,F28,I28) -> 21000 | N28: =SUM(D28,G28,J28) -> 0 | O28: =SUM(M28:N28) -> 21000
B29: Total 3 | C29: =SUM(C25:C28) -> 16864 | D29: =SUM(D25:D28) -> 0 | E29: =SUM(C29:D29) -> 16864 | F29: =SUM(F25:F28) -> 14864 | G29: =SUM(G25:G28) -> 0 | H29: =SUM(F29:G29) -> 14864 | I29: =SUM(I25:I28) -> 14364 | J29: =SUM(J25:J28) -> 0 | K29: =SUM(I29:J29) -> 14364 | M29: =SUM(M25:M28) -> 46092 | N29: =SUM(N25:N28) -> 0 | O29: =SUM(M29:N29) -> 46092
A30: 4 | B30: Local Office Running Costs | H30: =SUM(F30:G30) -> 0 | K30: =SUM(I30:J30) -> 0 | O30: =SUM(M30:N30) -> 0
A31: 4.3 | B31: ORC for local lead (4 people) | C31: =(150*4)*12 -> 7200 | E31: =SUM(C31:D31) -> 7200 | F31: =C31+(C31*0.05) -> 7560 | H31: =SUM(F31:G31) -> 7560 | I31: =F31+(F31*0.05) -> 7938 | K31: =SUM(I31:J31) -> 7938 | M31: =SUM(C31,F31,I31) -> 22698 | N31: =SUM(D31,G31,J31) -> 0 | O31: =SUM(M31:N31) -> 22698
A32: 4.4 | B32: Equipment (4xPC/software/printer and office set up) | C32: 6000 | E32: =SUM(C32:D32) -> 6000 | H32: =SUM(F32:G32) -> 0 | K32: =SUM(I32:J32) -> 0 | M32: =SUM(C32,F32,I32) -> 6000 | N32: =SUM(D32,G32,J32) -> 0 | O32: =SUM(M32:N32) -> 6000
E33: =SUM(C33:D33) -> 0 | H33: =SUM(F33:G33) -> 0 | K33: =SUM(I33:J33) -> 0 | M33: =SUM(C33,F33,I33) -> 0 | N33: =SUM(D33,G33,J33) -> 0 | O33: =SUM(M33:N33) -> 0
B36: Total 4 | C36: =SUM(C31:C35) -> 13200 | D36: =SUM(D31:D35) -> 0 | E36: =SUM(E31:E35) -> 13200 | F36: =SUM(F31:F35) -> 7560 | G36: =SUM(G31:G35) -> 0 | H36: =SUM(H31:H35) -> 7560 | I36: =SUM(I31:I35) -> 7938 | J36: =SUM(J31:J35) -> 0 | K36: =SUM(K31:K35) -> 7938 | M36: =SUM(M31:M35) -> 28698 | N36: =SUM(N31:N35) -> 0 | O36: =SUM(O31:O35) -> 28698
A38: 5 | B38: Management Fees - 8,5% | C38: =C48*0.085 -> 24091.414 | D38: =D48*0.085 -> 0 | E38: =SUM(C38:D38) -> 24091.414 | F38: =F48*0.085 -> 24518.813 | G38: =G48*0.085 -> 0 | H38: =SUM(F38:G38) -> 24518.813 | I38: =I48*0.085 -> 24936.238 | J38: =J48*0.085 -> 0 | K38: =SUM(I38:J38) -> 24936.238 | M38: =SUM(C38,F38,I38) -> 73546.464 | N38: =SUM(D38,G38,J38) -> 0 | O38: =SUM(M38:N38) -> 73546.464
B40: Total | C40: =SUM(C17,C23,C29,C36,C38) -> 307519.81 | D40: =SUM(D17,D23,D29,D36,D38) -> 0 | E40: =SUM(E17,E23,E29,E36,E38) -> 307519.81 | F40: =SUM(F17,F23,F29,F36,F38) -> 312975.43 | G40: =SUM(G17,G23,G29,G36,G38) -> 0 | H40: =SUM(H17,H23,H29,H36,H38) -> 312975.43 | I40: =SUM(I17,I23,I29,I36,I38) -> 318303.74 | J40: =SUM(J17,J23,J29,J36,J38) -> 0 | K40: =SUM(K17,K23,K29,K36,K38) -> 318303.74 | M40: =SUM(M17,M23,M29,M36,M38) -> 938798.99 | N40: =SUM(N17,N23,N29,N36,N38) -> 0 | O40: =SUM(O17,O23,O29,O36,O38) -> 938798.99
C41: Donor | D41: WWF MedPO | E41: Total
B42: Year 1 | C42: =SUM(C17+C23+C29+C36+C38) -> 307519.81 | D42: =SUM(D17+D23+D29+D36+D38) -> 0 | E42: =SUM(C42:D42) -> 307519.81
B43: Year 2 | C43: =SUM(F17+F23+F29+F36+F38) -> 312975.43 | D43: =SUM(G17+G23+G29+G36+G38) -> 0 | E43: =SUM(C43:D43) -> 312975.43
B44: Year 3 | C44: =SUM(I17+I23+I29+I36+I38) -> 318303.74 | D44: =SUM(J17+J23+J29+J36+J38) -> 0 | E44: =SUM(C44:D44) -> 318303.74
B45: Total 3 years | C45: =SUM(C42:C44) -> 938798.99 | D45: =SUM(D42:D44) -> 0 | E45: =SUM(E42:E44) -> 938798.99
B48: Total Direct Cost for MedPO ORC and Admin | C48: =SUM(C17,C23,C29,C36) -> 283428.4 | D48: =SUM(D17,D23,D29,D36) -> 0 | E48: =SUM(E17,E23,E29,E36) -> 283428.4 | F48: =SUM(F17,F23,F29,F36) -> 288456.62 | G48: =SUM(G17,G23,G29,G36) -> 0 | H48: =SUM(H17,H23,H29,H36) -> 288456.62 | I48: =SUM(I17,I23,I29,I36) -> 293367.5 | J48: =SUM(J17,J23,J29,J36) -> 0 | K48: =SUM(K17,K23,K29,K36) -> 293367.5 | M48: =SUM(M17,M23,M29,M36) -> 865252.52 | N48: =SUM(N17,N23,N29,N36) -> 0 | O48: =SUM(O17,O23,O29,O36) -> 865252.52
M51: =SUM(M34+M35) -> 0

Sheet COMMUNICATIONS & WSHOPS
B1: Project Title: | C1: LifeWeb | D1: New Coalitions for Biodiversity - Developing public-private partnerships within protected areas in five countries of the South East Europe - Budget
B2: Project Activities: | C2: COMMUNICATIONS & WORK-SHOPS
C5: YEAR 1 - 2011 | F5: YEAR 2 - 2012 | I5: YEAR 3 -2013 | M5: TOTAL 3 YEARS
B6: Category | C6: Donor | D6: WWF MEDPO | E6: Total | F6: Donor | G6: WWF MEDPO | H6: Total | I6: Donor | J6: WWF MEDPO | K6: Total | M6: Donor | N6: WWF MEDPO | O6: Total
A7: 1 | B7: Project Staff
A8: 1.1 | E8: =SUM(C8:D8) -> 0 | F8: =C8+(C8*0.05) -> 0 | H8: =SUM(F8:G8) -> 0 | I8: =F8+(F8*0.05) -> 0 | K8: =SUM(I8:J8) -> 0 | M8: =SUM(C8,F8,I8) -> 0 | N8: =SUM(D8,G8,J8) -> 0 | O8: =SUM(M8:N8) -> 0
A9: 1.2 | E9: =SUM(C9:D9) -> 0 | F9: =+C9*1.05 -> 0 | H9: =SUM(F9:G9) -> 0 | I9: =+F9*1.05 -> 0 | K9: =SUM(I9:J9) -> 0 | M9: =SUM(C9,F9,I9) -> 0 | N9: =SUM(D9,G9,J9) -> 0 | O9: =SUM(M9:N9) -> 0
A10: 1.5 | E10: =SUM(C10:D10) -> 0 | F10: =+C10*1.05 -> 0 | H10: =SUM(F10:G10) -> 0 | I10: =+F10*1.05 -> 0 | K10: =SUM(I10:J10) -> 0 | M10: =SUM(C10,F10,I10) -> 0 | N10: =SUM(D10,G10,J10) -> 0 | O10: =SUM(M10:N10) -> 0
A11: 1.4 | E11: =SUM(C11:D11) -> 0 | F11: =+C11*1.05 -> 0 | H11: =SUM(F11:G11) -> 0 | I11: =F11+(F11*0.05) -> 0 | K11: =SUM(I11:J11) -> 0 | M11: =SUM(C11,F11,I11) -> 0 | N11: =SUM(D11,G11,J11) -> 0 | O11: =SUM(M11:N11) -> 0
A12: 1.7 | E12: =SUM(C12:D12) -> 0 | F12: =+C12*1.05 -> 0 | H12: =SUM(F12:G12) -> 0 | I12: =+F12*1.05 -> 0 | K12: =SUM(I12:J12) -> 0 | M12: =SUM(C12,F12,I12) -> 0 | N12: =SUM(D12,G12,J12) -> 0 | O12: =SUM(M12:N12) -> 0
A13: 1.3 | E13: =SUM(C13:D13) -> 0 | F13: =C13+(C13*0.05) -> 0 | H13: =SUM(F13:G13) -> 0 | I13: =F13+(F13*0.05) -> 0 | K13: =SUM(I13:J13) -> 0 | M13: =SUM(C13,F13,I13) -> 0 | N13: =SUM(D13,G13,J13) -> 0 | O13: =SUM(M13:N13) -> 0
A14: 1.6 | E14: =SUM(C14:D14) -> 0 | F14: =C14*1.05 -> 0 | H14: =SUM(F14:G14) -> 0 | K14: =SUM(I14:J14) -> 0 | M14: =SUM(C14,F14,I14) -> 0 | N14: =SUM(D14,G14,J14) -> 0 | O14: =SUM(M14:N14) -> 0
B15: Total 1 | C15: =SUM(C8:C14) -> 0 | D15: =SUM(D8:D14) -> 0 | E15: =SUM(C15:D15) -> 0 | F15: =SUM(F8:F14) -> 0 | G15: =SUM(G8:G14) -> 0 | H15: =SUM(F15:G15) -> 0 | I15: =SUM(I8:I14) -> 0 | J15: =SUM(J8:J14) -> 0 | K15: =SUM(I15:J15) -> 0 | M15: =SUM(M8:M14) -> 0 | N15: =SUM(N8:N14) -> 0 | O15: =SUM(M15:N15) -> 0
A16: 2 | B16: Studies, publications and workshops
A17: 2.1 | B17: Training on public-private partnership development for PA managers | C17: 18000 | E17: =SUM(C17:D17) -> 18000 | F17: 18000 | H17: =SUM(F17:G17) -> 18000 | K17: =SUM(I17:J17) -> 0 | M17: =SUM(C17,F17,I17) -> 36000 | N17: =SUM(D17,G17,J17) -> 0 | O17: =SUM(M17:N17) -> 36000
A18: 2.2 | B18: Capacity building on BP and N. 2000 (€ 2000 per PA) | E18: =SUM(C18:D18) -> 0 | H18: =SUM(F18:G18) -> 0 | I18: =2000*6 -> 12000 | K18: =SUM(I18:J18) -> 12000 | M18: =SUM(C18,F18,I18) -> 12000 | N18: =SUM(D18,G18,J18) -> 0 | O18: =SUM(M18:N18) -> 12000
A19: 2.3 | B19: Promotion of PAs values, communications work to attract business, promotional materials for development of pub-priv partnerships (2,5) | C19: 30000 | E19: =SUM(C19:D19) -> 30000 | F19: 30000 | H19: =SUM(F19:G19) -> 30000 | I19: 20000 | K19: =SUM(I19:J19) -> 20000 | M19: =SUM(C19,F19,I19) -> 80000 | N19: =SUM(D19,G19,J19) -> 0 | O19: =SUM(M19:N19) -> 80000 | P19: =12000+20000+15000+10000 -> 57000 | Q19: 12000
A20: 2.4 | B20: Production of “how-to” guide for establishing public private partnerships based on the project experiences (off line or online tool) (At. 2,8) | E20: =SUM(C20:D20) -> 0 | H20: =SUM(F20:G20) -> 0 | I20: 7000 | K20: =SUM(I20:J20) -> 7000 | M20: =SUM(C20,F20,I20) -> 7000 | N20: =SUM(D20,G20,J20) -> 0 | O20: =SUM(M20:N20) -> 7000 | Q20: -10000
A21: 2.5 | B21: One Planet Leader - Training on corporate & private sector relationships development (2 people training) | C21: =5000*2 -> 10000 | E21: =SUM(C21:D21) -> 10000 | H21: =SUM(F21:G21) -> 0 | K21: =SUM(I21:J21) -> 0 | M21: =SUM(C21,F21,I21) -> 10000 | N21: =SUM(D21,G21,J21) -> 0 | O21: =SUM(M21:N21) -> 10000 | Q21: -10000
B22: Total 2 | C22: =SUM(C17:C21) -> 58000 | D22: =SUM(D17:D21) -> 0 | E22: =SUM(C22:D22) -> 58000 | F22: =SUM(F17:F21) -> 48000 | G22: =SUM(G17:G21) -> 0 | H22: =SUM(F22:G22) -> 48000 | I22: =SUM(I17:I21) -> 39000 | J22: =SUM(J17:J21) -> 0 | K22: =SUM(I22:J22) -> 39000 | M22: =SUM(M17:M21) -> 145000 | N22: =SUM(N17:N21) -> 0 | O22: =SUM(M22:N22) -> 145000
A23: 3 | B23: Travel
A24: 3.1 | E24: =SUM(C24:D24) -> 0 | H24: =SUM(F24:G24) -> 0 | K24: =SUM(I24:J24) -> 0 | M24: =SUM(C24,F24,I24) -> 0 | N24: =SUM(D24,G24,J24) -> 0 | O24: =SUM(M24:N24) -> 0
A25: 3.2 | E25: =SUM(C25:D25) -> 0 | H25: =SUM(F25:G25) -> 0 | K25: =SUM(I25:J25) -> 0 | M25: =SUM(C25,F25,I25) -> 0 | N25: =SUM(D25,G25,J25) -> 0 | O25: =SUM(M25:N25) -> 0
A26: 3.3 | E26: =SUM(C26:D26) -> 0 | H26: =SUM(F26:G26) -> 0 | K26: =SUM(I26:J26) -> 0 | M26: =SUM(C26,F26,I26) -> 0 | N26: =SUM(D26,G26,J26) -> 0 | O26: =SUM(M26:N26) -> 0
A27: 3.4 | E27: =SUM(C27:D27) -> 0 | H27: =SUM(F27:G27) -> 0 | K27: =SUM(I27:J27) -> 0 | M27: =SUM(C27,F27,I27) -> 0 | N27: =SUM(D27,G27,J27) -> 0 | O27: =SUM(M27:N27) -> 0
B28: Total 3 | C28: =SUM(C24:C27) -> 0 | D28: =SUM(D24:D27) -> 0 | E28: =SUM(C28:D28) -> 0 | F28: =SUM(F24:F27) -> 0 | G28: =SUM(G24:G27) -> 0 | H28: =SUM(F28:G28) -> 0 | I28: =SUM(I24:I27) -> 0 | J28: =SUM(J24:J27) -> 0 | K28: =SUM(I28:J28) -> 0 | M28: =SUM(M24:M27) -> 0 | N28: =SUM(N24:N27) -> 0 | O28: =SUM(M28:N28) -> 0
A29: 4 | B29: Local Office Running Costs | H29: =SUM(F29:G29) -> 0 | K29: =SUM(I29:J29) -> 0 | O29: =SUM(M29:N29) -> 0
A30: 4.1 | E30: =SUM(C30:D30) -> 0 | F30: =C30+(C30*0.05) -> 0 | H30: =SUM(F30:G30) -> 0 | I30: =F30+(F30*0.05) -> 0 | K30: =SUM(I30:J30) -> 0 | M30: =SUM(C30,F30,I30) -> 0 | N30: =SUM(D30,G30,J30) -> 0 | O30: =SUM(M30:N30) -> 0
A31: 4.2 | E31: =SUM(C31:D31) -> 0 | F31: =C31+(C31*0.05) -> 0 | H31: =SUM(F31:G31) -> 0 | I31: =F31+(F31*0.05) -> 0 | K31: =SUM(I31:J31) -> 0 | M31: =SUM(C31,F31,I31) -> 0 | N31: =SUM(D31,G31,J31) -> 0 | O31: =SUM(M31:N31) -> 0
A32: 4.3 | E32: =SUM(C32:D32) -> 0 | F32: =C32+(C32*0.05) -> 0 | H32: =SUM(F32:G32) -> 0 | I32: =F32+(F32*0.05) -> 0 | K32: =SUM(I32:J32) -> 0 | M32: =SUM(C32,F32,I32) -> 0 | N32: =SUM(D32,G32,J32) -> 0 | O32: =SUM(M32:N32) -> 0
A33: 4.4 | E33: =SUM(C33:D33) -> 0 | H33: =SUM(F33:G33) -> 0 | K33: =SUM(I33:J33) -> 0 | M33: =SUM(C33,F33,I33) -> 0 | N33: =SUM(D33,G33,J33) -> 0 | O33: =SUM(M33:N33) -> 0
A34: 4.5 | E34: =SUM(C34:D34) -> 0 | H34: =SUM(F34:G34) -> 0 | K34: =SUM(I34:J34) -> 0 | M34: =SUM(C34,F34,I34) -> 0 | N34: =SUM(D34,G34,J34) -> 0 | O34: =SUM(M34:N34) -> 0
B37: Total 4 | C37: =SUM(C30:C36) -> 0 | D37: =SUM(D30:D36) -> 0 | E37: =SUM(E30:E36) -> 0 | F37: =SUM(F30:F36) -> 0 | G37: =SUM(G30:G36) -> 0 | H37: =SUM(H30:H36) -> 0 | I37: =SUM(I30:I36) -> 0 | J37: =SUM(J30:J36) -> 0 | K37: =SUM(K30:K36) -> 0 | M37: =SUM(M30:M36) -> 0 | N37: =SUM(N30:N36) -> 0 | O37: =SUM(O30:O36) -> 0
A39: 5 | B39: Management Fees - 8,5% | C39: =C49*0.085 -> 4930 | D39: =D49*0.085 -> 0 | E39: =SUM(C39:D39) -> 4930 | F39: =F49*0.085 -> 4080 | G39: =G49*0.085 -> 0 | H39: =SUM(F39:G39) -> 4080 | I39: =I49*0.085 -> 3315 | J39: =J49*0.085 -> 0 | K39: =SUM(I39:J39) -> 3315 | M39: =SUM(C39,F39,I39) -> 12325 | N39: =SUM(D39,G39,J39) -> 0 | O39: =SUM(M39:N39) -> 12325
B41: Total | C41: =SUM(C15,C22,C28,C37,C39) -> 62930 | D41: =SUM(D15,D22,D28,D37,D39) -> 0 | E41: =SUM(E15,E22,E28,E37,E39) -> 62930 | F41: =SUM(F15,F22,F28,F37,F39) -> 52080 | G41: =SUM(G15,G22,G28,G37,G39) -> 0 | H41: =SUM(H15,H22,H28,H37,H39) -> 52080 | I41: =SUM(I15,I22,I28,I37,I39) -> 42315 | J41: =SUM(J15,J22,J28,J37,J39) -> 0 | K41: =SUM(K15,K22,K28,K37,K39) -> 42315 | M41: =SUM(M15,M22,M28,M37,M39) -> 157325 | N41: =SUM(N15,N22,N28,N37,N39) -> 0 | O41: =SUM(O15,O22,O28,O37,O39) -> 157325
C42: Donor | D42: WWF MedPO | E42: Total
B43: Year 1 | C43: =SUM(C15+C22+C28+C37+C39) -> 62930 | D43: =SUM(D15+D22+D28+D37+D39) -> 0 | E43: =SUM(C43:D43) -> 62930
B44: Year 2 | C44: =SUM(F15+F22+F28+F37+F39) -> 52080 | D44: =SUM(G15+G22+G28+G37+G39) -> 0 | E44: =SUM(C44:D44) -> 52080
B45: Year 3 | C45: =SUM(I15+I22+I28+I37+I39) -> 42315 | D45: =SUM(J15+J22+J28+J37+J39) -> 0 | E45: =SUM(C45:D45) -> 42315
B46: Total 3 years | C46: =SUM(C43:C45) -> 157325 | D46: =SUM(D43:D45) -> 0 | E46: =SUM(E43:E45) -> 157325
...

Sheet CROATIA 3 years
B1: Project Title: | C1: LifeWeb | D1: New Coalitions for Biodiversity - Developing public-private partnerships within protected areas in five countries of the South East Europe - Budget
B2: Project Activities: | C2: CROATIA
C5: YEAR 1 - 2011 | F5: YEAR 2 -2012 | I5: YEAR 3 2013 | M5: TOTAL 3 YEARS
B6: Category | C6: Donor | D6: WWF MEDPO | E6: Total | F6: Donor | G6: WWF MEDPO | H6: Total | I6: Donor | J6: WWF MEDPO | K6: Total | M6: Donor | N6: WWF MEDPO | O6: Total
A7: 1 | B7: Project Staff
A8: 1.1 | B8: BP development international support team: Expert 1: 30 month. (Marlen Flores) | C8: =(28443/6)*1 -> 4740.5 | E8: =SUM(C8:D8) -> 4740.5 | F8: =(20000/6)*1 -> 3333.3333 | H8: =SUM(F8:G8) -> 3333.3333 | I8: =(20000/6)*1 -> 3333.3333 | K8: =SUM(I8:J8) -> 3333.3333 | M8: =SUM(C8,F8,I8) -> 11407.167 | N8: =SUM(D8,G8,J8) -> 0 | O8: =SUM(M8:N8) -> 11407.167 | P8: Back to MATRA proposal
A9: 1.3 | B9: Ministry focal point (NPCs+Serbian focal point) | C9: 840 | E9: =SUM(C9:D9) -> 840 | H9: =SUM(F9:G9) -> 0 | K9: =SUM(I9:J9) -> 0 | M9: =SUM(C9,F9,I9) -> 840 | N9: =SUM(D9,G9,J9) -> 0 | O9: =SUM(M9:N9) -> 840
A10: 1.5 | B10: PA staff cost (€ 2000 x YEAR) | C10: =(3000/6)*1+(9000/6)*1 -> 2000 | E10: =SUM(C10:D10) -> 2000 | F10: =(12000/6)*1 -> 2000 | H10: =SUM(F10:G10) -> 2000 | I10: =(12000/6)*1 -> 2000 | K10: =SUM(I10:J10) -> 2000 | M10: =SUM(C10,F10,I10) -> 6000 | N10: =SUM(D10,G10,J10) -> 0 | O10: =SUM(M10:N10) -> 6000
B11: Total 1 | C11: =SUM(C7:C10) -> 7580.5 | D11: =SUM(D7:D10) -> 0 | E11: =SUM(E7:E10) -> 7580.5 | F11: =SUM(F7:F10) -> 5333.3333 | G11: =SUM(G7:G10) -> 0 | H11: =SUM(H7:H10) -> 5333.3333 | I11: =SUM(I7:I10) -> 5333.3333 | J11: =SUM(J7:J10) -> 0 | K11: =SUM(K7:K10) -> 5333.3333 | M11: =SUM(M7:M10) -> 18247.167 | N11: =SUM(N7:N10) -> 0 | O11: =SUM(O7:O10) -> 18247.167
A12: 2 | B12: Studies, publications and workshops
A13: 2.1 | B13: Twelve Market Studies (2x PA x 1000) | C13: =1000*2 -> 2000 | E13: =SUM(C13:D13) -> 2000 | F13: =1000*2 -> 2000 | H13: =SUM(F13:G13) -> 2000 | K13: =SUM(I13:J13) -> 0 | M13: =SUM(C13,F13,I13) -> 4000 | N13: =SUM(D13,G13,J13) -> 0 | O13: =SUM(M13:N13) -> 4000 | P13: Need more assumptions for estimation
A14: 2.2 | B14: BP development workshops (1 WS x Y x PA) | C14: ='BP Training Croatia'!$G$47 -> 4941 | E14: =SUM(C14:D14) -> 4941 | F14: ='BP Training Croatia'!$G$47 -> 4941 | H14: =SUM(F14:G14) -> 4941 | K14: =SUM(I14:J14) -> 0 | M14: =SUM(C14,F14,I14) -> 9882 | N14: =SUM(D14,G14,J14) -> 0 | O14: =SUM(M14:N14) -> 9882 | P14: check with old MATRA proposal
A15: 2.4 | B15: Printing of six business plans | E15: =SUM(C15:D15) -> 0 | F15: =(10000/6)*1 -> 1666.6667 | H15: =SUM(F15:G15) -> 1666.6667 | I15: =(10000/6)*1 -> 1666.6667 | K15: =SUM(I15:J15) -> 1666.6667 | M15: =SUM(C15,F15,I15) -> 3333.3333 | N15: =SUM(D15,G15,J15) -> 0 | O15: =SUM(M15:N15) -> 3333.3333
A16: 2.5 | B16: Public launches/visibility events to highlight public-private partnership achievements (2,7) € 4000 x country | E16: =SUM(C16:D16) -> 0 | F16: 4000 | H16: =SUM(F16:G16) -> 4000 | J16: meeting spaces will be in-kind contribution by Ministries/PAs | K16: =SUM(I16:J16) -> 0 | M16: =SUM(C16,F16,I16) -> 4000 | N16: =SUM(D16,G16,J16) -> 0 | O16: =SUM(M16:N16) -> 4000
B17: Total 2 | C17: =SUM(C13:C16) -> 6941 | D17: =SUM(D13:D16) -> 0 | E17: =SUM(E13:E16) -> 6941 | F17: =SUM(F13:F16) -> 12607.667 | G17: =SUM(G13:G16) -> 0 | H17: =SUM(H13:H16) -> 12607.667 | I17: =SUM(I13:I16) -> 1666.6667 | J17: =SUM(J13:J16) -> 0 | K17: =SUM(K13:K16) -> 1666.6667 | M17: =SUM(M13:M16) -> 21215.333 | N17: =SUM(N13:N16) -> 0 | O17: =SUM(O13:O16) -> 21215.333
A18: 3 | B18: Travel
A19: 3.1 | B19: Travel PPP Lead | C19: =((12000/25)*11)/5 -> 1056 | E19: =SUM(C19:D19) -> 1056 | F19: =((12000/25)*12)/5 -> 1152 | H19: =SUM(F19:G19) -> 1152 | I19: =((12000/25)*12)/5 -> 1152 | K19: =SUM(I19:J19) -> 1152 | M19: =SUM(C19,F19,I19) -> 3360 | N19: =SUM(D19,G19,J19) -> 0 | O19: =SUM(M19:N19) -> 3360
A20: 3.1 | B20: Travel BP consultant (international) | C20: =(15000/18*11)/6 -> 1527.7778 | E20: =SUM(C20:D20) -> 1527.7778 | F20: =(15000/18*7)/6 -> 972.22222 | H20: =SUM(F20:G20) -> 972.22222 | K20: =SUM(I20:J20) -> 0 | M20: =SUM(C20,F20,I20) -> 2500 | N20: =SUM(D20,G20,J20) -> 0 | O20: =SUM(M20:N20) -> 2500
A21: 3.2 | B21: Travel Regional Project leader (3Xcountry) | C21: =1*300 -> 300 | E21: =SUM(C21:D21) -> 300 | F21: =1*300 -> 300 | H21: =SUM(F21:G21) -> 300 | I21: =1*300 -> 300 | K21: =SUM(I21:J21) -> 300 | M21: =SUM(C21,F21,I21) -> 900 | N21: =SUM(D21,G21,J21) -> 0 | O21: =SUM(M21:N21) -> 900
A22: 3.2 | B22: Travel BP development lead local | C22: =((12000/25)*12)/5 -> 1152 | E22: =SUM(C22:D22) -> 1152 | F22: =((12000/25)*12)/5 -> 1152 | H22: =SUM(F22:G22) -> 1152 | I22: =((12000/25)*12)/5 -> 1152 | K22: =SUM(I22:J22) -> 1152 | M22: =SUM(C22,F22,I22) -> 3456 | N22: =SUM(D22,G22,J22) -> 0 | O22: =SUM(M22:N22) -> 3456
B23: Total 3 | C23: =SUM(C19:C22) -> 4035.7778 | D23: =SUM(D19:D22) -> 0 | E23: =SUM(E19:E22) -> 4035.7778 | F23: =SUM(F19:F22) -> 3576.2222 | G23: =SUM(G19:G22) -> 0 | H23: =SUM(H19:H22) -> 3576.2222 | I23: =SUM(I19:I22) -> 2604 | J23: =SUM(J19:J22) -> 0 | K23: =SUM(K19:K22) -> 2604 | M23: =SUM(M19:M22) -> 10216 | N23: =SUM(N19:N22) -> 0 | O23: =SUM(O19:O22) -> 10216
A24: 4 | B24: Local Office Running Costs
B26: Total 4 | C26: =SUM(C25:C25) -> 0 | D26: =SUM(D25:D25) -> 0 | E26: =SUM(E25:E25) -> 0 | F26: =SUM(F25:F25) -> 0 | G26: =SUM(G25:G25) -> 0 | H26: =SUM(H25:H25) -> 0 | I26: =SUM(I25:I25) -> 0 | J26: =SUM(J25:J25) -> 0 | K26: =SUM(K25:K25) -> 0 | M26: =SUM(M25:M25) -> 0 | N26: =SUM(N25:N25) -> 0 | O26: =SUM(O25:O25) -> 0
A28: 5 | B28: Management Fees -8,5% | C28: =C39*0.085 -> 1577.3686 | D28: =D39*0.085 -> 0 | E28: =SUM(C28:D28) -> 1577.3686 | F28: =F39*0.085 -> 1828.9639 | G28: =G39*0.085 -> 0 | H28: =SUM(F28:G28) -> 1828.9639 | I28: =I39*0.085 -> 816.34 | J28: =J39*0.085 -> 0 | K28: =SUM(I28:J28) -> 816.34 | M28: =SUM(C28,F28,I28) -> 4222.6725 | N28: =SUM(D28,G28,J28) -> 0 | O28: =SUM(M28:N28) -> 4222.6725
B30: Total | C30: =SUM(C11,C17,C23,C26,C28) -> 20134.646 | D30: =SUM(D11,D17,D23,D26,D28) -> 0 | E30: =SUM(E11,E17,E23,E26,E28) -> 20134.646 | F30: =SUM(F11,F17,F23,F26,F28) -> 23346.186 | G30: =SUM(G11,G17,G23,G26,G28) -> 0 | H30: =SUM(H11,H17,H23,H26,H28) -> 23346.186 | I30: =SUM(I11,I17,I23,I26,I28) -> 10420.34 | J30: =SUM(J11,J17,J23,J26,J28) -> 0 | K30: =SUM(K11,K17,K23,K26,K28) -> 10420.34 | M30: =SUM(M11,M17,M23,M26,M28) -> 53901.173 | N30: =SUM(N11,N17,N23,N26,N28) -> 0 | O30: =SUM(O11,O17,O23,O26,O28) -> 53901.173
C31: Donor | D31: WWF MedPO | E31: Total
B32: Year 1 | C32: =SUM(+C23+C17+C11+C26+C28) -> 20134.646 | D32: =SUM(+D23+D17+D11+D26+D28) -> 0 | E32: =SUM(C32:D32) -> 20134.646 | H32: =SUM(F32:G32) -> 0 | K32: =SUM(I32:J32) -> 0 | O32: =SUM(M32:N32) -> 0
B33: Year 2 | C33: =SUM(F26+F23+F17+F11+F28) -> 23346.186 | D33: =SUM(G26+G23+G17+G11+G28) -> 0 | E33: =SUM(C33:D33) -> 23346.186 | H33: =SUM(F33:G33) -> 0 | K33: =SUM(I33:J33) -> 0 | O33: =SUM(M33:N33) -> 0
B34: Year 3 | C34: =SUM(I26+I23+I17+I11+I28) -> 10420.34 | D34: =SUM(J26+J23+J17+J11+J28) -> 0 | E34: =SUM(C34:D34) -> 10420.34 | H34: =SUM(F34:G34) -> 0 | K34: =SUM(I34:J34) -> 0 | O34: =SUM(M34:N34) -> 0
B35: Total 3 years | C35: =SUM(C32:C34) -> 53901.173 | D35: =SUM(D32:D34) -> 0 | E35: =SUM(C35:D35) -> 53901.173 | H35: =SUM(F35:G35) -> 0 | K35: =SUM(I35:J35) -> 0 | O35: =SUM(M35:N35) -> 0
C37: =C28/(C26+C23+C17+C11) -> 0.085 | D37: 0 | E37: =E28/(E26+E23+E17+E11) -> 0.085 | F37: =F28/(F26+F23+F17+F11) -> 0.085 | G37: 0 | H37: =H28/(H26+H23+H17+H11) -> 0.085 | I37: =I28/(I26+I23+I17+I11) -> 0.085 | J37: 0 | K37: =K28/(K26+K23+K17+K11) -> 0.085 | M37: =M28/(M26+M23+M17+M11) -> 0.085 | N37: 0 | O37: =O28/(O26+O23+O17+O11) -> 0.085
B39: Total Direct Cost for MedPO ORC and Admin | C39: =SUM(C11,C17,C23,C26) -> 18557.278 | D39: =SUM(D11,D17,D23,D26) -> 0 | E39: =SUM(E11,E17,E23,E26) -> 18557.278 | F39: =SUM(F11,F17,F23,F26) -> 21517.222 | G39: =SUM(G11,G17,G23,G26) -> 0 | H39: =SUM(H11,H17,H23,H26) -> 21517.222 | I39: =SUM(I11,I17,I23,I26) -> 9604 | J39: =SUM(J11,J17,J23,J26) -> 0 | K39: =SUM(K11,K17,K23,K26) -> 9604 | M39: =SUM(M11,M17,M23,M26) -> 49678.5 | N39: =SUM(N11,N17,N23,N26) -> 0 | O39: =SUM(O11,O17,O23,O26) -> 49678.5

Sheet B&H 3 years
B1: Project Title: | C1: LifeWeb | D1: New Coalitions for Biodiversity - Developing public-private partnerships within protected areas in five countries of the South East Europe - Budget
B2: Project Activities: | C2: Bosnia & Herzegovina
C5: YEAR 1 - 2011 | F5: YEAR 2 -2012 | I5: YEAR 3 2013 | M5: TOTAL 3 YEARS
B6: Category | C6: Donor | D6: WWF MEDPO | E6: Total | F6: Donor | G6: WWF MEDPO | H6: Total | I6: Donor | J6: WWF MEDPO | K6: Total | M6: Donor | N6: WWF MEDPO | O6: Total
A7: 1 | B7: Project Staff
A8: 1.1 | B8: BP development international support team: Expert 1: 30 month. (Marlen Flores) | C8: =(28443/6)*2 -> 9481 | E8: =SUM(C8:D8) -> 9481 | F8: =(20000/6)*2 -> 6666.6667 | H8: =SUM(F8:G8) -> 6666.6667 | I8: =(20000/6)*2 -> 6666.6667 | K8: =SUM(I8:J8) -> 6666.6667 | M8: =SUM(C8,F8,I8) -> 22814.333 | N8: =SUM(D8,G8,J8) -> 0 | O8: =SUM(M8:N8) -> 22814.333 | P8: Back to MATRA proposal
A9: 1.3 | B9: Ministry focal point (NPCs+Serbian focal point) | C9: 840 | E9: =SUM(C9:D9) -> 840 | H9: =SUM(F9:G9) -> 0 | K9: =SUM(I9:J9) -> 0 | M9: =SUM(C9,F9,I9) -> 840 | N9: =SUM(D9,G9,J9) -> 0 | O9: =SUM(M9:N9) -> 840
A10: 1.5 | B10: PA staff cost (€ 2000 x YEAR x 2 PA) | C10: =(3000/6)*2+(9000/6)*2 -> 4000 | E10: =(12000/6)*2 -> 4000 | F10: =(3000/6)*2+(9000/6)*2 -> 4000 | H10: =(12000/6)*2 -> 4000 | I10: =(3000/6)*2+(9000/6)*2 -> 4000 | K10: =SUM(I10:J10) -> 4000 | M10: =SUM(C10,F10,I10) -> 12000 | N10: =SUM(D10,G10,J10) -> 0 | O10: =SUM(M10:N10) -> 12000
B11: Total 1 | C11: =SUM(C7:C10) -> 14321 | D11: =SUM(D7:D8) -> 0 | E11: =SUM(E7:E10) -> 14321 | F11: =SUM(F7:F10) -> 10666.667 | G11: =SUM(G7:G10) -> 0 | H11: =SUM(H7:H10) -> 10666.667 | I11: =SUM(I7:I10) -> 10666.667 | J11: =SUM(J7:J10) -> 0 | K11: =SUM(K7:K10) -> 10666.667 | M11: =SUM(M7:M10) -> 35654.333 | N11: =SUM(N7:N10) -> 0 | O11: =SUM(O7:O10) -> 35654.333
A12: 2 | B12: Studies, publications and workshops
A13: 2.1 | B13: Twelve Market Studies (2x PA x 1000) | E13: =SUM(C13:D13) -> 0 | F13: =1000*4 -> 4000 | H13: =SUM(F13:G13) -> 4000 | I13: =1000*4 -> 4000 | K13: =SUM(I13:J13) -> 4000 | M13: =SUM(C13,F13,I13) -> 8000 | N13: =SUM(D13,G13,J13) -> 0 | O13: =SUM(M13:N13) -> 8000 | P13: Need more assumptions for estimation
A14: 2.2 | B14: BP development workshops (1 WS x Y x PA) | C14: ='BP Training BiH'!$G$47 -> 3135 | E14: =SUM(C14:D14) -> 3135 | F14: ='BP Training BiH'!$G$47 -> 3135 | H14: =SUM(F14:G14) -> 3135 | K14: =SUM(I14:J14) -> 0 | M14: =SUM(C14,F14,I14) -> 6270 | N14: =SUM(D14,G14,J14) -> 0 | O14: =SUM(M14:N14) -> 6270 | P14: check with old MATRA proposal
A15: 2.4 | B15: Printing of six business plans | E15: =SUM(C15:D15) -> 0 | F15: =(10000/6)*2 -> 3333.3333 | H15: =SUM(F15:G15) -> 3333.3333 | I15: =(10000/6)*2 -> 3333.3333 | K15: =SUM(I15:J15) -> 3333.3333 | M15: =SUM(C15,F15,I15) -> 6666.6667 | N15: =SUM(D15,G15,J15) -> 0 | O15: =SUM(M15:N15) -> 6666.6667
A16: 2.5 | B16: Public launches/visibility events to highlight public-private partnership achievements (2,7) € 6000 (2 events) | E16: =SUM(C16:D16) -> 0 | F16: 6000 | H16: =SUM(F16:G16) -> 6000 | K16: =SUM(I16:J16) -> 0 | M16: =SUM(C16,F16,I16) -> 6000 | N16: =SUM(D16,G16,J16) -> 0 | O16: =SUM(M16:N16) -> 6000
B17: Total 2 | C17: =SUM(C13:C16) -> 3135 | D17: =SUM(D13:D16) -> 0 | E17: =SUM(E13:E16) -> 3135 | F17: =SUM(F13:F16) -> 16468.333 | G17: =SUM(G13:G16) -> 0 | H17: =SUM(H13:H16) -> 16468.333 | I17: =SUM(I13:I16) -> 7333.3333 | J17: =SUM(J13:J16) -> 0 | K17: =SUM(K13:K16) -> 7333.3333 | M17: =SUM(M13:M16) -> 26936.667 | N17: =SUM(N13:N16) -> 0 | O17: =SUM(O13:O16) -> 26936.667
A18: 3 | B18: Travel | I18: =SUM(I15:I17) -> 10666.667 | J18: =SUM(J15:J17) -> 0 | M18: =SUM(C18,F18,I18) -> 10666.667 | N18: =SUM(D18,G18,J18) -> 0
A19: 3.1 | B19: Travel PPP Lead | C19: =((12000/25)*11)/5 -> 1056 | E19: =SUM(C19:D19) -> 1056 | F19: =((12000/25)*12)/5 -> 1152 | H19: =SUM(F19:G19) -> 1152 | I19: =((12000/25)*12)/5 -> 1152 | K19: =SUM(I19:J19) -> 1152 | M19: =SUM(C19,F19,I19) -> 3360 | N19: =SUM(D19,G19,J19) -> 0 | O19: =SUM(M19:N19) -> 3360
A20: 3.1 | B20: Travel BP consultant (international) | C20: =((15000/18*11)/6)*2 -> 3055.5556 | E20: =SUM(C20:D20) -> 3055.5556 | F20: =((15000/18*7)/6)*2 -> 1944.4444 | H20: =SUM(F20:G20) -> 1944.4444 | K20: =SUM(I20:J20) -> 0 | M20: =SUM(C20,F20,I20) -> 5000 | N20: =SUM(D20,G20,J20) -> 0 | O20: =SUM(M20:N20) -> 5000
A21: 3.2 | B21: Travel Regional Project leader (3Xcountry) | C21: =2*500 -> 1000 | E21: =SUM(C21:D21) -> 1000 | F21: =2*500 -> 1000 | H21: =SUM(F21:G21) -> 1000 | I21: =2*500 -> 1000 | K21: =SUM(I21:J21) -> 1000 | M21: =SUM(C21,F21,I21) -> 3000 | N21: =SUM(D21,G21,J21) -> 0 | O21: =SUM(M21:N21) -> 3000
A22: 3.2 | B22: Travel BP development lead local | C22: =((12000/25)*12)/5 -> 1152 | E22: =SUM(C22:D22) -> 1152 | F22: =((12000/25)*12)/5 -> 1152 | H22: =SUM(F22:G22) -> 1152 | I22: =((12000/25)*12)/5 -> 1152 | K22: =SUM(I22:J22) -> 1152 | M22: =SUM(C22,F22,I22) -> 3456 | N22: =SUM(D22,G22,J22) -> 0 | O22: =SUM(M22:N22) -> 3456
B23: Total 3 | C23: =SUM(C19:C22) -> 6263.5556 | D23: =SUM(D19:D22) -> 0 | E23: =SUM(E19:E22) -> 6263.5556 | F23: =SUM(F19:F22) -> 5248.4444 | G23: =SUM(G19:G22) -> 0 | H23: =SUM(H19:H22) -> 5248.4444 | I23: =SUM(I19:I22) -> 3304 | J23: =SUM(J19:J22) -> 0 | K23: =SUM(K19:K22) -> 3304 | M23: =SUM(M19:M22) -> 14816 | N23: =SUM(N19:N22) -> 0 | O23: =SUM(O19:O22) -> 14816
A24: 4 | B24: Local Office Running Costs
B26: Total 4 | C26: =SUM(C25:C25) -> 0 | D26: =SUM(D25:D25) -> 0 | E26: =SUM(E25:E25) -> 0 | F26: =SUM(F25:F25) -> 0 | G26: =SUM(G25:G25) -> 0 | H26: =SUM(H25:H25) -> 0 | I26: =SUM(I25:I25) -> 0 | J26: =SUM(J25:J25) -> 0 | K26: =SUM(K25:K25) -> 0 | M26: =SUM(M25:M25) -> 0 | N26: =SUM(N25:N25) -> 0 | O26: =SUM(O25:O25) -> 0
A28: 5 | B28: Management Fees -8,5% | C28: =C39*0.085 -> 2016.1622 | D28: =D42*0.085 -> 0 | E28: =SUM(C28:D28) -> 2016.1622 | F28: =F39*0.085 -> 2752.5928 | G28: =G42*0.085 -> 0 | H28: =SUM(F28:G28) -> 2752.5928 | I28: =I39*0.085 -> 1810.84 | J28: =J42*0.085 -> 0 | K28: =SUM(I28:J28) -> 1810.84 | M28: =SUM(C28,F28,I28) -> 6579.595 | N28: =SUM(D28,G28,J28) -> 0 | O28: =SUM(M28:N28) -> 6579.595
B30: Total | C30: =SUM(C11,C17,C23,C26,C28) -> 25735.718 | D30: =SUM(D11,D17,D23,D26,D28) -> 0 | E30: =SUM(E11,E17,E23,E26,E28) -> 25735.718 | F30: =SUM(F11,F17,F23,F26,F28) -> 35136.037 | G30: =SUM(G11,G17,G23,G26,G28) -> 0 | H30: =SUM(H11,H17,H23,H26,H28) -> 35136.037 | I30: =SUM(I11,I17,I23,I26,I28) -> 23114.84 | J30: =SUM(J11,J17,J23,J26,J28) -> 0 | K30: =SUM(K11,K17,K23,K26,K28) -> 23114.84 | M30: =SUM(M11,M17,M23,M26,M28) -> 83986.595 | N30: =SUM(N11,N17,N23,N26,N28) -> 0 | O30: =SUM(O11,O17,O23,O26,O28) -> 83986.595
C31: Donor | D31: WWF MedPO | E31: Total
B32: Year 1 | C32: =SUM(+C23+C17+C11+C26+C28) -> 25735.718 | D32: =SUM(+D23+D17+D11+D26+D28) -> 0 | E32: =SUM(C32:D32) -> 25735.718 | H32: =SUM(F32:G32) -> 0 | K32: =SUM(I32:J32) -> 0 | O32: =SUM(M32:N32) -> 0
B33: Year 2 | C33: =SUM(F26+F23+F17+F11+F28) -> 35136.037 | D33: =SUM(G26+G23+G17+G11+G28) -> 0 | E33: =SUM(C33:D33) -> 35136.037 | H33: =SUM(F33:G33) -> 0 | K33: =SUM(I33:J33) -> 0 | O33: =SUM(M33:N33) -> 0
B34: Year 3 | C34: =SUM(I26+I23+I17+I11+I28) -> 23114.84 | D34: =SUM(J26+J23+J17+J11+J28) -> 0 | E34: =SUM(C34:D34) -> 23114.84 | H34: =SUM(F34:G34) -> 0 | K34: =SUM(I34:J34) -> 0 | O34: =SUM(M34:N34) -> 0
B35: Total 3 years | C35: =SUM(C32:C34) -> 83986.595 | D35: =SUM(D32:D34) -> 0 | E35: =SUM(C35:D35) -> 83986.595 | H35: =SUM(F35:G35) -> 0 | K35: =SUM(I35:J35) -> 0 | O35: =SUM(M35:N35) -> 0
C37: =C28/(C26+C23+C17+C11) -> 0.085 | D37: 0 | E37: =E28/(E26+E23+E17+E11) -> 0.085 | F37: =F28/(F26+F23+F17+F11) -> 0.085 | G37: 0 | H37: =H28/(H26+H23+H17+H11) -> 0.085 | I37: =I28/(I26+I23+I17+I11) -> 0.085 | J37: 0 | K37: =K28/(K26+K23+K17+K11) -> 0.085 | M37: =M28/(M26+M23+M17+M11) -> 0.085 | N37: 0 | O37: =O28/(O26+O23+O17+O11) -> 0.085
B39: Total Direct Cost for MedPO ORC and Admin | C39: =SUM(C11,C17,C23,C26) -> 23719.556 | D39: =D49*0.075 -> 0 | E39: =SUM(E11,E17,E23,E26) -> 23719.556 | F39: =SUM(F11,F17,F23,F26) -> 32383.444 | G39: =SUM(G11,G17,G23,G26) -> 0 | H39: =SUM(H11,H17,H23,H26) -> 32383.444 | I39: =SUM(I11,I17,I23,I26) -> 21304 | J39: =SUM(J11,J17,J23,J26) -> 0 | K39: =SUM(K11,K17,K23,K26) -> 21304 | M39: =SUM(M11,M17,M23,M26) -> 77407 | N39: =SUM(N11,N17,N23,N26) -> 0 | O39: =SUM(O11,O17,O23,O26) -> 77407

Sheet SERBIA 3 years
B1: Project Title: | C1: LifeWeb | D1: New Coalitions for Biodiversity - Developing public-private partnerships within protected areas in five countries of the South East Europe - Budget
B2: Project Activities: | C2: SERBIA
C5: YEAR 1 - 2011 | F5: YEAR 2 -2012 | I5: YEAR 3 2013 | M5: TOTAL 3 YEARS
B6: Category | C6: Donor | D6: WWF MEDPO | E6: Total | F6: Donor | G6: WWF MEDPO | H6: Total | I6: Donor | J6: WWF MEDPO | K6: Total | M6: Donor | N6: WWF MEDPO | O6: Total
A7: 1 | B7: Project Staff
A8: 1.1 | B8: BP development international support team: Expert 1: 30 month. (Marlen Flores) | C8: =(28443/6)*1 -> 4740.5 | E8: =SUM(C8:D8) -> 4740.5 | F8: =(20000/6)*1 -> 3333.3333 | H8: =SUM(F8:G8) -> 3333.3333 | I8: =(20000/6)*1 -> 3333.3333 | K8: =SUM(I8:J8) -> 3333.3333 | M8: =SUM(C8,F8,I8) -> 11407.167 | N8: =SUM(D8,G8,J8) -> 0 | O8: =SUM(M8:N8) -> 11407.167 | P8: Back to MATRA proposal
A9: 1.3 | B9: Ministry focal point (NPCs+Serbian focal point) | C9: =4200/5 -> 840 | E9: =SUM(C9:D9) -> 840 | F9: 2000 | H9: =SUM(F9:G9) -> 2000 | K9: =SUM(I9:J9) -> 0 | M9: =SUM(C9,F9,I9) -> 2840 | N9: =SUM(D9,G9,J9) -> 0 | O9: =SUM(M9:N9) -> 2840
A10: 1.5 | B10: PA staff cost (€ 2000 x YEAR) | C10: =(3000/6)*1+(9000/6)*1 -> 2000 | E10: =SUM(C10:D10) -> 2000 | F10: =(12000/6)*1 -> 2000 | H10: =SUM(F10:G10) -> 2000 | I10: =(12000/6)*1 -> 2000 | K10: =SUM(I10:J10) -> 2000 | M10: =SUM(C10,F10,I10) -> 6000 | N10: =SUM(D10,G10,J10) -> 0 | O10: =SUM(M10:N10) -> 6000
B11: Total 1 | C11: =SUM(C7:C10) -> 7580.5 | D11: =SUM(D7:D10) -> 0 | E11: =SUM(E7:E10) -> 7580.5 | F11: =SUM(F7:F10) -> 7333.3333 | G11: =SUM(G7:G10) -> 0 | H11: =SUM(H7:H10) -> 7333.3333 | I11: =SUM(I7:I10) -> 5333.3333 | J11: =SUM(J7:J10) -> 0 | K11: =SUM(K7:K10) -> 5333.3333 | M11: =SUM(M7:M10) -> 20247.167 | N11: =SUM(N7:N10) -> 0 | O11: =SUM(O7:O10) -> 20247.167
A12: 2 | B12: Studies, publications and workshops
A13: 2.1 | B13: Twelve Market Studies (2x PA x 1000) | E13: =SUM(C13:D13) -> 0 | F13: =1000*2 -> 2000 | H13: =SUM(F13:G13) -> 2000 | I13: =1000*2 -> 2000 | K13: =SUM(I13:J13) -> 2000 | M13: =SUM(C13,F13,I13) -> 4000 | N13: =SUM(D13,G13,J13) -> 0 | O13: =SUM(M13:N13) -> 4000 | P13: Need more assumptions for estimation
A14: 2.2 | B14: BP development workshops (1 WS x Y x PA) | C14: ='BP Training Serbia'!$G$47 -> 3794 | E14: =SUM(C14:D14) -> 3794 | F14: ='BP Training Serbia'!$G$47 -> 3794 | H14: =SUM(F14:G14) -> 3794 | K14: =SUM(I14:J14) -> 0 | M14: =SUM(C14,F14,I14) -> 7588 | N14: =SUM(D14,G14,J14) -> 0 | O14: =SUM(M14:N14) -> 7588 | P14: check with old MATRA proposal
A15: 2.4 | B15: Printing of six business plans | E15: =SUM(C15:D15) -> 0 | F15: =(10000/6)*1 -> 1666.6667 | H15: =SUM(F15:G15) -> 1666.6667 | I15: =(10000/6)*1 -> 1666.6667 | K15: =SUM(I15:J15) -> 1666.6667 | M15: =SUM(C15,F15,I15) -> 3333.3333 | N15: =SUM(D15,G15,J15) -> 0 | O15: =SUM(M15:N15) -> 3333.3333
A16: 2.5 | B16: Public launches/visibility events to highlight public-private partnership achievements (2,7) € 4000 x country | E16: =SUM(C16:D16) -> 0 | F16: 4000 | H16: =SUM(F16:G16) -> 4000 | K16: =SUM(I16:J16) -> 0 | M16: =SUM(C16,F16,I16) -> 4000 | N16: =SUM(D16,G16,J16) -> 0 | O16: =SUM(M16:N16) -> 4000
B17: Total 2 | C17: =SUM(C13:C16) -> 3794 | D17: =SUM(D13:D16) -> 0 | E17: =SUM(E13:E16) -> 3794 | F17: =SUM(F13:F16) -> 11460.667 | G17: =SUM(G13:G16) -> 0 | H17: =SUM(H13:H16) -> 11460.667 | I17: =SUM(I13:I16) -> 3666.6667 | J17: =SUM(J13:J16) -> 0 | K17: =SUM(K13:K16) -> 3666.6667 | M17: =SUM(M13:M16) -> 18921.333 | N17: =SUM(N13:N16) -> 0 | O17: =SUM(O13:O16) -> 18921.333
A18: 3 | B18: Travel | I18: =SUM(I15:I17) -> 5333.3333 | J18: =SUM(J15:J17) -> 0 | M18: =SUM(C18,F18,I18) -> 5333.3333 | N18: =SUM(D18,G18,J18) -> 0
A19: 3.1 | B19: Travel PPP Lead | C19: =((12000/25)*11)/5 -> 1056 | E19: =SUM(C19:D19) -> 1056 | F19: =((12000/25)*12)/5 -> 1152 | H19: =SUM(F19:G19) -> 1152 | I19: =((12000/25)*12)/5 -> 1152 | K19: =SUM(I19:J19) -> 1152 | M19: =SUM(C19,F19,I19) -> 3360 | N19: =SUM(D19,G19,J19) -> 0 | O19: =SUM(M19:N19) -> 3360
A20: 3.1 | B20: Travel BP consultant (international) | C20: =(15000/18*11)/6 -> 1527.7778 | E20: =SUM(C20:D20) -> 1527.7778 | F20: =(15000/18*7)/6 -> 972.22222 | H20: =SUM(F20:G20) -> 972.22222 | K20: =SUM(I20:J20) -> 0 | M20: =SUM(C20,F20,I20) -> 2500 | N20: =SUM(D20,G20,J20) -> 0 | O20: =SUM(M20:N20) -> 2500
A21: 3.2 | B21: Travel Regional Project leader (3Xcountry) | C21: =1*500 -> 500 | E21: =SUM(C21:D21) -> 500 | F21: =1*500 -> 500 | H21: =SUM(F21:G21) -> 500 | I21: =1*500 -> 500 | K21: =SUM(I21:J21) -> 500 | M21: =SUM(C21,F21,I21) -> 1500 | N21: =SUM(D21,G21,J21) -> 0 | O21: =SUM(M21:N21) -> 1500
A22: 3.2 | B22: Travel BP development lead local | C22: =((12000/25)*12)/5 -> 1152 | E22: =SUM(C22:D22) -> 1152 | F22: =((12000/25)*12)/5 -> 1152 | H22: =SUM(F22:G22) -> 1152 | I22: =((12000/25)*12)/5 -> 1152 | K22: =SUM(I22:J22) -> 1152 | M22: =SUM(C22,F22,I22) -> 3456 | N22: =SUM(D22,G22,J22) -> 0 | O22: =SUM(M22:N22) -> 3456
B23: Total 3 | C23: =SUM(C19:C22) -> 4235.7778 | D23: =SUM(D19:D22) -> 0 | E23: =SUM(E19:E22) -> 4235.7778 | F23: =SUM(F19:F22) -> 3776.2222 | G23: =SUM(G19:G22) -> 0 | H23: =SUM(H19:H22) -> 3776.2222 | I23: =SUM(I19:I22) -> 2804 | J23: =SUM(J19:J22) -> 0 | K23: =SUM(K19:K22) -> 2804 | M23: =SUM(M19:M22) -> 10816 | N23: =SUM(N19:N22) -> 0 | O23: =SUM(O19:O22) -> 10816
A24: 4 | B24: Local Office Running Costs
B26: Total 4 | C26: =SUM(C25:C25) -> 0 | D26: =SUM(D25:D25) -> 0 | E26: =SUM(E25:E25) -> 0 | F26: =SUM(F25:F25) -> 0 | G26: =SUM(G25:G25) -> 0 | H26: =SUM(H25:H25) -> 0 | I26: =SUM(I25:I25) -> 0 | J26: =SUM(J25:J25) -> 0 | K26: =SUM(K25:K25) -> 0 | M26: =SUM(M25:M25) -> 0 | N26: =SUM(N25:N25) -> 0 | O26: =SUM(O25:O25) -> 0
A28: 5 | B28: Management Fees -8,5% | C28: =C39*0.085 -> 1326.8736 | D28: =D42*0.085 -> 0 | E28: =SUM(C28:D28) -> 1326.8736 | F28: =F39*0.085 -> 1918.4689 | G28: =G42*0.085 -> 0 | H28: =SUM(F28:G28) -> 1918.4689 | I28: =I39*0.085 -> 1003.34 | J28: =J42*0.085 -> 0 | K28: =SUM(I28:J28) -> 1003.34 | M28: =SUM(C28,F28,I28) -> 4248.6825 | N28: =SUM(D28,G28,J28) -> 0 | O28: =SUM(M28:N28) -> 4248.6825
B30: Total | C30: =SUM(C11,C17,C23,C26,C28) -> 16937.151 | D30: =SUM(D11,D17,D23,D26,D28) -> 0 | E30: =SUM(E11,E17,E23,E26,E28) -> 16937.151 | F30: =SUM(F11,F17,F23,F26,F28) -> 24488.691 | G30: =SUM(G11,G17,G23,G26,G28) -> 0 | H30: =SUM(H11,H17,H23,H26,H28) -> 24488.691 | I30: =SUM(I11,I17,I23,I26,I28) -> 12807.34 | J30: =SUM(J11,J17,J23,J26,J28) -> 0 | K30: =SUM(K11,K17,K23,K26,K28) -> 12807.34 | M30: =SUM(M11,M17,M23,M26,M28) -> 54233.183 | N30: =SUM(N11,N17,N23,N26,N28) -> 0 | O30: =SUM(O11,O17,O23,O26,O28) -> 54233.183
C31: Donor | D31: WWF MedPO | E31: Total
B32: Year 1 | C32: =SUM(+C23+C17+C11+C26+C28) -> 16937.151 | D32: =SUM(+D23+D17+D11+D26+D28) -> 0 | E32: =SUM(C32:D32) -> 16937.151 | H32: =SUM(F32:G32) -> 0 | K32: =SUM(I32:J32) -> 0 | O32: =SUM(M32:N32) -> 0
B33: Year 2 | C33: =SUM(F26+F23+F17+F11+F28) -> 24488.691 | D33: =SUM(G26+G23+G17+G11+G28) -> 0 | E33: =SUM(C33:D33) -> 24488.691 | H33: =SUM(F33:G33) -> 0 | K33: =SUM(I33:J33) -> 0 | O33: =SUM(M33:N33) -> 0
B34: Year 3 | C34: =SUM(I26+I23+I17+I11+I28) -> 12807.34 | D34: =SUM(J26+J23+J17+J11+J28) -> 0 | E34: =SUM(C34:D34) -> 12807.34 | H34: =SUM(F34:G34) -> 0 | K34: =SUM(I34:J34) -> 0 | O34: =SUM(M34:N34) -> 0
B35: Total 3 years | C35: =SUM(C32:C34) -> 54233.182 | D35: =SUM(D32:D34) -> 0 | E35: =SUM(C35:D35) -> 54233.182 | H35: =SUM(F35:G35) -> 0 | K35: =SUM(I35:J35) -> 0 | O35: =SUM(M35:N35) -> 0
C37: =C28/(C26+C23+C17+C11) -> 0.085 | D37: 0 | E37: =E28/(E26+E23+E17+E11) -> 0.085 | F37: =F28/(F26+F23+F17+F11) -> 0.085 | G37: 0 | H37: =H28/(H26+H23+H17+H11) -> 0.085 | I37: =I28/(I26+I23+I17+I11) -> 0.085 | J37: 0 | K37: =K28/(K26+K23+K17+K11) -> 0.085 | M37: =M28/(M26+M23+M17+M11) -> 0.085 | N37: 0 | O37: =O28/(O26+O23+O17+O11) -> 0.085
B39: Total Direct Cost for MedPO ORC and Admin | C39: =SUM(C11,C17,C23,C26) -> 15610.278 | D39: =D49*0.075 -> 0 | E39: =SUM(E11,E17,E23,E26) -> 15610.278 | F39: =SUM(F11,F17,F23,F26) -> 22570.222 | G39: =SUM(G11,G17,G23,G26) -> 0 | H39: =SUM(H11,H17,H23,H26) -> 22570.222 | I39: =SUM(I11,I17,I23,I26) -> 11804 | J39: =SUM(J11,J17,J23,J26) -> 0 | K39: =SUM(K11,K17,K23,K26) -> 11804 | M39: =SUM(M11,M17,M23,M26) -> 49984.5 | N39: =SUM(N11,N17,N23,N26) -> 0 | O39: =SUM(O11,O17,O23,O26) -> 49984.5

Sheet MONTENEGRO 3 years
B1: Project Title: | C1: LifeWeb | D1: New Coalitions for Biodiversity - Developing public-private partnerships within protected areas in five countries of the South East Europe - Budget
B2: Project Activities: | C2: MONTENEGRO
C5: YEAR 1 - 2011 | F5: YEAR 2 -2012 | I5: YEAR 3 2013 | M5: TOTAL 3 YEARS
B6: Category | C6: Donor | D6: WWF MEDPO | E6: Total | F6: Donor | G6: WWF MEDPO | H6: Total | I6: Donor | J6: WWF MEDPO | K6: Total | M6: Donor | N6: WWF MEDPO | O6: Total
A7: 1 | B7: Project Staff
A8: 1.1 | B8: BP development international support team: Expert 1: 30 month. (Marlen Flores) | C8: =(28443/6)*1 -> 4740.5 | E8: =SUM(C8:D8) -> 4740.5 | F8: =(20000/6)*1 -> 3333.3333 | H8: =SUM(F8:G8) -> 3333.3333 | I8: =(20000/6)*1 -> 3333.3333 | K8: =SUM(I8:J8) -> 3333.3333 | M8: =SUM(C8,F8,I8) -> 11407.167 | N8: =SUM(D8,G8,J8) -> 0 | O8: =SUM(M8:N8) -> 11407.167 | P8: Back to MATRA proposal
A9: 1.3 | B9: Ministry focal point (NPCs+Serbian focal point) | C9: =4200/5 -> 840 | E9: =SUM(C9:D9) -> 840 | H9: =SUM(F9:G9) -> 0 | K9: =SUM(I9:J9) -> 0 | M9: =SUM(C9,F9,I9) -> 840 | N9: =SUM(D9,G9,J9) -> 0 | O9: =SUM(M9:N9) -> 840
A10: 1.5 | B10: PA staff cost (€ 2000 x YEAR) | C10: =(3000/6)*1+(9000/6)*1 -> 2000 | E10: =SUM(C10:D10) -> 2000 | F10: =(12000/6)*1 -> 2000 | H10: =SUM(F10:G10) -> 2000 | I10: =(12000/6)*1 -> 2000 | K10: =SUM(I10:J10) -> 2000 | M10: =SUM(C10,F10,I10) -> 6000 | N10: =SUM(D10,G10,J10) -> 0 | O10: =SUM(M10:N10) -> 6000
B11: Total 1 | C11: =SUM(C7:C10) -> 7580.5 | D11: =SUM(D7:D10) -> 0 | E11: =SUM(E7:E10) -> 7580.5 | F11: =SUM(F7:F10) -> 5333.3333 | G11: =SUM(G7:G10) -> 0 | H11: =SUM(H7:H10) -> 5333.3333 | I11: =SUM(I7:I10) -> 5333.3333 | J11: =SUM(J7:J10) -> 0 | K11: =SUM(K7:K10) -> 5333.3333 | M11: =SUM(M7:M10) -> 18247.167 | N11: =SUM(N7:N10) -> 0 | O11: =SUM(O7:O10) -> 18247.167
A12: 2 | B12: Studies, publications and workshops
A13: 2.1 | B13: Twelve Market Studies (2x PA x 1000) | E13: =SUM(C13:D13) -> 0 | F13: =1000*2 -> 2000 | H13: =SUM(F13:G13) -> 2000 | I13: =1000*2 -> 2000 | K13: =SUM(I13:J13) -> 2000 | M13: =SUM(C13,F13,I13) -> 4000 | N13: =SUM(D13,G13,J13) -> 0 | O13: =SUM(M13:N13) -> 4000 | P13: Need more assumptions for estimation
