Workbook

Sheet Intro
B3: Q6 Final Proposals - Opex - HAL
B4: The spreadsheet contains analysis underpinning the CAA's final proposal opex allowance for HAL over Q6.
B5: Owner: Duncan Kernohan
B6: duncan.kernohan@caa.co.uk
B7: t: 020 7453 6210
B9: Grey denotes input cell. These cells are used to denote input data from consultancy reports and other external sources.
B10: Green text denotes cells containing parameters. These cells are usually used to include or exclude certain factors from the final proposals or to convert from a nominal to real price base.

Sheet Reg>>

Sheet HAL - Reg
B2: Heathrow - CAA Allowance | O2: Heathrow - Outturn
B4: Regulatory Accounts | C4: Q4 | F4: Q5 | K4: Q5+1 | O4: Regulatory Accounts | P4: Q4 | S4: Q5 | X4: Q5+1
B5: £m nominal | C5: 2005/06 | D5: 2006/07 | E5: 2007/08 | F5: 2008/09 | G5: 2009/10 | H5: 2010/11 | I5: 2011/12 | J5: 2012/13 | K5: 2013/14 | M5: CAGR (Q5) | O5: £m nominal | P5: 2005/06 | Q5: 2006/07 | R5: 2007/08 | S5: 2008/09 | T5: 2009/10 | U5: 2010/11 | V5: 2011/12 | W5: 2012/13 | X5: 2013/14 | Z5: CAGR (Q5)
B6: Terminal Pax | C6: =69900 -> 69900 | D6: 70300 | E6: 70700 | F6: 70400 | G6: 72500 | H6: 74500 | I6: 76200 | J6: 78200 | M6: =((J6/F6)^(1/4))-1 -> 0.02661717 | O6: Terminal Pax | P6: 67421 | Q6: 67305 | R6: 67951 | S6: 65929 | T6: 66133 | U6: 66111 | V6: 70099 | W6: 70332 | Z6: =((W6/S6)^(1/4))-1 -> 0.016293434
B7: Net Revenue from Airport Charges | C7: 543.6 | D7: 603.1 | E7: 671.7 | F7: 927.7 | G7: 1029.2 | H7: 1193.5 | I7: 1372.9 | J7: 1558.8 | M7: =((J7/F7)^(1/4))-1 -> 0.13853323 | O7: Net Revenue from Airport Charges | P7: 532.2 | Q7: 579.6 | R7: 639.7 | S7: 886.8 | T7: 955.4 | U7: 997.5 | V7: 1178.6 | W7: 1295.9 | Z7: =((W7/S7)^(1/4))-1 -> 0.099477766
B8: Other Revenue | C8: 569.6 | D8: 595.7 | E8: 624.7 | F8: 720.8 | G8: 745.8 | H8: 805.1 | I8: 856.3 | J8: 908.6 | M8: =((J8/F8)^(1/4))-1 -> 0.059593996 | O8: Other Revenue | P8: 608.9 | Q8: 616.3 | R8: 638.5 | S8: 742.9 | T8: 787.5 | U8: 856.1 | V8: 895.5 | W8: 929.5 | Z8: =((W8/S8)^(1/4))-1 -> 0.057620253
B9: Total Revenue | C9: 1113.2 | D9: 198.8 | E9: 1296.4 | F9: 1648.5 | G9: 1775 | H9: 1998.6 | I9: 2229.2 | J9: 2467.5 | M9: =((J9/F9)^(1/4))-1 -> 0.10609404 | O9: Total Revenue | P9: 1141.1 | Q9: 1195.9 | R9: 1278.2 | S9: 1629.7 | T9: 1742.9 | U9: 1853.6 | V9: 2074.1 | W9: 2225.4 | Z9: =((W9/S9)^(1/4))-1 -> 0.080998533
B10: Operating Costs | C10: 490.7 | D10: 511.9 | E10: 541.5 | F10: 876 | G10: 865.4 | H10: 912.6 | I10: 962.4 | J10: 1000.2 | M10: =((J10/F10)^(1/4))-1 -> 0.033702784 | O10: Operating Costs | P10: 554.1 | Q10: 599.8 | R10: 772.7 | S10: 969 | T10: 956.5 | U10: 950.5 | V10: 1001 | W10: 1027.7 | Z10: =((W10/S10)^(1/4))-1 -> 0.014812119
B11: Assumed Ordinary Depreciation | C11: 184.7 | D11: 196.9 | E11: 218.5 | F11: 421.1 | G11: 434 | H11: 480.1 | I11: 517.4 | J11: 572.6 | M11: =((J11/F11)^(1/4))-1 -> 0.07985769 | O11: Assumed Ordinary Depreciation | P11: 184.7 | Q11: 196.9 | R11: 218.5 | S11: 421.1 | T11: 434 | U11: 480.1 | V11: 517.4 | W11: 572.6 | Z11: =((W11/S11)^(1/4))-1 -> 0.07985769
B12: Total Expenditure | C12: 675.4 | D12: 708.8 | E12: 760 | F12: 1297.1 | G12: 1229.4 | H12: 1392.7 | I12: 1479.8 | J12: 1572.8 | M12: =((J12/F12)^(1/4))-1 -> 0.04936122 | O12: Total Expenditure | P12: 738.8 | Q12: 796.7 | R12: 991.2 | S12: 1390.1 | T12: 1390.5 | U12: 1430.6 | V12: 1518.4 | W12: 1600.3 | Z12: =((W12/S12)^(1/4))-1 -> 0.035830848
B14: Regulatory Operating Profit (Before Exceptional) | C14: 437.8 | D14: 490 | E14: 536.4 | F14: 351.4 | G14: 475.6 | H14: 605.9 | I14: 749.4 | J14: 894.7 | M14: =((J14/F14)^(1/4))-1 -> 0.2631907 | O14: Regulatory Operating Profit (Before Exceptional) | P14: 402.3 | Q14: 399.2 | R14: 287 | S14: 239.6 | T14: 352.4 | U14: 423 | V14: 555.7 | W14: 625.1 | Z14: =((W14/S14)^(1/4))-1 -> 0.27091256
B15: Exceptional | C15: 0 | D15: 0 | E15: 0 | F15: 0 | G15: 0 | H15: 0 | I15: 0 | J15: 0 | O15: Exceptional | P15: 0 | Q15: 0 | R15: 0 | S15: 0 | T15: 197.4 | U15: -115.3 | V15: 158.9 | W15: 62
B16: Regulatory Operating Profit | C16: 437.8 | D16: 490 | E16: 536.4 | F16: =F14-F15 -> 351.4 | G16: =G14-G15 -> 475.6 | H16: =H14-H15 -> 605.9 | I16: =I14-I15 -> 749.4 | J16: 894.7 | M16: =((J16/F16)^(1/4))-1 -> 0.2631907 | O16: Regulatory Operating Profit | P16: 402.3 | Q16: 399.2 | R16: 287 | S16: 239.6 | T16: 155 | U16: =U14-U15 -> 538.3 | V16: 396.8 | W16: 563.1 | Z16: =((W16/S16)^(1/4))-1 -> 0.23815404
B18: Capital Expenditure | C18: 1069 | D18: 931.3 | E18: 975.8 | F18: 1099.6 | G18: 1234.5 | H18: 1150 | I18: 1008.5 | J18: 680.4 | M18: =((J18/F18)^(1/4))-1 -> -0.1130842 | O18: Capital Expenditure | P18: 1304.5 | Q18: 1051.2 | R18: 894 | S18: 739.9 | T18: 804.3 | U18: 812 | V18: 963.5 | W18: 1209.6 | Z18: =((W18/S18)^(1/4))-1 -> 0.13075154
B20: Opening Basic RAB | C20: 6006.3 | D20: 7041.2 | E20: 8130 | F20: 9232.6 | G20: 10096.7 | H20: 11539.1 | I20: 12973.9 | J20: 13996.3 | M20: =((J20/F20)^(1/4))-1 -> 0.10961497 | O20: Opening Basic RAB | P20: 6327.5 | Q20: 7596.6 | R20: 8834.2 | S20: 9232.6 | T20: 9742.9 | U20: 10728.5 | V20: 11773 | W20: 12705.3 | Z20: =((W20/S20)^(1/4))-1 -> 0.083091696
B22: Closing Basic RAB | C22: 7041.2 | D22: 8130 | E22: 9776.3 | F22: 10096.7 | G22: 11539.1 | H22: 12973.9 | I22: 13996.3 | J22: 14523.4 | M22: =((J22/F22)^(1/4))-1 -> 0.09514648 | O22: Closing Basic RAB | P22: 7596.6 | Q22: 8834.2 | R22: 9776.3 | S22: 9742.9 | T22: 10728.5 | U22: 11773 | V22: 12705.3 | W22: 13727.9 | Z22: =((W22/S22)^(1/4))-1 -> 0.089504342
B24: Weighted average basic RAB | C24: 6514.1 | D24: 7575.4 | E24: 8937.8 | F24: 9664.7 | G24: 10817.9 | H24: 12256.5 | I24: 13485.1 | J24: 14259.9 | M24: =((J24/F24)^(1/4))-1 -> 0.10212797 | O24: Weighted average basic RAB | P24: 6950.2 | Q24: 8203.8 | R24: 9296.5 | S24: 9487.8 | T24: 10235.7 | U24: 11250.7 | V24: 12239.1 | W24: 13216.6 | Z24: =((W24/S24)^(1/4))-1 -> 0.086396996
B26: Return on weighted average basic RAB (pre-exceptional) (%) | C26: 6.7 | D26: 6.5 | E26: 6 | F26: 3.6 | G26: 4.4 | H26: 4.9 | I26: 5.6 | J26: 6.3 | M26: =((J26/F26)^(1/4))-1 -> 0.15016332 | O26: Return on weighted average basic RAB (pre-exceptional) (%) | P26: 5.8 | Q26: 4.9 | R26: 3.1 | S26: 2.5 | T26: 3.4 | U26: 3.8 | V26: 4.5 | W26: 4.7 | Z26: =((W26/S26)^(1/4))-1 -> 0.170953
B28: Return on weighted average basic RAB (%) | C28: 6.7 | D28: 6.5 | E28: 6 | F28: 3.6 | G28: 4.4 | H28: 4.9 | I28: 5.6 | J28: 6.3 | M28: =((J28/F28)^(1/4))-1 -> 0.15016332 | O28: Return on weighted average basic RAB (%) | P28: 5.8 | Q28: 4.9 | R28: 3.1 | S28: 2.5 | T28: 1.5 | U28: 4.8 | V28: 3.2 | W28: 4.3 | Z28: =((W28/S28)^(1/4))-1 -> 0.14520204
B30: Breakdown of Operating Costs - CAA Projections | C30: Q4 | F30: Q5 | K30: Q5+1 | O30: Breakdown of Operating Costs | P30: Q4 | S30: Q5 | X30: Q5+1
B31: £m nominal | C31: 2005/06 | D31: 2006/07 | E31: 2007/08 | F31: 2008/09 | G31: 2009/10 | H31: 2010/11 | I31: 2011/12 | J31: 2012/13 | K31: 2013/14 | M31: CAGR (Q5) | O31: £m nominal | P31: 2005/06 | Q31: 2006/07 | R31: 2007/08 | S31: 2008/09 | T31: 2009/10 | U31: 2010/11 | V31: 2011/12 | W31: 2012/13 | X31: 2013/14 | Z31: CAGR (Q5)
B32: Staff Costs | F32: =249.7 -> 249.7 | G32: =244.6 -> 244.6 | H32: 253.2 | I32: 261.5 | J32: =[1]Sheet1!H11/1000 -> 267.78725 | K32: 267.4 | M32: =((J32/F32)^(1/4))-1 -> 0.017636883 | O32: Staff Costs | S32: 262 | T32: 231.5 | U32: 247 | V32: 270.4 | W32: 328.4 | Z32: =((W32/S32)^(1/4))-1 -> 0.058096954
B33: Maintenance and equipment costs | F33: 72.1 | G33: 106.4 | H33: 111.4 | I33: 115.3 | J33: =[1]Sheet1!H12/1000 -> 117.97343 | K33: 124.1 | M33: =((J33/F33)^(1/4))-1 -> 0.13099905 | O33: Maintenance and equipment costs | S33: 116.6 | T33: 121.3 | U33: 105.1 | V33: 118 | W33: 126.9 | Z33: =((W33/S33)^(1/4))-1 -> 0.021388039
B34: Rent and rates | F34: 98 | G34: 97.7 | H34: 103.1 | I34: 109.3 | J34: =[1]Sheet1!H13/1000 -> 119.16631 | K34: 119.4 | M34: =((J34/F34)^(1/4))-1 -> 0.050102888 | O34: Rent and rates | S34: 104.1 | T34: 110.6 | U34: 104.2 | V34: 116.9 | W34: 128.6 | Z34: =((W34/S34)^(1/4))-1 -> 0.054259589
B35: Utility costs | F35: 91.3 | G35: 92.9 | H35: 102.4 | I35: 110.6 | J35: =[1]Sheet1!H14/1000 -> 122.32067 | K35: 122.5 | M35: =((J35/F35)^(1/4))-1 -> 0.075863724 | O35: Utility costs | S35: 83.7 | T35: 107.9 | U35: 92.7 | V35: 89.4 | W35: 86.8 | Z35: =((W35/S35)^(1/4))-1 -> 0.009133368
B36: Police costs | F36: 33.1 | G36: 35.1 | H36: 36.4 | I36: 38.9 | J36: =[1]Sheet1!H15/1000 -> 39.79575 | K36: 39.8 | M36: =((J36/F36)^(1/4))-1 -> 0.047133791 | O36: Police costs | S36: 33.6 | T36: 31.4 | U36: 28.1 | V36: 28.8 | W36: 28.3 | Z36: =((W36/S36)^(1/4))-1 -> -0.042008205
B37: Rail costs | F37: 54.2 | G37: 55.3 | H37: 59.1 | I37: 63.3 | J37: =[1]Sheet1!H16/1000 -> 67.531568 | K37: 67.6 | M37: =((J37/F37)^(1/4))-1 -> 0.056517967 | O37: Rail costs | S37: 52.2 | T37: 54.3 | U37: 57.2 | V37: 58.9 | W37: 59.1 | Z37: =((W37/S37)^(1/4))-1 -> 0.03152378
B38: Other costs | F38: 176 | G38: 129.9 | H38: 139.2 | I38: 152 | J38: =[1]Sheet1!H17/1000 -> 149.82851 | K38: 145 | M38: =((J38/F38)^(1/4))-1 -> -0.03944895 | O38: Other costs | S38: 149.3 | T38: 165.2 | U38: 148.6 | V38: 149.4 | W38: 154.2 | Z38: =((W38/S38)^(1/4))-1 -> 0.0081058652
B39: Intragroup costs | F39: 101.6 | G39: 103.5 | H39: 107.8 | I39: 111.5 | J39: =[1]Sheet1!H18/1000 -> 114.2368 | K39: 114.4 | M39: =((J39/F39)^(1/4))-1 -> 0.029741189 | O39: Intragroup costs | S39: 151.4 | T39: 137.6 | U39: 168.3 | V39: 172.6 | W39: 127.1 | Z39: =((W39/S39)^(1/4))-1 -> -0.042795087
B41: Total operating costs | F41: 876 | G41: 865.4 | H41: 912.6 | I41: 962.4 | J41: =SUM(J32:J39) -> 998.6403 | K41: 1000.2 | M41: =((J41/F41)^(1/4))-1 -> 0.033299562 | O41: Total operating costs | S41: 952.9 | T41: 959.8 | U41: 951.2 | V41: 1004.4 | W41: 1039.5 | Z41: =((W41/S41)^(1/4))-1 -> 0.021984459
B43: Exceptional operating costs | F43: 0 | G43: 0 | H43: 0 | I43: 0 | J43: 0 | K43: 0 | O43: Exceptional operating costs | S43: 25.5 | T43: 0 | U43: 0 | V43: 0 | W43: 0 | Z43: =((W43/S43)^(1/4))-1 -> -1
B44: Service Quality Rebates | F44: 0 | G44: 0 | H44: 0 | I44: 0 | J44: 0 | K44: 0 | O44: Service Quality Rebates | S44: -9.4 | T44: -3.3 | U44: -0.7 | V44: -3.4 | W44: -11.8 | Z44: =((W44/S44)^(1/4))-1 -> 0.058494336
B46: Adjusted operating costs | F46: =F41-F43-F44 -> 876 | G46: =G41-G43-G44 -> 865.4 | H46: =H41-H43-H44 -> 912.6 | I46: =I41-I43-I44 -> 962.4 | J46: =J41-J43-J44 -> 998.6403 | K46: 1000 | M46: =((J46/F46)^(1/4))-1 -> 0.033299562 | O46: Adjusted operating costs | S46: =S41+S43+S44 -> 969 | T46: =T41+T43+T44 -> 956.5 | U46: =U41+U43+U44 -> 950.5 | V46: =V41+V43+V44 -> 1001 | W46: =W10 -> 1027.7 | Z46: =((W46/S46)^(1/4))-1 -> 0.014812119
B49: Price Base Conversion to 2011/12 | C49: =RPI!$T$103/RPI!$T97 -> 1.2290597 | D49: =RPI!$T$103/RPI!$T98 -> 1.1848323 | E49: =RPI!$T$103/RPI!$T99 -> 1.1378291 | F49: =RPI!$T$103/RPI!$T100 -> 1.1050283 | G49: =RPI!$T$103/RPI!$T101 -> 1.0999923 | H49: =RPI!$T$103/RPI!$T102 -> 1.0479817 | I49: =RPI!$T$103/RPI!$T103 -> 1 | J49: =RPI!$T$103/RPI!$V104 -> 0.97002827 | O49: Price Base Conversion to 2011/12 | P49: =RPI!$T$103/RPI!$T97 -> 1.2290597 | Q49: =RPI!$T$103/RPI!$T98 -> 1.1848323 | R49: =RPI!$T$103/RPI!$T99 -> 1.1378291 | S49: =RPI!$T$103/RPI!$T100 -> 1.1050283 | T49: =RPI!$T$103/RPI!$T101 -> 1.0999923 | U49: =RPI!$T$103/RPI!$T102 -> 1.0479817 | V49: =RPI!$T$103/RPI!$T103 -> 1 | W49: =RPI!$T$103/RPI!$V104 -> 0.97002827
B51: Heathrow - CAA Allowance | O51: Heathrow - Outturn
B53: Regulatory Accounts | C53: Q4 | F53: Q5 | K53: Q5+1 | O53: Regulatory Accounts | P53: Q4 | S53: Q5 | X53: Q5+1
B54: £m 2011/12 | C54: 2005/06 | D54: 2006/07 | E54: 2007/08 | F54: 2008/09 | G54: 2009/10 | H54: 2010/11 | I54: 2011/12 | J54: 2012/13 | K54: 2013/14 | M54: CAGR (Q5) | O54: £m 2011/12 | P54: 2005/06 | Q54: 2006/07 | R54: 2007/08 | S54: 2008/09 | T54: 2009/10 | U54: 2010/11 | V54: 2011/12 | W54: 2012/13 | X54: 2013/14 | Z54: CAGR (Q5)
B55: Terminal Pax | C55: =69900 -> 69900 | D55: 70300 | E55: 70700 | F55: 70400 | G55: 72500 | H55: 74500 | I55: 76200 | J55: 76201 | M55: =((J55/F55)^(1/4))-1 -> 0.019992557 | O55: Terminal Pax | P55: 67421 | Q55: 67305 | R55: 67951 | S55: 65929 | T55: 66133 | U55: 66111 | V55: 70099 | W55: 70100 | Z55: =((W55/S55)^(1/4))-1 -> 0.015454299
B56: Net Revenue from Airport Charges | C56: =C7*C$49 -> 668.11684 | D56: =D7*D$49 -> 714.57239 | E56: =E7*E$49 -> 764.2798 | F56: =F7*F$49 -> 1025.1348 | G56: =G7*G$49 -> 1132.1121 | H56: =H7*H$49 -> 1250.7662 | I56: =I7*I$49 -> 1372.9 | J56: =J7*J$49 -> 1512.0801 | M56: =((J56/F56)^(1/4))-1 -> 0.10204278 | O56: Net Revenue from Airport Charges | P56: =P7*P$49 -> 654.10556 | Q56: =Q7*Q$49 -> 686.72883 | R56: =R7*R$49 -> 727.86927 | S56: =S7*S$49 -> 979.93912 | T56: =T7*T$49 -> 1050.9326 | U56: =U7*U$49 -> 1045.3618 | V56: =V7*V$49 -> 1178.6 | W56: =W7*W$49 -> 1257.0596 | Z56: =((W56/S56)^(1/4))-1 -> 0.064239065
B57: Other Revenue | C57: =C8*C$49 -> 700.07239 | D57: =D8*D$49 -> 705.80463 | E57: =E8*E$49 -> 710.80183 | F57: =F8*F$49 -> 796.50442 | G57: =G8*G$49 -> 820.37424 | H57: =H8*H$49 -> 843.73011 | I57: =I8*I$49 -> 856.3 | J57: =J8*J$49 -> 881.36769 | M57: =((J57/F57)^(1/4))-1 -> 0.025633586 | O57: Other Revenue | P57: =P8*P$49 -> 748.37444 | Q57: =Q8*Q$49 -> 730.21218 | R57: =R8*R$49 -> 726.50388 | S57: =S8*S$49 -> 820.92554 | T57: =T8*T$49 -> 866.24392 | U57: =U8*U$49 -> 897.17718 | V57: =V8*V$49 -> 895.5 | W57: =W8*W$49 -> 901.64128 | Z57: =((W57/S57)^(1/4))-1 -> 0.023723103
...

Sheet GAL - Reg
B2: Gatwick - CAA Allowance | P2: Gatwick - Outturn
B4: Regulatory Accounts | C4: Q4 | F4: Q5 | K4: Q5+1 | P4: Regulatory Accounts | Q4: Q4 | T4: Q5 | Y4: Q5+1
B5: £m nominal | C5: 2005/06 | D5: 2006/07 | E5: 2007/08 | F5: 2008/09 | G5: 2009/10 | H5: 2010/11 | I5: 2011/12 | J5: 2012/13 | K5: 2013/14 | M5: CAGR (3) | P5: £m nominal | Q5: 2005/06 | R5: 2006/07 | S5: 2007/08 | T5: 2008/09 | U5: 2009/10 | V5: 2010/11 | W5: 2011/12 | X5: 2012/13 | Y5: 2013/14 | AA5: CAGR (3)
B6: Terminal Pax | C6: 36000 | D6: 38600 | E6: 39700 | F6: 35900 | G6: 36400 | H6: 36800 | I6: 37200 | J6: 37700 | M6: =((I6/F6)^(1/4))-1 -> 0.0089325255 | P6: Terminal Pax | Q6: 32845 | R6: 34383 | S6: 35562 | T6: 33105 | U6: 32397 | V6: 31647 | W6: 33819 | X6: 34241 | AA6: =((W6/T6)^(1/3))-1 -> 0.0071381716
B7: Net Revenue from Airport Charges | C7: 165.2 | D7: 183.7 | E7: 196.7 | F7: 250.9 | G7: 270.7 | H7: 275.9 | I7: 297.7 | J7: 323.5 | M7: =((I7/F7)^(1/4))-1 -> 0.043685244 | P7: Net Revenue from Airport Charges | Q7: 153.4 | R7: 163.8 | S7: 178.3 | T7: 234.5 | U7: 241.6 | V7: 241.9 | W7: 271.3 | X7: 282.5 | AA7: =((W7/T7)^(1/3))-1 -> 0.04978972
B8: Other Revenue | C8: 203.7 | D8: 223.2 | E8: 236.7 | F8: 222.1 | G8: 224.9 | H8: 237.8 | I8: 252.2 | J8: 261.7 | M8: =((I8/F8)^(1/4))-1 -> 0.032283845 | P8: Other Revenue | Q8: 201.7 | R8: 213 | S8: 225.2 | T8: 220.3 | U8: 219.6 | V8: 217.1 | W8: 231.4 | X8: 239.2 | AA8: =((W8/T8)^(1/3))-1 -> 0.016520838
B9: Total Revenue | C9: 368.9 | D9: 406.9 | E9: 433.4 | F9: 473 | G9: 495.6 | H9: 513.7 | I9: 549.9 | J9: 585.2 | M9: =((I9/F9)^(1/4))-1 -> 0.038378398 | P9: Total Revenue | Q9: 355.1 | R9: 376.8 | S9: 403.5 | T9: 454.8 | U9: 461.2 | V9: 459 | W9: 502.7 | X9: 521.7 | AA9: =((W9/T9)^(1/3))-1 -> 0.033941919
B10: Operating Costs | C10: 195.8 | D10: 211.9 | E10: 227.7 | F10: 284.9 | G10: 284.9 | H10: 299.2 | I10: 314.8 | J10: 322.4 | M10: =((I10/F10)^(1/4))-1 -> 0.02526367 | P10: Operating Costs | Q10: 223.4 | R10: 225.4 | S10: 272.3 | T10: 282.1 | U10: 289.6 | V10: 268 | W10: 280.9 | X10: 294.2 | AA10: =((W10/T10)^(1/3))-1 -> -0.0014199522
B11: Assumed Ordinary Depreciation | C11: 63.8 | D11: 70.4 | E11: 79.8 | F11: 76.5 | G11: 81.3 | H11: 89.8 | I11: 98.1 | J11: 114.5 | M11: =((I11/F11)^(1/4))-1 -> 0.064147657 | P11: Assumed Ordinary Depreciation | Q11: 63.8 | R11: 70.4 | S11: 79.8 | T11: 76.5 | U11: 81.3 | V11: 89.8 | W11: 98.1 | X11: 114.5 | AA11: =((W11/T11)^(1/3))-1 -> 0.086431938
B12: Total Expenditure | C12: 259.6 | D12: 282.3 | E12: 307.5 | F12: 361.4 | G12: 366.2 | H12: 389 | I12: 412.9 | J12: 436.9 | M12: =((I12/F12)^(1/4))-1 -> 0.033865834 | P12: Total Expenditure | Q12: 287.2 | R12: 295.8 | S12: 352.1 | T12: 358.6 | U12: 370.9 | V12: 357.8 | W12: 379 | X12: 408.7 | AA12: =((W12/T12)^(1/3))-1 -> 0.018614002
B14: Regulatory Operating Profit (Before Exceptional) | C14: 109.3 | D14: 124.6 | E14: 125.9 | F14: 111.6 | G14: 129.4 | H14: 124.7 | I14: 137 | J14: 148.3 | M14: =((I14/F14)^(1/4))-1 -> 0.052601763 | P14: Regulatory Operating Profit (Before Exceptional) | Q14: 67.9 | R14: 81 | S14: 51.4 | T14: 96.2 | U14: 90.3 | V14: 101.2 | W14: 123.7 | X14: 113 | AA14: =((W14/T14)^(1/3))-1 -> 0.087422236
B15: Exceptional | C15: 0 | D15: 0 | E15: 0 | F15: 0 | G15: 0 | H15: 0 | I15: 0 | J15: 0 | P15: Exceptional | Q15: 0 | R15: 0 | S15: 0 | T15: 0 | U15: 120 | V15: 17 | W15: 0 | X15: 0
B16: Regulatory Operating Profit | C16: 109.3 | D16: 124.6 | E16: 125.9 | F16: 111.6 | G16: 129.4 | H16: 124.7 | I16: 137 | J16: 148 | M16: =((I16/F16)^(1/4))-1 -> 0.052601763 | P16: Regulatory Operating Profit | Q16: 67.9 | R16: 81 | S16: 51.4 | T16: 96.2 | U16: -29.7 | V16: 84.2 | W16: 123.7 | X16: 113 | AA16: =((W16/T16)^(1/3))-1 -> 0.087422236
B18: Capital Expenditure | C18: 110.2 | D18: 148.4 | E18: 177.1 | F18: 200.6 | G18: 257.7 | H18: 259.7 | I18: 167.4 | J18: 105 | M18: =((I18/F18)^(1/4))-1 -> -0.044223977 | P18: Capital Expenditure | Q18: 84.1 | R18: 101 | S18: 103.7 | T18: 104 | U18: 181.4 | V18: 232.2 | W18: 239.2 | X18: 226.7 | AA18: =((W18/T18)^(1/3))-1 -> 0.32000612
B20: Opening Basic RAB | C20: 1329.7 | D20: 1408 | E20: 1555.5 | F20: 1559.7 | G20: 1670.6 | H20: 1922 | I20: 2201.1 | J20: 2353.1 | M20: =((I20/F20)^(1/4))-1 -> 0.089932682 | P20: Opening Basic RAB | Q20: 1364.1 | R20: 1416.8 | S20: 1515.7 | T20: 1559.7 | U20: 1575.5 | V20: 1744.6 | W20: 1985.5 | X20: 2200.9 | AA20: =((W20/T20)^(1/3))-1 -> 0.08378451
B22: Closing Basic RAB | C22: 1408 | D22: 1555.5 | E22: 1559.7 | F22: 1670.6 | G22: 1922 | H22: 2201.1 | I22: 2353.1 | J22: 2425.5 | M22: =((I22/F22)^(1/4))-1 -> 0.089411553 | P22: Closing Basic RAB | Q22: 1416.8 | R22: 1515.7 | S22: 1559.7 | T22: 1575.5 | U22: 1744.6 | V22: 1985.5 | W22: 2200.9 | X22: 2391.6 | AA22: =((W22/T22)^(1/3))-1 -> 0.11787686
B24: Weighted average basic RAB | C24: 1368.1 | D24: 1480.3 | E24: 1557.6 | F24: 1615.1 | G24: 1796.3 | H24: 2061.6 | I24: 2277.1 | J24: 2389.3 | M24: =((I24/F24)^(1/4))-1 -> 0.089671699 | P24: Weighted average basic RAB | Q24: 1390 | R24: 1465.3 | S24: 1559.7 | T24: 1567.6 | U24: 1660.1 | V24: 1865.2 | W24: 2093.2 | X24: 2296.3 | AA24: =((W24/T24)^(1/3))-1 -> 0.10118044
B26: Return on weighted average basic RAB (pre-exceptional) (%) | C26: 8 | D26: 8.4 | E26: 8.1 | F26: 6.9 | G26: 7.2 | H26: 6 | I26: 6 | J26: 6.2 | P26: Return on weighted average basic RAB (pre-exceptional) (%) | Q26: 4.9 | R26: 5.5 | S26: 3.3 | T26: 6.1 | U26: 5.4 | V26: 5.4 | W26: 5.9 | X26: 4.9
B28: Return on weighted average basic RAB (%) | C28: 8 | D28: 8.4 | E28: 8.1 | F28: 6.9 | G28: 7.2 | H28: 6 | I28: 6 | J28: 6.2 | P28: Return on weighted average basic RAB (%) | Q28: 4.9 | R28: 5.5 | S28: 3.3 | T28: 6.1 | U28: -1.8 | V28: 4.5 | W28: 5.9 | X28: 4.9
B30: Breakdown of Operating Costs - CAA Projections | C30: Q4 | F30: Q5 | K30: Q5+1 | P30: Breakdown of Operating Costs | Q30: Q4 | T30: Q5 | Y30: Q5+1
B31: £m nominal | C31: 2005/06 | D31: 2006/07 | E31: 2007/08 | F31: 2008/09 | G31: 2009/10 | H31: 2010/11 | I31: 2011/12 | J31: 2012/13 | K31: 2013/14 | M31: CAGR (Q5) | P31: £m nominal | Q31: 2005/06 | R31: 2006/07 | S31: 2007/08 | T31: 2008/09 | U31: 2009/10 | V31: 2010/11 | W31: 2011/12 | X31: 2012/13 | Y31: 2013/14 | AA31: CAGR (Q5)
B32: Staff Costs | F32: 121.3 | G32: 119.7 | H32: 123.1 | I32: 127.6 | J32: 128.2 | M32: =((J32/F32)^(1/4))-1 -> 0.013927275 | P32: Staff Costs | T32: 101.3 | U32: 113.7 | V32: 128.5 | W32: 140.5 | X32: 149.1 | AA32: =((W32/T32)^(1/3))-1 -> 0.11520736
B33: Maintenance and equipment costs | F33: 25.7 | G33: 25.7 | H33: 29.1 | I33: 31.5 | J33: 32.3 | M33: =((J33/F33)^(1/4))-1 -> 0.058808331 | P33: Maintenance and equipment costs | T33: 30.2 | U33: 26.5 | V33: 25.6 | W33: 35.2 | X33: 37.1 | AA33: =((W33/T33)^(1/3))-1 -> 0.052394509
B34: Rent and rates | F34: 25.9 | G34: 26.9 | H34: 28.5 | I34: 31.7 | J34: 33.9 | M34: =((J34/F34)^(1/4))-1 -> 0.06960884 | P34: Rent and rates | T34: 24.8 | U34: 25 | V34: 22.5 | W34: 26.8 | X34: 28.2 | AA34: =((W34/T34)^(1/3))-1 -> 0.026189826
B35: Utility costs | F35: 26.6 | G35: 27 | H35: 28.8 | I35: 30.8 | J35: 32.1 | M35: =((J35/F35)^(1/4))-1 -> 0.048107549 | P35: Utility costs | T35: 26.2 | U35: 31.7 | V35: 28.2 | W35: 30.2 | X35: 27.6 | AA35: =((W35/T35)^(1/3))-1 -> 0.048500279
B36: Police costs | F36: 13.4 | G36: 13.3 | H36: 13.8 | I36: 14.3 | J36: 14.5 | M36: =((J36/F36)^(1/4))-1 -> 0.019919279 | P36: Police costs | T36: 13.8 | U36: 13.2 | V36: 13.3 | W36: 12.7 | X36: 12.2 | AA36: =((W36/T36)^(1/3))-1 -> -0.027309043
B37: Other costs | F37: 36.7 | G37: 37.7 | H37: 39.9 | I37: 41.7 | J37: 43.7 | M37: =((J37/F37)^(1/4))-1 -> 0.044609192 | P37: Other costs | T37: 52.2 | U37: 59.1 | V37: 51.5 | W37: 35.5 | X37: 40 | AA37: =((W37/T37)^(1/3))-1 -> -0.12060104
B38: Intergroup costs | F38: 35.3 | G38: 34.6 | H38: 36 | I38: 37.2 | J38: 37.7 | M38: =((J38/F38)^(1/4))-1 -> 0.016580234 | P38: Intergroup costs | T38: 41.3 | U38: 23.1 | V38: 0 | W38: 0 | X38: 0 | AA38: =((W38/T38)^(1/3))-1 -> -1
B40: Total operating costs | F40: 284.9 | G40: 284.9 | H40: 299.2 | I40: 314.8 | J40: 322.4 | M40: =((J40/F40)^(1/4))-1 -> 0.031396483 | P40: Total operating costs | T40: 289.9 | U40: 292.3 | V40: 269.6 | W40: =SUM(W32:W38) -> 280.9 | X40: 294.2 | AA40: =((W40/T40)^(1/3))-1 -> -0.010457371
B42: Exceptional operating costs | F42: 0 | G42: 0 | H42: 0 | I42: 0 | J42: 0 | P42: Exceptional operating costs | T42: -2.1 | U42: 0 | V42: 0 | W42: 0 | X42: 0
B43: Service Quality Rebates | F43: 0 | G43: 0 | H43: 0 | I43: 0 | J43: 0 | P43: Service Quality Rebates | T43: -5.6 | U43: -2.7 | V43: -1.6 | W43: 0 | X43: 0
B45: Adjusted operating costs | F45: =F40-F42-F43 -> 284.9 | G45: =G40-G42-G43 -> 284.9 | H45: =H40-H42-H43 -> 299.2 | I45: =I40-I42-I43 -> 314.8 | J45: 322 | M45: =((I45/F45)^(1/3))-1 -> 0.03382594 | P45: Adjusted operating costs | T45: =T40+T42+T43 -> 282.2 | U45: =U40+U43 -> 289.6 | V45: =V40+V43 -> 268 | W45: 280.9 | X45: 294.2 | AA45: =((W45/T45)^(1/3))-1 -> -0.001537918
B48: Price Base Conversion to 2011/12 | C48: =RPI!$X$103/RPI!$X97 -> 1.2290597 | D48: =RPI!$X$103/RPI!$X98 -> 1.1848323 | E48: =RPI!$X$103/RPI!$X99 -> 1.1378291 | F48: =RPI!$X$103/RPI!$X100 -> 1.1050283 | G48: =RPI!$X$103/RPI!$X101 -> 1.0999923 | H48: =RPI!$X$103/RPI!$X102 -> 1.0479817 | I48: =RPI!$X$103/RPI!$X103 -> 1 | J48: =RPI!$X$103/RPI!$X104 -> 0.96899225 | P48: Price Base Conversion to 2011/12 | Q48: =RPI!$X$103/RPI!$X97 -> 1.2290597 | R48: =RPI!$X$103/RPI!$X98 -> 1.1848323 | S48: =RPI!$X$103/RPI!$X99 -> 1.1378291 | T48: =RPI!$X$103/RPI!$X100 -> 1.1050283 | U48: =RPI!$X$103/RPI!$X101 -> 1.0999923 | V48: =RPI!$X$103/RPI!$X102 -> 1.0479817 | W48: =RPI!$X$103/RPI!$X103 -> 1 | X48: =RPI!$X$103/RPI!$X104 -> 0.96899225
B50: Gatwick - CAA Allowance | P50: Gatwick - Outturn
B52: Regulatory Accounts | C52: Q4 | F52: Q5 | K52: Q5+1 | P52: Regulatory Accounts | Q52: Q4 | T52: Q5 | Y52: Q5+1
B53: £m 2011/12 | C53: 2005/06 | D53: 2006/07 | E53: 2007/08 | F53: 2008/09 | G53: 2009/10 | H53: 2010/11 | I53: 2011/12 | J53: 2012/13 | K53: 2013/14 | M53: CAGR (3) | P53: £m 2011/12 | Q53: 2005/06 | R53: 2006/07 | S53: 2007/08 | T53: 2008/09 | U53: 2009/10 | V53: 2010/11 | W53: 2011/12 | X53: 2012/13 | Y53: 2013/14 | AA53: CAGR (3)
B54: Terminal Pax | C54: =C6 -> 36000 | D54: =D6 -> 38600 | E54: =E6 -> 39700 | F54: =F6 -> 35900 | G54: =G6 -> 36400 | H54: =H6 -> 36800 | I54: =I6 -> 37200 | J54: =J6 -> 37700 | M54: =((I54/F54)^(1/3))-1 -> 0.01192773 | P54: Terminal Pax | Q54: 32845 | R54: 34383 | S54: 35562 | T54: 33105 | U54: 32397 | V54: 31647 | W54: 33819 | X54: 33820 | AA54: =((W54/T54)^(1/3))-1 -> 0.0071381716
B55: Net Revenue from Airport Charges | C55: =C7*C$48 -> 203.04066 | D55: =D7*D$48 -> 217.6537 | E55: =E7*E$48 -> 223.81098 | F55: =F7*F$48 -> 277.25161 | G55: =G7*G$48 -> 297.76791 | H55: =H7*H$48 -> 289.13816 | I55: =I7*I$48 -> 297.7 | J55: =J7*J$48 -> 313.46899 | M55: =((I55/F55)^(1/3))-1 -> 0.024003846 | P55: Net Revenue from Airport Charges | Q55: =Q7*Q$48 -> 188.53776 | R55: =R7*R$48 -> 194.07554 | S55: =S7*S$48 -> 202.87493 | T55: =T7*T$48 -> 259.12914 | U55: =U7*U$48 -> 265.75813 | V55: =V7*V$48 -> 253.50679 | W55: =W7*W$48 -> 271.3 | X55: =X7*X$48 -> 273.74031 | AA55: =((W55/T55)^(1/3))-1 -> 0.015417192
B56: Other Revenue | C56: =C8*C$48 -> 250.35946 | D56: =D8*D$48 -> 264.45458 | E56: =E8*E$48 -> 269.32415 | F56: =F8*F$48 -> 245.42679 | G56: =G8*G$48 -> 247.38826 | H56: =H8*H$48 -> 249.21006 | I56: =I8*I$48 -> 252.2 | J56: =J8*J$48 -> 253.58527 | M56: =((I56/F56)^(1/3))-1 -> 0.0091158742 | P56: Other Revenue | Q56: =Q8*Q$48 -> 247.90134 | R56: =R8*R$48 -> 252.36929 | S56: =S8*S$48 -> 256.23911 | T56: =T8*T$48 -> 243.43774 | U56: =U8*U$48 -> 241.5583 | V56: =V8*V$48 -> 227.51684 | W56: =W8*W$48 -> 231.4 | X56: =X8*X$48 -> 231.78295 | AA56: =((W56/T56)^(1/3))-1 -> -0.01676239
B57: Total Revenue | C57: =C9*C$48 -> 453.40012 | D57: =D9*D$48 -> 482.10828 | E57: =E9*E$48 -> 493.13513 | F57: =F9*F$48 -> 522.6784 | G57: =G9*G$48 -> 545.15617 | H57: =H9*H$48 -> 538.34822 | I57: =I9*I$48 -> 549.9 | J57: =J9*J$48 -> 567.05426 | M57: =((I57/F57)^(1/3))-1 -> 0.017067374 | P57: Total Revenue | Q57: =Q9*Q$48 -> 436.43909 | R57: =R9*R$48 -> 446.44483 | S57: =S9*S$48 -> 459.11404 | T57: =T9*T$48 -> 502.56688 | U57: =U9*U$48 -> 507.31644 | V57: =V9*V$48 -> 481.02362 | W57: =W9*W$48 -> 502.7 | X57: =X9*X$48 -> 505.52326 | AA57: =((W57/T57)^(1/3))-1 -> 8.8284697e-05
...

Sheet STAL - Reg
B2: Stansted - CAA Allowance | M2: Stansted - Outturn
B4: Regulatory Accounts | C4: Q4 | F4: Q4+1 | G4: Q5 | M4: Regulatory Accounts | N4: Q4 | Q4: Q4+1 | R4: Q5
B5: £m nominal | C5: 2005/06 | D5: 2006/07 | E5: 2007/08 | F5: 2008/09 | G5: 2009/10 | H5: 2010/11 | I5: 2011/12 | J5: 2012/13 | K5: 2013/14 | M5: £m nominal | N5: 2005/06 | O5: 2006/07 | P5: 2007/08 | Q5: 2008/09 | R5: 2009/10 | S5: 2010/11 | T5: 2011/12 | U5: 2012/13 | V5: 2013/14 | X5: CAGR (4)
B6: Terminal Pax | C6: 22237 | D6: 21100 | E6: 22300 | M6: Terminal Pax | N6: 22237 | O6: 23845 | P6: 23541 | Q6: 21635 | R6: 19758 | S6: 18308 | T6: 17847 | X6: =((T6/Q6)^(1/3))-1 -> -0.062144115
B7: Net Revenue from Airport Charges | C7: 72.5 | D7: 100.7 | E7: 113.5 | M7: Net Revenue from Airport Charges | N7: 72.5 | O7: 80.7 | P7: 138.3 | Q7: 141.1 | R7: 132.9 | S7: 121.6 | T7: 127.6 | X7: =((T7/Q7)^(1/3))-1 -> -0.032967166
B8: Other Revenue | C8: 103.1 | D8: 121.8 | E8: 132.9 | M8: Other Revenue | N8: 103.1 | O8: 108.2 | P8: 112.1 | Q8: 107.7 | R8: 103.2 | S8: 97.5 | T8: 100.4 | X8: =((T8/Q8)^(1/3))-1 -> -0.023124233
B9: Total Revenue | C9: 175.6 | D9: 222.5 | E9: 246.4 | M9: Total Revenue | N9: 175.6 | O9: 118.9 | P9: 250.4 | Q9: 248.8 | R9: 236.1 | S9: 219.1 | T9: 228 | X9: =((T9/Q9)^(1/3))-1 -> -0.028681881
B10: Operating Costs | C10: 100.5 | D10: 108.1 | E10: 116.7 | M10: Operating Costs | N10: 100.5 | O10: 114.7 | P10: 141.3 | Q10: 145.2 | R10: 132.6 | S10: 133.4 | T10: 141.5 | X10: =((T10/Q10)^(1/3))-1 -> -0.0085672189
B11: Assumed Ordinary Depreciation | C11: 36.4 | D11: 40.5 | E11: 45.9 | M11: Assumed Ordinary Depreciation | N11: 36.4 | O11: 40.5 | P11: 45.9 | Q11: 41.7 | R11: 45.5 | S11: 46.8 | T11: 45 | X11: =((T11/Q11)^(1/3))-1 -> 0.025712118
B12: Total Expenditure | C12: 136.9 | D12: 148.6 | E12: 162.6 | M12: Total Expenditure | N12: 136.9 | O12: 155.2 | P12: 187.2 | Q12: 186.9 | R12: 178.1 | S12: 180.2 | T12: 186.5 | X12: =((T12/Q12)^(1/3))-1 -> -0.00071390351
B14: Regulatory Operating Profit (Before Exceptional) | C14: 38.7 | D14: 73.9 | E14: 83.8 | M14: Regulatory Operating Profit (Before Exceptional) | N14: 38.7 | O14: 33.7 | P14: 63.2 | Q14: 61.9 | R14: 58 | S14: 38.9 | T14: 41.5 | X14: =((T14/Q14)^(1/3))-1 -> -0.12477614
B15: Exceptional | C15: 0 | D15: 0 | E15: 0 | M15: Exceptional | N15: 0 | O15: 0 | P15: 0 | Q15: 0 | R15: 39 | S15: -25.1 | T15: 32.7
B16: Regulatory Operating Profit | C16: 38.7 | D16: 73.9 | E16: 83.8 | M16: Regulatory Operating Profit | N16: 38.7 | O16: 33.7 | P16: 63.2 | Q16: 63.2 | R16: 19 | S16: 64 | T16: 8.8 | X16: =((T16/Q16)^(1/3))-1 -> -0.48169126
B18: Capital Expenditure | C18: 65.9 | D18: 91.7 | E18: 99.1 | M18: Capital Expenditure | N18: 65.9 | O18: 111.4 | P18: 110.7 | Q18: 100.4 | R18: 27.9 | S18: 20.8 | T18: 19.2 | X18: =((T18/Q18)^(1/3))-1 -> -0.42386733
B20: Opening Basic RAB | C20: 862 | D20: 1024.1 | E20: 1125.7 | M20: Opening Basic RAB | N20: 862 | O20: 912.1 | P20: 1028.3 | Q20: 1132.9 | R20: 1229.8 | S20: 1293 | T20: 1348.9 | X20: =((T20/Q20)^(1/3))-1 -> 0.059894713
B22: Closing Basic RAB | C22: 912.1 | D22: 1125.7 | E22: 1222.2 | M22: Closing Basic RAB | N22: 912.1 | O22: 1028.3 | P22: 1132.9 | Q22: 1186.1 | R22: 1266.5 | S22: 1348.9 | T22: 1359.6 | X22: =((T22/Q22)^(1/3))-1 -> 0.046557955
B24: Weighted average basic RAB | C24: 886.6 | D24: 1074 | E24: 1173.1 | M24: Weighted average basic RAB | N24: 886.6 | O24: 969.1 | P24: 1079.7 | Q24: 1159 | R24: 1248.2 | S24: 1321 | T24: 1354.2 | X24: =((T24/Q24)^(1/3))-1 -> 0.053254018
B26: Return on weighted average basic RAB (pre-exceptional) (%) | C26: 4.4 | D26: 6.9 | E26: 7.1 | M26: Return on weighted average basic RAB (pre-exceptional) (%) | N26: 4.4 | O26: 3.5 | P26: 5.9 | Q26: 5.3 | R26: 4.6 | S26: 2.9 | T26: 3.1 | X26: =((T26/Q26)^(1/3))-1 -> -0.1637003
B28: Return on weighted average basic RAB (%) | C28: 4.4 | D28: 6.9 | E28: 7.1 | M28: Return on weighted average basic RAB (%) | N28: 4.4 | O28: 3.5 | P28: 5.9 | Q28: 5.3 | R28: 1.5 | S28: 4.8 | T28: 0.6 | X28: =((T28/Q28)^(1/3))-1 -> -0.51624538
B30: Opex per pax | C30: =(C10/C6)*1000 -> 4.5194945 | D30: =(D10/D6)*1000 -> 5.1232227 | E30: =(E10/E6)*1000 -> 5.2331839 | M30: Opex per pax | N30: =(N10/N6)*1000 -> 4.5194945 | O30: =(O10/O6)*1000 -> 4.8102328 | P30: =(P10/P6)*1000 -> 6.0022939 | Q30: =(Q10/Q6)*1000 -> 6.7113474 | R30: =(R10/R6)*1000 -> 6.7112056 | S30: =(S10/S6)*1000 -> 7.2864322 | T30: =(T10/T6)*1000 -> 7.9285034
B32: Breakdown of Operating Costs - CAA Projection | C32: Q4 | F32: Q4+1 | G32: Q5 | M32: Breakdown of Operating Costs | N32: Q4 | Q32: Q4+1 | R32: Q5
B33: £m nominal | C33: 2005/06 | D33: 2006/07 | E33: 2007/08 | F33: 2008/09 | G33: 2009/10 | H33: 2010/11 | I33: 2011/12 | J33: 2012/13 | K33: 2013/14 | M33: £m nominal | N33: 2005/06 | O33: 2006/07 | P33: 2007/08 | Q33: 2008/09 | R33: 2009/10 | S33: 2010/11 | T33: 2011/12 | U33: 2012/13 | V33: 2013/14 | X33: CAGR (4)
B34: Staff Costs | M34: Staff Costs | P34: 54.5 | Q34: 51.2 | R34: 47.3 | S34: 50.4 | T34: 57 | X34: =((T34/Q34)^(1/3))-1 -> 0.036418043
B35: Maintenance and equipment costs | M35: Maintenance and equipment costs | P35: 11.8 | Q35: 9.6 | R35: 9.7 | S35: 9.2 | T35: 10.4 | X35: =((T35/Q35)^(1/3))-1 -> 0.027040025
B36: Rent and rates | M36: Rent and rates | P36: 10.8 | Q36: 11.3 | R36: 12.3 | S36: 13.5 | T36: 15 | X36: =((T36/Q36)^(1/3))-1 -> 0.09901665
B37: Utility costs | M37: Utility costs | P37: 11.8 | Q37: 13 | R37: 23.4 | S37: 19.2 | T37: 20.5 | X37: =((T37/Q37)^(1/3))-1 -> 0.16395673
B38: Police costs | M38: Police costs | P38: 7.2 | Q38: 7 | R38: 6.3 | S38: 6.7 | T38: 6.9 | X38: =((T38/Q38)^(1/3))-1 -> -0.0047847622
B39: Other costs | M39: Other costs | P39: 7.7 | Q39: 25.3 | R39: 22.2 | S39: 24.3 | T39: 22.7 | X39: =((T39/Q39)^(1/3))-1 -> -0.035501007
B40: Intragroup costs | M40: Intragroup costs | P40: 28.4 | Q40: 25.9 | R40: 12 | S40: 10.4 | T40: 9.2 | X40: =((T40/Q40)^(1/3))-1 -> -0.29178897
B42: Total operating costs | M42: Total operating costs | P42: 132.2 | Q42: 138.3 | R42: 133.2 | S42: 133.7 | T42: 141.7 | X42: =((T42/Q42)^(1/3))-1 -> 0.0081284943
B44: Exceptional operating costs | M44: Exceptional operating costs | P44: 9.1 | Q44: 6.9 | R44: 0 | S44: 0 | T44: 0 | X44: =((T44/Q44)^(1/3))-1 -> -1
B45: Service Quality Rebates | M45: Service Quality Rebates | P45: 0 | Q45: 0 | R45: -0.6 | S45: -0.3 | T45: -0.2
B47: Adjusted operating costs | M47: Adjusted operating costs | P47: 141.3 | Q47: 145.2 | R47: 132.6 | S47: 133.4 | T47: 141.5 | X47: =((T47/Q47)^(1/3))-1 -> -0.0085672189
B50: Price Base Conversion to Real 2011/12 | C50: =RPI!$T$103/RPI!$T97 -> 1.2290597 | D50: =RPI!$T$103/RPI!$T98 -> 1.1848323 | E50: =RPI!$T$103/RPI!$T99 -> 1.1378291 | F50: =RPI!$T$103/RPI!$T100 -> 1.1050283 | G50: =RPI!$T$103/RPI!$T101 -> 1.0999923 | H50: =RPI!$T$103/RPI!$T102 -> 1.0479817 | I50: =RPI!$T$103/RPI!$Z103 -> 1 | J50: =RPI!$T$103/RPI!$Z104 -> 0.9699321 | K50: =RPI!$T$103/RPI!$Z105 -> 0.94328432 | M50: Price Base Conversion to Real 2011/12 | N50: =RPI!$T$103/RPI!$T97 -> 1.2290597 | O50: =RPI!$T$103/RPI!$T98 -> 1.1848323 | P50: =RPI!$T$103/RPI!$T99 -> 1.1378291 | Q50: =RPI!$T$103/RPI!$T100 -> 1.1050283 | R50: =RPI!$T$103/RPI!$T101 -> 1.0999923 | S50: =RPI!$T$103/RPI!$T102 -> 1.0479817 | T50: =RPI!$T$103/RPI!$T103 -> 1
B52: Stansted - CAA Allowance | M52: Stansted - Outturn
B54: Regulatory Accounts | C54: Q4 | F54: Q4+1 | G54: Q5 | M54: Regulatory Accounts | N54: Q4 | Q54: Q4+1 | R54: Q5
B55: £m 2011/12 | C55: 2005/06 | D55: 2006/07 | E55: 2007/08 | F55: 2008/09 | G55: 2009/10 | H55: 2010/11 | I55: 2011/12 | J55: 2012/13 | K55: 2013/14 | M55: £m 2011/12 | N55: 2005/06 | O55: 2006/07 | P55: 2007/08 | Q55: 2008/09 | R55: 2009/10 | S55: 2010/11 | T55: 2011/12 | U55: 2012/13 | V55: 2013/14 | X55: CAGR (6)
B56: =B6 -> Terminal Pax | C56: =C6 -> 22237 | D56: =D6 -> 21100 | E56: =E6 -> 22300 | M56: =M6 -> Terminal Pax | N56: 22237 | O56: 23845 | P56: 23541 | Q56: 21635 | R56: 19758 | S56: 18308 | T56: 17847 | X56: =((T56/N56)^(1/6))-1 -> -0.035990076
B57: =B7 -> Net Revenue from Airport Charges | C57: =C7*C$50 -> 89.106827 | D57: =D7*D$50 -> 119.31262 | E57: =E7*E$50 -> 129.1436 | M57: =M7 -> Net Revenue from Airport Charges | N57: =N7*N$50 -> 89.106827 | O57: =O7*O$50 -> 95.615971 | P57: =P7*P$50 -> 157.36176 | Q57: =Q7*Q$50 -> 155.9195 | R57: =R7*R$50 -> 146.18897 | S57: =S7*S$50 -> 127.43458 | T57: =T7*T$50 -> 127.6 | X57: =((T57/N57)^(1/6))-1 -> 0.061670987
B58: =B8 -> Other Revenue | C58: =C8*C$50 -> 126.71605 | D58: =D8*D$50 -> 144.31258 | E58: =E8*E$50 -> 151.21749 | M58: =M8 -> Other Revenue | N58: =N8*N$50 -> 126.71605 | O58: =O8*O$50 -> 128.19886 | P58: =P8*P$50 -> 127.55064 | Q58: =Q8*Q$50 -> 119.01155 | R58: =R8*R$50 -> 113.5192 | S58: =S8*S$50 -> 102.17822 | T58: =T8*T$50 -> 100.4 | X58: =((T58/N58)^(1/6))-1 -> -0.038054769
...

Sheet HAL>>

Sheet HAL - iBP 
B2: Heathrow - Initial Business Plan - July 2012
B4: July 2012 IBP Forecast | C4: Q5 | H4: Q5+1 | I4: Q6 | P4: July 2012 IBP Forecast - Summary | U4: July 2012 IBP Forecast - Summary
B5: £m nominal | C5: 2008/09 | D5: 2009/10 | E5: 2010/11 | F5: 2011/12 | G5: 2012/13 | H5: 2013/14 | I5: 2014/15 | J5: 2015/16 | K5: 2016/17 | L5: 2017/18 | M5: 2018/19 | P5: £m nominal | Q5: Total Q5+1 | R5: % of Total | S5: CAGR (Q5+1) | U5: £m nominal | V5: Total Q6 | W5: % of Total | X5: CAGR (Q6)
B6: Security Costs | C6: =C31*C$27 -> 158.88744 | D6: =D31*D$27 -> 152.56006 | E6: =E31*E$27 -> 154.57781 | F6: =F31*F$27 -> 162.96475 | G6: =G31*G$27 -> 161 | H6: =H31*H$27 -> 182.98556 | I6: =I31*I$27 -> 189.17557 | J6: =J31*J$27 -> 193.38711 | ... M6: =M31*M$27 -> 200.63463 | P6: Security Costs | Q6: =SUM(C6:H6) -> 972.97562 | R6: =Q6/$Q$17 -> 0.16363464 | S6: =((H6/C6)^(1/5))-1 -> 0.028644845 | U6: Security Costs | V6: =SUM(I6:M6) -> 967.10561 | W6: =V6/$V$17 -> 0.15496107 | X6: =((M6/H6)^(1/5))-1 -> 0.018586266
B7: Staff Costs - Other Operational | C7: =C32*C$27 -> 56.181193 | D7: =D32*D$27 -> 47.619904 | E7: =E32*E$27 -> 51.834474 | F7: =F32*F$27 -> 53.351555 | G7: =G32*G$27 -> 57 | H7: =H32*H$27 -> 57.24688 | I7: =I32*I$27 -> 63.058523 | J7: =J32*J$27 -> 66.273111 | ... M7: =M32*M$27 -> 68.856857 | P7: Staff Costs - Other Operational | Q7: =SUM(C7:H7) -> 323.23401 | R7: =Q7/$Q$17 -> 0.054361363 | S7: =((H7/C7)^(1/5))-1 -> 0.0037652885 | U7: Staff Costs - Other Operational | V7: =SUM(I7:M7) -> 329.944 | W7: =V7/$V$17 -> 0.052867519 | X7: =((M7/H7)^(1/5))-1 -> 0.037621769
B8: Facilities Management | C8: =C33*C$27 -> 156.25394 | D8: =D33*D$27 -> 161.37856 | E8: =E33*E$27 -> 153.65219 | F8: =F33*F$27 -> 163.93478 | G8: =G33*G$27 -> 175 | H8: =H33*H$27 -> 196.27502 | I8: =I33*I$27 -> 232.26556 | J8: =J33*J$27 -> 233.58556 | ... M8: =M33*M$27 -> 244.56056 | P8: Facilities Management | Q8: =SUM(C8:H8) -> 1006.4945 | R8: =Q8/$Q$17 -> 0.16927183 | S8: =((H8/C8)^(1/5))-1 -> 0.046662846 | U8: Facilities Management | V8: =SUM(I8:M8) -> 1185.1523 | W8: =V8/$V$17 -> 0.18989908 | X8: =((M8/H8)^(1/5))-1 -> 0.0449711
B9: Utilities | C9: =C34*C$27 -> 81.638296 | D9: =D34*D$27 -> 105.82201 | E9: =E34*E$27 -> 87.933483 | F9: =F34*F$27 -> 84.392459 | G9: =G34*G$27 -> 92 | H9: =H34*H$27 -> 95.070711 | I9: =I34*I$27 -> 107.19949 | J9: =J34*J$27 -> 109.73089 | ... M9: =M34*M$27 -> 116.34434 | P9: Utilities | Q9: =SUM(C9:H9) -> 546.85696 | R9: =Q9/$Q$17 -> 0.09197018 | S9: =((H9/C9)^(1/5))-1 -> 0.030933287 | U9: Utilities | V9: =SUM(I9:M9) -> 555.92967 | W9: =V9/$V$17 -> 0.089077609 | X9: =((M9/H9)^(1/5))-1 -> 0.041213299
B10: Rent and Rates | C10: =C35*C$27 -> 103.58407 | D10: =D35*D$27 -> 110.23126 | E10: =E35*E$27 -> 103.66895 | F10: =F35*F$27 -> 116.40339 | G10: =G35*G$27 -> 126 | H10: =H35*H$27 -> 132.89454 | I10: =I35*I$27 -> 161.85021 | J10: =J35*J$27 -> 181.43622 | ... M10: =M35*M$27 -> 198.26026 | P10: Rent and Rates | Q10: =SUM(C10:H10) -> 692.78222 | R10: =Q10/$Q$17 -> 0.11651183 | S10: =((H10/C10)^(1/5))-1 -> 0.051097085 | U10: Rent and Rates | V10: =SUM(I10:M10) -> 920.91169 | W10: =V10/$V$17 -> 0.14755933 | X10: =((M10/H10)^(1/5))-1 -> 0.083292422
B11: Central Support Services | C11: =C36*C$27 -> 107.97323 | D11: =D36*D$27 -> 97.003508 | E11: =E36*E$27 -> 115.70195 | F11: =F36*F$27 -> 119.31348 | G11: =G36*G$27 -> 143 | H11: =H36*H$27 -> 113.47149 | I11: =I36*I$27 -> 117.70924 | J11: =J36*J$27 -> 120.59533 | ... M11: =M36*M$27 -> 125.84184 | P11: Central Support Services | Q11: =SUM(C11:H11) -> 696.46366 | R11: =Q11/$Q$17 -> 0.11713097 | S11: =((H11/C11)^(1/5))-1 -> 0.0099831679 | U11: Central Support Services | V11: =SUM(I11:M11) -> 608.33165 | W11: =V11/$V$17 -> 0.097474073 | X11: =((M11/H11)^(1/5))-1 -> 0.020910472
B12: Rail | C12: =C37*C$27 -> 64.081673 | D12: =D37*D$27 -> 67.902456 | E12: =E37*E$27 -> 69.421171 | F12: =F37*F$27 -> 64.021866 | G12: =G37*G$27 -> 66 | H12: =H37*H$27 -> 68.491803 | I12: =I37*I$27 -> 63.058523 | J12: =J37*J$27 -> 64.100223 | ... M12: =M37*M$27 -> 71.231231 | P12: Rail | Q12: =SUM(C12:H12) -> 399.91897 | R12: =Q12/$Q$17 -> 0.067258209 | S12: =((H12/C12)^(1/5))-1 -> 0.013400119 | U12: Rail | V12: =SUM(I12:M12) -> 333.56974 | W12: =V12/$V$17 -> 0.053448478 | X12: =((M12/H12)^(1/5))-1 -> 0.0078742991
B13: Commercial Expenditure | C13: =C38*C$27 -> 36.868908 | D13: =D38*D$27 -> 49.383604 | E13: =E38*E$27 -> 41.652703 | F13: =F38*F$27 -> 42.681244 | G13: =G38*G$27 -> 46 | H13: =H38*H$27 -> 49.068754 | I13: =I38*I$27 -> 53.599745 | J13: =J38*J$27 -> 56.495111 | ... M13: =M38*M$27 -> 60.546546 | P13: Commercial Expenditure | Q13: =SUM(C13:H13) -> 265.65521 | R13: =Q13/$Q$17 -> 0.044677785 | S13: =((H13/C13)^(1/5))-1 -> 0.058836617 | U13: Commercial Expenditure | V13: =SUM(I13:M13) -> 285.37635 | W13: =V13/$V$17 -> 0.045726364 | X13: =((M13/H13)^(1/5))-1 -> 0.042934104
B14: Other | C14: =C39*C$27 -> 139.57515 | D14: =D39*D$27 -> 134.92306 | E14: =E39*E$27 -> 135.13988 | F14: =F39*F$27 -> 151.32441 | G14: =G39*G$27 -> 166 | H14: =H39*H$27 -> 128.80548 | I14: =I39*I$27 -> 122.96412 | J14: =J39*J$27 -> 122.76822 | ... M14: =M39*M$27 -> 132.96496 | P14: Other | Q14: =SUM(C14:H14) -> 855.76798 | R14: =Q14/$Q$17 -> 0.14392271 | S14: =((H14/C14)^(1/5))-1 -> -0.015931689 | U14: Other | V14: =SUM(I14:M14) -> 637.66503 | W14: =V14/$V$17 -> 0.10217421 | X14: =((M14/H14)^(1/5))-1 -> 0.006376708
B15: Pensions | C15: =C40*C$27 -> 30.72409 | D15: =D40*D$27 -> 22.928102 | E15: =E40*E$27 -> 30.545315 | F15: =F40*F$27 -> 34.921018 | G15: =G40*G$27 -> 32 | H15: =H40*H$27 -> 34.757034 | I15: =I40*I$27 -> 81.97608 | J15: =J40*J$27 -> 82.569778 | ... M15: =M40*M$27 -> 85.477477 | P15: Pensions | Q15: =SUM(C15:H15) -> 185.87556 | R15: =Q15/$Q$17 -> 0.031260476 | S15: =((H15/C15)^(1/5))-1 -> 0.024973736 | U15: Pensions | V15: =SUM(I15:M15) -> 416.97258 | W15: =V15/$V$17 -> 0.066812266 | X15: =((M15/H15)^(1/5))-1 -> 0.19718646
B17: Total | C17: =C42*C$27 -> 935.76799 | D17: =D42*D$27 -> 949.75253 | E17: =E42*E$27 -> 944.12792 | F17: =F42*F$27 -> 993.30895 | G17: =G42*G$27 -> 1064 | H17: =H42*H$27 -> 1059.0673 | I17: =I42*I$27 -> 1192.8571 | J17: =J42*J$27 -> 1230.9416 | ... M17: =M42*M$27 -> 1304.7187 | P17: Total | Q17: =SUM(C17:H17) -> 5946.0247 | R17: =Q17/$Q$17 -> 1 | S17: =((H17/C17)^(1/5))-1 -> 0.025064215 | U17: Total | V17: =SUM(I17:M17) -> 6240.9586 | W17: =V17/$V$17 -> 1 | X17: =((M17/H17)^(1/5))-1 -> 0.042602276
B18: Impact of T1 Closure | I18: =I43*I$27 -> 0 | J18: =J43*J$27 -> 0 | K18: =K43*K$27 -> -34.690171 | L18: =L43*L$27 -> -36.883485 | M18: =M43*M$27 -> -37.98999 | U18: Impact of T1 Closure | V18: =SUM(I18:M18) -> -109.56365
B19: SQR at 5 mins queuing in transfers | I19: =I44*I$27 -> 5.2548769 | J19: =J44*J$27 -> 5.4322223 | K19: =K44*K$27 -> 5.5951889 | L19: =L44*L$27 -> 5.7630446 | M19: =M44*M$27 -> 5.9359359 | U19: SQR at 5 mins queuing in transfers | V19: =SUM(I19:M19) -> 27.981269
B20: Increase opex saving by 0.2% | I20: =I45*I$27 -> -3.1529261 | J20: =J45*J$27 -> -5.4322223 | K20: =K45*K$27 -> -8.9523023 | L20: =L45*L$27 -> -12.678698 | M20: =M45*M$27 -> -16.620621 | U20: Increase opex saving by 0.2% | V20: =SUM(I20:M20) -> -46.836769
B21: Total Q6 after Adjustments | C21: =C46*C$27 -> 935.76799 | D21: =D46*D$27 -> 949.75253 | E21: =E46*E$27 -> 944.12792 | F21: =F46*F$27 -> 993.30895 | G21: =G46*G$27 -> 1064 | H21: =H46*H$27 -> 1059.0673 | I21: =I46*I$27 -> 1194.959 | J21: =J46*J$27 -> 1230.9416 | ... M21: =M46*M$27 -> 1256.044 | U21: Total Q6 after Adjustments | V21: =SUM(I21:M21) -> 6112.5394 | X21: =((M21/H21)^(1/5))-1 -> 0.034704323
B23: Passengers (m) | C23: 65.9 | D23: 66.1 | E23: 66.1 | F23: 70.1 | G23: 69.2 | H23: 69.1 | I23: =I48 -> 69.2 | J23: =J48 -> 70.1 | K23: =K48 -> 71.1 | L23: =L48 -> 71.8 | M23: =M48 -> 72.6 | P23: Passengers (m) | Q23: =SUM(C23:H23) -> 406.5 | S23: =((H23/C23)^(1/5))-1 -> 0.0095283664 | U23: Passengers (m) | V23: =V48 -> 354.8 | X23: =((M23/H23)^(1/5))-1 -> 0.0099310268
B24: Total opex / passenger | C24: =C21/C23 -> 14.199818 | D24: =D17/D23 -> 14.368419 | E24: =E17/E23 -> 14.283327 | F24: =F17/F23 -> 14.169885 | G24: =G17/G23 -> 15.375723 | H24: =H17/H23 -> 15.326589 | I24: =I21/I23 -> 17.268194 | J24: =J21/J23 -> 17.559794 | K24: =K21/K23 -> 16.872131 | L24: =L21/L23 -> 17.144656 | M24: =M21/M23 -> 17.300882 | P24: Total opex / passenger | Q24: =Q17/Q23 -> 14.627367 | S24: =((H24/C24)^(1/5))-1 -> 0.015389215 | U24: Total opex / passenger | V24: =V21/V23 -> 17.228127 | X24: =((M24/H24)^(1/5))-1 -> 0.024529691
B27: Price Base Conversion 2012/13 to Nominal | C27: =RPI!$T100/RPI!$V$104 -> 0.87783114 | D27: =RPI!$T101/RPI!$V$104 -> 0.88185007 | E27: =RPI!$T102/RPI!$V$104 -> 0.92561561 | F27: =RPI!$T103/RPI!$V$104 -> 0.97002827 | G27: =RPI!$V104/RPI!$V$104 -> 1 | H27: =RPI!$V105/RPI!$V$104 -> 1.0222657 | I27: =RPI!$V106/RPI!$V$104 -> 1.0509754 | J27: =RPI!$V107/RPI!$V$104 -> 1.0864445 | K27: =RPI!$V108/RPI!$V$104 -> 1.1190378 | L27: =RPI!$V109/RPI!$V$104 -> 1.1526089 | M27: =RPI!$V110/RPI!$V$104 -> 1.1871872
B29: July 2012 IBP Forecast | C29: Q5 | H29: Q5+1 | I29: Q6 | P29: July 2012 IBP Forecast - Summary | U29: July 2012 IBP Forecast - Summary
B30: £m 2012/13 prices | C30: 2008/09 | D30: 2009/10 | E30: 2010/11 | F30: 2011/12 | G30: 2012/13 | H30: 2013/14 | I30: 2014/15 | J30: 2015/16 | K30: 2016/17 | L30: 2017/18 | M30: 2018/19 | P30: £m 2012/13 prices | Q30: Total Q5+1 | R30: % of Total | S30: CAGR (Q5+1) | U30: £m 2012/13 prices | V30: Total Q6 | W30: % of Total | X30: CAGR (Q6)
B31: Security Costs | C31: 181 | D31: 173 | E31: 167 | F31: 168 | G31: 161 | H31: 179 | I31: 180 | J31: 178 | K31: 169 | L31: 169 | M31: 169 | P31: Security Costs | Q31: =SUM(C31:G31) -> 850 | R31: =Q31/$Q$42 -> 0.16187393 | S31: =((H31/C31)^(1/5))-1 -> -0.0022197777 | U31: Security Costs | V31: =SUM(I31:M31) -> 865 | W31: =V31/$V$42 -> 0.15504571 | X31: =((M31/H31)^(1/5))-1 -> -0.011431575
B32: Staff Costs - Other Operational | C32: 64 | D32: 54 | E32: 56 | F32: 55 | G32: 57 | H32: 56 | I32: 60 | J32: 61 | K32: 58 | L32: 58 | M32: 58 | P32: Staff Costs - Other Operational | Q32: =SUM(C32:G32) -> 286 | R32: =Q32/$Q$42 -> 0.054465816 | S32: =((H32/C32)^(1/5))-1 -> -0.026352819 | U32: Staff Costs - Other Operational | V32: =SUM(I32:M32) -> 295 | W32: =V32/$V$42 -> 0.05287686 | X32: =((M32/H32)^(1/5))-1 -> 0.0070429497
B33: Facilities Management | C33: 178 | D33: 183 | E33: 166 | F33: 169 | G33: 175 | H33: 192 | I33: 221 | J33: 215 | K33: 210 | L33: 208 | M33: 206 | P33: Facilities Management | Q33: =SUM(C33:G33) -> 871 | R33: =Q33/$Q$42 -> 0.16587317 | S33: =((H33/C33)^(1/5))-1 -> 0.015257591 | U33: Facilities Management | V33: =SUM(I33:M33) -> 1060 | W33: =V33/$V$42 -> 0.18999821 | X33: =((M33/H33)^(1/5))-1 -> 0.014175695
B34: Utilities | C34: 93 | D34: 120 | E34: 95 | F34: 87 | G34: 92 | H34: 93 | I34: 102 | J34: 101 | K34: 97 | L34: 99 | M34: 98 | P34: Utilities | Q34: =SUM(C34:G34) -> 487 | R34: =Q34/$Q$42 -> 0.092744239 | S34: =((H34/C34)^(1/5))-1 -> 0 | U34: Utilities | V34: =SUM(I34:M34) -> 497 | W34: =V34/$V$42 -> 0.089084065 | X34: =((M34/H34)^(1/5))-1 -> 0.010528637
B35: Rent and Rates | C35: 118 | D35: 125 | E35: 112 | F35: 120 | G35: 126 | H35: 130 | I35: 154 | J35: 167 | K35: 167 | L35: 167 | M35: 167 | P35: Rent and Rates | Q35: =SUM(C35:G35) -> 601 | R35: =Q35/$Q$42 -> 0.11445439 | S35: =((H35/C35)^(1/5))-1 -> 0.01955878 | U35: Rent and Rates | V35: =SUM(I35:M35) -> 822 | W35: =V35/$V$42 -> 0.14733823 | X35: =((M35/H35)^(1/5))-1 -> 0.051367684
B36: Central Support Services | C36: 123 | D36: 110 | E36: 125 | F36: 123 | G36: 143 | H36: 111 | I36: 112 | J36: 111 | K36: 108 | L36: 107 | M36: 106 | P36: Central Support Services | Q36: =SUM(C36:G36) -> 624 | R36: =Q36/$Q$42 -> 0.11883451 | S36: =((H36/C36)^(1/5))-1 -> -0.020321508 | U36: Central Support Services | V36: =SUM(I36:M36) -> 544 | W36: =V36/$V$42 -> 0.097508514 | X36: =((M36/H36)^(1/5))-1 -> -0.0091758639
B37: Rail | C37: 73 | D37: 77 | E37: 75 | F37: 66 | G37: 66 | H37: 67 | I37: 60 | J37: 59 | K37: 59 | L37: 60 | M37: 60 | P37: Rail | Q37: =SUM(C37:G37) -> 357 | R37: =Q37/$Q$42 -> 0.06798705 | S37: =((H37/C37)^(1/5))-1 -> -0.017007083 | U37: Rail | V37: =SUM(I37:M37) -> 298 | W37: =V37/$V$42 -> 0.05341459 | X37: =((M37/H37)^(1/5))-1 -> -0.021827859
B38: Commercial Expenditure | C38: 42 | D38: 56 | E38: 45 | F38: 44 | G38: 46 | H38: 48 | I38: 51 | J38: 52 | K38: 50 | L38: 51 | M38: 51 | P38: Commercial Expenditure | Q38: =SUM(C38:G38) -> 233 | R38: =Q38/$Q$42 -> 0.0443725 | S38: =((H38/C38)^(1/5))-1 -> 0.027066087 | U38: Commercial Expenditure | V38: =SUM(I38:M38) -> 255 | W38: =V38/$V$42 -> 0.045707116 | X38: =((M38/H38)^(1/5))-1 -> 0.012198729
B39: Other | C39: 159 | D39: 153 | E39: 146 | F39: 156 | G39: 166 | H39: 126 | I39: 117 | J39: 113 | K39: 114 | L39: 114 | M39: 112 | P39: Other | Q39: =SUM(C39:G39) -> 780 | R39: =Q39/$Q$42 -> 0.14854313 | S39: =((H39/C39)^(1/5))-1 -> -0.045458787 | U39: Other | V39: =SUM(I39:M39) -> 570 | W39: =V39/$V$42 -> 0.10216885 | X39: =((M39/H39)^(1/5))-1 -> -0.023281316
B40: Pensions | C40: 35 | D40: 26 | E40: 33 | F40: 36 | G40: 32 | H40: 34 | I40: 78 | J40: 76 | K40: 74 | L40: 73 | M40: 72 | P40: Pensions | Q40: =SUM(C40:G40) -> 162 | R40: =Q40/$Q$42 -> 0.030851266 | S40: =((H40/C40)^(1/5))-1 -> -0.0057807343 | U40: Pensions | V40: =SUM(I40:M40) -> 373 | W40: =V40/$V$42 -> 0.06685786 | X40: =((M40/H40)^(1/5))-1 -> 0.16190525
B42: Total | C42: =SUM(C31:C41) -> 1066 | D42: =SUM(D31:D41) -> 1077 | E42: =SUM(E31:E41) -> 1020 | F42: =SUM(F31:F41) -> 1024 | G42: =SUM(G31:G41) -> 1064 | H42: =SUM(H31:H41) -> 1036 | I42: =SUM(I31:I41) -> 1135 | J42: =SUM(J31:J41) -> 1133 | ... M42: =SUM(M31:M41) -> 1099 | P42: Total | Q42: =SUM(C42:G42) -> 5251 | R42: =Q42/$Q$42 -> 1 | S42: =((H42/C42)^(1/5))-1 -> -0.0056929697 | U42: Total | V42: =SUM(I42:M42) -> 5579 | W42: =V42/$V$42 -> 1 | X42: =((M42/H42)^(1/5))-1 -> 0.011876681
B43: Impact of T1 Closure | K43: -31 | L43: -32 | M43: -32 | U43: Impact of T1 Closure | V43: =SUM(I43:M43) -> -95
B44: SQR at 5 mins queuing in transfers | I44: 5 | J44: 5 | K44: 5 | L44: 5 | M44: 5 | U44: SQR at 5 mins queuing in transfers | V44: =SUM(I44:M44) -> 25
B45: Increase opex saving by 0.2% | I45: -3 | J45: -5 | K45: -8 | L45: -11 | M45: -14 | U45: Increase opex saving by 0.2% | V45: =SUM(I45:M45) -> -41
B46: Total Q6 after Adjustments | C46: =SUM(C42:C45) -> 1066 | D46: =SUM(D42:D45) -> 1077 | E46: =SUM(E42:E45) -> 1020 | F46: =SUM(F42:F45) -> 1024 | G46: =SUM(G42:G45) -> 1064 | H46: =SUM(H42:H45) -> 1036 | I46: =SUM(I42:I45) -> 1137 | J46: =SUM(J42:J45) -> 1133 | ... M46: =SUM(M42:M45) -> 1058 | U46: Total Q6 after Adjustments | V46: =SUM(I46:M46) -> 5468 | X46: =((M46/H46)^(1/5))-1 -> 0.0042114814
B48: Passengers (m) | C48: 65.9 | D48: 66.1 | E48: 66.1 | F48: 70.1 | G48: 69.2 | H48: 69.1 | I48: 69.2 | J48: 70.1 | K48: 71.1 | L48: 71.8 | M48: 72.6 | P48: Passengers (m) | Q48: =SUM(C48:H48) -> 406.5 | S48: =((H48/C48)^(1/5))-1 -> 0.0095283664 | U48: Passengers (m) | V48: =SUM(I48:M48) -> 354.8 | X48: =((M48/H48)^(1/5))-1 -> 0.0099310268
B49: Total opex / passenger | C49: =C46/C48 -> 16.176024 | D49: =D46/D48 -> 16.293495 | E49: =E46/E48 -> 15.431165 | F49: =F46/F48 -> 14.607703 | G49: =G46/G48 -> 15.375723 | H49: =H46/H48 -> 14.992764 | I49: =I46/I48 -> 16.430636 | J49: =J46/J48 -> 16.162625 | ... M49: =M46/M48 -> 14.573003 | P49: Total opex / passenger | Q49: =Q42/Q48 -> 12.917589 | S49: =((H49/C49)^(1/5))-1 -> -0.015077671 | U49: Total opex / passenger | V49: =V46/V48 -> 15.411499 | X49: =((M49/H49)^(1/5))-1 -> -0.005663303
...

Sheet HAL - fBP
B2: Heathrow - Full Business Plan - January 2013
B4: January 2013 FBP Forecast | C4: Q5 | H4: Q5+1 | I4: Q6 | P4: January 2013 FBP Forecast - Summary - Q5+1 | U4: January 2013 FBP Forecast - Summary Q6
B5: £m nominal | C5: 2008/09 | D5: 2009/10 | E5: 2010/11 | F5: 2011/12 | G5: 2012/13 | H5: 2013/14 | I5: 2014/15 | J5: 2015/16 | K5: 2016/17 | L5: 2017/18 | M5: 2018/19 | P5: £m nominal | Q5: Total Q5+1 | R5: % of Total | S5: CAGR (Q5+1) | U5: £m nominal | V5: Total Q6 | W5: % of Total | X5: CAGR (Q6)
B6: =B28 -> Security Costs (includes police) | C6: =C28*C$24 -> 160.7284 | D6: =D28*D$24 -> 153.91017 | E6: =E28*E$24 -> 155.53706 | F6: =F28*F$24 -> 164.2 | G6: =G28*G$24 -> 167.4178 | H6: =H28*H$24 -> 163.8739 | I6: =I28*I$24 -> 173.35171 | J6: =J28*J$24 -> 171.47402 | ... M6: =M28*M$24 -> 162.89692 | P6: =B6 -> Security Costs (includes police) | Q6: =SUM(C6:H6) -> 965.66734 | R6: =Q6/$Q$17 -> 0.15746642 | S6: =((H6/C6)^(1/5))-1 -> 0.003883773 | U6: =P6 -> Security Costs (includes police) | V6: =SUM(I6:M6) -> 831.70118 | W6: =V6/$V$17 -> 0.13780319 | X6: =((M6/H6)^(1/5))-1 -> -0.0011952164
B7: =B29 -> Total Operational Staff | C7: =C29*C$24 -> 56.727671 | D7: =D29*D$24 -> 48.818525 | E7: =E29*E$24 -> 52.577252 | F7: =F29*F$24 -> 55.5 | G7: =G29*G$24 -> 66.183638 | H7: =H29*H$24 -> 76.404231 | I7: =I29*I$24 -> 74.324547 | J7: =J29*J$24 -> 71.456841 | ... M7: =M29*M$24 -> 71.963476 | P7: =B7 -> Total Operational Staff | Q7: =SUM(C7:H7) -> 356.21132 | R7: =Q7/$Q$17 -> 0.058085552 | S7: =((H7/C7)^(1/5))-1 -> 0.061364338 | U7: =P7 -> Total Operational Staff | V7: =SUM(I7:M7) -> 367.4493 | W7: =V7/$V$17 -> 0.060882066 | X7: =((M7/H7)^(1/5))-1 -> -0.011904446
B8: =B30 -> Facilities Management | C8: =C30*C$24 -> 155.91019 | D8: =D30*D$24 -> 161.18295 | E8: =E30*E$24 -> 150.86141 | F8: =F30*F$24 -> 161.1 | G8: =G30*G$24 -> 169.78887 | H8: =H30*H$24 -> 182.21092 | I8: =I30*I$24 -> 221.13178 | J8: =J30*J$24 -> 222.88262 | ... M8: =M30*M$24 -> 229.2306 | P8: =B8 -> Facilities Management | Q8: =SUM(C8:H8) -> 981.05433 | R8: =Q8/$Q$17 -> 0.1599755 | S8: =((H8/C8)^(1/5))-1 -> 0.031668051 | U8: =P8 -> Facilities Management | V8: =SUM(I8:M8) -> 1116.461 | W8: =V8/$V$17 -> 0.18498458 | X8: =((M8/H8)^(1/5))-1 -> 0.046983019
B9: =B31 -> Utilities | C9: =C31*C$24 -> 85.455146 | D9: =D31*D$24 -> 108.63713 | E9: =E31*E$24 -> 93.799343 | F9: =F31*F$24 -> 90.4 | G9: =G31*G$24 -> 87.523222 | H9: =H31*H$24 -> 100.53743 | I9: =I31*I$24 -> 110.72841 | J9: =J31*J$24 -> 118.04939 | ... M9: =M31*M$24 -> 129.4853 | P9: =B9 -> Utilities | Q9: =SUM(C9:H9) -> 566.35227 | R9: =Q9/$Q$17 -> 0.092352159 | S9: =((H9/C9)^(1/5))-1 -> 0.033041841 | U9: =P9 -> Utilities | V9: =SUM(I9:M9) -> 607.66167 | W9: =V9/$V$17 -> 0.10068245 | X9: =((M9/H9)^(1/5))-1 -> 0.051909894
B10: =B32 -> Rent and Rates | C10: =C32*C$24 -> 106.09165 | D10: =D32*D$24 -> 113.18261 | E10: =E32*E$24 -> 107.63546 | F10: =F32*F$24 -> 119.6 | G10: =G32*G$24 -> 130.61475 | H10: =H32*H$24 -> 131.52066 | I10: =I32*I$24 -> 151.79109 | J10: =J32*J$24 -> 159.93788 | ... M10: =M32*M$24 -> 213.56508 | P10: =B10 -> Rent and Rates | Q10: =SUM(C10:H10) -> 708.64514 | R10: =Q10/$Q$17 -> 0.11555513 | S10: =((H10/C10)^(1/5))-1 -> 0.043908788 | U10: =P10 -> Rent and Rates | V10: =SUM(I10:M10) -> 884.22362 | W10: =V10/$V$17 -> 0.14650555 | X10: =((M10/H10)^(1/5))-1 -> 0.10181137
B11: =B33 -> Other | C11: =C33*C$24 -> 141.63736 | D11: =D33*D$24 -> 136.00096 | E11: =E33*E$24 -> 135.68939 | F11: =F33*F$24 -> 148.9 | G11: =G33*G$24 -> 141.33609 | H11: =H33*H$24 -> 129.62373 | I11: =I33*I$24 -> 131.7473 | J11: =J33*J$24 -> 133.39357 | ... M11: =M33*M$24 -> 145.15082 | P11: =B11 -> Other | Q11: =SUM(C11:H11) -> 833.18752 | R11: =Q11/$Q$17 -> 0.13586361 | S11: =((H11/C11)^(1/5))-1 -> -0.017570625 | U11: =P11 -> Other | V11: =SUM(I11:M11) -> 688.26758 | W11: =V11/$V$17 -> 0.11403791 | X11: =((M11/H11)^(1/5))-1 -> 0.02288544
B12: =B34 -> Commercial | C12: =C34*C$24 -> 35.818433 | D12: =D34*D$24 -> 47.636698 | E12: =E34*E$24 -> 40.363298 | F12: =F34*F$24 -> 42.6 | G12: =G34*G$24 -> 49.070735 | H12: =H34*H$24 -> 51.322566 | I12: =I34*I$24 -> 51.572134 | J12: =J34*J$24 -> 52.976624 | ... M12: =M34*M$24 -> 59.847177 | P12: =B12 -> Commercial | Q12: =SUM(C12:H12) -> 266.81173 | R12: =Q12/$Q$17 -> 0.04350762 | S12: =((H12/C12)^(1/5))-1 -> 0.074583965 | U12: =P12 -> Commercial | V12: =SUM(I12:M12) -> 274.68601 | W12: =V12/$V$17 -> 0.04551227 | X12: =((M12/H12)^(1/5))-1 -> 0.031209869
B13: =B35 -> Rail | C13: =C35*C$24 -> 64.727727 | D13: =D35*D$24 -> 68.000478 | E13: =E35*E$24 -> 68.989751 | F13: =F35*F$24 -> 64.2 | G13: =G35*G$24 -> 65.5651 | H13: =H35*H$24 -> 66.392642 | I13: =I35*I$24 -> 62.081582 | J13: =J35*J$24 -> 63.280745 | ... M13: =M35*M$24 -> 67.312776 | P13: =B13 -> Rail | Q13: =SUM(C13:H13) -> 397.8757 | R13: =Q13/$Q$17 -> 0.064879549 | S13: =((H13/C13)^(1/5))-1 -> 0.0050922375 | U13: =P13 -> Rail | V13: =SUM(I13:M13) -> 323.81789 | W13: =V13/$V$17 -> 0.053652851 | X13: =((M13/H13)^(1/5))-1 -> 0.0027565541
B14: =B36 -> Central Support Services | C14: =C36*C$24 -> 108.72804 | D14: =D36*D$24 -> 96.273403 | E14: =E36*E$24 -> 113.93328 | F14: =F36*F$24 -> 118.9 | G14: =G36*G$24 -> 119.9965 | H14: =H36*H$24 -> 127.83218 | I14: =I36*I$24 -> 116.90406 | J14: =J36*J$24 -> 114.80135 | ... M14: =M36*M$24 -> 126.42563 | P14: =B14 -> Central Support Services | Q14: =SUM(C14:H14) -> 685.66341 | R14: =Q14/$Q$17 -> 0.11180761 | S14: =((H14/C14)^(1/5))-1 -> 0.032903459 | U14: =P14 -> Central Support Services | V14: =SUM(I14:M14) -> 599.33319 | W14: =V14/$V$17 -> 0.099302523 | X14: =((M14/H14)^(1/5))-1 -> -0.0022103715
B15: =B37 -> Pensions | C15: =C37*C$24 -> 42.091205 | D15: =D37*D$24 -> 50.909448 | E15: =E37*E$24 -> 60.020129 | F15: =F37*F$24 -> 64.1 | G15: =G37*G$24 -> 77.008065 | H15: =H37*H$24 -> 76.931157 | I15: =I37*I$24 -> 78.44165 | J15: =J37*J$24 -> 67.648796 | ... M15: =M37*M$24 -> 64.987425 | P15: =B15 -> Pensions | Q15: =SUM(C15:H15) -> 371.06 | R15: =Q15/$Q$17 -> 0.060506851 | S15: =((H15/C15)^(1/5))-1 -> 0.12818983 | U15: =P15 -> Pensions | V15: =SUM(I15:M15) -> 341.82613 | W15: =V15/$V$17 -> 0.056636605 | X15: =((M15/H15)^(1/5))-1 -> -0.033180473
B17: Total | C17: =C39*C$24 -> 957.91582 | D17: =D39*D$24 -> 984.55237 | E17: =E39*E$24 -> 979.40637 | F17: =F39*F$24 -> 1029.5 | G17: =G39*G$24 -> 1074.5048 | H17: =H39*H$24 -> 1106.6494 | I17: =I39*I$24 -> 1172.0743 | J17: =J39*J$24 -> 1175.9018 | ... M17: =M39*M$24 -> 1270.8652 | P17: =B17 -> Total | Q17: =SUM(C17:H17) -> 6132.5287 | R17: =Q17/$Q$17 -> 1 | S17: =((H17/C17)^(1/5))-1 -> 0.029287132 | U17: =P17 -> Total | V17: =SUM(I17:M17) -> 6035.4276 | W17: =V17/$V$17 -> 1 | X17: =((M17/H17)^(1/5))-1 -> 0.028058636
B19: Man Years | C19: =C55 -> 7907 | D19: =D55 -> 7406 | E19: =E55 -> 7457 | F19: =F55 -> 7464 | G19: =G55 -> 7152 | H19: =H55 -> 6893 | I19: =I55 -> 6552 | J19: =J55 -> 6362 | ... M19: =M55 -> 5797 | P19: Man Years | Q19: =SUM(C19:H19) -> 44279 | S19: =((H19/C19)^(1/5))-1 -> -0.027075123 | U19: =P19 -> Man Years | V19: =V41 -> 30616 | X19: =((M19/H19)^(1/5))-1 -> -0.034040308
B20: Passengers (m) | C20: =C42 -> 65.9 | D20: =D42 -> 66.1 | E20: =E42 -> 66.1 | F20: =F42 -> 70.067623 | G20: =G42 -> 69.6 | H20: =H42 -> 68.8 | I20: =I42 -> 69.494122 | J20: =J42 -> 70.256156 | ... M20: =M42 -> 72.602541 | P20: =B20 -> Passengers (m) | Q20: =SUM(C20:H20) -> 406.56762 | S20: =((H20/C20)^(1/5))-1 -> 0.0086502598 | U20: =P20 -> Passengers (m) | V20: =V42 -> 355.19129 | X20: =((M20/H20)^(1/5))-1 -> 0.010817324
B21: Total opex / passenger | C21: =C17/C20 -> 14.5359 | D21: =D17/D20 -> 14.894892 | E21: =E17/E20 -> 14.81704 | F21: =F17/F20 -> 14.692949 | G21: =G17/G20 -> 15.438287 | H21: =H17/H20 -> 16.085021 | I21: =I17/I20 -> 16.865804 | J21: =J17/J20 -> 16.73735 | ... M21: =M17/M20 -> 17.504418 | P21: =B21 -> Total opex / passenger | Q21: =Q17/Q20 -> 15.083662 | S21: =((H21/C21)^(1/5))-1 -> 0.020459889 | U21: =P21 -> Total opex / passenger | V21: =V17/V20 -> 16.992048 | X21: =((M21/H21)^(1/5))-1 -> 0.017056803
B24: Price Base Conversion 11/12 to Nominal | C24: =RPI!$T101/RPI!$T$103 -> 0.90909729 | D24: =RPI!$T101/RPI!$T$103 -> 0.90909729 | E24: =RPI!$T102/RPI!$T$103 -> 0.95421509 | F24: =RPI!$T103/RPI!$T$103 -> 1 | G24: =RPI!$V104/RPI!$T$103 -> 1.0308978 | H24: =RPI!$V105/RPI!$T$103 -> 1.0538515 | I24: =RPI!$V106/RPI!$T$103 -> 1.0834482 | J24: =RPI!$V107/RPI!$T$103 -> 1.1200132 | K24: =RPI!$V108/RPI!$T$103 -> 1.1536136 | L24: =RPI!$V109/RPI!$T$103 -> 1.188222 | M24: =RPI!$V110/RPI!$T$103 -> 1.2238686
B26: January 2013 FBP Forecast | C26: Q5 | H26: Q5+1 | I26: Q6 | P26: January 2013 FBP Forecast - Summary - Q5+1 | U26: January 2013 FBP Forecast - Summary Q6
B27: £m 2011/12 prices | C27: 2008/09 | D27: 2009/10 | E27: 2010/11 | F27: 2011/12 | G27: 2012/13 | H27: 2013/14 | I27: 2014/15 | J27: 2015/16 | K27: 2016/17 | L27: 2017/18 | M27: 2018/19 | P27: £m 2011/12 prices | Q27: Total Q5+1 | R27: % of Total | S27: CAGR (Q5+1) | U27: £m 2011/12 prices | V27: Total Q6 | W27: % of Total | X27: CAGR (Q6)
B28: Security Costs (includes police) | C28: 176.8 | D28: 169.3 | E28: 163 | F28: 164.2 | G28: 162.4 | H28: 155.5 | I28: 160 | J28: 153.1 | K28: 142.2 | L28: 134.6 | M28: 133.1 | P28: =B28 -> Security Costs (includes police) | Q28: =SUM(C28:H28) -> 991.2 | R28: =Q28/$Q$39 -> 0.15770883 | S28: =((H28/C28)^(1/5))-1 -> -0.025347892 | U28: =P28 -> Security Costs (includes police) | V28: =SUM(I28:M28) -> 723 | W28: =V28/$V$39 -> 0.13813527 | X28: =((M28/H28)^(1/5))-1 -> -0.030630095
