Workbook

Sheet Cover
A2: Within this Excel workbook is a worksheet for data entry. Click on the FinReview tab, and enter the CDN for your school district. Then enter the student and staff estimates, the financial categories/object code amounts, and the total revenues and total general fund amounts. The worksheet will automatically calculate the status.

Sheet FinReview
B2: CDN: | F2: District Name: | H2: =LOOKUP(FinReview!D2,TEAData!A2:A1050,TEAData!B2:B1050) -> #N/A
B5: Category 1. Student-to-Staff Ratio Outside Norm or Declining | D5: 2011-2012 Estimate | E5: 2010-2011 Actual | J5: Comments
B6: Enrollment | E6: =LOOKUP(FinReview!D2,TEAData!A2:A1050,TEAData!C2:C1050) -> #N/A
B7: WADA | E7: =LOOKUP(FinReview!D2,TEAData!A2:A1050,TEAData!D2:D1050) -> #N/A
B8: All Staff FTE | E8: =LOOKUP(FinReview!D2,TEAData!A2:A1050,TEAData!E2:E1050) -> #N/A
B9: Teacher FTE | E9: =LOOKUP(FinReview!D2,TEAData!A2:A1050,TEAData!F2:F1050) -> #N/A
D10: 2011-2012 Estimate | E10: 2010-2011 Actual | F10: Average per Group | H10: Indicator Description | I10: Indicators
B11: a. WADA-to-All-Staff-FTE Ratio | D11: =D7/D8 -> #DIV/0! | E11: =E7/E8 -> #N/A | F11: =IF(FinReview!E6>=Average!B12,Average!C12,IF(FinReview!E6>=Average!B11,Average!C11,IF(FinReview!E6>=Average!B10,Average!C10,IF(FinReview!E6>=Average!B9,Average!C9,IF(FinReview!E6>=Average!B8,Average!C8,IF(FinReview!E6>=Average!B7,Average!C7, IF(FinReview!E6>=Average!B6,Average!C6,IF(FinReview!E6>=Average!B5,Average!C5,IF(FinReview!E6>=Average!B4,Average!C4,IF(FinReview!E6>=Average!B3,Average!C3,IF(FinReview!E6>=Average!B2,Average!C2,0))))))))))) -> #N/A | H11: < 85% of group avg or decline of over 7% from prior year | I11: =IF(OR(D11<F11*0.85,D11<E11-(E11*0.07)),"Yes","No") -> #DIV/0! | J11: Any "Yes" for Category 1
B12: b. Enrollment-to-Teacher-FTE Ratio | D12: =D6/D9 -> #DIV/0! | E12: =E6/E9 -> #N/A | F12: =IF(FinReview!E6>=Average!B12,Average!D12,IF(FinReview!E6>=Average!B11,Average!D11,IF(FinReview!E6>=Average!B10,Average!D10,IF(FinReview!E6>=Average!B9,Average!D9,IF(FinReview!E6>=Average!B8,Average!D8,IF(FinReview!E6>=Average!B7,Average!D7,IF(FinReview!E6>=Average!B6,Average!D6,IF(FinReview!E6>=Average!B5,Average!D5,IF(FinReview!E6>=Average!B4,Average!D4,IF(FinReview!E6>=Average!B3,Average!D3,IF(FinReview!E6>=Average!B2,Average!D2,0))))))))))) -> #N/A | H12: < 85% of group avg or decline of over 7% from prior year | I12: =IF(OR(D12<F12*0.85,D12<E12-(E12*0.07)),"Yes","No") -> #DIV/0! | J12: =IF(COUNTIF(I11:I12,"Yes")>1,"Yes","No") -> No
B15: Category 2. General Fund Expenditures Exceeding Revenues | D15: 2011-2012 Amount | E15: 2010-2011 Actual Amount | F15: 2010-2011 Budget Amount | G15: Suggested Difference | H15: 2009-2010 Actual Amount | I15: 2009-2010 Budget Amount | J15: Comments
B17: Payroll
B18: Object codes 6110-6149
B20: Contract Costs
B21: Object code series 6200
B23: Supplies and Materials
B24: Object code series 6300 | G24: =#REF!*#REF! -> #REF!
B26: Other Operating
B27: Object code series 6400
B29: Debt Service
B30: Object code series 6500 | G30: =#REF!*#REF! -> #REF!
B32: Capital Outlay
B33: Object code series 6600
B35: Total Expenditures
D36: =SUM(D18+D21+D24+D27+D30+D33) -> 0 | E36: =SUM(E18+E21+E24+E27+E30+E33) -> 0 | F36: =LOOKUP(FinReview!D2,TEAData!A2:A1050,TEAData!J2:J1050) -> #N/A | G36: =#REF!*#REF! -> #REF! | H36: =LOOKUP(FinReview!D2,TEAData!A2:A1050,TEAData!K2:K1050) -> #N/A | I36: =LOOKUP(FinReview!D2,TEAData!A2:A1050,TEAData!I2:I1050) -> #N/A
B38: a. Expenditures exceed revenues by more than 6%. | I38: =IF(E36>E46*1.06,"Yes","No") -> No
B39: b. Expenditures exceed revenues by more than 4% and exceeded revenues by more than 3% in the prior year. | I39: =IF(AND(E36>E46*1.04,H36>H46*1.03),"Yes","No") -> #N/A | J39: Any "Yes" for Category 2
B40: c. Expenditures exceed revenues by any amount, and the district has a prior year end-of-year fund balance that has declined from the year before and that is less than 4% of the district's general fund expenditures. | I40: =IF(AND(E36>E46,E49<H49,E49<E36*0.04),"Yes","No") -> #N/A | J40: =IF(COUNTIF(I38:I40,"Yes")>1,"Yes","No") -> No
B41: Category 3. Actual Expenditures Consistently Exceed Budgeted Expenditures
B42: a. Actual expenditures exceeded budgeted expenditures by more than 10% in the prior year. | I42: =IF(E36>F36*1.1,"Yes","No") -> #N/A | J42: Any "Yes" for Category 3
B43: b. Actual expenditures exceeded budgeted expenditures by more than 6% in the prior year, and actual expenditures exceeded budgeted expenditures by more than 4% two years prior. | I43: =IF(AND(E36>F36*1.06,H36>I36*1.04),"Yes","No") -> #N/A | J43: =IF(COUNTIF(I42:I43,"Yes")>1,"Yes","No") -> No
B44: Category 4. Declining or Low General Fund Assigned and Unassigned Balance
B45: Total Revenues
F46: =LOOKUP(FinReview!D2,TEAData!A2:A1050,TEAData!M2:M1050) -> #N/A | G46: =#REF!*#REF! -> #REF! | H46: =LOOKUP(FinReview!D2,TEAData!A2:A1050,TEAData!N2:N1050) -> #N/A | I46: =LOOKUP(FinReview!D2,TEAData!A2:A1050,TEAData!M2:M1050) -> #N/A
B48: Total General Fund Unreserved/Undesignated Fund Balance | J48: Any "Yes" for Category 4
H49: =LOOKUP(FinReview!D2,TEAData!A2:A1050,TEAData!O2:O1050) -> #N/A | J49: =IF(COUNTIF(I52:I54,"Yes")>1,"Yes","No") -> No
J51: Additional Questions
B52: a. Prior year end-of-year fund balance declined from the year before, and fund balance is less than 6.25% of the district's general fund expenditures. | I52: =IF(AND(E49<H49,E49<E36*0.0625),"Yes","No") -> #N/A | J52: Did your district have a general fund balance of less than 2% of total expenditures for general fund function codes 11-61 in the prior fiscal year?
B53: b. Prior year end-of-year fund balance declined from the year before by more than 25%, and the fund balance is less than 12.5% (1.5 months) of the district's general fund expenditures. | I53: =IF(AND(E49<H49-(H49*0.25),E49<E36-(E36*0.125)),"Yes","No") -> #N/A | J53: Has your district declared financial exigency within the past two years?
B54: c. Prior year end-of-year fund balance is less than 1% of the district's general fund expenditures. | I54: =IF(E49<E36*0.01,"Yes","No") -> No | J54: How many superintendents has your district had in the last five years?
J55: How many business managers has your district had in the last five years?
...

Sheet TEAData
A1: CDN | B1: District Name | C1: 2010-2011 Enrollment | D1: 2010-2011 WADA | E1: 2010-2011 Staff FTE | F1: 2010-2011 Teacher FTE | G1: 2010-2011 WADA-to-All-Staff-FTE Avg | H1: 2010-2011 Enrollment-to-Teacher-FTE Avg | I1: 2009-2010 Budgeted Expenditures | J1: 2010-2011 Budgeted Expenditures | K1: 2009-2010 Actual Expenditures | L1: 2009-2010 Budget Revenues | M1: 2010-2011 Budget Revenues | N1: 2009-2010 Actual Revenues | O1: 2009-2010 General Fund Balance
A2: 001902 | B2: CAYUGA ISD | C2: 606 | D2: 908.278 | E2: 156.5504 | F2: 55.8524 | G2: 5.8018248 | H2: 10.850026 | I2: 6910280 | J2: 5622144 | K2: 6667910 | L2: 5695458 | M2: 5795538 | N2: 6135674 | O2: 1771622
A3: 001903 | B3: ELKHART ISD | C3: 1325 | D3: 1688.736 | E3: 182.9755 | F3: 103.7194 | G3: 9.2293012 | H3: 12.774852 | I3: 9344097 | J3: 9400500 | K3: 9680287 | L3: 9632124 | M3: 10089820 | N3: 10561290 | O3: 1063981
A4: 001904 | B4: FRANKSTON ISD | C4: 798 | D4: 1159.894 | E4: 131.7478 | F4: 69.6002 | G4: 8.8038965 | H4: 11.465484 | I4: 6312480 | J4: 6488296 | K4: 6443795 | L4: 6409357 | M4: 6778618 | N4: 6660275 | O4: 728191
A5: 001906 | B5: NECHES ISD | C5: 370 | D5: 581.534 | E5: 51.8716 | F5: 31.3738 | G5: 11.211029 | H5: 11.79328 | I5: 3054431 | J5: 2935380 | K5: 3213495 | L5: 3182756 | M5: 3155266 | N5: 3238229 | O5: 529562
A6: 001907 | B6: PALESTINE ISD | C6: 3241 | D6: 4029.539 | E6: 463.1022 | F6: 244.2746 | G6: 8.7011873 | H6: 13.267855 | I6: 25492359 | J6: 25587940 | K6: 24257452 | L6: 25688607 | M6: 24753649 | N6: 25397890 | O6: 4197116
A7: 001908 | B7: WESTWOOD ISD | C7: 1720 | D7: 2211.193 | E7: 237.2878 | F7: 130.7373 | G7: 9.3186123 | H7: 13.156154 | I7: 14466811 | J7: 13459352 | K7: 12403332 | L7: 11760976 | M7: 12758950 | N7: 13069965 | O7: 2192419
A8: 001909 | B8: SLOCUM ISD | C8: 404 | D8: 629.141 | E8: 60.6607 | F8: 38.4786 | G8: 10.371476 | H8: 10.499342 | I8: 3063668 | J8: 3155494 | K8: 2947201 | L8: 3182297 | M8: 3177800 | N8: 3592380 | O8: 2088832
A9: 002901 | B9: ANDREWS ISD | C9: 3242 | D9: 3979.581 | E9: 460.9809 | F9: 235.6247 | G9: 8.6328544 | H9: 13.759169 | I9: 28953998 | J9: 29429058 | K9: 28010985 | L9: 29586609 | M9: 29583213 | N9: 29009472 | O9: 8907687
A10: 003902 | B10: HUDSON ISD | C10: 2654 | D10: 3293.347 | E10: 348.4756 | F10: 180.6971 | G10: 9.4507248 | H10: 14.687563 | I10: 17681509 | J10: 19579900 | K10: 21231414 | L10: 17756495 | M10: 20330805 | N10: 19008793 | O10: 2517940
A11: 003903 | B11: LUFKIN ISD | C11: 8588 | D11: 10644.461 | E11: 1036.5399 | F11: 613.6067 | G11: 10.269225 | H11: 13.995936 | I11: 59011799 | J11: 59595797 | K11: 60523600 | L11: 59900574 | M11: 59247910 | N11: 60767533 | O11: 18209029
A12: 003904 | B12: HUNTINGTON ISD | C12: 1738 | D12: 2195.716 | E12: 260.7506 | F12: 124.7294 | G12: 8.4207515 | H12: 13.934165 | I12: 11088271 | J12: 12826302 | K12: 12150844 | L12: 11162763 | M12: 11921650 | N12: 12179796 | O12: 1289029
A13: 003905 | B13: DIBOLL ISD | C13: 1989 | D13: 2592.935 | E13: 288.5141 | F13: 141.4957 | G13: 8.9872037 | H13: 14.056964 | I13: 13323082 | J13: 13482023 | K13: 13334689 | L13: 13391086 | M13: 13589033 | N13: 14284037 | O13: 3274920
... A435: 103902 | B435: HARTLEY ISD | C435: 184 | D435: 357.122 | E435: 33.5018 | F435: 20.5018 | G435: 10.659785 | H435: 8.9748217 | I435: 2209839 | J435: 2440431 | K435: 2422242 | L435: 2463879 | M435: 2262118 | N435: 2296831 | O435: 888949
A436: 104901 | B436: HASKELL CISD | C436: 653 | D436: 1121.545 | E436: 125.1179 | F436: 62.9813 | G436: 8.9639052 | H436: 10.368157 | I436: 7633782 | J436: 7446633 | K436: 9521717 | L436: 7811782 | M436: 7645412 | N436: 7805828
A437: 104903 | B437: RULE ISD | C437: 140 | D437: 242.058 | E437: 30.7607 | F437: 18.0934 | G437: 7.8690667 | H437: 7.7376281 | I437: 1510456 | J437: 1625327 | K437: 1580559 | L437: 1563731 | M437: 1578364 | N437: 1576914 | O437: 193463
A438: 104907 | B438: PAINT CREEK ISD | C438: 169 | D438: 273.16 | E438: 25.6991 | F438: 15.9996 | G438: 10.629166 | H438: 10.562764 | I438: 1471172 | J438: 1527330 | K438: 1475075 | L438: 1642931 | M438: 1692866 | N438: 1581441 | O438: 374777
A439: 105902 | B439: SAN MARCOS CISD | C439: 7377 | D439: 8842.951 | E439: 1116.6499 | F439: 540.9171 | G439: 7.9191795 | H439: 13.637949 | I439: 56886796 | J439: 58434749 | K439: 54810211 | L439: 56730993 | M439: 59442653 | N439: 58004100 | O439: 10556301
A440: 105904 | B440: DRIPPING SPRINGS ISD | C440: 4468 | D440: 5035.432 | E440: 598.643 | F440: 282.458 | G440: 8.4114105 | H440: 15.818281 | I440: 34892856 | J440: 35532953 | K440: 32121563 | L440: 32185851 | M440: 31895563 | N440: 32618714 | O440: 17810348
A441: 105905 | B441: WIMBERLEY ISD | C441: 2002 | D441: 2466.897 | E441: 293.919 | F441: 149.7132 | G441: 8.3931185 | H441: 13.372234 | I441: 15972159 | J441: 16563114 | K441: 15765663 | L441: 16134443 | M441: 16761123 | N441: 16566375 | O441: 806174
A442: 105906 | B442: HAYS CISD | C442: 15262 | D442: 18152.122 | E442: 2211.6654 | F442: 1042.9605 | G442: 8.2074449 | H442: 14.633344 | I442: 111644899 | J442: 117688749 | K442: 110372408 | L442: 111016649 | M442: 115932492 | N442: 114608504 | O442: 23945354
A443: 106901 | B443: CANADIAN ISD | C443: 848 | D443: 1251.213 | E443: 151.6992 | F443: 81.8753 | G443: 8.2479868 | H443: 10.357214 | I443: 9766560 | J443: 9662289 | K443: 8716322 | L443: 4651839 | M443: 10287074 | N443: 359266 | O443: 2159340
A444: 107901 | B444: ATHENS ISD | C444: 3430 | D444: 4351.863 | E444: 475.9727 | F444: 234.7938 | G444: 9.1430937 | H444: 14.608563 | I444: 26035758 | J444: 24466548 | K444: 26372071 | L444: 24422011 | M444: 25122737 | N444: 25474265 | O444: 5270528
A445: 107902 | B445: BROWNSBORO ISD | C445: 2878 | D445: 3649.806 | E445: 393.0951 | F445: 194.351 | G445: 9.2847914 | H445: 14.808259 | I445: 17583193 | J445: 19415290 | K445: 19305055 | L445: 19134887 | M445: 19943847 | N445: 20760062 | O445: 4610889
A446: 107904 | B446: CROSS ROADS ISD | C446: 609 | D446: 948.986 | E446: 84.4806 | F446: 45.6159 | G446: 11.233183 | H446: 13.350608 | I446: 4856174 | J446: 5031043 | K446: 4820130 | L446: 5384578 | M446: 5265348 | N446: 5423544 | O446: 1303059
A447: 107905 | B447: EUSTACE ISD | C447: 1478 | D447: 1950.156 | E447: 239.0162 | F447: 107.8194 | G447: 8.1590955 | H447: 13.708108 | I447: 10780342 | J447: 9958843 | K447: 11539112 | L447: 10848584 | M447: 10445005 | N447: 11123398 | O447: 2036775
A448: 107906 | B448: MALAKOFF ISD | C448: 1264 | D448: 1747.51 | E448: 227.2011 | F448: 107.8036 | G448: 7.691468 | H448: 11.725026 | I448: 11478869 | J448: 11706049 | K448: 10948765 | L448: 12005708 | M448: 12381900 | N448: 12063926 | O448: 2663808
... A588: 138903 | B588: MUNDAY CISD | C588: 364 | D588: 589.238 | E588: 67.2584 | F588: 40.0424 | G588: 8.7608091 | H588: 9.0903642 | I588: 3788103 | J588: 3904606 | K588: 3582851 | L588: 3978918 | M588: 3801647 | N588: 4186036 | O588: 709893
A589: 138904 | B589: BENJAMIN ISD | C589: 75 | D589: 142.802 | E589: 17.1207 | F589: 10.8801 | G589: 8.3408973 | H589: 6.893319 | I589: 1210699 | J589: 1115228 | K589: 1102258 | L589: 995604 | M589: 951109 | N589: 1019141
A590: 139905 | B590: CHISUM ISD | C590: 819 | D590: 1208.685 | E590: 138.7948 | F590: 72.9083 | G590: 8.7084314 | H590: 11.233289 | I590: 7325414 | J590: 7743969 | K590: 8159090 | L590: 7767500 | M590: 7790190 | N590: 7593672 | O590: 3089764
A591: 139908 | B591: ROXTON ISD | C591: 195 | D591: 327.341 | E591: 40.0751 | F591: 23.3451 | G591: 8.1681892 | H591: 8.3529306 | I591: 1926339 | J591: 2073886 | K591: 1905735 | L591: 2010982 | M591: 1941800 | N591: 2016039 | O591: 462697
A592: 139909 | B592: PARIS ISD | C592: 3777 | D592: 4659.553 | E592: 629.9201 | F592: 323.3027 | G592: 7.397054 | H592: 11.68255 | I592: 24791279 | J592: 28415882 | K592: 25507484 | L592: 22796333 | M592: 29296227 | N592: 27244357 | O592: 1320256
A593: 139911 | B593: NORTH LAMAR ISD | C593: 2900 | D593: 3722.887 | E593: 486.9185 | F593: 252.4462 | G593: 7.6458114 | H593: 11.487596 | I593: 20799797 | J593: 20902768 | K593: 20230513 | L593: 22094894 | M593: 22185430 | N593: 22516571 | O593: 6799620
A594: 139912 | B594: PRAIRILAND ISD | C594: 1130 | D594: 1602.701 | E594: 139.2815 | F594: 80.7185 | G594: 11.506919 | H594: 13.999269 | I594: 8436736 | J594: 8472729 | K594: 7523999 | L594: 8972739 | M594: 9270228 | N594: 9281610 | O594: 2398408
A595: 140901 | B595: AMHERST ISD | C595: 178 | D595: 304.149 | E595: 32.9204 | F595: 19.2243 | G595: 9.2389218 | H595: 9.2591148 | I595: 1646159 | J595: 1706533 | K595: 1701859 | L595: 1769453 | M595: 1786257 | N595: 1819859 | O595: 413267
A596: 140904 | B596: LITTLEFIELD ISD | C596: 1484 | D596: 1951.741 | E596: 202.149 | F596: 97.1531 | G596: 9.6549624 | H596: 15.27486 | I596: 9569290 | J596: 9671726 | K596: 9713914 | L596: 10175772 | M596: 10381487 | N596: 11202619 | O596: 8068992
A597: 140905 | B597: OLTON ISD | C597: 682 | D597: 1186.69 | E597: 132.1699 | F597: 64.5157 | G597: 8.9785193 | H597: 10.57107 | I597: 6659975 | J597: 7201869 | K597: 6346096 | L597: 6744196 | M597: 6868690 | N597: 6812038 | O597: 971821
A598: 140907 | B598: SPRINGLAKE-EARTH ISD | C598: 390 | D598: 658.753 | E598: 74.6144 | F598: 37.9544 | G598: 8.828765 | H598: 10.275488 | I598: 4099848 | J598: 4120383 | K598: 3684846 | L598: 3894698 | M598: 3793687 | N598: 4017824 | O598: 583702
A599: 140908 | B599: SUDAN ISD | C599: 428 | D599: 769.18 | E599: 68.3521 | F599: 38.5217 | G599: 11.253202 | H599: 11.110621 | I599: 5057213 | J599: 4582700 | K599: 4783593 | L599: 4684209 | M599: 4473516 | N599: 5057111 | O599: 1330470
A600: 141901 | B600: LAMPASAS ISD | C600: 3381 | D600: 4206.777 | E600: 496.7004 | F600: 223.314 | G600: 8.4694456 | H600: 15.140117 | I600: 24656703 | J600: 25538257 | K600: 24563930 | L600: 24836349 | M600: 25570198 | N600: 25761541 | O600: 11357754
...

Sheet Average
A1: Group | B1: Enrollment | C1: Statewide Average WADA-to-All-Staff Ratio | D1: Statewide Average Enrollment-to-Teacher-FTE Ratio
A2: 1 | B2: 1 | C2: 14.35 | D2: 8.3
A3: 2 | B3: 100 | C3: 9.1 | D3: 9.54
A4: 3 | B4: 250 | C4: 9.07 | D4: 10.8
A5: 4 | B5: 500 | C5: 9.32 | D5: 11.54
A6: 5 | B6: 1000 | C6: 9.07 | D6: 12.65
A7: 6 | B7: 1600 | C7: 8.72 | D7: 13.65
A8: 7 | B8: 3000 | C8: 8.78 | D8: 14.43
A9: 8 | B9: 5000 | C9: 8.81 | D9: 14.97
A10: 9 | B10: 10000 | C10: 9.02 | D10: 15.12
A11: 10 | B11: 25000 | C11: 9.47 | D11: 15.27
A12: 11 | B12: 50000 | C12: 9.41 | D12: 15.44
