Workbook

Sheet Non-shuttle Bids
B1: Non-shuttle Secondary Rail Car Market Bids ($) | P1: Non-shuttle Secondary Rail Car Market Bids ($) | AB1: Non-shuttle Secondary Rail Car Market Bids ($) | AN1: Non-shuttle Secondary Rail Car Market Bids ($)
B2: Data Sources: Atwood/Conagra, Harvest States Coop, James B. Joiner Co., Tradewest Brokerage Co.
B3: Data taken from secondary_premiums_all database that was prepared by Upper Great Plains Transportation Institute
B4: Weeks having no reported activity are represented by blanks. Bids submitted at par value are represented by 0.
D5: (Occasionally, the data will not correspond to what was reported in the Grain Transportation Report)
B6: GTR | C6: Week | D6: Jan. | H6: Feb. | L6: Mar. | P6: Apr. | T6: May. | X6: Jun. | AB6: Jul. | AF6: Aug. | AJ6: Sep. | AN6: Oct. | AR6: Nov. | AV6: Dec.
A7: Week | B7: Date | C7: Ending | D7: BNSF-GF | E7: UP-Pool | F7: Avg. | H7: BNSF-GF | I7: UP-Pool | J7: Avg. | L7: BNSF-GF | M7: UP-Pool | N7: Avg. | P7: BNSF-GF | Q7: UP-Pool | R7: Avg. | T7: BNSF-GF | U7: UP-Pool | V7: Avg. | X7: BNSF-GF | Y7: UP-Pool | Z7: Avg. | AB7: BNSF-GF | AC7: UP-Pool | AD7: Avg. | AF7: BNSF-GF | AG7: UP-Pool | AH7: Avg. | AJ7: BNSF-GF | AK7: UP-Pool | AL7: Avg. | AN7: BNSF-GF | AO7: UP-Pool | AP7: Avg. | AR7: BNSF-GF | AS7: UP-Pool | AT7: Avg. | AV7: BNSF-GF | AW7: UP-Pool | AX7: Avg.
A8: 18 | B8: =+B9-7 -> 35555 | C8: 35553 | T8: -95 | U8: -28 | V8: =AVERAGE(T8,U8) -> -61.5 | AF8: 0 | AG8: 2 | AH8: =AVERAGE(AF8,AG8) -> 1
A9: 19 | B9: =+B10-7 -> 35562 | C9: 35560
A10: 20 | B10: =+B11-7-1 -> 35569 | C10: 35567 | T10: -83 | U10: -20 | V10: =AVERAGE(T10,U10) -> -51.5 | X10: -42 | Y10: -19 | Z10: =AVERAGE(X10,Y10) -> -30.5 | AB10: -25 | AC10: -10 | AD10: =AVERAGE(AB10,AC10) -> -17.5 | AF10: -15 | AG10: 14 | AH10: =AVERAGE(AF10,AG10) -> -0.5
A11: 21 | B11: =+B12-7+1 -> 35577 | C11: 35574 | X11: -53 | Y11: -18 | Z11: =AVERAGE(X11,Y11) -> -35.5 | AB11: -43 | AC11: -13 | AD11: =AVERAGE(AB11,AC11) -> -28 | AF11: -24 | AG11: 9 | AH11: =AVERAGE(AF11,AG11) -> -7.5 | AJ11: 10 | AK11: 27 | AL11: =AVERAGE(AJ11,AK11) -> 18.5
A12: 22 | B12: =+B13-7 -> 35583 | C12: 35581 | X12: -112 | Y12: -23 | Z12: =AVERAGE(X12,Y12) -> -67.5 | AB12: -102 | AC12: -18 | AD12: =AVERAGE(AB12,AC12) -> -60 | AF12: -94 | AG12: 3 | AH12: =AVERAGE(AF12,AG12) -> -45.5 | AJ12: -6 | AK12: 23 | AL12: =AVERAGE(AJ12,AK12) -> 8.5
A13: 23 | B13: =+B14-7 -> 35590 | C13: 35588 | X13: -65 | Y13: -21 | Z13: =AVERAGE(X13,Y13) -> -43 | AB13: -86 | AC13: -11 | AD13: =AVERAGE(AB13,AC13) -> -48.5 | AF13: -66 | AG13: 10 | AH13: =AVERAGE(AF13,AG13) -> -28 | AJ13: -17 | AK13: 23 | AL13: =AVERAGE(AJ13,AK13) -> 3
A14: 24 | B14: =+B15-7 -> 35597 | C14: 35595 | AB14: -83 | AC14: -10 | AD14: =AVERAGE(AB14,AC14) -> -46.5 | AF14: -48 | AG14: 24 | AH14: =AVERAGE(AF14,AG14) -> -12 | AJ14: -10 | AK14: 33 | AL14: =AVERAGE(AJ14,AK14) -> 11.5 | AN14: 43 | AO14: 101 | AP14: =AVERAGE(AN14,AO14) -> 72
A15: 25 | B15: =+B16-7 -> 35604 | C15: 35602 | AB15: -41 | AC15: -14 | AD15: =AVERAGE(AB15,AC15) -> -27.5 | AF15: -19 | AG15: 22 | AH15: =AVERAGE(AF15,AG15) -> 1.5 | AJ15: 0 | AK15: 30 | AL15: =AVERAGE(AJ15,AK15) -> 15 | AN15: 77 | AO15: 110 | AP15: =AVERAGE(AN15,AO15) -> 93.5
A16: 26 | B16: =+B17-7 -> 35611 | C16: 35609 | AB16: -34 | AD16: =AVERAGE(AB16,AC16) -> -34 | AF16: -2 | AG16: 26 | AH16: =AVERAGE(AF16,AG16) -> 12 | AJ16: 10 | AK16: 38 | AL16: =AVERAGE(AJ16,AK16) -> 24 | AN16: 96 | AO16: 143 | AP16: =AVERAGE(AN16,AO16) -> 119.5
A17: 27 | B17: =+B18-7 -> 35618 | C17: 35616 | AB17: -44 | AC17: -5 | AD17: =AVERAGE(AB17,AC17) -> -24.5 | AF17: -6 | AG17: 28 | AH17: =AVERAGE(AF17,AG17) -> 11 | AJ17: 20 | AK17: 45 | AL17: =AVERAGE(AJ17,AK17) -> 32.5 | AN17: 138 | AO17: 137 | AP17: =AVERAGE(AN17,AO17) -> 137.5
A18: 28 | B18: =+B19-7 -> 35625 | C18: 35623 | AB18: -93 | AC18: 3 | AD18: =AVERAGE(AB18,AC18) -> -45 | AF18: -43 | AG18: 19 | AH18: =AVERAGE(AF18,AG18) -> -12 | AJ18: 15 | AK18: 40 | AL18: =AVERAGE(AJ18,AK18) -> 27.5 | AN18: 126 | AO18: 171 | AP18: =AVERAGE(AN18,AO18) -> 148.5
A19: 29 | B19: =+B20-7 -> 35632 | C19: 35630 | AB19: -45 | AC19: 37 | AD19: =AVERAGE(AB19,AC19) -> -4 | AF19: -26 | AG19: 31 | AH19: =AVERAGE(AF19,AG19) -> 2.5 | AK19: 41 | AL19: =AVERAGE(AJ19,AK19) -> 41 | AN19: 98 | AO19: 132 | AP19: =AVERAGE(AN19,AO19) -> 115
A20: 30 | B20: =+B21-7 -> 35639 | C20: 35637 | D20: 122 | E20: 143 | F20: =AVERAGE(D20,E20) -> 132.5 | AF20: 17 | AG20: 53 | AH20: =AVERAGE(AF20,AG20) -> 35 | AJ20: 22 | AK20: 56 | AL20: =AVERAGE(AJ20,AK20) -> 39 | AN20: 122 | AO20: 155 | AP20: =AVERAGE(AN20,AO20) -> 138.5 | AR20: 175 | AS20: 169 | AT20: =AVERAGE(AR20,AS20) -> 172 | AV20: 157 | AW20: 166 | AX20: =AVERAGE(AV20,AW20) -> 161.5
A21: 31 | B21: =+B22-7 -> 35646 | C21: 35644 | D21: 189 | E21: 158 | F21: =AVERAGE(D21,E21) -> 173.5 | AF21: 144 | AG21: 125 | AH21: =AVERAGE(AF21,AG21) -> 134.5 | AJ21: 104 | AK21: 138 | AL21: =AVERAGE(AJ21,AK21) -> 121 | AN21: 182 | AO21: 200 | AP21: =AVERAGE(AN21,AO21) -> 191 | AR21: 208 | AS21: 210 | AT21: =AVERAGE(AR21,AS21) -> 209 | AV21: 202 | AW21: 201 | AX21: =AVERAGE(AV21,AW21) -> 201.5
A22: 32 | B22: =+B23-7 -> 35653 | C22: 35651 | D22: 182 | E22: 208 | F22: =AVERAGE(D22,E22) -> 195 | AF22: 184 | AG22: 148 | AH22: =AVERAGE(AF22,AG22) -> 166 | AJ22: 138 | AK22: 136 | AL22: =AVERAGE(AJ22,AK22) -> 137 | AN22: 191 | AO22: 184 | AP22: =AVERAGE(AN22,AO22) -> 187.5 | AR22: 205 | AS22: 200 | AT22: =AVERAGE(AR22,AS22) -> 202.5 | AV22: 184 | AW22: 189 | AX22: =AVERAGE(AV22,AW22) -> 186.5
A23: 33 | B23: =+B24-7 -> 35660 | C23: 35658 | D23: 168 | E23: 190 | F23: =AVERAGE(D23,E23) -> 179 | AF23: 189 | AH23: =AVERAGE(AF23,AG23) -> 189 | AJ23: 138 | AK23: 138 | AL23: =AVERAGE(AJ23,AK23) -> 138 | AN23: 177 | AO23: 184 | AP23: =AVERAGE(AN23,AO23) -> 180.5 | AR23: 205 | AS23: 208 | AT23: =AVERAGE(AR23,AS23) -> 206.5 | AV23: 180 | AW23: 184 | AX23: =AVERAGE(AV23,AW23) -> 182
A24: 34 | B24: =+B25-7 -> 35667 | C24: 35665 | D24: 148 | F24: =AVERAGE(D24,E24) -> 148 | H24: 118 | J24: =AVERAGE(H24,I24) -> 118 | AJ24: 86 | AK24: 107 | AL24: =AVERAGE(AJ24,AK24) -> 96.5 | AN24: 143 | AO24: 175 | AP24: =AVERAGE(AN24,AO24) -> 159 | AR24: 164 | AS24: 191 | AT24: =AVERAGE(AR24,AS24) -> 177.5 | AV24: 152 | AW24: 166 | AX24: =AVERAGE(AV24,AW24) -> 159
A25: 35 | B25: =+B26-7 -> 35674 | C25: 35672 | D25: 181 | F25: =AVERAGE(D25,E25) -> 181 | H25: 158 | J25: =AVERAGE(H25,I25) -> 158 | AJ25: 229 | AK25: 230 | AL25: =AVERAGE(AJ25,AK25) -> 229.5 | AN25: 221 | AO25: 254 | AP25: =AVERAGE(AN25,AO25) -> 237.5 | AR25: 218 | AS25: 251 | AT25: =AVERAGE(AR25,AS25) -> 234.5 | AV25: 193 | AW25: 219 | AX25: =AVERAGE(AV25,AW25) -> 206
A26: 36 | B26: =+B27-7 -> 35681 | C26: 35679 | D26: 181 | E26: 223 | F26: =AVERAGE(D26,E26) -> 202 | H26: 154 | I26: 200 | J26: =AVERAGE(H26,I26) -> 177 | AJ26: 271 | AK26: 288 | AL26: =AVERAGE(AJ26,AK26) -> 279.5 | AN26: 242 | AO26: 295 | AP26: =AVERAGE(AN26,AO26) -> 268.5 | AR26: 231 | AS26: 284 | AT26: =AVERAGE(AR26,AS26) -> 257.5 | AV26: 206 | AW26: 240 | AX26: =AVERAGE(AV26,AW26) -> 223
A27: 37 | B27: =+B28-7 -> 35688 | C27: 35686 | D27: 149 | E27: 166 | F27: =AVERAGE(D27,E27) -> 157.5 | H27: 120 | I27: 140 | J27: =AVERAGE(H27,I27) -> 130 | AJ27: 249 | AK27: 242 | AL27: =AVERAGE(AJ27,AK27) -> 245.5 | AN27: 191 | AO27: 249 | AP27: =AVERAGE(AN27,AO27) -> 220 | AR27: 167 | AS27: 238 | AT27: =AVERAGE(AR27,AS27) -> 202.5 | AV27: 153 | AW27: 192 | AX27: =AVERAGE(AV27,AW27) -> 172.5
A28: 38 | B28: =+B29-7 -> 35695 | C28: 35693 | D28: 131 | E28: 155 | F28: =AVERAGE(D28,E28) -> 143 | H28: 97 | I28: 137 | J28: =AVERAGE(H28,I28) -> 117 | AJ28: 148 | AK28: 250 | AL28: =AVERAGE(AJ28,AK28) -> 199 | AN28: 147 | AO28: 257 | AP28: =AVERAGE(AN28,AO28) -> 202 | AR28: 141 | AS28: 207 | AT28: =AVERAGE(AR28,AS28) -> 174 | AV28: 130 | AW28: 173 | AX28: =AVERAGE(AV28,AW28) -> 151.5
A29: 39 | B29: =+B30-7 -> 35702 | C29: 35700 | D29: 137 | E29: 208 | F29: =AVERAGE(D29,E29) -> 172.5 | H29: 114 | I29: 173 | J29: =AVERAGE(H29,I29) -> 143.5 | L29: 66 | M29: 120 | N29: =AVERAGE(L29,M29) -> 93 | AN29: 236 | AO29: 300 | AP29: =AVERAGE(AN29,AO29) -> 268 | AR29: 174 | AS29: 259 | AT29: =AVERAGE(AR29,AS29) -> 216.5 | AV29: 142 | AW29: 227 | AX29: =AVERAGE(AV29,AW29) -> 184.5
A30: 40 | B30: =+B31-7 -> 35709 | C30: 35707 | D30: 160 | E30: 250 | F30: =AVERAGE(D30,E30) -> 205 | H30: 123 | I30: 225 | J30: =AVERAGE(H30,I30) -> 174 | L30: 91 | M30: 167 | N30: =AVERAGE(L30,M30) -> 129 | AN30: 278 | AO30: 350 | AP30: =AVERAGE(AN30,AO30) -> 314 | AR30: 215 | AS30: 288 | AT30: =AVERAGE(AR30,AS30) -> 251.5 | AV30: 163 | AW30: 267 | AX30: =AVERAGE(AV30,AW30) -> 215
A31: 41 | B31: =+B32-7 -> 35716 | C31: 35714 | D31: 199 | E31: 268 | F31: =AVERAGE(D31,E31) -> 233.5 | H31: 155 | I31: 223 | J31: =AVERAGE(H31,I31) -> 189 | L31: 78 | M31: 163 | N31: =AVERAGE(L31,M31) -> 120.5 | AN31: 325 | AP31: =AVERAGE(AN31,AO31) -> 325 | AR31: 279 | AS31: 334 | AT31: =AVERAGE(AR31,AS31) -> 306.5 | AV31: 212 | AX31: =AVERAGE(AV31,AW31) -> 212
A32: 42 | B32: =+B33-7 -> 35723 | C32: 35721 | D32: 174 | E32: 264 | F32: =AVERAGE(D32,E32) -> 219 | H32: 140 | I32: 225 | J32: =AVERAGE(H32,I32) -> 182.5 | L32: 100 | M32: 152 | N32: =AVERAGE(L32,M32) -> 126 | AN32: 241 | AP32: =AVERAGE(AN32,AO32) -> 241 | AR32: 229 | AS32: 280 | AT32: =AVERAGE(AR32,AS32) -> 254.5 | AV32: 177 | AW32: 273 | AX32: =AVERAGE(AV32,AW32) -> 225
A33: 43 | B33: =+B34-7 -> 35730 | C33: 35728 | D33: 129 | E33: 214 | F33: =AVERAGE(D33,E33) -> 171.5 | H33: 109 | I33: 181 | J33: =AVERAGE(H33,I33) -> 145 | L33: 51 | M33: 115 | N33: =AVERAGE(L33,M33) -> 83 | P33: -21 | Q33: 35 | R33: =AVERAGE(P33,Q33) -> 7 | AR33: 151 | AS33: 219 | AT33: =AVERAGE(AR33,AS33) -> 185 | AV33: 123 | AW33: 198 | AX33: =AVERAGE(AV33,AW33) -> 160.5
A34: 44 | B34: =+B35-7 -> 35737 | C34: 35735 | D34: 112 | E34: 167 | F34: =AVERAGE(D34,E34) -> 139.5 | H34: 81 | I34: 143 | J34: =AVERAGE(H34,I34) -> 112 | L34: 56 | M34: 108 | N34: =AVERAGE(L34,M34) -> 82 | P34: -36 | Q34: 13 | R34: =AVERAGE(P34,Q34) -> -11.5 | AR34: 115 | AS34: 160 | AT34: =AVERAGE(AR34,AS34) -> 137.5 | AV34: 92 | AW34: 165 | AX34: =AVERAGE(AV34,AW34) -> 128.5
A35: 45 | B35: =+B36-7 -> 35744 | C35: 35742 | D35: 64 | E35: 172 | F35: =AVERAGE(D35,E35) -> 118 | H35: 64 | I35: 146 | J35: =AVERAGE(H35,I35) -> 105 | L35: 43 | M35: 98 | N35: =AVERAGE(L35,M35) -> 70.5 | P35: -20 | Q35: 19 | R35: =AVERAGE(P35,Q35) -> -0.5 | AR35: 69 | AS35: 205 | AT35: =AVERAGE(AR35,AS35) -> 137 | AV35: 44 | AW35: 162 | AX35: =AVERAGE(AV35,AW35) -> 103
A36: 46 | B36: =+B37-7 -> 35751 | C36: 35749 | D36: 41 | E36: 172 | F36: =AVERAGE(D36,E36) -> 106.5 | H36: 36 | I36: 153 | J36: =AVERAGE(H36,I36) -> 94.5 | L36: 28 | M36: 90 | N36: =AVERAGE(L36,M36) -> 59 | P36: -71 | Q36: 21 | R36: =AVERAGE(P36,Q36) -> -25 | AR36: 83 | AT36: =AVERAGE(AR36,AS36) -> 83 | AV36: 35 | AW36: 175 | AX36: =AVERAGE(AV36,AW36) -> 105
A37: 47 | B37: =+B38-7 -> 35758 | C37: 35756 | D37: 58 | E37: 181 | F37: =AVERAGE(D37,E37) -> 119.5 | H37: 33 | I37: 151 | J37: =AVERAGE(H37,I37) -> 92 | L37: 28 | M37: 100 | N37: =AVERAGE(L37,M37) -> 64 | P37: -83 | Q37: 21 | R37: =AVERAGE(P37,Q37) -> -31 | T37: -89 | U37: 19 | V37: =AVERAGE(T37,U37) -> -35 | AV37: 63 | AW37: 205 | AX37: =AVERAGE(AV37,AW37) -> 134
A38: 48 | B38: =+B39-7 -> 35765 | C38: 35763
A39: 49 | B39: =+B40-7 -> 35772 | C39: 35770 | D39: 7 | E39: 75 | F39: =AVERAGE(D39,E39) -> 41 | H39: 6 | I39: 63 | J39: =AVERAGE(H39,I39) -> 34.5 | L39: 4 | M39: 46 | N39: =AVERAGE(L39,M39) -> 25 | P39: -70 | Q39: 25 | R39: =AVERAGE(P39,Q39) -> -22.5 | T39: -51 | U39: 27 | V39: =AVERAGE(T39,U39) -> -12 | AV39: 17 | AW39: 100 | AX39: =AVERAGE(AV39,AW39) -> 58.5
A40: 50 | B40: =+B41-7 -> 35779 | C40: 35777 | D40: -48 | E40: 38 | F40: =AVERAGE(D40,E40) -> -5 | H40: -75 | I40: 35 | J40: =AVERAGE(H40,I40) -> -20 | L40: -75 | M40: 19 | N40: =AVERAGE(L40,M40) -> -28 | P40: -78 | Q40: 10 | R40: =AVERAGE(P40,Q40) -> -34 | T40: -83 | U40: 8 | V40: =AVERAGE(T40,U40) -> -37.5 | AV40: -84 | AX40: =AVERAGE(AV40,AW40) -> -84
...

Sheet Shuttle Bids
B1: Shuttle Bids for Secondary Rail Car Market ($) | P1: Shuttle Bids for Secondary Rail Car Market ($) | AB1: Shuttle Bids for Secondary Rail Car Market ($) | AN1: Shuttle Bids for Secondary Rail Car Market ($)
B2: Data Sources: Atwood/Conagra, Harvest States Coop, James B. Joiner Co., Tradewest Brokerage Co.
B3: Data taken from secondary_premiums_all database that was prepared by Upper Great Plains Transportation Institute
B4: Weeks having no reported activity are represented by blanks. Bids submitted at par value are represented by 0.
D5: (Occasionally, the data will not correspond to what was reported in the Grain Transportation Report)
B6: GTR | C6: Week | D6: Jan. | H6: Feb. | L6: Mar. | P6: Apr. | T6: May. | X6: Jun. | AB6: Jul. | AF6: Aug. | AJ6: Sep. | AN6: Oct. | AR6: Nov. | AV6: Dec.
A7: Week | B7: Date | C7: Ending | D7: BNSF-GF | E7: UP-Pool | F7: Avg. | H7: BNSF-GF | I7: UP-Pool | J7: Avg. | L7: BNSF-GF | M7: UP-Pool | N7: Avg. | P7: BNSF-GF | Q7: UP-Pool | R7: Avg. | T7: BNSF-GF | U7: UP-Pool | V7: Avg. | X7: BNSF-GF | Y7: UP-Pool | Z7: Avg. | AB7: BNSF-GF | AC7: UP-Pool | AD7: Avg. | AF7: BNSF-GF | AG7: UP-Pool | AH7: Avg. | AJ7: BNSF-GF | AK7: UP-Pool | AL7: Avg. | AN7: BNSF-GF | AO7: UP-Pool | AP7: Avg. | AR7: BNSF-GF | AS7: UP-Pool | AT7: Avg. | AV7: BNSF-GF | AW7: UP-Pool | AX7: Avg.
A8: 18 | B8: =+B9-7 -> 35558 | C8: 35553
A9: 19 | B9: =+B10-7 -> 35565 | C9: 35560
A10: 20 | B10: =+B11-7-1 -> 35572 | C10: 35567
A11: 21 | B11: =+B12-7+1 -> 35580 | C11: 35574
A12: 22 | B12: =+B13-7 -> 35586 | C12: 35581
A13: 23 | B13: =+B14-7 -> 35593 | C13: 35588
A14: 24 | B14: =+B15-7 -> 35600 | C14: 35595
A15: 25 | B15: =+B16-7 -> 35607 | C15: 35602
A16: 26 | B16: =+B17-7 -> 35614 | C16: 35609
A17: 27 | B17: =+B18-7 -> 35621 | C17: 35616
A18: 28 | B18: =+B19-7 -> 35628 | C18: 35623
A19: 29 | B19: =+B20-7 -> 35635 | C19: 35630
A20: 30 | B20: =+B21-7 -> 35642 | C20: 35637
A21: 31 | B21: =+B22-7 -> 35649 | C21: 35644
A22: 32 | B22: =+B23-7 -> 35656 | C22: 35651
A23: 33 | B23: =+B24-7 -> 35663 | C23: 35658
... A42: 52 | B42: =+B43-7 -> 35796 | C42: 35791
A43: 1 | B43: 35803 | C43: 35798
A44: 2 | B44: 35810 | C44: 35805
A45: =+A44+1 -> 3 | B45: 35817 | C45: 35812
A46: =+A45+1 -> 4 | B46: 35824 | C46: 35819
A47: =+A46+1 -> 5 | B47: 35831 | C47: 35826
A48: =+A47+1 -> 6 | B48: 35838 | C48: 35833
A49: =+A48+1 -> 7 | B49: 35845 | C49: 35840
A50: =+A49+1 -> 8 | B50: 35852 | C50: 35847
A51: =+A50+1 -> 9 | B51: 35859 | C51: 35854
A52: =+A51+1 -> 10 | B52: 35866 | C52: 35861
A53: =+A52+1 -> 11 | B53: 35873 | C53: 35868
A54: =+A53+1 -> 12 | B54: 35880 | C54: 35875
A55: =+A54+1 -> 13 | B55: 35887 | C55: 35882
A56: =+A55+1 -> 14 | B56: 35894 | C56: 35889
... A94: =+A93+1 -> 52 | B94: 36160 | C94: 36155
A95: 1 | B95: 36167 | C95: 36162
...

Sheet New Fig. 4
A1: Figure 4
A2: Bids/Offers for Railcars to be Delivered in August 2014, Secondary Market
A19: Non-shuttle bids include unit-train and single-car bids. n/a = not available.
A20: Source: Transportation & Marketing Programs/AMS/USDA

Sheet New Fig. 5
A1: Figure 5
A2: Bids/Offers for Railcars to be Delivered in September 2014, Secondary Market
A19: Non-shuttle bids include unit-train and single-car bids. n/a = not available.
A20: Source: Transportation & Marketing Programs/AMS/USDA

Sheet New Fig. 6
A1: Figure 6
A2: Bids/Offers for Railcars to be Delivered in October 2014, Secondary Market
A19: Non-shuttle bids include unit-train and single-car bids. n/a = not available.
A20: Source: Transportation & Marketing Programs/AMS/USDA

Sheet Prior 3-yr.Avg for Week
A1: Prior 3-year averages for each week in a trading month | O1: Prior 3-year averages for each week in a trading month | AB1: Prior 3-year averages for each week in a trading month | AS1: Prior 3-year averages for each week in a trading month | BF1: Prior 3-year averages for each week in a trading month | BS1: Prior 3-year averages for each week in a trading month
B4: Non-Shuttle | O4: Non-Shuttle | AB4: Non-Shuttle | AS4: Shuttle | BF4: Shuttle | BS4: Shuttle
B5: For the Following Delivery Dates: | O5: For the Following Delivery Dates: | AB5: For the Following Delivery Dates: | AS5: For the Following Delivery Dates: | BF5: For the Following Delivery Dates: | BS5: For the Following Delivery Dates:
B6: Jan. 2011-13 | E6: Feb. 2011-13 | H6: Mar. 2011-13 | L6: Apr. 2011-13 | O6: May 2011-13 | R6: June 2011-13 | V6: Jul. 2011-13 | Y6: Aug. 2011-13 | AB6: Sep. 2011-13 | AF6: Oct. 2011-13 | AJ6: Nov. 2011-13 | AN6: Dec. 2011-13 | AS6: Jan. 2011-13 | AV6: Feb. 2011-13 | AY6: Mar. 2011-13 | BC6: Apr. 2011-13 | BF6: May. 2011-13 | BI6: Jun. 2011-13 | BM6: Jul. 2011-13 | BP6: Aug. 2011-13 | BS6: Sep. 2011-13 | BW6: Oct. 2011-13 | CA6: Nov. 2011-13 | CE6: Dec. 2011-13
A7: week # | B7: BNSF-GF | C7: UP-Pool | D7: Both | E7: BNSF-GF | F7: UP-Pool | G7: Both | H7: BNSF-GF | I7: UP-Pool | J7: Both | K7: week # | L7: BNSF-GF | M7: UP-Pool | N7: Both | O7: BNSF-GF | P7: UP-Pool | Q7: Both | R7: BNSF-GF | S7: UP-Pool | T7: Both | U7: week # | V7: BNSF-GF | W7: UP-Pool | X7: Both | Y7: BNSF-GF | Z7: UP-Pool | AA7: Both | AB7: BNSF-GF | AC7: UP-Pool | AD7: Both | AE7: week # | AF7: BNSF-GF | AG7: UP-Pool | AH7: Both | AI7: week # | AJ7: BNSF-GF | AK7: UP-Pool | AL7: Both | AM7: week # | AN7: BNSF-GF | AO7: UP-Pool | AP7: Both | AS7: BNSF-GF | AT7: UP-Pool | AU7: Both | AV7: BNSF-GF | AW7: UP-Pool | AX7: Both | AY7: BNSF-GF | AZ7: UP-Pool | BA7: Both | BB7: week # | BC7: BNSF-GF | BD7: UP-Pool | BE7: Both | BF7: BNSF-GF | BG7: UP-Pool | BH7: Both | BI7: BNSF-GF | BJ7: UP-Pool | BK7: Both | BL7: week # | BM7: BNSF-GF | BN7: UP-Pool | BO7: Both | BP7: BNSF-GF | BQ7: UP-Pool | BR7: Both | BS7: BNSF-GF | BT7: UP-Pool | BU7: Both | BV7: week # | BW7: BNSF-GF | BX7: UP-Pool | BY7: Both | BZ7: week # | CA7: BNSF-GF | CB7: UP-Pool | CC7: Both | CD7: week # | CE7: BNSF-GF | CF7: UP-Pool | CG7: Both
AM8: 21 | CD8: 21 | CE8: =AVERAGE('Shuttle Bids'!AV741,'Shuttle Bids'!AV845,'Shuttle Bids'!AV793) -> 0 | CG8: =AVERAGE('Shuttle Bids'!AX741,'Shuttle Bids'!AX845,'Shuttle Bids'!AX793) -> 0
AM9: 22 | CD9: 22 | CE9: =AVERAGE('Shuttle Bids'!AV742,'Shuttle Bids'!AV846,'Shuttle Bids'!AV794) -> 0 | CG9: =AVERAGE('Shuttle Bids'!AX742,'Shuttle Bids'!AX846,'Shuttle Bids'!AX794) -> 0
AE10: 12 | AM10: 23 | BV10: 12 | BW10: =AVERAGE('Shuttle Bids'!AN733,'Shuttle Bids'!AN837,'Shuttle Bids'!AN785) -> 550 | BX10: =AVERAGE('Shuttle Bids'!AO733,'Shuttle Bids'!AO837,'Shuttle Bids'!AO785) -> 475 | BY10: =AVERAGE('Shuttle Bids'!AP733,'Shuttle Bids'!AP837,'Shuttle Bids'!AP785) -> 500 | CD10: 23
AE11: 13 | AI11: 17 | AM11: 24 | BV11: 13 | BX11: =AVERAGE('Shuttle Bids'!AO734,'Shuttle Bids'!AO838,'Shuttle Bids'!AO786) -> 500 | BY11: =AVERAGE('Shuttle Bids'!AP734,'Shuttle Bids'!AP838,'Shuttle Bids'!AP786) -> 500 | BZ11: 17 | CA11: =AVERAGE('Shuttle Bids'!AR737,'Shuttle Bids'!AR841,'Shuttle Bids'!AR789) -> 400 | CC11: =AVERAGE('Shuttle Bids'!AT737,'Shuttle Bids'!AT841,'Shuttle Bids'!AT789) -> 400 | CD11: 24
AE12: 14 | AI12: 18 | AM12: 25 | BV12: 14 | BX12: =AVERAGE('Shuttle Bids'!AO735,'Shuttle Bids'!AO839,'Shuttle Bids'!AO787) -> 600 | BY12: =AVERAGE('Shuttle Bids'!AP735,'Shuttle Bids'!AP839,'Shuttle Bids'!AP787) -> 600 | BZ12: 18 | CA12: =AVERAGE('Shuttle Bids'!AR738,'Shuttle Bids'!AR842,'Shuttle Bids'!AR790) -> 500 | CC12: =AVERAGE('Shuttle Bids'!AT738,'Shuttle Bids'!AT842,'Shuttle Bids'!AT790) -> 500 | CD12: 25
A13: 25 | AE13: 15 | AI13: 19 | AM13: 26 | AR13: 25 | BV13: 15 | BW13: =AVERAGE('Shuttle Bids'!AN736,'Shuttle Bids'!AN840,'Shuttle Bids'!AN788) -> 250 | BX13: =AVERAGE('Shuttle Bids'!AO736,'Shuttle Bids'!AO840,'Shuttle Bids'!AO788) -> 662.5 | BY13: =AVERAGE('Shuttle Bids'!AP736,'Shuttle Bids'!AP840,'Shuttle Bids'!AP788) -> 606.25 | BZ13: 19 | CA13: =AVERAGE('Shuttle Bids'!AR739,'Shuttle Bids'!AR843,'Shuttle Bids'!AR791) -> 600 | CC13: =AVERAGE('Shuttle Bids'!AT739,'Shuttle Bids'!AT843,'Shuttle Bids'!AT791) -> 600 | CD13: 26
A14: 26 | AE14: 16 | AI14: 20 | AM14: =+AM13+1 -> 27 | AR14: 26 | BV14: 16 | BW14: =AVERAGE('Shuttle Bids'!AN737,'Shuttle Bids'!AN841,'Shuttle Bids'!AN789) -> 200 | BX14: =AVERAGE('Shuttle Bids'!AO737,'Shuttle Bids'!AO841,'Shuttle Bids'!AO789) -> 562.5 | BY14: =AVERAGE('Shuttle Bids'!AP737,'Shuttle Bids'!AP841,'Shuttle Bids'!AP789) -> 493.75 | BZ14: 20 | CA14: =AVERAGE('Shuttle Bids'!AR740,'Shuttle Bids'!AR844,'Shuttle Bids'!AR792) -> 575 | CC14: =AVERAGE('Shuttle Bids'!AT740,'Shuttle Bids'!AT844,'Shuttle Bids'!AT792) -> 575 | CD14: =+CD13+1 -> 27
A15: =+A16-1 -> 27 | AE15: 17 | AG15: =AVERAGE('Non-shuttle Bids'!AO738,'Non-shuttle Bids'!AO842,'Non-shuttle Bids'!AO790) -> 93 | AH15: =AVERAGE('Non-shuttle Bids'!AP738,'Non-shuttle Bids'!AP842,'Non-shuttle Bids'!AP790) -> 93 | AI15: 21 | AM15: =+AM14+1 -> 28 | AN15: =AVERAGE('Non-shuttle Bids'!AV800,'Non-shuttle Bids'!AV852,'Non-shuttle Bids'!AV748) -> 200 | AP15: =AVERAGE('Non-shuttle Bids'!AX800,'Non-shuttle Bids'!AX852,'Non-shuttle Bids'!AX748) -> 200 | AR15: 27 | BV15: 17 | BW15: =AVERAGE('Shuttle Bids'!AN738,'Shuttle Bids'!AN842,'Shuttle Bids'!AN790) -> 500 | BX15: =AVERAGE('Shuttle Bids'!AO738,'Shuttle Bids'!AO842,'Shuttle Bids'!AO790) -> 575 | BY15: =AVERAGE('Shuttle Bids'!AP738,'Shuttle Bids'!AP842,'Shuttle Bids'!AP790) -> 575 | BZ15: 21 | CA15: =AVERAGE('Shuttle Bids'!AR741,'Shuttle Bids'!AR845,'Shuttle Bids'!AR793) -> 575 | CC15: =AVERAGE('Shuttle Bids'!AT741,'Shuttle Bids'!AT845,'Shuttle Bids'!AT793) -> 575 | CD15: =+CD14+1 -> 28
A16: =+A17-1 -> 28 | AE16: =+AE15+1 -> 18 | AG16: =AVERAGE('Non-shuttle Bids'!AO739,'Non-shuttle Bids'!AO843,'Non-shuttle Bids'!AO791) -> 93 | AH16: =AVERAGE('Non-shuttle Bids'!AP739,'Non-shuttle Bids'!AP843,'Non-shuttle Bids'!AP791) -> 93 | AI16: =+AI15+1 -> 22 | AM16: =+AM15+1 -> 29 | AN16: =AVERAGE('Non-shuttle Bids'!AV801,'Non-shuttle Bids'!AV853,'Non-shuttle Bids'!AV749) -> 200 | AP16: =AVERAGE('Non-shuttle Bids'!AX801,'Non-shuttle Bids'!AX853,'Non-shuttle Bids'!AX749) -> 200 | AR16: 28 | BV16: =+BV15+1 -> 18 | BW16: =AVERAGE('Shuttle Bids'!AN739,'Shuttle Bids'!AN843,'Shuttle Bids'!AN791) -> 700 | BX16: =AVERAGE('Shuttle Bids'!AO739,'Shuttle Bids'!AO843,'Shuttle Bids'!AO791) -> 625 | BY16: =AVERAGE('Shuttle Bids'!AP739,'Shuttle Bids'!AP843,'Shuttle Bids'!AP791) -> 675 | BZ16: =+BZ15+1 -> 22 | CA16: =AVERAGE('Shuttle Bids'!AR742,'Shuttle Bids'!AR846,'Shuttle Bids'!AR794) -> 600 | CC16: =AVERAGE('Shuttle Bids'!AT742,'Shuttle Bids'!AT846,'Shuttle Bids'!AT794) -> 600 | CD16: =+CD15+1 -> 29 | CE16: =AVERAGE('Shuttle Bids'!AV749,'Shuttle Bids'!AV853,'Shuttle Bids'!AV801) -> -112.5 | CF16: =AVERAGE('Shuttle Bids'!AW749,'Shuttle Bids'!AW853,'Shuttle Bids'!AW801) -> 0 | CG16: =AVERAGE('Shuttle Bids'!AX749,'Shuttle Bids'!AX853,'Shuttle Bids'!AX801) -> -106.25
A17: =+A18-1 -> 29 | AE17: =+AE16+1 -> 19 | AG17: =AVERAGE('Non-shuttle Bids'!AO740,'Non-shuttle Bids'!AO844,'Non-shuttle Bids'!AO792) -> 93 | AH17: =AVERAGE('Non-shuttle Bids'!AP740,'Non-shuttle Bids'!AP844,'Non-shuttle Bids'!AP792) -> 93 | AI17: =+AI16+1 -> 23 | AM17: =+AM16+1 -> 30 | AN17: =AVERAGE('Non-shuttle Bids'!AV802,'Non-shuttle Bids'!AV854,'Non-shuttle Bids'!AV750) -> 200 | AP17: =AVERAGE('Non-shuttle Bids'!AX802,'Non-shuttle Bids'!AX854,'Non-shuttle Bids'!AX750) -> 200 | AR17: 29 | BV17: =+BV16+1 -> 19 | BX17: =AVERAGE('Shuttle Bids'!AO740,'Shuttle Bids'!AO844,'Shuttle Bids'!AO792) -> 625 | BY17: =AVERAGE('Shuttle Bids'!AP740,'Shuttle Bids'!AP844,'Shuttle Bids'!AP792) -> 625 | BZ17: =+BZ16+1 -> 23 | CD17: =+CD16+1 -> 30 | CF17: =AVERAGE('Shuttle Bids'!AW750,'Shuttle Bids'!AW854,'Shuttle Bids'!AW802) -> 0 | CG17: =AVERAGE('Shuttle Bids'!AX750,'Shuttle Bids'!AX854,'Shuttle Bids'!AX802) -> 0
A18: =+A19-1 -> 30 | AE18: =+AE17+1 -> 20 | AG18: =AVERAGE('Non-shuttle Bids'!AO741,'Non-shuttle Bids'!AO845,'Non-shuttle Bids'!AO793) -> 93 | AH18: =AVERAGE('Non-shuttle Bids'!AP741,'Non-shuttle Bids'!AP845,'Non-shuttle Bids'!AP793) -> 93 | AI18: =+AI17+1 -> 24 | AM18: =+AM17+1 -> 31 | AN18: =AVERAGE('Non-shuttle Bids'!AV803,'Non-shuttle Bids'!AV855,'Non-shuttle Bids'!AV751) -> 200 | AP18: =AVERAGE('Non-shuttle Bids'!AX803,'Non-shuttle Bids'!AX855,'Non-shuttle Bids'!AX751) -> 200 | AR18: 30 | BV18: =+BV17+1 -> 20 | BX18: =AVERAGE('Shuttle Bids'!AO741,'Shuttle Bids'!AO845,'Shuttle Bids'!AO793) -> 550 | BY18: =AVERAGE('Shuttle Bids'!AP741,'Shuttle Bids'!AP845,'Shuttle Bids'!AP793) -> 550 | BZ18: =+BZ17+1 -> 24 | CD18: =+CD17+1 -> 31 | CF18: =AVERAGE('Shuttle Bids'!AW751,'Shuttle Bids'!AW855,'Shuttle Bids'!AW803) -> 0 | CG18: =AVERAGE('Shuttle Bids'!AX751,'Shuttle Bids'!AX855,'Shuttle Bids'!AX803) -> 0
A19: =+A20-1 -> 31 | AE19: =+AE18+1 -> 21 | AG19: =AVERAGE('Non-shuttle Bids'!AO742,'Non-shuttle Bids'!AO846,'Non-shuttle Bids'!AO794) -> 100 | AH19: =AVERAGE('Non-shuttle Bids'!AP742,'Non-shuttle Bids'!AP846,'Non-shuttle Bids'!AP794) -> 100 | AI19: =+AI18+1 -> 25 | AM19: =+AM18+1 -> 32 | AN19: =AVERAGE('Non-shuttle Bids'!AV804,'Non-shuttle Bids'!AV856,'Non-shuttle Bids'!AV752) -> 200 | AP19: =AVERAGE('Non-shuttle Bids'!AX804,'Non-shuttle Bids'!AX856,'Non-shuttle Bids'!AX752) -> 200 | AR19: 31 | BV19: =+BV18+1 -> 21 | BX19: =AVERAGE('Shuttle Bids'!AO742,'Shuttle Bids'!AO846,'Shuttle Bids'!AO794) -> 587.5 | BY19: =AVERAGE('Shuttle Bids'!AP742,'Shuttle Bids'!AP846,'Shuttle Bids'!AP794) -> 587.5 | BZ19: =+BZ18+1 -> 25 | CD19: =+CD18+1 -> 32 | CF19: =AVERAGE('Shuttle Bids'!AW752,'Shuttle Bids'!AW856,'Shuttle Bids'!AW804) -> -100 | CG19: =AVERAGE('Shuttle Bids'!AX752,'Shuttle Bids'!AX856,'Shuttle Bids'!AX804) -> -100
A20: =+A21-1 -> 32 | AE20: =+AE19+1 -> 22 | AG20: =AVERAGE('Non-shuttle Bids'!AO743,'Non-shuttle Bids'!AO847,'Non-shuttle Bids'!AO795) -> 100 | AH20: =AVERAGE('Non-shuttle Bids'!AP743,'Non-shuttle Bids'!AP847,'Non-shuttle Bids'!AP795) -> 100 | AI20: =+AI19+1 -> 26 | AM20: =+AM19+1 -> 33 | AN20: =AVERAGE('Non-shuttle Bids'!AV805,'Non-shuttle Bids'!AV857,'Non-shuttle Bids'!AV753) -> 200 | AP20: =AVERAGE('Non-shuttle Bids'!AX805,'Non-shuttle Bids'!AX857,'Non-shuttle Bids'!AX753) -> 200 | AR20: 32 | BV20: =+BV19+1 -> 22 | BX20: =AVERAGE('Shuttle Bids'!AO743,'Shuttle Bids'!AO847,'Shuttle Bids'!AO795) -> 575 | BY20: =AVERAGE('Shuttle Bids'!AP743,'Shuttle Bids'!AP847,'Shuttle Bids'!AP795) -> 575 | BZ20: =+BZ19+1 -> 26 | CD20: =+CD19+1 -> 33 | CF20: =AVERAGE('Shuttle Bids'!AW753,'Shuttle Bids'!AW857,'Shuttle Bids'!AW805) -> -100 | CG20: =AVERAGE('Shuttle Bids'!AX753,'Shuttle Bids'!AX857,'Shuttle Bids'!AX805) -> -100
A21: =+A22-1 -> 33 | AE21: =+AE20+1 -> 23 | AG21: =AVERAGE('Non-shuttle Bids'!AO744,'Non-shuttle Bids'!AO848,'Non-shuttle Bids'!AO796) -> 138 | AH21: =AVERAGE('Non-shuttle Bids'!AP744,'Non-shuttle Bids'!AP848,'Non-shuttle Bids'!AP796) -> 138 | AI21: =+AI20+1 -> 27 | AM21: =+AM20+1 -> 34 | AR21: 33 | BV21: =+BV20+1 -> 23 | BX21: =AVERAGE('Shuttle Bids'!AO744,'Shuttle Bids'!AO848,'Shuttle Bids'!AO796) -> 512.5 | BY21: =AVERAGE('Shuttle Bids'!AP744,'Shuttle Bids'!AP848,'Shuttle Bids'!AP796) -> 512.5 | BZ21: =+BZ20+1 -> 27 | CD21: =+CD20+1 -> 34 | CF21: =AVERAGE('Shuttle Bids'!AW754,'Shuttle Bids'!AW858,'Shuttle Bids'!AW806) -> -125 | CG21: =AVERAGE('Shuttle Bids'!AX754,'Shuttle Bids'!AX858,'Shuttle Bids'!AX806) -> -125
A22: =+A23-1 -> 34 | AE22: =+AE21+1 -> 24 | AG22: =AVERAGE('Non-shuttle Bids'!AO745,'Non-shuttle Bids'!AO849,'Non-shuttle Bids'!AO797) -> 100 | AH22: =AVERAGE('Non-shuttle Bids'!AP745,'Non-shuttle Bids'!AP849,'Non-shuttle Bids'!AP797) -> 100 | AI22: =+AI21+1 -> 28 | AJ22: =AVERAGE('Non-shuttle Bids'!AR800,'Non-shuttle Bids'!AR852,'Non-shuttle Bids'!AR748) -> 300 | AL22: =AVERAGE('Non-shuttle Bids'!AT800,'Non-shuttle Bids'!AT852,'Non-shuttle Bids'!AT748) -> 300 | AM22: =+AM21+1 -> 35 | AR22: 34 | BV22: =+BV21+1 -> 24 | BX22: =AVERAGE('Shuttle Bids'!AO745,'Shuttle Bids'!AO849,'Shuttle Bids'!AO797) -> 412.5 | BY22: =AVERAGE('Shuttle Bids'!AP745,'Shuttle Bids'!AP849,'Shuttle Bids'!AP797) -> 412.5 | BZ22: =+BZ21+1 -> 28 | CA22: =AVERAGE('Shuttle Bids'!AR748,'Shuttle Bids'!AR852,'Shuttle Bids'!AR800) -> 450 | CC22: =AVERAGE('Shuttle Bids'!AT748,'Shuttle Bids'!AT852,'Shuttle Bids'!AT800) -> 450 | CD22: =+CD21+1 -> 35 | CF22: =AVERAGE('Shuttle Bids'!AW755,'Shuttle Bids'!AW859,'Shuttle Bids'!AW807) -> -125 | CG22: =AVERAGE('Shuttle Bids'!AX755,'Shuttle Bids'!AX859,'Shuttle Bids'!AX807) -> -125
A23: =+A24-1 -> 35 | AE23: =+AE22+1 -> 25 | AG23: =AVERAGE('Non-shuttle Bids'!AO746,'Non-shuttle Bids'!AO850,'Non-shuttle Bids'!AO798) -> 100 | AH23: =AVERAGE('Non-shuttle Bids'!AP746,'Non-shuttle Bids'!AP850,'Non-shuttle Bids'!AP798) -> 100 | AI23: =+AI22+1 -> 29 | AJ23: =AVERAGE('Non-shuttle Bids'!AR801,'Non-shuttle Bids'!AR853,'Non-shuttle Bids'!AR749) -> 300 | AL23: =AVERAGE('Non-shuttle Bids'!AT801,'Non-shuttle Bids'!AT853,'Non-shuttle Bids'!AT749) -> 300 | AM23: =+AM22+1 -> 36 | AR23: 35 | BV23: =+BV22+1 -> 25 | BX23: =AVERAGE('Shuttle Bids'!AO746,'Shuttle Bids'!AO850,'Shuttle Bids'!AO798) -> 394 | BY23: =AVERAGE('Shuttle Bids'!AP746,'Shuttle Bids'!AP850,'Shuttle Bids'!AP798) -> 394 | BZ23: =+BZ22+1 -> 29 | CA23: =AVERAGE('Shuttle Bids'!AR749,'Shuttle Bids'!AR853,'Shuttle Bids'!AR801) -> 325 | CB23: =AVERAGE('Shuttle Bids'!AS749,'Shuttle Bids'!AS853,'Shuttle Bids'!AS801) -> 263 | CC23: =AVERAGE('Shuttle Bids'!AT749,'Shuttle Bids'!AT853,'Shuttle Bids'!AT801) -> 290.75 | CD23: =+CD22+1 -> 36 | CF23: =AVERAGE('Shuttle Bids'!AW756,'Shuttle Bids'!AW860,'Shuttle Bids'!AW808) -> -150 | CG23: =AVERAGE('Shuttle Bids'!AX756,'Shuttle Bids'!AX860,'Shuttle Bids'!AX808) -> -150
A24: =+A25-1 -> 36 | AE24: =+AE23+1 -> 26 | AG24: =AVERAGE('Non-shuttle Bids'!AO747,'Non-shuttle Bids'!AO851,'Non-shuttle Bids'!AO799) -> 100 | AH24: =AVERAGE('Non-shuttle Bids'!AP747,'Non-shuttle Bids'!AP851,'Non-shuttle Bids'!AP799) -> 100 | AI24: =+AI23+1 -> 30 | AJ24: =AVERAGE('Non-shuttle Bids'!AR802,'Non-shuttle Bids'!AR854,'Non-shuttle Bids'!AR750) -> 300 | AL24: =AVERAGE('Non-shuttle Bids'!AT802,'Non-shuttle Bids'!AT854,'Non-shuttle Bids'!AT750) -> 300 | AM24: =+AM23+1 -> 37 | AR24: 36 | BV24: =+BV23+1 -> 26 | BW24: =AVERAGE('Shuttle Bids'!AN747,'Shuttle Bids'!AN851,'Shuttle Bids'!AN799) -> 100 | BX24: =AVERAGE('Shuttle Bids'!AO747,'Shuttle Bids'!AO851,'Shuttle Bids'!AO799) -> 441.66667 | BY24: =AVERAGE('Shuttle Bids'!AP747,'Shuttle Bids'!AP851,'Shuttle Bids'!AP799) -> 408.33333 | BZ24: =+BZ23+1 -> 30 | CA24: =AVERAGE('Shuttle Bids'!AR750,'Shuttle Bids'!AR854,'Shuttle Bids'!AR802) -> 400 | CB24: =AVERAGE('Shuttle Bids'!AS750,'Shuttle Bids'!AS854,'Shuttle Bids'!AS802) -> 250 | CC24: =AVERAGE('Shuttle Bids'!AT750,'Shuttle Bids'!AT854,'Shuttle Bids'!AT802) -> 325 | CD24: =+CD23+1 -> 37 | CF24: =AVERAGE('Shuttle Bids'!AW757,'Shuttle Bids'!AW861,'Shuttle Bids'!AW809) -> -50 | CG24: =AVERAGE('Shuttle Bids'!AX757,'Shuttle Bids'!AX861,'Shuttle Bids'!AX809) -> -50
A25: =+'Non-shuttle Bids'!A131 -> 37 | AE25: =+AE24+1 -> 27 | AF25: =AVERAGE('Non-shuttle Bids'!AN748,'Non-shuttle Bids'!AN852,'Non-shuttle Bids'!AN800) -> 400 | AG25: =AVERAGE('Non-shuttle Bids'!AO748,'Non-shuttle Bids'!AO852,'Non-shuttle Bids'!AO800) -> 100 | AH25: =AVERAGE('Non-shuttle Bids'!AP748,'Non-shuttle Bids'!AP852,'Non-shuttle Bids'!AP800) -> 250 | AI25: =+AI24+1 -> 31 | AJ25: =AVERAGE('Non-shuttle Bids'!AR803,'Non-shuttle Bids'!AR855,'Non-shuttle Bids'!AR751) -> 300 | AL25: =AVERAGE('Non-shuttle Bids'!AT803,'Non-shuttle Bids'!AT855,'Non-shuttle Bids'!AT751) -> 300 | AM25: =+AM24+1 -> 38 | AR25: 37 | BV25: =+BV24+1 -> 27 | BX25: =AVERAGE('Shuttle Bids'!AO748,'Shuttle Bids'!AO852,'Shuttle Bids'!AO800) -> 391.66667 | BY25: =AVERAGE('Shuttle Bids'!AP748,'Shuttle Bids'!AP852,'Shuttle Bids'!AP800) -> 391.66667 | BZ25: =+BZ24+1 -> 31 | CD25: =+CD24+1 -> 38 | CE25: =AVERAGE('Shuttle Bids'!AV758,'Shuttle Bids'!AV862,'Shuttle Bids'!AV810) -> -138 | CF25: =AVERAGE('Shuttle Bids'!AW758,'Shuttle Bids'!AW862,'Shuttle Bids'!AW810) -> -50 | CG25: =AVERAGE('Shuttle Bids'!AX758,'Shuttle Bids'!AX862,'Shuttle Bids'!AX810) -> -81.333333
A26: =+'Non-shuttle Bids'!A132 -> 38 | K26: 38 | AE26: =+AE25+1 -> 28 | AF26: =AVERAGE('Non-shuttle Bids'!AN749,'Non-shuttle Bids'!AN853,'Non-shuttle Bids'!AN801) -> 400 | AG26: =AVERAGE('Non-shuttle Bids'!AO749,'Non-shuttle Bids'!AO853,'Non-shuttle Bids'!AO801) -> 100 | AH26: =AVERAGE('Non-shuttle Bids'!AP749,'Non-shuttle Bids'!AP853,'Non-shuttle Bids'!AP801) -> 250 | AI26: =+AI25+1 -> 32 | AJ26: =AVERAGE('Non-shuttle Bids'!AR804,'Non-shuttle Bids'!AR856,'Non-shuttle Bids'!AR752) -> 300 | AL26: =AVERAGE('Non-shuttle Bids'!AT804,'Non-shuttle Bids'!AT856,'Non-shuttle Bids'!AT752) -> 300 | AM26: =+AM25+1 -> 39 | AR26: 38 | BB26: 38 | BV26: =+BV25+1 -> 28 | BW26: =AVERAGE('Shuttle Bids'!AN749,'Shuttle Bids'!AN853,'Shuttle Bids'!AN801) -> 300 | BX26: =AVERAGE('Shuttle Bids'!AO749,'Shuttle Bids'!AO853,'Shuttle Bids'!AO801) -> 375 | BY26: =AVERAGE('Shuttle Bids'!AP749,'Shuttle Bids'!AP853,'Shuttle Bids'!AP801) -> 350 | BZ26: =+BZ25+1 -> 32 | CB26: =AVERAGE('Shuttle Bids'!AS752,'Shuttle Bids'!AS856,'Shuttle Bids'!AS804) -> 250 | CC26: =AVERAGE('Shuttle Bids'!AT752,'Shuttle Bids'!AT856,'Shuttle Bids'!AT804) -> 250 | CD26: =+CD25+1 -> 39 | CE26: =AVERAGE('Shuttle Bids'!AV759,'Shuttle Bids'!AV863,'Shuttle Bids'!AV811) -> -200 | CF26: =AVERAGE('Shuttle Bids'!AW759,'Shuttle Bids'!AW863,'Shuttle Bids'!AW811) -> -104.33333 | CG26: =AVERAGE('Shuttle Bids'!AX759,'Shuttle Bids'!AX863,'Shuttle Bids'!AX811) -> -129.33333
A27: =+'Non-shuttle Bids'!A133 -> 39 | K27: 39 | AE27: =+AE26+1 -> 29 | AF27: =AVERAGE('Non-shuttle Bids'!AN750,'Non-shuttle Bids'!AN854,'Non-shuttle Bids'!AN802) -> 400 | AG27: =AVERAGE('Non-shuttle Bids'!AO750,'Non-shuttle Bids'!AO854,'Non-shuttle Bids'!AO802) -> 100 | AH27: =AVERAGE('Non-shuttle Bids'!AP750,'Non-shuttle Bids'!AP854,'Non-shuttle Bids'!AP802) -> 250 | AI27: =+AI26+1 -> 33 | AJ27: =AVERAGE('Non-shuttle Bids'!AR805,'Non-shuttle Bids'!AR857,'Non-shuttle Bids'!AR753) -> 300 | AL27: =AVERAGE('Non-shuttle Bids'!AT805,'Non-shuttle Bids'!AT857,'Non-shuttle Bids'!AT753) -> 300 | AM27: =+AM26+1 -> 40 | AN27: =AVERAGE('Non-shuttle Bids'!AV812,'Non-shuttle Bids'!AV864,'Non-shuttle Bids'!AV760) -> 0 | AP27: =AVERAGE('Non-shuttle Bids'!AX812,'Non-shuttle Bids'!AX864,'Non-shuttle Bids'!AX760) -> 0 | AR27: 39 | BB27: 39 | BV27: =+BV26+1 -> 29 | BW27: =AVERAGE('Shuttle Bids'!AN750,'Shuttle Bids'!AN854,'Shuttle Bids'!AN802) -> 687.5 | BX27: =AVERAGE('Shuttle Bids'!AO750,'Shuttle Bids'!AO854,'Shuttle Bids'!AO802) -> 325 | BY27: =AVERAGE('Shuttle Bids'!AP750,'Shuttle Bids'!AP854,'Shuttle Bids'!AP802) -> 412.5 | BZ27: =+BZ26+1 -> 33 | CB27: =AVERAGE('Shuttle Bids'!AS753,'Shuttle Bids'!AS857,'Shuttle Bids'!AS805) -> 250 | CC27: =AVERAGE('Shuttle Bids'!AT753,'Shuttle Bids'!AT857,'Shuttle Bids'!AT805) -> 250 | CD27: =+CD26+1 -> 40 | CE27: =AVERAGE('Shuttle Bids'!AV760,'Shuttle Bids'!AV864,'Shuttle Bids'!AV812) -> -112.5 | CF27: =AVERAGE('Shuttle Bids'!AW760,'Shuttle Bids'!AW864,'Shuttle Bids'!AW812) -> -112.66667 | CG27: =AVERAGE('Shuttle Bids'!AX760,'Shuttle Bids'!AX864,'Shuttle Bids'!AX812) -> -123
A28: =+'Non-shuttle Bids'!A134 -> 40 | K28: 40 | AE28: =+AE27+1 -> 30 | AF28: =AVERAGE('Non-shuttle Bids'!AN751,'Non-shuttle Bids'!AN855,'Non-shuttle Bids'!AN803) -> 400 | AG28: =AVERAGE('Non-shuttle Bids'!AO751,'Non-shuttle Bids'!AO855,'Non-shuttle Bids'!AO803) -> 100 | AH28: =AVERAGE('Non-shuttle Bids'!AP751,'Non-shuttle Bids'!AP855,'Non-shuttle Bids'!AP803) -> 250 | AI28: =+AI27+1 -> 34 | AM28: =+AM27+1 -> 41 | AN28: =AVERAGE('Non-shuttle Bids'!AV813,'Non-shuttle Bids'!AV865,'Non-shuttle Bids'!AV761) -> 0 | AP28: =AVERAGE('Non-shuttle Bids'!AX813,'Non-shuttle Bids'!AX865,'Non-shuttle Bids'!AX761) -> 0 | AR28: 40 | AT28: =AVERAGE('Shuttle Bids'!E709,'Shuttle Bids'!E761,'Shuttle Bids'!E813) -> -100 | AU28: =AVERAGE('Shuttle Bids'!F709,'Shuttle Bids'!F761,'Shuttle Bids'!F813) -> -100 | BB28: 40 | BV28: =+BV27+1 -> 30 | BX28: =AVERAGE('Shuttle Bids'!AO751,'Shuttle Bids'!AO855,'Shuttle Bids'!AO803) -> 362.5 | BY28: =AVERAGE('Shuttle Bids'!AP751,'Shuttle Bids'!AP855,'Shuttle Bids'!AP803) -> 362.5 | BZ28: =+BZ27+1 -> 34 | CA28: =AVERAGE('Shuttle Bids'!AR754,'Shuttle Bids'!AR858,'Shuttle Bids'!AR806) -> 275 | CB28: =AVERAGE('Shuttle Bids'!AS754,'Shuttle Bids'!AS858,'Shuttle Bids'!AS806) -> 250 | CC28: =AVERAGE('Shuttle Bids'!AT754,'Shuttle Bids'!AT858,'Shuttle Bids'!AT806) -> 287.5 | CD28: =+CD27+1 -> 41 | CE28: =AVERAGE('Shuttle Bids'!AV761,'Shuttle Bids'!AV865,'Shuttle Bids'!AV813) -> -158.33333 | CF28: =AVERAGE('Shuttle Bids'!AW761,'Shuttle Bids'!AW865,'Shuttle Bids'!AW813) -> -108.33333 | CG28: =AVERAGE('Shuttle Bids'!AX761,'Shuttle Bids'!AX865,'Shuttle Bids'!AX813) -> -133.33333
A29: =+'Non-shuttle Bids'!A135 -> 41 | K29: 41 | AE29: =+AE28+1 -> 31 | AF29: =AVERAGE('Non-shuttle Bids'!AN752,'Non-shuttle Bids'!AN856,'Non-shuttle Bids'!AN804) -> 175 | AG29: =AVERAGE('Non-shuttle Bids'!AO752,'Non-shuttle Bids'!AO856,'Non-shuttle Bids'!AO804) -> 100 | AH29: =AVERAGE('Non-shuttle Bids'!AP752,'Non-shuttle Bids'!AP856,'Non-shuttle Bids'!AP804) -> 150 | AI29: =+AI28+1 -> 35 | AM29: =+AM28+1 -> 42 | AN29: =AVERAGE('Non-shuttle Bids'!AV814,'Non-shuttle Bids'!AV866,'Non-shuttle Bids'!AV762) -> 96 | AO29: =AVERAGE('Non-shuttle Bids'!AW814,'Non-shuttle Bids'!AW866,'Non-shuttle Bids'!AW762) -> -33 | AP29: =AVERAGE('Non-shuttle Bids'!AX814,'Non-shuttle Bids'!AX866,'Non-shuttle Bids'!AX762) -> 90.5 | AR29: 41 | BB29: 41 | BC29: =AVERAGE('Shuttle Bids'!P710,'Shuttle Bids'!P762,'Shuttle Bids'!P814) -> -400 | BE29: =AVERAGE('Shuttle Bids'!R710,'Shuttle Bids'!R762,'Shuttle Bids'!R814) -> -400 | BV29: =+BV28+1 -> 31 | BW29: =AVERAGE('Shuttle Bids'!AN752,'Shuttle Bids'!AN856,'Shuttle Bids'!AN804) -> -112 | BX29: =AVERAGE('Shuttle Bids'!AO752,'Shuttle Bids'!AO856,'Shuttle Bids'!AO804) -> 262.66667 | BY29: =AVERAGE('Shuttle Bids'!AP752,'Shuttle Bids'!AP856,'Shuttle Bids'!AP804) -> 196 | BZ29: =+BZ28+1 -> 35 | CA29: =AVERAGE('Shuttle Bids'!AR755,'Shuttle Bids'!AR859,'Shuttle Bids'!AR807) -> 400 | CB29: =AVERAGE('Shuttle Bids'!AS755,'Shuttle Bids'!AS859,'Shuttle Bids'!AS807) -> 250 | CC29: =AVERAGE('Shuttle Bids'!AT755,'Shuttle Bids'!AT859,'Shuttle Bids'!AT807) -> 325 | CD29: =+CD28+1 -> 42 | CE29: =AVERAGE('Shuttle Bids'!AV762,'Shuttle Bids'!AV866,'Shuttle Bids'!AV814) -> -56 | CF29: =AVERAGE('Shuttle Bids'!AW762,'Shuttle Bids'!AW866,'Shuttle Bids'!AW814) -> -150 | CG29: =AVERAGE('Shuttle Bids'!AX762,'Shuttle Bids'!AX866,'Shuttle Bids'!AX814) -> -127
A30: =+'Non-shuttle Bids'!A136 -> 42 | K30: 42 | AE30: =+AE29+1 -> 32 | AF30: =AVERAGE('Non-shuttle Bids'!AN753,'Non-shuttle Bids'!AN857,'Non-shuttle Bids'!AN805) -> 175 | AH30: =AVERAGE('Non-shuttle Bids'!AP753,'Non-shuttle Bids'!AP857,'Non-shuttle Bids'!AP805) -> 175 | AI30: =+AI29+1 -> 36 | AM30: =+AM29+1 -> 43 | AN30: =AVERAGE('Non-shuttle Bids'!AV815,'Non-shuttle Bids'!AV867,'Non-shuttle Bids'!AV763) -> 114 | AO30: =AVERAGE('Non-shuttle Bids'!AW815,'Non-shuttle Bids'!AW867,'Non-shuttle Bids'!AW763) -> -33 | AP30: =AVERAGE('Non-shuttle Bids'!AX815,'Non-shuttle Bids'!AX867,'Non-shuttle Bids'!AX763) -> 108.5 | AR30: 42 | AS30: =AVERAGE('Shuttle Bids'!D711,'Shuttle Bids'!D763,'Shuttle Bids'!D815) -> -350 | AT30: =AVERAGE('Shuttle Bids'!E711,'Shuttle Bids'!E763,'Shuttle Bids'!E815) -> -250 | AU30: =AVERAGE('Shuttle Bids'!F711,'Shuttle Bids'!F763,'Shuttle Bids'!F815) -> -300 | AV30: =AVERAGE('Shuttle Bids'!H710,'Shuttle Bids'!H762,'Shuttle Bids'!H814) -> -200 | AX30: =AVERAGE('Shuttle Bids'!J710,'Shuttle Bids'!J762,'Shuttle Bids'!J814) -> -200 | BB30: 42 | BC30: =AVERAGE('Shuttle Bids'!P711,'Shuttle Bids'!P763,'Shuttle Bids'!P815) -> -800 | BE30: =AVERAGE('Shuttle Bids'!R711,'Shuttle Bids'!R763,'Shuttle Bids'!R815) -> -800 | BV30: =+BV29+1 -> 32 | BW30: =AVERAGE('Shuttle Bids'!AN753,'Shuttle Bids'!AN857,'Shuttle Bids'!AN805) -> 450 | BX30: =AVERAGE('Shuttle Bids'!AO753,'Shuttle Bids'!AO857,'Shuttle Bids'!AO805) -> 300 | BY30: =AVERAGE('Shuttle Bids'!AP753,'Shuttle Bids'!AP857,'Shuttle Bids'!AP805) -> 325 | BZ30: =+BZ29+1 -> 36 | CA30: =AVERAGE('Shuttle Bids'!AR756,'Shuttle Bids'!AR860,'Shuttle Bids'!AR808) -> 350 | CB30: =AVERAGE('Shuttle Bids'!AS756,'Shuttle Bids'!AS860,'Shuttle Bids'!AS808) -> 200 | CC30: =AVERAGE('Shuttle Bids'!AT756,'Shuttle Bids'!AT860,'Shuttle Bids'!AT808) -> 350 | CD30: =+CD29+1 -> 43 | CE30: =AVERAGE('Shuttle Bids'!AV763,'Shuttle Bids'!AV867,'Shuttle Bids'!AV815) -> -325 | CF30: =AVERAGE('Shuttle Bids'!AW763,'Shuttle Bids'!AW867,'Shuttle Bids'!AW815) -> -125 | CG30: =AVERAGE('Shuttle Bids'!AX763,'Shuttle Bids'!AX867,'Shuttle Bids'!AX815) -> -145.83333
A31: =+'Non-shuttle Bids'!A137 -> 43 | B31: =AVERAGE('Non-shuttle Bids'!D712,'Non-shuttle Bids'!D764,'Non-shuttle Bids'!D816) -> -125 | D31: =AVERAGE('Non-shuttle Bids'!F712,'Non-shuttle Bids'!F764,'Non-shuttle Bids'!F816) -> -125 | K31: 43 | AE31: =+AE30+1 -> 33 | AF31: =AVERAGE('Non-shuttle Bids'!AN754,'Non-shuttle Bids'!AN858,'Non-shuttle Bids'!AN806) -> 66.5 | AH31: =AVERAGE('Non-shuttle Bids'!AP754,'Non-shuttle Bids'!AP858,'Non-shuttle Bids'!AP806) -> 66.5 | AI31: =+AI30+1 -> 37 | AM31: =+AM30+1 -> 44 | AN31: =AVERAGE('Non-shuttle Bids'!AV816,'Non-shuttle Bids'!AV868,'Non-shuttle Bids'!AV764) -> 83.333333 | AO31: =AVERAGE('Non-shuttle Bids'!AW816,'Non-shuttle Bids'!AW868,'Non-shuttle Bids'!AW764) -> -33 | AP31: =AVERAGE('Non-shuttle Bids'!AX816,'Non-shuttle Bids'!AX868,'Non-shuttle Bids'!AX764) -> 77.833333 | AR31: 43 | AT31: =AVERAGE('Shuttle Bids'!E712,'Shuttle Bids'!E764,'Shuttle Bids'!E816) -> -300 | AU31: =AVERAGE('Shuttle Bids'!F712,'Shuttle Bids'!F764,'Shuttle Bids'!F816) -> -300 | BB31: 43 | BF31: =AVERAGE('Shuttle Bids'!T712,'Shuttle Bids'!T764,'Shuttle Bids'!T816) -> -800 | BG31: =AVERAGE('Shuttle Bids'!U712,'Shuttle Bids'!U764,'Shuttle Bids'!U816) -> -900 | BH31: =AVERAGE('Shuttle Bids'!V712,'Shuttle Bids'!V764,'Shuttle Bids'!V816) -> -850 | BV31: =+BV30+1 -> 33 | BW31: =AVERAGE('Shuttle Bids'!AN754,'Shuttle Bids'!AN858,'Shuttle Bids'!AN806) -> 625 | BX31: =AVERAGE('Shuttle Bids'!AO754,'Shuttle Bids'!AO858,'Shuttle Bids'!AO806) -> 333.33333 | BY31: =AVERAGE('Shuttle Bids'!AP754,'Shuttle Bids'!AP858,'Shuttle Bids'!AP806) -> 425 | BZ31: =+BZ30+1 -> 37 | CB31: =AVERAGE('Shuttle Bids'!AS757,'Shuttle Bids'!AS861,'Shuttle Bids'!AS809) -> 175 | CC31: =AVERAGE('Shuttle Bids'!AT757,'Shuttle Bids'!AT861,'Shuttle Bids'!AT809) -> 175 | CD31: =+CD30+1 -> 44 | CE31: =AVERAGE('Shuttle Bids'!AV764,'Shuttle Bids'!AV868,'Shuttle Bids'!AV816) -> 87.5 | CF31: =AVERAGE('Shuttle Bids'!AW764,'Shuttle Bids'!AW868,'Shuttle Bids'!AW816) -> -150 | CG31: =AVERAGE('Shuttle Bids'!AX764,'Shuttle Bids'!AX868,'Shuttle Bids'!AX816) -> -100
A32: =+'Non-shuttle Bids'!A138 -> 44 | B32: =AVERAGE('Non-shuttle Bids'!D713,'Non-shuttle Bids'!D765,'Non-shuttle Bids'!D817) -> -125 | D32: =AVERAGE('Non-shuttle Bids'!F713,'Non-shuttle Bids'!F765,'Non-shuttle Bids'!F817) -> -125 | K32: 44 | AE32: =+AE31+1 -> 34 | AF32: =AVERAGE('Non-shuttle Bids'!AN755,'Non-shuttle Bids'!AN859,'Non-shuttle Bids'!AN807) -> 100 | AH32: =AVERAGE('Non-shuttle Bids'!AP755,'Non-shuttle Bids'!AP859,'Non-shuttle Bids'!AP807) -> 100 | AI32: =+AI31+1 -> 38 | AJ32: =AVERAGE('Non-shuttle Bids'!AR810,'Non-shuttle Bids'!AR862,'Non-shuttle Bids'!AR758) -> 100 | AL32: =AVERAGE('Non-shuttle Bids'!AT810,'Non-shuttle Bids'!AT862,'Non-shuttle Bids'!AT758) -> 100 | AM32: =+AM31+1 -> 45 | AN32: =AVERAGE('Non-shuttle Bids'!AV817,'Non-shuttle Bids'!AV869,'Non-shuttle Bids'!AV765) -> 391.66667 | AO32: =AVERAGE('Non-shuttle Bids'!AW817,'Non-shuttle Bids'!AW869,'Non-shuttle Bids'!AW765) -> -75 | AP32: =AVERAGE('Non-shuttle Bids'!AX817,'Non-shuttle Bids'!AX869,'Non-shuttle Bids'!AX765) -> 379.16667 | AR32: 44 | BB32: 44 | BF32: =AVERAGE('Shuttle Bids'!T713,'Shuttle Bids'!T765,'Shuttle Bids'!T817) -> -725 | BH32: =AVERAGE('Shuttle Bids'!V713,'Shuttle Bids'!V765,'Shuttle Bids'!V817) -> -725 | BV32: =+BV31+1 -> 34 | BW32: =AVERAGE('Shuttle Bids'!AN755,'Shuttle Bids'!AN859,'Shuttle Bids'!AN807) -> 350 | BX32: =AVERAGE('Shuttle Bids'!AO755,'Shuttle Bids'!AO859,'Shuttle Bids'!AO807) -> 350 | BY32: =AVERAGE('Shuttle Bids'!AP755,'Shuttle Bids'!AP859,'Shuttle Bids'!AP807) -> 333.33333 | BZ32: =+BZ31+1 -> 38 | CB32: =AVERAGE('Shuttle Bids'!AS758,'Shuttle Bids'!AS862,'Shuttle Bids'!AS810) -> 200 | CC32: =AVERAGE('Shuttle Bids'!AT758,'Shuttle Bids'!AT862,'Shuttle Bids'!AT810) -> 200 | CD32: =+CD31+1 -> 45 | CE32: =AVERAGE('Shuttle Bids'!AV765,'Shuttle Bids'!AV869,'Shuttle Bids'!AV817) -> 275 | CF32: =AVERAGE('Shuttle Bids'!AW765,'Shuttle Bids'!AW869,'Shuttle Bids'!AW817) -> -166.66667 | CG32: =AVERAGE('Shuttle Bids'!AX765,'Shuttle Bids'!AX869,'Shuttle Bids'!AX817) -> 54.166667
A33: =+'Non-shuttle Bids'!A139 -> 45 | B33: =AVERAGE('Non-shuttle Bids'!D714,'Non-shuttle Bids'!D766,'Non-shuttle Bids'!D818) -> -125 | C33: =AVERAGE('Non-shuttle Bids'!E714,'Non-shuttle Bids'!E766,'Non-shuttle Bids'!E818) -> -50 | D33: =AVERAGE('Non-shuttle Bids'!F714,'Non-shuttle Bids'!F766,'Non-shuttle Bids'!F818) -> -87.5 | K33: 45 | AE33: =+AE32+1 -> 35 | AF33: =AVERAGE('Non-shuttle Bids'!AN756,'Non-shuttle Bids'!AN860,'Non-shuttle Bids'!AN808) -> 237.5 | AH33: =AVERAGE('Non-shuttle Bids'!AP756,'Non-shuttle Bids'!AP860,'Non-shuttle Bids'!AP808) -> 237.5 | AI33: =+AI32+1 -> 39 | AJ33: =AVERAGE('Non-shuttle Bids'!AR811,'Non-shuttle Bids'!AR863,'Non-shuttle Bids'!AR759) -> 25 | AL33: =AVERAGE('Non-shuttle Bids'!AT811,'Non-shuttle Bids'!AT863,'Non-shuttle Bids'!AT759) -> 25 | AM33: =+AM32+1 -> 46 | AN33: =AVERAGE('Non-shuttle Bids'!AV818,'Non-shuttle Bids'!AV870,'Non-shuttle Bids'!AV766) -> 322.33333 | AO33: =AVERAGE('Non-shuttle Bids'!AW818,'Non-shuttle Bids'!AW870,'Non-shuttle Bids'!AW766) -> -25 | AP33: =AVERAGE('Non-shuttle Bids'!AX818,'Non-shuttle Bids'!AX870,'Non-shuttle Bids'!AX766) -> 319.5 | AR33: 45 | AT33: =AVERAGE('Shuttle Bids'!E714,'Shuttle Bids'!E766,'Shuttle Bids'!E818) -> -312.66667 | AU33: =AVERAGE('Shuttle Bids'!F714,'Shuttle Bids'!F766,'Shuttle Bids'!F818) -> -312.66667 | BB33: 45 | BF33: =AVERAGE('Shuttle Bids'!T714,'Shuttle Bids'!T766,'Shuttle Bids'!T818) -> -675 | BG33: =AVERAGE('Shuttle Bids'!U714,'Shuttle Bids'!U766,'Shuttle Bids'!U818) -> -800 | BH33: =AVERAGE('Shuttle Bids'!V714,'Shuttle Bids'!V766,'Shuttle Bids'!V818) -> -737.5 | BV33: =+BV32+1 -> 35 | BW33: =AVERAGE('Shuttle Bids'!AN756,'Shuttle Bids'!AN860,'Shuttle Bids'!AN808) -> 600 | BX33: =AVERAGE('Shuttle Bids'!AO756,'Shuttle Bids'!AO860,'Shuttle Bids'!AO808) -> 525 | BY33: =AVERAGE('Shuttle Bids'!AP756,'Shuttle Bids'!AP860,'Shuttle Bids'!AP808) -> 491.66667 | BZ33: =+BZ32+1 -> 39 | CB33: =AVERAGE('Shuttle Bids'!AS759,'Shuttle Bids'!AS863,'Shuttle Bids'!AS811) -> 41.666667 | CC33: =AVERAGE('Shuttle Bids'!AT759,'Shuttle Bids'!AT863,'Shuttle Bids'!AT811) -> 41.666667 | CD33: =+CD32+1 -> 46 | CE33: =AVERAGE('Shuttle Bids'!AV766,'Shuttle Bids'!AV870,'Shuttle Bids'!AV818) -> 287.5 | CF33: =AVERAGE('Shuttle Bids'!AW766,'Shuttle Bids'!AW870,'Shuttle Bids'!AW818) -> -171 | CG33: =AVERAGE('Shuttle Bids'!AX766,'Shuttle Bids'!AX870,'Shuttle Bids'!AX818) -> -64.666667
A34: =+'Non-shuttle Bids'!A140 -> 46 | B34: =AVERAGE('Non-shuttle Bids'!D715,'Non-shuttle Bids'!D767,'Non-shuttle Bids'!D819) -> -16.5 | C34: =AVERAGE('Non-shuttle Bids'!E715,'Non-shuttle Bids'!E767,'Non-shuttle Bids'!E819) -> 0 | D34: =AVERAGE('Non-shuttle Bids'!F715,'Non-shuttle Bids'!F767,'Non-shuttle Bids'!F819) -> -22.75 | K34: 46 | AE34: =+AE33+1 -> 36 | AF34: =AVERAGE('Non-shuttle Bids'!AN757,'Non-shuttle Bids'!AN861,'Non-shuttle Bids'!AN809) -> 158.33333 | AG34: =AVERAGE('Non-shuttle Bids'!AO757,'Non-shuttle Bids'!AO861,'Non-shuttle Bids'!AO809) -> 0 | AH34: =AVERAGE('Non-shuttle Bids'!AP757,'Non-shuttle Bids'!AP861,'Non-shuttle Bids'!AP809) -> 154.16667 | AI34: =+AI33+1 -> 40 | AJ34: =AVERAGE('Non-shuttle Bids'!AR812,'Non-shuttle Bids'!AR864,'Non-shuttle Bids'!AR760) -> 8.3333333 | AL34: =AVERAGE('Non-shuttle Bids'!AT812,'Non-shuttle Bids'!AT864,'Non-shuttle Bids'!AT760) -> 8.3333333 | AM34: =+AM33+1 -> 47 | AN34: =AVERAGE('Non-shuttle Bids'!AV819,'Non-shuttle Bids'!AV871,'Non-shuttle Bids'!AV767) -> 101.33333 | AO34: =AVERAGE('Non-shuttle Bids'!AW819,'Non-shuttle Bids'!AW871,'Non-shuttle Bids'!AW767) -> -4 | AP34: =AVERAGE('Non-shuttle Bids'!AX819,'Non-shuttle Bids'!AX871,'Non-shuttle Bids'!AX767) -> 99.333333 | AR34: 46 | AT34: =AVERAGE('Shuttle Bids'!E715,'Shuttle Bids'!E767,'Shuttle Bids'!E819) -> -300 | AU34: =AVERAGE('Shuttle Bids'!F715,'Shuttle Bids'!F767,'Shuttle Bids'!F819) -> -300 | AZ34: =AVERAGE('Shuttle Bids'!M715,'Shuttle Bids'!M767,'Shuttle Bids'!M819) -> -350 | BA34: =AVERAGE('Shuttle Bids'!N715,'Shuttle Bids'!N767,'Shuttle Bids'!N819) -> -350 | BB34: 46 | BD34: =AVERAGE('Shuttle Bids'!Q715,'Shuttle Bids'!Q767,'Shuttle Bids'!Q819) -> -625 | BE34: =AVERAGE('Shuttle Bids'!R715,'Shuttle Bids'!R767,'Shuttle Bids'!R819) -> -625 | BV34: =+BV33+1 -> 36 | BW34: =AVERAGE('Shuttle Bids'!AN757,'Shuttle Bids'!AN861,'Shuttle Bids'!AN809) -> 375 | BX34: =AVERAGE('Shuttle Bids'!AO757,'Shuttle Bids'!AO861,'Shuttle Bids'!AO809) -> 383.33333 | BY34: =AVERAGE('Shuttle Bids'!AP757,'Shuttle Bids'!AP861,'Shuttle Bids'!AP809) -> 379.16667 | BZ34: =+BZ33+1 -> 40 | CA34: =AVERAGE('Shuttle Bids'!AR760,'Shuttle Bids'!AR864,'Shuttle Bids'!AR812) -> 162.5 | CB34: =AVERAGE('Shuttle Bids'!AS760,'Shuttle Bids'!AS864,'Shuttle Bids'!AS812) -> 20.666667 | CC34: =AVERAGE('Shuttle Bids'!AT760,'Shuttle Bids'!AT864,'Shuttle Bids'!AT812) -> 60.333333 | CD34: =+CD33+1 -> 47 | CE34: =AVERAGE('Shuttle Bids'!AV767,'Shuttle Bids'!AV871,'Shuttle Bids'!AV819) -> -33.333333 | CF34: =AVERAGE('Shuttle Bids'!AW767,'Shuttle Bids'!AW871,'Shuttle Bids'!AW819) -> -243.66667 | CG34: =AVERAGE('Shuttle Bids'!AX767,'Shuttle Bids'!AX871,'Shuttle Bids'!AX819) -> -138.5
A35: =+'Non-shuttle Bids'!A141 -> 47 | B35: =AVERAGE('Non-shuttle Bids'!D716,'Non-shuttle Bids'!D768,'Non-shuttle Bids'!D820) -> 5 | C35: =AVERAGE('Non-shuttle Bids'!E716,'Non-shuttle Bids'!E768,'Non-shuttle Bids'!E820) -> -13 | D35: =AVERAGE('Non-shuttle Bids'!F716,'Non-shuttle Bids'!F768,'Non-shuttle Bids'!F820) -> 1.75 | K35: 47 | AE35: =+AE34+1 -> 37 | AF35: =AVERAGE('Non-shuttle Bids'!AN758,'Non-shuttle Bids'!AN862,'Non-shuttle Bids'!AN810) -> 171 | AG35: =AVERAGE('Non-shuttle Bids'!AO758,'Non-shuttle Bids'!AO862,'Non-shuttle Bids'!AO810) -> 79 | AH35: =AVERAGE('Non-shuttle Bids'!AP758,'Non-shuttle Bids'!AP862,'Non-shuttle Bids'!AP810) -> 178.5 | AI35: =+AI34+1 -> 41 | AJ35: =AVERAGE('Non-shuttle Bids'!AR813,'Non-shuttle Bids'!AR865,'Non-shuttle Bids'!AR761) -> 75 | AL35: =AVERAGE('Non-shuttle Bids'!AT813,'Non-shuttle Bids'!AT865,'Non-shuttle Bids'!AT761) -> 75 | AM35: =+AM34+1 -> 48 | AN35: =AVERAGE('Non-shuttle Bids'!AV820,'Non-shuttle Bids'!AV872,'Non-shuttle Bids'!AV768) -> 83.333333 | AO35: =AVERAGE('Non-shuttle Bids'!AW820,'Non-shuttle Bids'!AW872,'Non-shuttle Bids'!AW768) -> 14 | AP35: =AVERAGE('Non-shuttle Bids'!AX820,'Non-shuttle Bids'!AX872,'Non-shuttle Bids'!AX768) -> 48.666667 | AR35: 47 | AT35: =AVERAGE('Shuttle Bids'!E716,'Shuttle Bids'!E768,'Shuttle Bids'!E820) -> -262.5 | AU35: =AVERAGE('Shuttle Bids'!F716,'Shuttle Bids'!F768,'Shuttle Bids'!F820) -> -262.5 | AW35: =AVERAGE('Shuttle Bids'!I715,'Shuttle Bids'!I767,'Shuttle Bids'!I819) -> -350 | AX35: =AVERAGE('Shuttle Bids'!J715,'Shuttle Bids'!J767,'Shuttle Bids'!J819) -> -350 | AZ35: =AVERAGE('Shuttle Bids'!M716,'Shuttle Bids'!M768,'Shuttle Bids'!M820) -> -300 | BA35: =AVERAGE('Shuttle Bids'!N716,'Shuttle Bids'!N768,'Shuttle Bids'!N820) -> -300 | BB35: 47 | BJ35: =AVERAGE('Shuttle Bids'!Y715,'Shuttle Bids'!Y767,'Shuttle Bids'!Y819) -> -125 | BK35: =AVERAGE('Shuttle Bids'!Z715,'Shuttle Bids'!Z767,'Shuttle Bids'!Z819) -> -125 | BV35: =+BV34+1 -> 37 | BW35: =AVERAGE('Shuttle Bids'!AN758,'Shuttle Bids'!AN862,'Shuttle Bids'!AN810) -> 508.33333 | BX35: =AVERAGE('Shuttle Bids'!AO758,'Shuttle Bids'!AO862,'Shuttle Bids'!AO810) -> 416.66667 | BY35: =AVERAGE('Shuttle Bids'!AP758,'Shuttle Bids'!AP862,'Shuttle Bids'!AP810) -> 462.5 | BZ35: =+BZ34+1 -> 41 | CA35: =AVERAGE('Shuttle Bids'!AR761,'Shuttle Bids'!AR865,'Shuttle Bids'!AR813) -> 155.66667 | CB35: =AVERAGE('Shuttle Bids'!AS761,'Shuttle Bids'!AS865,'Shuttle Bids'!AS813) -> 50 | CC35: =AVERAGE('Shuttle Bids'!AT761,'Shuttle Bids'!AT865,'Shuttle Bids'!AT813) -> 102.83333 | CD35: =+CD34+1 -> 48 | CE35: =AVERAGE('Shuttle Bids'!AV768,'Shuttle Bids'!AV872,'Shuttle Bids'!AV820) -> 181.66667 | CF35: =AVERAGE('Shuttle Bids'!AW768,'Shuttle Bids'!AW872,'Shuttle Bids'!AW820) -> -123.66667 | CG35: =AVERAGE('Shuttle Bids'!AX768,'Shuttle Bids'!AX872,'Shuttle Bids'!AX820) -> 29
A36: =+'Non-shuttle Bids'!A142 -> 48 | B36: =AVERAGE('Non-shuttle Bids'!D717,'Non-shuttle Bids'!D769,'Non-shuttle Bids'!D821) -> -12.5 | C36: =AVERAGE('Non-shuttle Bids'!E717,'Non-shuttle Bids'!E769,'Non-shuttle Bids'!E821) -> -13 | D36: =AVERAGE('Non-shuttle Bids'!F717,'Non-shuttle Bids'!F769,'Non-shuttle Bids'!F821) -> -9.5 | K36: 48 | AE36: =+AE35+1 -> 38 | AF36: =AVERAGE('Non-shuttle Bids'!AN759,'Non-shuttle Bids'!AN863,'Non-shuttle Bids'!AN811) -> 103.33333 | AG36: =AVERAGE('Non-shuttle Bids'!AO759,'Non-shuttle Bids'!AO863,'Non-shuttle Bids'!AO811) -> 79.5 | AH36: =AVERAGE('Non-shuttle Bids'!AP759,'Non-shuttle Bids'!AP863,'Non-shuttle Bids'!AP811) -> 111.5 | AI36: =+AI35+1 -> 42 | AJ36: =AVERAGE('Non-shuttle Bids'!AR814,'Non-shuttle Bids'!AR866,'Non-shuttle Bids'!AR762) -> 172.33333 | AK36: =AVERAGE('Non-shuttle Bids'!AS814,'Non-shuttle Bids'!AS866,'Non-shuttle Bids'!AS762) -> -16.5 | AL36: =AVERAGE('Non-shuttle Bids'!AT814,'Non-shuttle Bids'!AT866,'Non-shuttle Bids'!AT762) -> 172.33333 | AM36: =+AM35+1 -> 49 | AN36: =AVERAGE('Non-shuttle Bids'!AV821,'Non-shuttle Bids'!AV873,'Non-shuttle Bids'!AV769) -> 89.666667 | AO36: =AVERAGE('Non-shuttle Bids'!AW821,'Non-shuttle Bids'!AW873,'Non-shuttle Bids'!AW769) -> 8.3333333 | AP36: =AVERAGE('Non-shuttle Bids'!AX821,'Non-shuttle Bids'!AX873,'Non-shuttle Bids'!AX769) -> 49 | AR36: 48 | AS36: =AVERAGE('Shuttle Bids'!D717,'Shuttle Bids'!D769,'Shuttle Bids'!D821) -> -200 | AT36: =AVERAGE('Shuttle Bids'!E717,'Shuttle Bids'!E769,'Shuttle Bids'!E821) -> -208.33333 | AU36: =AVERAGE('Shuttle Bids'!F717,'Shuttle Bids'!F769,'Shuttle Bids'!F821) -> -200 | AW36: =AVERAGE('Shuttle Bids'!I716,'Shuttle Bids'!I768,'Shuttle Bids'!I820) -> -250 | AX36: =AVERAGE('Shuttle Bids'!J716,'Shuttle Bids'!J768,'Shuttle Bids'!J820) -> -250 | AY36: =AVERAGE('Shuttle Bids'!L717,'Shuttle Bids'!L769,'Shuttle Bids'!L821) -> 13 | AZ36: =AVERAGE('Shuttle Bids'!M717,'Shuttle Bids'!M769,'Shuttle Bids'!M821) -> -250 | BA36: =AVERAGE('Shuttle Bids'!N717,'Shuttle Bids'!N769,'Shuttle Bids'!N821) -> -209.25 | BB36: 48 | BJ36: =AVERAGE('Shuttle Bids'!Y716,'Shuttle Bids'!Y768,'Shuttle Bids'!Y820) -> -125 | BK36: =AVERAGE('Shuttle Bids'!Z716,'Shuttle Bids'!Z768,'Shuttle Bids'!Z820) -> -125 | BV36: =+BV35+1 -> 38 | BW36: =AVERAGE('Shuttle Bids'!AN759,'Shuttle Bids'!AN863,'Shuttle Bids'!AN811) -> 286 | BX36: =AVERAGE('Shuttle Bids'!AO759,'Shuttle Bids'!AO863,'Shuttle Bids'!AO811) -> 262.66667 | BY36: =AVERAGE('Shuttle Bids'!AP759,'Shuttle Bids'!AP863,'Shuttle Bids'!AP811) -> 274.33333 | BZ36: =+BZ35+1 -> 42 | CA36: =AVERAGE('Shuttle Bids'!AR762,'Shuttle Bids'!AR866,'Shuttle Bids'!AR814) -> 356 | CB36: =AVERAGE('Shuttle Bids'!AS762,'Shuttle Bids'!AS866,'Shuttle Bids'!AS814) -> 33.333333 | CC36: =AVERAGE('Shuttle Bids'!AT762,'Shuttle Bids'!AT866,'Shuttle Bids'!AT814) -> 102 | CD36: =+CD35+1 -> 49 | CE36: =AVERAGE('Shuttle Bids'!AV769,'Shuttle Bids'!AV873,'Shuttle Bids'!AV821) -> 273.66667 | CF36: =AVERAGE('Shuttle Bids'!AW769,'Shuttle Bids'!AW873,'Shuttle Bids'!AW821) -> -75 | CG36: =AVERAGE('Shuttle Bids'!AX769,'Shuttle Bids'!AX873,'Shuttle Bids'!AX821) -> 99.333333
A37: =+'Non-shuttle Bids'!A143 -> 49 | B37: =AVERAGE('Non-shuttle Bids'!D718,'Non-shuttle Bids'!D770,'Non-shuttle Bids'!D822) -> 6 | C37: =AVERAGE('Non-shuttle Bids'!E718,'Non-shuttle Bids'!E770,'Non-shuttle Bids'!E822) -> -46 | D37: =AVERAGE('Non-shuttle Bids'!F718,'Non-shuttle Bids'!F770,'Non-shuttle Bids'!F822) -> -8.1666667 | F37: =AVERAGE('Non-shuttle Bids'!I821,'Non-shuttle Bids'!I769,'Non-shuttle Bids'!I717) -> 0 | G37: =AVERAGE('Non-shuttle Bids'!J821,'Non-shuttle Bids'!J769,'Non-shuttle Bids'!J717) -> 0 | I37: =AVERAGE('Non-shuttle Bids'!M821,'Non-shuttle Bids'!M769,'Non-shuttle Bids'!M717) -> 0 | J37: =AVERAGE('Non-shuttle Bids'!N821,'Non-shuttle Bids'!N769,'Non-shuttle Bids'!N717) -> 0 | K37: 49 | AE37: =+AE36+1 -> 39 | AF37: =AVERAGE('Non-shuttle Bids'!AN760,'Non-shuttle Bids'!AN864,'Non-shuttle Bids'!AN812) -> -8.5 | AG37: =AVERAGE('Non-shuttle Bids'!AO760,'Non-shuttle Bids'!AO864,'Non-shuttle Bids'!AO812) -> 14.5 | AH37: =AVERAGE('Non-shuttle Bids'!AP760,'Non-shuttle Bids'!AP864,'Non-shuttle Bids'!AP812) -> 3 | AI37: =+AI36+1 -> 43 | AJ37: =AVERAGE('Non-shuttle Bids'!AR815,'Non-shuttle Bids'!AR867,'Non-shuttle Bids'!AR763) -> 122.33333 | AK37: =AVERAGE('Non-shuttle Bids'!AS815,'Non-shuttle Bids'!AS867,'Non-shuttle Bids'!AS763) -> 22.333333 | AL37: =AVERAGE('Non-shuttle Bids'!AT815,'Non-shuttle Bids'!AT867,'Non-shuttle Bids'!AT763) -> 72.333333 | AM37: 50 | AN37: =AVERAGE('Non-shuttle Bids'!AV822,'Non-shuttle Bids'!AV874,'Non-shuttle Bids'!AV770) -> 452.5 | AO37: =AVERAGE('Non-shuttle Bids'!AW822,'Non-shuttle Bids'!AW874,'Non-shuttle Bids'!AW770) -> 25 | AP37: =AVERAGE('Non-shuttle Bids'!AX822,'Non-shuttle Bids'!AX874,'Non-shuttle Bids'!AX770) -> 163.33333 | AR37: 49 | AS37: =AVERAGE('Shuttle Bids'!D718,'Shuttle Bids'!D770,'Shuttle Bids'!D822) -> -44 | AT37: =AVERAGE('Shuttle Bids'!E718,'Shuttle Bids'!E770,'Shuttle Bids'!E822) -> -100 | AU37: =AVERAGE('Shuttle Bids'!F718,'Shuttle Bids'!F770,'Shuttle Bids'!F822) -> -98 | AW37: =AVERAGE('Shuttle Bids'!I717,'Shuttle Bids'!I769,'Shuttle Bids'!I821) -> -350 | AX37: =AVERAGE('Shuttle Bids'!J717,'Shuttle Bids'!J769,'Shuttle Bids'!J821) -> -350 | AZ37: =AVERAGE('Shuttle Bids'!M718,'Shuttle Bids'!M770,'Shuttle Bids'!M822) -> -208.33333 | BA37: =AVERAGE('Shuttle Bids'!N718,'Shuttle Bids'!N770,'Shuttle Bids'!N822) -> -208.33333 | BB37: 49 | BC37: =AVERAGE('Shuttle Bids'!P718,'Shuttle Bids'!P770,'Shuttle Bids'!P822) -> -200 | BE37: =AVERAGE('Shuttle Bids'!R718,'Shuttle Bids'!R770,'Shuttle Bids'!R822) -> -200 | BJ37: =AVERAGE('Shuttle Bids'!Y717,'Shuttle Bids'!Y769,'Shuttle Bids'!Y821) -> -100 | BK37: =AVERAGE('Shuttle Bids'!Z717,'Shuttle Bids'!Z769,'Shuttle Bids'!Z821) -> -100 | BV37: =+BV36+1 -> 39 | BW37: =AVERAGE('Shuttle Bids'!AN760,'Shuttle Bids'!AN864,'Shuttle Bids'!AN812) -> 719.33333 | BX37: =AVERAGE('Shuttle Bids'!AO760,'Shuttle Bids'!AO864,'Shuttle Bids'!AO812) -> 271 | BY37: =AVERAGE('Shuttle Bids'!AP760,'Shuttle Bids'!AP864,'Shuttle Bids'!AP812) -> 495.16667 | BZ37: =+BZ36+1 -> 43 | CA37: =AVERAGE('Shuttle Bids'!AR763,'Shuttle Bids'!AR867,'Shuttle Bids'!AR815) -> 270.66667 | CB37: =AVERAGE('Shuttle Bids'!AS763,'Shuttle Bids'!AS867,'Shuttle Bids'!AS815) -> 0 | CC37: =AVERAGE('Shuttle Bids'!AT763,'Shuttle Bids'!AT867,'Shuttle Bids'!AT815) -> 135.33333 | CD37: 50 | CE37: =AVERAGE('Shuttle Bids'!AV770,'Shuttle Bids'!AV874,'Shuttle Bids'!AV822) -> 852.66667 | CF37: =AVERAGE('Shuttle Bids'!AW770,'Shuttle Bids'!AW874,'Shuttle Bids'!AW822) -> 87.333333 | CG37: =AVERAGE('Shuttle Bids'!AX770,'Shuttle Bids'!AX874,'Shuttle Bids'!AX822) -> 470
