Workbook
Name Anlæg: 'Tekst og tabeller 2010'!$A$4:$A$16
Name produktionstype: 'Tekst og tabeller 2010'!$A$62:$A$65
Name Type_elproduktion: 'Tekst og tabeller 2010'!$J$15:$J$16
Name Varmeproduktionsanlæg: 'Tekst og tabeller 2010'!$A$4:$A$16

Sheet Tekst og tabeller 2010
A1: Anlægstyper
D2: CO2 | E2: NOx | F2: SO2 | G2: CH4 | H2: N2O
A3: Anlæg | B3: Enhed | C3: Brændværdi GJ/enhed | D3: kg/ GJ | E3: kg/ GJ | F3: kg/ GJ | G3: kg/ GJ | H3: kg/ GJ
A4: Naturgaskedel | B4: Nm3 | C4: 0.0396 | D4: 56.8 | E4: 0.042 | F4: 0.0003 | G4: 0.006 | H4: 0.001
A5: Oliekedel | B5: m3 | C5: 35.9 | D5: 74 | E5: 0.065 | F5: 0.023 | G5: 0.0015 | H5: 0.002
A6: Biooliekedel | B6: m3 | C6: 34.3 | D6: 0 | E6: 0.142 | F6: 0.344 | G6: 0.003 | H6: 0.002
A7: Fliskedel | B7: GJ | C7: 1 | D7: 0 | E7: 0.09 | F7: 0.025 | G7: 0.032 | H7: 0.004
A8: Halmkedel | B8: ton | C8: 14.5 | D8: 0 | E8: 0.09 | F8: 0.13 | G8: 0.032 | H8: 0.004
A9: Træpillekedel | B9: ton | C9: 17.5 | D9: 0 | E9: 0.12 | F9: 0.025 | G9: 0.2 | H9: 0.004
A10: Affaldskedel | B10: ton | C10: 10.5 | D10: 0 | E10: 0 | F10: 0 | G10: 0 | H10: 0
A11: Naturgaskraftvarme | B11: Nm3 | C11: 0.0396 | D11: 56.8 | E11: 0.135 | F11: 0.0003 | G11: 0.481 | H11: 0.0006
A12: Fliskraftvarme | B12: GJ | C12: 1 | D12: 0 | E12: 0.081 | F12: 0.0019 | G12: 0.0031 | H12: 0.0008
A13: Halmkraftvarme | B13: ton | C13: 14.5 | D13: 0 | E13: 0.125 | F13: 0.049 | G13: 0.0005 | H13: 0.0011
A14: Træpiller kraftvarme | B14: ton | C14: 17.5 | D14: 0 | E14: 0.12 | F14: 0.025 | G14: 0.2 | H14: 0.004
A15: Affaldskraftvarme | B15: ton | C15: 10.5 | D15: 0 | E15: 0 | F15: 0 | G15: 0 | H15: 0
... A19: Træpillefyr | B19: ton | C19: 17.5 | D19: 0 | E19: 0.12 | F19: 0.025 | G19: 0.2 | H19: 0.004
A20: Elvarme | B20: MWh | C20: 3.6 | D20: =+$C$31/3.6 -> 239.44444 | E20: =+$O$31/3.6/1000 -> 0.2025 | F20: =+$L$31/3.6/1000 -> 0.15916667 | G20: =+$F$31/3.6/1000 -> 0.0049722222 | H20: =+$I$31/3.6/1000 -> 0.0021111111
A21: Varmepumpe | B21: MWh | C21: 3.6 | D21: =+$C$31/3.6 -> 239.44444 | E21: =+$O$31/3.6/1000 -> 0.2025 | F21: =+$L$31/3.6/1000 -> 0.15916667 | G21: =+$F$31/3.6/1000 -> 0.0049722222 | H21: =+$I$31/3.6/1000 -> 0.0021111111
A22: Solvarme | B22: MWh | C22: 3.6 | D22: =+$C$31/3.6 -> 239.44444 | E22: =+$O$31/3.6/1000 -> 0.2025 | F22: =+$L$31/3.6/1000 -> 0.15916667 | G22: =+$F$31/3.6/1000 -> 0.0049722222 | H22: =+$I$31/3.6/1000 -> 0.0021111111
A23: Geotermi | B23: MWh | C23: 3.6 | D23: =+$C$31/3.6 -> 239.44444 | E23: =+$O$31/3.6/1000 -> 0.2025 | F23: =+$L$31/3.6/1000 -> 0.15916667 | G23: =+$F$31/3.6/1000 -> 0.0049722222 | H23: =+$I$31/3.6/1000 -> 0.0021111111
A25: Forudsætninger for samfundsøkonomiske analyser på energiområdet april 2010: Tabel 8 Emissionskoefficienter for el og fjernvarme
B27: CO2 | E27: CH4 | H27: N2O | K27: SO2 | N27: NOx
B28: El * | D28: Fjernvarme- | E28: El | G28: Fjernvarme- | H28: El | J28: Fjernvarme- | K28: El | M28: Fjernvarme- | N28: El | P28: Fjernvarme-
B29: kg/MWh | D29: forbrug | E29: g/MWh | G29: forbrug | H29: g/MWh | J29: forbrug | K29: g/MWh | M29: forbrug | N29: g/MWh | P29: forbrug
B30: Nord Pool | C30: Forbruger | D30: kg/GJ | E30: Nord Pool | F30: Forbruger | G30: g/GJ | H30: Nord Pool | I30: Forbruger | J30: g/GJ | K30: Nord Pool | L30: Forbruger | M30: g/GJ | N30: Nord Pool | O30: Forbruger | P30: g/GJ
A31: 2010 | B31: 802 | C31: 862 | D31: 49.1 | E31: 16.7 | F31: 17.9 | G31: 51.3 | H31: 7.1 | I31: 7.6 | J31: 1.7 | K31: 533 | L31: 573 | M31: 91.7 | N31: 678 | O31: 729 | P31: 104.3
A32: 2011 | B32: 791 | C32: 851 | D32: 48.3 | E32: 17.2 | F32: 18.5 | G32: 37.7 | H32: 7.1 | I32: 7.6 | J32: 1.8 | K32: 180 | L32: 193 | M32: 90 | N32: 558 | O32: 600 | P32: 99.7
A33: 2012 | B33: 789 | C33: 848 | D33: 48.2 | E33: 17.9 | F33: 19.3 | G33: 36.5 | H33: 7.1 | I33: 7.6 | J33: 1.8 | K33: 197 | L33: 212 | M33: 85.1 | N33: 560 | O33: 602 | P33: 99.4
A34: 2013 | B34: 792 | C34: 852 | D34: 42 | E34: 17.1 | F34: 18.4 | G34: 30.3 | H34: 7.1 | I34: 7.6 | J34: 1.8 | K34: 194 | L34: 208 | M34: 89.2 | N34: 559 | O34: 601 | P34: 100.8
A35: 2014 | B35: 796 | C35: 856 | D35: 42.7 | E35: 15.3 | F35: 16.4 | G35: 30.2 | H35: 7 | I35: 7.5 | J35: 1.8 | K35: 204 | L35: 219 | M35: 91.3 | N35: 564 | O35: 606 | P35: 102.6
A36: 2015 | B36: 806 | C36: 867 | D36: 42.4 | E36: 15.6 | F36: 16.8 | G36: 29.8 | H36: 7.1 | I36: 7.6 | J36: 1.8 | K36: 221 | L36: 238 | M36: 95 | N36: 577 | O36: 620 | P36: 104.1
A37: 2016 | B37: 800 | C37: 860 | D37: 41.2 | E37: 15.5 | F37: 16.7 | G37: 32.3 | H37: 7 | I37: 7.5 | J37: 1.7 | K37: 179 | L37: 193 | M37: 91.2 | N37: 563 | O37: 605 | P37: 107.1
A38: 2017 | B38: 796 | C38: 855 | D38: 40.8 | E38: 16 | F38: 17.2 | G38: 36 | H38: 7 | I38: 7.6 | J38: 1.7 | K38: 182 | L38: 196 | M38: 88.7 | N38: 566 | O38: 608 | P38: 109.1
A39: 2018 | B39: 792 | C39: 851 | D39: 40.2 | E39: 16.4 | F39: 17.7 | G39: 38.1 | H39: 7.1 | I39: 7.6 | J39: 1.7 | K39: 186 | L39: 200 | M39: 84.2 | N39: 564 | O39: 606 | P39: 109.3
A40: 2019 | B40: 783 | C40: 842 | D40: 40.3 | E40: 16.6 | F40: 17.9 | G40: 39 | H40: 7.1 | I40: 7.6 | J40: 1.7 | K40: 192 | L40: 206 | M40: 83.5 | N40: 569 | O40: 611 | P40: 110.7
A41: 2020 | B41: 784 | C41: 843 | D41: 39.7 | E41: 16.5 | F41: 17.8 | G41: 39.9 | H41: 7.1 | I41: 7.6 | J41: 1.7 | K41: 196 | L41: 211 | M41: 81.9 | N41: 571 | O41: 614 | P41: 111.9
A42: 2021 | B42: 782 | C42: 841 | D42: 39.4 | E42: 16.6 | F42: 17.8 | G42: 38.4 | H42: 7.1 | I42: 7.7 | J42: 1.7 | K42: 211 | L42: 226 | M42: 79.9 | N42: 577 | O42: 620 | P42: 111.1
... A51: 2030 | B51: 771 | C51: 829 | D51: 33.4 | E51: 18 | F51: 19.4 | G51: 37.5 | H51: 7 | I51: 7.6 | J51: 1.7 | K51: 195 | L51: 210 | M51: 68.1 | N51: 498 | O51: 536 | P51: 101.7
A53: Anm: Emissionerne knyttet til el er baseret på den forventede gennemsnitlige danske kondensproduktion.
A54: *) Da der altid regnes med et tillæg til elprisen grundet CO2-kvoter, bør CO2-emissioner fra elproduktion ikke værdisættes separat og indregnes i det samfundsøkonomiske regnestykke.
...

Sheet Indtast brændsler og produktion
A1: Indtastning af brændsler- og produktionsdata for fjernvarmeværket
A3: Kraftvarmeanlæg
A4: Antal anlæg | B4: Anlæg | C4: Type* | D4: Cv-værdi | E4: Brændselsforbrug | F4: Varmeproduktion | G4: Elproduktion | H4: Marginal % | I4: Elvirkningsgrad
D5: ** | E5: pr. enhed | F5: MWh | G5: MWh | H5: ***
A6: 1 | B6: Naturgaskraftvarme | C6: modtryk | E6: 10000 | F6: 53 | G6: 45 | H6: 80 | I6: =+IF(G6="","",G6/(E6*(VLOOKUP('Indtast brændsler og produktion'!B6,'Tekst og tabeller 2010'!$A$4:$H$20,3,FALSE)/3.6))) -> 0.40909091
A7: 2 | I7: =+IF(G7="","",G7/(E7*(VLOOKUP('Indtast brændsler og produktion'!B7,'Tekst og tabeller 2010'!$A$4:$H$20,3,FALSE)/3.6)))
A8: 3 | I8: =+IF(G8="","",G8/(E8*(VLOOKUP('Indtast brændsler og produktion'!B8,'Tekst og tabeller 2010'!$A$4:$H$20,3,FALSE)/3.6)))
A9: 4 | I9: =+IF(G9="","",G9/(E9*(VLOOKUP('Indtast brændsler og produktion'!B9,'Tekst og tabeller 2010'!$A$4:$H$20,3,FALSE)/3.6)))
A10: 5 | I10: =+IF(G10="","",G10/(E10*(VLOOKUP('Indtast brændsler og produktion'!B10,'Tekst og tabeller 2010'!$A$4:$H$20,3,FALSE)/3.6)))
A11: I alt | F11: =SUM(F6:F10) -> 53 | G11: =SUM(G6:G10) -> 45
A12: * Decentrale naturgasfyrede motoranlæg er altid modtryksanlæg. Dampturbiner er normalt udtagsanlæg, men nogle anlæg kører som modtryk.
A13: ** Skal kun indtastes for udtagsanlæg
A14: *** Indtast en vægtning af hvor stor en del af tiden anlægget er marginal over året. Sum af marginaler skal give 100. Indsæt ikke 2 helt ens tal.
A16: Kedelanlæg
A17: Antal anlæg | B17: Anlæg | E17: Brændselsforbrug | F17: Varmeproduktion | H17: Marginal %
E18: pr. enhed | F18: MWh | H18: ***
A19: 1 | B19: Naturgaskedel | E19: 2000 | F19: 20 | H19: 20
A20: 2
A21: 3
A22: 4
A23: 5
A24: I alt | F24: =SUM(F19:F23) -> 20
A26: Andre varmeproduktionsanlæg
A27: Antal anlæg | B27: Anlæg | E27: Elforbrug varme- | F27: Varmeproduktion | H27: Marginal % | I27: COP ****
E28: pumpe **** MWh | F28: MWh | H28: *** | I28: (elforb./varme)
A29: 1 | E29: 326 | F29: 815 | I29: =+IF(E29="","",F29/E29) -> 2.5
A30: 2 | I30: =+IF(E30="","",F30/E30)
A31: 3 | I31: =+IF(E31="","",F31/E31)
A32: 4 | I32: =+IF(E32="","",F32/E32)
F33: =SUM(F29:F32) -> 815
A34: **** Kun relevant for varmepumpeanlæg. Vær opmærksom på at varmeproduktion varmepumpe kan være indeholdt i ovenstående tabeller (kraftvarme/kedel)
A35: =+IF(SUM(H6:H10)+SUM(H19:H23)+SUM(H29:H32)=100,"","FEJL I ANGIVELSE AF MARGINAL % - SUM SKAL VÆRE LIG 100")
A36: Ledningstab % | C36: 0.25

Sheet Emissionsberegninger marginal
A1: Opgørelse af emissioner
A3: Kraftvarmeanlæg
A4: Antal anlæg | B4: Marginal | C4: Anlæg | D4: Type* | E4: Brændselsforbrug | F4: Elproduktion | G4: Emisf. CO2 | H4: CO2 | I4: Emisf. NOx | J4: NOx | K4: Emisf. SO2 | L4: SO2 | M4: Emisf. CH4 | N4: CH4 | O4: Emisf. N2O | P4: N2O
B5: % | E5: lokalt GJ | F5: MWh | G5: kg/GJ | H5: kg | I5: kg/GJ | J5: kg | K5: kg/GJ | L5: kg | M5: kg/GJ | N5: kg | O5: kg/GJ | P5: kg
A6: 1 | B6: =+IF('Indtast brændsler og produktion'!H6="",0,'Indtast brændsler og produktion'!H6) -> 80 | C6: =+IF('Indtast brændsler og produktion'!B6="","",'Indtast brændsler og produktion'!B6) -> Naturgaskraftvarme | D6: =+IF('Indtast brændsler og produktion'!C6="","",'Indtast brændsler og produktion'!C6) -> modtryk | E6: =+IF(C6="","",(VLOOKUP(C6,'Tekst og tabeller 2010'!$A$4:$C$23,3,FALSE)*VLOOKUP(C6,'Indtast brændsler og produktion'!$B$6:$E$10,4,FALSE))) -> 396 | F6: =+IF('Indtast brændsler og produktion'!G6="","",'Indtast brændsler og produktion'!G6) -> 45 | G6: =+IF(C6="","",VLOOKUP(C6,'Tekst og tabeller 2010'!$A$4:$H$23,4,FALSE)) -> 56.8 | H6: =+IF(C6="","",(E6*G6)-(IF(D6="modtryk",F6*'Tekst og tabeller 2010'!$H$71,0))) -> -14357.7 | I6: =+IF(C6="","",VLOOKUP(C6,'Tekst og tabeller 2010'!$A$4:$H$23,5,FALSE)) -> 0.135 | J6: =+IF(C6="","",(E6*I6)-(IF(D6="modtryk",F6*'Tekst og tabeller 2010'!$I$71,0))) -> 22.29525 | K6: =+IF(C6="","",VLOOKUP(C6,'Tekst og tabeller 2010'!$A$4:$H$23,6,FALSE)) -> 0.0003 | L6: =+IF(C6="","",(E6*K6)-(IF(D6="modtryk",F6*'Tekst og tabeller 2010'!$J$71,0))) -> -24.37695 | M6: =+IF(C6="","",VLOOKUP(C6,'Tekst og tabeller 2010'!$A$4:$H$23,7,FALSE)) -> 0.481 | N6: =+IF(C6="","",(E6*M6)-(IF(D6="modtryk",F6*'Tekst og tabeller 2010'!$K$71,0))) -> 189.71078 | O6: =+IF(C6="","",VLOOKUP(C6,'Tekst og tabeller 2010'!$A$4:$H$23,8,FALSE)) -> 0.0006 | P6: =+IF(C6="","",(E6*O6)-(IF(D6="modtryk",F6*'Tekst og tabeller 2010'!$L$71,0))) -> -0.0873
A7: 2 | B7: =+IF('Indtast brændsler og produktion'!H7="",0,'Indtast brændsler og produktion'!H7) -> 0 | C7: =+IF('Indtast brændsler og produktion'!B7="","",'Indtast brændsler og produktion'!B7) | D7: =+IF('Indtast brændsler og produktion'!C7="","",'Indtast brændsler og produktion'!C7) | E7: =+IF(C7="","",(VLOOKUP(C7,'Tekst og tabeller 2010'!$A$4:$C$23,3,FALSE)*VLOOKUP(C7,'Indtast brændsler og produktion'!$B$6:$E$10,4,FALSE))) | F7: =+IF('Indtast brændsler og produktion'!G7="","",'Indtast brændsler og produktion'!G7) | G7: =+IF(C7="","",VLOOKUP(C7,'Tekst og tabeller 2010'!$A$4:$H$23,4,FALSE)) | H7: =+IF(C7="","",(E7*G7)-(IF(D7="modtryk",F7*'Tekst og tabeller 2010'!$H$71,0))) | I7: =+IF(C7="","",VLOOKUP(C7,'Tekst og tabeller 2010'!$A$4:$H$23,5,FALSE)) | J7: =+IF(C7="","",(E7*I7)-(IF(D7="modtryk",F7*'Tekst og tabeller 2010'!$I$71,0))) | K7: =+IF(C7="","",VLOOKUP(C7,'Tekst og tabeller 2010'!$A$4:$H$23,6,FALSE)) | L7: =+IF(C7="","",(E7*K7)-(IF(D7="modtryk",F7*'Tekst og tabeller 2010'!$J$71,0))) | M7: =+IF(C7="","",VLOOKUP(C7,'Tekst og tabeller 2010'!$A$4:$H$23,7,FALSE)) | N7: =+IF(C7="","",(E7*M7)-(IF(D7="modtryk",F7*'Tekst og tabeller 2010'!$K$71,0))) | O7: =+IF(C7="","",VLOOKUP(C7,'Tekst og tabeller 2010'!$A$4:$H$23,8,FALSE)) | P7: =+IF(C7="","",(E7*O7)-(IF(D7="modtryk",F7*'Tekst og tabeller 2010'!$L$71,0)))
A8: 3 | B8: =+IF('Indtast brændsler og produktion'!H8="",0,'Indtast brændsler og produktion'!H8) -> 0 | C8: =+IF('Indtast brændsler og produktion'!B8="","",'Indtast brændsler og produktion'!B8) | D8: =+IF('Indtast brændsler og produktion'!C8="","",'Indtast brændsler og produktion'!C8) | E8: =+IF(C8="","",(VLOOKUP(C8,'Tekst og tabeller 2010'!$A$4:$C$23,3,FALSE)*VLOOKUP(C8,'Indtast brændsler og produktion'!$B$6:$E$10,4,FALSE))) | F8: =+IF('Indtast brændsler og produktion'!G8="","",'Indtast brændsler og produktion'!G8) | G8: =+IF(C8="","",VLOOKUP(C8,'Tekst og tabeller 2010'!$A$4:$H$23,4,FALSE)) | H8: =+IF(C8="","",(E8*G8)-(IF(D8="modtryk",F8*'Tekst og tabeller 2010'!$H$71,0))) | I8: =+IF(C8="","",VLOOKUP(C8,'Tekst og tabeller 2010'!$A$4:$H$23,5,FALSE)) | J8: =+IF(C8="","",(E8*I8)-(IF(D8="modtryk",F8*'Tekst og tabeller 2010'!$I$71,0))) | K8: =+IF(C8="","",VLOOKUP(C8,'Tekst og tabeller 2010'!$A$4:$H$23,6,FALSE)) | L8: =+IF(C8="","",(E8*K8)-(IF(D8="modtryk",F8*'Tekst og tabeller 2010'!$J$71,0))) | M8: =+IF(C8="","",VLOOKUP(C8,'Tekst og tabeller 2010'!$A$4:$H$23,7,FALSE)) | N8: =+IF(C8="","",(E8*M8)-(IF(D8="modtryk",F8*'Tekst og tabeller 2010'!$K$71,0))) | O8: =+IF(C8="","",VLOOKUP(C8,'Tekst og tabeller 2010'!$A$4:$H$23,8,FALSE)) | P8: =+IF(C8="","",(E8*O8)-(IF(D8="modtryk",F8*'Tekst og tabeller 2010'!$L$71,0)))
A9: 4 | B9: =+IF('Indtast brændsler og produktion'!H9="",0,'Indtast brændsler og produktion'!H9) -> 0 | C9: =+IF('Indtast brændsler og produktion'!B9="","",'Indtast brændsler og produktion'!B9) | D9: =+IF('Indtast brændsler og produktion'!C9="","",'Indtast brændsler og produktion'!C9) | E9: =+IF(C9="","",(VLOOKUP(C9,'Tekst og tabeller 2010'!$A$4:$C$23,3,FALSE)*VLOOKUP(C9,'Indtast brændsler og produktion'!$B$6:$E$10,4,FALSE))) | F9: =+IF('Indtast brændsler og produktion'!G9="","",'Indtast brændsler og produktion'!G9) | G9: =+IF(C9="","",VLOOKUP(C9,'Tekst og tabeller 2010'!$A$4:$H$23,4,FALSE)) | H9: =+IF(C9="","",(E9*G9)-(IF(D9="modtryk",F9*'Tekst og tabeller 2010'!$H$71,0))) | I9: =+IF(C9="","",VLOOKUP(C9,'Tekst og tabeller 2010'!$A$4:$H$23,5,FALSE)) | J9: =+IF(C9="","",(E9*I9)-(IF(D9="modtryk",F9*'Tekst og tabeller 2010'!$I$71,0))) | K9: =+IF(C9="","",VLOOKUP(C9,'Tekst og tabeller 2010'!$A$4:$H$23,6,FALSE)) | L9: =+IF(C9="","",(E9*K9)-(IF(D9="modtryk",F9*'Tekst og tabeller 2010'!$J$71,0))) | M9: =+IF(C9="","",VLOOKUP(C9,'Tekst og tabeller 2010'!$A$4:$H$23,7,FALSE)) | N9: =+IF(C9="","",(E9*M9)-(IF(D9="modtryk",F9*'Tekst og tabeller 2010'!$K$71,0))) | O9: =+IF(C9="","",VLOOKUP(C9,'Tekst og tabeller 2010'!$A$4:$H$23,8,FALSE)) | P9: =+IF(C9="","",(E9*O9)-(IF(D9="modtryk",F9*'Tekst og tabeller 2010'!$L$71,0)))
A10: 5 | B10: =+IF('Indtast brændsler og produktion'!H10="",0,'Indtast brændsler og produktion'!H10) -> 0 | C10: =+IF('Indtast brændsler og produktion'!B10="","",'Indtast brændsler og produktion'!B10) | D10: =+IF('Indtast brændsler og produktion'!C10="","",'Indtast brændsler og produktion'!C10) | E10: =+IF(C10="","",(VLOOKUP(C10,'Tekst og tabeller 2010'!$A$4:$C$23,3,FALSE)*VLOOKUP(C10,'Indtast brændsler og produktion'!$B$6:$E$10,4,FALSE))) | F10: =+IF('Indtast brændsler og produktion'!G10="","",'Indtast brændsler og produktion'!G10) | G10: =+IF(C10="","",VLOOKUP(C10,'Tekst og tabeller 2010'!$A$4:$H$23,4,FALSE)) | H10: =+IF(C10="","",(E10*G10)-(IF(D10="modtryk",F10*'Tekst og tabeller 2010'!$H$71,0))) | I10: =+IF(C10="","",VLOOKUP(C10,'Tekst og tabeller 2010'!$A$4:$H$23,5,FALSE)) | J10: =+IF(C10="","",(E10*I10)-(IF(D10="modtryk",F10*'Tekst og tabeller 2010'!$I$71,0))) | K10: =+IF(C10="","",VLOOKUP(C10,'Tekst og tabeller 2010'!$A$4:$H$23,6,FALSE)) | L10: =+IF(C10="","",(E10*K10)-(IF(D10="modtryk",F10*'Tekst og tabeller 2010'!$J$71,0))) | M10: =+IF(C10="","",VLOOKUP(C10,'Tekst og tabeller 2010'!$A$4:$H$23,7,FALSE)) | N10: =+IF(C10="","",(E10*M10)-(IF(D10="modtryk",F10*'Tekst og tabeller 2010'!$K$71,0))) | O10: =+IF(C10="","",VLOOKUP(C10,'Tekst og tabeller 2010'!$A$4:$H$23,8,FALSE)) | P10: =+IF(C10="","",(E10*O10)-(IF(D10="modtryk",F10*'Tekst og tabeller 2010'!$L$71,0)))
A11: I alt | E11: =SUM(E6:E10) -> 396 | F11: =SUM(F6:F10) -> 45 | H11: =SUM(H6:H10) -> -14357.7 | J11: =SUM(J6:J10) -> 22.29525 | L11: =SUM(L6:L10) -> -24.37695 | N11: =SUM(N6:N10) -> 189.71078 | P11: =SUM(P6:P10) -> -0.0873
A13: Kedelanlæg
A14: Antal anlæg | B14: Marginal | C14: Anlæg | E14: Brændselsforbrug | G14: Emisf. CO2 | H14: CO2 | I14: Emisf. NOx | J14: NOx | K14: Emisf. SO2 | L14: SO2 | M14: Emisf. CH4 | N14: CH4 | O14: Emisf. N2O | P14: N2O
B15: % | E15: lokalt GJ | G15: kg/GJ | H15: kg | I15: kg/GJ | J15: kg | K15: kg/GJ | L15: kg | M15: kg/GJ | N15: kg | O15: kg/GJ | P15: kg
A16: 1 | B16: =+IF('Indtast brændsler og produktion'!H19="",0,'Indtast brændsler og produktion'!H19) -> 20 | C16: =+IF('Indtast brændsler og produktion'!B19="","",'Indtast brændsler og produktion'!B19) -> Naturgaskedel | D16: =+IF('Indtast brændsler og produktion'!C19="","",'Indtast brændsler og produktion'!C19) | E16: =+IF(C16="","",(VLOOKUP(C16,'Tekst og tabeller 2010'!$A$4:$C$23,3,FALSE)*VLOOKUP(C16,'Indtast brændsler og produktion'!$B$19:$E$23,4,FALSE))) -> 79.2 | G16: =+IF(C16="","",VLOOKUP(C16,'Tekst og tabeller 2010'!$A$4:$H$23,4,FALSE)) -> 56.8 | H16: =+IF(C16="","",E16*G16) -> 4498.56 | I16: =+IF(C16="","",VLOOKUP(C16,'Tekst og tabeller 2010'!$A$4:$H$23,5,FALSE)) -> 0.042 | J16: =+IF(C16="","",E16*I16) -> 3.3264 | K16: =+IF(C16="","",VLOOKUP(C16,'Tekst og tabeller 2010'!$A$4:$H$23,6,FALSE)) -> 0.0003 | L16: =+IF(C16="","",E16*K16) -> 0.02376 | M16: =+IF(C16="","",VLOOKUP(C16,'Tekst og tabeller 2010'!$A$4:$H$23,7,FALSE)) -> 0.006 | N16: =+IF(C16="","",E16*M16) -> 0.4752 | O16: =+IF(C16="","",VLOOKUP(C16,'Tekst og tabeller 2010'!$A$4:$H$23,8,FALSE)) -> 0.001 | P16: =+IF(C16="","",E16*O16) -> 0.0792
A17: 2 | B17: =+IF('Indtast brændsler og produktion'!H20="",0,'Indtast brændsler og produktion'!H20) -> 0 | C17: =+IF('Indtast brændsler og produktion'!B20="","",'Indtast brændsler og produktion'!B20) | D17: =+IF('Indtast brændsler og produktion'!C20="","",'Indtast brændsler og produktion'!C20) | E17: =+IF(C17="","",(VLOOKUP(C17,'Tekst og tabeller 2010'!$A$4:$C$23,3,FALSE)*VLOOKUP(C17,'Indtast brændsler og produktion'!$B$19:$E$23,4,FALSE))) | G17: =+IF(C17="","",VLOOKUP(C17,'Tekst og tabeller 2010'!$A$4:$H$23,4,FALSE)) | H17: =+IF(C17="","",E17*G17) | I17: =+IF(C17="","",VLOOKUP(C17,'Tekst og tabeller 2010'!$A$4:$H$23,5,FALSE)) | J17: =+IF(C17="","",E17*I17) | K17: =+IF(C17="","",VLOOKUP(C17,'Tekst og tabeller 2010'!$A$4:$H$23,6,FALSE)) | L17: =+IF(C17="","",E17*K17) | M17: =+IF(C17="","",VLOOKUP(C17,'Tekst og tabeller 2010'!$A$4:$H$23,7,FALSE)) | N17: =+IF(C17="","",E17*M17) | O17: =+IF(C17="","",VLOOKUP(C17,'Tekst og tabeller 2010'!$A$4:$H$23,8,FALSE)) | P17: =+IF(C17="","",E17*O17)
A18: 3 | B18: =+IF('Indtast brændsler og produktion'!H21="",0,'Indtast brændsler og produktion'!H21) -> 0 | C18: =+IF('Indtast brændsler og produktion'!B21="","",'Indtast brændsler og produktion'!B21) | D18: =+IF('Indtast brændsler og produktion'!C21="","",'Indtast brændsler og produktion'!C21) | E18: =+IF(C18="","",(VLOOKUP(C18,'Tekst og tabeller 2010'!$A$4:$C$23,3,FALSE)*VLOOKUP(C18,'Indtast brændsler og produktion'!$B$19:$E$23,4,FALSE))) | G18: =+IF(C18="","",VLOOKUP(C18,'Tekst og tabeller 2010'!$A$4:$H$23,4,FALSE)) | H18: =+IF(C18="","",E18*G18) | I18: =+IF(C18="","",VLOOKUP(C18,'Tekst og tabeller 2010'!$A$4:$H$23,5,FALSE)) | J18: =+IF(C18="","",E18*I18) | K18: =+IF(C18="","",VLOOKUP(C18,'Tekst og tabeller 2010'!$A$4:$H$23,6,FALSE)) | L18: =+IF(C18="","",E18*K18) | M18: =+IF(C18="","",VLOOKUP(C18,'Tekst og tabeller 2010'!$A$4:$H$23,7,FALSE)) | N18: =+IF(C18="","",E18*M18) | O18: =+IF(C18="","",VLOOKUP(C18,'Tekst og tabeller 2010'!$A$4:$H$23,8,FALSE)) | P18: =+IF(C18="","",E18*O18)
A19: 4 | B19: =+IF('Indtast brændsler og produktion'!H22="",0,'Indtast brændsler og produktion'!H22) -> 0 | C19: =+IF('Indtast brændsler og produktion'!B22="","",'Indtast brændsler og produktion'!B22) | D19: =+IF('Indtast brændsler og produktion'!C22="","",'Indtast brændsler og produktion'!C22) | E19: =+IF(C19="","",(VLOOKUP(C19,'Tekst og tabeller 2010'!$A$4:$C$23,3,FALSE)*VLOOKUP(C19,'Indtast brændsler og produktion'!$B$19:$E$23,4,FALSE))) | G19: =+IF(C19="","",VLOOKUP(C19,'Tekst og tabeller 2010'!$A$4:$H$23,4,FALSE)) | H19: =+IF(C19="","",E19*G19) | I19: =+IF(C19="","",VLOOKUP(C19,'Tekst og tabeller 2010'!$A$4:$H$23,5,FALSE)) | J19: =+IF(C19="","",E19*I19) | K19: =+IF(C19="","",VLOOKUP(C19,'Tekst og tabeller 2010'!$A$4:$H$23,6,FALSE)) | L19: =+IF(C19="","",E19*K19) | M19: =+IF(C19="","",VLOOKUP(C19,'Tekst og tabeller 2010'!$A$4:$H$23,7,FALSE)) | N19: =+IF(C19="","",E19*M19) | O19: =+IF(C19="","",VLOOKUP(C19,'Tekst og tabeller 2010'!$A$4:$H$23,8,FALSE)) | P19: =+IF(C19="","",E19*O19)
A20: 5 | B20: =+IF('Indtast brændsler og produktion'!H23="",0,'Indtast brændsler og produktion'!H23) -> 0 | C20: =+IF('Indtast brændsler og produktion'!B23="","",'Indtast brændsler og produktion'!B23) | D20: =+IF('Indtast brændsler og produktion'!C23="","",'Indtast brændsler og produktion'!C23) | E20: =+IF(C20="","",(VLOOKUP(C20,'Tekst og tabeller 2010'!$A$4:$C$23,3,FALSE)*VLOOKUP(C20,'Indtast brændsler og produktion'!$B$19:$E$23,4,FALSE))) | G20: =+IF(C20="","",VLOOKUP(C20,'Tekst og tabeller 2010'!$A$4:$H$23,4,FALSE)) | H20: =+IF(C20="","",E20*G20) | I20: =+IF(C20="","",VLOOKUP(C20,'Tekst og tabeller 2010'!$A$4:$H$23,5,FALSE)) | J20: =+IF(C20="","",E20*I20) | K20: =+IF(C20="","",VLOOKUP(C20,'Tekst og tabeller 2010'!$A$4:$H$23,6,FALSE)) | L20: =+IF(C20="","",E20*K20) | M20: =+IF(C20="","",VLOOKUP(C20,'Tekst og tabeller 2010'!$A$4:$H$23,7,FALSE)) | N20: =+IF(C20="","",E20*M20) | O20: =+IF(C20="","",VLOOKUP(C20,'Tekst og tabeller 2010'!$A$4:$H$23,8,FALSE)) | P20: =+IF(C20="","",E20*O20)
A21: I alt | E21: =SUM(E16:E20) -> 79.2 | H21: =SUM(H16:H20) -> 4498.56 | J21: =SUM(J16:J20) -> 3.3264 | L21: =SUM(L16:L20) -> 0.02376 | N21: =SUM(N16:N20) -> 0.4752 | P21: =SUM(P16:P20) -> 0.0792
A23: Andre varmeproduktionsanlæg
A24: Antal anlæg | B24: Marginal | C24: Anlæg | E24: Brændselsforbrug | G24: Emisf. CO2 | H24: CO2 | I24: Emisf. NOx | J24: NOx | K24: Emisf. SO2 | L24: SO2 | M24: Emisf. CH4 | N24: CH4 | O24: Emisf. N2O | P24: N2O
B25: % | E25: lokalt GJ | G25: kg/GJ | H25: kg | I25: kg/GJ | J25: kg | K25: kg/GJ | L25: kg | M25: kg/GJ | N25: kg | O25: kg/GJ | P25: kg
A26: 1 | B26: =+IF('Indtast brændsler og produktion'!H29="",0,'Indtast brændsler og produktion'!H29) -> 0 | C26: =+IF('Indtast brændsler og produktion'!B29="","",'Indtast brændsler og produktion'!B29) | E26: =+IF(C26="","",(VLOOKUP(C26,'Tekst og tabeller 2010'!$A$4:$C$23,3,FALSE)*VLOOKUP(C26,'Indtast brændsler og produktion'!B29:E32,4,FALSE))) | G26: =+IF(C26="","",VLOOKUP(C26,'Tekst og tabeller 2010'!$A$4:$H$23,4,FALSE)) | H26: =+IF(C26="","",E26*G26) | I26: =+IF(C26="","",VLOOKUP(C26,'Tekst og tabeller 2010'!$A$4:$H$23,5,FALSE)) | J26: =+IF(C26="","",E26*I26) | K26: =+IF(C26="","",VLOOKUP(C26,'Tekst og tabeller 2010'!$A$4:$H$23,6,FALSE)) | L26: =+IF(C26="","",E26*K26) | M26: =+IF(C26="","",VLOOKUP(C26,'Tekst og tabeller 2010'!$A$4:$H$23,7,FALSE)) | N26: =+IF(C26="","",E26*M26) | O26: =+IF(C26="","",VLOOKUP(C26,'Tekst og tabeller 2010'!$A$4:$H$23,8,FALSE)) | P26: =+IF(C26="","",E26*O26)
A27: 2 | B27: =+IF('Indtast brændsler og produktion'!H30="",0,'Indtast brændsler og produktion'!H30) -> 0 | C27: =+IF('Indtast brændsler og produktion'!B30="","",'Indtast brændsler og produktion'!B30) | E27: =+IF(C27="","",(VLOOKUP(C27,'Tekst og tabeller 2010'!$A$4:$C$23,3,FALSE)*VLOOKUP(C27,'Indtast brændsler og produktion'!B30:E33,4,FALSE))) | G27: =+IF(C27="","",VLOOKUP(C27,'Tekst og tabeller 2010'!$A$4:$H$23,4,FALSE)) | H27: =+IF(C27="","",E27*G27) | I27: =+IF(C27="","",VLOOKUP(C27,'Tekst og tabeller 2010'!$A$4:$H$23,5,FALSE)) | J27: =+IF(C27="","",E27*I27) | K27: =+IF(C27="","",VLOOKUP(C27,'Tekst og tabeller 2010'!$A$4:$H$23,6,FALSE)) | L27: =+IF(C27="","",E27*K27) | M27: =+IF(C27="","",VLOOKUP(C27,'Tekst og tabeller 2010'!$A$4:$H$23,7,FALSE)) | N27: =+IF(C27="","",E27*M27) | O27: =+IF(C27="","",VLOOKUP(C27,'Tekst og tabeller 2010'!$A$4:$H$23,8,FALSE)) | P27: =+IF(C27="","",E27*O27)
A28: 3 | B28: =+IF('Indtast brændsler og produktion'!H31="",0,'Indtast brændsler og produktion'!H31) -> 0 | C28: =+IF('Indtast brændsler og produktion'!B31="","",'Indtast brændsler og produktion'!B31) | E28: =+IF(C28="","",(VLOOKUP(C28,'Tekst og tabeller 2010'!$A$4:$C$23,3,FALSE)*VLOOKUP(C28,'Indtast brændsler og produktion'!B31:E34,4,FALSE))) | G28: =+IF(C28="","",VLOOKUP(C28,'Tekst og tabeller 2010'!$A$4:$H$23,4,FALSE)) | H28: =+IF(C28="","",E28*G28) | I28: =+IF(C28="","",VLOOKUP(C28,'Tekst og tabeller 2010'!$A$4:$H$23,5,FALSE)) | J28: =+IF(C28="","",E28*I28) | K28: =+IF(C28="","",VLOOKUP(C28,'Tekst og tabeller 2010'!$A$4:$H$23,6,FALSE)) | L28: =+IF(C28="","",E28*K28) | M28: =+IF(C28="","",VLOOKUP(C28,'Tekst og tabeller 2010'!$A$4:$H$23,7,FALSE)) | N28: =+IF(C28="","",E28*M28) | O28: =+IF(C28="","",VLOOKUP(C28,'Tekst og tabeller 2010'!$A$4:$H$23,8,FALSE)) | P28: =+IF(C28="","",E28*O28)
A29: 4 | B29: =+IF('Indtast brændsler og produktion'!H32="",0,'Indtast brændsler og produktion'!H32) -> 0 | C29: =+IF('Indtast brændsler og produktion'!B32="","",'Indtast brændsler og produktion'!B32) | E29: =+IF(C29="","",(VLOOKUP(C29,'Tekst og tabeller 2010'!$A$4:$C$23,3,FALSE)*VLOOKUP(C29,'Indtast brændsler og produktion'!B32:E35,4,FALSE))) | G29: =+IF(C29="","",VLOOKUP(C29,'Tekst og tabeller 2010'!$A$4:$H$23,4,FALSE)) | H29: =+IF(C29="","",E29*G29) | I29: =+IF(C29="","",VLOOKUP(C29,'Tekst og tabeller 2010'!$A$4:$H$23,5,FALSE)) | J29: =+IF(C29="","",E29*I29) | K29: =+IF(C29="","",VLOOKUP(C29,'Tekst og tabeller 2010'!$A$4:$H$23,6,FALSE)) | L29: =+IF(C29="","",E29*K29) | M29: =+IF(C29="","",VLOOKUP(C29,'Tekst og tabeller 2010'!$A$4:$H$23,7,FALSE)) | N29: =+IF(C29="","",E29*M29) | O29: =+IF(C29="","",VLOOKUP(C29,'Tekst og tabeller 2010'!$A$4:$H$23,8,FALSE)) | P29: =+IF(C29="","",E29*O29)
A30: I alt | E30: =SUM(E26:E29) -> 0 | H30: =SUM(H26:H29) -> 0 | J30: =SUM(J26:J29) -> 0 | L30: =SUM(L26:L29) -> 0 | N30: =SUM(N26:N29) -> 0 | P30: =SUM(P26:P29) -> 0
B33: Marginal | C33: Anlæg | D33: Varme | E33: CO2 | F33: NOx | G33: SO2 | H33: CH4 | I33: N2O
B34: % | D34: MWh | E34: kg/MWh | F34: kg/MWh | G34: kg/MWh | H34: kg/MWh | I34: kg/MWh
B35: =+LARGE('Emissionsberegninger marginal'!$B$6:$B$29,1) -> 80 | C35: =+IF(B35=0,"",VLOOKUP(B35,'Emissionsberegninger marginal'!$B$6:$P$29,2,FALSE)) -> Naturgaskraftvarme | D35: =+IF(C35="","",VLOOKUP(C35,'Indtast brændsler og produktion'!$B$6:$F$32,5,FALSE)) -> 53 | E35: =+IF(C35="","",VLOOKUP(C35,'Emissionsberegninger marginal'!$C$6:$P$29,6,FALSE)/D35*B35/100) -> -216.72 | F35: =+IF(C35="","",VLOOKUP(C35,'Emissionsberegninger marginal'!$C$6:$P$29,8,FALSE)/D35*B35/100) -> 0.33653208 | G35: =+IF(C35="","",VLOOKUP(C35,'Emissionsberegninger marginal'!$C$6:$P$29,10,FALSE)/D35*B35/100) -> -0.36795396 | H35: =+IF(D35="","",VLOOKUP(C35,'Emissionsberegninger marginal'!$C$6:$P$29,12,FALSE)/D35*B35/100) -> 2.8635589 | I35: =+IF(D35="","",VLOOKUP(C35,'Emissionsberegninger marginal'!$C$6:$P$29,14,FALSE)/D35*B35/100) -> -0.0013177358
B36: =+LARGE('Emissionsberegninger marginal'!$B$6:$B$29,2) -> 20 | C36: =+IF(B36=0,"",VLOOKUP(B36,'Emissionsberegninger marginal'!$B$6:$P$29,2,FALSE)) -> Naturgaskedel | D36: =+IF(C36="","",VLOOKUP(C36,'Indtast brændsler og produktion'!$B$6:$F$32,5,FALSE)) -> 20 | E36: =+IF(C36="","",VLOOKUP(C36,'Emissionsberegninger marginal'!$C$6:$P$29,6,FALSE)/D36*B36/100) -> 44.9856 | F36: =+IF(C36="","",VLOOKUP(C36,'Emissionsberegninger marginal'!$C$6:$P$29,8,FALSE)/D36*B36/100) -> 0.033264 | G36: =+IF(C36="","",VLOOKUP(C36,'Emissionsberegninger marginal'!$C$6:$P$29,10,FALSE)/D36*B36/100) -> 0.0002376 | H36: =+IF(D36="","",VLOOKUP(C36,'Emissionsberegninger marginal'!$C$6:$P$29,12,FALSE)/D36*B36/100) -> 0.004752 | I36: =+IF(D36="","",VLOOKUP(C36,'Emissionsberegninger marginal'!$C$6:$P$29,14,FALSE)/D36*B36/100) -> 0.000792
B37: =+LARGE('Emissionsberegninger marginal'!$B$6:$B$29,3) -> 0 | C37: =+IF(B37=0,"",VLOOKUP(B37,'Emissionsberegninger marginal'!$B$6:$P$29,2,FALSE)) | D37: =+IF(C37="","",VLOOKUP(C37,'Indtast brændsler og produktion'!$B$6:$F$32,5,FALSE)) | E37: =+IF(C37="","",VLOOKUP(C37,'Emissionsberegninger marginal'!$C$6:$P$29,6,FALSE)/D37*B37/100) | F37: =+IF(C37="","",VLOOKUP(C37,'Emissionsberegninger marginal'!$C$6:$P$29,8,FALSE)/D37*B37/100) | G37: =+IF(C37="","",VLOOKUP(C37,'Emissionsberegninger marginal'!$C$6:$P$29,10,FALSE)/D37*B37/100) | H37: =+IF(D37="","",VLOOKUP(C37,'Emissionsberegninger marginal'!$C$6:$P$29,12,FALSE)/D37*B37/100) | I37: =+IF(D37="","",VLOOKUP(C37,'Emissionsberegninger marginal'!$C$6:$P$29,14,FALSE)/D37*B37/100)
B38: =+LARGE('Emissionsberegninger marginal'!$B$6:$B$29,4) -> 0 | C38: =+IF(B38=0,"",VLOOKUP(B38,'Emissionsberegninger marginal'!$B$6:$P$29,2,FALSE)) | D38: =+IF(C38="","",VLOOKUP(C38,'Indtast brændsler og produktion'!$B$6:$F$32,5,FALSE)) | E38: =+IF(C38="","",VLOOKUP(C38,'Emissionsberegninger marginal'!$C$6:$P$29,6,FALSE)/D38*B38/100) | F38: =+IF(C38="","",VLOOKUP(C38,'Emissionsberegninger marginal'!$C$6:$P$29,8,FALSE)/D38*B38/100) | G38: =+IF(C38="","",VLOOKUP(C38,'Emissionsberegninger marginal'!$C$6:$P$29,10,FALSE)/D38*B38/100) | H38: =+IF(D38="","",VLOOKUP(C38,'Emissionsberegninger marginal'!$C$6:$P$29,12,FALSE)/D38*B38/100) | I38: =+IF(D38="","",VLOOKUP(C38,'Emissionsberegninger marginal'!$C$6:$P$29,14,FALSE)/D38*B38/100)
B39: =+LARGE('Emissionsberegninger marginal'!$B$6:$B$29,5) -> 0 | C39: =+IF(B39=0,"",VLOOKUP(B39,'Emissionsberegninger marginal'!$B$6:$P$29,2,FALSE)) | D39: =+IF(C39="","",VLOOKUP(C39,'Indtast brændsler og produktion'!$B$6:$F$32,5,FALSE)) | E39: =+IF(C39="","",VLOOKUP(C39,'Emissionsberegninger marginal'!$C$6:$P$29,6,FALSE)/D39*B39/100) | F39: =+IF(C39="","",VLOOKUP(C39,'Emissionsberegninger marginal'!$C$6:$P$29,8,FALSE)/D39*B39/100) | G39: =+IF(C39="","",VLOOKUP(C39,'Emissionsberegninger marginal'!$C$6:$P$29,10,FALSE)/D39*B39/100) | H39: =+IF(D39="","",VLOOKUP(C39,'Emissionsberegninger marginal'!$C$6:$P$29,12,FALSE)/D39*B39/100) | I39: =+IF(D39="","",VLOOKUP(C39,'Emissionsberegninger marginal'!$C$6:$P$29,14,FALSE)/D39*B39/100)
B40: =+LARGE('Emissionsberegninger marginal'!$B$6:$B$29,6) -> 0 | C40: =+IF(B40=0,"",VLOOKUP(B40,'Emissionsberegninger marginal'!$B$6:$P$29,2,FALSE)) | D40: =+IF(C40="","",VLOOKUP(C40,'Indtast brændsler og produktion'!$B$6:$F$32,5,FALSE)) | E40: =+IF(C40="","",VLOOKUP(C40,'Emissionsberegninger marginal'!$C$6:$P$29,6,FALSE)/D40*B40/100) | F40: =+IF(C40="","",VLOOKUP(C40,'Emissionsberegninger marginal'!$C$6:$P$29,8,FALSE)/D40*B40/100) | G40: =+IF(C40="","",VLOOKUP(C40,'Emissionsberegninger marginal'!$C$6:$P$29,10,FALSE)/D40*B40/100) | H40: =+IF(D40="","",VLOOKUP(C40,'Emissionsberegninger marginal'!$C$6:$P$29,12,FALSE)/D40*B40/100) | I40: =+IF(D40="","",VLOOKUP(C40,'Emissionsberegninger marginal'!$C$6:$P$29,14,FALSE)/D40*B40/100)
B41: =+LARGE('Emissionsberegninger marginal'!$B$6:$B$29,7) -> 0 | C41: =+IF(B41=0,"",VLOOKUP(B41,'Emissionsberegninger marginal'!$B$6:$P$29,2,FALSE)) | D41: =+IF(C41="","",VLOOKUP(C41,'Indtast brændsler og produktion'!$B$6:$F$32,5,FALSE)) | E41: =+IF(C41="","",VLOOKUP(C41,'Emissionsberegninger marginal'!$C$6:$P$29,6,FALSE)/D41*B41/100) | F41: =+IF(C41="","",VLOOKUP(C41,'Emissionsberegninger marginal'!$C$6:$P$29,8,FALSE)/D41*B41/100) | G41: =+IF(C41="","",VLOOKUP(C41,'Emissionsberegninger marginal'!$C$6:$P$29,10,FALSE)/D41*B41/100) | H41: =+IF(D41="","",VLOOKUP(C41,'Emissionsberegninger marginal'!$C$6:$P$29,12,FALSE)/D41*B41/100) | I41: =+IF(D41="","",VLOOKUP(C41,'Emissionsberegninger marginal'!$C$6:$P$29,14,FALSE)/D41*B41/100)
B42: =+LARGE('Emissionsberegninger marginal'!$B$6:$B$29,8) -> 0 | C42: =+IF(B42=0,"",VLOOKUP(B42,'Emissionsberegninger marginal'!$B$6:$P$29,2,FALSE)) | D42: =+IF(C42="","",VLOOKUP(C42,'Indtast brændsler og produktion'!$B$6:$F$32,5,FALSE)) | E42: =+IF(C42="","",VLOOKUP(C42,'Emissionsberegninger marginal'!$C$6:$P$29,6,FALSE)/D42*B42/100) | F42: =+IF(C42="","",VLOOKUP(C42,'Emissionsberegninger marginal'!$C$6:$P$29,8,FALSE)/D42*B42/100) | G42: =+IF(C42="","",VLOOKUP(C42,'Emissionsberegninger marginal'!$C$6:$P$29,10,FALSE)/D42*B42/100) | H42: =+IF(D42="","",VLOOKUP(C42,'Emissionsberegninger marginal'!$C$6:$P$29,12,FALSE)/D42*B42/100) | I42: =+IF(D42="","",VLOOKUP(C42,'Emissionsberegninger marginal'!$C$6:$P$29,14,FALSE)/D42*B42/100)
B43: Samlet marginal | E43: =SUM(E35:E42) -> -171.7344 | F43: =SUM(F35:F42) -> 0.36979608 | G43: =SUM(G35:G42) -> -0.36771636 | H43: =SUM(H35:H42) -> 2.8683109 | I43: =SUM(I35:I42) -> -0.00052573585

Sheet Marginal miljøeffekt
A1: Miljøeffekt ved ændring i varmeforbrug
A3: "Fjordbykøbing fjernvarmeværk"
A5: ="Ved at spare 1MWh varme i"&A3&"opnås følgende miljøeffekter :" -> Ved at spare 1MWh varme i"Fjordbykøbing fjernvarmeværk"opnås følgende miljøeffekter :
A7: Parameter | B7: Besparelse* | C7: enhed
A9: Kuldioxid CO2 | B9: =+'Emissionsberegninger marginal'!E43 -> -171.7344 | C9: =+'Emissionsberegninger marginal'!E34 -> kg/MWh
A11: Kvælstofoxider NOx | B11: =+'Emissionsberegninger marginal'!F43 -> 0.36979608 | C11: =+'Emissionsberegninger marginal'!F34 -> kg/MWh
A13: Svovldioxid SO2 | B13: =+'Emissionsberegninger marginal'!G43 -> -0.36771636 | C13: =+'Emissionsberegninger marginal'!G34 -> kg/MWh
A15: Metan CH4 | B15: =+'Emissionsberegninger marginal'!H43 -> 2.8683109 | C15: kg/MWh
A17: Lattergas N2O | B17: =+'Emissionsberegninger marginal'!I43 -> -0.00052573585 | C17: =+'Emissionsberegninger marginal'!I34 -> kg/MWh
A19: * Et negativt fortegn medfører at en varmebesparelse marginalt set medfører en øget
A20: udledning. Dette forekommer typisk ved, at den afledte elproduktion produceres et
A21: sted, hvor udledningen ved elproduktion er større end besparelsen i det lokale værk.
