Workbook

Sheet 2013 Budget
C1: Year Ending | F1: Year Ending | G1: Budget Variance
C2: 41547 | D2: 41547 | F2: 41182 | G2: 41182
C3: Budget | F3: Approved | G3: to
C4: Draft | D4: % of Total | F4: Budget | G4: 40816
A6: 1 | B6: Revenues
A7: =A6+1 -> 2 | B7: Product & Council Shop Revenue, Net
A8: =A7+1 -> 3 | B8: Cookie Income, Net | C8: 3082394 | D8: =+C8/$C$33 -> 0.66502944 | F8: 2913327 | G8: =SUM(C8-F8) -> 169067 | H8: =G8/F8 -> 0.058032277
A9: =A8+1 -> 4 | B9: Fall Products, Net | C9: 344629.75 | D9: =+C9/$C$33 -> 0.074354197 | F9: 344630 | G9: =SUM(C9-F9) -> -0.25 | H9: =G9/F9 -> -7.2541566e-07
A10: =A9+1 -> 5 | B10: Council Shop Income, Net | C10: 180250 | D10: =+C10/$C$33 -> 0.038889109 | F10: 185250 | G10: =SUM(C10-F10) -> -5000 | H10: =G10/F10 -> -0.026990553
A11: =A10+1 -> 6 | B11: Total Product & Council Shop Revenue | C11: =SUM(C8:C10) -> 3607273.8 | D11: =SUM(D8:D10) -> 0.77827275 | F11: =SUM(F8:F10) -> 3443207 | G11: =SUM(C11-F11) -> 164066.75 | H11: =G11/F11 -> 0.047649401
A12: =A11+1 -> 7
A13: =A12+1 -> 8 | B13: Contributions | C13: 168400 | D13: =+C13/$C$33 -> 0.03633246 | F13: 129500 | G13: =SUM(C13-F13) -> 38900 | H13: =G13/F13 -> 0.3003861
A14: =A13+1 -> 9
A15: =A14+1 -> 10 | B15: Foundations & Grants
A16: =A15+1 -> 11 | B16: United Ways | C16: 85900 | D16: =+C16/$C$33 -> 0.018533007 | F16: 85900 | G16: =SUM(C16-F16) -> 0 | H16: =G16/F16 -> 0
A17: =A16+1 -> 12 | B17: Foundations & Other Grants | C17: 200000 | D17: =+C17/$C$33 -> 0.04315019 | F17: 86000 | G17: =SUM(C17-F17) -> 114000 | H17: =G17/F17 -> 1.3255814
A18: =A17+1 -> 13 | B18: Government Agency Grants | C18: 53413 | D18: =+C18/$C$33 -> 0.011523906 | F18: 50000 | G18: =SUM(C18-F18) -> 3413 | H18: =G18/F18 -> 0.06826
A19: =A18+1 -> 14 | B19: Total Foundations & Grants | C19: =SUM(C16:C18) -> 339313 | D19: =SUM(D16:D18) -> 0.073207103 | F19: =SUM(F16:F18) -> 221900 | G19: =SUM(G16:G18) -> 117413 | H19: =G19/F19 -> 0.52912573
A20: =A19+1 -> 15
A21: =A20+1 -> 16 | B21: Program Fees
A22: =A21+1 -> 17 | B22: Resident Camp Fees | C22: 206650 | D22: =+C22/$C$33 -> 0.044584934 | F22: 178750 | G22: =SUM(C22-F22) -> 27900 | H22: =G22/F22 -> 0.15608392
A23: =A22+1 -> 18 | B23: Day Camp Fees | C23: 52000 | D23: =+C23/$C$33 -> 0.01121905 | F23: 52000 | G23: =SUM(C23-F23) -> 0 | H23: =G23/F23 -> 0
A24: =A23+1 -> 19 | B24: Total Resident and Day Camp | C24: =SUM(C22:C23) -> 258650 | D24: =+C24/$C$33 -> 0.055803984 | F24: 230750 | G24: =SUM(C24-F24) -> 27900 | H24: =G24/F24 -> 0.12091008
A25: =A24+1 -> 20 | B25: Troop Camp Fees | C25: 33900 | D25: =+C25/$C$33 -> 0.0073139573 | F25: 66830 | G25: =SUM(C25-F25) -> -32930 | H25: =G25/F25 -> -0.49274278
A26: =A25+1 -> 21 | B26: Year Round Program Fees | C26: =120467+6970 -> 127437 | D26: =+C26/$C$33 -> 0.027494654 | F26: 73685 | G26: =SUM(C26-F26) -> 53752 | H26: =G26/F26 -> 0.72948361
A27: =A26+1 -> 22 | B27: Total Program Fees | C27: =SUM(C24:C26) -> 419987 | D27: =+C27/$C$33 -> 0.090612595 | F27: =SUM(F24:F26) -> 371265 | G27: =SUM(C27-F27) -> 48722 | H27: =G27/F27 -> 0.13123241
A28: =A27+1 -> 23 | B28: Fund Raising Events | C28: 80000 | D28: =+C28/$C$33 -> 0.017260076 | F28: 68150 | G28: =SUM(C28-F28) -> 11850 | H28: =G28/F28 -> 0.17388114
A29: =A28+1 -> 24 | B29: Outside Usage Group Fees | C29: 0 | D29: =+C29/$C$33 -> 0 | F29: 0 | G29: =SUM(C29-F29) -> 0
A30: =A29+1 -> 25 | B30: Rental Income | C30: 0 | D30: =+C30/$C$33 -> 0 | F30: 19200 | G30: =SUM(C30-F30) -> -19200 | H30: =G30/F30 -> -1
A31: =A30+1 -> 26 | B31: Investment Income | C31: 0 | D31: =+C31/$C$33 -> 0 | F31: 48000 | G31: =SUM(C31-F31) -> -48000 | H31: =G31/F31 -> -1
A32: =A31+1 -> 27 | B32: Donated Goods,Service & Facility | C32: 20000 | D32: =+C32/$C$33 -> 0.004315019 | F32: 38500 | H32: =G32/F32 -> 0
A33: =A32+1 -> 28 | B33: Total Revenues | C33: =C11+C13+C19+C27+C28+C29+C30+C31+C32 -> 4634973.8 | D33: =D11+D13+D19+D27+D28+D29+D30+D31+D32 -> 1 | F33: =F11+F13+F19+F27+F28+F29+F30+F31+F32 -> 4339722 | G33: =G11+G13+G19+G27+G28+G29+G30+G31+G32 -> 313751.75 | H33: =G33/F33 -> 0.072297661
A35: 29 | B35: Expenditures
A36: =A35+1 -> 30 | B36: Labor Cost
A37: =A36+1 -> 31 | B37: Salaries | C37: 2274738 | D37: =+C37/$C$84 -> 0.49143094 | F37: 1887477 | G37: =SUM(C37-F37) -> 387261 | H37: =G37/F37 -> 0.20517389
A38: =A37+1 -> 32 | B38: Seasonal Camp Staff | C38: 100000 | D38: =+C38/$C$84 -> 0.021603848 | F38: 123350 | G38: =SUM(C38-F38) -> -23350 | H38: =G38/F38 -> -0.18929874
A39: =A38+1 -> 33 | B39: Interim CEO | C39: 0 | D39: =+C39/$C$84 -> 0 | F39: 20000 | G39: =SUM(C39-F39) -> -20000 | H39: =G39/F39 -> -1
A40: =A39+1 -> 34 | B40: Employee Benefits | C40: 531103 | D40: =+C40/$C$84 -> 0.11473869 | F40: 553210 | G40: =SUM(C40-F40) -> -22107 | H40: =G40/F40 -> -0.039961317
A41: =A40+1 -> 35 | B41: Contract-Hire Services | C41: =500+5500 -> 6000 | D41: =+C41/$C$84 -> 0.0012962309 | F41: 4600 | G41: =SUM(C41-F41) -> 1400 | H41: =G41/F41 -> 0.30434783
A42: =A41+1 -> 36 | B42: Total Labor Cost | C42: =SUM(C37:C41) -> 2911841 | D42: =SUM(D37:D41) -> 0.62906971 | F42: =SUM(F37:F41) -> 2588637 | G42: =SUM(G37:G41) -> 323204 | H42: =G42/F42 -> 0.12485489
...

Sheet Summary by major Area
C1: Year Ending
C2: 41547 | D2: 41547
C3: Budget | F3: Admin | G3: Grant | H3: Gifts | I3: Events | J3: Product Sales/Shop | K3: Program | L3: Camp | M3: Facilities | O3: Total
C4: Draft | D4: % of Total
A6: 1 | B6: Revenues
A7: =A6+1 -> 2 | B7: Product & Council Shop Revenue, Net
A8: =A7+1 -> 3 | B8: Cookie Income, Net | C8: ='2013 Budget'!C8 -> 3082394 | D8: 0.665 | F8: 0 | G8: 0 | H8: 0 | I8: 0 | J8: ='2013 Budget'!C8 -> 3082394 | K8: 0 | L8: 0 | M8: 0 | O8: =SUM(F8:M8) -> 3082394
A9: =A8+1 -> 4 | B9: Fall Products, Net | C9: ='2013 Budget'!C9 -> 344629.75 | D9: 0.074 | F9: 0 | G9: 0 | H9: 0 | I9: 0 | J9: ='2013 Budget'!C9 -> 344629.75 | K9: 0 | L9: 0 | M9: 0 | O9: =SUM(F9:M9) -> 344629.75
A10: =A9+1 -> 5 | B10: Council Shop Income, Net | C10: ='2013 Budget'!C10 -> 180250 | D10: 0.039 | F10: 0 | G10: 0 | H10: 0 | I10: 0 | J10: ='2013 Budget'!C10 -> 180250 | K10: 0 | L10: 0 | M10: 0 | O10: =SUM(F10:M10) -> 180250 | U10: 0
A11: =A10+1 -> 6 | B11: Total Product & Council Shop Revenue | C11: =SUM(C8:C10) -> 3607273.8 | D11: =SUM(D8:D10) -> 0.778 | F11: =SUM(F8:F10) -> 0 | G11: =SUM(G8:G10) -> 0 | H11: =SUM(H8:H10) -> 0 | I11: =SUM(I8:I10) -> 0 | J11: =SUM(J8:J10) -> 3607273.8 | K11: =SUM(K8:K10) -> 0 | L11: =SUM(L8:L10) -> 0 | M11: =SUM(M8:M10) -> 0 | O11: =SUM(O8:O10) -> 3607273.8
A12: =A11+1 -> 7
A13: =A12+1 -> 8 | B13: Contributions | C13: ='2013 Budget'!C13 -> 168400 | D13: 0.036 | F13: 0 | G13: =SUM('Detail Summary'!F9) -> 0 | H13: 154400 | I13: 0 | J13: 0 | K13: 14000 | L13: 0 | M13: 0 | O13: =SUM(F13:M13) -> 168400 | Q13: =C13-O13 -> 0
A14: =A13+1 -> 9 | Q14: =C14-O14 -> 0
A15: =A14+1 -> 10 | B15: Foundations & Grants | Q15: =C15-O15 -> 0
A16: =A15+1 -> 11 | B16: United Ways | C16: =SUM(F16:M16) -> 85900 | D16: 0.019 | F16: 0 | G16: =SUM('Detail Summary'!F10) -> 85900 | H16: =SUM('Detail Summary'!G10) -> 0 | I16: 0 | J16: 0 | K16: 0 | L16: 0 | M16: 0 | O16: =SUM(F16:M16) -> 85900 | Q16: =C16-O16 -> 0
A17: =A16+1 -> 12 | B17: Foundations & Other Grants | C17: ='2013 Budget'!C17 -> 200000 | D17: 0.043 | F17: 0 | G17: 125000 | H17: 75000 | I17: 0 | J17: 0 | K17: 0 | L17: 0 | M17: 0 | O17: =SUM(F17:M17) -> 200000 | Q17: =C17-O17 -> 0
A18: =A17+1 -> 13 | B18: Government Agency Grants | C18: ='2013 Budget'!C18 -> 53413 | D18: 0.012 | F18: 0 | G18: 53413 | H18: =SUM('Detail Summary'!G15) -> 0 | I18: 0 | J18: 0 | K18: 0 | L18: 0 | M18: 0 | O18: =SUM(F18:M18) -> 53413 | Q18: =C18-O18 -> 0
A19: =A18+1 -> 14 | B19: Total Foundations & Grants | C19: =SUM(C16:C18) -> 339313 | D19: =SUM(D16:D18) -> 0.074 | F19: =SUM(F16:F18) -> 0 | G19: =SUM(G16:G18) -> 264313 | H19: =SUM(H16:H18) -> 75000 | I19: =SUM(I16:I18) -> 0 | J19: =SUM(J16:J18) -> 0 | K19: =SUM(K16:K18) -> 0 | L19: =SUM(L16:L18) -> 0 | M19: =SUM(M16:M18) -> 0 | O19: =SUM(O16:O18) -> 339313 | Q19: =C19-O19 -> 0
A20: =A19+1 -> 15 | Q20: =C20-O20 -> 0
A21: =A20+1 -> 16 | B21: Program Fees | Q21: =C21-O21 -> 0
A22: =A21+1 -> 17 | B22: Resident Camp Fees | C22: ='2013 Budget'!C22 -> 206650 | D22: 0.045 | F22: 0 | G22: 0 | H22: 0 | I22: 0 | J22: 0 | K22: 0 | L22: 206650 | M22: 0 | O22: =SUM(F22:M22) -> 206650 | Q22: =C22-O22 -> 0
A23: =A22+1 -> 18 | B23: Day Camp Fees | C23: ='2013 Budget'!C23 -> 52000 | D23: 0.011 | F23: 0 | G23: 0 | H23: 0 | I23: 0 | J23: 0 | K23: 0 | L23: 52000 | M23: 0 | O23: =SUM(F23:M23) -> 52000 | Q23: =C23-O23 -> 0
A24: =A23+1 -> 19 | B24: Total Resident and Day Camp | C24: =SUM(C22:C23) -> 258650 | D24: 0.056 | F24: =SUM(F22:F23) -> 0 | G24: =SUM(G22:G23) -> 0 | H24: =SUM(H22:H23) -> 0 | I24: =SUM(I22:I23) -> 0 | J24: =SUM(J22:J23) -> 0 | K24: =SUM(K22:K23) -> 0 | L24: =SUM(L22:L23) -> 258650 | M24: =SUM(M22:M23) -> 0 | O24: =SUM(O22:O23) -> 258650 | Q24: =C24-O24 -> 0
A25: =A24+1 -> 20 | B25: Troop Camp Fees | C25: ='2013 Budget'!C25 -> 33900 | D25: 0.007 | F25: 0 | G25: 0 | H25: 0 | I25: 0 | J25: 0 | K25: 0 | L25: 33900 | M25: 0 | O25: =SUM(F25:M25) -> 33900 | Q25: =C25-O25 -> 0
A26: =A25+1 -> 21 | B26: Year Round Program Fees | C26: ='2013 Budget'!C26 -> 127437 | D26: 0.027 | F26: 6970 | G26: =SUM('Detail Summary'!F28) -> 0 | H26: 0 | I26: 0 | J26: 0 | K26: 120467 | L26: 0 | M26: 0 | O26: =SUM(F26:M26) -> 127437 | Q26: =C26-O26 -> 0
A27: =A26+1 -> 22 | B27: Total Program Fees | C27: =SUM(C24:C26) -> 419987 | D27: 0.091 | F27: =SUM(F24:F26) -> 6970 | G27: =SUM(G24:G26) -> 0 | H27: =SUM(H24:H26) -> 0 | I27: =SUM(I24:I26) -> 0 | J27: =SUM(J24:J26) -> 0 | K27: =SUM(K24:K26) -> 120467 | L27: =SUM(L24:L26) -> 292550 | M27: =SUM(M24:M26) -> 0 | O27: =SUM(O24:O26) -> 419987 | Q27: =C27-O27 -> 0
A28: =A27+1 -> 23 | B28: Fund Raising Events | C28: ='2013 Budget'!C28 -> 80000 | D28: 0.017 | F28: 0 | G28: =SUM('Detail Summary'!F16) -> 0 | H28: 0 | I28: 80000 | J28: 0 | K28: 0 | L28: 0 | M28: 0 | O28: =SUM(F28:M28) -> 80000 | Q28: =C28-O28 -> 0
A29: =A28+1 -> 24 | B29: Outside Usage Group Fees | C29: 0 | D29: 0 | F29: 0 | G29: 0 | H29: 0 | I29: 0 | J29: 0 | K29: 0 | L29: 0 | M29: 0 | O29: =SUM(F29:M29) -> 0 | Q29: =C29-O29 -> 0
A30: =A29+1 -> 25 | B30: Rental Income | C30: 0 | D30: 0 | F30: 0 | G30: =SUM('Detail Summary'!F34) -> 0 | H30: 0 | I30: 0 | J30: 0 | K30: 0 | L30: 0 | M30: 0 | O30: =SUM(F30:M30) -> 0 | Q30: =C30-O30 -> 0
A31: =A30+1 -> 26 | B31: Investment Income | C31: 0 | D31: 0 | F31: 0 | G31: =SUM('Detail Summary'!F37:F38) -> 0 | H31: 0 | I31: 0 | J31: 0 | K31: 0 | L31: 0 | M31: 0 | O31: =SUM(F31:M31) -> 0 | Q31: =C31-O31 -> 0
A32: =A31+1 -> 27 | B32: Donated Goods,Service & Facility | C32: ='2013 Budget'!C32 -> 20000 | D32: 0.004 | F32: 0 | G32: =SUM('Detail Summary'!F11:F14) -> 0 | H32: 0 | I32: 20000 | J32: 0 | K32: 0 | L32: 0 | M32: 0 | O32: =SUM(F32:M32) -> 20000 | Q32: =C32-O32 -> 0
A33: =A32+1 -> 28 | B33: Total Revenues | C33: =C11+C13+C19+C27+C28+C29+C30+C31+C32 -> 4634973.8 | D33: =D11+D13+D19+D27+D28+D29+D30+D31+D32 -> 1 | F33: =F11+F13+F19+F27+F28+F29+F30+F31+F32 -> 6970 | G33: =G11+G13+G19+G27+G28+G29+G30+G31+G32 -> 264313 | H33: =H11+H13+H19+H27+H28+H29+H30+H31+H32 -> 229400 | I33: =I11+I13+I19+I27+I28+I29+I30+I31+I32 -> 100000 | J33: =J11+J13+J19+J27+J28+J29+J30+J31+J32 -> 3607273.8 | K33: =K11+K13+K19+K27+K28+K29+K30+K31+K32 -> 134467 | L33: =L11+L13+L19+L27+L28+L29+L30+L31+L32 -> 292550 | M33: =M11+M13+M19+M27+M28+M29+M30+M31+M32 -> 0 | O33: =O11+O13+O19+O27+O28+O29+O30+O31+O32 -> 4634973.8 | Q33: =C33-O33 -> 0
Q34: =C34-O34 -> 0
A35: 29 | B35: Expenditures | Q35: =C35-O35 -> 0
A36: =A35+1 -> 30 | B36: Labor Cost | Q36: =C36-O36 -> 0
A37: =A36+1 -> 31 | B37: Salaries | C37: ='2013 Budget'!C37 -> 2274738 | D37: =+C37/$C$84 -> 0.49143094 | F37: 2274738 | G37: =SUM('Detail Summary'!F50:F51)+SUM('Detail Summary'!F53:F54) -> 0 | H37: 0 | I37: 0 | J37: 0 | K37: 0 | L37: 0 | M37: 0 | O37: =SUM(F37:M37) -> 2274738 | Q37: =C37-O37 -> 0
A38: =A37+1 -> 32 | B38: Seasonal Camp Staff | C38: ='2013 Budget'!C38 -> 100000 | D38: =+C38/$C$84 -> 0.021603848 | F38: 0 | G38: =SUM('Detail Summary'!F52) -> 0 | H38: 0 | I38: 0 | J38: 0 | K38: 0 | L38: 100000 | M38: 0 | O38: =SUM(F38:M38) -> 100000 | Q38: =C38-O38 -> 0
A39: =A38+1 -> 33 | B39: Interim CEO | C39: ='2013 Budget'!C39 -> 0 | D39: =+C39/$C$84 -> 0 | F39: 0 | G39: =SUM('Detail Summary'!F124) -> 0 | H39: 0 | I39: 0 | J39: 0 | K39: 0 | L39: 0 | M39: 0 | O39: =SUM(F39:M39) -> 0 | Q39: =C39-O39 -> 0
A40: =A39+1 -> 34 | B40: Employee Benefits | C40: ='2013 Budget'!C40 -> 531103 | D40: =+C40/$C$84 -> 0.11473869 | F40: 512679 | G40: =SUM('Detail Summary'!F55:F62)+SUM('Detail Summary'!F64:F66) -> 0 | H40: 0 | I40: 0 | J40: 0 | K40: 0 | L40: 18424 | M40: 0 | O40: =SUM(F40:M40) -> 531103 | Q40: =C40-O40 -> 0
A41: =A40+1 -> 35 | B41: Contract-Hire Services | C41: ='2013 Budget'!C41 -> 6000 | D41: =+C41/$C$84 -> 0.0012962309 | F41: 0 | G41: =SUM('Detail Summary'!F53) -> 0 | H41: 0 | I41: 0 | J41: 6000 | K41: 0 | L41: 0 | M41: 0 | O41: =SUM(F41:M41) -> 6000 | Q41: =C41-O41 -> 0
...

Sheet Detail Summary
E1: e | F1: f | G1: Gifts | H1: h | I1: i | J1: j | K1: k | L1: l | N1: m
E2: Admin | F2: Grant | G2: Gifts | H2: Event | I2: Revenue (Products/Shop) | J2: Program Services | K2: Camp | L2: Facilities | N2: Total
A4: 4 | B4: 4100 | C4: Direct Contributions | E4: =SUM(#REF!) -> #REF! | G4: =SUM(#REF!) -> #REF! | H4: =SUM(#REF!) -> #REF! | I4: =SUM(#REF!) -> #REF! | J4: =SUM(#REF!+#REF!+#REF!+#REF!) -> #REF! | K4: =SUM(#REF!) -> #REF! | L4: =SUM(#REF!) -> #REF! | N4: =SUM(E4:M4) -> #REF!
A5: =+A4+1 -> 5 | B5: 4110 | C5: Individuals | E5: 0 | G5: =SUM(#REF!)+#REF! -> #REF! | H5: =SUM(#REF!) -> #REF! | I5: =SUM(#REF!) -> #REF! | J5: =SUM(#REF!+#REF!+#REF!+#REF!) -> #REF! | K5: =SUM(#REF!) -> #REF! | L5: =SUM(#REF!) -> #REF! | N5: =SUM(E5:M5) -> #REF!
A6: =+A5+1 -> 6 | B6: 4120 | C6: Corporations/Civic Groups | E6: =SUM(#REF!) -> #REF! | G6: =SUM(#REF!) -> #REF! | H6: =SUM(#REF!) -> #REF! | I6: =SUM(#REF!) -> #REF! | J6: =SUM(#REF!+#REF!+#REF!+#REF!) -> #REF! | K6: =SUM(#REF!) -> #REF! | L6: =SUM(#REF!) -> #REF! | N6: =SUM(E6:M6) -> #REF!
A7: =+A6+1 -> 7 | B7: 4130 | C7: Foundations | E7: =SUM(#REF!) -> #REF! | G7: =SUM(#REF!) -> #REF! | H7: =SUM(#REF!) -> #REF! | I7: =SUM(#REF!) -> #REF! | J7: =SUM(#REF!+#REF!+#REF!+#REF!) -> #REF! | K7: =SUM(#REF!) -> #REF! | L7: =SUM(#REF!) -> #REF! | N7: =SUM(E7:M7) -> #REF!
A8: =+A7+1 -> 8 | B8: 4140 | C8: Planned Giving | E8: =SUM(#REF!) -> #REF! | G8: =SUM(#REF!) -> #REF! | H8: =SUM(#REF!) -> #REF! | I8: =SUM(#REF!) -> #REF! | J8: =SUM(#REF!+#REF!+#REF!+#REF!) -> #REF! | K8: =SUM(#REF!) -> #REF! | L8: =SUM(#REF!) -> #REF! | N8: =SUM(E8:M8) -> #REF!
A9: =+A8+1 -> 9 | E9: =SUM(#REF!) -> #REF! | G9: =SUM(#REF!) -> #REF! | H9: =SUM(#REF!) -> #REF! | I9: =SUM(#REF!) -> #REF! | J9: =SUM(#REF!+#REF!+#REF!+#REF!) -> #REF! | K9: =SUM(#REF!) -> #REF! | L9: =SUM(#REF!) -> #REF! | N9: =SUM(E9:M9) -> #REF!
A10: =+A9+1 -> 10 | B10: 4200 | C10: United Way | E10: =SUM(#REF!) -> #REF! | F10: 85900 | H10: =SUM(#REF!) -> #REF! | I10: =SUM(#REF!) -> #REF! | J10: =SUM(#REF!+#REF!+#REF!+#REF!) -> #REF! | K10: =SUM(#REF!) -> #REF! | L10: =SUM(#REF!) -> #REF! | N10: =SUM(E10:M10) -> #REF!
A11: =+A10+1 -> 11 | B11: 4310 | C11: Donated Goods | E11: =SUM(#REF!) -> #REF! | G11: =SUM(#REF!) -> #REF! | H11: =SUM(#REF!) -> #REF! | I11: =SUM(#REF!) -> #REF! | J11: =SUM(#REF!+#REF!+#REF!+#REF!) -> #REF! | K11: =SUM(#REF!) -> #REF! | L11: =SUM(#REF!) -> #REF! | N11: =SUM(E11:M11) -> #REF!
A12: =+A11+1 -> 12 | B12: 4320 | C12: Donated Services | E12: =SUM(#REF!) -> #REF! | G12: =SUM(#REF!) -> #REF! | H12: =SUM(#REF!) -> #REF! | I12: =SUM(#REF!) -> #REF! | J12: =SUM(#REF!+#REF!+#REF!+#REF!) -> #REF! | K12: =SUM(#REF!) -> #REF! | L12: =SUM(#REF!) -> #REF! | N12: =SUM(E12:M12) -> #REF!
A13: =+A12+1 -> 13 | B13: 4330 | C13: Donated Use of Facilities | E13: =SUM(#REF!) -> #REF! | G13: =SUM(#REF!) -> #REF! | H13: =SUM(#REF!) -> #REF! | I13: =SUM(#REF!) -> #REF! | J13: =SUM(#REF!+#REF!+#REF!+#REF!) -> #REF! | K13: =SUM(#REF!) -> #REF! | L13: =SUM(#REF!) -> #REF! | N13: =SUM(E13:M13) -> #REF!
A14: =+A13+1 -> 14 | B14: 4340 | C14: Donated Assets | E14: =SUM(#REF!) -> #REF! | G14: =SUM(#REF!) -> #REF! | H14: =SUM(#REF!) -> #REF! | I14: =SUM(#REF!) -> #REF! | J14: =SUM(#REF!+#REF!+#REF!+#REF!) -> #REF! | K14: =SUM(#REF!) -> #REF! | L14: =SUM(#REF!) -> #REF! | N14: =SUM(E14:M14) -> #REF!
A15: =+A14+1 -> 15 | B15: 4400 | C15: Government Grants | E15: =SUM(#REF!) -> #REF! | F15: 50000 | H15: =SUM(#REF!) -> #REF! | I15: =SUM(#REF!) -> #REF! | J15: =SUM(#REF!+#REF!+#REF!+#REF!) -> #REF! | K15: =SUM(#REF!) -> #REF! | L15: =SUM(#REF!) -> #REF! | N15: =SUM(E15:M15) -> #REF!
A16: =+A15+1 -> 16 | B16: 4500 | C16: Special Fundraising Events | E16: =SUM(#REF!) -> #REF! | G16: =SUM(#REF!) -> #REF! | H16: =SUM(#REF!) -> #REF! | I16: =SUM(#REF!) -> #REF! | J16: =SUM(#REF!+#REF!+#REF!+#REF!) -> #REF! | K16: =SUM(#REF!) -> #REF! | L16: =SUM(#REF!) -> #REF! | N16: =SUM(E16:M16) -> #REF!
A17: =+A16+1 -> 17 | E17: =SUM(#REF!) -> #REF! | G17: =SUM(#REF!) -> #REF! | H17: =SUM(#REF!) -> #REF! | I17: =SUM(#REF!) -> #REF! | J17: =SUM(#REF!+#REF!+#REF!+#REF!) -> #REF! | K17: =SUM(#REF!) -> #REF! | L17: =SUM(#REF!) -> #REF! | N17: =SUM(E17:M17) -> #REF!
A18: =+A17+1 -> 18 | B18: 5010 | C18: Product Sales Gross | E18: =SUM(#REF!) -> #REF! | G18: =SUM(#REF!) -> #REF! | H18: =SUM(#REF!) -> #REF! | I18: =SUM(#REF!) -> #REF! | J18: =SUM(#REF!+#REF!+#REF!+#REF!) -> #REF! | K18: =SUM(#REF!) -> #REF! | L18: =SUM(#REF!) -> #REF! | N18: =SUM(E18:M18) -> #REF!
A19: =+A18+1 -> 19 | B19: 5011 | C19: Cost of Product Sales | E19: =SUM(#REF!) -> #REF! | G19: =SUM(#REF!) -> #REF! | H19: =SUM(#REF!) -> #REF! | I19: =SUM(#REF!) -> #REF! | J19: =SUM(#REF!+#REF!+#REF!+#REF!) -> #REF! | K19: =SUM(#REF!) -> #REF! | L19: =SUM(#REF!) -> #REF! | N19: =SUM(E19:M19) -> #REF!
A20: =+A19+1 -> 20 | B20: 5012 | C20: Troop/SU Proceeds | E20: =SUM(#REF!) -> #REF! | G20: =SUM(#REF!) -> #REF! | H20: =SUM(#REF!) -> #REF! | I20: =SUM(#REF!) -> #REF! | J20: =SUM(#REF!+#REF!+#REF!+#REF!) -> #REF! | K20: =SUM(#REF!) -> #REF! | L20: =SUM(#REF!) -> #REF! | N20: =SUM(E20:M20) -> #REF!
A21: =+A20+1 -> 21 | C21: Net | E21: =SUM(#REF!) -> #REF! | G21: =SUM(#REF!) -> #REF! | H21: =SUM(#REF!) -> #REF! | I21: =SUM(#REF!) -> #REF! | J21: =SUM(#REF!+#REF!+#REF!+#REF!) -> #REF! | K21: =SUM(#REF!) -> #REF! | L21: =SUM(#REF!) -> #REF! | N21: =SUM(E21:M21) -> #REF!
A22: =+A21+1 -> 22 | B22: 5110 | C22: Retail Gross Sales | E22: =SUM(#REF!) -> #REF! | G22: =SUM(#REF!) -> #REF! | H22: =SUM(#REF!) -> #REF! | I22: =SUM(#REF!) -> #REF! | J22: =SUM(#REF!+#REF!+#REF!+#REF!) -> #REF! | K22: =SUM(#REF!) -> #REF! | L22: =SUM(#REF!) -> #REF! | N22: =SUM(E22:M22) -> #REF!
A23: =+A22+1 -> 23 | B23: 5111 | C23: Cost of Sales—inventory (contra) | E23: =SUM(#REF!) -> #REF! | G23: =SUM(#REF!) -> #REF! | H23: =SUM(#REF!) -> #REF! | I23: =SUM(#REF!) -> #REF! | J23: =SUM(#REF!+#REF!+#REF!+#REF!) -> #REF! | K23: =SUM(#REF!) -> #REF! | L23: =SUM(#REF!) -> #REF! | N23: =SUM(E23:M23) -> #REF!
A24: =+A23+1 -> 24 | B24: 5112 | C24: Cost of Sales—Freight In (contra) | E24: =SUM(#REF!) -> #REF! | G24: =SUM(#REF!) -> #REF! | H24: =SUM(#REF!) -> #REF! | I24: =SUM(#REF!) -> #REF! | J24: =SUM(#REF!+#REF!+#REF!+#REF!) -> #REF! | K24: =SUM(#REF!) -> #REF! | L24: =SUM(#REF!) -> #REF! | N24: =SUM(E24:M24) -> #REF!
A25: =+A24+1 -> 25 | B25: 5113 | C25: Returns and Allowances (contra) | E25: =SUM(#REF!) -> #REF! | G25: =SUM(#REF!) -> #REF! | H25: =SUM(#REF!) -> #REF! | I25: =SUM(#REF!) -> #REF! | J25: =SUM(#REF!+#REF!+#REF!+#REF!) -> #REF! | K25: =SUM(#REF!) -> #REF! | L25: =SUM(#REF!) -> #REF! | N25: =SUM(E25:M25) -> #REF!
A26: =+A25+1 -> 26 | B26: 5114 | C26: Merchandise Discounts Taken | E26: =SUM(#REF!) -> #REF! | G26: =SUM(#REF!) -> #REF! | H26: =SUM(#REF!) -> #REF! | I26: =SUM(#REF!) -> #REF! | J26: =SUM(#REF!+#REF!+#REF!+#REF!) -> #REF! | K26: =SUM(#REF!) -> #REF! | L26: =SUM(#REF!) -> #REF! | N26: =SUM(E26:M26) -> #REF!
A27: =+A26+1 -> 27 | C27: Net Retail | E27: =SUM(#REF!) -> #REF! | G27: =SUM(#REF!) -> #REF! | H27: =SUM(#REF!) -> #REF! | I27: =SUM(#REF!) -> #REF! | J27: =SUM(#REF!+#REF!+#REF!+#REF!) -> #REF! | K27: =SUM(#REF!) -> #REF! | L27: =SUM(#REF!) -> #REF! | N27: =SUM(E27:M27) -> #REF!
A28: =+A27+1 -> 28 | B28: 5200 | C28: PROGRAM SERVICE FEES | E28: =SUM(#REF!) -> #REF! | G28: =SUM(#REF!) -> #REF! | H28: =SUM(#REF!) -> #REF! | I28: =SUM(#REF!) -> #REF! | J28: =SUM(#REF!+#REF!+#REF!+#REF!) -> #REF! | L28: =SUM(#REF!) -> #REF! | N28: =SUM(E28:M28) -> #REF!
A29: =+A28+1 -> 29 | B29: 5201 | C29: Program Revenue for Budget | E29: =SUM(#REF!) -> #REF! | G29: =SUM(#REF!) -> #REF! | H29: =SUM(#REF!) -> #REF! | I29: =SUM(#REF!) -> #REF! | J29: =SUM(#REF!+#REF!+#REF!+#REF!) -> #REF! | K29: =SUM(#REF!) -> #REF! | L29: =SUM(#REF!) -> #REF! | N29: =SUM(E29:M29) -> #REF!
A30: =+A29+1 -> 30 | B30: 5280 | C30: Government Fees and Contracts | E30: =SUM(#REF!) -> #REF! | G30: =SUM(#REF!) -> #REF! | H30: =SUM(#REF!) -> #REF! | I30: =SUM(#REF!) -> #REF! | J30: =SUM(#REF!+#REF!+#REF!+#REF!) -> #REF! | K30: =SUM(#REF!) -> #REF! | L30: =SUM(#REF!) -> #REF! | N30: =SUM(E30:M30) -> #REF!
A31: =+A30+1 -> 31 | B31: 5290 | C31: Special Event REVenue | E31: =SUM(#REF!) -> #REF! | G31: =SUM(#REF!) -> #REF! | H31: =SUM(#REF!) -> #REF! | I31: =SUM(#REF!) -> #REF! | J31: =SUM(#REF!+#REF!+#REF!+#REF!) -> #REF! | K31: =SUM(#REF!) -> #REF! | L31: =SUM(#REF!) -> #REF! | N31: =SUM(E31:M31) -> #REF!
A32: =+A31+1 -> 32 | B32: 5291 | C32: Cost of Direct Benefit to Donor | E32: =SUM(#REF!) -> #REF! | G32: =SUM(#REF!) -> #REF! | H32: =SUM(#REF!) -> #REF! | I32: =SUM(#REF!) -> #REF! | J32: =SUM(#REF!+#REF!+#REF!+#REF!) -> #REF! | K32: =SUM(#REF!) -> #REF! | L32: =SUM(#REF!) -> #REF! | N32: =SUM(E32:M32) -> #REF!
A33: =+A32+1 -> 33 | B33: 5300 | C33: RENTAL INCOME | E33: =SUM(#REF!) -> #REF! | G33: =SUM(#REF!) -> #REF! | H33: =SUM(#REF!) -> #REF! | I33: =SUM(#REF!) -> #REF! | J33: =SUM(#REF!+#REF!+#REF!+#REF!) -> #REF! | K33: =SUM(#REF!) -> #REF! | L33: =SUM(#REF!) -> #REF! | N33: =SUM(E33:M33) -> #REF!
A34: =+A33+1 -> 34 | B34: 5301 | C34: Rental Income Budget | E34: =SUM(#REF!) -> #REF! | G34: =SUM(#REF!) -> #REF! | H34: =SUM(#REF!) -> #REF! | I34: =SUM(#REF!) -> #REF! | J34: =SUM(#REF!+#REF!+#REF!+#REF!) -> #REF! | K34: =SUM(#REF!) -> #REF! | L34: =SUM(#REF!) -> #REF! | N34: =SUM(E34:M34) -> #REF!
A35: =+A34+1 -> 35 | B35: 5400 | C35: INVESTMENT INCOME | E35: =SUM(#REF!) -> #REF! | G35: =SUM(#REF!) -> #REF! | H35: =SUM(#REF!) -> #REF! | I35: =SUM(#REF!) -> #REF! | J35: =SUM(#REF!+#REF!+#REF!+#REF!) -> #REF! | K35: =SUM(#REF!) -> #REF! | L35: =SUM(#REF!) -> #REF! | N35: =SUM(E35:M35) -> #REF!
A36: =+A35+1 -> 36 | B36: 5401 | C36: Investment Income Budget | E36: =SUM(#REF!) -> #REF! | G36: =SUM(#REF!) -> #REF! | H36: =SUM(#REF!) -> #REF! | I36: =SUM(#REF!) -> #REF! | J36: =SUM(#REF!+#REF!+#REF!+#REF!) -> #REF! | K36: =SUM(#REF!) -> #REF! | L36: =SUM(#REF!) -> #REF! | N36: =SUM(E36:M36) -> #REF!
A37: =+A36+1 -> 37 | B37: 5410 | C37: Bank Interest | E37: =SUM(#REF!) -> #REF! | G37: =SUM(#REF!) -> #REF! | H37: =SUM(#REF!) -> #REF! | I37: =SUM(#REF!) -> #REF! | J37: =SUM(#REF!+#REF!+#REF!+#REF!) -> #REF! | K37: =SUM(#REF!) -> #REF! | L37: =SUM(#REF!) -> #REF! | N37: =SUM(E37:M37) -> #REF!
A38: =+A37+1 -> 38 | B38: 5415 | C38: Investment Interest and Dividends | E38: =SUM(#REF!) -> #REF! | G38: =SUM(#REF!) -> #REF! | H38: =SUM(#REF!) -> #REF! | I38: =SUM(#REF!) -> #REF! | J38: =SUM(#REF!+#REF!+#REF!+#REF!) -> #REF! | K38: =SUM(#REF!) -> #REF! | L38: =SUM(#REF!) -> #REF! | N38: =SUM(E38:M38) -> #REF!
A39: =+A38+1 -> 39 | B39: 5420 | C39: Realized Gain (or Loss) | E39: =SUM(#REF!) -> #REF! | G39: =SUM(#REF!) -> #REF! | H39: =SUM(#REF!) -> #REF! | I39: =SUM(#REF!) -> #REF! | J39: =SUM(#REF!+#REF!+#REF!+#REF!) -> #REF! | K39: =SUM(#REF!) -> #REF! | L39: =SUM(#REF!) -> #REF! | N39: =SUM(E39:M39) -> #REF!
A40: =+A39+1 -> 40 | B40: 5430 | C40: Unrealized Gain (or Loss) | E40: =SUM(#REF!) -> #REF! | G40: =SUM(#REF!) -> #REF! | H40: =SUM(#REF!) -> #REF! | I40: =SUM(#REF!) -> #REF! | J40: =SUM(#REF!+#REF!+#REF!+#REF!) -> #REF! | K40: =SUM(#REF!) -> #REF! | L40: =SUM(#REF!) -> #REF! | N40: =SUM(E40:M40) -> #REF!
... A45: =+A44+1 -> 45 | B45: 5650 | C45: Gain or Loss on Sale of Assets (Property and Equipment) | E45: =SUM(#REF!) -> #REF! | G45: =SUM(#REF!) -> #REF! | H45: =SUM(#REF!) -> #REF! | I45: =SUM(#REF!) -> #REF! | J45: =SUM(#REF!+#REF!+#REF!+#REF!) -> #REF! | K45: =SUM(#REF!) -> #REF! | L45: =SUM(#REF!) -> #REF! | N45: =SUM(E45:M45) -> #REF!
...
