Workbook

Sheet Excess Cost
A1: Excess Cost Worksheet
A2: ` | B2: LEA | D2: =IF(ISBLANK(C2),"-",VLOOKUP(C2,Data!A2:B71,2,FALSE)) -> - | H2: Year: | I2: 2011-2012
B3: Note: All requested data are from the prior school year (the 2010-2011 school year).
A4: Prior school year's total expenditures from all sources less capital outlay and debt service.
E5: Secondary (9-12, NG) | H5: Elementary (PreK-8)
A6: Total Expenditures
B7: State & Local | H7: =IF(ISBLANK(E7),"-",Totals!E6-'Excess Cost'!E7) -> -
B8: Federal Funds | H8: =IF(ISBLANK(E8),"-",Totals!E7-'Excess Cost'!E8) -> -
A9: Total Expenditures from all Sources | F9: =SUM(E7:E8) -> 0 | I9: =SUM(H7:H8) -> 0
A10: Less Capital Outlay & Debt Services
B11: Capital Outlay | H11: =IF(ISBLANK(E11),"-",Totals!E10-'Excess Cost'!E11) -> -
B12: Debt Services | H12: =IF(ISBLANK(E12),"-",Totals!E11-'Excess Cost'!E12) -> -
A13: Total Capital Outlay & Debt Services | F13: =SUM(E11:E12) -> 0 | I13: =SUM(H11:H12) -> 0
A14: Total Expenditures less Capital Outlay
A15: & Debt Services | F15: =F9-F13 -> 0 | I15: =I9-I13 -> 0
A18: Deduct prior year's special education expenditures.
E19: Secondary (9-12, NG) | H19: Elementary (PreK-8)
A20: Special Education Expenditures
B21: IDEA, Part B | H21: =IF(ISBLANK(E21),"-",Totals!E19-'Excess Cost'!E21) -> -
B22: ESEA Title I, Part A | H22: =IF(ISBLANK(E22),"-",Totals!E20-'Excess Cost'!E22) -> -
B23: ESEA Title III, Parts A & B | H23: =IF(ISBLANK(E23),"-",Totals!E21-'Excess Cost'!E23) -> -
B24: State and Local special education funds | H24: =IF(ISBLANK(E24),"-",Totals!E22-'Excess Cost'!E24) -> -
B25: State and local funds for programs under
B26: ESEA Title I, Part A, and ESEA Title III, Parts A & B | H26: =IF(ISBLANK(E26),"-",Totals!E24-'Excess Cost'!E26) -> -
A27: Total special education deductions | F27: =SUM(E21:E26) -> 0 | I27: =SUM(H21:H26) -> 0
A28: Total Expenditures less
A29: Special Education Expenditures | F29: =F15-F27 -> 0 | I29: =I15-I27 -> 0
A32: Prior year's school enrollments.
E33: Secondary (9-12, NG) | H33: Elementary (PreK-8)
A34: Prior year's September 20 count | F34: =IF(ISBLANK(C2),"-",VLOOKUP(C2,Data!A2:Q71,15,FALSE)) -> - | I34: =IF(ISBLANK(C2),"-",Totals!F31-'Excess Cost'!F34) -> -
A36: Prior year's December 1 count | F36: =IF(ISBLANK(C2),"-",VLOOKUP(C2,Data!A2:Q71,17,FALSE)) -> - | I36: =IF(ISBLANK(C2),"-",Totals!F33-'Excess Cost'!F36) -> -
A38: Current year's excess cost results.
E39: Secondary (9-12, NG) | H39: Elementary (PreK-8)
A40: Average annual expenditure per LEA
A41: Student | F41: =IF(F29>0,F29/F34,0) -> 0 | I41: =IF(I29>0,I29/I34,0) -> 0
A42: Minimum amount LEA must spend in the current year
A43: for the education of elementary students with
A44: disabilities before using IDEA Part B funds | F44: =IF(F29>0,F36*F41,0) -> 0 | I44: =IF(I29>0,I41*I36,0) -> 0
C46: I certify to the best of my knowledge the information provided is accurate and correct .
E48: Signature of LEA's Authorized Representative:
...

Sheet Totals
B2: LEA | C2: ='Excess Cost'!C2 -> 0 | D2: ='Excess Cost'!D2:E2 -> - | H2: Note: The data provided on this tab is informational only and is directly populated from the annual district budgets submitted to KSDE in July. No action is required by district officials on this tab.
E4: Total for LEA
A5: Total Expenditures
B6: State & Local | E6: =VLOOKUP(C2,Data!A2:O71,3,FALSE) -> #N/A
B7: Federal Funds | E7: =VLOOKUP(C2,Data!A2:O71,4,FALSE) -> #N/A
A8: Total Expenditures from all Sources | F8: =SUM(E6:E7) -> #N/A
A9: Less Capital Outlay & Debt Services
B10: Capital Outlay | E10: =VLOOKUP(C2,Data!A2:O71,5,FALSE) -> #N/A
B11: Debt Services | E11: =VLOOKUP(C2,Data!A2:O71,6,FALSE) -> #N/A
A12: Total Capital Outlay & Debt Services | F12: =SUM(E10:E11) -> #N/A
A13: Total Expenditures less Capital Outlay
A14: & Debt Services | F14: =F8-F12 -> #N/A
E17: Total for LEA
A18: Special Education Expenditures
B19: IDEA, Part B | E19: =VLOOKUP(C2,Data!A2:O71,7,FALSE) -> #N/A
B20: ESEA Title I, Part A | E20: =VLOOKUP(C2,Data!A2:O71,8,FALSE) -> #N/A
B21: ESEA Title III, Parts A & B | E21: =VLOOKUP(C2,Data!A2:O71,9,FALSE) -> #N/A
B22: State and Local special education funds | E22: =VLOOKUP(C2,Data!A2:O71,12,FALSE) -> #N/A
B23: State and local funds for programs under
B24: ESEA Title I, Part A, and ESEA Title III, Parts A & B | E24: =VLOOKUP(C2,Data!A2:O71,13,FALSE) -> #N/A
A25: Total special education deductions | F25: =SUM(E19:E24) -> #N/A
A26: Total Expenditures less
A27: Special Education Expenditures | F27: =F14-F25 -> #N/A
E30: Total for LEA
A31: Prior year's September 20 count | F31: =VLOOKUP(C2,Data!A2:Q71,14,FALSE)+VLOOKUP(C2,Data!A2:Q71,15,FALSE) -> #N/A
A33: Prior year's December 1 count | F33: =VLOOKUP(C2,Data!A2:Q71,16,FALSE)+VLOOKUP(C2,Data!A2:Q71,17,FALSE) -> #N/A
E36: Total for LEA
A37: Average annual expenditure per LEA
A38: Student | F38: =F27/F31 -> #N/A
A39: Minimum amount LEA must spend in the current year
A40: for the education of elementary students with
A41: disabilities before using IDEA Part B funds | F41: =F38*F33 -> #N/A

Sheet Form Assistant for Inter&Coop
A1: BOTH COOP & INTERLOCAL DIRECTORS complete this section to determine the secondary Federal expenditures for the "Excess Cost" tab of this workbook. | J1: COOP DIRECTORS ONLY must also complete this section to determine the secondary state and local special education expenditures for the "Excess Cost" tab of this workbook.
A6: STEP 1: Sum the Elementary Federal expenditures from the member district worksheets and enter the total in this box | J6: STEP 1: Sum the Elementary state and local special education expenditures from the member district worksheets and enter the total in this box
A10: STEP 2: Sum the Secondary Federal expenditures from the member district worksheets and enter the total in this box | J10: STEP 2: Sum the Secondary state and local special education expenditures from the member district worksheets and enter the total in this box
A13: Total | G13: =IF(ISBLANK(G12),0,SUM(G8,G12)) -> 0 | J13: Total | P13: =P8+P12 -> 0
A16: Total Federal funds on the "Total" tab of the LEA worksheet | J16: Total state and local special education funds on the "Total" tab of the LEA worksheet
G17: =Totals!E7 -> #N/A | P17: =Totals!E22 -> #N/A
A20: STEP 3: This is the amount of Federal funds, which represents the IDEA portion of Federal funds spent at the Coop level and subsequently the amount of which the special ed director will need to identify secondary specific expenditures. Refer to the Excess Cost LEA notes for guidance on identifying secondary specific expenditures. | J20: STEP 3: This is the amount of state and local special education funds spent at the Coop level and subsequently the amount from which the special ed director will need to identify secondary specific expenditures. Refer to the LEA Worksheet notes for guidance on identifying secondary specific expenditures.
G25: =IF(ISBLANK(G12), 0, G17-G13) -> 0 | P25: =IF(ISBLANK(P12),0,P17-P13) -> 0
A28: Step 4: Add the amount in Step 2 to the secondary specific expenditures identified in Step 3. Enter that amount in the shaded cell for Secondary Federal expenditures in the "Excess Cost" tab of this workbook. | J28: Step 4: Add the amount in Step 2 to the secondary specific expenditures identified in Step 3. Enter that amount in the shaded cell for Secondary state and local special education expenditures in the "Excess Cost" tab of this workbook.

Sheet Data
A1: Coop_ServCtr | B1: LEA Name | C1: Non-Fed Expend | D1: Fed Expend | E1: Cap_Outlay | F1: Debt_Service | G1: IDEA_Draw | H1: TitleI_Draw | I1: TitleIII_Draw | J1: Sped Fund | K1: Coop Fund | L1: Sped_Expend | M1: Bil_Expend | N1: PK-8_Hdct | O1: 9-12,NG_Hdct | P1: Child Count elementary | Q1: Child Count Secondary
A2: 115 | B2: Nemaha Central | C2: 14094069 | D2: 988591 | E2: 1023779 | F2: 607132 | G2: 531512 | H2: 221084 | I2: 0 | J2: 66993 | K2: 1200712 | L2: 1267705 | M2: 0 | N2: 805 | O2: 391 | P2: 162 | Q2: 40
A3: 202 | B3: Turner-Kansas City | C3: 41748875 | D3: 3035148 | E3: 3767346 | F3: 3761905 | G3: 1185541 | H3: 1457336 | I3: 67046 | J3: 4109176 | K3: 0 | L3: 4109176 | M3: 456154 | N3: 2780 | O3: 1296 | P3: 345 | Q3: 152
A4: 229 | B4: Blue Valley | C4: 252627473 | D4: 5996429 | E4: 14269150 | F4: 41965928 | G4: 5337596 | H4: 340546 | I4: 30806 | J4: 29746139 | K4: 0 | L4: 29746139 | M4: 1505859 | N4: 14768 | O4: 6663 | P4: 1441 | Q4: 546
A5: 230 | B5: Spring Hill | C5: 28786006 | D5: 990796 | E5: 430068 | F5: 3810929 | G5: 772581 | H5: 183017 | I5: 0 | J5: 2125599 | K5: 0 | L5: 2125599 | M5: 26137 | N5: 1555 | O5: 2053 | P5: 209 | Q5: 109
A6: 231 | B6: Gardner Edgerton | C6: 58294735 | D6: 2490760 | E6: 3747688 | F6: 11399195 | G6: 1267652 | H6: 412869 | I6: 0 | J6: 7033419 | K6: 0 | L6: 7033419 | M6: 270804 | N6: 3712 | O6: 1330 | P6: 535 | Q6: 124
A7: 232 | B7: De Soto | C7: 72362597 | D7: 2035001 | E7: 2210790 | F7: 16010332 | G7: 1674259 | H7: 148872 | I7: 17992 | J7: 6536322 | K7: 0 | L7: 6536322 | M7: 259117 | N7: 4926 | O7: 1742 | P7: 336 | Q7: 136
A8: 233 | B8: Olathe | C8: 289378300 | D8: 14208464 | E8: 3475490 | F8: 42372540 | G8: 9311424 | H8: 2217996 | I8: 138591 | J8: 33953344 | K8: 0 | L8: 33953344 | M8: 2482521 | N8: 19530 | O8: 7835 | P8: 2382 | Q8: 814
A9: 234 | B9: Fort Scott | C9: 17345758 | D9: 1613107 | E9: 537363 | F9: 1057041 | G9: 649891 | H9: 803285 | I9: 0 | J9: 1335376 | K9: 0 | L9: 1335376 | M9: 9645 | N9: 1406 | O9: 567 | P9: 132 | Q9: 50
A10: 244 | B10: Coffey County Special Services Coop | C10: 19487656 | D10: 897584 | E10: 1234893 | F10: 407488 | G10: 566736 | H10: 252982 | I10: 0 | J10: 2362117 | K10: 424094 | L10: 2786211 | M10: 0 | N10: 1136 | O10: 509 | P10: 235 | Q10: 92
A11: 253 | B11: Flint Hills Special Ed. Coop | C11: 80068613 | D11: 5848055 | E11: 4374022 | F11: 5273715 | G11: 2482257 | H11: 2165949 | I11: 135734 | J11: 635515 | K11: 5447328 | L11: 6082843 | M11: 1761554 | N11: 4843 | O11: 2277 | P11: 673 | Q11: 283
A12: 259 | B12: Wichita | C12: 562136049 | D12: 55909231 | E12: 44848559 | F12: 45595357 | G12: 17694348 | H12: 25769412 | I12: 765087 | J12: 70145127 | K12: 0 | L12: 70145127 | M12: 10727995 | N12: 35976 | O12: 13597 | P12: 4307 | Q12: 2230
A13: 260 | B13: Derby | C13: 62424947 | D13: 3417694 | E13: 5002215 | F13: 3754676 | G13: 2063641 | H13: 1087197 | I13: 69196 | J13: 6968616 | K13: 0 | L13: 6968616 | M13: 836215 | N13: 4872 | O13: 1881 | P13: 718 | Q13: 270
... A71: 999 | B71: Robinson LEA | C71: 45907028 | D71: 3814187 | E71: 1849286 | F71: 3179763 | G71: 1856451 | H71: 1137320 | I71: 59021 | J71: 102477 | K71: 4052087 | L71: 4154564 | M71: 580000 | N71: 2979 | O71: 1500 | P71: 430 | Q71: 183
