Workbook

Sheet GTR Corn Table

Sheet Total
B1: 3-Year Ave, | C1: 3-Year Ave, | E1: Unshipped Balance | G1: Accumulated Exports | I1: Total Commitments | K1: from last yr | O1: Exports3 | P1: Week ending 08/31/06 | AA1: 4 Not Included - FAS Daily Press Release: Corn Export Sales to Japan on 4/18: 152,400 mt for 2006/07.
B2: Total Sales | C2: Shipped | E2: Current | F2: Last | G2: Current | H2: Last | I2: Current | J2: Last | K2: % change | L2: net sales | M2: wk | R2: WASDE (MT) | S2: WASDE (bu) | V2: For the graph
O3: 2004/05 | P3: Crop Year (CY)
O4: - 1,000 mt - | AA4: WASHINGTON, May 11, 2007 -- Private exporters reported to the U.S. Department of Agriculture export sales of 550,000 metric tons of corn for delivery to South Korea. Of the total, 495,000 tons is for delivery during the 2006/2007 marketing year and 55,000 tons is for delivery during the 2007/2008 marketing year.
O5: 16428.5 | P5: Japan
A6: =+A7-7 -> 38680 | D6: US total | E6: 7813.5 | F6: 9141.4 | G6: 10251.3 | H6: 10258 | I6: =+E6+G6 -> 18064.8 | J6: =+F6+H6 -> 19399.4 | K6: =+I6/J6-1 -> -0.068795942 | O6: 6278.2 | P6: Mexico
A7: =+A8-7 -> 38687 | D7: =+D6 -> US total | E7: 7759.2 | F7: 8917.1 | G7: 10917.4 | H7: 11065.4 | I7: =+E7+G7 -> 18676.6 | J7: =+F7+H7 -> 19982.5 | K7: =+I7/J7-1 -> -0.065352183 | O7: 4690.3 | P7: Taiwan
A8: =+A9-7 -> 38694 | D8: =+D7 -> US total | E8: 7432.4 | F8: 8624 | G8: 11938.5 | H8: 12273.4 | I8: =+E8+G8 -> 19370.9 | J8: =+F8+H8 -> 20897.4 | K8: =+I8/J8-1 -> -0.073047365 | O8: 4563.3 | P8: Egypt
A9: =+A10-7 -> 38701 | D9: =+D8 -> US total | E9: 7334.4 | F9: 8113.4 | G9: 12957.1 | H9: 13420.7 | I9: =+E9+G9 -> 20291.5 | J9: =+F9+H9 -> 21534.1 | K9: =+I9/J9-1 -> -0.057703828 | O9: 2268.3 | P9: Korea
A10: =+A11-7 -> 38708 | D10: =+D9 -> US total | E10: 7037.3 | F10: 7770.2 | G10: 14137.5 | H10: 14489.7 | I10: =+E10+G10 -> 21174.8 | J10: =+F10+H10 -> 22259.9 | K10: =+I10/J10-1 -> -0.04874685 | O10: =SUM(O5:O9) -> 34228.6 | P10: Top 5 importers
A11: =+A12-7 -> 38715 | D11: =+D10 -> US total | E11: 6618.9 | F11: 7496.3 | G11: 14916.1 | H11: 15460.5 | I11: =+E11+G11 -> 21535 | J11: =+F11+H11 -> 22956.8 | K11: =+I11/J11-1 -> -0.061933719
A12: =+A13-7 -> 38722 | D12: =+D11 -> US total | E12: 5991.3 | F12: 6974.5 | G12: 16072.6 | H12: 16412.7 | I12: =+E12+G12 -> 22063.9 | J12: =+F12+H12 -> 23387.2 | K12: =+I12/J12-1 -> -0.056582233
A13: =+A14-7 -> 38729 | D13: =+D12 -> US total | E13: 5905.2 | F13: 6999 | G13: 16731.1 | H13: 17046.5 | I13: =+E13+G13 -> 22636.3 | J13: =+F13+H13 -> 24045.5 | K13: =+I13/J13-1 -> -0.05860556 | L13: 48260
A14: =+A15-7 -> 38736 | D14: =+D13 -> US total | E14: 7415.7 | F14: 6839.6 | G14: 18582.6 | H14: 18877.8 | I14: =+E14+G14 -> 25998.3 | J14: =+F14+H14 -> 25717.4 | K14: =+I14/J14-1 -> 0.010922566
A15: =+A16-7 -> 38743 | D15: =+D14 -> US total | E15: 7858.4 | F15: 6256.8 | G15: 19502.3 | H15: 19754.5 | I15: =+E15+G15 -> 27360.7 | J15: =+F15+H15 -> 26011.3 | K15: =+I15/J15-1 -> 0.051877453
A16: =+A17-7 -> 38750 | D16: =+D15 -> US total | E16: 8455 | G16: 20517.6 | I16: =+E16+G16 -> 28972.6 | J16: 27006.8 | K16: =+I16/J16-1 -> 0.072789075
A17: =+A18-7 -> 38757 | D17: =+D16 -> US total | E17: 8829.4 | F17: 6768.7 | G17: 21340.4 | H17: 21024.2 | I17: =+E17+G17 -> 30169.8 | J17: =+F17+H17 -> 27792.9 | K17: =+I17/J17-1 -> 0.085521842
A18: =+A19-7 -> 38764 | D18: =+D17 -> US total | E18: 9280.8 | G18: 22379.6 | I18: =+E18+G18 -> 31660.4 | K18: =+I18/J18-1 -> #DIV/0!
A19: =+A20-7 -> 38771 | D19: =+D18 -> US total | E19: 8934.8 | G19: 23339.1 | I19: =+E19+G19 -> 32273.9 | K19: =+I19/J19-1 -> #DIV/0!
A20: =+A21-7 -> 38778 | D20: =+D19 -> US total | E20: 9246.3 | G20: 24440.9 | I20: =+E20+G20 -> 33687.2 | K20: =+I20/J20-1 -> #DIV/0!
A21: =+A22-7 -> 38785 | D21: =+D20 -> US total | E21: 9442.6 | G21: 25213.1 | I21: =+E21+G21 -> 34655.7 | K21: =+I21/J21-1 -> #DIV/0!
A22: =+A23-7 -> 38792 | D22: =+D21 -> US total | E22: 9141.4 | G22: 26425.7 | I22: =+E22+G22 -> 35567.1 | K22: =+I22/J22-1 -> #DIV/0!
A23: =+A24-7 -> 38799 | D23: =+D22 -> US total | E23: 9285 | G23: 27320.9 | I23: =+E23+G23 -> 36605.9 | K23: =+I23/J23-1 -> #DIV/0!
A24: =+A25-7 -> 38806 | D24: =+D23 -> US total | E24: 8754.8 | G24: 28510.5 | I24: =+E24+G24 -> 37265.3 | K24: =+I24/J24-1 -> #DIV/0!
A25: =+A26-7 -> 38813 | D25: =+D24 -> US total | E25: 8687.4 | F25: 7576.2 | G25: 29392.6 | H25: 27325.8 | I25: =+E25+G25 -> 38080 | J25: =+F25+H25 -> 34902 | K25: =+(I25/J25-1)*100 -> 9.1054954 | Q25: =+I25-I24 -> 814.7
A26: =+A27-7 -> 38820 | D26: =+D25 -> US total | E26: 8888.4 | F26: 7394 | G26: 30294.7 | H26: 28176.5 | I26: =+E26+G26 -> 39183.1 | J26: =+F26+H26 -> 35570.5 | K26: =+(I26/J26-1)*100 -> 10.156169 | P26: =+I26/I25-1 -> 0.028967962 | Q26: =+I26-I25 -> 1103.1
A27: =+A28-7 -> 38827 | D27: =+D26 -> US total | E27: 8475.4 | G27: 31477.3 | I27: =+E27+G27 -> 39952.7 | J27: =+F27+H27 -> 0 | K27: =+(I27/J27-1)*100 -> #DIV/0! | P27: =+I27/I26-1 -> 0.019641121 | Q27: =+I27-I26 -> 769.6
A28: =+A29-7 -> 38834 | D28: =+D27 -> US total | E28: 8702.5 | F28: 6565.8 | G28: 32532.4 | H28: 30120.7 | I28: =+E28+G28 -> 41234.9 | J28: =+F28+H28 -> 36686.5 | K28: =+(I28/J28-1)*100 -> 12.398021 | P28: =+I28/I27-1 -> 0.03209295 | Q28: =+I28-I27 -> 1282.2
A29: =+A30-7 -> 38841 | D29: =+D28 -> US total | E29: 8702.9 | F29: 7097.5 | G29: 33637.1 | H29: 30978.6 | I29: =+E29+G29 -> 42340 | J29: =+F29+H29 -> 38076.1 | K29: =+(I29/J29-1)*100 -> 11.198363 | L29: =+(I29/I28-1)*100 -> 2.6800113 | P29: =+I29/I28-1 -> 0.026800113 | Q29: =+I29-I28 -> 1105.1
A30: =+A31-7 -> 38848 | D30: =+D29 -> US total | E30: 9156.9 | G30: 34723 | I30: =+E30+G30 -> 43879.9 | J30: =+F30+H30 -> 0 | K30: =+(I30/J30-1)*100 -> #DIV/0! | P30: =+I30/I29-1 -> 0.036369863 | Q30: =+I30-I29 -> 1539.9
A31: =+A32-7 -> 38855 | D31: =+D30 -> US total | E31: 8815.5 | F31: 6734 | G31: 36200.8 | H31: 32746.5 | I31: =+E31+G31 -> 45016.3 | J31: =+F31+H31 -> 39480.5 | K31: =+(I31/J31-1)*100 -> 14.021606 | L31: 636.9 | P31: =+I31/I30-1 -> 0.025897962 | Q31: =+I31-I30 -> 1136.4
A32: =+A33-7 -> 38862 | D32: =+D31 -> US total | E32: 8717.4 | F32: 6668.4 | G32: 37454.9 | H32: 33556.6 | I32: =+E32+G32 -> 46172.3 | J32: =+F32+H32 -> 40225 | K32: =+(I32/J32-1)*100 -> 14.785084 | L32: 715 | O32: 270 | P32: =+I32/I31-1 -> 0.025679587 | Q32: =+I32-I31 -> 1156
A33: =+A34-7 -> 38869 | D33: =+D32 -> US total | E33: 8420.4 | F33: 6385.7 | G33: 38619.2 | H33: 34400.8 | I33: =+E33+G33 -> 47039.6 | J33: =+F33+H33 -> 40786.5 | K33: =+(I33/J33-1)*100 -> 15.331298 | L33: 762.4 | P33: =+I33/I32-1 -> 0.01878399 | Q33: =+I33-I32 -> 867.3
A34: =+A35-7 -> 38876 | D34: =+D33 -> US total | E34: 8745.9 | F34: 6208.2 | G34: 39758.4 | H34: 35212.1 | I34: =+E34+G34 -> 48504.3 | J34: =+F34+H34 -> 41420.3 | K34: =+(I34/J34-1)*100 -> 17.102725 | L34: 836.8 | P34: =+I34/I33-1 -> 0.031137595 | Q34: =+I34-I33 -> 1464.7
A35: =+A36-7 -> 38883 | D35: =+D34 -> US total | E35: 9037.3 | F35: 5649.6 | G35: 41042.2 | H35: 36278.8 | I35: =+E35+G35 -> 50079.5 | J35: =+F35+H35 -> 41928.4 | K35: =+(I35/J35-1)*100 -> 19.440522 | L35: 1077.4 | O35: 420.2 | P35: =+I35/I34-1 -> 0.032475471 | Q35: =+I35-I34 -> 1575.2
A36: =+A37-7 -> 38890 | D36: =+D35 -> US total | E36: 9213.5 | F36: 5808.6 | G36: 42219.8 | H36: 37336.4 | I36: =+E36+G36 -> 51433.3 | J36: =+F36+H36 -> 43145 | K36: =+(I36/J36-1)*100 -> 19.210337 | L36: 1751.2 | O36: 542.1 | P36: =+I36/I35-1 -> 0.027033018 | Q36: =+I36-I35 -> 1353.8 | R36: 52710
A37: =+A38-7 -> 38897 | D37: =+D36 -> US total | E37: 8999.8 | F37: 5977.4 | G37: 43249.2 | H37: 38109.7 | I37: =+E37+G37 -> 52249 | J37: =+F37+H37 -> 44087.1 | K37: =+(I37/J37-1)*100 -> 18.513125 | L37: 2210.5 | O37: 569.6 | P37: =+I37/I36-1 -> 0.015859375 | Q37: =+I37-I36 -> 815.7
A38: =+A39-7 -> 38904 | D38: =+D37 -> US total | E38: 8655.6 | F38: 5724.8 | G38: 44156.6 | H38: 38685.3 | I38: =+E38+G38 -> 52812.2 | J38: =+F38+H38 -> 44410.1 | K38: =+(I38/J38-1)*100 -> 18.919345 | L38: 2289.9 | O38: 662.5 | P38: =+I38/I37-1 -> 0.010779154 | Q38: =+I38-I37 -> 563.2
A39: =+A40-7 -> 38911 | D39: =+D38 -> US total | E39: 7794 | F39: 5507.7 | G39: 45358.3 | H39: 39498.6 | I39: =+E39+G39 -> 53152.3 | J39: =+F39+H39 -> 45006.3 | K39: =+(I39/J39-1)*100 -> 18.099688 | L39: 2582.4 | O39: 925.3 | P39: =+I39/I38-1 -> 0.0064397999 | Q39: =+I39-I38 -> 340.1 | R39: 53340
A40: =+A41-7 -> 38918 | D40: =+D39 -> US total | E40: 7387.1 | F40: 5159.9 | G40: 46741 | H40: 40485 | I40: =+E40+G40 -> 54128.1 | J40: =+F40+H40 -> 45644.9 | K40: =+(I40/J40-1)*100 -> 18.585209 | L40: 2695.4 | O40: 926.3 | Q40: =+I40-I39 -> 975.8 | R40: 53340
...

Sheet Japan
B1: Corn by Destination Export Sales as of: | M1: Next Marketing Year
C2: Unshipped Balance | E2: Accumulated Exports | G2: Total Commitments | I2: from last yr | J2: Next Crop | K2: 05/06 5-yr avg | L2: 04/05 | M2: Unshipped Balance | O2: Accumulated Exports
C3: curr | D3: last | E3: curr | F3: last | G3: curr | H3: last | I3: % change | J3: Year | K3: Exports | L3: Exports | M3: 2006 | N3: 2005 | O3: 2006 | P3: 2005
A4: 38855 | B4: Japan | C4: 2813.3 | D4: 1802.1 | E4: 11550.4 | F4: 11374.6 | G4: =+C4+E4 -> 14363.7 | H4: =+D4+F4 -> 13176.7 | I4: =(G4/H4-1)*100 -> 9.0083253
A5: 38862 | B5: =+B4 -> Japan | C5: 2824.7 | D5: 1815.9 | E5: 11938.3 | F5: 11744.1 | G5: =+C5+E5 -> 14763 | H5: =+D5+F5 -> 13560 | I5: =(G5/H5-1)*100 -> 8.8716814 | J5: 283
A6: 38869 | B6: =+B5 -> Japan | C6: 2792.6 | D6: 1707.8 | E6: 12202.3 | F6: 12016.8 | G6: =+C6+E6 -> 14994.9 | H6: =+D6+F6 -> 13724.6 | I6: =(G6/H6-1)*100 -> 9.2556432 | J6: 274.6
A7: 38876 | B7: =+B6 -> Japan | C7: 3004 | D7: 1741.5 | E7: 12556.7 | F7: 12359.6 | G7: =+C7+E7 -> 15560.7 | H7: =+D7+F7 -> 14101.1 | I7: =(G7/H7-1)*100 -> 10.350966 | J7: 332.6
A8: 38883 | B8: =+B7 -> Japan | C8: 3031.1 | D8: 1513.4 | E8: 12844.1 | F8: 12754.4 | G8: =+C8+E8 -> 15875.2 | H8: =+D8+F8 -> 14267.8 | I8: =(G8/H8-1)*100 -> 11.265927 | J8: 466.7
A9: 38890 | B9: =+B8 -> Japan | C9: 2949.5 | D9: 1497.1 | E9: 13126.9 | F9: 13122.8 | G9: =+C9+E9 -> 16076.4 | H9: =+D9+F9 -> 14619.9 | I9: =(G9/H9-1)*100 -> 9.9624484 | J9: 745.7
A10: 38897 | B10: =+B9 -> Japan | C10: 2961.6 | D10: 1490.3 | E10: 13331.8 | F10: 13456.7 | G10: =+C10+E10 -> 16293.4 | H10: =+D10+F10 -> 14947 | I10: =(G10/H10-1)*100 -> 9.0078277 | J10: 1110.6
A11: 38904 | B11: =+B10 -> Japan | C11: 2721.1 | D11: 1578.9 | E11: 13694.2 | F11: 13583.6 | G11: =+C11+E11 -> 16415.3 | H11: =+D11+F11 -> 15162.5 | I11: =(G11/H11-1)*100 -> 8.2624897 | J11: 1112
A12: 38911 | B12: =+B11 -> Japan | C12: 2500.7 | D12: 1607.4 | E12: 13960.7 | F12: 13842 | G12: =+C12+E12 -> 16461.4 | H12: =+D12+F12 -> 15449.4 | I12: =(G12/H12-1)*100 -> 6.5504162 | J12: 1261.6
A13: 38918 | B13: =+B12 -> Japan | C13: 2281.3 | D13: 1552.8 | E13: 14358.8 | F13: 14144.5 | G13: =+C13+E13 -> 16640.1 | H13: =+D13+F13 -> 15697.3 | I13: =(G13/H13-1)*100 -> 6.0061284 | J13: 1300.2
A14: 38925 | B14: =+B13 -> Japan | C14: 1968.2 | D14: 1445.5 | E14: 14807.1 | F14: 14319.1 | G14: =+C14+E14 -> 16775.3 | H14: =+D14+F14 -> 15764.6 | I14: =(G14/H14-1)*100 -> 6.4111998 | J14: 1654.2
A15: 38932 | B15: =+B14 -> Japan | C15: 1923.6 | D15: 1274.3 | E15: 15107.7 | F15: 14816.5 | G15: =+C15+E15 -> 17031.3 | H15: =+D15+F15 -> 16090.8 | I15: =(G15/H15-1)*100 -> 5.8449549 | J15: 1909.7
A16: 38939 | B16: =+B15 -> Japan | C16: 1751.2 | D16: 996.5 | E16: 15374.6 | F16: 15242.6 | G16: =+C16+E16 -> 17125.8 | H16: =+D16+F16 -> 16239.1 | I16: =(G16/H16-1)*100 -> 5.460278 | J16: 2326.2
... A19: 38960 | B19: =+B18 -> Japan | C19: 447 | D19: 603.5 | E19: 16473.8 | F19: 15829.6 | G19: =+C19+E19 -> 16920.8 | H19: =+D19+F19 -> 16433.1 | I19: =(G19/H19-1)*100 -> 2.9677906 | J19: 4070.9
A20: 38967 | B20: =+B19 -> Japan | C20: 3972.9 | D20: 2495.8 | E20: 153 | F20: 37.2 | G20: =+C20+E20 -> 4125.9 | H20: =+D20+F20 -> 2533 | I20: =(G20/H20-1)*100 -> 62.885906
A21: 38974 | B21: =+B20 -> Japan | C21: 3473.1 | D21: 2337 | E21: 743.3 | F21: 365.6 | G21: =+C21+E21 -> 4216.4 | H21: =+D21+F21 -> 2702.6 | I21: =(G21/H21-1)*100 -> 56.012728
A22: 38981 | B22: =+B21 -> Japan | C22: 3433.5 | D22: 2248.3 | E22: 1071.8 | F22: 679.1 | G22: =+C22+E22 -> 4505.3 | H22: =+D22+F22 -> 2927.4 | I22: =(G22/H22-1)*100 -> 53.901073
A23: 38988 | B23: =+B22 -> Japan | C23: 3375.6 | D23: 2664 | E23: 1315 | F23: 860.1 | G23: =+C23+E23 -> 4690.6 | H23: =+D23+F23 -> 3524.1 | I23: =(G23/H23-1)*100 -> 33.10065
A24: 38995 | B24: =+B23 -> Japan | C24: 3759.9 | D24: 2692.8 | E24: 1710.4 | F24: 1240.5 | G24: =+C24+E24 -> 5470.3 | H24: =+D24+F24 -> 3933.3 | I24: =(G24/H24-1)*100 -> 39.076602
A25: 39002 | B25: =+B24 -> Japan | C25: 3884.4 | D25: 2704.2 | E25: 1868.6 | F25: 1638.8 | G25: =+C25+E25 -> 5753 | H25: =+D25+F25 -> 4343 | I25: =(G25/H25-1)*100 -> 32.466037
A26: 39009 | B26: =+B25 -> Japan | C26: 4036.4 | D26: 2330 | E26: 2107.7 | F26: 2130.9 | G26: =+C26+E26 -> 6144.1 | H26: =+D26+F26 -> 4460.9 | I26: =(G26/H26-1)*100 -> 37.732296
A27: 39016 | B27: =+B26 -> Japan | C27: 3928.8 | D27: 2449.7 | E27: 2468.8 | F27: 2414.9 | G27: =+C27+E27 -> 6397.6 | H27: =+D27+F27 -> 4864.6 | I27: =(G27/H27-1)*100 -> 31.513382
A28: 39023 | B28: =+B27 -> Japan | C28: 4062 | D28: 2261.6 | E28: 2670.8 | F28: 2778.4 | G28: =+C28+E28 -> 6732.8 | H28: =+D28+F28 -> 5040 | I28: =(G28/H28-1)*100 -> 33.587302
A29: 39030 | B29: =+B28 -> Japan | C29: 4166.6 | D29: 2171.5 | E29: 2911.7 | F29: 3142.1 | G29: =+C29+E29 -> 7078.3 | H29: =+D29+F29 -> 5313.6 | I29: =(G29/H29-1)*100 -> 33.211006
A30: 39037 | B30: =+B29 -> Japan | C30: 3937.3 | D30: 2217.1 | E30: 3293 | F30: 3489.2 | G30: =+C30+E30 -> 7230.3 | H30: =+D30+F30 -> 5706.3 | I30: =(G30/H30-1)*100 -> 26.707323
A31: 39044 | B31: =+B30 -> Japan | C31: 3890.8 | D31: 2381 | E31: 3497.8 | F31: 3651.3 | G31: =+C31+E31 -> 7388.6 | H31: =+D31+F31 -> 6032.3 | I31: =(G31/H31-1)*100 -> 22.483961
... A34: 39065 | B34: =+B33 -> Japan | C34: 3518.2 | D34: 2741.3 | E34: 4395.1 | F34: 4572.8 | G34: =+C34+E34 -> 7913.3 | H34: =+D34+F34 -> 7314.1 | I34: =(G34/H34-1)*100 -> 8.1923955
A35: 39072 | B35: =+B34 -> Japan | C35: 3299.1 | D35: 2641.8 | E35: 4717.9 | F35: 4707.4 | G35: =+C35+E35 -> 8017 | H35: =+D35+F35 -> 7349.2 | I35: =(G35/H35-1)*100 -> 9.0867033 | J35: 60
A36: 39079 | B36: =+B35 -> Japan | C36: 3110.7 | D36: 2414.8 | E36: 5058.3 | F36: 5050.1 | G36: =+C36+E36 -> 8169 | H36: =+D36+F36 -> 7464.9 | I36: =(G36/H36-1)*100 -> 9.4321424
A37: 39086 | B37: =+B36 -> Japan | C37: 3224.7 | D37: 2365 | E37: 5289 | F37: 5250.5 | G37: =+C37+E37 -> 8513.7 | H37: =+D37+F37 -> 7615.5 | I37: =(G37/H37-1)*100 -> 11.794367
A38: 39093 | B38: =+B37 -> Japan | C38: 3741.2 | D38: 2140.8 | E38: 5370.8 | F38: 5728 | G38: =+C38+E38 -> 9112 | H38: =+D38+F38 -> 7868.8 | I38: =(G38/H38-1)*100 -> 15.799105
A39: 39100 | B39: =+B38 -> Japan | C39: 3843.6 | D39: 2456.1 | E39: 5782.1 | F39: 6136 | G39: =+C39+E39 -> 9625.7 | H39: =+D39+F39 -> 8592.1 | I39: =(G39/H39-1)*100 -> 12.029655
A40: 39107 | B40: =+B39 -> Japan | C40: 3928.7 | D40: 2565.8 | E40: 6013.8 | F40: 6392.4 | G40: =+C40+E40 -> 9942.5 | H40: =+D40+F40 -> 8958.2 | I40: =(G40/H40-1)*100 -> 10.987698
A41: 39114 | B41: =+B40 -> Japan | C41: 3793.9 | D41: 2969.9 | E41: 6458.2 | F41: 6713.5 | G41: =+C41+E41 -> 10252.1 | H41: =+D41+F41 -> 9683.4 | I41: =(G41/H41-1)*100 -> 5.8729372
A42: 39121 | B42: =+B41 -> Japan | C42: 4317.3 | D42: 3052.7 | E42: 6619.2 | F42: 7054.9 | G42: =+C42+E42 -> 10936.5 | H42: =+D42+F42 -> 10107.6 | I42: =(G42/H42-1)*100 -> 8.2007598
A43: 39128 | B43: =+B42 -> Japan | C43: 4135 | D43: 2922.5 | E43: 6843.4 | F43: 7499.2 | G43: =+C43+E43 -> 10978.4 | H43: =+D43+F43 -> 10421.7 | I43: =(G43/H43-1)*100 -> 5.3417389
A44: 39135 | B44: =+B43 -> Japan | C44: 3940.7 | D44: 3036.3 | E44: 7141.9 | F44: 7580.1 | G44: =+C44+E44 -> 11082.6 | H44: =+D44+F44 -> 10616.4 | I44: =(G44/H44-1)*100 -> 4.3913191
...

Sheet Mexico
B1: Corn by Destination Export Sales as of: | AM1: =+#REF!/#REF! -> #REF! | AN1: =+#REF!/#REF! -> #REF! | AO1: =+#REF!/#REF! -> #REF! | AP1: =+#REF!/#REF! -> #REF! | AQ1: =+#REF!/#REF! -> #REF! | AR1: =+#REF!/#REF! -> #REF! | AS1: =+#REF!/#REF! -> #REF!
C2: Unshipped Balance | E2: Accumulated Exports | G2: Total Commitments | I2: from last yr | J2: Next
C3: curr | D3: last | E3: curr | F3: last | G3: curr | H3: last | I3: % change | J3: Marketing Year
A4: =Japan!A4 -> 38855 | B4: Mexico | C4: 847 | D4: 697 | E4: 4948 | F4: 4578.5 | G4: =+C4+E4 -> 5795 | H4: =+D4+F4 -> 5275.5 | I4: =+(G4/H4-1)*100 -> 9.8474078
A5: =Japan!A5 -> 38862 | B5: Mexico | C5: 790.6 | D5: 631.5 | E5: 5114 | F5: 4648.7 | G5: =+C5+E5 -> 5904.6 | H5: =+D5+F5 -> 5280.2 | I5: =+(G5/H5-1)*100 -> 11.82531 | J5: 116.8
A6: =Japan!A6 -> 38869 | B6: Mexico | C6: 730.9 | D6: 692.3 | E6: 5272.7 | F6: 4746.8 | G6: =+C6+E6 -> 6003.6 | H6: =+D6+F6 -> 5439.1 | I6: =+(G6/H6-1)*100 -> 10.378555 | J6: 116.8
A7: =Japan!A7 -> 38876 | B7: Mexico | C7: 746.6 | D7: 682.2 | E7: 5397.4 | F7: 4848.3 | G7: =+C7+E7 -> 6144 | H7: =+D7+F7 -> 5530.5 | I7: =+(G7/H7-1)*100 -> 11.09303 | J7: 116.8
A8: =Japan!A8 -> 38883 | B8: Mexico | C8: 768.7 | D8: 617.8 | E8: 5562.3 | F8: 5003.7 | G8: =+C8+E8 -> 6331 | H8: =+D8+F8 -> 5621.5 | I8: =+(G8/H8-1)*100 -> 12.621187 | J8: 116.8
A9: =Japan!A9 -> 38890 | B9: Mexico | C9: 820.1 | D9: 654.2 | E9: 5623.1 | F9: 5049.6 | G9: =+C9+E9 -> 6443.2 | H9: =+D9+F9 -> 5703.8 | I9: =+(G9/H9-1)*100 -> 12.963288 | J9: 242.8
A10: =Japan!A10 -> 38897 | B10: Mexico | C10: 891.4 | D10: 643.9 | E10: 5701.1 | F10: 5106.6 | G10: =+C10+E10 -> 6592.5 | H10: =+D10+F10 -> 5750.5 | I10: =+(G10/H10-1)*100 -> 14.642205 | J10: 274.8
A11: =Japan!A11 -> 38904 | B11: Mexico | C11: 905.7 | D11: 516.4 | E11: 5770.1 | F11: 5219.9 | G11: =+C11+E11 -> 6675.8 | H11: =+D11+F11 -> 5736.3 | I11: =+(G11/H11-1)*100 -> 16.378153 | J11: 274.8
A12: =Japan!A12 -> 38911 | B12: Mexico | C12: 789.1 | D12: 552.3 | E12: 5896.9 | F12: 5248.4 | G12: =+C12+E12 -> 6686 | H12: =+D12+F12 -> 5800.7 | I12: =+(G12/H12-1)*100 -> 15.261951 | J12: 311.8
A13: =Japan!A13 -> 38918 | B13: Mexico | C13: 887.2 | D13: 565.5 | E13: 5953.5 | F13: 5271.6 | G13: =+C13+E13 -> 6840.7 | H13: =+D13+F13 -> 5837.1 | I13: =+(G13/H13-1)*100 -> 17.193469 | J13: 311.8
A14: =Japan!A14 -> 38925 | B14: Mexico | C14: 1058.2 | D14: 513.3 | E14: 5990.2 | F14: 5368.6 | G14: =+C14+E14 -> 7048.4 | H14: =+D14+F14 -> 5881.9 | I14: =+(G14/H14-1)*100 -> 19.832027 | J14: 372.3
A15: =Japan!A15 -> 38932 | B15: Mexico | C15: 1000.9 | D15: 581.8 | E15: 6143.8 | F15: 5460.8 | G15: =+C15+E15 -> 7144.7 | H15: =+D15+F15 -> 6042.6 | I15: =+(G15/H15-1)*100 -> 18.238838 | J15: 393.3
A16: =Japan!A16 -> 38939 | B16: Mexico | C16: 851.8 | D16: 702.3 | E16: 6230.5 | F16: 5528 | G16: =+C16+E16 -> 7082.3 | H16: =+D16+F16 -> 6230.3 | I16: =+(G16/H16-1)*100 -> 13.675104 | J16: 663.8
A17: =Japan!A17 -> 38946 | B17: Mexico | C17: 896 | D17: 710.1 | E17: 6319.9 | F17: 5619.5 | G17: =+C17+E17 -> 7215.9 | H17: =+D17+F17 -> 6329.6 | I17: =+(G17/H17-1)*100 -> 14.002465 | J17: 909.3
A18: =+A17+7 -> 38953 | B18: Mexico | C18: 455.6 | D18: 600.2 | E18: 6550.2 | F18: 5691.7 | G18: =+C18+E18 -> 7005.8 | H18: =+D18+F18 -> 6291.9 | I18: =+(G18/H18-1)*100 -> 11.346334 | J18: 1414.6
A19: =+A18+7 -> 38960 | B19: Mexico | C19: 382.9 | D19: 516.7 | E19: 6653.1 | F19: 5761.5 | G19: =+C19+E19 -> 7036 | H19: =+D19+F19 -> 6278.2 | I19: =+(G19/H19-1)*100 -> 12.070339 | J19: 1932.5
A20: =+A19+7 -> 38967 | B20: Mexico | C20: 1800.8 | D20: 1402.3 | E20: 225.1 | F20: 69.3 | G20: =+C20+E20 -> 2025.9 | H20: =+D20+F20 -> 1471.6 | I20: =+(G20/H20-1)*100 -> 37.666485
A21: =+A20+7 -> 38974 | B21: Mexico | C21: 2019.9 | D21: 1451.8 | E21: 416.5 | F21: 267.8 | G21: =+C21+E21 -> 2436.4 | H21: =+D21+F21 -> 1719.6 | I21: =+(G21/H21-1)*100 -> 41.684113
A22: =+A21+7 -> 38981 | B22: Mexico | C22: 1917.1 | D22: 1456.2 | E22: 619.3 | F22: 385.3 | G22: =+C22+E22 -> 2536.4 | H22: =+D22+F22 -> 1841.5 | I22: =+(G22/H22-1)*100 -> 37.735542
A23: =+A22+7 -> 38988 | B23: Mexico | C23: 2013.2 | D23: 1437.2 | E23: 856.5 | F23: 497.2 | G23: =+C23+E23 -> 2869.7 | H23: =+D23+F23 -> 1934.4 | I23: =+(G23/H23-1)*100 -> 48.35091
A24: =+A23+7 -> 38995 | B24: Mexico | C24: 1953.3 | D24: 1372.8 | E24: 1109.9 | F24: 589.1 | G24: =+C24+E24 -> 3063.2 | H24: =+D24+F24 -> 1961.9 | I24: =+(G24/H24-1)*100 -> 56.13436
A25: =+A24+7 -> 39002 | B25: Mexico | C25: 1924.7 | D25: 1239.9 | E25: 1254.9 | F25: 762.8 | G25: =+C25+E25 -> 3179.6 | H25: =+D25+F25 -> 2002.7 | I25: =+(G25/H25-1)*100 -> 58.765666
A26: =+A25+7 -> 39009 | B26: Mexico | C26: 2202.4 | D26: 1244.2 | E26: 1410.2 | F26: 867.6 | G26: =+C26+E26 -> 3612.6 | H26: =+D26+F26 -> 2111.8 | I26: =+(G26/H26-1)*100 -> 71.067336
A27: =+A26+7 -> 39016 | B27: Mexico | C27: 2146.6 | D27: 1299.4 | E27: 1623.1 | F27: 1012.4 | G27: =+C27+E27 -> 3769.7 | H27: =+D27+F27 -> 2311.8 | I27: =+(G27/H27-1)*100 -> 63.063414
A28: =+A27+7 -> 39023 | B28: Mexico | C28: 2202.2 | D28: 1293.1 | E28: 1871.7 | F28: 1159.1 | G28: =+C28+E28 -> 4073.9 | H28: =+D28+F28 -> 2452.2 | I28: =+(G28/H28-1)*100 -> 66.132452
A29: =+A28+7 -> 39030 | B29: Mexico | C29: 2226.7 | D29: 1299.3 | E29: 2102.1 | F29: 1343 | G29: =+C29+E29 -> 4328.8 | H29: =+D29+F29 -> 2642.3 | I29: =+(G29/H29-1)*100 -> 63.826969
A30: =+A29+7 -> 39037 | B30: Mexico | C30: 2121.2 | D30: 1310 | E30: 2328.6 | F30: 1487.1 | G30: =+C30+E30 -> 4449.8 | H30: =+D30+F30 -> 2797.1 | I30: =+(G30/H30-1)*100 -> 59.086196
A31: =+A30+7 -> 39044 | B31: Mexico | C31: 2066.9 | D31: 1211.5 | E31: 2489.1 | F31: 1601 | G31: =+C31+E31 -> 4556 | H31: =+D31+F31 -> 2812.5 | I31: =+(G31/H31-1)*100 -> 61.991111
... A54: =+A53+7 -> 39205 | B54: Mexico | C54: 2545.2 | D54: 835.6 | E54: 6833.5 | F54: 4746.4 | G54: =+C54+E54 -> 9378.7 | H54: =+D54+F54 -> 5582 | I54: =+(G54/H54-1)*100 -> 68.01684
A55: =+A54+7 -> 39212 | B55: Mexico | C55: 2357.6 | D55: 910.9 | E55: 7064.3 | F55: 4822.2 | G55: =+C55+E55 -> 9421.9 | H55: =+D55+F55 -> 5733.1 | I55: =+(G55/H55-1)*100 -> 64.342153 | J55: 555.7
A56: =+A55+7 -> 39219 | B56: Mexico | C56: 2054.4 | D56: 847 | E56: 7234.8 | F56: 4948 | G56: =+C56+E56 -> 9289.2 | H56: =+D56+F56 -> 5795 | I56: =+(G56/H56-1)*100 -> 60.296808 | J56: 692.6
A57: =+A56+7 -> 39226 | B57: Mexico | C57: 1851 | D57: 790.6 | E57: 7491.1 | F57: 5114 | G57: =+C57+E57 -> 9342.1 | H57: =+D57+F57 -> 5904.6 | I57: =+(G57/H57-1)*100 -> 58.217322 | J57: 692.6
A58: =+A57+7 -> 39233 | B58: Mexico | C58: 1628.6 | D58: 730.9 | E58: 7721.4 | F58: 5272.7 | G58: =+C58+E58 -> 9350 | H58: =+D58+F58 -> 6003.6 | I58: =+(G58/H58-1)*100 -> 55.739889 | J58: 719.6
A59: =+A58+7 -> 39240 | B59: Mexico | C59: 1657.8 | D59: 746.6 | E59: 7784.5 | F59: 5397.4 | G59: =+C59+E59 -> 9442.3 | H59: =+D59+F59 -> 6144 | I59: =+(G59/H59-1)*100 -> 53.683268 | J59: 719.6
A60: =+A59+7 -> 39247 | B60: Mexico | C60: 1639.8 | D60: 768.7 | E60: 7858.9 | F60: 5562.3 | G60: =+C60+E60 -> 9498.7 | H60: =+D60+F60 -> 6331 | I60: =+(G60/H60-1)*100 -> 50.03475 | J60: 839.6
A61: =+A60+7 -> 39254 | B61: Mexico | C61: 1494.2 | D61: 820.1 | E61: 7937.2 | F61: 5623.1 | G61: =+C61+E61 -> 9431.4 | H61: =+D61+F61 -> 6443.2 | I61: =+(G61/H61-1)*100 -> 46.377576 | J61: 859.6
A62: =+A61+7 -> 39261 | B62: Mexico | C62: 1512.8 | D62: 891.4 | E62: 8067.1 | F62: 5701.1 | G62: =+C62+E62 -> 9579.9 | H62: =+D62+F62 -> 6592.5 | I62: =+(G62/H62-1)*100 -> 45.315131 | J62: 1045.3
...

Sheet Korea
B1: Corn by Destination Export Sales as of:
C2: Unshipped Balance | E2: Accumulated Exports | G2: Total Commitments | I2: from last yr
C3: 2013 | D3: 2012 | E3: 2013 | F3: 2012 | G3: 2013 | H3: 2012 | I3: % change | J3: Next Crop year
A4: Korea | B4: =+Taiwan!A4 -> 38855 | C4: 724.1 | D4: 58.2 | E4: 3292.5 | F4: 1372.6 | G4: =+C4+E4 -> 4016.6 | H4: =+D4+F4 -> 1430.8 | I4: =+(G4/H4-1)*100 -> 180.72407
A5: Korea | B5: =+Taiwan!A5 -> 38862 | C5: 635 | D5: 110.2 | E5: 3443.2 | F5: 1372.6 | G5: =+C5+E5 -> 4078.2 | H5: =+D5+F5 -> 1482.8 | I5: =+(G5/H5-1)*100 -> 175.03372 | J5: 1.2
A6: Korea | B6: =+Taiwan!A6 -> 38869 | C6: 680.7 | D6: 110.6 | E6: 3560.6 | F6: 1373.4 | G6: =+C6+E6 -> 4241.3 | H6: =+D6+F6 -> 1484 | I6: =+(G6/H6-1)*100 -> 185.80189 | J6: 56.2 | K6: (Canceled sales?)
A7: Korea | B7: =+Taiwan!A7 -> 38876 | C7: 813.5 | D7: 121.8 | E7: 3621.1 | F7: 1373.4 | G7: =+C7+E7 -> 4434.6 | H7: =+D7+F7 -> 1495.2 | I7: =+(G7/H7-1)*100 -> 196.58909 | J7: 1.2
A8: Korea | B8: =+Taiwan!A8 -> 38883 | C8: 1077.3 | D8: 121.1 | E8: 3736.6 | F8: 1431.6 | G8: =+C8+E8 -> 4813.9 | H8: =+D8+F8 -> 1552.7 | I8: =+(G8/H8-1)*100 -> 210.03413 | J8: 1.2
A9: Korea | B9: =+Taiwan!A9 -> 38890 | C9: 986.1 | D9: 239.4 | E9: 3996.1 | F9: 1432.3 | G9: =+C9+E9 -> 4982.2 | H9: =+D9+F9 -> 1671.7 | I9: =+(G9/H9-1)*100 -> 198.03194 | J9: 1.2
A10: Korea | B10: =+Taiwan!A10 -> 38897 | C10: 800.4 | D10: 274.3 | E10: 4205.6 | F10: 1512.8 | G10: =+C10+E10 -> 5006 | H10: =+D10+F10 -> 1787.1 | I10: =+(G10/H10-1)*100 -> 180.11863 | J10: 1.2
A11: Korea | B11: =+Taiwan!A11 -> 38904 | C11: 765.9 | D11: 261.8 | E11: 4210.7 | F11: 1572.2 | G11: =+C11+E11 -> 4976.6 | H11: =+D11+F11 -> 1834 | I11: =+(G11/H11-1)*100 -> 171.35224 | J11: 1.2
A12: Korea | B12: =+Taiwan!A12 -> 38911 | C12: 617.9 | D12: 173.5 | E12: 4421.4 | F12: 1663.5 | G12: =+C12+E12 -> 5039.3 | H12: =+D12+F12 -> 1837 | I12: =+(G12/H12-1)*100 -> 174.32226 | J12: 1.2
A13: Korea | B13: =+Taiwan!A13 -> 38918 | C13: 517.7 | D13: 173.7 | E13: 4527 | F13: 1721.3 | G13: =+C13+E13 -> 5044.7 | H13: =+D13+F13 -> 1895 | I13: =+(G13/H13-1)*100 -> 166.21108 | J13: 59.2
A14: Korea | B14: =+Taiwan!A14 -> 38925 | C14: 475.7 | D14: 181 | E14: 4675.3 | F14: 1779 | G14: =+C14+E14 -> 5151 | H14: =+D14+F14 -> 1960 | I14: =+(G14/H14-1)*100 -> 162.80612 | J14: 230.7
A15: Korea | B15: =+Taiwan!A15 -> 38932 | C15: 541.4 | D15: 237.5 | E15: 4895.7 | F15: 1836.7 | G15: =+C15+E15 -> 5437.1 | H15: =+D15+F15 -> 2074.2 | I15: =+(G15/H15-1)*100 -> 162.12998 | J15: 230.7
A16: Korea | B16: =+Taiwan!A16 -> 38939 | C16: 541.6 | D16: 284.4 | E16: 5069.3 | F16: 1836.8 | G16: =+C16+E16 -> 5610.9 | H16: =+D16+F16 -> 2121.2 | I16: =+(G16/H16-1)*100 -> 164.51537 | J16: 230.7
A17: Korea | B17: =+Taiwan!A17 -> 38946 | C17: 596.6 | D17: 286.1 | E17: 5069.3 | F17: 1926.7 | G17: =+C17+E17 -> 5665.9 | H17: =+D17+F17 -> 2212.8 | I17: =+(G17/H17-1)*100 -> 156.05116 | J17: 390.5
A18: Korea | B18: =+Taiwan!A18 -> 38953 | C18: 323 | D18: 228.6 | E18: 5239.2 | F18: 1981.8 | G18: =+C18+E18 -> 5562.2 | H18: =+D18+F18 -> 2210.4 | I18: =+(G18/H18-1)*100 -> 151.63771 | J18: 551.3
A19: Korea | B19: =+Taiwan!A19 -> 38960 | C19: 62.4 | D19: 169.8 | E19: 5572.9 | F19: 2098.5 | G19: =+C19+E19 -> 5635.3 | H19: =+D19+F19 -> 2268.3 | I19: =+(G19/H19-1)*100 -> 148.43716 | J19: 727.5
A20: Korea | B20: =+Taiwan!A20 -> 38967 | C20: 669.2 | D20: 586.3 | E20: 175.4 | F20: 0 | G20: =+C20+E20 -> 844.6 | H20: =+D20+F20 -> 586.3 | I20: =+(G20/H20-1)*100 -> 44.055944
A21: Korea | B21: =+Taiwan!A21 -> 38974 | C21: 672.6 | D21: 528.3 | E21: 339.6 | F21: 58.4 | G21: =+C21+E21 -> 1012.2 | H21: =+D21+F21 -> 586.7 | I21: =+(G21/H21-1)*100 -> 72.524288
A22: Korea | B22: =+Taiwan!A22 -> 38981 | C22: 500.2 | D22: 418.3 | E22: 454.6 | F22: 169.5 | G22: =+C22+E22 -> 954.8 | H22: =+D22+F22 -> 587.8 | I22: =+(G22/H22-1)*100 -> 62.436203
A23: Korea | B23: =+Taiwan!A23 -> 38988 | C23: 387 | D23: 398.3 | E23: 618.8 | F23: 341.1 | G23: =+C23+E23 -> 1005.8 | H23: =+D23+F23 -> 739.4 | I23: =+(G23/H23-1)*100 -> 36.029213
A24: Korea | B24: =+Taiwan!A24 -> 38995 | C24: 444.9 | D24: 287.8 | E24: 618.8 | F24: 456.4 | G24: =+C24+E24 -> 1063.7 | H24: =+D24+F24 -> 744.2 | I24: =+(G24/H24-1)*100 -> 42.932008
A25: Korea | B25: =+Taiwan!A25 -> 39002 | C25: 444.9 | D25: 232.8 | E25: 665.3 | F25: 456.6 | G25: =+C25+E25 -> 1110.2 | H25: =+D25+F25 -> 689.4 | I25: =+(G25/H25-1)*100 -> 61.038584
A26: Korea | B26: =+Taiwan!A26 -> 39009 | C26: 445 | D26: 215.7 | E26: 665.8 | F26: 515.8 | G26: =+C26+E26 -> 1110.8 | H26: =+D26+F26 -> 731.5 | I26: =+(G26/H26-1)*100 -> 51.852358
A27: Korea | B27: =+Taiwan!A27 -> 39016 | C27: 499.9 | D27: 218.7 | E27: 666.2 | F27: 572.8 | G27: =+C27+E27 -> 1166.1 | H27: =+D27+F27 -> 791.5 | I27: =+(G27/H27-1)*100 -> 47.327858
A28: Korea | B28: =+Taiwan!A28 -> 39023 | C28: 618.7 | D28: 243.1 | E28: 781.9 | F28: 605.1 | G28: =+C28+E28 -> 1400.6 | H28: =+D28+F28 -> 848.2 | I28: =+(G28/H28-1)*100 -> 65.126149
A29: Korea | B29: =+Taiwan!A29 -> 39030 | C29: 645.3 | D29: 244.7 | E29: 874.5 | F29: 661.5 | G29: =+C29+E29 -> 1519.8 | H29: =+D29+F29 -> 906.2 | I29: =+(G29/H29-1)*100 -> 67.711322
A30: Korea | B30: =+Taiwan!A30 -> 39037 | C30: 534.7 | D30: 245 | E30: 990.1 | F30: 714.6 | G30: =+C30+E30 -> 1524.8 | H30: =+D30+F30 -> 959.6 | I30: =+(G30/H30-1)*100 -> 58.899541
A31: Korea | B31: =+Taiwan!A31 -> 39044 | C31: 647.5 | D31: 245 | E31: 990.3 | F31: 774.5 | G31: =+C31+E31 -> 1637.8 | H31: =+D31+F31 -> 1019.5 | I31: =+(G31/H31-1)*100 -> 60.647376
A32: Korea | B32: =+B31+7 -> 39051 | C32: 700.8 | D32: 199 | E32: 1104.9 | F32: 774.5 | G32: =+C32+E32 -> 1805.7 | H32: =+D32+F32 -> 973.5 | I32: =+(G32/H32-1)*100 -> 85.485362
A33: Korea | B33: =+B32+7 -> 39058 | C33: 920.1 | D33: 233.9 | E33: 1105.6 | F33: 774.5 | G33: =+C33+E33 -> 2025.7 | H33: =+D33+F33 -> 1008.4 | I33: =+(G33/H33-1)*100 -> 100.88259
A34: Korea | B34: =+B33+7 -> 39065 | C34: 1038.2 | D34: 288.8 | E34: 1211.3 | F34: 832.8 | G34: =+C34+E34 -> 2249.5 | H34: =+D34+F34 -> 1121.6 | I34: =+(G34/H34-1)*100 -> 100.5617
A35: Korea | B35: =+B34+7 -> 39072 | C35: 954 | D35: 230.6 | E35: 1325.5 | F35: 833 | G35: =+C35+E35 -> 2279.5 | H35: =+D35+F35 -> 1063.6 | I35: =+(G35/H35-1)*100 -> 114.31929
A36: Korea | B36: =+B35+7 -> 39079 | C36: 1009 | D36: 254.6 | E36: 1325.5 | F36: 865.8 | G36: =+C36+E36 -> 2334.5 | H36: =+D36+F36 -> 1120.4 | I36: =+(G36/H36-1)*100 -> 108.36308
A37: Korea | B37: =+B36+7 -> 39086 | C37: 1008.9 | D37: 199.6 | E37: 1325.6 | F37: 1040.4 | G37: =+C37+E37 -> 2334.5 | H37: =+D37+F37 -> 1240 | I37: =+(G37/H37-1)*100 -> 88.266129
A38: Korea | B38: =+B37+7 -> 39093 | C38: 898.7 | D38: 253.9 | E38: 1382.7 | F38: 1059.4 | G38: =+C38+E38 -> 2281.4 | H38: =+D38+F38 -> 1313.3 | I38: =+(G38/H38-1)*100 -> 73.715069
A39: Korea | B39: =+B38+7 -> 39100 | C39: 898.7 | D39: 538.9 | E39: 1382.7 | F39: 1059.4 | G39: =+C39+E39 -> 2281.4 | H39: =+D39+F39 -> 1598.3 | I39: =+(G39/H39-1)*100 -> 42.73916
A40: Korea | B40: =+B39+7 -> 39107 | C40: 840.4 | D40: 627.9 | E40: 1498.5 | F40: 1090.4 | G40: =+C40+E40 -> 2338.9 | H40: =+D40+F40 -> 1718.3 | I40: =+(G40/H40-1)*100 -> 36.117092
...

Sheet China
B1: Corn by Destination Export Sales as of:
C2: Unshipped Balance | E2: Accumulated Exports | G2: Total Commitments | I2: from last yr | J2: next
C3: curr | D3: last | E3: curr | F3: last | G3: curr | H3: last | I3: % change | J3: crop year
A4: 40976 | B4: China | C4: 1029.2 | D4: 0 | E4: 2764.9 | F4: 313.7 | G4: =+C4+E4 -> 3794.1 | H4: =+D4+F4 -> 313.7 | I4: =+(G4/H4-1)*100 -> 1109.4676
A5: =+A4+7 -> 40983 | B5: China | C5: 1032.7 | D5: 0 | E5: 2764.9 | F5: 313.7 | G5: =+C5+E5 -> 3797.6 | H5: =+D5+F5 -> 313.7 | I5: =+(G5/H5-1)*100 -> 1110.5834
A6: =+A5+7 -> 40990 | B6: China | C6: 1037.2 | D6: 0 | E6: 2765.4 | F6: 313.7 | G6: =+C6+E6 -> 3802.6 | H6: =+D6+F6 -> 313.7 | I6: =+(G6/H6-1)*100 -> 1112.1772
A7: =+A6+7 -> 40997 | B7: China | C7: 1426.5 | D7: 0 | E7: 2770.2 | F7: 313.7 | G7: =+C7+E7 -> 4196.7 | H7: =+D7+F7 -> 313.7 | I7: =+(G7/H7-1)*100 -> 1237.8068
A8: =+A7+7 -> 41004 | B8: China | C8: 1486.5 | D8: 0 | E8: 2770.2 | F8: 313.7 | G8: =+C8+E8 -> 4256.7 | H8: =+D8+F8 -> 313.7 | I8: =+(G8/H8-1)*100 -> 1256.9334
A9: =+A8+7 -> 41011 | B9: China | C9: 1501.5 | D9: 0.5 | E9: 2770.2 | F9: 313.7 | G9: =+C9+E9 -> 4271.7 | H9: =+D9+F9 -> 314.2 | I9: =+(G9/H9-1)*100 -> 1259.5481
A10: =+A9+7 -> 41018 | B10: China | C10: 1472 | E10: 2837 | F10: 314.1 | G10: =+C10+E10 -> 4309 | H10: =+D10+F10 -> 314.1 | I10: =+(G10/H10-1)*100 -> 1271.8561
A11: =+A10+7 -> 41025 | B11: China | C11: 1686 | E11: 2837 | F11: 314.1 | G11: =+C11+E11 -> 4523 | H11: =+D11+F11 -> 314.1 | I11: =+(G11/H11-1)*100 -> 1339.9873
A12: =+A11+7 -> 41032 | B12: China | C12: 1626 | E12: 2837 | F12: 314.1 | G12: =+C12+E12 -> 4463 | H12: =+D12+F12 -> 314.1 | I12: =+(G12/H12-1)*100 -> 1320.8851 | J12: 172.5
A13: =+A12+7 -> 41039 | B13: China | C13: 1633.2 | E13: 2902.5 | F13: 314.1 | G13: =+C13+E13 -> 4535.7 | H13: =+D13+F13 -> 314.1 | I13: =+(G13/H13-1)*100 -> 1344.0306 | J13: 284.2
A14: =+A13+7 -> 41046 | B14: China | C14: 1820.1 | E14: 2970.6 | F14: 430.9 | G14: =+C14+E14 -> 4790.7 | H14: =+D14+F14 -> 430.9 | I14: =+(G14/H14-1)*100 -> 1011.7893 | J14: 987.8
A15: =+A14+7 -> 41053 | B15: China | C15: 1644.9 | D15: 2 | E15: 3287.7 | F15: 430.9 | G15: =+C15+E15 -> 4932.6 | H15: =+D15+F15 -> 432.9 | I15: =+(G15/H15-1)*100 -> 1039.4317 | J15: 1042.8
A16: =+A15+7 -> 41060 | B16: China | C16: 1452.5 | D16: 0 | E16: 3498.7 | F16: 489.8 | G16: =+C16+E16 -> 4951.2 | H16: =+D16+F16 -> 489.8 | I16: =+(G16/H16-1)*100 -> 910.86158 | J16: 1027.8
A17: =+A16+7 -> 41067 | B17: China | C17: 1446 | D17: 0 | E17: 3569.9 | F17: 555.5 | G17: =+C17+E17 -> 5015.9 | H17: =+D17+F17 -> 555.5 | I17: =+(G17/H17-1)*100 -> 802.9523 | J17: 1041.3
A18: =+A17+7 -> 41074 | B18: China | C18: 1258.2 | D18: 0 | E18: 3777.6 | F18: 555.5 | G18: =+C18+E18 -> 5035.8 | H18: =+D18+F18 -> 555.5 | I18: =+(G18/H18-1)*100 -> 806.53465 | J18: 1041.3
A19: =+A18+7 -> 41081 | B19: China | C19: 1130 | D19: 0 | E19: 3912.3 | F19: 555.5 | G19: =+C19+E19 -> 5042.3 | H19: =+D19+F19 -> 555.5 | I19: =+(G19/H19-1)*100 -> 807.70477 | J19: 1101.3
A20: =+A19+7 -> 41088 | B20: China | C20: 1058.6 | D20: 0 | E20: 4107.6 | F20: 555.5 | G20: =+C20+E20 -> 5166.2 | H20: =+D20+F20 -> 555.5 | I20: =+(G20/H20-1)*100 -> 830.009 | J20: 1101.3
A21: =+A20+7 -> 41095 | B21: China | C21: 1051.1 | D21: 15 | E21: 4115.1 | F21: 615.1 | G21: =+C21+E21 -> 5166.2 | H21: =+D21+F21 -> 630.1 | I21: =+(G21/H21-1)*100 -> 719.9016 | J21: 1101.3
A22: =+A21+7 -> 41102 | B22: China | C22: 951 | D22: 15 | E22: 4240 | F22: 615.1 | G22: =+C22+E22 -> 5191 | H22: =+D22+F22 -> 630.1 | I22: =+(G22/H22-1)*100 -> 723.83749 | J22: 1101.3
A23: =+A22+7 -> 41109 | B23: China | C23: 884.1 | D23: 15 | E23: 4317.7 | F23: 671.3 | G23: =+C23+E23 -> 5201.8 | H23: =+D23+F23 -> 686.3 | I23: =+(G23/H23-1)*100 -> 657.94842 | J23: 861.3
A24: =+A23+7 -> 41116 | B24: China | C24: 745.5 | D24: 11.6 | E24: 4503.8 | F24: 731.4 | G24: =+C24+E24 -> 5249.3 | H24: =+D24+F24 -> 743 | I24: =+(G24/H24-1)*100 -> 606.50067 | J24: 861.3
A25: =+A24+7 -> 41123 | B25: China | C25: 566.6 | D25: 11.6 | E25: 4688 | F25: 792 | G25: =+C25+E25 -> 5254.6 | H25: =+D25+F25 -> 803.6 | I25: =+(G25/H25-1)*100 -> 553.88253 | J25: 800.3
A26: =+A25+7 -> 41130 | B26: China | C26: 364.7 | D26: 5.1 | E26: 4949.1 | F26: 798.4 | G26: =+C26+E26 -> 5313.8 | H26: =+D26+F26 -> 803.5 | I26: =+(G26/H26-1)*100 -> 561.33167 | J26: 800.3
... A29: =+A28+7 -> 41151 | B29: China | C29: 239.8 | D29: 540.9 | E29: 5174.1 | F29: 0 | G29: =+C29+E29 -> 5413.9 | H29: =+D29+F29 -> 540.9 | I29: =+(G29/H29-1)*100 -> 900.9059 | J29: 801.3
A30: =+A29+7 -> 41158 | B30: China | C30: 980.8 | D30: 540.9 | E30: 54.6 | F30: 0 | G30: =+C30+E30 -> 1035.4 | H30: =+D30+F30 -> 540.9 | I30: =+(G30/H30-1)*100 -> 91.421705
A31: =+A30+7 -> 41165 | B31: China | C31: 785.6 | D31: 540.2 | E31: 275.1 | F31: 123.6 | G31: =+C31+E31 -> 1060.7 | H31: =+D31+F31 -> 663.8 | I31: =+(G31/H31-1)*100 -> 59.792106
A32: =+A31+7 -> 41172 | B32: China | C32: 613.1 | D32: 540.2 | E32: 440.3 | F32: 305.7 | G32: =+C32+E32 -> 1053.4 | H32: =+D32+F32 -> 845.9 | I32: =+(G32/H32-1)*100 -> 24.530086
A33: =+A32+7 -> 41179 | B33: China | C33: 493.1 | D33: 540 | E33: 548.4 | F33: 363.7 | G33: =+C33+E33 -> 1041.5 | H33: =+D33+F33 -> 903.7 | I33: =+(G33/H33-1)*100 -> 15.248423
A34: =+A33+7 -> 41186 | B34: China | C34: 433.1 | D34: 540 | E34: 665.7 | F34: 483 | G34: =+C34+E34 -> 1098.8 | H34: =+D34+F34 -> 1023 | I34: =+(G34/H34-1)*100 -> 7.4095797
A35: =+A34+7 -> 41193 | B35: China | C35: 433.1 | D35: 1440.1 | E35: 665.7 | F35: 483 | G35: =+C35+E35 -> 1098.8 | H35: =+D35+F35 -> 1923.1 | I35: =+(G35/H35-1)*100 -> -42.863086
A36: =+A35+7 -> 41200 | B36: China | C36: 311.6 | D36: 1500 | E36: 666.9 | F36: 483.1 | G36: =+C36+E36 -> 978.5 | H36: =+D36+F36 -> 1983.1 | I36: =+(G36/H36-1)*100 -> -50.658061
A37: =+A36+7 -> 41207 | B37: China | C37: 189.8 | D37: 1560 | E37: 727.8 | F37: 483.1 | G37: =+C37+E37 -> 917.6 | H37: =+D37+F37 -> 2043.1 | I37: =+(G37/H37-1)*100 -> -55.087857
A38: =+A37+7 -> 41214 | B38: China | C38: 189.8 | D38: 1554.8 | E38: 782.3 | F38: 607.9 | G38: =+C38+E38 -> 972.1 | H38: =+D38+F38 -> 2162.7 | I38: =+(G38/H38-1)*100 -> -55.051556
A39: =+A38+7 -> 41221 | B39: China | C39: 183.8 | D39: 1551.4 | E39: 836.8 | F39: 671.3 | G39: =+C39+E39 -> 1020.6 | H39: =+D39+F39 -> 2222.7 | I39: =+(G39/H39-1)*100 -> -54.082872
A40: =+A39+7 -> 41228 | B40: China | C40: 183.8 | D40: 1500 | E40: 836.8 | F40: 916.4 | G40: =+C40+E40 -> 1020.6 | H40: =+D40+F40 -> 2416.4 | I40: =+(G40/H40-1)*100 -> -57.763615
A41: =+A40+7 -> 41235 | B41: China | C41: 183.8 | D41: 1440.5 | E41: 894.8 | F41: 976.6 | G41: =+C41+E41 -> 1078.6 | H41: =+D41+F41 -> 2417.1 | I41: =+(G41/H41-1)*100 -> -55.376277
... A51: =+A50+7 -> 41305 | B51: China | C51: 123.8 | D51: 1146 | E51: 1678 | F51: 2507.1 | G51: =+C51+E51 -> 1801.8 | H51: =+D51+F51 -> 3653.1 | I51: =+(G51/H51-1)*100 -> -50.677507
...

Sheet Taiwan
B1: Corn by Destination Export Sales as of:
C2: Unshipped Balance | E2: Accumulated Exports | G2: Total Commitments | I2: from last yr | J2: Weekly
C3: 2013 | D3: 2012 | E3: 2013 | F3: 2012 | G3: 2013 | H3: 2012 | I3: % change | J3: Change
A4: =Japan!A4 -> 38855 | B4: Taiwan | C4: 536.3 | D4: 541.2 | E4: 3747.6 | F4: 3254.3 | G4: =+C4+E4 -> 4283.9 | H4: =+D4+F4 -> 3795.5 | I4: =+(G4/H4-1)*100 -> 12.86787
A5: =Japan!A5 -> 38862 | B5: Taiwan | C5: 710.2 | D5: 539 | E5: 3755.6 | F5: 3323.1 | G5: =+C5+E5 -> 4465.8 | H5: =+D5+F5 -> 3862.1 | I5: =+(G5/H5-1)*100 -> 15.631392 | J5: 0
A6: =Japan!A6 -> 38869 | B6: Taiwan | C6: 637.6 | D6: 510.7 | E6: 3922 | F6: 3469.6 | G6: =+C6+E6 -> 4559.6 | H6: =+D6+F6 -> 3980.3 | I6: =+(G6/H6-1)*100 -> 14.554179 | J6: 0
A7: =Japan!A7 -> 38876 | B7: Taiwan | C7: 695 | D7: 625.9 | E7: 4000.9 | F7: 3473.3 | G7: =+C7+E7 -> 4695.9 | H7: =+D7+F7 -> 4099.2 | I7: =+(G7/H7-1)*100 -> 14.556499 | J7: 0
A8: =Japan!A8 -> 38883 | B8: Taiwan | C8: 784 | D8: 480.1 | E8: 4120.7 | F8: 3624.1 | G8: =+C8+E8 -> 4904.7 | H8: =+D8+F8 -> 4104.2 | I8: =+(G8/H8-1)*100 -> 19.50441 | J8: 0
A9: =Japan!A9 -> 38890 | B9: Taiwan | C9: 739.9 | D9: 479.8 | E9: 4211.8 | F9: 3809.4 | G9: =+C9+E9 -> 4951.7 | H9: =+D9+F9 -> 4289.2 | I9: =+(G9/H9-1)*100 -> 15.445771 | J9: 0
A10: =Japan!A10 -> 38897 | B10: Taiwan | C10: 635.7 | D10: 559.2 | E10: 4276 | F10: 3814.7 | G10: =+C10+E10 -> 4911.7 | H10: =+D10+F10 -> 4373.9 | I10: =+(G10/H10-1)*100 -> 12.295663 | J10: 0
A11: =Japan!A11 -> 38904 | B11: Taiwan | C11: 617.1 | D11: 496.8 | E11: 4352.3 | F11: 3880.4 | G11: =+C11+E11 -> 4969.4 | H11: =+D11+F11 -> 4377.2 | I11: =+(G11/H11-1)*100 -> 13.529197 | J11: 0
A12: =Japan!A12 -> 38911 | B12: Taiwan | C12: 692 | D12: 533 | E12: 4361.4 | F12: 3947.4 | G12: =+C12+E12 -> 5053.4 | H12: =+D12+F12 -> 4480.4 | I12: =+(G12/H12-1)*100 -> 12.789037 | J12: 74
A13: =Japan!A13 -> 38918 | B13: Taiwan | C13: 483.9 | D13: 471 | E13: 4619 | F13: 4014 | G13: =+C13+E13 -> 5102.9 | H13: =+D13+F13 -> 4485 | I13: =+(G13/H13-1)*100 -> 13.777035 | J13: 87
A14: =Japan!A14 -> 38925 | B14: Taiwan | C14: 568.7 | D14: 530.8 | E14: 4623.9 | F14: 4078.8 | G14: =+C14+E14 -> 5192.6 | H14: =+D14+F14 -> 4609.6 | I14: =+(G14/H14-1)*100 -> 12.647518 | J14: 89
A15: =Japan!A15 -> 38932 | B15: Taiwan | C15: 785.3 | D15: 511.1 | E15: 4669.6 | F15: 4171.7 | G15: =+C15+E15 -> 5454.9 | H15: =+D15+F15 -> 4682.8 | I15: =+(G15/H15-1)*100 -> 16.487999 | J15: 139
A16: =Japan!A16 -> 38939 | B16: Taiwan | C16: 816.2 | D16: 397.3 | E16: 4843.9 | F16: 4235.6 | G16: =+C16+E16 -> 5660.1 | H16: =+D16+F16 -> 4632.9 | I16: =+(G16/H16-1)*100 -> 22.171858 | J16: 143
... A19: =Japan!A19 -> 38960 | B19: Taiwan | C19: 551.5 | D19: 205.4 | E19: 4951.3 | F19: 4484.9 | G19: =+C19+E19 -> 5502.8 | H19: =+D19+F19 -> 4690.3 | I19: =+(G19/H19-1)*100 -> 17.322986 | J19: 1164.9
A20: =Japan!A20 -> 38967 | B20: Taiwan | C20: 1280.3 | D20: 594.5 | E20: 70.9 | F20: 186.5 | G20: =+C20+E20 -> 1351.2 | H20: =+D20+F20 -> 781 | I20: =+(G20/H20-1)*100 -> 73.008963
A21: =Japan!A21 -> 38974 | B21: Taiwan | C21: 1212.1 | D21: 686.8 | E21: 100.6 | F21: 264.3 | G21: =+C21+E21 -> 1312.7 | H21: =+D21+F21 -> 951.1 | I21: =+(G21/H21-1)*100 -> 38.019136
A22: =Japan!A22 -> 38981 | B22: Taiwan | C22: 1235.4 | D22: 766.5 | E22: 208.5 | F22: 373.3 | G22: =+C22+E22 -> 1443.9 | H22: =+D22+F22 -> 1139.8 | I22: =+(G22/H22-1)*100 -> 26.680119
A23: =Japan!A23 -> 38988 | B23: Taiwan | C23: 1419.2 | D23: 642.5 | E23: 299.8 | F23: 501.8 | G23: =+C23+E23 -> 1719 | H23: =+D23+F23 -> 1144.3 | I23: =+(G23/H23-1)*100 -> 50.222844
A24: =Japan!A24 -> 38995 | B24: Taiwan | C24: 1436.2 | D24: 691 | E24: 451.4 | F24: 575.6 | G24: =+C24+E24 -> 1887.6 | H24: =+D24+F24 -> 1266.6 | I24: =+(G24/H24-1)*100 -> 49.028896
A25: =Japan!A25 -> 39002 | B25: Taiwan | C25: 1142.5 | D25: 706.6 | E25: 625.8 | F25: 682.3 | G25: =+C25+E25 -> 1768.3 | H25: =+D25+F25 -> 1388.9 | I25: =+(G25/H25-1)*100 -> 27.316581
A26: =Japan!A26 -> 39009 | B26: Taiwan | C26: 1163 | D26: 776 | E26: 641.8 | F26: 746.5 | G26: =+C26+E26 -> 1804.8 | H26: =+D26+F26 -> 1522.5 | I26: =+(G26/H26-1)*100 -> 18.541872
A27: =Japan!A27 -> 39016 | B27: Taiwan | C27: 1148.3 | D27: 777.8 | E27: 715.7 | F27: 821.8 | G27: =+C27+E27 -> 1864 | H27: =+D27+F27 -> 1599.6 | I27: =+(G27/H27-1)*100 -> 16.529132
A28: =Japan!A28 -> 39023 | B28: Taiwan | C28: 1228.6 | D28: 775.7 | E28: 802.7 | F28: 882.7 | G28: =+C28+E28 -> 2031.3 | H28: =+D28+F28 -> 1658.4 | I28: =+(G28/H28-1)*100 -> 22.485528
A29: =Japan!A29 -> 39030 | B29: Taiwan | C29: 1182.3 | D29: 772.5 | E29: 824 | F29: 1039.8 | G29: =+C29+E29 -> 2006.3 | H29: =+D29+F29 -> 1812.3 | I29: =+(G29/H29-1)*100 -> 10.704629
A30: =Japan!A30 -> 39037 | B30: Taiwan | C30: 1074.3 | D30: 812 | E30: 967 | F30: 1113.9 | G30: =+C30+E30 -> 2041.3 | H30: =+D30+F30 -> 1925.9 | I30: =+(G30/H30-1)*100 -> 5.9920037
A31: =Japan!A31 -> 39044 | B31: Taiwan | C31: 1109.2 | D31: 746.8 | E31: 997.5 | F31: 1186.3 | G31: =+C31+E31 -> 2106.7 | H31: =+D31+F31 -> 1933.1 | I31: =+(G31/H31-1)*100 -> 8.9803942
A32: =+A31+7 -> 39051 | B32: Taiwan | C32: 917.6 | D32: 785.7 | E32: 1176.3 | F32: 1297 | G32: =+C32+E32 -> 2093.9 | H32: =+D32+F32 -> 2082.7 | I32: =+(G32/H32-1)*100 -> 0.53776348
A33: =+A32+7 -> 39058 | B33: Taiwan | C33: 685 | D33: 774.8 | E33: 1438.1 | F33: 1347.5 | G33: =+C33+E33 -> 2123.1 | H33: =+D33+F33 -> 2122.3 | I33: =+(G33/H33-1)*100 -> 0.037694954
A34: =+A33+7 -> 39065 | B34: Taiwan | C34: 751.2 | D34: 735.3 | E34: 1547.8 | F34: 1541.7 | G34: =+C34+E34 -> 2299 | H34: =+D34+F34 -> 2277 | I34: =+(G34/H34-1)*100 -> 0.96618357
A35: =+A34+7 -> 39072 | B35: Taiwan | C35: 928.2 | D35: 716.2 | E35: 1555.9 | F35: 1678 | G35: =+C35+E35 -> 2484.1 | H35: =+D35+F35 -> 2394.2 | I35: =+(G35/H35-1)*100 -> 3.7549077
A36: =+A35+7 -> 39079 | B36: Taiwan | C36: 978.1 | D36: 596.9 | E36: 1584.5 | F36: 1867 | G36: =+C36+E36 -> 2562.6 | H36: =+D36+F36 -> 2463.9 | I36: =+(G36/H36-1)*100 -> 4.0058444
A37: =+A36+7 -> 39086 | B37: Taiwan | C37: 841.1 | D37: 484 | E37: 1734 | F37: 1921 | G37: =+C37+E37 -> 2575.1 | H37: =+D37+F37 -> 2405 | I37: =+(G37/H37-1)*100 -> 7.0727651
A38: =+A37+7 -> 39093 | B38: Taiwan | C38: 765.5 | D38: 557 | E38: 1879 | F38: 1969.5 | G38: =+C38+E38 -> 2644.5 | H38: =+D38+F38 -> 2526.5 | I38: =+(G38/H38-1)*100 -> 4.6704928
A39: =+A38+7 -> 39100 | B39: Taiwan | C39: 703.2 | D39: 542.1 | E39: 1959.8 | F39: 2127.7 | G39: =+C39+E39 -> 2663 | H39: =+D39+F39 -> 2669.8 | I39: =+(G39/H39-1)*100 -> -0.25470073
A40: =+A39+7 -> 39107 | B40: Taiwan | C40: 559.1 | D40: 472.6 | E40: 2133.9 | F40: 2293.1 | G40: =+C40+E40 -> 2693 | H40: =+D40+F40 -> 2765.7 | I40: =+(G40/H40-1)*100 -> -2.6286293
A41: =+A40+7 -> 39114 | B41: Taiwan | C41: 570.4 | D41: 465.1 | E41: 2166.4 | F41: 2301.5 | G41: =+C41+E41 -> 2736.8 | H41: =+D41+F41 -> 2766.6 | I41: =+(G41/H41-1)*100 -> -1.0771344
A42: =+A41+7 -> 39121 | B42: Taiwan | C42: 557 | D42: 438.9 | E42: 2241.4 | F42: 2329.3 | G42: =+C42+E42 -> 2798.4 | H42: =+D42+F42 -> 2768.2 | I42: =+(G42/H42-1)*100 -> 1.0909616
...

Sheet Venezuela
B1: Corn by Destination Export Sales as of:
C2: Unshipped Balance | E2: Accumulated Exports | G2: Total Commitments | I2: from last yr | J2: Weekly
C3: This Year | D3: Last Year | E3: This Year | F3: Last Year | G3: This | H3: Last | I3: % change | J3: Change
A4: 41158 | B4: Venezuela | C4: 104.1 | D4: 42.5 | E4: 0 | F4: 0 | G4: =+C4+E4 -> 104.1 | H4: =+D4+F4 -> 42.5 | I4: =+(G4/H4-1)*100 -> 144.94118
A5: =+A4+7 -> 41165 | B5: Venezuela | C5: 59.6 | D5: 23.5 | E5: 57.5 | F5: 48 | G5: =+C5+E5 -> 117.1 | H5: =+D5+F5 -> 71.5 | I5: =+(G5/H5-1)*100 -> 63.776224
A6: =+A5+7 -> 41172 | B6: Venezuela | C6: 47.6 | D6: 6 | E6: 69.5 | F6: 65.5 | G6: =+C6+E6 -> 117.1 | H6: =+D6+F6 -> 71.5 | I6: =+(G6/H6-1)*100 -> 63.776224
A7: =+A6+7 -> 41179 | B7: Venezuela | C7: 34.6 | D7: 6 | E7: 127.5 | F7: 65.5 | G7: =+C7+E7 -> 162.1 | H7: =+D7+F7 -> 71.5 | I7: =+(G7/H7-1)*100 -> 126.71329
A8: =+A7+7 -> 41186 | B8: Venezuela | C8: 34.6 | D8: 44 | E8: 137.5 | F8: 71.5 | G8: =+C8+E8 -> 172.1 | H8: =+D8+F8 -> 115.5 | I8: =+(G8/H8-1)*100 -> 49.004329
A9: =+A8+7 -> 41193 | B9: Venezuela | C9: 25 | D9: 24.5 | E9: 146.7 | F9: 96.5 | G9: =+C9+E9 -> 171.7 | H9: =+D9+F9 -> 121 | I9: =+(G9/H9-1)*100 -> 41.900826
A10: =+A9+7 -> 41200 | B10: Venezuela | C10: 0 | D10: 19.5 | E10: 171.7 | F10: 135.5 | G10: =+C10+E10 -> 171.7 | H10: =+D10+F10 -> 155 | I10: =+(G10/H10-1)*100 -> 10.774194
A11: =+A10+7 -> 41207 | B11: Venezuela | C11: 22.5 | D11: 14 | E11: 171.7 | F11: 141 | G11: =+C11+E11 -> 194.2 | H11: =+D11+F11 -> 155 | I11: =+(G11/H11-1)*100 -> 25.290323
A12: =+A11+7 -> 41214 | B12: Venezuela | C12: 22.5 | D12: 0 | E12: 171.7 | F12: 155 | G12: =+C12+E12 -> 194.2 | H12: =+D12+F12 -> 155 | I12: =+(G12/H12-1)*100 -> 25.290323
A13: =+A12+7 -> 41221 | B13: Venezuela | C13: 22.5 | D13: 0 | E13: 171.7 | F13: 181 | G13: =+C13+E13 -> 194.2 | H13: =+D13+F13 -> 181 | I13: =+(G13/H13-1)*100 -> 7.2928177
A14: =+A13+7 -> 41228 | B14: Venezuela | C14: 43 | D14: 0 | E14: 184.2 | F14: 186 | G14: =+C14+E14 -> 227.2 | H14: =+D14+F14 -> 186 | I14: =+(G14/H14-1)*100 -> 22.150538
A15: =+A14+7 -> 41235 | B15: Venezuela | C15: 33 | D15: 48.5 | E15: 194.2 | F15: 186 | G15: =+C15+E15 -> 227.2 | H15: =+D15+F15 -> 234.5 | I15: =+(G15/H15-1)*100 -> -3.1130064
A16: =+A15+7 -> 41242 | B16: Venezuela | C16: 10 | D16: 30 | E16: 227.2 | F16: 204.5 | G16: =+C16+E16 -> 237.2 | H16: =+D16+F16 -> 234.5 | I16: =+(G16/H16-1)*100 -> 1.1513859
... A49: =+A48+7 -> 41473 | B49: Venezuela | C49: 71 | D49: 87.1 | E49: 1008.8 | F49: 1099.1 | G49: =+C49+E49 -> 1079.8 | H49: =+D49+F49 -> 1186.2 | I49: =+(G49/H49-1)*100 -> -8.9698196
A50: =+A49+7 -> 41480 | B50: Venezuela | C50: 26 | D50: 89.6 | E50: 1071.6 | F50: 1126.6 | G50: =+C50+E50 -> 1097.6 | H50: =+D50+F50 -> 1216.2 | I50: =+(G50/H50-1)*100 -> -9.7516856 | J50: 16
A51: =+A50+7 -> 41487 | B51: Venezuela | C51: 46 | D51: 95.1 | E51: 1118.1 | F51: 1146.6 | G51: =+C51+E51 -> 1164.1 | H51: =+D51+F51 -> 1241.7 | I51: =+(G51/H51-1)*100 -> -6.2494967 | J51: 16
A52: =+A51+7 -> 41494 | B52: Venezuela | C52: 26 | D52: 86.6 | E52: 1138.1 | F52: 1209.6 | G52: =+C52+E52 -> 1164.1 | H52: =+D52+F52 -> 1296.2 | I52: =+(G52/H52-1)*100 -> -10.191328 | J52: 16
A53: =+A52+7 -> 41501 | B53: Venezuela | C53: 36 | D53: 96.6 | E53: 1138.1 | F53: 1235.1 | G53: =+C53+E53 -> 1174.1 | H53: =+D53+F53 -> 1331.7 | I53: =+(G53/H53-1)*100 -> -11.834497 | J53: 16
A54: =+A53+7 -> 41508 | B54: Venezuela | C54: 16 | D54: 51.6 | E54: 1158.1 | F54: 1280.1 | G54: =+C54+E54 -> 1174.1 | H54: =+D54+F54 -> 1331.7 | I54: =+(G54/H54-1)*100 -> -11.834497 | J54: 31
A55: =+A54+7 -> 41515 | B55: Venezuela | C55: 16 | D55: 51.6 | E55: 1158.1 | F55: 1280.1 | G55: =+C55+E55 -> 1174.1 | H55: =+D55+F55 -> 1331.7 | I55: =+(G55/H55-1)*100 -> -11.834497 | J55: 58
A56: =+A55+7 -> 41522 | B56: Venezuela | C56: 84 | D56: 104.1 | E56: 10 | F56: 0 | G56: =+C56+E56 -> 94 | H56: =+D56+F56 -> 104.1 | I56: =+(G56/H56-1)*100 -> -9.7022094
A57: =+A56+7 -> 41529 | B57: Venezuela | C57: 32 | D57: 59.6 | E57: 77 | F57: 57.5 | G57: =+C57+E57 -> 109 | H57: =+D57+F57 -> 117.1 | I57: =+(G57/H57-1)*100 -> -6.9171648
A58: =+A57+7 -> 41536 | B58: Venezuela | C58: 8 | D58: 47.6 | E58: 113.5 | F58: 69.5 | G58: =+C58+E58 -> 121.5 | H58: =+D58+F58 -> 117.1 | I58: =+(G58/H58-1)*100 -> 3.7574722
A59: =+A58+7 -> 41543 | B59: Venezuela | C59: 34.6 | D59: 34.6 | E59: 113.5 | F59: 127.5 | G59: =+C59+E59 -> 148.1 | H59: =+D59+F59 -> 162.1 | I59: =+(G59/H59-1)*100 -> -8.636644
A60: =+A59+7 -> 41550 | B60: Venezuela | C60: 34.6 | D60: 34.6 | E60: 142 | F60: 137.5 | G60: =+C60+E60 -> 176.6 | H60: =+D60+F60 -> 172.1 | I60: =+(G60/H60-1)*100 -> 2.6147589
A61: =+A60+7 -> 41557 | B61: Venezuela
A62: =+A61+7 -> 41564 | B62: Venezuela
A63: =+A62+7 -> 41571 | B63: Venezuela | C63: 71 | D63: 22.5 | E63: 160.6 | F63: 171.7 | G63: =+C63+E63 -> 231.6 | H63: =+D63+F63 -> 194.2 | I63: =+(G63/H63-1)*100 -> 19.258496
A64: =+A63+7 -> 41578 | B64: Venezuela | C64: 71 | D64: 22.5 | E64: 160.6 | F64: 171.7 | G64: =+C64+E64 -> 231.6 | H64: =+D64+F64 -> 194.2 | I64: =+(G64/H64-1)*100 -> 19.258496
A65: =+A64+7 -> 41585 | B65: Venezuela | C65: 61 | D65: 22.5 | E65: 165.6 | F65: 171.7 | G65: =+C65+E65 -> 226.6 | H65: =+D65+F65 -> 194.2 | I65: =+(G65/H65-1)*100 -> 16.683831
A66: =+A65+7 -> 41592 | B66: Venezuela | C66: 61 | D66: 43 | E66: 165.6 | F66: 184.2 | G66: =+C66+E66 -> 226.6 | H66: =+D66+F66 -> 227.2 | I66: =+(G66/H66-1)*100 -> -0.26408451
A67: =+A66+7 -> 41599 | B67: Venezuela | C67: 61 | D67: 33 | E67: 165.6 | F67: 194.2 | G67: =+C67+E67 -> 226.6 | H67: =+D67+F67 -> 227.2 | I67: =+(G67/H67-1)*100 -> -0.26408451
A68: =+A67+7 -> 41606 | B68: Venezuela | C68: 73 | D68: 10 | E68: 181.6 | F68: 227.2 | G68: =+C68+E68 -> 254.6 | H68: =+D68+F68 -> 237.2 | I68: =+(G68/H68-1)*100 -> 7.3355818
A69: =+A68+7 -> 41613 | B69: Venezuela | C69: 74 | D69: 10 | E69: 230.7 | F69: 237.2 | G69: =+C69+E69 -> 304.7 | H69: =+D69+F69 -> 247.2 | I69: =+(G69/H69-1)*100 -> 23.260518
A70: =+A69+7 -> 41620 | B70: Venezuela | C70: 64 | D70: 40 | E70: 240.7 | F70: 237.2 | G70: =+C70+E70 -> 304.7 | H70: =+D70+F70 -> 277.2 | I70: =+(G70/H70-1)*100 -> 9.9206349
A71: =+A70+7 -> 41627 | B71: Venezuela | C71: 151 | D71: 30 | E71: 240.7 | F71: 247.2 | G71: =+C71+E71 -> 391.7 | H71: =+D71+F71 -> 277.2 | I71: =+(G71/H71-1)*100 -> 41.305916
A72: =+A71+7 -> 41634 | B72: Venezuela | C72: 151 | D72: 30 | E72: 257.7 | F72: 247.2 | G72: =+C72+E72 -> 408.7 | H72: =+D72+F72 -> 277.2 | I72: =+(G72/H72-1)*100 -> 47.438672
...

Sheet Egypt
B1: Corn by Destination Export Sales as of:
C2: Unshipped Balance | E2: Accumulated Exports | G2: Total Commitments | I2: from last yr | J2: next
C3: curr | D3: last | E3: curr | F3: last | G3: curr | H3: last | I3: % change | J3: crop year
A4: =Japan!A4 -> 38855 | B4: Egypt | C4: 535.8 | D4: 500 | E4: 2666.9 | F4: 2779.9 | G4: =+C4+E4 -> 3202.7 | H4: =+D4+F4 -> 3279.9 | I4: =+(G4/H4-1)*100 -> -2.3537303
A5: =Japan!A5 -> 38862 | B5: Egypt | C5: 540 | D5: 500 | E5: 2725.3 | F5: 2844.8 | G5: =+C5+E5 -> 3265.3 | H5: =+D5+F5 -> 3344.8 | I5: =+(G5/H5-1)*100 -> -2.3768237
A6: =Japan!A6 -> 38869 | B6: Egypt | C6: 570 | D6: 552.8 | E6: 2755.3 | F6: 2901.9 | G6: =+C6+E6 -> 3325.3 | H6: =+D6+F6 -> 3454.7 | I6: =+(G6/H6-1)*100 -> -3.7456219 | J6: 0
A7: =Japan!A7 -> 38876 | B7: Egypt | C7: 435 | D7: 552.8 | E7: 2946.5 | F7: 2957.3 | G7: =+C7+E7 -> 3381.5 | H7: =+D7+F7 -> 3510.1 | I7: =+(G7/H7-1)*100 -> -3.6637133 | J7: 0
A8: =Japan!A8 -> 38883 | B8: Egypt | C8: 315 | D8: 620 | E8: 3010.8 | F8: 2982.3 | G8: =+C8+E8 -> 3325.8 | H8: =+D8+F8 -> 3602.3 | I8: =+(G8/H8-1)*100 -> -7.6756517 | J8: 0
A9: =Japan!A9 -> 38890 | B9: Egypt | C9: 435 | D9: 500 | E9: 3125.4 | F9: 3095.9 | G9: =+C9+E9 -> 3560.4 | H9: =+D9+F9 -> 3595.9 | I9: =+(G9/H9-1)*100 -> -0.98723546 | J9: 0
A10: =Japan!A10 -> 38897 | B10: Egypt | C10: 465 | D10: 580 | E10: 3196.4 | F10: 3095.9 | G10: =+C10+E10 -> 3661.4 | H10: =+D10+F10 -> 3675.9 | I10: =+(G10/H10-1)*100 -> -0.39446122 | J10: 0
A11: =Japan!A11 -> 38904 | B11: Egypt | C11: 445 | D11: 520 | E11: 3249 | F11: 3205.5 | G11: =+C11+E11 -> 3694 | H11: =+D11+F11 -> 3725.5 | I11: =+(G11/H11-1)*100 -> -0.84552409 | J11: 0
A12: =Japan!A12 -> 38911 | B12: Egypt | C12: 525 | D12: 440 | E12: 3318.5 | F12: 3347.7 | G12: =+C12+E12 -> 3843.5 | H12: =+D12+F12 -> 3787.7 | I12: =+(G12/H12-1)*100 -> 1.4731895
A13: =Japan!A13 -> 38918 | B13: Egypt | C13: 625 | D13: 500 | E13: 3409.7 | F13: 3531.7 | G13: =+C13+E13 -> 4034.7 | H13: =+D13+F13 -> 4031.7 | I13: =+(G13/H13-1)*100 -> 0.074410298
A14: =Japan!A14 -> 38925 | B14: Egypt | C14: 515 | D14: 440 | E14: 3540.9 | F14: 3708.1 | G14: =+C14+E14 -> 4055.9 | H14: =+D14+F14 -> 4148.1 | I14: =+(G14/H14-1)*100 -> -2.2227044 | J14: 0
A15: =Japan!A15 -> 38932 | B15: Egypt | C15: 465 | D15: 680 | E15: 3720.6 | F15: 3771.7 | G15: =+C15+E15 -> 4185.6 | H15: =+D15+F15 -> 4451.7 | I15: =+(G15/H15-1)*100 -> -5.9774917 | J15: 60
A16: =Japan!A16 -> 38939 | B16: Egypt | C16: 400 | D16: 620 | E16: 3771.3 | F16: 3837.5 | G16: =+C16+E16 -> 4171.3 | H16: =+D16+F16 -> 4457.5 | I16: =+(G16/H16-1)*100 -> -6.4206394 | J16: 120
A17: =Japan!A17 -> 38946 | B17: Egypt | C17: 280 | D17: 545 | E17: 3955.5 | F17: 3960.2 | G17: =+C17+E17 -> 4235.5 | H17: =+D17+F17 -> 4505.2 | I17: =+(G17/H17-1)*100 -> -5.9864157 | J17: 240
A18: =Japan!A18 -> 38953 | B18: Egypt | C18: 235 | D18: 440 | E18: 4083.2 | F18: 4123.3 | G18: =+C18+E18 -> 4318.2 | H18: =+D18+F18 -> 4563.3 | I18: =+(G18/H18-1)*100 -> -5.371113 | J18: 473
A19: =Japan!A19 -> 38960 | B19: Egypt | C19: 143.2 | D19: 440 | E19: 4298.1 | F19: 4123.3 | G19: =+C19+E19 -> 4441.3 | H19: =+D19+F19 -> 4563.3 | I19: =+(G19/H19-1)*100 -> -2.6735038 | J19: 676.2
A20: =Japan!A20 -> 38967 | B20: Egypt | C20: 673.2 | D20: 740 | E20: 50.6 | F20: 51.2 | G20: =+C20+E20 -> 723.8 | H20: =+D20+F20 -> 791.2 | I20: =+(G20/H20-1)*100 -> -8.5187058
A21: =+A20+7 -> 38974 | B21: Egypt | C21: 681.5 | D21: 740 | E21: 211.4 | F21: 51.2 | G21: =+C21+E21 -> 892.9 | H21: =+D21+F21 -> 791.2 | I21: =+(G21/H21-1)*100 -> 12.853893
A22: =+A21+7 -> 38981 | B22: Egypt | C22: 635 | D22: 704.3 | E22: 349.7 | F22: 152.9 | G22: =+C22+E22 -> 984.7 | H22: =+D22+F22 -> 857.2 | I22: =+(G22/H22-1)*100 -> 14.874008
A23: =+A22+7 -> 38988 | B23: Egypt | C23: 635 | D23: 704.3 | E23: 407.3 | F23: 152.9 | G23: =+C23+E23 -> 1042.3 | H23: =+D23+F23 -> 857.2 | I23: =+(G23/H23-1)*100 -> 21.59356
A24: =+A23+7 -> 38995 | B24: Egypt | C24: 615 | D24: 720.7 | E24: 407.3 | F24: 310.6 | G24: =+C24+E24 -> 1022.3 | H24: =+D24+F24 -> 1031.3 | I24: =+(G24/H24-1)*100 -> -0.87268496
A25: =+A24+7 -> 39002 | B25: Egypt | C25: 452.5 | D25: 608.3 | E25: 602.5 | F25: 471.7 | G25: =+C25+E25 -> 1055 | H25: =+D25+F25 -> 1080 | I25: =+(G25/H25-1)*100 -> -2.3148148
A26: =+A25+7 -> 39009 | B26: Egypt | C26: 293.9 | D26: 608.3 | E26: 743.4 | F26: 529.2 | G26: =+C26+E26 -> 1037.3 | H26: =+D26+F26 -> 1137.5 | I26: =+(G26/H26-1)*100 -> -8.8087912
A27: =+A26+7 -> 39016 | B27: Egypt | C27: 293.9 | D27: 558.2 | E27: 743.4 | F27: 644.5 | G27: =+C27+E27 -> 1037.3 | H27: =+D27+F27 -> 1202.7 | I27: =+(G27/H27-1)*100 -> -13.75239
A28: =+A27+7 -> 39023 | B28: Egypt | C28: 170.5 | D28: 531.2 | E28: 797.9 | F28: 708.9 | G28: =+C28+E28 -> 968.4 | H28: =+D28+F28 -> 1240.1 | I28: =+(G28/H28-1)*100 -> -21.909523
A29: =+A28+7 -> 39030 | B29: Egypt | C29: 131.7 | D29: 651.2 | E29: 836.7 | F29: 765.2 | G29: =+C29+E29 -> 968.4 | H29: =+D29+F29 -> 1416.4 | I29: =+(G29/H29-1)*100 -> -31.629483
A30: =+A29+7 -> 39037 | B30: Egypt | C30: 170.5 | D30: 531.2 | E30: 903.2 | F30: 876.2 | G30: =+C30+E30 -> 1073.7 | H30: =+D30+F30 -> 1407.4 | I30: =+(G30/H30-1)*100 -> -23.710388
A31: =+A30+7 -> 39044 | B31: Egypt | C31: 290.5 | D31: 591.2 | E31: 903.2 | F31: 918.3 | G31: =+C31+E31 -> 1193.7 | H31: =+D31+F31 -> 1509.5 | I31: =+(G31/H31-1)*100 -> -20.920835
A32: =+A31+7 -> 39051 | B32: Egypt | C32: 240.2 | D32: 441.2 | E32: 947.8 | F32: 982.5 | G32: =+C32+E32 -> 1188 | H32: =+D32+F32 -> 1423.7 | I32: =+(G32/H32-1)*100 -> -16.555454
... A34: =+A33+7 -> 39065 | B34: Egypt | C34: 282.2 | D34: 300 | E34: 947.8 | F34: 1111.6 | G34: =+C34+E34 -> 1230 | H34: =+D34+F34 -> 1411.6 | I34: =+(G34/H34-1)*100 -> -12.864834
A35: =+A34+7 -> 39072 | B35: Egypt | C35: 282.2 | D35: 229.8 | E35: 1004.5 | F35: 1173.9 | G35: =+C35+E35 -> 1286.7 | H35: =+D35+F35 -> 1403.7 | I35: =+(G35/H35-1)*100 -> -8.3351143 | J35: 60
A36: =+A35+7 -> 39079 | B36: Egypt | C36: 402.7 | D36: 324.5 | E36: 1070 | F36: 1199.2 | G36: =+C36+E36 -> 1472.7 | H36: =+D36+F36 -> 1523.7 | I36: =+(G36/H36-1)*100 -> -3.3471156 | J36: 60
A37: =+A36+7 -> 39086 | B37: Egypt | C37: 480.2 | D37: 254.5 | E37: 1134.8 | F37: 1275.1 | G37: =+C37+E37 -> 1615 | H37: =+D37+F37 -> 1529.6 | I37: =+(G37/H37-1)*100 -> 5.583159
A38: =+A37+7 -> 39093 | B38: Egypt | C38: 480.2 | D38: 350 | E38: 1134.8 | F38: 1305.4 | G38: =+C38+E38 -> 1615 | H38: =+D38+F38 -> 1655.4 | I38: =+(G38/H38-1)*100 -> -2.4404978 | J38: 60
A39: =+A38+7 -> 39100 | B39: Egypt | C39: 489.7 | D39: 300 | E39: 1312 | F39: 1465.2 | G39: =+C39+E39 -> 1801.7 | H39: =+D39+F39 -> 1765.2 | I39: =+(G39/H39-1)*100 -> 2.0677544 | J39: 60
A40: =+A39+7 -> 39107 | B40: Egypt | C40: 369.7 | D40: 240 | E40: 1371.2 | F40: 1591.3 | G40: =+C40+E40 -> 1740.9 | H40: =+D40+F40 -> 1831.3 | I40: =+(G40/H40-1)*100 -> -4.936384
A41: =+A40+7 -> 39114 | B41: Egypt | C41: 369.7 | D41: 240 | E41: 1468.7 | F41: 1713 | G41: =+C41+E41 -> 1838.4 | H41: =+D41+F41 -> 1953 | I41: =+(G41/H41-1)*100 -> -5.8678955
...

Sheet DATA
A1: --------------------------------------------------------------------------------
A2: : WEEK : OUT- :WEEKLY :CUMULATIVE EXPORTS: TOTAL : OFFICIAL
A3: COMMODITY : END- :STANDING:EXPORTS : FOR : COMMIT-:USDA EXPORT
A4: : ING : SALES : : MARKETING YEAR : MENT 2/:PROJECTIONS
A5: --------------------------------------------------------------------------------
A6: CORN : 09/05 12612.1 171.2 171.2 6.7 12783.2
A7: : 09/12 12530.6 518.8 690.0 27.2 13220.6 31120 3/
A8: :YR AGO 9112.9 739.7 989.1 38.9 10102.0
A11: CORN - UNMILLED | F11: MARKETI | G11: NG YEAR 09 | H11: /01 - 08/31 | J11: : | N11: :
A12: OUTSTANDING EXPORT | B12: S | C12: ALES AND | D12: EXPORTS | E12: BY COUNTRY | F12: , REGION | G12: AND MARKET | H12: ING YEAR
A13: 1000 METRIC TONS | C13: AS OF SE | D13: PTEMBER 1 | E13: 2, 2013
A14: ---------------------- | B14: - | C14: -------- | D14: --------- | E14: ---------- | F14: --------- | G14: ---------- | H14: -----------
B15: : | C15: CU | D15: RRENT MAR | E15: KETING YEA | F15: R | G15: :NEXT MAR | H15: KETING YEAR
C16: -------- | D16: --------- | E16: ---------- | F16: --------- | G16: ---------- | H16: -----------
B17: : | C17: OUTSTAND | D17: ING SALES | E17: :ACCUMULAT | F17: ED EXPORT | G17: S: OUTSTAN | H17: DING SALES
C18: -------- | D18: --------- | E18: ---------- | F18: --------- | G18: ---------- | H18: -----------
A19: DESTINATION | B19: : | C19: THIS WEE | D19: K: YR AGO | E19: :THIS WEEK | F19: : YR AGO | G19: :SECOND Y | H19: R: THIRD YR
A20: ---------------------- | B20: - | C20: -------- | D20: --------- | E20: ---------- | F20: --------- | G20: ---------- | H20: -----------
B21: :
A22: EUROPEAN UNION - 27 | B22: : | C22: 0.2 | D22: 0.4 | E22: 0 | F22: * | G22: 0 | H22: 0
A23: SPAIN | B23: : | C23: 0 | D23: 0.3 | E23: 0 | F23: 0 | G23: 0 | H23: 0
A24: U KING | B24: : | C24: 0.2 | D24: 0.1 | E24: 0 | F24: * | G24: 0 | H24: 0
B25: : | L25: 4Not included - FAS Press Release: 120,000 mt on 4/22 to Egypt for 2009/10.
A26: JAPAN | B26: : | C26: 1793.2 | D26: 2022.4 | E26: 182 | F26: 306 | G26: 0 | H26: 0
B27: : | L27: 4 Not included - FAS Press Release: 287,000 mt on 03/28 to Unknown for 2007/08; 110,000 mt for 2008/09.
A28: TAIWAN | B28: : | C28: 162.9 | D28: 107.9 | E28: 3.2 | F28: 32.7 | G28: 0 | H28: 0
B29: :
A30: CHINA | B30: : | C30: 3127.7 | D30: 785.6 | E30: 60 | F30: 275.1 | G30: 0 | H30: 0
B31: :
