Workbook
Name CondWeight: CIP!$G$3
Name Consequence_Ratings: Lists!$D$2:$D$12
Name Efactor: CIP!$AL$3
Name Funding_Source: Lists!$F$2:$F$11
Name Overall_Condition: Lists!$B$2:$B$12
Name Percent_Life_Left: Lists!$A$2:$A$12
Name PLifeWeight: CIP!$H$3
Name t: CIP!$I$3
Name Weight1: CIP!$I$3
Name Weight2: CIP!$J$3
Name Weight3: CIP!$K$3
Name Weight4: CIP!$L$3
Name Weight5: CIP!$M$3
Name Weight6: CIP!$N$3
Name Weight7: CIP!$O$3
Name Weight8: CIP!$P$3
Name WSum: CIP!$Q$3

Sheet CIP
A1: ="FY"& (YEAR(TODAY())+2)&"-" & (YEAR(TODAY())+6)&" CIP by Priority" -> FY2014-2018 CIP by Priority | G1: Overall Condition input | H1: % Life Left as input | I1: CONSEQUENCES OF FAILURE (IF NOT IMPLEMENTING PROGRAM) RATINGS AND WEIGHTS --0 (No Impact) to 10 (High Impact) | AC1: Threshold | AD1: Threshold | AM1: ESCALATED COSTS (Costs in FY2015-2018 are escalated 3.5% a year)
G2: Weight | H2: Weight | I2: Weight | J2: Weight | K2: Weight | L2: Weight | M2: Weight | N2: Weight | O2: Weight | P2: Weight | Q2: Sum of Weights | AC2: 0.75 | AD2: 6 | AH2: BUDGET DISTRIBUTION | AM2: Total | AN2: Total | AO2: Total | AP2: Total | AQ2: Total
G3: 2 | H3: 1 | I3: 9 | J3: 6 | K3: 8 | L3: 10 | M3: 5 | N3: 7 | O3: 6 | P3: 6 | Q3: =SUM(I3:P3) -> 57 | AH3: Escalation factor: | AL3: 0.035 | AM3: =SUM(AM5:AM329) -> 46641575 | AN3: =SUM(AN5:AN329) -> 40233912 | AO3: =SUM(AO5:AO329) -> 55880081 | AP3: =SUM(AP5:AP329) -> 41272841 | AQ3: =SUM(AQ5:AQ329) -> 37477694
A4: Priority | B4: Dept | C4: Asset Category | D4: Project Title | E4: Project Description / Justification | F4: ="Est Cost in FY"&YEAR(TODAY())+2 -> Est Cost in FY2014 | G4: Overall Condition 0: Worse to 10: Best | H4: % Life Left 0: Expired to 100: New | I4: City Operations | J4: Programs / Services | K4: Costs/ Savings Ratio | L4: Codes/ Health & Safety | M4: Property Damage | N4: Quality of Life | O4: Energy | P4: Dept. Mission or Vision | Q4: % Life Left (Dynamic) | R4: % Life Left | S4: City Operations | T4: Programs/Services | U4: Costs/Savings Ratio | V4: Health & Safety | W4: Property Damage | X4: Quality of Life | Y4: Energy | Z4: Dept. Mission or Vision | AA4: Condition Likelihood Failure | AB4: % Life Left Likelihood failure | AC4: Likelihood of Failure | AD4: Conseq. Factor | AE4: Risk Factor | AF4: Funding Source | AG4: Prior Year Funding | AH4: ="FY "&YEAR(TODAY())+2 -> FY 2014 | AI4: ="FY"&YEAR(TODAY())+3 -> FY2015 | AJ4: ="FY"&YEAR(TODAY())+4 -> FY2016 | AK4: ="FY"&YEAR(TODAY())+5 -> FY2017 | AL4: ="FY"&YEAR(TODAY())+6 -> FY2018 | AM4: =AH4 -> FY 2014 | AN4: =AI4 -> FY2015 | AO4: =AJ4 -> FY2016 | AP4: =AK4 -> FY2017 | AQ4: =AL4 -> FY2018
A5: 1 | B5: Schools | C5: Building | D5: Angier School - Renovation or Replacement | E5: $7.5M anticipated from MSBA. Renovate/ replace 92 yr old school due to poor condition, aging bldg systems and inadequate space per State Ed. MSBA required feasibility study. | F5: 35000000 | G5: 2 | H5: 0 | I5: 10 | J5: 10 | K5: 4 | L5: 6 | M5: 4 | N5: 9 | O5: 5 | P5: 10 | Q5: =(#REF!-(YEAR(TODAY())-#REF!))/#REF! -> #REF! | R5: =IFERROR(Q5,H5) -> 0 | S5: =I5*Weight1/(WSum) -> 1.5789474 | T5: =J5*Weight2/(WSum) -> 1.0526316 | U5: =K5*Weight3/(WSum) -> 0.56140351 | V5: =L5*Weight4/(WSum) -> 1.0526316 | W5: =M5*Weight5/(WSum) -> 0.35087719 | X5: =N5*Weight6/(WSum) -> 1.1052632 | Y5: =O5*Weight7/(WSum) -> 0.52631579 | Z5: =P5*Weight8/(WSum) -> 1.0526316 | AA5: =-1/10*G5+1 -> 0.8 | AB5: =IF(R5<0,0,-R5+1) -> 1 | AC5: =(AA5*CondWeight+AB5*PLifeWeight)/(CondWeight+PLifeWeight) -> 0.86666667 | AD5: =SUM(S5:Z5) -> 7.2807018 | AE5: =AD5*AC5*10 -> 63.099415 | AF5: Bonding /MSBA | AG5: 750000 | AH5: 5000000 | AI5: 16908212 | AJ5: 11668884 | AM5: =AH5 -> 5000000 | AN5: =AI5*(1+Efactor) -> 17500000 | AO5: =AJ5*(1+Efactor)^2 -> 12500000
A6: 2 | B6: Schools | C6: Building | D6: Carr School - Building Renovation | E6: Create swing space for on-going Elem. school bldg projects. Includes system and accessibility upgrades, sprinklers, sitework, windows, and roof. | F6: 12700000 | G6: 3 | H6: 0.1 | I6: 6 | J6: 10 | K6: 8 | L6: 4 | M6: 8 | N6: 8 | O6: 6 | P6: 10 | Q6: =(#REF!-(YEAR(TODAY())-#REF!))/#REF! -> #REF! | R6: =IFERROR(Q6,H6) -> 0.1 | S6: =I6*Weight1/(WSum) -> 0.94736842 | T6: =J6*Weight2/(WSum) -> 1.0526316 | U6: =K6*Weight3/(WSum) -> 1.122807 | V6: =L6*Weight4/(WSum) -> 0.70175439 | W6: =M6*Weight5/(WSum) -> 0.70175439 | X6: =N6*Weight6/(WSum) -> 0.98245614 | Y6: =O6*Weight7/(WSum) -> 0.63157895 | Z6: =P6*Weight8/(WSum) -> 1.0526316 | AA6: =-1/10*G6+1 -> 0.7 | AB6: =IF(R6<0,0,-R6+1) -> 0.9 | AC6: =(AA6*CondWeight+AB6*PLifeWeight)/(CondWeight+PLifeWeight) -> 0.76666667 | AD6: =SUM(S6:Z6) -> 7.1929825 | AE6: =AD6*AC6*10 -> 55.146199 | AF6: Bonding | AG6: 1000000 | AH6: 11700000 | AM6: =AH6 -> 11700000
A7: 3 | B7: Fire Dept | C7: Building | D7: Fire Station #3, HQs, and Wires - Renovate/Replace Newton Centre Station | E7: Station #3 needs major repairs/upgrades. Co-located w/ Fire HQs. Upgrade 60 yo systems for code compliance, access & female firefighters. | F7: 17500000 | G7: 3 | H7: 0.1 | I7: 8 | J7: 8 | K7: 5 | L7: 8 | M7: 7 | N7: 9 | O7: 3 | P7: 9 | Q7: =(#REF!-(YEAR(TODAY())-#REF!))/#REF! -> #REF! | R7: =IFERROR(Q7,H7) -> 0.1 | S7: =I7*Weight1/(WSum) -> 1.2631579 | T7: =J7*Weight2/(WSum) -> 0.84210526 | U7: =K7*Weight3/(WSum) -> 0.70175439 | V7: =L7*Weight4/(WSum) -> 1.4035088 | W7: =M7*Weight5/(WSum) -> 0.61403509 | X7: =N7*Weight6/(WSum) -> 1.1052632 | Y7: =O7*Weight7/(WSum) -> 0.31578947 | Z7: =P7*Weight8/(WSum) -> 0.94736842 | AA7: =-1/10*G7+1 -> 0.7 | AB7: =IF(R7<0,0,-R7+1) -> 0.9 | AC7: =(AA7*CondWeight+AB7*PLifeWeight)/(CondWeight+PLifeWeight) -> 0.76666667 | AD7: =SUM(S7:Z7) -> 7.1929825 | AE7: =AD7*AC7*10 -> 55.146199 | AF7: Bonding | AH7: 4000000 | AI7: 2898551 | AJ7: 7934841 | AM7: =AH7 -> 4000000 | AN7: 5000000 | AO7: =AJ7*(1+Efactor)^2 -> 8500000.1
A8: 4 | B8: DPW/ Sewer | C8: Sewer | D8: Sewer Inflow /Infiltration Project - West Newton Area | E8: Part of 12 yr $49.1 M program to remove excess inflow and infiltration into sewer system. Design (FY13) and constr (FY14) for West Newton area. | F8: 5643625 | G8: 3 | H8: 0.2 | I8: 8 | J8: 8 | K8: 8 | L8: 8 | M8: 6 | N8: 8 | O8: 0 | P8: 9 | Q8: =(#REF!-(YEAR(TODAY())-#REF!))/#REF! -> #REF! | R8: =IFERROR(Q8,H8) -> 0.2 | S8: =I8*Weight1/(WSum) -> 1.2631579 | T8: =J8*Weight2/(WSum) -> 0.84210526 | U8: =K8*Weight3/(WSum) -> 1.122807 | V8: =L8*Weight4/(WSum) -> 1.4035088 | W8: =M8*Weight5/(WSum) -> 0.52631579 | X8: =N8*Weight6/(WSum) -> 0.98245614 | Y8: =O8*Weight7/(WSum) -> 0 | Z8: =P8*Weight8/(WSum) -> 0.94736842 | AA8: =-1/10*G8+1 -> 0.7 | AB8: =IF(R8<0,0,-R8+1) -> 0.8 | AC8: =(AA8*CondWeight+AB8*PLifeWeight)/(CondWeight+PLifeWeight) -> 0.73333333 | AD8: =SUM(S8:Z8) -> 7.0877193 | AE8: =AD8*AC8*10 -> 51.976608 | AF8: Enterprise Funds | AG8: 902000 | AH8: 4741625 | AM8: =AH8 -> 4741625
A9: 5 | B9: DPW/ Water | C9: Water | D9: Replace Water Pipes to Improve Fire Flows | E9: Year two of 3 year program to replace and repair water pipes in order to meet ISO fire flow standards which are currently defficient. | F9: 3851000 | G9: 1 | H9: 0.4 | I9: 6 | J9: 6 | K9: 8 | L9: 8 | M9: 8 | N9: 6 | O9: 0 | P9: 8 | Q9: =(#REF!-(YEAR(TODAY())-#REF!))/#REF! -> #REF! | R9: =IFERROR(Q9,H9) -> 0.4 | S9: =I9*Weight1/(WSum) -> 0.94736842 | T9: =J9*Weight2/(WSum) -> 0.63157895 | U9: =K9*Weight3/(WSum) -> 1.122807 | V9: =L9*Weight4/(WSum) -> 1.4035088 | W9: =M9*Weight5/(WSum) -> 0.70175439 | X9: =N9*Weight6/(WSum) -> 0.73684211 | Y9: =O9*Weight7/(WSum) -> 0 | Z9: =P9*Weight8/(WSum) -> 0.84210526 | AA9: =-1/10*G9+1 -> 0.9 | AB9: =IF(R9<0,0,-R9+1) -> 0.6 | AC9: =(AA9*CondWeight+AB9*PLifeWeight)/(CondWeight+PLifeWeight) -> 0.8 | AD9: =SUM(S9:Z9) -> 6.3859649 | AE9: =AD9*AC9*10 -> 51.087719 | AF9: Enterprise Funds | AH9: 3851000 | AM9: =AH9 -> 3851000
A10: 6 | B10: Schools | C10: Building | D10: Remove Underground Tanks at Various Schools | E10: Remove underground tanks which are no longer needed at Memorial-Spaulding, Zervas, and Underwood Elementary Schools. | F10: 250000 | G10: 1 | H10: 0 | I10: 5 | J10: 6 | K10: 5 | L10: 10 | M10: 4 | N10: 2 | O10: 1 | P10: 8 | Q10: =(#REF!-(YEAR(TODAY())-#REF!))/#REF! -> #REF! | R10: =IFERROR(Q10,H10) -> 0 | S10: =I10*Weight1/(WSum) -> 0.78947368 | T10: =J10*Weight2/(WSum) -> 0.63157895 | U10: =K10*Weight3/(WSum) -> 0.70175439 | V10: =L10*Weight4/(WSum) -> 1.754386 | W10: =M10*Weight5/(WSum) -> 0.35087719 | X10: =N10*Weight6/(WSum) -> 0.24561404 | Y10: =O10*Weight7/(WSum) -> 0.10526316 | Z10: =P10*Weight8/(WSum) -> 0.84210526 | AA10: =-1/10*G10+1 -> 0.9 | AB10: =IF(R10<0,0,-R10+1) -> 1 | AC10: =(AA10*CondWeight+AB10*PLifeWeight)/(CondWeight+PLifeWeight) -> 0.93333333 | AD10: =SUM(S10:Z10) -> 5.4210526 | AE10: =AD10*AC10*10 -> 50.596491 | AF10: Other | AH10: 250000 | AM10: =AH10 -> 250000
A11: 7 | B11: Schools | C11: Building | D11: Lincoln Eliot School - Add Four Modular Classrooms | E11: Add modular classrooms for growing enrollment. Project includes sprinklers for the entire building as required by building code. | F11: 3000000 | G11: 2 | H11: 0 | I11: 6 | J11: 8 | K11: 6 | L11: 8 | M11: 0 | N11: 6 | O11: 0 | P11: 10 | Q11: =(#REF!-(YEAR(TODAY())-#REF!))/#REF! -> #REF! | R11: =IFERROR(Q11,H11) -> 0 | S11: =I11*Weight1/(WSum) -> 0.94736842 | T11: =J11*Weight2/(WSum) -> 0.84210526 | U11: =K11*Weight3/(WSum) -> 0.84210526 | V11: =L11*Weight4/(WSum) -> 1.4035088 | W11: =M11*Weight5/(WSum) -> 0 | X11: =N11*Weight6/(WSum) -> 0.73684211 | Y11: =O11*Weight7/(WSum) -> 0 | Z11: =P11*Weight8/(WSum) -> 1.0526316 | AA11: =-1/10*G11+1 -> 0.8 | AB11: =IF(R11<0,0,-R11+1) -> 1 | AC11: =(AA11*CondWeight+AB11*PLifeWeight)/(CondWeight+PLifeWeight) -> 0.86666667 | AD11: =SUM(S11:Z11) -> 5.8245614 | AE11: =AD11*AC11*10 -> 50.479532 | AF11: Bonding | AH11: 3000000 | AM11: =AH11 -> 3000000
A12: 8 | B12: Public Buildings | C12: Building | D12: Remove Underground Storage Tanks at City Buildings | E12: Remove tanks at Fire Station 10, City Hall, Police HQ, and Senior Center. Tanks are no longer needed. | F12: 125000 | G12: 1 | H12: 0 | I12: 5 | J12: 4 | K12: 5 | L12: 10 | M12: 5 | N12: 2 | O12: 2 | P12: 8 | Q12: =(#REF!-(YEAR(TODAY())-#REF!))/#REF! -> #REF! | R12: =IFERROR(Q12,H12) -> 0 | S12: =I12*Weight1/(WSum) -> 0.78947368 | T12: =J12*Weight2/(WSum) -> 0.42105263 | U12: =K12*Weight3/(WSum) -> 0.70175439 | V12: =L12*Weight4/(WSum) -> 1.754386 | W12: =M12*Weight5/(WSum) -> 0.43859649 | X12: =N12*Weight6/(WSum) -> 0.24561404 | Y12: =O12*Weight7/(WSum) -> 0.21052632 | Z12: =P12*Weight8/(WSum) -> 0.84210526 | AA12: =-1/10*G12+1 -> 0.9 | AB12: =IF(R12<0,0,-R12+1) -> 1 | AC12: =(AA12*CondWeight+AB12*PLifeWeight)/(CondWeight+PLifeWeight) -> 0.93333333 | AD12: =SUM(S12:Z12) -> 5.4035088 | AE12: =AD12*AC12*10 -> 50.432749 | AF12: Other | AH12: 125000 | AM12: =AH12 -> 125000
A13: 9 | B13: Fire Dept | C13: Building | D13: Fire Station #10 (Dedham Street) Renovation | E13: Project will address aging building systems, code upgrades, access and accommodations for female firefighters. | F13: 4252000 | G13: 3 | H13: 0.2 | I13: 8 | J13: 8 | K13: 5 | L13: 8 | M13: 6 | N13: 7 | O13: 4 | P13: 8 | Q13: =(#REF!-(YEAR(TODAY())-#REF!))/#REF! -> #REF! | R13: =IFERROR(Q13,H13) -> 0.2 | S13: =I13*Weight1/(WSum) -> 1.2631579 | T13: =J13*Weight2/(WSum) -> 0.84210526 | U13: =K13*Weight3/(WSum) -> 0.70175439 | V13: =L13*Weight4/(WSum) -> 1.4035088 | W13: =M13*Weight5/(WSum) -> 0.52631579 | X13: =N13*Weight6/(WSum) -> 0.85964912 | Y13: =O13*Weight7/(WSum) -> 0.42105263 | Z13: =P13*Weight8/(WSum) -> 0.84210526 | AA13: =-1/10*G13+1 -> 0.7 | AB13: =IF(R13<0,0,-R13+1) -> 0.8 | AC13: =(AA13*CondWeight+AB13*PLifeWeight)/(CondWeight+PLifeWeight) -> 0.73333333 | AD13: =SUM(S13:Z13) -> 6.8596491 | AE13: =AD13*AC13*10 -> 50.304094 | AF13: Bonding | AG13: 780000 | AH13: 3472000 | AM13: =AH13 -> 3472000
A14: 10 | B14: DPW | C14: Building | D14: Crafts Street Garage - Building Envelope & Roof Repair/ Replacemt | E14: Address active roof leaks and masonry gap. Repair flashing; replace roof with new EPDM Roof. FY13 design & ph 1 constr. FY14 phase 2 construction. | F14: 870000 | G14: 1 | H14: 0 | I14: 6 | J14: 4 | K14: 6 | L14: 7 | M14: 10 | N14: 1 | O14: 2 | P14: 7 | Q14: =(#REF!-(YEAR(TODAY())-#REF!))/#REF! -> #REF! | R14: =IFERROR(Q14,H14) -> 0 | S14: =I14*Weight1/(WSum) -> 0.94736842 | T14: =J14*Weight2/(WSum) -> 0.42105263 | U14: =K14*Weight3/(WSum) -> 0.84210526 | V14: =L14*Weight4/(WSum) -> 1.2280702 | W14: =M14*Weight5/(WSum) -> 0.87719298 | X14: =N14*Weight6/(WSum) -> 0.12280702 | Y14: =O14*Weight7/(WSum) -> 0.21052632 | Z14: =P14*Weight8/(WSum) -> 0.73684211 | AA14: =-1/10*G14+1 -> 0.9 | AB14: =IF(R14<0,0,-R14+1) -> 1 | AC14: =(AA14*CondWeight+AB14*PLifeWeight)/(CondWeight+PLifeWeight) -> 0.93333333 | AD14: =SUM(S14:Z14) -> 5.3859649 | AE14: =AD14*AC14*10 -> 50.269006 | AF14: Bonding | AG14: 260000 | AH14: 610000 | AM14: =AH14 -> 610000
A15: 11 | B15: Schools | C15: Building | D15: Cabot School - Renovation and Addition/Replacement | E15: FY14 feasibility study. Project will address aging systems, access, sprinklers, and space needs. Include cost to move to Carr and back to Cabot. Anticipate high maintenance costs on mechanical system until building is renovated. | F15: 37500000 | G15: 2 | H15: 0.1 | I15: 7 | J15: 8 | K15: 4 | L15: 6 | M15: 1 | N15: 8 | O15: 5 | P15: 8 | Q15: =(#REF!-(YEAR(TODAY())-#REF!))/#REF! -> #REF! | R15: =IFERROR(Q15,H15) -> 0.1 | S15: =I15*Weight1/(WSum) -> 1.1052632 | T15: =J15*Weight2/(WSum) -> 0.84210526 | U15: =K15*Weight3/(WSum) -> 0.56140351 | V15: =L15*Weight4/(WSum) -> 1.0526316 | W15: =M15*Weight5/(WSum) -> 0.087719298 | X15: =N15*Weight6/(WSum) -> 0.98245614 | Y15: =O15*Weight7/(WSum) -> 0.52631579 | Z15: =P15*Weight8/(WSum) -> 0.84210526 | AA15: =-1/10*G15+1 -> 0.8 | AB15: =IF(R15<0,0,-R15+1) -> 0.9 | AC15: =(AA15*CondWeight+AB15*PLifeWeight)/(CondWeight+PLifeWeight) -> 0.83333333 | AD15: =SUM(S15:Z15) -> 6 | AE15: =AD15*AC15*10 -> 50 | AF15: Bonding /MSBA | AH15: 750000 | AJ15: 14002660 | AK15: 20293711 | AM15: =AH15 -> 750000 | AO15: =AJ15*(1+Efactor)^2 -> 15000000 | AP15: =AK15*(1+Efactor)^3 -> 22500000
A16: 12 | B16: Fire Dept | C16: Large Vehicle/ Equipment | D16: Replace Fire Dept Rescue Truck and Rescue Boat | E16: Replace Special Ops. 1994 Ford (174K miles) Rescue truck needed for specialized rescue, with specialized tools and equipment. Special Ops gets taken out of service. | F16: 600000 | G16: 3 | H16: 0.1 | I16: 7 | J16: 7 | K16: 3 | L16: 10 | M16: 5 | N16: 8 | O16: 0 | P16: 10 | Q16: =(#REF!-(YEAR(TODAY())-#REF!))/#REF! -> #REF! | R16: =IFERROR(Q16,H16) -> 0.1 | S16: =I16*Weight1/(WSum) -> 1.1052632 | T16: =J16*Weight2/(WSum) -> 0.73684211 | U16: =K16*Weight3/(WSum) -> 0.42105263 | V16: =L16*Weight4/(WSum) -> 1.754386 | W16: =M16*Weight5/(WSum) -> 0.43859649 | X16: =N16*Weight6/(WSum) -> 0.98245614 | Y16: =O16*Weight7/(WSum) -> 0 | Z16: =P16*Weight8/(WSum) -> 1.0526316 | AA16: =-1/10*G16+1 -> 0.7 | AB16: =IF(R16<0,0,-R16+1) -> 0.9 | AC16: =(AA16*CondWeight+AB16*PLifeWeight)/(CondWeight+PLifeWeight) -> 0.76666667 | AD16: =SUM(S16:Z16) -> 6.4912281 | AE16: =AD16*AC16*10 -> 49.766082 | AF16: Other
A17: 13 | B17: DPW | C17: Roads/ Paving | D17: Street Paving - Cold Plane and Pave 21 Streets | E17: Streets include Lowell, Webster, Homer, Wolcott, Hawthone, Weldon, Bellevue, Summit, Lenox, Regent, Waban, Washington (2 sections), Morton, Hillside, Hunnewell, Country Club, Cross Hill, Saw Mill Brk, Carver, Randolph | F17: 2627240 | G17: 2 | H17: 0.1 | I17: 8 | J17: 8 | K17: 2 | L17: 6 | M17: 4 | N17: 9 | O17: 0 | P17: 10 | Q17: =(#REF!-(YEAR(TODAY())-#REF!))/#REF! -> #REF! | R17: =IFERROR(Q17,H17) -> 0.1 | S17: =I17*Weight1/(WSum) -> 1.2631579 | T17: =J17*Weight2/(WSum) -> 0.84210526 | U17: =K17*Weight3/(WSum) -> 0.28070175 | V17: =L17*Weight4/(WSum) -> 1.0526316 | W17: =M17*Weight5/(WSum) -> 0.35087719 | X17: =N17*Weight6/(WSum) -> 1.1052632 | Y17: =O17*Weight7/(WSum) -> 0 | Z17: =P17*Weight8/(WSum) -> 1.0526316 | AA17: =-1/10*G17+1 -> 0.8 | AB17: =IF(R17<0,0,-R17+1) -> 0.9 | AC17: =(AA17*CondWeight+AB17*PLifeWeight)/(CondWeight+PLifeWeight) -> 0.83333333 | AD17: =SUM(S17:Z17) -> 5.9473684 | AE17: =AD17*AC17*10 -> 49.561404 | AF17: Chapt 90/ Alt Funds | AH17: 2627240 | AM17: =AH17 -> 2627240
A18: 14 | B18: Schools | C18: Building | D18: Zervas and Bigelow School Electrical Upgrades | E18: Upgrades to electrical system and replace panels at Bigelow Middle School and Zervas Elemenatry School. | F18: 80000 | G18: 1 | H18: 0 | I18: 5 | J18: 8 | K18: 4 | L18: 7 | M18: 6 | N18: 5 | O18: 1 | P18: 6 | Q18: =(#REF!-(YEAR(TODAY())-#REF!))/#REF! -> #REF! | R18: =IFERROR(Q18,H18) -> 0 | S18: =I18*Weight1/(WSum) -> 0.78947368 | T18: =J18*Weight2/(WSum) -> 0.84210526 | U18: =K18*Weight3/(WSum) -> 0.56140351 | V18: =L18*Weight4/(WSum) -> 1.2280702 | W18: =M18*Weight5/(WSum) -> 0.52631579 | X18: =N18*Weight6/(WSum) -> 0.61403509 | Y18: =O18*Weight7/(WSum) -> 0.10526316 | Z18: =P18*Weight8/(WSum) -> 0.63157895 | AA18: =-1/10*G18+1 -> 0.9 | AB18: =IF(R18<0,0,-R18+1) -> 1 | AC18: =(AA18*CondWeight+AB18*PLifeWeight)/(CondWeight+PLifeWeight) -> 0.93333333 | AD18: =SUM(S18:Z18) -> 5.2982456 | AE18: =AD18*AC18*10 -> 49.450292 | AF18: Bonding | AH18: 80000 | AM18: =AH18 -> 80000
A19: 15 | B19: Schools | C19: Building | D19: Bowen School - Mechanical Upgrades | E19: Remove underground storage tank and replace or convert to gas if enough gas pressure. Leak detection system has failed. | F19: 100000 | G19: 1 | H19: 0 | I19: 5 | J19: 6 | K19: 4 | L19: 7 | M19: 6 | N19: 5 | O19: 2 | P19: 7 | Q19: =(#REF!-(YEAR(TODAY())-#REF!))/#REF! -> #REF! | R19: =IFERROR(Q19,H19) -> 0 | S19: =I19*Weight1/(WSum) -> 0.78947368 | T19: =J19*Weight2/(WSum) -> 0.63157895 | U19: =K19*Weight3/(WSum) -> 0.56140351 | V19: =L19*Weight4/(WSum) -> 1.2280702 | W19: =M19*Weight5/(WSum) -> 0.52631579 | X19: =N19*Weight6/(WSum) -> 0.61403509 | Y19: =O19*Weight7/(WSum) -> 0.21052632 | Z19: =P19*Weight8/(WSum) -> 0.73684211 | AA19: =-1/10*G19+1 -> 0.9 | AB19: =IF(R19<0,0,-R19+1) -> 1 | AC19: =(AA19*CondWeight+AB19*PLifeWeight)/(CondWeight+PLifeWeight) -> 0.93333333 | AD19: =SUM(S19:Z19) -> 5.2982456 | AE19: =AD19*AC19*10 -> 49.450292 | AF19: Bonding | AH19: 100000 | AM19: =AH19 -> 100000
A20: 16 | B20: DPW/ Water | C20: Water | D20: Clean and Line Water Pipes to Improve Water Quality | E20: Cleaning and lining of water pipes to improve water quality, ensure pipe integrity and capacity. Precedes scheduled roadway paving. | F20: 164000 | G20: 3 | H20: 0.1 | I20: 6 | J20: 6 | K20: 7 | L20: 8 | M20: 5 | N20: 8 | O20: 0 | P20: 10 | Q20: =(#REF!-(YEAR(TODAY())-#REF!))/#REF! -> #REF! | R20: =IFERROR(Q20,H20) -> 0.1 | S20: =I20*Weight1/(WSum) -> 0.94736842 | T20: =J20*Weight2/(WSum) -> 0.63157895 | U20: =K20*Weight3/(WSum) -> 0.98245614 | V20: =L20*Weight4/(WSum) -> 1.4035088 | W20: =M20*Weight5/(WSum) -> 0.43859649 | X20: =N20*Weight6/(WSum) -> 0.98245614 | Y20: =O20*Weight7/(WSum) -> 0 | Z20: =P20*Weight8/(WSum) -> 1.0526316 | AA20: =-1/10*G20+1 -> 0.7 | AB20: =IF(R20<0,0,-R20+1) -> 0.9 | AC20: =(AA20*CondWeight+AB20*PLifeWeight)/(CondWeight+PLifeWeight) -> 0.76666667 | AD20: =SUM(S20:Z20) -> 6.4385965 | AE20: =AD20*AC20*10 -> 49.362573 | AF20: Enterprise Funds | AH20: 164000 | AM20: =AH20 -> 164000
A21: 17 | B21: Public Buildings | C21: Building | D21: Energy Efficiency / Water Conservation Upgrades to City and School Buildings | E21: Project includes energy conservation measures at Library, Lincoln Eliot, Franklin, Underwood, Cabot Schools thru NSTAR preferred vendor program. | F21: 2000000 | G21: 3 | H21: 0.2 | I21: 6 | J21: 8 | K21: 8 | L21: 4 | M21: 0 | N21: 8 | O21: 10 | P21: 10 | Q21: =(#REF!-(YEAR(TODAY())-#REF!))/#REF! -> #REF! | R21: =IFERROR(Q21,H21) -> 0.2 | S21: =I21*Weight1/(WSum) -> 0.94736842 | T21: =J21*Weight2/(WSum) -> 0.84210526 | U21: =K21*Weight3/(WSum) -> 1.122807 | V21: =L21*Weight4/(WSum) -> 0.70175439 | W21: =M21*Weight5/(WSum) -> 0 | X21: =N21*Weight6/(WSum) -> 0.98245614 | Y21: =O21*Weight7/(WSum) -> 1.0526316 | Z21: =P21*Weight8/(WSum) -> 1.0526316 | AA21: =-1/10*G21+1 -> 0.7 | AB21: =IF(R21<0,0,-R21+1) -> 0.8 | AC21: =(AA21*CondWeight+AB21*PLifeWeight)/(CondWeight+PLifeWeight) -> 0.73333333 | AD21: =SUM(S21:Z21) -> 6.7017544 | AE21: =AD21*AC21*10 -> 49.146199 | AF21: Energy Stabilztn Fund | AG21: 1000000 | AH21: 1000000 | AM21: =AH21 -> 1000000
A22: 18 | B22: Senior Center | C22: Building | D22: Senior Center - Mechanical Upgrades | E22: Replace fans and air handling units. Change boiler burner to gas-fired. Replace basement fan coil unit. Improve operation & efficiency for consistent temp heating/cooling. | F22: 188000 | G22: 2 | H22: 0.1 | I22: 6 | J22: 8 | K22: 4 | L22: 6 | M22: 3 | N22: 7 | O22: 5 | P22: 8 | Q22: =(#REF!-(YEAR(TODAY())-#REF!))/#REF! -> #REF! | R22: =IFERROR(Q22,H22) -> 0.1 | S22: =I22*Weight1/(WSum) -> 0.94736842 | T22: =J22*Weight2/(WSum) -> 0.84210526 | U22: =K22*Weight3/(WSum) -> 0.56140351 | V22: =L22*Weight4/(WSum) -> 1.0526316 | W22: =M22*Weight5/(WSum) -> 0.26315789 | X22: =N22*Weight6/(WSum) -> 0.85964912 | Y22: =O22*Weight7/(WSum) -> 0.52631579 | Z22: =P22*Weight8/(WSum) -> 0.84210526 | AA22: =-1/10*G22+1 -> 0.8 | AB22: =IF(R22<0,0,-R22+1) -> 0.9 | AC22: =(AA22*CondWeight+AB22*PLifeWeight)/(CondWeight+PLifeWeight) -> 0.83333333 | AD22: =SUM(S22:Z22) -> 5.8947368 | AE22: =AD22*AC22*10 -> 49.122807 | AF22: Bonding | AH22: 188000 | AM22: =AH22 -> 188000
A23: 19 | B23: Schools | C23: Building | D23: Horace Mann - Add Classroom | E23: Additional classroom needed to address immediate space needs. Create new classroom within existing building footprint. | F23: 75000 | G23: 1 | H23: 0 | I23: 6 | J23: 8 | K23: 8 | L23: 3 | M23: 0 | N23: 8 | O23: 0 | P23: 8 | Q23: =(#REF!-(YEAR(TODAY())-#REF!))/#REF! -> #REF! | R23: =IFERROR(Q23,H23) -> 0 | S23: =I23*Weight1/(WSum) -> 0.94736842 | T23: =J23*Weight2/(WSum) -> 0.84210526 | U23: =K23*Weight3/(WSum) -> 1.122807 | V23: =L23*Weight4/(WSum) -> 0.52631579 | W23: =M23*Weight5/(WSum) -> 0 | X23: =N23*Weight6/(WSum) -> 0.98245614 | Y23: =O23*Weight7/(WSum) -> 0 | Z23: =P23*Weight8/(WSum) -> 0.84210526 | AA23: =-1/10*G23+1 -> 0.9 | AB23: =IF(R23<0,0,-R23+1) -> 1 | AC23: =(AA23*CondWeight+AB23*PLifeWeight)/(CondWeight+PLifeWeight) -> 0.93333333 | AD23: =SUM(S23:Z23) -> 5.2631579 | AE23: =AD23*AC23*10 -> 49.122807 | AF23: Other | AH23: 75000 | AM23: =AH23 -> 75000
A24: 20 | B24: DPW | C24: Roads/ Paving | D24: Repair / Improve Wales St. Bridge (Wellesley MOU) | E24: Repairs required in response to Mass DOT bridge inspection findings. Include new guardrails and bridge railings for height and impact safety requirements. Wellesley will bond their $400,000 share of cost. Approach sidewalks will be reconstructed. The approach roadway and bridge will also be cold-planed and paved. | F24: 400000 | G24: 2 | H24: 0 | I24: 5 | J24: 8 | K24: 4 | L24: 8 | M24: 7 | N24: 5 | O24: 0 | P24: 8 | Q24: =(#REF!-(YEAR(TODAY())-#REF!))/#REF! -> #REF! | R24: =IFERROR(Q24,H24) -> 0 | S24: =I24*Weight1/(WSum) -> 0.78947368 | T24: =J24*Weight2/(WSum) -> 0.84210526 | U24: =K24*Weight3/(WSum) -> 0.56140351 | V24: =L24*Weight4/(WSum) -> 1.4035088 | W24: =M24*Weight5/(WSum) -> 0.61403509 | X24: =N24*Weight6/(WSum) -> 0.61403509 | Y24: =O24*Weight7/(WSum) -> 0 | Z24: =P24*Weight8/(WSum) -> 0.84210526 | AA24: =-1/10*G24+1 -> 0.8 | AB24: =IF(R24<0,0,-R24+1) -> 1 | AC24: =(AA24*CondWeight+AB24*PLifeWeight)/(CondWeight+PLifeWeight) -> 0.86666667 | AD24: =SUM(S24:Z24) -> 5.6666667 | AE24: =AD24*AC24*10 -> 49.111111 | AF24: Chapt 90/ Alt Funds | AH24: 400000 | AM24: =AH24 -> 400000
A25: 21 | B25: DPW/ Sewer | C25: Sewer | D25: Islington Road Sewer Pump Station - Replace Pumps | E25: Sewerage is pumped to higher point and gravity fed to MWRA pipes for treatment. Replace pumps, motors and flow recorder which are at life expectancy. | F25: 100000 | G25: 3 | H25: 0.1 | I25: 6 | J25: 8 | K25: 6 | L25: 8 | M25: 4 | N25: 6 | O25: 2 | P25: 10 | Q25: =(#REF!-(YEAR(TODAY())-#REF!))/#REF! -> #REF! | R25: =IFERROR(Q25,H25) -> 0.1 | S25: =I25*Weight1/(WSum) -> 0.94736842 | T25: =J25*Weight2/(WSum) -> 0.84210526 | U25: =K25*Weight3/(WSum) -> 0.84210526 | V25: =L25*Weight4/(WSum) -> 1.4035088 | W25: =M25*Weight5/(WSum) -> 0.35087719 | X25: =N25*Weight6/(WSum) -> 0.73684211 | Y25: =O25*Weight7/(WSum) -> 0.21052632 | Z25: =P25*Weight8/(WSum) -> 1.0526316 | AA25: =-1/10*G25+1 -> 0.7 | AB25: =IF(R25<0,0,-R25+1) -> 0.9 | AC25: =(AA25*CondWeight+AB25*PLifeWeight)/(CondWeight+PLifeWeight) -> 0.76666667 | AD25: =SUM(S25:Z25) -> 6.3859649 | AE25: =AD25*AC25*10 -> 48.959064 | AF25: Enterprise Funds | AH25: 100000 | AM25: =AH25 -> 100000
A26: 22 | B26: Schools | C26: Building | D26: Ed Center - Pre-K Building Upgrades | E26: Renovate toilet rooms for Pre-school and other improvements to correct water infiltration issues and address HVAC and space needs. | F26: 1000000 | G26: 2 | H26: 0 | I26: 6 | J26: 8 | K26: 4 | L26: 6 | M26: 4 | N26: 6 | O26: 1 | P26: 10 | Q26: =(#REF!-(YEAR(TODAY())-#REF!))/#REF! -> #REF! | R26: =IFERROR(Q26,H26) -> 0 | S26: =I26*Weight1/(WSum) -> 0.94736842 | T26: =J26*Weight2/(WSum) -> 0.84210526 | U26: =K26*Weight3/(WSum) -> 0.56140351 | V26: =L26*Weight4/(WSum) -> 1.0526316 | W26: =M26*Weight5/(WSum) -> 0.35087719 | X26: =N26*Weight6/(WSum) -> 0.73684211 | Y26: =O26*Weight7/(WSum) -> 0.10526316 | Z26: =P26*Weight8/(WSum) -> 1.0526316 | AA26: =-1/10*G26+1 -> 0.8 | AB26: =IF(R26<0,0,-R26+1) -> 1 | AC26: =(AA26*CondWeight+AB26*PLifeWeight)/(CondWeight+PLifeWeight) -> 0.86666667 | AD26: =SUM(S26:Z26) -> 5.6491228 | AE26: =AD26*AC26*10 -> 48.959064 | AF26: Bonding | AH26: 1000000 | AM26: =AH26 -> 1000000
A27: 23 | B27: Parks/Rec | C27: Building | D27: Lower Falls Community Center - Accessibility/ Site Upgrades | E27: Code required project to provide accessible toilet rooms, an accessible drinking fountain, and lift for access to the lower gym level. | F27: 300000 | G27: 1 | H27: 0.1 | I27: 4 | J27: 8 | K27: 2 | L27: 10 | M27: 0 | N27: 8 | O27: 0 | P27: 9 | Q27: =(#REF!-(YEAR(TODAY())-#REF!))/#REF! -> #REF! | R27: =IFERROR(Q27,H27) -> 0.1 | S27: =I27*Weight1/(WSum) -> 0.63157895 | T27: =J27*Weight2/(WSum) -> 0.84210526 | U27: =K27*Weight3/(WSum) -> 0.28070175 | V27: =L27*Weight4/(WSum) -> 1.754386 | W27: =M27*Weight5/(WSum) -> 0 | X27: =N27*Weight6/(WSum) -> 0.98245614 | Y27: =O27*Weight7/(WSum) -> 0 | Z27: =P27*Weight8/(WSum) -> 0.94736842 | AA27: =-1/10*G27+1 -> 0.9 | AB27: =IF(R27<0,0,-R27+1) -> 0.9 | AC27: =(AA27*CondWeight+AB27*PLifeWeight)/(CondWeight+PLifeWeight) -> 0.9 | AD27: =SUM(S27:Z27) -> 5.4385965 | AE27: =AD27*AC27*10 -> 48.947368 | AF27: Bonding | AG27: 25000 | AH27: 275000 | AM27: =AH27 -> 275000
A28: 24 | B28: Schools | C28: Building | D28: Ward School - Accessible Entrance | E28: Code required project to provide accessible entrance, toilet, and water fountain. | F28: 200000 | G28: 1 | H28: 0.1 | I28: 4 | J28: 8 | K28: 2 | L28: 10 | M28: 0 | N28: 8 | O28: 0 | P28: 9 | Q28: =(#REF!-(YEAR(TODAY())-#REF!))/#REF! -> #REF! | R28: =IFERROR(Q28,H28) -> 0.1 | S28: =I28*Weight1/(WSum) -> 0.63157895 | T28: =J28*Weight2/(WSum) -> 0.84210526 | U28: =K28*Weight3/(WSum) -> 0.28070175 | V28: =L28*Weight4/(WSum) -> 1.754386 | W28: =M28*Weight5/(WSum) -> 0 | X28: =N28*Weight6/(WSum) -> 0.98245614 | Y28: =O28*Weight7/(WSum) -> 0 | Z28: =P28*Weight8/(WSum) -> 0.94736842 | AA28: =-1/10*G28+1 -> 0.9 | AB28: =IF(R28<0,0,-R28+1) -> 0.9 | AC28: =(AA28*CondWeight+AB28*PLifeWeight)/(CondWeight+PLifeWeight) -> 0.9 | AD28: =SUM(S28:Z28) -> 5.4385965 | AE28: =AD28*AC28*10 -> 48.947368 | AF28: Bonding | AH28: 200000 | AM28: =AH28 -> 200000
A29: 25 | B29: IT | C29: Information Technology | D29: Install Citywide IT Data Network | E29: IT Advisory Cmte recommends implementation of City-wide network as high priority imperative to improve speed, reliability, and security to build the framework for major improvements and expansion of the City's IT capabilities in areas such as electronic storage and retrieval, disaster recovery, integrated > data warehouse and electronic workflow systems resulting in improved > work efficiencies and expansion of services network connections. | F29: 1750000 | G29: 3 | H29: 0.2 | I29: 10 | J29: 10 | K29: 6 | L29: 6 | M29: 0 | N29: 8 | O29: 1 | P29: 10 | Q29: =(#REF!-(YEAR(TODAY())-#REF!))/#REF! -> #REF! | R29: =IFERROR(Q29,H29) -> 0.2 | S29: =I29*Weight1/(WSum) -> 1.5789474 | T29: =J29*Weight2/(WSum) -> 1.0526316 | U29: =K29*Weight3/(WSum) -> 0.84210526 | V29: =L29*Weight4/(WSum) -> 1.0526316 | W29: =M29*Weight5/(WSum) -> 0 | X29: =N29*Weight6/(WSum) -> 0.98245614 | Y29: =O29*Weight7/(WSum) -> 0.10526316 | Z29: =P29*Weight8/(WSum) -> 1.0526316 | AA29: =-1/10*G29+1 -> 0.7 | AB29: =IF(R29<0,0,-R29+1) -> 0.8 | AC29: =(AA29*CondWeight+AB29*PLifeWeight)/(CondWeight+PLifeWeight) -> 0.73333333 | AD29: =SUM(S29:Z29) -> 6.6666667 | AE29: =AD29*AC29*10 -> 48.888889 | AF29: Other | AG29: 500000 | AH29: 250000 | AI29: 250000 | AJ29: 250000 | AK29: 250000 | AL29: 250000 | AM29: =AH29 -> 250000 | AN29: =AI29*(1+Efactor) -> 258750 | AO29: =AJ29*(1+Efactor)^2 -> 267806.25 | AP29: =AK29*(1+Efactor)^3 -> 277179.47 | AQ29: =AL29*(1+Efactor)^4 -> 286880.75
A30: 26 | B30: Parks/Rec | C30: Parks / Open Space | D30: Crystal Lake - Water Filtration System | E30: Upgrade water filtration system to mitigate algea. | F30: 100000 | G30: 2 | H30: 0 | I30: 5 | J30: 8 | K30: 3 | L30: 8 | M30: 0 | N30: 9 | O30: 0 | P30: 10 | Q30: =(#REF!-(YEAR(TODAY())-#REF!))/#REF! -> #REF! | R30: =IFERROR(Q30,H30) -> 0 | S30: =I30*Weight1/(WSum) -> 0.78947368 | T30: =J30*Weight2/(WSum) -> 0.84210526 | U30: =K30*Weight3/(WSum) -> 0.42105263 | V30: =L30*Weight4/(WSum) -> 1.4035088 | W30: =M30*Weight5/(WSum) -> 0 | X30: =N30*Weight6/(WSum) -> 1.1052632 | Y30: =O30*Weight7/(WSum) -> 0 | Z30: =P30*Weight8/(WSum) -> 1.0526316 | AA30: =-1/10*G30+1 -> 0.8 | AB30: =IF(R30<0,0,-R30+1) -> 1 | AC30: =(AA30*CondWeight+AB30*PLifeWeight)/(CondWeight+PLifeWeight) -> 0.86666667 | AD30: =SUM(S30:Z30) -> 5.6140351 | AE30: =AD30*AC30*10 -> 48.654971 | AF30: Bonding | AH30: 100000 | AM30: =AH30 -> 100000
A31: 27 | B31: DPW | C31: Large Vehicle/ Equipment | D31: DPW - Replace Street Sweeper | E31: Replacement of vehicle taken out of service: Vehicle #148. Dept will not have minimum (6 ea) needed for 4 sweeps/yr efficiently. Contracting out services is alternative at great expense. | F31: 172000 | G31: 1 | H31: 0 | I31: 6 | J31: 8 | K31: 6 | L31: 5 | M31: 0 | N31: 7 | O31: 0 | P31: 8 | Q31: =(#REF!-(YEAR(TODAY())-#REF!))/#REF! -> #REF! | R31: =IFERROR(Q31,H31) -> 0 | S31: =I31*Weight1/(WSum) -> 0.94736842 | T31: =J31*Weight2/(WSum) -> 0.84210526 | U31: =K31*Weight3/(WSum) -> 0.84210526 | V31: =L31*Weight4/(WSum) -> 0.87719298 | W31: =M31*Weight5/(WSum) -> 0 | X31: =N31*Weight6/(WSum) -> 0.85964912 | Y31: =O31*Weight7/(WSum) -> 0 | Z31: =P31*Weight8/(WSum) -> 0.84210526 | AA31: =-1/10*G31+1 -> 0.9 | AB31: =IF(R31<0,0,-R31+1) -> 1 | AC31: =(AA31*CondWeight+AB31*PLifeWeight)/(CondWeight+PLifeWeight) -> 0.93333333 | AD31: =SUM(S31:Z31) -> 5.2105263 | AE31: =AD31*AC31*10 -> 48.631579 | AF31: Bonding | AH31: 172000 | AM31: =AH31 -> 172000
A32: 28 | B32: DPW/ Water | C32: Large Vehicle/ Equipment | D32: Replace 2002 Construction Truck | E32: Replacement of existing city vehicle used for construction work on City water mains and for snow removal/sanding operations. Life span of vehicles is 15 yrs. (#309) | F32: 130000 | G32: 1 | H32: 0 | I32: 6 | J32: 6 | K32: 5 | L32: 7 | M32: 4 | N32: 5 | O32: 1 | P32: 6 | Q32: =(#REF!-(YEAR(TODAY())-#REF!))/#REF! -> #REF! | R32: =IFERROR(Q32,H32) -> 0 | S32: =I32*Weight1/(WSum) -> 0.94736842 | T32: =J32*Weight2/(WSum) -> 0.63157895 | U32: =K32*Weight3/(WSum) -> 0.70175439 | V32: =L32*Weight4/(WSum) -> 1.2280702 | W32: =M32*Weight5/(WSum) -> 0.35087719 | X32: =N32*Weight6/(WSum) -> 0.61403509 | Y32: =O32*Weight7/(WSum) -> 0.10526316 | Z32: =P32*Weight8/(WSum) -> 0.63157895 | AA32: =-1/10*G32+1 -> 0.9 | AB32: =IF(R32<0,0,-R32+1) -> 1 | AC32: =(AA32*CondWeight+AB32*PLifeWeight)/(CondWeight+PLifeWeight) -> 0.93333333 | AD32: =SUM(S32:Z32) -> 5.2105263 | AE32: =AD32*AC32*10 -> 48.631579 | AF32: Enterprise Funds | AH32: 130000 | AM32: =AH32 -> 130000
A33: 29 | B33: DPW/ Sewer | C33: Sewer | D33: Elliot Street Sewer Pump Station - Repair Pumps | E33: Sewerage is pumped to higher point and gravity fed to MWRA pipes for treatment. Replace pumps and flow recorder which are at life expectancy. | F33: 100000 | G33: 2 | H33: 0.2 | I33: 6 | J33: 8 | K33: 6 | L33: 8 | M33: 4 | N33: 6 | O33: 1 | P33: 8 | Q33: =(#REF!-(YEAR(TODAY())-#REF!))/#REF! -> #REF! | R33: =IFERROR(Q33,H33) -> 0.2 | S33: =I33*Weight1/(WSum) -> 0.94736842 | T33: =J33*Weight2/(WSum) -> 0.84210526 | U33: =K33*Weight3/(WSum) -> 0.84210526 | V33: =L33*Weight4/(WSum) -> 1.4035088 | W33: =M33*Weight5/(WSum) -> 0.35087719 | X33: =N33*Weight6/(WSum) -> 0.73684211 | Y33: =O33*Weight7/(WSum) -> 0.10526316 | Z33: =P33*Weight8/(WSum) -> 0.84210526 | AA33: =-1/10*G33+1 -> 0.8 | AB33: =IF(R33<0,0,-R33+1) -> 0.8 | AC33: =(AA33*CondWeight+AB33*PLifeWeight)/(CondWeight+PLifeWeight) -> 0.8 | AD33: =SUM(S33:Z33) -> 6.0701754 | AE33: =AD33*AC33*10 -> 48.561404 | AF33: Enterprise Funds | AH33: 100000 | AM33: =AH33 -> 100000
A34: 30 | B34: DPW/ Sewer | C34: Large Vehicle/ Equipment | D34: Replace 2003 Backhoe | E34: Replacement of existing city vehicle/ equipment used in sewer line repairs and maintenance (#327). | F34: 120000 | G34: 3 | H34: 0 | I34: 6 | J34: 8 | K34: 6 | L34: 8 | M34: 4 | N34: 6 | O34: 1 | P34: 8 | Q34: =(#REF!-(YEAR(TODAY())-#REF!))/#REF! -> #REF! | R34: =IFERROR(Q34,H34) -> 0 | S34: =I34*Weight1/(WSum) -> 0.94736842 | T34: =J34*Weight2/(WSum) -> 0.84210526 | U34: =K34*Weight3/(WSum) -> 0.84210526 | V34: =L34*Weight4/(WSum) -> 1.4035088 | W34: =M34*Weight5/(WSum) -> 0.35087719 | X34: =N34*Weight6/(WSum) -> 0.73684211 | Y34: =O34*Weight7/(WSum) -> 0.10526316 | Z34: =P34*Weight8/(WSum) -> 0.84210526 | AA34: =-1/10*G34+1 -> 0.7 | AB34: =IF(R34<0,0,-R34+1) -> 1 | AC34: =(AA34*CondWeight+AB34*PLifeWeight)/(CondWeight+PLifeWeight) -> 0.8 | AD34: =SUM(S34:Z34) -> 6.0701754 | AE34: =AD34*AC34*10 -> 48.561404 | AF34: Enterprise Funds | AH34: 120000 | AM34: =AH34 -> 120000
A35: 31 | B35: DPW/ Sewer | C35: Large Vehicle/ Equipment | D35: Replace 2004 Sewer Clam Truck | E35: Replacement of damaged city vehicle/ equipment used to clean sewer catch basins and brook grates. (#330) | F35: 200000 | G35: 3 | H35: 0 | I35: 6 | J35: 8 | K35: 6 | L35: 8 | M35: 4 | N35: 6 | O35: 1 | P35: 8 | Q35: =(#REF!-(YEAR(TODAY())-#REF!))/#REF! -> #REF! | R35: =IFERROR(Q35,H35) -> 0 | S35: =I35*Weight1/(WSum) -> 0.94736842 | T35: =J35*Weight2/(WSum) -> 0.84210526 | U35: =K35*Weight3/(WSum) -> 0.84210526 | V35: =L35*Weight4/(WSum) -> 1.4035088 | W35: =M35*Weight5/(WSum) -> 0.35087719 | X35: =N35*Weight6/(WSum) -> 0.73684211 | Y35: =O35*Weight7/(WSum) -> 0.10526316 | Z35: =P35*Weight8/(WSum) -> 0.84210526 | AA35: =-1/10*G35+1 -> 0.7 | AB35: =IF(R35<0,0,-R35+1) -> 1 | AC35: =(AA35*CondWeight+AB35*PLifeWeight)/(CondWeight+PLifeWeight) -> 0.8 | AD35: =SUM(S35:Z35) -> 6.0701754 | AE35: =AD35*AC35*10 -> 48.561404 | AF35: Enterprise Funds | AH35: 200000 | AM35: =AH35 -> 200000
A36: 32 | B36: Schools | C36: Building | D36: Zervas School - Renovation and Addition/ Replacement | E36: FY14 feasibility study. Project to address space needs due to growing enrollment, bldg systems, access. Include cost to move to Carr and back to Zervas Anticipate high maintenance costs on mechanical system until building is renovated. | F36: 42500000 | G36: 3 | H36: 0 | I36: 8 | J36: 10 | K36: 4 | L36: 4 | M36: 0 | N36: 10 | O36: 2 | P36: 10 | Q36: =(#REF!-(YEAR(TODAY())-#REF!))/#REF! -> #REF! | R36: =IFERROR(Q36,H36) -> 0 | S36: =I36*Weight1/(WSum) -> 1.2631579 | T36: =J36*Weight2/(WSum) -> 1.0526316 | U36: =K36*Weight3/(WSum) -> 0.56140351 | V36: =L36*Weight4/(WSum) -> 0.70175439 | W36: =M36*Weight5/(WSum) -> 0 | X36: =N36*Weight6/(WSum) -> 1.2280702 | Y36: =O36*Weight7/(WSum) -> 0.21052632 | Z36: =P36*Weight8/(WSum) -> 1.0526316 | AA36: =-1/10*G36+1 -> 0.7 | AB36: =IF(R36<0,0,-R36+1) -> 1 | AC36: =(AA36*CondWeight+AB36*PLifeWeight)/(CondWeight+PLifeWeight) -> 0.8 | AD36: =SUM(S36:Z36) -> 6.0701754 | AE36: =AD36*AC36*10 -> 48.561404 | AF36: Bonding /MSBA | AH36: 750000 | AL36: 15250239 | AM36: =AH36 -> 750000 | AQ36: =AL36*(1+Efactor)^4 -> 17500000
A37: 33 | B37: DPW | C37: Large Vehicle/ Equipment | D37: DPW - Replace 1995 Backhoe | E37: Replacement of existing city vehicle/ equipment that is beyond useful life, used for street & sidewalk repairs. (#130). | F37: 110000 | G37: 2 | H37: 0.1 | I37: 7 | J37: 8 | K37: 6 | L37: 6 | M37: 2 | N37: 6 | O37: 0 | P37: 10 | Q37: =(#REF!-(YEAR(TODAY())-#REF!))/#REF! -> #REF! | R37: =IFERROR(Q37,H37) -> 0.1 | S37: =I37*Weight1/(WSum) -> 1.1052632 | T37: =J37*Weight2/(WSum) -> 0.84210526 | U37: =K37*Weight3/(WSum) -> 0.84210526 | V37: =L37*Weight4/(WSum) -> 1.0526316 | W37: =M37*Weight5/(WSum) -> 0.1754386 | X37: =N37*Weight6/(WSum) -> 0.73684211 | Y37: =O37*Weight7/(WSum) -> 0 | Z37: =P37*Weight8/(WSum) -> 1.0526316 | AA37: =-1/10*G37+1 -> 0.8 | AB37: =IF(R37<0,0,-R37+1) -> 0.9 | AC37: =(AA37*CondWeight+AB37*PLifeWeight)/(CondWeight+PLifeWeight) -> 0.83333333 | AD37: =SUM(S37:Z37) -> 5.8070175 | AE37: =AD37*AC37*10 -> 48.391813 | AF37: Bonding | AH37: 110000 | AM37: =AH37 -> 110000
A38: 34 | B38: DPW/ Sewer | C38: Sewer | D38: Sewer Inflow /Infiltration Project - Lower Falls Area | E38: Part of 12 yr $49.1 M program to remove excess inflow and infiltration into sewer system. Design (FY14) and constr (FY15) for Lower Falls area. | F38: 3861585 | G38: 3 | H38: 0.3 | I38: 8 | J38: 8 | K38: 8 | L38: 8 | M38: 4 | N38: 8 | O38: 0 | P38: 9 | Q38: =(#REF!-(YEAR(TODAY())-#REF!))/#REF! -> #REF! | R38: =IFERROR(Q38,H38) -> 0.3 | S38: =I38*Weight1/(WSum) -> 1.2631579 | T38: =J38*Weight2/(WSum) -> 0.84210526 | U38: =K38*Weight3/(WSum) -> 1.122807 | V38: =L38*Weight4/(WSum) -> 1.4035088 | W38: =M38*Weight5/(WSum) -> 0.35087719 | X38: =N38*Weight6/(WSum) -> 0.98245614 | Y38: =O38*Weight7/(WSum) -> 0 | Z38: =P38*Weight8/(WSum) -> 0.94736842 | AA38: =-1/10*G38+1 -> 0.7 | AB38: =IF(R38<0,0,-R38+1) -> 0.7 | AC38: =(AA38*CondWeight+AB38*PLifeWeight)/(CondWeight+PLifeWeight) -> 0.7 | AD38: =SUM(S38:Z38) -> 6.9122807 | AE38: =AD38*AC38*10 -> 48.385965 | AF38: Enterprise Funds | AH38: 523710 | AI38: 3337875 | AM38: =AH38 -> 523710 | AN38: =AI38*(1+Efactor) -> 3454700.6
A39: 35 | B39: DPW/ Water | C39: Water | D39: Replace Water Pipes to Improve Fire Flows | E39: Year three of 3 year program to replace and repair water pipes in order to meet ISO fire flow standards which are currently defficient. | F39: 4209000 | G39: 2 | H39: 0.3 | I39: 6 | J39: 6 | K39: 8 | L39: 8 | M39: 7 | N39: 6 | O39: 0 | P39: 8 | Q39: =(#REF!-(YEAR(TODAY())-#REF!))/#REF! -> #REF! | R39: =IFERROR(Q39,H39) -> 0.3 | S39: =I39*Weight1/(WSum) -> 0.94736842 | T39: =J39*Weight2/(WSum) -> 0.63157895 | U39: =K39*Weight3/(WSum) -> 1.122807 | V39: =L39*Weight4/(WSum) -> 1.4035088 | W39: =M39*Weight5/(WSum) -> 0.61403509 | X39: =N39*Weight6/(WSum) -> 0.73684211 | Y39: =O39*Weight7/(WSum) -> 0 | Z39: =P39*Weight8/(WSum) -> 0.84210526 | AA39: =-1/10*G39+1 -> 0.8 | AB39: =IF(R39<0,0,-R39+1) -> 0.7 | AC39: =(AA39*CondWeight+AB39*PLifeWeight)/(CondWeight+PLifeWeight) -> 0.76666667 | AD39: =SUM(S39:Z39) -> 6.2982456 | AE39: =AD39*AC39*10 -> 48.28655 | AF39: Enterprise Funds | AI39: 4209000 | AN39: =AI39*(1+Efactor) -> 4356315
A40: 36 | B40: Schools | C40: Building | D40: Peirce School - Mechanical Upgrades | E40: Replace one 60 yo boiler and associated systems. 2nd boiler and DDC conversion in future project. Remove underground tank. | F40: 240000 | G40: 3 | H40: 0 | I40: 6 | J40: 8 | K40: 6 | L40: 4 | M40: 3 | N40: 7 | O40: 7 | P40: 8 | Q40: =(#REF!-(YEAR(TODAY())-#REF!))/#REF! -> #REF! | R40: =IFERROR(Q40,H40) -> 0 | S40: =I40*Weight1/(WSum) -> 0.94736842 | T40: =J40*Weight2/(WSum) -> 0.84210526 | U40: =K40*Weight3/(WSum) -> 0.84210526 | V40: =L40*Weight4/(WSum) -> 0.70175439 | W40: =M40*Weight5/(WSum) -> 0.26315789 | X40: =N40*Weight6/(WSum) -> 0.85964912 | Y40: =O40*Weight7/(WSum) -> 0.73684211 | Z40: =P40*Weight8/(WSum) -> 0.84210526 | AA40: =-1/10*G40+1 -> 0.7 | AB40: =IF(R40<0,0,-R40+1) -> 1 | AC40: =(AA40*CondWeight+AB40*PLifeWeight)/(CondWeight+PLifeWeight) -> 0.8 | AD40: =SUM(S40:Z40) -> 6.0350877 | AE40: =AD40*AC40*10 -> 48.280702 | AF40: Bonding | AI40: 240000 | AN40: =AI40*(1+Efactor) -> 248400
...

Sheet Lists
A1: % Life Left | B1: Overall Condition | C1: Description | D1: Consequence | E1: Description | F1: Funding Source
A2: 0 | B2: 0 | C2: Deplorable | D2: 0 | E2: No Impact | F2: Bonding
A3: 0.1 | B3: 1 | C3: Very bad | D3: 1 | F3: Chapt 90/ Alt Funds
A4: 0.2 | B4: 2 | C4: Bad | D4: 2 | E4: Small Impact | F4: Bonding/MSBA
A5: 0.3 | B5: 3 | C5: Poor | D5: 3 | F5: CDBG Eligible
A6: 0.4 | B6: 4 | C6: Slightly below average | D6: 4 | F6: Alternate Funding
A7: 0.5 | B7: 5 | C7: Average | D7: 5 | E7: Moderate Impact | F7: CPA Eligible
A8: 0.6 | B8: 6 | C8: Slightly above average | D8: 6 | F8: Energy Stab. Fund
A9: 0.7 | B9: 7 | C9: Fair | D9: 7 | F9: Enterprise Funds
A10: 0.8 | B10: 8 | C10: Good | D10: 8 | E10: High Impact | F10: Grant
A11: 0.9 | B11: 9 | C11: Very good | D11: 9 | F11: Other
A12: 1 | B12: 10 | C12: Excellent | D12: 10 | E12: Very High Impact

Sheet 20 Year Plan
A1: City of Newton 20 Year Long Range Capital Projection | Q1: 10.9.12
A2: Cost estimates include 3.5% escalation.
A3: ASSET TYPES | D3: FY14 | E3: FY15 | F3: FY16 | G3: FY17 | H3: FY18 | I3: FY14-FY18 CIP | J3: FY19-FY23 CIP | K3: FY19-FY23 CIP | L3: FY24-FY28 CIP | M3: FY24-FY28 CIP | N3: FY29-FY33 CIP | O3: FY29-FY33 CIP | P3: 20 YEAR TOTAL | Q3: NOTES
A4: BUILDINGS
B5: SCHOOLS
B6: Carr Elementary
C7: Carr Mechanical
C8: Generation - Boiler, Chiller
C9: Generation - Air handlers
C10: Distribution
C11: Controls / EMS
C12: Underground Tanks
C13: Carr Electrical/Alt Energy
C14: Emergency Generator
C15: Switch Gear / Panels
C16: Distribution
C17: Lighting and Controls | N17: 150000 | O17: =N17*1.73 -> 259500 | P17: =SUM(I17,K17,M17,O17) -> 259500
C18: Carr Plumbing + Fire Protection
C19: Pumps
C20: Distribution
C21: Fixtures
C22: Sprinklers/Fire Alarm
C23: Carr Building Envelope
C24: Masonry/Walls
C25: Windows & Doors
C26: Roof
C27: Entrance Stairs/Ramps
C28: Carr Building Interior
C29: Stairs / Elevators
C30: Finishes (Flrs, Walls, Ceilgs) | J30: 100000 | K30: =J30*1.23 -> 123000 | P30: =SUM(I30,K30,M30,O30) -> 123000 | Q30: Gym Floor
C31: Equipment/Furnishing
C32: Other-Renovation Project | D32: =CIP!$AM$6 -> 11700000 | I32: =SUM(D32:H32) -> 11700000 | P32: =SUM(I32,K32,M32,O32) -> 11700000 | Q32: incl. roof & windows
C33: Carr Elementary | D33: =SUM(D6:D32) -> 11700000 | I33: =SUM(I6:I32) -> 11700000 | J33: =SUM(J6:J32) -> 100000 | K33: =J33*1.23 -> 123000 | N33: =SUM(N6:N32) -> 150000 | O33: =N33*1.73 -> 259500 | P33: =SUM(I33,K33,M33,O33) -> 12082500 | Q33: Carr Reno Total $12.7M
B34: Angier Elementary
C35: Mechanical
C36: Generation - Boiler, Chiller
C37: Generation - Air handlers
C38: Distribution
C39: Controls / EMS
C40: Underground Tanks
...
