Workbook
Name a: #REF!
Name asdf: #REF!
Name asdf: #REF!
Name asdf: #REF!
Name bnm: #REF!
Name bnm: #REF!
Name bnm: #REF!
Name Initial: #REF!
Name Initial: #REF!
Name Initial: #REF!
Name MSN_MoneyCentral_Investor_Stock_Quotes: 'Holdings Pull Sheet'!$C$9:$R$63
Name portbeg: #REF!
Name portbeg: #REF!
Name portbeg: #REF!
Name qwer: #REF!
Name qwer: #REF!
Name qwer: #REF!
Name s: #REF!
Name Sheet: #REF!
Name Sheet: #REF!
Name Sheet: #REF!
Name SP: #REF!
Name SP: #REF!
Name SP: #REF!
Name spbeg: #REF!
Name spbeg: #REF!
Name spbeg: #REF!
Name vb: #REF!
Name vb: #REF!
Name vb: #REF!
Name WINBEG: #REF!
Name WINBEG: #REF!
Name WINBEG: #REF!
Name WINSP: #REF!
Name WINSP: #REF!
Name WINSP: #REF!
Name zxc: #REF!
Name zxc: #REF!
Name zxc: #REF!

Sheet Summary
L3: Summer | S3: 1 Week | Z3: Today | AG3: Total Value | AH3: =Holdings!$H$22 -> 51169.51
L4: IPO | M4: =Holdings!$Q$22 -> 0.09995134 | S4: IPO | T4: =Holdings!$R$22 -> 0.017372717 | Z4: IPO | AA4: =Holdings!$S$22 -> 0.017093027 | AG4: Cost Basis | AH4: =Holdings!$I$22 -> 33209.83
L6: S&P 500 | M6: =('Holdings Pull Sheet'!$F$14/Data!$L$511)-1 -> 0.032299579 | S6: S&P 500 | T6: =('Holdings Pull Sheet'!$F$14/Data!$L$517)-1 -> 0.0085672374 | Z6: S&P 500 | AA6: =('Holdings Pull Sheet'!$F$14/'Holdings Pull Sheet'!$G$14)-1 -> 0.014784313 | AG6: Return since 5/02/03 | AH6: =Holdings!$O$22 -> 1.2387927
L8: Dow Jones | M8: =('Holdings Pull Sheet'!$F$12/Data!$S$511)-1 -> 0.032330213 | S8: Dow Jones | T8: =('Holdings Pull Sheet'!$F12/Data!$S517)-1 -> 0.0090217075 | Z8: Dow Jones | AA8: =('Holdings Pull Sheet'!$F$12/'Holdings Pull Sheet'!$G$12)-1 -> 0.012060502 | AE8: Cash Availailable | AH8: =Holdings!$H$4 -> 8114.57
AE9: % of Portfolio | AH9: =Holdings!$U$4 -> 0.15858213
C13: =Holdings!$C$5 -> Berkshire Hathaway | F13: =Holdings!$E$5 -> 114.99 | J13: =Holdings!$C$9 -> Cisco | M13: =Holdings!$E$9 -> 24.35 | Q13: =Holdings!$C$13 -> Immersion | T13: =Holdings!$E$13 -> 14.91 | X13: =Holdings!$C$17 -> Tutor Perini | AA13: =Holdings!$E$17 -> 17.43 | AE13: =Holdings!$C$21 -> YRC Worldwide | AH13: =Holdings!$E$21 -> 22.6
C15: =Holdings!$D$5 -> BRK.B | E15: Today | F15: =Holdings!$S$5 -> 0.018061089 | J15: =Holdings!$D$9 -> CSCO | L15: Today | M15: =Holdings!$S$9 -> 0.015006253 | Q15: =Holdings!$D$13 -> IMMR | S15: Today | T15: =Holdings!$S$13 -> 0.044849334 | X15: =Holdings!$D$17 -> TPC | Z15: Today | AA15: =Holdings!$S$17 -> 0.013914317 | AE15: =Holdings!$D$21 -> YRCW | AG15: Today | AH15: =Holdings!$S$21 -> 0.018539977
E16: 1 Week | F16: =Holdings!$R$5 -> 0.016710875 | L16: 1 Week | M16: =Holdings!$R$9 -> -0.0081466395 | S16: 1 Week | T16: =Holdings!$R$13 -> 0.026859504 | Z16: 1 Week | AA16: =Holdings!$R$17 -> 0.004610951 | AG16: 1 Week | AH16: =Holdings!$R$21 -> 0.17219917
E17: Summer | F17: =Holdings!$Q$5 -> 0.069973016 | L17: =$E$17 -> Summer | M17: =Holdings!$Q$9 -> 0.1894654 | S17: =$E$17 -> Summer | T17: =Holdings!$Q$13 -> -0.0090828533 | Z17: =$E$17 -> Summer | AA17: =Holdings!$Q$17 -> 0.040590717 | AG17: =$E$17 -> Summer | AH17: =Holdings!$Q$21 -> 2.1875882
E18: Total Gain | F18: =Holdings!$O$5 -> 0.46909473 | L18: Total Gain | M18: =Holdings!$O$9 -> 0.32777744 | S18: Total Gain | T18: =Holdings!$O$13 -> -0.0090828533 | Z18: Total Gain | AA18: =Holdings!$O$17 -> 0.26660466 | AG18: Total Gain | AH18: =Holdings!$O$21 -> 1.6248548
C20: =IF(C21=0,"No Cap", IF(C21<2,"Small Cap", IF(C21<10, "Mid Cap", IF(C21>10, "Large Cap")))) -> Large Cap | E20: Value | F20: =Holdings!$H$5 -> 2989.74 | J20: =IF(J21=0,"No Cap", IF(J21<2,"Small Cap", IF(J21<10, "Mid Cap", IF(J21>10, "Large Cap")))) -> Large Cap | L20: Value | M20: =Holdings!$H$9 -> 1657.2123 | Q20: =IF(Q21=0,"No Cap", IF(Q21<2,"Small Cap", IF(Q21<10, "Mid Cap", IF(Q21>10, "Large Cap")))) -> Small Cap | S20: Value | T20: =Holdings!$H$13 -> 2012.85 | X20: =IF(X21=0,"No Cap", IF(X21<2,"Small Cap", IF(X21<10, "Mid Cap", IF(X21>10, "Large Cap")))) -> Small Cap | Z20: Value | AA20: =Holdings!$H$17 -> 3486 | AE20: =IF(AE21=0,"No Cap", IF(AE21<2,"Small Cap", IF(AE21<10, "Mid Cap", IF(AE21>10, "Large Cap")))) -> Small Cap | AG20: Value | AH20: =Holdings!$H$21 -> 4520
C21: =Holdings!$V$5 -> 283.48254 | E21: Cost | F21: =Holdings!$I$5 -> 2035.09 | J21: =Holdings!$V$9 -> 130.13458 | L21: Cost | M21: =Holdings!$I$9 -> 1248.11 | Q21: =Holdings!$V$13 -> 0.41595396 | S21: Cost | T21: =Holdings!$I$13 -> 2031.3 | X21: =Holdings!$V$17 -> 0.82924429 | Z21: Cost | AA21: =Holdings!$I$17 -> 2752.24 | AE21: =Holdings!$V$21 -> 0.21236904 | AG21: Cost | AH21: =Holdings!$I$21 -> 1722
E23: % of Portfolio | F23: =Holdings!$U$5 -> 0.058428154 | L23: % of Portfolio | M23: =Holdings!$U$9 -> 0.032386715 | S23: % of Portfolio | T23: =Holdings!$U$13 -> 0.039336902 | Z23: % of Portfolio | AA23: =Holdings!$U$17 -> 0.068126508 | AG23: % of Portfolio | AH23: =Holdings!$U$21 -> 0.088333854
C27: =Holdings!$C$6 -> BlackRock Global | F27: =Holdings!$E$6 -> 19.39 | J27: =Holdings!$C$10 -> Delta Airlines | M27: =Holdings!$E$10 -> 18.71 | Q27: =Holdings!$C$14 -> Intel | T27: =Holdings!$E$14 -> 24.99 | X27: =Holdings!$C$18 -> Tyson Foods | AA27: =Holdings!$E$18 -> 25.71
C29: =Holdings!$D$6 -> MCLOX | E29: Today | F29: =Holdings!$S$6 -> 0.0072727273 | J29: =Holdings!$D$10 -> DAL | L29: Today | M29: =Holdings!$S$10 -> 0.03541782 | Q29: =Holdings!$D$14 -> INTC | S29: Today | T29: =Holdings!$S$14 -> 0.021668029 | X29: =Holdings!$D$18 -> TSN | Z29: Today | AA29: =Holdings!$S$18 -> 0.034421365
E30: 1 Week | F30: =Holdings!$R$6 -> 0.0041429311 | L30: 1 Week | M30: =Holdings!$R$10 -> 0.069754145 | S30: 1 Week | T30: =Holdings!$R$14 -> 0.010951542 | Z30: 1 Week | AA30: =Holdings!$R$18 -> 0.036275695
E31: =$E$17 -> Summer | F31: =Holdings!$Q$6 -> -0.0025720165 | L31: =$E$17 -> Summer | M31: =Holdings!$Q$10 -> 0.1485574 | S31: =$E$17 -> Summer | T31: =Holdings!$Q$14 -> 0.010951542 | Z31: =$E$17 -> Summer | AA31: =Holdings!$Q$18 -> 0.033360129
E32: Total Gain | F32: =Holdings!$O$6 -> 0.12124859 | L32: Total Gain | M32: =Holdings!$O$10 -> 0.13074589 | S32: Total Gain | T32: =Holdings!$O$14 -> 0.010951542 | Z32: Total Gain | AA32: =Holdings!$O$18 -> 0.54986041
C34: =IF(C35=0,"No Cap", IF(C35<2,"Small Cap", IF(C35<10, "Mid Cap", IF(C35>10, "Large Cap")))) -> No Cap | E34: Value | F34: =Holdings!$H$6 -> 1730.5575 | J34: =IF(J35=0,"No Cap", IF(J35<2,"Small Cap", IF(J35<10, "Mid Cap", IF(J35>10, "Large Cap")))) -> Large Cap | L34: Value | M34: =Holdings!$H$10 -> 2806.5 | Q34: =IF(Q35=0,"No Cap", IF(Q35<2,"Small Cap", IF(Q35<10, "Mid Cap", IF(Q35>10, "Large Cap")))) -> Large Cap | S34: Value | T34: =Holdings!$H$14 -> 2798.88 | X34: =IF(X35=0,"No Cap", IF(X35<2,"Small Cap", IF(X35<10, "Mid Cap", IF(X35>10, "Large Cap")))) -> Mid Cap | Z34: Value | AA34: =Holdings!$H$18 -> 2595.9387
C35: =Holdings!$V$6 -> 0 | E35: Cost | F35: =Holdings!$I$6 -> 1543.42 | J35: =Holdings!$V$10 -> 16.02596 | L35: Cost | M35: =Holdings!$I$10 -> 2481.99 | Q35: =Holdings!$V$14 -> 124.22529 | S35: Cost | T35: =Holdings!$I$14 -> 2768.56 | X35: =Holdings!$V$18 -> 9.1229926 | Z35: Cost | AA35: =Holdings!$I$18 -> 1674.95
E37: % of Portfolio | F37: =Holdings!$U$6 -> 0.033820092 | L37: % of Portfolio | M37: =Holdings!$U$10 -> 0.054847115 | S37: % of Portfolio | T37: =Holdings!$U$14 -> 0.054698199 | Z37: % of Portfolio | AA37: =Holdings!$U$18 -> 0.05073214
C41: =Holdings!$C$7 -> Caterpillar | F41: =Holdings!$E$7 -> 85.14 | J41: =Holdings!$C$11 -> Gentex | M41: =Holdings!$E$11 -> 23.27 | Q41: =Holdings!$C$15 -> Medtronic | T41: =Holdings!$E$15 -> 52.78 | X41: =Holdings!$C$19 -> Wells Fargo | AA41: =Holdings!$E$19 -> 40.94
C43: =Holdings!$D$7 -> CAT | E43: Today | F43: =Holdings!$S$7 -> 0.023194328 | J43: =Holdings!$D$11 -> GNTX | L43: Today | M43: =Holdings!$S$11 -> 0.028735632 | Q43: =Holdings!$D$15 -> MDT | S43: Today | T43: =Holdings!$S$15 -> 0.022670025 | X43: =Holdings!$D$19 -> WFC | Z43: Today | AA43: =Holdings!$S$19 -> 0.01140834
E44: 1 Week | F44: =Holdings!$R$7 -> 0.013571429 | L44: 1 Week | M44: =Holdings!$R$11 -> 0.015713662 | S44: 1 Week | T44: =Holdings!$R$15 -> 0.025252525 | Z44: 1 Week | AA44: =Holdings!$R$19 -> 0.0054027505
E45: =$E$17 -> Summer | F45: =Holdings!$Q$7 -> 0.01339941 | L45: =$E$17 -> Summer | M45: =Holdings!$Q$11 -> 0.03070425 | S45: =$E$17 -> Summer | T45: =Holdings!$Q$15 -> 0.12850624 | Z45: =$E$17 -> Summer | AA45: =Holdings!$Q$19 -> 0.086963142
E46: Total Gain | F46: =Holdings!$O$7 -> 0.02931916 | L46: Total Gain | M46: =Holdings!$O$11 -> 0.44316285 | S46: Total Gain | T46: =Holdings!$O$15 -> 0.12547834 | Z46: Total Gain | AA46: =Holdings!$O$19 -> 0.77051894
C48: =IF(C49=0,"No Cap", IF(C49<2,"Small Cap", IF(C49<10, "Mid Cap", IF(C49>10, "Large Cap")))) -> Large Cap | E48: Value | F48: =Holdings!$H$7 -> 1291.7441 | J48: =IF(J49=0,"No Cap", IF(J49<2,"Small Cap", IF(J49<10, "Mid Cap", IF(J49>10, "Large Cap")))) -> Mid Cap | L48: Value | M48: =Holdings!$H$11 -> 2168.1357 | Q48: =IF(Q49=0,"No Cap", IF(Q49<2,"Small Cap", IF(Q49<10, "Mid Cap", IF(Q49>10, "Large Cap")))) -> Large Cap | S48: Value | T48: =Holdings!$H$15 -> 1497.6853 | X48: =IF(X49=0,"No Cap", IF(X49<2,"Small Cap", IF(X49<10, "Mid Cap", IF(X49>10, "Large Cap")))) -> Large Cap | Z48: Value | AA48: =Holdings!$H$19 -> 2132.3599
C49: =Holdings!$V$7 -> 55.978264 | E49: Cost | F49: =Holdings!$I$7 -> 1254.95 | J49: =Holdings!$V$11 -> 3.3411997 | L49: Cost | M49: =Holdings!$I$11 -> 1502.35 | Q49: =Holdings!$V$15 -> 53.508679 | S49: Cost | T49: =Holdings!$I$15 -> 1330.71 | X49: =Holdings!$V$19 -> 216.83408 | Z49: Cost | AA49: =Holdings!$I$19 -> 1204.37
E51: % of Portfolio | F51: =Holdings!$U$7 -> 0.02524441 | L51: % of Portfolio | M51: =Holdings!$U$11 -> 0.042371634 | S51: % of Portfolio | T51: =Holdings!$U$15 -> 0.029269096 | Z51: % of Portfolio | AA51: =Holdings!$U$19 -> 0.041672471
C55: =Holdings!$C$8 -> Cemex | F55: =Holdings!$E$8 -> 10.55 | J55: =Holdings!$C$12 -> Home Depot | M55: =Holdings!$E$12 -> 76.53 | Q55: =Holdings!$C$16 -> Natural Grocers | T55: =Holdings!$E$16 -> 27.69 | X55: =Holdings!$C$20 -> Yahoo | AA55: =Holdings!$E$20 -> 26.37
C57: =Holdings!$D$8 -> CX | E57: Today | F57: =Holdings!$S$8 -> 0.029268293 | J57: =Holdings!$D$12 -> HD | L57: Today | M57: =Holdings!$S$12 -> 0.0017015707 | Q57: =Holdings!$D$16 -> NGVC | S57: Today | T57: =Holdings!$S$16 -> 0.022670025 | X57: =Holdings!$D$20 -> YHOO | Z57: Today | AA57: =Holdings!$S$20 -> 0.016637696
E58: 1 Week | F58: =Holdings!$R$8 -> -0.026752768 | L58: 1 Week | M58: =Holdings!$R$12 -> -0.0094486151 | S58: 1 Week | T58: =Holdings!$R$16 -> 0.0355273 | Z58: 1 Week | AA58: =Holdings!$R$20 -> 0.0061045403
E59: =$E$17 -> Summer | F59: =Holdings!$Q$8 -> -0.08840328 | L59: =$E$17 -> Summer | M59: =Holdings!$Q$12 -> 0.048899539 | S59: =$E$17 -> Summer | T59: =Holdings!$Q$16 -> 0.11338963 | Z59: =$E$17 -> Summer | AA59: =Holdings!$Q$20 -> 0.046428571
E60: Total Gain | F60: =Holdings!$O$8 -> -0.08840328 | L60: Total Gain | M60: =Holdings!$O$12 -> 1.7227482 | S60: Total Gain | T60: =Holdings!$O$16 -> 0.41112319 | Z60: Total Gain | AA60: =Holdings!$O$20 -> 0.21241937
C62: =IF(C63=0,"No Cap", IF(C63<2,"Small Cap", IF(C63<10, "Mid Cap", IF(C63>10, "Large Cap")))) -> Large Cap | E62: Value | F62: =Holdings!$H$8 -> 2110 | J62: =IF(J63=0,"No Cap", IF(J63<2,"Small Cap", IF(J63<10, "Mid Cap", IF(J63>10, "Large Cap")))) -> Large Cap | L62: Value | M62: =Holdings!$H$12 -> 4543.5861 | Q62: =IF(Q63=0,"No Cap", IF(Q63<2,"Small Cap", IF(Q63<10, "Mid Cap", IF(Q63>10, "Large Cap")))) -> Small Cap | S62: Value | T62: =Holdings!$H$16 -> 2076.75 | X62: =IF(X63=0,"No Cap", IF(X63<2,"Small Cap", IF(X63<10, "Mid Cap", IF(X63>10, "Large Cap")))) -> Large Cap | Z62: Value | AA62: =Holdings!$H$20 -> 2637
C63: =Holdings!$V$8 -> 11.867495 | E63: Cost | F63: =Holdings!$I$8 -> 2314.62 | J63: =Holdings!$V$12 -> 111.79472 | L63: Cost | M63: =Holdings!$I$12 -> 1668.75 | Q63: =Holdings!$V$16 -> 0.62030918 | S63: Cost | T63: =Holdings!$I$16 -> 1471.7 | X63: =Holdings!$V$20 -> 28.549086 | Z63: Cost | AA63: =Holdings!$I$20 -> 2174.99
E65: % of Portfolio | F65: =Holdings!$U$8 -> 0.041235494 | L65: % of Portfolio | M65: =Holdings!$U$12 -> 0.088794795 | S65: % of Portfolio | T65: =Holdings!$U$16 -> 0.040585693 | Z65: % of Portfolio | AA65: =Holdings!$U$20 -> 0.051534596
C69: Bought This Year | Q69: Sold This Year
F71: Date Bought | J71: Buy Price | L71: Current Price | M71: Change* | T71: Date Sold | X71: Sell Price | Z71: Current Price | AA71: Change*
D72: =Holdings!C26 -> Tyson Foods | F72: =Holdings!E26 -> 41173 | J72: =Holdings!H26 -> 16.65 | L72: =Holdings!I26 -> 25.71 | M72: =L72/J72-1 -> 0.54414414 | R72: =Holdings!C38 -> Vale | T72: =Holdings!E38 -> 41166 | X72: =Holdings!H38 -> 19.71 | Y72: 19.71 | Z72: =Holdings!I38 -> 14.47 | AA72: =(Z72/X72)-1 -> -0.2658549
...

Sheet Holdings
C3: Name | D3: Ticker | E3: Price | F3: Paid | G3: Shares | H3: Value | I3: Initial Cost | J3: Value on 9/6/12 | K3: Value on 4/25/13 | L3: Value 1 Week Ago | N3: Total Gain $ | O3: Total Gain | P3: School Year | Q3: Summer | R3: 1 Week | S3: Today | T3: Sector | U3: Portfolio Weight | V3: Market Cap (Billions) | X3: PE | Y3: EPS | AC3: % of Weekly Portfolio Return | AD3: % of Daily Portfolio Return
C4: Cash | E4: 1 | F4: 1 | G4: 8114.57 | H4: =E4*G4 -> 8114.57 | I4: 2029.73 | J4: 4804 | K4: 4361.76 | L4: 4444.5729 | T4: Cash | U4: =H4/$H$22 -> 0.15858213 | V4: 0 | X4: 0 | Y4: 0 | AC4: =(0.01/365)*U4 -> 4.344716e-06 | AD4: =(0.01/365)*U4 -> 4.344716e-06
C5: Berkshire Hathaway | D5: ='Holdings Pull Sheet'!B16 -> BRK.B | E5: ='Holdings Pull Sheet'!F16 -> 114.99 | F5: 77.89 | G5: 26 | H5: =G5*E5 -> 2989.74 | I5: 2035.09 | J5: 2248.22 | K5: 2794.22 | L5: 2940.6 | N5: =H5-I5 -> 954.65 | O5: =(H5/I5)-1 -> 0.46909473 | P5: =(H5/J5)-1 -> 0.32982535 | Q5: =(H5/K5)-1 -> 0.069973016 | R5: =(H5/L5)-1 -> 0.016710875 | S5: =('Holdings Pull Sheet'!F16/'Holdings Pull Sheet'!G16)-1 -> 0.018061089 | T5: Financial | U5: =H5/$H$22 -> 0.058428154 | V5: ='Holdings Pull Sheet'!O16/1000000000 -> 283.48254 | W5: =IF(V5<2,"Small", IF(V5<10, "Mid", IF(V5>10, "Large"))) -> Large | X5: ='Holdings Pull Sheet'!Q16 -> 17 | Y5: ='Holdings Pull Sheet'!P16 -> 9988.97 | AC5: =U5*R5 -> 0.0009763856 | AD5: =U5*S5 -> 0.0010552761
C6: BlackRock Global | D6: ='Holdings Pull Sheet'!B17 -> MCLOX | E6: ='Holdings Pull Sheet'!F17 -> 19.39 | F6: 17.23 | G6: 89.25 | H6: =G6*E6 -> 1730.5575 | I6: 1543.42 | J6: 1602.0455 | K6: 1735.02 | L6: 1723.4175 | N6: =H6-I6 -> 187.1375 | O6: =(H6/I6)-1 -> 0.12124859 | P6: =(H6/J6)-1 -> 0.080217474 | Q6: =(H6/K6)-1 -> -0.0025720165 | R6: =(H6/L6)-1 -> 0.0041429311 | S6: =('Holdings Pull Sheet'!F17/'Holdings Pull Sheet'!G17)-1 -> 0.0072727273 | T6: Misc | U6: =H6/$H$22 -> 0.033820092 | V6: ='Holdings Pull Sheet'!O17/1000000000 -> 0 | W6: =IF(V6<2,"Small", IF(V6<10, "Mid", IF(V6>10, "Large"))) -> Small | X6: ='Holdings Pull Sheet'!Q17 -> 0 | Y6: ='Holdings Pull Sheet'!P17 -> 0 | AC6: =U6*R6 -> 0.00014011431 | AD6: =U6*S6 -> 0.0002459643
C7: Caterpillar | D7: ='Holdings Pull Sheet'!B18 -> CAT | E7: ='Holdings Pull Sheet'!F18 -> 85.14 | F7: 83 | G7: 15.172 | H7: =G7*E7 -> 1291.7441 | I7: 1254.95 | J7: 1245 | K7: 1274.6643 | L7: 1274.448 | N7: =H7-I7 -> 36.79408 | O7: =(H7/I7)-1 -> 0.02931916 | P7: =(H7/J7)-1 -> 0.037545446 | Q7: =(H7/K7)-1 -> 0.01339941 | R7: =(H7/L7)-1 -> 0.013571429 | S7: =('Holdings Pull Sheet'!F18/'Holdings Pull Sheet'!G18)-1 -> 0.023194328 | T7: Industrials | U7: =H7/$H$22 -> 0.02524441 | V7: ='Holdings Pull Sheet'!O18/1000000000 -> 55.978264 | W7: =IF(V7<2,"Small", IF(V7<10, "Mid", IF(V7>10, "Large"))) -> Large | X7: ='Holdings Pull Sheet'!Q18 -> 11.2 | Y7: ='Holdings Pull Sheet'!P18 -> 7.43 | AC7: =U7*R7 -> 0.00034260271 | AD7: =U7*S7 -> 0.00058552712
C8: Cemex | D8: ='Holdings Pull Sheet'!B19 -> CX | E8: ='Holdings Pull Sheet'!F19 -> 10.55 | F8: 11.57 | G8: 200 | H8: =G8*E8 -> 2110 | I8: 2314.62 | J8: 2314.62 | K8: 2314.62 | L8: 2168 | N8: =H8-I8 -> -204.62 | O8: =(H8/I8)-1 -> -0.08840328 | P8: =(H8/J8)-1 -> -0.08840328 | Q8: =(H8/K8)-1 -> -0.08840328 | R8: =(H8/L8)-1 -> -0.026752768 | S8: =('Holdings Pull Sheet'!F19/'Holdings Pull Sheet'!G19)-1 -> 0.029268293 | T8: Industrials | U8: =H8/$H$22 -> 0.041235494 | V8: ='Holdings Pull Sheet'!O19/1000000000 -> 11.867495 | W8: =IF(V8<2,"Small", IF(V8<10, "Mid", IF(V8>10, "Large"))) -> Large | X8: ='Holdings Pull Sheet'!Q19 -> 0 | Y8: ='Holdings Pull Sheet'!P19 -> -1.03 | AC8: =U8*R8 -> -0.0011031636 | AD8: =U8*S8 -> 0.0012068925
C9: Cisco | D9: ='Holdings Pull Sheet'!B20 -> CSCO | E9: ='Holdings Pull Sheet'!F20 -> 24.35 | F9: 18.48 | G9: 68.058 | H9: =G9*E9 -> 1657.2123 | I9: 1248.11 | J9: 1311.6534 | K9: 1393.2413 | L9: 1670.8239 | N9: =H9-I9 -> 409.1023 | O9: =(H9/I9)-1 -> 0.32777744 | P9: =(H9/J9)-1 -> 0.26345295 | Q9: =(H9/K9)-1 -> 0.1894654 | R9: =(H9/L9)-1 -> -0.0081466395 | S9: =('Holdings Pull Sheet'!F20/'Holdings Pull Sheet'!G20)-1 -> 0.015006253 | T9: Information Technology | U9: =H9/$H$22 -> 0.032386715 | V9: ='Holdings Pull Sheet'!O20/1000000000 -> 130.13458 | W9: =IF(V9<2,"Small", IF(V9<10, "Mid", IF(V9>10, "Large"))) -> Large | X9: ='Holdings Pull Sheet'!Q20 -> 13.4 | Y9: ='Holdings Pull Sheet'!P20 -> 1.8 | AC9: =U9*R9 -> -0.00026384289 | AD9: =U9*S9 -> 0.00048600322
C10: Delta Airlines | D10: ='Holdings Pull Sheet'!B21 -> DAL | E10: ='Holdings Pull Sheet'!F21 -> 18.71 | F10: 16.58 | G10: 150 | H10: =G10*E10 -> 2806.5 | I10: 2481.99 | J10: 2481.99 | K10: 2443.5 | L10: 2623.5 | N10: =H10-I10 -> 324.51 | O10: =(H10/I10)-1 -> 0.13074589 | P10: =(H10/J10)-1 -> 0.13074589 | Q10: =(H10/K10)-1 -> 0.1485574 | R10: =(H10/L10)-1 -> 0.069754145 | S10: =('Holdings Pull Sheet'!F21/'Holdings Pull Sheet'!G21)-1 -> 0.03541782 | T10: Consumer Discretionary | U10: =H10/$H$22 -> 0.054847115 | V10: ='Holdings Pull Sheet'!O21/1000000000 -> 16.02596 | W10: =IF(V10<2,"Small", IF(V10<10, "Mid", IF(V10>10, "Large"))) -> Large | X10: ='Holdings Pull Sheet'!Q21 -> 17.6 | Y10: ='Holdings Pull Sheet'!P21 -> 1.05 | AC10: =U10*R10 -> 0.0038258137 | AD10: =U10*S10 -> 0.0019425652
C11: Gentex | D11: ='Holdings Pull Sheet'!B22 -> GNTX | E11: ='Holdings Pull Sheet'!F22 -> 23.27 | F11: 16.4 | G11: 93.173 | H11: =G11*E11 -> 2168.1357 | I11: 1502.35 | J11: 1669.6919 | K11: 2103.5478 | L11: 2134.5934 | N11: =H11-I11 -> 665.78571 | O11: =(H11/I11)-1 -> 0.44316285 | P11: =(H11/J11)-1 -> 0.2985244 | Q11: =(H11/K11)-1 -> 0.03070425 | R11: =(H11/L11)-1 -> 0.015713662 | S11: =('Holdings Pull Sheet'!F22/'Holdings Pull Sheet'!G22)-1 -> 0.028735632 | T11: Consumer Discretionary | U11: =H11/$H$22 -> 0.042371634 | V11: ='Holdings Pull Sheet'!O22/1000000000 -> 3.3411997 | W11: =IF(V11<2,"Small", IF(V11<10, "Mid", IF(V11>10, "Large"))) -> Mid | X11: ='Holdings Pull Sheet'!Q22 -> 19.5 | Y11: ='Holdings Pull Sheet'!P22 -> 1.17 | AC11: =U11*R11 -> 0.00066581354 | AD11: =U11*S11 -> 0.0012175757
C12: Home Depot | D12: ='Holdings Pull Sheet'!B23 -> HD | E12: ='Holdings Pull Sheet'!F23 -> 76.53 | F12: 28.6 | G12: 59.37 | H12: =G12*E12 -> 4543.5861 | I12: 1668.75 | J12: 3371.3144 | K12: 4331.7648 | L12: 4586.9262 | N12: =H12-I12 -> 2874.8361 | O12: =(H12/I12)-1 -> 1.7227482 | P12: =(H12/J12)-1 -> 0.34771947 | Q12: =(H12/K12)-1 -> 0.048899539 | R12: =(H12/L12)-1 -> -0.0094486151 | S12: =('Holdings Pull Sheet'!F23/'Holdings Pull Sheet'!G23)-1 -> 0.0017015707 | T12: Consumer Discretionary | U12: =H12/$H$22 -> 0.088794795 | V12: ='Holdings Pull Sheet'!O23/1000000000 -> 111.79472 | W12: =IF(V12<2,"Small", IF(V12<10, "Mid", IF(V12>10, "Large"))) -> Large | X12: ='Holdings Pull Sheet'!Q23 -> 24.6 | Y12: ='Holdings Pull Sheet'!P23 -> 3.16 | AC12: =U12*R12 -> -0.00083898784 | AD12: =U12*S12 -> 0.00015109062
C13: Immersion | D13: ='Holdings Pull Sheet'!B24 -> IMMR | E13: ='Holdings Pull Sheet'!F24 -> 14.91 | F13: 15.04 | G13: 135 | H13: =G13*E13 -> 2012.85 | I13: 2031.3 | J13: 2031.3 | K13: 2031.3 | L13: 1960.2 | N13: =H13-I13 -> -18.45 | O13: =(H13/I13)-1 -> -0.0090828533 | P13: =(H13/J13)-1 -> -0.0090828533 | Q13: =(H13/K13)-1 -> -0.0090828533 | R13: =(H13/L13)-1 -> 0.026859504 | S13: =('Holdings Pull Sheet'!F24/'Holdings Pull Sheet'!G24)-1 -> 0.044849334 | T13: Information Technology | U13: =H13/$H$22 -> 0.039336902 | V13: ='Holdings Pull Sheet'!O24/1000000000 -> 0.41595396 | W13: =IF(V13<2,"Small", IF(V13<10, "Mid", IF(V13>10, "Large"))) -> Small | X13: ='Holdings Pull Sheet'!Q24 -> 0 | Y13: ='Holdings Pull Sheet'!P24 -> -0.11 | AC13: =U13*R13 -> 0.0010565697 | AD13: =U13*S13 -> 0.0017642339
C14: Intel | D14: ='Holdings Pull Sheet'!B25 -> INTC | E14: ='Holdings Pull Sheet'!F25 -> 24.99 | F14: 24.72 | G14: 112 | H14: =G14*E14 -> 2798.88 | I14: 2768.56 | J14: 2768.56 | K14: 2768.56 | L14: 2768.56 | N14: =H14-I14 -> 30.32 | O14: =(H14/I14)-1 -> 0.010951542 | P14: =(H14/J14)-1 -> 0.010951542 | Q14: =(H14/K14)-1 -> 0.010951542 | R14: =(H14/L14)-1 -> 0.010951542 | S14: =('Holdings Pull Sheet'!F25/'Holdings Pull Sheet'!G25)-1 -> 0.021668029 | T14: Information Technology | U14: =H14/$H$22 -> 0.054698199 | V14: ='Holdings Pull Sheet'!O25/1000000000 -> 124.22529 | W14: =IF(V14<2,"Small", IF(V14<10, "Mid", IF(V14>10, "Large"))) -> Large | X14: ='Holdings Pull Sheet'!Q25 -> 12.3 | Y14: ='Holdings Pull Sheet'!P25 -> 2 | AC14: =U14*R14 -> 0.0005990296 | AD14: =U14*S14 -> 0.0011852022
C15: Medtronic | D15: ='Holdings Pull Sheet'!B26 -> MDT | E15: ='Holdings Pull Sheet'!F26 -> 52.78 | F15: 47.17 | G15: 28.376 | H15: =G15*E15 -> 1497.6853 | I15: 1330.71 | J15: 1158.5436 | K15: 1327.1396 | L15: 1460.7965 | N15: =H15-I15 -> 166.97528 | O15: =(H15/I15)-1 -> 0.12547834 | P15: =(H15/J15)-1 -> 0.29273106 | Q15: =(H15/K15)-1 -> 0.12850624 | R15: =(H15/L15)-1 -> 0.025252525 | S15: =('Holdings Pull Sheet'!F26/'Holdings Pull Sheet'!G26)-1 -> 0.022670025 | T15: Healthcare | U15: =H15/$H$22 -> 0.029269096 | V15: ='Holdings Pull Sheet'!O26/1000000000 -> 53.508679 | W15: =IF(V15<2,"Small", IF(V15<10, "Mid", IF(V15>10, "Large"))) -> Large | X15: ='Holdings Pull Sheet'!Q26 -> 15.4 | Y15: ='Holdings Pull Sheet'!P26 -> 3.38 | AC15: =U15*R15 -> 0.00073911858 | AD15: =U15*S15 -> 0.00066353114
C16: Natural Grocers | D16: ='Holdings Pull Sheet'!B27 -> NGVC | E16: ='Holdings Pull Sheet'!F27 -> 27.69 | F16: 19.49 | G16: 75 | H16: =G16*E16 -> 2076.75 | I16: 1471.7 | J16: 1471.7 | K16: 1865.25 | L16: 2005.5 | N16: =H16-I16 -> 605.05 | O16: =(H16/I16)-1 -> 0.41112319 | P16: =(H16/J16)-1 -> 0.41112319 | Q16: =(H16/K16)-1 -> 0.11338963 | R16: =(H16/L16)-1 -> 0.0355273 | S16: =('Holdings Pull Sheet'!F26/'Holdings Pull Sheet'!G26)-1 -> 0.022670025 | T16: Consumer Staples | U16: =H16/$H$22 -> 0.040585693 | V16: ='Holdings Pull Sheet'!O27/1000000000 -> 0.62030918 | W16: =IF(V16<2,"Small", IF(V16<10, "Mid", IF(V16>10, "Large"))) -> Small | X16: ='Holdings Pull Sheet'!Q27 -> 5.2 | Y16: ='Holdings Pull Sheet'!P27 -> 5.31 | AC16: =U16*R16 -> 0.0014419001 | AD16: =U16*S16 -> 0.00092007868
C17: Tutor Perini | D17: ='Holdings Pull Sheet'!B28 -> TPC | E17: ='Holdings Pull Sheet'!F28 -> 17.43 | F17: 13.7612 | G17: 200 | H17: =G17*E17 -> 3486 | I17: 2752.24 | J17: 1874.45 | K17: 2488.5 | L17: 3470 | N17: =H17-I17 -> 733.76 | O17: =(H17/I17)-1 -> 0.26660466 | P17: =((H17-896.49)/J17)-1 -> 0.38147723 | Q17: =((H17-896.49)/K17)-1 -> 0.040590717 | R17: =(H17/L17)-1 -> 0.004610951 | S17: =('Holdings Pull Sheet'!F27/'Holdings Pull Sheet'!G27)-1 -> 0.013914317 | T17: Industrials | U17: =H17/$H$22 -> 0.068126508 | V17: ='Holdings Pull Sheet'!O28/1000000000 -> 0.82924429 | W17: =IF(V17<2,"Small", IF(V17<10, "Mid", IF(V17>10, "Large"))) -> Small | X17: ='Holdings Pull Sheet'!Q28 -> 0 | Y17: ='Holdings Pull Sheet'!P28 -> -5.3 | AC17: =U17*R17 -> 0.00031412799 | AD17: =U17*S17 -> 0.00094793383
C18: Tyson Foods | D18: ='Holdings Pull Sheet'!B29 -> TSN | E18: ='Holdings Pull Sheet'!F29 -> 25.71 | F18: 16.65 | G18: 100.97 | H18: =G18*E18 -> 2595.9387 | I18: 1674.95 | J18: 1665 | K18: 2512.1336 | L18: 2505.0657 | N18: =H18-I18 -> 920.9887 | O18: =(H18/I18)-1 -> 0.54986041 | P18: =(H18/J18)-1 -> 0.55912234 | Q18: =(H18/K18)-1 -> 0.033360129 | R18: =(H18/L18)-1 -> 0.036275695 | S18: =('Holdings Pull Sheet'!F28/'Holdings Pull Sheet'!G28)-1 -> 0.034421365 | T18: Consumer Staples | U18: =H18/$H$22 -> 0.05073214 | V18: ='Holdings Pull Sheet'!O29/1000000000 -> 9.1229926 | W18: =IF(V18<2,"Small", IF(V18<10, "Mid", IF(V18>10, "Large"))) -> Mid | X18: ='Holdings Pull Sheet'!Q29 -> 17.5 | Y18: ='Holdings Pull Sheet'!P29 -> 1.45 | AC18: =U18*R18 -> 0.0018403436 | AD18: =U18*S18 -> 0.0017462695
C19: Wells Fargo | D19: ='Holdings Pull Sheet'!B30 -> WFC | E19: ='Holdings Pull Sheet'!F30 -> 40.94 | F19: 23.42 | G19: 52.085 | H19: =G19*E19 -> 2132.3599 | I19: 1204.37 | J19: 1778.2684 | K19: 1961.7592 | L19: 2120.9012 | N19: =H19-I19 -> 927.9899 | O19: =(H19/I19)-1 -> 0.77051894 | P19: =(H19/J19)-1 -> 0.19912148 | Q19: =(H19/K19)-1 -> 0.086963142 | R19: =(H19/L19)-1 -> 0.0054027505 | S19: =('Holdings Pull Sheet'!F29/'Holdings Pull Sheet'!G29)-1 -> 0.01140834 | T19: Financial | U19: =H19/$H$22 -> 0.041672471 | V19: ='Holdings Pull Sheet'!O30/1000000000 -> 216.83408 | W19: =IF(V19<2,"Small", IF(V19<10, "Mid", IF(V19>10, "Large"))) -> Large | X19: ='Holdings Pull Sheet'!Q30 -> 11.5 | Y19: ='Holdings Pull Sheet'!P30 -> 3.53 | AC19: =U19*R19 -> 0.00022514596 | AD19: =U19*S19 -> 0.00047541371
C20: Yahoo | D20: ='Holdings Pull Sheet'!B31 -> YHOO | E20: ='Holdings Pull Sheet'!F31 -> 26.37 | F20: 21.75 | G20: 100 | H20: =G20*E20 -> 2637 | I20: 2174.99 | J20: 2174.99 | K20: 2520 | L20: 2621 | N20: =H20-I20 -> 462.01 | O20: =(H20/I20)-1 -> 0.21241937 | P20: =(H20/J20)-1 -> 0.21241937 | Q20: =(H20/K20)-1 -> 0.046428571 | R20: =(H20/L20)-1 -> 0.0061045403 | S20: =('Holdings Pull Sheet'!F30/'Holdings Pull Sheet'!G30)-1 -> 0.016637696 | T20: Information Technology | U20: =H20/$H$22 -> 0.051534596 | V20: ='Holdings Pull Sheet'!O31/1000000000 -> 28.549086 | W20: =IF(V20<2,"Small", IF(V20<10, "Mid", IF(V20>10, "Large"))) -> Large | X20: ='Holdings Pull Sheet'!Q31 -> 7.7 | Y20: ='Holdings Pull Sheet'!P31 -> 3.41 | AC20: =U20*R20 -> 0.00031459502 | AD20: =U20*S20 -> 0.00085741692
C21: YRC Worldwide | D21: ='Holdings Pull Sheet'!B32 -> YRCW | E21: ='Holdings Pull Sheet'!F32 -> 22.6 | F21: 8.51 | G21: 200 | H21: =G21*E21 -> 4520 | I21: 1722 | J21: 1722 | K21: 1418 | L21: 3856 | N21: =H21-I21 -> 2798 | O21: =(H21/I21)-1 -> 1.6248548 | P21: =(H21/J21)-1 -> 1.6248548 | Q21: =(H21/K21)-1 -> 2.1875882 | R21: =(H21/L21)-1 -> 0.17219917 | S21: =('Holdings Pull Sheet'!F31/'Holdings Pull Sheet'!G31)-1 -> 0.018539977 | T21: Industrials | U21: =H21/$H$22 -> 0.088333854 | V21: ='Holdings Pull Sheet'!O32/1000000000 -> 0.21236904 | W21: =IF(V21<2,"Small", IF(V21<10, "Mid", IF(V21>10, "Large"))) -> Small | X21: ='Holdings Pull Sheet'!Q32 -> 0 | Y21: ='Holdings Pull Sheet'!P32 -> -14.95 | AC21: =U21*R21 -> 0.015211016 | AD21: =U21*S21 -> 0.0016377076
H22: =SUM(H4:H21) -> 51169.51 | I22: =SUM(I4:I21) -> 33209.83 | J22: 40381.87 | K22: 46519.794 | L22: 50295.736 | N22: =(H22-Data!D3) -> 28313.66 | O22: =(H22/Data!D3)-1 -> 1.2387927 | P22: =(H22/J22)-1 -> 0.26714065 | Q22: =(H22/K22)-1 -> 0.09995134 | R22: =(H22/L22)-1 -> 0.017372717 | S22: =AD22 -> 0.017093027 | U22: =SUM(U4:U21) -> 1 | AC22: =SUM(AC4:AC21) -> 0.025490927 | AD22: =SUM(AD4:AD21) -> 0.017093027
C25: Bought this Year | E25: Date Bought | H25: Buy Price | I25: Current Price | J25: % Change
C26: Tyson Foods | D26: TSN | E26: 41173 | H26: 16.65 | I26: ='Holdings Pull Sheet'!F29 -> 25.71 | J26: =(I26/H26)-1 -> 0.54414414
C27: Tutor Perini | D27: TPC | E27: 41215 | H27: 12.43 | I27: ='Holdings Pull Sheet'!F28 -> 17.43 | J27: =(I27/H27)-1 -> 0.40225261
C28: Caterpillar | D28: CAT | E28: 41222 | H28: 83 | I28: ='Holdings Pull Sheet'!F18 -> 85.14 | J28: =(I28/H28)-1 -> 0.025783133
C29: Natural Grocers | D29: NGVC | E29: 41243 | H29: 19.49 | I29: ='Holdings Pull Sheet'!F27 -> 27.69 | J29: =(I29/H29)-1 -> 0.42072858
C30: Yahoo | D30: YHOO | E30: 41333 | H30: 21.75 | I30: ='Holdings Pull Sheet'!F31 -> 26.37 | J30: =(I30/H30)-1 -> 0.21241379
C31: YRC Worldwide | D31: YRCW | E31: 41355 | H31: 8.61 | I31: ='Holdings Pull Sheet'!F32 -> 22.6 | J31: =(I31/H31)-1 -> 1.6248548
C32: Delta Airlines | D32: DAL | E32: 41362 | H32: 16.48 | I32: ='Holdings Pull Sheet'!F21 -> 18.71 | J32: =(I32/H32)-1 -> 0.13531553
C33: Cemex | D33: CX | E33: 41416 | H33: 11.57 | I33: ='Holdings Pull Sheet'!F19 -> 10.55 | J33: =(I33/H33)-1 -> -0.088159032
C34: Immersion | D34: IMMR | E34: 41424 | H34: 15.04 | I34: ='Holdings Pull Sheet'!F24 -> 14.91 | J34: =(I34/H34)-1 -> -0.008643617
C35: Intel | D35: INTC | E35: 41438 | H35: 24.72 | I35: ='Holdings Pull Sheet'!F25 -> 24.99 | J35: =(I35/H35)-1 -> 0.01092233
C37: Sold this Year | E37: Date Sold | H37: Sell Price | I37: Current Price | J37: % Change
C38: Vale | D38: VALE | E38: 41166 | H38: 19.71 | I38: ='Holdings Pull Sheet'!F34 -> 14.47 | J38: =(I38/H38)-1 -> -0.2658549
C39: CPFL Energia | D39: CPL | E39: 41215 | H39: 23 | I39: ='Holdings Pull Sheet'!F35 -> 20.31 | J39: =(I39/H39)-1 -> -0.11695652
C40: Stryker | D40: SYK | E40: 41243 | H40: 54.07 | I40: ='Holdings Pull Sheet'!F36 -> 67.72 | J40: =(I40/H40)-1 -> 0.25245053
C41: PowerShares | D41: PGX | E41: 41299 | H41: 14.86 | I41: ='Holdings Pull Sheet'!F37 -> 14.29 | J41: =(I41/H41)-1 -> -0.038358008
C42: PetroChina | D42: PTR | E42: 41355 | H42: 131.71 | I42: ='Holdings Pull Sheet'!F38 -> 110.05 | J42: =(I42/H42)-1 -> -0.16445221
C43: UPS | D43: UPS | E43: 41355 | H43: 83.3 | I43: ='Holdings Pull Sheet'!F39 -> 86.32 | J43: =(I43/H43)-1 -> 0.036254502
C44: Ford | D44: F | E44: 41362 | H44: 13.01 | I44: ='Holdings Pull Sheet'!F40 -> 15.58 | J44: =(I44/H44)-1 -> 0.19754035
C45: Tetra Tech | D45: TTEK | E45: 41416 | H45: 28.06 | I45: ='Holdings Pull Sheet'!F41 -> 26.68 | J45: =(I45/H45)-1 -> -0.049180328
...

Sheet 2012 Holiday Performance
C3: Name | D3: Ticker | E3: % Change | F3: Current Price | G3: Shares | H3: 1 Week Ago | I3: Today's Value
C4: =Holdings!C16 -> Natural Grocers | D4: ='Holdings Pull Sheet'!B27 -> NGVC | E4: =I4/H4-1 -> 0.0355273 | F4: =Holdings!E16 -> 27.69 | G4: =Holdings!G16 -> 75 | H4: =Holdings!L16 -> 2005.5 | I4: =Holdings!H16 -> 2076.75
C5: =Holdings!C19 -> Wells Fargo | D5: ='Holdings Pull Sheet'!B28 -> TPC | E5: =I5/H5-1 -> 0.004610951 | F5: =Holdings!E19 -> 40.94 | G5: =Holdings!G17 -> 200 | H5: =Holdings!L17 -> 3470 | I5: =Holdings!H17 -> 3486
C6: =Holdings!#REF! -> #REF! | D6: ='Holdings Pull Sheet'!B31 -> YHOO | E6: =I6/H6-1 -> 0.0061045403 | F6: =Holdings!#REF! -> #REF! | G6: =Holdings!G20 -> 100 | H6: =Holdings!L20 -> 2621 | I6: =Holdings!H20 -> 2637
C7: =Holdings!#REF! -> #REF! | D7: ='Holdings Pull Sheet'!B42 -> WMMVY | E7: =I7/H7-1 -> #REF! | F7: =Holdings!E21 -> 22.6 | G7: =Holdings!#REF! -> #REF! | H7: =Holdings!#REF! -> #REF! | I7: =Holdings!#REF! -> #REF!
C8: =Holdings!#REF! -> #REF! | D8: ='Holdings Pull Sheet'!B44 -> HCP | E8: =I8/H8-1 -> #REF! | F8: =Holdings!E11 -> 23.27 | G8: =Holdings!#REF! -> #REF! | H8: =Holdings!#REF! -> #REF! | I8: =Holdings!#REF! -> #REF!
C9: =Holdings!C15 -> Medtronic | D9: ='Holdings Pull Sheet'!B26 -> MDT | E9: =I9/H9-1 -> 0.025252525 | F9: =Holdings!E14 -> 24.99 | G9: =Holdings!G15 -> 28.376 | H9: =Holdings!L15 -> 1460.7965 | I9: =Holdings!H15 -> 1497.6853
C10: =Holdings!C13 -> Immersion | D10: ='Holdings Pull Sheet'!B24 -> IMMR | E10: =I10/H10-1 -> 0.026859504 | F10: =Holdings!E13 -> 14.91 | G10: =Holdings!G13 -> 135 | H10: =Holdings!L13 -> 1960.2 | I10: =Holdings!H13 -> 2012.85
C11: =Holdings!#REF! -> #REF! | D11: ='Holdings Pull Sheet'!B41 -> TTEK | E11: =I11/H11-1 -> #REF! | F11: =Holdings!E18 -> 25.71 | G11: =Holdings!#REF! -> #REF! | H11: =Holdings!#REF! -> #REF! | I11: =Holdings!#REF! -> #REF!
C12: =Holdings!C21 -> YRC Worldwide | D12: ='Holdings Pull Sheet'!B30 -> WFC | E12: =I12/H12-1 -> 0.0054027505 | F12: =Holdings!E22 -> 0 | G12: =Holdings!G19 -> 52.085 | H12: =Holdings!L19 -> 2120.9012 | I12: =Holdings!H19 -> 2132.3599
C13: =Holdings!C18 -> Tyson Foods | D13: ='Holdings Pull Sheet'!B45 -> QCOM | E13: =I13/H13-1 -> #REF! | F13: =Holdings!E17 -> 17.43 | G13: =Holdings!#REF! -> #REF! | H13: =Holdings!#REF! -> #REF! | I13: =Holdings!#REF! -> #REF!
C14: =Holdings!C20 -> Yahoo | D14: ='Holdings Pull Sheet'!B29 -> TSN | E14: =I14/H14-1 -> 0.036275695 | F14: =Holdings!E20 -> 26.37 | G14: =Holdings!G18 -> 100.97 | H14: =Holdings!L18 -> 2505.0657 | I14: =Holdings!H18 -> 2595.9387
C15: =Holdings!C11 -> Gentex | D15: ='Holdings Pull Sheet'!B22 -> GNTX | E15: =I15/H15-1 -> 0.015713662 | F15: =Holdings!E10 -> 18.71 | G15: =Holdings!G11 -> 93.173 | H15: =Holdings!L11 -> 2134.5934 | I15: =Holdings!H11 -> 2168.1357
C16: =Holdings!C6 -> BlackRock Global | D16: ='Holdings Pull Sheet'!B17 -> MCLOX | E16: =I16/H16-1 -> 0.0041429311 | F16: =Holdings!E6 -> 19.39 | G16: =Holdings!G6 -> 89.25 | H16: =Holdings!L6 -> 1723.4175 | I16: =Holdings!H6 -> 1730.5575
C17: =Holdings!C12 -> Home Depot | D17: ='Holdings Pull Sheet'!B23 -> HD | E17: =I17/H17-1 -> -0.0094486151 | F17: =Holdings!E12 -> 76.53 | G17: =Holdings!G12 -> 59.37 | H17: =Holdings!L12 -> 4586.9262 | I17: =Holdings!H12 -> 4543.5861
C18: =Holdings!C5 -> Berkshire Hathaway | D18: ='Holdings Pull Sheet'!B16 -> BRK.B | E18: =I18/H18-1 -> 0.016710875 | F18: =Holdings!E5 -> 114.99 | G18: =Holdings!G5 -> 26 | H18: =Holdings!L5 -> 2940.6 | I18: =Holdings!H5 -> 2989.74
C19: =Holdings!C10 -> Delta Airlines | D19: ='Holdings Pull Sheet'!B21 -> DAL | E19: =I19/H19-1 -> 0.069754145 | F19: =Holdings!E9 -> 24.35 | G19: =Holdings!G10 -> 150 | H19: =Holdings!L10 -> 2623.5 | I19: =Holdings!H10 -> 2806.5
C20: =Holdings!C7 -> Caterpillar | D20: ='Holdings Pull Sheet'!B18 -> CAT | E20: =I20/H20-1 -> 0.013571429 | F20: =Holdings!E7 -> 85.14 | G20: =Holdings!G7 -> 15.172 | H20: =Holdings!L7 -> 1274.448 | I20: =Holdings!H7 -> 1291.7441
C21: =Holdings!C22 -> 0 | D21: ='Holdings Pull Sheet'!B46 -> XRX | E21: =I21/H21-1 -> #REF! | F21: =Holdings!#REF! -> #REF! | G21: =Holdings!G22 -> 0 | H21: =Holdings!#REF! -> #REF! | I21: =Holdings!#REF! -> #REF!
C22: =Holdings!C9 -> Cisco | D22: ='Holdings Pull Sheet'!B20 -> CSCO | E22: =I22/H22-1 -> 0.26285002 | F22: =Holdings!E8 -> 10.55 | G22: =Holdings!G9 -> 68.058 | H22: =Holdings!L9 -> 1670.8239 | I22: =Holdings!H8 -> 2110
C23: =Holdings!#REF! -> #REF! | D23: ='Holdings Pull Sheet'!B32 -> YRCW | E23: =I23/H23-1 -> #REF! | F23: =Holdings!#REF! -> #REF! | G23: =Holdings!#REF! -> #REF! | H23: =Holdings!#REF! -> #REF! | I23: =Holdings!#REF! -> #REF!
C24: =Holdings!C4 -> Cash | F24: =Holdings!E4 -> 1 | G24: =Holdings!G4 -> 8114.57 | H24: =Holdings!L4 -> 4444.5729 | I24: =Holdings!H4 -> 8114.57
H25: =Holdings!L22 -> 50295.736 | I25: =SUM(I4:J24) -> #REF!

Sheet Holdings Pull Sheet
C5: Stock Quote Symbols | D5: $INDU,$COMP,$INX,$COMPX,BRK.B,MCLOX,CAT,CX,CSCO,DAL,GNTX,HD,IMMR,INTC,MDT,NGVC,TPC,TSN,WFC,YHOO,YRCW,.C\12A21\5.0,VALE,CPL,SYK,PGX, PTR,UPS,F,TTEK,WMMVY,ITRI,HCP,QCOM,XRX,DIS,PSX
C9: Stock Quotes Provided by MSN Money
C10: Click here to visit MSN Money
F11: Last | G11: Previous Close | H11: High | I11: Low | J11: Volume | K11: Change | L11: % Change | M11: 52 Wk High | N11: 52 Wk Low | O11: Market Cap | P11: EPS | Q11: P/E Ratio | R11: # Shares Out
C12: Dow Jones Industrial Average Index | D12: Chart | E12: News | F12: 15176.08 | G12: 14995.23 | H12: 15202.27 | I12: 14953.45 | J12: 104486129 | K12: 180.85 | L12: 0.0121 | M12: 15542.4 | N12: 12450.17
C13: NASDAQ Composite Index | D13: Chart | E13: News | F13: 3445.37 | G13: 3400.43 | H13: 3451.03 | I13: 3387.61 | J13: 1583241074 | K13: 44.94 | L13: 0.0132 | M13: 3532.04 | N13: 2807.55
C14: S&P 500 INDEX | D14: Chart | E14: News | F14: 1636.36 | G14: 1612.52 | H14: 1639.25 | I14: 1608.07 | J14: 0 | K14: 23.84 | L14: 0.0148 | M14: 1687.18 | N14: 1309.27
C15: NASDAQ Composite Index | D15: Chart | E15: News | F15: 3445.37 | G15: 3400.43 | H15: 3451.03 | I15: 3387.61 | J15: 1583241074 | K15: 44.94 | L15: 0.0132 | M15: 3532.04 | N15: 2807.55
B16: BRK.B | C16: Berkshire Hathaway Ord Shs Class B | D16: Chart | E16: News | F16: 114.99 | G16: 112.95 | H16: 115.14 | I16: 112.27 | J16: 4022135 | K16: 2.04 | L16: 0.0181 | M16: 115.98 | N16: 80.24 | O16: 283482541934 | P16: 9988.97 | Q16: 17 | R16: 2465280000
B17: MCLOX | C17: BlackRock Global Allocation Inv C | D17: Chart | E17: News | F17: 19.39 | G17: 19.25 | H17: 0 | I17: 0 | J17: 0 | K17: 0.14 | L17: 0.0073 | M17: 20.05 | N17: 17.04
B18: CAT | C18: Caterpillar Inc | D18: Chart | E18: News | F18: 85.14 | G18: 83.21 | H18: 85.28 | I18: 83.19 | J18: 6353695 | K18: 1.93 | L18: 0.0232 | M18: 99.7 | N18: 78.25 | O18: 55978263985 | P18: 7.43 | Q18: 11.2 | R18: 657484900
B19: CX | C19: Cemex ADR Representing 10 Par Shs | D19: Chart | E19: News | F19: 10.55 | G19: 10.25 | H19: 10.61 | I19: 10.27 | J19: 14882948 | K19: 0.3 | L19: 0.0293 | M19: 12.57 | N19: 4.75 | O19: 11867494765 | P19: -1.03 | R19: 1124881000
B20: CSCO | C20: Cisco Systems Inc | D20: Chart | E20: News | F20: 24.35 | G20: 23.99 | H20: 24.4 | I20: 23.88 | J20: 27240075 | K20: 0.36 | L20: 0.015 | M20: 24.78 | N20: 14.96 | O20: 130134583639 | P20: 1.8 | Q20: 13.4 | R20: 5344336000
B21: DAL | C21: Delta Air Lines Inc | D21: Chart | E21: News | F21: 18.71 | G21: 18.07 | H21: 18.8 | I21: 17.91 | J21: 12372788 | K21: 0.64 | L21: 0.0354 | M21: 19.43 | N21: 8.42 | O21: 16025959908 | P21: 1.05 | Q21: 17.6 | R21: 856545200
B22: GNTX | C22: Gentex Corp | D22: Chart | E22: News | F22: 23.27 | G22: 22.62 | H22: 23.29 | I22: 22.37 | J22: 627199 | K22: 0.65 | L22: 0.0287 | M22: 25.4 | N22: 14.38 | O22: 3341199746 | P22: 1.17 | Q22: 19.5 | R22: 143584000
B23: HD | C23: Home Depot Inc | D23: Chart | E23: News | F23: 76.53 | G23: 76.4 | H23: 76.83 | I23: 76.08 | J23: 9197359 | K23: 0.13 | L23: 0.0017 | M23: 81.56 | N23: 49.77 | O23: 111794716097 | P23: 3.16 | Q23: 24.6 | R23: 1460796000
B24: IMMR | C24: Immersion Corp | D24: Chart | E24: News | F24: 14.91 | G24: 14.27 | H24: 15.04 | I24: 14.13 | J24: 479639 | K24: 0.64 | L24: 0.0448 | M24: 15.75 | N24: 4.15 | O24: 415953957 | P24: -0.11 | R24: 27897650
B25: INTC | C25: Intel Corp | D25: Chart | E25: News | F25: 24.99 | G25: 24.46 | H25: 25.01 | I25: 24.4 | J25: 27709957 | K25: 0.53 | L25: 0.0217 | M25: 27.75 | N25: 19.23 | O25: 124225288862 | P25: 2 | Q25: 12.3 | R25: 4971000000
B26: MDT | C26: Medtronic Inc | D26: Chart | E26: News | F26: 52.78 | G26: 51.61 | H26: 52.85 | I26: 51.09 | J26: 5178134 | K26: 1.17 | L26: 0.0227 | M26: 53.83 | N26: 36.91 | O26: 53508679442 | P26: 3.38 | Q26: 15.4 | R26: 1013806000
B27: NGVC | C27: Natural Grocers by Vitamin Cottage Inc | D27: Chart | E27: News | F27: 27.69 | G27: 27.31 | H27: 27.79 | I27: 27.18 | J27: 49850 | K27: 0.38 | L27: 0.0139 | M27: 30.28 | N27: 17.2 | O27: 620309177 | P27: 5.31 | Q27: 5.2 | R27: 22401920
B28: TPC | C28: Tutor Perini Corp | D28: Chart | E28: News | F28: 17.43 | G28: 16.85 | H28: 17.48 | I28: 16.79 | J28: 77506 | K28: 0.58 | L28: 0.0344 | M28: 19.38 | N28: 9.21 | O28: 829244291 | P28: -5.3 | R28: 47575690
B29: TSN | C29: Tyson Foods Inc | D29: Chart | E29: News | F29: 25.71 | G29: 25.42 | H29: 25.79 | I29: 25.37 | J29: 2340681 | K29: 0.29 | L29: 0.0114 | M29: 25.86 | N29: 14.06 | O29: 9122992637 | P29: 1.45 | Q29: 17.5 | R29: 354842200
B30: WFC | C30: Wells Fargo & Co | D30: Chart | E30: News | F30: 40.94 | G30: 40.27 | H30: 40.99 | I30: 40.2 | J30: 17378892 | K30: 0.67 | L30: 0.0166 | M30: 41.69 | N30: 31.15 | O30: 216834076507 | P30: 3.53 | Q30: 11.5 | R30: 5296387000
B31: YHOO | C31: Yahoo! Inc | D31: Chart | E31: News | F31: 26.37 | G31: 25.89 | H31: 26.46 | I31: 25.71 | J31: 9764435 | K31: 0.48 | L31: 0.0185 | M31: 27.68 | N31: 14.59 | O31: 28549085859 | P31: 3.41 | Q31: 7.7 | R31: 1082635000
B32: YRCW | C32: YRC Worldwide Inc | D32: Chart | E32: News | F32: 22.6 | G32: 21.89 | H32: 22.85 | I32: 21.63 | J32: 348230 | K32: 0.71 | L32: 0.0324 | M32: 25 | N32: 5.01 | O32: 212369040 | P32: -14.95 | R32: 9396860
C33: .C\12A21\5.0 (Invalid symbol) | D33: ??? | E33: ??? | F33: ??? | G33: ??? | H33: ??? | I33: ??? | J33: ??? | K33: ??? | L33: ??? | M33: ??? | N33: ??? | O33: ??? | P33: ??? | Q33: ??? | R33: ???
B34: VALE | C34: Vale ADR Representing One Ord Shs | D34: Chart | E34: News | F34: 14.47 | G34: 13.71 | H34: 14.52 | I34: 13.83 | J34: 24769220 | K34: 0.76 | L34: 0.0554 | M34: 21.88 | N34: 13.6 | O34: 77635950313 | P34: 0.92 | Q34: 11.2 | R34: 5365304000
B35: CPL | C35: CPFL Energia SA | D35: Chart | E35: News | F35: 20.31 | G35: 19.85 | H35: 20.31 | I35: 19.93 | J35: 222130 | K35: 0.46 | L35: 0.0232 | M35: 25.81 | N35: 19.3 | O35: 9771894244 | P35: 1.17 | Q35: 17.3 | R35: 481137100
B36: SYK | C36: Stryker Corp | D36: Chart | E36: News | F36: 67.72 | G36: 66.37 | H36: 67.79 | I36: 65.81 | J36: 783003 | K36: 1.35 | L36: 0.0203 | M36: 70 | N36: 50.04 | O36: 25602006957 | P36: 3.27 | Q36: 20.4 | R36: 378056800
B37: PGX | C37: PowerShares Preferred | D37: Chart | E37: News | F37: 14.29 | G37: 14.11 | H37: 14.33 | I37: 13.92 | J37: 2410446 | K37: 0.18 | L37: 0.0128 | M37: 15.12 | N37: 14.04
B38: PTR | C38: Petrochina ADR Representing 100 Ord Shs | D38: Chart | E38: News | F38: 110.05 | G38: 110.3 | H38: 110.36 | I38: 108.1 | J38: 153672 | K38: -0.25 | L38: -0.0023 | M38: 146.68 | N38: 109.96 | O38: 201414506035 | P38: 10.05 | Q38: 11.1 | R38: 1830209000
B39: UPS | C39: United Parcel Service Inc | D39: Chart | E39: News | F39: 86.32 | G39: 85.51 | H39: 86.48 | I39: 85.11 | J39: 2281928 | K39: 0.81 | L39: 0.0095 | M39: 89.96 | N39: 69.56 | O39: 81515549360 | P39: 0.88 | Q39: 97 | R39: 944341400
B40: F | C40: Ford Motor Co | D40: Chart | E40: News | F40: 15.58 | G40: 15.37 | H40: 15.6 | I40: 15.18 | J40: 34327479 | K40: 0.21 | L40: 0.0137 | M40: 16.09 | N40: 8.82 | O40: 61248189180 | P40: 1.48 | Q40: 10.5 | R40: 3931206000
B41: TTEK | C41: Tetra Tech Inc | D41: Chart | E41: News | F41: 26.68 | G41: 26.92 | H41: 27.15 | I41: 26.57 | J41: 425878 | K41: -0.24 | L41: -0.0089 | M41: 31.49 | N41: 23.79 | O41: 1732278526 | P41: 1.71 | Q41: 15.8 | R41: 64927980
B42: WMMVY | C42: Wal Mart ADR Rep Ser V 10 Ord Shs | D42: Chart | E42: News | F42: 28.65 | G42: 28 | H42: 28.65 | I42: 28.02 | J42: 21361 | K42: 0.65 | L42: 0.0232 | M42: 33.85 | N42: 24.52 | O42: 50732989574 | P42: 1.02 | Q42: 27.1 | R42: 1770785000
B43: ITRI | C43: Itron Inc | D43: Chart | E43: News | F43: 42.52 | G43: 42.25 | H43: 42.56 | I43: 41.91 | J43: 349182 | K43: 0.27 | L43: 0.0064 | M43: 48.42 | N43: 35.53 | O43: 1680922343 | P43: 2.14 | Q43: 19.7 | R43: 39532510
B44: HCP | C44: HCP Inc | D44: Chart | E44: News | F44: 45.99 | G44: 45.36 | H44: 46.14 | I44: 45.2 | J44: 4439546 | K44: 0.63 | L44: 0.0139 | M44: 56.06 | N44: 40.92 | O44: 20901821101 | P44: 2.02 | Q44: 23.6 | R44: 454486200
B45: QCOM | C45: Qualcomm Inc | D45: Chart | E45: News | F45: 61.96 | G45: 61.11 | H45: 62.12 | I45: 60.75 | J45: 11578784 | K45: 0.85 | L45: 0.0139 | M45: 68.5 | N45: 53.09 | O45: 107056655018 | P45: 3.56 | Q45: 17.4 | R45: 1727835000
B46: XRX | C46: Xerox Corp | D46: Chart | E46: News | F46: 9.1 | G46: 8.85 | H46: 9.13 | I46: 8.77 | J46: 6511217 | K46: 0.25 | L46: 0.0282 | M46: 9.38 | N46: 6.1 | O46: 11173917768 | P46: 0.93 | Q46: 9.8 | R46: 1227903000
B47: DIS | C47: Walt Disney Co | D47: Chart | E47: News | F47: 64.3 | G47: 62.99 | H47: 64.4 | I47: 62.52 | J47: 5584875 | K47: 1.31 | L47: 0.0208 | M47: 67.89 | N47: 45.99 | O47: 115800576096 | P47: 3.29 | Q47: 19.4 | R47: 1800942000
...

Sheet Data
D1: IPO Portfolio | L1: S&P 500 Index
A2: Week # | B2: Date | D2: Portfolio Value | E2: Adjusted Portfolio Value | F2: Weekly +/- | G2: Weekly % Change | H2: Inception +/- | I2: Inception % Change | L2: S&P Close | M2: S&P Weekly % Change | N2: S&P Inception % Change | O2: Outperformed S&P 500? | P2: 1 = Yes, 0 = No | Q2: % IPO Outperforemed S&P 500 | S2: Dow Close | T2: Dow Weekly % Change | U2: Dow Inception % Change | V2: Outperformed Dow? | W2: 1 = Yes, 0 = No | X2: % IPO Outperforemed Dow | Z2: Nasdaq Close | AA2: Nasdaq Weekly % Change | AB2: Nasdaq Inception % Change
A3: 1 | B3: 37743 | D3: 22855.85 | E3: =D3 -> 22855.85 | F3: - | G3: - | H3: - | I3: - | L3: 930.08 | M3: - | N3: - | S3: 8582.68 | T3: - | U3: - | Z3: 1502.88 | AA3: - | AB3: -
A4: 2 | B4: 37750 | D4: 23075.51 | E4: =D4 -> 23075.51 | F4: =D4-D3 -> 219.66 | G4: =(D4/D3)-1 -> 0.0096106686 | H4: =D4-$D$3 -> 219.66 | I4: =(D4/$D$3)-1 -> 0.0096106686 | L4: 933.41 | M4: =(L4/L3)-1 -> 0.0035803372 | N4: =(L4/$L$3)-1 -> 0.0035803372 | O4: =IF(G4>M4,"Yes","No") -> Yes | P4: =IF(O4="Yes",1,0) -> 1 | Q4: =SUM(P4)/COUNT(P4) -> 1 | S4: 8604.6 | T4: =(S4/S3)-1 -> 0.0025539808 | U4: =(S4/$S$3)-1 -> 0.0025539808 | V4: =IF(G4>T4,"Yes","No") -> Yes | W4: =IF(V4="Yes",1,0) -> 1 | Z4: 1520.15 | AA4: =(Z4/Z3)-1 -> 0.01149127 | AB4: =(Z4/$Z$3)-1 -> 0.01149127
A5: 3 | B5: =B4+7 -> 37757 | D5: 23259.78 | E5: =D5 -> 23259.78 | F5: =D5-D4 -> 184.27 | G5: =(D5/D4)-1 -> 0.0079855223 | H5: =D5-$D$3 -> 403.93 | I5: =(D5/$D$3)-1 -> 0.017672937 | L5: 944.3 | M5: =(L5/L4)-1 -> 0.011666899 | N5: =(L5/$L$3)-1 -> 0.015289007 | O5: =IF(G5>M5,"Yes","No") -> No | P5: =IF(O5="Yes",1,0) -> 0 | Q5: =SUM(P4:P5)/COUNT(P4:P5) -> 0.5 | S5: 8678.97 | T5: =(S5/S4)-1 -> 0.0086430514 | U5: =(S5/$S$3)-1 -> 0.011219106 | V5: =IF(G5>T5,"Yes","No") -> No | W5: =IF(V5="Yes",1,0) -> 0 | Z5: 1538.53 | AA5: =(Z5/Z4)-1 -> 0.012090912 | AB5: =(Z5/$Z$3)-1 -> 0.023721122
A6: 4 | B6: =B5+7 -> 37764 | D6: 22880.42 | E6: =D6 -> 22880.42 | F6: =D6-D5 -> -379.36 | G6: =(D6/D5)-1 -> -0.016309699 | H6: =D6-$D$3 -> 24.57 | I6: =(D6/$D$3)-1 -> 0.0010749983 | L6: 921.29 | M6: =(L6/L5)-1 -> -0.024367256 | N6: =(L6/$L$3)-1 -> -0.0094507999 | O6: =IF(G6>M6,"Yes","No") -> Yes | P6: =IF(O6="Yes",1,0) -> 1 | Q6: =SUM(P4:P6)/COUNT(P4:P6) -> 0.66666667 | S6: 8497.59 | T6: =(S6/S5)-1 -> -0.020898793 | U6: =(S6/$S$3)-1 -> -0.0099141527 | V6: =IF(G6>T6,"Yes","No") -> Yes | W6: =IF(V6="Yes",1,0) -> 1 | Z6: 1483.2 | AA6: =(Z6/Z5)-1 -> -0.0359629 | AB6: =(Z6/$Z$3)-1 -> -0.013094858
A7: 5 | B7: =B6+7 -> 37771 | D7: 24142.6 | E7: =D7 -> 24142.6 | F7: =D7-D6 -> 1262.18 | G7: =(D7/D6)-1 -> 0.055164197 | H7: =D7-$D$3 -> 1286.75 | I7: =(D7/$D$3)-1 -> 0.056298497 | L7: 963.59 | M7: =(L7/L6)-1 -> 0.045913882 | N7: =(L7/$L$3)-1 -> 0.036029159 | O7: =IF(G7>M7,"Yes","No") -> Yes | P7: =IF(O7="Yes",1,0) -> 1 | S7: 8850.26 | T7: =(S7/S6)-1 -> 0.041502355 | U7: =(S7/$S$3)-1 -> 0.031176742 | V7: =IF(G7>T7,"Yes","No") -> Yes | W7: =IF(V7="Yes",1,0) -> 1 | Z7: 1595.91 | AA7: =(Z7/Z6)-1 -> 0.0759911 | AB7: =(Z7/$Z$3)-1 -> 0.06190115
A8: 6 | B8: =B7+7 -> 37778 | D8: 24843.31 | E8: =D8 -> 24843.31 | F8: =D8-D7 -> 700.71 | G8: =(D8/D7)-1 -> 0.0290238 | H8: =D8-$D$3 -> 1987.46 | I8: =(D8/$D$3)-1 -> 0.086956293 | L8: 987.76 | M8: =(L8/L7)-1 -> 0.025083282 | N8: =(L8/$L$3)-1 -> 0.062016171 | O8: =IF(G8>M8,"Yes","No") -> Yes | P8: =IF(O8="Yes",1,0) -> 1 | S8: 9062.79 | T8: =(S8/S7)-1 -> 0.024013984 | U8: =(S8/$S$3)-1 -> 0.055939404 | V8: =IF(G8>T8,"Yes","No") -> Yes | W8: =IF(V8="Yes",1,0) -> 1 | Z8: 1627.42 | AA8: =(Z8/Z7)-1 -> 0.019744221 | AB8: =(Z8/$Z$3)-1 -> 0.082867561
A9: 7 | B9: =B8+7 -> 37785 | D9: 24777.34 | E9: =D9 -> 24777.34 | F9: =D9-D8 -> -65.97 | G9: =(D9/D8)-1 -> -0.0026554433 | H9: =D9-$D$3 -> 1921.49 | I9: =(D9/$D$3)-1 -> 0.084069943 | L9: =995.16-6.55 -> 988.61 | M9: =(L9/L8)-1 -> 0.00086053292 | N9: =(L9/$L$3)-1 -> 0.062930071 | O9: =IF(G9>M9,"Yes","No") -> No | P9: =IF(O9="Yes",1,0) -> 0 | S9: =9176.41-59.29 -> 9117.12 | T9: =(S9/S8)-1 -> 0.0059948426 | U9: =(S9/$S$3)-1 -> 0.062269594 | V9: =IF(G9>T9,"Yes","No") -> No | W9: =IF(V9="Yes",1,0) -> 0 | Z9: =1637.82-11.33 -> 1626.49 | AA9: =(Z9/Z8)-1 -> -0.00057145666 | AB9: =(Z9/$Z$3)-1 -> 0.082248749
A10: 8 | B10: =B9+7 -> 37792 | D10: 25072.64 | E10: =D10 -> 25072.64 | F10: =D10-D9 -> 295.3 | G10: =(D10/D9)-1 -> 0.011918148 | H10: =D10-$D$3 -> 2216.79 | I10: =(D10/$D$3)-1 -> 0.096990048 | L10: 995.69 | M10: =(L10/L9)-1 -> 0.0071615703 | N10: =(L10/$L$3)-1 -> 0.070542319 | O10: =IF(G10>M10,"Yes","No") -> Yes | P10: =IF(O10="Yes",1,0) -> 1 | S10: 9200.75 | T10: =(S10/S9)-1 -> 0.0091728528 | U10: =(S10/$S$3)-1 -> 0.072013637 | V10: =IF(G10>T10,"Yes","No") -> Yes | W10: =IF(V10="Yes",1,0) -> 1 | Z10: 1644.72 | AA10: =(Z10/Z9)-1 -> 0.011208184 | AB10: =(Z10/$Z$3)-1 -> 0.094378793
A11: 9 | B11: =B10+7 -> 37799 | D11: 24857.12 | E11: =D11 -> 24857.12 | F11: =D11-D10 -> -215.52 | G11: =(D11/D10)-1 -> -0.008595824 | H11: =D11-$D$3 -> 2001.27 | I11: =(D11/$D$3)-1 -> 0.087560515 | L11: 976.22 | M11: =(L11/L10)-1 -> -0.019554279 | N11: =(L11/$L$3)-1 -> 0.049608636 | O11: =IF(G11>M11,"Yes","No") -> Yes | P11: =IF(O11="Yes",1,0) -> 1 | S11: 8989.05 | T11: =(S11/S10)-1 -> -0.023008994 | U11: =(S11/$S$3)-1 -> 0.047347682 | V11: =IF(G11>T11,"Yes","No") -> Yes | W11: =IF(V11="Yes",1,0) -> 1 | Z11: 1625.26 | AA11: =(Z11/Z10)-1 -> -0.011831801 | AB11: =(Z11/$Z$3)-1 -> 0.08143032
A12: 10 | B12: =B11+7 -> 37806 | D12: 24907.37 | E12: =D12 -> 24907.37 | F12: =D12-D11 -> 50.25 | G12: =(D12/D11)-1 -> 0.0020215536 | H12: =D12-$D$3 -> 2051.52 | I12: =(D12/$D$3)-1 -> 0.089759077 | L12: 991.66 | M12: =(L12/L11)-1 -> 0.015816107 | N12: =(L12/$L$3)-1 -> 0.066209358 | O12: =IF(G12>M12,"Yes","No") -> No | P12: =IF(O12="Yes",1,0) -> 0 | S12: 9070.21 | T12: =(S12/S11)-1 -> 0.0090287628 | U12: =(S12/$S$3)-1 -> 0.056803935 | V12: =IF(G12>T12,"Yes","No") -> No | W12: =IF(V12="Yes",1,0) -> 0 | Z12: 1663.46 | AA12: =(Z12/Z11)-1 -> 0.023503932 | AB12: =(Z12/$Z$3)-1 -> 0.10684818
A13: 11 | B13: =B12+7 -> 37813 | D13: 25578.29 | E13: =D13 -> 25578.29 | F13: =D13-D12 -> 670.92 | G13: =(D13/D12)-1 -> 0.026936606 | H13: =D13-$D$3 -> 2722.44 | I13: =(D13/$D$3)-1 -> 0.11911349 | L13: 998.14 | M13: =(L13/L12)-1 -> 0.0065344977 | N13: =(L13/$L$3)-1 -> 0.073176501 | O13: =IF(G13>M13,"Yes","No") -> Yes | P13: =IF(O13="Yes",1,0) -> 1 | S13: 9119.59 | T13: =(S13/S12)-1 -> 0.0054441959 | U13: =(S13/$S$3)-1 -> 0.062557383 | V13: =IF(G13>T13,"Yes","No") -> Yes | W13: =IF(V13="Yes",1,0) -> 1 | Z13: 1733.93 | AA13: =(Z13/Z12)-1 -> 0.042363507 | AB13: =(Z13/$Z$3)-1 -> 0.15373816
A14: 12 | B14: =B13+7 -> 37820 | D14: 25192.44 | E14: =D14 -> 25192.44 | F14: =D14-D13 -> -385.85 | G14: =(D14/D13)-1 -> -0.015085058 | H14: =D14-$D$3 -> 2336.59 | I14: =(D14/$D$3)-1 -> 0.10223159 | L14: 993.32 | M14: =(L14/L13)-1 -> -0.0048289819 | N14: =(L14/$L$3)-1 -> 0.067994151 | O14: =IF(G14>M14,"Yes","No") -> No | P14: =IF(O14="Yes",1,0) -> 0 | S14: 9188.15 | T14: =(S14/S13)-1 -> 0.0075178818 | U14: =(S14/$S$3)-1 -> 0.070545564 | V14: =IF(G14>T14,"Yes","No") -> No | W14: =IF(V14="Yes",1,0) -> 0 | Z14: 1708.5 | AA14: =(Z14/Z13)-1 -> -0.014666105 | AB14: =(Z14/$Z$3)-1 -> 0.13681731
A15: 13 | B15: =B14+7 -> 37827 | D15: 25421.8 | E15: =D15 -> 25421.8 | F15: =D15-D14 -> 229.36 | G15: =(D15/D14)-1 -> 0.0091043186 | H15: =D15-$D$3 -> 2565.95 | I15: =(D15/$D$3)-1 -> 0.11226666 | L15: 998.68 | M15: =(L15/L14)-1 -> 0.0053960456 | N15: =(L15/$L$3)-1 -> 0.073757096 | O15: =IF(G15>M15,"Yes","No") -> Yes | P15: =IF(O15="Yes",1,0) -> 1 | S15: 9284.57 | T15: =(S15/S14)-1 -> 0.010493951 | U15: =(S15/$S$3)-1 -> 0.081779817 | V15: =IF(G15>T15,"Yes","No") -> No | W15: =IF(V15="Yes",1,0) -> 0 | Z15: 1730.7 | AA15: =(Z15/Z14)-1 -> 0.012993854 | AB15: =(Z15/$Z$3)-1 -> 0.15158895
A16: 14 | B16: =B15+7 -> 37834 | D16: 25266.57 | E16: =D16 -> 25266.57 | F16: =D16-D15 -> -155.23 | G16: =(D16/D15)-1 -> -0.0061061766 | H16: =D16-$D$3 -> 2410.72 | I16: =(D16/$D$3)-1 -> 0.10547497 | L16: 980.15 | M16: =(L16/L15)-1 -> -0.018554492 | N16: =(L16/$L$3)-1 -> 0.053834079 | O16: =IF(G16>M16,"Yes","No") -> Yes | P16: =IF(O16="Yes",1,0) -> 1 | S16: 9153.97 | T16: =(S16/S15)-1 -> -0.014066349 | U16: =(S16/$S$3)-1 -> 0.066563125 | V16: =IF(G16>T16,"Yes","No") -> Yes | W16: =IF(V16="Yes",1,0) -> 1 | Z16: 1715.62 | AA16: =(Z16/Z15)-1 -> -0.0087132374 | AB16: =(Z16/$Z$3)-1 -> 0.14155488
A17: 15 | B17: =B16+7 -> 37841 | D17: 25228.34 | E17: =D17 -> 25228.34 | F17: =D17-D16 -> -38.23 | G17: =(D17/D16)-1 -> -0.0015130665 | H17: =D17-$D$3 -> 2372.49 | I17: =(D17/$D$3)-1 -> 0.10380231 | L17: 977.59 | M17: =(L17/L16)-1 -> -0.0026118451 | N17: =(L17/$L$3)-1 -> 0.051081627 | O17: =IF(G17>M17,"Yes","No") -> Yes | P17: =IF(O17="Yes",1,0) -> 1 | S17: 9191.09 | T17: =(S17/S16)-1 -> 0.0040550712 | U17: =(S17/$S$3)-1 -> 0.070888114 | V17: =IF(G17>T17,"Yes","No") -> No | W17: =IF(V17="Yes",1,0) -> 0 | Z17: 1644.03 | AA17: =(Z17/Z16)-1 -> -0.041728355 | AB17: =(Z17/$Z$3)-1 -> 0.093919674
A18: 16 | B18: =B17+7 -> 37848 | D18: 24951.71 | E18: =D18 -> 24951.71 | F18: =D18-D17 -> -276.63 | G18: =(D18/D17)-1 -> -0.01096505 | H18: =D18-$D$3 -> 2095.86 | I18: =(D18/$D$3)-1 -> 0.091699062 | L18: 990.67 | M18: =(L18/L17)-1 -> 0.013379842 | N18: =(L18/$L$3)-1 -> 0.065144934 | O18: =IF(G18>M18,"Yes","No") -> No | P18: =IF(O18="Yes",1,0) -> 0 | S18: 9321.69 | T18: =(S18/S17)-1 -> 0.014209414 | U18: =(S18/$S$3)-1 -> 0.086104806 | V18: =IF(G18>T18,"Yes","No") -> No | W18: =IF(V18="Yes",1,0) -> 0 | Z18: 1702.01 | AA18: =(Z18/Z17)-1 -> 0.035266996 | AB18: =(Z18/$Z$3)-1 -> 0.13249894
A19: 17 | B19: =B18+7 -> 37855 | D19: 25454.04 | E19: =D19 -> 25454.04 | F19: =D19-D18 -> 502.33 | G19: =(D19/D18)-1 -> 0.020132087 | H19: =D19-$D$3 -> 2598.19 | I19: =(D19/$D$3)-1 -> 0.11367724 | L19: 993.06 | M19: =(L19/L18)-1 -> 0.0024125087 | N19: =(L19/$L$3)-1 -> 0.067714605 | O19: =IF(G19>M19,"Yes","No") -> Yes | P19: =IF(O19="Yes",1,0) -> 1 | S19: 9348.87 | T19: =(S19/S18)-1 -> 0.0029157803 | U19: =(S19/$S$3)-1 -> 0.089271649 | V19: =IF(G19>T19,"Yes","No") -> Yes | W19: =IF(V19="Yes",1,0) -> 1 | Z19: 1765.32 | AA19: =(Z19/Z18)-1 -> 0.037197196 | AB19: =(Z19/$Z$3)-1 -> 0.17462472
A20: 18 | B20: =B19+7 -> 37862 | D20: 26198.38 | E20: =D20 -> 26198.38 | F20: =D20-D19 -> 744.34 | G20: =(D20/D19)-1 -> 0.029242509 | H20: =D20-$D$3 -> 3342.53 | I20: =(D20/$D$3)-1 -> 0.14624396 | L20: 1008.01 | M20: =(L20/L19)-1 -> 0.015054478 | N20: =(L20/$L$3)-1 -> 0.083788491 | O20: =IF(G20>M20,"Yes","No") -> Yes | P20: =IF(O20="Yes",1,0) -> 1 | S20: 9415.82 | T20: =(S20/S19)-1 -> 0.0071612933 | U20: =(S20/$S$3)-1 -> 0.097072243 | V20: =IF(G20>T20,"Yes","No") -> Yes | W20: =IF(V20="Yes",1,0) -> 1 | Z20: 1810.45 | AA20: =(Z20/Z19)-1 -> 0.02556477 | AB20: =(Z20/$Z$3)-1 -> 0.20465373
A21: 19 | B21: =B20+7 -> 37869 | D21: 26545.65 | E21: =D21 -> 26545.65 | F21: =D21-D20 -> 347.27 | G21: =(D21/D20)-1 -> 0.0132554 | H21: =D21-$D$3 -> 3689.8 | I21: =(D21/$D$3)-1 -> 0.16143788 | L21: 1021.39 | M21: =(L21/L20)-1 -> 0.013273678 | N21: =(L21/$L$3)-1 -> 0.098174351 | O21: =IF(G21>M21,"Yes","No") -> No | P21: =IF(O21="Yes",1,0) -> 0 | S21: 9503.34 | T21: =(S21/S20)-1 -> 0.009294995 | U21: =(S21/$S$3)-1 -> 0.10726952 | V21: =IF(G21>T21,"Yes","No") -> Yes | W21: =IF(V21="Yes",1,0) -> 1 | Z21: 1858.24 | AA21: =(Z21/Z20)-1 -> 0.026396752 | AB21: =(Z21/$Z$3)-1 -> 0.23645268
... A37: 35 | B37: =B36+7 -> 37981 | D37: 29690.49 | E37: =D37 -> 29690.49 | F37: =D37-D36 -> 362.49 | G37: =(D37/D36)-1 -> 0.012359861 | H37: =D37-$D$3 -> 6834.64 | I37: =(D37/$D$3)-1 -> 0.29903241 | L37: 1095.89 | M37: =(L37/L36)-1 -> 0.0066411919 | N37: =(L37/$L$3)-1 -> 0.17827499 | O37: =IF(G37>M37,"Yes","No") -> Yes | P37: =IF(O37="Yes",1,0) -> 1 | S37: 10324.67 | T37: =(S37/S36)-1 -> 0.004519265 | U37: =(S37/$S$3)-1 -> 0.20296574 | V37: =IF(G37>T37,"Yes","No") -> Yes | W37: =IF(V37="Yes",1,0) -> 1 | Z37: 1973.14 | AA37: =(Z37/Z36)-1 -> 0.0082370134 | AB37: =(Z37/$Z$3)-1 -> 0.31290589
A38: 36 | B38: =B37+7 -> 37988 | D38: 30649.47 | E38: =D38 -> 30649.47 | F38: =D38-D37 -> 958.98 | G38: =(D38/D37)-1 -> 0.032299231 | H38: =D38-$D$3 -> 7793.62 | I38: =(D38/$D$3)-1 -> 0.34099016 | J38: 0 | L38: 1108.48 | M38: =(L38/L37)-1 -> 0.011488379 | N38: =(L38/$L$3)-1 -> 0.19181146 | O38: =IF(G38>M38,"Yes","No") -> Yes | P38: =IF(O38="Yes",1,0) -> 1 | R38: 0 | S38: 10409.85 | T38: =(S38/S37)-1 -> 0.0082501426 | U38: =(S38/$S$3)-1 -> 0.21289038 | V38: =IF(G38>T38,"Yes","No") -> Yes | W38: =IF(V38="Yes",1,0) -> 1 | Z38: 2006.68 | AA38: =(Z38/Z37)-1 -> 0.016998287 | AB38: =(Z38/$Z$3)-1 -> 0.33522304
A39: 37 | B39: =B38+7 -> 37995 | D39: 30712.11 | E39: =D39 -> 30712.11 | F39: =D39-D38 -> 62.64 | G39: =(D39/D38)-1 -> 0.0020437548 | H39: =D39-$D$3 -> 7856.26 | I39: =(D39/$D$3)-1 -> 0.34373082 | J39: =(E39/$E$38)-1 -> 0.0020437548 | L39: 1121.86 | M39: =(L39/L38)-1 -> 0.012070583 | N39: =(L39/$L$3)-1 -> 0.20619732 | O39: =IF(G39>M39,"Yes","No") -> No | P39: =IF(O39="Yes",1,0) -> 0 | R39: =(L39/$L$38)-1 -> 0.012070583 | S39: 10458.89 | T39: =(S39/S38)-1 -> 0.0047109228 | U39: =(S39/$S$3)-1 -> 0.21860421 | V39: =IF(G39>T39,"Yes","No") -> No | W39: =IF(V39="Yes",1,0) -> 0 | Z39: 2086.92 | AA39: =(Z39/Z38)-1 -> 0.039986445 | AB39: =(Z39/$Z$3)-1 -> 0.38861386
A40: 38 | B40: =B39+7 -> 38002 | D40: 30500.54 | E40: =D40 -> 30500.54 | F40: =D40-D39 -> -211.57 | G40: =(D40/D39)-1 -> -0.0068888136 | H40: =D40-$D$3 -> 7644.69 | I40: =(D40/$D$3)-1 -> 0.33447411 | J40: =(E40/$E$38)-1 -> -0.0048591379 | L40: 1139.83 | M40: =(L40/L39)-1 -> 0.016018041 | N40: =(L40/$L$3)-1 -> 0.22551823 | O40: =IF(G40>M40,"Yes","No") -> No | P40: =IF(O40="Yes",1,0) -> 0 | R40: =(L40/$L$38)-1 -> 0.028281972 | S40: 10600.51 | T40: =(S40/S39)-1 -> 0.013540634 | U40: =(S40/$S$3)-1 -> 0.23510489 | V40: =IF(G40>T40,"Yes","No") -> No | W40: =IF(V40="Yes",1,0) -> 0 | Z40: 2140.46 | AA40: =(Z40/Z39)-1 -> 0.025655032 | AB40: =(Z40/$Z$3)-1 -> 0.42423879
A41: 39 | B41: =B40+7 -> 38009 | D41: 30340.26 | E41: =D41+Holdings_Old!$E$32 -> 30340.26 | F41: =E41-D40 -> -160.28 | G41: =(E41/E40)-1 -> -0.0052549889 | H41: =E41-$D$3 -> 7484.41 | I41: =(E41/$D$3)-1 -> 0.32746146 | J41: =(E41/$E$38)-1 -> -0.010088592 | L41: 1141.55 | M41: =(L41/L40)-1 -> 0.001508997 | N41: =(L41/$L$3)-1 -> 0.22736754 | O41: =IF(G41>M41,"Yes","No") -> No | P41: =IF(O41="Yes",1,0) -> 0 | R41: =(L41/$L$38)-1 -> 0.029833646 | S41: 10568.29 | T41: =(S41/S40)-1 -> -0.0030394764 | U41: =(S41/$S$3)-1 -> 0.23135081 | V41: =IF(G41>T41,"Yes","No") -> No | W41: =IF(V41="Yes",1,0) -> 0 | Z41: 2123.87 | AA41: =(Z41/Z40)-1 -> -0.0077506704 | AB41: =(Z41/$Z$3)-1 -> 0.41319999
A42: 40 | B42: =B41+7 -> 38016 | D42: 29390.96 | E42: =D42+Holdings_Old!$E$32 -> 29390.96 | F42: =E42-E41 -> -949.3 | G42: =(E42/E41)-1 -> -0.03128846 | H42: =E42-$D$3 -> 6535.11 | I42: =(E42/$D$3)-1 -> 0.28592724 | J42: =(E42/$E$38)-1 -> -0.041061395 | L42: 1131.13 | M42: =(L42/L41)-1 -> -0.0091279401 | N42: =(L42/$L$3)-1 -> 0.2161642 | O42: =IF(G42>M42,"Yes","No") -> No | P42: =IF(O42="Yes",1,0) -> 0 | R42: =(L42/$L$38)-1 -> 0.020433386 | S42: 10488.07 | T42: =(S42/S41)-1 -> -0.007590632 | U42: =(S42/$S$3)-1 -> 0.22200408 | V42: =IF(G42>T42,"Yes","No") -> No | W42: =IF(V42="Yes",1,0) -> 0 | Z42: 2066.15 | AA42: =(Z42/Z41)-1 -> -0.027176805 | AB42: =(Z42/$Z$3)-1 -> 0.37479373
A43: 41 | B43: =B42+7 -> 38023 | D43: 29673.82 | E43: =D43+Holdings_Old!$E$32 -> 29673.82 | F43: =E43-E42 -> 282.86 | G43: =(E43/E42)-1 -> 0.0096240477 | H43: =E43-$D$3 -> 6817.97 | I43: =(E43/$D$3)-1 -> 0.29830306 | J43: =(E43/$E$38)-1 -> -0.031832524 | L43: 1142.76 | M43: =(L43/L42)-1 -> 0.010281754 | N43: =(L43/$L$3)-1 -> 0.2286685 | O43: =IF(G43>M43,"Yes","No") -> No | P43: =IF(O43="Yes",1,0) -> 0 | R43: =(L43/$L$38)-1 -> 0.030925231 | S43: 10593.03 | T43: =(S43/S42)-1 -> 0.010007561 | U43: =(S43/$S$3)-1 -> 0.23423336 | V43: =IF(G43>T43,"Yes","No") -> No | W43: =IF(V43="Yes",1,0) -> 0 | Z43: 2064.01 | AA43: =(Z43/Z42)-1 -> -0.0010357428 | AB43: =(Z43/$Z$3)-1 -> 0.3733698
A44: 42 | B44: =B43+7 -> 38030 | D44: 29580.97 | E44: =D44+Holdings_Old!$E$32 -> 29580.97 | F44: =E44-E43 -> -92.85 | G44: =(E44/E43)-1 -> -0.0031290208 | H44: =E44-$D$3 -> 6725.12 | I44: =(E44/$D$3)-1 -> 0.29424064 | J44: =(E44/$E$38)-1 -> -0.034861941 | L44: 1145.81 | M44: =(L44/L43)-1 -> 0.0026689769 | N44: =(L44/$L$3)-1 -> 0.23194779 | O44: =IF(G44>M44,"Yes","No") -> No | P44: =IF(O44="Yes",1,0) -> 0 | R44: =(L44/$L$38)-1 -> 0.033676747 | S44: 10628.85 | T44: =(S44/S43)-1 -> 0.0033814688 | U44: =(S44/$S$3)-1 -> 0.23840688 | V44: =IF(G44>T44,"Yes","No") -> No | W44: =IF(V44="Yes",1,0) -> 0 | Z44: 2053.56 | AA44: =(Z44/Z43)-1 -> -0.00506296 | AB44: =(Z44/$Z$3)-1 -> 0.36641648
