Workbook

Sheet Closed Counts
A1: Auto Collision Insurer
A2: Exhibit I (Sheet 1) p.215
A3: Closed Claim Counts (Excluding Closed with No Payment)
A5: PART 1 - Data Triangle
A7: AY | B7: 6 | C7: =B7+6 -> 12 | D7: =C7+6 -> 18 | E7: =D7+6 -> 24 | F7: =E7+6 -> 30 | G7: =F7+6 -> 36 | H7: =G7+6 -> 42 | I7: =H7+6 -> 48 | J7: =I7+6 -> 54 | K7: =J7+6 -> 60
A8: 2003-2 | B8: 2547 | C8: 3262 | D8: 3287 | E8: 3291 | F8: 3292 | G8: 3292 | H8: 3292 | I8: 3292 | J8: 3292 | K8: 3292
A9: 2004-1 | B9: 2791 | C9: 3217 | D9: 3240 | E9: 3242 | F9: 3243 | G9: 3243 | H9: 3243 | I9: 3243 | J9: 3242
A10: 2004-2 | B10: 2099 | C10: 2677 | D10: 2695 | E10: 2697 | F10: 2697 | G10: 2698 | H10: 2698 | I10: 2698
A11: 2005-1 | B11: 2370 | C11: 2735 | D11: 2751 | E11: 2754 | F11: 2755 | G11: 2755 | H11: 2756
A12: 2005-2 | B12: 1966 | C12: 2609 | D12: 2630 | E12: 2634 | F12: 2634 | G12: 2634
A13: 2006-1 | B13: 2261 | C13: 2671 | D13: 2694 | E13: 2696 | F13: 2697
A14: 2006-2 | B14: 1949 | C14: 2637 | D14: 2659 | E14: 2662
A15: 2007-1 | B15: 2059 | C15: 2496 | D15: 2520
A16: 2007-2 | B16: 2083 | C16: 2732
A17: 2008-1 | B17: 2533
A19: AY | B19: =B7&"-"&C7 -> 6-12 | C19: =C7&"-"&D7 -> 12-18 | D19: =D7&"-"&E7 -> 18-24 | E19: =E7&"-"&F7 -> 24-30 | F19: =F7&"-"&G7 -> 30-36 | G19: =G7&"-"&H7 -> 36-42 | H19: =H7&"-"&I7 -> 42-48 | I19: =I7&"-"&J7 -> 48-54 | J19: =J7&"-"&K7 -> 54-60 | K19: 60-Ult
A20: 2003-2 | B20: =C8/B8 -> 1.2807224 | C20: =D8/C8 -> 1.007664 | D20: =E8/D8 -> 1.0012169 | E20: =F8/E8 -> 1.0003039 | F20: =G8/F8 -> 1 | G20: =H8/G8 -> 1 | H20: =I8/H8 -> 1 | I20: =J8/I8 -> 1 | J20: =K8/J8 -> 1
A21: 2004-1 | B21: =C9/B9 -> 1.1526335 | C21: =D9/C9 -> 1.0071495 | D21: =E9/D9 -> 1.0006173 | E21: =F9/E9 -> 1.0003085 | F21: =G9/F9 -> 1 | G21: =H9/G9 -> 1 | H21: =I9/H9 -> 1 | I21: =J9/I9 -> 0.99969164
A22: 2004-2 | B22: =C10/B10 -> 1.2753692 | C22: =D10/C10 -> 1.0067239 | D22: =E10/D10 -> 1.0007421 | E22: =F10/E10 -> 1 | F22: =G10/F10 -> 1.0003708 | G22: =H10/G10 -> 1 | H22: =I10/H10 -> 1
A23: 2005-1 | B23: =C11/B11 -> 1.1540084 | C23: =D11/C11 -> 1.0058501 | D23: =E11/D11 -> 1.0010905 | E23: =F11/E11 -> 1.0003631 | F23: =G11/F11 -> 1 | G23: =H11/G11 -> 1.000363
A24: 2005-2 | B24: =C12/B12 -> 1.32706 | C24: =D12/C12 -> 1.0080491 | D24: =E12/D12 -> 1.0015209 | E24: =F12/E12 -> 1 | F24: =G12/F12 -> 1
A25: 2006-1 | B25: =C13/B13 -> 1.1813357 | C25: =D13/C13 -> 1.008611 | D25: =E13/D13 -> 1.0007424 | E25: =F13/E13 -> 1.0003709
A26: 2006-2 | B26: =C14/B14 -> 1.3530015 | C26: =D14/C14 -> 1.0083428 | D26: =E14/D14 -> 1.0011282
A27: 2007-1 | B27: =C15/B15 -> 1.212239 | C27: =D15/C15 -> 1.0096154
A28: 2007-2 | B28: =C16/B16 -> 1.3115699
A30: Simple
A31: L5 | B31: =AVERAGE(B24:B28) -> 1.2770412 | C31: =AVERAGE(C23:C27) -> 1.0080937 | D31: =AVERAGE(D22:D26) -> 1.0010448 | E31: =AVERAGE(E21:E25) -> 1.0002085 | F31: =AVERAGE(F20:F24) -> 1.0000742 | G31: =AVERAGE(G20:G23) -> 1.0000907 | H31: =AVERAGE(H20:H22) -> 1 | I31: =AVERAGE(I20:I21) -> 0.99984582 | J31: =AVERAGE(J20) -> 1
A32: L3 | B32: =AVERAGE(B26:B28) -> 1.2922701 | C32: =AVERAGE(C25:C27) -> 1.0088564 | D32: =AVERAGE(D24:D26) -> 1.0011305 | E32: =AVERAGE(E23:E25) -> 1.0002447 | F32: =AVERAGE(F22:F24) -> 1.0001236 | G32: =AVERAGE(G21:G23) -> 1.000121 | H32: =AVERAGE(H20:H22) -> 1 | I32: =I31 -> 0.99984582 | J32: =J31 -> 1
A33: L2 | B33: =AVERAGE(B27:B28) -> 1.2619044 | C33: =AVERAGE(C26:C27) -> 1.0089791 | D33: =AVERAGE(D25:D26) -> 1.0009353 | E33: =AVERAGE(E24:E25) -> 1.0001855 | F33: =AVERAGE(F23:F24) -> 1 | G33: =AVERAGE(G22:G23) -> 1.0001815 | H33: =AVERAGE(H21:H22) -> 1 | I33: =AVERAGE(I20:I21) -> 0.99984582 | J33: =J31 -> 1
A35: Medial
A36: L5x1 | B36: =(1/3)*(SUM(B24:B28)-MIN(B24:B28)-MAX(B24:B28)) -> 1.2836229 | C36: =(1/3)*(SUM(C23:C27)-MIN(C23:C27)-MAX(C23:C27)) -> 1.0083343 | D36: =(1/3)*(SUM(D22:D26)-MIN(D22:D26)-MAX(D22:D26)) -> 1.000987 | E36: =(1/3)*(SUM(E21:E25)-MIN(E21:E25)-MAX(E21:E25)) -> 1.0002239 | F36: =(1/3)*(SUM(F20:F24)-MIN(F20:F24)-MAX(F20:F24)) -> 1 | G36: =(1/2)*(SUM(G20:G23)-MIN(G20:G23)-MAX(G20:G23)) -> 1 | H36: =(1/1)*(SUM(H20:H22)-MIN(H20:H22)-MAX(H20:H22)) -> 1 | I36: =I31 -> 0.99984582 | J36: =J31 -> 1
A38: Vol Wtd
A39: L5 | B39: =SUM(C12:C16)/SUM(B12:B16) -> 1.2739872 | C39: =SUM(D11:D15)/SUM(C11:C15) -> 1.0080621 | D39: =SUM(E10:E14)/SUM(D10:D14) -> 1.0010425 | E39: =SUM(F9:F13)/SUM(E9:E13) -> 1.0002139 | F39: =SUM(G9:G13)/SUM(F9:F13) -> 0.80778554 | G39: =SUM(H8:H11)/SUM(G8:G11) -> 1.0000834 | H39: =SUM(I8:I10)/SUM(H8:H10) -> 1 | I39: =SUM(J8:J9)/SUM(I8:I9) -> 0.99984698 | J39: =SUM(K8)/SUM(J8) -> 1
A40: L3 | B40: =SUM(C14:C16)/SUM(B14:B16) -> 1.2912494 | C40: =SUM(D13:D15)/SUM(C13:C15) -> 1.0088416 | D40: =SUM(E12:E14)/SUM(D12:D14) -> 1.0011274 | E40: =SUM(F11:F13)/SUM(E11:E13) -> 1.0002474 | F40: =SUM(G10:G12)/SUM(F10:F12) -> 1.0001237 | G40: =SUM(H9:H11)/SUM(G9:G11) -> 1.000115 | H40: =SUM(I8:I10)/SUM(H8:H10) -> 1 | I40: =SUM(J8:J9)/SUM(I8:I9) -> 0.99984698 | J40: =SUM(K8)/SUM(J8) -> 1
A42: Geo
A43: L4 | B43: =PRODUCT(B25:B28)^0.25 -> 1.2625914 | C43: =PRODUCT(C24:C27)^0.25 -> 1.0086544 | D43: =PRODUCT(D23:D26)^0.25 -> 1.0011205 | E43: =PRODUCT(E22:E25)^0.25 -> 1.0001835 | F43: =PRODUCT(F21:F24)^0.25 -> 1.0000927 | G43: =PRODUCT(G20:G23)^0.25 -> 1.0000907 | H43: =PRODUCT(H20:H22)^(1/3) -> 1 | I43: =PRODUCT(I20:I21)^(1/2) -> 0.99984581 | J43: =PRODUCT(J20)^(1/1) -> 1
B45: =B19 -> 6-12 | C45: =C19 -> 12-18 | D45: =D19 -> 18-24 | E45: =E19 -> 24-30 | F45: =F19 -> 30-36 | G45: =G19 -> 36-42 | H45: =H19 -> 42-48 | I45: =I19 -> 48-54 | ... K45: =K19 -> 60-Ult
A46: Prior
A47: Sel | B47: =AVERAGE(B27,B25,B23) -> 1.1825277 | C47: =C32 -> 1.0088564 | D47: =D32 -> 1.0011305 | E47: =E32 -> 1.0002447 | F47: =F32 -> 1.0001236 | G47: =G32 -> 1.000121 | H47: =H32 -> 1 | I47: =I32 -> 0.99984582 | J47: =J32 -> 1 | K47: 1
A48: CDF to Ult | B48: =C48*B47 -> 1.1947495 | C48: =D48*C47 -> 1.0103354 | D48: =E48*D47 -> 1.001466 | E48: =F48*E47 -> 1.0003351 | F48: =G48*F47 -> 1.0000904 | G48: =H48*G47 -> 0.9999668 | H48: =I48*H47 -> 0.99984582 | I48: =J48*I47 -> 0.99984582 | J48: =K48*J47 -> 1 | K48: =K47 -> 1
...

Sheet Reported Counts
A1: Auto Collision Insurer
A2: Exhibit I (Sheet 2) p.216
A3: Reported Claim Counts
A5: PART 1 - Data Triangle
A7: AY | B7: 6 | C7: =B7+6 -> 12 | D7: =C7+6 -> 18 | E7: =D7+6 -> 24 | F7: =E7+6 -> 30 | G7: =F7+6 -> 36 | H7: =G7+6 -> 42 | I7: =H7+6 -> 48 | J7: =I7+6 -> 54 | K7: =J7+6 -> 60
A8: 2003-2 | B8: 3556 | C8: 3314 | D8: 3301 | E8: 3299 | F8: 3295 | G8: 3294 | H8: 3293 | I8: 3293 | J8: 3293 | K8: 3292
A9: 2004-1 | B9: 3492 | C9: 3262 | D9: 3250 | E9: 3247 | F9: 3247 | G9: 3245 | H9: 3245 | I9: 3244 | J9: 3243
A10: 2004-2 | B10: 2980 | C10: 2712 | D10: 2704 | E10: 2702 | F10: 2700 | G10: 2700 | H10: 2699 | I10: 2699
A11: 2005-1 | B11: 2896 | C11: 2768 | D11: 2761 | E11: 2758 | F11: 2758 | G11: 2758 | H11: 2757
A12: 2005-2 | B12: 2814 | C12: 2650 | D12: 2640 | E12: 2639 | F12: 2638 | G12: 2636
A13: 2006-1 | B13: 2808 | C13: 2712 | D13: 2704 | E13: 2701 | F13: 2700
A14: 2006-2 | B14: 2799 | C14: 2675 | D14: 2670 | E14: 2668
A15: 2007-1 | B15: 2578 | C15: 2533 | D15: 2529
A16: 2007-2 | B16: 2791 | C16: 2778
A17: 2008-1 | B17: 3139
A19: AY | B19: =B7&"-"&C7 -> 6-12 | C19: =C7&"-"&D7 -> 12-18 | D19: =D7&"-"&E7 -> 18-24 | E19: =E7&"-"&F7 -> 24-30 | F19: =F7&"-"&G7 -> 30-36 | G19: =G7&"-"&H7 -> 36-42 | H19: =H7&"-"&I7 -> 42-48 | I19: =I7&"-"&J7 -> 48-54 | J19: =J7&"-"&K7 -> 54-60 | K19: 60-Ult
A20: 2003-2 | B20: =C8/B8 -> 0.93194601 | C20: =D8/C8 -> 0.99607725 | D20: =E8/D8 -> 0.99939412 | E20: =F8/E8 -> 0.99878751 | F20: =G8/F8 -> 0.99969651 | G20: =H8/G8 -> 0.99969642 | H20: =I8/H8 -> 1 | I20: =J8/I8 -> 1 | J20: =K8/J8 -> 0.99969633
A21: 2004-1 | B21: =C9/B9 -> 0.93413517 | C21: =D9/C9 -> 0.99632128 | D21: =E9/D9 -> 0.99907692 | E21: =F9/E9 -> 1 | F21: =G9/F9 -> 0.99938405 | G21: =H9/G9 -> 1 | H21: =I9/H9 -> 0.99969183 | I21: =J9/I9 -> 0.99969174
A22: 2004-2 | B22: =C10/B10 -> 0.91006711 | C22: =D10/C10 -> 0.99705015 | D22: =E10/D10 -> 0.99926036 | E22: =F10/E10 -> 0.99925981 | F22: =G10/F10 -> 1 | G22: =H10/G10 -> 0.99962963 | H22: =I10/H10 -> 1
A23: 2005-1 | B23: =C11/B11 -> 0.9558011 | C23: =D11/C11 -> 0.9974711 | D23: =E11/D11 -> 0.99891344 | E23: =F11/E11 -> 1 | F23: =G11/F11 -> 1 | G23: =H11/G11 -> 0.99963742
A24: 2005-2 | B24: =C12/B12 -> 0.94171997 | C24: =D12/C12 -> 0.99622642 | D24: =E12/D12 -> 0.99962121 | E24: =F12/E12 -> 0.99962107 | F24: =G12/F12 -> 0.99924185
A25: 2006-1 | B25: =C13/B13 -> 0.96581197 | C25: =D13/C13 -> 0.99705015 | D25: =E13/D13 -> 0.99889053 | E25: =F13/E13 -> 0.99962977
A26: 2006-2 | B26: =C14/B14 -> 0.95569846 | C26: =D14/C14 -> 0.99813084 | D26: =E14/D14 -> 0.99925094
A27: 2007-1 | B27: =C15/B15 -> 0.98254461 | C27: =D15/C15 -> 0.99842084
A28: 2007-2 | B28: =C16/B16 -> 0.99534217
A30: Simple
A31: L5 | B31: =AVERAGE(B24:B28) -> 0.96822344 | C31: =AVERAGE(C23:C27) -> 0.99745987 | D31: =AVERAGE(D22:D26) -> 0.99918729 | E31: =AVERAGE(E21:E25) -> 0.99970213 | F31: =AVERAGE(F20:F24) -> 0.99966448 | G31: =AVERAGE(G20:G23) -> 0.99974087 | H31: =AVERAGE(H20:H22) -> 0.99989728 | I31: =AVERAGE(I20:I21) -> 0.99984587 | J31: =AVERAGE(J20) -> 0.99969633
A32: L3 | B32: =AVERAGE(B26:B28) -> 0.97786175 | C32: =AVERAGE(C25:C27) -> 0.99786728 | D32: =AVERAGE(D24:D26) -> 0.99925423 | E32: =AVERAGE(E23:E25) -> 0.99975028 | F32: =AVERAGE(F22:F24) -> 0.99974728 | G32: =AVERAGE(G21:G23) -> 0.99975568 | H32: =AVERAGE(H20:H22) -> 0.99989728 | I32: =I31 -> 0.99984587 | J32: =J31 -> 0.99969633
A33: L2 | B33: =AVERAGE(B27:B28) -> 0.98894339 | C33: =AVERAGE(C26:C27) -> 0.99827584 | D33: =AVERAGE(D25:D26) -> 0.99907073 | E33: =AVERAGE(E24:E25) -> 0.99962542 | F33: =AVERAGE(F23:F24) -> 0.99962092 | G33: =AVERAGE(G22:G23) -> 0.99963352 | H33: =AVERAGE(H21:H22) -> 0.99984592 | I33: =AVERAGE(I20:I21) -> 0.99984587 | J33: =J31 -> 0.99969633
A35: Medial
A36: L5x1 | B36: =(1/3)*(SUM(B24:B28)-MIN(B24:B28)-MAX(B24:B28)) -> 0.96801835 | C36: =(1/3)*(SUM(C23:C27)-MIN(C23:C27)-MAX(C23:C27)) -> 0.9975507 | D36: =(1/3)*(SUM(D22:D26)-MIN(D22:D26)-MAX(D22:D26)) -> 0.99914158 | E36: =(1/3)*(SUM(E21:E25)-MIN(E21:E25)-MAX(E21:E25)) -> 0.99975028 | F36: =(1/3)*(SUM(F20:F24)-MIN(F20:F24)-MAX(F20:F24)) -> 0.99969352 | G36: =(1/2)*(SUM(G20:G23)-MIN(G20:G23)-MAX(G20:G23)) -> 0.99966692 | H36: =(1/1)*(SUM(H20:H22)-MIN(H20:H22)-MAX(H20:H22)) -> 1 | I36: =I31 -> 0.99984587 | J36: =J31 -> 0.99969633
A38: Vol Wtd
A39: L5 | B39: =SUM(C12:C16)/SUM(B12:B16) -> 0.96794779 | C39: =SUM(D11:D15)/SUM(C11:C15) -> 0.99745089 | D39: =SUM(E10:E14)/SUM(D10:D14) -> 0.99918392 | E39: =SUM(F9:F13)/SUM(E9:E13) -> 0.99971524 | F39: =SUM(G9:G13)/SUM(F9:F13) -> 0.80744855 | G39: =SUM(H8:H11)/SUM(G8:G11) -> 0.99974994 | H39: =SUM(I8:I10)/SUM(H8:H10) -> 0.99989174 | I39: =SUM(J8:J9)/SUM(I8:I9) -> 0.99984702 | J39: =SUM(K8)/SUM(J8) -> 0.99969633
A40: L3 | B40: =SUM(C14:C16)/SUM(B14:B16) -> 0.97771792 | C40: =SUM(D13:D15)/SUM(C13:C15) -> 0.99785354 | D40: =SUM(E12:E14)/SUM(D12:D14) -> 0.99925131 | E40: =SUM(F11:F13)/SUM(E11:E13) -> 0.99975303 | F40: =SUM(G10:G12)/SUM(F10:F12) -> 0.99975296 | G40: =SUM(H9:H11)/SUM(G9:G11) -> 0.99977019 | H40: =SUM(I8:I10)/SUM(H8:H10) -> 0.99989174 | I40: =SUM(J8:J9)/SUM(I8:I9) -> 0.99984702 | J40: =SUM(K8)/SUM(J8) -> 0.99969633
A42: Geo
A43: L4 | B43: =PRODUCT(B25:B28)^0.25 -> 0.97473046 | C43: =PRODUCT(C24:C27)^0.25 -> 0.99745668 | D43: =PRODUCT(D23:D26)^0.25 -> 0.99916899 | E43: =PRODUCT(E22:E25)^0.25 -> 0.99962763 | F43: =PRODUCT(F21:F24)^0.25 -> 0.99965641 | G43: =PRODUCT(G20:G23)^0.25 -> 0.99974085 | H43: =PRODUCT(H20:H22)^(1/3) -> 0.99989727 | I43: =PRODUCT(I20:I21)^(1/2) -> 0.99984586 | J43: =PRODUCT(J20)^(1/1) -> 0.99969633
B45: =B19 -> 6-12 | C45: =C19 -> 12-18 | D45: =D19 -> 18-24 | E45: =E19 -> 24-30 | F45: =F19 -> 30-36 | G45: =G19 -> 36-42 | H45: =H19 -> 42-48 | I45: =I19 -> 48-54 | ... K45: =K19 -> 60-Ult
A46: Prior
A47: Sel | B47: =B32 -> 0.97786175 | C47: =C32 -> 0.99786728 | D47: =D32 -> 0.99925423 | E47: =E32 -> 0.99975028 | F47: =F32 -> 0.99974728 | G47: =G32 -> 0.99975568 | H47: =H32 -> 0.99989728 | I47: =I32 -> 0.99984587 | J47: =J32 -> 0.99969633 | K47: 1
A48: CDF to Ult | B48: =C48*B47 -> 0.97377455 | C48: =D48*C47 -> 0.99582027 | D48: =E48*D47 -> 0.99794862 | E48: =F48*E47 -> 0.99869342 | F48: =G48*F47 -> 0.99894287 | G48: =H48*G47 -> 0.99919539 | H48: =I48*H47 -> 0.99943957 | I48: =J48*I47 -> 0.99954224 | J48: =K48*J47 -> 0.99969633 | K48: =K47 -> 1
...

Sheet Reported Claims
A1: Auto Collision Insurer
A2: Exhibit I (Sheet 5) p.219
A3: Reported Claims
A5: PART 1 - Data Triangle
A7: AY | B7: 6 | C7: =B7+6 -> 12 | D7: =C7+6 -> 18 | E7: =D7+6 -> 24 | F7: =E7+6 -> 30 | G7: =F7+6 -> 36 | H7: =G7+6 -> 42 | I7: =H7+6 -> 48 | J7: =I7+6 -> 54 | K7: =J7+6 -> 60
A8: 2003-2 | B8: 14235000 | C8: 14960000 | D8: 14921000 | E8: 14911000 | F8: 14926000 | G8: 14864000 | H8: 14860000 | I8: 14854000 | J8: 14850000 | K8: 14847000
A9: 2004-1 | B9: 14548000 | C9: 14674000 | D9: 14643000 | E9: 14626000 | F9: 14621000 | G9: 14610000 | H9: 14610000 | I9: 14611000 | J9: 14617000
A10: 2004-2 | B10: 12129000 | C10: 12576000 | D10: 12541000 | E10: 12531000 | F10: 12523000 | G10: 12523000 | H10: 12510000 | I10: 12502000
A11: 2005-1 | B11: 11980000 | C11: 11921000 | D11: 11882000 | E11: 11862000 | F11: 11854000 | G11: 11844000 | H11: 11841000
A12: 2005-2 | B12: 11283000 | C12: 11843000 | D12: 11805000 | E12: 11789000 | F12: 11772000 | G12: 11770000
A13: 2006-1 | B13: 11947000 | C13: 11856000 | D13: 11820000 | E13: 11772000 | F13: 11760000
A14: 2006-2 | B14: 12503000 | C14: 12762000 | D14: 12706000 | E14: 12697000
A15: 2007-1 | B15: 11662000 | C15: 11523000 | D15: 11492000
A16: 2007-2 | B16: 12647000 | C16: 12854000
A17: 2008-1 | B17: 14071000
A19: AY | B19: 6-12 | C19: 12-18 | D19: 18-24 | E19: 24-30 | F19: 30-36 | G19: 36-42 | H19: 42-48 | I19: 48-54 | J19: 54-60 | K19: 60-Ult
A20: 2003-2 | B20: =C8/B8 -> 1.0509308 | C20: =D8/C8 -> 0.99739305 | D20: =E8/D8 -> 0.9993298 | E20: =F8/E8 -> 1.001006 | F20: =G8/F8 -> 0.99584617 | G20: =H8/G8 -> 0.99973089 | H20: =I8/H8 -> 0.99959623 | I20: =J8/I8 -> 0.99973071 | J20: =K8/J8 -> 0.99979798
A21: 2004-1 | B21: =C9/B9 -> 1.008661 | C21: =D9/C9 -> 0.99788742 | D21: =E9/D9 -> 0.99883904 | E21: =F9/E9 -> 0.99965814 | F21: =G9/F9 -> 0.99924766 | G21: =H9/G9 -> 1 | H21: =I9/H9 -> 1.0000684 | I21: =J9/I9 -> 1.0004106
A22: 2004-2 | B22: =C10/B10 -> 1.0368538 | C22: =D10/C10 -> 0.99721692 | D22: =E10/D10 -> 0.99920262 | E22: =F10/E10 -> 0.99936158 | F22: =G10/F10 -> 1 | G22: =H10/G10 -> 0.99896191 | H22: =I10/H10 -> 0.99936051
A23: 2005-1 | B23: =C11/B11 -> 0.99507513 | C23: =D11/C11 -> 0.99672846 | D23: =E11/D11 -> 0.99831678 | E23: =F11/E11 -> 0.99932558 | F23: =G11/F11 -> 0.9991564 | G23: =H11/G11 -> 0.99974671
A24: 2005-2 | B24: =C12/B12 -> 1.0496322 | C24: =D12/C12 -> 0.99679135 | D24: =E12/D12 -> 0.99864464 | E24: =F12/E12 -> 0.99855798 | F24: =G12/F12 -> 0.99983011
A25: 2006-1 | B25: =C13/B13 -> 0.99238303 | C25: =D13/C13 -> 0.99696356 | D25: =E13/D13 -> 0.99593909 | E25: =F13/E13 -> 0.99898063
A26: 2006-2 | B26: =C14/B14 -> 1.020715 | C26: =D14/C14 -> 0.99561197 | D26: =E14/D14 -> 0.99929167
A27: 2007-1 | B27: =C15/B15 -> 0.98808095 | C27: =D15/C15 -> 0.99730973
A28: 2007-2 | B28: =C16/B16 -> 1.0163675
A30: Simple
A31: L5 | B31: =AVERAGE(B24:B28) -> 1.0134357 | C31: =AVERAGE(C23:C27) -> 0.99668102 | D31: =AVERAGE(D22:D26) -> 0.99827896 | E31: =AVERAGE(E21:E25) -> 0.99917678 | F31: =AVERAGE(F20:F24) -> 0.99881607 | G31: =AVERAGE(G20:G23) -> 0.99960988 | H31: =AVERAGE(H20:H22) -> 0.99967506 | I31: =AVERAGE(I20:I21) -> 1.0000707 | J31: =AVERAGE(J20) -> 0.99979798
A32: L3 | B32: =AVERAGE(B26:B28) -> 1.0083878 | C32: =AVERAGE(C25:C27) -> 0.99662842 | D32: =AVERAGE(D24:D26) -> 0.99795847 | E32: =AVERAGE(E23:E25) -> 0.99895473 | F32: =AVERAGE(F22:F24) -> 0.99966217 | G32: =AVERAGE(G21:G23) -> 0.99956954 | H32: =AVERAGE(H20:H22) -> 0.99967506 | I32: =I31 -> 1.0000707 | J32: =J31 -> 0.99979798
A33: L2 | B33: =AVERAGE(B27:B28) -> 1.0022242 | C33: =AVERAGE(C26:C27) -> 0.99646085 | D33: =AVERAGE(D25:D26) -> 0.99761538 | E33: =AVERAGE(E24:E25) -> 0.9987693 | F33: =AVERAGE(F23:F24) -> 0.99949325 | G33: =AVERAGE(G22:G23) -> 0.99935431 | H33: =AVERAGE(H21:H22) -> 0.99971448 | I33: =AVERAGE(I20:I21) -> 1.0000707 | J33: =J31 -> 0.99979798
A35: Medial
A36: L5x1 | B36: =(1/3)*(SUM(B24:B28)-MIN(B24:B28)-MAX(B24:B28)) -> 1.0098219 | C36: =(1/3)*(SUM(C23:C27)-MIN(C23:C27)-MAX(C23:C27)) -> 0.99682779 | D36: =(1/3)*(SUM(D22:D26)-MIN(D22:D26)-MAX(D22:D26)) -> 0.99872135 | E36: =(1/3)*(SUM(E21:E25)-MIN(E21:E25)-MAX(E21:E25)) -> 0.9992226 | F36: =(1/3)*(SUM(F20:F24)-MIN(F20:F24)-MAX(F20:F24)) -> 0.99941139 | G36: =(1/2)*(SUM(G20:G23)-MIN(G20:G23)-MAX(G20:G23)) -> 0.9997388 | H36: =(1/1)*(SUM(H20:H22)-MIN(H20:H22)-MAX(H20:H22)) -> 0.99959623 | I36: =I31 -> 1.0000707 | J36: =J31 -> 0.99979798
A38: Vol Wtd
A39: L5 | B39: =SUM(C12:C16)/SUM(B12:B16) -> 1.0132574 | C39: =SUM(D11:D15)/SUM(C11:C15) -> 0.99666138 | D39: =SUM(E10:E14)/SUM(D10:D14) -> 0.99830464 | E39: =SUM(F9:F13)/SUM(E9:E13) -> 0.99920102 | F39: =SUM(G9:G13)/SUM(F9:F13) -> 0.81156245 | G39: =SUM(H8:H11)/SUM(G8:G11) -> 0.99962854 | H39: =SUM(I8:I10)/SUM(H8:H10) -> 0.99969033 | I39: =SUM(J8:J9)/SUM(I8:I9) -> 1.0000679 | J39: =SUM(K8)/SUM(J8) -> 0.99979798
A40: L3 | B40: =SUM(C14:C16)/SUM(B14:B16) -> 1.008883 | C40: =SUM(D13:D15)/SUM(C13:C15) -> 0.99659666 | D40: =SUM(E12:E14)/SUM(D12:D14) -> 0.9979907 | E40: =SUM(F11:F13)/SUM(E11:E13) -> 0.99895548 | F40: =SUM(G10:G12)/SUM(F10:F12) -> 0.99966804 | G40: =SUM(H9:H11)/SUM(G9:G11) -> 0.9995895 | H40: =SUM(I8:I10)/SUM(H8:H10) -> 0.99969033 | I40: =SUM(J8:J9)/SUM(I8:I9) -> 1.0000679 | J40: =SUM(K8)/SUM(J8) -> 0.99979798
A42: Geo
A43: L4 | B43: =PRODUCT(B25:B28)^0.25 -> 1.0042846 | C43: =PRODUCT(C24:C27)^0.25 -> 0.99666895 | D43: =PRODUCT(D23:D26)^0.25 -> 0.99804724 | E43: =PRODUCT(E22:E25)^0.25 -> 0.99905639 | F43: =PRODUCT(F21:F24)^0.25 -> 0.99955848 | G43: =PRODUCT(G20:G23)^0.25 -> 0.9996098 | H43: =PRODUCT(H20:H22)^(1/3) -> 0.99967502 | I43: =PRODUCT(I20:I21)^(1/2) -> 1.0000706 | J43: =PRODUCT(J20)^(1/1) -> 0.99979798
B45: =B19 -> 6-12 | C45: =C19 -> 12-18 | D45: =D19 -> 18-24 | E45: =E19 -> 24-30 | F45: =F19 -> 30-36 | G45: =G19 -> 36-42 | H45: =H19 -> 42-48 | I45: =I19 -> 48-54 | ... K45: =K19 -> 60-Ult
A46: Prior
A47: Sel | B47: =B32 -> 1.0083878 | C47: =C32 -> 0.99662842 | D47: =D32 -> 0.99795847 | E47: =E32 -> 0.99895473 | F47: =F32 -> 0.99966217 | G47: =G32 -> 0.99956954 | H47: =H32 -> 0.99967506 | I47: =I32 -> 1.0000707 | J47: =J32 -> 0.99979798 | K47: 1
A48: CDF to Ult | B48: =C48*B47 -> 1.0006616 | C48: =D48*C47 -> 0.992338 | D48: =E48*D47 -> 0.99569506 | E48: =F48*E47 -> 0.99773197 | F48: =G48*F47 -> 0.99877596 | G48: =H48*G47 -> 0.99911349 | H48: =I48*H47 -> 0.99954375 | I48: =J48*I47 -> 0.99986865 | J48: =K48*J47 -> 0.99979798 | K48: =K47 -> 1
...

Sheet Reported Severity
A1: Auto Collision Insurer
A2: Exhibit I (Sheet 6) p.220
A3: Reported Severity
A5: PART 1 - Data Triangle
A7: AY | B7: 6 | C7: =B7+6 -> 12 | D7: =C7+6 -> 18 | E7: =D7+6 -> 24 | F7: =E7+6 -> 30 | G7: =F7+6 -> 36 | H7: =G7+6 -> 42 | I7: =H7+6 -> 48 | J7: =I7+6 -> 54 | K7: =J7+6 -> 60
A8: 2003-2 | B8: ='Reported Claims'!B8/'Reported Counts'!B8 -> 4003.0934 | C8: ='Reported Claims'!C8/'Reported Counts'!C8 -> 4514.1823 | D8: ='Reported Claims'!D8/'Reported Counts'!D8 -> 4520.1454 | E8: ='Reported Claims'!E8/'Reported Counts'!E8 -> 4519.8545 | F8: ='Reported Claims'!F8/'Reported Counts'!F8 -> 4529.8938 | G8: ='Reported Claims'!G8/'Reported Counts'!G8 -> 4512.4469 | H8: ='Reported Claims'!H8/'Reported Counts'!H8 -> 4512.6025 | I8: ='Reported Claims'!I8/'Reported Counts'!I8 -> 4510.7804 | ... K8: ='Reported Claims'!K8/'Reported Counts'!K8 -> 4510.0243
A9: 2004-1 | B9: ='Reported Claims'!B9/'Reported Counts'!B9 -> 4166.0939 | C9: ='Reported Claims'!C9/'Reported Counts'!C9 -> 4498.4672 | D9: ='Reported Claims'!D9/'Reported Counts'!D9 -> 4505.5385 | E9: ='Reported Claims'!E9/'Reported Counts'!E9 -> 4504.4657 | F9: ='Reported Claims'!F9/'Reported Counts'!F9 -> 4502.9258 | G9: ='Reported Claims'!G9/'Reported Counts'!G9 -> 4502.3112 | H9: ='Reported Claims'!H9/'Reported Counts'!H9 -> 4502.3112 | I9: ='Reported Claims'!I9/'Reported Counts'!I9 -> 4504.0074 | J9: ='Reported Claims'!J9/'Reported Counts'!J9 -> 4507.2464
A10: 2004-2 | B10: ='Reported Claims'!B10/'Reported Counts'!B10 -> 4070.1342 | C10: ='Reported Claims'!C10/'Reported Counts'!C10 -> 4637.1681 | D10: ='Reported Claims'!D10/'Reported Counts'!D10 -> 4637.9438 | E10: ='Reported Claims'!E10/'Reported Counts'!E10 -> 4637.6758 | F10: ='Reported Claims'!F10/'Reported Counts'!F10 -> 4638.1481 | G10: ='Reported Claims'!G10/'Reported Counts'!G10 -> 4638.1481 | H10: ='Reported Claims'!H10/'Reported Counts'!H10 -> 4635.05 | I10: ='Reported Claims'!I10/'Reported Counts'!I10 -> 4632.086
A11: 2005-1 | B11: ='Reported Claims'!B11/'Reported Counts'!B11 -> 4136.7403 | C11: ='Reported Claims'!C11/'Reported Counts'!C11 -> 4306.7197 | D11: ='Reported Claims'!D11/'Reported Counts'!D11 -> 4303.5132 | E11: ='Reported Claims'!E11/'Reported Counts'!E11 -> 4300.9427 | F11: ='Reported Claims'!F11/'Reported Counts'!F11 -> 4298.0421 | G11: ='Reported Claims'!G11/'Reported Counts'!G11 -> 4294.4162 | H11: ='Reported Claims'!H11/'Reported Counts'!H11 -> 4294.8857
A12: 2005-2 | B12: ='Reported Claims'!B12/'Reported Counts'!B12 -> 4009.5949 | C12: ='Reported Claims'!C12/'Reported Counts'!C12 -> 4469.0566 | D12: ='Reported Claims'!D12/'Reported Counts'!D12 -> 4471.5909 | E12: ='Reported Claims'!E12/'Reported Counts'!E12 -> 4467.2224 | F12: ='Reported Claims'!F12/'Reported Counts'!F12 -> 4462.4716 | G12: ='Reported Claims'!G12/'Reported Counts'!G12 -> 4465.0986
A13: 2006-1 | B13: ='Reported Claims'!B13/'Reported Counts'!B13 -> 4254.6296 | C13: ='Reported Claims'!C13/'Reported Counts'!C13 -> 4371.6814 | D13: ='Reported Claims'!D13/'Reported Counts'!D13 -> 4371.3018 | E13: ='Reported Claims'!E13/'Reported Counts'!E13 -> 4358.3858 | F13: ='Reported Claims'!F13/'Reported Counts'!F13 -> 4355.5556
A14: 2006-2 | B14: ='Reported Claims'!B14/'Reported Counts'!B14 -> 4466.9525 | C14: ='Reported Claims'!C14/'Reported Counts'!C14 -> 4770.8411 | D14: ='Reported Claims'!D14/'Reported Counts'!D14 -> 4758.8015 | E14: ='Reported Claims'!E14/'Reported Counts'!E14 -> 4758.9955
A15: 2007-1 | B15: ='Reported Claims'!B15/'Reported Counts'!B15 -> 4523.6618 | C15: ='Reported Claims'!C15/'Reported Counts'!C15 -> 4549.1512 | D15: ='Reported Claims'!D15/'Reported Counts'!D15 -> 4544.0886
A16: 2007-2 | B16: ='Reported Claims'!B16/'Reported Counts'!B16 -> 4531.3508 | C16: ='Reported Claims'!C16/'Reported Counts'!C16 -> 4627.0698
A17: 2008-1 | B17: ='Reported Claims'!B17/'Reported Counts'!B17 -> 4482.6378
A19: AY | B19: 6-12 | C19: 12-18 | D19: 18-24 | E19: 24-30 | F19: 30-36 | G19: 36-42 | H19: 42-48 | I19: 48-54 | J19: 54-60 | K19: 60-Ult
A20: 2003-2 | B20: =C8/B8 -> 1.1276735 | C20: =D8/C8 -> 1.001321 | D20: =E8/D8 -> 0.99993564 | E20: =F8/E8 -> 1.0022212 | F20: =G8/F8 -> 0.9961485 | G20: =H8/G8 -> 1.0000345 | H20: =I8/H8 -> 0.99959623 | I20: =J8/I8 -> 0.99973071 | J20: =K8/J8 -> 1.0001017
A21: 2004-1 | B21: =C9/B9 -> 1.0797806 | C21: =D9/C9 -> 1.0015719 | D21: =E9/D9 -> 0.99976189 | E21: =F9/E9 -> 0.99965814 | F21: =G9/F9 -> 0.99986353 | G21: =H9/G9 -> 1 | H21: =I9/H9 -> 1.0003767 | I21: =J9/I9 -> 1.0007191
A22: 2004-2 | B22: =C10/B10 -> 1.1393158 | C22: =D10/C10 -> 1.0001673 | D22: =E10/D10 -> 0.99994222 | E22: =F10/E10 -> 1.0001019 | F22: =G10/F10 -> 1 | G22: =H10/G10 -> 0.99933203 | H22: =I10/H10 -> 0.99936051
A23: 2005-1 | B23: =C11/B11 -> 1.0410902 | C23: =D11/C11 -> 0.99925548 | D23: =E11/D11 -> 0.9994027 | E23: =F11/E11 -> 0.99932558 | F23: =G11/F11 -> 0.9991564 | G23: =H11/G11 -> 1.0001093
A24: 2005-2 | B24: =C12/B12 -> 1.1145906 | C24: =D12/C12 -> 1.0005671 | D24: =E12/D12 -> 0.99902306 | E24: =F12/E12 -> 0.99893651 | F24: =G12/F12 -> 1.0005887
A25: 2006-1 | B25: =C13/B13 -> 1.0275116 | C25: =D13/C13 -> 0.99991316 | D25: =E13/D13 -> 0.99704528 | E25: =F13/E13 -> 0.99935062
A26: 2006-2 | B26: =C14/B14 -> 1.0680304 | C26: =D14/C14 -> 0.99747641 | D26: =E14/D14 -> 1.0000408
A27: 2007-1 | B27: =C15/B15 -> 1.0056347 | C27: =D15/C15 -> 0.99888713
A28: 2007-2 | B28: =C16/B16 -> 1.0211237
A30: Simple
A31: L5 | B31: =AVERAGE(B24:B28) -> 1.0473782 | C31: =AVERAGE(C23:C27) -> 0.99921985 | D31: =AVERAGE(D22:D26) -> 0.9990908 | E31: =AVERAGE(E21:E25) -> 0.99947454 | F31: =AVERAGE(F20:F24) -> 0.99915143 | G31: =AVERAGE(G20:G23) -> 0.99986896 | H31: =AVERAGE(H20:H22) -> 0.99977782 | I31: =AVERAGE(I20:I21) -> 1.0002249 | J31: =AVERAGE(J20) -> 1.0001017
A32: L3 | B32: =AVERAGE(B26:B28) -> 1.0315963 | C32: =AVERAGE(C25:C27) -> 0.9987589 | D32: =AVERAGE(D24:D26) -> 0.99870303 | E32: =AVERAGE(E23:E25) -> 0.99920424 | F32: =AVERAGE(F22:F24) -> 0.99991503 | G32: =AVERAGE(G21:G23) -> 0.99981379 | H32: =AVERAGE(H20:H22) -> 0.99977782 | I32: =I31 -> 1.0002249 | J32: =J31 -> 1.0001017
A33: L2 | B33: =AVERAGE(B27:B28) -> 1.0133792 | C33: =AVERAGE(C26:C27) -> 0.99818177 | D33: =AVERAGE(D25:D26) -> 0.99854302 | E33: =AVERAGE(E24:E25) -> 0.99914357 | F33: =AVERAGE(F23:F24) -> 0.99987255 | G33: =AVERAGE(G22:G23) -> 0.99972068 | H33: =AVERAGE(H21:H22) -> 0.99986862 | I33: =AVERAGE(I20:I21) -> 1.0002249 | J33: =J31 -> 1.0001017
A35: Medial
A36: L5x1 | B36: =(1/3)*(SUM(B24:B28)-MIN(B24:B28)-MAX(B24:B28)) -> 1.0388886 | C36: =(1/3)*(SUM(C23:C27)-MIN(C23:C27)-MAX(C23:C27)) -> 0.99935192 | D36: =(1/3)*(SUM(D22:D26)-MIN(D22:D26)-MAX(D22:D26)) -> 0.99945599 | E36: =(1/3)*(SUM(E21:E25)-MIN(E21:E25)-MAX(E21:E25)) -> 0.99944478 | F36: =(1/3)*(SUM(F20:F24)-MIN(F20:F24)-MAX(F20:F24)) -> 0.99967331 | G36: =(1/2)*(SUM(G20:G23)-MIN(G20:G23)-MAX(G20:G23)) -> 1.0000172 | H36: =(1/1)*(SUM(H20:H22)-MIN(H20:H22)-MAX(H20:H22)) -> 0.99959623 | I36: =I31 -> 1.0002249 | J36: =J31 -> 1.0001017
A38: Vol Wtd
A39: L5 | B39: =SUM(C12:C16)/SUM(B12:B16) -> 1.0459746 | C39: =SUM(D11:D15)/SUM(C11:C15) -> 0.99919199 | D39: =SUM(E10:E14)/SUM(D10:D14) -> 0.99911596 | E39: =SUM(F9:F13)/SUM(E9:E13) -> 0.99948137 | F39: =SUM(G9:G13)/SUM(F9:F13) -> 0.80423504 | G39: =SUM(H8:H11)/SUM(G8:G11) -> 0.99986221 | H39: =SUM(I8:I10)/SUM(H8:H10) -> 0.99977363 | I39: =SUM(J8:J9)/SUM(I8:I9) -> 1.0002246 | J39: =SUM(K8)/SUM(J8) -> 1.0001017
A40: L3 | B40: =SUM(C14:C16)/SUM(B14:B16) -> 1.0314375 | C40: =SUM(D13:D15)/SUM(C13:C15) -> 0.99872317 | D40: =SUM(E12:E14)/SUM(D12:D14) -> 0.9987435 | E40: =SUM(F11:F13)/SUM(E11:E13) -> 0.99920149 | F40: =SUM(G10:G12)/SUM(F10:F12) -> 0.99992546 | G40: =SUM(H9:H11)/SUM(G9:G11) -> 0.99980434 | H40: =SUM(I8:I10)/SUM(H8:H10) -> 0.99977363 | I40: =SUM(J8:J9)/SUM(I8:I9) -> 1.0002246 | J40: =SUM(K8)/SUM(J8) -> 1.0001017
A42: Geo
A43: L4 | B43: =PRODUCT(B25:B28)^0.25 -> 1.0303203 | C43: =PRODUCT(C24:C27)^0.25 -> 0.99921026 | D43: =PRODUCT(D23:D26)^0.25 -> 0.99887732 | E43: =PRODUCT(E22:E25)^0.25 -> 0.99942855 | F43: =PRODUCT(F21:F24)^0.25 -> 0.99990203 | G43: =PRODUCT(G20:G23)^0.25 -> 0.99986891 | H43: =PRODUCT(H20:H22)^(1/3) -> 0.99977773 | I43: =PRODUCT(I20:I21)^(1/2) -> 1.0002248 | J43: =PRODUCT(J20)^(1/1) -> 1.0001017
B45: =B19 -> 6-12 | C45: =C19 -> 12-18 | D45: =D19 -> 18-24 | E45: =E19 -> 24-30 | F45: =F19 -> 30-36 | G45: =G19 -> 36-42 | H45: =H19 -> 42-48 | I45: =I19 -> 48-54 | ... K45: =K19 -> 60-Ult
A46: Prior
A47: Sel | B47: =B36 -> 1.0388886 | C47: =C32 -> 0.9987589 | D47: =D32 -> 0.99870303 | E47: =E32 -> 0.99920424 | F47: =F32 -> 0.99991503 | G47: =G32 -> 0.99981379 | H47: =H32 -> 0.99977782 | I47: =I32 -> 1.0002249 | J47: =J32 -> 1.0001017 | K47: 1
A48: CDF to Ult | B48: =C48*B47 -> 1.0352562 | C48: =D48*C47 -> 0.99650355 | D48: =E48*D47 -> 0.99774184 | E48: =F48*E47 -> 0.99903756 | F48: =G48*F47 -> 0.99983319 | G48: =H48*G47 -> 0.99991815 | H48: =I48*H47 -> 1.0001044 | I48: =J48*I47 -> 1.0003266 | J48: =K48*J47 -> 1.0001017 | K48: =K47 -> 1
...

Sheet Diagnostics
A1: Auto Collision Insurer
A2: Exhibit I (Sheet 4) p.218
A3: Closed to Reported Claim Counts
A5: PART 1 - Data Triangle
A7: AY | B7: 6 | C7: =B7+6 -> 12 | D7: =C7+6 -> 18 | E7: =D7+6 -> 24 | F7: =E7+6 -> 30 | G7: =F7+6 -> 36 | H7: =G7+6 -> 42 | I7: =H7+6 -> 48 | J7: =I7+6 -> 54 | K7: =J7+6 -> 60
A8: 2003-2 | B8: ='Closed Counts'!B8/'Reported Counts'!B8 -> 0.71625422 | C8: ='Closed Counts'!C8/'Reported Counts'!C8 -> 0.98430899 | D8: ='Closed Counts'!D8/'Reported Counts'!D8 -> 0.99575886 | E8: ='Closed Counts'!E8/'Reported Counts'!E8 -> 0.99757502 | F8: ='Closed Counts'!F8/'Reported Counts'!F8 -> 0.99908953 | G8: ='Closed Counts'!G8/'Reported Counts'!G8 -> 0.99939284 | H8: ='Closed Counts'!H8/'Reported Counts'!H8 -> 0.99969633 | I8: ='Closed Counts'!I8/'Reported Counts'!I8 -> 0.99969633 | ... K8: ='Closed Counts'!K8/'Reported Counts'!K8 -> 1
A9: 2004-1 | B9: ='Closed Counts'!B9/'Reported Counts'!B9 -> 0.79925544 | C9: ='Closed Counts'!C9/'Reported Counts'!C9 -> 0.98620478 | D9: ='Closed Counts'!D9/'Reported Counts'!D9 -> 0.99692308 | E9: ='Closed Counts'!E9/'Reported Counts'!E9 -> 0.99846012 | F9: ='Closed Counts'!F9/'Reported Counts'!F9 -> 0.99876809 | G9: ='Closed Counts'!G9/'Reported Counts'!G9 -> 0.99938367 | H9: ='Closed Counts'!H9/'Reported Counts'!H9 -> 0.99938367 | I9: ='Closed Counts'!I9/'Reported Counts'!I9 -> 0.99969174 | J9: ='Closed Counts'!J9/'Reported Counts'!J9 -> 0.99969164
A10: 2004-2 | B10: ='Closed Counts'!B10/'Reported Counts'!B10 -> 0.70436242 | C10: ='Closed Counts'!C10/'Reported Counts'!C10 -> 0.9870944 | D10: ='Closed Counts'!D10/'Reported Counts'!D10 -> 0.9966716 | E10: ='Closed Counts'!E10/'Reported Counts'!E10 -> 0.99814952 | F10: ='Closed Counts'!F10/'Reported Counts'!F10 -> 0.99888889 | G10: ='Closed Counts'!G10/'Reported Counts'!G10 -> 0.99925926 | H10: ='Closed Counts'!H10/'Reported Counts'!H10 -> 0.99962949 | I10: ='Closed Counts'!I10/'Reported Counts'!I10 -> 0.99962949
A11: 2005-1 | B11: ='Closed Counts'!B11/'Reported Counts'!B11 -> 0.81837017 | C11: ='Closed Counts'!C11/'Reported Counts'!C11 -> 0.98807803 | D11: ='Closed Counts'!D11/'Reported Counts'!D11 -> 0.99637812 | E11: ='Closed Counts'!E11/'Reported Counts'!E11 -> 0.99854967 | F11: ='Closed Counts'!F11/'Reported Counts'!F11 -> 0.99891226 | G11: ='Closed Counts'!G11/'Reported Counts'!G11 -> 0.99891226 | H11: ='Closed Counts'!H11/'Reported Counts'!H11 -> 0.99963729
A12: 2005-2 | B12: ='Closed Counts'!B12/'Reported Counts'!B12 -> 0.69864961 | C12: ='Closed Counts'!C12/'Reported Counts'!C12 -> 0.9845283 | D12: ='Closed Counts'!D12/'Reported Counts'!D12 -> 0.99621212 | E12: ='Closed Counts'!E12/'Reported Counts'!E12 -> 0.99810534 | F12: ='Closed Counts'!F12/'Reported Counts'!F12 -> 0.9984837 | G12: ='Closed Counts'!G12/'Reported Counts'!G12 -> 0.99924127
A13: 2006-1 | B13: ='Closed Counts'!B13/'Reported Counts'!B13 -> 0.80519943 | C13: ='Closed Counts'!C13/'Reported Counts'!C13 -> 0.98488201 | D13: ='Closed Counts'!D13/'Reported Counts'!D13 -> 0.99630178 | E13: ='Closed Counts'!E13/'Reported Counts'!E13 -> 0.99814883 | F13: ='Closed Counts'!F13/'Reported Counts'!F13 -> 0.99888889
A14: 2006-2 | B14: ='Closed Counts'!B14/'Reported Counts'!B14 -> 0.69632011 | C14: ='Closed Counts'!C14/'Reported Counts'!C14 -> 0.98579439 | D14: ='Closed Counts'!D14/'Reported Counts'!D14 -> 0.99588015 | E14: ='Closed Counts'!E14/'Reported Counts'!E14 -> 0.99775112
A15: 2007-1 | B15: ='Closed Counts'!B15/'Reported Counts'!B15 -> 0.79868115 | C15: ='Closed Counts'!C15/'Reported Counts'!C15 -> 0.98539281 | D15: ='Closed Counts'!D15/'Reported Counts'!D15 -> 0.99644128
A16: 2007-2 | B16: ='Closed Counts'!B16/'Reported Counts'!B16 -> 0.74632748 | C16: ='Closed Counts'!C16/'Reported Counts'!C16 -> 0.98344132
A17: 2008-1 | B17: ='Closed Counts'!B17/'Reported Counts'!B17 -> 0.80694489

Sheet Dev Method
A1: Auto Collision Insurer
A2: Exhibit I (Sheet 3) p.217
A3: Projection of Ultimate Claims Using Reported and Paid Claims ($000)
B5: Age of | C5: Claim Counts at 6/30/2008 | E5: CDF to Ult | G5: Development Method | I5: Selected
A6: AY | B6: AY @ 12/31/07 | C6: Closed | D6: Reported | E6: Closed | F6: Reported | G6: Closed | H6: Reported | I6: Ult
A7: 2003-2 | B7: =B8+6 -> 60 | C7: ='Closed Counts'!$K$8 -> 3292 | D7: ='Reported Counts'!$K$8 -> 3292 | E7: ='Closed Counts'!$K$48 -> 1 | F7: ='Reported Counts'!$K$48 -> 1 | G7: =C7*E7 -> 3292 | H7: =D7*F7 -> 3292 | I7: =AVERAGE(G7:H7) -> 3292
A8: 2004-1 | B8: =B9+6 -> 54 | C8: ='Closed Counts'!$J$9 -> 3242 | D8: ='Reported Counts'!$J$9 -> 3243 | E8: ='Closed Counts'!$J$48 -> 1 | F8: ='Reported Counts'!$J$48 -> 0.99969633 | G8: =C8*E8 -> 3242 | H8: =D8*F8 -> 3242.0152 | I8: =AVERAGE(G8:H8) -> 3242.0076
A9: 2004-2 | B9: =B10+6 -> 48 | C9: ='Closed Counts'!$I$10 -> 2698 | D9: ='Reported Counts'!$I$10 -> 2699 | E9: ='Closed Counts'!$I$48 -> 0.99984582 | F9: ='Reported Counts'!$I$48 -> 0.99954224 | G9: =C9*E9 -> 2697.584 | H9: =D9*F9 -> 2697.7645 | I9: =AVERAGE(G9:H9) -> 2697.6743
A10: 2005-1 | B10: =B11+6 -> 42 | C10: ='Closed Counts'!$H$11 -> 2756 | D10: ='Reported Counts'!$H$11 -> 2757 | E10: ='Closed Counts'!$H$48 -> 0.99984582 | F10: ='Reported Counts'!$H$48 -> 0.99943957 | G10: =C10*E10 -> 2755.5751 | H10: =D10*F10 -> 2755.4549 | I10: =AVERAGE(G10:H10) -> 2755.515
A11: 2005-2 | B11: =B12+6 -> 36 | C11: ='Closed Counts'!$G$12 -> 2634 | D11: ='Reported Counts'!$G$12 -> 2636 | E11: ='Closed Counts'!$G$48 -> 0.9999668 | F11: ='Reported Counts'!$G$48 -> 0.99919539 | G11: =C11*E11 -> 2633.9125 | H11: =D11*F11 -> 2633.879 | I11: =AVERAGE(G11:H11) -> 2633.8958
A12: 2006-1 | B12: =B13+6 -> 30 | C12: ='Closed Counts'!$F$13 -> 2697 | D12: ='Reported Counts'!$F$13 -> 2700 | E12: ='Closed Counts'!$F$48 -> 1.0000904 | F12: ='Reported Counts'!$F$48 -> 0.99894287 | G12: =C12*E12 -> 2697.2438 | H12: =D12*F12 -> 2697.1458 | I12: =AVERAGE(G12:H12) -> 2697.1948
A13: 2006-2 | B13: =B14+6 -> 24 | C13: ='Closed Counts'!$E$14 -> 2662 | D13: ='Reported Counts'!$E$14 -> 2668 | E13: ='Closed Counts'!$E$48 -> 1.0003351 | F13: ='Reported Counts'!$E$48 -> 0.99869342 | G13: =C13*E13 -> 2662.892 | H13: =D13*F13 -> 2664.514 | I13: =AVERAGE(G13:H13) -> 2663.703
A14: 2007-1 | B14: =B15+6 -> 18 | C14: ='Closed Counts'!$D$15 -> 2520 | D14: ='Reported Counts'!$D$15 -> 2529 | E14: ='Closed Counts'!$D$48 -> 1.001466 | F14: ='Reported Counts'!$D$48 -> 0.99794862 | G14: =C14*E14 -> 2523.6943 | H14: =D14*F14 -> 2523.8121 | I14: =AVERAGE(G14:H14) -> 2523.7532
A15: 2007-2 | B15: =B16+6 -> 12 | C15: ='Closed Counts'!$C$16 -> 2732 | D15: ='Reported Counts'!$C$16 -> 2778 | E15: ='Closed Counts'!$C$48 -> 1.0103354 | F15: ='Reported Counts'!$C$48 -> 0.99582027 | G15: =C15*E15 -> 2760.2362 | H15: =D15*F15 -> 2766.3887 | I15: =AVERAGE(G15:H15) -> 2763.3125
A16: 2008-1 | B16: 6 | C16: ='Closed Counts'!$B$17 -> 2533 | D16: ='Reported Counts'!$B$17 -> 3139 | E16: ='Closed Counts'!$B$48 -> 1.1947495 | F16: ='Reported Counts'!$B$48 -> 0.97377455 | G16: =C16*E16 -> 3026.3006 | H16: =D16*F16 -> 3056.6783 | I16: =H16 -> 3056.6783
A18: Total | C18: =SUM(C7:C16) -> 27766 | D18: =SUM(D7:D16) -> 28441 | G18: =SUM(G7:G16) -> 28291.438 | H18: =SUM(H7:H16) -> 28329.652 | I18: =SUM(I7:I16) -> 28325.734

Sheet Dev Unpaid
A1: U.S. Industry Auto
A2: Exhibit I (Sheet 8)
A3: Projection of Ultimate Claims Using Reported and Paid Claims ($000) | G3: Unpaid Claim Estimate at 12/31/08
G4: IBNR - Based on | I4: Total - Based on
B5: Claims at 12/31/07 | D5: Development Method | F5: Case O/S | G5: Dev. Method with | I5: Dev. Method with
A6: AY | B6: Reported | C6: Paid | D6: Reported | E6: Paid | F6: @ 12/31/07 | G6: Reported | H6: Paid | I6: Reported | J6: Paid
A7: 1999 | B7: ='Dev Method'!C7 -> 3292 | C7: ='Dev Method'!D7 -> 3292 | D7: ='Dev Method'!G7 -> 3292 | E7: ='Dev Method'!H7 -> 3292 | F7: =B7-C7 -> 0 | G7: =D7-B7 -> 0 | H7: =E7-B7 -> 0 | I7: =F7+G7 -> 0 | J7: =F7+H7 -> 0
A8: 1999 | B8: ='Dev Method'!C8 -> 3242 | C8: ='Dev Method'!D8 -> 3243 | D8: ='Dev Method'!G8 -> 3242 | E8: ='Dev Method'!H8 -> 3242.0152 | F8: =B8-C8 -> -1 | G8: =D8-B8 -> 0 | H8: =E8-B8 -> 0.015183723 | I8: =F8+G8 -> -1 | J8: =F8+H8 -> -0.98481628
A9: =A8+1 -> 2000 | B9: ='Dev Method'!C9 -> 2698 | C9: ='Dev Method'!D9 -> 2699 | D9: ='Dev Method'!G9 -> 2697.584 | E9: ='Dev Method'!H9 -> 2697.7645 | F9: =B9-C9 -> -1 | G9: =D9-B9 -> -0.41597286 | H9: =E9-B9 -> -0.23548981 | I9: =F9+G9 -> -1.4159729 | J9: =F9+H9 -> -1.2354898
A10: =A9+1 -> 2001 | B10: ='Dev Method'!C10 -> 2756 | C10: ='Dev Method'!D10 -> 2757 | D10: ='Dev Method'!G10 -> 2755.5751 | E10: ='Dev Method'!H10 -> 2755.4549 | F10: =B10-C10 -> -1 | G10: =D10-B10 -> -0.4249152 | H10: =E10-B10 -> -0.54511508 | I10: =F10+G10 -> -1.4249152 | J10: =F10+H10 -> -1.5451151
A11: =A10+1 -> 2002 | B11: ='Dev Method'!C11 -> 2634 | C11: ='Dev Method'!D11 -> 2636 | D11: ='Dev Method'!G11 -> 2633.9125 | E11: ='Dev Method'!H11 -> 2633.879 | F11: =B11-C11 -> -2 | G11: =D11-B11 -> -0.087461309 | H11: =E11-B11 -> -0.12096215 | I11: =F11+G11 -> -2.0874613 | J11: =F11+H11 -> -2.1209622
A12: =A11+1 -> 2003 | B12: ='Dev Method'!C12 -> 2697 | C12: ='Dev Method'!D12 -> 2700 | D12: ='Dev Method'!G12 -> 2697.2438 | E12: ='Dev Method'!H12 -> 2697.1458 | F12: =B12-C12 -> -3 | G12: =D12-B12 -> 0.24376906 | H12: =E12-B12 -> 0.14575647 | I12: =F12+G12 -> -2.7562309 | J12: =F12+H12 -> -2.8542435
A13: =A12+1 -> 2004 | B13: ='Dev Method'!C13 -> 2662 | C13: ='Dev Method'!D13 -> 2668 | D13: ='Dev Method'!G13 -> 2662.892 | E13: ='Dev Method'!H13 -> 2664.514 | F13: =B13-C13 -> -6 | G13: =D13-B13 -> 0.89199203 | H13: =E13-B13 -> 2.5140318 | I13: =F13+G13 -> -5.108008 | J13: =F13+H13 -> -3.4859682
A14: =A13+1 -> 2005 | B14: ='Dev Method'!C14 -> 2520 | C14: ='Dev Method'!D14 -> 2529 | D14: ='Dev Method'!G14 -> 2523.6943 | E14: ='Dev Method'!H14 -> 2523.8121 | F14: =B14-C14 -> -9 | G14: =D14-B14 -> 3.6942641 | H14: =E14-B14 -> 3.8120514 | I14: =F14+G14 -> -5.3057359 | J14: =F14+H14 -> -5.1879486
A15: =A14+1 -> 2006 | B15: ='Dev Method'!C15 -> 2732 | C15: ='Dev Method'!D15 -> 2778 | D15: ='Dev Method'!G15 -> 2760.2362 | E15: ='Dev Method'!H15 -> 2766.3887 | F15: =B15-C15 -> -46 | G15: =D15-B15 -> 28.236212 | H15: =E15-B15 -> 34.388709 | I15: =F15+G15 -> -17.763788 | J15: =F15+H15 -> -11.611291
A16: =A15+1 -> 2007 | B16: ='Dev Method'!C16 -> 2533 | C16: ='Dev Method'!D16 -> 3139 | D16: ='Dev Method'!G16 -> 3026.3006 | E16: ='Dev Method'!H16 -> 3056.6783 | F16: =B16-C16 -> -606 | G16: =D16-B16 -> 493.3006 | H16: =E16-B16 -> 523.67831 | I16: =F16+G16 -> -112.6994 | J16: =F16+H16 -> -82.32169
A18: Total | B18: =SUM(B7:B16) -> 27766 | C18: =SUM(C7:C16) -> 28441 | D18: =SUM(D7:D16) -> 28291.438 | E18: =SUM(E7:E16) -> 28329.652 | F18: =SUM(F7:F16) -> -675 | G18: =SUM(G7:G16) -> 525.43849 | H18: =SUM(H7:H16) -> 563.65247 | I18: =SUM(I7:I16) -> -149.56151 | J18: =SUM(J7:J16) -> -111.34753

Sheet Proj FS
A1: U.S. Industry Auto
A2: Exhibit I (Sheet 7-8) p.221-222
A3: Projection of Ultimate Claims Using Reported and Paid Claims ($000)
B5: Age of | C5: Reported | D5: Paid | E5: Reported | G5: Ultimate | H5: Ultimate | I5: Ultimate
A6: AY | B6: AY @ 12/31/07 | C6: Claims | D6: Claims | E6: Severity | F6: CDF | G6: Severity | H6: Counts | I6: Claims | J6: IBNR | K6: Unpaid
A7: 2003-2 | B7: =B8+6 -> 60 | C7: ='Reported Claims'!K8 -> 14847000 | D7: 14846000 | E7: ='Reported Severity'!K8 -> 4510.0243 | F7: ='Reported Severity'!K48 -> 1 | G7: =E7*F7 -> 4510.0243 | H7: ='Dev Method'!I7 -> 3292 | I7: =G7*H7 -> 14847000 | J7: =I7-C7 -> 0 | K7: =I7-D7 -> 1000
A8: 2004-1 | B8: =B9+6 -> 54 | C8: ='Reported Claims'!J9 -> 14617000 | D8: 14614000 | E8: ='Reported Severity'!J9 -> 4507.2464 | F8: ='Reported Severity'!J48 -> 1.0001017 | G8: =E8*F8 -> 4507.7047 | H8: ='Dev Method'!I8 -> 3242.0076 | I8: =G8*H8 -> 14614013 | J8: =I8-C8 -> -2987.1512 | K8: =I8-D8 -> 12.848837
A9: 2004-2 | B9: =B10+6 -> 48 | C9: ='Reported Claims'!I10 -> 12502000 | D9: 12502000 | E9: ='Reported Severity'!I10 -> 4632.086 | F9: ='Reported Severity'!I48 -> 1.0003266 | G9: =E9*F9 -> 4633.5989 | H9: ='Dev Method'!I9 -> 2697.6743 | I9: =G9*H9 -> 12499941 | J9: =I9-C9 -> -2059.3735 | K9: =I9-D9 -> -2059.3735
A10: 2005-1 | B10: =B11+6 -> 42 | C10: ='Reported Claims'!H11 -> 11841000 | D10: 11840000 | E10: ='Reported Severity'!H11 -> 4294.8857 | F10: ='Reported Severity'!H48 -> 1.0001044 | G10: =E10*F10 -> 4295.3341 | H10: ='Dev Method'!I10 -> 2755.515 | I10: =G10*H10 -> 11835857 | J10: =I10-C10 -> -5142.6509 | K10: =I10-D10 -> -4142.6509
A11: 2005-2 | B11: =B12+6 -> 36 | C11: ='Reported Claims'!G12 -> 11770000 | D11: 11765000 | E11: ='Reported Severity'!G12 -> 4465.0986 | F11: ='Reported Severity'!G48 -> 0.99991815 | G11: =E11*F11 -> 4464.7332 | H11: ='Dev Method'!I11 -> 2633.8958 | I11: =G11*H11 -> 11759642 | J11: =I11-C11 -> -10358.124 | K11: =I11-D11 -> -5358.1237
A12: 2006-1 | B12: =B13+6 -> 30 | C12: ='Reported Claims'!F13 -> 11760000 | D12: 11755000 | E12: ='Reported Severity'!F13 -> 4355.5556 | F12: ='Reported Severity'!F48 -> 0.99983319 | G12: =E12*F12 -> 4354.829 | H12: ='Dev Method'!I12 -> 2697.1948 | I12: =G12*H12 -> 11745822 | J12: =I12-C12 -> -14177.998 | K12: =I12-D12 -> -9177.9977
A13: 2006-2 | B13: =B14+6 -> 24 | C13: ='Reported Claims'!E14 -> 12697000 | D13: 12679000 | E13: ='Reported Severity'!E14 -> 4758.9955 | F13: ='Reported Severity'!E48 -> 0.99903756 | G13: =E13*F13 -> 4754.4153 | H13: ='Dev Method'!I13 -> 2663.703 | I13: =G13*H13 -> 12664350 | J13: =I13-C13 -> -32649.763 | K13: =I13-D13 -> -14649.763
A14: 2007-1 | B14: =B15+6 -> 18 | C14: ='Reported Claims'!D15 -> 11492000 | D14: 11406000 | E14: ='Reported Severity'!D15 -> 4544.0886 | F14: ='Reported Severity'!D48 -> 0.99774184 | G14: =E14*F14 -> 4533.8273 | H14: ='Dev Method'!I14 -> 2523.7532 | I14: =G14*H14 -> 11442261 | J14: =I14-C14 -> -49739.018 | K14: =I14-D14 -> 36260.982
A15: 2007-2 | B15: =B16+6 -> 12 | C15: ='Reported Claims'!C16 -> 12854000 | D15: 12648000 | E15: ='Reported Severity'!C16 -> 4627.0698 | F15: ='Reported Severity'!C48 -> 0.99650355 | G15: =E15*F15 -> 4610.8915 | H15: ='Dev Method'!I15 -> 2763.3125 | I15: =G15*H15 -> 12741334 | J15: =I15-C15 -> -112666.08 | K15: =I15-D15 -> 93333.921
A16: 2008-1 | B16: 6 | C16: ='Reported Claims'!B17 -> 14071000 | D16: 11833000 | E16: ='Reported Severity'!B17 -> 4482.6378 | F16: ='Reported Severity'!B48 -> 1.0352562 | G16: =E16*F16 -> 4640.6784 | H16: ='Dev Method'!I16 -> 3056.6783 | I16: =G16*H16 -> 14185061 | J16: =I16-C16 -> 114061.04 | K16: =I16-D16 -> 2352061
A18: Total | H18: =SUM(H7:H16) -> 28325.734 | I18: =SUM(I7:I16) -> 1.2833528e+08 | J18: =SUM(J7:J16) -> -115719.12 | K18: =SUM(K7:K16) -> 2447280.9
