Workbook
Name Facility: 'Audit Scoresheet'!$A$5

Sheet Page 1-3
A1: USDA Good Agricultural Practices Good Handling Practices
A2: Audit Verification Checklist
A3: for use only for SUBWAY SUPPLIERS
A14: This program is intended to assess a participant’s efforts to minimize the risk of contamination of fresh fruits, vegetables, nuts and miscellaneous commodities by microbial pathogens based on the U.S. Food and Drug Administration’s “Guide to Minimize Microbial Food Safety Hazards for Fresh Fruits and Vegetables,” and generally recognized good agricultural practices.
A18: Firm Name:
A19: Contact Person:
A20: Audit Site(s):
A21: Main Address:
A22: City: | G22: State: | L22: Zip:
A23: Telephone No: | I23: Fax:
A24: E-mail:
A25: Auditor (s): (list all auditors with the lead listed first)
A27: USDA or Fed-State Office performing audit:
A28: Arrival Date: | H28: Time:
A29: Departure Date: | H29: Time:
A30: Travel Time | H30: Code
A31: Person(s) Interviewed (use back of sheet if necessary to list all persons interviewed)
A34: Did the auditee participate in GAP & GHP training?
A36: Yes | I36: No
A38: Is there a map that accurately represents the farm operations?
A40: Yes | I40: No | L40: N/A
A41: Legal Description/GPS/Lat.-Long. of Location:
A42: Are all crop production areas located on this audit site?
A44: Yes | I44: No | L44: N/A
A45: Total acres farmed (Owned, leased/rented, contracted, consigned):
A46: Does the company have more than one packing facility?
A48: Yes | I48: No | L48: N/A
A49: Is there a floor plan of the packing house facility(s) indicating flow of product, storage areas, cull areas, employee break rooms, restrooms, offices?
A51: Yes | I51: No | L51: N/A
A52: Is any product commingled prior to packing?
A54: Yes | I54: No
A56: Audit Scope: (Please check all scopes audited)
A57: General Questions (All audits must begin with and pass this portion)
A59: Part 6 – Wholesale Distribution Center/Terminal Warehouse.…………………………............
A61: Part 7 – Preventive Food Defense Procedures.………………………….…………...….
A62: Products:
A64: Auditors’ Signature(s):
A67: Conditions Under Which an Automatic "Unsatisfactory"
A68: Will be Assessed
A69: • An immediate food safety risk is present when produce is grown, processed,
...

Sheet Pg. 4 General Questions
A1: General Questions
A2: Implementation of a Food Safety Program
A3: Questions | K3: Points | L3: Compliant | M3: Not Compliant | N3: N/A | O3: Doc
A4: P-1 | B4: The auditee shall have implemented a documented food safety program that incorporates Good Handling Practices. | O4: D
A7: P-2 | B7: The operation must have designated a person(s) to implement and oversee the operation's food safety program. | O7: D
B10: Name
A12: Traceability
A13: Questions | K13: Points | L13: Compliant | M13: Not Compliant | N13: N/A | O13: Doc
A14: G-1 | B14: The operation shall have a established documented traceability program. | K14: 15 | O14: D
A16: G-2 | B16: The operation shall perform scheduled a "mock recall" and take corrective actions if proven to not be effective. | K16: 10 | O16: R
A19: Worker Health & Hygiene
A20: Questions | K20: Points | L20: Compliant | M20: Not Compliant | N20: N/A | O20: Doc
A21: G-3 | B21: Potable water shall be available to all workers. | K21: 10 | O21: R
A22: G-4 | B22: All employees and visitors to the location are required to follow proper sanitation and hygiene practices. | K22: 10 | O22: P
A25: G-5 | B25: Training on proper sanitation and hygiene shall be provided to all staff. | K25: 15 | O25: D
A27: G-6 | B27: All Employees and visitors must follow good sanitation/hygienic practices. | K27: 15
A29: G-7 | B29: Employees who handle produce must properly wash their hands before beginning or returning to work. | K29: 15
A32: Questions | K32: Points | L32: Compliant | M32: Not Compliant | N32: N/A | O32: Doc
A33: G-8 | B33: Readily understandable signs shall be posted to instruct employees to wash their hands before beginning or returning to work. | K33: 10
A37: G-9 | B37: All toilet/restroom facilities shall be clean and properly supplied with single use towels, toilet paper, hand or antibacterial soap and potable water for hand washing. | K37: 15
A42: G-10 | B42: All toilet/restroom facilities shall be serviced and cleaned on a scheduled basis. | K42: 10 | O42: R
A45: G-11 | B45: Smoking and eating shall be confined to designated areas separate from product handling areas. | K45: 10 | O45: P
A48: G-12 | B48: Workers with diarrheal disease or symptoms of other infectious disease shall be prohibited from handling fresh produce. | K48: 15 | O48: P
A52: G-13 | B52: There is a policy which must describe procedures which specify the handling/distribution of produce or food contact surfaces which have come into contact with blood or other bodily fluids. | K52: 15 | O52: P
A58: G-14 | B58: Workers shall be instructed to seek prompt treatment with clean first aid supplies for cuts, abrasions, and other injuries. | K58: 5 | O58: P
A62: G-15 | B62: Company personnel or contracted personnel that apply regulated pre-harvest and/or post harvest material must be licensed. Company personnel or contracted personnel applying non-regulated materials shall be trained on its proper use. | K62: 10 | O62: R
A69: COMMENTS:
A84: Total Points earned for General Questions = | L84: =L14+L16+L21+L22+L25+L27+L29+L33+L37+L42+L45+L48+L52+L58+L62 -> 0
A85: Total Possible | D85: = | E85: 180 | G85: The total number of points possible for this section.
A86: Subtract "N/A" | D86: = | E86: =N16+N29+N33+N37+N42+N45+N62 -> 0 | G86: Enter the additive number of N/A points (+points) here.
A87: Adjusted Total | D87: = | E87: =E85-E86 -> 180 | G87: Subtract the N/A points from the Total possible points
A88: X .8 (80%) | G88: Multiply the Adjusted Total by .8 and show it as the Passing Score
A89: Passing Score | D89: = | E89: =E87*0.8 -> 144
E91: Compliant | I91: Not Compliant | M91: (please mark one)
A93: This program is intended to assess a participant’s efforts to minimize the risk of contamination of fresh
A94: fruits, vegetables, nuts and miscellaneous commodities by microbial pathogens based on the U.S. Food
A95: and Drug Administration’s “Guide to Minimize Microbial Food Safety Hazards for Fresh Fruits and
A96: Vegetables,” and generally recognized good agricultural practices.

Sheet Part 6-Wholesale Distribution
A1: Part 6-Wholesale Distribution Center/Terminal Warehouses
A2: Receiving
A3: Questions | K3: Points | L3: Compliant | M3: Not Compliant | N3: N/A | O3: Doc
A4: 6-1 | B4: All companies shall have an approved supplier program which requires produce suppliers to meet USDA acceptance criteria for a USDA audit appropriate for the commodity(s) being supplied. | K4: 15 | O4: D
A8: 6-2 | B8: Upon receiving, conveyances must be clean, in good physical condition, and shall be free from obvious objectionable odors, dirt, and/or debris at time of unloading. | K8: 10 | O8: P
A13: 6-3 | B13: Company shall not accept produce items that are loaded with, or are not protected from potentially contaminating products. | K13: 10 | O13: P
A16: 6-4 | B16: Refrigerated commodities shall be monitored for temperatures at the time of receiving. | K16: 5 | O16: R
A19: 6-5 | B19: The company shall have a written policy regarding the disposition of product when temperatures are not within the company's requirements at the time of receiving. | K19: 5 | O19: P
A24: Storage Facility/Temperature Control
A25: Questions | K25: Points | L25: Compliant | M25: Not Compliant | N25: N/A | O25: Doc
A26: 6-6 | B26: The facility shall be clean and maintained in an orderly manner. | K26: 5
A28: 6-7 | B28: Refrigerated rooms shall be monitored for temperature and logs are maintained. | K28: 5 | O28: D
A30: 6-8 | B30: Thermometer(s) shall be checked for accuracy and records shall be available. | K30: 5 | O30: D
A32: 6-9 | B32: Refrigeration system condensation shall not come into contact with the produce. | K32: 10
A34: 6-10 | B34: Refrigeration equipment (condensers, fans, etc.) shall be cleaned on a scheduled basis. | K34: 10 | O34: D
A37: Questions | K37: Points | L37: Compliant | M37: Not Compliant | N37: N/A | O37: Doc
A38: 6-11 | B38: Iced product shall not drip on pallets of produce stored below. | K38: 10
A40: 6-12 | B40: The water used for cooling/ice must be potable. | K40: 10 | O40: R
A42: 6-13 | B42: Manufacturing, storage, and transportation facilities used in making and delivering ice used for cooling the product shall be sanitized on a scheduled basis. | K42: 10 | O42: D
A47: 6-14 | B47: There shall be a policy describing procedures which specify the handling/disposition of finished product which is opened, spilled, or comes in contact with the floor. | K47: 15 | O47: P
A52: 6-15 | B52: Product flow zones shall be protected from sources of contamination. | K52: 10
A54: 6-16 | B54: Glass materials above product flow zones shall be contained in case of breakage. | K54: 10
A56: 6-17 | B56: The grounds shall be reasonably free of litter and debris. | K56: 5
A58: 6-18 | B58: The grounds shall be reasonably free of standing water. | K58: 5
A60: 6-19 | B60: Outside garbage receptacles/dumpsters must be closed or are located away from facility entrances and the areas around such sites are reasonably clean. | K60: 5
A64: 6-20 | B64: The facility shall be enclosed. | K64: 5
A65: 6-21 | B65: Floor drains shall be free of obstructions. | K65: 5
A66: 6-22 | B66: Pipes, ducts, fans, and ceilings in the facility shall be reasonably clean. | K66: 5
A68: 6-23 | B68: Possible wastewater spillage shall be prevented from contaminating any food storage or handling areas by barriers, drains, or a sufficient distance. | K68: 10
A72: 6-24 | B72: Non-food grade substances such as paints, lubricants, pesticides, etc. shall not be stored in close proximity to the product. | K72: 10
A76: Pest Control
A77: Questions | K77: Points | L77: Compliant | M77: Not Compliant | N77: N/A | O77: Doc
A78: 6-25 | B78: Measures shall be taken to exclude animals or pests from the facility. | K78: 10 | O78: D
A80: 6-26 | B80: There shall be an established pest control program for the facility. | K80: 10 | O80: D
A82: 6-27 | B82: Service reports for the pest control program shall be available for review. | K82: 5 | O82: R
A84: 6-28 | B84: Interior walls, floors and ceilings shall be well-maintained and free of major cracks and crevices. | K84: 5
A87: Repacking/Reconditioning
A88: (6-29) Does the facility repack and/or recondition product?
E89: YES | I89: NO | K89: (please mark one)
A90: If the answer to question 6-29 is YES, answer questions 6-30 through 6-41. If the answer is
...

Sheet Part 7-Preventive Food Defense
A1: Part 7 - Preventive Food Defense Procedures
A2: Based on the U.S. Food and Drug Administration’s Food Producers, Processors, and Transporters:
A3: Food Security Preventive Measure Guidance for Industry.
A4: Secure Employee/Visitor Procedures
A5: Questions | K5: Points | L5: Compliant | M5: Not Compliant | N5: N/A | O5: Doc
A6: 7-1 | B6: The company shall have a documented food defense plan and a person has been designated to oversee it. | K6: 5 | O6: D
B10: Name:
A12: 7-2 | B12: Food defense training shall be provided to all employees. | K12: 5 | O12: D
A14: 7-3 | B14: Employees are aware of whom in management they shall contact about potential security problems/issues. | K14: 5
B17: Name of management representative:
A20: 7-4 | B20: Visitors shall be required to check in (showing proof of identity) and out, when entering/leaving the facility. | K20: 5 | O20: D
A23: 7-5 | B23: The purpose of visitation to site shall be verified before admittance to the facility. | K23: 5 | O23: D
A26: 7-6 | B26: Visitors shall be prohibited from the packing/storage areas unless accompanied by an employee. | K26: 5 | O26: D
A29: 7-7 | B29: Incoming and outgoing employee and visitor vehicles to and from the site shall be subject to inspection. | K29: 5 | O29: D
A32: 7-8 | B32: Parked vehicles belonging to employees and visitors shall display a decal or placard issued by the facility. | K32: 5
A35: 7-9 | B35: Staff is prohibited from bringing personal items into the handling or storage areas. | K35: 5 | O35: D
A38: Questions | K38: Points | L38: Compliant | M38: Not Compliant | N38: N/A | O38: Doc
A39: 7-10 | B39: Staff access in the facility shall be limited to the area related to their job function and unrestricted areas. | K39: 5 | O39: D
A42: 7-11 | B42: Management is aware of which employee shall be on the premises, and the area to which they are assigned. | K42: 5 | O42: D
A46: 7-12 | B46: A system of positive identification of employees shall be established and is enforced. | K46: 5
A49: Secure Facility Procedures
A50: Questions | K50: Points | L50: Compliant | M50: Not Compliant | N50: N/A | O50: Doc
A51: 7-13 | B51: Uniforms, name tags, or identification badges shall be collected from employees prior to the termination of employment. | K51: 5 | O51: D
A55: 7-14 | B55: The mailroom shall be located away from the packing/storage facilities. | K55: 5
A57: 7-15 | B57: Computer access must be restricted to specific personnel. | K57: 5 | O57: D
A59: 7-16 | B59: A system of traceability of computer transactions shall be established. | K59: 5
A61: 7-17 | B61: A minimum level of background checks shall be established for all employees. | K61: 5 | O61: D
A64: 7-18 | B64: Routine security checks of the premises shall be performed for signs of tampering, criminal or terrorist activity. | K64: 5 | O64: D
A68: 7-19 | B68: Perimeter of facility shall be secured by fencing or other deterrent. | K68: 5
A70: 7-20 | B70: Checklists shall be used to verify the security of doors, windows, and other points of entry. | K70: 5 | O70: D
A73: 7-21 | B73: All keys to the establishment must be accounted for. | K73: 5 | O73: D
A75: Questions | K75: Points | L75: Compliant | M75: Not Compliant | N75: N/A | O75: Doc
A76: 7-22 | B76: The facility shall have an emergency lighting system. | K76: 5
A78: 7-23 | B78: The facility shall be enclosed. | K78: 5
A79: 7-24 | B79: Storage or vehicles/containers/ trailers/railcars that are not being used shall be kept locked. | K79: 5
A82: 7-25 | B82: Delivery schedules shall be established. | K82: 5
A84: 7-26 | B84: The off-loading of incoming materials must be supervised. | K84: 5
A86: 7-27 | B86: The organization shall have an established policy for rejecting deliveries. | K86: 5 | O86: D
A89: 7-28 | B89: Unauthorized deliveries shall not be accepted. | K89: 5 | O89: D
A91: 7-29 | B91: The company shall not accept returned (empty) containers for packing of product unless they are sanitized containers intended for reuse. | K91: 5 | O91: D
...

Sheet Audit Scoresheet
A1: United States Department of Agriculture | F1: Good Agricultural Practices & Good Handling Practices
A2: Agricultural Marketing Services | F2: Audit Verification Program Scoresheet www.ams.usda.gov/gapghp
A3: Fresh Products Branch | F3: for use only for SUBWAY SUPPLIERS
A4: Facility Name (Print) as it should appear on Certificate:
C5: ='Page 1-3'!D18 -> 0
A6: Street Address (Print): | H6: City (Print): | Q6: State (Print): | T6: Zip (Print):
A7: ='Page 1-3'!D21 -> 0 | H7: ='Page 1-3'!B22 -> 0 | Q7: ='Page 1-3'!H22 -> 0 | T7: ='Page 1-3'!M22 -> 0
A8: e-mail Address (Print): | H8: fax number: | Q8: Date Audit Requested:
A9: ='Page 1-3'!C24 -> 0 | H9: ='Page 1-3'!J23 -> 0 | Q9: Date of Previous Audit :
A10: Date Audit Began: | C10: ='Page 1-3'!E28 -> 0 | I10: Date Audit Completed: | M10: ='Page 1-3'!E29 -> 0 | Q10: USDA Commodity Procurement Audit?
A11: Time Audit Began: | C11: ='Page 1-3'!J28 -> 0 | I11: Time Audit Completed: | M11: ='Page 1-3'!J29 -> 0 | Q11: Check One | S11: Yes | U11: No
A13: EVALUATION ELEMENTS
A14: Scopes | B14: Element | F14: Possible | G14: Less N/A | I14: Adjusted | K14: Passing | M14: Facility | N14: Compliant | P14: Date | R14: General | T14: Reviewing | W14: Un-announced
A15: Requested | F15: Points | G15: Points | I15: Points | K15: Score* | M15: Score | N15: Not Comp | P15: Passed | R15: Questions | T15: Official
B16: General Questions | F16: 180 | G16: ='Pg. 4 General Questions'!E86 -> 0 | I16: ='Pg. 4 General Questions'!E87 -> 180 | K16: ='Pg. 4 General Questions'!E89 -> 144 | M16: ='Pg. 4 General Questions'!L84 -> 0
A17: ='Page 1-3'!P59 -> 0 | B17: Part 6 – Wholesale Distribution | F17: 410 | G17: ='Part 6-Wholesale Distribution'!E197 -> 0 | I17: ='Part 6-Wholesale Distribution'!E198 -> 410 | K17: ='Part 6-Wholesale Distribution'!E200 -> 328 | M17: ='Part 6-Wholesale Distribution'!J195 -> 0
B18: Center/ Warehouses
A19: ='Page 1-3'!P61 -> 0 | B19: Part 7 – Preventative Food | F19: 180 | G19: ='Part 7-Preventive Food Defense'!E150 -> 0 | I19: ='Part 7-Preventive Food Defense'!E151 -> 180 | K19: ='Part 7-Preventive Food Defense'!E153 -> 144 | M19: ='Part 7-Preventive Food Defense'!J148 -> 0
B20: Defense Procedures
A21: **A Passing Score is 80% of the Possible Points or the Adjusted Points, if adjustment are necessary, with no "automatic unsatisfactory" conditions is required for certification.
A22: Commodities | C22: Commodity:
A24: Reviewed (Print): | C24: Acres:
A26: Send completed GAP&GHP Certificate to: (choose one) | G26: Inspection office: (list office) | Q26: Directly to auditee above:
A27: Lead Auditor Name (Print): | I27: Duty Station: | P27: Signature & Date:
A28: Facility Representative signature: | M28: Date: | R28: All Scopes Completed:
A30: By signing this form, the facility representative agrees to have company information posted to the USDA website. A company will only be listed on the USDA website if all scopes audited receive a passing score.
A31: For USDA HQ use:
A32: Reviewing Official Name (Print) | K32: Signature:
A33: Date Received: | D33: Date Certificate Mailed: | J33: Date Posted to USDA Website: | S33: Revised January 26, 2012
S34: USDA, AMS, FVP, FPB
A35: To verify a company's continued good standing in the USDA GAP&GHP Program please visit http://www.ams.usda.gov/gapghp | S35: For Official Government Use Only

Sheet CAR Duplication Instructions
A1: DUPLICATION OF CORRECTIVE ACTION TAB INSTRUCTIONS
A3: Any item on any checklist with a checkmark beside the Corrective Action Needed (CAN) box or the Immediate Action Required (IAR) box must be documented using a Corrective Action Report. A separate form is required for each item with either of these entities. If there is more than one form needed, follow the instructions below to duplicate the Corrective Action Report Tab:
B4: 1. Right-click the "Corrective Action Report" Tab at the bottom of Excel.
B6: 2. Click "Move or Copy.
B8: 3. Under the box titled "Before Sheet," select "(move to end)"
B10: 4. Place a check in the box beside "Create a Copy"
B12: 5. Click "Ok"

Sheet Corrective Action Report
A1: USDA Good Agricultural Practices and Good Handling Practices
A2: Corrective Action Report
A4: USDA Fruit and Vegetable Programs | F4: Report #:
A5: Good Agricultural Practice & Good Handling Practices | H5: of
A6: CORRECTIVE ACTION REPORT
A7: Company Name/Farm: | C7: ='Page 1-3'!D18 -> 0 | F7: Date:
A9: Lead Auditor:
A11: Crop(s):
A13: Description of Non-Conformity:
A21: Notified company staff at time of finding non-conformity:
A23: Checklist question number and/or section of auditee food safety plan non-conformity is associated with:
A25: Company Representative Signature:
C27: SIGNATURE AFFIRMS FACTS CONCERNING NON-CONFORMITY ARE CORRECT
A28: Corrective Action Proposed and Time Frame for Implementation:
A38: Auditor Signature for Acceptance of Proposed Corrective Action and Timetable for Implementation:
