Workbook
Name Facility: 'Audit Scoresheet'!$A$5

Sheet Page 1-3
A1: USDA Good Agricultural Practices Good Handling Practices
A2: Audit Verification Checklist
A13: This program is intended to assess a participant’s efforts to minimize the risk of contamination of fresh fruits, vegetables, nuts and miscellaneous commodities by microbial pathogens based on the U.S. Food and Drug Administration’s “Guide to Minimize Microbial Food Safety Hazards for Fresh Fruits and Vegetables,” and generally recognized good agricultural practices.
A17: Firm Name:
A18: Contact Person:
A19: Audit Site(s):
A20: Main Address:
A21: City: | G21: State: | L21: Zip:
A22: Telephone No: | I22: Fax:
A23: E-mail:
A24: Auditor (s): (list all auditors with the lead listed first)
A26: USDA or Fed-State Office performing audit:
A27: Arrival Date: | H27: Time:
A28: Departure Date: | H28: Time:
A29: Travel Time | H29: Code
A30: Person(s) Interviewed (use back of sheet if necessary to list all persons interviewed)
A33: Did the auditee participate in GAP & GHP training?
A35: Yes | I35: No
A37: Is there a map that accurately represents the farm operations?
A39: Yes | I39: No | L39: N/A
A40: Legal Description/GPS/Lat.-Long. of Location:
A41: Are all crop production areas located on this audit site?
A43: Yes | I43: No | L43: N/A
A44: Total acres farmed (Owned, leased/rented, contracted, consigned):
A45: Does the company have more than one packing facility?
A47: Yes | I47: No | L47: N/A
A48: Is there a floor plan of the packing house facility(s) indicating flow of product, storage areas, cull areas, employee break rooms, restrooms, offices?
A50: Yes | I50: No | L50: N/A
A51: Is any product commingled prior to packing?
A53: Yes | I53: No
A55: Audit Scope: (Please check all scopes audited)
A56: General Questions (All audits must begin with and pass this portion)
A58: Part 1 – Farm Review…………………………………………………………………………...…..…..
A60: Part 2 - Field Harvest and Field Packing Activities…………………………………...……..…….
A62: Part 3 - House Packing Facility…………………………………………………………………...….
A64: Part 4 – Storage and Transportation…………………………………………………...……….…...
A66: Part 5 – (Not Used)
A68: Part 6 – Wholesale Distribution Center/Terminal Warehouse.…………………………............
A70: Part 7 – Preventive Food Defense Procedures.………………………….…………...….
A71: Products:
...

Sheet Pg. 4 General Questions
A1: General Questions
A2: Implementation of a Food Safety Program
A3: Questions | K3: Points | L3: Yes | M3: NO | N3: N/A | O3: Doc
A4: P-1 | B4: A documented food safety program that | O4: D
B5: incorporates GAP and/or GHP has been
B6: implemented.
A7: P-2 | B7: The operation has designated someone to | O7: D
B8: implement and oversee an established food
B9: safety program.
B10: Name
A12: Traceability
A13: Questions | K13: Points | L13: Yes | M13: NO | N13: N/A | O13: Doc
A14: G-1 | B14: A documented traceability program has | K14: 15 | O14: D
B15: been established.
A16: G-2 | B16: The operation has performed a "mock recall" | K16: 10 | O16: R
B17: that was proven to be effective.
A18: Worker Health & Hygiene
A19: Questions | K19: Points | L19: Yes | M19: NO | N19: N/A | O19: Doc
A20: G-3 | B20: Potable water is available to all workers. | K20: 10 | O20: R
A21: G-4 | B21: All employees and all visitors to the location are | K21: 10 | O21: P
B22: required to follow proper sanitation and hygiene
B23: practices.
A24: G-5 | B24: Training on proper sanitation and hygiene | K24: 15 | O24: D
B25: practices is provided to all staff.
A26: G-6 | B26: Employees and visitors are following good | K26: 15
B27: hygiene/sanitation practices.
A28: G-7 | B28: Employees who handle or package produce are | K28: 15
B29: washing their hands before beginning or
B30: returning to work.
A31: G-8 | B31: Readily understandable signs are posted to | K31: 10
B32: instruct employees to wash their hands before
B33: beginning or returning to work.
A34: G-9 | B34: All toilet/restroom/field sanitation facilities are | K34: 15
B35: clean. They are properly supplied with single
B36: use towels, toilet paper, hand soap or anti-
B37: bacterial soap, and potable water for hand
B38: washing.
A39: G-10 | B39: All toilet/restroom/field sanitation facilities are | K39: 10 | O39: R
B40: serviced and cleaned on a scheduled basis.
A41: Questions | K41: Points | L41: Yes | M41: NO | N41: N/A | O41: Doc
...

Sheet Part 1-Farm Review
A1: Part 1 - Farm Review
A2: Water Usage
A3: (1-1) | B3: What is the source of irrigation water? (Pond, Stream, Well, Municipal, Other)
A4: Please specify:
A6: (1-2) | B6: How are crops irrigated? (Flood, Drip, Sprinkler, Other) Please specify:
A9: Questions | K9: Points | L9: Yes | M9: NO | N9: N/A | O9: Doc
A10: 1-3 | B10: A water quality assessment has been performed to determine the quality of water used for irrigation purpose on the crop(s) being applied. | K10: 15 | O10: D
A13: 1-4 | B13: A water quality assessment has been performed to determine the quality of water use for chemical application or fertigation method. | K13: 15 | O13: D
A16: 1-5 | B16: If necessary, steps are taken to protect irrigation water from potential direct and non-point source contamination. | K16: 15
A19: Sewage Treatment
A20: Questions | K20: Points | L20: Yes | M20: NO | N20: N/A | O20: Doc
A21: 1-6 | B21: The farm sewage treatment system/septic system is functioning properly and there is no evidence of leaking or runoff. | K21: 15
A24: 1-7 | B24: There is no municipal/commercial sewage treatment facility or waste material landfill adjacent to the farm. | K24: 10
A27: Animals/Wildlife/Livestock
A28: Questions | K28: Points | L28: Yes | M28: NO | N28: N/A | O28: Doc
A29: 1-8 | B29: Crop production areas are not located near or adjacent to dairy, livestock, or fowl production facilities unless adequate barriers exist. | K29: 15
A32: 1-9 | B32: Manure lagoons located near or adjacent to crop production areas are maintained to prevent leaking/overflowing, or measures have been taken to stop runoff from contaminating the crop production areas. | K32: 10
A37: Questions | K37: Points | L37: Yes | M37: NO | N37: N/A | O37: Doc
A38: 1-10 | B38: Manure stored near or adjacent to crop | K38: 10
B39: production areas is contained to prevent
B40: contamination of crops.
A41: 1-11 | B41: Measures are taken to restrict access of | K41: 10
B42: livestock to the source or delivery system of
B43: crop irrigation water.
A44: 1-12 | B44: Crop production areas are monitored for the | K44: 5 | O44: R
B45: presence or signs of wild or domestic animals
B46: the entering the land.
A47: 1-13 | B47: Measures are taken to reduce the opportunity | K47: 5 | O47: R
B48: for wild and/or domestic animals from entering
B49: crop production areas.
A50: Manure and Municipal Biosolids
A51: Please choose one of the following options as it relates to the farm operations:
C52: Option A. Raw manure or a combination of raw and composed manure is
D53: used as a soil amendment.
C54: Option B. Only composted manure/treated municipal biosolids are used as
D55: soil amendments.
C56: Option C. No manure or municipal biosolids of any kind are used as soil
D57: amendments.
A58: Only answer the following manure questions (questions 1-14 to 1-22) that are
A59: assigned to the Option chosen above. DO NOT answer the questions from the other
...

Sheet Part 2-Field Harvest & Packing 
A1: Part 2 - Field Harvest and Field Packing Activities
A2: Field Sanitation and Hygiene
A3: Questions | K3: Points | L3: Yes | M3: NO | N3: N/A | O3: Doc
A4: 2-1 | B4: A documented pre-harvest assessment is made | K4: 15 | O4: D
B5: on the crop production areas. Risks and
B6: possible sources of crop contamination are
B7: noted and assessed.
A8: 2-2 | B8: The number, condition, and placement of field | K8: 10
B9: sanitation units comply with applicable state
B10: and/or federal regulations.
A11: 2-3 | B11: When question 2-2 is answered "N/A" (sanitation | K11: 10
B12: units are not required), a toilet facility is readily
B13: available for all workers.
A14: 2-4 | B14: Field sanitation units are located in a location | K14: 10
B15: that minimizes the potential risk for product
B16: contamination and are directly accessible for
B17: servicing.
A18: 2-5 | B18: A response plan is in place for the event of a | K18: 10 | O18: P
B19: major spill or leak of field sanitation units or
B20: toilet facilities.
A21: Field Harvesting and Transportation
A22: Questions | K22: Points | L22: Yes | M22: NO | N22: N/A | O22: Doc
A23: 2-6 | B23: All harvesting containers and bulk hauling | K23: 10 | O23: D
B24: vehicles that come in direct contact with
B25: product are cleaned and/or sanitized on a
B26: scheduled basis and kept as clean as
B27: practicable.
A28: 2-7 | B28: All hand harvesting equipment and implements | K28: 10 | O28: D
B29: (knives, pruners machetes, etc.) are kept as
B30: clean as practical and are disinfected on a
B31: scheduled basis.
A32: 2-8 | B32: Damaged containers are properly repaired or | K32: 5
B33: disposed of.
A34: 2-9 | B34: Harvesting equipment and/or machinery which | K34: 10
B35: comes into contact with product is in good
B36: repair.
A37: 2-10 | B37: Light bulbs and glass on harvesting equipment | K37: 10
B38: are protected so as not to contaminate produce
B39: or fields in the case of breakage.
A40: Questions | K40: Points | L40: Yes | M40: NO | N40: N/A | O40: Doc
...

Sheet Part 3-House Packing Facilty
A1: Part 3 - HOUSE PACKING FACILITY
A2: Receiving
A3: Questions | K3: Points | L3: Yes | M3: NO | N3: N/A | O3: Doc
A4: 3-1 | B4: Product delivered from the field which is held in | K4: 5
B5: a staging area prior to packing or processing is
B6: protected from possible contamination.
A7: 3-2 | B7: Prior to packing, product is properly stored | K7: 5
B8: and/or handled in order to reduce possible
B9: contamination.
A10: Washing/Packing Line
A11: Questions | K11: Points | L11: Yes | M11: NO | N11: N/A | O11: Doc
A12: 3-3 | B12: Source water used in the packing operation is | K12: 15 | O12: R
B13: potable.
A14: 3-4 | B14: If applicable, the temperature of processing | K14: 10 | O14: D
B15: water used in dump tanks, flumes, etc., is
B16: monitored and is kept at temperatures
B17: appropriate for the commodity.
A18: 3-5 | B18: Processing water is sufficiently treated to | K18: 10 | O18: D
B19: reduce microbial contamination.
A20: 3-6 | B20: Water-contact surfaces, such as dump tanks, | K20: 10 | O20: D
B21: flumes, wash tanks and hydro coolers, are
B22: cleaned and/or sanitized on a scheduled basis.
A23: 3-7 | B23: Water treatment (strength levels and pH) and | K23: 10 | O23: D
B24: exposure time is monitored and the facility has
B25: demonstrated it is appropriate for the product.
A26: 3-8 | B26: Food contact surfaces are in good condition; | K26: 15 | O26: D
B27: cleaned and/or sanitized prior to use and
B28: cleaning logs are maintained.
A29: 3-9 | B29: Product flow zones are protected from sources | K29: 10
B30: of contamination.
A31: 3-10 | B31: The water used for cooling and/or making ice | K31: 15 | O31: R
B32: is potable.
A33: 3-11 | B33: Any ice used for cooling produce is | K33: 10 | O33: R
B34: manufactured, transported and stored under
B35: sanitary conditions.
A36: Packing House Worker Health & Hygiene
A37: Questions | K37: Points | L37: Yes | M37: NO | N37: N/A | O37: Doc
A38: 3-12 | B38: Employee facilities (locker rooms, lunch and | K38: 10
B39: break areas, etc.) are clean and located away
B40: from packing area.
...

Sheet Part 4-Storage & Transportation
A1: Part 4 - STORAGE AND TRANSPORTATION
A2: Product, Containers & Pallets
A3: Questions | K3: Points | L3: Yes | M3: NO | N3: N/A | O3: Doc
A4: 4-1 | B4: The storage facility is cleaned and maintained in | K4: 5
B5: an orderly manner.
A6: 4-2 | B6: Bulk storage facilities are inspected for foreign | K6: 5 | O6: R
B7: material prior to use and records are maintained.
A8: 4-3 | B8: Storage rooms, buildings, and/or facilities are | K8: 10
B9: maintained and sufficiently sealed or isolated
B10: and are protected from external contamination.
A11: 4-4 | B11: Storage grounds are reasonably free of litter | K11: 5
B12: and debris.
A13: 4-5 | B13: Floors in storage areas are reasonably | K13: 5
B14: free of standing water.
A15: 4-6 | B15: Possible wastewater spillage is prevented from | K15: 10
B16: contaminating any food handling area by
B17: barriers, drains, or sufficient distance.
A18: 4-7 | B18: There is a policy describing procedures which | K18: 15 | O18: P
B19: specify handling/disposition of finished product
B20: which is opened, spilled, or comes into contact
B21: with the floor.
A22: 4-8 | B22: Packing containers are properly stored and | K22: 10
B23: sufficiently sealed, to be protected from
B24: contamination (birds, rodents, pests, and other
B25: contaminants).
A26: 4-9 | B26: Pallets, pallet boxes, tote bags, and portable | K26: 5
B27: bins, etc. are clean, in good condition and do
B28: not contribute foreign material to the product.
A29: 4-10 | B29: Product stored outside in totes, trucks, bins, | K29: 10
B30: other containers or on the ground in bulk is
B31: covered and protected from contamination.
A32: 4-11 | B32: Non-food grade substances such as paints, | K32: 10
B33: lubricants, pesticides, etc., are not stored in
B34: close proximity to the product.
A35: 4-12 | B35: Mechanical equipment used during the storage | K35: 5 | O35: D
B36: process is clean and maintained to prevent
B37: contamination of the product.
A38: Pest Control
A39: Questions | K39: Points | L39: Yes | M39: NO | N39: N/A | O39: Doc
A40: 4-13 | B40: Measures are taken to exclude animals or pests | K40: 10 | O40: D
...

Sheet Part 6-Wholesale Distribution
A1: Part 6-Wholesale Distribution Center/Terminal Warehouses
A2: Receiving
A3: Questions | K3: Points | L3: Yes | M3: NO | N3: N/A | O3: Doc
A4: 6-1 | B4: All companies that supply fresh produce are | K4: 15 | O4: D
B5: required to have passed a third party audit
B6: verification of GAP and/or GHP.
A7: 6-2 | B7: Upon receiving, conveyances are required to be | K7: 10 | O7: P
B8: clean, in good physical condition and free from
B9: obvious objectionable odors, dirt and/or debris
B10: at time of unloading.
A11: 6-3 | B11: Company does not accept produce items that | K11: 10 | O11: P
B12: are loaded with or are not protected from
B13: potentially contaminating products.
A14: 6-4 | B14: Refrigerated commodities are monitored for | K14: 5 | O14: R
B15: temperatures at the time of receiving.
A16: 6-5 | B16: The company has a written policy regarding the | K16: 5 | O16: P
B17: disposition of product when temperatures are
B18: not within the company's guidelines at the time
B19: of receiving.
A20: Storage Facility/Temperature Control
A21: Questions | K21: Points | L21: Yes | M21: NO | N21: N/A | O21: Doc
A22: 6-6 | B22: The facility is clean and maintained in an | K22: 5
B23: orderly manner.
A24: 6-7 | B24: Refrigerated rooms are monitored for | K24: 5 | O24: D
B25: temperature and logs are maintained.
A26: 6-8 | B26: Thermometer(s) are checked for accuracy and | K26: 5 | O26: D
B27: records are available for review.
A28: 6-9 | B28: Refrigeration system condensation does not | K28: 10
B29: come into contact with produce.
A30: 6-10 | B30: Refrigeration equipment (condensers, fans, | K30: 10 | O30: D
B31: etc.) is cleaned on a scheduled basis.
A32: 6-11 | B32: Iced product does not drip on pallets of | K32: 10
B33: produce stored below.
A34: 6-12 | B34: The water used for cooling/ice is potable. | K34: 10 | O34: R
A35: 6-13 | B35: Manufacturing, storage, and transportation | K35: 10 | O35: D
B36: facilities used in making and delivering ice used
B37: for cooling the product are sanitized on a
B38: scheduled basis.
A39: 6-14 | B39: There is a policy describing procedures which | K39: 15 | O39: P
B40: specify handling/disposition of finished product
...

Sheet Part 7-Preventive Food Defense
A1: Part 7 - Preventive Food Defense Procedures
A2: Based on the U.S. Food and Drug Administration’s Food Producers, Processors, and Transporters:
A3: Food Security Preventive Measure Guidance for Industry.
A4: Secure Employee/Visitor Procedures
A5: Questions | K5: Points | L5: Yes | M5: NO | N5: N/A | O5: Doc
A6: 7-1 | B6: The company has a documented food defense | K6: 5 | O6: D
B7: plan and a person has been designated to
B8: oversee it.
B9: Name:
A11: 7-2 | B11: Food defense training has been provided to all | K11: 5 | O11: D
B12: employees.
A13: 7-3 | B13: Employees are aware of whom in management | K13: 5
B14: they should contact about potential security
B15: problems/issues.
B16: Name of management representative:
A19: 7-4 | B19: Visitors are required to check in (showing | K19: 5 | O19: D
B20: proof of identity) and out, when
B21: entering/leaving the facility.
A22: 7-5 | B22: The purpose of visitation to site is verified | K22: 5 | O22: D
B23: before admittance to the facility.
A24: 7-6 | B24: Visitors are prohibited from the | K24: 5 | O24: D
B25: packing/storage areas unless accompanied by
B26: an employee.
A27: 7-7 | B27: Incoming and outgoing employee and visitor | K27: 5 | O27: D
B28: vehicles to and from the site are subject to
B29: inspection.
A30: 7-8 | B30: Parked vehicles belonging to employees and | K30: 5
B31: visitors display a decal or placard issued by
B32: the facility.
A33: 7-9 | B33: Staff is prohibited from bringing personal | K33: 5 | O33: D
B34: items into the handling or storage areas.
A35: 7-10 | B35: Staff access in the facility is limited to the area | K35: 5 | O35: D
B36: of their job function and unrestricted areas.
A37: 7-11 | B37: Management is aware of which employee | K37: 5 | O37: D
B38: should be on the premises, and the area
B39: they are assigned to.
A40: 7-12 | B40: A system of positive identification of | K40: 5
B41: employees has been established and is
B42: enforced.
A43: Secure Facility Procedures
...

Sheet Audit Scoresheet
A1: United States Department of Agriculture | F1: Good Agricultural Practices & Good Handling Practices
A2: Agricultural Marketing Services | F2: Audit Verification Program Scoresheet www.ams.usda.gov/gapghp
A3: Fresh Products Branch
A4: Facility Name (Print) as it should appear on Certificate:
C5: ='Page 1-3'!D17 -> 0
A6: Street Address (Print): | H6: City (Print): | Q6: State (Print): | T6: Zip (Print):
A7: ='Page 1-3'!D20 -> 0 | H7: ='Page 1-3'!B21 -> 0 | Q7: ='Page 1-3'!H21 -> 0 | T7: ='Page 1-3'!M21 -> 0
A8: e-mail Address (Print): | H8: fax number: | Q8: Date Audit Requested:
A9: ='Page 1-3'!C23 -> 0 | H9: ='Page 1-3'!J22 -> 0 | Q9: Date of Previous Audit :
A10: Date Audit Began: | C10: ='Page 1-3'!E27 -> 0 | I10: Date Audit Completed: | M10: ='Page 1-3'!E28 -> 0 | Q10: USDA Commodity Procurement Audit?
A11: Time Audit Began: | C11: ='Page 1-3'!J27 -> 0 | I11: Time Audit Completed: | M11: ='Page 1-3'!J28 -> 0 | Q11: Check One | S11: Yes | U11: No
A13: EVALUATION ELEMENTS
A14: Scopes | B14: Element | F14: Possible | G14: Less N/A | I14: Adjusted | K14: Passing | M14: Facility | N14: Pass | P14: Date | R14: General | T14: Reviewing | W14: Un-announced
A15: Requested | F15: Points | G15: Points | I15: Points | K15: Score* | M15: Score | N15: Fail | P15: Passed | R15: Questions | T15: Official
A16: X | B16: General Questions | F16: 180 | G16: ='Pg. 4 General Questions'!E92 -> 0 | I16: ='Pg. 4 General Questions'!E93 -> 180 | K16: ='Pg. 4 General Questions'!E95 -> 144 | M16: ='Pg. 4 General Questions'!J90 -> 0
A17: ='Page 1-3'!P58 -> 0 | B17: Part 1 – Farm Review | F17: 190 | G17: ='Part 1-Farm Review'!E131 -> 0 | I17: ='Part 1-Farm Review'!E132 -> 190 | K17: ='Part 1-Farm Review'!E134 -> 152 | M17: ='Part 1-Farm Review'!J129 -> 0
A18: ='Page 1-3'!P60 -> 0 | B18: Part 2 – Field Harvesting & Field | F18: 185 | G18: ='Part 2-Field Harvest & Packing '!E99 -> 0 | I18: ='Part 2-Field Harvest & Packing '!E100 -> 185 | K18: ='Part 2-Field Harvest & Packing '!E102 -> 148 | M18: ='Part 2-Field Harvest & Packing '!J97 -> 0
B19: Packing Activities
A20: ='Page 1-3'!P62 -> 0 | B20: Part 3 – House Packing Facility | F20: 290 | G20: ='Part 3-House Packing Facilty'!E129 -> 0 | I20: ='Part 3-House Packing Facilty'!E130 -> 290 | K20: ='Part 3-House Packing Facilty'!E132 -> 232 | M20: ='Part 3-House Packing Facilty'!J127 -> 0
A21: ='Page 1-3'!P64 -> 0 | B21: Part 4 – Storage and | F21: 255 | G21: ='Part 4-Storage & Transportation'!E128 -> 0 | I21: ='Part 4-Storage & Transportation'!E129 -> 255 | K21: ='Part 4-Storage & Transportation'!E131 -> 204 | M21: ='Part 4-Storage & Transportation'!J126 -> 0
B22: Transportation
A23: ='Page 1-3'!P68 -> 0 | B23: Part 6 – Wholesale Distribution | F23: 410 | G23: ='Part 6-Wholesale Distribution'!E176 -> 0 | I23: ='Part 6-Wholesale Distribution'!E177 -> 410 | K23: ='Part 6-Wholesale Distribution'!E179 -> 328 | M23: ='Part 6-Wholesale Distribution'!J174 -> 0
B24: Center/ Warehouses
A25: ='Page 1-3'!P70 -> 0 | B25: Part 7 – Preventative Food | F25: 180 | G25: ='Part 7-Preventive Food Defense'!E125 -> 0 | I25: ='Part 7-Preventive Food Defense'!E126 -> 180 | K25: ='Part 7-Preventive Food Defense'!E128 -> 144 | M25: ='Part 7-Preventive Food Defense'!J123 -> 0
B26: Defense Procedures
A27: **A Passing Score is 80% of the Possible Points or the Adjusted Points, if adjustment are necessary, with no "automatic unsatisfactory" conditions is required for certification.
A28: Commodities | C28: Commodity:
A30: Reviewed (Print): | C30: Acres:
A32: Send completed GAP&GHP Certificate to: (choose one) | G32: Inspection office: (list office) | Q32: Directly to auditee above:
A33: Lead Auditor Name (Print): | I33: Duty Station: | P33: Signature & Date:
A34: Facility Representative signature: | M34: Date: | R34: All Scopes Completed:
A36: By signing this form, the facility representative agrees to have company information posted to the USDA website. A company will only be listed on the USDA website if all scopes audited receive a passing score.
A37: For USDA HQ use:
A38: Reviewing Official Name (Print) | K38: Signature:
A39: Date Received: | D39: Date Certificate Mailed: | J39: Date Posted to USDA Website: | S39: Revised January 26, 2012
S40: USDA, AMS, FVP, FPB
A41: To verify a company's continued good standing in the USDA GAP&GHP Program please visit http://www.ams.usda.gov/gapghp | S41: For Official Government Use Only

Sheet CAR Duplication Instructions
A1: DUPLICATION OF CORRECTIVE ACTION TAB INSTRUCTIONS
A3: Any item on any checklist with a checkmark beside the Corrective Action Needed (CAN) box or the Immediate Action Required (IAR) box must be documented using a Corrective Action Report. A separate form is required for each item with either of these entities. If there is more than one form needed, follow the instructions below to duplicate the Corrective Action Report Tab:
B4: 1. Right-click the "Corrective Action Report" Tab at the bottom of Excel.
B6: 2. Click "Move or Copy.
B8: 3. Under the box titled "Before Sheet," select "(move to end)"
B10: 4. Place a check in the box beside "Create a Copy"
B12: 5. Click "Ok"

Sheet Corrective Action Report
A1: USDA Good Agricultural Practices and Good Handling Practices
A2: Corrective Action Report
A4: USDA Fruit and Vegetable Programs | F4: Report #:
A5: Good Agricultural Practice & Good Handling Practices | H5: of
A6: CORRECTIVE ACTION REPORT
A7: Company Name/Farm: | C7: ='Page 1-3'!D17 -> 0 | F7: Date:
A9: Lead Auditor:
A11: Crop(s):
A13: Description of Non-Conformity:
A21: Notified company staff at time of finding non-conformity:
A23: Checklist question number and/or section of auditee food safety plan non-conformity is associated with:
A25: Company Representative Signature:
C27: SIGNATURE AFFIRMS FACTS CONCERNING NON-CONFORMITY ARE CORRECT
A28: Corrective Action Proposed and Time Frame for Implementation:
A38: Auditor Signature for Acceptance of Proposed Corrective Action and Timetable for Implementation:
