Workbook

Sheet quick cross ref
A2: MEM® series - Wiring Accessories Product Changes
A3: Quick Cross Reference Lookup
A4: 1. Just punch in any part number to see if it has changed
A7: Punch in the old or new reference no. below | B7: Description | C7: Status | D7: The alternative or correct reference no. is: | E7: New (or replacement) Description | F7: Product Sector
B8: =VLOOKUP(A8,data!A:E,4,0) -> #N/A | C8: =VLOOKUP(A8,data!A:C,2,0) -> #N/A | D8: =VLOOKUP(A8,data!A:C,3,0) -> #N/A | E8: =VLOOKUP(A8,data!A:H,5,0) -> #N/A | F8: =VLOOKUP(A8,data!A:F,6,0) -> #N/A
B9: =VLOOKUP(A9,data!A:E,4,0) -> #N/A | C9: =VLOOKUP(A9,data!A:C,2,0) -> #N/A | D9: =VLOOKUP(A9,data!A:C,3,0) -> #N/A | E9: =VLOOKUP(A9,data!A:H,5,0) -> #N/A | F9: =VLOOKUP(A9,data!A:F,6,0) -> #N/A
B10: =VLOOKUP(A10,data!A:E,4,0) -> #N/A | C10: =VLOOKUP(A10,data!A:C,2,0) -> #N/A | D10: =VLOOKUP(A10,data!A:C,3,0) -> #N/A | E10: =VLOOKUP(A10,data!A:H,5,0) -> #N/A | F10: =VLOOKUP(A10,data!A:F,6,0) -> #N/A
B11: =VLOOKUP(A11,data!A:E,4,0) -> #N/A | C11: =VLOOKUP(A11,data!A:C,2,0) -> #N/A | D11: =VLOOKUP(A11,data!A:C,3,0) -> #N/A | E11: =VLOOKUP(A11,data!A:H,5,0) -> #N/A | F11: =VLOOKUP(A11,data!A:F,6,0) -> #N/A
B12: =VLOOKUP(A12,data!A:E,4,0) -> #N/A | C12: =VLOOKUP(A12,data!A:C,2,0) -> #N/A | D12: =VLOOKUP(A12,data!A:C,3,0) -> #N/A | E12: =VLOOKUP(A12,data!A:H,5,0) -> #N/A | F12: =VLOOKUP(A12,data!A:F,6,0) -> #N/A
B13: =VLOOKUP(A13,data!A:E,4,0) -> #N/A | C13: =VLOOKUP(A13,data!A:C,2,0) -> #N/A | D13: =VLOOKUP(A13,data!A:C,3,0) -> #N/A | E13: =VLOOKUP(A13,data!A:H,5,0) -> #N/A | F13: =VLOOKUP(A13,data!A:F,6,0) -> #N/A
B14: =VLOOKUP(A14,data!A:E,4,0) -> #N/A | C14: =VLOOKUP(A14,data!A:C,2,0) -> #N/A | D14: =VLOOKUP(A14,data!A:C,3,0) -> #N/A | E14: =VLOOKUP(A14,data!A:H,5,0) -> #N/A | F14: =VLOOKUP(A14,data!A:F,6,0) -> #N/A
B15: =VLOOKUP(A15,data!A:E,4,0) -> #N/A | C15: =VLOOKUP(A15,data!A:C,2,0) -> #N/A | D15: =VLOOKUP(A15,data!A:C,3,0) -> #N/A | E15: =VLOOKUP(A15,data!A:H,5,0) -> #N/A | F15: =VLOOKUP(A15,data!A:F,6,0) -> #N/A
B16: =VLOOKUP(A16,data!A:E,4,0) -> #N/A | C16: =VLOOKUP(A16,data!A:C,2,0) -> #N/A | D16: =VLOOKUP(A16,data!A:C,3,0) -> #N/A | E16: =VLOOKUP(A16,data!A:H,5,0) -> #N/A | F16: =VLOOKUP(A16,data!A:F,6,0) -> #N/A
B17: =VLOOKUP(A17,data!A:E,4,0) -> #N/A | C17: =VLOOKUP(A17,data!A:C,2,0) -> #N/A | D17: =VLOOKUP(A17,data!A:C,3,0) -> #N/A | E17: =VLOOKUP(A17,data!A:H,5,0) -> #N/A | F17: =VLOOKUP(A17,data!A:F,6,0) -> #N/A
B18: =VLOOKUP(A18,data!A:E,4,0) -> #N/A | C18: =VLOOKUP(A18,data!A:C,2,0) -> #N/A | D18: =VLOOKUP(A18,data!A:C,3,0) -> #N/A | E18: =VLOOKUP(A18,data!A:H,5,0) -> #N/A | F18: =VLOOKUP(A18,data!A:F,6,0) -> #N/A
B19: =VLOOKUP(A19,data!A:E,4,0) -> #N/A | C19: =VLOOKUP(A19,data!A:C,2,0) -> #N/A | D19: =VLOOKUP(A19,data!A:C,3,0) -> #N/A | E19: =VLOOKUP(A19,data!A:H,5,0) -> #N/A | F19: =VLOOKUP(A19,data!A:F,6,0) -> #N/A
... B31: =VLOOKUP(A31,data!A:E,4,0) -> #N/A | C31: =VLOOKUP(A31,data!A:C,2,0) -> #N/A | D31: =VLOOKUP(A31,data!A:C,3,0) -> #N/A | E31: =VLOOKUP(A31,data!A:H,5,0) -> #N/A | F31: =VLOOKUP(A31,data!A:F,6,0) -> #N/A

Sheet data
A1: Item No | B1: Status | C1: Replacement alternative Product | D1: Existing Item Description | E1: New Description | F1: Product sector | G1: pack qty | H1: T Price oct 04
A2: A015HP | B2: Being replaced by | C2: B015HP | D2: (F2465) 10A 1G SW PUSH HP | E2: 10A 1G SW PUSH HP | F2: COPA Wiring Accessories
A3: A015SB | B3: Being phased out - No direct replacement | C3: Use COPA SB | D3: (F2435) 10A 1G SW PUSH SB | F3: COPA Wiring Accessories
A4: A015SS | B4: Being replaced by | C4: B015SS | D4: (F2425) 10A 1G SW PUSH SS | E4: 10A 1G SW PUSH SS | F4: COPA Wiring Accessories
A5: A017HP | B5: Being replaced by | C5: B017HP | D5: (F2464) 10A INT SW HP | E5: 10A INT SW HP | F5: COPA Wiring Accessories
A6: A017SB | B6: Being phased out - No direct replacement | C6: Use COPA SB | D6: (F2434) 10A INT SW SB | F6: COPA Wiring Accessories
A7: A017SS | B7: Being replaced by | C7: B017SS | D7: (F2424) 10A INT SW SS | E7: 10A INT SW SS | F7: COPA Wiring Accessories
A8: A021HP | B8: Being replaced by | C8: B021HP | D8: (F2461) 10A 1G 2W SW HP | E8: 10A 1G 2W SW HP | F8: COPA Wiring Accessories
A9: A021SB | B9: Being phased out - No direct replacement | C9: Use COPA SB | D9: 10A 1G 2W SW SB | F9: COPA Wiring Accessories
A10: A021SS | B10: Being replaced by | C10: B021SS | D10: 10A 1G 2W SW SS | E10: 10A 1G 2W SW SS | F10: COPA Wiring Accessories
A11: A022HP | B11: Being replaced by | C11: B022HP | D11: (F2462) 10A 2G 2W SW HP | E11: 10A 2G 2W SW HP | F11: COPA Wiring Accessories
A12: A022SB | B12: Being phased out - No direct replacement | C12: Use COPA SB | D12: 10A 2G 2W SW SB | F12: COPA Wiring Accessories
A13: A022SS | B13: Being replaced by | C13: B022SS | D13: 10A 2G 2W SW SS | E13: 10A 2G 2W SW SS | F13: COPA Wiring Accessories
A14: A023HP | B14: Being replaced by | C14: B023HP | D14: (F2463) 10A 3G 2W SW HP | E14: 10A 3G 2W SW HP | F14: COPA Wiring Accessories
A15: A023SB | B15: Being phased out - No direct replacement | C15: Use COPA SB | D15: 10A 3G 2W SW SB | F15: COPA Wiring Accessories
A16: A023SS | B16: Being replaced by | C16: B023SS | D16: (F2423) 10A 3G 2W SW SS | E16: 10A 3G 2W SW SS | F16: COPA Wiring Accessories
A17: A041HP | B17: Being phased out - No direct replacement | C17: Use COPA HP | D17: (F2870) 10A 1G 2W BRDSW HP | F17: COPA Wiring Accessories
A18: A041SS | B18: Being phased out - No direct replacement | C18: Use COPA SS | D18: (F2850) 10A 1G 2W BRDSW SS | F18: COPA Wiring Accessories
A19: A048HP | B19: Being replaced by | C19: B048HP | D19: (F2876) 10A 3POLE FAN ISO HP | E19: 10A 3POLE FAN ISO HP | F19: COPA Wiring Accessories
A20: A048SB | B20: Being phased out - No direct replacement | C20: Use COPA SB | D20: (F2866) 10A 3POLE FAN ISO SB | F20: COPA Wiring Accessories
A21: A048SS | B21: Being replaced by | C21: B048SS | D21: (F2856) 10A 3POLE FAN ISO SS | E21: 10A 3POLE FAN ISO SS | F21: COPA Wiring Accessories
A22: A111HP | B22: Being phased out - No direct replacement | C22: Use COPA HP | D22: (F3051) 13A 1G SKT HP | F22: COPA Wiring Accessories
A23: A111SS | B23: Being replaced by | C23: B111SS | D23: (F3021) 13A 1G SKT SS | E23: 13A 1G SKT SS | F23: COPA Wiring Accessories
A24: A112HP | B24: Being phased out - No direct replacement | C24: Use COPA HP | D24: (F3052) 13A 2G SKT HP | F24: COPA Wiring Accessories
A25: A112SS | B25: Being replaced by | C25: B112SS | D25: (F3022) 13A 2G SKT SS | E25: 13A 2G SKT SS | F25: COPA Wiring Accessories
A26: A200HP | B26: Being phased out - No direct replacement | C26: Use COPA HP | D26: (FM3273) 13A CON UNIT HP | F26: COPA Wiring Accessories
A27: A200NHP | B27: Being phased out - No direct replacement | C27: Use COPA HP | D27: (FM3277) 13A CON UNIT NEON HP | F27: COPA Wiring Accessories
A28: A200NRRSS | B28: Being phased out - No direct replacement | C28: No equivalent | D28: 13A FUSED CONN UNIT CW NEON OP | F28: Aura Flush metal
A29: A200NSB | B29: Being phased out - No direct replacement | C29: Use COPA SB | D29: (FM3236) 13A CON UNIT NEON SB | F29: COPA Wiring Accessories
A30: A200NSS | B30: Being replaced by | C30: B220NSS | D30: (FM3227) 13A CON UNIT NEON SS | E30: 13A CON UNIT NEON SS | F30: COPA Wiring Accessories
A31: A200RRSS | B31: Being phased out - No direct replacement | C31: Use COPA SS | D31: 13A CON UNIT RED FUSE DRAW SS | F31: COPA Wiring Accessories
A32: A200SB | B32: Being phased out - No direct replacement | C32: Use COPA SB | D32: (FM3263) 13A CON UNIT NEON SB | F32: COPA Wiring Accessories
A33: A200SS | B33: Being replaced by | C33: B220SS | D33: (FM3222) 13A CON UNIT SS | E33: 13A CON UNIT SS | F33: COPA Wiring Accessories
A34: A201HP | B34: Being replaced by | C34: B221HP | D34: (FM3271) 13A SW CON UNIT HP | E34: 13A SW CON UNIT HP | F34: COPA Wiring Accessories
A35: A201NHP | B35: Being replaced by | C35: B221NHP | D35: (FM3274) 13A SW FCU NEON HP | E35: 13A SW FCU NEON HP | F35: COPA Wiring Accessories
A36: A201NRRSS | B36: Being phased out - No direct replacement | C36: Use COPA SS | D36: 13A SW CONN UNIT NEON RR SS | F36: COPA Wiring Accessories
A37: A201NSB | B37: Being phased out - No direct replacement | C37: Use COPA SB | D37: (FM3234) 13A SW FCU NEON SB | F37: COPA Wiring Accessories
A38: A201NSS | B38: Being replaced by | C38: B221NSS | D38: 13A SW FCU NEON SS | E38: 13A SW FCU NEON SS | F38: COPA Wiring Accessories
A39: A201RRSS | B39: Being phased out - No direct replacement | C39: Use COPA SS | D39: 13A SW CONN UNIT RR SS | F39: COPA Wiring Accessories
A40: A201SB | B40: Being phased out - No direct replacement | C40: Use COPA SB | D40: 13A SW CON UNIT SB | F40: COPA Wiring Accessories
...
