Workbook

Sheet Instructions
B1: Academic Planner and GPA Calculator
B2: The Academic Planner and GPA Calculator is designed to aid in plotting your course for your academic career and tracking your progress toward your goal of graduation. You can use this tool to plan courses for your degree and major. You can add courses for a minor if you decide you want to pursue one.
B4: Please note that this calculator reflects the latest grading policy which includes pluses and minuses for each letter grade. For calulating GPA prior to the 2014 grading policy, please contact your academic advisor.
B6: DIRECTIONS:
B7: To ensure you have a copy, be sure to save the file to your computer.
B8: - Select a term (Fall, Spring, or Summer) from the drop-down menu
B9: - Enter the year for that term
B10: - Fill in the Course prefix (PHY, CHE, etc.) and number (1305, 3304, etc.)
B11: - Fill in the number of credit hours for that course (This is the second digit of the course number).
B12: - Enter the grade you received or plan on receiving for the course.
B13: - Enter an "X” under Transfer if credit was received from an exam (AP, SAT II, CLEP, etc.) or was taken from another college.
B14: - If the course is a required course for your major, place an “X” under the Major column
... B32: If you have any questions or concerns with the GPA, academic planning, or filling out the GPA calculator, contact your academic advisor.

Sheet GPA Calculator
A1: Academic Planner and GPA Calculator | AA1: Semesters
A3: Term: | D3: Year: | K3: Term: | N3: Year: | AA3: Fall
A4: Prefix | B4: No. | C4: Course Title | D4: Hours | E4: Grade | F4: Points | G4: Transfer | H4: Major | I4: Replaced | K4: Prefix | L4: No. | M4: Course Title | N4: Hours | O4: Grade | P4: Points | Q4: Transfer | R4: Major | S4: Replaced | AA4: Spring
F5: ='GPA Formulas'!E5 | P5: ='GPA Formulas'!W5 | AA5: Summer
F6: ='GPA Formulas'!E6 | P6: ='GPA Formulas'!W6
F7: ='GPA Formulas'!E7 | P7: ='GPA Formulas'!W7
F8: ='GPA Formulas'!E8 | P8: ='GPA Formulas'!W8
F9: ='GPA Formulas'!E9 | P9: ='GPA Formulas'!W9
F10: ='GPA Formulas'!E10 | P10: ='GPA Formulas'!W10
F11: ='GPA Formulas'!E11 | P11: ='GPA Formulas'!W11
F12: ='GPA Formulas'!E12 | P12: ='GPA Formulas'!W12
F13: ='GPA Formulas'!E13 | P13: ='GPA Formulas'!W13
C14: Term Totals | D14: =SUM(D5:D13) -> 0 | F14: =SUM(F5:F13) -> 0 | M14: Term Totals | N14: =SUM(N5:N13) -> 0 | P14: =SUM(P5:P13) -> 0
C15: Term GPA | D15: =IF('GPA Formulas'!L14=0,"",'GPA Formulas'!M15) | M15: Term GPA | N15: =IF('GPA Formulas'!AD14=0,"",'GPA Formulas'!AE15)
C16: Baylor GPA | D16: =IF('GPA Formulas'!N14=0,"",'GPA Formulas'!O15) | M16: Baylor GPA | N16: =IF('GPA Formulas'!AF14=0,"",'GPA Formulas'!AG15)
C17: BCMP GPA | D17: =IF('BCMP GPA Calc'!E11=0,"",'BCMP GPA Calc'!E11) | M17: BCMP GPA | N17: =IF('BCMP GPA Calc'!L11=0,"",'BCMP GPA Calc'!L11)
C18: Major GPA | D18: =IF('GPA Formulas'!P14=0,"",'GPA Formulas'!Q15) | M18: Major GPA | N18: =IF('GPA Formulas'!AH14=0,"",'GPA Formulas'!AI15)
A20: Term: | D20: Year: | K20: Term: | N20: Year:
A21: Prefix | B21: No. | C21: Course Title | D21: Hours | E21: Grade | F21: Points | G21: Transfer | H21: Major | I21: Replaced | K21: Prefix | L21: No. | M21: Course Title | N21: Hours | O21: Grade | P21: Points | Q21: Transfer | R21: Major | S21: Replaced | AA21: Spring
F22: ='GPA Formulas'!E21 | P22: ='GPA Formulas'!W21
F23: ='GPA Formulas'!E22 | P23: ='GPA Formulas'!W22
F24: ='GPA Formulas'!E23 | P24: ='GPA Formulas'!W23
F25: ='GPA Formulas'!E24 | P25: ='GPA Formulas'!W24
F26: ='GPA Formulas'!E25 | P26: ='GPA Formulas'!W25
F27: ='GPA Formulas'!E26 | P27: ='GPA Formulas'!W26
F28: ='GPA Formulas'!E27 | P28: ='GPA Formulas'!W27
F29: ='GPA Formulas'!E28 | P29: ='GPA Formulas'!W28
F30: ='GPA Formulas'!E29 | P30: ='GPA Formulas'!W29
C31: Term Totals | D31: =SUM(D22:D30) -> 0 | F31: =SUM(F22:F30) -> 0 | M31: Term Totals | N31: =SUM(N22:N30) -> 0 | P31: =SUM(P22:P30) -> 0
C32: Term GPA | D32: =IF('GPA Formulas'!L30=0,"",'GPA Formulas'!M31) | M32: Term GPA | N32: =IF('GPA Formulas'!AD30=0,"",'GPA Formulas'!AE31)
C33: Baylor GPA | D33: =IF('GPA Formulas'!N30=0,"",'GPA Formulas'!O31) | M33: Baylor GPA | N33: =IF('GPA Formulas'!AF30=0,"",'GPA Formulas'!AG31)
C34: BCMP GPA | D34: =IF('BCMP GPA Calc'!E27=0,"",'BCMP GPA Calc'!E27) | M34: BCMP GPA | N34: =IF('BCMP GPA Calc'!L27=0,"",'BCMP GPA Calc'!L27)
C35: Major GPA | D35: =IF('GPA Formulas'!P30=0,"",'GPA Formulas'!Q31) | M35: Major GPA | N35: =IF('GPA Formulas'!AH30=0,"",'GPA Formulas'!AI31)
A37: Term: | D37: Year: | K37: Term: | N37: Year:
A38: Prefix | B38: No. | C38: Course Title | D38: Hours | E38: Grade | F38: Points | G38: Transfer | H38: Major | I38: Replaced | K38: Prefix | L38: No. | M38: Course Title | N38: Hours | O38: Grade | P38: Points | Q38: Transfer | R38: Major | S38: Replaced | AA38: Spring
F46: ='GPA Formulas'!E44 | P46: ='GPA Formulas'!W44
F47: ='GPA Formulas'!E45 | P47: ='GPA Formulas'!W45
C48: Term Totals | D48: =SUM(D39:D47) -> 0 | E48: =SUM(E39:E47) -> 0 | F48: =SUM(F39:F47) -> 0 | M48: Term Totals | N48: =SUM(N39:N47) -> 0 | O48: =SUM(O39:O47) -> 0 | P48: =SUM(P39:P47) -> 0
C49: Term GPA | D49: =IF('GPA Formulas'!L46=0,"",'GPA Formulas'!M47) | M49: Term GPA | N49: =IF('GPA Formulas'!AD46=0,"",'GPA Formulas'!AE47)
C50: Baylor GPA | D50: =IF('GPA Formulas'!N46=0,"",'GPA Formulas'!O47) | M50: Baylor GPA | N50: =IF('GPA Formulas'!AF46=0,"",'GPA Formulas'!AG47)
...

Sheet GPA Formulas
AL1: Grades
AL2: A | AM2: 4
AL3: A- | AM3: 3.67
A4: Hours | B4: QHrs | C4: Grades | D4: Grd Pts | E4: Points | F4: TR | H4: MAJ | J4: RPL | L4: Ttl Hrs | M4: Ttl Pts | N4: BU Hrs | O4: BU Pts | P4: Major Hrs | Q4: Major Pts | S4: Hours | T4: QHrs | U4: Grades | V4: Grd Pts | W4: Points | X4: TR | Z4: MAJ | AB4: RPL | AD4: Ttl Hrs | AE4: Ttl Pts | AF4: BU Hrs | AG4: BU Pts | AH4: Major Hrs | AI4: Major Pts | AL4: B+ | AM4: 3.33
A5: ='GPA Calculator'!D5 -> 0 | B5: =IF('GPA Calculator'!E5="W",0,IF('GPA Calculator'!E5="P",0,IF('GPA Calculator'!E5="FA",0,IF('GPA Calculator'!E5="CR",0,IF('GPA Calculator'!E5="NC",0,IF('GPA Calculator'!E5="",0,A5)))))) -> 0 | C5: =IF('GPA Calculator'!E5="W",0,IF('GPA Calculator'!E5="P",0,IF('GPA Calculator'!E5="FA",0,IF('GPA Calculator'!E5="CR",0,IF('GPA Calculator'!E5="NC",0,IF('GPA Calculator'!E5="",0,'GPA Calculator'!E5)))))) -> 0 | D5: =IF(C5=0,0,VLOOKUP(C5,$AL$2:$AM$14,2,FALSE)) -> 0 | E5: =IF(D5=0,"",B5*D5) | F5: ='GPA Calculator'!G5 -> 0 | G5: =IF(F5=0,0,1) -> 0 | H5: ='GPA Calculator'!H5 -> 0 | I5: =IF(H5=0,0,1) -> 0 | J5: ='GPA Calculator'!I5 -> 0 | K5: =IF(J5=0,0,1) -> 0 | L5: =B5 -> 0 | M5: =E5 | N5: =IF(G5=1,"",IF(K5=1,"",B5)) -> 0 | O5: =IF(G5=1,"",IF(K5=1,"",E5)) | P5: =IF(G5=1,"",IF(K5=1,"",IF(I5=0,"",B5))) | Q5: =IF(G5=1,"",IF(K5=1,"",IF(I5=0,"",E5))) | S5: ='GPA Calculator'!N5 -> 0 | T5: =IF('GPA Calculator'!O5="DP",0,IF('GPA Calculator'!O5="WP",0,IF('GPA Calculator'!O5="P",0,IF('GPA Calculator'!O5="FA",0,IF('GPA Calculator'!O5="CR",0,IF('GPA Calculator'!O5="NC",0,IF('GPA Calculator'!O5="",0,S5))))))) -> 0 | U5: =IF('GPA Calculator'!O5="W",0,IF('GPA Calculator'!O5="P",0,IF('GPA Calculator'!O5="FA",0,IF('GPA Calculator'!O5="CR",0,IF('GPA Calculator'!O5="NC",0,IF('GPA Calculator'!O5="",0,'GPA Calculator'!O5)))))) -> 0 | V5: =IF(U5=0,0,VLOOKUP(U5,$AL$2:$AM$14,2,FALSE)) -> 0 | W5: =IF(V5=0,"",T5*V5) | X5: ='GPA Calculator'!Q5 -> 0 | Y5: =IF(X5=0,0,1) -> 0 | Z5: ='GPA Calculator'!R5 -> 0 | AA5: =IF(Z5=0,0,1) -> 0 | AB5: ='GPA Calculator'!S5 -> 0 | AC5: =IF(AB5=0,0,1) -> 0 | AD5: =T5 -> 0 | AE5: =W5 | AF5: =IF(Y5=1,"",IF(AC5=1,"",T5)) -> 0 | AG5: =IF(Y5=1,"",IF(AC5=1,"",W5)) | AH5: =IF(Y5=1,"",IF(AC5=1,"",IF(AA5=0,"",T5))) | AI5: =IF(Y5=1,"",IF(AC5=1,"",IF(AA5=0,"",W5))) | AL5: B | AM5: 3
A6: ='GPA Calculator'!D6 -> 0 | B6: =IF('GPA Calculator'!E6="W",0,IF('GPA Calculator'!E6="P",0,IF('GPA Calculator'!E6="FA",0,IF('GPA Calculator'!E6="CR",0,IF('GPA Calculator'!E6="NC",0,IF('GPA Calculator'!E6="",0,A6)))))) -> 0 | C6: =IF('GPA Calculator'!E6="W",0,IF('GPA Calculator'!E6="P",0,IF('GPA Calculator'!E6="FA",0,IF('GPA Calculator'!E6="CR",0,IF('GPA Calculator'!E6="NC",0,IF('GPA Calculator'!E6="",0,'GPA Calculator'!E6)))))) -> 0 | D6: =IF(C6=0,0,VLOOKUP(C6,$AL$2:$AM$14,2,FALSE)) -> 0 | E6: =IF(D6=0,"",B6*D6) | F6: ='GPA Calculator'!G6 -> 0 | G6: =IF(F6=0,0,1) -> 0 | H6: ='GPA Calculator'!H6 -> 0 | I6: =IF(H6=0,0,1) -> 0 | J6: ='GPA Calculator'!I6 -> 0 | K6: =IF(J6=0,0,1) -> 0 | L6: =B6 -> 0 | M6: =E6 | N6: =IF(G6=1,"",IF(K6=1,"",B6)) -> 0 | O6: =IF(G6=1,"",IF(K6=1,"",E6)) | P6: =IF(G6=1,"",IF(K6=1,"",IF(I6=0,"",B6))) | Q6: =IF(G6=1,"",IF(K6=1,"",IF(I6=0,"",E6))) | S6: ='GPA Calculator'!N6 -> 0 | T6: =IF('GPA Calculator'!O6="DP",0,IF('GPA Calculator'!O6="WP",0,IF('GPA Calculator'!O6="P",0,IF('GPA Calculator'!O6="FA",0,IF('GPA Calculator'!O6="CR",0,IF('GPA Calculator'!O6="NC",0,IF('GPA Calculator'!O6="",0,S6))))))) -> 0 | U6: =IF('GPA Calculator'!O6="W",0,IF('GPA Calculator'!O6="P",0,IF('GPA Calculator'!O6="FA",0,IF('GPA Calculator'!O6="CR",0,IF('GPA Calculator'!O6="NC",0,IF('GPA Calculator'!O6="",0,'GPA Calculator'!O6)))))) -> 0 | V6: =IF(U6=0,0,VLOOKUP(U6,$AL$2:$AM$14,2,FALSE)) -> 0 | W6: =IF(V6=0,"",T6*V6) | X6: ='GPA Calculator'!Q6 -> 0 | Y6: =IF(X6=0,0,1) -> 0 | Z6: ='GPA Calculator'!R6 -> 0 | AA6: =IF(Z6=0,0,1) -> 0 | AB6: ='GPA Calculator'!S6 -> 0 | AC6: =IF(AB6=0,0,1) -> 0 | AD6: =T6 -> 0 | AE6: =W6 | AF6: =IF(Y6=1,"",IF(AC6=1,"",T6)) -> 0 | AG6: =IF(Y6=1,"",IF(AC6=1,"",W6)) | AH6: =IF(Y6=1,"",IF(AC6=1,"",IF(AA6=0,"",T6))) | AI6: =IF(Y6=1,"",IF(AC6=1,"",IF(AA6=0,"",W6))) | AL6: B- | AM6: 2.67
A7: ='GPA Calculator'!D7 -> 0 | B7: =IF('GPA Calculator'!E7="W",0,IF('GPA Calculator'!E7="P",0,IF('GPA Calculator'!E7="FA",0,IF('GPA Calculator'!E7="CR",0,IF('GPA Calculator'!E7="NC",0,IF('GPA Calculator'!E7="",0,A7)))))) -> 0 | C7: =IF('GPA Calculator'!E7="W",0,IF('GPA Calculator'!E7="P",0,IF('GPA Calculator'!E7="FA",0,IF('GPA Calculator'!E7="CR",0,IF('GPA Calculator'!E7="NC",0,IF('GPA Calculator'!E7="",0,'GPA Calculator'!E7)))))) -> 0 | D7: =IF(C7=0,0,VLOOKUP(C7,$AL$2:$AM$14,2,FALSE)) -> 0 | E7: =IF(D7=0,"",B7*D7) | F7: ='GPA Calculator'!G7 -> 0 | G7: =IF(F7=0,0,1) -> 0 | H7: ='GPA Calculator'!H7 -> 0 | I7: =IF(H7=0,0,1) -> 0 | J7: ='GPA Calculator'!I7 -> 0 | K7: =IF(J7=0,0,1) -> 0 | L7: =B7 -> 0 | M7: =E7 | N7: =IF(G7=1,"",IF(K7=1,"",B7)) -> 0 | O7: =IF(G7=1,"",IF(K7=1,"",E7)) | P7: =IF(G7=1,"",IF(K7=1,"",IF(I7=0,"",B7))) | Q7: =IF(G7=1,"",IF(K7=1,"",IF(I7=0,"",E7))) | S7: ='GPA Calculator'!N7 -> 0 | T7: =IF('GPA Calculator'!O7="DP",0,IF('GPA Calculator'!O7="WP",0,IF('GPA Calculator'!O7="P",0,IF('GPA Calculator'!O7="FA",0,IF('GPA Calculator'!O7="CR",0,IF('GPA Calculator'!O7="NC",0,IF('GPA Calculator'!O7="",0,S7))))))) -> 0 | U7: =IF('GPA Calculator'!O7="W",0,IF('GPA Calculator'!O7="P",0,IF('GPA Calculator'!O7="FA",0,IF('GPA Calculator'!O7="CR",0,IF('GPA Calculator'!O7="NC",0,IF('GPA Calculator'!O7="",0,'GPA Calculator'!O7)))))) -> 0 | V7: =IF(U7=0,0,VLOOKUP(U7,$AL$2:$AM$14,2,FALSE)) -> 0 | W7: =IF(V7=0,"",T7*V7) | X7: ='GPA Calculator'!Q7 -> 0 | Y7: =IF(X7=0,0,1) -> 0 | Z7: ='GPA Calculator'!R7 -> 0 | AA7: =IF(Z7=0,0,1) -> 0 | AB7: ='GPA Calculator'!S7 -> 0 | AC7: =IF(AB7=0,0,1) -> 0 | AD7: =T7 -> 0 | AE7: =W7 | AF7: =IF(Y7=1,"",IF(AC7=1,"",T7)) -> 0 | AG7: =IF(Y7=1,"",IF(AC7=1,"",W7)) | AH7: =IF(Y7=1,"",IF(AC7=1,"",IF(AA7=0,"",T7))) | AI7: =IF(Y7=1,"",IF(AC7=1,"",IF(AA7=0,"",W7))) | AL7: C+ | AM7: 2.33
A8: ='GPA Calculator'!D8 -> 0 | B8: =IF('GPA Calculator'!E8="W",0,IF('GPA Calculator'!E8="P",0,IF('GPA Calculator'!E8="FA",0,IF('GPA Calculator'!E8="CR",0,IF('GPA Calculator'!E8="NC",0,IF('GPA Calculator'!E8="",0,A8)))))) -> 0 | C8: =IF('GPA Calculator'!E8="W",0,IF('GPA Calculator'!E8="P",0,IF('GPA Calculator'!E8="FA",0,IF('GPA Calculator'!E8="CR",0,IF('GPA Calculator'!E8="NC",0,IF('GPA Calculator'!E8="",0,'GPA Calculator'!E8)))))) -> 0 | D8: =IF(C8=0,0,VLOOKUP(C8,$AL$2:$AM$14,2,FALSE)) -> 0 | E8: =IF(D8=0,"",B8*D8) | F8: ='GPA Calculator'!G8 -> 0 | G8: =IF(F8=0,0,1) -> 0 | H8: ='GPA Calculator'!H8 -> 0 | I8: =IF(H8=0,0,1) -> 0 | J8: ='GPA Calculator'!I8 -> 0 | K8: =IF(J8=0,0,1) -> 0 | L8: =B8 -> 0 | M8: =E8 | N8: =IF(G8=1,"",IF(K8=1,"",B8)) -> 0 | O8: =IF(G8=1,"",IF(K8=1,"",E8)) | P8: =IF(G8=1,"",IF(K8=1,"",IF(I8=0,"",B8))) | Q8: =IF(G8=1,"",IF(K8=1,"",IF(I8=0,"",E8))) | S8: ='GPA Calculator'!N8 -> 0 | T8: =IF('GPA Calculator'!O8="DP",0,IF('GPA Calculator'!O8="WP",0,IF('GPA Calculator'!O8="P",0,IF('GPA Calculator'!O8="FA",0,IF('GPA Calculator'!O8="CR",0,IF('GPA Calculator'!O8="NC",0,IF('GPA Calculator'!O8="",0,S8))))))) -> 0 | U8: =IF('GPA Calculator'!O8="W",0,IF('GPA Calculator'!O8="P",0,IF('GPA Calculator'!O8="FA",0,IF('GPA Calculator'!O8="CR",0,IF('GPA Calculator'!O8="NC",0,IF('GPA Calculator'!O8="",0,'GPA Calculator'!O8)))))) -> 0 | V8: =IF(U8=0,0,VLOOKUP(U8,$AL$2:$AM$14,2,FALSE)) -> 0 | W8: =IF(V8=0,"",T8*V8) | X8: ='GPA Calculator'!Q8 -> 0 | Y8: =IF(X8=0,0,1) -> 0 | Z8: ='GPA Calculator'!R8 -> 0 | AA8: =IF(Z8=0,0,1) -> 0 | AB8: ='GPA Calculator'!S8 -> 0 | AC8: =IF(AB8=0,0,1) -> 0 | AD8: =T8 -> 0 | AE8: =W8 | AF8: =IF(Y8=1,"",IF(AC8=1,"",T8)) -> 0 | AG8: =IF(Y8=1,"",IF(AC8=1,"",W8)) | AH8: =IF(Y8=1,"",IF(AC8=1,"",IF(AA8=0,"",T8))) | AI8: =IF(Y8=1,"",IF(AC8=1,"",IF(AA8=0,"",W8))) | AL8: C | AM8: 2
A9: ='GPA Calculator'!D9 -> 0 | B9: =IF('GPA Calculator'!E9="W",0,IF('GPA Calculator'!E9="P",0,IF('GPA Calculator'!E9="FA",0,IF('GPA Calculator'!E9="CR",0,IF('GPA Calculator'!E9="NC",0,IF('GPA Calculator'!E9="",0,A9)))))) -> 0 | C9: =IF('GPA Calculator'!E9="W",0,IF('GPA Calculator'!E9="P",0,IF('GPA Calculator'!E9="FA",0,IF('GPA Calculator'!E9="CR",0,IF('GPA Calculator'!E9="NC",0,IF('GPA Calculator'!E9="",0,'GPA Calculator'!E9)))))) -> 0 | D9: =IF(C9=0,0,VLOOKUP(C9,$AL$2:$AM$14,2,FALSE)) -> 0 | E9: =IF(D9=0,"",B9*D9) | F9: ='GPA Calculator'!G9 -> 0 | G9: =IF(F9=0,0,1) -> 0 | H9: ='GPA Calculator'!H9 -> 0 | I9: =IF(H9=0,0,1) -> 0 | J9: ='GPA Calculator'!I9 -> 0 | K9: =IF(J9=0,0,1) -> 0 | L9: =B9 -> 0 | M9: =E9 | N9: =IF(G9=1,"",IF(K9=1,"",B9)) -> 0 | O9: =IF(G9=1,"",IF(K9=1,"",E9)) | P9: =IF(G9=1,"",IF(K9=1,"",IF(I9=0,"",B9))) | Q9: =IF(G9=1,"",IF(K9=1,"",IF(I9=0,"",E9))) | S9: ='GPA Calculator'!N9 -> 0 | T9: =IF('GPA Calculator'!O9="DP",0,IF('GPA Calculator'!O9="WP",0,IF('GPA Calculator'!O9="P",0,IF('GPA Calculator'!O9="FA",0,IF('GPA Calculator'!O9="CR",0,IF('GPA Calculator'!O9="NC",0,IF('GPA Calculator'!O9="",0,S9))))))) -> 0 | U9: =IF('GPA Calculator'!O9="W",0,IF('GPA Calculator'!O9="P",0,IF('GPA Calculator'!O9="FA",0,IF('GPA Calculator'!O9="CR",0,IF('GPA Calculator'!O9="NC",0,IF('GPA Calculator'!O9="",0,'GPA Calculator'!O9)))))) -> 0 | V9: =IF(U9=0,0,VLOOKUP(U9,$AL$2:$AM$14,2,FALSE)) -> 0 | W9: =IF(V9=0,"",T9*V9) | X9: ='GPA Calculator'!Q9 -> 0 | Y9: =IF(X9=0,0,1) -> 0 | Z9: ='GPA Calculator'!R9 -> 0 | AA9: =IF(Z9=0,0,1) -> 0 | AB9: ='GPA Calculator'!S9 -> 0 | AC9: =IF(AB9=0,0,1) -> 0 | AD9: =T9 -> 0 | AE9: =W9 | AF9: =IF(Y9=1,"",IF(AC9=1,"",T9)) -> 0 | AG9: =IF(Y9=1,"",IF(AC9=1,"",W9)) | AH9: =IF(Y9=1,"",IF(AC9=1,"",IF(AA9=0,"",T9))) | AI9: =IF(Y9=1,"",IF(AC9=1,"",IF(AA9=0,"",W9))) | AL9: C- | AM9: 1.67
A10: ='GPA Calculator'!D10 -> 0 | B10: =IF('GPA Calculator'!E10="W",0,IF('GPA Calculator'!E10="P",0,IF('GPA Calculator'!E10="FA",0,IF('GPA Calculator'!E10="CR",0,IF('GPA Calculator'!E10="NC",0,IF('GPA Calculator'!E10="",0,A10)))))) -> 0 | C10: =IF('GPA Calculator'!E10="W",0,IF('GPA Calculator'!E10="P",0,IF('GPA Calculator'!E10="FA",0,IF('GPA Calculator'!E10="CR",0,IF('GPA Calculator'!E10="NC",0,IF('GPA Calculator'!E10="",0,'GPA Calculator'!E10)))))) -> 0 | D10: =IF(C10=0,0,VLOOKUP(C10,$AL$2:$AM$14,2,FALSE)) -> 0 | E10: =IF(D10=0,"",B10*D10) | F10: ='GPA Calculator'!G10 -> 0 | G10: =IF(F10=0,0,1) -> 0 | H10: ='GPA Calculator'!H10 -> 0 | I10: =IF(H10=0,0,1) -> 0 | J10: ='GPA Calculator'!I10 -> 0 | K10: =IF(J10=0,0,1) -> 0 | L10: =B10 -> 0 | M10: =E10 | N10: =IF(G10=1,"",IF(K10=1,"",B10)) -> 0 | O10: =IF(G10=1,"",IF(K10=1,"",E10)) | P10: =IF(G10=1,"",IF(K10=1,"",IF(I10=0,"",B10))) | Q10: =IF(G10=1,"",IF(K10=1,"",IF(I10=0,"",E10))) | S10: ='GPA Calculator'!N10 -> 0 | T10: =IF('GPA Calculator'!O10="DP",0,IF('GPA Calculator'!O10="WP",0,IF('GPA Calculator'!O10="P",0,IF('GPA Calculator'!O10="FA",0,IF('GPA Calculator'!O10="CR",0,IF('GPA Calculator'!O10="NC",0,IF('GPA Calculator'!O10="",0,S10))))))) -> 0 | U10: =IF('GPA Calculator'!O10="W",0,IF('GPA Calculator'!O10="P",0,IF('GPA Calculator'!O10="FA",0,IF('GPA Calculator'!O10="CR",0,IF('GPA Calculator'!O10="NC",0,IF('GPA Calculator'!O10="",0,'GPA Calculator'!O10)))))) -> 0 | V10: =IF(U10=0,0,VLOOKUP(U10,$AL$2:$AM$14,2,FALSE)) -> 0 | W10: =IF(V10=0,"",T10*V10) | X10: ='GPA Calculator'!Q10 -> 0 | Y10: =IF(X10=0,0,1) -> 0 | Z10: ='GPA Calculator'!R10 -> 0 | AA10: =IF(Z10=0,0,1) -> 0 | AB10: ='GPA Calculator'!S10 -> 0 | AC10: =IF(AB10=0,0,1) -> 0 | AD10: =T10 -> 0 | AE10: =W10 | AF10: =IF(Y10=1,"",IF(AC10=1,"",T10)) -> 0 | AG10: =IF(Y10=1,"",IF(AC10=1,"",W10)) | AH10: =IF(Y10=1,"",IF(AC10=1,"",IF(AA10=0,"",T10))) | AI10: =IF(Y10=1,"",IF(AC10=1,"",IF(AA10=0,"",W10))) | AL10: D+ | AM10: 1.33
A11: ='GPA Calculator'!D11 -> 0 | B11: =IF('GPA Calculator'!E11="W",0,IF('GPA Calculator'!E11="P",0,IF('GPA Calculator'!E11="FA",0,IF('GPA Calculator'!E11="CR",0,IF('GPA Calculator'!E11="NC",0,IF('GPA Calculator'!E11="",0,A11)))))) -> 0 | C11: =IF('GPA Calculator'!E11="W",0,IF('GPA Calculator'!E11="P",0,IF('GPA Calculator'!E11="FA",0,IF('GPA Calculator'!E11="CR",0,IF('GPA Calculator'!E11="NC",0,IF('GPA Calculator'!E11="",0,'GPA Calculator'!E11)))))) -> 0 | D11: =IF(C11=0,0,VLOOKUP(C11,$AL$2:$AM$14,2,FALSE)) -> 0 | E11: =IF(D11=0,"",B11*D11) | F11: ='GPA Calculator'!G11 -> 0 | G11: =IF(F11=0,0,1) -> 0 | H11: ='GPA Calculator'!H11 -> 0 | I11: =IF(H11=0,0,1) -> 0 | J11: ='GPA Calculator'!I11 -> 0 | K11: =IF(J11=0,0,1) -> 0 | L11: =B11 -> 0 | M11: =E11 | N11: =IF(G11=1,"",IF(K11=1,"",B11)) -> 0 | O11: =IF(G11=1,"",IF(K11=1,"",E11)) | P11: =IF(G11=1,"",IF(K11=1,"",IF(I11=0,"",B11))) | Q11: =IF(G11=1,"",IF(K11=1,"",IF(I11=0,"",E11))) | S11: ='GPA Calculator'!N11 -> 0 | T11: =IF('GPA Calculator'!O11="DP",0,IF('GPA Calculator'!O11="WP",0,IF('GPA Calculator'!O11="P",0,IF('GPA Calculator'!O11="FA",0,IF('GPA Calculator'!O11="CR",0,IF('GPA Calculator'!O11="NC",0,IF('GPA Calculator'!O11="",0,S11))))))) -> 0 | U11: =IF('GPA Calculator'!O11="W",0,IF('GPA Calculator'!O11="P",0,IF('GPA Calculator'!O11="FA",0,IF('GPA Calculator'!O11="CR",0,IF('GPA Calculator'!O11="NC",0,IF('GPA Calculator'!O11="",0,'GPA Calculator'!O11)))))) -> 0 | V11: =IF(U11=0,0,VLOOKUP(U11,$AL$2:$AM$14,2,FALSE)) -> 0 | W11: =IF(V11=0,"",T11*V11) | X11: ='GPA Calculator'!Q11 -> 0 | Y11: =IF(X11=0,0,1) -> 0 | Z11: ='GPA Calculator'!R11 -> 0 | AA11: =IF(Z11=0,0,1) -> 0 | AB11: ='GPA Calculator'!S11 -> 0 | AC11: =IF(AB11=0,0,1) -> 0 | AD11: =T11 -> 0 | AE11: =W11 | AF11: =IF(Y11=1,"",IF(AC11=1,"",T11)) -> 0 | AG11: =IF(Y11=1,"",IF(AC11=1,"",W11)) | AH11: =IF(Y11=1,"",IF(AC11=1,"",IF(AA11=0,"",T11))) | AI11: =IF(Y11=1,"",IF(AC11=1,"",IF(AA11=0,"",W11))) | AL11: D | AM11: 1
A12: ='GPA Calculator'!D12 -> 0 | B12: =IF('GPA Calculator'!E12="W",0,IF('GPA Calculator'!E12="P",0,IF('GPA Calculator'!E12="FA",0,IF('GPA Calculator'!E12="CR",0,IF('GPA Calculator'!E12="NC",0,IF('GPA Calculator'!E12="",0,A12)))))) -> 0 | C12: =IF('GPA Calculator'!E12="W",0,IF('GPA Calculator'!E12="P",0,IF('GPA Calculator'!E12="FA",0,IF('GPA Calculator'!E12="CR",0,IF('GPA Calculator'!E12="NC",0,IF('GPA Calculator'!E12="",0,'GPA Calculator'!E12)))))) -> 0 | D12: =IF(C12=0,0,VLOOKUP(C12,$AL$2:$AM$14,2,FALSE)) -> 0 | E12: =IF(D12=0,"",B12*D12) | F12: ='GPA Calculator'!G12 -> 0 | G12: =IF(F12=0,0,1) -> 0 | H12: ='GPA Calculator'!H12 -> 0 | I12: =IF(H12=0,0,1) -> 0 | J12: ='GPA Calculator'!I12 -> 0 | K12: =IF(J12=0,0,1) -> 0 | L12: =B12 -> 0 | M12: =E12 | N12: =IF(G12=1,"",IF(K12=1,"",B12)) -> 0 | O12: =IF(G12=1,"",IF(K12=1,"",E12)) | P12: =IF(G12=1,"",IF(K12=1,"",IF(I12=0,"",B12))) | Q12: =IF(G12=1,"",IF(K12=1,"",IF(I12=0,"",E12))) | S12: ='GPA Calculator'!N12 -> 0 | T12: =IF('GPA Calculator'!O12="DP",0,IF('GPA Calculator'!O12="WP",0,IF('GPA Calculator'!O12="P",0,IF('GPA Calculator'!O12="FA",0,IF('GPA Calculator'!O12="CR",0,IF('GPA Calculator'!O12="NC",0,IF('GPA Calculator'!O12="",0,S12))))))) -> 0 | U12: =IF('GPA Calculator'!O12="W",0,IF('GPA Calculator'!O12="P",0,IF('GPA Calculator'!O12="FA",0,IF('GPA Calculator'!O12="CR",0,IF('GPA Calculator'!O12="NC",0,IF('GPA Calculator'!O12="",0,'GPA Calculator'!O12)))))) -> 0 | V12: =IF(U12=0,0,VLOOKUP(U12,$AL$2:$AM$14,2,FALSE)) -> 0 | W12: =IF(V12=0,"",T12*V12) | X12: ='GPA Calculator'!Q12 -> 0 | Y12: =IF(X12=0,0,1) -> 0 | Z12: ='GPA Calculator'!R12 -> 0 | AA12: =IF(Z12=0,0,1) -> 0 | AB12: ='GPA Calculator'!S12 -> 0 | AC12: =IF(AB12=0,0,1) -> 0 | AD12: =T12 -> 0 | AE12: =W12 | AF12: =IF(Y12=1,"",IF(AC12=1,"",T12)) -> 0 | AG12: =IF(Y12=1,"",IF(AC12=1,"",W12)) | AH12: =IF(Y12=1,"",IF(AC12=1,"",IF(AA12=0,"",T12))) | AI12: =IF(Y12=1,"",IF(AC12=1,"",IF(AA12=0,"",W12))) | AL12: D- | AM12: 0.67
A13: ='GPA Calculator'!D13 -> 0 | B13: =IF('GPA Calculator'!E13="W",0,IF('GPA Calculator'!E13="P",0,IF('GPA Calculator'!E13="FA",0,IF('GPA Calculator'!E13="CR",0,IF('GPA Calculator'!E13="NC",0,IF('GPA Calculator'!E13="",0,A13)))))) -> 0 | C13: =IF('GPA Calculator'!E13="W",0,IF('GPA Calculator'!E13="P",0,IF('GPA Calculator'!E13="FA",0,IF('GPA Calculator'!E13="CR",0,IF('GPA Calculator'!E13="NC",0,IF('GPA Calculator'!E13="",0,'GPA Calculator'!E13)))))) -> 0 | D13: =IF(C13=0,0,VLOOKUP(C13,$AL$2:$AM$14,2,FALSE)) -> 0 | E13: =IF(D13=0,"",B13*D13) | F13: ='GPA Calculator'!G13 -> 0 | G13: =IF(F13=0,0,1) -> 0 | H13: ='GPA Calculator'!H13 -> 0 | I13: =IF(H13=0,0,1) -> 0 | J13: ='GPA Calculator'!I13 -> 0 | K13: =IF(J13=0,0,1) -> 0 | L13: =B13 -> 0 | M13: =E13 | N13: =IF(G13=1,"",IF(K13=1,"",B13)) -> 0 | O13: =IF(G13=1,"",IF(K13=1,"",E13)) | P13: =IF(G13=1,"",IF(K13=1,"",IF(I13=0,"",B13))) | Q13: =IF(G13=1,"",IF(K13=1,"",IF(I13=0,"",E13))) | S13: ='GPA Calculator'!N13 -> 0 | T13: =IF('GPA Calculator'!O13="DP",0,IF('GPA Calculator'!O13="WP",0,IF('GPA Calculator'!O13="P",0,IF('GPA Calculator'!O13="FA",0,IF('GPA Calculator'!O13="CR",0,IF('GPA Calculator'!O13="NC",0,IF('GPA Calculator'!O13="",0,S13))))))) -> 0 | U13: =IF('GPA Calculator'!O13="W",0,IF('GPA Calculator'!O13="P",0,IF('GPA Calculator'!O13="FA",0,IF('GPA Calculator'!O13="CR",0,IF('GPA Calculator'!O13="NC",0,IF('GPA Calculator'!O13="",0,'GPA Calculator'!O13)))))) -> 0 | V13: =IF(U13=0,0,VLOOKUP(U13,$AL$2:$AM$14,2,FALSE)) -> 0 | W13: =IF(V13=0,"",T13*V13) | X13: ='GPA Calculator'!Q13 -> 0 | Y13: =IF(X13=0,0,1) -> 0 | Z13: ='GPA Calculator'!R13 -> 0 | AA13: =IF(Z13=0,0,1) -> 0 | AB13: ='GPA Calculator'!S13 -> 0 | AC13: =IF(AB13=0,0,1) -> 0 | AD13: =T13 -> 0 | AE13: =W13 | AF13: =IF(Y13=1,"",IF(AC13=1,"",T13)) -> 0 | AG13: =IF(Y13=1,"",IF(AC13=1,"",W13)) | AH13: =IF(Y13=1,"",IF(AC13=1,"",IF(AA13=0,"",T13))) | AI13: =IF(Y13=1,"",IF(AC13=1,"",IF(AA13=0,"",W13))) | AL13: F | AM13: 0
B14: =SUM(B5:B13) -> 0 | E14: =SUM(E5:E13) -> 0 | L14: =SUM(L5:L13) -> 0 | M14: =SUM(M5:M13) -> 0 | N14: =SUM(N5:N13) -> 0 | O14: =SUM(O5:O13) -> 0 | P14: =SUM(P5:P13) -> 0 | Q14: =SUM(Q5:Q13) -> 0 | T14: =SUM(T5:T13) -> 0 | V14: =SUM(V5:V13) -> 0 | W14: =SUM(W5:W13) -> 0 | AD14: =SUM(AD5:AD13) -> 0 | AE14: =SUM(AE5:AE13) -> 0 | AF14: =SUM(AF5:AF13) -> 0 | AG14: =SUM(AG5:AG13) -> 0 | AH14: =SUM(AH5:AH13) -> 0 | AI14: =SUM(AI5:AI13) -> 0 | AL14: W | AM14: 0
L15: Term GPA | M15: =IF(L14=0,"",M14/L14) | N15: BU GPA | O15: =IF(N14=0,"",O14/N14) | P15: MAJ GPA | Q15: =IF(P14=0,"",Q14/P14) | AD15: Term GPA | AE15: =IF(AD14=0,"",AE14/AD14) | AF15: BU GPA | AG15: =IF(AF14=0,"",AG14/AF14) | AH15: MAJ GPA | AI15: =IF(AH14=0,"",AI14/AH14)
A20: Hours | B20: QHrs | C20: Grades | D20: Grd Pts | E20: Points | F20: TR | H20: MAJ | J20: RPL | L20: Ttl Hrs | M20: Ttl Pts | N20: BU Hrs | O20: BU Pts | P20: Major Hrs | Q20: Major Pts | S20: Hours | T20: QHrs | U20: Grades | V20: Grd Pts | W20: Points | X20: TR | Z20: MAJ | AB20: RPL | AD20: Ttl Hrs | AE20: Ttl Pts | AF20: BU Hrs | AG20: BU Pts | AH20: Major Hrs | AI20: Major Pts
A21: ='GPA Calculator'!D22 -> 0 | B21: =IF('GPA Calculator'!E22="W",0,IF('GPA Calculator'!E22="P",0,IF('GPA Calculator'!E22="FA",0,IF('GPA Calculator'!E22="CR",0,IF('GPA Calculator'!E22="NC",0,IF('GPA Calculator'!E22="",0,A21)))))) -> 0 | C21: =IF('GPA Calculator'!E22="W",0,IF('GPA Calculator'!E22="P",0,IF('GPA Calculator'!E22="FA",0,IF('GPA Calculator'!E22="CR",0,IF('GPA Calculator'!E22="NC",0,IF('GPA Calculator'!E22="",0,'GPA Calculator'!E22)))))) -> 0 | D21: =IF(C21=0,0,VLOOKUP(C21,$AL$2:$AM$14,2,FALSE)) -> 0 | E21: =IF(D21=0,"",B21*D21) | F21: ='GPA Calculator'!G22 -> 0 | G21: =IF(F21=0,0,1) -> 0 | H21: ='GPA Calculator'!H22 -> 0 | I21: =IF(H21=0,0,1) -> 0 | J21: ='GPA Calculator'!I22 -> 0 | K21: =IF(J21=0,0,1) -> 0 | L21: =B21 -> 0 | M21: =E21 | N21: =IF(G21=1,"",IF(K21=1,"",B21)) -> 0 | O21: =IF(G21=1,"",IF(K21=1,"",E21)) | P21: =IF(G21=1,"",IF(K21=1,"",IF(I21=0,"",B21))) | Q21: =IF(G21=1,"",IF(K21=1,"",IF(I21=0,"",E21))) | S21: ='GPA Calculator'!N22 -> 0 | T21: =IF('GPA Calculator'!O22="DP",0,IF('GPA Calculator'!O22="WP",0,IF('GPA Calculator'!O22="P",0,IF('GPA Calculator'!O22="FA",0,IF('GPA Calculator'!O22="CR",0,IF('GPA Calculator'!O22="NC",0,IF('GPA Calculator'!O22="",0,S21))))))) -> 0 | U21: =IF('GPA Calculator'!O22="W",0,IF('GPA Calculator'!O22="P",0,IF('GPA Calculator'!O22="FA",0,IF('GPA Calculator'!O22="CR",0,IF('GPA Calculator'!O22="NC",0,IF('GPA Calculator'!O22="",0,'GPA Calculator'!O22)))))) -> 0 | V21: =IF(U21=0,0,VLOOKUP(U21,$AL$2:$AM$14,2,FALSE)) -> 0 | W21: =IF(V21=0,"",T21*V21) | X21: ='GPA Calculator'!Q22 -> 0 | Y21: =IF(X21=0,0,1) -> 0 | Z21: ='GPA Calculator'!R22 -> 0 | AA21: =IF(Z21=0,0,1) -> 0 | AB21: ='GPA Calculator'!S22 -> 0 | AC21: =IF(AB21=0,0,1) -> 0 | AD21: =T21 -> 0 | AE21: =W21 | AF21: =IF(Y21=1,"",IF(AC21=1,"",T21)) -> 0 | AG21: =IF(Y21=1,"",IF(AC21=1,"",W21)) | AH21: =IF(Y21=1,"",IF(AC21=1,"",IF(AA21=0,"",T21))) | AI21: =IF(Y21=1,"",IF(AC21=1,"",IF(AA21=0,"",W21)))
A22: ='GPA Calculator'!D23 -> 0 | B22: =IF('GPA Calculator'!E23="DP",0,IF('GPA Calculator'!E23="WP",0,IF('GPA Calculator'!E23="P",0,IF('GPA Calculator'!E23="FA",0,IF('GPA Calculator'!E23="CR",0,IF('GPA Calculator'!E23="NC",0,IF('GPA Calculator'!E23="",0,A22))))))) -> 0 | C22: =IF('GPA Calculator'!E23="W",0,IF('GPA Calculator'!E23="P",0,IF('GPA Calculator'!E23="FA",0,IF('GPA Calculator'!E23="CR",0,IF('GPA Calculator'!E23="NC",0,IF('GPA Calculator'!E23="",0,'GPA Calculator'!E23)))))) -> 0 | D22: =IF(C22=0,0,VLOOKUP(C22,$AL$2:$AM$14,2,FALSE)) -> 0 | E22: =IF(D22=0,"",B22*D22) | F22: ='GPA Calculator'!G23 -> 0 | G22: =IF(F22=0,0,1) -> 0 | H22: ='GPA Calculator'!H23 -> 0 | I22: =IF(H22=0,0,1) -> 0 | J22: ='GPA Calculator'!I23 -> 0 | K22: =IF(J22=0,0,1) -> 0 | L22: =B22 -> 0 | M22: =E22 | N22: =IF(G22=1,"",IF(K22=1,"",B22)) -> 0 | O22: =IF(G22=1,"",IF(K22=1,"",E22)) | P22: =IF(G22=1,"",IF(K22=1,"",IF(I22=0,"",B22))) | Q22: =IF(G22=1,"",IF(K22=1,"",IF(I22=0,"",E22))) | S22: ='GPA Calculator'!N23 -> 0 | T22: =IF('GPA Calculator'!O23="DP",0,IF('GPA Calculator'!O23="WP",0,IF('GPA Calculator'!O23="P",0,IF('GPA Calculator'!O23="FA",0,IF('GPA Calculator'!O23="CR",0,IF('GPA Calculator'!O23="NC",0,IF('GPA Calculator'!O23="",0,S22))))))) -> 0 | U22: =IF('GPA Calculator'!O23="W",0,IF('GPA Calculator'!O23="P",0,IF('GPA Calculator'!O23="FA",0,IF('GPA Calculator'!O23="CR",0,IF('GPA Calculator'!O23="NC",0,IF('GPA Calculator'!O23="",0,'GPA Calculator'!O23)))))) -> 0 | V22: =IF(U22=0,0,VLOOKUP(U22,$AL$2:$AM$14,2,FALSE)) -> 0 | W22: =IF(V22=0,"",T22*V22) | X22: ='GPA Calculator'!Q23 -> 0 | Y22: =IF(X22=0,0,1) -> 0 | Z22: ='GPA Calculator'!R23 -> 0 | AA22: =IF(Z22=0,0,1) -> 0 | AB22: ='GPA Calculator'!S23 -> 0 | AC22: =IF(AB22=0,0,1) -> 0 | AD22: =T22 -> 0 | AE22: =W22 | AF22: =IF(Y22=1,"",IF(AC22=1,"",T22)) -> 0 | AG22: =IF(Y22=1,"",IF(AC22=1,"",W22)) | AH22: =IF(Y22=1,"",IF(AC22=1,"",IF(AA22=0,"",T22))) | AI22: =IF(Y22=1,"",IF(AC22=1,"",IF(AA22=0,"",W22)))
A23: ='GPA Calculator'!D24 -> 0 | B23: =IF('GPA Calculator'!E24="DP",0,IF('GPA Calculator'!E24="WP",0,IF('GPA Calculator'!E24="P",0,IF('GPA Calculator'!E24="FA",0,IF('GPA Calculator'!E24="CR",0,IF('GPA Calculator'!E24="NC",0,IF('GPA Calculator'!E24="",0,A23))))))) -> 0 | C23: =IF('GPA Calculator'!E24="W",0,IF('GPA Calculator'!E24="P",0,IF('GPA Calculator'!E24="FA",0,IF('GPA Calculator'!E24="CR",0,IF('GPA Calculator'!E24="NC",0,IF('GPA Calculator'!E24="",0,'GPA Calculator'!E24)))))) -> 0 | D23: =IF(C23=0,0,VLOOKUP(C23,$AL$2:$AM$14,2,FALSE)) -> 0 | E23: =IF(D23=0,"",B23*D23) | F23: ='GPA Calculator'!G24 -> 0 | G23: =IF(F23=0,0,1) -> 0 | H23: ='GPA Calculator'!H24 -> 0 | I23: =IF(H23=0,0,1) -> 0 | J23: ='GPA Calculator'!I24 -> 0 | K23: =IF(J23=0,0,1) -> 0 | L23: =B23 -> 0 | M23: =E23 | N23: =IF(G23=1,"",IF(K23=1,"",B23)) -> 0 | O23: =IF(G23=1,"",IF(K23=1,"",E23)) | P23: =IF(G23=1,"",IF(K23=1,"",IF(I23=0,"",B23))) | Q23: =IF(G23=1,"",IF(K23=1,"",IF(I23=0,"",E23))) | S23: ='GPA Calculator'!N24 -> 0 | T23: =IF('GPA Calculator'!O24="DP",0,IF('GPA Calculator'!O24="WP",0,IF('GPA Calculator'!O24="P",0,IF('GPA Calculator'!O24="FA",0,IF('GPA Calculator'!O24="CR",0,IF('GPA Calculator'!O24="NC",0,IF('GPA Calculator'!O24="",0,S23))))))) -> 0 | U23: =IF('GPA Calculator'!O24="W",0,IF('GPA Calculator'!O24="P",0,IF('GPA Calculator'!O24="FA",0,IF('GPA Calculator'!O24="CR",0,IF('GPA Calculator'!O24="NC",0,IF('GPA Calculator'!O24="",0,'GPA Calculator'!O24)))))) -> 0 | V23: =IF(U23=0,0,VLOOKUP(U23,$AL$2:$AM$14,2,FALSE)) -> 0 | W23: =IF(V23=0,"",T23*V23) | X23: ='GPA Calculator'!Q24 -> 0 | Y23: =IF(X23=0,0,1) -> 0 | Z23: ='GPA Calculator'!R24 -> 0 | AA23: =IF(Z23=0,0,1) -> 0 | AB23: ='GPA Calculator'!S24 -> 0 | AC23: =IF(AB23=0,0,1) -> 0 | AD23: =T23 -> 0 | AE23: =W23 | AF23: =IF(Y23=1,"",IF(AC23=1,"",T23)) -> 0 | AG23: =IF(Y23=1,"",IF(AC23=1,"",W23)) | AH23: =IF(Y23=1,"",IF(AC23=1,"",IF(AA23=0,"",T23))) | AI23: =IF(Y23=1,"",IF(AC23=1,"",IF(AA23=0,"",W23)))
A24: ='GPA Calculator'!D25 -> 0 | B24: =IF('GPA Calculator'!E25="DP",0,IF('GPA Calculator'!E25="WP",0,IF('GPA Calculator'!E25="P",0,IF('GPA Calculator'!E25="FA",0,IF('GPA Calculator'!E25="CR",0,IF('GPA Calculator'!E25="NC",0,IF('GPA Calculator'!E25="",0,A24))))))) -> 0 | C24: =IF('GPA Calculator'!E25="W",0,IF('GPA Calculator'!E25="P",0,IF('GPA Calculator'!E25="FA",0,IF('GPA Calculator'!E25="CR",0,IF('GPA Calculator'!E25="NC",0,IF('GPA Calculator'!E25="",0,'GPA Calculator'!E25)))))) -> 0 | D24: =IF(C24=0,0,VLOOKUP(C24,$AL$2:$AM$14,2,FALSE)) -> 0 | E24: =IF(D24=0,"",B24*D24) | F24: ='GPA Calculator'!G25 -> 0 | G24: =IF(F24=0,0,1) -> 0 | H24: ='GPA Calculator'!H25 -> 0 | I24: =IF(H24=0,0,1) -> 0 | J24: ='GPA Calculator'!I25 -> 0 | K24: =IF(J24=0,0,1) -> 0 | L24: =B24 -> 0 | M24: =E24 | N24: =IF(G24=1,"",IF(K24=1,"",B24)) -> 0 | O24: =IF(G24=1,"",IF(K24=1,"",E24)) | P24: =IF(G24=1,"",IF(K24=1,"",IF(I24=0,"",B24))) | Q24: =IF(G24=1,"",IF(K24=1,"",IF(I24=0,"",E24))) | S24: ='GPA Calculator'!N25 -> 0 | T24: =IF('GPA Calculator'!O25="DP",0,IF('GPA Calculator'!O25="WP",0,IF('GPA Calculator'!O25="P",0,IF('GPA Calculator'!O25="FA",0,IF('GPA Calculator'!O25="CR",0,IF('GPA Calculator'!O25="NC",0,IF('GPA Calculator'!O25="",0,S24))))))) -> 0 | U24: =IF('GPA Calculator'!O25="W",0,IF('GPA Calculator'!O25="P",0,IF('GPA Calculator'!O25="FA",0,IF('GPA Calculator'!O25="CR",0,IF('GPA Calculator'!O25="NC",0,IF('GPA Calculator'!O25="",0,'GPA Calculator'!O25)))))) -> 0 | V24: =IF(U24=0,0,VLOOKUP(U24,$AL$2:$AM$14,2,FALSE)) -> 0 | W24: =IF(V24=0,"",T24*V24) | X24: ='GPA Calculator'!Q25 -> 0 | Y24: =IF(X24=0,0,1) -> 0 | Z24: ='GPA Calculator'!R25 -> 0 | AA24: =IF(Z24=0,0,1) -> 0 | AB24: ='GPA Calculator'!S25 -> 0 | AC24: =IF(AB24=0,0,1) -> 0 | AD24: =T24 -> 0 | AE24: =W24 | AF24: =IF(Y24=1,"",IF(AC24=1,"",T24)) -> 0 | AG24: =IF(Y24=1,"",IF(AC24=1,"",W24)) | AH24: =IF(Y24=1,"",IF(AC24=1,"",IF(AA24=0,"",T24))) | AI24: =IF(Y24=1,"",IF(AC24=1,"",IF(AA24=0,"",W24)))
A25: ='GPA Calculator'!D26 -> 0 | B25: =IF('GPA Calculator'!E26="DP",0,IF('GPA Calculator'!E26="WP",0,IF('GPA Calculator'!E26="P",0,IF('GPA Calculator'!E26="FA",0,IF('GPA Calculator'!E26="CR",0,IF('GPA Calculator'!E26="NC",0,IF('GPA Calculator'!E26="",0,A25))))))) -> 0 | C25: =IF('GPA Calculator'!E26="W",0,IF('GPA Calculator'!E26="P",0,IF('GPA Calculator'!E26="FA",0,IF('GPA Calculator'!E26="CR",0,IF('GPA Calculator'!E26="NC",0,IF('GPA Calculator'!E26="",0,'GPA Calculator'!E26)))))) -> 0 | D25: =IF(C25=0,0,VLOOKUP(C25,$AL$2:$AM$14,2,FALSE)) -> 0 | E25: =IF(D25=0,"",B25*D25) | F25: ='GPA Calculator'!G26 -> 0 | G25: =IF(F25=0,0,1) -> 0 | H25: ='GPA Calculator'!H26 -> 0 | I25: =IF(H25=0,0,1) -> 0 | J25: ='GPA Calculator'!I26 -> 0 | K25: =IF(J25=0,0,1) -> 0 | L25: =B25 -> 0 | M25: =E25 | N25: =IF(G25=1,"",IF(K25=1,"",B25)) -> 0 | O25: =IF(G25=1,"",IF(K25=1,"",E25)) | P25: =IF(G25=1,"",IF(K25=1,"",IF(I25=0,"",B25))) | Q25: =IF(G25=1,"",IF(K25=1,"",IF(I25=0,"",E25))) | S25: ='GPA Calculator'!N26 -> 0 | T25: =IF('GPA Calculator'!O26="DP",0,IF('GPA Calculator'!O26="WP",0,IF('GPA Calculator'!O26="P",0,IF('GPA Calculator'!O26="FA",0,IF('GPA Calculator'!O26="CR",0,IF('GPA Calculator'!O26="NC",0,IF('GPA Calculator'!O26="",0,S25))))))) -> 0 | U25: =IF('GPA Calculator'!O26="W",0,IF('GPA Calculator'!O26="P",0,IF('GPA Calculator'!O26="FA",0,IF('GPA Calculator'!O26="CR",0,IF('GPA Calculator'!O26="NC",0,IF('GPA Calculator'!O26="",0,'GPA Calculator'!O26)))))) -> 0 | V25: =IF(U25=0,0,VLOOKUP(U25,$AL$2:$AM$14,2,FALSE)) -> 0 | W25: =IF(V25=0,"",T25*V25) | X25: ='GPA Calculator'!Q26 -> 0 | Y25: =IF(X25=0,0,1) -> 0 | Z25: ='GPA Calculator'!R26 -> 0 | AA25: =IF(Z25=0,0,1) -> 0 | AB25: ='GPA Calculator'!S26 -> 0 | AC25: =IF(AB25=0,0,1) -> 0 | AD25: =T25 -> 0 | AE25: =W25 | AF25: =IF(Y25=1,"",IF(AC25=1,"",T25)) -> 0 | AG25: =IF(Y25=1,"",IF(AC25=1,"",W25)) | AH25: =IF(Y25=1,"",IF(AC25=1,"",IF(AA25=0,"",T25))) | AI25: =IF(Y25=1,"",IF(AC25=1,"",IF(AA25=0,"",W25)))
A26: ='GPA Calculator'!D27 -> 0 | B26: =IF('GPA Calculator'!E27="DP",0,IF('GPA Calculator'!E27="WP",0,IF('GPA Calculator'!E27="P",0,IF('GPA Calculator'!E27="FA",0,IF('GPA Calculator'!E27="CR",0,IF('GPA Calculator'!E27="NC",0,IF('GPA Calculator'!E27="",0,A26))))))) -> 0 | C26: =IF('GPA Calculator'!E27="W",0,IF('GPA Calculator'!E27="P",0,IF('GPA Calculator'!E27="FA",0,IF('GPA Calculator'!E27="CR",0,IF('GPA Calculator'!E27="NC",0,IF('GPA Calculator'!E27="",0,'GPA Calculator'!E27)))))) -> 0 | D26: =IF(C26=0,0,VLOOKUP(C26,$AL$2:$AM$14,2,FALSE)) -> 0 | E26: =IF(D26=0,"",B26*D26) | F26: ='GPA Calculator'!G27 -> 0 | G26: =IF(F26=0,0,1) -> 0 | H26: ='GPA Calculator'!H27 -> 0 | I26: =IF(H26=0,0,1) -> 0 | J26: ='GPA Calculator'!I27 -> 0 | K26: =IF(J26=0,0,1) -> 0 | L26: =B26 -> 0 | M26: =E26 | N26: =IF(G26=1,"",IF(K26=1,"",B26)) -> 0 | O26: =IF(G26=1,"",IF(K26=1,"",E26)) | P26: =IF(G26=1,"",IF(K26=1,"",IF(I26=0,"",B26))) | Q26: =IF(G26=1,"",IF(K26=1,"",IF(I26=0,"",E26))) | S26: ='GPA Calculator'!N27 -> 0 | T26: =IF('GPA Calculator'!O27="DP",0,IF('GPA Calculator'!O27="WP",0,IF('GPA Calculator'!O27="P",0,IF('GPA Calculator'!O27="FA",0,IF('GPA Calculator'!O27="CR",0,IF('GPA Calculator'!O27="NC",0,IF('GPA Calculator'!O27="",0,S26))))))) -> 0 | U26: =IF('GPA Calculator'!O27="W",0,IF('GPA Calculator'!O27="P",0,IF('GPA Calculator'!O27="FA",0,IF('GPA Calculator'!O27="CR",0,IF('GPA Calculator'!O27="NC",0,IF('GPA Calculator'!O27="",0,'GPA Calculator'!O27)))))) -> 0 | V26: =IF(U26=0,0,VLOOKUP(U26,$AL$2:$AM$14,2,FALSE)) -> 0 | W26: =IF(V26=0,"",T26*V26) | X26: ='GPA Calculator'!Q27 -> 0 | Y26: =IF(X26=0,0,1) -> 0 | Z26: ='GPA Calculator'!R27 -> 0 | AA26: =IF(Z26=0,0,1) -> 0 | AB26: ='GPA Calculator'!S27 -> 0 | AC26: =IF(AB26=0,0,1) -> 0 | AD26: =T26 -> 0 | AE26: =W26 | AF26: =IF(Y26=1,"",IF(AC26=1,"",T26)) -> 0 | AG26: =IF(Y26=1,"",IF(AC26=1,"",W26)) | AH26: =IF(Y26=1,"",IF(AC26=1,"",IF(AA26=0,"",T26))) | AI26: =IF(Y26=1,"",IF(AC26=1,"",IF(AA26=0,"",W26)))
A27: ='GPA Calculator'!D28 -> 0 | B27: =IF('GPA Calculator'!E28="DP",0,IF('GPA Calculator'!E28="WP",0,IF('GPA Calculator'!E28="P",0,IF('GPA Calculator'!E28="FA",0,IF('GPA Calculator'!E28="CR",0,IF('GPA Calculator'!E28="NC",0,IF('GPA Calculator'!E28="",0,A27))))))) -> 0 | C27: =IF('GPA Calculator'!E28="W",0,IF('GPA Calculator'!E28="P",0,IF('GPA Calculator'!E28="FA",0,IF('GPA Calculator'!E28="CR",0,IF('GPA Calculator'!E28="NC",0,IF('GPA Calculator'!E28="",0,'GPA Calculator'!E28)))))) -> 0 | D27: =IF(C27=0,0,VLOOKUP(C27,$AL$2:$AM$14,2,FALSE)) -> 0 | E27: =IF(D27=0,"",B27*D27) | F27: ='GPA Calculator'!G28 -> 0 | G27: =IF(F27=0,0,1) -> 0 | H27: ='GPA Calculator'!H28 -> 0 | I27: =IF(H27=0,0,1) -> 0 | J27: ='GPA Calculator'!I28 -> 0 | K27: =IF(J27=0,0,1) -> 0 | L27: =B27 -> 0 | M27: =E27 | N27: =IF(G27=1,"",IF(K27=1,"",B27)) -> 0 | O27: =IF(G27=1,"",IF(K27=1,"",E27)) | P27: =IF(G27=1,"",IF(K27=1,"",IF(I27=0,"",B27))) | Q27: =IF(G27=1,"",IF(K27=1,"",IF(I27=0,"",E27))) | S27: ='GPA Calculator'!N28 -> 0 | T27: =IF('GPA Calculator'!O28="DP",0,IF('GPA Calculator'!O28="WP",0,IF('GPA Calculator'!O28="P",0,IF('GPA Calculator'!O28="FA",0,IF('GPA Calculator'!O28="CR",0,IF('GPA Calculator'!O28="NC",0,IF('GPA Calculator'!O28="",0,S27))))))) -> 0 | U27: =IF('GPA Calculator'!O28="W",0,IF('GPA Calculator'!O28="P",0,IF('GPA Calculator'!O28="FA",0,IF('GPA Calculator'!O28="CR",0,IF('GPA Calculator'!O28="NC",0,IF('GPA Calculator'!O28="",0,'GPA Calculator'!O28)))))) -> 0 | V27: =IF(U27=0,0,VLOOKUP(U27,$AL$2:$AM$14,2,FALSE)) -> 0 | W27: =IF(V27=0,"",T27*V27) | X27: ='GPA Calculator'!Q28 -> 0 | Y27: =IF(X27=0,0,1) -> 0 | Z27: ='GPA Calculator'!R28 -> 0 | AA27: =IF(Z27=0,0,1) -> 0 | AB27: ='GPA Calculator'!S28 -> 0 | AC27: =IF(AB27=0,0,1) -> 0 | AD27: =T27 -> 0 | AE27: =W27 | AF27: =IF(Y27=1,"",IF(AC27=1,"",T27)) -> 0 | AG27: =IF(Y27=1,"",IF(AC27=1,"",W27)) | AH27: =IF(Y27=1,"",IF(AC27=1,"",IF(AA27=0,"",T27))) | AI27: =IF(Y27=1,"",IF(AC27=1,"",IF(AA27=0,"",W27)))
A28: ='GPA Calculator'!D29 -> 0 | B28: =IF('GPA Calculator'!E29="DP",0,IF('GPA Calculator'!E29="WP",0,IF('GPA Calculator'!E29="P",0,IF('GPA Calculator'!E29="FA",0,IF('GPA Calculator'!E29="CR",0,IF('GPA Calculator'!E29="NC",0,IF('GPA Calculator'!E29="",0,A28))))))) -> 0 | C28: =IF('GPA Calculator'!E29="W",0,IF('GPA Calculator'!E29="P",0,IF('GPA Calculator'!E29="FA",0,IF('GPA Calculator'!E29="CR",0,IF('GPA Calculator'!E29="NC",0,IF('GPA Calculator'!E29="",0,'GPA Calculator'!E29)))))) -> 0 | D28: =IF(C28=0,0,VLOOKUP(C28,$AL$2:$AM$14,2,FALSE)) -> 0 | E28: =IF(D28=0,"",B28*D28) | F28: ='GPA Calculator'!G29 -> 0 | G28: =IF(F28=0,0,1) -> 0 | H28: ='GPA Calculator'!H29 -> 0 | I28: =IF(H28=0,0,1) -> 0 | J28: ='GPA Calculator'!I29 -> 0 | K28: =IF(J28=0,0,1) -> 0 | L28: =B28 -> 0 | M28: =E28 | N28: =IF(G28=1,"",IF(K28=1,"",B28)) -> 0 | O28: =IF(G28=1,"",IF(K28=1,"",E28)) | P28: =IF(G28=1,"",IF(K28=1,"",IF(I28=0,"",B28))) | Q28: =IF(G28=1,"",IF(K28=1,"",IF(I28=0,"",E28))) | S28: ='GPA Calculator'!N29 -> 0 | T28: =IF('GPA Calculator'!O29="DP",0,IF('GPA Calculator'!O29="WP",0,IF('GPA Calculator'!O29="P",0,IF('GPA Calculator'!O29="FA",0,IF('GPA Calculator'!O29="CR",0,IF('GPA Calculator'!O29="NC",0,IF('GPA Calculator'!O29="",0,S28))))))) -> 0 | U28: =IF('GPA Calculator'!O29="W",0,IF('GPA Calculator'!O29="P",0,IF('GPA Calculator'!O29="FA",0,IF('GPA Calculator'!O29="CR",0,IF('GPA Calculator'!O29="NC",0,IF('GPA Calculator'!O29="",0,'GPA Calculator'!O29)))))) -> 0 | V28: =IF(U28=0,0,VLOOKUP(U28,$AL$2:$AM$14,2,FALSE)) -> 0 | W28: =IF(V28=0,"",T28*V28) | X28: ='GPA Calculator'!Q29 -> 0 | Y28: =IF(X28=0,0,1) -> 0 | Z28: ='GPA Calculator'!R29 -> 0 | AA28: =IF(Z28=0,0,1) -> 0 | AB28: ='GPA Calculator'!S29 -> 0 | AC28: =IF(AB28=0,0,1) -> 0 | AD28: =T28 -> 0 | AE28: =W28 | AF28: =IF(Y28=1,"",IF(AC28=1,"",T28)) -> 0 | AG28: =IF(Y28=1,"",IF(AC28=1,"",W28)) | AH28: =IF(Y28=1,"",IF(AC28=1,"",IF(AA28=0,"",T28))) | AI28: =IF(Y28=1,"",IF(AC28=1,"",IF(AA28=0,"",W28)))
A29: ='GPA Calculator'!D30 -> 0 | B29: =IF('GPA Calculator'!E30="DP",0,IF('GPA Calculator'!E30="WP",0,IF('GPA Calculator'!E30="P",0,IF('GPA Calculator'!E30="FA",0,IF('GPA Calculator'!E30="CR",0,IF('GPA Calculator'!E30="NC",0,IF('GPA Calculator'!E30="",0,A29))))))) -> 0 | C29: =IF('GPA Calculator'!E30="W",0,IF('GPA Calculator'!E30="P",0,IF('GPA Calculator'!E30="FA",0,IF('GPA Calculator'!E30="CR",0,IF('GPA Calculator'!E30="NC",0,IF('GPA Calculator'!E30="",0,'GPA Calculator'!E30)))))) -> 0 | D29: =IF(C29=0,0,VLOOKUP(C29,$AL$2:$AM$14,2,FALSE)) -> 0 | E29: =IF(D29=0,"",B29*D29) | F29: ='GPA Calculator'!G30 -> 0 | G29: =IF(F29=0,0,1) -> 0 | H29: ='GPA Calculator'!H30 -> 0 | I29: =IF(H29=0,0,1) -> 0 | J29: ='GPA Calculator'!I30 -> 0 | K29: =IF(J29=0,0,1) -> 0 | L29: =B29 -> 0 | M29: =E29 | N29: =IF(G29=1,"",IF(K29=1,"",B29)) -> 0 | O29: =IF(G29=1,"",IF(K29=1,"",E29)) | P29: =IF(G29=1,"",IF(K29=1,"",IF(I29=0,"",B29))) | Q29: =IF(G29=1,"",IF(K29=1,"",IF(I29=0,"",E29))) | S29: ='GPA Calculator'!N30 -> 0 | T29: =IF('GPA Calculator'!O30="DP",0,IF('GPA Calculator'!O30="WP",0,IF('GPA Calculator'!O30="P",0,IF('GPA Calculator'!O30="FA",0,IF('GPA Calculator'!O30="CR",0,IF('GPA Calculator'!O30="NC",0,IF('GPA Calculator'!O30="",0,S29))))))) -> 0 | U29: =IF('GPA Calculator'!O30="W",0,IF('GPA Calculator'!O30="P",0,IF('GPA Calculator'!O30="FA",0,IF('GPA Calculator'!O30="CR",0,IF('GPA Calculator'!O30="NC",0,IF('GPA Calculator'!O30="",0,'GPA Calculator'!O30)))))) -> 0 | V29: =IF(U29=0,0,VLOOKUP(U29,$AL$2:$AM$14,2,FALSE)) -> 0 | W29: =IF(V29=0,"",T29*V29) | X29: ='GPA Calculator'!Q30 -> 0 | Y29: =IF(X29=0,0,1) -> 0 | Z29: ='GPA Calculator'!R30 -> 0 | AA29: =IF(Z29=0,0,1) -> 0 | AB29: ='GPA Calculator'!S30 -> 0 | AC29: =IF(AB29=0,0,1) -> 0 | AD29: =T29 -> 0 | AE29: =W29 | AF29: =IF(Y29=1,"",IF(AC29=1,"",T29)) -> 0 | AG29: =IF(Y29=1,"",IF(AC29=1,"",W29)) | AH29: =IF(Y29=1,"",IF(AC29=1,"",IF(AA29=0,"",T29))) | AI29: =IF(Y29=1,"",IF(AC29=1,"",IF(AA29=0,"",W29)))
B30: =SUM(B21:B29) -> 0 | E30: =SUM(E21:E29) -> 0 | L30: =SUM(L21:L29) -> 0 | M30: =SUM(M21:M29) -> 0 | N30: =SUM(N21:N29) -> 0 | O30: =SUM(O21:O29) -> 0 | P30: =SUM(P21:P29) -> 0 | Q30: =SUM(Q21:Q29) -> 0 | T30: =SUM(T21:T29) -> 0 | V30: =SUM(V21:V29) -> 0 | W30: =SUM(W21:W29) -> 0 | AD30: =SUM(AD21:AD29) -> 0 | AE30: =SUM(AE21:AE29) -> 0 | AF30: =SUM(AF21:AF29) -> 0 | AG30: =SUM(AG21:AG29) -> 0 | AH30: =SUM(AH21:AH29) -> 0 | AI30: =SUM(AI21:AI29) -> 0
L31: Term GPA | M31: =IF(L30=0,"",M30/L30) | N31: BU GPA | O31: =IF(N30=0,"",O30/N30) | P31: MAJ GPA | Q31: =IF(P30=0,"",Q30/P30) | AD31: Term GPA | AE31: =IF(AD30=0,"",AE30/AD30) | AF31: BU GPA | AG31: =IF(AF30=0,"",AG30/AF30) | AH31: MAJ GPA | AI31: =IF(AH30=0,"",AI30/AH30)
A36: Hours | B36: QHrs | C36: Grades | D36: Grd Pts | E36: Points | F36: TR | H36: MAJ | J36: RPL | L36: Ttl Hrs | M36: Ttl Pts | N36: BU Hrs | O36: BU Pts | P36: Major Hrs | Q36: Major Pts | S36: Hours | T36: QHrs | U36: Grades | V36: Grd Pts | W36: Points | X36: TR | Z36: MAJ | AB36: RPL | AD36: Ttl Hrs | AE36: Ttl Pts | AF36: BU Hrs | AG36: BU Pts | AH36: Major Hrs | AI36: Major Pts
A37: ='GPA Calculator'!D39 -> 0 | B37: =IF('GPA Calculator'!E39="W",0,IF('GPA Calculator'!E39="P",0,IF('GPA Calculator'!E39="FA",0,IF('GPA Calculator'!E39="CR",0,IF('GPA Calculator'!E39="NC",0,IF('GPA Calculator'!E39="",0,A37)))))) -> 0 | C37: =IF('GPA Calculator'!E39="W",0,IF('GPA Calculator'!E39="P",0,IF('GPA Calculator'!E39="FA",0,IF('GPA Calculator'!E39="CR",0,IF('GPA Calculator'!E39="NC",0,IF('GPA Calculator'!E39="",0,'GPA Calculator'!E39)))))) -> 0 | D37: =IF(C37=0,0,VLOOKUP(C37,$AL$2:$AM$14,2,FALSE)) -> 0 | E37: =IF(D37=0,"",B37*D37) | F37: ='GPA Calculator'!G39 -> 0 | G37: =IF(F37=0,0,1) -> 0 | H37: ='GPA Calculator'!H39 -> 0 | I37: =IF(H37=0,0,1) -> 0 | J37: ='GPA Calculator'!I39 -> 0 | K37: =IF(J37=0,0,1) -> 0 | L37: =B37 -> 0 | M37: =E37 | N37: =IF(G37=1,"",IF(K37=1,"",B37)) -> 0 | O37: =IF(G37=1,"",IF(K37=1,"",E37)) | P37: =IF(G37=1,"",IF(K37=1,"",IF(I37=0,"",B37))) | Q37: =IF(G37=1,"",IF(K37=1,"",IF(I37=0,"",E37))) | S37: ='GPA Calculator'!N39 -> 0 | T37: =IF('GPA Calculator'!O39="DP",0,IF('GPA Calculator'!O39="WP",0,IF('GPA Calculator'!O39="P",0,IF('GPA Calculator'!O39="FA",0,IF('GPA Calculator'!O39="CR",0,IF('GPA Calculator'!O39="NC",0,IF('GPA Calculator'!O39="",0,S37))))))) -> 0 | U37: =IF('GPA Calculator'!O39="W",0,IF('GPA Calculator'!O39="P",0,IF('GPA Calculator'!O39="FA",0,IF('GPA Calculator'!O39="CR",0,IF('GPA Calculator'!O39="NC",0,IF('GPA Calculator'!O39="",0,'GPA Calculator'!O39)))))) -> 0 | V37: =IF(U37=0,0,VLOOKUP(U37,$AL$2:$AM$14,2,FALSE)) -> 0 | W37: =IF(V37=0,"",T37*V37) | X37: ='GPA Calculator'!Q39 -> 0 | Y37: =IF(X37=0,0,1) -> 0 | Z37: ='GPA Calculator'!R39 -> 0 | AA37: =IF(Z37=0,0,1) -> 0 | AB37: ='GPA Calculator'!S39 -> 0 | AC37: =IF(AB37=0,0,1) -> 0 | AD37: =T37 -> 0 | AE37: =W37 | AF37: =IF(Y37=1,"",IF(AC37=1,"",T37)) -> 0 | AG37: =IF(Y37=1,"",IF(AC37=1,"",W37)) | AH37: =IF(Y37=1,"",IF(AC37=1,"",IF(AA37=0,"",T37))) | AI37: =IF(Y37=1,"",IF(AC37=1,"",IF(AA37=0,"",W37)))
A38: ='GPA Calculator'!D40 -> 0 | B38: =IF('GPA Calculator'!E40="DP",0,IF('GPA Calculator'!E40="WP",0,IF('GPA Calculator'!E40="P",0,IF('GPA Calculator'!E40="FA",0,IF('GPA Calculator'!E40="CR",0,IF('GPA Calculator'!E40="NC",0,IF('GPA Calculator'!E40="",0,A38))))))) -> 0 | C38: =IF('GPA Calculator'!E40="W",0,IF('GPA Calculator'!E40="P",0,IF('GPA Calculator'!E40="FA",0,IF('GPA Calculator'!E40="CR",0,IF('GPA Calculator'!E40="NC",0,IF('GPA Calculator'!E40="",0,'GPA Calculator'!E40)))))) -> 0 | D38: =IF(C38=0,0,VLOOKUP(C38,$AL$2:$AM$14,2,FALSE)) -> 0 | E38: =IF(D38=0,"",B38*D38) | F38: ='GPA Calculator'!G40 -> 0 | G38: =IF(F38=0,0,1) -> 0 | H38: ='GPA Calculator'!H40 -> 0 | I38: =IF(H38=0,0,1) -> 0 | J38: ='GPA Calculator'!I40 -> 0 | K38: =IF(J38=0,0,1) -> 0 | L38: =B38 -> 0 | M38: =E38 | N38: =IF(G38=1,"",IF(K38=1,"",B38)) -> 0 | O38: =IF(G38=1,"",IF(K38=1,"",E38)) | P38: =IF(G38=1,"",IF(K38=1,"",IF(I38=0,"",B38))) | Q38: =IF(G38=1,"",IF(K38=1,"",IF(I38=0,"",E38))) | S38: ='GPA Calculator'!N40 -> 0 | T38: =IF('GPA Calculator'!O40="DP",0,IF('GPA Calculator'!O40="WP",0,IF('GPA Calculator'!O40="P",0,IF('GPA Calculator'!O40="FA",0,IF('GPA Calculator'!O40="CR",0,IF('GPA Calculator'!O40="NC",0,IF('GPA Calculator'!O40="",0,S38))))))) -> 0 | U38: =IF('GPA Calculator'!O40="W",0,IF('GPA Calculator'!O40="P",0,IF('GPA Calculator'!O40="FA",0,IF('GPA Calculator'!O40="CR",0,IF('GPA Calculator'!O40="NC",0,IF('GPA Calculator'!O40="",0,'GPA Calculator'!O40)))))) -> 0 | V38: =IF(U38=0,0,VLOOKUP(U38,$AL$2:$AM$14,2,FALSE)) -> 0 | W38: =IF(V38=0,"",T38*V38) | X38: ='GPA Calculator'!Q40 -> 0 | Y38: =IF(X38=0,0,1) -> 0 | Z38: ='GPA Calculator'!R40 -> 0 | AA38: =IF(Z38=0,0,1) -> 0 | AB38: ='GPA Calculator'!S40 -> 0 | AC38: =IF(AB38=0,0,1) -> 0 | AD38: =T38 -> 0 | AE38: =W38 | AF38: =IF(Y38=1,"",IF(AC38=1,"",T38)) -> 0 | AG38: =IF(Y38=1,"",IF(AC38=1,"",W38)) | AH38: =IF(Y38=1,"",IF(AC38=1,"",IF(AA38=0,"",T38))) | AI38: =IF(Y38=1,"",IF(AC38=1,"",IF(AA38=0,"",W38)))
A39: ='GPA Calculator'!D41 -> 0 | B39: =IF('GPA Calculator'!E41="DP",0,IF('GPA Calculator'!E41="WP",0,IF('GPA Calculator'!E41="P",0,IF('GPA Calculator'!E41="FA",0,IF('GPA Calculator'!E41="CR",0,IF('GPA Calculator'!E41="NC",0,IF('GPA Calculator'!E41="",0,A39))))))) -> 0 | C39: =IF('GPA Calculator'!E41="W",0,IF('GPA Calculator'!E41="P",0,IF('GPA Calculator'!E41="FA",0,IF('GPA Calculator'!E41="CR",0,IF('GPA Calculator'!E41="NC",0,IF('GPA Calculator'!E41="",0,'GPA Calculator'!E41)))))) -> 0 | D39: =IF(C39=0,0,VLOOKUP(C39,$AL$2:$AM$14,2,FALSE)) -> 0 | E39: =IF(D39=0,"",B39*D39) | F39: ='GPA Calculator'!G41 -> 0 | G39: =IF(F39=0,0,1) -> 0 | H39: ='GPA Calculator'!H41 -> 0 | I39: =IF(H39=0,0,1) -> 0 | J39: ='GPA Calculator'!I41 -> 0 | K39: =IF(J39=0,0,1) -> 0 | L39: =B39 -> 0 | M39: =E39 | N39: =IF(G39=1,"",IF(K39=1,"",B39)) -> 0 | O39: =IF(G39=1,"",IF(K39=1,"",E39)) | P39: =IF(G39=1,"",IF(K39=1,"",IF(I39=0,"",B39))) | Q39: =IF(G39=1,"",IF(K39=1,"",IF(I39=0,"",E39))) | S39: ='GPA Calculator'!N41 -> 0 | T39: =IF('GPA Calculator'!O41="DP",0,IF('GPA Calculator'!O41="WP",0,IF('GPA Calculator'!O41="P",0,IF('GPA Calculator'!O41="FA",0,IF('GPA Calculator'!O41="CR",0,IF('GPA Calculator'!O41="NC",0,IF('GPA Calculator'!O41="",0,S39))))))) -> 0 | U39: =IF('GPA Calculator'!O41="W",0,IF('GPA Calculator'!O41="P",0,IF('GPA Calculator'!O41="FA",0,IF('GPA Calculator'!O41="CR",0,IF('GPA Calculator'!O41="NC",0,IF('GPA Calculator'!O41="",0,'GPA Calculator'!O41)))))) -> 0 | V39: =IF(U39=0,0,VLOOKUP(U39,$AL$2:$AM$14,2,FALSE)) -> 0 | W39: =IF(V39=0,"",T39*V39) | X39: ='GPA Calculator'!Q41 -> 0 | Y39: =IF(X39=0,0,1) -> 0 | Z39: ='GPA Calculator'!R41 -> 0 | AA39: =IF(Z39=0,0,1) -> 0 | AB39: ='GPA Calculator'!S41 -> 0 | AC39: =IF(AB39=0,0,1) -> 0 | AD39: =T39 -> 0 | AE39: =W39 | AF39: =IF(Y39=1,"",IF(AC39=1,"",T39)) -> 0 | AG39: =IF(Y39=1,"",IF(AC39=1,"",W39)) | AH39: =IF(Y39=1,"",IF(AC39=1,"",IF(AA39=0,"",T39))) | AI39: =IF(Y39=1,"",IF(AC39=1,"",IF(AA39=0,"",W39)))
A40: ='GPA Calculator'!D42 -> 0 | B40: =IF('GPA Calculator'!E42="DP",0,IF('GPA Calculator'!E42="WP",0,IF('GPA Calculator'!E42="P",0,IF('GPA Calculator'!E42="FA",0,IF('GPA Calculator'!E42="CR",0,IF('GPA Calculator'!E42="NC",0,IF('GPA Calculator'!E42="",0,A40))))))) -> 0 | C40: =IF('GPA Calculator'!E42="W",0,IF('GPA Calculator'!E42="P",0,IF('GPA Calculator'!E42="FA",0,IF('GPA Calculator'!E42="CR",0,IF('GPA Calculator'!E42="NC",0,IF('GPA Calculator'!E42="",0,'GPA Calculator'!E42)))))) -> 0 | D40: =IF(C40=0,0,VLOOKUP(C40,$AL$2:$AM$14,2,FALSE)) -> 0 | E40: =IF(D40=0,"",B40*D40) | F40: ='GPA Calculator'!G42 -> 0 | G40: =IF(F40=0,0,1) -> 0 | H40: ='GPA Calculator'!H42 -> 0 | I40: =IF(H40=0,0,1) -> 0 | J40: ='GPA Calculator'!I42 -> 0 | K40: =IF(J40=0,0,1) -> 0 | L40: =B40 -> 0 | M40: =E40 | N40: =IF(G40=1,"",IF(K40=1,"",B40)) -> 0 | O40: =IF(G40=1,"",IF(K40=1,"",E40)) | P40: =IF(G40=1,"",IF(K40=1,"",IF(I40=0,"",B40))) | Q40: =IF(G40=1,"",IF(K40=1,"",IF(I40=0,"",E40))) | S40: ='GPA Calculator'!N42 -> 0 | T40: =IF('GPA Calculator'!O42="DP",0,IF('GPA Calculator'!O42="WP",0,IF('GPA Calculator'!O42="P",0,IF('GPA Calculator'!O42="FA",0,IF('GPA Calculator'!O42="CR",0,IF('GPA Calculator'!O42="NC",0,IF('GPA Calculator'!O42="",0,S40))))))) -> 0 | U40: =IF('GPA Calculator'!O42="W",0,IF('GPA Calculator'!O42="P",0,IF('GPA Calculator'!O42="FA",0,IF('GPA Calculator'!O42="CR",0,IF('GPA Calculator'!O42="NC",0,IF('GPA Calculator'!O42="",0,'GPA Calculator'!O42)))))) -> 0 | V40: =IF(U40=0,0,VLOOKUP(U40,$AL$2:$AM$14,2,FALSE)) -> 0 | W40: =IF(V40=0,"",T40*V40) | X40: ='GPA Calculator'!Q42 -> 0 | Y40: =IF(X40=0,0,1) -> 0 | Z40: ='GPA Calculator'!R42 -> 0 | AA40: =IF(Z40=0,0,1) -> 0 | AB40: ='GPA Calculator'!S42 -> 0 | AC40: =IF(AB40=0,0,1) -> 0 | AD40: =T40 -> 0 | AE40: =W40 | AF40: =IF(Y40=1,"",IF(AC40=1,"",T40)) -> 0 | AG40: =IF(Y40=1,"",IF(AC40=1,"",W40)) | AH40: =IF(Y40=1,"",IF(AC40=1,"",IF(AA40=0,"",T40))) | AI40: =IF(Y40=1,"",IF(AC40=1,"",IF(AA40=0,"",W40)))
A41: ='GPA Calculator'!D43 -> 0 | B41: =IF('GPA Calculator'!E43="DP",0,IF('GPA Calculator'!E43="WP",0,IF('GPA Calculator'!E43="P",0,IF('GPA Calculator'!E43="FA",0,IF('GPA Calculator'!E43="CR",0,IF('GPA Calculator'!E43="NC",0,IF('GPA Calculator'!E43="",0,A41))))))) -> 0 | C41: =IF('GPA Calculator'!E43="W",0,IF('GPA Calculator'!E43="P",0,IF('GPA Calculator'!E43="FA",0,IF('GPA Calculator'!E43="CR",0,IF('GPA Calculator'!E43="NC",0,IF('GPA Calculator'!E43="",0,'GPA Calculator'!E43)))))) -> 0 | D41: =IF(C41=0,0,VLOOKUP(C41,$AL$2:$AM$14,2,FALSE)) -> 0 | E41: =IF(D41=0,"",B41*D41) | F41: ='GPA Calculator'!G43 -> 0 | G41: =IF(F41=0,0,1) -> 0 | H41: ='GPA Calculator'!H43 -> 0 | I41: =IF(H41=0,0,1) -> 0 | J41: ='GPA Calculator'!I43 -> 0 | K41: =IF(J41=0,0,1) -> 0 | L41: =B41 -> 0 | M41: =E41 | N41: =IF(G41=1,"",IF(K41=1,"",B41)) -> 0 | O41: =IF(G41=1,"",IF(K41=1,"",E41)) | P41: =IF(G41=1,"",IF(K41=1,"",IF(I41=0,"",B41))) | Q41: =IF(G41=1,"",IF(K41=1,"",IF(I41=0,"",E41))) | S41: ='GPA Calculator'!N43 -> 0 | T41: =IF('GPA Calculator'!O43="DP",0,IF('GPA Calculator'!O43="WP",0,IF('GPA Calculator'!O43="P",0,IF('GPA Calculator'!O43="FA",0,IF('GPA Calculator'!O43="CR",0,IF('GPA Calculator'!O43="NC",0,IF('GPA Calculator'!O43="",0,S41))))))) -> 0 | U41: =IF('GPA Calculator'!O43="W",0,IF('GPA Calculator'!O43="P",0,IF('GPA Calculator'!O43="FA",0,IF('GPA Calculator'!O43="CR",0,IF('GPA Calculator'!O43="NC",0,IF('GPA Calculator'!O43="",0,'GPA Calculator'!O43)))))) -> 0 | V41: =IF(U41=0,0,VLOOKUP(U41,$AL$2:$AM$14,2,FALSE)) -> 0 | W41: =IF(V41=0,"",T41*V41) | X41: ='GPA Calculator'!Q43 -> 0 | Y41: =IF(X41=0,0,1) -> 0 | Z41: ='GPA Calculator'!R43 -> 0 | AA41: =IF(Z41=0,0,1) -> 0 | AB41: ='GPA Calculator'!S43 -> 0 | AC41: =IF(AB41=0,0,1) -> 0 | AD41: =T41 -> 0 | AE41: =W41 | AF41: =IF(Y41=1,"",IF(AC41=1,"",T41)) -> 0 | AG41: =IF(Y41=1,"",IF(AC41=1,"",W41)) | AH41: =IF(Y41=1,"",IF(AC41=1,"",IF(AA41=0,"",T41))) | AI41: =IF(Y41=1,"",IF(AC41=1,"",IF(AA41=0,"",W41)))
A42: ='GPA Calculator'!D44 -> 0 | B42: =IF('GPA Calculator'!E44="DP",0,IF('GPA Calculator'!E44="WP",0,IF('GPA Calculator'!E44="P",0,IF('GPA Calculator'!E44="FA",0,IF('GPA Calculator'!E44="CR",0,IF('GPA Calculator'!E44="NC",0,IF('GPA Calculator'!E44="",0,A42))))))) -> 0 | C42: =IF('GPA Calculator'!E44="W",0,IF('GPA Calculator'!E44="P",0,IF('GPA Calculator'!E44="FA",0,IF('GPA Calculator'!E44="CR",0,IF('GPA Calculator'!E44="NC",0,IF('GPA Calculator'!E44="",0,'GPA Calculator'!E44)))))) -> 0 | D42: =IF(C42=0,0,VLOOKUP(C42,$AL$2:$AM$14,2,FALSE)) -> 0 | E42: =IF(D42=0,"",B42*D42) | F42: ='GPA Calculator'!G44 -> 0 | G42: =IF(F42=0,0,1) -> 0 | H42: ='GPA Calculator'!H44 -> 0 | I42: =IF(H42=0,0,1) -> 0 | J42: ='GPA Calculator'!I44 -> 0 | K42: =IF(J42=0,0,1) -> 0 | L42: =B42 -> 0 | M42: =E42 | N42: =IF(G42=1,"",IF(K42=1,"",B42)) -> 0 | O42: =IF(G42=1,"",IF(K42=1,"",E42)) | P42: =IF(G42=1,"",IF(K42=1,"",IF(I42=0,"",B42))) | Q42: =IF(G42=1,"",IF(K42=1,"",IF(I42=0,"",E42))) | S42: ='GPA Calculator'!N44 -> 0 | T42: =IF('GPA Calculator'!O44="DP",0,IF('GPA Calculator'!O44="WP",0,IF('GPA Calculator'!O44="P",0,IF('GPA Calculator'!O44="FA",0,IF('GPA Calculator'!O44="CR",0,IF('GPA Calculator'!O44="NC",0,IF('GPA Calculator'!O44="",0,S42))))))) -> 0 | U42: =IF('GPA Calculator'!O44="W",0,IF('GPA Calculator'!O44="P",0,IF('GPA Calculator'!O44="FA",0,IF('GPA Calculator'!O44="CR",0,IF('GPA Calculator'!O44="NC",0,IF('GPA Calculator'!O44="",0,'GPA Calculator'!O44)))))) -> 0 | V42: =IF(U42=0,0,VLOOKUP(U42,$AL$2:$AM$14,2,FALSE)) -> 0 | W42: =IF(V42=0,"",T42*V42) | X42: ='GPA Calculator'!Q44 -> 0 | Y42: =IF(X42=0,0,1) -> 0 | Z42: ='GPA Calculator'!R44 -> 0 | AA42: =IF(Z42=0,0,1) -> 0 | AB42: ='GPA Calculator'!S44 -> 0 | AC42: =IF(AB42=0,0,1) -> 0 | AD42: =T42 -> 0 | AE42: =W42 | AF42: =IF(Y42=1,"",IF(AC42=1,"",T42)) -> 0 | AG42: =IF(Y42=1,"",IF(AC42=1,"",W42)) | AH42: =IF(Y42=1,"",IF(AC42=1,"",IF(AA42=0,"",T42))) | AI42: =IF(Y42=1,"",IF(AC42=1,"",IF(AA42=0,"",W42)))
A43: ='GPA Calculator'!D45 -> 0 | B43: =IF('GPA Calculator'!E45="DP",0,IF('GPA Calculator'!E45="WP",0,IF('GPA Calculator'!E45="P",0,IF('GPA Calculator'!E45="FA",0,IF('GPA Calculator'!E45="CR",0,IF('GPA Calculator'!E45="NC",0,IF('GPA Calculator'!E45="",0,A43))))))) -> 0 | C43: =IF('GPA Calculator'!E45="W",0,IF('GPA Calculator'!E45="P",0,IF('GPA Calculator'!E45="FA",0,IF('GPA Calculator'!E45="CR",0,IF('GPA Calculator'!E45="NC",0,IF('GPA Calculator'!E45="",0,'GPA Calculator'!E45)))))) -> 0 | D43: =IF(C43=0,0,VLOOKUP(C43,$AL$2:$AM$14,2,FALSE)) -> 0 | E43: =IF(D43=0,"",B43*D43) | F43: ='GPA Calculator'!G45 -> 0 | G43: =IF(F43=0,0,1) -> 0 | H43: ='GPA Calculator'!H45 -> 0 | I43: =IF(H43=0,0,1) -> 0 | J43: ='GPA Calculator'!I45 -> 0 | K43: =IF(J43=0,0,1) -> 0 | L43: =B43 -> 0 | M43: =E43 | N43: =IF(G43=1,"",IF(K43=1,"",B43)) -> 0 | O43: =IF(G43=1,"",IF(K43=1,"",E43)) | P43: =IF(G43=1,"",IF(K43=1,"",IF(I43=0,"",B43))) | Q43: =IF(G43=1,"",IF(K43=1,"",IF(I43=0,"",E43))) | S43: ='GPA Calculator'!N45 -> 0 | T43: =IF('GPA Calculator'!O45="DP",0,IF('GPA Calculator'!O45="WP",0,IF('GPA Calculator'!O45="P",0,IF('GPA Calculator'!O45="FA",0,IF('GPA Calculator'!O45="CR",0,IF('GPA Calculator'!O45="NC",0,IF('GPA Calculator'!O45="",0,S43))))))) -> 0 | U43: =IF('GPA Calculator'!O45="W",0,IF('GPA Calculator'!O45="P",0,IF('GPA Calculator'!O45="FA",0,IF('GPA Calculator'!O45="CR",0,IF('GPA Calculator'!O45="NC",0,IF('GPA Calculator'!O45="",0,'GPA Calculator'!O45)))))) -> 0 | V43: =IF(U43=0,0,VLOOKUP(U43,$AL$2:$AM$14,2,FALSE)) -> 0 | W43: =IF(V43=0,"",T43*V43) | X43: ='GPA Calculator'!Q45 -> 0 | Y43: =IF(X43=0,0,1) -> 0 | Z43: ='GPA Calculator'!R45 -> 0 | AA43: =IF(Z43=0,0,1) -> 0 | AB43: ='GPA Calculator'!S45 -> 0 | AC43: =IF(AB43=0,0,1) -> 0 | AD43: =T43 -> 0 | AE43: =W43 | AF43: =IF(Y43=1,"",IF(AC43=1,"",T43)) -> 0 | AG43: =IF(Y43=1,"",IF(AC43=1,"",W43)) | AH43: =IF(Y43=1,"",IF(AC43=1,"",IF(AA43=0,"",T43))) | AI43: =IF(Y43=1,"",IF(AC43=1,"",IF(AA43=0,"",W43)))
A44: ='GPA Calculator'!D46 -> 0 | B44: =IF('GPA Calculator'!E46="DP",0,IF('GPA Calculator'!E46="WP",0,IF('GPA Calculator'!E46="P",0,IF('GPA Calculator'!E46="FA",0,IF('GPA Calculator'!E46="CR",0,IF('GPA Calculator'!E46="NC",0,IF('GPA Calculator'!E46="",0,A44))))))) -> 0 | C44: =IF('GPA Calculator'!E46="W",0,IF('GPA Calculator'!E46="P",0,IF('GPA Calculator'!E46="FA",0,IF('GPA Calculator'!E46="CR",0,IF('GPA Calculator'!E46="NC",0,IF('GPA Calculator'!E46="",0,'GPA Calculator'!E46)))))) -> 0 | D44: =IF(C44=0,0,VLOOKUP(C44,$AL$2:$AM$14,2,FALSE)) -> 0 | E44: =IF(D44=0,"",B44*D44) | F44: ='GPA Calculator'!G46 -> 0 | G44: =IF(F44=0,0,1) -> 0 | H44: ='GPA Calculator'!H46 -> 0 | I44: =IF(H44=0,0,1) -> 0 | J44: ='GPA Calculator'!I46 -> 0 | K44: =IF(J44=0,0,1) -> 0 | L44: =B44 -> 0 | M44: =E44 | N44: =IF(G44=1,"",IF(K44=1,"",B44)) -> 0 | O44: =IF(G44=1,"",IF(K44=1,"",E44)) | P44: =IF(G44=1,"",IF(K44=1,"",IF(I44=0,"",B44))) | Q44: =IF(G44=1,"",IF(K44=1,"",IF(I44=0,"",E44))) | S44: ='GPA Calculator'!N46 -> 0 | T44: =IF('GPA Calculator'!O46="DP",0,IF('GPA Calculator'!O46="WP",0,IF('GPA Calculator'!O46="P",0,IF('GPA Calculator'!O46="FA",0,IF('GPA Calculator'!O46="CR",0,IF('GPA Calculator'!O46="NC",0,IF('GPA Calculator'!O46="",0,S44))))))) -> 0 | U44: =IF('GPA Calculator'!O46="W",0,IF('GPA Calculator'!O46="P",0,IF('GPA Calculator'!O46="FA",0,IF('GPA Calculator'!O46="CR",0,IF('GPA Calculator'!O46="NC",0,IF('GPA Calculator'!O46="",0,'GPA Calculator'!O46)))))) -> 0 | V44: =IF(U44=0,0,VLOOKUP(U44,$AL$2:$AM$14,2,FALSE)) -> 0 | W44: =IF(V44=0,"",T44*V44) | X44: ='GPA Calculator'!Q46 -> 0 | Y44: =IF(X44=0,0,1) -> 0 | Z44: ='GPA Calculator'!R46 -> 0 | AA44: =IF(Z44=0,0,1) -> 0 | AB44: ='GPA Calculator'!S46 -> 0 | AC44: =IF(AB44=0,0,1) -> 0 | AD44: =T44 -> 0 | AE44: =W44 | AF44: =IF(Y44=1,"",IF(AC44=1,"",T44)) -> 0 | AG44: =IF(Y44=1,"",IF(AC44=1,"",W44)) | AH44: =IF(Y44=1,"",IF(AC44=1,"",IF(AA44=0,"",T44))) | AI44: =IF(Y44=1,"",IF(AC44=1,"",IF(AA44=0,"",W44)))
