Workbook

Sheet meetings_data
A1: Year | B1: Location | C1: No.* | D1: Dates | E1: Attend. | F1: Theme
A2: 2015 | B2: Baltimore, MD | C2: 100 | D2: Aug 9-14, 2015
A3: 2014 | B3: Sacramento, CA | C3: 99 | D3: Aug 10-15, 2014 | F3: From Oceans to Mountains: It's All Ecology
A4: 2013 | B4: Minneapolis, MN | C4: 98 | D4: Aug 4-9, 2013 | E4: 3363 | F4: Sustainable Pathways: Learning from the past and shaping the future
A5: 2012 | B5: =HYPERLINK("http://www.esa.org/portland/","Portland, OR") -> Portland, OR | C5: 97 | D5: Aug 5-10, 2012 | E5: 4992 | F5: Life on Earth: Preserving, Utilizing, and Sustaining our Ecosystems | G5: =HYPERLINK("http://www.esa.org/portland/plenary.php","Plenary") -> Plenary | H5: =HYPERLINK("http://eco.confex.com/eco/2012/webprogrampreliminary/meeting.html","Program") -> Program | I5: =HYPERLINK("http://dx.doi.org/10.1890/0012-9623-93.4.282","Awards") -> Awards | J5: =HYPERLINK("http://www.esajournals.org/doi/pdf/10.1890/2012.councilreport","Reports") -> Reports
A6: 2011 | B6: =HYPERLINK("http://www.esa.org/austin/","Austin, TX") -> Austin, TX | C6: 96 | D6: Aug 7-12, 2011 | E6: 3721 | F6: Earth Stewardship: Preserving and enhancing the earth's life-support systems | G6: =HYPERLINK("http://www.esa.org/austin/plenary_session.php","Plenary") -> Plenary | H6: =HYPERLINK("http://eco.confex.com/eco/2011/webprogram/meeting.html","Program") -> Program | I6: =HYPERLINK("http://dx.doi.org/10.1890/0012-9623-92.4.330","Awards") -> Awards | J6: =HYPERLINK("http://dx.doi.org/10.1890/2011.councilreport","Reports") -> Reports
A7: 2010 | B7: =HYPERLINK("http://www.esa.org/pittsburgh/","Pittsburgh, PA") -> Pittsburgh, PA | C7: 95 | D7: Aug 1-6, 2010 | E7: 3525 | F7: Global Warming: The legacy of our past, the challenge for our future | G7: =HYPERLINK("http://www.esa.org/pittsburgh/plenary.php","Plenary") -> Plenary | H7: =HYPERLINK("http://eco.confex.com/eco/2010/techprogram/index.htm","Program") -> Program | I7: =HYPERLINK("http://dx.doi.org/10.1890/0012-9623-91.4.394","Awards") -> Awards | J7: =HYPERLINK("http://dx.doi.org/10.1890/2010.councilreport","Reports") -> Reports
A8: 2009 | B8: =HYPERLINK("http://www.esa.org/albuquerque/","Albuquerque, NM") -> Albuquerque, NM | C8: 94 | D8: Aug 2-7, 2009 | E8: 3648 | F8: Ecological Knowledge and a Global Sustainable Society | G8: =HYPERLINK("http://www.esa.org/albuquerque/plenary.php","Plenary") -> Plenary | H8: =HYPERLINK("http://eco.confex.com/eco/2009/techprogram/","Program") -> Program | I8: =HYPERLINK("http://dx.doi.org/10.1890/0012-9623-90.4.327","Awards") -> Awards | J8: =HYPERLINK("http://dx.doi.org/10.1890/0012-9623-90.4.360","Reports") -> Reports
A9: 2008 | B9: =HYPERLINK("http://www.esa.org/milwaukee/","Milwaukee, WI") -> Milwaukee, WI | C9: 93 | D9: Aug 3-8, 2008 | E9: 3354 | F9: Enhancing Ecological Thought by Linking Research and Education | G9: Plenary | H9: Program | I9: =HYPERLINK("http://dx.doi.org/10.1890/0012-9623(2008)89%5b344:AC%5d2.0.CO;2","Awards") -> Awards | J9: Reports
A10: 2007 | B10: =HYPERLINK("http://www.esa.org/sanjose/","San Jose, CA") -> San Jose, CA | C10: 92 | D10: Aug 5-10, 2007 | E10: 4185 | F10: Ecology-based restoration in a changing world | G10: Plenary | H10: Program | I10: Awards | J10: =HYPERLINK("http://dx.doi.org/10.1890/0012-9623(2007)88%5b309:ARTCES%5d2.0.CO;2","Reports") -> Reports
A11: 2006 | B11: =HYPERLINK("http://www.esa.org/memphis/","Memphis, TN") -> Memphis, TN | C11: 91 | D11: Aug 6-11, 2006 | E11: 2838 | F11: Icons and Upstarts in Ecology | G11: Plenary | H11: Program | I11: Awards | J11: Reports
A12: 2005 | B12: =HYPERLINK("http://www.esa.org/montreal/","Montreal, Canada") -> Montreal, Canada | C12: 90 | D12: Aug 7-12, 2005 | E12: 4359 | F12: Ecology at multiple scales | G12: Plenary | H12: Program | I12: Awards | J12: Reports
A13: 2004 | B13: =HYPERLINK("http://www.esa.org/portland2004/","Portland, OR") -> Portland, OR | C13: 89 | D13: Aug 1-6, 2004 | F13: Lessons of Lewis & Clark: Ecological Exploration of Inhabited Landscapes | G13: Plenary | H13: Program | I13: Awards | J13: Reports
A14: 2003 | B14: =HYPERLINK("http://www.esa.org/savannah/","Savannah, GA") -> Savannah, GA | C14: 88 | D14: Aug 3-8, 2003 | E14: 2718 | F14: Uplands to Lowlands: Coastal processes in a time of global change | G14: Plenary | H14: Program | I14: Awards | J14: Reports
A15: 2002 | B15: Tucson, AZ | C15: 87 | D15: Aug 23-25, 2002 | E15: 3756 | F15: A Convocation: Understanding and Restoring Ecosystems | G15: Plenary | H15: Program | I15: Awards | J15: Reports
A16: 2001 | B16: Madison, WI | C16: 86 | D16: Aug 6-10, 2001 | E16: 3010 | F16: Keeping All the Parts: Preserving, Restoring, and Sustaining Complex Ecosystems | G16: Plenary | H16: Program | I16: Awards | J16: Reports
A17: 2000 | B17: Snowbird, UT | C17: 85 | D17: Aug 6-10, 2000 | E17: 2664 | F17: Communicating and Advancing Ecology | G17: Plenary | H17: Program | I17: Awards | J17: Reports
A18: 1999 | B18: Spokane, WA | C18: 84 | D18: Aug 8-12, 1999 | E18: 2985 | F18: Legacies, Landscapes, and Limits: Bridging Borders
A19: 1998 | B19: Baltimore, MD | C19: 83 | D19: Aug 2-6, 1998 | E19: 3060 | F19: Ecological Exchanges between Major Ecosystems
A20: 1997 | B20: Albuquerque, NM | C20: 82 | D20: Aug 10-14, 1997 | E20: 3106 | F20: Changing Ecosystems: Natural and Human Influences
A21: 1996 | B21: Providence, RI | C21: 81 | D21: Aug 10-14, 1996 | E21: 2900 | F21: Ecologists/Biologists as Problem-solvers
A22: 1995 | B22: Snowbird, UT | C22: 80 | D22: July 30-Aug 3, 1995 | E22: 2500 | F22: The Transdisciplinary Nature of Ecology
A23: 1994 | B23: Knoxville, TN | C23: 79 | D23: Aug 7-11, 1994 | F23: Science and Public Policy
A24: 1993 | B24: Madison, WI | C24: 78 | D24: July 31-Aug 4, 1993 | F24: Ecology and Global Sustainability
A25: 1992 | B25: Honolulu, HI | C25: 77 | D25: Aug 8-13, 1992 | F25: Voyagers
A26: 1991 | B26: San Antonio, TX | C26: 76 | D26: Aug 3-8, 1991 | F26: Education: The Future of Biology
A27: 1990 | B27: Snowbird, UT | C27: 75 | D27: July 29-Aug 1990 | F27: Perspectives in Ecology: Past, Present, and Future
A28: 1989 | B28: Toronto, Canada | C28: 74 | D28: Aug 6-10, 1989 | F28: Global Change
A29: 1988 | B29: Davis, CA | C29: 73 | D29: Aug 14-19, 1988 | F29: Biological Diversity
A30: 1987 | B30: Columbus, OH | C30: 72 | D30: Aug 9-13, 1987
A31: 1986 | B31: Syracuse, NY | C31: 71 | D31: Aug 10-16, 1986
A32: 1985 | B32: Minneapolis, MN | C32: 70 | D32: June 17-21, 1985 | F32: Conceptual Developments in Ecology
A33: 1984 | B33: Fort Collins, CO | C33: 69 | D33: Aug 5-9, 1984
A34: 1983 | B34: Fargo, ND | C34: 68 | D34: Aug 7-11, 1983
A35: 1982 | B35: University Park, PA | C35: 67 | D35: Aug 8-12, 1982
A36: 1981 | B36: Bloomington, IN | C36: 66 | D36: Aug 16-20, 1981
A37: 1980 | B37: Tucson, AZ | C37: 65 | D37: Aug 3-7 1980
A38: 1979 | B38: Stillwater, OK | C38: 64 | D38: Aug 12-17, 1979 | F38: Mid-American Grasslands--Prairie to Dustbowl to Present
A39: 1978 | B39: Athens, GA | C39: 63 | D39: Aug 20-24,1978 | F39: Nature of the Southeast in Transition
A40: 1977 | B40: East Lansing, MI | C40: 62 | D40: Aug 21-25, 1977
...

Sheet attendance
A1: =meetings_data!A1 -> Year | B1: =meetings_data!E1 -> Attend.
A2: =meetings_data!A2 -> 2015 | B2: =meetings_data!E2
A3: =meetings_data!A3 -> 2014 | B3: =meetings_data!E3
A4: =meetings_data!A4 -> 2013 | B4: =meetings_data!E4 -> 3363
A5: =meetings_data!A5 -> 2012 | B5: =meetings_data!E5 -> 4992
A6: =meetings_data!A6 -> 2011 | B6: =meetings_data!E6 -> 3721
A7: =meetings_data!A7 -> 2010 | B7: =meetings_data!E7 -> 3525
A8: =meetings_data!A8 -> 2009 | B8: =meetings_data!E8 -> 3648
A9: =meetings_data!A9 -> 2008 | B9: =meetings_data!E9 -> 3354
A10: =meetings_data!A10 -> 2007 | B10: =meetings_data!E10 -> 4185
A11: =meetings_data!A11 -> 2006 | B11: =meetings_data!E11 -> 2838
A12: =meetings_data!A12 -> 2005 | B12: =meetings_data!E12 -> 4359
... A102: =meetings_data!A102 -> 1915 | B102: =meetings_data!E102

Sheet meetings_map
A1: Locations | B1: Placeholder
A2: Baltimore, MD | B2: 1
A3: Sacramento, CA | B3: 1
A4: Minneapolis, MN | B4: 1
A5: Portland, OR | B5: 1
A6: Austin, TX | B6: 1
A7: Pittsburgh, PA | B7: 1
A8: Albuquerque, NM | B8: 1
A9: Milwaukee, WI | B9: 1
A10: San Jose, CA | B10: 1
A11: Memphis, TN | B11: 1
A12: Montreal, Canada | B12: 1
A13: Portland, OR | B13: 1
... A63: Cleveland, OH | B63: 1
B64: 1
A65: Dallas, TX | B65: 1
A66: Philadelphia, PA | B66: 1
A67: Richmond, VA | B67: 1
A68: Indianapolis, IN | B68: 1
A69: Atlantic City, NJ | B69: 1
A70: Pittsburgh, PA | B70: 1
A71: Des Moines, IA | B71: 1
A72: Nashville, TN | B72: 1
A73: Kansas City, MO | B73: 1
A74: Washington, DC | B74: 1
A75: Cincinnati, OH | B75: 1
A76: Baltimore, OH
