Workbook

Sheet Information
A2: Changes in senior management in the Claims department.
A4: Priority set to maintain adequate case outstanding.
A6: Management says that strength of current case outstanding is much greater than prior years.
A8: New information systems implementing during last 3 years have sped up reporting and settlement process.
A10: Tort reforms - management is reducing presence in this geographic area

Sheet Concerns
A1: What happened in AY 2003?
A2: Rept/EP | B2: Low at 12 and 24 month valuations
B4: Exposures | C4: Check exposure growth
D5: 7.7% increase in exposures.
B7: Paid & Rept | C7: Lower paid and reported at these periods is strange.
B8: Counts | D8: Change in systems processing?
B9: Counts & Avgs | D9: Unusually good loss experience?
E10: Both down 25% from prior AY
A12: What happened in AY 2004?
A13: Rept/EP | B13: Large after 24 months
B15: Premium | C15: Check premium growth
B17: Premium | C17: Spike in earned premium (and exposures)
B18: Paid | C18: Larger spike in paid losses
B19: Reported | C19: Huge spike in reported losses
D21: What is driving this?
B23: Severity | E23: Large loss activity?
B24: Counts | E24: More claim counts?
B25: Rsv/Open | E25: Change in reserve adequacy at 12/31/2005 valuation?
B27: Rept'd Count | D27: Reported count change 03 to 04 at 12: | H27: =Basic!B25/Basic!B24-1 -> 0.40713765
D28: Closed count change 03 to 04 at 12: | H28: =Basic!B35/Basic!B34-1 -> 0.29834254
D29: Reported claim change 03 to 04 at 12: | H29: =Basic!B5/Basic!B4-1 -> 0.76095741
D31: Reported count change 03 to 04 at 24: | H31: =Basic!C25/Basic!C24-1 -> 0.34158416 | J31: Why are claims increasing so much more
D32: Closed count change 03 to 04 at 24: | H32: =Basic!C35/Basic!C34-1 -> 0.38110749 | J32: than the number of claims? Could it be
D33: Reported claim change 03 to 04 at 24: | H33: =Basic!C15/Basic!C14-1 -> 0.58621795 | J33: due to large losses?
A35: What happened in AY 2005 and 2006?
B36: Reported losses are unusually high at 12 months.
B37: Exposures also increasing between 2004 and 2005
C39: 2004-2005 | D39: 2004-2006
B40: Exposures | C40: =Premiums!E7 -> 0.20951355 | D40: =(Premiums!B8/Premiums!B6)/((1+Premiums!C8)*(1+Premiums!C7))-1 -> -0.14377583
B41: Reported | C41: =Basic!B6/Basic!B5-1 -> 0.68720212 | D41: =Basic!B7/Basic!B5-1 -> 0.59258605
C43: Tort Reform?
B44: Reported | D44: Observe 24 month valuation
B45: Paid | D45: Higher reported and paid
B47: Dropping levels of exposures, reported, and paids after 2005.

Sheet Premiums
A1: Table 1 - Summary of Earned Premium and Rate Changes
C2: Rate | D2: Cumul Avg | E2: Annual | F2: Annual
A3: CY | B3: EP | C3: Change | D3: Rate Level | E3: Exp. Chg | F3: Prem Chg
A4: 2002 | B4: 61183 | D4: 0
A5: =A4+1 -> 2003 | B5: 69175 | C5: 0.05 | D5: =(1+C5)-1 -> 0.05 | E5: =(B5/B4)/(1+C5)-1 -> 0.076785257 | F5: =B5/B4-1 -> 0.13062452
A6: =A5+1 -> 2004 | B6: 99322 | C6: 0.075 | D6: =(1+D5)*(1+C6)-1 -> 0.12875 | E6: =(B6/B5)/(1+C6)-1 -> 0.3356351 | F6: =B6/B5-1 -> 0.43580773
A7: =A6+1 -> 2005 | B7: 138151 | C7: 0.15 | D7: =(1+D6)*(1+C7)-1 -> 0.2980625 | E7: =(B7/B6)/(1+C7)-1 -> 0.20951355 | F7: =B7/B6-1 -> 0.39094058
A8: =A7+1 -> 2006 | B8: 107578 | C8: 0.1 | D8: =(1+D7)*(1+C8)-1 -> 0.42786875 | E8: =(B8/B7)/(1+C8)-1 -> -0.29209212 | F8: =B8/B7-1 -> -0.22130133
A9: =A8+1 -> 2007 | B9: 62438 | C9: -0.2 | D9: =(1+D8)*(1+C9)-1 -> 0.142295 | E9: =(B9/B8)/(1+C9)-1 -> -0.27450315 | F9: =B9/B8-1 -> -0.41960252
A10: =A9+1 -> 2008 | B10: 47797 | C10: -0.2 | D10: =(1+D9)*(1+C10)-1 -> -0.086164 | E10: =(B10/B9)/(1+C10)-1 -> -0.043110766 | F10: =B10/B9-1 -> -0.23448861

Sheet Basic
A1: Table 2 - Reported Claim Development Triangle ($000)
A2: AY | B2: 12 | C2: =B2+12 -> 24 | D2: =C2+12 -> 36 | E2: =D2+12 -> 48 | F2: =E2+12 -> 60 | G2: =F2+12 -> 72 | H2: =G2+12 -> 84
A3: 2002 | B3: 12811 | C3: 20370 | D3: 26656 | E3: 37667 | F3: 44414 | G3: 48701 | H3: 48169
A4: =A3+1 -> 2003 | B4: 9651 | C4: 16995 | D4: 30354 | E4: 40594 | F4: 44231 | G4: 44373
A5: =A4+1 -> 2004 | B5: 16995 | C5: 40180 | D5: 58866 | E5: 71707 | F5: 70288
A6: =A5+1 -> 2005 | B6: 28674 | C6: 47432 | D6: 70340 | E6: 70655
A7: =A6+1 -> 2006 | B7: 27066 | C7: 46783 | D7: 48804
A8: =A7+1 -> 2007 | B8: 19477 | C8: 31732
A9: =A8+1 -> 2008 | B9: 18632
A11: Table 3 - Paid Claim Development Triangle ($000)
A12: AY | B12: 12 | C12: =B12+12 -> 24 | D12: =C12+12 -> 36 | E12: =D12+12 -> 48 | F12: =E12+12 -> 60 | G12: =F12+12 -> 72 | H12: =G12+12 -> 84
A13: 2002 | B13: 2318 | C13: 7932 | D13: 13822 | E13: 22095 | F13: 31945 | G13: 40629 | H13: 44437
A14: =A13+1 -> 2003 | B14: 1743 | C14: 6240 | D14: 12683 | E14: 22892 | F14: 34505 | G14: 39320
A15: =A14+1 -> 2004 | B15: 2221 | C15: 9898 | D15: 25950 | E15: 43439 | F15: 52811
A16: =A15+1 -> 2005 | B16: 3043 | C16: 12219 | D16: 27073 | E16: 40026
A17: =A16+1 -> 2006 | B17: 3531 | C17: 11778 | D17: 22819
A18: =A17+1 -> 2007 | B18: 3529 | C18: 11865
A19: =A18+1 -> 2008 | B19: 3409
A21: Table 8 - Reported Claim Count Development Triangle
A22: AY | B22: 12 | C22: =B22+12 -> 24 | D22: =C22+12 -> 36 | E22: =D22+12 -> 48 | F22: =E22+12 -> 60 | G22: =F22+12 -> 72 | H22: =G22+12 -> 84
A23: 2002 | B23: 1342 | C23: 1514 | D23: 1548 | E23: 1557 | F23: 1549 | G23: 1552 | H23: 1554
A24: =A23+1 -> 2003 | B24: 1373 | C24: 1616 | D24: 1630 | E24: 1626 | F24: 1629 | G24: 1629
A25: =A24+1 -> 2004 | B25: 1932 | C25: 2168 | D25: 2234 | E25: 2249 | F25: 2258
A26: =A25+1 -> 2005 | B26: 2067 | C26: 2293 | D26: 2367 | E26: 2390
A27: =A26+1 -> 2006 | B27: 1473 | C27: 1645 | D27: 1657
A28: =A27+1 -> 2007 | B28: 1192 | C28: 1264
A29: =A28+1 -> 2008 | B29: 1036
A31: Table 9 - Closed Claim Count Development Triangle (Excludes closed non-pay (CNP))
A32: AY | B32: 12 | C32: =B32+12 -> 24 | D32: =C32+12 -> 36 | E32: =D32+12 -> 48 | F32: =E32+12 -> 60 | G32: =F32+12 -> 72 | H32: =G32+12 -> 84
A33: 2002 | B33: 203 | C33: 607 | D33: 841 | E33: 1089 | F33: 1327 | G33: 1464 | H33: 1523
A34: =A33+1 -> 2003 | B34: 181 | C34: 614 | D34: 941 | E34: 1263 | F34: 1507 | G34: 1568
A35: =A34+1 -> 2004 | B35: 235 | C35: 848 | D35: 1442 | E35: 1852 | F35: 2029
A36: =A35+1 -> 2005 | B36: 295 | C36: 1119 | D36: 1664 | E36: 1946
A37: =A36+1 -> 2006 | B37: 307 | C37: 906 | D37: 1201
A38: =A37+1 -> 2007 | B38: 329 | C38: 791
A39: =A38+1 -> 2008 | B39: 276

Sheet Diagnostics
A1: Table 4 - Ratio of Reported Claims to Earned Premium
A2: AY | B2: 12 | C2: =B2+12 -> 24 | D2: =C2+12 -> 36 | E2: =D2+12 -> 48 | F2: =E2+12 -> 60 | G2: =F2+12 -> 72 | H2: =G2+12 -> 84
A3: 2002 | B3: =Basic!B3/Premiums!$B4 -> 0.20938823 | C3: =Basic!C3/Premiums!$B4 -> 0.33293562 | D3: =Basic!D3/Premiums!$B4 -> 0.43567658 | E3: =Basic!E3/Premiums!$B4 -> 0.61564487 | F3: =Basic!F3/Premiums!$B4 -> 0.7259206 | G3: =Basic!G3/Premiums!$B4 -> 0.79598908 | H3: =Basic!H3/Premiums!$B4 -> 0.78729386
A4: =A3+1 -> 2003 | B4: =Basic!B4/Premiums!$B5 -> 0.13951572 | C4: =Basic!C4/Premiums!$B5 -> 0.24568124 | D4: =Basic!D4/Premiums!$B5 -> 0.43880014 | E4: =Basic!E4/Premiums!$B5 -> 0.5868305 | F4: =Basic!F4/Premiums!$B5 -> 0.6394073 | G4: =Basic!G4/Premiums!$B5 -> 0.64146007
A5: =A4+1 -> 2004 | B5: =Basic!B5/Premiums!$B6 -> 0.17111013 | C5: =Basic!C5/Premiums!$B6 -> 0.4045428 | D5: =Basic!D5/Premiums!$B6 -> 0.59267836 | E5: =Basic!E5/Premiums!$B6 -> 0.72196492 | F5: =Basic!F5/Premiums!$B6 -> 0.70767806
A6: =A5+1 -> 2005 | B6: =Basic!B6/Premiums!$B7 -> 0.2075555 | C6: =Basic!C6/Premiums!$B7 -> 0.34333447 | D6: =Basic!D6/Premiums!$B7 -> 0.50915303 | E6: =Basic!E6/Premiums!$B7 -> 0.51143314
A7: =A6+1 -> 2006 | B7: =Basic!B7/Premiums!$B8 -> 0.25159419 | C7: =Basic!C7/Premiums!$B8 -> 0.43487516 | D7: =Basic!D7/Premiums!$B8 -> 0.45366153
A8: =A7+1 -> 2007 | B8: =Basic!B8/Premiums!$B9 -> 0.31194145 | C8: =Basic!C8/Premiums!$B9 -> 0.50821615
A9: =A8+1 -> 2008 | B9: =Basic!B9/Premiums!$B10 -> 0.38981526
A11: Table 5 - Ratio of Reported Claims to On-Level Earned Premium
A12: AY | B12: 12 | C12: =B12+12 -> 24 | D12: =C12+12 -> 36 | E12: =D12+12 -> 48 | F12: =E12+12 -> 60 | G12: =F12+12 -> 72 | H12: =G12+12 -> 84
A13: 2002 | B13: =Basic!B3/(Premiums!$B4*(1+Premiums!$D$10)/(1+Premiums!$D4)) -> 0.22913108 | C13: =Basic!C3/(Premiums!$B4*(1+Premiums!$D$10)/(1+Premiums!$D4)) -> 0.36432754 | D13: =Basic!D3/(Premiums!$B4*(1+Premiums!$D$10)/(1+Premiums!$D4)) -> 0.47675576 | E13: =Basic!E3/(Premiums!$B4*(1+Premiums!$D$10)/(1+Premiums!$D4)) -> 0.67369295 | F13: =Basic!F3/(Premiums!$B4*(1+Premiums!$D$10)/(1+Premiums!$D4)) -> 0.79436638 | G13: =Basic!G3/(Premiums!$B4*(1+Premiums!$D$10)/(1+Premiums!$D4)) -> 0.8710415 | H13: =Basic!H3/(Premiums!$B4*(1+Premiums!$D$10)/(1+Premiums!$D4)) -> 0.86152642
A14: =A13+1 -> 2003 | B14: =Basic!B4/(Premiums!$B5*(1+Premiums!$D$10)/(1+Premiums!$D5)) -> 0.16030394 | C14: =Basic!C4/(Premiums!$B5*(1+Premiums!$D$10)/(1+Premiums!$D5)) -> 0.2822884 | D14: =Basic!D4/(Premiums!$B5*(1+Premiums!$D$10)/(1+Premiums!$D5)) -> 0.50418254 | E14: =Basic!E4/(Premiums!$B5*(1+Premiums!$D$10)/(1+Premiums!$D5)) -> 0.67426981 | F14: =Basic!F4/(Premiums!$B5*(1+Premiums!$D$10)/(1+Premiums!$D5)) -> 0.73468069 | G14: =Basic!G4/(Premiums!$B5*(1+Premiums!$D$10)/(1+Premiums!$D5)) -> 0.73703932
A15: =A14+1 -> 2004 | B15: =Basic!B5/(Premiums!$B6*(1+Premiums!$D$10)/(1+Premiums!$D6)) -> 0.21135144 | C15: =Basic!C5/(Premiums!$B6*(1+Premiums!$D$10)/(1+Premiums!$D6)) -> 0.49968231 | D15: =Basic!D5/(Premiums!$B6*(1+Premiums!$D$10)/(1+Premiums!$D6)) -> 0.73206319 | E15: =Basic!E5/(Premiums!$B6*(1+Premiums!$D$10)/(1+Premiums!$D6)) -> 0.89175509 | F15: =Basic!F5/(Premiums!$B6*(1+Premiums!$D$10)/(1+Premiums!$D6)) -> 0.87410827
A16: =A15+1 -> 2005 | B16: =Basic!B6/(Premiums!$B7*(1+Premiums!$D$10)/(1+Premiums!$D7)) -> 0.29482315 | C16: =Basic!C6/(Premiums!$B7*(1+Premiums!$D$10)/(1+Premiums!$D7)) -> 0.487691 | D16: =Basic!D6/(Premiums!$B7*(1+Premiums!$D$10)/(1+Premiums!$D7)) -> 0.72322873 | E16: =Basic!E6/(Premiums!$B7*(1+Premiums!$D$10)/(1+Premiums!$D7)) -> 0.72646753
A17: =A16+1 -> 2006 | B17: =Basic!B7/(Premiums!$B8*(1+Premiums!$D$10)/(1+Premiums!$D8)) -> 0.39311593 | C17: =Basic!C7/(Premiums!$B8*(1+Premiums!$D$10)/(1+Premiums!$D8)) -> 0.67949244 | D17: =Basic!D7/(Premiums!$B8*(1+Premiums!$D$10)/(1+Premiums!$D8)) -> 0.70884614
A18: =A17+1 -> 2007 | B18: =Basic!B8/(Premiums!$B9*(1+Premiums!$D$10)/(1+Premiums!$D9)) -> 0.38992681 | C18: =Basic!C8/(Premiums!$B9*(1+Premiums!$D$10)/(1+Premiums!$D9)) -> 0.63527019
A19: =A18+1 -> 2008 | B19: =Basic!B9/(Premiums!$B10*(1+Premiums!$D$10)/(1+Premiums!$D10)) -> 0.38981526
A21: Table 6 - Ratio of Paid Claims-to-Reported Claims
A22: AY | B22: 12 | C22: =B22+12 -> 24 | D22: =C22+12 -> 36 | E22: =D22+12 -> 48 | F22: =E22+12 -> 60 | G22: =F22+12 -> 72 | H22: =G22+12 -> 84
A23: 2002 | B23: =Basic!B13/Basic!B3 -> 0.18093826 | C23: =Basic!C13/Basic!C3 -> 0.38939617 | D23: =Basic!D13/Basic!D3 -> 0.51853241 | E23: =Basic!E13/Basic!E3 -> 0.58658773 | F23: =Basic!F13/Basic!F3 -> 0.71925519 | G23: =Basic!G13/Basic!G3 -> 0.83425392 | H23: =Basic!H13/Basic!H3 -> 0.92252278
A24: =A23+1 -> 2003 | B24: =Basic!B14/Basic!B4 -> 0.18060305 | C24: =Basic!C14/Basic!C4 -> 0.36716681 | D24: =Basic!D14/Basic!D4 -> 0.4178362 | E24: =Basic!E14/Basic!E4 -> 0.5639257 | F24: =Basic!F14/Basic!F4 -> 0.78010897 | G24: =Basic!G14/Basic!G4 -> 0.88612445
A25: =A24+1 -> 2004 | B25: =Basic!B15/Basic!B5 -> 0.1306855 | C25: =Basic!C15/Basic!C5 -> 0.24634146 | D25: =Basic!D15/Basic!D5 -> 0.44083172 | E25: =Basic!E15/Basic!E5 -> 0.60578465 | F25: =Basic!F15/Basic!F5 -> 0.75135158
A26: =A25+1 -> 2005 | B26: =Basic!B16/Basic!B6 -> 0.10612401 | C26: =Basic!C16/Basic!C6 -> 0.2576109 | D26: =Basic!D16/Basic!D6 -> 0.38488769 | E26: =Basic!E16/Basic!E6 -> 0.56649919
A27: =A26+1 -> 2006 | B27: =Basic!B17/Basic!B7 -> 0.13045888 | C27: =Basic!C17/Basic!C7 -> 0.25175812 | D27: =Basic!D17/Basic!D7 -> 0.46756413
A28: =A27+1 -> 2007 | B28: =Basic!B18/Basic!B8 -> 0.18118807 | C28: =Basic!C18/Basic!C8 -> 0.37391277
A29: =A28+1 -> 2008 | B29: =Basic!B19/Basic!B9 -> 0.18296479
A31: Table 7 - Ratio of Cumulative Paid Claims to On-Level Earned Premium
A32: AY | B32: 12 | C32: =B32+12 -> 24 | D32: =C32+12 -> 36 | E32: =D32+12 -> 48 | F32: =E32+12 -> 60 | G32: =F32+12 -> 72 | H32: =G32+12 -> 84
A33: 2002 | B33: =Basic!B13/(Premiums!$B4*(1+Premiums!$D$10)/(1+Premiums!$D4)) -> 0.041458578 | C33: =Basic!C13/(Premiums!$B4*(1+Premiums!$D$10)/(1+Premiums!$D4)) -> 0.14186775 | D33: =Basic!D13/(Premiums!$B4*(1+Premiums!$D$10)/(1+Premiums!$D4)) -> 0.24721331 | E33: =Basic!E13/(Premiums!$B4*(1+Premiums!$D$10)/(1+Premiums!$D4)) -> 0.39518002 | F33: =Basic!F13/(Premiums!$B4*(1+Premiums!$D$10)/(1+Premiums!$D4)) -> 0.57135214 | G33: =Basic!G13/(Premiums!$B4*(1+Premiums!$D$10)/(1+Premiums!$D4)) -> 0.72666978 | H33: =Basic!H13/(Premiums!$B4*(1+Premiums!$D$10)/(1+Premiums!$D4)) -> 0.79477775
A34: =A33+1 -> 2003 | B34: =Basic!B14/(Premiums!$B5*(1+Premiums!$D$10)/(1+Premiums!$D5)) -> 0.028951379 | C34: =Basic!C14/(Premiums!$B5*(1+Premiums!$D$10)/(1+Premiums!$D5)) -> 0.10364693 | D34: =Basic!D14/(Premiums!$B5*(1+Premiums!$D$10)/(1+Premiums!$D5)) -> 0.21066571 | E34: =Basic!E14/(Premiums!$B5*(1+Premiums!$D$10)/(1+Premiums!$D5)) -> 0.38023808 | F34: =Basic!F14/(Premiums!$B5*(1+Premiums!$D$10)/(1+Premiums!$D5)) -> 0.573131 | G34: =Basic!G14/(Premiums!$B5*(1+Premiums!$D$10)/(1+Premiums!$D5)) -> 0.65310856
A35: =A34+1 -> 2004 | B35: =Basic!B15/(Premiums!$B6*(1+Premiums!$D$10)/(1+Premiums!$D6)) -> 0.027620568 | C35: =Basic!C15/(Premiums!$B6*(1+Premiums!$D$10)/(1+Premiums!$D6)) -> 0.12309247 | D35: =Basic!D15/(Premiums!$B6*(1+Premiums!$D$10)/(1+Premiums!$D6)) -> 0.32271668 | E35: =Basic!E15/(Premiums!$B6*(1+Premiums!$D$10)/(1+Premiums!$D6)) -> 0.54021155 | F35: =Basic!F15/(Premiums!$B6*(1+Premiums!$D$10)/(1+Premiums!$D6)) -> 0.65676263
A36: =A35+1 -> 2005 | B36: =Basic!B16/(Premiums!$B7*(1+Premiums!$D$10)/(1+Premiums!$D7)) -> 0.031287817 | C36: =Basic!C16/(Premiums!$B7*(1+Premiums!$D$10)/(1+Premiums!$D7)) -> 0.12563452 | D36: =Basic!D16/(Premiums!$B7*(1+Premiums!$D$10)/(1+Premiums!$D7)) -> 0.27836184 | E36: =Basic!E16/(Premiums!$B7*(1+Premiums!$D$10)/(1+Premiums!$D7)) -> 0.41154327
A37: =A36+1 -> 2006 | B37: =Basic!B17/(Premiums!$B8*(1+Premiums!$D$10)/(1+Premiums!$D8)) -> 0.051285463 | C37: =Basic!C17/(Premiums!$B8*(1+Premiums!$D$10)/(1+Premiums!$D8)) -> 0.17106774 | D37: =Basic!D17/(Premiums!$B8*(1+Premiums!$D$10)/(1+Premiums!$D8)) -> 0.33143103
A38: =A37+1 -> 2007 | B38: =Basic!B18/(Premiums!$B9*(1+Premiums!$D$10)/(1+Premiums!$D9)) -> 0.070650085 | C38: =Basic!C18/(Premiums!$B9*(1+Premiums!$D$10)/(1+Premiums!$D9)) -> 0.23753564
A39: =A38+1 -> 2008 | B39: =Basic!B19/(Premiums!$B10*(1+Premiums!$D$10)/(1+Premiums!$D10)) -> 0.071322468
A41: Table 10 - Ratio of Closed-to-Reported Claim Counts
A42: AY | B42: 12 | C42: =B42+12 -> 24 | D42: =C42+12 -> 36 | E42: =D42+12 -> 48 | F42: =E42+12 -> 60 | G42: =F42+12 -> 72 | H42: =G42+12 -> 84
A43: 2002 | B43: =Basic!B33/Basic!B23 -> 0.15126677 | C43: =Basic!C33/Basic!C23 -> 0.4009247 | D43: =Basic!D33/Basic!D23 -> 0.54328165 | E43: =Basic!E33/Basic!E23 -> 0.69942197 | F43: =Basic!F33/Basic!F23 -> 0.85668173 | G43: =Basic!G33/Basic!G23 -> 0.94329897 | H43: =Basic!H33/Basic!H23 -> 0.98005148
A44: =A43+1 -> 2003 | B44: =Basic!B34/Basic!B24 -> 0.13182811 | C44: =Basic!C34/Basic!C24 -> 0.3799505 | D44: =Basic!D34/Basic!D24 -> 0.57730061 | E44: =Basic!E34/Basic!E24 -> 0.77675277 | F44: =Basic!F34/Basic!F24 -> 0.92510743 | G44: =Basic!G34/Basic!G24 -> 0.96255371
...
