Workbook
Name AllowFundHlook: 'Linked Program Codes'!$B$6:$W$7
Name AllowProg: 'Linked Program Codes'!$A$8:$W$53
Name CertBen: 'Staff Details'!$AA$11:$AA$201
Name CertFund: 'Staff Details'!$A$11:$A$201
Name CertGrant: 'Staff Details'!$I$11:$I$201
Name CertObj: 'Staff Details'!$G$11:$G$201
Name CertProg: 'Staff Details'!$E$11:$E$201
Name CertSalary: 'Staff Details'!$R$11:$R$201
Name ERRORRPT: #REF!
Name Fund22Grants: 'Fund 20 Grants'!$D$3:$W$3
Name Fund22Grants: 'Fund 22 Grants'!$D$3:$W$3
Name MINRESERVE: #REF!
Name PAGE01: #REF!
Name PAGE02: #REF!
Name PAGE03: #REF!
Name PAGE04: #REF!
Name PAGE05: #REF!
Name PAGE06: #REF!
Name PAGE07: #REF!
Name PAGE08: #REF!
Name PAGE09: #REF!
Name PAGE10: #REF!
Name PAGE11: #REF!
Name PAGE12: #REF!
Name PAGE13: #REF!
Name PAGE14: #REF!
Name PAGE15: #REF!
Name PAGE16: #REF!
Name page17: #REF!
Name PAGE18: #REF!
Name PAGE19: #REF!
Name PAGE20: #REF!
Name PAGE21: #REF!
Name PAGE22: #REF!
Name PAGE23: #REF!
Name printjob1: #REF!,#REF!,#REF!,#REF!,#REF!,#REF!,#REF!,#REF!,#REF!,#REF!,#REF!
Name printjob2: #REF!,#REF!,#REF!,#REF!,#REF!,#REF!,#REF!,#REF!,#REF!,#REF!,#REF!
Name printjob3: #REF!,#REF!
Name printsumm: #REF!,#REF!,#REF!,#REF!,#REF!
Name printtabor: #REF!,#REF!,#REF!
Name SPENDLIM: #REF!
Name SUMM01: #REF!
Name SUMM02: #REF!
Name SUMM03: #REF!
Name SUMM04: #REF!
Name SUMM05: #REF!
Name TAXLIM: #REF!

Sheet General Instructions
A1: GENERAL INSTRUCTIONS
A4: 1. | B4: Please enter information in the cells with Blue Text. Do not use decimals when entering data in the CDE-18 report.
B6: Cells that are gray are protected cells and can not be modified.
A9: 2. | B9: In cell B5, F5, C7and F7 on page 1, enter the header information exactly as it is to appears below.
B10: DISTRICT NAME: ALAMOSA RE-11J
B11: COUNTY: ALAMOSA
B12: ESTIMATED FUNDED PUPIL COUNT: 3000
B13: FOUR DIGIT DISTRICT/BOCES CODE: 0100
A16: 3. | B16: The "Salary Schedule" tab has been added for you to provide your master salary schedule for this workbook.
B17: The information on the "Salary Schedule" tab will be available to use on the "Staff Details" tab
A20: 4. | B20: The "Linked Program Codes" lets you know which fund - program combination will be linked to be various fund tab
B21: through the "Staff Details" tab.
A24: 5. | B24: Complete the "Staff Details" tab with staff that meet the valid fund - program combination for linkage to the various
B25: fund tabs in this workbook.
B26: If a cell is "Pink" is input is not valid and must be fixed.
B27: The "Salary" column of the "Staff Details" tab may be modified if needed, by overwriting the cell input.
B28: Columns highlighted in "Rose" are linked to the various fund tabs in this workbook.
A31: 6. | B31: After the data is provided on the "Staff Details" tab, the Fund 22 Grants must be
B32: identified and added to row 3 of the "Fund 22 Grants" tab.
B33: Also , add the grant description to row 4 of the "Fund 22 Grants" tab.
A36: 7. | B36: Complete the CDE-18 pages for funds that only pertain to your district
B38: You may "Hide" sheets that you are not using - under "Format", "Sheet", "Hide"
B39: You may "Hide" rows or columns that you are not using - under "Format", "Row" or "Column", "Hide"
B40: Be careful that no data is reflected on the hidden sheets.
A43: 8. | B43: After completing the CDE-18 -review the error report. Make appropriate corrections to fund pages to correct errors.
A46: 9. | B46: Additional worksheets to assist you in the budget process
B47: TABOR Worksheets (2 pages)
B48: Consolidated Budget Summary (6 pages)
A51: 10. | B51: Budget Adoption and Appropriations Resolution
A54: 11 | B54: Summary Budget Form page is generated based on the data provided within this workbook.

Sheet Page 1 - FY2013-14
A1: FISCAL YEAR 2013-2014
A2: COLORADO SCHOOL DISTRICT/BOCES
A3: OPTIONAL REPORT OF ADOPTED BUDGET - FORM CDE-18
A5: FOR SCHOOL DISTRICT (NAME) | E5: HEADQUARTERED IN (COUNTY)
A6: OR BOCES
A7: ESTIMATED FUNDED PUPIL COUNT FOR USE IN BUDGET YEAR 2013-2014 | E7: FOUR DIGIT DISTRICT/BOCES CODE
A11: CONTENTS
A12: Fund Type & | E12: Fund Type &
A13: Fund Number | E13: Fund Number
A14: 10 General Fund Revenue . . . . . . . . . . . . . . . . . . . . . . . . . . . . . . . . . . . . . . . . . . . . . . . . . . . . . . . . . . . . . . . . . . . . . . . . | E14: Internal Service Funds:
A15: 10 General Fund Expenditures . . . . . . . . . . . . . . . . . . . . . . . . . . . . . . . . . . . . . . . . . . . . . . . . . . . . . . . . . . . . . . . . . . | E15: 64 Risk-Related Activity Fund . . . . . . . . . . . . . . . . . . . . . . . . . . . . . . . . . . . . . . . . . . . . . . . . . . . . . . . . . . . . . . . . . . . . . . . .
A16: 11 Charter Fund Revenue . . . . . . . . . . . . . . . . . . . . . . . . . . . . . . . . . . . . . . . . . . . . . . . . . . . . . . . . . . . . . . | E16: Note: Fund 63 may be used as another risk-related activity fund. It will roll to Fund 64
A17: 11 Charter Fund Expenditures . . . . . . . . . . . . . . . . . . . . . . . . . . . . . . . . . . . . . . . . . . . . . . . . . . . . . . . . | E17: 61-62 & 65-69 Other Internal Service Funds . . . . . . . . . . . . . . . . . . . . . . . . . . . . . . . . . . . . . . . . . . . . . . . . . . . . . . . . . . . . . . . . . . . . . .
A18: 18 Insurance Reserve Special Revenue Fund. . . . . . . . . . . . . . . . . . . . . . . . . . . . . . . . . . . . . . . . . . . . . . . . . . . . . . . | E18: Trust/Agency Funds:
A19: 19 Colorado Preschool Fund. . . . . . . . . . . . . . . . . . . . . . . . . . . . . . . . . . . . . . . . . . . . . . . . . . . . . . . . . . . . . . . . . | E19: 74 Pupil Activity Agency Fund . . . . . . . . . . . . . . . . . . . . . . . . . . . . . . . . . . . . . . . . . . . . . . . . . . . . .
A20: Special Revenue Funds: | E20: 71-73 & 75-79 Trust and Other Agency Funds . . . . . . . . . . . . . . . . . . . . . . . . . . . . . . . . . . . . . . . . . . . . . . . . . . . . . . . . . . . . .
A21: 20 ARRA (Federal Stimulus Funding) Grants Fund . . . . . . . . . . . . . . . . . . . . . . . . . . . . . . . . . . . . . . . . . . . .
A22: 21 Capital Reserve Special Revenue Fund . . . . . . . . . . . . . . . . . . . . . . . . . . . . . . . . . . . . . . . . . . . . . . . . | E22: 85 Foundation Fund . . . . . . . . . . . . . . . . . . . . . . . . . . . . . . . . . . . . . . . . . . . . . . . . . . . . . . . . . . . . . . . . . .
A23: 22 Governmental Designated-Purpose Grants Fund. . . . . . . . . . . . . . . . . . . . . . . . . . . . . . . . . . . . . . . . . | E23: GASB 34 . . . . . . . . . . . . . . . . . . . . . . . . . . . . . . . . . . . . . . . . . . . . . . . . . . . . . . . . . . . . . . . . . . . . . . . . . . .
A24: 23 Pupil Activity Special Revenue Fund . . . . . . . . . . . . . . . . . . . . . . . . . . . . . . . . . . . . . . . . . . . . . . . . . . . . . . . . . . . . | E24: District Debt . . . . . . . . . . . . . . . . . . . . . . . . . . . . . . . . . . . . . . . . . . . . . . . . . . . . . . . . . . . . . . . . . . . . . .
A25: 24 Full-Day Kindergarten Mill Levy Override Fund. . . . . . . . . . . . . . . . . . . . . . . . . . . . . . . . . . . . . . .
A26: 25 Transportation Fund . . . . . . . . . . . . . . . . . . . . . . . . . . . . . . . . . . . . . . . . . . . . . . . . . . . . . . . . . . . . . . . . .
A27: 26-29 Other Special Revenue Funds . . . . . . . . . . . . . . . . . . . . . . . . . . . . . . . . . . . . . . . . . . . . . . . . . . . . . . . . .
A28: Debt Service Fund: | E28: Miscellaneous Worksheets: (USE WHEN RELEVANT)
A29: 31 Bond Redemption Fund . . . . . . . . . . . . . . . . . . . . . . . . . . . . . . . . . . . . . . . . . . . . . . . . . . . . . . . . . . . . . . . . . . . . . | E29: Arbitrage Rebate Amount . . . . . . . . . . . . . . . . . . . . . . . . . . . . . . . . . . . . . . . . . . . . . . . . . . . . . . . . . . . . . . . . . . . . . .
A30: 39 Non-Voter Approved Debt Service Fund . . . . . . . . . . . . . . . . . . . . . . . . . . . . . . . . . . . . . . . . . . . . . . . . . . . . . . . . . . . . . . . . . . . . . | E30: Arbitrage Rebate Amount . . . . . . . . . . . . . . . . . . . . . . . . . . . . . . . . . . . . . . . . . . . . . . . . . . . . . . . . . . . . . . . . . . . . . .
A31: Capital Projects Funds: | E31: Component Unit Revenues and Expenditures/Expenses . . . . . . . . . . . . . . . . . . . . . . . . . . . . . . . . . . .
A32: 41 Building Fund . . . . . . . . . . . . . . . . . . . . . . . . . . . . . . . . . . . . . . . . . . . . . . . . . . . . . . . . . . . . . . . . . . . . . . . . . . . . | E32: TABOR Emergency Reserves . . . . . . . . . . . . . . . . . . . . . . . . . . . . . . . . . . . . . . . . . . . . . . . . . . . . . . . . . . . . . . .
A33: 42 Special Building and Technology Fund . . . . . . . . . . . . . . . .. . . . . . . . . . . . . . . . . . . . . . . . . . . . . . . . . . . . . . . . . | E33: Appropriation Resolution. . . . . . . . . . . . . . . . . . . . . . . . . . . . . . . . . . . . . . . . . . . . . . . . . . . . . . . . . . . . . . . . . . . .
A34: 43 Capital Reserve Capital Projects Fund . . . . . . . . . . . . . . . . . . . . . . . . . . . . . . . . . . . . . . . . . . . . . . . . . . . . . . . . . . . . . . . . . . . | E34: Error Report . . . . . . . . . . . . . . . . . . . . . . . . . . . . . . . . . . . . . . . . . . . . . . . . . . . . .
A35: Enterprise Funds: | E35: Tabor Compliance Worksheet. . . . . . . . . . . . . . . . . . . . . . . . . . . . . . . . . . . . . . . . . . . . . . . . . . . . . . . . . . . . . . .
A36: 51 Food Service Fund . . . . . . . . . . . . . . . . . . . . . . . . . . . . . . . . . . . . . . . . . . . . . . . . . . . . . . . . . . . . . . . . . . . . . . . . . | E36: Summary Information:
A37: 52-59 Other Enterprise Funds . . . . . . . . . . . . . . . . . . . . . . . . . . . . . . . . . . . . . . . . . . . . . . . . . . . . . . . . . . . . . . . . . . . . . . . | E37: Budget Summary Worksheet (District Use Only) . . . . . . . . . . . . . . . . . . . . . . . . . . . . . . . . . . . . . . . . . . . . . . . . .
A39: NAME AND TITLE OF PERSON(S) TO CONTACT IN THE EVENT THERE ARE QUESTIONS REGARDING THIS REPORT:
A41: NAME | E41: TITLE
A43: PHONE | E43: FAX
A45: E-MAIL

Sheet Salary Schedule
B1: School District | D1: =+'Page 1 - FY2013-14'!B5 -> 0 | J1: District Code | K1: =+'Page 1 - FY2013-14'!F7 -> 0
B2: School District
B3: Salary Schedule for Certified Staff
B4: FY 2013-2014
B5: Directions:
B6: Insert the BASE amount in cell C11
B7: Insert the Step Increase amount (DOWN) in cell C12
B8: Insert the Education Level increase amount (ACROSS) in cell C13
B9: Insert the Step increase amount for Education Level at MA or higher (MA-DOWN) in cell C14
B11: S D | C11: BASE | D11: 0
B12: T O | C12: DOWN | D12: 0 | F12: Note: Do not change the size or location of this schedule, will impact linkage.
B13: E W | C13: ACROSS | D13: 0
B14: P N | C14: MA-DOWN | D14: 0
C15: 1 | D15: 2 | E15: 3 | F15: 4 | G15: 5 | H15: 6 | I15: 7 | J15: 8 | K15: 9 | L15: 10 | M15: 11 | N15: 12
C16: BA | D16: BA+12 | E16: BA+24 | F16: BA+36 | G16: BA+45 | H16: MA | I16: MA+12 | J16: MA+24 | K16: MA+36 | L16: MA+45 | M16: SPECED | N16: ED
B17: 0 | C17: =+$D$11 -> 0 | D17: =+C17+$D$13 -> 0 | E17: =+D17+$D$13 -> 0 | F17: =+E17+$D$13 -> 0 | G17: =+F17+$D$13 -> 0 | H17: =+G17+$D$13 -> 0 | I17: =+H17+$D$13 -> 0 | J17: =+I17+$D$13 -> 0 | K17: =+J17+$D$13 -> 0 | ... N17: =+M17+$D$13 -> 0
B18: 1 | C18: =+C17+$D$12 -> 0 | D18: =+D17+$D$12 -> 0 | E18: =+E17+$D$12 -> 0 | F18: =+F17+$D$12 -> 0 | G18: =+G17+$D$12 -> 0 | H18: =+H17+$D$14 -> 0 | I18: =+I17+$D$14 -> 0 | J18: =+J17+$D$14 -> 0 | K18: =+K17+$D$14 -> 0 | L18: =+L17+$D$14 -> 0 | M18: =+M17+$D$14 -> 0 | N18: =+N17+$D$14 -> 0
B19: 2 | C19: =+C18+$D$12 -> 0 | D19: =+D18+$D$12 -> 0 | E19: =+E18+$D$12 -> 0 | F19: =+F18+$D$12 -> 0 | G19: =+G18+$D$12 -> 0 | H19: =+H18+$D$14 -> 0 | I19: =+I18+$D$14 -> 0 | J19: =+J18+$D$14 -> 0 | K19: =+K18+$D$14 -> 0 | L19: =+L18+$D$14 -> 0 | M19: =+M18+$D$14 -> 0 | N19: =+N18+$D$14 -> 0
B20: 3 | C20: =+C19+$D$12 -> 0 | D20: =+D19+$D$12 -> 0 | E20: =+E19+$D$12 -> 0 | F20: =+F19+$D$12 -> 0 | G20: =+G19+$D$12 -> 0 | H20: =+H19+$D$14 -> 0 | I20: =+I19+$D$14 -> 0 | J20: =+J19+$D$14 -> 0 | K20: =+K19+$D$14 -> 0 | L20: =+L19+$D$14 -> 0 | M20: =+M19+$D$14 -> 0 | N20: =+N19+$D$14 -> 0
B21: 4 | C21: =+C20+$D$12 -> 0 | D21: =+D20+$D$12 -> 0 | E21: =+E20+$D$12 -> 0 | F21: =+F20+$D$12 -> 0 | G21: =+G20+$D$12 -> 0 | H21: =+H20+$D$14 -> 0 | I21: =+I20+$D$14 -> 0 | J21: =+J20+$D$14 -> 0 | K21: =+K20+$D$14 -> 0 | L21: =+L20+$D$14 -> 0 | M21: =+M20+$D$14 -> 0 | N21: =+N20+$D$14 -> 0
B22: 5 | C22: =+C21+$D$12 -> 0 | D22: =+D21+$D$12 -> 0 | E22: =+E21+$D$12 -> 0 | F22: =+F21+$D$12 -> 0 | G22: =+G21+$D$12 -> 0 | H22: =+H21+$D$14 -> 0 | I22: =+I21+$D$14 -> 0 | J22: =+J21+$D$14 -> 0 | K22: =+K21+$D$14 -> 0 | L22: =+L21+$D$14 -> 0 | M22: =+M21+$D$14 -> 0 | N22: =+N21+$D$14 -> 0
B23: 6 | C23: =+C22+$D$12 -> 0 | D23: =+D22+$D$12 -> 0 | E23: =+E22+$D$12 -> 0 | F23: =+F22+$D$12 -> 0 | G23: =+G22+$D$12 -> 0 | H23: =+H22+$D$14 -> 0 | I23: =+I22+$D$14 -> 0 | J23: =+J22+$D$14 -> 0 | K23: =+K22+$D$14 -> 0 | L23: =+L22+$D$14 -> 0 | M23: =+M22+$D$14 -> 0 | N23: =+N22+$D$14 -> 0
B24: 7 | C24: =+C23+$D$12 -> 0 | D24: =+D23+$D$12 -> 0 | E24: =+E23+$D$12 -> 0 | F24: =+F23+$D$12 -> 0 | G24: =+G23+$D$12 -> 0 | H24: =+H23+$D$14 -> 0 | I24: =+I23+$D$14 -> 0 | J24: =+J23+$D$14 -> 0 | K24: =+K23+$D$14 -> 0 | L24: =+L23+$D$14 -> 0 | M24: =+M23+$D$14 -> 0 | N24: =+N23+$D$14 -> 0
B25: 8 | C25: =+C24+$D$12 -> 0 | D25: =+D24+$D$12 -> 0 | E25: =+E24+$D$12 -> 0 | F25: =+F24+$D$12 -> 0 | G25: =+G24+$D$12 -> 0 | H25: =+H24+$D$14 -> 0 | I25: =+I24+$D$14 -> 0 | J25: =+J24+$D$14 -> 0 | K25: =+K24+$D$14 -> 0 | L25: =+L24+$D$14 -> 0 | M25: =+M24+$D$14 -> 0 | N25: =+N24+$D$14 -> 0
B26: 9 | C26: =+C25+$D$12 -> 0 | D26: =+D25+$D$12 -> 0 | E26: =+E25+$D$12 -> 0 | F26: =+F25+$D$12 -> 0 | G26: =+G25+$D$12 -> 0 | H26: =+H25+$D$14 -> 0 | I26: =+I25+$D$14 -> 0 | J26: =+J25+$D$14 -> 0 | K26: =+K25+$D$14 -> 0 | L26: =+L25+$D$14 -> 0 | M26: =+M25+$D$14 -> 0 | N26: =+N25+$D$14 -> 0
B27: 10 | C27: =+C26+$D$12 -> 0 | D27: =+D26+$D$12 -> 0 | E27: =+E26+$D$12 -> 0 | F27: =+F26+$D$12 -> 0 | G27: =+G26+$D$12 -> 0 | H27: =+H26+$D$14 -> 0 | I27: =+I26+$D$14 -> 0 | J27: =+J26+$D$14 -> 0 | K27: =+K26+$D$14 -> 0 | L27: =+L26+$D$14 -> 0 | M27: =+M26+$D$14 -> 0 | N27: =+N26+$D$14 -> 0
B28: 11 | C28: =+C27+$D$12 -> 0 | D28: =+D27+$D$12 -> 0 | E28: =+E27+$D$12 -> 0 | F28: =+F27+$D$12 -> 0 | G28: =+G27+$D$12 -> 0 | H28: =+H27+$D$14 -> 0 | I28: =+I27+$D$14 -> 0 | J28: =+J27+$D$14 -> 0 | K28: =+K27+$D$14 -> 0 | L28: =+L27+$D$14 -> 0 | M28: =+M27+$D$14 -> 0 | N28: =+N27+$D$14 -> 0
B29: 12 | C29: =+C28+$D$12 -> 0 | D29: =+D28+$D$12 -> 0 | E29: =+E28+$D$12 -> 0 | F29: =+F28+$D$12 -> 0 | G29: =+G28+$D$12 -> 0 | H29: =+H28+$D$14 -> 0 | I29: =+I28+$D$14 -> 0 | J29: =+J28+$D$14 -> 0 | K29: =+K28+$D$14 -> 0 | L29: =+L28+$D$14 -> 0 | M29: =+M28+$D$14 -> 0 | N29: =+N28+$D$14 -> 0
... B47: 30 | C47: =+C46+$D$12 -> 0 | D47: =+D46+$D$12 -> 0 | E47: =+E46+$D$12 -> 0 | F47: =+F46+$D$12 -> 0 | G47: =+G46+$D$12 -> 0 | H47: =+H46+$D$14 -> 0 | I47: =+I46+$D$14 -> 0 | J47: =+J46+$D$14 -> 0 | K47: =+K46+$D$14 -> 0 | L47: =+L46+$D$14 -> 0 | M47: =+M46+$D$14 -> 0 | N47: =+N46+$D$14 -> 0

Sheet Linked Program Codes
A1: School District | C1: =+'Page 1 - FY2013-14'!B5 -> 0 | I1: District Code | K1: =+'Page 1 - FY2013-14'!F7 -> 0
A2: School District
A3: Program Codes that are Linked to the Fund Tabs through Staff Details Page
A4: FY 2013-2014
B5: Fund:
B6: 10 | C6: 11 | D6: 18 | E6: 19 | F6: 20 | G6: 21 | H6: 22 | I6: 23 | J6: 24 | K6: 25 | L6: 26-29 | M6: 31 | N6: 41 | O6: 42 | P6: 43 | Q6: 51 | R6: 52-59 | S6: 64 | T6: 61-62/65-69 | U6: 74 | V6: 72-73/75-78 | W6: 85
A7: Program: | B7: 2 | C7: 3 | D7: 4 | E7: 5 | F7: 6 | G7: 7 | H7: 8 | I7: 9 | J7: 10 | K7: 11 | L7: 12 | M7: 13 | N7: 14 | O7: 15 | P7: 16 | Q7: 17 | R7: 18 | S7: 19 | T7: 20 | U7: 21 | V7: 22 | W7: 23
A8: 0010 | B8: 0010 | C8: 0010 | D8: N/A | E8: N/A | F8: 0010 | G8: N/A | H8: 0010 | I8: N/A | J8: 0010 | K8: N/A | L8: N/A | M8: N/A | N8: N/A | O8: N/A | P8: N/A | Q8: N/A | R8: N/A | S8: N/A | T8: N/A | U8: N/A | V8: N/A | W8: N/A
A9: 0020 | B9: 0020 | C9: 0020 | D9: N/A | E9: N/A | F9: 0020 | G9: N/A | H9: 0020 | I9: N/A | J9: N/A | K9: N/A | L9: N/A | M9: N/A | N9: N/A | O9: N/A | P9: N/A | Q9: N/A | R9: N/A | S9: N/A | T9: N/A | U9: N/A | V9: N/A | W9: N/A
A10: 0030 | B10: 0030 | C10: 0030 | D10: N/A | E10: N/A | F10: N/A | G10: N/A | H10: N/A | I10: N/A | J10: N/A | K10: N/A | L10: N/A | M10: N/A | N10: N/A | O10: N/A | P10: N/A | Q10: N/A | R10: N/A | S10: N/A | T10: N/A | U10: N/A | V10: N/A | W10: N/A
A11: 0040 | B11: 0040 | C11: 0040 | D11: N/A | E11: 0040 | F11: N/A | G11: N/A | H11: N/A | I11: N/A | J11: N/A | K11: N/A | L11: N/A | M11: N/A | N11: N/A | O11: N/A | P11: N/A | Q11: N/A | R11: N/A | S11: N/A | T11: N/A | U11: N/A | V11: N/A | W11: N/A
A12: 0050 | B12: 0050 | C12: 0050 | D12: N/A | E12: N/A | F12: N/A | G12: N/A | H12: N/A | I12: N/A | J12: N/A | K12: N/A | L12: N/A | M12: N/A | N12: N/A | O12: N/A | P12: N/A | Q12: N/A | R12: N/A | S12: N/A | T12: N/A | U12: N/A | V12: N/A | W12: N/A
A13: 0051 | B13: 0051 | C13: 0051 | D13: N/A | E13: N/A | F13: N/A | G13: N/A | H13: N/A | I13: N/A | J13: N/A | K13: N/A | L13: N/A | M13: N/A | N13: N/A | O13: N/A | P13: N/A | Q13: N/A | R13: N/A | S13: N/A | T13: N/A | U13: N/A | V13: N/A | W13: N/A
A14: 0060 | B14: 0060 | C14: 0060 | D14: N/A | E14: N/A | F14: 0060 | G14: N/A | H14: 0060 | I14: N/A | J14: N/A | K14: N/A | L14: N/A | M14: N/A | N14: N/A | O14: N/A | P14: N/A | Q14: N/A | R14: N/A | S14: N/A | T14: N/A | U14: N/A | V14: N/A | W14: N/A
A15: 0070 | B15: 0070 | C15: 0070 | D15: N/A | E15: N/A | F15: N/A | G15: N/A | H15: N/A | I15: N/A | J15: N/A | K15: N/A | L15: N/A | M15: N/A | N15: N/A | O15: N/A | P15: N/A | Q15: N/A | R15: N/A | S15: N/A | T15: N/A | U15: N/A | V15: N/A | W15: N/A
A16: 0080 | B16: 0080 | C16: 0080 | D16: N/A | E16: N/A | F16: N/A | G16: N/A | H16: N/A | I16: N/A | J16: N/A | K16: N/A | L16: N/A | M16: N/A | N16: N/A | O16: N/A | P16: N/A | Q16: N/A | R16: N/A | S16: N/A | T16: N/A | U16: N/A | V16: N/A | W16: N/A
A17: 0090 | B17: 0090 | C17: 0090 | D17: N/A | E17: N/A | F17: N/A | G17: N/A | H17: N/A | I17: N/A | J17: N/A | K17: N/A | L17: N/A | M17: N/A | N17: N/A | O17: N/A | P17: N/A | Q17: N/A | R17: N/A | S17: N/A | T17: N/A | U17: N/A | V17: N/A | W17: N/A
A18: 0100 | B18: 0100 | C18: 0100 | D18: N/A | E18: N/A | F18: N/A | G18: N/A | H18: N/A | I18: N/A | J18: N/A | K18: N/A | L18: N/A | M18: N/A | N18: N/A | O18: N/A | P18: N/A | Q18: N/A | R18: N/A | S18: N/A | T18: N/A | U18: N/A | V18: N/A | W18: N/A
A19: 0200 | B19: 0200 | C19: 0200 | D19: N/A | E19: N/A | F19: N/A | G19: N/A | H19: N/A | I19: N/A | J19: N/A | K19: N/A | L19: N/A | M19: N/A | N19: N/A | O19: N/A | P19: N/A | Q19: N/A | R19: N/A | S19: N/A | T19: N/A | U19: N/A | V19: N/A | W19: N/A
... A53: 4000 | B53: 4000 | C53: 4000 | D53: N/A | E53: N/A | F53: N/A | G53: N/A | H53: N/A | I53: N/A | J53: N/A | K53: N/A | L53: N/A | M53: N/A | N53: N/A | O53: N/A | P53: N/A | Q53: N/A | R53: N/A | S53: N/A | T53: N/A | U53: N/A | V53: N/A | W53: N/A

Sheet Staff Details
A1: School District | C1: =+'Page 1 - FY2013-14'!B5 -> 0 | J1: District Code | K1: =+'Page 1 - FY2013-14'!F7 -> 0
S3: 0.1015 | T3: 0.07 | U3: 0.0145 | V3: 300 | W3: Amount per month towards insurances
L4: FY2013-2014 | S4: 0.1015 | T4: 0.07 | U4: 0.0145
A5: State Account Number | L5: Salary Schedule | R5: PROPOSED SALARY AND BENEFITS FY2011-2012 | AA5: Total | AB5: Total
E6: Bolded | F6: Salary | G6: Bolded | H6: Job | I6: Grant | L6: Education | M6: Step - | N6: Salary Schedule | O6: Contract | P6: FTE % | Q6: PY | T6: Add'l | AA6: Benefit | AB6: Position
A7: Fund | B7: Location | C7: SRE | D7: Program | E7: Program | F7: Object | G7: Object | H7: Class | I7: Code | J7: Employee Name | K7: Position | L7: Level | M7: Years in District | N7: Amount | O7: Start Date | P7: 1.00 = 100% | Q7: Salary | R7: Salary | S7: PERA | T7: PERA | U7: Medicare | V7: Health | W7: Dental | X7: Life | Y7: St. Disab. | Z7: Others | AA7: Costs | AB7: Costs
R9: =SUM(R11:R65536) -> 0 | S9: =SUM(S11:S65536) -> 0 | T9: =SUM(T11:T65536) -> 0 | U9: =SUM(U11:U65536) -> 0 | V9: =SUM(V11:V65536) -> 0 | W9: =SUM(W11:W65536) -> 0 | X9: =SUM(X11:X65536) -> 0 | Y9: =SUM(Y11:Y65536) -> 0 | ... AB9: =SUM(AB11:AB65536) -> 0 | AC9: Totals
A10: f1 | B10: f2 | C10: f3 | D10: f4 | E10: f5 | F10: f6 | G10: f7 | H10: f8 | I10: f9 | J10: f10 | K10: f11 | L10: f13 | M10: f14 | N10: f15 | O10: f16 | P10: f18 | Q10: f19 | R10: f20 | S10: f21 | T10: f22 | U10: f23 | V10: f24 | W10: f25 | X10: f26 | Y10: f27 | Z10: f28 | AA10: f29 | AB10: f30
G11: 0100 | N11: =VLOOKUP(M11,'Salary Schedule'!$B$16:$N$47,L11+1,FALSE) -> 0 | P11: 0 | R11: =ROUND((+N11*P11),0) -> 0 | S11: =+R11*$S$4 -> 0 | T11: =+R11*$T$4 -> 0 | U11: =+R11*$U$4 -> 0 | V11: =($V$3*12)*P11 -> 0 | W11: 0 | X11: 0 | Y11: 0 | Z11: 0 | AA11: =ROUND((SUM(S11:Z11)),0) -> 0 | AB11: =ROUND((+R11+AA11),0) -> 0
G12: 0100 | N12: =VLOOKUP(M12,'Salary Schedule'!$B$16:$N$47,L12+1,FALSE) -> 0 | P12: 0 | R12: =ROUND((+N12*P12),0) -> 0 | S12: =+R12*$S$4 -> 0 | T12: =+R12*$T$4 -> 0 | U12: =+R12*$U$4 -> 0 | V12: =($V$3*12)*P12 -> 0 | W12: 0 | X12: 0 | Y12: 0 | Z12: 0 | AA12: =ROUND((SUM(S12:Z12)),0) -> 0 | AB12: =ROUND((+R12+AA12),0) -> 0
G13: 0100 | N13: =VLOOKUP(M13,'Salary Schedule'!$B$16:$N$47,L13+1,FALSE) -> 0 | P13: 0 | R13: =ROUND((+N13*P13),0) -> 0 | S13: =+R13*$S$4 -> 0 | T13: =+R13*$T$4 -> 0 | U13: =+R13*$U$4 -> 0 | V13: =($V$3*12)*P13 -> 0 | W13: 0 | X13: 0 | Y13: 0 | Z13: 0 | AA13: =ROUND((SUM(S13:Z13)),0) -> 0 | AB13: =ROUND((+R13+AA13),0) -> 0
G14: 0100 | N14: =VLOOKUP(M14,'Salary Schedule'!$B$16:$N$47,L14+1,FALSE) -> 0 | P14: 0 | R14: =ROUND((+N14*P14),0) -> 0 | S14: =+R14*$S$4 -> 0 | T14: =+R14*$T$4 -> 0 | U14: =+R14*$U$4 -> 0 | V14: =($V$3*12)*P14 -> 0 | W14: 0 | X14: 0 | Y14: 0 | Z14: 0 | AA14: =ROUND((SUM(S14:Z14)),0) -> 0 | AB14: =ROUND((+R14+AA14),0) -> 0
G15: 0100 | N15: =VLOOKUP(M15,'Salary Schedule'!$B$16:$N$47,L15+1,FALSE) -> 0 | P15: 0 | R15: =ROUND((+N15*P15),0) -> 0 | S15: =+R15*$S$4 -> 0 | T15: =+R15*$T$4 -> 0 | U15: =+R15*$U$4 -> 0 | V15: =($V$3*12)*P15 -> 0 | W15: 0 | X15: 0 | Y15: 0 | Z15: 0 | AA15: =ROUND((SUM(S15:Z15)),0) -> 0 | AB15: =ROUND((+R15+AA15),0) -> 0
G16: 0100 | N16: =VLOOKUP(M16,'Salary Schedule'!$B$16:$N$47,L16+1,FALSE) -> 0 | P16: 0 | R16: =ROUND((+N16*P16),0) -> 0 | S16: =+R16*$S$4 -> 0 | T16: =+R16*$T$4 -> 0 | U16: =+R16*$U$4 -> 0 | V16: =($V$3*12)*P16 -> 0 | W16: 0 | X16: 0 | Y16: 0 | Z16: 0 | AA16: =ROUND((SUM(S16:Z16)),0) -> 0 | AB16: =ROUND((+R16+AA16),0) -> 0
G17: 0100 | N17: =VLOOKUP(M17,'Salary Schedule'!$B$16:$N$47,L17+1,FALSE) -> 0 | P17: 0 | R17: =ROUND((+N17*P17),0) -> 0 | S17: =+R17*$S$4 -> 0 | T17: =+R17*$T$4 -> 0 | U17: =+R17*$U$4 -> 0 | V17: =($V$3*12)*P17 -> 0 | W17: 0 | X17: 0 | Y17: 0 | Z17: 0 | AA17: =ROUND((SUM(S17:Z17)),0) -> 0 | AB17: =ROUND((+R17+AA17),0) -> 0
G18: 0100 | N18: =VLOOKUP(M18,'Salary Schedule'!$B$16:$N$47,L18+1,FALSE) -> 0 | P18: 0 | R18: =ROUND((+N18*P18),0) -> 0 | S18: =+R18*$S$4 -> 0 | T18: =+R18*$T$4 -> 0 | U18: =+R18*$U$4 -> 0 | V18: =($V$3*12)*P18 -> 0 | W18: 0 | X18: 0 | Y18: 0 | Z18: 0 | AA18: =ROUND((SUM(S18:Z18)),0) -> 0 | AB18: =ROUND((+R18+AA18),0) -> 0
G19: 0100 | N19: =VLOOKUP(M19,'Salary Schedule'!$B$16:$N$47,L19+1,FALSE) -> 0 | P19: 0 | R19: =ROUND((+N19*P19),0) -> 0 | S19: =+R19*$S$4 -> 0 | T19: =+R19*$T$4 -> 0 | U19: =+R19*$U$4 -> 0 | V19: =($V$3*12)*P19 -> 0 | W19: 0 | X19: 0 | Y19: 0 | Z19: 0 | AA19: =ROUND((SUM(S19:Z19)),0) -> 0 | AB19: =ROUND((+R19+AA19),0) -> 0
G20: 0100 | N20: =VLOOKUP(M20,'Salary Schedule'!$B$16:$N$47,L20+1,FALSE) -> 0 | P20: 0 | R20: =ROUND((+N20*P20),0) -> 0 | S20: =+R20*$S$4 -> 0 | T20: =+R20*$T$4 -> 0 | U20: =+R20*$U$4 -> 0 | V20: =($V$3*12)*P20 -> 0 | W20: 0 | X20: 0 | Y20: 0 | Z20: 0 | AA20: =ROUND((SUM(S20:Z20)),0) -> 0 | AB20: =ROUND((+R20+AA20),0) -> 0
G21: 0100 | N21: =VLOOKUP(M21,'Salary Schedule'!$B$16:$N$47,L21+1,FALSE) -> 0 | P21: 0 | R21: =ROUND((+N21*P21),0) -> 0 | S21: =+R21*$S$4 -> 0 | T21: =+R21*$T$4 -> 0 | U21: =+R21*$U$4 -> 0 | V21: =($V$3*12)*P21 -> 0 | W21: 0 | X21: 0 | Y21: 0 | Z21: 0 | AA21: =ROUND((SUM(S21:Z21)),0) -> 0 | AB21: =ROUND((+R21+AA21),0) -> 0
G22: 0100 | N22: =VLOOKUP(M22,'Salary Schedule'!$B$16:$N$47,L22+1,FALSE) -> 0 | P22: 0 | R22: =ROUND((+N22*P22),0) -> 0 | S22: =+R22*$S$4 -> 0 | T22: =+R22*$T$4 -> 0 | U22: =+R22*$U$4 -> 0 | V22: =($V$3*12)*P22 -> 0 | W22: 0 | X22: 0 | Y22: 0 | Z22: 0 | AA22: =ROUND((SUM(S22:Z22)),0) -> 0 | AB22: =ROUND((+R22+AA22),0) -> 0
... G201: 0100 | N201: =VLOOKUP(M201,'Salary Schedule'!$B$16:$N$47,L201+1,FALSE) -> 0 | P201: 0 | R201: =ROUND((+N201*P201),0) -> 0 | S201: =+R201*$S$4 -> 0 | T201: =+R201*$T$4 -> 0 | U201: =+R201*$U$4 -> 0 | V201: =($V$3*12)*P201 -> 0 | W201: 0 | X201: 0 | Y201: 0 | Z201: 0 | AA201: =ROUND((SUM(S201:Z201)),0) -> 0 | AB201: =ROUND((+R201+AA201),0) -> 0

Sheet GenFundREV
A1: School District | C1: =+'Page 1 - FY2013-14'!B5 -> 0 | D1: District Code | E1: =+'Page 1 - FY2013-14'!F7 -> 0 | G1: * Round to Nearest Dollar *
A2: Fund 10: GENERAL FUND REVENUE
D3: Prior Year Actual - Audited FY11-12 | E3: Current Fiscal Year - Budgeted FY12-13 | F3: Current Fiscal Year - Projected FY12-13 | G3: Original Ensuing Fiscal Year - Budget FY13-14 | H3: Adjustments Ensuing Fiscal Year - Budget FY13-14 | I3: Revised Ensuing Fiscal Year - Budget FY13-14
H4: Record Inceases to revenue are positive amounts and Decreases as negatives | I4: Figures (Totals) which will appear on Budget Form to Submit to CDE
A5: Codes | B5: BEGINNING FUND BALANCE | D5: 0 | E5: 0 | F5: 0 | G5: 0 | H5: 0 | I5: =SUM(G5+H5) -> 0
A6: Source | B6: REVENUE FROM LOCAL SOURCES
A7: 1110 | B7: 1. | C7: Current Property Taxes | D7: 0 | E7: 0 | F7: 0 | G7: 0 | H7: 0 | I7: =SUM(G7+H7) -> 0
A8: 1120 | B8: 2. | C8: Specific Ownership Taxes | D8: 0 | E8: 0 | F8: 0 | G8: 0 | H8: 0 | I8: =SUM(G8+H8) -> 0
A9: 1130 | B9: 3. | C9: Sales and Use Taxes | D9: 0 | E9: 0 | F9: 0 | G9: 0 | H9: 0 | I9: =SUM(G9+H9) -> 0
A10: 1140 | B10: 4. | C10: Delinquent Taxes and Penalties and Interest on Taxes | D10: 0 | E10: 0 | F10: 0 | G10: 0 | H10: 0 | I10: =SUM(G10+H10) -> 0
A11: 1190 | B11: 5. | C11: Other Taxes from Local Sources | D11: 0 | E11: 0 | F11: 0 | G11: 0 | H11: 0 | I11: =SUM(G11+H11) -> 0
A12: 1310 | B12: 6. | C12: Tuition from Individuals | D12: 0 | E12: 0 | F12: 0 | G12: 0 | H12: 0 | I12: =SUM(G12+H12) -> 0
A13: 1311 | B13: 7. | C13: Summer School/Interterm/Intercession Fees | D13: 0 | E13: 0 | F13: 0 | G13: 0 | H13: 0 | I13: =SUM(G13+H13) -> 0
A14: 1321 | B14: 8. | C14: Tuition from WITHIN the BOCES (or Administrative Unit(AU)) | D14: 0 | E14: 0 | F14: 0 | G14: 0 | H14: 0 | I14: =SUM(G14+H14) -> 0
A15: 1322 | B15: 9. | C15: Tuition from Other Colorado Districts or BOCES (or AU) | D15: 0 | E15: 0 | F15: 0 | G15: 0 | H15: 0 | I15: =SUM(G15+H15) -> 0
A16: 1323 | B16: 10. | C16: Tuition from Excess Costs | D16: 0 | E16: 0 | F16: 0 | G16: 0 | H16: 0 | I16: =SUM(G16+H16) -> 0
A17: 1324 | B17: 11. | C17: Tuition from CDE for Out-of District Placed Pupils | D17: 0 | E17: 0 | F17: 0 | G17: 0 | H17: 0 | I17: =SUM(G17+H17) -> 0
A18: 1330 | B18: 12. | C18: Tuition from School Districts Outside the State | D18: 0 | E18: 0 | F18: 0 | G18: 0 | H18: 0 | I18: =SUM(G18+H18) -> 0
... A30: 1740 | B30: 24. | C30: Fees | D30: 0 | E30: 0 | F30: 0 | G30: 0 | H30: 0 | I30: =SUM(G30+H30) -> 0
A31: 1800 | B31: 25. | C31: Community Service Activities | D31: 0 | E31: 0 | F31: 0 | G31: 0 | H31: 0 | I31: =SUM(G31+H31) -> 0
A32: 1850 | B32: 26. | C32: Charter School Revenue | D32: 0 | E32: 0 | F32: 0 | G32: 0 | H32: 0 | I32: =SUM(G32+H32) -> 0
A33: 1900 | B33: 28. | C33: Other Revenue from Local Sources | D33: 0 | E33: 0 | F33: 0 | G33: 0 | H33: 0 | I33: =SUM(G33+H33) -> 0
A34: 1910 | B34: 29. | C34: Rentals/Leases | D34: 0 | E34: 0 | F34: 0 | G34: 0 | H34: 0 | I34: =SUM(G34+H34) -> 0
A35: 1920 | B35: 30. | C35: Contributions and Donations for Private Sources | D35: 0 | E35: 0 | F35: 0 | G35: 0 | H35: 0 | I35: =SUM(G35+H35) -> 0
A36: 1930 | B36: 31. | C36: Sale of Fixed Assets | D36: 0 | E36: 0 | F36: 0 | G36: 0 | H36: 0 | I36: =SUM(G36+H36) -> 0
A37: 1940 | B37: 32. | C37: Instructional Materials Fees | D37: 0 | E37: 0 | F37: 0 | G37: 0 | H37: 0 | I37: =SUM(G37+H37) -> 0
A38: 1951 | B38: 33. | C38: Services Provided within BOCES: local | D38: 0 | E38: 0 | F38: 0 | G38: 0 | H38: 0 | I38: =SUM(G38+H38) -> 0
A39: 1952 | B39: 34. | C39: Serivces Provided other Colorado BOCES of Districts: local | D39: 0 | E39: 0 | F39: 0 | G39: 0 | H39: 0 | I39: =SUM(G39+H39) -> 0
A40: 1954 | B40: 35. | C40: Services Provided Charter Schools: local | D40: 0 | E40: 0 | F40: 0 | G40: 0 | H40: 0 | I40: =SUM(G40+H40) -> 0
A41: 1959 | B41: 36. | C41: Services Provided other Units: local | D41: 0 | E41: 0 | F41: 0 | G41: 0 | H41: 0 | I41: =SUM(G41+H41) -> 0
A42: 1960 | B42: 37. | C42: Parking Fees | D42: 0 | E42: 0 | F42: 0 | G42: 0 | H42: 0 | I42: =SUM(G42+H42) -> 0
B43: 38. | C43: All Other Local Revenue Codes | D43: 0 | E43: 0 | F43: 0 | G43: 0 | H43: 0 | I43: =SUM(G43+H43) -> 0
B45: 39. | C45: TOTAL REVENUE FROM LOCAL SOURCES (Sum of lines 1-38) | D45: =SUM(D7:D43) -> 0 | E45: =SUM(E7:E43) -> 0 | F45: =SUM(F7:F43) -> 0 | G45: =SUM(G7:G43) -> 0 | H45: =SUM(H7:H43) -> 0 | I45: =SUM(I7:I43) -> 0
B47: REVENUE FROM INTERMEDIATE (COUNTY) SOURCES
A48: 2000 | B48: 40. | C48: TOTAL REVENUE FROM INTERMEDIATE (COUNTY) SOURCES | D48: 0 | E48: 0 | F48: 0 | G48: 0 | H48: 0 | I48: =SUM(G48+H48) -> 0
B50: REVENUE FROM STATE SOURCES
A51: 3110 | B51: 41. | C51: State Equalization | D51: 0 | E51: 0 | F51: 0 | G51: 0 | H51: 0 | I51: =SUM(G51+H51) -> 0
A52: 3111 | B52: 41a | C52: Full Day Kindergarten, Hold Harmless (Grant Code: 0000) | D52: 0 | E52: 0 | F52: 0 | G52: 0 | H52: 0 | I52: =SUM(G52+H52) -> 0
A53: 3112 | B53: 42. | C53: Capital Construction | D53: 0 | E53: 0 | F53: 0 | G53: 0 | H53: 0 | I53: =SUM(G53+H53) -> 0
A54: 3113 | B54: 43. | C54: Charter School Capital Constrcution | D54: 0 | E54: 0 | F54: 0 | G54: 0 | H54: 0 | I54: =SUM(G54+H54) -> 0
...

Sheet GenFundExp
A1: School District | C1: =+'Page 1 - FY2013-14'!B5 -> 0 | D1: District Code | E1: =+'Page 1 - FY2013-14'!F7 -> 0 | G1: * Round to Nearest Dollar *
A2: Fund 10: GENERAL FUND EXPENDITURES
D4: Prior Year Actual - Audited FY11-12 | E4: Current Fiscal Year - Budgeted FY12-13 | F4: Current Fiscal Year - Projected FY12-13 | G4: Original Ensuing Fiscal Year - Budget FY13-14 | H4: Adjustments Ensuing Fiscal Year - Budget FY13-14 | I4: Revised Ensuing Fiscal Year - Budget FY13-14
H5: Record Inceases to revenue are positive amounts and Decreases as negatives | I5: Figures (Totals) which will appear on Budget Form to Submit to CDE
A8: INSTRUCTION PROGRAM CODES
B9: Object Codes
A10: 0010 - General Elementary Education
B11: 0100 | C11: Salaries - from staff details tab | D11: 0 | E11: 0 | F11: 0 | G11: {=SUM(IF(CertFund&CertProg&CertObj=RIGHT(LEFT($A$2,7),2)&LEFT(A10,4)&B11,CertSalary))} -> 0 | H11: 0 | I11: =SUM(G11+H11) -> 0
B12: 0100 | C12: Salaries - additional items | D12: 0 | E12: 0 | F12: 0 | G12: 0 | H12: 0 | I12: =SUM(G12+H12) -> 0
B13: 0200 | C13: Employee Benefits - staff details tab | D13: 0 | E13: 0 | F13: 0 | G13: {=SUM(IF(CertFund&CertProg&CertObj=RIGHT(LEFT($A$2,7),2)&LEFT(A10,4)&B11,CertBen))} -> 0 | H13: 0 | I13: =SUM(G13+H13) -> 0
B14: 0200 | C14: Employee Benefits - addl items | D14: 0 | E14: 0 | F14: 0 | G14: 0 | H14: 0 | I14: =SUM(G14+H14) -> 0
B15: 0300 | C15: Purchased Professional & Technical Services | D15: 0 | E15: 0 | F15: 0 | G15: 0 | H15: 0 | I15: =SUM(G15+H15) -> 0
B16: 0400 | C16: Purchased Property Services | D16: 0 | E16: 0 | F16: 0 | G16: 0 | H16: 0 | I16: =SUM(G16+H16) -> 0
B17: 0430 | C17: Repairs & Maintenance Services | D17: 0 | E17: 0 | F17: 0 | G17: 0 | H17: 0 | I17: =SUM(G17+H17) -> 0
B18: 0442 | C18: Rental of Equipment | D18: 0 | E18: 0 | F18: 0 | G18: 0 | H18: 0 | I18: =SUM(G18+H18) -> 0
B19: 0500 | C19: Other Purchased Services | D19: 0 | E19: 0 | F19: 0 | G19: 0 | H19: 0 | I19: =SUM(G19+H19) -> 0
B20: 0513 | C20: Contracted Field Trips | D20: 0 | E20: 0 | F20: 0 | G20: 0 | H20: 0 | I20: =SUM(G20+H20) -> 0
B21: 0519 | C21: Other Purchased Student Transportation | D21: 0 | E21: 0 | F21: 0 | G21: 0 | H21: 0 | I21: =SUM(G21+H21) -> 0
B22: 0561 | C22: Tuition Paid Within the BOCES or AU | D22: 0 | E22: 0 | F22: 0 | G22: 0 | H22: 0 | I22: =SUM(G22+H22) -> 0
B23: 0562 | C23: Tuition Paid to Other Colorado Districts, BOCES or AU | D23: 0 | E23: 0 | F23: 0 | G23: 0 | H23: 0 | I23: =SUM(G23+H23) -> 0
B24: 0563 | C24: Tuition to School Districts Outside The State | D24: 0 | E24: 0 | F24: 0 | G24: 0 | H24: 0 | I24: =SUM(G24+H24) -> 0
B25: 0564 | C25: Tuition To Private Sources | D25: 0 | E25: 0 | F25: 0 | G25: 0 | H25: 0 | I25: =SUM(G25+H25) -> 0
... B43: 0851 | C43: Transportation/Field Trips | D43: 0 | E43: 0 | F43: 0 | G43: 0 | H43: 0 | I43: =SUM(G43+H43) -> 0
C44: TOTAL GENERAL ELEMENTARY EDUCATION | D44: =SUM(D11:D43) -> 0 | E44: =SUM(E11:E43) -> 0 | F44: =SUM(F11:F43) -> 0 | G44: =SUM(G11:G43) -> 0 | H44: =SUM(H11:H43) -> 0 | I44: =SUM(G44+H44) -> 0
A46: 0020 - General Middle/Jr. High School Education
B47: 0100 | C47: Salaries - from staff details tab | D47: 0 | E47: 0 | F47: 0 | G47: {=SUM(IF(CertFund&CertProg&CertObj=RIGHT(LEFT($A$2,7),2)&LEFT(A46,4)&B47,CertSalary))} -> 0 | H47: 0 | I47: =SUM(G47+H47) -> 0
B48: 0100 | C48: Salaries - additional items | D48: 0 | E48: 0 | F48: 0 | G48: 0 | H48: 0 | I48: =SUM(G48+H48) -> 0
B49: 0200 | C49: Employee Benefits - staff details tab | D49: 0 | E49: 0 | F49: 0 | G49: {=SUM(IF(CertFund&CertProg&CertObj=RIGHT(LEFT($A$2,7),2)&LEFT(A46,4)&B47,CertBen))} -> 0 | H49: 0 | I49: =SUM(G49+H49) -> 0
B50: 0200 | C50: Employee Benefits - addl items | D50: 0 | E50: 0 | F50: 0 | G50: 0 | H50: 0 | I50: =SUM(G50+H50) -> 0
B51: 0300 | C51: Purchased Professional & Technical Services | D51: 0 | E51: 0 | F51: 0 | G51: 0 | H51: 0 | I51: =SUM(G51+H51) -> 0
B52: 0400 | C52: Purchased Property Services | D52: 0 | E52: 0 | F52: 0 | G52: 0 | H52: 0 | I52: =SUM(G52+H52) -> 0
B53: 0430 | C53: Repairs & Maintenance Services | D53: 0 | E53: 0 | F53: 0 | G53: 0 | H53: 0 | I53: =SUM(G53+H53) -> 0
B54: 0442 | C54: Rental of Equipment | D54: 0 | E54: 0 | F54: 0 | G54: 0 | H54: 0 | I54: =SUM(G54+H54) -> 0
B55: 0500 | C55: Other Purchased Services | D55: 0 | E55: 0 | F55: 0 | G55: 0 | H55: 0 | I55: =SUM(G55+H55) -> 0
B56: 0513 | C56: Contracted Field Trips | D56: 0 | E56: 0 | F56: 0 | G56: 0 | H56: 0 | I56: =SUM(G56+H56) -> 0
B57: 0519 | C57: Other Purchased Student Transportation | D57: 0 | E57: 0 | F57: 0 | G57: 0 | H57: 0 | I57: =SUM(G57+H57) -> 0
B58: 0561 | C58: Tuition Paid Within the BOCES or AU | D58: 0 | E58: 0 | F58: 0 | G58: 0 | H58: 0 | I58: =SUM(G58+H58) -> 0
B59: 0562 | C59: Tuition Paid to Other Colorado Districts, BOCES or AU | D59: 0 | E59: 0 | F59: 0 | G59: 0 | H59: 0 | I59: =SUM(G59+H59) -> 0
B60: 0563 | C60: Tuition to School Districts Outside The State | D60: 0 | E60: 0 | F60: 0 | G60: 0 | H60: 0 | I60: =SUM(G60+H60) -> 0
B61: 0564 | C61: Tuition To Private Sources | D61: 0 | E61: 0 | F61: 0 | G61: 0 | H61: 0 | I61: =SUM(G61+H61) -> 0
...

Sheet GenFundExp2
A1: School District | C1: =+'Page 1 - FY2013-14'!B5 -> 0 | D1: District Code | E1: =+'Page 1 - FY2013-14'!F7 -> 0 | G1: * Round to Nearest Dollar *
A2: Fund 10: GENERAL FUND EXPENDITURES
D4: Prior Year Actual - Audited FY11-12 | E4: Current Fiscal Year - Budgeted FY12-13 | F4: Current Fiscal Year - Projected FY12-13 | G4: Original Ensuing Fiscal Year - Budget FY13-14 | H4: Adjustments Ensuing Fiscal Year - Budget FY13-14 | I4: Revised Ensuing Fiscal Year - Budget FY13-14
H5: Record Inceases to revenue are positive amounts and Decreases as negatives | I5: Figures (Totals) which will appear on Budget Form to Submit to CDE
A7: SUPPORT SERVICES PROGRAM CODES
B8: Object Codes
A9: 2100 - Students
B10: 0100 | C10: Salaries - from staff details tab | D10: 0 | E10: 0 | F10: 0 | G10: {=SUM(IF(CertFund&CertProg&CertObj=RIGHT(LEFT($A$2,7),2)&LEFT(A9,4)&B10,CertSalary))} -> 0 | H10: 0 | I10: =SUM(G10+H10) -> 0
B11: 0100 | C11: Salaries - additional items | D11: 0 | E11: 0 | F11: 0 | G11: 0 | H11: 0 | I11: =SUM(G11+H11) -> 0
B12: 0200 | C12: Employee Benefits - staff details tab | D12: 0 | E12: 0 | F12: 0 | G12: {=SUM(IF(CertFund&CertProg&CertObj=RIGHT(LEFT($A$2,7),2)&LEFT(A9,4)&B10,CertBen))} -> 0 | H12: 0 | I12: =SUM(G12+H12) -> 0
B13: 0200 | C13: Employee Benefits - addl items | D13: 0 | E13: 0 | F13: 0 | G13: 0 | H13: 0 | I13: =SUM(G13+H13) -> 0
B14: 0300 | C14: Purchased Professional & Technical Services | D14: 0 | E14: 0 | F14: 0 | G14: 0 | H14: 0 | I14: =SUM(G14+H14) -> 0
B15: 0400 | C15: Purchased Property Services | D15: 0 | E15: 0 | F15: 0 | G15: 0 | H15: 0 | I15: =SUM(G15+H15) -> 0
B16: 0430 | C16: Repairs & Maintenance Services | D16: 0 | E16: 0 | F16: 0 | G16: 0 | H16: 0 | I16: =SUM(G16+H16) -> 0
B17: 0442 | C17: Rental of Equipment | D17: 0 | E17: 0 | F17: 0 | G17: 0 | H17: 0 | I17: =SUM(G17+H17) -> 0
B18: 0500 | C18: Other Purchased Services | D18: 0 | E18: 0 | F18: 0 | G18: 0 | H18: 0 | I18: =SUM(G18+H18) -> 0
B19: 0511 | C19: Student Transportation Purchased Within the BOCES or AU | D19: 0 | E19: 0 | F19: 0 | G19: 0 | H19: 0 | I19: =SUM(G19+H19) -> 0
B20: 0512 | C20: Student Transportation Purchased from Other Colorado Districts, BOCES or AU | D20: 0 | E20: 0 | F20: 0 | G20: 0 | H20: 0 | I20: =SUM(G20+H20) -> 0
B21: 0513 | C21: Contracted Field Trips | D21: 0 | E21: 0 | F21: 0 | G21: 0 | H21: 0 | I21: =SUM(G21+H21) -> 0
B22: 0514 | C22: Student Transportation Purchased from Parents | D22: 0 | E22: 0 | F22: 0 | G22: 0 | H22: 0 | I22: =SUM(G22+H22) -> 0
B23: 0515 | C23: Student Transportation Purchased from Contractors | D23: 0 | E23: 0 | F23: 0 | G23: 0 | H23: 0 | I23: =SUM(G23+H23) -> 0
B24: 0517 | C24: Student Transportation Purchased from School District Outside the State | D24: 0 | E24: 0 | F24: 0 | G24: 0 | H24: 0 | I24: =SUM(G24+H24) -> 0
... B43: 0869 | C43: Indirect Costs | D43: 0 | E43: 0 | F43: 0 | G43: 0 | H43: 0 | I43: =SUM(G43+H43) -> 0
C44: TOTAL STUDENT SUPPORT | D44: =SUM(D10:D43) -> 0 | E44: =SUM(E10:E43) -> 0 | F44: =SUM(F10:F43) -> 0 | G44: =SUM(G10:G43) -> 0 | H44: =SUM(H10:H43) -> 0 | I44: =SUM(G44+H44) -> 0
A46: 2200 - Instructional Staff
B47: 0100 | C47: Salaries - from staff details tab | D47: 0 | E47: 0 | F47: 0 | G47: {=SUM(IF(CertFund&CertProg&CertObj=RIGHT(LEFT($A$2,7),2)&LEFT(A46,4)&B47,CertSalary))} -> 0 | H47: 0 | I47: =SUM(G47+H47) -> 0
B48: 0100 | C48: Salaries - additional items | D48: 0 | E48: 0 | F48: 0 | G48: 0 | H48: 0 | I48: =SUM(G48+H48) -> 0
B49: 0200 | C49: Employee Benefits - staff details tab | D49: 0 | E49: 0 | F49: 0 | G49: {=SUM(IF(CertFund&CertProg&CertObj=RIGHT(LEFT($A$2,7),2)&LEFT(A46,4)&B47,CertBen))} -> 0 | H49: 0 | I49: =SUM(G49+H49) -> 0
B50: 0200 | C50: Employee Benefits - addl items | D50: 0 | E50: 0 | F50: 0 | G50: 0 | H50: 0 | I50: =SUM(G50+H50) -> 0
B51: 0300 | C51: Purchased Professional & Technical Services | D51: 0 | E51: 0 | F51: 0 | G51: 0 | H51: 0 | I51: =SUM(G51+H51) -> 0
B52: 0400 | C52: Purchased Property Services | D52: 0 | E52: 0 | F52: 0 | G52: 0 | H52: 0 | I52: =SUM(G52+H52) -> 0
B53: 0430 | C53: Repairs & Maintenance Services | D53: 0 | E53: 0 | F53: 0 | G53: 0 | H53: 0 | I53: =SUM(G53+H53) -> 0
B54: 0442 | C54: Rental of Equipment | D54: 0 | E54: 0 | F54: 0 | G54: 0 | H54: 0 | I54: =SUM(G54+H54) -> 0
B55: 0500 | C55: Other Purchased Services | D55: 0 | E55: 0 | F55: 0 | G55: 0 | H55: 0 | I55: =SUM(G55+H55) -> 0
B56: 0511 | C56: Student Transportation Purchased Within the BOCES or AU | D56: 0 | E56: 0 | F56: 0 | G56: 0 | H56: 0 | I56: =SUM(G56+H56) -> 0
B57: 0512 | C57: Student Transportation Purchased from Other Colorado Districts, BOCES or AU | D57: 0 | E57: 0 | F57: 0 | G57: 0 | H57: 0 | I57: =SUM(G57+H57) -> 0
B58: 0513 | C58: Contracted Field Trips | D58: 0 | E58: 0 | F58: 0 | G58: 0 | H58: 0 | I58: =SUM(G58+H58) -> 0
B59: 0514 | C59: Student Transportation Purchased from Parents | D59: 0 | E59: 0 | F59: 0 | G59: 0 | H59: 0 | I59: =SUM(G59+H59) -> 0
B60: 0515 | C60: Student Transportation Purchased from Contractors | D60: 0 | E60: 0 | F60: 0 | G60: 0 | H60: 0 | I60: =SUM(G60+H60) -> 0
B61: 0517 | C61: Student Transportation Purchased from School District Outside the State | D61: 0 | E61: 0 | F61: 0 | G61: 0 | H61: 0 | I61: =SUM(G61+H61) -> 0
...

Sheet CharterFundRev
A1: School District | C1: =+'Page 1 - FY2013-14'!B5 -> 0 | D1: District Code | E1: =+'Page 1 - FY2013-14'!F7 -> 0 | G1: * Round to Nearest Dollar *
A2: Fund 11: CHARTER FUND REVENUE
D3: Prior Year Actual - Audited FY11-12 | E3: Current Fiscal Year - Budgeted FY12-13 | F3: Current Fiscal Year - Projected FY12-13 | G3: Original Ensuing Fiscal Year - Budget FY13-14 | H3: Adjustments Ensuing Fiscal Year - Budget FY13-14 | I3: Revised Ensuing Fiscal Year - Budget FY13-14
H4: Record Inceases to revenue are positive amounts and Decreases as negatives | I4: Figures (Totals) which will appear on Budget Form to Submit to CDE
A5: Codes | B5: BEGINNING FUND BALANCE | D5: 0 | E5: 0 | F5: 0 | G5: 0 | H5: 0 | I5: =SUM(G5+H5) -> 0
A6: Source | B6: REVENUE FROM LOCAL SOURCES
A7: 1110 | B7: 1. | C7: Current Property Taxes | D7: 0 | E7: 0 | F7: 0 | G7: 0 | H7: 0 | I7: =SUM(G7+H7) -> 0
A8: 1120 | B8: 2. | C8: Specific Ownership Taxes | D8: 0 | E8: 0 | F8: 0 | G8: 0 | H8: 0 | I8: =SUM(G8+H8) -> 0
A9: 1130 | B9: 3. | C9: Sales and Use Taxes | D9: 0 | E9: 0 | F9: 0 | G9: 0 | H9: 0 | I9: =SUM(G9+H9) -> 0
A10: 1140 | B10: 4. | C10: Delinquent Taxes and Penalties and Interest on Taxes | D10: 0 | E10: 0 | F10: 0 | G10: 0 | H10: 0 | I10: =SUM(G10+H10) -> 0
A11: 1190 | B11: 5. | C11: Other Taxes from Local Sources | D11: 0 | E11: 0 | F11: 0 | G11: 0 | H11: 0 | I11: =SUM(G11+H11) -> 0
A12: 1310 | B12: 6. | C12: Tuition from Individuals | D12: 0 | E12: 0 | F12: 0 | G12: 0 | H12: 0 | I12: =SUM(G12+H12) -> 0
A13: 1311 | B13: 7. | C13: Summer School/Interterm/Intercession Fees | D13: 0 | E13: 0 | F13: 0 | G13: 0 | H13: 0 | I13: =SUM(G13+H13) -> 0
A14: 1321 | B14: 8. | C14: Tuition from WITHIN the BOCES (or Administrative Unit(AU)) | D14: 0 | E14: 0 | F14: 0 | G14: 0 | H14: 0 | I14: =SUM(G14+H14) -> 0
A15: 1322 | B15: 9. | C15: Tuition from Other Colorado Districts or BOCES (or AU) | D15: 0 | E15: 0 | F15: 0 | G15: 0 | H15: 0 | I15: =SUM(G15+H15) -> 0
A16: 1323 | B16: 10. | C16: Tuition from Excess Costs | D16: 0 | E16: 0 | F16: 0 | G16: 0 | H16: 0 | I16: =SUM(G16+H16) -> 0
A17: 1324 | B17: 11. | C17: Tuition from CDE for Out-of District Placed Pupils | D17: 0 | E17: 0 | F17: 0 | G17: 0 | H17: 0 | I17: =SUM(G17+H17) -> 0
A18: 1330 | B18: 12. | C18: Tuition from School Districts Outside the State | D18: 0 | E18: 0 | F18: 0 | G18: 0 | H18: 0 | I18: =SUM(G18+H18) -> 0
... A30: 1740 | B30: 24. | C30: Fees | D30: 0 | E30: 0 | F30: 0 | G30: 0 | H30: 0 | I30: =SUM(G30+H30) -> 0
A31: 1800 | B31: 25. | C31: Community Service Activities | D31: 0 | E31: 0 | F31: 0 | G31: 0 | H31: 0 | I31: =SUM(G31+H31) -> 0
A32: 1850 | B32: 26. | C32: Charter School Revenue | D32: 0 | E32: 0 | F32: 0 | G32: 0 | H32: 0 | I32: =SUM(G32+H32) -> 0
A33: 1900 | B33: 28. | C33: Other Revenue from Local Sources | D33: 0 | E33: 0 | F33: 0 | G33: 0 | H33: 0 | I33: =SUM(G33+H33) -> 0
A34: 1910 | B34: 29. | C34: Rentals/Leases | D34: 0 | E34: 0 | F34: 0 | G34: 0 | H34: 0 | I34: =SUM(G34+H34) -> 0
A35: 1920 | B35: 30. | C35: Contributions and Donations for Private Sources | D35: 0 | E35: 0 | F35: 0 | G35: 0 | H35: 0 | I35: =SUM(G35+H35) -> 0
A36: 1930 | B36: 31. | C36: Sale of Fixed Assets | D36: 0 | E36: 0 | F36: 0 | G36: 0 | H36: 0 | I36: =SUM(G36+H36) -> 0
A37: 1940 | B37: 32. | C37: Instructional Materials Fees | D37: 0 | E37: 0 | F37: 0 | G37: 0 | H37: 0 | I37: =SUM(G37+H37) -> 0
A38: 1951 | B38: 33. | C38: Services Provided within BOCES: local | D38: 0 | E38: 0 | F38: 0 | G38: 0 | H38: 0 | I38: =SUM(G38+H38) -> 0
A39: 1952 | B39: 34. | C39: Serivces Provided other Colorado BOCES of Districts: local | D39: 0 | E39: 0 | F39: 0 | G39: 0 | H39: 0 | I39: =SUM(G39+H39) -> 0
A40: 1954 | B40: 35. | C40: Services Provided Charter Schools: local | D40: 0 | E40: 0 | F40: 0 | G40: 0 | H40: 0 | I40: =SUM(G40+H40) -> 0
A41: 1959 | B41: 36. | C41: Services Provided other Units: local | D41: 0 | E41: 0 | F41: 0 | G41: 0 | H41: 0 | I41: =SUM(G41+H41) -> 0
A42: 1960 | B42: 37. | C42: Parking Fees | D42: 0 | E42: 0 | F42: 0 | G42: 0 | H42: 0 | I42: =SUM(G42+H42) -> 0
B43: 38. | C43: All Other Local Revenue Codes | D43: 0 | E43: 0 | F43: 0 | G43: 0 | H43: 0 | I43: =SUM(G43+H43) -> 0
B45: 39. | C45: TOTAL REVENUE FROM LOCAL SOURCES (Sum of lines 1-38) | D45: =SUM(D7:D43) -> 0 | E45: =SUM(E7:E43) -> 0 | F45: =SUM(F7:F43) -> 0 | G45: =SUM(G7:G43) -> 0 | H45: =SUM(H7:H43) -> 0 | I45: =SUM(I7:I43) -> 0
B47: REVENUE FROM INTERMEDIATE (COUNTY) SOURCES
A48: 2000 | B48: 40. | C48: TOTAL REVENUE FROM INTERMEDIATE (COUNTY) SOURCES | D48: 0 | E48: 0 | F48: 0 | G48: 0 | H48: 0 | I48: =SUM(G48+H48) -> 0
B50: REVENUE FROM STATE SOURCES
A51: 3110 | B51: 41. | C51: State Equalization | D51: 0 | E51: 0 | F51: 0 | G51: 0 | H51: 0 | I51: =SUM(G51+H51) -> 0
A52: 3112 | B52: 42. | C52: Capital Construction | D52: 0 | E52: 0 | F52: 0 | G52: 0 | H52: 0 | I52: =SUM(G52+H52) -> 0
A53: 3113 | B53: 43. | C53: Charter School Capital Constrcution | D53: 0 | E53: 0 | F53: 0 | G53: 0 | H53: 0 | I53: =SUM(G53+H53) -> 0
A54: 3114 | B54: 44. | C54: Increasing Enrollment Aid | D54: 0 | E54: 0 | F54: 0 | G54: 0 | H54: 0 | I54: =SUM(G54+H54) -> 0
...

Sheet CharterFundExp
A1: School District | C1: =+'Page 1 - FY2013-14'!B5 -> 0 | D1: District Code | E1: =+'Page 1 - FY2013-14'!F7 -> 0 | G1: * Round to Nearest Dollar *
A2: Fund 11: CHARTER FUND EXPENDITURES
D4: Prior Year Actual - Audited FY11-12 | E4: Current Fiscal Year - Budgeted FY12-13 | F4: Current Fiscal Year - Projected FY12-13 | G4: Original Ensuing Fiscal Year - Budget FY13-14 | H4: Adjustments Ensuing Fiscal Year - Budget FY13-14 | I4: Revised Ensuing Fiscal Year - Budget FY13-14
H5: Record Inceases to revenue are positive amounts and Decreases as negatives | I5: Figures (Totals) which will appear on Budget Form to Submit to CDE
A8: INSTRUCTION PROGRAM CODES
B9: Object Codes
A10: 0010 - General Elementary Education
B11: 0100 | C11: Salaries - from staff details tab | D11: 0 | E11: 0 | F11: 0 | G11: {=SUM(IF(CertFund&CertProg&CertObj=RIGHT(LEFT($A$2,7),2)&LEFT(A10,4)&B11,CertSalary))} -> 0 | H11: 0 | I11: =SUM(G11+H11) -> 0
B12: 0100 | C12: Salaries - additional items | D12: 0 | E12: 0 | F12: 0 | G12: 0 | H12: 0 | I12: =SUM(G12+H12) -> 0
B13: 0200 | C13: Employee Benefits - staff details tab | D13: 0 | E13: 0 | F13: 0 | G13: {=SUM(IF(CertFund&CertProg&CertObj=RIGHT(LEFT($A$2,7),2)&LEFT(A10,4)&B11,CertBen))} -> 0 | H13: 0 | I13: =SUM(G13+H13) -> 0
B14: 0200 | C14: Employee Benefits - addl items | D14: 0 | E14: 0 | F14: 0 | G14: 0 | H14: 0 | I14: =SUM(G14+H14) -> 0
B15: 0300 | C15: Purchased Professional & Technical Services | D15: 0 | E15: 0 | F15: 0 | G15: 0 | H15: 0 | I15: =SUM(G15+H15) -> 0
B16: 0400 | C16: Purchased Property Services | D16: 0 | E16: 0 | F16: 0 | G16: 0 | H16: 0 | I16: =SUM(G16+H16) -> 0
B17: 0430 | C17: Repairs & Maintenance Services | D17: 0 | E17: 0 | F17: 0 | G17: 0 | H17: 0 | I17: =SUM(G17+H17) -> 0
B18: 0442 | C18: Rental of Equipment | D18: 0 | E18: 0 | F18: 0 | G18: 0 | H18: 0 | I18: =SUM(G18+H18) -> 0
B19: 0500 | C19: Other Purchased Services | D19: 0 | E19: 0 | F19: 0 | G19: 0 | H19: 0 | I19: =SUM(G19+H19) -> 0
B20: 0513 | C20: Contracted Field Trips | D20: 0 | E20: 0 | F20: 0 | G20: 0 | H20: 0 | I20: =SUM(G20+H20) -> 0
B21: 0519 | C21: Other Purchased Student Transportation | D21: 0 | E21: 0 | F21: 0 | G21: 0 | H21: 0 | I21: =SUM(G21+H21) -> 0
B22: 0561 | C22: Tuition Paid Within the BOCES or AU | D22: 0 | E22: 0 | F22: 0 | G22: 0 | H22: 0 | I22: =SUM(G22+H22) -> 0
B23: 0562 | C23: Tuition Paid to Other Colorado Districts, BOCES or AU | D23: 0 | E23: 0 | F23: 0 | G23: 0 | H23: 0 | I23: =SUM(G23+H23) -> 0
B24: 0563 | C24: Tuition to School Districts Outside The State | D24: 0 | E24: 0 | F24: 0 | G24: 0 | H24: 0 | I24: =SUM(G24+H24) -> 0
B25: 0564 | C25: Tuition To Private Sources | D25: 0 | E25: 0 | F25: 0 | G25: 0 | H25: 0 | I25: =SUM(G25+H25) -> 0
... B43: 0851 | C43: Transportation/Field Trips | D43: 0 | E43: 0 | F43: 0 | G43: 0 | H43: 0 | I43: =SUM(G43+H43) -> 0
C44: TOTAL GENERAL ELEMENTARY EDUCATION | D44: =SUM(D11:D43) -> 0 | E44: =SUM(E11:E43) -> 0 | F44: =SUM(F11:F43) -> 0 | G44: =SUM(G11:G43) -> 0 | H44: =SUM(H11:H43) -> 0 | I44: =SUM(G44+H44) -> 0
A46: 0020 - General Middle/Jr. High School Education
B47: 0100 | C47: Salaries - from staff details tab | D47: 0 | E47: 0 | F47: 0 | G47: {=SUM(IF(CertFund&CertProg&CertObj=RIGHT(LEFT($A$2,7),2)&LEFT(A46,4)&B47,CertSalary))} -> 0 | H47: 0 | I47: =SUM(G47+H47) -> 0
B48: 0100 | C48: Salaries - additional items | D48: 0 | E48: 0 | F48: 0 | G48: 0 | H48: 0 | I48: =SUM(G48+H48) -> 0
B49: 0200 | C49: Employee Benefits - staff details tab | D49: 0 | E49: 0 | F49: 0 | G49: {=SUM(IF(CertFund&CertProg&CertObj=RIGHT(LEFT($A$2,7),2)&LEFT(A46,4)&B47,CertBen))} -> 0 | H49: 0 | I49: =SUM(G49+H49) -> 0
B50: 0200 | C50: Employee Benefits - addl items | D50: 0 | E50: 0 | F50: 0 | G50: 0 | H50: 0 | I50: =SUM(G50+H50) -> 0
B51: 0300 | C51: Purchased Professional & Technical Services | D51: 0 | E51: 0 | F51: 0 | G51: 0 | H51: 0 | I51: =SUM(G51+H51) -> 0
B52: 0400 | C52: Purchased Property Services | D52: 0 | E52: 0 | F52: 0 | G52: 0 | H52: 0 | I52: =SUM(G52+H52) -> 0
B53: 0430 | C53: Repairs & Maintenance Services | D53: 0 | E53: 0 | F53: 0 | G53: 0 | H53: 0 | I53: =SUM(G53+H53) -> 0
B54: 0442 | C54: Rental of Equipment | D54: 0 | E54: 0 | F54: 0 | G54: 0 | H54: 0 | I54: =SUM(G54+H54) -> 0
B55: 0500 | C55: Other Purchased Services | D55: 0 | E55: 0 | F55: 0 | G55: 0 | H55: 0 | I55: =SUM(G55+H55) -> 0
B56: 0513 | C56: Contracted Field Trips | D56: 0 | E56: 0 | F56: 0 | G56: 0 | H56: 0 | I56: =SUM(G56+H56) -> 0
B57: 0519 | C57: Other Purchased Student Transportation | D57: 0 | E57: 0 | F57: 0 | G57: 0 | H57: 0 | I57: =SUM(G57+H57) -> 0
B58: 0561 | C58: Tuition Paid Within the BOCES or AU | D58: 0 | E58: 0 | F58: 0 | G58: 0 | H58: 0 | I58: =SUM(G58+H58) -> 0
B59: 0562 | C59: Tuition Paid to Other Colorado Districts, BOCES or AU | D59: 0 | E59: 0 | F59: 0 | G59: 0 | H59: 0 | I59: =SUM(G59+H59) -> 0
B60: 0563 | C60: Tuition to School Districts Outside The State | D60: 0 | E60: 0 | F60: 0 | G60: 0 | H60: 0 | I60: =SUM(G60+H60) -> 0
B61: 0564 | C61: Tuition To Private Sources | D61: 0 | E61: 0 | F61: 0 | G61: 0 | H61: 0 | I61: =SUM(G61+H61) -> 0
...

Sheet CharterFundExp2
A1: School District | C1: =+'Page 1 - FY2013-14'!B5 -> 0 | D1: District Code | E1: =+'Page 1 - FY2013-14'!F7 -> 0 | G1: * Round to Nearest Dollar *
A2: Fund 11: CHARTER FUND EXPENDITURES
D4: Prior Year Actual - Audited FY11-12 | E4: Current Fiscal Year - Budgeted FY12-13 | F4: Current Fiscal Year - Projected FY12-13 | G4: Original Ensuing Fiscal Year - Budget FY13-14 | H4: Adjustments Ensuing Fiscal Year - Budget FY13-14 | I4: Revised Ensuing Fiscal Year - Budget FY13-14
H5: Record Inceases to revenue are positive amounts and Decreases as negatives | I5: Figures (Totals) which will appear on Budget Form to Submit to CDE
A7: SUPPORT SERVICES PROGRAM CODES
B8: Object Codes
A9: 2100 - Students
B10: 0100 | C10: Salaries - from staff details tab | D10: 0 | E10: 0 | F10: 0 | G10: {=SUM(IF(CertFund&CertProg&CertObj=RIGHT(LEFT($A$2,7),2)&LEFT(A9,4)&B10,CertSalary))} -> 0 | H10: 0 | I10: =SUM(G10+H10) -> 0
B11: 0100 | C11: Salaries - additional items | D11: 0 | E11: 0 | F11: 0 | G11: 0 | H11: 0 | I11: =SUM(G11+H11) -> 0
B12: 0200 | C12: Employee Benefits - staff details tab | D12: 0 | E12: 0 | F12: 0 | G12: {=SUM(IF(CertFund&CertProg&CertObj=RIGHT(LEFT($A$2,7),2)&LEFT(A9,4)&B10,CertBen))} -> 0 | H12: 0 | I12: =SUM(G12+H12) -> 0
B13: 0200 | C13: Employee Benefits - addl items | D13: 0 | E13: 0 | F13: 0 | G13: 0 | H13: 0 | I13: =SUM(G13+H13) -> 0
B14: 0300 | C14: Purchased Professional & Technical Services | D14: 0 | E14: 0 | F14: 0 | G14: 0 | H14: 0 | I14: =SUM(G14+H14) -> 0
B15: 0400 | C15: Purchased Property Services | D15: 0 | E15: 0 | F15: 0 | G15: 0 | H15: 0 | I15: =SUM(G15+H15) -> 0
B16: 0430 | C16: Repairs & Maintenance Services | D16: 0 | E16: 0 | F16: 0 | G16: 0 | H16: 0 | I16: =SUM(G16+H16) -> 0
B17: 0442 | C17: Rental of Equipment | D17: 0 | E17: 0 | F17: 0 | G17: 0 | H17: 0 | I17: =SUM(G17+H17) -> 0
B18: 0500 | C18: Other Purchased Services | D18: 0 | E18: 0 | F18: 0 | G18: 0 | H18: 0 | I18: =SUM(G18+H18) -> 0
B19: 0511 | C19: Student Transportation Purchased Within the BOCES or AU | D19: 0 | E19: 0 | F19: 0 | G19: 0 | H19: 0 | I19: =SUM(G19+H19) -> 0
B20: 0512 | C20: Student Transportation Purchased from Other Colorado Districts, BOCES or AU | D20: 0 | E20: 0 | F20: 0 | G20: 0 | H20: 0 | I20: =SUM(G20+H20) -> 0
B21: 0513 | C21: Contracted Field Trips | D21: 0 | E21: 0 | F21: 0 | G21: 0 | H21: 0 | I21: =SUM(G21+H21) -> 0
B22: 0514 | C22: Student Transportation Purchased from Parents | D22: 0 | E22: 0 | F22: 0 | G22: 0 | H22: 0 | I22: =SUM(G22+H22) -> 0
B23: 0515 | C23: Student Transportation Purchased from Contractors | D23: 0 | E23: 0 | F23: 0 | G23: 0 | H23: 0 | I23: =SUM(G23+H23) -> 0
B24: 0517 | C24: Student Transportation Purchased from School District Outside the State | D24: 0 | E24: 0 | F24: 0 | G24: 0 | H24: 0 | I24: =SUM(G24+H24) -> 0
... B43: 0869 | C43: Indirect Costs | D43: 0 | E43: 0 | F43: 0 | G43: 0 | H43: 0 | I43: =SUM(G43+H43) -> 0
C44: TOTAL STUDENT SUPPORT | D44: =SUM(D10:D43) -> 0 | E44: =SUM(E10:E43) -> 0 | F44: =SUM(F10:F43) -> 0 | G44: =SUM(G10:G43) -> 0 | H44: =SUM(H10:H43) -> 0 | I44: =SUM(G44+H44) -> 0
A46: 2200 - Instructional Staff
B47: 0100 | C47: Salaries - from staff details tab | D47: 0 | E47: 0 | F47: 0 | G47: {=SUM(IF(CertFund&CertProg&CertObj=RIGHT(LEFT($A$2,7),2)&LEFT(A46,4)&B47,CertSalary))} -> 0 | H47: 0 | I47: =SUM(G47+H47) -> 0
B48: 0100 | C48: Salaries - additional items | D48: 0 | E48: 0 | F48: 0 | G48: 0 | H48: 0 | I48: =SUM(G48+H48) -> 0
B49: 0200 | C49: Employee Benefits - staff details tab | D49: 0 | E49: 0 | F49: 0 | G49: {=SUM(IF(CertFund&CertProg&CertObj=RIGHT(LEFT($A$2,7),2)&LEFT(A46,4)&B47,CertBen))} -> 0 | H49: 0 | I49: =SUM(G49+H49) -> 0
B50: 0200 | C50: Employee Benefits - addl items | D50: 0 | E50: 0 | F50: 0 | G50: 0 | H50: 0 | I50: =SUM(G50+H50) -> 0
B51: 0300 | C51: Purchased Professional & Technical Services | D51: 0 | E51: 0 | F51: 0 | G51: 0 | H51: 0 | I51: =SUM(G51+H51) -> 0
B52: 0400 | C52: Purchased Property Services | D52: 0 | E52: 0 | F52: 0 | G52: 0 | H52: 0 | I52: =SUM(G52+H52) -> 0
B53: 0430 | C53: Repairs & Maintenance Services | D53: 0 | E53: 0 | F53: 0 | G53: 0 | H53: 0 | I53: =SUM(G53+H53) -> 0
B54: 0442 | C54: Rental of Equipment | D54: 0 | E54: 0 | F54: 0 | G54: 0 | H54: 0 | I54: =SUM(G54+H54) -> 0
B55: 0500 | C55: Other Purchased Services | D55: 0 | E55: 0 | F55: 0 | G55: 0 | H55: 0 | I55: =SUM(G55+H55) -> 0
B56: 0511 | C56: Student Transportation Purchased Within the BOCES or AU | D56: 0 | E56: 0 | F56: 0 | G56: 0 | H56: 0 | I56: =SUM(G56+H56) -> 0
B57: 0512 | C57: Student Transportation Purchased from Other Colorado Districts, BOCES or AU | D57: 0 | E57: 0 | F57: 0 | G57: 0 | H57: 0 | I57: =SUM(G57+H57) -> 0
B58: 0513 | C58: Contracted Field Trips | D58: 0 | E58: 0 | F58: 0 | G58: 0 | H58: 0 | I58: =SUM(G58+H58) -> 0
B59: 0514 | C59: Student Transportation Purchased from Parents | D59: 0 | E59: 0 | F59: 0 | G59: 0 | H59: 0 | I59: =SUM(G59+H59) -> 0
B60: 0515 | C60: Student Transportation Purchased from Contractors | D60: 0 | E60: 0 | F60: 0 | G60: 0 | H60: 0 | I60: =SUM(G60+H60) -> 0
B61: 0517 | C61: Student Transportation Purchased from School District Outside the State | D61: 0 | E61: 0 | F61: 0 | G61: 0 | H61: 0 | I61: =SUM(G61+H61) -> 0
...

Sheet InsResv
A1: School District | C1: =+'Page 1 - FY2013-14'!B5 -> 0 | D1: District Code | E1: =+'Page 1 - FY2013-14'!F7 -> 0 | G1: * Round to Nearest Dollar *
A2: Fund 18: INSURANCE RESERVE FUND
D3: Prior Year Actual - Audited FY11-12 | E3: Current Fiscal Year - Budgeted FY12-13 | F3: Current Fiscal Year - Projected FY12-13 | G3: Original Ensuing Fiscal Year - Budget FY13-14 | H3: Adjustments Ensuing Fiscal Year - Budget FY13-14 | I3: Revised Ensuing Fiscal Year - Budget FY13-14
H4: Record Inceases to revenue are positive amounts and Decreases as negatives | I4: Figures (Totals) which will appear on Budget Form to Submit to CDE
A6: Codes: | B6: BEGINNING FUND BALANCE | D6: 0 | E6: 0 | F6: 0 | G6: 0 | H6: 0 | I6: =G6+H6 -> 0
A7: Source | C7: REVENUE AND OTHER SOURCES
A8: 1110 | B8: 1. | C8: Property Taxes | D8: 0 | E8: 0 | F8: 0 | G8: 0 | H8: 0 | I8: =SUM(G8+H8) -> 0
A9: 1120 | B9: 2. | C9: Specific Ownership Taxes | D9: 0 | E9: 0 | F9: 0 | G9: 0 | H9: 0 | I9: =SUM(G9+H9) -> 0
A10: 1500 | B10: 3. | C10: Earnings on Investments | D10: 0 | E10: 0 | F10: 0 | G10: 0 | H10: 0 | I10: =SUM(G10+H10) -> 0
A11: 3110 | B11: 4. | C11: State Equalization | D11: 0 | E11: 0 | F11: 0 | G11: 0 | H11: 0 | I11: =SUM(G11+H11) -> 0
A12: 52XX | B12: 5. | C12: Transfer From(+)/To(-)________________Fund(s) (Net to zero across all funds)* NOTE-1 | D12: 0 | E12: 0 | F12: 0 | G12: 0 | H12: 0 | I12: =SUM(G12+H12) -> 0
A13: 5600 | B13: 6. | C13: Allocation From General Fund** (Optional starting in FY09-10) | D13: 0 | E13: 0 | F13: 0 | G13: 0 | H13: 0 | I13: =SUM(G13+H13) -> 0
B14: 7. | C14: Other Revenue | D14: 0 | E14: 0 | F14: 0 | G14: 0 | H14: 0 | I14: =SUM(G14+H14) -> 0
B16: 8. | C16: TOTAL REVENUE (Sum of lines 1-7) | D16: =SUM(D8:D14) -> 0 | E16: =SUM(E8:E14) -> 0 | F16: =SUM(F8:F14) -> 0 | G16: =SUM(G8:G14) -> 0 | H16: =SUM(H8:H14) -> 0 | I16: =SUM(I8:I14) -> 0
A18: TOTAL REVENUE INCLUDING BEGINNING FUND BALANCE (Sum of line 8 and BFB) | D18: =D6+D16 -> 0 | E18: =E6+E16 -> 0 | F18: =F6+F16 -> 0 | G18: =G6+G16 -> 0 | H18: =H6+H16 -> 0 | I18: =I6+I16 -> 0
A20: NOTE-1: | C20: If you treat Transfers Out as an expenditure - report such amounts here:
A21: 52XX | B21: 5a | C21: Transfer To________________Fund(s) (input as a positive number on this line) | D21: 0 | E21: 0 | F21: 0 | G21: 0 | H21: 0 | I21: =SUM(G21+H21) -> 0
A24: Object | C24: EXPENDITURES AND OTHER USES
A25: 0520 | B25: 9. | C25: Insurance Premiums (typically Program 2600) | D25: 0 | E25: 0 | F25: 0 | G25: 0 | H25: 0 | I25: =SUM(G25+H25) -> 0
A26: 0521 | B26: 10. | C26: Liability Insurance (typically Program 2600) | D26: 0 | E26: 0 | F26: 0 | G26: 0 | H26: 0 | I26: =SUM(G26+H26) -> 0
A27: 0522 | B27: 11. | C27: Property Insurance - Program Code 2620 (or 2600) | D27: 0 | E27: 0 | F27: 0 | G27: 0 | H27: 0 | I27: =SUM(G27+H27) -> 0
A28: 0523 | B28: 12a | C28: Vehicle Insurance - Program Code 2650 (or 2600) | D28: 0 | E28: 0 | F28: 0 | G28: 0 | H28: 0 | I28: =SUM(G28+H28) -> 0
A29: 0523 | B29: 12b | C29: Vehicle Insurance - Program Code 2720 (or 2700) | D29: 0 | E29: 0 | F29: 0 | G29: 0 | H29: 0 | I29: =SUM(G29+H29) -> 0
A30: 0523 | B30: 12c | C30: Vehicle Insurance - Program Code 3130 (or 3100) | D30: 0 | E30: 0 | F30: 0 | G30: 0 | H30: 0 | I30: =SUM(G30+H30) -> 0
A31: 0524 | B31: 13. | C31: Fidelity Insurance - Program Code 2850 (or 2800) | D31: 0 | E31: 0 | F31: 0 | G31: 0 | H31: 0 | I31: =SUM(G31+H31) -> 0
A32: 0525 | B32: 14. | C32: Unemployment Compensation Insurance - Program Code 2850 (or 2800) | D32: 0 | E32: 0 | F32: 0 | G32: 0 | H32: 0 | I32: =SUM(G32+H32) -> 0
A33: 0526 | B33: 15. | C33: Workers' Compensation Insurance - Program Code 2850 (or 2800) | D33: 0 | E33: 0 | F33: 0 | G33: 0 | H33: 0 | I33: =SUM(G33+H33) -> 0
A34: 0527 | B34: 16. | C34: District Multiple-Coverage &/or Other Insurance - Program Code 2850 (or 2800) | D34: 0 | E34: 0 | F34: 0 | G34: 0 | H34: 0 | I34: =SUM(G34+H34) -> 0
