Workbook

Sheet Budget Template
D1: Title of Project
D2: starting date-ending date
A4: Key Personnel | D4: AY or ACAD % FTE (Course Release)* | I4: Summer Effort
A5: Role/Title | B5: Name | C5: Institutional Base Salary | D5: Y1 | E5: Y2 | F5: Y3 | G5: Y4 | H5: Y5 | I5: #Months | J5: Summer FTE | K5: # Years
A6: PI/PD | B6: PI Name | C6: 0 | D6: 0 | E6: 0 | F6: 0 | G6: 0 | H6: 0 | I6: 0 | J6: 1 | K6: 3
A7: Co-PI | B7: Co-PI Name | C7: 0 | D7: 0 | E7: 0 | F7: 0 | G7: 0 | H7: 0 | I7: 0 | J7: 1 | K7: 3
A8: Co-PI | B8: Faculty Name | C8: 0 | D8: 0 | E8: 0 | F8: 0 | G8: 0 | H8: 0 | I8: 0 | J8: 1 | K8: 3
A9: Co-PI | B9: Faculty Name | C9: 0 | D9: 0 | E9: 0 | F9: 0 | G9: 0 | H9: 0 | I9: 0 | J9: 1 | K9: 3
A10: Research Assistant | B10: Staff Name | C10: 0 | D10: 0 | E10: 0 | F10: 0 | G10: 0 | H10: 0 | I10: 0 | J10: 1 | K10: 3
B12: Cost of Living Adjustment (COLA)' | D12: 1.03 | F12: *Note: One academic course release is equivalent to 14.29% FTE or 1/7 of faculty time
D14: Year 1 | E14: =IF($K6>1, "Year 2", "") -> Year 2 | F14: =IF($K6>2, "Year 3", "") -> Year 3 | G14: =IF($K6>3, "Year 4", "") | H14: =IF($K6>4, "Year 5", "") | I14: Total
A15: A. Key Personnel Salaries
A16: =A6 -> PI/PD | B16: AY/ACAD | D16: =$C$6*D6*$D$12 -> 0 | E16: =$C$6*E6*$D$12 -> 0 | F16: =$C$6*F6*$D$12 -> 0 | G16: =$C$6*G6*$D$12 -> 0 | H16: =$C$6*H6*$D$12 -> 0 | I16: =SUM(D16:H16) -> 0
B17: Summer | D17: =$C$6/9*$D$12*I6*J6 -> 0 | E17: =IF($K$6>1,D17*$D$12, "") -> 0 | F17: =IF($K$6>2,E17*$D$12, "") -> 0 | G17: =IF($K$6>3,F17*$D$12, "") | H17: =IF($K$6>4,G17*$D$12, "") | I17: =SUM(D17:H17) -> 0
B18: Subtotal | C18: =B6 -> PI Name | D18: =SUM(D16:D17) -> 0 | E18: =SUM(E16:E17) -> 0 | F18: =SUM(F16:F17) -> 0 | G18: =SUM(G16:G17) -> 0 | H18: =SUM(H16:H17) -> 0 | I18: =SUM(I16:I17) -> 0
A19: Co-PI | B19: AY/ACAD | D19: =$C$7*$D$12*D7 -> 0 | E19: =$C$7*$D$12*E7 -> 0 | F19: =$C$7*$D$12*F7 -> 0 | G19: =$C$7*$D$12*G7 -> 0 | H19: =$C$7*$D$12*H7 -> 0 | I19: =SUM(D19:H19) -> 0
B20: Summer | D20: =$C$7/9*$D$12*$I$7*$J$7 -> 0 | E20: =IF($K$7>1,D20*$D$12, "") -> 0 | F20: =IF($K$7>2,E20*$D$12, "") -> 0 | G20: =IF($K$7>3,F20*$D$12, "") | H20: =IF($K$7>4,G20*$D$12, "") | I20: =SUM(D20:H20) -> 0
B21: Subtotal | C21: =B7 -> Co-PI Name | D21: =SUM(D19:D20) -> 0 | E21: =SUM(E19:E20) -> 0 | F21: =SUM(F19:F20) -> 0 | G21: =SUM(G19:G20) -> 0 | H21: =SUM(H19:H20) -> 0 | I21: =SUM(I19:I20) -> 0
A22: Co-PI | B22: AY/ACAD | D22: =$C$8*$D$12*D8 -> 0 | E22: =$C$8*$D$12*E8 -> 0 | F22: =$C$8*$D$12*F8 -> 0 | G22: =$C$8*$D$12*G8 -> 0 | H22: =$C$8*$D$12*H8 -> 0 | I22: =SUM(D22:H22) -> 0
B23: Summer | D23: =$C$8/9*$D$12*I8*J8 -> 0 | E23: =IF($K$8>1,D23*$D$12, "") -> 0 | F23: =IF($K$8>2,E23*$D$12, "") -> 0 | G23: =IF($K$8>3,F23*$D$12," ") | H23: =IF($K$8>4,G23*$D$12, "") | I23: =SUM(D23:H23) -> 0
B24: Subtotal | C24: =B8 -> Faculty Name | D24: =D22+D23 -> 0 | E24: =SUM(E22:E23) -> 0 | F24: =SUM(F22:F23) -> 0 | G24: =SUM(G22:G23) -> 0 | H24: =SUM(H22:H23) -> 0 | I24: =SUM(I22:I23) -> 0
A25: Co-PI | B25: AY/ACAD | D25: =$C$9*$D$12*D9 -> 0 | E25: =$C$9*$D$12*E9 -> 0 | F25: =$C$9*$D$12*F9 -> 0 | G25: =$C$9*$D$12*G9 -> 0 | H25: =$C$9*$D$12*H9 -> 0 | I25: =SUM(D25:H25) -> 0
B26: Summer | D26: =$C$9/9*$D$12*$I$9*$J$9 -> 0 | E26: =IF($K$9>1,D26*$D$12, "") -> 0 | F26: =IF($K$9>2,E26*$D$12, "") -> 0 | G26: =IF($K$9>3,F26*$D$12, "") | H26: =IF($K$9>4,G26*$D$12, "") | I26: =SUM(D26:H26) -> 0
B27: Subtotal | C27: =B9 -> Faculty Name | D27: =D25+D26 -> 0 | E27: =SUM(E25:E26) -> 0 | F27: =SUM(F25:F26) -> 0 | G27: =SUM(G25:G26) -> 0 | H27: =SUM(H25:H26) -> 0 | I27: =SUM(I25:I26) -> 0
A28: =A10 -> Research Assistant | B28: AY/ACAD | D28: =$C$10*D10*$D$12 -> 0 | E28: =$C$10*E10*$D$12 -> 0 | F28: =$C$10*F10*$D$12 -> 0 | G28: =$C$10*G10*$D$12 -> 0 | H28: =$C$10*H10*$D$12 -> 0 | I28: =SUM(D28:H28) -> 0
B29: Summer | D29: =$C$10/9*$D$12*I10*J10 -> 0 | E29: =IF($K$10>1,D29*$D$12, "") -> 0 | F29: =IF($K$10>2,E29*$D$12, "") -> 0 | G29: =IF($K$10>3,F29*$D$12, "") | H29: =IF($K$10>4,G29*$D$12, "") | I29: =SUM(D29:H29) -> 0
B30: Subtotal | C30: =B10 -> Staff Name | D30: =SUM(D28:D29) -> 0 | E30: =SUM(E28:E29) -> 0 | F30: =SUM(F28:F29) -> 0 | G30: =SUM(G28:G29) -> 0 | H30: =SUM(H28:H29) -> 0 | I30: =SUM(I28:I29) -> 0
C32: Total Key Personnel (Salary) | D32: =D18+D21+D24+D27+D30 -> 0 | E32: =E18+E21+E24+E27+E30 -> 0 | F32: =F18+F21+F24+F27+F30 -> 0 | G32: =G18+G21+G24+G27+G30 -> 0 | H32: =H18+H21+H24+H27+H30 -> 0 | I32: =I18+I21+I24+I27+I30 -> 0
J33: Student Wages*
A34: B. Student Wages | J34: Rate/Hr | K34: Hrs/Wk | L34: #Wks | M34: #Students | N34: Level
C35: Students Level 1 | D35: =J35*K35*L35*M35 -> 0 | E35: =D35*$D$12 -> 0 | F35: =E35*$D$12 -> 0 | G35: =F35*$D$12 -> 0 | H35: =G35*$D$12 -> 0 | I35: =SUM(D35:H35) -> 0 | J35: 9.9 | K35: 0 | L35: 0 | M35: 0 | N35: Level 1
C36: Students Level 2 | D36: =J36*K36*L36*M36 -> 0 | E36: =D36*$D$12 -> 0 | F36: =E36*$D$12 -> 0 | G36: =F36*$D$12 -> 0 | H36: =G36*$D$12 -> 0 | I36: =SUM(D36:H36) -> 0 | J36: 11 | K36: 0 | L36: 0 | M36: 0 | N36: Level 2
C37: Students Level 3 | D37: =J37*K37*L37*M37 -> 0 | E37: =D37*$D$12 -> 0 | F37: =E37*$D$12 -> 0 | G37: =F37*$D$12 -> 0 | H37: =G37*$D$12 -> 0 | I37: =SUM(D37:H37) -> 0 | J37: 12.05 | K37: 0 | L37: 0 | M37: 0 | N37: Level 3
C38: Students Level 4 | D38: =J38*K38*L38*M38 -> 0 | E38: =D38*$D$12 -> 0 | F38: =E38*$D$12 -> 0 | G38: =F38*$D$12 -> 0 | H38: =G38*$D$12 -> 0 | I38: =SUM(D38:H38) -> 0 | J38: 21.67 | K38: 0 | L38: 0 | M38: 0 | N38: Level 4
C39: Total Student Wages | D39: =SUM(D35:D38) -> 0 | E39: =SUM(E35:E38) -> 0 | F39: =SUM(F35:F38) -> 0 | G39: =SUM(G35:G38) -> 0 | H39: =SUM(H35:H38) -> 0 | I39: =SUM(D39:H39) -> 0
J40: *Consult Student Financial Services for the
A41: C. Fringe Benefits | J41: job details that match each wage level
C42: Key Personnel (30.6%) | D42: =D32*0.306 -> 0 | E42: =E32*0.306 -> 0 | F42: =F32*0.306 -> 0 | G42: =G32*0.306 -> 0 | H42: =H32*0.306 -> 0 | I42: =SUM(D42:H42) -> 0
C43: Total Key Personnel (Fringe) | D43: =SUM(D42:D42) -> 0 | E43: =SUM(E42:E42) -> 0 | F43: =SUM(F42:F42) -> 0 | G43: =SUM(G42:G42) -> 0 | H43: =SUM(H42:H42) -> 0 | I43: =SUM(D43:H43) -> 0
A45: D. Equipment
...

Sheet Summary linked to Detailed Budg
A1: CATEGORY | B1: Year 1 | C1: Year 2 | D1: Year 3 | E1: Year 4 | F1: Year 5 | G1: Total | I1: Cross-check
A2: Personnel (Salaries and Student Wages) | B2: ='Budget Template'!D32+'Budget Template'!D39 -> 0 | C2: ='Budget Template'!E32+'Budget Template'!E39 -> 0 | D2: ='Budget Template'!F32+'Budget Template'!F39 -> 0 | E2: ='Budget Template'!G32+'Budget Template'!G39 -> 0 | F2: ='Budget Template'!H32+'Budget Template'!H39 -> 0 | G2: ='Budget Template'!I32+'Budget Template'!I39 -> 0
A3: Fringe | B3: ='Budget Template'!D43 -> 0 | C3: ='Budget Template'!E43 -> 0 | D3: ='Budget Template'!F43 -> 0 | E3: ='Budget Template'!G43 -> 0 | F3: ='Budget Template'!H43 -> 0 | G3: ='Budget Template'!I43 -> 0
A4: Travel | B4: ='Budget Template'!D52 -> 0 | C4: ='Budget Template'!E52 -> 0 | D4: ='Budget Template'!F52 -> 0 | E4: ='Budget Template'!G52 -> 0 | F4: ='Budget Template'!H52 -> 0 | G4: ='Budget Template'!I52 -> 0
A5: Equipment | B5: ='Budget Template'!D47 -> 0 | C5: ='Budget Template'!E47 -> 0 | D5: ='Budget Template'!F47 -> 0 | E5: ='Budget Template'!G47 -> 0 | F5: ='Budget Template'!H47 -> 0 | G5: ='Budget Template'!I47 -> 0
A6: Participant Support | B6: ='Budget Template'!D59 -> 0 | C6: ='Budget Template'!E59 -> 0 | D6: ='Budget Template'!F59 -> 0 | E6: ='Budget Template'!G59 -> 0 | F6: ='Budget Template'!H59 -> 0 | G6: ='Budget Template'!I59 -> 0
A7: Other Direct Cost | B7: ='Budget Template'!D75 -> 0 | C7: ='Budget Template'!E75 -> 0 | D7: ='Budget Template'!F75 -> 0 | E7: ='Budget Template'!G75 -> 0 | F7: ='Budget Template'!H75 -> 0 | G7: ='Budget Template'!I75 -> 0
A8: Subawards | B8: ='Budget Template'!D80 -> 0 | C8: ='Budget Template'!E80 -> 0 | D8: ='Budget Template'!F80 -> 0 | E8: ='Budget Template'!G80 -> 0 | F8: ='Budget Template'!H80 -> 0 | G8: ='Budget Template'!I80 -> 0
A9: Total Direct Costs | B9: ='Budget Template'!D82 -> 0 | C9: ='Budget Template'!E82 -> 0 | D9: ='Budget Template'!F82 -> 0 | E9: ='Budget Template'!G82 -> 0 | F9: ='Budget Template'!H82 -> 0 | G9: ='Budget Template'!I82 -> 0 | I9: =SUM(G2:G8) -> 0
A10: Indirect Costs | B10: ='Budget Template'!D83 -> 0 | C10: ='Budget Template'!E83 -> 0 | D10: ='Budget Template'!F83 -> 0 | E10: ='Budget Template'!G83 -> 0 | F10: ='Budget Template'!H83 -> 0 | G10: ='Budget Template'!I83 -> 0
A11: TOTAL COST | B11: =SUM(B9:B10) -> 0 | C11: =SUM(C9:C10) -> 0 | D11: =SUM(D9:D10) -> 0 | E11: =SUM(E9:E10) -> 0 | F11: =SUM(F9:F10) -> 0 | G11: =SUM(B11:F11) -> 0 | I11: =G9+G10 -> 0

Sheet Travel Calculations
A3: TRIP #1 | C3: Units | D3: Total
B4: Rates | C4: (days/miles) | D4: # Travellers
A5: Per Diem | B5: 35 | E5: =B5*C5*D5 -> 0
A6: Hotel | E6: =B6*C6*D6 -> 0
A7: Mileage | B7: 0.56 | E7: =B7*C7*D7 -> 0
A8: Rental Car | E8: =B8*C8*D8 -> 0
A9: Airfare | E9: =B9*C9*D9 -> 0
A10: Registration | E10: =B10*C10*D10 -> 0
A11: Other | E11: =B11*C11*D11 -> 0
D12: Total | E12: =SUM(E5:E11) -> 0
A14: TRIP #2 | C14: Units | D14: Total
B15: Rates | C15: (days/miles) | D15: # Travellers
A16: Per Diem | B16: 35 | E16: =B16*C16*D16 -> 0
A17: Hotel | E17: =B17*C17*D17 -> 0
A18: Mileage | B18: 0.56 | E18: =B18*C18*D18 -> 0
A19: Rental Car | E19: =B19*C19*D19 -> 0
A20: Airfare | E20: =B20*C20*D20 -> 0
A21: Registration | E21: =B21*C21*D21 -> 0
A22: Other | E22: =B22*C22*D22 -> 0
D23: Total | E23: =SUM(E16:E22) -> 0
A25: TRIP #3 | C25: Units | D25: Total
B26: Rates | C26: (days/miles) | D26: # Travellers
A27: Per Diem | B27: 35 | E27: =B27*C27*D27 -> 0
A28: Hotel | E28: =B28*C28*D28 -> 0
A29: Mileage | B29: 0.56 | E29: =B29*C29*D29 -> 0
A30: Rental Car | E30: =B30*C30*D30 -> 0
A31: Airfare | E31: =B31*C31*D31 -> 0
A32: Registration | E32: =B32*C32*D32 -> 0
A33: Other | E33: =B33*C33*D33 -> 0
D34: Total | E34: =SUM(E27:E33) -> 0
A36: TRIP #4 | C36: Units | D36: Total
B37: Rates | C37: (days/miles) | D37: # Travellers
A38: Per Diem | B38: 35 | E38: =B38*C38*D38 -> 0
A39: Hotel | E39: =B39*C39*D39 -> 0
A40: Mileage | B40: 0.56 | E40: =B40*C40*D40 -> 0
A41: Rental Car | E41: =B41*C41*D41 -> 0
A42: Airfare | E42: =B42*C42*D42 -> 0
A43: Registration | E43: =B43*C43*D43 -> 0
A44: Other | E44: =B44*C44*D44 -> 0
D45: Total | E45: =SUM(E38:E44) -> 0
