Workbook

Sheet Introduction
B2: FabulesslyFrugal.com - Budget Model 2012 | H2: Budget Model Directions
B4: Personal Budget Prepared for: | G4: =MATCH(C8,$G$11:$G$22,0) -> 1 | H4: 1. Enter your Name - it will appear on throughout the model .
B5: Budget for Year | C5: 2012 | H5: 2. Enter your Income Categories (Net Payroll, Gift from Parents, etc. in green cells in Box Titled Income Categories in Left Column.
B6: Applied to Worksheets Start | C6: =CONCATENATE("01/01/",C5) -> 01/01/2012 | H6: 3. Enter your Expense Categories (Rent, Auto, Cell Phone, Water, Gas, Electric, Cable, etc. in yellow in Box Titled Expense Categories
B7: Applied to Worksheets End | C7: =CONCATENATE("12/31/",C5) -> 12/31/2012 | H7: in Center Column (Orange). (Note: your income and expense categories will be captured in your bank ledger entries and reporting.
B8: Budget Comparison Month for Reports | C8: Jan | H8: 4. Enter your Current IRA Balance. The model is designed with an IRA Budget category for your convenience.
B10: Income Categories | D10: 0 | E10: Expense Categories | H10: (Note: your income and expense categories will be made available to you in your bank ledger and reporting results.
A11: 1 | B11: Income 1 | C11: Income 1 | D11: 1 | E11: Expense 1 | F11: Expense 1 | G11: Jan
A12: 2 | B12: Income 2 | C12: Income 2 | D12: 2 | E12: Expense 2 | F12: Expense 2 | G12: Feb | H12: Once you have set up your income and expense categories, enter your Beginning Cash balance in Center Box, bottom. If you have, a IRA
A13: 3 | B13: Income 3 | C13: Income 3 | D13: 3 | E13: Expense 3 | F13: Expense 3 | G13: Mar | H13: balance, enter it in Center Box above the Beginning Cash Balance. You are now ready to begin budgeting. Simply open the BUDGET tab
A14: 4 | B14: Income 4 | C14: Income 4 | D14: 4 | E14: Expense 4 | F14: Expense 4 | G14: Apr | H14: =CONCATENATE("and begin entering your monthly budget numbers. That's it -- the model does all the math for you. Beginning Cash Balance is -> $",F32,".") -> and begin entering your monthly budget numbers. That's it -- the model does all the math for you. Beginning Cash Balance is -> $0.
A15: 5 | B15: Income 5 | C15: Income 5 | D15: 5 | E15: Expense 5 | F15: Expense 5 | G15: May
A16: 6 | B16: Income 6 | C16: Income 6 | D16: 6 | E16: Expense 6 | F16: Expense 6 | G16: Jun | H16: Now it is time to capture your actual results. This is simple too -- go to the LEDGER tab and update your banking ledger for all checks, debit
A17: 7 | B17: Income 7 | C17: Income 7 | D17: 7 | E17: Expense 7 | F17: Expense 7 | G17: Jul | H17: charges, withdrawals, etc. Also, enter check deposits, cash deposits, or other sources of funding entering the account. The model will
A18: 8 | B18: Income 8 | C18: Income 8 | D18: 8 | E18: Expense 8 | F18: Expense 8 | G18: Aug | H18: do all the math for you and provide you a statement against your budget by month, quarter to date, and year-to-date.
D19: 9 | E19: Expense 9 | F19: Expense 9 | G19: Sep
B20: Fabulessly Frugal Budget Model | D20: 10 | E20: Expense 10 | F20: Expense 10 | G20: Oct | H20: As you receive a new bank statement, go to the ledger tab and put number "1" in the bank reconciliation field to balance your bank account.
B21: This simple budget model has been prepared as an expression of my love for my children, in hopes that in some small way I can teach them to organize their financial affairs in a fun and meaningful way. While simple, this model is quite powerful, and it can be used by beginners and experts alike. I give special acknowledgment to my daughter Monica, who has worked diligently with her partner Cathy and the rest of the Fabulessly Frugal team to provide you this wonderful web site that gives you practical advice on cost effectively providing for your family in a -- Fabulessly Frugal way. I hope you find this budget tool to be helpful, Dave January 2012. | D21: 11 | E21: Expense 11 | F21: Expense 11 | G21: Nov | H21: Note the example below, employee Payroll receipt cleared the bank, as did the rent, electric, and gas payments so "1" is entered. The Auto
D22: 12 | E22: Expense 12 | F22: Expense 12 | G22: Dec | H22: payment has not cleared the bank. You can track your actual cash balance, anticipating all payments clearing the bank. No more overdrafts.
D23: 13 | E23: Expense 13 | F23: Expense 13
D24: 14 | E24: Expense 14 | F24: Expense 14
D25: 15 | E25: Expense 15 | F25: Expense 15
D26: 16 | E26: Expense 16 | F26: Expense 16
D27: 17 | E27: Expense 17 | F27: Expense 17
D28: 18 | E28: Expense 18 | F28: Expense 18
D29: 19 | E29: Expense 19 | F29: Expense 19
D30: 20 | E30: Expense 20 | F30: IRA Contribution
E31: IRA Beginning Balance | F31: 0
E32: Beginning Cash Balance | F32: 0
F33: Income
F34: Expense
E35: Click to go to website
H75: category. That's it -- the model does all the math. Beginning Cash Balance is ….

Sheet Ledger
B2: Reconcile your banking account on this sheet. This ledger feeds directly to the expense report. Note the bank clearing column (K), enter 1 as you reconcile to your bank statement. Enter Check number (if applicable), Date, Income or Expense then Category Number, Description, Amount (positive numbers income, negative as expense), and bank clearing as you reconcile to your bank statement. | O2: 1
B3: Check Number | C3: Date | D3: Income or Expense | E3: Cateogry Number | F3: Budget Category From Input Sheets (This captures the Category for Reporting based on Category Number) | G3: Pay to or Received From Enter Name or Description | H3: Amount | I3: Your Actual Account Balance | J3: Bank Clearing - Enter 1 if Cleared Bank | K3: Bank Balance as Shown on your Bank Statement | P3: Lookup Field
I5: =+Introduction!F32 -> 0 | K5: =+Introduction!F32 -> 0 | M5: Income
A6: Start Here => | F6: =IF(D6="Income",LOOKUP(E6,Introduction!$A$11:$A$18,Introduction!$C$11:$C$18),IF(D6="Expense",LOOKUP(E6,Introduction!$D$11:$D$30,Introduction!$F$11:$F$30),"_")) -> _ | I6: =+I5+H6 -> 0 | K6: =IF(J6=1,K5+H6,++K5) -> 0 | M6: Expense | P6: =CONCATENATE(D6," ",E6," ",MONTH(C6)," ",YEAR(C6)," ") -> 1 1900
F7: =IF(D7="Income",LOOKUP(E7,Introduction!$A$11:$A$18,Introduction!$C$11:$C$18),IF(D7="Expense",LOOKUP(E7,Introduction!$D$11:$D$30,Introduction!$F$11:$F$30),"_")) -> _ | I7: =+I6+H7 -> 0 | K7: =IF(J7=1,K6+H7,++K6) -> 0 | P7: =CONCATENATE(D7," ",E7," ",MONTH(C7)," ",YEAR(C7)," ") -> 1 1900
F8: =IF(D8="Income",LOOKUP(E8,Introduction!$A$11:$A$18,Introduction!$C$11:$C$18),IF(D8="Expense",LOOKUP(E8,Introduction!$D$11:$D$30,Introduction!$F$11:$F$30),"_")) -> _ | I8: =+I7+H8 -> 0 | K8: =IF(J8=1,K7+H8,++K7) -> 0 | P8: =CONCATENATE(D8," ",E8," ",MONTH(C8)," ",YEAR(C8)," ") -> 1 1900
F9: =IF(D9="Income",LOOKUP(E9,Introduction!$A$11:$A$18,Introduction!$C$11:$C$18),IF(D9="Expense",LOOKUP(E9,Introduction!$D$11:$D$30,Introduction!$F$11:$F$30),"_")) -> _ | I9: =+I8+H9 -> 0 | K9: =IF(J9=1,K8+H9,++K8) -> 0 | P9: =CONCATENATE(D9," ",E9," ",MONTH(C9)," ",YEAR(C9)," ") -> 1 1900
F10: =IF(D10="Income",LOOKUP(E10,Introduction!$A$11:$A$18,Introduction!$C$11:$C$18),IF(D10="Expense",LOOKUP(E10,Introduction!$D$11:$D$30,Introduction!$F$11:$F$30),"_")) -> _ | I10: =+I9+H10 -> 0 | K10: =IF(J10=1,K9+H10,++K9) -> 0 | P10: =CONCATENATE(D10," ",E10," ",MONTH(C10)," ",YEAR(C10)," ") -> 1 1900
F11: =IF(D11="Income",LOOKUP(E11,Introduction!$A$11:$A$18,Introduction!$C$11:$C$18),IF(D11="Expense",LOOKUP(E11,Introduction!$D$11:$D$30,Introduction!$F$11:$F$30),"_")) -> _ | I11: =+I10+H11 -> 0 | K11: =IF(J11=1,K10+H11,++K10) -> 0 | P11: =CONCATENATE(D11," ",E11," ",MONTH(C11)," ",YEAR(C11)," ") -> 1 1900
F12: =IF(D12="Income",LOOKUP(E12,Introduction!$A$11:$A$18,Introduction!$C$11:$C$18),IF(D12="Expense",LOOKUP(E12,Introduction!$D$11:$D$30,Introduction!$F$11:$F$30),"_")) -> _ | I12: =+I11+H12 -> 0 | K12: =IF(J12=1,K11+H12,++K11) -> 0 | P12: =CONCATENATE(D12," ",E12," ",MONTH(C12)," ",YEAR(C12)," ") -> 1 1900
F13: =IF(D13="Income",LOOKUP(E13,Introduction!$A$11:$A$18,Introduction!$C$11:$C$18),IF(D13="Expense",LOOKUP(E13,Introduction!$D$11:$D$30,Introduction!$F$11:$F$30),"_")) -> _ | I13: =+I12+H13 -> 0 | K13: =IF(J13=1,K12+H13,++K12) -> 0 | P13: =CONCATENATE(D13," ",E13," ",MONTH(C13)," ",YEAR(C13)," ") -> 1 1900
F14: =IF(D14="Income",LOOKUP(E14,Introduction!$A$11:$A$18,Introduction!$C$11:$C$18),IF(D14="Expense",LOOKUP(E14,Introduction!$D$11:$D$30,Introduction!$F$11:$F$30),"_")) -> _ | I14: =+I13+H14 -> 0 | K14: =IF(J14=1,K13+H14,++K13) -> 0 | P14: =CONCATENATE(D14," ",E14," ",MONTH(C14)," ",YEAR(C14)," ") -> 1 1900
F15: =IF(D15="Income",LOOKUP(E15,Introduction!$A$11:$A$18,Introduction!$C$11:$C$18),IF(D15="Expense",LOOKUP(E15,Introduction!$D$11:$D$30,Introduction!$F$11:$F$30),"_")) -> _ | I15: =+I14+H15 -> 0 | K15: =IF(J15=1,K14+H15,++K14) -> 0 | P15: =CONCATENATE(D15," ",E15," ",MONTH(C15)," ",YEAR(C15)," ") -> 1 1900
F16: =IF(D16="Income",LOOKUP(E16,Introduction!$A$11:$A$18,Introduction!$C$11:$C$18),IF(D16="Expense",LOOKUP(E16,Introduction!$D$11:$D$30,Introduction!$F$11:$F$30),"_")) -> _ | I16: =+I15+H16 -> 0 | K16: =IF(J16=1,K15+H16,++K15) -> 0 | P16: =CONCATENATE(D16," ",E16," ",MONTH(C16)," ",YEAR(C16)," ") -> 1 1900
F17: =IF(D17="Income",LOOKUP(E17,Introduction!$A$11:$A$18,Introduction!$C$11:$C$18),IF(D17="Expense",LOOKUP(E17,Introduction!$D$11:$D$30,Introduction!$F$11:$F$30),"_")) -> _ | I17: =+I16+H17 -> 0 | K17: =IF(J17=1,K16+H17,++K16) -> 0 | P17: =CONCATENATE(D17," ",E17," ",MONTH(C17)," ",YEAR(C17)," ") -> 1 1900
F18: =IF(D18="Income",LOOKUP(E18,Introduction!$A$11:$A$18,Introduction!$C$11:$C$18),IF(D18="Expense",LOOKUP(E18,Introduction!$D$11:$D$30,Introduction!$F$11:$F$30),"_")) -> _ | I18: =+I17+H18 -> 0 | K18: =IF(J18=1,K17+H18,++K17) -> 0 | P18: =CONCATENATE(D18," ",E18," ",MONTH(C18)," ",YEAR(C18)," ") -> 1 1900
... F111: =IF(D111="Income",LOOKUP(E111,Introduction!$A$11:$A$18,Introduction!$C$11:$C$18),IF(D111="Expense",LOOKUP(E111,Introduction!$D$11:$D$30,Introduction!$F$11:$F$30),"_")) -> _ | I111: =+I110+H111 -> 0 | K111: =IF(J111=1,K110+H111,++K110) -> 0 | P111: =CONCATENATE(D111," ",E111," ",MONTH(C111)," ",YEAR(C111)," ") -> 1 1900
F112: =IF(D112="Income",LOOKUP(E112,Introduction!$A$11:$A$18,Introduction!$C$11:$C$18),IF(D112="Expense",LOOKUP(E112,Introduction!$D$11:$D$30,Introduction!$F$11:$F$30),"_")) -> _ | H112: =-ROUND(H6*$O$2,2) -> 0 | I112: =+I111+H112 -> 0 | K112: =IF(J112=1,K111+H112,++K111) -> 0 | P112: =CONCATENATE(D112," ",E112," ",MONTH(C112)," ",YEAR(C112)," ") -> 1 1900
F113: =IF(D113="Income",LOOKUP(E113,Introduction!$A$11:$A$18,Introduction!$C$11:$C$18),IF(D113="Expense",LOOKUP(E113,Introduction!$D$11:$D$30,Introduction!$F$11:$F$30),"_")) -> _ | H113: =-ROUND(H7*$O$2,2) -> 0 | I113: =+I112+H113 -> 0 | K113: =IF(J113=1,K112+H113,++K112) -> 0 | P113: =CONCATENATE(D113," ",E113," ",MONTH(C113)," ",YEAR(C113)," ") -> 1 1900
F114: =IF(D114="Income",LOOKUP(E114,Introduction!$A$11:$A$18,Introduction!$C$11:$C$18),IF(D114="Expense",LOOKUP(E114,Introduction!$D$11:$D$30,Introduction!$F$11:$F$30),"_")) -> _ | H114: =-ROUND(H8*$O$2,2) -> 0 | I114: =+I113+H114 -> 0 | K114: =IF(J114=1,K113+H114,++K113) -> 0 | P114: =CONCATENATE(D114," ",E114," ",MONTH(C114)," ",YEAR(C114)," ") -> 1 1900
F115: =IF(D115="Income",LOOKUP(E115,Introduction!$A$11:$A$18,Introduction!$C$11:$C$18),IF(D115="Expense",LOOKUP(E115,Introduction!$D$11:$D$30,Introduction!$F$11:$F$30),"_")) -> _ | H115: =-ROUND(H9*$O$2,2) -> 0 | I115: =+I114+H115 -> 0 | K115: =IF(J115=1,K114+H115,++K114) -> 0 | P115: =CONCATENATE(D115," ",E115," ",MONTH(C115)," ",YEAR(C115)," ") -> 1 1900
F116: =IF(D116="Income",LOOKUP(E116,Introduction!$A$11:$A$18,Introduction!$C$11:$C$18),IF(D116="Expense",LOOKUP(E116,Introduction!$D$11:$D$30,Introduction!$F$11:$F$30),"_")) -> _ | H116: =-ROUND(H10*$O$2,2) -> 0 | I116: =+I115+H116 -> 0 | K116: =IF(J116=1,K115+H116,++K115) -> 0 | P116: =CONCATENATE(D116," ",E116," ",MONTH(C116)," ",YEAR(C116)," ") -> 1 1900
F117: =IF(D117="Income",LOOKUP(E117,Introduction!$A$11:$A$18,Introduction!$C$11:$C$18),IF(D117="Expense",LOOKUP(E117,Introduction!$D$11:$D$30,Introduction!$F$11:$F$30),"_")) -> _ | H117: =-ROUND(H11*$O$2,2) -> 0 | I117: =+I116+H117 -> 0 | K117: =IF(J117=1,K116+H117,++K116) -> 0 | P117: =CONCATENATE(D117," ",E117," ",MONTH(C117)," ",YEAR(C117)," ") -> 1 1900
F118: =IF(D118="Income",LOOKUP(E118,Introduction!$A$11:$A$18,Introduction!$C$11:$C$18),IF(D118="Expense",LOOKUP(E118,Introduction!$D$11:$D$30,Introduction!$F$11:$F$30),"_")) -> _ | H118: =-ROUND(H12*$O$2,2) -> 0 | I118: =+I117+H118 -> 0 | K118: =IF(J118=1,K117+H118,++K117) -> 0 | P118: =CONCATENATE(D118," ",E118," ",MONTH(C118)," ",YEAR(C118)," ") -> 1 1900
F119: =IF(D119="Income",LOOKUP(E119,Introduction!$A$11:$A$18,Introduction!$C$11:$C$18),IF(D119="Expense",LOOKUP(E119,Introduction!$D$11:$D$30,Introduction!$F$11:$F$30),"_")) -> _ | H119: =-ROUND(H13*$O$2,2) -> 0 | I119: =+I118+H119 -> 0 | K119: =IF(J119=1,K118+H119,++K118) -> 0 | P119: =CONCATENATE(D119," ",E119," ",MONTH(C119)," ",YEAR(C119)," ") -> 1 1900
F120: =IF(D120="Income",LOOKUP(E120,Introduction!$A$11:$A$18,Introduction!$C$11:$C$18),IF(D120="Expense",LOOKUP(E120,Introduction!$D$11:$D$30,Introduction!$F$11:$F$30),"_")) -> _ | H120: =-ROUND(H14*$O$2,2) -> 0 | I120: =+I119+H120 -> 0 | K120: =IF(J120=1,K119+H120,++K119) -> 0 | P120: =CONCATENATE(D120," ",E120," ",MONTH(C120)," ",YEAR(C120)," ") -> 1 1900
F121: =IF(D121="Income",LOOKUP(E121,Introduction!$A$11:$A$18,Introduction!$C$11:$C$18),IF(D121="Expense",LOOKUP(E121,Introduction!$D$11:$D$30,Introduction!$F$11:$F$30),"_")) -> _ | H121: =-ROUND(H15*$O$2,2) -> 0 | I121: =+I120+H121 -> 0 | K121: =IF(J121=1,K120+H121,++K120) -> 0 | P121: =CONCATENATE(D121," ",E121," ",MONTH(C121)," ",YEAR(C121)," ") -> 1 1900
F122: =IF(D122="Income",LOOKUP(E122,Introduction!$A$11:$A$18,Introduction!$C$11:$C$18),IF(D122="Expense",LOOKUP(E122,Introduction!$D$11:$D$30,Introduction!$F$11:$F$30),"_")) -> _ | H122: =-ROUND(H16*$O$2,2) -> 0 | I122: =+I121+H122 -> 0 | K122: =IF(J122=1,K121+H122,++K121) -> 0 | P122: =CONCATENATE(D122," ",E122," ",MONTH(C122)," ",YEAR(C122)," ") -> 1 1900
F123: =IF(D123="Income",LOOKUP(E123,Introduction!$A$11:$A$18,Introduction!$C$11:$C$18),IF(D123="Expense",LOOKUP(E123,Introduction!$D$11:$D$30,Introduction!$F$11:$F$30),"_")) -> _ | H123: =-ROUND(H17*$O$2,2) -> 0 | I123: =+I122+H123 -> 0 | K123: =IF(J123=1,K122+H123,++K122) -> 0 | P123: =CONCATENATE(D123," ",E123," ",MONTH(C123)," ",YEAR(C123)," ") -> 1 1900
F124: =IF(D124="Income",LOOKUP(E124,Introduction!$A$11:$A$18,Introduction!$C$11:$C$18),IF(D124="Expense",LOOKUP(E124,Introduction!$D$11:$D$30,Introduction!$F$11:$F$30),"_")) -> _ | I124: =+I123+H124 -> 0 | K124: =IF(J124=1,K123+H124,++K123) -> 0 | P124: =CONCATENATE(D124," ",E124," ",MONTH(C124)," ",YEAR(C124)," ") -> 1 1900
F125: =IF(D125="Income",LOOKUP(E125,Introduction!$A$11:$A$18,Introduction!$C$11:$C$18),IF(D125="Expense",LOOKUP(E125,Introduction!$D$11:$D$30,Introduction!$F$11:$F$30),"_")) -> _ | H125: =-ROUND(H19*$O$2,2) -> 0 | I125: =+I124+H125 -> 0 | K125: =IF(J125=1,K124+H125,++K124) -> 0 | P125: =CONCATENATE(D125," ",E125," ",MONTH(C125)," ",YEAR(C125)," ") -> 1 1900
F126: =IF(D126="Income",LOOKUP(E126,Introduction!$A$11:$A$18,Introduction!$C$11:$C$18),IF(D126="Expense",LOOKUP(E126,Introduction!$D$11:$D$30,Introduction!$F$11:$F$30),"_")) -> _ | H126: =-ROUND(H20*$O$2,2) -> 0 | I126: =+I125+H126 -> 0 | K126: =IF(J126=1,K125+H126,++K125) -> 0 | P126: =CONCATENATE(D126," ",E126," ",MONTH(C126)," ",YEAR(C126)," ") -> 1 1900
F127: =IF(D127="Income",LOOKUP(E127,Introduction!$A$11:$A$18,Introduction!$C$11:$C$18),IF(D127="Expense",LOOKUP(E127,Introduction!$D$11:$D$30,Introduction!$F$11:$F$30),"_")) -> _ | H127: =-ROUND(H21*$O$2,2) -> 0 | I127: =+I126+H127 -> 0 | K127: =IF(J127=1,K126+H127,++K126) -> 0 | P127: =CONCATENATE(D127," ",E127," ",MONTH(C127)," ",YEAR(C127)," ") -> 1 1900
F128: =IF(D128="Income",LOOKUP(E128,Introduction!$A$11:$A$18,Introduction!$C$11:$C$18),IF(D128="Expense",LOOKUP(E128,Introduction!$D$11:$D$30,Introduction!$F$11:$F$30),"_")) -> _ | H128: =-ROUND(H22*$O$2,2) -> 0 | I128: =+I127+H128 -> 0 | K128: =IF(J128=1,K127+H128,++K127) -> 0 | P128: =CONCATENATE(D128," ",E128," ",MONTH(C128)," ",YEAR(C128)," ") -> 1 1900
F129: =IF(D129="Income",LOOKUP(E129,Introduction!$A$11:$A$18,Introduction!$C$11:$C$18),IF(D129="Expense",LOOKUP(E129,Introduction!$D$11:$D$30,Introduction!$F$11:$F$30),"_")) -> _ | H129: =-ROUND(H23*$O$2,2) -> 0 | I129: =+I128+H129 -> 0 | K129: =IF(J129=1,K128+H129,++K128) -> 0 | P129: =CONCATENATE(D129," ",E129," ",MONTH(C129)," ",YEAR(C129)," ") -> 1 1900
F130: =IF(D130="Income",LOOKUP(E130,Introduction!$A$11:$A$18,Introduction!$C$11:$C$18),IF(D130="Expense",LOOKUP(E130,Introduction!$D$11:$D$30,Introduction!$F$11:$F$30),"_")) -> _ | H130: =-ROUND(H24*$O$2,2) -> 0 | I130: =+I129+H130 -> 0 | K130: =IF(J130=1,K129+H130,++K129) -> 0 | P130: =CONCATENATE(D130," ",E130," ",MONTH(C130)," ",YEAR(C130)," ") -> 1 1900
F131: =IF(D131="Income",LOOKUP(E131,Introduction!$A$11:$A$18,Introduction!$C$11:$C$18),IF(D131="Expense",LOOKUP(E131,Introduction!$D$11:$D$30,Introduction!$F$11:$F$30),"_")) -> _ | H131: =-ROUND(H25*$O$2,2) -> 0 | I131: =+I130+H131 -> 0 | K131: =IF(J131=1,K130+H131,++K130) -> 0 | P131: =CONCATENATE(D131," ",E131," ",MONTH(C131)," ",YEAR(C131)," ") -> 1 1900
F132: =IF(D132="Income",LOOKUP(E132,Introduction!$A$11:$A$18,Introduction!$C$11:$C$18),IF(D132="Expense",LOOKUP(E132,Introduction!$D$11:$D$30,Introduction!$F$11:$F$30),"_")) -> _ | H132: =-ROUND(H26*$O$2,2) -> 0 | I132: =+I131+H132 -> 0 | K132: =IF(J132=1,K131+H132,++K131) -> 0 | P132: =CONCATENATE(D132," ",E132," ",MONTH(C132)," ",YEAR(C132)," ") -> 1 1900
F133: =IF(D133="Income",LOOKUP(E133,Introduction!$A$11:$A$18,Introduction!$C$11:$C$18),IF(D133="Expense",LOOKUP(E133,Introduction!$D$11:$D$30,Introduction!$F$11:$F$30),"_")) -> _ | H133: =-ROUND(H27*$O$2,2) -> 0 | I133: =+I132+H133 -> 0 | K133: =IF(J133=1,K132+H133,++K132) -> 0 | P133: =CONCATENATE(D133," ",E133," ",MONTH(C133)," ",YEAR(C133)," ") -> 1 1900
F134: =IF(D134="Income",LOOKUP(E134,Introduction!$A$11:$A$18,Introduction!$C$11:$C$18),IF(D134="Expense",LOOKUP(E134,Introduction!$D$11:$D$30,Introduction!$F$11:$F$30),"_")) -> _ | H134: =-ROUND(H28*$O$2,2) -> 0 | I134: =+I133+H134 -> 0 | K134: =IF(J134=1,K133+H134,++K133) -> 0 | P134: =CONCATENATE(D134," ",E134," ",MONTH(C134)," ",YEAR(C134)," ") -> 1 1900
...

Sheet Budget
B2: =CONCATENATE(Introduction!C4:C4,"'s"," Personal Budget ",Introduction!C5) -> 's Personal Budget 2012
B3: Days on Month Calc | E3: 31 | F3: =IF(MOD(Introduction!C5,4)=0,29,28) -> 29 | G3: 31 | H3: 30 | I3: 31 | J3: 30 | K3: 31 | L3: 31 | M3: 30 | N3: 31 | O3: 30 | P3: 31
B4: Month and Year Calc | E4: =CONCATENATE(MONTH(E5)," ",YEAR(E5)) -> 1 2012 | F4: =CONCATENATE(MONTH(F5)," ",YEAR(F5)) -> 2 2012 | G4: =CONCATENATE(MONTH(G5)," ",YEAR(G5)) -> 3 2012 | H4: =CONCATENATE(MONTH(H5)," ",YEAR(H5)) -> 4 2012 | I4: =CONCATENATE(MONTH(I5)," ",YEAR(I5)) -> 5 2012 | J4: =CONCATENATE(MONTH(J5)," ",YEAR(J5)) -> 6 2012 | K4: =CONCATENATE(MONTH(K5)," ",YEAR(K5)) -> 7 2012 | L4: =CONCATENATE(MONTH(L5)," ",YEAR(L5)) -> 8 2012 | ... P4: =CONCATENATE(MONTH(P5)," ",YEAR(P5)) -> 12 2012
B5: Items Revenue/Expense | E5: =+Introduction!C6+0 -> 40909 | F5: =+E5+E3 -> 40940 | G5: =+F5+F3 -> 40969 | H5: =+G5+G3 -> 41000 | I5: =+H5+H3 -> 41030 | J5: =+I5+I3 -> 41061 | K5: =+J5+J3 -> 41091 | L5: =+K5+K3 -> 41122 | M5: =+L5+L3 -> 41153 | ... Q5: =+P5+P3 -> 41275 | R5: Total
B6: 1 | C6: =+Introduction!C11 -> Income 1 | Q6: . | R6: =SUM(E6:P6) -> 0
B7: 2 | C7: =+Introduction!C12 -> Income 2 | R7: =SUM(E7:P7) -> 0
B8: 3 | C8: =+Introduction!C13 -> Income 3 | R8: =SUM(E8:P8) -> 0
B9: 4 | C9: =+Introduction!C14 -> Income 4 | R9: =SUM(E9:P9) -> 0
B10: 5 | C10: =+Introduction!C15 -> Income 5 | R10: =SUM(E10:P10) -> 0
B11: 6 | C11: =+Introduction!C16 -> Income 6 | R11: =SUM(E11:P11) -> 0
B12: 7 | C12: =+Introduction!C17 -> Income 7 | R12: =SUM(E12:P12) -> 0
B13: 8 | C13: =+Introduction!C18 -> Income 8 | R13: =SUM(E13:P13) -> 0
C14: Total Income | E14: =SUM(E6:E13) -> 0 | F14: =SUM(F6:F13) -> 0 | G14: =SUM(G6:G13) -> 0 | H14: =SUM(H6:H13) -> 0 | I14: =SUM(I6:I13) -> 0 | J14: =SUM(J6:J13) -> 0 | K14: =SUM(K6:K13) -> 0 | L14: =SUM(L6:L13) -> 0 | ... R14: =SUM(R6:R13) -> 0
R15: =IF(SUM(E15:P15)<>0,SUM(E15:P15),"")
C16: Month and Year Calc Income/Expense | E16: =CONCATENATE(MONTH(E17)," ",YEAR(E17), " Expense") -> 1 2012 Expense | F16: =CONCATENATE(MONTH(F17)," ",YEAR(F17), " Expense") -> 2 2012 Expense | G16: =CONCATENATE(MONTH(G17)," ",YEAR(G17), " Expense") -> 3 2012 Expense | H16: =CONCATENATE(MONTH(H17)," ",YEAR(H17), " Expense") -> 4 2012 Expense | I16: =CONCATENATE(MONTH(I17)," ",YEAR(I17), " Expense") -> 5 2012 Expense | J16: =CONCATENATE(MONTH(J17)," ",YEAR(J17), " Expense") -> 6 2012 Expense | K16: =CONCATENATE(MONTH(K17)," ",YEAR(K17), " Expense") -> 7 2012 Expense | L16: =CONCATENATE(MONTH(L17)," ",YEAR(L17), " Expense") -> 8 2012 Expense | ... P16: =CONCATENATE(MONTH(P17)," ",YEAR(P17), " Expense") -> 12 2012 Expense
C17: Expenses | E17: =+E5 -> 40909 | F17: =+F5 -> 40940 | G17: =+G5 -> 40969 | H17: =+H5 -> 41000 | I17: =+I5 -> 41030 | J17: =+J5 -> 41061 | K17: =+K5 -> 41091 | L17: =+L5 -> 41122 | ... P17: =+P5 -> 41244 | R17: Total
B18: 1 | C18: =+Introduction!F11 -> Expense 1 | R18: =SUM(E18:P18) -> 0
B19: 2 | C19: =+Introduction!F12 -> Expense 2 | R19: =SUM(E19:P19) -> 0
B20: 3 | C20: =+Introduction!F13 -> Expense 3 | R20: =SUM(E20:P20) -> 0
B21: 4 | C21: =+Introduction!F14 -> Expense 4 | R21: =SUM(E21:P21) -> 0
B22: 5 | C22: =+Introduction!F15 -> Expense 5 | R22: =SUM(E22:P22) -> 0
B23: 6 | C23: =+Introduction!F16 -> Expense 6 | R23: =SUM(E23:P23) -> 0
B24: 7 | C24: =+Introduction!F17 -> Expense 7 | R24: =SUM(E24:P24) -> 0
B25: 8 | C25: =+Introduction!F18 -> Expense 8 | R25: =SUM(E25:P25) -> 0
B26: 9 | C26: =+Introduction!F19 -> Expense 9 | R26: =SUM(E26:P26) -> 0
B27: 10 | C27: =+Introduction!F20 -> Expense 10 | R27: =SUM(E27:P27) -> 0
B28: 11 | C28: =+Introduction!F21 -> Expense 11 | R28: =SUM(E28:P28) -> 0
B29: 12 | C29: =+Introduction!F22 -> Expense 12 | R29: =SUM(E29:P29) -> 0
... B37: 20 | C37: =+Introduction!F30 -> IRA Contribution | R37: =SUM(E37:P37) -> 0
B38: Total Expenses | E38: =SUM(E18:E37) -> 0 | F38: =SUM(F18:F37) -> 0 | G38: =SUM(G18:G37) -> 0 | H38: =SUM(H18:H37) -> 0 | I38: =SUM(I18:I37) -> 0 | J38: =SUM(J18:J37) -> 0 | K38: =SUM(K18:K37) -> 0 | L38: =SUM(L18:L37) -> 0 | ... P38: =SUM(P18:P37) -> 0 | R38: =SUM(E38:P38) -> 0
R39: =IF(SUM(E39:P39)<>0,SUM(E39:P39),"")
B40: Income Less Expenses | E40: =+E14-E38 -> 0 | F40: =+F14-F38 -> 0 | G40: =+G14-G38 -> 0 | H40: =+H14-H38 -> 0 | I40: =+I14-I38 -> 0 | J40: =+J14-J38 -> 0 | K40: =+K14-K38 -> 0 | L40: =+L14-L38 -> 0 | ... R40: =+R14-R38 -> 0
R41: =IF(SUM(E41:P41)<>0,SUM(E41:P41),"")
B42: 1 | C42: Beginning Cash Balance | E42: =+Introduction!F32 -> 0 | F42: =+E44 -> 0 | G42: =+F44 -> 0 | H42: =+G44 -> 0 | I42: =+H44 -> 0 | J42: =+I44 -> 0 | K42: =+J44 -> 0 | L42: =+K44 -> 0 | M42: =+L44 -> 0 | ... P42: =+O44 -> 0 | R42: =+E42 -> 0
B43: 2 | C43: Income Less Expense | E43: =+E40 -> 0 | F43: =+F40 -> 0 | G43: =+G40 -> 0 | H43: =+H40 -> 0 | I43: =+I40 -> 0 | J43: =+J40 -> 0 | K43: =+K40 -> 0 | L43: =+L40 -> 0 | ... P43: =+P40 -> 0 | R43: =SUM(E43:P43) -> 0
B44: 3 | C44: Ending Cash Balance | E44: =+E43+E42 -> 0 | F44: =+F43+F42 -> 0 | G44: =+G43+G42 -> 0 | H44: =+H43+H42 -> 0 | I44: =+I43+I42 -> 0 | J44: =+J43+J42 -> 0 | K44: =+K43+K42 -> 0 | L44: =+L43+L42 -> 0 | ... P44: =+P43+P42 -> 0 | Q44: =IFERROR(IF(OR(Q42<>0,Q43<>0),Q42+Q43,""),"") | R44: =R42+R43 -> 0
B46: 1 | C46: Roth IRA Cumulative Contribution | E46: =+Introduction!F31+Budget!E37 -> 0 | F46: =+E46+F37 -> 0 | G46: =+F46+G37 -> 0 | H46: =+G46+H37 -> 0 | I46: =+H46+I37 -> 0 | J46: =+I46+J37 -> 0 | K46: =+J46+K37 -> 0 | L46: =+K46+L37 -> 0 | M46: =+L46+M37 -> 0 | ... P46: =+O46+P37 -> 0 | R46: =+P46 -> 0
R48: =IF(SUM(E48:P48)<>0,SUM(E48:P48),"")
R49: =IF(SUM(E49:P49)<>0,SUM(E49:P49),"")
R50: =IF(SUM(E50:P50)<>0,SUM(E50:P50),"")
...

Sheet Actual
B2: =CONCATENATE(Introduction!C4:C4,"'s"," ACTUAL SPENDING ",Introduction!C5) -> 's ACTUAL SPENDING 2012
C3: Days on Month Calc | E3: 31 | F3: =IF(MOD(Introduction!C5,4)=0,29,28) -> 29 | G3: 31 | H3: 30 | I3: 31 | J3: 30 | K3: 31 | L3: 31 | M3: 30 | N3: 31 | O3: 30 | P3: 31
C4: Month and Year Calc Income/Expense | E4: =CONCATENATE(MONTH(E5)," ",YEAR(E5), " Income") -> 1 2012 Income | F4: =CONCATENATE(MONTH(F5)," ",YEAR(F5), " Income") -> 2 2012 Income | G4: =CONCATENATE(MONTH(G5)," ",YEAR(G5), " Income") -> 3 2012 Income | H4: =CONCATENATE(MONTH(H5)," ",YEAR(H5), " Income") -> 4 2012 Income | I4: =CONCATENATE(MONTH(I5)," ",YEAR(I5), " Income") -> 5 2012 Income | J4: =CONCATENATE(MONTH(J5)," ",YEAR(J5), " Income") -> 6 2012 Income | K4: =CONCATENATE(MONTH(K5)," ",YEAR(K5), " Income") -> 7 2012 Income | L4: =CONCATENATE(MONTH(L5)," ",YEAR(L5), " Income") -> 8 2012 Income | ... P4: =CONCATENATE(MONTH(P5)," ",YEAR(P5), " Income") -> 12 2012 Income
B5: ={"Items Revenue/Expense",0} -> Items Revenue/Expense | C5: Items Revenue/Expense | E5: =+Introduction!C6+0 -> 40909 | F5: =+E5+E3 -> 40940 | G5: =+F5+F3 -> 40969 | H5: =+G5+G3 -> 41000 | I5: =+H5+H3 -> 41030 | J5: =+I5+I3 -> 41061 | K5: =+J5+J3 -> 41091 | L5: =+K5+K3 -> 41122 | M5: =+L5+L3 -> 41153 | ... Q5: =+P5+P3 -> 41275 | R5: Total
B6: 1 | C6: =+Introduction!C11 -> Income 1 | E6: =SUMIF(Ledger!$P$6:$P$2011,CONCATENATE("Income ",Actual!$B6," ",MONTH(Actual!E$5)," ",YEAR(Actual!E$5)," "),Ledger!$H$6:$H$2011) -> 0 | F6: =SUMIF(Ledger!$P$6:$P$2011,CONCATENATE("Income ",Actual!$B6," ",MONTH(Actual!F$5)," ",YEAR(Actual!F$5)," "),Ledger!$H$6:$H$2011) -> 0 | G6: =SUMIF(Ledger!$P$6:$P$2011,CONCATENATE("Income ",Actual!$B6," ",MONTH(Actual!G$5)," ",YEAR(Actual!G$5)," "),Ledger!$H$6:$H$2011) -> 0 | H6: =SUMIF(Ledger!$P$6:$P$2011,CONCATENATE("Income ",Actual!$B6," ",MONTH(Actual!H$5)," ",YEAR(Actual!H$5)," "),Ledger!$H$6:$H$2011) -> 0 | I6: =SUMIF(Ledger!$P$6:$P$2011,CONCATENATE("Income ",Actual!$B6," ",MONTH(Actual!I$5)," ",YEAR(Actual!I$5)," "),Ledger!$H$6:$H$2011) -> 0 | J6: =SUMIF(Ledger!$P$6:$P$2011,CONCATENATE("Income ",Actual!$B6," ",MONTH(Actual!J$5)," ",YEAR(Actual!J$5)," "),Ledger!$H$6:$H$2011) -> 0 | K6: =SUMIF(Ledger!$P$6:$P$2011,CONCATENATE("Income ",Actual!$B6," ",MONTH(Actual!K$5)," ",YEAR(Actual!K$5)," "),Ledger!$H$6:$H$2011) -> 0 | L6: =SUMIF(Ledger!$P$6:$P$2011,CONCATENATE("Income ",Actual!$B6," ",MONTH(Actual!L$5)," ",YEAR(Actual!L$5)," "),Ledger!$H$6:$H$2011) -> 0 | ... P6: =SUMIF(Ledger!$P$6:$P$2011,CONCATENATE("Income ",Actual!$B6," ",MONTH(Actual!P$5)," ",YEAR(Actual!P$5)," "),Ledger!$H$6:$H$2011) -> 0 | R6: =SUM(E6:P6) -> 0
B7: 2 | C7: =+Introduction!C12 -> Income 2 | E7: =SUMIF(Ledger!$P$6:$P$2011,CONCATENATE("Income ",Actual!$B7," ",MONTH(Actual!E$5)," ",YEAR(Actual!E$5)," "),Ledger!$H$6:$H$2011) -> 0 | F7: =SUMIF(Ledger!$P$6:$P$2011,CONCATENATE("Income ",Actual!$B7," ",MONTH(Actual!F$5)," ",YEAR(Actual!F$5)," "),Ledger!$H$6:$H$2011) -> 0 | G7: =SUMIF(Ledger!$P$6:$P$2011,CONCATENATE("Income ",Actual!$B7," ",MONTH(Actual!G$5)," ",YEAR(Actual!G$5)," "),Ledger!$H$6:$H$2011) -> 0 | H7: =SUMIF(Ledger!$P$6:$P$2011,CONCATENATE("Income ",Actual!$B7," ",MONTH(Actual!H$5)," ",YEAR(Actual!H$5)," "),Ledger!$H$6:$H$2011) -> 0 | I7: =SUMIF(Ledger!$P$6:$P$2011,CONCATENATE("Income ",Actual!$B7," ",MONTH(Actual!I$5)," ",YEAR(Actual!I$5)," "),Ledger!$H$6:$H$2011) -> 0 | J7: =SUMIF(Ledger!$P$6:$P$2011,CONCATENATE("Income ",Actual!$B7," ",MONTH(Actual!J$5)," ",YEAR(Actual!J$5)," "),Ledger!$H$6:$H$2011) -> 0 | K7: =SUMIF(Ledger!$P$6:$P$2011,CONCATENATE("Income ",Actual!$B7," ",MONTH(Actual!K$5)," ",YEAR(Actual!K$5)," "),Ledger!$H$6:$H$2011) -> 0 | L7: =SUMIF(Ledger!$P$6:$P$2011,CONCATENATE("Income ",Actual!$B7," ",MONTH(Actual!L$5)," ",YEAR(Actual!L$5)," "),Ledger!$H$6:$H$2011) -> 0 | ... P7: =SUMIF(Ledger!$P$6:$P$2011,CONCATENATE("Income ",Actual!$B7," ",MONTH(Actual!P$5)," ",YEAR(Actual!P$5)," "),Ledger!$H$6:$H$2011) -> 0 | R7: =SUM(E7:P7) -> 0
B8: 3 | C8: =+Introduction!C13 -> Income 3 | E8: =SUMIF(Ledger!$P$6:$P$2011,CONCATENATE("Income ",Actual!$B8," ",MONTH(Actual!E$5)," ",YEAR(Actual!E$5)," "),Ledger!$H$6:$H$2011) -> 0 | F8: =SUMIF(Ledger!$P$6:$P$2011,CONCATENATE("Income ",Actual!$B8," ",MONTH(Actual!F$5)," ",YEAR(Actual!F$5)," "),Ledger!$H$6:$H$2011) -> 0 | G8: =SUMIF(Ledger!$P$6:$P$2011,CONCATENATE("Income ",Actual!$B8," ",MONTH(Actual!G$5)," ",YEAR(Actual!G$5)," "),Ledger!$H$6:$H$2011) -> 0 | H8: =SUMIF(Ledger!$P$6:$P$2011,CONCATENATE("Income ",Actual!$B8," ",MONTH(Actual!H$5)," ",YEAR(Actual!H$5)," "),Ledger!$H$6:$H$2011) -> 0 | I8: =SUMIF(Ledger!$P$6:$P$2011,CONCATENATE("Income ",Actual!$B8," ",MONTH(Actual!I$5)," ",YEAR(Actual!I$5)," "),Ledger!$H$6:$H$2011) -> 0 | J8: =SUMIF(Ledger!$P$6:$P$2011,CONCATENATE("Income ",Actual!$B8," ",MONTH(Actual!J$5)," ",YEAR(Actual!J$5)," "),Ledger!$H$6:$H$2011) -> 0 | K8: =SUMIF(Ledger!$P$6:$P$2011,CONCATENATE("Income ",Actual!$B8," ",MONTH(Actual!K$5)," ",YEAR(Actual!K$5)," "),Ledger!$H$6:$H$2011) -> 0 | L8: =SUMIF(Ledger!$P$6:$P$2011,CONCATENATE("Income ",Actual!$B8," ",MONTH(Actual!L$5)," ",YEAR(Actual!L$5)," "),Ledger!$H$6:$H$2011) -> 0 | ... P8: =SUMIF(Ledger!$P$6:$P$2011,CONCATENATE("Income ",Actual!$B8," ",MONTH(Actual!P$5)," ",YEAR(Actual!P$5)," "),Ledger!$H$6:$H$2011) -> 0 | R8: =SUM(E8:P8) -> 0
B9: 4 | C9: =+Introduction!C14 -> Income 4 | E9: =SUMIF(Ledger!$P$6:$P$2011,CONCATENATE("Income ",Actual!$B9," ",MONTH(Actual!E$5)," ",YEAR(Actual!E$5)," "),Ledger!$H$6:$H$2011) -> 0 | F9: =SUMIF(Ledger!$P$6:$P$2011,CONCATENATE("Income ",Actual!$B9," ",MONTH(Actual!F$5)," ",YEAR(Actual!F$5)," "),Ledger!$H$6:$H$2011) -> 0 | G9: =SUMIF(Ledger!$P$6:$P$2011,CONCATENATE("Income ",Actual!$B9," ",MONTH(Actual!G$5)," ",YEAR(Actual!G$5)," "),Ledger!$H$6:$H$2011) -> 0 | H9: =SUMIF(Ledger!$P$6:$P$2011,CONCATENATE("Income ",Actual!$B9," ",MONTH(Actual!H$5)," ",YEAR(Actual!H$5)," "),Ledger!$H$6:$H$2011) -> 0 | I9: =SUMIF(Ledger!$P$6:$P$2011,CONCATENATE("Income ",Actual!$B9," ",MONTH(Actual!I$5)," ",YEAR(Actual!I$5)," "),Ledger!$H$6:$H$2011) -> 0 | J9: =SUMIF(Ledger!$P$6:$P$2011,CONCATENATE("Income ",Actual!$B9," ",MONTH(Actual!J$5)," ",YEAR(Actual!J$5)," "),Ledger!$H$6:$H$2011) -> 0 | K9: =SUMIF(Ledger!$P$6:$P$2011,CONCATENATE("Income ",Actual!$B9," ",MONTH(Actual!K$5)," ",YEAR(Actual!K$5)," "),Ledger!$H$6:$H$2011) -> 0 | L9: =SUMIF(Ledger!$P$6:$P$2011,CONCATENATE("Income ",Actual!$B9," ",MONTH(Actual!L$5)," ",YEAR(Actual!L$5)," "),Ledger!$H$6:$H$2011) -> 0 | ... P9: =SUMIF(Ledger!$P$6:$P$2011,CONCATENATE("Income ",Actual!$B9," ",MONTH(Actual!P$5)," ",YEAR(Actual!P$5)," "),Ledger!$H$6:$H$2011) -> 0 | R9: =SUM(E9:P9) -> 0
B10: 5 | C10: =+Introduction!C15 -> Income 5 | E10: =SUMIF(Ledger!$P$6:$P$2011,CONCATENATE("Income ",Actual!$B10," ",MONTH(Actual!E$5)," ",YEAR(Actual!E$5)," "),Ledger!$H$6:$H$2011) -> 0 | F10: =SUMIF(Ledger!$P$6:$P$2011,CONCATENATE("Income ",Actual!$B10," ",MONTH(Actual!F$5)," ",YEAR(Actual!F$5)," "),Ledger!$H$6:$H$2011) -> 0 | G10: =SUMIF(Ledger!$P$6:$P$2011,CONCATENATE("Income ",Actual!$B10," ",MONTH(Actual!G$5)," ",YEAR(Actual!G$5)," "),Ledger!$H$6:$H$2011) -> 0 | H10: =SUMIF(Ledger!$P$6:$P$2011,CONCATENATE("Income ",Actual!$B10," ",MONTH(Actual!H$5)," ",YEAR(Actual!H$5)," "),Ledger!$H$6:$H$2011) -> 0 | I10: =SUMIF(Ledger!$P$6:$P$2011,CONCATENATE("Income ",Actual!$B10," ",MONTH(Actual!I$5)," ",YEAR(Actual!I$5)," "),Ledger!$H$6:$H$2011) -> 0 | J10: =SUMIF(Ledger!$P$6:$P$2011,CONCATENATE("Income ",Actual!$B10," ",MONTH(Actual!J$5)," ",YEAR(Actual!J$5)," "),Ledger!$H$6:$H$2011) -> 0 | K10: =SUMIF(Ledger!$P$6:$P$2011,CONCATENATE("Income ",Actual!$B10," ",MONTH(Actual!K$5)," ",YEAR(Actual!K$5)," "),Ledger!$H$6:$H$2011) -> 0 | L10: =SUMIF(Ledger!$P$6:$P$2011,CONCATENATE("Income ",Actual!$B10," ",MONTH(Actual!L$5)," ",YEAR(Actual!L$5)," "),Ledger!$H$6:$H$2011) -> 0 | ... P10: =SUMIF(Ledger!$P$6:$P$2011,CONCATENATE("Income ",Actual!$B10," ",MONTH(Actual!P$5)," ",YEAR(Actual!P$5)," "),Ledger!$H$6:$H$2011) -> 0 | R10: =SUM(E10:P10) -> 0
B11: 6 | C11: =+Introduction!C16 -> Income 6 | E11: =SUMIF(Ledger!$P$6:$P$2011,CONCATENATE("Income ",Actual!$B11," ",MONTH(Actual!E$5)," ",YEAR(Actual!E$5)," "),Ledger!$H$6:$H$2011) -> 0 | F11: =SUMIF(Ledger!$P$6:$P$2011,CONCATENATE("Income ",Actual!$B11," ",MONTH(Actual!F$5)," ",YEAR(Actual!F$5)," "),Ledger!$H$6:$H$2011) -> 0 | G11: =SUMIF(Ledger!$P$6:$P$2011,CONCATENATE("Income ",Actual!$B11," ",MONTH(Actual!G$5)," ",YEAR(Actual!G$5)," "),Ledger!$H$6:$H$2011) -> 0 | H11: =SUMIF(Ledger!$P$6:$P$2011,CONCATENATE("Income ",Actual!$B11," ",MONTH(Actual!H$5)," ",YEAR(Actual!H$5)," "),Ledger!$H$6:$H$2011) -> 0 | I11: =SUMIF(Ledger!$P$6:$P$2011,CONCATENATE("Income ",Actual!$B11," ",MONTH(Actual!I$5)," ",YEAR(Actual!I$5)," "),Ledger!$H$6:$H$2011) -> 0 | J11: =SUMIF(Ledger!$P$6:$P$2011,CONCATENATE("Income ",Actual!$B11," ",MONTH(Actual!J$5)," ",YEAR(Actual!J$5)," "),Ledger!$H$6:$H$2011) -> 0 | K11: =SUMIF(Ledger!$P$6:$P$2011,CONCATENATE("Income ",Actual!$B11," ",MONTH(Actual!K$5)," ",YEAR(Actual!K$5)," "),Ledger!$H$6:$H$2011) -> 0 | L11: =SUMIF(Ledger!$P$6:$P$2011,CONCATENATE("Income ",Actual!$B11," ",MONTH(Actual!L$5)," ",YEAR(Actual!L$5)," "),Ledger!$H$6:$H$2011) -> 0 | ... P11: =SUMIF(Ledger!$P$6:$P$2011,CONCATENATE("Income ",Actual!$B11," ",MONTH(Actual!P$5)," ",YEAR(Actual!P$5)," "),Ledger!$H$6:$H$2011) -> 0 | R11: =SUM(E11:P11) -> 0
B12: 7 | C12: =+Introduction!C17 -> Income 7 | E12: =SUMIF(Ledger!$P$6:$P$2011,CONCATENATE("Income ",Actual!$B12," ",MONTH(Actual!E$5)," ",YEAR(Actual!E$5)," "),Ledger!$H$6:$H$2011) -> 0 | F12: =SUMIF(Ledger!$P$6:$P$2011,CONCATENATE("Income ",Actual!$B12," ",MONTH(Actual!F$5)," ",YEAR(Actual!F$5)," "),Ledger!$H$6:$H$2011) -> 0 | G12: =SUMIF(Ledger!$P$6:$P$2011,CONCATENATE("Income ",Actual!$B12," ",MONTH(Actual!G$5)," ",YEAR(Actual!G$5)," "),Ledger!$H$6:$H$2011) -> 0 | H12: =SUMIF(Ledger!$P$6:$P$2011,CONCATENATE("Income ",Actual!$B12," ",MONTH(Actual!H$5)," ",YEAR(Actual!H$5)," "),Ledger!$H$6:$H$2011) -> 0 | I12: =SUMIF(Ledger!$P$6:$P$2011,CONCATENATE("Income ",Actual!$B12," ",MONTH(Actual!I$5)," ",YEAR(Actual!I$5)," "),Ledger!$H$6:$H$2011) -> 0 | J12: =SUMIF(Ledger!$P$6:$P$2011,CONCATENATE("Income ",Actual!$B12," ",MONTH(Actual!J$5)," ",YEAR(Actual!J$5)," "),Ledger!$H$6:$H$2011) -> 0 | K12: =SUMIF(Ledger!$P$6:$P$2011,CONCATENATE("Income ",Actual!$B12," ",MONTH(Actual!K$5)," ",YEAR(Actual!K$5)," "),Ledger!$H$6:$H$2011) -> 0 | L12: =SUMIF(Ledger!$P$6:$P$2011,CONCATENATE("Income ",Actual!$B12," ",MONTH(Actual!L$5)," ",YEAR(Actual!L$5)," "),Ledger!$H$6:$H$2011) -> 0 | ... P12: =SUMIF(Ledger!$P$6:$P$2011,CONCATENATE("Income ",Actual!$B12," ",MONTH(Actual!P$5)," ",YEAR(Actual!P$5)," "),Ledger!$H$6:$H$2011) -> 0 | R12: =SUM(E12:P12) -> 0
B13: 8 | C13: =+Introduction!C18 -> Income 8 | E13: =SUMIF(Ledger!$P$6:$P$2011,CONCATENATE("Income ",Actual!$B13," ",MONTH(Actual!E$5)," ",YEAR(Actual!E$5)," "),Ledger!$H$6:$H$2011) -> 0 | F13: =SUMIF(Ledger!$P$6:$P$2011,CONCATENATE("Income ",Actual!$B13," ",MONTH(Actual!F$5)," ",YEAR(Actual!F$5)," "),Ledger!$H$6:$H$2011) -> 0 | G13: =SUMIF(Ledger!$P$6:$P$2011,CONCATENATE("Income ",Actual!$B13," ",MONTH(Actual!G$5)," ",YEAR(Actual!G$5)," "),Ledger!$H$6:$H$2011) -> 0 | H13: =SUMIF(Ledger!$P$6:$P$2011,CONCATENATE("Income ",Actual!$B13," ",MONTH(Actual!H$5)," ",YEAR(Actual!H$5)," "),Ledger!$H$6:$H$2011) -> 0 | I13: =SUMIF(Ledger!$P$6:$P$2011,CONCATENATE("Income ",Actual!$B13," ",MONTH(Actual!I$5)," ",YEAR(Actual!I$5)," "),Ledger!$H$6:$H$2011) -> 0 | J13: =SUMIF(Ledger!$P$6:$P$2011,CONCATENATE("Income ",Actual!$B13," ",MONTH(Actual!J$5)," ",YEAR(Actual!J$5)," "),Ledger!$H$6:$H$2011) -> 0 | K13: =SUMIF(Ledger!$P$6:$P$2011,CONCATENATE("Income ",Actual!$B13," ",MONTH(Actual!K$5)," ",YEAR(Actual!K$5)," "),Ledger!$H$6:$H$2011) -> 0 | L13: =SUMIF(Ledger!$P$6:$P$2011,CONCATENATE("Income ",Actual!$B13," ",MONTH(Actual!L$5)," ",YEAR(Actual!L$5)," "),Ledger!$H$6:$H$2011) -> 0 | ... P13: =SUMIF(Ledger!$P$6:$P$2011,CONCATENATE("Income ",Actual!$B13," ",MONTH(Actual!P$5)," ",YEAR(Actual!P$5)," "),Ledger!$H$6:$H$2011) -> 0 | R13: =SUM(E13:P13) -> 0
C14: Total Income | E14: =SUM(E6:E13) -> 0 | F14: =SUM(F6:F13) -> 0 | G14: =SUM(G6:G13) -> 0 | H14: =SUM(H6:H13) -> 0 | I14: =SUM(I6:I13) -> 0 | J14: =SUM(J6:J13) -> 0 | K14: =SUM(K6:K13) -> 0 | L14: =SUM(L6:L13) -> 0 | ... R14: =SUM(R6:R13) -> 0
R15: =IF(SUM(E15:P15)<>0,SUM(E15:P15),"")
C16: Month and Year Calc Income/Expense | E16: =CONCATENATE(MONTH(E17)," ",YEAR(E17), " Expense") -> 1 2012 Expense | F16: =CONCATENATE(MONTH(F17)," ",YEAR(F17), " Expense") -> 2 2012 Expense | G16: =CONCATENATE(MONTH(G17)," ",YEAR(G17), " Expense") -> 3 2012 Expense | H16: =CONCATENATE(MONTH(H17)," ",YEAR(H17), " Expense") -> 4 2012 Expense | I16: =CONCATENATE(MONTH(I17)," ",YEAR(I17), " Expense") -> 5 2012 Expense | J16: =CONCATENATE(MONTH(J17)," ",YEAR(J17), " Expense") -> 6 2012 Expense | K16: =CONCATENATE(MONTH(K17)," ",YEAR(K17), " Expense") -> 7 2012 Expense | L16: =CONCATENATE(MONTH(L17)," ",YEAR(L17), " Expense") -> 8 2012 Expense | ... P16: =CONCATENATE(MONTH(P17)," ",YEAR(P17), " Expense") -> 12 2012 Expense
C17: Expenses | E17: =+E5 -> 40909 | F17: =+F5 -> 40940 | G17: =+G5 -> 40969 | H17: =+H5 -> 41000 | I17: =+I5 -> 41030 | J17: =+J5 -> 41061 | K17: =+K5 -> 41091 | L17: =+L5 -> 41122 | ... P17: =+P5 -> 41244 | R17: Total
B18: 1 | C18: =+Introduction!F11 -> Expense 1 | E18: =-SUMIF(Ledger!$P$6:$P$2011,CONCATENATE("Expense ",Actual!$B18," ",MONTH(Actual!E$5)," ",YEAR(Actual!E$5)," "),Ledger!$H$6:$H$2011) -> 0 | F18: =-SUMIF(Ledger!$P$6:$P$2011,CONCATENATE("Expense ",Actual!$B18," ",MONTH(Actual!F$5)," ",YEAR(Actual!F$5)," "),Ledger!$H$6:$H$2011) -> 0 | G18: =-SUMIF(Ledger!$P$6:$P$2011,CONCATENATE("Expense ",Actual!$B18," ",MONTH(Actual!G$5)," ",YEAR(Actual!G$5)," "),Ledger!$H$6:$H$2011) -> 0 | H18: =-SUMIF(Ledger!$P$6:$P$2011,CONCATENATE("Expense ",Actual!$B18," ",MONTH(Actual!H$5)," ",YEAR(Actual!H$5)," "),Ledger!$H$6:$H$2011) -> 0 | I18: =-SUMIF(Ledger!$P$6:$P$2011,CONCATENATE("Expense ",Actual!$B18," ",MONTH(Actual!I$5)," ",YEAR(Actual!I$5)," "),Ledger!$H$6:$H$2011) -> 0 | J18: =-SUMIF(Ledger!$P$6:$P$2011,CONCATENATE("Expense ",Actual!$B18," ",MONTH(Actual!J$5)," ",YEAR(Actual!J$5)," "),Ledger!$H$6:$H$2011) -> 0 | K18: =-SUMIF(Ledger!$P$6:$P$2011,CONCATENATE("Expense ",Actual!$B18," ",MONTH(Actual!K$5)," ",YEAR(Actual!K$5)," "),Ledger!$H$6:$H$2011) -> 0 | L18: =-SUMIF(Ledger!$P$6:$P$2011,CONCATENATE("Expense ",Actual!$B18," ",MONTH(Actual!L$5)," ",YEAR(Actual!L$5)," "),Ledger!$H$6:$H$2011) -> 0 | ... P18: =-SUMIF(Ledger!$P$6:$P$2011,CONCATENATE("Expense ",Actual!$B18," ",MONTH(Actual!P$5)," ",YEAR(Actual!P$5)," "),Ledger!$H$6:$H$2011) -> 0 | R18: =SUM(E18:P18) -> 0
B19: 2 | C19: =+Introduction!F12 -> Expense 2 | E19: =-SUMIF(Ledger!$P$6:$P$2011,CONCATENATE("Expense ",Actual!$B19," ",MONTH(Actual!E$5)," ",YEAR(Actual!E$5)," "),Ledger!$H$6:$H$2011) -> 0 | F19: =-SUMIF(Ledger!$P$6:$P$2011,CONCATENATE("Expense ",Actual!$B19," ",MONTH(Actual!F$5)," ",YEAR(Actual!F$5)," "),Ledger!$H$6:$H$2011) -> 0 | G19: =-SUMIF(Ledger!$P$6:$P$2011,CONCATENATE("Expense ",Actual!$B19," ",MONTH(Actual!G$5)," ",YEAR(Actual!G$5)," "),Ledger!$H$6:$H$2011) -> 0 | H19: =-SUMIF(Ledger!$P$6:$P$2011,CONCATENATE("Expense ",Actual!$B19," ",MONTH(Actual!H$5)," ",YEAR(Actual!H$5)," "),Ledger!$H$6:$H$2011) -> 0 | I19: =-SUMIF(Ledger!$P$6:$P$2011,CONCATENATE("Expense ",Actual!$B19," ",MONTH(Actual!I$5)," ",YEAR(Actual!I$5)," "),Ledger!$H$6:$H$2011) -> 0 | J19: =-SUMIF(Ledger!$P$6:$P$2011,CONCATENATE("Expense ",Actual!$B19," ",MONTH(Actual!J$5)," ",YEAR(Actual!J$5)," "),Ledger!$H$6:$H$2011) -> 0 | K19: =-SUMIF(Ledger!$P$6:$P$2011,CONCATENATE("Expense ",Actual!$B19," ",MONTH(Actual!K$5)," ",YEAR(Actual!K$5)," "),Ledger!$H$6:$H$2011) -> 0 | L19: =-SUMIF(Ledger!$P$6:$P$2011,CONCATENATE("Expense ",Actual!$B19," ",MONTH(Actual!L$5)," ",YEAR(Actual!L$5)," "),Ledger!$H$6:$H$2011) -> 0 | ... P19: =-SUMIF(Ledger!$P$6:$P$2011,CONCATENATE("Expense ",Actual!$B19," ",MONTH(Actual!P$5)," ",YEAR(Actual!P$5)," "),Ledger!$H$6:$H$2011) -> 0 | R19: =SUM(E19:P19) -> 0
B20: 3 | C20: =+Introduction!F13 -> Expense 3 | E20: =-SUMIF(Ledger!$P$6:$P$2011,CONCATENATE("Expense ",Actual!$B20," ",MONTH(Actual!E$5)," ",YEAR(Actual!E$5)," "),Ledger!$H$6:$H$2011) -> 0 | F20: =-SUMIF(Ledger!$P$6:$P$2011,CONCATENATE("Expense ",Actual!$B20," ",MONTH(Actual!F$5)," ",YEAR(Actual!F$5)," "),Ledger!$H$6:$H$2011) -> 0 | G20: =-SUMIF(Ledger!$P$6:$P$2011,CONCATENATE("Expense ",Actual!$B20," ",MONTH(Actual!G$5)," ",YEAR(Actual!G$5)," "),Ledger!$H$6:$H$2011) -> 0 | H20: =-SUMIF(Ledger!$P$6:$P$2011,CONCATENATE("Expense ",Actual!$B20," ",MONTH(Actual!H$5)," ",YEAR(Actual!H$5)," "),Ledger!$H$6:$H$2011) -> 0 | I20: =-SUMIF(Ledger!$P$6:$P$2011,CONCATENATE("Expense ",Actual!$B20," ",MONTH(Actual!I$5)," ",YEAR(Actual!I$5)," "),Ledger!$H$6:$H$2011) -> 0 | J20: =-SUMIF(Ledger!$P$6:$P$2011,CONCATENATE("Expense ",Actual!$B20," ",MONTH(Actual!J$5)," ",YEAR(Actual!J$5)," "),Ledger!$H$6:$H$2011) -> 0 | K20: =-SUMIF(Ledger!$P$6:$P$2011,CONCATENATE("Expense ",Actual!$B20," ",MONTH(Actual!K$5)," ",YEAR(Actual!K$5)," "),Ledger!$H$6:$H$2011) -> 0 | L20: =-SUMIF(Ledger!$P$6:$P$2011,CONCATENATE("Expense ",Actual!$B20," ",MONTH(Actual!L$5)," ",YEAR(Actual!L$5)," "),Ledger!$H$6:$H$2011) -> 0 | ... P20: =-SUMIF(Ledger!$P$6:$P$2011,CONCATENATE("Expense ",Actual!$B20," ",MONTH(Actual!P$5)," ",YEAR(Actual!P$5)," "),Ledger!$H$6:$H$2011) -> 0 | R20: =SUM(E20:P20) -> 0
B21: 4 | C21: =+Introduction!F14 -> Expense 4 | E21: =-SUMIF(Ledger!$P$6:$P$2011,CONCATENATE("Expense ",Actual!$B21," ",MONTH(Actual!E$5)," ",YEAR(Actual!E$5)," "),Ledger!$H$6:$H$2011) -> 0 | F21: =-SUMIF(Ledger!$P$6:$P$2011,CONCATENATE("Expense ",Actual!$B21," ",MONTH(Actual!F$5)," ",YEAR(Actual!F$5)," "),Ledger!$H$6:$H$2011) -> 0 | G21: =-SUMIF(Ledger!$P$6:$P$2011,CONCATENATE("Expense ",Actual!$B21," ",MONTH(Actual!G$5)," ",YEAR(Actual!G$5)," "),Ledger!$H$6:$H$2011) -> 0 | H21: =-SUMIF(Ledger!$P$6:$P$2011,CONCATENATE("Expense ",Actual!$B21," ",MONTH(Actual!H$5)," ",YEAR(Actual!H$5)," "),Ledger!$H$6:$H$2011) -> 0 | I21: =-SUMIF(Ledger!$P$6:$P$2011,CONCATENATE("Expense ",Actual!$B21," ",MONTH(Actual!I$5)," ",YEAR(Actual!I$5)," "),Ledger!$H$6:$H$2011) -> 0 | J21: =-SUMIF(Ledger!$P$6:$P$2011,CONCATENATE("Expense ",Actual!$B21," ",MONTH(Actual!J$5)," ",YEAR(Actual!J$5)," "),Ledger!$H$6:$H$2011) -> 0 | K21: =-SUMIF(Ledger!$P$6:$P$2011,CONCATENATE("Expense ",Actual!$B21," ",MONTH(Actual!K$5)," ",YEAR(Actual!K$5)," "),Ledger!$H$6:$H$2011) -> 0 | L21: =-SUMIF(Ledger!$P$6:$P$2011,CONCATENATE("Expense ",Actual!$B21," ",MONTH(Actual!L$5)," ",YEAR(Actual!L$5)," "),Ledger!$H$6:$H$2011) -> 0 | ... P21: =-SUMIF(Ledger!$P$6:$P$2011,CONCATENATE("Expense ",Actual!$B21," ",MONTH(Actual!P$5)," ",YEAR(Actual!P$5)," "),Ledger!$H$6:$H$2011) -> 0 | R21: =SUM(E21:P21) -> 0
B22: 5 | C22: =+Introduction!F15 -> Expense 5 | E22: =-SUMIF(Ledger!$P$6:$P$2011,CONCATENATE("Expense ",Actual!$B22," ",MONTH(Actual!E$5)," ",YEAR(Actual!E$5)," "),Ledger!$H$6:$H$2011) -> 0 | F22: =-SUMIF(Ledger!$P$6:$P$2011,CONCATENATE("Expense ",Actual!$B22," ",MONTH(Actual!F$5)," ",YEAR(Actual!F$5)," "),Ledger!$H$6:$H$2011) -> 0 | G22: =-SUMIF(Ledger!$P$6:$P$2011,CONCATENATE("Expense ",Actual!$B22," ",MONTH(Actual!G$5)," ",YEAR(Actual!G$5)," "),Ledger!$H$6:$H$2011) -> 0 | H22: =-SUMIF(Ledger!$P$6:$P$2011,CONCATENATE("Expense ",Actual!$B22," ",MONTH(Actual!H$5)," ",YEAR(Actual!H$5)," "),Ledger!$H$6:$H$2011) -> 0 | I22: =-SUMIF(Ledger!$P$6:$P$2011,CONCATENATE("Expense ",Actual!$B22," ",MONTH(Actual!I$5)," ",YEAR(Actual!I$5)," "),Ledger!$H$6:$H$2011) -> 0 | J22: =-SUMIF(Ledger!$P$6:$P$2011,CONCATENATE("Expense ",Actual!$B22," ",MONTH(Actual!J$5)," ",YEAR(Actual!J$5)," "),Ledger!$H$6:$H$2011) -> 0 | K22: =-SUMIF(Ledger!$P$6:$P$2011,CONCATENATE("Expense ",Actual!$B22," ",MONTH(Actual!K$5)," ",YEAR(Actual!K$5)," "),Ledger!$H$6:$H$2011) -> 0 | L22: =-SUMIF(Ledger!$P$6:$P$2011,CONCATENATE("Expense ",Actual!$B22," ",MONTH(Actual!L$5)," ",YEAR(Actual!L$5)," "),Ledger!$H$6:$H$2011) -> 0 | ... P22: =-SUMIF(Ledger!$P$6:$P$2011,CONCATENATE("Expense ",Actual!$B22," ",MONTH(Actual!P$5)," ",YEAR(Actual!P$5)," "),Ledger!$H$6:$H$2011) -> 0 | R22: =SUM(E22:P22) -> 0
B23: 6 | C23: =+Introduction!F16 -> Expense 6 | E23: =-SUMIF(Ledger!$P$6:$P$2011,CONCATENATE("Expense ",Actual!$B23," ",MONTH(Actual!E$5)," ",YEAR(Actual!E$5)," "),Ledger!$H$6:$H$2011) -> 0 | F23: =-SUMIF(Ledger!$P$6:$P$2011,CONCATENATE("Expense ",Actual!$B23," ",MONTH(Actual!F$5)," ",YEAR(Actual!F$5)," "),Ledger!$H$6:$H$2011) -> 0 | G23: =-SUMIF(Ledger!$P$6:$P$2011,CONCATENATE("Expense ",Actual!$B23," ",MONTH(Actual!G$5)," ",YEAR(Actual!G$5)," "),Ledger!$H$6:$H$2011) -> 0 | H23: =-SUMIF(Ledger!$P$6:$P$2011,CONCATENATE("Expense ",Actual!$B23," ",MONTH(Actual!H$5)," ",YEAR(Actual!H$5)," "),Ledger!$H$6:$H$2011) -> 0 | I23: =-SUMIF(Ledger!$P$6:$P$2011,CONCATENATE("Expense ",Actual!$B23," ",MONTH(Actual!I$5)," ",YEAR(Actual!I$5)," "),Ledger!$H$6:$H$2011) -> 0 | J23: =-SUMIF(Ledger!$P$6:$P$2011,CONCATENATE("Expense ",Actual!$B23," ",MONTH(Actual!J$5)," ",YEAR(Actual!J$5)," "),Ledger!$H$6:$H$2011) -> 0 | K23: =-SUMIF(Ledger!$P$6:$P$2011,CONCATENATE("Expense ",Actual!$B23," ",MONTH(Actual!K$5)," ",YEAR(Actual!K$5)," "),Ledger!$H$6:$H$2011) -> 0 | L23: =-SUMIF(Ledger!$P$6:$P$2011,CONCATENATE("Expense ",Actual!$B23," ",MONTH(Actual!L$5)," ",YEAR(Actual!L$5)," "),Ledger!$H$6:$H$2011) -> 0 | ... P23: =-SUMIF(Ledger!$P$6:$P$2011,CONCATENATE("Expense ",Actual!$B23," ",MONTH(Actual!P$5)," ",YEAR(Actual!P$5)," "),Ledger!$H$6:$H$2011) -> 0 | R23: =SUM(E23:P23) -> 0
B24: 7 | C24: =+Introduction!F17 -> Expense 7 | E24: =-SUMIF(Ledger!$P$6:$P$2011,CONCATENATE("Expense ",Actual!$B24," ",MONTH(Actual!E$5)," ",YEAR(Actual!E$5)," "),Ledger!$H$6:$H$2011) -> 0 | F24: =-SUMIF(Ledger!$P$6:$P$2011,CONCATENATE("Expense ",Actual!$B24," ",MONTH(Actual!F$5)," ",YEAR(Actual!F$5)," "),Ledger!$H$6:$H$2011) -> 0 | G24: =-SUMIF(Ledger!$P$6:$P$2011,CONCATENATE("Expense ",Actual!$B24," ",MONTH(Actual!G$5)," ",YEAR(Actual!G$5)," "),Ledger!$H$6:$H$2011) -> 0 | H24: =-SUMIF(Ledger!$P$6:$P$2011,CONCATENATE("Expense ",Actual!$B24," ",MONTH(Actual!H$5)," ",YEAR(Actual!H$5)," "),Ledger!$H$6:$H$2011) -> 0 | I24: =-SUMIF(Ledger!$P$6:$P$2011,CONCATENATE("Expense ",Actual!$B24," ",MONTH(Actual!I$5)," ",YEAR(Actual!I$5)," "),Ledger!$H$6:$H$2011) -> 0 | J24: =-SUMIF(Ledger!$P$6:$P$2011,CONCATENATE("Expense ",Actual!$B24," ",MONTH(Actual!J$5)," ",YEAR(Actual!J$5)," "),Ledger!$H$6:$H$2011) -> 0 | K24: =-SUMIF(Ledger!$P$6:$P$2011,CONCATENATE("Expense ",Actual!$B24," ",MONTH(Actual!K$5)," ",YEAR(Actual!K$5)," "),Ledger!$H$6:$H$2011) -> 0 | L24: =-SUMIF(Ledger!$P$6:$P$2011,CONCATENATE("Expense ",Actual!$B24," ",MONTH(Actual!L$5)," ",YEAR(Actual!L$5)," "),Ledger!$H$6:$H$2011) -> 0 | ... P24: =-SUMIF(Ledger!$P$6:$P$2011,CONCATENATE("Expense ",Actual!$B24," ",MONTH(Actual!P$5)," ",YEAR(Actual!P$5)," "),Ledger!$H$6:$H$2011) -> 0 | R24: =SUM(E24:P24) -> 0
B25: 8 | C25: =+Introduction!F18 -> Expense 8 | E25: =-SUMIF(Ledger!$P$6:$P$2011,CONCATENATE("Expense ",Actual!$B25," ",MONTH(Actual!E$5)," ",YEAR(Actual!E$5)," "),Ledger!$H$6:$H$2011) -> 0 | F25: =-SUMIF(Ledger!$P$6:$P$2011,CONCATENATE("Expense ",Actual!$B25," ",MONTH(Actual!F$5)," ",YEAR(Actual!F$5)," "),Ledger!$H$6:$H$2011) -> 0 | G25: =-SUMIF(Ledger!$P$6:$P$2011,CONCATENATE("Expense ",Actual!$B25," ",MONTH(Actual!G$5)," ",YEAR(Actual!G$5)," "),Ledger!$H$6:$H$2011) -> 0 | H25: =-SUMIF(Ledger!$P$6:$P$2011,CONCATENATE("Expense ",Actual!$B25," ",MONTH(Actual!H$5)," ",YEAR(Actual!H$5)," "),Ledger!$H$6:$H$2011) -> 0 | I25: =-SUMIF(Ledger!$P$6:$P$2011,CONCATENATE("Expense ",Actual!$B25," ",MONTH(Actual!I$5)," ",YEAR(Actual!I$5)," "),Ledger!$H$6:$H$2011) -> 0 | J25: =-SUMIF(Ledger!$P$6:$P$2011,CONCATENATE("Expense ",Actual!$B25," ",MONTH(Actual!J$5)," ",YEAR(Actual!J$5)," "),Ledger!$H$6:$H$2011) -> 0 | K25: =-SUMIF(Ledger!$P$6:$P$2011,CONCATENATE("Expense ",Actual!$B25," ",MONTH(Actual!K$5)," ",YEAR(Actual!K$5)," "),Ledger!$H$6:$H$2011) -> 0 | L25: =-SUMIF(Ledger!$P$6:$P$2011,CONCATENATE("Expense ",Actual!$B25," ",MONTH(Actual!L$5)," ",YEAR(Actual!L$5)," "),Ledger!$H$6:$H$2011) -> 0 | ... P25: =-SUMIF(Ledger!$P$6:$P$2011,CONCATENATE("Expense ",Actual!$B25," ",MONTH(Actual!P$5)," ",YEAR(Actual!P$5)," "),Ledger!$H$6:$H$2011) -> 0 | R25: =SUM(E25:P25) -> 0
B26: 9 | C26: =+Introduction!F19 -> Expense 9 | E26: =-SUMIF(Ledger!$P$6:$P$2011,CONCATENATE("Expense ",Actual!$B26," ",MONTH(Actual!E$5)," ",YEAR(Actual!E$5)," "),Ledger!$H$6:$H$2011) -> 0 | F26: =-SUMIF(Ledger!$P$6:$P$2011,CONCATENATE("Expense ",Actual!$B26," ",MONTH(Actual!F$5)," ",YEAR(Actual!F$5)," "),Ledger!$H$6:$H$2011) -> 0 | G26: =-SUMIF(Ledger!$P$6:$P$2011,CONCATENATE("Expense ",Actual!$B26," ",MONTH(Actual!G$5)," ",YEAR(Actual!G$5)," "),Ledger!$H$6:$H$2011) -> 0 | H26: =-SUMIF(Ledger!$P$6:$P$2011,CONCATENATE("Expense ",Actual!$B26," ",MONTH(Actual!H$5)," ",YEAR(Actual!H$5)," "),Ledger!$H$6:$H$2011) -> 0 | I26: =-SUMIF(Ledger!$P$6:$P$2011,CONCATENATE("Expense ",Actual!$B26," ",MONTH(Actual!I$5)," ",YEAR(Actual!I$5)," "),Ledger!$H$6:$H$2011) -> 0 | J26: =-SUMIF(Ledger!$P$6:$P$2011,CONCATENATE("Expense ",Actual!$B26," ",MONTH(Actual!J$5)," ",YEAR(Actual!J$5)," "),Ledger!$H$6:$H$2011) -> 0 | K26: =-SUMIF(Ledger!$P$6:$P$2011,CONCATENATE("Expense ",Actual!$B26," ",MONTH(Actual!K$5)," ",YEAR(Actual!K$5)," "),Ledger!$H$6:$H$2011) -> 0 | L26: =-SUMIF(Ledger!$P$6:$P$2011,CONCATENATE("Expense ",Actual!$B26," ",MONTH(Actual!L$5)," ",YEAR(Actual!L$5)," "),Ledger!$H$6:$H$2011) -> 0 | ... P26: =-SUMIF(Ledger!$P$6:$P$2011,CONCATENATE("Expense ",Actual!$B26," ",MONTH(Actual!P$5)," ",YEAR(Actual!P$5)," "),Ledger!$H$6:$H$2011) -> 0 | R26: =SUM(E26:P26) -> 0
B27: 10 | C27: =+Introduction!F20 -> Expense 10 | E27: =-SUMIF(Ledger!$P$6:$P$2011,CONCATENATE("Expense ",Actual!$B27," ",MONTH(Actual!E$5)," ",YEAR(Actual!E$5)," "),Ledger!$H$6:$H$2011) -> 0 | F27: =-SUMIF(Ledger!$P$6:$P$2011,CONCATENATE("Expense ",Actual!$B27," ",MONTH(Actual!F$5)," ",YEAR(Actual!F$5)," "),Ledger!$H$6:$H$2011) -> 0 | G27: =-SUMIF(Ledger!$P$6:$P$2011,CONCATENATE("Expense ",Actual!$B27," ",MONTH(Actual!G$5)," ",YEAR(Actual!G$5)," "),Ledger!$H$6:$H$2011) -> 0 | H27: =-SUMIF(Ledger!$P$6:$P$2011,CONCATENATE("Expense ",Actual!$B27," ",MONTH(Actual!H$5)," ",YEAR(Actual!H$5)," "),Ledger!$H$6:$H$2011) -> 0 | I27: =-SUMIF(Ledger!$P$6:$P$2011,CONCATENATE("Expense ",Actual!$B27," ",MONTH(Actual!I$5)," ",YEAR(Actual!I$5)," "),Ledger!$H$6:$H$2011) -> 0 | J27: =-SUMIF(Ledger!$P$6:$P$2011,CONCATENATE("Expense ",Actual!$B27," ",MONTH(Actual!J$5)," ",YEAR(Actual!J$5)," "),Ledger!$H$6:$H$2011) -> 0 | K27: =-SUMIF(Ledger!$P$6:$P$2011,CONCATENATE("Expense ",Actual!$B27," ",MONTH(Actual!K$5)," ",YEAR(Actual!K$5)," "),Ledger!$H$6:$H$2011) -> 0 | L27: =-SUMIF(Ledger!$P$6:$P$2011,CONCATENATE("Expense ",Actual!$B27," ",MONTH(Actual!L$5)," ",YEAR(Actual!L$5)," "),Ledger!$H$6:$H$2011) -> 0 | ... P27: =-SUMIF(Ledger!$P$6:$P$2011,CONCATENATE("Expense ",Actual!$B27," ",MONTH(Actual!P$5)," ",YEAR(Actual!P$5)," "),Ledger!$H$6:$H$2011) -> 0 | R27: =SUM(E27:P27) -> 0
B28: 11 | C28: =+Introduction!F21 -> Expense 11 | E28: =-SUMIF(Ledger!$P$6:$P$2011,CONCATENATE("Expense ",Actual!$B28," ",MONTH(Actual!E$5)," ",YEAR(Actual!E$5)," "),Ledger!$H$6:$H$2011) -> 0 | F28: =-SUMIF(Ledger!$P$6:$P$2011,CONCATENATE("Expense ",Actual!$B28," ",MONTH(Actual!F$5)," ",YEAR(Actual!F$5)," "),Ledger!$H$6:$H$2011) -> 0 | G28: =-SUMIF(Ledger!$P$6:$P$2011,CONCATENATE("Expense ",Actual!$B28," ",MONTH(Actual!G$5)," ",YEAR(Actual!G$5)," "),Ledger!$H$6:$H$2011) -> 0 | H28: =-SUMIF(Ledger!$P$6:$P$2011,CONCATENATE("Expense ",Actual!$B28," ",MONTH(Actual!H$5)," ",YEAR(Actual!H$5)," "),Ledger!$H$6:$H$2011) -> 0 | I28: =-SUMIF(Ledger!$P$6:$P$2011,CONCATENATE("Expense ",Actual!$B28," ",MONTH(Actual!I$5)," ",YEAR(Actual!I$5)," "),Ledger!$H$6:$H$2011) -> 0 | J28: =-SUMIF(Ledger!$P$6:$P$2011,CONCATENATE("Expense ",Actual!$B28," ",MONTH(Actual!J$5)," ",YEAR(Actual!J$5)," "),Ledger!$H$6:$H$2011) -> 0 | K28: =-SUMIF(Ledger!$P$6:$P$2011,CONCATENATE("Expense ",Actual!$B28," ",MONTH(Actual!K$5)," ",YEAR(Actual!K$5)," "),Ledger!$H$6:$H$2011) -> 0 | L28: =-SUMIF(Ledger!$P$6:$P$2011,CONCATENATE("Expense ",Actual!$B28," ",MONTH(Actual!L$5)," ",YEAR(Actual!L$5)," "),Ledger!$H$6:$H$2011) -> 0 | ... P28: =-SUMIF(Ledger!$P$6:$P$2011,CONCATENATE("Expense ",Actual!$B28," ",MONTH(Actual!P$5)," ",YEAR(Actual!P$5)," "),Ledger!$H$6:$H$2011) -> 0 | R28: =SUM(E28:P28) -> 0
B29: 12 | C29: =+Introduction!F22 -> Expense 12 | E29: =-SUMIF(Ledger!$P$6:$P$2011,CONCATENATE("Expense ",Actual!$B29," ",MONTH(Actual!E$5)," ",YEAR(Actual!E$5)," "),Ledger!$H$6:$H$2011) -> 0 | F29: =-SUMIF(Ledger!$P$6:$P$2011,CONCATENATE("Expense ",Actual!$B29," ",MONTH(Actual!F$5)," ",YEAR(Actual!F$5)," "),Ledger!$H$6:$H$2011) -> 0 | G29: =-SUMIF(Ledger!$P$6:$P$2011,CONCATENATE("Expense ",Actual!$B29," ",MONTH(Actual!G$5)," ",YEAR(Actual!G$5)," "),Ledger!$H$6:$H$2011) -> 0 | H29: =-SUMIF(Ledger!$P$6:$P$2011,CONCATENATE("Expense ",Actual!$B29," ",MONTH(Actual!H$5)," ",YEAR(Actual!H$5)," "),Ledger!$H$6:$H$2011) -> 0 | I29: =-SUMIF(Ledger!$P$6:$P$2011,CONCATENATE("Expense ",Actual!$B29," ",MONTH(Actual!I$5)," ",YEAR(Actual!I$5)," "),Ledger!$H$6:$H$2011) -> 0 | J29: =-SUMIF(Ledger!$P$6:$P$2011,CONCATENATE("Expense ",Actual!$B29," ",MONTH(Actual!J$5)," ",YEAR(Actual!J$5)," "),Ledger!$H$6:$H$2011) -> 0 | K29: =-SUMIF(Ledger!$P$6:$P$2011,CONCATENATE("Expense ",Actual!$B29," ",MONTH(Actual!K$5)," ",YEAR(Actual!K$5)," "),Ledger!$H$6:$H$2011) -> 0 | L29: =-SUMIF(Ledger!$P$6:$P$2011,CONCATENATE("Expense ",Actual!$B29," ",MONTH(Actual!L$5)," ",YEAR(Actual!L$5)," "),Ledger!$H$6:$H$2011) -> 0 | ... P29: =-SUMIF(Ledger!$P$6:$P$2011,CONCATENATE("Expense ",Actual!$B29," ",MONTH(Actual!P$5)," ",YEAR(Actual!P$5)," "),Ledger!$H$6:$H$2011) -> 0 | R29: =SUM(E29:P29) -> 0
... B37: 20 | C37: =+Introduction!F30 -> IRA Contribution | E37: =-SUMIF(Ledger!$P$6:$P$2011,CONCATENATE("Expense ",Actual!$B37," ",MONTH(Actual!E$5)," ",YEAR(Actual!E$5)," "),Ledger!$H$6:$H$2011) -> 0 | F37: =-SUMIF(Ledger!$P$6:$P$2011,CONCATENATE("Expense ",Actual!$B37," ",MONTH(Actual!F$5)," ",YEAR(Actual!F$5)," "),Ledger!$H$6:$H$2011) -> 0 | G37: =-SUMIF(Ledger!$P$6:$P$2011,CONCATENATE("Expense ",Actual!$B37," ",MONTH(Actual!G$5)," ",YEAR(Actual!G$5)," "),Ledger!$H$6:$H$2011) -> 0 | H37: =-SUMIF(Ledger!$P$6:$P$2011,CONCATENATE("Expense ",Actual!$B37," ",MONTH(Actual!H$5)," ",YEAR(Actual!H$5)," "),Ledger!$H$6:$H$2011) -> 0 | I37: =-SUMIF(Ledger!$P$6:$P$2011,CONCATENATE("Expense ",Actual!$B37," ",MONTH(Actual!I$5)," ",YEAR(Actual!I$5)," "),Ledger!$H$6:$H$2011) -> 0 | J37: =-SUMIF(Ledger!$P$6:$P$2011,CONCATENATE("Expense ",Actual!$B37," ",MONTH(Actual!J$5)," ",YEAR(Actual!J$5)," "),Ledger!$H$6:$H$2011) -> 0 | K37: =-SUMIF(Ledger!$P$6:$P$2011,CONCATENATE("Expense ",Actual!$B37," ",MONTH(Actual!K$5)," ",YEAR(Actual!K$5)," "),Ledger!$H$6:$H$2011) -> 0 | L37: =-SUMIF(Ledger!$P$6:$P$2011,CONCATENATE("Expense ",Actual!$B37," ",MONTH(Actual!L$5)," ",YEAR(Actual!L$5)," "),Ledger!$H$6:$H$2011) -> 0 | ... P37: =-SUMIF(Ledger!$P$6:$P$2011,CONCATENATE("Expense ",Actual!$B37," ",MONTH(Actual!P$5)," ",YEAR(Actual!P$5)," "),Ledger!$H$6:$H$2011) -> 0 | R37: =SUM(E37:P37) -> 0
C38: Total Expenses | E38: =SUM(E18:E37) -> 0 | F38: =SUM(F18:F37) -> 0 | G38: =SUM(G18:G37) -> 0 | H38: =SUM(H18:H37) -> 0 | I38: =SUM(I18:I37) -> 0 | J38: =SUM(J18:J37) -> 0 | K38: =SUM(K18:K37) -> 0 | L38: =SUM(L18:L37) -> 0 | ... Q38: =SUM(Q18:Q37) -> 0 | R38: =SUM(E38:P38) -> 0
R39: =IF(SUM(E39:P39)<>0,SUM(E39:P39),"")
C40: Income Less Expenses | E40: =+E14-E38 -> 0 | F40: =+F14-F38 -> 0 | G40: =+G14-G38 -> 0 | H40: =+H14-H38 -> 0 | I40: =+I14-I38 -> 0 | J40: =+J14-J38 -> 0 | K40: =+K14-K38 -> 0 | L40: =+L14-L38 -> 0 | ... P40: =+P14-P38 -> 0 | R40: =+R14-R38 -> 0
R41: =IF(SUM(E41:P41)<>0,SUM(E41:P41),"")
B42: 1 | C42: Beginning Cash Balance | E42: =+Ledger!K5 -> 0 | F42: =+E44 -> 0 | G42: =+F44 -> 0 | H42: =+G44 -> 0 | I42: =+H44 -> 0 | J42: =+I44 -> 0 | K42: =+J44 -> 0 | L42: =+K44 -> 0 | M42: =+L44 -> 0 | ... P42: =+O44 -> 0 | R42: =+E42 -> 0
B43: 2 | C43: Income Less Expense | E43: =+E40 -> 0 | F43: =+F40 -> 0 | G43: =+G40 -> 0 | H43: =+H40 -> 0 | I43: =+I40 -> 0 | J43: =+J40 -> 0 | K43: =+K40 -> 0 | L43: =+L40 -> 0 | ... P43: =+P40 -> 0 | R43: =SUM(E43:P43) -> 0
B44: 3 | C44: Ending Cash Balance | E44: =+E42+E43 -> 0 | F44: =+F42+F43 -> 0 | G44: =+G42+G43 -> 0 | H44: =+H42+H43 -> 0 | I44: =+I42+I43 -> 0 | J44: =+J42+J43 -> 0 | K44: =+K42+K43 -> 0 | L44: =+L42+L43 -> 0 | ... P44: =+P42+P43 -> 0 | R44: =+R42+R43 -> 0
B46: 1 | C46: Roth IRA Cumulative Contribution | E46: =+Introduction!F31+Actual!E37 -> 0 | F46: =+E46+F37 -> 0 | G46: =+F46+G37 -> 0 | H46: =+G46+H37 -> 0 | I46: =+H46+I37 -> 0 | J46: =+I46+J37 -> 0 | K46: =+J46+K37 -> 0 | L46: =+K46+L37 -> 0 | M46: =+L46+M37 -> 0 | ... P46: =+O46+P37 -> 0 | R46: =+P46 -> 0
R48: =IF(SUM(E48:P48)<>0,SUM(E48:P48),"")
R49: =IF(SUM(E49:P49)<>0,SUM(E49:P49),"")
R50: =IF(SUM(E50:P50)<>0,SUM(E50:P50),"")
...

Sheet Budget Actual Comparision
B2: =CONCATENATE(Introduction!C4:C4,"'s"," Budget To Actual Performance for ", Introduction!C8," ",Introduction!C5) -> 's Budget To Actual Performance for Jan 2012
C3: Days on Month Calc | D3: 31 | E3: =IF(MOD(Introduction!C7,4)=0,29,28) -> 28 | F3: 31 | G3: 30 | H3: 31 | I3: 30 | J3: 31 | K3: 30 | L3: 30 | M3: 31 | N3: 30
C4: Month and Year Calc Income/Expense | D4: =CONCATENATE(MONTH(D5)," ",YEAR(D5), " Income") -> #VALUE! | E4: =CONCATENATE(MONTH(E5)," ",YEAR(E5), " Income") -> #VALUE! | F4: =CONCATENATE(MONTH(F5)," ",YEAR(F5), " Income") -> #VALUE! | G4: =CONCATENATE(MONTH(G5)," ",YEAR(G5), " Income") -> 1 1900 Income | H4: =CONCATENATE(MONTH(H5)," ",YEAR(H5), " Income") -> #VALUE! | I4: =CONCATENATE(MONTH(I5)," ",YEAR(I5), " Income") -> #VALUE! | J4: =CONCATENATE(MONTH(J5)," ",YEAR(J5), " Income") -> #VALUE! | K4: =CONCATENATE(MONTH(K5)," ",YEAR(K5), " Income") -> 1 1900 Income | ... N4: =CONCATENATE(MONTH(N5)," ",YEAR(N5), " Income") -> #VALUE!
B5: ={"Items Revenue/Expense",0} -> Items Revenue/Expense | C5: Items Revenue/Expense | D5: Month Act | E5: Month Bud | F5: Month Var | H5: QRT Act | I5: QRT Bud | J5: QRT Var | L5: YTD Act | M5: YTD Budget | N5: YTD Var
B6: 1 | C6: =+Introduction!C11 -> Income 1 | D6: =INDEX(Actual!$E6:$P6,Introduction!$G$4) -> 0 | E6: =INDEX(Budget!$E6:$P6,Introduction!$G$4) -> 0 | F6: =+D6-E6 -> 0 | H6: =INDEX('Actual QTD'!$E6:$P6,Introduction!$G$4) -> 0 | I6: =INDEX('Budget QTD'!$E6:$P6,Introduction!$G$4) -> 0 | J6: =+H6-I6 -> 0 | L6: =INDEX('Actual YTD'!$E6:$P6,Introduction!$G$4) -> 0 | M6: =INDEX('Budget YTD'!$E6:$P6,Introduction!$G$4) -> 0 | N6: =+L6-M6 -> 0
B7: 2 | C7: =+Introduction!C12 -> Income 2 | D7: =INDEX(Actual!$E7:$P7,Introduction!$G$4) -> 0 | E7: =INDEX(Budget!$E7:$P7,Introduction!$G$4) -> 0 | F7: =+D7-E7 -> 0 | H7: =INDEX('Actual QTD'!$E7:$P7,Introduction!$G$4) -> 0 | I7: =INDEX('Budget QTD'!$E7:$P7,Introduction!$G$4) -> 0 | J7: =+H7-I7 -> 0 | L7: =INDEX('Actual YTD'!$E7:$P7,Introduction!$G$4) -> 0 | M7: =INDEX('Budget YTD'!$E7:$P7,Introduction!$G$4) -> 0 | N7: =+L7-M7 -> 0
B8: 3 | C8: =+Introduction!C13 -> Income 3 | D8: =INDEX(Actual!$E8:$P8,Introduction!$G$4) -> 0 | E8: =INDEX(Budget!$E8:$P8,Introduction!$G$4) -> 0 | F8: =+D8-E8 -> 0 | H8: =INDEX('Actual QTD'!$E8:$P8,Introduction!$G$4) -> 0 | I8: =INDEX('Budget QTD'!$E8:$P8,Introduction!$G$4) -> 0 | J8: =+H8-I8 -> 0 | L8: =INDEX('Actual YTD'!$E8:$P8,Introduction!$G$4) -> 0 | M8: =INDEX('Budget YTD'!$E8:$P8,Introduction!$G$4) -> 0 | N8: =+L8-M8 -> 0
B9: 4 | C9: =+Introduction!C14 -> Income 4 | D9: =INDEX(Actual!$E9:$P9,Introduction!$G$4) -> 0 | E9: =INDEX(Budget!$E9:$P9,Introduction!$G$4) -> 0 | F9: =+D9-E9 -> 0 | H9: =INDEX('Actual QTD'!$E9:$P9,Introduction!$G$4) -> 0 | I9: =INDEX('Budget QTD'!$E9:$P9,Introduction!$G$4) -> 0 | J9: =+H9-I9 -> 0 | L9: =INDEX('Actual YTD'!$E9:$P9,Introduction!$G$4) -> 0 | M9: =INDEX('Budget YTD'!$E9:$P9,Introduction!$G$4) -> 0 | N9: =+L9-M9 -> 0
