Workbook

Sheet Summary
A1: FUNDRAISING EVENT - SUMMARY SHEET rev. 03/2012
A4: EVENT NAME:
A5: EVENT DATE(S):
A6: Account:
A8: * | B8: cell automatically linked- do not enter any information
A10: Total Amount Raised | B10: =Income!M32 -> 0 | C10: *
A12: Breakout of Income:
A13: Gifts/Contributions | B13: =Income!P32 -> 0 | C13: *
A14: Revenue from Fundraising | B14: =B10-B13 -> 0 | C14: *
B15: =SUM(B13:B14) -> 0 | C15: * | D15: =B15-B10 -> 0
D16: Check-should be zero
A20: Total Expenses: | B20: =Expenses!H29 -> 0 | C20: *
A22: Breakout of Expenses:
A23: Cash prizes | B23: =Expenses!H23 -> 0 | C23: *
A24: Non-cash prizes | B24: =Expenses!D13 -> 0 | C24: *
A25: Rent/facility costs | B25: =Expenses!H13 -> 0 | C25: *
A26: Other direct expenses | B26: =Expenses!D23 -> 0 | C26: *
A27: Sales tax paid | B27: =Expenses!H27 -> 0 | C27: *
B28: =SUM(B23:B27) -> 0 | C28: * | D28: =B20-B28 -> 0
D29: Check-should be zero
A30: EVENT PROFIT/LOSS | B30: =B15-B28 -> 0 | C30: *

Sheet Income
A1: FUNDRAISING EVENT - MONEY COLLECTED
A3: *Please enter all information for income received for this event in peach shaded areas. Enter additional rows as necessary. See inserted comments for additional instructions.
B5: Event Name (Prefils from Summary Tab) | D5: =Summary!B4 -> 0
B6: Event Date (Prefils from Summary Tab) | D6: =Summary!B5 -> 0
B7: QUESTIONS:
A8: 1 | B8: Description of Activity
A9: 2 | B9: Sales Price of meal/item? | D9: 10 | E9: $ Amount
A10: 3 | B10: SU Cost per meal/Item being sold? | D10: 2.5 | E10: $ Amount
A11: If Sales Tax is Applicable - Pick 1 of the 3 options below:
A12: 4 | B12: Does SU need to pay sales tax on the cost? | D12: No
A13: 5 | B13: Does SU need to pay sales tax on the sale price? | D13: No
A14: 6 | B14: Does SU need to pay sales tax already included in the sales price? | D14: Yes
N15: Breakout of Total Amount
B16: Date | C16: Full Name OR Organization | D16: Address | E16: City | F16: State | G16: Zip | H16: Phone | I16: Check # / Cash | J16: $ Amount Received | K16: # of Tickets/ Items | L16: Price per Ticket/ Item | M16: Total $ Amount Charged | N16: Expense/ Cost Per Ticket | O16: Sales Tax (8.25%) | P16: Gifts/Contributions (ANY Negative Gifts will be deducted from Exp/Cost) | Q16: Total Verification
A17: 1 | L17: =$D$9 -> 10 | M17: =K17*L17 -> 0 | N17: =ROUND(IF($D$10>$D$9,($D$9*K17)-O17,$D$10*K17),2) -> 0 | O17: =ROUND(IF($D$12="Yes", N17*8.25%,IF($D$13="Yes", M17*8.25%,IF($D$14="Yes",(M17/1.0825)*8.25%,"0"))),2) -> 0 | P17: =ROUND(J17-N17-O17,2) -> 0 | Q17: =SUM(N17:P17) -> 0
A18: =A17+1 -> 2 | L18: =$D$9 -> 10 | M18: =K18*L18 -> 0 | N18: =ROUND(IF($D$10>$D$9,($D$9*K18)-O18,$D$10*K18),2) -> 0 | O18: =ROUND(IF($D$12="Yes", N18*8.25%,IF($D$13="Yes", M18*8.25%,IF($D$14="Yes",(M18/1.0825)*8.25%,"0"))),2) -> 0 | P18: =ROUND(J18-N18-O18,2) -> 0 | Q18: =SUM(N18:P18) -> 0
A19: =A18+1 -> 3 | L19: =$D$9 -> 10 | M19: =K19*L19 -> 0 | N19: =ROUND(IF($D$10>$D$9,($D$9*K19)-O19,$D$10*K19),2) -> 0 | O19: =ROUND(IF($D$12="Yes", N19*8.25%,IF($D$13="Yes", M19*8.25%,IF($D$14="Yes",(M19/1.0825)*8.25%,"0"))),2) -> 0 | P19: =ROUND(J19-N19-O19,2) -> 0 | Q19: =SUM(N19:P19) -> 0
A20: =A19+1 -> 4 | L20: =$D$9 -> 10 | M20: =K20*L20 -> 0 | N20: =ROUND(IF($D$10>$D$9,($D$9*K20)-O20,$D$10*K20),2) -> 0 | O20: =ROUND(IF($D$12="Yes", N20*8.25%,IF($D$13="Yes", M20*8.25%,IF($D$14="Yes",(M20/1.0825)*8.25%,"0"))),2) -> 0 | P20: =ROUND(J20-N20-O20,2) -> 0 | Q20: =SUM(N20:P20) -> 0
A21: =A20+1 -> 5 | L21: =$D$9 -> 10 | M21: =K21*L21 -> 0 | N21: =ROUND(IF($D$10>$D$9,($D$9*K21)-O21,$D$10*K21),2) -> 0 | O21: =ROUND(IF($D$12="Yes", N21*8.25%,IF($D$13="Yes", M21*8.25%,IF($D$14="Yes",(M21/1.0825)*8.25%,"0"))),2) -> 0 | P21: =ROUND(J21-N21-O21,2) -> 0 | Q21: =SUM(N21:P21) -> 0
A22: =A21+1 -> 6 | L22: =$D$9 -> 10 | M22: =K22*L22 -> 0 | N22: =ROUND(IF($D$10>$D$9,($D$9*K22)-O22,$D$10*K22),2) -> 0 | O22: =ROUND(IF($D$12="Yes", N22*8.25%,IF($D$13="Yes", M22*8.25%,IF($D$14="Yes",(M22/1.0825)*8.25%,"0"))),2) -> 0 | P22: =ROUND(J22-N22-O22,2) -> 0 | Q22: =SUM(N22:P22) -> 0
A23: =A22+1 -> 7 | L23: =$D$9 -> 10 | M23: =K23*L23 -> 0 | N23: =ROUND(IF($D$10>$D$9,($D$9*K23)-O23,$D$10*K23),2) -> 0 | O23: =ROUND(IF($D$12="Yes", N23*8.25%,IF($D$13="Yes", M23*8.25%,IF($D$14="Yes",(M23/1.0825)*8.25%,"0"))),2) -> 0 | P23: =ROUND(J23-N23-O23,2) -> 0 | Q23: =SUM(N23:P23) -> 0
A24: =A23+1 -> 8 | L24: =$D$9 -> 10 | M24: =K24*L24 -> 0 | N24: =ROUND(IF($D$10>$D$9,($D$9*K24)-O24,$D$10*K24),2) -> 0 | O24: =ROUND(IF($D$12="Yes", N24*8.25%,IF($D$13="Yes", M24*8.25%,IF($D$14="Yes",(M24/1.0825)*8.25%,"0"))),2) -> 0 | P24: =ROUND(J24-N24-O24,2) -> 0 | Q24: =SUM(N24:P24) -> 0
A25: =A24+1 -> 9 | L25: =$D$9 -> 10 | M25: =K25*L25 -> 0 | N25: =ROUND(IF($D$10>$D$9,($D$9*K25)-O25,$D$10*K25),2) -> 0 | O25: =ROUND(IF($D$12="Yes", N25*8.25%,IF($D$13="Yes", M25*8.25%,IF($D$14="Yes",(M25/1.0825)*8.25%,"0"))),2) -> 0 | P25: =ROUND(J25-N25-O25,2) -> 0 | Q25: =SUM(N25:P25) -> 0
A26: =A25+1 -> 10 | L26: =$D$9 -> 10 | M26: =K26*L26 -> 0 | N26: =ROUND(IF($D$10>$D$9,($D$9*K26)-O26,$D$10*K26),2) -> 0 | O26: =ROUND(IF($D$12="Yes", N26*8.25%,IF($D$13="Yes", M26*8.25%,IF($D$14="Yes",(M26/1.0825)*8.25%,"0"))),2) -> 0 | P26: =ROUND(J26-N26-O26,2) -> 0 | Q26: =SUM(N26:P26) -> 0
A27: =A26+1 -> 11 | L27: =$D$9 -> 10 | M27: =K27*L27 -> 0 | N27: =ROUND(IF($D$10>$D$9,($D$9*K27)-O27,$D$10*K27),2) -> 0 | O27: =ROUND(IF($D$12="Yes", N27*8.25%,IF($D$13="Yes", M27*8.25%,IF($D$14="Yes",(M27/1.0825)*8.25%,"0"))),2) -> 0 | P27: =ROUND(J27-N27-O27,2) -> 0 | Q27: =SUM(N27:P27) -> 0
A28: =A27+1 -> 12 | L28: =$D$9 -> 10 | M28: =K28*L28 -> 0 | N28: =ROUND(IF($D$10>$D$9,($D$9*K28)-O28,$D$10*K28),2) -> 0 | O28: =ROUND(IF($D$12="Yes", N28*8.25%,IF($D$13="Yes", M28*8.25%,IF($D$14="Yes",(M28/1.0825)*8.25%,"0"))),2) -> 0 | P28: =ROUND(J28-N28-O28,2) -> 0 | Q28: =SUM(N28:P28) -> 0
A29: =A28+1 -> 13 | I29: CASH | L29: =$D$9 -> 10 | M29: =K29*L29 -> 0 | N29: =ROUND(IF($D$10>$D$9,($D$9*K29)-O29,$D$10*K29),2) -> 0 | O29: =ROUND(IF($D$12="Yes", N29*8.25%,IF($D$13="Yes", M29*8.25%,IF($D$14="Yes",(M29/1.0825)*8.25%,"0"))),2) -> 0 | P29: =ROUND(J29-N29-O29,2) -> 0 | Q29: =SUM(N29:P29) -> 0
A30: =A29+1 -> 14 | M30: =K30*L30 -> 0 | N30: =ROUND(IF($D$10>$D$9,($D$9*K30)-O30,$D$10*K30),2) -> 0 | O30: =ROUND(IF($D$12="Yes", N30*8.25%,IF($D$13="Yes", M30*8.25%,IF($D$14="Yes",(M30/1.0825)*8.25%,"0"))),2) -> 0 | P30: =ROUND(J30-N30-O30,2) -> 0 | Q30: =SUM(N30:P30) -> 0
A31: =A30+1 -> 15 | M31: =K31*L31 -> 0 | N31: =ROUND(IF($D$10>$D$9,($D$9*K31)-O31,$D$10*K31),2) -> 0 | O31: =ROUND(IF($D$12="Yes", N31*8.25%,IF($D$13="Yes", M31*8.25%,IF($D$14="Yes",(M31/1.0825)*8.25%,"0"))),2) -> 0 | P31: =ROUND(J31-N31-O31,2) -> 0 | Q31: =SUM(N31:P31) -> 0
I32: TOTAL CASH RECEIVED | J32: =SUM(J17:J31) -> 0 | M32: =SUM(M17:M31) -> 0 | N32: =SUM(N17:N31) -> 0 | O32: =SUM(O17:O31) -> 0 | P32: =SUM(P17:P31) -> 0 | Q32: =SUM(Q17:Q31) -> 0
N37: Expense Reimbursement | O37: =IF($P$32<0, $N$32+$P$32, N32) -> 0 | Q37: Cashiers Enter
N38: Sales Tax Payable | O38: =O32 -> 0 | P38: 11-0000-21041 | Q38: Cashiers Enter
N39: Donation | O39: =IF($P$32<0, "",$P$32) -> 0 | Q39: Cullie Enters
O40: =SUM(O37:O39) -> 0

Sheet Expenses
A1: FUNDRAISING EVENT - RELATED EXPENSES/COSTS
A3: *Please enter expense information in peach cells for all event costs incurred in the current fiscal year. For donated items/prizes, list item followed by "DONATED" in description column, donor name in vendor name and $0 in amount paid.
B6: Non-cash prizes | F6: Rent/facility costs
B7: Description | C7: Vendor | D7: Amount Paid | F7: Description | G7: Vendor | H7: Amount Paid
A8: 1 | E8: 1
A9: 2 | E9: 2
A10: 3 | E10: 3
A11: 4 | E11: 4
A12: 5 | E12: 5
D13: =SUM(D8:D10) -> 0 | H13: =SUM(H8:H10) -> 0
B16: Other direct expenses
B17: Description | C17: Vendor | D17: Amount Paid
A18: 1
A19: 2
A20: 3
A21: 4
A22: 5
D23: =SUM(D18:D20) -> 0 | G23: Total Cash Prizes | H23: 0
G25: Total Exp Before Sales Tax | H25: =H23+H13+D13+D23 -> 0
G27: Total Sales Tax | H27: =Income!O32 -> 0
G29: Total Expenses | H29: =H25+H27 -> 0

Sheet Silent Auctions-Auctions
A1: FUNDRAISING EVENT - Summary sheet for auctions, silent auctions, and raffles
A3: ** Only enter information in the peach colored cells.
A5: LIST OF ITEMS COLLECTED FOR AUCTION OR RAFFLE
C6: SU BOUGHT ITEM | E6: ITEM DONATED
B7: Auction Item | C7: SU Cost of Item Purchased | D7: Account used for purchase | E7: If Donation - Who donated item | F7: Address | G7: City | H7: State | I7: Zip | J7: Value if Known
A8: EXAMPLE | B8: Athetic Shirt | C8: 4.87 | D8: 11-0271-54571
A9: EXAMPLE | B9: Chili's Gift Certificate | E9: Chili's - Sam Persons, Manager | F9: 400 N IH 35 | G9: Georgetown | H9: TX | I9: 78626 | J9: 25
A10: 1
A11: =A10+1 -> 2
A12: =A11+1 -> 3
A13: =A12+1 -> 4
A14: =A13+1 -> 5
A15: =A14+1 -> 6
A16: =A15+1 -> 7
A17: =A16+1 -> 8
A18: =A17+1 -> 9
A19: =A18+1 -> 10
A20: =A19+1 -> 11
A21: =A20+1 -> 12
A22: =A21+1 -> 13
... A29: =A28+1 -> 20
B30: TOTALS | C30: =SUM(C8:C29) -> 4.87 | J30: =SUM(J9:J29) -> 25
A32: LIST OF ITEMS AUCTIONED -
B33: Auction Items | C33: Ending Bid | D33: SU Cost if applicable | E33: Name of Person Who Bought Item | F33: Address | G33: City | H33: State | I33: Zip | J33: Cash Credit Card (CC) or Check | K33: Check #
A34: EXAMPLE | B34: Athetic Shirt | C34: 10 | D34: =C8 -> 4.87 | E34: Sam Peters | F34: 1234 Red Bud Lane | G34: Georgetown | H34: TX | I34: 78628 | J34: Check | K34: 5798
A35: EXAMPLE | B35: Chili's Gift Certificate | C35: 40 | D35: =C9 -> 0 | E35: Yolanda Perez | F35: 4545 Cat Hollow Blvd. | G35: Florence | H35: TX | I35: 76527 | J35: Cash
A36: 1 | B36: =B10 -> 0 | D36: =C10 -> 0 | J36: Cash
A37: =A36+1 -> 2 | B37: =B11 -> 0 | D37: =C11 -> 0 | J37: Cash
A38: =A37+1 -> 3 | B38: =B12 -> 0 | D38: =C12 -> 0 | J38: Cash
A39: =A38+1 -> 4 | B39: =B13 -> 0 | D39: =C13 -> 0 | J39: Cash
A40: =A39+1 -> 5 | B40: =B14 -> 0 | D40: =C14 -> 0 | J40: Cash
A41: =A40+1 -> 6 | B41: =B15 -> 0 | D41: =C15 -> 0 | J41: Cash
A42: =A41+1 -> 7 | B42: =B16 -> 0 | D42: =C16 -> 0 | J42: Cash
A43: =A42+1 -> 8 | B43: =B17 -> 0 | D43: =C17 -> 0 | J43: Cash
A44: =A43+1 -> 9 | B44: =B18 -> 0 | D44: =C18 -> 0 | J44: Cash
A45: =A44+1 -> 10 | B45: =B19 -> 0 | D45: =C19 -> 0 | J45: Cash
A46: =A45+1 -> 11 | B46: =B20 -> 0 | D46: =C20 -> 0 | J46: Cash
A47: =A46+1 -> 12 | B47: =B21 -> 0 | D47: =C21 -> 0 | J47: Cash
A48: =A47+1 -> 13 | B48: =B22 -> 0 | D48: =C22 -> 0 | J48: Cash
A49: =A48+1 -> 14 | B49: =B23 -> 0 | D49: =C23 -> 0 | J49: Cash | R49: Check
...
