Workbook
Name CmpIdSelected: INDIRECT(ADDRESS(CmpSelectedOnRow,1,1,TRUE,"Cmp"))
Name CmpSelectedOnRow: IFERROR(MATCH('Concept Note'!$C$4,Cmp!$D:$D,0),IFERROR(MATCH('Concept Note'!$C$4,Cmp!$E:$E,0),IFERROR(MATCH('Concept Note'!$C$4,Cmp!$F:$F,0),IFERROR(MATCH('Concept Note'!$C$4,Cmp!$G:$G,0),""))))
Name ComponentSelected: 'Concept Note'!$C$4
Name Country_Applicant: Definitions!$N$3:$N$204
Name DataSrcInCmp: OFFSET('Data src'!$D$1,MATCH(CmpIdSelected,'Data src'!$A:$A,0)-1,0,COUNTIF('Data src'!$A:$A,CmpIdSelected),1)
Name ImpactIndInCmp: OFFSET('Impact ind'!$E$1,MATCH(CmpIdSelected,'Impact ind'!$A:$A,0)-1,0,COUNTIF('Impact ind'!$A:$A,CmpIdSelected),1)
Name LangOffset: Translations!$C$1
Name Language: 'Concept Note'!$P$1
Name ModulesInCmp: OFFSET(Modules!$D$1,MATCH(CmpIdSelected,Modules!$A:$A,0)-1,0,COUNTIF(Modules!$A:$A,CmpIdSelected),1)
Name MonthIndex: Definitions!$M$3
Name Months: Definitions!$G$3:$G$15
Name MonthSelected: 'Concept Note'!$C$6
Name OutcomeIndInCmp: OFFSET('Outcome ind'!$E$1,MATCH(CmpIdSelected,'Outcome ind'!$A:$A,0)-1,0,COUNTIF('Outcome ind'!$A:$A,CmpIdSelected),1)
Name PRs: 'Concept Note'!$H$5
Name PRsInApplicant: OFFSET(Definitions!$R$3,MATCH(VLOOKUP('Concept Note'!$C$3,Definitions!D:E,2,FALSE),Definitions!G:G,0)-3,0,COUNTIF(Definitions!G:G,VLOOKUP('Concept Note'!$C$3,Definitions!D:E,2,FALSE)),1)
Name StartYearSelected: 'Concept Note'!$C$5
Name TiedTo: Definitions!$U$3:$U$7
Name Years: Definitions!$A$3:$A$6
Name YearSelected: 'Concept Note'!$C$5

Sheet Instructions en
A1: =Translations!B81 -> Modular Approach - Concept Note | O1: =Translations!$B$80 -> Language: | P1: English
A2: =Translations!$B$7 -> A. Program details
A3: =Translations!$B$8 -> Country / Applicant: | D3: =Translations!B72 -> Please select… | H3: =Translations!$B$13 -> Principal Recipients | S3: =IFERROR(VLOOKUP(K3,Definitions!R:S,2,FALSE),"") | U3: =Translations!$B$77 -> Total requested amount
A4: =Translations!$B$9 -> Component: | D4: =Translations!B72 -> Please select… | S4: =IFERROR(VLOOKUP(K4,Definitions!R:S,2,FALSE),"")
A5: =Translations!$B$10 -> Start Year: | D5: =Translations!B72 -> Please select… | H5: =Translations!$B$14 -> (Please select from list or add a new one) | S5: =IFERROR(VLOOKUP(K5,Definitions!R:S,2,FALSE),"") | U5: =Translations!$B$78 -> Indicative | Y5: =SUMIF(A:A,Translations!$A$84,F:F) -> 0
A6: =Translations!$B$11 -> Start Month: | D6: =Translations!B72 -> Please select… | S6: =IFERROR(VLOOKUP(K6,Definitions!R:S,2,FALSE),"") | U6: =Translations!$B$79 -> Above indicative | Y6: =SUMIF(J:J,Translations!$A$85,Q:Q) -> 0
A8: =Translations!$B$25 -> B. Program goals and impact indicators
A9: =Translations!$B$26 -> Goals:
A10: 1
A11: 2
A12: 3
A14: =Translations!$B$27 -> Linked to goal(s) # | B14: =Translations!$B$28 -> Impact indicator | I14: =Translations!$B$29 -> Baseline | O14: =Translations!$B$30 -> Targets | U14: =Translations!$B$73 -> Comments and Assumptions
I15: =Translations!$B$31 -> Value | K15: =Translations!$B$32 -> Year | L15: =Translations!$B$33 -> Source | O15: =Translations!$B$34 -> Year 1 | Q15: =Translations!$B$35 -> Year 2 | S15: =Translations!$B$36 -> Year 3
O16: =IFERROR(IF(MonthIndex<7,StartYearSelected,StartYearSelected+1),"") -> Please select… | Q16: =IFERROR(O16+1,"") | S16: =IFERROR(Q16+1,"")
B17: =Translations!B72 -> Please select… | L17: =Translations!$B$72 -> Please select…
B18: =Translations!B72 -> Please select… | L18: =Translations!$B$72 -> Please select…
B19: =Translations!B72 -> Please select… | L19: =Translations!$B$72 -> Please select…
B20: =Translations!B72 -> Please select… | L20: =Translations!$B$72 -> Please select…
B21: =Translations!B72 -> Please select… | L21: =Translations!$B$72 -> Please select…
A23: =Translations!$B$41 -> C. Program objectives and outcome indicators
A24: =Translations!$B$42 -> Objectives:
A25: 1
A26: 2
A27: 3
A28: 4
A29: 5
A30: 6
A32: =Translations!$B$43 -> Linked to objective(s) # | B32: =Translations!B44 -> Outcome indicator | I32: =Translations!$B$29 -> Baseline | O32: =Translations!$B$30 -> Targets | U32: =Translations!$B$73 -> Comments and Assumptions
I33: =Translations!$B$31 -> Value | K33: =Translations!$B$32 -> Year | L33: =Translations!$B$33 -> Source | O33: =Translations!$B$34 -> Year 1 | Q33: =Translations!$B$35 -> Year 2 | S33: =Translations!$B$36 -> Year 3
O34: =O16 -> Please select… | Q34: =Q16 | S34: =S16
B35: =Translations!$B$72 -> Please select… | L35: =Translations!$B$72 -> Please select…
B36: =Translations!$B$72 -> Please select… | L36: =Translations!$B$72 -> Please select…
B37: =Translations!$B$72 -> Please select… | L37: =Translations!$B$72 -> Please select…
B38: =Translations!$B$72 -> Please select… | L38: =Translations!$B$72 -> Please select…
B39: =Translations!$B$72 -> Please select… | L39: =Translations!$B$72 -> Please select…
A41: =Translations!B74 -> D. Modules
A43: =Translations!$B$75 -> Module | C43: 1 | D43: =Translations!$B$72 -> Please select…
A44: =Translations!$B$76 -> Measurement framework for module
A45: =Translations!$B$49 -> Coverage/Output indicator | D45: =Translations!$B$67 -> Responsible Principal Recipient(s) | E45: =Translations!$B$66 -> Tied to | G45: =Translations!$B$29 -> Baseline | M45: =Translations!$B$30 -> Targets | S45: =Translations!$B$82 -> Target assumptions
M46: =Translations!$B$34 -> Year 1 | O46: =Translations!$B$35 -> Year 2 | Q46: =Translations!$B$36 -> Year 3 | S46: =Translations!$B$83 -> Please describe: 1) overall assumptions used in calculating targets, 2) anticipated rate of scale-up, 3) population size estimates, 4) description of indicator/package of services, 5) data source, 6) other relevant information
...

Sheet Instructions fr
A1: =Translations!C81 -> Démarche modulaire : note conceptuelle | O1: =Translations!$C$80 -> Langue : | P1: Français
A2: =Translations!$C$7 -> A. Détails du programme
A3: =Translations!$C$8 -> Pays / Candidat : | D3: =Translations!C72 -> Veuillez sélectionner… | H3: =Translations!$C$13 -> Récipiendaires principaux | U3: =Translations!$C$77 demandé -> #NAME?
A4: =Translations!$C$9 -> Composante : | D4: =Translations!C72 -> Veuillez sélectionner…
A5: =Translations!$C$10 -> Année de début : | D5: =Translations!C72 -> Veuillez sélectionner… | H5: =Translations!$C$14 -> (Veuillez choisir un récipiendaire principal dans la liste ou en ajouter un nouveau) | U5: =Translations!$C$78 -> Indicatif | Y5: 0
A6: =Translations!$C$11 -> Mois de début : | D6: =Translations!C72 -> Veuillez sélectionner… | U6: =Translations!$C$79 -> Au-delà du montant indicatif | Y6: 0
A8: =Translations!$C$25 -> B. Buts du programme et indicateurs d'impact
A9: =Translations!$C$26 -> Buts :
A10: 1
A11: 2
A12: 3
A14: =Translations!$C$27 -> Lié au(x) but(s) n° | B14: =Translations!$C$28 -> Indicateur d'impact | I14: =Translations!$C$29 -> Données de référence | O14: =Translations!$C$30 -> Cibles | U14: =Translations!$C$73 -> Remarques et hypothèses
I15: =Translations!$C$31 -> Valeur | K15: =Translations!$C$32 -> Année | L15: =Translations!$C$33 -> Source | O15: =Translations!$C$34 -> Année 1 | Q15: =Translations!$C$35 -> Année 2 | S15: =Translations!$C$36 -> Année 3
O16: =IFERROR(IF(MonthIndex<7,StartYearSelected,StartYearSelected+1),"") -> Please select… | Q16: =IFERROR(O16+1,"") | S16: =IFERROR(Q16+1,"")
B17: =Translations!$C$72 -> Veuillez sélectionner… | L17: =Translations!$C$72 -> Veuillez sélectionner…
B18: =Translations!$C$72 -> Veuillez sélectionner… | L18: =Translations!$C$72 -> Veuillez sélectionner…
B19: Please select… | L19: =Translations!$C$72 -> Veuillez sélectionner…
B20: Please select… | L20: =Translations!$C$72 -> Veuillez sélectionner…
B21: Please select… | L21: =Translations!$C$72 -> Veuillez sélectionner…
A23: =Translations!$C$41 -> C. Objectifs du programme et indicateurs d'effets
A24: =Translations!$C$42 -> Objectifs :
A25: 1
A26: 2
A27: 3
A28: 4
A29: 5
A30: 6
A32: =Translations!$C$43 -> Lié à ou aux objectifs n° | B32: =Translations!C44 -> Indicateur d'effet | I32: =Translations!$C$29 -> Données de référence | O32: =Translations!$C$30 -> Cibles | U32: =Translations!$C$73 -> Remarques et hypothèses
I33: =Translations!$C$31 -> Valeur | K33: =Translations!$C$32 -> Année | L33: =Translations!$C$33 -> Source | O33: =Translations!$C$34 -> Année 1 | Q33: =Translations!$C$35 -> Année 2 | S33: =Translations!$C$36 -> Année 3
O34: =O16 -> Please select… | Q34: =Q16 | S34: =S16
B35: =Translations!$C$72 -> Veuillez sélectionner… | L35: =Translations!$C$72 -> Veuillez sélectionner…
B36: =Translations!$C$72 -> Veuillez sélectionner… | L36: =Translations!$C$72 -> Veuillez sélectionner…
B37: =Translations!$C$72 -> Veuillez sélectionner… | L37: =Translations!$C$72 -> Veuillez sélectionner…
B38: =Translations!$C$72 -> Veuillez sélectionner… | L38: =Translations!$C$72 -> Veuillez sélectionner…
B39: =Translations!$C$72 -> Veuillez sélectionner… | L39: =Translations!$C$72 -> Veuillez sélectionner…
A41: =Translations!$C$74 -> D. Modules
A43: =Translations!$C$75 -> Module | C43: 1 | D43: =Translations!$C$72 -> Veuillez sélectionner…
A44: =Translations!$C$76 -> Cadre de mesure du module
A45: =Translations!$C$49 -> Indicateur de couverture/produit | D45: =Translations!$C$67 -> Récipiendaires principaux responsables | E45: =Translations!$C$66 -> Lié à | G45: =Translations!$C$29 -> Données de référence | M45: =Translations!$C$30 -> Cibles | S45: =Translations!$C$82 -> Hypothèses pour les cibles
M46: =Translations!$C$34 -> Année 1 | O46: =Translations!$C$35 -> Année 2 | Q46: =Translations!$C$36 -> Année 3 | S46: =Translations!$C$83 -> Veuillez décrire : 1) les hypothèses générales utilisées pour le calcul des cibles, 2) le taux d'intensification prévisionnel, 3) les estimations démographiques, 4) l'indicateur ou paquet de services, 5) les sources de données, 6) toute autre information pertinente
...

Sheet Instructions es
A1: =Translations!D81 -> Enfoque modular - nota conceptual | O1: =Translations!D80 -> Idioma: | P1: Inglés
A2: =Translations!$D$7 -> A. Datos del programa
A3: =Translations!$D$8 -> País / Solicitante: | D3: =Translations!$D$72 -> Seleccione… | H3: =Translations!$D$13 -> Receptores principales | U3: =Translations!$D$77 solicitado -> #NAME?
A4: =Translations!$D$9 -> Componente: | D4: =Translations!$D$72 -> Seleccione…
A5: =Translations!$D$10 -> Año de inicio: | D5: =Translations!$D$72 -> Seleccione… | H5: =Translations!$D$14 -> (seleccione uno de la lista o añada uno nuevo) | U5: =Translations!$D$78 -> Indicativo | Y5: 0
A6: =Translations!$D$11 -> Mes de inicio: | D6: =Translations!$D$72 -> Seleccione… | U6: =Translations!$D$79 -> Por encima del indicativo | Y6: 0
A8: =Translations!$D$25 -> B. Metas del programa e indicadores de impacto
A9: =Translations!$D$26 -> Metas:
A10: 1
A11: 2
A12: 3
A14: =Translations!$D$27 -> Vinculado a lo(s) objetivos(s) nº | B14: =Translations!$D$28 -> Indicador de impacto | I14: =Translations!$D$29 -> Línea de base | O14: =Translations!$D$30 -> Metas | U14: =Translations!$D$73 -> Comentarios y supuestos
I15: =Translations!$D$31 -> Valor | K15: =Translations!$D$32 -> Año | L15: =Translations!$D$33 -> Fuente | O15: =Translations!$D$34 -> Año 1 | Q15: =Translations!$D$35 -> Año 2 | S15: =Translations!$D$36 -> Año 3
O16: =IFERROR(IF(MonthIndex<7,StartYearSelected,StartYearSelected+1),"") -> Please select… | Q16: =IFERROR(O16+1,"") | S16: =IFERROR(Q16+1,"")
B17: =Translations!$D$72 -> Seleccione… | L17: =Translations!$D$72 -> Seleccione…
B18: =Translations!$D$72 -> Seleccione… | L18: =Translations!$D$72 -> Seleccione…
B19: =Translations!$D$72 -> Seleccione… | L19: =Translations!$D$72 -> Seleccione…
B20: =Translations!$D$72 -> Seleccione… | L20: =Translations!$D$72 -> Seleccione…
B21: =Translations!$D$72 -> Seleccione… | L21: =Translations!$D$72 -> Seleccione…
A23: =Translations!$D$41 -> C. Objetivos del programa e indicadores de resultados
A24: =Translations!$D$42 -> Objetivos:
A25: 1
A26: 2
A27: 3
A28: 4
A29: 5
A30: 6
A32: =Translations!$D$43 -> Vinculado al (los) objetivo(s) nº | B32: =Translations!D44 -> Indicador de resultados | I32: =Translations!$D$29 -> Línea de base | O32: =Translations!$D$30 -> Metas | U32: =Translations!$D$73 -> Comentarios y supuestos
I33: =Translations!$D$31 -> Valor | K33: =Translations!$D$32 -> Año | L33: =Translations!$D$33 -> Fuente | O33: =Translations!$D$34 -> Año 1 | Q33: =Translations!$D$35 -> Año 2 | S33: =Translations!$D$36 -> Año 3
O34: =O16 -> Please select… | Q34: =Q16 | S34: =S16
B35: =Translations!$D$72 -> Seleccione… | L35: =Translations!$D$72 -> Seleccione…
B36: =Translations!$D$72 -> Seleccione… | L36: =Translations!$D$72 -> Seleccione…
B37: =Translations!$D$72 -> Seleccione… | L37: =Translations!$D$72 -> Seleccione…
B38: =Translations!$D$72 -> Seleccione… | L38: =Translations!$D$72 -> Seleccione…
B39: =Translations!$D$72 -> Seleccione… | L39: =Translations!$D$72 -> Seleccione…
A41: =Translations!$D$74 -> D. Módulos
A43: =Translations!$D$75 -> Módulo | C43: 1 | D43: =Translations!$D$72 -> Seleccione…
A44: =Translations!$D$76 -> Marco de medición por módulo
A45: =Translations!$D$49 -> Indicador de cobertura/producto | D45: =Translations!$D$67 -> Receptores principales | E45: =Translations!$D$66 -> Vinculado al | G45: =Translations!$D$29 -> Línea de base | M45: =Translations!$D$30 -> Metas | S45: =Translations!$D$82 -> Supuestos de metas
M46: =Translations!$D$34 -> Año 1 | O46: =Translations!$D$35 -> Año 2 | Q46: =Translations!$D$36 -> Año 3 | S46: =Translations!$D$83 -> Describa lo siguiente: 1) supuestos generales usados al calcular las metas;: 2) tasa de ampliación prevista; 3) estimaciones del tamaño de la población; 4) descripción del indicador/paquete de servicios; 5) fuente de datos; 6) otra información pertinente.
...

Sheet Instructions ru
A1: =Translations!E81 -> Модульный подход — концептуальная записка | O1: =Translations!$E$80 -> Язык: | P1: Английский
A2: =Translations!$E$7 -> A. Сведения о программе
A3: =Translations!$E$8 -> Страна/ Кандидат: | D3: =Translations!$E$72 -> Выберите значение… | H3: =Translations!$E$13 -> Основные реципиенты | U3: =Translations!$E$77 запрашиваемого финансирования -> #NAME?
A4: =Translations!$E$9 -> Компонент: | D4: =Translations!$E$72 -> Выберите значение…
A5: =Translations!$E$10 -> Год начала: | D5: =Translations!$E$72 -> Выберите значение… | H5: =Translations!$E$14 -> (Выберите из списка или добавьте нового) | U5: =Translations!$E$78 -> Ориентировочное | Y5: 0
A6: =Translations!$E$11 -> Месяц начала: | D6: =Translations!$E$72 -> Выберите значение… | U6: =Translations!$E$79 -> Свыше ориентировочного | Y6: 0
A8: =Translations!$E$25 -> B. Цели программы и показатели воздействия
A9: =Translations!$E$26 -> Цели:
A10: 1
A11: 2
A12: 3
A14: =Translations!$E$27 -> Привязка к цели(ям) # | B14: =Translations!$E$28 -> Показатель воздействия | I14: =Translations!$E$29 -> Исходный уровень | O14: =Translations!$E$30 -> Целевые показатели | U14: =Translations!$E$73 -> Комментарии и ориентировочные расчеты
I15: =Translations!$E$31 -> Величина | K15: =Translations!$E$32 -> Год | L15: =Translations!$E$33 -> Источник | O15: =Translations!$E$34 -> Год 1 | Q15: =Translations!$E$35 -> Год 2 | S15: =Translations!$E$36 -> Год 3
O16: =IFERROR(IF(MonthIndex<7,StartYearSelected,StartYearSelected+1),"") -> Please select… | Q16: =IFERROR(O16+1,"") | S16: =IFERROR(Q16+1,"")
B17: =Translations!$E$72 -> Выберите значение… | L17: =Translations!$E$72 -> Выберите значение…
B18: =Translations!$E$72 -> Выберите значение… | L18: =Translations!$E$72 -> Выберите значение…
B19: =Translations!$E$72 -> Выберите значение… | L19: =Translations!$E$72 -> Выберите значение…
B20: =Translations!$E$72 -> Выберите значение… | L20: =Translations!$E$72 -> Выберите значение…
B21: =Translations!$E$72 -> Выберите значение… | L21: =Translations!$E$72 -> Выберите значение…
A23: =Translations!$E$41 -> C. Задачи программы и показатели долгосрочных результатов
A24: =Translations!$E$42 -> Задачи:
A25: 1
A26: 2
A27: 3
A28: 4
A29: 5
A30: 6
A32: =Translations!$E$43 -> Привязка к задаче(задачам) # | B32: =Translations!E44 -> Показатель долгосрочного результата | I32: =Translations!$E$29 -> Исходный уровень | O32: =Translations!$E$30 -> Целевые показатели | U32: =Translations!$E$73 -> Комментарии и ориентировочные расчеты
I33: =Translations!$E$31 -> Величина | K33: =Translations!$E$32 -> Год | L33: =Translations!$E$33 -> Источник | O33: =Translations!$E$34 -> Год 1 | Q33: =Translations!$E$35 -> Год 2 | S33: =Translations!$E$36 -> Год 3
O34: =O16 -> Please select… | Q34: =Q16 | S34: =S16
B35: =Translations!$E$72 -> Выберите значение… | L35: =Translations!$E$72 -> Выберите значение…
B36: =Translations!$E$72 -> Выберите значение… | L36: =Translations!$E$72 -> Выберите значение…
B37: =Translations!$E$72 -> Выберите значение… | L37: =Translations!$E$72 -> Выберите значение…
B38: =Translations!$E$72 -> Выберите значение… | L38: =Translations!$E$72 -> Выберите значение…
B39: =Translations!$E$72 -> Выберите значение… | L39: =Translations!$E$72 -> Выберите значение…
A41: =Translations!$E$74 -> D. Модули
A43: =Translations!$E$75 -> Модуль | C43: 1 | D43: =Translations!$E$72 -> Выберите значение…
A44: =Translations!$E$76 -> Система показателей для модуля
A45: =Translations!$E$49 -> Показатель долгосрочного охвата/ результата | D45: =Translations!$E$67 -> Ответственный основной реципиент (реципиенты) | E45: =Translations!$E$66 -> Привязывается к | G45: =Translations!$E$29 -> Исходный уровень | M45: =Translations!$E$30 -> Целевые показатели | S45: =Translations!$E$82 -> Целевые предпосылки
M46: =Translations!$E$34 -> Год 1 | O46: =Translations!$E$35 -> Год 2 | Q46: =Translations!$E$36 -> Год 3 | S46: =Translations!$E$83 -> Укажите: 1) общие предположения, использованные при расчете целевых показателей; 2) предположительный уровень расширения охвата; 3) показатели численности населения, 4) описание показателей/ пакета услуг; 5) источники данных; 6) другую необходимую информацию.
...

Sheet Concept Note
A1: =Translations!A81 -> Modular Approach - Concept Note | O1: =Translations!$A$80 -> Language: | P1: English
A2: =Translations!$A$7 -> A. Program details
A3: =Translations!$A$8 -> Country / Applicant: | C3: Please select… | H3: =Translations!$A$13 -> Principal Recipients | S3: =IFERROR(VLOOKUP(K3,Definitions!R:S,2,FALSE),"") | U3: =Translations!$A$77 -> Total requested amount
A4: =Translations!$A$9 -> Component: | C4: =Translations!$A$72 -> Please select… | S4: =IFERROR(VLOOKUP(K4,Definitions!R:S,2,FALSE),"")
A5: =Translations!$A$10 -> Start Year: | C5: =Translations!$A$72 -> Please select… | H5: =Translations!$A$14 -> (Please select from list or add a new one) | S5: =IFERROR(VLOOKUP(K5,Definitions!R:S,2,FALSE),"") | U5: =Translations!$A$78 -> Indicative | Y5: =SUMIF(A:A,Translations!$A$84,F:F) -> 0
A6: =Translations!$A$11 -> Start Month: | C6: =Translations!$A$72 -> Please select… | S6: =IFERROR(VLOOKUP(K6,Definitions!R:S,2,FALSE),"") | U6: =Translations!$A$79 -> Above indicative | Y6: =SUMIF(J:J,Translations!$A$85,Q:Q) -> 0
A8: =Translations!$A$25 -> B. Program goals and impact indicators
A9: =Translations!$A$26 -> Goals:
A10: 1
A11: 2
A12: 3
A14: =Translations!$A$27 -> Linked to goal(s) # | B14: =Translations!$A$28 -> Impact indicator | I14: =Translations!$A$29 -> Baseline | O14: =Translations!$A$30 -> Targets | U14: =Translations!$A$73 -> Comments and Assumptions
I15: =Translations!$A$31 -> Value | K15: =Translations!$A$32 -> Year | L15: =Translations!$A$33 -> Source | O15: =Translations!$A$34 -> Year 1 | Q15: =Translations!$A$35 -> Year 2 | S15: =Translations!$A$36 -> Year 3
O16: =IFERROR(IF(MonthIndex<7,StartYearSelected,StartYearSelected+1),"") -> Please select… | Q16: =IFERROR(O16+1,"") | S16: =IFERROR(Q16+1,"")
B17: =Translations!$A$72 -> Please select… | L17: =Translations!$A$72 -> Please select…
B18: =Translations!$A$72 -> Please select… | L18: =Translations!$A$72 -> Please select…
B19: =Translations!$A$72 -> Please select… | L19: =Translations!$A$72 -> Please select…
B20: =Translations!$A$72 -> Please select… | L20: =Translations!$A$72 -> Please select…
B21: =Translations!$A$72 -> Please select… | L21: =Translations!$A$72 -> Please select…
A23: =Translations!$A$41 -> C. Program objectives and outcome indicators
A24: =Translations!$A$42 -> Objectives:
A25: 1
A26: 2
A27: 3
A28: 4
A29: 5
A30: 6
A32: =Translations!$A$43 -> Linked to objective(s) # | B32: =Translations!A44 -> Outcome indicator | I32: =Translations!$A$29 -> Baseline | O32: =Translations!$A$30 -> Targets | U32: =Translations!$A$73 -> Comments and Assumptions
I33: =Translations!$A$31 -> Value | K33: =Translations!$A$32 -> Year | L33: =Translations!$A$33 -> Source | O33: =Translations!$A$34 -> Year 1 | Q33: =Translations!$A$35 -> Year 2 | S33: =Translations!$A$36 -> Year 3
O34: =O16 -> Please select… | Q34: =Q16 | S34: =S16
B35: =Translations!$A$72 -> Please select… | L35: =Translations!$A$72 -> Please select…
B36: =Translations!$A$72 -> Please select… | L36: =Translations!$A$72 -> Please select…
B37: =Translations!$A$72 -> Please select… | L37: =Translations!$A$72 -> Please select…
B38: =Translations!$A$72 -> Please select… | L38: =Translations!$A$72 -> Please select…
B39: =Translations!$A$72 -> Please select… | L39: =Translations!$A$72 -> Please select…
A41: =Translations!A74 -> D. Modules | AJ41: Start row | AK41: Nbr of ind | AL41: Cov ind row | AM41: ModuleId | AN41: Indicative | AO41: Above
A43: =Translations!$A$75 -> Module | AM43: =INDIRECT(ADDRESS(MATCH(D43,ModulesInCmp,0)+MATCH(CmpIdSelected,Modules!$A:$A,0)-1,3,1,TRUE,"Modules")) -> #VALUE!
A44: =Translations!$A$76 -> Measurement framework for module | AM44: =INDIRECT(ADDRESS(ROW()-1,COLUMN())) -> #VALUE!
A45: =Translations!$A$49 -> Coverage/Output indicator | D45: =Translations!$A$67 -> Responsible Principal Recipient(s) | E45: =Translations!$A$66 -> Tied to | G45: =Translations!$A$29 -> Baseline | M45: =Translations!$A$30 -> Targets | S45: =Translations!$A$82 -> Target assumptions | AJ45: =MATCH(AM44,'Coverage ind'!$A:$A,0)-1 -> #VALUE! | AK45: =COUNTIF('Coverage ind'!A:A,'Concept Note'!AM44) -> 0 | AL45: =MATCH(AM44,'Coverage ind'!$A:$A,0)-1 -> #VALUE! | AM45: =INDIRECT(ADDRESS(ROW()-1,COLUMN())) -> #VALUE!
M46: =Translations!$A$34 -> Year 1 | O46: =Translations!$A$35 -> Year 2 | Q46: =Translations!$A$36 -> Year 3 | S46: =Translations!$A$83 -> Please describe: 1) overall assumptions used in calculating targets, 2) anticipated rate of scale-up, 3) population size estimates, 4) description of indicator/package of services, 5) data source, 6) other relevant information | AJ46: =INDIRECT(ADDRESS(ROW()-1,COLUMN())) -> #VALUE! | AK46: =INDIRECT(ADDRESS(ROW()-1,COLUMN())) -> 0 | AM46: =INDIRECT(ADDRESS(ROW()-1,COLUMN())) -> #VALUE!
...

Sheet Summary budget
J1: =Translations!$A$96 -> Summary of requested 3 years of funding by module
A3: ModId | B3: =Modules!D1 -> Label | C3: Indicative | D3: P1 | E3: Above | F3: P2 | G3: Total / Full | H3: P3 | J3: =Translations!$A$97 -> To refresh the pivot table with latest amounts entered in the Module budgets on the Concept Note sheet, click anywhere on the pivot table and then press Alt + F5.
A4: =Modules!C2 -> 1 | B4: =Modules!D2 -> Prevention - General population | C4: =SUMIF('Concept Note'!AM:AM,A4,'Concept Note'!AN:AN) -> 0 | D4: =C4/SUM(C:C) -> #DIV/0! | E4: =SUMIF('Concept Note'!$AM:$AM,A4,'Concept Note'!$AO:$AO) -> 0 | F4: =E4/SUM(E:E) -> #DIV/0! | G4: =SUM(C4,E4) -> 0 | H4: =G4/SUM(G:G) -> #DIV/0!
A5: =Modules!C8 -> 2 | B5: =Modules!D8 -> PMTCT | C5: =SUMIF('Concept Note'!AM:AM,A5,'Concept Note'!AN:AN) -> 0 | D5: =C5/SUM(C:C) -> #DIV/0! | E5: =SUMIF('Concept Note'!$AM:$AM,A5,'Concept Note'!$AO:$AO) -> 0 | F5: =E5/SUM(E:E) -> #DIV/0! | G5: =SUM(C5,E5) -> 0 | H5: =G5/SUM(G:G) -> #DIV/0!
A6: =Modules!C9 -> 3 | B6: =Modules!D9 -> Treatment, care and support | C6: =SUMIF('Concept Note'!AM:AM,A6,'Concept Note'!AN:AN) -> 0 | D6: =C6/SUM(C:C) -> #DIV/0! | E6: =SUMIF('Concept Note'!$AM:$AM,A6,'Concept Note'!$AO:$AO) -> 0 | F6: =E6/SUM(E:E) -> #DIV/0! | G6: =SUM(C6,E6) -> 0 | H6: =G6/SUM(G:G) -> #DIV/0! | J6: Row Labels | K6: Indicative budget | L6: Indicative % | M6: Above indicative | N6: Above % | O6: Full request | P6: Full %
A7: =Modules!C10 -> 4 | B7: =Modules!D10 -> Monitoring and Evaluation | C7: =SUMIF('Concept Note'!AM:AM,A7,'Concept Note'!AN:AN) -> 0 | D7: =C7/SUM(C:C) -> #DIV/0! | E7: =SUMIF('Concept Note'!$AM:$AM,A7,'Concept Note'!$AO:$AO) -> 0 | F7: =E7/SUM(E:E) -> #DIV/0! | G7: =SUM(C7,E7) -> 0 | H7: =G7/SUM(G:G) -> #DIV/0! | J7: Grand Total
A8: =Modules!C11 -> 5 | B8: =Modules!D11 -> Program management | C8: =SUMIF('Concept Note'!AM:AM,A8,'Concept Note'!AN:AN) -> 0 | D8: =C8/SUM(C:C) -> #DIV/0! | E8: =SUMIF('Concept Note'!$AM:$AM,A8,'Concept Note'!$AO:$AO) -> 0 | F8: =E8/SUM(E:E) -> #DIV/0! | G8: =SUM(C8,E8) -> 0 | H8: =G8/SUM(G:G) -> #DIV/0!
A9: =Modules!C12 -> 6 | B9: =Modules!D12 -> DOTS-based package | C9: =SUMIF('Concept Note'!AM:AM,A9,'Concept Note'!AN:AN) -> 0 | D9: =C9/SUM(C:C) -> #DIV/0! | E9: =SUMIF('Concept Note'!$AM:$AM,A9,'Concept Note'!$AO:$AO) -> 0 | F9: =E9/SUM(E:E) -> #DIV/0! | G9: =SUM(C9,E9) -> 0 | H9: =G9/SUM(G:G) -> #DIV/0!
A10: =Modules!C13 -> 7 | B10: =Modules!D13 -> TB/HIV package (in high TB/HIV burden countries or for high risk groups in all countries) | C10: =SUMIF('Concept Note'!AM:AM,A10,'Concept Note'!AN:AN) -> 0 | D10: =C10/SUM(C:C) -> #DIV/0! | E10: =SUMIF('Concept Note'!$AM:$AM,A10,'Concept Note'!$AO:$AO) -> 0 | F10: =E10/SUM(E:E) -> #DIV/0! | G10: =SUM(C10,E10) -> 0 | H10: =G10/SUM(G:G) -> #DIV/0!
A11: =Modules!C14 -> 8 | B11: =Modules!D14 -> MDR-TB package (in high MDR-TB burden countries or for high risk groups in all countries) | C11: =SUMIF('Concept Note'!AM:AM,A11,'Concept Note'!AN:AN) -> 0 | D11: =C11/SUM(C:C) -> #DIV/0! | E11: =SUMIF('Concept Note'!$AM:$AM,A11,'Concept Note'!$AO:$AO) -> 0 | F11: =E11/SUM(E:E) -> #DIV/0! | G11: =SUM(C11,E11) -> 0 | H11: =G11/SUM(G:G) -> #DIV/0!
A12: =Modules!C15 -> 9 | B12: =Modules!D15 -> Human Rights | C12: =SUMIF('Concept Note'!AM:AM,A12,'Concept Note'!AN:AN) -> 0 | D12: =C12/SUM(C:C) -> #DIV/0! | E12: =SUMIF('Concept Note'!$AM:$AM,A12,'Concept Note'!$AO:$AO) -> 0 | F12: =E12/SUM(E:E) -> #DIV/0! | G12: =SUM(C12,E12) -> 0 | H12: =G12/SUM(G:G) -> #DIV/0!
A13: =Modules!C16 -> 10 | B13: =Modules!D16 -> Monitoring and Evaluation | C13: =SUMIF('Concept Note'!AM:AM,A13,'Concept Note'!AN:AN) -> 0 | D13: =C13/SUM(C:C) -> #DIV/0! | E13: =SUMIF('Concept Note'!$AM:$AM,A13,'Concept Note'!$AO:$AO) -> 0 | F13: =E13/SUM(E:E) -> #DIV/0! | G13: =SUM(C13,E13) -> 0 | H13: =G13/SUM(G:G) -> #DIV/0!
A14: =Modules!C17 -> 11 | B14: =Modules!D17 -> Program Management | C14: =SUMIF('Concept Note'!AM:AM,A14,'Concept Note'!AN:AN) -> 0 | D14: =C14/SUM(C:C) -> #DIV/0! | E14: =SUMIF('Concept Note'!$AM:$AM,A14,'Concept Note'!$AO:$AO) -> 0 | F14: =E14/SUM(E:E) -> #DIV/0! | G14: =SUM(C14,E14) -> 0 | H14: =G14/SUM(G:G) -> #DIV/0!
A15: =Modules!C18 -> 12 | B15: =Modules!D18 -> Vector Control (VC) | C15: =SUMIF('Concept Note'!AM:AM,A15,'Concept Note'!AN:AN) -> 0 | D15: =C15/SUM(C:C) -> #DIV/0! | E15: =SUMIF('Concept Note'!$AM:$AM,A15,'Concept Note'!$AO:$AO) -> 0 | F15: =E15/SUM(E:E) -> #DIV/0! | G15: =SUM(C15,E15) -> 0 | H15: =G15/SUM(G:G) -> #DIV/0!
A16: =Modules!C19 -> 13 | B16: =Modules!D19 -> Case Management (CM) | C16: =SUMIF('Concept Note'!AM:AM,A16,'Concept Note'!AN:AN) -> 0 | D16: =C16/SUM(C:C) -> #DIV/0! | E16: =SUMIF('Concept Note'!$AM:$AM,A16,'Concept Note'!$AO:$AO) -> 0 | F16: =E16/SUM(E:E) -> #DIV/0! | G16: =SUM(C16,E16) -> 0 | H16: =G16/SUM(G:G) -> #DIV/0!
A17: =Modules!C20 -> 14 | B17: =Modules!D20 -> Specific Prevention Interventions (SPI) | C17: =SUMIF('Concept Note'!AM:AM,A17,'Concept Note'!AN:AN) -> 0 | D17: =C17/SUM(C:C) -> #DIV/0! | E17: =SUMIF('Concept Note'!$AM:$AM,A17,'Concept Note'!$AO:$AO) -> 0 | F17: =E17/SUM(E:E) -> #DIV/0! | G17: =SUM(C17,E17) -> 0 | H17: =G17/SUM(G:G) -> #DIV/0!
A18: =Modules!C21 -> 15 | B18: =Modules!D21 -> Monitoring and Evaluation (ME) | C18: =SUMIF('Concept Note'!AM:AM,A18,'Concept Note'!AN:AN) -> 0 | D18: =C18/SUM(C:C) -> #DIV/0! | E18: =SUMIF('Concept Note'!$AM:$AM,A18,'Concept Note'!$AO:$AO) -> 0 | F18: =E18/SUM(E:E) -> #DIV/0! | G18: =SUM(C18,E18) -> 0 | H18: =G18/SUM(G:G) -> #DIV/0!
A19: =Modules!C22 -> 16 | B19: =Modules!D22 -> Program Management (PM) | C19: =SUMIF('Concept Note'!AM:AM,A19,'Concept Note'!AN:AN) -> 0 | D19: =C19/SUM(C:C) -> #DIV/0! | E19: =SUMIF('Concept Note'!$AM:$AM,A19,'Concept Note'!$AO:$AO) -> 0 | F19: =E19/SUM(E:E) -> #DIV/0! | G19: =SUM(C19,E19) -> 0 | H19: =G19/SUM(G:G) -> #DIV/0!
... A27: =Modules!C30 -> 24 | B27: =Modules!D30 -> Program management (applicable for standalone HSS grants) | C27: =SUMIF('Concept Note'!AM:AM,A27,'Concept Note'!AN:AN) -> 0 | D27: =C27/SUM(C:C) -> #DIV/0! | E27: =SUMIF('Concept Note'!$AM:$AM,A27,'Concept Note'!$AO:$AO) -> 0 | F27: =E27/SUM(E:E) -> #DIV/0! | G27: =SUM(C27,E27) -> 0 | H27: =G27/SUM(G:G) -> #DIV/0!
A28: =Modules!C3 -> 25 | B28: =Modules!D3 -> Prevention - MSM and TGs | C28: =SUMIF('Concept Note'!AM:AM,A28,'Concept Note'!AN:AN) -> 0 | D28: =C28/SUM(C:C) -> #DIV/0! | E28: =SUMIF('Concept Note'!$AM:$AM,A28,'Concept Note'!$AO:$AO) -> 0 | F28: =E28/SUM(E:E) -> #DIV/0! | G28: =SUM(C28,E28) -> 0 | H28: =G28/SUM(G:G) -> #DIV/0!
A29: =Modules!C4 -> 26 | B29: =Modules!D4 -> Prevention - Sex Workers and their clients | C29: =SUMIF('Concept Note'!AM:AM,A29,'Concept Note'!AN:AN) -> 0 | D29: =C29/SUM(C:C) -> #DIV/0! | E29: =SUMIF('Concept Note'!$AM:$AM,A29,'Concept Note'!$AO:$AO) -> 0 | F29: =E29/SUM(E:E) -> #DIV/0! | G29: =SUM(C29,E29) -> 0 | H29: =G29/SUM(G:G) -> #DIV/0!
A30: =Modules!C5 -> 27 | B30: =Modules!D5 -> Prevention - Harm-reduction programmes for injecting drug users (IDUs) and their partners | C30: =SUMIF('Concept Note'!AM:AM,A30,'Concept Note'!AN:AN) -> 0 | D30: =C30/SUM(C:C) -> #DIV/0! | E30: =SUMIF('Concept Note'!$AM:$AM,A30,'Concept Note'!$AO:$AO) -> 0 | F30: =E30/SUM(E:E) -> #DIV/0! | G30: =SUM(C30,E30) -> 0 | H30: =G30/SUM(G:G) -> #DIV/0!
A31: =Modules!C7 -> 28 | B31: =Modules!D7 -> Prevention - Other vulnerable populations (please specify) | C31: =SUMIF('Concept Note'!AM:AM,A31,'Concept Note'!AN:AN) -> 0 | D31: =C31/SUM(C:C) -> #DIV/0! | E31: =SUMIF('Concept Note'!$AM:$AM,A31,'Concept Note'!$AO:$AO) -> 0 | F31: =E31/SUM(E:E) -> #DIV/0! | G31: =SUM(C31,E31) -> 0 | H31: =G31/SUM(G:G) -> #DIV/0!
A32: =Modules!C6 -> 29 | B32: =Modules!D6 -> Prevention - Adolescents and youth, in and out of school | C32: =SUMIF('Concept Note'!AM:AM,A32,'Concept Note'!AN:AN) -> 0 | D32: =C32/SUM(C:C) -> #DIV/0! | E32: =SUMIF('Concept Note'!$AM:$AM,A32,'Concept Note'!$AO:$AO) -> 0 | F32: =E32/SUM(E:E) -> #DIV/0! | G32: =SUM(C32,E32) -> 0 | H32: =G32/SUM(G:G) -> #DIV/0!
A33: =Modules!C31 -> 0 | B33: =Modules!D31 -> 0 | C33: =SUMIF('Concept Note'!AM:AM,A33,'Concept Note'!AN:AN) -> 0 | D33: =C33/SUM(C:C) -> #DIV/0! | E33: =SUMIF('Concept Note'!$AM:$AM,A33,'Concept Note'!$AO:$AO) -> 0 | F33: =E33/SUM(E:E) -> #DIV/0! | G33: =SUM(C33,E33) -> 0 | H33: =G33/SUM(G:G) -> #DIV/0!
A34: =Modules!C32 -> 0 | B34: =Modules!D32 -> 0 | C34: =SUMIF('Concept Note'!AM:AM,A34,'Concept Note'!AN:AN) -> 0 | D34: =C34/SUM(C:C) -> #DIV/0! | E34: =SUMIF('Concept Note'!$AM:$AM,A34,'Concept Note'!$AO:$AO) -> 0 | F34: =E34/SUM(E:E) -> #DIV/0! | G34: =SUM(C34,E34) -> 0 | H34: =G34/SUM(G:G) -> #DIV/0!
A35: =Modules!C33 -> 0 | B35: =Modules!D33 -> 0 | C35: =SUMIF('Concept Note'!AM:AM,A35,'Concept Note'!AN:AN) -> 0 | D35: =C35/SUM(C:C) -> #DIV/0! | E35: =SUMIF('Concept Note'!$AM:$AM,A35,'Concept Note'!$AO:$AO) -> 0 | F35: =E35/SUM(E:E) -> #DIV/0! | G35: =SUM(C35,E35) -> 0 | H35: =G35/SUM(G:G) -> #DIV/0!
A36: =Modules!C34 -> 0 | B36: =Modules!D34 -> 0 | C36: =SUMIF('Concept Note'!AM:AM,A36,'Concept Note'!AN:AN) -> 0 | D36: =C36/SUM(C:C) -> #DIV/0! | E36: =SUMIF('Concept Note'!$AM:$AM,A36,'Concept Note'!$AO:$AO) -> 0 | F36: =E36/SUM(E:E) -> #DIV/0! | G36: =SUM(C36,E36) -> 0 | H36: =G36/SUM(G:G) -> #DIV/0!
A37: =Modules!C35 -> 0 | B37: =Modules!D35 -> 0 | C37: =SUMIF('Concept Note'!AM:AM,A37,'Concept Note'!AN:AN) -> 0 | D37: =C37/SUM(C:C) -> #DIV/0! | E37: =SUMIF('Concept Note'!$AM:$AM,A37,'Concept Note'!$AO:$AO) -> 0 | F37: =E37/SUM(E:E) -> #DIV/0! | G37: =SUM(C37,E37) -> 0 | H37: =G37/SUM(G:G) -> #DIV/0!
A38: =Modules!C36 -> 0 | B38: =Modules!D36 -> 0 | C38: =SUMIF('Concept Note'!AM:AM,A38,'Concept Note'!AN:AN) -> 0 | D38: =C38/SUM(C:C) -> #DIV/0! | E38: =SUMIF('Concept Note'!$AM:$AM,A38,'Concept Note'!$AO:$AO) -> 0 | F38: =E38/SUM(E:E) -> #DIV/0! | G38: =SUM(C38,E38) -> 0 | H38: =G38/SUM(G:G) -> #DIV/0!
A39: =Modules!C37 -> 0 | B39: =Modules!D37 -> 0 | C39: =SUMIF('Concept Note'!AM:AM,A39,'Concept Note'!AN:AN) -> 0 | D39: =C39/SUM(C:C) -> #DIV/0! | E39: =SUMIF('Concept Note'!$AM:$AM,A39,'Concept Note'!$AO:$AO) -> 0 | F39: =E39/SUM(E:E) -> #DIV/0! | G39: =SUM(C39,E39) -> 0 | H39: =G39/SUM(G:G) -> #DIV/0!
A40: =Modules!C38 -> 0 | B40: =Modules!D38 -> 0 | C40: =SUMIF('Concept Note'!AM:AM,A40,'Concept Note'!AN:AN) -> 0 | D40: =C40/SUM(C:C) -> #DIV/0! | E40: =SUMIF('Concept Note'!$AM:$AM,A40,'Concept Note'!$AO:$AO) -> 0 | F40: =E40/SUM(E:E) -> #DIV/0! | G40: =SUM(C40,E40) -> 0 | H40: =G40/SUM(G:G) -> #DIV/0!
A41: =Modules!C39 -> 0 | B41: =Modules!D39 -> 0 | C41: =SUMIF('Concept Note'!AM:AM,A41,'Concept Note'!AN:AN) -> 0 | D41: =C41/SUM(C:C) -> #DIV/0! | E41: =SUMIF('Concept Note'!$AM:$AM,A41,'Concept Note'!$AO:$AO) -> 0 | F41: =E41/SUM(E:E) -> #DIV/0! | G41: =SUM(C41,E41) -> 0 | H41: =G41/SUM(G:G) -> #DIV/0!
A42: =Modules!C40 -> 0 | B42: =Modules!D40 -> 0 | C42: =SUMIF('Concept Note'!AM:AM,A42,'Concept Note'!AN:AN) -> 0 | D42: =C42/SUM(C:C) -> #DIV/0! | E42: =SUMIF('Concept Note'!$AM:$AM,A42,'Concept Note'!$AO:$AO) -> 0 | F42: =E42/SUM(E:E) -> #DIV/0! | G42: =SUM(C42,E42) -> 0 | H42: =G42/SUM(G:G) -> #DIV/0!
A43: =Modules!C41 -> 0 | B43: =Modules!D41 -> 0 | C43: =SUMIF('Concept Note'!AM:AM,A43,'Concept Note'!AN:AN) -> 0 | D43: =C43/SUM(C:C) -> #DIV/0! | E43: =SUMIF('Concept Note'!$AM:$AM,A43,'Concept Note'!$AO:$AO) -> 0 | F43: =E43/SUM(E:E) -> #DIV/0! | G43: =SUM(C43,E43) -> 0 | H43: =G43/SUM(G:G) -> #DIV/0!
A44: =Modules!C42 -> 0 | B44: =Modules!D42 -> 0 | C44: =SUMIF('Concept Note'!AM:AM,A44,'Concept Note'!AN:AN) -> 0 | D44: =C44/SUM(C:C) -> #DIV/0! | E44: =SUMIF('Concept Note'!$AM:$AM,A44,'Concept Note'!$AO:$AO) -> 0 | F44: =E44/SUM(E:E) -> #DIV/0! | G44: =SUM(C44,E44) -> 0 | H44: =G44/SUM(G:G) -> #DIV/0!
... A52: =Modules!C50 -> 0 | B52: =Modules!D50 -> 0 | C52: =SUMIF('Concept Note'!AM:AM,A52,'Concept Note'!AN:AN) -> 0 | D52: =C52/SUM(C:C) -> #DIV/0! | E52: =SUMIF('Concept Note'!$AM:$AM,A52,'Concept Note'!$AO:$AO) -> 0 | F52: =E52/SUM(E:E) -> #DIV/0! | G52: =SUM(C52,E52) -> 0 | H52: =G52/SUM(G:G) -> #DIV/0!
A57: =MATCH(TRUE,INDEX((Modules!I:I<>0),0),0) -> 2
A58: =MATCH(TRUE,INDEX((INDIRECT(ADDRESS(A57+1,9,1,TRUE,"Modules")):'Modules'!$I$50<>0),0),0) -> 6 | B58: =ADDRESS(A57+1,9,1,TRUE,"Modules") -> Modules!$I$3
B59: =VLOOKUP(86,Modules!$I$8:'Modules'!$I$50,1,FALSE) -> #N/A
...

Sheet Target assumptions - optional
A1: =Translations!$A$69 -> PLEASE PROVIDE TARGET ASSUMPTIONS FOR OUTPUT AND COVERAGE INDICATORS HERE
A2: =Translations!$A$70 -> It is not compulsory to provide target assumptions for the indicators included in the performance framework, however providing additional information on how targets were set may help to reach a common understanding and agreement between the Principal Recipient and the Global Fund Secretariat and speed up the negotiation process.

Sheet Cost assumptions - optional
A1: =Translations!A94 -> PLEASE PROVIDE COST ASSUMPTIONS FOR BUDGET HERE
A2: =Translations!A95 -> It is not compulsory to provide detailed cost assumptions for the budget, however providing additional information may help to reach a common understanding and agreement between the Principal Recipient and the Global Fund Secretariat and speed up the negotiation process.

Sheet Cmp
A1: CmpId | B1: CmpAcro | C1: Label | D1: Component en | E1: Component fr | F1: Component es | G1: Component ru
A2: 1 | B2: H | C2: =OFFSET(D2,0,LangOffset,1,1) -> HIV/AIDS | D2: HIV/AIDS | E2: VIH/SIDA | F2: VIH/SIDA | G2: ВИЧ/СПИД
A3: 2 | B3: T | C3: =OFFSET(D3,0,LangOffset,1,1) -> Tuberculosis | D3: Tuberculosis | E3: Tuberculose | F3: Tuberculosis | G3: Туберкулез
A4: 3 | B4: M | C4: =OFFSET(D4,0,LangOffset,1,1) -> Malaria | D4: Malaria | E4: Paludisme | F4: Malaria | G4: Малярия
A5: 6 | B5: S | C5: =OFFSET(D5,0,LangOffset,1,1) -> HSS | D5: HSS | E5: RSS | F5: FSS | G5: УСЗ

Sheet Modules
A1: CmpId | B1: CmpAcro | C1: ModId | D1: Label | E1: Module en | F1: Module fr | G1: Module es | H1: Module ru
A2: 1 | B2: H | C2: 1 | D2: =OFFSET(E2,0,LangOffset,1,1) -> Prevention - General population | E2: Prevention - General population | F2: Prévention - Population générale | G2: Prevención - Población general | H2: Профилактика для всего населения | I2: =IFERROR(MATCH(C2,'Concept Note'!AM:AM,0),"")
A3: 1 | B3: H | C3: 25 | D3: =OFFSET(E3,0,LangOffset,1,1) -> Prevention - MSM and TGs | E3: Prevention - MSM and TGs | F3: Prévention - HSM et transgenres | G3: Prevención - Hombres que tienen relaciones sexuales con hombres y personas transgénero | H3: Профилактика для МСМ и целевых групп населения
A4: 1 | B4: H | C4: 26 | D4: =OFFSET(E4,0,LangOffset,1,1) -> Prevention - Sex Workers and their clients | E4: Prevention - Sex Workers and their clients | F4: Prévention - Professionnels du sexe et leurs clients | G4: Prevención - Profesionales del sexo y sus clientes | H4: Профилактика для работников секс-бизнеса и их клиентов
A5: 1 | B5: H | C5: 27 | D5: =OFFSET(E5,0,LangOffset,1,1) -> Prevention - Harm-reduction programmes for injecting drug users (IDUs) and their partners | E5: Prevention - Harm-reduction programmes for injecting drug users (IDUs) and their partners | F5: Prévention - Programmes de réduction des méfaits pour les consommateurs de drogues par injection et leurs partenaires | G5: Prevención - Programas de reducción de daños para consumidores de drogas inyectables y sus parejas | H5: Профилактика для ПИН и их партнеров
A6: 1 | B6: H | C6: 29 | D6: =OFFSET(E6,0,LangOffset,1,1) -> Prevention - Adolescents and youth, in and out of school | E6: Prevention - Adolescents and youth, in and out of school | F6: Prévention - Adolescents et jeunes, scolarisés ou non | G6: Prevención - Adolescentes y jóvenes | H6: Профилактика для подростков и молодежи
A7: 1 | B7: H | C7: 28 | D7: =OFFSET(E7,0,LangOffset,1,1) -> Prevention - Other vulnerable populations (please specify) | E7: Prevention - Other vulnerable populations (please specify) | F7: Prévention - Autres populations vulnérables (préciser) | G7: Prevención - Otras poblaciones vulnerables | H7: Профилактика для других язвимых групп населения
A8: 1 | B8: H | C8: 2 | D8: =OFFSET(E8,0,LangOffset,1,1) -> PMTCT | E8: PMTCT | F8: Prévention de la transmission de la mère à l'enfant | G8: PTMI | H8: ППМР | I8: =IFERROR(MATCH(C8,'Concept Note'!AM:AM,0),"")
A9: 1 | B9: H | C9: 3 | D9: =OFFSET(E9,0,LangOffset,1,1) -> Treatment, care and support | E9: Treatment, care and support | F9: Traitement, prise en charge et soutien | G9: Tratamiento, atención y apoyo | H9: Лечение | I9: =IFERROR(MATCH(C9,'Concept Note'!AM:AM,0),"")
A10: 1 | B10: H | C10: 4 | D10: =OFFSET(E10,0,LangOffset,1,1) -> Monitoring and Evaluation | E10: Monitoring and Evaluation | F10: Suivi et évaluation | G10: Seguimiento y evaluación | H10: Мониторинг и оценка | I10: =IFERROR(MATCH(C10,'Concept Note'!AM:AM,0),"")
A11: 1 | B11: H | C11: 5 | D11: =OFFSET(E11,0,LangOffset,1,1) -> Program management | E11: Program management | F11: Gestion de programme | G11: Gestión de programas | H11: Управление программой | I11: =IFERROR(MATCH(C11,'Concept Note'!AM:AM,0),"")
A12: 2 | B12: T | C12: 6 | D12: =OFFSET(E12,0,LangOffset,1,1) -> DOTS-based package | E12: DOTS-based package | F12: Pack DOTS | G12: Paquete basado en DOTS | H12: Пакет мер на основе ДОТС | I12: =IFERROR(MATCH(C12,'Concept Note'!AM:AM,0),"")
A13: 2 | B13: T | C13: 7 | D13: =OFFSET(E13,0,LangOffset,1,1) -> TB/HIV package (in high TB/HIV burden countries or for high risk groups in all countries) | E13: TB/HIV package (in high TB/HIV burden countries or for high risk groups in all countries) | F13: Tuberculose/VIH (dans les pays lourdement touchés par la tuberculose et le VIH ou pour les groupes à haut risque dans tous les pays) | G13: Paquete para tuberculosis/VIH (en países con una carga elevada de tuberculosis/VIH o para grupos de alto riesgo de todos los países) | H13: Пакет мер по борьбе с ТБ/ВИЧ (для стран с высоким бременем ТБ/ВИЧ или для групп населения, подверженных высокому риску, во всех странах) | I13: =IFERROR(MATCH(C13,'Concept Note'!AM:AM,0),"")
A14: 2 | B14: T | C14: 8 | D14: =OFFSET(E14,0,LangOffset,1,1) -> MDR-TB package (in high MDR-TB burden countries or for high risk groups in all countries) | E14: MDR-TB package (in high MDR-TB burden countries or for high risk groups in all countries) | F14: Tuberculose multirésistante (dans les pays lourdement touchés par la tuberculose multirésistante ou pour les groupes à haut risque dans tous les pays) | G14: Paquete para TB-MR (en países con una carga elevada de tuberculosis multirresistente o para grupos de alto riesgo de todos los países) | H14: Пакет мер по борьбе с МЛУ-ТБ (для стран с высоким бременем МЛУ-ТБ или для групп населения, подверженных высокому риску, во всех странах) | I14: =IFERROR(MATCH(C14,'Concept Note'!AM:AM,0),"")
A15: 2 | B15: T | C15: 9 | D15: =OFFSET(E15,0,LangOffset,1,1) -> Human Rights | E15: Human Rights | F15: Droits de l'homme | G15: Derechos humanos | H15: Права человека | I15: =IFERROR(MATCH(C15,'Concept Note'!AM:AM,0),"")
A16: 2 | B16: T | C16: 10 | D16: =OFFSET(E16,0,LangOffset,1,1) -> Monitoring and Evaluation | E16: Monitoring and Evaluation | F16: Suivi et évaluation | G16: Seguimiento y evaluación | H16: Мониторинг и оценка | I16: =IFERROR(MATCH(C16,'Concept Note'!AM:AM,0),"")
A17: 2 | B17: T | C17: 11 | D17: =OFFSET(E17,0,LangOffset,1,1) -> Program Management | E17: Program Management | F17: Gestion de programme | G17: Gestión de programas | H17: Управление программой | I17: =IFERROR(MATCH(C17,'Concept Note'!AM:AM,0),"")
A18: 3 | B18: M | C18: 12 | D18: =OFFSET(E18,0,LangOffset,1,1) -> Vector Control (VC) | E18: Vector Control (VC) | F18: Lutte antivectorielle | G18: Control de vectores | H18: Борьба с переносчиками (БсП) | I18: =IFERROR(MATCH(C18,'Concept Note'!AM:AM,0),"")
A19: 3 | B19: M | C19: 13 | D19: =OFFSET(E19,0,LangOffset,1,1) -> Case Management (CM) | E19: Case Management (CM) | F19: Prise en charge | G19: Gestión de casos | H19: Ведение пациентов (ВП) | I19: =IFERROR(MATCH(C19,'Concept Note'!AM:AM,0),"")
... A30: 6 | B30: S | C30: 24 | D30: =OFFSET(E30,0,LangOffset,1,1) -> Program management (applicable for standalone HSS grants) | E30: Program management (applicable for standalone HSS grants) | F30: Gestion de programme (applicable dans le cadre des subventions indépendantes allouées au renforcement des systèmes de santé) | G30: Gestión de programas (aplicable para subvenciones de FSS independientes) | H30: Управление программой (относится к отдельным грантам по УЗС) | I30: =IFERROR(MATCH(C30,'Concept Note'!AM:AM,0),"")

Sheet Interven
A1: ModId | B1: CmpAcro | C1: Module | D1: IntId | E1: Label | F1: Intervention en | G1: Intervention fr | H1: Intervention es | I1: Intervention ru | J1: En: Scope and description of intervention package (includes human resources required under each intervention) | K1: Fr: Scope… | L1: Es: Scope…
A2: 1 | B2: H | D2: 1 | E2: =OFFSET(F2,0,LangOffset,1,1) -> Behavioural Change as part of programs for General population | F2: Behavioural Change as part of programs for General population | G2: Changement de comportement dans le cadre des programmes destinés à la population générale | H2: Cambio del comportamiento como parte de programas para la población general | I2: Распространение информации о поведенческих изменениях в рамках программ для всего населения
A3: 1 | B3: H | D3: 2 | E3: =OFFSET(F3,0,LangOffset,1,1) -> Condoms as part of programs for General population | F3: Condoms as part of programs for General population | G3: Préservatifs dans le cadre des programmes destinés à la population générale | H3: Preservativos como parte de programas para la población general | I3: Распространение презервативов в рамках программ для всего населения
A4: 1 | B4: H | D4: 3 | E4: =OFFSET(F4,0,LangOffset,1,1) -> Male Circumcision | F4: Male Circumcision | G4: Circoncision masculine | H4: Circuncisión masculina | I4: Мужское обрезание
A5: 1 | B5: H | D5: 4 | E5: =OFFSET(F5,0,LangOffset,1,1) -> HIV testing and Counselling as part of programs for General population | F5: HIV testing and Counselling as part of programs for General population | G5: Dépistage du VIH et conseil dans le cadre des programmes destinés à la population générale | H5: Pruebas de VIH y asesoramiento como parte de programas para la población general | I5: Тестирование на ВИЧ и консультирование по вопросам ВИЧ в рамках программ для всего населения
A6: 1 | B6: H | D6: 5 | E6: =OFFSET(F6,0,LangOffset,1,1) -> Diagnosis and treatment of STIs as part of programs for General population | F6: Diagnosis and treatment of STIs as part of programs for General population | G6: Diagnostic et traitement des infections sexuellement transmissibles dans le cadre des programmes destinés à la population générale | H6: Diagnóstico y tratamiento de ITS como parte de programas para la población general | I6: Диагностика и лечение ИППП в рамках программ для всего населения
A7: 1 | B7: H | D7: 6 | E7: =OFFSET(F7,0,LangOffset,1,1) -> Blood Safety | F7: Blood Safety | G7: Sécurité transfusionnelle | H7: Seguridad hematológica | I7: Безопасность крови
A8: 1 | B8: H | D8: 7 | E8: =OFFSET(F8,0,LangOffset,1,1) -> Orphan and Vulnerable Children (OVC) Package | F8: Orphan and Vulnerable Children (OVC) Package | G8: Orphelins et enfants vulnérables | H8: Paquete para huérfanos y niños vulnerables | I8: Мероприятия по поддержке сирот и уязвимых детей (СУД)
A9: 1 | B9: H | D9: 8 | E9: =OFFSET(F9,0,LangOffset,1,1) -> Community Systems Strengthening -Prevention General Population | F9: Community Systems Strengthening -Prevention General Population | G9: Renforcement des systèmes communautaires : prévention auprès de la population générale | H9: Fortalecimiento de los sistemas comunitarios - Prevención para la población general | I9: Укрепление систем сообществ — профилактика для всего населения
A10: 1 | B10: H | D10: 9 | E10: =OFFSET(F10,0,LangOffset,1,1) -> Removing human rights barriers to accessing services - Prevention General Population | F10: Removing human rights barriers to accessing services - Prevention General Population | G10: Suppression des obstacles aux droits de l'homme afin d'accéder aux services : prévention auprès de la population générale | H10: Supresión de obstáculos relacionados con los derechos humanos para el acceso a servicios - Prevención para la población general | I10: Устранение факторов, имеющих отношение к правам человека и препятствующих доступу к услугам — профилактика всего населения
A11: 1 | B11: H | D11: 10 | E11: =OFFSET(F11,0,LangOffset,1,1) -> RMNCH linkages and Gender Based Violence (GBV) | F11: RMNCH linkages and Gender Based Violence (GBV) | G11: Liens avec la santé génésique, maternelle, néonatale et infantile et violence sexiste | H11: Vínculos entre la salud reproductiva, materna, neonatal e infantil y la violencia de género | I11: Репродуктивное здоровье, здоровье матерей, новорожденных и детей и гендерное насилие
A12: 1 | B12: H | D12: 11 | E12: =OFFSET(F12,0,LangOffset,1,1) -> Other interventions for General Populations - please specify | F12: Other interventions for General Populations - please specify | G12: Autres interventions réalisées auprès de la population générale : veuillez préciser | H12: Otras intervenciones para la población general (especificar) | I12: Другие мероприятия для всего населения (укажите)
A13: 25 | B13: H | D13: 12 | E13: =OFFSET(F13,0,LangOffset,1,1) -> Behavioural Change as part of Programs for MSM and TGs | F13: Behavioural Change as part of Programs for MSM and TGs | G13: Changement de comportement dans le cadre des programmes destinés aux hommes ayant des rapports sexuels avec des hommes et aux transgenres | H13: Cambio de comportamiento como parte de programas para hombres que tienen relaciones sexuales con hombres y personas transgénero | I13: Распространение информации о поведенческих изменениях в рамках программ для МСМ и целевых групп населения
... A51: 29 | B51: H | D51: 50 | E51: =OFFSET(F51,0,LangOffset,1,1) -> Removing human rights barriers to accessing services - Prevention adolescents and youth | F51: Removing human rights barriers to accessing services - Prevention adolescents and youth | G51: Suppression des obstacles aux droits de l'homme afin d'accéder aux services : prévention auprès des jeunes et des adolescents | H51: Supresión de obstáculos relacionados con los derechos humanos para el acceso a servicios - Prevención para adolescentes y jóvenes | I51: Устранение факторов, имеющих отношение к правам человека и препятствующих доступу к услугам — профилактика для подростков и молодежи
A52: 2 | B52: H | C52: PMTCT | D52: 51 | E52: =OFFSET(F52,0,LangOffset,1,1) -> Prong 1: Primary prevention of HIV infection among women of childbearing age | F52: Prong 1: Primary prevention of HIV infection among women of childbearing age | G52: Volet 1 : prévention primaire de l'infection à VIH chez les femmes en âge de procréer | H52: Flanco 1: Prevención primaria de la infección por el VIH en mujeres en edad fértil | I52: Направление 1: первичная профилактика ВИЧ-инфицирования среди женщин детородного возраста
A53: 2 | B53: H | C53: PMTCT | D53: 52 | E53: =OFFSET(F53,0,LangOffset,1,1) -> Prong 2: Preventing unintended pregnancies among women living with HIV | F53: Prong 2: Preventing unintended pregnancies among women living with HIV | G53: Volet 2 : prévention des grossesses non désirées chez les femmes vivant avec le VIH | H53: Flanco 2: Prevención de embarazos no deseados entre mujeres que viven con el VIH | I53: Направление 2: предупреждение нежелательной беременности среди женщин, живущих с ВИЧ
A54: 2 | B54: H | C54: PMTCT | D54: 53 | E54: =OFFSET(F54,0,LangOffset,1,1) -> Prong 3: Preventing vertical HIV transmission | F54: Prong 3: Preventing vertical HIV transmission | G54: Volet 3 : prévention de la transmission verticale du VIH | H54: Flanco 3: Prevención de la transmisión vertical del VIH | I54: Направление 3: профилактика вертикальной передачи ВИЧ-инфекции
A55: 2 | B55: H | C55: PMTCT | D55: 54 | E55: =OFFSET(F55,0,LangOffset,1,1) -> Prong 4: Treatment, care and support to mothers living with HIV and their children and families | F55: Prong 4: Treatment, care and support to mothers living with HIV and their children and families | G55: Volet 4 : traitement, soins et prise en charge pour les mères vivant avec le VIH, ainsi que leurs enfants et familles | H55: Flanco 4: Tratamiento, atención y apoyo para madres que viven con el VIH, así como para sus hijos y familias | I55: Направление 4: надлежащее лечение, уход и поддержка для ВИЧ-инфицированных матерей, их детей и близких
A56: 2 | B56: H | C56: PMTCT | D56: 55 | E56: =OFFSET(F56,0,LangOffset,1,1) -> Community Systems Strengthening - PMTCT | F56: Community Systems Strengthening - PMTCT | G56: Renforcement des systèmes communautaires : prévention de la transmission de la mère à l'enfant | H56: Fortalecimiento de los sistemas comunitarios - PTMI | I56: Укрепление систем сообществ — ППМР
A57: 2 | B57: H | C57: PMTCT | D57: 56 | E57: =OFFSET(F57,0,LangOffset,1,1) -> Removing human rights barriers to accessing services - PMTCT | F57: Removing human rights barriers to accessing services - PMTCT | G57: Suppression des obstacles aux droits de l'homme afin d'accéder aux services : prévention de la transmission de la mère à l'enfant | H57: Supresión de obstáculos relacionados con los derechos humanos para el acceso a servicios - PTMI | I57: Устранение факторов, имеющих отношение к правам человека и препятствующих доступу к услугам — ППМР
A58: 2 | B58: H | C58: PMTCT | D58: 57 | E58: =OFFSET(F58,0,LangOffset,1,1) -> Other interventions for PMTCT- Please specify | F58: Other interventions for PMTCT- Please specify | G58: Autres interventions réalisées pour prévenir la transmission de la mère à l'enfant : veuillez préciser | H58: Otras intervenciones para PTMI (especificar) | I58: Другие мероприятия в целях ППМР (укажите)
A59: 3 | B59: H | C59: Treatment | D59: 58 | E59: =OFFSET(F59,0,LangOffset,1,1) -> Pre-ART Care | F59: Pre-ART Care | G59: Soins préalables au traitement antirétroviral | H59: Pretratamiento antirretroviral | I59: Лечение до начала АРТ
A60: 3 | B60: H | C60: Treatment | D60: 59 | E60: =OFFSET(F60,0,LangOffset,1,1) -> First-line ART – adults | F60: First-line ART – adults | G60: Traitement antirétroviral de première intention : adultes | H60: Tratamiento antirretroviral de primera línea – adultos | I60: АРТ первой линии для взрослых
A61: 3 | B61: H | C61: Treatment | D61: 60 | E61: =OFFSET(F61,0,LangOffset,1,1) -> Second-line ART – adults | F61: Second-line ART – adults | G61: Traitement antirétroviral de deuxième intention : adultes | H61: Tratamiento antirretroviral de segunda línea – adultos | I61: АРТ второй линии для взрослых
A62: 3 | B62: H | C62: Treatment | D62: 61 | E62: =OFFSET(F62,0,LangOffset,1,1) -> Adult multidrug ART after second-line treatment failure | F62: Adult multidrug ART after second-line treatment failure | G62: Multithérapie antirétrovirale chez les adultes après échec du traitement de deuxième intention | H62: Tratamiento antirretroviral multimedicamentoso para adultos tras fracaso en el tratamiento de segunda línea | I62: Многокомпонентная АРТ для взрослых в случае неблагоприятного исхода терапии препаратами первой линии
A63: 3 | B63: H | C63: Treatment | D63: 62 | E63: =OFFSET(F63,0,LangOffset,1,1) -> First-line ART – paediatric | F63: First-line ART – paediatric | G63: Traitement antirétroviral de première intention : enfants | H63: Tratamiento antirretroviral de primera línea – pediátrico | I63: АРТ первой линии для детей
... A122: 11 | B122: T | C122: Program Management | D122: 176 | E122: =OFFSET(F122,0,LangOffset,1,1) -> Other | F122: Other | G122: Autre | H122: Otro | I122: другой
A123: 12 | B123: M | C123: Vector Control (VC) | D123: 114 | E123: =OFFSET(F123,0,LangOffset,1,1) -> Long-lasting Insecticide-treated Nets (LLIN) - Mass Campaign | F123: Long-lasting Insecticide-treated Nets (LLIN) - Mass Campaign | G123: Moustiquaires imprégnées d'insecticide de longue durée : campagne à grande échelle | H123: Mosquiteros tratados con insecticida de larga duración (MILD) – Campaña a gran escala | I123: Сетки, обработанные инсектицидом длительного действия (СОИДД) – массовая кампания | J123: Includes activities related to planning and implementation of mass LLIN distributions, whether targeted to specific population groups or for universal coverage. It includes coordination, planning and budgeting, procurement, logistics, communication, implementation, training, etc. | K123: Comprend les activités liées à la planification et à la mise en œuvre de campagnes de distribution de masse de moustiquaires imprégnées d'insecticide de longue durée, qu'elles ciblent des groupes de population spécifiques ou qu'elles visent une couverture universelle. Comprend la coordination, la planification et la budgétisation, les achats, la logistique, la communication, la mise en œuvre, les formations, etc. | L123: Incluye actividades relacionadas con la planificación y ejecución de campañas de distribución de MILD masivas, ya sean dirigidas a grupos de población específicos o de cobertura universal. Aquí se incluyen la coordinación, planificación y creación de presupuestos, adquisición, logística, comunicación, ejecución, formación, etc.
A124: 12 | B124: M | C124: Vector Control (VC) | D124: 115 | E124: =OFFSET(F124,0,LangOffset,1,1) -> Long-lasting Insecticide-treated Nets (LLIN) - Routine Distribution | F124: Long-lasting Insecticide-treated Nets (LLIN) - Routine Distribution | G124: Moustiquaires imprégnées d'insecticide de longue durée : distribution régulière | H124: Mosquiteros tratados con insecticida de larga duración (MILD) – Distribución rutinaria | I124: Сетки, обработанные инсектицидом длительного действия (СОИДД) – регулярное распространение | J124: This intervention encompasses efforts to start, strengthen or scale up continuous delivery of LLINs through antenatal care (ANC) clinics, the Expanded Programme on Immunization (EPI), or other routine services at public and private health facilities, to sustain high LLIN coverage. It includes activities related to- Coordination and Planning; Training; Logistics; Communication; Supervision, etc. | K124: Cette intervention comprend les mesures visant à commencer, renforcer ou intensifier la distribution continue de moustiquaires imprégnées d’insecticide longue durée à travers les centres de consultations prénatales, le Programme élargi de vaccination (PEV) ou tout autre service courant fourni dans des établissements de santé publics et privés, afin de maintenir une forte couverture en moustiquaires imprégnées d'insecticide de longue durée. Comprend les activités liées à la coordination et à la planification, aux formations, à la logistique, à la communication, à la supervision, etc. | L124: Esta intervención entraña esfuerzos destinados a iniciar, fomentar o ampliar la entrega continua de MILD a través de clínicas de atención prenatal, el Programa Ampliado de Inmunización u otros servicios rutinarios en centros de salud públicos y privados con el fin de mantener una cobertura de MILD alta. Incluye actividades relacionadas con la coordinación y planificación, formación, logística, comunicación, supervisión, etc.
A125: 12 | B125: M | C125: Vector Control (VC) | D125: 116 | E125: =OFFSET(F125,0,LangOffset,1,1) -> Indoor Residual Spraying (IRS) | F125: Indoor Residual Spraying (IRS) | G125: Pulvérisation intradomiciliaire d’insecticide à effet rémanent | H125: Fumigación de interiores con insecticidas de acción residual (IRS) | I125: Обработка помещений инсектицидами длительного действия | J125: It includes planning and implementation of Indoor Residual Spraying campaigns as well as enumeration of households to be sprayed. Activities include procurement of insecticides, equipment, other commodities, IEC material for IRS campaigns, trainings, etc. | K125: Comprend la planification et la mise en œuvre de campagnes de pulvérisation intradomiciliaire d'insecticide à effet rémanent ainsi que le recensement des foyers à traiter. Comprend les activités liées à l'approvisionnement en insecticides, en équipements et autres produits de base, les supports IEC pour les campagnes de pulvérisation intradomiciliaire d'insecticide à effet rémanent, les formations, etc. | L125: Incluye la planificación y puesta en práctica de campañas de fumigación de interiores con insecticidas de acción residual, así como la enumeración de hogares por fumigar. Entre las actividades, se incluyen la adquisición de insecticidas, equipamiento, otros productos, material de IEC para campañas de IRS, formación, etc.
