Workbook

Sheet All Contract Holders
A1: All Contract Holders - All Functional Areas | G1: Last Updated November-05-2014
A2: Note: VETS GWAC Industry Partners were required to re-represent their size status prior to the February 2012 option period and are required to re-represent in accordance with FAR 52.219-28. Size is represented in column N. Only those Industry Partners shown as small may be awarded task orders after February 1, 2012.
A3: Small Business Prime Contractors
A4: Contract Numbers | B4: Vendor Name | C4: Vendor Address | D4: City | E4: State | F4: Zip Code | G4: Vendor Contact Name | H4: Email Address | I4: Website | J4: Phone | K4: Fax | L4: FA1 | M4: FA2 | N4: Small Business
A5: GS-06F-0508Z | B5: Advanced Systems, Inc. | C5: 8280 Willow Oaks Corporate Drive, Suite LL113 | D5: Fairfax | E5: VA | F5: 22031 | G5: Robert A. Walker | H5: rwalker@AdvSystems.com, ASI@AdvSystems.com | I5: www.advsystems.com | J5: (703) 218-3360 x206 | K5: (703) 218-3644 | L5: x | M5: x | N5: x
A6: GS-06F-0524Z | B6: American Veterans, LLC | C6: 2 Brittany Lane | D6: Stafford | E6: VA | F6: 22554 | G6: Vic Blanco | H6: vetsgwac@sbgts.com, vblanco@sbgts.com | I6: www.americanveteransllc.com | J6: (540) 658-1311 | K6: (540) 658-1359 | M6: x | N6: x
A7: GS-06F-0509Z | B7: C Watkins & Associates, INC | C7: 23 Griswold CT | D7: Sterling | E7: VA | F7: 20165 | G7: Carl A. Watkins, Danny Watkins | H7: carl@cwivetsteam.com, danny@cwivetsteam.com | I7: www.cwatkinsinc.com www.cwivetsteam.com | J7: (703) 444-1625 | K7: (703) 236-5046 | L7: x | M7: x | N7: x
A8: GS-06F-0510Z | B8: C2 Solutions Group, Inc. | C8: 1881 Campus Commons Drive, Suite 301 | D8: Reston | E8: VA | F8: 20191 | G8: Brian Newell | H8: vets@c2sginc.com | I8: www.c2sginc.com | J8: (571) 210-2390 | K8: (703) 853-7927 | L8: x | M8: x | N8: x
A9: GS-06F-0541Z | B9: Centuria Corporation | C9: 1851 Alexander Bell Drive, Suite 440 | D9: Reston | E9: VA | F9: 20190 | G9: Marjan Hekmat, Kevin Burke | H9: VETS@centuria.com | I9: www.centuria.com | J9: (571) 313-4026 | K9: (703) 435-9974 | L9: x | N9: x
A10: GS-06F-0512Z | B10: Client Server Software Solutions dba Constellation West | C10: 3906 Raynor Parkway, STE 201 | D10: Bellevue | E10: NE | F10: 68123 | G10: Steve Johns | H10: VETSGWAC@constellationwest.com | I10: www.csss.net | J10: (402) 502-4158 | K10: (402) 393-1825 | L10: x | M10: x | N10: x
A11: GS-06F-0513Z | B11: DV United, LLC | C11: 7343 Waverly Drive | D11: Warrenton | E11: VA | F11: 20186 | G11: Thomas Dalton, Edgar Lewin | H11: thomas.dalton@tdginc.com, edgar.lewin@alyngroup.com | I11: www.dvunited.com | J11: (540) 349-1939 | K11: (540) 347-2295 | L11: x | M11: x | N11: x
A12: GS-06F-0527Z | B12: Ian, Evan & Alexander Corporation | C12: 20098 Ashbrook Place, Suite 260 | D12: Ashburn | E12: VA | F12: 20147 | G12: John E. Cochran | H12: jcochran@iea-corp.com, jwynn@iea-corp.com | I12: www.iea-corp.com | J12: (703) 682-4575 | K12: (703) 935-1063 | L12: x | M12: x | N12: x
A13: GS-06F-0529Z | B13: Innovative Management Concepts | C13: 21400 Ridgetop Circle, Suite 210 | D13: Dulles | E13: VA | F13: 20166 | G13: Robert J. Might, Ph.D., Mike Metz | H13: rmight@imcva.com, mmetz@imcva.com | I13: www.imcva.com | J13: (703) 318-8044 x209 | K13: (703) 318-8740 | L13: x | M13: x | N13: x
A14: GS-06F-0531Z | B14: INTECON, LLC | C14: 1325 Aeroplaza Drive, Ste 105 | D14: Colorado Springs | E14: CO | F14: 80916 | G14: John Benjamin, Alan Omo | H14: vetsgwac@inteconusa.com | I14: www.inteconusa.com | J14: (719) 597-2275 | K14: (719) 597-7120 | L14: x | M14: x | N14: x
A15: GS-06F-0534Z | B15: Kingfisher Systems, Inc. | C15: 3110 Fairview Park Drive, Ste 1250 | D15: Falls Church | E15: VA | F15: 22042 | G15: Sonya Ford | H15: VETSGWAC@kingfishersys.com | I15: www.kingfishersys.com | J15: (703) 820-7970 | K15: (703) 820-7976 | L15: x | M15: x | N15: x
A16: GS-06F-0538Z | B16: KT Consulting | C16: 2327 South Hardy Drive | D16: Tempe | E16: AZ | F16: 85282 | G16: Kevin Terrell | H16: kterrell@ktc-ops.com | I16: www.ktc-vets.com | J16: (480) 538-2668 | K16: (480) 538-2686 | L16: x | M16: x | N16: x
A17: GS-06F-0544Z | B17: Milvets System Technology, Inc. | C17: 11825 High Tech Ave., Suite 150 | D17: Orlando | E17: FL | F17: 32817 | G17: Bob Daniels, Robin Nickerson | H17: vetsgwac@milvets.com | I17: www.milvets.com | J17: (301) 731-9130 ext.35 | K17: (301) 731-4773 | L17: x | M17: x | N17: x
A18: GS-06F-0545Z | B18: Advanced Facility Management Services, Inc. | C18: 60 South Washington St. | D18: Greencastle | E18: PA | F18: 17225 | G18: Kevin McCracken | H18: afmsvetsgwac@afmsinc.com | I18: http://www.afmsvetsgwac.com | J18: (717) 458-8786 | K18: (717) 458-8947 | L18: x | M18: x | N18: x
A19: GS-06F-0539Z | B19: OBXtek, Inc. | C19: 8300 Boone Blvd, Suite 800 | D19: Vienna | E19: VA | F19: 22182 | G19: Ed Jesson, Jasmine Feeney | H19: vets@obxtek.com | I19: www.obxtek.com | J19: (703) 373-3736 (571) 395-4542 | K19: (866) 633-9157 | L19: x | N19: x
A20: GS-06F-0551Z | B20: OBXtek, Inc. | C20: 8300 Boone Blvd, Suite 800 | D20: Vienna | E20: VA | F20: 22182 | G20: Ed Jesson, Jasmine Feeney | H20: vets@obxtek.com | I20: www.obxtek.com | J20: (703) 373-3736 (571) 395-4542 | K20: (866) 633-9157 | M20: x | N20: x
A21: GS-06F-0546Z | B21: Penobscot Bay Media LLC | C21: 58 Dodge Mountain Rd | D21: Rockland | E21: ME | F21: 04841 | G21: Ann S. Yahner | H21: vetsgwac@penbaymedia.com | I21: www.penbaymedia.com | J21: (207) 596-6130 | K21: (207) 596-6130 | L21: x | M21: x | N21: x
A22: GS-06F-0517Z | B22: Pro-Sphere Tek, Inc. | C22: 415 North Lee Street | D22: Alexandria | E22: VA | F22: 22314 | G22: Tom Kenny | H22: rblevins@pro-spheretek.com, TKenny@pro-spheretek.com | I22: www.pro-spheretek.com | J22: (571) 227-9700 | K22: (571) 227-9701 | L22: x | N22: x
A23: GS-06F-0549Z | B23: Standard Communications, INC | C23: 5402 Leeds Manor Road, Fauquier County | D23: Hume | E23: VA | F23: 22639 | G23: John P. Moliere | H23: john.moliere@stdcomm.com, bob.waizenegger@stdcomm.com | I23: www.stdcomm.com | J23: (540) 364-3688 | K23: (703) 4261956 | L23: x | M23: x | N23: x
A24: GS-06F-0528Z | B24: Veteran Corps of America | C24: 10300 Eaton Place, Suite 340 | D24: Fairfax | E24: VA | F24: 22030 | G24: John R. Wheeler | H24: gsavets@veterancorps.com | I24: www.veterancorps.com | J24: (703) 691-8387 | K24: (703) 691-8385 | L24: x | M24: x | N24: x
A25: GS-06F-0530Z | B25: Veteran Engineering & Technology, LLC | C25: 5475 Mark Dabling Blvd, Suite 300 | D25: Colorado Springs | E25: CO | F25: 80918 | G25: Craig Newmaker, Norm Andersson | H25: engineering@vetengineering.com | I25: www.vetengineering.com | J25: (719) 623-3600 | K25: (877) 870-9002 | L25: x | M25: x | N25: x
A26: GS-06F-0532Z | B26: Veterans Enterprise Technology Solutions, INC | C26: 2057 Woodford Road, STE 200 | D26: Vienna | E26: VA | F26: 22182 | G26: James H. Moody | H26: jmoody@vets-inc.com, HEdwards@vets-inc.com | I26: www.vets-inc.com | J26: (434) 374-5899 | K26: (866) 320-0911 | L26: x | M26: x | N26: x
A27: GS-06F-0533Z | B27: Vetsamerica Business Consulting, INC | C27: 8300 Greensboro Drive, Suite 800 | D27: McLean | E27: VA | F27: 22102 | G27: John Collins | H27: johncollins@vetsamerica.us | I27: www.vetsamerica.us | J27: (843) 238-2517 | K27: (843) 238-8426 | L27: x | M27: x | N27: x
A30: Large Strategic Partner Contractors
A31: Contract Numbers | B31: Vendor Name | C31: Vendor Address | D31: City | E31: State | F31: Zip Code | G31: Vendor Contact Name | H31: Email Address | I31: Website | J31: Phone | K31: Fax | L31: FA1 | M31: FA2
A32: GS-06F-0511Z | B32: Catapult Technology, LTD | C32: 7500 Old Georgetown Road, 11th Floor | D32: Bethesda | E32: MD | F32: 20814-6198 | G32: Jane Green | H32: gsavets@catapulttechnology.com | I32: www.catapulttechnology.com | J32: (240) 482-2136 | K32: (888) 338-1391 | L32: x | M32: x
A33: GS-06F-0525Z | B33: Council for Logistics Research, Inc. | C33: 1550 Crystal Drive, Suite 500 | D33: Arlington | E33: VA | F33: 22202 | G33: Maureen Soldano | H33: vets@clrexec.com, msoldano@clrexec.com | I33: www.clrexec.com | J33: (703) 412-1563 | K33: (703) 412-1564 | M33: x
A34: GS-06F-0514Z | B34: Engineering Services Network, Inc. | C34: 2450 Crystal Drive, Suite 1015 | D34: Arlington | E34: VA | F34: 22202 | G34: Michelle "Shelly" Smith | H34: esncontracts@esncc.com | I34: www.esncc.com | J34: (703) 412-3640 | K34: (703) 412-3643 | L34: x | M34: x
A35: GS-06F-0518Z | B35: HMS Technologies, INC | C35: One Discovery Place | D35: Martinsburg | E35: WV | F35: 25403 | G35: Roy Jones, Harry Siegel | H35: roy.jones@hmstech.com, HSiegel@hmstech.com | I35: www.hmstech.com | J35: (304) 596-5583 | K35: (304) 596-5589 | L35: x
A36: GS-06F-0519Z | B36: Information Innovators, Inc | C36: 7400 Fullerton Road, STE 210 | D36: Springfield | E36: VA | F36: 22153 | G36: Mark Harrington | H36: vets@iiinfo.com | I36: www.iiinfo.com | J36: (703) 665-4256 | K36: (703) 440-1332 | L36: x
A37: GS-06F-0543Z | B37: Metters Industries, INC | C37: 8200 Greensboro Drive, STE 500 | D37: McLean | E37: VA | F37: 22102 | G37: Will Dolan, Bob LeFebvre | H37: MI-GSA-VETSGWAC@metters.com, Bob.Lefebvre@metters.com | I37: www.metters.com | J37: (703) 821-3300 ext 709 | K37: (703) 821-3996 | L37: x | M37: x
A38: GS-06F-0547Z | B38: Professional Solutions, LLC | C38: 5500 Cherokee Avenue, Suite 400 | D38: Alexandria | E38: VA | F38: 22312 | G38: Ms. Ari Abraham | H38: VETsGWAC@prosol1.com, AAbraham@prosol1.com | I38: www.prosol1.com | J38: (703) 823-2696 x101 | K38: (703) 823-2698 | L38: x | M38: x
A39: GS-06F-0548Z | B39: Systems Made Simple, INC | C39: One Northern Concourse | D39: Syracuse | E39: NY | F39: 13212 | G39: Ron Fishbeck | H39: ron.fishbeck@systemsmadesimple.com, vetsgwac@teamsms.net | I39: https://www.teamsms.net/GWAC | J39: (315) 455-3200 x26 (800) 893-9883 x26 | K39: (315) 455-3120 | L39: x | M39: x
A40: GS-06F-0535Z | B40: Vision Technologies, Inc | C40: 530 J McCormick Drive | D40: Glen Burnie | E40: MD | F40: 21061 | G40: Michael Sandberg | H40: vetsgwac@visiontech.biz | I40: www.vets-gsa.com | J40: (410) 424-2183 x243 (703) 598-7990 | K40: (410) 424-2208 | L40: x | M40: x

Sheet FA1 Contract Holders
A1: Functional Area 1 - Systems Operations & Maintenance Including Security
A2: Note: VETS GWAC Industry Partners were required to re-represent their size status prior to the February 2012 option period and are required to re-represent in accordance with FAR 52.219-28. Size is represented in column N. Only those Industry Partners shown as small may be awarded task orders after February 1, 2012.
A3: Small Business Prime Contractors
A4: Contract Numbers | B4: Vendor Name | C4: Vendor Address | D4: City | E4: State | F4: Zip Code | G4: Vendor Contact Name | H4: Email Address | J4: Phone | K4: Fax | L4: FA1 | M4: FA2 | N4: Small Business
A5: GS-06F-0508Z | B5: =VLOOKUP($A5,'All Contract Holders'!$A$5:$K$40,2,FALSE) -> Advanced Systems, Inc. | C5: =VLOOKUP($A5,'All Contract Holders'!$A$5:$K$40,3,FALSE) -> 8280 Willow Oaks Corporate Drive, Suite LL113 | D5: =VLOOKUP($A5,'All Contract Holders'!$A$5:$K$40,4,FALSE) -> Fairfax | E5: =VLOOKUP($A5,'All Contract Holders'!$A$5:$K$40,5,FALSE) -> VA | F5: =VLOOKUP($A5,'All Contract Holders'!$A$5:$K$40,6,FALSE) -> 22031 | G5: =VLOOKUP($A5,'All Contract Holders'!$A$5:$K$40,7,FALSE) -> Robert A. Walker | H5: =VLOOKUP($A5,'All Contract Holders'!$A$5:$K$40,8,FALSE) -> rwalker@AdvSystems.com, ASI@AdvSystems.com | I5: =VLOOKUP($A5,'All Contract Holders'!$A$5:$K$40,9,FALSE) -> www.advsystems.com | J5: =VLOOKUP($A5,'All Contract Holders'!$A$5:$K$40,10,FALSE) -> (703) 218-3360 x206 | K5: =VLOOKUP($A5,'All Contract Holders'!$A$5:$K$40,11,FALSE) -> (703) 218-3644 | L5: x | M5: x | N5: x
A6: GS-06F-0509Z | B6: =VLOOKUP($A6,'All Contract Holders'!$A$5:$K$40,2,FALSE) -> C Watkins & Associates, INC | C6: =VLOOKUP($A6,'All Contract Holders'!$A$5:$K$40,3,FALSE) -> 23 Griswold CT | D6: =VLOOKUP($A6,'All Contract Holders'!$A$5:$K$40,4,FALSE) -> Sterling | E6: =VLOOKUP($A6,'All Contract Holders'!$A$5:$K$40,5,FALSE) -> VA | F6: =VLOOKUP($A6,'All Contract Holders'!$A$5:$K$40,6,FALSE) -> 20165 | G6: =VLOOKUP($A6,'All Contract Holders'!$A$5:$K$40,7,FALSE) -> Carl A. Watkins, Danny Watkins | H6: =VLOOKUP($A6,'All Contract Holders'!$A$5:$K$40,8,FALSE) -> carl@cwivetsteam.com, danny@cwivetsteam.com | I6: =VLOOKUP($A6,'All Contract Holders'!$A$5:$K$40,9,FALSE) -> www.cwatkinsinc.com www.cwivetsteam.com | J6: =VLOOKUP($A6,'All Contract Holders'!$A$5:$K$40,10,FALSE) -> (703) 444-1625 | K6: =VLOOKUP($A6,'All Contract Holders'!$A$5:$K$40,11,FALSE) -> (703) 236-5046 | L6: x | M6: x | N6: x
A7: GS-06F-0510Z | B7: =VLOOKUP($A7,'All Contract Holders'!$A$5:$K$40,2,FALSE) -> C2 Solutions Group, Inc. | C7: =VLOOKUP($A7,'All Contract Holders'!$A$5:$K$40,3,FALSE) -> 1881 Campus Commons Drive, Suite 301 | D7: =VLOOKUP($A7,'All Contract Holders'!$A$5:$K$40,4,FALSE) -> Reston | E7: =VLOOKUP($A7,'All Contract Holders'!$A$5:$K$40,5,FALSE) -> VA | F7: =VLOOKUP($A7,'All Contract Holders'!$A$5:$K$40,6,FALSE) -> 20191 | G7: =VLOOKUP($A7,'All Contract Holders'!$A$5:$K$40,7,FALSE) -> Brian Newell | H7: =VLOOKUP($A7,'All Contract Holders'!$A$5:$K$40,8,FALSE) -> vets@c2sginc.com | I7: =VLOOKUP($A7,'All Contract Holders'!$A$5:$K$40,9,FALSE) -> www.c2sginc.com | J7: =VLOOKUP($A7,'All Contract Holders'!$A$5:$K$40,10,FALSE) -> (571) 210-2390 | K7: =VLOOKUP($A7,'All Contract Holders'!$A$5:$K$40,11,FALSE) -> (703) 853-7927 | L7: x | M7: x | N7: x
A8: GS-06F-0541Z | B8: =VLOOKUP($A8,'All Contract Holders'!$A$5:$K$40,2,FALSE) -> Centuria Corporation | C8: =VLOOKUP($A8,'All Contract Holders'!$A$5:$K$40,3,FALSE) -> 1851 Alexander Bell Drive, Suite 440 | D8: =VLOOKUP($A8,'All Contract Holders'!$A$5:$K$40,4,FALSE) -> Reston | E8: =VLOOKUP($A8,'All Contract Holders'!$A$5:$K$40,5,FALSE) -> VA | F8: =VLOOKUP($A8,'All Contract Holders'!$A$5:$K$40,6,FALSE) -> 20190 | G8: =VLOOKUP($A8,'All Contract Holders'!$A$5:$K$40,7,FALSE) -> Marjan Hekmat, Kevin Burke | H8: =VLOOKUP($A8,'All Contract Holders'!$A$5:$K$40,8,FALSE) -> VETS@centuria.com | I8: =VLOOKUP($A8,'All Contract Holders'!$A$5:$K$40,9,FALSE) -> www.centuria.com | J8: =VLOOKUP($A8,'All Contract Holders'!$A$5:$K$40,10,FALSE) -> (571) 313-4026 | K8: =VLOOKUP($A8,'All Contract Holders'!$A$5:$K$40,11,FALSE) -> (703) 435-9974 | L8: x | N8: x
A9: GS-06F-0512Z | B9: =VLOOKUP($A9,'All Contract Holders'!$A$5:$K$40,2,FALSE) -> Client Server Software Solutions dba Constellation West | C9: =VLOOKUP($A9,'All Contract Holders'!$A$5:$K$40,3,FALSE) -> 3906 Raynor Parkway, STE 201 | D9: =VLOOKUP($A9,'All Contract Holders'!$A$5:$K$40,4,FALSE) -> Bellevue | E9: =VLOOKUP($A9,'All Contract Holders'!$A$5:$K$40,5,FALSE) -> NE | F9: =VLOOKUP($A9,'All Contract Holders'!$A$5:$K$40,6,FALSE) -> 68123 | G9: =VLOOKUP($A9,'All Contract Holders'!$A$5:$K$40,7,FALSE) -> Steve Johns | H9: =VLOOKUP($A9,'All Contract Holders'!$A$5:$K$40,8,FALSE) -> VETSGWAC@constellationwest.com | I9: =VLOOKUP($A9,'All Contract Holders'!$A$5:$K$40,9,FALSE) -> www.csss.net | J9: =VLOOKUP($A9,'All Contract Holders'!$A$5:$K$40,10,FALSE) -> (402) 502-4158 | K9: =VLOOKUP($A9,'All Contract Holders'!$A$5:$K$40,11,FALSE) -> (402) 393-1825 | L9: x | M9: x | N9: x
A10: GS-06F-0513Z | B10: =VLOOKUP($A10,'All Contract Holders'!$A$5:$K$40,2,FALSE) -> DV United, LLC | C10: =VLOOKUP($A10,'All Contract Holders'!$A$5:$K$40,3,FALSE) -> 7343 Waverly Drive | D10: =VLOOKUP($A10,'All Contract Holders'!$A$5:$K$40,4,FALSE) -> Warrenton | E10: =VLOOKUP($A10,'All Contract Holders'!$A$5:$K$40,5,FALSE) -> VA | F10: =VLOOKUP($A10,'All Contract Holders'!$A$5:$K$40,6,FALSE) -> 20186 | G10: =VLOOKUP($A10,'All Contract Holders'!$A$5:$K$40,7,FALSE) -> Thomas Dalton, Edgar Lewin | H10: =VLOOKUP($A10,'All Contract Holders'!$A$5:$K$40,8,FALSE) -> thomas.dalton@tdginc.com, edgar.lewin@alyngroup.com | I10: =VLOOKUP($A10,'All Contract Holders'!$A$5:$K$40,9,FALSE) -> www.dvunited.com | J10: =VLOOKUP($A10,'All Contract Holders'!$A$5:$K$40,10,FALSE) -> (540) 349-1939 | K10: =VLOOKUP($A10,'All Contract Holders'!$A$5:$K$40,11,FALSE) -> (540) 347-2295 | L10: x | M10: x | N10: x
A11: GS-06F-0527Z | B11: =VLOOKUP($A11,'All Contract Holders'!$A$5:$K$40,2,FALSE) -> Ian, Evan & Alexander Corporation | C11: =VLOOKUP($A11,'All Contract Holders'!$A$5:$K$40,3,FALSE) -> 20098 Ashbrook Place, Suite 260 | D11: =VLOOKUP($A11,'All Contract Holders'!$A$5:$K$40,4,FALSE) -> Ashburn | E11: =VLOOKUP($A11,'All Contract Holders'!$A$5:$K$40,5,FALSE) -> VA | F11: =VLOOKUP($A11,'All Contract Holders'!$A$5:$K$40,6,FALSE) -> 20147 | G11: =VLOOKUP($A11,'All Contract Holders'!$A$5:$K$40,7,FALSE) -> John E. Cochran | H11: =VLOOKUP($A11,'All Contract Holders'!$A$5:$K$40,8,FALSE) -> jcochran@iea-corp.com, jwynn@iea-corp.com | I11: =VLOOKUP($A11,'All Contract Holders'!$A$5:$K$40,9,FALSE) -> www.iea-corp.com | J11: =VLOOKUP($A11,'All Contract Holders'!$A$5:$K$40,10,FALSE) -> (703) 682-4575 | K11: =VLOOKUP($A11,'All Contract Holders'!$A$5:$K$40,11,FALSE) -> (703) 935-1063 | L11: x | M11: x | N11: x
A12: GS-06F-0529Z | B12: =VLOOKUP($A12,'All Contract Holders'!$A$5:$K$40,2,FALSE) -> Innovative Management Concepts | C12: =VLOOKUP($A12,'All Contract Holders'!$A$5:$K$40,3,FALSE) -> 21400 Ridgetop Circle, Suite 210 | D12: =VLOOKUP($A12,'All Contract Holders'!$A$5:$K$40,4,FALSE) -> Dulles | E12: =VLOOKUP($A12,'All Contract Holders'!$A$5:$K$40,5,FALSE) -> VA | F12: =VLOOKUP($A12,'All Contract Holders'!$A$5:$K$40,6,FALSE) -> 20166 | G12: =VLOOKUP($A12,'All Contract Holders'!$A$5:$K$40,7,FALSE) -> Robert J. Might, Ph.D., Mike Metz | H12: =VLOOKUP($A12,'All Contract Holders'!$A$5:$K$40,8,FALSE) -> rmight@imcva.com, mmetz@imcva.com | I12: =VLOOKUP($A12,'All Contract Holders'!$A$5:$K$40,9,FALSE) -> www.imcva.com | J12: =VLOOKUP($A12,'All Contract Holders'!$A$5:$K$40,10,FALSE) -> (703) 318-8044 x209 | K12: =VLOOKUP($A12,'All Contract Holders'!$A$5:$K$40,11,FALSE) -> (703) 318-8740 | L12: x | M12: x | N12: x
A13: GS-06F-0531Z | B13: =VLOOKUP($A13,'All Contract Holders'!$A$5:$K$40,2,FALSE) -> INTECON, LLC | C13: =VLOOKUP($A13,'All Contract Holders'!$A$5:$K$40,3,FALSE) -> 1325 Aeroplaza Drive, Ste 105 | D13: =VLOOKUP($A13,'All Contract Holders'!$A$5:$K$40,4,FALSE) -> Colorado Springs | E13: =VLOOKUP($A13,'All Contract Holders'!$A$5:$K$40,5,FALSE) -> CO | F13: =VLOOKUP($A13,'All Contract Holders'!$A$5:$K$40,6,FALSE) -> 80916 | G13: =VLOOKUP($A13,'All Contract Holders'!$A$5:$K$40,7,FALSE) -> John Benjamin, Alan Omo | H13: =VLOOKUP($A13,'All Contract Holders'!$A$5:$K$40,8,FALSE) -> vetsgwac@inteconusa.com | I13: =VLOOKUP($A13,'All Contract Holders'!$A$5:$K$40,9,FALSE) -> www.inteconusa.com | J13: =VLOOKUP($A13,'All Contract Holders'!$A$5:$K$40,10,FALSE) -> (719) 597-2275 | K13: =VLOOKUP($A13,'All Contract Holders'!$A$5:$K$40,11,FALSE) -> (719) 597-7120 | L13: x | M13: x | N13: x
A14: GS-06F-0534Z | B14: =VLOOKUP($A14,'All Contract Holders'!$A$5:$K$40,2,FALSE) -> Kingfisher Systems, Inc. | C14: =VLOOKUP($A14,'All Contract Holders'!$A$5:$K$40,3,FALSE) -> 3110 Fairview Park Drive, Ste 1250 | D14: =VLOOKUP($A14,'All Contract Holders'!$A$5:$K$40,4,FALSE) -> Falls Church | E14: =VLOOKUP($A14,'All Contract Holders'!$A$5:$K$40,5,FALSE) -> VA | F14: =VLOOKUP($A14,'All Contract Holders'!$A$5:$K$40,6,FALSE) -> 22042 | G14: =VLOOKUP($A14,'All Contract Holders'!$A$5:$K$40,7,FALSE) -> Sonya Ford | H14: =VLOOKUP($A14,'All Contract Holders'!$A$5:$K$40,8,FALSE) -> VETSGWAC@kingfishersys.com | I14: =VLOOKUP($A14,'All Contract Holders'!$A$5:$K$40,9,FALSE) -> www.kingfishersys.com | J14: =VLOOKUP($A14,'All Contract Holders'!$A$5:$K$40,10,FALSE) -> (703) 820-7970 | K14: =VLOOKUP($A14,'All Contract Holders'!$A$5:$K$40,11,FALSE) -> (703) 820-7976 | L14: x | M14: x | N14: x
A15: GS-06F-0538Z | B15: =VLOOKUP($A15,'All Contract Holders'!$A$5:$K$40,2,FALSE) -> KT Consulting | C15: =VLOOKUP($A15,'All Contract Holders'!$A$5:$K$40,3,FALSE) -> 2327 South Hardy Drive | D15: =VLOOKUP($A15,'All Contract Holders'!$A$5:$K$40,4,FALSE) -> Tempe | E15: =VLOOKUP($A15,'All Contract Holders'!$A$5:$K$40,5,FALSE) -> AZ | F15: =VLOOKUP($A15,'All Contract Holders'!$A$5:$K$40,6,FALSE) -> 85282 | G15: =VLOOKUP($A15,'All Contract Holders'!$A$5:$K$40,7,FALSE) -> Kevin Terrell | H15: =VLOOKUP($A15,'All Contract Holders'!$A$5:$K$40,8,FALSE) -> kterrell@ktc-ops.com | I15: =VLOOKUP($A15,'All Contract Holders'!$A$5:$K$40,9,FALSE) -> www.ktc-vets.com | J15: =VLOOKUP($A15,'All Contract Holders'!$A$5:$K$40,10,FALSE) -> (480) 538-2668 | K15: =VLOOKUP($A15,'All Contract Holders'!$A$5:$K$40,11,FALSE) -> (480) 538-2686 | L15: x | M15: x | N15: x
A16: GS-06F-0544Z | B16: =VLOOKUP($A16,'All Contract Holders'!$A$5:$K$40,2,FALSE) -> Milvets System Technology, Inc. | C16: =VLOOKUP($A16,'All Contract Holders'!$A$5:$K$40,3,FALSE) -> 11825 High Tech Ave., Suite 150 | D16: =VLOOKUP($A16,'All Contract Holders'!$A$5:$K$40,4,FALSE) -> Orlando | E16: =VLOOKUP($A16,'All Contract Holders'!$A$5:$K$40,5,FALSE) -> FL | F16: =VLOOKUP($A16,'All Contract Holders'!$A$5:$K$40,6,FALSE) -> 32817 | G16: =VLOOKUP($A16,'All Contract Holders'!$A$5:$K$40,7,FALSE) -> Bob Daniels, Robin Nickerson | H16: =VLOOKUP($A16,'All Contract Holders'!$A$5:$K$40,8,FALSE) -> vetsgwac@milvets.com | I16: =VLOOKUP($A16,'All Contract Holders'!$A$5:$K$40,9,FALSE) -> www.milvets.com | J16: =VLOOKUP($A16,'All Contract Holders'!$A$5:$K$40,10,FALSE) -> (301) 731-9130 ext.35 | K16: =VLOOKUP($A16,'All Contract Holders'!$A$5:$K$40,11,FALSE) -> (301) 731-4773 | L16: x | M16: x | N16: x
A17: GS-06F-0545Z | B17: =VLOOKUP($A17,'All Contract Holders'!$A$5:$K$40,2,FALSE) -> Advanced Facility Management Services, Inc. | C17: =VLOOKUP($A17,'All Contract Holders'!$A$5:$K$40,3,FALSE) -> 60 South Washington St. | D17: =VLOOKUP($A17,'All Contract Holders'!$A$5:$K$40,4,FALSE) -> Greencastle | E17: =VLOOKUP($A17,'All Contract Holders'!$A$5:$K$40,5,FALSE) -> PA | F17: =VLOOKUP($A17,'All Contract Holders'!$A$5:$K$40,6,FALSE) -> 17225 | G17: =VLOOKUP($A17,'All Contract Holders'!$A$5:$K$40,7,FALSE) -> Kevin McCracken | H17: =VLOOKUP($A17,'All Contract Holders'!$A$5:$K$40,8,FALSE) -> afmsvetsgwac@afmsinc.com | I17: =VLOOKUP($A17,'All Contract Holders'!$A$5:$K$40,9,FALSE) -> http://www.afmsvetsgwac.com | J17: =VLOOKUP($A17,'All Contract Holders'!$A$5:$K$40,10,FALSE) -> (717) 458-8786 | K17: =VLOOKUP($A17,'All Contract Holders'!$A$5:$K$40,11,FALSE) -> (717) 458-8947 | L17: x | M17: x | N17: x
A18: GS-06F-0539Z | B18: =VLOOKUP($A18,'All Contract Holders'!$A$5:$K$40,2,FALSE) -> OBXtek, Inc. | C18: =VLOOKUP($A18,'All Contract Holders'!$A$5:$K$40,3,FALSE) -> 8300 Boone Blvd, Suite 800 | D18: =VLOOKUP($A18,'All Contract Holders'!$A$5:$K$40,4,FALSE) -> Vienna | E18: =VLOOKUP($A18,'All Contract Holders'!$A$5:$K$40,5,FALSE) -> VA | F18: =VLOOKUP($A18,'All Contract Holders'!$A$5:$K$40,6,FALSE) -> 22182 | G18: =VLOOKUP($A18,'All Contract Holders'!$A$5:$K$40,7,FALSE) -> Ed Jesson, Jasmine Feeney | H18: =VLOOKUP($A18,'All Contract Holders'!$A$5:$K$40,8,FALSE) -> vets@obxtek.com | I18: =VLOOKUP($A18,'All Contract Holders'!$A$5:$K$40,9,FALSE) -> www.obxtek.com | J18: =VLOOKUP($A18,'All Contract Holders'!$A$5:$K$40,10,FALSE) -> (703) 373-3736 (571) 395-4542 | K18: =VLOOKUP($A18,'All Contract Holders'!$A$5:$K$40,11,FALSE) -> (866) 633-9157 | L18: x | N18: x
A19: GS-06F-0546Z | B19: =VLOOKUP($A19,'All Contract Holders'!$A$5:$K$40,2,FALSE) -> Penobscot Bay Media LLC | C19: =VLOOKUP($A19,'All Contract Holders'!$A$5:$K$40,3,FALSE) -> 58 Dodge Mountain Rd | D19: =VLOOKUP($A19,'All Contract Holders'!$A$5:$K$40,4,FALSE) -> Rockland | E19: =VLOOKUP($A19,'All Contract Holders'!$A$5:$K$40,5,FALSE) -> ME | F19: =VLOOKUP($A19,'All Contract Holders'!$A$5:$K$40,6,FALSE) -> 04841 | G19: =VLOOKUP($A19,'All Contract Holders'!$A$5:$K$40,7,FALSE) -> Ann S. Yahner | H19: =VLOOKUP($A19,'All Contract Holders'!$A$5:$K$40,8,FALSE) -> vetsgwac@penbaymedia.com | I19: =VLOOKUP($A19,'All Contract Holders'!$A$5:$K$40,9,FALSE) -> www.penbaymedia.com | J19: =VLOOKUP($A19,'All Contract Holders'!$A$5:$K$40,10,FALSE) -> (207) 596-6130 | K19: =VLOOKUP($A19,'All Contract Holders'!$A$5:$K$40,11,FALSE) -> (207) 596-6130 | L19: x | M19: x | N19: x
A20: GS-06F-0517Z | B20: =VLOOKUP($A20,'All Contract Holders'!$A$5:$K$40,2,FALSE) -> Pro-Sphere Tek, Inc. | C20: =VLOOKUP($A20,'All Contract Holders'!$A$5:$K$40,3,FALSE) -> 415 North Lee Street | D20: =VLOOKUP($A20,'All Contract Holders'!$A$5:$K$40,4,FALSE) -> Alexandria | E20: =VLOOKUP($A20,'All Contract Holders'!$A$5:$K$40,5,FALSE) -> VA | F20: =VLOOKUP($A20,'All Contract Holders'!$A$5:$K$40,6,FALSE) -> 22314 | G20: =VLOOKUP($A20,'All Contract Holders'!$A$5:$K$40,7,FALSE) -> Tom Kenny | H20: =VLOOKUP($A20,'All Contract Holders'!$A$5:$K$40,8,FALSE) -> rblevins@pro-spheretek.com, TKenny@pro-spheretek.com | I20: =VLOOKUP($A20,'All Contract Holders'!$A$5:$K$40,9,FALSE) -> www.pro-spheretek.com | J20: =VLOOKUP($A20,'All Contract Holders'!$A$5:$K$40,10,FALSE) -> (571) 227-9700 | K20: =VLOOKUP($A20,'All Contract Holders'!$A$5:$K$40,11,FALSE) -> (571) 227-9701 | L20: x | N20: x
A21: GS-06F-0549Z | B21: =VLOOKUP($A21,'All Contract Holders'!$A$5:$K$40,2,FALSE) -> Standard Communications, INC | C21: =VLOOKUP($A21,'All Contract Holders'!$A$5:$K$40,3,FALSE) -> 5402 Leeds Manor Road, Fauquier County | D21: =VLOOKUP($A21,'All Contract Holders'!$A$5:$K$40,4,FALSE) -> Hume | E21: =VLOOKUP($A21,'All Contract Holders'!$A$5:$K$40,5,FALSE) -> VA | F21: =VLOOKUP($A21,'All Contract Holders'!$A$5:$K$40,6,FALSE) -> 22639 | G21: =VLOOKUP($A21,'All Contract Holders'!$A$5:$K$40,7,FALSE) -> John P. Moliere | H21: =VLOOKUP($A21,'All Contract Holders'!$A$5:$K$40,8,FALSE) -> john.moliere@stdcomm.com, bob.waizenegger@stdcomm.com | I21: =VLOOKUP($A21,'All Contract Holders'!$A$5:$K$40,9,FALSE) -> www.stdcomm.com | J21: =VLOOKUP($A21,'All Contract Holders'!$A$5:$K$40,10,FALSE) -> (540) 364-3688 | K21: =VLOOKUP($A21,'All Contract Holders'!$A$5:$K$40,11,FALSE) -> (703) 4261956 | L21: x | M21: x | N21: x
A22: GS-06F-0528Z | B22: =VLOOKUP($A22,'All Contract Holders'!$A$5:$K$40,2,FALSE) -> Veteran Corps of America | C22: =VLOOKUP($A22,'All Contract Holders'!$A$5:$K$40,3,FALSE) -> 10300 Eaton Place, Suite 340 | D22: =VLOOKUP($A22,'All Contract Holders'!$A$5:$K$40,4,FALSE) -> Fairfax | E22: =VLOOKUP($A22,'All Contract Holders'!$A$5:$K$40,5,FALSE) -> VA | F22: =VLOOKUP($A22,'All Contract Holders'!$A$5:$K$40,6,FALSE) -> 22030 | G22: =VLOOKUP($A22,'All Contract Holders'!$A$5:$K$40,7,FALSE) -> John R. Wheeler | H22: =VLOOKUP($A22,'All Contract Holders'!$A$5:$K$40,8,FALSE) -> gsavets@veterancorps.com | I22: =VLOOKUP($A22,'All Contract Holders'!$A$5:$K$40,9,FALSE) -> www.veterancorps.com | J22: =VLOOKUP($A22,'All Contract Holders'!$A$5:$K$40,10,FALSE) -> (703) 691-8387 | K22: =VLOOKUP($A22,'All Contract Holders'!$A$5:$K$40,11,FALSE) -> (703) 691-8385 | L22: x | M22: x | N22: x
A23: GS-06F-0530Z | B23: =VLOOKUP($A23,'All Contract Holders'!$A$5:$K$40,2,FALSE) -> Veteran Engineering & Technology, LLC | C23: =VLOOKUP($A23,'All Contract Holders'!$A$5:$K$40,3,FALSE) -> 5475 Mark Dabling Blvd, Suite 300 | D23: =VLOOKUP($A23,'All Contract Holders'!$A$5:$K$40,4,FALSE) -> Colorado Springs | E23: =VLOOKUP($A23,'All Contract Holders'!$A$5:$K$40,5,FALSE) -> CO | F23: =VLOOKUP($A23,'All Contract Holders'!$A$5:$K$40,6,FALSE) -> 80918 | G23: =VLOOKUP($A23,'All Contract Holders'!$A$5:$K$40,7,FALSE) -> Craig Newmaker, Norm Andersson | H23: =VLOOKUP($A23,'All Contract Holders'!$A$5:$K$40,8,FALSE) -> engineering@vetengineering.com | I23: =VLOOKUP($A23,'All Contract Holders'!$A$5:$K$40,9,FALSE) -> www.vetengineering.com | J23: =VLOOKUP($A23,'All Contract Holders'!$A$5:$K$40,10,FALSE) -> (719) 623-3600 | K23: =VLOOKUP($A23,'All Contract Holders'!$A$5:$K$40,11,FALSE) -> (877) 870-9002 | L23: x | M23: x | N23: x
A24: GS-06F-0532Z | B24: =VLOOKUP($A24,'All Contract Holders'!$A$5:$K$40,2,FALSE) -> Veterans Enterprise Technology Solutions, INC | C24: =VLOOKUP($A24,'All Contract Holders'!$A$5:$K$40,3,FALSE) -> 2057 Woodford Road, STE 200 | D24: =VLOOKUP($A24,'All Contract Holders'!$A$5:$K$40,4,FALSE) -> Vienna | E24: =VLOOKUP($A24,'All Contract Holders'!$A$5:$K$40,5,FALSE) -> VA | F24: =VLOOKUP($A24,'All Contract Holders'!$A$5:$K$40,6,FALSE) -> 22182 | G24: =VLOOKUP($A24,'All Contract Holders'!$A$5:$K$40,7,FALSE) -> James H. Moody | H24: =VLOOKUP($A24,'All Contract Holders'!$A$5:$K$40,8,FALSE) -> jmoody@vets-inc.com, HEdwards@vets-inc.com | I24: =VLOOKUP($A24,'All Contract Holders'!$A$5:$K$40,9,FALSE) -> www.vets-inc.com | J24: =VLOOKUP($A24,'All Contract Holders'!$A$5:$K$40,10,FALSE) -> (434) 374-5899 | K24: =VLOOKUP($A24,'All Contract Holders'!$A$5:$K$40,11,FALSE) -> (866) 320-0911 | L24: x | M24: x | N24: x
A25: GS-06F-0533Z | B25: =VLOOKUP($A25,'All Contract Holders'!$A$5:$K$40,2,FALSE) -> Vetsamerica Business Consulting, INC | C25: =VLOOKUP($A25,'All Contract Holders'!$A$5:$K$40,3,FALSE) -> 8300 Greensboro Drive, Suite 800 | D25: =VLOOKUP($A25,'All Contract Holders'!$A$5:$K$40,4,FALSE) -> McLean | E25: =VLOOKUP($A25,'All Contract Holders'!$A$5:$K$40,5,FALSE) -> VA | F25: =VLOOKUP($A25,'All Contract Holders'!$A$5:$K$40,6,FALSE) -> 22102 | G25: =VLOOKUP($A25,'All Contract Holders'!$A$5:$K$40,7,FALSE) -> John Collins | H25: =VLOOKUP($A25,'All Contract Holders'!$A$5:$K$40,8,FALSE) -> johncollins@vetsamerica.us | I25: =VLOOKUP($A25,'All Contract Holders'!$A$5:$K$40,9,FALSE) -> www.vetsamerica.us | J25: =VLOOKUP($A25,'All Contract Holders'!$A$5:$K$40,10,FALSE) -> (843) 238-2517 | K25: =VLOOKUP($A25,'All Contract Holders'!$A$5:$K$40,11,FALSE) -> (843) 238-8426 | L25: x | M25: x | N25: x
A28: Large Strategic Partner Contractors
A29: Contract Numbers | B29: Vendor Name | C29: Vendor Address | D29: City | E29: State | F29: Zip Code | G29: Vendor Contact Name | H29: Email Address | I29: Website | J29: Phone | K29: Fax | L29: FA1 | M29: FA2
A30: GS-06F-0511Z | B30: =VLOOKUP($A30,'All Contract Holders'!$A$5:$K$40,2,FALSE) -> Catapult Technology, LTD | C30: =VLOOKUP($A30,'All Contract Holders'!$A$5:$K$40,3,FALSE) -> 7500 Old Georgetown Road, 11th Floor | D30: =VLOOKUP($A30,'All Contract Holders'!$A$5:$K$40,4,FALSE) -> Bethesda | E30: =VLOOKUP($A30,'All Contract Holders'!$A$5:$K$40,5,FALSE) -> MD | F30: =VLOOKUP($A30,'All Contract Holders'!$A$5:$K$40,6,FALSE) -> 20814-6198 | G30: =VLOOKUP($A30,'All Contract Holders'!$A$5:$K$40,7,FALSE) -> Jane Green | H30: =VLOOKUP($A30,'All Contract Holders'!$A$5:$K$40,8,FALSE) -> gsavets@catapulttechnology.com | I30: =VLOOKUP($A30,'All Contract Holders'!$A$5:$K$40,9,FALSE) -> www.catapulttechnology.com | J30: =VLOOKUP($A30,'All Contract Holders'!$A$5:$K$40,10,FALSE) -> (240) 482-2136 | K30: =VLOOKUP($A30,'All Contract Holders'!$A$5:$K$40,11,FALSE) -> (888) 338-1391 | L30: x | M30: x
A31: GS-06F-0514Z | B31: =VLOOKUP($A31,'All Contract Holders'!$A$5:$K$40,2,FALSE) -> Engineering Services Network, Inc. | C31: =VLOOKUP($A31,'All Contract Holders'!$A$5:$K$40,3,FALSE) -> 2450 Crystal Drive, Suite 1015 | D31: =VLOOKUP($A31,'All Contract Holders'!$A$5:$K$40,4,FALSE) -> Arlington | E31: =VLOOKUP($A31,'All Contract Holders'!$A$5:$K$40,5,FALSE) -> VA | F31: =VLOOKUP($A31,'All Contract Holders'!$A$5:$K$40,6,FALSE) -> 22202 | G31: =VLOOKUP($A31,'All Contract Holders'!$A$5:$K$40,7,FALSE) -> Michelle "Shelly" Smith | H31: =VLOOKUP($A31,'All Contract Holders'!$A$5:$K$40,8,FALSE) -> esncontracts@esncc.com | I31: =VLOOKUP($A31,'All Contract Holders'!$A$5:$K$40,9,FALSE) -> www.esncc.com | J31: =VLOOKUP($A31,'All Contract Holders'!$A$5:$K$40,10,FALSE) -> (703) 412-3640 | K31: =VLOOKUP($A31,'All Contract Holders'!$A$5:$K$40,11,FALSE) -> (703) 412-3643 | L31: x | M31: x
A32: GS-06F-0518Z | B32: =VLOOKUP($A32,'All Contract Holders'!$A$5:$K$40,2,FALSE) -> HMS Technologies, INC | C32: =VLOOKUP($A32,'All Contract Holders'!$A$5:$K$40,3,FALSE) -> One Discovery Place | D32: =VLOOKUP($A32,'All Contract Holders'!$A$5:$K$40,4,FALSE) -> Martinsburg | E32: =VLOOKUP($A32,'All Contract Holders'!$A$5:$K$40,5,FALSE) -> WV | F32: =VLOOKUP($A32,'All Contract Holders'!$A$5:$K$40,6,FALSE) -> 25403 | G32: =VLOOKUP($A32,'All Contract Holders'!$A$5:$K$40,7,FALSE) -> Roy Jones, Harry Siegel | H32: =VLOOKUP($A32,'All Contract Holders'!$A$5:$K$40,8,FALSE) -> roy.jones@hmstech.com, HSiegel@hmstech.com | I32: =VLOOKUP($A32,'All Contract Holders'!$A$5:$K$40,9,FALSE) -> www.hmstech.com | J32: =VLOOKUP($A32,'All Contract Holders'!$A$5:$K$40,10,FALSE) -> (304) 596-5583 | K32: =VLOOKUP($A32,'All Contract Holders'!$A$5:$K$40,11,FALSE) -> (304) 596-5589 | L32: x
A33: GS-06F-0519Z | B33: =VLOOKUP($A33,'All Contract Holders'!$A$5:$K$40,2,FALSE) -> Information Innovators, Inc | C33: =VLOOKUP($A33,'All Contract Holders'!$A$5:$K$40,3,FALSE) -> 7400 Fullerton Road, STE 210 | D33: =VLOOKUP($A33,'All Contract Holders'!$A$5:$K$40,4,FALSE) -> Springfield | E33: =VLOOKUP($A33,'All Contract Holders'!$A$5:$K$40,5,FALSE) -> VA | F33: =VLOOKUP($A33,'All Contract Holders'!$A$5:$K$40,6,FALSE) -> 22153 | G33: =VLOOKUP($A33,'All Contract Holders'!$A$5:$K$40,7,FALSE) -> Mark Harrington | H33: =VLOOKUP($A33,'All Contract Holders'!$A$5:$K$40,8,FALSE) -> vets@iiinfo.com | I33: =VLOOKUP($A33,'All Contract Holders'!$A$5:$K$40,9,FALSE) -> www.iiinfo.com | J33: =VLOOKUP($A33,'All Contract Holders'!$A$5:$K$40,10,FALSE) -> (703) 665-4256 | K33: =VLOOKUP($A33,'All Contract Holders'!$A$5:$K$40,11,FALSE) -> (703) 440-1332 | L33: x
A34: GS-06F-0543Z | B34: =VLOOKUP($A34,'All Contract Holders'!$A$5:$K$40,2,FALSE) -> Metters Industries, INC | C34: =VLOOKUP($A34,'All Contract Holders'!$A$5:$K$40,3,FALSE) -> 8200 Greensboro Drive, STE 500 | D34: =VLOOKUP($A34,'All Contract Holders'!$A$5:$K$40,4,FALSE) -> McLean | E34: =VLOOKUP($A34,'All Contract Holders'!$A$5:$K$40,5,FALSE) -> VA | F34: =VLOOKUP($A34,'All Contract Holders'!$A$5:$K$40,6,FALSE) -> 22102 | G34: =VLOOKUP($A34,'All Contract Holders'!$A$5:$K$40,7,FALSE) -> Will Dolan, Bob LeFebvre | H34: =VLOOKUP($A34,'All Contract Holders'!$A$5:$K$40,8,FALSE) -> MI-GSA-VETSGWAC@metters.com, Bob.Lefebvre@metters.com | I34: =VLOOKUP($A34,'All Contract Holders'!$A$5:$K$40,9,FALSE) -> www.metters.com | J34: =VLOOKUP($A34,'All Contract Holders'!$A$5:$K$40,10,FALSE) -> (703) 821-3300 ext 709 | K34: =VLOOKUP($A34,'All Contract Holders'!$A$5:$K$40,11,FALSE) -> (703) 821-3996 | L34: x | M34: x
A35: GS-06F-0547Z | B35: =VLOOKUP($A35,'All Contract Holders'!$A$5:$K$40,2,FALSE) -> Professional Solutions, LLC | C35: =VLOOKUP($A35,'All Contract Holders'!$A$5:$K$40,3,FALSE) -> 5500 Cherokee Avenue, Suite 400 | D35: =VLOOKUP($A35,'All Contract Holders'!$A$5:$K$40,4,FALSE) -> Alexandria | E35: =VLOOKUP($A35,'All Contract Holders'!$A$5:$K$40,5,FALSE) -> VA | F35: =VLOOKUP($A35,'All Contract Holders'!$A$5:$K$40,6,FALSE) -> 22312 | G35: =VLOOKUP($A35,'All Contract Holders'!$A$5:$K$40,7,FALSE) -> Ms. Ari Abraham | H35: =VLOOKUP($A35,'All Contract Holders'!$A$5:$K$40,8,FALSE) -> VETsGWAC@prosol1.com, AAbraham@prosol1.com | I35: =VLOOKUP($A35,'All Contract Holders'!$A$5:$K$40,9,FALSE) -> www.prosol1.com | J35: =VLOOKUP($A35,'All Contract Holders'!$A$5:$K$40,10,FALSE) -> (703) 823-2696 x101 | K35: =VLOOKUP($A35,'All Contract Holders'!$A$5:$K$40,11,FALSE) -> (703) 823-2698 | L35: x | M35: x
A36: GS-06F-0548Z | B36: =VLOOKUP($A36,'All Contract Holders'!$A$5:$K$40,2,FALSE) -> Systems Made Simple, INC | C36: =VLOOKUP($A36,'All Contract Holders'!$A$5:$K$40,3,FALSE) -> One Northern Concourse | D36: =VLOOKUP($A36,'All Contract Holders'!$A$5:$K$40,4,FALSE) -> Syracuse | E36: =VLOOKUP($A36,'All Contract Holders'!$A$5:$K$40,5,FALSE) -> NY | F36: =VLOOKUP($A36,'All Contract Holders'!$A$5:$K$40,6,FALSE) -> 13212 | G36: =VLOOKUP($A36,'All Contract Holders'!$A$5:$K$40,7,FALSE) -> Ron Fishbeck | H36: =VLOOKUP($A36,'All Contract Holders'!$A$5:$K$40,8,FALSE) -> ron.fishbeck@systemsmadesimple.com, vetsgwac@teamsms.net | I36: =VLOOKUP($A36,'All Contract Holders'!$A$5:$K$40,9,FALSE) -> https://www.teamsms.net/GWAC | J36: =VLOOKUP($A36,'All Contract Holders'!$A$5:$K$40,10,FALSE) -> (315) 455-3200 x26 (800) 893-9883 x26 | K36: =VLOOKUP($A36,'All Contract Holders'!$A$5:$K$40,11,FALSE) -> (315) 455-3120 | L36: x | M36: x
A37: GS-06F-0535Z | B37: =VLOOKUP($A37,'All Contract Holders'!$A$5:$K$40,2,FALSE) -> Vision Technologies, Inc | C37: =VLOOKUP($A37,'All Contract Holders'!$A$5:$K$40,3,FALSE) -> 530 J McCormick Drive | D37: =VLOOKUP($A37,'All Contract Holders'!$A$5:$K$40,4,FALSE) -> Glen Burnie | E37: =VLOOKUP($A37,'All Contract Holders'!$A$5:$K$40,5,FALSE) -> MD | F37: =VLOOKUP($A37,'All Contract Holders'!$A$5:$K$40,6,FALSE) -> 21061 | G37: =VLOOKUP($A37,'All Contract Holders'!$A$5:$K$40,7,FALSE) -> Michael Sandberg | H37: =VLOOKUP($A37,'All Contract Holders'!$A$5:$K$40,8,FALSE) -> vetsgwac@visiontech.biz | I37: =VLOOKUP($A37,'All Contract Holders'!$A$5:$K$40,9,FALSE) -> www.vets-gsa.com | J37: =VLOOKUP($A37,'All Contract Holders'!$A$5:$K$40,10,FALSE) -> (410) 424-2183 x243 (703) 598-7990 | K37: =VLOOKUP($A37,'All Contract Holders'!$A$5:$K$40,11,FALSE) -> (410) 424-2208 | L37: x | M37: x

Sheet FA2 Contract Holders
A1: Functional Area 2 - Information Systems Engineering - Including Security
A2: Note: VETS GWAC Industry Partners were required to re-represent their size status prior to the February 2012 option period and are required to re-represent in accordance with FAR 52.219-28. Size is represented in column N. Only those Industry Partners shown as small may be awarded task orders after February 1, 2012.
A3: Small Business Prime Contractors
A4: Contract Numbers | B4: Vendor Name | C4: Vendor Address | D4: City | E4: State | F4: Zip Code | G4: Vendor Contact Name | H4: Email Address | I4: Website | J4: Phone | K4: Fax | L4: FA1 | M4: FA2 | N4: Small Business
A5: GS-06F-0508Z | B5: =VLOOKUP($A5,'All Contract Holders'!$A$5:$K$40,2,FALSE) -> Advanced Systems, Inc. | C5: =VLOOKUP($A5,'All Contract Holders'!$A$5:$K$40,3,FALSE) -> 8280 Willow Oaks Corporate Drive, Suite LL113 | D5: =VLOOKUP($A5,'All Contract Holders'!$A$5:$K$40,4,FALSE) -> Fairfax | E5: =VLOOKUP($A5,'All Contract Holders'!$A$5:$K$40,5,FALSE) -> VA | F5: =VLOOKUP($A5,'All Contract Holders'!$A$5:$K$40,6,FALSE) -> 22031 | G5: =VLOOKUP($A5,'All Contract Holders'!$A$5:$K$40,7,FALSE) -> Robert A. Walker | H5: =VLOOKUP($A5,'All Contract Holders'!$A$5:$K$40,8,FALSE) -> rwalker@AdvSystems.com, ASI@AdvSystems.com | I5: =VLOOKUP($A5,'All Contract Holders'!$A$5:$K$40,9,FALSE) -> www.advsystems.com | J5: =VLOOKUP($A5,'All Contract Holders'!$A$5:$K$40,10,FALSE) -> (703) 218-3360 x206 | K5: =VLOOKUP($A5,'All Contract Holders'!$A$5:$K$40,11,FALSE) -> (703) 218-3644 | L5: x | M5: x | N5: x
A6: GS-06F-0524Z | B6: =VLOOKUP($A6,'All Contract Holders'!$A$5:$K$40,2,FALSE) -> American Veterans, LLC | C6: =VLOOKUP($A6,'All Contract Holders'!$A$5:$K$40,3,FALSE) -> 2 Brittany Lane | D6: =VLOOKUP($A6,'All Contract Holders'!$A$5:$K$40,4,FALSE) -> Stafford | E6: =VLOOKUP($A6,'All Contract Holders'!$A$5:$K$40,5,FALSE) -> VA | F6: =VLOOKUP($A6,'All Contract Holders'!$A$5:$K$40,6,FALSE) -> 22554 | G6: =VLOOKUP($A6,'All Contract Holders'!$A$5:$K$40,7,FALSE) -> Vic Blanco | H6: =VLOOKUP($A6,'All Contract Holders'!$A$5:$K$40,8,FALSE) -> vetsgwac@sbgts.com, vblanco@sbgts.com | I6: =VLOOKUP($A6,'All Contract Holders'!$A$5:$K$40,9,FALSE) -> www.americanveteransllc.com | J6: =VLOOKUP($A6,'All Contract Holders'!$A$5:$K$40,10,FALSE) -> (540) 658-1311 | K6: =VLOOKUP($A6,'All Contract Holders'!$A$5:$K$40,11,FALSE) -> (540) 658-1359 | M6: x | N6: x
A7: GS-06F-0509Z | B7: =VLOOKUP($A7,'All Contract Holders'!$A$5:$K$40,2,FALSE) -> C Watkins & Associates, INC | C7: =VLOOKUP($A7,'All Contract Holders'!$A$5:$K$40,3,FALSE) -> 23 Griswold CT | D7: =VLOOKUP($A7,'All Contract Holders'!$A$5:$K$40,4,FALSE) -> Sterling | E7: =VLOOKUP($A7,'All Contract Holders'!$A$5:$K$40,5,FALSE) -> VA | F7: =VLOOKUP($A7,'All Contract Holders'!$A$5:$K$40,6,FALSE) -> 20165 | G7: =VLOOKUP($A7,'All Contract Holders'!$A$5:$K$40,7,FALSE) -> Carl A. Watkins, Danny Watkins | H7: =VLOOKUP($A7,'All Contract Holders'!$A$5:$K$40,8,FALSE) -> carl@cwivetsteam.com, danny@cwivetsteam.com | I7: =VLOOKUP($A7,'All Contract Holders'!$A$5:$K$40,9,FALSE) -> www.cwatkinsinc.com www.cwivetsteam.com | J7: =VLOOKUP($A7,'All Contract Holders'!$A$5:$K$40,10,FALSE) -> (703) 444-1625 | K7: =VLOOKUP($A7,'All Contract Holders'!$A$5:$K$40,11,FALSE) -> (703) 236-5046 | L7: x | M7: x | N7: x
A8: GS-06F-0510Z | B8: =VLOOKUP($A8,'All Contract Holders'!$A$5:$K$40,2,FALSE) -> C2 Solutions Group, Inc. | C8: =VLOOKUP($A8,'All Contract Holders'!$A$5:$K$40,3,FALSE) -> 1881 Campus Commons Drive, Suite 301 | D8: =VLOOKUP($A8,'All Contract Holders'!$A$5:$K$40,4,FALSE) -> Reston | E8: =VLOOKUP($A8,'All Contract Holders'!$A$5:$K$40,5,FALSE) -> VA | F8: =VLOOKUP($A8,'All Contract Holders'!$A$5:$K$40,6,FALSE) -> 20191 | G8: =VLOOKUP($A8,'All Contract Holders'!$A$5:$K$40,7,FALSE) -> Brian Newell | H8: =VLOOKUP($A8,'All Contract Holders'!$A$5:$K$40,8,FALSE) -> vets@c2sginc.com | I8: =VLOOKUP($A8,'All Contract Holders'!$A$5:$K$40,9,FALSE) -> www.c2sginc.com | J8: =VLOOKUP($A8,'All Contract Holders'!$A$5:$K$40,10,FALSE) -> (571) 210-2390 | K8: =VLOOKUP($A8,'All Contract Holders'!$A$5:$K$40,11,FALSE) -> (703) 853-7927 | L8: x | M8: x | N8: x
A9: GS-06F-0512Z | B9: =VLOOKUP($A9,'All Contract Holders'!$A$5:$K$40,2,FALSE) -> Client Server Software Solutions dba Constellation West | C9: =VLOOKUP($A9,'All Contract Holders'!$A$5:$K$40,3,FALSE) -> 3906 Raynor Parkway, STE 201 | D9: =VLOOKUP($A9,'All Contract Holders'!$A$5:$K$40,4,FALSE) -> Bellevue | E9: =VLOOKUP($A9,'All Contract Holders'!$A$5:$K$40,5,FALSE) -> NE | F9: =VLOOKUP($A9,'All Contract Holders'!$A$5:$K$40,6,FALSE) -> 68123 | G9: =VLOOKUP($A9,'All Contract Holders'!$A$5:$K$40,7,FALSE) -> Steve Johns | H9: =VLOOKUP($A9,'All Contract Holders'!$A$5:$K$40,8,FALSE) -> VETSGWAC@constellationwest.com | I9: =VLOOKUP($A9,'All Contract Holders'!$A$5:$K$40,9,FALSE) -> www.csss.net | J9: =VLOOKUP($A9,'All Contract Holders'!$A$5:$K$40,10,FALSE) -> (402) 502-4158 | K9: =VLOOKUP($A9,'All Contract Holders'!$A$5:$K$40,11,FALSE) -> (402) 393-1825 | L9: x | M9: x | N9: x
A10: GS-06F-0513Z | B10: =VLOOKUP($A10,'All Contract Holders'!$A$5:$K$40,2,FALSE) -> DV United, LLC | C10: =VLOOKUP($A10,'All Contract Holders'!$A$5:$K$40,3,FALSE) -> 7343 Waverly Drive | D10: =VLOOKUP($A10,'All Contract Holders'!$A$5:$K$40,4,FALSE) -> Warrenton | E10: =VLOOKUP($A10,'All Contract Holders'!$A$5:$K$40,5,FALSE) -> VA | F10: =VLOOKUP($A10,'All Contract Holders'!$A$5:$K$40,6,FALSE) -> 20186 | G10: =VLOOKUP($A10,'All Contract Holders'!$A$5:$K$40,7,FALSE) -> Thomas Dalton, Edgar Lewin | H10: =VLOOKUP($A10,'All Contract Holders'!$A$5:$K$40,8,FALSE) -> thomas.dalton@tdginc.com, edgar.lewin@alyngroup.com | I10: =VLOOKUP($A10,'All Contract Holders'!$A$5:$K$40,9,FALSE) -> www.dvunited.com | J10: =VLOOKUP($A10,'All Contract Holders'!$A$5:$K$40,10,FALSE) -> (540) 349-1939 | K10: =VLOOKUP($A10,'All Contract Holders'!$A$5:$K$40,11,FALSE) -> (540) 347-2295 | L10: x | M10: x | N10: x
A11: GS-06F-0527Z | B11: =VLOOKUP($A11,'All Contract Holders'!$A$5:$K$40,2,FALSE) -> Ian, Evan & Alexander Corporation | C11: =VLOOKUP($A11,'All Contract Holders'!$A$5:$K$40,3,FALSE) -> 20098 Ashbrook Place, Suite 260 | D11: =VLOOKUP($A11,'All Contract Holders'!$A$5:$K$40,4,FALSE) -> Ashburn | E11: =VLOOKUP($A11,'All Contract Holders'!$A$5:$K$40,5,FALSE) -> VA | F11: =VLOOKUP($A11,'All Contract Holders'!$A$5:$K$40,6,FALSE) -> 20147 | G11: =VLOOKUP($A11,'All Contract Holders'!$A$5:$K$40,7,FALSE) -> John E. Cochran | H11: =VLOOKUP($A11,'All Contract Holders'!$A$5:$K$40,8,FALSE) -> jcochran@iea-corp.com, jwynn@iea-corp.com | I11: =VLOOKUP($A11,'All Contract Holders'!$A$5:$K$40,9,FALSE) -> www.iea-corp.com | J11: =VLOOKUP($A11,'All Contract Holders'!$A$5:$K$40,10,FALSE) -> (703) 682-4575 | K11: =VLOOKUP($A11,'All Contract Holders'!$A$5:$K$40,11,FALSE) -> (703) 935-1063 | L11: x | M11: x | N11: x
A12: GS-06F-0529Z | B12: =VLOOKUP($A12,'All Contract Holders'!$A$5:$K$40,2,FALSE) -> Innovative Management Concepts | C12: =VLOOKUP($A12,'All Contract Holders'!$A$5:$K$40,3,FALSE) -> 21400 Ridgetop Circle, Suite 210 | D12: =VLOOKUP($A12,'All Contract Holders'!$A$5:$K$40,4,FALSE) -> Dulles | E12: =VLOOKUP($A12,'All Contract Holders'!$A$5:$K$40,5,FALSE) -> VA | F12: =VLOOKUP($A12,'All Contract Holders'!$A$5:$K$40,6,FALSE) -> 20166 | G12: =VLOOKUP($A12,'All Contract Holders'!$A$5:$K$40,7,FALSE) -> Robert J. Might, Ph.D., Mike Metz | H12: =VLOOKUP($A12,'All Contract Holders'!$A$5:$K$40,8,FALSE) -> rmight@imcva.com, mmetz@imcva.com | I12: =VLOOKUP($A12,'All Contract Holders'!$A$5:$K$40,9,FALSE) -> www.imcva.com | J12: =VLOOKUP($A12,'All Contract Holders'!$A$5:$K$40,10,FALSE) -> (703) 318-8044 x209 | K12: =VLOOKUP($A12,'All Contract Holders'!$A$5:$K$40,11,FALSE) -> (703) 318-8740 | L12: x | M12: x | N12: x
A13: GS-06F-0531Z | B13: =VLOOKUP($A13,'All Contract Holders'!$A$5:$K$40,2,FALSE) -> INTECON, LLC | C13: =VLOOKUP($A13,'All Contract Holders'!$A$5:$K$40,3,FALSE) -> 1325 Aeroplaza Drive, Ste 105 | D13: =VLOOKUP($A13,'All Contract Holders'!$A$5:$K$40,4,FALSE) -> Colorado Springs | E13: =VLOOKUP($A13,'All Contract Holders'!$A$5:$K$40,5,FALSE) -> CO | F13: =VLOOKUP($A13,'All Contract Holders'!$A$5:$K$40,6,FALSE) -> 80916 | G13: =VLOOKUP($A13,'All Contract Holders'!$A$5:$K$40,7,FALSE) -> John Benjamin, Alan Omo | H13: =VLOOKUP($A13,'All Contract Holders'!$A$5:$K$40,8,FALSE) -> vetsgwac@inteconusa.com | I13: =VLOOKUP($A13,'All Contract Holders'!$A$5:$K$40,9,FALSE) -> www.inteconusa.com | J13: =VLOOKUP($A13,'All Contract Holders'!$A$5:$K$40,10,FALSE) -> (719) 597-2275 | K13: =VLOOKUP($A13,'All Contract Holders'!$A$5:$K$40,11,FALSE) -> (719) 597-7120 | L13: x | M13: x | N13: x
A14: GS-06F-0534Z | B14: =VLOOKUP($A14,'All Contract Holders'!$A$5:$K$40,2,FALSE) -> Kingfisher Systems, Inc. | C14: =VLOOKUP($A14,'All Contract Holders'!$A$5:$K$40,3,FALSE) -> 3110 Fairview Park Drive, Ste 1250 | D14: =VLOOKUP($A14,'All Contract Holders'!$A$5:$K$40,4,FALSE) -> Falls Church | E14: =VLOOKUP($A14,'All Contract Holders'!$A$5:$K$40,5,FALSE) -> VA | F14: =VLOOKUP($A14,'All Contract Holders'!$A$5:$K$40,6,FALSE) -> 22042 | G14: =VLOOKUP($A14,'All Contract Holders'!$A$5:$K$40,7,FALSE) -> Sonya Ford | H14: =VLOOKUP($A14,'All Contract Holders'!$A$5:$K$40,8,FALSE) -> VETSGWAC@kingfishersys.com | I14: =VLOOKUP($A14,'All Contract Holders'!$A$5:$K$40,9,FALSE) -> www.kingfishersys.com | J14: =VLOOKUP($A14,'All Contract Holders'!$A$5:$K$40,10,FALSE) -> (703) 820-7970 | K14: =VLOOKUP($A14,'All Contract Holders'!$A$5:$K$40,11,FALSE) -> (703) 820-7976 | L14: x | M14: x | N14: x
A15: GS-06F-0538Z | B15: =VLOOKUP($A15,'All Contract Holders'!$A$5:$K$40,2,FALSE) -> KT Consulting | C15: =VLOOKUP($A15,'All Contract Holders'!$A$5:$K$40,3,FALSE) -> 2327 South Hardy Drive | D15: =VLOOKUP($A15,'All Contract Holders'!$A$5:$K$40,4,FALSE) -> Tempe | E15: =VLOOKUP($A15,'All Contract Holders'!$A$5:$K$40,5,FALSE) -> AZ | F15: =VLOOKUP($A15,'All Contract Holders'!$A$5:$K$40,6,FALSE) -> 85282 | G15: =VLOOKUP($A15,'All Contract Holders'!$A$5:$K$40,7,FALSE) -> Kevin Terrell | H15: =VLOOKUP($A15,'All Contract Holders'!$A$5:$K$40,8,FALSE) -> kterrell@ktc-ops.com | I15: =VLOOKUP($A15,'All Contract Holders'!$A$5:$K$40,9,FALSE) -> www.ktc-vets.com | J15: =VLOOKUP($A15,'All Contract Holders'!$A$5:$K$40,10,FALSE) -> (480) 538-2668 | K15: =VLOOKUP($A15,'All Contract Holders'!$A$5:$K$40,11,FALSE) -> (480) 538-2686 | L15: x | M15: x | N15: x
A16: GS-06F-0544Z | B16: =VLOOKUP($A16,'All Contract Holders'!$A$5:$K$40,2,FALSE) -> Milvets System Technology, Inc. | C16: =VLOOKUP($A16,'All Contract Holders'!$A$5:$K$40,3,FALSE) -> 11825 High Tech Ave., Suite 150 | D16: =VLOOKUP($A16,'All Contract Holders'!$A$5:$K$40,4,FALSE) -> Orlando | E16: =VLOOKUP($A16,'All Contract Holders'!$A$5:$K$40,5,FALSE) -> FL | F16: =VLOOKUP($A16,'All Contract Holders'!$A$5:$K$40,6,FALSE) -> 32817 | G16: =VLOOKUP($A16,'All Contract Holders'!$A$5:$K$40,7,FALSE) -> Bob Daniels, Robin Nickerson | H16: =VLOOKUP($A16,'All Contract Holders'!$A$5:$K$40,8,FALSE) -> vetsgwac@milvets.com | I16: =VLOOKUP($A16,'All Contract Holders'!$A$5:$K$40,9,FALSE) -> www.milvets.com | J16: =VLOOKUP($A16,'All Contract Holders'!$A$5:$K$40,10,FALSE) -> (301) 731-9130 ext.35 | K16: =VLOOKUP($A16,'All Contract Holders'!$A$5:$K$40,11,FALSE) -> (301) 731-4773 | L16: x | M16: x | N16: x
A17: GS-06F-0545Z | B17: =VLOOKUP($A17,'All Contract Holders'!$A$5:$K$40,2,FALSE) -> Advanced Facility Management Services, Inc. | C17: =VLOOKUP($A17,'All Contract Holders'!$A$5:$K$40,3,FALSE) -> 60 South Washington St. | D17: =VLOOKUP($A17,'All Contract Holders'!$A$5:$K$40,4,FALSE) -> Greencastle | E17: =VLOOKUP($A17,'All Contract Holders'!$A$5:$K$40,5,FALSE) -> PA | F17: =VLOOKUP($A17,'All Contract Holders'!$A$5:$K$40,6,FALSE) -> 17225 | G17: =VLOOKUP($A17,'All Contract Holders'!$A$5:$K$40,7,FALSE) -> Kevin McCracken | H17: =VLOOKUP($A17,'All Contract Holders'!$A$5:$K$40,8,FALSE) -> afmsvetsgwac@afmsinc.com | I17: =VLOOKUP($A17,'All Contract Holders'!$A$5:$K$40,9,FALSE) -> http://www.afmsvetsgwac.com | J17: =VLOOKUP($A17,'All Contract Holders'!$A$5:$K$40,10,FALSE) -> (717) 458-8786 | K17: =VLOOKUP($A17,'All Contract Holders'!$A$5:$K$40,11,FALSE) -> (717) 458-8947 | L17: x | M17: x | N17: x
A18: GS-06F-0551Z | B18: =VLOOKUP($A18,'All Contract Holders'!$A$5:$K$40,2,FALSE) -> OBXtek, Inc. | C18: =VLOOKUP($A18,'All Contract Holders'!$A$5:$K$40,3,FALSE) -> 8300 Boone Blvd, Suite 800 | D18: =VLOOKUP($A18,'All Contract Holders'!$A$5:$K$40,4,FALSE) -> Vienna | E18: =VLOOKUP($A18,'All Contract Holders'!$A$5:$K$40,5,FALSE) -> VA | F18: =VLOOKUP($A18,'All Contract Holders'!$A$5:$K$40,6,FALSE) -> 22182 | G18: =VLOOKUP($A18,'All Contract Holders'!$A$5:$K$40,7,FALSE) -> Ed Jesson, Jasmine Feeney | H18: =VLOOKUP($A18,'All Contract Holders'!$A$5:$K$40,8,FALSE) -> vets@obxtek.com | I18: =VLOOKUP($A18,'All Contract Holders'!$A$5:$K$40,9,FALSE) -> www.obxtek.com | J18: =VLOOKUP($A18,'All Contract Holders'!$A$5:$K$40,10,FALSE) -> (703) 373-3736 (571) 395-4542 | K18: =VLOOKUP($A18,'All Contract Holders'!$A$5:$K$40,11,FALSE) -> (866) 633-9157 | M18: x | N18: x
A19: GS-06F-0546Z | B19: =VLOOKUP($A19,'All Contract Holders'!$A$5:$K$40,2,FALSE) -> Penobscot Bay Media LLC | C19: =VLOOKUP($A19,'All Contract Holders'!$A$5:$K$40,3,FALSE) -> 58 Dodge Mountain Rd | D19: =VLOOKUP($A19,'All Contract Holders'!$A$5:$K$40,4,FALSE) -> Rockland | E19: =VLOOKUP($A19,'All Contract Holders'!$A$5:$K$40,5,FALSE) -> ME | F19: =VLOOKUP($A19,'All Contract Holders'!$A$5:$K$40,6,FALSE) -> 04841 | G19: =VLOOKUP($A19,'All Contract Holders'!$A$5:$K$40,7,FALSE) -> Ann S. Yahner | H19: =VLOOKUP($A19,'All Contract Holders'!$A$5:$K$40,8,FALSE) -> vetsgwac@penbaymedia.com | I19: =VLOOKUP($A19,'All Contract Holders'!$A$5:$K$40,9,FALSE) -> www.penbaymedia.com | J19: =VLOOKUP($A19,'All Contract Holders'!$A$5:$K$40,10,FALSE) -> (207) 596-6130 | K19: =VLOOKUP($A19,'All Contract Holders'!$A$5:$K$40,11,FALSE) -> (207) 596-6130 | L19: x | M19: x | N19: x
A20: GS-06F-0549Z | B20: =VLOOKUP($A20,'All Contract Holders'!$A$5:$K$40,2,FALSE) -> Standard Communications, INC | C20: =VLOOKUP($A20,'All Contract Holders'!$A$5:$K$40,3,FALSE) -> 5402 Leeds Manor Road, Fauquier County | D20: =VLOOKUP($A20,'All Contract Holders'!$A$5:$K$40,4,FALSE) -> Hume | E20: =VLOOKUP($A20,'All Contract Holders'!$A$5:$K$40,5,FALSE) -> VA | F20: =VLOOKUP($A20,'All Contract Holders'!$A$5:$K$40,6,FALSE) -> 22639 | G20: =VLOOKUP($A20,'All Contract Holders'!$A$5:$K$40,7,FALSE) -> John P. Moliere | H20: =VLOOKUP($A20,'All Contract Holders'!$A$5:$K$40,8,FALSE) -> john.moliere@stdcomm.com, bob.waizenegger@stdcomm.com | I20: =VLOOKUP($A20,'All Contract Holders'!$A$5:$K$40,9,FALSE) -> www.stdcomm.com | J20: =VLOOKUP($A20,'All Contract Holders'!$A$5:$K$40,10,FALSE) -> (540) 364-3688 | K20: =VLOOKUP($A20,'All Contract Holders'!$A$5:$K$40,11,FALSE) -> (703) 4261956 | L20: x | M20: x | N20: x
A21: GS-06F-0528Z | B21: =VLOOKUP($A21,'All Contract Holders'!$A$5:$K$40,2,FALSE) -> Veteran Corps of America | C21: =VLOOKUP($A21,'All Contract Holders'!$A$5:$K$40,3,FALSE) -> 10300 Eaton Place, Suite 340 | D21: =VLOOKUP($A21,'All Contract Holders'!$A$5:$K$40,4,FALSE) -> Fairfax | E21: =VLOOKUP($A21,'All Contract Holders'!$A$5:$K$40,5,FALSE) -> VA | F21: =VLOOKUP($A21,'All Contract Holders'!$A$5:$K$40,6,FALSE) -> 22030 | G21: =VLOOKUP($A21,'All Contract Holders'!$A$5:$K$40,7,FALSE) -> John R. Wheeler | H21: =VLOOKUP($A21,'All Contract Holders'!$A$5:$K$40,8,FALSE) -> gsavets@veterancorps.com | I21: =VLOOKUP($A21,'All Contract Holders'!$A$5:$K$40,9,FALSE) -> www.veterancorps.com | J21: =VLOOKUP($A21,'All Contract Holders'!$A$5:$K$40,10,FALSE) -> (703) 691-8387 | K21: =VLOOKUP($A21,'All Contract Holders'!$A$5:$K$40,11,FALSE) -> (703) 691-8385 | L21: x | M21: x | N21: x
A22: GS-06F-0530Z | B22: =VLOOKUP($A22,'All Contract Holders'!$A$5:$K$40,2,FALSE) -> Veteran Engineering & Technology, LLC | C22: =VLOOKUP($A22,'All Contract Holders'!$A$5:$K$40,3,FALSE) -> 5475 Mark Dabling Blvd, Suite 300 | D22: =VLOOKUP($A22,'All Contract Holders'!$A$5:$K$40,4,FALSE) -> Colorado Springs | E22: =VLOOKUP($A22,'All Contract Holders'!$A$5:$K$40,5,FALSE) -> CO | F22: =VLOOKUP($A22,'All Contract Holders'!$A$5:$K$40,6,FALSE) -> 80918 | G22: =VLOOKUP($A22,'All Contract Holders'!$A$5:$K$40,7,FALSE) -> Craig Newmaker, Norm Andersson | H22: =VLOOKUP($A22,'All Contract Holders'!$A$5:$K$40,8,FALSE) -> engineering@vetengineering.com | I22: =VLOOKUP($A22,'All Contract Holders'!$A$5:$K$40,9,FALSE) -> www.vetengineering.com | J22: =VLOOKUP($A22,'All Contract Holders'!$A$5:$K$40,10,FALSE) -> (719) 623-3600 | K22: =VLOOKUP($A22,'All Contract Holders'!$A$5:$K$40,11,FALSE) -> (877) 870-9002 | L22: x | M22: x | N22: x
A23: GS-06F-0532Z | B23: =VLOOKUP($A23,'All Contract Holders'!$A$5:$K$40,2,FALSE) -> Veterans Enterprise Technology Solutions, INC | C23: =VLOOKUP($A23,'All Contract Holders'!$A$5:$K$40,3,FALSE) -> 2057 Woodford Road, STE 200 | D23: =VLOOKUP($A23,'All Contract Holders'!$A$5:$K$40,4,FALSE) -> Vienna | E23: =VLOOKUP($A23,'All Contract Holders'!$A$5:$K$40,5,FALSE) -> VA | F23: =VLOOKUP($A23,'All Contract Holders'!$A$5:$K$40,6,FALSE) -> 22182 | G23: =VLOOKUP($A23,'All Contract Holders'!$A$5:$K$40,7,FALSE) -> James H. Moody | H23: =VLOOKUP($A23,'All Contract Holders'!$A$5:$K$40,8,FALSE) -> jmoody@vets-inc.com, HEdwards@vets-inc.com | I23: =VLOOKUP($A23,'All Contract Holders'!$A$5:$K$40,9,FALSE) -> www.vets-inc.com | J23: =VLOOKUP($A23,'All Contract Holders'!$A$5:$K$40,10,FALSE) -> (434) 374-5899 | K23: =VLOOKUP($A23,'All Contract Holders'!$A$5:$K$40,11,FALSE) -> (866) 320-0911 | L23: x | M23: x | N23: x
A24: GS-06F-0533Z | B24: =VLOOKUP($A24,'All Contract Holders'!$A$5:$K$40,2,FALSE) -> Vetsamerica Business Consulting, INC | C24: =VLOOKUP($A24,'All Contract Holders'!$A$5:$K$40,3,FALSE) -> 8300 Greensboro Drive, Suite 800 | D24: =VLOOKUP($A24,'All Contract Holders'!$A$5:$K$40,4,FALSE) -> McLean | E24: =VLOOKUP($A24,'All Contract Holders'!$A$5:$K$40,5,FALSE) -> VA | F24: =VLOOKUP($A24,'All Contract Holders'!$A$5:$K$40,6,FALSE) -> 22102 | G24: =VLOOKUP($A24,'All Contract Holders'!$A$5:$K$40,7,FALSE) -> John Collins | H24: =VLOOKUP($A24,'All Contract Holders'!$A$5:$K$40,8,FALSE) -> johncollins@vetsamerica.us | I24: =VLOOKUP($A24,'All Contract Holders'!$A$5:$K$40,9,FALSE) -> www.vetsamerica.us | J24: =VLOOKUP($A24,'All Contract Holders'!$A$5:$K$40,10,FALSE) -> (843) 238-2517 | K24: =VLOOKUP($A24,'All Contract Holders'!$A$5:$K$40,11,FALSE) -> (843) 238-8426 | L24: x | M24: x | N24: x
A27: Large Strategic Partner Contractors
A28: Contract Numbers | B28: Vendor Name | C28: Vendor Address | D28: City | E28: State | F28: Zip Code | G28: Vendor Contact Name | H28: Email Address | I28: Website | J28: Phone | K28: Fax | L28: FA1 | M28: FA2
A29: GS-06F-0511Z | B29: =VLOOKUP($A29,'All Contract Holders'!$A$5:$K$40,2,FALSE) -> Catapult Technology, LTD | C29: =VLOOKUP($A29,'All Contract Holders'!$A$5:$K$40,3,FALSE) -> 7500 Old Georgetown Road, 11th Floor | D29: =VLOOKUP($A29,'All Contract Holders'!$A$5:$K$40,4,FALSE) -> Bethesda | E29: =VLOOKUP($A29,'All Contract Holders'!$A$5:$K$40,5,FALSE) -> MD | F29: =VLOOKUP($A29,'All Contract Holders'!$A$5:$K$40,6,FALSE) -> 20814-6198 | G29: =VLOOKUP($A29,'All Contract Holders'!$A$5:$K$40,7,FALSE) -> Jane Green | H29: =VLOOKUP($A29,'All Contract Holders'!$A$5:$K$40,8,FALSE) -> gsavets@catapulttechnology.com | I29: =VLOOKUP($A29,'All Contract Holders'!$A$5:$K$40,9,FALSE) -> www.catapulttechnology.com | J29: =VLOOKUP($A29,'All Contract Holders'!$A$5:$K$40,10,FALSE) -> (240) 482-2136 | K29: =VLOOKUP($A29,'All Contract Holders'!$A$5:$K$40,11,FALSE) -> (888) 338-1391 | L29: x | M29: x
A30: GS-06F-0525Z | B30: =VLOOKUP($A30,'All Contract Holders'!$A$5:$K$40,2,FALSE) -> Council for Logistics Research, Inc. | C30: =VLOOKUP($A30,'All Contract Holders'!$A$5:$K$40,3,FALSE) -> 1550 Crystal Drive, Suite 500 | D30: =VLOOKUP($A30,'All Contract Holders'!$A$5:$K$40,4,FALSE) -> Arlington | E30: =VLOOKUP($A30,'All Contract Holders'!$A$5:$K$40,5,FALSE) -> VA | F30: =VLOOKUP($A30,'All Contract Holders'!$A$5:$K$40,6,FALSE) -> 22202 | G30: =VLOOKUP($A30,'All Contract Holders'!$A$5:$K$40,7,FALSE) -> Maureen Soldano | H30: =VLOOKUP($A30,'All Contract Holders'!$A$5:$K$40,8,FALSE) -> vets@clrexec.com, msoldano@clrexec.com | I30: =VLOOKUP($A30,'All Contract Holders'!$A$5:$K$40,9,FALSE) -> www.clrexec.com | J30: =VLOOKUP($A30,'All Contract Holders'!$A$5:$K$40,10,FALSE) -> (703) 412-1563 | K30: =VLOOKUP($A30,'All Contract Holders'!$A$5:$K$40,11,FALSE) -> (703) 412-1564 | M30: x
A31: GS-06F-0514Z | B31: =VLOOKUP($A31,'All Contract Holders'!$A$5:$K$40,2,FALSE) -> Engineering Services Network, Inc. | C31: =VLOOKUP($A31,'All Contract Holders'!$A$5:$K$40,3,FALSE) -> 2450 Crystal Drive, Suite 1015 | D31: =VLOOKUP($A31,'All Contract Holders'!$A$5:$K$40,4,FALSE) -> Arlington | E31: =VLOOKUP($A31,'All Contract Holders'!$A$5:$K$40,5,FALSE) -> VA | F31: =VLOOKUP($A31,'All Contract Holders'!$A$5:$K$40,6,FALSE) -> 22202 | G31: =VLOOKUP($A31,'All Contract Holders'!$A$5:$K$40,7,FALSE) -> Michelle "Shelly" Smith | H31: =VLOOKUP($A31,'All Contract Holders'!$A$5:$K$40,8,FALSE) -> esncontracts@esncc.com | I31: =VLOOKUP($A31,'All Contract Holders'!$A$5:$K$40,9,FALSE) -> www.esncc.com | J31: =VLOOKUP($A31,'All Contract Holders'!$A$5:$K$40,10,FALSE) -> (703) 412-3640 | K31: =VLOOKUP($A31,'All Contract Holders'!$A$5:$K$40,11,FALSE) -> (703) 412-3643 | L31: x | M31: x
A32: GS-06F-0543Z | B32: =VLOOKUP($A32,'All Contract Holders'!$A$5:$K$40,2,FALSE) -> Metters Industries, INC | C32: =VLOOKUP($A32,'All Contract Holders'!$A$5:$K$40,3,FALSE) -> 8200 Greensboro Drive, STE 500 | D32: =VLOOKUP($A32,'All Contract Holders'!$A$5:$K$40,4,FALSE) -> McLean | E32: =VLOOKUP($A32,'All Contract Holders'!$A$5:$K$40,5,FALSE) -> VA | F32: =VLOOKUP($A32,'All Contract Holders'!$A$5:$K$40,6,FALSE) -> 22102 | G32: =VLOOKUP($A32,'All Contract Holders'!$A$5:$K$40,7,FALSE) -> Will Dolan, Bob LeFebvre | H32: =VLOOKUP($A32,'All Contract Holders'!$A$5:$K$40,8,FALSE) -> MI-GSA-VETSGWAC@metters.com, Bob.Lefebvre@metters.com | I32: =VLOOKUP($A32,'All Contract Holders'!$A$5:$K$40,9,FALSE) -> www.metters.com | J32: =VLOOKUP($A32,'All Contract Holders'!$A$5:$K$40,10,FALSE) -> (703) 821-3300 ext 709 | K32: =VLOOKUP($A32,'All Contract Holders'!$A$5:$K$40,11,FALSE) -> (703) 821-3996 | L32: x | M32: x
