Workbook

Sheet Summary
A1: FY 2012
A2: Telecommunications Equity Aid
A4: PAYMENTS TO TELECOM ACCESS CLUSTERS | F4: DIRECT PAYMENTS TO SCHOOLS
A6: Cluster | B6: NUMBER | C6: Aid Eligible | D6: Prorated Aid | F6: None
A7: CMETS | B7: 01-206 | C7: ='Schools by Cluster Group'!O11 -> 118050.74 | D7: ='Schools by Cluster Group'!Q11 -> 54618.46
A8: ECMECC | B8: 50-6003 | C8: ='Schools by Cluster Group'!O27 -> 548617.9 | D8: ='Schools by Cluster Group'!Q27 -> 253828.76
A9: FRESHWATER ED. DIST. | B9: 61-6004 | C9: ='Schools by Cluster Group'!O40 -> 45305.74 | D9: ='Schools by Cluster Group'!Q40 -> 20961.58
A10: REGION 10 - SOUTHEAST SERVICE COOP | B10: 83-0921 | C10: ='Schools by Cluster Group'!O60 -> 569516.78 | D10: ='Schools by Cluster Group'!Q60 -> 263498.02
A11: IASC | B11: 50-6070 | C11: ='Schools by Cluster Group'!O70 -> 75790.01 | D11: ='Schools by Cluster Group'!Q70 -> 35065.72
A12: LITTLE CROW TELE-MEDIA NETWORK | B12: 50-6040 | C12: ='Schools by Cluster Group'!O84 -> 322598 | D12: ='Schools by Cluster Group'!Q84 -> 149256.23
A13: MSET | B13: 61-6979 | C13: ='Schools by Cluster Group'!O96 -> 115285.23 | D13: ='Schools by Cluster Group'!Q96 -> 53338.95
A14: MNRVED | B14: 61-6018 | C14: ='Schools by Cluster Group'!O106 -> 119557.91 | D14: ='Schools by Cluster Group'!Q106 -> 55315.82
A15: NW LINKS (REGION I) | B15: 82-0869 | C15: ='Schools by Cluster Group'!O172 -> 879326.4 | D15: ='Schools by Cluster Group'!Q172 -> 406837.47
A16: REDWOOD AREA TELECOM COOPERATIVE | B16: 01-2890 | C16: ='Schools by Cluster Group'!O178 -> 23519.72 | D16: ='Schools by Cluster Group'!Q178 -> 10881.85
A17: REGION 2 - ARCC | B17: 82-0868 | C17: ='Schools by Cluster Group'!O190 -> 82066.97 | D17: ='Schools by Cluster Group'!Q190 -> 37969.88
A18: CENTRAL | B18: 82-0867 | C18: ='Schools by Cluster Group'!O214 -> 350028 | D18: ='Schools by Cluster Group'!Q214 -> 161947.27
A19: NESC | B19: 83-0927 | C19: ='Schools by Cluster Group'!O234 -> 536144.05 | D19: ='Schools by Cluster Group'!Q234 -> 248057.5
A20: Ties (Region 7) | B20: 82-0925 | C20: ='Schools by Cluster Group'!O275 -> 2492939 | D20: ='Schools by Cluster Group'!Q275 -> 1153406.7
A21: SOUTHWEST (Region 6 & 8) | B21: 83-0991 | C21: ='Schools by Cluster Group'!O311 -> 683147.3 | D21: ='Schools by Cluster Group'!Q311 -> 316071.4
A22: SOCRATES | B22: 50-6036 | C22: ='Schools by Cluster Group'!O342 -> 986300.58 | D22: ='Schools by Cluster Group'!Q342 -> 456331.15
A23: WETC | B23: 50-6048 | C23: ='Schools by Cluster Group'!O348 -> 131424.98 | D23: ='Schools by Cluster Group'!Q348 -> 60806.32
A24: SCSN | B24: 01-720 | C24: ='Schools by Cluster Group'!O353 -> 25519 | D24: ='Schools by Cluster Group'!Q353 -> 11806.86
A25: TOTAL | C25: =SUM(C7:C24) -> 8105138.3 | D25: =SUM(D7:D24) -> 3750000
A29: Proration Rate > | B29: 0.46266947

Sheet Schools by Cluster Group
A1: Dist Num | B1: District Or School Name | C1: Cluster Name | D1: Cluster Num | E1: Cluster Type | F1: Line Lease Before Erate | G1: Line Lease After Erate | H1: Install Before E Rate | I1: E Rate Discount Install | J1: Install After E Rate | K1: COOP Costs | L1: Maint Costs | M1: E Rate Discount | N1: Total Before E Rate | O1: Total After E Rate | P1: Prorated Aid Amount | Q1: Rounded
A2: 206 | B2: ALEXANDRIA PUBLIC SCHOOL DISTRICT | C2: CENTRAL MN ED TELECOM SYSTEM | D2: 6054 | E2: 50 | F2: 63276.98 | G2: 23354.5 | H2: 0 | I2: 0 | J2: 0 | K2: 0 | L2: 4680 | M2: 39922.48 | N2: 67956.98 | O2: 28034.5 | P2: =O2*Summary!$B$29 -> 12970.707 | Q2: =ROUND(P2,2) -> 12970.71
A3: 207 | B3: BRANDON PUBLIC SCHOOL DISTRICT | C3: CENTRAL MN ED TELECOM SYSTEM | D3: 6054 | E3: 50 | F3: 24859.46 | G3: 9610.56 | H3: 0 | I3: 0 | J3: 0 | K3: 0 | L3: 0 | M3: 15248.9 | N3: 24859.46 | O3: 9610.56 | P3: =O3*Summary!$B$29 -> 4446.5127 | Q3: =ROUND(P3,2) -> 4446.51
A4: 208 | B4: EVANSVILLE PUBLIC SCHOOL DISTRICT | C4: CENTRAL MN ED TELECOM SYSTEM | D4: 6054 | E4: 50 | F4: 24859.46 | G4: 9610.56 | H4: 0 | I4: 0 | J4: 0 | K4: 0 | L4: 0 | M4: 15248.9 | N4: 24859.46 | O4: 9610.56 | P4: =O4*Summary!$B$29 -> 4446.5127 | Q4: =ROUND(P4,2) -> 4446.51
A5: 213 | B5: OSAKIS PUBLIC SCHOOL DISTRICT | C5: CENTRAL MN ED TELECOM SYSTEM | D5: 6054 | E5: 50 | F5: 24859.46 | G5: 9610.56 | H5: 0 | I5: 0 | J5: 0 | K5: 0 | L5: 0 | M5: 15248.9 | N5: 24859.46 | O5: 9610.56 | P5: =O5*Summary!$B$29 -> 4446.5127 | Q5: =ROUND(P5,2) -> 4446.51
A6: 547 | B6: PARKERS PRAIRIE PUBLIC SCHOOL DIST. | C6: CENTRAL MN ED TELECOM SYSTEM | D6: 6054 | E6: 50 | F6: 24859.46 | G6: 9610.56 | H6: 0 | I6: 0 | J6: 0 | K6: 0 | L6: 0 | M6: 15248.9 | N6: 24859.46 | O6: 9610.56 | P6: =O6*Summary!$B$29 -> 4446.5127 | Q6: =ROUND(P6,2) -> 4446.51
A7: 740 | B7: MELROSE PUBLIC SCHOOL DISTRICT | C7: CENTRAL MN ED TELECOM SYSTEM | D7: 6054 | E7: 50 | F7: 24859.46 | G7: 9610.56 | H7: 0 | I7: 0 | J7: 0 | K7: 0 | L7: 0 | M7: 15248.9 | N7: 24859.46 | O7: 9610.56 | P7: =O7*Summary!$B$29 -> 4446.5127 | Q7: =ROUND(P7,2) -> 4446.51
A8: 743 | B8: SAUK CENTRE PUBLIC SCHOOL DISTRICT | C8: CENTRAL MN ED TELECOM SYSTEM | D8: 6054 | E8: 50 | F8: 24859.46 | G8: 9610.56 | H8: 0 | I8: 0 | J8: 0 | K8: 0 | L8: 0 | M8: 15248.9 | N8: 24859.46 | O8: 9610.56 | P8: =O8*Summary!$B$29 -> 4446.5127 | Q8: =ROUND(P8,2) -> 4446.51
A9: 745 | B9: ALBANY PUBLIC SCHOOL DISTRICT | C9: CENTRAL MN ED TELECOM SYSTEM | D9: 6054 | E9: 50 | F9: 24859.46 | G9: 9610.56 | H9: 0 | I9: 0 | J9: 0 | K9: 0 | L9: 0 | M9: 15248.9 | N9: 24859.46 | O9: 9610.56 | P9: =O9*Summary!$B$29 -> 4446.5127 | Q9: =ROUND(P9,2) -> 4446.51
A10: 2149 | B10: MINNEWASKA SCHOOL DISTRICT | C10: CENTRAL MN ED TELECOM SYSTEM | D10: 6054 | E10: 50 | F10: 63311.46 | G10: 22742.32 | H10: 0 | I10: 0 | J10: 0 | K10: 0 | L10: 0 | M10: 40569.14 | N10: 63311.46 | O10: 22742.32 | P10: =O10*Summary!$B$29 -> 10522.177 | Q10: =ROUND(P10,2) -> 10522.18
M11: =SUM(M2:M10) -> 187233.92 | N11: =SUM(N2:N10) -> 305284.66 | O11: =SUM(O2:O10) -> 118050.74 | P11: =SUM(P2:P10) -> 54618.473 | Q11: =SUM(Q2:Q10) -> 54618.46
A14: 15 | B14: ST. FRANCIS PUBLIC SCHOOL DISTRICT | C14: EAST CENTRAL MN ED. CABLE COOP. | D14: 6003 | E14: 50 | F14: 73845 | G14: 35088.3 | H14: 0 | I14: 0 | J14: 0 | K14: 27771.71 | L14: 0 | M14: 38756.7 | N14: 101616.71 | O14: 62860.01 | P14: =O14*Summary!$B$29 -> 29083.407 | Q14: =ROUND(P14,2) -> 29083.41
A15: 138 | B15: NORTH BRANCH PUBLIC SCHOOLS | C15: EAST CENTRAL MN ED. CABLE COOP. | D15: 6003 | E15: 50 | F15: 55740 | G15: 25105.2 | H15: 0 | I15: 0 | J15: 0 | K15: 20483.21 | L15: 323.6 | M15: 30634.8 | N15: 76546.81 | O15: 45912.01 | P15: =O15*Summary!$B$29 -> 21242.085 | Q15: =ROUND(P15,2) -> 21242.09
A16: 139 | B16: RUSH CITY PUBLIC SCHOOL DISTRICT | C16: EAST CENTRAL MN ED. CABLE COOP. | D16: 6003 | E16: 50 | F16: 47235 | G16: 19963.5 | H16: 0 | I16: 0 | J16: 0 | K16: 10062.26 | L16: 0 | M16: 27271.5 | N16: 57297.26 | O16: 30025.76 | P16: =O16*Summary!$B$29 -> 13892.002 | Q16: =ROUND(P16,2) -> 13892
A17: 314 | B17: BRAHAM PUBLIC SCHOOL DISTRICT | C17: EAST CENTRAL MN ED. CABLE COOP. | D17: 6003 | E17: 50 | F17: 50700 | G17: 19422 | H17: 0 | I17: 0 | J17: 0 | K17: 15406.23 | L17: 0 | M17: 31278 | N17: 66106.23 | O17: 34828.23 | P17: =O17*Summary!$B$29 -> 16113.959 | Q17: =ROUND(P17,2) -> 16113.96
A18: 332 | B18: MORA PUBLIC SCHOOL DISTRICT | C18: EAST CENTRAL MN ED. CABLE COOP. | D18: 6003 | E18: 50 | F18: 47310 | G18: 16819.5 | H18: 0 | I18: 0 | J18: 0 | K18: 13186.52 | L18: 0 | M18: 30490.5 | N18: 60496.52 | O18: 30006.02 | P18: =O18*Summary!$B$29 -> 13882.869 | Q18: =ROUND(P18,2) -> 13882.87
A19: 333 | B19: OGILVIE PUBLIC SCHOOL DISTRICT | C19: EAST CENTRAL MN ED. CABLE COOP. | D19: 6003 | E19: 50 | F19: 37875 | G19: 12928.5 | H19: 0 | I19: 0 | J19: 0 | K19: 8124.92 | L19: 0 | M19: 24946.5 | N19: 45999.92 | O19: 21053.42 | P19: =O19*Summary!$B$29 -> 9740.7746 | Q19: =ROUND(P19,2) -> 9740.77
A20: 477 | B20: PRINCETON PUBLIC SCHOOL DISTRICT | C20: EAST CENTRAL MN ED. CABLE COOP. | D20: 6003 | E20: 50 | F20: 48015 | G20: 18819.45 | H20: 0 | I20: 0 | J20: 0 | K20: 19823.67 | L20: 2034.4 | M20: 29195.55 | N20: 69873.07 | O20: 40677.52 | P20: =O20*Summary!$B$29 -> 18820.246 | Q20: =ROUND(P20,2) -> 18820.25
A21: 578 | B21: PINE CITY PUBLIC SCHOOL DISTRICT | C21: EAST CENTRAL MN ED. CABLE COOP. | D21: 6003 | E21: 50 | F21: 56855 | G21: 20276.25 | H21: 0 | I21: 0 | J21: 0 | K21: 18873.64 | L21: 0 | M21: 36578.75 | N21: 75728.64 | O21: 39149.89 | P21: =O21*Summary!$B$29 -> 18113.459 | Q21: =ROUND(P21,2) -> 18113.46
A22: 911 | B22: CAMBRIDGE-ISANTI PUBLIC SCHOOL DIST | C22: EAST CENTRAL MN ED. CABLE COOP. | D22: 6003 | E22: 50 | F22: 93840 | G22: 41616 | H22: 0 | I22: 0 | J22: 0 | K22: 26903.3 | L22: 0 | M22: 52224 | N22: 120743.3 | O22: 68519.3 | P22: =O22*Summary!$B$29 -> 31701.788 | Q22: =ROUND(P22,2) -> 31701.79
A23: 912 | B23: MILACA PUBLIC SCHOOL DISTRICT | C23: EAST CENTRAL MN ED. CABLE COOP. | D23: 6003 | E23: 50 | F23: 44895 | G23: 16914 | H23: 0 | I23: 0 | J23: 0 | K23: 13496.67 | L23: 0 | M23: 27981 | N23: 58391.67 | O23: 30410.67 | P23: =O23*Summary!$B$29 -> 14070.088 | Q23: =ROUND(P23,2) -> 14070.09
A24: 2144 | B24: CHISAGO LAKES SCHOOL DISTRICT | C24: EAST CENTRAL MN ED. CABLE COOP. | D24: 6003 | E24: 50 | F24: 96270 | G24: 55407.3 | H24: 0 | I24: 0 | J24: 0 | K24: 20512.16 | L24: 1028 | M24: 40862.7 | N24: 117810.16 | O24: 76947.46 | P24: =O24*Summary!$B$29 -> 35601.24 | Q24: =ROUND(P24,2) -> 35601.24
A25: 2165 | B25: HINCKLEY-FINLAYSON SCHOOL DISTRICT | C25: EAST CENTRAL MN ED. CABLE COOP. | D25: 6003 | E25: 50 | F25: 73640 | G25: 23636.4 | H25: 0 | I25: 0 | J25: 0 | K25: 16268.4 | L25: 0 | M25: 50003.6 | N25: 89908.4 | O25: 39904.8 | P25: =O25*Summary!$B$29 -> 18462.732 | Q25: =ROUND(P25,2) -> 18462.73
A26: 2580 | B26: EAST CENTRAL SCHOOL DISTRICT | C26: EAST CENTRAL MN ED. CABLE COOP. | D26: 6003 | E26: 50 | F26: 44718 | G26: 13026.2 | H26: 0 | I26: 0 | J26: 0 | K26: 15296.61 | L26: 0 | M26: 31691.8 | N26: 60014.61 | O26: 28322.81 | P26: =O26*Summary!$B$29 -> 13104.099 | Q26: =ROUND(P26,2) -> 13104.1
M27: =SUM(M14:M26) -> 451915.4 | N27: =SUM(N14:N26) -> 1000533.3 | O27: =SUM(O14:O26) -> 548617.9 | P27: =SUM(P14:P26) -> 253828.75 | Q27: =SUM(Q14:Q26) -> 253828.76
A30: 116 | B30: PILLAGER PUBLIC SCHOOL DISTRICT | C30: FRESHWATER ED. DIST. | D30: 6004 | E30: 61 | F30: 9018 | G30: 1803.6 | H30: 0 | I30: 0 | J30: 0 | K30: 863.08 | L30: 1797.5 | M30: 7214.4 | N30: 11678.58 | O30: 4464.18 | P30: =O30*Summary!$B$29 -> 2065.4398 | Q30: =ROUND(P30,2) -> 2065.44
A31: 545 | B31: HENNING PUBLIC SCHOOL DISTRICT | C31: FRESHWATER ED. DIST. | D31: 6004 | E31: 61 | F31: 12480 | G31: 3744 | H31: 0 | I31: 0 | J31: 0 | K31: 1797.5 | L31: 863.08 | M31: 8736 | N31: 15140.58 | O31: 6404.58 | P31: =O31*Summary!$B$29 -> 2963.2036 | Q31: =ROUND(P31,2) -> 2963.2
A32: 786 | B32: BERTHA-HEWITT PUBLIC SCHOOL DIST. | C32: FRESHWATER ED. DIST. | D32: 6004 | E32: 61 | F32: 11856 | G32: 2371.2 | H32: 0 | I32: 0 | J32: 0 | K32: 0 | L32: 0 | M32: 9484.8 | N32: 11856 | O32: 2371.2 | P32: =O32*Summary!$B$29 -> 1097.0818 | Q32: =ROUND(P32,2) -> 1097.08
A33: 787 | B33: BROWERVILLE PUBLIC SCHOOL DISTRICT | C33: FRESHWATER ED. DIST. | D33: 6004 | E33: 61 | F33: 12096 | G33: 2419.2 | H33: 0 | I33: 0 | J33: 0 | K33: 0 | L33: 0 | M33: 9676.8 | N33: 12096 | O33: 2419.2 | P33: =O33*Summary!$B$29 -> 1119.29 | Q33: =ROUND(P33,2) -> 1119.29
A34: 818 | B34: VERNDALE PUBLIC SCHOOL DISTRICT | C34: FRESHWATER ED. DIST. | D34: 6004 | E34: 61 | F34: 8502.84 | G34: 1700.57 | H34: 0 | I34: 0 | J34: 0 | K34: 863.08 | L34: 1797.5 | M34: 6802.27 | N34: 11163.42 | O34: 4361.15 | P34: =O34*Summary!$B$29 -> 2017.7709 | Q34: =ROUND(P34,2) -> 2017.77
A35: 820 | B35: SEBEKA PUBLIC SCHOOL DISTRICT | C35: FRESHWATER ED. DIST. | D35: 6004 | E35: 61 | F35: 8502.96 | G35: 1700.59 | H35: 0 | I35: 0 | J35: 0 | K35: 863.08 | L35: 1797.5 | M35: 6802.37 | N35: 11163.54 | O35: 4361.17 | P35: =O35*Summary!$B$29 -> 2017.7802 | Q35: =ROUND(P35,2) -> 2017.78
A36: 821 | B36: MENAHGA PUBLIC SCHOOL DISTRICT | C36: FRESHWATER ED. DIST. | D36: 6004 | E36: 61 | F36: 8502.96 | G36: 2040.71 | H36: 0 | I36: 0 | J36: 0 | K36: 1797.5 | L36: 863.08 | M36: 6462.25 | N36: 11163.54 | O36: 4701.29 | P36: =O36*Summary!$B$29 -> 2175.1433 | Q36: =ROUND(P36,2) -> 2175.14
A37: 2155 | B37: WADENA-DEER CREEK SCHOOL DISTRICT | C37: FRESHWATER ED. DIST. | D37: 6004 | E37: 61 | F37: 10575 | G37: 2115 | H37: 0 | I37: 0 | J37: 0 | K37: 863.08 | L37: 1797.5 | M37: 8460 | N37: 13235.58 | O37: 4775.58 | P37: =O37*Summary!$B$29 -> 2209.515 | Q37: =ROUND(P37,2) -> 2209.52
A38: 2170 | B38: STAPLES-MOTLEY SCHOOL DISTRICT | C38: FRESHWATER ED. DIST. | D38: 6004 | E38: 61 | F38: 12698.57 | G38: 2683.56 | H38: 0 | I38: 0 | J38: 0 | K38: 1797.5 | L38: 0 | M38: 10015.01 | N38: 14496.07 | O38: 4481.06 | P38: =O38*Summary!$B$29 -> 2073.2496 | Q38: =ROUND(P38,2) -> 2073.25
A39: 2759 | B39: EAGLE VALLEY PUBLIC SCHOOL DISTRICT | C39: FRESHWATER ED. DIST. | D39: 6004 | E39: 61 | F39: 17223 | G39: 4305.75 | H39: 0 | I39: 0 | J39: 0 | K39: 863.08 | L39: 1797.5 | M39: 12917.25 | N39: 19883.58 | O39: 6966.33 | P39: =O39*Summary!$B$29 -> 3223.1082 | Q39: =ROUND(P39,2) -> 3223.11
M40: =SUM(M30:M39) -> 86571.15 | N40: =SUM(N30:N39) -> 131876.89 | O40: =SUM(O30:O39) -> 45305.74 | P40: =SUM(P30:P39) -> 20961.582 | Q40: =SUM(Q30:Q39) -> 20961.58
A43: 227 | B43: CHATFIELD PUBLIC SCHOOLS | C43: REGION 10 - SOUTHEAST SERVICE COOP | D43: 921 | E43: 83 | F43: 50973.56 | G43: 28035.46 | H43: 1900 | I43: 855 | J43: 1045 | K43: 1599.95 | L43: 0 | M43: 23793.1 | N43: 54473.51 | O43: 30680.41 | P43: =O43*Summary!$B$29 -> 14194.889 | Q43: =ROUND(P43,2) -> 14194.89
A44: 241 | B44: ALBERT LEA PUBLIC SCHOOL DISTRICT | C44: REGION 10 - SOUTHEAST SERVICE COOP | D44: 921 | E44: 83 | F44: 113340 | G44: 35135.4 | H44: 1250 | J44: 1250 | K44: 1000 | L44: 0 | M44: 78204.6 | N44: 115590 | O44: 37385.4 | P44: =O44*Summary!$B$29 -> 17297.083 | Q44: =ROUND(P44,2) -> 17297.08
A45: 252 | B45: CANNON FALLS PUBLIC SCHOOL DISTRICT | C45: REGION 10 - SOUTHEAST SERVICE COOP | D45: 921 | E45: 83 | F45: 65446.01 | G45: 32722.86 | H45: 0 | I45: 0 | J45: 0 | K45: 1446.54 | L45: 0 | M45: 32723.15 | N45: 66892.55 | O45: 34169.4 | P45: =O45*Summary!$B$29 -> 15809.138 | Q45: =ROUND(P45,2) -> 15809.14
A46: 255 | B46: PINE ISLAND PUBLIC SCHOOL DIST. | C46: REGION 10 - SOUTHEAST SERVICE COOP | D46: 921 | E46: 83 | F46: 67583.25 | G46: 31507.67 | H46: 0 | I46: 0 | J46: 0 | K46: 1232.64 | L46: 0 | M46: 36075.58 | N46: 68815.89 | O46: 32740.31 | P46: =O46*Summary!$B$29 -> 15147.942 | Q46: =ROUND(P46,2) -> 15147.94
...
