Workbook

Sheet Sample Non-Price Criteria 
A1: Sample Non-Price Criteria for Evaluation of Proposals
A2: (Insert Desired Evaluation Criteria on Point Calculator Sheet)
A4: District Manager Support
B5: Location of District Manager (in-state or out-of-state)
B6: Experience managing K-12 school districts
B7: Experience staffing K-12 food service programs
B8: Professional development provided for district manager
B9: Knowledge and ability to work with union employees
B10: Knowledge and ability to understand and honor collective bargaining agreements
B11: Level of support and guidance provided to on-site manager
B12: Level of support and guidance received from upper level management
A13: Employee Training and Development
B14: Training program for foodservice employees
B15: Examples of training materials used for foodservice employees
B16: Food safety and sanitation training/Hazard Analysis and Critical Control Points (HACCP)
B17: Work safety (lifting, bending, cutting, slicing, etc.)
B18: Portion control and quantity food production
B19: Professional development provided for on-site manager
A20: Evaluation of FSMC References
B21: Relationship/Communication with the School District
B22: Student/Staff/Parent Satisfaction
B23: Maintenance of kitchen and food serving areas/equipment
B24: Awareness and timely compliance with government regulations/requirements
B25: Projected operating budgets/forecasts meet established goals/timelines
A26: Integrity and Reliability of Projected Operating Budget/Forecast
B27: Integrity of cost and revenue information
B28: Recommendations made to adjust forecast
B29: Methods used to monitor food and non-food cost
B30: Methods used to monitor labor cost
B31: Financial Reports for Revenue and Cost (monthly, quarterly, etc.)
A32: Manager Candidate
B33: Experience working in school foodservice
B34: Experience staffing K-12 breakfast and lunch programs
B35: Experience with menu development and special events
B36: Experience conducting procurement
B37: Experience working with USDA Commodities
B38: Experience working collaboratively with various school personnel (i.e., wellness programs)
B39: Knowledge and ability to work with union employees
B40: Knowledge and ability to understand and honor collective bargaining agreements
B41: Professional development provided for manager candidate (workshops, continuing education, etc)
...

Sheet Point Calculator - Instructions
A1: Instructions for Completing Evaluation Criteria and Point Calculator:
A2: The Point Calculator may be used to calculate the total number of points awarded by the SFA to each proposal. The Point Calculator can be used for either a cost-reimbursable or a fixed meal price contract.
A3: 1. At the top of the spreadsheet, type in each company name. The companies must be listed in order of lowest price, with the lowest price at the left and highest price at the right.
A4: 2. In the cell for “Points Available for Low Price” line, type in the maximum number of points that the school has set to be available based on the price portion of each proposal. Federal procurement regulations require that the number of points avalable for low price be greater than the number of points available for any other criterion. There is no maximum limit to the number of points that may be awarded for low price.
A5: 3. On the “Grand Total" line, type in the grand total costs from each proposal.
A6: 4. Once the required information on costs from each proposal has been entered on the spreadsheet, the numbers for “Percent of points Awarded for Low Price” and “Total Points Awarded for Low Price” will automatically populate for each proposal.
A7: “Percent of points Awarded for Low Price” – This line shows the percentage, out of the total points available for price, to be awarded to each company. The lowest price proposal, listed in the column farthest to the left, receives 100 percent of maximum points; the other proposals receive fewer points in descending order. The default calculation in the spreadsheet awards, for example, 95% of available points to a price that exceeded the low price by 5 percent. However this specific manner of calculating points for price on the spreadsheet is not required – the school may change these equations on the spreadsheet, or may make these calculations manually, so that the percentages on this line will calculate as specified by the school. For example, the school could give more importance to price by changing the equation so that a bid price that is 5 percent higher than the lowest bid price would receive a lower percentage such as 90 percent of price points rather than 95 percent.
A8: “Total Points Awarded for Low Price” – This line shows the total number of points awarded to each proposal based on how low the price is. These numbers automatically populate based on the percentages shown on the previous line, multiplied by the maximum number of points that are available based on price.
A9: 5. In the non-price criteria section in the lower part of the spreadsheet, list the school’s non-price criteria (add or delete from the sample list of criteria as needed) and show the maximum available points in the column to the left of each criterion. The number of points assigned to any non-price criterion may not be greater than the number of points assigned to price. For each company's proposal, enter the number of points that the school awarded for each of the non-price criteria.
A10: 6. After price and non-price points have been entered on the spreadsheet for each proposal, the total number of points (price + non-price) for each company will automatically populate in the final row of the spreadsheet. School awards contract to the company that received the most total points.

Sheet Point Calculator
A1: Sample Evaluation Criteria and Point Calculator
E2: Company Name
B5: Maximum Points Available for Low Price
B7: Grand Total Proposed Price
B9: Percent of Points Awarded for Low Price | C9: 1 | D9: =1-(D7-$C$7)/$C$7 -> #DIV/0! | E9: =1-(E7-$C$7)/$C$7 -> #DIV/0! | F9: =1-(F7-$C$7)/$C$7 -> #DIV/0! | G9: =1-(G7-$C$7)/$C$7 -> #DIV/0! | H9: =1-(H7-$C$7)/$C$7 -> #DIV/0!
B11: Total Points Awarded for Low Price | C11: =$C$5*C9 -> 0 | D11: =$C$5*D9 -> #DIV/0! | E11: =$C$5*E9 -> #DIV/0! | F11: =$C$5*F9 -> #DIV/0! | G11: =$C$5*G9 -> #DIV/0! | H11: =$C$5*H9 -> #DIV/0!
A13: Pts | B13: Non-Price Criteria (max.points in this section should total 100 when added to max.Cost Points from above)
B39: TOTAL | C39: =SUM(C11:C38) -> 0 | D39: =SUM(D11:D38) -> #DIV/0! | E39: =SUM(E11:E38) -> #DIV/0! | F39: =SUM(F11:F38) -> #DIV/0! | G39: =SUM(G11:G38) -> #DIV/0! | H39: =SUM(H11:H38) -> #DIV/0!

Sheet Labor & Fringe Worksheet
A1: LABOR AND FRINGE WORKSHEET
A2: SFA has completed information for SFA employees. Company complete information for Company employees.
F3: Pay rates for the School Year __________
H4: Retirement % | I4: FICA/Med % | J4: Wk Comp %
A7: School | F7: Annual | G7: Total | K7: Insurance &
A8: Building* | B8: Employee | C8: Job Title* | D8: Hrly Pay | E8: Daily Hrs* | F8: Days* | G8: Wages* | H8: Retirement* | I8: FICA* | J8: Work Comp* | K8: Longevity
H9: =+G9*#REF! -> #REF! | I9: =+G9*#REF! -> #REF! | J9: =+G9*#REF! -> #REF!
G10: =+D10*E10*F10 -> 0 | H10: =+G10*#REF! -> #REF! | I10: =+G10*#REF! -> #REF! | J10: =+G10*#REF! -> #REF!
G11: =+D11*E11*F11 -> 0 | H11: =+G11*#REF! -> #REF! | I11: =+G11*#REF! -> #REF! | J11: =+G11*#REF! -> #REF!
G12: =+D12*E12*F12 -> 0 | H12: =+G12*#REF! -> #REF! | I12: =+G12*#REF! -> #REF! | J12: =+G12*#REF! -> #REF!
G13: =+D13*E13*F13 -> 0 | H13: =+G13*#REF! -> #REF! | I13: =+G13*#REF! -> #REF! | J13: =+G13*#REF! -> #REF!
G14: =+D14*E14*F14 -> 0 | H14: =+G14*#REF! -> #REF! | I14: =+G14*#REF! -> #REF! | J14: =+G14*#REF! -> #REF!
G15: =+D15*E15*F15 -> 0 | H15: =+G15*#REF! -> #REF! | I15: =+G15*#REF! -> #REF! | J15: =+G15*#REF! -> #REF!
G16: =+D16*E16*F16 -> 0 | H16: =+G16*#REF! -> #REF! | I16: =+G16*#REF! -> #REF! | J16: =+G16*#REF! -> #REF!
G17: =+D17*E17*F17 -> 0 | H17: =+G17*#REF! -> #REF! | I17: =+G17*#REF! -> #REF! | J17: =+G17*#REF! -> #REF!
G18: =+D18*E18*F18 -> 0 | H18: =+G18*#REF! -> #REF! | I18: =+G18*#REF! -> #REF! | J18: =+G18*#REF! -> #REF!
G19: =+D19*E19*F19 -> 0 | H19: =+G19*#REF! -> #REF! | I19: =+G19*#REF! -> #REF! | J19: =+G19*#REF! -> #REF!
G20: =+D20*E20*F20 -> 0 | H20: =+G20*#REF! -> #REF! | I20: =+G20*#REF! -> #REF! | J20: =+G20*#REF! -> #REF!
G21: =+D21*E21*F21 -> 0 | H21: =+G21*#REF! -> #REF! | I21: =+G21*#REF! -> #REF! | J21: =+G21*#REF! -> #REF!
... G39: =+D39*E39*F39 -> 0 | H39: =+G39*#REF! -> #REF! | I39: =+G39*#REF! -> #REF! | J39: =+G39*#REF! -> #REF!
B40: Total Food Service | G40: =SUM(G9:G39) -> 0 | H40: =SUM(H9:H39) -> #REF! | I40: =SUM(I9:I39) -> #REF! | J40: =SUM(J9:J39) -> #REF! | K40: =SUM(K9:K39) -> 0
A48: *Minimum information that must be completed for this worksheet.
A49: Note: Insert percentage for Retirement in cell H5, FICA/Med in cell I5, and Wk Compensation in cell J5. Then insert hourly pay, daily hours and annual days to automatically calculate
A50: and populate cells for wages, retirement, FICA, and worker's compensation.

Sheet Costs
A1: PROJECTED COSTS
A2: Based on (insert days) Days of Service in School Year ________
A4: EXPENSES: (From Food Service Account) | B4: TOTAL COST
A5: Food Cost-Including commodities delivery charge
A6: Labor
A7: Fringe Benefits
A8: On-Site Manager Salary and Benefits
A9: Contracted Services
A10: Transportation Cost
A11: Non-Food (Supplies and Other Materials)
A12: Indirect Cost (Assigned to food service)
A13: Other:
A15: Total | B15: =SUM(B5:B14) -> 0
A16: FSMC Administrative Cost/Fee, if applicable, have not been included.
A17: Please refer to the district annual audit for additional cost information.

Sheet Lunch Prices & Counts
A1: LUNCH PROGRAM
A2: PRICES / COUNTS / OTHER INCOME
E3: Counts:
C4: Meal Prices: | E4: *Reimbursable Meal ADP: | H4: *Total for School Year
A5: School Builiding | B5: Enrollment | C5: Adult | D5: Student | E5: Free | F5: Reduced | G5: Paid | H5: A la Carte and Other Income
H6: =+' Revenues'!$D$23*'Lunch Prices & Counts'!J6 -> 0
H7: =+' Revenues'!$D$23*'Lunch Prices & Counts'!J7 -> 0
H8: =+' Revenues'!$D$23*'Lunch Prices & Counts'!J8 -> 0
H9: =+' Revenues'!$D$23*'Lunch Prices & Counts'!J9 -> 0
H10: =+' Revenues'!$D$23*'Lunch Prices & Counts'!J10 -> 0
H11: =+' Revenues'!$D$23*'Lunch Prices & Counts'!J11 -> 0
H12: =+' Revenues'!$D$23*'Lunch Prices & Counts'!J12 -> 0
H13: =+' Revenues'!$D$23*'Lunch Prices & Counts'!J13 -> 0
H14: =+' Revenues'!$D$23*'Lunch Prices & Counts'!J14 -> 0
H15: =+' Revenues'!$D$23*'Lunch Prices & Counts'!J15 -> 0
H16: =+' Revenues'!$D$23*'Lunch Prices & Counts'!J16 -> 0
H17: =+' Revenues'!$D$23*'Lunch Prices & Counts'!J17 -> 0
... H31: =+' Revenues'!$D$23*'Lunch Prices & Counts'!J31 -> 0
A32: Total | B32: =SUM(B6:B31) -> 0 | E32: =SUM(E6:E31) -> 0 | F32: =SUM(F6:F31) -> 0 | G32: =SUM(G6:G31) -> 0 | H32: =SUM(H6:H31) -> 0 | J32: =SUM(J6:J31) -> 0
A35: *Check one:
A36: ( ) The ADP (Average Daily Participation) and A la Carte/Catering Information is based on data from a projection for the current school year __________
A37: using the month(s) of insert months/year.
A38: ( ) The ADP (Average Daily Participation) and A la Carte/Catering Information is based on data from the entire previous school year ___________.

Sheet Brkfst Prices & Counts
A1: BREAKFAST PROGRAM
A2: PRICES/COUNTS/OTHER INCOME
F3: Counts:
C4: Meal Prices: | E4: *Reimbursable Meal ADP:
A5: School Building | B5: Enrollment | C5: Adult | D5: Student | E5: Free | F5: Reduced | G5: Paid | H5: A la Carte & Other Income
H6: =+' Revenues'!$D$23*'Lunch Prices & Counts'!J6 -> 0
H7: =+' Revenues'!$D$23*'Lunch Prices & Counts'!J7 -> 0
H8: =+' Revenues'!$D$23*'Lunch Prices & Counts'!J8 -> 0
H9: =+' Revenues'!$D$23*'Lunch Prices & Counts'!J9 -> 0
H10: =+' Revenues'!$D$23*'Lunch Prices & Counts'!J10 -> 0
H11: =+' Revenues'!$D$23*'Lunch Prices & Counts'!J11 -> 0
H12: =+' Revenues'!$D$23*'Lunch Prices & Counts'!J12 -> 0
H13: =+' Revenues'!$D$23*'Lunch Prices & Counts'!J13 -> 0
H14: =+' Revenues'!$D$23*'Lunch Prices & Counts'!J14 -> 0
H15: =+' Revenues'!$D$23*'Lunch Prices & Counts'!J15 -> 0
H16: =+' Revenues'!$D$23*'Lunch Prices & Counts'!J16 -> 0
H17: =+' Revenues'!$D$23*'Lunch Prices & Counts'!J17 -> 0
... H31: =+' Revenues'!$D$23*'Lunch Prices & Counts'!J31 -> 0
A32: Total | B32: =SUM(B6:B31) -> 0 | E32: =SUM(E6:E31) -> 0 | F32: =SUM(F6:F31) -> 0 | G32: =SUM(G6:G31) -> 0 | H32: =SUM(H6:H31) -> 0
A33: *Check one:
A34: ( ) The ADP (Average Daily Participation) and A la Carte/Catering Information is based on data from a projection for the current school year _________
A35: using the month(s) of (insert months/year).
A36: ( ) The ADP (Average Daily Participation) and A la Carte/Catering Information is based on data from the entire previous school year ________.

Sheet  Revenues
A1: PROJECTED REVENUES
A3: Based on (insert # days___) Days of Lunch / (insert # days___) Days of Breakfast in School Year ________
B5: LOCAL REVENUE
A7: Breakfasts: | B7: Number Sold: | C7: Price:
A8: Elementary Paid | D8: =+B8*C8 -> 0
A9: Secondary Paid | D9: =+B9*C9 -> 0
A10: Reduced | D10: =+B10*C10 -> 0
A11: Adult | D11: =+B11*C11 -> 0
C12: Breakfast Revenue: | D12: =SUM(D8:D11) -> 0
A14: Lunches:
A15: Elementary Paid | D15: =+B15*C15 -> 0
A16: Secondary Paid | D16: =+B16*C16 -> 0
A17: Reduced | D17: =+B17*C17 -> 0
A18: Adult | D18: =+B18*C18 -> 0
C19: Lunch Revenue: | D19: =SUM(D15:D18) -> 0
A21: Milk Programs | C21: Milk Revenue: | D21: 0
A23: *A la Carte Sales | C23: = | F23: =SUM(D23:D23)+D11+D18 -> 0
A24: Other | C24: = | D24: 0
C26: Total Local Revenue | D26: =+D12+D19+D21+D23+#REF!+#REF!+D24+#REF! -> #REF!
A28: *Includes income from vending machines, if applicable.
B30: PROGRAM REIMBURSEMENTS:
B31: Number Sold: | C31: Federal + State Rates for SY _________
A32: Breakfasts:
A33: Free | D33: =+B33*C33 -> 0 | F33: =SUM(D33:D37) -> 0 | G33: =SUM(B33:B37) -> 0
A34: Free, severe need | D34: =+B34*C34 -> 0
A35: Reduced | D35: =+B35*C35 -> 0
A36: Reduced, severe need | D36: =+B36*C36 -> 0
A37: Paid | D37: =+B37*C37 -> 0
A39: Lunches:
A40: Free | D40: =+B40*C40 -> 0 | F40: =SUM(D40:D45) -> 0 | G40: =SUM(B40:B45) -> 0
A41: Free, severe need | D41: =+B41*C41 -> 0
A42: Reduced | D42: =+B42*C42 -> 0
A43: Reduced, severe need | D43: =+B43*C43 -> 0
A44: Paid | D44: =+B44*C44 -> 0
A45: Paid, severe need | D45: =+B45*C45 -> 0
C47: Total Meals Reimbursement | D47: =SUM(D33:D45) -> 0
C49: Total Milk Reimbursement | D49: =+#REF!+#REF! -> #REF!
C51: Total Revenue | D51: =SUM(D50:D50) -> 0
A53: Check one:
A54: ( ) These figures are based on projected revenue for the currect school year ________ using the
...

Sheet Meals & Equivalents
A1: MEALS AND MEAL EQUIVALENTS CALCULATOR
A4: Federal Free Lunch Rate
A5: + Commodity Rate
A6: Total
B7: *A la carte income | C7: =+' Revenues'!$F$23 -> 0
C8: Meal Equivalents (Divide Income by Total) | D8: =IF(B6=0,0,C7/B6) -> 0
C9: Breakfasts Served | D9: =+' Revenues'!$G$33 -> 0
C10: Lunches Served | D10: =+' Revenues'!$G$40 -> 0
C11: *Total Meals and Meal Equivalents | D11: =SUM(D8:D10) -> 0
A13: A la Carte income includes any income from dining room operations which are not part of the
A14: Reimbursable Meals Program.
A17: *Check one:
A18: ( ) The a la carte and catering income, total meals and meal equivalents is based on data from a
A19: projection for the current school year _________) using the months of (insert months/year).
A20: ( ) The a la carte and catering income, total meals and meal equivalents is based on data from the
A21: entire previous school year _________.

Sheet Bldg Demographics
A1: BUILDING DEMOGRAPHICS AND SERVICE INFORMATION
A2: ~~See attached copy of (insert month/year) claim~~
C4: Service Times:
A5: School Building | B5: Grades | C5: Breakfast | D5: Lunch | E5: Self-Prep,Satellite, Etc. | F5: Days / Year

Sheet Services by Location
A1: SFA INFORMATION: The services that are indicated below with an "x" are to be provided at the following locations.
H2: Split Session | I2: MN
C3: Offer vs Serve | E3: Offer vs Serve | G3: Adult | H3: Kindergarten | I3: Kindergarten
A4: School Building | B4: Lunch | C4: Lunch | D4: Breakfast | E4: Breakfast | F4: A la Carte | G4: Meals | H4: Special Milk | I4: Milk

Sheet Cost Responsibility
A1: Cost Responsibility Detail Sheet
A2: Indicate with an "x" whether the cost will be paid by the FSMC, the School Food Authority (SFA), or
A3: the cost does not apply to the prospective contract.
B4: Areas of Responsibility | E4: FSMC | G4: SFA | I4: N/A
A5: Food
B6: Food Purchases
B7: USDA Handling & Processing Charges
B8: Processing and Payment of Invoices
A9: Non-Food
A10: Labor | B10: FSMC Employees
C11: Salary/Wages
C12: Fringe Benefits & Insurance
C13: Retirement
C14: Payroll Taxes
C15: Workers Compensation
C16: Unemployment Compensation
C17: Preparation & Processing of Payroll
B18: SFA Employees
C19: Wages
C20: Fringe Benefits & Insurance
C21: Retirement
C22: Payroll Taxes
C23: Workers Compensation
C24: Unemployment Compensation
C25: Preparation & Processing of Payroll
A26: Miscellaneous/Additional Items
B27: Cleaning/Janitorial Supplies
B28: Paper/Disposable Supplies
B29: Tickets/Tokens/I.D. System
B30: Silverware/Glassware
C31: Initial Inventory
C32: Replacement During Operation
A33: Telephone
B34: Local
B35: Long Distance
A36: Uniforms
A37: Linens
A38: Laundry
B39: Areas of Responsibility | E39: FSMC | G39: SFA | I39: N/A
A40: Trash Removal
...

Sheet Sheet1
