Workbook

Sheet Instructions
B9: Selection of Accountability Measures for Alternative Education Campuses
B10: REQUIRED INFORMATION | D10: School Name
D11: School Code
D12: District/Authorizer Name
D13: District/Authorizer Code
D14: Principal's Name
D15: Primary Contact
D16: Primary Contact's E-mail
D17: Primary Contact's Phone #
B18: SCHOOL LEVELS SERVED BY THIS AEC | D18: Elementary School
D19: Middle School
D20: High School
B21: ASSURANCE SIGNATURES | D21: Principal/Administrator Signature
D22: District/Authorizer Signature
D23: District Board President Signature
B25: OVERVIEW
B26: All of Colorado’s Alternative Education Campuses (AECs) are accountable for the following performance indicators: Academic Achievement, Academic Growth, Postsecondary and Workforce Readiness (high schools only) and Student Engagement. Performance on these indicators will serve as the basis for an AEC’s school plan type assignment by districts and the Colorado Department of Education (CDE).
B27: The measures selected in this document will be used to calculate 2013-2014 framework results. You do not need to fill out this form if (1) your AEC and authorizer are aproved by CDE to modify any of these CDE approved metrics, cut-points, and/or weights, and/or (2) your AEC and authorizer are approved by CDE to use the framework agreed to by your board last year. The authorizer will also be responsible for generating and submitting to CDE a framework report using its proposed metrics and/or cut-points. This form is due back to CDE no later than July 1, 2014. Scan cover sheet, with appropriate signatures, to: accountability@cde.state.co.us.
B28: In the attached worksheets, please indicate the supplemental measures for each of the four performance indicator areas for which your AEC will be accountable. The measures for each of the performance indicators must be approved by the Local School Board or Charter School Institute for each AEC, before submission to CDE. CDE will then notify the local school board or Charter School Institute if any revisions to the measures are necessary. This notification will be given on or before September 1, 2014. Revisions will be due within 10 days of notification. Data submitted in this form is subject to CDE audit and verification.
B30: INSTRUCTIONS
B31: 1. | C31: Complete the highlighted REQUIRED INFORMATION fields in the table above.
B32: 2. | C32: If your AEC serves elementary students, select YES from the drop-down menu in MEASURES SELECTED FOR THE FOLLOWING LEVELS: Elementary School, if your school does not serve elementary students, select NO. Repeat this process for Middle and High School. Be sure to represent all grades served by your school as you will need to select measures for EACH level separately.
B33: 3. | C33: If your AEC serves high school students click on the Select Measures-High School tab along the bottom of the workbook. Follow instructions 4-11 to complete the data template and indicate your performance framework selections. Please note that if your school serves elementary or middle school students you will also need to complete the Select Measures-Elementary Sch and/or Select Measures-Middle School worksheets.
B34: 4. | C34: The first two rows for school name and number should automatically populate from the REQUIRED INFORMATION fields on this INSTRUCTIONS tab. Although the worksheet may seem long, the only fields you need to fill out are highlighted in yellow. You may more easily navigate the form by clicking on the blue links to help you jump between performance indicators on each sheet.
B35: 5. | C35: Within each framework indicator, the required measures are listed first, followed by the optional measures. For each measure, the following information is required: • the metric of interest (i.e. % of students scoring proficient or advanced); • the criteria for exceeding, meeting, approaching and not meeting the AEC norms (e.g., at or above the 90th percentile of AECs) ; • the cut-point values associated with each of the criteria levels (e.g. the % of students scoring proficient or advanced associated with the 90th percentile of AECs); and • your school's observed score on the measure and metric of interest (e.g., 15.8% of your students were proficient or advanced) • if your school meets the minimum N requirement, the total number of students contributing to your school's actual score on the measure and metric of interest (e.g. 25 students took CSAP/TCAP)
B36: 6. | C36: CDE has populated all the fields for measures and metrics using state data from 2009-2012 as the baseline, including for all required measures and some available optional measures. A few of the of the state fields may be updated with 2013-2014 data in August, 2014. You may review the baseline values associated with each cut-point as set using state data from 2009-2012 on the Reference Cut-points tab. Note that you do not need to fill in information for the required measures; required measures will be included in all AEC frameworks for schools with enough data. You may select other additional/ supplemental measures to include in your school's performance framework only if you can supply the necessary criteria and cut-point value information.
B37: 7. | C37: The most common additional measures used by AECs have been added to the data collection template. For measures labeled as OPTIONAL use the drop-down menu in the highlighted box to indicate if you wish to count the measure towards your framework. You only need to fill out and/or modify cells in yellow. If there is a choice of metrics, the first row in the section will be highlighted in yellow and you will need to select from a drop-down menu. Cut-points have been for the most common additional measures used by AECs. If you choose to add an additional measure, please enter the information in the "Other" box and include cut-point values in the highlighted cells. Finally, enter your school's actual performance on the measure. Note that all versions/administrations of an assessment (e.g. Acuity A, Acuity B, and Acuity C) count as a single measure and results should be aggregated.
B38: 8. | C38: To meet minimum n requirements and provide more reliable ratings, when multiple years of data are available for an optional metric please aggregate your school's actual performance across the most recent 3 years. If data are not available for all 3 years, provide as many years as possible (i.e. the two year aggregate or if the assessment is new only the current year results).
B39: 9. | C39: If you wish to include an additional measure and/or subject area that is not included on the data template, the last one, two, or three sections of cells within each indicator can be filled in by hand. Indicate: (1) the name of the measure, (2) the subject area of the measure, (3) the metric of the measure, (4) the criteria to exceed, meet, approach and not meet AEC Norms, (5) the cut-point values to exceed, meet, approach and not meet AEC Norms, and (6) your school's actual value for the additional measure. Consider ambitious but attainable targets for the population of students you serve.
B40: 10. | C40: Refer to the tables below for information about the point values associated with each criteria and the number of framework points associated with each indicator by elementary/middle and high school-levels. All measures default to 4 possible points, contributing equally to the indicator point total. Changes to these weights will need to be approved by CDE, and the district/authorizer will need to generate its own framework report if weights are approved.
B41: 11. | C41: After making sure all highlighted cells in the current sheet have been appropriately filled out, complete the Select Measures data templates for all other grades served by your school.
B42: 12. | C42: Once all templates have been completed, please save this form as "Selection of Accountability Measures - 0000.xls" . Replace "0000" with the school's specific code.
... B45: 15. | C45: Scan or Fax cover sheet, with appropriate signatures, to accountability@cde.state.co.us.
C46: For technical assistance, please contact Jessica Knevals, knevals_j@cde.state.co.us or 303-866-6778.
C49: Alternative Scoring Guide 2014- ELEMENTARY & MIDDLE SCHOOL
C50: Scoring Guide for Alternative Education Campuses (AECs) ONLY
C51: Performance Indicator | D51: For each selected measure: | E51: Point Value | F51: Framework Points (combined across measures)
C52: Academic Achievement | D52: Exceeds AEC Norms | E52: 4 | F52: 20
D53: Meets AEC Norms | E53: 3
D54: Approaching AEC Norms | E54: 2
...

Sheet Select Measures-High School
A1: Selection of Measures for AECs - HIGH SCHOOL
C2: School Name | D2: =IF(Instructions!E20="YES",Instructions!E10,"Not submitting HIGH SCHOOL measurement selections") -> Not submitting HIGH SCHOOL measurement selections
C3: School Code | D3: =IF(Instructions!E20="YES",Instructions!E11,"Not submitting HIGH SCHOOL measurement selections") -> Not submitting HIGH SCHOOL measurement selections
C4: School Level | D4: H
C5: Years for which Measures will apply | D5: =IF(Instructions!#REF!="2011-2012 ONLY","2011-2012 ONLY","2010-2011 & 2011-2012") -> #REF!
C6: Select Measure (Click on name of measure to jump to section) | D6: ACADEMIC ACHIEVEMENT | M6: Select a Subject
D7: ACADEMIC GROWTH | M7: English
D8: STUDENT ENGAGEMENT | M8: Language Arts
D9: POST-SECONDARY & WORKFORCE READINESS | M9: Reading
A10: ACADEMIC ACHIEVEMENT | M10: Reading & Language Arts (Acuity Only)
A11: REQUIRED | B11: CSAP/TCAP Reading | C11: To receive the indicator rating, the AEC's percent of students scoring proficient and advanced was: | D11: =C11 -> To receive the indicator rating, the AEC's percent of students scoring proficient and advanced was: | G11: OPTIONAL | I11: NWEA MAPS | J11: To receive the indicator rating, | M11: English Language Proficiency (CELAPro/ACCESS Only)
C12: Exceeds AEC norms | D12: at or above the 90th percentile of all AECs | J12: Exceeds AEC norms | K12: at or above 90 percent of students | M12: Mathematics
C13: Meets AEC norms | D13: below the 90th percentile but at or above the 60th percentile of all AECs | J13: Meets AEC norms | K13: below 90 percent but at or above 60 percent of students | M13: Math/Algebra (Acuity Only)
C14: Approaching AEC norms | D14: below the 60th percentile but at or above the 40th percentile of all AECs | H14: Use measure? | J14: Approaching AEC norms | K14: below 60 percent but at or above 40 percent of students | M14: Science
C15: Does Not Meet AEC norms | D15: below the 40th percentile of all AECs | J15: Does Not Meet AEC norms | K15: below 40 percent of students | M15: Select a Measure
C16: Cut-point values for percent of students scoring proficient and advanced were: | D16: =C16 -> Cut-point values for percent of students scoring proficient and advanced were: | J16: =IF(K11=G$822, "Cut-point values for percent of students increasing a grade level were:", "Cut-point values for percent of students scoring at grade level were:") -> Cut-point values for percent of students increasing a grade level were: | M16: Acuity
C17: Cut-point value for Exceeds | D17: 54.8 | J17: Cut-point value for Exceeds | K17: 90 | M17: Galileo
C18: Cut-point value for Meets | D18: 35.4 | J18: Cut-point value for Meets | K18: 60 | M18: NWEA MAP
C19: Cut-point value for Approaching | D19: 26.7 | J19: Cut-point value for Approaching | K19: 40 | M19: Scantron
C20: Your school's actual percent of students scoring proficient and advanced was: | D20: =C20 -> Your school's actual percent of students scoring proficient and advanced was: | J20: =IF(K11=G$822, "Your school's actual percent of students increasing a grade level was:", "Your school's actual percent of students scoring at grade level was:") -> Your school's actual percent of students increasing a grade level was: | M20: STAR Enterprise
C21: Percent proficient and advanced | D21: to be populated by CDE with 2013-2014 data | J21: Percent proficient and advanced | M21: Test for Adult Basic Education (TABE)
C22: Total student count (if N ≥ 16) | D22: to be populated by CDE with 2013-2014 data | J22: Total student count (if N ≥ 16) | M22: Wide Range Achievement Test (WRAT)
A23: REQUIRED | B23: CSAP/TCAP Writing | C23: To receive the indicator rating, the AEC's percent of students scoring proficient and advanced was: | D23: =C23 -> To receive the indicator rating, the AEC's percent of students scoring proficient and advanced was: | J23: Using following measure?
C24: Exceeds AEC norms | D24: at or above the 90th percentile of all AECs | G24: OPTIONAL | I24: Scantron | J24: To receive the indicator rating,
C25: Meets AEC norms | D25: below the 90th percentile but at or above the 60th percentile of all AECs | J25: Exceeds AEC norms | K25: at or above 90 percent of students | N25: Exceeds AEC norms | O25: Meets AEC norms | P25: Approaching AEC norms | Q25: Does Not Meet AEC norms | R25: Cut-point value for Exceeds | S25: Cut-point value for Meets | T25: Cut-point value for Approaching
C26: Approaching AEC norms | D26: below the 60th percentile but at or above the 40th percentile of all AECs | J26: Meets AEC norms | K26: below 90 percent but at or above 60 percent of students | M26: Select a Measure
C27: Does Not Meet AEC norms | D27: below the 40th percentile of all AECs | H27: Use measure? | J27: Approaching AEC norms | K27: below 60 percent but at or above 40 percent of students | M27: NWEA MAP | N27: at or above 90 percent of students | O27: below 90 percent but at or above 60 percent of students | P27: below 60 percent but at or above 40 percent of students | Q27: below 40 percent of students | R27: 90 | S27: 60 | T27: 40
C28: Cut-point values for percent of students scoring proficient and advanced were: | D28: =C28 -> Cut-point values for percent of students scoring proficient and advanced were: | J28: Does Not Meet AEC norms | K28: below 40 percent of students | M28: Scantron | N28: at or above 90 percent of students | O28: below 90 percent but at or above 60 percent of students | P28: below 60 percent but at or above 40 percent of students | Q28: below 40 percent of students | R28: 90 | S28: 60 | T28: 40
C29: Cut-point value for Exceeds | D29: 28.6 | J29: =IF(K24=G$822, "Cut-point values for percent of students increasing a grade level were:", "Cut-point values for percent of students scoring at grade level were:") -> Cut-point values for percent of students increasing a grade level were: | M29: Acuity | N29: at or above 90 percent of students | O29: below 90 percent but at or above 60 percent of students | P29: below 60 percent but at or above 40 percent of students | Q29: below 40 percent of students | R29: 90 | S29: 60 | T29: 40
C30: Cut-point value for Meets | D30: 14.6 | J30: Cut-point value for Exceeds | K30: 90 | M30: Galileo | N30: at or above 90 percent of students | O30: below 90 percent but at or above 60 percent of students | P30: below 60 percent but at or above 40 percent of students | Q30: below 40 percent of students | R30: 90 | S30: 60 | T30: 40
C31: Cut-point value for Approaching | D31: 10 | J31: Cut-point value for Meets | K31: 60 | M31: Wide Range Achievement Test (WRAT) | N31: at or above 90 percent of students | O31: below 90 percent but at or above 60 percent of students | P31: below 60 percent but at or above 40 percent of students | Q31: below 40 percent of students | R31: 90 | S31: 60 | T31: 40
C32: Your school's actual percent of students scoring proficient and advanced was: | D32: =C32 -> Your school's actual percent of students scoring proficient and advanced was: | J32: Cut-point value for Approaching | K32: 40 | M32: Test for Adult Basic Education (TABE) | N32: at or above 90 percent of students | O32: below 90 percent but at or above 60 percent of students | P32: below 60 percent but at or above 40 percent of students | Q32: below 40 percent of students | R32: 90 | S32: 60 | T32: 40
C33: Percent proficient and advanced | D33: to be populated by CDE with 2013-2014 data | J33: =IF(K24=G$822, "Your school's actual percent of students increasing a grade level was:", "Your school's actual percent of students scoring at grade level was:") -> Your school's actual percent of students increasing a grade level was: | M33: STAR Enterprise | N33: at or above 90 percent of students | O33: below 90 percent but at or above 60 percent of students | P33: below 60 percent but at or above 40 percent of students | Q33: below 40 percent of students | R33: 90 | S33: 60 | T33: 40
C34: Total student count (if N ≥ 16) | D34: to be populated by CDE with 2013-2014 data | J34: Percent proficient and advanced
A35: REQUIRED | B35: CSAP/TCAP Math | C35: To receive the indicator rating, the AEC's percent of students scoring proficient and advanced was: | D35: =C35 -> To receive the indicator rating, the AEC's percent of students scoring proficient and advanced was: | J35: Total student count (if N ≥ 16)
C36: Exceeds AEC norms | D36: at or above the 90th percentile of all AECs | J36: Using following measure? | M36: the percent of students increasing at least one grade level was: | Q36: Number of students increasing at least one grade level | R36: Percent of students increasing at least one grade level
C37: Meets AEC norms | D37: below the 90th percentile but at or above the 60th percentile of all AECs | G37: OPTIONAL | I37: Acuity | J37: To receive the indicator rating, | M37: the percent of students scoring at grade level was: | Q37: Number of students scoring at grade level | R37: Percent of students scoring at grade level
C38: Approaching AEC norms | D38: below the 60th percentile but at or above the 40th percentile of all AECs | J38: Exceeds AEC norms | K38: at or above 90 percent of students
C39: Does Not Meet AEC norms | D39: below the 40th percentile of all AECs | J39: Meets AEC norms | K39: below 90 percent but at or above 60 percent of students | M39: Select a Measure
C40: Cut-point values for percent of students scoring proficient and advanced were: | D40: =C40 -> Cut-point values for percent of students scoring proficient and advanced were: | H40: Use measure? | J40: Approaching AEC norms | K40: below 60 percent but at or above 40 percent of students | M40: NWEA MAP | N40: Percent Proficient and Advanced
...

Sheet Select Measures-Middle School
A1: Selection of Measures for AECs - MIDDLE SCHOOL
C2: School Name | D2: =IF(Instructions!E19="YES",Instructions!E10,"Not submitting MIDDLE SCHOOL measurement selections") -> Not submitting MIDDLE SCHOOL measurement selections
C3: School Code | D3: =IF(Instructions!E19="YES",Instructions!E11,"Not submitting MIDDLE SCHOOL measurement selections") -> Not submitting MIDDLE SCHOOL measurement selections
C4: School Level | D4: H
C5: Years for which Measures will apply | D5: =IF(Instructions!#REF!="2011-2012 ONLY","2011-2012 ONLY","2010-2011 & 2011-2012") -> #REF!
C6: Select Measure (Click on name of measure to jump to section) | D6: ACADEMIC ACHIEVEMENT | M6: Select a Subject
D7: ACADEMIC GROWTH | M7: English
D8: STUDENT ENGAGEMENT | M8: Language Arts
M9: Reading
A10: ACADEMIC ACHIEVEMENT | M10: Reading & Language Arts (Acuity Only)
A11: REQUIRED | B11: CSAP/TCAP Reading | C11: To receive the indicator rating, the AEC's percent of students scoring proficient and advanced was: | D11: =C11 -> To receive the indicator rating, the AEC's percent of students scoring proficient and advanced was: | G11: OPTIONAL | I11: NWEA MAPS | J11: To receive the indicator rating, | M11: English Language Proficiency (CELAPro/ACCESS Only)
C12: Exceeds AEC norms | D12: at or above the 90th percentile of all AECs | J12: Exceeds AEC norms | K12: at or above 90 percent of students | M12: Mathematics
C13: Meets AEC norms | D13: below the 90th percentile but at or above the 60th percentile of all AECs | J13: Meets AEC norms | K13: below 90 percent but at or above 60 percent of students | M13: Math/Algebra (Acuity Only)
C14: Approaching AEC norms | D14: below the 60th percentile but at or above the 40th percentile of all AECs | H14: Use measure? | J14: Approaching AEC norms | K14: below 60 percent but at or above 40 percent of students | M14: Elementary Algebra (Accuplacer Only)
C15: Does Not Meet AEC norms | D15: below the 40th percentile of all AECs | J15: Does Not Meet AEC norms | K15: below 40 percent of students | M15: Science
C16: Cut-point values for percent of students scoring proficient and advanced were: | D16: =C16 -> Cut-point values for percent of students scoring proficient and advanced were: | J16: =IF(K11=G$545, "Cut-point values for percent of students increasing a grade level were:", "Cut-point values for percent of students scoring at grade level were:") -> Cut-point values for percent of students increasing a grade level were: | M16: Select a Measure
C17: Cut-point value for Exceeds | D17: 54.8 | J17: Cut-point value for Exceeds | K17: 90 | M17: Accuplacer
C18: Cut-point value for Meets | D18: 35.4 | J18: Cut-point value for Meets | K18: 60 | M18: Acuity
C19: Cut-point value for Approaching | D19: 26.7 | J19: Cut-point value for Approaching | K19: 40 | M19: Galileo
C20: Your school's actual percent of students scoring proficient and advanced was: | D20: =C20 -> Your school's actual percent of students scoring proficient and advanced was: | J20: =IF(K11=G$545, "Your school's actual percent of students increasing a grade level was:", "Your school's actual percent of students scoring at grade level was:") -> Your school's actual percent of students increasing a grade level was: | M20: NWEA MAPS
C21: Percent proficient and advanced | D21: to be populated by CDE with 2013-2014 data | J21: Percent proficient and advanced | M21: Scantron
C22: Total student count (if N ≥ 16) | D22: to be populated by CDE with 2013-2014 data | J22: Total student count (if N ≥ 16) | M22: STAR Enterprise
A23: REQUIRED | B23: CSAP/TCAP Writing | C23: To receive the indicator rating, the AEC's percent of students scoring proficient and advanced was: | D23: =C23 -> To receive the indicator rating, the AEC's percent of students scoring proficient and advanced was: | J23: Using following measure? | M23: Test for Adult Basic Education (TABE)
C24: Exceeds AEC norms | D24: at or above the 90th percentile of all AECs | G24: OPTIONAL | I24: Scantron | J24: To receive the indicator rating, | M24: Wide Range Achievement Test (WRAT)
C25: Meets AEC norms | D25: below the 90th percentile but at or above the 60th percentile of all AECs | J25: Exceeds AEC norms | K25: at or above 90 percent of students | N25: Exceeds AEC norms | O25: Meets AEC norms | P25: Approaching AEC norms | Q25: Does Not Meet AEC norms | R25: Cut-point value for Exceeds | S25: Cut-point value for Meets | T25: Cut-point value for Approaching
C26: Approaching AEC norms | D26: below the 60th percentile but at or above the 40th percentile of all AECs | J26: Meets AEC norms | K26: below 90 percent but at or above 60 percent of students | M26: Select a Measure
C27: Does Not Meet AEC norms | D27: below the 40th percentile of all AECs | H27: Use measure? | J27: Approaching AEC norms | K27: below 60 percent but at or above 40 percent of students | M27: NWEA MAPS | N27: at or above 90 percent of students | O27: below 90 percent but at or above 60 percent of students | P27: below 60 percent but at or above 40 percent of students | Q27: below 40 percent of students | R27: 90 | S27: 60 | T27: 40
C28: Cut-point values for percent of students scoring proficient and advanced were: | D28: =C28 -> Cut-point values for percent of students scoring proficient and advanced were: | J28: Does Not Meet AEC norms | K28: below 40 percent of students | M28: Scantron | N28: at or above 90 percent of students | O28: below 90 percent but at or above 60 percent of students | P28: below 60 percent but at or above 40 percent of students | Q28: below 40 percent of students | R28: 90 | S28: 60 | T28: 40
C29: Cut-point value for Exceeds | D29: 28.6 | J29: =IF(K24=G$545, "Cut-point values for percent of students increasing a grade level were:", "Cut-point values for percent of students scoring at grade level were:") -> Cut-point values for percent of students increasing a grade level were: | M29: Acuity | N29: at or above 90 percent of students | O29: below 90 percent but at or above 60 percent of students | P29: below 60 percent but at or above 40 percent of students | Q29: below 40 percent of students | R29: 90 | S29: 60 | T29: 40
C30: Cut-point value for Meets | D30: 14.6 | J30: Cut-point value for Exceeds | K30: 90 | M30: Galileo | N30: at or above 90 percent of students | O30: below 90 percent but at or above 60 percent of students | P30: below 60 percent but at or above 40 percent of students | Q30: below 40 percent of students | R30: 90 | S30: 60 | T30: 40
C31: Cut-point value for Approaching | D31: 10 | J31: Cut-point value for Meets | K31: 60 | M31: Wide Range Achievement Test (WRAT) | N31: at or above 90 percent of students | O31: below 90 percent but at or above 60 percent of students | P31: below 60 percent but at or above 40 percent of students | Q31: below 40 percent of students | R31: 90 | S31: 60 | T31: 40
C32: Your school's actual percent of students scoring proficient and advanced was: | D32: =C32 -> Your school's actual percent of students scoring proficient and advanced was: | J32: Cut-point value for Approaching | K32: 40 | M32: Test for Adult Basic Education (TABE) | N32: at or above 90 percent of students | O32: below 90 percent but at or above 60 percent of students | P32: below 60 percent but at or above 40 percent of students | Q32: below 40 percent of students | R32: 90 | S32: 60 | T32: 40
C33: Percent proficient and advanced | D33: to be populated by CDE with 2013-2014 data | J33: =IF(K24=G$545, "Your school's actual percent of students increasing a grade level was:", "Your school's actual percent of students scoring at grade level was:") -> Your school's actual percent of students increasing a grade level was: | M33: Accuplacer | N33: at or above the score needed for college placement without remediation | O33: at or above the score needed for placement in 090 level course | P33: at or above the score needed for placement in 060 level course | Q33: below the score needed for placement in 060 level course | R33: 80 | S33: 62 | T33: 40
C34: Total student count (if N ≥ 16) | D34: to be populated by CDE with 2013-2014 data | J34: Percent proficient and advanced | M34: STAR Enterprise | N34: at or above 90 percent of students | O34: below 90 percent but at or above 60 percent of students | P34: below 60 percent but at or above 40 percent of students | Q34: below 40 percent of students | R34: 90 | S34: 60 | T34: 40
A35: REQUIRED | B35: CSAP/TCAP Math | C35: To receive the indicator rating, the AEC's percent of students scoring proficient and advanced was: | D35: =C35 -> To receive the indicator rating, the AEC's percent of students scoring proficient and advanced was: | J35: Total student count (if N ≥ 16)
C36: Exceeds AEC norms | D36: at or above the 90th percentile of all AECs | J36: Using following measure? | M36: the percent of students increasing at least one grade level was: | Q36: Number of students increasing at least one grade level | R36: Percent of students increasing at least one grade level
C37: Meets AEC norms | D37: below the 90th percentile but at or above the 60th percentile of all AECs | G37: OPTIONAL | I37: Acuity | J37: To receive the indicator rating, | M37: the percent of students scoring at grade level was: | Q37: Number of students scoring at grade level | R37: Percent of students scoring at grade level
C38: Approaching AEC norms | D38: below the 60th percentile but at or above the 40th percentile of all AECs | J38: Exceeds AEC norms | K38: at or above 90 percent of students
C39: Does Not Meet AEC norms | D39: below the 40th percentile of all AECs | J39: Meets AEC norms | K39: below 90 percent but at or above 60 percent of students | M39: Select a Measure
C40: Cut-point values for percent of students scoring proficient and advanced were: | D40: =C40 -> Cut-point values for percent of students scoring proficient and advanced were: | H40: Use measure? | J40: Approaching AEC norms | K40: below 60 percent but at or above 40 percent of students | M40: NWEA MAPS | N40: Percent Proficient and Advanced
...

Sheet Select Measures-Elementary Sch
A1: Selection of Measures for AECs - ELEMENTARY SCHOOL
C2: School Name | D2: =IF(Instructions!E18="YES",Instructions!E10,"Not submitting ELEMENTARY SCHOOL measurement selections") -> Not submitting ELEMENTARY SCHOOL measurement selections
C3: School Code | D3: =IF(Instructions!E18="YES",Instructions!E11,"Not submitting ELEMENTARY SCHOOL measurement selections") -> Not submitting ELEMENTARY SCHOOL measurement selections
C4: School Level | D4: H
C5: Years for which Measures will apply | D5: =IF(Instructions!#REF!="2011-2012 ONLY","2011-2012 ONLY","2010-2011 & 2011-2012") -> #REF!
C6: Select Measure (Click on name of measure to jump to section) | D6: ACADEMIC ACHIEVEMENT | M6: Select a Subject
D7: ACADEMIC GROWTH | M7: English
D8: STUDENT ENGAGEMENT | M8: Language Arts
M9: Reading
A10: ACADEMIC ACHIEVEMENT | M10: Reading & Language Arts (Acuity Only)
A11: REQUIRED | B11: CSAP/TCAP Reading | C11: To receive the indicator rating, the AEC's percent of students scoring proficient and advanced was: | D11: =C11 -> To receive the indicator rating, the AEC's percent of students scoring proficient and advanced was: | G11: OPTIONAL | I11: NWEA MAPS | J11: To receive the indicator rating, | M11: English Language Proficiency (CELAPro/ACCESS Only)
C12: Exceeds AEC norms | D12: at or above the 90th percentile of all AECs | J12: Exceeds AEC norms | K12: at or above 90 percent of students | M12: Mathematics
C13: Meets AEC norms | D13: below the 90th percentile but at or above the 60th percentile of all AECs | J13: Meets AEC norms | K13: below 90 percent but at or above 60 percent of students | M13: Math/Algebra (Acuity Only)
C14: Approaching AEC norms | D14: below the 60th percentile but at or above the 40th percentile of all AECs | H14: Use measure? | J14: Approaching AEC norms | K14: below 60 percent but at or above 40 percent of students | M14: Elementary Algebra (Accuplacer Only)
C15: Does Not Meet AEC norms | D15: below the 40th percentile of all AECs | J15: Does Not Meet AEC norms | K15: below 40 percent of students | M15: Science
C16: Cut-point values for percent of students scoring proficient and advanced were: | D16: =C16 -> Cut-point values for percent of students scoring proficient and advanced were: | J16: =IF(K11=G$529, "Cut-point values for percent of students increasing a grade level were:", "Cut-point values for percent of students scoring at grade level were:") -> Cut-point values for percent of students increasing a grade level were: | M16: Select a Measure
C17: Cut-point value for Exceeds | D17: 54.8 | J17: Cut-point value for Exceeds | K17: 90 | M17: Accuplacer
C18: Cut-point value for Meets | D18: 35.4 | J18: Cut-point value for Meets | K18: 60 | M18: Acuity
C19: Cut-point value for Approaching | D19: 26.7 | J19: Cut-point value for Approaching | K19: 40 | M19: Galileo
C20: Your school's actual percent of students scoring proficient and advanced was: | D20: =C20 -> Your school's actual percent of students scoring proficient and advanced was: | J20: =IF(K11=G$529, "Your school's actual percent of students increasing a grade level was:", "Your school's actual percent of students scoring at grade level was:") -> Your school's actual percent of students increasing a grade level was: | M20: NWEA MAPS
C21: Percent proficient and advanced | D21: to be populated by CDE with 2013-2014 data | J21: Percent proficient and advanced | M21: Scantron
C22: Total student count (if N ≥ 16) | D22: to be populated by CDE with 2013-2014 data | J22: Total student count (if N ≥ 16) | M22: STAR Enterprise
A23: REQUIRED | B23: CSAP/TCAP Writing | C23: To receive the indicator rating, the AEC's percent of students scoring proficient and advanced was: | D23: =C23 -> To receive the indicator rating, the AEC's percent of students scoring proficient and advanced was: | J23: Using following measure? | M23: Test for Adult Basic Education (TABE)
C24: Exceeds AEC norms | D24: at or above the 90th percentile of all AECs | G24: OPTIONAL | I24: Scantron | J24: To receive the indicator rating, | M24: Wide Range Achievement Test (WRAT)
C25: Meets AEC norms | D25: below the 90th percentile but at or above the 60th percentile of all AECs | J25: Exceeds AEC norms | K25: at or above 90 percent of students | N25: Exceeds AEC norms | O25: Meets AEC norms | P25: Approaching AEC norms | Q25: Does Not Meet AEC norms | R25: Cut-point value for Exceeds | S25: Cut-point value for Meets | T25: Cut-point value for Approaching
C26: Approaching AEC norms | D26: below the 60th percentile but at or above the 40th percentile of all AECs | J26: Meets AEC norms | K26: below 90 percent but at or above 60 percent of students | M26: Select a Measure
C27: Does Not Meet AEC norms | D27: below the 40th percentile of all AECs | H27: Use measure? | J27: Approaching AEC norms | K27: below 60 percent but at or above 40 percent of students | M27: NWEA MAPS | N27: at or above 90 percent of students | O27: below 90 percent but at or above 60 percent of students | P27: below 60 percent but at or above 40 percent of students | Q27: below 40 percent of students | R27: 90 | S27: 60 | T27: 40
C28: Cut-point values for percent of students scoring proficient and advanced were: | D28: =C28 -> Cut-point values for percent of students scoring proficient and advanced were: | J28: Does Not Meet AEC norms | K28: below 40 percent of students | M28: Scantron | N28: at or above 90 percent of students | O28: below 90 percent but at or above 60 percent of students | P28: below 60 percent but at or above 40 percent of students | Q28: below 40 percent of students | R28: 90 | S28: 60 | T28: 40
C29: Cut-point value for Exceeds | D29: 28.6 | J29: =IF(K24=G$529, "Cut-point values for percent of students increasing a grade level were:", "Cut-point values for percent of students scoring at grade level were:") -> Cut-point values for percent of students increasing a grade level were: | M29: Acuity | N29: at or above 90 percent of students | O29: below 90 percent but at or above 60 percent of students | P29: below 60 percent but at or above 40 percent of students | Q29: below 40 percent of students | R29: 90 | S29: 60 | T29: 40
C30: Cut-point value for Meets | D30: 14.6 | J30: Cut-point value for Exceeds | K30: 90 | M30: Galileo | N30: at or above 90 percent of students | O30: below 90 percent but at or above 60 percent of students | P30: below 60 percent but at or above 40 percent of students | Q30: below 40 percent of students | R30: 90 | S30: 60 | T30: 40
C31: Cut-point value for Approaching | D31: 10 | J31: Cut-point value for Meets | K31: 60 | M31: Wide Range Achievement Test (WRAT) | N31: at or above 90 percent of students | O31: below 90 percent but at or above 60 percent of students | P31: below 60 percent but at or above 40 percent of students | Q31: below 40 percent of students | R31: 90 | S31: 60 | T31: 40
C32: Your school's actual percent of students scoring proficient and advanced was: | D32: =C32 -> Your school's actual percent of students scoring proficient and advanced was: | J32: Cut-point value for Approaching | K32: 40 | M32: Test for Adult Basic Education (TABE) | N32: at or above 90 percent of students | O32: below 90 percent but at or above 60 percent of students | P32: below 60 percent but at or above 40 percent of students | Q32: below 40 percent of students | R32: 90 | S32: 60 | T32: 40
C33: Percent proficient and advanced | D33: to be populated by CDE with 2013-2014 data | J33: =IF(K24=G$529, "Your school's actual percent of students increasing a grade level was:", "Your school's actual percent of students scoring at grade level was:") -> Your school's actual percent of students increasing a grade level was: | M33: Accuplacer | N33: at or above the score needed for college placement without remediation | O33: at or above the score needed for placement in 090 level course | P33: at or above the score needed for placement in 060 level course | Q33: below the score needed for placement in 060 level course | R33: 80 | S33: 62 | T33: 40
C34: Total student count (if N ≥ 16) | D34: to be populated by CDE with 2013-2014 data | J34: Percent proficient and advanced | M34: STAR Enterprise | N34: at or above 90 percent of students | O34: below 90 percent but at or above 60 percent of students | P34: below 60 percent but at or above 40 percent of students | Q34: below 40 percent of students | R34: 90 | S34: 60 | T34: 40
A35: REQUIRED | B35: CSAP/TCAP Math | C35: To receive the indicator rating, the AEC's percent of students scoring proficient and advanced was: | D35: =C35 -> To receive the indicator rating, the AEC's percent of students scoring proficient and advanced was: | J35: Total student count (if N ≥ 16)
C36: Exceeds AEC norms | D36: at or above the 90th percentile of all AECs | J36: Using following measure? | M36: the percent of students increasing at least one grade level was: | Q36: Number of students increasing at least one grade level | R36: Percent of students increasing at least one grade level
C37: Meets AEC norms | D37: below the 90th percentile but at or above the 60th percentile of all AECs | G37: OPTIONAL | I37: Acuity | J37: To receive the indicator rating, | M37: the percent of students scoring at grade level was: | Q37: Number of students scoring at grade level | R37: Percent of students scoring at grade level
C38: Approaching AEC norms | D38: below the 60th percentile but at or above the 40th percentile of all AECs | J38: Exceeds AEC norms | K38: at or above 90 percent of students
C39: Does Not Meet AEC norms | D39: below the 40th percentile of all AECs | J39: Meets AEC norms | K39: below 90 percent but at or above 60 percent of students | M39: Select a Measure
C40: Cut-point values for percent of students scoring proficient and advanced were: | D40: =C40 -> Cut-point values for percent of students scoring proficient and advanced were: | H40: Use measure? | J40: Approaching AEC norms | K40: below 60 percent but at or above 40 percent of students | M40: NWEA MAPS | N40: Percent Proficient and Advanced
...

Sheet Reference Cut-points
A1: Baseline Data for AECS, 2009-11
B2: PERCENTILE
A3: Measure | B3: 40th | C3: 60th | D3: 90th
A4: 3 Year CSAP Reading - % Prof/Adv.
A5: E | B5: 16.7% | C5: 29.4% | D5: 31.6%
A6: M | B6: 15.5% | C6: 21.4% | D6: 46.7%
A7: H | B7: 26.7% | C7: 35.4% | D7: 54.8%
A8: 3 Year CSAP Writing - % Prof/Adv.
A9: E | B9: 12.3% | C9: 14.3% | D9: 35.3%
A10: M | B10: 8.4% | C10: 16.7% | D10: 32.1%
A11: H | B11: 10.0% | C11: 14.6% | D11: 28.6%
A12: 3 Year CSAP Math - % Prof/Adv.
A13: E | B13: 15.0% | C13: 15.5% | D13: 17.7%
A14: M | B14: 6.2% | C14: 10.0% | D14: 34.0%
A15: H | B15: 2.0% | C15: 4.4% | D15: 9.4%
A16: 3 Year CSAP Science - % Prof/Adv.
A17: E | B17: 16.8% | C17: 37.0% | D17: 43.8%
A18: M | B18: 8.0% | C18: 12.1% | D18: 44.0%
A19: H | B19: 10.8% | C19: 16.4% | D19: 30.3%
A20: 3 Year CSAP Reading - MGP
A21: E | B21: NA | C21: NA | D21: NA
A22: M | B22: 35.6 | C22: 43.2 | D22: 58
A23: H | B23: 41.2 | C23: 46.8 | D23: 57.4
A24: 3 Year CSAP Writing - MGP
A25: E | B25: N/A | C25: N/A | D25: N/A
A26: M | B26: 34 | C26: 35.8 | D26: 52.8
A27: H | B27: 38.6 | C27: 43.4 | D27: 57.2
A28: 3 Year CSAP Math - MGP
A29: E | B29: N/A | C29: N/A | D29: N/A
A30: M | B30: 25 | C30: 31.8 | D30: 57.6
A31: H | B31: 33.6 | C31: 42 | D31: 50.6
A32: Completion Rate
A33: Best of 4, 5, 6, 7yr | B33: 44.2% | C33: 55.4% | D33: 70.9%
A34: Graduation Rate
A35: Best of 4, 5, 6, 7yr | B35: 30.7% | C35: 39.9% | D35: 65.3%
A36: 3 Year Drop-out Rate
A37: H | B37: 17.7% | C37: 11.4% | D37: 4.6%
A38: 3 Year ACT Composite Score
A39: H | B39: 14.9 | C39: 15.5 | D39: 16.6
A40: Attendance
...
