Workbook
Name Administered: Dropdowns!$A$58:$A$61
Name Day: Dropdowns!$A$16:$A$47
Name DistrictType: Dropdowns!$A$49:$A$56
Name DistritType: Dropdowns!#REF!
Name G1_DecodableWords: CriteriaDropdowns!$C$15:$C$19
Name G1_OralLanguage: CriteriaDropdowns!$C$63:$C$67
Name G1_SegmentBlend: CriteriaDropdowns!$C$20:$C$23
Name G1DecodableWords: #REF!
Name G1OralLanguage: #REF!
Name G1SegmentingBlending: #REF!
Name G2_HighFreqWords: CriteriaDropdowns!$C$25:$C$26
Name G2_OralFluency: CriteriaDropdowns!$C$28:$C$39
Name G2_OralLanguage: CriteriaDropdowns!$C$68:$C$72
Name G2OralFluency: #REF!
Name G2OralLanguage: #REF!
Name G3_Comprehension: CriteriaDropdowns!$C$54
Name G3_OralFluency: CriteriaDropdowns!$C$42:$C$52
Name G3_Vocabulary: CriteriaDropdowns!$C$41:$C$41
Name G3Comprehension: #REF!
Name G3Vocabulary: #REF!
Name K_LetterSounds: CriteriaDropdowns!$C$3:$C$7
Name K_OralLanguage: CriteriaDropdowns!$C$57:$C$62
Name K_SegmentBlend: CriteriaDropdowns!$C$9:$C$13
Name KLetterSounds: #REF!
Name KOralLanguage: #REF!
Name KSegmentingBlending: #REF!
Name Month: Dropdowns!$A$2:$A$14
Name Type: Dropdowns!#REF!

Sheet Start Here - Directions
A1: Reading Well by Third Grade
A2: Assessment Data Submission 2013
A3: Directions for Accurately Completing
A5: There are multiple steps to this data submission. Please read all directions carefully and follow the steps outlined below to complete your submission.
A8: Technical Assistance: Kat Edwards: katherine.edwards@state.mn.us
A9: Content Assistance: Kari Ross: kari.ross@state.mn.us
A11: Saving File with District Information
B12: Do a 'Save As' of this file inserting your DistrictName_Number (4 digits)_Type (2 digits) in the file name replacing DistrictName_Number_Type in the current file name.
B13: District number and type listed in file name MUST correspond with district number and name listed on District Information & Measures worksheet. Leading zeros are included in the numbers if appropriate.
A15: General Information:
A16: Complete information in yellow cells of each of the following worksheets:
B17: District Information & Measures (Second Sheet)
B18: Literacy Data (Third Sheet)
A20: District Information & Measures Worksheet
A21: Step | B21: Action to be Completed
A22: 1 | B22: Select month and day of submission from drop down menu.
A23: 2 | B23: Complete the district information: Name, Number, and Type.
C24: District name should be same as name used by MDE.
C25: District Number must be a 4-digit number. Include leading 0s.
C26: District Type will be selected from a dropdown list.
A27: 3 | B27: Complete ALL requested information for person responsible for the information in this form.
C28: Include area code in phone number.
C29: Zipcode should be at least 5 digits. May include dash and 4 other digit zipcode information.
A30: 4 | B30: For each literacy measure to be included in this data submission,
B31: a. | C31: If reporting one of the common research based measures, select the measure's name from the dropdown list
C32: OR
C33: If not applicable, enter the name of measure in one of the two available 'Other' categories
C34: Enter at least one measure for each grade level.
C35: Note: Types of Measures listed in blue are representative of commonly used assessments based on review of research literature and may be a subscore within a larger commercial or standardized assessment. Districts are not required to include these measures, but are encouraged to provide if available. At this time, these measures are being limited to dropdown lists to help guide districts and improve data collection.
C36: Reporting is limited to a total of five different measures for each grade level. It is not necessary to provide data for each measure, only report those that are reflected in Local Literacy Plan and provide evidence that the district has collected information to assess all students to measure reading proficiency.
C37: Please select 'Other' measures judiciously; only include those the district has evidence to support accurate predictions of students' success on 3rd grade reading state accountability tests (MCA, MTAS, MCA-Modified).
C38: If typing in the name of a measure, please include date or edition of measure as well as name of subscore being used when appropriate.
B39: b. | C39: Identify the specific criteria used to determine students who are 'at or above grade level'
C40: Please include both cut score (e.g., number) and type of metric (i.e., words per minute or scale score or national norm).
C41: *If using commercial test in dropdown list, please reference Criteria Options worksheet to verify district is using expected norms. If not using expected norms, enter detailed information in the far right column about how alternative cut score was determined.
B42: c. | C42: Select the time of year the literacy measure data was collected for this report (e.g., fall, winter, or spring) in for all schools in the district. You are encouraged to submit your most recent data whenever possible.
C43: The data collection process assumes the district is reporting data from all schools that was collected in the same time period (fall, winter, or spring) to allow summary of data across all schools in district. It is also implied that all schools are using the same measure of 'at or above grade level'.
B44: d. | C44: Provide details about the measure including how 'at or above grade level' cuts were determined
C45: if measure was locally developed
C46: OR
...

Sheet District Information & Measures
A1: Reading Well by Third Grade
A2: Assessment Data Submission 2013
A4: District Information and Literacy Measures
A6: Date of Report: | H6: , 2013
A8: District/Charter School Name:
A9: District Number: | E9: District Type: | G9: Select
A11: Person Responsible for Report and Contact Information
A12: Name:
A13: Address:
A14: City: | F14: , MN | G14: Zipcode:
A15: Phone: | F15: Title:
A17: Identify screening measures used for determining grade level reading proficiency.
A18: Grade | B18: Type of Measure | C18: Name of Measure Used | D18: Criteria for Determining 'at or above grade level' | H18: Date Measure Administered | I18: Explanation of Measure If Locally Developed or If Not Using Expected Norms
A19: Kindergarten | B19: Letter Sounds | H19: Select
B20: Oral Language | H20: Select
B21: Blending/Segmenting | H21: Select
B22: Kindergarten Other 1 | H22: Select
B23: Kindergarten Other 2 | H23: Select
A24: Grade 1 | B24: Decodable Words | H24: Select
B25: Oral Language | H25: Select
B26: Blending/Segmenting | H26: Select
B27: Grade 1 Other 1 | H27: Select
B28: Grade 1 Other 2 | H28: Select
A29: Grade 2 | B29: High Frequency Words | H29: Select
B30: Oral Language | H30: Select
B31: Oral Fluency | H31: Select
B32: Grade 2 Other 1 | H32: Select
B33: Grade 2 Other 2 | H33: Select
A34: Grade 3 | B34: Vocabulary | H34: Select
B35: Comprehension | H35: Select
B36: Oral Fluency | H36: Select
B37: Grade 3 Other 1 | H37: Select
B38: Grade 3 Other 2 | H38: Select
A40: Summarize practices currently used in district schools that will lead to all students reading well by third grade
A43: List all district elementary schools serving grades K - 3 and MARSS grade enrollment at time literacy data is gathered:
A44: School Number | B44: School Name | D44: Enrollment (during administration of reported literacy measures) | H44: Link to Literacy Data worksheet | I44: Additional Comments or Information About School
D45: Kindergarten | E45: Grade 1 | F45: Grade 2 | G45: Grade 3 | H45: School Number Count
D46: 0 | E46: 0 | F46: 0 | G46: 0 | H46: 1
D47: 0 | E47: 0 | F47: 0 | G47: 0 | H47: 2
D48: 0 | E48: 0 | F48: 0 | G48: 0 | H48: 3
...

Sheet Literacy Data
A1: Grade | B1: Type of Measure | C1: Name of Measure | D1: Count of Students 'at or above grade level' and Count of Students Assessed | M1: Count of Students 'at or above grade level' and Count of Students Assessed
D2: District Summary | G2: School # 1 | J2: School # 2 | M2: School # 3 | P2: School # 4 | S2: School # 5 | V2: School # 6 | Y2: School # 7 | AB2: School # 8 | AE2: School # 9 | AH2: School # 10 | AK2: School # 11 | AN2: School # 12 | AQ2: School # 13 | AT2: School # 14 | AW2: School # 15 | AZ2: School # 16 | BC2: School # 17 | BF2: School # 18 | BI2: School # 19 | BL2: School # 20 | BO2: School # 21 | BR2: School # 22 | BU2: School # 23 | BX2: School # 24 | CA2: School # 25 | CD2: School # 26 | CG2: School # 27 | CJ2: School # 28 | CM2: School # 29 | CP2: School # 30 | CS2: School # 31 | CV2: School # 32 | CY2: School # 33 | DB2: School # 34 | DE2: School # 35 | DH2: School # 36 | DK2: School # 37 | DN2: School # 38 | DQ2: School # 39 | DT2: School # 40 | DW2: School # 41 | DZ2: School # 42 | EC2: School # 43 | EF2: School # 44 | EI2: School # 45 | EL2: School # 46 | EO2: School # 47 | ER2: School # 48 | EU2: School # 49 | EX2: School # 50 | FA2: School # 51 | FD2: School # 52 | FG2: School # 53
G3: ='District Information & Measures'!B46 -> 0 | J3: ='District Information & Measures'!B47 -> 0 | M3: ='District Information & Measures'!B48 -> 0 | P3: ='District Information & Measures'!B49 -> 0 | S3: ='District Information & Measures'!B50 -> 0 | V3: ='District Information & Measures'!B51 -> 0 | Y3: ='District Information & Measures'!B52 -> 0 | AB3: ='District Information & Measures'!B53 -> 0 | AE3: ='District Information & Measures'!B54 -> 0 | AH3: ='District Information & Measures'!B55 -> 0 | AK3: ='District Information & Measures'!B56 -> 0 | AN3: ='District Information & Measures'!B57 -> 0 | AQ3: ='District Information & Measures'!B58 -> 0 | AT3: ='District Information & Measures'!B59 -> 0 | AW3: ='District Information & Measures'!B60 -> 0 | AZ3: ='District Information & Measures'!B61 -> 0 | BC3: ='District Information & Measures'!B62 -> 0 | BF3: ='District Information & Measures'!B63 -> 0 | BI3: ='District Information & Measures'!B64 -> 0 | BL3: ='District Information & Measures'!B65 -> 0 | BO3: ='District Information & Measures'!B66 -> 0 | BR3: ='District Information & Measures'!B67 -> 0 | BU3: ='District Information & Measures'!B68 -> 0 | BX3: ='District Information & Measures'!B69 -> 0 | CA3: ='District Information & Measures'!B70 -> 0 | CD3: ='District Information & Measures'!B71 -> 0 | CG3: ='District Information & Measures'!B72 -> 0 | CJ3: ='District Information & Measures'!B73 -> 0 | CM3: ='District Information & Measures'!B73 -> 0 | CP3: ='District Information & Measures'!B75 -> 0 | CS3: ='District Information & Measures'!B76 -> 0 | CV3: ='District Information & Measures'!B77 -> 0 | CY3: ='District Information & Measures'!B78 -> 0 | DB3: ='District Information & Measures'!B79 -> 0 | DE3: ='District Information & Measures'!B80 -> 0 | DH3: ='District Information & Measures'!B81 -> 0 | DK3: ='District Information & Measures'!B82 -> 0 | DN3: ='District Information & Measures'!B83 -> 0 | DQ3: ='District Information & Measures'!B84 -> 0 | DT3: ='District Information & Measures'!B85 -> 0 | DW3: ='District Information & Measures'!B86 -> 0 | DZ3: ='District Information & Measures'!B87 -> 0 | EC3: ='District Information & Measures'!B88 -> 0 | EF3: ='District Information & Measures'!B89 -> 0 | EI3: ='District Information & Measures'!B90 -> 0 | EL3: ='District Information & Measures'!B91 -> 0 | EO3: ='District Information & Measures'!B92 -> 0 | ER3: ='District Information & Measures'!B93 -> 0 | EU3: ='District Information & Measures'!B94 -> 0 | EX3: ='District Information & Measures'!B95 -> 0 | FA3: ='District Information & Measures'!B96 -> 0 | FD3: ='District Information & Measures'!B97 -> 0 | FG3: ='District Information & Measures'!B98 -> 0
E4: Number | G4: Percent 'at or above grade level' | H4: Number | J4: Percent 'at or above grade level' | K4: Number | M4: Percent 'at or above grade level' | N4: Number | P4: Percent 'at or above grade level' | Q4: Number | S4: Percent 'at or above grade level' | T4: Number | V4: Percent 'at or above grade level' | W4: Number | Y4: Percent 'at or above grade level' | Z4: Number | AB4: Percent 'at or above grade level' | AC4: Number | AE4: Percent 'at or above grade level' | AF4: Number | AH4: Percent 'at or above grade level' | AI4: Number | AK4: Percent 'at or above grade level' | AL4: Number | AN4: Percent 'at or above grade level' | AO4: Number | AQ4: Percent 'at or above grade level' | AR4: Number | AT4: Percent 'at or above grade level' | AU4: Number | AW4: Percent 'at or above grade level' | AX4: Number | AZ4: Percent 'at or above grade level' | BA4: Number | BC4: Percent 'at or above grade level' | BD4: Number | BF4: Percent 'at or above grade level' | BG4: Number | BI4: Percent 'at or above grade level' | BJ4: Number | BL4: Percent 'at or above grade level' | BM4: Number | BO4: Percent 'at or above grade level' | BP4: Number | BR4: Percent 'at or above grade level' | BS4: Number | BU4: Percent 'at or above grade level' | BV4: Number | BX4: Percent 'at or above grade level' | BY4: Number | CA4: Percent 'at or above grade level' | CB4: Number | CD4: Percent 'at or above grade level' | CE4: Number | CG4: Percent 'at or above grade level' | CH4: Number | CJ4: Percent 'at or above grade level' | CK4: Number | CM4: Percent 'at or above grade level' | CN4: Number | CP4: Percent 'at or above grade level' | CQ4: Number | CS4: Percent 'at or above grade level' | CT4: Number | CV4: Percent 'at or above grade level' | CW4: Number | CY4: Percent 'at or above grade level' | CZ4: Number | DB4: Percent 'at or above grade level' | DC4: Number | DE4: Percent 'at or above grade level' | DF4: Number | DH4: Percent 'at or above grade level' | DI4: Number | DK4: Percent 'at or above grade level' | DL4: Number | DN4: Percent 'at or above grade level' | DO4: Number | DQ4: Percent 'at or above grade level' | DR4: Number | DT4: Percent 'at or above grade level' | DU4: Number | DW4: Percent 'at or above grade level' | DX4: Number | DZ4: Percent 'at or above grade level' | EA4: Number | EC4: Percent 'at or above grade level' | ED4: Number | EF4: Percent 'at or above grade level' | EG4: Number | EI4: Percent 'at or above grade level' | EJ4: Number | EL4: Percent 'at or above grade level' | EM4: Number | EO4: Percent 'at or above grade level' | EP4: Number | ER4: Percent 'at or above grade level' | ES4: Number | EU4: Percent 'at or above grade level' | EV4: Number | EX4: Percent 'at or above grade level' | EY4: Number | FA4: Percent 'at or above grade level' | FB4: Number | FD4: Percent 'at or above grade level' | FE4: Number | FG4: Percent 'at or above grade level' | FH4: Number
D5: Percent 'at or above grade level' | E5: Number 'at or above grade level' | F5: Number Assessed | H5: Number 'at or above grade level' | I5: Number Assessed | K5: Number 'at or above grade level' | L5: Number Assessed | N5: Number 'at or above grade level' | O5: Number Assessed | Q5: Number 'at or above grade level' | R5: Number Assessed | T5: Number 'at or above grade level' | U5: Number Assessed | W5: Number 'at or above grade level' | X5: Number Assessed | Z5: Number 'at or above grade level' | AA5: Number Assessed | AC5: Number 'at or above grade level' | AD5: Number Assessed | AF5: Number 'at or above grade level' | AG5: Number Assessed | AI5: Number 'at or above grade level' | AJ5: Number Assessed | AL5: Number 'at or above grade level' | AM5: Number Assessed | AO5: Number 'at or above grade level' | AP5: Number Assessed | AR5: Number 'at or above grade level' | AS5: Number Assessed | AU5: Number 'at or above grade level' | AV5: Number Assessed | AX5: Number 'at or above grade level' | AY5: Number Assessed | BA5: Number 'at or above grade level' | BB5: Number Assessed | BD5: Number 'at or above grade level' | BE5: Number Assessed | BG5: Number 'at or above grade level' | BH5: Number Assessed | BJ5: Number 'at or above grade level' | BK5: Number Assessed | BM5: Number 'at or above grade level' | BN5: Number Assessed | BP5: Number 'at or above grade level' | BQ5: Number Assessed | BS5: Number 'at or above grade level' | BT5: Number Assessed | BV5: Number 'at or above grade level' | BW5: Number Assessed | BY5: Number 'at or above grade level' | BZ5: Number Assessed | CB5: Number 'at or above grade level' | CC5: Number Assessed | CE5: Number 'at or above grade level' | CF5: Number Assessed | CH5: Number 'at or above grade level' | CI5: Number Assessed | CK5: Number 'at or above grade level' | CL5: Number Assessed | CN5: Number 'at or above grade level' | CO5: Number Assessed | CQ5: Number 'at or above grade level' | CR5: Number Assessed | CT5: Number 'at or above grade level' | CU5: Number Assessed | CW5: Number 'at or above grade level' | CX5: Number Assessed | CZ5: Number 'at or above grade level' | DA5: Number Assessed | DC5: Number 'at or above grade level' | DD5: Number Assessed | DF5: Number 'at or above grade level' | DG5: Number Assessed | DI5: Number 'at or above grade level' | DJ5: Number Assessed | DL5: Number 'at or above grade level' | DM5: Number Assessed | DO5: Number 'at or above grade level' | DP5: Number Assessed | DR5: Number 'at or above grade level' | DS5: Number Assessed | DU5: Number 'at or above grade level' | DV5: Number Assessed | DX5: Number 'at or above grade level' | DY5: Number Assessed | EA5: Number 'at or above grade level' | EB5: Number Assessed | ED5: Number 'at or above grade level' | EE5: Number Assessed | EG5: Number 'at or above grade level' | EH5: Number Assessed | EJ5: Number 'at or above grade level' | EK5: Number Assessed | EM5: Number 'at or above grade level' | EN5: Number Assessed | EP5: Number 'at or above grade level' | EQ5: Number Assessed | ES5: Number 'at or above grade level' | ET5: Number Assessed | EV5: Number 'at or above grade level' | EW5: Number Assessed | EY5: Number 'at or above grade level' | EZ5: Number Assessed | FB5: Number 'at or above grade level' | FC5: Number Assessed | FE5: Number 'at or above grade level' | FF5: Number Assessed | FH5: Number 'at or above grade level' | FI5: Number Assessed
A6: Kindergarten | B6: Letter Sound | C6: ='District Information & Measures'!C19 -> 0 | D6: =E6/F6 -> 1.25 | E6: =SUM(H6,K6,N6,Q6,T6,W6,Z6,AC6,AF6,AI6,AL6,AO6,AR6,AU6,AX6,BA6,BD6,BG6,BJ6,BM6,BP6,BS6,BV6,BY6,CB6,CE6,CH6,CK6,CN6,CQ6,CT6,CW6,CZ6,DC6,DF6,DI6,DL6,DO6,DR6,DU6,DX6,EA6,ED6,EG6,EJ6,EM6,EP6,ES6,EV6,EY6,FB6,FE6,FH6) -> 30 | F6: =SUM(I6,L6,O6,R6,U6,X6,AA6,AD6,AG6,AJ6,AM6,AP6,AS6,AV6,AY6,BB6,BE6,BH6,BK6,BN6,BQ6,BT6,BW6,BZ6,CC6,CF6,CI6,CL6,CO6,CR6,CU6,CX6,DA6,DD6,DG6,DJ6,DM6,DP6,DS6,DV6,DY6,EB6,EE6,EH6,EK6,EN6,EQ6,ET6,EW6,EZ6,FC6,FF6,FI6) -> 24 | G6: =H6/I6 -> 1.25 | H6: 30 | I6: 24 | J6: =K6/L6 -> #DIV/0! | K6: 0 | L6: 0 | M6: =N6/O6 -> #DIV/0! | N6: 0 | O6: 0 | P6: =Q6/R6 -> #DIV/0! | Q6: 0 | R6: 0 | S6: =T6/U6 -> #DIV/0! | T6: 0 | U6: 0 | V6: =W6/X6 -> #DIV/0! | W6: 0 | X6: 0 | Y6: =Z6/AA6 -> #DIV/0! | Z6: 0 | AA6: 0 | AB6: =AC6/AD6 -> #DIV/0! | AC6: 0 | AD6: 0 | AE6: =AF6/AG6 -> #DIV/0! | AF6: 0 | AG6: 0 | AH6: =AI6/AJ6 -> #DIV/0! | AI6: 0 | AJ6: 0 | AK6: =AL6/AM6 -> #DIV/0! | AL6: 0 | AM6: 0 | AN6: =AO6/AP6 -> #DIV/0! | AO6: 0 | AP6: 0 | AQ6: =AR6/AS6 -> #DIV/0! | AR6: 0 | AS6: 0 | AT6: =AU6/AV6 -> #DIV/0! | AU6: 0 | AV6: 0 | AW6: =AX6/AY6 -> #DIV/0! | AX6: 0 | AY6: 0 | AZ6: =BA6/BB6 -> #DIV/0! | BA6: 0 | BB6: 0 | BC6: =BD6/BE6 -> #DIV/0! | BD6: 0 | BE6: 0 | BF6: =BG6/BH6 -> #DIV/0! | BG6: 0 | BH6: 0 | BI6: =BJ6/BK6 -> #DIV/0! | BJ6: 0 | BK6: 0 | BL6: =BM6/BN6 -> #DIV/0! | BM6: 0 | BN6: 0 | BO6: =BP6/BQ6 -> #DIV/0! | BP6: 0 | BQ6: 0 | BR6: =BS6/BT6 -> #DIV/0! | BS6: 0 | BT6: 0 | BU6: =BV6/BW6 -> #DIV/0! | BV6: 0 | BW6: 0 | BX6: =BY6/BZ6 -> #DIV/0! | BY6: 0 | BZ6: 0 | CA6: =CB6/CC6 -> #DIV/0! | CB6: 0 | CC6: 0 | CD6: =CE6/CF6 -> #DIV/0! | CE6: 0 | CF6: 0 | CG6: =CH6/CI6 -> #DIV/0! | CH6: 0 | CI6: 0 | CJ6: =CK6/CL6 -> #DIV/0! | CK6: 0 | CL6: 0 | CM6: =CN6/CO6 -> #DIV/0! | CN6: 0 | CO6: 0 | CP6: =CQ6/CR6 -> #DIV/0! | CQ6: 0 | CR6: 0 | CS6: =CT6/CU6 -> #DIV/0! | CT6: 0 | CU6: 0 | CV6: =CW6/CX6 -> #DIV/0! | CW6: 0 | CX6: 0 | CY6: =CZ6/DA6 -> #DIV/0! | CZ6: 0 | DA6: 0 | DB6: =DC6/DD6 -> #DIV/0! | DC6: 0 | DD6: 0 | DE6: =DF6/DG6 -> #DIV/0! | DF6: 0 | DG6: 0 | DH6: =DI6/DJ6 -> #DIV/0! | DI6: 0 | DJ6: 0 | DK6: =DL6/DM6 -> #DIV/0! | DL6: 0 | DM6: 0 | DN6: =DO6/DP6 -> #DIV/0! | DO6: 0 | DP6: 0 | DQ6: =DR6/DS6 -> #DIV/0! | DR6: 0 | DS6: 0 | DT6: =DU6/DV6 -> #DIV/0! | DU6: 0 | DV6: 0 | DW6: =DX6/DY6 -> #DIV/0! | DX6: 0 | DY6: 0 | DZ6: =EA6/EB6 -> #DIV/0! | EA6: 0 | EB6: 0 | EC6: =ED6/EE6 -> #DIV/0! | ED6: 0 | EE6: 0 | EF6: =EG6/EH6 -> #DIV/0! | EG6: 0 | EH6: 0 | EI6: =EJ6/EK6 -> #DIV/0! | EJ6: 0 | EK6: 0 | EL6: =EM6/EN6 -> #DIV/0! | EM6: 0 | EN6: 0 | EO6: =EP6/EQ6 -> #DIV/0! | EP6: 0 | EQ6: 0 | ER6: =ES6/ET6 -> #DIV/0! | ES6: 0 | ET6: 0 | EU6: =EV6/EW6 -> #DIV/0! | EV6: 0 | EW6: 0 | EX6: =EY6/EZ6 -> #DIV/0! | EY6: 0 | EZ6: 0 | FA6: =FB6/FC6 -> #DIV/0! | FB6: 0 | FC6: 0 | FD6: =FE6/FF6 -> #DIV/0! | FE6: 0 | FF6: 0 | FG6: =FH6/FI6 -> #DIV/0! | FH6: 0 | FI6: 0
B7: Oral Language | C7: ='District Information & Measures'!C20 -> 0 | D7: =E7/F7 -> #DIV/0! | E7: =SUM(H7,K7,N7,Q7,T7,W7,Z7,AC7,AF7,AI7,AL7,AO7,AR7,AU7,AX7,BA7,BD7,BG7,BJ7,BM7,BP7,BS7,BV7,BY7,CB7,CE7,CH7,CK7,CN7,CQ7,CT7,CW7,CZ7,DC7,DF7,DI7,DL7,DO7,DR7,DU7,DX7,EA7,ED7,EG7,EJ7,EM7,EP7,ES7,EV7,EY7,FB7,FE7,FH7) -> 0 | F7: =SUM(I7,L7,O7,R7,U7,X7,AA7,AD7,AG7,AJ7,AM7,AP7,AS7,AV7,AY7,BB7,BE7,BH7,BK7,BN7,BQ7,BT7,BW7,BZ7,CC7,CF7,CI7,CL7,CO7,CR7,CU7,CX7,DA7,DD7,DG7,DJ7,DM7,DP7,DS7,DV7,DY7,EB7,EE7,EH7,EK7,EN7,EQ7,ET7,EW7,EZ7,FC7,FF7,FI7) -> 0 | G7: =H7/I7 -> #DIV/0! | H7: 0 | I7: 0 | J7: =K7/L7 -> #DIV/0! | K7: 0 | L7: 0 | M7: =N7/O7 -> #DIV/0! | N7: 0 | O7: 0 | P7: =Q7/R7 -> #DIV/0! | Q7: 0 | R7: 0 | S7: =T7/U7 -> #DIV/0! | T7: 0 | U7: 0 | V7: =W7/X7 -> #DIV/0! | W7: 0 | X7: 0 | Y7: =Z7/AA7 -> #DIV/0! | Z7: 0 | AA7: 0 | AB7: =AC7/AD7 -> #DIV/0! | AC7: 0 | AD7: 0 | AE7: =AF7/AG7 -> #DIV/0! | AF7: 0 | AG7: 0 | AH7: =AI7/AJ7 -> #DIV/0! | AI7: 0 | AJ7: 0 | AK7: =AL7/AM7 -> #DIV/0! | AL7: 0 | AM7: 0 | AN7: =AO7/AP7 -> #DIV/0! | AO7: 0 | AP7: 0 | AQ7: =AR7/AS7 -> #DIV/0! | AR7: 0 | AS7: 0 | AT7: =AU7/AV7 -> #DIV/0! | AU7: 0 | AV7: 0 | AW7: =AX7/AY7 -> #DIV/0! | AX7: 0 | AY7: 0 | AZ7: =BA7/BB7 -> #DIV/0! | BA7: 0 | BB7: 0 | BC7: =BD7/BE7 -> #DIV/0! | BD7: 0 | BE7: 0 | BF7: =BG7/BH7 -> #DIV/0! | BG7: 0 | BH7: 0 | BI7: =BJ7/BK7 -> #DIV/0! | BJ7: 0 | BK7: 0 | BL7: =BM7/BN7 -> #DIV/0! | BM7: 0 | BN7: 0 | BO7: =BP7/BQ7 -> #DIV/0! | BP7: 0 | BQ7: 0 | BR7: =BS7/BT7 -> #DIV/0! | BS7: 0 | BT7: 0 | BU7: =BV7/BW7 -> #DIV/0! | BV7: 0 | BW7: 0 | BX7: =BY7/BZ7 -> #DIV/0! | BY7: 0 | BZ7: 0 | CA7: =CB7/CC7 -> #DIV/0! | CB7: 0 | CC7: 0 | CD7: =CE7/CF7 -> #DIV/0! | CE7: 0 | CF7: 0 | CG7: =CH7/CI7 -> #DIV/0! | CH7: 0 | CI7: 0 | CJ7: =CK7/CL7 -> #DIV/0! | CK7: 0 | CL7: 0 | CM7: =CN7/CO7 -> #DIV/0! | CN7: 0 | CO7: 0 | CP7: =CQ7/CR7 -> #DIV/0! | CQ7: 0 | CR7: 0 | CS7: =CT7/CU7 -> #DIV/0! | CT7: 0 | CU7: 0 | CV7: =CW7/CX7 -> #DIV/0! | CW7: 0 | CX7: 0 | CY7: =CZ7/DA7 -> #DIV/0! | CZ7: 0 | DA7: 0 | DB7: =DC7/DD7 -> #DIV/0! | DC7: 0 | DD7: 0 | DE7: =DF7/DG7 -> #DIV/0! | DF7: 0 | DG7: 0 | DH7: =DI7/DJ7 -> #DIV/0! | DI7: 0 | DJ7: 0 | DK7: =DL7/DM7 -> #DIV/0! | DL7: 0 | DM7: 0 | DN7: =DO7/DP7 -> #DIV/0! | DO7: 0 | DP7: 0 | DQ7: =DR7/DS7 -> #DIV/0! | DR7: 0 | DS7: 0 | DT7: =DU7/DV7 -> #DIV/0! | DU7: 0 | DV7: 0 | DW7: =DX7/DY7 -> #DIV/0! | DX7: 0 | DY7: 0 | DZ7: =EA7/EB7 -> #DIV/0! | EA7: 0 | EB7: 0 | EC7: =ED7/EE7 -> #DIV/0! | ED7: 0 | EE7: 0 | EF7: =EG7/EH7 -> #DIV/0! | EG7: 0 | EH7: 0 | EI7: =EJ7/EK7 -> #DIV/0! | EJ7: 0 | EK7: 0 | EL7: =EM7/EN7 -> #DIV/0! | EM7: 0 | EN7: 0 | EO7: =EP7/EQ7 -> #DIV/0! | EP7: 0 | EQ7: 0 | ER7: =ES7/ET7 -> #DIV/0! | ES7: 0 | ET7: 0 | EU7: =EV7/EW7 -> #DIV/0! | EV7: 0 | EW7: 0 | EX7: =EY7/EZ7 -> #DIV/0! | EY7: 0 | EZ7: 0 | FA7: =FB7/FC7 -> #DIV/0! | FB7: 0 | FC7: 0 | FD7: =FE7/FF7 -> #DIV/0! | FE7: 0 | FF7: 0 | FG7: =FH7/FI7 -> #DIV/0! | FH7: 0 | FI7: 0
B8: Blending/Segmenting | C8: ='District Information & Measures'!C21 -> 0 | D8: =E8/F8 -> #DIV/0! | E8: =SUM(H8,K8,N8,Q8,T8,W8,Z8,AC8,AF8,AI8,AL8,AO8,AR8,AU8,AX8,BA8,BD8,BG8,BJ8,BM8,BP8,BS8,BV8,BY8,CB8,CE8,CH8,CK8,CN8,CQ8,CT8,CW8,CZ8,DC8,DF8,DI8,DL8,DO8,DR8,DU8,DX8,EA8,ED8,EG8,EJ8,EM8,EP8,ES8,EV8,EY8,FB8,FE8,FH8) -> 0 | F8: =SUM(I8,L8,O8,R8,U8,X8,AA8,AD8,AG8,AJ8,AM8,AP8,AS8,AV8,AY8,BB8,BE8,BH8,BK8,BN8,BQ8,BT8,BW8,BZ8,CC8,CF8,CI8,CL8,CO8,CR8,CU8,CX8,DA8,DD8,DG8,DJ8,DM8,DP8,DS8,DV8,DY8,EB8,EE8,EH8,EK8,EN8,EQ8,ET8,EW8,EZ8,FC8,FF8,FI8) -> 0 | G8: =H8/I8 -> #DIV/0! | H8: 0 | I8: 0 | J8: =K8/L8 -> #DIV/0! | K8: 0 | L8: 0 | M8: =N8/O8 -> #DIV/0! | N8: 0 | O8: 0 | P8: =Q8/R8 -> #DIV/0! | Q8: 0 | R8: 0 | S8: =T8/U8 -> #DIV/0! | T8: 0 | U8: 0 | V8: =W8/X8 -> #DIV/0! | W8: 0 | X8: 0 | Y8: =Z8/AA8 -> #DIV/0! | Z8: 0 | AA8: 0 | AB8: =AC8/AD8 -> #DIV/0! | AC8: 0 | AD8: 0 | AE8: =AF8/AG8 -> #DIV/0! | AF8: 0 | AG8: 0 | AH8: =AI8/AJ8 -> #DIV/0! | AI8: 0 | AJ8: 0 | AK8: =AL8/AM8 -> #DIV/0! | AL8: 0 | AM8: 0 | AN8: =AO8/AP8 -> #DIV/0! | AO8: 0 | AP8: 0 | AQ8: =AR8/AS8 -> #DIV/0! | AR8: 0 | AS8: 0 | AT8: =AU8/AV8 -> #DIV/0! | AU8: 0 | AV8: 0 | AW8: =AX8/AY8 -> #DIV/0! | AX8: 0 | AY8: 0 | AZ8: =BA8/BB8 -> #DIV/0! | BA8: 0 | BB8: 0 | BC8: =BD8/BE8 -> #DIV/0! | BD8: 0 | BE8: 0 | BF8: =BG8/BH8 -> #DIV/0! | BG8: 0 | BH8: 0 | BI8: =BJ8/BK8 -> #DIV/0! | BJ8: 0 | BK8: 0 | BL8: =BM8/BN8 -> #DIV/0! | BM8: 0 | BN8: 0 | BO8: =BP8/BQ8 -> #DIV/0! | BP8: 0 | BQ8: 0 | BR8: =BS8/BT8 -> #DIV/0! | BS8: 0 | BT8: 0 | BU8: =BV8/BW8 -> #DIV/0! | BV8: 0 | BW8: 0 | BX8: =BY8/BZ8 -> #DIV/0! | BY8: 0 | BZ8: 0 | CA8: =CB8/CC8 -> #DIV/0! | CB8: 0 | CC8: 0 | CD8: =CE8/CF8 -> #DIV/0! | CE8: 0 | CF8: 0 | CG8: =CH8/CI8 -> #DIV/0! | CH8: 0 | CI8: 0 | CJ8: =CK8/CL8 -> #DIV/0! | CK8: 0 | CL8: 0 | CM8: =CN8/CO8 -> #DIV/0! | CN8: 0 | CO8: 0 | CP8: =CQ8/CR8 -> #DIV/0! | CQ8: 0 | CR8: 0 | CS8: =CT8/CU8 -> #DIV/0! | CT8: 0 | CU8: 0 | CV8: =CW8/CX8 -> #DIV/0! | CW8: 0 | CX8: 0 | CY8: =CZ8/DA8 -> #DIV/0! | CZ8: 0 | DA8: 0 | DB8: =DC8/DD8 -> #DIV/0! | DC8: 0 | DD8: 0 | DE8: =DF8/DG8 -> #DIV/0! | DF8: 0 | DG8: 0 | DH8: =DI8/DJ8 -> #DIV/0! | DI8: 0 | DJ8: 0 | DK8: =DL8/DM8 -> #DIV/0! | DL8: 0 | DM8: 0 | DN8: =DO8/DP8 -> #DIV/0! | DO8: 0 | DP8: 0 | DQ8: =DR8/DS8 -> #DIV/0! | DR8: 0 | DS8: 0 | DT8: =DU8/DV8 -> #DIV/0! | DU8: 0 | DV8: 0 | DW8: =DX8/DY8 -> #DIV/0! | DX8: 0 | DY8: 0 | DZ8: =EA8/EB8 -> #DIV/0! | EA8: 0 | EB8: 0 | EC8: =ED8/EE8 -> #DIV/0! | ED8: 0 | EE8: 0 | EF8: =EG8/EH8 -> #DIV/0! | EG8: 0 | EH8: 0 | EI8: =EJ8/EK8 -> #DIV/0! | EJ8: 0 | EK8: 0 | EL8: =EM8/EN8 -> #DIV/0! | EM8: 0 | EN8: 0 | EO8: =EP8/EQ8 -> #DIV/0! | EP8: 0 | EQ8: 0 | ER8: =ES8/ET8 -> #DIV/0! | ES8: 0 | ET8: 0 | EU8: =EV8/EW8 -> #DIV/0! | EV8: 0 | EW8: 0 | EX8: =EY8/EZ8 -> #DIV/0! | EY8: 0 | EZ8: 0 | FA8: =FB8/FC8 -> #DIV/0! | FB8: 0 | FC8: 0 | FD8: =FE8/FF8 -> #DIV/0! | FE8: 0 | FF8: 0 | FG8: =FH8/FI8 -> #DIV/0! | FH8: 0 | FI8: 0
B9: Kindergarten Other 1 | C9: ='District Information & Measures'!C22 -> 0 | D9: =E9/F9 -> #DIV/0! | E9: =SUM(H9,K9,N9,Q9,T9,W9,Z9,AC9,AF9,AI9,AL9,AO9,AR9,AU9,AX9,BA9,BD9,BG9,BJ9,BM9,BP9,BS9,BV9,BY9,CB9,CE9,CH9,CK9,CN9,CQ9,CT9,CW9,CZ9,DC9,DF9,DI9,DL9,DO9,DR9,DU9,DX9,EA9,ED9,EG9,EJ9,EM9,EP9,ES9,EV9,EY9,FB9,FE9,FH9) -> 0 | F9: =SUM(I9,L9,O9,R9,U9,X9,AA9,AD9,AG9,AJ9,AM9,AP9,AS9,AV9,AY9,BB9,BE9,BH9,BK9,BN9,BQ9,BT9,BW9,BZ9,CC9,CF9,CI9,CL9,CO9,CR9,CU9,CX9,DA9,DD9,DG9,DJ9,DM9,DP9,DS9,DV9,DY9,EB9,EE9,EH9,EK9,EN9,EQ9,ET9,EW9,EZ9,FC9,FF9,FI9) -> 0 | G9: =H9/I9 -> #DIV/0! | H9: 0 | I9: 0 | J9: =K9/L9 -> #DIV/0! | K9: 0 | L9: 0 | M9: =N9/O9 -> #DIV/0! | N9: 0 | O9: 0 | P9: =Q9/R9 -> #DIV/0! | Q9: 0 | R9: 0 | S9: =T9/U9 -> #DIV/0! | T9: 0 | U9: 0 | V9: =W9/X9 -> #DIV/0! | W9: 0 | X9: 0 | Y9: =Z9/AA9 -> #DIV/0! | Z9: 0 | AA9: 0 | AB9: =AC9/AD9 -> #DIV/0! | AC9: 0 | AD9: 0 | AE9: =AF9/AG9 -> #DIV/0! | AF9: 0 | AG9: 0 | AH9: =AI9/AJ9 -> #DIV/0! | AI9: 0 | AJ9: 0 | AK9: =AL9/AM9 -> #DIV/0! | AL9: 0 | AM9: 0 | AN9: =AO9/AP9 -> #DIV/0! | AO9: 0 | AP9: 0 | AQ9: =AR9/AS9 -> #DIV/0! | AR9: 0 | AS9: 0 | AT9: =AU9/AV9 -> #DIV/0! | AU9: 0 | AV9: 0 | AW9: =AX9/AY9 -> #DIV/0! | AX9: 0 | AY9: 0 | AZ9: =BA9/BB9 -> #DIV/0! | BA9: 0 | BB9: 0 | BC9: =BD9/BE9 -> #DIV/0! | BD9: 0 | BE9: 0 | BF9: =BG9/BH9 -> #DIV/0! | BG9: 0 | BH9: 0 | BI9: =BJ9/BK9 -> #DIV/0! | BJ9: 0 | BK9: 0 | BL9: =BM9/BN9 -> #DIV/0! | BM9: 0 | BN9: 0 | BO9: =BP9/BQ9 -> #DIV/0! | BP9: 0 | BQ9: 0 | BR9: =BS9/BT9 -> #DIV/0! | BS9: 0 | BT9: 0 | BU9: =BV9/BW9 -> #DIV/0! | BV9: 0 | BW9: 0 | BX9: =BY9/BZ9 -> #DIV/0! | BY9: 0 | BZ9: 0 | CA9: =CB9/CC9 -> #DIV/0! | CB9: 0 | CC9: 0 | CD9: =CE9/CF9 -> #DIV/0! | CE9: 0 | CF9: 0 | CG9: =CH9/CI9 -> #DIV/0! | CH9: 0 | CI9: 0 | CJ9: =CK9/CL9 -> #DIV/0! | CK9: 0 | CL9: 0 | CM9: =CN9/CO9 -> #DIV/0! | CN9: 0 | CO9: 0 | CP9: =CQ9/CR9 -> #DIV/0! | CQ9: 0 | CR9: 0 | CS9: =CT9/CU9 -> #DIV/0! | CT9: 0 | CU9: 0 | CV9: =CW9/CX9 -> #DIV/0! | CW9: 0 | CX9: 0 | CY9: =CZ9/DA9 -> #DIV/0! | CZ9: 0 | DA9: 0 | DB9: =DC9/DD9 -> #DIV/0! | DC9: 0 | DD9: 0 | DE9: =DF9/DG9 -> #DIV/0! | DF9: 0 | DG9: 0 | DH9: =DI9/DJ9 -> #DIV/0! | DI9: 0 | DJ9: 0 | DK9: =DL9/DM9 -> #DIV/0! | DL9: 0 | DM9: 0 | DN9: =DO9/DP9 -> #DIV/0! | DO9: 0 | DP9: 0 | DQ9: =DR9/DS9 -> #DIV/0! | DR9: 0 | DS9: 0 | DT9: =DU9/DV9 -> #DIV/0! | DU9: 0 | DV9: 0 | DW9: =DX9/DY9 -> #DIV/0! | DX9: 0 | DY9: 0 | DZ9: =EA9/EB9 -> #DIV/0! | EA9: 0 | EB9: 0 | EC9: =ED9/EE9 -> #DIV/0! | ED9: 0 | EE9: 0 | EF9: =EG9/EH9 -> #DIV/0! | EG9: 0 | EH9: 0 | EI9: =EJ9/EK9 -> #DIV/0! | EJ9: 0 | EK9: 0 | EL9: =EM9/EN9 -> #DIV/0! | EM9: 0 | EN9: 0 | EO9: =EP9/EQ9 -> #DIV/0! | EP9: 0 | EQ9: 0 | ER9: =ES9/ET9 -> #DIV/0! | ES9: 0 | ET9: 0 | EU9: =EV9/EW9 -> #DIV/0! | EV9: 0 | EW9: 0 | EX9: =EY9/EZ9 -> #DIV/0! | EY9: 0 | EZ9: 0 | FA9: =FB9/FC9 -> #DIV/0! | FB9: 0 | FC9: 0 | FD9: =FE9/FF9 -> #DIV/0! | FE9: 0 | FF9: 0 | FG9: =FH9/FI9 -> #DIV/0! | FH9: 0 | FI9: 0
B10: Kindergarten Other 2 | C10: ='District Information & Measures'!C23 -> 0 | D10: =E10/F10 -> #DIV/0! | E10: =SUM(H10,K10,N10,Q10,T10,W10,Z10,AC10,AF10,AI10,AL10,AO10,AR10,AU10,AX10,BA10,BD10,BG10,BJ10,BM10,BP10,BS10,BV10,BY10,CB10,CE10,CH10,CK10,CN10,CQ10,CT10,CW10,CZ10,DC10,DF10,DI10,DL10,DO10,DR10,DU10,DX10,EA10,ED10,EG10,EJ10,EM10,EP10,ES10,EV10,EY10,FB10,FE10,FH10) -> 0 | F10: =SUM(I10,L10,O10,R10,U10,X10,AA10,AD10,AG10,AJ10,AM10,AP10,AS10,AV10,AY10,BB10,BE10,BH10,BK10,BN10,BQ10,BT10,BW10,BZ10,CC10,CF10,CI10,CL10,CO10,CR10,CU10,CX10,DA10,DD10,DG10,DJ10,DM10,DP10,DS10,DV10,DY10,EB10,EE10,EH10,EK10,EN10,EQ10,ET10,EW10,EZ10,FC10,FF10,FI10) -> 0 | G10: =H10/I10 -> #DIV/0! | H10: 0 | I10: 0 | J10: =K10/L10 -> #DIV/0! | K10: 0 | L10: 0 | M10: =N10/O10 -> #DIV/0! | N10: 0 | O10: 0 | P10: =Q10/R10 -> #DIV/0! | Q10: 0 | R10: 0 | S10: =T10/U10 -> #DIV/0! | T10: 0 | U10: 0 | V10: =W10/X10 -> #DIV/0! | W10: 0 | X10: 0 | Y10: =Z10/AA10 -> #DIV/0! | Z10: 0 | AA10: 0 | AB10: =AC10/AD10 -> #DIV/0! | AC10: 0 | AD10: 0 | AE10: =AF10/AG10 -> #DIV/0! | AF10: 0 | AG10: 0 | AH10: =AI10/AJ10 -> #DIV/0! | AI10: 0 | AJ10: 0 | AK10: =AL10/AM10 -> #DIV/0! | AL10: 0 | AM10: 0 | AN10: =AO10/AP10 -> #DIV/0! | AO10: 0 | AP10: 0 | AQ10: =AR10/AS10 -> #DIV/0! | AR10: 0 | AS10: 0 | AT10: =AU10/AV10 -> #DIV/0! | AU10: 0 | AV10: 0 | AW10: =AX10/AY10 -> #DIV/0! | AX10: 0 | AY10: 0 | AZ10: =BA10/BB10 -> #DIV/0! | BA10: 0 | BB10: 0 | BC10: =BD10/BE10 -> #DIV/0! | BD10: 0 | BE10: 0 | BF10: =BG10/BH10 -> #DIV/0! | BG10: 0 | BH10: 0 | BI10: =BJ10/BK10 -> #DIV/0! | BJ10: 0 | BK10: 0 | BL10: =BM10/BN10 -> #DIV/0! | BM10: 0 | BN10: 0 | BO10: =BP10/BQ10 -> #DIV/0! | BP10: 0 | BQ10: 0 | BR10: =BS10/BT10 -> #DIV/0! | BS10: 0 | BT10: 0 | BU10: =BV10/BW10 -> #DIV/0! | BV10: 0 | BW10: 0 | BX10: =BY10/BZ10 -> #DIV/0! | BY10: 0 | BZ10: 0 | CA10: =CB10/CC10 -> #DIV/0! | CB10: 0 | CC10: 0 | CD10: =CE10/CF10 -> #DIV/0! | CE10: 0 | CF10: 0 | CG10: =CH10/CI10 -> #DIV/0! | CH10: 0 | CI10: 0 | CJ10: =CK10/CL10 -> #DIV/0! | CK10: 0 | CL10: 0 | CM10: =CN10/CO10 -> #DIV/0! | CN10: 0 | CO10: 0 | CP10: =CQ10/CR10 -> #DIV/0! | CQ10: 0 | CR10: 0 | CS10: =CT10/CU10 -> #DIV/0! | CT10: 0 | CU10: 0 | CV10: =CW10/CX10 -> #DIV/0! | CW10: 0 | CX10: 0 | CY10: =CZ10/DA10 -> #DIV/0! | CZ10: 0 | DA10: 0 | DB10: =DC10/DD10 -> #DIV/0! | DC10: 0 | DD10: 0 | DE10: =DF10/DG10 -> #DIV/0! | DF10: 0 | DG10: 0 | DH10: =DI10/DJ10 -> #DIV/0! | DI10: 0 | DJ10: 0 | DK10: =DL10/DM10 -> #DIV/0! | DL10: 0 | DM10: 0 | DN10: =DO10/DP10 -> #DIV/0! | DO10: 0 | DP10: 0 | DQ10: =DR10/DS10 -> #DIV/0! | DR10: 0 | DS10: 0 | DT10: =DU10/DV10 -> #DIV/0! | DU10: 0 | DV10: 0 | DW10: =DX10/DY10 -> #DIV/0! | DX10: 0 | DY10: 0 | DZ10: =EA10/EB10 -> #DIV/0! | EA10: 0 | EB10: 0 | EC10: =ED10/EE10 -> #DIV/0! | ED10: 0 | EE10: 0 | EF10: =EG10/EH10 -> #DIV/0! | EG10: 0 | EH10: 0 | EI10: =EJ10/EK10 -> #DIV/0! | EJ10: 0 | EK10: 0 | EL10: =EM10/EN10 -> #DIV/0! | EM10: 0 | EN10: 0 | EO10: =EP10/EQ10 -> #DIV/0! | EP10: 0 | EQ10: 0 | ER10: =ES10/ET10 -> #DIV/0! | ES10: 0 | ET10: 0 | EU10: =EV10/EW10 -> #DIV/0! | EV10: 0 | EW10: 0 | EX10: =EY10/EZ10 -> #DIV/0! | EY10: 0 | EZ10: 0 | FA10: =FB10/FC10 -> #DIV/0! | FB10: 0 | FC10: 0 | FD10: =FE10/FF10 -> #DIV/0! | FE10: 0 | FF10: 0 | FG10: =FH10/FI10 -> #DIV/0! | FH10: 0 | FI10: 0
A12: Grade 1 | B12: Decodable Word | C12: ='District Information & Measures'!C24 -> 0 | D12: =E12/F12 -> #DIV/0! | E12: =SUM(H12,K12,N12,Q12,T12,W12,Z12,AC12,AF12,AI12,AL12,AO12,AR12,AU12,AX12,BA12,BD12,BG12,BJ12,BM12,BP12,BS12,BV12,BY12,CB12,CE12,CH12,CK12,CN12,CQ12,CT12,CW12,CZ12,DC12,DF12,DI12,DL12,DO12,DR12,DU12,DX12,EA12,ED12,EG12,EJ12,EM12,EP12,ES12,EV12,EY12,FB12,FE12,FH12) -> 0 | F12: =SUM(I12,L12,O12,R12,U12,X12,AA12,AD12,AG12,AJ12,AM12,AP12,AS12,AV12,AY12,BB12,BE12,BH12,BK12,BN12,BQ12,BT12,BW12,BZ12,CC12,CF12,CI12,CL12,CO12,CR12,CU12,CX12,DA12,DD12,DG12,DJ12,DM12,DP12,DS12,DV12,DY12,EB12,EE12,EH12,EK12,EN12,EQ12,ET12,EW12,EZ12,FC12,FF12,FI12) -> 0 | G12: =H12/I12 -> #DIV/0! | H12: 0 | I12: 0 | J12: =K12/L12 -> #DIV/0! | K12: 0 | L12: 0 | M12: =N12/O12 -> #DIV/0! | N12: 0 | O12: 0 | P12: =Q12/R12 -> #DIV/0! | Q12: 0 | R12: 0 | S12: =T12/U12 -> #DIV/0! | T12: 0 | U12: 0 | V12: =W12/X12 -> #DIV/0! | W12: 0 | X12: 0 | Y12: =Z12/AA12 -> #DIV/0! | Z12: 0 | AA12: 0 | AB12: =AC12/AD12 -> #DIV/0! | AC12: 0 | AD12: 0 | AE12: =AF12/AG12 -> #DIV/0! | AF12: 0 | AG12: 0 | AH12: =AI12/AJ12 -> #DIV/0! | AI12: 0 | AJ12: 0 | AK12: =AL12/AM12 -> #DIV/0! | AL12: 0 | AM12: 0 | AN12: =AO12/AP12 -> #DIV/0! | AO12: 0 | AP12: 0 | AQ12: =AR12/AS12 -> #DIV/0! | AR12: 0 | AS12: 0 | AT12: =AU12/AV12 -> #DIV/0! | AU12: 0 | AV12: 0 | AW12: =AX12/AY12 -> #DIV/0! | AX12: 0 | AY12: 0 | AZ12: =BA12/BB12 -> #DIV/0! | BA12: 0 | BB12: 0 | BC12: =BD12/BE12 -> #DIV/0! | BD12: 0 | BE12: 0 | BF12: =BG12/BH12 -> #DIV/0! | BG12: 0 | BH12: 0 | BI12: =BJ12/BK12 -> #DIV/0! | BJ12: 0 | BK12: 0 | BL12: =BM12/BN12 -> #DIV/0! | BM12: 0 | BN12: 0 | BO12: =BP12/BQ12 -> #DIV/0! | BP12: 0 | BQ12: 0 | BR12: =BS12/BT12 -> #DIV/0! | BS12: 0 | BT12: 0 | BU12: =BV12/BW12 -> #DIV/0! | BV12: 0 | BW12: 0 | BX12: =BY12/BZ12 -> #DIV/0! | BY12: 0 | BZ12: 0 | CA12: =CB12/CC12 -> #DIV/0! | CB12: 0 | CC12: 0 | CD12: =CE12/CF12 -> #DIV/0! | CE12: 0 | CF12: 0 | CG12: =CH12/CI12 -> #DIV/0! | CH12: 0 | CI12: 0 | CJ12: =CK12/CL12 -> #DIV/0! | CK12: 0 | CL12: 0 | CM12: =CN12/CO12 -> #DIV/0! | CN12: 0 | CO12: 0 | CP12: =CQ12/CR12 -> #DIV/0! | CQ12: 0 | CR12: 0 | CS12: =CT12/CU12 -> #DIV/0! | CT12: 0 | CU12: 0 | CV12: =CW12/CX12 -> #DIV/0! | CW12: 0 | CX12: 0 | CY12: =CZ12/DA12 -> #DIV/0! | CZ12: 0 | DA12: 0 | DB12: =DC12/DD12 -> #DIV/0! | DC12: 0 | DD12: 0 | DE12: =DF12/DG12 -> #DIV/0! | DF12: 0 | DG12: 0 | DH12: =DI12/DJ12 -> #DIV/0! | DI12: 0 | DJ12: 0 | DK12: =DL12/DM12 -> #DIV/0! | DL12: 0 | DM12: 0 | DN12: =DO12/DP12 -> #DIV/0! | DO12: 0 | DP12: 0 | DQ12: =DR12/DS12 -> #DIV/0! | DR12: 0 | DS12: 0 | DT12: =DU12/DV12 -> #DIV/0! | DU12: 0 | DV12: 0 | DW12: =DX12/DY12 -> #DIV/0! | DX12: 0 | DY12: 0 | DZ12: =EA12/EB12 -> #DIV/0! | EA12: 0 | EB12: 0 | EC12: =ED12/EE12 -> #DIV/0! | ED12: 0 | EE12: 0 | EF12: =EG12/EH12 -> #DIV/0! | EG12: 0 | EH12: 0 | EI12: =EJ12/EK12 -> #DIV/0! | EJ12: 0 | EK12: 0 | EL12: =EM12/EN12 -> #DIV/0! | EM12: 0 | EN12: 0 | EO12: =EP12/EQ12 -> #DIV/0! | EP12: 0 | EQ12: 0 | ER12: =ES12/ET12 -> #DIV/0! | ES12: 0 | ET12: 0 | EU12: =EV12/EW12 -> #DIV/0! | EV12: 0 | EW12: 0 | EX12: =EY12/EZ12 -> #DIV/0! | EY12: 0 | EZ12: 0 | FA12: =FB12/FC12 -> #DIV/0! | FB12: 0 | FC12: 0 | FD12: =FE12/FF12 -> #DIV/0! | FE12: 0 | FF12: 0 | FG12: =FH12/FI12 -> #DIV/0! | FH12: 0 | FI12: 0
B13: Oral Language | C13: ='District Information & Measures'!C25 -> 0 | D13: =E13/F13 -> #DIV/0! | E13: =SUM(H13,K13,N13,Q13,T13,W13,Z13,AC13,AF13,AI13,AL13,AO13,AR13,AU13,AX13,BA13,BD13,BG13,BJ13,BM13,BP13,BS13,BV13,BY13,CB13,CE13,CH13,CK13,CN13,CQ13,CT13,CW13,CZ13,DC13,DF13,DI13,DL13,DO13,DR13,DU13,DX13,EA13,ED13,EG13,EJ13,EM13,EP13,ES13,EV13,EY13,FB13,FE13,FH13) -> 0 | F13: =SUM(I13,L13,O13,R13,U13,X13,AA13,AD13,AG13,AJ13,AM13,AP13,AS13,AV13,AY13,BB13,BE13,BH13,BK13,BN13,BQ13,BT13,BW13,BZ13,CC13,CF13,CI13,CL13,CO13,CR13,CU13,CX13,DA13,DD13,DG13,DJ13,DM13,DP13,DS13,DV13,DY13,EB13,EE13,EH13,EK13,EN13,EQ13,ET13,EW13,EZ13,FC13,FF13,FI13) -> 0 | G13: =H13/I13 -> #DIV/0! | H13: 0 | I13: 0 | J13: =K13/L13 -> #DIV/0! | K13: 0 | L13: 0 | M13: =N13/O13 -> #DIV/0! | N13: 0 | O13: 0 | P13: =Q13/R13 -> #DIV/0! | Q13: 0 | R13: 0 | S13: =T13/U13 -> #DIV/0! | T13: 0 | U13: 0 | V13: =W13/X13 -> #DIV/0! | W13: 0 | X13: 0 | Y13: =Z13/AA13 -> #DIV/0! | Z13: 0 | AA13: 0 | AB13: =AC13/AD13 -> #DIV/0! | AC13: 0 | AD13: 0 | AE13: =AF13/AG13 -> #DIV/0! | AF13: 0 | AG13: 0 | AH13: =AI13/AJ13 -> #DIV/0! | AI13: 0 | AJ13: 0 | AK13: =AL13/AM13 -> #DIV/0! | AL13: 0 | AM13: 0 | AN13: =AO13/AP13 -> #DIV/0! | AO13: 0 | AP13: 0 | AQ13: =AR13/AS13 -> #DIV/0! | AR13: 0 | AS13: 0 | AT13: =AU13/AV13 -> #DIV/0! | AU13: 0 | AV13: 0 | AW13: =AX13/AY13 -> #DIV/0! | AX13: 0 | AY13: 0 | AZ13: =BA13/BB13 -> #DIV/0! | BA13: 0 | BB13: 0 | BC13: =BD13/BE13 -> #DIV/0! | BD13: 0 | BE13: 0 | BF13: =BG13/BH13 -> #DIV/0! | BG13: 0 | BH13: 0 | BI13: =BJ13/BK13 -> #DIV/0! | BJ13: 0 | BK13: 0 | BL13: =BM13/BN13 -> #DIV/0! | BM13: 0 | BN13: 0 | BO13: =BP13/BQ13 -> #DIV/0! | BP13: 0 | BQ13: 0 | BR13: =BS13/BT13 -> #DIV/0! | BS13: 0 | BT13: 0 | BU13: =BV13/BW13 -> #DIV/0! | BV13: 0 | BW13: 0 | BX13: =BY13/BZ13 -> #DIV/0! | BY13: 0 | BZ13: 0 | CA13: =CB13/CC13 -> #DIV/0! | CB13: 0 | CC13: 0 | CD13: =CE13/CF13 -> #DIV/0! | CE13: 0 | CF13: 0 | CG13: =CH13/CI13 -> #DIV/0! | CH13: 0 | CI13: 0 | CJ13: =CK13/CL13 -> #DIV/0! | CK13: 0 | CL13: 0 | CM13: =CN13/CO13 -> #DIV/0! | CN13: 0 | CO13: 0 | CP13: =CQ13/CR13 -> #DIV/0! | CQ13: 0 | CR13: 0 | CS13: =CT13/CU13 -> #DIV/0! | CT13: 0 | CU13: 0 | CV13: =CW13/CX13 -> #DIV/0! | CW13: 0 | CX13: 0 | CY13: =CZ13/DA13 -> #DIV/0! | CZ13: 0 | DA13: 0 | DB13: =DC13/DD13 -> #DIV/0! | DC13: 0 | DD13: 0 | DE13: =DF13/DG13 -> #DIV/0! | DF13: 0 | DG13: 0 | DH13: =DI13/DJ13 -> #DIV/0! | DI13: 0 | DJ13: 0 | DK13: =DL13/DM13 -> #DIV/0! | DL13: 0 | DM13: 0 | DN13: =DO13/DP13 -> #DIV/0! | DO13: 0 | DP13: 0 | DQ13: =DR13/DS13 -> #DIV/0! | DR13: 0 | DS13: 0 | DT13: =DU13/DV13 -> #DIV/0! | DU13: 0 | DV13: 0 | DW13: =DX13/DY13 -> #DIV/0! | DX13: 0 | DY13: 0 | DZ13: =EA13/EB13 -> #DIV/0! | EA13: 0 | EB13: 0 | EC13: =ED13/EE13 -> #DIV/0! | ED13: 0 | EE13: 0 | EF13: =EG13/EH13 -> #DIV/0! | EG13: 0 | EH13: 0 | EI13: =EJ13/EK13 -> #DIV/0! | EJ13: 0 | EK13: 0 | EL13: =EM13/EN13 -> #DIV/0! | EM13: 0 | EN13: 0 | EO13: =EP13/EQ13 -> #DIV/0! | EP13: 0 | EQ13: 0 | ER13: =ES13/ET13 -> #DIV/0! | ES13: 0 | ET13: 0 | EU13: =EV13/EW13 -> #DIV/0! | EV13: 0 | EW13: 0 | EX13: =EY13/EZ13 -> #DIV/0! | EY13: 0 | EZ13: 0 | FA13: =FB13/FC13 -> #DIV/0! | FB13: 0 | FC13: 0 | FD13: =FE13/FF13 -> #DIV/0! | FE13: 0 | FF13: 0 | FG13: =FH13/FI13 -> #DIV/0! | FH13: 0 | FI13: 0
B14: Blending/Segmenting | C14: ='District Information & Measures'!C6 -> 0 | D14: =E14/F14 -> #DIV/0! | E14: =SUM(H14,K14,N14,Q14,T14,W14,Z14,AC14,AF14,AI14,AL14,AO14,AR14,AU14,AX14,BA14,BD14,BG14,BJ14,BM14,BP14,BS14,BV14,BY14,CB14,CE14,CH14,CK14,CN14,CQ14,CT14,CW14,CZ14,DC14,DF14,DI14,DL14,DO14,DR14,DU14,DX14,EA14,ED14,EG14,EJ14,EM14,EP14,ES14,EV14,EY14,FB14,FE14,FH14) -> 0 | F14: =SUM(I14,L14,O14,R14,U14,X14,AA14,AD14,AG14,AJ14,AM14,AP14,AS14,AV14,AY14,BB14,BE14,BH14,BK14,BN14,BQ14,BT14,BW14,BZ14,CC14,CF14,CI14,CL14,CO14,CR14,CU14,CX14,DA14,DD14,DG14,DJ14,DM14,DP14,DS14,DV14,DY14,EB14,EE14,EH14,EK14,EN14,EQ14,ET14,EW14,EZ14,FC14,FF14,FI14) -> 0 | G14: =H14/I14 -> #DIV/0! | H14: 0 | I14: 0 | J14: =K14/L14 -> #DIV/0! | K14: 0 | L14: 0 | M14: =N14/O14 -> #DIV/0! | N14: 0 | O14: 0 | P14: =Q14/R14 -> #DIV/0! | Q14: 0 | R14: 0 | S14: =T14/U14 -> #DIV/0! | T14: 0 | U14: 0 | V14: =W14/X14 -> #DIV/0! | W14: 0 | X14: 0 | Y14: =Z14/AA14 -> #DIV/0! | Z14: 0 | AA14: 0 | AB14: =AC14/AD14 -> #DIV/0! | AC14: 0 | AD14: 0 | AE14: =AF14/AG14 -> #DIV/0! | AF14: 0 | AG14: 0 | AH14: =AI14/AJ14 -> #DIV/0! | AI14: 0 | AJ14: 0 | AK14: =AL14/AM14 -> #DIV/0! | AL14: 0 | AM14: 0 | AN14: =AO14/AP14 -> #DIV/0! | AO14: 0 | AP14: 0 | AQ14: =AR14/AS14 -> #DIV/0! | AR14: 0 | AS14: 0 | AT14: =AU14/AV14 -> #DIV/0! | AU14: 0 | AV14: 0 | AW14: =AX14/AY14 -> #DIV/0! | AX14: 0 | AY14: 0 | AZ14: =BA14/BB14 -> #DIV/0! | BA14: 0 | BB14: 0 | BC14: =BD14/BE14 -> #DIV/0! | BD14: 0 | BE14: 0 | BF14: =BG14/BH14 -> #DIV/0! | BG14: 0 | BH14: 0 | BI14: =BJ14/BK14 -> #DIV/0! | BJ14: 0 | BK14: 0 | BL14: =BM14/BN14 -> #DIV/0! | BM14: 0 | BN14: 0 | BO14: =BP14/BQ14 -> #DIV/0! | BP14: 0 | BQ14: 0 | BR14: =BS14/BT14 -> #DIV/0! | BS14: 0 | BT14: 0 | BU14: =BV14/BW14 -> #DIV/0! | BV14: 0 | BW14: 0 | BX14: =BY14/BZ14 -> #DIV/0! | BY14: 0 | BZ14: 0 | CA14: =CB14/CC14 -> #DIV/0! | CB14: 0 | CC14: 0 | CD14: =CE14/CF14 -> #DIV/0! | CE14: 0 | CF14: 0 | CG14: =CH14/CI14 -> #DIV/0! | CH14: 0 | CI14: 0 | CJ14: =CK14/CL14 -> #DIV/0! | CK14: 0 | CL14: 0 | CM14: =CN14/CO14 -> #DIV/0! | CN14: 0 | CO14: 0 | CP14: =CQ14/CR14 -> #DIV/0! | CQ14: 0 | CR14: 0 | CS14: =CT14/CU14 -> #DIV/0! | CT14: 0 | CU14: 0 | CV14: =CW14/CX14 -> #DIV/0! | CW14: 0 | CX14: 0 | CY14: =CZ14/DA14 -> #DIV/0! | CZ14: 0 | DA14: 0 | DB14: =DC14/DD14 -> #DIV/0! | DC14: 0 | DD14: 0 | DE14: =DF14/DG14 -> #DIV/0! | DF14: 0 | DG14: 0 | DH14: =DI14/DJ14 -> #DIV/0! | DI14: 0 | DJ14: 0 | DK14: =DL14/DM14 -> #DIV/0! | DL14: 0 | DM14: 0 | DN14: =DO14/DP14 -> #DIV/0! | DO14: 0 | DP14: 0 | DQ14: =DR14/DS14 -> #DIV/0! | DR14: 0 | DS14: 0 | DT14: =DU14/DV14 -> #DIV/0! | DU14: 0 | DV14: 0 | DW14: =DX14/DY14 -> #DIV/0! | DX14: 0 | DY14: 0 | DZ14: =EA14/EB14 -> #DIV/0! | EA14: 0 | EB14: 0 | EC14: =ED14/EE14 -> #DIV/0! | ED14: 0 | EE14: 0 | EF14: =EG14/EH14 -> #DIV/0! | EG14: 0 | EH14: 0 | EI14: =EJ14/EK14 -> #DIV/0! | EJ14: 0 | EK14: 0 | EL14: =EM14/EN14 -> #DIV/0! | EM14: 0 | EN14: 0 | EO14: =EP14/EQ14 -> #DIV/0! | EP14: 0 | EQ14: 0 | ER14: =ES14/ET14 -> #DIV/0! | ES14: 0 | ET14: 0 | EU14: =EV14/EW14 -> #DIV/0! | EV14: 0 | EW14: 0 | EX14: =EY14/EZ14 -> #DIV/0! | EY14: 0 | EZ14: 0 | FA14: =FB14/FC14 -> #DIV/0! | FB14: 0 | FC14: 0 | FD14: =FE14/FF14 -> #DIV/0! | FE14: 0 | FF14: 0 | FG14: =FH14/FI14 -> #DIV/0! | FH14: 0 | FI14: 0
B15: Grade 1 Other 1 | C15: ='District Information & Measures'!C27 -> 0 | D15: =E15/F15 -> #DIV/0! | E15: =SUM(H15,K15,N15,Q15,T15,W15,Z15,AC15,AF15,AI15,AL15,AO15,AR15,AU15,AX15,BA15,BD15,BG15,BJ15,BM15,BP15,BS15,BV15,BY15,CB15,CE15,CH15,CK15,CN15,CQ15,CT15,CW15,CZ15,DC15,DF15,DI15,DL15,DO15,DR15,DU15,DX15,EA15,ED15,EG15,EJ15,EM15,EP15,ES15,EV15,EY15,FB15,FE15,FH15) -> 0 | F15: =SUM(I15,L15,O15,R15,U15,X15,AA15,AD15,AG15,AJ15,AM15,AP15,AS15,AV15,AY15,BB15,BE15,BH15,BK15,BN15,BQ15,BT15,BW15,BZ15,CC15,CF15,CI15,CL15,CO15,CR15,CU15,CX15,DA15,DD15,DG15,DJ15,DM15,DP15,DS15,DV15,DY15,EB15,EE15,EH15,EK15,EN15,EQ15,ET15,EW15,EZ15,FC15,FF15,FI15) -> 0 | G15: =H15/I15 -> #DIV/0! | H15: 0 | I15: 0 | J15: =K15/L15 -> #DIV/0! | K15: 0 | L15: 0 | M15: =N15/O15 -> #DIV/0! | N15: 0 | O15: 0 | P15: =Q15/R15 -> #DIV/0! | Q15: 0 | R15: 0 | S15: =T15/U15 -> #DIV/0! | T15: 0 | U15: 0 | V15: =W15/X15 -> #DIV/0! | W15: 0 | X15: 0 | Y15: =Z15/AA15 -> #DIV/0! | Z15: 0 | AA15: 0 | AB15: =AC15/AD15 -> #DIV/0! | AC15: 0 | AD15: 0 | AE15: =AF15/AG15 -> #DIV/0! | AF15: 0 | AG15: 0 | AH15: =AI15/AJ15 -> #DIV/0! | AI15: 0 | AJ15: 0 | AK15: =AL15/AM15 -> #DIV/0! | AL15: 0 | AM15: 0 | AN15: =AO15/AP15 -> #DIV/0! | AO15: 0 | AP15: 0 | AQ15: =AR15/AS15 -> #DIV/0! | AR15: 0 | AS15: 0 | AT15: =AU15/AV15 -> #DIV/0! | AU15: 0 | AV15: 0 | AW15: =AX15/AY15 -> #DIV/0! | AX15: 0 | AY15: 0 | AZ15: =BA15/BB15 -> #DIV/0! | BA15: 0 | BB15: 0 | BC15: =BD15/BE15 -> #DIV/0! | BD15: 0 | BE15: 0 | BF15: =BG15/BH15 -> #DIV/0! | BG15: 0 | BH15: 0 | BI15: =BJ15/BK15 -> #DIV/0! | BJ15: 0 | BK15: 0 | BL15: =BM15/BN15 -> #DIV/0! | BM15: 0 | BN15: 0 | BO15: =BP15/BQ15 -> #DIV/0! | BP15: 0 | BQ15: 0 | BR15: =BS15/BT15 -> #DIV/0! | BS15: 0 | BT15: 0 | BU15: =BV15/BW15 -> #DIV/0! | BV15: 0 | BW15: 0 | BX15: =BY15/BZ15 -> #DIV/0! | BY15: 0 | BZ15: 0 | CA15: =CB15/CC15 -> #DIV/0! | CB15: 0 | CC15: 0 | CD15: =CE15/CF15 -> #DIV/0! | CE15: 0 | CF15: 0 | CG15: =CH15/CI15 -> #DIV/0! | CH15: 0 | CI15: 0 | CJ15: =CK15/CL15 -> #DIV/0! | CK15: 0 | CL15: 0 | CM15: =CN15/CO15 -> #DIV/0! | CN15: 0 | CO15: 0 | CP15: =CQ15/CR15 -> #DIV/0! | CQ15: 0 | CR15: 0 | CS15: =CT15/CU15 -> #DIV/0! | CT15: 0 | CU15: 0 | CV15: =CW15/CX15 -> #DIV/0! | CW15: 0 | CX15: 0 | CY15: =CZ15/DA15 -> #DIV/0! | CZ15: 0 | DA15: 0 | DB15: =DC15/DD15 -> #DIV/0! | DC15: 0 | DD15: 0 | DE15: =DF15/DG15 -> #DIV/0! | DF15: 0 | DG15: 0 | DH15: =DI15/DJ15 -> #DIV/0! | DI15: 0 | DJ15: 0 | DK15: =DL15/DM15 -> #DIV/0! | DL15: 0 | DM15: 0 | DN15: =DO15/DP15 -> #DIV/0! | DO15: 0 | DP15: 0 | DQ15: =DR15/DS15 -> #DIV/0! | DR15: 0 | DS15: 0 | DT15: =DU15/DV15 -> #DIV/0! | DU15: 0 | DV15: 0 | DW15: =DX15/DY15 -> #DIV/0! | DX15: 0 | DY15: 0 | DZ15: =EA15/EB15 -> #DIV/0! | EA15: 0 | EB15: 0 | EC15: =ED15/EE15 -> #DIV/0! | ED15: 0 | EE15: 0 | EF15: =EG15/EH15 -> #DIV/0! | EG15: 0 | EH15: 0 | EI15: =EJ15/EK15 -> #DIV/0! | EJ15: 0 | EK15: 0 | EL15: =EM15/EN15 -> #DIV/0! | EM15: 0 | EN15: 0 | EO15: =EP15/EQ15 -> #DIV/0! | EP15: 0 | EQ15: 0 | ER15: =ES15/ET15 -> #DIV/0! | ES15: 0 | ET15: 0 | EU15: =EV15/EW15 -> #DIV/0! | EV15: 0 | EW15: 0 | EX15: =EY15/EZ15 -> #DIV/0! | EY15: 0 | EZ15: 0 | FA15: =FB15/FC15 -> #DIV/0! | FB15: 0 | FC15: 0 | FD15: =FE15/FF15 -> #DIV/0! | FE15: 0 | FF15: 0 | FG15: =FH15/FI15 -> #DIV/0! | FH15: 0 | FI15: 0
B16: Grade 1 Other 2 | C16: ='District Information & Measures'!C28 -> 0 | D16: =E16/F16 -> #DIV/0! | E16: =SUM(H16,K16,N16,Q16,T16,W16,Z16,AC16,AF16,AI16,AL16,AO16,AR16,AU16,AX16,BA16,BD16,BG16,BJ16,BM16,BP16,BS16,BV16,BY16,CB16,CE16,CH16,CK16,CN16,CQ16,CT16,CW16,CZ16,DC16,DF16,DI16,DL16,DO16,DR16,DU16,DX16,EA16,ED16,EG16,EJ16,EM16,EP16,ES16,EV16,EY16,FB16,FE16,FH16) -> 0 | F16: =SUM(I16,L16,O16,R16,U16,X16,AA16,AD16,AG16,AJ16,AM16,AP16,AS16,AV16,AY16,BB16,BE16,BH16,BK16,BN16,BQ16,BT16,BW16,BZ16,CC16,CF16,CI16,CL16,CO16,CR16,CU16,CX16,DA16,DD16,DG16,DJ16,DM16,DP16,DS16,DV16,DY16,EB16,EE16,EH16,EK16,EN16,EQ16,ET16,EW16,EZ16,FC16,FF16,FI16) -> 0 | G16: =H16/I16 -> #DIV/0! | H16: 0 | I16: 0 | J16: =K16/L16 -> #DIV/0! | K16: 0 | L16: 0 | M16: =N16/O16 -> #DIV/0! | N16: 0 | O16: 0 | P16: =Q16/R16 -> #DIV/0! | Q16: 0 | R16: 0 | S16: =T16/U16 -> #DIV/0! | T16: 0 | U16: 0 | V16: =W16/X16 -> #DIV/0! | W16: 0 | X16: 0 | Y16: =Z16/AA16 -> #DIV/0! | Z16: 0 | AA16: 0 | AB16: =AC16/AD16 -> #DIV/0! | AC16: 0 | AD16: 0 | AE16: =AF16/AG16 -> #DIV/0! | AF16: 0 | AG16: 0 | AH16: =AI16/AJ16 -> #DIV/0! | AI16: 0 | AJ16: 0 | AK16: =AL16/AM16 -> #DIV/0! | AL16: 0 | AM16: 0 | AN16: =AO16/AP16 -> #DIV/0! | AO16: 0 | AP16: 0 | AQ16: =AR16/AS16 -> #DIV/0! | AR16: 0 | AS16: 0 | AT16: =AU16/AV16 -> #DIV/0! | AU16: 0 | AV16: 0 | AW16: =AX16/AY16 -> #DIV/0! | AX16: 0 | AY16: 0 | AZ16: =BA16/BB16 -> #DIV/0! | BA16: 0 | BB16: 0 | BC16: =BD16/BE16 -> #DIV/0! | BD16: 0 | BE16: 0 | BF16: =BG16/BH16 -> #DIV/0! | BG16: 0 | BH16: 0 | BI16: =BJ16/BK16 -> #DIV/0! | BJ16: 0 | BK16: 0 | BL16: =BM16/BN16 -> #DIV/0! | BM16: 0 | BN16: 0 | BO16: =BP16/BQ16 -> #DIV/0! | BP16: 0 | BQ16: 0 | BR16: =BS16/BT16 -> #DIV/0! | BS16: 0 | BT16: 0 | BU16: =BV16/BW16 -> #DIV/0! | BV16: 0 | BW16: 0 | BX16: =BY16/BZ16 -> #DIV/0! | BY16: 0 | BZ16: 0 | CA16: =CB16/CC16 -> #DIV/0! | CB16: 0 | CC16: 0 | CD16: =CE16/CF16 -> #DIV/0! | CE16: 0 | CF16: 0 | CG16: =CH16/CI16 -> #DIV/0! | CH16: 0 | CI16: 0 | CJ16: =CK16/CL16 -> #DIV/0! | CK16: 0 | CL16: 0 | CM16: =CN16/CO16 -> #DIV/0! | CN16: 0 | CO16: 0 | CP16: =CQ16/CR16 -> #DIV/0! | CQ16: 0 | CR16: 0 | CS16: =CT16/CU16 -> #DIV/0! | CT16: 0 | CU16: 0 | CV16: =CW16/CX16 -> #DIV/0! | CW16: 0 | CX16: 0 | CY16: =CZ16/DA16 -> #DIV/0! | CZ16: 0 | DA16: 0 | DB16: =DC16/DD16 -> #DIV/0! | DC16: 0 | DD16: 0 | DE16: =DF16/DG16 -> #DIV/0! | DF16: 0 | DG16: 0 | DH16: =DI16/DJ16 -> #DIV/0! | DI16: 0 | DJ16: 0 | DK16: =DL16/DM16 -> #DIV/0! | DL16: 0 | DM16: 0 | DN16: =DO16/DP16 -> #DIV/0! | DO16: 0 | DP16: 0 | DQ16: =DR16/DS16 -> #DIV/0! | DR16: 0 | DS16: 0 | DT16: =DU16/DV16 -> #DIV/0! | DU16: 0 | DV16: 0 | DW16: =DX16/DY16 -> #DIV/0! | DX16: 0 | DY16: 0 | DZ16: =EA16/EB16 -> #DIV/0! | EA16: 0 | EB16: 0 | EC16: =ED16/EE16 -> #DIV/0! | ED16: 0 | EE16: 0 | EF16: =EG16/EH16 -> #DIV/0! | EG16: 0 | EH16: 0 | EI16: =EJ16/EK16 -> #DIV/0! | EJ16: 0 | EK16: 0 | EL16: =EM16/EN16 -> #DIV/0! | EM16: 0 | EN16: 0 | EO16: =EP16/EQ16 -> #DIV/0! | EP16: 0 | EQ16: 0 | ER16: =ES16/ET16 -> #DIV/0! | ES16: 0 | ET16: 0 | EU16: =EV16/EW16 -> #DIV/0! | EV16: 0 | EW16: 0 | EX16: =EY16/EZ16 -> #DIV/0! | EY16: 0 | EZ16: 0 | FA16: =FB16/FC16 -> #DIV/0! | FB16: 0 | FC16: 0 | FD16: =FE16/FF16 -> #DIV/0! | FE16: 0 | FF16: 0 | FG16: =FH16/FI16 -> #DIV/0! | FH16: 0 | FI16: 0
A18: Grade 2 | B18: High Frequency Words | C18: ='District Information & Measures'!C29 -> 0 | D18: =E18/F18 -> #DIV/0! | E18: =SUM(H18,K18,N18,Q18,T18,W18,Z18,AC18,AF18,AI18,AL18,AO18,AR18,AU18,AX18,BA18,BD18,BG18,BJ18,BM18,BP18,BS18,BV18,BY18,CB18,CE18,CH18,CK18,CN18,CQ18,CT18,CW18,CZ18,DC18,DF18,DI18,DL18,DO18,DR18,DU18,DX18,EA18,ED18,EG18,EJ18,EM18,EP18,ES18,EV18,EY18,FB18,FE18,FH18) -> 0 | F18: =SUM(I18,L18,O18,R18,U18,X18,AA18,AD18,AG18,AJ18,AM18,AP18,AS18,AV18,AY18,BB18,BE18,BH18,BK18,BN18,BQ18,BT18,BW18,BZ18,CC18,CF18,CI18,CL18,CO18,CR18,CU18,CX18,DA18,DD18,DG18,DJ18,DM18,DP18,DS18,DV18,DY18,EB18,EE18,EH18,EK18,EN18,EQ18,ET18,EW18,EZ18,FC18,FF18,FI18) -> 0 | G18: =H18/I18 -> #DIV/0! | H18: 0 | I18: 0 | J18: =K18/L18 -> #DIV/0! | K18: 0 | L18: 0 | M18: =N18/O18 -> #DIV/0! | N18: 0 | O18: 0 | P18: =Q18/R18 -> #DIV/0! | Q18: 0 | R18: 0 | S18: =T18/U18 -> #DIV/0! | T18: 0 | U18: 0 | V18: =W18/X18 -> #DIV/0! | W18: 0 | X18: 0 | Y18: =Z18/AA18 -> #DIV/0! | Z18: 0 | AA18: 0 | AB18: =AC18/AD18 -> #DIV/0! | AC18: 0 | AD18: 0 | AE18: =AF18/AG18 -> #DIV/0! | AF18: 0 | AG18: 0 | AH18: =AI18/AJ18 -> #DIV/0! | AI18: 0 | AJ18: 0 | AK18: =AL18/AM18 -> #DIV/0! | AL18: 0 | AM18: 0 | AN18: =AO18/AP18 -> #DIV/0! | AO18: 0 | AP18: 0 | AQ18: =AR18/AS18 -> #DIV/0! | AR18: 0 | AS18: 0 | AT18: =AU18/AV18 -> #DIV/0! | AU18: 0 | AV18: 0 | AW18: =AX18/AY18 -> #DIV/0! | AX18: 0 | AY18: 0 | AZ18: =BA18/BB18 -> #DIV/0! | BA18: 0 | BB18: 0 | BC18: =BD18/BE18 -> #DIV/0! | BD18: 0 | BE18: 0 | BF18: =BG18/BH18 -> #DIV/0! | BG18: 0 | BH18: 0 | BI18: =BJ18/BK18 -> #DIV/0! | BJ18: 0 | BK18: 0 | BL18: =BM18/BN18 -> #DIV/0! | BM18: 0 | BN18: 0 | BO18: =BP18/BQ18 -> #DIV/0! | BP18: 0 | BQ18: 0 | BR18: =BS18/BT18 -> #DIV/0! | BS18: 0 | BT18: 0 | BU18: =BV18/BW18 -> #DIV/0! | BV18: 0 | BW18: 0 | BX18: =BY18/BZ18 -> #DIV/0! | BY18: 0 | BZ18: 0 | CA18: =CB18/CC18 -> #DIV/0! | CB18: 0 | CC18: 0 | CD18: =CE18/CF18 -> #DIV/0! | CE18: 0 | CF18: 0 | CG18: =CH18/CI18 -> #DIV/0! | CH18: 0 | CI18: 0 | CJ18: =CK18/CL18 -> #DIV/0! | CK18: 0 | CL18: 0 | CM18: =CN18/CO18 -> #DIV/0! | CN18: 0 | CO18: 0 | CP18: =CQ18/CR18 -> #DIV/0! | CQ18: 0 | CR18: 0 | CS18: =CT18/CU18 -> #DIV/0! | CT18: 0 | CU18: 0 | CV18: =CW18/CX18 -> #DIV/0! | CW18: 0 | CX18: 0 | CY18: =CZ18/DA18 -> #DIV/0! | CZ18: 0 | DA18: 0 | DB18: =DC18/DD18 -> #DIV/0! | DC18: 0 | DD18: 0 | DE18: =DF18/DG18 -> #DIV/0! | DF18: 0 | DG18: 0 | DH18: =DI18/DJ18 -> #DIV/0! | DI18: 0 | DJ18: 0 | DK18: =DL18/DM18 -> #DIV/0! | DL18: 0 | DM18: 0 | DN18: =DO18/DP18 -> #DIV/0! | DO18: 0 | DP18: 0 | DQ18: =DR18/DS18 -> #DIV/0! | DR18: 0 | DS18: 0 | DT18: =DU18/DV18 -> #DIV/0! | DU18: 0 | DV18: 0 | DW18: =DX18/DY18 -> #DIV/0! | DX18: 0 | DY18: 0 | DZ18: =EA18/EB18 -> #DIV/0! | EA18: 0 | EB18: 0 | EC18: =ED18/EE18 -> #DIV/0! | ED18: 0 | EE18: 0 | EF18: =EG18/EH18 -> #DIV/0! | EG18: 0 | EH18: 0 | EI18: =EJ18/EK18 -> #DIV/0! | EJ18: 0 | EK18: 0 | EL18: =EM18/EN18 -> #DIV/0! | EM18: 0 | EN18: 0 | EO18: =EP18/EQ18 -> #DIV/0! | EP18: 0 | EQ18: 0 | ER18: =ES18/ET18 -> #DIV/0! | ES18: 0 | ET18: 0 | EU18: =EV18/EW18 -> #DIV/0! | EV18: 0 | EW18: 0 | EX18: =EY18/EZ18 -> #DIV/0! | EY18: 0 | EZ18: 0 | FA18: =FB18/FC18 -> #DIV/0! | FB18: 0 | FC18: 0 | FD18: =FE18/FF18 -> #DIV/0! | FE18: 0 | FF18: 0 | FG18: =FH18/FI18 -> #DIV/0! | FH18: 0 | FI18: 0
B19: Oral Language | C19: ='District Information & Measures'!C30 -> 0 | D19: =E19/F19 -> #DIV/0! | E19: =SUM(H19,K19,N19,Q19,T19,W19,Z19,AC19,AF19,AI19,AL19,AO19,AR19,AU19,AX19,BA19,BD19,BG19,BJ19,BM19,BP19,BS19,BV19,BY19,CB19,CE19,CH19,CK19,CN19,CQ19,CT19,CW19,CZ19,DC19,DF19,DI19,DL19,DO19,DR19,DU19,DX19,EA19,ED19,EG19,EJ19,EM19,EP19,ES19,EV19,EY19,FB19,FE19,FH19) -> 0 | F19: =SUM(I19,L19,O19,R19,U19,X19,AA19,AD19,AG19,AJ19,AM19,AP19,AS19,AV19,AY19,BB19,BE19,BH19,BK19,BN19,BQ19,BT19,BW19,BZ19,CC19,CF19,CI19,CL19,CO19,CR19,CU19,CX19,DA19,DD19,DG19,DJ19,DM19,DP19,DS19,DV19,DY19,EB19,EE19,EH19,EK19,EN19,EQ19,ET19,EW19,EZ19,FC19,FF19,FI19) -> 0 | G19: =H19/I19 -> #DIV/0! | H19: 0 | I19: 0 | J19: =K19/L19 -> #DIV/0! | K19: 0 | L19: 0 | M19: =N19/O19 -> #DIV/0! | N19: 0 | O19: 0 | P19: =Q19/R19 -> #DIV/0! | Q19: 0 | R19: 0 | S19: =T19/U19 -> #DIV/0! | T19: 0 | U19: 0 | V19: =W19/X19 -> #DIV/0! | W19: 0 | X19: 0 | Y19: =Z19/AA19 -> #DIV/0! | Z19: 0 | AA19: 0 | AB19: =AC19/AD19 -> #DIV/0! | AC19: 0 | AD19: 0 | AE19: =AF19/AG19 -> #DIV/0! | AF19: 0 | AG19: 0 | AH19: =AI19/AJ19 -> #DIV/0! | AI19: 0 | AJ19: 0 | AK19: =AL19/AM19 -> #DIV/0! | AL19: 0 | AM19: 0 | AN19: =AO19/AP19 -> #DIV/0! | AO19: 0 | AP19: 0 | AQ19: =AR19/AS19 -> #DIV/0! | AR19: 0 | AS19: 0 | AT19: =AU19/AV19 -> #DIV/0! | AU19: 0 | AV19: 0 | AW19: =AX19/AY19 -> #DIV/0! | AX19: 0 | AY19: 0 | AZ19: =BA19/BB19 -> #DIV/0! | BA19: 0 | BB19: 0 | BC19: =BD19/BE19 -> #DIV/0! | BD19: 0 | BE19: 0 | BF19: =BG19/BH19 -> #DIV/0! | BG19: 0 | BH19: 0 | BI19: =BJ19/BK19 -> #DIV/0! | BJ19: 0 | BK19: 0 | BL19: =BM19/BN19 -> #DIV/0! | BM19: 0 | BN19: 0 | BO19: =BP19/BQ19 -> #DIV/0! | BP19: 0 | BQ19: 0 | BR19: =BS19/BT19 -> #DIV/0! | BS19: 0 | BT19: 0 | BU19: =BV19/BW19 -> #DIV/0! | BV19: 0 | BW19: 0 | BX19: =BY19/BZ19 -> #DIV/0! | BY19: 0 | BZ19: 0 | CA19: =CB19/CC19 -> #DIV/0! | CB19: 0 | CC19: 0 | CD19: =CE19/CF19 -> #DIV/0! | CE19: 0 | CF19: 0 | CG19: =CH19/CI19 -> #DIV/0! | CH19: 0 | CI19: 0 | CJ19: =CK19/CL19 -> #DIV/0! | CK19: 0 | CL19: 0 | CM19: =CN19/CO19 -> #DIV/0! | CN19: 0 | CO19: 0 | CP19: =CQ19/CR19 -> #DIV/0! | CQ19: 0 | CR19: 0 | CS19: =CT19/CU19 -> #DIV/0! | CT19: 0 | CU19: 0 | CV19: =CW19/CX19 -> #DIV/0! | CW19: 0 | CX19: 0 | CY19: =CZ19/DA19 -> #DIV/0! | CZ19: 0 | DA19: 0 | DB19: =DC19/DD19 -> #DIV/0! | DC19: 0 | DD19: 0 | DE19: =DF19/DG19 -> #DIV/0! | DF19: 0 | DG19: 0 | DH19: =DI19/DJ19 -> #DIV/0! | DI19: 0 | DJ19: 0 | DK19: =DL19/DM19 -> #DIV/0! | DL19: 0 | DM19: 0 | DN19: =DO19/DP19 -> #DIV/0! | DO19: 0 | DP19: 0 | DQ19: =DR19/DS19 -> #DIV/0! | DR19: 0 | DS19: 0 | DT19: =DU19/DV19 -> #DIV/0! | DU19: 0 | DV19: 0 | DW19: =DX19/DY19 -> #DIV/0! | DX19: 0 | DY19: 0 | DZ19: =EA19/EB19 -> #DIV/0! | EA19: 0 | EB19: 0 | EC19: =ED19/EE19 -> #DIV/0! | ED19: 0 | EE19: 0 | EF19: =EG19/EH19 -> #DIV/0! | EG19: 0 | EH19: 0 | EI19: =EJ19/EK19 -> #DIV/0! | EJ19: 0 | EK19: 0 | EL19: =EM19/EN19 -> #DIV/0! | EM19: 0 | EN19: 0 | EO19: =EP19/EQ19 -> #DIV/0! | EP19: 0 | EQ19: 0 | ER19: =ES19/ET19 -> #DIV/0! | ES19: 0 | ET19: 0 | EU19: =EV19/EW19 -> #DIV/0! | EV19: 0 | EW19: 0 | EX19: =EY19/EZ19 -> #DIV/0! | EY19: 0 | EZ19: 0 | FA19: =FB19/FC19 -> #DIV/0! | FB19: 0 | FC19: 0 | FD19: =FE19/FF19 -> #DIV/0! | FE19: 0 | FF19: 0 | FG19: =FH19/FI19 -> #DIV/0! | FH19: 0 | FI19: 0
B20: Oral Fluency | C20: ='District Information & Measures'!C31 -> 0 | D20: =E20/F20 -> #DIV/0! | E20: =SUM(H20,K20,N20,Q20,T20,W20,Z20,AC20,AF20,AI20,AL20,AO20,AR20,AU20,AX20,BA20,BD20,BG20,BJ20,BM20,BP20,BS20,BV20,BY20,CB20,CE20,CH20,CK20,CN20,CQ20,CT20,CW20,CZ20,DC20,DF20,DI20,DL20,DO20,DR20,DU20,DX20,EA20,ED20,EG20,EJ20,EM20,EP20,ES20,EV20,EY20,FB20,FE20,FH20) -> 0 | F20: =SUM(I20,L20,O20,R20,U20,X20,AA20,AD20,AG20,AJ20,AM20,AP20,AS20,AV20,AY20,BB20,BE20,BH20,BK20,BN20,BQ20,BT20,BW20,BZ20,CC20,CF20,CI20,CL20,CO20,CR20,CU20,CX20,DA20,DD20,DG20,DJ20,DM20,DP20,DS20,DV20,DY20,EB20,EE20,EH20,EK20,EN20,EQ20,ET20,EW20,EZ20,FC20,FF20,FI20) -> 0 | G20: =H20/I20 -> #DIV/0! | H20: 0 | I20: 0 | J20: =K20/L20 -> #DIV/0! | K20: 0 | L20: 0 | M20: =N20/O20 -> #DIV/0! | N20: 0 | O20: 0 | P20: =Q20/R20 -> #DIV/0! | Q20: 0 | R20: 0 | S20: =T20/U20 -> #DIV/0! | T20: 0 | U20: 0 | V20: =W20/X20 -> #DIV/0! | W20: 0 | X20: 0 | Y20: =Z20/AA20 -> #DIV/0! | Z20: 0 | AA20: 0 | AB20: =AC20/AD20 -> #DIV/0! | AC20: 0 | AD20: 0 | AE20: =AF20/AG20 -> #DIV/0! | AF20: 0 | AG20: 0 | AH20: =AI20/AJ20 -> #DIV/0! | AI20: 0 | AJ20: 0 | AK20: =AL20/AM20 -> #DIV/0! | AL20: 0 | AM20: 0 | AN20: =AO20/AP20 -> #DIV/0! | AO20: 0 | AP20: 0 | AQ20: =AR20/AS20 -> #DIV/0! | AR20: 0 | AS20: 0 | AT20: =AU20/AV20 -> #DIV/0! | AU20: 0 | AV20: 0 | AW20: =AX20/AY20 -> #DIV/0! | AX20: 0 | AY20: 0 | AZ20: =BA20/BB20 -> #DIV/0! | BA20: 0 | BB20: 0 | BC20: =BD20/BE20 -> #DIV/0! | BD20: 0 | BE20: 0 | BF20: =BG20/BH20 -> #DIV/0! | BG20: 0 | BH20: 0 | BI20: =BJ20/BK20 -> #DIV/0! | BJ20: 0 | BK20: 0 | BL20: =BM20/BN20 -> #DIV/0! | BM20: 0 | BN20: 0 | BO20: =BP20/BQ20 -> #DIV/0! | BP20: 0 | BQ20: 0 | BR20: =BS20/BT20 -> #DIV/0! | BS20: 0 | BT20: 0 | BU20: =BV20/BW20 -> #DIV/0! | BV20: 0 | BW20: 0 | BX20: =BY20/BZ20 -> #DIV/0! | BY20: 0 | BZ20: 0 | CA20: =CB20/CC20 -> #DIV/0! | CB20: 0 | CC20: 0 | CD20: =CE20/CF20 -> #DIV/0! | CE20: 0 | CF20: 0 | CG20: =CH20/CI20 -> #DIV/0! | CH20: 0 | CI20: 0 | CJ20: =CK20/CL20 -> #DIV/0! | CK20: 0 | CL20: 0 | CM20: =CN20/CO20 -> #DIV/0! | CN20: 0 | CO20: 0 | CP20: =CQ20/CR20 -> #DIV/0! | CQ20: 0 | CR20: 0 | CS20: =CT20/CU20 -> #DIV/0! | CT20: 0 | CU20: 0 | CV20: =CW20/CX20 -> #DIV/0! | CW20: 0 | CX20: 0 | CY20: =CZ20/DA20 -> #DIV/0! | CZ20: 0 | DA20: 0 | DB20: =DC20/DD20 -> #DIV/0! | DC20: 0 | DD20: 0 | DE20: =DF20/DG20 -> #DIV/0! | DF20: 0 | DG20: 0 | DH20: =DI20/DJ20 -> #DIV/0! | DI20: 0 | DJ20: 0 | DK20: =DL20/DM20 -> #DIV/0! | DL20: 0 | DM20: 0 | DN20: =DO20/DP20 -> #DIV/0! | DO20: 0 | DP20: 0 | DQ20: =DR20/DS20 -> #DIV/0! | DR20: 0 | DS20: 0 | DT20: =DU20/DV20 -> #DIV/0! | DU20: 0 | DV20: 0 | DW20: =DX20/DY20 -> #DIV/0! | DX20: 0 | DY20: 0 | DZ20: =EA20/EB20 -> #DIV/0! | EA20: 0 | EB20: 0 | EC20: =ED20/EE20 -> #DIV/0! | ED20: 0 | EE20: 0 | EF20: =EG20/EH20 -> #DIV/0! | EG20: 0 | EH20: 0 | EI20: =EJ20/EK20 -> #DIV/0! | EJ20: 0 | EK20: 0 | EL20: =EM20/EN20 -> #DIV/0! | EM20: 0 | EN20: 0 | EO20: =EP20/EQ20 -> #DIV/0! | EP20: 0 | EQ20: 0 | ER20: =ES20/ET20 -> #DIV/0! | ES20: 0 | ET20: 0 | EU20: =EV20/EW20 -> #DIV/0! | EV20: 0 | EW20: 0 | EX20: =EY20/EZ20 -> #DIV/0! | EY20: 0 | EZ20: 0 | FA20: =FB20/FC20 -> #DIV/0! | FB20: 0 | FC20: 0 | FD20: =FE20/FF20 -> #DIV/0! | FE20: 0 | FF20: 0 | FG20: =FH20/FI20 -> #DIV/0! | FH20: 0 | FI20: 0
