Workbook
Name Aid: 'Aid Adjust'!$A$10:$H$341
Name Ideas: Credits!$A$8:$C$339
Name Ideas: Levy!$A$9:$C$342
Name Ideas: Ideas!$A$9:$H$341
Name Query_from_Databridge: Query1!$A$3:$F$125
Name Query_from_Databridge: Query4!$A$3:$F$48
Name Shift05: Receipts!$A$7:$K$338
Name ShiftCY: 'Shift 14'!$A$6:$O$337
Name ShiftPY: 'Shift 13'!$A$11:$O$342
Name TitleRegion1.a1.ba339.8: Data!$BA$339
Name TitleRegion1.a1.bd340.10: Levy!$BD$340
Name TitleRegion1.a1.g345.15: Names!$G$345
Name TitleRegion1.a1.n108.4: Accounts!$N$108
Name TitleRegion1.a1.o342.9: 'Shift 13'!$O$342
Name TitleRegion1.a2.ah339.11: Credits!$AH$339
Name TitleRegion1.a2.f130.14: Query1!$F$130
Name TitleRegion1.a2.f55.15: Query4!$A$1
Name TitleRegion1.a2.h341.6: 'Aid Adjust'!$H$341
Name TitleRegion1.a2.p340.13: Ideas!$A$2
Name TitleRegion1.a2.q338.12: Receipts!$Q$338
Name TitleRegion1.a2.q342.7: 'Shift 14'!$Q$342
Name TitleRegion1.a3.d72.5: Entries!$D$72
Name TitleRegion1.a3.i124.2: Report!$I$124
Name TitleRegion1.a4.s131.3: Funds!$S$131
Name TitleRegiona1.t70.1: Instructions!$T$70

Sheet Instructions
A1: PROPERTY TAX SHIFT | F1: n/a | G1: n/a | H1: n/a | I1: n/a | J1: n/a | K1: n/a | L1: n/a | M1: =Report!I1 -> 41828 | N1: coulumn left blank intentionally | O1: 2014 | P1: Pay 2014 | Q1: 13 Pay 14 | R1: FY 2015
A2: n/a | B2: n/a | C2: n/a | D2: n/a | E2: n/a | F2: n/a | G2: n/a | H2: n/a | I2: n/a | J2: n/a | K2: n/a | L2: n/a | M2: n/a | O2: rest of coulumn left blank intentionally | P2: Pay 2013 | Q2: 12 Pay 13 | R2: FY 2014 | S2: 06/30/14 | T2: 07/01/2013 to 06/30/2014
A3: n/a | B3: n/a | C3: n/a | D3: n/a | E3: n/a | F3: n/a | G3: n/a | H3: n/a | I3: n/a | J3: n/a | K3: n/a | L3: n/a | M3: n/a | P3: Pay 2012 | Q3: rest of column left blank intentionally | R3: FY 2013 | S3: 06/30/13 | T3: 07/01/2013 to 04/30/2014
A4: n/a | B4: n/a | C4: n/a | D4: n/a | E4: n/a | F4: n/a | G4: n/a | H4: n/a | I4: n/a | J4: n/a | K4: n/a | L4: n/a | M4: n/a | P4: Pay 2011 | R4: rest of column left blank intentionally | S4: rest of column left blank intentionally | T4: 05/01/2014 to 06/30/2014
A5: ="The property tax shift is an accounting entry that takes a portion of the school district's property tax revenue and moves it forward one fiscal year, i.e., taxes that would otherwise be revenue for fiscal year "&RIGHT(R1,4)&" are shifted into fiscal year "&RIGHT(R2,4)&". The property tax shift requirement is in Minnesota Statutes, section 123B.75, subdivision 5." -> The property tax shift is an accounting entry that takes a portion of the school district's property tax revenue and moves it forward one fiscal year, i.e., taxes that would otherwise be revenue for fiscal year 2015 are shifted into fiscal year 2014. The property tax shift requirement is in Minnesota Statutes, section 123B.75, subdivision 5. | P5: Pay 2010 | T5: rest of column left blank intentionally
A6: n/a | B6: n/a | C6: n/a | D6: n/a | E6: n/a | F6: n/a | G6: n/a | H6: n/a | I6: n/a | J6: n/a | K6: n/a | L6: n/a | M6: n/a | O6: n/a | P6: Pay 2009
A7: n/a | B7: n/a | C7: n/a | D7: n/a | E7: n/a | F7: n/a | G7: n/a | H7: n/a | I7: n/a | J7: n/a | K7: n/a | L7: n/a | M7: n/a | O7: n/a | P7: Pay 2008
A8: Notes: | C8: n/a | D8: n/a | E8: n/a | F8: n/a | G8: n/a | H8: n/a | I8: n/a | J8: n/a | K8: n/a | L8: n/a | M8: n/a | O8: n/a | P8: Pay 2007
A9: line left blank intentionally
A10: ="For the June 30, "&RIGHT(R2,4)&", tax shift this spreadsheet is using the payable "&RIGHT(P1,4)&" final certified levies plus/minus county auditor adjustments." -> For the June 30, 2014, tax shift this spreadsheet is using the payable 2014 final certified levies plus/minus county auditor adjustments.
A11: line left blank intentionally
A12: ="Preliminary payable "&RIGHT(P1,4)&" credits are used in this spreadsheet. The spreadsheet will be updated to use final payable "&RIGHT(P1,4)&" credits when that data is available." -> Preliminary payable 2014 credits are used in this spreadsheet. The spreadsheet will be updated to use final payable 2014 credits when that data is available.
A13: line left blank intentionally
A14: ="Tax receipts for May-July "&RIGHT(R2,4)&" for the general fund and community service fund have been estimated on the Receipts tab. Preliminary payable "&RIGHT(P1,4)&" credits from the Department of Revenue are used in computing estimated tax receipts. These estimates are carried over to cells E91 and F91 of the Report tab. Districts should override these estimates when actual tax receipts are determined." -> Tax receipts for May-July 2014 for the general fund and community service fund have been estimated on the Receipts tab. Preliminary payable 2014 credits from the Department of Revenue are used in computing estimated tax receipts. These estimates are carried over to cells E91 and F91 of the Report tab. Districts should override these estimates when actual tax receipts are determined.
A17: line left blank intentionally
A18: Early Recognition Levies | E18: n/a | F18: n/a | G18: n/a | H18: n/a | I18: n/a | J18: n/a | K18: n/a | L18: n/a | M18: n/a
A19: Certain levies have been--and will continue to be--shifted 100% with no aid reduction. Recognizing these levies early gets the revenue into the same fiscal year as the related expenditures. There is no state aid adjustment for this portion of the shift.
A20: line left blank intentionally
A21: Other Levies | D21: n/a | E21: n/a | F21: n/a | G21: n/a | H21: n/a | I21: n/a | J21: n/a | K21: n/a | L21: n/a | M21: n/a
A22: Starting in fiscal year 2004, the shift was expanded to include all other general and community service fund levies, net of tax credits. There is a corresponding state aid adjustment for this portion of the property tax shift, making this portion of the shift revenue neutral to school districts each year. If the shift at the end of the current year is larger than the shift at the end of the previous year, state aid for the current year is reduced for the net increase in the shift. If the shift at the end of the current year is less than the shift at the end of the previous year, state aid for the current year is increased for the net decrease in the shift.
A26: line left blank intentionally
A27: Starting in fiscal year 2006, the shift percentage for other levies was set to zero percent.
A28: Starting in fiscal year 2011, the shift percentage for other levies was set to 48.6 percent, and based on gross levies (before subtraction of credits).
A29: Starting in fiscal year 2014, the shift percentage for other levies was again set to zero percent.
A30: line left blank intentionally
A31: The "Reports" tab shows the property tax shift report for a selected school district. | I31: n/a | J31: n/a | K31: n/a | L31: n/a | M31: n/a
B32: To select a specific district, type the district number in cell A3 (use 1.2 for Minneapolis) and press enter. Information for the selected district will then appear in the report. Running a macro is not required.
A34: line left blank intentionally
A35: n/a | B35: The first section shows the property tax shift report for the school district, with a definition for each tax shift category. | K35: n/a | L35: n/a | M35: n/a
A36: n/a | B36: n/a | C36: ="Column 1 is the amount of payable "&RIGHT(P1,4)&" levy to be recognized in fiscal year "&RIGHT(R2,4)&"." -> Column 1 is the amount of payable 2014 levy to be recognized in fiscal year 2014. | I36: n/a | J36: n/a | K36: n/a | L36: n/a | M36: n/a
A37: n/a | B37: n/a | C37: ="Column 2 is the amount of payable "&RIGHT(P2,4)&" levy that was recognized in fiscal year "&RIGHT(R3,4)&"." -> Column 2 is the amount of payable 2013 levy that was recognized in fiscal year 2013. | I37: n/a | J37: n/a | K37: n/a | L37: n/a | M37: n/a
A38: n/a | B38: n/a | C38: Column 3 is the revenue change to be recognized as a result of the levies shifted with with no aid reduction (net of column 1 and column 2 for these categories).
A39: n/a | B39: n/a | C39: Column 4 is the net shift amount to be recognized as a result of levies shifted with an aid reduction. A negative amount in this column represents a debit balance in source 020 and related crebit balance in source 299.
A40: line left blank intentionally
A41: n/a | B41: n/a | C41: Column 5 is the state aid payment (reduction) that is being made in the current year for the property tax shift.
A42: n/a | B42: n/a | C42: Column 6 represents the state aid payment (reduction) that will be made next year, for this year's tax shift. Column 4 plus column 5 plus column 6 should equal zero.
A43: line left blank intentionally
A44: n/a | B44: The second section discusses the assumptions that have been made in generating the entries to record the tax shift. Also review the Accounts tab and Entries tab.
A45: line left blank intentionally
A46: n/a | B46: ="In the third section, estimated tax receipts for May, June and July "&RIGHT(R2,4)&" have been computed. See blue highlighted area. Override these estimates with actual tax settlement receipts for May, June and July "&RIGHT(R2,4)&" when this data is available. If the gross shift amount is greater than May, June and July tax receipts, the district will recognize fiscal year "&RIGHT(R1,4)&" general education aid early in an amount equal to the difference between tax receipts and the gross shift." -> In the third section, estimated tax receipts for May, June and July 2014 have been computed. See blue highlighted area. Override these estimates with actual tax settlement receipts for May, June and July 2014 when this data is available. If the gross shift amount is greater than May, June and July tax receipts, the district will recognize fiscal year 2015 general education aid early in an amount equal to the difference between tax receipts and the gross shift.
...

Sheet Report
D1: PROPERTY TAX SHIFT YEAR-END RECONCILIATION | I1: 41828
D2: =Instructions!S2 -> 06/30/14
A3: 1 | B3: Enter District Number
B5: =VLOOKUP(A3,ShiftCY,3) -> AITKIN
C6: 1 | D6: 2 | E6: 3 | F6: 4 | H6: 5 | I6: 6
C7: ="Gross Shift Amount "&Instructions!Q1 -> Gross Shift Amount 13 Pay 14 | D7: ="Replacement for "&Instructions!Q2&" Shift" -> Replacement for 12 Pay 13 Shift | E7: =Instructions!R2&" Revenue Adjust Src Code 001" -> FY 2014 Revenue Adjust Src Code 001 | F7: =Instructions!R2&" Net Shift Amount Src Code 020" -> FY 2014 Net Shift Amount Src Code 020 | H7: State Aid Adjustment Src Code 299 | I7: Revenue Adjustment Src Code 299
A9: A | B9: General - Shift & Adjust Aid | C9: =VLOOKUP($A$3,ShiftCY,4,FALSE) -> 0 | D9: =VLOOKUP($A$3,ShiftPY,4,FALSE) -> 348692.74 | F9: =C9-D9 -> -348692.74
A10: B | B10: General - Operating Referendum (with aid adjust) | C10: =VLOOKUP($A$3,ShiftCY,5,FALSE) -> 0 | D10: =VLOOKUP($A$3,ShiftPY,5,FALSE) -> 0 | F10: =C10-D10 -> 0
A11: C | B11: General - Operating Referendum (no aid adjust) | C11: =VLOOKUP($A$3,ShiftCY,6,FALSE) -> 141143.88 | D11: =VLOOKUP($A$3,ShiftPY,6,FALSE) -> 141143.88 | E11: =C11-D11 -> 0
A12: D | B12: General - Addl Referendum Shift | C12: =VLOOKUP($A$3,ShiftCY,7,FALSE) -> 0 | D12: =VLOOKUP($A$3,ShiftPY,7,FALSE) -> 0 | E12: =C12-D12 -> 0
A13: E | B13: General - Career Technical | C13: =VLOOKUP($A$3,ShiftCY,8,FALSE) -> 30163.77 | D13: =VLOOKUP($A$3,ShiftPY,8,FALSE) -> 25644.59 | E13: =C13-D13 -> 4519.18
A14: F | B14: General - 100% Shift, No Adjust | C14: =VLOOKUP($A$3,ShiftCY,9,FALSE) -> 0 | D14: =VLOOKUP($A$3,ShiftPY,9,FALSE) -> 0 | E14: =C14-D14 -> 0
A15: G | B15: General - Reemploy Ins (Reserved) | C15: =VLOOKUP($A$3,ShiftCY,10,FALSE) -> 0 | D15: =VLOOKUP($A$3,ShiftPY,10,FALSE) -> 0 | E15: =C15-D15 -> 0
A16: H | B16: General - Reemploy Ins (Unreserved) | C16: =VLOOKUP($A$3,ShiftCY,11,FALSE) -> 6695.76 | D16: =VLOOKUP($A$3,ShiftPY,11,FALSE) -> 8234.63 | E16: =C16-D16 -> -1538.87
A17: I | B17: General - Legislative Changes | C17: =VLOOKUP($A$3,ShiftCY,12,FALSE) -> 0 | D17: =VLOOKUP($A$3,ShiftPY,12,FALSE) -> 0 | E17: =C17-D17 -> 0
A18: J | B18: General Fund Total | C18: =SUM(C9:C17) -> 178003.41 | D18: =SUM(D9:D17) -> 523715.84 | E18: =SUM(E9:E17) -> 2980.31 | F18: =SUM(F9:F17) -> -348692.74 | H18: =VLOOKUP($A$3,Ideas,4) -> 354088.31 | I18: =-F18-H18 -> -5395.57
A20: K | B20: Comm Serv - Shift & Adjust Aid | C20: =VLOOKUP($A$3,ShiftCY,13,FALSE) -> 0 | D20: =VLOOKUP($A$3,ShiftPY,13,FALSE) -> 5395.57 | F20: =C20-D20 -> -5395.57
A21: L | B21: Comm Serv - 100% Shift, No Adjust | C21: 0 | D21: 0 | E21: =C21-D21 -> 0
A22: M | B22: Comm Serv - Legislative Change | C22: =VLOOKUP($A$3,ShiftCY,14,FALSE) -> 0 | D22: =VLOOKUP($A$3,ShiftPY,14,FALSE) -> 0 | E22: =C22-D22 -> 0
A23: N | B23: Comm Serv Fund Total | C23: =SUM(C20:C22) -> 0 | D23: =SUM(D20:D22) -> 5395.57 | E23: =SUM(E20:E22) -> 0 | F23: =SUM(F20:F22) -> -5395.57 | H23: =VLOOKUP($A$3,Ideas,5) -> 0 | I23: =-F23-H23 -> 5395.57
A26: O | B26: Total | C26: =C18+C23 -> 178003.41 | D26: =D18+D23 -> 529111.41 | E26: =E18+E23 -> 2980.31 | F26: =F18+F23 -> -354088.31 | H26: =H18+H23 -> 354088.31 | I26: =I18+I23 -> -7.2759576e-12
A28: Definitions of levy categories within funds
A29: The following categories are mutually exclusive, that is, each levy appears in one category only.
B30: Shift & Adjust Aid | C30: ="For "&Instructions!P1&" this category includes all levies not identified below, shifted at 0.0%." -> For Pay 2014 this category includes all levies not identified below, shifted at 0.0%.
C31: ="For "&Instructions!P2&" this category includes all levies not identified below, shifted at 48.6%." -> For Pay 2013 this category includes all levies not identified below, shifted at 48.6%.
B32: Operating referendum (with aid adjust) | C32: ="For "&Instructions!P1&" this category is the greater of zero, or the "&Instructions!P1&" referendum levy shifted at 0.0% minus" -> For Pay 2014 this category is the greater of zero, or the Pay 2014 referendum levy shifted at 0.0% minus
C33: ="the Pay 2001 referendum shifted at 31%." -> the Pay 2001 referendum shifted at 31%.
B34: Operating referendum (no aid adjust) | C34: This category is the Pay 2001 referendum levy shifted at 31%. This amount will be constant from year to year.
B35: Addl referendum shift | C35: This is an additional revenue shift for districts that had a decrease in Pay 1994 referendum levy
C36: due to the net of changes in the allocation of HACA and the increase in referendum equalization aid.
C37: This amount will be constant from year to year.
B38: Career Technical | C38: Career technical levy and adjustment shifted at 100% with no aid adjustment.
B39: 100% shift, no adjust | C39: Includes levies that are shifted at 100% and for which there is no reduction to state aid. This category
C40: includes integration for first class districts, additional retirement, health benefits, and related adjustments.
B41: Reemploy Ins (reserved) | C41: Includes reemployment insurance levy adjustments for FY 2003 shifted at 100% with no aid adjustment.
B42: Reemploy Ins (unreserved) | C42: Includes reemployment insurance levy and adjustments for FY 2004 and later shifted at 100% with no aid adjustment.
B43: Legislative changes | C43: Includes selected levies that have been adjusted based on legislation that changes a levy authority after the levy has
C44: been certified (See Minnesota Statutes, section 126C.48, subdivision 6). The revenue shift is at 100% and there is
C45: ="no adjustment to state aids. For "&Instructions!P2&" and "&Instructions!P1&" this category is zero." -> no adjustment to state aids. For Pay 2013 and Pay 2014 this category is zero.
A46: =$A$3 -> 1 | B46: =VLOOKUP($A$3,ShiftCY,3) -> AITKIN | I46: =Instructions!$M$1 -> 41828
...

Sheet Funds
A1: Enter certified levies for each year below | K1: =Report!I1 -> 41828 | L1: rest of line left blank
A2: This data is used to report certified levies on Accounts tab | L2: rest of line left blank
A3: Also used to allocate adjustments and abatements on Accounts tab | L3: rest of line left blank
A4: n/a | B4: n/a | C4: n/a | D4: Certified Levy | L4: rest of line left blank
A5: n/a | B5: n/a | C5: n/a | D5: =Instructions!P1 -> Pay 2014 | E5: =Instructions!P2 -> Pay 2013 | F5: =Instructions!P3 -> Pay 2012 | G5: =Instructions!P4 -> Pay 2011 | H5: =Instructions!P5 -> Pay 2010 | I5: =Instructions!P6 -> Pay 2009 | J5: =Instructions!P7 -> Pay 2008 | K5: =Instructions!P8 -> Pay 2007 | L5: rest of line left blank
A6: n/a | B6: General | C6: n/a | D6: 0 | E6: 0 | F6: 0 | G6: 0 | H6: 0 | I6: 0 | J6: 0 | K6: 0 | L6: rest of line left blank
A7: n/a | B7: Community Serv | D7: 0 | E7: 0 | F7: 0 | G7: 0 | H7: 0 | I7: 0 | J7: 0 | K7: 0 | L7: rest of line left blank
A8: n/a | B8: Debt Service | C8: n/a | D8: 0 | E8: 0 | F8: 0 | G8: 0 | H8: 0 | I8: 0 | J8: 0 | K8: 0 | L8: rest of line left blank
A9: n/a | B9: OPEB | C9: n/a | D9: 0 | E9: 0 | F9: 0 | G9: 0 | H9: 0 | I9: 0 | J9: 0 | K9: 0 | L9: rest of line left blank
A10: line left blank intentionally | L10: rest of line left blank
A11: n/a | B11: Total Certified Levy | D11: =SUM(D6:D10) -> 0 | E11: =SUM(E6:E10) -> 0 | F11: =SUM(F6:F10) -> 0 | G11: =SUM(G6:G10) -> 0 | H11: =SUM(H6:H10) -> 0 | I11: =SUM(I6:I10) -> 0 | J11: =SUM(J6:J10) -> 0 | K11: =SUM(K6:K10) -> 0 | L11: rest of line left blank
A12: ="Enter each tax settlement received July 1, "&RIGHT(Instructions!P2,4)&" through June 30, "&RIGHT(Instructions!P1,4) -> Enter each tax settlement received July 1, 2013 through June 30, 2014 | G12: rest of line left blank
A13: Enter data in green highlighted cells | F13: rest of line left blank
A14: If more columns are needed, insert between column M and S | F14: rest of line left blank
A15: Amounts will be allocated to funds based upon certified levies above | F15: rest of line left blank
A16: Settlements will be totaled by year and fund for carryover to Accounts tab | F16: rest of line left blank
A17: line left blank intentionally | F17: rest of line left blank
A18: If settlement sheet from the county already shows settlements by fund: | G18: rest of line left blank
A19: Unprotect this tab and enter settlement data directly into cells E56 through S145, orange outlined section below | H19: rest of line left blank
A20: Caution: You will be overriding the formulas in these cells | E20: rest of line left blank
A21: n/a | B21: n/a | C21: n/a | D21: n/a | E21: County | F21: County | G21: County | H21: County | I21: County | J21: County | K21: County | L21: County | M21: County | N21: County | O21: County | P21: County | Q21: County | R21: County | S21: County
A22: n/a | B22: n/a | C22: n/a | D22: Total | E22: Date | F22: Date | G22: Date | H22: Date | I22: Date | J22: Date | K22: Date | L22: Date | M22: Date | N22: Date | O22: Date | P22: Date | Q22: Date | R22: Date | S22: Date
A24: Taxes receivable | C24: =Instructions!P1 -> Pay 2014 | D24: =SUM(E24:S24) -> 0 | E24: 0 | F24: 0 | G24: 0 | H24: 0 | I24: 0 | J24: 0 | K24: 0 | L24: 0 | M24: 0 | N24: 0 | O24: 0 | P24: 0 | Q24: 0 | R24: 0 | S24: 0
A25: n/a | B25: n/a | C25: =Instructions!P2 -> Pay 2013 | D25: =SUM(E25:S25) -> 0 | E25: 0 | F25: 0 | G25: 0 | H25: 0 | I25: 0 | J25: 0 | K25: 0 | L25: 0 | M25: 0 | N25: 0 | O25: 0 | P25: 0 | Q25: 0 | R25: 0 | S25: 0
A26: n/a | B26: n/a | C26: =Instructions!P3 -> Pay 2012 | D26: =SUM(E26:S26) -> 0 | E26: 0 | F26: 0 | G26: 0 | H26: 0 | I26: 0 | J26: 0 | K26: 0 | L26: 0 | M26: 0 | N26: 0 | O26: 0 | P26: 0 | Q26: 0 | R26: 0 | S26: 0
A27: n/a | B27: n/a | C27: =Instructions!P4 -> Pay 2011 | D27: =SUM(E27:S27) -> 0 | E27: 0 | F27: 0 | G27: 0 | H27: 0 | I27: 0 | J27: 0 | K27: 0 | L27: 0 | M27: 0 | N27: 0 | O27: 0 | P27: 0 | Q27: 0 | R27: 0 | S27: 0
A28: n/a | B28: n/a | C28: =Instructions!P5 -> Pay 2010 | D28: =SUM(E28:S28) -> 0 | E28: 0 | F28: 0 | G28: 0 | H28: 0 | I28: 0 | J28: 0 | K28: 0 | L28: 0 | M28: 0 | N28: 0 | O28: 0 | P28: 0 | Q28: 0 | R28: 0 | S28: 0
A29: n/a | B29: n/a | C29: =Instructions!P6 -> Pay 2009 | D29: =SUM(E29:S29) -> 0 | E29: 0 | F29: 0 | G29: 0 | H29: 0 | I29: 0 | J29: 0 | K29: 0 | L29: 0 | M29: 0 | N29: 0 | O29: 0 | P29: 0 | Q29: 0 | R29: 0 | S29: 0
A30: n/a | B30: n/a | C30: =Instructions!P7 -> Pay 2008 | D30: =SUM(E30:S30) -> 0 | E30: 0 | F30: 0 | G30: 0 | H30: 0 | I30: 0 | J30: 0 | K30: 0 | L30: 0 | M30: 0 | N30: 0 | O30: 0 | P30: 0 | Q30: 0 | R30: 0 | S30: 0
A31: n/a | B31: n/a | C31: =Instructions!P8 -> Pay 2007 | D31: =SUM(E31:S31) -> 0 | E31: 0 | F31: 0 | G31: 0 | H31: 0 | I31: 0 | J31: 0 | K31: 0 | L31: 0 | M31: 0 | N31: 0 | O31: 0 | P31: 0 | Q31: 0 | R31: 0 | S31: 0
A32: Fiscal disparities | C32: =Instructions!P1 -> Pay 2014 | D32: =SUM(E32:S32) -> 0 | E32: 0 | F32: 0 | G32: 0 | H32: 0 | I32: 0 | J32: 0 | K32: 0 | L32: 0 | M32: 0 | N32: 0 | O32: 0 | P32: 0 | Q32: 0 | R32: 0 | S32: 0
A33: n/a | B33: n/a | C33: =Instructions!P2 -> Pay 2013 | D33: =SUM(E33:S33) -> 0 | E33: 0 | F33: 0 | G33: 0 | H33: 0 | I33: 0 | J33: 0 | K33: 0 | L33: 0 | M33: 0 | N33: 0 | O33: 0 | P33: 0 | Q33: 0 | R33: 0 | S33: 0
A34: Taconite homestead | C34: =Instructions!P1 -> Pay 2014 | D34: =SUM(E34:S34) -> 0 | E34: 0 | F34: 0 | G34: 0 | H34: 0 | I34: 0 | J34: 0 | K34: 0 | L34: 0 | M34: 0 | N34: 0 | O34: 0 | P34: 0 | Q34: 0 | R34: 0 | S34: 0
A35: n/a | B35: n/a | C35: =Instructions!P2 -> Pay 2013 | D35: =SUM(E35:S35) -> 0 | E35: 0 | F35: 0 | G35: 0 | H35: 0 | I35: 0 | J35: 0 | K35: 0 | L35: 0 | M35: 0 | N35: 0 | O35: 0 | P35: 0 | Q35: 0 | R35: 0 | S35: 0
A36: Miscellaneous taxes | E36: 0 | F36: 0 | G36: 0 | H36: 0 | I36: 0 | J36: 0 | K36: 0 | L36: 0 | M36: 0 | N36: 0 | O36: 0 | P36: 0 | Q36: 0 | R36: 0 | S36: 0
A37: line left blank intentionally
A38: n/a | B38: Total settlement | D38: =SUM(D24:D37) -> 0 | E38: =SUM(E24:E37) -> 0 | F38: =SUM(F24:F37) -> 0 | G38: =SUM(G24:G37) -> 0 | H38: =SUM(H24:H37) -> 0 | I38: =SUM(I24:I37) -> 0 | J38: =SUM(J24:J37) -> 0 | K38: =SUM(K24:K37) -> 0 | ... S38: =SUM(S24:S37) -> 0
A39: Current Taxes receivable
A40: n/a | B40: =Instructions!P1 -> Pay 2014 | C40: General | D40: =SUM(E40:S40) -> 0 | E40: =ROUND(IF($D$11=0,0,E$24/$D$11*$D6),2) -> 0 | F40: =ROUND(IF($D$11=0,0,F$24/$D$11*$D6),2) -> 0 | G40: =ROUND(IF($D$11=0,0,G$24/$D$11*$D6),2) -> 0 | H40: =ROUND(IF($D$11=0,0,H$24/$D$11*$D6),2) -> 0 | I40: =ROUND(IF($D$11=0,0,I$24/$D$11*$D6),2) -> 0 | J40: =ROUND(IF($D$11=0,0,J$24/$D$11*$D6),2) -> 0 | K40: =ROUND(IF($D$11=0,0,K$24/$D$11*$D6),2) -> 0 | L40: =ROUND(IF($D$11=0,0,L$24/$D$11*$D6),2) -> 0 | ... S40: =ROUND(IF($D$11=0,0,S$24/$D$11*$D6),2) -> 0
A41: n/a | B41: =Instructions!P1 -> Pay 2014 | C41: Comm Serv | D41: =SUM(E41:S41) -> 0 | E41: =ROUND(IF($D$11=0,0,E$24/$D$11*$D7),2) -> 0 | F41: =ROUND(IF($D$11=0,0,F$24/$D$11*$D7),2) -> 0 | G41: =ROUND(IF($D$11=0,0,G$24/$D$11*$D7),2) -> 0 | H41: =ROUND(IF($D$11=0,0,H$24/$D$11*$D7),2) -> 0 | I41: =ROUND(IF($D$11=0,0,I$24/$D$11*$D7),2) -> 0 | J41: =ROUND(IF($D$11=0,0,J$24/$D$11*$D7),2) -> 0 | K41: =ROUND(IF($D$11=0,0,K$24/$D$11*$D7),2) -> 0 | L41: =ROUND(IF($D$11=0,0,L$24/$D$11*$D7),2) -> 0 | ... S41: =ROUND(IF($D$11=0,0,S$24/$D$11*$D7),2) -> 0
...

Sheet Accounts
A1: Reconciation of Property Tax Accounts | I1: =Report!A3 -> 1 | J1: =Report!B5 -> AITKIN | L1: =Report!I1 -> 41828 | N1: Note:
N2: Account balances are indicated as debit or (credit) balance
A3: On Reports tab enter your district # in cell A3 so correct tax shift amounts carryover | N3: Asset and expenditure accounts would normally have a debit balance
A4: Data entered on Funds tab will carryover and be used to allocate adjustments and abatements | N4: Liability and revenue accounts would normally have a credit balance
A5: On this tab enter data in highlighted fields only--from source indicated | N5: See comments by accounts GNL 214 and SRC 020 and 299
A6: All other fields will compute, including those that come from the Tax Shift spreadsheet
A7: Enter debits as positive and credits as negative, as indicated in column H | I7: General | J7: Comm Serv | K7: GDS Debt | L7: OPEB Debt | M7: Total
I8: Debit (Credit) | J8: Debit (Credit) | K8: Debit (Credit) | L8: Debit (Credit) | M8: Debit (Credit)
A10: Balance Sheet Acccounts:
A12: =Instructions!P1&" Certified Levy" -> Pay 2014 Certified Levy | H12: Debit | I12: =Funds!D6 -> 0 | J12: =Funds!D7 -> 0 | K12: =Funds!D8 -> 0 | L12: =Funds!D9 -> 0 | M12: =SUM(I12:L12) -> 0 | N12: Levy Limitation & Certification Report
A13: ="Tax settlements "&Instructions!T4&" for "&Instructions!P1&" levy" -> Tax settlements 05/01/2014 to 06/30/2014 for Pay 2014 levy | H13: (Credit) | I13: =-Funds!D40 -> 0 | J13: =-Funds!D41 -> 0 | K13: =-Funds!D42 -> 0 | L13: =-Funds!D43 -> 0 | M13: =SUM(I13:L13) -> 0 | N13: ="Tax Settlement Reports (Form 52) "&Instructions!T2 -> Tax Settlement Reports (Form 52) 07/01/2013 to 06/30/2014
A14: ="Tax settlements Fiscal disparities "&Instructions!T4&" for "&Instructions!P1&" levy" -> Tax settlements Fiscal disparities 05/01/2014 to 06/30/2014 for Pay 2014 levy | H14: (Credit) | I14: =-Funds!D94 -> 0 | J14: =-Funds!D95 -> 0 | K14: =-Funds!D96 -> 0 | L14: =-Funds!D97 -> 0 | M14: =SUM(I14:L14) -> 0 | N14: ="Tax Settlement Reports (Form 52) "&Instructions!T2 -> Tax Settlement Reports (Form 52) 07/01/2013 to 06/30/2014
A15: ="Tax settlements Taconite homestead credit "&Instructions!T4&" for "&Instructions!P1&" levy" -> Tax settlements Taconite homestead credit 05/01/2014 to 06/30/2014 for Pay 2014 levy | H15: (Credit) | I15: =-Funds!D112 -> 0 | J15: =-Funds!D113 -> 0 | K15: =-Funds!D114 -> 0 | L15: =-Funds!D115 -> 0 | M15: =SUM(I15:L15) -> 0 | N15: ="Tax Settlement Reports (Form 52) "&Instructions!T2 -> Tax Settlement Reports (Form 52) 07/01/2013 to 06/30/2014
A16: (Do not include any July payments)
B18: ="110 Taxes Receivable--Current "&Instructions!S2 -> 110 Taxes Receivable--Current 06/30/14 | I18: =SUM(I12:I16) -> 0 | J18: =SUM(J12:J16) -> 0 | K18: =SUM(K12:K16) -> 0 | L18: =SUM(L12:L16) -> 0
A22: ="Delinquent Taxes Receivable "&Instructions!S3 -> Delinquent Taxes Receivable 06/30/13 | H22: Debit | I22: 0 | J22: 0 | K22: 0 | L22: 0 | M22: =SUM(I22:L22) -> 0 | N22: ="General Ledger "&Instructions!S3 -> General Ledger 06/30/13
A23: ="Current Taxes Receivable "&Instructions!S3 -> Current Taxes Receivable 06/30/13 | H23: Debit | I23: 0 | J23: 0 | K23: 0 | L23: 0 | M23: =SUM(I23:L23) -> 0 | N23: ="General Ledger "&Instructions!S3 -> General Ledger 06/30/13
A24: ="Increase (decrease) to "&Instructions!P2&" levy by county" -> Increase (decrease) to Pay 2013 levy by county | H24: Debit (Credit) | I24: =ROUND(IF(M24=0,0,Funds!E6/Funds!E11*M24),2) -> 0 | J24: =ROUND(IF(M24=0,0,Funds!E7/Funds!E11*M24),2) -> 0 | K24: =ROUND(IF(M24=0,0,Funds!E8/Funds!E11*M24),2) -> 0 | L24: =ROUND(IF(M24=0,0,Funds!E9/Funds!E11*M24),2) -> 0 | M24: 0 | N24: Taxes Receivable Report (Form 51)
A25: ="Increase (decrease) to "&Instructions!P3&" levy by county" -> Increase (decrease) to Pay 2012 levy by county | H25: Debit (Credit) | I25: =ROUND(IF($M$25=0,0,Funds!F6/Funds!$F$11*$M$25),2) -> 0 | J25: =ROUND(IF($M$25=0,0,Funds!F7/Funds!$F$11*$M$25),2) -> 0 | K25: =ROUND(IF($M$25=0,0,Funds!F8/Funds!$F$11*$M$25),2) -> 0 | L25: =ROUND(IF($M$25=0,0,Funds!F9/Funds!$F$11*$M$25),2) -> 0 | M25: 0 | N25: Taxes Receivable Report (Form 51)
A26: ="Agricultural Educ Homestead Market Value Credit for "&Instructions!R2 -> Agricultural Educ Homestead Market Value Credit for FY 2014 | H26: (Credit) | I26: 0 | J26: 0 | K26: 0 | L26: 0 | M26: =SUM(I26:L26) -> 0 | N26: Report of Credits from Dept of Revenue
A27: ="Other credits for "&Instructions!R2 -> Other credits for FY 2014 | H27: (Credit) | I27: 0 | J27: 0 | K27: 0 | L27: 0 | M27: =SUM(I27:L27) -> 0 | N27: Report of Credits from Dept of Revenue
A28: ="Disparity Aid adjustments for "&Instructions!R2 -> Disparity Aid adjustments for FY 2014 | H28: (Credit) | I28: 0 | J28: 0 | K28: 0 | L28: 0 | M28: =SUM(I28:L28) -> 0 | N28: Report of Credits from Dept of Revenue
A29: ="Decrease (increase) to credits by county" -> Decrease (increase) to credits by county | H29: Debit (Credit) | I29: =ROUND(IF(Funds!$E$11=0,0,Funds!E6/Funds!$E$11*$M$29),2) -> 0 | J29: =ROUND(IF(Funds!$E$11=0,0,Funds!E7/Funds!$E$11*$M$29),2) -> 0 | K29: =ROUND(IF(Funds!$E$11=0,0,Funds!E8/Funds!$E$11*$M$29),2) -> 0 | L29: =ROUND(IF(Funds!$E$11=0,0,Funds!E9/Funds!$E$11*$M$29),2) -> 0 | M29: 0 | N29: Credits on Taxes receivable minus credits from Revenue
A30: ="Abatements "&Instructions!T2&" for "&Instructions!P2&" levy" -> Abatements 07/01/2013 to 06/30/2014 for Pay 2013 levy | H30: (Credit) | I30: =ROUND(IF(Funds!$E$11=0,0,Funds!E6/Funds!$E$11*$M$30),2) -> 0 | J30: =ROUND(IF(Funds!$E$11=0,0,Funds!E7/Funds!$E$11*$M$30),2) -> 0 | K30: =ROUND(IF(Funds!$E$11=0,0,Funds!E8/Funds!$E$11*$M$30),2) -> 0 | L30: =ROUND(IF(Funds!$E$11=0,0,Funds!E9/Funds!$E$11*$M$30),2) -> 0 | M30: 0 | N30: Taxes Receivable Report (Form 51)
A31: ="Abatements "&Instructions!T2&" for "&Instructions!P3&" levy" -> Abatements 07/01/2013 to 06/30/2014 for Pay 2012 levy | H31: (Credit) | I31: =ROUND(IF(Funds!$F$11=0,0,Funds!F6/Funds!$F$11*$M$31),2) -> 0 | J31: =ROUND(IF(Funds!$F$11=0,0,Funds!F7/Funds!$F$11*$M$31),2) -> 0 | K31: =ROUND(IF(Funds!$F$11=0,0,Funds!F8/Funds!$F$11*$M$31),2) -> 0 | L31: =ROUND(IF(Funds!$F$11=0,0,Funds!F9/Funds!$F$11*$M$31),2) -> 0 | M31: 0 | N31: Taxes Receivable Report (Form 51)
A32: ="Abatements "&Instructions!T2&" for "&Instructions!P4&" levy" -> Abatements 07/01/2013 to 06/30/2014 for Pay 2011 levy | H32: (Credit) | I32: =ROUND(IF(Funds!$G$11=0,0,Funds!G6/Funds!$G$11*$M$32),2) -> 0 | J32: =ROUND(IF(Funds!$G$11=0,0,Funds!G7/Funds!$G$11*$M$32),2) -> 0 | K32: =ROUND(IF(Funds!$G$11=0,0,Funds!G8/Funds!$G$11*$M$32),2) -> 0 | L32: =ROUND(IF(Funds!$G$11=0,0,Funds!G9/Funds!$G$11*$M$32),2) -> 0 | M32: 0 | N32: Taxes Receivable Report (Form 51)
A33: ="Abatements "&Instructions!T2&" for "&Instructions!P5&" levy" -> Abatements 07/01/2013 to 06/30/2014 for Pay 2010 levy | H33: (Credit) | I33: =ROUND(IF(Funds!$H$11=0,0,Funds!H6/Funds!$H$11*$M$33),2) -> 0 | J33: =ROUND(IF(Funds!$H$11=0,0,Funds!H7/Funds!$H$11*$M$33),2) -> 0 | K33: =ROUND(IF(Funds!$H$11=0,0,Funds!H8/Funds!$H$11*$M$33),2) -> 0 | L33: =ROUND(IF(Funds!$H$11=0,0,Funds!H9/Funds!$H$11*$M$33),2) -> 0 | M33: 0 | N33: Taxes Receivable Report (Form 51)
A34: ="Abatements "&Instructions!T2&" for "&Instructions!P6&" levy" -> Abatements 07/01/2013 to 06/30/2014 for Pay 2009 levy | H34: (Credit) | I34: =ROUND(IF(Funds!$I$11=0,0,Funds!I6/Funds!$I$11*$M$34),2) -> 0 | J34: =ROUND(IF(Funds!$I$11=0,0,Funds!I7/Funds!$I$11*$M$34),2) -> 0 | K34: =ROUND(IF(Funds!$I$11=0,0,Funds!I8/Funds!$I$11*$M$34),2) -> 0 | L34: =ROUND(IF(Funds!$I$11=0,0,Funds!I9/Funds!$I$11*$M$34),2) -> 0 | M34: 0 | N34: Taxes Receivable Report (Form 51)
A35: ="Abatements "&Instructions!T2&" for "&Instructions!P7&" levy" -> Abatements 07/01/2013 to 06/30/2014 for Pay 2008 levy | H35: (Credit) | I35: =ROUND(IF(Funds!$J$11=0,0,Funds!J6/Funds!$J$11*$M$35),2) -> 0 | J35: =ROUND(IF(Funds!$J$11=0,0,Funds!J7/Funds!$J$11*$M$35),2) -> 0 | K35: =ROUND(IF(Funds!$J$11=0,0,Funds!J8/Funds!$J$11*$M$35),2) -> 0 | L35: =ROUND(IF(Funds!$J$11=0,0,Funds!J9/Funds!$J$11*$M$35),2) -> 0 | M35: 0 | N35: Taxes Receivable Report (Form 51)
A36: ="Abatements "&Instructions!T2&" for "&Instructions!P8&" levy" -> Abatements 07/01/2013 to 06/30/2014 for Pay 2007 levy | H36: (Credit) | I36: =ROUND(IF(Funds!$K$11=0,0,Funds!K6/Funds!$K$11*$M$36),2) -> 0 | J36: =ROUND(IF(Funds!$K$11=0,0,Funds!K7/Funds!$K$11*$M$36),2) -> 0 | K36: =ROUND(IF(Funds!$K$11=0,0,Funds!K8/Funds!$K$11*$M$36),2) -> 0 | L36: =ROUND(IF(Funds!$K$11=0,0,Funds!K9/Funds!$K$11*$M$36),2) -> 0 | M36: 0 | N36: Taxes Receivable Report (Form 51)
A37: ="Write off "&Instructions!P8&" delinquent taxes negative (positive) balance due" -> Write off Pay 2007 delinquent taxes negative (positive) balance due | H37: Debit (Credit) | I37: =ROUND(IF(Funds!$K$11=0,0,Funds!K6/Funds!$K$11*$M$37),2) -> 0 | J37: =ROUND(IF(Funds!$K$11=0,0,Funds!K7/Funds!$K$11*$M$37),2) -> 0 | K37: =ROUND(IF(Funds!$K$11=0,0,Funds!K8/Funds!$K$11*$M$37),2) -> 0 | L37: =ROUND(IF(Funds!$K$11=0,0,Funds!K9/Funds!$K$11*$M$37),2) -> 0 | M37: 0 | N37: Taxes Receivable Report (Form 51)
A38: ="Tax settlements "&Instructions!T2&" for "&Instructions!P2&" and prior levies" -> Tax settlements 07/01/2013 to 06/30/2014 for Pay 2013 and prior levies | H38: (Credit) | I38: =-Funds!D57 -> 0 | J38: =-Funds!D68 -> 0 | K38: =-Funds!D79 -> 0 | L38: =-Funds!D90 -> 0 | M38: =SUM(I38:L38) -> 0 | N38: ="Tax Settlement Reports (Form 52) "&Instructions!T2 -> Tax Settlement Reports (Form 52) 07/01/2013 to 06/30/2014
A39: ="Tax settlements Fiscal Disparities "&Instructions!T3&" for "&Instructions!P2 -> Tax settlements Fiscal Disparities 07/01/2013 to 04/30/2014 for Pay 2013 | H39: (Credit) | I39: =-Funds!D103 -> 0 | J39: =-Funds!D104 -> 0 | K39: =-Funds!D105 -> 0 | L39: =-Funds!D106 -> 0 | M39: =SUM(I39:L39) -> 0 | N39: ="Tax Settlement Reports (Form 52) "&Instructions!T2 -> Tax Settlement Reports (Form 52) 07/01/2013 to 06/30/2014
A40: ="Tax settlements Taconite homestead credit "&Instructions!T3&" for "&Instructions!P2 -> Tax settlements Taconite homestead credit 07/01/2013 to 04/30/2014 for Pay 2013 | H40: (Credit) | I40: =-Funds!D121 -> 0 | J40: =-Funds!D122 -> 0 | K40: =-Funds!D123 -> 0 | L40: =-Funds!D124 -> 0 | M40: =SUM(I40:L40) -> 0 | N40: ="Tax Settlement Reports (Form 52) "&Instructions!T2 -> Tax Settlement Reports (Form 52) 07/01/2013 to 06/30/2014
B42: ="111 Delinquent Taxes Receivable "&Instructions!S2 -> 111 Delinquent Taxes Receivable 06/30/14 | I42: =SUM(I22:I40) -> 0 | J42: =SUM(J22:J40) -> 0 | K42: =SUM(K22:K40) -> 0 | L42: =SUM(L22:L40) -> 0
A44: Year end receivable (payable) adjustment for property tax shift | H44: (Credit) | I44: =Report!I18 -> -5395.57 | J44: =Report!I23 -> 5395.57 | M44: =SUM(I44:L44) -> -7.2759576e-12 | N44: Tax Shift Report (column 6)
B46: ="213 Property Tax Shift Adjustment "&Instructions!S2 -> 213 Property Tax Shift Adjustment 06/30/14 | I46: =I44 -> -5395.57 | J46: =J44 -> 5395.57
A48: Amount by which tax shift exceeds property tax receipts | H48: Debit | I48: =Report!E86 -> 0 | J48: =Report!E88 -> 0 | M48: =SUM(I48:L48) -> 0 | N48: Tax Shift Entry
B50: ="214 Advance of Unearned General Education Aid "&Instructions!S2 -> 214 Advance of Unearned General Education Aid 06/30/14 | I50: =SUM(I48:I49) -> 0 | J50: =SUM(J48:J49) -> 0
A52: ="Deferred Revenue for Delinquent Taxes "&Instructions!S3 -> Deferred Revenue for Delinquent Taxes 06/30/13 | H52: (Credit) | I52: 0 | J52: 0 | K52: 0 | L52: 0 | M52: =SUM(I52:L52) -> 0 | N52: ="General Ledger "&Instructions!S3 -> General Ledger 06/30/13
...

Sheet Entries
A1: Entries to record property taxes | C1: n/a | D1: n/a | E1: =Report!I1 -> 41828 | F1: n/a | G1: n/a
A2: line left blank intentionally
A3: Jan 1 | B3: Debit | C3: GL 110 | D3: Current Taxes Receivable
A4: n/a | B4: Credit | C4: GL 235 | D4: Deferred Revenue
A5: n/a | B5: n/a | C5: To record current year levy as taxes receivable
A6: line left blank intentionally
A7: Jan 1 | B7: Debit | C7: GL 111 | D7: Delinquent Taxes Receivable
A8: n/a | B8: Credit | C8: GL 110 | D8: Current Taxes Receivable
A9: n/a | B9: n/a | C9: To transfer current taxes receivable to delinquent taxes
A10: line left blank intentionally
A11: Jan - July | B11: Debit | C11: GL 101 | D11: Cash
A12: n/a | B12: Credit | C12: GL 110 | D12: Current Taxes Receivable
A13: n/a | B13: Credit | C13: GL 111 | D13: Delinquent Taxes Receivable
A14: n/a | B14: Credit | C14: SRC 009 | D14: Fiscal Disparities
A15: n/a | B15: Credit | C15: SRC 014 | D15: Taconite Homestead Credit
A16: n/a | B16: Credit | C16: SRC 019 | D16: Miscellaneous tax revenue
A17: n/a | B17: n/a | C17: To record first half tax settlements received from counties
A18: line left blank intentionally
A19: June 30 | B19: Debit | C19: GL 235 | D19: Deferred Revenue
A20: n/a | B20: Debit | C20: GL 214 | D20: Advance of Unearned Gened
A21: n/a | B21: Credit | C21: SRC 001 | D21: Tax Revenue
A22: n/a | B22: Credit | C22: SRC 211 | D22: Tax Revenue (Portions with Finance Codes)
A23: n/a | B23: n/a | C23: To record current year tax shift
A24: line left blank intentionally
A25: n/a | B25: Note: Property tax shift entry shown on "Report" tab combines the June 30th entry to record the current year tax shift (entry just above this note) with the prior July 1st entry to reverse the prior year tax shift (entry similar to entry below, but for the previous July 1st). | C25: n/a | D25: n/a | E25: n/a | F25: n/a | G25: n/a
A26: line left blank intentionally
A27: July 1 | B27: Debit | C27: SRC 001 | D27: Tax Revenue
A28: n/a | B28: Debit | C28: SRC 211 | D28: Tax Revenue (Portions with Finance Codes)
A29: n/a | B29: Credit | C29: GL 235 | D29: Deferred Revenue
A30: n/a | B30: Debit | C30: GL 214 | D30: Advance of Unearned Gened
A31: n/a | B31: n/a | C31: To reverse prior year tax shift
A32: line left blank intentionally
A33: July 1 | B33: Debit | C33: GL 235 | D33: Deferred Revenue
A34: n/a | B34: Credit | C34: SRC 001 | D34: Tax Revenue
A35: n/a | B35: Credit | C35: SRC 001 | D35: Tax Revenue (Portions with Finance Codes)
A36: n/a | B36: n/a | C36: To record levy revenue for current year
A37: line left blank intentionally
A38: July 1 | B38: Debit | C38: SRC 001 | D38: Tax Revenue
A39: n/a | B39: Credit | C39: GL 110 | D39: Current Taxes Receivable
A40: n/a | B40: n/a | C40: To reduce taxes receivable for amount to be paid by state credits
...

Sheet Aid Adjust
A1: =Instructions!R2&" Aid Payment (Reduction)" -> FY 2014 Aid Payment (Reduction) | H1: =Report!I1 -> 41828
A2: Positve amount indicates state aid payment | E2: n/a | F2: n/a | G2: n/a | H2: n/a
A3: Negative amount indicates reduction to state aid payments | E3: n/a | F3: n/a | G3: n/a | H3: n/a
A4: File created from LEVY run under S:\common\TAXSHIFT | E4: n/a | F4: n/a | G4: n/a | H4: n/a
A5: line left blank intentionally | E5: n/a | F5: n/a | G5: n/a | H5: n/a
A6: n/a | B6: n/a | C6: n/a | D6: General Shift Aid Adjust | E6: Refer Aid Adjust | F6: Total General Aid Adjust | G6: Comm Serv Aid Adjust | H6: Total Aid Adjust
A7: n/a | B7: n/a | C7: n/a | D7: -2.4734801e+08 | E7: -2.455034e+08 | F7: -4.9285142e+08 | G7: -35601749 | H7: -5.2845317e+08
A8: n/a | B8: n/a | C8: n/a | D8: =SUM(D10:D341) -> 2.4944436e+08 | E8: =SUM(E10:E341) -> 2.6547387e+08 | F8: =SUM(F10:F341) -> 5.1491822e+08 | G8: =SUM(G10:G341) -> 36141518 | H8: =SUM(H10:H341) -> 5.5105974e+08
A9: line left blank intentionally
A10: 1 | B10: 1 | C10: AITKIN | D10: ='Shift 13'!D11-'Shift 14'!D6 -> 348692.74 | E10: ='Shift 13'!E11-'Shift 14'!E6 -> 0 | F10: =D10+E10 -> 348692.74 | G10: ='Shift 13'!M11-'Shift 14'!M6 -> 5395.57 | H10: =SUM(F10:G10) -> 354088.31
A11: 1.2 | B11: 3 | C11: MINNEAPOLIS | D11: ='Shift 13'!D12-'Shift 14'!D7 -> 10520675 | E11: ='Shift 13'!E12-'Shift 14'!E7 -> 21877596 | F11: =D11+E11 -> 32398271 | G11: ='Shift 13'!M12-'Shift 14'!M7 -> 2310760.1 | H11: =SUM(F11:G11) -> 34709031
A12: 2 | B12: 1 | C12: HILL CITY | D12: ='Shift 13'!D13-'Shift 14'!D8 -> 52908.37 | E12: ='Shift 13'!E13-'Shift 14'!E8 -> 0 | F12: =D12+E12 -> 52908.37 | G12: ='Shift 13'!M13-'Shift 14'!M8 -> 9691.81 | H12: =SUM(F12:G12) -> 62600.18
A13: 4 | B13: 1 | C13: MCGREGOR | D13: ='Shift 13'!D14-'Shift 14'!D9 -> 171965.38 | E13: ='Shift 13'!E14-'Shift 14'!E9 -> 0 | F13: =D13+E13 -> 171965.38 | G13: ='Shift 13'!M14-'Shift 14'!M9 -> 25493.62 | H13: =SUM(F13:G13) -> 197459
A14: 6 | B14: 3 | C14: SOUTH ST. PAUL | D14: ='Shift 13'!D15-'Shift 14'!D10 -> 1373574.9 | E14: ='Shift 13'!E15-'Shift 14'!E10 -> 1070015.6 | F14: =D14+E14 -> 2443590.5 | G14: ='Shift 13'!M15-'Shift 14'!M10 -> 174530.38 | H14: =SUM(F14:G14) -> 2618120.8
A15: 11 | B15: 1 | C15: ANOKA-HENNEPIN | D15: ='Shift 13'!D16-'Shift 14'!D11 -> 10965625 | E15: ='Shift 13'!E16-'Shift 14'!E11 -> 20072770 | F15: =D15+E15 -> 31038395 | G15: ='Shift 13'!M16-'Shift 14'!M11 -> 1511185 | H15: =SUM(F15:G15) -> 32549580
A16: 12 | B16: 1 | C16: CENTENNIAL | D16: ='Shift 13'!D17-'Shift 14'!D12 -> 1678920.9 | E16: ='Shift 13'!E17-'Shift 14'!E12 -> 2331680 | F16: =D16+E16 -> 4010601 | G16: ='Shift 13'!M17-'Shift 14'!M12 -> 203136.35 | H16: =SUM(F16:G16) -> 4213737.3
A17: 13 | B17: 1 | C17: COLUMBIA HEIGHTS | D17: ='Shift 13'!D18-'Shift 14'!D13 -> 1067552.7 | E17: ='Shift 13'!E18-'Shift 14'!E13 -> 780519.38 | F17: =D17+E17 -> 1848072.1 | G17: ='Shift 13'!M18-'Shift 14'!M13 -> 171191.46 | H17: =SUM(F17:G17) -> 2019263.6
A18: 14 | B18: 1 | C18: FRIDLEY | D18: ='Shift 13'!D19-'Shift 14'!D14 -> 1197487.9 | E18: ='Shift 13'!E19-'Shift 14'!E14 -> 702683.97 | F18: =D18+E18 -> 1900171.8 | G18: ='Shift 13'!M19-'Shift 14'!M14 -> 198881.39 | H18: =SUM(F18:G18) -> 2099053.2
A19: 15 | B19: 1 | C19: ST. FRANCIS | D19: ='Shift 13'!D20-'Shift 14'!D15 -> 1128147.4 | E19: ='Shift 13'!E20-'Shift 14'!E15 -> 558074.99 | F19: =D19+E19 -> 1686222.4 | G19: ='Shift 13'!M20-'Shift 14'!M15 -> 177575.69 | H19: =SUM(F19:G19) -> 1863798.1
A20: 16 | B20: 1 | C20: SPRING LAKE PARK | D20: ='Shift 13'!D21-'Shift 14'!D16 -> 2285453.8 | E20: ='Shift 13'!E21-'Shift 14'!E16 -> 1718912.6 | F20: =D20+E20 -> 4004366.4 | G20: ='Shift 13'!M21-'Shift 14'!M16 -> 224515.36 | H20: =SUM(F20:G20) -> 4228881.8
A21: 22 | B21: 1 | C21: DETROIT LAKES | D21: ='Shift 13'!D22-'Shift 14'!D17 -> 704875.8 | E21: ='Shift 13'!E22-'Shift 14'!E17 -> 499115.63 | F21: =D21+E21 -> 1203991.4 | G21: ='Shift 13'!M22-'Shift 14'!M17 -> 102673.53 | H21: =SUM(F21:G21) -> 1306665
... A341: 2908 | B341: 1 | C341: BRANDON-EVANSVILLE | D341: ='Shift 13'!D342-'Shift 14'!D337 -> 161904.79 | E341: ='Shift 13'!E342-'Shift 14'!E337 -> 235233.04 | F341: =D341+E341 -> 397137.83 | G341: ='Shift 13'!M342-'Shift 14'!M337 -> 18280.88 | H341: =SUM(F341:G341) -> 415418.71
A342: End of worksheet

Sheet Shift 14
A1: =Instructions!P1&" Gross Shift" -> Pay 2014 Gross Shift | D1: n/a | E1: n/a | F1: n/a | G1: n/a | H1: n/a | I1: n/a | J1: n/a | K1: n/a | L1: n/a | M1: n/a | N1: n/a | O1: n/a | P1: n/a | Q1: =Report!I1 -> 41828
A2: Shift at | B2: 0 | C2: n/a | D2: n/a | E2: n/a | F2: n/a | G2: n/a | H2: n/a | I2: n/a | J2: n/a | K2: n/a | L2: n/a | M2: n/a | N2: n/a | O2: n/a | P2: n/a | Q2: n/a
A3: n/a | B3: n/a | C3: n/a | D3: Genl with Aid Adjust | E3: Refer with Aid Adjust | F3: Refer No Aid Adjust | G3: Addl Refer Shift | H3: Career Technical | I3: 100% Shift | J3: Reemploy Resv | K3: Reemploy Unrsv | L3: Leg Changes Genl Fund | M3: Comm Serv at Shift % | N3: Leg Changes Comm Serv | O3: Total Gross Shift | P3: Total General Fund Shift | Q3: Total Comm Serv Fund Shift
A4: n/a | B4: n/a | C4: State Total | D4: =SUM(D6:D337) -> 0 | E4: =SUM(E6:E337) -> 0 | F4: =SUM(F6:F337) -> 1.1422854e+08 | G4: =SUM(G6:G337) -> 4282529.2 | H4: =SUM(H6:H337) -> 13410958 | I4: =SUM(I6:I337) -> 33527326 | J4: =SUM(J6:J337) -> -42970.9 | K4: =SUM(K6:K337) -> 5715999.1 | ... Q4: =SUM(Q6:Q337) -> 0
A5: line left blank intentionally
A6: 1 | B6: 1 | C6: AITKIN | D6: =ROUND(Data!AA8*$B$2,2) -> 0 | E6: =MAX(0,Data!AD8-Data!Y8) -> 0 | F6: =Data!Y8 -> 141143.88 | G6: =Data!X8 -> 0 | H6: =Data!K8+Data!R8 -> 30163.77 | I6: =Data!I8+Data!L8+Data!M8+Data!N8+Data!O8+Data!S8 -> 0 | J6: =Data!Q8 -> 0 | K6: =Data!J8+Data!P8 -> 6695.76 | L6: =Data!T8 -> 0 | M6: =ROUND(Data!AB8*$B$2,2) -> 0 | N6: =Data!U8 -> 0 | O6: =SUM(D6:N6) -> 178003.41 | P6: =SUM(D6:L6) -> 178003.41 | Q6: =SUM(M6:N6) -> 0
A7: 1.2 | B7: 3 | C7: MINNEAPOLIS | D7: =ROUND(Data!AA9*$B$2,2) -> 0 | E7: =MAX(0,Data!AD9-Data!Y9) -> 0 | F7: =Data!Y9 -> 10049626 | G7: =Data!X9 -> 1205612.7 | H7: =Data!K9+Data!R9 -> 677261.48 | I7: =Data!I9+Data!L9+Data!M9+Data!N9+Data!O9+Data!S9 -> 12969267 | J7: =Data!Q9 -> 0 | K7: =Data!J9+Data!P9 -> 652807.7 | L7: =Data!T9 -> 0 | M7: =ROUND(Data!AB9*$B$2,2) -> 0 | N7: =Data!U9 -> 0 | O7: =SUM(D7:N7) -> 25554575 | P7: =SUM(D7:L7) -> 25554575 | Q7: =SUM(M7:N7) -> 0
A8: 2 | B8: 1 | C8: HILL CITY | D8: =ROUND(Data!AA10*$B$2,2) -> 0 | E8: =MAX(0,Data!AD10-Data!Y10) -> 0 | F8: =Data!Y10 -> 0 | G8: =Data!X10 -> 0 | H8: =Data!K10+Data!R10 -> -10000 | I8: =Data!I10+Data!L10+Data!M10+Data!N10+Data!O10+Data!S10 -> 0 | J8: =Data!Q10 -> 0 | K8: =Data!J10+Data!P10 -> -9946.37 | L8: =Data!T10 -> 0 | M8: =ROUND(Data!AB10*$B$2,2) -> 0 | N8: =Data!U10 -> 0 | O8: =SUM(D8:N8) -> -19946.37 | P8: =SUM(D8:L8) -> -19946.37 | Q8: =SUM(M8:N8) -> 0
A9: 4 | B9: 1 | C9: MCGREGOR | D9: =ROUND(Data!AA11*$B$2,2) -> 0 | E9: =MAX(0,Data!AD11-Data!Y11) -> 0 | F9: =Data!Y11 -> 51784.65 | G9: =Data!X11 -> 0 | H9: =Data!K11+Data!R11 -> 10982.92 | I9: =Data!I11+Data!L11+Data!M11+Data!N11+Data!O11+Data!S11 -> 0 | J9: =Data!Q11 -> 0 | K9: =Data!J11+Data!P11 -> 15077.41 | L9: =Data!T11 -> 0 | M9: =ROUND(Data!AB11*$B$2,2) -> 0 | N9: =Data!U11 -> 0 | O9: =SUM(D9:N9) -> 77844.98 | P9: =SUM(D9:L9) -> 77844.98 | Q9: =SUM(M9:N9) -> 0
A10: 6 | B10: 3 | C10: SOUTH ST. PAUL | D10: =ROUND(Data!AA12*$B$2,2) -> 0 | E10: =MAX(0,Data!AD12-Data!Y12) -> 0 | F10: =Data!Y12 -> 360711.07 | G10: =Data!X12 -> 0 | H10: =Data!K12+Data!R12 -> 33145.64 | I10: =Data!I12+Data!L12+Data!M12+Data!N12+Data!O12+Data!S12 -> 0 | J10: =Data!Q12 -> 0 | K10: =Data!J12+Data!P12 -> 18214.15 | L10: =Data!T12 -> 0 | M10: =ROUND(Data!AB12*$B$2,2) -> 0 | N10: =Data!U12 -> 0 | O10: =SUM(D10:N10) -> 412070.86 | P10: =SUM(D10:L10) -> 412070.86 | Q10: =SUM(M10:N10) -> 0
A11: 11 | B11: 1 | C11: ANOKA-HENNEPIN | D11: =ROUND(Data!AA13*$B$2,2) -> 0 | E11: =MAX(0,Data!AD13-Data!Y13) -> 0 | F11: =Data!Y13 -> 3515884.7 | G11: =Data!X13 -> 197692.1 | H11: =Data!K13+Data!R13 -> 502489.57 | I11: =Data!I13+Data!L13+Data!M13+Data!N13+Data!O13+Data!S13 -> 0 | J11: =Data!Q13 -> 0 | K11: =Data!J13+Data!P13 -> -42469.48 | L11: =Data!T13 -> 0 | M11: =ROUND(Data!AB13*$B$2,2) -> 0 | N11: =Data!U13 -> 0 | O11: =SUM(D11:N11) -> 4173596.9 | P11: =SUM(D11:L11) -> 4173596.9 | Q11: =SUM(M11:N11) -> 0
A12: 12 | B12: 1 | C12: CENTENNIAL | D12: =ROUND(Data!AA14*$B$2,2) -> 0 | E12: =MAX(0,Data!AD14-Data!Y14) -> 0 | F12: =Data!Y14 -> 320094.52 | G12: =Data!X14 -> 16533.75 | H12: =Data!K14+Data!R14 -> 51446.72 | I12: =Data!I14+Data!L14+Data!M14+Data!N14+Data!O14+Data!S14 -> 0 | J12: =Data!Q14 -> 0 | K12: =Data!J14+Data!P14 -> 50424.71 | L12: =Data!T14 -> 0 | M12: =ROUND(Data!AB14*$B$2,2) -> 0 | N12: =Data!U14 -> 0 | O12: =SUM(D12:N12) -> 438499.7 | P12: =SUM(D12:L12) -> 438499.7 | Q12: =SUM(M12:N12) -> 0
A13: 13 | B13: 1 | C13: COLUMBIA HEIGHTS | D13: =ROUND(Data!AA15*$B$2,2) -> 0 | E13: =MAX(0,Data!AD15-Data!Y15) -> 0 | F13: =Data!Y15 -> 848958.71 | G13: =Data!X15 -> 0 | H13: =Data!K15+Data!R15 -> 50538.88 | I13: =Data!I15+Data!L15+Data!M15+Data!N15+Data!O15+Data!S15 -> 0 | J13: =Data!Q15 -> 0 | K13: =Data!J15+Data!P15 -> 36973.76 | L13: =Data!T15 -> 0 | M13: =ROUND(Data!AB15*$B$2,2) -> 0 | N13: =Data!U15 -> 0 | O13: =SUM(D13:N13) -> 936471.35 | P13: =SUM(D13:L13) -> 936471.35 | Q13: =SUM(M13:N13) -> 0
A14: 14 | B14: 1 | C14: FRIDLEY | D14: =ROUND(Data!AA16*$B$2,2) -> 0 | E14: =MAX(0,Data!AD16-Data!Y16) -> 0 | F14: =Data!Y16 -> 468605.33 | G14: =Data!X16 -> 0 | H14: =Data!K16+Data!R16 -> 34601.96 | I14: =Data!I16+Data!L16+Data!M16+Data!N16+Data!O16+Data!S16 -> 0 | J14: =Data!Q16 -> 0 | K14: =Data!J16+Data!P16 -> -28231.13 | L14: =Data!T16 -> 0 | M14: =ROUND(Data!AB16*$B$2,2) -> 0 | N14: =Data!U16 -> 0 | O14: =SUM(D14:N14) -> 474976.16 | P14: =SUM(D14:L14) -> 474976.16 | Q14: =SUM(M14:N14) -> 0
A15: 15 | B15: 1 | C15: ST. FRANCIS | D15: =ROUND(Data!AA17*$B$2,2) -> 0 | E15: =MAX(0,Data!AD17-Data!Y17) -> 0 | F15: =Data!Y17 -> 288492.79 | G15: =Data!X17 -> 0 | H15: =Data!K17+Data!R17 -> 75072.48 | I15: =Data!I17+Data!L17+Data!M17+Data!N17+Data!O17+Data!S17 -> 0 | J15: =Data!Q17 -> 0 | K15: =Data!J17+Data!P17 -> 26458.58 | L15: =Data!T17 -> 0 | M15: =ROUND(Data!AB17*$B$2,2) -> 0 | N15: =Data!U17 -> 0 | O15: =SUM(D15:N15) -> 390023.85 | P15: =SUM(D15:L15) -> 390023.85 | Q15: =SUM(M15:N15) -> 0
A16: 16 | B16: 1 | C16: SPRING LAKE PARK | D16: =ROUND(Data!AA18*$B$2,2) -> 0 | E16: =MAX(0,Data!AD18-Data!Y18) -> 0 | F16: =Data!Y18 -> 804793.86 | G16: =Data!X18 -> 73286.44 | H16: =Data!K18+Data!R18 -> 57958.55 | I16: =Data!I18+Data!L18+Data!M18+Data!N18+Data!O18+Data!S18 -> 0 | J16: =Data!Q18 -> 0 | K16: =Data!J18+Data!P18 -> 135923.82 | L16: =Data!T18 -> 0 | M16: =ROUND(Data!AB18*$B$2,2) -> 0 | N16: =Data!U18 -> 0 | O16: =SUM(D16:N16) -> 1071962.7 | P16: =SUM(D16:L16) -> 1071962.7 | Q16: =SUM(M16:N16) -> 0
A17: 22 | B17: 1 | C17: DETROIT LAKES | D17: =ROUND(Data!AA19*$B$2,2) -> 0 | E17: =MAX(0,Data!AD19-Data!Y19) -> 0 | F17: =Data!Y19 -> 133298.49 | G17: =Data!X19 -> 0 | H17: =Data!K19+Data!R19 -> 53846.78 | I17: =Data!I19+Data!L19+Data!M19+Data!N19+Data!O19+Data!S19 -> 0 | J17: =Data!Q19 -> 0 | K17: =Data!J19+Data!P19 -> 29758.83 | L17: =Data!T19 -> 0 | M17: =ROUND(Data!AB19*$B$2,2) -> 0 | N17: =Data!U19 -> 0 | O17: =SUM(D17:N17) -> 216904.1 | P17: =SUM(D17:L17) -> 216904.1 | Q17: =SUM(M17:N17) -> 0
... A337: 2908 | B337: 1 | C337: BRANDON-EVANSVILLE | D337: =ROUND(Data!AA339*$B$2,2) -> 0 | E337: =MAX(0,Data!AD339-Data!Y339) -> 0 | F337: =Data!Y339 -> 0 | G337: =Data!X339 -> 0 | H337: =Data!K339+Data!R339 -> 26815.88 | I337: =Data!I339+Data!L339+Data!M339+Data!N339+Data!O339+Data!S339 -> 0 | J337: =Data!Q339 -> -4306.76 | K337: =Data!J339+Data!P339 -> -493.12 | L337: =Data!T339 -> 0 | M337: =ROUND(Data!AB339*$B$2,2) -> 0 | N337: =Data!U339 -> 0 | O337: =SUM(D337:N337) -> 22016 | P337: =SUM(D337:L337) -> 22016 | Q337: =SUM(M337:N337) -> 0
A338: line left blank intentionally
A339: line left blank intentionally
A340: line left blank intentionally | D340: =+D4 -> 0
A341: n/a | B341: n/a | C341: n/a | D341: 2.4944824e+08
A342: n/a | B342: n/a | C342: n/a | D342: =+D340-D341 -> -2.4944824e+08
A343: End of worksheet

Sheet Data
A1: =Levy!A3 -> Pay 2014 Levy | I1: Pay 2014 Levy Summary data (G:\Finance\LEVY\levy summaries\…\......xls) | AD1: =Report!I1 -> 41828
I2: From Certified Levy Summaries
I3: dsg_lvy | J3: mnt_lvy_ini_une | K3: car_tec_lvy_crt | L3: hea_ben_lvy | M3: add_ret_lvy | N3: dsg_adj_lvy | O3: dsg_adj_lvy_2 | P3: une_adj_lvy | Q3: mnt_lvy_une_fb1 | R3: car_tec_adj_lvy | S3: hea_ben_adj_lvy | V3: ref_mkt_err_crt | W3: ref_tcp_err_crt | X3: fixed | Y3: fixed
D4: Genl RMV Voter | E4: Genl RMV Other | F4: Genl NTC Voter | G4: Genl NTC Other | H4: Comm Service | I4: Integ--1st Class | J4: Reemploy | K4: Career Technical | L4: Hea Ben | M4: Addl Retire | N4: Int Adj PY--1st Class | O4: Int Adj 2YP--1st Class | P4: Reemploy Adjust Unreserved | Q4: Reemploy Adjust Reserved | R4: Career Tech Adjust | S4: Hea Ben Adjust | T4: Legislative Changes Genl Fund | U4: Legislative Changes Comm Serv | V4: Prinsburg Exclusion RMV Voter | W4: Prinsburg Exclusion NTC Voter | X4: Add'l Referendum | Y4: Pay 2001 Refer Shift | Z4: 100% Shift Total | AA4: Shiftable Oth Gen (E+F+G-U-X-Y-AA) | AB4: Shiftable Comm Serv (H-T-V) | AC4: =Instructions!P1&" Refer at Shift Percent" -> Pay 2014 Refer at Shift Percent | AD4: ="Refer (GTR of "&Instructions!P1&" or Pay 2001)" -> Refer (GTR of Pay 2014 or Pay 2001) | AZ4: Add'l Referendum | BA4: Pay 2001 Refer Shift
AA5: 5.0894653e+08 | AB5: 73254628 | AZ5: 4282529.2 | BA5: 1.1422854e+08
C6: State Total | D6: =SUM(D8:D339) -> 5.3052543e+08 | E6: =SUM(E8:E339) -> 3.3639926e+08 | F6: =SUM(F8:F339) -> 60897104 | G6: =SUM(G8:G339) -> 4.8154312e+08 | H6: =SUM(H8:H339) -> 74876386 | I6: =SUM(I8:I339) -> 10042493 | J6: =SUM(J8:J339) -> 8090511.2 | K6: =SUM(K8:K339) -> 16370041 | ... AD6: =SUM(AD8:AD339) -> 1.1422854e+08 | AY6: State Total | AZ6: =SUM(AZ8:AZ339) -> 4282529.2 | BA6: =SUM(BA8:BA339) -> 1.1422854e+08
AF7: dst_num | AG7: dst_tye | AH7: ref_mkt_err_crt | AI7: ref_tcp_err_crt | AJ7: dsg_lvy | AK7: mnt_lvy_ini_une | AL7: car_tec_lvy_crt | AM7: hea_ben_lvy | AN7: add_ret_lvy | AO7: dsg_adj_lvy | AP7: dsg_adj_lvy_2 | AQ7: une_adj_lvy | AR7: mnt_lvy_une_fb1 | AS7: car_tec_adj_lvy | AT7: hea_ben_adj_lvy | AV7: cos-num | AW7: dist | AX7: type
A8: 1 | B8: 1 | C8: AITKIN | D8: =Levy!F9 -> 3 | E8: =Levy!G9 -> 512160 | F8: =Levy!H9 -> 0 | G8: =Levy!I9 -> 376935 | H8: =Levy!J9 -> 0 | I8: 0 | J8: 7000 | K8: 34841.34 | L8: 0 | M8: 0 | N8: 0 | O8: 0 | P8: -304.24 | Q8: 0 | R8: -4677.57 | S8: 0 | T8: 0 | U8: 0 | V8: 0 | W8: 0 | X8: 0 | Y8: 141143.88 | Z8: =SUM(I8:T8) -> 36859.53 | AA8: =ROUND(MAX(E8+F8+G8-W8-X8-Z8,0),2) -> 852235.47 | AB8: =ROUND(MAX(H8-U8,0),2) -> 0 | AC8: =ROUND(MAX(0,(D8-V8)*'Shift 14'!$B$2),2) -> 0 | AD8: =MAX(AC8,Y8) -> 141143.88 | AE8: =AF8-A8 -> 0 | AF8: 1 | AG8: 1 | AH8: 0 | AI8: 0 | AJ8: 0 | AK8: 7000 | AL8: 34841.34 | AM8: 0 | AN8: 0 | AO8: 0 | AP8: 0 | AQ8: -304.24 | AR8: 0 | AS8: -4677.57 | AT8: 0 | AU8: =AV8-A8 -> 0 | AV8: 1 | AW8: 1 | AX8: 1 | AY8: AITKIN | AZ8: 0 | BA8: 141143.88
A9: 1.2 | B9: 3 | C9: MINNEAPOLIS | D9: =Levy!F10 -> 42963957 | E9: =Levy!G10 -> 32244453 | F9: =Levy!H10 -> 0 | G9: =Levy!I10 -> 40377225 | H9: =Levy!J10 -> 4958085 | I9: 4400061 | J9: 1000000 | K9: 705788.41 | L9: 0 | M9: 8470800 | N9: 0 | O9: 98405.69 | P9: -347192.3 | Q9: 0 | R9: -28526.93 | S9: 0 | T9: 0 | U9: 0 | V9: 0 | W9: 0 | X9: 1205612.7 | Y9: 10049626 | Z9: =SUM(I9:T9) -> 14299336 | AA9: =ROUND(MAX(E9+F9+G9-W9-X9-Z9,0),2) -> 57116729 | AB9: =ROUND(MAX(H9-U9,0),2) -> 4958085 | AC9: =ROUND(MAX(0,(D9-V9)*'Shift 14'!$B$2),2) -> 0 | AD9: =MAX(AC9,Y9) -> 10049626 | AE9: =AF9-A9 -> 0 | AF9: 1.2 | AG9: 3 | AH9: 0 | AI9: 0 | AJ9: 4400061 | AK9: 1000000 | AL9: 705788.41 | AM9: 0 | AN9: 8470800 | AO9: 0 | AP9: 98405.69 | AQ9: -347192.3 | AR9: 0 | AS9: -28526.93 | AT9: 0 | AU9: =AV9-A9 -> 0 | AV9: 1.2 | AW9: 1.2 | AX9: 3 | AY9: MINNEAPOLIS | AZ9: 1205612.7 | BA9: 10049626
A10: 2 | B10: 1 | C10: HILL CITY | D10: =Levy!F11 -> 0 | E10: =Levy!G11 -> 55347 | F10: =Levy!H11 -> 0 | G10: =Levy!I11 -> 61170 | H10: =Levy!J11 -> 18559 | I10: 0 | J10: 0 | K10: 0 | L10: 0 | M10: 0 | N10: 0 | O10: 0 | P10: -9946.37 | Q10: 0 | R10: -10000 | S10: 0 | T10: 0 | U10: 0 | V10: 0 | W10: 0 | X10: 0 | Y10: 0 | Z10: =SUM(I10:T10) -> -19946.37 | AA10: =ROUND(MAX(E10+F10+G10-W10-X10-Z10,0),2) -> 136463.37 | AB10: =ROUND(MAX(H10-U10,0),2) -> 18559 | AC10: =ROUND(MAX(0,(D10-V10)*'Shift 14'!$B$2),2) -> 0 | AD10: =MAX(AC10,Y10) -> 0 | AE10: =AF10-A10 -> 0 | AF10: 2 | AG10: 1 | AH10: 0 | AI10: 0 | AJ10: 0 | AK10: 0 | AL10: 0 | AM10: 0 | AN10: 0 | AO10: 0 | AP10: 0 | AQ10: -9946.37 | AR10: 0 | AS10: -10000 | AT10: 0 | AU10: =AV10-A10 -> 0 | AV10: 2 | AW10: 2 | AX10: 1 | AY10: HILL CITY | AZ10: 0 | BA10: 0
A11: 4 | B11: 1 | C11: MCGREGOR | D11: =Levy!F12 -> 375 | E11: =Levy!G12 -> 100950 | F11: =Levy!H12 -> 0 | G11: =Levy!I12 -> 319645 | H11: =Levy!J12 -> 53030 | I11: 0 | J11: 7300 | K11: 12648 | L11: 0 | M11: 0 | N11: 0 | O11: 0 | P11: 7777.41 | Q11: 0 | R11: -1665.08 | S11: 0 | T11: 0 | U11: 0 | V11: 0 | W11: 0 | X11: 0 | Y11: 51784.65 | Z11: =SUM(I11:T11) -> 26060.33 | AA11: =ROUND(MAX(E11+F11+G11-W11-X11-Z11,0),2) -> 394534.67 | AB11: =ROUND(MAX(H11-U11,0),2) -> 53030 | AC11: =ROUND(MAX(0,(D11-V11)*'Shift 14'!$B$2),2) -> 0 | AD11: =MAX(AC11,Y11) -> 51784.65 | AE11: =AF11-A11 -> 0 | AF11: 4 | AG11: 1 | AH11: 0 | AI11: 0 | AJ11: 0 | AK11: 7300 | AL11: 12648 | AM11: 0 | AN11: 0 | AO11: 0 | AP11: 0 | AQ11: 7777.41 | AR11: 0 | AS11: -1665.08 | AT11: 0 | AU11: =AV11-A11 -> 0 | AV11: 4 | AW11: 4 | AX11: 1 | AY11: MCGREGOR | AZ11: 0 | BA11: 51784.65
A12: 6 | B12: 3 | C12: SOUTH ST. PAUL | D12: =Levy!F13 -> 1109814 | E12: =Levy!G13 -> 1607848 | F12: =Levy!H13 -> 522346 | G12: =Levy!I13 -> 2118168 | H12: =Levy!J13 -> 313589 | I12: 0 | J12: 26700 | K12: 45409.2 | L12: 0 | M12: 0 | N12: 0 | O12: 0 | P12: -8485.85 | Q12: 0 | R12: -12263.56 | S12: 0 | T12: 0 | U12: 0 | V12: 0 | W12: 0 | X12: 0 | Y12: 360711.07 | Z12: =SUM(I12:T12) -> 51359.79 | AA12: =ROUND(MAX(E12+F12+G12-W12-X12-Z12,0),2) -> 4197002.2 | AB12: =ROUND(MAX(H12-U12,0),2) -> 313589 | AC12: =ROUND(MAX(0,(D12-V12)*'Shift 14'!$B$2),2) -> 0 | AD12: =MAX(AC12,Y12) -> 360711.07 | AE12: =AF12-A12 -> 0 | AF12: 6 | AG12: 3 | AH12: 0 | AI12: 0 | AJ12: 154304.54 | AK12: 26700 | AL12: 45409.2 | AM12: 0 | AN12: 0 | AO12: 0 | AP12: -1881.17 | AQ12: -8485.85 | AR12: 0 | AS12: -12263.56 | AT12: 0 | AU12: =AV12-A12 -> 0 | AV12: 6 | AW12: 6 | AX12: 3 | AY12: SOUTH ST. PAUL | AZ12: 0 | BA12: 360711.07
A13: 11 | B13: 1 | C13: ANOKA-HENNEPIN | D13: =Levy!F14 -> 26446869 | E13: =Levy!G14 -> 15845308 | F13: =Levy!H14 -> 2728226 | G13: =Levy!I14 -> 23560897 | H13: =Levy!J14 -> 3085048.6 | I13: 0 | J13: 100000 | K13: 652459.11 | L13: 0 | M13: 0 | N13: 0 | O13: 0 | P13: -142469.48 | Q13: 0 | R13: -149969.54 | S13: 0 | T13: 0 | U13: 0 | V13: 0 | W13: 0 | X13: 197692.1 | Y13: 3515884.7 | Z13: =SUM(I13:T13) -> 460020.09 | AA13: =ROUND(MAX(E13+F13+G13-W13-X13-Z13,0),2) -> 41476719 | AB13: =ROUND(MAX(H13-U13,0),2) -> 3085048.6 | AC13: =ROUND(MAX(0,(D13-V13)*'Shift 14'!$B$2),2) -> 0 | AD13: =MAX(AC13,Y13) -> 3515884.7 | AE13: =AF13-A13 -> 0 | AF13: 11 | AG13: 1 | AH13: 0 | AI13: 0 | AJ13: 1502416.4 | AK13: 100000 | AL13: 652459.11 | AM13: 0 | AN13: 0 | AO13: 0 | AP13: 288.18 | AQ13: -142469.48 | AR13: 0 | AS13: -149969.54 | AT13: 0 | AU13: =AV13-A13 -> 0 | AV13: 11 | AW13: 11 | AX13: 1 | AY13: ANOKA-HENNEPIN | AZ13: 197692.1 | BA13: 3515884.7
A14: 12 | B14: 1 | C14: CENTENNIAL | D14: =Levy!F15 -> 1845321.4 | E14: =Levy!G15 -> 3019153.1 | F14: =Levy!H15 -> 0 | G14: =Levy!I15 -> 4960893.5 | H14: =Levy!J15 -> 413840.61 | I14: 0 | J14: 25000 | K14: 67877.92 | L14: 0 | M14: 0 | N14: 0 | O14: 0 | P14: 25424.71 | Q14: 0 | R14: -16431.2 | S14: 0 | T14: 0 | U14: 0 | V14: 0 | W14: 0 | X14: 16533.75 | Y14: 320094.52 | Z14: =SUM(I14:T14) -> 101871.43 | AA14: =ROUND(MAX(E14+F14+G14-W14-X14-Z14,0),2) -> 7861641.5 | AB14: =ROUND(MAX(H14-U14,0),2) -> 413840.61 | AC14: =ROUND(MAX(0,(D14-V14)*'Shift 14'!$B$2),2) -> 0 | AD14: =MAX(AC14,Y14) -> 320094.52 | AE14: =AF14-A14 -> 0 | AF14: 12 | AG14: 1 | AH14: 0 | AI14: 0 | AJ14: 0 | AK14: 25000 | AL14: 67877.92 | AM14: 0 | AN14: 0 | AO14: 0 | AP14: 0 | AQ14: 25424.71 | AR14: 0 | AS14: -16431.2 | AT14: 0 | AU14: =AV14-A14 -> 0 | AV14: 12 | AW14: 12 | AX14: 1 | AY14: CENTENNIAL | AZ14: 16533.75 | BA14: 320094.52
A15: 13 | B15: 1 | C15: COLUMBIA HEIGHTS | D15: =Levy!F16 -> 999598.58 | E15: =Levy!G16 -> 1846818.2 | F15: =Levy!H16 -> 0 | G15: =Levy!I16 -> 1950276.2 | H15: =Levy!J16 -> 404050.21 | I15: 0 | J15: 22414.64 | K15: 57533.58 | L15: 0 | M15: 0 | N15: 0 | O15: 0 | P15: 14559.12 | Q15: 0 | R15: -6994.7 | S15: 0 | T15: 0 | U15: 0 | V15: 0 | W15: 0 | X15: 0 | Y15: 848958.71 | Z15: =SUM(I15:T15) -> 87512.64 | AA15: =ROUND(MAX(E15+F15+G15-W15-X15-Z15,0),2) -> 3709581.8 | AB15: =ROUND(MAX(H15-U15,0),2) -> 404050.21 | AC15: =ROUND(MAX(0,(D15-V15)*'Shift 14'!$B$2),2) -> 0 | AD15: =MAX(AC15,Y15) -> 848958.71 | AE15: =AF15-A15 -> 0 | AF15: 13 | AG15: 1 | AH15: 0 | AI15: 0 | AJ15: 19944.57 | AK15: 22414.64 | AL15: 57533.58 | AM15: 0 | AN15: 0 | AO15: 0 | AP15: 0 | AQ15: 14559.12 | AR15: 0 | AS15: -6994.7 | AT15: 0 | AU15: =AV15-A15 -> 0 | AV15: 13 | AW15: 13 | AX15: 1 | AY15: COLUMBIA HEIGHTS | AZ15: 0 | BA15: 848958.71
A16: 14 | B16: 1 | C16: FRIDLEY | D16: =Levy!F17 -> 799891.31 | E16: =Levy!G17 -> 1293258.1 | F16: =Levy!H17 -> 651253 | G16: =Levy!I17 -> 1382396.7 | H16: =Levy!J17 -> 321785.77 | I16: 0 | J16: 40000 | K16: 44391.45 | L16: 0 | M16: 0 | N16: 0 | O16: 0 | P16: -68231.13 | Q16: 0 | R16: -9789.49 | S16: 0 | T16: 0 | U16: 0 | V16: 0 | W16: 0 | X16: 0 | Y16: 468605.33 | Z16: =SUM(I16:T16) -> 6370.83 | AA16: =ROUND(MAX(E16+F16+G16-W16-X16-Z16,0),2) -> 3320537 | AB16: =ROUND(MAX(H16-U16,0),2) -> 321785.77 | AC16: =ROUND(MAX(0,(D16-V16)*'Shift 14'!$B$2),2) -> 0 | AD16: =MAX(AC16,Y16) -> 468605.33 | AE16: =AF16-A16 -> 0 | AF16: 14 | AG16: 1 | AH16: 0 | AI16: 0 | AJ16: 155039.36 | AK16: 40000 | AL16: 44391.45 | AM16: 0 | AN16: 0 | AO16: 0 | AP16: 0 | AQ16: -68231.13 | AR16: 0 | AS16: -9789.49 | AT16: 0 | AU16: =AV16-A16 -> 0 | AV16: 14 | AW16: 14 | AX16: 1 | AY16: FRIDLEY | AZ16: 0 | BA16: 468605.33
