Workbook

Sheet GRA-FINANC.
A2: CRONOGRAMA FINANCIERO REFORMULADO - ORDEN DE CAMBIO No 1
A4: 2.0439169e+08
B6: Cert Nº1 | C6: Cert Nº2 | D6: Cert Nº3 | E6: Cert Nº4 | F6: Cert Nº5 | G6: Cert Nº6 | H6: Cert Nº7 | I6: Cert Nº9 | J6: Cert Nº10 | K6: Cert Nº11 | L6: Cert Nº12 | M6: Cert Nº13 | N6: Cert Nº14 | O6: Cert Nº15 | P6: Cert Nº16 | Q6: Cert Nº17 | R6: Cert Nº18 | S6: Cert Nº19 | T6: Cert Nº20 | U6: Cert Nº21 | V6: Cert Nº22 | W6: Cert Nº23 | X6: Cert Nº24 | Y6: Cert Nº25 | Z6: Cert Nº26 | AA6: Cert Nº27 | AB6: Cert Nº28 | AC6: Cert Nº29 | AD6: Cert Nº30 | AE6: Cert Nº31 | AF6: Cert Nº32 | AG6: Cert Nº33 | AH6: Cert-Año1 | AI6: Cert-Año2 | AJ6: Cert-Año3 | AK6: TOTAL (BS.)
B7: 40544 | C7: 40575 | D7: 40603 | E7: 40634 | F7: 40664 | G7: 40695 | H7: 40725 | I7: 40756 | J7: 40787 | K7: 40817 | L7: 40848 | M7: 40878 | N7: 40909 | O7: 40940 | P7: 40969 | Q7: 41000 | R7: 41030 | S7: 41061 | T7: 41091 | U7: 41122 | V7: 41153 | W7: 41183 | X7: 41214 | Y7: 41244 | Z7: 41275 | AA7: 41306 | AB7: 41334 | AC7: 41365 | AD7: 41395 | AE7: 41426 | AF7: 41456 | AG7: 41487
A8: PROGRAMADO
A9: PROGRAMADO MENSUAL (BS.): | C9: =+C14 -> 77666.36 | D9: =+D14 -> 67986.93 | E9: =+E14 -> 81681.27 | F9: =+F14 -> 85754.32 | G9: =+G14 -> 782177.68 | H9: =+H14 -> 2839990.9 | I9: =+I14 -> 3867198.6 | J9: =+J14 -> 3154343.5 | ... Q9: =+Q14 -> 1867946.4 | R9: =CRONO!U489-'GRA-FINANC.'!Q10 -> 5612044 | S9: =+CRONO!W489 -> 3801368.9 | T9: =+CRONO!X489 -> 6224643.6 | U9: =+CRONO!Y489 -> 8526568.3 | V9: =+CRONO!Z489 -> 10676787 | W9: =+CRONO!AA489 -> 12837837 | X9: =+CRONO!AB489 -> 12721622 | Y9: =+CRONO!AC489 -> 11582344 | Z9: =+CRONO!AD489 -> 11865789 | ... AG9: =+CRONO!AK489 -> 4291994.5 | AH9: =+CRONO!AM489 -> 2739007.9 | AI9: =+CRONO!AN489 -> 2739007.9 | AJ9: =+CRONO!AO489 -> 2739007.9 | AK9: =SUM(C9:AJ9) -> 2.2419464e+08
A10: DESEMBOLSO ACUMULADO (BS.): | B10: =B9 -> 0 | C10: =B10+C9 -> 77666.36 | D10: =C10+D9 -> 145653.29 | E10: =D10+E9 -> 227334.56 | F10: =E10+F9 -> 313088.88 | G10: =F10+G9 -> 1095266.6 | H10: =G10+H9 -> 3935257.5 | I10: =H10+I9 -> 7802456 | J10: =I10+J9 -> 10956800 | ... AJ10: =AI10+AJ9 -> 2.2419464e+08
A13: EJECUTADO | B13: Cert Nº1 | C13: Cert Nº2 | D13: Cert Nº3 | E13: Cert Nº4 | F13: Cert Nº5 | G13: Cert Nº6 | H13: Cert Nº7 | I13: Cert Nº9 | J13: Cert Nº10 | K13: Cert Nº11 | L13: Cert Nº12 | M13: Cert Nº13 | N13: Cert Nº14 | O13: Cert Nº15 | P13: Cert Nº16 | Q13: Cert Nº17 | R13: Cert Nº18 | S13: Cert Nº19 | T13: Cert Nº20 | U13: Cert Nº21 | V13: Cert Nº22 | W13: Cert Nº23 | X13: Cert Nº24 | Y13: Cert Nº25 | Z13: Cert Nº26 | AA13: Cert Nº27 | AB13: Cert Nº28 | AC13: Cert Nº29 | AD13: Cert Nº30 | AE13: Cert Nº31 | AF13: Cert Nº32 | AG13: Cert Nº33 | AH13: Cert-Año1 | AI13: Cert-Año2 | AJ13: Cert-Año3
A14: EJECUTADO MENSUAL (BS.): | B14: =+B9 -> 0 | C14: 77666.36 | D14: 67986.93 | E14: 81681.27 | F14: 85754.32 | G14: 782177.68 | H14: 2839990.9 | I14: 3867198.6 | J14: 3154343.5 | K14: 1251047.5 | L14: 1217725.5 | M14: 129468.78 | N14: 935930.37 | O14: 720487.39 | P14: 1257187.2 | Q14: 1867946.4 | R14: 2072454.3 | AK14: =SUM(C14:AJ14) -> 20409047
A15: EJECUTADO ACUMULADO (BS.): | B15: =B14 -> 0 | C15: =B15+C14 -> 77666.36 | D15: =C15+D14 -> 145653.29 | E15: =D15+E14 -> 227334.56 | F15: =E15+F14 -> 313088.88 | G15: =F15+G14 -> 1095266.6 | H15: =G15+H14 -> 3935257.5 | I15: =H15+I14 -> 7802456 | J15: =I15+J14 -> 10956800 | ... R15: =Q15+R14 -> 20409047
C96: NOTA: | D96: Certificado Nº 8 Corresponde al Anticipo Adicional del Cemento Asfaltico
B106: 40878338 | L106: 2.2419464e+08
L107: =L15 -> 13425573
L108: =L107/L106 -> 0.0599
L109: =L14/L106 -> 0.0054

Sheet CRONO
D1: CRONOGRAMA FISICO - FINANCIERO
C2: CRONOGRAMA REFORMULADO DE OBRA - ORDEN DE CAMBIO No 1
C3: PROYECTO PAVIMENTACION ZUDAÑEZ - PADILLA: PROGRESIVAS: (INICIO:99+000; FIN:167+668)
C6: N° | D6: Descripcion de Rubros/Items | E6: Unidad | F6: Precio Unitario ( Bs ) | G6: CANTIDADES Y MONTOS | N6: Notas | O6: Mes 10 | P6: Mes 12 | Q6: Mes 12 | R6: Mes 13 | S6: Mes 14 | T6: Mes 15 | U6: Mes 17 | W6: Mes 18 | X6: Mes 19 | Y6: Mes 20 | Z6: Mes 21 | AA6: Mes 22 | AB6: Mes 23 | AC6: Mes 24 | AD6: Mes 25 | AE6: Mes 26 | AF6: Mes 27 | AG6: Mes 28 | AH6: Mes 29 | AI6: Mes 30 | AJ6: Mes 31 | AK6: Mes 32 | AM6: Año 1 | AN6: Año 2 | AO6: Año 3
G7: Contrato Original | H7: Contrato Modific.#3 | I7: Ejecutada | J7: Adicional | K7: TOTAL | L7: A Ejecutar | O7: 40817 | P7: 40848 | Q7: 40878 | R7: 40909 | S7: 40940 | T7: 40969 | U7: 41030 | W7: =U7+31 -> 41061 | X7: =W7+31 -> 41092 | Y7: =X7+31 -> 41123 | Z7: =Y7+31 -> 41154 | AA7: =Z7+31 -> 41185 | AB7: =AA7+31 -> 41216 | AC7: =AB7+31 -> 41247 | AD7: =AC7+31 -> 41278 | AE7: =AD7+31 -> 41309 | ... AK7: =AJ7+31 -> 41495
AV8: Por Ejecutar
C9: 1 | D9: MOVIMIENTO DE TIERRAS. | E9: =+E12+E16+E20+E24+E28+E32+E36+E40+E44+E48+E52 -> 0
A10: P | C10: 1 | D10: 1.1 Desbroce, Desbosque, Destronque y Limpieza | E10: [ ha ] | F10: 3467.88 | G10: 378 | H10: 391 | I10: 0.75 | K10: =H10+J10 -> 391 | L10: =+H10-I10+J10 -> 390.25 | N10: Cantidad | U10: =+I10 -> 0.75 | W10: =+W11*$G$10 -> 0 | X10: =+X11*$G$10 -> 0 | Y10: =+Y11*$K$10 -> 39.1 | Z10: =+Z11*$K$10 -> 39.1 | AA10: =+AA11*$K$10 -> 39.1 | AB10: =+AB11*$K$10 -> 39.1 | AC10: =+AC11*$G$10 -> 0 | AD10: =+AD11*$G$10 -> 0 | AE10: =+AE11*$G$10 -> 0 | AF10: =+AF11*$K$10 -> 58.65 | AG10: =+AG11*$K$10 -> 58.65 | AH10: =+AH11*$K$10 -> 58.65 | AI10: =+AI11*$K$10+0.03 -> 57.9 | AJ10: =+AJ11*$K$10 -> 0 | AQ10: =SUM(O10:AO10) -> 391 | AR10: =+K10-AQ10 -> 0 | AT10: =+F10*K10 -> 1355941.1 | AV10: =SUM(W10:AO10) -> 390.25 | AW10: =+L10-AV10 -> 0 | BA10: =SUM(O10:U10) -> 0.75
A11: P | N11: Porcentaje | U11: =+U10/G10 -> 0.002 | Y11: 0.1 | Z11: 0.1 | AA11: 0.1 | AB11: 0.1 | AF11: 0.15 | AG11: 0.15 | AH11: 0.15 | AI11: 0.148 | AQ11: =SUM(O11:AO11) -> 1 | BA11: =SUM(O11:U11) -> 0
A12: C | BA12: =SUM(O12:U12) -> 0
A13: 1 | G13: =ROUND(G10*$F10,2) -> 1310858.6 | H13: =ROUND(H10*$F10,2) -> 1355941.1 | I13: =ROUND(I10*$F10,2) -> 2600.91 | J13: =J10*$F10 -> 0 | K13: =ROUND(K10*$F10,2) -> 1355941.1 | L13: =ROUND(L10*$F10,2) -> 1353340.2 | N13: Monto | U13: =U10*$F10 -> 2600.91 | W13: =W10*$F10 -> 0 | X13: =X10*$F10 -> 0 | Y13: =Y10*$F10 -> 135594.11 | Z13: =Z10*$F10 -> 135594.11 | AA13: =AA10*$F10 -> 135594.11 | AB13: =AB10*$F10 -> 135594.11 | AC13: =AC10*$F10 -> 0 | AD13: =AD10*$F10 -> 0 | ... AJ13: =AJ10*$F10 -> 0 | AQ13: =SUM(O13:AO13) -> 1355941.1 | AR13: =+K13-AQ13 -> 0
C14: 2 | D14: 1.2 Excavación No Clasificada Distancia < 300 m | E14: [ m³ ] | F14: 17.35 | G14: 757437 | H14: 840374.49 | I14: 325132.65 | K14: =H14+J14 -> 840374.49 | L14: =+H14-I14+J14 -> 515241.84 | N14: Cantidad | U14: =+I14 -> 325132.65 | W14: 25000 | X14: 25000 | Y14: 25000 | Z14: 25000 | AA14: 25000 | AB14: 25000 | AC14: 25000 | AD14: 50000 | AE14: 50000 | AF14: 60000 | AG14: 75000 | AH14: 60000 | AI14: 45241.84 | AQ14: =SUM(O14:AO14) -> 840374.49 | AR14: =+K14-AQ14 -> 0 | AT14: =+F14*K14 -> 14580497 | AV14: =SUM(W14:AO14) -> 515241.84 | AW14: =+L14-AV14 -> 0 | BA14: =SUM(O14:U14) -> 325132.65
A15: P | N15: Porcentaje | U15: =+U14/K14 -> 0.3869 | W15: =+W14/$K14 -> 0.0297 | X15: =+X14/$K14 -> 0.0297 | Y15: =+Y14/$K14 -> 0.0297 | Z15: =+Z14/$K14 -> 0.0297 | AA15: =+AA14/$K14 -> 0.0297 | AB15: =+AB14/$K14 -> 0.0297 | AC15: =+AC14/$K14 -> 0.0297 | AD15: =+AD14/$K14 -> 0.0595 | ... AK15: =+AK14/$K14 -> 0 | AQ15: =SUM(O15:AO15) -> 0.9996
A16: C | BA16: =SUM(O16:U16) -> 0
A17: 1 | G17: =ROUND(G14*$F14,2) -> 13141532 | H17: =ROUND(H14*$F14,2) -> 14580497 | I17: =ROUND(I14*$F14,2) -> 5641051.5 | J17: =J14*$F14 -> 0 | K17: =ROUND(K14*$F14,2) -> 14580497 | L17: =ROUND(L14*$F14,2) -> 8939445.9 | N17: Monto | U17: =U14*$F14+0.01 -> 5641051.5 | W17: =W14*$F14 -> 433750 | X17: =X14*$F14 -> 433750 | Y17: =Y14*$F14 -> 433750 | Z17: =Z14*$F14 -> 433750 | AA17: =AA14*$F14 -> 433750 | AB17: =AB14*$F14 -> 433750 | AC17: =AC14*$F14 -> 433750 | AD17: =AD14*$F14 -> 867500 | ... AH17: =AH14*$F14 -> 1041000 | AI17: =AI14*$F14-0.01 -> 784945.91 | AJ17: =AJ14*$F14 -> 0 | AK17: =AK14*$F14 -> 0 | AQ17: =SUM(O17:AO17) -> 14580497 | AR17: =+K17-AQ17 -> 0
C18: 3 | D18: 1.3 Excavación en Fango Distancia < 300 m | E18: [ m³ ] | F18: 26.97 | G18: 22724 | H18: 22724 | I18: 0 | J18: -13395.106 | K18: =H18+J18 -> 9328.8936 | L18: =+H18-I18+J18 -> 9328.89 | N18: Cantidad | U18: =+I18 -> 0 | AE18: =+AE19*$K18 -> 1865.78 | AF18: =+AF19*$K18 -> 1865.78 | AG18: =+AG19*$K18 -> 1865.78 | AH18: =+AH19*$K18 -> 1865.78 | AI18: 1865.77 | AJ18: =+AJ19*$K18 -> 0 | AQ18: =SUM(O18:AO18) -> 9328.89 | AR18: =+K18-AQ18 -> 0 | AT18: =+F18*K18 -> 251600.26 | AV18: =SUM(W18:AO18) -> 9328.89 | AW18: =+L18-AV18 -> 0 | BA18: =SUM(O18:U18) -> 0
A19: P | N19: Porcentaje | U19: =+U18/K18 -> 0 | AE19: 0.2 | AF19: 0.2 | AG19: 0.2 | AH19: 0.2 | AI19: 0.2 | AQ19: =SUM(O19:AO19) -> 1 | BA19: =SUM(O19:U19) -> 0
A20: C | BA20: =SUM(O20:U20) -> 0
A21: 1 | G21: =ROUND(G18*$F18,2) -> 612866.28 | H21: =ROUND(H18*$F18,2) -> 612866.28 | I21: =ROUND(I18*$F18,2) -> 0 | J21: =J18*$F18 -> -361266.02 | K21: =ROUND(K18*$F18,4) -> 251600.26 | L21: =ROUND(L18*$F18,2) -> 251600.16 | N21: Monto | U21: =U18*$F18 -> 0 | AE21: =AE18*$F18 -> 50320.087 | AF21: =AF18*$F18 -> 50320.087 | AG21: =AG18*$F18 -> 50320.087 | AH21: =AH18*$F18 -> 50320.087 | AI21: =AI18*$F18+0.09 -> 50319.907 | AJ21: =AJ18*$F18 -> 0 | AQ21: =SUM(O21:AO21) -> 251600.26 | AR21: =+K21-AQ21 -> 0 | BA21: =SUM(O21:U21) -> 0
C22: 4 | D22: 1.4 Terraplén con Material de Préstamo | E22: [ m³ ] | F22: 21.91 | G22: 201199 | H22: 203324.05 | I22: 106111.67 | K22: =H22+J22 -> 203324.05 | L22: =+H22-I22+J22 -> 97212.38 | N22: Cantidad | U22: =+I22 -> 106111.67 | W22: 1500 | X22: 1500 | Y22: 1500 | Z22: 1500 | AA22: 5000 | AB22: 5000 | AC22: 5000 | AD22: 10000 | AE22: 10000 | AF22: 10000 | AG22: 15000 | AH22: 15000 | AI22: 16212.38 | AQ22: =SUM(O22:AO22) -> 203324.05 | AR22: =+K22-AQ22 -> 0 | AT22: =+F22*K22 -> 4454829.9 | AV22: =SUM(W22:AO22) -> 97212.38 | AW22: =+L22-AV22 -> 0 | BA22: =SUM(O22:U22) -> 106111.67
A23: P | N23: Porcentaje | U23: =+U22/K22 -> 0.5219 | W23: =+W22/$K22 -> 0.0074 | X23: =+X22/$K22 -> 0.0074 | Y23: =+Y22/$K22 -> 0.0074 | Z23: =+Z22/$K22 -> 0.0074 | AA23: =+AA22/$K22 -> 0.0246 | AB23: =+AB22/$K22 -> 0.0246 | AC23: =+AC22/$K22 -> 0.0246 | AD23: =+AD22/$K22 -> 0.0492 | ... AK23: =+AK22/$K22 -> 0 | AQ23: =SUM(O23:AO23) -> 1.0002
A24: C | BA24: =SUM(O24:U24) -> 0
A25: 1 | G25: =ROUND(G22*$F22,2) -> 4408270.1 | H25: =ROUND(H22*$F22,2) -> 4454829.9 | I25: =ROUND(I22*$F22,2) -> 2324906.7 | J25: =J22*$F22 -> 0 | K25: =ROUND(K22*$F22,2) -> 4454829.9 | L25: =ROUND(L22*$F22,2) -> 2129923.2 | N25: Monto | U25: =U22*$F22 -> 2324906.7 | W25: =W22*$F22 -> 32865 | X25: =X22*$F22 -> 32865 | Y25: =Y22*$F22 -> 32865 | Z25: =Z22*$F22 -> 32865 | AA25: =AA22*$F22 -> 109550 | AB25: =AB22*$F22 -> 109550 | AC25: =AC22*$F22 -> 109550 | AD25: =AD22*$F22 -> 219100 | ... AK25: =AK22*$F22 -> 0 | AQ25: =SUM(O25:AO25) -> 4454829.9 | AR25: =+K25-AQ25 -> 0
C26: 5 | D26: 1.5 Terraplén con Material de Corte | E26: [ m³ ] | F26: 11.19 | G26: 299800 | H26: 323252 | I26: 47007.92 | K26: =H26+J26 -> 323252 | L26: =+H26-I26+J26 -> 276244.08 | N26: Cantidad | U26: =+I26 -> 47007.92 | W26: 15000 | X26: 20000 | Y26: 20000 | Z26: 25000 | AA26: 15000 | AB26: 25000 | AC26: 25000 | AD26: 25000 | AE26: 35000 | AF26: 35000 | AG26: 36244.08 | AQ26: =SUM(O26:AO26) -> 323252 | AR26: =+K26-AQ26 -> 0 | AT26: =+F26*K26 -> 3617189.9 | AV26: =SUM(W26:AO26) -> 276244.08 | AW26: =+L26-AV26 -> 0 | BA26: =SUM(O26:U26) -> 47007.92
A27: P | N27: Porcentaje | U27: =+U26/K26 -> 0.1454 | W27: =+W26/$K26 -> 0.0464 | X27: =+X26/$K26 -> 0.0619 | Y27: =+Y26/$K26 -> 0.0619 | Z27: =+Z26/$K26 -> 0.0773 | AA27: =+AA26/$K26 -> 0.0464 | AB27: =+AB26/$K26 -> 0.0773 | AC27: =+AC26/$K26 -> 0.0773 | AD27: =+AD26/$K26 -> 0.0773 | ... AI27: =+AI26/$K26 -> 0 | AQ27: =SUM(O27:AO27) -> 0.9999
A28: C | BA28: =SUM(O28:U28) -> 0
A29: 1 | G29: =ROUND(G26*$F26,2) -> 3354762 | H29: =ROUND(H26*$F26,2) -> 3617189.9 | I29: =ROUND(I26*$F26,2) -> 526018.62 | J29: =J26*$F26 -> 0 | K29: =ROUND(K26*$F26,2) -> 3617189.9 | L29: =ROUND(L26*$F26,2) -> 3091171.3 | N29: Monto | U29: =U26*$F26+0.02 -> 526018.64 | W29: =W26*$F26 -> 167850 | X29: =X26*$F26 -> 223800 | Y29: =Y26*$F26 -> 223800 | Z29: =Z26*$F26 -> 279750 | AA29: =AA26*$F26 -> 167850 | AB29: =AB26*$F26 -> 279750 | AC29: =AC26*$F26 -> 279750 | AD29: =AD26*$F26 -> 279750 | ... AF29: =AF26*$F26 -> 391650 | AG29: =AG26*$F26-0.02 -> 405571.24 | AH29: =AH26*$F26 -> 0 | AI29: =AI26*$F26 -> 0 | AQ29: =SUM(O29:AO29) -> 3617189.9 | AR29: =+K29-AQ29 -> 0
C30: 6 | D30: 1.6 Relleno Compactado en Áreas de Depósito | E30: [ m³ ] | F30: 4.05 | G30: 409401 | H30: 471920.81 | I30: 165193.72 | K30: =H30+J30 -> 471920.81 | L30: =+H30-I30+J30 -> 306727.09 | N30: Cantidad | U30: =+I30 -> 165193.72 | W30: 10000 | X30: 15000 | Y30: 15000 | Z30: 15000 | AA30: 15000 | AB30: 15000 | AC30: 15000 | AD30: 35000 | AE30: 35000 | AF30: 35000 | AG30: 35000 | AH30: 35000 | AI30: 31727.09 | AQ30: =SUM(O30:AO30) -> 471920.81 | AR30: =+K30-AQ30 -> 0 | AT30: =+F30*K30 -> 1911279.3 | AV30: =SUM(W30:AO30) -> 306727.09 | AW30: =+L30-AV30 -> 0 | BA30: =SUM(O30:U30) -> 165193.72
A31: P | N31: Porcentaje | U31: =+U30/K30 -> 0.35 | W31: =+W30/$K30 -> 0.0212 | X31: =+X30/$K30 -> 0.0318 | Y31: =+Y30/$K30 -> 0.0318 | Z31: =+Z30/$K30 -> 0.0318 | AA31: =+AA30/$K30 -> 0.0318 | AB31: =+AB30/$K30 -> 0.0318 | AC31: =+AC30/$K30 -> 0.0318 | AD31: =+AD30/$K30 -> 0.0742 | ... AK31: =+AK30/$K30 -> 0 | AQ31: =SUM(O31:AO31) -> 1.0002
A32: C | BA32: =SUM(O32:U32) -> 0
A33: 1 | G33: =ROUND(G30*$F30,2) -> 1658074.1 | H33: =ROUND(H30*$F30,2) -> 1911279.3 | I33: =ROUND(I30*$F30,2) -> 669034.57 | J33: =J30*$F30 -> 0 | K33: =ROUND(K30*$F30,2) -> 1911279.3 | L33: =ROUND(L30*$F30,2) -> 1242244.7 | N33: Monto | U33: =U30*$F30 -> 669034.57 | W33: =W30*$F30 -> 40500 | X33: =X30*$F30 -> 60750 | Y33: =Y30*$F30 -> 60750 | Z33: =Z30*$F30 -> 60750 | AA33: =AA30*$F30 -> 60750 | AB33: =AB30*$F30 -> 60750 | AC33: =AC30*$F30 -> 60750 | AD33: =AD30*$F30 -> 141750 | ... AK33: =AK30*$F30 -> 0 | AQ33: =SUM(O33:AO33) -> 1911279.3 | AR33: =+K33-AQ33 -> 0
C34: 7 | D34: 1.7 Remoción de Derrumbes | E34: [ m³ ] | F34: 19.71 | G34: 75744 | H34: 75744 | I34: 9913.26 | K34: =H34+J34 -> 75744 | L34: =+H34-I34+J34 -> 65830.74 | N34: Cantidad | U34: =+I34 -> 9913.26 | AB34: 5000 | AC34: 10000 | AD34: 10000 | AE34: 15000 | AF34: 15000 | AG34: 6000 | AH34: 4830.74 | AQ34: =SUM(O34:AO34) -> 75744 | AR34: =+K34-AQ34 -> 0 | AT34: =+F34*K34 -> 1492914.2 | AV34: =SUM(W34:AO34) -> 65830.74 | AW34: =+L34-AV34 -> 0 | BA34: =SUM(O34:U34) -> 9913.26
A35: P | N35: Porcentaje | U35: =+U34/K34 -> 0.1309 | AB35: =+AB34/$K34 -> 0.066 | AC35: =+AC34/$K34 -> 0.132 | AD35: =+AD34/$K34 -> 0.132 | AE35: =+AE34/$K34 -> 0.198 | AF35: =+AF34/$K34 -> 0.198 | AG35: =+AG34/$K34 -> 0.0792 | AH35: =+AH34/$K34 -> 0.0638 | AK35: =+AK34/$K34 -> 0 | AQ35: =SUM(O35:AO35) -> 0.9999
A36: C | BA36: =SUM(O36:U36) -> 0
A37: 1 | G37: =ROUND(G34*$F34,2) -> 1492914.2 | H37: =ROUND(H34*$F34,2) -> 1492914.2 | I37: =ROUND(I34*$F34,2) -> 195390.35 | J37: =J34*$F34 -> 0 | K37: =ROUND(K34*$F34,2) -> 1492914.2 | L37: =ROUND(L34*$F34,2) -> 1297523.9 | N37: Monto | U37: =U34*$F34 -> 195390.35 | AB37: =AB34*$F34 -> 98550 | AC37: =AC34*$F34 -> 197100 | AD37: =AD34*$F34 -> 197100 | AE37: =AE34*$F34 -> 295650 | AF37: =AF34*$F34 -> 295650 | AG37: =AG34*$F34 -> 118260 | AH37: =AH34*$F34 -> 95213.89 | AK37: =AK34*$F34 -> 0 | AQ37: =SUM(O37:AO37) -> 1492914.2 | AR37: =+K37-AQ37 -> 0
C38: 8 | D38: 1.8 Sobreacarreo para Distancias > 300 m | E38: [ m³-km ] | F38: 2.48 | G38: 152240 | H38: 157482.36 | I38: 9504.28 | K38: =H38+J38 -> 157482.36 | L38: =+H38-I38+J38 -> 147978.08 | N38: Cantidad | U38: =+I38 -> 9504.28 | W38: 1500 | X38: 1500 | Y38: 1500 | Z38: 1500 | AA38: 1500 | AB38: 1500 | AC38: 1500 | AD38: 23500 | AE38: 23500 | AF38: 23500 | AG38: 23500 | AH38: 23500 | AI38: 19978.08 | AQ38: =SUM(O38:AO38) -> 157482.36 | AR38: =+K38-AQ38 -> 0 | AT38: =+F38*K38 -> 390556.25 | AV38: =SUM(W38:AO38) -> 147978.08 | AW38: =+L38-AV38 -> 0 | BA38: =SUM(O38:U38) -> 9504.28
A39: P | N39: Porcentaje | U39: =+U38/K38 -> 0.0604 | W39: =+W38/$K38 -> 0.0095 | X39: =+X38/$K38 -> 0.0095 | Y39: =+Y38/$K38 -> 0.0095 | Z39: =+Z38/$K38 -> 0.0095 | AA39: =+AA38/$K38 -> 0.0095 | AB39: =+AB38/$K38 -> 0.0095 | AC39: =+AC38/$K38 -> 0.0095 | AD39: =+AD38/$K38 -> 0.1492 | ... AI39: =+AI38/$K38 -> 0.1269 | AQ39: =SUM(O39:AO39) -> 0.9998
A40: C | BA40: =SUM(O40:U40) -> 0
A41: 1 | G41: =ROUND(G38*$F38,2) -> 377555.2 | H41: =ROUND(H38*$F38,2) -> 390556.25 | I41: =ROUND(I38*$F38,2) -> 23570.61 | J41: =J38*$F38 -> 0 | K41: =ROUND(K38*$F38,2) -> 390556.25 | L41: =ROUND(L38*$F38,2) -> 366985.64 | N41: Monto | U41: =U38*$F38 -> 23570.61 | W41: =W38*$F38 -> 3720 | X41: =X38*$F38 -> 3720 | Y41: =Y38*$F38 -> 3720 | Z41: =Z38*$F38 -> 3720 | AA41: =AA38*$F38 -> 3720 | AB41: =AB38*$F38 -> 3720 | AC41: =AC38*$F38 -> 3720 | AD41: =AD38*$F38 -> 58280 | ... AI41: =AI38*$F38 -> 49545.64 | AQ41: =SUM(O41:AO41) -> 390556.25 | AR41: =+K41-AQ41 -> 0
C42: 9 | D42: 1.9 Transporte de Material de Acopios | E42: [ m³-km ] | F42: 2.22 | G42: 1647249 | H42: 1650035.6 | I42: 172514.55 | K42: =H42+J42 -> 1650035.6 | L42: =+H42-I42+J42 -> 1477521 | N42: Cantidad | U42: =+I42 -> 172514.55 | W42: 3500 | X42: 4500 | Y42: 4500 | Z42: 5000 | AA42: =+AA22*5 -> 25000 | AB42: =+AB22*5 -> 25000 | AC42: =+AC22*5 -> 25000 | AD42: 250000 | AE42: 250000 | AF42: 250000 | AG42: 266000 | AH42: 369021.03 | AJ42: =+AJ22*10 -> 0 | AK42: =+AK22*10 -> 0 | AQ42: =SUM(O42:AO42) -> 1650035.6 | AR42: =+K42-AQ42 -> 0 | AT42: =+F42*K42 -> 3663079 | AV42: =SUM(W42:AO42) -> 1477521 | AW42: =+L42-AV42 -> 0 | BA42: =SUM(O42:U42) -> 172514.55
...
