Workbook
Name TSBINDEX: Data!$A$4:$G$5

Sheet Data
A1: T&M Grain Transport Cost Index Calculations
A2: ENTER DATA IN Columns B..E, COPY G...K and Extend G...K to calculate data for current week
A3: CHANGE CELL REF for most current week and SEND A4...F4 to USDA | Q3: Used diff formula for rail index as Tariff Rate=0 as index base
A4: =(A630) -> 41843 | B4: =J630 -> 259.66443 | C4: =K630 -> 282.81498 | D4: =L630 -> 290.26329 | E4: =M630 -> 303.88889 | F4: =N630 -> 190.07156 | G4: =O630 -> 166.66667
B5: =(B630-B629)/(B629) -> -0.0064201335 | C5: =(C630-C629)/(C629) -> -0.11764706 | D5: =(D630-D629)/(D629) -> -0.068947368 | E5: =(E630-E629)/(E629) -> 0.35061728 | F5: =(F630-F629)/(F629) -> -0.011627907 | G5: =(G630-G629)/(G629) -> -0.020833333 | Y5: Monthly Averaged Tariffs with Fuel Surcharges
A6: Weekly Data | B6: Diesel | C6: Secondary | D6: Secondary | E6: Illinois | F6: Ocean | I6: Autocalculation with Copy/Paste for weekly report | Q6: Base Year=2000, Value
A7: Date | B7: Price | C7: Unit | D7: Shuttle | E7: River | F7: Gulf | G7: PNW | I7: Weekly Index | Q7: Truck | R7: Unit | S7: Shuttle | T7: Barge | U7: Gulf | V7: PNW | Y7: Unit | Z7: Shuttle
A8: 37489 | B8: 1.333 | C8: -21.5 | E8: 128 | F8: 20.13 | G8: 11.05 | I8: =A8 -> 37489 | J8: =(1+(B8-Q8)/Q8)*100 -> 89.463087 | K8: =(C8+Y8)/R8*100 -> 95.192233 | L8: =(D8+Z8)/S8*100 -> 100.26436 | M8: =(1+(E8-T8)/T8)*100 -> 71.111111 | N8: =(1+(F8-U8)/U8)*100 -> 90.026834 | O8: =(1+(G8-V8)/V8)*100 -> 78.368794 | Q8: 1.49 | R8: 1815.8526 | S8: 2338.2847 | T8: 180 | U8: 22.36 | V8: 14.1 | X8: 37489 | Y8: 1750.0506 | Z8: 2344.4663
A9: 37496 | B9: 1.37 | C9: -11.5 | E9: 128 | F9: 20.83 | G9: 11.03 | I9: 37496 | J9: =(1+(B9-Q9)/Q9)*100 -> 91.946309 | K9: =(C9+Y9)/R9*100 -> 95.742939 | L9: =(D9+Z9)/S9*100 -> 100.26436 | M9: =(1+(E9-T9)/T9)*100 -> 71.111111 | N9: =(1+(F9-U9)/U9)*100 -> 93.157424 | O9: =(1+(G9-V9)/V9)*100 -> 78.22695 | Q9: 1.49 | R9: 1815.8526 | S9: 2338.2847 | T9: 180 | U9: 22.36 | V9: 14.1 | X9: 37496 | Y9: 1750.0506 | Z9: 2344.4663
A10: 37503 | B10: 1.388 | C10: -13 | E10: 139 | F10: 22.06 | G10: 11.21 | I10: 37503 | J10: =(1+(B10-Q10)/Q10)*100 -> 93.154362 | K10: =(C10+Y10)/R10*100 -> 96.11202 | L10: =(D10+Z10)/S10*100 -> 100.82617 | M10: =(1+(E10-T10)/T10)*100 -> 77.222222 | N10: =(1+(F10-U10)/U10)*100 -> 98.658318 | O10: =(1+(G10-V10)/V10)*100 -> 79.503546 | Q10: 1.49 | R10: 1815.8526 | S10: 2338.2847 | T10: 180 | U10: 22.36 | V10: 14.1 | X10: 37503 | Y10: 1758.2526 | Z10: 2357.6029
A11: 37510 | B11: 1.396 | C11: -15 | E11: 145 | F11: 22.7 | G11: 12.16 | I11: 37510 | J11: =(1+(B11-Q11)/Q11)*100 -> 93.691275 | K11: =(C11+Y11)/R11*100 -> 96.001879 | L11: =(D11+Z11)/S11*100 -> 100.82617 | M11: =(1+(E11-T11)/T11)*100 -> 80.555556 | N11: =(1+(F11-U11)/U11)*100 -> 101.52057 | O11: =(1+(G11-V11)/V11)*100 -> 86.241135 | Q11: 1.49 | R11: 1815.8526 | S11: 2338.2847 | T11: 180 | U11: 22.36 | V11: 14.1 | X11: 37510 | Y11: 1758.2526 | Z11: 2357.6029
A12: 37517 | B12: 1.414 | C12: 14 | E12: 150 | F12: 23.1 | G12: 12.51 | I12: 37517 | J12: =(1+(B12-Q12)/Q12)*100 -> 94.899329 | K12: =(C12+Y12)/R12*100 -> 97.598925 | L12: =(D12+Z12)/S12*100 -> 100.82617 | M12: =(1+(E12-T12)/T12)*100 -> 83.333333 | N12: =(1+(F12-U12)/U12)*100 -> 103.30948 | O12: =(1+(G12-V12)/V12)*100 -> 88.723404 | Q12: 1.49 | R12: 1815.8526 | S12: 2338.2847 | T12: 180 | U12: 22.36 | V12: 14.1 | X12: 37517 | Y12: 1758.2526 | Z12: 2357.6029
A13: 37524 | B13: 1.417 | C13: 0 | E13: 157 | F13: 24.5 | G13: 12.94 | I13: 37524 | J13: =(1+(B13-Q13)/Q13)*100 -> 95.100671 | K13: =(C13+Y13)/R13*100 -> 96.827937 | L13: =(D13+Z13)/S13*100 -> 100.83147 | M13: =(1+(E13-T13)/T13)*100 -> 87.222222 | N13: =(1+(F13-U13)/U13)*100 -> 109.57066 | O13: =(1+(G13-V13)/V13)*100 -> 91.77305 | Q13: 1.49 | R13: 1815.8526 | S13: 2338.2847 | T13: 180 | U13: 22.36 | V13: 14.1 | X13: 37524 | Y13: 1758.2526 | Z13: 2357.7269
A14: 37531 | B14: 1.438 | C14: 0 | E14: 178 | F14: 24.62 | G14: 13.27 | I14: 37531 | J14: =(1+(B14-Q14)/Q14)*100 -> 96.510067 | K14: =(C14+Y14)/R14*100 -> 98.922759 | L14: =(D14+Z14)/S14*100 -> 102.6164 | M14: =(1+(E14-T14)/T14)*100 -> 98.888889 | N14: =(1+(F14-U14)/U14)*100 -> 110.10733 | O14: =(1+(G14-V14)/V14)*100 -> 94.113475 | Q14: 1.49 | R14: 1815.8526 | S14: 2338.2847 | T14: 180 | U14: 22.36 | V14: 14.1 | X14: 37531 | Y14: 1796.2915 | Z14: 2399.4636
A15: 37538 | B15: 1.46 | C15: 0 | E15: 200 | F15: 24.12 | G15: 13.81 | I15: 37538 | J15: =(1+(B15-Q15)/Q15)*100 -> 97.986577 | K15: =(C15+Y15)/R15*100 -> 98.922759 | L15: =(D15+Z15)/S15*100 -> 102.6164 | M15: =(1+(E15-T15)/T15)*100 -> 111.11111 | N15: =(1+(F15-U15)/U15)*100 -> 107.8712 | O15: =(1+(G15-V15)/V15)*100 -> 97.943262 | Q15: 1.49 | R15: 1815.8526 | S15: 2338.2847 | T15: 180 | U15: 22.36 | V15: 14.1 | X15: 37538 | Y15: 1796.2915 | Z15: 2399.4636
A16: 37545 | B16: 1.46 | C16: 0 | E16: 206 | F16: 24.3 | G16: 13.3 | I16: 37545 | J16: =(1+(B16-Q16)/Q16)*100 -> 97.986577 | K16: =(C16+Y16)/R16*100 -> 98.922759 | L16: =(D16+Z16)/S16*100 -> 102.6164 | M16: =(1+(E16-T16)/T16)*100 -> 114.44444 | N16: =(1+(F16-U16)/U16)*100 -> 108.67621 | O16: =(1+(G16-V16)/V16)*100 -> 94.326241 | Q16: 1.49 | R16: 1815.8526 | S16: 2338.2847 | T16: 180 | U16: 22.36 | V16: 14.1 | X16: 37545 | Y16: 1796.2915 | Z16: 2399.4636
A17: 37552 | B17: 1.47 | C17: 0 | E17: 209 | F17: 24.75 | G17: 13.59 | I17: 37552 | J17: =(1+(B17-Q17)/Q17)*100 -> 98.657718 | K17: =(C17+Y17)/R17*100 -> 98.922759 | L17: =(D17+Z17)/S17*100 -> 102.6164 | M17: =(1+(E17-T17)/T17)*100 -> 116.11111 | N17: =(1+(F17-U17)/U17)*100 -> 110.68873 | O17: =(1+(G17-V17)/V17)*100 -> 96.382979 | Q17: 1.49 | R17: 1815.8526 | S17: 2338.2847 | T17: 180 | U17: 22.36 | V17: 14.1 | X17: 37552 | Y17: 1796.2915 | Z17: 2399.4636
A18: 37559 | B18: 1.46 | C18: 16 | E18: 209 | F18: 24.96 | G18: 13.97 | I18: 37559 | J18: =(1+(B18-Q18)/Q18)*100 -> 97.986577 | K18: =(C18+Y18)/R18*100 -> 99.784907 | L18: =(D18+Z18)/S18*100 -> 102.61046 | M18: =(1+(E18-T18)/T18)*100 -> 116.11111 | N18: =(1+(F18-U18)/U18)*100 -> 111.62791 | O18: =(1+(G18-V18)/V18)*100 -> 99.078014 | Q18: 1.49 | R18: 1815.8526 | S18: 2338.2847 | T18: 180 | U18: 22.36 | V18: 14.1 | X18: 37559 | Y18: 1795.9468 | Z18: 2399.3247
A19: 37566 | B19: 1.44 | C19: 19 | E19: 217 | F19: 25.1 | G19: 14.42 | I19: 37566 | J19: =(1+(B19-Q19)/Q19)*100 -> 96.644295 | K19: =(C19+Y19)/R19*100 -> 99.485531 | L19: =(D19+Z19)/S19*100 -> 104.52166 | M19: =(1+(E19-T19)/T19)*100 -> 120.55556 | N19: =(1+(F19-U19)/U19)*100 -> 112.25403 | O19: =(1+(G19-V19)/V19)*100 -> 102.2695 | Q19: 1.49 | R19: 1815.8526 | S19: 2338.2847 | T19: 180 | U19: 22.36 | V19: 14.1 | X19: 37566 | Y19: 1787.5106 | Z19: 2444.0141
A20: 37573 | B20: 1.43 | C20: 8 | E20: 223 | F20: 24.81 | G20: 14.8 | I20: 37573 | J20: =(1+(B20-Q20)/Q20)*100 -> 95.973154 | K20: =(C20+Y20)/R20*100 -> 98.879755 | L20: =(D20+Z20)/S20*100 -> 104.52166 | M20: =(1+(E20-T20)/T20)*100 -> 123.88889 | N20: =(1+(F20-U20)/U20)*100 -> 110.95707 | O20: =(1+(G20-V20)/V20)*100 -> 104.96454 | Q20: 1.49 | R20: 1815.8526 | S20: 2338.2847 | T20: 180 | U20: 22.36 | V20: 14.1 | X20: 37573 | Y20: 1787.5106 | Z20: 2444.0141
... A78: 37979 | B78: 1.5 | C78: 92 | E78: 215 | F78: 51.36 | G78: 41.56 | I78: 37979 | J78: =(1+(B78-Q78)/Q78)*100 -> 100.67114 | K78: =(C78+Y78)/R78*100 -> 109.51586 | L78: =(D78+Z78)/S78*100 -> 103.51552 | M78: =(1+(E78-T78)/T78)*100 -> 119.44444 | N78: =(1+(F78-U78)/U78)*100 -> 229.69589 | O78: =(1+(G78-V78)/V78)*100 -> 294.75177 | Q78: 1.49 | R78: 1815.8526 | S78: 2338.2847 | T78: 180 | U78: 22.36 | V78: 14.1 | X78: 37979 | Y78: 1896.6466 | Z78: 2420.4876
A79: 37986 | B79: 1.502 | C79: 80.5 | E79: 201 | F79: n/a | G79: n/a | I79: 37986 | J79: =(1+(B79-Q79)/Q79)*100 -> 100.80537 | K79: =(C79+Y79)/R79*100 -> 108.85874 | L79: =(D79+Z79)/S79*100 -> 103.55688 | M79: =(1+(E79-T79)/T79)*100 -> 111.66667 | N79: =(1+(F79-U79)/U79)*100 -> 0 | O79: =(1+(G79-V79)/V79)*100 -> 0 | Q79: 1.49 | R79: 1815.8526 | S79: 2338.2847 | T79: 180 | U79: 22.36 | V79: 14.1 | X79: 37986 | Y79: 1896.2142 | Z79: 2421.4546
A80: 37993 | B80: 1.5 | C80: 81.5 | E80: 200 | F80: 51.63 | G80: 41.45 | I80: 37993 | J80: =(1+(B80-Q80)/Q80)*100 -> 100.67114 | K80: =(C80+Y80)/R80*100 -> 107.84587 | L80: =(D80+Z80)/S80*100 -> 105.2118 | M80: =(1+(E80-T80)/T80)*100 -> 111.11111 | N80: =(1+(F80-U80)/U80)*100 -> 230.9034 | O80: =(1+(G80-V80)/V80)*100 -> 293.97163 | Q80: 1.49 | R80: 1815.8526 | S80: 2338.2847 | T80: 180 | U80: 22.36 | V80: 14.1 | X80: 37993 | Y80: 1876.8221 | Z80: 2460.1513
A81: 38000 | B81: 1.58 | C81: 32.5 | E81: 200 | F81: 58.17 | G81: 45.14 | I81: 38000 | J81: =(1+(B81-Q81)/Q81)*100 -> 106.04027 | K81: =(C81+Y81)/R81*100 -> 105.14742 | L81: =(D81+Z81)/S81*100 -> 105.2118 | M81: =(1+(E81-T81)/T81)*100 -> 111.11111 | N81: =(1+(F81-U81)/U81)*100 -> 260.15206 | O81: =(1+(G81-V81)/V81)*100 -> 320.14184 | Q81: 1.49 | R81: 1815.8526 | S81: 2338.2847 | T81: 180 | U81: 22.36 | V81: 14.1 | X81: 38000 | Y81: 1876.8221 | Z81: 2460.1513
A82: 38007 | B82: 1.56 | C82: 132 | E82: 190 | F82: 59.08 | G82: 43.65 | I82: 38007 | J82: =(1+(B82-Q82)/Q82)*100 -> 104.69799 | K82: =(C82+Y82)/R82*100 -> 110.62694 | L82: =(D82+Z82)/S82*100 -> 105.2118 | M82: =(1+(E82-T82)/T82)*100 -> 105.55556 | N82: =(1+(F82-U82)/U82)*100 -> 264.22182 | O82: =(1+(G82-V82)/V82)*100 -> 309.57447 | Q82: 1.49 | R82: 1815.8526 | S82: 2338.2847 | T82: 180 | U82: 22.36 | V82: 14.1 | X82: 38007 | Y82: 1876.8221 | Z82: 2460.1513
A83: 38014 | B83: 1.58 | C83: 70.5 | E83: 208 | F83: 62.23 | G83: 43.89 | I83: 38014 | J83: =(1+(B83-Q83)/Q83)*100 -> 106.04027 | K83: =(C83+Y83)/R83*100 -> 107.30591 | L83: =(D83+Z83)/S83*100 -> 105.20994 | M83: =(1+(E83-T83)/T83)*100 -> 115.55556 | N83: =(1+(F83-U83)/U83)*100 -> 278.30948 | O83: =(1+(G83-V83)/V83)*100 -> 311.2766 | Q83: 1.49 | R83: 1815.8526 | S83: 2338.2847 | T83: 180 | U83: 22.36 | V83: 14.1 | X83: 38014 | Y83: 1878.0171 | Z83: 2460.1078
A84: 38021 | B84: 1.58 | C84: 137.5 | E84: 215 | F84: 71.47 | G84: 45.27 | I84: 38021 | J84: =(1+(B84-Q84)/Q84)*100 -> 106.04027 | K84: =(C84+Y84)/R84*100 -> 113.72068 | L84: =(D84+Z84)/S84*100 -> 105.1229 | M84: =(1+(E84-T84)/T84)*100 -> 119.44444 | N84: =(1+(F84-U84)/U84)*100 -> 319.63327 | O84: =(1+(G84-V84)/V84)*100 -> 321.06383 | Q84: 1.49 | R84: 1815.8526 | S84: 2338.2847 | T84: 180 | U84: 22.36 | V84: 14.1 | X84: 38021 | Y84: 1927.4999 | Z84: 2458.0728
A85: 38028 | B85: 1.57 | C85: 200 | E85: 196 | F85: 69.21 | G85: 43.93 | I85: 38028 | J85: =(1+(B85-Q85)/Q85)*100 -> 105.36913 | K85: =(C85+Y85)/R85*100 -> 117.16259 | L85: =(D85+Z85)/S85*100 -> 105.1229 | M85: =(1+(E85-T85)/T85)*100 -> 108.88889 | N85: =(1+(F85-U85)/U85)*100 -> 309.52594 | O85: =(1+(G85-V85)/V85)*100 -> 311.56028 | Q85: 1.49 | R85: 1815.8526 | S85: 2338.2847 | T85: 180 | U85: 22.36 | V85: 14.1 | X85: 38028 | Y85: 1927.4999 | Z85: 2458.0728
A86: 38035 | B86: 1.58 | C86: 218 | E86: 181 | F86: 68.83 | G86: 43.74 | I86: 38035 | J86: =(1+(B86-Q86)/Q86)*100 -> 106.04027 | K86: =(C86+Y86)/R86*100 -> 118.15386 | L86: =(D86+Z86)/S86*100 -> 105.1229 | M86: =(1+(E86-T86)/T86)*100 -> 100.55556 | N86: =(1+(F86-U86)/U86)*100 -> 307.82648 | O86: =(1+(G86-V86)/V86)*100 -> 310.21277 | Q86: 1.49 | R86: 1815.8526 | S86: 2338.2847 | T86: 180 | U86: 22.36 | V86: 14.1 | X86: 38035 | Y86: 1927.4999 | Z86: 2458.0728
A87: 38042 | B87: 1.6 | C87: 105.5 | E87: 158 | F87: 73.01 | G87: 44.76 | I87: 38042 | J87: =(1+(B87-Q87)/Q87)*100 -> 107.38255 | K87: =(C87+Y87)/R87*100 -> 111.94872 | L87: =(D87+Z87)/S87*100 -> 105.10175 | M87: =(1+(E87-T87)/T87)*100 -> 87.777778 | N87: =(1+(F87-U87)/U87)*100 -> 326.52057 | O87: =(1+(G87-V87)/V87)*100 -> 317.44681 | Q87: 1.49 | R87: 1815.8526 | S87: 2338.2847 | T87: 180 | U87: 22.36 | V87: 14.1 | X87: 38042 | Y87: 1927.3237 | Z87: 2457.5781
A88: 38049 | B88: 1.62 | C88: 129.5 | E88: 160 | F88: 72.21 | G88: 43.76 | I88: 38049 | J88: =(1+(B88-Q88)/Q88)*100 -> 108.72483 | K88: =(C88+Y88)/R88*100 -> 113.80142 | L88: =(D88+Z88)/S88*100 -> 105.35879 | M88: =(1+(E88-T88)/T88)*100 -> 88.888889 | N88: =(1+(F88-U88)/U88)*100 -> 322.94275 | O88: =(1+(G88-V88)/V88)*100 -> 310.35461 | Q88: 1.49 | R88: 1815.8526 | S88: 2338.2847 | T88: 180 | U88: 22.36 | V88: 14.1 | X88: 38049 | Y88: 1936.966 | Z88: 2463.5884
A89: 38056 | B89: 1.63 | C89: 153.5 | E89: 149 | F89: 73.11 | G89: 44.93 | I89: 38056 | J89: =(1+(B89-Q89)/Q89)*100 -> 109.39597 | K89: =(C89+Y89)/R89*100 -> 115.12311 | L89: =(D89+Z89)/S89*100 -> 105.35879 | M89: =(1+(E89-T89)/T89)*100 -> 82.777778 | N89: =(1+(F89-U89)/U89)*100 -> 326.9678 | O89: =(1+(G89-V89)/V89)*100 -> 318.65248 | Q89: 1.49 | R89: 1815.8526 | S89: 2338.2847 | T89: 180 | U89: 22.36 | V89: 14.1 | X89: 38056 | Y89: 1936.966 | Z89: 2463.5884
A90: 38063 | B90: 1.617 | C90: 125 | E90: 151 | F90: 73.261 | G90: 45.386 | I90: 38063 | J90: =(1+(B90-Q90)/Q90)*100 -> 108.52349 | K90: =(C90+Y90)/R90*100 -> 113.5536 | L90: =(D90+Z90)/S90*100 -> 105.35879 | M90: =(1+(E90-T90)/T90)*100 -> 83.888889 | N90: =(1+(F90-U90)/U90)*100 -> 327.64311 | O90: =(1+(G90-V90)/V90)*100 -> 321.88652 | Q90: 1.49 | R90: 1815.8526 | S90: 2338.2847 | T90: 180 | U90: 22.36 | V90: 14.1 | X90: 38063 | Y90: 1936.966 | Z90: 2463.5884
A91: 38070 | B91: 1.64 | C91: 90 | E91: 143 | F91: 73.03 | G91: 44.01 | I91: 38070 | J91: =(1+(B91-Q91)/Q91)*100 -> 110.06711 | K91: =(C91+Y91)/R91*100 -> 111.62613 | L91: =(D91+Z91)/S91*100 -> 105.35879 | M91: =(1+(E91-T91)/T91)*100 -> 79.444444 | N91: =(1+(F91-U91)/U91)*100 -> 326.61002 | O91: =(1+(G91-V91)/V91)*100 -> 312.12766 | Q91: 1.49 | R91: 1815.8526 | S91: 2338.2847 | T91: 180 | U91: 22.36 | V91: 14.1 | X91: 38070 | Y91: 1936.966 | Z91: 2463.5884
... A130: 38343 | B130: 1.984 | C130: 181 | E130: 345.8 | F130: 60.731 | G130: 39.558 | I130: 38343 | J130: =(1+(B130-Q130)/Q130)*100 -> 133.15436 | K130: =(C130+Y130)/R130*100 -> 129.89032 | L130: =(D130+Z130)/S130*100 -> 124.44641 | M130: =(1+(E130-T130)/T130)*100 -> 192.11111 | N130: =(1+(F130-U130)/U130)*100 -> 271.60555 | O130: =(1+(G130-V130)/V130)*100 -> 280.55319 | Q130: 1.49 | R130: 1815.8526 | S130: 2338.2847 | T130: 180 | U130: 22.36 | V130: 14.1 | X130: 38343 | Y130: 2177.6167 | Z130: 2909.9113
A131: 38350 | B131: 1.987 | C131: 178.5 | E131: 300 | F131: n/a | G131: n/a | I131: 38350 | J131: =(1+(B131-Q131)/Q131)*100 -> 133.3557 | K131: =(C131+Y131)/R131*100 -> 129.76506 | L131: =(D131+Z131)/S131*100 -> 124.30286 | M131: =(1+(E131-T131)/T131)*100 -> 166.66667 | N131: n/a | O131: n/a | Q131: 1.49 | R131: 1815.8526 | S131: 2338.2847 | T131: 180 | U131: 22.36 | V131: 14.1 | X131: 38350 | Y131: 2177.8421 | Z131: 2906.5547
A132: 38357 | B132: 1.957 | C132: 169 | E132: 261 | F132: 58.275 | G132: 36.45 | I132: 38357 | J132: =(1+(B132-Q132)/Q132)*100 -> 131.34228 | K132: =(C132+Y132)/R132*100 -> 128.8763 | L132: =(D132+Z132)/S132*100 -> 121.99287 | M132: =(1+(E132-T132)/T132)*100 -> 145 | N132: =(1+(F132-U132)/U132)*100 -> 260.62165 | O132: =(1+(G132-V132)/V132)*100 -> 258.51064 | Q132: 1.49 | R132: 1815.8526 | S132: 2338.2847 | T132: 180 | U132: 22.36 | V132: 14.1 | X132: 38357 | Y132: 2171.2036 | Z132: 2852.5407
A133: 38364 | B133: 1.934 | C133: 169 | E133: 324 | F133: 62.264 | G133: 39.121 | I133: 38364 | J133: =(1+(B133-Q133)/Q133)*100 -> 129.79866 | K133: =(C133+Y133)/R133*100 -> 128.8763 | L133: =(D133+Z133)/S133*100 -> 121.99287 | M133: =(1+(E133-T133)/T133)*100 -> 180 | N133: =(1+(F133-U133)/U133)*100 -> 278.46154 | O133: =(1+(G133-V133)/V133)*100 -> 277.4539 | Q133: 1.49 | R133: 1815.8526 | S133: 2338.2847 | T133: 180 | U133: 22.36 | V133: 14.1 | X133: 38364 | Y133: 2171.2036 | Z133: 2852.5407
A134: 38371 | B134: 1.952 | C134: 187 | E134: 361 | F134: 60.171 | G134: 36.896 | I134: 38371 | J134: =(1+(B134-Q134)/Q134)*100 -> 131.00671 | K134: =(C134+Y134)/R134*100 -> 129.86757 | L134: =(D134+Z134)/S134*100 -> 121.99287 | M134: =(1+(E134-T134)/T134)*100 -> 200.55556 | N134: =(1+(F134-U134)/U134)*100 -> 269.10107 | O134: =(1+(G134-V134)/V134)*100 -> 261.67376 | Q134: 1.49 | R134: 1815.8526 | S134: 2338.2847 | T134: 180 | U134: 22.36 | V134: 14.1 | X134: 38371 | Y134: 2171.2036 | Z134: 2852.5407
A135: 38378 | B135: 1.959 | C135: 130 | E135: 292 | F135: 58.818 | G135: 34.179 | I135: 38378 | J135: =(1+(B135-Q135)/Q135)*100 -> 131.47651 | K135: =(C135+Y135)/R135*100 -> 126.49493 | L135: =(D135+Z135)/S135*100 -> 122.78582 | M135: =(1+(E135-T135)/T135)*100 -> 162.22222 | N135: =(1+(F135-U135)/U135)*100 -> 263.05009 | O135: =(1+(G135-V135)/V135)*100 -> 242.40426 | Q135: 1.49 | R135: 1815.8526 | S135: 2338.2847 | T135: 180 | U135: 22.36 | V135: 14.1 | X135: 38378 | Y135: 2166.9614 | Z135: 2871.082
...

Sheet New Table 1_Inde
B1: Table 1
B2: Grain Transport Cost Indicators1
C3: Truck | D3: Rail | F3: Barge | G3: Ocean
B4: Week ending | D4: Unit Train | E4: Shuttle | G4: Gulf | H4: Pacific
B5: =Data!A4 -> 41843 | C5: =Data!B4 -> 259.66443 | D5: =Data!C4 -> 282.81498 | E5: =Data!D4 -> 290.26329 | F5: =Data!E4 -> 303.88889 | G5: =Data!F4 -> 190.07156 | H5: =Data!G4 -> 166.66667
C6: =Data!B5 -> -0.0064201335 | D6: =Data!C5 -> -0.11764706 | F6: =Data!E5 -> 0.35061728 | G6: =Data!F5 -> -0.011627907 | H6: =Data!G5 -> -0.020833333
B7: =Data!A629 -> 41836 | C7: =Data!J629 -> 261.34228 | D7: =Data!K629 -> 288.32203 | E7: =Data!L629 -> 295.86569 | F7: =Data!M629 -> 225 | G7: =Data!N629 -> 192.30769 | H7: =Data!O629 -> 170.21277
B8: 1Indicator: Base year 2000 = 100; Weekly updates include truck = diesel ($/gallon); rail = near-month secondary rail market bid and monthly tariff rate with fuel
B9: surcharge ($/car); barge = Illinois River barge rate (index = percent of tariff rate); and ocean = routes to Japan ($/metric ton)
B11: Source: Transportation & Marketing Programs/AMS/USDA
