Workbook

Sheet Index & Totals
D1: Family Day Care Home Budget Worksheet
D2: Fiscal Year:
B3: Sponsor Name:
B4: Sponsor ID: | C4: 100000___________
B5: Fiscal Year:
B6: Do Not Enter values in any field that is shaded Yellow. These fields are calculated based on detailed entries. Only make entries to the tabbed worksheets. Be sure to remove any sample cost items.
B7: FDCH Detail Budget Worsheet Summary - to be transcribed into CLiCS
B9: Salaries | C9: =Salaries!N19 -> 0
B10: Benefits | C10: =Benefits!L33 -> 0
B11: Supplies | C11: =Supplies!H23 -> 0
B12: Printing | C12: =Printing!G22 -> 0
B13: Equipment | C13: =Equipment!F25 -> 0
B14: Depreciation | C14: =Depreciation!I23 -> 0
B15: Staff Training | C15: ='Staff Training'!N19 -> 0
B16: Provider Training | C16: ='Provider Training'!N18 -> 0
B17: Contracted Services | C17: ='Contracted Services'!I26 -> 0
B18: In-State Travel | C18: ='In-State Travel'!$H$24 -> 0
B19: Out state travel | C19: ='Out-State Travel'!$M$15 -> 0
B20: Occupancy | C20: =Occupancy!I30 -> 0
B21: Communications | C21: =Communications!F32 -> 0
B22: Carry Over | C22: 0
B24: CACFP Admin Costs for Reimbursement | C24: =C9+C10+C11+C12+C13+C14+C15+C16+C17+C18+C19+C20+C21 -> 0
E26: Edit check for "other funding" values
B27: Alternate Funding Source | C27: ='Alt Funding Source'!F39 -> 0 | D27: Identification of other funding sources. Please list other funding sources below: | E27: =C29-C24 -> 0
B29: GRAND Total of CACFP Administrative Budget | C29: =C27+C24 -> 0
B31: Instructions:
B32: Enter the above totals into your sponsor application in CLiCS
B33: Submit a copy of this entire budget detail worksheet electronically to FNS
B34: Budget Detail Worksheet and contracts are to be placed in section V8 of your management plan binder

Sheet Salaries
A1: SALARIES
A2: Provide information for all CACFP-related employees. If you have employees that are not paid based on a monthly salary or hourly rate, please attach additional information (i.e., dollar rate per home).
A3: For all employees, if salaries are increased since last year provide the following for each applicable employee: Date increase is effective; percentage and nature of increase.
A4: Cost of living increases in pay must be based on current, generally acepted statistical data. Provide explanation in cost allocation plan.
E6: For Salaried Employees | F6: For Hourly Employees | H6: Nature of Increase
A7: Employee Name: First and Last | B7: Position Title | C7: If position is hourly place an "X" in this box | D7: Daily work hours (include beginning & end times) | E7: Gross Monthly Rate (before deductions) | F7: Gross Hourly rate (before deductions) | G7: Annual Percentage of Increase | H7: (Cost-of-living or Merit) | I7: Total Work Hours per month | J7: Total Work Hours for CACFP per month | K7: Percent of Total Work Hours for CACFP | L7: Total Required Employer Taxes per month* | M7: Total Employer Taxes Paid Per month by CACFP. | N7: Total Annual Cost to CACFP ** *
E8: 0 | F8: 0 | G8: 0 | H8: COL | I8: 1 | J8: 0 | K8: =J8/I8 -> 0 | M8: =K8*L8 -> 0 | N8: =IF(C8="X",F8*J8*12*(1+G8)+M8,E8*K8*12*(1+G8)+M8) -> 0
E9: 0 | F9: 0 | G9: 0 | H9: Merit | I9: 1 | J9: 0 | K9: =J9/I9 -> 0 | M9: =K9*L9 -> 0 | N9: =IF(C9="X",F9*J9*12*(1+G9)+M9,E9*K9*12*(1+G9)+M9) -> 0
E10: 0 | F10: 0 | G10: 0 | I10: 1 | J10: 0 | K10: =J10/I10 -> 0 | M10: =K10*L10 -> 0 | N10: =IF(C10="X",F10*J10*12*(1+G10)+M10,E10*K10*12*(1+G10)+M10) -> 0
E11: 0 | F11: 0 | G11: 0 | I11: 1 | J11: 0 | K11: =J11/I11 -> 0 | M11: =K11*L11 -> 0 | N11: =IF(C11="X",F11*J11*12*(1+G11)+M11,E11*K11*12*(1+G11)+M11) -> 0
E12: 0 | F12: 0 | G12: 0 | I12: 1 | J12: 0 | K12: =J12/I12 -> 0 | M12: =K12*L12 -> 0 | N12: =IF(C12="X",F12*J12*12*(1+G12)+M12,E12*K12*12*(1+G12)+M12) -> 0
E13: 0 | F13: 0 | G13: 0 | I13: 1 | J13: 0 | K13: =J13/I13 -> 0 | M13: =K13*L13 -> 0 | N13: =IF(C13="X",F13*J13*12*(1+G13)+M13,E13*K13*12*(1+G13)+M13) -> 0
E14: 0 | F14: 0 | G14: 0 | I14: 1 | J14: 0 | K14: =J14/I14 -> 0 | M14: =K14*L14 -> 0 | N14: =IF(C14="X",F14*J14*12*(1+G14)+M14,E14*K14*12*(1+G14)+M14) -> 0
E15: 0 | F15: 0 | G15: 0 | I15: 1 | J15: 0 | K15: =J15/I15 -> 0 | M15: =K15*L15 -> 0 | N15: =IF(C15="X",F15*J15*12*(1+G15)+M15,E15*K15*12*(1+G15)+M15) -> 0
E16: 0 | F16: 0 | G16: 0 | I16: 1 | J16: 0 | K16: =J16/I16 -> 0 | M16: =K16*L16 -> 0 | N16: =IF(C16="X",F16*J16*12*(1+G16)+M16,E16*K16*12*(1+G16)+M16) -> 0
E17: 0 | F17: 0 | G17: 0 | I17: 1 | J17: 0 | K17: =J17/I17 -> 0 | M17: =K17*L17 -> 0 | N17: =IF(C17="X",F17*J17*12*(1+G17)+M17,E17*K17*12*(1+G17)+M17) -> 0
E18: 0 | F18: 0 | G18: 0 | I18: 1 | J18: 0 | K18: =J18/I18 -> 0 | M18: =K18*L18 -> 0 | N18: =IF(C18="X",F18*J18*12*(1+G18)+M18,E18*K18*12*(1+G18)+M18) -> 0
I19: Total CACFP Salaries | N19: =SUM(N8:N18) -> 0
A20: * Include Worker's Compensation, Unemployment Insurance, Social Security Tax and any other required tax.

Sheet Benefits
A1: BENEFITS
A2: Provide information for ALL CACFP-related employees.
B4: Health Insurance | D4: Dental Insurance | F4: Life Insurance | H4: Retirement | J4: Other: Identify
A5: 1 | B5: 2 | C5: 3 | D5: 4 | E5: 5 | F5: 6 | G5: 7 | H5: 8 | I5: 9 | J5: 10 | K5: 11 | L5: 12
A6: Employee | B6: Total | C6: Total | D6: Total | E6: Total | F6: Total | G6: Total | H6: Total | I6: Total | J6: Total | K6: Total | L6: Total Annual
A7: Name | B7: Monthly | C7: Monthly | D7: Monthly | E7: Monthly | F7: Monthly | G7: Monthly | H7: Monthly | I7: Monthly | J7: Monthly | K7: Monthly | L7: Cost to
B8: Cost | C8: Amt Paid by | D8: Cost | E8: Amt Paid by | F8: Cost | G8: Amt Paid by | H8: Cost | I8: Amt Paid by | J8: Cost | K8: Amt Paid by | L8: CACFP***
C9: CACFP* | E9: CACFP* | G9: CACFP* | I9: CACFP** | K9: CACFP*
B10: 0 | C10: 0 | D10: 0 | E10: 0 | F10: 0 | G10: 0 | H10: 0 | I10: 0 | J10: 0 | K10: 0 | L10: =C10+E10+G10+I10+K10 -> 0
L11: =C11+E11+G11+I11+K11 -> 0
L12: =C12+E12+G12+I12+K12 -> 0
L13: =C13+E13+G13+I13+K13 -> 0
L14: =C14+E14+G14+I14+K14 -> 0
L15: =C15+E15+G15+I15+K15 -> 0
L16: =C16+E16+G16+I16+K16 -> 0
L17: =C17+E17+G17+I17+K17 -> 0
L18: =C18+E18+G18+I18+K18 -> 0
L19: =C19+E19+G19+I19+K19 -> 0
L20: =C20+E20+G20+I20+K20 -> 0
L21: =C21+E21+G21+I21+K21 -> 0
L22: =C22+E22+G22+I22+K22 -> 0
... L32: =C32+E32+G32+I32+K32 -> 0
G33: Total Benefits | L33: =SUM(L10:L32) -> 0
A35: *Do not include amounts paid by employees
A36: **Attach a copy of the retirement plan. Indicate what percentage of the plan is paid by CACFP program funds

Sheet Supplies
A1: SUPPLIES
A2: List any item with a unit value of under $5,000 or a life expectancy of one year or less is considered a supply. Include paper
A3: forms, office supplies, computer software, equipment such as desks, chairs, file cabinets, fax machines, computers, copiers.
A5: Supply Item | C5: Source or Company Name | D5: Quanity of Purchase Units | E5: Cost/Unit | F5: Annual Cost of Supply | G5: % Allocated to CACFP | H5: Total Annual Cost to CACFP
E6: 0 | F6: =E6*D6 -> 0 | H6: =F6*G6 -> 0
E7: 0 | F7: =E7*D7 -> 0 | H7: =F7*G7 -> 0
E8: 0 | F8: =E8*D8 -> 0 | H8: =F8*G8 -> 0
E9: 0 | F9: =E9*D9 -> 0 | H9: =F9*G9 -> 0
E10: 0 | F10: =E10*D10 -> 0 | H10: =F10*G10 -> 0
E11: 0 | F11: =E11*D11 -> 0 | H11: =F11*G11 -> 0
E12: 0 | F12: =E12*D12 -> 0 | H12: =F12*G12 -> 0
E13: 0 | F13: =E13*D13 -> 0 | H13: =F13*G13 -> 0
E14: 0 | F14: =E14*D14 -> 0 | H14: =F14*G14 -> 0
E15: 0 | F15: =E15*D15 -> 0 | H15: =F15*G15 -> 0
E16: 0 | F16: =E16*D16 -> 0 | H16: =F16*G16 -> 0
E17: 0 | F17: =E17*D17 -> 0 | H17: =F17*G17 -> 0
E18: 0 | F18: =E18*D18 -> 0 | H18: 0
E19: 0 | F19: =E19*D19 -> 0 | H19: 0
E20: 0 | F20: =E20*D20 -> 0 | H20: 0
E21: 0 | F21: =E21*D21 -> 0 | H21: 0
E22: 0 | F22: =E22*D22 -> 0 | H22: 0
F23: Total Supplies | H23: =SUM(H6:H22) -> 0

Sheet Printing
A1: PRINTING
A2: List cost of printing services.
A3: Printing costs are services paid for printing forms, brochures, monitoring forms and newsletters.
A4: Do NOT include cost of copying (cost of copying should be listed under "Supplies")
A5: Printing Item | B5: Printing Company Name | C5: Quantity | D5: Cost/Unit | E5: Annual Cost | F5: % Allocated to CACFP | G5: Total Annual Cost to CACFP
D6: 0 | E6: =D6*C6 -> 0 | G6: =F6*E6 -> 0
D7: 0 | E7: =D7*C7 -> 0 | G7: =F7*E7 -> 0
D8: 0 | E8: =D8*C8 -> 0 | G8: =F8*E8 -> 0
D9: 0 | E9: =D9*C9 -> 0 | G9: =F9*E9 -> 0
D10: 0 | E10: =D10*C10 -> 0 | G10: =F10*E10 -> 0
D11: 0 | E11: =D11*C11 -> 0 | G11: =F11*E11 -> 0
D12: 0 | E12: =D12*C12 -> 0 | G12: =F12*E12 -> 0
D13: 0 | E13: =D13*C13 -> 0 | G13: =F13*E13 -> 0
D14: 0 | E14: =D14*C14 -> 0 | G14: =F14*E14 -> 0
D15: 0 | E15: =D15*C15 -> 0 | G15: =F15*E15 -> 0
D16: 0 | E16: =D16*C16 -> 0 | G16: =F16*E16 -> 0
D17: 0 | E17: =D17*C17 -> 0 | G17: =F17*E17 -> 0
... D21: 0 | E21: =D21*C21 -> 0 | G21: =F21*E21 -> 0
D22: Total PRINTING | G22: =SUM(G6:G21) -> 0

Sheet Equipment
A1: EQUIPMENT
A2: Purchased Equipment
A3: 1. List any equipment over $5,000 that you intend to purchase in the upcoming fiscal year and maintain documentation of three bids/quotes and justification of need for each item. If you are a private organization and plan on purchasing equipment over $100,000, additional procurement steps must be followed (see procurement worksheet in management plan binder). If you are a public organization, state threshold requirements and procedures must be followed. 2. For all items you intend to purchase later, which are not included here, please provide a written request. Certain expenditures require specific prior written approval.
A8: Durable Supplies Purchased over $5000
A9: Type of Equipment Purchased | C9: Expected Purchase Date | D9: Quanity | E9: Life Expectancy of Equipment (Years) | F9: Cost of Equipment | G9: % of cost allocated to CACFP | H9: Total Annual Cost to CACFP
F10: 0 | H10: =G10*F10 -> 0
F11: 0 | H11: =G11*F11 -> 0
F12: 0 | H12: =G12*F12 -> 0
F13: 0 | H13: =G13*F13 -> 0
F14: 0 | H14: =G14*F14 -> 0
H15: =SUM(H10:H14) -> 0
A16: Rented/Leased Equipment
A17: List all rented/leased equipment. Attach or send copies of all equipment leases.
A18: Type of Equipment Rented/Leased | C18: Estimated Total Annual Cost | E18: % Allocated to CACFP | F18: Annual Cost to CACFP
F19: =E19*C19 -> 0
F20: =E20*C20 -> 0
F21: =E21*C21 -> 0
F22: =E22*C22 -> 0
B23: Sub-Total Rented/Leased Equipment | F23: =SUM(F19:F22) -> 0
D25: Total EQUIPMENT | F25: =H15+F23 -> 0

Sheet Depreciation
A1: DEPRECIATION
A3: List all equipment that your sponsorship owns or will purchase with other funds and is not directly expensing that is considered nonexpendable property with a useful
A4: life of more than one year and an acquisition cost of $5,000 or more per unit.
A6: Complete Description of Equipment or Item to Depreciate (Specify model #) | B6: Purchase Date | C6: Cost per Item | D6: Quantity | E6: Total Cost | F6: Life Expectancy (Years) | G6: Annual Amount to Depreciate | H6: % Allocated to CACFP | I6: Total Annual Cost to CACFP
E7: =D7*C7 -> 0 | I7: =G7*H7 -> 0
E8: =D8*C8 -> 0 | G8: 0 | I8: =G8*H8 -> 0
E9: =D9*C9 -> 0 | G9: 0 | I9: =G9*H9 -> 0
E10: =D10*C10 -> 0 | G10: 0 | I10: =G10*H10 -> 0
E11: =D11*C11 -> 0 | G11: 0 | I11: =G11*H11 -> 0
E12: =D12*C12 -> 0 | G12: 0 | I12: =G12*H12 -> 0
E13: =D13*C13 -> 0 | G13: 0 | I13: =G13*H13 -> 0
E14: =D14*C14 -> 0 | G14: 0 | I14: =G14*H14 -> 0
E15: =D15*C15 -> 0 | G15: 0 | I15: =G15*H15 -> 0
E16: =D16*C16 -> 0 | G16: 0 | I16: =G16*H16 -> 0
E17: =D17*C17 -> 0 | G17: 0 | I17: =G17*H17 -> 0
E18: =D18*C18 -> 0 | G18: 0 | I18: =G18*H18 -> 0
E19: =D19*C19 -> 0 | G19: 0 | I19: =G19*H19 -> 0
... E22: =D22*C22 -> 0 | G22: 0 | I22: =G22*H22 -> 0
F23: Total Annual DEPRECIATION | I23: =SUM(I7:I22) -> 0

Sheet Staff Training
A1: STAFF TRAINING
A2: Include travel related costs for attendance at staff training as well as any costs incurred to conduct training.
A3: Attach copies of training report forms and agendas when required training is held. The records will maintained in your organization's management plan.
A4: Examples of training supplies include paper, brochures, folders, handouts, etc.
A5: Date(s) of Training | B5: Title and Description of Training Session | D5: Facility Rental | E5: Training Supplies | F5: Equipment Costs | G5: Registation Fees | H5: Milage Cost | I5: Lodging | J5: Meals | K5: Other | L5: Total Cost Staff Training | M5: % Allocated to CACFP | N5: Total Cost to CACFP
L6: =K6+J6+I6+H6+G6+F6+E6+D6 -> 0 | N6: =M6*L6 -> 0
L7: =K7+J7+I7+H7+G7+F7+E7+D7 -> 0 | N7: =M7*L7 -> 0
L8: =K8+J8+I8+H8+G8+F8+E8+D8 -> 0 | N8: =M8*L8 -> 0
L9: =K9+J9+I9+H9+G9+F9+E9+D9 -> 0 | N9: =M9*L9 -> 0
L10: =K10+J10+I10+H10+G10+F10+E10+D10 -> 0 | N10: =M10*L10 -> 0
L11: =K11+J11+I11+H11+G11+F11+E11+D11 -> 0 | N11: =M11*L11 -> 0
L12: =K12+J12+I12+H12+G12+F12+E12+D12 -> 0 | N12: =M12*L12 -> 0
L13: =K13+J13+I13+H13+G13+F13+E13+D13 -> 0 | N13: =M13*L13 -> 0
L14: =K14+J14+I14+H14+G14+F14+E14+D14 -> 0 | N14: =M14*L14 -> 0
L15: =K15+J15+I15+H15+G15+F15+E15+D15 -> 0 | N15: =M15*L15 -> 0
L16: =K16+J16+I16+H16+G16+F16+E16+D16 -> 0 | N16: =M16*L16 -> 0
L17: =K17+J17+I17+H17+G17+F17+E17+D17 -> 0 | N17: =M17*L17 -> 0
D18: =SUM(D6:D17) -> 0 | E18: =SUM(E6:E17) -> 0 | F18: =SUM(F6:F17) -> 0 | G18: =SUM(G6:G17) -> 0 | H18: =SUM(H6:H17) -> 0 | I18: =SUM(I6:I17) -> 0 | J18: =SUM(J6:J17) -> 0 | K18: =SUM(K6:K17) -> 0 | L18: =SUM(L6:L17) -> 0
J19: Total Staff Training | N19: =SUM(N6:N17) -> 0

Sheet Provider Training
A1: PROVIDER TRAINING
A2: List each training separately using the same title as the corresponding training form provided for inclusion in the management plan.
A3: Travel and transportation costs for daycare home providers are not allowable administrative costs to CACFP.
A4: Date(s) of Training | B4: Provider Training Title and Description | D4: Cost Facility Rental | E4: Cost Training Supplies | F4: Cost Equipment | G4: Cost Registation Fees | H4: Cost Milage | I4: Cost Lodging | J4: Cost Meals | K4: Cost Other | L4: Total Cost Provider Training | M4: % Allocated to CACFP | N4: Total Cost to CACFP
L5: =SUM(D5:K5) -> 0 | N5: =M5*L5 -> 0
L6: =SUM(D6:K6) -> 0 | N6: =M6*L6 -> 0
L7: =SUM(D7:K7) -> 0 | N7: =M7*L7 -> 0
L8: =SUM(D8:K8) -> 0 | N8: =M8*L8 -> 0
L9: =SUM(D9:K9) -> 0 | N9: =M9*L9 -> 0
L10: =SUM(D10:K10) -> 0 | N10: =M10*L10 -> 0
L11: =SUM(D11:K11) -> 0 | N11: =M11*L11 -> 0
L12: =SUM(D12:K12) -> 0 | N12: =M12*L12 -> 0
L13: =SUM(D13:K13) -> 0 | N13: =M13*L13 -> 0
L14: =SUM(D14:K14) -> 0 | N14: =M14*L14 -> 0
L15: =SUM(D15:K15) -> 0 | N15: =M15*L15 -> 0
L16: =SUM(D16:K16) -> 0 | N16: =M16*L16 -> 0
L17: =SUM(L5:L16) -> 0
J18: Total Provider Training | N18: =SUM(N5:N17) -> 0

Sheet Contracted Services
A1: CONTRACTED SERVICES
A2: Assign a number or letter to each contract to be placed in the management plan behind tab V8. Clearly display the number or letter on the copy of the contract for matching purposes.
A3: List below all contracted or paid services for administrative and operating functions not performed by any organization personnel.
A4: Cost for contracted services may be charged over the period of the contract.
A5: Copies of all contracts must be on file at FNS. Sponsors are responsible to ensure updated copies are submitted to FNS annually or whenever the contract is revised or renewed.
A6: Bank charges may be listed here. Include a copy of bank agreement of applicable charges to be placed in the management plan with FNS.
A7: Contracted services must be directly related to the CACFP or the expense will be disallowed.
A8: Number or Letter for each contract listed for FNS Matching purposes | B8: Type of Service | C8: Company Name | D8: Contract Begin Date | E8: Contract End Date | F8: Contract/Policy Number if Applicable | G8: Annual Cost to CACFP | H8: % Allocated to CACFP | I8: Total Annual Cost to CACFP
I9: =H9*G9 -> 0
I10: =H10*G10 -> 0
I11: =H11*G11 -> 0
I12: =H12*G12 -> 0
I13: =H13*G13 -> 0
I14: =H14*G14 -> 0
I15: =H15*G15 -> 0
I16: =H16*G16 -> 0
I17: =H17*G17 -> 0
I18: =H18*G18 -> 0
I19: =H19*G19 -> 0
I20: =H20*G20 -> 0
... I25: =H25*G25 -> 0
F26: Total Contracted Services | I26: =SUM(I9:I25) -> 0

Sheet In-State Travel
A1: IN-STATE TRAVEL
A2: List expenses incurred for program monitoring and all other program-related activities.
A3: Include mileage for facility reviews and other local travel required to manage the program.
A4: Maximum allowable rate is current state rate.
D5: Annual Costs
A6: Employee Name | C6: Purpose of Travel | D6: Mileage | E6: Mileage | F6: Lodging | G6: Meals | H6: Total Annual
D7: Total | E7: Rate | H7: Cost to CACFP
D8: 0 | H8: =(D8*E8)+F8+G8 -> 0
D9: 0 | H9: =(D9*E9)+F9+G9 -> 0
D10: 0 | H10: =(D10*E10)+F10+G10 -> 0
D11: 0 | H11: =(D11*E11)+F11+G11 -> 0
D12: 0 | H12: =(D12*E12)+F12+G12 -> 0
D13: 0 | H13: =(D13*E13)+F13+G13 -> 0
D14: 0 | H14: =(D14*E14)+F14+G14 -> 0
D15: 0 | H15: =(D15*E15)+F15+G15 -> 0
D16: 0 | H16: =(D16*E16)+F16+G16 -> 0
D17: 0 | H17: =(D17*E17)+F17+G17 -> 0
D18: 0 | H18: =(D18*E18)+F18+G18 -> 0
D19: 0 | H19: =(D19*E19)+F19+G19 -> 0
... D23: 0 | H23: =(D23*E23)+F23+G23 -> 0
E24: Total IN-STATE Travel | H24: =SUM(H8:H23) -> 0

Sheet Out-State Travel
A1: OUT-OF-STATE TRAVEL
A2: * Note: Total cost (see equation) does not include the amount for Registration Fee
A3: Registration Fee can be included in training budget.
A4: Employee Name | C4: Travel Purpose | D4: Beginning / Ending Dates | F4: Mileage | G4: Mileage Rate | H4: Airfare | I4: Lodging | J4: Meals | K4: Ground Transport | L4: % Allocated to CACFP | M4: Total Annual Cost
M5: =(F5*G5)+(H5+I5+J5+K5)*L5 -> 0
M6: =(F6*G6)+(H6+I6+J6+K6)*L6 -> 0
M7: =(F7*G7)+(H7+I7+J7+K7)*L7 -> 0
M8: =(F8*G8)+(H8+I8+J8+K8)*L8 -> 0
M9: =(F9*G9)+(H9+I9+J9+K9)*L9 -> 0
M10: =(F10*G10)+(H10+I10+J10+K10)*L10 -> 0
M11: =(F11*G11)+(H11+I11+J11+K11)*L11 -> 0
M12: =(F12*G12)+(H12+I12+J12+K12)*L12 -> 0
M13: =(F13*G13)+(H13+I13+J13+K13)*L13 -> 0
M14: =(F14*G14)+(H14+I14+J14+K14)*L14 -> 0
H15: Total OUT-STATE Travel | M15: =SUM(M5:M14) -> 0

Sheet Occupancy
A1: OCCUPANCY
A2: Indicate the following information regarding office space:
A3: * If office space is rented or leased. If more than one office is rented/leased, provide information on all offices. Attach a copy of each new or renewal lease agreement that includes name of lessor, relationship of lessor to lessee, contact information, length of agreement, beginning and ending dates of agreement, total square footage of office space, and, if office space is utilized for non-CACFP purposes, description of allocation method. * If office space is partially or fully owned by the organization or its administrative personnel. Attach an explanation that details the method for determining the monthly use fee. NOTE: Costs associated with less than arms lengths lease arrangements are limited to depreciation or use allowance. * If office maintenance is included in rental or lease agreement. * If utilities are included in rental or lease agreement.
A8: Utilities/Office Space | C8: # of months service will be provided | D8: Total Monthly Cost | E8: % Allocated to CACFP | F8: Annual Cost to CACFP
A9: Cleaning Cost | F9: =(E9*D9)*C9 -> 0
A10: Utilities | F10: =(E10*D10)*C10 -> 0
A11: Supplies | F11: =(E11*D11)*C11 -> 0
A12: Snow removal | F12: =(E12*D12)*C12 -> 0
A13: lawn mowing | F13: =(E13*D13)*C13 -> 0
A14: Taxes | F14: =(E14*D14)*C14 -> 0
A15: *Office Rental Depreciation (Owned Facility) | F15: =(E15*D15)*C15 -> 0
A16: *Office Rental Lease (Rented Facility) | F16: =(E16*D16)*C16 -> 0
A17: Utilities | F17: =(E17*D17)*C17 -> 0
A18: **Other (Specify) | F18: =(E18*D18)*C18 -> 0
D19: Sub-Total Utilities/Office Space | F19: =SUM(F9:F18) -> 0
A20: Insurance
A21: Include a copy of newinsurance policies or renewed insurance policies.
A22: Type of Insurance | C22: Effective Date | D22: Company Name | E22: Policy Number | F22: Monthly Amt to Organization | G22: % Allocated to CACFP | H22: # of months service will be provided | I22: Total Amount to CACFP
A23: Property/Casualty | I23: =(G23*F23)*H23 -> 0
A24: Liability | I24: =(G24*F24)*H24 -> 0
A25: Other (Specify) | I25: =(G25*F25)*H25 -> 0
F28: Sub-Total Insurance | I28: =SUM(I23:I26) -> 0
F30: Total Occupancy | I30: =F19+I28 -> 0

Sheet Communications
A1: COMMUNICATIONS
A3: Include the following types of communication-related expenses
A4: • Dues, subscription, memberships, etc.
A5: • Advertising media, ie, newspapers, magazines, radio, television, direct mail and similar goods
A6: • Telephone expenses, ie, monthly service charges, long distance charges, cell phones, pagers, Internet charges, etc.
A7: • Postage charges, ie, stamps, bulk mailings, certified mail charges, monthly postage meter costs, etc. The cost of
A8: the postage meter should be listed with leased equipment.
A10: Item | B10: Purpose (indicate if | C10: Number of Months | D10: Monthly Cost | E10: % Allocated to CACFP | F10: Total Annual Cost
B11: for a group or individual) | F11: to CACFP
A12: Advertising | F12: =(D12*E12)*C12 -> 0
A13: Telephone | F13: =(D13*E13)*C13 -> 0
A14: Monthly Service Charge | F14: =(D14*E14)*C14 -> 0
A15: Long Distance Charge | F15: =(D15*E15)*C15 -> 0
A16: Internet Service | F16: =(D16*E16)*C16 -> 0
A17: Cell Phone | F17: =(D17*E17)*C17 -> 0
A18: Cell Phone | F18: =(D18*E18)*C18 -> 0
A19: Cell Phone | F19: =(D19*E19)*C19 -> 0
A20: Dues/Memberships: | F20: =(D20*E20)*C20 -> 0
F21: =(D21*E21)*C21 -> 0
F22: =(D22*E22)*C22 -> 0
A23: Subscription(s): | F23: =(D23*E23)*C23 -> 0
F24: =(D24*E24)*C24 -> 0
F25: =(D25*E25)*C25 -> 0
A26: Postage | F26: =(D26*E26)*C26 -> 0
A27: Shipping (UPS, FedEx, etc) | F27: =(D27*E27)*C27 -> 0
A28: Other (Specify) | F28: =(D28*E28)*C28 -> 0
F29: =(D29*E29)*C29 -> 0
F30: =(D30*E30)*C30 -> 0
F31: =(D31*E31)*C31 -> 0
F32: =SUM(F12:F31) -> 0
A36: Note: Cell Phones leased or owned by the insitution must have prior approval. List a line item for each phone or indicate number of phones for a particular position title. Example 7-Monitors and then the total cost for all 7 monitoring phones.

Sheet Alt Funding Source
B1: Expenditures of ALTERNATE FUNDING SOURCE for CACFP Admin
B3: List the costs that will be paid for with an alternate funding source should you exceed the CACFP adminstrative funds allocated to your organization.
B5: The total cost of these funds should match the amount of $$ identified by CACFP Reimbursement (including carry forward amounts) minus
B6: expenditures.
B7: Make sure that the items listed below are not already accounted for in any other area of the budget.
B9: Identify the Item of Cost | C9: Quantity | D9: Cost | E9: Allocation % (if applicable) | F9: Total Cost for Operation of CACFP Using Other Funding Source
F10: =(D10*E10)*D10 -> 0
F11: 0
F12: =(D12*E12)*D12 -> 0
F13: =(D13*E13)*D13 -> 0
F14: =(D14*E14)*D14 -> 0
F15: =(D15*E15)*D15 -> 0
F16: =(D16*E16)*D16 -> 0
F17: =(D17*E17)*D17 -> 0
F18: =(D18*E18)*D18 -> 0
F19: =(D19*E19)*D19 -> 0
B20: Total | F20: =(D20*E20)*D20 -> 0
B22: ALTERNATE FUNDING SOURCE Description
B24: List the current and projected alternate funding source should you exceed the CACFP adminstrative funds allocated to your organization.
B26: Make sure that the items listed below are not already accounted for in any other area of the FDCH budget.
B28: List the Sources of the Alternate Funding Source or Unrestricted Fund | C28: Frequency of Funding (weekly, monthly) | D28: Activities Supported by Funding Source | F28: Amount | G28: % Allocated to FDCH Admin Costs | H28: FDCH Admin Amount
F29: 0 | H29: =G29*F29 -> 0
F30: =(E30*C30)*D30 -> 0 | H30: =G30*F30 -> 0
F31: =(E31*C31)*D31 -> 0 | H31: =G31*F31 -> 0
F32: =(E32*C32)*D32 -> 0 | H32: =G32*F32 -> 0
F33: =(E33*C33)*D33 -> 0 | H33: =G33*F33 -> 0
F34: =(E34*C34)*D34 -> 0 | H34: =G34*F34 -> 0
F35: =(E35*C35)*D35 -> 0 | H35: =G35*F35 -> 0
F36: =(E36*C36)*D36 -> 0 | H36: =G36*F36 -> 0
F37: =(E37*C37)*D37 -> 0 | H37: =G37*F37 -> 0
F38: =(E38*C38)*D38 -> 0 | H38: =G38*F38 -> 0
B39: Total | F39: =SUM(F29:F38) -> 0 | G39: =SUM(G29:G38) -> 0 | H39: =G39*F39 -> 0

Sheet Carry Over
A1: MINNESOTA DEPARTMENT OF EDUCATION
A2: Food and Nutrition Service
A3: Calculation of FDCA Sponsor Administrative Expense Carryforward
A4: For the Federal Year Ending September 30, 2012
B5: Budget | C5: Actual Y-T-D as of: | D5: Projected Remaining Expenses Through 09/30/12 | E5: Projected Total Administrative Costs | G5: 07/01/11-06/30/12 | H5: 07/01/12-06/30/13
A6: Actual Costs | F6: Homes, 0-50 | G6: 0 | H6: 0
A7: Wages & Salaries | B7: 0 | C7: 0 | D7: 0 | E7: =SUM(C7:D7) -> 0 | F7: Homes, 51-200 | G7: 0 | H7: 0
A8: Employee Benefits | B8: 0 | C8: 0 | D8: 0 | E8: =SUM(C8:D8) -> 0 | F8: Homes, 201-1,000 | G8: 0 | H8: 0
A9: Supplies | B9: 0 | C9: 0 | D9: 0 | E9: =SUM(C9:D9) -> 0 | F9: Homes, Over 1,000 | G9: 0 | H9: 0
A10: Printing | B10: 0 | C10: 0 | D10: 0 | E10: =SUM(C10:D10) -> 0
A11: Equipment | B11: 0 | C11: 0 | D11: 0 | E11: =SUM(C11:D11) -> 0 | F11: Rates effective July 1, 2012 are estimates
A12: Depreciation | B12: 0 | C12: 0 | D12: 0 | E12: =SUM(C12:D12) -> 0 | F12: until USDA publishes new rates.
A13: Staff Training | B13: 0 | C13: 0 | D13: 0 | E13: =SUM(C13:D13) -> 0
A14: Provider Training | B14: 0 | C14: 0 | D14: 0 | E14: =SUM(C14:D14) -> 0 | F14: 1) Include all costs that have been claimed in
A15: Contracted Services | B15: 0 | C15: 0 | D15: 0 | E15: =SUM(C15:D15) -> 0 | F15: CLiCS
A16: In-State Travel | B16: 0 | C16: 0 | D16: 0 | E16: =SUM(C16:D16) -> 0 | F16: 2) Estimate costs to be incurred through the end
A17: Out-of-State Travel | B17: 0 | C17: 0 | D17: 0 | E17: =SUM(C17:D17) -> 0 | F17: of September, 2012.
A18: Rent & Occupancy | B18: 0 | C18: 0 | D18: 0 | E18: =SUM(C18:D18) -> 0 | F18: 3) Enter estimates in green shaded cells only.
A19: Communications | B19: 0 | C19: 0 | D19: 0 | E19: =SUM(C19:D19) -> 0
A20: Claim Total | B20: =SUM(B7:B19) -> 0 | C20: =SUM(C7:C19) -> 0 | D20: =SUM(D7:D19) -> 0 | E20: =SUM(E7:E19) -> 0
A21: Income/Rev Adjust | B21: 0 | C21: 0 | D21: 0 | E21: =SUM(C21:D21) -> 0
A22: Adjusted Total | B22: =SUM(B20:B21) -> 0 | C22: =SUM(C20:C21) -> 0 | D22: =SUM(D20:D21) -> 0 | E22: =SUM(E20:E21) -> 0
A25: Month | B25: Actual Homes Sponsored | C25: Projected Homes Sponsored | D25: Projected Homes Times Rate
A26: 40847 | B26: 140 | C26: 0 | D26: =ROUND((E26*$G$7)+(F26*$G$8)+(G26*$G$9)+($G$10*H26),2) -> 0 | E26: =IF(C26+B26>50,50,IF(B26+C26=0,0,C26+B26)) -> 50 | F26: =IF(B26+C26>200,150,IF(C26+B26<=50,0,C26+B26-50)) -> 90 | G26: =IF(C26+B26>1000,800,IF(C26+B26=0,0,C26+B26-F26-E26)) -> 0 | H26: =IF(C26+B26>1000,C26+B26-1000,0) -> 0
A27: 40877 | B27: 137 | C27: 0 | D27: =ROUND((E27*$G$7)+(F27*$G$8)+(G27*$G$9)+($G$10*H27),2) -> 0 | E27: =IF(C27+B27>50,50,IF(B27+C27=0,0,C27+B27)) -> 50 | F27: =IF(B27+C27>200,150,IF(C27+B27<=50,0,C27+B27-50)) -> 87 | G27: =IF(C27+B27>1000,800,IF(C27+B27=0,0,C27+B27-F27-E27)) -> 0 | H27: =IF(C27+B27>1000,C27+B27-1000,0) -> 0
A28: 40908 | B28: 136 | C28: 0 | D28: =ROUND((E28*$G$7)+(F28*$G$8)+(G28*$G$9)+($G$10*H28),2) -> 0 | E28: =IF(C28+B28>50,50,IF(B28+C28=0,0,C28+B28)) -> 50 | F28: =IF(B28+C28>200,150,IF(C28+B28<=50,0,C28+B28-50)) -> 86 | G28: =IF(C28+B28>1000,800,IF(C28+B28=0,0,C28+B28-F28-E28)) -> 0 | H28: =IF(C28+B28>1000,C28+B28-1000,0) -> 0
A29: 40939 | B29: 136 | C29: 0 | D29: =ROUND((E29*$G$7)+(F29*$G$8)+(G29*$G$9)+($G$10*H29),2) -> 0 | E29: =IF(C29+B29>50,50,IF(B29+C29=0,0,C29+B29)) -> 50 | F29: =IF(B29+C29>200,150,IF(C29+B29<=50,0,C29+B29-50)) -> 86 | G29: =IF(C29+B29>1000,800,IF(C29+B29=0,0,C29+B29-F29-E29)) -> 0 | H29: =IF(C29+B29>1000,C29+B29-1000,0) -> 0
A30: 40968 | B30: 142 | C30: 0 | D30: =ROUND((E30*$G$7)+(F30*$G$8)+(G30*$G$9)+($G$10*H30),2) -> 0 | E30: =IF(C30+B30>50,50,IF(B30+C30=0,0,C30+B30)) -> 50 | F30: =IF(B30+C30>200,150,IF(C30+B30<=50,0,C30+B30-50)) -> 92 | G30: =IF(C30+B30>1000,800,IF(C30+B30=0,0,C30+B30-F30-E30)) -> 0 | H30: =IF(C30+B30>1000,C30+B30-1000,0) -> 0
A31: 40999 | B31: 138 | C31: 0 | D31: =ROUND((E31*$G$7)+(F31*$G$8)+(G31*$G$9)+($G$10*H31),2) -> 0 | E31: =IF(C31+B31>50,50,IF(B31+C31=0,0,C31+B31)) -> 50 | F31: =IF(B31+C31>200,150,IF(C31+B31<=50,0,C31+B31-50)) -> 88 | G31: =IF(C31+B31>1000,800,IF(C31+B31=0,0,C31+B31-F31-E31)) -> 0 | H31: =IF(C31+B31>1000,C31+B31-1000,0) -> 0
A32: 41029 | B32: 139 | C32: 0 | D32: =ROUND((E32*$G$7)+(F32*$G$8)+(G32*$G$9)+($G$10*H32),2) -> 0 | E32: =IF(C32+B32>50,50,IF(B32+C32=0,0,C32+B32)) -> 50 | F32: =IF(B32+C32>200,150,IF(C32+B32<=50,0,C32+B32-50)) -> 89 | G32: =IF(C32+B32>1000,800,IF(C32+B32=0,0,C32+B32-F32-E32)) -> 0 | H32: =IF(C32+B32>1000,C32+B32-1000,0) -> 0
A33: 41060 | B33: 135 | C33: 0 | D33: =ROUND((E33*$G$7)+(F33*$G$8)+(G33*$G$9)+($G$10*H33),2) -> 0 | E33: =IF(C33+B33>50,50,IF(B33+C33=0,0,C33+B33)) -> 50 | F33: =IF(B33+C33>200,150,IF(C33+B33<=50,0,C33+B33-50)) -> 85 | G33: =IF(C33+B33>1000,800,IF(C33+B33=0,0,C33+B33-F33-E33)) -> 0 | H33: =IF(C33+B33>1000,C33+B33-1000,0) -> 0
A34: 41090 | B34: 0 | C34: 0 | D34: =ROUND((E34*$G$7)+(F34*$G$8)+(G34*$G$9)+($G$10*H34),2) -> 0 | E34: =IF(C34+B34>50,50,IF(B34+C34=0,0,C34+B34)) -> 0 | F34: =IF(B34+C34>200,150,IF(C34+B34<=50,0,C34+B34-50)) -> 0 | G34: =IF(C34+B34>1000,800,IF(C34+B34=0,0,C34+B34-F34-E34)) -> 0 | H34: =IF(C34+B34>1000,C34+B34-1000,0) -> 0
A35: 41121 | B35: 0 | C35: 0 | D35: =ROUND((E35*$H$7)+(F35*$H$8)+(G35*$H$9)+($H$10*H35),2) -> 0 | E35: =IF(C35+B35>50,50,IF(B35+C35=0,0,C35+B35)) -> 0 | F35: =IF(B35+C35>200,150,IF(C35+B35<=50,0,C35+B35-50)) -> 0 | G35: =IF(C35+B35>1000,800,IF(C35+B35=0,0,C35+B35-F35-E35)) -> 0 | H35: =IF(C35+B35>1000,C35+B35-1000,0) -> 0
A36: 41152 | B36: 0 | C36: 0 | D36: =ROUND((E36*$H$7)+(F36*$H$8)+(G36*$H$9)+($H$10*H36),2) -> 0 | E36: =IF(C36+B36>50,50,IF(B36+C36=0,0,C36+B36)) -> 0 | F36: =IF(B36+C36>200,150,IF(C36+B36<=50,0,C36+B36-50)) -> 0 | G36: =IF(C36+B36>1000,800,IF(C36+B36=0,0,C36+B36-F36-E36)) -> 0 | H36: =IF(C36+B36>1000,C36+B36-1000,0) -> 0
A37: 41182 | B37: 0 | C37: 0 | D37: =ROUND((E37*$H$7)+(F37*$H$8)+(G37*$H$9)+($H$10*H37),2) -> 0 | E37: =IF(C37+B37>50,50,IF(B37+C37=0,0,C37+B37)) -> 0 | F37: =IF(B37+C37>200,150,IF(C37+B37<=50,0,C37+B37-50)) -> 0 | G37: =IF(C37+B37>1000,800,IF(C37+B37=0,0,C37+B37-F37-E37)) -> 0 | H37: =IF(C37+B37>1000,C37+B37-1000,0) -> 0
B38: =SUM(B26:B37) -> 1103 | C38: =SUM(C26:C37) -> 0 | D38: =SUM(D26:D37) -> 0
A40: Projected administrative costs | D40: =E22 -> 0
A41: Prior year (FFY 2011) carryforward | D41: 0
A42: Projected current year expenditures (net of carryforward) | D42: =SUM(D40:D41) -> 0 | E42: Estimated Costs in Excess of Administrative Reimbursement
E43: Note: If the estimated administrative costs exceed the
...
