Workbook
Name Beef: Allocations!$J$60
Name Brown_Rice: Allocations!$J$86
Name Cheese: Allocations!$J$28
Name Chicken: Allocations!$J$41
Name Corn: Allocations!$J$84
Name Eggs: Allocations!$J$32
Name Flour: Allocations!$J$82
Name Fruit_Juice: Allocations!$J$72
Name Peanut_Butter: Allocations!$J$76
Name Pollock: Allocations!$J$89
Name Pork: Allocations!$J$65
Name Potatoes: Allocations!$J$98
Name sepdsflour: [1]Sheet8!$A$310:$J$600,[1]Sheet8!$A$309:$J$310
Name Tomato_Paste: Allocations!$J$74
Name Turkey: Allocations!$J$49

Sheet Allocations
A1: NOI Request Form
A2: Choose Name of SFA From Drop Down: | S2: Adair-Casey Comm School District
A3: Agreement Number: | F3: Due: March 8th, 2013 | S3: Adel DeSoto Minburn Comm School District
A4: Contact Name: | F4: Estimated Entitlement Budget | S4: AEA 267
A5: Contact e-mail: | F5: =LOOKUP(B2,Data!C2:C496,Data!E2:E496) -> #N/A | S5: AGWSR Comm School District
A6: Processor Name | B6: Material # | C6: Pounds | D6: $ Value | E6: Total $ Value | F6: Broker | S6: A-H-S-T Comm School District
S7: Akron Westfield Comm School District
A8: Cheese | S8: Albert City-Truesdale Comm School District
A9: 1. Bongard's Cheese | B9: 110242 | D9: 1.8003 | E9: =C9*D9 -> 0 | F9: Wolff Group | S9: Albia Comm School District
A10: 2. ES Foods | B10: 110242 | D10: 1.8003 | E10: =C10*D10 -> 0 | F10: Wolff Group | S10: Alburnett Comm School District
A11: 3. JTM Food Group | B11: 110242 | D11: 1.8003 | E11: =C11*D11 -> 0 | F11: Wolff Group | S11: Alden Comm School District
A12: 4. Land O Lakes | B12: 110242 | D12: 1.8003 | E12: =C12*D12 -> 0 | F12: Advantage Waypoint | S12: Algona Comm School District
A13: 5. Windsor Foods | B13: 110242 | D13: 1.8003 | E13: =C13*D13 -> 0 | F13: Advantage Waypoint | S13: All Saints Catholic School
A14: 6. Tasty Brands | B14: 110242 | D14: 1.8003 | E14: =C14*D14 -> 0 | F14: Advantage Waypoint | S14: All Saints School
A15: 7. Alpha Foods Co. | B15: 110244 | D15: 1.7117 | E15: =C15*D15 -> 0 | F15: GVM Food Marketing | S15: Allamakee Comm School District
A16: 8. Nardone Brothers | B16: 110244 | D16: 1.8003 | E16: =C16*D16 -> 0 | F16: Food Marketing Service | S16: Alta Comm School District
A17: 9. Rich's Products Corp. | B17: 110244 | D17: 1.7117 | E17: =C17*D17 -> 0 | F17: Elite Foodservice | S17: Ames Comm School District
A18: 10. Schwans Foodservice | B18: 110244 | D18: 1.7117 | E18: =C18*D18 -> 0 | F18: Elite Foodservice | S18: Anamosa Comm School District
A19: 11. Bosco Pizza | B19: 110244 | D19: 1.7117 | E19: =C19*D19 -> 0 | F19: Advantage Waypoint | S19: Andrew Comm School District
A20: 12. Café Favorites | B20: 110244 | D20: 1.7117 | E20: =C20*D20 -> 0 | F20: Café Favorites | S20: Ankeny Comm School District
... A27: 19. McCain Foods USA | B27: 100034 | D27: 1.7117 | E27: =C27*D27 -> 0 | F27: Elite Foodservice | S27: Assumption School
A28: Eggs | J28: =SUM(E9:E27) -> 0 | S28: Atlantic Comm School District
A29: 20. Café Favorites | B29: 100047 | D29: 0.696 | E29: =C29*D29 -> 0 | F29: Café Favorites | S29: Audubon Comm School District
A30: 21. Cargill Kitchen Solutions | B30: 100047 | D30: 0.696 | E30: =C30*D30 -> 0 | F30: Hockenberg Newburgh | S30: Aurelia Comm School District
A31: 22. Michael Foods | B31: 100047 | D31: 0.696 | E31: =C31*D31 -> 0 | F31: Advantage Waypoint | S31: Ballard Comm School District
A32: Chicken | J32: =SUM(E29:E31) -> 0 | S32: Battle Creek-Ida Grove Comm School District
A33: 23. Asian Food Solutions | B33: 100113 | D33: 0.7063 | E33: =C33*D33 -> 0 | F33: Hockenberg Newburgh | S33: Baxter Comm School District
A34: 24. Ling's 5th Taste | B34: 100113 | D34: 0.7063 | E34: =C34*D34 -> 0 | F34: GVM Food Marketing | S34: BCLUW Comm School District
A35: 25. Schwans Foodservice | B35: 100113 | D35: 0.7063 | E35: =C35*D35 -> 0 | F35: Elite Foodservice | S35: Beckman High School
A36: 26. Pilgrim's Pride | B36: 100103 | D36: 0.7503 | E36: =C36*D36 -> 0 | F36: Food Marketing Service | S36: Bedford Comm School District
A37: 27. Tyson | B37: 100103 | D37: 0.7503 | E37: =C37*D37 -> 0 | F37: Advantage Waypoint | S37: Belle Plaine Comm School District
A38: 28. Quantum Foods | B38: 100103 | D38: 0.7503 | E38: =C38*D38 -> 0 | F38: Hockenberg Newburgh | S38: Bellevue Comm School District
A39: 29. Pilgrim's Pride | B39: 100100 | D39: 0.863 | E39: =C39*D39 -> 0 | F39: Food Marketing Service | S39: Belmond-Klemme Comm School District
A40: 30. Tyson | B40: 100100 | D40: 0.863 | E40: =C40*D40 -> 0 | F40: Advantage Waypoint | S40: Bennett Comm School District
A41: Turkey | J41: =SUM(E33:E40) -> 0 | S41: Benton Comm School District
A42: 31. Café Favorites | B42: 100124 | D42: 1.1167 | E42: =C42*D42 -> 0 | F42: Café Favorites | S42: Bettendorf Comm School District
A43: 32. Cargill Value Added Meats | B43: 100124 | D43: 1.1167 | E43: =C43*D43 -> 0 | F43: Hockenberg Newburgh | S43: Bishop Garrigan High School
A44: 33. Jennie-O-Turkey | B44: 100124 | D44: 1.1167 | E44: =C44*D44 -> 0 | F44: Food Marketing Service | S44: Bishop Heelan Catholic Schools
A45: 34. Tasty Brands | B45: 100124 | D45: 1.1167 | E45: =C45*D45 -> 0 | F45: Advantage Waypoint | S45: Bishop Heelan Catholic High School
A46: 35. Jennie-O-Turkey | B46: 100883 | D46: 1.3259 | E46: =C46*D46 -> 0 | F46: Food Marketing Service | S46: Blackhawk Co Youth Shelt Youth Shelter
...

Sheet Entitlement Details
B1: Estimated Entitlement Budget Overview, SY 14
B2: Estimated Total Entitlement Budget (taken from SY 13) | C2: =LOOKUP(Allocations!B2,Data!C2:C496,Data!E2:E496) -> #N/A
B3: DoD Budget, SY 14 | C3: =LOOKUP(Allocations!B2,Data!C2:C496,Data!F2:F496) -> #N/A
B4: NOI Request, SY 14 | C4: =C23 -> 0
B5: Entitlement Balance Remaining for 6 state orders | C5: =C2-C23-C3 -> #N/A
B8: NOI Request Overview | C8: Dollars
B9: Cheese | C9: =Cheese -> 0
B10: Eggs | C10: =Eggs -> 0
B11: Chicken | C11: =Chicken -> 0
B12: Turkey | C12: =Turkey -> 0 | D12: =IF(C5<0,"Request exceeds entitlement balance !","") -> #N/A
B13: Beef | C13: =Beef -> 0
B14: Pork | C14: =Pork -> 0
B15: Fruit Juice | C15: =Fruit_Juice -> 0
B16: Tomato Paste | C16: =Tomato_Paste -> 0
B17: Peanut Butter | C17: =Peanut_Butter -> 0
B18: Flour | C18: =Flour -> 0
B19: Corn | C19: =Corn -> 0
B20: Brown Rice | C20: =Brown_Rice -> 0
B21: Pollock | C21: =Pollock -> 0
B22: Potatoes | C22: =Potatoes -> 0
B23: Total NOI Request | C23: =SUM(C9:C22) -> 0

Sheet Data
A1: District | B1: School | C1: Name | D1: ADP | E1: CalcEntitle | F1: DoD Amount
E2: 0 | F2: 0
A3: 0018 | B3: 0000 | C3: Adair-Casey Comm School District | D3: 266 | E3: 11491.2
A4: 0027 | B4: 0000 | C4: Adel DeSoto Minburn Comm School District | D4: 1110 | E4: 47952 | F4: 10000
A5: 9207 | B5: 0000 | C5: AEA 267 | D5: 143 | E5: 6177.6
A6: 0009 | B6: 0000 | C6: AGWSR Comm School District | D6: 460 | E6: 19872
A7: 0441 | B7: 0000 | C7: A-H-S-T Comm School District | D7: 486 | E7: 20995.2
A8: 0063 | B8: 0000 | C8: Akron Westfield Comm School District | D8: 442 | E8: 19094.4
A9: 0072 | B9: 0000 | C9: Albert City-Truesdale Comm School District | D9: 88 | E9: 3801.6
A10: 0081 | B10: 0000 | C10: Albia Comm School District | D10: 877 | E10: 37886.4
A11: 0099 | B11: 0000 | C11: Alburnett Comm School District | D11: 514 | E11: 22204.8 | F11: 7500
A12: 0108 | B12: 0000 | C12: Alden Comm School District | D12: 238 | E12: 10281.6
A13: 0126 | B13: 0000 | C13: Algona Comm School District | D13: 1016 | E13: 43891.2
A14: 1611 | B14: 8103 | C14: All Saints Catholic School | D14: 298 | E14: 12873.6 | F14: 5000
A15: 1053 | B15: 8101 | C15: All Saints School | D15: 151 | E15: 6523.2
A16: 0135 | B16: 0000 | C16: Allamakee Comm School District | D16: 1041 | E16: 44971.2
A17: 0171 | B17: 0000 | C17: Alta Comm School District | D17: 417 | E17: 18014.4
A18: 0225 | B18: 0000 | C18: Ames Comm School District | D18: 2031 | E18: 87739.2 | F18: 15000
A19: 0234 | B19: 0000 | C19: Anamosa Comm School District | D19: 947 | E19: 40910.4
A20: 0243 | B20: 0000 | C20: Andrew Comm School District | D20: 145 | E20: 6264
A21: 0261 | B21: 0000 | C21: Ankeny Comm School District | D21: 4581 | E21: 197899.2 | F21: 50000
A22: 0279 | B22: 0000 | C22: Aplington-Parkersburg Comm School District | D22: 732 | E22: 31622.4
A23: 6961 | B23: 8150 | C23: Aquin Elementary School | D23: 220 | E23: 9504
A24: 1053 | B24: 8006 | C24: Area Substnce Abuse Coun System | D24: 19 | E24: 820.8
A25: 0333 | B25: 0000 | C25: Armstrong-Ringsted Comm School District | D25: 275 | E25: 11880
A26: 0355 | B26: 0000 | C26: Ar-We-Va Comm School District | D26: 192 | E26: 8294.4
A27: 1611 | B27: 8101 | C27: Assumption High School | D27: 266 | E27: 11491.2
A28: 7110 | B28: 8101 | C28: Assumption School | D28: 59 | E28: 2548.8
A29: 0387 | B29: 0000 | C29: Atlantic Comm School District | D29: 1193 | E29: 51537.6
A30: 0414 | B30: 0000 | C30: Audubon Comm School District | D30: 466 | E30: 20131.2
A31: 0423 | B31: 0000 | C31: Aurelia Comm School District | D31: 238 | E31: 10281.6
A32: 0472 | B32: 0000 | C32: Ballard Comm School District | D32: 1174 | E32: 50716.8
A33: 0504 | B33: 0000 | C33: Battle Creek-Ida Grove Comm School District | D33: 505 | E33: 21816
A34: 0513 | B34: 0000 | C34: Baxter Comm School District | D34: 344 | E34: 14860.8 | F34: 2000
A35: 0540 | B35: 0000 | C35: BCLUW Comm School District | D35: 528 | E35: 22809.6
A36: 6961 | B36: 8146 | C36: Beckman High School | D36: 414 | E36: 17884.8 | F36: 5000
A37: 0549 | B37: 0000 | C37: Bedford Comm School District | D37: 438 | E37: 18921.6
A38: 0576 | B38: 0000 | C38: Belle Plaine Comm School District | D38: 441 | E38: 19051.2 | F38: 5000
A39: 0585 | B39: 0000 | C39: Bellevue Comm School District | D39: 479 | E39: 20692.8
A40: 0594 | B40: 0000 | C40: Belmond-Klemme Comm School District | D40: 527 | E40: 22766.4
...
