Workbook
Name physical: 'All Very Good Moves'!$B$2
Name special: 'All Very Good Moves'!$B$31
Name non: 'All Very Good Moves'!$B$58

Sheet List Builder
B2: Total List of All Moves | I2: Equivalents / Outclassing ("Doubles")
B3: Move | C3: VGM? | D3: Type | E3: Category | F3: Doubles with? | G3: Commonly Paired With? | I3: Total # Doubles: | J3: 1
A4: 1 | B4: Attract | C4: =VLOOKUP(B4,'Moves Index'!$B$3:$C$561,2,FALSE) -> No | D4: =VLOOKUP(B4,'Moves Index'!$B$3:$D$561,3,FALSE) -> Non-Attacking | E4: =VLOOKUP(B4,'Moves Index'!$B$3:$E$561,4,FALSE) -> N/A | F4: =VLOOKUP(B4,Lookup!$B$3:$C$54,2,FALSE) -> #N/A:lookupNotFound:Attract | G4: =VLOOKUP(B4,Lookup!$E$24:$F$121,2,FALSE) -> #N/A:lookupNotFound:Attract | I4: # VGM Doubles: | J4: 1
A5: =A4+1 -> 2 | B5: Double Team | C5: =VLOOKUP(B5,'Moves Index'!$B$3:$C$561,2,FALSE) -> No | D5: =VLOOKUP(B5,'Moves Index'!$B$3:$D$561,3,FALSE) -> Non-Attacking | E5: =VLOOKUP(B5,'Moves Index'!$B$3:$E$561,4,FALSE) -> N/A | F5: =VLOOKUP(B5,Lookup!$B$3:$C$54,2,FALSE) -> #N/A:lookupNotFound:Double Team | G5: =VLOOKUP(B5,Lookup!$E$24:$F$121,2,FALSE) -> #N/A:lookupNotFound:Double Team
A6: =A5+1 -> 3 | B6: Facade | C6: =VLOOKUP(B6,'Moves Index'!$B$3:$C$561,2,FALSE) -> Yes | D6: =VLOOKUP(B6,'Moves Index'!$B$3:$D$561,3,FALSE) -> Attacking | E6: =VLOOKUP(B6,'Moves Index'!$B$3:$E$561,4,FALSE) -> Physical | F6: =VLOOKUP(B6,Lookup!$B$3:$C$54,2,FALSE) -> #N/A:lookupNotFound:Facade | G6: =VLOOKUP(B6,Lookup!$E$24:$F$121,2,FALSE) -> #N/A:lookupNotFound:Facade | I6: Type-Move Guidelines
A7: =A6+1 -> 4 | B7: Frustration | C7: =VLOOKUP(B7,'Moves Index'!$B$3:$C$561,2,FALSE) -> Yes | D7: =VLOOKUP(B7,'Moves Index'!$B$3:$D$561,3,FALSE) -> Attacking | E7: =VLOOKUP(B7,'Moves Index'!$B$3:$E$561,4,FALSE) -> Physical | F7: =VLOOKUP(B7,Lookup!$B$3:$C$54,2,FALSE) -> Return | G7: =VLOOKUP(B7,Lookup!$E$24:$F$121,2,FALSE) -> #N/A:lookupNotFound:Frustration | I7: Type | J7: Commonly Paired With?
A8: =A7+1 -> 5 | B8: Giga Impact | C8: =VLOOKUP(B8,'Moves Index'!$B$3:$C$561,2,FALSE) -> No | D8: =VLOOKUP(B8,'Moves Index'!$B$3:$D$561,3,FALSE) -> Attacking | E8: =VLOOKUP(B8,'Moves Index'!$B$3:$E$561,4,FALSE) -> Physical | F8: =VLOOKUP(B8,Lookup!$B$3:$C$54,2,FALSE) -> #N/A:lookupNotFound:Giga Impact | G8: =VLOOKUP(B8,Lookup!$E$24:$F$121,2,FALSE) -> #N/A:lookupNotFound:Giga Impact | J8: =VLOOKUP(I8,Lookup!$E$4:$F$20,2,FALSE) -> #N/A:blankIndicator:
A9: =A8+1 -> 6 | B9: Hidden Power | C9: =VLOOKUP(B9,'Moves Index'!$B$3:$C$561,2,FALSE) -> Yes | D9: =VLOOKUP(B9,'Moves Index'!$B$3:$D$561,3,FALSE) -> Attacking | E9: =VLOOKUP(B9,'Moves Index'!$B$3:$E$561,4,FALSE) -> Special | F9: =VLOOKUP(B9,Lookup!$B$3:$C$54,2,FALSE) -> #N/A:lookupNotFound:Hidden Power | G9: =VLOOKUP(B9,Lookup!$E$24:$F$121,2,FALSE) -> #N/A:lookupNotFound:Hidden Power | J9: =VLOOKUP(I9,Lookup!$E$4:$F$20,2,FALSE) -> #N/A:blankIndicator:
A10: =A9+1 -> 7 | B10: Hyper Beam | C10: =VLOOKUP(B10,'Moves Index'!$B$3:$C$561,2,FALSE) -> No | D10: =VLOOKUP(B10,'Moves Index'!$B$3:$D$561,3,FALSE) -> Attacking | E10: =VLOOKUP(B10,'Moves Index'!$B$3:$E$561,4,FALSE) -> Special | F10: =VLOOKUP(B10,Lookup!$B$3:$C$54,2,FALSE) -> #N/A:lookupNotFound:Hyper Beam | G10: =VLOOKUP(B10,Lookup!$E$24:$F$121,2,FALSE) -> #N/A:lookupNotFound:Hyper Beam
A11: =A10+1 -> 8 | B11: Protect | C11: =VLOOKUP(B11,'Moves Index'!$B$3:$C$561,2,FALSE) -> Yes | D11: =VLOOKUP(B11,'Moves Index'!$B$3:$D$561,3,FALSE) -> Non-Attacking | E11: =VLOOKUP(B11,'Moves Index'!$B$3:$E$561,4,FALSE) -> N/A | F11: =VLOOKUP(B11,Lookup!$B$3:$C$54,2,FALSE) -> #N/A:lookupNotFound:Protect | G11: =VLOOKUP(B11,Lookup!$E$24:$F$121,2,FALSE) -> #N/A:lookupNotFound:Protect | I11: Overall Counts
A12: =A11+1 -> 9 | B12: Recycle | C12: =VLOOKUP(B12,'Moves Index'!$B$3:$C$561,2,FALSE) -> No | D12: =VLOOKUP(B12,'Moves Index'!$B$3:$D$561,3,FALSE) -> Non-Attacking | E12: =VLOOKUP(B12,'Moves Index'!$B$3:$E$561,4,FALSE) -> N/A | F12: =VLOOKUP(B12,Lookup!$B$3:$C$54,2,FALSE) -> #N/A:lookupNotFound:Recycle | G12: =VLOOKUP(B12,Lookup!$E$24:$F$121,2,FALSE) -> #N/A:lookupNotFound:Recycle | I12: Absolute # Moves: | J12: =COUNTA(B4:B103) -> 17
A13: =A12+1 -> 10 | B13: Rest | C13: =VLOOKUP(B13,'Moves Index'!$B$3:$C$561,2,FALSE) -> Yes | D13: =VLOOKUP(B13,'Moves Index'!$B$3:$D$561,3,FALSE) -> Non-Attacking | E13: =VLOOKUP(B13,'Moves Index'!$B$3:$E$561,4,FALSE) -> N/A | F13: =VLOOKUP(B13,Lookup!$B$3:$C$54,2,FALSE) -> #N/A:lookupNotFound:Rest | G13: =VLOOKUP(B13,Lookup!$E$24:$F$121,2,FALSE) -> #N/A:lookupNotFound:Rest
A14: =A13+1 -> 11 | B14: Return | C14: =VLOOKUP(B14,'Moves Index'!$B$3:$C$561,2,FALSE) -> Yes | D14: =VLOOKUP(B14,'Moves Index'!$B$3:$D$561,3,FALSE) -> Attacking | E14: =VLOOKUP(B14,'Moves Index'!$B$3:$E$561,4,FALSE) -> Physical | F14: =VLOOKUP(B14,Lookup!$B$3:$C$54,2,FALSE) -> Frustration | G14: =VLOOKUP(B14,Lookup!$E$24:$F$121,2,FALSE) -> #N/A:lookupNotFound:Return | I14: Absolute # VGMs: | J14: =COUNTIF(C4:C103,"Yes")-J4 -> 8
A15: =A14+1 -> 12 | B15: Round | C15: =VLOOKUP(B15,'Moves Index'!$B$3:$C$561,2,FALSE) -> No | D15: =VLOOKUP(B15,'Moves Index'!$B$3:$D$561,3,FALSE) -> Attacking | E15: =VLOOKUP(B15,'Moves Index'!$B$3:$E$561,4,FALSE) -> Special | F15: =VLOOKUP(B15,Lookup!$B$3:$C$54,2,FALSE) -> #N/A:lookupNotFound:Round | G15: =VLOOKUP(B15,Lookup!$E$24:$F$121,2,FALSE) -> #N/A:lookupNotFound:Round
A16: =A15+1 -> 13 | B16: Sleep Talk | C16: =VLOOKUP(B16,'Moves Index'!$B$3:$C$561,2,FALSE) -> Yes | D16: =VLOOKUP(B16,'Moves Index'!$B$3:$D$561,3,FALSE) -> Non-Attacking | E16: =VLOOKUP(B16,'Moves Index'!$B$3:$E$561,4,FALSE) -> N/A | F16: =VLOOKUP(B16,Lookup!$B$3:$C$54,2,FALSE) -> #N/A:lookupNotFound:Sleep Talk | G16: =VLOOKUP(B16,Lookup!$E$24:$F$121,2,FALSE) -> #N/A:lookupNotFound:Sleep Talk | I16: Total Attacking Moves: | J16: =COUNTIF(D4:D103,"Attacking") -> 8
A17: =A16+1 -> 14 | B17: Snore | C17: =VLOOKUP(B17,'Moves Index'!$B$3:$C$561,2,FALSE) -> No | D17: =VLOOKUP(B17,'Moves Index'!$B$3:$D$561,3,FALSE) -> Attacking | E17: =VLOOKUP(B17,'Moves Index'!$B$3:$E$561,4,FALSE) -> Special | F17: =VLOOKUP(B17,Lookup!$B$3:$C$54,2,FALSE) -> #N/A:lookupNotFound:Snore | G17: =VLOOKUP(B17,Lookup!$E$24:$F$121,2,FALSE) -> #N/A:lookupNotFound:Snore | I17: Total Non-Attacking Moves: | J17: =COUNTIF(D4:D103,"Non-Attacking") -> 9
A18: =A17+1 -> 15 | B18: Substitute | C18: =VLOOKUP(B18,'Moves Index'!$B$3:$C$561,2,FALSE) -> Yes | D18: =VLOOKUP(B18,'Moves Index'!$B$3:$D$561,3,FALSE) -> Non-Attacking | E18: =VLOOKUP(B18,'Moves Index'!$B$3:$E$561,4,FALSE) -> N/A | F18: =VLOOKUP(B18,Lookup!$B$3:$C$54,2,FALSE) -> #N/A:lookupNotFound:Substitute | G18: =VLOOKUP(B18,Lookup!$E$24:$F$121,2,FALSE) -> #N/A:lookupNotFound:Substitute | I18: Total Physical Moves: | J18: =COUNTIF(E4:E103,"Physical") -> 4
A19: =A18+1 -> 16 | B19: Swagger | C19: =VLOOKUP(B19,'Moves Index'!$B$3:$C$561,2,FALSE) -> No | D19: =VLOOKUP(B19,'Moves Index'!$B$3:$D$561,3,FALSE) -> Non-Attacking | E19: =VLOOKUP(B19,'Moves Index'!$B$3:$E$561,4,FALSE) -> N/A | F19: =VLOOKUP(B19,Lookup!$B$3:$C$54,2,FALSE) -> #N/A:lookupNotFound:Swagger | G19: =VLOOKUP(B19,Lookup!$E$24:$F$121,2,FALSE) -> #N/A:lookupNotFound:Swagger | I19: Total Special Moves: | J19: =COUNTIF(E4:E103,"Special") -> 4
A20: =A19+1 -> 17 | B20: Toxic | C20: =VLOOKUP(B20,'Moves Index'!$B$3:$C$561,2,FALSE) -> Yes | D20: =VLOOKUP(B20,'Moves Index'!$B$3:$D$561,3,FALSE) -> Non-Attacking | E20: =VLOOKUP(B20,'Moves Index'!$B$3:$E$561,4,FALSE) -> N/A | F20: =VLOOKUP(B20,Lookup!$B$3:$C$54,2,FALSE) -> #N/A:lookupNotFound:Toxic | G20: =VLOOKUP(B20,Lookup!$E$24:$F$121,2,FALSE) -> #N/A:lookupNotFound:Toxic
A21: =A20+1 -> 18 | C21: =VLOOKUP(B21,'Moves Index'!$B$3:$C$561,2,FALSE) -> #N/A:blankIndicator: | D21: =VLOOKUP(B21,'Moves Index'!$B$3:$D$561,3,FALSE) -> #N/A:blankIndicator: | E21: =VLOOKUP(B21,'Moves Index'!$B$3:$E$561,4,FALSE) -> #N/A:blankIndicator: | F21: =VLOOKUP(B21,Lookup!$B$3:$C$54,2,FALSE) -> #N/A:blankIndicator: | G21: =VLOOKUP(B21,Lookup!$E$24:$F$121,2,FALSE) -> #N/A:blankIndicator: | I21: NB. You may want to extend the final two columns if all the text doesn't fit.
A22: =A21+1 -> 19 | C22: =VLOOKUP(B22,'Moves Index'!$B$3:$C$561,2,FALSE) -> #N/A:blankIndicator: | D22: =VLOOKUP(B22,'Moves Index'!$B$3:$D$561,3,FALSE) -> #N/A:blankIndicator: | E22: =VLOOKUP(B22,'Moves Index'!$B$3:$E$561,4,FALSE) -> #N/A:blankIndicator: | F22: =VLOOKUP(B22,Lookup!$B$3:$C$54,2,FALSE) -> #N/A:blankIndicator: | G22: =VLOOKUP(B22,Lookup!$E$24:$F$121,2,FALSE) -> #N/A:blankIndicator:
A23: =A22+1 -> 20 | C23: =VLOOKUP(B23,'Moves Index'!$B$3:$C$561,2,FALSE) -> #N/A:blankIndicator: | D23: =VLOOKUP(B23,'Moves Index'!$B$3:$D$561,3,FALSE) -> #N/A:blankIndicator: | E23: =VLOOKUP(B23,'Moves Index'!$B$3:$E$561,4,FALSE) -> #N/A:blankIndicator: | F23: =VLOOKUP(B23,Lookup!$B$3:$C$54,2,FALSE) -> #N/A:blankIndicator: | G23: =VLOOKUP(B23,Lookup!$E$24:$F$121,2,FALSE) -> #N/A:blankIndicator:
A24: =A23+1 -> 21 | C24: =VLOOKUP(B24,'Moves Index'!$B$3:$C$561,2,FALSE) -> #N/A:blankIndicator: | D24: =VLOOKUP(B24,'Moves Index'!$B$3:$D$561,3,FALSE) -> #N/A:blankIndicator: | E24: =VLOOKUP(B24,'Moves Index'!$B$3:$E$561,4,FALSE) -> #N/A:blankIndicator: | F24: =VLOOKUP(B24,Lookup!$B$3:$C$54,2,FALSE) -> #N/A:blankIndicator: | G24: =VLOOKUP(B24,Lookup!$E$24:$F$121,2,FALSE) -> #N/A:blankIndicator:
A25: =A24+1 -> 22 | C25: =VLOOKUP(B25,'Moves Index'!$B$3:$C$561,2,FALSE) -> #N/A:blankIndicator: | D25: =VLOOKUP(B25,'Moves Index'!$B$3:$D$561,3,FALSE) -> #N/A:blankIndicator: | E25: =VLOOKUP(B25,'Moves Index'!$B$3:$E$561,4,FALSE) -> #N/A:blankIndicator: | F25: =VLOOKUP(B25,Lookup!$B$3:$C$54,2,FALSE) -> #N/A:blankIndicator: | G25: =VLOOKUP(B25,Lookup!$E$24:$F$121,2,FALSE) -> #N/A:blankIndicator:
A26: =A25+1 -> 23 | C26: =VLOOKUP(B26,'Moves Index'!$B$3:$C$561,2,FALSE) -> #N/A:blankIndicator: | D26: =VLOOKUP(B26,'Moves Index'!$B$3:$D$561,3,FALSE) -> #N/A:blankIndicator: | E26: =VLOOKUP(B26,'Moves Index'!$B$3:$E$561,4,FALSE) -> #N/A:blankIndicator: | F26: =VLOOKUP(B26,Lookup!$B$3:$C$54,2,FALSE) -> #N/A:blankIndicator: | G26: =VLOOKUP(B26,Lookup!$E$24:$F$121,2,FALSE) -> #N/A:blankIndicator:
A27: =A26+1 -> 24 | C27: =VLOOKUP(B27,'Moves Index'!$B$3:$C$561,2,FALSE) -> #N/A:blankIndicator: | D27: =VLOOKUP(B27,'Moves Index'!$B$3:$D$561,3,FALSE) -> #N/A:blankIndicator: | E27: =VLOOKUP(B27,'Moves Index'!$B$3:$E$561,4,FALSE) -> #N/A:blankIndicator: | F27: =VLOOKUP(B27,Lookup!$B$3:$C$54,2,FALSE) -> #N/A:blankIndicator: | G27: =VLOOKUP(B27,Lookup!$E$24:$F$121,2,FALSE) -> #N/A:blankIndicator:
A28: =A27+1 -> 25 | C28: =VLOOKUP(B28,'Moves Index'!$B$3:$C$561,2,FALSE) -> #N/A:blankIndicator: | D28: =VLOOKUP(B28,'Moves Index'!$B$3:$D$561,3,FALSE) -> #N/A:blankIndicator: | E28: =VLOOKUP(B28,'Moves Index'!$B$3:$E$561,4,FALSE) -> #N/A:blankIndicator: | F28: =VLOOKUP(B28,Lookup!$B$3:$C$54,2,FALSE) -> #N/A:blankIndicator: | G28: =VLOOKUP(B28,Lookup!$E$24:$F$121,2,FALSE) -> #N/A:blankIndicator:
A29: =A28+1 -> 26 | C29: =VLOOKUP(B29,'Moves Index'!$B$3:$C$561,2,FALSE) -> #N/A:blankIndicator: | D29: =VLOOKUP(B29,'Moves Index'!$B$3:$D$561,3,FALSE) -> #N/A:blankIndicator: | E29: =VLOOKUP(B29,'Moves Index'!$B$3:$E$561,4,FALSE) -> #N/A:blankIndicator: | F29: =VLOOKUP(B29,Lookup!$B$3:$C$54,2,FALSE) -> #N/A:blankIndicator: | G29: =VLOOKUP(B29,Lookup!$E$24:$F$121,2,FALSE) -> #N/A:blankIndicator:
A30: =A29+1 -> 27 | C30: =VLOOKUP(B30,'Moves Index'!$B$3:$C$561,2,FALSE) -> #N/A:blankIndicator: | D30: =VLOOKUP(B30,'Moves Index'!$B$3:$D$561,3,FALSE) -> #N/A:blankIndicator: | E30: =VLOOKUP(B30,'Moves Index'!$B$3:$E$561,4,FALSE) -> #N/A:blankIndicator: | F30: =VLOOKUP(B30,Lookup!$B$3:$C$54,2,FALSE) -> #N/A:blankIndicator: | G30: =VLOOKUP(B30,Lookup!$E$24:$F$121,2,FALSE) -> #N/A:blankIndicator:
A31: =A30+1 -> 28 | C31: =VLOOKUP(B31,'Moves Index'!$B$3:$C$561,2,FALSE) -> #N/A:blankIndicator: | D31: =VLOOKUP(B31,'Moves Index'!$B$3:$D$561,3,FALSE) -> #N/A:blankIndicator: | E31: =VLOOKUP(B31,'Moves Index'!$B$3:$E$561,4,FALSE) -> #N/A:blankIndicator: | F31: =VLOOKUP(B31,Lookup!$B$3:$C$54,2,FALSE) -> #N/A:blankIndicator: | G31: =VLOOKUP(B31,Lookup!$E$24:$F$121,2,FALSE) -> #N/A:blankIndicator:
A32: =A31+1 -> 29 | C32: =VLOOKUP(B32,'Moves Index'!$B$3:$C$561,2,FALSE) -> #N/A:blankIndicator: | D32: =VLOOKUP(B32,'Moves Index'!$B$3:$D$561,3,FALSE) -> #N/A:blankIndicator: | E32: =VLOOKUP(B32,'Moves Index'!$B$3:$E$561,4,FALSE) -> #N/A:blankIndicator: | F32: =VLOOKUP(B32,Lookup!$B$3:$C$54,2,FALSE) -> #N/A:blankIndicator: | G32: =VLOOKUP(B32,Lookup!$E$24:$F$121,2,FALSE) -> #N/A:blankIndicator:
A33: =A32+1 -> 30 | C33: =VLOOKUP(B33,'Moves Index'!$B$3:$C$561,2,FALSE) -> #N/A:blankIndicator: | D33: =VLOOKUP(B33,'Moves Index'!$B$3:$D$561,3,FALSE) -> #N/A:blankIndicator: | E33: =VLOOKUP(B33,'Moves Index'!$B$3:$E$561,4,FALSE) -> #N/A:blankIndicator: | F33: =VLOOKUP(B33,Lookup!$B$3:$C$54,2,FALSE) -> #N/A:blankIndicator: | G33: =VLOOKUP(B33,Lookup!$E$24:$F$121,2,FALSE) -> #N/A:blankIndicator:
... A103: =A102+1 -> 100 | C103: =VLOOKUP(B103,'Moves Index'!$B$3:$C$561,2,FALSE) -> #N/A:blankIndicator: | D103: =VLOOKUP(B103,'Moves Index'!$B$3:$D$561,3,FALSE) -> #N/A:blankIndicator: | E103: =VLOOKUP(B103,'Moves Index'!$B$3:$E$561,4,FALSE) -> #N/A:blankIndicator: | F103: =VLOOKUP(B103,Lookup!$B$3:$C$54,2,FALSE) -> #N/A:blankIndicator: | G103: =VLOOKUP(B103,Lookup!$E$24:$F$121,2,FALSE) -> #N/A:blankIndicator:

Sheet Movepool Builder
C3: Technical Machines and Hidden Machines
C4: Move | D4: VGM? | E4: Type | F4: Category | G4: Move | H4: VGM? | I4: Type | J4: Category | K4: Move | L4: VGM? | M4: Type | N4: Category | O4: Move | P4: VGM? | Q4: Type | R4: Category
C5: Hone Claws | D5: =VLOOKUP(C5,'Moves Index'!$B$3:$C$561,2,FALSE) -> Yes | E5: =VLOOKUP(C5,'Moves Index'!$B$3:$D$561,3,FALSE) -> Non-Attacking | F5: =VLOOKUP(C5,'Moves Index'!$B$3:$E$561,4,FALSE) -> N/A | G5: Earthquake | H5: =VLOOKUP(G5,'Moves Index'!$B$3:$C$561,2,FALSE) -> Yes | I5: =VLOOKUP(G5,'Moves Index'!$B$3:$D$561,3,FALSE) -> Attacking | J5: =VLOOKUP(G5,'Moves Index'!$B$3:$E$561,4,FALSE) -> Physical | K5: Ally Switch | L5: =VLOOKUP(K5,'Moves Index'!$B$3:$C$561,2,FALSE) -> No | M5: =VLOOKUP(K5,'Moves Index'!$B$3:$D$561,3,FALSE) -> Non-Attacking | N5: =VLOOKUP(K5,'Moves Index'!$B$3:$E$561,4,FALSE) -> N/A | O5: Struggle Bug | P5: =VLOOKUP(O5,'Moves Index'!$B$3:$C$561,2,FALSE) -> No | Q5: =VLOOKUP(O5,'Moves Index'!$B$3:$D$561,3,FALSE) -> Attacking | R5: =VLOOKUP(O5,'Moves Index'!$B$3:$E$561,4,FALSE) -> Special | T5: Technical Machine Counts | W5: Equivalents / Outclassing ("Doubles") | Z5: Equivalents, Outclassing, and Move-Move Guidelines Check Sheet
C6: Dragon Claw | D6: =VLOOKUP(C6,'Moves Index'!$B$3:$C$561,2,FALSE) -> Yes | E6: =VLOOKUP(C6,'Moves Index'!$B$3:$D$561,3,FALSE) -> Attacking | F6: =VLOOKUP(C6,'Moves Index'!$B$3:$E$561,4,FALSE) -> Physical | G6: Return | H6: =VLOOKUP(G6,'Moves Index'!$B$3:$C$561,2,FALSE) -> Yes | I6: =VLOOKUP(G6,'Moves Index'!$B$3:$D$561,3,FALSE) -> Attacking | J6: =VLOOKUP(G6,'Moves Index'!$B$3:$E$561,4,FALSE) -> Physical | K6: Focus Blast | L6: =VLOOKUP(K6,'Moves Index'!$B$3:$C$561,2,FALSE) -> Yes | M6: =VLOOKUP(K6,'Moves Index'!$B$3:$D$561,3,FALSE) -> Attacking | N6: =VLOOKUP(K6,'Moves Index'!$B$3:$E$561,4,FALSE) -> Special | O6: Psych Up | P6: =VLOOKUP(O6,'Moves Index'!$B$3:$C$561,2,FALSE) -> No | Q6: =VLOOKUP(O6,'Moves Index'!$B$3:$D$561,3,FALSE) -> Non-Attacking | R6: =VLOOKUP(O6,'Moves Index'!$B$3:$E$561,4,FALSE) -> N/A | T6: Total # Moves: | U6: =((COUNTA(C5:C30)+COUNTA(G5:G30))+COUNTA(K5:K30))+COUNTA(O5:O30) -> 101 | W6: # VGM Doubles: | Z6: Technical Machines and Hidden Machines
C7: Psyshock | D7: =VLOOKUP(C7,'Moves Index'!$B$3:$C$561,2,FALSE) -> Yes | E7: =VLOOKUP(C7,'Moves Index'!$B$3:$D$561,3,FALSE) -> Attacking | F7: =VLOOKUP(C7,'Moves Index'!$B$3:$E$561,4,FALSE) -> Special | G7: Dig | H7: =VLOOKUP(G7,'Moves Index'!$B$3:$C$561,2,FALSE) -> No | I7: =VLOOKUP(G7,'Moves Index'!$B$3:$D$561,3,FALSE) -> Attacking | J7: =VLOOKUP(G7,'Moves Index'!$B$3:$E$561,4,FALSE) -> Physical | K7: Energy Ball | L7: =VLOOKUP(K7,'Moves Index'!$B$3:$C$561,2,FALSE) -> Yes | M7: =VLOOKUP(K7,'Moves Index'!$B$3:$D$561,3,FALSE) -> Attacking | N7: =VLOOKUP(K7,'Moves Index'!$B$3:$E$561,4,FALSE) -> Special | O7: Bulldoze | P7: =VLOOKUP(O7,'Moves Index'!$B$3:$C$561,2,FALSE) -> No | Q7: =VLOOKUP(O7,'Moves Index'!$B$3:$D$561,3,FALSE) -> Attacking | R7: =VLOOKUP(O7,'Moves Index'!$B$3:$E$561,4,FALSE) -> Physical | T7: Total # VGMs: | U7: =((COUNTIF(D5:D30,"Yes")+COUNTIF(H5:H30,"Yes"))+COUNTIF(L5:L30,"Yes"))+COUNTIF(P5:P30,"Yes") -> 60 | Z7: Move | AA7: Doubles with? | AB7: Commonly Paired With?
C8: Calm Mind | D8: =VLOOKUP(C8,'Moves Index'!$B$3:$C$561,2,FALSE) -> Yes | E8: =VLOOKUP(C8,'Moves Index'!$B$3:$D$561,3,FALSE) -> Non-Attacking | F8: =VLOOKUP(C8,'Moves Index'!$B$3:$E$561,4,FALSE) -> N/A | G8: Psychic | H8: =VLOOKUP(G8,'Moves Index'!$B$3:$C$561,2,FALSE) -> Yes | I8: =VLOOKUP(G8,'Moves Index'!$B$3:$D$561,3,FALSE) -> Attacking | J8: =VLOOKUP(G8,'Moves Index'!$B$3:$E$561,4,FALSE) -> Special | K8: False Swipe | L8: =VLOOKUP(K8,'Moves Index'!$B$3:$C$561,2,FALSE) -> No | M8: =VLOOKUP(K8,'Moves Index'!$B$3:$D$561,3,FALSE) -> Attacking | N8: =VLOOKUP(K8,'Moves Index'!$B$3:$E$561,4,FALSE) -> Physical | O8: Frost Breath | P8: =VLOOKUP(O8,'Moves Index'!$B$3:$C$561,2,FALSE) -> Yes | Q8: =VLOOKUP(O8,'Moves Index'!$B$3:$D$561,3,FALSE) -> Attacking | R8: =VLOOKUP(O8,'Moves Index'!$B$3:$E$561,4,FALSE) -> Special | T8: Total Attacking Moves: | U8: =((COUNTIF(E5:E30,"Attacking")+COUNTIF(I5:I30,"Attacking"))+COUNTIF(M5:M30,"Attacking"))+COUNTIF(Q5:Q30,"Attacking") -> 69 | Z8: =C5 -> Hone Claws | AA8: =VLOOKUP(Z8,Lookup!$B$3:$C$54,2,FALSE) -> Meditate, Sharpen, Howl, Coil | AB8: =VLOOKUP(Z8,Lookup!$E$24:$F$121,2,FALSE) -> #N/A:lookupNotFound:Hone Claws
C9: Roar | D9: =VLOOKUP(C9,'Moves Index'!$B$3:$C$561,2,FALSE) -> Yes | E9: =VLOOKUP(C9,'Moves Index'!$B$3:$D$561,3,FALSE) -> Non-Attacking | F9: =VLOOKUP(C9,'Moves Index'!$B$3:$E$561,4,FALSE) -> N/A | G9: Shadow Ball | H9: =VLOOKUP(G9,'Moves Index'!$B$3:$C$561,2,FALSE) -> Yes | I9: =VLOOKUP(G9,'Moves Index'!$B$3:$D$561,3,FALSE) -> Attacking | J9: =VLOOKUP(G9,'Moves Index'!$B$3:$E$561,4,FALSE) -> Special | K9: Scald | L9: =VLOOKUP(K9,'Moves Index'!$B$3:$C$561,2,FALSE) -> Yes | M9: =VLOOKUP(K9,'Moves Index'!$B$3:$D$561,3,FALSE) -> Attacking | N9: =VLOOKUP(K9,'Moves Index'!$B$3:$E$561,4,FALSE) -> Special | O9: Rock Slide | P9: =VLOOKUP(O9,'Moves Index'!$B$3:$C$561,2,FALSE) -> Yes | Q9: =VLOOKUP(O9,'Moves Index'!$B$3:$D$561,3,FALSE) -> Attacking | R9: =VLOOKUP(O9,'Moves Index'!$B$3:$E$561,4,FALSE) -> Physical | T9: Total Non-Attacking Moves: | U9: =((COUNTIF(E5:E30,"Non-Attacking")+COUNTIF(I5:I30,"Non-Attacking"))+COUNTIF(M5:M30,"Non-Attacking"))+COUNTIF(Q5:Q30,"Non-Attacking") -> 32 | W9: Repeats | Z9: =C6 -> Dragon Claw | AA9: =VLOOKUP(Z9,Lookup!$B$3:$C$54,2,FALSE) -> #N/A:lookupNotFound:Dragon Claw | AB9: =VLOOKUP(Z9,Lookup!$E$24:$F$121,2,FALSE) -> Hone Claws
C10: Toxic | D10: =VLOOKUP(C10,'Moves Index'!$B$3:$C$561,2,FALSE) -> Yes | E10: =VLOOKUP(C10,'Moves Index'!$B$3:$D$561,3,FALSE) -> Non-Attacking | F10: =VLOOKUP(C10,'Moves Index'!$B$3:$E$561,4,FALSE) -> N/A | G10: Brick Break | H10: =VLOOKUP(G10,'Moves Index'!$B$3:$C$561,2,FALSE) -> Yes | I10: =VLOOKUP(G10,'Moves Index'!$B$3:$D$561,3,FALSE) -> Attacking | J10: =VLOOKUP(G10,'Moves Index'!$B$3:$E$561,4,FALSE) -> Physical | K10: Fling | L10: =VLOOKUP(K10,'Moves Index'!$B$3:$C$561,2,FALSE) -> No | M10: =VLOOKUP(K10,'Moves Index'!$B$3:$D$561,3,FALSE) -> Attacking | N10: =VLOOKUP(K10,'Moves Index'!$B$3:$E$561,4,FALSE) -> Physical | O10: X-Scissor | P10: =VLOOKUP(O10,'Moves Index'!$B$3:$C$561,2,FALSE) -> Yes | Q10: =VLOOKUP(O10,'Moves Index'!$B$3:$D$561,3,FALSE) -> Attacking | R10: =VLOOKUP(O10,'Moves Index'!$B$3:$E$561,4,FALSE) -> Physical | T10: Total Physical Moves: | U10: =((COUNTIF(F5:F30,"Physical")+COUNTIF(J5:J30,"Physical"))+COUNTIF(N5:N30,"Physical"))+COUNTIF(R5:R30,"Physical") -> 38 | W10: Total # Repeats: | Z10: =C7 -> Psyshock | AA10: =VLOOKUP(Z10,Lookup!$B$3:$C$54,2,FALSE) -> #N/A:lookupNotFound:Psyshock | AB10: =VLOOKUP(Z10,Lookup!$E$24:$F$121,2,FALSE) -> Dream Eater, Flash, Light Screen, Psychic, Psych Up, Shadow Ball, Telekinesis
C11: Hail | D11: =VLOOKUP(C11,'Moves Index'!$B$3:$C$561,2,FALSE) -> No | E11: =VLOOKUP(C11,'Moves Index'!$B$3:$D$561,3,FALSE) -> Non-Attacking | F11: =VLOOKUP(C11,'Moves Index'!$B$3:$E$561,4,FALSE) -> N/A | G11: Double Team | H11: =VLOOKUP(G11,'Moves Index'!$B$3:$C$561,2,FALSE) -> No | I11: =VLOOKUP(G11,'Moves Index'!$B$3:$D$561,3,FALSE) -> Non-Attacking | J11: =VLOOKUP(G11,'Moves Index'!$B$3:$E$561,4,FALSE) -> N/A | K11: Charge Beam | L11: =VLOOKUP(K11,'Moves Index'!$B$3:$C$561,2,FALSE) -> Yes | M11: =VLOOKUP(K11,'Moves Index'!$B$3:$D$561,3,FALSE) -> Attacking | N11: =VLOOKUP(K11,'Moves Index'!$B$3:$E$561,4,FALSE) -> Special | O11: Dragon Tail | P11: =VLOOKUP(O11,'Moves Index'!$B$3:$C$561,2,FALSE) -> Yes | Q11: =VLOOKUP(O11,'Moves Index'!$B$3:$D$561,3,FALSE) -> Attacking | R11: =VLOOKUP(O11,'Moves Index'!$B$3:$E$561,4,FALSE) -> Physical | T11: Total Special Moves: | U11: =((COUNTIF(F5:F30,"Special")+COUNTIF(J5:J30,"Special"))+COUNTIF(N5:N30,"Special"))+COUNTIF(R5:R30,"Special") -> 31 | W11: # VGM Repeats: | Z11: =C8 -> Calm Mind | AA11: =VLOOKUP(Z11,Lookup!$B$3:$C$54,2,FALSE) -> Quiver Dance | AB11: =VLOOKUP(Z11,Lookup!$E$24:$F$121,2,FALSE) -> Psych Up
C12: Bulk Up | D12: =VLOOKUP(C12,'Moves Index'!$B$3:$C$561,2,FALSE) -> Yes | E12: =VLOOKUP(C12,'Moves Index'!$B$3:$D$561,3,FALSE) -> Non-Attacking | F12: =VLOOKUP(C12,'Moves Index'!$B$3:$E$561,4,FALSE) -> N/A | G12: Reflect | H12: =VLOOKUP(G12,'Moves Index'!$B$3:$C$561,2,FALSE) -> Yes | I12: =VLOOKUP(G12,'Moves Index'!$B$3:$D$561,3,FALSE) -> Non-Attacking | J12: =VLOOKUP(G12,'Moves Index'!$B$3:$E$561,4,FALSE) -> N/A | K12: Sky Drop | L12: =VLOOKUP(K12,'Moves Index'!$B$3:$C$561,2,FALSE) -> No | M12: =VLOOKUP(K12,'Moves Index'!$B$3:$D$561,3,FALSE) -> Attacking | N12: =VLOOKUP(K12,'Moves Index'!$B$3:$E$561,4,FALSE) -> Physical | O12: Work Up | P12: =VLOOKUP(O12,'Moves Index'!$B$3:$C$561,2,FALSE) -> Yes | Q12: =VLOOKUP(O12,'Moves Index'!$B$3:$D$561,3,FALSE) -> Non-Attacking | R12: =VLOOKUP(O12,'Moves Index'!$B$3:$E$561,4,FALSE) -> N/A | Z12: =C9 -> Roar | AA12: =VLOOKUP(Z12,Lookup!$B$3:$C$54,2,FALSE) -> Whirlwind | AB12: =VLOOKUP(Z12,Lookup!$E$24:$F$121,2,FALSE) -> #N/A:lookupNotFound:Roar
C13: Venoshock | D13: =VLOOKUP(C13,'Moves Index'!$B$3:$C$561,2,FALSE) -> No | E13: =VLOOKUP(C13,'Moves Index'!$B$3:$D$561,3,FALSE) -> Attacking | F13: =VLOOKUP(C13,'Moves Index'!$B$3:$E$561,4,FALSE) -> Special | G13: Sludge Wave | H13: =VLOOKUP(G13,'Moves Index'!$B$3:$C$561,2,FALSE) -> Yes | I13: =VLOOKUP(G13,'Moves Index'!$B$3:$D$561,3,FALSE) -> Attacking | J13: =VLOOKUP(G13,'Moves Index'!$B$3:$E$561,4,FALSE) -> Special | K13: Incinerate | L13: =VLOOKUP(K13,'Moves Index'!$B$3:$C$561,2,FALSE) -> No | M13: =VLOOKUP(K13,'Moves Index'!$B$3:$D$561,3,FALSE) -> Attacking | N13: =VLOOKUP(K13,'Moves Index'!$B$3:$E$561,4,FALSE) -> Special | O13: Poison Jab | P13: =VLOOKUP(O13,'Moves Index'!$B$3:$C$561,2,FALSE) -> Yes | Q13: =VLOOKUP(O13,'Moves Index'!$B$3:$D$561,3,FALSE) -> Attacking | R13: =VLOOKUP(O13,'Moves Index'!$B$3:$E$561,4,FALSE) -> Physical | T13: Level-Up Counts | Z13: =C10 -> Toxic | AA13: =VLOOKUP(Z13,Lookup!$B$3:$C$54,2,FALSE) -> #N/A:lookupNotFound:Toxic | AB13: =VLOOKUP(Z13,Lookup!$E$24:$F$121,2,FALSE) -> #N/A:lookupNotFound:Toxic
C14: Hidden Power | D14: =VLOOKUP(C14,'Moves Index'!$B$3:$C$561,2,FALSE) -> Yes | E14: =VLOOKUP(C14,'Moves Index'!$B$3:$D$561,3,FALSE) -> Attacking | F14: =VLOOKUP(C14,'Moves Index'!$B$3:$E$561,4,FALSE) -> Special | G14: Flamethrower | H14: =VLOOKUP(G14,'Moves Index'!$B$3:$C$561,2,FALSE) -> Yes | I14: =VLOOKUP(G14,'Moves Index'!$B$3:$D$561,3,FALSE) -> Attacking | J14: =VLOOKUP(G14,'Moves Index'!$B$3:$E$561,4,FALSE) -> Special | K14: Quash | L14: =VLOOKUP(K14,'Moves Index'!$B$3:$C$561,2,FALSE) -> No | M14: =VLOOKUP(K14,'Moves Index'!$B$3:$D$561,3,FALSE) -> Non-Attacking | N14: =VLOOKUP(K14,'Moves Index'!$B$3:$E$561,4,FALSE) -> N/A | O14: Dream Eater | P14: =VLOOKUP(O14,'Moves Index'!$B$3:$C$561,2,FALSE) -> No | Q14: =VLOOKUP(O14,'Moves Index'!$B$3:$D$561,3,FALSE) -> Attacking | R14: =VLOOKUP(O14,'Moves Index'!$B$3:$E$561,4,FALSE) -> Special | T14: Total # Moves: | U14: =COUNTA(C34:C51)-X10 -> 0 | Z14: =C11 -> Hail | AA14: =VLOOKUP(Z14,Lookup!$B$3:$C$54,2,FALSE) -> #N/A:lookupNotFound:Hail | AB14: =VLOOKUP(Z14,Lookup!$E$24:$F$121,2,FALSE) -> #N/A:lookupNotFound:Hail
C15: Sunny Day | D15: =VLOOKUP(C15,'Moves Index'!$B$3:$C$561,2,FALSE) -> No | E15: =VLOOKUP(C15,'Moves Index'!$B$3:$D$561,3,FALSE) -> Non-Attacking | F15: =VLOOKUP(C15,'Moves Index'!$B$3:$E$561,4,FALSE) -> N/A | G15: Sludge Bomb | H15: =VLOOKUP(G15,'Moves Index'!$B$3:$C$561,2,FALSE) -> Yes | I15: =VLOOKUP(G15,'Moves Index'!$B$3:$D$561,3,FALSE) -> Attacking | J15: =VLOOKUP(G15,'Moves Index'!$B$3:$E$561,4,FALSE) -> Special | K15: Will-O-Wisp | L15: =VLOOKUP(K15,'Moves Index'!$B$3:$C$561,2,FALSE) -> Yes | M15: =VLOOKUP(K15,'Moves Index'!$B$3:$D$561,3,FALSE) -> Non-Attacking | N15: =VLOOKUP(K15,'Moves Index'!$B$3:$E$561,4,FALSE) -> N/A | O15: Grass Knot | P15: =VLOOKUP(O15,'Moves Index'!$B$3:$C$561,2,FALSE) -> Yes | Q15: =VLOOKUP(O15,'Moves Index'!$B$3:$D$561,3,FALSE) -> Attacking | R15: =VLOOKUP(O15,'Moves Index'!$B$3:$E$561,4,FALSE) -> Special | T15: Total # VGMs: | U15: =COUNTIF(D34:D51,"Yes") -> 0 | Z15: =C12 -> Bulk Up | AA15: =VLOOKUP(Z15,Lookup!$B$3:$C$54,2,FALSE) -> Meditate, Sharpen, Howl, Coil | AB15: =VLOOKUP(Z15,Lookup!$E$24:$F$121,2,FALSE) -> Brick Break, Focus Blast, Rock Slide, Rock Tomb
C16: Taunt | D16: =VLOOKUP(C16,'Moves Index'!$B$3:$C$561,2,FALSE) -> Yes | E16: =VLOOKUP(C16,'Moves Index'!$B$3:$D$561,3,FALSE) -> Non-Attacking | F16: =VLOOKUP(C16,'Moves Index'!$B$3:$E$561,4,FALSE) -> N/A | G16: Sandstorm | H16: =VLOOKUP(G16,'Moves Index'!$B$3:$C$561,2,FALSE) -> No | I16: =VLOOKUP(G16,'Moves Index'!$B$3:$D$561,3,FALSE) -> Non-Attacking | J16: =VLOOKUP(G16,'Moves Index'!$B$3:$E$561,4,FALSE) -> N/A | K16: Acrobatics | L16: =VLOOKUP(K16,'Moves Index'!$B$3:$C$561,2,FALSE) -> Yes | M16: =VLOOKUP(K16,'Moves Index'!$B$3:$D$561,3,FALSE) -> Attacking | N16: =VLOOKUP(K16,'Moves Index'!$B$3:$E$561,4,FALSE) -> Physical | O16: Swagger | P16: =VLOOKUP(O16,'Moves Index'!$B$3:$C$561,2,FALSE) -> No | Q16: =VLOOKUP(O16,'Moves Index'!$B$3:$D$561,3,FALSE) -> Non-Attacking | R16: =VLOOKUP(O16,'Moves Index'!$B$3:$E$561,4,FALSE) -> N/A | T16: Total Attacking Moves: | U16: =COUNTIF(E34:E51,"Attacking") -> 0 | Z16: =C13 -> Venoshock | AA16: =VLOOKUP(Z16,Lookup!$B$3:$C$54,2,FALSE) -> #N/A:lookupNotFound:Venoshock | AB16: =VLOOKUP(Z16,Lookup!$E$24:$F$121,2,FALSE) -> #N/A:lookupNotFound:Venoshock
C17: Ice Beam | D17: =VLOOKUP(C17,'Moves Index'!$B$3:$C$561,2,FALSE) -> Yes | E17: =VLOOKUP(C17,'Moves Index'!$B$3:$D$561,3,FALSE) -> Attacking | F17: =VLOOKUP(C17,'Moves Index'!$B$3:$E$561,4,FALSE) -> Special | G17: Fire Blast | H17: =VLOOKUP(G17,'Moves Index'!$B$3:$C$561,2,FALSE) -> Yes | I17: =VLOOKUP(G17,'Moves Index'!$B$3:$D$561,3,FALSE) -> Attacking | J17: =VLOOKUP(G17,'Moves Index'!$B$3:$E$561,4,FALSE) -> Special | K17: Embargo | L17: =VLOOKUP(K17,'Moves Index'!$B$3:$C$561,2,FALSE) -> No | M17: =VLOOKUP(K17,'Moves Index'!$B$3:$D$561,3,FALSE) -> Non-Attacking | N17: =VLOOKUP(K17,'Moves Index'!$B$3:$E$561,4,FALSE) -> N/A | O17: Pluck | P17: =VLOOKUP(O17,'Moves Index'!$B$3:$C$561,2,FALSE) -> No | Q17: =VLOOKUP(O17,'Moves Index'!$B$3:$D$561,3,FALSE) -> Attacking | R17: =VLOOKUP(O17,'Moves Index'!$B$3:$E$561,4,FALSE) -> Physical | T17: Total Non-Attacking Moves: | U17: =COUNTIF(E34:E51,"Non-Attacking") -> 0 | Z17: =C14 -> Hidden Power | AA17: =VLOOKUP(Z17,Lookup!$B$3:$C$54,2,FALSE) -> #N/A:lookupNotFound:Hidden Power | AB17: =VLOOKUP(Z17,Lookup!$E$24:$F$121,2,FALSE) -> #N/A:lookupNotFound:Hidden Power
C18: Blizzard | D18: =VLOOKUP(C18,'Moves Index'!$B$3:$C$561,2,FALSE) -> Yes | E18: =VLOOKUP(C18,'Moves Index'!$B$3:$D$561,3,FALSE) -> Attacking | F18: =VLOOKUP(C18,'Moves Index'!$B$3:$E$561,4,FALSE) -> Special | G18: Rock Tomb | H18: =VLOOKUP(G18,'Moves Index'!$B$3:$C$561,2,FALSE) -> No | I18: =VLOOKUP(G18,'Moves Index'!$B$3:$D$561,3,FALSE) -> Attacking | J18: =VLOOKUP(G18,'Moves Index'!$B$3:$E$561,4,FALSE) -> Physical | K18: Explosion | L18: =VLOOKUP(K18,'Moves Index'!$B$3:$C$561,2,FALSE) -> No | M18: =VLOOKUP(K18,'Moves Index'!$B$3:$D$561,3,FALSE) -> Attacking | N18: =VLOOKUP(K18,'Moves Index'!$B$3:$E$561,4,FALSE) -> Physical | O18: U-turn | P18: =VLOOKUP(O18,'Moves Index'!$B$3:$C$561,2,FALSE) -> Yes | Q18: =VLOOKUP(O18,'Moves Index'!$B$3:$D$561,3,FALSE) -> Attacking | R18: =VLOOKUP(O18,'Moves Index'!$B$3:$E$561,4,FALSE) -> Physical | T18: Total Physical Moves: | U18: =COUNTIF(F34:F51,"Physical") -> 0 | Z18: =C15 -> Sunny Day | AA18: =VLOOKUP(Z18,Lookup!$B$3:$C$54,2,FALSE) -> #N/A:lookupNotFound:Sunny Day | AB18: =VLOOKUP(Z18,Lookup!$E$24:$F$121,2,FALSE) -> #N/A:lookupNotFound:Sunny Day
C19: Hyper Beam | D19: =VLOOKUP(C19,'Moves Index'!$B$3:$C$561,2,FALSE) -> No | E19: =VLOOKUP(C19,'Moves Index'!$B$3:$D$561,3,FALSE) -> Attacking | F19: =VLOOKUP(C19,'Moves Index'!$B$3:$E$561,4,FALSE) -> Special | G19: Aerial Ace | H19: =VLOOKUP(G19,'Moves Index'!$B$3:$C$561,2,FALSE) -> Yes | I19: =VLOOKUP(G19,'Moves Index'!$B$3:$D$561,3,FALSE) -> Attacking | J19: =VLOOKUP(G19,'Moves Index'!$B$3:$E$561,4,FALSE) -> Physical | K19: Shadow Claw | L19: =VLOOKUP(K19,'Moves Index'!$B$3:$C$561,2,FALSE) -> Yes | M19: =VLOOKUP(K19,'Moves Index'!$B$3:$D$561,3,FALSE) -> Attacking | N19: =VLOOKUP(K19,'Moves Index'!$B$3:$E$561,4,FALSE) -> Physical | O19: Substitute | P19: =VLOOKUP(O19,'Moves Index'!$B$3:$C$561,2,FALSE) -> Yes | Q19: =VLOOKUP(O19,'Moves Index'!$B$3:$D$561,3,FALSE) -> Non-Attacking | R19: =VLOOKUP(O19,'Moves Index'!$B$3:$E$561,4,FALSE) -> N/A | T19: Total Special Moves: | U19: =COUNTIF(F34:F51,"Special") -> 0 | Z19: =C16 -> Taunt | AA19: =VLOOKUP(Z19,Lookup!$B$3:$C$54,2,FALSE) -> #N/A:lookupNotFound:Taunt | AB19: =VLOOKUP(Z19,Lookup!$E$24:$F$121,2,FALSE) -> #N/A:lookupNotFound:Taunt
C20: Light Screen | D20: =VLOOKUP(C20,'Moves Index'!$B$3:$C$561,2,FALSE) -> Yes | E20: =VLOOKUP(C20,'Moves Index'!$B$3:$D$561,3,FALSE) -> Non-Attacking | F20: =VLOOKUP(C20,'Moves Index'!$B$3:$E$561,4,FALSE) -> N/A | G20: Torment | H20: =VLOOKUP(G20,'Moves Index'!$B$3:$C$561,2,FALSE) -> No | I20: =VLOOKUP(G20,'Moves Index'!$B$3:$D$561,3,FALSE) -> Non-Attacking | J20: =VLOOKUP(G20,'Moves Index'!$B$3:$E$561,4,FALSE) -> N/A | K20: Payback | L20: =VLOOKUP(K20,'Moves Index'!$B$3:$C$561,2,FALSE) -> Yes | M20: =VLOOKUP(K20,'Moves Index'!$B$3:$D$561,3,FALSE) -> Attacking | N20: =VLOOKUP(K20,'Moves Index'!$B$3:$E$561,4,FALSE) -> Physical | O20: Flash Cannon | P20: =VLOOKUP(O20,'Moves Index'!$B$3:$C$561,2,FALSE) -> Yes | Q20: =VLOOKUP(O20,'Moves Index'!$B$3:$D$561,3,FALSE) -> Attacking | R20: =VLOOKUP(O20,'Moves Index'!$B$3:$E$561,4,FALSE) -> Special | Z20: =C17 -> Ice Beam | AA20: =VLOOKUP(Z20,Lookup!$B$3:$C$54,2,FALSE) -> #N/A:lookupNotFound:Ice Beam | AB20: =VLOOKUP(Z20,Lookup!$E$24:$F$121,2,FALSE) -> Blizzard
C21: Protect | D21: =VLOOKUP(C21,'Moves Index'!$B$3:$C$561,2,FALSE) -> Yes | E21: =VLOOKUP(C21,'Moves Index'!$B$3:$D$561,3,FALSE) -> Non-Attacking | F21: =VLOOKUP(C21,'Moves Index'!$B$3:$E$561,4,FALSE) -> N/A | G21: Facade | H21: =VLOOKUP(G21,'Moves Index'!$B$3:$C$561,2,FALSE) -> Yes | I21: =VLOOKUP(G21,'Moves Index'!$B$3:$D$561,3,FALSE) -> Attacking | J21: =VLOOKUP(G21,'Moves Index'!$B$3:$E$561,4,FALSE) -> Physical | K21: Retaliate | L21: =VLOOKUP(K21,'Moves Index'!$B$3:$C$561,2,FALSE) -> No | M21: =VLOOKUP(K21,'Moves Index'!$B$3:$D$561,3,FALSE) -> Attacking | N21: =VLOOKUP(K21,'Moves Index'!$B$3:$E$561,4,FALSE) -> Physical | O21: Trick Room | P21: =VLOOKUP(O21,'Moves Index'!$B$3:$C$561,2,FALSE) -> Yes | Q21: =VLOOKUP(O21,'Moves Index'!$B$3:$D$561,3,FALSE) -> Non-Attacking | R21: =VLOOKUP(O21,'Moves Index'!$B$3:$E$561,4,FALSE) -> N/A | T21: Egg Move Counts | Z21: =C18 -> Blizzard | AA21: =VLOOKUP(Z21,Lookup!$B$3:$C$54,2,FALSE) -> #N/A:lookupNotFound:Blizzard | AB21: =VLOOKUP(Z21,Lookup!$E$24:$F$121,2,FALSE) -> Ice Beam
C22: Rain Dance | D22: =VLOOKUP(C22,'Moves Index'!$B$3:$C$561,2,FALSE) -> Yes | E22: =VLOOKUP(C22,'Moves Index'!$B$3:$D$561,3,FALSE) -> Non-Attacking | F22: =VLOOKUP(C22,'Moves Index'!$B$3:$E$561,4,FALSE) -> N/A | G22: Flame Charge | H22: =VLOOKUP(G22,'Moves Index'!$B$3:$C$561,2,FALSE) -> Yes | I22: =VLOOKUP(G22,'Moves Index'!$B$3:$D$561,3,FALSE) -> Attacking | J22: =VLOOKUP(G22,'Moves Index'!$B$3:$E$561,4,FALSE) -> Physical | K22: Giga Impact | L22: =VLOOKUP(K22,'Moves Index'!$B$3:$C$561,2,FALSE) -> No | M22: =VLOOKUP(K22,'Moves Index'!$B$3:$D$561,3,FALSE) -> Attacking | N22: =VLOOKUP(K22,'Moves Index'!$B$3:$E$561,4,FALSE) -> Physical | O22: Wild Charge | P22: =VLOOKUP(O22,'Moves Index'!$B$3:$C$561,2,FALSE) -> Yes | Q22: =VLOOKUP(O22,'Moves Index'!$B$3:$D$561,3,FALSE) -> Attacking | R22: =VLOOKUP(O22,'Moves Index'!$B$3:$E$561,4,FALSE) -> Physical | T22: Total # Moves: | U22: =COUNTA(G34:G51) -> 0 | W22: Overall Counts | Z22: =C19 -> Hyper Beam | AA22: =VLOOKUP(Z22,Lookup!$B$3:$C$54,2,FALSE) -> #N/A:lookupNotFound:Hyper Beam | AB22: =VLOOKUP(Z22,Lookup!$E$24:$F$121,2,FALSE) -> #N/A:lookupNotFound:Hyper Beam
C23: Telekinesis | D23: =VLOOKUP(C23,'Moves Index'!$B$3:$C$561,2,FALSE) -> No | E23: =VLOOKUP(C23,'Moves Index'!$B$3:$D$561,3,FALSE) -> Non-Attacking | F23: =VLOOKUP(C23,'Moves Index'!$B$3:$E$561,4,FALSE) -> N/A | G23: Rest | H23: =VLOOKUP(G23,'Moves Index'!$B$3:$C$561,2,FALSE) -> Yes | I23: =VLOOKUP(G23,'Moves Index'!$B$3:$D$561,3,FALSE) -> Non-Attacking | J23: =VLOOKUP(G23,'Moves Index'!$B$3:$E$561,4,FALSE) -> N/A | K23: Rock Polish | L23: =VLOOKUP(K23,'Moves Index'!$B$3:$C$561,2,FALSE) -> Yes | M23: =VLOOKUP(K23,'Moves Index'!$B$3:$D$561,3,FALSE) -> Non-Attacking | N23: =VLOOKUP(K23,'Moves Index'!$B$3:$E$561,4,FALSE) -> N/A | O23: Rock Smash | P23: =VLOOKUP(O23,'Moves Index'!$B$3:$C$561,2,FALSE) -> No | Q23: =VLOOKUP(O23,'Moves Index'!$B$3:$D$561,3,FALSE) -> Attacking | R23: =VLOOKUP(O23,'Moves Index'!$B$3:$E$561,4,FALSE) -> Physical | T23: Total # VGMs: | U23: =COUNTIF(H34:H51,"Yes") -> 0 | W23: Absolute # Moves: | X23: =(((U6+U14)+U22)+U30)-X10 -> 137 | Z23: =C20 -> Light Screen | AA23: =VLOOKUP(Z23,Lookup!$B$3:$C$54,2,FALSE) -> #N/A:lookupNotFound:Light Screen | AB23: =VLOOKUP(Z23,Lookup!$E$24:$F$121,2,FALSE) -> #N/A:lookupNotFound:Light Screen
C24: Safeguard | D24: =VLOOKUP(C24,'Moves Index'!$B$3:$C$561,2,FALSE) -> No | E24: =VLOOKUP(C24,'Moves Index'!$B$3:$D$561,3,FALSE) -> Non-Attacking | F24: =VLOOKUP(C24,'Moves Index'!$B$3:$E$561,4,FALSE) -> N/A | G24: Attract | H24: =VLOOKUP(G24,'Moves Index'!$B$3:$C$561,2,FALSE) -> No | I24: =VLOOKUP(G24,'Moves Index'!$B$3:$D$561,3,FALSE) -> Non-Attacking | J24: =VLOOKUP(G24,'Moves Index'!$B$3:$E$561,4,FALSE) -> N/A | K24: Flash | L24: =VLOOKUP(K24,'Moves Index'!$B$3:$C$561,2,FALSE) -> No | M24: =VLOOKUP(K24,'Moves Index'!$B$3:$D$561,3,FALSE) -> Non-Attacking | N24: =VLOOKUP(K24,'Moves Index'!$B$3:$E$561,4,FALSE) -> N/A | O24: Snarl | P24: =VLOOKUP(O24,'Moves Index'!$B$3:$C$561,2,FALSE) -> No | Q24: =VLOOKUP(O24,'Moves Index'!$B$3:$D$561,3,FALSE) -> Attacking | R24: =VLOOKUP(O24,'Moves Index'!$B$3:$E$561,4,FALSE) -> Special | T24: Total Attacking Moves: | U24: =COUNTIF(I34:I45,"Attacking") -> 0 | Z24: =C21 -> Protect | AA24: =VLOOKUP(Z24,Lookup!$B$3:$C$54,2,FALSE) -> #N/A:lookupNotFound:Protect | AB24: =VLOOKUP(Z24,Lookup!$E$24:$F$121,2,FALSE) -> #N/A:lookupNotFound:Protect
C25: Frustration | D25: =VLOOKUP(C25,'Moves Index'!$B$3:$C$561,2,FALSE) -> Yes | E25: =VLOOKUP(C25,'Moves Index'!$B$3:$D$561,3,FALSE) -> Attacking | F25: =VLOOKUP(C25,'Moves Index'!$B$3:$E$561,4,FALSE) -> Physical | G25: Thief | H25: =VLOOKUP(G25,'Moves Index'!$B$3:$C$561,2,FALSE) -> No | I25: =VLOOKUP(G25,'Moves Index'!$B$3:$D$561,3,FALSE) -> Attacking | J25: =VLOOKUP(G25,'Moves Index'!$B$3:$E$561,4,FALSE) -> Physical | K25: Stone Edge | L25: =VLOOKUP(K25,'Moves Index'!$B$3:$C$561,2,FALSE) -> Yes | M25: =VLOOKUP(K25,'Moves Index'!$B$3:$D$561,3,FALSE) -> Attacking | N25: =VLOOKUP(K25,'Moves Index'!$B$3:$E$561,4,FALSE) -> Physical | O25: Cut | P25: =VLOOKUP(O25,'Moves Index'!$B$3:$C$561,2,FALSE) -> No | Q25: =VLOOKUP(O25,'Moves Index'!$B$3:$D$561,3,FALSE) -> Attacking | R25: =VLOOKUP(O25,'Moves Index'!$B$3:$E$561,4,FALSE) -> Physical | T25: Total Non-Attacking Moves: | U25: =COUNTIF(I34:I45,"Non-Attacking") -> 0 | W25: Absolute # VGMs: | X25: =((((U7+U15)+U23)+U31)-X6)-X11 -> 83 | Z25: =C22 -> Rain Dance | AA25: =VLOOKUP(Z25,Lookup!$B$3:$C$54,2,FALSE) -> #N/A:lookupNotFound:Rain Dance | AB25: =VLOOKUP(Z25,Lookup!$E$24:$F$121,2,FALSE) -> #N/A:lookupNotFound:Rain Dance
C26: SolarBeam | D26: =VLOOKUP(C26,'Moves Index'!$B$3:$C$561,2,FALSE) -> No | E26: =VLOOKUP(C26,'Moves Index'!$B$3:$D$561,3,FALSE) -> Attacking | F26: =VLOOKUP(C26,'Moves Index'!$B$3:$E$561,4,FALSE) -> Special | G26: Low Sweep | H26: =VLOOKUP(G26,'Moves Index'!$B$3:$C$561,2,FALSE) -> No | I26: =VLOOKUP(G26,'Moves Index'!$B$3:$D$561,3,FALSE) -> Attacking | J26: =VLOOKUP(G26,'Moves Index'!$B$3:$E$561,4,FALSE) -> Physical | K26: Volt Switch | L26: =VLOOKUP(K26,'Moves Index'!$B$3:$C$561,2,FALSE) -> Yes | M26: =VLOOKUP(K26,'Moves Index'!$B$3:$D$561,3,FALSE) -> Attacking | N26: =VLOOKUP(K26,'Moves Index'!$B$3:$E$561,4,FALSE) -> Special | O26: Fly | P26: =VLOOKUP(O26,'Moves Index'!$B$3:$C$561,2,FALSE) -> No | Q26: =VLOOKUP(O26,'Moves Index'!$B$3:$D$561,3,FALSE) -> Attacking | R26: =VLOOKUP(O26,'Moves Index'!$B$3:$E$561,4,FALSE) -> Physical | T26: Total Physical Moves: | U26: =COUNTIF(J34:J51,"Physical") -> 0 | Z26: =C23 -> Telekinesis | AA26: =VLOOKUP(Z26,Lookup!$B$3:$C$54,2,FALSE) -> #N/A:lookupNotFound:Telekinesis | AB26: =VLOOKUP(Z26,Lookup!$E$24:$F$121,2,FALSE) -> #N/A:lookupNotFound:Telekinesis
C27: Smack Down | D27: =VLOOKUP(C27,'Moves Index'!$B$3:$C$561,2,FALSE) -> No | E27: =VLOOKUP(C27,'Moves Index'!$B$3:$D$561,3,FALSE) -> Attacking | F27: =VLOOKUP(C27,'Moves Index'!$B$3:$E$561,4,FALSE) -> Physical | G27: Round | H27: =VLOOKUP(G27,'Moves Index'!$B$3:$C$561,2,FALSE) -> No | I27: =VLOOKUP(G27,'Moves Index'!$B$3:$D$561,3,FALSE) -> Attacking | J27: =VLOOKUP(G27,'Moves Index'!$B$3:$E$561,4,FALSE) -> Special | K27: Thunder Wave | L27: =VLOOKUP(K27,'Moves Index'!$B$3:$C$561,2,FALSE) -> Yes | M27: =VLOOKUP(K27,'Moves Index'!$B$3:$D$561,3,FALSE) -> Non-Attacking | N27: =VLOOKUP(K27,'Moves Index'!$B$3:$E$561,4,FALSE) -> N/A | O27: Surf | P27: =VLOOKUP(O27,'Moves Index'!$B$3:$C$561,2,FALSE) -> Yes | Q27: =VLOOKUP(O27,'Moves Index'!$B$3:$D$561,3,FALSE) -> Attacking | R27: =VLOOKUP(O27,'Moves Index'!$B$3:$E$561,4,FALSE) -> Special | T27: Total Special Moves: | U27: =COUNTIF(J34:J51,"Special") -> 0 | W27: Total Attacking Moves: | X27: =((U8+U16)+U24)+U32 -> 92 | Z27: =C24 -> Safeguard | AA27: =VLOOKUP(Z27,Lookup!$B$3:$C$54,2,FALSE) -> #N/A:lookupNotFound:Safeguard | AB27: =VLOOKUP(Z27,Lookup!$E$24:$F$121,2,FALSE) -> #N/A:lookupNotFound:Safeguard
C28: Thunderbolt | D28: =VLOOKUP(C28,'Moves Index'!$B$3:$C$561,2,FALSE) -> Yes | E28: =VLOOKUP(C28,'Moves Index'!$B$3:$D$561,3,FALSE) -> Attacking | F28: =VLOOKUP(C28,'Moves Index'!$B$3:$E$561,4,FALSE) -> Special | G28: Echoed Voice | H28: =VLOOKUP(G28,'Moves Index'!$B$3:$C$561,2,FALSE) -> No | I28: =VLOOKUP(G28,'Moves Index'!$B$3:$D$561,3,FALSE) -> Attacking | J28: =VLOOKUP(G28,'Moves Index'!$B$3:$E$561,4,FALSE) -> Special | K28: Gyro Ball | L28: =VLOOKUP(K28,'Moves Index'!$B$3:$C$561,2,FALSE) -> Yes | M28: =VLOOKUP(K28,'Moves Index'!$B$3:$D$561,3,FALSE) -> Attacking | N28: =VLOOKUP(K28,'Moves Index'!$B$3:$E$561,4,FALSE) -> Physical | O28: Strength | P28: =VLOOKUP(O28,'Moves Index'!$B$3:$C$561,2,FALSE) -> No | Q28: =VLOOKUP(O28,'Moves Index'!$B$3:$D$561,3,FALSE) -> Attacking | R28: =VLOOKUP(O28,'Moves Index'!$B$3:$E$561,4,FALSE) -> Physical | W28: Total Non-Attacking Moves: | X28: =((U9+U17)+U25)+U33 -> 45 | Z28: =C25 -> Frustration | AA28: =VLOOKUP(Z28,Lookup!$B$3:$C$54,2,FALSE) -> Return | AB28: =VLOOKUP(Z28,Lookup!$E$24:$F$121,2,FALSE) -> #N/A:lookupNotFound:Frustration
C29: Thunder | D29: =VLOOKUP(C29,'Moves Index'!$B$3:$C$561,2,FALSE) -> Yes | E29: =VLOOKUP(C29,'Moves Index'!$B$3:$D$561,3,FALSE) -> Attacking | F29: =VLOOKUP(C29,'Moves Index'!$B$3:$E$561,4,FALSE) -> Special | G29: Overheat | H29: =VLOOKUP(G29,'Moves Index'!$B$3:$C$561,2,FALSE) -> Yes | I29: =VLOOKUP(G29,'Moves Index'!$B$3:$D$561,3,FALSE) -> Attacking | J29: =VLOOKUP(G29,'Moves Index'!$B$3:$E$561,4,FALSE) -> Special | K29: Swords Dance | L29: =VLOOKUP(K29,'Moves Index'!$B$3:$C$561,2,FALSE) -> Yes | M29: =VLOOKUP(K29,'Moves Index'!$B$3:$D$561,3,FALSE) -> Non-Attacking | N29: =VLOOKUP(K29,'Moves Index'!$B$3:$E$561,4,FALSE) -> N/A | O29: Waterfall | P29: =VLOOKUP(O29,'Moves Index'!$B$3:$C$561,2,FALSE) -> Yes | Q29: =VLOOKUP(O29,'Moves Index'!$B$3:$D$561,3,FALSE) -> Attacking | R29: =VLOOKUP(O29,'Moves Index'!$B$3:$E$561,4,FALSE) -> Physical | T29: Move Tutor Counts | W29: Total Physical Moves: | X29: =((U10+U18)+U26)+U34 -> 55 | Z29: =C26 -> SolarBeam | AA29: =VLOOKUP(Z29,Lookup!$B$3:$C$54,2,FALSE) -> #N/A:lookupNotFound:SolarBeam | AB29: =VLOOKUP(Z29,Lookup!$E$24:$F$121,2,FALSE) -> #N/A:lookupNotFound:SolarBeam
O30: Dive | P30: =VLOOKUP(O30,'Moves Index'!$B$3:$C$561,2,FALSE) -> No | Q30: =VLOOKUP(O30,'Moves Index'!$B$3:$D$561,3,FALSE) -> Attacking | R30: =VLOOKUP(O30,'Moves Index'!$B$3:$E$561,4,FALSE) -> Physical | T30: Total # Moves: | U30: =COUNTA(K34:K51)+COUNTA(O34:O51) -> 36 | W30: Total Special Moves: | X30: =((U11+U19)+U27)+U35 -> 39 | Z30: =C27 -> Smack Down | AA30: =VLOOKUP(Z30,Lookup!$B$3:$C$54,2,FALSE) -> #N/A:lookupNotFound:Smack Down | AB30: =VLOOKUP(Z30,Lookup!$E$24:$F$121,2,FALSE) -> #N/A:lookupNotFound:Smack Down
T31: Total # VGMs: | U31: =COUNTIF(L34:L51,"Yes")+COUNTIF(P34:P51,"Yes") -> 23 | Z31: =C28 -> Thunderbolt | AA31: =VLOOKUP(Z31,Lookup!$B$3:$C$54,2,FALSE) -> #N/A:lookupNotFound:Thunderbolt | AB31: =VLOOKUP(Z31,Lookup!$E$24:$F$121,2,FALSE) -> Thunder
B32: Level-Up | G32: Egg Moves | K32: Move Tutors | T32: Total Attacking Moves: | U32: =COUNTIF(M34:M51,"Attacking")+COUNTIF(Q34:Q51,"Attacking") -> 23 | Z32: =C29 -> Thunder | AA32: =VLOOKUP(Z32,Lookup!$B$3:$C$54,2,FALSE) -> #N/A:lookupNotFound:Thunder | AB32: =VLOOKUP(Z32,Lookup!$E$24:$F$121,2,FALSE) -> Thunderbolt
B33: Level | C33: Move | D33: VGM? | E33: Type | F33: Category | G33: Move | H33: VGM? | I33: Type | J33: Category | K33: Move | L33: VGM? | M33: Type | N33: Category | O33: Move | P33: VGM? | Q33: Type | R33: Category | T33: Total Non-Attacking Moves: | U33: =COUNTIF(M34:M51,"Non-Attacking")+COUNTIF(Q34:Q51,"Non-Attacking") -> 13 | Z33: =G5 -> Earthquake | AA33: =VLOOKUP(Z33,Lookup!$B$3:$C$54,2,FALSE) -> #N/A:lookupNotFound:Earthquake | AB33: =VLOOKUP(Z33,Lookup!$E$24:$F$121,2,FALSE) -> Bulldoze
D34: =VLOOKUP(C34,'Moves Index'!$B$3:$C$561,2,FALSE) -> #N/A:blankIndicator: | E34: =VLOOKUP(C34,'Moves Index'!$B$3:$D$561,3,FALSE) -> #N/A:blankIndicator: | F34: =VLOOKUP(C34,'Moves Index'!$B$3:$E$561,4,FALSE) -> #N/A:blankIndicator: | H34: =VLOOKUP(G34,'Moves Index'!$B$3:$C$561,2,FALSE) -> #N/A:blankIndicator: | I34: =VLOOKUP(G34,'Moves Index'!$B$3:$D$561,3,FALSE) -> #N/A:blankIndicator: | J34: =VLOOKUP(G34,'Moves Index'!$B$3:$E$561,4,FALSE) -> #N/A:blankIndicator: | K34: After You | L34: =VLOOKUP(K34,'Moves Index'!$B$3:$C$561,2,FALSE) -> No | M34: =VLOOKUP(K34,'Moves Index'!$B$3:$D$561,3,FALSE) -> Non-Attacking | N34: =VLOOKUP(K34,'Moves Index'!$B$3:$E$561,4,FALSE) -> N/A | O34: Iron Head | P34: =VLOOKUP(O34,'Moves Index'!$B$3:$C$561,2,FALSE) -> Yes | Q34: =VLOOKUP(O34,'Moves Index'!$B$3:$D$561,3,FALSE) -> Attacking | R34: =VLOOKUP(O34,'Moves Index'!$B$3:$E$561,4,FALSE) -> Physical | T34: Total Physical Moves: | U34: =COUNTIF(N34:N51,"Physical")+COUNTIF(R34:R51,"Physical") -> 17 | Z34: =G6 -> Return | AA34: =VLOOKUP(Z34,Lookup!$B$3:$C$54,2,FALSE) -> Frustration | AB34: =VLOOKUP(Z34,Lookup!$E$24:$F$121,2,FALSE) -> #N/A:lookupNotFound:Return
D35: =VLOOKUP(C35,'Moves Index'!$B$3:$C$561,2,FALSE) -> #N/A:blankIndicator: | E35: =VLOOKUP(C35,'Moves Index'!$B$3:$D$561,3,FALSE) -> #N/A:blankIndicator: | F35: =VLOOKUP(C35,'Moves Index'!$B$3:$E$561,4,FALSE) -> #N/A:blankIndicator: | H35: =VLOOKUP(G35,'Moves Index'!$B$3:$C$561,2,FALSE) -> #N/A:blankIndicator: | I35: =VLOOKUP(G35,'Moves Index'!$B$3:$D$561,3,FALSE) -> #N/A:blankIndicator: | J35: =VLOOKUP(G35,'Moves Index'!$B$3:$E$561,4,FALSE) -> #N/A:blankIndicator: | K35: Aqua Tail | L35: =VLOOKUP(K35,'Moves Index'!$B$3:$C$561,2,FALSE) -> Yes | M35: =VLOOKUP(K35,'Moves Index'!$B$3:$D$561,3,FALSE) -> Attacking | N35: =VLOOKUP(K35,'Moves Index'!$B$3:$E$561,4,FALSE) -> Physical | O35: Iron Tail | P35: =VLOOKUP(O35,'Moves Index'!$B$3:$C$561,2,FALSE) -> Yes | Q35: =VLOOKUP(O35,'Moves Index'!$B$3:$D$561,3,FALSE) -> Attacking | R35: =VLOOKUP(O35,'Moves Index'!$B$3:$E$561,4,FALSE) -> Physical | T35: Total Special Moves: | U35: =COUNTIF(N34:N51,"Special")+COUNTIF(R34:R51,"Special") -> 8 | Z35: =G7 -> Dig | AA35: =VLOOKUP(Z35,Lookup!$B$3:$C$54,2,FALSE) -> #N/A:lookupNotFound:Dig | AB35: =VLOOKUP(Z35,Lookup!$E$24:$F$121,2,FALSE) -> #N/A:lookupNotFound:Dig
D36: =VLOOKUP(C36,'Moves Index'!$B$3:$C$561,2,FALSE) -> #N/A:blankIndicator: | E36: =VLOOKUP(C36,'Moves Index'!$B$3:$D$561,3,FALSE) -> #N/A:blankIndicator: | F36: =VLOOKUP(C36,'Moves Index'!$B$3:$E$561,4,FALSE) -> #N/A:blankIndicator: | H36: =VLOOKUP(G36,'Moves Index'!$B$3:$C$561,2,FALSE) -> #N/A:blankIndicator: | I36: =VLOOKUP(G36,'Moves Index'!$B$3:$D$561,3,FALSE) -> #N/A:blankIndicator: | J36: =VLOOKUP(G36,'Moves Index'!$B$3:$E$561,4,FALSE) -> #N/A:blankIndicator: | K36: Bind | L36: =VLOOKUP(K36,'Moves Index'!$B$3:$C$561,2,FALSE) -> No | M36: =VLOOKUP(K36,'Moves Index'!$B$3:$D$561,3,FALSE) -> Attacking | N36: =VLOOKUP(K36,'Moves Index'!$B$3:$E$561,4,FALSE) -> Physical | O36: Knock Off | P36: =VLOOKUP(O36,'Moves Index'!$B$3:$C$561,2,FALSE) -> Yes | Q36: =VLOOKUP(O36,'Moves Index'!$B$3:$D$561,3,FALSE) -> Non-Attacking | R36: =VLOOKUP(O36,'Moves Index'!$B$3:$E$561,4,FALSE) -> Physical | Z36: =G8 -> Psychic | AA36: =VLOOKUP(Z36,Lookup!$B$3:$C$54,2,FALSE) -> #N/A:lookupNotFound:Psychic | AB36: =VLOOKUP(Z36,Lookup!$E$24:$F$121,2,FALSE) -> #N/A:lookupNotFound:Psychic
D37: =VLOOKUP(C37,'Moves Index'!$B$3:$C$561,2,FALSE) -> #N/A:blankIndicator: | E37: =VLOOKUP(C37,'Moves Index'!$B$3:$D$561,3,FALSE) -> #N/A:blankIndicator: | F37: =VLOOKUP(C37,'Moves Index'!$B$3:$E$561,4,FALSE) -> #N/A:blankIndicator: | H37: =VLOOKUP(G37,'Moves Index'!$B$3:$C$561,2,FALSE) -> #N/A:blankIndicator: | I37: =VLOOKUP(G37,'Moves Index'!$B$3:$D$561,3,FALSE) -> #N/A:blankIndicator: | J37: =VLOOKUP(G37,'Moves Index'!$B$3:$E$561,4,FALSE) -> #N/A:blankIndicator: | K37: Blast Burn | L37: =VLOOKUP(K37,'Moves Index'!$B$3:$C$561,2,FALSE) -> No | M37: =VLOOKUP(K37,'Moves Index'!$B$3:$D$561,3,FALSE) -> Attacking | N37: =VLOOKUP(K37,'Moves Index'!$B$3:$E$561,4,FALSE) -> Special | O37: Last Resort | P37: =VLOOKUP(O37,'Moves Index'!$B$3:$C$561,2,FALSE) -> No | Q37: =VLOOKUP(O37,'Moves Index'!$B$3:$D$561,3,FALSE) -> Attacking | R37: =VLOOKUP(O37,'Moves Index'!$B$3:$E$561,4,FALSE) -> Physical | T37: Instruction Manual | Z37: =G9 -> Shadow Ball | AA37: =VLOOKUP(Z37,Lookup!$B$3:$C$54,2,FALSE) -> #N/A:lookupNotFound:Shadow Ball | AB37: =VLOOKUP(Z37,Lookup!$E$24:$F$121,2,FALSE) -> #N/A:lookupNotFound:Shadow Ball
D38: =VLOOKUP(C38,'Moves Index'!$B$3:$C$561,2,FALSE) -> #N/A:blankIndicator: | E38: =VLOOKUP(C38,'Moves Index'!$B$3:$D$561,3,FALSE) -> #N/A:blankIndicator: | F38: =VLOOKUP(C38,'Moves Index'!$B$3:$E$561,4,FALSE) -> #N/A:blankIndicator: | H38: =VLOOKUP(G38,'Moves Index'!$B$3:$C$561,2,FALSE) -> #N/A:blankIndicator: | I38: =VLOOKUP(G38,'Moves Index'!$B$3:$D$561,3,FALSE) -> #N/A:blankIndicator: | J38: =VLOOKUP(G38,'Moves Index'!$B$3:$E$561,4,FALSE) -> #N/A:blankIndicator: | K38: Block | L38: =VLOOKUP(K38,'Moves Index'!$B$3:$C$561,2,FALSE) -> Yes | M38: =VLOOKUP(K38,'Moves Index'!$B$3:$D$561,3,FALSE) -> Non-Attacking | N38: =VLOOKUP(K38,'Moves Index'!$B$3:$E$561,4,FALSE) -> N/A | O38: Low Kick | P38: =VLOOKUP(O38,'Moves Index'!$B$3:$C$561,2,FALSE) -> Yes | Q38: =VLOOKUP(O38,'Moves Index'!$B$3:$D$561,3,FALSE) -> Attacking | R38: =VLOOKUP(O38,'Moves Index'!$B$3:$E$561,4,FALSE) -> Physical | T38: Hallo there! This is a new widget I've been building to help movepool-makers with VGM counting and other annoying things. Firstly, if you look at the tabs below, you have easy access to all the lists of TM and Move Tutor moves, all Very Good Moves, all Outclassed/Equivalent moves, and all Type-Move and Move-Move Guidelines currently in existence. This device will tell you whether or not a move is a VGM when you put it in the calculator, count the total number, and all the other little things you can see above. It'll also tell you which moves in your movepool have doubles or move requirements when you add them to your movepool (see right). You have enough space on the left for all TMs, all Move Tutors, 18 level-up moves and 12 Egg moves. Here's how to use the calculator: | Z38: =G10 -> Brick Break | AA38: =VLOOKUP(Z38,Lookup!$B$3:$C$54,2,FALSE) -> #N/A:lookupNotFound:Brick Break | AB38: =VLOOKUP(Z38,Lookup!$E$24:$F$121,2,FALSE) -> Fling
D39: =VLOOKUP(C39,'Moves Index'!$B$3:$C$561,2,FALSE) -> #N/A:blankIndicator: | E39: =VLOOKUP(C39,'Moves Index'!$B$3:$D$561,3,FALSE) -> #N/A:blankIndicator: | F39: =VLOOKUP(C39,'Moves Index'!$B$3:$E$561,4,FALSE) -> #N/A:blankIndicator: | H39: =VLOOKUP(G39,'Moves Index'!$B$3:$C$561,2,FALSE) -> #N/A:blankIndicator: | I39: =VLOOKUP(G39,'Moves Index'!$B$3:$D$561,3,FALSE) -> #N/A:blankIndicator: | J39: =VLOOKUP(G39,'Moves Index'!$B$3:$E$561,4,FALSE) -> #N/A:blankIndicator: | K39: Bounce | L39: =VLOOKUP(K39,'Moves Index'!$B$3:$C$561,2,FALSE) -> Yes | M39: =VLOOKUP(K39,'Moves Index'!$B$3:$D$561,3,FALSE) -> Attacking | N39: =VLOOKUP(K39,'Moves Index'!$B$3:$E$561,4,FALSE) -> Physical | O39: Magic Coat | P39: =VLOOKUP(O39,'Moves Index'!$B$3:$C$561,2,FALSE) -> Yes | Q39: =VLOOKUP(O39,'Moves Index'!$B$3:$D$561,3,FALSE) -> Non-Attacking | R39: =VLOOKUP(O39,'Moves Index'!$B$3:$E$561,4,FALSE) -> N/A | Z39: =G11 -> Double Team | AA39: =VLOOKUP(Z39,Lookup!$B$3:$C$54,2,FALSE) -> #N/A:lookupNotFound:Double Team | AB39: =VLOOKUP(Z39,Lookup!$E$24:$F$121,2,FALSE) -> #N/A:lookupNotFound:Double Team
D40: =VLOOKUP(C40,'Moves Index'!$B$3:$C$561,2,FALSE) -> #N/A:blankIndicator: | E40: =VLOOKUP(C40,'Moves Index'!$B$3:$D$561,3,FALSE) -> #N/A:blankIndicator: | F40: =VLOOKUP(C40,'Moves Index'!$B$3:$E$561,4,FALSE) -> #N/A:blankIndicator: | H40: =VLOOKUP(G40,'Moves Index'!$B$3:$C$561,2,FALSE) -> #N/A:blankIndicator: | I40: =VLOOKUP(G40,'Moves Index'!$B$3:$D$561,3,FALSE) -> #N/A:blankIndicator: | J40: =VLOOKUP(G40,'Moves Index'!$B$3:$E$561,4,FALSE) -> #N/A:blankIndicator: | K40: Bug Bite | L40: =VLOOKUP(K40,'Moves Index'!$B$3:$C$561,2,FALSE) -> No | M40: =VLOOKUP(K40,'Moves Index'!$B$3:$D$561,3,FALSE) -> Attacking | N40: =VLOOKUP(K40,'Moves Index'!$B$3:$E$561,4,FALSE) -> Physical | O40: Magic Room | P40: =VLOOKUP(O40,'Moves Index'!$B$3:$C$561,2,FALSE) -> No | Q40: =VLOOKUP(O40,'Moves Index'!$B$3:$D$561,3,FALSE) -> Non-Attacking | R40: =VLOOKUP(O40,'Moves Index'!$B$3:$E$561,4,FALSE) -> N/A | Z40: =G12 -> Reflect | AA40: =VLOOKUP(Z40,Lookup!$B$3:$C$54,2,FALSE) -> #N/A:lookupNotFound:Reflect | AB40: =VLOOKUP(Z40,Lookup!$E$24:$F$121,2,FALSE) -> #N/A:lookupNotFound:Reflect
D41: =VLOOKUP(C41,'Moves Index'!$B$3:$C$561,2,FALSE) -> #N/A:blankIndicator: | E41: =VLOOKUP(C41,'Moves Index'!$B$3:$D$561,3,FALSE) -> #N/A:blankIndicator: | F41: =VLOOKUP(C41,'Moves Index'!$B$3:$E$561,4,FALSE) -> #N/A:blankIndicator: | H41: =VLOOKUP(G41,'Moves Index'!$B$3:$C$561,2,FALSE) -> #N/A:blankIndicator: | I41: =VLOOKUP(G41,'Moves Index'!$B$3:$D$561,3,FALSE) -> #N/A:blankIndicator: | J41: =VLOOKUP(G41,'Moves Index'!$B$3:$E$561,4,FALSE) -> #N/A:blankIndicator: | K41: Covet | L41: =VLOOKUP(K41,'Moves Index'!$B$3:$C$561,2,FALSE) -> No | M41: =VLOOKUP(K41,'Moves Index'!$B$3:$D$561,3,FALSE) -> Attacking | N41: =VLOOKUP(K41,'Moves Index'!$B$3:$E$561,4,FALSE) -> Physical | O41: Magnet Rise | P41: =VLOOKUP(O41,'Moves Index'!$B$3:$C$561,2,FALSE) -> Yes | Q41: =VLOOKUP(O41,'Moves Index'!$B$3:$D$561,3,FALSE) -> Non-Attacking | R41: =VLOOKUP(O41,'Moves Index'!$B$3:$E$561,4,FALSE) -> N/A | Z41: =G13 -> Sludge Wave | AA41: =VLOOKUP(Z41,Lookup!$B$3:$C$54,2,FALSE) -> #N/A:lookupNotFound:Sludge Wave | AB41: =VLOOKUP(Z41,Lookup!$E$24:$F$121,2,FALSE) -> Sludge Bomb
D42: =VLOOKUP(C42,'Moves Index'!$B$3:$C$561,2,FALSE) -> #N/A:blankIndicator: | E42: =VLOOKUP(C42,'Moves Index'!$B$3:$D$561,3,FALSE) -> #N/A:blankIndicator: | F42: =VLOOKUP(C42,'Moves Index'!$B$3:$E$561,4,FALSE) -> #N/A:blankIndicator: | H42: =VLOOKUP(G42,'Moves Index'!$B$3:$C$561,2,FALSE) -> #N/A:blankIndicator: | I42: =VLOOKUP(G42,'Moves Index'!$B$3:$D$561,3,FALSE) -> #N/A:blankIndicator: | J42: =VLOOKUP(G42,'Moves Index'!$B$3:$E$561,4,FALSE) -> #N/A:blankIndicator: | K42: Dark Pulse | L42: =VLOOKUP(K42,'Moves Index'!$B$3:$C$561,2,FALSE) -> Yes | M42: =VLOOKUP(K42,'Moves Index'!$B$3:$D$561,3,FALSE) -> Attacking | N42: =VLOOKUP(K42,'Moves Index'!$B$3:$E$561,4,FALSE) -> Special | O42: Outrage | P42: =VLOOKUP(O42,'Moves Index'!$B$3:$C$561,2,FALSE) -> Yes | Q42: =VLOOKUP(O42,'Moves Index'!$B$3:$D$561,3,FALSE) -> Attacking | R42: =VLOOKUP(O42,'Moves Index'!$B$3:$E$561,4,FALSE) -> Physical | Z42: =G14 -> Flamethrower | AA42: =VLOOKUP(Z42,Lookup!$B$3:$C$54,2,FALSE) -> #N/A:lookupNotFound:Flamethrower | AB42: =VLOOKUP(Z42,Lookup!$E$24:$F$121,2,FALSE) -> Incinerate
...

Sheet Move Tutors, TMs and HMs
B3: Technical Machines and Hidden Machines
B4: TM01 Hone Claws | C4: TM26 Earthquake | D4: TM51 Ally Switch | E4: TM76 Struggle Bug
B5: TM02 Dragon Claw | C5: TM27 Return | D5: TM52 Focus Blast | E5: TM77 Psych Up
B6: TM03 Psyshock | C6: TM28 Dig | D6: TM53 Energy Ball | E6: TM78 Bulldoze
B7: TM04 Calm Mind | C7: TM29 Psychic | D7: TM54 False Swipe | E7: TM79 Frost Breath
B8: TM05 Roar | C8: TM30 Shadow Ball | D8: TM55 Scald | E8: TM80 Rock Slide
B9: TM06 Toxic | C9: TM31 Brick Break | D9: TM56 Fling | E9: TM81 X-Scissor
B10: TM07 Hail | C10: TM32 Double Team | D10: TM57 Charge Beam | E10: TM82 Dragon Tail
B11: TM08 Bulk Up | C11: TM33 Reflect | D11: TM58 Sky Drop | E11: TM83 Work Up
B12: TM09 Venoshock | C12: TM34 Sludge Wave | D12: TM59 Incinerate | E12: TM84 Poison Jab
B13: TM10 Hidden Power | C13: TM35 Flamethrower | D13: TM60 Quash | E13: TM85 Dream Eater
B14: TM11 Sunny Day | C14: TM36 Sludge Bomb | D14: TM61 Will-O-Wisp | E14: TM86 Grass Knot
B15: TM12 Taunt | C15: TM37 Sandstorm | D15: TM62 Acrobatics | E15: TM87 Swagger | G15: Bold: Present on most fully-evolved Pokemon.
B16: TM13 Ice Beam | C16: TM38 Fire Blast | D16: TM63 Embargo | E16: TM88 Pluck
B17: TM14 Blizzard | C17: TM39 Rock Tomb | D17: TM64 Explosion | E17: TM89 U-turn
B18: TM15 Hyper Beam | C18: TM40 Aerial Ace | D18: TM65 Shadow Claw | E18: TM90 Substitute
B19: TM16 Light Screen | C19: TM41 Torment | D19: TM66 Payback | E19: TM91 Flash Cannon
B20: TM17 Protect | C20: TM42 Facade | D20: TM67 Retaliate | E20: TM92 Trick Room
B21: TM18 Rain Dance | C21: TM43 Flame Charge | D21: TM68 Giga Impact | E21: TM93 Wild Charge
B22: TM19 Telekinesis | C22: TM44 Rest | D22: TM69 Rock Polish | E22: TM94 Rock Smash
B23: TM20 Safeguard | C23: TM45 Attract | D23: TM70 Flash | E23: TM95 Snarl
B24: TM21 Frustration | C24: TM46 Thief | D24: TM71 Stone Edge | E24: HM01 Cut
B25: TM22 SolarBeam | C25: TM47 Low Sweep | D25: TM72 Volt Switch | E25: HM02 Fly
B26: TM23 Smack Down | C26: TM48 Round | D26: TM73 Thunder Wave | E26: HM03 Surf
B27: TM24 Thunderbolt | C27: TM49 Echoed Voice | D27: TM74 Gyro Ball | E27: HM04 Strength
B28: TM25 Thunder | C28: TM50 Overheat | D28: TM75 Swords Dance | E28: HM05 Waterfall
E29: HM06 Dive
B31: Move Tutors
B32: After You | C32: Dragon Pulse | D32: Frenzy Plant | E32: Hyper Voice | F32: Magic Room | G32: Sky Attack | H32: Thunderpunch
B33: Aqua Tail | C33: Drain Punch | D33: Gastro Acid | E33: Ice Punch | F33: Magnet Rise | G33: Sleep Talk | H33: Trick
B34: Bind | C34: Drill Run | D34: Giga Drain | E34: Icy Wind | F34: Outrage | G34: Snatch | H34: Uproar
B35: Blast Burn | C35: Dual Chop | D35: Grass Pledge | E35: Iron Defense | F35: Pain Split | G35: Snore | H35: Water Pledge
B36: Block | C36: Earth Power | D36: Gravity | E36: Iron Head | F36: Recycle | G36: Spite | H36: Wonder Room
B37: Bounce | C37: Electroweb | D37: Gunk Shot | E37: Iron Tail | F37: Role Play | G37: Stealth Rock | H37: Worry Seed
B38: Bug Bite | C38: Endeavor | D38: Heal Bell | E38: Knock Off | F38: Roost | G38: Super Fang | H38: Zen Headbutt
B39: Covet | C39: Fire Pledge | D39: Heat Wave | E39: Last Resort | F39: Seed Bomb | G39: Superpower
B40: Dark Pulse | C40: Fire Punch | D40: Helping Hand | E40: Low Kick | F40: Signal Beam | G40: Synthesis
B41: Draco Meteor | C41: Foul Play | D41: Hydro Cannon | E41: Magic Coat | F41: Skill Swap | G41: Tailwind

Sheet All Very Good Moves
B2: Competitive Physical Attacking Moves
B3: Bug | C3: Fighting | D3: Flying | E3: Ice | F3: Psychic
B4: Attack Order | C4: Brick Break | D4: Acrobatics | E4: Avalanche | F4: Zen Headbutt
B5: Megahorn | C5: Circle Throw | D5: Aerial Ace | E5: Freeze Shock | F5: Rock
B6: U-turn | C6: Close Combat | D6: Bounce | E6: Ice Shard | F6: Head Smash
B7: X-Scissor | C7: Cross Chop | D7: Brave Bird | E7: Ice Punch | F7: Rock Slide
B8: Dark | C8: Drain Punch | D8: Drill Peck | E8: Ice Fang | F8: Rock Blast
B9: Crunch | C9: Focus Punch | D9: Ghost | E9: Icicle Crash | F9: Stone Edge
B10: Foul Play | C10: Hammer Arm | D10: Shadow Claw | E10: Icicle Spear | F10: Steel
B11: Night Slash | C11: Hi Jump Kick | D11: Shadow Force | E11: Normal | F11: Bullet Punch
B12: Payback | C12: Jump Kick | D12: Shadow Punch | E12: Body Slam | F12: Gear Grind
B13: Pursuit | C13: Low Kick | D13: Shadow Sneak | E13: DoubleEdge | F13: Gyro Ball
B14: Sucker Punch | C14: Mach Punch | D14: ShadowStrike | E14: ExtremeSpeed | F14: Heavy Slam
... B22: Bolt Strike | C22: Blaze Kick | D22: Ground | E22: Return | F22: Waterfall
B23: Fusion Bolt | C23: Flame Charge | D23: Bone Rush | E23: Tail Slap
B24: Spark | C24: Flare Blitz | D24: Bonemerang | E24: Thrash
B25: Thunder Fang | C25: Fire Punch | D25: Drill Run | E25: Poison
B26: ThunderPunch | C26: Fire Fang | D26: Earthquake | E26: Cross Poison
B27: Volt Tackle | C27: Heat Crash | D27: Nature Power | E27: Gunk Shot
B28: Wild Charge | C28: Sacred Fire | E28: Poison Jab
C29: V-create
B31: Competitive Special Attacking Moves
B32: Bug | C32: Fire | D32: Ground | E32: Psychic
B33: Bug Buzz | C33: Blue Flare | D33: Earth Power | E33: Extrasensory
B34: Signal Beam | C34: Eruption | D34: Ice | E34: Luster Purge
B35: Dark | C35: Fire Blast | D35: Blizzard | E35: Mist Ball
B36: Dark Pulse | C36: Flamethrower | D36: Frost Breath | E36: Psychic
B37: Night Daze | C37: Fusion Flare | D37: Glaciate | E37: Psycho Boost
B38: Dragon | C38: Heat Wave | D38: Ice Beam | E38: Psyshock
B39: Draco Meteor | C39: Lava Plume | D39: Ice Burn | E39: Psystrike
B40: Dragon Pulse | C40: Magma Storm | D40: Normal | E40: Stored Power
B41: Roar of Time | C41: Overheat | D41: Crush Grip | E41: Rock
B42: Spacial Rend | C42: Searing Shot | D42: Hidden Power | E42: Power Gem
B43: Electric | C43: Flying | D43: Hyper Voice | E43: Paleo Wave
... B52: Secret Sword | C52: Giga Drain | D52: Sludge Bomb | E52: Water Spout
B53: Vacuum Wave | C53: Grass Knot | D53: Sludge Wave
C54: Leaf Storm
C55: Petal Dance
C56: Seed Flare
B58: Competitive Non-Attacking Moves
...

Sheet Moves Index
B2: Move Name | C2: VGM? | D2: Type | E2: Category
B3: Absorb | C3: No | D3: Attacking | E3: Special
B4: Acid | C4: No | D4: Attacking | E4: Special
B5: Acid Armor | C5: Yes | D5: Non-Attacking | E5: N/A
B6: Acid Spray | C6: Yes | D6: Attacking | E6: Special
B7: Acrobatics | C7: Yes | D7: Attacking | E7: Physical
B8: Acupressure | C8: No | D8: Non-Attacking | E8: N/A
B9: Aerial Ace | C9: Yes | D9: Attacking | E9: Physical
B10: Aeroblast | C10: Yes | D10: Attacking | E10: Special
B11: After You | C11: No | D11: Non-Attacking | E11: N/A
B12: Agility | C12: Yes | D12: Non-Attacking | E12: N/A
B13: Air Cutter | C13: No | D13: Attacking | E13: Special
