Workbook
Name standings?category_league_season_2008_REG_split_Overall: powerflaws!$A$1:$T$34

Sheet power
A1: Rank | B1: Team | C1: Team Code | D1: Sando | E1: Clayton | F1: Graziano | G1: Hensley | H1: Fox | I1: Average | J1: High | K1: Low | L1: Biggest Gap | M1: Division | N1: Sando High Vote | O1: Clayton High Vote | P1: Kuharsky High Vote | Q1: Walker High Vote | R1: Fox High Vote | S1: Sando Low Vote | T1: Clayton Low Vote | U1: Kuharsky Low Vote | V1: Walker Low Vote | W1: Fox Low Vote | X1: Week1 | Y1: Week 2 | Z1: Week 3 | AA1: Week 4 | AB1: Week 5 | AC1: x | AD1: x | AE1: x | AF1: x | AG1: x | AH1: x | AI1: x | AJ1: x | AK1: x | AL1: x | AM1: x | AN1: x | AO1: x | AP1: x | AQ1: x | AR1: Average
A2: 1 | B2: Houston Texans | C2: HOU | D2: 1 | E2: 1 | F2: 1 | G2: 2 | H2: 1 | I2: 1.2 | J2: 1 | K2: 2 | L2: 1 | M2: AFC South | N2: 1 | O2: 1 | P2: 1 | Q2: 0 | R2: 1 | S2: 0 | T2: 0 | U2: 0 | V2: 1 | W2: 0 | X2: 5 | Y2: 4 | Z2: 2 | AA2: 1 | AB2: 1 | AR2: 2.6 | AS2: Houston Texans
A3: 2 | B3: Atlanta Falcons | C3: ATL | D3: 2 | E3: 2 | F3: 2 | G3: 1 | H3: 2 | I3: 1.8 | J3: 1 | K3: 2 | L3: 1 | M3: NFC South | N3: 0 | O3: 0 | P3: 0 | Q3: 1 | R3: 0 | S3: 1 | T3: 1 | U3: 1 | V3: 0 | W3: 1 | X3: 10 | Y3: 6 | Z3: 3 | AA3: 2 | AB3: 2 | AR3: 4.6 | AS3: Atlanta Falcons
A4: 3 | B4: Baltimore Ravens | C4: BAL | D4: 3 | E4: 3 | F4: 5 | G4: 4 | H4: 3 | I4: 3.6 | J4: 3 | K4: 5 | L4: 2 | M4: AFC North | N4: 1 | O4: 1 | P4: 0 | Q4: 0 | R4: 1 | S4: 0 | T4: 0 | U4: 1 | V4: 0 | W4: 0 | X4: 6 | Y4: 3 | Z4: 6 | AA4: 3 | AB4: 3 | AR4: 4.2 | AS4: Baltimore Ravens
A5: 4 | B5: San Francisco 49ers | C5: SF | D5: 4 | E5: 4 | F5: 3 | G5: 3 | H5: 5 | I5: 3.8 | J5: 3 | K5: 5 | L5: 2 | M5: NFC West | N5: 0 | O5: 0 | P5: 1 | Q5: 1 | R5: 0 | S5: 0 | T5: 0 | U5: 0 | V5: 0 | W5: 1 | X5: 4 | Y5: 2 | Z5: 1 | AA5: 4 | AB5: 4 | AR5: 3 | AS5: San Francisco 49ers
A6: 5 | B6: Arizona Cardinals | C6: ARI | D6: 5 | E6: 5 | F6: 8 | G6: 5 | H6: 4 | I6: 5.4 | J6: 4 | K6: 8 | L6: 4 | M6: NFC West | N6: 0 | O6: 0 | P6: 0 | Q6: 0 | R6: 1 | S6: 0 | T6: 0 | U6: 1 | V6: 0 | W6: 0 | X6: 23 | Y6: 20 | Z6: 14 | AA6: 5 | AB6: 5 | AR6: 13.4 | AS6: Arizona Cardinals
A7: 6 | B7: New England Patriots | C7: NE | D7: 6 | E7: 6 | F7: 7 | G7: 10 | H7: 6 | I7: 7 | J7: 6 | K7: 10 | L7: 4 | M7: AFC East | N7: 1 | O7: 1 | P7: 0 | Q7: 0 | R7: 1 | S7: 0 | T7: 0 | U7: 0 | V7: 1 | W7: 0 | X7: 2 | Y7: 1 | Z7: 5 | AA7: 8 | AB7: 6 | AR7: 4.4 | AS7: New England Patriots
A8: 7 | B8: Philadelphia Eagles | C8: PHI | D8: 8 | E8: 8 | F8: 9 | G8: 6 | H8: 7 | I8: 7.6 | J8: 6 | K8: 9 | L8: 3 | M8: NFC East | N8: 0 | O8: 0 | P8: 0 | Q8: 1 | R8: 0 | S8: 0 | T8: 0 | U8: 1 | V8: 0 | W8: 0 | X8: 7 | Y8: 12 | Z8: 7 | AA8: 9 | AB8: 7 | AR8: 8.4 | AS8: Philadelphia Eagles
A9: 8 | B9: Green Bay Packers | C9: GB | D9: 7 | E9: 12 | F9: 4 | G9: 7 | H9: 8 | I9: 7.6 | J9: 4 | K9: 12 | L9: 8 | M9: NFC North | N9: 0 | O9: 0 | P9: 1 | Q9: 0 | R9: 0 | S9: 0 | T9: 1 | U9: 0 | V9: 0 | W9: 0 | X9: 1 | Y9: 5 | Z9: 4 | AA9: 7 | AB9: 8 | AR9: 5 | AS9: Green Bay Packers
A10: 9 | B10: Chicago Bears | C10: CHI | D10: 9 | E10: 14 | F10: 10 | G10: 8 | H10: 9 | I10: 10 | J10: 8 | K10: 14 | L10: 6 | M10: NFC North | N10: 0 | O10: 0 | P10: 0 | Q10: 1 | R10: 0 | S10: 0 | T10: 1 | U10: 0 | V10: 0 | W10: 0 | X10: 9 | Y10: 8 | Z10: 12 | AA10: 11 | AB10: 9 | AR10: 9.8 | AS10: Chicago Bears
A11: 10 | B11: New York Giants | C11: NYG | D11: 10 | E11: 15 | F11: 6 | G11: 9 | H11: 12 | I11: 10.4 | J11: 6 | K11: 15 | L11: 9 | M11: NFC East | N11: 0 | O11: 0 | P11: 1 | Q11: 0 | R11: 0 | S11: 0 | T11: 1 | U11: 0 | V11: 0 | W11: 0 | X11: 3 | Y11: 7 | Z11: 8 | AA11: 6 | AB11: 10 | AR11: 6.8 | AS11: New York Giants
A12: 11 | B12: San Diego Chargers | C12: SD | D12: 14 | E12: 10 | F12: 15 | G12: 11 | H12: 10 | I12: 12 | J12: 10 | K12: 15 | L12: 5 | M12: AFC West | N12: 0 | O12: 1 | P12: 0 | Q12: 0 | R12: 1 | S12: 0 | T12: 0 | U12: 1 | V12: 0 | W12: 0 | X12: 15 | Y12: 14 | Z12: 11 | AA12: 13 | AB12: 11 | AR12: 12.8 | AS12: San Diego Chargers
A13: 12 | B13: Cincinnati Bengals | C13: CIN | D13: 12 | E13: 9 | F13: 14 | G13: 12 | H13: 13 | I13: 12 | J13: 9 | K13: 14 | L13: 5 | M13: AFC North | N13: 0 | O13: 1 | P13: 0 | Q13: 0 | R13: 0 | S13: 0 | T13: 0 | U13: 1 | V13: 0 | W13: 0 | X13: 16 | Y13: 18 | Z13: 16 | AA13: 15 | AB13: 12 | AR13: 15.4 | AS13: Cincinnati Bengals
... A33: 32 | B33: Cleveland Browns | C33: CLE | D33: 32 | E33: 32 | F33: 32 | G33: 32 | H33: 32 | I33: 32 | J33: 32 | K33: 32 | L33: 0 | M33: AFC North | N33: 1 | O33: 1 | P33: 1 | Q33: 1 | R33: 1 | S33: 1 | T33: 1 | U33: 1 | V33: 1 | W33: 1 | X33: 31 | Y33: 31 | Z33: 32 | AA33: 32 | AB33: 32 | AR33: 31.6 | AS33: Cleveland Browns
C37: high votes | D37: 7 | E37: 10 | F37: 9 | G37: 10 | H37: 11
C38: low votes | D38: 7 | E38: 11 | F38: 14 | G38: 7 | H38: 7
C40: Repeats | D40: 0 | E40: 0 | F40: 0 | G40: 0 | H40: 0
Y41: AFC East | Z41: AFC North | AA41: AFC South | AB41: AFC West
C42: Correlation | D42: Sando | E42: Clayton | F42: Graziano | G42: Hensley | H42: Fox | Y42: 6-NE | Z42: 3-BAL | AA42: 1-HOU | AB42: 11-SD
C43: Sando | E43: 0.94538123 | F43: 0.95124633 | G43: 0.97030792 | H43: 0.94501466 | Y43: 21-BUF | Z43: 11-CIN | AA43: 25-TEN | AB43: 13-DEN
C44: Clayton | D44: 0.94538123 | F44: 0.87939883 | G44: 0.92705279 | H44: 0.91495601 | Y44: 23-NYJ | Z44: 16-PIT | AA44: 30-JAC | AB44: 27-KC
C45: Graziano | D45: 0.95124633 | E45: 0.87939883 | G45: 0.92008798 | H45: 0.92815249 | Y45: 26-MIA | Z45: 32-CLE | AA45: 31-IND | AB45: 29-OAK
C46: Hensley | D46: 0.97030792 | E46: 0.92705279 | F46: 0.92815249 | H46: 0.95197947
C47: Fox | D47: 0.94501466 | E47: 0.91495601 | F47: 0.92815249 | G47: 0.95197947 | Y47: NFC East | Z47: NFC North | AA47: NFC South | AB47: NFC West
Y48: 7-PHI | Z48: 7-GB | AA48: 2-ATL | AB48: 4-SF
B49: Tiebreakers | Y49: 10-NYG | Z49: 9-CHI | AA49: 22-TB | AB49: 5-ARI
B50: Head to head | Y50: 15-DAL | Z50: 14-MIN | AA50: 24-CAR | AB50: 17-SEA
B51: Overall record | Y51: 18-WAS | Z51: 20-DET | AA51: 28-NO | AB51: 19-STL
B52: Won most recently
B53: Previous Ranking
B55: Date | C55: Tiebreak | D55: Tiebreak | E55: Tiebreak | F55: Tiebreak
B56: Week 1 | C56: BAL>PHI | D56: TEN>BUF | E56: MIA>STL
B57: Week 2 | C57: NE>SF | D57: CIN>KC | E57: TEN>CAR>BUF
B58: Week 3 | C58: ARI>DAL | D58: SEA>NYJ
B59: Week 4
B60: Week 5 | C60: PHI>GB | D60: SD>CIN
B61: Week 6
B62: Week 7
B63: Week 8
B64: Week 9
...

Sheet Sando
A1: Team | B1: Week 1 | C1: Week 2 | D1: Week 3 | E1: Week 4 | F1: Week 5 | G1: Week 6 | H1: Week 7 | I1: Week 8 | J1: Week 9 | K1: Week 10 | L1: Week 11 | M1: Week 12 | N1: Week 13 | O1: Week 14 | P1: Week 15 | Q1: Week 16 | R1: Week 17 | S1: Week 18 | T1: Average | U1: Highest | V1: Lowest | W1: Gap | X1: x
A2: Arizona Cardinals | B2: 23 | C2: 20 | D2: 14 | E2: 5 | F2: 5 | T2: =AVERAGE(B2:S2) -> 13.4 | U2: =MINA(B2:S2) -> 5 | V2: =MAXA(B2:S2) -> 23 | W2: =V2-U2 -> 18 | AE2: =AC2-AD2 -> 0
A3: Minnesota Vikings | B3: 30 | C3: 28 | D3: 30 | E3: 22 | F3: 13 | T3: =AVERAGE(B3:S3) -> 24.6 | U3: =MINA(B3:S3) -> 13 | V3: =MAXA(B3:S3) -> 30 | W3: =V3-U3 -> 17 | AE3: =AC3-AD3 -> 0
A4: New Orleans Saints | B4: 13 | C4: 14 | D4: 23 | E4: 28 | F4: 28 | T4: =AVERAGE(B4:S4) -> 21.2 | U4: =MINA(B4:S4) -> 13 | V4: =MAXA(B4:S4) -> 28 | W4: =V4-U4 -> 15 | AE4: =AC4-AD4 -> 0
A5: Kansas City Chiefs | B5: 15 | C5: 18 | D5: 29 | E5: 26 | F5: 27 | T5: =AVERAGE(B5:S5) -> 23 | U5: =MINA(B5:S5) -> 15 | V5: =MAXA(B5:S5) -> 29 | W5: =V5-U5 -> 14 | AE5: =AC5-AD5 -> 0
A6: Seattle Seahawks | B6: 14 | C6: 22 | D6: 15 | E6: 9 | F6: 15 | T6: =AVERAGE(B6:S6) -> 15 | U6: =MINA(B6:S6) -> 9 | V6: =MAXA(B6:S6) -> 22 | W6: =V6-U6 -> 13 | AE6: =AC6-AD6 -> 0
A7: Detroit Lions | B7: 10 | C7: 10 | D7: 11 | E7: 17 | F7: 20 | T7: =AVERAGE(B7:S7) -> 13.6 | U7: =MINA(B7:S7) -> 10 | V7: =MAXA(B7:S7) -> 20 | W7: =V7-U7 -> 10 | AE7: =AC7-AD7 -> 0
A8: Atlanta Falcons | B8: 12 | C8: 6 | D8: 3 | E8: 2 | F8: 2 | T8: =AVERAGE(B8:S8) -> 5 | U8: =MINA(B8:S8) -> 2 | V8: =MAXA(B8:S8) -> 12 | W8: =V8-U8 -> 10 | AE8: =AC8-AD8 -> 0
A9: St. Louis Rams | B9: 26 | C9: 27 | D9: 19 | E9: 21 | F9: 17 | T9: =AVERAGE(B9:S9) -> 22 | U9: =MINA(B9:S9) -> 17 | V9: =MAXA(B9:S9) -> 27 | W9: =V9-U9 -> 10
A10: New York Giants | B10: 3 | C10: 12 | D10: 9 | E10: 8 | F10: 10 | T10: =AVERAGE(B10:S10) -> 8.4 | U10: =MINA(B10:S10) -> 3 | V10: =MAXA(B10:S10) -> 12 | W10: =V10-U10 -> 9
A11: Washington Redskins | B11: 25 | C11: 16 | D11: 22 | E11: 23 | F11: 19 | T11: =AVERAGE(B11:S11) -> 21 | U11: =MINA(B11:S11) -> 16 | V11: =MAXA(B11:S11) -> 25 | W11: =V11-U11 -> 9
A12: Pittsburgh Steelers | B12: 8 | C12: 9 | D12: 8 | E12: 15 | F12: 16 | T12: =AVERAGE(B12:S12) -> 11.2 | U12: =MINA(B12:S12) -> 8 | V12: =MAXA(B12:S12) -> 16 | W12: =V12-U12 -> 8
A13: San Diego Chargers | B13: 18 | C13: 15 | D13: 10 | E13: 16 | F13: 14 | T13: =AVERAGE(B13:S13) -> 14.6 | U13: =MINA(B13:S13) -> 10 | V13: =MAXA(B13:S13) -> 18 | W13: =V13-U13 -> 8
A14: Dallas Cowboys | B14: 17 | C14: 11 | D14: 16 | E14: 11 | F14: 18 | T14: =AVERAGE(B14:S14) -> 14.6 | U14: =MINA(B14:S14) -> 11 | V14: =MAXA(B14:S14) -> 18 | W14: =V14-U14 -> 7
A15: Cincinnati Bengals | B15: 16 | C15: 19 | D15: 17 | E15: 14 | F15: 12 | T15: =AVERAGE(B15:S15) -> 15.6 | U15: =MINA(B15:S15) -> 12 | V15: =MAXA(B15:S15) -> 19 | W15: =V15-U15 -> 7
A16: Philadelphia Eagles | B16: 7 | C16: 13 | D16: 6 | E16: 10 | F16: 8 | T16: =AVERAGE(B16:S16) -> 8.8 | U16: =MINA(B16:S16) -> 6 | V16: =MAXA(B16:S16) -> 13 | W16: =V16-U16 -> 7
A17: Miami Dolphins | B17: 29 | C17: 30 | D17: 26 | E17: 29 | F17: 23 | T17: =AVERAGE(B17:S17) -> 27.4 | U17: =MINA(B17:S17) -> 23 | V17: =MAXA(B17:S17) -> 30 | W17: =V17-U17 -> 7
A18: Buffalo Bills | B18: 19 | C18: 25 | D18: 24 | E18: 20 | F18: 24 | T18: =AVERAGE(B18:S18) -> 22.4 | U18: =MINA(B18:S18) -> 19 | V18: =MAXA(B18:S18) -> 25 | W18: =V18-U18 -> 6
A19: Tennessee Titans | B19: 20 | C19: 24 | D19: 25 | E19: 24 | F19: 26 | T19: =AVERAGE(B19:S19) -> 23.8 | U19: =MINA(B19:S19) -> 20 | V19: =MAXA(B19:S19) -> 26 | W19: =V19-U19 -> 6
A20: Carolina Panthers | B20: 22 | C20: 23 | D20: 21 | E20: 27 | F20: 25 | T20: =AVERAGE(B20:S20) -> 23.6 | U20: =MINA(B20:S20) -> 21 | V20: =MAXA(B20:S20) -> 27 | W20: =V20-U20 -> 6
... A33: Cleveland Browns | B33: 31 | C33: 32 | D33: 32 | E33: 32 | F33: 32 | T33: =AVERAGE(B33:S33) -> 31.8 | U33: =MINA(B33:S33) -> 31 | V33: =MAXA(B33:S33) -> 32 | W33: =V33-U33 -> 1

Sheet Clayton
A1: Team | B1: Week 1 | C1: Week 2 | D1: Week 3 | E1: Week 4 | F1: Week 5 | G1: Week 6 | H1: Week 7 | I1: Week 8 | J1: Week 9 | K1: Week 10 | L1: Week 11 | M1: Week 12 | N1: Week 13 | O1: Week 14 | P1: Week 15 | Q1: Week 16 | R1: Week 17 | S1: Week 18 | T1: Average | U1: Highest | V1: Lowest | W1: Gap | X1: x
A2: Minnesota Vikings | B2: 32 | C2: 28 | D2: 26 | E2: 22 | F2: 7 | T2: =AVERAGE(B2:S2) -> 23 | U2: =MINA(B2:S2) -> 7 | V2: =MAXA(B2:S2) -> 32 | W2: =V2-U2 -> 25
A3: Arizona Cardinals | B3: 26 | C3: 25 | D3: 17 | E3: 5 | F3: 5 | T3: =AVERAGE(B3:S3) -> 15.6 | U3: =MINA(B3:S3) -> 5 | V3: =MAXA(B3:S3) -> 26 | W3: =V3-U3 -> 21
A4: Seattle Seahawks | B4: 16 | C4: 26 | D4: 18 | E4: 7 | F4: 11 | T4: =AVERAGE(B4:S4) -> 15.6 | U4: =MINA(B4:S4) -> 7 | V4: =MAXA(B4:S4) -> 26 | W4: =V4-U4 -> 19
A5: New Orleans Saints | B5: 11 | C5: 15 | D5: 24 | E5: 29 | F5: 29 | T5: =AVERAGE(B5:S5) -> 21.6 | U5: =MINA(B5:S5) -> 11 | V5: =MAXA(B5:S5) -> 29 | W5: =V5-U5 -> 18
A6: Kansas City Chiefs | B6: 18 | C6: 20 | D6: 29 | E6: 25 | F6: 27 | T6: =AVERAGE(B6:S6) -> 23.8 | U6: =MINA(B6:S6) -> 18 | V6: =MAXA(B6:S6) -> 29 | W6: =V6-U6 -> 11
A7: Green Bay Packers | B7: 2 | C7: 6 | D7: 4 | E7: 8 | F7: 12 | T7: =AVERAGE(B7:S7) -> 6.4 | U7: =MINA(B7:S7) -> 2 | V7: =MAXA(B7:S7) -> 12 | W7: =V7-U7 -> 10
A8: Pittsburgh Steelers | B8: 7 | C8: 10 | D8: 9 | E8: 14 | F8: 17 | T8: =AVERAGE(B8:S8) -> 11.4 | U8: =MINA(B8:S8) -> 7 | V8: =MAXA(B8:S8) -> 17 | W8: =V8-U8 -> 10
A9: New York Giants | B9: 6 | C9: 12 | D9: 11 | E9: 10 | F9: 15 | T9: =AVERAGE(B9:S9) -> 10.8 | U9: =MINA(B9:S9) -> 6 | V9: =MAXA(B9:S9) -> 15 | W9: =V9-U9 -> 9
A10: Denver Broncos | B10: 17 | C10: 9 | D10: 8 | E10: 13 | F10: 16 | T10: =AVERAGE(B10:S10) -> 12.6 | U10: =MINA(B10:S10) -> 8 | V10: =MAXA(B10:S10) -> 17 | W10: =V10-U10 -> 9
A11: Washington Redskins | B11: 23 | C11: 14 | D11: 23 | E11: 23 | F11: 23 | T11: =AVERAGE(B11:S11) -> 21.2 | U11: =MINA(B11:S11) -> 14 | V11: =MAXA(B11:S11) -> 23 | W11: =V11-U11 -> 9
A12: Philadelphia Eagles | B12: 3 | C12: 8 | D12: 6 | E12: 12 | F12: 8 | T12: =AVERAGE(B12:S12) -> 7.4 | U12: =MINA(B12:S12) -> 3 | V12: =MAXA(B12:S12) -> 12 | W12: =V12-U12 -> 9
A13: New York Jets | B13: 21 | C13: 18 | D13: 16 | E13: 18 | F13: 24 | T13: =AVERAGE(B13:S13) -> 19.4 | U13: =MINA(B13:S13) -> 16 | V13: =MAXA(B13:S13) -> 24 | W13: =V13-U13 -> 8
... A33: Cleveland Browns | B33: 31 | C33: 32 | D33: 32 | E33: 32 | F33: 32 | T33: =AVERAGE(B33:S33) -> 31.8 | U33: =MINA(B33:S33) -> 31 | V33: =MAXA(B33:S33) -> 32 | W33: =V33-U33 -> 1

Sheet Graziano
A1: Team | B1: Week 1 | C1: Week 2 | D1: Week 3 | E1: Week 4 | F1: Week 5 | G1: Week 6 | H1: Week 7 | I1: Week 8 | J1: Week 9 | K1: Week 10 | L1: Week 11 | M1: Week 12 | N1: Week 13 | O1: Week 14 | P1: Week 15 | Q1: Week 16 | R1: Week 17 | S1: Week 18 | T1: Average | U1: Highest | V1: Lowest | W1: Gap | X1: x
A2: San Francisco 49ers | B2: 4 | C2: 1 | D2: 1 | E2: 3 | F2: 3 | T2: =AVERAGE(B2:S2) -> 2.4 | U2: =MINA(B2:S2) -> 1 | V2: =MAXA(B2:S2) -> 4 | W2: =V2-U2 -> 3
A3: Green Bay Packers | B3: 1 | C3: 2 | D3: 2 | E3: 4 | F3: 4 | T3: =AVERAGE(B3:S3) -> 2.6 | U3: =MINA(B3:S3) -> 1 | V3: =MAXA(B3:S3) -> 4 | W3: =V3-U3 -> 3
A4: Houston Texans | B4: 6 | C4: 4 | D4: 3 | E4: 1 | F4: 1 | T4: =AVERAGE(B4:S4) -> 3 | U4: =MINA(B4:S4) -> 1 | V4: =MAXA(B4:S4) -> 6 | W4: =V4-U4 -> 5
A5: Atlanta Falcons | B5: 8 | C5: 7 | D5: 4 | E5: 2 | F5: 2 | T5: =AVERAGE(B5:S5) -> 4.6 | U5: =MINA(B5:S5) -> 2 | V5: =MAXA(B5:S5) -> 8 | W5: =V5-U5 -> 6
A6: New York Giants | B6: 2 | C6: 5 | D6: 6 | E6: 5 | F6: 6 | T6: =AVERAGE(B6:S6) -> 4.8 | U6: =MINA(B6:S6) -> 2 | V6: =MAXA(B6:S6) -> 6 | W6: =V6-U6 -> 4
A7: New England Patriots | B7: 5 | C7: 3 | D7: 5 | E7: 7 | F7: 7 | T7: =AVERAGE(B7:S7) -> 5.4 | U7: =MINA(B7:S7) -> 3 | V7: =MAXA(B7:S7) -> 7 | W7: =V7-U7 -> 4
A8: Baltimore Ravens | B8: 7 | C8: 6 | D8: 8 | E8: 6 | F8: 5 | T8: =AVERAGE(B8:S8) -> 6.4 | U8: =MINA(B8:S8) -> 5 | V8: =MAXA(B8:S8) -> 8 | W8: =V8-U8 -> 3
A9: Philadelphia Eagles | B9: 3 | C9: 9 | D9: 7 | E9: 9 | F9: 9 | T9: =AVERAGE(B9:S9) -> 7.4 | U9: =MINA(B9:S9) -> 3 | V9: =MAXA(B9:S9) -> 9 | W9: =V9-U9 -> 6
A10: Chicago Bears | B10: 10 | C10: 8 | D10: 10 | E10: 10 | F10: 10 | T10: =AVERAGE(B10:S10) -> 9.6 | U10: =MINA(B10:S10) -> 8 | V10: =MAXA(B10:S10) -> 10 | W10: =V10-U10 -> 2
A11: Pittsburgh Steelers | B11: 9 | C11: 11 | D11: 9 | E11: 12 | F11: 12 | T11: =AVERAGE(B11:S11) -> 10.6 | U11: =MINA(B11:S11) -> 9 | V11: =MAXA(B11:S11) -> 12 | W11: =V11-U11 -> 3
A12: Dallas Cowboys | B12: 15 | C12: 10 | D12: 13 | E12: 11 | F12: 13 | T12: =AVERAGE(B12:S12) -> 12.4 | U12: =MINA(B12:S12) -> 10 | V12: =MAXA(B12:S12) -> 15 | W12: =V12-U12 -> 5
A13: Denver Broncos | B13: 18 | C13: 12 | D13: 12 | E13: 13 | F13: 11 | T13: =AVERAGE(B13:S13) -> 13.2 | U13: =MINA(B13:S13) -> 11 | V13: =MAXA(B13:S13) -> 18 | W13: =V13-U13 -> 7
... A33: Cleveland Browns | B33: 31 | C33: 30 | D33: 32 | E33: 32 | F33: 32 | T33: =AVERAGE(B33:S33) -> 31.4 | U33: =MINA(B33:S33) -> 30 | V33: =MAXA(B33:S33) -> 32 | W33: =V33-U33 -> 2

Sheet Hensley
A1: Team | B1: Week 1 | C1: Week 2 | D1: Week 3 | E1: Week 4 | F1: Week 5 | G1: Week 6 | H1: Week 7 | I1: Week 8 | J1: Week 9 | K1: Week 10 | L1: Week 11 | M1: Week 12 | N1: Week 13 | O1: Week 14 | P1: Week 15 | Q1: Week 16 | R1: Week 17 | S1: Week 18 | T1: Average | U1: Highest | V1: Lowest | W1: Gap | X1: x
A2: New Orleans Saints | B2: 10 | C2: 16 | D2: 24 | E2: 31 | F2: 31 | T2: =AVERAGE(B2:S2) -> 22.4 | U2: =MINA(B2:S2) -> 10 | V2: =MAXA(B2:S2) -> 31 | W2: =V2-U2 -> 21
A3: Minnesota Vikings | B3: 29 | C3: 27 | D3: 26 | E3: 19 | F3: 13 | T3: =AVERAGE(B3:S3) -> 22.8 | U3: =MINA(B3:S3) -> 13 | V3: =MAXA(B3:S3) -> 29 | W3: =V3-U3 -> 16
A4: Seattle Seahawks | B4: 25 | C4: 26 | D4: 16 | E4: 12 | F4: 18 | T4: =AVERAGE(B4:S4) -> 19.4 | U4: =MINA(B4:S4) -> 12 | V4: =MAXA(B4:S4) -> 26 | W4: =V4-U4 -> 14
A5: Atlanta Falcons | B5: 15 | C5: 11 | D5: 4 | E5: 1 | F5: 1 | T5: =AVERAGE(B5:S5) -> 6.4 | U5: =MINA(B5:S5) -> 1 | V5: =MAXA(B5:S5) -> 15 | W5: =V5-U5 -> 14
A6: Arizona Cardinals | B6: 19 | C6: 18 | D6: 12 | E6: 6 | F6: 5 | T6: =AVERAGE(B6:S6) -> 12 | U6: =MINA(B6:S6) -> 5 | V6: =MAXA(B6:S6) -> 19 | W6: =V6-U6 -> 14
A7: Washington Redskins | B7: 26 | C7: 15 | D7: 23 | E7: 29 | F7: 19 | T7: =AVERAGE(B7:S7) -> 22.4 | U7: =MINA(B7:S7) -> 15 | V7: =MAXA(B7:S7) -> 29 | W7: =V7-U7 -> 14
A8: St. Louis Rams | B8: 30 | C8: 29 | D8: 22 | E8: 23 | F8: 17 | T8: =AVERAGE(B8:S8) -> 24.2 | U8: =MINA(B8:S8) -> 17 | V8: =MAXA(B8:S8) -> 30 | W8: =V8-U8 -> 13
A9: Detroit Lions | B9: 14 | C9: 13 | D9: 15 | E9: 22 | F9: 25 | T9: =AVERAGE(B9:S9) -> 17.8 | U9: =MINA(B9:S9) -> 13 | V9: =MAXA(B9:S9) -> 25 | W9: =V9-U9 -> 12
A10: Pittsburgh Steelers | B10: 4 | C10: 10 | D10: 10 | E10: 16 | F10: 16 | T10: =AVERAGE(B10:S10) -> 11.2 | U10: =MINA(B10:S10) -> 4 | V10: =MAXA(B10:S10) -> 16 | W10: =V10-U10 -> 12
A11: New England Patriots | B11: 2 | C11: 1 | D11: 8 | E11: 13 | F11: 10 | T11: =AVERAGE(B11:S11) -> 6.8 | U11: =MINA(B11:S11) -> 1 | V11: =MAXA(B11:S11) -> 13 | W11: =V11-U11 -> 12
A12: Tennessee Titans | B12: 17 | C12: 25 | D12: 28 | E12: 21 | F12: 23 | T12: =AVERAGE(B12:S12) -> 22.8 | U12: =MINA(B12:S12) -> 17 | V12: =MAXA(B12:S12) -> 28 | W12: =V12-U12 -> 11
A13: Dallas Cowboys | B13: 7 | C13: 6 | D13: 13 | E13: 9 | F13: 15 | T13: =AVERAGE(B13:S13) -> 10 | U13: =MINA(B13:S13) -> 6 | V13: =MAXA(B13:S13) -> 15 | W13: =V13-U13 -> 9
... A33: Tampa Bay Bucs | B33: 22 | C33: 19 | D33: 19 | E33: 20 | F33: 20 | T33: =AVERAGE(B33:S33) -> 20 | U33: =MINA(B33:S33) -> 19 | V33: =MAXA(B33:S33) -> 22 | W33: =V33-U33 -> 3

Sheet Fox
A1: Team | B1: Week 1 | C1: Week 2 | D1: Week 3 | E1: Week 4 | F1: Week 5 | G1: Week 6 | H1: Week 7 | I1: Week 8 | J1: Week 9 | K1: Week 10 | L1: Week 11 | M1: Week 12 | N1: Week 13 | O1: Week 14 | P1: Week 15 | Q1: Week 16 | R1: Week 17 | S1: Week 18 | T1: Average | U1: Highest | V1: Lowest | W1: Gap | X1: x
A2: New Orleans Saints | B2: 14 | C2: 15 | D2: 23 | E2: 30 | F2: 30 | T2: =AVERAGE(B2:S2) -> 22.4 | U2: =MINA(B2:S2) -> 14 | V2: =MAXA(B2:S2) -> 30 | W2: =V2-U2 -> 16
A3: Arizona Cardinals | B3: 19 | C3: 19 | D3: 12 | E3: 5 | F3: 4 | T3: =AVERAGE(B3:S3) -> 11.8 | U3: =MINA(B3:S3) -> 4 | V3: =MAXA(B3:S3) -> 19 | W3: =V3-U3 -> 15
A4: Minnesota Vikings | B4: 31 | C4: 30 | D4: 30 | E4: 26 | F4: 17 | T4: =AVERAGE(B4:S4) -> 26.8 | U4: =MINA(B4:S4) -> 17 | V4: =MAXA(B4:S4) -> 31 | W4: =V4-U4 -> 14
A5: Seattle Seahawks | B5: 21 | C5: 24 | D5: 19 | E5: 12 | F5: 20 | T5: =AVERAGE(B5:S5) -> 19.2 | U5: =MINA(B5:S5) -> 12 | V5: =MAXA(B5:S5) -> 24 | W5: =V5-U5 -> 12
A6: Detroit Lions | B6: 11 | C6: 11 | D6: 14 | E6: 19 | F6: 23 | T6: =AVERAGE(B6:S6) -> 15.6 | U6: =MINA(B6:S6) -> 11 | V6: =MAXA(B6:S6) -> 23 | W6: =V6-U6 -> 12
A7: New York Giants | B7: 1 | C7: 5 | D7: 5 | E7: 4 | F7: 12 | T7: =AVERAGE(B7:S7) -> 5.4 | U7: =MINA(B7:S7) -> 1 | V7: =MAXA(B7:S7) -> 12 | W7: =V7-U7 -> 11
A8: Buffalo Bills | B8: 23 | C8: 25 | D8: 20 | E8: 14 | F8: 18 | T8: =AVERAGE(B8:S8) -> 20 | U8: =MINA(B8:S8) -> 14 | V8: =MAXA(B8:S8) -> 25 | W8: =V8-U8 -> 11
A9: Atlanta Falcons | B9: 12 | C9: 9 | D9: 3 | E9: 2 | F9: 2 | T9: =AVERAGE(B9:S9) -> 5.6 | U9: =MINA(B9:S9) -> 2 | V9: =MAXA(B9:S9) -> 12 | W9: =V9-U9 -> 10
A10: Denver Broncos | B10: 8 | C10: 7 | D10: 9 | E10: 17 | F10: 14 | T10: =AVERAGE(B10:S10) -> 11 | U10: =MINA(B10:S10) -> 7 | V10: =MAXA(B10:S10) -> 17 | W10: =V10-U10 -> 10
A11: Washington Redskins | B11: 25 | C11: 17 | D11: 18 | E11: 21 | F11: 15 | T11: =AVERAGE(B11:S11) -> 19.2 | U11: =MINA(B11:S11) -> 15 | V11: =MAXA(B11:S11) -> 25 | W11: =V11-U11 -> 10
A12: Tennessee Titans | B12: 18 | C12: 21 | D12: 27 | E12: 23 | F12: 26 | T12: =AVERAGE(B12:S12) -> 23 | U12: =MINA(B12:S12) -> 18 | V12: =MAXA(B12:S12) -> 27 | W12: =V12-U12 -> 9
A13: Kansas City Chiefs | B13: 17 | C13: 18 | D13: 26 | E13: 22 | F13: 24 | T13: =AVERAGE(B13:S13) -> 21.4 | U13: =MINA(B13:S13) -> 17 | V13: =MAXA(B13:S13) -> 26 | W13: =V13-U13 -> 9
... A33: Baltimore Ravens | B33: 4 | C33: 3 | D33: 4 | E33: 3 | F33: 3 | T33: =AVERAGE(B33:S33) -> 3.4 | U33: =MINA(B33:S33) -> 3 | V33: =MAXA(B33:S33) -> 4 | W33: =V33-U33 -> 1

Sheet powerflaws
Z1: =SUM(Z3:Z34) -> 11
A2: NFL Team | B2: Conf | C2: Div | D2: W | E2: L | F2: T | G2: Pct | H2: PF | I2: PA | J2: Net Pts | K2: TD | L2: Home | M2: Road | N2: Div | O2: Pct | P2: Conf | Q2: Pct | R2: Non-Conf | S2: Streak | T2: Last 5 | U2: PPG | V2: PPG Allowed | W2: PPG Differential | X2: Total Games Played | Y2: Power Ranking | Z2: Higher Ranked Teams Beaten | AA2: Team Code | AB2: Beat | AC2: Beat | AD2: Beat | AE2: Beat | AF2: Beat | AG2: Beat | AH2: Beat | AI2: Beat | AJ2: Beat | AK2: Beat | AL2: Beat | AM2: Beat | AN2: Beat | AO2: Beat | AP2: Beat | AQ2: Beat | AR2: Beat | AS2: Team | AT2: Wins | AU2: Losses
A3: Houston Texans | B3: NFC | C3: ACS | D3: 4 | E3: 0 | F3: 0 | G3: 1 | H3: 126 | I3: 56 | J3: 70 | K3: 15 | L3: 2-0 | M3: 2-0 | N3: 2-0 | O3: 1 | P3: 4-0 | Q3: 1 | R3: 0-0 | S3: 4W | T3: 4-0 | U3: =H3/(D3+E3+F3) -> 31.5 | V3: =I3/(D3+E3+F3) -> 14 | W3: =U3-V3 -> 17.5 | X3: =SUM(D3:F3) -> 4 | Y3: 1 | Z3: 0 | AA3: =VLOOKUP(A3,howfared!$A$2:$B$33,2,FALSE) -> HOU | AB3: =VLOOKUP(AA3,howfared!$B$2:$AH$33,2,FALSE) -> MIA | AC3: =VLOOKUP(AA3,howfared!$B$2:$AH$33,3,FALSE) -> JAC | AD3: =VLOOKUP(AA3,howfared!$B$2:$AH$33,4,FALSE) -> DEN | AE3: =VLOOKUP(AA3,howfared!$B$2:$AH$33,5,FALSE) -> 0 | AF3: =VLOOKUP(AA3,howfared!$B$2:$AH$33,6,FALSE) -> 0 | AG3: =VLOOKUP(AA3,howfared!$B$2:$AH$33,7,FALSE) -> 0 | AH3: =VLOOKUP(AA3,howfared!$B$2:$AH$33,8,FALSE) -> 0 | AI3: =VLOOKUP(AA3,howfared!$B$2:$AH$33,9,FALSE) -> 0 | AJ3: =VLOOKUP(AA3,howfared!$B$2:$AH$33,10,FALSE) -> 0 | AK3: =VLOOKUP(AA3,howfared!$B$2:$AH$33,11,FALSE) -> 0 | AL3: =VLOOKUP(AA3,howfared!$B$2:$AH$33,12,FALSE) -> 0 | AM3: =VLOOKUP(AA3,howfared!$B$2:$AH$33,13,FALSE) -> 0 | AN3: =VLOOKUP(AA3,howfared!$B$2:$AH$33,14,FALSE) -> 0 | AO3: =VLOOKUP(AA3,howfared!$B$2:$AH$33,15,FALSE) -> 0 | AP3: =VLOOKUP(AA3,howfared!$B$2:$AH$33,16,FALSE) -> 0 | AQ3: =VLOOKUP(AA3,howfared!$B$2:$AH$33,17,FALSE) -> 0 | AR3: =VLOOKUP(AA3,howfared!$B$2:$AH$33,18,FALSE) -> 0 | AS3: =AA3 -> HOU | AT3: =D3 -> 4 | AU3: =E3 -> 0
A4: Atlanta Falcons | B4: NFC | C4: NCS | D4: 4 | E4: 0 | F4: 0 | G4: 1 | H4: 124 | I4: 76 | J4: 48 | K4: 14 | L4: 2-0 | M4: 2-0 | N4: 1-0 | O4: 1 | P4: 1-0 | Q4: 1 | R4: 3-0 | S4: 4W | T4: 4-0 | U4: =H4/(D4+E4+F4) -> 31 | V4: =I4/(D4+E4+F4) -> 19 | W4: =U4-V4 -> 12 | X4: =SUM(D4:F4) -> 4 | Y4: 2 | Z4: =COUNTIF(AA$3:AA3,AB4)+COUNTIF(AA$3:AA4,AC4)+COUNTIF(AA$3:AA4,AD4)+COUNTIF(AA$3:AA4,AE4)+COUNTIF(AA$3:AA4,AF4)+COUNTIF(AA$3:AA4,AG4)+COUNTIF(AA$3:AA4,AH4)+COUNTIF(AA$3:AA4,AI4)+COUNTIF(AA$3:AA4,AJ4)+COUNTIF(AA$3:AA4,AK4)+COUNTIF(AA$3:AA4,AL4)+COUNTIF(AA$3:AA4,AM4)+COUNTIF(AA$3:AA4,AN4)+COUNTIF(AA$3:AA4,AO4)+COUNTIF(AA$3:AA4,AP4)+COUNTIF(AA$3:AA4,AQ4)+COUNTIF(AA$3:AA4,AR4) -> 0 | AA4: =VLOOKUP(A4,howfared!$A$2:$B$33,2,FALSE) -> ATL | AB4: =VLOOKUP(AA4,howfared!$B$2:$AH$33,2,FALSE) -> KC | AC4: =VLOOKUP(AA4,howfared!$B$2:$AH$33,3,FALSE) -> DEN | AD4: =VLOOKUP(AA4,howfared!$B$2:$AH$33,4,FALSE) -> SD | AE4: =VLOOKUP(AA4,howfared!$B$2:$AH$33,5,FALSE) -> 0 | AF4: =VLOOKUP(AA4,howfared!$B$2:$AH$33,6,FALSE) -> 0 | AG4: =VLOOKUP(AA4,howfared!$B$2:$AH$33,7,FALSE) -> 0 | AH4: =VLOOKUP(AA4,howfared!$B$2:$AH$33,8,FALSE) -> 0 | AI4: =VLOOKUP(AA4,howfared!$B$2:$AH$33,9,FALSE) -> 0 | AJ4: =VLOOKUP(AA4,howfared!$B$2:$AH$33,10,FALSE) -> 0 | AK4: =VLOOKUP(AA4,howfared!$B$2:$AH$33,11,FALSE) -> 0 | AL4: =VLOOKUP(AA4,howfared!$B$2:$AH$33,12,FALSE) -> 0 | AM4: =VLOOKUP(AA4,howfared!$B$2:$AH$33,13,FALSE) -> 0 | AN4: =VLOOKUP(AA4,howfared!$B$2:$AH$33,14,FALSE) -> 0 | AO4: =VLOOKUP(AA4,howfared!$B$2:$AH$33,15,FALSE) -> 0 | AP4: =VLOOKUP(AA4,howfared!$B$2:$AH$33,16,FALSE) -> 0 | AQ4: =VLOOKUP(AA4,howfared!$B$2:$AH$33,17,FALSE) -> 0 | AR4: =VLOOKUP(AA4,howfared!$B$2:$AH$33,18,FALSE) -> 0 | AS4: =AA4 -> ATL | AT4: =D4 -> 4 | AU4: =E4 -> 0
A5: Baltimore Ravens | B5: AFC | C5: ACN | D5: 3 | E5: 1 | F5: 0 | G5: 0.75 | H5: 121 | I5: 83 | J5: 38 | K5: 14 | L5: 3-0 | M5: 0-1 | N5: 2-0 | O5: 1 | P5: 3-0 | Q5: 1 | R5: 0-1 | S5: 2W | T5: 3-1 | U5: =H5/(D5+E5+F5) -> 30.25 | V5: =I5/(D5+E5+F5) -> 20.75 | W5: =U5-V5 -> 9.5 | X5: =SUM(D5:F5) -> 4 | Y5: 3 | Z5: =COUNTIF(AA$3:AA4,AB5)+COUNTIF(AA$3:AA5,AC5)+COUNTIF(AA$3:AA5,AD5)+COUNTIF(AA$3:AA5,AE5)+COUNTIF(AA$3:AA5,AF5)+COUNTIF(AA$3:AA5,AG5)+COUNTIF(AA$3:AA5,AH5)+COUNTIF(AA$3:AA5,AI5)+COUNTIF(AA$3:AA5,AJ5)+COUNTIF(AA$3:AA5,AK5)+COUNTIF(AA$3:AA5,AL5)+COUNTIF(AA$3:AA5,AM5)+COUNTIF(AA$3:AA5,AN5)+COUNTIF(AA$3:AA5,AO5)+COUNTIF(AA$3:AA5,AP5)+COUNTIF(AA$3:AA5,AQ5)+COUNTIF(AA$3:AA5,AR5) -> 0 | AA5: =VLOOKUP(A5,howfared!$A$2:$B$33,2,FALSE) -> BAL | AB5: =VLOOKUP(AA5,howfared!$B$2:$AH$33,2,FALSE) -> CIN | AC5: =VLOOKUP(AA5,howfared!$B$2:$AH$33,3,FALSE) -> 0 | AD5: =VLOOKUP(AA5,howfared!$B$2:$AH$33,4,FALSE) -> NE | AE5: =VLOOKUP(AA5,howfared!$B$2:$AH$33,5,FALSE) -> 0 | AF5: =VLOOKUP(AA5,howfared!$B$2:$AH$33,6,FALSE) -> 0 | AG5: =VLOOKUP(AA5,howfared!$B$2:$AH$33,7,FALSE) -> 0 | AH5: =VLOOKUP(AA5,howfared!$B$2:$AH$33,8,FALSE) -> 0 | AI5: =VLOOKUP(AA5,howfared!$B$2:$AH$33,9,FALSE) -> 0 | AJ5: =VLOOKUP(AA5,howfared!$B$2:$AH$33,10,FALSE) -> 0 | AK5: =VLOOKUP(AA5,howfared!$B$2:$AH$33,11,FALSE) -> 0 | AL5: =VLOOKUP(AA5,howfared!$B$2:$AH$33,12,FALSE) -> 0 | AM5: =VLOOKUP(AA5,howfared!$B$2:$AH$33,13,FALSE) -> 0 | AN5: =VLOOKUP(AA5,howfared!$B$2:$AH$33,14,FALSE) -> 0 | AO5: =VLOOKUP(AA5,howfared!$B$2:$AH$33,15,FALSE) -> 0 | AP5: =VLOOKUP(AA5,howfared!$B$2:$AH$33,16,FALSE) -> 0 | AQ5: =VLOOKUP(AA5,howfared!$B$2:$AH$33,17,FALSE) -> 0 | AR5: =VLOOKUP(AA5,howfared!$B$2:$AH$33,18,FALSE) -> 0 | AS5: =AA5 -> BAL | AT5: =D5 -> 3 | AU5: =E5 -> 1
A6: San Francisco 49ers | B6: NFC | C6: NCW | D6: 3 | E6: 1 | F6: 0 | G6: 0.75 | H6: 104 | I6: 65 | J6: 39 | K6: 11 | L6: 1-0 | M6: 2-1 | N6: 0-0 | O6: 0 | P6: 2-1 | Q6: 0.667 | R6: 1-0 | S6: 1W | T6: 3-1 | U6: =H6/(D6+E6+F6) -> 26 | V6: =I6/(D6+E6+F6) -> 16.25 | W6: =U6-V6 -> 9.75 | X6: =SUM(D6:F6) -> 4 | Y6: 4 | Z6: =COUNTIF(AA$3:AA5,AB6)+COUNTIF(AA$3:AA6,AC6)+COUNTIF(AA$3:AA6,AD6)+COUNTIF(AA$3:AA6,AE6)+COUNTIF(AA$3:AA6,AF6)+COUNTIF(AA$3:AA6,AG6)+COUNTIF(AA$3:AA6,AH6)+COUNTIF(AA$3:AA6,AI6)+COUNTIF(AA$3:AA6,AJ6)+COUNTIF(AA$3:AA6,AK6)+COUNTIF(AA$3:AA6,AL6)+COUNTIF(AA$3:AA6,AM6)+COUNTIF(AA$3:AA6,AN6)+COUNTIF(AA$3:AA6,AO6)+COUNTIF(AA$3:AA6,AP6)+COUNTIF(AA$3:AA6,AQ6)+COUNTIF(AA$3:AA6,AR6) -> 0 | AA6: =VLOOKUP(A6,howfared!$A$2:$B$33,2,FALSE) -> SF | AB6: =VLOOKUP(AA6,howfared!$B$2:$AH$33,2,FALSE) -> GB | AC6: =VLOOKUP(AA6,howfared!$B$2:$AH$33,3,FALSE) -> DET | AD6: =VLOOKUP(AA6,howfared!$B$2:$AH$33,4,FALSE) -> 0 | AE6: =VLOOKUP(AA6,howfared!$B$2:$AH$33,5,FALSE) -> 0 | AF6: =VLOOKUP(AA6,howfared!$B$2:$AH$33,6,FALSE) -> 0 | AG6: =VLOOKUP(AA6,howfared!$B$2:$AH$33,7,FALSE) -> 0 | AH6: =VLOOKUP(AA6,howfared!$B$2:$AH$33,8,FALSE) -> 0 | AI6: =VLOOKUP(AA6,howfared!$B$2:$AH$33,9,FALSE) -> 0 | AJ6: =VLOOKUP(AA6,howfared!$B$2:$AH$33,10,FALSE) -> 0 | AK6: =VLOOKUP(AA6,howfared!$B$2:$AH$33,11,FALSE) -> 0 | AL6: =VLOOKUP(AA6,howfared!$B$2:$AH$33,12,FALSE) -> 0 | AM6: =VLOOKUP(AA6,howfared!$B$2:$AH$33,13,FALSE) -> 0 | AN6: =VLOOKUP(AA6,howfared!$B$2:$AH$33,14,FALSE) -> 0 | AO6: =VLOOKUP(AA6,howfared!$B$2:$AH$33,15,FALSE) -> 0 | AP6: =VLOOKUP(AA6,howfared!$B$2:$AH$33,16,FALSE) -> 0 | AQ6: =VLOOKUP(AA6,howfared!$B$2:$AH$33,17,FALSE) -> 0 | AR6: =VLOOKUP(AA6,howfared!$B$2:$AH$33,18,FALSE) -> 0 | AS6: =AA6 -> SF | AT6: =D6 -> 3 | AU6: =E6 -> 1
A7: Arizona Cardinals | B7: NFC | C7: NCW | D7: 4 | E7: 0 | F7: 0 | G7: 1 | H7: 91 | I7: 61 | J7: 30 | K7: 10 | L7: 3-0 | M7: 1-0 | N7: 1-0 | O7: 1 | P7: 2-0 | Q7: 1 | R7: 2-0 | S7: 4W | T7: 4-0 | U7: =H7/(D7+E7+F7) -> 22.75 | V7: =I7/(D7+E7+F7) -> 15.25 | W7: =U7-V7 -> 7.5 | X7: =SUM(D7:F7) -> 4 | Y7: 5 | Z7: =COUNTIF(AA$3:AA6,AB7)+COUNTIF(AA$3:AA7,AC7)+COUNTIF(AA$3:AA7,AD7)+COUNTIF(AA$3:AA7,AE7)+COUNTIF(AA$3:AA7,AF7)+COUNTIF(AA$3:AA7,AG7)+COUNTIF(AA$3:AA7,AH7)+COUNTIF(AA$3:AA7,AI7)+COUNTIF(AA$3:AA7,AJ7)+COUNTIF(AA$3:AA7,AK7)+COUNTIF(AA$3:AA7,AL7)+COUNTIF(AA$3:AA7,AM7)+COUNTIF(AA$3:AA7,AN7)+COUNTIF(AA$3:AA7,AO7)+COUNTIF(AA$3:AA7,AP7)+COUNTIF(AA$3:AA7,AQ7)+COUNTIF(AA$3:AA7,AR7) -> 0 | AA7: =VLOOKUP(A7,howfared!$A$2:$B$33,2,FALSE) -> ARI | AB7: =VLOOKUP(AA7,howfared!$B$2:$AH$33,2,FALSE) -> SEA | AC7: =VLOOKUP(AA7,howfared!$B$2:$AH$33,3,FALSE) -> NE | AD7: =VLOOKUP(AA7,howfared!$B$2:$AH$33,4,FALSE) -> PHI | AE7: =VLOOKUP(AA7,howfared!$B$2:$AH$33,5,FALSE) -> 0 | AF7: =VLOOKUP(AA7,howfared!$B$2:$AH$33,6,FALSE) -> 0 | AG7: =VLOOKUP(AA7,howfared!$B$2:$AH$33,7,FALSE) -> 0 | AH7: =VLOOKUP(AA7,howfared!$B$2:$AH$33,8,FALSE) -> 0 | AI7: =VLOOKUP(AA7,howfared!$B$2:$AH$33,9,FALSE) -> 0 | AJ7: =VLOOKUP(AA7,howfared!$B$2:$AH$33,10,FALSE) -> 0 | AK7: =VLOOKUP(AA7,howfared!$B$2:$AH$33,11,FALSE) -> 0 | AL7: =VLOOKUP(AA7,howfared!$B$2:$AH$33,12,FALSE) -> 0 | AM7: =VLOOKUP(AA7,howfared!$B$2:$AH$33,13,FALSE) -> 0 | AN7: =VLOOKUP(AA7,howfared!$B$2:$AH$33,14,FALSE) -> 0 | AO7: =VLOOKUP(AA7,howfared!$B$2:$AH$33,15,FALSE) -> 0 | AP7: =VLOOKUP(AA7,howfared!$B$2:$AH$33,16,FALSE) -> 0 | AQ7: =VLOOKUP(AA7,howfared!$B$2:$AH$33,17,FALSE) -> 0 | AR7: =VLOOKUP(AA7,howfared!$B$2:$AH$33,18,FALSE) -> 0 | AS7: =AA7 -> ARI | AT7: =D7 -> 4 | AU7: =E7 -> 0
A8: New England Patriots | B8: AFC | C8: ACE | D8: 2 | E8: 2 | F8: 0 | G8: 0.5 | H8: 134 | I8: 92 | J8: 42 | K8: 15 | L8: 0-1 | M8: 2-1 | N8: 1-0 | O8: 1 | P8: 2-1 | Q8: 0.667 | R8: 0-1 | S8: 1W | T8: 2-2 | U8: =H8/(D8+E8+F8) -> 33.5 | V8: =I8/(D8+E8+F8) -> 23 | W8: =U8-V8 -> 10.5 | X8: =SUM(D8:F8) -> 4 | Y8: 6 | Z8: =COUNTIF(AA$3:AA7,AB8)+COUNTIF(AA$3:AA8,AC8)+COUNTIF(AA$3:AA8,AD8)+COUNTIF(AA$3:AA8,AE8)+COUNTIF(AA$3:AA8,AF8)+COUNTIF(AA$3:AA8,AG8)+COUNTIF(AA$3:AA8,AH8)+COUNTIF(AA$3:AA8,AI8)+COUNTIF(AA$3:AA8,AJ8)+COUNTIF(AA$3:AA8,AK8)+COUNTIF(AA$3:AA8,AL8)+COUNTIF(AA$3:AA8,AM8)+COUNTIF(AA$3:AA8,AN8)+COUNTIF(AA$3:AA8,AO8)+COUNTIF(AA$3:AA8,AP8)+COUNTIF(AA$3:AA8,AQ8)+COUNTIF(AA$3:AA8,AR8) -> 0 | AA8: =VLOOKUP(A8,howfared!$A$2:$B$33,2,FALSE) -> NE | AB8: =VLOOKUP(AA8,howfared!$B$2:$AH$33,2,FALSE) -> TEN | AC8: =VLOOKUP(AA8,howfared!$B$2:$AH$33,3,FALSE) -> 0 | AD8: =VLOOKUP(AA8,howfared!$B$2:$AH$33,4,FALSE) -> 0 | AE8: =VLOOKUP(AA8,howfared!$B$2:$AH$33,5,FALSE) -> 0 | AF8: =VLOOKUP(AA8,howfared!$B$2:$AH$33,6,FALSE) -> 0 | AG8: =VLOOKUP(AA8,howfared!$B$2:$AH$33,7,FALSE) -> 0 | AH8: =VLOOKUP(AA8,howfared!$B$2:$AH$33,8,FALSE) -> 0 | AI8: =VLOOKUP(AA8,howfared!$B$2:$AH$33,9,FALSE) -> 0 | AJ8: =VLOOKUP(AA8,howfared!$B$2:$AH$33,10,FALSE) -> 0 | AK8: =VLOOKUP(AA8,howfared!$B$2:$AH$33,11,FALSE) -> 0 | AL8: =VLOOKUP(AA8,howfared!$B$2:$AH$33,12,FALSE) -> 0 | AM8: =VLOOKUP(AA8,howfared!$B$2:$AH$33,13,FALSE) -> 0 | AN8: =VLOOKUP(AA8,howfared!$B$2:$AH$33,14,FALSE) -> 0 | AO8: =VLOOKUP(AA8,howfared!$B$2:$AH$33,15,FALSE) -> 0 | AP8: =VLOOKUP(AA8,howfared!$B$2:$AH$33,16,FALSE) -> 0 | AQ8: =VLOOKUP(AA8,howfared!$B$2:$AH$33,17,FALSE) -> 0 | AR8: =VLOOKUP(AA8,howfared!$B$2:$AH$33,18,FALSE) -> 0 | AS8: =AA8 -> NE | AT8: =D8 -> 2 | AU8: =E8 -> 2
A9: Philadelphia Eagles | B9: AFC | C9: NCE | D9: 3 | E9: 1 | F9: 0 | G9: 0.75 | H9: 66 | I9: 83 | J9: -17 | K9: 6 | L9: 2-0 | M9: 1-1 | N9: 1-0 | O9: 1 | P9: 1-1 | Q9: 0.5 | R9: 2-0 | S9: 1W | T9: 3-1 | U9: =H9/(D9+E9+F9) -> 16.5 | V9: =I9/(D9+E9+F9) -> 20.75 | W9: =U9-V9 -> -4.25 | X9: =SUM(D9:F9) -> 4 | Y9: 7 | Z9: =COUNTIF(AA$3:AA8,AB9)+COUNTIF(AA$3:AA9,AC9)+COUNTIF(AA$3:AA9,AD9)+COUNTIF(AA$3:AA9,AE9)+COUNTIF(AA$3:AA9,AF9)+COUNTIF(AA$3:AA9,AG9)+COUNTIF(AA$3:AA9,AH9)+COUNTIF(AA$3:AA9,AI9)+COUNTIF(AA$3:AA9,AJ9)+COUNTIF(AA$3:AA9,AK9)+COUNTIF(AA$3:AA9,AL9)+COUNTIF(AA$3:AA9,AM9)+COUNTIF(AA$3:AA9,AN9)+COUNTIF(AA$3:AA9,AO9)+COUNTIF(AA$3:AA9,AP9)+COUNTIF(AA$3:AA9,AQ9)+COUNTIF(AA$3:AA9,AR9) -> 1 | AA9: =VLOOKUP(A9,howfared!$A$2:$B$33,2,FALSE) -> PHI | AB9: =VLOOKUP(AA9,howfared!$B$2:$AH$33,2,FALSE) -> CLE | AC9: =VLOOKUP(AA9,howfared!$B$2:$AH$33,3,FALSE) -> BAL | AD9: =VLOOKUP(AA9,howfared!$B$2:$AH$33,4,FALSE) -> 0 | AE9: =VLOOKUP(AA9,howfared!$B$2:$AH$33,5,FALSE) -> 0 | AF9: =VLOOKUP(AA9,howfared!$B$2:$AH$33,6,FALSE) -> 0 | AG9: =VLOOKUP(AA9,howfared!$B$2:$AH$33,7,FALSE) -> 0 | AH9: =VLOOKUP(AA9,howfared!$B$2:$AH$33,8,FALSE) -> 0 | AI9: =VLOOKUP(AA9,howfared!$B$2:$AH$33,9,FALSE) -> 0 | AJ9: =VLOOKUP(AA9,howfared!$B$2:$AH$33,10,FALSE) -> 0 | AK9: =VLOOKUP(AA9,howfared!$B$2:$AH$33,11,FALSE) -> 0 | AL9: =VLOOKUP(AA9,howfared!$B$2:$AH$33,12,FALSE) -> 0 | AM9: =VLOOKUP(AA9,howfared!$B$2:$AH$33,13,FALSE) -> 0 | AN9: =VLOOKUP(AA9,howfared!$B$2:$AH$33,14,FALSE) -> 0 | AO9: =VLOOKUP(AA9,howfared!$B$2:$AH$33,15,FALSE) -> 0 | AP9: =VLOOKUP(AA9,howfared!$B$2:$AH$33,16,FALSE) -> 0 | AQ9: =VLOOKUP(AA9,howfared!$B$2:$AH$33,17,FALSE) -> 0 | AR9: =VLOOKUP(AA9,howfared!$B$2:$AH$33,18,FALSE) -> 0 | AS9: =AA9 -> PHI | AT9: =D9 -> 3 | AU9: =E9 -> 1
A10: Green Bay Packers | B10: NFC | C10: NCN | D10: 2 | E10: 2 | F10: 0 | G10: 0.5 | H10: 85 | I10: 81 | J10: 4 | K10: 10 | L10: 2-1 | M10: 0-1 | N10: 1-0 | O10: 1 | P10: 2-2 | Q10: 0.5 | R10: 0-0 | S10: 1W | T10: 2-2 | U10: =H10/(D10+E10+F10) -> 21.25 | V10: =I10/(D10+E10+F10) -> 20.25 | W10: =U10-V10 -> 1 | X10: =SUM(D10:F10) -> 4 | Y10: 8 | Z10: =COUNTIF(AA$3:AA9,AB10)+COUNTIF(AA$3:AA10,AC10)+COUNTIF(AA$3:AA10,AD10)+COUNTIF(AA$3:AA10,AE10)+COUNTIF(AA$3:AA10,AF10)+COUNTIF(AA$3:AA10,AG10)+COUNTIF(AA$3:AA10,AH10)+COUNTIF(AA$3:AA10,AI10)+COUNTIF(AA$3:AA10,AJ10)+COUNTIF(AA$3:AA10,AK10)+COUNTIF(AA$3:AA10,AL10)+COUNTIF(AA$3:AA10,AM10)+COUNTIF(AA$3:AA10,AN10)+COUNTIF(AA$3:AA10,AO10)+COUNTIF(AA$3:AA10,AP10)+COUNTIF(AA$3:AA10,AQ10)+COUNTIF(AA$3:AA10,AR10) -> 0 | AA10: =VLOOKUP(A10,howfared!$A$2:$B$33,2,FALSE) -> GB | AB10: =VLOOKUP(AA10,howfared!$B$2:$AH$33,2,FALSE) -> 0 | AC10: =VLOOKUP(AA10,howfared!$B$2:$AH$33,3,FALSE) -> CHI | AD10: =VLOOKUP(AA10,howfared!$B$2:$AH$33,4,FALSE) -> 0 | AE10: =VLOOKUP(AA10,howfared!$B$2:$AH$33,5,FALSE) -> 0 | AF10: =VLOOKUP(AA10,howfared!$B$2:$AH$33,6,FALSE) -> 0 | AG10: =VLOOKUP(AA10,howfared!$B$2:$AH$33,7,FALSE) -> 0 | AH10: =VLOOKUP(AA10,howfared!$B$2:$AH$33,8,FALSE) -> 0 | AI10: =VLOOKUP(AA10,howfared!$B$2:$AH$33,9,FALSE) -> 0 | AJ10: =VLOOKUP(AA10,howfared!$B$2:$AH$33,10,FALSE) -> 0 | AK10: =VLOOKUP(AA10,howfared!$B$2:$AH$33,11,FALSE) -> 0 | AL10: =VLOOKUP(AA10,howfared!$B$2:$AH$33,12,FALSE) -> 0 | AM10: =VLOOKUP(AA10,howfared!$B$2:$AH$33,13,FALSE) -> 0 | AN10: =VLOOKUP(AA10,howfared!$B$2:$AH$33,14,FALSE) -> 0 | AO10: =VLOOKUP(AA10,howfared!$B$2:$AH$33,15,FALSE) -> 0 | AP10: =VLOOKUP(AA10,howfared!$B$2:$AH$33,16,FALSE) -> 0 | AQ10: =VLOOKUP(AA10,howfared!$B$2:$AH$33,17,FALSE) -> 0 | AR10: =VLOOKUP(AA10,howfared!$B$2:$AH$33,18,FALSE) -> 0 | AS10: =AA10 -> GB | AT10: =D10 -> 2 | AU10: =E10 -> 2
A11: Chicago Bears | B11: AFC | C11: NCN | D11: 3 | E11: 1 | F11: 0 | G11: 0.75 | H11: 108 | I11: 68 | J11: 40 | K11: 12 | L11: 2-0 | M11: 1-1 | N11: 0-1 | O11: 0 | P11: 2-1 | Q11: 0.667 | R11: 1-0 | S11: 2W | T11: 3-1 | U11: =H11/(D11+E11+F11) -> 27 | V11: =I11/(D11+E11+F11) -> 17 | W11: =U11-V11 -> 10 | X11: =SUM(D11:F11) -> 4 | Y11: 9 | Z11: =COUNTIF(AA$3:AA10,AB11)+COUNTIF(AA$3:AA11,AC11)+COUNTIF(AA$3:AA11,AD11)+COUNTIF(AA$3:AA11,AE11)+COUNTIF(AA$3:AA11,AF11)+COUNTIF(AA$3:AA11,AG11)+COUNTIF(AA$3:AA11,AH11)+COUNTIF(AA$3:AA11,AI11)+COUNTIF(AA$3:AA11,AJ11)+COUNTIF(AA$3:AA11,AK11)+COUNTIF(AA$3:AA11,AL11)+COUNTIF(AA$3:AA11,AM11)+COUNTIF(AA$3:AA11,AN11)+COUNTIF(AA$3:AA11,AO11)+COUNTIF(AA$3:AA11,AP11)+COUNTIF(AA$3:AA11,AQ11)+COUNTIF(AA$3:AA11,AR11) -> 0 | AA11: =VLOOKUP(A11,howfared!$A$2:$B$33,2,FALSE) -> CHI | AB11: =VLOOKUP(AA11,howfared!$B$2:$AH$33,2,FALSE) -> IND | AC11: =VLOOKUP(AA11,howfared!$B$2:$AH$33,3,FALSE) -> 0 | AD11: =VLOOKUP(AA11,howfared!$B$2:$AH$33,4,FALSE) -> STL | AE11: =VLOOKUP(AA11,howfared!$B$2:$AH$33,5,FALSE) -> 0 | AF11: =VLOOKUP(AA11,howfared!$B$2:$AH$33,6,FALSE) -> 0 | AG11: =VLOOKUP(AA11,howfared!$B$2:$AH$33,7,FALSE) -> 0 | AH11: =VLOOKUP(AA11,howfared!$B$2:$AH$33,8,FALSE) -> 0 | AI11: =VLOOKUP(AA11,howfared!$B$2:$AH$33,9,FALSE) -> 0 | AJ11: =VLOOKUP(AA11,howfared!$B$2:$AH$33,10,FALSE) -> 0 | AK11: =VLOOKUP(AA11,howfared!$B$2:$AH$33,11,FALSE) -> 0 | AL11: =VLOOKUP(AA11,howfared!$B$2:$AH$33,12,FALSE) -> 0 | AM11: =VLOOKUP(AA11,howfared!$B$2:$AH$33,13,FALSE) -> 0 | AN11: =VLOOKUP(AA11,howfared!$B$2:$AH$33,14,FALSE) -> 0 | AO11: =VLOOKUP(AA11,howfared!$B$2:$AH$33,15,FALSE) -> 0 | AP11: =VLOOKUP(AA11,howfared!$B$2:$AH$33,16,FALSE) -> 0 | AQ11: =VLOOKUP(AA11,howfared!$B$2:$AH$33,17,FALSE) -> 0 | AR11: =VLOOKUP(AA11,howfared!$B$2:$AH$33,18,FALSE) -> 0 | AS11: =AA11 -> CHI | AT11: =D11 -> 3 | AU11: =E11 -> 1
A12: New York Giants | B12: NFC | C12: NCE | D12: 2 | E12: 2 | F12: 0 | G12: 0.5 | H12: 111 | I12: 84 | J12: 27 | K12: 11 | L12: 1-1 | M12: 1-1 | N12: 0-2 | O12: 0 | P12: 2-2 | Q12: 0.5 | R12: 0-0 | S12: 1L | T12: 2-2 | U12: =H12/(D12+E12+F12) -> 27.75 | V12: =I12/(D12+E12+F12) -> 21 | W12: =U12-V12 -> 6.75 | X12: =SUM(D12:F12) -> 4 | Y12: 10 | Z12: =COUNTIF(AA$3:AA11,AB12)+COUNTIF(AA$3:AA12,AC12)+COUNTIF(AA$3:AA12,AD12)+COUNTIF(AA$3:AA12,AE12)+COUNTIF(AA$3:AA12,AF12)+COUNTIF(AA$3:AA12,AG12)+COUNTIF(AA$3:AA12,AH12)+COUNTIF(AA$3:AA12,AI12)+COUNTIF(AA$3:AA12,AJ12)+COUNTIF(AA$3:AA12,AK12)+COUNTIF(AA$3:AA12,AL12)+COUNTIF(AA$3:AA12,AM12)+COUNTIF(AA$3:AA12,AN12)+COUNTIF(AA$3:AA12,AO12)+COUNTIF(AA$3:AA12,AP12)+COUNTIF(AA$3:AA12,AQ12)+COUNTIF(AA$3:AA12,AR12) -> 0 | AA12: =VLOOKUP(A12,howfared!$A$2:$B$33,2,FALSE) -> NYG | AB12: =VLOOKUP(AA12,howfared!$B$2:$AH$33,2,FALSE) -> 0 | AC12: =VLOOKUP(AA12,howfared!$B$2:$AH$33,3,FALSE) -> TB | AD12: =VLOOKUP(AA12,howfared!$B$2:$AH$33,4,FALSE) -> CAR | AE12: =VLOOKUP(AA12,howfared!$B$2:$AH$33,5,FALSE) -> 0 | AF12: =VLOOKUP(AA12,howfared!$B$2:$AH$33,6,FALSE) -> 0 | AG12: =VLOOKUP(AA12,howfared!$B$2:$AH$33,7,FALSE) -> 0 | AH12: =VLOOKUP(AA12,howfared!$B$2:$AH$33,8,FALSE) -> 0 | AI12: =VLOOKUP(AA12,howfared!$B$2:$AH$33,9,FALSE) -> 0 | AJ12: =VLOOKUP(AA12,howfared!$B$2:$AH$33,10,FALSE) -> 0 | AK12: =VLOOKUP(AA12,howfared!$B$2:$AH$33,11,FALSE) -> 0 | AL12: =VLOOKUP(AA12,howfared!$B$2:$AH$33,12,FALSE) -> 0 | AM12: =VLOOKUP(AA12,howfared!$B$2:$AH$33,13,FALSE) -> 0 | AN12: =VLOOKUP(AA12,howfared!$B$2:$AH$33,14,FALSE) -> 0 | AO12: =VLOOKUP(AA12,howfared!$B$2:$AH$33,15,FALSE) -> 0 | AP12: =VLOOKUP(AA12,howfared!$B$2:$AH$33,16,FALSE) -> 0 | AQ12: =VLOOKUP(AA12,howfared!$B$2:$AH$33,17,FALSE) -> 0 | AR12: =VLOOKUP(AA12,howfared!$B$2:$AH$33,18,FALSE) -> 0 | AS12: =AA12 -> NYG | AT12: =D12 -> 2 | AU12: =E12 -> 2
A13: San Diego Chargers | B13: NFC | C13: ACW | D13: 3 | E13: 1 | F13: 0 | G13: 0.75 | H13: 100 | I13: 71 | J13: 29 | K13: 10 | L13: 1-1 | M13: 2-0 | N13: 2-0 | O13: 1 | P13: 3-0 | Q13: 1 | R13: 0-1 | S13: 1W | T13: 3-1 | U13: =H13/(D13+E13+F13) -> 25 | V13: =I13/(D13+E13+F13) -> 17.75 | W13: =U13-V13 -> 7.25 | X13: =SUM(D13:F13) -> 4 | Y13: 11 | Z13: =COUNTIF(AA$3:AA12,AB13)+COUNTIF(AA$3:AA13,AC13)+COUNTIF(AA$3:AA13,AD13)+COUNTIF(AA$3:AA13,AE13)+COUNTIF(AA$3:AA13,AF13)+COUNTIF(AA$3:AA13,AG13)+COUNTIF(AA$3:AA13,AH13)+COUNTIF(AA$3:AA13,AI13)+COUNTIF(AA$3:AA13,AJ13)+COUNTIF(AA$3:AA13,AK13)+COUNTIF(AA$3:AA13,AL13)+COUNTIF(AA$3:AA13,AM13)+COUNTIF(AA$3:AA13,AN13)+COUNTIF(AA$3:AA13,AO13)+COUNTIF(AA$3:AA13,AP13)+COUNTIF(AA$3:AA13,AQ13)+COUNTIF(AA$3:AA13,AR13) -> 0 | AA13: =VLOOKUP(A13,howfared!$A$2:$B$33,2,FALSE) -> SD | AB13: =VLOOKUP(AA13,howfared!$B$2:$AH$33,2,FALSE) -> OAK | AC13: =VLOOKUP(AA13,howfared!$B$2:$AH$33,3,FALSE) -> TEN | AD13: =VLOOKUP(AA13,howfared!$B$2:$AH$33,4,FALSE) -> 0 | AE13: =VLOOKUP(AA13,howfared!$B$2:$AH$33,5,FALSE) -> 0 | AF13: =VLOOKUP(AA13,howfared!$B$2:$AH$33,6,FALSE) -> 0 | AG13: =VLOOKUP(AA13,howfared!$B$2:$AH$33,7,FALSE) -> 0 | AH13: =VLOOKUP(AA13,howfared!$B$2:$AH$33,8,FALSE) -> 0 | AI13: =VLOOKUP(AA13,howfared!$B$2:$AH$33,9,FALSE) -> 0 | AJ13: =VLOOKUP(AA13,howfared!$B$2:$AH$33,10,FALSE) -> 0 | AK13: =VLOOKUP(AA13,howfared!$B$2:$AH$33,11,FALSE) -> 0 | AL13: =VLOOKUP(AA13,howfared!$B$2:$AH$33,12,FALSE) -> 0 | AM13: =VLOOKUP(AA13,howfared!$B$2:$AH$33,13,FALSE) -> 0 | AN13: =VLOOKUP(AA13,howfared!$B$2:$AH$33,14,FALSE) -> 0 | AO13: =VLOOKUP(AA13,howfared!$B$2:$AH$33,15,FALSE) -> 0 | AP13: =VLOOKUP(AA13,howfared!$B$2:$AH$33,16,FALSE) -> 0 | AQ13: =VLOOKUP(AA13,howfared!$B$2:$AH$33,17,FALSE) -> 0 | AR13: =VLOOKUP(AA13,howfared!$B$2:$AH$33,18,FALSE) -> 0 | AS13: =AA13 -> SD | AT13: =D13 -> 3 | AU13: =E13 -> 1
A14: Cincinnati Bengals | B14: NFC | C14: ACN | D14: 3 | E14: 1 | F14: 0 | G14: 0.75 | H14: 112 | I14: 112 | J14: 0 | K14: 13 | L14: 1-0 | M14: 2-1 | N14: 1-1 | O14: 0.5 | P14: 2-1 | Q14: 0.667 | R14: 1-0 | S14: 3W | T14: 3-1 | U14: =H14/(D14+E14+F14) -> 28 | V14: =I14/(D14+E14+F14) -> 28 | W14: =U14-V14 -> 0 | X14: =SUM(D14:F14) -> 4 | Y14: 12 | Z14: =COUNTIF(AA$3:AA13,AB14)+COUNTIF(AA$3:AA14,AC14)+COUNTIF(AA$3:AA14,AD14)+COUNTIF(AA$3:AA14,AE14)+COUNTIF(AA$3:AA14,AF14)+COUNTIF(AA$3:AA14,AG14)+COUNTIF(AA$3:AA14,AH14)+COUNTIF(AA$3:AA14,AI14)+COUNTIF(AA$3:AA14,AJ14)+COUNTIF(AA$3:AA14,AK14)+COUNTIF(AA$3:AA14,AL14)+COUNTIF(AA$3:AA14,AM14)+COUNTIF(AA$3:AA14,AN14)+COUNTIF(AA$3:AA14,AO14)+COUNTIF(AA$3:AA14,AP14)+COUNTIF(AA$3:AA14,AQ14)+COUNTIF(AA$3:AA14,AR14) -> 0 | AA14: =VLOOKUP(A14,howfared!$A$2:$B$33,2,FALSE) -> CIN | AB14: =VLOOKUP(AA14,howfared!$B$2:$AH$33,2,FALSE) -> 0 | AC14: =VLOOKUP(AA14,howfared!$B$2:$AH$33,3,FALSE) -> CLE | AD14: =VLOOKUP(AA14,howfared!$B$2:$AH$33,4,FALSE) -> WAS | AE14: =VLOOKUP(AA14,howfared!$B$2:$AH$33,5,FALSE) -> 0 | AF14: =VLOOKUP(AA14,howfared!$B$2:$AH$33,6,FALSE) -> 0 | AG14: =VLOOKUP(AA14,howfared!$B$2:$AH$33,7,FALSE) -> 0 | AH14: =VLOOKUP(AA14,howfared!$B$2:$AH$33,8,FALSE) -> 0 | AI14: =VLOOKUP(AA14,howfared!$B$2:$AH$33,9,FALSE) -> 0 | AJ14: =VLOOKUP(AA14,howfared!$B$2:$AH$33,10,FALSE) -> 0 | AK14: =VLOOKUP(AA14,howfared!$B$2:$AH$33,11,FALSE) -> 0 | AL14: =VLOOKUP(AA14,howfared!$B$2:$AH$33,12,FALSE) -> 0 | AM14: =VLOOKUP(AA14,howfared!$B$2:$AH$33,13,FALSE) -> 0 | AN14: =VLOOKUP(AA14,howfared!$B$2:$AH$33,14,FALSE) -> 0 | AO14: =VLOOKUP(AA14,howfared!$B$2:$AH$33,15,FALSE) -> 0 | AP14: =VLOOKUP(AA14,howfared!$B$2:$AH$33,16,FALSE) -> 0 | AQ14: =VLOOKUP(AA14,howfared!$B$2:$AH$33,17,FALSE) -> 0 | AR14: =VLOOKUP(AA14,howfared!$B$2:$AH$33,18,FALSE) -> 0 | AS14: =AA14 -> CIN | AT14: =D14 -> 3 | AU14: =E14 -> 1
A15: Denver Broncos | B15: AFC | C15: ACW | D15: 2 | E15: 2 | F15: 0 | G15: 0.5 | H15: 114 | I15: 83 | J15: 31 | K15: 13 | L15: 2-1 | M15: 0-1 | N15: 1-0 | O15: 1 | P15: 2-1 | Q15: 0.667 | R15: 0-1 | S15: 1W | T15: 2-2 | U15: =H15/(D15+E15+F15) -> 28.5 | V15: =I15/(D15+E15+F15) -> 20.75 | W15: =U15-V15 -> 7.75 | X15: =SUM(D15:F15) -> 4 | Y15: 13 | Z15: =COUNTIF(AA$3:AA14,AB15)+COUNTIF(AA$3:AA15,AC15)+COUNTIF(AA$3:AA15,AD15)+COUNTIF(AA$3:AA15,AE15)+COUNTIF(AA$3:AA15,AF15)+COUNTIF(AA$3:AA15,AG15)+COUNTIF(AA$3:AA15,AH15)+COUNTIF(AA$3:AA15,AI15)+COUNTIF(AA$3:AA15,AJ15)+COUNTIF(AA$3:AA15,AK15)+COUNTIF(AA$3:AA15,AL15)+COUNTIF(AA$3:AA15,AM15)+COUNTIF(AA$3:AA15,AN15)+COUNTIF(AA$3:AA15,AO15)+COUNTIF(AA$3:AA15,AP15)+COUNTIF(AA$3:AA15,AQ15)+COUNTIF(AA$3:AA15,AR15) -> 0 | AA15: =VLOOKUP(A15,howfared!$A$2:$B$33,2,FALSE) -> DEN | AB15: =VLOOKUP(AA15,howfared!$B$2:$AH$33,2,FALSE) -> PIT | AC15: =VLOOKUP(AA15,howfared!$B$2:$AH$33,3,FALSE) -> 0 | AD15: =VLOOKUP(AA15,howfared!$B$2:$AH$33,4,FALSE) -> 0 | AE15: =VLOOKUP(AA15,howfared!$B$2:$AH$33,5,FALSE) -> 0 | AF15: =VLOOKUP(AA15,howfared!$B$2:$AH$33,6,FALSE) -> 0 | AG15: =VLOOKUP(AA15,howfared!$B$2:$AH$33,7,FALSE) -> 0 | AH15: =VLOOKUP(AA15,howfared!$B$2:$AH$33,8,FALSE) -> 0 | AI15: =VLOOKUP(AA15,howfared!$B$2:$AH$33,9,FALSE) -> 0 | AJ15: =VLOOKUP(AA15,howfared!$B$2:$AH$33,10,FALSE) -> 0 | AK15: =VLOOKUP(AA15,howfared!$B$2:$AH$33,11,FALSE) -> 0 | AL15: =VLOOKUP(AA15,howfared!$B$2:$AH$33,12,FALSE) -> 0 | AM15: =VLOOKUP(AA15,howfared!$B$2:$AH$33,13,FALSE) -> 0 | AN15: =VLOOKUP(AA15,howfared!$B$2:$AH$33,14,FALSE) -> 0 | AO15: =VLOOKUP(AA15,howfared!$B$2:$AH$33,15,FALSE) -> 0 | AP15: =VLOOKUP(AA15,howfared!$B$2:$AH$33,16,FALSE) -> 0 | AQ15: =VLOOKUP(AA15,howfared!$B$2:$AH$33,17,FALSE) -> 0 | AR15: =VLOOKUP(AA15,howfared!$B$2:$AH$33,18,FALSE) -> 0 | AS15: =AA15 -> DEN | AT15: =D15 -> 2 | AU15: =E15 -> 2
... A34: Cleveland Browns | B34: AFC | C34: ACN | D34: 0 | E34: 4 | F34: 0 | G34: 0 | H34: 73 | I34: 98 | J34: -25 | K34: 7 | L34: 0-2 | M34: 0-2 | N34: 0-2 | O34: 0 | P34: 0-3 | Q34: 0 | R34: 0-1 | S34: 4L | T34: 0-4 | U34: =H34/(D34+E34+F34) -> 18.25 | V34: =I34/(D34+E34+F34) -> 24.5 | W34: =U34-V34 -> -6.25 | X34: =SUM(D34:F34) -> 4 | Y34: 32 | Z34: =COUNTIF(AA$3:AA33,AB34)+COUNTIF(AA$3:AA34,AC34)+COUNTIF(AA$3:AA34,AD34)+COUNTIF(AA$3:AA34,AE34)+COUNTIF(AA$3:AA34,AF34)+COUNTIF(AA$3:AA34,AG34)+COUNTIF(AA$3:AA34,AH34)+COUNTIF(AA$3:AA34,AI34)+COUNTIF(AA$3:AA34,AJ34)+COUNTIF(AA$3:AA34,AK34)+COUNTIF(AA$3:AA34,AL34)+COUNTIF(AA$3:AA34,AM34)+COUNTIF(AA$3:AA34,AN34)+COUNTIF(AA$3:AA34,AO34)+COUNTIF(AA$3:AA34,AP34)+COUNTIF(AA$3:AA34,AQ34)+COUNTIF(AA$3:AA34,AR34) -> 0 | AA34: =VLOOKUP(A34,howfared!$A$2:$B$33,2,FALSE) -> CLE | AB34: =VLOOKUP(AA34,howfared!$B$2:$AH$33,2,FALSE) -> 0 | AC34: =VLOOKUP(AA34,howfared!$B$2:$AH$33,3,FALSE) -> 0 | AD34: =VLOOKUP(AA34,howfared!$B$2:$AH$33,4,FALSE) -> 0 | AE34: =VLOOKUP(AA34,howfared!$B$2:$AH$33,5,FALSE) -> 0 | AF34: =VLOOKUP(AA34,howfared!$B$2:$AH$33,6,FALSE) -> 0 | AG34: =VLOOKUP(AA34,howfared!$B$2:$AH$33,7,FALSE) -> 0 | AH34: =VLOOKUP(AA34,howfared!$B$2:$AH$33,8,FALSE) -> 0 | AI34: =VLOOKUP(AA34,howfared!$B$2:$AH$33,9,FALSE) -> 0 | AJ34: =VLOOKUP(AA34,howfared!$B$2:$AH$33,10,FALSE) -> 0 | AK34: =VLOOKUP(AA34,howfared!$B$2:$AH$33,11,FALSE) -> 0 | AL34: =VLOOKUP(AA34,howfared!$B$2:$AH$33,12,FALSE) -> 0 | AM34: =VLOOKUP(AA34,howfared!$B$2:$AH$33,13,FALSE) -> 0 | AN34: =VLOOKUP(AA34,howfared!$B$2:$AH$33,14,FALSE) -> 0 | AO34: =VLOOKUP(AA34,howfared!$B$2:$AH$33,15,FALSE) -> 0 | AP34: =VLOOKUP(AA34,howfared!$B$2:$AH$33,16,FALSE) -> 0 | AQ34: =VLOOKUP(AA34,howfared!$B$2:$AH$33,17,FALSE) -> 0 | AR34: =VLOOKUP(AA34,howfared!$B$2:$AH$33,18,FALSE) -> 0 | AS34: =AA34 -> CLE | AT34: =D34 -> 0 | AU34: =E34 -> 4

Sheet Power by Week
A1: Team | B1: Week 1 | C1: Week 2 | D1: Week 3 | E1: Week 4 | F1: Week 5 | G1: Week 6 | H1: Week 7 | I1: Week 8 | J1: Week 9 | K1: Week 10 | L1: Week 11 | M1: Week 12 | N1: Week 13 | O1: Week 14 | P1: Week 15 | Q1: Week 16 | R1: Week 17 | S1: Average | T1: Highest | U1: Lowest | V1: Biggest Gap | W1: Team Change Code | X1: Change from Last Week | Y1: Change from Week 1
A2: Minnesota Vikings | B2: 31 | C2: 28 | D2: 29 | E2: 21 | F2: 14 | S2: =AVERAGE(B2:R2) -> 24.6 | T2: =MINA(B2:R2) -> 14 | U2: =MAXA(B2:R2) -> 31 | V2: =U2-T2 -> 17 | W2: =IF(X2<0,CONCATENATE(A2," (-",ABS(X2),"), "),IF(X2=0,CONCATENATE(A2,", "),CONCATENATE(A2," (+",ABS(X2),"), "))) -> #REF! | X2: =#REF!-B2 -> #REF! | Y2: =#REF!-B2 -> #REF!
A3: Seattle Seahawks | B3: 22 | C3: 26 | D3: 17 | E3: 10 | F3: 17 | S3: =AVERAGE(B3:R3) -> 18.4 | T3: =MINA(B3:R3) -> 10 | U3: =MAXA(B3:R3) -> 26 | V3: =U3-T3 -> 16 | W3: =IF(X3<0,CONCATENATE(A3," (-",ABS(X3),"), "),IF(X3=0,CONCATENATE(A3,", "),CONCATENATE(A3," (+",ABS(X3),"), "))) -> #REF! | X3: =#REF!-B3 -> #REF! | Y3: =#REF!-B3 -> #REF!
A4: Arizona Cardinals | B4: 19 | C4: 20 | D4: 14 | E4: 5 | F4: 5 | S4: =AVERAGE(B4:R4) -> 12.6 | T4: =MINA(B4:R4) -> 5 | U4: =MAXA(B4:R4) -> 20 | V4: =U4-T4 -> 15 | W4: =IF(X4<0,CONCATENATE(A4," (-",ABS(X4),"), "),IF(X4=0,CONCATENATE(A4,", "),CONCATENATE(A4," (+",ABS(X4),"), "))) -> #REF! | X4: =#REF!-B4 -> #REF! | Y4: =#REF!-B4 -> #REF!
A5: New Orleans Saints | B5: 13 | C5: 16 | D5: 24 | E5: 28 | F5: 28 | S5: =AVERAGE(B5:R5) -> 21.8 | T5: =MINA(B5:R5) -> 13 | U5: =MAXA(B5:R5) -> 28 | V5: =U5-T5 -> 15 | W5: =IF(X5<0,CONCATENATE(A5," (-",ABS(X5),"), "),IF(X5=0,CONCATENATE(A5,", "),CONCATENATE(A5," (+",ABS(X5),"), "))) -> #REF! | X5: =#REF!-B5 -> #REF! | Y5: =#REF!-B5 -> #REF!
A6: Detroit Lions | B6: 9 | C6: 13 | D6: 13 | E6: 18 | F6: 20 | S6: =AVERAGE(B6:R6) -> 14.6 | T6: =MINA(B6:R6) -> 9 | U6: =MAXA(B6:R6) -> 20 | V6: =U6-T6 -> 11 | W6: =IF(X6<0,CONCATENATE(A6," (-",ABS(X6),"), "),IF(X6=0,CONCATENATE(A6,", "),CONCATENATE(A6," (+",ABS(X6),"), "))) -> #REF! | X6: =#REF!-B6 -> #REF! | Y6: =#REF!-B6 -> #REF!
A7: Kansas City Chiefs | B7: 17 | C7: 19 | D7: 28 | E7: 26 | F7: 27 | S7: =AVERAGE(B7:R7) -> 23.4 | T7: =MINA(B7:R7) -> 17 | U7: =MAXA(B7:R7) -> 28 | V7: =U7-T7 -> 11 | W7: =IF(X7<0,CONCATENATE(A7," (-",ABS(X7),"), "),IF(X7=0,CONCATENATE(A7,", "),CONCATENATE(A7," (+",ABS(X7),"), "))) -> #REF! | X7: =#REF!-B7 -> #REF! | Y7: =#REF!-B7 -> #REF!
A8: Atlanta Falcons | B8: 12 | C8: 6 | D8: 3 | E8: 2 | F8: 2 | S8: =AVERAGE(B8:R8) -> 5 | T8: =MINA(B8:R8) -> 2 | U8: =MAXA(B8:R8) -> 12 | V8: =U8-T8 -> 10 | W8: =IF(X8<0,CONCATENATE(A8," (-",ABS(X8),"), "),IF(X8=0,CONCATENATE(A8,", "),CONCATENATE(A8," (+",ABS(X8),"), "))) -> #REF! | X8: =#REF!-B8 -> #REF! | Y8: =#REF!-B8 -> #REF!
A9: St. Louis Rams | B9: 29 | C9: 27 | D9: 23 | E9: 25 | F9: 19 | S9: =AVERAGE(B9:R9) -> 24.6 | T9: =MINA(B9:R9) -> 19 | U9: =MAXA(B9:R9) -> 29 | V9: =U9-T9 -> 10 | W9: =IF(X9<0,CONCATENATE(A9," (-",ABS(X9),"), "),IF(X9=0,CONCATENATE(A9,", "),CONCATENATE(A9," (+",ABS(X9),"), "))) -> #REF! | X9: =#REF!-B9 -> #REF! | Y9: =#REF!-B9 -> #REF!
A10: Washington Redskins | B10: 25 | C10: 15 | D10: 20 | E10: 22 | F10: 18 | S10: =AVERAGE(B10:R10) -> 20 | T10: =MINA(B10:R10) -> 15 | U10: =MAXA(B10:R10) -> 25 | V10: =U10-T10 -> 10 | W10: =IF(X10<0,CONCATENATE(A10," (-",ABS(X10),"), "),IF(X10=0,CONCATENATE(A10,", "),CONCATENATE(A10," (+",ABS(X10),"), "))) -> #REF! | X10: =#REF!-B10 -> #REF! | Y10: =#REF!-B10 -> #REF!
A11: New York Giants | B11: 1 | C11: 7 | D11: 8 | E11: 6 | F11: 10 | S11: =AVERAGE(B11:R11) -> 6.4 | T11: =MINA(B11:R11) -> 1 | U11: =MAXA(B11:R11) -> 10 | V11: =U11-T11 -> 9 | W11: =IF(X11<0,CONCATENATE(A11," (-",ABS(X11),"), "),IF(X11=0,CONCATENATE(A11,", "),CONCATENATE(A11," (+",ABS(X11),"), "))) -> #REF! | X11: =#REF!-B11 -> #REF! | Y11: =#REF!-B11 -> #REF!
A12: Pittsburgh Steelers | B12: 8 | C12: 11 | D12: 9 | E12: 16 | F12: 16 | S12: =AVERAGE(B12:R12) -> 12 | T12: =MINA(B12:R12) -> 8 | U12: =MAXA(B12:R12) -> 16 | V12: =U12-T12 -> 8 | W12: =IF(X12<0,CONCATENATE(A12," (-",ABS(X12),"), "),IF(X12=0,CONCATENATE(A12,", "),CONCATENATE(A12," (+",ABS(X12),"), "))) -> #REF! | X12: =#REF!-B12 -> #REF! | Y12: =#REF!-B12 -> #REF!
A13: Tennessee Titans | B13: 18 | C13: 22 | D13: 26 | E13: 24 | F13: 25 | S13: =AVERAGE(B13:R13) -> 23 | T13: =MINA(B13:R13) -> 18 | U13: =MAXA(B13:R13) -> 26 | V13: =U13-T13 -> 8 | W13: =IF(X13<0,CONCATENATE(A13," (-",ABS(X13),"), "),IF(X13=0,CONCATENATE(A13,", "),CONCATENATE(A13," (+",ABS(X13),"), "))) -> #REF! | X13: =#REF!-B13 -> #REF! | Y13: =#REF!-B13 -> #REF!
... A33: Cleveland Browns | B33: 30 | C33: 31 | D33: 32 | E33: 32 | F33: 32 | S33: =AVERAGE(B33:R33) -> 31.4 | T33: =MINA(B33:R33) -> 30 | U33: =MAXA(B33:R33) -> 32 | V33: =U33-T33 -> 2 | W33: =IF(X33<0,CONCATENATE(A33," (-",ABS(X33),"), "),IF(X33=0,CONCATENATE(A33,", "),CONCATENATE(A33," (+",ABS(X33),"), "))) -> #REF! | X33: =#REF!-B33 -> #REF! | Y33: =#REF!-B33 -> #REF!

Sheet divisions
A1: Voter | B1: AFC East | C1: AFC North | D1: AFC South | E1: AFC West | F1: NFC East | G1: NFC North | H1: NFC South | I1: NFC West | J1: Average (should equal 16.5)
A2: Mike Sando | B2: 18.75 | C2: 15.75 | D2: 22 | E2: 20.25 | F2: 13.75 | G2: 12.25 | H2: 19 | I2: 10.25 | J2: 16.5 | AE2: 0
A3: John Clayton | B3: 19 | C3: 15.25 | D3: 22 | E3: 20.25 | F3: 14.75 | G3: 12.75 | H3: 17.5 | I3: 10.5 | J3: 16.5 | AE3: 0
A4: Dan Graziano | B4: 20.25 | C4: 15.75 | D4: 22.25 | E4: 20.25 | F4: 11.25 | G4: 12.25 | H4: 17.5 | I4: 12.5 | J4: 16.5 | AE4: 0
A5: Jamison Hensley | B5: 20 | C5: 16 | D5: 19.75 | E5: 21 | F5: 12.25 | G5: 13.25 | H5: 19 | I5: 10.75 | J5: 16.5 | AE5: 0
A6: Ashley Fox | B6: 18.5 | C6: 16 | D6: 21.75 | E6: 18.25 | F6: 11.25 | G6: 14.25 | H6: 20 | I6: 12 | J6: 16.5 | AE6: 0
AE7: 0
A8: Average | B8: 19.3 | C8: 15.75 | D8: 21.55 | E8: 20 | F8: 12.65 | G8: 12.95 | H8: 18.6 | I8: 11.2 | AE8: 0
A9: Rank | B9: 6 | C9: 4 | D9: 8 | E9: 7 | F9: 2 | G9: 3 | H9: 5 | I9: 1

Sheet howfared
A1: Team | B1: Code | C1: Beat | D1: Beat | E1: Beat | F1: Beat | G1: Beat | H1: Beat | I1: Beat | J1: Beat | K1: Beat | L1: Beat | M1: Beat | N1: Beat | O1: Beat | P1: Beat | Q1: Beat | R1: Beat | S1: Beat | T1: Total Wins | U1: Playoffs | V1: Wins vs Playoff Teams | W1: Losses vs Playoff Teams
A2: Arizona Cardinals | B2: ARI | C2: SEA | D2: NE | E2: PHI | T2: =COUNTIF(C2:S2,">0'") -> 3
A3: Atlanta Falcons | B3: ATL | C3: KC | D3: DEN | E3: SD | T3: =COUNTIF(C3:S3,">0'") -> 3
A4: Baltimore Ravens | B4: BAL | C4: CIN | E4: NE | T4: =COUNTIF(C4:S4,">0'") -> 2
A5: Buffalo Bills | B5: BUF | D5: KC | E5: CLE | T5: =COUNTIF(C5:S5,">0'") -> 2
A6: Carolina Panthers | B6: CAR | D6: NO | T6: =COUNTIF(C6:S6,">0'") -> 1
A7: Chicago Bears | B7: CHI | C7: IND | E7: STL | T7: =COUNTIF(C7:S7,">0'") -> 2
A8: Cincinnati Bengals | B8: CIN | D8: CLE | E8: WAS | T8: =COUNTIF(C8:S8,">0'") -> 2
A9: Cleveland Browns | B9: CLE | T9: =COUNTIF(C9:S9,">0'") -> 0
A10: Dallas Cowboys | B10: DAL | C10: NYG | E10: TB | T10: =COUNTIF(C10:S10,">0'") -> 2
A11: Denver Broncos | B11: DEN | C11: PIT | T11: =COUNTIF(C11:S11,">0'") -> 1
A12: Detroit Lions | B12: DET | C12: STL | T12: =COUNTIF(C12:S12,">0'") -> 1
A13: Green Bay Packers | B13: GB | D13: CHI | T13: =COUNTIF(C13:S13,">0'") -> 1
A14: Houston Texans | B14: HOU | C14: MIA | D14: JAC | E14: DEN | T14: =COUNTIF(C14:S14,">0'") -> 3
A15: Indianapolis Colts | B15: IND | D15: MIN | T15: =COUNTIF(C15:S15,">0'") -> 1
A16: Jacksonville Jaguars | B16: JAC | E16: IND | T16: =COUNTIF(C16:S16,">0'") -> 1
A17: Kansas City Chiefs | B17: KC | E17: NO | T17: =COUNTIF(C17:S17,">0'") -> 1
A18: Miami Dolphins | B18: MIA | D18: OAK | T18: =COUNTIF(C18:S18,">0'") -> 1
A19: Minnesota Vikings | B19: MIN | C19: JAC | E19: SF | T19: =COUNTIF(C19:S19,">0'") -> 2
A20: New England Patriots | B20: NE | C20: TEN | T20: =COUNTIF(C20:S20,">0'") -> 1
A21: New Orleans Saints | B21: NO | T21: =COUNTIF(C21:S21,">0'") -> 0
A22: New York Giants | B22: NYG | D22: TB | E22: CAR | T22: =COUNTIF(C22:S22,">0'") -> 2
A23: New York Jets | B23: NYJ | C23: BUF | E23: MIA | T23: =COUNTIF(C23:S23,">0'") -> 2
A24: Oakland Raiders | B24: OAK | E24: PIT | T24: =COUNTIF(C24:S24,">0'") -> 1
A25: Philadelphia Eagles | B25: PHI | C25: CLE | D25: BAL | T25: =COUNTIF(C25:S25,">0'") -> 2
A26: Pittsburgh Steelers | B26: PIT | D26: NYJ | T26: =COUNTIF(C26:S26,">0'") -> 1
A27: San Diego Chargers | B27: SD | C27: OAK | D27: TEN | T27: =COUNTIF(C27:S27,">0'") -> 2
A28: San Francisco 49ers | B28: SF | C28: GB | D28: DET | T28: =COUNTIF(C28:S28,">0'") -> 2
A29: Seattle Seahawks | B29: SEA | D29: DAL | E29: GB | T29: =COUNTIF(C29:S29,">0'") -> 2
A30: St. Louis Rams | B30: STL | D30: WAS | T30: =COUNTIF(C30:S30,">0'") -> 1
A31: Tampa Bay Buccaneers | B31: TB | C31: CAR | T31: =COUNTIF(C31:S31,">0'") -> 1
A32: Tennessee Titans | B32: TEN | E32: DET | T32: =COUNTIF(C32:S32,">0'") -> 1
A33: Washington Redskins | B33: WAS | C33: NO | T33: =COUNTIF(C33:S33,">0'") -> 1
