Workbook
Name RRDEL: #REF!

Sheet Port Region Graphs-weekly
B1: With new data | P1: Group this figure if use preliminary data

Sheet Weekly Data
A1: New Table 3_Rrport, * Miss. River deliveries data incomplete prior to 2004
A2: Rail Deliveries to Port
C6: S Atlantic | D6: Mississippi | F6: Cross Border | H6: Atlantic & | J6: Cross Border | K6: Week
A7: DATE | B7: N Atlantic | C7: East Gulf | D7: River* | E7: Texas | F7: Mexico | G7: Pacific | H7: East Gulf | I7: Total* | J7: Mexico-2 | K7: Number
A8: 34346 | B8: 16 | C8: 0 | E8: 910 | G8: 976 | H8: =B8+C8 -> 16
A9: 34353 | B9: 3 | C9: 138 | E9: 2156 | G9: 3445 | H9: =B9+C9 -> 141
A10: 34360 | B10: 30 | C10: 64 | E10: 1933 | G10: 3616 | H10: =B10+C10 -> 94
A11: 34367 | B11: 50 | C11: 15 | E11: 1978 | G11: 2805 | H11: =B11+C11 -> 65
A12: 34374 | B12: 61 | C12: 23 | E12: 1702 | G12: 2388 | H12: =B12+C12 -> 84
A13: 34381 | B13: 30 | C13: 74 | E13: 1576 | G13: 1697 | H13: =B13+C13 -> 104
A14: 34388 | B14: 35 | C14: 5 | E14: 1947 | G14: 2761 | H14: =B14+C14 -> 40
A15: 34395 | B15: 120 | C15: 3 | E15: 1771 | G15: 2749 | H15: =B15+C15 -> 123
A16: 34402 | B16: 132 | C16: 75 | E16: 1144 | G16: 2661 | H16: =B16+C16 -> 207
A17: 34409 | B17: 95 | C17: 81 | E17: 1434 | G17: 3125 | H17: =B17+C17 -> 176
A18: 34416 | B18: 142 | C18: 75 | E18: 1881 | G18: 3488 | H18: =B18+C18 -> 217
A19: 34423 | B19: 59 | C19: 57 | E19: 1453 | G19: 3000 | H19: =B19+C19 -> 116
... A80: 34850 | B80: 23 | C80: 39 | E80: 1004 | G80: 5238 | H80: =B80+C80 -> 62
A81: 34857 | B81: 25 | C81: =2+338 -> 340 | E81: =499+194+290+1 -> 984 | G81: 5144 | H81: =B81+C81 -> 365
A82: 34864 | B82: 72 | C82: 109 | E82: 1828 | G82: 5242 | H82: =B82+C82 -> 181
A83: 34871 | B83: 46 | C83: 110 | E83: 2036 | G83: 4661 | H83: =B83+C83 -> 156
A84: 34878 | B84: 126 | C84: 138 | E84: 2638 | G84: 5658 | H84: =B84+C84 -> 264
A85: 34885 | B85: 143 | C85: 45 | E85: 2423 | G85: 4821 | H85: =B85+C85 -> 188
A86: 34892 | B86: 93 | C86: 322 | E86: 845 | G86: 4273 | H86: =B86+C86 -> 415
A87: 34899 | B87: 127 | C87: 177 | E87: 1882 | G87: 5701 | H87: =B87+C87 -> 304
A88: 34906 | B88: 88 | C88: 166 | E88: 1319 | G88: 5611 | H88: =B88+C88 -> 254
A89: 34913 | B89: 270 | C89: 43 | E89: 1541 | G89: 3948 | H89: =B89+C89 -> 313
A90: 34920 | B90: 189 | C90: 107 | E90: 2220 | G90: 4827 | H90: =B90+C90 -> 296
A91: 34927 | B91: 161 | C91: 53 | E91: 2525 | G91: 3935 | H91: =B91+C91 -> 214
A92: 34934 | B92: 76 | C92: 68 | E92: 3144 | G92: 5174 | H92: =B92+C92 -> 144
A93: 34941 | B93: 100 | C93: 88 | E93: 2799 | G93: 5407 | H93: =B93+C93 -> 188
... A110: 35060 | B110: 47 | C110: 138 | E110: 2477 | G110: 4385 | H110: =B110+C110 -> 185
A111: 35067 | B111: 10 | C111: 8 | E111: 2306 | G111: 5000 | H111: =B111+C111 -> 18 | K111: 1
A112: 35074 | B112: 52 | C112: 109 | E112: 2494 | G112: 6954 | H112: =B112+C112 -> 161 | K112: =K111+1 -> 2
A113: 35081 | B113: 86 | C113: 69 | E113: 2342 | G113: 7663 | H113: =B113+C113 -> 155 | K113: =K112+1 -> 3
A114: 35088 | B114: 195 | C114: 201 | E114: 2381 | G114: 6516 | H114: =B114+C114 -> 396 | K114: =K113+1 -> 4
A115: 35095 | B115: 33 | C115: 297 | E115: 2388 | G115: 4721 | H115: =B115+C115 -> 330 | K115: =K114+1 -> 5
A116: 35102 | B116: 66 | C116: 306 | E116: 2620 | G116: 4137 | H116: =B116+C116 -> 372 | K116: =K115+1 -> 6
A117: 35109 | B117: 124 | C117: 131 | E117: 2789 | G117: 1520 | H117: =B117+C117 -> 255 | K117: =K116+1 -> 7
A118: 35116 | B118: 61 | C118: 589 | E118: 2971 | G118: 5090 | H118: =B118+C118 -> 650 | K118: =K117+1 -> 8
A119: 35123 | B119: 119 | C119: 326 | E119: 3542 | G119: 5844 | H119: =B119+C119 -> 445 | K119: =K118+1 -> 9
...

Sheet Weekly Averages
A2: * Miss. River deliveries data incomplete prior to 2004
B4: with new
B5: data | J5: 3-yr avg (when red) | O5: 3-yr avg (when red) | S5: 3-yr avg (when red) | X5: 3-yr avg (when red)
B6: Mississippi | C6: Texas | D6: Cross-Border | E6: Pacific | F6: Atlantic & | H6: Cross-Border | J6: Prior 4-year Averages (carloads) (week to week) | P6: Cross-Border | S6: Prior 4-year Averages (carloads) (of 4 week running average) | Y6: Cross-Border
B7: River* | C7: Gulf | D7: Mexico | E7: Northwest | F7: E Gulf | G7: Total | H7: Mexico -2 | J7: Mississippi | K7: Texas | L7: Cross-Border | M7: Pacific | N7: Atlantic & | P7: Mexico -2 | S7: Mississippi | T7: Texas | U7: Cross-Border | V7: Pacific | W7: Atlantic & | Y7: Mexico -2
J8: River (new) | K8: Gulf | L8: Mexico | M8: Northwest | N8: E Gulf | O8: Total | S8: River (new) | T8: Gulf | U8: Mexico | V8: Northwest | W8: E Gulf | X8: Total
D9: Cross-Border
C10: Texas | D10: Mexico | E10: Pacific
A11: 34367 | C11: =SUM('Weekly Data'!E8:E11)/4 -> 1744.25 | E11: =SUM('Weekly Data'!G8:G11)/4 -> 2710.5 | F11: =SUM('Weekly Data'!H8:H11)/4 -> 79 | R11: 34367
A12: =A11+7 -> 34374 | C12: =SUM('Weekly Data'!E9:E12)/4 -> 1942.25 | E12: =SUM('Weekly Data'!G9:G12)/4 -> 3063.5 | F12: =SUM('Weekly Data'!H9:H12)/4 -> 96 | R12: 34374
A13: =A12+7 -> 34381 | C13: =SUM('Weekly Data'!E10:E13)/4 -> 1797.25 | E13: =SUM('Weekly Data'!G10:G13)/4 -> 2626.5 | F13: =SUM('Weekly Data'!H10:H13)/4 -> 86.75 | R13: 34381
A14: =A13+7 -> 34388 | C14: =SUM('Weekly Data'!E11:E14)/4 -> 1800.75 | E14: =SUM('Weekly Data'!G11:G14)/4 -> 2412.75 | F14: =SUM('Weekly Data'!H11:H14)/4 -> 73.25 | R14: 34388
A15: =A14+7 -> 34395 | C15: =SUM('Weekly Data'!E12:E15)/4 -> 1749 | E15: =SUM('Weekly Data'!G12:G15)/4 -> 2398.75 | F15: =SUM('Weekly Data'!H12:H15)/4 -> 87.75 | R15: 34395
A16: =A15+7 -> 34402 | C16: =SUM('Weekly Data'!E13:E16)/4 -> 1609.5 | E16: =SUM('Weekly Data'!G13:G16)/4 -> 2467 | F16: =SUM('Weekly Data'!H13:H16)/4 -> 118.5 | R16: 34402
A17: =A16+7 -> 34409 | C17: =SUM('Weekly Data'!E14:E17)/4 -> 1574 | E17: =SUM('Weekly Data'!G14:G17)/4 -> 2824 | F17: =SUM('Weekly Data'!H14:H17)/4 -> 136.5 | R17: 34409
A18: =A17+7 -> 34416 | C18: =SUM('Weekly Data'!E15:E18)/4 -> 1557.5 | E18: =SUM('Weekly Data'!G15:G18)/4 -> 3005.75 | F18: =SUM('Weekly Data'!H15:H18)/4 -> 180.75 | R18: 34416
A19: =A18+7 -> 34423 | C19: =SUM('Weekly Data'!E16:E19)/4 -> 1478 | E19: =SUM('Weekly Data'!G16:G19)/4 -> 3068.5 | F19: =SUM('Weekly Data'!H16:H19)/4 -> 179 | R19: 34423
A20: =A19+7 -> 34430 | C20: =SUM('Weekly Data'!E17:E20)/4 -> 1532.5 | E20: =SUM('Weekly Data'!G17:G20)/4 -> 3096.75 | F20: =SUM('Weekly Data'!H17:H20)/4 -> 179 | R20: 34430
A21: =A20+7 -> 34437 | C21: =SUM('Weekly Data'!E18:E21)/4 -> 1530.5 | E21: =SUM('Weekly Data'!G18:G21)/4 -> 2854 | F21: =SUM('Weekly Data'!H18:H21)/4 -> 178.5 | R21: 34437
A22: =A21+7 -> 34444 | C22: =SUM('Weekly Data'!E19:E22)/4 -> 1374.75 | E22: =SUM('Weekly Data'!G19:G22)/4 -> 2645.75 | F22: =SUM('Weekly Data'!H19:H22)/4 -> 138 | R22: 34444
A23: =A22+7 -> 34451 | C23: =SUM('Weekly Data'!E20:E23)/4 -> 1506.5 | E23: =SUM('Weekly Data'!G20:G23)/4 -> 2434 | F23: =SUM('Weekly Data'!H20:H23)/4 -> 125 | R23: 34451
... A426: =A425+7 -> 37272 | C426: =SUM('Weekly Data'!E423:E426)/4 -> 1696.5 | E426: =SUM('Weekly Data'!G423:G426)/4 -> 1711.5 | F426: =SUM('Weekly Data'!H423:H426)/4 -> 894 | R426: 37272
A427: =A426+7 -> 37279 | C427: =SUM('Weekly Data'!E424:E427)/4 -> 1728.75 | D427: =SUM('Weekly Data'!F424:F427)/4 -> 459 | E427: =SUM('Weekly Data'!G424:G427)/4 -> 1479 | F427: =SUM('Weekly Data'!H424:H427)/4 -> 988.75 | R427: 37279
A428: =A427+7 -> 37286 | C428: =SUM('Weekly Data'!E425:E428)/4 -> 2135 | D428: =SUM('Weekly Data'!F425:F428)/4 -> 525.25 | E428: =SUM('Weekly Data'!G425:G428)/4 -> 1763.5 | F428: =SUM('Weekly Data'!H425:H428)/4 -> 1027.75 | R428: 37286
A429: =A428+7 -> 37293 | C429: =SUM('Weekly Data'!E426:E429)/4 -> 1909 | D429: =SUM('Weekly Data'!F426:F429)/4 -> 527.25 | E429: =SUM('Weekly Data'!G426:G429)/4 -> 2140.25 | F429: =SUM('Weekly Data'!H426:H429)/4 -> 952 | R429: 37293
A430: =A429+7 -> 37300 | C430: =SUM('Weekly Data'!E427:E430)/4 -> 2218 | D430: =SUM('Weekly Data'!F427:F430)/4 -> 524.75 | E430: =SUM('Weekly Data'!G427:G430)/4 -> 2851.25 | F430: =SUM('Weekly Data'!H427:H430)/4 -> 749.5 | R430: 37300
A431: =A430+7 -> 37307 | C431: =SUM('Weekly Data'!E428:E431)/4 -> 2365.5 | D431: =SUM('Weekly Data'!F428:F431)/4 -> 470.5 | E431: =SUM('Weekly Data'!G428:G431)/4 -> 3143 | F431: =SUM('Weekly Data'!H428:H431)/4 -> 659 | R431: 37307
A432: =A431+7 -> 37314 | C432: =SUM('Weekly Data'!E429:E432)/4 -> 2134.75 | D432: =SUM('Weekly Data'!F429:F432)/4 -> 470 | E432: =SUM('Weekly Data'!G429:G432)/4 -> 3203.75 | F432: =SUM('Weekly Data'!H429:H432)/4 -> 659.5 | R432: 37314
A433: =A432+7 -> 37321 | C433: =SUM('Weekly Data'!E430:E433)/4 -> 2343.25 | D433: =SUM('Weekly Data'!F430:F433)/4 -> 637 | E433: =SUM('Weekly Data'!G430:G433)/4 -> 2974.5 | F433: =SUM('Weekly Data'!H430:H433)/4 -> 588.75 | R433: 37321
A434: =A433+7 -> 37328 | C434: =SUM('Weekly Data'!E431:E434)/4 -> 2025.75 | D434: =SUM('Weekly Data'!F431:F434)/4 -> 930 | E434: =SUM('Weekly Data'!G431:G434)/4 -> 2361.5 | F434: =SUM('Weekly Data'!H431:H434)/4 -> 551.75 | R434: 37328
A435: =A434+7 -> 37335 | C435: =SUM('Weekly Data'!E432:E435)/4 -> 1913.75 | D435: =SUM('Weekly Data'!F432:F435)/4 -> 1219.25 | E435: =SUM('Weekly Data'!G432:G435)/4 -> 2221 | F435: =SUM('Weekly Data'!H432:H435)/4 -> 470.75 | R435: 37335
A436: =A435+7 -> 37342 | C436: =SUM('Weekly Data'!E433:E436)/4 -> 1953.25 | D436: =SUM('Weekly Data'!F433:F436)/4 -> 1353.5 | E436: =SUM('Weekly Data'!G433:G436)/4 -> 2098.25 | F436: =SUM('Weekly Data'!H433:H436)/4 -> 311 | R436: 37342
A437: =A436+7 -> 37349 | C437: =SUM('Weekly Data'!E434:E437)/4 -> 1854.75 | D437: =SUM('Weekly Data'!F434:F437)/4 -> 1291.5 | E437: =SUM('Weekly Data'!G434:G437)/4 -> 1878.75 | F437: =SUM('Weekly Data'!H434:H437)/4 -> 375.5 | R437: 37349
A438: =A437+7 -> 37356 | C438: =SUM('Weekly Data'!E435:E438)/4 -> 2047.5 | D438: =SUM('Weekly Data'!F435:F438)/4 -> 1195.5 | E438: =SUM('Weekly Data'!G435:G438)/4 -> 1694.5 | F438: =SUM('Weekly Data'!H435:H438)/4 -> 357 | R438: 37356
... A531: =A530+7 -> 38007 | C531: =SUM('Weekly Data'!E528:E531)/4 -> 2839 | D531: =SUM('Weekly Data'!F528:F531)/4 -> 914.5 | E531: =SUM('Weekly Data'!G528:G531)/4 -> 3137.25 | F531: =SUM('Weekly Data'!H528:H531)/4 -> 323.5 | R531: 38007
A532: =A531+7 -> 38014 | B532: =SUM('Weekly Data'!D529:D532)/4 -> 1294.5 | C532: =SUM('Weekly Data'!E529:E532)/4 -> 2871.75 | D532: =SUM('Weekly Data'!F529:F532)/4 -> 870.75 | E532: =SUM('Weekly Data'!G529:G532)/4 -> 3554.25 | F532: =SUM('Weekly Data'!H529:H532)/4 -> 336.75 | G532: =SUM('Weekly Data'!I529:I532)/4 -> 8057.25 | R532: 38014
A533: =A532+7 -> 38021 | B533: =SUM('Weekly Data'!D530:D533)/4 -> 1225.75 | C533: =SUM('Weekly Data'!E530:E533)/4 -> 2961 | D533: =SUM('Weekly Data'!F530:F533)/4 -> 868 | E533: =SUM('Weekly Data'!G530:G533)/4 -> 3764.75 | F533: =SUM('Weekly Data'!H530:H533)/4 -> 333.25 | G533: =SUM('Weekly Data'!I530:I533)/4 -> 8284.75 | R533: 38021
A534: =A533+7 -> 38028 | B534: =SUM('Weekly Data'!D531:D534)/4 -> 1153.75 | C534: =SUM('Weekly Data'!E531:E534)/4 -> 2576.5 | D534: =SUM('Weekly Data'!F531:F534)/4 -> 794.75 | E534: =SUM('Weekly Data'!G531:G534)/4 -> 4020.5 | F534: =SUM('Weekly Data'!H531:H534)/4 -> 383.5 | G534: =SUM('Weekly Data'!I531:I534)/4 -> 8134.25 | R534: 38028
A535: =A534+7 -> 38035 | B535: =SUM('Weekly Data'!D532:D535)/4 -> 1015.75 | C535: =SUM('Weekly Data'!E532:E535)/4 -> 2374.25 | D535: =SUM('Weekly Data'!F532:F535)/4 -> 837.5 | E535: =SUM('Weekly Data'!G532:G535)/4 -> 4438 | F535: =SUM('Weekly Data'!H532:H535)/4 -> 346.5 | G535: =SUM('Weekly Data'!I532:I535)/4 -> 8174.5 | R535: 38035
A536: =A535+7 -> 38042 | B536: =SUM('Weekly Data'!D533:D536)/4 -> 1022.25 | C536: =SUM('Weekly Data'!E533:E536)/4 -> 2391.25 | D536: =SUM('Weekly Data'!F533:F536)/4 -> 825.5 | E536: =SUM('Weekly Data'!G533:G536)/4 -> 4638 | F536: =SUM('Weekly Data'!H533:H536)/4 -> 328 | G536: =SUM('Weekly Data'!I533:I536)/4 -> 8379.5 | R536: 38042
...

Sheet Weekly Changes
D2: Rail to port--Week to Week Changes | M2: Rail to port--Changes in 4-week averages
D3: MS | E3: TX | F3: Cross-Border-2 | G3: Cross-Border | H3: PNW | I3: East coast | J3: Total | M3: MS | N3: TX | O3: Cross-Border-2 | P3: Cross | Q3: PNW | R3: East coast | S3: Total
A4: % chg from prior week | D4: =('Weekly Data'!D1017/'Weekly Data'!D1016)*100 -> 4066.6667 | E4: =('Weekly Data'!E1017/'Weekly Data'!E1016)*100 -> 59.580664 | F4: =('Weekly Data'!J1017/'Weekly Data'!J1016)*100 -> 99.241786 | G4: n/a | H4: =('Weekly Data'!G1017/'Weekly Data'!G1016)*100 -> 82.640145 | I4: =('Weekly Data'!H1017/'Weekly Data'!H1016)*100 -> 216.36364 | J4: =('Weekly Data'!I1017/'Weekly Data'!I1016)*100 -> 78.235695 | L4: % chg from prior week | M4: =('Weekly Averages'!B1017/'Weekly Averages'!B1016)*100 -> 176.10063 | N4: =('Weekly Averages'!C1017/'Weekly Averages'!C1016)*100 -> 89.681051 | O4: =('Weekly Averages'!H1017/'Weekly Averages'!H1016)*100 -> 98.492363 | P4: n/a | Q4: =('Weekly Averages'!E1017/'Weekly Averages'!E1016)*100 -> 92.126681 | R4: =('Weekly Averages'!F1017/'Weekly Averages'!F1016)*100 -> 135.7265 | S4: =('Weekly Averages'!G1017/'Weekly Averages'!G1016)*100 -> 93.941526
A5: % chg from prior year | D5: =('Weekly Data'!D1017/'Weekly Data'!D965)*100 -> #DIV/0! | E5: =('Weekly Data'!E1017/'Weekly Data'!E965)*100 -> 250.12225 | F5: =('Weekly Data'!J1017/'Weekly Data'!J965)*100 -> 47.657577 | G5: n/a | H5: =('Weekly Data'!G1017/'Weekly Data'!G965)*100 -> 26.249282 | I5: =('Weekly Data'!H1017/'Weekly Data'!H965)*100 -> 70.414201 | J5: =('Weekly Data'!I1017/'Weekly Data'!I965)*100 -> 54.315441 | L5: % chg from prior year | M5: =('Weekly Averages'!B1017/'Weekly Averages'!B965)*100 -> 288.65979 | N5: =('Weekly Averages'!C1017/'Weekly Averages'!C965)*100 -> 344.09118 | O5: =('Weekly Averages'!H1017/'Weekly Averages'!H965)*100 -> 51.287878 | P5: n/a | Q5: =('Weekly Averages'!E1017/'Weekly Averages'!E965)*100 -> 36.311018 | R5: =('Weekly Averages'!F1017/'Weekly Averages'!F965)*100 -> 58.511422 | S5: =('Weekly Averages'!G1017/'Weekly Averages'!G965)*100 -> 68.821946
A6: % chg from 4-yr avg. | D6: =('Weekly Data'!D1017/'Weekly Averages'!J1017)*100 -> 55.016911 | E6: =('Weekly Data'!E1017/'Weekly Averages'!K1017)*100 -> 114.62185 | F6: =('Weekly Data'!J1017/'Weekly Averages'!P1017)*100 -> 62.929151 | G6: n/a | H6: =('Weekly Data'!G1017/'Weekly Averages'!M1017)*100 -> 28.587067 | I6: =('Weekly Data'!H1017/'Weekly Averages'!N1017)*100 -> 85.304659 | J6: =('Weekly Data'!I1017/'Weekly Averages'!O1017)*100 -> 50.038122 | L6: % chg from 4-yr avg. | M6: =('Weekly Averages'!B1017/'Weekly Averages'!S1017)*100 -> 32.351242 | N6: =('Weekly Averages'!C1017/'Weekly Averages'!T1017)*100 -> 132.37941 | O6: =('Weekly Averages'!H1017/'Weekly Averages'!Y1017)*100 -> 61.827248 | P6: n/a | Q6: =('Weekly Averages'!E1017/'Weekly Averages'!V1017)*100 -> 38.002445 | R6: =('Weekly Averages'!F1017/'Weekly Averages'!W1017)*100 -> 55.876144 | S6: =('Weekly Averages'!G1017/'Weekly Averages'!X1017)*100 -> 59.135142
D7: 4-yr avg | J7: 4-yr avg | M7: 4-yr avg | S7: 4-yr avg
A10: 1st Quarter 2013 | D10: =SUM('Weekly Data'!D998:D1010) -> 7582 | E10: =SUM('Weekly Data'!E998:E1010) -> 11498 | F10: =SUM('Weekly Data'!J998:J1010) -> 14431 | G10: n/a | H10: =SUM('Weekly Data'!G998:G1010) -> 53722 | I10: =SUM('Weekly Data'!H998:H1010) -> 7865 | J10: =SUM('Weekly Data'!I998:I1010) -> 80667
A11: 1st Quarter 2012 | D11: =SUM('Weekly Data'!D946:D958) -> 3182 | E11: =SUM('Weekly Data'!E946:E958) -> 9240 | F11: =SUM('Weekly Data'!J946:J958) -> 26702.94 | G11: n/a | H11: =SUM('Weekly Data'!G946:G958) -> 59953 | I11: =SUM('Weekly Data'!H946:H958) -> 6648 | J11: =SUM('Weekly Data'!I946:I958) -> 79023
A12: Change | D12: =(D10/D11)-1 -> 1.3827781 | E12: =(E10/E11)-1 -> 0.24437229 | F12: =(F10/F11)-1 -> -0.45957262 | G12: n/a | H12: =(H10/H11)-1 -> -0.10393141 | I12: =(I10/I11)-1 -> 0.18306258 | J12: =(J10/J11)-1 -> 0.02080407

Sheet New Table 3
A1: Table 3
A2: Rail Deliveries to Port (carloads)1
B3: Mississippi | D3: Pacific | E3: Atlantic & | H3: Cross-Border
A4: Week ending | B4: Gulf | C4: Texas Gulf | D4: Northwest | E4: East Gulf | F4: Total | G4: Week ending | H4: Mexico3
A6: 05/15/2013p | B6: ='Weekly Data'!D1017 -> 122 | C6: ='Weekly Data'!E1017 -> 1023 | D6: ='Weekly Data'!G1017 -> 914 | E6: ='Weekly Data'!H1017 -> 238 | F6: ='Weekly Data'!I1017 -> 2297 | G6: 41405 | H6: ='Weekly Data'!J1017 -> 1178
A7: 05/08/2013r | B7: ='Weekly Data'!D1016 -> 3 | C7: ='Weekly Data'!E1016 -> 1717 | D7: ='Weekly Data'!G1016 -> 1106 | E7: ='Weekly Data'!H1016 -> 110 | F7: ='Weekly Data'!I1016 -> 2936 | G7: 41398 | H7: ='Weekly Data'!J1016 -> 1187
A8: 2013 YTDr | B8: =SUM('Weekly Data'!D998:D1049) -> 8170 | C8: =SUM('Weekly Data'!E998:E1049) -> 21857 | D8: =SUM('Weekly Data'!G998:G1049) -> 64769 | E8: =SUM('Weekly Data'!H998:H1049) -> 8926 | F8: =SUM('Weekly Data'!I998:I1049) -> 103722 | G8: 2013 YTD | H8: =SUM('Weekly Data'!J998:J1049) -> 23385
A9: 2012 YTDr | B9: =SUM('Weekly Data'!D946:D965) -> 3585 | C9: =SUM('Weekly Data'!E946:E965) -> 12893 | D9: =SUM('Weekly Data'!G946:G965) -> 86463 | E9: =SUM('Weekly Data'!H946:H965) -> 9128 | F9: =SUM('Weekly Data'!I946:I965) -> 112069 | G9: 2012 YTD | H9: =SUM('Weekly Data'!J946:J965) -> 44331.94
A10: 2013 YTD as % of 2012 YTD | B10: =B8/B9*100 -> 227.894 | C10: =C8/C9*100 -> 169.5261 | D10: =D8/D9*100 -> 74.909499 | E10: =E8/E9*100 -> 97.787029 | F10: =F8/F9*100 -> 92.55191 | G10: % change YTD | H10: =H8/H9*100 -> 52.749778
A11: Last 4 weeks as % of 20122 | B11: ='Weekly Changes'!M5 -> 288.65979 | C11: ='Weekly Changes'!N5 -> 344.09118 | D11: ='Weekly Changes'!Q5 -> 36.311018 | E11: ='Weekly Changes'!R5 -> 58.511422 | F11: ='Weekly Changes'!S5 -> 68.821946 | G11: Last 4wks % 2012 | H11: ='Weekly Changes'!O5 -> 51.287878
A12: Last 4 weeks as % of 4-year avg.2 | B12: ='Weekly Changes'!M6 -> 32.351242 | C12: ='Weekly Changes'!N6 -> 132.37941 | D12: ='Weekly Changes'!Q6 -> 38.002445 | E12: ='Weekly Changes'!R6 -> 55.876144 | F12: ='Weekly Changes'!S6 -> 59.135142 | G12: Last 4wks % 4 yr | H12: ='Weekly Changes'!O6 -> 61.827248
A13: Total 2012 | B13: =SUM('Weekly Data'!D946:D997) -> 22604 | C13: =SUM('Weekly Data'!E946:E997) -> 40780 | D13: =SUM('Weekly Data'!G946:G997) -> 199419 | E13: =SUM('Weekly Data'!H946:H9997) -> 33585 | F13: =SUM('Weekly Data'!I946:I997) -> 287462 | G13: Total 2011 | H13: 97118
A14: Total 2011 | B14: =SUM('Weekly Data'!D894:D945) -> 27358 | C14: =SUM('Weekly Data'!E894:E945) -> 77515 | D14: =SUM('Weekly Data'!G894:G945) -> 191187 | E14: =SUM('Weekly Data'!H894:H945) -> 24088 | F14: =SUM('Weekly Data'!I894:I945) -> 320148 | G14: Total 2010 | H14: 90175
A15: 1 Data is incomplete as it is voluntarily provided
A16: 2 Compared with same 4-weeks in 2011 and prior 4-year average.
A17: 3 Cross- border weekly data is aproximately 15 percent below the Association of American Railroads reported weekly carloads received by Mexican railroads
A18: to reflect switching between KCSM and FerroMex.
A19: YTD = year-to-date; p = preliminary data; r = revised data; YTD PNW carloads includes revisions back to August 2011 ; n/a = not available
A20: Source: Transportation & Marketing Programs/AMS/USDA

Sheet Port Region Graphs-4 week avg.
