Workbook

Sheet Common
A1: Industrial Stormwater Discharge Monitoring Report - 1200-COLS Permit
A2: Permittee Legal Name: | F2: ODEQ File No./Facility ID:
A4: Facility Common Name: | F4: Reporting Period: | H4: July 1, | J4: to | K4: June 30,
A6: Facility Location: | F6: Laboratory Name:
A8: County: | F8: Laboratory ORELAP #: | J8: SIC Code(s):
A10: Monitor for the following pollutants at sampling point(s) specified in your SWPCP and use the sampling point name or number from your SWPCP. Add more sheets if necessary (e.g., if more than 4 samples are collected per pollutant or facility has more than 4 sampling points). You MUST also attach a copy of laboratory results sheet(s).
A12: Benchmark Sampling: 4 times per year, every year
A13: Name or # of Sampling Point(s) (group data per sampling point) | B13: Sample Date | C13: pH | D13: Suspended Solids, Total | E13: Oil and Grease, Total | F13: Copper, Total | G13: Lead, Total | H13: Zinc, Total | I13: E. coli | J13: Phosphorus, Total | K13: BOD5
C14: s.u. | D14: mg/L | E14: mg/L | F14: mg/L | G14: mg/L | H14: mg/L | I14: counts/100 mL | J14: mg/L | K14: mg/L
T16: =IF(ISBLANK(C16),"",IF(ISNUMBER(C16),C16,IF(LEFT(C16,2)="NS","",IF(LEFT(C16,2)="No","",C16)))) | U16: =IF(ISBLANK(D16),"",IF(ISNUMBER(D16),D16,IF(LEFT(D16,2)="NS",D$39,IF(LEFT(D16,3)="ND(",VALUE(MID(D16,4,LEN(D16)-4))/2,IF(LEFT(D16,3)="ND ",VALUE(MID(D16,5,LEN(D16)-5)/2),D16))))) | V16: =IF(ISBLANK(E16),"",IF(ISNUMBER(E16),E16,IF(LEFT(E16,2)="NS",E$39,IF(LEFT(E16,3)="ND(",VALUE(MID(E16,4,LEN(E16)-4))/2,IF(LEFT(E16,3)="ND ",VALUE(MID(E16,5,LEN(E16)-5)/2),E16))))) | W16: =IF(ISBLANK(F16),"",IF(ISNUMBER(F16),F16,IF(LEFT(F16,2)="NS",F$39,IF(LEFT(F16,3)="ND(",VALUE(MID(F16,4,LEN(F16)-4))/2,IF(LEFT(F16,3)="ND ",VALUE(MID(F16,5,LEN(F16)-5)/2),F16))))) | X16: =IF(ISBLANK(G16),"",IF(ISNUMBER(G16),G16,IF(LEFT(G16,2)="NS",G$39,IF(LEFT(G16,3)="ND(",VALUE(MID(G16,4,LEN(G16)-4))/2,IF(LEFT(G16,3)="ND ",VALUE(MID(G16,5,LEN(G16)-5)/2),G16))))) | Y16: =IF(ISBLANK(H16),"",IF(ISNUMBER(H16),H16,IF(LEFT(H16,2)="NS",H$39,IF(LEFT(H16,3)="ND(",VALUE(MID(H16,4,LEN(H16)-4))/2,IF(LEFT(H16,3)="ND ",VALUE(MID(H16,5,LEN(H16)-5)/2),H16))))) | Z16: =IF(ISBLANK(I16),"",IF(ISNUMBER(I16),I16,IF(LEFT(I16,2)="NS",I$39,IF(LEFT(I16,1)="<",VALUE(MID(I16,2,LEN(I16)-1)),IF(LEFT(I16,1)=">",VALUE(MID(I16,2,LEN(I16)-1)),I16))))) | AA16: =IF(ISBLANK(J16),"",IF(ISNUMBER(J16),J16,IF(LEFT(J16,2)="NS",J$39,IF(LEFT(J16,3)="ND(",VALUE(MID(J16,4,LEN(J16)-4))/2,IF(LEFT(J16,3)="ND ",VALUE(MID(J16,5,LEN(J16)-5)/2),J16))))) | AB16: =IF(ISBLANK(K16),"",IF(ISNUMBER(K16),K16,IF(LEFT(K16,2)="NS",K$39,IF(LEFT(K16,3)="ND(",VALUE(MID(K16,4,LEN(K16)-4))/2,IF(LEFT(K16,3)="ND ",VALUE(MID(K16,5,LEN(K16)-5)/2),K16)))))
T17: =IF(ISBLANK(C17),"",IF(ISNUMBER(C17),C17,IF(LEFT(C17,2)="NS","",IF(LEFT(C17,2)="No","",C17)))) | U17: =IF(ISBLANK(D17),"",IF(ISNUMBER(D17),D17,IF(LEFT(D17,2)="NS",D$39,IF(LEFT(D17,3)="ND(",VALUE(MID(D17,4,LEN(D17)-4))/2,IF(LEFT(D17,3)="ND ",VALUE(MID(D17,5,LEN(D17)-5)/2),D17))))) | V17: =IF(ISBLANK(E17),"",IF(ISNUMBER(E17),E17,IF(LEFT(E17,2)="NS",E$39,IF(LEFT(E17,3)="ND(",VALUE(MID(E17,4,LEN(E17)-4))/2,IF(LEFT(E17,3)="ND ",VALUE(MID(E17,5,LEN(E17)-5)/2),E17))))) | W17: =IF(ISBLANK(F17),"",IF(ISNUMBER(F17),F17,IF(LEFT(F17,2)="NS",F$39,IF(LEFT(F17,3)="ND(",VALUE(MID(F17,4,LEN(F17)-4))/2,IF(LEFT(F17,3)="ND ",VALUE(MID(F17,5,LEN(F17)-5)/2),F17))))) | X17: =IF(ISBLANK(G17),"",IF(ISNUMBER(G17),G17,IF(LEFT(G17,2)="NS",G$39,IF(LEFT(G17,3)="ND(",VALUE(MID(G17,4,LEN(G17)-4))/2,IF(LEFT(G17,3)="ND ",VALUE(MID(G17,5,LEN(G17)-5)/2),G17))))) | Y17: =IF(ISBLANK(H17),"",IF(ISNUMBER(H17),H17,IF(LEFT(H17,2)="NS",H$39,IF(LEFT(H17,3)="ND(",VALUE(MID(H17,4,LEN(H17)-4))/2,IF(LEFT(H17,3)="ND ",VALUE(MID(H17,5,LEN(H17)-5)/2),H17))))) | Z17: =IF(ISBLANK(I17),"",IF(ISNUMBER(I17),I17,IF(LEFT(I17,2)="NS",I$39,IF(LEFT(I17,1)="<",VALUE(MID(I17,2,LEN(I17)-1)),IF(LEFT(I17,1)=">",VALUE(MID(I17,2,LEN(I17)-1)),I17))))) | AA17: =IF(ISBLANK(J17),"",IF(ISNUMBER(J17),J17,IF(LEFT(J17,2)="NS",J$39,IF(LEFT(J17,3)="ND(",VALUE(MID(J17,4,LEN(J17)-4))/2,IF(LEFT(J17,3)="ND ",VALUE(MID(J17,5,LEN(J17)-5)/2),J17))))) | AB17: =IF(ISBLANK(K17),"",IF(ISNUMBER(K17),K17,IF(LEFT(K17,2)="NS",K$39,IF(LEFT(K17,3)="ND(",VALUE(MID(K17,4,LEN(K17)-4))/2,IF(LEFT(K17,3)="ND ",VALUE(MID(K17,5,LEN(K17)-5)/2),K17)))))
T18: =IF(ISBLANK(C18),"",IF(ISNUMBER(C18),C18,IF(LEFT(C18,2)="NS","",IF(LEFT(C18,2)="No","",C18)))) | U18: =IF(ISBLANK(D18),"",IF(ISNUMBER(D18),D18,IF(LEFT(D18,2)="NS",D$39,IF(LEFT(D18,3)="ND(",VALUE(MID(D18,4,LEN(D18)-4))/2,IF(LEFT(D18,3)="ND ",VALUE(MID(D18,5,LEN(D18)-5)/2),D18))))) | V18: =IF(ISBLANK(E18),"",IF(ISNUMBER(E18),E18,IF(LEFT(E18,2)="NS",E$39,IF(LEFT(E18,3)="ND(",VALUE(MID(E18,4,LEN(E18)-4))/2,IF(LEFT(E18,3)="ND ",VALUE(MID(E18,5,LEN(E18)-5)/2),E18))))) | W18: =IF(ISBLANK(F18),"",IF(ISNUMBER(F18),F18,IF(LEFT(F18,2)="NS",F$39,IF(LEFT(F18,3)="ND(",VALUE(MID(F18,4,LEN(F18)-4))/2,IF(LEFT(F18,3)="ND ",VALUE(MID(F18,5,LEN(F18)-5)/2),F18))))) | X18: =IF(ISBLANK(G18),"",IF(ISNUMBER(G18),G18,IF(LEFT(G18,2)="NS",G$39,IF(LEFT(G18,3)="ND(",VALUE(MID(G18,4,LEN(G18)-4))/2,IF(LEFT(G18,3)="ND ",VALUE(MID(G18,5,LEN(G18)-5)/2),G18))))) | Y18: =IF(ISBLANK(H18),"",IF(ISNUMBER(H18),H18,IF(LEFT(H18,2)="NS",H$39,IF(LEFT(H18,3)="ND(",VALUE(MID(H18,4,LEN(H18)-4))/2,IF(LEFT(H18,3)="ND ",VALUE(MID(H18,5,LEN(H18)-5)/2),H18))))) | Z18: =IF(ISBLANK(I18),"",IF(ISNUMBER(I18),I18,IF(LEFT(I18,2)="NS",I$39,IF(LEFT(I18,1)="<",VALUE(MID(I18,2,LEN(I18)-1)),IF(LEFT(I18,1)=">",VALUE(MID(I18,2,LEN(I18)-1)),I18))))) | AA18: =IF(ISBLANK(J18),"",IF(ISNUMBER(J18),J18,IF(LEFT(J18,2)="NS",J$39,IF(LEFT(J18,3)="ND(",VALUE(MID(J18,4,LEN(J18)-4))/2,IF(LEFT(J18,3)="ND ",VALUE(MID(J18,5,LEN(J18)-5)/2),J18))))) | AB18: =IF(ISBLANK(K18),"",IF(ISNUMBER(K18),K18,IF(LEFT(K18,2)="NS",K$39,IF(LEFT(K18,3)="ND(",VALUE(MID(K18,4,LEN(K18)-4))/2,IF(LEFT(K18,3)="ND ",VALUE(MID(K18,5,LEN(K18)-5)/2),K18)))))
T19: =IF(ISBLANK(C19),"",IF(ISNUMBER(C19),C19,IF(LEFT(C19,2)="NS","",IF(LEFT(C19,2)="No","",C19)))) | U19: =IF(ISBLANK(D19),"",IF(ISNUMBER(D19),D19,IF(LEFT(D19,2)="NS",D$39,IF(LEFT(D19,3)="ND(",VALUE(MID(D19,4,LEN(D19)-4))/2,IF(LEFT(D19,3)="ND ",VALUE(MID(D19,5,LEN(D19)-5)/2),D19))))) | V19: =IF(ISBLANK(E19),"",IF(ISNUMBER(E19),E19,IF(LEFT(E19,2)="NS",E$39,IF(LEFT(E19,3)="ND(",VALUE(MID(E19,4,LEN(E19)-4))/2,IF(LEFT(E19,3)="ND ",VALUE(MID(E19,5,LEN(E19)-5)/2),E19))))) | W19: =IF(ISBLANK(F19),"",IF(ISNUMBER(F19),F19,IF(LEFT(F19,2)="NS",F$39,IF(LEFT(F19,3)="ND(",VALUE(MID(F19,4,LEN(F19)-4))/2,IF(LEFT(F19,3)="ND ",VALUE(MID(F19,5,LEN(F19)-5)/2),F19))))) | X19: =IF(ISBLANK(G19),"",IF(ISNUMBER(G19),G19,IF(LEFT(G19,2)="NS",G$39,IF(LEFT(G19,3)="ND(",VALUE(MID(G19,4,LEN(G19)-4))/2,IF(LEFT(G19,3)="ND ",VALUE(MID(G19,5,LEN(G19)-5)/2),G19))))) | Y19: =IF(ISBLANK(H19),"",IF(ISNUMBER(H19),H19,IF(LEFT(H19,2)="NS",H$39,IF(LEFT(H19,3)="ND(",VALUE(MID(H19,4,LEN(H19)-4))/2,IF(LEFT(H19,3)="ND ",VALUE(MID(H19,5,LEN(H19)-5)/2),H19))))) | Z19: =IF(ISBLANK(I19),"",IF(ISNUMBER(I19),I19,IF(LEFT(I19,2)="NS",I$39,IF(LEFT(I19,1)="<",VALUE(MID(I19,2,LEN(I19)-1)),IF(LEFT(I19,1)=">",VALUE(MID(I19,2,LEN(I19)-1)),I19))))) | AA19: =IF(ISBLANK(J19),"",IF(ISNUMBER(J19),J19,IF(LEFT(J19,2)="NS",J$39,IF(LEFT(J19,3)="ND(",VALUE(MID(J19,4,LEN(J19)-4))/2,IF(LEFT(J19,3)="ND ",VALUE(MID(J19,5,LEN(J19)-5)/2),J19))))) | AB19: =IF(ISBLANK(K19),"",IF(ISNUMBER(K19),K19,IF(LEFT(K19,2)="NS",K$39,IF(LEFT(K19,3)="ND(",VALUE(MID(K19,4,LEN(K19)-4))/2,IF(LEFT(K19,3)="ND ",VALUE(MID(K19,5,LEN(K19)-5)/2),K19)))))
A20: Geometric Mean (Note 3) | D20: =IF(ISBLANK(D19),"",IF(ISNUMBER(D19),GEOMEAN(U16:U19),IF(LEFT(D19,2)="NS",GEOMEAN(U16:U19),IF(LEFT(D19,2)="ND",GEOMEAN(U16:U19),"M")))) | E20: =IF(ISBLANK(E19),"",IF(ISNUMBER(E19),GEOMEAN(V16:V19),IF(LEFT(E19,2)="NS",GEOMEAN(V16:V19),IF(LEFT(E19,2)="ND",GEOMEAN(V16:V19),"M")))) | F20: =IF(ISBLANK(F19),"",IF(ISNUMBER(F19),GEOMEAN(W16:W19),IF(LEFT(F19,2)="NS",GEOMEAN(W16:W19),IF(LEFT(F19,2)="ND",GEOMEAN(W16:W19),"M")))) | G20: =IF(ISBLANK(G19),"",IF(ISNUMBER(G19),GEOMEAN(X16:X19),IF(LEFT(G19,2)="NS",GEOMEAN(X16:X19),IF(LEFT(G19,2)="ND",GEOMEAN(X16:X19),"M")))) | H20: =IF(ISBLANK(H19),"",IF(ISNUMBER(H19),GEOMEAN(Y16:Y19),IF(LEFT(H19,2)="NS",GEOMEAN(Y16:Y19),IF(LEFT(H19,2)="ND",GEOMEAN(Y16:Y19),"M")))) | I20: =IF(ISBLANK(I19),"",IF(ISNUMBER(I19),GEOMEAN(Z16:Z19),IF(LEFT(I19,2)="NS",GEOMEAN(Z16:Z19),IF(LEFT(I19,2)="ND",GEOMEAN(Z16:Z19),IF(LEFT(I19,1)="<",GEOMEAN(C16:Z19),IF(LEFT(I19,1)=">",GEOMEAN(Z16:Z19),"M")))))) | J20: =IF(ISBLANK(J19),"",IF(ISNUMBER(J19),GEOMEAN(AA16:AA19),IF(LEFT(J19,2)="NS",GEOMEAN(AA16:AA19),IF(LEFT(J19,2)="ND",GEOMEAN(AA16:AA19),"M")))) | K20: =IF(ISBLANK(K19),"",IF(ISNUMBER(K19),GEOMEAN(AB16:AB19),IF(LEFT(K19,2)="NS",GEOMEAN(AB16:AB19),IF(LEFT(K19,2)="ND",GEOMEAN(AB16:AB19),"M"))))
T21: =IF(ISBLANK(C21),"",IF(ISNUMBER(C21),C21,IF(LEFT(C21,2)="NS","",IF(LEFT(C21,2)="No","",C21)))) | U21: =IF(ISBLANK(D21),"",IF(ISNUMBER(D21),D21,IF(LEFT(D21,2)="NS",D$39,IF(LEFT(D21,3)="ND(",VALUE(MID(D21,4,LEN(D21)-4))/2,IF(LEFT(D21,3)="ND ",VALUE(MID(D21,5,LEN(D21)-5)/2),D21))))) | V21: =IF(ISBLANK(E21),"",IF(ISNUMBER(E21),E21,IF(LEFT(E21,2)="NS",E$39,IF(LEFT(E21,3)="ND(",VALUE(MID(E21,4,LEN(E21)-4))/2,IF(LEFT(E21,3)="ND ",VALUE(MID(E21,5,LEN(E21)-5)/2),E21))))) | W21: =IF(ISBLANK(F21),"",IF(ISNUMBER(F21),F21,IF(LEFT(F21,2)="NS",F$39,IF(LEFT(F21,3)="ND(",VALUE(MID(F21,4,LEN(F21)-4))/2,IF(LEFT(F21,3)="ND ",VALUE(MID(F21,5,LEN(F21)-5)/2),F21))))) | X21: =IF(ISBLANK(G21),"",IF(ISNUMBER(G21),G21,IF(LEFT(G21,2)="NS",G$39,IF(LEFT(G21,3)="ND(",VALUE(MID(G21,4,LEN(G21)-4))/2,IF(LEFT(G21,3)="ND ",VALUE(MID(G21,5,LEN(G21)-5)/2),G21))))) | Y21: =IF(ISBLANK(H21),"",IF(ISNUMBER(H21),H21,IF(LEFT(H21,2)="NS",H$39,IF(LEFT(H21,3)="ND(",VALUE(MID(H21,4,LEN(H21)-4))/2,IF(LEFT(H21,3)="ND ",VALUE(MID(H21,5,LEN(H21)-5)/2),H21))))) | Z21: =IF(ISBLANK(I21),"",IF(ISNUMBER(I21),I21,IF(LEFT(I21,2)="NS",I$39,IF(LEFT(I21,1)="<",VALUE(MID(I21,2,LEN(I21)-1)),IF(LEFT(I21,1)=">",VALUE(MID(I21,2,LEN(I21)-1)),I21))))) | AA21: =IF(ISBLANK(J21),"",IF(ISNUMBER(J21),J21,IF(LEFT(J21,2)="NS",J$39,IF(LEFT(J21,3)="ND(",VALUE(MID(J21,4,LEN(J21)-4))/2,IF(LEFT(J21,3)="ND ",VALUE(MID(J21,5,LEN(J21)-5)/2),J21))))) | AB21: =IF(ISBLANK(K21),"",IF(ISNUMBER(K21),K21,IF(LEFT(K21,2)="NS",K$39,IF(LEFT(K21,3)="ND(",VALUE(MID(K21,4,LEN(K21)-4))/2,IF(LEFT(K21,3)="ND ",VALUE(MID(K21,5,LEN(K21)-5)/2),K21)))))
T22: =IF(ISBLANK(C22),"",IF(ISNUMBER(C22),C22,IF(LEFT(C22,2)="NS","",IF(LEFT(C22,2)="No","",C22)))) | U22: =IF(ISBLANK(D22),"",IF(ISNUMBER(D22),D22,IF(LEFT(D22,2)="NS",D$39,IF(LEFT(D22,3)="ND(",VALUE(MID(D22,4,LEN(D22)-4))/2,IF(LEFT(D22,3)="ND ",VALUE(MID(D22,5,LEN(D22)-5)/2),D22))))) | V22: =IF(ISBLANK(E22),"",IF(ISNUMBER(E22),E22,IF(LEFT(E22,2)="NS",E$39,IF(LEFT(E22,3)="ND(",VALUE(MID(E22,4,LEN(E22)-4))/2,IF(LEFT(E22,3)="ND ",VALUE(MID(E22,5,LEN(E22)-5)/2),E22))))) | W22: =IF(ISBLANK(F22),"",IF(ISNUMBER(F22),F22,IF(LEFT(F22,2)="NS",F$39,IF(LEFT(F22,3)="ND(",VALUE(MID(F22,4,LEN(F22)-4))/2,IF(LEFT(F22,3)="ND ",VALUE(MID(F22,5,LEN(F22)-5)/2),F22))))) | X22: =IF(ISBLANK(G22),"",IF(ISNUMBER(G22),G22,IF(LEFT(G22,2)="NS",G$39,IF(LEFT(G22,3)="ND(",VALUE(MID(G22,4,LEN(G22)-4))/2,IF(LEFT(G22,3)="ND ",VALUE(MID(G22,5,LEN(G22)-5)/2),G22))))) | Y22: =IF(ISBLANK(H22),"",IF(ISNUMBER(H22),H22,IF(LEFT(H22,2)="NS",H$39,IF(LEFT(H22,3)="ND(",VALUE(MID(H22,4,LEN(H22)-4))/2,IF(LEFT(H22,3)="ND ",VALUE(MID(H22,5,LEN(H22)-5)/2),H22))))) | Z22: =IF(ISBLANK(I22),"",IF(ISNUMBER(I22),I22,IF(LEFT(I22,2)="NS",I$39,IF(LEFT(I22,1)="<",VALUE(MID(I22,2,LEN(I22)-1)),IF(LEFT(I22,1)=">",VALUE(MID(I22,2,LEN(I22)-1)),I22))))) | AA22: =IF(ISBLANK(J22),"",IF(ISNUMBER(J22),J22,IF(LEFT(J22,2)="NS",J$39,IF(LEFT(J22,3)="ND(",VALUE(MID(J22,4,LEN(J22)-4))/2,IF(LEFT(J22,3)="ND ",VALUE(MID(J22,5,LEN(J22)-5)/2),J22))))) | AB22: =IF(ISBLANK(K22),"",IF(ISNUMBER(K22),K22,IF(LEFT(K22,2)="NS",K$39,IF(LEFT(K22,3)="ND(",VALUE(MID(K22,4,LEN(K22)-4))/2,IF(LEFT(K22,3)="ND ",VALUE(MID(K22,5,LEN(K22)-5)/2),K22)))))
T23: =IF(ISBLANK(C23),"",IF(ISNUMBER(C23),C23,IF(LEFT(C23,2)="NS","",IF(LEFT(C23,2)="No","",C23)))) | U23: =IF(ISBLANK(D23),"",IF(ISNUMBER(D23),D23,IF(LEFT(D23,2)="NS",D$39,IF(LEFT(D23,3)="ND(",VALUE(MID(D23,4,LEN(D23)-4))/2,IF(LEFT(D23,3)="ND ",VALUE(MID(D23,5,LEN(D23)-5)/2),D23))))) | V23: =IF(ISBLANK(E23),"",IF(ISNUMBER(E23),E23,IF(LEFT(E23,2)="NS",E$39,IF(LEFT(E23,3)="ND(",VALUE(MID(E23,4,LEN(E23)-4))/2,IF(LEFT(E23,3)="ND ",VALUE(MID(E23,5,LEN(E23)-5)/2),E23))))) | W23: =IF(ISBLANK(F23),"",IF(ISNUMBER(F23),F23,IF(LEFT(F23,2)="NS",F$39,IF(LEFT(F23,3)="ND(",VALUE(MID(F23,4,LEN(F23)-4))/2,IF(LEFT(F23,3)="ND ",VALUE(MID(F23,5,LEN(F23)-5)/2),F23))))) | X23: =IF(ISBLANK(G23),"",IF(ISNUMBER(G23),G23,IF(LEFT(G23,2)="NS",G$39,IF(LEFT(G23,3)="ND(",VALUE(MID(G23,4,LEN(G23)-4))/2,IF(LEFT(G23,3)="ND ",VALUE(MID(G23,5,LEN(G23)-5)/2),G23))))) | Y23: =IF(ISBLANK(H23),"",IF(ISNUMBER(H23),H23,IF(LEFT(H23,2)="NS",H$39,IF(LEFT(H23,3)="ND(",VALUE(MID(H23,4,LEN(H23)-4))/2,IF(LEFT(H23,3)="ND ",VALUE(MID(H23,5,LEN(H23)-5)/2),H23))))) | Z23: =IF(ISBLANK(I23),"",IF(ISNUMBER(I23),I23,IF(LEFT(I23,2)="NS",I$39,IF(LEFT(I23,1)="<",VALUE(MID(I23,2,LEN(I23)-1)),IF(LEFT(I23,1)=">",VALUE(MID(I23,2,LEN(I23)-1)),I23))))) | AA23: =IF(ISBLANK(J23),"",IF(ISNUMBER(J23),J23,IF(LEFT(J23,2)="NS",J$39,IF(LEFT(J23,3)="ND(",VALUE(MID(J23,4,LEN(J23)-4))/2,IF(LEFT(J23,3)="ND ",VALUE(MID(J23,5,LEN(J23)-5)/2),J23))))) | AB23: =IF(ISBLANK(K23),"",IF(ISNUMBER(K23),K23,IF(LEFT(K23,2)="NS",K$39,IF(LEFT(K23,3)="ND(",VALUE(MID(K23,4,LEN(K23)-4))/2,IF(LEFT(K23,3)="ND ",VALUE(MID(K23,5,LEN(K23)-5)/2),K23)))))
T24: =IF(ISBLANK(C24),"",IF(ISNUMBER(C24),C24,IF(LEFT(C24,2)="NS","",IF(LEFT(C24,2)="No","",C24)))) | U24: =IF(ISBLANK(D24),"",IF(ISNUMBER(D24),D24,IF(LEFT(D24,2)="NS",D$39,IF(LEFT(D24,3)="ND(",VALUE(MID(D24,4,LEN(D24)-4))/2,IF(LEFT(D24,3)="ND ",VALUE(MID(D24,5,LEN(D24)-5)/2),D24))))) | V24: =IF(ISBLANK(E24),"",IF(ISNUMBER(E24),E24,IF(LEFT(E24,2)="NS",E$39,IF(LEFT(E24,3)="ND(",VALUE(MID(E24,4,LEN(E24)-4))/2,IF(LEFT(E24,3)="ND ",VALUE(MID(E24,5,LEN(E24)-5)/2),E24))))) | W24: =IF(ISBLANK(F24),"",IF(ISNUMBER(F24),F24,IF(LEFT(F24,2)="NS",F$39,IF(LEFT(F24,3)="ND(",VALUE(MID(F24,4,LEN(F24)-4))/2,IF(LEFT(F24,3)="ND ",VALUE(MID(F24,5,LEN(F24)-5)/2),F24))))) | X24: =IF(ISBLANK(G24),"",IF(ISNUMBER(G24),G24,IF(LEFT(G24,2)="NS",G$39,IF(LEFT(G24,3)="ND(",VALUE(MID(G24,4,LEN(G24)-4))/2,IF(LEFT(G24,3)="ND ",VALUE(MID(G24,5,LEN(G24)-5)/2),G24))))) | Y24: =IF(ISBLANK(H24),"",IF(ISNUMBER(H24),H24,IF(LEFT(H24,2)="NS",H$39,IF(LEFT(H24,3)="ND(",VALUE(MID(H24,4,LEN(H24)-4))/2,IF(LEFT(H24,3)="ND ",VALUE(MID(H24,5,LEN(H24)-5)/2),H24))))) | Z24: =IF(ISBLANK(I24),"",IF(ISNUMBER(I24),I24,IF(LEFT(I24,2)="NS",I$39,IF(LEFT(I24,1)="<",VALUE(MID(I24,2,LEN(I24)-1)),IF(LEFT(I24,1)=">",VALUE(MID(I24,2,LEN(I24)-1)),I24))))) | AA24: =IF(ISBLANK(J24),"",IF(ISNUMBER(J24),J24,IF(LEFT(J24,2)="NS",J$39,IF(LEFT(J24,3)="ND(",VALUE(MID(J24,4,LEN(J24)-4))/2,IF(LEFT(J24,3)="ND ",VALUE(MID(J24,5,LEN(J24)-5)/2),J24))))) | AB24: =IF(ISBLANK(K24),"",IF(ISNUMBER(K24),K24,IF(LEFT(K24,2)="NS",K$39,IF(LEFT(K24,3)="ND(",VALUE(MID(K24,4,LEN(K24)-4))/2,IF(LEFT(K24,3)="ND ",VALUE(MID(K24,5,LEN(K24)-5)/2),K24)))))
A25: Geometric Mean (Note 3) | D25: =IF(ISBLANK(D24),"",IF(ISNUMBER(D24),GEOMEAN(U21:U24),IF(LEFT(D24,2)="NS",GEOMEAN(U21:U24),IF(LEFT(D24,2)="ND",GEOMEAN(U21:U24),"M")))) | E25: =IF(ISBLANK(E24),"",IF(ISNUMBER(E24),GEOMEAN(V21:V24),IF(LEFT(E24,2)="NS",GEOMEAN(V21:V24),IF(LEFT(E24,2)="ND",GEOMEAN(V21:V24),"M")))) | F25: =IF(ISBLANK(F24),"",IF(ISNUMBER(F24),GEOMEAN(W21:W24),IF(LEFT(F24,2)="NS",GEOMEAN(W21:W24),IF(LEFT(F24,2)="ND",GEOMEAN(W21:W24),"M")))) | G25: =IF(ISBLANK(G24),"",IF(ISNUMBER(G24),GEOMEAN(X21:X24),IF(LEFT(G24,2)="NS",GEOMEAN(X21:X24),IF(LEFT(G24,2)="ND",GEOMEAN(X21:X24),"M")))) | H25: =IF(ISBLANK(H24),"",IF(ISNUMBER(H24),GEOMEAN(Y21:Y24),IF(LEFT(H24,2)="NS",GEOMEAN(Y21:Y24),IF(LEFT(H24,2)="ND",GEOMEAN(Y21:Y24),"M")))) | I25: =IF(ISBLANK(I24),"",IF(ISNUMBER(I24),GEOMEAN(Z21:Z24),IF(LEFT(I24,2)="NS",GEOMEAN(Z21:Z24),IF(LEFT(I24,2)="ND",GEOMEAN(Z21:Z24),IF(LEFT(I24,1)="<",GEOMEAN(C21:Z24),IF(LEFT(I24,1)=">",GEOMEAN(Z21:Z24),"M")))))) | J25: =IF(ISBLANK(J24),"",IF(ISNUMBER(J24),GEOMEAN(AA21:AA24),IF(LEFT(J24,2)="NS",GEOMEAN(AA21:AA24),IF(LEFT(J24,2)="ND",GEOMEAN(AA21:AA24),"M")))) | K25: =IF(ISBLANK(K24),"",IF(ISNUMBER(K24),GEOMEAN(AB21:AB24),IF(LEFT(K24,2)="NS",GEOMEAN(AB21:AB24),IF(LEFT(K24,2)="ND",GEOMEAN(AB21:AB24),"M"))))
T26: =IF(ISBLANK(C26),"",IF(ISNUMBER(C26),C26,IF(LEFT(C26,2)="NS","",IF(LEFT(C26,2)="No","",C26)))) | U26: =IF(ISBLANK(D26),"",IF(ISNUMBER(D26),D26,IF(LEFT(D26,2)="NS",D$39,IF(LEFT(D26,3)="ND(",VALUE(MID(D26,4,LEN(D26)-4))/2,IF(LEFT(D26,3)="ND ",VALUE(MID(D26,5,LEN(D26)-5)/2),D26))))) | V26: =IF(ISBLANK(E26),"",IF(ISNUMBER(E26),E26,IF(LEFT(E26,2)="NS",E$39,IF(LEFT(E26,3)="ND(",VALUE(MID(E26,4,LEN(E26)-4))/2,IF(LEFT(E26,3)="ND ",VALUE(MID(E26,5,LEN(E26)-5)/2),E26))))) | W26: =IF(ISBLANK(F26),"",IF(ISNUMBER(F26),F26,IF(LEFT(F26,2)="NS",F$39,IF(LEFT(F26,3)="ND(",VALUE(MID(F26,4,LEN(F26)-4))/2,IF(LEFT(F26,3)="ND ",VALUE(MID(F26,5,LEN(F26)-5)/2),F26))))) | X26: =IF(ISBLANK(G26),"",IF(ISNUMBER(G26),G26,IF(LEFT(G26,2)="NS",G$39,IF(LEFT(G26,3)="ND(",VALUE(MID(G26,4,LEN(G26)-4))/2,IF(LEFT(G26,3)="ND ",VALUE(MID(G26,5,LEN(G26)-5)/2),G26))))) | Y26: =IF(ISBLANK(H26),"",IF(ISNUMBER(H26),H26,IF(LEFT(H26,2)="NS",H$39,IF(LEFT(H26,3)="ND(",VALUE(MID(H26,4,LEN(H26)-4))/2,IF(LEFT(H26,3)="ND ",VALUE(MID(H26,5,LEN(H26)-5)/2),H26))))) | Z26: =IF(ISBLANK(I26),"",IF(ISNUMBER(I26),I26,IF(LEFT(I26,2)="NS",I$39,IF(LEFT(I26,1)="<",VALUE(MID(I26,2,LEN(I26)-1)),IF(LEFT(I26,1)=">",VALUE(MID(I26,2,LEN(I26)-1)),I26))))) | AA26: =IF(ISBLANK(J26),"",IF(ISNUMBER(J26),J26,IF(LEFT(J26,2)="NS",J$39,IF(LEFT(J26,3)="ND(",VALUE(MID(J26,4,LEN(J26)-4))/2,IF(LEFT(J26,3)="ND ",VALUE(MID(J26,5,LEN(J26)-5)/2),J26))))) | AB26: =IF(ISBLANK(K26),"",IF(ISNUMBER(K26),K26,IF(LEFT(K26,2)="NS",K$39,IF(LEFT(K26,3)="ND(",VALUE(MID(K26,4,LEN(K26)-4))/2,IF(LEFT(K26,3)="ND ",VALUE(MID(K26,5,LEN(K26)-5)/2),K26)))))
T27: =IF(ISBLANK(C27),"",IF(ISNUMBER(C27),C27,IF(LEFT(C27,2)="NS","",IF(LEFT(C27,2)="No","",C27)))) | U27: =IF(ISBLANK(D27),"",IF(ISNUMBER(D27),D27,IF(LEFT(D27,2)="NS",D$39,IF(LEFT(D27,3)="ND(",VALUE(MID(D27,4,LEN(D27)-4))/2,IF(LEFT(D27,3)="ND ",VALUE(MID(D27,5,LEN(D27)-5)/2),D27))))) | V27: =IF(ISBLANK(E27),"",IF(ISNUMBER(E27),E27,IF(LEFT(E27,2)="NS",E$39,IF(LEFT(E27,3)="ND(",VALUE(MID(E27,4,LEN(E27)-4))/2,IF(LEFT(E27,3)="ND ",VALUE(MID(E27,5,LEN(E27)-5)/2),E27))))) | W27: =IF(ISBLANK(F27),"",IF(ISNUMBER(F27),F27,IF(LEFT(F27,2)="NS",F$39,IF(LEFT(F27,3)="ND(",VALUE(MID(F27,4,LEN(F27)-4))/2,IF(LEFT(F27,3)="ND ",VALUE(MID(F27,5,LEN(F27)-5)/2),F27))))) | X27: =IF(ISBLANK(G27),"",IF(ISNUMBER(G27),G27,IF(LEFT(G27,2)="NS",G$39,IF(LEFT(G27,3)="ND(",VALUE(MID(G27,4,LEN(G27)-4))/2,IF(LEFT(G27,3)="ND ",VALUE(MID(G27,5,LEN(G27)-5)/2),G27))))) | Y27: =IF(ISBLANK(H27),"",IF(ISNUMBER(H27),H27,IF(LEFT(H27,2)="NS",H$39,IF(LEFT(H27,3)="ND(",VALUE(MID(H27,4,LEN(H27)-4))/2,IF(LEFT(H27,3)="ND ",VALUE(MID(H27,5,LEN(H27)-5)/2),H27))))) | Z27: =IF(ISBLANK(I27),"",IF(ISNUMBER(I27),I27,IF(LEFT(I27,2)="NS",I$39,IF(LEFT(I27,1)="<",VALUE(MID(I27,2,LEN(I27)-1)),IF(LEFT(I27,1)=">",VALUE(MID(I27,2,LEN(I27)-1)),I27))))) | AA27: =IF(ISBLANK(J27),"",IF(ISNUMBER(J27),J27,IF(LEFT(J27,2)="NS",J$39,IF(LEFT(J27,3)="ND(",VALUE(MID(J27,4,LEN(J27)-4))/2,IF(LEFT(J27,3)="ND ",VALUE(MID(J27,5,LEN(J27)-5)/2),J27))))) | AB27: =IF(ISBLANK(K27),"",IF(ISNUMBER(K27),K27,IF(LEFT(K27,2)="NS",K$39,IF(LEFT(K27,3)="ND(",VALUE(MID(K27,4,LEN(K27)-4))/2,IF(LEFT(K27,3)="ND ",VALUE(MID(K27,5,LEN(K27)-5)/2),K27)))))
T28: =IF(ISBLANK(C28),"",IF(ISNUMBER(C28),C28,IF(LEFT(C28,2)="NS","",IF(LEFT(C28,2)="No","",C28)))) | U28: =IF(ISBLANK(D28),"",IF(ISNUMBER(D28),D28,IF(LEFT(D28,2)="NS",D$39,IF(LEFT(D28,3)="ND(",VALUE(MID(D28,4,LEN(D28)-4))/2,IF(LEFT(D28,3)="ND ",VALUE(MID(D28,5,LEN(D28)-5)/2),D28))))) | V28: =IF(ISBLANK(E28),"",IF(ISNUMBER(E28),E28,IF(LEFT(E28,2)="NS",E$39,IF(LEFT(E28,3)="ND(",VALUE(MID(E28,4,LEN(E28)-4))/2,IF(LEFT(E28,3)="ND ",VALUE(MID(E28,5,LEN(E28)-5)/2),E28))))) | W28: =IF(ISBLANK(F28),"",IF(ISNUMBER(F28),F28,IF(LEFT(F28,2)="NS",F$39,IF(LEFT(F28,3)="ND(",VALUE(MID(F28,4,LEN(F28)-4))/2,IF(LEFT(F28,3)="ND ",VALUE(MID(F28,5,LEN(F28)-5)/2),F28))))) | X28: =IF(ISBLANK(G28),"",IF(ISNUMBER(G28),G28,IF(LEFT(G28,2)="NS",G$39,IF(LEFT(G28,3)="ND(",VALUE(MID(G28,4,LEN(G28)-4))/2,IF(LEFT(G28,3)="ND ",VALUE(MID(G28,5,LEN(G28)-5)/2),G28))))) | Y28: =IF(ISBLANK(H28),"",IF(ISNUMBER(H28),H28,IF(LEFT(H28,2)="NS",H$39,IF(LEFT(H28,3)="ND(",VALUE(MID(H28,4,LEN(H28)-4))/2,IF(LEFT(H28,3)="ND ",VALUE(MID(H28,5,LEN(H28)-5)/2),H28))))) | Z28: =IF(ISBLANK(I28),"",IF(ISNUMBER(I28),I28,IF(LEFT(I28,2)="NS",I$39,IF(LEFT(I28,1)="<",VALUE(MID(I28,2,LEN(I28)-1)),IF(LEFT(I28,1)=">",VALUE(MID(I28,2,LEN(I28)-1)),I28))))) | AA28: =IF(ISBLANK(J28),"",IF(ISNUMBER(J28),J28,IF(LEFT(J28,2)="NS",J$39,IF(LEFT(J28,3)="ND(",VALUE(MID(J28,4,LEN(J28)-4))/2,IF(LEFT(J28,3)="ND ",VALUE(MID(J28,5,LEN(J28)-5)/2),J28))))) | AB28: =IF(ISBLANK(K28),"",IF(ISNUMBER(K28),K28,IF(LEFT(K28,2)="NS",K$39,IF(LEFT(K28,3)="ND(",VALUE(MID(K28,4,LEN(K28)-4))/2,IF(LEFT(K28,3)="ND ",VALUE(MID(K28,5,LEN(K28)-5)/2),K28)))))
T29: =IF(ISBLANK(C29),"",IF(ISNUMBER(C29),C29,IF(LEFT(C29,2)="NS","",IF(LEFT(C29,2)="No","",C29)))) | U29: =IF(ISBLANK(D29),"",IF(ISNUMBER(D29),D29,IF(LEFT(D29,2)="NS",D$39,IF(LEFT(D29,3)="ND(",VALUE(MID(D29,4,LEN(D29)-4))/2,IF(LEFT(D29,3)="ND ",VALUE(MID(D29,5,LEN(D29)-5)/2),D29))))) | V29: =IF(ISBLANK(E29),"",IF(ISNUMBER(E29),E29,IF(LEFT(E29,2)="NS",E$39,IF(LEFT(E29,3)="ND(",VALUE(MID(E29,4,LEN(E29)-4))/2,IF(LEFT(E29,3)="ND ",VALUE(MID(E29,5,LEN(E29)-5)/2),E29))))) | W29: =IF(ISBLANK(F29),"",IF(ISNUMBER(F29),F29,IF(LEFT(F29,2)="NS",F$39,IF(LEFT(F29,3)="ND(",VALUE(MID(F29,4,LEN(F29)-4))/2,IF(LEFT(F29,3)="ND ",VALUE(MID(F29,5,LEN(F29)-5)/2),F29))))) | X29: =IF(ISBLANK(G29),"",IF(ISNUMBER(G29),G29,IF(LEFT(G29,2)="NS",G$39,IF(LEFT(G29,3)="ND(",VALUE(MID(G29,4,LEN(G29)-4))/2,IF(LEFT(G29,3)="ND ",VALUE(MID(G29,5,LEN(G29)-5)/2),G29))))) | Y29: =IF(ISBLANK(H29),"",IF(ISNUMBER(H29),H29,IF(LEFT(H29,2)="NS",H$39,IF(LEFT(H29,3)="ND(",VALUE(MID(H29,4,LEN(H29)-4))/2,IF(LEFT(H29,3)="ND ",VALUE(MID(H29,5,LEN(H29)-5)/2),H29))))) | Z29: =IF(ISBLANK(I29),"",IF(ISNUMBER(I29),I29,IF(LEFT(I29,2)="NS",I$39,IF(LEFT(I29,1)="<",VALUE(MID(I29,2,LEN(I29)-1)),IF(LEFT(I29,1)=">",VALUE(MID(I29,2,LEN(I29)-1)),I29))))) | AA29: =IF(ISBLANK(J29),"",IF(ISNUMBER(J29),J29,IF(LEFT(J29,2)="NS",J$39,IF(LEFT(J29,3)="ND(",VALUE(MID(J29,4,LEN(J29)-4))/2,IF(LEFT(J29,3)="ND ",VALUE(MID(J29,5,LEN(J29)-5)/2),J29))))) | AB29: =IF(ISBLANK(K29),"",IF(ISNUMBER(K29),K29,IF(LEFT(K29,2)="NS",K$39,IF(LEFT(K29,3)="ND(",VALUE(MID(K29,4,LEN(K29)-4))/2,IF(LEFT(K29,3)="ND ",VALUE(MID(K29,5,LEN(K29)-5)/2),K29)))))
A30: Geometric Mean (Note 3) | D30: =IF(ISBLANK(D29),"",IF(ISNUMBER(D29),GEOMEAN(U26:U29),IF(LEFT(D29,2)="NS",GEOMEAN(U26:U29),IF(LEFT(D29,2)="ND",GEOMEAN(U26:U29),"M")))) | E30: =IF(ISBLANK(E29),"",IF(ISNUMBER(E29),GEOMEAN(V26:V29),IF(LEFT(E29,2)="NS",GEOMEAN(V26:V29),IF(LEFT(E29,2)="ND",GEOMEAN(V26:V29),"M")))) | F30: =IF(ISBLANK(F29),"",IF(ISNUMBER(F29),GEOMEAN(W26:W29),IF(LEFT(F29,2)="NS",GEOMEAN(W26:W29),IF(LEFT(F29,2)="ND",GEOMEAN(W26:W29),"M")))) | G30: =IF(ISBLANK(G29),"",IF(ISNUMBER(G29),GEOMEAN(X26:X29),IF(LEFT(G29,2)="NS",GEOMEAN(X26:X29),IF(LEFT(G29,2)="ND",GEOMEAN(X26:X29),"M")))) | H30: =IF(ISBLANK(H29),"",IF(ISNUMBER(H29),GEOMEAN(Y26:Y29),IF(LEFT(H29,2)="NS",GEOMEAN(Y26:Y29),IF(LEFT(H29,2)="ND",GEOMEAN(Y26:Y29),"M")))) | I30: =IF(ISBLANK(I29),"",IF(ISNUMBER(I29),GEOMEAN(Z26:Z29),IF(LEFT(I29,2)="NS",GEOMEAN(Z26:Z29),IF(LEFT(I29,2)="ND",GEOMEAN(Z26:Z29),IF(LEFT(I29,1)="<",GEOMEAN(C26:Z29),IF(LEFT(I29,1)=">",GEOMEAN(Z26:Z29),"M")))))) | J30: =IF(ISBLANK(J29),"",IF(ISNUMBER(J29),GEOMEAN(AA26:AA29),IF(LEFT(J29,2)="NS",GEOMEAN(AA26:AA29),IF(LEFT(J29,2)="ND",GEOMEAN(AA26:AA29),"M")))) | K30: =IF(ISBLANK(K29),"",IF(ISNUMBER(K29),GEOMEAN(AB26:AB29),IF(LEFT(K29,2)="NS",GEOMEAN(AB26:AB29),IF(LEFT(K29,2)="ND",GEOMEAN(AB26:AB29),"M"))))
T31: =IF(ISBLANK(C31),"",IF(ISNUMBER(C31),C31,IF(LEFT(C31,2)="NS","",IF(LEFT(C31,2)="No","",C31)))) | U31: =IF(ISBLANK(D31),"",IF(ISNUMBER(D31),D31,IF(LEFT(D31,2)="NS",D$39,IF(LEFT(D31,3)="ND(",VALUE(MID(D31,4,LEN(D31)-4))/2,IF(LEFT(D31,3)="ND ",VALUE(MID(D31,5,LEN(D31)-5)/2),D31))))) | V31: =IF(ISBLANK(E31),"",IF(ISNUMBER(E31),E31,IF(LEFT(E31,2)="NS",E$39,IF(LEFT(E31,3)="ND(",VALUE(MID(E31,4,LEN(E31)-4))/2,IF(LEFT(E31,3)="ND ",VALUE(MID(E31,5,LEN(E31)-5)/2),E31))))) | W31: =IF(ISBLANK(F31),"",IF(ISNUMBER(F31),F31,IF(LEFT(F31,2)="NS",F$39,IF(LEFT(F31,3)="ND(",VALUE(MID(F31,4,LEN(F31)-4))/2,IF(LEFT(F31,3)="ND ",VALUE(MID(F31,5,LEN(F31)-5)/2),F31))))) | X31: =IF(ISBLANK(G31),"",IF(ISNUMBER(G31),G31,IF(LEFT(G31,2)="NS",G$39,IF(LEFT(G31,3)="ND(",VALUE(MID(G31,4,LEN(G31)-4))/2,IF(LEFT(G31,3)="ND ",VALUE(MID(G31,5,LEN(G31)-5)/2),G31))))) | Y31: =IF(ISBLANK(H31),"",IF(ISNUMBER(H31),H31,IF(LEFT(H31,2)="NS",H$39,IF(LEFT(H31,3)="ND(",VALUE(MID(H31,4,LEN(H31)-4))/2,IF(LEFT(H31,3)="ND ",VALUE(MID(H31,5,LEN(H31)-5)/2),H31))))) | Z31: =IF(ISBLANK(I31),"",IF(ISNUMBER(I31),I31,IF(LEFT(I31,2)="NS",I$39,IF(LEFT(I31,1)="<",VALUE(MID(I31,2,LEN(I31)-1)),IF(LEFT(I31,1)=">",VALUE(MID(I31,2,LEN(I31)-1)),I31))))) | AA31: =IF(ISBLANK(J31),"",IF(ISNUMBER(J31),J31,IF(LEFT(J31,2)="NS",J$39,IF(LEFT(J31,3)="ND(",VALUE(MID(J31,4,LEN(J31)-4))/2,IF(LEFT(J31,3)="ND ",VALUE(MID(J31,5,LEN(J31)-5)/2),J31))))) | AB31: =IF(ISBLANK(K31),"",IF(ISNUMBER(K31),K31,IF(LEFT(K31,2)="NS",K$39,IF(LEFT(K31,3)="ND(",VALUE(MID(K31,4,LEN(K31)-4))/2,IF(LEFT(K31,3)="ND ",VALUE(MID(K31,5,LEN(K31)-5)/2),K31)))))
T32: =IF(ISBLANK(C32),"",IF(ISNUMBER(C32),C32,IF(LEFT(C32,2)="NS","",IF(LEFT(C32,2)="No","",C32)))) | U32: =IF(ISBLANK(D32),"",IF(ISNUMBER(D32),D32,IF(LEFT(D32,2)="NS",D$39,IF(LEFT(D32,3)="ND(",VALUE(MID(D32,4,LEN(D32)-4))/2,IF(LEFT(D32,3)="ND ",VALUE(MID(D32,5,LEN(D32)-5)/2),D32))))) | V32: =IF(ISBLANK(E32),"",IF(ISNUMBER(E32),E32,IF(LEFT(E32,2)="NS",E$39,IF(LEFT(E32,3)="ND(",VALUE(MID(E32,4,LEN(E32)-4))/2,IF(LEFT(E32,3)="ND ",VALUE(MID(E32,5,LEN(E32)-5)/2),E32))))) | W32: =IF(ISBLANK(F32),"",IF(ISNUMBER(F32),F32,IF(LEFT(F32,2)="NS",F$39,IF(LEFT(F32,3)="ND(",VALUE(MID(F32,4,LEN(F32)-4))/2,IF(LEFT(F32,3)="ND ",VALUE(MID(F32,5,LEN(F32)-5)/2),F32))))) | X32: =IF(ISBLANK(G32),"",IF(ISNUMBER(G32),G32,IF(LEFT(G32,2)="NS",G$39,IF(LEFT(G32,3)="ND(",VALUE(MID(G32,4,LEN(G32)-4))/2,IF(LEFT(G32,3)="ND ",VALUE(MID(G32,5,LEN(G32)-5)/2),G32))))) | Y32: =IF(ISBLANK(H32),"",IF(ISNUMBER(H32),H32,IF(LEFT(H32,2)="NS",H$39,IF(LEFT(H32,3)="ND(",VALUE(MID(H32,4,LEN(H32)-4))/2,IF(LEFT(H32,3)="ND ",VALUE(MID(H32,5,LEN(H32)-5)/2),H32))))) | Z32: =IF(ISBLANK(I32),"",IF(ISNUMBER(I32),I32,IF(LEFT(I32,2)="NS",I$39,IF(LEFT(I32,1)="<",VALUE(MID(I32,2,LEN(I32)-1)),IF(LEFT(I32,1)=">",VALUE(MID(I32,2,LEN(I32)-1)),I32))))) | AA32: =IF(ISBLANK(J32),"",IF(ISNUMBER(J32),J32,IF(LEFT(J32,2)="NS",J$39,IF(LEFT(J32,3)="ND(",VALUE(MID(J32,4,LEN(J32)-4))/2,IF(LEFT(J32,3)="ND ",VALUE(MID(J32,5,LEN(J32)-5)/2),J32))))) | AB32: =IF(ISBLANK(K32),"",IF(ISNUMBER(K32),K32,IF(LEFT(K32,2)="NS",K$39,IF(LEFT(K32,3)="ND(",VALUE(MID(K32,4,LEN(K32)-4))/2,IF(LEFT(K32,3)="ND ",VALUE(MID(K32,5,LEN(K32)-5)/2),K32)))))
T33: =IF(ISBLANK(C33),"",IF(ISNUMBER(C33),C33,IF(LEFT(C33,2)="NS","",IF(LEFT(C33,2)="No","",C33)))) | U33: =IF(ISBLANK(D33),"",IF(ISNUMBER(D33),D33,IF(LEFT(D33,2)="NS",D$39,IF(LEFT(D33,3)="ND(",VALUE(MID(D33,4,LEN(D33)-4))/2,IF(LEFT(D33,3)="ND ",VALUE(MID(D33,5,LEN(D33)-5)/2),D33))))) | V33: =IF(ISBLANK(E33),"",IF(ISNUMBER(E33),E33,IF(LEFT(E33,2)="NS",E$39,IF(LEFT(E33,3)="ND(",VALUE(MID(E33,4,LEN(E33)-4))/2,IF(LEFT(E33,3)="ND ",VALUE(MID(E33,5,LEN(E33)-5)/2),E33))))) | W33: =IF(ISBLANK(F33),"",IF(ISNUMBER(F33),F33,IF(LEFT(F33,2)="NS",F$39,IF(LEFT(F33,3)="ND(",VALUE(MID(F33,4,LEN(F33)-4))/2,IF(LEFT(F33,3)="ND ",VALUE(MID(F33,5,LEN(F33)-5)/2),F33))))) | X33: =IF(ISBLANK(G33),"",IF(ISNUMBER(G33),G33,IF(LEFT(G33,2)="NS",G$39,IF(LEFT(G33,3)="ND(",VALUE(MID(G33,4,LEN(G33)-4))/2,IF(LEFT(G33,3)="ND ",VALUE(MID(G33,5,LEN(G33)-5)/2),G33))))) | Y33: =IF(ISBLANK(H33),"",IF(ISNUMBER(H33),H33,IF(LEFT(H33,2)="NS",H$39,IF(LEFT(H33,3)="ND(",VALUE(MID(H33,4,LEN(H33)-4))/2,IF(LEFT(H33,3)="ND ",VALUE(MID(H33,5,LEN(H33)-5)/2),H33))))) | Z33: =IF(ISBLANK(I33),"",IF(ISNUMBER(I33),I33,IF(LEFT(I33,2)="NS",I$39,IF(LEFT(I33,1)="<",VALUE(MID(I33,2,LEN(I33)-1)),IF(LEFT(I33,1)=">",VALUE(MID(I33,2,LEN(I33)-1)),I33))))) | AA33: =IF(ISBLANK(J33),"",IF(ISNUMBER(J33),J33,IF(LEFT(J33,2)="NS",J$39,IF(LEFT(J33,3)="ND(",VALUE(MID(J33,4,LEN(J33)-4))/2,IF(LEFT(J33,3)="ND ",VALUE(MID(J33,5,LEN(J33)-5)/2),J33))))) | AB33: =IF(ISBLANK(K33),"",IF(ISNUMBER(K33),K33,IF(LEFT(K33,2)="NS",K$39,IF(LEFT(K33,3)="ND(",VALUE(MID(K33,4,LEN(K33)-4))/2,IF(LEFT(K33,3)="ND ",VALUE(MID(K33,5,LEN(K33)-5)/2),K33)))))
T34: =IF(ISBLANK(C34),"",IF(ISNUMBER(C34),C34,IF(LEFT(C34,2)="NS","",IF(LEFT(C34,2)="No","",C34)))) | U34: =IF(ISBLANK(D34),"",IF(ISNUMBER(D34),D34,IF(LEFT(D34,2)="NS",D$39,IF(LEFT(D34,3)="ND(",VALUE(MID(D34,4,LEN(D34)-4))/2,IF(LEFT(D34,3)="ND ",VALUE(MID(D34,5,LEN(D34)-5)/2),D34))))) | V34: =IF(ISBLANK(E34),"",IF(ISNUMBER(E34),E34,IF(LEFT(E34,2)="NS",E$39,IF(LEFT(E34,3)="ND(",VALUE(MID(E34,4,LEN(E34)-4))/2,IF(LEFT(E34,3)="ND ",VALUE(MID(E34,5,LEN(E34)-5)/2),E34))))) | W34: =IF(ISBLANK(F34),"",IF(ISNUMBER(F34),F34,IF(LEFT(F34,2)="NS",F$39,IF(LEFT(F34,3)="ND(",VALUE(MID(F34,4,LEN(F34)-4))/2,IF(LEFT(F34,3)="ND ",VALUE(MID(F34,5,LEN(F34)-5)/2),F34))))) | X34: =IF(ISBLANK(G34),"",IF(ISNUMBER(G34),G34,IF(LEFT(G34,2)="NS",G$39,IF(LEFT(G34,3)="ND(",VALUE(MID(G34,4,LEN(G34)-4))/2,IF(LEFT(G34,3)="ND ",VALUE(MID(G34,5,LEN(G34)-5)/2),G34))))) | Y34: =IF(ISBLANK(H34),"",IF(ISNUMBER(H34),H34,IF(LEFT(H34,2)="NS",H$39,IF(LEFT(H34,3)="ND(",VALUE(MID(H34,4,LEN(H34)-4))/2,IF(LEFT(H34,3)="ND ",VALUE(MID(H34,5,LEN(H34)-5)/2),H34))))) | Z34: =IF(ISBLANK(I34),"",IF(ISNUMBER(I34),I34,IF(LEFT(I34,2)="NS",I$39,IF(LEFT(I34,1)="<",VALUE(MID(I34,2,LEN(I34)-1)),IF(LEFT(I34,1)=">",VALUE(MID(I34,2,LEN(I34)-1)),I34))))) | AA34: =IF(ISBLANK(J34),"",IF(ISNUMBER(J34),J34,IF(LEFT(J34,2)="NS",J$39,IF(LEFT(J34,3)="ND(",VALUE(MID(J34,4,LEN(J34)-4))/2,IF(LEFT(J34,3)="ND ",VALUE(MID(J34,5,LEN(J34)-5)/2),J34))))) | AB34: =IF(ISBLANK(K34),"",IF(ISNUMBER(K34),K34,IF(LEFT(K34,2)="NS",K$39,IF(LEFT(K34,3)="ND(",VALUE(MID(K34,4,LEN(K34)-4))/2,IF(LEFT(K34,3)="ND ",VALUE(MID(K34,5,LEN(K34)-5)/2),K34)))))
A35: Geometric Mean (Note 3) | D35: =IF(ISBLANK(D34),"",IF(ISNUMBER(D34),GEOMEAN(U31:U34),IF(LEFT(D34,2)="NS",GEOMEAN(U31:U34),IF(LEFT(D34,2)="ND",GEOMEAN(U31:U34),"M")))) | E35: =IF(ISBLANK(E34),"",IF(ISNUMBER(E34),GEOMEAN(V31:V34),IF(LEFT(E34,2)="NS",GEOMEAN(V31:V34),IF(LEFT(E34,2)="ND",GEOMEAN(V31:V34),"M")))) | F35: =IF(ISBLANK(F34),"",IF(ISNUMBER(F34),GEOMEAN(W31:W34),IF(LEFT(F34,2)="NS",GEOMEAN(W31:W34),IF(LEFT(F34,2)="ND",GEOMEAN(W31:W34),"M")))) | G35: =IF(ISBLANK(G34),"",IF(ISNUMBER(G34),GEOMEAN(X31:X34),IF(LEFT(G34,2)="NS",GEOMEAN(X31:X34),IF(LEFT(G34,2)="ND",GEOMEAN(X31:X34),"M")))) | H35: =IF(ISBLANK(H34),"",IF(ISNUMBER(H34),GEOMEAN(Y31:Y34),IF(LEFT(H34,2)="NS",GEOMEAN(Y31:Y34),IF(LEFT(H34,2)="ND",GEOMEAN(Y31:Y34),"M")))) | I35: =IF(ISBLANK(I34),"",IF(ISNUMBER(I34),GEOMEAN(Z31:Z34),IF(LEFT(I34,2)="NS",GEOMEAN(Z31:Z34),IF(LEFT(I34,2)="ND",GEOMEAN(Z31:Z34),IF(LEFT(I34,1)="<",GEOMEAN(C31:Z34),IF(LEFT(I34,1)=">",GEOMEAN(Z31:Z34),"M")))))) | J35: =IF(ISBLANK(J34),"",IF(ISNUMBER(J34),GEOMEAN(AA31:AA34),IF(LEFT(J34,2)="NS",GEOMEAN(AA31:AA34),IF(LEFT(J34,2)="ND",GEOMEAN(AA31:AA34),"M")))) | K35: =IF(ISBLANK(K34),"",IF(ISNUMBER(K34),GEOMEAN(AB31:AB34),IF(LEFT(K34,2)="NS",GEOMEAN(AB31:AB34),IF(LEFT(K34,2)="ND",GEOMEAN(AB31:AB34),"M"))))
A36: Permit Benchmark | D36: 50 | E36: 10 | F36: 0.036 | G36: 0.06 | H36: 0.24 | I36: 406 | J36: 0.16
A37: Name/Title Principal Executive Officer or Authorized Delegate
A38: (Please Print) First Name: | E38: Last Name: | J38: Title:
A40: Telephone: | D40: Email:
A41: 40 CFR 122.22 I certify, under penalty of law, that this document and all attachments were prepared under my direct supervision in accordance with a system designed to assure that qualified personnel properly gather and evaluate the information submitted. Based on my inquiry of the person or persons who manage the system, or those persons directly responsible for gathering the information, the information submitted is, to the best of my knowledge and belief, true, accurate, and complete. I am aware that there are significant penalties for submitting false information, including the possibility of fines and imprisonment for knowing violations.
A45: Sign here: | I45: Date:
A48: Page 1 | L48: Last updated 1/23/2013 | M48: 08-WQ-032
A51: Additional Sampling
C52: 8 samples during first 3 years | G52: 4 samples during first 3 years
C53: All Permittees | G53: Auto Salvage & Scrap Recycling Facilities | I53: Scrap Recycling Facilities | K53: * PCBs should be reported as the sum of the following aroclors 1016, 1221, 1232, 1242, 1248, 1254, 1260. Do not use any value for any aloclor that is non-detect, Should all Aloclors be non-detect report the ND value for the highest non-detect value from the lab report; typically, this will be ND (0.002).
A54: Name or Number of Sampling Point(s) (group data per sampling point) | B54: Sample Date | C54: Cadmium, Total | D54: Nickel, Total | E54: Chromium, Total | G54: Mercury, Total | I54: Total PCBs *
...

Sheet Sector
A1: =Common!A1:N1 -> Industrial Stormwater Discharge Monitoring Report - 1200-COLS Permit
A2: Permittee Legal Name: | D2: =IF(ISBLANK(Common!C2:E3),"",Common!C2:E3) | G2: ODEQ File No./Facility ID: | J2: =IF(ISBLANK(Common!I2),"",Common!I2)
A4: Facility Common Name: | D4: =IF(ISBLANK(Common!C4:E5),"",Common!C4:E5) | G4: Reporting Period: | I4: July 1, | J4: =IF(ISBLANK(Common!I4),"",Common!I4) | K4: to | L4: June 30, | M4: =IF(ISBLANK(Common!L4),"",Common!L4)
A6: Facility Location: | D6: =IF(ISBLANK(Common!C6:E7),"",Common!C6:E7) | G6: Laboratory Name: | J6: =IF(ISBLANK(Common!I6),"",Common!I6)
A8: County: | D8: =IF(ISBLANK(Common!C8:E9),"",Common!C8:E9) | G8: Laboratory ORELAP #: | J8: =IF(ISBLANK(Common!I8),"",Common!I8) | K8: SIC Code(s): | L8: =IF(ISBLANK(Common!K8),"",Common!K8)
A10: Sector Specific Benchmark Sampling: 4 times per year, every year
A11: Please refer to the permit assignment letter to determine if sector specific benchmark sampling is required.
A12: Name or Number of Sampling Point(s) (group data per sampling point) | C12: Sample Date | D12: Iron, Total | E12: Aluminum, Total | F12: Nitrate + Nitrite Nitrogen | G12: COD
D13: mg/L | E13: mg/L | F13: mg/L | G13: mg/L
A31: Permit Benchmark | D31: 1 | E31: 0.75 | F31: 0.68 | G31: 120
A33: Page 3 | M33: =Common!L48 -> Last updated 1/23/2013 | N33: =Common!M48 -> 08-WQ-032

Sheet Impairment
A1: =Common!A1:N1 -> Industrial Stormwater Discharge Monitoring Report - 1200-COLS Permit
A2: Permittee Legal Name: | D2: =IF(ISBLANK(Common!C2:E3),"",Common!C2:E3) | G2: ODEQ File No./Facility ID: | J2: =IF(ISBLANK(Common!I2),"",Common!I2)
A4: Facility Common Name: | D4: =IF(ISBLANK(Common!C4:E5),"",Common!C4:E5) | G4: Reporting Period: | I4: July 1, | J4: =IF(ISBLANK(Common!I4),"",Common!I4) | K4: to | L4: June 30, | M4: =IF(ISBLANK(Common!L4),"",Common!L4)
A6: Facility Location: | D6: =IF(ISBLANK(Common!C6:E7),"",Common!C6:E7) | G6: Laboratory Name: | J6: =IF(ISBLANK(Common!I6),"",Common!I6)
A8: County: | D8: =IF(ISBLANK(Common!C8:E9),"",Common!C8:E9) | G8: Laboratory ORELAP #: | J8: =IF(ISBLANK(Common!I8),"",Common!I8) | K8: SIC Code(s): | L8: =IF(ISBLANK(Common!K8),"",Common!K8)
A10: Impairment Sampling: 2 times per year, every year
A11: Please refer to the permit assignment letter to determine if impairment sampling is required.
A12: Name or Number of Sampling Point(s) (group data per sampling point) | C12: Sample Date | D12: Iron
D13: mg/L
A23: Permit Reference Concentration | D23: 1
A24: Name or Number of Sampling Point(s) (group data per sampling point) | C24: Sample Date
D25: mg/L | E25: mg/L | F25: mg/L | G25: mg/L | H25: mg/L | I25: mg/L | J25: mg/L | K25: mg/L | L25: mg/L
A35: Permit Reference Concentration
A36: Name or Number of Sampling Point(s) (group data per sampling point) | C36: Sample Date
D37: mg/L | E37: mg/L | F37: mg/L | G37: mg/L | H37: mg/L | I37: mg/L | J37: mg/L | K37: mg/L | L37: mg/L | M37: mg/L | N37: mg/L
A47: Permit Reference Concentration
A48: Page 4 | M48: =Common!L48 -> Last updated 1/23/2013 | N48: =Common!M48 -> 08-WQ-032

Sheet INSTRUCTIONS
A1: DMR Instructions
A2: Industrial Stormwater Discharge Monitoring Report - 1200-COLS Permit
A4: All Sections
A5: · Organize data first by sample location/outfall.
A6: · For each location, provide the data.
A7: · Where applicable, the spreadsheet will calculate the geometric mean.
A8: · Submit only pages needed for your facility.
A9: · Report non-detects as "ND" along with the applicable method detection limit or minimum quantification limit in parentheses; for example ND (0.001).
A10: · If you collected more data than will fit in the standard form (for example, more than 4 locations or more than 4 samples per location), fill out additional pages as needed.
A12: Common tab: Benchmark Sampling
A13: · Required for all permit holders
A14: · Sample 4 times per year, every year (unless a monitoring waiver applies).
... A43: If your facility does not have impairment pollutant requirements, do not submit this page.

Sheet tabulationDO-NOT-SORT
A1: Legal Name | B1: Common Name | C1: Location | D1: County | E1: Facility ID | F1: Reporting Year | G1: Laboratory | H1: ORELAP # | I1: SIC Codes | J1: Section | K1: Sample Location | L1: Date | M1: Parameter | N1: Units | O1: Result | P1: MaxComparison | Q1: MinComparison
A2: =IF(ISBLANK(Common!C$2),"",Common!C$2) | B2: =IF(ISBLANK(Common!C$4),"",Common!C$4) | C2: =IF(ISBLANK(Common!C$6),"",Common!C$6) | D2: =IF(ISBLANK(Common!C$8),"",Common!C$8) | E2: =IF(ISBLANK(Common!I$2),"",Common!I$2) | F2: =IF(ISBLANK(Common!I$4),"",Common!I$4) | G2: =IF(ISBLANK(Common!I$6),"",Common!I$6) | H2: =IF(ISBLANK(Common!I$8),"",Common!I$8) | I2: =IF(ISBLANK(Common!K$8),"",Common!K$8) | J2: Benchmark | K2: =Common!A16 -> 0 | L2: =Common!B16 -> 0 | M2: =Common!C13 -> pH | N2: =Common!C14 -> s.u. | O2: =IF(ISBLANK(Common!C16),"",Common!C16) | P2: 9 | Q2: 5.5
A3: =IF(ISBLANK(Common!C$2),"",Common!C$2) | B3: =IF(ISBLANK(Common!C$4),"",Common!C$4) | C3: =IF(ISBLANK(Common!C$6),"",Common!C$6) | D3: =IF(ISBLANK(Common!C$8),"",Common!C$8) | E3: =IF(ISBLANK(Common!I$2),"",Common!I$2) | F3: =IF(ISBLANK(Common!I$4),"",Common!I$4) | G3: =IF(ISBLANK(Common!I$6),"",Common!I$6) | H3: =IF(ISBLANK(Common!I$8),"",Common!I$8) | I3: =IF(ISBLANK(Common!K$8),"",Common!K$8) | J3: Benchmark | K3: =K2 -> 0 | L3: =Common!B17 -> 0 | M3: =M2 -> pH | N3: =N2 -> s.u. | O3: =IF(ISBLANK(Common!C17),"",Common!C17) | P3: 9 | Q3: 5.5
A4: =IF(ISBLANK(Common!C$2),"",Common!C$2) | B4: =IF(ISBLANK(Common!C$4),"",Common!C$4) | C4: =IF(ISBLANK(Common!C$6),"",Common!C$6) | D4: =IF(ISBLANK(Common!C$8),"",Common!C$8) | E4: =IF(ISBLANK(Common!I$2),"",Common!I$2) | F4: =IF(ISBLANK(Common!I$4),"",Common!I$4) | G4: =IF(ISBLANK(Common!I$6),"",Common!I$6) | H4: =IF(ISBLANK(Common!I$8),"",Common!I$8) | I4: =IF(ISBLANK(Common!K$8),"",Common!K$8) | J4: Benchmark | K4: =K3 -> 0 | L4: =Common!B18 -> 0 | M4: =M3 -> pH | N4: =N3 -> s.u. | O4: =IF(ISBLANK(Common!C18),"",Common!C18) | P4: 9 | Q4: 5.5
A5: =IF(ISBLANK(Common!C$2),"",Common!C$2) | B5: =IF(ISBLANK(Common!C$4),"",Common!C$4) | C5: =IF(ISBLANK(Common!C$6),"",Common!C$6) | D5: =IF(ISBLANK(Common!C$8),"",Common!C$8) | E5: =IF(ISBLANK(Common!I$2),"",Common!I$2) | F5: =IF(ISBLANK(Common!I$4),"",Common!I$4) | G5: =IF(ISBLANK(Common!I$6),"",Common!I$6) | H5: =IF(ISBLANK(Common!I$8),"",Common!I$8) | I5: =IF(ISBLANK(Common!K$8),"",Common!K$8) | J5: Benchmark | K5: =K4 -> 0 | L5: =Common!B19 -> 0 | M5: =M4 -> pH | N5: =N4 -> s.u. | O5: =IF(ISBLANK(Common!C19),"",Common!C19) | P5: 9 | Q5: 5.5
A6: =IF(ISBLANK(Common!C$2),"",Common!C$2) | B6: =IF(ISBLANK(Common!C$4),"",Common!C$4) | C6: =IF(ISBLANK(Common!C$6),"",Common!C$6) | D6: =IF(ISBLANK(Common!C$8),"",Common!C$8) | E6: =IF(ISBLANK(Common!I$2),"",Common!I$2) | F6: =IF(ISBLANK(Common!I$4),"",Common!I$4) | G6: =IF(ISBLANK(Common!I$6),"",Common!I$6) | H6: =IF(ISBLANK(Common!I$8),"",Common!I$8) | I6: =IF(ISBLANK(Common!K$8),"",Common!K$8) | J6: Benchmark | K6: =K5 -> 0 | L6: =L2 -> 0 | M6: =Common!D13 -> Suspended Solids, Total | N6: =Common!D14 -> mg/L | O6: =IF(ISBLANK(Common!D16),"",Common!D16) | P6: =Common!D$36 -> 50
A7: =IF(ISBLANK(Common!C$2),"",Common!C$2) | B7: =IF(ISBLANK(Common!C$4),"",Common!C$4) | C7: =IF(ISBLANK(Common!C$6),"",Common!C$6) | D7: =IF(ISBLANK(Common!C$8),"",Common!C$8) | E7: =IF(ISBLANK(Common!I$2),"",Common!I$2) | F7: =IF(ISBLANK(Common!I$4),"",Common!I$4) | G7: =IF(ISBLANK(Common!I$6),"",Common!I$6) | H7: =IF(ISBLANK(Common!I$8),"",Common!I$8) | I7: =IF(ISBLANK(Common!K$8),"",Common!K$8) | J7: Benchmark | K7: =K6 -> 0 | L7: =L3 -> 0 | M7: =M6 -> Suspended Solids, Total | N7: =N6 -> mg/L | O7: =IF(ISBLANK(Common!D17),"",Common!D17) | P7: =Common!D$36 -> 50
A8: =IF(ISBLANK(Common!C$2),"",Common!C$2) | B8: =IF(ISBLANK(Common!C$4),"",Common!C$4) | C8: =IF(ISBLANK(Common!C$6),"",Common!C$6) | D8: =IF(ISBLANK(Common!C$8),"",Common!C$8) | E8: =IF(ISBLANK(Common!I$2),"",Common!I$2) | F8: =IF(ISBLANK(Common!I$4),"",Common!I$4) | G8: =IF(ISBLANK(Common!I$6),"",Common!I$6) | H8: =IF(ISBLANK(Common!I$8),"",Common!I$8) | I8: =IF(ISBLANK(Common!K$8),"",Common!K$8) | J8: Benchmark | K8: =K7 -> 0 | L8: =L4 -> 0 | M8: =M7 -> Suspended Solids, Total | N8: =N7 -> mg/L | O8: =IF(ISBLANK(Common!D18),"",Common!D18) | P8: =Common!D$36 -> 50
A9: =IF(ISBLANK(Common!C$2),"",Common!C$2) | B9: =IF(ISBLANK(Common!C$4),"",Common!C$4) | C9: =IF(ISBLANK(Common!C$6),"",Common!C$6) | D9: =IF(ISBLANK(Common!C$8),"",Common!C$8) | E9: =IF(ISBLANK(Common!I$2),"",Common!I$2) | F9: =IF(ISBLANK(Common!I$4),"",Common!I$4) | G9: =IF(ISBLANK(Common!I$6),"",Common!I$6) | H9: =IF(ISBLANK(Common!I$8),"",Common!I$8) | I9: =IF(ISBLANK(Common!K$8),"",Common!K$8) | J9: Benchmark | K9: =K8 -> 0 | L9: =L5 -> 0 | M9: =M8 -> Suspended Solids, Total | N9: =N8 -> mg/L | O9: =IF(ISBLANK(Common!D19),"",Common!D19) | P9: =Common!D$36 -> 50
A10: =IF(ISBLANK(Common!C$2),"",Common!C$2) | B10: =IF(ISBLANK(Common!C$4),"",Common!C$4) | C10: =IF(ISBLANK(Common!C$6),"",Common!C$6) | D10: =IF(ISBLANK(Common!C$8),"",Common!C$8) | E10: =IF(ISBLANK(Common!I$2),"",Common!I$2) | F10: =IF(ISBLANK(Common!I$4),"",Common!I$4) | G10: =IF(ISBLANK(Common!I$6),"",Common!I$6) | H10: =IF(ISBLANK(Common!I$8),"",Common!I$8) | I10: =IF(ISBLANK(Common!K$8),"",Common!K$8) | J10: Benchmark | K10: =K9 -> 0 | L10: =L6 -> 0 | M10: =Common!E13 -> Oil and Grease, Total | N10: =Common!E14 -> mg/L | O10: =IF(ISBLANK(Common!E16),"",Common!E16) | P10: =Common!E$36 -> 10
A11: =IF(ISBLANK(Common!C$2),"",Common!C$2) | B11: =IF(ISBLANK(Common!C$4),"",Common!C$4) | C11: =IF(ISBLANK(Common!C$6),"",Common!C$6) | D11: =IF(ISBLANK(Common!C$8),"",Common!C$8) | E11: =IF(ISBLANK(Common!I$2),"",Common!I$2) | F11: =IF(ISBLANK(Common!I$4),"",Common!I$4) | G11: =IF(ISBLANK(Common!I$6),"",Common!I$6) | H11: =IF(ISBLANK(Common!I$8),"",Common!I$8) | I11: =IF(ISBLANK(Common!K$8),"",Common!K$8) | J11: Benchmark | K11: =K10 -> 0 | L11: =L7 -> 0 | M11: =M10 -> Oil and Grease, Total | N11: =N10 -> mg/L | O11: =IF(ISBLANK(Common!E17),"",Common!E17) | P11: =Common!E$36 -> 10
A12: =IF(ISBLANK(Common!C$2),"",Common!C$2) | B12: =IF(ISBLANK(Common!C$4),"",Common!C$4) | C12: =IF(ISBLANK(Common!C$6),"",Common!C$6) | D12: =IF(ISBLANK(Common!C$8),"",Common!C$8) | E12: =IF(ISBLANK(Common!I$2),"",Common!I$2) | F12: =IF(ISBLANK(Common!I$4),"",Common!I$4) | G12: =IF(ISBLANK(Common!I$6),"",Common!I$6) | H12: =IF(ISBLANK(Common!I$8),"",Common!I$8) | I12: =IF(ISBLANK(Common!K$8),"",Common!K$8) | J12: Benchmark | K12: =K11 -> 0 | L12: =L8 -> 0 | M12: =M11 -> Oil and Grease, Total | N12: =N11 -> mg/L | O12: =IF(ISBLANK(Common!E18),"",Common!E18) | P12: =Common!E$36 -> 10
A13: =IF(ISBLANK(Common!C$2),"",Common!C$2) | B13: =IF(ISBLANK(Common!C$4),"",Common!C$4) | C13: =IF(ISBLANK(Common!C$6),"",Common!C$6) | D13: =IF(ISBLANK(Common!C$8),"",Common!C$8) | E13: =IF(ISBLANK(Common!I$2),"",Common!I$2) | F13: =IF(ISBLANK(Common!I$4),"",Common!I$4) | G13: =IF(ISBLANK(Common!I$6),"",Common!I$6) | H13: =IF(ISBLANK(Common!I$8),"",Common!I$8) | I13: =IF(ISBLANK(Common!K$8),"",Common!K$8) | J13: Benchmark | K13: =K12 -> 0 | L13: =L9 -> 0 | M13: =M12 -> Oil and Grease, Total | N13: =N12 -> mg/L | O13: =IF(ISBLANK(Common!E19),"",Common!E19) | P13: =Common!E$36 -> 10
A14: =IF(ISBLANK(Common!C$2),"",Common!C$2) | B14: =IF(ISBLANK(Common!C$4),"",Common!C$4) | C14: =IF(ISBLANK(Common!C$6),"",Common!C$6) | D14: =IF(ISBLANK(Common!C$8),"",Common!C$8) | E14: =IF(ISBLANK(Common!I$2),"",Common!I$2) | F14: =IF(ISBLANK(Common!I$4),"",Common!I$4) | G14: =IF(ISBLANK(Common!I$6),"",Common!I$6) | H14: =IF(ISBLANK(Common!I$8),"",Common!I$8) | I14: =IF(ISBLANK(Common!K$8),"",Common!K$8) | J14: Benchmark | K14: =K13 -> 0 | L14: =L10 -> 0 | M14: =Common!F13 -> Copper, Total | N14: =Common!F14 -> mg/L | O14: =IF(ISBLANK(Common!F16),"",Common!F16) | P14: =Common!F$36 -> 0.036
A15: =IF(ISBLANK(Common!C$2),"",Common!C$2) | B15: =IF(ISBLANK(Common!C$4),"",Common!C$4) | C15: =IF(ISBLANK(Common!C$6),"",Common!C$6) | D15: =IF(ISBLANK(Common!C$8),"",Common!C$8) | E15: =IF(ISBLANK(Common!I$2),"",Common!I$2) | F15: =IF(ISBLANK(Common!I$4),"",Common!I$4) | G15: =IF(ISBLANK(Common!I$6),"",Common!I$6) | H15: =IF(ISBLANK(Common!I$8),"",Common!I$8) | I15: =IF(ISBLANK(Common!K$8),"",Common!K$8) | J15: Benchmark | K15: =K14 -> 0 | L15: =L11 -> 0 | M15: =M14 -> Copper, Total | N15: =N14 -> mg/L | O15: =IF(ISBLANK(Common!F17),"",Common!F17) | P15: =Common!F$36 -> 0.036
A16: =IF(ISBLANK(Common!C$2),"",Common!C$2) | B16: =IF(ISBLANK(Common!C$4),"",Common!C$4) | C16: =IF(ISBLANK(Common!C$6),"",Common!C$6) | D16: =IF(ISBLANK(Common!C$8),"",Common!C$8) | E16: =IF(ISBLANK(Common!I$2),"",Common!I$2) | F16: =IF(ISBLANK(Common!I$4),"",Common!I$4) | G16: =IF(ISBLANK(Common!I$6),"",Common!I$6) | H16: =IF(ISBLANK(Common!I$8),"",Common!I$8) | I16: =IF(ISBLANK(Common!K$8),"",Common!K$8) | J16: Benchmark | K16: =K15 -> 0 | L16: =L12 -> 0 | M16: =M15 -> Copper, Total | N16: =N15 -> mg/L | O16: =IF(ISBLANK(Common!F18),"",Common!F18) | P16: =Common!F$36 -> 0.036
A17: =IF(ISBLANK(Common!C$2),"",Common!C$2) | B17: =IF(ISBLANK(Common!C$4),"",Common!C$4) | C17: =IF(ISBLANK(Common!C$6),"",Common!C$6) | D17: =IF(ISBLANK(Common!C$8),"",Common!C$8) | E17: =IF(ISBLANK(Common!I$2),"",Common!I$2) | F17: =IF(ISBLANK(Common!I$4),"",Common!I$4) | G17: =IF(ISBLANK(Common!I$6),"",Common!I$6) | H17: =IF(ISBLANK(Common!I$8),"",Common!I$8) | I17: =IF(ISBLANK(Common!K$8),"",Common!K$8) | J17: Benchmark | K17: =K16 -> 0 | L17: =L13 -> 0 | M17: =M16 -> Copper, Total | N17: =N16 -> mg/L | O17: =IF(ISBLANK(Common!F19),"",Common!F19) | P17: =Common!F$36 -> 0.036
A18: =IF(ISBLANK(Common!C$2),"",Common!C$2) | B18: =IF(ISBLANK(Common!C$4),"",Common!C$4) | C18: =IF(ISBLANK(Common!C$6),"",Common!C$6) | D18: =IF(ISBLANK(Common!C$8),"",Common!C$8) | E18: =IF(ISBLANK(Common!I$2),"",Common!I$2) | F18: =IF(ISBLANK(Common!I$4),"",Common!I$4) | G18: =IF(ISBLANK(Common!I$6),"",Common!I$6) | H18: =IF(ISBLANK(Common!I$8),"",Common!I$8) | I18: =IF(ISBLANK(Common!K$8),"",Common!K$8) | J18: Benchmark | K18: =K17 -> 0 | L18: =L14 -> 0 | M18: =Common!G13 -> Lead, Total | N18: =Common!G14 -> mg/L | O18: =IF(ISBLANK(Common!G16),"",Common!G16) | P18: =Common!G$36 -> 0.06
A19: =IF(ISBLANK(Common!C$2),"",Common!C$2) | B19: =IF(ISBLANK(Common!C$4),"",Common!C$4) | C19: =IF(ISBLANK(Common!C$6),"",Common!C$6) | D19: =IF(ISBLANK(Common!C$8),"",Common!C$8) | E19: =IF(ISBLANK(Common!I$2),"",Common!I$2) | F19: =IF(ISBLANK(Common!I$4),"",Common!I$4) | G19: =IF(ISBLANK(Common!I$6),"",Common!I$6) | H19: =IF(ISBLANK(Common!I$8),"",Common!I$8) | I19: =IF(ISBLANK(Common!K$8),"",Common!K$8) | J19: Benchmark | K19: =K18 -> 0 | L19: =L15 -> 0 | M19: =M18 -> Lead, Total | N19: =N18 -> mg/L | O19: =IF(ISBLANK(Common!G17),"",Common!G17) | P19: =Common!G$36 -> 0.06
A20: =IF(ISBLANK(Common!C$2),"",Common!C$2) | B20: =IF(ISBLANK(Common!C$4),"",Common!C$4) | C20: =IF(ISBLANK(Common!C$6),"",Common!C$6) | D20: =IF(ISBLANK(Common!C$8),"",Common!C$8) | E20: =IF(ISBLANK(Common!I$2),"",Common!I$2) | F20: =IF(ISBLANK(Common!I$4),"",Common!I$4) | G20: =IF(ISBLANK(Common!I$6),"",Common!I$6) | H20: =IF(ISBLANK(Common!I$8),"",Common!I$8) | I20: =IF(ISBLANK(Common!K$8),"",Common!K$8) | J20: Benchmark | K20: =K19 -> 0 | L20: =L16 -> 0 | M20: =M19 -> Lead, Total | N20: =N19 -> mg/L | O20: =IF(ISBLANK(Common!G18),"",Common!G18) | P20: =Common!G$36 -> 0.06
A21: =IF(ISBLANK(Common!C$2),"",Common!C$2) | B21: =IF(ISBLANK(Common!C$4),"",Common!C$4) | C21: =IF(ISBLANK(Common!C$6),"",Common!C$6) | D21: =IF(ISBLANK(Common!C$8),"",Common!C$8) | E21: =IF(ISBLANK(Common!I$2),"",Common!I$2) | F21: =IF(ISBLANK(Common!I$4),"",Common!I$4) | G21: =IF(ISBLANK(Common!I$6),"",Common!I$6) | H21: =IF(ISBLANK(Common!I$8),"",Common!I$8) | I21: =IF(ISBLANK(Common!K$8),"",Common!K$8) | J21: Benchmark | K21: =K20 -> 0 | L21: =L17 -> 0 | M21: =M20 -> Lead, Total | N21: =N20 -> mg/L | O21: =IF(ISBLANK(Common!G19),"",Common!G19) | P21: =Common!G$36 -> 0.06
A22: =IF(ISBLANK(Common!C$2),"",Common!C$2) | B22: =IF(ISBLANK(Common!C$4),"",Common!C$4) | C22: =IF(ISBLANK(Common!C$6),"",Common!C$6) | D22: =IF(ISBLANK(Common!C$8),"",Common!C$8) | E22: =IF(ISBLANK(Common!I$2),"",Common!I$2) | F22: =IF(ISBLANK(Common!I$4),"",Common!I$4) | G22: =IF(ISBLANK(Common!I$6),"",Common!I$6) | H22: =IF(ISBLANK(Common!I$8),"",Common!I$8) | I22: =IF(ISBLANK(Common!K$8),"",Common!K$8) | J22: Benchmark | K22: =K21 -> 0 | L22: =L18 -> 0 | M22: =Common!H13 -> Zinc, Total | N22: =Common!H14 -> mg/L | O22: =IF(ISBLANK(Common!H16),"",Common!H16) | P22: =Common!H$36 -> 0.24
A23: =IF(ISBLANK(Common!C$2),"",Common!C$2) | B23: =IF(ISBLANK(Common!C$4),"",Common!C$4) | C23: =IF(ISBLANK(Common!C$6),"",Common!C$6) | D23: =IF(ISBLANK(Common!C$8),"",Common!C$8) | E23: =IF(ISBLANK(Common!I$2),"",Common!I$2) | F23: =IF(ISBLANK(Common!I$4),"",Common!I$4) | G23: =IF(ISBLANK(Common!I$6),"",Common!I$6) | H23: =IF(ISBLANK(Common!I$8),"",Common!I$8) | I23: =IF(ISBLANK(Common!K$8),"",Common!K$8) | J23: Benchmark | K23: =K22 -> 0 | L23: =L19 -> 0 | M23: =M22 -> Zinc, Total | N23: =N22 -> mg/L | O23: =IF(ISBLANK(Common!H17),"",Common!H17) | P23: =Common!H$36 -> 0.24
A24: =IF(ISBLANK(Common!C$2),"",Common!C$2) | B24: =IF(ISBLANK(Common!C$4),"",Common!C$4) | C24: =IF(ISBLANK(Common!C$6),"",Common!C$6) | D24: =IF(ISBLANK(Common!C$8),"",Common!C$8) | E24: =IF(ISBLANK(Common!I$2),"",Common!I$2) | F24: =IF(ISBLANK(Common!I$4),"",Common!I$4) | G24: =IF(ISBLANK(Common!I$6),"",Common!I$6) | H24: =IF(ISBLANK(Common!I$8),"",Common!I$8) | I24: =IF(ISBLANK(Common!K$8),"",Common!K$8) | J24: Benchmark | K24: =K23 -> 0 | L24: =L20 -> 0 | M24: =M23 -> Zinc, Total | N24: =N23 -> mg/L | O24: =IF(ISBLANK(Common!H18),"",Common!H18) | P24: =Common!H$36 -> 0.24
A25: =IF(ISBLANK(Common!C$2),"",Common!C$2) | B25: =IF(ISBLANK(Common!C$4),"",Common!C$4) | C25: =IF(ISBLANK(Common!C$6),"",Common!C$6) | D25: =IF(ISBLANK(Common!C$8),"",Common!C$8) | E25: =IF(ISBLANK(Common!I$2),"",Common!I$2) | F25: =IF(ISBLANK(Common!I$4),"",Common!I$4) | G25: =IF(ISBLANK(Common!I$6),"",Common!I$6) | H25: =IF(ISBLANK(Common!I$8),"",Common!I$8) | I25: =IF(ISBLANK(Common!K$8),"",Common!K$8) | J25: Benchmark | K25: =K24 -> 0 | L25: =L21 -> 0 | M25: =M24 -> Zinc, Total | N25: =N24 -> mg/L | O25: =IF(ISBLANK(Common!H19),"",Common!H19) | P25: =Common!H$36 -> 0.24
A26: =IF(ISBLANK(Common!C$2),"",Common!C$2) | B26: =IF(ISBLANK(Common!C$4),"",Common!C$4) | C26: =IF(ISBLANK(Common!C$6),"",Common!C$6) | D26: =IF(ISBLANK(Common!C$8),"",Common!C$8) | E26: =IF(ISBLANK(Common!I$2),"",Common!I$2) | F26: =IF(ISBLANK(Common!I$4),"",Common!I$4) | G26: =IF(ISBLANK(Common!I$6),"",Common!I$6) | H26: =IF(ISBLANK(Common!I$8),"",Common!I$8) | I26: =IF(ISBLANK(Common!K$8),"",Common!K$8) | J26: Benchmark | K26: =K25 -> 0 | L26: =L22 -> 0 | M26: =Common!I13 -> E. coli | N26: =Common!I14 -> counts/100 mL | O26: =IF(ISBLANK(Common!I16),"",Common!I16) | P26: =Common!I$36 -> 406
A27: =IF(ISBLANK(Common!C$2),"",Common!C$2) | B27: =IF(ISBLANK(Common!C$4),"",Common!C$4) | C27: =IF(ISBLANK(Common!C$6),"",Common!C$6) | D27: =IF(ISBLANK(Common!C$8),"",Common!C$8) | E27: =IF(ISBLANK(Common!I$2),"",Common!I$2) | F27: =IF(ISBLANK(Common!I$4),"",Common!I$4) | G27: =IF(ISBLANK(Common!I$6),"",Common!I$6) | H27: =IF(ISBLANK(Common!I$8),"",Common!I$8) | I27: =IF(ISBLANK(Common!K$8),"",Common!K$8) | J27: Benchmark | K27: =K26 -> 0 | L27: =L23 -> 0 | M27: =M26 -> E. coli | N27: =N26 -> counts/100 mL | O27: =IF(ISBLANK(Common!I17),"",Common!I17) | P27: =Common!I$36 -> 406
A28: =IF(ISBLANK(Common!C$2),"",Common!C$2) | B28: =IF(ISBLANK(Common!C$4),"",Common!C$4) | C28: =IF(ISBLANK(Common!C$6),"",Common!C$6) | D28: =IF(ISBLANK(Common!C$8),"",Common!C$8) | E28: =IF(ISBLANK(Common!I$2),"",Common!I$2) | F28: =IF(ISBLANK(Common!I$4),"",Common!I$4) | G28: =IF(ISBLANK(Common!I$6),"",Common!I$6) | H28: =IF(ISBLANK(Common!I$8),"",Common!I$8) | I28: =IF(ISBLANK(Common!K$8),"",Common!K$8) | J28: Benchmark | K28: =K27 -> 0 | L28: =L24 -> 0 | M28: =M27 -> E. coli | N28: =N27 -> counts/100 mL | O28: =IF(ISBLANK(Common!I18),"",Common!I18) | P28: =Common!I$36 -> 406
A29: =IF(ISBLANK(Common!C$2),"",Common!C$2) | B29: =IF(ISBLANK(Common!C$4),"",Common!C$4) | C29: =IF(ISBLANK(Common!C$6),"",Common!C$6) | D29: =IF(ISBLANK(Common!C$8),"",Common!C$8) | E29: =IF(ISBLANK(Common!I$2),"",Common!I$2) | F29: =IF(ISBLANK(Common!I$4),"",Common!I$4) | G29: =IF(ISBLANK(Common!I$6),"",Common!I$6) | H29: =IF(ISBLANK(Common!I$8),"",Common!I$8) | I29: =IF(ISBLANK(Common!K$8),"",Common!K$8) | J29: Benchmark | K29: =K28 -> 0 | L29: =L25 -> 0 | M29: =M28 -> E. coli | N29: =N28 -> counts/100 mL | O29: =IF(ISBLANK(Common!I19),"",Common!I19) | P29: =Common!I$36 -> 406
A30: =IF(ISBLANK(Common!C$2),"",Common!C$2) | B30: =IF(ISBLANK(Common!C$4),"",Common!C$4) | C30: =IF(ISBLANK(Common!C$6),"",Common!C$6) | D30: =IF(ISBLANK(Common!C$8),"",Common!C$8) | E30: =IF(ISBLANK(Common!I$2),"",Common!I$2) | F30: =IF(ISBLANK(Common!I$4),"",Common!I$4) | G30: =IF(ISBLANK(Common!I$6),"",Common!I$6) | H30: =IF(ISBLANK(Common!I$8),"",Common!I$8) | I30: =IF(ISBLANK(Common!K$8),"",Common!K$8) | J30: Benchmark | K30: =Common!A21 -> 0 | L30: =Common!B21 -> 0 | M30: =M2 -> pH | N30: =N2 -> s.u. | O30: =IF(ISBLANK(Common!C21),"",Common!C21) | P30: 9 | Q30: 5.5
A31: =IF(ISBLANK(Common!C$2),"",Common!C$2) | B31: =IF(ISBLANK(Common!C$4),"",Common!C$4) | C31: =IF(ISBLANK(Common!C$6),"",Common!C$6) | D31: =IF(ISBLANK(Common!C$8),"",Common!C$8) | E31: =IF(ISBLANK(Common!I$2),"",Common!I$2) | F31: =IF(ISBLANK(Common!I$4),"",Common!I$4) | G31: =IF(ISBLANK(Common!I$6),"",Common!I$6) | H31: =IF(ISBLANK(Common!I$8),"",Common!I$8) | I31: =IF(ISBLANK(Common!K$8),"",Common!K$8) | J31: Benchmark | K31: =K30 -> 0 | L31: =Common!B22 -> 0 | M31: =M3 -> pH | N31: =N3 -> s.u. | O31: =IF(ISBLANK(Common!C22),"",Common!C22) | P31: 9 | Q31: 5.5
A32: =IF(ISBLANK(Common!C$2),"",Common!C$2) | B32: =IF(ISBLANK(Common!C$4),"",Common!C$4) | C32: =IF(ISBLANK(Common!C$6),"",Common!C$6) | D32: =IF(ISBLANK(Common!C$8),"",Common!C$8) | E32: =IF(ISBLANK(Common!I$2),"",Common!I$2) | F32: =IF(ISBLANK(Common!I$4),"",Common!I$4) | G32: =IF(ISBLANK(Common!I$6),"",Common!I$6) | H32: =IF(ISBLANK(Common!I$8),"",Common!I$8) | I32: =IF(ISBLANK(Common!K$8),"",Common!K$8) | J32: Benchmark | K32: =K31 -> 0 | L32: =Common!B23 -> 0 | M32: =M4 -> pH | N32: =N4 -> s.u. | O32: =IF(ISBLANK(Common!C23),"",Common!C23) | P32: 9 | Q32: 5.5
A33: =IF(ISBLANK(Common!C$2),"",Common!C$2) | B33: =IF(ISBLANK(Common!C$4),"",Common!C$4) | C33: =IF(ISBLANK(Common!C$6),"",Common!C$6) | D33: =IF(ISBLANK(Common!C$8),"",Common!C$8) | E33: =IF(ISBLANK(Common!I$2),"",Common!I$2) | F33: =IF(ISBLANK(Common!I$4),"",Common!I$4) | G33: =IF(ISBLANK(Common!I$6),"",Common!I$6) | H33: =IF(ISBLANK(Common!I$8),"",Common!I$8) | I33: =IF(ISBLANK(Common!K$8),"",Common!K$8) | J33: Benchmark | K33: =K32 -> 0 | L33: =Common!B24 -> 0 | M33: =M5 -> pH | N33: =N5 -> s.u. | O33: =IF(ISBLANK(Common!C24),"",Common!C24) | P33: 9 | Q33: 5.5
A34: =IF(ISBLANK(Common!C$2),"",Common!C$2) | B34: =IF(ISBLANK(Common!C$4),"",Common!C$4) | C34: =IF(ISBLANK(Common!C$6),"",Common!C$6) | D34: =IF(ISBLANK(Common!C$8),"",Common!C$8) | E34: =IF(ISBLANK(Common!I$2),"",Common!I$2) | F34: =IF(ISBLANK(Common!I$4),"",Common!I$4) | G34: =IF(ISBLANK(Common!I$6),"",Common!I$6) | H34: =IF(ISBLANK(Common!I$8),"",Common!I$8) | I34: =IF(ISBLANK(Common!K$8),"",Common!K$8) | J34: Benchmark | K34: =K33 -> 0 | L34: =L30 -> 0 | M34: =M6 -> Suspended Solids, Total | N34: =N6 -> mg/L | O34: =IF(ISBLANK(Common!D21),"",Common!D21) | P34: =Common!D$36 -> 50
A35: =IF(ISBLANK(Common!C$2),"",Common!C$2) | B35: =IF(ISBLANK(Common!C$4),"",Common!C$4) | C35: =IF(ISBLANK(Common!C$6),"",Common!C$6) | D35: =IF(ISBLANK(Common!C$8),"",Common!C$8) | E35: =IF(ISBLANK(Common!I$2),"",Common!I$2) | F35: =IF(ISBLANK(Common!I$4),"",Common!I$4) | G35: =IF(ISBLANK(Common!I$6),"",Common!I$6) | H35: =IF(ISBLANK(Common!I$8),"",Common!I$8) | I35: =IF(ISBLANK(Common!K$8),"",Common!K$8) | J35: Benchmark | K35: =K34 -> 0 | L35: =L31 -> 0 | M35: =M7 -> Suspended Solids, Total | N35: =N7 -> mg/L | O35: =IF(ISBLANK(Common!D22),"",Common!D22) | P35: =Common!D$36 -> 50
A36: =IF(ISBLANK(Common!C$2),"",Common!C$2) | B36: =IF(ISBLANK(Common!C$4),"",Common!C$4) | C36: =IF(ISBLANK(Common!C$6),"",Common!C$6) | D36: =IF(ISBLANK(Common!C$8),"",Common!C$8) | E36: =IF(ISBLANK(Common!I$2),"",Common!I$2) | F36: =IF(ISBLANK(Common!I$4),"",Common!I$4) | G36: =IF(ISBLANK(Common!I$6),"",Common!I$6) | H36: =IF(ISBLANK(Common!I$8),"",Common!I$8) | I36: =IF(ISBLANK(Common!K$8),"",Common!K$8) | J36: Benchmark | K36: =K35 -> 0 | L36: =L32 -> 0 | M36: =M8 -> Suspended Solids, Total | N36: =N8 -> mg/L | O36: =IF(ISBLANK(Common!D23),"",Common!D23) | P36: =Common!D$36 -> 50
A37: =IF(ISBLANK(Common!C$2),"",Common!C$2) | B37: =IF(ISBLANK(Common!C$4),"",Common!C$4) | C37: =IF(ISBLANK(Common!C$6),"",Common!C$6) | D37: =IF(ISBLANK(Common!C$8),"",Common!C$8) | E37: =IF(ISBLANK(Common!I$2),"",Common!I$2) | F37: =IF(ISBLANK(Common!I$4),"",Common!I$4) | G37: =IF(ISBLANK(Common!I$6),"",Common!I$6) | H37: =IF(ISBLANK(Common!I$8),"",Common!I$8) | I37: =IF(ISBLANK(Common!K$8),"",Common!K$8) | J37: Benchmark | K37: =K36 -> 0 | L37: =L33 -> 0 | M37: =M9 -> Suspended Solids, Total | N37: =N9 -> mg/L | O37: =IF(ISBLANK(Common!D24),"",Common!D24) | P37: =Common!D$36 -> 50
A38: =IF(ISBLANK(Common!C$2),"",Common!C$2) | B38: =IF(ISBLANK(Common!C$4),"",Common!C$4) | C38: =IF(ISBLANK(Common!C$6),"",Common!C$6) | D38: =IF(ISBLANK(Common!C$8),"",Common!C$8) | E38: =IF(ISBLANK(Common!I$2),"",Common!I$2) | F38: =IF(ISBLANK(Common!I$4),"",Common!I$4) | G38: =IF(ISBLANK(Common!I$6),"",Common!I$6) | H38: =IF(ISBLANK(Common!I$8),"",Common!I$8) | I38: =IF(ISBLANK(Common!K$8),"",Common!K$8) | J38: Benchmark | K38: =K37 -> 0 | L38: =L34 -> 0 | M38: =M10 -> Oil and Grease, Total | N38: =N10 -> mg/L | O38: =IF(ISBLANK(Common!E21),"",Common!E21) | P38: =Common!E$36 -> 10
A39: =IF(ISBLANK(Common!C$2),"",Common!C$2) | B39: =IF(ISBLANK(Common!C$4),"",Common!C$4) | C39: =IF(ISBLANK(Common!C$6),"",Common!C$6) | D39: =IF(ISBLANK(Common!C$8),"",Common!C$8) | E39: =IF(ISBLANK(Common!I$2),"",Common!I$2) | F39: =IF(ISBLANK(Common!I$4),"",Common!I$4) | G39: =IF(ISBLANK(Common!I$6),"",Common!I$6) | H39: =IF(ISBLANK(Common!I$8),"",Common!I$8) | I39: =IF(ISBLANK(Common!K$8),"",Common!K$8) | J39: Benchmark | K39: =K38 -> 0 | L39: =L35 -> 0 | M39: =M11 -> Oil and Grease, Total | N39: =N11 -> mg/L | O39: =IF(ISBLANK(Common!E22),"",Common!E22) | P39: =Common!E$36 -> 10
