Workbook
Name LicenseType: Sheet1!$B$3:$B$5
Name ProdSource: Sheet1!$B$7:$B$8

Sheet  Deliverables
C1: Replacement Deliverables Price Sheet
B3: PHASE I – PROJECT PLANNING
B4: Number | C4: Deliverable | F4: Total Cost | G4: SFY2014 | H4: SFY2015 | I4: SFY2016 | J4: SFY2017 | K4: SFY2018 | L4: SFY2019 | M4: SFY2020 | N4: SFY2021
B5: 1 | C5: Project Facility Plan - Data Center | F5: =SUM(G5:N5) -> 0
B6: =B5+1 -> 2 | C6: Infrastructure Assets Inventory | F6: =SUM(G6:N6) -> 0
B7: =B6+1 -> 3 | C7: Computing Environment Plan | F7: =SUM(G7:N7) -> 0
B8: =B7+1 -> 4 | C8: Project Facility Plan - DDI Project Office | F8: =SUM(G8:N8) -> 0
B9: =B8+1 -> 5 | C9: Project Facility Plan - Operations | F9: =SUM(G9:N9) -> 0
B10: =B9+1 -> 6 | C10: Project Management Plan | F10: =SUM(G10:N10) -> 0
B11: =B10+1 -> 7 | C11: Incoming Orientation Plan | F11: =SUM(G11:N11) -> 0
B12: =B11+1 -> 8 | C12: Requirements Traceability Matrix (RTM) | F12: =SUM(G12:N12) -> 0
B13: =B12+1 -> 9 | C13: Training Master Plan | F13: =SUM(G13:N13) -> 0
B14: =B13+1 -> 10 | C14: Staffing Master Plan | F14: =SUM(G14:N14) -> 0
B15: =B14+1 -> 11 | C15: Performance Management Plan | F15: =SUM(G15:N15) -> 0
B16: =B15+1 -> 12 | C16: Data Center Computing Environment Specifications Plan | F16: =SUM(G16:N16) -> 0
B17: =B16+1 -> 13 | C17: Systems Engineering Management Plan (SEMP) | F17: =SUM(G17:N17) -> 0
... B22: =B21+1 -> 18 | C22: Phase 1 Completion Report | F22: =SUM(G22:N22) -> 0
B23: Phase I Subtotal | F23: =SUM(F5:F22) -> 0 | G23: =SUM(G5:G22) -> 0 | H23: =SUM(H5:H22) -> 0 | I23: =SUM(I5:I22) -> 0 | J23: =SUM(J5:J22) -> 0 | K23: =SUM(K5:K22) -> 0 | L23: =SUM(L5:L22) -> 0 | M23: =SUM(M5:M22) -> 0 | N23: =SUM(N5:N22) -> 0
B24: Phase II - DEVELOPMENT, CONFIGURATION, AND UAT TEST
B25: Number | C25: Deliverable | F25: Total Cost | G25: SFY2014 | H25: SFY2015 | I25: SFY2016 | J25: SFY2017 | K25: SFY2018 | L25: SFY2019 | M25: SFY2020 | N25: SFY2021
B26: =B22+1 -> 19 | C26: Technical Architecture | F26: =SUM(G26:N26) -> 0
B27: =B26+1 -> 20 | C27: Information Architecture | F27: =SUM(G27:N27) -> 0
B28: =B27+1 -> 21 | C28: Business Architecture | F28: =SUM(G28:N28) -> 0
B29: =B28+1 -> 22 | C29: End-to-End Integration Test | F29: =SUM(G29:N29) -> 0
B30: =B29+1 -> 23 | C30: User Acceptance Test | F30: =SUM(G30:N30) -> 0
B31: Phase II Subtotal | F31: =SUM(F26:F30) -> 0 | G31: =SUM(G26:G30) -> 0 | H31: =SUM(H26:H30) -> 0 | I31: =SUM(I26:I30) -> 0 | J31: =SUM(J26:J30) -> 0 | K31: =SUM(K26:K30) -> 0 | L31: =SUM(L26:L30) -> 0 | M31: =SUM(M26:M30) -> 0 | N31: =SUM(N26:N30) -> 0
B32: Phase III Operations Readiness, Production Cutover, and Facilities Rollout
B33: Number | C33: Deliverable | F33: Total Cost | G33: SFY2014 | H33: SFY2015 | I33: SFY2016 | J33: SFY2017 | K33: SFY2018 | L33: SFY2019 | M33: SFY2020 | N33: SFY2021
B34: =B30+1 -> 24 | C34: Implementation Master Plan | F34: =SUM(G34:N34) -> 0
B35: =B34+1 -> 25 | C35: Detailed Training Plan | F35: =SUM(G35:N35) -> 0
B36: =B35+1 -> 26 | C36: Detailed Data Conversion Plan | F36: =SUM(G36:N36) -> 0
B37: =B36+1 -> 27 | C37: Detailed End-to-End Integraion | F37: =SUM(G37:N37) -> 0
B38: =B37+1 -> 28 | C38: Detailed User Acceptance Test Plan | F38: =SUM(G38:N38) -> 0
B39: =B38+1 -> 29 | C39: Detailed Performance Management Plan (Operations) | F39: =SUM(G39:N39) -> 0
B40: =B39+1 -> 30 | C40: Detailed Operations Readiness Review Plan | F40: =SUM(G40:N40) -> 0
B41: =B40+1 -> 31 | C41: Operations Readiness Report and State Approvals | F41: =SUM(G41:N41) -> 0
B42: =B41+1 -> 32 | C42: Final Acceptance Certification | F42: =SUM(G42:N42) -> 0
B43: Phase III Subtotal | F43: =SUM(F34:F42) -> 0 | G43: =SUM(G34:G42) -> 0 | H43: =SUM(H34:H42) -> 0 | I43: =SUM(I34:I42) -> 0 | J43: =SUM(J34:J42) -> 0 | K43: =SUM(K34:K42) -> 0 | L43: =SUM(L34:L42) -> 0 | M43: =SUM(M34:M42) -> 0 | N43: =SUM(N34:N42) -> 0
B44: Phase V Operations and CMS Certification
B45: Number | C45: Deliverable | F45: Total Cost | G45: SFY2014 | H45: SFY2015 | I45: SFY2016 | J45: SFY2017 | K45: SFY2018 | L45: SFY2019 | M45: SFY2020 | N45: SFY2021
...

Sheet DevelopmentFacility
B1: Replacement Development Facility Price Sheet
B3: Item Number | C3: Description | D3: SFY2014 | E3: SFY2015 | F3: SFY2016 | G3: SFY2017 | H3: SFY2018 | I3: SFY2019 | J3: SFY2020 | K3: SFY2021 | L3: TOTAL
B4: DEV.1 | C4: Development Facility | L4: =SUM(D4:K4) -> 0
B5: DEV.3 | C5: Data Center (Vendor Facility) | L5: =SUM(D5:K5) -> 0
B6: DEV.4 | C6: Installation/Configuration Costs | L6: =SUM(D6:K6) -> 0
B7: DEV.4.1 | C7: Facility Build-Out | L7: =SUM(D7:K7) -> 0
B8: Total by SFY | D8: =SUM(D4:D7) -> 0 | E8: =SUM(E4:E7) -> 0 | F8: =SUM(F4:F7) -> 0 | G8: =SUM(G4:G7) -> 0 | H8: =SUM(H4:H7) -> 0 | I8: =SUM(I4:I7) -> 0 | J8: =SUM(J4:J7) -> 0 | K8: =SUM(K4:K7) -> 0 | L8: =SUM(L4:L7) -> 0

Sheet Hardware
C1: Replacement Hardware Price Sheet
B3: CI Number | C3: Hardware Product | D3: Number of Licenses | E3: COTS or Proprietary | F3: Purchase Cost | O3: Annual Maintenance Fee*
F4: Total Cost | G4: SFY2014 | H4: SFY2015 | I4: SFY2016 | J4: SFY2017 | K4: SFY2018 | L4: SFY2019 | M4: SFY2020 | N4: SFY2021 | O4: Total Cost | P4: SFY2014 | Q4: SFY2015 | R4: SFY2016 | S4: SFY2017 | T4: SFY2018 | U4: SFY2019 | V4: SFY2020 | W4: SFY2021
F5: =SUM(G5:N5) -> 0 | O5: =SUM(P5:W5) -> 0
F6: =SUM(G6:N6) -> 0 | O6: =SUM(P6:W6) -> 0
F7: =SUM(G7:N7) -> 0 | O7: =SUM(P7:W7) -> 0
F8: =SUM(G8:N8) -> 0 | O8: =SUM(P8:W8) -> 0
F9: =SUM(G9:N9) -> 0 | O9: =SUM(P9:W9) -> 0
F10: =SUM(G10:N10) -> 0 | O10: =SUM(P10:W10) -> 0
F11: =SUM(G11:N11) -> 0 | O11: =SUM(P11:W11) -> 0
F12: =SUM(G12:N12) -> 0 | O12: =SUM(P12:W12) -> 0
F13: =SUM(G13:N13) -> 0 | O13: =SUM(P13:W13) -> 0
F14: =SUM(G14:N14) -> 0 | O14: =SUM(P14:W14) -> 0
F15: =SUM(G15:N15) -> 0 | O15: =SUM(P15:W15) -> 0
F16: =SUM(G16:N16) -> 0 | O16: =SUM(P16:W16) -> 0
... F43: =SUM(G43:N43) -> 0 | O43: =SUM(P43:W43) -> 0
B44: Total | F44: =SUM(F5:F43) -> 0 | G44: =SUM(G5:G43) -> 0 | H44: =SUM(H5:H43) -> 0 | I44: =SUM(I5:I43) -> 0 | J44: =SUM(J5:J43) -> 0 | K44: =SUM(K5:K43) -> 0 | L44: =SUM(L5:L43) -> 0 | M44: =SUM(M5:M43) -> 0 | ... W44: =SUM(W5:W43) -> 0

Sheet Software
C1: Replacement Software Price Sheet
B3: CI Number | C3: Software Product | D3: Number of Licenses | E3: License Type | F3: COTS or Proprietary | G3: Purchase Cost | P3: Annual Maintenance Fee*
G4: Total Cost | H4: SFY2014 | I4: SFY2015 | J4: SFY2016 | K4: SFY2017 | L4: SFY2018 | M4: SFY2019 | N4: SFY2020 | O4: SFY2021 | P4: Total Cost | Q4: SFY2014 | R4: SFY2015 | S4: SFY2016 | T4: SFY2017 | U4: SFY2018 | V4: SFY2019 | W4: SFY2020 | X4: SFY2021
G5: =SUM(H5:O5) -> 0 | P5: =SUM(Q5:X5) -> 0
G6: =SUM(H6:O6) -> 0 | P6: =SUM(Q6:X6) -> 0
G7: =SUM(H7:O7) -> 0 | P7: =SUM(Q7:X7) -> 0
G8: =SUM(H8:O8) -> 0 | P8: =SUM(Q8:X8) -> 0
G9: =SUM(H9:O9) -> 0 | P9: =SUM(Q9:X9) -> 0
G10: =SUM(H10:O10) -> 0 | P10: =SUM(Q10:X10) -> 0
G11: =SUM(H11:O11) -> 0 | P11: =SUM(Q11:X11) -> 0
G12: =SUM(H12:O12) -> 0 | P12: =SUM(Q12:X12) -> 0
G13: =SUM(H13:O13) -> 0 | P13: =SUM(Q13:X13) -> 0
G14: =SUM(H14:O14) -> 0 | P14: =SUM(Q14:X14) -> 0
G15: =SUM(H15:O15) -> 0 | P15: =SUM(Q15:X15) -> 0
G16: =SUM(H16:O16) -> 0 | P16: =SUM(Q16:X16) -> 0
... G46: =SUM(H46:O46) -> 0 | P46: =SUM(Q46:X46) -> 0
B47: Total | G47: =SUM(G5:G46) -> 0 | H47: =SUM(H5:H46) -> 0 | I47: =SUM(I5:I46) -> 0 | J47: =SUM(J5:J46) -> 0 | K47: =SUM(K5:K46) -> 0 | L47: =SUM(L5:L46) -> 0 | M47: =SUM(M5:M46) -> 0 | N47: =SUM(N5:N46) -> 0 | O47: =SUM(O5:O46) -> 0 | P47: =SUM(P4:P46) -> 0 | Q47: =SUM(Q5:Q46) -> 0 | R47: =SUM(R5:R46) -> 0 | S47: =SUM(S5:S46) -> 0 | T47: =SUM(T5:T46) -> 0 | U47: =SUM(U5:U46) -> 0 | V47: =SUM(V5:V46) -> 0 | W47: =SUM(W5:W46) -> 0 | X47: =SUM(X5:X46) -> 0

Sheet Labor Rates
C1: Replacement Labor Rates Price Sheet
B3: Item Number | C3: Labor Category | D3: Hourly Rate
D4: Base Year | E4: Renewal Year 1 | F4: Renewal Year 2 | G4: Renewal Year 3 | H4: Renewal Year 4 | I4: Renewal Year 5 | J4: Renewal Year 6
B5: 1
B6: =B5+1 -> 2
B7: =B6+1 -> 3
B8: =B7+1 -> 4
B9: =B8+1 -> 5
B10: =B9+1 -> 6
B11: =B10+1 -> 7
B12: =B11+1 -> 8
B13: =B12+1 -> 9
B14: =B13+1 -> 10
B15: =B14+1 -> 11
B16: =B15+1 -> 12
B17: =B16+1 -> 13
... B37: =B36+1 -> 33

Sheet Operations
B1: Replacement Operations Price Sheet
B3: Line Item Description | C3: SFY2014 | D3: SFY2015 | E3: SFY2016 | F3: SFY2017 | G3: SFY2018 | H3: SFY2019 | I3: SFY2020 | J3: SFY2021 | K3: Total
B4: Operations Before Contract Month 15
B5: Salaries and Benefits | K5: =SUM(C5:J5) -> 0
B6: Administrative Overhead | K6: =SUM(C6:J6) -> 0
B7: Other Costs (itemized in the following rows)
B8: Data Center (State Facility) | K8: =SUM(C8:J8) -> 0
B9: Data Center (Vendor Facility) | K9: =SUM(C9:J9) -> 0
B10: Operations Office Spaces | K10: =SUM(C10:J10) -> 0
B11: Operations Facility Build Out | K11: =SUM(C11:J11) -> 0
B12: Miscellaneous Costs | K12: =SUM(C12:J12) -> 0
B13: Operations less Facility Costs | C13: =SUM(C5:C12) - SUM(C8:C11) -> 0 | D13: =SUM(D5:D12) - SUM(D8:D11) -> 0 | E13: =SUM(E5:E12) - SUM(E8:E11) -> 0 | F13: =SUM(F5:F12) - SUM(F8:F11) -> 0 | G13: =SUM(G5:G12) - SUM(G8:G11) -> 0 | H13: =SUM(H5:H12) - SUM(H8:H11) -> 0 | I13: =SUM(I5:I12) - SUM(I8:I11) -> 0 | J13: =SUM(J5:J12) - SUM(J8:J11) -> 0 | K13: =SUM(K5:K12) - SUM(K8:K11) -> 0
B14: Total | C14: =SUM(C5:C12) -> 0 | D14: =SUM(D5:D12) -> 0 | E14: =SUM(E5:E12) -> 0 | F14: =SUM(F5:F12) -> 0 | G14: =SUM(G5:G12) -> 0 | H14: =SUM(H5:H12) -> 0 | I14: =SUM(I5:I12) -> 0 | J14: =SUM(J5:J12) -> 0 | K14: =SUM(K5:K12) -> 0
B15: Operations Starting in Contract Month 15
B16: Salaries and Benefits | K16: =SUM(C16:J16) -> 0
B17: Administrative Overhead | K17: =SUM(C17:J17) -> 0
B18: Other Costs (itemized in the following rows)
B19: Data Center (State Facility) | K19: =SUM(C19:J19) -> 0
B20: Data Center (Vendor Facility) | K20: =SUM(C20:J20) -> 0
B21: Operations Office Spaces | K21: =SUM(C21:J21) -> 0
B22: Operations Facility Build Out | K22: =SUM(C22:J22) -> 0
B23: Miscellaneous Costs | K23: =SUM(C23:J23) -> 0
B24: Operations less Facility Costs | C24: =SUM(C16:C23) - SUM(C19:C22) -> 0 | D24: =SUM(D16:D23) - SUM(D19:D22) -> 0 | E24: =SUM(E16:E23) - SUM(E19:E22) -> 0 | F24: =SUM(F16:F23) - SUM(F19:F22) -> 0 | G24: =SUM(G16:G23) - SUM(G19:G22) -> 0 | H24: =SUM(H16:H23) - SUM(H19:H22) -> 0 | I24: =SUM(I16:I23) - SUM(I19:I22) -> 0 | J24: =SUM(J16:J23) - SUM(J19:J22) -> 0 | K24: =SUM(K16:K23) - SUM(K19:K22) -> 0
B25: Total | C25: =SUM(C16:C23) -> 0 | D25: =SUM(D16:D23) -> 0 | E25: =SUM(E16:E23) -> 0 | F25: =SUM(F16:F23) -> 0 | G25: =SUM(G16:G23) -> 0 | H25: =SUM(H16:H23) -> 0 | I25: =SUM(I16:I23) -> 0 | J25: =SUM(J16:J23) -> 0 | K25: =SUM(K16:K23) -> 0

Sheet Summary
B1: Replacement Summary Price Sheet
B3: Design Development and Implementation (DDI)
B4: DDI - Deliverables | C4: Total | D4: SFY2014 | E4: SFY2015 | F4: SFY2016 | G4: SFY2017 | H4: SFY2018 | I4: SFY2019 | J4: SFY2020 | K4: SFY2021
B5: Phase I | C5: =' Deliverables'!F23 -> 0 | D5: =' Deliverables'!G23 -> 0 | E5: =' Deliverables'!H23 -> 0 | F5: =' Deliverables'!I23 -> 0 | G5: =' Deliverables'!J23 -> 0 | H5: =' Deliverables'!K23 -> 0 | I5: =' Deliverables'!L23 -> 0 | J5: =' Deliverables'!M23 -> 0 | K5: =' Deliverables'!N23 -> 0
B6: Phase II | C6: =' Deliverables'!F31 -> 0 | D6: =' Deliverables'!G31 -> 0 | E6: =' Deliverables'!H31 -> 0 | F6: =' Deliverables'!I31 -> 0 | G6: =' Deliverables'!J31 -> 0 | H6: =' Deliverables'!K31 -> 0 | I6: =' Deliverables'!L31 -> 0 | J6: =' Deliverables'!M31 -> 0 | K6: =' Deliverables'!N31 -> 0
B7: Phase III | C7: =' Deliverables'!F43 -> 0 | D7: =' Deliverables'!G43 -> 0 | E7: =' Deliverables'!H43 -> 0 | F7: =' Deliverables'!I43 -> 0 | G7: =' Deliverables'!J43 -> 0 | H7: =' Deliverables'!K43 -> 0 | I7: =' Deliverables'!L43 -> 0 | J7: =' Deliverables'!M43 -> 0 | K7: =' Deliverables'!N43 -> 0
B8: Subtotal | C8: =SUM(C5:C7) -> 0 | D8: =SUM(D5:D7) -> 0 | E8: =SUM(E5:E7) -> 0 | F8: =SUM(F5:F7) -> 0 | G8: =SUM(G5:G7) -> 0 | H8: =SUM(H5:H7) -> 0 | I8: =SUM(I5:I7) -> 0 | J8: =SUM(J5:J7) -> 0 | K8: =SUM(K5:K7) -> 0
B9: DDI - Facilities | C9: Total | D9: SFY2014 | E9: SFY2015 | F9: SFY2016 | G9: SFY2017 | H9: SFY2018 | I9: SFY2019 | J9: SFY2020 | K9: SFY2021
B10: Development Facility | C10: =DevelopmentFacility!L4 -> 0 | D10: =DevelopmentFacility!D4 -> 0 | E10: =DevelopmentFacility!E4 -> 0 | F10: =DevelopmentFacility!F4 -> 0 | G10: =DevelopmentFacility!G4 -> 0 | H10: =DevelopmentFacility!H4 -> 0 | I10: =DevelopmentFacility!I4 -> 0 | J10: =DevelopmentFacility!J4 -> 0 | K10: =DevelopmentFacility!K4 -> 0
B11: Data Center (Vendor Facility) | C11: =DevelopmentFacility!L5 -> 0 | D11: =DevelopmentFacility!D5 -> 0 | E11: =DevelopmentFacility!E5 -> 0 | F11: =DevelopmentFacility!F5 -> 0 | G11: =DevelopmentFacility!G5 -> 0 | H11: =DevelopmentFacility!H5 -> 0 | I11: =DevelopmentFacility!I5 -> 0 | J11: =DevelopmentFacility!J5 -> 0 | K11: =DevelopmentFacility!K5 -> 0
B12: Installation/Configuration Costs (State Facility) | C12: =DevelopmentFacility!L6 -> 0 | D12: =DevelopmentFacility!D6 -> 0 | E12: =DevelopmentFacility!E6 -> 0 | F12: =DevelopmentFacility!F6 -> 0 | G12: =DevelopmentFacility!G6 -> 0 | H12: =DevelopmentFacility!H6 -> 0 | I12: =DevelopmentFacility!I6 -> 0 | J12: =DevelopmentFacility!J6 -> 0 | K12: =DevelopmentFacility!K6 -> 0
B13: Facility Build-Out | C13: =DevelopmentFacility!L7 -> 0 | D13: =DevelopmentFacility!D7 -> 0 | E13: =DevelopmentFacility!E7 -> 0 | F13: =DevelopmentFacility!F7 -> 0 | G13: =DevelopmentFacility!G7 -> 0 | H13: =DevelopmentFacility!H7 -> 0 | I13: =DevelopmentFacility!I7 -> 0 | J13: =DevelopmentFacility!J7 -> 0 | K13: =DevelopmentFacility!K7 -> 0
B14: Subtotal | C14: =SUM(C10:C13) -> 0 | D14: =SUM(D10:D13) -> 0 | E14: =SUM(E10:E13) -> 0 | F14: =SUM(F10:F13) -> 0 | G14: =SUM(G10:G13) -> 0 | H14: =SUM(H10:H13) -> 0 | I14: =SUM(I10:I13) -> 0 | J14: =SUM(J10:J13) -> 0 | K14: =SUM(K10:K13) -> 0
B15: Hardware | C15: Total | D15: SFY2014 | E15: SFY2015 | F15: SFY2016 | G15: SFY2017 | H15: SFY2018 | I15: SFY2019 | J15: SFY2020 | K15: SFY2021
B16: Total Cost | C16: =Hardware!F44 -> 0 | D16: =Hardware!G44 -> 0 | E16: =Hardware!H44 -> 0 | F16: =Hardware!I44 -> 0 | G16: =Hardware!J44 -> 0 | H16: =Hardware!K44 -> 0 | I16: =Hardware!L44 -> 0 | J16: =Hardware!M44 -> 0 | K16: =Hardware!N44 -> 0
B17: Maintenance Fee | C17: =Hardware!O44 -> 0 | D17: =Hardware!P44 -> 0 | E17: =Hardware!Q44 -> 0 | F17: =Hardware!R44 -> 0 | G17: =Hardware!S44 -> 0 | H17: =Hardware!T44 -> 0 | I17: =Hardware!U44 -> 0 | J17: =Hardware!V44 -> 0 | K17: =Hardware!W44 -> 0
B18: Subtotal | C18: =SUM(C16:C17) -> 0 | D18: =SUM(D16:D17) -> 0 | E18: =SUM(E16:E17) -> 0 | F18: =SUM(F16:F17) -> 0 | G18: =SUM(G16:G17) -> 0 | H18: =SUM(H16:H17) -> 0 | I18: =SUM(I16:I17) -> 0 | J18: =SUM(J16:J17) -> 0 | K18: =SUM(K16:K17) -> 0
B19: Software | C19: Total | D19: SFY2014 | E19: SFY2015 | F19: SFY2016 | G19: SFY2017 | H19: SFY2018 | I19: SFY2019 | J19: SFY2020 | K19: SFY2021
B20: Total Cost | C20: =Software!G47 -> 0 | D20: =Software!H47 -> 0 | E20: =Software!I47 -> 0 | F20: =Software!J47 -> 0 | G20: =Software!K47 -> 0 | H20: =Software!L47 -> 0 | I20: =Software!M47 -> 0 | J20: =Software!N47 -> 0 | K20: =Software!O47 -> 0
B21: Maintenance Fee | C21: =Software!P47 -> 0 | D21: =Software!Q47 -> 0 | E21: =Software!R47 -> 0 | F21: =Software!S47 -> 0 | G21: =Software!T47 -> 0 | H21: =Software!U47 -> 0 | I21: =Software!V47 -> 0 | J21: =Software!W47 -> 0 | K21: =Software!X47 -> 0
B22: Subtotal | C22: =SUM(C20:C21) -> 0 | D22: =SUM(D20:D21) -> 0 | E22: =SUM(E20:E21) -> 0 | F22: =SUM(F20:F21) -> 0 | G22: =SUM(G20:G21) -> 0 | H22: =SUM(H20:H21) -> 0 | I22: =SUM(I20:I21) -> 0 | J22: =SUM(J20:J21) -> 0 | K22: =SUM(K20:K21) -> 0
B23: Total DDI Cost | C23: =C8+C14+C18+C22 -> 0 | D23: =D8+D14+D18+D22 -> 0 | E23: =E8+E14+E18+E22 -> 0 | F23: =F8+F14+F18+F22 -> 0 | G23: =G8+G14+G18+G22 -> 0 | H23: =H8+H14+H18+H22 -> 0 | I23: =I8+I14+I18+I22 -> 0 | J23: =J8+J14+J18+J22 -> 0 | K23: =K8+K14+K18+K22 -> 0
B24: Operations
C25: TOTAL | D25: SFY2014 | E25: SFY2015 | F25: SFY2016 | G25: SFY2017 | H25: SFY2018 | I25: SFY2019 | J25: SFY2020 | K25: SFY2021
B26: Deliverables | C26: =SUM(D26:K26) -> 0 | D26: =' Deliverables'!G47+' Deliverables'!G54 -> 0 | E26: =' Deliverables'!H47+' Deliverables'!H54 -> 0 | F26: =' Deliverables'!I47+' Deliverables'!I54 -> 0 | G26: =' Deliverables'!J47+' Deliverables'!J54 -> 0 | H26: =' Deliverables'!K47+' Deliverables'!K54 -> 0 | I26: =' Deliverables'!L47+' Deliverables'!L54 -> 0 | J26: =' Deliverables'!M47+' Deliverables'!M54 -> 0 | K26: =' Deliverables'!N47+' Deliverables'!N54 -> 0
B27: Operations beginning before Month 15
B28: Facilities | C28: =SUM(D28:K28) -> 0 | D28: =SUM(Operations!C8:C11) -> 0 | E28: =SUM(Operations!D8:D11) -> 0 | F28: =SUM(Operations!E8:E11) -> 0 | G28: =SUM(Operations!F8:F11) -> 0 | H28: =SUM(Operations!G8:G11) -> 0 | I28: =SUM(Operations!H8:H11) -> 0 | J28: =SUM(Operations!I8:I11) -> 0 | K28: =SUM(Operations!J8:J11) -> 0
B29: Professional Services | C29: =SUM(D29:K29) -> 0 | D29: =Operations!C5+Operations!C6+Operations!C12 -> 0 | E29: =Operations!D5+Operations!D6+Operations!D12 -> 0 | F29: =Operations!E5+Operations!E6+Operations!E12 -> 0 | G29: =Operations!F5+Operations!F6+Operations!F12 -> 0 | H29: =Operations!G5+Operations!G6+Operations!G12 -> 0 | I29: =Operations!H5+Operations!H6+Operations!H12 -> 0 | J29: =Operations!I5+Operations!I6+Operations!I12 -> 0 | K29: =Operations!J5+Operations!J6+Operations!J12 -> 0
B30: Operations beginning in Month 15
B31: Facilities | C31: =SUM(D31:K31) -> 0 | D31: =SUM(Operations!C19:C21) -> 0 | E31: =SUM(Operations!D19:D21) -> 0 | F31: =SUM(Operations!E19:E21) -> 0 | G31: =SUM(Operations!F19:F21) -> 0 | H31: =SUM(Operations!G19:G21) -> 0 | I31: =SUM(Operations!H19:H21) -> 0 | J31: =SUM(Operations!I19:I21) -> 0 | K31: =SUM(Operations!J19:J21) -> 0
B32: Professional Services | C32: =SUM(D32:K32) -> 0 | D32: =Operations!C16+Operations!C17+Operations!C23 -> 0 | E32: =Operations!D16+Operations!D17+Operations!D23 -> 0 | F32: =Operations!E16+Operations!E17+Operations!E23 -> 0 | G32: =Operations!F16+Operations!F17+Operations!F23 -> 0 | H32: =Operations!G16+Operations!G17+Operations!G23 -> 0 | I32: =Operations!H16+Operations!H17+Operations!H23 -> 0 | J32: =Operations!I16+Operations!I17+Operations!I23 -> 0 | K32: =Operations!J16+Operations!J17+Operations!J23 -> 0
B33: Subtotal | C33: =SUM(C26:C32) -> 0 | D33: =SUM(D26:D32) -> 0 | E33: =SUM(E26:E32) -> 0 | F33: =SUM(F26:F32) -> 0 | G33: =SUM(G26:G32) -> 0 | H33: =SUM(H26:H32) -> 0 | I33: =SUM(I26:I32) -> 0 | J33: =SUM(J26:J32) -> 0 | K33: =SUM(K26:K32) -> 0
B34: Total Operations Cost | C34: =SUM(C26:C32) -> 0 | D34: =SUM(D26:D32) -> 0 | E34: =SUM(E26:E32) -> 0 | F34: =SUM(F26:F32) -> 0 | G34: =SUM(G26:G32) -> 0 | H34: =SUM(H26:H32) -> 0 | I34: =SUM(I26:I32) -> 0 | J34: =SUM(J26:J32) -> 0 | K34: =SUM(K26:K32) -> 0
B35: Total Cost (DDI + Operations) | C35: =C34+C23 -> 0 | D35: =D34+D23 -> 0 | E35: =E34+E23 -> 0 | F35: =F34+F23 -> 0 | G35: =G34+G23 -> 0 | H35: =H34+H23 -> 0 | I35: =I34+I23 -> 0 | J35: =J34+J23 -> 0 | K35: =K34+K23 -> 0
B37: Total price for Proposal Evaluation* | C37: =C35 -(C13 + C28 + C29 + Operations!K11 + Operations!K22 ) -> 0
B39: Note - For evaluation purposes, the State will deduct all pricing related to operations beginning before Month 15 of the contract, build out costs for the DDI facility, and build out costs for the operations facility from the total price. These will be added back into the contract of the winning bidder.

Sheet Sheet1
A1: NameList | B1: Values
A3: License Type | B3: Concurrent
B4: Named
B5: Site
A7: ProdSource | B7: COTS
B8: Proprietary
