Workbook

Sheet Recap C2I
A1: Recapitulatif C2i
A2: code utilisateur | B2: Nom de famille | C2: Prénom | D2: QCM | E2: Word | F2: Excel | G2: PPT | H2: Note Word | I2: Note Excel | J2: Note PPT | K2: Moyenne | L2: Acquis
A3: 3559 | B3: BOUBRED - | C3: Sabine | D3: =QCM!E3 -> 17.297778 | E3: =Word!D3 -> O | F3: =Excel!D3 -> O | G3: =PPT!D3 -> O | H3: =Word!E3 -> 14 | I3: =Excel!E3 -> 11 | J3: =PPT!E3 -> 10
A4: 3769 | B4: BENZOUGHARI | C4: Rachid | D4: =QCM!E4 -> 10.666667 | E4: =Word!D4 -> O | F4: =Excel!D4 -> O | G4: =PPT!D4 -> O | H4: =Word!E4 -> 2 | I4: =Excel!E4 -> 4 | J4: =PPT!E4 -> 8
A5: 3922 | B5: BAUDOUIN | C5: Emeline | D5: =QCM!E5 -> 12.737778 | E5: =Word!D5 -> N | F5: =Excel!D5 -> O | G5: =PPT!D5 -> N | H5: =Word!E5 -> 0 | I5: =Excel!E5 -> 8 | J5: =PPT!E5 -> 12
A6: 3936 | B6: BOURGEOIS | C6: Benjamin | D6: =QCM!E6 -> 15.52 | E6: =Word!D6 -> O | F6: =Excel!D6 -> O | G6: =PPT!D6 -> O | H6: =Word!E6 -> 4 | I6: =Excel!E6 -> 11 | J6: =PPT!E6 -> 13
A7: 3967 | B7: DJAMALIDINE | C7: Laylat | D7: =QCM!E7 -> 13 | E7: =Word!D7 -> N | F7: =Excel!D7 -> N | G7: =PPT!D7 -> O | H7: =Word!E7 -> 0 | I7: =Excel!E7 -> 0 | J7: =PPT!E7 -> 11
A8: 3991 | B8: HADJ-CHERIF | C8: L'aalia | D8: =QCM!E8 -> 15.146667 | E8: =Word!D8 -> O | F8: =Excel!D8 -> O | G8: =PPT!D8 -> N | H8: =Word!E8 -> 7 | I8: =Excel!E8 -> 15 | J8: =PPT!E8 -> 0
A9: 3996 | B9: JEAN-CHARLES | C9: Fabien | D9: =QCM!E9 -> 17.333333 | E9: =Word!D9 -> O | F9: =Excel!D9 -> O | G9: =PPT!D9 -> N | H9: =Word!E9 -> 12 | I9: =Excel!E9 -> 0 | J9: =PPT!E9 -> 0
A10: 4002 | B10: LAGORCE | C10: Capucine | D10: =QCM!E10 -> 17.182222 | E10: =Word!D10 -> O | F10: =Excel!D10 -> O | G10: =PPT!D10 -> O | H10: =Word!E10 -> 11 | I10: =Excel!E10 -> 12 | J10: =PPT!E10 -> 9
A11: 4004 | B11: LE BORGNE | C11: Kevin | D11: =QCM!E11 -> 13.333333 | E11: =Word!D11 -> O | F11: =Excel!D11 -> O | G11: =PPT!D11 -> O | H11: =Word!E11 -> 8 | I11: =Excel!E11 -> 0 | J11: =PPT!E11 -> 4
A12: 4025 | B12: NAJI | C12: Mounir | D12: =QCM!E12 -> 13.782222 | E12: =Word!D12 -> O | F12: =Excel!D12 -> O | G12: =PPT!D12 -> O | H12: =Word!E12 -> 14 | I12: =Excel!E12 -> 0 | J12: =PPT!E12 -> 4
A13: 4034 | B13: NYOURI | C13: Sadame | D13: =QCM!E13 -> 10.222222 | E13: =Word!D13 -> O | F13: =Excel!D13 -> O | G13: =PPT!D13 -> N | H13: =Word!E13 -> 6 | I13: =Excel!E13 -> 0 | J13: =PPT!E13 -> 0
A14: 4049 | B14: SAYARATH | C14: Oscar | D14: =QCM!E14 -> 18.666667 | E14: =Word!D14 -> O | F14: =Excel!D14 -> O | G14: =PPT!D14 -> O | H14: =Word!E14 -> 9 | I14: =Excel!E14 -> 0 | J14: =PPT!E14 -> 6
... A41: 4392 | B41: LAMBEAU | C41: Loic | D41: =QCM!E41 -> 11.924444 | E41: =Word!D41 -> O | F41: =Excel!D41 -> O | G41: =PPT!D41 -> O | H41: =Word!E41 -> 11 | I41: =Excel!E41 -> 9 | J41: =PPT!E41 -> 14
C45: Moyenne | D45: =AVERAGE(D3:D41) -> 14.689136 | H45: =AVERAGE(H3:H41) -> 8.0512821 | I45: =AVERAGE(I3:I41) -> 6.6666667 | J45: =AVERAGE(J3:J41) -> 6.7179487
C46: Note Max | D46: =MAX(D3:D41) -> 18.666667 | H46: =MAX(H3:H41) -> 17 | I46: =MAX(I3:I41) -> 15 | J46: =MAX(J3:J41) -> 14
C47: Note Min | D47: =MIN(D3:D41) -> 10.222222 | H47: =MIN(H3:H41) -> 0 | I47: =MIN(I3:I41) -> 0 | J47: =MIN(J3:J41) -> 0

Sheet Recap UE
A1: Recapitulatif UE
A2: code utilisateur | B2: Nom de famille | C2: Prénom | D2: QCM | E2: Word | F2: Excel | G2: PPT | H2: Note Word | I2: Note Excel | J2: Note PPT | K2: Moyenne | L2: Acquis
A3: 3559 | B3: BOUBRED - | C3: Sabine | D3: =QCM!E3 -> 17.297778 | E3: =Word!D3 -> O | F3: =Excel!D3 -> O | G3: =PPT!D3 -> O | H3: =Word!E3 -> 14 | I3: =Excel!E3 -> 11 | J3: =PPT!E3 -> 10
A4: 3769 | B4: BENZOUGHARI | C4: Rachid | D4: =QCM!E4 -> 10.666667 | E4: =Word!D4 -> O | F4: =Excel!D4 -> O | G4: =PPT!D4 -> O | H4: =Word!E4 -> 2 | I4: =Excel!E4 -> 4 | J4: =PPT!E4 -> 8
A5: 3922 | B5: BAUDOUIN | C5: Emeline | D5: =QCM!E5 -> 12.737778 | E5: =Word!D5 -> N | F5: =Excel!D5 -> O | G5: =PPT!D5 -> N | H5: =Word!E5 -> 0 | I5: =Excel!E5 -> 8 | J5: =PPT!E5 -> 12
A6: 3936 | B6: BOURGEOIS | C6: Benjamin | D6: =QCM!E6 -> 15.52 | E6: =Word!D6 -> O | F6: =Excel!D6 -> O | G6: =PPT!D6 -> O | H6: =Word!E6 -> 4 | I6: =Excel!E6 -> 11 | J6: =PPT!E6 -> 13
A7: 3967 | B7: DJAMALIDINE | C7: Laylat | D7: =QCM!E7 -> 13 | E7: =Word!D7 -> N | F7: =Excel!D7 -> N | G7: =PPT!D7 -> O | H7: =Word!E7 -> 0 | I7: =Excel!E7 -> 0 | J7: =PPT!E7 -> 11
A8: 3991 | B8: HADJ-CHERIF | C8: L'aalia | D8: =QCM!E8 -> 15.146667 | E8: =Word!D8 -> O | F8: =Excel!D8 -> O | G8: =PPT!D8 -> N | H8: =Word!E8 -> 7 | I8: =Excel!E8 -> 15 | J8: =PPT!E8 -> 0
A9: 3996 | B9: JEAN-CHARLES | C9: Fabien | D9: =QCM!E9 -> 17.333333 | E9: =Word!D9 -> O | F9: =Excel!D9 -> O | G9: =PPT!D9 -> N | H9: =Word!E9 -> 12 | I9: =Excel!E9 -> 0 | J9: =PPT!E9 -> 0
A10: 4002 | B10: LAGORCE | C10: Capucine | D10: =QCM!E10 -> 17.182222 | E10: =Word!D10 -> O | F10: =Excel!D10 -> O | G10: =PPT!D10 -> O | H10: =Word!E10 -> 11 | I10: =Excel!E10 -> 12 | J10: =PPT!E10 -> 9
A11: 4004 | B11: LE BORGNE | C11: Kevin | D11: =QCM!E11 -> 13.333333 | E11: =Word!D11 -> O | F11: =Excel!D11 -> O | G11: =PPT!D11 -> O | H11: =Word!E11 -> 8 | I11: =Excel!E11 -> 0 | J11: =PPT!E11 -> 4
A12: 4025 | B12: NAJI | C12: Mounir | D12: =QCM!E12 -> 13.782222 | E12: =Word!D12 -> O | F12: =Excel!D12 -> O | G12: =PPT!D12 -> O | H12: =Word!E12 -> 14 | I12: =Excel!E12 -> 0 | J12: =PPT!E12 -> 4
A13: 4034 | B13: NYOURI | C13: Sadame | D13: =QCM!E13 -> 10.222222 | E13: =Word!D13 -> O | F13: =Excel!D13 -> O | G13: =PPT!D13 -> N | H13: =Word!E13 -> 6 | I13: =Excel!E13 -> 0 | J13: =PPT!E13 -> 0
A14: 4049 | B14: SAYARATH | C14: Oscar | D14: =QCM!E14 -> 18.666667 | E14: =Word!D14 -> O | F14: =Excel!D14 -> O | G14: =PPT!D14 -> O | H14: =Word!E14 -> 9 | I14: =Excel!E14 -> 0 | J14: =PPT!E14 -> 6
... A41: 4392 | B41: LAMBEAU | C41: Loic | D41: =QCM!E41 -> 11.924444 | E41: =Word!D41 -> O | F41: =Excel!D41 -> O | G41: =PPT!D41 -> O | H41: =Word!E41 -> 11 | I41: =Excel!E41 -> 9 | J41: =PPT!E41 -> 14
C45: Moyenne | D45: =AVERAGE(D3:D41) -> 14.689136 | H45: =AVERAGE(H3:H41) -> 8.0512821 | I45: =AVERAGE(I3:I41) -> 6.6666667 | J45: =AVERAGE(J3:J41) -> 6.7179487
C46: Note Max | D46: =MAX(D3:D41) -> 18.666667 | H46: =MAX(H3:H41) -> 17 | I46: =MAX(I3:I41) -> 15 | J46: =MAX(J3:J41) -> 14
C47: Note Min | D47: =MIN(D3:D41) -> 10.222222 | H47: =MIN(H3:H41) -> 0 | I47: =MIN(I3:I41) -> 0 | J47: =MIN(J3:J41) -> 0

Sheet QCM
A1: Epreuve : QCM
A2: code utilisateur | B2: Nom de famille | C2: Prénom | D2: Note QCM [/40] | E2: Note [/20]
A3: 3559 | B3: BOUBRED - | C3: Sabine | D3: 38.92 | E3: =IF(D3="","A",(D3/45)*20) -> 17.297778
A4: 3769 | B4: BENZOUGHARI | C4: Rachid | D4: 24 | E4: =IF(D4="","A",(D4/45)*20) -> 10.666667
A5: 3922 | B5: BAUDOUIN | C5: Emeline | D5: 28.66 | E5: =IF(D5="","A",(D5/45)*20) -> 12.737778
A6: 3936 | B6: BOURGEOIS | C6: Benjamin | D6: 34.92 | E6: =IF(D6="","A",(D6/45)*20) -> 15.52
A7: 3967 | B7: DJAMALIDINE | C7: Laylat | D7: 29.25 | E7: =IF(D7="","A",(D7/45)*20) -> 13
A8: 3991 | B8: HADJ-CHERIF | C8: L'aalia | D8: 34.08 | E8: =IF(D8="","A",(D8/45)*20) -> 15.146667
A9: 3996 | B9: JEAN-CHARLES | C9: Fabien | D9: 39 | E9: =IF(D9="","A",(D9/45)*20) -> 17.333333
A10: 4002 | B10: LAGORCE | C10: Capucine | D10: 38.66 | E10: =IF(D10="","A",(D10/45)*20) -> 17.182222
A11: 4004 | B11: LE BORGNE | C11: Kevin | D11: 30 | E11: =IF(D11="","A",(D11/45)*20) -> 13.333333
A12: 4025 | B12: NAJI | C12: Mounir | D12: 31.01 | E12: =IF(D12="","A",(D12/45)*20) -> 13.782222
A13: 4034 | B13: NYOURI | C13: Sadame | D13: 23 | E13: =IF(D13="","A",(D13/45)*20) -> 10.222222
A14: 4049 | B14: SAYARATH | C14: Oscar | D14: 42 | E14: =IF(D14="","A",(D14/45)*20) -> 18.666667
... A32: 4349 | B32: DUPUIS | C32: Antoine | D32: 32.16 | E32: =IF(D32="","A",(D32/45)*20) -> 14.293333
A33: 4350 | B33: DUSSAIX | C33: Patrick | E33: =IF(D33="","A",(D33/45)*20) -> A
A34: 4362 | B34: GALLARD | C34: Jeremy | D34: 36.33 | E34: =IF(D34="","A",(D34/45)*20) -> 16.146667
A35: 4367 | B35: GENRI | C35: Ariane | E35: =IF(D35="","A",(D35/45)*20) -> A
A36: 4375 | B36: GROSJEAN | C36: Ulric | E36: =IF(D36="","A",(D36/45)*20) -> A
A37: 4379 | B37: HAMILLE | C37: Julien | D37: 32.16 | E37: =IF(D37="","A",(D37/45)*20) -> 14.293333
A38: 4381 | B38: JEAN | C38: Christiane | D38: 34.33 | E38: =IF(D38="","A",(D38/45)*20) -> 15.257778
A39: 4386 | B39: KELI | C39: Hesna | D39: 31 | E39: =IF(D39="","A",(D39/45)*20) -> 13.777778
A40: 4388 | B40: KOPTIENT | C40: Amelie | D40: 36.92 | E40: =IF(D40="","A",(D40/45)*20) -> 16.408889
A41: 4392 | B41: LAMBEAU | C41: Loic | D41: 26.83 | E41: =IF(D41="","A",(D41/45)*20) -> 11.924444

Sheet Word
A1: Epreuve : Traitement de Texte
A2: code utilisateur | B2: Nom de famille | C2: Prénom | D2: Rendu | E2: Note Totale
A3: =QCM!A3 -> 3559 | B3: =QCM!B3 -> BOUBRED - | C3: =QCM!C3 -> Sabine | D3: O | E3: 14
A4: =QCM!A4 -> 3769 | B4: =QCM!B4 -> BENZOUGHARI | C4: =QCM!C4 -> Rachid | D4: O | E4: 2
A5: =QCM!A5 -> 3922 | B5: =QCM!B5 -> BAUDOUIN | C5: =QCM!C5 -> Emeline | D5: N | E5: =IF(D5="N",0,SUM(#REF!)) -> 0
A6: =QCM!A6 -> 3936 | B6: =QCM!B6 -> BOURGEOIS | C6: =QCM!C6 -> Benjamin | D6: O | E6: 4
A7: =QCM!A7 -> 3967 | B7: =QCM!B7 -> DJAMALIDINE | C7: =QCM!C7 -> Laylat | D7: N | E7: =IF(D7="N",0,SUM(#REF!)) -> 0
A8: =QCM!A8 -> 3991 | B8: =QCM!B8 -> HADJ-CHERIF | C8: =QCM!C8 -> L'aalia | D8: O | E8: 7
A9: =QCM!A9 -> 3996 | B9: =QCM!B9 -> JEAN-CHARLES | C9: =QCM!C9 -> Fabien | D9: O | E9: 12
A10: =QCM!A10 -> 4002 | B10: =QCM!B10 -> LAGORCE | C10: =QCM!C10 -> Capucine | D10: O | E10: 11
A11: =QCM!A11 -> 4004 | B11: =QCM!B11 -> LE BORGNE | C11: =QCM!C11 -> Kevin | D11: O | E11: 8
A12: =QCM!A12 -> 4025 | B12: =QCM!B12 -> NAJI | C12: =QCM!C12 -> Mounir | D12: O | E12: 14
A13: =QCM!A13 -> 4034 | B13: =QCM!B13 -> NYOURI | C13: =QCM!C13 -> Sadame | D13: O | E13: 6
A14: =QCM!A14 -> 4049 | B14: =QCM!B14 -> SAYARATH | C14: =QCM!C14 -> Oscar | D14: O | E14: 9
A15: =QCM!A15 -> 4052 | B15: =QCM!B15 -> SINCLAIR | C15: =QCM!C15 -> Xavier | D15: O | E15: 15
A16: =QCM!A16 -> 4062 | B16: =QCM!B16 -> TOUAGH | C16: =QCM!C16 -> Ali | D16: O | E16: 12
A17: =QCM!A17 -> 4070 | B17: =QCM!B17 -> YAFU | C17: =QCM!C17 -> Ludovic | D17: O | E17: 11
A18: =QCM!A18 -> 4176 | B18: =QCM!B18 -> TOUROUDE | C18: =QCM!C18 -> John | D18: N | E18: =IF(D18="N",0,SUM(#REF!)) -> 0
A19: =QCM!A19 -> 4187 | B19: =QCM!B19 -> TRIBOULT | C19: =QCM!C19 -> Pierre-Alain | D19: O | E19: 4
A20: =QCM!A20 -> 4289 | B20: =QCM!B20 -> ALERTE | C20: =QCM!C20 -> Virginie | D20: O | E20: 8
A21: =QCM!A21 -> 4293 | B21: =QCM!B21 -> AMRANI | C21: =QCM!C21 -> Maud | D21: O | E21: 9
A22: =QCM!A22 -> 4302 | B22: =QCM!B22 -> BERNARD | C22: =QCM!C22 -> Cecile | D22: O | E22: 12
A23: =QCM!A23 -> 4304 | B23: =QCM!B23 -> BOCHE | C23: =QCM!C23 -> Cedric | D23: O | E23: 17
A24: =QCM!A24 -> 4307 | B24: =QCM!B24 -> BOULANGE | C24: =QCM!C24 -> Eve-aurore | D24: O | E24: 13
A25: =QCM!A25 -> 4310 | B25: =QCM!B25 -> BOUSSALEM | C25: =QCM!C25 -> Ghizlane | D25: O | E25: 13
A26: =QCM!A26 -> 4313 | B26: =QCM!B26 -> BUTRUILLE | C26: =QCM!C26 -> Amelie | D26: O | E26: 12
A27: =QCM!A27 -> 4318 | B27: =QCM!B27 -> CHEDDAD | C27: =QCM!C27 -> Audrey | D27: O | E27: 7
A28: =QCM!A28 -> 4325 | B28: =QCM!B28 -> COURROUX | C28: =QCM!C28 -> Nicolas | D28: O | E28: 4
A29: =QCM!A29 -> 4337 | B29: =QCM!B29 -> DENARDOU | C29: =QCM!C29 -> Bruno | D29: O | E29: 8
A30: =QCM!A30 -> 4339 | B30: =QCM!B30 -> DEPARIS | C30: =QCM!C30 -> Thibaud | D30: O | E30: 11
... A41: =QCM!A41 -> 4392 | B41: =QCM!B41 -> LAMBEAU | C41: =QCM!C41 -> Loic | D41: O | E41: 11

Sheet Excel
A1: Epreuve : Tableur
A2: code utilisateur | B2: Nom de famille | C2: Prénom | D2: Rendu | E2: Note Totale
A3: =Word!A3 -> 3559 | B3: =Word!B3 -> BOUBRED - | C3: =Word!C3 -> Sabine | D3: O | E3: 11
A4: =Word!A4 -> 3769 | B4: =Word!B4 -> BENZOUGHARI | C4: =Word!C4 -> Rachid | D4: O | E4: 4
A5: =Word!A5 -> 3922 | B5: =Word!B5 -> BAUDOUIN | C5: =Word!C5 -> Emeline | D5: O | E5: 8
A6: =Word!A6 -> 3936 | B6: =Word!B6 -> BOURGEOIS | C6: =Word!C6 -> Benjamin | D6: O | E6: 11
A7: =Word!A7 -> 3967 | B7: =Word!B7 -> DJAMALIDINE | C7: =Word!C7 -> Laylat | D7: N | E7: 0
A8: =Word!A8 -> 3991 | B8: =Word!B8 -> HADJ-CHERIF | C8: =Word!C8 -> L'aalia | D8: O | E8: 15
A9: =Word!A9 -> 3996 | B9: =Word!B9 -> JEAN-CHARLES | C9: =Word!C9 -> Fabien | D9: O | E9: 0
A10: =Word!A10 -> 4002 | B10: =Word!B10 -> LAGORCE | C10: =Word!C10 -> Capucine | D10: O | E10: 12
A11: =Word!A11 -> 4004 | B11: =Word!B11 -> LE BORGNE | C11: =Word!C11 -> Kevin | D11: O | E11: 0
A12: =Word!A12 -> 4025 | B12: =Word!B12 -> NAJI | C12: =Word!C12 -> Mounir | D12: O | E12: 0
A13: =Word!A13 -> 4034 | B13: =Word!B13 -> NYOURI | C13: =Word!C13 -> Sadame | D13: O | E13: 0
A14: =Word!A14 -> 4049 | B14: =Word!B14 -> SAYARATH | C14: =Word!C14 -> Oscar | D14: O | E14: 0
... A17: =Word!A17 -> 4070 | B17: =Word!B17 -> YAFU | C17: =Word!C17 -> Ludovic | D17: O | E17: 11
A18: =Word!A18 -> 4176 | B18: =Word!B18 -> TOUROUDE | C18: =Word!C18 -> John | D18: N | E18: =IF(D18="N",0,SUM(#REF!)) -> 0
A19: =Word!A19 -> 4187 | B19: =Word!B19 -> TRIBOULT | C19: =Word!C19 -> Pierre-Alain | D19: O | E19: 12
A20: =Word!A20 -> 4289 | B20: =Word!B20 -> ALERTE | C20: =Word!C20 -> Virginie | D20: O | E20: 11
A21: =Word!A21 -> 4293 | B21: =Word!B21 -> AMRANI | C21: =Word!C21 -> Maud | D21: O | E21: 8
A22: =Word!A22 -> 4302 | B22: =Word!B22 -> BERNARD | C22: =Word!C22 -> Cecile | D22: O | E22: 14
A23: =Word!A23 -> 4304 | B23: =Word!B23 -> BOCHE | C23: =Word!C23 -> Cedric | D23: O | E23: 6
A24: =Word!A24 -> 4307 | B24: =Word!B24 -> BOULANGE | C24: =Word!C24 -> Eve-aurore | D24: O | E24: 9
A25: =Word!A25 -> 4310 | B25: =Word!B25 -> BOUSSALEM | C25: =Word!C25 -> Ghizlane | D25: O | E25: 15
A26: =Word!A26 -> 4313 | B26: =Word!B26 -> BUTRUILLE | C26: =Word!C26 -> Amelie | D26: O | E26: 12
A27: =Word!A27 -> 4318 | B27: =Word!B27 -> CHEDDAD | C27: =Word!C27 -> Audrey | D27: O | E27: 11
A28: =Word!A28 -> 4325 | B28: =Word!B28 -> COURROUX | C28: =Word!C28 -> Nicolas | D28: O | E28: 5
A29: =Word!A29 -> 4337 | B29: =Word!B29 -> DENARDOU | C29: =Word!C29 -> Bruno | D29: O | E29: 4
A30: =Word!A30 -> 4339 | B30: =Word!B30 -> DEPARIS | C30: =Word!C30 -> Thibaud | D30: O | E30: 8
... A32: =Word!A32 -> 4349 | B32: =Word!B32 -> DUPUIS | C32: =Word!C32 -> Antoine | D32: O | E32: 4
A33: =Word!A33 -> 4350 | B33: =Word!B33 -> DUSSAIX | C33: =Word!C33 -> Patrick | D33: N | E33: =IF(D33="N",0,SUM(#REF!)) -> 0
A34: =Word!A34 -> 4362 | B34: =Word!B34 -> GALLARD | C34: =Word!C34 -> Jeremy | D34: O | E34: 8
A35: =Word!A35 -> 4367 | B35: =Word!B35 -> GENRI | C35: =Word!C35 -> Ariane | D35: N | E35: =IF(D35="N",0,SUM(#REF!)) -> 0
A36: =Word!A36 -> 4375 | B36: =Word!B36 -> GROSJEAN | C36: =Word!C36 -> Ulric | D36: N | E36: =IF(D36="N",0,SUM(#REF!)) -> 0
A37: =Word!A37 -> 4379 | B37: =Word!B37 -> HAMILLE | C37: =Word!C37 -> Julien | D37: N | E37: =IF(D37="N",0,SUM(#REF!)) -> 0
A38: =Word!A38 -> 4381 | B38: =Word!B38 -> JEAN | C38: =Word!C38 -> Christiane | D38: O | E38: 9
A39: =Word!A39 -> 4386 | B39: =Word!B39 -> KELI | C39: =Word!C39 -> Hesna | D39: O | E39: 11
A40: =Word!A40 -> 4388 | B40: =Word!B40 -> KOPTIENT | C40: =Word!C40 -> Amelie | D40: O | E40: 7
A41: =Word!A41 -> 4392 | B41: =Word!B41 -> LAMBEAU | C41: =Word!C41 -> Loic | D41: O | E41: 9

Sheet PPT
A1: Epreuve : Présentation Assitée par Ordinateur
A2: code utilisateur | B2: Nom de famille | C2: Prénom | D2: Rendu | E2: Note Totale
A3: =QCM!A3 -> 3559 | B3: =QCM!B3 -> BOUBRED - | C3: =QCM!C3 -> Sabine | D3: O | E3: 10
A4: =QCM!A4 -> 3769 | B4: =QCM!B4 -> BENZOUGHARI | C4: =QCM!C4 -> Rachid | D4: O | E4: 8
A5: =QCM!A5 -> 3922 | B5: =QCM!B5 -> BAUDOUIN | C5: =QCM!C5 -> Emeline | D5: N | E5: 12
A6: =QCM!A6 -> 3936 | B6: =QCM!B6 -> BOURGEOIS | C6: =QCM!C6 -> Benjamin | D6: O | E6: 13
A7: =QCM!A7 -> 3967 | B7: =QCM!B7 -> DJAMALIDINE | C7: =QCM!C7 -> Laylat | D7: O | E7: 11
A8: =QCM!A8 -> 3991 | B8: =QCM!B8 -> HADJ-CHERIF | C8: =QCM!C8 -> L'aalia | D8: N | E8: =IF(D8="N",0,SUM(#REF!)) -> 0
A9: =QCM!A9 -> 3996 | B9: =QCM!B9 -> JEAN-CHARLES | C9: =QCM!C9 -> Fabien | D9: N | E9: =IF(D9="N",0,SUM(#REF!)) -> 0
A10: =QCM!A10 -> 4002 | B10: =QCM!B10 -> LAGORCE | C10: =QCM!C10 -> Capucine | D10: O | E10: 9
A11: =QCM!A11 -> 4004 | B11: =QCM!B11 -> LE BORGNE | C11: =QCM!C11 -> Kevin | D11: O | E11: 4
A12: =QCM!A12 -> 4025 | B12: =QCM!B12 -> NAJI | C12: =QCM!C12 -> Mounir | D12: O | E12: 4
A13: =QCM!A13 -> 4034 | B13: =QCM!B13 -> NYOURI | C13: =QCM!C13 -> Sadame | D13: N | E13: =IF(D13="N",0,SUM(#REF!)) -> 0
A14: =QCM!A14 -> 4049 | B14: =QCM!B14 -> SAYARATH | C14: =QCM!C14 -> Oscar | D14: O | E14: 6
A15: =QCM!A15 -> 4052 | B15: =QCM!B15 -> SINCLAIR | C15: =QCM!C15 -> Xavier | D15: O | E15: 8
A16: =QCM!A16 -> 4062 | B16: =QCM!B16 -> TOUAGH | C16: =QCM!C16 -> Ali | D16: O | E16: 3
A17: =QCM!A17 -> 4070 | B17: =QCM!B17 -> YAFU | C17: =QCM!C17 -> Ludovic | D17: N | E17: =IF(D17="N",0,SUM(#REF!)) -> 0
A18: =QCM!A18 -> 4176 | B18: =QCM!B18 -> TOUROUDE | C18: =QCM!C18 -> John | D18: O | E18: 13
A19: =QCM!A19 -> 4187 | B19: =QCM!B19 -> TRIBOULT | C19: =QCM!C19 -> Pierre-Alain | D19: N | E19: =IF(D19="N",0,SUM(#REF!)) -> 0
A20: =QCM!A20 -> 4289 | B20: =QCM!B20 -> ALERTE | C20: =QCM!C20 -> Virginie | D20: O | E20: 14
A21: =QCM!A21 -> 4293 | B21: =QCM!B21 -> AMRANI | C21: =QCM!C21 -> Maud | D21: O | E21: 11
A22: =QCM!A22 -> 4302 | B22: =QCM!B22 -> BERNARD | C22: =QCM!C22 -> Cecile | D22: N | E22: =IF(D22="N",0,SUM(#REF!)) -> 0
A23: =QCM!A23 -> 4304 | B23: =QCM!B23 -> BOCHE | C23: =QCM!C23 -> Cedric | D23: O | E23: 10
A24: =QCM!A24 -> 4307 | B24: =QCM!B24 -> BOULANGE | C24: =QCM!C24 -> Eve-aurore | D24: O | E24: 7
A25: =QCM!A25 -> 4310 | B25: =QCM!B25 -> BOUSSALEM | C25: =QCM!C25 -> Ghizlane | D25: N | E25: =IF(D25="N",0,SUM(#REF!)) -> 0
A26: =QCM!A26 -> 4313 | B26: =QCM!B26 -> BUTRUILLE | C26: =QCM!C26 -> Amelie | D26: O | E26: 6
A27: =QCM!A27 -> 4318 | B27: =QCM!B27 -> CHEDDAD | C27: =QCM!C27 -> Audrey | D27: O | E27: 9
A28: =QCM!A28 -> 4325 | B28: =QCM!B28 -> COURROUX | C28: =QCM!C28 -> Nicolas | D28: O | E28: 11
A29: =QCM!A29 -> 4337 | B29: =QCM!B29 -> DENARDOU | C29: =QCM!C29 -> Bruno | D29: O | E29: 14
A30: =QCM!A30 -> 4339 | B30: =QCM!B30 -> DEPARIS | C30: =QCM!C30 -> Thibaud | D30: O | E30: 11
A31: =QCM!A31 -> 4341 | B31: =QCM!B31 -> DJAMALIDINE | C31: =QCM!C31 -> Tahiyat | D31: O | E31: 10
A32: =QCM!A32 -> 4349 | B32: =QCM!B32 -> DUPUIS | C32: =QCM!C32 -> Antoine | D32: O | E32: 5
A33: =QCM!A33 -> 4350 | B33: =QCM!B33 -> DUSSAIX | C33: =QCM!C33 -> Patrick | D33: O | E33: 8
A34: =QCM!A34 -> 4362 | B34: =QCM!B34 -> GALLARD | C34: =QCM!C34 -> Jeremy | D34: N | E34: =IF(D34="N",0,SUM(#REF!)) -> 0
A35: =QCM!A35 -> 4367 | B35: =QCM!B35 -> GENRI | C35: =QCM!C35 -> Ariane | D35: O | E35: 9
A36: =QCM!A36 -> 4375 | B36: =QCM!B36 -> GROSJEAN | C36: =QCM!C36 -> Ulric | D36: N | E36: =IF(D36="N",0,SUM(#REF!)) -> 0
A37: =QCM!A37 -> 4379 | B37: =QCM!B37 -> HAMILLE | C37: =QCM!C37 -> Julien | D37: N | E37: =IF(D37="N",0,SUM(#REF!)) -> 0
A38: =QCM!A38 -> 4381 | B38: =QCM!B38 -> JEAN | C38: =QCM!C38 -> Christiane | D38: N | E38: =IF(D38="N",0,SUM(#REF!)) -> 0
A39: =QCM!A39 -> 4386 | B39: =QCM!B39 -> KELI | C39: =QCM!C39 -> Hesna | D39: O | E39: 10
A40: =QCM!A40 -> 4388 | B40: =QCM!B40 -> KOPTIENT | C40: =QCM!C40 -> Amelie | D40: O | E40: 12
...
