Workbook
Name FASEXPT: #REF!
Name FASEXPT2: #REF!

Sheet enter data
A1: FAS - Accumulated Grain Export Sales
A2: Metric Tons
A3: Crop Year-Wheat=6/01-5/31; Corn & Soybeans=9/01-8/31;
B4: HRW | D4: SRW | F4: HRS | H4: SWW | J4: DUR | L4: All | N4: Corn | P4: Soybean
B5: Outstd | C5: Accum | D5: Outstd | E5: Accum | F5: Outstd | G5: Accum | H5: Outstd | I5: Accum | J5: Outstd | K5: Accum | L5: Outstd | M5: Accum | N5: Outstd | O5: Accum | P5: Outstd | Q5: Accum
A7: 41032 | B7: 1074 | C7: 9067 | D7: 711 | E7: 3621 | F7: 874 | G7: 5874 | H7: 596 | I7: 5198 | J7: 44 | K7: 447 | L7: 3299 | M7: 24206 | N7: 9691 | O7: 27837 | P7: 5065 | Q7: 29419 | R7: =P7+N7+L7 -> 18055
A8: 41396 | B8: 1406 | C8: 8864 | D8: 701 | E8: 3631 | F8: 518 | G8: 5495 | H8: 245 | I8: 4361 | J8: 58 | K8: 489 | L8: 2928 | M8: 23840 | N8: 4152 | O8: 12714 | P8: 2111 | Q8: 34371 | R8: =P8+N8+L8 -> 9191
A11: enter the data on this sheet, then copy these two lines to the end to the copy data sheet

Sheet Tble 12
A1: Table 12
A2: U.S. Export Balances and Cumulative Exports (1,000 metric tons)
B3: Wheat | H3: Corn | I3: Soybeans | J3: Total
A4: Week ending | B4: HRW | C4: SRW | D4: HRS | E4: SWW | F4: DUR | G4: All wheat
A5: Export Balances1
A6: ='enter data'!A8 -> 41396 | B6: ='enter data'!B8 -> 1406 | C6: ='enter data'!D8 -> 701 | D6: ='enter data'!F8 -> 518 | E6: ='enter data'!H8 -> 245 | F6: ='enter data'!J8 -> 58 | G6: ='enter data'!L8 -> 2928 | H6: ='enter data'!N8 -> 4152 | I6: ='enter data'!P8 -> 2111 | J6: =SUM(G6:I6) -> 9191
A7: This week year ago | B7: ='enter data'!B7 -> 1074 | C7: ='enter data'!D7 -> 711 | D7: ='enter data'!F7 -> 874 | E7: ='enter data'!H7 -> 596 | F7: ='enter data'!J7 -> 44 | G7: ='enter data'!L7 -> 3299 | H7: ='enter data'!N7 -> 9691 | I7: ='enter data'!P7 -> 5065 | J7: =SUM(G7:I7) -> 18055
A8: Cumulative exports-marketing year 2
A9: 2012/13 YTD | B9: ='enter data'!C8 -> 8864 | C9: ='enter data'!E8 -> 3631 | D9: ='enter data'!G8 -> 5495 | E9: ='enter data'!I8 -> 4361 | F9: ='enter data'!K8 -> 489 | G9: ='enter data'!M8 -> 23840 | H9: ='enter data'!O8 -> 12714 | I9: ='enter data'!Q8 -> 34371 | J9: =SUM(G9:I9) -> 70925
A10: 2011/12 YTD | B10: ='enter data'!C7 -> 9067 | C10: ='enter data'!E7 -> 3621 | D10: ='enter data'!G7 -> 5874 | E10: ='enter data'!I7 -> 5198 | F10: ='enter data'!K7 -> 447 | G10: ='enter data'!M7 -> 24206 | H10: ='enter data'!O7 -> 27837 | I10: ='enter data'!Q7 -> 29419 | J10: =SUM(G10:I10) -> 81462
A11: YTD 2012/13 as % of 2011/12 | B11: =(B9/B10)*100 -> 97.761112 | C11: =(C9/C10)*100 -> 100.27617 | D11: =(D9/D10)*100 -> 93.547838 | E11: =(E9/E10)*100 -> 83.897653 | F11: =(F9/F10)*100 -> 109.39597 | G11: =(G9/G10)*100 -> 98.487978 | H11: =(H9/H10)*100 -> 45.673025 | I11: =(I9/I10)*100 -> 116.83266 | J11: =(J9/J10)*100 -> 87.065135
A12: Last 4 wks as % of same period 2011/12 | B12: ='copy data'!W650 -> 150 | C12: ='copy data'!Z650 -> 115.43601 | D12: ='copy data'!AC650 -> 81.721968 | E12: ='copy data'!AF650 -> 59.941275 | F12: ='copy data'!AI650 -> 217.04545 | G12: ='copy data'!AL650 -> 109.08609 | H12: ='copy data'!AO650 -> 43.837065 | I12: ='copy data'!AR650 -> 47.931885 | J12: ='copy data'!AU650 -> 56.908059
A13: 2011/12 Total | B13: 9904 | C13: 4319 | D13: 6312 | E13: 5601 | F13: 491 | G13: =SUM(B13:F13) -> 26627 | H13: 37900 | I13: 36727 | J13: =SUM(G13:I13) -> 101254
A14: 2010/11 Total | B14: 15837 | C14: 2828 | D14: 8623 | E14: 4717 | F14: 979 | G14: =SUM(B14:F14) -> 32984 | H14: 44569 | I14: 39753 | J14: =SUM(G14:I14) -> 117306
A15: 1 Current unshipped export sales to date
A16: 2 Shipped export sales to date; new marketing year begins for corn and soybeans
A17: Note: YTD = year-to-date. Marketing Year: wheat = 6/01-5/31, corn & soybeans = 9/01-8/31
A18: Source: Foreign Agricultural Service/USDA (www.fas.usda.gov)

Sheet copy data
A1: FAS - Accumulated Grain Export Sales
A2: Metric Tons | S2: EXTEND RANGE in L..N
A3: Crop Year-Wheat=6/01-5/31; Corn & Soybeans=9/01-8/31; | R3: 3 Crop | S3: each week FOR GRAPHIC | AJ3: All | AW3: All Wheat | AY3: Soybeans | BA3: Corn | BC3: All 3 Crops
B4: HRW | D4: SRW | F4: HRS | H4: SWW | J4: DUR | L4: All | N4: Corn | P4: Soybean | R4: Total | U4: HRW | V4: HRW | W4: 4-wk as % | X4: SRW | Z4: 4-wk as % | AA4: HRS | AC4: 4-wk as % | AD4: SWW | AF4: 4-wk as % | AG4: DUR | AI4: 4-wk as % | AJ4: Wheat | AL4: 4-wk as % | AM4: Corn | AO4: 4-wk as % | AP4: Soybeans | AR4: 4-wk as % | AS4: All 3 Crops | AU4: 4-wk as % | AW4: % Chng | AX4: % Chng | AY4: % Chng | AZ4: % Chng | BA4: % Chng | BB4: % Chng | BC4: % Chng | BD4: % Chng
B5: Outstd | C5: Accum | D5: Outstd | E5: Accum | F5: Outstd | G5: Accum | H5: Outstd | I5: Accum | J5: Outstd | K5: Accum | L5: Outstd | M5: Accum | N5: Outstd | O5: Accum | P5: Outstd | Q5: Accum | S5: Week | T5: Date | U5: Outstd | V5: 4-wk average | W5: of 2010/2011 | X5: Outstd | Y5: 4-wk average | Z5: of 2010/2011 | AA5: Outstd | AB5: 4-wk average | AC5: of 2010/2011 | AD5: Outstd | AE5: 4-wk average | AF5: of 2011/2012 | AG5: Outstd | AH5: 4-wk average | AI5: of 2011/2012 | AJ5: Outstd | AK5: 4-wk average | AL5: of 2011/2012 | AM5: Outstd | AN5: 4-wk average | AO5: of 2011/2012 | AP5: Outstd | AQ5: 4-wk average | AR5: of 2011/2012 | AS5: Outstd | AT5: 4-wk average | AU5: of 2011/2012 | AW5: from Prior Week | AX5: from Last Year | AY5: from Prior Week | AZ5: from Last Year | BA5: from Prior Week | BB5: from Last Year | BC5: from Prior Week | BD5: from Last Year
A6: 36523 | B6: 894 | C6: 7280 | D6: 642 | E6: 2514 | F6: 801 | G6: 3375 | H6: 721 | I6: 2326 | J6: 255 | K6: 563 | L6: 3312 | M6: 16058 | N6: 7894 | O6: 17010 | P6: 4521 | Q6: 11070 | R6: =P6+N6+L6 -> 15727 | AS6: 15727
A7: 36888 | B7: 998 | C7: 5836 | D7: 295 | E7: 2759 | F7: 923 | G7: 3301 | H7: 666 | I7: 3023 | J7: 170 | K7: 737 | L7: 3047 | M7: 15656 | N7: 6697 | O7: 15269 | P7: 6104 | Q7: 11059 | R7: =P7+N7+L7 -> 15848 | AS7: 15848
A8: 01/05/2000 | B8: 854 | C8: 7364 | D8: 523 | E8: 2644 | F8: 707 | G8: 3493 | H8: 638 | I8: 2455 | J8: 206 | K8: 619 | L8: 2928 | M8: 16575 | N8: 7360 | O8: 17826 | P8: 4436 | Q8: 11672 | R8: =P8+N8+L8 -> 14724 | T8: 36902 | AS8: 14724
A9: 01/04/2001 | B9: 906 | C9: 5946 | D9: 179 | E9: 2898 | F9: 920 | G9: 3379 | H9: 596 | I9: 3132 | J9: 173 | K9: 748 | L9: 2775 | M9: 16103 | N9: 6253 | O9: 15898 | P9: 5712 | Q9: 11894 | R9: =P9+N9+L9 -> 14740 | T9: =T8+7 -> 36909 | AS9: 14740 | AT9: =AVERAGE(AS6:AS9) -> 15259.75
A10: 36537 | B10: 780.4 | C10: 7583.5 | D10: 430.7 | E10: 2745 | F10: 687 | G10: 3564 | H10: 589 | I10: 2535 | J10: 224 | K10: 619 | L10: 2711 | M10: 17047 | N10: 7487 | O10: 18837 | P10: 4338 | Q10: 12360 | R10: =P10+N10+L10 -> 14536 | T10: =T9+7 -> 36916 | AS10: 14972 | AT10: =AVERAGE(AS7:AS10) -> 15071
A11: 36902 | B11: 998 | C11: 6063.2 | D11: 259 | E11: 2933 | F11: 894 | G11: 3499 | H11: 604 | I11: 3159 | J11: 141 | K11: 781 | L11: 2896 | M11: 16432.5 | N11: 5936 | O11: 16827 | P11: 6140 | Q11: 12416 | R11: =P11+N11+L11 -> 14972 | T11: =T10+7 -> 36923 | AS11: 13821 | AT11: =AVERAGE(AS8:AS11) -> 14564.25
A12: 36544 | B12: 808 | C12: 7709 | D12: 394 | E12: 2818 | F12: 704 | G12: 3617 | H12: 535 | I12: 2616 | J12: 175 | K12: 670 | L12: 2614 | M12: 17430 | N12: 7737 | O12: 19721 | P12: 3887 | Q12: 12978 | R12: =P12+N12+L12 -> 14238 | T12: =T11+7 -> 36930 | AS12: 17171 | AT12: =AVERAGE(AS9:AS12) -> 15176
A13: 36909 | B13: 1032 | C13: 6176 | D13: 424 | E13: 2983 | F13: 988 | G13: 3525 | H13: 1032 | I13: 3213 | J13: 138 | K13: 781 | L13: 3614 | M13: 16678 | N13: 6654 | O13: 17667 | P13: 3553 | Q13: 13114 | R13: =P13+N13+L13 -> 13821 | T13: =T12+7 -> 36937 | AS13: 18232 | AT13: =AVERAGE(AS10:AS13) -> 16049
A14: 36551 | B14: 870 | C14: 7882 | D14: 424 | E14: 2888 | F14: 786 | G14: 3697 | H14: 442 | I14: 2767 | J14: 237 | K14: 673 | L14: 2704 | M14: 17907 | N14: 7579 | O14: 20673 | P14: 3593 | Q14: 13664 | R14: =P14+N14+L14 -> 13876 | T14: =T13+7 -> 36944 | AS14: 17897.9 | AT14: =AVERAGE(AS11:AS14) -> 16780.475
A15: 36916 | B15: 1107 | C15: 6332 | D15: 454 | E15: 3030 | F15: 973 | G15: 3642 | H15: 981 | I15: 3324 | J15: 182 | K15: 807 | L15: 3654 | M15: 17133 | N15: 7071 | O15: 18382 | P15: 6446 | Q15: 13996 | R15: =P15+N15+L15 -> 17171 | T15: =T14+7 -> 36951 | AS15: 17513 | AT15: =AVERAGE(AS12:AS15) -> 17703.475
A16: 36558 | B16: 959 | C16: 8037 | D16: 482 | E16: 2949 | F16: 831 | G16: 3840 | H16: 440 | I16: 2882 | J16: 188 | K16: 692 | L16: 2898 | M16: 18398 | N16: 7771 | O16: 21491 | P16: 3920 | Q16: 14289 | R16: =P16+N16+L16 -> 14589 | T16: =T15+7 -> 36958 | AS16: 16616 | AT16: =AVERAGE(AS13:AS16) -> 17564.725
A17: 36923 | B17: 1363 | C17: 6428 | D17: 543 | E17: 3092 | F17: 966 | G17: 3771 | H17: 960 | I17: 3390 | J17: 128 | K17: 839 | L17: 3960 | M17: 17521 | N17: 7569 | O17: 18913 | P17: 6703 | Q17: 14541 | R17: =P17+N17+L17 -> 18232 | T17: =T16+7 -> 36965 | AS17: 16074 | AT17: =AVERAGE(AS14:AS17) -> 17025.225
A18: 36565 | B18: 1027 | C18: 8168 | D18: 466 | E18: 3094 | F18: 800 | G18: 3955 | H18: 487 | I18: 2899.7 | J18: 176 | K18: 691.5 | L18: 2938 | M18: 18808 | N18: 7408 | O18: 22378.8 | P18: 3681 | Q18: 15192.5 | R18: =P18+N18+L18 -> 14027 | T18: =T17+7 -> 36972 | AS18: 15586 | AT18: =AVERAGE(AS15:AS18) -> 16447.25
A19: 36930 | B19: 1291 | C19: 6664.7 | D19: 509 | E19: 3184 | F19: 933 | G19: 3936 | H19: 975 | I19: 3507 | J19: 124 | K19: 842.4 | L19: 3833 | M19: 18134 | N19: 7584.9 | O19: 20055 | P19: 6480 | Q19: 15501.8 | R19: =P19+N19+L19 -> 17897.9 | T19: =T18+7 -> 36979 | AS19: 15109 | AT19: =AVERAGE(AS16:AS19) -> 15846.25
A20: 36572 | B20: 984 | C20: 8405 | D20: 488 | E20: 3171 | F20: 921 | G20: 4057 | H20: 489 | I20: 2970 | J20: 166 | K20: 703 | L20: 3047 | M20: 19306 | N20: 7423 | O20: 23257.5 | P20: 4002 | Q20: 15857 | R20: =P20+N20+L20 -> 14472 | T20: =T19+7 -> 36986 | AS20: 13770 | AT20: =AVERAGE(AS17:AS20) -> 15134.75
A21: 36937 | B21: 1260 | C21: 6814.9 | D21: 482 | E21: 3279 | F21: 870 | G21: 4048 | H21: 902 | I21: 3595 | J21: 163 | K21: 842 | L21: 3677 | M21: 18580 | N21: 7576 | O21: 20800 | P21: 6260 | Q21: 16306 | R21: =P21+N21+L21 -> 17513 | T21: =T20+7 -> 36993 | AS21: 12883 | AT21: =AVERAGE(AS18:AS21) -> 14337
... A60: 36713 | B60: 1052 | C60: 896 | D60: 551 | E60: 547 | F60: 787 | G60: 573 | H60: 604 | I60: 387 | J60: 239 | K60: 28 | L60: 3233 | M60: 2431 | N60: 6820 | O60: 40757 | P60: 2197 | Q60: 24063 | R60: =P60+N60+L60 -> 12250 | T60: =T59+7 -> 37266 | AS60: 18002 | AT60: =AVERAGE(AS57:AS60) -> 19147.75
A61: 37077 | B61: 1011 | C61: 737 | D61: 634 | E61: 342 | F61: 854 | G61: 406 | H61: 481 | I61: 268 | J61: 219 | K61: 83 | L61: 3198 | M61: 1835 | N61: 7384 | O61: 37918 | P61: 2029 | Q61: 25429 | R61: =P61+N61+L61 -> 12611 | T61: =T60+7 -> 37273 | AS61: 18280 | AT61: =AVERAGE(AS58:AS61) -> 18812 | AU61: =(AT61/AS9)*100 -> 127.62551
A62: 36720 | B62: 964 | C62: 1193 | D62: 564 | E62: 686 | F62: 828 | G62: 656 | H62: 645 | I62: 413 | J62: 239 | K62: 58 | L62: 3239 | M62: 3005 | N62: 6716 | O62: 41668 | P62: 1993 | Q62: 24479 | R62: =P62+N62+L62 -> 11948 | T62: =T61+7 -> 37280 | AS62: 18509 | AT62: =AVERAGE(AS59:AS62) -> 18504.75 | AU62: =(AT62/AS10)*100 -> 123.59571
A63: 37084 | B63: 1072 | C63: 870 | D63: 697 | E63: 443 | F63: 844 | G63: 476 | H63: 534 | I63: 308 | J63: 240 | K63: 95 | L63: 3386 | M63: 2193 | N63: 7550 | O63: 39080 | P63: 2092 | Q63: 25633 | R63: =P63+N63+L63 -> 13028 | T63: =T62+7 -> 37287 | AS63: 18402 | AT63: =AVERAGE(AS60:AS63) -> 18298.25 | AU63: =(AT63/AS11)*100 -> 132.39454
A64: 36727 | B64: 1143 | C64: 1335 | D64: 512 | E64: 806 | F64: 839 | G64: 756 | H64: 789 | I64: 427 | J64: 354 | K64: 100 | L64: 3637 | M64: 3423 | N64: 6478 | O64: 42560 | P64: 1923 | Q64: 24800 | R64: =P64+N64+L64 -> 12038 | T64: =T63+7 -> 37294 | AS64: 18217 | AT64: =AVERAGE(AS61:AS64) -> 18352 | AU64: =(AT64/AS12)*100 -> 106.87788
A65: 37091 | B65: 1253 | C65: 1042 | D65: 797 | E65: 512 | F65: 820 | G65: 610 | H65: 528 | I65: 339 | J65: 288 | K65: 97 | L65: 3687 | M65: 2599 | N65: 7934 | O65: 39922 | P65: 1907 | Q65: 25829 | R65: =P65+N65+L65 -> 13528 | T65: =T64+7 -> 37301 | AS65: 18012 | AT65: =AVERAGE(AS62:AS65) -> 18285 | AU65: =(AT65/AS13)*100 -> 100.2907
A66: 36734 | B66: 1136 | C66: 1500 | D66: 543 | E66: 848 | F66: 804 | G66: 883 | H66: 761 | I66: 491 | J66: 318 | K66: 146 | L66: 3562 | M66: 3869 | N66: 6116 | O66: 43461 | P66: 1788 | Q66: 25175 | R66: =P66+N66+L66 -> 11466 | T66: =T65+7 -> 37308 | AS66: 17256 | AT66: =AVERAGE(AS63:AS66) -> 17971.75 | AU66: =(AT66/AS14)*100 -> 100.41262
A67: 37098 | B67: 1307 | C67: 1131 | D67: 818 | E67: 570 | F67: 908 | G67: 665 | H67: 586 | I67: 356 | J67: 256 | K67: 143 | L67: 3873 | M67: 2865 | N67: 7111 | O67: 41067 | P67: 1899 | Q67: 26067 | R67: =P67+N67+L67 -> 12883 | T67: =T66+7 -> 37315 | AS67: 16435 | AT67: =AVERAGE(AS64:AS67) -> 17480 | AU67: =(AT67/AS15)*100 -> 99.811569
A68: 36741 | B68: 1215 | C68: 1691 | D68: 651 | E68: 934 | F68: 901 | G68: 957 | H68: 1038 | I68: 637 | J68: 343 | K68: 163 | L68: 4148 | M68: 4382 | N68: 5766 | O68: 44317 | P68: 1635 | Q68: 25625 | R68: =P68+N68+L68 -> 11549 | T68: =T67+7 -> 37322 | AS68: 14784 | AT68: =AVERAGE(AS65:AS68) -> 16621.75 | AU68: =(AT68/AS16)*100 -> 100.03461
A69: 37105 | B69: 1247 | C69: 1319 | D69: 868 | E69: 730 | F69: 881 | G69: 811 | H69: 499 | I69: 449 | J69: 289 | K69: 186 | L69: 3784 | M69: 3495 | N69: 6466 | O69: 42327 | P69: 1790 | Q69: 26337 | R69: =P69+N69+L69 -> 12040 | T69: =T68+7 -> 37329 | AS69: 14179 | AT69: =AVERAGE(AS66:AS69) -> 15663.5 | AU69: =(AT69/AS17)*100 -> 97.446186
A70: 36748 | B70: 1273 | C70: 1915 | D70: 727 | E70: 1029.5 | F70: 978 | G70: 1029 | H70: 963 | I70: 778 | J70: 308 | K70: 201 | L70: 4248 | M70: 4952 | N70: 5388 | O70: 44949 | P70: 1360 | Q70: 25991 | R70: =P70+N70+L70 -> 10996 | T70: =T69+7 -> 37336 | AS70: 13621 | AT70: =AVERAGE(AS67:AS70) -> 14754.75 | AU70: =(AT70/AS18)*100 -> 94.666688
A71: 37112 | B71: 1398 | C71: 1375 | D71: 1047 | E71: 834 | F71: 974 | G71: 866 | H71: 474 | I71: 531 | J71: 343 | K71: 204 | L71: 4235 | M71: 3809 | N71: 5807 | O71: 43648 | P71: 1521 | Q71: 26586 | R71: =P71+N71+L71 -> 11563 | T71: =T70+7 -> 37343 | AS71: 13276 | AT71: =AVERAGE(AS68:AS71) -> 13965 | AU71: =(AT71/AS19)*100 -> 92.428354
A72: 36755 | B72: 1440 | C72: 2120 | D72: 694 | E72: 1099 | F72: 992 | G72: 1096 | H72: 949 | I72: 882 | J72: 299 | K72: 273 | L72: 4375 | M72: 5469 | N72: 4296 | O72: 46181 | P72: 1050 | Q72: 26331 | R72: =P72+N72+L72 -> 9721 | T72: =T71+7 -> 37350 | AS72: 12522 | AT72: =AVERAGE(AS69:AS72) -> 13399.5 | AU72: =(AT72/AS20)*100 -> 97.309368
... A215: 37616 | B215: 1083 | C215: 4581 | D215: 730 | E215: 1546 | F215: 1230 | G215: 4104 | H215: 618 | I215: 2068 | J215: 123 | K215: 518 | L215: 3783 | M215: 12818 | N215: 6561 | O215: 13037 | P215: 8262 | Q215: 11347 | R215: =P215+N215+L215 -> 18606 | T215: =T214+7 -> 38351 | AS215: 16240 | AT215: =AVERAGE(AS212:AS215) -> 17342.5 | AU215: =(AT215/AS163)*100 -> 73.9237
A216: 37259 | B216: 1124 | C216: 5046 | D216: 633 | E216: 3534 | F216: 936 | G216: 3316 | H216: 617 | I216: 1934 | J216: 124 | K216: 800 | L216: 3433 | M216: 14629 | N216: 6830 | O216: 14456 | P216: 7739 | Q216: 12986 | R216: =P216+N216+L216 -> 18002 | T216: =T215+7 -> 38358 | U216: ='copy data3'!B270 -> 1479 | V216: =AVERAGE(U213:U216) -> 1479 | W216: =(V216/U164)*100 -> #DIV/0! | X216: ='copy data3'!D270 -> 367 | Y216: =AVERAGE(X213:X216) -> 367 | Z216: =(Y216/X164)*100 -> #DIV/0! | AA216: ='copy data3'!F270 -> 1096 | AB216: =AVERAGE(AA213:AA216) -> 1096 | AC216: =(AB216/AA164)*100 -> #DIV/0! | AD216: ='copy data3'!H270 -> 735 | AE216: =AVERAGE(AD213:AD216) -> 735 | AF216: =(AE216/AD164)*100 -> #DIV/0! | AG216: ='copy data3'!J270 -> 115 | AH216: =AVERAGE(AG213:AG216) -> 115 | AI216: =(AH216/AG164)*100 -> #DIV/0! | AJ216: ='copy data3'!L270 -> 3792 | AK216: =AVERAGE(AJ213:AJ216) -> 3792 | AL216: =(AK216/AJ164)*100 -> #DIV/0! | AM216: ='copy data3'!N270 -> 6999 | AN216: =AVERAGE(AM213:AM216) -> 6999 | AO216: =(AN216/AM164)*100 -> #DIV/0! | AP216: ='copy data3'!P270 -> 5692 | AQ216: =AVERAGE(AP213:AP216) -> 5692 | AR216: =(AQ216/AP164)*100 -> #DIV/0! | AS216: ='copy data3'!R270 -> 16483 | AT216: =AVERAGE(AS213:AS216) -> 16968 | AU216: =(AT216/AS164)*100 -> 74.33954
A217: 37623 | B217: 1017 | C217: 4682 | D217: 580 | E217: 1707 | F217: 1161 | G217: 4244 | H217: 535 | I217: 2181 | J217: 123 | K217: 518 | L217: 3415 | M217: 13332 | N217: 5860 | O217: 13997 | P217: 7980 | Q217: 12015 | R217: =P217+N217+L217 -> 17255 | T217: =T216+7 -> 38365 | U217: ='copy data3'!B271 -> 1448 | V217: =AVERAGE(U214:U217) -> 1463.5 | W217: =(V217/U165)*100 -> #DIV/0! | X217: ='copy data3'!D271 -> 383 | Y217: =AVERAGE(X214:X217) -> 375 | Z217: =(Y217/X165)*100 -> #DIV/0! | AA217: ='copy data3'!F271 -> 1230 | AB217: =AVERAGE(AA214:AA217) -> 1163 | AC217: =(AB217/AA165)*100 -> #DIV/0! | AD217: ='copy data3'!H271 -> 686 | AE217: =AVERAGE(AD214:AD217) -> 710.5 | AF217: =(AE217/AD165)*100 -> #DIV/0! | AG217: ='copy data3'!J271 -> 129 | AH217: =AVERAGE(AG214:AG217) -> 122 | AI217: =(AH217/AG165)*100 -> #DIV/0! | AJ217: ='copy data3'!L271 -> 3874 | AK217: =AVERAGE(AJ214:AJ217) -> 3833 | AL217: =(AK217/AJ165)*100 -> #DIV/0! | AM217: ='copy data3'!N271 -> 7157 | AN217: =AVERAGE(AM214:AM217) -> 7078 | AO217: =(AN217/AM165)*100 -> #DIV/0! | AP217: ='copy data3'!P271 -> 5732 | AQ217: =AVERAGE(AP214:AP217) -> 5712 | AR217: =(AQ217/AP165)*100 -> #DIV/0! | AS217: ='copy data3'!R271 -> 16763 | AT217: =AVERAGE(AS214:AS217) -> 16718.5 | AU217: =(AT217/AS165)*100 -> 85.881235
A218: 37266 | B218: 1003 | C218: 5279 | D218: 693 | E218: 3568 | F218: 943 | G218: 3404 | H218: 592 | I218: 1996 | J218: 124 | K218: 800 | L218: 3354 | M218: 15046 | N218: 7110 | O218: 15092 | P218: 7816 | Q218: 14039 | R218: =P218+N218+L218 -> 18280 | T218: =T217+7 -> 38372 | U218: ='copy data3'!B272 -> 1386 | V218: =AVERAGE(U215:U218) -> 1437.6667 | W218: =(V218/U166)*100 -> #DIV/0! | X218: ='copy data3'!D272 -> 392 | Y218: =AVERAGE(X215:X218) -> 380.66667 | Z218: =(Y218/X166)*100 -> #DIV/0! | AA218: ='copy data3'!F272 -> 1192 | AB218: =AVERAGE(AA215:AA218) -> 1172.6667 | AC218: =(AB218/AA166)*100 -> #DIV/0! | AD218: ='copy data3'!H272 -> 590 | AE218: =AVERAGE(AD215:AD218) -> 670.33333 | AF218: =(AE218/AD166)*100 -> #DIV/0! | AG218: ='copy data3'!J272 -> 105 | AH218: =AVERAGE(AG215:AG218) -> 116.33333 | AI218: =(AH218/AG166)*100 -> #DIV/0! | AJ218: ='copy data3'!L272 -> 3664 | AK218: =AVERAGE(AJ215:AJ218) -> 3776.6667 | AL218: =(AK218/AJ166)*100 -> #DIV/0! | AM218: ='copy data3'!N272 -> 6840 | AN218: =AVERAGE(AM215:AM218) -> 6998.6667 | AO218: =(AN218/AM166)*100 -> #DIV/0! | AP218: ='copy data3'!P272 -> 5116 | AQ218: =AVERAGE(AP215:AP218) -> 5513.3333 | AR218: =(AQ218/AP166)*100 -> #DIV/0! | AS218: ='copy data3'!R272 -> 15620 | AT218: =AVERAGE(AS215:AS218) -> 16276.5 | AU218: =(AT218/AS166)*100 -> 77.264312
A219: 37630 | B219: 951 | C219: 4785 | D219: 527 | E219: 1893 | F219: 1103 | G219: 4400 | H219: 526 | I219: 2309 | J219: 113 | K219: 525 | L219: 3220 | M219: 13911 | N219: 5635 | O219: 14848 | P219: 8278 | Q219: 13082 | R219: =P219+N219+L219 -> 17133 | T219: =T218+7 -> 38379 | U219: ='copy data3'!B273 -> 1562 | V219: =AVERAGE(U216:U219) -> 1468.75 | W219: =(V219/U167)*100 -> #DIV/0! | X219: ='copy data3'!D273 -> 389 | Y219: =AVERAGE(X216:X219) -> 382.75 | Z219: =(Y219/X167)*100 -> #DIV/0! | AA219: ='copy data3'!F273 -> 1220 | AB219: =AVERAGE(AA216:AA219) -> 1184.5 | AC219: =(AB219/AA167)*100 -> #DIV/0! | AD219: ='copy data3'!H273 -> 604 | AE219: =AVERAGE(AD216:AD219) -> 653.75 | AF219: =(AE219/AD167)*100 -> #DIV/0! | AG219: ='copy data3'!J273 -> 111 | AH219: =AVERAGE(AG216:AG219) -> 115 | AI219: =(AH219/AG167)*100 -> #DIV/0! | AJ219: ='copy data3'!L273 -> 3886 | AK219: =AVERAGE(AJ216:AJ219) -> 3804 | AL219: =(AK219/AJ167)*100 -> #DIV/0! | AM219: ='copy data3'!N273 -> 6257 | AN219: =AVERAGE(AM216:AM219) -> 6813.25 | AO219: =(AN219/AM167)*100 -> #DIV/0! | AP219: ='copy data3'!P273 -> 4951 | AQ219: =AVERAGE(AP216:AP219) -> 5372.75 | AR219: =(AQ219/AP167)*100 -> #DIV/0! | AS219: ='copy data3'!R273 -> 15094 | AT219: =AVERAGE(AS216:AS219) -> 15990 | AU219: =(AT219/AS167)*100 -> 77.216535
A220: 37273 | B220: 1192 | C220: 5454 | D220: 702 | E220: 3639 | F220: 934 | G220: 3554 | H220: 595 | I220: 2057 | J220: 132 | K220: 810 | L220: 3555 | M220: 15514 | N220: 7432 | O220: 16017 | P220: 7522 | Q220: 15087 | R220: =P220+N220+L220 -> 18509 | T220: =T219+7 -> 38386 | U220: ='copy data3'!B274 -> 1640 | V220: =AVERAGE(U217:U220) -> 1509 | W220: =(V220/U168)*100 -> #DIV/0! | X220: ='copy data3'!D274 -> 389 | Y220: =AVERAGE(X217:X220) -> 388.25 | Z220: =(Y220/X168)*100 -> #DIV/0! | AA220: ='copy data3'!F274 -> 1249 | AB220: =AVERAGE(AA217:AA220) -> 1222.75 | AC220: =(AB220/AA168)*100 -> #DIV/0! | AD220: ='copy data3'!H274 -> 616 | AE220: =AVERAGE(AD217:AD220) -> 624 | AF220: =(AE220/AD168)*100 -> #DIV/0! | AG220: ='copy data3'!J274 -> 114 | AH220: =AVERAGE(AG217:AG220) -> 114.75 | AI220: =(AH220/AG168)*100 -> #DIV/0! | AJ220: ='copy data3'!L274 -> 4007 | AK220: =AVERAGE(AJ217:AJ220) -> 3857.75 | AL220: =(AK220/AJ168)*100 -> #DIV/0! | AM220: ='copy data3'!N274 -> 6744 | AN220: =AVERAGE(AM217:AM220) -> 6749.5 | AO220: =(AN220/AM168)*100 -> #DIV/0! | AP220: ='copy data3'!P274 -> 4807 | AQ220: =AVERAGE(AP217:AP220) -> 5151.5 | AR220: =(AQ220/AP168)*100 -> #DIV/0! | AS220: ='copy data3'!R274 -> 15558 | AT220: =AVERAGE(AS217:AS220) -> 15758.75 | AU220: =(AT220/AS168)*100 -> 77.732699
...

Sheet copy data2
A1: New Table12
A2: FAS - Accumulated Grain Export Sales | AH2: COMPARISON - SALES & EXPORTS
A3: Metric Tons | S3: EXTEND RANGE in L..N | AH3: OUTSTANDING EXPORT SALES AND EXPORTS - CURRENT MARKETING YEAR
A4: Crop Year-Wheat=6/01-5/31; Corn & Soybeans=9/01-8/31; | R4: 3 Crop | S4: each week FOR GRAPHIC | AH4: SUMMARY AND COMPARISON OF SELECTED COMMODITIES 1/
B5: HRW | D5: SRW | F5: HRS | H5: SWW | J5: DUR | L5: All Wheat | N5: Corn | P5: Soybean | R5: Total | S5: Accum | U5: All 3 Crops | V5: Outstd | W5: Accum | Y5: Outstd | AB5: Cumulative | AH5: ---------------------- | AI5: --------- | AJ5: --------- | AK5: ------------ | AL5: --------- | AM5: ---------
B6: Outstd | C6: Accum | D6: Outstd | E6: Accum | F6: Outstd | G6: Accum | H6: Outstd | I6: Accum | J6: Outstd | K6: Accum | L6: Outstd | M6: Accum | N6: Outstd | O6: Accum | P6: Outstd | Q6: Accum | S6: Week | T6: Date | U6: Outstd | V6: 4-wk average | W6: 4-wk average | X6: Corn | Y6: Soybeans | Z6: Wheat | AA6: Corn | AB6: Soybeans | AC6: Wheat | AH6: : WEEK | AI6: : OUT- | AJ6: :WEEKLY | AK6: :CUMULATIVE | AL6: EXPORTS: | AM6: TOTAL :
A7: 36523 | B7: 894 | C7: 7280 | D7: 642 | E7: 2514 | F7: 801 | G7: 3375 | H7: 721 | I7: 2326 | J7: 255 | K7: 563 | L7: 3312 | M7: 16058 | N7: 7894 | O7: 17010 | P7: 4521 | Q7: 11070 | R7: =L7+N7+P7 -> 15727 | S7: =M7+O7+Q7 -> 44138 | T7: Dec. 00 | U7: 15727 | AH7: COMMODITY : END- | AI7: :STANDIN | AJ7: G:EXPORTS | AK7: : FO | AL7: R : | AM7: COMMIT-:
A8: 36888 | B8: 998 | C8: 5836 | D8: 295 | E8: 2759 | F8: 923 | G8: 3301 | H8: 666 | I8: 3023 | J8: 170 | K8: 737 | L8: 3047 | M8: 15656 | N8: 6697 | O8: 15269 | P8: 6104 | Q8: 11059 | R8: =L8+N8+P8 -> 15848 | S8: =M8+O8+Q8 -> 41984 | T8: Dec. 00 | U8: 15848 | AH8: : ING | AI8: : SALES | AJ8: : | AK8: : MARKETIN | AL8: G YEAR : | AM8: MENT 2/:
A9: 01/05/2000 | B9: 854 | C9: 7364 | D9: 523 | E9: 2644 | F9: 707 | G9: 3493 | H9: 638 | I9: 2455 | J9: 206 | K9: 619 | L9: 2928 | M9: 16575 | N9: 7360 | O9: 17826 | P9: 4436 | Q9: 11672 | R9: =L9+N9+P9 -> 14724 | S9: =M9+O9+Q9 -> 46073 | T9: Dec. 00 | U9: 14724 | AH9: ---------------------- | AI9: --------- | AJ9: --------- | AK9: ------------ | AL9: --------- | AM9: ---------
A10: 01/04/2001 | B10: 906 | C10: 5946 | D10: 179 | E10: 2898 | F10: 920 | G10: 3379 | H10: 596 | I10: 3132 | J10: 173 | K10: 748 | L10: 2775 | M10: 16103 | N10: 6253 | O10: 15898 | P10: 5712 | Q10: 11894 | R10: =L10+N10+P10 -> 14740 | S10: =M10+O10+Q10 -> 43895 | T10: Jan. 01 | U10: 14740 | V10: =AVERAGE(U7:U10) -> 15259.75 | W10: =AVERAGE(S7:S10) -> 44022.5 | AH10: : | AJ10: 1000 | AL10: MILLION | AM10: 10
A11: 36537 | B11: 780.4 | C11: 7583.5 | D11: 430.7 | E11: 2745 | F11: 687 | G11: 3564 | H11: 589 | I11: 2535 | J11: 224 | K11: 619 | L11: 2711 | M11: 17047 | N11: 7487 | O11: 18837 | P11: 4338 | Q11: 12360 | R11: =L11+N11+P11 -> 14536 | S11: =M11+O11+Q11 -> 48244 | T11: Jan. 01 | U11: 14536 | V11: =AVERAGE(U8:U11) -> 14962 | W11: =AVERAGE(S8:S11) -> 45049 | AH11: : | AI11: ------ | AJ11: METRIC T | AK11: ONS ------ | AL11: BUSHELS | AM11: =-- METR -> #NAME?
A12: 36902 | B12: 998 | C12: 6063.2 | D12: 259 | E12: 2933 | F12: 894 | G12: 3499 | H12: 604 | I12: 3159 | J12: 141 | K12: 781 | L12: 2896 | M12: 16432.5 | N12: 5936 | O12: 16827 | P12: 6140 | Q12: 12416 | R12: =L12+N12+P12 -> 14972 | S12: =M12+O12+Q12 -> 45675.5 | T12: Jan. 01 | U12: 14972 | V12: =AVERAGE(U9:U12) -> 14743 | W12: =AVERAGE(S9:S12) -> 45971.875 | AH12: HARD RED WINTER: 12/13 | AI12: 4228.7 | AJ12: 161.9 | AK12: 7955.7 | AL12: 292.3 | AM12: 12184.4
A13: 36544 | B13: 808 | C13: 7709 | D13: 394 | E13: 2818 | F13: 704 | G13: 3617 | H13: 535 | I13: 2616 | J13: 175 | K13: 670 | L13: 2614 | M13: 17430 | N13: 7737 | O13: 19721 | P13: 3887 | Q13: 12978 | R13: =L13+N13+P13 -> 14238 | S13: =M13+O13+Q13 -> 50129 | T13: Jan. 01 | U13: 14238 | V13: =AVERAGE(U10:U13) -> 14621.5 | W13: =AVERAGE(S10:S13) -> 46985.875 | AH13: WHEAT : 12/20 | AI13: 4080.7 | AJ13: 178.4 | AK13: 8134.2 | AL13: 298.9 | AM13: 12214.8
A14: 36909 | B14: 1032 | C14: 6176 | D14: 424 | E14: 2983 | F14: 988 | G14: 3525 | H14: 1032 | I14: 3213 | J14: 138 | K14: 781 | L14: 3614 | M14: 16678 | N14: 6654 | O14: 17667 | P14: 3553 | Q14: 13114 | R14: =L14+N14+P14 -> 13821 | S14: =M14+O14+Q14 -> 47459 | T14: Feb. 01 | U14: 13821 | V14: =AVERAGE(U11:U14) -> 14391.75 | W14: =AVERAGE(S11:S14) -> 47876.875 | AH14: :YR AGO | AI14: 1681.3 | AJ14: 160.9 | AK14: 3151.8 | AL14: 115.8 | AM14: 4833.1
A15: 36551 | B15: 870 | C15: 7882 | D15: 424 | E15: 2888 | F15: 786 | G15: 3697 | H15: 442 | I15: 2767 | J15: 237 | K15: 673 | L15: 2704 | M15: 17907 | N15: 7579 | O15: 20673 | P15: 3593 | Q15: 13664 | R15: =L15+N15+P15 -> 13876 | S15: =M15+O15+Q15 -> 52244 | T15: Feb. 01 | U15: 13876 | V15: =AVERAGE(U12:U15) -> 14226.75 | W15: =AVERAGE(S12:S15) -> 48876.875 | AH15: :
A16: 36916 | B16: 1107 | C16: 6332 | D16: 454 | E16: 3030 | F16: 973 | G16: 3642 | H16: 981 | I16: 3324 | J16: 182 | K16: 807 | L16: 3654 | M16: 17133 | N16: 7071 | O16: 18382 | P16: 6446 | Q16: 13996 | R16: =L16+N16+P16 -> 17171 | S16: =M16+O16+Q16 -> 49511 | T16: Feb. 01 | U16: 17171 | V16: =AVERAGE(U13:U16) -> 14776.5 | W16: =AVERAGE(S13:S16) -> 49835.75 | AH16: SOFT RED WINTER: 12/13 | AI16: 830.2 | AJ16: 37.2 | AK16: 4053.3 | AL16: 148.9 | AM16: 4883.5
A17: 36558 | B17: 959 | C17: 8037 | D17: 482 | E17: 2949 | F17: 831 | G17: 3840 | H17: 440 | I17: 2882 | J17: 188 | K17: 692 | L17: 2898 | M17: 18398 | N17: 7771 | O17: 21491 | P17: 3920 | Q17: 14289 | R17: =L17+N17+P17 -> 14589 | S17: =M17+O17+Q17 -> 54178 | T17: Feb. 01 | U17: 14589 | V17: =AVERAGE(U14:U17) -> 14864.25 | W17: =AVERAGE(S14:S17) -> 50848 | AH17: WHEAT : 12/20 | AI17: 818 | AJ17: 14.3 | AK17: 4067.5 | AL17: 149.5 | AM17: 4885.5
A18: 36923 | B18: 1363 | C18: 6428 | D18: 543 | E18: 3092 | F18: 966 | G18: 3771 | H18: 960 | I18: 3390 | J18: 128 | K18: 839 | L18: 3960 | M18: 17521 | N18: 7569 | O18: 18913 | P18: 6703 | Q18: 14541 | R18: =L18+N18+P18 -> 18232 | S18: =M18+O18+Q18 -> 50975 | T18: Mar. 01 | U18: 18232 | V18: =AVERAGE(U15:U18) -> 15967 | W18: =AVERAGE(S15:S18) -> 51727 | AH18: :YR AGO | AI18: 552.6 | AJ18: 11.3 | AK18: 1987.4 | AL18: 73 | AM18: 2540
A19: 36565 | B19: 1027 | C19: 8168 | D19: 466 | E19: 3094 | F19: 800 | G19: 3955 | H19: 487 | I19: 2899.7 | J19: 176 | K19: 691.5 | L19: 2938 | M19: 18808 | N19: 7408 | O19: 22378.8 | P19: 3681 | Q19: 15192.5 | R19: =L19+N19+P19 -> 14027 | S19: =M19+O19+Q19 -> 56379.3 | T19: Mar. 01 | U19: 14027 | V19: =AVERAGE(U16:U19) -> 16004.75 | W19: =AVERAGE(S16:S19) -> 52760.825 | AH19: :
A20: 36930 | B20: 1291 | C20: 6664.7 | D20: 509 | E20: 3184 | F20: 933 | G20: 3936 | H20: 975 | I20: 3507 | J20: 124 | K20: 842.4 | L20: 3833 | M20: 18134 | N20: 7584.9 | O20: 20055 | P20: 6480 | Q20: 15501.8 | R20: =L20+N20+P20 -> 17897.9 | S20: =M20+O20+Q20 -> 53690.8 | T20: Mar. 01 | U20: 17897.9 | V20: =AVERAGE(U17:U20) -> 16186.475 | W20: =AVERAGE(S17:S20) -> 53805.775 | AH20: HARD RED SPRING: 12/13 | AI20: 2352.8 | AJ20: 183.4 | AK20: 4653.1 | AL20: 171 | AM20: 7005.9
A21: 36572 | B21: 984 | C21: 8405 | D21: 488 | E21: 3171 | F21: 921 | G21: 4057 | H21: 489 | I21: 2970 | J21: 166 | K21: 703 | L21: 3047 | M21: 19306 | N21: 7423 | O21: 23257.5 | P21: 4002 | Q21: 15857 | R21: =L21+N21+P21 -> 14472 | S21: =M21+O21+Q21 -> 58420.5 | T21: Mar. 01 | U21: 14472 | V21: =AVERAGE(U18:U21) -> 16157.225 | W21: =AVERAGE(S18:S21) -> 54866.4 | AH21: WHEAT : 12/20 | AI21: 2419.9 | AJ21: 102.7 | AK21: 4755.8 | AL21: 174.7 | AM21: 7175.7
A22: 36937 | B22: 1260 | C22: 6814.9 | D22: 482 | E22: 3279 | F22: 870 | G22: 4048 | H22: 902 | I22: 3595 | J22: 163 | K22: 842 | L22: 3677 | M22: 18580 | N22: 7576 | O22: 20800 | P22: 6260 | Q22: 16306 | R22: =L22+N22+P22 -> 17513 | S22: =M22+O22+Q22 -> 55686 | T22: Mar. 01 | U22: 17513 | V22: =AVERAGE(U19:U22) -> 15977.475 | W22: =AVERAGE(S19:S22) -> 56044.15 | AH22: :YR AGO | AI22: 1280.2 | AJ22: 74.2 | AK22: 3622 | AL22: 133.1 | AM22: 4902.2
A23: 36579 | B23: 943 | C23: 8540 | D23: 385 | E23: 3286 | F23: 910 | G23: 4134 | H23: 482 | I23: 3035 | J23: 155 | K23: 713 | L23: 2875 | M23: 19709 | N23: 7517 | O23: 24291 | P23: 3938 | Q23: 16479 | R23: =L23+N23+P23 -> 14330 | S23: =M23+O23+Q23 -> 60479 | T23: Apr. 01 | U23: 14330 | V23: =AVERAGE(U20:U23) -> 16053.225 | W23: =AVERAGE(S20:S23) -> 57069.075 | AH23: :
A24: 36944 | B24: 1176 | C24: 7056 | D24: 404 | E24: 3411 | F24: 867 | G24: 4231 | H24: 941 | I24: 3737 | J24: 174 | K24: 867 | L24: 3560 | M24: 19302 | N24: 7303 | O24: 21728 | P24: 5753 | Q24: 17326 | R24: =L24+N24+P24 -> 16616 | S24: =M24+O24+Q24 -> 58356 | T24: Apr. 01 | U24: 16616 | V24: =AVERAGE(U21:U24) -> 15732.75 | W24: =AVERAGE(S21:S24) -> 58235.375 | AH24: WHITE WHEAT : 12/13 | AI24: 1361.4 | AJ24: 109.4 | AK24: 2477.9 | AL24: 91 | AM24: 3839.3
A25: 36586 | B25: 942 | C25: 8687 | D25: 401 | E25: 3371 | F25: 1009 | G25: 4209 | H25: 557 | I25: 3076 | J25: 247 | K25: 741 | L25: 3156 | M25: 20084 | N25: 8148 | O25: 25033 | P25: 3852 | Q25: 17091 | R25: =L25+N25+P25 -> 15156 | S25: =M25+O25+Q25 -> 62208 | T25: Apr. 01 | U25: 15156 | V25: =AVERAGE(U22:U25) -> 15903.75 | W25: =AVERAGE(S22:S25) -> 59182.25 | AH25: : 12/20 | AI25: 1372.4 | AJ25: 79.8 | AK25: 2557.7 | AL25: 94 | AM25: 3930.1
A26: 36951 | B26: 1204 | C26: 7191 | D26: 387 | E26: 3552 | F26: 847 | G26: 4318 | H26: 910 | I26: 3862 | J26: 182 | K26: 868 | L26: 3530 | M26: 19792 | N26: 7415 | O26: 22492 | P26: 5129 | Q26: 18173 | R26: =L26+N26+P26 -> 16074 | S26: =M26+O26+Q26 -> 60457 | T26: Apr. 01 | U26: 16074 | V26: =AVERAGE(U23:U26) -> 15544 | W26: =AVERAGE(S23:S26) -> 60375 | AH26: :YR AGO | AI26: 1032.6 | AJ26: 26 | AK26: 2615.7 | AL26: 96.1 | AM26: 3648.2
A27: 36593 | B27: 1009 | C27: 8792 | D27: 438 | E27: 3371 | F27: 1037 | G27: 4336 | H27: 562 | I27: 3121 | J27: 290 | K27: 749 | L27: 3336 | M27: 20368 | N27: 7952 | O27: 25999 | P27: 3223 | Q27: 18093 | R27: =L27+N27+P27 -> 14511 | S27: =M27+O27+Q27 -> 64460 | T27: May. 01 | U27: 14511 | V27: =AVERAGE(U24:U27) -> 15589.25 | W27: =AVERAGE(S24:S27) -> 61370.25 | AH27: :
A28: 36958 | B28: 1075 | C28: 7404 | D28: 399 | E28: 3613 | F28: 899 | G28: 4420 | H28: 798 | I28: 4035 | J28: 195 | K28: 874 | L28: 3365 | M28: 20346 | N28: 7488 | O28: 23341 | P28: 4733 | Q28: 19089 | R28: =L28+N28+P28 -> 15586 | S28: =M28+O28+Q28 -> 62776 | T28: May. 01 | U28: 15586 | V28: =AVERAGE(U25:U28) -> 15331.75 | W28: =AVERAGE(S25:S28) -> 62475.25 | AH28: DURUM WHEAT : 12/13 | AI28: 173 | AJ28: 32 | AK28: 766 | AL28: 28.1 | AM28: 938.9
A29: 36601 | B29: 1068 | C29: 8875 | D29: 321 | E29: 3523 | F29: 1045 | G29: 4389 | H29: 600 | I29: 3146 | J29: 276 | K29: 775 | L29: 3310 | M29: 20709 | N29: 7537 | O29: 26906 | P29: 2941 | Q29: 18747 | R29: =L29+N29+P29 -> 13788 | S29: =M29+O29+Q29 -> 66362 | T29: May. 01 | U29: 13788 | V29: =AVERAGE(U26:U29) -> 14989.75 | W29: =AVERAGE(S26:S29) -> 63513.75 | AH29: : 12/20 | AI29: 173 | AJ29: 6.1 | AK29: 772.1 | AL29: 28.4 | AM29: 945
A30: 36965 | B30: 1121 | C30: 7517 | D30: 387 | E30: 3648 | F30: 1012 | G30: 4490 | H30: 845 | I30: 4073 | J30: 261 | K30: 878 | L30: 3626 | M30: 20606 | N30: 7315 | O30: 24160 | P30: 4168 | Q30: 19950 | R30: =L30+N30+P30 -> 15109 | S30: =M30+O30+Q30 -> 64716 | T30: May. 01 | U30: 15109 | V30: =AVERAGE(U27:U30) -> 14748.5 | W30: =AVERAGE(S27:S30) -> 64578.5 | AH30: :YR AGO | AI30: 83.4 | AJ30: 19.6 | AK30: 533.9 | AL30: 19.6 | AM30: 617.3
A31: 36608 | B31: 1028 | C31: 8982 | D31: 308 | E31: 3586 | F31: 1117 | G31: 4489 | H31: 622 | I31: 3192 | J31: 254 | K31: 797 | L31: 3229 | M31: 21047 | N31: 7316 | O31: 27895 | P31: 2514 | Q31: 19444 | R31: =L31+N31+P31 -> 13059 | S31: =M31+O31+Q31 -> 68386 | T31: May. 01 | U31: 13059 | V31: =AVERAGE(U28:U31) -> 14385.5 | W31: =AVERAGE(S28:S31) -> 65560 | AH31: :
A32: 36972 | B32: 1182 | C32: 7626 | D32: 471 | E32: 3670 | F32: 1092 | G32: 4529 | H32: 859 | I32: 4136 | J32: 275 | K32: 905 | L32: 3878 | M32: 20866 | N32: 6439 | O32: 25448 | P32: 3453 | Q32: 20954 | R32: =L32+N32+P32 -> 13770 | S32: =M32+O32+Q32 -> 67268 | T32: Jun. 01 | U32: 13770 | V32: =AVERAGE(U29:U32) -> 13931.5 | W32: =AVERAGE(S29:S32) -> 66683 | AH32: ALL WHEAT : 12/13 | AI32: 8946.1 | AJ32: 524 | AK32: 19906 | AL32: 731.4 | AM32: 28852.1
A33: 36615 | B33: 1033 | C33: 9168 | D33: 317 | E33: 3631 | F33: 1023 | G33: 4588 | H33: 591 | I33: 3282 | J33: 256 | K33: 797 | L33: 3219 | M33: 21464 | N33: 7249 | O33: 28827 | P33: 2309 | Q33: 19951 | R33: =L33+N33+P33 -> 12777 | S33: =M33+O33+Q33 -> 70242 | T33: Jun. 01 | U33: 12777 | V33: =AVERAGE(U30:U33) -> 13678.75 | W33: =AVERAGE(S30:S33) -> 67653 | AH33: : 12/20 | AI33: 8863.8 | AJ33: 381.3 | AK33: 20287.2 | AL33: 745.4 | AM33: 29151.1
A34: 36979 | B34: 1184 | C34: 7716 | D34: 452 | E34: 3721 | F34: 1000 | G34: 4693 | H34: 721 | I34: 4306 | J34: 281 | K34: 933 | L34: 3638 | M34: 21368 | N34: 6338 | O34: 26668 | P34: 2907 | Q34: 21648 | R34: =L34+N34+P34 -> 12883 | S34: =M34+O34+Q34 -> 69684 | T34: Jun. 01 | U34: 12883 | V34: =AVERAGE(U31:U34) -> 13122.25 | W34: =AVERAGE(S31:S34) -> 68895 | AH34: :YR AGO | AI34: 4630.1 | AJ34: 292 | AK34: 11910.7 | AL34: 437.6 | AM34: 16540.9
A35: 36622 | B35: 1088 | C35: 9298 | D35: 302 | E35: 3726 | F35: 837 | G35: 4794 | H35: 596 | I35: 3390 | J35: 255 | K35: 798 | L35: 3077 | M35: 22007 | N35: 7132 | O35: 29668 | P35: 2021 | Q35: 20454 | R35: =L35+N35+P35 -> 12230 | S35: =M35+O35+Q35 -> 72129 | T35: Jun. 01 | U35: 12230 | V35: =AVERAGE(U32:U35) -> 12915 | W35: =AVERAGE(S32:S35) -> 69830.75
A36: 36986 | B36: 1132 | C36: 7903 | D36: 499 | E36: 3793 | F36: 910 | G36: 4819 | H36: 605 | I36: 4462 | J36: 268 | K36: 954 | L36: 3415 | M36: 21931 | N36: 5618 | O36: 27841 | P36: 2477 | Q36: 22284 | R36: =L36+N36+P36 -> 11510 | S36: =M36+O36+Q36 -> 72056 | T36: Jul. 01 | U36: 11510 | V36: =AVERAGE(U33:U36) -> 12350 | W36: =AVERAGE(S33:S36) -> 71027.75
A37: 36629 | B37: 1008 | C37: 9460 | D37: 328 | E37: 3781 | F37: 785 | G37: 4881 | H37: 694 | I37: 3435 | J37: 246 | K37: 825 | L37: 3061 | M37: 22383 | N37: 7258 | O37: 30593 | P37: 1956 | Q37: 20823 | R37: =L37+N37+P37 -> 12275 | S37: =M37+O37+Q37 -> 73799 | T37: Jul. 01 | U37: 12275 | V37: =AVERAGE(U34:U37) -> 12224.5 | W37: =AVERAGE(S34:S37) -> 71917
A38: 36993 | B38: 1098 | C38: 8073 | D38: 404 | E38: 4028 | F38: 879 | G38: 4927 | H38: 569 | I38: 4561 | J38: 274 | K38: 954 | L38: 3223 | M38: 22543 | N38: 5216 | O38: 28787 | P38: 2090 | Q38: 22744 | R38: =L38+N38+P38 -> 10529 | S38: =M38+O38+Q38 -> 74074 | T38: Jul. 01 | U38: 10529 | V38: =AVERAGE(U35:U38) -> 11636 | W38: =AVERAGE(S35:S38) -> 73014.5
A39: 36636 | B39: 867 | C39: 9632 | D39: 346 | E39: 3828 | F39: 681 | G39: 5072 | H39: 665 | I39: 3472 | J39: 256 | K39: 825 | L39: 2815 | M39: 22829 | N39: 7405 | O39: 31682 | P39: 1909 | Q39: 21107 | R39: =L39+N39+P39 -> 12129 | S39: =M39+O39+Q39 -> 75618 | T39: Jul. 01 | U39: 12129 | V39: =AVERAGE(U36:U39) -> 11610.75 | W39: =AVERAGE(S36:S39) -> 73886.75
A40: 37000 | B40: 952 | C40: 8297 | D40: 407 | E40: 4110 | F40: 853 | G40: 5033 | H40: 531 | I40: 4635 | J40: 205 | K40: 1021 | L40: 2947 | M40: 23096 | N40: 4735 | O40: 29675 | P40: 2060 | Q40: 22906 | R40: =L40+N40+P40 -> 9742 | S40: =M40+O40+Q40 -> 75677 | T40: Aug. 01 | U40: 9742 | V40: =AVERAGE(U37:U40) -> 11168.75 | W40: =AVERAGE(S37:S40) -> 74792
...

Sheet copy data3
A1: New Table 12
A2: FAS - Accumulated Grain Export Sales
A3: Metric Tons
A4: Crop Year-Wheat=6/01-5/31; Corn & Soybeans=9/01-8/31;
R5: 3 Crop
B6: HRW | D6: SRW | F6: HRS | H6: SWW | J6: DUR | L6: All Wheat | N6: Corn | P6: Soybean | R6: Total | S6: 4-week running | U6: Net Export | V6: Sales, Current Marketing Year
B7: Outstd | C7: Accum | D7: Outstd | E7: Accum | F7: Outstd | G7: Accum | H7: Outstd | I7: Accum | J7: Outstd | K7: Accum | L7: Outstd | M7: Accum | N7: Outstd | O7: Accum | P7: Outstd | Q7: Accum | S7: Outstd
A8: 36523 | B8: 894 | C8: 7280 | D8: 642 | E8: 2514 | F8: 801 | G8: 3375 | H8: 721 | I8: 2326 | J8: 255 | K8: 563 | L8: 3312 | M8: 16058 | N8: 7894 | O8: 17010 | P8: 4521 | Q8: 11070 | R8: =P8+N8+L8 -> 15727
A9: 36531 | B9: 854 | C9: 7364 | D9: 523 | E9: 2644 | F9: 707 | G9: 3493 | H9: 638 | I9: 2455 | J9: 206 | K9: 619 | L9: 2928 | M9: 16575 | N9: 7360 | O9: 17826 | P9: 4436 | Q9: 11672 | R9: =P9+N9+L9 -> 14724 | T9: 36531
A10: =A9+7 -> 36538 | B10: 780.4 | C10: 7583.5 | D10: 430.7 | E10: 2745 | F10: 687 | G10: 3564 | H10: 589 | I10: 2535 | J10: 224 | K10: 619 | L10: 2711 | M10: 17047 | N10: 7487 | O10: 18837 | P10: 4338 | Q10: 12360 | R10: =P10+N10+L10 -> 14536 | S10: =AVERAGE(R7:R10) -> 14995.667 | T10: =T9+7 -> 36538
A11: =A10+7 -> 36545 | B11: 808 | C11: 7709 | D11: 394 | E11: 2818 | F11: 704 | G11: 3617 | H11: 535 | I11: 2616 | J11: 175 | K11: 670 | L11: 2614 | M11: 17430 | N11: 7737 | O11: 19721 | P11: 3887 | Q11: 12978 | R11: =P11+N11+L11 -> 14238 | S11: =AVERAGE(R8:R11) -> 14806.25 | T11: =T10+7 -> 36545
A12: =A11+7 -> 36552 | B12: 870 | C12: 7882 | D12: 424 | E12: 2888 | F12: 786 | G12: 3697 | H12: 442 | I12: 2767 | J12: 237 | K12: 673 | L12: 2704 | M12: 17907 | N12: 7579 | O12: 20673 | P12: 3593 | Q12: 13664 | R12: =P12+N12+L12 -> 13876 | S12: =AVERAGE(R9:R12) -> 14343.5 | T12: =T11+7 -> 36552
A13: =A12+7 -> 36559 | B13: 959 | C13: 8037 | D13: 482 | E13: 2949 | F13: 831 | G13: 3840 | H13: 440 | I13: 2882 | J13: 188 | K13: 692 | L13: 2898 | M13: 18398 | N13: 7771 | O13: 21491 | P13: 3920 | Q13: 14289 | R13: =P13+N13+L13 -> 14589 | S13: =AVERAGE(R10:R13) -> 14309.75 | T13: =T12+7 -> 36559
A14: =A13+7 -> 36566 | B14: 1027 | C14: 8168 | D14: 466 | E14: 3094 | F14: 800 | G14: 3955 | H14: 487 | I14: 2899.7 | J14: 176 | K14: 691.5 | L14: 2938 | M14: 18808 | N14: 7408 | O14: 22378.8 | P14: 3681 | Q14: 15192.5 | R14: =P14+N14+L14 -> 14027 | S14: =AVERAGE(R11:R14) -> 14182.5 | T14: =T13+7 -> 36566
A15: =A14+7 -> 36573 | B15: 984 | C15: 8405 | D15: 488 | E15: 3171 | F15: 921 | G15: 4057 | H15: 489 | I15: 2970 | J15: 166 | K15: 703 | L15: 3047 | M15: 19306 | N15: 7423 | O15: 23257.5 | P15: 4002 | Q15: 15857 | R15: =P15+N15+L15 -> 14472 | S15: =AVERAGE(R12:R15) -> 14241 | T15: =T14+7 -> 36573
A16: =A15+7 -> 36580 | B16: 943 | C16: 8540 | D16: 385 | E16: 3286 | F16: 910 | G16: 4134 | H16: 482 | I16: 3035 | J16: 155 | K16: 713 | L16: 2875 | M16: 19709 | N16: 7517 | O16: 24291 | P16: 3938 | Q16: 16479 | R16: =P16+N16+L16 -> 14330 | S16: =AVERAGE(R13:R16) -> 14354.5 | T16: =T15+7 -> 36580
A17: =A16+7 -> 36587 | B17: 942 | C17: 8687 | D17: 401 | E17: 3371 | F17: 1009 | G17: 4209 | H17: 557 | I17: 3076 | J17: 247 | K17: 741 | L17: 3156 | M17: 20084 | N17: 8148 | O17: 25033 | P17: 3852 | Q17: 17091 | R17: =P17+N17+L17 -> 15156 | S17: =AVERAGE(R14:R17) -> 14496.25 | T17: =T16+7 -> 36587
A18: =A17+7 -> 36594 | B18: 1009 | C18: 8792 | D18: 438 | E18: 3371 | F18: 1037 | G18: 4336 | H18: 562 | I18: 3121 | J18: 290 | K18: 749 | L18: 3336 | M18: 20368 | N18: 7952 | O18: 25999 | P18: 3223 | Q18: 18093 | R18: =P18+N18+L18 -> 14511 | S18: =AVERAGE(R15:R18) -> 14617.25 | T18: =T17+7 -> 36594
A19: =A18+7 -> 36601 | B19: 1068 | C19: 8875 | D19: 321 | E19: 3523 | F19: 1045 | G19: 4389 | H19: 600 | I19: 3146 | J19: 276 | K19: 775 | L19: 3310 | M19: 20709 | N19: 7537 | O19: 26906 | P19: 2941 | Q19: 18747 | R19: =P19+N19+L19 -> 13788 | S19: =AVERAGE(R16:R19) -> 14446.25 | T19: =T18+7 -> 36601
A20: =A19+7 -> 36608 | B20: 1028 | C20: 8982 | D20: 308 | E20: 3586 | F20: 1117 | G20: 4489 | H20: 622 | I20: 3192 | J20: 254 | K20: 797 | L20: 3229 | M20: 21047 | N20: 7316 | O20: 27895 | P20: 2514 | Q20: 19444 | R20: =P20+N20+L20 -> 13059 | S20: =AVERAGE(R17:R20) -> 14128.5 | T20: =T19+7 -> 36608
A21: =A20+7 -> 36615 | B21: 1033 | C21: 9168 | D21: 317 | E21: 3631 | F21: 1023 | G21: 4588 | H21: 591 | I21: 3282 | J21: 256 | K21: 797 | L21: 3219 | M21: 21464 | N21: 7249 | O21: 28827 | P21: 2309 | Q21: 19951 | R21: =P21+N21+L21 -> 12777 | S21: =AVERAGE(R18:R21) -> 13533.75 | T21: =T20+7 -> 36615
... A38: =A37+7 -> 36734 | B38: 1136 | C38: 1500 | D38: 543 | E38: 848 | F38: 804 | G38: 883 | H38: 761 | I38: 491 | J38: 318 | K38: 146 | L38: 3562 | M38: 3869 | N38: 6116 | O38: 43461 | P38: 1788 | Q38: 25175 | R38: =P38+N38+L38 -> 11466 | S38: =AVERAGE(R35:R38) -> 11925.5 | T38: =T37+7 -> 36734
A39: =A38+7 -> 36741 | B39: 1215 | C39: 1691 | D39: 651 | E39: 934 | F39: 901 | G39: 957 | H39: 1038 | I39: 637 | J39: 343 | K39: 163 | L39: 4148 | M39: 4382 | N39: 5766 | O39: 44317 | P39: 1635 | Q39: 25625 | R39: =L39+N39+P39 -> 11549 | S39: =AVERAGE(R36:R39) -> 11750.25 | T39: =T38+7 -> 36741
A40: =A39+7 -> 36748 | B40: 1273 | C40: 1915 | D40: 727 | E40: 1029.5 | F40: 978 | G40: 1029 | H40: 963 | I40: 778 | J40: 308 | K40: 201 | L40: 4248 | M40: 4952 | N40: 5388 | O40: 44949 | P40: 1360 | Q40: 25991 | R40: =L40+N40+P40 -> 10996 | S40: =AVERAGE(R37:R40) -> 11512.25 | T40: =T39+7 -> 36748
A41: =A40+7 -> 36755 | B41: 1440 | C41: 2120 | D41: 694 | E41: 1099 | F41: 992 | G41: 1096 | H41: 949 | I41: 882 | J41: 299 | K41: 273 | L41: 4375 | M41: 5469 | N41: 4296 | O41: 46181 | P41: 1050 | Q41: 26331 | R41: =L41+N41+P41 -> 9721 | S41: =AVERAGE(R38:R41) -> 10933 | T41: =T40+7 -> 36755
A42: =A41+7 -> 36762 | B42: 1301 | C42: 2350 | D42: 623 | E42: 1191 | F42: 981 | G42: 1240 | H42: 947 | I42: 957 | J42: 272 | K42: 311 | L42: 4123 | M42: 6048 | N42: 3372 | O42: 47318 | P42: 1002 | Q42: 26565 | R42: =L42+N42+P42 -> 8497 | S42: =AVERAGE(R39:R42) -> 10190.75 | T42: =T41+7 -> 36762
A43: =A42+7 -> 36769 | B43: 1346 | C43: 2640 | D43: 599 | E43: 1356 | F43: 927 | G43: 1427 | H43: 905 | I43: 1071 | J43: 283 | K43: 315 | L43: 4059 | M43: 6809 | N43: 2006 | O43: 48760 | P43: 613 | Q43: 26972 | R43: =L43+N43+P43 -> 6678 | S43: =AVERAGE(R40:R43) -> 8973 | T43: =T42+7 -> 36769
A44: =A43+7 -> 36776 | B44: 1185 | C44: 2922 | D44: 597 | E44: 1455 | F44: 915 | G44: 1532 | H44: 874 | I44: 1129 | J44: 267 | K44: 341 | L44: 3837 | M44: 7380 | N44: 7856 | O44: 825 | P44: 4785 | Q44: 409 | R44: =L44+N44+P44 -> 16478 | S44: =AVERAGE(R41:R44) -> 10343.5 | T44: =T43+7 -> 36776
A45: =A44+7 -> 36783 | B45: 1167 | C45: 3070 | D45: 656 | E45: 1537 | F45: 854 | G45: 1674 | H45: 815 | I45: 1303 | J45: 255 | K45: 377 | L45: 3746 | M45: 7962 | N45: 7509 | O45: 1848 | P45: 4968 | Q45: 749 | R45: =L45+N45+P45 -> 16223 | S45: =AVERAGE(R42:R45) -> 11969 | T45: =T44+7 -> 36783
A46: =A45+7 -> 36790 | B46: 1059 | C46: 3310 | D46: 618 | E46: 1676 | F46: 840 | G46: 1848 | H46: 710 | I46: 1462 | J46: 263 | K46: 406 | L46: 3489 | M46: 8703 | N46: 7767 | O46: 2959 | P46: 5726 | Q46: 1011 | R46: =L46+N46+P46 -> 16982 | S46: =AVERAGE(R43:R46) -> 14090.25 | T46: =T45+7 -> 36790
A47: =A46+7 -> 36797 | B47: 1164 | C47: 3511 | D47: 516 | E47: 1867 | F47: 817 | G47: 1911 | H47: 647 | I47: 1566 | J47: 238 | K47: 433 | L47: 3382 | M47: 9288 | N47: 6994 | O47: 4400 | P47: 5836 | Q47: 1411 | R47: =L47+N47+P47 -> 16212 | S47: =AVERAGE(R44:R47) -> 16473.75 | T47: =T46+7 -> 36797
A48: =A47+7 -> 36804 | B48: 1180 | C48: 3721 | D48: 508 | E48: 1919 | F48: 757 | G48: 2004 | H48: 593 | I48: 1753 | J48: 173 | K48: 479 | L48: 3212 | M48: 9876 | N48: 6640 | O48: 5723 | P48: 5912 | Q48: 1987 | R48: =L48+N48+P48 -> 15764 | S48: =AVERAGE(R45:R48) -> 16295.25 | T48: =T47+7 -> 36804
A49: =A48+7 -> 36811 | B49: 1125 | C49: 3921 | D49: 373 | E49: 2060 | F49: 741 | G49: 2094 | H49: 688 | I49: 1824 | J49: 193 | K49: 486 | L49: 3120 | M49: 10385 | N49: 6812 | O49: 6597 | P49: 6190 | Q49: 2734 | R49: =L49+N49+P49 -> 16122 | S49: =AVERAGE(R46:R49) -> 16270 | T49: =T48+7 -> 36811
A50: =A49+7 -> 36818 | B50: 1175 | C50: 4033 | D50: 339 | E50: 2159 | F50: 801 | G50: 2152 | H50: 746 | I50: 1926 | J50: 193 | K50: 486 | L50: 3253 | M50: 10756 | N50: 6923 | O50: 7404 | P50: 6224 | Q50: 3563 | R50: =L50+N50+P50 -> 16400 | S50: =AVERAGE(R47:R50) -> 16124.5 | T50: =T49+7 -> 36818
... A112: =A111+7 -> 37252 | B112: 1220 | C112: 4900 | D112: 623 | E112: 3403 | F112: 948 | G112: 3239 | H112: 563 | I112: 1902 | J112: 118 | K112: 800 | L112: 3472 | M112: 14243 | N112: 7347 | O112: 13825 | P112: 7820 | Q112: 12333 | R112: =L112+N112+P112 -> 18639 | S112: =AVERAGE(R109:R112) -> 19307 | T112: =T111+7 -> 37252
A113: =A112+7 -> 37259 | B113: 1124 | C113: 5046 | D113: 633 | E113: 3534 | F113: 936 | G113: 3316 | H113: 617 | I113: 1934 | J113: 124 | K113: 800 | L113: 3433 | M113: 14630 | N113: 6830 | O113: 14456 | P113: 7739 | Q113: 12997 | R113: =P113+N113+L113 -> 18002 | S113: =AVERAGE(R110:R113) -> 18901.75 | T113: =T112+7 -> 37259
A114: =A113+7 -> 37266 | B114: 1003 | C114: 5279 | D114: 693 | E114: 3568 | F114: 943 | G114: 3404 | H114: 592 | I114: 1996 | J114: 124 | K114: 800 | L114: 3354 | M114: 15047 | N114: 7110 | O114: 15085 | P114: 7816 | Q114: 14078 | R114: =P114+N114+L114 -> 18280 | S114: =AVERAGE(R111:R114) -> 18537.25 | T114: =T113+7 -> 37266
A115: =A114+7 -> 37273 | B115: 1192 | C115: 5454 | D115: 702 | E115: 3639 | F115: 934 | G115: 3554 | H115: 595 | I115: 2057 | J115: 132 | K115: 810 | L115: 3555 | M115: 15514 | N115: 7432 | O115: 16075 | P115: 7522 | Q115: 15099 | R115: 18509 | S115: =AVERAGE(R112:R115) -> 18357.5 | T115: =T114+7 -> 37273
A116: =A115+7 -> 37280 | B116: 1357 | C116: 5543 | D116: 675 | E116: 3731 | F116: 963 | G116: 3636 | H116: 505 | I116: 2212 | J116: 181 | K116: 812 | L116: 3681 | M116: 15932 | N116: 7415 | O116: 16841 | P116: 7306 | Q116: 16026 | R116: =L116+N116+P116 -> 18402 | S116: =AVERAGE(R113:R116) -> 18298.25 | T116: =T115+7 -> 37280
A117: =A116+7 -> 37287 | B117: 1324 | C117: 5764 | D117: 826 | E117: 3794 | F117: 878 | G117: 3827 | H117: 525 | I117: 2222 | J117: 205 | K117: 812 | L117: 3759 | M117: 16418 | N117: 7944 | O117: 17695 | P117: 6514 | Q117: 17182 | R117: =L117+N117+P117 -> 18217 | S117: =AVERAGE(R114:R117) -> 18352 | T117: =T116+7 -> 37287
...

Sheet Chart2
