Workbook
Name CableSub: #REF!
Name Customer_Metrics: #REF!
Name OLE_LINK1: Notes!$A$5

Sheet Customer Metrics
A1: Pro Forma Cable Customer Metrics
A2: (Customers and boxes in thousands, except per customer data; unaudited)
B4: 2008 | H4: 2009 | N4: 2010
B5: 1Q | C5: 2Q | D5: 3Q | E5: 4Q | F5: FY | H5: 1Q | I5: 2Q | J5: 3Q | K5: 4Q | L5: FY | N5: 1Q | O5: 2Q | P5: 3Q
A7: Homes Passed1 | B7: 49902 | C7: 50096 | D7: 50329 | E7: 50575.4 | F7: 50575.4 | H7: 50740 | I7: 50900 | J7: 51078 | K7: 51233 | L7: 51233 | N7: 51387.098 | O7: 51547.254 | P7: 51740.34
A9: Total Video
A10: Total Video Customers | B10: 24700.8 | C10: 24562.7 | D10: 24415.2 | E10: 24182.4 | F10: 24182.4 | H10: 24104 | I10: 23891 | J10: 23759 | K10: 23559 | L10: 23559 | N10: 23476.968 | O10: 23212.322 | P10: 22937.177
A11: Total Video Penetration of Homes Passed2 | B11: 0.49498617 | C11: 0.4903126 | D11: 0.48511196 | E11: 0.4781455 | F11: 0.4781455 | H11: 0.475 | I11: 0.469 | J11: 0.465 | K11: 0.46 | L11: 0.46 | N11: 0.45686503 | O11: 0.45031152 | P11: 0.44331322
A12: Total Video Net Additions (Losses) | B12: -56.9 | C12: -138.1 | D12: -147.5 | E12: -232.8 | F12: -575.3 | H12: -78 | I12: -214 | J12: -132 | K12: -199 | L12: -623 | N12: -82.431208 | O12: -264.64618 | P12: -275.14519
J13: 0 | K13: 0
A14: Digital Video Customers3 | B14: 16020.7 | C14: 16340.5 | D14: 16757.6 | E14: 17004.1 | F14: 17004.1 | H14: 17293 | I14: 17542 | J14: 18005 | K14: 18415 | L14: 18415 | N14: 18842.688 | O14: 19236.723 | P14: 19456.121
A15: Digital Penetration of Total Video | B15: 0.64859033 | C15: 0.66525667 | D15: 0.68635932 | E15: 0.70316015 | F15: 0.70316015 | H15: 0.717 | I15: 0.734 | J15: 0.758 | K15: 0.782 | L15: 0.782 | N15: 0.8026031 | O15: 0.82872894 | P15: 0.8482352
A16: Digital Video Additions | B16: 494.2 | C16: 319.8 | D16: 417.1 | E16: 246.5 | F16: 1477.6 | H16: 288 | I16: 250 | J16: 463 | K16: 410 | L16: 1411 | N16: 427.3829 | O16: 394.03556 | P16: 219.39775
A17: Digital Set-Top Boxes3 | B17: 25862.7 | C17: 26352.3 | D17: 27067.6 | E17: 27580 | F17: 27580 | H17: 28824 | I17: 30697 | J17: 33314 | K17: 36402 | L17: 36402 | N17: 39649.375 | O17: 44246.968 | P17: 46803.337
A18: Boxes per Digital Customer | B18: 1.6143302 | C18: 1.6126985 | D18: 1.6152432 | E18: 1.6198152 | F18: 1.6198152 | H18: 1.7 | I18: 1.7 | J18: 1.9 | K18: 2 | L18: 2 | N18: 2.1042314 | O18: 2.3001302 | P18: 2.4055842
A20: Advanced Services Customers4 | B20: 6908.7 | C20: 6982 | D20: 7292.8 | E20: 7725.3 | F20: 7725.3 | H20: 8177 | I20: 8349 | J20: 8748 | K20: 9158 | L20: 9158 | N20: 9510.6194 | O20: 9664.5826 | P20: 9892.3218
A21: Advanced Services Penetration of Total Video | B21: 0.27969539 | C21: 0.28425214 | D21: 0.29869917 | E21: 0.31945961 | F21: 0.31945961 | H21: 0.339 | I21: 0.349 | J21: 0.368 | K21: 0.389 | L21: 0.389 | N21: 0.40510424 | O21: 0.4163557 | P21: 0.43127896
A22: Advanced Services Penetration of Digital Video | B22: 0.43123584 | C22: 0.42728191 | D22: 0.43519358 | E22: 0.45431984 | F22: 0.45431984 | H22: 0.473 | I22: 0.476 | J22: 0.486 | K22: 0.497 | L22: 0.497 | N22: 0.50473794 | O22: 0.50240275 | P22: 0.50844265
A24: High-Speed Internet (HSI)
A25: HSI Customers | B25: 14085.3 | C25: 14363.7 | D25: 14745.4 | E25: 14929 | F25: 14929 | H25: 15258 | I25: 15322 | J25: 15684 | K25: 15930 | L25: 15930 | N25: 16329.27 | O25: 16447.737 | P25: 16696.394
A26: HSI "Available" Homes5 | B26: 49548 | C26: 49745 | D26: 49982 | E26: 50283 | F26: 50283 | H26: 50456 | I26: 50615 | J26: 50805 | K26: 50754 | L26: 50754 | N26: 50906.062 | O26: 51059.545 | P26: 51259.22
A27: HSI Penetration of "Available" Homes2 | B27: 0.284 | C27: 0.289 | D27: 0.295 | E27: 0.297 | F27: 0.297 | H27: 0.302 | I27: 0.303 | J27: 0.309 | K27: 0.314 | L27: 0.314 | N27: 0.3207726 | O27: 0.32212855 | P27: 0.3257247
A28: HSI Net Additions | B28: 492.3 | C28: 278.5 | D28: 381.7 | E28: 183.5 | F28: 1336 | H28: 329 | I28: 65 | J28: 361 | K28: 247 | L28: 1002 | N28: 398.79845 | O28: 118.46742 | P28: 248.65656
A30: Voice
A31: Comcast Digital Voice (CDV) Customers | B31: 5087.9 | C31: 5643.4 | D31: 6126.5 | E31: 6470.1 | F31: 6470.1 | H31: 6769 | I31: 7002 | J31: 7377 | K31: 7620 | L31: 7620 | N31: 7894.2904 | O31: 8124.8438 | P31: 8353.0475
A32: Circuit-Switched Voice Customers | B32: 66 | C32: 10.4 | D32: 6.7 | E32: 2.8 | F32: 2.8 | H32: 2 | I32: 2 | J32: 2 | K32: 2 | L32: 2 | N32: 0.982 | O32: 0 | P32: 0
A33: Total Voice Customers | B33: 5153.9 | C33: 5653.8 | D33: 6133.2 | E33: 6472.9 | F33: 6472.9 | H33: 6771 | I33: 7004 | J33: 7379 | K33: 7622 | L33: 7622 | N33: 7895.2724 | O33: 8124.8438 | P33: 8353.0475
A35: CDV "Available" Homes5 | B35: 44081.9 | C35: 45142.8 | D35: 46083.2 | E35: 46687.3 | F35: 46687.3 | H35: 47393 | I35: 47654 | J35: 48136 | K35: 48406 | L35: 48406 | N35: 48879.724 | O35: 49183.815 | P35: 49614.914
A36: CDV Penetration of "Available" Homes2 | B36: 0.11541925 | C36: 0.12501218 | D36: 0.13294433 | E36: 0.13858373 | F36: 0.13858373 | H36: 0.143 | I36: 0.147 | J36: 0.153 | K36: 0.157 | L36: 0.157 | N36: 0.1615044 | O36: 0.16519344 | P36: 0.16835759
A37: CDV Net Additions | B37: 638.9 | C37: 555 | D37: 483.1 | E37: 343.6 | F37: 2020.6 | H37: 298 | I37: 233 | J37: 375 | K37: 243 | L37: 1149 | N37: 274.54584 | O37: 229.55344 | P37: 228.20363
A41: Combined Video, HSI and Voice Customers | B41: 43940 | C41: 44580.2 | D41: 45293.8 | E41: 45584.3 | F41: 45584.3 | H41: 46133 | I41: 46217 | J41: 46821 | K41: 47112 | L41: 47112 | N41: 47701.511 | O41: 47784.903 | P41: 47986.618
A42: Combined Video, HSI and Voice Net Additions | B42: 964.3 | C42: 640.3 | D42: 713.6 | E42: 290.4 | F42: 2608.6 | H42: 549 | I42: 84 | J42: 604 | K42: 290 | L42: 1528 | N42: 589.68408 | O42: 83.392684 | P42: 201.715
A44: Total Revenue Generating Units (includes Digital Video Customers)6 | B44: 59960.7 | C44: 60920.7 | D44: 62051.4 | E44: 62588.4 | F44: 62588.4 | H44: 63426 | I44: 63760 | J44: 64826 | K44: 65527 | L44: 65527 | N44: 66544.198 | O44: 67021.627 | P44: 67442.739
A45: RGU Net Adds | B45: 1458.5 | C45: 960.1 | D45: 1130.7 | E45: 536.9 | F45: 4086.2 | H45: 837 | I45: 334 | J45: 1067 | K45: 701 | L45: 2939 | N45: 1017.067 | O45: 477.42824 | P45: 421.11275
A49: Average Monthly Revenue per Video Customer | B49: 107.2 | C49: 110.24 | D49: 111.32 | E49: 114.48 | F49: 111.1 | H49: 115.74 | I49: 118.32 | J49: 117.54 | K49: 120.66 | L49: 118.23 | N49: 122.98 | O49: 127.78 | P49: 129.75

Sheet Revenue and Exp
A1: Revenue and Expenses
A2: ($ in millions; unaudited)
B4: 2008 | H4: 2009 | N4: 2010
B5: 1Q | C5: 2Q | D5: 3Q | E5: 4Q | F5: FY | H5: 1Q | I5: 2Q | J5: 3Q | K5: 4Q | L5: FY | N5: 1Q | O5: 2Q | P5: 3Q
A7: Revenue
A8: Video7 | B8: 4778 | C8: 4800 | D8: 4767 | E8: 4817 | F8: 19162 | H8: 4929 | I8: 4884 | J8: 4777 | K8: 4787 | L8: 19377 | N8: 4842 | O8: 4917 | P8: 4881
A9: High-Speed Internet | B9: 1750 | C9: 1792 | D9: 1822 | E9: 1861 | F9: 7225 | H9: 1909 | I9: 1929 | J9: 1930 | K9: 1989 | L9: 7757 | N9: 2071 | O9: 2129 | P9: 2164
A10: Voice | B10: 587 | C10: 640 | D10: 690 | E10: 732 | F10: 2649 | H10: 777 | I10: 801 | J10: 829 | K10: 855 | L10: 3262 | N10: 877 | O10: 916 | P10: 934
A11: Advertising | B11: 379 | C11: 446 | D11: 423 | E11: 461 | F11: 1709 | H11: 292 | I11: 363 | J11: 363 | K11: 426 | L11: 1444 | N11: 360 | O11: 446 | P11: 461
A12: Other8 | B12: 235 | C12: 241 | D12: 248 | E12: 242 | F12: 966 | H12: 242 | I12: 303 | J12: 265 | K12: 269 | L12: 1079 | N12: 285 | O12: 290 | P12: 293
A13: Franchise Fees | B13: 224 | C13: 227 | D13: 228 | E13: 232 | F13: 911 | H13: 234 | I13: 238 | J13: 238 | K13: 238 | L13: 948 | N13: 242 | O13: 251 | P13: 248
A14: Total Cable Segment * | B14: 7953 | C14: 8146 | D14: 8178 | E14: 8345 | F14: 32622 | H14: 8383 | I14: 8518 | J14: 8402 | K14: 8564 | L14: 33867 | N14: 8677 | O14: 8949 | P14: 8981
A16: Advertising | B16: 154.12922 | C16: 169.64496 | D16: 145.9018 | E16: 142.51283 | F16: 613 | H16: 143 | I16: 158 | J16: 158 | K16: 152 | L16: 611 | N16: 152 | O16: 191 | P16: 165
A17: Affiliate | B17: 155.66506 | C17: 154.80112 | D17: 158.36343 | E17: 162.8766 | F17: 631.70621 | H17: 178 | I17: 179 | J17: 178 | K17: 171 | L17: 706 | N17: 185 | O17: 196 | P17: 196
A18: Other9 | B18: 53 | C18: 41.380641 | D18: 42.591809 | E18: 44 | F18: 180.97245 | H18: 40 | I18: 47 | J18: 47 | K18: 45 | L18: 179 | N18: 48 | O18: 67 | P18: 55
A19: Total Programming Segment | B19: 363 | C19: 366 | D19: 347 | E19: 350 | F19: 1426 | H19: 361 | I19: 384 | J19: 383 | K19: 368 | L19: 1496 | N19: 385 | O19: 454 | P19: 416
A21: Corporate & Other | B21: 107 | C21: 85 | D21: 67 | E21: 116 | F21: 375 | H21: 122 | I21: 76 | J21: 60 | K21: 135 | L21: 393 | N21: 140 | O21: 122 | P21: 92
... A25: * Business Services Revenue (included in Cable service revenues) | B25: 120 | C25: 131 | D25: 145 | E25: 162 | F25: 558 | H25: 176 | I25: 198 | J25: 216 | K25: 238 | L25: 828 | N25: 263 | O25: 306 | P25: 333
A27: Operating Expense
A28: Video Programming | B28: 1619 | C28: 1611 | D28: 1617 | E28: 1632 | F28: 6479 | H28: 1775 | I28: 1758 | J28: 1759 | K28: 1754 | L28: 7046 | N28: 1864 | O28: 1870 | P28: 1846
A29: High-Speed Internet | B29: 139 | C29: 137 | D29: 132 | E29: 118 | F29: 526 | H29: 127 | I29: 126 | J29: 134 | K29: 137 | L29: 524 | N29: 125 | O29: 128 | P29: 124
A30: Voice | B30: 193 | C30: 174 | D30: 170 | E30: 162 | F30: 699 | H30: 154 | I30: 132 | J30: 135 | K30: 146 | L30: 567 | N30: 141 | O30: 145 | P30: 148
A31: Technical Labor | B31: 535 | C31: 528 | D31: 572 | E31: 553 | F31: 2188 | H31: 586 | I31: 586 | J31: 573 | K31: 550 | L31: 2295 | N31: 561 | O31: 541 | P31: 594
A32: Other (includes Franchise Fees) | B32: 718 | C32: 740 | D32: 742 | E32: 765 | F32: 2965 | H32: 731 | I32: 785 | J32: 780 | K32: 794 | L32: 3090 | N32: 808 | O32: 897 | P32: 893
A33: Total Cable Operating Expense10 | B33: 3204 | C33: 3190 | D33: 3233 | E33: 3230 | F33: 12857 | H33: 3373 | I33: 3387 | J33: 3381 | K33: 3381 | L33: 13522 | N33: 3499 | O33: 3581 | P33: 3605
A35: Customer Service | B35: 438 | C35: 430 | D35: 439 | E35: 450 | F35: 1757 | H35: 474 | I35: 457 | J35: 471 | K35: 459 | L35: 1861 | N35: 449 | O35: 446 | P35: 459
A36: Marketing | B36: 400 | C36: 411 | D36: 427 | E36: 390 | F36: 1628 | H36: 370 | I36: 403 | J36: 443 | K36: 387 | L36: 1603 | N36: 429 | O36: 453 | P36: 520
A37: Administrative and Other11 | B37: 771 | C37: 755 | D37: 830 | E37: 861 | F37: 3217 | H37: 762 | I37: 772 | J37: 795 | K37: 866 | L37: 3195 | N37: 758 | O37: 771 | P37: 851
A38: Total Cable SG&A | B38: 1609 | C38: 1596 | D38: 1696 | E38: 1701 | F38: 6602 | H38: 1606 | I38: 1632 | J38: 1709 | K38: 1712 | L38: 6659 | N38: 1636 | O38: 1670 | P38: 1830
A40: Total Cable Segment | B40: 4813 | C40: 4786 | D40: 4929 | E40: 4931 | F40: 19459 | H40: 4979 | I40: 5019 | J40: 5090 | K40: 5093 | L40: 20181 | N40: 5135 | O40: 5251 | P40: 5435
A42: Total Programming Segment | B42: 250 | C42: 277 | D42: 242 | E42: 295 | F42: 1064 | H42: 249 | I42: 271 | J42: 265 | K42: 322 | L42: 1107 | N42: 264 | O42: 302 | P42: 266
... A46: Total Consolidated Operating Expense | B46: 5249 | C46: 5246 | D46: 5355 | E46: 5441 | F46: 21291 | H46: 5422 | I46: 5443 | J46: 5519 | K46: 5658 | L46: 22042 | N46: 5637 | O46: 5788 | P46: 5911
A48: Operating Cash Flow (OCF)12
A49: Cable | B49: 3140 | C49: 3360 | D49: 3249 | E49: 3414 | F49: 13163 | H49: 3404 | I49: 3499 | J49: 3312 | K49: 3471 | L49: 13686 | N49: 3542 | O49: 3698 | P49: 3546
A50: Programming | B50: 113 | C50: 89 | D50: 105 | E50: 55 | F50: 362 | H50: 112 | I50: 113 | J50: 118 | K50: 46 | L50: 389 | N50: 121 | O50: 152 | P50: 150
A51: Corporate & Other | B51: -79 | C51: -98 | D51: -117 | E51: -99 | F51: -393 | H51: -72 | I51: -77 | J51: -104 | K51: -108 | L51: -361 | N51: -98 | O51: -113 | P51: -118
A52: Total Consolidated OCF | B52: 3174 | C52: 3351 | D52: 3237 | E52: 3370 | F52: 13132 | H52: 3444 | I52: 3535 | J52: 3326 | K52: 3409 | L52: 13714 | N52: 3565 | O52: 3737 | P52: 3578
A54: Cable | B54: 0.3948044 | C54: 0.41245932 | D54: 0.39730292 | E54: 0.40907088 | F54: 0.40348901 | H54: 0.40605913 | I54: 0.4107696 | J54: 0.39424452 | K54: 0.40531083 | L54: 0.4041238 | N54: 0.40825088 | O54: 0.41319878 | P54: 0.39486431
A55: Programming | B55: 0.31177593 | C55: 0.24154658 | D55: 0.30319342 | E55: 0.15707702 | F55: 0.2536823 | H55: 0.30943968 | I55: 0.29482822 | J55: 0.30916939 | K55: 0.12395437 | L55: 0.25992489 | N55: 0.31455143 | O55: 0.33550037 | P55: 0.3592664
A56: Total Consolidated OCF Margin | B56: 0.37684799 | C56: 0.38978936 | D56: 0.37668043 | E56: 0.38255281 | F56: 0.38149848 | H56: 0.38841593 | I56: 0.39382225 | J56: 0.37596258 | K56: 0.37595126 | L56: 0.38353202 | N56: 0.38737279 | O56: 0.39234044 | P56: 0.37707161

Sheet Exp as a % of Rev
L1: Pro Forma Operating Expenses as a % of Revenue
B3: 2007 | H3: 2008 | N3: Growth
B4: 1Q | C4: 2Q | D4: 3Q | E4: 4Q | F4: FY | H4: 1Q | I4: 2Q | J4: 3Q | K4: 4Q | L4: FY | N4: 1Q | O4: 2Q | P4: 3Q | Q4: 4Q | R4: FY
A6: Product Operating Expense as a % of Product Revenue
A7: Video Programming (% of Video Rev) | B7: ='Revenue and Exp'!#REF!/'Revenue and Exp'!#REF! -> #REF! | C7: ='Revenue and Exp'!#REF!/'Revenue and Exp'!#REF! -> #REF! | D7: ='Revenue and Exp'!#REF!/'Revenue and Exp'!#REF! -> #REF! | E7: ='Revenue and Exp'!#REF!/'Revenue and Exp'!#REF! -> #REF! | F7: ='Revenue and Exp'!#REF!/'Revenue and Exp'!#REF! -> #REF! | H7: ='Revenue and Exp'!B28/'Revenue and Exp'!B8 -> 0.3388447 | I7: ='Revenue and Exp'!C28/'Revenue and Exp'!C8 -> 0.335625 | J7: ='Revenue and Exp'!D28/'Revenue and Exp'!D8 -> 0.33920705 | K7: ='Revenue and Exp'!E28/'Revenue and Exp'!E8 -> 0.33880008 | L7: ='Revenue and Exp'!F28/'Revenue and Exp'!F8 -> 0.33811711 | N7: =H7/B7-1 -> #REF! | O7: =I7/C7-1 -> #REF! | P7: =J7/D7-1 -> #REF! | Q7: =K7/E7-1 -> #REF! | R7: =L7/F7-1 -> #REF!
A8: Voice (% of Voice Rev) | B8: ='Revenue and Exp'!#REF!/'Revenue and Exp'!#REF! -> #REF! | C8: ='Revenue and Exp'!#REF!/'Revenue and Exp'!#REF! -> #REF! | D8: ='Revenue and Exp'!#REF!/'Revenue and Exp'!#REF! -> #REF! | E8: ='Revenue and Exp'!#REF!/'Revenue and Exp'!#REF! -> #REF! | F8: ='Revenue and Exp'!#REF!/'Revenue and Exp'!#REF! -> #REF! | H8: ='Revenue and Exp'!B30/'Revenue and Exp'!B10 -> 0.32879046 | I8: ='Revenue and Exp'!C30/'Revenue and Exp'!C10 -> 0.271875 | J8: ='Revenue and Exp'!D30/'Revenue and Exp'!D10 -> 0.24637681 | K8: ='Revenue and Exp'!E30/'Revenue and Exp'!E10 -> 0.22131148 | L8: ='Revenue and Exp'!F30/'Revenue and Exp'!F10 -> 0.26387316 | N8: =H8/B8-1 -> #REF! | O8: =I8/C8-1 -> #REF! | P8: =J8/D8-1 -> #REF! | Q8: =K8/E8-1 -> #REF! | R8: =L8/F8-1 -> #REF!
A9: High-Speed Internet (% of HSI Rev) | B9: ='Revenue and Exp'!#REF!/'Revenue and Exp'!#REF! -> #REF! | C9: ='Revenue and Exp'!#REF!/'Revenue and Exp'!#REF! -> #REF! | D9: ='Revenue and Exp'!#REF!/'Revenue and Exp'!#REF! -> #REF! | E9: ='Revenue and Exp'!#REF!/'Revenue and Exp'!#REF! -> #REF! | F9: ='Revenue and Exp'!#REF!/'Revenue and Exp'!#REF! -> #REF! | H9: ='Revenue and Exp'!B29/'Revenue and Exp'!B9 -> 0.079428571 | I9: ='Revenue and Exp'!C29/'Revenue and Exp'!C9 -> 0.076450893 | J9: ='Revenue and Exp'!D29/'Revenue and Exp'!D9 -> 0.072447859 | K9: ='Revenue and Exp'!E29/'Revenue and Exp'!E9 -> 0.063406771 | L9: ='Revenue and Exp'!F29/'Revenue and Exp'!F9 -> 0.072802768 | N9: =H9/B9-1 -> #REF! | O9: =I9/C9-1 -> #REF! | P9: =J9/D9-1 -> #REF! | Q9: =K9/E9-1 -> #REF! | R9: =L9/F9-1 -> #REF!
A11: Operating Expense as a % of Cable and Programming Revenue
A12: Video Programming (% of Cable Rev) | B12: ='Revenue and Exp'!#REF!/'Revenue and Exp'!#REF! -> #REF! | C12: ='Revenue and Exp'!#REF!/'Revenue and Exp'!#REF! -> #REF! | D12: ='Revenue and Exp'!#REF!/'Revenue and Exp'!#REF! -> #REF! | E12: ='Revenue and Exp'!#REF!/'Revenue and Exp'!#REF! -> #REF! | F12: ='Revenue and Exp'!#REF!/'Revenue and Exp'!#REF! -> #REF! | H12: ='Revenue and Exp'!B28/'Revenue and Exp'!B$14 -> 0.20357098 | I12: ='Revenue and Exp'!C28/'Revenue and Exp'!C$14 -> 0.19776577 | J12: ='Revenue and Exp'!D28/'Revenue and Exp'!D$14 -> 0.19772561 | K12: ='Revenue and Exp'!E28/'Revenue and Exp'!E$14 -> 0.19556621 | L12: ='Revenue and Exp'!F28/'Revenue and Exp'!F$14 -> 0.1986083 | N12: =H12/B12-1 -> #REF! | O12: =I12/C12-1 -> #REF! | P12: =J12/D12-1 -> #REF! | Q12: =K12/E12-1 -> #REF! | R12: =L12/F12-1 -> #REF!
A13: Technical Labor (% of Cable Rev) | B13: ='Revenue and Exp'!#REF!/'Revenue and Exp'!#REF! -> #REF! | C13: ='Revenue and Exp'!#REF!/'Revenue and Exp'!#REF! -> #REF! | D13: ='Revenue and Exp'!#REF!/'Revenue and Exp'!#REF! -> #REF! | E13: ='Revenue and Exp'!#REF!/'Revenue and Exp'!#REF! -> #REF! | F13: ='Revenue and Exp'!#REF!/'Revenue and Exp'!#REF! -> #REF! | H13: ='Revenue and Exp'!B31/'Revenue and Exp'!B$14 -> 0.067270212 | I13: ='Revenue and Exp'!C31/'Revenue and Exp'!C$14 -> 0.064817088 | J13: ='Revenue and Exp'!D31/'Revenue and Exp'!D$14 -> 0.069943752 | K13: ='Revenue and Exp'!E31/'Revenue and Exp'!E$14 -> 0.066267226 | L13: ='Revenue and Exp'!F31/'Revenue and Exp'!F$14 -> 0.067071302 | N13: =H13/B13-1 -> #REF! | O13: =I13/C13-1 -> #REF! | P13: =J13/D13-1 -> #REF! | Q13: =K13/E13-1 -> #REF! | R13: =L13/F13-1 -> #REF!
A14: Voice (% of Cable Rev) | B14: ='Revenue and Exp'!#REF!/'Revenue and Exp'!#REF! -> #REF! | C14: ='Revenue and Exp'!#REF!/'Revenue and Exp'!#REF! -> #REF! | D14: ='Revenue and Exp'!#REF!/'Revenue and Exp'!#REF! -> #REF! | E14: ='Revenue and Exp'!#REF!/'Revenue and Exp'!#REF! -> #REF! | F14: ='Revenue and Exp'!#REF!/'Revenue and Exp'!#REF! -> #REF! | H14: ='Revenue and Exp'!B30/'Revenue and Exp'!B$14 -> 0.024267572 | I14: ='Revenue and Exp'!C30/'Revenue and Exp'!C$14 -> 0.021360177 | J14: ='Revenue and Exp'!D30/'Revenue and Exp'!D$14 -> 0.020787479 | K14: ='Revenue and Exp'!E30/'Revenue and Exp'!E$14 -> 0.019412822 | L14: ='Revenue and Exp'!F30/'Revenue and Exp'!F$14 -> 0.021427258 | N14: =H14/B14-1 -> #REF! | O14: =I14/C14-1 -> #REF! | P14: =J14/D14-1 -> #REF! | Q14: =K14/E14-1 -> #REF! | R14: =L14/F14-1 -> #REF!
A15: High-Speed Internet (% of Cable Rev) | B15: ='Revenue and Exp'!#REF!/'Revenue and Exp'!#REF! -> #REF! | C15: ='Revenue and Exp'!#REF!/'Revenue and Exp'!#REF! -> #REF! | D15: ='Revenue and Exp'!#REF!/'Revenue and Exp'!#REF! -> #REF! | E15: ='Revenue and Exp'!#REF!/'Revenue and Exp'!#REF! -> #REF! | F15: ='Revenue and Exp'!#REF!/'Revenue and Exp'!#REF! -> #REF! | H15: ='Revenue and Exp'!B29/'Revenue and Exp'!B$14 -> 0.017477681 | I15: ='Revenue and Exp'!C29/'Revenue and Exp'!C$14 -> 0.01681807 | J15: ='Revenue and Exp'!D29/'Revenue and Exp'!D$14 -> 0.016140866 | K15: ='Revenue and Exp'!E29/'Revenue and Exp'!E$14 -> 0.014140204 | L15: ='Revenue and Exp'!F29/'Revenue and Exp'!F$14 -> 0.016124088 | N15: =H15/B15-1 -> #REF! | O15: =I15/C15-1 -> #REF! | P15: =J15/D15-1 -> #REF! | Q15: =K15/E15-1 -> #REF! | R15: =L15/F15-1 -> #REF!
A16: Other (% of Cable Rev) | B16: ='Revenue and Exp'!#REF!/'Revenue and Exp'!#REF! -> #REF! | C16: ='Revenue and Exp'!#REF!/'Revenue and Exp'!#REF! -> #REF! | D16: ='Revenue and Exp'!#REF!/'Revenue and Exp'!#REF! -> #REF! | E16: ='Revenue and Exp'!#REF!/'Revenue and Exp'!#REF! -> #REF! | F16: ='Revenue and Exp'!#REF!/'Revenue and Exp'!#REF! -> #REF! | H16: ='Revenue and Exp'!B32/'Revenue and Exp'!B$14 -> 0.090280397 | I16: ='Revenue and Exp'!C32/'Revenue and Exp'!C$14 -> 0.090842131 | J16: ='Revenue and Exp'!D32/'Revenue and Exp'!D$14 -> 0.09073123 | K16: ='Revenue and Exp'!E32/'Revenue and Exp'!E$14 -> 0.09167166 | L16: ='Revenue and Exp'!F32/'Revenue and Exp'!F$14 -> 0.090889584 | N16: =H16/B16-1 -> #REF! | O16: =I16/C16-1 -> #REF! | P16: =J16/D16-1 -> #REF! | Q16: =K16/E16-1 -> #REF! | R16: =L16/F16-1 -> #REF!
A17: Total Cable Operating Expense (% of Cable Rev) | B17: ='Revenue and Exp'!#REF!/'Revenue and Exp'!#REF! -> #REF! | C17: ='Revenue and Exp'!#REF!/'Revenue and Exp'!#REF! -> #REF! | D17: ='Revenue and Exp'!#REF!/'Revenue and Exp'!#REF! -> #REF! | E17: ='Revenue and Exp'!#REF!/'Revenue and Exp'!#REF! -> #REF! | F17: ='Revenue and Exp'!#REF!/'Revenue and Exp'!#REF! -> #REF! | H17: ='Revenue and Exp'!B33/'Revenue and Exp'!B$14 -> 0.40286684 | I17: ='Revenue and Exp'!C33/'Revenue and Exp'!C$14 -> 0.39160324 | J17: ='Revenue and Exp'!D33/'Revenue and Exp'!D$14 -> 0.39532893 | K17: ='Revenue and Exp'!E33/'Revenue and Exp'!E$14 -> 0.38705812 | L17: ='Revenue and Exp'!F33/'Revenue and Exp'!F$14 -> 0.39412053 | N17: =H17/B17-1 -> #REF! | O17: =I17/C17-1 -> #REF! | P17: =J17/D17-1 -> #REF! | Q17: =K17/E17-1 -> #REF! | R17: =L17/F17-1 -> #REF!
A19: Customer Service (% of Cable Rev) | B19: ='Revenue and Exp'!#REF!/'Revenue and Exp'!#REF! -> #REF! | C19: ='Revenue and Exp'!#REF!/'Revenue and Exp'!#REF! -> #REF! | D19: ='Revenue and Exp'!#REF!/'Revenue and Exp'!#REF! -> #REF! | E19: ='Revenue and Exp'!#REF!/'Revenue and Exp'!#REF! -> #REF! | F19: ='Revenue and Exp'!#REF!/'Revenue and Exp'!#REF! -> #REF! | H19: ='Revenue and Exp'!B35/'Revenue and Exp'!B$14 -> 0.055073557 | I19: ='Revenue and Exp'!C35/'Revenue and Exp'!C$14 -> 0.052786644 | J19: ='Revenue and Exp'!D35/'Revenue and Exp'!D$14 -> 0.053680607 | K19: ='Revenue and Exp'!E35/'Revenue and Exp'!E$14 -> 0.053924506 | L19: ='Revenue and Exp'!F35/'Revenue and Exp'!F$14 -> 0.053859359 | N19: =H19/B19-1 -> #REF! | O19: =I19/C19-1 -> #REF! | P19: =J19/D19-1 -> #REF! | Q19: =K19/E19-1 -> #REF! | R19: =L19/F19-1 -> #REF!
A20: Marketing (% of Cable Rev) | B20: ='Revenue and Exp'!#REF!/'Revenue and Exp'!#REF! -> #REF! | C20: ='Revenue and Exp'!#REF!/'Revenue and Exp'!#REF! -> #REF! | D20: ='Revenue and Exp'!#REF!/'Revenue and Exp'!#REF! -> #REF! | E20: ='Revenue and Exp'!#REF!/'Revenue and Exp'!#REF! -> #REF! | F20: ='Revenue and Exp'!#REF!/'Revenue and Exp'!#REF! -> #REF! | H20: ='Revenue and Exp'!B36/'Revenue and Exp'!B$14 -> 0.050295486 | I20: ='Revenue and Exp'!C36/'Revenue and Exp'!C$14 -> 0.050454211 | J20: ='Revenue and Exp'!D36/'Revenue and Exp'!D$14 -> 0.052213255 | K20: ='Revenue and Exp'!E36/'Revenue and Exp'!E$14 -> 0.046734572 | L20: ='Revenue and Exp'!F36/'Revenue and Exp'!F$14 -> 0.049904972 | N20: =H20/B20-1 -> #REF! | O20: =I20/C20-1 -> #REF! | P20: =J20/D20-1 -> #REF! | Q20: =K20/E20-1 -> #REF! | R20: =L20/F20-1 -> #REF!
A21: Administrative and Other (% of Cable Rev) | B21: ='Revenue and Exp'!#REF!/'Revenue and Exp'!#REF! -> #REF! | C21: ='Revenue and Exp'!#REF!/'Revenue and Exp'!#REF! -> #REF! | D21: ='Revenue and Exp'!#REF!/'Revenue and Exp'!#REF! -> #REF! | E21: ='Revenue and Exp'!#REF!/'Revenue and Exp'!#REF! -> #REF! | F21: ='Revenue and Exp'!#REF!/'Revenue and Exp'!#REF! -> #REF! | H21: ='Revenue and Exp'!B37/'Revenue and Exp'!B$14 -> 0.096944549 | I21: ='Revenue and Exp'!C37/'Revenue and Exp'!C$14 -> 0.092683526 | J21: ='Revenue and Exp'!D37/'Revenue and Exp'!D$14 -> 0.10149181 | K21: ='Revenue and Exp'!E37/'Revenue and Exp'!E$14 -> 0.10317555 | L21: ='Revenue and Exp'!F37/'Revenue and Exp'!F$14 -> 0.098614432 | N21: =H21/B21-1 -> #REF! | O21: =I21/C21-1 -> #REF! | P21: =J21/D21-1 -> #REF! | Q21: =K21/E21-1 -> #REF! | R21: =L21/F21-1 -> #REF!
A22: Total Cable SG&A (% of Cable Rev) | B22: ='Revenue and Exp'!#REF!/'Revenue and Exp'!#REF! -> #REF! | C22: ='Revenue and Exp'!#REF!/'Revenue and Exp'!#REF! -> #REF! | D22: ='Revenue and Exp'!#REF!/'Revenue and Exp'!#REF! -> #REF! | E22: ='Revenue and Exp'!#REF!/'Revenue and Exp'!#REF! -> #REF! | F22: ='Revenue and Exp'!#REF!/'Revenue and Exp'!#REF! -> #REF! | H22: ='Revenue and Exp'!B38/'Revenue and Exp'!B$14 -> 0.20231359 | I22: ='Revenue and Exp'!C38/'Revenue and Exp'!C$14 -> 0.19592438 | J22: ='Revenue and Exp'!D38/'Revenue and Exp'!D$14 -> 0.20738567 | K22: ='Revenue and Exp'!E38/'Revenue and Exp'!E$14 -> 0.20383463 | L22: ='Revenue and Exp'!F38/'Revenue and Exp'!F$14 -> 0.20237876 | N22: =H22/B22-1 -> #REF! | O22: =I22/C22-1 -> #REF! | P22: =J22/D22-1 -> #REF! | Q22: =K22/E22-1 -> #REF! | R22: =L22/F22-1 -> #REF!
A24: Total Cable (% of Cable Rev) | B24: ='Revenue and Exp'!#REF!/'Revenue and Exp'!#REF! -> #REF! | C24: ='Revenue and Exp'!#REF!/'Revenue and Exp'!#REF! -> #REF! | D24: ='Revenue and Exp'!#REF!/'Revenue and Exp'!#REF! -> #REF! | E24: ='Revenue and Exp'!#REF!/'Revenue and Exp'!#REF! -> #REF! | F24: ='Revenue and Exp'!#REF!/'Revenue and Exp'!#REF! -> #REF! | H24: ='Revenue and Exp'!B40/'Revenue and Exp'!B$14 -> 0.60518044 | I24: ='Revenue and Exp'!C40/'Revenue and Exp'!C$14 -> 0.58752762 | J24: ='Revenue and Exp'!D40/'Revenue and Exp'!D$14 -> 0.6027146 | K24: ='Revenue and Exp'!E40/'Revenue and Exp'!E$14 -> 0.59089275 | L24: ='Revenue and Exp'!F40/'Revenue and Exp'!F$14 -> 0.59649929 | N24: =H24/B24-1 -> #REF! | O24: =I24/C24-1 -> #REF! | P24: =J24/D24-1 -> #REF! | Q24: =K24/E24-1 -> #REF! | R24: =L24/F24-1 -> #REF!
A26: Programming (% of Programming Rev) | B26: ='Revenue and Exp'!#REF!/'Revenue and Exp'!#REF! -> #REF! | C26: ='Revenue and Exp'!#REF!/'Revenue and Exp'!#REF! -> #REF! | D26: ='Revenue and Exp'!#REF!/'Revenue and Exp'!#REF! -> #REF! | E26: ='Revenue and Exp'!#REF!/'Revenue and Exp'!#REF! -> #REF! | F26: ='Revenue and Exp'!#REF!/'Revenue and Exp'!#REF! -> #REF! | H26: ='Revenue and Exp'!B42/'Revenue and Exp'!B$19 -> 0.68870523 | I26: ='Revenue and Exp'!C42/'Revenue and Exp'!C$19 -> 0.7568306 | J26: ='Revenue and Exp'!D42/'Revenue and Exp'!D$19 -> 0.69740634 | K26: ='Revenue and Exp'!E42/'Revenue and Exp'!E$19 -> 0.84285714 | L26: ='Revenue and Exp'!F42/'Revenue and Exp'!F$19 -> 0.74614306 | N26: =H26/B26-1 -> #REF! | O26: =I26/C26-1 -> #REF! | P26: =J26/D26-1 -> #REF! | Q26: =K26/E26-1 -> #REF! | R26: =L26/F26-1 -> #REF!
A28: Corporate and Other (% of Total Rev) | B28: ='Revenue and Exp'!#REF!/'Revenue and Exp'!#REF! -> #REF! | C28: ='Revenue and Exp'!#REF!/'Revenue and Exp'!#REF! -> #REF! | D28: ='Revenue and Exp'!#REF!/'Revenue and Exp'!#REF! -> #REF! | E28: ='Revenue and Exp'!#REF!/'Revenue and Exp'!#REF! -> #REF! | F28: ='Revenue and Exp'!#REF!/'Revenue and Exp'!#REF! -> #REF! | H28: ='Revenue and Exp'!B44/'Revenue and Exp'!B$23 -> 0.022082393 | I28: ='Revenue and Exp'!C44/'Revenue and Exp'!C$23 -> 0.021286495 | J28: ='Revenue and Exp'!D44/'Revenue and Exp'!D$23 -> 0.02141527 | K28: ='Revenue and Exp'!E44/'Revenue and Exp'!E$23 -> 0.024401317 | L28: ='Revenue and Exp'!F44/'Revenue and Exp'!F$23 -> 0.022310664 | N28: =H28/B28-1 -> #REF! | O28: =I28/C28-1 -> #REF! | P28: =J28/D28-1 -> #REF! | Q28: =K28/E28-1 -> #REF! | R28: =L28/F28-1 -> #REF!
A30: Total Consolidated Operating Expense (% of Total Rev) | B30: ='Revenue and Exp'!#REF!/'Revenue and Exp'!#REF! -> #REF! | C30: ='Revenue and Exp'!#REF!/'Revenue and Exp'!#REF! -> #REF! | D30: ='Revenue and Exp'!#REF!/'Revenue and Exp'!#REF! -> #REF! | E30: ='Revenue and Exp'!#REF!/'Revenue and Exp'!#REF! -> #REF! | F30: ='Revenue and Exp'!#REF!/'Revenue and Exp'!#REF! -> #REF! | H30: ='Revenue and Exp'!B46/'Revenue and Exp'!B$23 -> 0.62317464 | I30: ='Revenue and Exp'!C46/'Revenue and Exp'!C$23 -> 0.61021286 | J30: ='Revenue and Exp'!D46/'Revenue and Exp'!D$23 -> 0.62325419 | K30: ='Revenue and Exp'!E46/'Revenue and Exp'!E$23 -> 0.61752355 | L30: ='Revenue and Exp'!F46/'Revenue and Exp'!F$23 -> 0.61851088 | N30: =H30/B30-1 -> #REF! | O30: =I30/C30-1 -> #REF! | P30: =J30/D30-1 -> #REF! | Q30: =K30/E30-1 -> #REF! | R30: =L30/F30-1 -> #REF!
A32: Operating Cash Flow (OCF)
A33: Cable | B33: 2876 | C33: 3124 | D33: 3050 | E33: 3196 | F33: =SUM(B33:E33) -> 12246 | H33: 3142 | I33: 3362 | J33: 3251 | K33: 3415 | L33: 13170 | N33: =H33/B33-1 -> 0.092489569 | O33: =I33/C33-1 -> 0.076184379 | P33: =J33/D33-1 -> 0.065901639 | Q33: =K33/E33-1 -> 0.068523154 | R33: =L33/F33-1 -> 0.075453209
A34: Programming | B34: 64.537684 | C34: 75 | D34: 97 | E34: 49 | F34: =SUM(B34:E34) -> 285.53768 | H34: 113.30411 | I34: 89 | J34: 105.16293 | K34: 55.032389 | L34: =SUM(H34:K34) -> 362.49943 | N34: =H34/B34-1 -> 0.75562712 | O34: =I34/C34-1 -> 0.18666667 | P34: =J34/D34-1 -> 0.084153947 | Q34: =K34/E34-1 -> 0.12310998 | R34: =L34/F34-1 -> 0.26953271
A35: Corporate & Other | B35: -96 | C35: -93 | D35: -143 | E35: -91 | F35: =SUM(B35:E35) -> -423 | H35: -81 | I35: -100 | J35: -119 | K35: =#REF!-K28 -> #REF! | L35: =SUM(H35:K35) -> #REF! | N35: =H35/B35-1 -> -0.15625 | O35: =I35/C35-1 -> 0.075268817 | P35: =J35/D35-1 -> -0.16783217 | Q35: =K35/E35-1 -> #REF! | R35: =L35/F35-1 -> #REF!
A36: Total Consolidated OCF | B36: =+B33+B34+B35 -> 2844.5377 | C36: =+C33+C34+C35 -> 3106 | D36: =+D33+D34+D35 -> 3004 | E36: =+E33+E34+E35 -> 3154 | F36: =SUM(F31:F35) -> 12108.538 | H36: =+H33+H34+H35 -> 3174.3041 | I36: =+I33+I34+I35 -> 3351 | J36: =+J33+J34+J35 -> 3237.1629 | K36: =+K33+K34+K35 -> #REF! | L36: =SUM(L33:L35) -> #REF! | N36: =H36/B36-1 -> 0.11592971 | O36: =I36/C36-1 -> 0.078879588 | P36: =J36/D36-1 -> 0.077617488 | Q36: =K36/E36-1 -> #REF! | R36: =L36/F36-1 -> #REF!
A38: Cable | B38: =+B33/#REF! -> #REF! | C38: =+C33/#REF! -> #REF! | D38: =+D33/#REF! -> #REF! | E38: =+E33/#REF! -> #REF! | F38: =+F33/#REF! -> #REF! | H38: =+H33/#REF! -> #REF! | I38: =+I33/#REF! -> #REF! | J38: =+J33/#REF! -> #REF! | K38: =+K33/#REF! -> #REF! | L38: =+L33/#REF! -> #REF! | N38: =H38/B38-1 -> #REF! | O38: =I38/C38-1 -> #REF! | P38: =J38/D38-1 -> #REF! | Q38: =K38/E38-1 -> #REF! | R38: =L38/F38-1 -> #REF!
A39: Programming | B39: =B34/#REF! -> #REF! | C39: =C34/#REF! -> #REF! | D39: =D34/#REF! -> #REF! | E39: =E34/#REF! -> #REF! | F39: =F34/#REF! -> #REF! | H39: =H34/#REF! -> #REF! | I39: =I34/#REF! -> #REF! | J39: =J34/#REF! -> #REF! | K39: =K34/#REF! -> #REF! | L39: =L34/#REF! -> #REF! | N39: =H39/B39-1 -> #REF! | O39: =I39/C39-1 -> #REF! | P39: =J39/D39-1 -> #REF! | Q39: =K39/E39-1 -> #REF! | R39: =L39/F39-1 -> #REF!
A40: Total Consolidated OCF Margin | B40: =+B36/#REF! -> #REF! | C40: =+C36/#REF! -> #REF! | D40: =+D36/#REF! -> #REF! | E40: =+E36/#REF! -> #REF! | F40: =+F36/#REF! -> #REF! | H40: =+H36/#REF! -> #REF! | I40: =+I36/#REF! -> #REF! | J40: =+J36/#REF! -> #REF! | K40: =+K36/#REF! -> #REF! | L40: =+L36/#REF! -> #REF! | N40: =H40/B40-1 -> #REF! | O40: =I40/C40-1 -> #REF! | P40: =J40/D40-1 -> #REF! | Q40: =K40/E40-1 -> #REF! | R40: =L40/F40-1 -> #REF!
A42: * Business Services Revenue (included in Total Cable) | B42: 87 | C42: 95 | D42: 102 | E42: 110 | F42: =SUM(B42:E42) -> 394 | H42: 120 | I42: 131 | J42: 145 | K42: 162 | L42: =SUM(H42:K42) -> 558 | N42: =H42/B42-1 -> 0.37931034 | O42: =I42/C42-1 -> 0.37894737 | P42: =J42/D42-1 -> 0.42156863 | Q42: =K42/E42-1 -> 0.47272727 | R42: =L42/F42-1 -> 0.41624365
A44: Total Operating Expense as a % of Total Revenue
A45: Total Cable (% of Total Rev) | B45: ='Revenue and Exp'!#REF!/'Revenue and Exp'!#REF! -> #REF! | C45: ='Revenue and Exp'!#REF!/'Revenue and Exp'!#REF! -> #REF! | D45: ='Revenue and Exp'!#REF!/'Revenue and Exp'!#REF! -> #REF! | E45: ='Revenue and Exp'!#REF!/'Revenue and Exp'!#REF! -> #REF! | F45: ='Revenue and Exp'!#REF!/'Revenue and Exp'!#REF! -> #REF! | H45: ='Revenue and Exp'!B40/'Revenue and Exp'!B$23 -> 0.57141161 | I45: ='Revenue and Exp'!C40/'Revenue and Exp'!C$23 -> 0.55670583 | J45: ='Revenue and Exp'!D40/'Revenue and Exp'!D$23 -> 0.57367318 | K45: ='Revenue and Exp'!E40/'Revenue and Exp'!E$23 -> 0.55964136 | L45: ='Revenue and Exp'!F40/'Revenue and Exp'!F$23 -> 0.56529065
A47: Programming (% of Total Rev) | B47: ='Revenue and Exp'!#REF!/'Revenue and Exp'!#REF! -> #REF! | C47: ='Revenue and Exp'!#REF!/'Revenue and Exp'!#REF! -> #REF! | D47: ='Revenue and Exp'!#REF!/'Revenue and Exp'!#REF! -> #REF! | E47: ='Revenue and Exp'!#REF!/'Revenue and Exp'!#REF! -> #REF! | F47: ='Revenue and Exp'!#REF!/'Revenue and Exp'!#REF! -> #REF! | H47: ='Revenue and Exp'!B42/'Revenue and Exp'!B$23 -> 0.029680636 | I47: ='Revenue and Exp'!C42/'Revenue and Exp'!C$23 -> 0.032220542 | J47: ='Revenue and Exp'!D42/'Revenue and Exp'!D$23 -> 0.028165736 | K47: ='Revenue and Exp'!E42/'Revenue and Exp'!E$23 -> 0.033480876 | L47: ='Revenue and Exp'!F42/'Revenue and Exp'!F$23 -> 0.030909566
A49: Corporate and Other (% of Total Rev) | B49: ='Revenue and Exp'!#REF!/'Revenue and Exp'!#REF! -> #REF! | C49: ='Revenue and Exp'!#REF!/'Revenue and Exp'!#REF! -> #REF! | D49: ='Revenue and Exp'!#REF!/'Revenue and Exp'!#REF! -> #REF! | E49: ='Revenue and Exp'!#REF!/'Revenue and Exp'!#REF! -> #REF! | F49: ='Revenue and Exp'!#REF!/'Revenue and Exp'!#REF! -> #REF! | H49: ='Revenue and Exp'!B44/'Revenue and Exp'!B$23 -> 0.022082393 | I49: ='Revenue and Exp'!C44/'Revenue and Exp'!C$23 -> 0.021286495 | J49: ='Revenue and Exp'!D44/'Revenue and Exp'!D$23 -> 0.02141527 | K49: ='Revenue and Exp'!E44/'Revenue and Exp'!E$23 -> 0.024401317 | L49: ='Revenue and Exp'!F44/'Revenue and Exp'!F$23 -> 0.022310664
A51: Total Consolidated Operating Expense (% of Total Rev) | B51: ='Revenue and Exp'!#REF!/'Revenue and Exp'!#REF! -> #REF! | C51: ='Revenue and Exp'!#REF!/'Revenue and Exp'!#REF! -> #REF! | D51: ='Revenue and Exp'!#REF!/'Revenue and Exp'!#REF! -> #REF! | E51: ='Revenue and Exp'!#REF!/'Revenue and Exp'!#REF! -> #REF! | F51: ='Revenue and Exp'!#REF!/'Revenue and Exp'!#REF! -> #REF! | H51: ='Revenue and Exp'!B46/'Revenue and Exp'!B$23 -> 0.62317464 | I51: ='Revenue and Exp'!C46/'Revenue and Exp'!C$23 -> 0.61021286 | J51: ='Revenue and Exp'!D46/'Revenue and Exp'!D$23 -> 0.62325419 | K51: ='Revenue and Exp'!E46/'Revenue and Exp'!E$23 -> 0.61752355 | L51: ='Revenue and Exp'!F46/'Revenue and Exp'!F$23 -> 0.61851088
A52: Note: Pro Forma adjustments for 2007 include the cable system acquired from Patriot Media, the SportsNet Bay Area/Sports Channel New England acquisitions and the cable systems acquired
A53: as a result of the dissolution of our cable partnership with Insight Communications.
A54: (1) Results have been adjusted to reflect the impact of the Insight, Patriot, New England SN and Bay Area SN Acquisitions
A56: Revenue:
...

Sheet Capex and FCF
A1: Capital Expenditures and Free Cash Flow
A2: ($ and shares in millions, except per share data; unaudited)
B4: 2008 | H4: 2009 | N4: 2010
B5: 1Q | C5: 2Q | D5: 3Q | E5: 4Q | F5: FY | H5: 1Q | I5: 2Q | J5: 3Q | K5: 4Q | L5: FY | N5: 1Q | O5: 2Q | P5: 3Q
A7: Capital Expenditures
A9: Growth Capital
A10: Customer Premise Equipment (CPE) | B10: 819 | C10: 687 | D10: 590 | E10: 775 | F10: 2871 | H10: 704 | I10: 564 | J10: 626 | K10: 750 | L10: 2644 | N10: 518 | O10: 566 | P10: 675
A11: Scalable Infrastructure | B11: 59 | C11: 55 | D11: 61 | E11: 80 | F11: 255 | H11: 31 | I11: 47 | J11: 45 | K11: 88 | L11: 211 | N11: 25 | O11: 39 | P11: 50
A12: Line Extensions | B12: 48 | C12: 52 | D12: 54 | E12: 58 | F12: 212 | H12: 27 | I12: 30 | J12: 31 | K12: 32 | L12: 120 | N12: 19 | O12: 24 | P12: 28
A13: Support Capital | B13: 54 | C13: 57 | D13: 65 | E13: 102 | F13: 278 | H13: 45 | I13: 40 | J13: 49 | K13: 81 | L13: 215 | N13: 32 | O13: 39 | P13: 55
A14: Upgrades (Capacity Expansion) | B14: 21 | C14: 25 | D14: 13 | E14: 8 | F14: 67 | H14: 1 | I14: 4 | J14: 5 | K14: 5 | L14: 15 | N14: 2 | O14: 3 | P14: 4
A15: Business Services | B15: 50 | C15: 48 | D15: 61 | E15: 72 | F15: 231 | H15: 53 | I15: 85 | J15: 94 | K15: 119 | L15: 351 | N15: 96 | O15: 109 | P15: 129
A16: Total Growth Capital | B16: 1051 | C16: 924 | D16: 844 | E16: 1095 | F16: 3914 | H16: 861 | I16: 770 | J16: 850 | K16: 1075 | L16: 3556 | N16: 692 | O16: 780 | P16: 941
A18: Maintenance Capital
A19: CPE | B19: 58 | C19: 73 | D19: 76 | E19: 69 | F19: 276 | H19: 62 | I19: 76 | J19: 82 | K19: 70 | L19: 290 | N19: 57 | O19: 71 | P19: 74
A20: Scalable Infrastructure | B20: 103 | C20: 115 | D20: 194 | E20: 269 | F20: 681 | H20: 97 | I20: 137 | J20: 130 | K20: 248 | L20: 612 | N20: 66 | O20: 121 | P20: 134
A21: Support Capital | B21: 43 | C21: 58 | D21: 54 | E21: 72 | F21: 227 | H21: 39 | I21: 36 | J21: 48 | K21: 70 | L21: 193 | N21: 23 | O21: 30 | P21: 45
A22: Upgrades | B22: 60 | C22: 58 | D22: 81 | E22: 141 | F22: 340 | H22: 63 | I22: 83 | J22: 93 | K22: 102 | L22: 341 | N22: 55 | O22: 81 | P22: 92
A23: Total Maintenance Capital | B23: 264 | C23: 304 | D23: 405 | E23: 551 | F23: 1524 | H23: 261 | I23: 332 | J23: 353 | K23: 490 | L23: 1436 | N23: 201 | O23: 303 | P23: 345
A25: Strategic/Discretionary Capital | B25: 40 | C25: 26 | D25: 19 | E25: 22 | F25: 107 | H25: 8 | I25: 6 | J25: 9 | K25: 22 | L25: 45 | N25: 20 | O25: 37 | P25: 32
A27: Total Cable Segment13 | B27: 1355 | C27: 1254 | D27: 1268 | E27: 1668 | F27: 5545 | H27: 1130 | I27: 1108 | J27: 1212 | K27: 1587 | L27: 5037 | N27: 913 | O27: 1120 | P27: 1318
A29: Total Programming Segment | B29: 4 | C29: 6 | D29: 12 | E29: 22 | F29: 44 | H29: 8 | I29: 6 | J29: 9 | K29: 11 | L29: 34 | N29: 5 | O29: 7 | P29: 7
A31: Corporate and Other | B31: 72 | C31: 40 | D31: 26 | E31: 23 | F31: 161 | H31: 22 | I31: 7 | J31: 6 | K31: 11 | L31: 46 | N31: 7 | O31: 11 | P31: 41
A33: Total Consolidated Capital Expenditures | B33: 1431 | C33: 1300 | D33: 1306 | E33: 1713 | F33: 5750 | H33: 1160 | I33: 1121 | J33: 1227 | K33: 1609 | L33: 5117 | N33: 925 | O33: 1138 | P33: 1366
A34: Percent of Total Consolidated Revenue | B34: 0.16988925 | C34: 0.15118048 | D34: 0.15199487 | E34: 0.19440676 | F34: 0.16702563 | H34: 0.13083976 | I34: 0.12488787 | J34: 0.13865537 | K34: 0.17750653 | L34: 0.14311208 | N34: 0.10052211 | O34: 0.11947857 | P34: 0.14395456
A36: Free Cash Flow14
A38: Net Cash Provided by Operating Activities | B38: 2259 | C38: 2669 | D38: 2445 | E38: 2858 | F38: 10231 | H38: 2512 | I38: 2601 | J38: 2612 | K38: 2556 | L38: 10281 | N38: 2903 | O38: 2429 | P38: 2400
A39: Capital Expenditures | B39: -1431 | C39: -1300 | D39: -1306 | E39: -1713 | F39: -5750 | H39: -1160 | I39: -1121 | J39: -1227 | K39: -1609 | L39: -5117 | N39: -925 | O39: -1138 | P39: -1366
A40: Cash Paid for Capitalized Software | B40: -99 | C40: -88 | D40: -100 | E40: -123 | F40: -410 | H40: -105 | I40: -83 | J40: -99 | K40: -106 | L40: -393 | N40: -80 | O40: -95 | P40: -102
A41: Cash Paid for Other Intangible Assets | B41: -27 | C41: -31 | D41: -31 | E41: -28 | F41: -117 | H41: -28 | I41: -25 | J41: -43 | K41: -33 | L41: -129 | N41: -37 | O41: -25 | P41: -33
A43: Adjustments for Payment of Tax on Nonoperating Items | B43: 0 | C43: 228 | D43: 88 | E43: -13 | F43: 303 | H43: 147 | I43: 3 | J43: -84 | K43: 49 | L43: 115 | N43: 26 | O43: 5 | P43: 37
A44: Free Cash Flow (Including Economic Stimulus Packages) | B44: 702 | C44: 1478 | D44: 1096 | E44: 981 | F44: 4257 | H44: 1366 | I44: 1375 | J44: 1159 | K44: 857 | L44: 4757 | N44: 1887 | O44: 1176 | P44: 936
A45: Economic Stimulus Packages * | B45: 0 | C45: -315 | D45: -168 | E45: -117 | F45: -600 | H45: 0 | I45: -205 | J45: -47 | K45: -89 | L45: -341 | N45: 0 | O45: 179 | P45: 89
A47: Free Cash Flow | B47: 702 | C47: 1163 | D47: 928 | E47: 864 | F47: 3657 | H47: 1366 | I47: 1170 | J47: 1112 | K47: 768 | L47: 4416 | N47: 1887 | O47: 1355 | P47: 1025
A49: Free Cash Flow per Share | B49: 0.23266304 | C49: 0.39155577 | D49: 0.3178227 | E49: 0.29917046 | F49: 1.2387159 | H49: 0.47261413 | I49: 0.40468915 | J49: 0.3865242 | K49: 0.26835682 | L49: 1.5308054 | N49: 0.6651093 | O49: 0.48 | P49: 0.36472237
A51: Diluted weighted-average number of common shares | B51: 3017 | C51: 2970 | D51: 2920 | E51: 2888 | F51: 2952 | H51: 2890 | I51: 2891 | J51: 2877 | K51: 2862 | L51: 2885 | N51: 2837 | O51: 2822 | P51: 2810
A54: *Our definition of Free Cash Flow remains unchanged and specifically excludes any impact from the 2008-2010 Economic Stimulus packages. These amounts have been excluded from Free Cash Flow to provide an appropriate comparison.

Sheet Notes
A1: Notes

Sheet Capex as a % of Cable Capex
L1: Pro Forma Capex as a % of Cable and Total Capex
B3: 2007 | H3: 2008 | N3: Growth
B4: 1Q | C4: 2Q | D4: 3Q | E4: 4Q | F4: FY | H4: 1Q | I4: 2Q | J4: 3Q | K4: 4Q | L4: FY | N4: 1Q | O4: 2Q | P4: 3Q | Q4: 4Q | R4: FY
A6: Capex as a % of Cable and Total Capex
A8: Growth Capital (as a % of Cable Capex)
A9: Customer Premise Equipment (CPE) | B9: ='Capex and FCF'!#REF!/'Capex and FCF'!#REF! -> #REF! | C9: ='Capex and FCF'!#REF!/'Capex and FCF'!#REF! -> #REF! | D9: ='Capex and FCF'!#REF!/'Capex and FCF'!#REF! -> #REF! | E9: ='Capex and FCF'!#REF!/'Capex and FCF'!#REF! -> #REF! | F9: ='Capex and FCF'!#REF!/'Capex and FCF'!#REF! -> #REF! | H9: ='Capex and FCF'!B10/'Capex and FCF'!B$27 -> 0.60442804 | I9: ='Capex and FCF'!C10/'Capex and FCF'!C$27 -> 0.54784689 | J9: ='Capex and FCF'!D10/'Capex and FCF'!D$27 -> 0.46529968 | K9: ='Capex and FCF'!E10/'Capex and FCF'!E$27 -> 0.4646283 | L9: ='Capex and FCF'!F10/'Capex and FCF'!F$27 -> 0.51776375 | N9: =H9/B9-1 -> #REF! | O9: =I9/C9-1 -> #REF! | P9: =J9/D9-1 -> #REF! | Q9: =K9/E9-1 -> #REF! | R9: =L9/F9-1 -> #REF!
A10: Scalable Infrastructure | B10: ='Capex and FCF'!#REF!/'Capex and FCF'!#REF! -> #REF! | C10: ='Capex and FCF'!#REF!/'Capex and FCF'!#REF! -> #REF! | D10: ='Capex and FCF'!#REF!/'Capex and FCF'!#REF! -> #REF! | E10: ='Capex and FCF'!#REF!/'Capex and FCF'!#REF! -> #REF! | F10: ='Capex and FCF'!#REF!/'Capex and FCF'!#REF! -> #REF! | H10: ='Capex and FCF'!B11/'Capex and FCF'!B$27 -> 0.043542435 | I10: ='Capex and FCF'!C11/'Capex and FCF'!C$27 -> 0.043859649 | J10: ='Capex and FCF'!D11/'Capex and FCF'!D$27 -> 0.048107256 | K10: ='Capex and FCF'!E11/'Capex and FCF'!E$27 -> 0.047961631 | L10: ='Capex and FCF'!F11/'Capex and FCF'!F$27 -> 0.045987376 | N10: =H10/B10-1 -> #REF! | O10: =I10/C10-1 -> #REF! | P10: =J10/D10-1 -> #REF! | Q10: =K10/E10-1 -> #REF! | R10: =L10/F10-1 -> #REF!
A11: Line Extensions | B11: ='Capex and FCF'!#REF!/'Capex and FCF'!#REF! -> #REF! | C11: ='Capex and FCF'!#REF!/'Capex and FCF'!#REF! -> #REF! | D11: ='Capex and FCF'!#REF!/'Capex and FCF'!#REF! -> #REF! | E11: ='Capex and FCF'!#REF!/'Capex and FCF'!#REF! -> #REF! | F11: ='Capex and FCF'!#REF!/'Capex and FCF'!#REF! -> #REF! | H11: ='Capex and FCF'!B12/'Capex and FCF'!B$27 -> 0.035424354 | I11: ='Capex and FCF'!C12/'Capex and FCF'!C$27 -> 0.041467305 | J11: ='Capex and FCF'!D12/'Capex and FCF'!D$27 -> 0.042586751 | K11: ='Capex and FCF'!E12/'Capex and FCF'!E$27 -> 0.034772182 | L11: ='Capex and FCF'!F12/'Capex and FCF'!F$27 -> 0.038232642 | N11: =H11/B11-1 -> #REF! | O11: =I11/C11-1 -> #REF! | P11: =J11/D11-1 -> #REF! | Q11: =K11/E11-1 -> #REF! | R11: =L11/F11-1 -> #REF!
A12: Support Capital | B12: ='Capex and FCF'!#REF!/'Capex and FCF'!#REF! -> #REF! | C12: ='Capex and FCF'!#REF!/'Capex and FCF'!#REF! -> #REF! | D12: ='Capex and FCF'!#REF!/'Capex and FCF'!#REF! -> #REF! | E12: ='Capex and FCF'!#REF!/'Capex and FCF'!#REF! -> #REF! | F12: ='Capex and FCF'!#REF!/'Capex and FCF'!#REF! -> #REF! | H12: ='Capex and FCF'!B13/'Capex and FCF'!B$27 -> 0.039852399 | I12: ='Capex and FCF'!C13/'Capex and FCF'!C$27 -> 0.045454545 | J12: ='Capex and FCF'!D13/'Capex and FCF'!D$27 -> 0.05126183 | K12: ='Capex and FCF'!E13/'Capex and FCF'!E$27 -> 0.061151079 | L12: ='Capex and FCF'!F13/'Capex and FCF'!F$27 -> 0.050135257 | N12: =H12/B12-1 -> #REF! | O12: =I12/C12-1 -> #REF! | P12: =J12/D12-1 -> #REF! | Q12: =K12/E12-1 -> #REF! | R12: =L12/F12-1 -> #REF!
A13: Upgrades (Capacity Expansion) | B13: ='Capex and FCF'!#REF!/'Capex and FCF'!#REF! -> #REF! | C13: ='Capex and FCF'!#REF!/'Capex and FCF'!#REF! -> #REF! | D13: ='Capex and FCF'!#REF!/'Capex and FCF'!#REF! -> #REF! | E13: ='Capex and FCF'!#REF!/'Capex and FCF'!#REF! -> #REF! | F13: ='Capex and FCF'!#REF!/'Capex and FCF'!#REF! -> #REF! | H13: ='Capex and FCF'!B14/'Capex and FCF'!B$27 -> 0.015498155 | I13: ='Capex and FCF'!C14/'Capex and FCF'!C$27 -> 0.019936204 | J13: ='Capex and FCF'!D14/'Capex and FCF'!D$27 -> 0.010252366 | K13: ='Capex and FCF'!E14/'Capex and FCF'!E$27 -> 0.0047961631 | L13: ='Capex and FCF'!F14/'Capex and FCF'!F$27 -> 0.012082958 | N13: =H13/B13-1 -> #REF! | O13: =I13/C13-1 -> #REF! | P13: =J13/D13-1 -> #REF! | Q13: =K13/E13-1 -> #REF! | R13: =L13/F13-1 -> #REF!
A14: Business Services | B14: ='Capex and FCF'!#REF!/'Capex and FCF'!#REF! -> #REF! | C14: ='Capex and FCF'!#REF!/'Capex and FCF'!#REF! -> #REF! | D14: ='Capex and FCF'!#REF!/'Capex and FCF'!#REF! -> #REF! | E14: ='Capex and FCF'!#REF!/'Capex and FCF'!#REF! -> #REF! | F14: ='Capex and FCF'!#REF!/'Capex and FCF'!#REF! -> #REF! | H14: ='Capex and FCF'!B15/'Capex and FCF'!B$27 -> 0.036900369 | I14: ='Capex and FCF'!C15/'Capex and FCF'!C$27 -> 0.038277512 | J14: ='Capex and FCF'!D15/'Capex and FCF'!D$27 -> 0.048107256 | K14: ='Capex and FCF'!E15/'Capex and FCF'!E$27 -> 0.043165468 | L14: ='Capex and FCF'!F15/'Capex and FCF'!F$27 -> 0.041659152 | N14: =H14/B14-1 -> #REF! | O14: =I14/C14-1 -> #REF! | P14: =J14/D14-1 -> #REF! | Q14: =K14/E14-1 -> #REF! | R14: =L14/F14-1 -> #REF!
A15: Total Growth Capital | B15: ='Capex and FCF'!#REF!/'Capex and FCF'!#REF! -> #REF! | C15: ='Capex and FCF'!#REF!/'Capex and FCF'!#REF! -> #REF! | D15: ='Capex and FCF'!#REF!/'Capex and FCF'!#REF! -> #REF! | E15: ='Capex and FCF'!#REF!/'Capex and FCF'!#REF! -> #REF! | F15: ='Capex and FCF'!#REF!/'Capex and FCF'!#REF! -> #REF! | H15: ='Capex and FCF'!B16/'Capex and FCF'!B$27 -> 0.77564576 | I15: ='Capex and FCF'!C16/'Capex and FCF'!C$27 -> 0.73684211 | J15: ='Capex and FCF'!D16/'Capex and FCF'!D$27 -> 0.66561514 | K15: ='Capex and FCF'!E16/'Capex and FCF'!E$27 -> 0.65647482 | L15: ='Capex and FCF'!F16/'Capex and FCF'!F$27 -> 0.70586114 | N15: =H15/B15-1 -> #REF! | O15: =I15/C15-1 -> #REF! | P15: =J15/D15-1 -> #REF! | Q15: =K15/E15-1 -> #REF! | R15: =L15/F15-1 -> #REF!
A17: Maintenance Capital (as a % of Cable Capex)
A18: CPE (Drop Replacements) | B18: ='Capex and FCF'!#REF!/'Capex and FCF'!#REF! -> #REF! | C18: ='Capex and FCF'!#REF!/'Capex and FCF'!#REF! -> #REF! | D18: ='Capex and FCF'!#REF!/'Capex and FCF'!#REF! -> #REF! | E18: ='Capex and FCF'!#REF!/'Capex and FCF'!#REF! -> #REF! | F18: ='Capex and FCF'!#REF!/'Capex and FCF'!#REF! -> #REF! | H18: ='Capex and FCF'!B19/'Capex and FCF'!B$27 -> 0.042804428 | I18: ='Capex and FCF'!C19/'Capex and FCF'!C$27 -> 0.058213716 | J18: ='Capex and FCF'!D19/'Capex and FCF'!D$27 -> 0.059936909 | K18: ='Capex and FCF'!E19/'Capex and FCF'!E$27 -> 0.041366906 | L18: ='Capex and FCF'!F19/'Capex and FCF'!F$27 -> 0.049774572 | N18: =H18/B18-1 -> #REF! | O18: =I18/C18-1 -> #REF! | P18: =J18/D18-1 -> #REF! | Q18: =K18/E18-1 -> #REF! | R18: =L18/F18-1 -> #REF!
A19: Scalable Infrastructure | B19: ='Capex and FCF'!#REF!/'Capex and FCF'!#REF! -> #REF! | C19: ='Capex and FCF'!#REF!/'Capex and FCF'!#REF! -> #REF! | D19: ='Capex and FCF'!#REF!/'Capex and FCF'!#REF! -> #REF! | E19: ='Capex and FCF'!#REF!/'Capex and FCF'!#REF! -> #REF! | F19: ='Capex and FCF'!#REF!/'Capex and FCF'!#REF! -> #REF! | H19: ='Capex and FCF'!B20/'Capex and FCF'!B$27 -> 0.07601476 | I19: ='Capex and FCF'!C20/'Capex and FCF'!C$27 -> 0.091706539 | J19: ='Capex and FCF'!D20/'Capex and FCF'!D$27 -> 0.15299685 | K19: ='Capex and FCF'!E20/'Capex and FCF'!E$27 -> 0.16127098 | L19: ='Capex and FCF'!F20/'Capex and FCF'!F$27 -> 0.12281335 | N19: =H19/B19-1 -> #REF! | O19: =I19/C19-1 -> #REF! | P19: =J19/D19-1 -> #REF! | Q19: =K19/E19-1 -> #REF! | R19: =L19/F19-1 -> #REF!
A20: Support Capital | B20: ='Capex and FCF'!#REF!/'Capex and FCF'!#REF! -> #REF! | C20: ='Capex and FCF'!#REF!/'Capex and FCF'!#REF! -> #REF! | D20: ='Capex and FCF'!#REF!/'Capex and FCF'!#REF! -> #REF! | E20: ='Capex and FCF'!#REF!/'Capex and FCF'!#REF! -> #REF! | F20: ='Capex and FCF'!#REF!/'Capex and FCF'!#REF! -> #REF! | H20: ='Capex and FCF'!B21/'Capex and FCF'!B$27 -> 0.031734317 | I20: ='Capex and FCF'!C21/'Capex and FCF'!C$27 -> 0.046251994 | J20: ='Capex and FCF'!D21/'Capex and FCF'!D$27 -> 0.042586751 | K20: ='Capex and FCF'!E21/'Capex and FCF'!E$27 -> 0.043165468 | L20: ='Capex and FCF'!F21/'Capex and FCF'!F$27 -> 0.040937782 | N20: =H20/B20-1 -> #REF! | O20: =I20/C20-1 -> #REF! | P20: =J20/D20-1 -> #REF! | Q20: =K20/E20-1 -> #REF! | R20: =L20/F20-1 -> #REF!
A21: Upgrades | B21: ='Capex and FCF'!#REF!/'Capex and FCF'!#REF! -> #REF! | C21: ='Capex and FCF'!#REF!/'Capex and FCF'!#REF! -> #REF! | D21: ='Capex and FCF'!#REF!/'Capex and FCF'!#REF! -> #REF! | E21: ='Capex and FCF'!#REF!/'Capex and FCF'!#REF! -> #REF! | F21: ='Capex and FCF'!#REF!/'Capex and FCF'!#REF! -> #REF! | H21: ='Capex and FCF'!B22/'Capex and FCF'!B$27 -> 0.044280443 | I21: ='Capex and FCF'!C22/'Capex and FCF'!C$27 -> 0.046251994 | J21: ='Capex and FCF'!D22/'Capex and FCF'!D$27 -> 0.063880126 | K21: ='Capex and FCF'!E22/'Capex and FCF'!E$27 -> 0.084532374 | L21: ='Capex and FCF'!F22/'Capex and FCF'!F$27 -> 0.061316501 | N21: =H21/B21-1 -> #REF! | O21: =I21/C21-1 -> #REF! | P21: =J21/D21-1 -> #REF! | Q21: =K21/E21-1 -> #REF! | R21: =L21/F21-1 -> #REF!
A22: Total Maintenance Capital | B22: ='Capex and FCF'!#REF!/'Capex and FCF'!#REF! -> #REF! | C22: ='Capex and FCF'!#REF!/'Capex and FCF'!#REF! -> #REF! | D22: ='Capex and FCF'!#REF!/'Capex and FCF'!#REF! -> #REF! | E22: ='Capex and FCF'!#REF!/'Capex and FCF'!#REF! -> #REF! | F22: ='Capex and FCF'!#REF!/'Capex and FCF'!#REF! -> #REF! | H22: ='Capex and FCF'!B23/'Capex and FCF'!B$27 -> 0.19483395 | I22: ='Capex and FCF'!C23/'Capex and FCF'!C$27 -> 0.24242424 | J22: ='Capex and FCF'!D23/'Capex and FCF'!D$27 -> 0.31940063 | K22: ='Capex and FCF'!E23/'Capex and FCF'!E$27 -> 0.33033573 | L22: ='Capex and FCF'!F23/'Capex and FCF'!F$27 -> 0.2748422 | N22: =H22/B22-1 -> #REF! | O22: =I22/C22-1 -> #REF! | P22: =J22/D22-1 -> #REF! | Q22: =K22/E22-1 -> #REF! | R22: =L22/F22-1 -> #REF!
A24: Strategic/Discretionary Capital (as a % of Cable Capex) | B24: ='Capex and FCF'!#REF!/'Capex and FCF'!#REF! -> #REF! | C24: ='Capex and FCF'!#REF!/'Capex and FCF'!#REF! -> #REF! | D24: ='Capex and FCF'!#REF!/'Capex and FCF'!#REF! -> #REF! | E24: ='Capex and FCF'!#REF!/'Capex and FCF'!#REF! -> #REF! | F24: ='Capex and FCF'!#REF!/'Capex and FCF'!#REF! -> #REF! | H24: ='Capex and FCF'!B25/'Capex and FCF'!B$27 -> 0.029520295 | I24: ='Capex and FCF'!C25/'Capex and FCF'!C$27 -> 0.020733652 | J24: ='Capex and FCF'!D25/'Capex and FCF'!D$27 -> 0.014984227 | K24: ='Capex and FCF'!E25/'Capex and FCF'!E$27 -> 0.013189448 | L24: ='Capex and FCF'!F25/'Capex and FCF'!F$27 -> 0.019296664 | N24: =H24/B24-1 -> #REF! | O24: =I24/C24-1 -> #REF! | P24: =J24/D24-1 -> #REF! | Q24: =K24/E24-1 -> #REF! | R24: =L24/F24-1 -> #REF!
A26: Total Cable (as a % of Total Capex) | B26: ='Capex and FCF'!#REF!/'Capex and FCF'!#REF! -> #REF! | C26: ='Capex and FCF'!#REF!/'Capex and FCF'!#REF! -> #REF! | D26: ='Capex and FCF'!#REF!/'Capex and FCF'!#REF! -> #REF! | E26: ='Capex and FCF'!#REF!/'Capex and FCF'!#REF! -> #REF! | F26: ='Capex and FCF'!#REF!/'Capex and FCF'!#REF! -> #REF! | H26: ='Capex and FCF'!B27/'Capex and FCF'!B$33 -> 0.94689029 | I26: ='Capex and FCF'!C27/'Capex and FCF'!C$33 -> 0.96461538 | J26: ='Capex and FCF'!D27/'Capex and FCF'!D$33 -> 0.97090352 | K26: ='Capex and FCF'!E27/'Capex and FCF'!E$33 -> 0.9737303 | L26: ='Capex and FCF'!F27/'Capex and FCF'!F$33 -> 0.96434783 | N26: =H26/B26-1 -> #REF! | O26: =I26/C26-1 -> #REF! | P26: =J26/D26-1 -> #REF! | Q26: =K26/E26-1 -> #REF! | R26: =L26/F26-1 -> #REF!
A28: Programming (as a % of Total Capex) | B28: ='Capex and FCF'!#REF!/'Capex and FCF'!#REF! -> #REF! | C28: ='Capex and FCF'!#REF!/'Capex and FCF'!#REF! -> #REF! | D28: ='Capex and FCF'!#REF!/'Capex and FCF'!#REF! -> #REF! | E28: ='Capex and FCF'!#REF!/'Capex and FCF'!#REF! -> #REF! | F28: ='Capex and FCF'!#REF!/'Capex and FCF'!#REF! -> #REF! | H28: ='Capex and FCF'!B29/'Capex and FCF'!B$33 -> 0.0027952481 | I28: ='Capex and FCF'!C29/'Capex and FCF'!C$33 -> 0.0046153846 | J28: ='Capex and FCF'!D29/'Capex and FCF'!D$33 -> 0.0091883614 | K28: ='Capex and FCF'!E29/'Capex and FCF'!E$33 -> 0.012842966 | L28: ='Capex and FCF'!F29/'Capex and FCF'!F$33 -> 0.0076521739 | N28: =H28/B28-1 -> #REF! | O28: =I28/C28-1 -> #REF! | P28: =J28/D28-1 -> #REF! | Q28: =K28/E28-1 -> #REF! | R28: =L28/F28-1 -> #REF!
A30: Corporate and Other (as a % of Total Capex) | B30: ='Capex and FCF'!#REF!/'Capex and FCF'!#REF! -> #REF! | C30: ='Capex and FCF'!#REF!/'Capex and FCF'!#REF! -> #REF! | D30: ='Capex and FCF'!#REF!/'Capex and FCF'!#REF! -> #REF! | E30: ='Capex and FCF'!#REF!/'Capex and FCF'!#REF! -> #REF! | F30: ='Capex and FCF'!#REF!/'Capex and FCF'!#REF! -> #REF! | H30: ='Capex and FCF'!B31/'Capex and FCF'!B$33 -> 0.050314465 | I30: ='Capex and FCF'!C31/'Capex and FCF'!C$33 -> 0.030769231 | J30: ='Capex and FCF'!D31/'Capex and FCF'!D$33 -> 0.019908116 | K30: ='Capex and FCF'!E31/'Capex and FCF'!E$33 -> 0.013426737 | L30: ='Capex and FCF'!F31/'Capex and FCF'!F$33 -> 0.028 | N30: =H30/B30-1 -> #REF! | O30: =I30/C30-1 -> #REF! | P30: =J30/D30-1 -> #REF! | Q30: =K30/E30-1 -> #REF! | R30: =L30/F30-1 -> #REF!
A32: Total Consolidated Capital Expenditures (as a % of Total Capex) | B32: ='Capex and FCF'!#REF!/'Capex and FCF'!#REF! -> #REF! | C32: ='Capex and FCF'!#REF!/'Capex and FCF'!#REF! -> #REF! | D32: ='Capex and FCF'!#REF!/'Capex and FCF'!#REF! -> #REF! | E32: ='Capex and FCF'!#REF!/'Capex and FCF'!#REF! -> #REF! | F32: ='Capex and FCF'!#REF!/'Capex and FCF'!#REF! -> #REF! | H32: ='Capex and FCF'!B33/'Capex and FCF'!B$33 -> 1 | I32: ='Capex and FCF'!C33/'Capex and FCF'!C$33 -> 1 | J32: ='Capex and FCF'!D33/'Capex and FCF'!D$33 -> 1 | K32: ='Capex and FCF'!E33/'Capex and FCF'!E$33 -> 1 | L32: ='Capex and FCF'!F33/'Capex and FCF'!F$33 -> 1 | N32: =H32/B32-1 -> #REF! | O32: =I32/C32-1 -> #REF! | P32: =J32/D32-1 -> #REF! | Q32: =K32/E32-1 -> #REF! | R32: =L32/F32-1 -> #REF!
A33: Percent of Total Consolidated Revenue | B33: =+B32/'Revenue and Exp'!#REF! -> #REF! | C33: =+C32/'Revenue and Exp'!#REF! -> #REF! | D33: =+D32/'Revenue and Exp'!#REF! -> #REF! | E33: =+E32/'Revenue and Exp'!#REF! -> #REF! | F33: =+F32/'Revenue and Exp'!#REF! -> #REF! | H33: =+H32/'Revenue and Exp'!#REF! -> #REF! | I33: =+I32/'Revenue and Exp'!#REF! -> #REF! | J33: =+J32/'Revenue and Exp'!#REF! -> #REF! | K33: =+K32/'Revenue and Exp'!#REF! -> #REF! | L33: =+L32/'Revenue and Exp'!#REF! -> #REF! | N33: =H33/B33-1 -> #REF! | O33: =I33/C33-1 -> #REF! | P33: =J33/D33-1 -> #REF! | Q33: =K33/E33-1 -> #REF! | R33: =L33/F33-1 -> #REF!
A35: Free Cash Flow
A37: Net Cash Provided by Operating Activities | B37: 1965 | C37: 1942 | D37: 1598 | E37: 2684 | F37: =SUM(B37:E37) -> 8189 | H37: 2259 | I37: 2669 | J37: 2445 | K37: 2858 | L37: =SUM(H37:K37) -> 10231 | N37: =H37/B37-1 -> 0.14961832 | O37: =I37/C37-1 -> 0.37435633 | P37: =J37/D37-1 -> 0.53003755 | Q37: =K37/E37-1 -> 0.064828614 | R37: =L37/F37-1 -> 0.2493589
A38: Capital Expenditures | B38: -1454 | C38: =-3058-B38 -> -1604 | D38: =-4584+3058 -> -1526 | E38: -1574 | F38: =SUM(B38:E38) -> -6158 | H38: -1431 | I38: -1300 | J38: -1306 | K38: -1713 | L38: =SUM(H38:K38) -> -5750 | N38: =H38/B38-1 -> -0.015818432 | O38: =I38/C38-1 -> -0.18952618 | P38: =J38/D38-1 -> -0.14416776 | Q38: =K38/E38-1 -> 0.088310038 | R38: =L38/F38-1 -> -0.066255278
A39: Cash Paid for Capitalized Software | B39: -88 | C39: -86 | D39: -60 | E39: -77 | F39: =SUM(B39:E39) -> -311 | H39: -99 | I39: -88 | J39: -100 | K39: -123 | L39: =SUM(H39:K39) -> -410 | N39: =H39/B39-1 -> 0.125 | O39: =I39/C39-1 -> 0.023255814 | P39: =J39/D39-1 -> 0.66666667 | Q39: =K39/E39-1 -> 0.5974026 | R39: =L39/F39-1 -> 0.31832797
A40: Cash Paid for Other Intangible Assets | B40: -30 | C40: -25 | D40: -24 | E40: -16 | F40: =SUM(B40:E40) -> -95 | H40: -27 | I40: -31 | J40: -31 | K40: -28 | L40: =SUM(H40:K40) -> -117 | N40: =H40/B40-1 -> -0.1 | O40: =I40/C40-1 -> 0.24 | P40: =J40/D40-1 -> 0.29166667 | Q40: =K40/E40-1 -> 0.75 | R40: =L40/F40-1 -> 0.23157895
A42: Adjustments for Nonoperating and Nonrecurring items, net of tax:
A43: Payment of Tax on Nonoperating Items | B43: 49 | C43: 141 | D43: 536 | E43: =141-132-18 -> -9 | F43: =SUM(B43:E43) -> 717 | H43: 0 | I43: 228 | J43: 88 | K43: -13 | L43: =SUM(H43:K43) -> 303 | N43: =H43/B43-1 -> -1 | O43: =I43/C43-1 -> 0.61702128 | P43: =J43/D43-1 -> -0.8358209 | Q43: =K43/E43-1 -> 0.44444444 | R43: =L43/F43-1 -> -0.57740586
A44: Economic Stimulus Package * | B44: 0 | C44: 0 | D44: 0 | E44: 0 | F44: =SUM(B44:E44) -> 0 | H44: 0 | I44: -315 | J44: -168 | K44: -117 | L44: =SUM(H44:K44) -> -600 | N44: - | O44: - | P44: - | Q44: - | R44: -
A46: Free Cash Flow | B46: =SUM(B37:B44) -> 442 | C46: =SUM(C37:C44) -> 368 | D46: =SUM(D37:D44) -> 524 | E46: =SUM(E37:E44) -> 1008 | F46: =SUM(F37:F44) -> 2342 | H46: =SUM(H37:H44) -> 702 | I46: =SUM(I37:I44) -> 1163 | J46: =SUM(J37:J44) -> 928 | K46: =SUM(K37:K44) -> 864 | L46: =SUM(L37:L44) -> 3657 | N46: =H46/B46-1 -> 0.58823529 | O46: =I46/C46-1 -> 2.1603261 | P46: =J46/D46-1 -> 0.77099237 | Q46: =K46/E46-1 -> -0.14285714 | R46: =L46/F46-1 -> 0.56148591
A48: FCF per Share | B48: =B46/B56 -> 0.13982917 | C48: =C46/C56 -> 0.11693677 | D48: =D46/D56 -> 0.16805645 | E48: =E46/E56 -> 0.32748538 | F48: =F46/F56 -> 0.74848194 | H48: =H46/H56 -> 0.23268147 | I48: =I46/I56 -> 0.39158249 | J48: =J46/J56 -> 0.31780822 | K48: =K46/K56 -> 0.29916898 | L48: =L46/L56 -> 1.2388211 | N48: =H48/B48-1 -> 0.66404102 | O48: =I48/C48-1 -> 2.3486688 | P48: =J48/D48-1 -> 0.8910802 | Q48: =K48/E48-1 -> -0.086466165 | R48: =L48/F48-1 -> 0.65511159
A50: Cash Paid Interest | B50: 662 | C50: 416 | D50: 646 | E50: 410 | H50: 708 | I50: 408 | J50: 679 | K50: 461 | L50: 2256
A52: Unlevered Free Cash Flow | B52: =SUM(B50,B46) -> 1104 | C52: =SUM(C50,C46) -> 784 | D52: =SUM(D50,D46) -> 1170 | E52: =SUM(E50,E46) -> 1418 | H52: =SUM(H50,H46) -> 1410 | I52: =SUM(I50,I46) -> 1571 | J52: =SUM(J50,J46) -> 1607 | K52: =SUM(K50,K46) -> 1325 | L52: =SUM(L50,L46) -> 5913
A54: Unlevered FCF per Share | B54: =B52/B56 -> 0.34925656 | C54: =C52/C56 -> 0.24912615 | D54: =D52/D56 -> 0.37524054 | E54: =E52/E56 -> 0.46068876 | H54: =H52/H56 -> 0.46735167 | I54: =I52/I56 -> 0.52895623 | J54: =J52/J56 -> 0.55034247 | K54: =K52/K56 -> 0.45879501 | L54: =L52/L56 -> 2.0030488
A56: Diluted weighted-average number of common shares | B56: 3161 | C56: 3147 | D56: 3118 | E56: 3078 | F56: 3129 | H56: 3017 | I56: 2970 | J56: 2920 | K56: 2888 | L56: 2952 | N56: =H56/B56-1 -> -0.045555204 | O56: =I56/C56-1 -> -0.056244042 | P56: =J56/D56-1 -> -0.063502245 | Q56: =K56/E56-1 -> -0.061728395 | R56: =L56/F56-1 -> -0.056567593
A58: * Our definition of Free Cash Flow remains unchanged and specifically eliminates any impact from the Economic Stimulus package. These amounts have been excluded from Free Cash Flow to provide an appropriate comparison.
A60: Note: Pro Forma adjustments for 2007 include the cable system acquired from Patriot Media, the SportsNet Bay Area/Sports Channel New England acquisitions and the cable systems acquired
...
