Workbook

Sheet Expense Report as of 1_1_13
E1: STATE OF MARYLAND EXPENSE ACCOUNT
E2: ='CHANGE RATE IN CELL'!A15 -> Use for reimbursement effective January 1, 2013
E3: ='CHANGE RATE IN CELL'!A16 -> 56.5 ¢ per mile
A5: Department | B5: Coppin State University
A6: Unit or Division
A7: Agency Code | B7: R27 | D7: Employee Social Security No.
A8: Employee Name
A9: and Address
A10: Assigned Office Location (City) | C10: Baltimore, MD | E10: One Way Commute Miles
A11: For Period Beginning | E11: And Ending
A13: Date
A14: Day | B14: SUNDAY | C14: MONDAY | D14: TUESDAY | E14: WEDNESDAY | F14: THURSDAY | G14: FRIDAY | H14: SATURDAY | I14: TOTALS
A15: Hotel | I15: =SUM(B15:H15) -> 0
A16: Breakfast | I16: =SUM(B16:H16) -> 0
A17: Lunch | I17: =SUM(B17:H17) -> 0
A18: Dinner | I18: =SUM(B18:H18) -> 0
A19: Telephone | I19: =SUM(B19:H19) -> 0
A20: Fare (Indicate below) | I20: =SUM(B20:H20) -> 0
A21: Taxi | I21: =SUM(B21:H21) -> 0
A22: Bridge or Road Tolls | I22: =SUM(B22:H22) -> 0
A23: Mileage * (See Below) | B23: =ROUND(IF(J40>0,J40*'CHANGE RATE IN CELL'!$C$10,"0.00"),2) -> 0 | C23: =ROUND(IF(J41>0,J41*'CHANGE RATE IN CELL'!$C$10,"0.00"),2) -> 0 | D23: =ROUND(IF(J42>0,J42*'CHANGE RATE IN CELL'!$C$10,"0.00"),2) -> 0 | E23: =ROUND(IF(J43>0,J43*'CHANGE RATE IN CELL'!$C$10,"0.00"),2) -> 0 | F23: =ROUND(IF(J44>0,J44*'CHANGE RATE IN CELL'!$C$10,"0.00"),2) -> 0 | G23: =ROUND(IF(J45>0,J45*'CHANGE RATE IN CELL'!$C$10,"0.00"),2) -> 0 | H23: =ROUND(IF(J46>0,J46*'CHANGE RATE IN CELL'!$C$10,"0.00"),2) -> 0 | I23: =SUM(B23:H23) -> 0
A24: Parking | I24: =SUM(B24:H24) -> 0
A25: Registration Fee | I25: =SUM(B25:H25) -> 0
I26: =SUM(B26:H26) -> 0
I27: =SUM(B27:H27) -> 0
I28: =SUM(B28:H28) -> 0
I29: =SUM(B29:H29) -> 0
I30: =SUM(B30:H30) -> 0
A31: Totals | B31: =SUM(B15:B30) -> 0 | C31: =SUM(C15:C30) -> 0 | D31: =SUM(D15:D30) -> 0 | E31: =SUM(E15:E30) -> 0 | F31: =SUM(F15:F30) -> 0 | G31: =SUM(G15:G30) -> 0 | H31: =SUM(H15:H30) -> 0 | I31: =SUM(I15:I30) -> 0
A32: Method of Travel
G33: (Specify)
A34: Purpose of Travel:
A38: Date | B38: Time | H38: Total | I38: Total | J38: Reimb.
A39: Day | B39: Start | C39: End | D39: TERRITORY COVERED INCURRING ABOVE EXPENSES | H39: Miles | I39: Commute Miles | J39: Miles*
A40: Sunday | J40: =IF(H40>0,ROUND(H40,1)-ROUND(I40,1),"0.0") -> 0.0
A41: Monday | J41: =IF(H41>0,ROUND(H41,1)-ROUND(I41,1),"0.0") -> 0.0
A42: Tuesday | J42: =IF(H42>0,ROUND(H42,1)-ROUND(I42,1),"0.0") -> 0.0
A43: Wednesday | J43: =IF(H43>0,ROUND(H43,1)-ROUND(I43,1),"0.0") -> 0.0
A44: Thursday | J44: =IF(H44>0,ROUND(H44,1)-ROUND(I44,1),"0.0") -> 0.0
A45: Friday | J45: =IF(H45>0,ROUND(H45,1)-ROUND(I45,1),"0.0") -> 0.0
...

Sheet CHANGE RATE IN CELL
A1: PREVIOUS RATE: | C1: 0.48 | E1: During Period: | F1: 38616 | G1: to | H1: 38717
C2: 0.445 | E2: During Period: | F2: 38718 | H2: 39082
C3: 0.485 | E3: During Period: | F3: 39083 | H3: 39447
C4: 0.505 | E4: During Period: | F4: 39448 | G4: to | H4: 39600
C5: 0.585 | E5: During Period: | F5: 39630 | G5: to | H5: 39813
C6: 0.55 | E6: During Period: | F6: 39814 | G6: to | H6: 40178
C7: 0.5 | E7: During Period: | F7: 40179 | G7: to | H7: 40543
C8: 0.51 | E8: During Period: | F8: 40544 | G8: to | H8: 40724
C9: 0.555 | E9: During Period: | F9: 40725 | G9: to | H9: XXX
A10: NEW RATE: | B10: CURRENT: | C10: 0.565 | E10: During Period: | F10: 41275 | G10: to | H10: XXX
A15: Use for reimbursement effective January 1, 2013
A16: 56.5 ¢ per mile
