Workbook
Name Language: Language!$B$4:$B$5
Name LicenseeField1: 'Licensee details section'!$B$4
Name LicenseeField2: 'Licensee details section'!$B$5
Name Prov: 'Province & tax rates'!$A$3:$A$16
Name termsconditions: 'Tariff 9'!$A$98:$BB$119

Sheet Tariff 9
A1: =IF(A2=1,"Select Language","Selectionnez la langue") -> Select Language | J1: ='Tariff Info'!C5 -> MUSIC LICENCE FORM - TARIFF 9 - SPORTS EVENTS
A2: 1 | J2: ='Tariff Info'!C6 -> Baseball, football, hockey, skating competitions, races, track meets and other sports events
B4: • | C4: ='Tariff Info'!C7 -> Grants you permission to play (publicly perform) live or recorded musical works at sports events
B5: • | C5: ='Tariff Info'!C8 -> Does not cover music performances at opening/closing events for which an additional admission is charged (see Tariff 4)
B6: • | C6: ='Tariff Info'!C9 -> Fee is 0.1% of the gross receipts from ticket sales (a complimentary ticket is valued at half the lowest price paid for a sold ticket from the same category in the same event) net of sales and amusement taxes (minimum fee for admission to free events is $5) + taxes
B7: • | C7: ='Tariff Info'!C10 -> Deadline for SOCAN to receive forms and payments is no later than 30 days after the end of each quarter.
B8: • | C8: ='Tariff Info'!C11 -> For more information, read the Tariff 9 Infocard
D11: =IF(Language!D2="English","Tired of printing? Would you rather submit your Music Licence online? Now you can with eSOCAN!","Vous en avez assez d’imprimer? Vous aimeriez soumettre votre formulaire de licence en ligne? Vous le pouvez avec eSOCAN!") -> Tired of printing? Would you rather submit your Music Licence online? Now you can with eSOCAN!
A13: =IF(Language!D2="English","Licensee","Licencié") -> Licensee | C13: =LicenseeField1 -> Account number | AC13: =LicenseeField2 -> (or if you are a new licensee, check here) | AR13: ='Licensee details section'!B21 -> Website
C15: ='Licensee details section'!B6 -> Business name | AA15: ='Licensee details section'!B7 -> Legal name of organization or owner
C16: ='Licensee details section'!B8 -> Contact name
V17: ='Licensee details section'!B9 -> Title | AF17: ='Licensee details section'!B10 -> Phone number | AR17: ='Licensee details section'!B11 -> Fax number
C19: ='Licensee details section'!B12 -> Email | P19: ='Licensee details section'!B13 -> Street address | AG19: ='Licensee details section'!B14 -> City | AN19: ='Licensee details section'!B15 -> Province | AS19: ='Licensee details section'!B16 -> Postal code
E20: @
C21: ='Licensee details section'!B17 -> Mailing address | H21: FALSE | I21: ='Licensee details section'!B18 -> (check here if same as above) | AJ21: ='Licensee details section'!B19 -> Tax exemption number (if applicable)
H22: =IF(H21=TRUE,1,"")
A24: =IF(Language!D2="English","Licence fee","Redevance") -> Licence fee | C24: =IF(Language!D2="English","Licence fee = [gross receipt] × 0.1% or $5 for a free event","Droits de licence = [recettes brutes] × 0,1 % ou 5 $ si l'événement est gratuit") -> Licence fee = [gross receipt] × 0.1% or $5 for a free event
C25: =IF(Language!D2="English","Total licence fee","Total des droits de licence") -> Total licence fee | M25: =IF(Language!D2="English","GST/HST","TPS/TVH") -> GST/HST | Q25: =IF(Language!D2="English","QST","TVQ") -> QST | U25: =IF(Language!D2="English","Total due","Total à payer") -> Total due | BC25: =IF(F2="English","ML-2013-01 (GST/HST N⁰ R101077931 QST N⁰ 1010390466)","ML-2013-04 (TPS/TVH N⁰ R101077931 TVQ N⁰ 1010390466)") -> ML-2013-04 (TPS/TVH N⁰ R101077931 TVQ N⁰ 1010390466)
C26: =IF(Language!D2="English","(see page 2 for calculation)","(voir le calcul à la page 2)") -> (see page 2 for calculation)
C27: =AN83 -> 0 | M27: =IF(ISERROR(C27*VLOOKUP(AQ19,'Province & tax rates'!A:C,2,FALSE)),0,(C27*VLOOKUP(AQ19,'Province & tax rates'!A:C,2,FALSE))) -> 0 | Q27: =IF(ISERROR(C27*VLOOKUP(AQ19,'Province & tax rates'!A:C,3,FALSE)),0,(C27*VLOOKUP(AQ19,'Province & tax rates'!A:C,3,FALSE))) -> 0 | U27: =SUM(C27:T27) -> 0
D29: FALSE | E29: =IF(Language!D2="English","I have read and understand the Terms&Conditions (see attached/reverse), all the information provided is correct and complete, and I have authority to bind the licensee.","J’ai pris connaissance des conditions générales (voir ci-joint/au verso), et je certifie que tous les renseignements fournis sont exacts et complets et que j’ai l’autorité requise pour lier le titulaire de licence.") -> I have read and understand the Terms&Conditions (see attached/reverse), all the information provided is correct and complete, and I have authority to bind the licensee.
C30: =IF(ISBLANK(K13),1,0) -> 1 | D30: =IF(ISBLANK(I15),1,0) -> 1 | E30: =IF(ISBLANK(AN15),1,0) -> 1 | F30: =IF(ISBLANK(L17),1,0) -> 1 | G30: =IF(ISBLANK(X17),1,0) -> 1 | H30: =IF(ISBLANK(AL17),1,0) -> 1 | I30: =IF(ISBLANK(AV17),1,0) -> 1 | J30: =IF(ISBLANK(F19),1,0) -> 1 | K30: =IF(ISBLANK(U19),1,0) -> 1 | L30: =IF(ISBLANK(AI19),1,0) -> 1 | M30: =IF(ISBLANK(AQ19),1,0) -> 1 | N30: =IF(ISBLANK(AW19),1,0) -> 1 | O30: =IF(AND(ISBLANK(T21),H22=""),1,0) -> 1 | P30: =IF((D29),0,1) -> 1 | Q30: =SUM(C30:P30) -> 14
C32: Signature | P32: Date | X32: =IF(Language!D2="English","Name","Nom") -> Name | AQ32: ='Licensee details section'!B9 -> Title
C33: =IF(Q30>0,IF(Language!D2="English","Please complete the information in the required-entry field of licensees before signing","Veuillez remplir les informations dans les champs requis avant de signer"),"1") -> Please complete the information in the required-entry field of licensees before signing
C34: ='Licensee details section'!B20 -> Please return this form by email or mail, and send your payment by cheque made payable to SOCAN or contact SOCAN to pay by credit card. Or visit eSOCAN to submit online.
C35: =IF(Language!D2="English","If you have any additional uses(s) of music, contact us or try our Licence Finder tool at www.socan.ca","") -> If you have any additional uses(s) of music, contact us or try our Licence Finder tool at www.socan.ca
A36: =IF(Language!D2="English","SOCAN Licensing, 41 Valleybrook Drive, Toronto ON, M3B 2S6 | Current accounts t 1.866.944.6223 | f 416.442.3829 licence@socan.ca","Licenses SOCAN, 41 Valleybrook Drive, Toronto ON, M3B 2S6 | Licenciés actuels t 1.866.944.6224 | téléc. 416.442.3829 licence@socan.ca") -> SOCAN Licensing, 41 Valleybrook Drive, Toronto ON, M3B 2S6 | Current accounts t 1.866.944.6223 | f 416.442.3829 licence@socan.ca
A37: =IF(Language!D2="English","First time licensees: t 1.866.944.6210 | f 514.844.4560","Nouveaux comptes: t 1.866.944.6211 | téléc. 514.844.4560") -> First time licensees: t 1.866.944.6210 | f 514.844.4560
A38: =J1 -> MUSIC LICENCE FORM - TARIFF 9 - SPORTS EVENTS
C41: ='page2 translations'!B6 -> Event date | K41: ='page2 translations'!B8 -> Event name | AB41: ='page2 translations'!B9 -> Gross receipts (A) | AN41: ='page2 translations'!B11 -> Total licence fee
C42: ='page2 translations'!B7 -> (DD/MM/YYYY) | AB42: ='page2 translations'!B10 -> = $0 if the event is free | AN42: ='page2 translations'!B12 -> = (A) x 0.1% (or $5 if free event)
B43: 1 | AN43: =IF(AB43="",0,IF(AB43=0,5,AB43*0.1%)) -> 0 | AX43: =IF(AND(BG43<3,BG43<>0),IF('page2 translations'!B1="English","Please complete entries in the required entry fields","Veuillez entrer les informations complétes dans les champs requis"),"") | BD43: =IF(ISBLANK(C43),1,0) -> 1 | BE43: =IF(ISBLANK(K43),1,0) -> 1 | BF43: =IF(ISBLANK(AB43),1,0) -> 1 | BG43: =SUM(BD43:BF43) -> 3
B44: 2 | AN44: =IF(AB44="",0,IF(AB44=0,5,AB44*0.1%)) -> 0 | AX44: =IF(AND(BG44<3,BG44<>0),IF('page2 translations'!B2="English","Please complete entries in the required entry fields","Veuillez entrer les informations complétes dans les champs requis"),"") | BD44: =IF(ISBLANK(C44),1,0) -> 1 | BE44: =IF(ISBLANK(K44),1,0) -> 1 | BF44: =IF(ISBLANK(AB44),1,0) -> 1 | BG44: =SUM(BD44:BF44) -> 3
B45: 3 | AN45: =IF(AB45="",0,IF(AB45=0,5,AB45*0.1%)) -> 0 | AX45: =IF(AND(BG45<3,BG45<>0),IF('page2 translations'!B3="English","Please complete entries in the required entry fields","Veuillez entrer les informations complétes dans les champs requis"),"") | BD45: =IF(ISBLANK(C45),1,0) -> 1 | BE45: =IF(ISBLANK(K45),1,0) -> 1 | BF45: =IF(ISBLANK(AB45),1,0) -> 1 | BG45: =SUM(BD45:BF45) -> 3
B46: 4 | AN46: =IF(AB46="",0,IF(AB46=0,5,AB46*0.1%)) -> 0 | AX46: =IF(AND(BG46<3,BG46<>0),IF('page2 translations'!B4="English","Please complete entries in the required entry fields","Veuillez entrer les informations complétes dans les champs requis"),"") | BD46: =IF(ISBLANK(C46),1,0) -> 1 | BE46: =IF(ISBLANK(K46),1,0) -> 1 | BF46: =IF(ISBLANK(AB46),1,0) -> 1 | BG46: =SUM(BD46:BF46) -> 3
B47: 5 | AN47: =IF(AB47="",0,IF(AB47=0,5,AB47*0.1%)) -> 0 | AX47: =IF(AND(BG47<3,BG47<>0),IF('page2 translations'!B5="English","Please complete entries in the required entry fields","Veuillez entrer les informations complétes dans les champs requis"),"") | BD47: =IF(ISBLANK(C47),1,0) -> 1 | BE47: =IF(ISBLANK(K47),1,0) -> 1 | BF47: =IF(ISBLANK(AB47),1,0) -> 1 | BG47: =SUM(BD47:BF47) -> 3
B48: 6 | AN48: =IF(AB48="",0,IF(AB48=0,5,AB48*0.1%)) -> 0 | AX48: =IF(AND(BG48<3,BG48<>0),IF('page2 translations'!B6="English","Please complete entries in the required entry fields","Veuillez entrer les informations complétes dans les champs requis"),"") | BD48: =IF(ISBLANK(C48),1,0) -> 1 | BE48: =IF(ISBLANK(K48),1,0) -> 1 | BF48: =IF(ISBLANK(AB48),1,0) -> 1 | BG48: =SUM(BD48:BF48) -> 3
B49: 7 | AN49: =IF(AB49="",0,IF(AB49=0,5,AB49*0.1%)) -> 0 | AX49: =IF(AND(BG49<3,BG49<>0),IF('page2 translations'!B7="English","Please complete entries in the required entry fields","Veuillez entrer les informations complétes dans les champs requis"),"") | BD49: =IF(ISBLANK(C49),1,0) -> 1 | BE49: =IF(ISBLANK(K49),1,0) -> 1 | BF49: =IF(ISBLANK(AB49),1,0) -> 1 | BG49: =SUM(BD49:BF49) -> 3
B50: 8 | AN50: =IF(AB50="",0,IF(AB50=0,5,AB50*0.1%)) -> 0 | AX50: =IF(AND(BG50<3,BG50<>0),IF('page2 translations'!B8="English","Please complete entries in the required entry fields","Veuillez entrer les informations complétes dans les champs requis"),"") | BD50: =IF(ISBLANK(C50),1,0) -> 1 | BE50: =IF(ISBLANK(K50),1,0) -> 1 | BF50: =IF(ISBLANK(AB50),1,0) -> 1 | BG50: =SUM(BD50:BF50) -> 3
B51: 9 | AN51: =IF(AB51="",0,IF(AB51=0,5,AB51*0.1%)) -> 0 | AX51: =IF(AND(BG51<3,BG51<>0),IF('page2 translations'!B9="English","Please complete entries in the required entry fields","Veuillez entrer les informations complétes dans les champs requis"),"") | BD51: =IF(ISBLANK(C51),1,0) -> 1 | BE51: =IF(ISBLANK(K51),1,0) -> 1 | BF51: =IF(ISBLANK(AB51),1,0) -> 1 | BG51: =SUM(BD51:BF51) -> 3
...

Sheet Language
A1: 1 | B1: English | C1: Selected Language
A2: 2 | B2: French | C2: ='Tariff 9'!A2 -> 1 | D2: =VLOOKUP(C2,A:B,2,FALSE) -> English
B4: =IF(C2=1,"English","Anglais") -> English
B5: =IF(C2=1,"French","Français") -> French

Sheet Tariff Info
A1: Selected Language | C1: =Language!D2 -> English
B3: Ref row
C4: Description Selected | D4: English | E4: French
A5: Desc1 | B5: 2 | C5: =IF($C$1="English",D5,E5) -> MUSIC LICENCE FORM - TARIFF 9 - SPORTS EVENTS | D5: MUSIC LICENCE FORM - TARIFF 9 - SPORTS EVENTS | E5: FORMULAIRE DE LICENCE DE MUSIQUE - TARIF 9 - ÉVÉNEMENTS SPORTIFS
A6: Desc2 | B6: 3 | C6: =IF($C$1="English",D6,E6) -> Baseball, football, hockey, skating competitions, races, track meets and other sports events | D6: Baseball, football, hockey, skating competitions, races, track meets and other sports events | E6: Baseball, football, hockey, compétitions de patinage, courses, rencontres d'athlétisme et autres événements sportifs
A7: Desc1 | B7: 4 | C7: =IF($C$1="English",D7,E7) -> Grants you permission to play (publicly perform) live or recorded musical works at sports events | D7: Grants you permission to play (publicly perform) live or recorded musical works at sports events | E7: Cette licence vous autorise à jouer (exécuter publiquement) des œuvres musicales enregistrées ou en direct lors d'événements sportifs
A8: Desc2 | B8: 5 | C8: =IF($C$1="English",D8,E8) -> Does not cover music performances at opening/closing events for which an additional admission is charged (see Tariff 4) | D8: Does not cover music performances at opening/closing events for which an additional admission is charged (see Tariff 4) | E8: Elle ne couvre pas les exécutions musicales lors d'événements d'ouverture ou de clôture pour lesquels un prix d'entrée distinct est exigé (voir le tarif 4)
A9: Desc3 | B9: 6 | C9: =IF($C$1="English",D9,E9) -> Fee is 0.1% of the gross receipts from ticket sales (a complimentary ticket is valued at half the lowest price paid for a sold ticket from the same category in the same event) net of sales and amusement taxes (minimum fee for admission to free events is $5) + taxes | D9: Fee is 0.1% of the gross receipts from ticket sales (a complimentary ticket is valued at half the lowest price paid for a sold ticket from the same category in the same event) net of sales and amusement taxes (minimum fee for admission to free events is $5) + taxes | E9: Les droits par événement sont de 0,1 % des recettes brutes des ventes de billets (un billet gratuit est considéré comme valant la moitié du prix du billet le moins cher de la même catégorie pour le même événement) excluant les taxes de vente et d'amusement (les droits minimums pour les événements gratuits sont de 5 $) + taxes
A10: Desc4 | B10: 7 | C10: =IF($C$1="English",D10,E10) -> Deadline for SOCAN to receive forms and payments is no later than 30 days after the end of each quarter. | D10: Deadline for SOCAN to receive forms and payments is no later than 30 days after the end of each quarter. | E10: La SOCAN doit recevoir le formulaire et le paiement au plus tard 30 jours après la fin de chaque trimestre.
A11: Desc5 | B11: 8 | C11: =IF($C$1="English",D11,E11) -> For more information, read the Tariff 9 Infocard | D11: For more information, read the Tariff 9 Infocard | E11: Pour de plus amples informations, lisez l'Info carte du tarif 9

Sheet Licensee details section
A1: Language Selected | B1: =Language!D2 -> English
B3: Selected Desc | C3: English | D3: French
A4: Field1 | B4: =IF($B$1="English",C4,D4) -> Account number | C4: Account number | D4: Numéro de compte
A5: Field2 | B5: =IF($B$1="English",C5,D5) -> (or if you are a new licensee, check here) | C5: (or if you are a new licensee, check here) | D5: (ou si vous n’êtes pas encore licencié, cliquez ici)
A6: Field3 | B6: =IF($B$1="English",C6,D6) -> Business name | C6: Business name | D6: Nom de l’entreprise
A7: Field4 | B7: =IF($B$1="English",C7,D7) -> Legal name of organization or owner | C7: Legal name of organization or owner | D7: Nom légal de l’organisation ou nom du propriétaire
A8: Field5 | B8: =IF($B$1="English",C8,D8) -> Contact name | C8: Contact name | D8: Personne contact
A9: Field6 | B9: =IF($B$1="English",C9,D9) -> Title | C9: Title | D9: Titre
A10: Field7 | B10: =IF($B$1="English",C10,D10) -> Phone number | C10: Phone number | D10: Numéro de tél.
A11: Field8 | B11: =IF($B$1="English",C11,D11) -> Fax number | C11: Fax number | D11: Numéro de téléc.
A12: Field9 | B12: =IF($B$1="English",C12,D12) -> Email | C12: Email | D12: Courriel
A13: Field10 | B13: =IF($B$1="English",C13,D13) -> Street address | C13: Street address | D13: Adresse civique
A14: Field11 | B14: =IF($B$1="English",C14,D14) -> City | C14: City | D14: Ville
A15: Field12 | B15: =IF($B$1="English",C15,D15) -> Province | C15: Province | D15: Province
... A21: Field18 | B21: =IF($B$1="English",C21,D21) -> Website | C21: Website | D21: Site web

Sheet Province & tax rates
B1: Existing Rates | D1: new rates
A2: Province | B2: =IF(Language!D2="English","GST/HST","TPS/TVH") -> GST/HST | C2: =IF(Language!D2="English","QST","TVQ") -> QST | D2: =IF(Language!H1="English","GST/HST","TPS/TVH") -> TPS/TVH | E2: =IF(Language!H1="English","QST","TVQ") -> TVQ
A3: nil | B3: 0 | D3: 0
A4: AB | B4: 0.05 | D4: 0.05
A5: BC | B5: 0.05 | D5: 0.05
A6: MB | B6: 0.05 | D6: 0.05
A7: NB | B7: 0.13 | D7: 0.13
A8: NL | B8: 0.13 | D8: 0.13
A9: NS | B9: 0.15 | D9: 0.15
A10: NT | B10: 0.05 | D10: 0.05
A11: NU | B11: 0.05 | D11: 0.05
A12: ON | B12: 0.13 | D12: 0.13
A13: PE | B13: 0.14 | D13: 0.14
A14: QC | B14: 0.05 | C14: 0.09975 | D14: 0.05
A15: SK | B15: 0.05 | D15: 0.05
A16: YT | B16: 0.05 | D16: 0.05

Sheet PostalCode validation
B2: Value on form | C2: =TRIM('Tariff 9'!AW19) | D2: Correct value | E2: Condition met | F2: =SUM(F3:F9) -> 0
B3: Check # of characters | C3: =IF(C11=" ",LEN('Tariff 9'!AW19)-1,LEN('Tariff 9'!AW19)) -> 0 | D3: 6 | E3: =IF(C3=0,"True",EXACT(C3,D3)) -> True | F3: =IF(E3=FALSE,1,0) -> 0
B4: Check 1st char is letter | C4: =LEFT('Tariff 9'!AW19,1) | E4: =IF($C$3=0,"True",IF(ISERROR(IF(ISTEXT(C4),"True","False")),"False",IF(ISTEXT(C4),"True","False"))) -> True | F4: =IF(E4="false",1,0) -> 0
B5: Check 2nd char is number | C5: =MID('Tariff 9'!AW19,2,1) | D5: =HLOOKUP(C5,H5:Q5,1,FALSE) -> #N/A | E5: =IF(C3=0,"True",IF(ISERROR(EXACT(C5,D5)),"False",EXACT(C5,D5))) -> True | F5: =IF(E5="false",1,0) -> 0 | H5: 1 | I5: 2 | J5: 3 | K5: 4 | L5: 5 | M5: 6 | N5: 7 | O5: 8 | P5: 9 | Q5: 0
B6: Check 3rd char is letter | C6: =MID('Tariff 9'!AW19,3,1) | E6: =IF($C$3=0,"True",IF(ISERROR(IF(ISTEXT(C6),"True","False")),"False",IF(ISTEXT(C6),"True","False"))) -> True | F6: =IF(E6="false",1,0) -> 0
B7: Check 4th char is number | C7: =IF(C11=" ",MID('Tariff 9'!AW19,5,1),MID('Tariff 9'!AW19,4,1)) | D7: =HLOOKUP(C7,H7:Q7,1,FALSE) -> #N/A | E7: =IF(C3=0,"True",IF(ISERROR(EXACT(C7,D7)),"False",EXACT(C7,D7))) -> True | F7: =IF(E7="false",1,0) -> 0 | H7: 1 | I7: 2 | J7: 3 | K7: 4 | L7: 5 | M7: 6 | N7: 7 | O7: 8 | P7: 9 | Q7: 0
B8: Check 5th char is letter | C8: =IF(C11=" ",MID('Tariff 9'!AW19,6,1),MID('Tariff 9'!AW19,5,1)) | E8: =IF($C$3=0,"True",IF(ISERROR(IF(ISTEXT(C8),"True","False")),"False",IF(ISTEXT(C8),"True","False"))) -> True | F8: =IF(E8="false",1,0) -> 0
B9: Check 6th char is number | C9: =IF(C11=" ",MID('Tariff 9'!AW19,7,1),MID('Tariff 9'!AW19,6,1)) | D9: =HLOOKUP(C9,H9:Q9,1,FALSE) -> #N/A | E9: =IF(C3=0,"True",IF(ISERROR(EXACT(C9,D9)),"False",EXACT(C9,D9))) -> True | F9: =IF(E9="false",1,0) -> 0 | H9: 1 | I9: 2 | J9: 3 | K9: 4 | L9: 5 | M9: 6 | N9: 7 | O9: 8 | P9: 9 | Q9: 0
B11: Is there as space at 4th char | C11: =MID(C2,4,1)

Sheet page2 translations
A1: Language Selected | B1: =Language!D2 -> English
A3: Fee%
A4: Min
B5: Selected Desc | C5: English | D5: French
A6: Field1 | B6: =IF($B$1="English",C6,D6) -> Event date | C6: Event date | D6: Date de l'événement
A7: Field2 | B7: =IF($B$1="English",C7,D7) -> (DD/MM/YYYY) | C7: (DD/MM/YYYY) | D7: (JJ/MM/AAAA)
A8: Field3 | B8: =IF($B$1="English",C8,D8) -> Event name | C8: Event name | D8: Nom de l'événement
A9: Field4 | B9: =IF($B$1="English",C9,D9) -> Gross receipts (A) | C9: Gross receipts (A) | D9: Recettes brutes (A)
A10: Field5 | B10: =IF($B$1="English",C10,D10) -> = $0 if the event is free | C10: = $0 if the event is free | D10: = 0 $ si gratuit
A11: Field6 | B11: =IF($B$1="English",C11,D11) -> Total licence fee | C11: Total licence fee | D11: Total des droits de licence
A12: Field7 | B12: =IF($B$1="English",C12,D12) -> = (A) x 0.1% (or $5 if free event) | C12: = (A) x 0.1% (or $5 if free event) | D12: '= (A) x 0,1 % (ou 5 $ si gratuit)
A13: Field8 | B13: =IF($B$1="English",C13,D13) -> TOTAL DUE | C13: TOTAL DUE | D13: TOTAL À PAYER

Sheet page4 translations
A1: Language Selected | B1: =Language!D2 -> English
B5: Selected Desc | C5: English | D5: French
A6: Field1 | B6: =IF($B$1="English",C6,D6) -> Important Information | C6: Important Information | D6: Renseignement important
A7: Field2 | B7: =IF($B$1="English",C7,D7) -> SOCAN is a not-for-profit, member-based organization that represents the Canadian performing rights of more than three-million Canadian and international music creators and publishers. SOCAN is proud to play a leading role in supporting the long-term success of its more than 110,000 Canadian members, and the Canadian music industry overall. SOCAN licenses more than 125,000 businesses in Canada, and distributes royalties to its members and music rights organizations around the world. SOCAN also distributes royalties to its members for the use of their music internationally in collaboration with its peer societies. | C7: SOCAN is a not-for-profit, member-based organization that represents the Canadian performing rights of more than three-million Canadian and international music creators and publishers. SOCAN is proud to play a leading role in supporting the long-term success of its more than 110,000 Canadian members, and the Canadian music industry overall. SOCAN licenses more than 125,000 businesses in Canada, and distributes royalties to its members and music rights organizations around the world. SOCAN also distributes royalties to its members for the use of their music internationally in collaboration with its peer societies. | D7: La SOCAN est une organisation sans but lucratif qui représente les droits d’exécution musicale canadiens de plus de trois millions de créateurs et d’éditeurs de musique au pays et à travers le monde. La SOCAN est fière de jouer un rôle d’avant-garde pour assurer le bien-être à long terme de ses plus de 110 000 membres canadiens et de l’industrie musicale canadienne dans son ensemble. La SOCAN perçoit des droits de licences de plus de 125 000 entreprises au pays et distribue ces redevances à ses membres et affiliées internationales. La SOCAN distribue également à ses membres les redevances qu’elle reçoit des organisations affiliées internationales pour l’utilisation de leur musique à travers le monde.
A8: Field3 | B8: =IF($B$1="English",C8,D8) -> Terms & Conditions | C8: Terms & Conditions | D8: Conditions générales
A9: Field4 | B9: =IF($B$1="English",C9,D9) -> The legal terms that govern your licence include those set out herein as well as those found in the approved tariff including the General Provisions, as approved by the Copyright Board of Canada for each year (collectively, the “tariff”). If you have any questions regarding the terms, please contact us. | C9: The legal terms that govern your licence include those set out herein as well as those found in the approved tariff including the General Provisions, as approved by the Copyright Board of Canada for each year (collectively, the “tariff”). If you have any questions regarding the terms, please contact us. | D9: Les dispositions qui régissent votre licence incluent celles décrites ci-dessous et celles apparaissant dans le tarif approuvé, dont les dispositions générales, tel qu’homologué par la Commission du droit d’auteur du Canada chaque année (collectivement le « tarif »). Pour toute question au sujet de ces conditions, veuillez nous contacter.
A10: Field5 | B10: =IF($B$1="English",C10,D10) -> In this form, you, your and licensee means the person or company applying for a licence or filing an annual report. We, our, us and SOCAN means the Society of Composers, Authors and Music Publishers of Canada. Works means any or all of the musical works in SOCAN’s repertoire. | C10: In this form, you, your and licensee means the person or company applying for a licence or filing an annual report. We, our, us and SOCAN means the Society of Composers, Authors and Music Publishers of Canada. Works means any or all of the musical works in SOCAN’s repertoire. | D10: Dans ce formulaire, vous, votre et le titulaire de licence désignent la personne ou l’entreprise qui présente une demande de licence ou une déclaration annuelle. Nous, notre et la SOCAN désignent la Société canadienne des auteurs, compositeurs et éditeurs de musique. Le mot œuvre désigne toute œuvre musicale du répertoire de la SOCAN.
A11: Field6 | B11: =IF($B$1="English",C11,D11) -> A copy of any SOCAN tariff may be obtained by emailing licence@socan.ca or calling 1.866.944.6223. | C11: A copy of any SOCAN tariff may be obtained by emailing licence@socan.ca or calling 1.866.944.6223. | D11: Vous pouvez obtenir un exemplaire de tout tarif de la SOCAN en écrivant à licence@socan.ca ou en appelant au 1.866.944.6224.
A12: Field7 | B12: =IF($B$1="English",C12,D12) -> If the tariff for a year has not been approved by January 1st of that year, the last approved tariff will govern until the new tariff is approved, at which time the licence fees will be adjusted to reflect the approved tariff for the year. | C12: If the tariff for a year has not been approved by January 1st of that year, the last approved tariff will govern until the new tariff is approved, at which time the licence fees will be adjusted to reflect the approved tariff for the year. | D12: Si le tarif d’une année n’a pas été homologué au 1er janvier de cette même année, le dernier tarif en vigueur s’appliquera jusqu’à l’approbation de sa nouvelle version, date à laquelle les droits de licence seront corrigés afin de refléter la version homologuée pour l’année.
A13: Field8 | B13: =IF($B$1="English",C13,D13) -> The licence fee, plus applicable taxes for the year, will be calculated in accordance with the terms of the tariff based on the information set out in the most recently filed report form or audit form, subject to adjustment to reflect any updated reports or audits pursuant to the tariff. | C13: The licence fee, plus applicable taxes for the year, will be calculated in accordance with the terms of the tariff based on the information set out in the most recently filed report form or audit form, subject to adjustment to reflect any updated reports or audits pursuant to the tariff. | D13: Les droits de licence, plus les taxes en vigueur pour l’année, seront calculés conformément aux dispositions du tarif d’après les renseignements figurant sur le formulaire de déclaration annuelle ou de vérification le plus récent, sous réserve de correction afin de refléter toute mise à jour de ces renseignements conformément au tarif.
A14: Field9 | B14: =IF($B$1="English",C14,D14) -> You will keep records of all information required to calculate the licence fees. | C14: You will keep records of all information required to calculate the licence fees. | D14: Vous devez conserver toute information nécessaire au calcul des droits de licence.
A15: Field10 | B15: =IF($B$1="English",C15,D15) -> You will submit to SOCAN your licence application and payment on the first day of the licensed month. | C15: You will submit to SOCAN your licence application and payment on the first day of the licensed month. | D15: Vous devez soumettre à la SOCAN votre demande de licence ainsi que votre paiement le premier jour du mois couvert par la licence.
A16: Field11 | B16: =IF($B$1="English",C16,D16) -> We are committed to handling your personal information responsibly. For more information about SOCAN’s Privacy Policy, please visit www.socan.ca | C16: We are committed to handling your personal information responsibly. For more information about SOCAN’s Privacy Policy, please visit www.socan.ca | D16: Nous nous engageons à traiter vos renseignements personnels de façon responsable. Pour de plus amples informations sur la Politique de confidentialité de la SOCAN, veuillez visiter www.socan.ca.
A17: Field12 | B17: =IF($B$1="English",C17,D17) -> Where does you license fee go? | C17: Where does you license fee go? | D17: Où vont vos redevances?
... A19: Field14 | B19: =IF($B$1="English",C19,D19) -> Operating costs | C19: Operating costs | D19: Frais d'exploitation
