Workbook

Sheet InsHRA-Request
A2: Premium Saver-Insured HRA-Request for Quote
A3: Employer Name: | H3: Telephone:
A4: Employer Address:
A5: Employer City: | F5: State: | H5: Zip Code:
A6: Nature of business | H6: Effective Date:
A7: Agent Name: | H7: Telephone:
A8: Email To: | E8: Fax to: | H8: Questions:
A10: Current Plan(s) | B10: Plan One | E10: Plan Two | H10: Plan Three
A11: Medical Carrier
A12: Deductible Amount
A13: Employee Coinsurance | B13: 0 | E13: 0 | H13: 0
A14: $ Of Coinsurance
A15: Total Dollars OOP
A16: Doctor Office
A17: Specialist Office Visit
A18: Chiropractic
A19: Drug Co Pays
A20: Emergency Room Copay
A21: Urgent Care Copay
A22: Drug Deductible Amount | B22: 0 | E22: 0 | H22: 0
A23: Renewal Date
B24: # Employee | C24: Current | D24: Renewal | E24: # Employee | F24: Current | G24: Renewal | H24: # Employee | I24: Current | J24: Renewal
A25: Employee
A26: Employee and Spouse
A27: Employee/Child(ren)
A28: Family
E37: Special Instructions
A38: Alternate Plan
A39: Medical Carrier
A40: Deductible Amount
A41: Employee Coins. | D41: %
A42: $ Of Coinsurance
A43: Total Dollars OOP
A44: Doctor Office
A45: Specialist Office Visit
A46: Chiropractic
A47: Drug Co Pays | E47: Primary Goal of this Quote is to Save Premium
A48: ER Copay | E48: Second Goal is to…
A49: Urgent Care Copay | E49: (Please check one)
A50: Drug Deductible Amt | B50: 0 | F50: Save Premium
...

Sheet 3Plans-3Opt
B1: Insured HRA Quote for:
B2: ='InsHRA-Request'!B3:J3 -> 0
B4: Current Plans
C5: Status | D5: # | E5: ='InsHRA-Request'!B11 -> 0 | H5: # | I5: ='InsHRA-Request'!E11 -> 0 | J5: # | K5: ='InsHRA-Request'!H11 -> 0 | L5: Total
C6: Employee | D6: ='InsHRA-Request'!B25 -> 0 | E6: ='InsHRA-Request'!C25 -> 0 | H6: ='InsHRA-Request'!E25 -> 0 | I6: ='InsHRA-Request'!F25 -> 0 | J6: ='InsHRA-Request'!H25 -> 0 | K6: ='InsHRA-Request'!I25 -> 0
C7: 2 Person | D7: ='InsHRA-Request'!B26 -> 0 | E7: ='InsHRA-Request'!C26 -> 0 | H7: ='InsHRA-Request'!E26 -> 0 | I7: ='InsHRA-Request'!F26 -> 0 | J7: ='InsHRA-Request'!H26 -> 0 | K7: ='InsHRA-Request'!I26 -> 0
C8: Emp/Child | D8: ='InsHRA-Request'!B27 -> 0 | E8: ='InsHRA-Request'!C27 -> 0 | H8: ='InsHRA-Request'!E27 -> 0 | I8: ='InsHRA-Request'!F27 -> 0 | J8: ='InsHRA-Request'!H27 -> 0 | K8: ='InsHRA-Request'!I27 -> 0
C9: Family | D9: ='InsHRA-Request'!B28 -> 0 | E9: ='InsHRA-Request'!C28 -> 0 | H9: ='InsHRA-Request'!E28 -> 0 | I9: ='InsHRA-Request'!F28 -> 0 | J9: ='InsHRA-Request'!H28 -> 0 | K9: ='InsHRA-Request'!I28 -> 0
D10: =SUM(D6:D9) -> 0 | E10: =(D6*E6)+(D7*E7)+(D9*E9)+(D8*E8) -> 0 | H10: =SUM(H6:H9) -> 0 | I10: =(H6*I6)+(H7*I7)+(H9*I9)+(H8*I8) -> 0 | J10: =SUM(J6:J9) -> 0 | K10: =(J6*K6)+(J7*K7)+(J9*K9)+(J8*K8) -> 0 | L10: =I10+E10+K10 -> 0
B12: Renewal Plans
C13: Status | D13: # | E13: =E5 -> 0 | H13: # | I13: ='InsHRA-Request'!E11 -> 0 | J13: # | K13: =K5 -> 0 | L13: Total
C14: Employee | D14: =D6 -> 0 | E14: ='InsHRA-Request'!D25 -> 0 | H14: =H6 -> 0 | I14: ='InsHRA-Request'!G25 -> 0 | J14: ='InsHRA-Request'!H25 -> 0 | K14: ='InsHRA-Request'!J25 -> 0
C15: 2 Person | D15: =D7 -> 0 | E15: ='InsHRA-Request'!D26 -> 0 | H15: =H7 -> 0 | I15: ='InsHRA-Request'!G26 -> 0 | J15: ='InsHRA-Request'!H26 -> 0 | K15: ='InsHRA-Request'!J26 -> 0
C16: Emp/Child | D16: =D8 -> 0 | E16: ='InsHRA-Request'!D27 -> 0 | H16: =H8 -> 0 | I16: ='InsHRA-Request'!G27 -> 0 | J16: ='InsHRA-Request'!H27 -> 0 | K16: ='InsHRA-Request'!J27 -> 0
C17: Family | D17: =D9 -> 0 | E17: ='InsHRA-Request'!D28 -> 0 | H17: =H9 -> 0 | I17: ='InsHRA-Request'!G28 -> 0 | J17: ='InsHRA-Request'!H28 -> 0 | K17: ='InsHRA-Request'!J28 -> 0
D18: =SUM(D14:D17) -> 0 | E18: =(D14*E14)+(D15*E15)+(D17*E17)+(D16*E16) -> 0 | H18: =SUM(H14:H17) -> 0 | I18: =(H14*I14)+(H15*I15)+(H17*I17)+(H16*I16) -> 0 | J18: =SUM(J14:J17) -> 0 | K18: =(J14*K14)+(J15*K15)+(J17*K17)+(J16*K16) -> 0 | L18: =I18+E18+K18 -> 0
B19: Proposed Plan 1: Annual Savings Versus Renewal PH HMO
C20: Status | D20: Census | E20: Medical | G20: Insured HRA 250 Ded 80% to $750 | L20: Total
C21: Employee | E21: 247.46 | G21: 137.81 | I21: =[1]TransRates!$W$29 | L21: =SUM(E21:I21) -> 385.27
C22: 2 Person | E22: 593.89 | G22: 263.48 | I22: =[1]TransRates!$W$30 | L22: =SUM(E22:I22) -> 857.37
C23: Emp/Child | E23: =[1]Census!O17 -> 0 | G23: 0 | I23: =[1]TransRates!$W$31 | L23: =SUM(E23:I23) -> 0
C24: Family | E24: 742.37 | G24: 373.27 | I24: =[1]TransRates!$W$32 | L24: =SUM(E24:I24) -> 1115.64
B25: =SUM(B21:B24) -> 0
B27: ="Proposed Plan 1: "&'InsHRA-Request'!B39&" & Insured HRA ($"&'InsHRA-Request'!C69&" deductible / $"&'InsHRA-Request'!C72&" coinsurance)" -> Proposed Plan 1: & Insured HRA ($ deductible / $ coinsurance)
G28: 4Kdd/10K
C29: Status | D29: # | E29: ='InsHRA-Request'!B39 -> 0 | H29: Insured HRA | L29: Total
B30: 12 | C30: Employee | D30: ='InsHRA-Request'!B53 -> 0 | E30: ='InsHRA-Request'!C53 -> 0 | H30: ='InsHRA-Request'!D75 -> 0 | L30: =H30+E30 -> 0
B31: 0 | C31: 2 Person | D31: ='InsHRA-Request'!B54 -> 0 | E31: ='InsHRA-Request'!C54 -> 0 | H31: ='InsHRA-Request'!D76 -> 0 | L31: =H31+E31 -> 0
C32: Emp/Child | D32: ='InsHRA-Request'!B55 -> 0 | E32: ='InsHRA-Request'!C55 -> 0 | H32: ='InsHRA-Request'!D77 -> 0 | L32: =H32+E32 -> 0
B33: 1 | C33: Family | D33: ='InsHRA-Request'!B56 -> 0 | E33: ='InsHRA-Request'!C56 -> 0 | H33: ='InsHRA-Request'!D78 -> 0 | L33: =H33+E33 -> 0
B34: =SUM(B30:B33) -> 13 | D34: =SUM(D30:D33) -> 0 | E34: =(D30*E30)+(D31*E31)+(D33*E33)+(D32*E32) -> 0 | H34: =(D30*H30)+(D31*H31)+(D33*H33)+(D32*H32) -> 0 | L34: =(D30*L30)+(D31*L31)+(D33*L33)+(D32*L32) -> 0
B36: ="Proposed Plan 2: "&'InsHRA-Request'!B39&" & Insured HRA ($"&'InsHRA-Request'!E69&" deductible / $"&'InsHRA-Request'!E72&" coinsurance)" -> Proposed Plan 2: & Insured HRA ($ deductible / $ coinsurance)
C37: Status | D37: # | E37: =E29 -> 0 | H37: =H29 -> Insured HRA | L37: Total
B38: 28 | C38: Employee | D38: =D30 -> 0 | E38: =E30 -> 0 | H38: ='InsHRA-Request'!F75 -> 0 | L38: =H38+E38 -> 0
B39: 10 | C39: 2 Person | D39: =D31 -> 0 | E39: =E31 -> 0 | H39: ='InsHRA-Request'!F76 -> 0 | L39: =H39+E39 -> 0
C40: Emp/Child | D40: =D32 -> 0 | E40: =E32 -> 0 | H40: ='InsHRA-Request'!F77 -> 0 | L40: =H40+E40 -> 0
B41: 30 | C41: Family | D41: =D33 -> 0 | E41: =E33 -> 0 | H41: ='InsHRA-Request'!F78 -> 0 | L41: =H41+E41 -> 0
B42: =SUM(B38:B41) -> 68 | D42: =SUM(D38:D41) -> 0 | E42: =(D38*E38)+(D39*E39)+(D41*E41)+(D40*E40) -> 0 | H42: =(D38*H38)+(D39*H39)+(D41*H41)+(D40*H40) -> 0 | L42: =(D38*L38)+(D39*L39)+(D41*L41)+(D40*L40) -> 0
C44: Proposed Plan Totals | L44: =L42+L34 -> 0
B46: ="Proposed Plan 3: "&'InsHRA-Request'!B39&" & Insured HRA ($"&'InsHRA-Request'!G69&" deductible / $"&'InsHRA-Request'!G72&" coinsurance)" -> Proposed Plan 3: & Insured HRA ($ deductible / $ coinsurance)
...

Sheet 2Plan-3Opt
B1: Insured HRA Quote for:
B2: ='InsHRA-Request'!B3 -> 0
B4: Current Plans
C5: Status | D5: # | E5: ='InsHRA-Request'!B11 -> 0 | H5: # | I5: ='InsHRA-Request'!E11 -> 0 | J5: Total
C6: Employee | D6: ='InsHRA-Request'!B25 -> 0 | E6: ='InsHRA-Request'!C25 -> 0 | H6: ='InsHRA-Request'!E25 -> 0 | I6: ='InsHRA-Request'!F25 -> 0
C7: 2 Person | D7: ='InsHRA-Request'!B26 -> 0 | E7: ='InsHRA-Request'!C26 -> 0 | H7: ='InsHRA-Request'!E26 -> 0 | I7: ='InsHRA-Request'!F26 -> 0
C8: Emp/Child | D8: ='InsHRA-Request'!B27 -> 0 | E8: ='InsHRA-Request'!C27 -> 0 | H8: ='InsHRA-Request'!E27 -> 0 | I8: ='InsHRA-Request'!F27 -> 0
C9: Family | D9: ='InsHRA-Request'!B28 -> 0 | E9: ='InsHRA-Request'!C28 -> 0 | H9: ='InsHRA-Request'!E28 -> 0 | I9: ='InsHRA-Request'!F28 -> 0
D10: =SUM(D6:D9) -> 0 | E10: =(D6*E6)+(D7*E7)+(D9*E9)+(D8*E8) -> 0 | H10: =SUM(H6:H9) -> 0 | I10: =(H6*I6)+(H7*I7)+(H9*I9)+(H8*I8) -> 0 | J10: =I10+E10 -> 0
B12: Renewal Plans
C13: Status | D13: # | E13: =E5 -> 0 | H13: # | I13: =I5 -> 0 | J13: Total
C14: Employee | D14: =D6 -> 0 | E14: ='InsHRA-Request'!D25 -> 0 | H14: =H6 -> 0 | I14: ='InsHRA-Request'!G25 -> 0
C15: 2 Person | D15: =D7 -> 0 | E15: ='InsHRA-Request'!D26 -> 0 | H15: =H7 -> 0 | I15: ='InsHRA-Request'!G26 -> 0
C16: Emp/Child | D16: =D8 -> 0 | E16: ='InsHRA-Request'!D27 -> 0 | H16: =H8 -> 0 | I16: ='InsHRA-Request'!G27 -> 0
C17: Family | D17: =D9 -> 0 | E17: ='InsHRA-Request'!D28 -> 0 | H17: =H9 -> 0 | I17: ='InsHRA-Request'!G28 -> 0
D18: =SUM(D14:D17) -> 0 | E18: =(D14*E14)+(D15*E15)+(D17*E17)+(D16*E16) -> 0 | H18: =SUM(H14:H17) -> 0 | I18: =(H14*I14)+(H15*I15)+(H17*I17)+(H16*I16) -> 0 | J18: =I18+E18 -> 0
B19: Proposed Plan 1: Annual Savings Versus Renewal PH HMO
C20: Status | D20: Census | E20: Medical | G20: Insured HRA 250 Ded 80% to $750 | J20: Total
C21: Employee | E21: 247.46 | G21: 137.81 | I21: =[1]TransRates!$W$29 | J21: =SUM(E21:I21) -> 385.27
C22: 2 Person | E22: 593.89 | G22: 263.48 | I22: =[1]TransRates!$W$30 | J22: =SUM(E22:I22) -> 857.37
C23: Emp/Child | E23: =[1]Census!O17 -> 0 | G23: 0 | I23: =[1]TransRates!$W$31 | J23: =SUM(E23:I23) -> 0
C24: Family | E24: 742.37 | G24: 373.27 | I24: =[1]TransRates!$W$32 | J24: =SUM(E24:I24) -> 1115.64
B25: =SUM(B21:B24) -> 0
B27: ="Proposed Plan 1: "&'InsHRA-Request'!B39&" & Insured HRA ($"&'InsHRA-Request'!C69&" deductible / $"&'InsHRA-Request'!C72&" coinsurance)" -> Proposed Plan 1: & Insured HRA ($ deductible / $ coinsurance)
G28: 4Kdd/10K
C29: Status | D29: Census | E29: ='InsHRA-Request'!B39 -> 0 | H29: Insured HRA | J29: Total
B30: 12 | C30: Employee | D30: =D6+H6 -> 0 | E30: ='InsHRA-Request'!C53 -> 0 | H30: ='InsHRA-Request'!D75 -> 0 | J30: =H30+E30 -> 0
B31: 0 | C31: 2 Person | D31: =D7+H7 -> 0 | E31: ='InsHRA-Request'!C54 -> 0 | H31: ='InsHRA-Request'!D76 -> 0 | J31: =H31+E31 -> 0
C32: Emp/Child | D32: =D8+H8 -> 0 | E32: ='InsHRA-Request'!C55 -> 0 | H32: ='InsHRA-Request'!D77 -> 0 | J32: =H32+E32 -> 0
B33: 1 | C33: Family | D33: =D9+H9 -> 0 | E33: ='InsHRA-Request'!C56 -> 0 | H33: ='InsHRA-Request'!D78 -> 0 | J33: =H33+E33 -> 0
B34: =SUM(B30:B33) -> 13 | D34: =SUM(D30:D33) -> 0 | E34: =(D30*E30)+(D31*E31)+(D33*E33)+(D32*E32) -> 0 | H34: =(D30*H30)+(D31*H31)+(D33*H33)+(D32*H32) -> 0 | J34: =(D30*J30)+(D31*J31)+(D33*J33)+(D32*J32) -> 0
B36: ="Proposed Plan 2: "&'InsHRA-Request'!B39&" & Insured HRA ($"&'InsHRA-Request'!E69&" deductible / $"&'InsHRA-Request'!E72&" coinsurance)" -> Proposed Plan 2: & Insured HRA ($ deductible / $ coinsurance)
C37: Status | D37: # | E37: =E29 -> 0 | H37: =H29 -> Insured HRA | J37: Total
B38: 28 | C38: Employee | D38: =D30 -> 0 | E38: =E30 -> 0 | H38: ='InsHRA-Request'!F75 -> 0 | J38: =H38+E38 -> 0
B39: 10 | C39: 2 Person | D39: =D31 -> 0 | E39: =E31 -> 0 | H39: ='InsHRA-Request'!F76 -> 0 | J39: =H39+E39 -> 0
C40: Emp/Child | D40: =D32 -> 0 | E40: =E32 -> 0 | H40: ='InsHRA-Request'!F77 -> 0 | J40: =H40+E40 -> 0
B41: 30 | C41: Family | D41: =D33 -> 0 | E41: =E33 -> 0 | H41: ='InsHRA-Request'!F78 -> 0 | J41: =H41+E41 -> 0
B42: =SUM(B38:B41) -> 68 | D42: =SUM(D38:D41) -> 0 | E42: =(D38*E38)+(D39*E39)+(D41*E41)+(D40*E40) -> 0 | H42: =(D38*H38)+(D39*H39)+(D41*H41)+(D40*H40) -> 0 | J42: =(D38*J38)+(D39*J39)+(D41*J41)+(D40*J40) -> 0
C44: Proposed Plan Totals | J44: =J42+J34 -> 0
B46: ="Proposed Plan 3: "&'InsHRA-Request'!B39&" & Insured HRA ($"&'InsHRA-Request'!G69&" deductible / $"&'InsHRA-Request'!G72&" coinsurance)" -> Proposed Plan 3: & Insured HRA ($ deductible / $ coinsurance)
...

Sheet 2Plans-2Opt
B1: Insured HRA Quote for:
B2: ='InsHRA-Request'!B3 -> 0
B4: Current Plans
C5: Status | D5: # | E5: ='InsHRA-Request'!B11 -> 0 | H5: # | I5: ='InsHRA-Request'!E11 -> 0 | J5: Total
C6: Employee | D6: ='InsHRA-Request'!B25 -> 0 | E6: ='InsHRA-Request'!C25 -> 0 | H6: ='InsHRA-Request'!E25 -> 0 | I6: ='InsHRA-Request'!F25 -> 0
C7: 2 Person | D7: ='InsHRA-Request'!B26 -> 0 | E7: ='InsHRA-Request'!C26 -> 0 | H7: ='InsHRA-Request'!E26 -> 0 | I7: ='InsHRA-Request'!F26 -> 0
C8: Emp/Child | D8: ='InsHRA-Request'!B27 -> 0 | E8: ='InsHRA-Request'!C27 -> 0 | H8: ='InsHRA-Request'!E27 -> 0 | I8: ='InsHRA-Request'!F27 -> 0
C9: Family | D9: ='InsHRA-Request'!B28 -> 0 | E9: ='InsHRA-Request'!C28 -> 0 | H9: ='InsHRA-Request'!E28 -> 0 | I9: ='InsHRA-Request'!F28 -> 0
D10: =SUM(D6:D9) -> 0 | E10: =(D6*E6)+(D7*E7)+(D9*E9)+(D8*E8) -> 0 | H10: =SUM(H6:H9) -> 0 | I10: =(H6*I6)+(H7*I7)+(H9*I9)+(H8*I8) -> 0 | J10: =I10+E10 -> 0
B12: Renewal Plans
C13: Status | D13: # | E13: =E5 -> 0 | H13: # | I13: =I5 -> 0 | J13: Total
C14: Employee | D14: =D6 -> 0 | E14: ='InsHRA-Request'!D25 -> 0 | H14: =H6 -> 0 | I14: ='InsHRA-Request'!G25 -> 0
C15: 2 Person | D15: =D7 -> 0 | E15: ='InsHRA-Request'!D26 -> 0 | H15: =H7 -> 0 | I15: ='InsHRA-Request'!G26 -> 0
C16: Emp/Child | D16: =D8 -> 0 | E16: ='InsHRA-Request'!D27 -> 0 | H16: =H8 -> 0 | I16: ='InsHRA-Request'!G27 -> 0
C17: Family | D17: =D9 -> 0 | E17: ='InsHRA-Request'!D28 -> 0 | H17: =H9 -> 0 | I17: ='InsHRA-Request'!G28 -> 0
D18: =SUM(D14:D17) -> 0 | E18: =(D14*E14)+(D15*E15)+(D17*E17)+(D16*E16) -> 0 | H18: =SUM(H14:H17) -> 0 | I18: =(H14*I14)+(H15*I15)+(H17*I17)+(H16*I16) -> 0 | J18: =I18+E18 -> 0
B19: Proposed Plan 1: Annual Savings Versus Renewal PH HMO
C20: Status | D20: Census | E20: Medical | G20: Insured HRA 250 Ded 80% to $750 | J20: Total
C21: Employee | E21: 247.46 | G21: 137.81 | I21: =[1]TransRates!$W$29 | J21: =SUM(E21:I21) -> 385.27
C22: 2 Person | E22: 593.89 | G22: 263.48 | I22: =[1]TransRates!$W$30 | J22: =SUM(E22:I22) -> 857.37
C23: Emp/Child | E23: =[1]Census!O17 -> 0 | G23: 0 | I23: =[1]TransRates!$W$31 | J23: =SUM(E23:I23) -> 0
C24: Family | E24: 742.37 | G24: 373.27 | I24: =[1]TransRates!$W$32 | J24: =SUM(E24:I24) -> 1115.64
B25: =SUM(B21:B24) -> 0
B27: ="Proposed Plan 1: "&'InsHRA-Request'!B39&" & Insured HRA ($"&'InsHRA-Request'!C69&" deductible / $"&'InsHRA-Request'!C72&" coinsurance)" -> Proposed Plan 1: & Insured HRA ($ deductible / $ coinsurance)
G28: 4Kdd/10K
C29: Status | D29: Census | E29: ='InsHRA-Request'!B39 -> 0 | H29: Insured HRA | J29: Total
B30: 12 | C30: Employee | D30: =D6+H6 -> 0 | E30: ='InsHRA-Request'!C53 -> 0 | H30: ='InsHRA-Request'!D75 -> 0 | J30: =H30+E30 -> 0
B31: 0 | C31: 2 Person | D31: =D7+H7 -> 0 | E31: ='InsHRA-Request'!C54 -> 0 | H31: ='InsHRA-Request'!D76 -> 0 | J31: =H31+E31 -> 0
C32: Emp/Child | D32: =D8+H8 -> 0 | E32: ='InsHRA-Request'!C55 -> 0 | H32: ='InsHRA-Request'!D77 -> 0 | J32: =H32+E32 -> 0
B33: 1 | C33: Family | D33: =D9+H9 -> 0 | E33: ='InsHRA-Request'!C56 -> 0 | H33: ='InsHRA-Request'!D78 -> 0 | J33: =H33+E33 -> 0
B34: =SUM(B30:B33) -> 13 | D34: =SUM(D30:D33) -> 0 | E34: =(D30*E30)+(D31*E31)+(D33*E33)+(D32*E32) -> 0 | H34: =(D30*H30)+(D31*H31)+(D33*H33)+(D32*H32) -> 0 | J34: =(D30*J30)+(D31*J31)+(D33*J33)+(D32*J32) -> 0
B36: ="Proposed Plan 2: "&'InsHRA-Request'!B39&" & Insured HRA ($"&'InsHRA-Request'!E69&" deductible / $"&'InsHRA-Request'!E72&" coinsurance)" -> Proposed Plan 2: & Insured HRA ($ deductible / $ coinsurance)
C37: Status | D37: Census | E37: =E29 -> 0 | H37: =H29 -> Insured HRA | J37: Total
B38: 28 | C38: Employee | D38: =D30 -> 0 | E38: =E30 -> 0 | H38: ='InsHRA-Request'!F75 -> 0 | J38: =H38+E38 -> 0
B39: 10 | C39: 2 Person | D39: =D31 -> 0 | E39: =E31 -> 0 | H39: ='InsHRA-Request'!F76 -> 0 | J39: =H39+E39 -> 0
C40: Emp/Child | D40: =D32 -> 0 | E40: =E32 -> 0 | H40: ='InsHRA-Request'!F77 -> 0 | J40: =H40+E40 -> 0
B41: 30 | C41: Family | D41: =D33 -> 0 | E41: =E33 -> 0 | H41: ='InsHRA-Request'!F78 -> 0 | J41: =H41+E41 -> 0
B42: =SUM(B38:B41) -> 68 | D42: =SUM(D38:D41) -> 0 | E42: =(D38*E38)+(D39*E39)+(D41*E41)+(D40*E40) -> 0 | H42: =(D38*H38)+(D39*H39)+(D41*H41)+(D40*H40) -> 0 | J42: =(D38*J38)+(D39*J39)+(D41*J41)+(D40*J40) -> 0
C44: Proposed Plan Totals | J44: =J42+J34 -> 0
B46: Plan Summary
...

Sheet 2PlansTiers
B1: Insured HRA Quote for:
B2: ='InsHRA-Request'!B3:J3 -> 0
B4: Current Plans
C5: Status | D5: # | E5: ='InsHRA-Request'!B11 -> 0 | H5: # | I5: ='InsHRA-Request'!E11 -> 0 | J5: Total
C6: Employee | D6: ='InsHRA-Request'!B25 -> 0 | E6: ='InsHRA-Request'!C25 -> 0 | H6: ='InsHRA-Request'!E25 -> 0 | I6: ='InsHRA-Request'!F25 -> 0
C7: 2 Person | D7: ='InsHRA-Request'!B26 -> 0 | E7: ='InsHRA-Request'!C26 -> 0 | H7: ='InsHRA-Request'!E26 -> 0 | I7: ='InsHRA-Request'!F26 -> 0
C8: Emp/Child | D8: ='InsHRA-Request'!B27 -> 0 | E8: ='InsHRA-Request'!C27 -> 0 | H8: ='InsHRA-Request'!E27 -> 0 | I8: ='InsHRA-Request'!F27 -> 0
C9: Family | D9: ='InsHRA-Request'!B28 -> 0 | E9: ='InsHRA-Request'!C28 -> 0 | H9: ='InsHRA-Request'!E28 -> 0 | I9: ='InsHRA-Request'!F28 -> 0
D10: =SUM(D6:D9) -> 0 | E10: =(D6*E6)+(D7*E7)+(D9*E9)+(D8*E8) -> 0 | H10: =SUM(H6:H9) -> 0 | I10: =(H6*I6)+(H7*I7)+(H9*I9)+(H8*I8) -> 0 | J10: =I10+E10 -> 0
B12: Renewal Plans
C13: Status | D13: # | E13: =E5 -> 0 | H13: # | I13: =I5 -> 0 | J13: Total
C14: Employee | D14: =D6 -> 0 | E14: ='InsHRA-Request'!D25 -> 0 | H14: =H6 -> 0 | I14: ='InsHRA-Request'!G25 -> 0
C15: 2 Person | D15: =D7 -> 0 | E15: ='InsHRA-Request'!D26 -> 0 | H15: =H7 -> 0 | I15: ='InsHRA-Request'!G26 -> 0
C16: Emp/Child | D16: =D8 -> 0 | E16: ='InsHRA-Request'!D27 -> 0 | H16: =H8 -> 0 | I16: ='InsHRA-Request'!G27 -> 0
C17: Family | D17: =D9 -> 0 | E17: ='InsHRA-Request'!D28 -> 0 | H17: =H9 -> 0 | I17: ='InsHRA-Request'!G28 -> 0
D18: =SUM(D14:D17) -> 0 | E18: =(D14*E14)+(D15*E15)+(D17*E17)+(D16*E16) -> 0 | H18: =SUM(H14:H17) -> 0 | I18: =(H14*I14)+(H15*I15)+(H17*I17)+(H16*I16) -> 0 | J18: =I18+E18 -> 0
B19: Proposed Plan 1: Annual Savings Versus Renewal PH HMO
C20: Status | D20: Census | E20: Medical | G20: Insured HRA 250 Ded 80% to $750 | J20: Total
C21: Employee | E21: 247.46 | G21: 137.81 | I21: =[1]TransRates!$W$29 | J21: =SUM(E21:I21) -> 385.27
C22: 2 Person | E22: 593.89 | G22: 263.48 | I22: =[1]TransRates!$W$30 | J22: =SUM(E22:I22) -> 857.37
C23: Emp/Child | E23: =[1]Census!O17 -> 0 | G23: 0 | I23: =[1]TransRates!$W$31 | J23: =SUM(E23:I23) -> 0
C24: Family | E24: 742.37 | G24: 373.27 | I24: =[1]TransRates!$W$32 | J24: =SUM(E24:I24) -> 1115.64
B25: =SUM(B21:B24) -> 0
B27: ="Proposed Plan 1: Move "&E13&" Employees to:" -> Proposed Plan 1: Move 0 Employees to:
B28: ='InsHRA-Request'!B39&" & Insured HRA ($"&'InsHRA-Request'!C69&" deductible / $"&'InsHRA-Request'!C72&" coinsurance)" -> & Insured HRA ($ deductible / $ coinsurance)
G29: 4Kdd/10K
C30: Status | D30: Census | E30: ='InsHRA-Request'!B39 -> 0 | H30: Insured HRA | J30: Total
B31: 12 | C31: Employee | D31: =D6 -> 0 | E31: ='InsHRA-Request'!C53 -> 0 | H31: ='InsHRA-Request'!D75 -> 0 | J31: =H31+E31 -> 0
B32: 0 | C32: 2 Person | D32: =D7 -> 0 | E32: ='InsHRA-Request'!C54 -> 0 | H32: ='InsHRA-Request'!D76 -> 0 | J32: =H32+E32 -> 0
C33: Emp/Child | D33: =D8 -> 0 | E33: ='InsHRA-Request'!C55 -> 0 | H33: ='InsHRA-Request'!D77 -> 0 | J33: =H33+E33 -> 0
B34: 1 | C34: Family | D34: =D9 -> 0 | E34: ='InsHRA-Request'!C56 -> 0 | H34: ='InsHRA-Request'!D78 -> 0 | J34: =H34+E34 -> 0
B35: =SUM(B31:B34) -> 13 | D35: =SUM(D31:D34) -> 0 | E35: =(D31*E31)+(D32*E32)+(D34*E34)+(D33*E33) -> 0 | H35: =(D31*H31)+(D32*H32)+(D34*H34)+(D33*H33) -> 0 | J35: =(D31*J31)+(D32*J32)+(D34*J34)+(D33*J33) -> 0
B37: ="Proposed Plan 2: Move "&I13&" Employees to:" -> Proposed Plan 2: Move 0 Employees to:
B38: ='InsHRA-Request'!B39&" & Insured HRA ($"&'InsHRA-Request'!E69&" deductible / $"&'InsHRA-Request'!E72&" coinsurance)" -> & Insured HRA ($ deductible / $ coinsurance)
C39: Status | D39: Census | E39: =E30 -> 0 | H39: =H30 -> Insured HRA | J39: Total
B40: 28 | C40: Employee | D40: =H6 -> 0 | E40: =E31 -> 0 | H40: ='InsHRA-Request'!F75 -> 0 | J40: =H40+E40 -> 0
B41: 10 | C41: 2 Person | D41: =H7 -> 0 | E41: =E32 -> 0 | H41: ='InsHRA-Request'!F76 -> 0 | J41: =H41+E41 -> 0
C42: Emp/Child | D42: =H8 -> 0 | E42: =E33 -> 0 | H42: ='InsHRA-Request'!F77 -> 0 | J42: =H42+E42 -> 0
B43: 30 | C43: Family | D43: =H9 -> 0 | E43: =E34 -> 0 | H43: ='InsHRA-Request'!F78 -> 0 | J43: =H43+E43 -> 0
B44: =SUM(B40:B43) -> 68 | D44: =SUM(D40:D43) -> 0 | E44: =(D40*E40)+(D41*E41)+(D43*E43)+(D42*E42) -> 0 | H44: =(D40*H40)+(D41*H41)+(D43*H43)+(D42*H42) -> 0 | J44: =(D40*J40)+(D41*J41)+(D43*J43)+(D42*J42) -> 0
...

Sheet 1Plan-3Opt
B2: Insured HRA Quote for:
B3: ='InsHRA-Request'!B3:G3 -> 0
B5: ="Current Plan: "&'InsHRA-Request'!B11:D11 -> Current Plan:
E6: 2500dd/10K
B7: Census | C7: Status | D7: Medical | F7: Total
B8: ='InsHRA-Request'!B25 -> 0 | C8: Employee | D8: ='InsHRA-Request'!C25 -> 0 | F8: =SUM(D8:E8) -> 0
B9: ='InsHRA-Request'!B26 -> 0 | C9: 2 Person | D9: ='InsHRA-Request'!C26 -> 0 | F9: =SUM(D9:E9) -> 0
B10: ='InsHRA-Request'!B27 -> 0 | C10: Emp/Child | D10: ='InsHRA-Request'!C27 -> 0 | F10: =SUM(D10:E10) -> 0
B11: ='InsHRA-Request'!B28 -> 0 | C11: Family | D11: ='InsHRA-Request'!C28 -> 0 | F11: =SUM(D11:E11) -> 0
B12: =SUM(B8:B11) -> 0 | D12: =(B8*D8)+(B9*D9)+(B11*D11)+(B10*D10) -> 0 | F12: =(B8*F8)+(B9*F9)+(B10*F10)+(B11*F11) -> 0
B14: ="Renewal Plan: "&'InsHRA-Request'!B11:D11 -> Renewal Plan:
E15: 2500dd/10K
B16: Census | C16: Status | D16: Medical | F16: Total
B17: ='InsHRA-Request'!B25 -> 0 | C17: Employee | D17: ='InsHRA-Request'!D25 -> 0 | F17: =SUM(D17:E17) -> 0
B18: ='InsHRA-Request'!B26 -> 0 | C18: 2 Person | D18: ='InsHRA-Request'!D26 -> 0 | F18: =SUM(D18:E18) -> 0
B19: ='InsHRA-Request'!B27 -> 0 | C19: Emp/Child | D19: ='InsHRA-Request'!D27 -> 0 | F19: =SUM(D19:E19) -> 0
B20: ='InsHRA-Request'!B28 -> 0 | C20: Family | D20: ='InsHRA-Request'!D28 -> 0 | F20: =SUM(D20:E20) -> 0
B21: =SUM(B17:B20) -> 0 | D21: =(B17*D17)+(B18*D18)+(B20*D20)+(B19*D19) -> 0 | F21: =(B17*F17)+(B18*F18)+(B19*F19)+(B20*F20) -> 0
B23: ="Proposed Plan 1: "&'InsHRA-Request'!B39&" & Insured HRA ($"&'InsHRA-Request'!C69&" deductible / $"&'InsHRA-Request'!C72&" coinsurance)" -> Proposed Plan 1: & Insured HRA ($ deductible / $ coinsurance)
E24: 2500dd/10K
B25: Census | C25: Status | D25: Medical | E25: Insured HRA | F25: Total
B26: ='InsHRA-Request'!B25 -> 0 | C26: Employee | D26: ='InsHRA-Request'!C53 -> 0 | E26: ='InsHRA-Request'!D75 -> 0 | F26: =SUM(D26:E26) -> 0
B27: ='InsHRA-Request'!B26 -> 0 | C27: 2 Person | D27: ='InsHRA-Request'!C54 -> 0 | E27: ='InsHRA-Request'!D76 -> 0 | F27: =SUM(D27:E27) -> 0
B28: ='InsHRA-Request'!B27 -> 0 | C28: Emp/Child | D28: ='InsHRA-Request'!C55 -> 0 | E28: ='InsHRA-Request'!D77 -> 0 | F28: =SUM(D28:E28) -> 0
B29: ='InsHRA-Request'!B28 -> 0 | C29: Family | D29: ='InsHRA-Request'!C56 -> 0 | E29: ='InsHRA-Request'!D78 -> 0 | F29: =SUM(D29:E29) -> 0
B30: =SUM(B26:B29) -> 0 | D30: =(B26*D26)+(B27*D27)+(B29*D29)+(B28*D28) -> 0 | E30: =(B26*E26)+(B27*E27)+(B29*E29)+(B28*E28) -> 0 | F30: =(B26*F26)+(B27*F27)+(B28*F28)+(B29*F29) -> 0
B32: ="Proposed Plan 2: "&'InsHRA-Request'!B39&" & Insured HRA ($"&'InsHRA-Request'!E69&" deductible / $"&'InsHRA-Request'!E72&" coinsurance)" -> Proposed Plan 2: & Insured HRA ($ deductible / $ coinsurance)
E33: 2500dd/10K
B34: Census | C34: Status | D34: Medical | E34: Insured HRA | F34: Total
B35: ='InsHRA-Request'!B25 -> 0 | C35: Employee | D35: =D26 -> 0 | E35: ='InsHRA-Request'!F75 -> 0 | F35: =SUM(D35:E35) -> 0
B36: ='InsHRA-Request'!B26 -> 0 | C36: 2 Person | D36: =D27 -> 0 | E36: ='InsHRA-Request'!F76 -> 0 | F36: =SUM(D36:E36) -> 0
B37: ='InsHRA-Request'!B27 -> 0 | C37: Emp/Child | D37: =D28 -> 0 | E37: ='InsHRA-Request'!F77 -> 0 | F37: =SUM(D37:E37) -> 0
B38: ='InsHRA-Request'!B28 -> 0 | C38: Family | D38: =D29 -> 0 | E38: ='InsHRA-Request'!F78 -> 0 | F38: =SUM(D38:E38) -> 0
B39: =SUM(B35:B38) -> 0 | D39: =(B35*D35)+(B36*D36)+(B38*D38)+(B37*D37) -> 0 | E39: =(B35*E35)+(B36*E36)+(B38*E38)+(B37*E37) -> 0 | F39: =(B35*F35)+(B36*F36)+(B37*F37)+(B38*F38) -> 0
B41: ="Proposed Plan 3: "&'InsHRA-Request'!B39&" & Insured HRA ($"&'InsHRA-Request'!G69&" deductible / $"&'InsHRA-Request'!G72&" coinsurance)" -> Proposed Plan 3: & Insured HRA ($ deductible / $ coinsurance)
E42: 2500dd/10K
B43: Census | C43: Status | D43: Medical | E43: Insured HRA | F43: Total
B44: ='InsHRA-Request'!B25 -> 0 | C44: Employee | D44: =D35 -> 0 | E44: ='InsHRA-Request'!H75 -> 0 | F44: =SUM(D44:E44) -> 0
B45: ='InsHRA-Request'!B26 -> 0 | C45: 2 Person | D45: =D36 -> 0 | E45: ='InsHRA-Request'!H76 -> 0 | F45: =SUM(D45:E45) -> 0
B46: ='InsHRA-Request'!B27 -> 0 | C46: Emp/Child | D46: =D37 -> 0 | E46: ='InsHRA-Request'!H77 -> 0 | F46: =SUM(D46:E46) -> 0
...

Sheet 1Plan-2Opt
B2: Insured HRA Quote for:
B3: ='InsHRA-Request'!B3:G3 -> 0
B5: ="Current Plan: "&'InsHRA-Request'!B11:D11 -> Current Plan:
E6: 2500dd/10K
B7: Census | C7: Status | D7: Medical | F7: Total
B8: ='InsHRA-Request'!B25 -> 0 | C8: Employee | D8: ='InsHRA-Request'!C25 -> 0 | F8: =SUM(D8:E8) -> 0
B9: ='InsHRA-Request'!B26 -> 0 | C9: 2 Person | D9: ='InsHRA-Request'!C26 -> 0 | F9: =SUM(D9:E9) -> 0
B10: ='InsHRA-Request'!B27 -> 0 | C10: Emp/Child | D10: ='InsHRA-Request'!C27 -> 0 | F10: =SUM(D10:E10) -> 0
B11: ='InsHRA-Request'!B28 -> 0 | C11: Family | D11: ='InsHRA-Request'!C28 -> 0 | F11: =SUM(D11:E11) -> 0
B12: =SUM(B8:B11) -> 0 | D12: =(B8*D8)+(B9*D9)+(B11*D11)+(B10*D10) -> 0 | F12: =(B8*F8)+(B9*F9)+(B10*F10)+(B11*F11) -> 0
B14: ="Renewal Plan: "&'InsHRA-Request'!B11:D11 -> Renewal Plan:
E15: 2500dd/10K
B16: Census | C16: Status | D16: Medical | F16: Total
B17: =B8 -> 0 | C17: Employee | D17: ='InsHRA-Request'!D25 -> 0 | F17: =SUM(D17:E17) -> 0
B18: =B9 -> 0 | C18: 2 Person | D18: ='InsHRA-Request'!D26 -> 0 | F18: =SUM(D18:E18) -> 0
B19: =B10 -> 0 | C19: Emp/Child | D19: ='InsHRA-Request'!D27 -> 0 | F19: =SUM(D19:E19) -> 0
B20: =B11 -> 0 | C20: Family | D20: ='InsHRA-Request'!D28 -> 0 | F20: =SUM(D20:E20) -> 0
B21: =SUM(B17:B20) -> 0 | D21: =(B17*D17)+(B18*D18)+(B20*D20)+(B19*D19) -> 0 | F21: =(B17*F17)+(B18*F18)+(B19*F19)+(B20*F20) -> 0
B23: ="Proposed Plan 1: "&'InsHRA-Request'!B39&" & Insured HRA ($"&'InsHRA-Request'!C69&" deductible / $"&'InsHRA-Request'!C72&" coinsurance)" -> Proposed Plan 1: & Insured HRA ($ deductible / $ coinsurance)
E24: 2500dd/10K
B25: Census | C25: Status | D25: Medical | E25: Insured HRA | F25: Total
B26: =B17 -> 0 | C26: Employee | D26: ='InsHRA-Request'!C53 -> 0 | E26: ='InsHRA-Request'!D75 -> 0 | F26: =SUM(D26:E26) -> 0
B27: =B18 -> 0 | C27: 2 Person | D27: ='InsHRA-Request'!C54 -> 0 | E27: ='InsHRA-Request'!D76 -> 0 | F27: =SUM(D27:E27) -> 0
B28: =B19 -> 0 | C28: Emp/Child | D28: ='InsHRA-Request'!C55 -> 0 | E28: ='InsHRA-Request'!D77 -> 0 | F28: =SUM(D28:E28) -> 0
B29: =B20 -> 0 | C29: Family | D29: ='InsHRA-Request'!C56 -> 0 | E29: ='InsHRA-Request'!D78 -> 0 | F29: =SUM(D29:E29) -> 0
B30: =SUM(B26:B29) -> 0 | D30: =(B26*D26)+(B27*D27)+(B29*D29)+(B28*D28) -> 0 | E30: =(B26*E26)+(B27*E27)+(B29*E29)+(B28*E28) -> 0 | F30: =(B26*F26)+(B27*F27)+(B28*F28)+(B29*F29) -> 0
B32: ="Proposed Plan 2: "&'InsHRA-Request'!B39&" & Insured HRA ($"&'InsHRA-Request'!E69&" deductible / $"&'InsHRA-Request'!E72&" coinsurance)" -> Proposed Plan 2: & Insured HRA ($ deductible / $ coinsurance)
E33: 2500dd/10K
B34: Census | C34: Status | D34: Medical | E34: Insured HRA | F34: Total
B35: =B26 -> 0 | C35: Employee | D35: =D26 -> 0 | E35: ='InsHRA-Request'!F75 -> 0 | F35: =SUM(D35:E35) -> 0
B36: =B27 -> 0 | C36: 2 Person | D36: =D27 -> 0 | E36: ='InsHRA-Request'!F76 -> 0 | F36: =SUM(D36:E36) -> 0
B37: =B28 -> 0 | C37: Emp/Child | D37: =D28 -> 0 | E37: ='InsHRA-Request'!F77 -> 0 | F37: =SUM(D37:E37) -> 0
B38: =B29 -> 0 | C38: Family | D38: =D29 -> 0 | E38: ='InsHRA-Request'!F78 -> 0 | F38: =SUM(D38:E38) -> 0
B39: =SUM(B35:B38) -> 0 | D39: =(B35*D35)+(B36*D36)+(B38*D38)+(B37*D37) -> 0 | E39: =(B35*E35)+(B36*E36)+(B38*E38)+(B37*E37) -> 0 | F39: =(B35*F35)+(B36*F36)+(B37*F37)+(B38*F38) -> 0
B41: ="Proposed Plan 3: "&'InsHRA-Request'!B39&" & Insured HRA ($"&'InsHRA-Request'!G69&" deductible / $"&'InsHRA-Request'!G69&" coinsurance)" -> Proposed Plan 3: & Insured HRA ($ deductible / $ coinsurance)
E42: 2500dd/10K
B43: Census | C43: Status | D43: Medical | E43: Insured HRA | F43: Total
B44: =B35 -> 0 | C44: Employee | D44: =D35 -> 0 | F44: =SUM(D44:E44) -> 0
B45: =B36 -> 0 | C45: 2 Person | D45: =D36 -> 0 | F45: =SUM(D45:E45) -> 0
B46: ='[3]InsHRA-Request'!B42 -> 0 | C46: Emp/Child | D46: =D37 -> 0 | F46: =SUM(D46:E46) -> 0
...

Sheet 1Plan-1Opt
B2: Insured HRA Quote for:
B3: ='InsHRA-Request'!B3:G3 -> 0
B5: ="Current Plan: "&'InsHRA-Request'!B11:D11 -> Current Plan:
E6: 2500dd/10K
B7: Census | C7: Status | D7: Medical | F7: Total
B8: ='InsHRA-Request'!B25 -> 0 | C8: Employee | D8: ='InsHRA-Request'!C25 -> 0 | F8: =SUM(D8:E8) -> 0
B9: ='InsHRA-Request'!B26 -> 0 | C9: 2 Person | D9: ='InsHRA-Request'!C26 -> 0 | F9: =SUM(D9:E9) -> 0
B10: ='InsHRA-Request'!B27 -> 0 | C10: Emp/Child | D10: ='InsHRA-Request'!C27 -> 0 | F10: =SUM(D10:E10) -> 0
B11: ='InsHRA-Request'!B28 -> 0 | C11: Family | D11: ='InsHRA-Request'!C28 -> 0 | F11: =SUM(D11:E11) -> 0
B12: =SUM(B8:B11) -> 0 | D12: =(B8*D8)+(B9*D9)+(B11*D11)+(B10*D10) -> 0 | F12: =(B8*F8)+(B9*F9)+(B10*F10)+(B11*F11) -> 0
B14: ="Renewal Plan: "&'InsHRA-Request'!B11:D11 -> Renewal Plan:
E15: 2500dd/10K
B16: Census | C16: Status | D16: Medical | F16: Total
B17: =B8 -> 0 | C17: Employee | D17: ='InsHRA-Request'!D25 -> 0 | F17: =SUM(D17:E17) -> 0
B18: =B9 -> 0 | C18: 2 Person | D18: ='InsHRA-Request'!D26 -> 0 | F18: =SUM(D18:E18) -> 0
B19: =B10 -> 0 | C19: Emp/Child | D19: ='InsHRA-Request'!D27 -> 0 | F19: =SUM(D19:E19) -> 0
B20: =B11 -> 0 | C20: Family | D20: ='InsHRA-Request'!D28 -> 0 | F20: =SUM(D20:E20) -> 0
B21: =SUM(B17:B20) -> 0 | D21: =(B17*D17)+(B18*D18)+(B20*D20)+(B19*D19) -> 0 | F21: =(B17*F17)+(B18*F18)+(B19*F19)+(B20*F20) -> 0
B23: ="Proposed Plan 1: "&'InsHRA-Request'!B39&" & Insured HRA ($"&'InsHRA-Request'!C69&" deductible / $"&'InsHRA-Request'!C72&" coinsurance)" -> Proposed Plan 1: & Insured HRA ($ deductible / $ coinsurance)
E24: 2500dd/10K
B25: Census | C25: Status | D25: Medical | E25: Insured HRA | F25: Total
B26: =B17 -> 0 | C26: Employee | D26: ='InsHRA-Request'!C53 -> 0 | E26: ='InsHRA-Request'!D75 -> 0 | F26: =SUM(D26:E26) -> 0
B27: =B18 -> 0 | C27: 2 Person | D27: ='InsHRA-Request'!C54 -> 0 | E27: ='InsHRA-Request'!D76 -> 0 | F27: =SUM(D27:E27) -> 0
B28: =B19 -> 0 | C28: Emp/Child | D28: ='InsHRA-Request'!C55 -> 0 | E28: ='InsHRA-Request'!D77 -> 0 | F28: =SUM(D28:E28) -> 0
B29: =B20 -> 0 | C29: Family | D29: ='InsHRA-Request'!C56 -> 0 | E29: ='InsHRA-Request'!D78 -> 0 | F29: =SUM(D29:E29) -> 0
B30: =SUM(B26:B29) -> 0 | D30: =(B26*D26)+(B27*D27)+(B29*D29)+(B28*D28) -> 0 | E30: =(B26*E26)+(B27*E27)+(B29*E29)+(B28*E28) -> 0 | F30: =(B26*F26)+(B27*F27)+(B28*F28)+(B29*F29) -> 0
B32: ="Proposed Plan 2: "&'InsHRA-Request'!B39&" & Insured HRA ($"&'InsHRA-Request'!E69&" deductible / $"&'InsHRA-Request'!E72&" coinsurance)" -> Proposed Plan 2: & Insured HRA ($ deductible / $ coinsurance)
E33: 2500dd/10K
B34: Census | C34: Status | D34: Medical | E34: Insured HRA | F34: Total
B35: =B26 -> 0 | C35: Employee | F35: =SUM(D35:E35) -> 0
B36: =B27 -> 0 | C36: 2 Person | F36: =SUM(D36:E36) -> 0
B37: ='[3]InsHRA-Request'!B33 -> 1 | C37: Emp/Child | F37: =SUM(D37:E37) -> 0
B38: =B29 -> 0 | C38: Family | F38: =SUM(D38:E38) -> 0
B39: =SUM(B35:B38) -> 1 | D39: =(B35*D35)+(B36*D36)+(B38*D38)+(B37*D37) -> 0 | E39: =(B35*E35)+(B36*E36)+(B38*E38)+(B37*E37) -> 0 | F39: =(B35*F35)+(B36*F36)+(B37*F37)+(B38*F38) -> 0
B41: Proposed Plan 1: Annual Savings Versus Renewal Plan | F41: =12*(F21-F30) -> 0
B43: Proposed Plan 2: Annual Savings Versus Renewal Plan | F43: =12*(F21-F39) -> 0

Sheet Example
A2: Premium Saver-Insured HRA-Request for Quote
A3: Employer Name: | B3: ABC Manufacturing | H3: Telephone: | I3: 989-999-999
A4: Employer Address: | B4: 123 Main Street
A5: Employer City: | B5: Anytown | F5: State: | G5: MI | H5: Zip Code: | I5: 49xxx
A6: Nature of business | H6: Effective Date: | I6: 41275
A7: Agent Name: | B7: CIC | H7: Telephone: | I7: 248-464-6544
A8: Email To: | B8: email address@company | E8: Fax to: | F8: 248-464-6543 | H8: Questions: | I8: 248-464-6544
A10: Current Plan(s) | B10: Plan One | E10: Plan Two | H10: Plan Three
A11: Medical Carrier | B11: BCBSM CB 1 | E11: BCBSM CB 4 | H11: BCBSM CB 19
A12: Deductible Amount | B12: 0 | E12: 500 | H12: 1000
A13: Employee Coinsurance | B13: 0 | E13: 0.2 | H13: 0.2
A14: $ Of Coinsurance | B14: 0 | E14: 1500 | H14: 3000
A15: Total Dollars OOP | B15: 0 | E15: 2000 | H15: 4000
A16: Doctor Office | B16: $10 Copay | E16: $20 Copay | H16: $40 Copay
A17: Specialist Office Visit | B17: $10 Copay | E17: $20 Copay | H17: $40 Copay
A18: Chiropractic | B18: $10 Copay | E18: $20 Copay | H18: $40 Copay
A19: Drug Co Pays | B19: Tiered Copay | E19: Tiered Copay | H19: Tiered Copay
A20: Emergency Room Copay | B20: $50 Copay | E20: $100 Copay | H20: $250 Copay
A21: Urgent Care Copay | B21: $10 Copay | E21: $20 Copay | H21: $40 Copay
A22: Drug Deductible Amount | B22: 0 | E22: 0 | H22: 0
A23: Renewal Date | B23: 41275 | E23: 41275 | H23: 41275
B24: # Employee | C24: Current | D24: Renewal | E24: # Employee | F24: Current | G24: Renewal | H24: # Employee | I24: Current | J24: Renewal
A25: Employee | B25: 11 | C25: 650 | D25: 780 | E25: 20 | F25: 400 | G25: 480 | H25: 6 | I25: 350 | J25: 400
A26: Employee and Spouse | B26: 10 | C26: 1300 | D26: 1560 | E26: 10 | F26: 800 | G26: 960 | H26: 5 | I26: 850 | J26: 970
A27: Employee/Child(ren) | B27: 0
A28: Family | B28: 20 | C28: 1950 | D28: 2340 | E28: 35 | F28: 1200 | G28: 1440 | H28: 1 | I28: 1000 | J28: 1180
E37: Special Instructions
A38: Alternate Plan
A39: Medical Carrier | B39: BCBSM CB 15/20
A40: Deductible Amount | B40: 5000
A41: Employee Coins. | C41: 20 | D41: %
A42: $ Of Coinsurance | B42: 2500
A43: Total Dollars OOP | B43: 7500
A44: Doctor Office | B44: $20 Copay
A45: Specialist Office Visit | B45: $20 Copay
A46: Chiropractic | B46: $20 Copay
A47: Drug Co Pays | B47: Tiered | E47: Primary Goal of this Quote is to Save Premium
A48: ER Copay | B48: $100 Copay | E48: Second Goal is to…
A49: Urgent Care Copay | B49: $20 Copay | E49: (Please check one)
A50: Drug Deductible Amt | B50: 0 | F50: Save Premium
...

Sheet 3PlansTiers
B1: Insured HRA Quote for:
B2: ='InsHRA-Request'!B3:J3 -> 0
B4: Current Plans
C5: Status | D5: # | E5: ='InsHRA-Request'!B11 -> 0 | H5: # | I5: ='InsHRA-Request'!E11 -> 0 | J5: # | K5: ='InsHRA-Request'!H11 -> 0 | L5: Total
C6: Employee | D6: ='InsHRA-Request'!B25 -> 0 | E6: ='InsHRA-Request'!C25 -> 0 | H6: ='InsHRA-Request'!E25 -> 0 | I6: ='InsHRA-Request'!F25 -> 0 | J6: ='InsHRA-Request'!H25 -> 0 | K6: ='InsHRA-Request'!I25 -> 0
C7: 2 Person | D7: ='InsHRA-Request'!B26 -> 0 | E7: ='InsHRA-Request'!C26 -> 0 | H7: ='InsHRA-Request'!E26 -> 0 | I7: ='InsHRA-Request'!F26 -> 0 | J7: ='InsHRA-Request'!H26 -> 0 | K7: ='InsHRA-Request'!I26 -> 0
C8: Emp/Child | D8: ='InsHRA-Request'!B27 -> 0 | E8: ='InsHRA-Request'!C27 -> 0 | H8: ='InsHRA-Request'!E27 -> 0 | I8: ='InsHRA-Request'!F27 -> 0 | J8: ='InsHRA-Request'!H27 -> 0 | K8: ='InsHRA-Request'!I27 -> 0
C9: Family | D9: ='InsHRA-Request'!B28 -> 0 | E9: ='InsHRA-Request'!C28 -> 0 | H9: ='InsHRA-Request'!E28 -> 0 | I9: ='InsHRA-Request'!F28 -> 0 | J9: ='InsHRA-Request'!H28 -> 0 | K9: ='InsHRA-Request'!I28 -> 0
D10: =SUM(D6:D9) -> 0 | E10: =(D6*E6)+(D7*E7)+(D9*E9)+(D8*E8) -> 0 | H10: =SUM(H6:H9) -> 0 | I10: =(H6*I6)+(H7*I7)+(H9*I9)+(H8*I8) -> 0 | J10: =SUM(J6:J9) -> 0 | K10: =(J6*K6)+(J7*K7)+(J9*K9)+(J8*K8) -> 0 | L10: =I10+E10+K10 -> 0
B12: Renewal Plans
C13: Status | D13: # | E13: =E5 -> 0 | H13: # | I13: ='InsHRA-Request'!E11 -> 0 | J13: # | K13: =K5 -> 0 | L13: Total
C14: Employee | D14: =D6 -> 0 | E14: ='InsHRA-Request'!D25 -> 0 | H14: =H6 -> 0 | I14: ='InsHRA-Request'!G25 -> 0 | J14: ='InsHRA-Request'!H25 -> 0 | K14: ='InsHRA-Request'!J25 -> 0
C15: 2 Person | D15: =D7 -> 0 | E15: ='InsHRA-Request'!D26 -> 0 | H15: =H7 -> 0 | I15: ='InsHRA-Request'!G26 -> 0 | J15: ='InsHRA-Request'!H26 -> 0 | K15: ='InsHRA-Request'!J26 -> 0
C16: Emp/Child | D16: =D8 -> 0 | E16: ='InsHRA-Request'!D27 -> 0 | H16: =H8 -> 0 | I16: ='InsHRA-Request'!G27 -> 0 | J16: ='InsHRA-Request'!H27 -> 0 | K16: ='InsHRA-Request'!J27 -> 0
C17: Family | D17: =D9 -> 0 | E17: ='InsHRA-Request'!D28 -> 0 | H17: =H9 -> 0 | I17: ='InsHRA-Request'!G28 -> 0 | J17: ='InsHRA-Request'!H28 -> 0 | K17: ='InsHRA-Request'!J28 -> 0
D18: =SUM(D14:D17) -> 0 | E18: =(D14*E14)+(D15*E15)+(D17*E17)+(D16*E16) -> 0 | H18: =SUM(H14:H17) -> 0 | I18: =(H14*I14)+(H15*I15)+(H17*I17)+(H16*I16) -> 0 | J18: =SUM(J14:J17) -> 0 | K18: =(J14*K14)+(J15*K15)+(J17*K17)+(J16*K16) -> 0 | L18: =I18+E18+K18 -> 0
B19: Proposed Plan 1: Annual Savings Versus Renewal PH HMO
C20: Status | D20: Census | E20: Medical | G20: Insured HRA 250 Ded 80% to $750 | L20: Total
C21: Employee | E21: 247.46 | G21: 137.81 | I21: =[1]TransRates!$W$29 | L21: =SUM(E21:I21) -> 385.27
C22: 2 Person | E22: 593.89 | G22: 263.48 | I22: =[1]TransRates!$W$30 | L22: =SUM(E22:I22) -> 857.37
C23: Emp/Child | E23: =[1]Census!O17 -> 0 | G23: 0 | I23: =[1]TransRates!$W$31 | L23: =SUM(E23:I23) -> 0
C24: Family | E24: 742.37 | G24: 373.27 | I24: =[1]TransRates!$W$32 | L24: =SUM(E24:I24) -> 1115.64
B25: =SUM(B21:B24) -> 0
B27: ="Proposed Plan 1: Move "&E5&" Employees to:" -> Proposed Plan 1: Move 0 Employees to:
B28: ="Proposed Plan 1: "&'InsHRA-Request'!B39&" & Insured HRA ($"&'InsHRA-Request'!C69&" deductible / $"&'InsHRA-Request'!C72&" coinsurance)" -> Proposed Plan 1: & Insured HRA ($ deductible / $ coinsurance)
G29: 4Kdd/10K
C30: Status | D30: # | E30: ='InsHRA-Request'!B39 -> 0 | H30: Insured HRA | L30: Total
B31: 12 | C31: Employee | D31: =D6 -> 0 | E31: ='InsHRA-Request'!C53 -> 0 | H31: ='InsHRA-Request'!D75 -> 0 | L31: =H31+E31 -> 0
B32: 0 | C32: 2 Person | D32: =D7 -> 0 | E32: ='InsHRA-Request'!C54 -> 0 | H32: ='InsHRA-Request'!D76 -> 0 | L32: =H32+E32 -> 0
C33: Emp/Child | D33: =D8 -> 0 | E33: ='InsHRA-Request'!C55 -> 0 | H33: ='InsHRA-Request'!D77 -> 0 | L33: =H33+E33 -> 0
B34: 1 | C34: Family | D34: =D9 -> 0 | E34: ='InsHRA-Request'!C56 -> 0 | H34: ='InsHRA-Request'!D78 -> 0 | L34: =H34+E34 -> 0
B35: =SUM(B31:B34) -> 13 | D35: =SUM(D31:D34) -> 0 | E35: =(D31*E31)+(D32*E32)+(D34*E34)+(D33*E33) -> 0 | H35: =(D31*H31)+(D32*H32)+(D34*H34)+(D33*H33) -> 0 | L35: =(D31*L31)+(D32*L32)+(D34*L34)+(D33*L33) -> 0
B37: ="Proposed Plan 2: Move "&I5&" Employees to:" -> Proposed Plan 2: Move 0 Employees to:
B38: ="Proposed Plan 2: "&'InsHRA-Request'!B39&" & Insured HRA ($"&'InsHRA-Request'!E69&" deductible / $"&'InsHRA-Request'!E72&" coinsurance)" -> Proposed Plan 2: & Insured HRA ($ deductible / $ coinsurance)
C39: Status | D39: # | E39: =E30 -> 0 | H39: =H30 -> Insured HRA | L39: Total
B40: 28 | C40: Employee | D40: =H6 -> 0 | E40: ='InsHRA-Request'!C53 -> 0 | H40: ='InsHRA-Request'!F75 -> 0 | L40: =H40+E40 -> 0
B41: 10 | C41: 2 Person | D41: =H7 -> 0 | E41: ='InsHRA-Request'!C54 -> 0 | H41: ='InsHRA-Request'!F76 -> 0 | L41: =H41+E41 -> 0
C42: Emp/Child | D42: =H8 -> 0 | E42: ='InsHRA-Request'!C55 -> 0 | H42: ='InsHRA-Request'!F77 -> 0 | L42: =H42+E42 -> 0
B43: 30 | C43: Family | D43: =H9 -> 0 | E43: ='InsHRA-Request'!C56 -> 0 | H43: ='InsHRA-Request'!F78 -> 0 | L43: =H43+E43 -> 0
B44: =SUM(B40:B43) -> 68 | D44: =SUM(D40:D43) -> 0 | E44: =(D40*E40)+(D41*E41)+(D43*E43)+(D42*E42) -> 0 | H44: =(D40*H40)+(D41*H41)+(D43*H43)+(D42*H42) -> 0 | L44: =(D40*L40)+(D41*L41)+(D43*L43)+(D42*L42) -> 0
...

Sheet BAAG
C3: YOUR BENEFITS AT A GLANCE
C4: ='InsHRA-Request'!B3 -> 0
C6: Effective Date:
C7: ='InsHRA-Request'!I6 -> 0
D8: ='InsHRA-Request'!B11 -> 0 | E8: ='InsHRA-Request'!E11 -> 0 | F8: ='InsHRA-Request'!H11 -> 0 | G8: ='InsHRA-Request'!B39&" & Insured HRA to $"&'InsHRA-Request'!C69&"/"&IF('InsHRA-Request'!C71=0,"100%",100-'InsHRA-Request'!C71&"%") -> & Insured HRA to $/100% | H8: ='InsHRA-Request'!B39&" & Insured HRA to $"&'InsHRA-Request'!E69&"/"&IF('InsHRA-Request'!#REF!=0,"100%",100-'InsHRA-Request'!#REF!&"%") -> #REF! | I8: ='InsHRA-Request'!B39&" & Insured HRA to $"&'InsHRA-Request'!G69&"/"&IF('InsHRA-Request'!#REF!=0,"100%",100-'InsHRA-Request'!#REF!&"%") -> #REF!
C9: Office Visits
C10: Primary | D10: ='InsHRA-Request'!B16 -> 0 | E10: ='InsHRA-Request'!E16 -> 0 | F10: ='InsHRA-Request'!H16 -> 0 | G10: ='InsHRA-Request'!B44 -> 0 | H10: ='InsHRA-Request'!B44 -> 0 | I10: ='InsHRA-Request'!B44 -> 0
C11: Specialist | D11: ='InsHRA-Request'!B17 -> 0 | E11: ='InsHRA-Request'!E17 -> 0 | F11: ='InsHRA-Request'!H17 -> 0 | G11: ='InsHRA-Request'!B45 -> 0 | H11: ='InsHRA-Request'!B45 -> 0 | I11: ='InsHRA-Request'!B45 -> 0
C12: Chiropractic | D12: ='InsHRA-Request'!B18 -> 0 | E12: ='InsHRA-Request'!E18 -> 0 | F12: ='InsHRA-Request'!H18 -> 0 | G12: ='InsHRA-Request'!B46 -> 0 | H12: ='InsHRA-Request'!B46 -> 0 | I12: ='InsHRA-Request'!B46 -> 0
C13: X-Ray | D13: =100-'InsHRA-Request'!B13&"% After Deductible" -> 100% After Deductible | E13: =100-'InsHRA-Request'!E13&"% After Deductible" -> 100% After Deductible | F13: =100-'InsHRA-Request'!H13&"% After Deductible" -> 100% After Deductible | G13: =100-'InsHRA-Request'!C71&"% after deductible" -> 100% after deductible | H13: =100-'InsHRA-Request'!#REF!&"% After Deductible" -> #REF! | I13: =100-'InsHRA-Request'!#REF!&"% After Deductible" -> #REF!
C14: Blood/Lab Tests | D14: =D13 -> 100% After Deductible | E14: =E13 -> 100% After Deductible | F14: =F13 -> 100% After Deductible | G14: =G13 -> 100% after deductible | H14: =H13 -> #REF! | I14: =I13 -> #REF!
C16: Hospital - In & Out-Patient Services
C17: Deductible per Calendar year | D17: ="$"&'InsHRA-Request'!B12&" Per Person" -> $ Per Person | E17: ="$"&'InsHRA-Request'!E12&" Per Person" -> $ Per Person | F17: ="$"&'InsHRA-Request'!H12&" Per Person" -> $ Per Person | G17: ="$"&'InsHRA-Request'!B40&" per person. Employee pays a $"&'InsHRA-Request'!C69&" deductible per person"&IF('InsHRA-Request'!C71=0,". Insured HRA covers remaining deductible & coinsurance"," and $"&'InsHRA-Request'!C72&" coinsurance, then Insured HRA Covers remaining deductible & coinsurance") -> $ per person. Employee pays a $ deductible per person. Insured HRA covers remaining deductible & coinsurance | H17: ="$"&'InsHRA-Request'!B40&" per person. Employee pays a $"&'InsHRA-Request'!E69&" deductible per person"&IF('InsHRA-Request'!#REF!=0,". Insured HRA covers remaining deductible & coinsurance"," and $"&'InsHRA-Request'!E72&" coinsurance, then Insured HRA Covers remaining deductible & coinsurance") -> #REF! | I17: ="$"&'InsHRA-Request'!B40&" per person. Employee pays a $"&'InsHRA-Request'!G69&" deductible per person"&IF('InsHRA-Request'!#REF!=0,". Insured HRA covers remaining deductible & coinsurance"," and $"&'InsHRA-Request'!G72&" coinsurance, then Insured HRA Covers remaining deductible & coinsurance") -> #REF!
C18: In Patient Services | D18: =D13 -> 100% After Deductible | E18: =E20 -> 100% After Deductible | F18: =F20 -> 100% After Deductible | G18: =G13 -> 100% after deductible | H18: =H13 -> #REF! | I18: =I13 -> #REF!
C19: Out Patient Services | D19: =D18 -> 100% After Deductible | E19: =E13 -> 100% After Deductible | F19: =F13 -> 100% After Deductible | G19: =G13 -> 100% after deductible | H19: =H13 -> #REF! | I19: =I13 -> #REF!
C20: MRI's/CT/PET Scans | D20: =D19 -> 100% After Deductible | E20: =E19 -> 100% After Deductible | F20: =F19 -> 100% After Deductible | G20: =G13 -> 100% after deductible | H20: =H13 -> #REF! | I20: =I13 -> #REF!
C21: Emergency Room | D21: ='InsHRA-Request'!B20 -> 0 | E21: ='InsHRA-Request'!E20 -> 0 | F21: ='InsHRA-Request'!H20 -> 0 | G21: ='InsHRA-Request'!B48 -> 0 | H21: ='InsHRA-Request'!B48 -> 0 | I21: ='InsHRA-Request'!B48 -> 0
C22: Urgent Care | D22: ='InsHRA-Request'!B21 -> 0 | E22: ='InsHRA-Request'!E21 -> 0 | F22: ='InsHRA-Request'!H21 -> 0 | G22: ='InsHRA-Request'!B49 -> 0 | H22: ='InsHRA-Request'!B49 -> 0 | I22: ='InsHRA-Request'!B49 -> 0
C23: Out of Pocket: | D23: ="$"&'InsHRA-Request'!B15&" Per Person" -> $ Per Person | E23: ="$"&'InsHRA-Request'!E15&" Per Person" -> $ Per Person | F23: ="$"&'InsHRA-Request'!H15 & " Per Person" -> $ Per Person | G23: ="$"&'InsHRA-Request'!C69+'InsHRA-Request'!C72&" Per Person" -> $0 Per Person | H23: ="$"&'InsHRA-Request'!E69+'InsHRA-Request'!E72&" Per Person" -> $0 Per Person | I23: ="$"&'InsHRA-Request'!G69+'InsHRA-Request'!G72&" Per Person" -> $0 Per Person
C24: Deductibles are capped at two per family
C25: Prescription Drugs | D25: =E25 -> Covered - Tiered Copays | E25: Covered - Tiered Copays | F25: Covered - Tiered Copays | G25: Covered - Tiered Copays | H25: Covered - Tiered Copays | I25: Covered - Tiered Copays
