Workbook

Sheet Rammeplan
A1: TRENINGSDAGBOK-HOVDEN SKIGYMNAS, 2012-2013: | M1: Vg2-Vg3
A3: Uker: | B3: 16-48
B5: Skidager | H5: 2 | I5: 1 | K5: 2 | L5: 6 | S5: 6 | W5: 4 | Z5: 5 | AA5: 6 | AC5: 5 | AD5: 4 | AF5: 5 | AG5: 7 | AH5: 3 | AJ5: =SUM(C5:AI5) -> 56
A6: Kvalitet | B6: Form | C6: 16 | D6: 17 | E6: 18 | F6: 19 | G6: 20 | H6: 21 | I6: 22 | J6: 23 | K6: 24 | L6: 25 | M6: 26 | N6: 27 | O6: 28 | P6: 29 | Q6: 30 | R6: 31 | S6: 32 | T6: 33 | U6: 34 | V6: 35 | X6: 37 | Y6: 38 | Z6: 39 | AA6: 40 | AB6: 41 | AC6: 42 | AD6: 43 | AE6: 44 | AF6: 45 | AG6: 46 | AH6: 47 | AI6: 48 | AJ6: SUM
A7: Aerob | B7: Kontinuerli | C7: 120 | D7: 120 | E7: 120 | F7: 240 | G7: 240 | H7: 240 | I7: 120 | J7: 240 | K7: 120 | L7: 120 | M7: 120 | N7: 120 | O7: 240 | P7: 240 | Q7: 240 | R7: 120 | S7: 120 | T7: 120 | U7: 120 | V7: 120 | W7: 120 | X7: 120 | Y7: 60 | Z7: 60 | AA7: 120 | AB7: 120 | AC7: 120 | AD7: 120 | AE7: 120 | AF7: 120 | AG7: 120 | AH7: 120 | AI7: 120 | AJ7: =SUM(C7:AI7) -> 4680
B8: Intervall | N8: 30 | P8: 30 | Q8: 30 | U8: 30 | X8: 30 | Y8: 60 | Z8: 60 | AC8: 20 | AD8: 20 | AJ8: =SUM(C8:AI8) -> 310
A9: Anaerob | B9: Lokalt | U9: 20 | Y9: 20 | AE9: 20 | AJ9: =SUM(C9:AI9) -> 60
B10: Generell | H10: 30 | M10: 60 | Y10: 20 | AE10: 20 | AJ10: =SUM(C10:AI10) -> 130
A11: Maks.styrke | B11: Sub.maks. | C11: 60 | D11: 120 | E11: 120 | F11: 120 | G11: 180 | H11: 180 | I11: 120 | J11: 180 | N11: 120 | O11: 120 | P11: 120 | Q11: 120 | R11: 120 | T11: 120 | U11: 120 | V11: 120 | W11: 120 | X11: 120 | Y11: 120 | AB11: 60 | AC11: 120 | AD11: 120 | AE11: 120 | AF11: 60 | AG11: 60 | AH11: 60 | AI11: 60 | AJ11: =SUM(C11:AI11) -> 3060
B12: Tungt | P12: 60 | Q12: 60 | R12: 60 | U12: 60 | V12: 60 | W12: 60 | X12: 60 | Y12: 60 | Z12: 60 | AE12: 60 | AJ12: =SUM(C12:AI12) -> 600
B13: Eksplosivt | Y13: 30 | Z13: 30 | AE13: 30 | AF13: 30 | AG13: 30 | AH13: 30 | AI13: 30 | AJ13: =SUM(C13:AI13) -> 210
A14: Uth.styrke | B14: Sirkel | C14: 120 | D14: 120 | E14: 120 | F14: 120 | G14: 120 | H14: 120 | I14: 90 | J14: 120 | K14: 90 | L14: 120 | M14: 120 | N14: 120 | O14: 120 | P14: 120 | Q14: 120 | R14: 120 | S14: 120 | T14: 120 | U14: 120 | V14: 90 | W14: 120 | X14: 120 | Y14: 120 | Z14: 120 | AA14: 60 | AB14: 60 | AC14: 60 | AD14: 60 | AE14: 60 | AF14: 120 | AG14: 120 | AH14: 120 | AI14: 60 | AJ14: =SUM(C14:AI14) -> 3510
B15: Tungt | C15: 90 | D15: 90 | E15: 90 | F15: 90 | G15: 90 | H15: 90 | I15: 60 | J15: 90 | N15: 120 | O15: 120 | P15: 120 | Q15: 120 | R15: 120 | T15: 120 | U15: 120 | V15: 90 | W15: 120 | X15: 120 | Y15: 120 | AB15: 60 | AC15: 60 | AD15: 60 | AE15: 120 | AI15: 60 | AJ15: =SUM(C15:AI15) -> 2340
A16: Spenst | E16: 20 | I16: 20 | J16: 40 | K16: 20 | L16: 20 | O16: 20 | P16: 40 | Q16: 40 | R16: 40 | U16: 20 | V16: 40 | Y16: 20 | Z16: 40 | AB16: 20 | AC16: 20 | AD16: 20 | AE16: 60 | AF16: 20 | AG16: 20 | AH16: 20 | AI16: 40 | AJ16: =SUM(C16:AI16) -> 600
A17: Hurtighet | E17: 20 | I17: 20 | J17: 40 | K17: 20 | L17: 20 | O17: 20 | P17: 40 | Q17: 40 | R17: 40 | U17: 20 | V17: 40 | Y17: 20 | Z17: 40 | AB17: 20 | AC17: 20 | AD17: 20 | AE17: 60 | AF17: 20 | AG17: 20 | AH17: 20 | AI17: 40 | AJ17: =SUM(C17:AI17) -> 600
A18: Koordinasjon | D18: 120 | E18: 120 | F18: 120 | G18: 120 | H18: 120 | I18: 60 | J18: 120 | K18: 60 | N18: 120 | O18: 120 | P18: 120 | Q18: 120 | R18: 120 | U18: 60 | V18: 60 | W18: 120 | X18: 120 | Y18: 60 | AB18: 60 | AC18: 60 | AD18: 60 | AE18: 60 | AJ18: =SUM(C18:AI18) -> 2100
A19: Bevegelighet | C19: 30 | D19: 30 | E19: 30 | F19: 30 | G19: 30 | H19: 30 | I19: 30 | J19: 30 | K19: 30 | L19: 30 | M19: 30 | N19: 30 | O19: 30 | P19: 30 | Q19: 30 | R19: 30 | S19: 30 | T19: 30 | U19: 30 | V19: 30 | W19: 30 | X19: 30 | Y19: 30 | Z19: 30 | AA19: 30 | AB19: 30 | AC19: 30 | AD19: 30 | AE19: 30 | AF19: 30 | AG19: 30 | AH19: 30 | AI19: 30 | AJ19: =SUM(C19:AI19) -> 990
A20: Rekreasjon | C20: 60 | D20: 60 | E20: 60 | F20: 60 | G20: 60 | H20: 60 | I20: 60 | J20: 60 | K20: 60 | L20: 60 | M20: 60 | N20: 120 | O20: 120 | P20: 120 | Q20: 120 | R20: 120 | S20: 60 | T20: 60 | U20: 120 | V20: 120 | W20: 60 | X20: 60 | Y20: 120 | Z20: 120 | AA20: 60 | AB20: 60 | AC20: 60 | AD20: 120 | AE20: 120 | AF20: 60 | AG20: 60 | AH20: 60 | AI20: 60 | AJ20: =SUM(C20:AI20) -> 2640
B21: Sum | C21: =SUM(C7:C20) -> 480 | D21: =SUM(D7:D20) -> 660 | E21: =SUM(E7:E20) -> 700 | F21: =SUM(F7:F20) -> 780 | G21: =SUM(G7:G20) -> 840 | H21: =SUM(H7:H20) -> 870 | I21: =SUM(I7:I20) -> 580 | J21: =SUM(J7:J20) -> 920 | ... AJ21: =SUM(AJ7:AJ20) -> 21830
B22: Tester
B23: Barm:
E24: Utholdenhet | L24: Alt.trening | S24: Test | AA24: Utholdenhet(vedl.) | AF24: Vedlikehold
E25: Grunnstyrke | L25: Utholdenhet (int) | S25: Koordinasjon | AA25: Maks.vedlikehold | AF25: Rennforberedende
E26: Test | L26: Maks.styrke | S26: Utholdenhet(vedl.) | AA26: Hurtighet/spenst
E27: Medisinsk sjekk | L27: Hurtighet/spenst | S27: Maks.styrke
S28: Hurtighet/spenst (vedl.)

Sheet 16
A1: =Rammeplan!A1 -> TRENINGSDAGBOK-HOVDEN SKIGYMNAS, 2012-2013:
A3: Uke: | B3: 16 | G3: Navn:
C5: Mandag | E5: Tirsdag | G5: Onsdag | I5: Torsdag | K5: Fredag | M5: Lørdag | O5: Søndag | Q5: Sum
A6: Kvalitet | B6: Form | C6: Plan | D6: ok | E6: Plan | F6: ok | G6: Plan | H6: ok | I6: Plan | J6: ok | K6: Plan | L6: ok | M6: Plan | N6: ok | O6: Plan | P6: ok | Q6: Plan | R6: Trent | S6: Diff. | T6: Feedback
A7: Aerob | B7: Kontinuerlig | Q7: =Rammeplan!C7 -> 120 | R7: =(C7*D7)+(E7*F7)+(G7*H7)+(I7*J7)+(K7*L7)+(M7*N7)+(O7*P7) -> 0 | S7: =R7-Q7 -> -120
B8: Intervall | Q8: =Rammeplan!C8 -> 0 | R8: =(C8*D8)+(E8*F8)+(G8*H8)+(I8*J8)+(K8*L8)+(M8*N8)+(O8*P8) -> 0 | S8: =R8-Q8 -> 0
A9: Anaerob | B9: Lokalt | Q9: =Rammeplan!C9 -> 0 | R9: =(C9*D9)+(E9*F9)+(G9*H9)+(I9*J9)+(K9*L9)+(M9*N9)+(O9*P9) -> 0 | S9: =R9-Q9 -> 0
B10: Generell | Q10: =Rammeplan!C10 -> 0 | R10: =(C10*D10)+(E10*F10)+(G10*H10)+(I10*J10)+(K10*L10)+(M10*N10)+(O10*P10) -> 0 | S10: =R10-Q10 -> 0
A11: Maks.styrke | B11: Sub.maks. | Q11: =Rammeplan!C11 -> 60 | R11: =(C11*D11)+(E11*F11)+(G11*H11)+(I11*J11)+(K11*L11)+(M11*N11)+(O11*P11) -> 0 | S11: =R11-Q11 -> -60
B12: Tungt | Q12: =Rammeplan!C12 -> 0 | R12: =(C12*D12)+(E12*F12)+(G12*H12)+(I12*J12)+(K12*L12)+(M12*N12)+(O12*P12) -> 0 | S12: =R12-Q12 -> 0
B13: Eksplosivt | Q13: =Rammeplan!C13 -> 0 | R13: =(C13*D13)+(E13*F13)+(G13*H13)+(I13*J13)+(K13*L13)+(M13*N13)+(O13*P13) -> 0 | S13: =R13-Q13 -> 0
A14: Uth.styrke | B14: Sirkel | Q14: =Rammeplan!C14 -> 120 | R14: =(C14*D14)+(E14*F14)+(G14*H14)+(I14*J14)+(K14*L14)+(M14*N14)+(O14*P14) -> 0 | S14: =R14-Q14 -> -120
B15: Tungt | Q15: =Rammeplan!C15 -> 90 | R15: =(C15*D15)+(E15*F15)+(G15*H15)+(I15*J15)+(K15*L15)+(M15*N15)+(O15*P15) -> 0 | S15: =R15-Q15 -> -90
A16: Spenst | Q16: =Rammeplan!C16 -> 0 | R16: =(C16*D16)+(E16*F16)+(G16*H16)+(I16*J16)+(K16*L16)+(M16*N16)+(O16*P16) -> 0 | S16: =R16-Q16 -> 0
A17: Hurtighet | Q17: =Rammeplan!C17 -> 0 | R17: =(C17*D17)+(E17*F17)+(G17*H17)+(I17*J17)+(K17*L17)+(M17*N17)+(O17*P17) -> 0 | S17: =R17-Q17 -> 0
A18: Koordinasjon | Q18: =Rammeplan!C18 -> 0 | R18: =(C18*D18)+(E18*F18)+(G18*H18)+(I18*J18)+(K18*L18)+(M18*N18)+(O18*P18) -> 0 | S18: =R18-Q18 -> 0
A19: Bevegelighet | Q19: =Rammeplan!C19 -> 30 | R19: =(C19*D19)+(E19*F19)+(G19*H19)+(I19*J19)+(K19*L19)+(M19*N19)+(O19*P19) -> 0 | S19: =R19-Q19 -> -30
A20: Rekreasjon | Q20: =Rammeplan!C20 -> 60 | R20: =(C20*D20)+(E20*F20)+(G20*H20)+(I20*J20)+(K20*L20)+(M20*N20)+(O20*P20) -> 0 | S20: =R20-Q20 -> -60
B21: Sum | C21: =SUM(C7:C20) -> 0 | E21: =SUM(E7:E20) -> 0 | G21: =SUM(G7:G20) -> 0 | I21: =SUM(I7:I20) -> 0 | K21: =SUM(K7:K20) -> 0 | M21: =SUM(M7:M20) -> 0 | O21: =SUM(O7:O20) -> 0 | Q21: =SUM(Q7:Q20) -> 480 | R21: =SUM(R7:R20) -> 0 | S21: =R21-Q21 -> -480
A30: AKKUMULERT
A32: Kvalitet | B32: Form | C32: Plan | E32: Trent
A33: Aerob | B33: Kontinuerlig | C33: =Rammeplan!C7 -> 120 | E33: =R7 -> 0
B34: Intervall | C34: =Rammeplan!C8 -> 0 | E34: =R8 -> 0
A35: Anaerob | B35: Lokalt | C35: =Rammeplan!C9 -> 0 | E35: =R9 -> 0
B36: Generell | C36: =Rammeplan!C10 -> 0 | E36: =R10 -> 0
A37: Maks.styrke | B37: Sub.maks. | C37: =Rammeplan!C11 -> 60 | E37: =R11 -> 0
B38: Tungt | C38: =Rammeplan!C12 -> 0 | E38: =R12 -> 0
B39: Eksplosivt | C39: =Rammeplan!C13 -> 0 | E39: =R13 -> 0
A40: Uth.styrke | B40: Sirkel | C40: =Rammeplan!C14 -> 120 | E40: =R14 -> 0
B41: Tungt | C41: =Rammeplan!C15 -> 90 | E41: =R15 -> 0
A42: Spenst | C42: =Rammeplan!C16 -> 0 | E42: =R16 -> 0
A43: Hurtighet | C43: =Rammeplan!C17 -> 0 | E43: =R17 -> 0
A44: Koordinasjon | C44: =Rammeplan!C18 -> 0 | E44: =R18 -> 0
A45: Bevegelighet | C45: =Rammeplan!C19 -> 30 | E45: =R19 -> 0
A46: Rekreasjon | C46: =Rammeplan!C20 -> 60 | E46: =R20 -> 0
B47: Sum | C47: =SUM(C33:C46) -> 480 | E47: =R21 -> 0

Sheet 17
A1: =Rammeplan!A1 -> TRENINGSDAGBOK-HOVDEN SKIGYMNAS, 2012-2013:
A3: Uke: | B3: 17 | G3: Navn: | H3: ='16'!H3 -> 0
C5: Mandag | E5: Tirsdag | G5: Onsdag | I5: Torsdag | K5: Fredag | M5: Lørdag | O5: Søndag | Q5: Sum
A6: Kvalitet | B6: Form | C6: Plan | D6: ok | E6: Plan | F6: ok | G6: Plan | H6: ok | I6: Plan | J6: ok | K6: Plan | L6: ok | M6: Plan | N6: ok | O6: Plan | P6: ok | Q6: Plan | R6: Trent | S6: Diff. | T6: Feedback
A7: Aerob | B7: Kontinuerlig | Q7: =Rammeplan!D7 -> 120 | R7: =(C7*D7)+(E7*F7)+(G7*H7)+(I7*J7)+(K7*L7)+(M7*N7)+(O7*P7) -> 0 | S7: =R7-Q7 -> -120
B8: Intervall | Q8: =Rammeplan!D8 -> 0 | R8: =(C8*D8)+(E8*F8)+(G8*H8)+(I8*J8)+(K8*L8)+(M8*N8)+(O8*P8) -> 0 | S8: =R8-Q8 -> 0
A9: Anaerob | B9: Lokalt | Q9: =Rammeplan!D9 -> 0 | R9: =(C9*D9)+(E9*F9)+(G9*H9)+(I9*J9)+(K9*L9)+(M9*N9)+(O9*P9) -> 0 | S9: =R9-Q9 -> 0
B10: Generell | Q10: =Rammeplan!D10 -> 0 | R10: =(C10*D10)+(E10*F10)+(G10*H10)+(I10*J10)+(K10*L10)+(M10*N10)+(O10*P10) -> 0 | S10: =R10-Q10 -> 0
A11: Maks.styrke | B11: Sub.maks. | Q11: =Rammeplan!D11 -> 120 | R11: =(C11*D11)+(E11*F11)+(G11*H11)+(I11*J11)+(K11*L11)+(M11*N11)+(O11*P11) -> 0 | S11: =R11-Q11 -> -120
B12: Tungt | Q12: =Rammeplan!D12 -> 0 | R12: =(C12*D12)+(E12*F12)+(G12*H12)+(I12*J12)+(K12*L12)+(M12*N12)+(O12*P12) -> 0 | S12: =R12-Q12 -> 0
B13: Eksplosivt | Q13: =Rammeplan!D13 -> 0 | R13: =(C13*D13)+(E13*F13)+(G13*H13)+(I13*J13)+(K13*L13)+(M13*N13)+(O13*P13) -> 0 | S13: =R13-Q13 -> 0
A14: Uth.styrke | B14: Sirkel | Q14: =Rammeplan!D14 -> 120 | R14: =(C14*D14)+(E14*F14)+(G14*H14)+(I14*J14)+(K14*L14)+(M14*N14)+(O14*P14) -> 0 | S14: =R14-Q14 -> -120
B15: Tungt | Q15: =Rammeplan!D15 -> 90 | R15: =(C15*D15)+(E15*F15)+(G15*H15)+(I15*J15)+(K15*L15)+(M15*N15)+(O15*P15) -> 0 | S15: =R15-Q15 -> -90
A16: Spenst | Q16: =Rammeplan!D16 -> 0 | R16: =(C16*D16)+(E16*F16)+(G16*H16)+(I16*J16)+(K16*L16)+(M16*N16)+(O16*P16) -> 0 | S16: =R16-Q16 -> 0
A17: Hurtighet | Q17: =Rammeplan!D17 -> 0 | R17: =(C17*D17)+(E17*F17)+(G17*H17)+(I17*J17)+(K17*L17)+(M17*N17)+(O17*P17) -> 0 | S17: =R17-Q17 -> 0
A18: Koordinasjon | Q18: =Rammeplan!D18 -> 120 | R18: =(C18*D18)+(E18*F18)+(G18*H18)+(I18*J18)+(K18*L18)+(M18*N18)+(O18*P18) -> 0 | S18: =R18-Q18 -> -120
A19: Bevegelighet | Q19: =Rammeplan!D19 -> 30 | R19: =(C19*D19)+(E19*F19)+(G19*H19)+(I19*J19)+(K19*L19)+(M19*N19)+(O19*P19) -> 0 | S19: =R19-Q19 -> -30
A20: Rekreasjon | Q20: =Rammeplan!D20 -> 60 | R20: =(C20*D20)+(E20*F20)+(G20*H20)+(I20*J20)+(K20*L20)+(M20*N20)+(O20*P20) -> 0 | S20: =R20-Q20 -> -60
B21: Sum | C21: =SUM(C7:C20) -> 0 | E21: =SUM(E7:E20) -> 0 | G21: =SUM(G7:G20) -> 0 | I21: =SUM(I7:I20) -> 0 | K21: =SUM(K7:K20) -> 0 | M21: =SUM(M7:M20) -> 0 | O21: =SUM(O7:O20) -> 0 | Q21: =SUM(Q7:Q20) -> 660 | R21: =SUM(R7:R20) -> 0 | S21: =R21-Q21 -> -660
A30: AKKUMULERT
A32: Kvalitet | B32: Form | C32: Plan | E32: Trent
A33: Aerob | B33: Kontinuerlig | C33: ='16'!C33+'17'!Q7 -> 240 | E33: =R7 -> 0
B34: Intervall | C34: ='16'!C34+'17'!Q8 -> 0 | E34: =R8 -> 0
A35: Anaerob | B35: Lokalt | C35: ='16'!C35+'17'!Q9 -> 0 | E35: =R9 -> 0
B36: Generell | C36: ='16'!C36+'17'!Q10 -> 0 | E36: =R10 -> 0
A37: Maks.styrke | B37: Sub.maks. | C37: ='16'!C37+'17'!Q11 -> 180 | E37: =R11 -> 0
B38: Tungt | C38: ='16'!C38+'17'!Q12 -> 0 | E38: =R12 -> 0
B39: Eksplosivt | C39: ='16'!C39+'17'!Q13 -> 0 | E39: =R13 -> 0
A40: Uth.styrke | B40: Sirkel | C40: ='16'!C40+'17'!Q14 -> 240 | E40: =R14 -> 0
B41: Tungt | C41: ='16'!C41+'17'!Q15 -> 180 | E41: =R15 -> 0
A42: Spenst | C42: ='16'!C42+'17'!Q16 -> 0 | E42: =R16 -> 0
A43: Hurtighet | C43: ='16'!C43+'17'!Q17 -> 0 | E43: =R17 -> 0
A44: Koordinasjon | C44: ='16'!C44+'17'!Q18 -> 120 | E44: =R18 -> 0
A45: Bevegelighet | C45: ='16'!C45+'17'!Q19 -> 60 | E45: =R19 -> 0
A46: Rekreasjon | C46: ='16'!C46+'17'!Q20 -> 120 | E46: =R20 -> 0
B47: Sum | C47: =SUM(C33:C46) -> 1140 | E47: =R21 -> 0

Sheet 18
A1: =Rammeplan!A1 -> TRENINGSDAGBOK-HOVDEN SKIGYMNAS, 2012-2013:
A3: Uke: | B3: 18 | G3: Navn: | H3: ='16'!H3 -> 0
C5: Mandag | E5: Tirsdag | G5: Onsdag | I5: Torsdag | K5: Fredag | M5: Lørdag | O5: Søndag | Q5: Sum
A6: Kvalitet | B6: Form | C6: Plan | D6: ok | E6: Plan | F6: ok | G6: Plan | H6: ok | I6: Plan | J6: ok | K6: Plan | L6: ok | M6: Plan | N6: ok | O6: Plan | P6: ok | Q6: Plan | R6: Trent | S6: Diff. | T6: Feedback
A7: Aerob | B7: Kontinuerlig | Q7: =Rammeplan!E7 -> 120 | R7: =(C7*D7)+(E7*F7)+(G7*H7)+(I7*J7)+(K7*L7)+(M7*N7)+(O7*P7) -> 0 | S7: =R7-Q7 -> -120
B8: Intervall | Q8: =Rammeplan!E8 -> 0 | R8: =(C8*D8)+(E8*F8)+(G8*H8)+(I8*J8)+(K8*L8)+(M8*N8)+(O8*P8) -> 0 | S8: =R8-Q8 -> 0
A9: Anaerob | B9: Lokalt | Q9: =Rammeplan!E9 -> 0 | R9: =(C9*D9)+(E9*F9)+(G9*H9)+(I9*J9)+(K9*L9)+(M9*N9)+(O9*P9) -> 0 | S9: =R9-Q9 -> 0
B10: Generell | Q10: =Rammeplan!E10 -> 0 | R10: =(C10*D10)+(E10*F10)+(G10*H10)+(I10*J10)+(K10*L10)+(M10*N10)+(O10*P10) -> 0 | S10: =R10-Q10 -> 0
A11: Maks.styrke | B11: Sub.maks. | Q11: =Rammeplan!E11 -> 120 | R11: =(C11*D11)+(E11*F11)+(G11*H11)+(I11*J11)+(K11*L11)+(M11*N11)+(O11*P11) -> 0 | S11: =R11-Q11 -> -120
B12: Tungt | Q12: =Rammeplan!E12 -> 0 | R12: =(C12*D12)+(E12*F12)+(G12*H12)+(I12*J12)+(K12*L12)+(M12*N12)+(O12*P12) -> 0 | S12: =R12-Q12 -> 0
B13: Eksplosivt | Q13: =Rammeplan!E13 -> 0 | R13: =(C13*D13)+(E13*F13)+(G13*H13)+(I13*J13)+(K13*L13)+(M13*N13)+(O13*P13) -> 0 | S13: =R13-Q13 -> 0
A14: Uth.styrke | B14: Sirkel | Q14: =Rammeplan!E14 -> 120 | R14: =(C14*D14)+(E14*F14)+(G14*H14)+(I14*J14)+(K14*L14)+(M14*N14)+(O14*P14) -> 0 | S14: =R14-Q14 -> -120
B15: Tungt | Q15: =Rammeplan!E15 -> 90 | R15: =(C15*D15)+(E15*F15)+(G15*H15)+(I15*J15)+(K15*L15)+(M15*N15)+(O15*P15) -> 0 | S15: =R15-Q15 -> -90
A16: Spenst | Q16: =Rammeplan!E16 -> 20 | R16: =(C16*D16)+(E16*F16)+(G16*H16)+(I16*J16)+(K16*L16)+(M16*N16)+(O16*P16) -> 0 | S16: =R16-Q16 -> -20
A17: Hurtighet | Q17: =Rammeplan!E17 -> 20 | R17: =(C17*D17)+(E17*F17)+(G17*H17)+(I17*J17)+(K17*L17)+(M17*N17)+(O17*P17) -> 0 | S17: =R17-Q17 -> -20
A18: Koordinasjon | Q18: =Rammeplan!E18 -> 120 | R18: =(C18*D18)+(E18*F18)+(G18*H18)+(I18*J18)+(K18*L18)+(M18*N18)+(O18*P18) -> 0 | S18: =R18-Q18 -> -120
A19: Bevegelighet | Q19: =Rammeplan!E19 -> 30 | R19: =(C19*D19)+(E19*F19)+(G19*H19)+(I19*J19)+(K19*L19)+(M19*N19)+(O19*P19) -> 0 | S19: =R19-Q19 -> -30
A20: Rekreasjon | Q20: =Rammeplan!E20 -> 60 | R20: =(C20*D20)+(E20*F20)+(G20*H20)+(I20*J20)+(K20*L20)+(M20*N20)+(O20*P20) -> 0 | S20: =R20-Q20 -> -60
B21: Sum | C21: =SUM(C7:C20) -> 0 | E21: =SUM(E7:E20) -> 0 | G21: =SUM(G7:G20) -> 0 | I21: =SUM(I7:I20) -> 0 | K21: =SUM(K7:K20) -> 0 | M21: =SUM(M7:M20) -> 0 | O21: =SUM(O7:O20) -> 0 | Q21: =SUM(Q7:Q20) -> 700 | R21: =SUM(R7:R20) -> 0 | S21: =R21-Q21 -> -700
A30: AKKUMULERT
A32: Kvalitet | B32: Form | C32: Plan | E32: Trent
A33: Aerob | B33: Kontinuerlig | C33: ='17'!C33+'17'!Q7 -> 360 | E33: =R7 -> 0
B34: Intervall | C34: ='17'!C34+'17'!Q8 -> 0 | E34: =R8 -> 0
A35: Anaerob | B35: Lokalt | C35: ='17'!C35+'17'!Q9 -> 0 | E35: =R9 -> 0
B36: Generell | C36: ='17'!C36+'17'!Q10 -> 0 | E36: =R10 -> 0
A37: Maks.styrke | B37: Sub.maks. | C37: ='17'!C37+'17'!Q11 -> 300 | E37: =R11 -> 0
B38: Tungt | C38: ='17'!C38+'17'!Q12 -> 0 | E38: =R12 -> 0
B39: Eksplosivt | C39: ='17'!C39+'17'!Q13 -> 0 | E39: =R13 -> 0
A40: Uth.styrke | B40: Sirkel | C40: ='17'!C40+'17'!Q14 -> 360 | E40: =R14 -> 0
B41: Tungt | C41: ='17'!C41+'17'!Q15 -> 270 | E41: =R15 -> 0
A42: Spenst | C42: ='17'!C42+'17'!Q16 -> 0 | E42: =R16 -> 0
A43: Hurtighet | C43: ='17'!C43+'17'!Q17 -> 0 | E43: =R17 -> 0
A44: Koordinasjon | C44: ='17'!C44+'17'!Q18 -> 240 | E44: =R18 -> 0
A45: Bevegelighet | C45: ='17'!C45+'17'!Q19 -> 90 | E45: =R19 -> 0
A46: Rekreasjon | C46: ='17'!C46+'17'!Q20 -> 180 | E46: =R20 -> 0
B47: Sum | C47: =SUM(C33:C46) -> 1800 | E47: =R21 -> 0

Sheet 19
A1: =Rammeplan!A1 -> TRENINGSDAGBOK-HOVDEN SKIGYMNAS, 2012-2013:
A3: Uke: | B3: 19 | G3: Navn: | H3: ='16'!H3 -> 0
C5: Mandag | E5: Tirsdag | G5: Onsdag | I5: Torsdag | K5: Fredag | M5: Lørdag | O5: Søndag | Q5: Sum
A6: Kvalitet | B6: Form | C6: Plan | D6: ok | E6: Plan | F6: ok | G6: Plan | H6: ok | I6: Plan | J6: ok | K6: Plan | L6: ok | M6: Plan | N6: ok | O6: Plan | P6: ok | Q6: Plan | R6: Trent | S6: Diff. | T6: Feedback
A7: Aerob | B7: Kontinuerlig | Q7: =Rammeplan!F7 -> 240 | R7: =(C7*D7)+(E7*F7)+(G7*H7)+(I7*J7)+(K7*L7)+(M7*N7)+(O7*P7) -> 0 | S7: =R7-Q7 -> -240
B8: Intervall | Q8: =Rammeplan!F8 -> 0 | R8: =(C8*D8)+(E8*F8)+(G8*H8)+(I8*J8)+(K8*L8)+(M8*N8)+(O8*P8) -> 0 | S8: =R8-Q8 -> 0
A9: Anaerob | B9: Lokalt | Q9: =Rammeplan!F9 -> 0 | R9: =(C9*D9)+(E9*F9)+(G9*H9)+(I9*J9)+(K9*L9)+(M9*N9)+(O9*P9) -> 0 | S9: =R9-Q9 -> 0
B10: Generell | Q10: =Rammeplan!F10 -> 0 | R10: =(C10*D10)+(E10*F10)+(G10*H10)+(I10*J10)+(K10*L10)+(M10*N10)+(O10*P10) -> 0 | S10: =R10-Q10 -> 0
A11: Maks.styrke | B11: Sub.maks. | Q11: =Rammeplan!F11 -> 120 | R11: =(C11*D11)+(E11*F11)+(G11*H11)+(I11*J11)+(K11*L11)+(M11*N11)+(O11*P11) -> 0 | S11: =R11-Q11 -> -120
B12: Tungt | Q12: =Rammeplan!F12 -> 0 | R12: =(C12*D12)+(E12*F12)+(G12*H12)+(I12*J12)+(K12*L12)+(M12*N12)+(O12*P12) -> 0 | S12: =R12-Q12 -> 0
B13: Eksplosivt | Q13: =Rammeplan!F13 -> 0 | R13: =(C13*D13)+(E13*F13)+(G13*H13)+(I13*J13)+(K13*L13)+(M13*N13)+(O13*P13) -> 0 | S13: =R13-Q13 -> 0
A14: Uth.styrke | B14: Sirkel | Q14: =Rammeplan!F14 -> 120 | R14: =(C14*D14)+(E14*F14)+(G14*H14)+(I14*J14)+(K14*L14)+(M14*N14)+(O14*P14) -> 0 | S14: =R14-Q14 -> -120
B15: Tungt | Q15: =Rammeplan!F15 -> 90 | R15: =(C15*D15)+(E15*F15)+(G15*H15)+(I15*J15)+(K15*L15)+(M15*N15)+(O15*P15) -> 0 | S15: =R15-Q15 -> -90
A16: Spenst | Q16: =Rammeplan!F16 -> 0 | R16: =(C16*D16)+(E16*F16)+(G16*H16)+(I16*J16)+(K16*L16)+(M16*N16)+(O16*P16) -> 0 | S16: =R16-Q16 -> 0
A17: Hurtighet | Q17: =Rammeplan!F17 -> 0 | R17: =(C17*D17)+(E17*F17)+(G17*H17)+(I17*J17)+(K17*L17)+(M17*N17)+(O17*P17) -> 0 | S17: =R17-Q17 -> 0
A18: Koordinasjon | Q18: =Rammeplan!F18 -> 120 | R18: =(C18*D18)+(E18*F18)+(G18*H18)+(I18*J18)+(K18*L18)+(M18*N18)+(O18*P18) -> 0 | S18: =R18-Q18 -> -120
A19: Bevegelighet | Q19: =Rammeplan!F19 -> 30 | R19: =(C19*D19)+(E19*F19)+(G19*H19)+(I19*J19)+(K19*L19)+(M19*N19)+(O19*P19) -> 0 | S19: =R19-Q19 -> -30
A20: Rekreasjon | Q20: =Rammeplan!F20 -> 60 | R20: =(C20*D20)+(E20*F20)+(G20*H20)+(I20*J20)+(K20*L20)+(M20*N20)+(O20*P20) -> 0 | S20: =R20-Q20 -> -60
B21: Sum | C21: =SUM(C7:C20) -> 0 | E21: =SUM(E7:E20) -> 0 | G21: =SUM(G7:G20) -> 0 | I21: =SUM(I7:I20) -> 0 | K21: =SUM(K7:K20) -> 0 | M21: =SUM(M7:M20) -> 0 | O21: =SUM(O7:O20) -> 0 | Q21: =SUM(Q7:Q20) -> 780 | R21: =SUM(R7:R20) -> 0 | S21: =R21-Q21 -> -780
A31: AKKUMULERT
A33: Kvalitet | B33: Form | C33: Plan | E33: Trent
A34: Aerob | B34: Kontinuerlig | C34: ='18'!C33+'19'!Q7 -> 600 | E34: ='18'!E33+'19'!R7 -> 0
B35: Intervall | C35: ='18'!C34+'19'!Q8 -> 0 | E35: ='18'!E34+'18'!R8 -> 0
A36: Anaerob | B36: Lokalt | C36: ='18'!C35+'19'!Q9 -> 0 | E36: ='18'!E35+'18'!R9 -> 0
B37: Generell | C37: ='18'!C36+'19'!Q10 -> 0 | E37: ='18'!E36+'18'!R10 -> 0
A38: Maks.styrke | B38: Sub.maks. | C38: ='18'!C37+'19'!Q11 -> 420 | E38: ='18'!E37+'18'!R11 -> 0
B39: Tungt | C39: ='18'!C38+'19'!Q12 -> 0 | E39: ='18'!E38+'18'!R12 -> 0
B40: Eksplosivt | C40: ='18'!C39+'19'!Q13 -> 0 | E40: ='18'!E39+'18'!R13 -> 0
A41: Uth.styrke | B41: Sirkel | C41: ='18'!C40+'19'!Q14 -> 480 | E41: ='18'!E40+'18'!R14 -> 0
B42: Tungt | C42: ='18'!C41+'19'!Q15 -> 360 | E42: ='18'!E41+'18'!R15 -> 0
A43: Spenst | C43: ='18'!C42+'19'!Q16 -> 0 | E43: ='18'!E42+'18'!R16 -> 0
A44: Hurtighet | C44: ='18'!C43+'19'!Q17 -> 0 | E44: ='18'!E43+'18'!R17 -> 0
A45: Koordinasjon | C45: ='18'!C44+'19'!Q18 -> 360 | E45: ='18'!E44+'18'!R18 -> 0
A46: Bevegelighet | C46: ='18'!C45+'19'!Q19 -> 120 | E46: ='18'!E45+'18'!R19 -> 0
A47: Rekreasjon | C47: ='18'!C46+'19'!Q20 -> 240 | E47: ='18'!E46+'18'!R20 -> 0
B48: Sum | C48: =SUM(C34:C47) -> 2580 | E48: =SUM(E34:E47) -> 0

Sheet 20
A1: =Rammeplan!A1 -> TRENINGSDAGBOK-HOVDEN SKIGYMNAS, 2012-2013:
A3: Uke: | B3: 20 | G3: Navn: | H3: ='18'!H3 -> 0
C5: Mandag | E5: Tirsdag | G5: Onsdag | I5: Torsdag | K5: Fredag | M5: Lørdag | O5: Søndag | Q5: Sum
A6: Kvalitet | B6: Form | C6: Plan | D6: ok | E6: Plan | F6: ok | G6: Plan | H6: ok | I6: Plan | J6: ok | K6: Plan | L6: ok | M6: Plan | N6: ok | O6: Plan | P6: ok | Q6: Plan | R6: Trent | S6: Diff. | T6: Feedback
A7: Aerob | B7: Kontinuerlig | Q7: =Rammeplan!G7 -> 240 | R7: =(C7*D7)+(E7*F7)+(G7*H7)+(I7*J7)+(K7*L7)+(M7*N7)+(O7*P7) -> 0 | S7: =R7-Q7 -> -240
B8: Intervall | Q8: =Rammeplan!G8 -> 0 | R8: =(C8*D8)+(E8*F8)+(G8*H8)+(I8*J8)+(K8*L8)+(M8*N8)+(O8*P8) -> 0 | S8: =R8-Q8 -> 0
A9: Anaerob | B9: Lokalt | Q9: =Rammeplan!G9 -> 0 | R9: =(C9*D9)+(E9*F9)+(G9*H9)+(I9*J9)+(K9*L9)+(M9*N9)+(O9*P9) -> 0 | S9: =R9-Q9 -> 0
B10: Generell | Q10: =Rammeplan!G10 -> 0 | R10: =(C10*D10)+(E10*F10)+(G10*H10)+(I10*J10)+(K10*L10)+(M10*N10)+(O10*P10) -> 0 | S10: =R10-Q10 -> 0
A11: Maks.styrke | B11: Sub.maks. | Q11: =Rammeplan!G11 -> 180 | R11: =(C11*D11)+(E11*F11)+(G11*H11)+(I11*J11)+(K11*L11)+(M11*N11)+(O11*P11) -> 0 | S11: =R11-Q11 -> -180
B12: Tungt | Q12: =Rammeplan!G12 -> 0 | R12: =(C12*D12)+(E12*F12)+(G12*H12)+(I12*J12)+(K12*L12)+(M12*N12)+(O12*P12) -> 0 | S12: =R12-Q12 -> 0
B13: Eksplosivt | Q13: =Rammeplan!G13 -> 0 | R13: =(C13*D13)+(E13*F13)+(G13*H13)+(I13*J13)+(K13*L13)+(M13*N13)+(O13*P13) -> 0 | S13: =R13-Q13 -> 0
A14: Uth.styrke | B14: Sirkel | Q14: =Rammeplan!G14 -> 120 | R14: =(C14*D14)+(E14*F14)+(G14*H14)+(I14*J14)+(K14*L14)+(M14*N14)+(O14*P14) -> 0 | S14: =R14-Q14 -> -120
B15: Tungt | Q15: =Rammeplan!G15 -> 90 | R15: =(C15*D15)+(E15*F15)+(G15*H15)+(I15*J15)+(K15*L15)+(M15*N15)+(O15*P15) -> 0 | S15: =R15-Q15 -> -90
A16: Spenst | Q16: =Rammeplan!L16 -> 20 | R16: =(C16*D16)+(E16*F16)+(G16*H16)+(I16*J16)+(K16*L16)+(M16*N16)+(O16*P16) -> 0 | S16: =R16-Q16 -> -20
A17: Hurtighet | Q17: =Rammeplan!L17 -> 20 | R17: =(C17*D17)+(E17*F17)+(G17*H17)+(I17*J17)+(K17*L17)+(M17*N17)+(O17*P17) -> 0 | S17: =R17-Q17 -> -20
A18: Koordinasjon | Q18: =Rammeplan!G18 -> 120 | R18: =(C18*D18)+(E18*F18)+(G18*H18)+(I18*J18)+(K18*L18)+(M18*N18)+(O18*P18) -> 0 | S18: =R18-Q18 -> -120
A19: Bevegelighet | Q19: =Rammeplan!G19 -> 30 | R19: =(C19*D19)+(E19*F19)+(G19*H19)+(I19*J19)+(K19*L19)+(M19*N19)+(O19*P19) -> 0 | S19: =R19-Q19 -> -30
A20: Rekreasjon | Q20: =Rammeplan!G20 -> 60 | R20: =(C20*D20)+(E20*F20)+(G20*H20)+(I20*J20)+(K20*L20)+(M20*N20)+(O20*P20) -> 0 | S20: =R20-Q20 -> -60
B21: Sum | C21: =SUM(C7:C20) -> 0 | E21: =SUM(E7:E20) -> 0 | G21: =SUM(G7:G20) -> 0 | I21: =SUM(I7:I20) -> 0 | K21: =SUM(K7:K20) -> 0 | M21: =SUM(M7:M20) -> 0 | O21: =SUM(O7:O20) -> 0 | Q21: =SUM(Q7:Q20) -> 880 | R21: =SUM(R7:R20) -> 0 | S21: =R21-Q21 -> -880
A31: AKKUMULERT
A33: Kvalitet | B33: Form | C33: Plan | E33: Trent
A34: Aerob | B34: Kontinuerlig | C34: ='19'!C34+'20'!Q7 -> 840 | E34: ='19'!E34+'20'!R7 -> 0
B35: Intervall | C35: ='19'!C35+'20'!Q8 -> 0 | E35: ='19'!E35+'20'!R8 -> 0
A36: Anaerob | B36: Lokalt | C36: ='19'!C36+'20'!Q9 -> 0 | E36: ='19'!E36+'20'!R9 -> 0
B37: Generell | C37: ='19'!C37+'20'!Q10 -> 0 | E37: ='19'!E37+'20'!R10 -> 0
A38: Maks.styrke | B38: Sub.maks. | C38: ='19'!C38+'20'!Q11 -> 600 | E38: ='19'!E38+'20'!R11 -> 0
B39: Tungt | C39: ='19'!C39+'20'!Q12 -> 0 | E39: ='19'!E39+'20'!R12 -> 0
B40: Eksplosivt | C40: ='19'!C40+'20'!Q13 -> 0 | E40: ='19'!E40+'20'!R13 -> 0
A41: Uth.styrke | B41: Sirkel | C41: ='19'!C41+'20'!Q14 -> 600 | E41: ='19'!E41+'20'!R14 -> 0
B42: Tungt | C42: ='19'!C42+'20'!Q15 -> 450 | E42: ='19'!E42+'20'!R15 -> 0
A43: Spenst | C43: ='19'!C43+'20'!Q16 -> 20 | E43: ='19'!E43+'20'!R16 -> 0
A44: Hurtighet | C44: ='19'!C44+'20'!Q17 -> 20 | E44: ='19'!E44+'20'!R17 -> 0
A45: Koordinasjon | C45: ='19'!C45+'20'!Q18 -> 480 | E45: ='19'!E45+'20'!R18 -> 0
A46: Bevegelighet | C46: ='19'!C46+'20'!Q19 -> 150 | E46: ='19'!E46+'20'!R19 -> 0
A47: Rekreasjon | C47: ='19'!C47+'20'!Q20 -> 300 | E47: ='19'!E47+'20'!R20 -> 0
B48: Sum | C48: =SUM(C34:C47) -> 3460 | E48: =SUM(E34:E47) -> 0

Sheet 21
A1: =Rammeplan!A1 -> TRENINGSDAGBOK-HOVDEN SKIGYMNAS, 2012-2013:
A3: Uke: | B3: 21 | G3: Navn: | H3: ='18'!H3 -> 0
C5: Mandag | E5: Tirsdag | G5: Onsdag | I5: Torsdag | K5: Fredag | M5: Lørdag | O5: Søndag | Q5: Sum
A6: Kvalitet | B6: Form | C6: Plan | D6: ok | E6: Plan | F6: ok | G6: Plan | H6: ok | I6: Plan | J6: ok | K6: Plan | L6: ok | M6: Plan | N6: ok | O6: Plan | P6: ok | Q6: Plan | R6: Trent | S6: Diff. | T6: Feedback
A7: Aerob | B7: Kontinuerlig | Q7: =Rammeplan!H7 -> 240 | R7: =(C7*D7)+(E7*F7)+(G7*H7)+(I7*J7)+(K7*L7)+(M7*N7)+(O7*P7) -> 0 | S7: =R7-Q7 -> -240
B8: Intervall | Q8: =Rammeplan!H8 -> 0 | R8: =(C8*D8)+(E8*F8)+(G8*H8)+(I8*J8)+(K8*L8)+(M8*N8)+(O8*P8) -> 0 | S8: =R8-Q8 -> 0
A9: Anaerob | B9: Lokalt | Q9: =Rammeplan!H9 -> 0 | R9: =(C9*D9)+(E9*F9)+(G9*H9)+(I9*J9)+(K9*L9)+(M9*N9)+(O9*P9) -> 0 | S9: =R9-Q9 -> 0
B10: Generell | Q10: =Rammeplan!H10 -> 30 | R10: =(C10*D10)+(E10*F10)+(G10*H10)+(I10*J10)+(K10*L10)+(M10*N10)+(O10*P10) -> 0 | S10: =R10-Q10 -> -30
A11: Maks.styrke | B11: Sub.maks. | Q11: =Rammeplan!H11 -> 180 | R11: =(C11*D11)+(E11*F11)+(G11*H11)+(I11*J11)+(K11*L11)+(M11*N11)+(O11*P11) -> 0 | S11: =R11-Q11 -> -180
B12: Tungt | Q12: =Rammeplan!H12 -> 0 | R12: =(C12*D12)+(E12*F12)+(G12*H12)+(I12*J12)+(K12*L12)+(M12*N12)+(O12*P12) -> 0 | S12: =R12-Q12 -> 0
B13: Eksplosivt | Q13: =Rammeplan!H13 -> 0 | R13: =(C13*D13)+(E13*F13)+(G13*H13)+(I13*J13)+(K13*L13)+(M13*N13)+(O13*P13) -> 0 | S13: =R13-Q13 -> 0
A14: Uth.styrke | B14: Sirkel | Q14: =Rammeplan!H14 -> 120 | R14: =(C14*D14)+(E14*F14)+(G14*H14)+(I14*J14)+(K14*L14)+(M14*N14)+(O14*P14) -> 0 | S14: =R14-Q14 -> -120
B15: Tungt | Q15: =Rammeplan!H15 -> 90 | R15: =(C15*D15)+(E15*F15)+(G15*H15)+(I15*J15)+(K15*L15)+(M15*N15)+(O15*P15) -> 0 | S15: =R15-Q15 -> -90
A16: Spenst | Q16: =Rammeplan!I16 -> 20 | R16: =(C16*D16)+(E16*F16)+(G16*H16)+(I16*J16)+(K16*L16)+(M16*N16)+(O16*P16) -> 0 | S16: =R16-Q16 -> -20
A17: Hurtighet | Q17: =Rammeplan!I17 -> 20 | R17: =(C17*D17)+(E17*F17)+(G17*H17)+(I17*J17)+(K17*L17)+(M17*N17)+(O17*P17) -> 0 | S17: =R17-Q17 -> -20
A18: Koordinasjon | Q18: =Rammeplan!H18 -> 120 | R18: =(C18*D18)+(E18*F18)+(G18*H18)+(I18*J18)+(K18*L18)+(M18*N18)+(O18*P18) -> 0 | S18: =R18-Q18 -> -120
A19: Bevegelighet | Q19: =Rammeplan!H19 -> 30 | R19: =(C19*D19)+(E19*F19)+(G19*H19)+(I19*J19)+(K19*L19)+(M19*N19)+(O19*P19) -> 0 | S19: =R19-Q19 -> -30
A20: Rekreasjon | Q20: =Rammeplan!H20 -> 60 | R20: =(C20*D20)+(E20*F20)+(G20*H20)+(I20*J20)+(K20*L20)+(M20*N20)+(O20*P20) -> 0 | S20: =R20-Q20 -> -60
B21: Sum | C21: =SUM(C7:C20) -> 0 | E21: =SUM(E7:E20) -> 0 | G21: =SUM(G7:G20) -> 0 | I21: =SUM(I7:I20) -> 0 | K21: =SUM(K7:K20) -> 0 | M21: =SUM(M7:M20) -> 0 | O21: =SUM(O7:O20) -> 0 | Q21: =SUM(Q7:Q20) -> 910 | R21: =SUM(R7:R20) -> 0 | S21: =R21-Q21 -> -910
A31: AKKUMULERT
A33: Kvalitet | B33: Form | C33: Plan | E33: Trent
A34: Aerob | B34: Kontinuerlig | C34: ='20'!C34+'21'!Q7 -> 1080 | E34: ='20'!E34+'21'!R7 -> 0
B35: Intervall | C35: ='20'!C35+'21'!Q8 -> 0 | E35: ='20'!E35+'21'!R8 -> 0
A36: Anaerob | B36: Lokalt | C36: ='20'!C36+'21'!Q9 -> 0 | E36: ='20'!E36+'21'!R9 -> 0
B37: Generell | C37: ='20'!C37+'21'!Q10 -> 30 | E37: ='20'!E37+'21'!R10 -> 0
A38: Maks.styrke | B38: Sub.maks. | C38: ='20'!C38+'21'!Q11 -> 780 | E38: ='20'!E38+'21'!R11 -> 0
B39: Tungt | C39: ='20'!C39+'21'!Q12 -> 0 | E39: ='20'!E39+'21'!R12 -> 0
B40: Eksplosivt | C40: ='20'!C40+'21'!Q13 -> 0 | E40: ='20'!E40+'21'!R13 -> 0
A41: Uth.styrke | B41: Sirkel | C41: ='20'!C41+'21'!Q14 -> 720 | E41: ='20'!E41+'21'!R14 -> 0
B42: Tungt | C42: ='20'!C42+'21'!Q15 -> 540 | E42: ='20'!E42+'21'!R15 -> 0
A43: Spenst | C43: ='20'!C43+'21'!Q16 -> 40 | E43: ='20'!E43+'21'!R16 -> 0
A44: Hurtighet | C44: ='20'!C44+'21'!Q17 -> 40 | E44: ='20'!E44+'21'!R17 -> 0
A45: Koordinasjon | C45: ='20'!C45+'21'!Q18 -> 600 | E45: ='20'!E45+'21'!R18 -> 0
A46: Bevegelighet | C46: ='20'!C46+'21'!Q19 -> 180 | E46: ='20'!E46+'21'!R19 -> 0
A47: Rekreasjon | C47: ='20'!C47+'21'!Q20 -> 360 | E47: ='20'!E47+'21'!R20 -> 0
B48: Sum | C48: =SUM(C34:C47) -> 4370 | E48: =SUM(E34:E47) -> 0

Sheet 22
A1: =Rammeplan!A1 -> TRENINGSDAGBOK-HOVDEN SKIGYMNAS, 2012-2013:
A3: Uke: | B3: 22 | G3: Navn: | H3: ='18'!H3 -> 0
C5: Mandag | E5: Tirsdag | G5: Onsdag | I5: Torsdag | K5: Fredag | M5: Lørdag | O5: Søndag | Q5: Sum
A6: Kvalitet | B6: Form | C6: Plan | D6: ok | E6: Plan | F6: ok | G6: Plan | H6: ok | I6: Plan | J6: ok | K6: Plan | L6: ok | M6: Plan | N6: ok | O6: Plan | P6: ok | Q6: Plan | R6: Trent | S6: Diff. | T6: Feedback
A7: Aerob | B7: Kontinuerlig | Q7: =Rammeplan!I7 -> 120 | R7: =(C7*D7)+(E7*F7)+(G7*H7)+(I7*J7)+(K7*L7)+(M7*N7)+(O7*P7) -> 0 | S7: =R7-Q7 -> -120
B8: Intervall | Q8: =Rammeplan!I8 -> 0 | R8: =(C8*D8)+(E8*F8)+(G8*H8)+(I8*J8)+(K8*L8)+(M8*N8)+(O8*P8) -> 0 | S8: =R8-Q8 -> 0
A9: Anaerob | B9: Lokalt | Q9: =Rammeplan!I9 -> 0 | R9: =(C9*D9)+(E9*F9)+(G9*H9)+(I9*J9)+(K9*L9)+(M9*N9)+(O9*P9) -> 0 | S9: =R9-Q9 -> 0
B10: Generell | Q10: =Rammeplan!I10 -> 0 | R10: =(C10*D10)+(E10*F10)+(G10*H10)+(I10*J10)+(K10*L10)+(M10*N10)+(O10*P10) -> 0 | S10: =R10-Q10 -> 0
A11: Maks.styrke | B11: Sub.maks. | Q11: =Rammeplan!I11 -> 120 | R11: =(C11*D11)+(E11*F11)+(G11*H11)+(I11*J11)+(K11*L11)+(M11*N11)+(O11*P11) -> 0 | S11: =R11-Q11 -> -120
B12: Tungt | Q12: =Rammeplan!I12 -> 0 | R12: =(C12*D12)+(E12*F12)+(G12*H12)+(I12*J12)+(K12*L12)+(M12*N12)+(O12*P12) -> 0 | S12: =R12-Q12 -> 0
B13: Eksplosivt | Q13: =Rammeplan!I13 -> 0 | R13: =(C13*D13)+(E13*F13)+(G13*H13)+(I13*J13)+(K13*L13)+(M13*N13)+(O13*P13) -> 0 | S13: =R13-Q13 -> 0
A14: Uth.styrke | B14: Sirkel | Q14: =Rammeplan!I14 -> 90 | R14: =(C14*D14)+(E14*F14)+(G14*H14)+(I14*J14)+(K14*L14)+(M14*N14)+(O14*P14) -> 0 | S14: =R14-Q14 -> -90
B15: Tungt | Q15: =Rammeplan!I15 -> 60 | R15: =(C15*D15)+(E15*F15)+(G15*H15)+(I15*J15)+(K15*L15)+(M15*N15)+(O15*P15) -> 0 | S15: =R15-Q15 -> -60
A16: Spenst | Q16: =Rammeplan!J16 -> 40 | R16: =(C16*D16)+(E16*F16)+(G16*H16)+(I16*J16)+(K16*L16)+(M16*N16)+(O16*P16) -> 0 | S16: =R16-Q16 -> -40
A17: Hurtighet | Q17: =Rammeplan!J17 -> 40 | R17: =(C17*D17)+(E17*F17)+(G17*H17)+(I17*J17)+(K17*L17)+(M17*N17)+(O17*P17) -> 0 | S17: =R17-Q17 -> -40
A18: Koordinasjon | Q18: =Rammeplan!I18 -> 60 | R18: =(C18*D18)+(E18*F18)+(G18*H18)+(I18*J18)+(K18*L18)+(M18*N18)+(O18*P18) -> 0 | S18: =R18-Q18 -> -60
A19: Bevegelighet | Q19: =Rammeplan!I19 -> 30 | R19: =(C19*D19)+(E19*F19)+(G19*H19)+(I19*J19)+(K19*L19)+(M19*N19)+(O19*P19) -> 0 | S19: =R19-Q19 -> -30
A20: Rekreasjon | Q20: =Rammeplan!I20 -> 60 | R20: =(C20*D20)+(E20*F20)+(G20*H20)+(I20*J20)+(K20*L20)+(M20*N20)+(O20*P20) -> 0 | S20: =R20-Q20 -> -60
B21: Sum | C21: =SUM(C7:C20) -> 0 | E21: =SUM(E7:E20) -> 0 | G21: =SUM(G7:G20) -> 0 | I21: =SUM(I7:I20) -> 0 | K21: =SUM(K7:K20) -> 0 | M21: =SUM(M7:M20) -> 0 | O21: =SUM(O7:O20) -> 0 | Q21: =SUM(Q7:Q20) -> 620 | R21: =SUM(R7:R20) -> 0 | S21: =R21-Q21 -> -620
A31: AKKUMULERT
A33: Kvalitet | B33: Form | C33: Plan | E33: Trent
A34: Aerob | B34: Kontinuerlig | C34: ='21'!C34+'22'!Q7 -> 1200 | E34: ='21'!E34+'22'!R7 -> 0
B35: Intervall | C35: ='21'!C35+'22'!Q8 -> 0 | E35: ='21'!E35+'22'!R8 -> 0
A36: Anaerob | B36: Lokalt | C36: ='21'!C36+'22'!Q9 -> 0 | E36: ='21'!E36+'22'!R9 -> 0
B37: Generell | C37: ='21'!C37+'22'!Q10 -> 30 | E37: ='21'!E37+'22'!R10 -> 0
A38: Maks.styrke | B38: Sub.maks. | C38: ='21'!C38+'22'!Q11 -> 900 | E38: ='21'!E38+'22'!R11 -> 0
B39: Tungt | C39: ='21'!C39+'22'!Q12 -> 0 | E39: ='21'!E39+'22'!R12 -> 0
B40: Eksplosivt | C40: ='21'!C40+'22'!Q13 -> 0 | E40: ='21'!E40+'22'!R13 -> 0
A41: Uth.styrke | B41: Sirkel | C41: ='21'!C41+'22'!Q14 -> 810 | E41: ='21'!E41+'22'!R14 -> 0
B42: Tungt | C42: ='21'!C42+'22'!Q15 -> 600 | E42: ='21'!E42+'22'!R15 -> 0
A43: Spenst | C43: ='21'!C43+'22'!Q16 -> 80 | E43: ='21'!E43+'22'!R16 -> 0
A44: Hurtighet | C44: ='21'!C44+'22'!Q17 -> 80 | E44: ='21'!E44+'22'!R17 -> 0
A45: Koordinasjon | C45: ='21'!C45+'22'!Q18 -> 660 | E45: ='21'!E45+'22'!R18 -> 0
A46: Bevegelighet | C46: ='21'!C46+'22'!Q19 -> 210 | E46: ='21'!E46+'22'!R19 -> 0
A47: Rekreasjon | C47: ='21'!C47+'22'!Q20 -> 420 | E47: ='21'!E47+'22'!R20 -> 0
B48: Sum | C48: =SUM(C34:C47) -> 4990 | E48: =SUM(E34:E47) -> 0

Sheet 23
A1: =Rammeplan!A1 -> TRENINGSDAGBOK-HOVDEN SKIGYMNAS, 2012-2013:
A3: Uke: | B3: 23 | G3: Navn: | H3: ='18'!H3 -> 0
C5: Mandag | E5: Tirsdag | G5: Onsdag | I5: Torsdag | K5: Fredag | M5: Lørdag | O5: Søndag | Q5: Sum
A6: Kvalitet | B6: Form | C6: Plan | D6: ok | E6: Plan | F6: ok | G6: Plan | H6: ok | I6: Plan | J6: ok | K6: Plan | L6: ok | M6: Plan | N6: ok | O6: Plan | P6: ok | Q6: Plan | R6: Trent | S6: Diff. | T6: Feedback
A7: Aerob | B7: Kontinuerlig | Q7: =Rammeplan!J7 -> 240 | R7: =(C7*D7)+(E7*F7)+(G7*H7)+(I7*J7)+(K7*L7)+(M7*N7)+(O7*P7) -> 0 | S7: =R7-Q7 -> -240
B8: Intervall | Q8: =Rammeplan!J8 -> 0 | R8: =(C8*D8)+(E8*F8)+(G8*H8)+(I8*J8)+(K8*L8)+(M8*N8)+(O8*P8) -> 0 | S8: =R8-Q8 -> 0
A9: Anaerob | B9: Lokalt | Q9: =Rammeplan!J9 -> 0 | R9: =(C9*D9)+(E9*F9)+(G9*H9)+(I9*J9)+(K9*L9)+(M9*N9)+(O9*P9) -> 0 | S9: =R9-Q9 -> 0
B10: Generell | Q10: =Rammeplan!J10 -> 0 | R10: =(C10*D10)+(E10*F10)+(G10*H10)+(I10*J10)+(K10*L10)+(M10*N10)+(O10*P10) -> 0 | S10: =R10-Q10 -> 0
A11: Maks.styrke | B11: Sub.maks. | Q11: =Rammeplan!J11 -> 180 | R11: =(C11*D11)+(E11*F11)+(G11*H11)+(I11*J11)+(K11*L11)+(M11*N11)+(O11*P11) -> 0 | S11: =R11-Q11 -> -180
B12: Tungt | Q12: =Rammeplan!J12 -> 0 | R12: =(C12*D12)+(E12*F12)+(G12*H12)+(I12*J12)+(K12*L12)+(M12*N12)+(O12*P12) -> 0 | S12: =R12-Q12 -> 0
B13: Eksplosivt | Q13: =Rammeplan!J13 -> 0 | R13: =(C13*D13)+(E13*F13)+(G13*H13)+(I13*J13)+(K13*L13)+(M13*N13)+(O13*P13) -> 0 | S13: =R13-Q13 -> 0
A14: Uth.styrke | B14: Sirkel | Q14: =Rammeplan!J14 -> 120 | R14: =(C14*D14)+(E14*F14)+(G14*H14)+(I14*J14)+(K14*L14)+(M14*N14)+(O14*P14) -> 0 | S14: =R14-Q14 -> -120
B15: Tungt | Q15: =Rammeplan!J15 -> 90 | R15: =(C15*D15)+(E15*F15)+(G15*H15)+(I15*J15)+(K15*L15)+(M15*N15)+(O15*P15) -> 0 | S15: =R15-Q15 -> -90
A16: Spenst | Q16: =Rammeplan!J16 -> 40 | R16: =(C16*D16)+(E16*F16)+(G16*H16)+(I16*J16)+(K16*L16)+(M16*N16)+(O16*P16) -> 0 | S16: =R16-Q16 -> -40
A17: Hurtighet | Q17: =Rammeplan!J17 -> 40 | R17: =(C17*D17)+(E17*F17)+(G17*H17)+(I17*J17)+(K17*L17)+(M17*N17)+(O17*P17) -> 0 | S17: =R17-Q17 -> -40
A18: Koordinasjon | Q18: =Rammeplan!J18 -> 120 | R18: =(C18*D18)+(E18*F18)+(G18*H18)+(I18*J18)+(K18*L18)+(M18*N18)+(O18*P18) -> 0 | S18: =R18-Q18 -> -120
A19: Bevegelighet | Q19: =Rammeplan!J19 -> 30 | R19: =(C19*D19)+(E19*F19)+(G19*H19)+(I19*J19)+(K19*L19)+(M19*N19)+(O19*P19) -> 0 | S19: =R19-Q19 -> -30
A20: Rekreasjon | Q20: =Rammeplan!J20 -> 60 | R20: =(C20*D20)+(E20*F20)+(G20*H20)+(I20*J20)+(K20*L20)+(M20*N20)+(O20*P20) -> 0 | S20: =R20-Q20 -> -60
B21: Sum | C21: =SUM(C7:C20) -> 0 | E21: =SUM(E7:E20) -> 0 | G21: =SUM(G7:G20) -> 0 | I21: =SUM(I7:I20) -> 0 | K21: =SUM(K7:K20) -> 0 | M21: =SUM(M7:M20) -> 0 | O21: =SUM(O7:O20) -> 0 | Q21: =SUM(Q7:Q20) -> 920 | R21: =SUM(R7:R20) -> 0 | S21: =R21-Q21 -> -920
A31: AKKUMULERT
A33: Kvalitet | B33: Form | C33: Plan | E33: Trent
A34: Aerob | B34: Kontinuerlig | C34: ='22'!C34+'23'!Q7 -> 1440 | E34: ='22'!E34+'23'!R7 -> 0
B35: Intervall | C35: ='22'!C35+'23'!Q8 -> 0 | E35: ='22'!E35+'23'!R8 -> 0
A36: Anaerob | B36: Lokalt | C36: ='22'!C36+'23'!Q9 -> 0 | E36: ='22'!E36+'23'!R9 -> 0
B37: Generell | C37: ='22'!C37+'23'!Q10 -> 30 | E37: ='22'!E37+'23'!R10 -> 0
A38: Maks.styrke | B38: Sub.maks. | C38: ='22'!C38+'23'!Q11 -> 1080 | E38: ='22'!E38+'23'!R11 -> 0
B39: Tungt | C39: ='22'!C39+'23'!Q12 -> 0 | E39: ='22'!E39+'23'!R12 -> 0
B40: Eksplosivt | C40: ='22'!C40+'23'!Q13 -> 0 | E40: ='22'!E40+'23'!R13 -> 0
A41: Uth.styrke | B41: Sirkel | C41: ='22'!C41+'23'!Q14 -> 930 | E41: ='22'!E41+'23'!R14 -> 0
B42: Tungt | C42: ='22'!C42+'23'!Q15 -> 690 | E42: ='22'!E42+'23'!R15 -> 0
A43: Spenst | C43: ='22'!C43+'23'!Q16 -> 120 | E43: ='22'!E43+'23'!R16 -> 0
A44: Hurtighet | C44: ='22'!C44+'23'!Q17 -> 120 | E44: ='22'!E44+'23'!R17 -> 0
A45: Koordinasjon | C45: ='22'!C45+'23'!Q18 -> 780 | E45: ='22'!E45+'23'!R18 -> 0
A46: Bevegelighet | C46: ='22'!C46+'23'!Q19 -> 240 | E46: ='22'!E46+'23'!R19 -> 0
A47: Rekreasjon | C47: ='22'!C47+'23'!Q20 -> 480 | E47: ='22'!E47+'23'!R20 -> 0
B48: Sum | C48: =SUM(C34:C47) -> 5910 | E48: =SUM(E34:E47) -> 0

Sheet 24
A1: =Rammeplan!A1 -> TRENINGSDAGBOK-HOVDEN SKIGYMNAS, 2012-2013:
A3: Uke: | B3: 24 | G3: Navn: | H3: ='18'!H3 -> 0
C5: Mandag | E5: Tirsdag | G5: Onsdag | I5: Torsdag | K5: Fredag | M5: Lørdag | O5: Søndag | Q5: Sum
A6: Kvalitet | B6: Form | C6: Plan | D6: ok | E6: Plan | F6: ok | G6: Plan | H6: ok | I6: Plan | J6: ok | K6: Plan | L6: ok | M6: Plan | N6: ok | O6: Plan | P6: ok | Q6: Plan | R6: Trent | S6: Diff. | T6: Feedback
A7: Aerob | B7: Kontinuerlig | Q7: =Rammeplan!K7 -> 120 | R7: =(C7*D7)+(E7*F7)+(G7*H7)+(I7*J7)+(K7*L7)+(M7*N7)+(O7*P7) -> 0 | S7: =R7-Q7 -> -120
B8: Intervall | Q8: =Rammeplan!K8 -> 0 | R8: =(C8*D8)+(E8*F8)+(G8*H8)+(I8*J8)+(K8*L8)+(M8*N8)+(O8*P8) -> 0 | S8: =R8-Q8 -> 0
A9: Anaerob | B9: Lokalt | Q9: =Rammeplan!K9 -> 0 | R9: =(C9*D9)+(E9*F9)+(G9*H9)+(I9*J9)+(K9*L9)+(M9*N9)+(O9*P9) -> 0 | S9: =R9-Q9 -> 0
B10: Generell | Q10: =Rammeplan!K10 -> 0 | R10: =(C10*D10)+(E10*F10)+(G10*H10)+(I10*J10)+(K10*L10)+(M10*N10)+(O10*P10) -> 0 | S10: =R10-Q10 -> 0
A11: Maks.styrke | B11: Sub.maks. | Q11: =Rammeplan!K11 -> 0 | R11: =(C11*D11)+(E11*F11)+(G11*H11)+(I11*J11)+(K11*L11)+(M11*N11)+(O11*P11) -> 0 | S11: =R11-Q11 -> 0
B12: Tungt | Q12: =Rammeplan!K12 -> 0 | R12: =(C12*D12)+(E12*F12)+(G12*H12)+(I12*J12)+(K12*L12)+(M12*N12)+(O12*P12) -> 0 | S12: =R12-Q12 -> 0
B13: Eksplosivt | Q13: =Rammeplan!K13 -> 0 | R13: =(C13*D13)+(E13*F13)+(G13*H13)+(I13*J13)+(K13*L13)+(M13*N13)+(O13*P13) -> 0 | S13: =R13-Q13 -> 0
A14: Uth.styrke | B14: Sirkel | Q14: =Rammeplan!K14 -> 90 | R14: =(C14*D14)+(E14*F14)+(G14*H14)+(I14*J14)+(K14*L14)+(M14*N14)+(O14*P14) -> 0 | S14: =R14-Q14 -> -90
B15: Tungt | Q15: =Rammeplan!K15 -> 0 | R15: =(C15*D15)+(E15*F15)+(G15*H15)+(I15*J15)+(K15*L15)+(M15*N15)+(O15*P15) -> 0 | S15: =R15-Q15 -> 0
A16: Spenst | Q16: =Rammeplan!K16 -> 20 | R16: =(C16*D16)+(E16*F16)+(G16*H16)+(I16*J16)+(K16*L16)+(M16*N16)+(O16*P16) -> 0 | S16: =R16-Q16 -> -20
A17: Hurtighet | Q17: =Rammeplan!K17 -> 20 | R17: =(C17*D17)+(E17*F17)+(G17*H17)+(I17*J17)+(K17*L17)+(M17*N17)+(O17*P17) -> 0 | S17: =R17-Q17 -> -20
A18: Koordinasjon | Q18: =Rammeplan!K18 -> 60 | R18: =(C18*D18)+(E18*F18)+(G18*H18)+(I18*J18)+(K18*L18)+(M18*N18)+(O18*P18) -> 0 | S18: =R18-Q18 -> -60
A19: Bevegelighet | Q19: =Rammeplan!K19 -> 30 | R19: =(C19*D19)+(E19*F19)+(G19*H19)+(I19*J19)+(K19*L19)+(M19*N19)+(O19*P19) -> 0 | S19: =R19-Q19 -> -30
A20: Rekreasjon | Q20: =Rammeplan!K20 -> 60 | R20: =(C20*D20)+(E20*F20)+(G20*H20)+(I20*J20)+(K20*L20)+(M20*N20)+(O20*P20) -> 0 | S20: =R20-Q20 -> -60
B21: Sum | C21: =SUM(C7:C20) -> 0 | E21: =SUM(E7:E20) -> 0 | G21: =SUM(G7:G20) -> 0 | I21: =SUM(I7:I20) -> 0 | K21: =SUM(K7:K20) -> 0 | M21: =SUM(M7:M20) -> 0 | O21: =SUM(O7:O20) -> 0 | Q21: =SUM(Q7:Q20) -> 400 | R21: =SUM(R7:R20) -> 0 | S21: =R21-Q21 -> -400
A31: AKKUMULERT
A33: Kvalitet | B33: Form | C33: Plan | E33: Trent
A34: Aerob | B34: Kontinuerlig | C34: ='23'!C34+'24'!Q7 -> 1560 | E34: ='23'!E34+'24'!R7 -> 0
B35: Intervall | C35: ='23'!C35+'24'!Q8 -> 0 | E35: ='23'!E35+'24'!R8 -> 0
A36: Anaerob | B36: Lokalt | C36: ='23'!C36+'24'!Q9 -> 0 | E36: ='23'!E36+'24'!R9 -> 0
B37: Generell | C37: ='23'!C37+'24'!Q10 -> 30 | E37: ='23'!E37+'24'!R10 -> 0
A38: Maks.styrke | B38: Sub.maks. | C38: ='23'!C38+'24'!Q11 -> 1080 | E38: ='23'!E38+'24'!R11 -> 0
B39: Tungt | C39: ='23'!C39+'24'!Q12 -> 0 | E39: ='23'!E39+'24'!R12 -> 0
B40: Eksplosivt | C40: ='23'!C40+'24'!Q13 -> 0 | E40: ='23'!E40+'24'!R13 -> 0
A41: Uth.styrke | B41: Sirkel | C41: ='23'!C41+'24'!Q14 -> 1020 | E41: ='23'!E41+'24'!R14 -> 0
B42: Tungt | C42: ='23'!C42+'24'!Q15 -> 690 | E42: ='23'!E42+'24'!R15 -> 0
A43: Spenst | C43: ='23'!C43+'24'!Q16 -> 140 | E43: ='23'!E43+'24'!R16 -> 0
A44: Hurtighet | C44: ='23'!C44+'24'!Q17 -> 140 | E44: ='23'!E44+'24'!R17 -> 0
A45: Koordinasjon | C45: ='23'!C45+'24'!Q18 -> 840 | E45: ='23'!E45+'24'!R18 -> 0
A46: Bevegelighet | C46: ='23'!C46+'24'!Q19 -> 270 | E46: ='23'!E46+'24'!R19 -> 0
A47: Rekreasjon | C47: ='23'!C47+'24'!Q20 -> 540 | E47: ='23'!E47+'24'!R20 -> 0
B48: Sum | C48: =SUM(C34:C47) -> 6310 | E48: =SUM(E34:E47) -> 0

Sheet 25
A1: =Rammeplan!A1 -> TRENINGSDAGBOK-HOVDEN SKIGYMNAS, 2012-2013:
A3: Uke: | B3: 25 | G3: Navn: | H3: ='18'!H3 -> 0
C5: Mandag | E5: Tirsdag | G5: Onsdag | I5: Torsdag | K5: Fredag | M5: Lørdag | O5: Søndag | Q5: Sum
A6: Kvalitet | B6: Form | C6: Plan | D6: ok | E6: Plan | F6: ok | G6: Plan | H6: ok | I6: Plan | J6: ok | K6: Plan | L6: ok | M6: Plan | N6: ok | O6: Plan | P6: ok | Q6: Plan | R6: Trent | S6: Diff. | T6: Feedback
A7: Aerob | B7: Kontinuerlig | Q7: =Rammeplan!L7 -> 120 | R7: =(C7*D7)+(E7*F7)+(G7*H7)+(I7*J7)+(K7*L7)+(M7*N7)+(O7*P7) -> 0 | S7: =R7-Q7 -> -120
B8: Intervall | Q8: =Rammeplan!L8 -> 0 | R8: =(C8*D8)+(E8*F8)+(G8*H8)+(I8*J8)+(K8*L8)+(M8*N8)+(O8*P8) -> 0 | S8: =R8-Q8 -> 0
A9: Anaerob | B9: Lokalt | Q9: =Rammeplan!L9 -> 0 | R9: =(C9*D9)+(E9*F9)+(G9*H9)+(I9*J9)+(K9*L9)+(M9*N9)+(O9*P9) -> 0 | S9: =R9-Q9 -> 0
B10: Generell | Q10: =Rammeplan!L10 -> 0 | R10: =(C10*D10)+(E10*F10)+(G10*H10)+(I10*J10)+(K10*L10)+(M10*N10)+(O10*P10) -> 0 | S10: =R10-Q10 -> 0
A11: Maks.styrke | B11: Sub.maks. | Q11: =Rammeplan!L11 -> 0 | R11: =(C11*D11)+(E11*F11)+(G11*H11)+(I11*J11)+(K11*L11)+(M11*N11)+(O11*P11) -> 0 | S11: =R11-Q11 -> 0
B12: Tungt | Q12: =Rammeplan!L12 -> 0 | R12: =(C12*D12)+(E12*F12)+(G12*H12)+(I12*J12)+(K12*L12)+(M12*N12)+(O12*P12) -> 0 | S12: =R12-Q12 -> 0
B13: Eksplosivt | Q13: =Rammeplan!L13 -> 0 | R13: =(C13*D13)+(E13*F13)+(G13*H13)+(I13*J13)+(K13*L13)+(M13*N13)+(O13*P13) -> 0 | S13: =R13-Q13 -> 0
A14: Uth.styrke | B14: Sirkel | Q14: =Rammeplan!L14 -> 120 | R14: =(C14*D14)+(E14*F14)+(G14*H14)+(I14*J14)+(K14*L14)+(M14*N14)+(O14*P14) -> 0 | S14: =R14-Q14 -> -120
B15: Tungt | Q15: =Rammeplan!L15 -> 0 | R15: =(C15*D15)+(E15*F15)+(G15*H15)+(I15*J15)+(K15*L15)+(M15*N15)+(O15*P15) -> 0 | S15: =R15-Q15 -> 0
A16: Spenst | Q16: =Rammeplan!L16 -> 20 | R16: =(C16*D16)+(E16*F16)+(G16*H16)+(I16*J16)+(K16*L16)+(M16*N16)+(O16*P16) -> 0 | S16: =R16-Q16 -> -20
A17: Hurtighet | Q17: =Rammeplan!L17 -> 20 | R17: =(C17*D17)+(E17*F17)+(G17*H17)+(I17*J17)+(K17*L17)+(M17*N17)+(O17*P17) -> 0 | S17: =R17-Q17 -> -20
A18: Koordinasjon | Q18: =Rammeplan!L18 -> 0 | R18: =(C18*D18)+(E18*F18)+(G18*H18)+(I18*J18)+(K18*L18)+(M18*N18)+(O18*P18) -> 0 | S18: =R18-Q18 -> 0
A19: Bevegelighet | Q19: =Rammeplan!L19 -> 30 | R19: =(C19*D19)+(E19*F19)+(G19*H19)+(I19*J19)+(K19*L19)+(M19*N19)+(O19*P19) -> 0 | S19: =R19-Q19 -> -30
A20: Rekreasjon | Q20: =Rammeplan!L20 -> 60 | R20: =(C20*D20)+(E20*F20)+(G20*H20)+(I20*J20)+(K20*L20)+(M20*N20)+(O20*P20) -> 0 | S20: =R20-Q20 -> -60
B21: Sum | C21: =SUM(C7:C20) -> 0 | E21: =SUM(E7:E20) -> 0 | G21: =SUM(G7:G20) -> 0 | I21: =SUM(I7:I20) -> 0 | K21: =SUM(K7:K20) -> 0 | M21: =SUM(M7:M20) -> 0 | O21: =SUM(O7:O20) -> 0 | Q21: =SUM(Q7:Q20) -> 370 | R21: =SUM(R7:R20) -> 0 | S21: =R21-Q21 -> -370
A31: AKKUMULERT
A33: Kvalitet | B33: Form | C33: Plan | E33: Trent
A34: Aerob | B34: Kontinuerlig | C34: ='24'!C34+'25'!Q7 -> 1680 | E34: ='24'!E34+'25'!R7 -> 0
B35: Intervall | C35: ='24'!C35+'25'!Q8 -> 0 | E35: ='24'!E35+'25'!R8 -> 0
A36: Anaerob | B36: Lokalt | C36: ='24'!C36+'25'!Q9 -> 0 | E36: ='24'!E36+'25'!R9 -> 0
B37: Generell | C37: ='24'!C37+'25'!Q10 -> 30 | E37: ='24'!E37+'25'!R10 -> 0
A38: Maks.styrke | B38: Sub.maks. | C38: ='24'!C38+'25'!Q11 -> 1080 | E38: ='24'!E38+'25'!R11 -> 0
B39: Tungt | C39: ='24'!C39+'25'!Q12 -> 0 | E39: ='24'!E39+'25'!R12 -> 0
B40: Eksplosivt | C40: ='24'!C40+'25'!Q13 -> 0 | E40: ='24'!E40+'25'!R13 -> 0
A41: Uth.styrke | B41: Sirkel | C41: ='24'!C41+'25'!Q14 -> 1140 | E41: ='24'!E41+'25'!R14 -> 0
B42: Tungt | C42: ='24'!C42+'25'!Q15 -> 690 | E42: ='24'!E42+'25'!R15 -> 0
A43: Spenst | C43: ='24'!C43+'25'!Q16 -> 160 | E43: ='24'!E43+'25'!R16 -> 0
A44: Hurtighet | C44: ='24'!C44+'25'!Q17 -> 160 | E44: ='24'!E44+'25'!R17 -> 0
A45: Koordinasjon | C45: ='24'!C45+'25'!Q18 -> 840 | E45: ='24'!E45+'25'!R18 -> 0
A46: Bevegelighet | C46: ='24'!C46+'25'!Q19 -> 300 | E46: ='24'!E46+'25'!R19 -> 0
A47: Rekreasjon | C47: ='24'!C47+'25'!Q20 -> 600 | E47: ='24'!E47+'25'!R20 -> 0
B48: Sum | C48: =SUM(C34:C47) -> 6680 | E48: =SUM(E34:E47) -> 0

Sheet 26
A1: =Rammeplan!A1 -> TRENINGSDAGBOK-HOVDEN SKIGYMNAS, 2012-2013:
A3: Uke: | B3: 26 | G3: Navn: | H3: ='18'!H3 -> 0
C5: Mandag | E5: Tirsdag | G5: Onsdag | I5: Torsdag | K5: Fredag | M5: Lørdag | O5: Søndag | Q5: Sum
A6: Kvalitet | B6: Form | C6: Plan | D6: ok | E6: Plan | F6: ok | G6: Plan | H6: ok | I6: Plan | J6: ok | K6: Plan | L6: ok | M6: Plan | N6: ok | O6: Plan | P6: ok | Q6: Plan | R6: Trent | S6: Diff. | T6: Feedback
A7: Aerob | B7: Kontinuerlig | Q7: =Rammeplan!M7 -> 120 | R7: =(C7*D7)+(E7*F7)+(G7*H7)+(I7*J7)+(K7*L7)+(M7*N7)+(O7*P7) -> 0 | S7: =R7-Q7 -> -120
B8: Intervall | Q8: =Rammeplan!M8 -> 0 | R8: =(C8*D8)+(E8*F8)+(G8*H8)+(I8*J8)+(K8*L8)+(M8*N8)+(O8*P8) -> 0 | S8: =R8-Q8 -> 0
A9: Anaerob | B9: Lokalt | Q9: =Rammeplan!M9 -> 0 | R9: =(C9*D9)+(E9*F9)+(G9*H9)+(I9*J9)+(K9*L9)+(M9*N9)+(O9*P9) -> 0 | S9: =R9-Q9 -> 0
B10: Generell | Q10: =Rammeplan!M10 -> 60 | R10: =(C10*D10)+(E10*F10)+(G10*H10)+(I10*J10)+(K10*L10)+(M10*N10)+(O10*P10) -> 0 | S10: =R10-Q10 -> -60
A11: Maks.styrke | B11: Sub.maks. | Q11: =Rammeplan!M11 -> 0 | R11: =(C11*D11)+(E11*F11)+(G11*H11)+(I11*J11)+(K11*L11)+(M11*N11)+(O11*P11) -> 0 | S11: =R11-Q11 -> 0
B12: Tungt | Q12: =Rammeplan!M12 -> 0 | R12: =(C12*D12)+(E12*F12)+(G12*H12)+(I12*J12)+(K12*L12)+(M12*N12)+(O12*P12) -> 0 | S12: =R12-Q12 -> 0
B13: Eksplosivt | Q13: =Rammeplan!M13 -> 0 | R13: =(C13*D13)+(E13*F13)+(G13*H13)+(I13*J13)+(K13*L13)+(M13*N13)+(O13*P13) -> 0 | S13: =R13-Q13 -> 0
A14: Uth.styrke | B14: Sirkel | Q14: =Rammeplan!M14 -> 120 | R14: =(C14*D14)+(E14*F14)+(G14*H14)+(I14*J14)+(K14*L14)+(M14*N14)+(O14*P14) -> 0 | S14: =R14-Q14 -> -120
B15: Tungt | Q15: =Rammeplan!M15 -> 0 | R15: =(C15*D15)+(E15*F15)+(G15*H15)+(I15*J15)+(K15*L15)+(M15*N15)+(O15*P15) -> 0 | S15: =R15-Q15 -> 0
A16: Spenst | Q16: =Rammeplan!M16 -> 0 | R16: =(C16*D16)+(E16*F16)+(G16*H16)+(I16*J16)+(K16*L16)+(M16*N16)+(O16*P16) -> 0 | S16: =R16-Q16 -> 0
A17: Hurtighet | Q17: =Rammeplan!M17 -> 0 | R17: =(C17*D17)+(E17*F17)+(G17*H17)+(I17*J17)+(K17*L17)+(M17*N17)+(O17*P17) -> 0 | S17: =R17-Q17 -> 0
A18: Koordinasjon | Q18: =Rammeplan!M18 -> 0 | R18: =(C18*D18)+(E18*F18)+(G18*H18)+(I18*J18)+(K18*L18)+(M18*N18)+(O18*P18) -> 0 | S18: =R18-Q18 -> 0
A19: Bevegelighet | Q19: =Rammeplan!M19 -> 30 | R19: =(C19*D19)+(E19*F19)+(G19*H19)+(I19*J19)+(K19*L19)+(M19*N19)+(O19*P19) -> 0 | S19: =R19-Q19 -> -30
A20: Rekreasjon | Q20: =Rammeplan!M20 -> 60 | R20: =(C20*D20)+(E20*F20)+(G20*H20)+(I20*J20)+(K20*L20)+(M20*N20)+(O20*P20) -> 0 | S20: =R20-Q20 -> -60
B21: Sum | C21: =SUM(C7:C20) -> 0 | E21: =SUM(E7:E20) -> 0 | G21: =SUM(G7:G20) -> 0 | I21: =SUM(I7:I20) -> 0 | K21: =SUM(K7:K20) -> 0 | M21: =SUM(M7:M20) -> 0 | O21: =SUM(O7:O20) -> 0 | Q21: =SUM(Q7:Q20) -> 390 | R21: =SUM(R7:R20) -> 0 | S21: =R21-Q21 -> -390
A31: AKKUMULERT
A33: Kvalitet | B33: Form | C33: Plan | E33: Trent
A34: Aerob | B34: Kontinuerlig | C34: ='25'!C34+'26'!Q7 -> 1800 | E34: ='25'!E34+'26'!R7 -> 0
B35: Intervall | C35: ='25'!C35+'26'!Q8 -> 0 | E35: ='25'!E35+'26'!R8 -> 0
A36: Anaerob | B36: Lokalt | C36: ='25'!C36+'26'!Q9 -> 0 | E36: ='25'!E36+'26'!R9 -> 0
B37: Generell | C37: ='25'!C37+'26'!Q10 -> 90 | E37: ='25'!E37+'26'!R10 -> 0
A38: Maks.styrke | B38: Sub.maks. | C38: ='25'!C38+'26'!Q11 -> 1080 | E38: ='25'!E38+'26'!R11 -> 0
B39: Tungt | C39: ='25'!C39+'26'!Q12 -> 0 | E39: ='25'!E39+'26'!R12 -> 0
B40: Eksplosivt | C40: ='25'!C40+'26'!Q13 -> 0 | E40: ='25'!E40+'26'!R13 -> 0
A41: Uth.styrke | B41: Sirkel | C41: ='25'!C41+'26'!Q14 -> 1260 | E41: ='25'!E41+'26'!R14 -> 0
B42: Tungt | C42: ='25'!C42+'26'!Q15 -> 690 | E42: ='25'!E42+'26'!R15 -> 0
A43: Spenst | C43: ='25'!C43+'26'!Q16 -> 160 | E43: ='25'!E43+'26'!R16 -> 0
A44: Hurtighet | C44: ='25'!C44+'26'!Q17 -> 160 | E44: ='25'!E44+'26'!R17 -> 0
A45: Koordinasjon | C45: ='25'!C45+'26'!Q18 -> 840 | E45: ='25'!E45+'26'!R18 -> 0
A46: Bevegelighet | C46: ='25'!C46+'26'!Q19 -> 330 | E46: ='25'!E46+'26'!R19 -> 0
A47: Rekreasjon | C47: ='25'!C47+'26'!Q20 -> 660 | E47: ='25'!E47+'26'!R20 -> 0
B48: Sum | C48: =SUM(C34:C47) -> 7070 | E48: =SUM(E34:E47) -> 0

Sheet 27
A1: =Rammeplan!A1 -> TRENINGSDAGBOK-HOVDEN SKIGYMNAS, 2012-2013:
A3: Uke: | B3: 27 | G3: Navn: | H3: ='18'!H3 -> 0
C5: Mandag | E5: Tirsdag | G5: Onsdag | I5: Torsdag | K5: Fredag | M5: Lørdag | O5: Søndag | Q5: Sum
A6: Kvalitet | B6: Form | C6: Plan | D6: ok | E6: Plan | F6: ok | G6: Plan | H6: ok | I6: Plan | J6: ok | K6: Plan | L6: ok | M6: Plan | N6: ok | O6: Plan | P6: ok | Q6: Plan | R6: Trent | S6: Diff. | T6: Feedback
A7: Aerob | B7: Kontinuerlig | Q7: =Rammeplan!N7 -> 120 | R7: =(C7*D7)+(E7*F7)+(G7*H7)+(I7*J7)+(K7*L7)+(M7*N7)+(O7*P7) -> 0 | S7: =R7-Q7 -> -120
B8: Intervall | Q8: =Rammeplan!N8 -> 30 | R8: =(C8*D8)+(E8*F8)+(G8*H8)+(I8*J8)+(K8*L8)+(M8*N8)+(O8*P8) -> 0 | S8: =R8-Q8 -> -30
A9: Anaerob | B9: Lokalt | Q9: =Rammeplan!N9 -> 0 | R9: =(C9*D9)+(E9*F9)+(G9*H9)+(I9*J9)+(K9*L9)+(M9*N9)+(O9*P9) -> 0 | S9: =R9-Q9 -> 0
B10: Generell | Q10: =Rammeplan!N10 -> 0 | R10: =(C10*D10)+(E10*F10)+(G10*H10)+(I10*J10)+(K10*L10)+(M10*N10)+(O10*P10) -> 0 | S10: =R10-Q10 -> 0
A11: Maks.styrke | B11: Sub.maks. | Q11: =Rammeplan!N11 -> 120 | R11: =(C11*D11)+(E11*F11)+(G11*H11)+(I11*J11)+(K11*L11)+(M11*N11)+(O11*P11) -> 0 | S11: =R11-Q11 -> -120
B12: Tungt | Q12: =Rammeplan!N12 -> 0 | R12: =(C12*D12)+(E12*F12)+(G12*H12)+(I12*J12)+(K12*L12)+(M12*N12)+(O12*P12) -> 0 | S12: =R12-Q12 -> 0
B13: Eksplosivt | Q13: =Rammeplan!N13 -> 0 | R13: =(C13*D13)+(E13*F13)+(G13*H13)+(I13*J13)+(K13*L13)+(M13*N13)+(O13*P13) -> 0 | S13: =R13-Q13 -> 0
A14: Uth.styrke | B14: Sirkel | Q14: =Rammeplan!N14 -> 120 | R14: =(C14*D14)+(E14*F14)+(G14*H14)+(I14*J14)+(K14*L14)+(M14*N14)+(O14*P14) -> 0 | S14: =R14-Q14 -> -120
B15: Tungt | Q15: =Rammeplan!N15 -> 120 | R15: =(C15*D15)+(E15*F15)+(G15*H15)+(I15*J15)+(K15*L15)+(M15*N15)+(O15*P15) -> 0 | S15: =R15-Q15 -> -120
A16: Spenst | Q16: =Rammeplan!O16 -> 20 | R16: =(C16*D16)+(E16*F16)+(G16*H16)+(I16*J16)+(K16*L16)+(M16*N16)+(O16*P16) -> 0 | S16: =R16-Q16 -> -20
A17: Hurtighet | Q17: =Rammeplan!O17 -> 20 | R17: =(C17*D17)+(E17*F17)+(G17*H17)+(I17*J17)+(K17*L17)+(M17*N17)+(O17*P17) -> 0 | S17: =R17-Q17 -> -20
A18: Koordinasjon | Q18: =Rammeplan!O18 -> 120 | R18: =(C18*D18)+(E18*F18)+(G18*H18)+(I18*J18)+(K18*L18)+(M18*N18)+(O18*P18) -> 0 | S18: =R18-Q18 -> -120
A19: Bevegelighet | Q19: =Rammeplan!N19 -> 30 | R19: =(C19*D19)+(E19*F19)+(G19*H19)+(I19*J19)+(K19*L19)+(M19*N19)+(O19*P19) -> 0 | S19: =R19-Q19 -> -30
A20: Rekreasjon | Q20: =Rammeplan!N20 -> 120 | R20: =(C20*D20)+(E20*F20)+(G20*H20)+(I20*J20)+(K20*L20)+(M20*N20)+(O20*P20) -> 0 | S20: =R20-Q20 -> -120
B21: Sum | C21: =SUM(C7:C20) -> 0 | E21: =SUM(E7:E20) -> 0 | G21: =SUM(G7:G20) -> 0 | I21: =SUM(I7:I20) -> 0 | K21: =SUM(K7:K20) -> 0 | M21: =SUM(M7:M20) -> 0 | O21: =SUM(O7:O20) -> 0 | Q21: =SUM(Q7:Q20) -> 820 | R21: =SUM(R7:R20) -> 0 | S21: =R21-Q21 -> -820
A31: AKKUMULERT
A33: Kvalitet | B33: Form | C33: Plan | E33: Trent
A34: Aerob | B34: Kontinuerlig | C34: ='26'!C34+'26'!Q7 -> 1920 | E34: ='26'!E34+'27'!R7 -> 0
B35: Intervall | C35: ='26'!C35+'26'!Q8 -> 0 | E35: ='26'!E35+'27'!R8 -> 0
A36: Anaerob | B36: Lokalt | C36: ='26'!C36+'26'!Q9 -> 0 | E36: ='26'!E36+'27'!R9 -> 0
B37: Generell | C37: ='26'!C37+'26'!Q10 -> 150 | E37: ='26'!E37+'27'!R10 -> 0
A38: Maks.styrke | B38: Sub.maks. | C38: ='26'!C38+'26'!Q11 -> 1080 | E38: ='26'!E38+'27'!R11 -> 0
B39: Tungt | C39: ='26'!C39+'26'!Q12 -> 0 | E39: ='26'!E39+'27'!R12 -> 0
B40: Eksplosivt | C40: ='26'!C40+'26'!Q13 -> 0 | E40: ='26'!E40+'27'!R13 -> 0
A41: Uth.styrke | B41: Sirkel | C41: ='26'!C41+'26'!Q14 -> 1380 | E41: ='26'!E41+'27'!R14 -> 0
B42: Tungt | C42: ='26'!C42+'26'!Q15 -> 690 | E42: ='26'!E42+'27'!R15 -> 0
A43: Spenst | C43: ='26'!C43+'26'!Q16 -> 160 | E43: ='26'!E43+'27'!R16 -> 0
A44: Hurtighet | C44: ='26'!C44+'26'!Q17 -> 160 | E44: ='26'!E44+'27'!R17 -> 0
A45: Koordinasjon | C45: ='26'!C45+'26'!Q18 -> 840 | E45: ='26'!E45+'27'!R18 -> 0
A46: Bevegelighet | C46: ='26'!C46+'26'!Q19 -> 360 | E46: ='26'!E46+'27'!R19 -> 0
A47: Rekreasjon | C47: ='26'!C47+'26'!Q20 -> 720 | E47: ='26'!E47+'27'!R20 -> 0
B48: Sum | C48: =SUM(C34:C47) -> 7460 | E48: =SUM(E34:E47) -> 0

Sheet 28
A1: =Rammeplan!A1 -> TRENINGSDAGBOK-HOVDEN SKIGYMNAS, 2012-2013:
A3: Uke: | B3: 28 | G3: Navn: | H3: ='18'!H3 -> 0
C5: Mandag | E5: Tirsdag | G5: Onsdag | I5: Torsdag | K5: Fredag | M5: Lørdag | O5: Søndag | Q5: Sum
A6: Kvalitet | B6: Form | C6: Plan | D6: ok | E6: Plan | F6: ok | G6: Plan | H6: ok | I6: Plan | J6: ok | K6: Plan | L6: ok | M6: Plan | N6: ok | O6: Plan | P6: ok | Q6: Plan | R6: Trent | S6: Diff. | T6: Feedback
A7: Aerob | B7: Kontinuerlig | Q7: =Rammeplan!O7 -> 240 | R7: =(C7*D7)+(E7*F7)+(G7*H7)+(I7*J7)+(K7*L7)+(M7*N7)+(O7*P7) -> 0 | S7: =R7-Q7 -> -240
B8: Intervall | Q8: =Rammeplan!O8 -> 0 | R8: =(C8*D8)+(E8*F8)+(G8*H8)+(I8*J8)+(K8*L8)+(M8*N8)+(O8*P8) -> 0 | S8: =R8-Q8 -> 0
A9: Anaerob | B9: Lokalt | Q9: =Rammeplan!O9 -> 0 | R9: =(C9*D9)+(E9*F9)+(G9*H9)+(I9*J9)+(K9*L9)+(M9*N9)+(O9*P9) -> 0 | S9: =R9-Q9 -> 0
B10: Generell | Q10: =Rammeplan!O10 -> 0 | R10: =(C10*D10)+(E10*F10)+(G10*H10)+(I10*J10)+(K10*L10)+(M10*N10)+(O10*P10) -> 0 | S10: =R10-Q10 -> 0
A11: Maks.styrke | B11: Sub.maks. | Q11: =Rammeplan!O11 -> 120 | R11: =(C11*D11)+(E11*F11)+(G11*H11)+(I11*J11)+(K11*L11)+(M11*N11)+(O11*P11) -> 0 | S11: =R11-Q11 -> -120
B12: Tungt | Q12: =Rammeplan!O12 -> 0 | R12: =(C12*D12)+(E12*F12)+(G12*H12)+(I12*J12)+(K12*L12)+(M12*N12)+(O12*P12) -> 0 | S12: =R12-Q12 -> 0
B13: Eksplosivt | Q13: =Rammeplan!O13 -> 0 | R13: =(C13*D13)+(E13*F13)+(G13*H13)+(I13*J13)+(K13*L13)+(M13*N13)+(O13*P13) -> 0 | S13: =R13-Q13 -> 0
A14: Uth.styrke | B14: Sirkel | Q14: =Rammeplan!O14 -> 120 | R14: =(C14*D14)+(E14*F14)+(G14*H14)+(I14*J14)+(K14*L14)+(M14*N14)+(O14*P14) -> 0 | S14: =R14-Q14 -> -120
B15: Tungt | Q15: =Rammeplan!O15 -> 120 | R15: =(C15*D15)+(E15*F15)+(G15*H15)+(I15*J15)+(K15*L15)+(M15*N15)+(O15*P15) -> 0 | S15: =R15-Q15 -> -120
A16: Spenst | Q16: =Rammeplan!P16 -> 40 | R16: =(C16*D16)+(E16*F16)+(G16*H16)+(I16*J16)+(K16*L16)+(M16*N16)+(O16*P16) -> 0 | S16: =R16-Q16 -> -40
A17: Hurtighet | Q17: =Rammeplan!P17 -> 40 | R17: =(C17*D17)+(E17*F17)+(G17*H17)+(I17*J17)+(K17*L17)+(M17*N17)+(O17*P17) -> 0 | S17: =R17-Q17 -> -40
A18: Koordinasjon | Q18: =Rammeplan!P18 -> 120 | R18: =(C18*D18)+(E18*F18)+(G18*H18)+(I18*J18)+(K18*L18)+(M18*N18)+(O18*P18) -> 0 | S18: =R18-Q18 -> -120
A19: Bevegelighet | Q19: =Rammeplan!O19 -> 30 | R19: =(C19*D19)+(E19*F19)+(G19*H19)+(I19*J19)+(K19*L19)+(M19*N19)+(O19*P19) -> 0 | S19: =R19-Q19 -> -30
A20: Rekreasjon | Q20: =Rammeplan!O20 -> 120 | R20: =(C20*D20)+(E20*F20)+(G20*H20)+(I20*J20)+(K20*L20)+(M20*N20)+(O20*P20) -> 0 | S20: =R20-Q20 -> -120
B21: Sum | C21: =SUM(C7:C20) -> 0 | E21: =SUM(E7:E20) -> 0 | G21: =SUM(G7:G20) -> 0 | I21: =SUM(I7:I20) -> 0 | K21: =SUM(K7:K20) -> 0 | M21: =SUM(M7:M20) -> 0 | O21: =SUM(O7:O20) -> 0 | Q21: =SUM(Q7:Q20) -> 950 | R21: =SUM(R7:R20) -> 0 | S21: =R21-Q21 -> -950
A31: AKKUMULERT
A33: Kvalitet | B33: Form | C33: Plan | E33: Trent
A34: Aerob | B34: Kontinuerlig | C34: ='27'!C34+'28'!Q7 -> 2160 | E34: ='27'!E34+'28'!R7 -> 0
B35: Intervall | C35: ='27'!C35+'28'!Q8 -> 0 | E35: ='27'!E35+'28'!R8 -> 0
A36: Anaerob | B36: Lokalt | C36: ='27'!C36+'28'!Q9 -> 0 | E36: ='27'!E36+'28'!R9 -> 0
B37: Generell | C37: ='27'!C37+'28'!Q10 -> 150 | E37: ='27'!E37+'28'!R10 -> 0
A38: Maks.styrke | B38: Sub.maks. | C38: ='27'!C38+'28'!Q11 -> 1200 | E38: ='27'!E38+'28'!R11 -> 0
B39: Tungt | C39: ='27'!C39+'28'!Q12 -> 0 | E39: ='27'!E39+'28'!R12 -> 0
B40: Eksplosivt | C40: ='27'!C40+'28'!Q13 -> 0 | E40: ='27'!E40+'28'!R13 -> 0
A41: Uth.styrke | B41: Sirkel | C41: ='27'!C41+'28'!Q14 -> 1500 | E41: ='27'!E41+'28'!R14 -> 0
B42: Tungt | C42: ='27'!C42+'28'!Q15 -> 810 | E42: ='27'!E42+'28'!R15 -> 0
A43: Spenst | C43: ='27'!C43+'28'!Q16 -> 200 | E43: ='27'!E43+'28'!R16 -> 0
A44: Hurtighet | C44: ='27'!C44+'28'!Q17 -> 200 | E44: ='27'!E44+'28'!R17 -> 0
A45: Koordinasjon | C45: ='27'!C45+'28'!Q18 -> 960 | E45: ='27'!E45+'28'!R18 -> 0
A46: Bevegelighet | C46: ='27'!C46+'28'!Q19 -> 390 | E46: ='27'!E46+'28'!R19 -> 0
A47: Rekreasjon | C47: ='27'!C47+'28'!Q20 -> 840 | E47: ='27'!E47+'28'!R20 -> 0
B48: Sum | C48: =SUM(C34:C47) -> 8410 | E48: =SUM(E34:E47) -> 0

Sheet 29
A1: =Rammeplan!A1 -> TRENINGSDAGBOK-HOVDEN SKIGYMNAS, 2012-2013:
A3: Uke: | B3: 29 | G3: Navn: | H3: ='18'!H3 -> 0
C5: Mandag | E5: Tirsdag | G5: Onsdag | I5: Torsdag | K5: Fredag | M5: Lørdag | O5: Søndag | Q5: Sum
A6: Kvalitet | B6: Form | C6: Plan | D6: ok | E6: Plan | F6: ok | G6: Plan | H6: ok | I6: Plan | J6: ok | K6: Plan | L6: ok | M6: Plan | N6: ok | O6: Plan | P6: ok | Q6: Plan | R6: Trent | S6: Diff. | T6: Feedback
A7: Aerob | B7: Kontinuerlig | Q7: =Rammeplan!P7 -> 240 | R7: =(C7*D7)+(E7*F7)+(G7*H7)+(I7*J7)+(K7*L7)+(M7*N7)+(O7*P7) -> 0 | S7: =R7-Q7 -> -240
B8: Intervall | Q8: =Rammeplan!P8 -> 30 | R8: =(C8*D8)+(E8*F8)+(G8*H8)+(I8*J8)+(K8*L8)+(M8*N8)+(O8*P8) -> 0 | S8: =R8-Q8 -> -30
A9: Anaerob | B9: Lokalt | Q9: =Rammeplan!P9 -> 0 | R9: =(C9*D9)+(E9*F9)+(G9*H9)+(I9*J9)+(K9*L9)+(M9*N9)+(O9*P9) -> 0 | S9: =R9-Q9 -> 0
B10: Generell | Q10: =Rammeplan!P10 -> 0 | R10: =(C10*D10)+(E10*F10)+(G10*H10)+(I10*J10)+(K10*L10)+(M10*N10)+(O10*P10) -> 0 | S10: =R10-Q10 -> 0
A11: Maks.styrke | B11: Sub.maks. | Q11: =Rammeplan!P11 -> 120 | R11: =(C11*D11)+(E11*F11)+(G11*H11)+(I11*J11)+(K11*L11)+(M11*N11)+(O11*P11) -> 0 | S11: =R11-Q11 -> -120
B12: Tungt | Q12: =Rammeplan!P12 -> 60 | R12: =(C12*D12)+(E12*F12)+(G12*H12)+(I12*J12)+(K12*L12)+(M12*N12)+(O12*P12) -> 0 | S12: =R12-Q12 -> -60
B13: Eksplosivt | Q13: =Rammeplan!P13 -> 0 | R13: =(C13*D13)+(E13*F13)+(G13*H13)+(I13*J13)+(K13*L13)+(M13*N13)+(O13*P13) -> 0 | S13: =R13-Q13 -> 0
A14: Uth.styrke | B14: Sirkel | Q14: =Rammeplan!P14 -> 120 | R14: =(C14*D14)+(E14*F14)+(G14*H14)+(I14*J14)+(K14*L14)+(M14*N14)+(O14*P14) -> 0 | S14: =R14-Q14 -> -120
B15: Tungt | Q15: =Rammeplan!P15 -> 120 | R15: =(C15*D15)+(E15*F15)+(G15*H15)+(I15*J15)+(K15*L15)+(M15*N15)+(O15*P15) -> 0 | S15: =R15-Q15 -> -120
A16: Spenst | Q16: =Rammeplan!Q16 -> 40 | R16: =(C16*D16)+(E16*F16)+(G16*H16)+(I16*J16)+(K16*L16)+(M16*N16)+(O16*P16) -> 0 | S16: =R16-Q16 -> -40
A17: Hurtighet | Q17: =Rammeplan!Q17 -> 40 | R17: =(C17*D17)+(E17*F17)+(G17*H17)+(I17*J17)+(K17*L17)+(M17*N17)+(O17*P17) -> 0 | S17: =R17-Q17 -> -40
A18: Koordinasjon | Q18: =Rammeplan!Q18 -> 120 | R18: =(C18*D18)+(E18*F18)+(G18*H18)+(I18*J18)+(K18*L18)+(M18*N18)+(O18*P18) -> 0 | S18: =R18-Q18 -> -120
A19: Bevegelighet | Q19: =Rammeplan!P19 -> 30 | R19: =(C19*D19)+(E19*F19)+(G19*H19)+(I19*J19)+(K19*L19)+(M19*N19)+(O19*P19) -> 0 | S19: =R19-Q19 -> -30
A20: Rekreasjon | Q20: =Rammeplan!P20 -> 120 | R20: =(C20*D20)+(E20*F20)+(G20*H20)+(I20*J20)+(K20*L20)+(M20*N20)+(O20*P20) -> 0 | S20: =R20-Q20 -> -120
B21: Sum | C21: =SUM(C7:C20) -> 0 | E21: =SUM(E7:E20) -> 0 | G21: =SUM(G7:G20) -> 0 | I21: =SUM(I7:I20) -> 0 | K21: =SUM(K7:K20) -> 0 | M21: =SUM(M7:M20) -> 0 | O21: =SUM(O7:O20) -> 0 | Q21: =SUM(Q7:Q20) -> 1040 | R21: =SUM(R7:R20) -> 0 | S21: =R21-Q21 -> -1040
A30: AKKUMULERT
A32: Kvalitet | B32: Form | C32: Plan | E32: Trent
A33: Aerob | B33: Kontinuerlig | C33: ='28'!C34+'29'!Q7 -> 2400 | E33: ='28'!E34+'29'!R7 -> 0
B34: Intervall | C34: ='28'!C35+'29'!Q8 -> 30 | E34: ='28'!E35+'29'!R8 -> 0
A35: Anaerob | B35: Lokalt | C35: ='28'!C36+'29'!Q9 -> 0 | E35: ='28'!E36+'29'!R9 -> 0
B36: Generell | C36: ='28'!C37+'29'!Q10 -> 150 | E36: ='28'!E37+'29'!R10 -> 0
