Workbook
Name Modules: 'Input Teaching data here'!$A$2:$A$3

Sheet Input Teaching data here
A1: Activity | B1: Students | C1: Lecture hours | D1: Workshop hours | E1: Seminar hours | F1: Tutorial hours | G1: Supervision hours | H1: Online delivery | I1: Lecture groups | J1: Workshop groups | K1: Seminar groups | L1: Tutorial groups | M1: Supervision groups | N1: Online delivery groups | O1: Staff hours needed for lectures | P1: Staff hours needed for workshops | Q1: Staff hours needed for seminars | R1: Staff hours needed for tutorials | S1: Staff hours needed for supervision | T1: Staff hours needed online | U1: FST | V1: TRDA
A2: Example Module 1 | B2: 60 | C2: 48 | D2: 0 | E2: 4 | F2: 0 | G2: 0 | H2: 0 | I2: 1 | J2: 0 | K2: 4 | L2: 0 | M2: 0 | N2: 0 | O2: =C2*I2 -> 48 | P2: =D2*J2 -> 0 | Q2: =E2*K2 -> 16 | R2: =F2*L2 -> 0 | S2: =G2*M2 -> 0 | T2: =H2*N2 -> 0 | U2: =SUM(O2:T2) -> 64 | V2: =U2 -> 64
A3: Example Module 2 | B3: 25 | C3: 48 | D3: 0 | E3: 4 | F3: 0 | G3: 0 | H3: 0 | I3: 1 | J3: 0 | K3: 2 | L3: 0 | M3: 0 | N3: 0 | O3: =C3*I3 -> 48 | P3: =D3*J3 -> 0 | Q3: =E3*K3 -> 8 | R3: =F3*L3 -> 0 | S3: =G3*M3 -> 0 | T3: =H3*N3 -> 0 | U3: =SUM(O3:T3) -> 56 | V3: =U3 -> 56
B4: 0 | C4: 0 | D4: 0 | E4: 0 | F4: 0 | G4: 0 | H4: 0 | I4: 0 | J4: 0 | K4: 0 | L4: 0 | M4: 0 | N4: 0 | O4: =C4*I4 -> 0 | P4: =D4*J4 -> 0 | Q4: =E4*K4 -> 0 | R4: =F4*L4 -> 0 | S4: =G4*M4 -> 0 | T4: =H4*N4 -> 0 | U4: =SUM(O4:T4) -> 0 | V4: =U4 -> 0
B5: 0 | C5: 0 | D5: 0 | E5: 0 | F5: 0 | G5: 0 | H5: 0 | I5: 0 | J5: 0 | K5: 0 | L5: 0 | M5: 0 | N5: 0 | O5: =C5*I5 -> 0 | P5: =D5*J5 -> 0 | Q5: =E5*K5 -> 0 | R5: =F5*L5 -> 0 | S5: =G5*M5 -> 0 | T5: =H5*N5 -> 0 | U5: =SUM(O5:T5) -> 0 | V5: =U5 -> 0
B6: 0 | C6: 0 | D6: 0 | E6: 0 | F6: 0 | G6: 0 | H6: 0 | I6: 0 | J6: 0 | K6: 0 | L6: 0 | M6: 0 | N6: 0 | O6: =C6*I6 -> 0 | P6: =D6*J6 -> 0 | Q6: =E6*K6 -> 0 | R6: =F6*L6 -> 0 | S6: =G6*M6 -> 0 | T6: =H6*N6 -> 0 | U6: =SUM(O6:T6) -> 0 | V6: =U6 -> 0
B7: 0 | C7: 0 | D7: 0 | E7: 0 | F7: 0 | G7: 0 | H7: 0 | I7: 0 | J7: 0 | K7: 0 | L7: 0 | M7: 0 | N7: 0 | O7: =C7*I7 -> 0 | P7: =D7*J7 -> 0 | Q7: =E7*K7 -> 0 | R7: =F7*L7 -> 0 | S7: =G7*M7 -> 0 | T7: =H7*N7 -> 0 | U7: =SUM(O7:T7) -> 0 | V7: =U7 -> 0
B8: 0 | C8: 0 | D8: 0 | E8: 0 | F8: 0 | G8: 0 | H8: 0 | I8: 0 | J8: 0 | K8: 0 | L8: 0 | M8: 0 | N8: 0 | O8: =C8*I8 -> 0 | P8: =D8*J8 -> 0 | Q8: =E8*K8 -> 0 | R8: =F8*L8 -> 0 | S8: =G8*M8 -> 0 | T8: =H8*N8 -> 0 | U8: =SUM(O8:T8) -> 0 | V8: =U8 -> 0
B9: 0 | C9: 0 | D9: 0 | E9: 0 | F9: 0 | G9: 0 | H9: 0 | I9: 0 | J9: 0 | K9: 0 | L9: 0 | M9: 0 | N9: 0 | O9: =C9*I9 -> 0 | P9: =D9*J9 -> 0 | Q9: =E9*K9 -> 0 | R9: =F9*L9 -> 0 | S9: =G9*M9 -> 0 | T9: =H9*N9 -> 0 | U9: =SUM(O9:T9) -> 0 | V9: =U9 -> 0
B10: 0 | C10: 0 | D10: 0 | E10: 0 | F10: 0 | G10: 0 | H10: 0 | I10: 0 | J10: 0 | K10: 0 | L10: 0 | M10: 0 | N10: 0 | O10: =C10*I10 -> 0 | P10: =D10*J10 -> 0 | Q10: =E10*K10 -> 0 | R10: =F10*L10 -> 0 | S10: =G10*M10 -> 0 | T10: =H10*N10 -> 0 | U10: =SUM(O10:T10) -> 0 | V10: =U10 -> 0
B11: 0 | C11: 0 | D11: 0 | E11: 0 | F11: 0 | G11: 0 | H11: 0 | I11: 0 | J11: 0 | K11: 0 | L11: 0 | M11: 0 | N11: 0 | O11: =C11*I11 -> 0 | P11: =D11*J11 -> 0 | Q11: =E11*K11 -> 0 | R11: =F11*L11 -> 0 | S11: =G11*M11 -> 0 | T11: =H11*N11 -> 0 | U11: =SUM(O11:T11) -> 0 | V11: =U11 -> 0
B12: 0 | C12: 0 | D12: 0 | E12: 0 | F12: 0 | G12: 0 | H12: 0 | I12: 0 | J12: 0 | K12: 0 | L12: 0 | M12: 0 | N12: 0 | O12: =C12*I12 -> 0 | P12: =D12*J12 -> 0 | Q12: =E12*K12 -> 0 | R12: =F12*L12 -> 0 | S12: =G12*M12 -> 0 | T12: =H12*N12 -> 0 | U12: =SUM(O12:T12) -> 0 | V12: =U12 -> 0
B13: 0 | C13: 0 | D13: 0 | E13: 0 | F13: 0 | G13: 0 | H13: 0 | I13: 0 | J13: 0 | K13: 0 | L13: 0 | M13: 0 | N13: 0 | O13: =C13*I13 -> 0 | P13: =D13*J13 -> 0 | Q13: =E13*K13 -> 0 | R13: =F13*L13 -> 0 | S13: =G13*M13 -> 0 | T13: =H13*N13 -> 0 | U13: =SUM(O13:T13) -> 0 | V13: =U13 -> 0
B14: 0 | C14: 0 | D14: 0 | E14: 0 | F14: 0 | G14: 0 | H14: 0 | I14: 0 | J14: 0 | K14: 0 | L14: 0 | M14: 0 | N14: 0 | O14: =C14*I14 -> 0 | P14: =D14*J14 -> 0 | Q14: =E14*K14 -> 0 | R14: =F14*L14 -> 0 | S14: =G14*M14 -> 0 | T14: =H14*N14 -> 0 | U14: =SUM(O14:T14) -> 0 | V14: =U14 -> 0
B15: 0 | C15: 0 | D15: 0 | E15: 0 | F15: 0 | G15: 0 | H15: 0 | I15: 0 | J15: 0 | K15: 0 | L15: 0 | M15: 0 | N15: 0 | O15: =C15*I15 -> 0 | P15: =D15*J15 -> 0 | Q15: =E15*K15 -> 0 | R15: =F15*L15 -> 0 | S15: =G15*M15 -> 0 | T15: =H15*N15 -> 0 | U15: =SUM(O15:T15) -> 0 | V15: =U15 -> 0
... B56: 0 | C56: 0 | D56: 0 | E56: 0 | F56: 0 | G56: 0 | H56: 0 | I56: 0 | J56: 0 | K56: 0 | L56: 0 | M56: 0 | N56: 0 | O56: =C56*I56 -> 0 | P56: =D56*J56 -> 0 | Q56: =E56*K56 -> 0 | R56: =F56*L56 -> 0 | S56: =G56*M56 -> 0 | T56: =H56*N56 -> 0 | U56: =SUM(O56:T56) -> 0 | V56: =U56 -> 0

Sheet template
A1: Academic Work Planning Model 2010-11
A2: Faculty: | C2: Individual:
A3: Subject: | C3: FTE: | D3: 1
A5: A. Teaching:
A6: Select activity below… | B6: % of module | C6: Formal Scheduled Teaching | D6: Teaching Related Delivery Activity | E6: Total
A7: Example Module 1 | B7: 1 | C7: =IF(ISERROR(VLOOKUP(A7,'Input Teaching data here'!$A$2:$V$560,21,FALSE)*B7), "0",(VLOOKUP(A7,'Input Teaching data here'!$A$2:$V$560,21,FALSE)*B7)) -> 64 | D7: =C7 -> 64 | E7: =SUM(C7:D7) -> 128
A8: Example Module 2 | B8: 0.5 | C8: =IF(ISERROR(VLOOKUP(A8,'Input Teaching data here'!$A$2:$V$560,21,FALSE)*B8), "0",(VLOOKUP(A8,'Input Teaching data here'!$A$2:$V$560,21,FALSE)*B8)) -> 28 | D8: =C8 -> 28 | E8: =SUM(C8:D8) -> 56
B9: 1 | C9: =IF(ISERROR(VLOOKUP(A9,'Input Teaching data here'!$A$2:$V$560,21,FALSE)*B9), "0",(VLOOKUP(A9,'Input Teaching data here'!$A$2:$V$560,21,FALSE)*B9)) -> 0 | D9: =C9 -> 0 | E9: =SUM(C9:D9) -> 0
B10: 1 | C10: =IF(ISERROR(VLOOKUP(A10,'Input Teaching data here'!$A$2:$V$560,21,FALSE)*B10), "0",(VLOOKUP(A10,'Input Teaching data here'!$A$2:$V$560,21,FALSE)*B10)) -> 0 | D10: =C10 -> 0 | E10: =SUM(C10:D10) -> 0
B11: 1 | C11: =IF(ISERROR(VLOOKUP(A11,'Input Teaching data here'!$A$2:$V$560,21,FALSE)*B11), "0",(VLOOKUP(A11,'Input Teaching data here'!$A$2:$V$560,21,FALSE)*B11)) -> 0 | D11: =C11 -> 0 | E11: =SUM(C11:D11) -> 0
B12: 1 | C12: =IF(ISERROR(VLOOKUP(A12,'Input Teaching data here'!$A$2:$V$560,21,FALSE)*B12), "0",(VLOOKUP(A12,'Input Teaching data here'!$A$2:$V$560,21,FALSE)*B12)) -> 0 | D12: =C12 -> 0 | E12: =SUM(C12:D12) -> 0
B13: 1 | C13: =IF(ISERROR(VLOOKUP(A13,'Input Teaching data here'!$A$2:$V$560,21,FALSE)*B13), "0",(VLOOKUP(A13,'Input Teaching data here'!$A$2:$V$560,21,FALSE)*B13)) -> 0 | D13: =C13 -> 0 | E13: =SUM(C13:D13) -> 0
B14: 1 | C14: =IF(ISERROR(VLOOKUP(A14,'Input Teaching data here'!$A$2:$V$560,21,FALSE)*B14), "0",(VLOOKUP(A14,'Input Teaching data here'!$A$2:$V$560,21,FALSE)*B14)) -> 0 | D14: =C14 -> 0 | E14: =SUM(C14:D14) -> 0
B15: 1 | C15: =IF(ISERROR(VLOOKUP(A15,'Input Teaching data here'!$A$2:$V$560,21,FALSE)*B15), "0",(VLOOKUP(A15,'Input Teaching data here'!$A$2:$V$560,21,FALSE)*B15)) -> 0 | D15: =C15 -> 0 | E15: =SUM(C15:D15) -> 0
C16: =SUM(C7:C15) -> 92 | D16: =SUM(D7:D15) -> 92 | E16: =SUM(B16:D16) -> 184
C17: =D3*450 -> 450
A18: A. Teaching: Other Teaching Related Activity
A19: Membership of Boards of examiners | E19: 0
D20: Academic guidance | E20: 0
A21: Ongoing development of teaching and learning methods | E21: 0
D22: Professional subject updating related to teaching | E22: 0
D23: General admin related to teaching | E23: 0
D24: Account to be taken of new modules | E24: 0
A25: Account to be taken of new lecturer | E25: 0
D26: Preparation and assessment associated with research degree supervision | E26: 0
E27: 0
A28: Total | E28: =SUM(E19:E27) -> 0
A30: B. Academic Leadership & Management
D31: Module Year leadership | E31: 0
A32: Programme leadership | E32: 0
A33: Subject/Team leadership | E33: 0
A34: Faculty wide responsibilities | E34: 0
A35: Recognised trade union duties | E35: 0
A36: Admissions related activities | E36: 0
A37: Approved external responsibilities | E37: 0
D38: Development of existing curriculum and subject provision | E38: 0
D39: Invigilation | E39: 0
D40: Placement development | E40: 0
D41: Provision on mentoring for new staff | E41: 0
D42: Examining associated with research degrees | E42: 0
...
