Workbook

Sheet Data
A3: Table 10: Grain Barge Movements
A4: Source: U.S. Army Corps of Engineers
H5: % change | I5: % change | J5: % change | R5: % change | S5: % change | T5: % change | AB5: % change | AC5: % change | AD5: % change | AL5: % change | AM5: % change | AN5: % change | AV5: % change | AW5: % change | AX5: % change | AZ5: Weekly Totals (1000 tons)
B6: Corn Volumes | G6: 3-year avg of | H6: this week to | I6: last 4-weeks | J6: last 4-weeks | L6: Wheat Volumes | Q6: 3-year avg of | R6: this week to | S6: last 4-weeks | T6: last 4-weeks | V6: Soybean Volumes | AA6: 3-year avg of | AB6: this week to | AC6: last 4-weeks | AD6: last 4-weeks | AF6: Other Grain Volumes | AK6: 3-year avg of | AL6: this week to | AM6: last 4-weeks | AN6: last 4-weeks | AP6: Total Grain Volumes | AU6: 3-year avg of | AV6: this week to | AW6: last 4-weeks | AX6: last 4-weeks | AZ6: Corn | BA6: Wheat | BB6: Soybean | BC6: Other | BD6: Total | BE6: Corn | BF6: Wheat | BG6: Soybean | BH6: Other | BI6: Total
B7: Mississippi | C7: Ohio | D7: Arkansas | E7: Total | F7: 4-week | G7: 4-week | H7: same week | I7: to same 4-weeks | J7: to 3-year | L7: Mississippi | M7: Ohio | N7: Arkansas | O7: Total | P7: 4-week | Q7: 4-week | R7: same week | S7: to same 4-weeks | T7: to 3-year | V7: Mississippi | W7: Ohio | X7: Arkansas | Y7: Total | Z7: 4-week | AA7: 4-week | AB7: same week | AC7: to same 4-weeks | AD7: to 3-year | AF7: Mississippi | AG7: Ohio | AH7: Arkansas | AI7: Total | AJ7: 4-week | AK7: 4-week | AL7: same week | AM7: to same 4-weeks | AN7: to 3-year | AP7: Mississippi | AQ7: Ohio | AR7: Arkansas | AS7: Total | AT7: 4-week | AU7: 4-week | AV7: same week | AW7: to same 4-weeks | AX7: to 3-year | AZ7: =+E7 -> Total | BA7: =+O7 -> Total | BB7: =+Y7 -> Total | BC7: =+AI7 -> Total | BD7: =+AS7 -> Total | BE7: YTD | BF7: YTD | BG7: YTD | BH7: YTD | BI7: YTD | BJ7: Week Number
A8: Week ending | B8: Lock 27 | C8: Lock 52 | D8: Lock 1 | E8: Miss. | F8: average | G8: average | H8: last year | I8: last year | J8: average | L8: Lock 27 | M8: Lock 52 | N8: Lock 1 | O8: Miss. | P8: average | Q8: average | R8: last year | S8: last year | T8: average | V8: Lock 27 | W8: Lock 52 | X8: Lock 1 | Y8: Miss. | Z8: average | AA8: average | AB8: last year | AC8: last year | AD8: average | AF8: Lock 27 | AG8: Lock 52 | AH8: Lock 1 | AI8: Miss. | AJ8: average | AK8: average | AL8: last year | AM8: last year | AN8: average | AP8: Lock 27 | AQ8: Lock 52 | AR8: Lock 1 | AS8: Miss. | AT8: average | AU8: average | AV8: last year | AW8: last year | AX8: average | AZ8: =+E8 -> Miss. | BA8: =+O8 -> Miss. | BB8: =+Y8 -> Miss. | BC8: =+AI8 -> Miss. | BD8: =+AS8 -> Miss.
A10: 37625 | B10: 366644 | C10: 24721 | D10: 0 | E10: =SUM(B10:D10) -> 391365 | L10: 7535 | M10: 4500 | N10: 8500 | O10: =SUM(L10:N10) -> 20535 | V10: 121265 | W10: 46454 | X10: 11500 | Y10: =SUM(V10:X10) -> 179219 | AF10: 16520 | AG10: 11993 | AH10: 0 | AI10: =SUM(AF10:AH10) -> 28513 | AP10: =SUM(B10,L10,V10,AF10) -> 511964 | AQ10: =SUM(C10,M10,W10,AG10) -> 87668 | AR10: =SUM(D10,N10,X10,AH10) -> 20000 | AS10: =SUM(E10,O10,Y10,AI10) -> 619632 | AZ10: =+E10/1000 -> 391.365 | BA10: =+O10/1000 -> 20.535 | BB10: =+Y10/1000 -> 179.219 | BC10: =+AI10/1000 -> 28.513 | BD10: =+AS10/1000 -> 619.632 | BE10: =AZ10 -> 391.365 | BF10: =BA10 -> 20.535 | BG10: =BB10 -> 179.219 | BH10: =BC10 -> 28.513 | BI10: =BD10 -> 619.632 | BJ10: 1
A11: 37632 | B11: 446444 | C11: 41350 | D11: 0 | E11: =SUM(B11:D11) -> 487794 | L11: 25633 | M11: 1842 | N11: 14600 | O11: =SUM(L11:N11) -> 42075 | V11: 163965 | W11: 43229 | X11: 21600 | Y11: =SUM(V11:X11) -> 228794 | AF11: 11200 | AG11: 47580 | AH11: 0 | AI11: =SUM(AF11:AH11) -> 58780 | AP11: =SUM(B11,L11,V11,AF11) -> 647242 | AQ11: =SUM(C11,M11,W11,AG11) -> 134001 | AR11: =SUM(D11,N11,X11,AH11) -> 36200 | AS11: =SUM(E11,O11,Y11,AI11) -> 817443 | AZ11: =+E11/1000 -> 487.794 | BA11: =+O11/1000 -> 42.075 | BB11: =+Y11/1000 -> 228.794 | BC11: =+AI11/1000 -> 58.78 | BD11: =+AS11/1000 -> 817.443 | BE11: =BE10+AZ11 -> 879.159 | BF11: =BF10+BA11 -> 62.61 | BG11: =BG10+BB11 -> 408.013 | BH11: =BH10+BC11 -> 87.293 | BI11: =BI10+BD11 -> 1437.075 | BJ11: 2
A12: 37639 | B12: 432764 | C12: 149294 | D12: 0 | E12: =SUM(B12:D12) -> 582058 | L12: 1405 | M12: 4680 | N12: 19600 | O12: =SUM(L12:N12) -> 25685 | V12: 251138 | W12: 138720 | X12: 19000 | Y12: =SUM(V12:X12) -> 408858 | AF12: 0 | AG12: 18035 | AH12: 0 | AI12: =SUM(AF12:AH12) -> 18035 | AP12: =SUM(B12,L12,V12,AF12) -> 685307 | AQ12: =SUM(C12,M12,W12,AG12) -> 310729 | AR12: =SUM(D12,N12,X12,AH12) -> 38600 | AS12: =SUM(E12,O12,Y12,AI12) -> 1034636 | AZ12: =+E12/1000 -> 582.058 | BA12: =+O12/1000 -> 25.685 | BB12: =+Y12/1000 -> 408.858 | BC12: =+AI12/1000 -> 18.035 | BD12: =+AS12/1000 -> 1034.636 | BE12: =BE11+AZ12 -> 1461.217 | BF12: =BF11+BA12 -> 88.295 | BG12: =BG11+BB12 -> 816.871 | BH12: =BH11+BC12 -> 105.328 | BI12: =BI11+BD12 -> 2471.711 | BJ12: 3
A13: 37646 | B13: 345846 | C13: 190786 | D13: 0 | E13: =SUM(B13:D13) -> 536632 | F13: =AVERAGE(E10,E11,E12,E13) -> 499462.25 | L13: 10925 | M13: 4600 | N13: 23900 | O13: =SUM(L13:N13) -> 39425 | P13: =AVERAGE(O10,O11,O12,O13) -> 31930 | V13: 94152 | W13: 176655 | X13: 21000 | Y13: =SUM(V13:X13) -> 291807 | Z13: =AVERAGE(Y10,Y11,Y12,Y13) -> 277169.5 | AF13: 3008 | AG13: 15052 | AH13: 0 | AI13: =SUM(AF13:AH13) -> 18060 | AJ13: =AVERAGE(AI10,AI11,AI12,AI13) -> 30847 | AP13: =SUM(B13,L13,V13,AF13) -> 453931 | AQ13: =SUM(C13,M13,W13,AG13) -> 387093 | AR13: =SUM(D13,N13,X13,AH13) -> 44900 | AS13: =SUM(E13,O13,Y13,AI13) -> 885924 | AT13: =AVERAGE(AS10,AS11,AS12,AS13) -> 839408.75 | AZ13: =+E13/1000 -> 536.632 | BA13: =+O13/1000 -> 39.425 | BB13: =+Y13/1000 -> 291.807 | BC13: =+AI13/1000 -> 18.06 | BD13: =+AS13/1000 -> 885.924 | BE13: =BE12+AZ13 -> 1997.849 | BF13: =BF12+BA13 -> 127.72 | BG13: =BG12+BB13 -> 1108.678 | BH13: =BH12+BC13 -> 123.388 | BI13: =BI12+BD13 -> 3357.635 | BJ13: 4
A14: 37653 | B14: 231488 | C14: 97782 | D14: 0 | E14: =SUM(B14:D14) -> 329270 | F14: =AVERAGE(E11,E12,E13,E14) -> 483938.5 | L14: 1500 | M14: 0 | N14: 19700 | O14: =SUM(L14:N14) -> 21200 | P14: =AVERAGE(O11,O12,O13,O14) -> 32096.25 | V14: 158945 | W14: 81821 | X14: 22980 | Y14: =SUM(V14:X14) -> 263746 | Z14: =AVERAGE(Y11,Y12,Y13,Y14) -> 298301.25 | AF14: 0 | AG14: 14573 | AH14: 0 | AI14: =SUM(AF14:AH14) -> 14573 | AJ14: =AVERAGE(AI11,AI12,AI13,AI14) -> 27362 | AP14: =SUM(B14,L14,V14,AF14) -> 391933 | AQ14: =SUM(C14,M14,W14,AG14) -> 194176 | AR14: =SUM(D14,N14,X14,AH14) -> 42680 | AS14: =SUM(E14,O14,Y14,AI14) -> 628789 | AT14: =AVERAGE(AS11,AS12,AS13,AS14) -> 841698 | AZ14: =+E14/1000 -> 329.27 | BA14: =+O14/1000 -> 21.2 | BB14: =+Y14/1000 -> 263.746 | BC14: =+AI14/1000 -> 14.573 | BD14: =+AS14/1000 -> 628.789 | BE14: =BE13+AZ14 -> 2327.119 | BF14: =BF13+BA14 -> 148.92 | BG14: =BG13+BB14 -> 1372.424 | BH14: =BH13+BC14 -> 137.961 | BI14: =BI13+BD14 -> 3986.424 | BJ14: 5
A15: 37660 | B15: 263380 | C15: 51257 | D15: 0 | E15: =SUM(B15:D15) -> 314637 | F15: =AVERAGE(E12,E13,E14,E15) -> 440649.25 | L15: 4570 | M15: 13535 | N15: 28600 | O15: =SUM(L15:N15) -> 46705 | P15: =AVERAGE(O12,O13,O14,O15) -> 33253.75 | V15: 120593 | W15: 137384 | X15: 10200 | Y15: =SUM(V15:X15) -> 268177 | Z15: =AVERAGE(Y12,Y13,Y14,Y15) -> 308147 | AF15: 11120 | AG15: 22400 | AH15: 0 | AI15: =SUM(AF15:AH15) -> 33520 | AJ15: =AVERAGE(AI12,AI13,AI14,AI15) -> 21047 | AP15: =SUM(B15,L15,V15,AF15) -> 399663 | AQ15: =SUM(C15,M15,W15,AG15) -> 224576 | AR15: =SUM(D15,N15,X15,AH15) -> 38800 | AS15: =SUM(E15,O15,Y15,AI15) -> 663039 | AT15: =AVERAGE(AS12,AS13,AS14,AS15) -> 803097 | AZ15: =+E15/1000 -> 314.637 | BA15: =+O15/1000 -> 46.705 | BB15: =+Y15/1000 -> 268.177 | BC15: =+AI15/1000 -> 33.52 | BD15: =+AS15/1000 -> 663.039 | BE15: =BE14+AZ15 -> 2641.756 | BF15: =BF14+BA15 -> 195.625 | BG15: =BG14+BB15 -> 1640.601 | BH15: =BH14+BC15 -> 171.481 | BI15: =BI14+BD15 -> 4649.463 | BJ15: 6
A16: 37667 | B16: 304179 | C16: 57800 | D16: 0 | E16: =SUM(B16:D16) -> 361979 | F16: =AVERAGE(E13,E14,E15,E16) -> 385629.5 | L16: 10700 | M16: 7300 | N16: 28100 | O16: =SUM(L16:N16) -> 46100 | P16: =AVERAGE(O13,O14,O15,O16) -> 38357.5 | V16: 116066 | W16: 62700 | X16: 20600 | Y16: =SUM(V16:X16) -> 199366 | Z16: =AVERAGE(Y13,Y14,Y15,Y16) -> 255774 | AF16: 0 | AG16: 40949 | AH16: 0 | AI16: =SUM(AF16:AH16) -> 40949 | AJ16: =AVERAGE(AI13,AI14,AI15,AI16) -> 26775.5 | AP16: =SUM(B16,L16,V16,AF16) -> 430945 | AQ16: =SUM(C16,M16,W16,AG16) -> 168749 | AR16: =SUM(D16,N16,X16,AH16) -> 48700 | AS16: =SUM(E16,O16,Y16,AI16) -> 648394 | AT16: =AVERAGE(AS13,AS14,AS15,AS16) -> 706536.5 | AZ16: =+E16/1000 -> 361.979 | BA16: =+O16/1000 -> 46.1 | BB16: =+Y16/1000 -> 199.366 | BC16: =+AI16/1000 -> 40.949 | BD16: =+AS16/1000 -> 648.394 | BE16: =BE15+AZ16 -> 3003.735 | BF16: =BF15+BA16 -> 241.725 | BG16: =BG15+BB16 -> 1839.967 | BH16: =BH15+BC16 -> 212.43 | BI16: =BI15+BD16 -> 5297.857 | BJ16: 7
A17: 37674 | B17: 322520 | C17: 23835 | D17: 0 | E17: =SUM(B17:D17) -> 346355 | F17: =AVERAGE(E14,E15,E16,E17) -> 338060.25 | L17: 3200 | M17: 1500 | N17: 36900 | O17: =SUM(L17:N17) -> 41600 | P17: =AVERAGE(O14,O15,O16,O17) -> 38901.25 | V17: 115481 | W17: 41216 | X17: 21600 | Y17: =SUM(V17:X17) -> 178297 | Z17: =AVERAGE(Y14,Y15,Y16,Y17) -> 227396.5 | AF17: 0 | AG17: 20949 | AH17: 0 | AI17: =SUM(AF17:AH17) -> 20949 | AJ17: =AVERAGE(AI14,AI15,AI16,AI17) -> 27497.75 | AP17: =SUM(B17,L17,V17,AF17) -> 441201 | AQ17: =SUM(C17,M17,W17,AG17) -> 87500 | AR17: =SUM(D17,N17,X17,AH17) -> 58500 | AS17: =SUM(E17,O17,Y17,AI17) -> 587201 | AT17: =AVERAGE(AS14,AS15,AS16,AS17) -> 631855.75 | AZ17: =+E17/1000 -> 346.355 | BA17: =+O17/1000 -> 41.6 | BB17: =+Y17/1000 -> 178.297 | BC17: =+AI17/1000 -> 20.949 | BD17: =+AS17/1000 -> 587.201 | BE17: =BE16+AZ17 -> 3350.09 | BF17: =BF16+BA17 -> 283.325 | BG17: =BG16+BB17 -> 2018.264 | BH17: =BH16+BC17 -> 233.379 | BI17: =BI16+BD17 -> 5885.058 | BJ17: 8
A18: 37681 | B18: 363486 | C18: 51900 | D18: 0 | E18: =SUM(B18:D18) -> 415386 | F18: =AVERAGE(E15,E16,E17,E18) -> 359589.25 | L18: 15307 | M18: 4500 | N18: 19600 | O18: =SUM(L18:N18) -> 39407 | P18: =AVERAGE(O15,O16,O17,O18) -> 43453 | V18: 87463 | W18: 35195 | X18: 11200 | Y18: =SUM(V18:X18) -> 133858 | Z18: =AVERAGE(Y15,Y16,Y17,Y18) -> 194924.5 | AF18: 7850 | AG18: 17978 | AH18: 0 | AI18: =SUM(AF18:AH18) -> 25828 | AJ18: =AVERAGE(AI15,AI16,AI17,AI18) -> 30311.5 | AP18: =SUM(B18,L18,V18,AF18) -> 474106 | AQ18: =SUM(C18,M18,W18,AG18) -> 109573 | AR18: =SUM(D18,N18,X18,AH18) -> 30800 | AS18: =SUM(E18,O18,Y18,AI18) -> 614479 | AT18: =AVERAGE(AS15,AS16,AS17,AS18) -> 628278.25 | AZ18: =+E18/1000 -> 415.386 | BA18: =+O18/1000 -> 39.407 | BB18: =+Y18/1000 -> 133.858 | BC18: =+AI18/1000 -> 25.828 | BD18: =+AS18/1000 -> 614.479 | BE18: =BE17+AZ18 -> 3765.476 | BF18: =BF17+BA18 -> 322.732 | BG18: =BG17+BB18 -> 2152.122 | BH18: =BH17+BC18 -> 259.207 | BI18: =BI17+BD18 -> 6499.537 | BJ18: 9
A19: 37688 | B19: 507339 | C19: 27336 | D19: 0 | E19: =SUM(B19:D19) -> 534675 | F19: =AVERAGE(E16,E17,E18,E19) -> 414598.75 | L19: 16172 | M19: 7400 | N19: 24000 | O19: =SUM(L19:N19) -> 47572 | P19: =AVERAGE(O16,O17,O18,O19) -> 43669.75 | V19: 132052 | W19: 47724 | X19: 8400 | Y19: =SUM(V19:X19) -> 188176 | Z19: =AVERAGE(Y16,Y17,Y18,Y19) -> 174924.25 | AF19: 0 | AG19: 12385 | AH19: 0 | AI19: =SUM(AF19:AH19) -> 12385 | AJ19: =AVERAGE(AI16,AI17,AI18,AI19) -> 25027.75 | AP19: =SUM(B19,L19,V19,AF19) -> 655563 | AQ19: =SUM(C19,M19,W19,AG19) -> 94845 | AR19: =SUM(D19,N19,X19,AH19) -> 32400 | AS19: =SUM(E19,O19,Y19,AI19) -> 782808 | AT19: =AVERAGE(AS16,AS17,AS18,AS19) -> 658220.5 | AZ19: =+E19/1000 -> 534.675 | BA19: =+O19/1000 -> 47.572 | BB19: =+Y19/1000 -> 188.176 | BC19: =+AI19/1000 -> 12.385 | BD19: =+AS19/1000 -> 782.808 | BE19: =BE18+AZ19 -> 4300.151 | BF19: =BF18+BA19 -> 370.304 | BG19: =BG18+BB19 -> 2340.298 | BH19: =BH18+BC19 -> 271.592 | BI19: =BI18+BD19 -> 7282.345 | BJ19: 10
A20: 37695 | B20: 413681 | C20: 32993 | D20: 0 | E20: =SUM(B20:D20) -> 446674 | F20: =AVERAGE(E17,E18,E19,E20) -> 435772.5 | L20: 7635 | M20: 1500 | N20: 19900 | O20: =SUM(L20:N20) -> 29035 | P20: =AVERAGE(O17,O18,O19,O20) -> 39403.5 | V20: 79407 | W20: 42740 | X20: 5700 | Y20: =SUM(V20:X20) -> 127847 | Z20: =AVERAGE(Y17,Y18,Y19,Y20) -> 157044.5 | AF20: 0 | AG20: 7700 | AH20: 0 | AI20: =SUM(AF20:AH20) -> 7700 | AJ20: =AVERAGE(AI17,AI18,AI19,AI20) -> 16715.5 | AP20: =SUM(B20,L20,V20,AF20) -> 500723 | AQ20: =SUM(C20,M20,W20,AG20) -> 84933 | AR20: =SUM(D20,N20,X20,AH20) -> 25600 | AS20: =SUM(E20,O20,Y20,AI20) -> 611256 | AT20: =AVERAGE(AS17,AS18,AS19,AS20) -> 648936 | AZ20: =+E20/1000 -> 446.674 | BA20: =+O20/1000 -> 29.035 | BB20: =+Y20/1000 -> 127.847 | BC20: =+AI20/1000 -> 7.7 | BD20: =+AS20/1000 -> 611.256 | BE20: =BE19+AZ20 -> 4746.825 | BF20: =BF19+BA20 -> 399.339 | BG20: =BG19+BB20 -> 2468.145 | BH20: =BH19+BC20 -> 279.292 | BI20: =BI19+BD20 -> 7893.601 | BJ20: 11
A21: 37702 | B21: 442830 | C21: 33260 | D21: 0 | E21: =SUM(B21:D21) -> 476090 | F21: =AVERAGE(E18,E19,E20,E21) -> 468206.25 | L21: 7550 | M21: 4580 | N21: 27200 | O21: =SUM(L21:N21) -> 39330 | P21: =AVERAGE(O18,O19,O20,O21) -> 38836 | V21: 84436 | W21: 44960 | X21: 7300 | Y21: =SUM(V21:X21) -> 136696 | Z21: =AVERAGE(Y18,Y19,Y20,Y21) -> 146644.25 | AF21: 0 | AG21: 13937 | AH21: 0 | AI21: =SUM(AF21:AH21) -> 13937 | AJ21: =AVERAGE(AI18,AI19,AI20,AI21) -> 14962.5 | AP21: =SUM(B21,L21,V21,AF21) -> 534816 | AQ21: =SUM(C21,M21,W21,AG21) -> 96737 | AR21: =SUM(D21,N21,X21,AH21) -> 34500 | AS21: =SUM(E21,O21,Y21,AI21) -> 666053 | AT21: =AVERAGE(AS18,AS19,AS20,AS21) -> 668649 | AZ21: =+E21/1000 -> 476.09 | BA21: =+O21/1000 -> 39.33 | BB21: =+Y21/1000 -> 136.696 | BC21: =+AI21/1000 -> 13.937 | BD21: =+AS21/1000 -> 666.053 | BE21: =BE20+AZ21 -> 5222.915 | BF21: =BF20+BA21 -> 438.669 | BG21: =BG20+BB21 -> 2604.841 | BH21: =BH20+BC21 -> 293.229 | BI21: =BI20+BD21 -> 8559.654 | BJ21: 12
A22: 37709 | B22: 682701 | C22: 49168 | D22: 0 | E22: =SUM(B22:D22) -> 731869 | F22: =AVERAGE(E19,E20,E21,E22) -> 547327 | L22: 15259 | M22: 0 | N22: 19600 | O22: =SUM(L22:N22) -> 34859 | P22: =AVERAGE(O19,O20,O21,O22) -> 37699 | V22: 111184 | W22: 19624 | X22: 5600 | Y22: =SUM(V22:X22) -> 136408 | Z22: =AVERAGE(Y19,Y20,Y21,Y22) -> 147281.75 | AF22: 6000 | AG22: 21420 | AH22: 0 | AI22: =SUM(AF22:AH22) -> 27420 | AJ22: =AVERAGE(AI19,AI20,AI21,AI22) -> 15360.5 | AP22: =SUM(B22,L22,V22,AF22) -> 815144 | AQ22: =SUM(C22,M22,W22,AG22) -> 90212 | AR22: =SUM(D22,N22,X22,AH22) -> 25200 | AS22: =SUM(E22,O22,Y22,AI22) -> 930556 | AT22: =AVERAGE(AS19,AS20,AS21,AS22) -> 747668.25 | AZ22: =+E22/1000 -> 731.869 | BA22: =+O22/1000 -> 34.859 | BB22: =+Y22/1000 -> 136.408 | BC22: =+AI22/1000 -> 27.42 | BD22: =+AS22/1000 -> 930.556 | BE22: =BE21+AZ22 -> 5954.784 | BF22: =BF21+BA22 -> 473.528 | BG22: =BG21+BB22 -> 2741.249 | BH22: =BH21+BC22 -> 320.649 | BI22: =BI21+BD22 -> 9490.21 | BJ22: 13
A23: 37716 | B23: 675491 | C23: 36735 | D23: 0 | E23: =SUM(B23:D23) -> 712226 | F23: =AVERAGE(E20,E21,E22,E23) -> 591714.75 | L23: 13924 | M23: 4500 | N23: 11300 | O23: =SUM(L23:N23) -> 29724 | P23: =AVERAGE(O20,O21,O22,O23) -> 33237 | V23: 134812 | W23: 23913 | X23: 5500 | Y23: =SUM(V23:X23) -> 164225 | Z23: =AVERAGE(Y20,Y21,Y22,Y23) -> 141294 | AF23: 0 | AG23: 9124 | AH23: 0 | AI23: =SUM(AF23:AH23) -> 9124 | AJ23: =AVERAGE(AI20,AI21,AI22,AI23) -> 14545.25 | AP23: =SUM(B23,L23,V23,AF23) -> 824227 | AQ23: =SUM(C23,M23,W23,AG23) -> 74272 | AR23: =SUM(D23,N23,X23,AH23) -> 16800 | AS23: =SUM(E23,O23,Y23,AI23) -> 915299 | AT23: =AVERAGE(AS20,AS21,AS22,AS23) -> 780791 | AZ23: =+E23/1000 -> 712.226 | BA23: =+O23/1000 -> 29.724 | BB23: =+Y23/1000 -> 164.225 | BC23: =+AI23/1000 -> 9.124 | BD23: =+AS23/1000 -> 915.299 | BE23: =BE22+AZ23 -> 6667.01 | BF23: =BF22+BA23 -> 503.252 | BG23: =BG22+BB23 -> 2905.474 | BH23: =BH22+BC23 -> 329.773 | BI23: =BI22+BD23 -> 10405.509 | BJ23: 14
A24: 37723 | B24: 595846 | C24: 33200 | D24: 0 | E24: =SUM(B24:D24) -> 629046 | F24: =AVERAGE(E21,E22,E23,E24) -> 637307.75 | L24: 3000 | M24: 4493 | N24: 13800 | O24: =SUM(L24:N24) -> 21293 | P24: =AVERAGE(O21,O22,O23,O24) -> 31301.5 | V24: 162020 | W24: 16700 | X24: 1400 | Y24: =SUM(V24:X24) -> 180120 | Z24: =AVERAGE(Y21,Y22,Y23,Y24) -> 154362.25 | AF24: 1600 | AG24: 16289 | AH24: 0 | AI24: =SUM(AF24:AH24) -> 17889 | AJ24: =AVERAGE(AI21,AI22,AI23,AI24) -> 17092.5 | AP24: =SUM(B24,L24,V24,AF24) -> 762466 | AQ24: =SUM(C24,M24,W24,AG24) -> 70682 | AR24: =SUM(D24,N24,X24,AH24) -> 15200 | AS24: =SUM(E24,O24,Y24,AI24) -> 848348 | AT24: =AVERAGE(AS21,AS22,AS23,AS24) -> 840064 | AZ24: =+E24/1000 -> 629.046 | BA24: =+O24/1000 -> 21.293 | BB24: =+Y24/1000 -> 180.12 | BC24: =+AI24/1000 -> 17.889 | BD24: =+AS24/1000 -> 848.348 | BE24: =BE23+AZ24 -> 7296.056 | BF24: =BF23+BA24 -> 524.545 | BG24: =BG23+BB24 -> 3085.594 | BH24: =BH23+BC24 -> 347.662 | BI24: =BI23+BD24 -> 11253.857 | BJ24: 15
... A51: 37912 | B51: 323136 | C51: 49500 | D51: 0 | E51: =SUM(B51:D51) -> 372636 | F51: =AVERAGE(E48,E49,E50,E51) -> 440361 | L51: 6357 | M51: 10300 | N51: 27100 | O51: =SUM(L51:N51) -> 43757 | P51: =AVERAGE(O48,O49,O50,O51) -> 51924.5 | V51: 364847 | W51: 42389 | X51: 7100 | Y51: =SUM(V51:X51) -> 414336 | Z51: =AVERAGE(Y48,Y49,Y50,Y51) -> 215899.25 | AF51: 0 | AG51: 0 | AH51: 0 | AI51: =SUM(AF51:AH51) -> 0 | AJ51: =AVERAGE(AI48,AI49,AI50,AI51) -> 1550 | AP51: =SUM(B51,L51,V51,AF51) -> 694340 | AQ51: =SUM(C51,M51,W51,AG51) -> 102189 | AR51: =SUM(D51,N51,X51,AH51) -> 34200 | AS51: =SUM(E51,O51,Y51,AI51) -> 830729 | AT51: =AVERAGE(AS48,AS49,AS50,AS51) -> 709734.75 | AZ51: =+E51/1000 -> 372.636 | BA51: =+O51/1000 -> 43.757 | BB51: =+Y51/1000 -> 414.336 | BC51: =+AI51/1000 -> 0 | BD51: =+AS51/1000 -> 830.729 | BE51: =BE50+AZ51 -> 22661.697 | BF51: =BF50+BA51 -> 2409.055 | BG51: =BG50+BB51 -> 6435.339 | BH51: =BH50+BC51 -> 596.629 | BI51: =BI50+BD51 -> 32102.72 | BJ51: 42
A52: 37919 | B52: 508706 | C52: 25535 | D52: 0 | E52: =SUM(B52:D52) -> 534241 | F52: =AVERAGE(E49,E50,E51,E52) -> 453700.25 | N52: 8400 | O52: =SUM(L52:N52) -> 8400 | P52: =AVERAGE(O49,O50,O51,O52) -> 34329.5 | V52: 138493 | W52: 159454 | X52: 39500 | Y52: =SUM(V52:X52) -> 337447 | Z52: =AVERAGE(Y49,Y50,Y51,Y52) -> 279926.5 | AF52: 6335 | AG52: 1500 | AH52: 0 | AI52: =SUM(AF52:AH52) -> 7835 | AJ52: =AVERAGE(AI49,AI50,AI51,AI52) -> 2333.75 | AP52: =SUM(B52,L52,V52,AF52) -> 653534 | AQ52: =SUM(C52,M52,W52,AG52) -> 186489 | AR52: =SUM(D52,N52,X52,AH52) -> 47900 | AS52: =SUM(E52,O52,Y52,AI52) -> 887923 | AT52: =AVERAGE(AS49,AS50,AS51,AS52) -> 770290 | AZ52: =+E52/1000 -> 534.241 | BA52: =+O52/1000 -> 8.4 | BB52: =+Y52/1000 -> 337.447 | BC52: =+AI52/1000 -> 7.835 | BD52: =+AS52/1000 -> 887.923 | BE52: =BE51+AZ52 -> 23195.938 | BF52: =BF51+BA52 -> 2417.455 | BG52: =BG51+BB52 -> 6772.786 | BH52: =BH51+BC52 -> 604.464 | BI52: =BI51+BD52 -> 32990.643 | BJ52: 43
A53: 37926 | B53: 420975 | C53: 37884 | D53: 0 | E53: =SUM(B53:D53) -> 458859 | F53: =AVERAGE(E50,E51,E52,E53) -> 457252 | L53: 17908 | N53: 18400 | O53: =SUM(L53:N53) -> 36308 | P53: =AVERAGE(O50,O51,O52,O53) -> 31372.25 | V53: 322987 | W53: 89358 | X53: 28800 | Y53: =SUM(V53:X53) -> 441145 | Z53: =AVERAGE(Y50,Y51,Y52,Y53) -> 356622.5 | AF53: 9600 | AG53: 1600 | AH53: 0 | AI53: =SUM(AF53:AH53) -> 11200 | AJ53: =AVERAGE(AI50,AI51,AI52,AI53) -> 5133.75 | AP53: =SUM(B53,L53,V53,AF53) -> 771470 | AQ53: =SUM(C53,M53,W53,AG53) -> 128842 | AR53: =SUM(D53,N53,X53,AH53) -> 47200 | AS53: =SUM(E53,O53,Y53,AI53) -> 947512 | AT53: =AVERAGE(AS50,AS51,AS52,AS53) -> 850380.5 | AZ53: =+E53/1000 -> 458.859 | BA53: =+O53/1000 -> 36.308 | BB53: =+Y53/1000 -> 441.145 | BC53: =+AI53/1000 -> 11.2 | BD53: =+AS53/1000 -> 947.512 | BE53: =BE52+AZ53 -> 23654.797 | BF53: =BF52+BA53 -> 2453.763 | BG53: =BG52+BB53 -> 7213.931 | BH53: =BH52+BC53 -> 615.664 | BI53: =BI52+BD53 -> 33938.155 | BJ53: 44
A54: 37933 | B54: 813647 | C54: 45901 | D54: 0 | E54: =SUM(B54:D54) -> 859548 | F54: =AVERAGE(E51,E52,E53,E54) -> 556321 | L54: 22477 | N54: 16900 | O54: =SUM(L54:N54) -> 39377 | P54: =AVERAGE(O51,O52,O53,O54) -> 31960.5 | V54: 136828 | W54: 138065 | X54: 43200 | Y54: =SUM(V54:X54) -> 318093 | Z54: =AVERAGE(Y51,Y52,Y53,Y54) -> 377755.25 | AF54: 1600 | AG54: 6700 | AH54: 0 | AI54: =SUM(AF54:AH54) -> 8300 | AJ54: =AVERAGE(AI51,AI52,AI53,AI54) -> 6833.75 | AP54: =SUM(B54,L54,V54,AF54) -> 974552 | AQ54: =SUM(C54,M54,W54,AG54) -> 190666 | AR54: =SUM(D54,N54,X54,AH54) -> 60100 | AS54: =SUM(E54,O54,Y54,AI54) -> 1225318 | AT54: =AVERAGE(AS51,AS52,AS53,AS54) -> 972870.5 | AZ54: =+E54/1000 -> 859.548 | BA54: =+O54/1000 -> 39.377 | BB54: =+Y54/1000 -> 318.093 | BC54: =+AI54/1000 -> 8.3 | BD54: =+AS54/1000 -> 1225.318 | BE54: =BE53+AZ54 -> 24514.345 | BF54: =BF53+BA54 -> 2493.14 | BG54: =BG53+BB54 -> 7532.024 | BH54: =BH53+BC54 -> 623.964 | BI54: =BI53+BD54 -> 35163.473 | BJ54: 45
A55: 37940 | B55: 623316 | C55: 42320 | D55: 0 | E55: =SUM(B55:D55) -> 665636 | F55: =AVERAGE(E52,E53,E54,E55) -> 629571 | L55: 10948 | M55: 6000 | N55: 7000 | O55: =SUM(L55:N55) -> 23948 | P55: =AVERAGE(O52,O53,O54,O55) -> 27008.25 | V55: 106451 | W55: 71222 | X55: 41200 | Y55: =SUM(V55:X55) -> 218873 | Z55: =AVERAGE(Y52,Y53,Y54,Y55) -> 328889.5 | AF55: 4500 | AG55: 0 | AH55: 0 | AI55: =SUM(AF55:AH55) -> 4500 | AJ55: =AVERAGE(AI52,AI53,AI54,AI55) -> 7958.75 | AP55: =SUM(B55,L55,V55,AF55) -> 745215 | AQ55: =SUM(C55,M55,W55,AG55) -> 119542 | AR55: =SUM(D55,N55,X55,AH55) -> 48200 | AS55: =SUM(E55,O55,Y55,AI55) -> 912957 | AT55: =AVERAGE(AS52,AS53,AS54,AS55) -> 993427.5 | AZ55: =+E55/1000 -> 665.636 | BA55: =+O55/1000 -> 23.948 | BB55: =+Y55/1000 -> 218.873 | BC55: =+AI55/1000 -> 4.5 | BD55: =+AS55/1000 -> 912.957 | BE55: =BE54+AZ55 -> 25179.981 | BF55: =BF54+BA55 -> 2517.088 | BG55: =BG54+BB55 -> 7750.897 | BH55: =BH54+BC55 -> 628.464 | BI55: =BI54+BD55 -> 36076.43 | BJ55: 46
A56: 37947 | B56: 786202 | C56: 58724 | D56: 0 | E56: =SUM(B56:D56) -> 844926 | F56: =AVERAGE(E53,E54,E55,E56) -> 707242.25 | L56: 16852 | N56: 14000 | O56: =SUM(L56:N56) -> 30852 | P56: =AVERAGE(O53,O54,O55,O56) -> 32621.25 | V56: 113631 | W56: 88728 | X56: 16800 | Y56: =SUM(V56:X56) -> 219159 | Z56: =AVERAGE(Y53,Y54,Y55,Y56) -> 299317.5 | AF56: 3000 | AG56: 3000 | AH56: 0 | AI56: =SUM(AF56:AH56) -> 6000 | AJ56: =AVERAGE(AI53,AI54,AI55,AI56) -> 7500 | AP56: =SUM(B56,L56,V56,AF56) -> 919685 | AQ56: =SUM(C56,M56,W56,AG56) -> 150452 | AR56: =SUM(D56,N56,X56,AH56) -> 30800 | AS56: =SUM(E56,O56,Y56,AI56) -> 1100937 | AT56: =AVERAGE(AS53,AS54,AS55,AS56) -> 1046681 | AZ56: =+E56/1000 -> 844.926 | BA56: =+O56/1000 -> 30.852 | BB56: =+Y56/1000 -> 219.159 | BC56: =+AI56/1000 -> 6 | BD56: =+AS56/1000 -> 1100.937 | BE56: =BE55+AZ56 -> 26024.907 | BF56: =BF55+BA56 -> 2547.94 | BG56: =BG55+BB56 -> 7970.056 | BH56: =BH55+BC56 -> 634.464 | BI56: =BI55+BD56 -> 37177.367 | BJ56: 47
A57: 37954 | B57: 700370 | C57: 36772 | D57: 0 | E57: =SUM(B57:D57) -> 737142 | F57: =AVERAGE(E54,E55,E56,E57) -> 776813 | L57: 21352 | M57: 9642 | N57: 14100 | O57: =SUM(L57:N57) -> 45094 | P57: =AVERAGE(O54,O55,O56,O57) -> 34817.75 | V57: 167447 | W57: 66606 | X57: 42100 | Y57: =SUM(V57:X57) -> 276153 | Z57: =AVERAGE(Y54,Y55,Y56,Y57) -> 258069.5 | AF57: 0 | AG57: 0 | AH57: 0 | AI57: =SUM(AF57:AH57) -> 0 | AJ57: =AVERAGE(AI54,AI55,AI56,AI57) -> 4700 | AP57: =SUM(B57,L57,V57,AF57) -> 889169 | AQ57: =SUM(C57,M57,W57,AG57) -> 113020 | AR57: =SUM(D57,N57,X57,AH57) -> 56200 | AS57: =SUM(E57,O57,Y57,AI57) -> 1058389 | AT57: =AVERAGE(AS54,AS55,AS56,AS57) -> 1074400.2 | AZ57: =+E57/1000 -> 737.142 | BA57: =+O57/1000 -> 45.094 | BB57: =+Y57/1000 -> 276.153 | BC57: =+AI57/1000 -> 0 | BD57: =+AS57/1000 -> 1058.389 | BE57: =BE56+AZ57 -> 26762.049 | BF57: =BF56+BA57 -> 2593.034 | BG57: =BG56+BB57 -> 8246.209 | BH57: =BH56+BC57 -> 634.464 | BI57: =BI56+BD57 -> 38235.756 | BJ57: 48
A58: 37961 | B58: 833745 | C58: 63121 | D58: 0 | E58: =SUM(B58:D58) -> 896866 | F58: =AVERAGE(E55,E56,E57,E58) -> 786142.5 | L58: 19994 | M58: 8100 | N58: 30400 | O58: =SUM(L58:N58) -> 58494 | P58: =AVERAGE(O55,O56,O57,O58) -> 39597 | V58: 285069 | W58: 72800 | X58: 18500 | Y58: =SUM(V58:X58) -> 376369 | Z58: =AVERAGE(Y55,Y56,Y57,Y58) -> 272638.5 | AF58: 1600 | AG58: 0 | AH58: 0 | AI58: =SUM(AF58:AH58) -> 1600 | AJ58: =AVERAGE(AI55,AI56,AI57,AI58) -> 3025 | AP58: =SUM(B58,L58,V58,AF58) -> 1140408 | AQ58: =SUM(C58,M58,W58,AG58) -> 144021 | AR58: =SUM(D58,N58,X58,AH58) -> 48900 | AS58: =SUM(E58,O58,Y58,AI58) -> 1333329 | AT58: =AVERAGE(AS55,AS56,AS57,AS58) -> 1101403 | AZ58: =+E58/1000 -> 896.866 | BA58: =+O58/1000 -> 58.494 | BB58: =+Y58/1000 -> 376.369 | BC58: =+AI58/1000 -> 1.6 | BD58: =+AS58/1000 -> 1333.329 | BE58: =BE57+AZ58 -> 27658.915 | BF58: =BF57+BA58 -> 2651.528 | BG58: =BG57+BB58 -> 8622.578 | BH58: =BH57+BC58 -> 636.064 | BI58: =BI57+BD58 -> 39569.085 | BJ58: 49
A59: 37968 | B59: 953441 | C59: 52450 | D59: 0 | E59: =SUM(B59:D59) -> 1005891 | F59: =AVERAGE(E56,E57,E58,E59) -> 871206.25 | L59: 23100 | M59: 13200 | O59: =SUM(L59:N59) -> 36300 | P59: =AVERAGE(O56,O57,O58,O59) -> 42685 | V59: 265090 | W59: 10250 | X59: 0 | Y59: =SUM(V59:X59) -> 275340 | Z59: =AVERAGE(Y56,Y57,Y58,Y59) -> 286755.25 | AF59: 0 | AG59: 0 | AH59: 0 | AI59: =SUM(AF59:AH59) -> 0 | AJ59: =AVERAGE(AI56,AI57,AI58,AI59) -> 1900 | AP59: =SUM(B59,L59,V59,AF59) -> 1241631 | AQ59: =SUM(C59,M59,W59,AG59) -> 75900 | AR59: =SUM(D59,N59,X59,AH59) -> 0 | AS59: =SUM(E59,O59,Y59,AI59) -> 1317531 | AT59: =AVERAGE(AS56,AS57,AS58,AS59) -> 1202546.5 | AZ59: =+E59/1000 -> 1005.891 | BA59: =+O59/1000 -> 36.3 | BB59: =+Y59/1000 -> 275.34 | BC59: =+AI59/1000 -> 0 | BD59: =+AS59/1000 -> 1317.531 | BE59: =BE58+AZ59 -> 28664.806 | BF59: =BF58+BA59 -> 2687.828 | BG59: =BG58+BB59 -> 8897.918 | BH59: =BH58+BC59 -> 636.064 | BI59: =BI58+BD59 -> 40886.616 | BJ59: 50
A60: 37975 | B60: 519841 | C60: 103329 | D60: 0 | E60: =SUM(B60:D60) -> 623170 | F60: =AVERAGE(E57,E58,E59,E60) -> 815767.25 | L60: 10764 | M60: 14583 | N60: 27100 | O60: =SUM(L60:N60) -> 52447 | P60: =AVERAGE(O57,O58,O59,O60) -> 48083.75 | V60: 71251 | W60: 46629 | X60: 18300 | Y60: =SUM(V60:X60) -> 136180 | Z60: =AVERAGE(Y57,Y58,Y59,Y60) -> 266010.5 | AF60: 27400 | AG60: 21150 | AH60: 0 | AI60: =SUM(AF60:AH60) -> 48550 | AJ60: =AVERAGE(AI57,AI58,AI59,AI60) -> 12537.5 | AP60: =SUM(B60,L60,V60,AF60) -> 629256 | AQ60: =SUM(C60,M60,W60,AG60) -> 185691 | AR60: =SUM(D60,N60,X60,AH60) -> 45400 | AS60: =SUM(E60,O60,Y60,AI60) -> 860347 | AT60: =AVERAGE(AS57,AS58,AS59,AS60) -> 1142399 | AZ60: =+E60/1000 -> 623.17 | BA60: =+O60/1000 -> 52.447 | BB60: =+Y60/1000 -> 136.18 | BC60: =+AI60/1000 -> 48.55 | BD60: =+AS60/1000 -> 860.347 | BE60: =BE59+AZ60 -> 29287.976 | BF60: =BF59+BA60 -> 2740.275 | BG60: =BG59+BB60 -> 9034.098 | BH60: =BH59+BC60 -> 684.614 | BI60: =BI59+BD60 -> 41746.963 | BJ60: 51
A61: 37982 | B61: 506413 | C61: 103329 | D61: 0 | E61: =SUM(B61:D61) -> 609742 | F61: =AVERAGE(E58,E59,E60,E61) -> 783917.25 | L61: 15700 | M61: 14583 | N61: 16800 | O61: =SUM(L61:N61) -> 47083 | P61: =AVERAGE(O58,O59,O60,O61) -> 48581 | V61: 54683 | W61: 46629 | X61: 10100 | Y61: =SUM(V61:X61) -> 111412 | Z61: =AVERAGE(Y58,Y59,Y60,Y61) -> 224825.25 | AF61: 0 | AG61: 10450 | AH61: 0 | AI61: =SUM(AF61:AH61) -> 10450 | AJ61: =AVERAGE(AI58,AI59,AI60,AI61) -> 15150 | AP61: =SUM(B61,L61,V61,AF61) -> 576796 | AQ61: =SUM(C61,M61,W61,AG61) -> 174991 | AR61: =SUM(D61,N61,X61,AH61) -> 26900 | AS61: =SUM(E61,O61,Y61,AI61) -> 778687 | AT61: =AVERAGE(AS58,AS59,AS60,AS61) -> 1072473.5 | AZ61: =+E61/1000 -> 609.742 | BA61: =+O61/1000 -> 47.083 | BB61: =+Y61/1000 -> 111.412 | BC61: =+AI61/1000 -> 10.45 | BD61: =+AS61/1000 -> 778.687 | BE61: =BE60+AZ61 -> 29897.718 | BF61: =BF60+BA61 -> 2787.358 | BG61: =BG60+BB61 -> 9145.51 | BH61: =BH60+BC61 -> 695.064 | BI61: =BI60+BD61 -> 42525.65 | BJ61: 52
A62: 37989 | B62: 372917 | C62: 65875 | D62: 0 | E62: =SUM(B62:D62) -> 438792 | F62: =AVERAGE(E59,E60,E61,E62) -> 669398.75 | H62: =((E62/E10)-1)*100 -> 12.118355 | L62: 3000 | M62: 11054 | N62: 13100 | O62: =SUM(L62:N62) -> 27154 | P62: =AVERAGE(O59,O60,O61,O62) -> 40746 | R62: =((O62/O10)-1)*100 -> 32.232773 | V62: 42800 | W62: 48151 | X62: 8500 | Y62: =SUM(V62:X62) -> 99451 | Z62: =AVERAGE(Y59,Y60,Y61,Y62) -> 155595.75 | AB62: =((Y62/Y10)-1)*100 -> -44.508674 | AF62: 0 | AG62: 0 | AH62: 8000 | AI62: =SUM(AF62:AH62) -> 8000 | AJ62: =AVERAGE(AI59,AI60,AI61,AI62) -> 16750 | AL62: =((AI62/AI10)-1)*100 -> -71.942623 | AP62: =SUM(B62,L62,V62,AF62) -> 418717 | AQ62: =SUM(C62,M62,W62,AG62) -> 125080 | AR62: =SUM(D62,N62,X62,AH62) -> 29600 | AS62: =SUM(E62,O62,Y62,AI62) -> 573397 | AT62: =AVERAGE(AS59,AS60,AS61,AS62) -> 882490.5 | AV62: =((AS62/AS10)-1)*100 -> -7.4616869 | AZ62: =+E62/1000 -> 438.792 | BA62: =+O62/1000 -> 27.154 | BB62: =+Y62/1000 -> 99.451 | BC62: =+AI62/1000 -> 8 | BD62: =+AS62/1000 -> 573.397 | BE62: =BE61+AZ62 -> 30336.51 | BF62: =BF61+BA62 -> 2814.512 | BG62: =BG61+BB62 -> 9244.961 | BH62: =BH61+BC62 -> 703.064 | BI62: =BI61+BD62 -> 43099.047 | BJ62: 53
A63: 37996 | B63: 413456 | C63: 84552 | D63: 0 | E63: =SUM(B63:D63) -> 498008 | F63: =AVERAGE(E60,E61,E62,E63) -> 542428 | H63: =((E63/E11)-1)*100 -> 2.0939167 | L63: 10500 | M63: 15393 | N63: 11300 | O63: =SUM(L63:N63) -> 37193 | P63: =AVERAGE(O60,O61,O62,O63) -> 40969.25 | R63: =((O63/O11)-1)*100 -> -11.60309 | V63: 54472 | W63: 91916 | X63: 0 | Y63: =SUM(V63:X63) -> 146388 | Z63: =AVERAGE(Y60,Y61,Y62,Y63) -> 123357.75 | AB63: =((Y63/Y11)-1)*100 -> -36.017553 | AF63: 0 | AG63: 19225 | AH63: 0 | AI63: =SUM(AF63:AH63) -> 19225 | AJ63: =AVERAGE(AI60,AI61,AI62,AI63) -> 21556.25 | AL63: =((AI63/AI11)-1)*100 -> -67.293297 | AP63: =SUM(B63,L63,V63,AF63) -> 478428 | AQ63: =SUM(C63,M63,W63,AG63) -> 211086 | AR63: =SUM(D63,N63,X63,AH63) -> 11300 | AS63: =SUM(E63,O63,Y63,AI63) -> 700814 | AT63: =AVERAGE(AS60,AS61,AS62,AS63) -> 728311.25 | AV63: =((AS63/AS11)-1)*100 -> -14.267539 | AZ63: =+E63/1000 -> 498.008 | BA63: =+O63/1000 -> 37.193 | BB63: =+Y63/1000 -> 146.388 | BC63: =+AI63/1000 -> 19.225 | BD63: =+AS63/1000 -> 700.814 | BE63: =AZ63 -> 498.008 | BF63: =BA63 -> 37.193 | BG63: =BB63 -> 146.388 | BH63: =BC63 -> 19.225 | BI63: =BD63 -> 700.814 | BJ63: 1
A64: 38003 | B64: 425615 | C64: 173006 | D64: 0 | E64: =SUM(B64:D64) -> 598621 | F64: =AVERAGE(E61,E62,E63,E64) -> 536290.75 | H64: =((E64/E12)-1)*100 -> 2.8455927 | L64: 0 | M64: 1500 | N64: 38900 | O64: =SUM(L64:N64) -> 40400 | P64: =AVERAGE(O61,O62,O63,O64) -> 37957.5 | R64: =((O64/O12)-1)*100 -> 57.290247 | V64: 72687 | W64: 129367 | X64: 10200 | Y64: =SUM(V64:X64) -> 212254 | Z64: =AVERAGE(Y61,Y62,Y63,Y64) -> 142376.25 | AB64: =((Y64/Y12)-1)*100 -> -48.086133 | AF64: 1535 | AG64: 19500 | AH64: 0 | AI64: =SUM(AF64:AH64) -> 21035 | AJ64: =AVERAGE(AI61,AI62,AI63,AI64) -> 14677.5 | AL64: =((AI64/AI12)-1)*100 -> 16.634322 | AP64: =SUM(B64,L64,V64,AF64) -> 499837 | AQ64: =SUM(C64,M64,W64,AG64) -> 323373 | AR64: =SUM(D64,N64,X64,AH64) -> 49100 | AS64: =SUM(E64,O64,Y64,AI64) -> 872310 | AT64: =AVERAGE(AS61,AS62,AS63,AS64) -> 731302 | AV64: =((AS64/AS12)-1)*100 -> -15.689189 | AZ64: =+E64/1000 -> 598.621 | BA64: =+O64/1000 -> 40.4 | BB64: =+Y64/1000 -> 212.254 | BC64: =+AI64/1000 -> 21.035 | BD64: =+AS64/1000 -> 872.31 | BE64: =BE63+AZ64 -> 1096.629 | BF64: =BF63+BA64 -> 77.593 | BG64: =BG63+BB64 -> 358.642 | BH64: =BH63+BC64 -> 40.26 | BI64: =BI63+BD64 -> 1573.124 | BJ64: 2
A65: 38010 | B65: 378386 | C65: 128101 | D65: 0 | E65: =SUM(B65:D65) -> 506487 | F65: =AVERAGE(E62,E63,E64,E65) -> 510477 | H65: =((E65/E13)-1)*100 -> -5.6174436 | I65: =((F65/F13)-1)*100 -> 2.2053218 | L65: 51725 | M65: 10624 | N65: 9200 | O65: =SUM(L65:N65) -> 71549 | P65: =AVERAGE(O62,O63,O64,O65) -> 44074 | R65: =((O65/O13)-1)*100 -> 81.481294 | S65: =((P65/P13)-1)*100 -> 38.033198 | V65: 51725 | W65: 81931 | X65: 9800 | Y65: =SUM(V65:X65) -> 143456 | Z65: =AVERAGE(Y62,Y63,Y64,Y65) -> 150387.25 | AB65: =((Y65/Y13)-1)*100 -> -50.838739 | AC65: =((Z65/Z13)-1)*100 -> -45.741775 | AF65: 1500 | AG65: 23238 | AH65: 0 | AI65: =SUM(AF65:AH65) -> 24738 | AJ65: =AVERAGE(AI62,AI63,AI64,AI65) -> 18249.5 | AL65: =((AI65/AI13)-1)*100 -> 36.976744 | AM65: =((AJ65/AJ13)-1)*100 -> -40.838655 | AP65: =SUM(B65,L65,V65,AF65) -> 483336 | AQ65: =SUM(C65,M65,W65,AG65) -> 243894 | AR65: =SUM(D65,N65,X65,AH65) -> 19000 | AS65: =SUM(E65,O65,Y65,AI65) -> 746230 | AT65: =AVERAGE(AS62,AS63,AS64,AS65) -> 723187.75 | AV65: =((AS65/AS13)-1)*100 -> -15.76817 | AW65: =((AT65/AT13)-1)*100 -> -13.845579 | AZ65: =+E65/1000 -> 506.487 | BA65: =+O65/1000 -> 71.549 | BB65: =+Y65/1000 -> 143.456 | BC65: =+AI65/1000 -> 24.738 | BD65: =+AS65/1000 -> 746.23 | BE65: =BE64+AZ65 -> 1603.116 | BF65: =BF64+BA65 -> 149.142 | BG65: =BG64+BB65 -> 502.098 | BH65: =BH64+BC65 -> 64.998 | BI65: =BI64+BD65 -> 2319.354 | BJ65: 3
A66: 38017 | B66: 241188 | C66: 173737 | D66: 0 | E66: =SUM(B66:D66) -> 414925 | F66: =AVERAGE(E63,E64,E65,E66) -> 504510.25 | H66: =((E66/E14)-1)*100 -> 26.013606 | I66: =((F66/F14)-1)*100 -> 4.2509017 | L66: 7983 | M66: 13890 | N66: 34000 | O66: =SUM(L66:N66) -> 55873 | P66: =AVERAGE(O63,O64,O65,O66) -> 51253.75 | R66: =((O66/O14)-1)*100 -> 163.55189 | S66: =((P66/P14)-1)*100 -> 59.687658 | V66: 66641 | W66: 130707 | X66: 19300 | Y66: =SUM(V66:X66) -> 216648 | Z66: =AVERAGE(Y63,Y64,Y65,Y66) -> 179686.5 | AB66: =((Y66/Y14)-1)*100 -> -17.857332 | AC66: =((Z66/Z14)-1)*100 -> -39.76341 | AF66: 9000 | AG66: 20950 | AH66: 0 | AI66: =SUM(AF66:AH66) -> 29950 | AJ66: =AVERAGE(AI63,AI64,AI65,AI66) -> 23737 | AL66: =((AI66/AI14)-1)*100 -> 105.51705 | AM66: =((AJ66/AJ14)-1)*100 -> -13.248301 | AP66: =SUM(B66,L66,V66,AF66) -> 324812 | AQ66: =SUM(C66,M66,W66,AG66) -> 339284 | AR66: =SUM(D66,N66,X66,AH66) -> 53300 | AS66: =SUM(E66,O66,Y66,AI66) -> 717396 | AT66: =AVERAGE(AS63,AS64,AS65,AS66) -> 759187.5 | AV66: =((AS66/AS14)-1)*100 -> 14.091691 | AW66: =((AT66/AT14)-1)*100 -> -9.8028628 | AZ66: =+E66/1000 -> 414.925 | BA66: =+O66/1000 -> 55.873 | BB66: =+Y66/1000 -> 216.648 | BC66: =+AI66/1000 -> 29.95 | BD66: =+AS66/1000 -> 717.396 | BE66: =BE65+AZ66 -> 2018.041 | BF66: =BF65+BA66 -> 205.015 | BG66: =BG65+BB66 -> 718.746 | BH66: =BH65+BC66 -> 94.948 | BI66: =BI65+BD66 -> 3036.75 | BJ66: 4
A67: 38024 | B67: 178264 | C67: 154722 | D67: 0 | E67: =SUM(B67:D67) -> 332986 | F67: =AVERAGE(E64,E65,E66,E67) -> 463254.75 | H67: =((E67/E15)-1)*100 -> 5.8317998 | I67: =((F67/F15)-1)*100 -> 5.1300439 | L67: 6200 | M67: 13630 | N67: 37700 | O67: =SUM(L67:N67) -> 57530 | P67: =AVERAGE(O64,O65,O66,O67) -> 56338 | R67: =((O67/O15)-1)*100 -> 23.17739 | S67: =((P67/P15)-1)*100 -> 69.418487 | V67: 39464 | W67: 75265 | X67: 15600 | Y67: =SUM(V67:X67) -> 130329 | Z67: =AVERAGE(Y64,Y65,Y66,Y67) -> 175671.75 | AB67: =((Y67/Y15)-1)*100 -> -51.401873 | AC67: =((Z67/Z15)-1)*100 -> -42.990926 | AF67: 1600 | AG67: 25500 | AH67: 0 | AI67: =SUM(AF67:AH67) -> 27100 | AJ67: =AVERAGE(AI64,AI65,AI66,AI67) -> 25705.75 | AL67: =((AI67/AI15)-1)*100 -> -19.152745 | AM67: =((AJ67/AJ15)-1)*100 -> 22.134984 | AP67: =SUM(B67,L67,V67,AF67) -> 225528 | AQ67: =SUM(C67,M67,W67,AG67) -> 269117 | AR67: =SUM(D67,N67,X67,AH67) -> 53300 | AS67: =SUM(E67,O67,Y67,AI67) -> 547945 | AT67: =AVERAGE(AS64,AS65,AS66,AS67) -> 720970.25 | AV67: =((AS67/AS15)-1)*100 -> -17.358557 | AW67: =((AT67/AT15)-1)*100 -> -10.226255 | AZ67: =+E67/1000 -> 332.986 | BA67: =+O67/1000 -> 57.53 | BB67: =+Y67/1000 -> 130.329 | BC67: =+AI67/1000 -> 27.1 | BD67: =+AS67/1000 -> 547.945 | BE67: =BE66+AZ67 -> 2351.027 | BF67: =BF66+BA67 -> 262.545 | BG67: =BG66+BB67 -> 849.075 | BH67: =BH66+BC67 -> 122.048 | BI67: =BI66+BD67 -> 3584.695 | BJ67: 5
A68: 38031 | B68: 173210 | C68: 148509 | D68: 0 | E68: =SUM(B68:D68) -> 321719 | F68: =AVERAGE(E65,E66,E67,E68) -> 394029.25 | H68: =((E68/E16)-1)*100 -> -11.122192 | I68: =((F68/F16)-1)*100 -> 2.1781918 | L68: 4859 | M68: 1493 | N68: 23000 | O68: =SUM(L68:N68) -> 29352 | P68: =AVERAGE(O65,O66,O67,O68) -> 53576 | R68: =((O68/O16)-1)*100 -> -36.329718 | S68: =((P68/P16)-1)*100 -> 39.675422 | V68: 40285 | W68: 54293 | X68: 14000 | Y68: =SUM(V68:X68) -> 108578 | Z68: =AVERAGE(Y65,Y66,Y67,Y68) -> 149752.75 | AB68: =((Y68/Y16)-1)*100 -> -45.538357 | AC68: =((Z68/Z16)-1)*100 -> -41.451144 | AF68: 0 | AG68: 1500 | AH68: 0 | AI68: =SUM(AF68:AH68) -> 1500 | AJ68: =AVERAGE(AI65,AI66,AI67,AI68) -> 20822 | AL68: =((AI68/AI16)-1)*100 -> -96.336907 | AM68: =((AJ68/AJ16)-1)*100 -> -22.234879 | AP68: =SUM(B68,L68,V68,AF68) -> 218354 | AQ68: =SUM(C68,M68,W68,AG68) -> 205795 | AR68: =SUM(D68,N68,X68,AH68) -> 37000 | AS68: =SUM(E68,O68,Y68,AI68) -> 461149 | AT68: =AVERAGE(AS65,AS66,AS67,AS68) -> 618180 | AV68: =((AS68/AS16)-1)*100 -> -28.878275 | AW68: =((AT68/AT16)-1)*100 -> -12.505582 | AZ68: =+E68/1000 -> 321.719 | BA68: =+O68/1000 -> 29.352 | BB68: =+Y68/1000 -> 108.578 | BC68: =+AI68/1000 -> 1.5 | BD68: =+AS68/1000 -> 461.149 | BE68: =BE67+AZ68 -> 2672.746 | BF68: =BF67+BA68 -> 291.897 | BG68: =BG67+BB68 -> 957.653 | BH68: =BH67+BC68 -> 123.548 | BI68: =BI67+BD68 -> 4045.844 | BJ68: 6
A69: 38038 | B69: 239587 | C69: 112199 | D69: 0 | E69: =SUM(B69:D69) -> 351786 | F69: =AVERAGE(E66,E67,E68,E69) -> 355354 | H69: =((E69/E17)-1)*100 -> 1.5680443 | I69: =((F69/F17)-1)*100 -> 5.1155822 | L69: 3248 | M69: 10500 | N69: 44000 | O69: =SUM(L69:N69) -> 57748 | P69: =AVERAGE(O66,O67,O68,O69) -> 50125.75 | R69: =((O69/O17)-1)*100 -> 38.817308 | S69: =((P69/P17)-1)*100 -> 28.853829 | V69: 18920 | W69: 61900 | X69: 4400 | Y69: =SUM(V69:X69) -> 85220 | Z69: =AVERAGE(Y66,Y67,Y68,Y69) -> 135193.75 | AB69: =((Y69/Y17)-1)*100 -> -52.203346 | AC69: =((Z69/Z17)-1)*100 -> -40.547128 | AF69: 29629 | AG69: 4700 | AH69: 0 | AI69: =SUM(AF69:AH69) -> 34329 | AJ69: =AVERAGE(AI66,AI67,AI68,AI69) -> 23219.75 | AL69: =((AI69/AI17)-1)*100 -> 63.869397 | AM69: =((AJ69/AJ17)-1)*100 -> -15.557637 | AP69: =SUM(B69,L69,V69,AF69) -> 291384 | AQ69: =SUM(C69,M69,W69,AG69) -> 189299 | AR69: =SUM(D69,N69,X69,AH69) -> 48400 | AS69: =SUM(E69,O69,Y69,AI69) -> 529083 | AT69: =AVERAGE(AS66,AS67,AS68,AS69) -> 563893.25 | AV69: =((AS69/AS17)-1)*100 -> -9.8974627 | AW69: =((AT69/AT17)-1)*100 -> -10.756015 | AZ69: =+E69/1000 -> 351.786 | BA69: =+O69/1000 -> 57.748 | BB69: =+Y69/1000 -> 85.22 | BC69: =+AI69/1000 -> 34.329 | BD69: =+AS69/1000 -> 529.083 | BE69: =BE68+AZ69 -> 3024.532 | BF69: =BF68+BA69 -> 349.645 | BG69: =BG68+BB69 -> 1042.873 | BH69: =BH68+BC69 -> 157.877 | BI69: =BI68+BD69 -> 4574.927 | BJ69: 7
...

Sheet Table 10
A1: Table 10
A2: Barge Grain Movements (1,000 tons)
A3: Week ending 4/12/2014 | B3: Corn | C3: Wheat | D3: Soybeans | E3: Other | F3: Total
A4: Mississippi River
A5: Rock Island, IL (L15) | B5: =17200/1000 -> 17.2 | C5: 0 | D5: =12500/1000 -> 12.5 | E5: 0 | F5: =SUM(B5:E5) -> 29.7
A6: Winfield, MO (L25) | B6: =127100/1000 -> 127.1 | C6: 0 | D6: =112700/1000 -> 112.7 | E6: =1600/1000 -> 1.6 | F6: =SUM(B6:E6) -> 241.4
A7: Alton, IL (L26) | B7: =261100/1000 -> 261.1 | C7: =17644/1000 -> 17.644 | D7: =139076/1000 -> 139.076 | E7: =3200/1000 -> 3.2 | F7: =SUM(B7:E7) -> 421.02
A8: Granite City, IL (L27) | B8: =Data!B598/1000 -> 277.4 | C8: =Data!L598/1000 -> 17.644 | D8: =Data!V598/1000 -> 125.276 | E8: =Data!AF598/1000 -> 3.2 | F8: =SUM(B8:E8) -> 423.52
A9: Illinois River (L8) | B9: =171200/1000 -> 171.2 | C9: =6300/1000 -> 6.3 | D9: =30900/1000 -> 30.9 | E9: =1600/1000 -> 1.6 | F9: =SUM(B9:E9) -> 210
A10: Ohio River (L52) | B10: =Data!C598/1000 -> 203.45 | C10: =Data!M598/1000 -> 21.15 | D10: =Data!W598/1000 -> 31.95 | E10: =Data!AG598/1000 -> 0 | F10: =SUM(B10:E10) -> 256.55 | G10: n/a
A11: Arkansas River (L1) | B11: =Data!D598/1000 -> 4.2 | C11: =Data!N598/1000 -> 21 | D11: =Data!X598/1000 -> 0 | E11: =Data!AH598/1000 -> 2.8 | F11: =SUM(B11:E11) -> 28
A13: Weekly total - 2014 | B13: =Data!AZ598 -> 485.05 | C13: =+Data!BA598 -> 59.794 | D13: =+Data!BB598 -> 157.226 | E13: =+Data!BC598 -> 6 | F13: =+Data!BD598 -> 708.07 | J13: =(+F13-F14)/F14 -> 1.0973637
A14: Weekly total - 2013 | B14: =Data!AZ546 -> 170.6 | C14: =Data!BA546 -> 84.55 | D14: =Data!BB546 -> 82.45 | E14: =Data!BC546 -> 0 | F14: =Data!BD546 -> 337.6
A15: 2014 YTD1 | B15: =Data!BE598 -> 5068.409 | C15: =Data!BF598 -> 503.911 | D15: =Data!BG598 -> 3659.981 | E15: =Data!BH598 -> 58.75 | F15: =Data!BI598 -> 9291.051
A16: 2013 YTD | B16: =Data!BE546 -> 1872.053 | C16: =Data!BF546 -> 1271.05 | D16: =Data!BG546 -> 3083.267 | E16: =Data!BH546 -> 84.77 | F16: =Data!BI546 -> 6311.14
A17: 2014 as % of 2013 YTD | B17: =(B15/B16)*100 -> 270.74068 | C17: =(C15/C16)*100 -> 39.645254 | D17: =(D15/D16)*100 -> 118.70464 | E17: =(E15/E16)*100 -> 69.305179 | F17: =(F15/F16)*100 -> 147.21668
A18: Last 4 weeks as % of 20132 | B18: =+Data!I598+100 -> 313.50854 | C18: =+Data!S598+100 -> 74.370968 | D18: =+Data!AC598+100 -> 143.17387 | E18: =+Data!AM598+100 -> 54.545455 | F18: =+Data!AW598+100 -> 205.87794
A19: Total 2013 | B19: =Data!BE583 -> 9504.445 | C19: =Data!BF583 -> 4110.692 | D19: =Data!BG583 -> 10064.815 | E19: =Data!BH583 -> 254.728 | F19: =Data!BI583 -> 23934.68
A20: 1 Weekly total, YTD (year-to-date) and calendar year total includes Miss/27, Ohio/52, and Ark/1; "Other" refers to oats, barley, sorghum, and rye.
A21: 2 As a percent of same period in 2013.
A22: Note: Total may not add exactly, due to rounding
A23: Source: U.S. Army Corps of Engineers
