Workbook
Name _Toc251576535: Ledelsespåtegning!$A$1
Name _Toc516985418: Noter!#REF!

Sheet Forside
G1: Indsæt logo
A17: ÅRSREGNSKAB FOR 2011
A19: (NAVN)
A47: Afleveringsfrist 1. april 2013

Sheet Ledelsespåtegning
A1: Ledelsespåtegning
A2: Bestyrelse har dags dato behandlet og godkendt årsrapporten for regnskabsåret 1. januar – 31. december 2012 for BAR XX
A3: Årsrapporten er aflagt i overensstemmelse med årsregnskabsloven og bekendtgørelse om branchearbejdsmiljørådenes arbejdsmiljøindsats, finansiering, regnskab m.v.
A4: Det er vores opfattelse, at årsregnskabet giver et retvisende billede aktiver, passiver og finansielle stilling pr. 31. december 2010 samt af resultatet af aktiviteter for regnskabsåret 1. januar – 31. december 2012.
A6: By, den 22. februar 2013
A8: Bestyrelse

Sheet Resultatopgørelse
A1: RESULTATOPGØRELSE
G2: 2012 | I2: Budget 2012
A3: INDTÆGTER
A4: Note
A5: =1 -> 1 | B5: Tilskud | G5: =Noter!N9 | I5: =Noter!P9
A6: =A5+1 -> 2 | B6: Renteindtægter | G6: =Noter!N14 | I6: =Noter!P14
A7: =A6+1 -> 3 | B7: Øvrige indtægter | G7: =Noter!N22 | I7: =Noter!P22
B9: INDTÆGTER I ALT | G9: =IF(SUM(G5:G7)=0,"",SUM(G5:G7)) | I9: =IF(SUM(I5:I7)=0," ",SUM(I5:I7))
A11: UDGIFTER
A12: Note
A13: =$A$7+1 -> 4 | B13: Personaleomkostninger | G13: =Noter!N31 | I13: =Noter!P31
A14: =A13+1 -> 5 | B14: Partskonsulentbistand m.v. | G14: =Noter!N39 | I14: =Noter!P39
A15: =A14+1 -> 6 | B15: Ekstern konsulentbistand | G15: =Noter!N45 | I15: =Noter!P45
A16: =A15+1 -> 7 | B16: Mødeudgifter | I16: =Noter!P50
A17: =A16+1 -> 8 | B17: Rejseudgifter | G17: =Noter!N56 | I17: =Noter!P56
A18: =A17+1 -> 9 | B18: Husleje | G18: =Noter!N61 | I18: =Noter!P61
A19: =A18+1 -> 10 | B19: Kontorhold og it | G19: =Noter!N74 | I19: =Noter!P74
A20: =A19+1 -> 11 | B20: Tryk og web | G20: =Noter!N78 | I20: =Noter!P78
A21: =A20+1 -> 12 | B21: Renteudgifter | G21: =Noter!N83 | I21: =Noter!P83
B23: UDGIFTER I ALT | G23: =IF(SUM(G13:G21)=0,"",SUM(G13:G21)) | I23: =IF(SUM(I13:I21)=0," ",SUM(I13:I21))
B25: ÅRETS RESULTAT | G25: =G9-G23 -> #VALUE! | I25: =I9-I23 -> #VALUE!

Sheet Balance
A1: BALANCE
G2: 2012 | I2: Budget 2012
A3: AKTIVER
A5: Note | B5: Omsætningsaktiver
A6: =Resultatopgørelse!A21+1 -> 13 | B6: Tilgodehavender | G6: =Noter!N90 | I6: =Noter!P90
A7: =A6+1 -> 14 | B7: Periodeafgræsningsposter | G7: =Noter!N95 | I7: =Noter!P95
B8: OMSÆTNINGSAKTIVER I ALT | G8: =SUM(G6:G7) -> 0 | I8: =SUM(I6:I7) -> 0
A10: =A7+1 -> 15 | B10: Likvide midler | G10: =Noter!N100 | I10: =Noter!P100
B12: AKTIVER I ALT
A14: PASSIVER
A16: =A10+1 -> 16 | B16: Egenkapital | G16: =Noter!N107 | I16: =Noter!P107
B18: Gæld
A19: =A16+1 -> 17 | B19: Kreditorer | G19: =Noter!N111 | I19: =Noter!P111
A20: =A19+1 -> 18 | B20: Gæld til Arbejdstilsynet | G20: =Noter!N115 | I20: =Noter!P115
A21: =A20+1 -> 19 | B21: Anden gæld | G21: =Noter!N121 | I21: =Noter!P121
A22: =A21+1 -> 20 | B22: Periodeafgrænsningsposter | G22: =Noter!N130 | I22: =Noter!P130
B23: Gæld i alt | G23: =SUM(G19:G22) -> 0 | I23: =SUM(I19:I22) -> 0
B25: PASSIVER I ALT | G25: =SUM(G23+G16) -> #VALUE! | I25: =I23+I16 -> #VALUE!
A27: =A22+1 -> 21 | B27: Eventualforpligtelser

Sheet Noter
A1: NOTER
A2: Note | B2: Beskrivelse | N2: 2012 | P2: Budget 2012
A3: INDTÆGTER
A4: 1 | B4: Tilskud | N4: KR. | P4: KR.
B5: Modtaget tilskud
B6: Tilbagebetaling af tilskud
B7: Tilskud overført fra tidligere år (tillæg)
B8: Tilskud overført til næste år (fradrag)
B9: TILSKUD I ALT | N9: =IF(SUM(N5:N8)=0,"",SUM(N5:N8)) | O9: =IF(SUM(O5:O8)=0,"",SUM(O5:O8)) | P9: =IF(SUM(P5:P8)=0,"",SUM(P5:P8))
A11: =A4+1 -> 2 | B11: Renteindtægter
B12: Renteindtægter af likvide beholdninger
B13: Renteindtægter øvrige
B14: RENTEINDTÆGTER I ALT | N14: =IF(SUM(N12:N13)=0,"",SUM(N12:N13)) | P14: =IF(SUM(P12:P13)=0,"",SUM(P12:P13))
A16: =A11+1 -> 3 | B16: Øvrige indtægter
B17: Salg af materiale
B18: Deltagerbetaling fra kursus, seminar og konference
B19: Tilskud fra organisationerne
B20: Adm. Indtægt (fællesekretariat)
B21: [art]
B22: ØVRIGE INDTÆGTER I ALT | N22: =IF(SUM(N17:N21)=0,"",SUM(N17:N21)) | P22: =IF(SUM(P17:P21)=0,"",SUM(P17:P21))
A24: OMKOSTNINGER
A25: =A16+1 -> 4 | B25: Personaleomkostninger | D25: Indsats #A | E25: Indsats #B | F25: Indsats #C | G25: Indsats #D | H25: Indsats #E | I25: Indsats #F | J25: Indsats #G | K25: Indsats #H | L25: ADM. | N25: Total
B26: Gager og lønninger | N26: =IF(SUM(D26:L26)=0," ",SUM(D26:L26))
B27: Pensioner
B28: Andre omkostninger til social sikring | N28: =IF(SUM(D28:L28)=0," ",SUM(D28:L28))
B29: Efteruddannelse, interne kurser m.v. | N29: =IF(SUM(D29:L29)=0," ",SUM(D29:L29))
B30: Øvrige personaleomkostninger | N30: =IF(SUM(D30:L30)=0," ",SUM(D30:L30))
B31: PERSONALEOMKOSTNINGER I ALT | D31: =IF(SUM(D26:D30)=0,"",SUM(D26:D30)) | E31: =IF(SUM(E26:E30)=0,"",SUM(E26:E30)) | F31: =IF(SUM(F26:F30)=0,"",SUM(F26:F30)) | G31: =IF(SUM(G26:G30)=0,"",SUM(G26:G30)) | H31: =IF(SUM(H26:H30)=0,"",SUM(H26:H30)) | L31: =IF(SUM(L26:L30)=0,"",SUM(L26:L30)) | M31: =IF(SUM(M26:M30)=0,"",SUM(M26:M30)) | N31: =IF(SUM(N26:N30)=0,"",SUM(N26:N30)) | P31: =IF(SUM(P26:P30)=0,"",SUM(P26:P30))
B33: Antal medarbejdere , Fuldtidsmedarbejdere
A35: =A25+1 -> 5 | B35: Partskonsulentbistand | D35: Indsats #A | E35: Indsats #B | F35: Indsats #C | G35: Indsats #D | H35: Indsats #E | I35: Indsats #F | J35: Indsats #G | K35: Indsats #H | L35: ADM. | N35: Total
B36: Partskonsulenter | N36: =IF(SUM(D36:L36)=0," ",SUM(D36:L36))
B37: Sekretærbistand | N37: =IF(SUM(D37:L37)=0," ",SUM(D37:L37))
B38: [art] | N38: =IF(SUM(D38:L38)=0," ",SUM(D38:L38))
B39: PARTSKONSULENTBISTAND I ALT | D39: =IF(SUM(D36:D38)=0,"",SUM(D36:D38)) | E39: =IF(SUM(E36:E38)=0,"",SUM(E36:E38)) | F39: =IF(SUM(F36:F38)=0,"",SUM(F36:F38)) | G39: =IF(SUM(G36:G38)=0,"",SUM(G36:G38)) | H39: =IF(SUM(H36:H38)=0,"",SUM(H36:H38)) | L39: =IF(SUM(L36:L38)=0,"",SUM(L36:L38)) | N39: =IF(SUM(D39:L39)=0," ",SUM(D39:L39)) | P39: =IF(SUM(P36:P38)=0," ",SUM(P36:P38))
A41: =A35+1 -> 6 | B41: Ekstern konsulentbistand | D41: Indsats #A | E41: Indsats #B | F41: Indsats #C | G41: Indsats #D | H41: Indsats #E | I41: Indsats #F | J41: Indsats #G | K41: Indsats #H | L41: ADM. | N41: =IF(SUM(D41:L41)=0," ",SUM(D41:L41))
B42: Bogføring og regnskabsassistance | N42: =IF(SUM(D42:L42)=0," ",SUM(D42:L42))
B43: [art] | N43: =IF(SUM(D43:L43)=0," ",SUM(D43:L43))
B44: [art] | N44: =IF(SUM(D44:L44)=0," ",SUM(D44:L44))
B45: EKSTERN KONSULENTBISTAND I ALT | D45: =IF(SUM(D42:D44)=0,"",SUM(D42:D44)) | E45: =IF(SUM(E42:E44)=0,"",SUM(E42:E44)) | F45: =IF(SUM(F42:F44)=0,"",SUM(F42:F44)) | G45: =IF(SUM(G42:G44)=0,"",SUM(G42:G44)) | H45: =IF(SUM(H42:H44)=0,"",SUM(H42:H44)) | L45: =IF(SUM(L42:L44)=0,"",SUM(L42:L44)) | N45: =IF(SUM(N42:N44)=0,"",SUM(N42:N44)) | P45: =IF(SUM(P42:P44)=0," ",SUM(P42:P44))
A47: =A41+1 -> 7 | B47: Mødeudgifter | D47: Indsats #A | E47: Indsats #B | F47: Indsats #C | G47: Indsats #D | H47: Indsats #E | I47: Indsats #F | J47: Indsats #G | K47: Indsats #H | L47: ADM.
...
