Workbook

Sheet RATS_q
A1: Quarter | B1: 18264 | C1: 18354 | D1: 18445 | E1: 18537 | F1: 18629 | G1: 18719 | H1: 18810 | I1: 18902 | J1: 18994 | K1: 19085 | L1: 19176 | M1: 19268 | N1: 19360 | O1: 19450 | P1: 19541 | Q1: 19633 | R1: 19725 | S1: 19815 | T1: 19906 | U1: 19998 | V1: 20090 | W1: 20180 | X1: 20271 | Y1: 20363 | Z1: 20455 | AA1: 20546 | AB1: 20637 | AC1: 20729 | AD1: 20821 | AE1: 20911 | AF1: 21002 | AG1: 21094 | AH1: 21186 | AI1: 21276 | AJ1: 21367 | AK1: 21459 | AL1: 21551 | AM1: 21641 | AN1: 21732 | AO1: 21824 | AP1: 21916 | AQ1: 22007 | AR1: 22098 | AS1: 22190 | AT1: 22282 | AU1: 22372 | AV1: 22463 | AW1: 22555 | AX1: 22647 | AY1: 22737 | AZ1: 22828 | BA1: 22920 | BB1: 23012 | BC1: 23102 | BD1: 23193 | BE1: 23285 | BF1: 23377 | BG1: 23468 | BH1: 23559 | BI1: 23651 | BJ1: 23743 | BK1: 23833 | BL1: 23924 | BM1: 24016 | BN1: 24108 | BO1: 24198 | BP1: 24289 | BQ1: 24381 | BR1: 24473 | BS1: 24563 | BT1: 24654 | BU1: 24746 | BV1: 24838 | BW1: 24929 | BX1: 25020 | BY1: 25112 | BZ1: 25204 | CA1: 25294 | CB1: 25385 | CC1: 25477 | CD1: 25569 | CE1: 25659 | CF1: 25750 | CG1: 25842 | CH1: 25934 | CI1: 26024 | CJ1: 26115 | CK1: 26207 | CL1: 26299 | CM1: 26390 | CN1: 26481 | CO1: 26573 | CP1: 26665 | CQ1: 26755 | CR1: 26846 | CS1: 26938 | CT1: 27030 | CU1: 27120 | CV1: 27211 | CW1: 27303 | CX1: 27395 | CY1: 27485 | CZ1: 27576 | DA1: 27668 | DB1: 27760 | DC1: 27851 | DD1: 27942 | DE1: 28034 | DF1: 28126 | DG1: 28216 | DH1: 28307 | DI1: 28399 | DJ1: 28491 | DK1: 28581 | DL1: 28672 | DM1: 28764 | DN1: 28856 | DO1: 28946 | DP1: 29037 | DQ1: 29129 | DR1: 29221 | DS1: 29312 | DT1: 29403 | DU1: 29495 | DV1: 29587 | DW1: 29677 | DX1: 29768 | DY1: 29860 | DZ1: 29952 | EA1: 30042 | EB1: 30133 | EC1: 30225 | ED1: 30317 | EE1: 30407 | EF1: 30498 | EG1: 30590 | EH1: 30682 | EI1: 30773 | EJ1: 30864 | EK1: 30956 | EL1: 31048 | EM1: 31138 | EN1: 31229 | EO1: 31321 | EP1: 31413 | EQ1: 31503 | ER1: 31594 | ES1: 31686 | ET1: 31778 | EU1: 31868 | EV1: 31959 | EW1: 32051 | EX1: 32143 | EY1: 32234 | EZ1: 32325 | FA1: 32417 | FB1: 32509 | FC1: 32599 | FD1: 32690 | FE1: 32782 | FF1: 32874 | FG1: 32964 | FH1: 33055 | FI1: 33147 | FJ1: 33239 | FK1: 33329 | FL1: 33420 | FM1: 33512 | FN1: 33604 | FO1: 33695 | FP1: 33786 | FQ1: 33878 | FR1: 33970 | FS1: 34060 | FT1: 34151 | FU1: 34243 | FV1: 34335 | FW1: 34425 | FX1: 34516 | FY1: 34608 | FZ1: 34700 | GA1: 34790 | GB1: 34881 | GC1: 34973 | GD1: 35065 | GE1: 35156 | GF1: 35247 | GG1: 35339 | GH1: 35431 | GI1: 35521 | GJ1: 35612 | GK1: 35704 | GL1: 35796 | GM1: 35886 | GN1: 35977 | GO1: 36069 | GP1: 36161 | GQ1: 36251 | GR1: 36342 | GS1: 36434 | GT1: 36526 | GU1: 36617 | GV1: 36708 | GW1: 36800 | GX1: 36892 | GY1: 36982 | GZ1: 37073 | HA1: 37165 | HB1: 37257 | HC1: 37347 | HD1: 37438 | HE1: 37530 | HF1: 37622 | HG1: 37712 | HH1: 37803 | HI1: 37895 | HJ1: 37987 | HK1: 38078 | HL1: 38169 | HM1: 38261 | HN1: 38353 | HO1: 38443 | HP1: 38534 | HQ1: 38626 | HR1: 38718 | HS1: 38808 | HT1: 38899 | HU1: 38991 | HV1: 39083 | HW1: 39173 | HX1: 39264 | HY1: 39356 | HZ1: 39448 | IA1: 39539 | IB1: 39630 | IC1: 39722 | ID1: 39814 | IE1: 39904 | IF1: 39995 | IG1: 40087 | IH1: 40179 | II1: 40269 | IJ1: 40360 | IK1: 40452 | IL1: 40544 | IM1: 40634 | IN1: 40725 | IO1: 40817 | IP1: 40909 | IQ1: 41000 | IR1: 41091 | IS1: 41183 | IT1: 41275 | IU1: 41365 | IV1: 41456 | IW1: 41548 | IX1: 41640 | IY1: 41730 | IZ1: 41821 | JA1: 41913
A2: Index | B2: 1 | C2: 2 | D2: 3 | E2: 4 | F2: 5 | G2: 6 | H2: 7 | I2: 8 | J2: 9 | K2: 10 | L2: 11 | M2: 12 | N2: 13 | O2: 14 | P2: 15 | Q2: 16 | R2: 17 | S2: 18 | T2: 19 | U2: 20 | V2: 21 | W2: 22 | X2: 23 | Y2: 24 | Z2: 25 | AA2: 26 | AB2: 27 | AC2: 28 | AD2: 29 | AE2: 30 | AF2: 31 | AG2: 32 | AH2: 33 | AI2: 34 | AJ2: 35 | AK2: 36 | AL2: 37 | AM2: 38 | AN2: 39 | AO2: 40 | AP2: 41 | AQ2: 42 | AR2: 43 | AS2: 44 | AT2: 45 | AU2: 46 | AV2: 47 | AW2: 48 | AX2: 49 | AY2: 50 | AZ2: 51 | BA2: 52 | BB2: 53 | BC2: 54 | BD2: 55 | BE2: 56 | BF2: 57 | BG2: 58 | BH2: 59 | BI2: 60 | BJ2: 61 | BK2: 62 | BL2: 63 | BM2: 64 | BN2: 65 | BO2: 66 | BP2: 67 | BQ2: 68 | BR2: 69 | BS2: 70 | BT2: 71 | BU2: 72 | BV2: 73 | BW2: 74 | BX2: 75 | BY2: 76 | BZ2: 77 | CA2: 78 | CB2: 79 | CC2: 80 | CD2: 81 | CE2: 82 | CF2: 83 | CG2: 84 | CH2: 85 | CI2: 86 | CJ2: 87 | CK2: 88 | CL2: 89 | CM2: 90 | CN2: 91 | CO2: 92 | CP2: 93 | CQ2: 94 | CR2: 95 | CS2: 96 | CT2: 97 | CU2: 98 | CV2: 99 | CW2: 100 | CX2: 101 | CY2: 102 | CZ2: 103 | DA2: 104 | DB2: 105 | DC2: 106 | DD2: 107 | DE2: 108 | DF2: 109 | DG2: 110 | DH2: 111 | DI2: 112 | DJ2: 113 | DK2: 114 | DL2: 115 | DM2: 116 | DN2: 117 | DO2: 118 | DP2: 119 | DQ2: 120 | DR2: 121 | DS2: 122 | DT2: 123 | DU2: 124 | DV2: 125 | DW2: 126 | DX2: 127 | DY2: 128 | DZ2: 129 | EA2: 130 | EB2: 131 | EC2: 132 | ED2: 133 | EE2: 134 | EF2: 135 | EG2: 136 | EH2: 137 | EI2: 138 | EJ2: 139 | EK2: 140 | EL2: 141 | EM2: 142 | EN2: 143 | EO2: 144 | EP2: 145 | EQ2: 146 | ER2: 147 | ES2: 148 | ET2: 149 | EU2: 150 | EV2: 151 | EW2: 152 | EX2: 153 | EY2: 154 | EZ2: 155 | FA2: 156 | FB2: 157 | FC2: 158 | FD2: 159 | FE2: 160 | FF2: 161 | FG2: 162 | FH2: 163 | FI2: 164 | FJ2: 165 | FK2: 166 | FL2: 167 | FM2: 168 | FN2: 169 | FO2: 170 | FP2: 171 | FQ2: 172 | FR2: 173 | FS2: 174 | FT2: 175 | FU2: 176 | FV2: 177 | FW2: 178 | FX2: 179 | FY2: 180 | FZ2: 181 | GA2: 182 | GB2: 183 | GC2: 184 | GD2: 185 | GE2: 186 | GF2: 187 | GG2: 188 | GH2: 189 | GI2: 190 | GJ2: 191 | GK2: 192 | GL2: 193 | GM2: 194 | GN2: 195 | GO2: 196 | GP2: 197 | GQ2: 198 | GR2: 199 | GS2: 200 | GT2: 201 | GU2: 202 | GV2: 203 | GW2: 204 | GX2: 205 | GY2: 206 | GZ2: 207 | HA2: 208 | HB2: 209 | HC2: 210 | HD2: 211 | HE2: 212 | HF2: 213 | HG2: 214 | HH2: 215 | HI2: 216 | HJ2: 217 | HK2: 218 | HL2: 219 | HM2: 220 | HN2: 221 | HO2: 222 | HP2: 223 | HQ2: 224 | HR2: 225 | HS2: 226 | HT2: 227 | HU2: 228 | HV2: 229 | HW2: 230 | HX2: 231 | HY2: 232 | HZ2: 233 | IA2: 234 | IB2: 235 | IC2: 236 | ID2: 237 | IE2: 238 | IF2: 239 | IG2: 240 | IH2: 241 | II2: 242 | IJ2: 243 | IK2: 244 | IL2: 245 | IM2: 246 | IN2: 247 | IO2: 248 | IP2: 249 | IQ2: 250 | IR2: 251 | IS2: 252 | IT2: 253 | IU2: 254 | IV2: 255 | IW2: 256 | IX2: 257 | IY2: 258 | IZ2: 259 | JA2: 260
A3: GDP | B3: =[1]q!B3 -> 1913 | C3: =[1]q!C3 -> 1971.2 | D3: =[1]q!D3 -> 2048.4 | E3: =[1]q!E3 -> 2084.4 | F3: =[1]q!F3 -> 2110.7 | G3: =[1]q!G3 -> 2145.7 | H3: =[1]q!H3 -> 2188.5 | I3: =[1]q!I3 -> 2192.2 | ... IN3: =[1]q!IN3 -> 13352.8
A4: PCON | B4: =[1]q!B4 -> 1244.9 | C4: =[1]q!C4 -> 1265.4 | D4: =[1]q!D4 -> 1330.3 | E4: =[1]q!E4 -> 1290.2 | F4: =[1]q!F4 -> 1321.4 | G4: =[1]q!G4 -> 1284.1 | H4: =[1]q!H4 -> 1299.1 | I4: =[1]q!I4 -> 1306.7 | ... IN4: =[1]q!IN4 -> 9449.5
A5: PDUR | FZ5: =[1]q!FZ5 -> 497.3 | GA5: =[1]q!GA5 -> 502.4 | GB5: =[1]q!GB5 -> 516.6 | GC5: =[1]q!GC5 -> 525.5 | GD5: =[1]q!GD5 -> 531.2 | GE5: =[1]q!GE5 -> 548.1 | GF5: =[1]q!GF5 -> 552 | GG5: =[1]q!GG5 -> 562.8 | ... IN5: =[1]q!IN5 -> 1273
A6: PNDUR | FZ6: =[1]q!FZ9 -> 1428 | GA6: =[1]q!GA9 -> 1435 | GB6: =[1]q!GB9 -> 1440.1 | GC6: =[1]q!GC9 -> 1447.5 | GD6: =[1]q!GD9 -> 1456.9 | GE6: =[1]q!GE9 -> 1475.6 | GF6: =[1]q!GF9 -> 1486.1 | GG6: =[1]q!GG9 -> 1498.2 | ... IN6: =[1]q!IN9 -> 2077.7
A7: FINV | B7: =[1]q!B21 -> 214.9 | C7: =[1]q!C21 -> 238.9 | D7: =[1]q!D21 -> 260.4 | E7: =[1]q!E21 -> 295 | F7: =[1]q!F21 -> 263.9 | G7: =[1]q!G21 -> 270.4 | H7: =[1]q!H21 -> 249.5 | I7: =[1]q!I21 -> 228.3 | ... IN7: =[1]q!IN21 -> 1796.6
A8: NRESINV | FZ8: =[1]q!FZ22 -> 777.3 | GA8: =[1]q!GA22 -> 782.6 | GB8: =[1]q!GB22 -> 787.9 | GC8: =[1]q!GC22 -> 803.8 | GD8: =[1]q!GD22 -> 823.7 | GE8: =[1]q!GE22 -> 847.4 | GF8: =[1]q!GF22 -> 875.6 | GG8: =[1]q!GG22 -> 899.3 | ... IN8: =[1]q!IN22 -> 1467.5
A9: Structures | FZ9: =[1]q!FZ23 -> 336.5 | GA9: =[1]q!GA23 -> 343.2 | GB9: =[1]q!GB23 -> 345.7 | GC9: =[1]q!GC23 -> 342.8 | GD9: =[1]q!GD23 -> 348.9 | GE9: =[1]q!GE23 -> 356.5 | GF9: =[1]q!GF23 -> 360.9 | GG9: =[1]q!GG23 -> 379.3 | ... IN9: =[1]q!IN23 -> 332.1
A10: Equipment | FZ10: =[1]q!FZ24 -> 483.2 | GA10: =[1]q!GA24 -> 484.4 | GB10: =[1]q!GB24 -> 487.6 | GC10: =[1]q!GC24 -> 502.3 | GD10: =[1]q!GD24 -> 516 | GE10: =[1]q!GE24 -> 532.1 | GF10: =[1]q!GF24 -> 553.6 | GG10: =[1]q!GG24 -> 564 | ... IN10: =[1]q!IN24 -> 1148.7
A11: RESINV | FZ11: =[1]q!FZ25 -> 457.7 | GA11: =[1]q!GA25 -> 443 | GB11: =[1]q!GB25 -> 456.7 | GC11: =[1]q!GC25 -> 467 | GD11: =[1]q!GD25 -> 479.3 | GE11: =[1]q!GE25 -> 499.5 | GF11: =[1]q!GF25 -> 498.2 | GG11: =[1]q!GG25 -> 493 | ... IN11: =[1]q!IN25 -> 326.3
A12: EXPORT | B12: =[1]q!B30 -> 52.4 | C12: =[1]q!C30 -> 53.1 | D12: =[1]q!D30 -> 54.4 | E12: =[1]q!E30 -> 58.8 | F12: =[1]q!F30 -> 61.8 | G12: =[1]q!G30 -> 67.9 | H12: =[1]q!H30 -> 69.5 | I12: =[1]q!I30 -> 68.9 | ... IN12: =[1]q!IN30 -> 1782.4
A13: IMPORT | B13: =[1]q!B33 -> 56.4 | C13: =[1]q!C33 -> 59.5 | D13: =[1]q!D33 -> 73.4 | E13: =[1]q!E33 -> 73.6 | F13: =[1]q!F33 -> 73.6 | G13: =[1]q!G33 -> 71.1 | H13: =[1]q!H33 -> 65.1 | I13: =[1]q!I33 -> 63.4 | ... IN13: =[1]q!IN33 -> 2191.8
A14: GOV | B14: =[1]q!B36 -> 483.5 | C14: =[1]q!C36 -> 491.4 | D14: =[1]q!D36 -> 482 | E14: =[1]q!E36 -> 512.7 | F14: =[1]q!F36 -> 567.5 | G14: =[1]q!G36 -> 645.6 | H14: =[1]q!H36 -> 718.8 | I14: =[1]q!I36 -> 758.9 | ... IN14: =[1]q!IN36 -> 2508.2
A15: DISPINCOME | B15: =[1]q!B147 -> 204.9 | C15: =[1]q!C147 -> 204.7 | D15: =[1]q!D147 -> 212.2 | E15: =[1]q!E147 -> 218 | F15: =[1]q!F147 -> 225.1 | G15: =[1]q!G147 -> 230.4 | H15: =[1]q!H147 -> 232.2 | I15: =[1]q!I147 -> 235.7 | ... IN15: =[1]q!IN147 -> 11608.5
A16: SRATIO | B16: =[1]q!B155 -> 9.3 | C16: =[1]q!C155 -> 7.3 | D16: =[1]q!D155 -> 4.1 | E16: =[1]q!E155 -> 7.8 | F16: =[1]q!F155 -> 5.6 | G16: =[1]q!G155 -> 9.7 | H16: =[1]q!H155 -> 9.2 | I16: =[1]q!I155 -> 8.9 | ... IN16: =[1]q!IN155 -> 4.1
A17: TCBCEO_F | DC17: =INDEX([2]Surveys_q!$D$69:$D$369,DC$2-105,1) -> 74 | DD17: =INDEX([2]Surveys_q!$D$69:$D$369,DD$2-105,1) -> 71 | DE17: =INDEX([2]Surveys_q!$D$69:$D$369,DE$2-105,1) -> 67 | DF17: =INDEX([2]Surveys_q!$D$69:$D$369,DF$2-105,1) -> 71 | DG17: =INDEX([2]Surveys_q!$D$69:$D$369,DG$2-105,1) -> 70 | DH17: =INDEX([2]Surveys_q!$D$69:$D$369,DH$2-105,1) -> 56 | DI17: =INDEX([2]Surveys_q!$D$69:$D$369,DI$2-105,1) -> 49 | DJ17: =INDEX([2]Surveys_q!$D$69:$D$369,DJ$2-105,1) -> 49 | ... IN17: =INDEX([2]Surveys_q!$D$69:$D$369,IN$2-105,1) -> 45
A18: TCBCEO_P | DC18: =INDEX([2]Surveys_q!$C$69:$C$369,DC$2-105,1) -> 81 | DD18: =INDEX([2]Surveys_q!$C$69:$C$369,DD$2-105,1) -> 80 | DE18: =INDEX([2]Surveys_q!$C$69:$C$369,DE$2-105,1) -> 60 | DF18: =INDEX([2]Surveys_q!$C$69:$C$369,DF$2-105,1) -> 65 | DG18: =INDEX([2]Surveys_q!$C$69:$C$369,DG$2-105,1) -> 74 | DH18: =INDEX([2]Surveys_q!$C$69:$C$369,DH$2-105,1) -> 62 | DI18: =INDEX([2]Surveys_q!$C$69:$C$369,DI$2-105,1) -> 48 | DJ18: =INDEX([2]Surveys_q!$C$69:$C$369,DJ$2-105,1) -> 46 | ... IN18: =INDEX([2]Surveys_q!$C$69:$C$369,IN$2-105,1) -> 32
A19: LOSURV_LM_Standards | FG19: =INDEX([2]Surveys_q!$U$125:$U$307,FG2-161,1) -> 56.9 | FH19: =INDEX([2]Surveys_q!$U$125:$U$307,FH2-161,1) -> 39.45 | FI19: =INDEX([2]Surveys_q!$U$125:$U$307,FI2-161,1) -> 48.9 | FJ19: =INDEX([2]Surveys_q!$U$125:$U$307,FJ2-161,1) -> 36 | FK19: =INDEX([2]Surveys_q!$U$125:$U$307,FK2-161,1) -> 15.5 | FL19: =INDEX([2]Surveys_q!$U$125:$U$307,FL2-161,1) -> 12.25 | FM19: =INDEX([2]Surveys_q!$U$125:$U$307,FM2-161,1) -> 9 | FN19: =INDEX([2]Surveys_q!$U$125:$U$307,FN2-161,1) -> 5.25 | ... IN19: =INDEX([2]Surveys_q!$U$125:$U$307,IN2-161,1) -> -21.8
A20: LOSURV_LM_Demand | FM20: =INDEX([2]Surveys_q!$T$125:$T$307,FM2-161,1) -> -29.65 | FN20: =INDEX([2]Surveys_q!$T$125:$T$307,FN2-161,1) -> -26.5 | FO20: =INDEX([2]Surveys_q!$T$125:$T$307,FO2-161,1) -> 6.25 | FP20: =INDEX([2]Surveys_q!$T$125:$T$307,FP2-161,1) -> -8.6 | FQ20: =INDEX([2]Surveys_q!$T$125:$T$307,FQ2-161,1) -> 6.15 | FR20: =INDEX([2]Surveys_q!$T$125:$T$307,FR2-161,1) -> 20.2 | FS20: =INDEX([2]Surveys_q!$T$125:$T$307,FS2-161,1) -> -0.1 | FT20: =INDEX([2]Surveys_q!$T$125:$T$307,FT2-161,1) -> 18.05 | ... IN20: =INDEX([2]Surveys_q!$T$125:$T$307,IN2-161,1) -> 20
A21: HHLoanSvy | BP21: =INDEX([2]Surveys_q!$AC$30:$AC$307,BP2-66,1) -> -25 | BQ21: =INDEX([2]Surveys_q!$AC$30:$AC$307,BQ2-66,1) -> 4 | BR21: =INDEX([2]Surveys_q!$AC$30:$AC$307,BR2-66,1) -> 25 | BS21: =INDEX([2]Surveys_q!$AC$30:$AC$307,BS2-66,1) -> 34 | BT21: =INDEX([2]Surveys_q!$AC$30:$AC$307,BT2-66,1) -> 19 | BU21: =INDEX([2]Surveys_q!$AC$30:$AC$307,BU2-66,1) -> 19 | BV21: =INDEX([2]Surveys_q!$AC$30:$AC$307,BV2-66,1) -> 24 | BW21: =INDEX([2]Surveys_q!$AC$30:$AC$307,BW2-66,1) -> 0 | ... IN21: =INDEX([2]Surveys_q!$AC$30:$AC$307,IN2-66,1) -> 26.9
A22: GDPDEFL | B22: =[1]q!B171 -> 14.374 | C22: =[1]q!C171 -> 14.433 | D22: =[1]q!D171 -> 14.727 | E22: =[1]q!E171 -> 14.977 | F22: =[1]q!F171 -> 15.493 | G22: =[1]q!G171 -> 15.582 | H22: =[1]q!H171 -> 15.632 | I22: =[1]q!I171 -> 15.834 | ... IN22: =[1]q!IN171 -> 113.797
A23: FFR | R23: =[3]q!N101 -> 1.1666667 | S23: =[3]q!O101 -> 0.8 | T23: =[3]q!P101 -> 1.0266667 | U23: =[3]q!Q101 -> 0.98666667 | V23: =[3]q!R101 -> 1.3433333 | W23: =[3]q!S101 -> 1.5 | X23: =[3]q!T101 -> 1.94 | Y23: =[3]q!U101 -> 2.3566667 | ... IN23: =[3]q!IJ101 -> 0.07
A24: ALQ | AP24: =[3]q!AL72 -> 4.590969 | AQ24: =[3]q!AM72 -> -5.706681 | AR24: =[3]q!AN72 -> 1.1413022 | AS24: =[3]q!AO72 -> -7.0649479 | AT24: =[3]q!AP72 -> 2.0969694 | AU24: =[3]q!AQ72 -> 3.2960402 | AV24: =[3]q!AR72 -> 3.4817443 | AW24: =[3]q!AS72 -> -0.67918548 | ... IN24: =[3]q!IJ72 -> -1.0658554 | IO24: =IF(ISNUMBER('[4]Fortschreibung von Monatswerten'!IO15),'[4]Fortschreibung von Monatswerten'!IO15,"") | IP24: =IF(ISNUMBER('[4]Fortschreibung von Monatswerten'!IP15),'[4]Fortschreibung von Monatswerten'!IP15,"") | IQ24: =IF(ISNUMBER('[4]Fortschreibung von Monatswerten'!IQ15),'[4]Fortschreibung von Monatswerten'!IQ15,"") | IR24: =IF(ISNUMBER('[4]Fortschreibung von Monatswerten'!IR15),'[4]Fortschreibung von Monatswerten'!IR15,"") | IS24: =IF(ISNUMBER('[4]Fortschreibung von Monatswerten'!IS15),'[4]Fortschreibung von Monatswerten'!IS15,"") | IT24: =IF(ISNUMBER('[4]Fortschreibung von Monatswerten'!IT15),'[4]Fortschreibung von Monatswerten'!IT15,"") | IU24: =IF(ISNUMBER('[4]Fortschreibung von Monatswerten'!IU15),'[4]Fortschreibung von Monatswerten'!IU15,"") | IV24: =IF(ISNUMBER('[4]Fortschreibung von Monatswerten'!IV15),'[4]Fortschreibung von Monatswerten'!IV15,"")
A25: CPI | B25: =[5]q!B$3 -> 23.587 | C25: =[5]q!C$3 -> 23.767 | D25: =[5]q!D$3 -> 24.203 | E25: =[5]q!E$3 -> 24.693 | F25: =[5]q!F$3 -> 25.697 | G25: =[5]q!G$3 -> 25.947 | H25: =[5]q!H$3 -> 25.933 | I25: =[5]q!I$3 -> 26.317 | ... IN25: =[5]q!IN$3 -> 226.216 | IO25: =IF(ISNUMBER('[4]Fortschreibung von Monatswerten'!IO17),'[4]Fortschreibung von Monatswerten'!IO17,"") | IP25: =IF(ISNUMBER('[4]Fortschreibung von Monatswerten'!IP17),'[4]Fortschreibung von Monatswerten'!IP17,"") | IQ25: =IF(ISNUMBER('[4]Fortschreibung von Monatswerten'!IQ17),'[4]Fortschreibung von Monatswerten'!IQ17,"") | IR25: =IF(ISNUMBER('[4]Fortschreibung von Monatswerten'!IR17),'[4]Fortschreibung von Monatswerten'!IR17,"") | IS25: =IF(ISNUMBER('[4]Fortschreibung von Monatswerten'!IS17),'[4]Fortschreibung von Monatswerten'!IS17,"") | IT25: =IF(ISNUMBER('[4]Fortschreibung von Monatswerten'!IT17),'[4]Fortschreibung von Monatswerten'!IT17,"") | IU25: =IF(ISNUMBER('[4]Fortschreibung von Monatswerten'!IU17),'[4]Fortschreibung von Monatswerten'!IU17,"") | IV25: =IF(ISNUMBER('[4]Fortschreibung von Monatswerten'!IV17),'[4]Fortschreibung von Monatswerten'!IV17,"")
A26: CPI_CORE | AD26: =[5]q!AD$5 -> 28.6 | AE26: =[5]q!AE$5 -> 28.833 | AF26: =[5]q!AF$5 -> 29.033 | AG26: =[5]q!AG$5 -> 29.267 | AH26: =[5]q!AH$5 -> 29.4 | AI26: =[5]q!AI$5 -> 29.533 | AJ26: =[5]q!AJ$5 -> 29.633 | AK26: =[5]q!AK$5 -> 29.8 | ... IN26: =[5]q!IN$5 -> 225.871 | IO26: =IF(ISNUMBER('[4]Fortschreibung von Monatswerten'!IO18),'[4]Fortschreibung von Monatswerten'!IO18,"") | IP26: =IF(ISNUMBER('[4]Fortschreibung von Monatswerten'!IP18),'[4]Fortschreibung von Monatswerten'!IP18,"") | IQ26: =IF(ISNUMBER('[4]Fortschreibung von Monatswerten'!IQ18),'[4]Fortschreibung von Monatswerten'!IQ18,"") | IR26: =IF(ISNUMBER('[4]Fortschreibung von Monatswerten'!IR18),'[4]Fortschreibung von Monatswerten'!IR18,"") | IS26: =IF(ISNUMBER('[4]Fortschreibung von Monatswerten'!IS18),'[4]Fortschreibung von Monatswerten'!IS18,"") | IT26: =IF(ISNUMBER('[4]Fortschreibung von Monatswerten'!IT18),'[4]Fortschreibung von Monatswerten'!IT18,"") | IU26: =IF(ISNUMBER('[4]Fortschreibung von Monatswerten'!IU18),'[4]Fortschreibung von Monatswerten'!IU18,"") | IV26: =IF(ISNUMBER('[4]Fortschreibung von Monatswerten'!IV18),'[4]Fortschreibung von Monatswerten'!IV18,"")
A27: PPI | C27: ='[4]Fortschreibung von Monatswerten'!C19 -> 26.366667 | D27: ='[4]Fortschreibung von Monatswerten'!D19 -> 27.866667 | E27: ='[4]Fortschreibung von Monatswerten'!E19 -> 29.1 | F27: ='[4]Fortschreibung von Monatswerten'!F19 -> 30.766667 | G27: ='[4]Fortschreibung von Monatswerten'!G19 -> 30.666667 | H27: ='[4]Fortschreibung von Monatswerten'!H19 -> 30.166667 | I27: ='[4]Fortschreibung von Monatswerten'!I19 -> 30.1 | J27: ='[4]Fortschreibung von Monatswerten'!J19 -> 29.866667 | ... W27: ='[4]Fortschreibung von Monatswerten'!W19 -> 29.233333 | X27: =[5]q!X$18 -> 29.4 | Y27: =[5]q!Y$18 -> 29.5 | Z27: =[5]q!Z$18 -> 29.8 | AA27: =[5]q!AA$18 -> 30.2 | AB27: =[5]q!AB$18 -> 30.4 | AC27: =[5]q!AC$18 -> 30.7 | AD27: =[5]q!AD$18 -> 31 | AE27: =[5]q!AE$18 -> 31.1 | ... IN27: =[5]q!IN$18 -> 203.9
A28: INFL_EXP_1 | DJ28: =[5]q!DJ$10 -> 7.4 | DK28: =[5]q!DK$10 -> 8.3 | DL28: =[5]q!DL$10 -> 8.9 | DM28: =[5]q!DM$10 -> 8.6 | DN28: =[5]q!DN$10 -> 10.4 | DO28: =[5]q!DO$10 -> 11.7 | DP28: =[5]q!DP$10 -> 11 | DQ28: =[5]q!DQ$10 -> 11 | ... IN28: =[5]q!IN$10 -> 4.4
A29: POEL | AD29: =[5]q!AD23 -> 2.08 | AE29: =[5]q!AE23 -> 2.08 | AF29: =[5]q!AF23 -> 2.08 | AG29: =[5]q!AG23 -> 2.08 | AH29: =[5]q!AH23 -> 2.21 | AI29: =[5]q!AI23 -> 2.21 | AJ29: =[5]q!AJ23 -> 2.21 | AK29: =[5]q!AK23 -> 2.21 | ... IN29: =[5]q!IN23 -> 113.26
A30: LSK | B30: =[5]q!B24 -> 18.467 | C30: =[5]q!C24 -> 18.442 | D30: =[5]q!D24 -> 18.453 | E30: =[5]q!E24 -> 18.757 | F30: =[5]q!F24 -> 19.405 | G30: =[5]q!G24 -> 19.828 | H30: =[5]q!H24 -> 19.616 | I30: =[5]q!I24 -> 19.852 | ... IN30: =[5]q!IN24 -> 106.927
A31: GDPN | B31: =[1]q!B72 -> 275.2 | C31: =[1]q!C72 -> 284.5 | D31: =[1]q!D72 -> 301.9 | E31: =[1]q!E72 -> 313.3 | F31: =[1]q!F72 -> 329 | G31: =[1]q!G72 -> 336.6 | H31: =[1]q!H72 -> 343.5 | I31: =[1]q!I72 -> 347.9 | ... IN31: =[1]q!IN72 -> 15198.6
A32: BUDGETSALDO | B32: =[6]q!B5 -> -8.3 | C32: =[6]q!C5 -> 2.8 | D32: =[6]q!D5 -> 13.6 | E32: =[6]q!E5 -> 14.2 | F32: =[6]q!F5 -> 17.3 | G32: =[6]q!G5 -> 10.1 | H32: =[6]q!H5 -> 5.4 | I32: =[6]q!I5 -> 6 | ... IN32: =[6]q!IN5 -> NA
A33: CBAAA | R33: =[3]q!N104 -> 2.9566667 | S33: =[3]q!O104 -> 2.8766667 | T33: =[3]q!P104 -> 2.8833333 | U33: =[3]q!Q104 -> 2.8866667 | V33: =[3]q!R104 -> 2.96 | W33: =[3]q!S104 -> 3.0333333 | X33: =[3]q!T104 -> 3.1 | Y33: =[3]q!U104 -> 3.1166667 | ... IN33: =[3]q!IJ104 -> 4.93
A34: CBBAA | R34: =[3]q!N105 -> 3.61 | S34: =[3]q!O105 -> 3.4766667 | T34: =[3]q!P105 -> 3.4866667 | U34: =[3]q!Q105 -> 3.4533333 | V34: =[3]q!R105 -> 3.4666667 | W34: =[3]q!S105 -> 3.5 | X34: =[3]q!T105 -> 3.5566667 | Y34: =[3]q!U105 -> 3.5966667 | ... IN34: =[3]q!IJ105 -> 5.76
A35: T3M | R35: =[3]q!N102 -> 1.1666667 | S35: =[3]q!O102 -> 0.8 | T35: =[3]q!P102 -> 1.0266667 | U35: =[3]q!Q102 -> 0.98666667 | V35: =[3]q!R102 -> 1.3433333 | W35: =[3]q!S102 -> 1.5 | X35: =[3]q!T102 -> 1.94 | Y35: =[3]q!U102 -> 2.3566667 | ... IN35: =[3]q!IJ102 -> 0.06 | IO35: =IF(ISNUMBER('[4]Fortschreibung von Monatswerten'!IO28),'[4]Fortschreibung von Monatswerten'!IO28,"") | IP35: =IF(ISNUMBER('[4]Fortschreibung von Monatswerten'!IP28),'[4]Fortschreibung von Monatswerten'!IP28,"") | IQ35: =IF(ISNUMBER('[4]Fortschreibung von Monatswerten'!IQ28),'[4]Fortschreibung von Monatswerten'!IQ28,"") | IR35: =IF(ISNUMBER('[4]Fortschreibung von Monatswerten'!IR28),'[4]Fortschreibung von Monatswerten'!IR28,"") | IS35: =IF(ISNUMBER('[4]Fortschreibung von Monatswerten'!IS28),'[4]Fortschreibung von Monatswerten'!IS28,"") | IT35: =IF(ISNUMBER('[4]Fortschreibung von Monatswerten'!IT28),'[4]Fortschreibung von Monatswerten'!IT28,"") | IU35: =IF(ISNUMBER('[4]Fortschreibung von Monatswerten'!IU28),'[4]Fortschreibung von Monatswerten'!IU28,"") | IV35: =IF(ISNUMBER('[4]Fortschreibung von Monatswerten'!IV28),'[4]Fortschreibung von Monatswerten'!IV28,"")
A36: T10Y | R36: =[3]q!N103 -> 2.44 | S36: =[3]q!O103 -> 2.3466667 | T36: =[3]q!P103 -> 2.3466667 | U36: =[3]q!Q103 -> 2.4733333 | V36: =[3]q!R103 -> 2.6466667 | W36: =[3]q!S103 -> 2.7633333 | X36: =[3]q!T103 -> 2.9466667 | Y36: =[3]q!U103 -> 2.91 | ... IN36: =[3]q!IJ103 -> 3 | IO36: =IF(ISNUMBER('[4]Fortschreibung von Monatswerten'!IO29),'[4]Fortschreibung von Monatswerten'!IO29,"") | IP36: =IF(ISNUMBER('[4]Fortschreibung von Monatswerten'!IP29),'[4]Fortschreibung von Monatswerten'!IP29,"") | IQ36: =IF(ISNUMBER('[4]Fortschreibung von Monatswerten'!IQ29),'[4]Fortschreibung von Monatswerten'!IQ29,"") | IR36: =IF(ISNUMBER('[4]Fortschreibung von Monatswerten'!IR29),'[4]Fortschreibung von Monatswerten'!IR29,"") | IS36: =IF(ISNUMBER('[4]Fortschreibung von Monatswerten'!IS29),'[4]Fortschreibung von Monatswerten'!IS29,"") | IT36: =IF(ISNUMBER('[4]Fortschreibung von Monatswerten'!IT29),'[4]Fortschreibung von Monatswerten'!IT29,"") | IU36: =IF(ISNUMBER('[4]Fortschreibung von Monatswerten'!IU29),'[4]Fortschreibung von Monatswerten'!IU29,"") | IV36: =IF(ISNUMBER('[4]Fortschreibung von Monatswerten'!IV29),'[4]Fortschreibung von Monatswerten'!IV29,"")
A37: EMP_NA | AP37: =[3]q!AL71 -> 0.63 | AQ37: =[3]q!AM71 -> -1.76 | AR37: =[3]q!AN71 -> -0.6 | AS37: =[3]q!AO71 -> -0.02 | AT37: =[3]q!AP71 -> 0.07 | AU37: =[3]q!AQ71 -> 0.07 | AV37: =[3]q!AR71 -> 1.02 | AW37: =[3]q!AS71 -> 0.66 | ... IN37: =[3]q!IJ71 -> 0.052197151
A38: O_mfexcldef | FO38: =AVERAGE(INDEX(RATS_m!$AM$509:$AM$761,(FO2-170)*3+1,1):INDEX(RATS_m!$AM$509:$AM$761,(FO2-169)*3,1)) -> 116654.67 | FP38: =AVERAGE(INDEX(RATS_m!$AM$509:$AM$761,(FP2-170)*3+1,1):INDEX(RATS_m!$AM$509:$AM$761,(FP2-169)*3,1)) -> 114974 | FQ38: =AVERAGE(INDEX(RATS_m!$AM$509:$AM$761,(FQ2-170)*3+1,1):INDEX(RATS_m!$AM$509:$AM$761,(FQ2-169)*3,1)) -> 116005 | FR38: =AVERAGE(INDEX(RATS_m!$AM$509:$AM$761,(FR2-170)*3+1,1):INDEX(RATS_m!$AM$509:$AM$761,(FR2-169)*3,1)) -> 118531 | FS38: =AVERAGE(INDEX(RATS_m!$AM$509:$AM$761,(FS2-170)*3+1,1):INDEX(RATS_m!$AM$509:$AM$761,(FS2-169)*3,1)) -> 121420.67 | FT38: =AVERAGE(INDEX(RATS_m!$AM$509:$AM$761,(FT2-170)*3+1,1):INDEX(RATS_m!$AM$509:$AM$761,(FT2-169)*3,1)) -> 120547.33 | FU38: =AVERAGE(INDEX(RATS_m!$AM$509:$AM$761,(FU2-170)*3+1,1):INDEX(RATS_m!$AM$509:$AM$761,(FU2-169)*3,1)) -> 126004.33 | FV38: =AVERAGE(INDEX(RATS_m!$AM$509:$AM$761,(FV2-170)*3+1,1):INDEX(RATS_m!$AM$509:$AM$761,(FV2-169)*3,1)) -> 131026.67 | ... IN38: =AVERAGE(INDEX(RATS_m!$AM$509:$AM$761,(IN2-170)*3+1,1):INDEX(RATS_m!$AM$509:$AM$761,(IN2-169)*3,1)) -> 191186.67
A39: BIPOECD | AT39: =[7]q!AT$21 -> 22.6 | AU39: =[7]q!AU$21 -> 22.9 | AV39: =[7]q!AV$21 -> 23.2 | AW39: =[7]q!AW$21 -> 23.6 | AX39: =[7]q!AX$21 -> 24 | AY39: =[7]q!AY$21 -> 24.2 | AZ39: =[7]q!AZ$21 -> 24.6 | BA39: =[7]q!BA$21 -> 24.7 | ... IN39: =[7]q!IN$21 -> NA
A40: REXRATE | CP40: =[7]q!CP$20 -> 100 | CQ40: =[7]q!CQ$20 -> 97.483 | CR40: =[7]q!CR$20 -> 95.849 | CS40: =[7]q!CS$20 -> 98.292 | CT40: =[7]q!CT$20 -> 95.777 | CU40: =[7]q!CU$20 -> 94.423 | CV40: =[7]q!CV$20 -> 96.492 | CW40: =[7]q!CW$20 -> 94.696 | ... IN40: =[7]q!IN$20 -> 83.534
...

Sheet RATS_m
A1: Month | B1: PCONn_m | C1: PDURn_m | D1: PNDURn_m | E1: PSERVn_m | F1: PCONr_m | G1: PDURr_m | H1: PNDURr_m | I1: PSERVr_m | J1: RETAILn | K1: RETAILr | L1: cars | M1: IPROD | N1: FFR | O1: ALQ | P1: ICS | Q1: CPI | R1: CPI_CORE | S1: PPI | T1: Budgetsaldo | U1: Mean_Uduration | V1: Med_Uduration | W1: unemp | X1: unemp_0w | Y1: unemp_5w | Z1: unemp_15w | AA1: unemp_27w | AB1: T3M | AC1: T10Y | AD1: nfe | AE1: iprod | AF1: ccred | AG1: CBAAA | AH1: CBBAA | AI1: Exports | AJ1: Imports | AK1: ISM | AL1: vacancies | AM1: o_mfexcldef | AN1: HWI | AO1: discouraged | AP1: notdiscouraged | AQ1: labforce | AR1: claims | AS1: CBLI | AT1: OECDLI1 | AU1: OECDLI2 | AV1: hprices
A2: 18264 | B2: 2 | C2: 2 | D2: 2 | E2: 2 | F2: 2 | G2: 2 | H2: 2 | I2: 2 | J2: 2 | K2: 2 | L2: 1 | M2: 2 | N2: 0 | O2: 0 | P2: 0 | Q2: 2 | R2: 2 | S2: 2 | T2: 0 | U2: 0 | V2: 0 | W2: 2 | X2: 2 | Y2: 2 | Z2: 2 | AA2: 2 | AB2: 0 | AC2: 0 | AD2: 2 | AE2: 2 | AF2: 2 | AG2: 0 | AH2: 0 | AI2: 2 | AJ2: 2 | AK2: 0 | AL2: 2 | AM2: 2 | AN2: 2 | AO2: 2 | AP2: 2 | AQ2: 2 | AR2: 0 | AS2: 2 | AT2: 2 | AU2: 0 | AV2: 2
A3: 18295 | Q3: =[5]m!$B5 -> 23.61 | S3: =[5]m!$Q5 -> 26.1 | AF3: =[8]m!$AS5 -> 19.4 | AG3: =[8]m!$H5 -> 2.58 | AH3: =[8]m!$I5 -> 3.24 | AI3: =[7]m!C4 -> 795 | AJ3: =[7]m!D4 -> 592
A4: 18323 | Q4: =[5]m!$B6 -> 23.64 | S4: =[5]m!$Q6 -> 26.1 | AF4: =[8]m!$AS6 -> 19.7 | AG4: =[8]m!$H6 -> 2.58 | AH4: =[8]m!$I6 -> 3.24 | AI4: =[7]m!C5 -> 792 | AJ4: =[7]m!D5 -> 606
A5: 18354 | Q5: =[5]m!$B7 -> 23.65 | S5: =[5]m!$Q7 -> 26.1 | AF5: =[8]m!$AS7 -> 20.1 | AG5: =[8]m!$H7 -> 2.6 | AH5: =[8]m!$I7 -> 3.23 | AI5: =[7]m!C6 -> 772 | AJ5: =[7]m!D6 -> 577
A6: 18384 | Q6: =[5]m!$B8 -> 23.77 | S6: =[5]m!$Q8 -> 26.4 | AF6: =[8]m!$AS8 -> 20.6 | AG6: =[8]m!$H8 -> 2.61 | AH6: =[8]m!$I8 -> 3.25 | AI6: =[7]m!C7 -> 786 | AJ6: =[7]m!D7 -> 606
A7: 18415 | Q7: =[5]m!$B9 -> 23.88 | S7: =[5]m!$Q9 -> 26.6 | AF7: =[8]m!$AS9 -> 21.1 | AG7: =[8]m!$H9 -> 2.62 | AH7: =[8]m!$I9 -> 3.28 | AI7: =[7]m!C8 -> 772 | AJ7: =[7]m!D8 -> 636
A8: 18445 | Q8: =[5]m!$B10 -> 24.07 | S8: =[5]m!$Q10 -> 27.3 | AF8: =[8]m!$AS10 -> 22.1 | AG8: =[8]m!$H10 -> 2.65 | AH8: =[8]m!$I10 -> 3.32 | AI8: =[7]m!C9 -> 831 | AJ8: =[7]m!D9 -> 684
A9: 18476 | Q9: =[5]m!$B11 -> 24.2 | S9: =[5]m!$Q11 -> 27.9 | AF9: =[8]m!$AS11 -> 22.7 | AG9: =[8]m!$H11 -> 2.61 | AH9: =[8]m!$I11 -> 3.23 | AI9: =[7]m!C10 -> 821 | AJ9: =[7]m!D10 -> 787
A10: 18507 | Q10: =[5]m!$B12 -> 24.34 | S10: =[5]m!$Q12 -> 28.4 | AF10: =[8]m!$AS12 -> 23.2 | AG10: =[8]m!$H12 -> 2.64 | AH10: =[8]m!$I12 -> 3.21 | AI10: =[7]m!C11 -> 813 | AJ10: =[7]m!D11 -> 821
A11: 18537 | Q11: =[5]m!$B13 -> 24.5 | S11: =[5]m!$Q13 -> 28.6 | AF11: =[8]m!$AS13 -> 23.2 | AG11: =[8]m!$H13 -> 2.67 | AH11: =[8]m!$I13 -> 3.22 | AI11: =[7]m!C12 -> 889 | AJ11: =[7]m!D12 -> 955
A12: 18568 | Q12: =[5]m!$B14 -> 24.6 | S12: =[5]m!$Q14 -> 29 | AF12: =[8]m!$AS14 -> 23.3 | AG12: =[8]m!$H14 -> 2.67 | AH12: =[8]m!$I14 -> 3.22 | AI12: =[7]m!C13 -> 893 | AJ12: =[7]m!D13 -> 912
A13: 18598 | Q13: =[5]m!$B15 -> 24.98 | S13: =[5]m!$Q15 -> 29.7 | AF13: =[8]m!$AS15 -> 23.2 | AG13: =[8]m!$H15 -> 2.67 | AH13: =[8]m!$I15 -> 3.2 | AI13: =[7]m!C14 -> 940 | AJ13: =[7]m!D14 -> 876
A14: 18629 | Q14: =[5]m!$B16 -> 25.38 | S14: =[5]m!$Q16 -> 30.5 | AF14: =[8]m!$AS16 -> 23.8 | AG14: =[8]m!$H16 -> 2.66 | AH14: =[8]m!$I16 -> 3.17 | AI14: =[7]m!C15 -> 915 | AJ14: =[7]m!D15 -> 891 | AL14: =AL15*AN14/AN15 -> 1977.176 | AN14: 40
A15: 18660 | Q15: =[5]m!$B17 -> 25.83 | S15: =[5]m!$Q17 -> 30.9 | AF15: =[8]m!$AS17 -> 24.1 | AG15: =[8]m!$H17 -> 2.66 | AH15: =[8]m!$I17 -> 3.16 | AI15: =[7]m!C16 -> 970 | AJ15: =[7]m!D16 -> 939 | AL15: =AL16*AN15/AN16 -> 2026.6054 | AN15: 41
A16: 18688 | Q16: =[5]m!$B18 -> 25.88 | S16: =[5]m!$Q18 -> 30.9 | AF16: =[8]m!$AS18 -> 24.3 | AG16: =[8]m!$H18 -> 2.78 | AH16: =[8]m!$I18 -> 3.23 | AI16: =[7]m!C17 -> 1022 | AJ16: =[7]m!D17 -> 927 | AL16: =AL17*AN16/AN17 -> 2125.4642 | AN16: 43
A17: 18719 | Q17: =[5]m!$B19 -> 25.92 | S17: =[5]m!$Q19 -> 30.8 | AF17: =[8]m!$AS19 -> 24.1 | AG17: =[8]m!$H19 -> 2.87 | AH17: =[8]m!$I19 -> 3.35 | AI17: =[7]m!C18 -> 1080 | AJ17: =[7]m!D18 -> 997 | AL17: =AL18*AN17/AN18 -> 2076.0348 | AN17: 42
A18: 18749 | Q18: =[5]m!$B20 -> 25.99 | S18: =[5]m!$Q20 -> 30.7 | AF18: =[8]m!$AS20 -> 24 | AG18: =[8]m!$H20 -> 2.89 | AH18: =[8]m!$I20 -> 3.4 | AI18: =[7]m!C19 -> 1256 | AJ18: =[7]m!D19 -> 1005 | AL18: =AL19*AN18/AN19 -> 2125.4642 | AN18: 43
A19: 18780 | Q19: =[5]m!$B21 -> 25.93 | S19: =[5]m!$Q21 -> 30.5 | AF19: =[8]m!$AS21 -> 23.8 | AG19: =[8]m!$H21 -> 2.94 | AH19: =[8]m!$I21 -> 3.49 | AI19: =[7]m!C20 -> 1133 | AJ19: =[7]m!D20 -> 986 | AL19: =AL20*AN19/AN20 -> 2026.6054 | AN19: 41
A20: 18810 | Q20: =[5]m!$B22 -> 25.91 | S20: =[5]m!$Q22 -> 30.3 | AF20: =[8]m!$AS22 -> 23.7 | AG20: =[8]m!$H22 -> 2.94 | AH20: =[8]m!$I22 -> 3.53 | AI20: =[7]m!C21 -> 1132 | AJ20: =[7]m!D21 -> 967 | AL20: =AL21*AN20/AN21 -> 2076.0348 | AN20: 42
A21: 18841 | Q21: =[5]m!$B23 -> 25.86 | S21: =[5]m!$Q23 -> 30.1 | AF21: =[8]m!$AS23 -> 23.9 | AG21: =[8]m!$H23 -> 2.88 | AH21: =[8]m!$I23 -> 3.5 | AI21: =[7]m!C22 -> 1234 | AJ21: =[7]m!D22 -> 940 | AL21: =AL22*AN21/AN22 -> 2076.0348 | AN21: 42
A22: 18872 | Q22: =[5]m!$B24 -> 26.03 | S22: =[5]m!$Q24 -> 30.1 | AF22: =[8]m!$AS24 -> 24.1 | AG22: =[8]m!$H24 -> 2.84 | AH22: =[8]m!$I24 -> 3.46 | AI22: =[7]m!C23 -> 1233 | AJ22: =[7]m!D23 -> 885 | AL22: =AL23*AN22/AN23 -> 2026.6054 | AN22: 41
A23: 18902 | Q23: =[5]m!$B25 -> 26.16 | S23: =[5]m!$Q25 -> 30.1 | AF23: =[8]m!$AS25 -> 24.3 | AG23: =[8]m!$H25 -> 2.89 | AH23: =[8]m!$I25 -> 3.5 | AI23: =[7]m!C24 -> 1233 | AJ23: =[7]m!D24 -> 838 | AL23: =AL24*AN23/AN24 -> 2076.0348 | AN23: 42
A24: 18933 | Q24: =[5]m!$B26 -> 26.32 | S24: =[5]m!$Q26 -> 30.1 | AF24: =[8]m!$AS26 -> 24.6 | AG24: =[8]m!$H26 -> 2.96 | AH24: =[8]m!$I26 -> 3.56 | AI24: =[7]m!C25 -> 1101 | AJ24: =[7]m!D25 -> 800 | AL24: =AL25*AN24/AN25 -> 2076.0348 | AN24: 42
A25: 18963 | Q25: =[5]m!$B27 -> 26.47 | S25: =[5]m!$Q27 -> 30.1 | AF25: =[8]m!$AS27 -> 24.6 | AG25: =[8]m!$H27 -> 3.01 | AH25: =[8]m!$I27 -> 3.61 | AI25: =[7]m!C26 -> 1273 | AJ25: =[7]m!D26 -> 845 | AL25: =AL26*AN25/AN26 -> 2076.0348 | AN25: 42
... A40: 19419 | Q40: =[5]m!$B42 -> 26.63 | S40: =[5]m!$Q42 -> 29.2 | AF40: =[8]m!$AS42 -> 31.6 | AG40: =[8]m!$H42 -> 3.12 | AH40: =[8]m!$I42 -> 3.57 | AI40: =[7]m!C41 -> 971 | AJ40: =[7]m!D41 -> 902 | AL40: =AL41*AN40/AN41 -> 2471.47 | AN40: 50
A41: 19450 | Q41: =[5]m!$B43 -> 26.69 | S41: =[5]m!$Q43 -> 29 | AC41: =[8]m!$F43 -> 2.83 | AF41: =[8]m!$AS43 -> 32.1 | AG41: =[8]m!$H43 -> 3.23 | AH41: =[8]m!$I43 -> 3.65 | AI41: =[7]m!C42 -> 1001 | AJ41: =[7]m!D42 -> 923 | AL41: =AL42*AN41/AN42 -> 2422.0406 | AN41: 49
A42: 19480 | Q42: =[5]m!$B44 -> 26.7 | S42: =[5]m!$Q44 -> 29.1 | AC42: =[8]m!$F44 -> 3.05 | AF42: =[8]m!$AS44 -> 32.4 | AG42: =[8]m!$H44 -> 3.34 | AH42: =[8]m!$I44 -> 3.78 | AI42: =[7]m!C43 -> 1024 | AJ42: =[7]m!D43 -> 998 | AL42: =AL43*AN42/AN43 -> 2323.1818 | AN42: 47
A43: 19511 | Q43: =[5]m!$B45 -> 26.77 | S43: =[5]m!$Q45 -> 29 | AC43: =[8]m!$F45 -> 3.11 | AF43: =[8]m!$AS45 -> 32.5 | AG43: =[8]m!$H45 -> 3.4 | AH43: =[8]m!$I45 -> 3.86 | AI43: =[7]m!C44 -> 1008 | AJ43: =[7]m!D44 -> 931 | AL43: =AL44*AN43/AN44 -> 2224.323 | AN43: 45
A44: 19541 | Q44: =[5]m!$B46 -> 26.79 | S44: =[5]m!$Q46 -> 29.4 | AC44: =[8]m!$F46 -> 2.93 | AF44: =[8]m!$AS46 -> 32.8 | AG44: =[8]m!$H46 -> 3.28 | AH44: =[8]m!$I46 -> 3.86 | AI44: =[7]m!C45 -> 998 | AJ44: =[7]m!D45 -> 913 | AL44: =AL45*AN44/AN45 -> 2125.4642 | AN44: 43
A45: 19572 | Q45: =[5]m!$B47 -> 26.85 | S45: =[5]m!$Q47 -> 29.3 | AC45: =[8]m!$F47 -> 2.95 | AF45: =[8]m!$AS47 -> 33.1 | AG45: =[8]m!$H47 -> 3.24 | AH45: =[8]m!$I47 -> 3.85 | AI45: =[7]m!C46 -> 1011 | AJ45: =[7]m!D46 -> 899 | AL45: =AL46*AN45/AN46 -> 2026.6054 | AN45: 41
A46: 19603 | Q46: =[5]m!$B48 -> 26.89 | S46: =[5]m!$Q48 -> 29.4 | AC46: =[8]m!$F48 -> 2.87 | AF46: =[8]m!$AS48 -> 33.3 | AG46: =[8]m!$H48 -> 3.29 | AH46: =[8]m!$I48 -> 3.88 | AI46: =[7]m!C47 -> 1026 | AJ46: =[7]m!D47 -> 910 | AL46: =AL47*AN46/AN47 -> 1977.176 | AN46: 40
A47: 19633 | Q47: =[5]m!$B49 -> 26.95 | S47: =[5]m!$Q49 -> 29.2 | AC47: =[8]m!$F49 -> 2.66 | AF47: =[8]m!$AS49 -> 33.5 | AG47: =[8]m!$H49 -> 3.16 | AH47: =[8]m!$I49 -> 3.82 | AI47: =[7]m!C48 -> 1154 | AJ47: =[7]m!D48 -> 968 | AL47: =AL48*AN47/AN48 -> 1779.4584 | AN47: 36
A48: 19664 | Q48: =[5]m!$B50 -> 26.85 | S48: =[5]m!$Q50 -> 29.1 | AC48: =[8]m!$F50 -> 2.68 | AF48: =[8]m!$AS50 -> 33.6 | AG48: =[8]m!$H50 -> 3.11 | AH48: =[8]m!$I50 -> 3.75 | AI48: =[7]m!C49 -> 951 | AJ48: =[7]m!D49 -> 818 | AL48: =AL49*AN48/AN49 -> 1631.1702 | AN48: 33
A49: 19694 | Q49: =[5]m!$B51 -> 26.87 | S49: =[5]m!$Q51 -> 29.2 | AC49: =[8]m!$F51 -> 2.59 | AF49: =[8]m!$AS51 -> 33.7 | AG49: =[8]m!$H51 -> 3.13 | AH49: =[8]m!$I51 -> 3.74 | AI49: =[7]m!C50 -> 1035 | AJ49: =[7]m!D50 -> 873 | AL49: =AL50*AN49/AN50 -> 1482.882 | AN49: 30
A50: 19725 | N50: =[8]m!$C52 -> 0.73 | Q50: =[5]m!$B52 -> 26.94 | S50: =[5]m!$Q52 -> 29.4 | T50: =[6]m!B52 -> -185 | AB50: =[8]m!$C52 -> 0.73 | AC50: =[8]m!$F52 -> 2.48 | AF50: =[8]m!$AS52 -> 34.1 | AG50: =[8]m!$H52 -> 3.06 | AH50: =[8]m!$I52 -> 3.71 | AI50: =[7]m!C51 -> 1073 | AJ50: =[7]m!D51 -> 837 | AL50: =AL51*AN50/AN51 -> 1433.4526 | AN50: 29
A51: 19756 | N51: =[8]m!$C53 -> 1.51 | Q51: =[5]m!$B53 -> 26.99 | S51: =[5]m!$Q53 -> 29.3 | T51: =[6]m!B53 -> 737 | AB51: =[8]m!$C53 -> 1.51 | AC51: =[8]m!$F53 -> 2.47 | AF51: =[8]m!$AS53 -> 33.7 | AG51: =[8]m!$H53 -> 2.95 | AH51: =[8]m!$I53 -> 3.61 | AI51: =[7]m!C52 -> 962 | AJ51: =[7]m!D52 -> 855 | AL51: =AL52*AN51/AN52 -> 1384.0232 | AN51: 28
A52: 19784 | N52: =[8]m!$C54 -> 1.26 | Q52: =[5]m!$B54 -> 26.93 | S52: =[5]m!$Q54 -> 29.3 | T52: =[6]m!B54 -> 5879 | AB52: =[8]m!$C54 -> 1.26 | AC52: =[8]m!$F54 -> 2.37 | AF52: =[8]m!$AS54 -> 33.5 | AG52: =[8]m!$H54 -> 2.86 | AH52: =[8]m!$I54 -> 3.51 | AI52: =[7]m!C53 -> 1047 | AJ52: =[7]m!D53 -> 852 | AL52: =AL53*AN52/AN53 -> 1334.5938 | AN52: 27
A53: 19815 | N53: =[8]m!$C55 -> 0.85 | Q53: =[5]m!$B55 -> 26.86 | S53: =[5]m!$Q55 -> 29.4 | T53: =[6]m!B55 -> -2545 | AB53: =[8]m!$C55 -> 0.85 | AC53: =[8]m!$F55 -> 2.29 | AF53: =[8]m!$AS55 -> 33.7 | AG53: =[8]m!$H55 -> 2.85 | AH53: =[8]m!$I55 -> 3.47 | AI53: =[7]m!C54 -> 862 | AJ53: =[7]m!D54 -> 762 | AL53: =AL54*AN53/AN54 -> 1334.5938 | AN53: 27
A54: 19845 | N54: =[8]m!$C56 -> 0.86 | Q54: =[5]m!$B56 -> 26.93 | S54: =[5]m!$Q56 -> 29.4 | T54: =[6]m!B56 -> -1611 | AB54: =[8]m!$C56 -> 0.86 | AC54: =[8]m!$F56 -> 2.37 | AF54: =[8]m!$AS56 -> 33.7 | AG54: =[8]m!$H56 -> 2.88 | AH54: =[8]m!$I56 -> 3.47 | AI54: =[7]m!C55 -> 1196 | AJ54: =[7]m!D55 -> 945 | AL54: =AL55*AN54/AN55 -> 1285.1644 | AN54: 26
...
