Workbook
Name No: 'Sections 5 & 6'!$M$42
Name PATI_SCHOOL_10: 'Sections 1 & 2'!$C$63:$C$66
Name PATI_SCHOOL_1030: 'Sections 5 & 6'!$B$42:$B$43
Name PATI_SCHOOL_1040: 'Sections 5 & 6'!$C$42:$C$54
Name PATI_SCHOOL_1050: 'Sections 5 & 6'!$D$42:$D$49
Name PATI_SCHOOL_1060: 'Sections 5 & 6'!$E$42:$E$53
Name PATI_SCHOOL_1070: 'Sections 5 & 6'!$F$42:$F$47
Name PATI_SCHOOL_1080: 'Sections 5 & 6'!$G$42:$G$44
Name PATI_SCHOOL_1090: 'Sections 5 & 6'!$H$42:$H$54
Name PATI_SCHOOL_1100: 'Sections 5 & 6'!$I$42:$I$53
Name PATI_SCHOOL_1110: 'Sections 5 & 6'!$J$42:$J$50
Name PATI_SCHOOL_1120: 'Sections 5 & 6'!$K$42:$K$54
Name PATI_SCHOOL_1130: 'Sections 5 & 6'!$L$42:$L$48
Name PATI_SCHOOL_20: 'Sections 1 & 2'!$D$63:$D$66
Name PATI_SCHOOL_30: 'Sections 1 & 2'!$E$63:$E$69
Name PATI_SCHOOL_840: 'Section 3'!$B$83:$B$84
Name PATI_SCHOOL_850: 'Section 3'!$D$83:$D$84
Name PATI_SCHOOL_860: 'Section 3'!$F$83:$F$84
Name PATI_SCHOOL_870: 'Section 3'!$G$83:$G$84
Name PATI_SCHOOL_880: 'Section 3'!$H$83:$H$84
Name PATI_SCHOOL_890: 'Section 3'!$I$83:$I$84
Name PATI_SCHOOL_900: 'Section 3'!$J$83:$J$84
Name PATI_SCHOOL_910: 'Section 3'!$K$83:$K$84
Name PATI_SCHOOL_920: 'Section 3'!$L$83:$L$84
Name School_Year: 'Sections 1 & 2'!$B$63:$B$63

Sheet Terms & Definitions
B2: Term | C2: Definition
B3: 1-1 Student Program | C3: Some schools provide laptops or devices for 1-1 student use. To be counted in this category, laptops must be assigned to individual students for multiple class use. DO NOT include 1-1 student access to laptop computers or devices that reside in a specific classroom. These should be included under the classroom count.
B4: Classroom | C4: A room that is used for instructional purposes.
B5: e-Readers | C5: Devices that are not laptops or pocket sized and are used primarily for reading only and may have the option to access the Internet. Examples include: • Kindle • Nook • Etc
B6: Handheld Devices | C6: Handheld or mobile devices that are pocket-sized, typically having a display screen with touch input, miniature keyboard, or other user interface. Examples include: • PDAs (Palm Pilot, etc) • Audio/Video Devices (MP3 player, iPod , etc) • Other Wi-Fi accessible devices DO NOT include devices that are used solely as student response systems (clickers).
B7: High Capacity Computer | C7: A high capacity computer meets the following criteria: • 2 years old or newer • Contains a 10/100/1000mb network card and can run data intensive/graphic/video rendering applications such as CAD, web design, video production etc. • DO NOT include networks or thin clients Examples of high capacity computers include: • Designed for Windows 8 or Windows 7 (PC) • Able to run Microsoft Office 2010 (PC) • Designed for OS X v10.8 (Mountain Lion), OS X v10.7 (Lion) or OS X v10.6 (Snow Leopard) • Able to run Microsoft Office 2011 (Mac)
B8: Instructional Use | C8: Instructional use includes Classrooms, Stationary Computer Labs, Mobile Computer Labs, Library Media Centers, and 1-1 Student Programs.
B9: IU-Based WAN | C9: An IU-Based WAN is defined as a network that has the potential to connect all the LEAs within your Intermediate Unit.
B10: ISP | C10: Internet Service Provider
B11: LEA | C11: Local Education Agency (LEA): A school district, charter school or career and technical center.
B12: LEA-Based WAN | C12: An LEA-based WAN is defined as a building to building network that connects buildings within an LEA.
B13: Library/Media Center | C13: This is a general resource area where students conduct research and/or receive instruction.
... B26: Wireless Internet Access | C26: Wireless signal is accessible from the room/lab.

Sheet Sections 1 & 2
B2: PATI Survey for Schools Excel Data Entry Tool v3.1
B4: District Code (AUN):
B5: Participant ID (School Code):
B6: School Year: | C6: 2012-2013
B8: Question ID | C8: Question | D8: Response Selection | E8: Free Form Response | F8: Response ID for Template
B10: Section 1 – School Infrastructure
B11: 10 | C11: What is the maximum Wired Local Area Network (LAN) capacity at this school? | F11: =IF(ISERR(LEFT(D11,(FIND(" ",D11)))),"",LEFT(D11,(FIND(" ",D11)-1)))
B12: 20 | C12: What is the maximum Wireless Local Area Network (LAN) capacity at this school? | F12: =IF(ISERR(LEFT(D12,(FIND(" ",D12)))),"",LEFT(D12,(FIND(" ",D12)-1)))
B13: 30 | C13: What level of access is your Wireless Local Area Network (LAN) capacity at this school? | F13: =IF(ISERR(LEFT(D13,(FIND(" ",D13)))),"",LEFT(D13,(FIND(" ",D13)-1)))
B14: Section 2 – Room and Lab Counts
B15: 40 | C15: What is the total number of classrooms in the school? A classroom is defined as a room that is used for instructional purposes. _ Note: The value of this field is prepopulated based on the sum of questions 70 & 80. | D15: 99 - Free form | E15: =SUM(E18:E19) -> 0 | F15: =IF(ISERR(LEFT(D15,(FIND(" ",D15)))),"",LEFT(D15,(FIND(" ",D15)-1))) -> 99
B16: 50 | C16: (Question ID Not Used This Year)
B17: 60 | C17: (Question ID Not Used This Year)
B18: 70 | C18: What is the number of classrooms with either wired or wireless Internet access in the school? | D18: 99 - Free form | E18: 0 | F18: =IF(ISERR(LEFT(D18,(FIND(" ",D18)))),"",LEFT(D18,(FIND(" ",D18)-1))) -> 99
B19: 80 | C19: What is the number of classrooms with no Internet access in the school? | D19: 99 - Free form | E19: 0 | F19: =IF(ISERR(LEFT(D19,(FIND(" ",D19)))),"",LEFT(D19,(FIND(" ",D19)-1))) -> 99
B20: 90 | C20: What is the total number of stationary computer labs in the school? A stationary computer lab is defined as a room/Lab that is used for general computer use (NOT course specific). _ Note: The value of this field is prepopulated based on the sum of questions 120 & 130. | D20: 99 - Free form | E20: =SUM(E23:E24) -> 0 | F20: =IF(ISERR(LEFT(D20,(FIND(" ",D20)))),"",LEFT(D20,(FIND(" ",D20)-1))) -> 99
B21: 100 | C21: (Question ID Not Used This Year)
B22: 110 | C22: (Question ID Not Used This Year)
B23: 120 | C23: What is the number of stationary computer labs with either wired or wireless Internet access in the school? | D23: 99 - Free form | E23: 0 | F23: =IF(ISERR(LEFT(D23,(FIND(" ",D23)))),"",LEFT(D23,(FIND(" ",D23)-1))) -> 99
B24: 130 | C24: What is the number of stationary computer labs with no Internet access in the school? | D24: 99 - Free form | E24: 0 | F24: =IF(ISERR(LEFT(D24,(FIND(" ",D24)))),"",LEFT(D24,(FIND(" ",D24)-1))) -> 99
B25: 140 | C25: What is the total number of library/media centers in the school? A library/media center is a general resource area where students conduct research and/or receive instruction. _ Note: The value of this field is prepopulated based on the sum of questions 170 & 180. | D25: 99 - Free form | E25: =SUM(E28:E29) -> 0 | F25: =IF(ISERR(LEFT(D25,(FIND(" ",D25)))),"",LEFT(D25,(FIND(" ",D25)-1))) -> 99
B26: 150 | C26: (Question ID Not Used This Year)
B27: 160 | C27: (Question ID Not Used This Year)
B28: 170 | C28: What is the number of library/media centers with either wired or wireless Internet access in the school? | D28: 99 - Free form | E28: 0 | F28: =IF(ISERR(LEFT(D28,(FIND(" ",D28)))),"",LEFT(D28,(FIND(" ",D28)-1))) -> 99
B29: 180 | C29: What is the number of library/media centers with no Internet access in the school? | D29: 99 - Free form | E29: 0 | F29: =IF(ISERR(LEFT(D29,(FIND(" ",D29)))),"",LEFT(D29,(FIND(" ",D29)-1))) -> 99
B30: 190 | C30: What is the total number of mobile computer labs in the school? Mobile computer labs include mobile carts that consist of 16 or more computers and other digital tools that remain exclusively with the mobile lab. | D30: 99 - Free form | E30: 0 | F30: =IF(ISERR(LEFT(D30,(FIND(" ",D30)))),"",LEFT(D30,(FIND(" ",D30)-1))) -> 99
B62: School_Year | C62: PATI_SCHOOL_10 | D62: PATI_SCHOOL_20 | E62: PATI_SCHOOL_30
B63: 2012-2013 | C63: 1 - 10/100 MB Ethernet (Switched, Shared, None) | D63: 1 - 802.11 a/b | E63: 1 - Building-wide
C64: 2 - 10/100/1000 MB Ethernet (Switched, Shared, None) | D64: 2 - 802.11 g | E64: 2 - Limited service within building
C65: 3 - Greater than 1000 MB Ethernet (Switched, Shared, None) | D65: 3 - 802.11 n | E65: 3 - Campus-wide
C66: 98 - Not Applicable (wireless only) | D66: 98 - Not Applicable (no wireless) | E66: 4 - Limited service within campus
E67: 5 - Planned, will be installed within 2 years
E68: 6 - Not planned at this time
E69: 98 - Not Applicable (no wireless)

Sheet Section 3
B2: PATI Survey for Schools Excel Data Entry Tool v3.1
B5: Section 3 – Computer and Device Counts for Instructional Use
B7: Computer Counts
B8: Within your classrooms, stationary computer labs, moblie computer labs, and library/media centers, identify the number of high, mid, and low capacity computers. In addition classify the computers based on their Internet connection.
B9: Classrooms
C10: ID # | D10: Internet Access | E10: ID # | F10: No Internet Access
B11: High Capacity Computers | C11: 200 | D11: 0 | E11: 230 | F11: 0
B12: Mid Capacity Computers | C12: 210 | D12: 0 | E12: 240 | F12: 0
B13: Low Capacity Computers | C13: 220 | D13: 0 | E13: 250 | F13: 0
B14: Stationary Computer Labs
C15: ID # | D15: Internet Access | E15: ID # | F15: No Internet Access
B16: High Capacity Computers | C16: 260 | D16: 0 | E16: 290 | F16: 0
B17: Mid Capacity Computers | C17: 270 | D17: 0 | E17: 300 | F17: 0
B18: Low Capacity Computers | C18: 280 | D18: 0 | E18: 310 | F18: 0
B19: Mobile Computer Labs
C20: ID # | D20: Internet Access | E20: ID # | F20: No Internet Access
B21: High Capacity Computers | C21: 320 | D21: 0 | E21: 350 | F21: 0
B22: Mid Capacity Computers | C22: 330 | D22: 0 | E22: 360 | F22: 0
B23: Low Capacity Computers | C23: 340 | D23: 0 | E23: 370 | F23: 0
B24: Library/Media Centers
C25: ID # | D25: Internet Access | E25: ID # | F25: No Internet Access
B26: High Capacity Computers | C26: 380 | D26: 0 | E26: 410 | F26: 0
B27: Mid Capacity Computers | C27: 390 | D27: 0 | E27: 420 | F27: 0
B28: Low Capacity Computers | C28: 400 | D28: 0 | E28: 430 | F28: 0
B30: Device Counts
B31: Within your classrooms, stationary computer labs, moblie computer labs, and library/media centers, identify the numbers of thin clients, netbooks, handheld devices, e-readers, and tablet devices. In addition classify the devices based on their Internet connection.
B32: Classrooms
C33: ID # | D33: Internet Access | E33: ID # | F33: No Internet Access
B34: Thin Clients | C34: 440 | D34: 0 | E34: 450 | F34: 0
B35: Netbooks | C35: 460 | D35: 0 | E35: 470 | F35: 0
B36: Handheld Devices | C36: 480 | D36: 0 | E36: 490 | F36: 0
B37: e-readers | C37: 500 | D37: 0 | E37: 510 | F37: 0
B38: Tablet Devices | C38: 520 | D38: 0 | E38: 530 | F38: 0
B39: Stationary Computer Labs
C40: ID # | D40: Internet Access | E40: ID # | F40: No Internet Access
B41: Thin Clients | C41: 540 | D41: 0 | E41: 550 | F41: 0
B42: Netbooks | C42: 560 | D42: 0 | E42: 570 | F42: 0
B43: Handheld Devices | C43: 580 | D43: 0 | E43: 590 | F43: 0
B44: e-readers | C44: 600 | D44: 0 | E44: 610 | F44: 0
B45: Tablet Devices | C45: 620 | D45: 0 | E45: 630 | F45: 0
...

Sheet Section 4 (Not Used This Year)
B2: PATI Survey for Schools Excel Data Entry Tool v3.1
B5: Section 4 – (This Section Intentionally Left Blank)
B9: 930 | C9: (Question ID Not Used This Year)
B10: 940 | C10: (Question ID Not Used This Year)
B11: 950 | C11: (Question ID Not Used This Year)
B12: 960 | C12: (Question ID Not Used This Year)
B13: 970 | C13: (Question ID Not Used This Year)
B14: 980 | C14: (Question ID Not Used This Year)
B15: 990 | C15: (Question ID Not Used This Year)
B16: 1000 | C16: (Question ID Not Used This Year)
B17: 1010 | C17: (Question ID Not Used This Year)
B18: 1020 | C18: (Question ID Not Used This Year)

Sheet Sections 5 & 6
B2: PATI Survey for Schools Excel Data Entry Tool v3.1
B5: Question ID | C5: Question | D5: Response Selection | E5: Free Form Response | F5: Response ID for template format
B7: Section 5 – School Transport Questions
B8: 1030 | C8: Is this school connected to an LEA-Based WAN that is used for applications such as file sharing, administrative functions, student information, digital content, etc.? _ An LEA-Based WAN is defined as a building-to-building network that connects buildings within YOUR LEA (district, CTC or charter school). _ For single LEAs containing ONLY one school: Since your network is contained within your own school answer "NO" to this question. | F8: =IF(ISERR(LEFT(D8,(FIND(" ",D8)))),"",LEFT(D8,(FIND(" ",D8)-1)))
B9: 1040 | C9: Who is the primary Transport Access provider to your WAN? | F9: =IF(ISERR(LEFT(D9,(FIND(" ",D9)))),"",LEFT(D9,(FIND(" ",D9)-1))) | G9: =IF($D$8="2 - No","No",CONCATENATE("PATI_SCHOOL_",B9)) -> PATI_SCHOOL_1040
B10: 1050 | C10: What is the primary Transport type from this School to the LEA Head End? _ Note: "Public" means that the connection is leased from a telecommunications provider; "Private" means the LEA owns the connection. | F10: =IF(ISERR(LEFT(D10,(FIND(" ",D10)))),"",LEFT(D10,(FIND(" ",D10)-1))) | G10: =IF($D$8="2 - No","No",CONCATENATE("PATI_SCHOOL_",B10)) -> PATI_SCHOOL_1050
B11: 1060 | C11: What is the transport capacity from this School to the LEA Head End? | F11: =IF(ISERR(LEFT(D11,(FIND(" ",D11)))),"",LEFT(D11,(FIND(" ",D11)-1))) | G11: =IF($D$8="2 - No","No",CONCATENATE("PATI_SCHOOL_",B11)) -> PATI_SCHOOL_1060
B12: 1070 | C12: What is your estimated monthly pre-Erate cost for the transport from this School to the LEA Head End? | F12: =IF(ISERR(LEFT(D12,(FIND(" ",D12)))),"",LEFT(D12,(FIND(" ",D12)-1))) | G12: =IF($D$8="2 - No","No",CONCATENATE("PATI_SCHOOL_",B12)) -> PATI_SCHOOL_1070
B13: Section 6 – School Internet Questions
B14: 1080 | C14: How does this school receive its Internet connection? | F14: =IF(ISERR(LEFT(D14,(FIND(" ",D14)))),"",LEFT(D14,(FIND(" ",D14)-1)))
B15: 1090 | C15: If your school is receiving its Internet connection as part of an LEA-based WAN, what is the Internet capacity from this school to the LEA Head End? | F15: =IF(ISERR(LEFT(D15,(FIND(" ",D15)))),"",LEFT(D15,(FIND(" ",D15)-1)))
B16: 1100 | C16: If your school is receiving its Internet connection directly from an Internet Service Provider (ISP), who is your primary ISP? | F16: =IF(ISERR(LEFT(D16,(FIND(" ",D16)))),"",LEFT(D16,(FIND(" ",D16)-1)))
B17: 1110 | C17: If your school is receiving its Internet connection directly from an Internet Service Provider (ISP), what is the primary Transport type from this school to the ISP? _ Note: "Public" means that the connection is leased from a telecommunications provider; "Private" means the LEA owns the connection. | F17: =IF(ISERR(LEFT(D17,(FIND(" ",D17)))),"",LEFT(D17,(FIND(" ",D17)-1)))
B18: 1120 | C18: If your school is receiving its Internet connection directly from an Internet Service Provider (ISP), what is the Internet capacity from this school to the ISP? | F18: =IF(ISERR(LEFT(D18,(FIND(" ",D18)))),"",LEFT(D18,(FIND(" ",D18)-1)))
B19: 1130 | C19: If your school is receiving its Internet connection directly from an Internet Service Provider (ISP) what is your estimated monthly pre-Erate cost for the Internet? | F19: =IF(ISERR(LEFT(D19,(FIND(" ",D19)))),"",LEFT(D19,(FIND(" ",D19)-1)))
B41: PATI_SCHOOL_1030 | C41: PATI_SCHOOL_1040 | D41: PATI_SCHOOL_1050 | E41: PATI_SCHOOL_1060 | F41: PATI_SCHOOL_1070 | G41: PATI_SCHOOL_1080 | H41: PATI_SCHOOL_1090 | I41: PATI_SCHOOL_1100 | J41: PATI_SCHOOL_1110 | K41: PATI_SCHOOL_1120 | L41: PATI_SCHOOL_1130 | M41: No
B42: 1 - Yes | C42: 1 - Comcast | D42: 1 - Public Telco | E42: 1 - Less than 768 kbps | F42: 1 - Zero | G42: 1 - From the LEA-Based WAN | H42: 1 - Less than 768 kbps | I42: 1 - Comcast | J42: 1 - Public Telco | K42: 1 - Less than 768 kbps | L42: 1 - Zero | M42: 98 - Not Applicable (school not connected to LEA-based WAN)
B43: 2 - No | C43: 2 - D&E Communications | D43: 2 - Public Fiber | E43: 2 - 768 kbps only | F43: 2 - $1.00 - $500.00 | G43: 2 - Direct from an Internet Service Provider (ISP) | H43: 2 - 768 kbps only | I43: 2 - D&E Communications | J43: 2 - Public Fiber | K43: 2 - 768 kbps only | L43: 2 - $1.00 - $500.00
C44: 3 - DQE Communications | D44: 3 - Public Microwave | E44: 3 - Greater than 768 kbps and less than 1.54Mb (T-1) | F44: 3 - $501.00 - $1,000.00 | G44: 3 - This school does not have a connection to the Internet | H44: 3 - Greater than 768 kbps and less than 1.54Mb (T-1) | I44: 3 - Embarq | J44: 3 - Public Microwave | K44: 3 - Greater than 768 kbps and less than 1.54Mb (T-1) | L44: 3 - $501.00 - $1,000.00
C45: 4 - Embarq | D45: 4 - Public Wireless | E45: 4 - 1.54Mb (T-1) only | F45: 4 - $1001.00 - $2,500.00 | H45: 4 - 1.54Mb (T-1) only | I45: 4 - Expedient | J45: 4 - Public Wireless | K45: 4 - 1.54Mb (T-1) only | L45: 4 - $1001.00 - $2,500.00
C46: 5 - Level 3 | D46: 5 - Private Telco | E46: 5 - Greater than 1.54MB and less than 3MB | F46: 5 - $2,501.00 - $5,000.00 | H46: 5 - Greater than 1.54MB and less than 3MB | I46: 5 - Level 3 | J46: 5 - Private Telco | K46: 5 - Greater than 1.54MB and less than 3MB | L46: 5 - $2,501.00 - $5,000.00
C47: 6 - Prolog | D47: 6 - Private Fiber | E47: 6 - 3MB to 5MB | F47: 6 - Greater than $5,000.00 | H47: 6 - 3MB to 5MB | I47: 6 - Prolog | J47: 6 - Private Fiber | K47: 6 - 3MB to 5MB | L47: 6 - Greater than $5,000.00
C48: 7 - Qwest | D48: 7 - Private Microwave | E48: 7 - 6MB to 9MB | H48: 7 - 6MB to 9MB | I48: 7 - Qwest | J48: 7 - Private Microwave | K48: 7 - 6MB to 9MB | L48: 98 - Not Applicable (school receives Internet connection from an LEA-based WAN or has no connection to the Internet)
C49: 8 - Sting Communications | D49: 8 - Private Wireless | E49: 8 - 10MB to 24MB | H49: 8 - 10MB to 24MB | I49: 8 - Sting Communications | J49: 8 - Private Wireless | K49: 8 - 10MB to 24MB
C50: 9 - Sunesys | E50: 9 - 25MB to 49MB | H50: 9 - 25MB to 49MB | I50: 9 - Verizon | J50: 98 - Not Applicable (school receives Internet connection from an LEA-based WAN or has no connection to the Internet) | K50: 9 - 25MB to 49MB
C51: 10 - Verizon | E51: 10 - 50MB to 99MB | H51: 10 - 50MB to 99MB | I51: 10 - Wind Stream | K51: 10 - 50MB to 99MB
C52: 11 - Wind Stream | E52: 11 - 100MB to 999MB | H52: 11 - 100MB to 999MB | I52: 98 - Not Applicable (school receives Internet connection from an LEA-based WAN or has no connection to the Internet) | K52: 11 - 100MB to 999MB
C53: 12 - Owned (fiber, wireless, coax) | E53: 12 - 1GB or greater | H53: 12 - 1GB or greater | I53: 99 - Other | K53: 12 - 1GB or greater
C54: 99 - Other | H54: 98 - Not Applicable (school receives Internet connection directly from an ISP or has no connection to the Internet) | K54: 98 - Not Applicable (school receives Internet connection from an LEA-based WAN or has no connection to the Internet)

Sheet SURVEY_PARTCPNT_RESPONSE
A1: DISTRICT CODE | B1: SURVEY_NAME | C1: SURVEY ADMINISTRATION | D1: PARTICIPANT ID | E1: SURVEY QUESTION ID | F1: SURVEY CHOICE VALUE | G1: Not collected | H1: FREE FORM RESPONSE TEXT
A2: =IF(ISBLANK('Sections 1 & 2'!$C$4),"",'Sections 1 & 2'!$C$4) | B2: PATI_SCHOOL | C2: =IF(ISBLANK('Sections 1 & 2'!$C$6),"",CONCATENATE(RIGHT('Sections 1 & 2'!$C$6,4),"-06-30")) -> 2013-06-30 | D2: =IF(ISBLANK('Sections 1 & 2'!$C$5),"",'Sections 1 & 2'!$C$5) | E2: 10 | F2: ='Sections 1 & 2'!F11 | H2: =IF(ISBLANK('Sections 1 & 2'!E11),"",'Sections 1 & 2'!E11)
A3: =IF(ISBLANK('Sections 1 & 2'!$C$4),"",'Sections 1 & 2'!$C$4) | B3: PATI_SCHOOL | C3: =IF(ISBLANK('Sections 1 & 2'!$C$6),"",CONCATENATE(RIGHT('Sections 1 & 2'!$C$6,4),"-06-30")) -> 2013-06-30 | D3: =IF(ISBLANK('Sections 1 & 2'!$C$5),"",'Sections 1 & 2'!$C$5) | E3: 20 | F3: ='Sections 1 & 2'!F12 | H3: =IF(ISBLANK('Sections 1 & 2'!E12),"",'Sections 1 & 2'!E12)
A4: =IF(ISBLANK('Sections 1 & 2'!$C$4),"",'Sections 1 & 2'!$C$4) | B4: PATI_SCHOOL | C4: =IF(ISBLANK('Sections 1 & 2'!$C$6),"",CONCATENATE(RIGHT('Sections 1 & 2'!$C$6,4),"-06-30")) -> 2013-06-30 | D4: =IF(ISBLANK('Sections 1 & 2'!$C$5),"",'Sections 1 & 2'!$C$5) | E4: 30 | F4: ='Sections 1 & 2'!F13 | H4: =IF(ISBLANK('Sections 1 & 2'!E13),"",'Sections 1 & 2'!E13)
A5: =IF(ISBLANK('Sections 1 & 2'!$C$4),"",'Sections 1 & 2'!$C$4) | B5: PATI_SCHOOL | C5: =IF(ISBLANK('Sections 1 & 2'!$C$6),"",CONCATENATE(RIGHT('Sections 1 & 2'!$C$6,4),"-06-30")) -> 2013-06-30 | D5: =IF(ISBLANK('Sections 1 & 2'!$C$5),"",'Sections 1 & 2'!$C$5) | E5: 40 | F5: ='Sections 1 & 2'!F15 -> 99 | H5: =IF(ISBLANK('Sections 1 & 2'!E15),"",'Sections 1 & 2'!E15) -> 0
A6: =IF(ISBLANK('Sections 1 & 2'!$C$4),"",'Sections 1 & 2'!$C$4) | B6: PATI_SCHOOL | C6: =IF(ISBLANK('Sections 1 & 2'!$C$6),"",CONCATENATE(RIGHT('Sections 1 & 2'!$C$6,4),"-06-30")) -> 2013-06-30 | D6: =IF(ISBLANK('Sections 1 & 2'!$C$5),"",'Sections 1 & 2'!$C$5) | E6: 70 | F6: ='Sections 1 & 2'!F18 -> 99 | H6: =IF(ISBLANK('Sections 1 & 2'!E18),"",'Sections 1 & 2'!E18) -> 0
A7: =IF(ISBLANK('Sections 1 & 2'!$C$4),"",'Sections 1 & 2'!$C$4) | B7: PATI_SCHOOL | C7: =IF(ISBLANK('Sections 1 & 2'!$C$6),"",CONCATENATE(RIGHT('Sections 1 & 2'!$C$6,4),"-06-30")) -> 2013-06-30 | D7: =IF(ISBLANK('Sections 1 & 2'!$C$5),"",'Sections 1 & 2'!$C$5) | E7: 80 | F7: ='Sections 1 & 2'!F19 -> 99 | H7: =IF(ISBLANK('Sections 1 & 2'!E19),"",'Sections 1 & 2'!E19) -> 0
A8: =IF(ISBLANK('Sections 1 & 2'!$C$4),"",'Sections 1 & 2'!$C$4) | B8: PATI_SCHOOL | C8: =IF(ISBLANK('Sections 1 & 2'!$C$6),"",CONCATENATE(RIGHT('Sections 1 & 2'!$C$6,4),"-06-30")) -> 2013-06-30 | D8: =IF(ISBLANK('Sections 1 & 2'!$C$5),"",'Sections 1 & 2'!$C$5) | E8: 90 | F8: ='Sections 1 & 2'!F20 -> 99 | H8: =IF(ISBLANK('Sections 1 & 2'!E20),"",'Sections 1 & 2'!E20) -> 0
A9: =IF(ISBLANK('Sections 1 & 2'!$C$4),"",'Sections 1 & 2'!$C$4) | B9: PATI_SCHOOL | C9: =IF(ISBLANK('Sections 1 & 2'!$C$6),"",CONCATENATE(RIGHT('Sections 1 & 2'!$C$6,4),"-06-30")) -> 2013-06-30 | D9: =IF(ISBLANK('Sections 1 & 2'!$C$5),"",'Sections 1 & 2'!$C$5) | E9: 120 | F9: ='Sections 1 & 2'!F23 -> 99 | H9: =IF(ISBLANK('Sections 1 & 2'!E23),"",'Sections 1 & 2'!E23) -> 0
A10: =IF(ISBLANK('Sections 1 & 2'!$C$4),"",'Sections 1 & 2'!$C$4) | B10: PATI_SCHOOL | C10: =IF(ISBLANK('Sections 1 & 2'!$C$6),"",CONCATENATE(RIGHT('Sections 1 & 2'!$C$6,4),"-06-30")) -> 2013-06-30 | D10: =IF(ISBLANK('Sections 1 & 2'!$C$5),"",'Sections 1 & 2'!$C$5) | E10: 130 | F10: ='Sections 1 & 2'!F24 -> 99 | H10: =IF(ISBLANK('Sections 1 & 2'!E24),"",'Sections 1 & 2'!E24) -> 0
A11: =IF(ISBLANK('Sections 1 & 2'!$C$4),"",'Sections 1 & 2'!$C$4) | B11: PATI_SCHOOL | C11: =IF(ISBLANK('Sections 1 & 2'!$C$6),"",CONCATENATE(RIGHT('Sections 1 & 2'!$C$6,4),"-06-30")) -> 2013-06-30 | D11: =IF(ISBLANK('Sections 1 & 2'!$C$5),"",'Sections 1 & 2'!$C$5) | E11: 140 | F11: ='Sections 1 & 2'!F25 -> 99 | H11: =IF(ISBLANK('Sections 1 & 2'!E25),"",'Sections 1 & 2'!E25) -> 0
A12: =IF(ISBLANK('Sections 1 & 2'!$C$4),"",'Sections 1 & 2'!$C$4) | B12: PATI_SCHOOL | C12: =IF(ISBLANK('Sections 1 & 2'!$C$6),"",CONCATENATE(RIGHT('Sections 1 & 2'!$C$6,4),"-06-30")) -> 2013-06-30 | D12: =IF(ISBLANK('Sections 1 & 2'!$C$5),"",'Sections 1 & 2'!$C$5) | E12: 170 | F12: ='Sections 1 & 2'!F28 -> 99 | H12: =IF(ISBLANK('Sections 1 & 2'!E28),"",'Sections 1 & 2'!E28) -> 0
A13: =IF(ISBLANK('Sections 1 & 2'!$C$4),"",'Sections 1 & 2'!$C$4) | B13: PATI_SCHOOL | C13: =IF(ISBLANK('Sections 1 & 2'!$C$6),"",CONCATENATE(RIGHT('Sections 1 & 2'!$C$6,4),"-06-30")) -> 2013-06-30 | D13: =IF(ISBLANK('Sections 1 & 2'!$C$5),"",'Sections 1 & 2'!$C$5) | E13: 180 | F13: ='Sections 1 & 2'!F29 -> 99 | H13: =IF(ISBLANK('Sections 1 & 2'!E29),"",'Sections 1 & 2'!E29) -> 0
A14: =IF(ISBLANK('Sections 1 & 2'!$C$4),"",'Sections 1 & 2'!$C$4) | B14: PATI_SCHOOL | C14: =IF(ISBLANK('Sections 1 & 2'!$C$6),"",CONCATENATE(RIGHT('Sections 1 & 2'!$C$6,4),"-06-30")) -> 2013-06-30 | D14: =IF(ISBLANK('Sections 1 & 2'!$C$5),"",'Sections 1 & 2'!$C$5) | E14: 190 | F14: ='Sections 1 & 2'!F30 -> 99 | H14: =IF(ISBLANK('Sections 1 & 2'!E30),"",'Sections 1 & 2'!E30) -> 0
A15: =IF(ISBLANK('Sections 1 & 2'!$C$4),"",'Sections 1 & 2'!$C$4) | B15: PATI_SCHOOL | C15: =IF(ISBLANK('Sections 1 & 2'!$C$6),"",CONCATENATE(RIGHT('Sections 1 & 2'!$C$6,4),"-06-30")) -> 2013-06-30 | D15: =IF(ISBLANK('Sections 1 & 2'!$C$5),"",'Sections 1 & 2'!$C$5) | E15: 200 | F15: 99 | H15: =IF(ISBLANK('Section 3'!D11),"",'Section 3'!D11) -> 0
A16: =IF(ISBLANK('Sections 1 & 2'!$C$4),"",'Sections 1 & 2'!$C$4) | B16: PATI_SCHOOL | C16: =IF(ISBLANK('Sections 1 & 2'!$C$6),"",CONCATENATE(RIGHT('Sections 1 & 2'!$C$6,4),"-06-30")) -> 2013-06-30 | D16: =IF(ISBLANK('Sections 1 & 2'!$C$5),"",'Sections 1 & 2'!$C$5) | E16: 210 | F16: 99 | H16: =IF(ISBLANK('Section 3'!D12),"",'Section 3'!D12) -> 0
A17: =IF(ISBLANK('Sections 1 & 2'!$C$4),"",'Sections 1 & 2'!$C$4) | B17: PATI_SCHOOL | C17: =IF(ISBLANK('Sections 1 & 2'!$C$6),"",CONCATENATE(RIGHT('Sections 1 & 2'!$C$6,4),"-06-30")) -> 2013-06-30 | D17: =IF(ISBLANK('Sections 1 & 2'!$C$5),"",'Sections 1 & 2'!$C$5) | E17: 220 | F17: 99 | H17: =IF(ISBLANK('Section 3'!D13),"",'Section 3'!D13) -> 0
A18: =IF(ISBLANK('Sections 1 & 2'!$C$4),"",'Sections 1 & 2'!$C$4) | B18: PATI_SCHOOL | C18: =IF(ISBLANK('Sections 1 & 2'!$C$6),"",CONCATENATE(RIGHT('Sections 1 & 2'!$C$6,4),"-06-30")) -> 2013-06-30 | D18: =IF(ISBLANK('Sections 1 & 2'!$C$5),"",'Sections 1 & 2'!$C$5) | E18: 230 | F18: 99 | H18: =IF(ISBLANK('Section 3'!F11),"",'Section 3'!F11) -> 0
A19: =IF(ISBLANK('Sections 1 & 2'!$C$4),"",'Sections 1 & 2'!$C$4) | B19: PATI_SCHOOL | C19: =IF(ISBLANK('Sections 1 & 2'!$C$6),"",CONCATENATE(RIGHT('Sections 1 & 2'!$C$6,4),"-06-30")) -> 2013-06-30 | D19: =IF(ISBLANK('Sections 1 & 2'!$C$5),"",'Sections 1 & 2'!$C$5) | E19: 240 | F19: 99 | H19: =IF(ISBLANK('Section 3'!F12),"",'Section 3'!F12) -> 0
A20: =IF(ISBLANK('Sections 1 & 2'!$C$4),"",'Sections 1 & 2'!$C$4) | B20: PATI_SCHOOL | C20: =IF(ISBLANK('Sections 1 & 2'!$C$6),"",CONCATENATE(RIGHT('Sections 1 & 2'!$C$6,4),"-06-30")) -> 2013-06-30 | D20: =IF(ISBLANK('Sections 1 & 2'!$C$5),"",'Sections 1 & 2'!$C$5) | E20: 250 | F20: 99 | H20: =IF(ISBLANK('Section 3'!F13),"",'Section 3'!F13) -> 0
A21: =IF(ISBLANK('Sections 1 & 2'!$C$4),"",'Sections 1 & 2'!$C$4) | B21: PATI_SCHOOL | C21: =IF(ISBLANK('Sections 1 & 2'!$C$6),"",CONCATENATE(RIGHT('Sections 1 & 2'!$C$6,4),"-06-30")) -> 2013-06-30 | D21: =IF(ISBLANK('Sections 1 & 2'!$C$5),"",'Sections 1 & 2'!$C$5) | E21: 260 | F21: 99 | H21: =IF(ISBLANK('Section 3'!D16),"",'Section 3'!D16) -> 0
A22: =IF(ISBLANK('Sections 1 & 2'!$C$4),"",'Sections 1 & 2'!$C$4) | B22: PATI_SCHOOL | C22: =IF(ISBLANK('Sections 1 & 2'!$C$6),"",CONCATENATE(RIGHT('Sections 1 & 2'!$C$6,4),"-06-30")) -> 2013-06-30 | D22: =IF(ISBLANK('Sections 1 & 2'!$C$5),"",'Sections 1 & 2'!$C$5) | E22: 270 | F22: 99 | H22: =IF(ISBLANK('Section 3'!D17),"",'Section 3'!D17) -> 0
A23: =IF(ISBLANK('Sections 1 & 2'!$C$4),"",'Sections 1 & 2'!$C$4) | B23: PATI_SCHOOL | C23: =IF(ISBLANK('Sections 1 & 2'!$C$6),"",CONCATENATE(RIGHT('Sections 1 & 2'!$C$6,4),"-06-30")) -> 2013-06-30 | D23: =IF(ISBLANK('Sections 1 & 2'!$C$5),"",'Sections 1 & 2'!$C$5) | E23: 280 | F23: 99 | H23: =IF(ISBLANK('Section 3'!D18),"",'Section 3'!D18) -> 0
A24: =IF(ISBLANK('Sections 1 & 2'!$C$4),"",'Sections 1 & 2'!$C$4) | B24: PATI_SCHOOL | C24: =IF(ISBLANK('Sections 1 & 2'!$C$6),"",CONCATENATE(RIGHT('Sections 1 & 2'!$C$6,4),"-06-30")) -> 2013-06-30 | D24: =IF(ISBLANK('Sections 1 & 2'!$C$5),"",'Sections 1 & 2'!$C$5) | E24: 290 | F24: 99 | H24: =IF(ISBLANK('Section 3'!F16),"",'Section 3'!F16) -> 0
A25: =IF(ISBLANK('Sections 1 & 2'!$C$4),"",'Sections 1 & 2'!$C$4) | B25: PATI_SCHOOL | C25: =IF(ISBLANK('Sections 1 & 2'!$C$6),"",CONCATENATE(RIGHT('Sections 1 & 2'!$C$6,4),"-06-30")) -> 2013-06-30 | D25: =IF(ISBLANK('Sections 1 & 2'!$C$5),"",'Sections 1 & 2'!$C$5) | E25: 300 | F25: 99 | H25: =IF(ISBLANK('Section 3'!F17),"",'Section 3'!F17) -> 0
A26: =IF(ISBLANK('Sections 1 & 2'!$C$4),"",'Sections 1 & 2'!$C$4) | B26: PATI_SCHOOL | C26: =IF(ISBLANK('Sections 1 & 2'!$C$6),"",CONCATENATE(RIGHT('Sections 1 & 2'!$C$6,4),"-06-30")) -> 2013-06-30 | D26: =IF(ISBLANK('Sections 1 & 2'!$C$5),"",'Sections 1 & 2'!$C$5) | E26: 310 | F26: 99 | H26: =IF(ISBLANK('Section 3'!F18),"",'Section 3'!F18) -> 0
A27: =IF(ISBLANK('Sections 1 & 2'!$C$4),"",'Sections 1 & 2'!$C$4) | B27: PATI_SCHOOL | C27: =IF(ISBLANK('Sections 1 & 2'!$C$6),"",CONCATENATE(RIGHT('Sections 1 & 2'!$C$6,4),"-06-30")) -> 2013-06-30 | D27: =IF(ISBLANK('Sections 1 & 2'!$C$5),"",'Sections 1 & 2'!$C$5) | E27: 320 | F27: 99 | H27: =IF(ISBLANK('Section 3'!D21),"",'Section 3'!D21) -> 0
A28: =IF(ISBLANK('Sections 1 & 2'!$C$4),"",'Sections 1 & 2'!$C$4) | B28: PATI_SCHOOL | C28: =IF(ISBLANK('Sections 1 & 2'!$C$6),"",CONCATENATE(RIGHT('Sections 1 & 2'!$C$6,4),"-06-30")) -> 2013-06-30 | D28: =IF(ISBLANK('Sections 1 & 2'!$C$5),"",'Sections 1 & 2'!$C$5) | E28: 330 | F28: 99 | H28: =IF(ISBLANK('Section 3'!D22),"",'Section 3'!D22) -> 0
A29: =IF(ISBLANK('Sections 1 & 2'!$C$4),"",'Sections 1 & 2'!$C$4) | B29: PATI_SCHOOL | C29: =IF(ISBLANK('Sections 1 & 2'!$C$6),"",CONCATENATE(RIGHT('Sections 1 & 2'!$C$6,4),"-06-30")) -> 2013-06-30 | D29: =IF(ISBLANK('Sections 1 & 2'!$C$5),"",'Sections 1 & 2'!$C$5) | E29: 340 | F29: 99 | H29: =IF(ISBLANK('Section 3'!D23),"",'Section 3'!D23) -> 0
A30: =IF(ISBLANK('Sections 1 & 2'!$C$4),"",'Sections 1 & 2'!$C$4) | B30: PATI_SCHOOL | C30: =IF(ISBLANK('Sections 1 & 2'!$C$6),"",CONCATENATE(RIGHT('Sections 1 & 2'!$C$6,4),"-06-30")) -> 2013-06-30 | D30: =IF(ISBLANK('Sections 1 & 2'!$C$5),"",'Sections 1 & 2'!$C$5) | E30: 350 | F30: 99 | H30: =IF(ISBLANK('Section 3'!F21),"",'Section 3'!F21) -> 0
A31: =IF(ISBLANK('Sections 1 & 2'!$C$4),"",'Sections 1 & 2'!$C$4) | B31: PATI_SCHOOL | C31: =IF(ISBLANK('Sections 1 & 2'!$C$6),"",CONCATENATE(RIGHT('Sections 1 & 2'!$C$6,4),"-06-30")) -> 2013-06-30 | D31: =IF(ISBLANK('Sections 1 & 2'!$C$5),"",'Sections 1 & 2'!$C$5) | E31: 360 | F31: 99 | H31: =IF(ISBLANK('Section 3'!F22),"",'Section 3'!F22) -> 0
A32: =IF(ISBLANK('Sections 1 & 2'!$C$4),"",'Sections 1 & 2'!$C$4) | B32: PATI_SCHOOL | C32: =IF(ISBLANK('Sections 1 & 2'!$C$6),"",CONCATENATE(RIGHT('Sections 1 & 2'!$C$6,4),"-06-30")) -> 2013-06-30 | D32: =IF(ISBLANK('Sections 1 & 2'!$C$5),"",'Sections 1 & 2'!$C$5) | E32: 370 | F32: 99 | H32: =IF(ISBLANK('Section 3'!F23),"",'Section 3'!F23) -> 0
A33: =IF(ISBLANK('Sections 1 & 2'!$C$4),"",'Sections 1 & 2'!$C$4) | B33: PATI_SCHOOL | C33: =IF(ISBLANK('Sections 1 & 2'!$C$6),"",CONCATENATE(RIGHT('Sections 1 & 2'!$C$6,4),"-06-30")) -> 2013-06-30 | D33: =IF(ISBLANK('Sections 1 & 2'!$C$5),"",'Sections 1 & 2'!$C$5) | E33: 380 | F33: 99 | H33: =IF(ISBLANK('Section 3'!D26),"",'Section 3'!D26) -> 0
A34: =IF(ISBLANK('Sections 1 & 2'!$C$4),"",'Sections 1 & 2'!$C$4) | B34: PATI_SCHOOL | C34: =IF(ISBLANK('Sections 1 & 2'!$C$6),"",CONCATENATE(RIGHT('Sections 1 & 2'!$C$6,4),"-06-30")) -> 2013-06-30 | D34: =IF(ISBLANK('Sections 1 & 2'!$C$5),"",'Sections 1 & 2'!$C$5) | E34: 390 | F34: 99 | H34: =IF(ISBLANK('Section 3'!D27),"",'Section 3'!D27) -> 0
A35: =IF(ISBLANK('Sections 1 & 2'!$C$4),"",'Sections 1 & 2'!$C$4) | B35: PATI_SCHOOL | C35: =IF(ISBLANK('Sections 1 & 2'!$C$6),"",CONCATENATE(RIGHT('Sections 1 & 2'!$C$6,4),"-06-30")) -> 2013-06-30 | D35: =IF(ISBLANK('Sections 1 & 2'!$C$5),"",'Sections 1 & 2'!$C$5) | E35: 400 | F35: 99 | H35: =IF(ISBLANK('Section 3'!D28),"",'Section 3'!D28) -> 0
A36: =IF(ISBLANK('Sections 1 & 2'!$C$4),"",'Sections 1 & 2'!$C$4) | B36: PATI_SCHOOL | C36: =IF(ISBLANK('Sections 1 & 2'!$C$6),"",CONCATENATE(RIGHT('Sections 1 & 2'!$C$6,4),"-06-30")) -> 2013-06-30 | D36: =IF(ISBLANK('Sections 1 & 2'!$C$5),"",'Sections 1 & 2'!$C$5) | E36: 410 | F36: 99 | H36: =IF(ISBLANK('Section 3'!F26),"",'Section 3'!F26) -> 0
A37: =IF(ISBLANK('Sections 1 & 2'!$C$4),"",'Sections 1 & 2'!$C$4) | B37: PATI_SCHOOL | C37: =IF(ISBLANK('Sections 1 & 2'!$C$6),"",CONCATENATE(RIGHT('Sections 1 & 2'!$C$6,4),"-06-30")) -> 2013-06-30 | D37: =IF(ISBLANK('Sections 1 & 2'!$C$5),"",'Sections 1 & 2'!$C$5) | E37: 420 | F37: 99 | H37: =IF(ISBLANK('Section 3'!F27),"",'Section 3'!F27) -> 0
A38: =IF(ISBLANK('Sections 1 & 2'!$C$4),"",'Sections 1 & 2'!$C$4) | B38: PATI_SCHOOL | C38: =IF(ISBLANK('Sections 1 & 2'!$C$6),"",CONCATENATE(RIGHT('Sections 1 & 2'!$C$6,4),"-06-30")) -> 2013-06-30 | D38: =IF(ISBLANK('Sections 1 & 2'!$C$5),"",'Sections 1 & 2'!$C$5) | E38: 430 | F38: 99 | H38: =IF(ISBLANK('Section 3'!F28),"",'Section 3'!F28) -> 0
A39: =IF(ISBLANK('Sections 1 & 2'!$C$4),"",'Sections 1 & 2'!$C$4) | B39: PATI_SCHOOL | C39: =IF(ISBLANK('Sections 1 & 2'!$C$6),"",CONCATENATE(RIGHT('Sections 1 & 2'!$C$6,4),"-06-30")) -> 2013-06-30 | D39: =IF(ISBLANK('Sections 1 & 2'!$C$5),"",'Sections 1 & 2'!$C$5) | E39: 440 | F39: 99 | H39: =IF(ISBLANK('Section 3'!D34),"",'Section 3'!D34) -> 0
A40: =IF(ISBLANK('Sections 1 & 2'!$C$4),"",'Sections 1 & 2'!$C$4) | B40: PATI_SCHOOL | C40: =IF(ISBLANK('Sections 1 & 2'!$C$6),"",CONCATENATE(RIGHT('Sections 1 & 2'!$C$6,4),"-06-30")) -> 2013-06-30 | D40: =IF(ISBLANK('Sections 1 & 2'!$C$5),"",'Sections 1 & 2'!$C$5) | E40: 450 | F40: 99 | H40: =IF(ISBLANK('Section 3'!F34),"",'Section 3'!F34) -> 0
...

Sheet ReferenceData
A1: School_Year | B1: School-Question Answer Options
A2: 2011-2012 | B2: PATI_SCHOOL_10 | C2: PATI_SCHOOL_20 | D2: PATI_SCHOOL_30 | E2: PATI_SCHOOL_40 | F2: PATI_SCHOOL_50 | G2: PATI_SCHOOL_60 | H2: PATI_SCHOOL_70 | I2: PATI_SCHOOL_80 | J2: PATI_SCHOOL_90 | K2: PATI_SCHOOL_100 | L2: PATI_SCHOOL_110 | M2: PATI_SCHOOL_120 | N2: PATI_SCHOOL_130 | O2: PATI_SCHOOL_140 | P2: PATI_SCHOOL_150 | Q2: PATI_SCHOOL_160 | R2: PATI_SCHOOL_170 | S2: PATI_SCHOOL_180 | T2: PATI_SCHOOL_190 | U2: PATI_SCHOOL_200 | V2: PATI_SCHOOL_210 | W2: PATI_SCHOOL_220 | X2: PATI_SCHOOL_230 | Y2: PATI_SCHOOL_240 | Z2: PATI_SCHOOL_250 | AA2: PATI_SCHOOL_260 | AB2: PATI_SCHOOL_270 | AC2: PATI_SCHOOL_280 | AD2: PATI_SCHOOL_290 | AE2: PATI_SCHOOL_300 | AF2: PATI_SCHOOL_310 | AG2: PATI_SCHOOL_320 | AH2: PATI_SCHOOL_330 | AI2: PATI_SCHOOL_340 | AJ2: PATI_SCHOOL_350 | AK2: PATI_SCHOOL_360 | AL2: PATI_SCHOOL_370 | AM2: PATI_SCHOOL_380 | AN2: PATI_SCHOOL_390 | AO2: PATI_SCHOOL_400 | AP2: PATI_SCHOOL_410 | AQ2: PATI_SCHOOL_420 | AR2: PATI_SCHOOL_430 | AS2: PATI_SCHOOL_440 | AT2: PATI_SCHOOL_450 | AU2: PATI_SCHOOL_460 | AV2: PATI_SCHOOL_470 | AW2: PATI_SCHOOL_480 | AX2: PATI_SCHOOL_490 | AY2: PATI_SCHOOL_500 | AZ2: PATI_SCHOOL_510 | BA2: PATI_SCHOOL_520 | BB2: PATI_SCHOOL_530 | BC2: PATI_SCHOOL_540 | BD2: PATI_SCHOOL_550 | BE2: PATI_SCHOOL_560 | BF2: PATI_SCHOOL_570 | BG2: PATI_SCHOOL_580 | BH2: PATI_SCHOOL_590 | BI2: PATI_SCHOOL_600 | BJ2: PATI_SCHOOL_610 | BK2: PATI_SCHOOL_620 | BL2: PATI_SCHOOL_630 | BM2: PATI_SCHOOL_640 | BN2: PATI_SCHOOL_650 | BO2: PATI_SCHOOL_660 | BP2: PATI_SCHOOL_670 | BQ2: PATI_SCHOOL_680 | BR2: PATI_SCHOOL_690 | BS2: PATI_SCHOOL_700 | BT2: PATI_SCHOOL_710 | BU2: PATI_SCHOOL_720 | BV2: PATI_SCHOOL_730 | BW2: PATI_SCHOOL_740 | BX2: PATI_SCHOOL_750 | BY2: PATI_SCHOOL_760 | BZ2: PATI_SCHOOL_770 | CA2: PATI_SCHOOL_780 | CB2: PATI_SCHOOL_790 | CC2: PATI_SCHOOL_800 | CD2: PATI_SCHOOL_810 | CE2: PATI_SCHOOL_820 | CF2: PATI_SCHOOL_830 | CG2: PATI_SCHOOL_840 | CH2: PATI_SCHOOL_850 | CI2: PATI_SCHOOL_860 | CJ2: PATI_SCHOOL_870 | CK2: PATI_SCHOOL_880 | CL2: PATI_SCHOOL_890 | CM2: PATI_SCHOOL_900 | CN2: PATI_SCHOOL_910 | CO2: PATI_SCHOOL_920 | CP2: PATI_SCHOOL_930 | CQ2: PATI_SCHOOL_940 | CR2: PATI_SCHOOL_950 | CS2: PATI_SCHOOL_960 | CT2: PATI_SCHOOL_970 | CU2: PATI_SCHOOL_980 | CV2: PATI_SCHOOL_990 | CW2: PATI_SCHOOL_1000 | CX2: PATI_SCHOOL_1010 | CY2: PATI_SCHOOL_1020 | CZ2: PATI_SCHOOL_1030 | DA2: PATI_SCHOOL_1040 | DB2: PATI_SCHOOL_1050 | DC2: PATI_SCHOOL_1060 | DD2: PATI_SCHOOL_1070 | DE2: PATI_SCHOOL_1080 | DF2: PATI_SCHOOL_1090 | DG2: PATI_SCHOOL_1100 | DH2: PATI_SCHOOL_1110 | DI2: PATI_SCHOOL_1120 | DJ2: PATI_SCHOOL_1130
A3: 2012-2013 | B3: 1 - 10/100 MB Ethernet (Switched, Shared, None) | C3: 1 - 802.11 a/b | D3: 1 - Building-wide | E3: 99 - Free form | F3: 99 - Free form | G3: 99 - Free form | H3: 99 - Free form | I3: 99 - Free form | J3: 99 - Free form | K3: 99 - Free form | L3: 99 - Free form | M3: 99 - Free form | N3: 99 - Free form | O3: 99 - Free form | P3: 99 - Free form | Q3: 99 - Free form | R3: 99 - Free form | S3: 99 - Free form | T3: 99 - Free form | U3: 99 - Free form | V3: 99 - Free form | W3: 99 - Free form | X3: 99 - Free form | Y3: 99 - Free form | Z3: 99 - Free form | AA3: 99 - Free form | AB3: 99 - Free form | AC3: 99 - Free form | AD3: 99 - Free form | AE3: 99 - Free form | AF3: 99 - Free form | AG3: 99 - Free form | AH3: 99 - Free form | AI3: 99 - Free form | AJ3: 99 - Free form | AK3: 99 - Free form | AL3: 99 - Free form | AM3: 99 - Free form | AN3: 99 - Free form | AO3: 99 - Free form | AP3: 99 - Free form | AQ3: 99 - Free form | AR3: 99 - Free form | AS3: 99 - Free form | AT3: 99 - Free form | AU3: 99 - Free form | AV3: 99 - Free form | AW3: 99 - Free form | AX3: 99 - Free form | AY3: 99 - Free form | AZ3: 99 - Free form | BA3: 99 - Free form | BB3: 99 - Free form | BC3: 99 - Free form | BD3: 99 - Free form | BE3: 99 - Free form | BF3: 99 - Free form | BG3: 99 - Free form | BH3: 99 - Free form | BI3: 99 - Free form | BJ3: 99 - Free form | BK3: 99 - Free form | BL3: 99 - Free form | BM3: 99 - Free form | BN3: 99 - Free form | BO3: 99 - Free form | BP3: 99 - Free form | BQ3: 99 - Free form | BR3: 99 - Free form | BS3: 99 - Free form | BT3: 99 - Free form | BU3: 99 - Free form | BV3: 99 - Free form | BW3: 99 - Free form | BX3: 99 - Free form | BY3: 99 - Free form | BZ3: 99 - Free form | CA3: 99 - Free form | CB3: 99 - Free form | CC3: 99 - Free form | CD3: 99 - Free form | CE3: 99 - Free form | CF3: 99 - Free form | CG3: 1 - Yes | CH3: 98 - Not Applicable (school does not have 1-1 program) | CI3: 98 - Not Applicable (school does not have 1-1 program) | CJ3: 98 - Not Applicable (school does not have 1-1 program) | CK3: 98 - Not Applicable (school does not have 1-1 program) | CL3: 98 - Not Applicable (school does not have 1-1 program) | CM3: 98 - Not Applicable (school does not have 1-1 program) | CN3: 98 - Not Applicable (school does not have 1-1 program) | CO3: 98 - Not Applicable (school does not have 1-1 program) | CP3: 99 - Free form | CQ3: 99 - Free form | CR3: 99 - Free form | CS3: 99 - Free form | CT3: 99 - Free form | CU3: 99 - Free form | CV3: 99 - Free form | CW3: 99 - Free form | CX3: 99 - Free form | CY3: 99 - Free form | CZ3: 1 - Yes | DA3: 1 - Comcast | DB3: 1 - Public Telco | DC3: 1 - Less than 768 kbps | DD3: 1 - Zero | DE3: 1 - From the LEA-Based WAN | DF3: 1 - Less than 768 kbps | DG3: 1 - Comcast | DH3: 1 - Public Telco | DI3: 1 - Less than 768 kbps | DJ3: 1 - Zero
A4: 2013-2014 | B4: 2 - 10/100/1000 MB Ethernet (Switched, Shared, None) | C4: 2 - 802.11 g | D4: 2 - Limited service within building | CG4: 2 - No | CH4: 99 - Free form | CI4: 99 - Free form | CJ4: 99 - Free form | CK4: 99 - Free form | CL4: 99 - Free form | CM4: 99 - Free form | CN4: 99 - Free form | CO4: 99 - Free form | CZ4: 2 - No | DA4: 2 - D&E Communications | DB4: 2 - Public Fiber | DC4: 2 - 768 kbps only | DD4: 2 - $1.00 - $500.00 | DE4: 2 - Direct from an Internet Service Provider (ISP) | DF4: 2 - 768 kbps only | DG4: 2 - D&E Communications | DH4: 2 - Public Fiber | DI4: 2 - 768 kbps only | DJ4: 2 - $1.00 - $500.00
A5: 2014-2015 | B5: 3 - Greater than 1000 MB Ethernet (Switched, Shared, None) | C5: 3 - 802.11 n | D5: 3 - Campus-wide | DA5: 3 - DQE Communications | DB5: 3 - Public Microwave | DC5: 3 - Greater than 768 kbps and less than 1.54Mb (T-1) | DD5: 3 - $501.00 - $1,000.00 | DE5: 3 - This school does not have a connection to the Internet | DF5: 3 - Greater than 768 kbps and less than 1.54Mb (T-1) | DG5: 3 - Embarq | DH5: 3 - Public Microwave | DI5: 3 - Greater than 768 kbps and less than 1.54Mb (T-1) | DJ5: 3 - $501.00 - $1,000.00
A6: 2015-2016 | B6: 98 - Not Applicable (wireless only) | C6: 98 - Not Applicable (no wireless) | D6: 4 - Limited service within campus | DA6: 4 - Embarq | DB6: 4 - Public Wireless | DC6: 4 - 1.54Mb (T-1) only | DD6: 4 - $1001.00 - $2,500.00 | DF6: 4 - 1.54Mb (T-1) only | DG6: 4 - Expedient | DH6: 4 - Public Wireless | DI6: 4 - 1.54Mb (T-1) only | DJ6: 4 - $1001.00 - $2,500.00
A7: 2016-2017 | D7: 5 - Planned, will be installed within 2 years | DA7: 5 - Level 3 | DB7: 5 - Private Telco | DC7: 5 - Greater than 1.54MB and less than 3MB | DD7: 5 - $2,501.00 - $5,000.00 | DF7: 5 - Greater than 1.54MB and less than 3MB | DG7: 5 - Level 3 | DH7: 5 - Private Telco | DI7: 5 - Greater than 1.54MB and less than 3MB | DJ7: 5 - $2,501.00 - $5,000.00
D8: 6 - Not planned at this time | DA8: 6 - Prolog | DB8: 6 - Private Fiber | DC8: 6 - 3MB to 5MB | DD8: 6 - Greater than $5,000.00 | DF8: 6 - 3MB to 5MB | DG8: 6 - Prolog | DH8: 6 - Private Fiber | DI8: 6 - 3MB to 5MB | DJ8: 6 - Greater than $5,000.00
D9: 98 - Not Applicable (no wireless) | DA9: 7 - Qwest | DB9: 7 - Private Microwave | DC9: 7 - 6MB to 9MB | DD9: 98 - Not Applicable (school not connected to LEA-based WAN) | DF9: 7 - 6MB to 9MB | DG9: 7 - Qwest | DH9: 7 - Private Microwave | DI9: 7 - 6MB to 9MB | DJ9: 98 - Not Applicable (school receives Internet connection from an LEA-based WAN or has no connection to the Internet)
DA10: 8 - Sting Communications | DB10: 8 - Private Wireless | DC10: 8 - 10MB to 24MB | DF10: 8 - 10MB to 24MB | DG10: 8 - Sting Communications | DH10: 8 - Private Wireless | DI10: 8 - 10MB to 24MB
DA11: 9 - Sunesys | DB11: 98 - Not Applicable (school not connected to LEA-based WAN) | DC11: 9 - 25MB to 49MB | DF11: 9 - 25MB to 49MB | DG11: 9 - Verizon | DH11: 98 - Not Applicable (school receives Internet connection from an LEA-based WAN or has no connection to the Internet) | DI11: 9 - 25MB to 49MB
DA12: 10 - Verizon | DC12: 10 - 50MB to 99MB | DF12: 10 - 50MB to 99MB | DG12: 10 - Wind Stream | DI12: 10 - 50MB to 99MB
DA13: 11 - Wind Stream | DC13: 11 - 100MB to 999MB | DF13: 11 - 100MB to 999MB | DG13: 98 - Not Applicable (school receives Internet connection from an LEA-based WAN or has no connection to the Internet) | DI13: 11 - 100MB to 999MB
DA14: 12 - Owned (fiber, wireless, coax) | DC14: 12 - 1GB or greater | DF14: 12 - 1GB or greater | DG14: 99 - Other | DI14: 12 - 1GB or greater
DA15: 98 - Not Applicable (school not connected to LEA-based WAN) | DC15: 98 - Not Applicable (school not connected to LEA-based WAN) | DF15: 98 - Not Applicable (school receives Internet connection directly from an ISP or has no connection to the Internet) | DI15: 98 - Not Applicable (school receives Internet connection from an LEA-based WAN or has no connection to the Internet)
DA16: 99 - Other
