Workbook

Sheet GTR Soybean Table

Sheet US
A1: US Total | B1: Unshipped Balance | D1: Accumulated Exports | F1: Total Commitments | H1: last year | I1: last week | J1: last year | K1: last week | M1: 3-year average | N1: 3-year average | O1: This week | P1: This week
B2: curr | C2: last | D2: curr | E2: last | F2: curr | G2: last | H2: Commitments | J2: Accum Exports | M2: Total Sales | N2: Total Shipped | O2: % ttl sales | P2: % ttl shipped
A3: 38862 | B3: 1808.5 | C3: 1561.9 | D3: 21621.7 | E3: 27677.2 | F3: =+B3+D3 -> 23430.2 | G3: =+C3+E3 -> 29239.1 | H3: =+F3/G3-1 -> -0.19866891
A4: 38869 | B4: 1733 | C4: 1522.3 | D4: 21877.9 | E4: 27792.7 | F4: =+B4+D4 -> 23610.9 | G4: =+C4+E4 -> 29315 | H4: =+F4/G4-1 -> -0.19457957
A5: 38876 | B5: 1900.8 | C5: 1481.2 | D5: 22093.6 | E5: 28016.5 | F5: =+B5+D5 -> 23994.4 | G5: =+C5+E5 -> 29497.7 | H5: =+F5/G5-1 -> -0.18656709
A6: 38883 | B6: 1892.6 | C6: 1344.4 | D6: 22301.9 | E6: 28299.9 | F6: =+B6+D6 -> 24194.5 | G6: =+C6+E6 -> 29644.3 | H6: =+F6/G6-1 -> -0.18383973
A7: 38890 | B7: 1954.1 | C7: 1338.9 | D7: 22609.2 | E7: 28475.6 | F7: =+B7+D7 -> 24563.3 | G7: =+C7+E7 -> 29814.5 | H7: =+F7/G7-1 -> -0.17612906
A8: 38897 | B8: 1943.1 | C8: 1333.5 | D8: 22834.7 | E8: 28643.2 | F8: =+B8+D8 -> 24777.8 | G8: =+C8+E8 -> 29976.7 | H8: =+F8/G8-1 -> -0.17343137
A9: 38904 | B9: 2118.6 | C9: 1296.9 | D9: 22975.6 | E9: 28799.3 | F9: =+B9+D9 -> 25094.2 | G9: =+C9+E9 -> 30096.2 | H9: =+F9/G9-1 -> -0.16620038
A10: 38911 | B10: 1999.8 | C10: 1267.1 | D10: 23330.4 | E10: 28894.9 | F10: =+B10+D10 -> 25330.2 | G10: =+C10+E10 -> 30162 | H10: =+F10/G10-1 -> -0.16019495
A11: 38918 | B11: 1901.4 | C11: 1007.5 | D11: 23618.6 | E11: 29091.6 | F11: =+B11+D11 -> 25520 | G11: =+C11+E11 -> 30099.1 | H11: =+F11/G11-1 -> -0.15213412
A12: 38925 | B12: 1841.7 | C12: 999.2 | D12: 23855.6 | E12: 29195.9 | F12: =+B12+D12 -> 25697.3 | G12: =+C12+E12 -> 30195.1 | H12: =+F12/G12-1 -> -0.14895794
A13: 38932 | B13: 1662.4 | C13: 957.9 | D13: 24309.5 | E13: 29329.7 | F13: =+B13+D13 -> 25971.9 | G13: =+C13+E13 -> 30287.6 | H13: =+F13/G13-1 -> -0.14249066
A14: 38939 | B14: 1732.7 | C14: 900.8 | D14: 24496.7 | E14: 29537.7 | F14: =+B14+D14 -> 26229.4 | G14: =+C14+E14 -> 30438.5 | H14: =+F14/G14-1 -> -0.13828211
... A17: 38960 | B17: 813.8 | C17: 624.7 | D17: 25510.3 | E17: 29966 | F17: =+B17+D17 -> 26324.1 | G17: =+C17+E17 -> 30590.7 | H17: =+F17/G17-1 -> -0.13947376
A18: =+A17+7 -> 38967 | B18: 7003.7 | C18: 4421.7 | D18: 212.4 | E18: 154.5 | F18: =+B18+D18 -> 7216.1 | G18: =+C18+E18 -> 4576.2 | H18: =+F18/G18-1 -> 0.57687601 | J18: =+D18/E18-1 -> 0.37475728
A19: =+A18+7 -> 38974 | B19: 7408.7 | C19: 5016.6 | D19: 558.9 | E19: 311.6 | F19: =+B19+D19 -> 7967.6 | G19: =+C19+E19 -> 5328.2 | H19: =+F19/G19-1 -> 0.49536429 | I19: =+F19/F18-1 -> 0.10414213 | J19: =+D19/E19-1 -> 0.7936457 | K19: =D19/D18-1 -> 1.6313559
A20: =+A19+7 -> 38981 | B20: 7970.7 | C20: 5473.3 | D20: 863.5 | E20: 530.5 | F20: =+B20+D20 -> 8834.2 | G20: =+C20+E20 -> 6003.8 | H20: =+F20/G20-1 -> 0.47143476 | I20: =+F20/F19-1 -> 0.1087655 | J20: =+D20/E20-1 -> 0.62770971 | K20: =D20/D19-1 -> 0.54499911
A21: =+A20+7 -> 38988 | B21: 8592.1 | C21: 5808.5 | D21: 1437 | E21: 736.6 | F21: =+B21+D21 -> 10029.1 | G21: =+C21+E21 -> 6545.1 | H21: =+F21/G21-1 -> 0.53230661
A22: =+A21+7 -> 38995 | B22: 8954.1 | C22: 6095.5 | D22: 2161.1 | E22: 1134.4 | F22: =+B22+D22 -> 11115.2 | G22: =+C22+E22 -> 7229.9 | H22: =+F22/G22-1 -> 0.53739332 | I22: =+F22-F21 -> 1086.1 | J22: =+D22-D21 -> 724.1
A23: =+A22+7 -> 39002 | B23: 8995.8 | C23: 5986.8 | D23: 2987.8 | E23: 2131.9 | F23: =+B23+D23 -> 11983.6 | G23: =+C23+E23 -> 8118.7 | H23: =+F23/G23-1 -> 0.47604912 | I23: =+F23-F22 -> 868.4 | J23: =+D23-D22 -> 826.7
A24: =+A23+7 -> 39009 | B24: 8438.7 | C24: 5922.7 | D24: 4168.8 | E24: 3037.9 | F24: =+B24+D24 -> 12607.5 | G24: =+C24+E24 -> 8960.6 | H24: =+F24/G24-1 -> 0.40699284 | I24: =+F24-F23 -> 623.9 | J24: =+D24-D23 -> 1181
A25: =+A24+7 -> 39016 | B25: 7852.8 | C25: 5672.5 | D25: 5394.9 | E25: 4049.4 | F25: =+B25+D25 -> 13247.7 | G25: =+C25+E25 -> 9721.9 | H25: =+F25/G25-1 -> 0.36266573 | I25: =+F25-F24 -> 640.2 | J25: =+D25-D24 -> 1226.1
A26: =+A25+7 -> 39023 | B26: 7496.7 | C26: 5241.8 | D26: 6460.1 | E26: 5060.3 | F26: =+B26+D26 -> 13956.8 | G26: =+C26+E26 -> 10302.1 | H26: =+F26/G26-1 -> 0.35475291 | I26: =+F26-F25 -> 709.1 | J26: =+D26-D25 -> 1065.2 | L26: 31160
A27: =+A26+7 -> 39030 | B27: 7080.1 | C27: 5146.8 | D27: 7632.3 | E27: 5753.7 | F27: =+B27+D27 -> 14712.4 | G27: =+C27+E27 -> 10900.5 | H27: =+F27/G27-1 -> 0.34969956 | I27: =+F27-F26 -> 755.6 | J27: =+D27-D26 -> 1172.2 | L27: 31160
A28: =+A27+7 -> 39037 | B28: 7272.5 | C28: 4383.5 | D28: 8241.9 | E28: 6726.4 | F28: =+B28+D28 -> 15514.4 | G28: =+C28+E28 -> 11109.9 | H28: =+F28/G28-1 -> 0.39644821 | I28: =+F28-F27 -> 802 | J28: =+D28-D27 -> 609.6
A29: =+A28+7 -> 39044 | B29: 7331.3 | C29: 3926 | D29: 8912.4 | E29: 7515 | F29: =+B29+D29 -> 16243.7 | G29: =+C29+E29 -> 11441 | H29: =+F29/G29-1 -> 0.41977974 | I29: =+F29-F28 -> 729.3
A30: =+A29+7 -> 39051 | B30: 7068.1 | C30: 4079.4 | D30: 9842.5 | E30: 8313.7 | F30: =+B30+D30 -> 16910.6 | G30: =+C30+E30 -> 12393.1 | H30: =+F30/G30-1 -> 0.36451735 | I30: =+F30-F29 -> 666.9 | L30: =+F30/L27 -> 0.54270218
A31: =+A30+7 -> 39058 | B31: 6897.6 | C31: 3944.3 | D31: 10916.4 | E31: 8861.9 | F31: =+B31+D31 -> 17814 | G31: =+C31+E31 -> 12806.2 | H31: =+F31/G31-1 -> 0.39104496 | I31: =+F31-F30 -> 903.4
A32: =+A31+7 -> 39065 | B32: 7010.6 | C32: 4003.6 | D32: 11545.3 | E32: 9632.2 | F32: =+B32+D32 -> 18555.9 | G32: =+C32+E32 -> 13635.8 | H32: =+F32/G32-1 -> 0.36082225 | I32: =+F32-F31 -> 741.9
A33: =+A32+7 -> 39072 | B33: 7375.7 | C33: 4286.2 | D33: 12217.7 | E33: 10239.9 | F33: =+B33+D33 -> 19593.4 | G33: =+C33+E33 -> 14526.1 | H33: =+F33/G33-1 -> 0.34884105 | I33: =+F33-F32 -> 1037.5
A34: =+A33+7 -> 39079 | B34: 6886.2 | C34: 4375.1 | D34: 13033.4 | E34: 10612.5 | F34: =+B34+D34 -> 19919.6 | G34: =+C34+E34 -> 14987.6 | H34: =+F34/G34-1 -> 0.32907203 | I34: =+F34-F33 -> 326.2
A35: =+A34+7 -> 39086 | B35: 6917.8 | C35: 4148.8 | D35: 13591.4 | E35: 11286.9 | F35: =+B35+D35 -> 20509.2 | G35: =+C35+E35 -> 15435.7 | H35: =+F35/G35-1 -> 0.3286861 | I35: =+F35-F34 -> 589.6
A36: =+A35+7 -> 39093 | B36: 7138.7 | C36: 4870.1 | D36: 14466.3 | E36: 11844.2 | F36: =+B36+D36 -> 21605 | G36: =+C36+E36 -> 16714.3 | H36: =+F36/G36-1 -> 0.29260573 | I36: =+F36-F35 -> 1095.8 | J36: 30480
A37: =+A36+7 -> 39100 | B37: 7124.4 | C37: 4523.8 | D37: 15096.2 | E37: 12712.5 | F37: =+B37+D37 -> 22220.6 | G37: =+C37+E37 -> 17236.3 | H37: =+F37/G37-1 -> 0.28917459 | I37: =+F37-F36 -> 615.6 | J37: 30480
A38: =+A37+7 -> 39107 | B38: 6778 | C38: 4402.6 | D38: 16120.2 | E38: 13280.3 | F38: =+B38+D38 -> 22898.2 | G38: =+C38+E38 -> 17682.9 | H38: =+F38/G38-1 -> 0.29493465 | I38: =+F38-F37 -> 677.6
A39: =+A38+7 -> 39114 | B39: 6685.8 | C39: 4247 | D39: 17015.7 | E39: 13954.1 | F39: =+B39+D39 -> 23701.5 | G39: =+C39+E39 -> 18201.1 | H39: =+F39/G39-1 -> 0.30220152 | I39: =+F39-F38 -> 803.3 | J39: 1120 | K39: 36.743333
A40: =+A39+7 -> 39121 | B40: 5862.6 | C40: 3788.4 | D40: 18219.5 | E40: 14942.3 | F40: =+B40+D40 -> 24082.1 | G40: =+C40+E40 -> 18730.7 | H40: =+F40/G40-1 -> 0.28570208 | I40: =+F40-F39 -> 380.6 | K40: =+J39/K39 -> 30.48172
A41: =+A40+7 -> 39128 | B41: 5735.7 | C41: 3543.9 | D41: 18951.3 | E41: 15690.6 | F41: =+B41+D41 -> 24687 | G41: =+C41+E41 -> 19234.5 | H41: =+F41/G41-1 -> 0.28347501 | I41: =+F41-F40 -> 604.9 | J41: 1100 | K41: =+J41/K39 -> 29.937404
A42: =+A41+7 -> 39135 | B42: 5217.1 | C42: 3406.2 | D42: 19885.5 | E42: 16195.8 | F42: =+B42+D42 -> 25102.6 | G42: =+C42+E42 -> 19602 | H42: =+F42/G42-1 -> 0.28061422 | I42: =+F42-F41 -> 415.6
...

Sheet China
C1: Unshipped Balance | E1: Accumulated Exports | G1: Total Commitments | J1: 05/06Projected | K1: 04/05 | L1: Chng in | M1: Chnge in | N1: Weekly | AQ1: 38652 | AR1: Japan | AS1: 2449.7 | AT1: 2936.5 | AU1: 2414.9 | AV1: 2427 | AW1: =+AS1+AU1 -> 4864.6 | AX1: =+AT1+AV1 -> 5363.5 | AY1: =+AW1/AX1-1 -> -0.093017619 | AZ1: =+#REF! -> #REF! | BA1: =+#REF! -> #REF! | BB1: Mexico
A2: EXPORT SALES, China | C2: this year | D2: last year | E2: this year | F2: last year | G2: this year | H2: last year | I2: % change | J2: Exports | K2: Exports | L2: Ttl Cmtmnts | M2: unshipped | N2: Sales | AQ2: =+AQ1+7 -> 38659 | AR2: Japan | AS2: 2261.6 | AT2: 2616.8 | AU2: 2778.4 | AV2: 2952.9 | AW2: =+AS2+AU2 -> 5040 | AX2: =+AT2+AV2 -> 5569.7 | AY2: =+AW2/AX2-1 -> -0.095103866
A3: 38855 | C3: 60 | D3: 100.7 | E3: 9246.5 | F3: 11766.9 | G3: =+C3+E3 -> 9306.5 | H3: =+D3+F3 -> 11867.6 | I3: =+(G3/H3-1)*100 -> -21.580606 | AR3: Korea | AS3: =+#REF! -> #REF! | AT3: =+#REF! -> #REF! | AU3: =+AS3/AT3-1 -> #REF! | AV3: =+#REF! -> #REF! | AW3: 2098.5 | AX3: =+(AV3/AW3)-1 -> #REF!
A4: =+A3+7 -> 38862 | C4: 60 | D4: 100.7 | E4: 9301.3 | F4: 11791.6 | G4: =+C4+E4 -> 9361.3 | H4: =+D4+F4 -> 11892.3 | I4: =+(G4/H4-1)*100 -> -21.282679 | J4: 1752 | L4: =+G4-G3 -> 54.8 | AR4: Top 5 Importers | AS4: =SUM(AS3:AS3) -> #REF! | AT4: =SUM(AT3:AT3) -> #REF! | AU4: =+AS4/AT4-1 -> #REF! | AV4: =SUM(AV3:AV3) -> #REF! | AW4: =SUM(AW3:AW3) -> 2098.5 | AX4: =+(AV4/AW4)-1 -> #REF!
A5: =+A4+7 -> 38869 | C5: 60 | D5: 100.7 | E5: 9301.3 | F5: 11791.6 | G5: =+C5+E5 -> 9361.3 | H5: =+D5+F5 -> 11892.3 | I5: =+(G5/H5-1)*100 -> -21.282679 | J5: 1752 | L5: =+G5-G4 -> 0 | AR5: US Corn Exports | AV5: =+#REF! -> #REF! | AW5: 45409.4
A6: =+A5+7 -> 38876 | C6: 173 | D6: 56 | E6: 9301.3 | F6: 11791.6 | G6: =+C6+E6 -> 9474.3 | H6: =+D6+F6 -> 11847.6 | I6: =+(G6/H6-1)*100 -> -20.031905 | J6: 1807 | L6: =+G6-G5 -> 113 | AR6: Top 5 Share of U.S. Corn Exports | AV6: =+AV4/AV5 -> #REF! | AW6: =+AW4/AW5 -> 0.046212899
A7: =+A6+7 -> 38883 | C7: 173 | D7: 56 | E7: 9346.2 | F7: 11791.6 | G7: =+C7+E7 -> 9519.2 | H7: =+D7+F7 -> 11847.6 | I7: =+(G7/H7-1)*100 -> -19.652925 | J7: 1807 | L7: =+G7-G6 -> 44.9 | AR7: * Cumulative Exports + Outstanding (unshipped) exports
A8: =+A7+7 -> 38890 | C8: 289 | D8: 56 | E8: 9346.2 | F8: 11791.6 | G8: =+C8+E8 -> 9635.2 | H8: =+D8+F8 -> 11847.6 | I8: =+(G8/H8-1)*100 -> -18.673824 | J8: 1867 | L8: =+G8-G7 -> 116 | AR8: ** AMS Estimate, based on a 5 -year average U.S. share of Total Imports and WASDE Projected Import demand.
A9: =+A8+7 -> 38897 | C9: 367 | D9: 56 | E9: 9346.2 | F9: 11791.6 | G9: =+C9+E9 -> 9713.2 | H9: =+D9+F9 -> 11847.6 | I9: =+(G9/H9-1)*100 -> -18.015463 | J9: 1867 | L9: =+G9-G8 -> 78
A10: =+A9+7 -> 38904 | C10: 482 | D10: 0 | E10: 9346.2 | F10: 11850.4 | G10: =+C10+E10 -> 9828.2 | H10: =+D10+F10 -> 11850.4 | I10: =+(G10/H10-1)*100 -> -17.064403 | J10: 1867 | L10: =+G10-G9 -> 115
A11: =+A10+7 -> 38911 | C11: 406 | D11: 0 | E11: 9408 | F11: 11850.4 | G11: =+C11+E11 -> 9814 | H11: =+D11+F11 -> 11850.4 | I11: =+(G11/H11-1)*100 -> -17.18423 | J11: 1867 | L11: =+G11-G10 -> -14.2
A12: =+A11+7 -> 38918 | C12: 346 | D12: 0 | E12: 9408 | F12: 11850.5 | G12: =+C12+E12 -> 9754 | H12: =+D12+F12 -> 11850.5 | I12: =+(G12/H12-1)*100 -> -17.691237 | J12: 1867 | L12: =+G12-G11 -> -60
A13: =+A12+7 -> 38925 | C13: 346 | D13: 0 | E13: 9408 | F13: 11850.5 | G13: =+C13+E13 -> 9754 | H13: =+D13+F13 -> 11850.5 | I13: =+(G13/H13-1)*100 -> -17.691237 | J13: 1923 | L13: =+G13-G12 -> 0
A14: =+A13+7 -> 38932 | C14: 280 | D14: 0 | E14: 9531.6 | F14: 11850.5 | G14: =+C14+E14 -> 9811.6 | H14: =+D14+F14 -> 11850.5 | I14: =+(G14/H14-1)*100 -> -17.205181 | J14: 1923 | L14: =+G14-G13 -> 57.6
A15: =+A14+7 -> 38939 | C15: 340 | D15: 0 | E15: 9531.6 | F15: 11850.5 | G15: =+C15+E15 -> 9871.6 | H15: =+D15+F15 -> 11850.5 | I15: =+(G15/H15-1)*100 -> -16.698873 | J15: 2149
A16: =+A15+7 -> 38946 | C16: 225 | D16: 0 | E16: 9596.6 | F16: 11850.5 | G16: =+C16+E16 -> 9821.6 | H16: =+D16+F16 -> 11850.5 | I16: =+(G16/H16-1)*100 -> -17.120797 | J16: 2250
A17: =+A16+7 -> 38953 | C17: 170 | D17: 0 | E17: 9596.6 | F17: 11850.5 | G17: =+C17+E17 -> 9766.6 | H17: =+D17+F17 -> 11850.5 | I17: =+(G17/H17-1)*100 -> -17.584912 | J17: 2480
A18: =+A17+7 -> 38960 | C18: 60 | D18: 0 | E18: 9706.3 | F18: 11850.5 | G18: =+C18+E18 -> 9766.3 | H18: =+D18+F18 -> 11850.5 | I18: =+(G18/H18-1)*100 -> -17.587444 | J18: 2770
A19: =+A18+7 -> 38967 | C19: 3081 | D19: 802 | E19: 0 | F19: 0 | G19: =+C19+E19 -> 3081 | H19: =+D19+F19 -> 802 | I19: =+(G19/H19-1)*100 -> 284.16459
A20: =+A19+7 -> 38974 | C20: 3295.4 | D20: 1025 | E20: 111.8 | F20: 0 | G20: =+C20+E20 -> 3407.2 | H20: =+D20+F20 -> 1025 | I20: =+(G20/H20-1)*100 -> 232.40976
A21: =+A20+7 -> 38981 | C21: 3477 | D21: 1271 | E21: 171.5 | F21: 117.3 | G21: =+C21+E21 -> 3648.5 | H21: =+D21+F21 -> 1388.3 | I21: =+(G21/H21-1)*100 -> 162.80343
A22: =+A21+7 -> 38988 | C22: 3760 | D22: 1546 | E22: 459.3 | F22: 173.3 | G22: =+C22+E22 -> 4219.3 | H22: =+D22+F22 -> 1719.3 | I22: =+(G22/H22-1)*100 -> 145.40801
A23: =+A22+7 -> 38995 | C23: 4146.5 | D23: 1836 | E23: 573.6 | F23: 401.1 | G23: =+C23+E23 -> 4720.1 | H23: =+D23+F23 -> 2237.1 | I23: =+(G23/H23-1)*100 -> 110.99191
A24: =+A23+7 -> 39002 | C24: 4168.4 | D24: 1719 | E24: 940 | F24: 995.6 | G24: =+C24+E24 -> 5108.4 | H24: =+D24+F24 -> 2714.6 | I24: =+(G24/H24-1)*100 -> 88.182421
A25: =+A24+7 -> 39009 | C25: 3912.6 | D25: 1664 | E25: 1493.7 | F25: 1397.8 | G25: =+C25+E25 -> 5406.3 | H25: =+D25+F25 -> 3061.8 | I25: =+(G25/H25-1)*100 -> 76.572604
A26: =+A25+7 -> 39016 | C26: 3419.6 | D26: 1535 | E26: 2322.6 | F26: 1993.9 | G26: =+C26+E26 -> 5742.2 | H26: =+D26+F26 -> 3528.9 | I26: =+(G26/H26-1)*100 -> 62.719261
A27: =+A26+7 -> 39023 | C27: 3001.8 | D27: 1364 | E27: 2970.8 | F27: 2527.3 | G27: =+C27+E27 -> 5972.6 | H27: =+D27+F27 -> 3891.3 | I27: =+(G27/H27-1)*100 -> 53.485982
A28: =+A27+7 -> 39030 | C28: 2834.3 | D28: 1419 | E28: 3377.7 | F28: 2817.8 | G28: =+C28+E28 -> 6212 | H28: =+D28+F28 -> 4236.8 | I28: =+(G28/H28-1)*100 -> 46.620091
A29: =+A28+7 -> 39037 | C29: 2862.2 | D29: 1041 | E29: 3603.3 | F29: 3198.7 | G29: =+C29+E29 -> 6465.5 | H29: =+D29+F29 -> 4239.7 | I29: =+(G29/H29-1)*100 -> 52.498998
A30: =+A29+7 -> 39044 | C30: 2980.7 | D30: 973 | E30: 3835.7 | F30: 3559.5 | G30: =+C30+E30 -> 6816.4 | H30: =+D30+F30 -> 4532.5 | I30: =+(G30/H30-1)*100 -> 50.38941
... A40: =+A39+7 -> 39114 | C40: 2655.2 | D40: 1189 | E40: 7159.1 | F40: 6129.6 | G40: =+C40+E40 -> 9814.3 | H40: =+D40+F40 -> 7318.6 | I40: =+(G40/H40-1)*100 -> 34.100784
A41: =+A40+7 -> 39121 | C41: 2266.5 | D41: 1018 | E41: 7799.9 | F41: 6660.9 | G41: =+C41+E41 -> 10066.4 | H41: =+D41+F41 -> 7678.9 | I41: =+(G41/H41-1)*100 -> 31.091693 | L41: =+G41-G40 -> 252.1
A42: =+A41+7 -> 39128 | C42: 2158.6 | D42: 850 | E42: 8102.4 | F42: 7238.2 | G42: =+C42+E42 -> 10261 | H42: =+D42+F42 -> 8088.2 | I42: =+(G42/H42-1)*100 -> 26.863826 | L42: =+G42-G41 -> 194.6
A43: =+A42+7 -> 39135 | C43: 1971.2 | D43: 865 | E43: 8534.4 | F43: 7473.7 | G43: =+C43+E43 -> 10505.6 | H43: =+D43+F43 -> 8338.7 | I43: =+(G43/H43-1)*100 -> 25.986065 | L43: =+G43-G42 -> 244.6
A44: =+A43+7 -> 39142 | C44: 1884.8 | D44: 914 | E44: 8855.9 | F44: 7760.8 | G44: =+C44+E44 -> 10740.7 | H44: =+D44+F44 -> 8674.8 | I44: =+(G44/H44-1)*100 -> 23.814958 | L44: =+G44-G43 -> 235.1
A45: =+A44+7 -> 39149 | C45: 1705.4 | D45: 791 | E45: 9138.6 | F45: 8194.2 | G45: =+C45+E45 -> 10844 | H45: =+D45+F45 -> 8985.2 | I45: =+(G45/H45-1)*100 -> 20.687353 | L45: =+G45-G44 -> 103.3
A46: =+A45+7 -> 39156 | C46: 1545.5 | D46: 633 | E46: 9426 | F46: 8417.2 | G46: =+C46+E46 -> 10971.5 | H46: =+D46+F46 -> 9050.2 | I46: =+(G46/H46-1)*100 -> 21.229365 | L46: =+G46-G45 -> 127.5
A47: =+A46+7 -> 39163 | C47: 1467.8 | D47: 293 | E47: 9579.8 | F47: 8870 | G47: =+C47+E47 -> 11047.6 | H47: =+D47+F47 -> 9163 | I47: =+(G47/H47-1)*100 -> 20.5675 | L47: =+G47-G46 -> 76.1
A48: =+A47+7 -> 39170 | C48: 1186.1 | D48: 153 | E48: 9882.2 | F48: 9081.7 | G48: =+C48+E48 -> 11068.3 | H48: =+D48+F48 -> 9234.7 | I48: =+(G48/H48-1)*100 -> 19.855545 | L48: =+G48-G47 -> 20.7
A49: =+A48+7 -> 39177 | C49: 952.3 | D49: 153 | E49: 10131.1 | F49: 9081.7 | G49: =+C49+E49 -> 11083.4 | H49: =+D49+F49 -> 9234.7 | I49: =+(G49/H49-1)*100 -> 20.019059 | L49: =+G49-G48 -> 15.1
...

Sheet Mexico
C1: Outstanding Sales (Unshipped) | E1: Accumulated Exports | G1: Total Commitments | K1: 05/06Projected | L1: 04/05 | M1: Chng in | N1: Chnge in | O1: Weekly
A2: EXPORT SALES, Mexico | C2: current | D2: last | E2: current | F2: last | G2: current | H2: last | I2: % change | K2: Exports | L2: Exports | M2: Ttl Cmtmnts | N2: unshipped | O2: Sales
A3: 38855 | C3: 489.8 | D3: 352.9 | E3: 2635.8 | F3: 2513.8 | G3: =+C3+E3 -> 3125.6 | H3: =+D3+F3 -> 2866.7 | I3: =+(G3/H3-1)*100 -> 9.0312903
A4: 38862 | C4: 475.1 | D4: 374.9 | E4: 2733.3 | F4: 2585.5 | G4: =+C4+E4 -> 3208.4 | H4: =+D4+F4 -> 2960.4 | I4: =+(G4/H4-1)*100 -> 8.3772463 | J4: 40
A5: 38869 | C5: 414.3 | D5: 397.7 | E5: 2805.5 | F5: 2643.2 | G5: =+C5+E5 -> 3219.8 | H5: =+D5+F5 -> 3040.9 | I5: =+(G5/H5-1)*100 -> 5.8831267 | J5: 40
A6: 38876 | C6: 345.7 | D6: 371.1 | E6: 2911.8 | F6: 2734.2 | G6: =+C6+E6 -> 3257.5 | H6: =+D6+F6 -> 3105.3 | I6: =+(G6/H6-1)*100 -> 4.9012978 | J6: 40
A7: =+A6+7 -> 38883 | C7: 338.4 | D7: 359.5 | E7: 2971.9 | F7: 2834.1 | G7: =+C7+E7 -> 3310.3 | H7: =+D7+F7 -> 3193.6 | I7: =+(G7/H7-1)*100 -> 3.6541834 | J7: 40
A8: =+A7+7 -> 38890 | C8: 374.8 | D8: 338.8 | E8: 2993.4 | F8: 2923.9 | G8: =+C8+E8 -> 3368.2 | H8: =+D8+F8 -> 3262.7 | I8: =+(G8/H8-1)*100 -> 3.2335183 | J8: 40
A9: =+A8+7 -> 38897 | C9: 368.3 | D9: 378.5 | E9: 3025.4 | F9: 2956 | G9: =+C9+E9 -> 3393.7 | H9: =+D9+F9 -> 3334.5 | I9: =+(G9/H9-1)*100 -> 1.7753786 | J9: 40
A10: =+A9+7 -> 38904 | C10: 370.8 | D10: 327.2 | E10: 3072.2 | F10: 3019.5 | G10: =+C10+E10 -> 3443 | H10: =+D10+F10 -> 3346.7 | I10: =+(G10/H10-1)*100 -> 2.8774614 | J10: 71
A11: =+A10+7 -> 38911 | C11: 291.3 | D11: 322.4 | E11: 3154.6 | F11: 3060.8 | G11: =+C11+E11 -> 3445.9 | H11: =+D11+F11 -> 3383.2 | I11: =+(G11/H11-1)*100 -> 1.853275 | J11: 71
A12: =+A11+7 -> 38918 | C12: 307.2 | D12: 295 | E12: 3203.2 | F12: 3142.5 | G12: =+C12+E12 -> 3510.4 | H12: =+D12+F12 -> 3437.5 | I12: =+(G12/H12-1)*100 -> 2.1207273 | J12: 101
A13: =+A12+7 -> 38925 | C13: 303.6 | D13: 258.8 | E13: 3288.1 | F13: 3198.4 | G13: =+C13+E13 -> 3591.7 | H13: =+D13+F13 -> 3457.2 | I13: =+(G13/H13-1)*100 -> 3.8904316 | J13: 101
A14: =+A13+7 -> 38932 | C14: 253.1 | D14: 258.9 | E14: 3366.1 | F14: 3227 | G14: =+C14+E14 -> 3619.2 | H14: =+D14+F14 -> 3485.9 | I14: =+(G14/H14-1)*100 -> 3.8239766 | J14: 101
A15: =+A14+7 -> 38939 | C15: 283.2 | D15: 223.5 | E15: 3418.9 | F15: 3304.3 | G15: =+C15+E15 -> 3702.1 | H15: =+D15+F15 -> 3527.8 | I15: =+(G15/H15-1)*100 -> 4.9407563 | J15: 121
A16: =+A15+7 -> 38946 | C16: 240.4 | D16: 188.2 | E16: 3470 | F16: 3364.2 | G16: =+C16+E16 -> 3710.4 | H16: =+D16+F16 -> 3552.4 | I16: =+(G16/H16-1)*100 -> 4.4476973 | J16: 134.5
A17: =+A16+7 -> 38953 | C17: 172.2 | D17: 151.3 | E17: 3563.2 | F17: 3421.3 | G17: =+C17+E17 -> 3735.4 | H17: =+D17+F17 -> 3572.6 | I17: =+(G17/H17-1)*100 -> 4.5569053 | J17: 171.1
A18: =+A17+7 -> 38960 | C18: 150.7 | D18: 122.2 | E18: 3594 | F18: 3456.3 | G18: =+C18+E18 -> 3744.7 | H18: =+D18+F18 -> 3578.5 | I18: =+(G18/H18-1)*100 -> 4.6444041 | J18: 361.5
A19: =+A18+7 -> 38967 | C19: 365.3 | D19: 629.4 | E19: 128.1 | F19: 32.5 | G19: =+C19+E19 -> 493.4 | H19: =+D19+F19 -> 661.9 | I19: =+(G19/H19-1)*100 -> -25.457018
A20: =+A19+7 -> 38974 | C20: 389.7 | D20: 692.3 | E20: 162.3 | F20: 108.7 | G20: =+C20+E20 -> 552 | H20: =+D20+F20 -> 801 | I20: =+(G20/H20-1)*100 -> -31.086142
A21: =+A20+7 -> 38981 | C21: 411.8 | D21: 767.9 | E21: 238.4 | F21: 131.8 | G21: =+C21+E21 -> 650.2 | H21: =+D21+F21 -> 899.7 | I21: =+(G21/H21-1)*100 -> -27.731466
A22: =+A21+7 -> 38988 | C22: 395.8 | D22: 753.1 | E22: 316 | F22: 188.5 | G22: =+C22+E22 -> 711.8 | H22: =+D22+F22 -> 941.6 | I22: =+(G22/H22-1)*100 -> -24.405268
A23: =+A22+7 -> 38995 | C23: 408.6 | D23: 716.2 | E23: 397.1 | F23: 261.8 | G23: =+C23+E23 -> 805.7 | H23: =+D23+F23 -> 978 | I23: =+(G23/H23-1)*100 -> -17.617587
A24: =+A23+7 -> 39002 | C24: 341.1 | D24: 712.7 | E24: 568.8 | F24: 341.8 | G24: =+C24+E24 -> 909.9 | H24: =+D24+F24 -> 1054.5 | I24: =+(G24/H24-1)*100 -> -13.71266
A25: =+A24+7 -> 39009 | C25: 261.6 | D25: 606 | E25: 691.9 | F25: 512.9 | G25: =+C25+E25 -> 953.5 | H25: =+D25+F25 -> 1118.9 | I25: =+(G25/H25-1)*100 -> -14.782376
A26: =+A25+7 -> 39016 | C26: 388.1 | D26: 638.6 | E26: 721.5 | F26: 607.1 | G26: =+C26+E26 -> 1109.6 | H26: =+D26+F26 -> 1245.7 | I26: =+(G26/H26-1)*100 -> -10.925584
A27: =+A26+7 -> 39023 | C27: 394 | D27: 566.1 | E27: 803.3 | F27: 736.2 | G27: =+C27+E27 -> 1197.3 | H27: =+D27+F27 -> 1302.3 | I27: =+(G27/H27-1)*100 -> -8.0626584
A28: =+A27+7 -> 39030 | C28: 356.3 | D28: 486.1 | E28: 905.3 | F28: 830.8 | G28: =+C28+E28 -> 1261.6 | H28: =+D28+F28 -> 1316.9 | I28: =+(G28/H28-1)*100 -> -4.1992558
A29: =+A28+7 -> 39037 | C29: 415.8 | D29: 459.1 | E29: 922.4 | F29: 927.2 | G29: =+C29+E29 -> 1338.2 | H29: =+D29+F29 -> 1386.3 | I29: =+(G29/H29-1)*100 -> -3.4696675
A30: =+A29+7 -> 39044 | C30: 402.8 | D30: 443.7 | E30: 979 | F30: 951.7 | G30: =+C30+E30 -> 1381.8 | H30: =+D30+F30 -> 1395.4 | I30: =+(G30/H30-1)*100 -> -0.97463093
... A52: =+A51+7 -> 39198 | C52: 826.6 | D52: 422.6 | E52: 2583.8 | F52: 2403.6 | G52: =+C52+E52 -> 3410.4 | H52: =+D52+F52 -> 2826.2 | I52: =+(G52/H52-1)*100 -> 20.670865
A53: =+A52+7 -> 39205 | C53: 789.4 | D53: 447.1 | E53: 2639.3 | F53: 2460.5 | G53: =+C53+E53 -> 3428.7 | H53: =+D53+F53 -> 2907.6 | I53: =+(G53/H53-1)*100 -> 17.921998 | J53: 180
A54: =+A53+7 -> 39212 | C54: 759.6 | D54: 450.1 | E54: 2704.5 | F54: 2563.4 | G54: =+C54+E54 -> 3464.1 | H54: =+D54+F54 -> 3013.5 | I54: =+(G54/H54-1)*100 -> 14.952713 | J54: 180
A55: =+A54+7 -> 39219 | C55: 624.5 | D55: 489.8 | E55: 2839.5 | F55: 2635.8 | G55: =+C55+E55 -> 3464 | H55: =+D55+F55 -> 3125.6 | I55: =+(G55/H55-1)*100 -> 10.826721 | J55: 211
A56: =+A55+7 -> 39226 | C56: 683.7 | D56: 475.1 | E56: 2908.1 | F56: 2733.3 | G56: =+C56+E56 -> 3591.8 | H56: =+D56+F56 -> 3208.4 | I56: =+(G56/H56-1)*100 -> 11.949882 | J56: 241
A57: =+A56+7 -> 39233 | C57: 663 | D57: 414.3 | E57: 2943.7 | F57: 2805.5 | G57: =+C57+E57 -> 3606.7 | H57: =+D57+F57 -> 3219.8 | I57: =+(G57/H57-1)*100 -> 12.016274 | J57: 241
A58: =+A57+7 -> 39240 | C58: 682.9 | D58: 345.7 | E58: 2995 | F58: 2911.8 | G58: =+C58+E58 -> 3677.9 | H58: =+D58+F58 -> 3257.5 | I58: =+(G58/H58-1)*100 -> 12.905602 | J58: 241
A59: =+A58+7 -> 39247 | C59: 724.3 | D59: 338.4 | E59: 3061.3 | F59: 2971.9 | G59: =+C59+E59 -> 3785.6 | H59: =+D59+F59 -> 3310.3 | I59: =+(G59/H59-1)*100 -> 14.358215 | J59: 272
A60: =+A59+7 -> 39254 | C60: 658 | D60: 374.8 | E60: 3196.8 | F60: 2993.4 | G60: =+C60+E60 -> 3854.8 | H60: =+D60+F60 -> 3368.2 | I60: =+(G60/H60-1)*100 -> 14.446886 | J60: 272
A61: =+A60+7 -> 39261 | C61: 693.4 | D61: 368.3 | E61: 3252.4 | F61: 3025.4 | G61: =+C61+E61 -> 3945.8 | H61: =+D61+F61 -> 3393.7 | I61: =+(G61/H61-1)*100 -> 16.26838 | J61: 283
...

Sheet Japan
C1: Unshipped Balance | E1: Accumulated Exports | G1: Total Commitments | K1: 05/06Projected | L1: 04/05
A2: EXPORT SALES, Japan | C2: 2011 | D2: 2010 | E2: 2011 | F2: 2010 | G2: 2011 | H2: 2010 | I2: % change | K2: Exports | L2: Exports
A3: 38855 | C3: 370 | D3: 438.6 | E3: 2197.5 | F3: 2358.2 | G3: =+C3+E3 -> 2567.5 | H3: =+D3+F3 -> 2796.8 | I3: =+(G3/H3-1)*100 -> -8.1986556
A4: =+A3+7 -> 38862 | C4: 365.1 | D4: 411 | E4: 2254.9 | F4: 2431.2 | G4: =+C4+E4 -> 2620 | H4: =+D4+F4 -> 2842.2 | I4: =+(G4/H4-1)*100 -> -7.8178876 | J4: 393.2
A5: =+A4+7 -> 38869 | C5: 370.9 | D5: 385.2 | E5: 2347.3 | F5: 2450.1 | G5: =+C5+E5 -> 2718.2 | H5: =+D5+F5 -> 2835.3 | I5: =+(G5/H5-1)*100 -> -4.1300744 | J5: 393.2
A6: =+A5+7 -> 38876 | C6: 436.7 | D6: 428.9 | E6: 2353.1 | F6: 2509.6 | G6: =+C6+E6 -> 2789.8 | H6: =+D6+F6 -> 2938.5 | I6: =+(G6/H6-1)*100 -> -5.060405 | J6: 393.4
A7: =+A6+7 -> 38883 | C7: 366.6 | D7: 356 | E7: 2416 | F7: 2610.7 | G7: =+C7+E7 -> 2782.6 | H7: =+D7+F7 -> 2966.7 | I7: =+(G7/H7-1)*100 -> -6.2055483 | J7: 393.4
A8: =+A7+7 -> 38890 | C8: 417.1 | D8: 357.5 | E8: 2451.1 | F8: 2647.5 | G8: =+C8+E8 -> 2868.2 | H8: =+D8+F8 -> 3005 | I8: =+(G8/H8-1)*100 -> -4.5524126 | J8: 393.4
A9: =+A8+7 -> 38897 | C9: 458.1 | D9: 371 | E9: 2477.8 | F9: 2660.1 | G9: =+C9+E9 -> 2935.9 | H9: =+D9+F9 -> 3031.1 | I9: =+(G9/H9-1)*100 -> -3.140774 | J9: 393.4
A10: =+A9+7 -> 38904 | C10: 435.4 | D10: 393.4 | E10: 2517.6 | F10: 2684 | G10: =+C10+E10 -> 2953 | H10: =+D10+F10 -> 3077.4 | I10: =+(G10/H10-1)*100 -> -4.0423734 | J10: 393.6
A11: =+A10+7 -> 38911 | C11: 494.8 | D11: 365.3 | E11: 2541.1 | F11: 2729.4 | G11: =+C11+E11 -> 3035.9 | H11: =+D11+F11 -> 3094.7 | I11: =+(G11/H11-1)*100 -> -1.9000226 | J11: 393.6
A12: =+A11+7 -> 38918 | C12: 448.3 | D12: 326.4 | E12: 2614.4 | F12: 2804 | G12: =+C12+E12 -> 3062.7 | H12: =+D12+F12 -> 3130.4 | I12: =+(G12/H12-1)*100 -> -2.1626629 | J12: 410.2
A13: =+A12+7 -> 38925 | C13: 381.1 | D13: 373.5 | E13: 2700.7 | F13: 2810.7 | G13: =+C13+E13 -> 3081.8 | H13: =+D13+F13 -> 3184.2 | I13: =+(G13/H13-1)*100 -> -3.2158784 | J13: 410.2
A14: =+A13+7 -> 38932 | C14: 354.1 | D14: 331.9 | E14: 2744.8 | F14: 2851.9 | G14: =+C14+E14 -> 3098.9 | H14: =+D14+F14 -> 3183.8 | I14: =+(G14/H14-1)*100 -> -2.6666248 | J14: 444.2
A15: =+A14+7 -> 38939 | C15: 329.9 | D15: 256 | E15: 2757.7 | F15: 2966.1 | G15: =+C15+E15 -> 3087.6 | H15: =+D15+F15 -> 3222.1 | I15: =+(G15/H15-1)*100 -> -4.1742963 | J15: 498
... A18: =+A17+7 -> 38960 | C18: 209 | D18: 167.6 | E18: 3018.8 | F18: 3121.6 | G18: =+C18+E18 -> 3227.8 | H18: =+D18+F18 -> 3289.2 | I18: =+(G18/H18-1)*100 -> -1.8667153 | J18: 776
A19: =+A18+7 -> 38967 | C19: 739 | D19: 656 | E19: 40.6 | F19: 1.4 | G19: =+C19+E19 -> 779.6 | H19: =+D19+F19 -> 657.4 | I19: =+(G19/H19-1)*100 -> 18.588378
A20: =+A19+7 -> 38974 | C20: 777.8 | D20: 626.2 | E20: 95.9 | F20: 46.6 | G20: =+C20+E20 -> 873.7 | H20: =+D20+F20 -> 672.8 | I20: =+(G20/H20-1)*100 -> 29.860285
A21: =+A20+7 -> 38981 | C21: 871.3 | D21: 672.1 | E21: 105.6 | F21: 47.3 | G21: =+C21+E21 -> 976.9 | H21: =+D21+F21 -> 719.4 | I21: =+(G21/H21-1)*100 -> 35.793717
A22: =+A21+7 -> 38988 | C22: 859.6 | D22: 680 | E22: 142.8 | F22: 64.4 | G22: =+C22+E22 -> 1002.4 | H22: =+D22+F22 -> 744.4 | I22: =+(G22/H22-1)*100 -> 34.658786
A23: =+A22+7 -> 38995 | C23: 888.7 | D23: 783.4 | E23: 199.4 | F23: 82.1 | G23: =+C23+E23 -> 1088.1 | H23: =+D23+F23 -> 865.5 | I23: =+(G23/H23-1)*100 -> 25.719237
A24: =+A23+7 -> 39002 | C24: 865.8 | D24: 800.7 | E24: 271.7 | F24: 155.9 | G24: =+C24+E24 -> 1137.5 | H24: =+D24+F24 -> 956.6 | I24: =+(G24/H24-1)*100 -> 18.910725
A25: =+A24+7 -> 39009 | C25: 775.1 | D25: 798.4 | E25: 363.7 | F25: 243.9 | G25: =+C25+E25 -> 1138.8 | H25: =+D25+F25 -> 1042.3 | I25: =+(G25/H25-1)*100 -> 9.2583709
A26: =+A25+7 -> 39016 | C26: 775.8 | D26: 792.9 | E26: 397.4 | F26: 311.9 | G26: =+C26+E26 -> 1173.2 | H26: =+D26+F26 -> 1104.8 | I26: =+(G26/H26-1)*100 -> 6.1911658
A27: =+A26+7 -> 39023 | C27: 838.6 | D27: 802.3 | E27: 410.4 | F27: 346.8 | G27: =+C27+E27 -> 1249 | H27: =+D27+F27 -> 1149.1 | I27: =+(G27/H27-1)*100 -> 8.6937603
A28: =+A27+7 -> 39030 | C28: 740.6 | D28: 882.6 | E28: 538.8 | F28: 362.3 | G28: =+C28+E28 -> 1279.4 | H28: =+D28+F28 -> 1244.9 | I28: =+(G28/H28-1)*100 -> 2.7713069
A29: =+A28+7 -> 39037 | C29: 783.4 | D29: 815.8 | E29: 600.8 | F29: 451 | G29: =+C29+E29 -> 1384.2 | H29: =+D29+F29 -> 1266.8 | I29: =+(G29/H29-1)*100 -> 9.2674455
A30: =+A29+7 -> 39044 | C30: 747.8 | D30: 674.2 | E30: 675.6 | F30: 565.2 | G30: =+C30+E30 -> 1423.4 | H30: =+D30+F30 -> 1239.4 | I30: =+(G30/H30-1)*100 -> 14.845893
... A34: =+A33+7 -> 39072 | C34: 766.7 | D34: 665.8 | E34: 964.3 | F34: 852.8 | G34: =+C34+E34 -> 1731 | H34: =+D34+F34 -> 1518.6 | I34: =+(G34/H34-1)*100 -> 13.986567
A35: =+A34+7 -> 39079 | C35: 749.8 | D35: 650.5 | E35: 996.8 | F35: 903.3 | G35: =+C35+E35 -> 1746.6 | H35: =+D35+F35 -> 1553.8 | I35: =+(G35/H35-1)*100 -> 12.408289 | J35: 13.6
A36: =+A35+7 -> 39086 | C36: 724.1 | D36: 624.9 | E36: 1051.5 | F36: 994.1 | G36: =+C36+E36 -> 1775.6 | H36: =+D36+F36 -> 1619 | I36: =+(G36/H36-1)*100 -> 9.6726374
A37: =+A36+7 -> 39093 | C37: 761 | D37: 619.7 | E37: 1080.9 | F37: 1092 | G37: =+C37+E37 -> 1841.9 | H37: =+D37+F37 -> 1711.7 | I37: =+(G37/H37-1)*100 -> 7.6064731
A38: =+A37+7 -> 39100 | C38: 755 | D38: 594 | E38: 1139.1 | F38: 1200.2 | G38: =+C38+E38 -> 1894.1 | H38: =+D38+F38 -> 1794.2 | I38: =+(G38/H38-1)*100 -> 5.5679411 | J38: 16.3
A39: =+A38+7 -> 39107 | C39: 782.6 | D39: 581.3 | E39: 1186.1 | F39: 1286.8 | G39: =+C39+E39 -> 1968.7 | H39: =+D39+F39 -> 1868.1 | I39: =+(G39/H39-1)*100 -> 5.3851507
A40: =+A39+7 -> 39114 | C40: 689.3 | D40: 554.8 | E40: 1291.4 | F40: 1318.3 | G40: =+C40+E40 -> 1980.7 | H40: =+D40+F40 -> 1873.1 | I40: =+(G40/H40-1)*100 -> 5.7444877
A41: =+A40+7 -> 39121 | C41: 730.6 | D41: 464 | E41: 1363.1 | F41: 1418.6 | G41: =+C41+E41 -> 2093.7 | H41: =+D41+F41 -> 1882.6 | I41: =+(G41/H41-1)*100 -> 11.213216
A42: =+A41+7 -> 39128 | C42: 704.3 | D42: 484 | E42: 1432.8 | F42: 1441.4 | G42: =+C42+E42 -> 2137.1 | H42: =+D42+F42 -> 1925.4 | I42: =+(G42/H42-1)*100 -> 10.995118
A43: =+A42+7 -> 39135 | C43: 622.8 | D43: 507.9 | E43: 1556.8 | F43: 1456.4 | G43: =+C43+E43 -> 2179.6 | H43: =+D43+F43 -> 1964.3 | I43: =+(G43/H43-1)*100 -> 10.960648
A44: =+A43+7 -> 39142 | C44: 654.1 | D44: 500 | E44: 1642.8 | F44: 1594.5 | G44: =+C44+E44 -> 2296.9 | H44: =+D44+F44 -> 2094.5 | I44: =+(G44/H44-1)*100 -> 9.6634042
A45: =+A44+7 -> 39149 | C45: 602.5 | D45: 434.9 | E45: 1726.8 | F45: 1671 | G45: =+C45+E45 -> 2329.3 | H45: =+D45+F45 -> 2105.9 | I45: =+(G45/H45-1)*100 -> 10.608291
...

Sheet Taiwan
C1: Unshipped Balance | E1: Accumulated Exports | G1: Total Commitments | K1: 05/06Projected | L1: 04/05
A2: EXPORT SALES, Taiwan | C2: 2005 | D2: 2004 | E2: 2005 | F2: 2004 | G2: 2005 | H2: 2004 | I2: % change | K2: Exports | L2: Exports
A4: =China!A3 -> 38855 | B4: Taiwan | C4: 79.3 | D4: 164.6 | E4: 1307.6 | F4: 1356.3 | G4: =+C4+E4 -> 1386.9 | H4: =+D4+F4 -> 1520.9 | I4: =+(G4/H4-1)*100 -> -8.8105727
A5: =+A4+7 -> 38862 | B5: Taiwan | C5: 154.5 | D5: 153.3 | E5: 1316.9 | F5: 1370.1 | G5: =+C5+E5 -> 1471.4 | H5: =+D5+F5 -> 1523.4 | I5: =+(G5/H5-1)*100 -> -3.4134174 | J5: 0
A6: =+A5+7 -> 38869 | B6: Taiwan | C6: 126.3 | D6: 134.9 | E6: 1352 | F6: 1388.8 | G6: =+C6+E6 -> 1478.3 | H6: =+D6+F6 -> 1523.7 | I6: =+(G6/H6-1)*100 -> -2.9795892 | J6: 0
A7: =+A6+7 -> 38876 | B7: Taiwan | C7: 175 | D7: 133.9 | E7: 1369.3 | F7: 1398.9 | G7: =+C7+E7 -> 1544.3 | H7: =+D7+F7 -> 1532.8 | I7: =+(G7/H7-1)*100 -> 0.75026096 | J7: 0
A8: =+A7+7 -> 38883 | B8: Taiwan | C8: 205.5 | D8: 96.3 | E8: 1376.8 | F8: 1437.4 | G8: =+C8+E8 -> 1582.3 | H8: =+D8+F8 -> 1533.7 | I8: =+(G8/H8-1)*100 -> 3.1688075 | J8: 0
A9: =+A8+7 -> 38890 | B9: Taiwan | C9: 200.1 | D9: 91.7 | E9: 1479.3 | F9: 1442 | G9: =+C9+E9 -> 1679.4 | H9: =+D9+F9 -> 1533.7 | I9: =+(G9/H9-1)*100 -> 9.4999022 | J9: 0
A10: =+A9+7 -> 38897 | B10: Taiwan | C10: 157.7 | D10: 120.3 | E10: 1537.3 | F10: 1446 | G10: =+C10+E10 -> 1695 | H10: =+D10+F10 -> 1566.3 | I10: =+(G10/H10-1)*100 -> 8.2168167 | J10: 0
A11: =+A10+7 -> 38904 | B11: Taiwan | C11: 238.3 | D11: 115.9 | E11: 1549.1 | F11: 1450.6 | G11: =+C11+E11 -> 1787.4 | H11: =+D11+F11 -> 1566.5 | I11: =+(G11/H11-1)*100 -> 14.1015 | J11: 2
A12: =+A11+7 -> 38911 | B12: Taiwan | C12: 234.8 | D12: 118.9 | E12: 1561.5 | F12: 1450.6 | G12: =+C12+E12 -> 1796.3 | H12: =+D12+F12 -> 1569.5 | I12: =+(G12/H12-1)*100 -> 14.450462 | J12: 6
A13: =+A12+7 -> 38918 | B13: Taiwan | C13: 275.5 | D13: 62.8 | E13: 1572.9 | F13: 1450.9 | G13: =+C13+E13 -> 1848.4 | H13: =+D13+F13 -> 1513.7 | I13: =+(G13/H13-1)*100 -> 22.111383 | J13: 9
A14: =+A13+7 -> 38925 | B14: Taiwan | C14: 304.4 | D14: 68.4 | E14: 1579.1 | F14: 1451.8 | G14: =+C14+E14 -> 1883.5 | H14: =+D14+F14 -> 1520.2 | I14: =+(G14/H14-1)*100 -> 23.898171 | J14: 46
A15: =+A14+7 -> 38932 | B15: Taiwan | C15: 297.1 | D15: 64.5 | E15: 1677.4 | F15: 1479.1 | G15: =+C15+E15 -> 1974.5 | H15: =+D15+F15 -> 1543.6 | I15: =+(G15/H15-1)*100 -> 27.915263 | J15: 53.5
A16: =+A15+7 -> 38939 | B16: Taiwan | C16: 291.7 | D16: 63.9 | E16: 1741.8 | F16: 1484.1 | G16: =+C16+E16 -> 2033.5 | H16: =+D16+F16 -> 1548 | I16: =+(G16/H16-1)*100 -> 31.363049 | J16: 55.5
... A19: =+A18+7 -> 38960 | B19: Taiwan | C19: 141.8 | D19: 59.4 | E19: 1850.3 | F19: 1525.4 | G19: =+C19+E19 -> 1992.1 | H19: =+D19+F19 -> 1584.8 | I19: =+(G19/H19-1)*100 -> 25.700404 | J19: 351.7
A20: =+A19+7 -> 38967 | B20: Taiwan | C20: 369.4 | D20: 235.1 | E20: 11.8 | F20: 0.8 | G20: =+C20+E20 -> 381.2 | H20: =+D20+F20 -> 235.9 | I20: =+(G20/H20-1)*100 -> 61.593896
A21: =+A20+7 -> 38974 | B21: Taiwan | C21: 367.2 | D21: 254.9 | E21: 31.9 | F21: 31.3 | G21: =+C21+E21 -> 399.1 | H21: =+D21+F21 -> 286.2 | I21: =+(G21/H21-1)*100 -> 39.447939
A22: =+A21+7 -> 38981 | B22: Taiwan | C22: 412.1 | D22: 269.3 | E22: 64.6 | F22: 56.3 | G22: =+C22+E22 -> 476.7 | H22: =+D22+F22 -> 325.6 | I22: =+(G22/H22-1)*100 -> 46.406634
A23: =+A22+7 -> 38988 | B23: Taiwan | C23: 425.4 | D23: 265.2 | E23: 96.4 | F23: 66.9 | G23: =+C23+E23 -> 521.8 | H23: =+D23+F23 -> 332.1 | I23: =+(G23/H23-1)*100 -> 57.121349
A24: =+A23+7 -> 38995 | B24: Taiwan | C24: 385.6 | D24: 279.8 | E24: 180.8 | F24: 100.5 | G24: =+C24+E24 -> 566.4 | H24: =+D24+F24 -> 380.3 | I24: =+(G24/H24-1)*100 -> 48.935051
A25: =+A24+7 -> 39002 | B25: Taiwan | C25: 350.7 | D25: 242.8 | E25: 218.2 | F25: 138.7 | G25: =+C25+E25 -> 568.9 | H25: =+D25+F25 -> 381.5 | I25: =+(G25/H25-1)*100 -> 49.121887
A26: =+A25+7 -> 39009 | B26: Taiwan | C26: 374.5 | D26: 301.4 | E26: 256.8 | F26: 150.1 | G26: =+C26+E26 -> 631.3 | H26: =+D26+F26 -> 451.5 | I26: =+(G26/H26-1)*100 -> 39.822813
A27: =+A26+7 -> 39016 | B27: Taiwan | C27: 343.1 | D27: 239.8 | E27: 336.9 | F27: 221.1 | G27: =+C27+E27 -> 680 | H27: =+D27+F27 -> 460.9 | I27: =+(G27/H27-1)*100 -> 47.537427
A28: =+A27+7 -> 39023 | B28: Taiwan | C28: 409 | D28: 295.6 | E28: 350.2 | F28: 288.7 | G28: =+C28+E28 -> 759.2 | H28: =+D28+F28 -> 584.3 | I28: =+(G28/H28-1)*100 -> 29.933253
A29: =+A28+7 -> 39030 | B29: Taiwan | C29: 431 | D29: 212.1 | E29: 373.5 | F29: 382.5 | G29: =+C29+E29 -> 804.5 | H29: =+D29+F29 -> 594.6 | I29: =+(G29/H29-1)*100 -> 35.301043
A30: =+A29+7 -> 39037 | B30: Taiwan | C30: 395.7 | D30: 238.4 | E30: 452.4 | F30: 401.6 | G30: =+C30+E30 -> 848.1 | H30: =+D30+F30 -> 640 | I30: =+(G30/H30-1)*100 -> 32.515625
A31: =+A30+7 -> 39044 | B31: Taiwan | C31: 408.6 | D31: 230.4 | E31: 470.1 | F31: 413.8 | G31: =+C31+E31 -> 878.7 | H31: =+D31+F31 -> 644.2 | I31: =+(G31/H31-1)*100 -> 36.401739
... A53: =+A52+7 -> 39198 | B53: Taiwan | C53: 142.8 | D53: 112.5 | E53: 1375.9 | F53: 1260.8 | G53: =+C53+E53 -> 1518.7 | H53: =+D53+F53 -> 1373.3 | I53: =+(G53/H53-1)*100 -> 10.587636
A54: =+A53+7 -> 39205 | B54: Taiwan | C54: 160.1 | D54: 102.6 | E54: 1406 | F54: 1270.9 | G54: =+C54+E54 -> 1566.1 | H54: =+D54+F54 -> 1373.5 | I54: =+(G54/H54-1)*100 -> 14.02257 | J54: 0
A55: =+A54+7 -> 39212 | B55: Taiwan | C55: 176.1 | D55: 84.2 | E55: 1432.3 | F55: 1293.1 | G55: =+C55+E55 -> 1608.4 | H55: =+D55+F55 -> 1377.3 | I55: =+(G55/H55-1)*100 -> 16.779206
A56: =+A55+7 -> 39219 | B56: Taiwan | C56: 183.6 | D56: 79.3 | E56: 1453.5 | F56: 1307.6 | G56: =+C56+E56 -> 1637.1 | H56: =+D56+F56 -> 1386.9 | I56: =+(G56/H56-1)*100 -> 18.040234
A57: =+A56+7 -> 39226 | B57: Taiwan | C57: 173.5 | D57: 154.5 | E57: 1484.7 | F57: 1316.9 | G57: =+C57+E57 -> 1658.2 | H57: =+D57+F57 -> 1471.4 | I57: =+(G57/H57-1)*100 -> 12.695392 | J57: 0
A58: =+A57+7 -> 39233 | B58: Taiwan | C58: 167.8 | D58: 126.3 | E58: 1507.6 | F58: 1352 | G58: =+C58+E58 -> 1675.4 | H58: =+D58+F58 -> 1478.3 | I58: =+(G58/H58-1)*100 -> 13.332882
A59: =+A58+7 -> 39240 | B59: Taiwan | C59: 189.2 | D59: 175 | E59: 1539 | F59: 1369.3 | G59: =+C59+E59 -> 1728.2 | H59: =+D59+F59 -> 1544.3 | I59: =+(G59/H59-1)*100 -> 11.908308
A60: =+A59+7 -> 39247 | B60: Taiwan | C60: 202.7 | D60: 205.5 | E60: 1561.9 | F60: 1376.8 | G60: =+C60+E60 -> 1764.6 | H60: =+D60+F60 -> 1582.3 | I60: =+(G60/H60-1)*100 -> 11.521203
A61: =+A60+7 -> 39254 | B61: Taiwan | C61: 235.7 | D61: 200.1 | E61: 1585.1 | F61: 1461.5 | G61: =+C61+E61 -> 1820.8 | H61: =+D61+F61 -> 1661.6 | I61: =+(G61/H61-1)*100 -> 9.5811266
A62: =+A61+7 -> 39261 | B62: Taiwan | C62: 240.2 | D62: 157.7 | E62: 1614.2 | F62: 1528.5 | G62: =+C62+E62 -> 1854.4 | H62: =+D62+F62 -> 1686.2 | I62: =+(G62/H62-1)*100 -> 9.9750919 | J62: 4
A63: =+A62+7 -> 39268 | B63: Taiwan | C63: 235.9 | D63: 238.3 | E63: 1635.6 | F63: 1540.2 | G63: =+C63+E63 -> 1871.5 | H63: =+D63+F63 -> 1778.5 | I63: =+(G63/H63-1)*100 -> 5.2291257 | J63: 6
A64: =+A63+7 -> 39275 | B64: Taiwan | C64: 223.8 | D64: 234.8 | E64: 1678.8 | F64: 1552.7 | G64: =+C64+E64 -> 1902.6 | H64: =+D64+F64 -> 1787.5 | I64: =+(G64/H64-1)*100 -> 6.4391608 | J64: 15
...

Sheet Indonesia
C1: Unshipped Balance | E1: Accumulated Exports | G1: Total Commitments | J1: 05/06Projected | K1: 04/05
A2: EXPORT SALES, Indonesia | C2: 2005 | D2: 2004 | E2: 2005 | F2: 2004 | G2: 2005 | H2: 2004 | I2: % change | J2: Exports | K2: Exports
A3: 38855 | C3: 113.6 | D3: 43.8 | E3: 944.7 | F3: 858.8 | G3: =+C3+E3 -> 1058.3 | H3: =+D3+F3 -> 902.6 | I3: =+(G3/H3-1)*100 -> 17.250166
A4: =+A3+7 -> 38862 | C4: 58.9 | D4: 43.8 | E4: 1010.7 | F4: 858.8 | G4: =+C4+E4 -> 1069.6 | H4: =+D4+F4 -> 902.6 | I4: =+(G4/H4-1)*100 -> 18.502105
A5: =+A4+7 -> 38869 | C5: 57.8 | D5: 43.8 | E5: 1011.8 | F5: 858.8 | G5: =+C5+E5 -> 1069.6 | H5: =+D5+F5 -> 902.6 | I5: =+(G5/H5-1)*100 -> 18.502105
A6: =+A5+7 -> 38876 | C6: 57 | D6: 4.8 | E6: 1012.6 | F6: 900.8 | G6: =+C6+E6 -> 1069.6 | H6: =+D6+F6 -> 905.6 | I6: =+(G6/H6-1)*100 -> 18.109541 | J6: 0
A7: =+A6+7 -> 38883 | C7: 61.5 | D7: 4.8 | E7: 1012.6 | F7: 924.1 | G7: =+C7+E7 -> 1074.1 | H7: =+D7+F7 -> 928.9 | I7: =+(G7/H7-1)*100 -> 15.631392 | J7: 0
A8: =+A7+7 -> 38890 | C8: 63.5 | D8: 4.8 | E8: 1072.5 | F8: 924.1 | G8: =+C8+E8 -> 1136 | H8: =+D8+F8 -> 928.9 | I8: =+(G8/H8-1)*100 -> 22.295188 | J8: 0
A9: =+A8+7 -> 38897 | C9: 63.2 | D9: 4.8 | E9: 1072.8 | F9: 948.6 | G9: =+C9+E9 -> 1136 | H9: =+D9+F9 -> 953.4 | I9: =+(G9/H9-1)*100 -> 19.152507 | J9: 0
A10: =+A9+7 -> 38904 | C10: 63.2 | D10: 4.8 | E10: 1097.2 | F10: 948.6 | G10: =+C10+E10 -> 1160.4 | H10: =+D10+F10 -> 953.4 | I10: =+(G10/H10-1)*100 -> 21.711768 | J10: 0
A11: =+A10+7 -> 38911 | C11: 95.2 | D11: 4.8 | E11: 1098.2 | F11: 948.6 | G11: =+C11+E11 -> 1193.4 | H11: =+D11+F11 -> 953.4 | I11: =+(G11/H11-1)*100 -> 25.173065 | J11: 0
A12: =+A11+7 -> 38918 | C12: 37.5 | D12: 4.8 | E12: 1162.1 | F12: 948.6 | G12: =+C12+E12 -> 1199.6 | H12: =+D12+F12 -> 953.4 | I12: =+(G12/H12-1)*100 -> 25.823369 | J12: 0
A13: =+A12+7 -> 38925 | C13: 37.5 | D13: 9.3 | E13: 1164.2 | F13: 948.6 | G13: =+C13+E13 -> 1201.7 | H13: =+D13+F13 -> 957.9 | I13: =+(G13/H13-1)*100 -> 25.451509 | J13: 0
A14: =+A13+7 -> 38932 | C14: 43.1 | D14: 10.3 | E14: 1165.5 | F14: 949.1 | G14: =+C14+E14 -> 1208.6 | H14: =+D14+F14 -> 959.4 | I14: =+(G14/H14-1)*100 -> 25.974567 | J14: 0
A15: =+A14+7 -> 38939 | C15: 50 | D15: 70.4 | E15: 1167.6 | F15: 950.5 | G15: =+C15+E15 -> 1217.6 | H15: =+D15+F15 -> 1020.9 | I15: =+(G15/H15-1)*100 -> 19.267313 | J15: 0
A16: =+A15+7 -> 38946 | C16: 52.7 | D16: 68.6 | E16: 1171 | F16: 953.7 | G16: =+C16+E16 -> 1223.7 | H16: =+D16+F16 -> 1022.3 | I16: =+(G16/H16-1)*100 -> 19.700675 | J16: 0
A17: =+A16+7 -> 38953 | C17: 49.1 | D17: 63.8 | E17: 1178.6 | F17: 958.5 | G17: =+C17+E17 -> 1227.7 | H17: =+D17+F17 -> 1022.3 | I17: =+(G17/H17-1)*100 -> 20.09195 | J17: 25
A18: =+A17+7 -> 38960 | C18: 16.2 | D18: 119.8 | E18: 1211.1 | F18: 959.5 | G18: =+C18+E18 -> 1227.3 | H18: =+D18+F18 -> 1079.3 | I18: =+(G18/H18-1)*100 -> 13.712591 | J18: 102.2
A19: =+A18+7 -> 38967 | C19: 100 | D19: 62.9 | E19: 2.4 | F19: 84.2 | G19: =+C19+E19 -> 102.4 | H19: =+D19+F19 -> 147.1 | I19: =+(G19/H19-1)*100 -> -30.387492
A20: =+A19+7 -> 38974 | C20: 99 | D20: 67.5 | E20: 3.4 | F20: 86.6 | G20: =+C20+E20 -> 102.4 | H20: =+D20+F20 -> 154.1 | I20: =+(G20/H20-1)*100 -> -33.549643
A21: =+A20+7 -> 38981 | C21: 98.7 | D21: 70.2 | E21: 3.7 | F21: 89.2 | G21: =+C21+E21 -> 102.4 | H21: =+D21+F21 -> 159.4 | I21: =+(G21/H21-1)*100 -> -35.759097
A22: =+A21+7 -> 38988 | C22: 156.1 | D22: 67.9 | E22: 4.3 | F22: 91.1 | G22: =+C22+E22 -> 160.4 | H22: =+D22+F22 -> 159 | I22: =+(G22/H22-1)*100 -> 0.88050314
A23: =+A22+7 -> 38995 | C23: 155.9 | D23: 76 | E23: 71.7 | F23: 92.4 | G23: =+C23+E23 -> 227.6 | H23: =+D23+F23 -> 168.4 | I23: =+(G23/H23-1)*100 -> 35.154394
A24: =+A23+7 -> 39002 | C24: 135.3 | D24: 16 | E24: 132.8 | F24: 160 | G24: =+C24+E24 -> 268.1 | H24: =+D24+F24 -> 176 | I24: =+(G24/H24-1)*100 -> 52.329545
A25: =+A24+7 -> 39009 | C25: 83.3 | D25: 26 | E25: 194.8 | F25: 278.9 | G25: =+C25+E25 -> 278.1 | H25: =+D25+F25 -> 304.9 | I25: =+(G25/H25-1)*100 -> -8.7897671
A26: =+A25+7 -> 39016 | C26: 23 | D26: 31.1 | E26: 264.7 | F26: 281.9 | G26: =+C26+E26 -> 287.7 | H26: =+D26+F26 -> 313 | I26: =+(G26/H26-1)*100 -> -8.0830671
A27: =+A26+7 -> 39023 | C27: 21.9 | D27: 25.1 | E27: 290.2 | F27: 355.5 | G27: =+C27+E27 -> 312.1 | H27: =+D27+F27 -> 380.6 | I27: =+(G27/H27-1)*100 -> -17.997898
A28: =+A27+7 -> 39030 | C28: 21.2 | D28: 79.5 | E28: 359.1 | F28: 358.1 | G28: =+C28+E28 -> 380.3 | H28: =+D28+F28 -> 437.6 | I28: =+(G28/H28-1)*100 -> -13.09415
A29: =+A28+7 -> 39037 | C29: 26.8 | D29: 76.3 | E29: 361.5 | F29: 361.3 | G29: =+C29+E29 -> 388.3 | H29: =+D29+F29 -> 437.6 | I29: =+(G29/H29-1)*100 -> -11.265996
A30: =+A29+7 -> 39044 | C30: 86 | D30: 73.8 | E30: 362.3 | F30: 364.1 | G30: =+C30+E30 -> 448.3 | H30: =+D30+F30 -> 437.9 | I30: =+(G30/H30-1)*100 -> 2.3749715
... A39: =+A38+7 -> 39107 | C39: 243.9 | D39: 75.5 | E39: 546.7 | F39: 495.4 | G39: =+C39+E39 -> 790.6 | H39: =+D39+F39 -> 570.9 | I39: =+(G39/H39-1)*100 -> 38.483097
A40: =+A39+7 -> 39114
A41: =+A40+7 -> 39121 | C41: 185.1 | D41: 114.9 | E41: 621.9 | F41: 568.8 | G41: =+C41+E41 -> 807 | H41: =+D41+F41 -> 683.7 | I41: =+(G41/H41-1)*100 -> 18.034226
A42: =+A41+7 -> 39128 | C42: 312.1 | D42: 113.8 | E42: 623.9 | F42: 571.5 | G42: =+C42+E42 -> 936 | H42: =+D42+F42 -> 685.3 | I42: =+(G42/H42-1)*100 -> 36.582519
A43: =+A42+7 -> 39135 | C43: 309.9 | D43: 62.2 | E43: 626.1 | F43: 630.6 | G43: =+C43+E43 -> 936 | H43: =+D43+F43 -> 692.8 | I43: =+(G43/H43-1)*100 -> 35.103926
A44: =+A43+7 -> 39142 | C44: 337.9 | D44: 62.1 | E44: 682.2 | F44: 634.6 | G44: =+C44+E44 -> 1020.1 | H44: =+D44+F44 -> 696.7 | I44: =+(G44/H44-1)*100 -> 46.418832
A45: =+A44+7 -> 39149 | C45: 328.3 | D45: 57 | E45: 691.8 | F45: 639.8 | G45: =+C45+E45 -> 1020.1 | H45: =+D45+F45 -> 696.8 | I45: =+(G45/H45-1)*100 -> 46.397819
A46: =+A45+7 -> 39156 | C46: 317.3 | D46: 54 | E46: 702.9 | F46: 643.9 | G46: =+C46+E46 -> 1020.2 | H46: =+D46+F46 -> 697.9 | I46: =+(G46/H46-1)*100 -> 46.181401
A47: =+A46+7 -> 39163 | C47: 279 | D47: 11 | E47: 820.3 | F47: 692.5 | G47: =+C47+E47 -> 1099.3 | H47: =+D47+F47 -> 703.5 | I47: =+(G47/H47-1)*100 -> 56.261549
A48: =+A47+7 -> 39170 | C48: 318.3 | D48: 128 | E48: 824.9 | F48: 717.9 | G48: =+C48+E48 -> 1143.2 | H48: =+D48+F48 -> 845.9 | I48: =+(G48/H48-1)*100 -> 35.145998
...

Sheet Korea
C1: Unshipped Balance | E1: Accumulated Exports | G1: Total Commitments
A2: EXPORT SALES, Korea | C2: 2005 | D2: 2004 | E2: 2005 | F2: 2004 | G2: 2005 | H2: 2004 | I2: % change
A3: 38855 | C3: 75 | D3: 156.5 | E3: 413.1 | F3: 705.9 | G3: =+C3+E3 -> 488.1 | H3: =+D3+F3 -> 862.4 | I3: =+(G3/H3-1)*100 -> -43.402134
A4: 38862 | C4: 75 | D4: 156.5 | E4: 413.1 | F4: 705.9 | G4: =+C4+E4 -> 488.1 | H4: =+D4+F4 -> 862.4 | I4: =+(G4/H4-1)*100 -> -43.402134
A5: 38869 | C5: 75 | D5: 156.5 | E5: 413.1 | F5: 705.9 | G5: =+C5+E5 -> 488.1 | H5: =+D5+F5 -> 862.4 | I5: =+(G5/H5-1)*100 -> -43.402134
A6: 38876 | C6: 75 | D6: 156.5 | E6: 413.1 | F6: 705.9 | G6: =+C6+E6 -> 488.1 | H6: =+D6+F6 -> 862.4 | I6: =+(G6/H6-1)*100 -> -43.402134 | J6: 0
A7: 38883 | C7: 75 | D7: 180 | E7: 413.1 | F7: 705.9 | G7: =+C7+E7 -> 488.1 | H7: =+D7+F7 -> 885.9 | I7: =+(G7/H7-1)*100 -> -44.903488
A8: 38890 | C8: 50 | D8: 180 | E8: 437.1 | F8: 705.9 | G8: =+C8+E8 -> 487.1 | H8: =+D8+F8 -> 885.9 | I8: =+(G8/H8-1)*100 -> -45.016368
A9: 38897 | C9: 50 | D9: 155 | E9: 437.1 | F9: 729.5 | G9: =+C9+E9 -> 487.1 | H9: =+D9+F9 -> 884.5 | I9: =+(G9/H9-1)*100 -> -44.929339
A10: 38904 | C10: 50 | D10: 155 | E10: 437.1 | F10: 729.5 | G10: =+C10+E10 -> 487.1 | H10: =+D10+F10 -> 884.5 | I10: =+(G10/H10-1)*100 -> -44.929339
A11: 38911 | C11: 50 | D11: 155 | E11: 461.8 | F11: 729.5 | G11: =+C11+E11 -> 511.8 | H11: =+D11+F11 -> 884.5 | I11: =+(G11/H11-1)*100 -> -42.1368
A12: 38918 | C12: 50 | D12: 25 | E12: 461.8 | F12: 755.8 | G12: =+C12+E12 -> 511.8 | H12: =+D12+F12 -> 780.8 | I12: =+(G12/H12-1)*100 -> -34.451844
A13: 38925 | C13: 25 | D13: 25 | E13: 486.8 | F13: 755.8 | G13: =+C13+E13 -> 511.8 | H13: =+D13+F13 -> 780.8 | I13: =+(G13/H13-1)*100 -> -34.451844
A14: 38932 | C14: 25 | D14: 25 | E14: 486.8 | F14: 755.8 | G14: =+C14+E14 -> 511.8 | H14: =+D14+F14 -> 780.8 | I14: =+(G14/H14-1)*100 -> -34.451844 | J14: 45
A15: 38939 | C15: 25 | D15: 25 | E15: 486.8 | F15: 755.8 | G15: =+C15+E15 -> 511.8 | H15: =+D15+F15 -> 780.8 | I15: =+(G15/H15-1)*100 -> -34.451844 | J15: 45
A16: 38946 | C16: 25 | D16: 0 | E16: 486.8 | F16: 780.1 | G16: =+C16+E16 -> 511.8 | H16: =+D16+F16 -> 780.1 | I16: =+(G16/H16-1)*100 -> -34.393027 | J16: 45
A17: 38953 | C17: 25 | D17: 0 | E17: 486.8 | F17: 780.1 | G17: =+C17+E17 -> 511.8 | H17: =+D17+F17 -> 780.1 | I17: =+(G17/H17-1)*100 -> -34.393027 | J17: 45
A18: 38960 | C18: 25 | D18: 0 | E18: 486.8 | F18: 780.1 | G18: =+C18+E18 -> 511.8 | H18: =+D18+F18 -> 780.1 | I18: =+(G18/H18-1)*100 -> -34.393027 | J18: 70
A19: 38967 | C19: 70 | D19: 282.5 | E19: 0 | F19: 0 | G19: =+C19+E19 -> 70 | H19: =+D19+F19 -> 282.5 | I19: =+(G19/H19-1)*100 -> -75.221239
A20: 38974 | C20: 160 | D20: 282.5 | E20: 0 | F20: 0 | G20: =+C20+E20 -> 160 | H20: =+D20+F20 -> 282.5 | I20: =+(G20/H20-1)*100 -> -43.362832
A21: 38981 | C21: 304 | D21: 282.5 | E21: 0 | F21: 0 | G21: =+C21+E21 -> 304 | H21: =+D21+F21 -> 282.5 | I21: =+(G21/H21-1)*100 -> 7.6106195
A22: 38988 | C22: 259 | D22: 282.5 | E22: 46.8 | F22: 0 | G22: =+C22+E22 -> 305.8 | H22: =+D22+F22 -> 282.5 | I22: =+(G22/H22-1)*100 -> 8.2477876
A23: 38995 | G23: =+C23+E23 -> 0 | H23: =+D23+F23 -> 0 | I23: =+(G23/H23-1)*100 -> #DIV/0!
A24: 39002 | C24: 369 | D24: 387.5 | E24: 56.5 | F24: 0 | G24: =+C24+E24 -> 425.5 | H24: =+D24+F24 -> 387.5 | I24: =+(G24/H24-1)*100 -> 9.8064516
A25: 39009 | C25: 324 | D25: 440 | E25: 99.8 | F25: 0 | G25: =+C25+E25 -> 423.8 | H25: =+D25+F25 -> 440 | I25: =+(G25/H25-1)*100 -> -3.6818182
A26: 39016 | C26: 324 | D26: 440.1 | E26: 99.8 | F26: 0 | G26: =+C26+E26 -> 423.8 | H26: =+D26+F26 -> 440.1 | I26: =+(G26/H26-1)*100 -> -3.7037037
A27: 39023 | C27: 332.5 | D27: 415.1 | E27: 99.8 | F27: 24.9 | G27: =+C27+E27 -> 432.3 | H27: =+D27+F27 -> 440 | I27: =+(G27/H27-1)*100 -> -1.75
A28: 39030 | C28: 332.5 | D28: 415.1 | E28: 123.6 | F28: 24.9 | G28: =+C28+E28 -> 456.1 | H28: =+D28+F28 -> 440 | I28: =+(G28/H28-1)*100 -> 3.6590909
A29: 39037 | C29: 287.5 | D29: 307.6 | E29: 172.8 | F29: 139.6 | G29: =+C29+E29 -> 460.3 | H29: =+D29+F29 -> 447.2 | I29: =+(G29/H29-1)*100 -> 2.9293381
A30: 39044 | C30: 287.5 | D30: 307.6 | E30: 172.8 | F30: 139.6 | G30: =+C30+E30 -> 460.3 | H30: =+D30+F30 -> 447.2 | I30: =+(G30/H30-1)*100 -> 2.9293381
A31: 39051 | C31: 235 | D31: 307.6 | E31: 230.2 | F31: 139.6 | G31: =+C31+E31 -> 465.2 | H31: =+D31+F31 -> 447.2 | I31: =+(G31/H31-1)*100 -> 4.0250447
A32: 39058 | C32: 235 | D32: 307.5 | E32: 230.2 | F32: 139.6 | G32: =+C32+E32 -> 465.2 | H32: =+D32+F32 -> 447.1 | I32: =+(G32/H32-1)*100 -> 4.0483113
A33: 39065 | C33: 235 | D33: 255 | E33: 230.2 | F33: 197.4 | G33: =+C33+E33 -> 465.2 | H33: =+D33+F33 -> 452.4 | I33: =+(G33/H33-1)*100 -> 2.8293546
A34: 39072 | C34: 235 | D34: 202.5 | E34: 230.2 | F34: 255.1 | G34: =+C34+E34 -> 465.2 | H34: =+D34+F34 -> 457.6 | I34: =+(G34/H34-1)*100 -> 1.6608392
A35: 39079 | C35: 190 | D35: 177.5 | E35: 279.2 | F35: 279.8 | G35: =+C35+E35 -> 469.2 | H35: =+D35+F35 -> 457.3 | I35: =+(G35/H35-1)*100 -> 2.6022305
... A52: 39198 | C52: 46 | D52: 50 | E52: 496.6 | F52: 413.1 | G52: =+C52+E52 -> 542.6 | H52: =+D52+F52 -> 463.1 | I52: =+(G52/H52-1)*100 -> 17.166919
A53: 39205 | C53: 46 | D53: 75 | E53: 523.5 | F53: 413.1 | G53: =+C53+E53 -> 569.5 | H53: =+D53+F53 -> 488.1 | I53: =+(G53/H53-1)*100 -> 16.67691 | J53: 25
A54: 39212 | C54: 46 | D54: 75 | E54: 523.5 | F54: 413.1 | G54: =+C54+E54 -> 569.5 | H54: =+D54+F54 -> 488.1 | I54: =+(G54/H54-1)*100 -> 16.67691 | J54: 25
A55: 39219 | C55: 46 | D55: 75 | E55: 523.5 | F55: 413.1 | G55: =+C55+E55 -> 569.5 | H55: =+D55+F55 -> 488.1 | I55: =+(G55/H55-1)*100 -> 16.67691 | J55: 25
A56: 39226 | C56: 46 | D56: 75 | E56: 523.5 | F56: 413.1 | G56: =+C56+E56 -> 569.5 | H56: =+D56+F56 -> 488.1 | I56: =+(G56/H56-1)*100 -> 16.67691 | J56: 25
...

Sheet EU
A1: EU-25 | B1: Unshipped Balance | D1: Accumulated Exports | F1: Total Commitments
A2: EXPORT SALES, Indonesia | B2: This year | C2: Last year | D2: This year | E2: Last year | F2: This year | G2: Last year | H2: % change
A3: 38855 | F3: =+B3+D3 -> 0 | G3: =+C3+E3 -> 0 | H3: =+(F3/G3-1)*100 -> #DIV/0!
A4: 38862 | B4: 0 | C4: 12.5 | D4: 1904.1 | E4: 4567.3 | F4: =+B4+D4 -> 1904.1 | G4: =+C4+E4 -> 4579.8 | H4: =+(F4/G4-1)*100 -> -58.423949
A5: 38869 | B5: 0 | C5: 12.5 | D5: 1905.5 | E5: 4568.1 | F5: =+B5+D5 -> 1905.5 | G5: =+C5+E5 -> 4580.6 | H5: =+(F5/G5-1)*100 -> -58.400646
A6: 38876 | B6: 0 | C6: 12.5 | D6: 1905.7 | E6: 4569.4 | F6: =+B6+D6 -> 1905.7 | G6: =+C6+E6 -> 4581.9 | H6: =+(F6/G6-1)*100 -> -58.408084
A7: 38883 | F7: =+B7+D7 -> 0 | G7: =+C7+E7 -> 0 | H7: =+(F7/G7-1)*100 -> #DIV/0!
A8: 38890 | F8: =+B8+D8 -> 0 | G8: =+C8+E8 -> 0 | H8: =+(F8/G8-1)*100 -> #DIV/0!
A9: 38897 | F9: =+B9+D9 -> 0 | G9: =+C9+E9 -> 0 | H9: =+(F9/G9-1)*100 -> #DIV/0!
A10: 38904 | F10: =+B10+D10 -> 0 | G10: =+C10+E10 -> 0 | H10: =+(F10/G10-1)*100 -> #DIV/0!
A11: 38911 | F11: =+B11+D11 -> 0 | G11: =+C11+E11 -> 0 | H11: =+(F11/G11-1)*100 -> #DIV/0!
A12: 38918 | B12: 7.9 | C12: 37.5 | D12: 2057 | E12: 4569.5 | F12: =+B12+D12 -> 2064.9 | G12: =+C12+E12 -> 4607 | H12: =+(F12/G12-1)*100 -> -55.179075
A13: 38925
A14: 38932 | B14: 7.9 | C14: 37.5 | D14: 2123 | E14: 4569.5 | F14: =+B14+D14 -> 2130.9 | G14: =+C14+E14 -> 4607 | H14: =+(F14/G14-1)*100 -> -53.746473
A15: 38939
A16: 38946
A17: 38953
A18: =+A17+7 -> 38960
A19: =+A18+7 -> 38967 | B19: 22.3 | C19: 207.6 | D19: 0 | E19: 23.9 | F19: =+B19+D19 -> 22.3 | G19: =+C19+E19 -> 231.5 | H19: =+(F19/G19-1)*100 -> -90.367171
A20: =+A19+7 -> 38974
A21: =+A20+7 -> 38981 | B21: 82.3 | C21: 230.6 | D21: 66 | E21: 23.9 | F21: =+B21+D21 -> 148.3 | G21: =+C21+E21 -> 254.5 | H21: =+(F21/G21-1)*100 -> -41.72888
A22: =+A21+7 -> 38988 | B22: 137.3 | C22: 207.6 | D22: 66 | E22: 45.2 | F22: =+B22+D22 -> 203.3 | G22: =+C22+E22 -> 252.8 | H22: =+(F22/G22-1)*100 -> -19.580696
A23: =+A22+7 -> 38995 | B23: 233.1 | C23: 187.6 | D23: 287.9 | E23: 45.2 | F23: =+B23+D23 -> 521 | G23: =+C23+E23 -> 232.8 | H23: =+(F23/G23-1)*100 -> 123.79725
A24: =+A23+7 -> 39002 | B24: 329.1 | C24: 141.6 | D24: 291.1 | E24: 102.1 | F24: =+B24+D24 -> 620.2 | G24: =+C24+E24 -> 243.7 | H24: =+(F24/G24-1)*100 -> 154.49323
A25: =+A24+7 -> 39009 | B25: 387 | C25: 206.1 | D25: 457.3 | E25: 172.1 | F25: =+B25+D25 -> 844.3 | G25: =+C25+E25 -> 378.2 | H25: =+(F25/G25-1)*100 -> 123.24167
A26: =+A25+7 -> 39016 | B26: 327 | C26: 206.1 | D26: 574.8 | E26: 198.8 | F26: =+B26+D26 -> 901.8 | G26: =+C26+E26 -> 404.9 | H26: =+(F26/G26-1)*100 -> 122.72166
A27: =+A26+7 -> 39023 | B27: 327 | C27: 204.5 | D27: 794.1 | E27: 262.6 | F27: =+B27+D27 -> 1121.1 | G27: =+C27+E27 -> 467.1 | H27: =+(F27/G27-1)*100 -> 140.01285
A28: =+A27+7 -> 39030 | B28: 327 | C28: 177 | D28: 953.3 | E28: 291.5 | F28: =+B28+D28 -> 1280.3 | G28: =+C28+E28 -> 468.5 | H28: =+(F28/G28-1)*100 -> 173.27641
A29: =+A28+7 -> 39037 | B29: 288.5 | C29: 235.1 | D29: 1040.2 | E29: 392.4 | F29: =+B29+D29 -> 1328.7 | G29: =+C29+E29 -> 627.5 | H29: =+(F29/G29-1)*100 -> 111.74502
A30: =+A29+7 -> 39044 | B30: 323.5 | C30: 212.1 | D30: 1181.5 | E30: 504.6 | F30: =+B30+D30 -> 1505 | G30: =+C30+E30 -> 716.7 | H30: =+(F30/G30-1)*100 -> 109.99023
A31: =+A30+7 -> 39051 | B31: 287.5 | C31: 342 | D31: 1226 | E31: 506 | F31: =+B31+D31 -> 1513.5 | G31: =+C31+E31 -> 848 | H31: =+(F31/G31-1)*100 -> 78.478774
A32: =+A31+7 -> 39058 | B32: 227.5 | C32: 282 | D32: 1456.8 | E32: 607.4 | F32: =+B32+D32 -> 1684.3 | G32: =+C32+E32 -> 889.4 | H32: =+(F32/G32-1)*100 -> 89.374859
... A50: =+A49+7 -> 39184 | B50: 0 | C50: 0 | D50: 3548.7 | E50: 1900.8 | F50: =+B50+D50 -> 3548.7 | G50: =+C50+E50 -> 1900.8 | H50: =+(F50/G50-1)*100 -> 86.695076
A51: =+A50+7 -> 39191 | B51: 0 | D51: 3551.1 | E51: 1900.8 | F51: =+B51+D51 -> 3551.1 | G51: =+C51+E51 -> 1900.8 | H51: =+(F51/G51-1)*100 -> 86.821338
A52: =+A51+7 -> 39198 | B52: 0 | D52: 3551.5 | E52: 1903 | F52: =+B52+D52 -> 3551.5 | G52: =+C52+E52 -> 1903 | H52: =+(F52/G52-1)*100 -> 86.626379
A53: =+A52+7 -> 39205 | B53: 0 | C53: 1.2 | D53: 3551.5 | E53: 1903 | F53: =+B53+D53 -> 3551.5 | G53: =+C53+E53 -> 1904.2 | H53: =+(F53/G53-1)*100 -> 86.50877 | I53: 60
A54: =+A53+7 -> 39212 | B54: 0 | D54: 3554.9 | E54: 1904.1 | F54: =+B54+D54 -> 3554.9 | G54: =+C54+E54 -> 1904.1 | H54: =+(F54/G54-1)*100 -> 86.697127 | I54: 60
A55: =+A54+7 -> 39219 | B55: 0 | C55: 0 | D55: 3554.9 | E55: 1904.2 | F55: =+B55+D55 -> 3554.9 | G55: =+C55+E55 -> 1904.2 | H55: =+(F55/G55-1)*100 -> 86.687323 | I55: 60
A56: =+A55+7 -> 39226 | B56: 0 | C56: 0 | D56: 3556.4 | E56: 1904.2 | F56: =+B56+D56 -> 3556.4 | G56: =+C56+E56 -> 1904.2 | H56: =+(F56/G56-1)*100 -> 86.766096 | I56: 60
A57: =+A56+7 -> 39233 | B57: 0 | C57: 0 | D57: 3573.1 | E57: 1905.6 | F57: =+B57+D57 -> 3573.1 | G57: =+C57+E57 -> 1905.6 | H57: =+(F57/G57-1)*100 -> 87.505248 | I57: 60
...

Sheet Egypt
C1: Unshipped Balance | E1: Accumulated Exports | G1: Total Commitments
A2: Export Sales | B2: Egypt | C2: This yr | D2: Last yr | E2: This yr | F2: Last yr | G2: This yr | H2: Last yr
A3: 41158 | C3: 86.5 | D3: 140 | E3: 66 | F3: 0 | G3: =+C3+E3 -> 152.5 | H3: =+D3+F3 -> 140
A4: =A3+7 -> 41165 | C4: 146.5 | D4: 147.5 | E4: 66 | F4: 0 | G4: =+C4+E4 -> 212.5 | H4: =+D4+F4 -> 147.5
A5: =A4+7 -> 41172 | C5: 146.5 | D5: 150.2 | E5: 66 | F5: 24.3 | G5: =+C5+E5 -> 212.5 | H5: =+D5+F5 -> 174.5
A6: =A5+7 -> 41179 | C6: 146.5 | D6: 150.2 | E6: 66 | F6: 24.3 | G6: =+C6+E6 -> 212.5 | H6: =+D6+F6 -> 174.5
A7: =A6+7 -> 41186 | C7: 146.5 | D7: 150.2 | E7: 66 | F7: 24.3 | G7: =+C7+E7 -> 212.5 | H7: =+D7+F7 -> 174.5
A8: =A7+7 -> 41193 | C8: 87 | D8: 63.2 | E8: 130.7 | F8: 112 | G8: =+C8+E8 -> 217.7 | H8: =+D8+F8 -> 175.2
A9: =A8+7 -> 41200 | C9: 87 | D9: 60 | E9: 130.7 | F9: 112 | G9: =+C9+E9 -> 217.7 | H9: =+D9+F9 -> 172
A10: =A9+7 -> 41207 | C10: 87 | D10: 60 | E10: 130.7 | F10: 161.5 | G10: =+C10+E10 -> 217.7 | H10: =+D10+F10 -> 221.5
A11: =A10+7 -> 41214 | C11: 163.5 | D11: 96 | E11: 140.9 | F11: 161.5 | G11: =+C11+E11 -> 304.4 | H11: =+D11+F11 -> 257.5
A12: =A11+7 -> 41221 | C12: 137 | D12: 87.3 | E12: 199.7 | F12: 170.2 | G12: =+C12+E12 -> 336.7 | H12: =+D12+F12 -> 257.5
A13: =A12+7 -> 41228 | C13: 137 | D13: 147.3 | E13: 199.7 | F13: 170.2 | G13: =+C13+E13 -> 336.7 | H13: =+D13+F13 -> 317.5
A14: =A13+7 -> 41235 | C14: 77 | D14: 207.3 | E14: 263.9 | F14: 170.2 | G14: =+C14+E14 -> 340.9 | H14: =+D14+F14 -> 377.5
A15: =A14+7 -> 41242 | C15: 77 | D15: 147.3 | E15: 263.9 | F15: 215.5 | G15: =+C15+E15 -> 340.9 | H15: =+D15+F15 -> 362.8
... A38: =A37+7 -> 41403 | C38: 0 | D38: 102 | E38: 677.3 | F38: 848.3 | G38: =+C38+E38 -> 677.3 | H38: =+D38+F38 -> 950.3
A39: =A38+7 -> 41410 | C39: 0 | D39: 138 | E39: 677.3 | F39: 881.7 | G39: =+C39+E39 -> 677.3 | H39: =+D39+F39 -> 1019.7 | I39: 60
A40: =A39+7 -> 41417 | C40: 0 | D40: 138 | E40: 677.3 | F40: 881.7 | G40: =+C40+E40 -> 677.3 | H40: =+D40+F40 -> 1019.7 | I40: 60
A41: =A40+7 -> 41424 | C41: 0 | D41: 102 | E41: 677.3 | F41: 929.4 | G41: =+C41+E41 -> 677.3 | H41: =+D41+F41 -> 1031.4 | I41: 60
A42: =A41+7 -> 41431 | C42: 0 | D42: 222 | E42: 677.3 | F42: 929.4 | G42: =+C42+E42 -> 677.3 | H42: =+D42+F42 -> 1151.4 | I42: 60
A43: =A42+7 -> 41438 | C43: 0 | D43: 222 | E43: 677.3 | F43: 929.4 | G43: =+C43+E43 -> 677.3 | H43: =+D43+F43 -> 1151.4 | I43: 60
A44: =A43+7 -> 41445 | C44: 0 | D44: 222 | E44: 677.3 | F44: 929.4 | G44: =+C44+E44 -> 677.3 | H44: =+D44+F44 -> 1151.4 | I44: 60
A45: =A44+7 -> 41452 | C45: 0 | D45: 201 | E45: 677.3 | F45: 1005.9 | G45: =+C45+E45 -> 677.3 | H45: =+D45+F45 -> 1206.9 | I45: 60
A46: =A45+7 -> 41459 | C46: 0 | D46: 201 | E46: 677.3 | F46: 1005.9 | G46: =+C46+E46 -> 677.3 | H46: =+D46+F46 -> 1206.9 | I46: 60
A47: =A46+7 -> 41466 | C47: 0 | D47: 184 | E47: 677.3 | F47: 1025.6 | G47: =+C47+E47 -> 677.3 | H47: =+D47+F47 -> 1209.6 | I47: 60
A48: =A47+7 -> 41473 | C48: 0 | D48: 244 | E48: 677.3 | F48: 1025.6 | G48: =+C48+E48 -> 677.3 | H48: =+D48+F48 -> 1269.6 | I48: 60
A49: =A48+7 -> 41480 | C49: 0 | D49: 84 | E49: 677.3 | F49: 1200 | G49: =+C49+E49 -> 677.3 | H49: =+D49+F49 -> 1284 | I49: 60
A50: =A49+7 -> 41487 | C50: 0 | D50: 84 | E50: 677.3 | F50: 1200 | G50: =+C50+E50 -> 677.3 | H50: =+D50+F50 -> 1284 | I50: 120
... A54: =A53+7 -> 41515 | C54: 0 | D54: 68 | E54: 677.3 | F54: 1224.1 | G54: =+C54+E54 -> 677.3 | H54: =+D54+F54 -> 1292.1 | I54: 120
A55: =A54+7 -> 41522 | C55: 120 | D55: 86.5 | E55: 0 | F55: 66 | G55: =+C55+E55 -> 120 | H55: =+D55+F55 -> 152.5
A56: =A55+7 -> 41529 | C56: 120 | D56: 146.5 | E56: 0 | F56: 66 | G56: =+C56+E56 -> 120 | H56: =+D56+F56 -> 212.5
A57: =A56+7 -> 41536 | C57: 180 | D57: 146.5 | E57: 0 | F57: 66 | G57: =+C57+E57 -> 180 | H57: =+D57+F57 -> 212.5
A58: =A57+7 -> 41543 | C58: 180 | D58: 146.5 | E58: 0 | F58: 66 | G58: =+C58+E58 -> 180 | H58: =+D58+F58 -> 212.5
A59: =A58+7 -> 41550 | C59: 180 | D59: 146.5 | E59: 0 | F59: 66 | G59: =+C59+E59 -> 180 | H59: =+D59+F59 -> 212.5
A60: =A59+7 -> 41557
A61: =A60+7 -> 41564
A62: =A61+7 -> 41571 | C62: 246 | D62: 87 | E62: 0 | F62: 130.7 | G62: =+C62+E62 -> 246 | H62: =+D62+F62 -> 217.7
A63: =A62+7 -> 41578 | C63: 206 | D63: 163.5 | E63: 53.4 | F63: 140.9 | G63: =+C63+E63 -> 259.4 | H63: =+D63+F63 -> 304.4
A64: =A63+7 -> 41585 | C64: 206 | D64: 137 | E64: 53.4 | F64: 199.7 | G64: =+C64+E64 -> 259.4 | H64: =+D64+F64 -> 336.7
A65: =A64+7 -> 41592 | C65: 146 | D65: 137 | E65: 116.5 | F65: 199.7 | G65: =+C65+E65 -> 262.5 | H65: =+D65+F65 -> 336.7
...

Sheet Data
A5: SOYBEANS : 09/05 21896.3 60.1 60.1 2.2 21956.4
A6: : 09/12 22745.4 74.2 134.3 4.9 22879.7 37290
A7: :YR AGO 20825.0 207.3 546.7 20.1 21371.7
A11: SOYBEANS | F11: MARKETI | G11: NG YEAR 09 | H11: /01 - 08/31
A12: OUTSTANDING EXPORT | B12: S | C12: ALES AND | D12: EXPORTS | E12: BY COUNTRY, | F12: REGION | G12: AND MARKET | H12: ING YEAR
A13: 1000 METRIC TONS | C13: AS OF SE | D13: PTEMBER 1 | E13: 2, 2013
A14: ---------------------- | B14: - | C14: -------- | D14: --------- | E14: ----------- | F14: -------- | G14: ---------- | H14: ----------- | K14: :
B15: : | C15: CU | D15: RRENT MAR | E15: KETING YEAR | G15: :NEXT MAR | H15: KETING YEAR
C16: -------- | D16: --------- | E16: ----------- | F16: -------- | G16: ---------- | H16: -----------
B17: : | C17: OUTSTAND | D17: ING SALES | E17: :ACCUMULATE | F17: D EXPORT | G17: S: OUTSTAN | H17: DING SALES
C18: -------- | D18: --------- | E18: ----------- | F18: -------- | G18: ---------- | H18: -----------
A19: DESTINATION | B19: : | C19: THIS WEE | D19: K: YR AGO | E19: :THIS WEEK: | F19: YR AGO | G19: :SECOND Y | H19: R: THIRD YR
A20: ---------------------- | B20: - | C20: -------- | D20: --------- | E20: ----------- | F20: -------- | G20: ---------- | H20: -----------
B21: :
A22: EUROPEAN UNION - 27 | B22: : | C22: 124.9 | D22: 232.8 | E22: 0.1 | F22: 0.1 | G22: 0 | H22: 0
A23: FRANCE | B23: : | C23: 0 | D23: 60 | E23: 0 | F23: 0 | G23: 0 | H23: 0
A24: IRELAND | B24: : | C24: 0 | D24: 0.8 | E24: 0 | F24: 0 | G24: 0 | H24: 0
A25: ITALY | B25: : | C25: 55 | D25: 0 | E25: 0.1 | F25: 0.1 | G25: 0 | H25: 0
A26: NETHLDS | B26: : | C26: 9.9 | D26: 60 | E26: 0 | F26: 0 | G26: 0 | H26: 0
A27: U KING | B27: : | C27: 60 | D27: 112 | E27: 0 | F27: 0 | G27: 0 | H27: 0
B28: :
A29: OTHER EUROPE | B29: : | C29: 66 | D29: 89 | E29: 0 | F29: 0 | G29: 0 | H29: 0
