Workbook

Sheet TWK
A1: Spot Barge Rates (twk), 2004 - Present
A3: DATE | B3: TWC | C3: MM | D3: ILL | E3: ST LOUIS | F3: CINC | G3: LOH | H3: CAR-MEM | I3: MEM-SO
A4: 37993 | B4: 0 | C4: 0 | D4: 200 | E4: 162 | F4: 163.75 | G4: 165 | H4: 152.5 | I4: 195
A5: 38000 | B5: 0 | C5: 0 | D5: 200 | E5: 162 | F5: 169.5 | G5: 169.5 | H5: 149 | I5: 198.3
A6: 38007 | B6: 0 | C6: 0 | D6: 194 | E6: 157 | F6: 172 | G6: 171 | H6: 144 | I6: 182
A7: 38014 | B7: 0 | C7: 0 | D7: 208 | E7: 150 | F7: 161 | G7: 159 | H7: 137 | I7: 165
A8: 38021 | B8: 0 | C8: 0 | D8: 214 | E8: 147 | F8: 152 | G8: 151 | H8: 127 | I8: 185
A9: 38028 | B9: 0 | C9: 0 | D9: 183 | E9: 135 | F9: 134 | G9: 134 | H9: 118 | I9: 165
A10: 38035 | B10: 0 | C10: 0 | D10: 181 | E10: 133 | F10: 131 | G10: 130 | H10: 117 | I10: 173
A11: 38042 | B11: 0 | C11: 0 | D11: 161 | E11: 130 | F11: 126 | G11: 125 | H11: 120 | I11: 165
A12: 38049 | B12: 0 | C12: 0 | D12: 160 | E12: 130 | F12: 124 | G12: 126 | H12: 116 | I12: 162
A13: 38056 | B13: 0 | C13: 0 | D13: 149 | E13: 127 | F13: 122 | G13: 122 | H13: 114 | I13: 160
A14: 38063 | B14: 0 | C14: 165 | D14: 151 | E14: 124 | F14: 122 | G14: 121 | H14: 112 | I14: 158
A15: 38070 | B15: 184 | C15: 152 | D15: 143 | E15: 115 | F15: 119 | G15: 119 | H15: 110 | I15: 152
... A50: 38315 | B50: 255 | C50: 244 | D50: 236 | E50: 180 | F50: 208 | G50: 208 | H50: 171 | I50: 235
A51: 38322 | C51: 249 | D51: 240 | E51: 175 | F51: 192 | G51: 192 | H51: 166 | I51: 218
A52: 38329 | C52: 245 | D52: 245 | E52: 198 | F52: 199 | G52: 202 | H52: 180 | I52: 230
A53: 38336 | C53: 318 | D53: 301 | E53: 277 | F53: 270 | G53: 279 | H53: 267 | I53: 375
A54: 38343 | D54: 346 | E54: 345 | F54: 333 | G54: 344 | H54: 303 | I54: 388
A55: 38350 | D55: 300 | E55: 257 | F55: 273 | G55: 278 | H55: 237 | I55: 308
A56: 38357 | D56: 261 | E56: 200 | F56: 222 | G56: 222 | H56: 190 | I56: 253
A57: 38364 | D57: 324 | E57: 285 | F57: 244 | G57: 248 | H57: 264 | I57: 368
A58: 38371 | D58: 361 | E58: 329 | F58: 290 | G58: 294 | H58: 313 | I58: 405
A59: 38378 | D59: 293 | E59: 281 | F59: 329 | G59: 326 | H59: 285 | I59: 363
A60: 38385 | D60: 263 | E60: 218 | F60: 301 | G60: 299 | H60: 207 | I60: 285
A61: 38392 | D61: 233 | E61: 215 | F61: 218 | G61: 219 | H61: 202 | I61: 265
A62: 38399 | D62: 278 | E62: 303 | F62: 243 | G62: 247 | H62: 278 | I62: 367
A63: 38406 | D63: 320 | E63: 313 | F63: 289 | G63: 289 | H63: 291 | I63: 388
A64: 38413 | C64: 380 | D64: 369 | E64: 323 | F64: 322 | G64: 323 | H64: 298 | I64: 388
A65: 38420 | C65: 304 | D65: 278 | E65: 247 | F65: 268 | G65: 272 | H65: 237 | I65: 308
A66: 38427 | C66: 350 | D66: 344 | E66: 308 | F66: 341 | G66: 343 | H66: 287 | I66: 363
A67: 38434 | C67: 271 | D67: 250 | E67: 203 | F67: 232 | G67: 233 | H67: 198 | I67: 263
A68: 38441 | B68: 270 | C68: 243 | D68: 231 | E68: 171 | F68: 206 | G68: 208 | H68: 167 | I68: 230
A69: 38448 | B69: 307 | C69: 316 | D69: 313 | E69: 221 | F69: 233 | G69: 235 | H69: 210 | I69: 293
A70: 38455 | B70: 278 | C70: 249 | D70: 241 | E70: 188 | F70: 195 | G70: 195 | H70: 177 | I70: 238
A71: 38462 | B71: 276 | C71: 248 | D71: 238 | E71: 179 | F71: 188 | G71: 189 | H71: 170 | I71: 243
A72: 38469 | B72: 261 | C72: 233 | D72: 223 | E72: 168 | F72: 178 | G72: 178 | H72: 161 | I72: 225
A73: 38476 | B73: 263 | C73: 237 | D73: 245 | E73: 214 | F73: 187 | G73: 189 | H73: 171 | I73: 233
A74: 38483 | B74: 252 | C74: 231 | D74: 229 | E74: 195 | F74: 182 | G74: 186 | H74: 167 | I74: 225
A75: 38490 | B75: 258 | C75: 252 | D75: 249 | E75: 185 | F75: 178 | G75: 179 | H75: 165 | I75: 225
...

Sheet NXTMONTH
A1: Barge Rates, 2004 - Present
A2: (1 MONTH OUT)
A3: DATE | B3: MONTH | C3: TWC | D3: MM | E3: ILL | F3: ST LOUIS | G3: CINC | H3: LOH | I3: CAR-MEM | J3: MEM-SO
A4: 37993 | B4: 2 | C4: 0 | D4: 0 | E4: 202.5 | F4: 158.161 | G4: 161 | H4: 161 | I4: 145 | J4: 191.67
A5: 38000 | B5: 2 | C5: 0 | D5: 0 | E5: 199.2 | F5: 155.9 | G5: 159 | H5: 159 | I5: 144 | J5: 191.67
A6: 38007 | B6: 2 | C6: 0 | D6: 0 | E6: 194 | F6: 151 | G6: 159 | H6: 158 | I6: 140 | J6: 180
A7: 38014 | B7: 2 | C7: 0 | D7: 0 | E7: 201 | F7: 147 | G7: 155 | H7: 153 | I7: 141 | J7: 164
A8: 38021 | B8: 3 | C8: 0 | D8: 189 | E8: 179 | F8: 148 | G8: 153 | H8: 152 | I8: 131 | J8: 180
A9: 38028 | B9: 3 | C9: 0 | D9: 187 | E9: 167 | F9: 144 | G9: 141 | H9: 141 | I9: 123 | J9: 167
A10: 38035 | B10: 3 | C10: 0 | D10: 184 | E10: 173 | F10: 137 | G10: 137 | H10: 136 | I10: 123 | J10: 177
A11: 38042 | B11: 3 | C11: 0 | D11: 181 | E11: 164 | F11: 134 | G11: 129 | H11: 128 | I11: 118 | J11: 168
A12: 38049 | B12: 4 | C12: 195 | D12: 171 | E12: 159 | F12: 133 | G12: 130 | H12: 129 | I12: 120 | J12: 167
A13: 38056 | B13: 4 | C13: 193 | D13: 166 | E13: 153 | F13: 129 | G13: 128 | H13: 127 | I13: 118 | J13: 165
A14: 38063 | B14: 4 | C14: 189 | D14: 163 | E14: 150 | F14: 123 | G14: 126 | H14: 125 | I14: 117 | J14: 163
A15: 38070 | B15: 4 | C15: 180 | D15: 153 | E15: 146 | F15: 122 | G15: 123 | H15: 123 | I15: 114 | J15: 155
... A46: 38287 | B46: 11 | C46: 359 | D46: 325 | E46: 323 | F46: 274 | G46: 297 | H46: 313 | I46: 248 | J46: 298
A47: 38294 | B47: 12 | E47: 261 | F47: 196 | G47: 222 | H47: 222 | I47: 189 | J47: 255
A48: 38301 | B48: 12 | E48: 263 | F48: 200 | G48: 225 | H48: 225 | I48: 188 | J48: 275
A49: 38308 | B49: 12 | E49: 249 | F49: 201 | G49: 220 | H49: 220 | I49: 187 | J49: 240
A50: 38315 | B50: 12 | E50: 240 | F50: 184 | G50: 202 | H50: 202 | I50: 169 | J50: 225
A51: 38322 | B51: 1 | E51: 246 | F51: 180 | G51: 191 | H51: 191 | I51: 173 | J51: 218
A52: 38329 | B52: 1 | E52: 254 | F52: 185 | G52: 192 | H52: 192 | I52: 172 | J52: 228
A53: 38336 | B53: 1 | E53: 278 | F53: 220 | G53: 229 | H53: 228 | I53: 205 | J53: 282
A54: 38343 | B54: 1 | E54: 313 | F54: 236 | G54: 247 | H54: 249 | I54: 228 | J54: 310
A55: 38350 | B55: 1 | E55: 288 | F55: 234 | G55: 246 | H55: 246 | I55: 214 | J55: 290
A56: 38357 | B56: 2 | E56: 253 | F56: 195 | G56: 216 | H56: 216 | I56: 185 | J56: 237
A57: 38364 | B57: 2 | E57: 274 | F57: 216 | G57: 223 | H57: 223 | I57: 199 | J57: 258
A58: 38371 | B58: 2 | E58: 281 | F58: 232 | G58: 241 | H58: 241 | I58: 221 | J58: 275
A59: 38378 | B59: 2 | E59: 276 | F59: 238 | G59: 260 | H59: 260 | I59: 238 | J59: 310
A60: 38385 | B60: 3 | D60: 253 | E60: 238 | F60: 198 | G60: 205 | H60: 205 | I60: 184 | J60: 245
A61: 38392 | B61: 3 | D61: 241 | E61: 225 | F61: 186 | G61: 197 | H61: 197 | I61: 173 | J61: 240
A62: 38399 | B62: 3 | D62: 256 | E62: 242 | F62: 218 | G62: 208 | H62: 211 | I62: 217 | J62: 270
A63: 38406 | B63: 3 | D63: 283 | E63: 276 | F63: 244 | G63: 243 | H63: 243 | I63: 231 | J63: 325
A64: 38413 | B64: 4 | C64: 303 | D64: 284 | E64: 270 | F64: 239 | G64: 253 | H64: 253 | I64: 231 | J64: 305
A65: 38420 | B65: 4 | C65: 294 | D65: 265 | E65: 255 | F65: 226 | G65: 240 | H65: 242 | I65: 216 | J65: 295
A66: 38427 | B66: 4 | C66: 317 | D66: 289 | E66: 278 | F66: 251 | G66: 270 | H66: 270 | I66: 237 | J66: 313
A67: 38434 | B67: 4 | C67: 291 | D67: 254 | E67: 242 | F67: 204 | G67: 227 | H67: 227 | I67: 199 | J67: 268
A68: 38441 | B68: 4 | C68: 269 | D68: 238 | E68: 228 | F68: 175 | G68: 206 | H68: 207 | I68: 169 | J68: 235
A69: 38448 | B69: 5 | C69: 282 | D69: 264 | E69: 252 | F69: 196 | G69: 210 | H69: 210 | I69: 187 | J69: 268
A70: 38455 | B70: 5 | C70: 275 | D70: 251 | E70: 243 | F70: 192 | G70: 198 | H70: 198 | I70: 178 | J70: 255
...

Sheet THREEMONTH
A1: Barge Rate Quotes, 2004 - Present
A2: (3 MONTHS OUT)
A3: DATE | B3: MONTH | C3: TWC | D3: MM | E3: ILL | F3: ST LOUIS | G3: CINC | H3: LOH | I3: CAR-MEM | J3: MEM-SO
A4: 37993 | B4: 4 | C4: 203.75 | D4: 174.16 | E4: 170 | F4: 144 | G4: 146.5 | H4: 146.5 | I4: 130.5 | J4: 183.3
A5: 38000 | B5: 4 | C5: 198.75 | D5: 185 | E5: 171.25 | F5: 144 | G5: 144.5 | H5: 144.5 | I5: 130.5 | J5: 183.3
A6: 38007 | B6: 4 | C6: 201 | D6: 179 | E6: 168 | F6: 137 | G6: 141 | H6: 140 | I6: 126 | J6: 172
A7: 38014 | B7: 4 | C7: 203 | D7: 177 | E7: 167 | F7: 138 | G7: 140 | H7: 141 | I7: 130 | J7: 158
A8: 38021 | B8: 5 | C8: 193 | D8: 172 | E8: 160 | F8: 136 | G8: 135 | H8: 135 | I8: 124 | J8: 180
A9: 38028 | B9: 5 | C9: 192 | D9: 167 | E9: 153 | F9: 139 | G9: 136 | H9: 136 | I9: 123 | J9: 167
A10: 38035 | B10: 5 | C10: 191 | D10: 168 | E10: 158 | F10: 131 | G10: 128 | H10: 127 | I10: 118 | J10: 175
A11: 38042 | B11: 5 | C11: 189 | D11: 166 | E11: 155 | F11: 131 | G11: 126 | H11: 125 | I11: 121 | J11: 167
A12: 38049 | B12: 6 | C12: 190 | D12: 168 | E12: 158 | F12: 135 | G12: 131 | H12: 130 | I12: 124 | J12: 167
A13: 38056 | B13: 6 | C13: 190 | D13: 166 | E13: 155 | F13: 133 | G13: 134 | H13: 133 | I13: 125 | J13: 170
A14: 38063 | B14: 6 | C14: 189 | D14: 163 | E14: 155 | F14: 129 | G14: 134 | H14: 133 | I14: 122 | J14: 163
A15: 38070 | B15: 6 | C15: 183 | D15: 159 | E15: 152 | F15: 130 | G15: 132 | H15: 132 | I15: 122 | J15: 165
... A37: 38224 | B37: 11 | C37: 283 | D37: 242 | E37: 230 | F37: 186 | G37: 199 | H37: 199 | I37: 175 | J37: 238
A38: 38231 | B38: 12 | E38: 199 | F38: 158 | G38: 167 | H38: 167 | I38: 150 | J38: 193
A39: 38238 | B39: 12 | E39: 204 | F39: 161 | G39: 170 | H39: 170 | I39: 153 | J39: 202
A40: 38245 | B40: 12 | E40: 208 | F40: 165 | G40: 171 | H40: 171 | I40: 156 | J40: 200
A41: 38252 | B41: 12 | E41: 208 | F41: 166 | G41: 174 | H41: 172 | I41: 155 | J41: 190
A42: 38259 | B42: 12 | E42: 224 | F42: 176 | G42: 185 | H42: 185 | I42: 169 | J42: 217
A43: 38266 | B43: 1 | E43: 252 | F43: 181 | G43: 195 | H43: 196 | I43: 170 | J43: 212
A44: 38273 | B44: 1 | E44: 243 | F44: 175 | G44: 191 | H44: 192 | I44: 169 | J44: 210
A45: 38280 | B45: 1 | E45: 247 | F45: 182 | G45: 200 | H45: 200 | I45: 176 | J45: 213
A46: 38287 | B46: 1 | E46: 265 | F46: 198 | G46: 216 | H46: 216 | I46: 185 | J46: 223
A47: 38294 | B47: 2 | E47: 245 | F47: 189 | G47: 202 | H47: 202 | I47: 180 | J47: 227
A48: 38301 | B48: 2 | E48: 251 | F48: 194 | G48: 213 | H48: 213 | I48: 180 | J48: 240
A49: 38308 | B49: 2 | E49: 242 | F49: 191 | G49: 207 | H49: 207 | I49: 180 | J49: 218
A50: 38315 | B50: 2 | E50: 242 | F50: 191 | G50: 198 | H50: 198 | I50: 173 | J50: 225
A51: 38322 | B51: 3 | D51: 225 | E51: 220 | F51: 179 | G51: 190 | H51: 190 | I51: 169 | J51: 208
A52: 38329 | B52: 3 | D52: 225 | E52: 220 | F52: 180 | G52: 189 | H52: 189 | I52: 168 | J52: 208
A53: 38336 | B53: 3 | D53: 225 | E53: 219 | F53: 186 | G53: 195 | H53: 195 | I53: 171 | J53: 213
A54: 38343 | B54: 3 | D54: 242 | E54: 228 | F54: 195 | G54: 206 | H54: 212 | I54: 181 | J54: 232
A55: 38350 | B55: 3 | D55: 236 | E55: 228 | F55: 195 | G55: 206 | H55: 210 | I55: 181 | J55: 220
A56: 38357 | B56: 4 | C56: 246 | D56: 226 | E56: 214 | F56: 178 | G56: 188 | H56: 188 | I56: 168 | J56: 218
A57: 38364 | B57: 4 | C57: 252 | D57: 228 | E57: 216 | F57: 182 | G57: 193 | H57: 193 | I57: 170 | J57: 223
A58: 38371 | B58: 4 | C58: 254 | D58: 229 | E58: 217 | F58: 180 | G58: 202 | H58: 198 | I58: 171 | J58: 228
A59: 38378 | B59: 4 | C59: 260 | D59: 238 | E59: 228 | F59: 193 | G59: 200 | H59: 200 | I59: 189 | J59: 240
A60: 38385 | B60: 5 | C60: 240 | D60: 232 | E60: 218 | F60: 181 | G60: 188 | H60: 188 | I60: 169 | J60: 225
A61: 38392 | B61: 5 | C61: 237 | D61: 222 | E61: 212 | F61: 174 | G61: 185 | H61: 185 | I61: 162 | J61: 220
...

Sheet New Figure 8
A1: Weekly Barge Rates for Illinois River
A2: Figure 8
A3: Illinois River Barge Freight Rate1,2
A16: 1Rate = percent of 1976 tariff benchmark index (1976 = 100 percent); 24-week moving average of the 3-year average.
A17: Source: Transportation & Marketing Programs/AMS/USDA
A23: Week ending April 15: up 4 percent from last week, up 40 percent from last year, and up 8 percent from the 3-yr average.

Sheet Figure 8_data
A1: Barge Spot Rate Quotes - Weekly Average from Survey Quotes and 3-yr Average
A3: Ill Rivr | B3: Weekly rate | G3: for the text box:
A4: Date | C4: 4-wk running avg | G4: IN %: change
A5: 36131 | B5: 142 | D5: 3-year avg. for the week | G5: last week | H5: last year | I5: 3-yr avg
A6: 36138 | B6: 126 | D6: --- | G6: Data begins in 2006
A7: 36145 | B7: 126 | D7: ---
A8: 36152 | B8: 144 | C8: =AVERAGE(B5:B8) -> 134.5 | D8: --- | E8: 51
A9: 36159 | B9: 161 | C9: =AVERAGE(B6:B9) -> 139.25 | D9: --- | E9: 52
A10: 36166 | B10: 221 | C10: =AVERAGE(B7:B10) -> 163 | D10: --- | E10: 1
A11: 36173 | B11: 187 | C11: =AVERAGE(B8:B11) -> 178.25 | D11: --- | E11: 2
A12: 36180 | B12: 164 | C12: =AVERAGE(B9:B12) -> 183.25 | D12: --- | E12: 3
A13: 36187 | B13: 158 | C13: =AVERAGE(B10:B13) -> 182.5 | D13: --- | E13: 4
A14: 36194 | B14: 157 | C14: =AVERAGE(B11:B14) -> 166.5 | D14: --- | E14: 5
A15: 36201 | B15: 154 | C15: =AVERAGE(B12:B15) -> 158.25 | D15: --- | E15: 6
A16: 36208 | B16: 141 | C16: =AVERAGE(B13:B16) -> 152.5 | D16: --- | E16: 7
A17: 36215 | B17: 127 | C17: =AVERAGE(B14:B17) -> 144.75 | D17: --- | E17: 8
A18: 36222 | B18: 140 | C18: =AVERAGE(B15:B18) -> 140.5 | D18: --- | E18: 9
A19: 36229 | B19: 134 | C19: =AVERAGE(B16:B19) -> 135.5 | D19: --- | E19: 10
... A152: 37160 | B152: 209 | C152: =AVERAGE(B149:B152) -> 195.25 | D152: --- | E152: 39
A153: 37167 | B153: 218 | C153: =AVERAGE(B150:B153) -> 197.5 | E153: 40
A154: 37174 | B154: 204 | C154: =AVERAGE(B151:B154) -> 202.25 | E154: 41
A155: 37181 | B155: 198 | C155: =AVERAGE(B152:B155) -> 207.25 | E155: 42
A156: 37188 | B156: 248 | C156: =AVERAGE(B153:B156) -> 217 | E156: 43
A157: 37195 | B157: 260 | C157: =AVERAGE(B154:B157) -> 227.5 | E157: 44
A158: 37202 | B158: 179 | C158: =AVERAGE(B155:B158) -> 221.25 | E158: 45
A159: 37209 | B159: 136 | C159: =AVERAGE(B156:B159) -> 205.75 | E159: 46
A160: 37216 | B160: 153 | C160: =AVERAGE(B157:B160) -> 182 | E160: 47
A161: 37223 | B161: 150 | C161: =AVERAGE(B158:B161) -> 154.5 | E161: 48
A162: 37230 | B162: 165 | C162: =AVERAGE(B159:B162) -> 151 | E162: 49
A163: 37237 | B163: 180 | C163: =AVERAGE(B160:B163) -> 162 | E163: 50
A164: 37244 | B164: 167 | C164: =AVERAGE(B161:B164) -> 165.5 | D164: =(C8+C60+C112)/3 -> 163.83333 | E164: 51
A165: 37251 | B165: 195 | C165: =AVERAGE(B162:B165) -> 176.75 | D165: =(C9+C61+C113)/3 -> 178.16667 | E165: 52
A166: 37258 | B166: 194 | C166: =AVERAGE(B163:B166) -> 184 | D166: =(C10+C62+C114)/3 -> 193.16667 | E166: 1
A167: 37265 | B167: 171 | C167: =AVERAGE(B164:B167) -> 181.75 | D167: =(C11+C63+C115)/3 -> 202.58333 | E167: 2
A168: 37272 | B168: 173 | C168: =AVERAGE(B165:B168) -> 183.25 | D168: =(C12+C64+C116)/3 -> 203 | E168: 3
A169: 37279 | B169: 158 | C169: =AVERAGE(B166:B169) -> 174 | D169: =(C13+C65+C117)/3 -> 209.41667 | E169: 4
A170: 37286 | B170: 153 | C170: =AVERAGE(B167:B170) -> 163.75 | D170: =(C14+C66+C118)/3 -> 204.33333 | E170: 5
A171: 37293 | B171: 146 | C171: =AVERAGE(B168:B171) -> 157.5 | D171: =(C15+C67+C119)/3 -> 197.66667 | E171: 6
A172: 37300 | B172: 145 | C172: =AVERAGE(B169:B172) -> 150.5 | D172: =(C16+C68+C120)/3 -> 191.08333 | E172: 7
A173: 37307 | B173: 146 | C173: =AVERAGE(B170:B173) -> 147.5 | D173: =(C17+C69+C121)/3 -> 173.66667 | E173: 8
...

Sheet Table 9_data
A1: Barge Spot Rate Quotes - Weekly Average from Survey Quotes, 4-wk running average, 3-yr average of the 4-wk running average, % change from 3-year average of the 4-wk running average, and % change of the same week last year | AC1: Data checking field - value should always = 0 | AM1: This field is used by the USDA to check data (should always be 0)
B2: Barge Spot Rate Quotes - Weekly Average from Survey Quotes | K2: Barge Spot Rate Quotes - 4-wk running average | T2: Barge Spot Rate Quotes - 4-wk running average, 3-year average | AD2: % CHANGE This Week from 3-year average of the 4-week running average | AN2: % CHANGE This Week from last year same week
A3: All Points | B3: TWC | C3: MM | D3: ILL | E3: ST LOUIS | F3: CINC | G3: LOH | H3: CAR-MEM | I3: MEM-SO | K3: TWC | L3: MM | M3: ILL | N3: ST LOUIS | O3: CINC | P3: LOH | Q3: CAR-MEM | R3: MEM-SO | T3: TWC | U3: MM | V3: ILL | W3: ST LOUIS | X3: CINC | Y3: LOH | Z3: CAR-MEM | AA3: MEM-SO | AD3: TWC | AE3: MM | AF3: ILL | AG3: ST LOUIS | AH3: CINC | AI3: LOH | AJ3: CAR-MEM | AK3: MEM-SO | AN3: TWC | AO3: MM | AP3: ILL | AQ3: ST LOUIS | AR3: CINC | AS3: LOH | AT3: CAR-MEM | AU3: MEM-SO
A4: Date
A6: 37622 | B6: 0 | C6: 0 | D6: 160 | E6: 136 | F6: 131 | G6: 128 | H6: 118 | I6: 167 | T6: data begins in 2007
A7: 37629 | B7: 0 | C7: 0 | D7: 160 | E7: 136 | F7: 134 | G7: 133 | H7: 120 | I7: 168
A8: 37636 | B8: 0 | C8: 0 | D8: 237 | E8: 216 | F8: 168 | G8: 163 | H8: 130 | I8: 172
A9: 37643 | B9: 0 | C9: 0 | D9: 239 | E9: 214 | F9: 174 | G9: 173 | H9: 133 | I9: 167 | K9: =AVERAGE(B6:B9) -> 0 | L9: =AVERAGE(C6:C9) -> 0 | M9: =AVERAGE(D6:D9) -> 199 | N9: =AVERAGE(E6:E9) -> 175.5 | O9: =AVERAGE(F6:F9) -> 151.75 | P9: =AVERAGE(G6:G9) -> 149.25 | Q9: =AVERAGE(H6:H9) -> 125.25 | R9: =AVERAGE(I6:I9) -> 168.5
A10: 37650 | B10: 0 | C10: 0 | D10: 223 | E10: 172 | F10: 156 | G10: 153 | H10: 118 | I10: 157 | K10: =AVERAGE(B7:B10) -> 0 | L10: =AVERAGE(C7:C10) -> 0 | M10: =AVERAGE(D7:D10) -> 214.75 | N10: =AVERAGE(E7:E10) -> 184.5 | O10: =AVERAGE(F7:F10) -> 158 | P10: =AVERAGE(G7:G10) -> 155.5 | Q10: =AVERAGE(H7:H10) -> 125.25 | R10: =AVERAGE(I7:I10) -> 166
A11: 37657 | B11: 0 | C11: 0 | D11: 205 | E11: 146 | F11: 144 | G11: 141 | H11: 113 | I11: 155 | K11: =AVERAGE(B8:B11) -> 0 | L11: =AVERAGE(C8:C11) -> 0 | M11: =AVERAGE(D8:D11) -> 226 | N11: =AVERAGE(E8:E11) -> 187 | O11: =AVERAGE(F8:F11) -> 160.5 | P11: =AVERAGE(G8:G11) -> 157.5 | Q11: =AVERAGE(H8:H11) -> 123.5 | R11: =AVERAGE(I8:I11) -> 162.75
A12: 37664 | B12: 0 | C12: 0 | D12: 178 | E12: 139 | F12: 135 | G12: 134 | H12: 111 | I12: 157 | K12: =AVERAGE(B9:B12) -> 0 | L12: =AVERAGE(C9:C12) -> 0 | M12: =AVERAGE(D9:D12) -> 211.25 | N12: =AVERAGE(E9:E12) -> 167.75 | O12: =AVERAGE(F9:F12) -> 152.25 | P12: =AVERAGE(G9:G12) -> 150.25 | Q12: =AVERAGE(H9:H12) -> 118.75 | R12: =AVERAGE(I9:I12) -> 159
A13: 37671 | B13: 0 | C13: 0 | D13: 165 | E13: 133 | F13: 127 | G13: 130 | H13: 110 | I13: 165 | K13: =AVERAGE(B10:B13) -> 0 | L13: =AVERAGE(C10:C13) -> 0 | M13: =AVERAGE(D10:D13) -> 192.75 | N13: =AVERAGE(E10:E13) -> 147.5 | O13: =AVERAGE(F10:F13) -> 140.5 | P13: =AVERAGE(G10:G13) -> 139.5 | Q13: =AVERAGE(H10:H13) -> 113 | R13: =AVERAGE(I10:I13) -> 158.5
A14: 37678 | B14: 0 | C14: 0 | D14: 168 | E14: 133 | F14: 121 | G14: 120 | H14: 109 | I14: 155 | K14: =AVERAGE(B11:B14) -> 0 | L14: =AVERAGE(C11:C14) -> 0 | M14: =AVERAGE(D11:D14) -> 179 | N14: =AVERAGE(E11:E14) -> 137.75 | O14: =AVERAGE(F11:F14) -> 131.75 | P14: =AVERAGE(G11:G14) -> 131.25 | Q14: =AVERAGE(H11:H14) -> 110.75 | R14: =AVERAGE(I11:I14) -> 158
A15: 37685 | B15: 0 | C15: 0 | D15: 182 | E15: 141 | F15: 128 | G15: 128 | H15: 109 | I15: 144 | K15: =AVERAGE(B12:B15) -> 0 | L15: =AVERAGE(C12:C15) -> 0 | M15: =AVERAGE(D12:D15) -> 173.25 | N15: =AVERAGE(E12:E15) -> 136.5 | O15: =AVERAGE(F12:F15) -> 127.75 | P15: =AVERAGE(G12:G15) -> 128 | Q15: =AVERAGE(H12:H15) -> 109.75 | R15: =AVERAGE(I12:I15) -> 155.25
A16: 37692 | B16: 0 | C16: 0 | D16: 189 | E16: 155 | F16: 140 | G16: 143 | H16: 126 | I16: 170 | K16: =AVERAGE(B13:B16) -> 0 | L16: =AVERAGE(C13:C16) -> 0 | M16: =AVERAGE(D13:D16) -> 176 | N16: =AVERAGE(E13:E16) -> 140.5 | O16: =AVERAGE(F13:F16) -> 129 | P16: =AVERAGE(G13:G16) -> 130.25 | Q16: =AVERAGE(H13:H16) -> 113.5 | R16: =AVERAGE(I13:I16) -> 158.5
A17: 37699 | B17: 0 | C17: 187 | D17: 175 | E17: 146 | F17: 139 | G17: 140 | H17: 123 | I17: 170 | K17: =AVERAGE(B14:B17) -> 0 | L17: =AVERAGE(C14:C17) -> 46.75 | M17: =AVERAGE(D14:D17) -> 178.5 | N17: =AVERAGE(E14:E17) -> 143.75 | O17: =AVERAGE(F14:F17) -> 132 | P17: =AVERAGE(G14:G17) -> 132.75 | Q17: =AVERAGE(H14:H17) -> 116.75 | R17: =AVERAGE(I14:I17) -> 159.75
A18: 37706 | B18: 0 | C18: 163 | D18: 154 | E18: 126 | F18: 134 | G18: 137 | H18: 114 | I18: 163 | K18: =AVERAGE(B15:B18) -> 0 | L18: =AVERAGE(C15:C18) -> 87.5 | M18: =AVERAGE(D15:D18) -> 175 | N18: =AVERAGE(E15:E18) -> 142 | O18: =AVERAGE(F15:F18) -> 135.25 | P18: =AVERAGE(G15:G18) -> 137 | Q18: =AVERAGE(H15:H18) -> 118 | R18: =AVERAGE(I15:I18) -> 161.75
A19: 37713 | B19: 186 | C19: 154 | D19: 145 | E19: 115 | F19: 128 | G19: 128 | H19: 109 | I19: 155 | K19: =AVERAGE(B16:B19) -> 46.5 | L19: =AVERAGE(C16:C19) -> 126 | M19: =AVERAGE(D16:D19) -> 165.75 | N19: =AVERAGE(E16:E19) -> 135.5 | O19: =AVERAGE(F16:F19) -> 135.25 | P19: =AVERAGE(G16:G19) -> 137 | Q19: =AVERAGE(H16:H19) -> 118 | R19: =AVERAGE(I16:I19) -> 164.5
A20: 37720 | B20: 188 | C20: 158 | D20: 143 | E20: 110 | F20: 121 | G20: 121 | H20: 105 | I20: 153 | K20: =AVERAGE(B17:B20) -> 93.5 | L20: =AVERAGE(C17:C20) -> 165.5 | M20: =AVERAGE(D17:D20) -> 154.25 | N20: =AVERAGE(E17:E20) -> 124.25 | O20: =AVERAGE(F17:F20) -> 130.5 | P20: =AVERAGE(G17:G20) -> 131.5 | Q20: =AVERAGE(H17:H20) -> 112.75 | R20: =AVERAGE(I17:I20) -> 160.25
... A58: 37986 | B58: 0 | C58: 0 | D58: 200.5 | E58: 164.5 | F58: 165.5 | G58: 163.5 | H58: 155 | I58: 195 | K58: =AVERAGE(B55:B58) -> 0 | L58: =AVERAGE(C55:C58) -> 0 | M58: =AVERAGE(D55:D58) -> 211.875 | N58: =AVERAGE(E55:E58) -> 173.125 | O58: =AVERAGE(F55:F58) -> 187.875 | P58: =AVERAGE(G55:G58) -> 187.375 | Q58: =AVERAGE(H55:H58) -> 159.75 | R58: =AVERAGE(I55:I58) -> 202.5
A59: 37993 | B59: =+TWK!B4 -> 0 | C59: =+TWK!C4 -> 0 | D59: =+TWK!D4 -> 200 | E59: =+TWK!E4 -> 162 | F59: =+TWK!F4 -> 163.75 | G59: =+TWK!G4 -> 165 | H59: =+TWK!H4 -> 152.5 | I59: =+TWK!I4 -> 195 | K59: =AVERAGE(B56:B59) -> 0 | L59: =AVERAGE(C56:C59) -> 0 | M59: =AVERAGE(D56:D59) -> 207.375 | N59: =AVERAGE(E56:E59) -> 168.875 | O59: =AVERAGE(F56:F59) -> 176.5625 | P59: =AVERAGE(G56:G59) -> 176.375 | Q59: =AVERAGE(H56:H59) -> 156.125 | R59: =AVERAGE(I56:I59) -> 199.5
A60: 38000 | B60: =+TWK!B5 -> 0 | C60: =+TWK!C5 -> 0 | D60: =+TWK!D5 -> 200 | E60: =+TWK!E5 -> 162 | F60: =+TWK!F5 -> 169.5 | G60: =+TWK!G5 -> 169.5 | H60: =+TWK!H5 -> 149 | I60: =+TWK!I5 -> 198.3 | K60: =AVERAGE(B57:B60) -> 0 | L60: =AVERAGE(C57:C60) -> 0 | M60: =AVERAGE(D57:D60) -> 203.875 | N60: =AVERAGE(E57:E60) -> 163.875 | O60: =AVERAGE(F57:F60) -> 168.9375 | P60: =AVERAGE(G57:G60) -> 168.75 | Q60: =AVERAGE(H57:H60) -> 152.375 | R60: =AVERAGE(I57:I60) -> 195.825
A61: 38007 | B61: =+TWK!B6 -> 0 | C61: =+TWK!C6 -> 0 | D61: =+TWK!D6 -> 194 | E61: =+TWK!E6 -> 157 | F61: =+TWK!F6 -> 172 | G61: =+TWK!G6 -> 171 | H61: =+TWK!H6 -> 144 | I61: =+TWK!I6 -> 182 | K61: =AVERAGE(B58:B61) -> 0 | L61: =AVERAGE(C58:C61) -> 0 | M61: =AVERAGE(D58:D61) -> 198.625 | N61: =AVERAGE(E58:E61) -> 161.375 | O61: =AVERAGE(F58:F61) -> 167.6875 | P61: =AVERAGE(G58:G61) -> 167.25 | Q61: =AVERAGE(H58:H61) -> 150.125 | R61: =AVERAGE(I58:I61) -> 192.575
A62: 38014 | B62: =+TWK!B7 -> 0 | C62: =+TWK!C7 -> 0 | D62: =+TWK!D7 -> 208 | E62: =+TWK!E7 -> 150 | F62: =+TWK!F7 -> 161 | G62: =+TWK!G7 -> 159 | H62: =+TWK!H7 -> 137 | I62: =+TWK!I7 -> 165 | K62: =AVERAGE(B59:B62) -> 0 | L62: =AVERAGE(C59:C62) -> 0 | M62: =AVERAGE(D59:D62) -> 200.5 | N62: =AVERAGE(E59:E62) -> 157.75 | O62: =AVERAGE(F59:F62) -> 166.5625 | P62: =AVERAGE(G59:G62) -> 166.125 | Q62: =AVERAGE(H59:H62) -> 145.625 | R62: =AVERAGE(I59:I62) -> 185.075
A63: 38021 | B63: =+TWK!B8 -> 0 | C63: =+TWK!C8 -> 0 | D63: =+TWK!D8 -> 214 | E63: =+TWK!E8 -> 147 | F63: =+TWK!F8 -> 152 | G63: =+TWK!G8 -> 151 | H63: =+TWK!H8 -> 127 | I63: =+TWK!I8 -> 185 | K63: =AVERAGE(B60:B63) -> 0 | L63: =AVERAGE(C60:C63) -> 0 | M63: =AVERAGE(D60:D63) -> 204 | N63: =AVERAGE(E60:E63) -> 154 | O63: =AVERAGE(F60:F63) -> 163.625 | P63: =AVERAGE(G60:G63) -> 162.625 | Q63: =AVERAGE(H60:H63) -> 139.25 | R63: =AVERAGE(I60:I63) -> 182.575
A64: 38028 | B64: =+TWK!B9 -> 0 | C64: =+TWK!C9 -> 0 | D64: =+TWK!D9 -> 183 | E64: =+TWK!E9 -> 135 | F64: =+TWK!F9 -> 134 | G64: =+TWK!G9 -> 134 | H64: =+TWK!H9 -> 118 | I64: =+TWK!I9 -> 165 | K64: =AVERAGE(B61:B64) -> 0 | L64: =AVERAGE(C61:C64) -> 0 | M64: =AVERAGE(D61:D64) -> 199.75 | N64: =AVERAGE(E61:E64) -> 147.25 | O64: =AVERAGE(F61:F64) -> 154.75 | P64: =AVERAGE(G61:G64) -> 153.75 | Q64: =AVERAGE(H61:H64) -> 131.5 | R64: =AVERAGE(I61:I64) -> 174.25
A65: 38035 | B65: =+TWK!B10 -> 0 | C65: =+TWK!C10 -> 0 | D65: =+TWK!D10 -> 181 | E65: =+TWK!E10 -> 133 | F65: =+TWK!F10 -> 131 | G65: =+TWK!G10 -> 130 | H65: =+TWK!H10 -> 117 | I65: =+TWK!I10 -> 173 | K65: =AVERAGE(B62:B65) -> 0 | L65: =AVERAGE(C62:C65) -> 0 | M65: =AVERAGE(D62:D65) -> 196.5 | N65: =AVERAGE(E62:E65) -> 141.25 | O65: =AVERAGE(F62:F65) -> 144.5 | P65: =AVERAGE(G62:G65) -> 143.5 | Q65: =AVERAGE(H62:H65) -> 124.75 | R65: =AVERAGE(I62:I65) -> 172
A66: 38042 | B66: =+TWK!B11 -> 0 | C66: =+TWK!C11 -> 0 | D66: =+TWK!D11 -> 161 | E66: =+TWK!E11 -> 130 | F66: =+TWK!F11 -> 126 | G66: =+TWK!G11 -> 125 | H66: =+TWK!H11 -> 120 | I66: =+TWK!I11 -> 165 | K66: =AVERAGE(B63:B66) -> 0 | L66: =AVERAGE(C63:C66) -> 0 | M66: =AVERAGE(D63:D66) -> 184.75 | N66: =AVERAGE(E63:E66) -> 136.25 | O66: =AVERAGE(F63:F66) -> 135.75 | P66: =AVERAGE(G63:G66) -> 135 | Q66: =AVERAGE(H63:H66) -> 120.5 | R66: =AVERAGE(I63:I66) -> 172
A67: 38049 | B67: =+TWK!B12 -> 0 | C67: =+TWK!C12 -> 0 | D67: =+TWK!D12 -> 160 | E67: =+TWK!E12 -> 130 | F67: =+TWK!F12 -> 124 | G67: =+TWK!G12 -> 126 | H67: =+TWK!H12 -> 116 | I67: =+TWK!I12 -> 162 | K67: =AVERAGE(B64:B67) -> 0 | L67: =AVERAGE(C64:C67) -> 0 | M67: =AVERAGE(D64:D67) -> 171.25 | N67: =AVERAGE(E64:E67) -> 132 | O67: =AVERAGE(F64:F67) -> 128.75 | P67: =AVERAGE(G64:G67) -> 128.75 | Q67: =AVERAGE(H64:H67) -> 117.75 | R67: =AVERAGE(I64:I67) -> 166.25
A68: 38056 | B68: =+TWK!B13 -> 0 | C68: =+TWK!C13 -> 0 | D68: =+TWK!D13 -> 149 | E68: =+TWK!E13 -> 127 | F68: =+TWK!F13 -> 122 | G68: =+TWK!G13 -> 122 | H68: =+TWK!H13 -> 114 | I68: =+TWK!I13 -> 160 | K68: =AVERAGE(B65:B68) -> 0 | L68: =AVERAGE(C65:C68) -> 0 | M68: =AVERAGE(D65:D68) -> 162.75 | N68: =AVERAGE(E65:E68) -> 130 | O68: =AVERAGE(F65:F68) -> 125.75 | P68: =AVERAGE(G65:G68) -> 125.75 | Q68: =AVERAGE(H65:H68) -> 116.75 | R68: =AVERAGE(I65:I68) -> 165
A69: 38063 | B69: =+TWK!B14 -> 0 | C69: =+TWK!C14 -> 165 | D69: =+TWK!D14 -> 151 | E69: =+TWK!E14 -> 124 | F69: =+TWK!F14 -> 122 | G69: =+TWK!G14 -> 121 | H69: =+TWK!H14 -> 112 | I69: =+TWK!I14 -> 158 | K69: =AVERAGE(B66:B69) -> 0 | L69: =AVERAGE(C66:C69) -> 41.25 | M69: =AVERAGE(D66:D69) -> 155.25 | N69: =AVERAGE(E66:E69) -> 127.75 | O69: =AVERAGE(F66:F69) -> 123.5 | P69: =AVERAGE(G66:G69) -> 123.5 | Q69: =AVERAGE(H66:H69) -> 115.5 | R69: =AVERAGE(I66:I69) -> 161.25
A70: 38070 | B70: =+TWK!B15 -> 184 | C70: =+TWK!C15 -> 152 | D70: =+TWK!D15 -> 143 | E70: =+TWK!E15 -> 115 | F70: =+TWK!F15 -> 119 | G70: =+TWK!G15 -> 119 | H70: =+TWK!H15 -> 110 | I70: =+TWK!I15 -> 152 | K70: =AVERAGE(B67:B70) -> 46 | L70: =AVERAGE(C67:C70) -> 79.25 | M70: =AVERAGE(D67:D70) -> 150.75 | N70: =AVERAGE(E67:E70) -> 124 | O70: =AVERAGE(F67:F70) -> 121.75 | P70: =AVERAGE(G67:G70) -> 122 | Q70: =AVERAGE(H67:H70) -> 113 | R70: =AVERAGE(I67:I70) -> 158
... A201: 38986 | B201: =+TWK!B146 -> 591 | C201: =+TWK!C146 -> 572 | D201: =+TWK!D146 -> 581 | E201: =+TWK!E146 -> 501 | F201: =+TWK!F146 -> 528 | G201: =+TWK!G146 -> 529 | H201: =+TWK!H146 -> 421 | I201: =+TWK!I146 -> 568 | K201: =AVERAGE(B198:B201) -> 570.5 | L201: =AVERAGE(C198:C201) -> 552.5 | M201: =AVERAGE(D198:D201) -> 534.75 | N201: =AVERAGE(E198:E201) -> 489.75 | O201: =AVERAGE(F198:F201) -> 539.25 | P201: =AVERAGE(G198:G201) -> 540.5 | Q201: =AVERAGE(H198:H201) -> 434.75 | R201: =AVERAGE(I198:I201) -> 566.25
A202: =+A201+7 -> 38993 | B202: =+TWK!B147 -> 632 | C202: =+TWK!C147 -> 639 | D202: =+TWK!D147 -> 608 | E202: =+TWK!E147 -> 605 | F202: =+TWK!F147 -> 646 | G202: =+TWK!G147 -> 648 | H202: =+TWK!H147 -> 546 | I202: =+TWK!I147 -> 701 | K202: =AVERAGE(B199:B202) -> 594 | L202: =AVERAGE(C199:C202) -> 581 | M202: =AVERAGE(D199:D202) -> 560.75 | N202: =AVERAGE(E199:E202) -> 520.25 | O202: =AVERAGE(F199:F202) -> 570 | P202: =AVERAGE(G199:G202) -> 571 | Q202: =AVERAGE(H199:H202) -> 464.75 | R202: =AVERAGE(I199:I202) -> 601
A203: =A202+7 -> 39000 | B203: =+TWK!B148 -> 616 | C203: =+TWK!C148 -> 619 | D203: =+TWK!D148 -> 562 | E203: =+TWK!E148 -> 570 | F203: =+TWK!F148 -> 643 | G203: =+TWK!G148 -> 647 | H203: =+TWK!H148 -> 543 | I203: =+TWK!I148 -> 717 | K203: =AVERAGE(B200:B203) -> 606.75 | L203: =AVERAGE(C200:C203) -> 595.5 | M203: =AVERAGE(D200:D203) -> 572.75 | N203: =AVERAGE(E200:E203) -> 539 | O203: =AVERAGE(F200:F203) -> 587 | P203: =AVERAGE(G200:G203) -> 589 | Q203: =AVERAGE(H200:H203) -> 484 | R203: =AVERAGE(I200:I203) -> 634
A204: =+A203+7 -> 39007 | B204: =+TWK!B149 -> 592 | C204: =+TWK!C149 -> 597 | D204: =+TWK!D149 -> 554 | E204: =+TWK!E149 -> 513 | F204: =+TWK!F149 -> 578 | G204: =+TWK!G149 -> 582 | H204: =+TWK!H149 -> 450 | I204: =+TWK!I149 -> 588 | K204: =AVERAGE(B201:B204) -> 607.75 | L204: =AVERAGE(C201:C204) -> 606.75 | M204: =AVERAGE(D201:D204) -> 576.25 | N204: =AVERAGE(E201:E204) -> 547.25 | O204: =AVERAGE(F201:F204) -> 598.75 | P204: =AVERAGE(G201:G204) -> 601.5 | Q204: =AVERAGE(H201:H204) -> 490 | R204: =AVERAGE(I201:I204) -> 643.5
A205: =+A204+7 -> 39014 | B205: =+TWK!B150 -> 490 | C205: =+TWK!C150 -> 461 | D205: =+TWK!D150 -> 450 | E205: =+TWK!E150 -> 350 | F205: =+TWK!F150 -> 400 | G205: =+TWK!G150 -> 400 | H205: =+TWK!H150 -> 310 | I205: =+TWK!I150 -> 427 | K205: =AVERAGE(B202:B205) -> 582.5 | L205: =AVERAGE(C202:C205) -> 579 | M205: =AVERAGE(D202:D205) -> 543.5 | N205: =AVERAGE(E202:E205) -> 509.5 | O205: =AVERAGE(F202:F205) -> 566.75 | P205: =AVERAGE(G202:G205) -> 569.25 | Q205: =AVERAGE(H202:H205) -> 462.25 | R205: =AVERAGE(I202:I205) -> 608.25
A206: 39021 | B206: =+TWK!B151 -> 648 | C206: =+TWK!C151 -> 543 | D206: =+TWK!D151 -> 528 | E206: =+TWK!E151 -> 439 | F206: =+TWK!F151 -> 389 | G206: =+TWK!G151 -> 389 | H206: =+TWK!H151 -> 325 | I206: =+TWK!I151 -> 425 | K206: =AVERAGE(B203:B206) -> 586.5 | L206: =AVERAGE(C203:C206) -> 555 | M206: =AVERAGE(D203:D206) -> 523.5 | N206: =AVERAGE(E203:E206) -> 468 | O206: =AVERAGE(F203:F206) -> 502.5 | P206: =AVERAGE(G203:G206) -> 504.5 | Q206: =AVERAGE(H203:H206) -> 407 | R206: =AVERAGE(I203:I206) -> 539.25
A207: 39028 | B207: =+TWK!B152 -> 548 | C207: =+TWK!C152 -> 494 | D207: =+TWK!D152 -> 459 | E207: =+TWK!E152 -> 409 | F207: =+TWK!F152 -> 401 | G207: =+TWK!G152 -> 401 | H207: =+TWK!H152 -> 300 | I207: =+TWK!I152 -> 409 | K207: =AVERAGE(B204:B207) -> 569.5 | L207: =AVERAGE(C204:C207) -> 523.75 | M207: =AVERAGE(D204:D207) -> 497.75 | N207: =AVERAGE(E204:E207) -> 427.75 | O207: =AVERAGE(F204:F207) -> 442 | P207: =AVERAGE(G204:G207) -> 443 | Q207: =AVERAGE(H204:H207) -> 346.25 | R207: =AVERAGE(I204:I207) -> 462.25
A208: 39035 | B208: =+TWK!B153 -> 498 | C208: =+TWK!C153 -> 438 | D208: =+TWK!D153 -> 445 | E208: =+TWK!E153 -> 378 | F208: =+TWK!F153 -> 377 | G208: =+TWK!G153 -> 377 | H208: =+TWK!H153 -> 281 | I208: =+TWK!I153 -> 386 | K208: =AVERAGE(B205:B208) -> 546 | L208: =AVERAGE(C205:C208) -> 484 | M208: =AVERAGE(D205:D208) -> 470.5 | N208: =AVERAGE(E205:E208) -> 394 | O208: =AVERAGE(F205:F208) -> 391.75 | P208: =AVERAGE(G205:G208) -> 391.75 | Q208: =AVERAGE(H205:H208) -> 304 | R208: =AVERAGE(I205:I208) -> 411.75
...

Sheet New Table 9
A1: Weekly Barge Rates for Major Grain Shipping Points on the Mississippi, Ohio, and Arkansas Rivers
A2: Table 9
A3: Weekly Barge Freight Rates: Southbound Only
C4: Twin Cities | D4: Mid-Mississippi | E4: Lower Illinois River | F4: St. Louis | G4: Cincinnati | H4: Lower Ohio | I4: Cairo-Memphis
A6: Rate1 | B6: 41933 | C6: =+TWK!B567 -> 793.75 | D6: =+TWK!C567 -> 856.25 | E6: =+TWK!D567 -> 872.5 | F6: =+TWK!E567 -> 731.25 | G6: =+TWK!F567 -> 887.5 | H6: =+TWK!G567 -> 887.5 | I6: =+TWK!H567 -> 650
B7: =+B6-7 -> 41926 | C7: =+TWK!B566 -> 741.66667 | D7: =+TWK!C566 -> 836.66667 | E7: =+TWK!D566 -> 833.33333 | F7: =+TWK!E566 -> 683.33333 | G7: =+TWK!F566 -> 808.33333 | H7: =+TWK!G566 -> 808.33333 | I7: =+TWK!H566 -> 616.66667 | L7: -
A9: $/ton | B9: =B6 -> 41933 | C9: =(ROUND(C6,0))*C$24/100 -> 49.1486 | D9: =(ROUND(D6,0))*D$24/100 -> 45.5392 | E9: =(ROUND(E6,0))*E$24/100 -> 40.5072 | F9: =(ROUND(F6,0))*F$24/100 -> 29.1669 | G9: =(ROUND(G6,0))*G$24/100 -> 41.6472 | H9: =(ROUND(H6,0))*H$24/100 -> 35.8752 | I9: =(ROUND(I6,0))*I$24/100 -> 20.41
B10: =B7 -> 41926 | C10: =(ROUND(C7,0))*C$24/100 -> 45.9298 | D10: =(ROUND(D7,0))*D$24/100 -> 44.5284 | E10: =(ROUND(E7,0))*E$24/100 -> 38.6512 | F10: =(ROUND(F7,0))*F$24/100 -> 27.2517 | G10: =(ROUND(G7,0))*G$24/100 -> 37.8952 | H10: =(ROUND(H7,0))*H$24/100 -> 32.6432 | I10: =(ROUND(I7,0))*I$24/100 -> 19.3738
A12: Current week % change from the same week:
B14: Last year | C14: =+'Table 9_data'!AN622 -> 28.716216 | D14: =+'Table 9_data'!AO622 -> 35.769027 | E14: =+'Table 9_data'!AP622 -> 36.186264 | F14: =+'Table 9_data'!AQ622 -> 28.665689 | G14: =+'Table 9_data'!AR622 -> 27.881844 | H14: =+'Table 9_data'!AS622 -> 27.881844 | I14: =+'Table 9_data'!AT622 -> 27.035831
B15: 3-year avg. 2 | C15: =+'Table 9_data'!AD622 -> 37.910232 | D15: =+'Table 9_data'!AE622 -> 52.924542 | E15: =+'Table 9_data'!AF622 -> 55.822895 | F15: =+'Table 9_data'!AG622 -> 41.873594 | G15: =+'Table 9_data'!AH622 -> 54.291923 | H15: =+'Table 9_data'!AI622 -> 54.291923 | I15: =+'Table 9_data'!AJ622 -> 33.894086
F16: =+'Table 9_data'!AG495 -> -2.1818873 | G16: =+'Table 9_data'!AH495 -> 6.4785119 | H16: =+'Table 9_data'!AI495 -> 6.3080371
A17: Rate1 | B17: November | C17: =+NXTMONTH!C567 -> 775 | D17: =+NXTMONTH!D567 -> 787.5 | E17: =+NXTMONTH!E567 -> 756.25 | F17: =+NXTMONTH!F567 -> 625 | G17: =+NXTMONTH!G567 -> 743.75 | H17: =+NXTMONTH!H567 -> 766.66667 | I17: =+NXTMONTH!I567 -> 558.33333
B18: January | C18: - | D18: - | E18: =+THREEMONTH!E567 -> 600 | F18: =+THREEMONTH!F567 -> 468.75 | G18: =+THREEMONTH!G567 -> 520 | H18: =+THREEMONTH!H567 -> 545 | I18: =+THREEMONTH!I567 -> 431.25
A19: 1Rate = percent of 1976 tariff benchmark index (1976 = 100 percent); 24-week moving average; ton = 2,000 pounds;
A20: Source: Transportation & Marketing Programs/AMS/USDA
C23: TWC | D23: MM | E23: ILL | F23: ST LOUIS | G23: =+TWK!F3 -> CINC | H23: LOH | I23: CAR-MEM
A24: Benchmark Tariff Rates | C24: 6.19 | D24: 5.32 | E24: 4.64 | F24: 3.99 | G24: 4.69 | H24: 4.04 | I24: 3.14
