Workbook
Name standings?category_league_season_2008_REG_split_Overall: powerflaws!$A$1:$T$34

Sheet power
A1: Rank | B1: Team | C1: W | D1: L | E1: W-L | F1: Team Code | G1: Sando | H1: Clayton | I1: Graziano | J1: Hensley | K1: Fox | L1: Average | M1: High | N1: Low | O1: Biggest Gap | P1: Division | Q1: Sando High Vote | R1: Clayton High Vote | S1: Kuharsky High Vote | T1: Walker High Vote | U1: Fox High Vote | V1: Sando Low Vote | W1: Clayton Low Vote | X1: Kuharsky Low Vote | Y1: Walker Low Vote | Z1: Fox Low Vote | AA1: Week1 | AB1: Week 2 | AC1: Week 3 | AD1: Week 4 | AE1: Week 5 | AF1: Week 6 | AG1: Week 7 | AH1: x | AI1: x | AJ1: x | AK1: x | AL1: x | AM1: x | AN1: x | AO1: x | AP1: x | AQ1: x | AR1: x | AS1: x | AT1: x | AU1: Average
A2: 1 | B2: Atlanta Falcons | C2: 6 | D2: 0 | E2: 6-0 | F2: ATL | G2: 1 | H2: 1 | I2: 1 | J2: 1 | K2: 1 | L2: 1 | M2: 1 | N2: 1 | O2: 0 | P2: NFC South | Q2: 1 | R2: 1 | S2: 1 | T2: 1 | U2: 1 | V2: 1 | W2: 1 | X2: 1 | Y2: 1 | Z2: 1 | AA2: 10 | AB2: 6 | AC2: 3 | AD2: 2 | AE2: 2 | AF2: 2 | AG2: 1 | AU2: 3.7142857 | AV2: Atlanta Falcons (+2),
A3: 2 | B3: Houston Texans | C3: 5 | D3: 1 | E3: 5-1 | F3: HOU | G3: 3 | H3: 3 | I3: 3 | J3: 3 | K3: 3 | L3: 3 | M3: 3 | N3: 3 | O3: 0 | P3: AFC South | Q3: 1 | R3: 1 | S3: 1 | T3: 1 | U3: 1 | V3: 1 | W3: 1 | X3: 1 | Y3: 1 | Z3: 1 | AA3: 5 | AB3: 4 | AC3: 2 | AD3: 1 | AE3: 1 | AF3: 1 | AG3: 2 | AU3: 2.2857143 | AV3: Houston Texans (+1),
A4: 2 | B4: New York Giants | C4: 4 | D4: 2 | E4: 4-2 | F4: NYG | G4: 2 | H4: 5 | I4: 2 | J4: 4 | K4: 2 | L4: 3 | M4: 2 | N4: 5 | O4: 3 | P4: NFC East | Q4: 1 | R4: 0 | S4: 1 | T4: 0 | U4: 1 | V4: 0 | W4: 1 | X4: 0 | Y4: 0 | Z4: 0 | AA4: 3 | AB4: 7 | AC4: 8 | AD4: 6 | AE4: 10 | AF4: 7 | AG4: 3 | AU4: 6.2857143 | AV4: New York Giants (+7),
A5: 4 | B5: Baltimore Ravens | C5: 5 | D5: 1 | E5: 5-1 | F5: BAL | G5: 4 | H5: 2 | I5: 4 | J5: 2 | K5: 4 | L5: 3.2 | M5: 2 | N5: 4 | O5: 2 | P5: AFC North | Q5: 0 | R5: 1 | S5: 0 | T5: 1 | U5: 0 | V5: 1 | W5: 0 | X5: 1 | Y5: 0 | Z5: 1 | AA5: 6 | AB5: 3 | AC5: 6 | AD5: 3 | AE5: 3 | AF5: 4 | AG5: 4 | AU5: 4.1428571 | AV5: Baltimore Ravens (+4),
A6: 5 | B6: San Francisco 49ers | C6: 4 | D6: 2 | E6: 4-2 | F6: SF | G6: 5 | H6: 6 | I6: 5 | J6: 5 | K6: 6 | L6: 5.4 | M6: 5 | N6: 6 | O6: 1 | P6: NFC West | Q6: 1 | R6: 0 | S6: 1 | T6: 1 | U6: 0 | V6: 0 | W6: 1 | X6: 0 | Y6: 0 | Z6: 1 | AA6: 4 | AB6: 2 | AC6: 1 | AD6: 4 | AE6: 4 | AF6: 3 | AG6: 5 | AU6: 3.2857143 | AV6: San Francisco 49ers (+3),
A7: 6 | B7: Chicago Bears | C7: 4 | D7: 1 | E7: 4-1 | F7: CHI | G7: 6 | H7: 4 | I7: 7 | J7: 6 | K7: 5 | L7: 5.6 | M7: 4 | N7: 7 | O7: 3 | P7: NFC North | Q7: 0 | R7: 1 | S7: 0 | T7: 0 | U7: 0 | V7: 0 | W7: 0 | X7: 1 | Y7: 0 | Z7: 0 | AA7: 9 | AB7: 8 | AC7: 12 | AD7: 11 | AE7: 9 | AF7: 6 | AG7: 6 | AU7: 8.7142857 | AV7: Chicago Bears (+6),
A8: 7 | B8: New England Patriots | C8: 3 | D8: 3 | E8: 3-3 | F8: NE | G8: 9 | H8: 7 | I8: 8 | J8: 8 | K8: 8 | L8: 8 | M8: 7 | N8: 9 | O8: 2 | P8: AFC East | Q8: 0 | R8: 1 | S8: 0 | T8: 0 | U8: 0 | V8: 1 | W8: 0 | X8: 0 | Y8: 0 | Z8: 0 | AA8: 2 | AB8: 1 | AC8: 5 | AD8: 8 | AE8: 6 | AF8: 5 | AG8: 7 | AU8: 4.8571429 | AV8: New England Patriots (+5),
A9: 8 | B9: Green Bay Packers | C9: 3 | D9: 3 | E9: 3-3 | F9: GB | G9: 8 | H9: 12 | I9: 6 | J9: 7 | K9: 9 | L9: 8.4 | M9: 6 | N9: 12 | O9: 6 | P9: NFC North | Q9: 0 | R9: 0 | S9: 1 | T9: 0 | U9: 0 | V9: 0 | W9: 1 | X9: 0 | Y9: 0 | Z9: 0 | AA9: 1 | AB9: 5 | AC9: 4 | AD9: 7 | AE9: 8 | AF9: 12 | AG9: 8 | AU9: 6.4285714 | AV9: Green Bay Packers (+12),
A10: 9 | B10: Seattle Seahawks | C10: 4 | D10: 2 | E10: 4-2 | F10: SEA | G10: 7 | H10: 10 | I10: 16 | J10: 11 | K10: 7 | L10: 10.2 | M10: 7 | N10: 16 | O10: 9 | P10: NFC West | Q10: 1 | R10: 0 | S10: 0 | T10: 0 | U10: 1 | V10: 0 | W10: 0 | X10: 1 | Y10: 0 | Z10: 0 | AA10: 20 | AB10: 26 | AC10: 17 | AD10: 10 | AE10: 17 | AF10: 16 | AG10: 9 | AU10: 16.428571 | AV10: Seattle Seahawks (+16),
A11: 10 | B11: Minnesota Vikings | C11: 4 | D11: 2 | E11: 4-2 | F11: MIN | G11: 11 | H11: 8 | I11: 17 | J11: 9 | K11: 10 | L11: 11 | M11: 8 | N11: 17 | O11: 9 | P11: NFC North | Q11: 0 | R11: 1 | S11: 0 | T11: 0 | U11: 0 | V11: 0 | W11: 0 | X11: 1 | Y11: 0 | Z11: 0 | AA11: 30 | AB11: 28 | AC11: 29 | AD11: 21 | AE11: 14 | AF11: 8 | AG11: 10 | AU11: 20 | AV11: Minnesota Vikings (+8),
A12: 10 | B12: Arizona Cardinals | C12: 4 | D12: 2 | E12: 4-2 | F12: ARI | G12: 14 | H12: 9 | I12: 11 | J12: 10 | K12: 11 | L12: 11 | M12: 9 | N12: 14 | O12: 5 | P12: NFC West | Q12: 0 | R12: 1 | S12: 0 | T12: 0 | U12: 0 | V12: 1 | W12: 0 | X12: 0 | Y12: 0 | Z12: 0 | AA12: 23 | AB12: 20 | AC12: 14 | AD12: 5 | AE12: 5 | AF12: 9 | AG12: 11 | AU12: 12.428571 | AV12: Arizona Cardinals (+9),
A13: 12 | B13: Denver Broncos | C13: 3 | D13: 3 | E13: 3-3 | F13: DEN | G13: 10 | H13: 15 | I13: 9 | J13: 12 | K13: 14 | L13: 12 | M13: 9 | N13: 15 | O13: 6 | P13: AFC West | Q13: 0 | R13: 0 | S13: 1 | T13: 0 | U13: 0 | V13: 0 | W13: 1 | X13: 0 | Y13: 0 | Z13: 0 | AA13: 13 | AB13: 9 | AC13: 10 | AD13: 14 | AE13: 13 | AF13: 17 | AG13: 12 | AU13: 12.571429 | AV13: Denver Broncos (+17),
... A33: 31 | B33: Kansas City Chiefs | C33: 1 | D33: 5 | E33: 1-5 | F33: KC | G33: 31 | H33: 32 | I33: 30 | J33: 32 | K33: 32 | L33: 31.4 | M33: 30 | N33: 32 | O33: 2 | P33: AFC West | Q33: 0 | R33: 0 | S33: 1 | T33: 0 | U33: 0 | V33: 0 | W33: 1 | X33: 0 | Y33: 1 | Z33: 1 | AA33: 17 | AB33: 19 | AC33: 28 | AD33: 26 | AE33: 27 | AF33: 30 | AG33: 32 | AU33: 25.571429 | AV33: Kansas City Chiefs (+30),
F37: high votes | G37: 7 | H37: 12 | I37: 15 | J37: 10 | K37: 9
F38: low votes | G38: 11 | H38: 10 | I38: 12 | J38: 7 | K38: 8
F40: Repeats | G40: 0 | H40: 0 | I40: 0 | J40: 0 | K40: 0
AB41: AFC East | AC41: AFC North | AD41: AFC South | AE41: AFC West
F42: Correlation | G42: Sando | H42: Clayton | I42: Graziano | J42: Hensley | K42: Fox | AB42: 7-NE | AC42: 4-BAL | AD42: 2-HOU | AE42: 12-DEN
F43: Sando | H43: 0.95747801 | I43: 0.92558651 | J43: 0.94904692 | K43: 0.96590909 | AB43: 17-MIA | AC43: 14-PIT | AD43: 26-IND | AE43: 16-SD
F44: Clayton | G44: 0.95747801 | I44: 0.91239003 | J44: 0.9398827 | K44: 0.94428152 | AB44: 23-NYJ | AC44: 21-CIN | AD44: 27-TEN | AE44: 29-OAK
F45: Graziano | G45: 0.92558651 | H45: 0.91239003 | J45: 0.90835777 | K45: 0.92705279 | AB45: 25-BUF | AC45: 30-CLE | AD45: 31-JAC | AE45: 32-KC
F46: Hensley | G46: 0.94904692 | H46: 0.9398827 | I46: 0.92705279 | K46: 0.96260997
F47: Fox | G47: 0.96590909 | H47: 0.94428152 | I47: 0.92705279 | J47: 0.96260997 | AB47: NFC East | AC47: NFC North | AD47: NFC South | AE47: NFC West
AB48: 3-NYG | AC48: 6-CHI | AD48: 1-ATL | AE48: 5-SF
B49: Tiebreakers | AB49: 13-PHI | AC49: 8-GB | AD49: 22-TB | AE49: 9-SEA
B50: Head to head | AB50: 15-WAS | AC50: 10-MIN | AD50: 24-NO | AE50: 11-ARI
B51: Overall record | AB51: 18-DAL | AC51: 19-DET | AD51: 28-CAR | AE51: 20-STL
B52: Won most recently
B53: Previous Ranking
B55: Date | F55: Tiebreak | G55: Tiebreak | H55: Tiebreak | I55: Tiebreak
B56: Week 1 | F56: BAL>PHI | G56: TEN>BUF | H56: MIA>STL
B57: Week 2 | F57: NE>SF | G57: CIN>KC | H57: TEN>CAR>BUF
B58: Week 3 | F58: ARI>DAL | G58: SEA>NYJ
B59: Week 4
B60: Week 5 | F60: PHI>GB | G60: SD>CIN
B61: Week 6 | F61: SD>CIN | G61: MIA>DET | H61: IND>TB | I61: NYJ>CAR
B62: Week 7 | F62: HOU>NYG | G62: MIN>ARI | H62: JAC>KC
B63: Week 8
B64: Week 9
...

Sheet Sando
A1: Team | B1: Week 1 | C1: Week 2 | D1: Week 3 | E1: Week 4 | F1: Week 5 | G1: Week 6 | H1: Week 7 | I1: Week 8 | J1: Week 9 | K1: Week 10 | L1: Week 11 | M1: Week 12 | N1: Week 13 | O1: Week 14 | P1: Week 15 | Q1: Week 16 | R1: Week 17 | S1: Week 18 | T1: Average | U1: Highest | V1: Lowest | W1: Gap | X1: x
A2: Houston Texans | B2: 6 | C2: 4 | D2: 2 | E2: 1 | F2: 1 | G2: 2 | H2: 3 | T2: =AVERAGE(B2:S2) -> 2.7142857 | U2: =MINA(B2:S2) -> 1 | V2: =MAXA(B2:S2) -> 6 | W2: =V2-U2 -> 5 | AE2: =AC2-AD2 -> 0
A3: San Francisco 49ers | B3: 4 | C3: 1 | D3: 1 | E3: 4 | F3: 4 | G3: 1 | H3: 5 | T3: =AVERAGE(B3:S3) -> 2.8571429 | U3: =MINA(B3:S3) -> 1 | V3: =MAXA(B3:S3) -> 5 | W3: =V3-U3 -> 4 | AE3: =AC3-AD3 -> 0
A4: Baltimore Ravens | B4: 5 | C4: 3 | D4: 7 | E4: 3 | F4: 3 | G4: 4 | H4: 4 | T4: =AVERAGE(B4:S4) -> 4.1428571 | U4: =MINA(B4:S4) -> 3 | V4: =MAXA(B4:S4) -> 7 | W4: =V4-U4 -> 4 | AE4: =AC4-AD4 -> 0
A5: Atlanta Falcons | B5: 12 | C5: 6 | D5: 3 | E5: 2 | F5: 2 | G5: 3 | H5: 1 | T5: =AVERAGE(B5:S5) -> 4.1428571 | U5: =MINA(B5:S5) -> 1 | V5: =MAXA(B5:S5) -> 12 | W5: =V5-U5 -> 11 | AE5: =AC5-AD5 -> 0
A6: New England Patriots | B6: 1 | C6: 2 | D6: 5 | E6: 6 | F6: 6 | G6: 5 | H6: 9 | T6: =AVERAGE(B6:S6) -> 4.8571429 | U6: =MINA(B6:S6) -> 1 | V6: =MAXA(B6:S6) -> 9 | W6: =V6-U6 -> 8 | AE6: =AC6-AD6 -> 0
A7: Green Bay Packers | B7: 2 | C7: 5 | D7: 4 | E7: 7 | F7: 7 | G7: 13 | H7: 8 | T7: =AVERAGE(B7:S7) -> 6.5714286 | U7: =MINA(B7:S7) -> 2 | V7: =MAXA(B7:S7) -> 13 | W7: =V7-U7 -> 11 | AE7: =AC7-AD7 -> 0
A8: New York Giants | B8: 3 | C8: 12 | D8: 9 | E8: 8 | F8: 10 | G8: 7 | H8: 2 | T8: =AVERAGE(B8:S8) -> 7.2857143 | U8: =MINA(B8:S8) -> 2 | V8: =MAXA(B8:S8) -> 12 | W8: =V8-U8 -> 10 | AE8: =AC8-AD8 -> 0
A9: Chicago Bears | B9: 9 | C9: 7 | D9: 13 | E9: 12 | F9: 9 | G9: 6 | H9: 6 | T9: =AVERAGE(B9:S9) -> 8.8571429 | U9: =MINA(B9:S9) -> 6 | V9: =MAXA(B9:S9) -> 13 | W9: =V9-U9 -> 7
A10: Philadelphia Eagles | B10: 7 | C10: 13 | D10: 6 | E10: 10 | F10: 8 | G10: 12 | H10: 13 | T10: =AVERAGE(B10:S10) -> 9.8571429 | U10: =MINA(B10:S10) -> 6 | V10: =MAXA(B10:S10) -> 13 | W10: =V10-U10 -> 7
A11: Pittsburgh Steelers | B11: 8 | C11: 9 | D11: 8 | E11: 15 | F11: 16 | G11: 9 | H11: 12 | T11: =AVERAGE(B11:S11) -> 11 | U11: =MINA(B11:S11) -> 8 | V11: =MAXA(B11:S11) -> 16 | W11: =V11-U11 -> 8
A12: Denver Broncos | B12: 11 | C12: 8 | D12: 12 | E12: 13 | F12: 11 | G12: 14 | H12: 10 | T12: =AVERAGE(B12:S12) -> 11.285714 | U12: =MINA(B12:S12) -> 8 | V12: =MAXA(B12:S12) -> 14 | W12: =V12-U12 -> 6
A13: Arizona Cardinals | B13: 23 | C13: 20 | D13: 14 | E13: 5 | F13: 5 | G13: 10 | H13: 14 | T13: =AVERAGE(B13:S13) -> 13 | U13: =MINA(B13:S13) -> 5 | V13: =MAXA(B13:S13) -> 23 | W13: =V13-U13 -> 18
A14: Seattle Seahawks | B14: 14 | C14: 22 | D14: 15 | E14: 9 | F14: 15 | G14: 11 | H14: 7 | T14: =AVERAGE(B14:S14) -> 13.285714 | U14: =MINA(B14:S14) -> 7 | V14: =MAXA(B14:S14) -> 22 | W14: =V14-U14 -> 15
A15: Detroit Lions | B15: 10 | C15: 10 | D15: 11 | E15: 17 | F15: 20 | G15: 19 | H15: 16 | T15: =AVERAGE(B15:S15) -> 14.714286 | U15: =MINA(B15:S15) -> 10 | V15: =MAXA(B15:S15) -> 20 | W15: =V15-U15 -> 10
A16: San Diego Chargers | B16: 18 | C16: 15 | D16: 10 | E16: 16 | F16: 14 | G16: 16 | H16: 17 | T16: =AVERAGE(B16:S16) -> 15.142857 | U16: =MINA(B16:S16) -> 10 | V16: =MAXA(B16:S16) -> 18 | W16: =V16-U16 -> 8
A17: Cincinnati Bengals | B17: 16 | C17: 19 | D17: 17 | E17: 14 | F17: 12 | G17: 15 | H17: 18 | T17: =AVERAGE(B17:S17) -> 15.857143 | U17: =MINA(B17:S17) -> 12 | V17: =MAXA(B17:S17) -> 19 | W17: =V17-U17 -> 7
A18: Dallas Cowboys | B18: 17 | C18: 11 | D18: 16 | E18: 11 | F18: 18 | G18: 18 | H18: 21 | T18: =AVERAGE(B18:S18) -> 16 | U18: =MINA(B18:S18) -> 11 | V18: =MAXA(B18:S18) -> 21 | W18: =V18-U18 -> 10
A19: Minnesota Vikings | B19: 30 | C19: 28 | D19: 30 | E19: 22 | F19: 13 | G19: 8 | H19: 11 | T19: =AVERAGE(B19:S19) -> 20.285714 | U19: =MINA(B19:S19) -> 8 | V19: =MAXA(B19:S19) -> 30 | W19: =V19-U19 -> 22
A20: Washington Redskins | B20: 25 | C20: 16 | D20: 22 | E20: 23 | F20: 19 | G20: 21 | H20: 20 | T20: =AVERAGE(B20:S20) -> 20.857143 | U20: =MINA(B20:S20) -> 16 | V20: =MAXA(B20:S20) -> 25 | W20: =V20-U20 -> 9
... A33: Cleveland Browns | B33: 31 | C33: 32 | D33: 32 | E33: 32 | F33: 32 | G33: 32 | H33: 29 | T33: =AVERAGE(B33:S33) -> 31.428571 | U33: =MINA(B33:S33) -> 29 | V33: =MAXA(B33:S33) -> 32 | W33: =V33-U33 -> 3

Sheet Clayton
A1: Team | B1: Week 1 | C1: Week 2 | D1: Week 3 | E1: Week 4 | F1: Week 5 | G1: Week 6 | H1: Week 7 | I1: Week 8 | J1: Week 9 | K1: Week 10 | L1: Week 11 | M1: Week 12 | N1: Week 13 | O1: Week 14 | P1: Week 15 | Q1: Week 16 | R1: Week 17 | S1: Week 18 | T1: Average | U1: Highest | V1: Lowest | W1: Gap | X1: x
A2: Houston Texans | B2: 5 | C2: 3 | D2: 2 | E2: 1 | F2: 1 | G2: 1 | H2: 3 | T2: =AVERAGE(B2:S2) -> 2.2857143 | U2: =MINA(B2:S2) -> 1 | V2: =MAXA(B2:S2) -> 5 | W2: =V2-U2 -> 4
A3: San Francisco 49ers | B3: 4 | C3: 2 | D3: 1 | E3: 4 | F3: 4 | G3: 4 | H3: 6 | T3: =AVERAGE(B3:S3) -> 3.5714286 | U3: =MINA(B3:S3) -> 1 | V3: =MAXA(B3:S3) -> 6 | W3: =V3-U3 -> 5
A4: Atlanta Falcons | B4: 10 | C4: 5 | D4: 3 | E4: 2 | F4: 2 | G4: 2 | H4: 1 | T4: =AVERAGE(B4:S4) -> 3.5714286 | U4: =MINA(B4:S4) -> 1 | V4: =MAXA(B4:S4) -> 10 | W4: =V4-U4 -> 9
A5: Baltimore Ravens | B5: 8 | C5: 4 | D5: 7 | E5: 3 | F5: 3 | G5: 3 | H5: 2 | T5: =AVERAGE(B5:S5) -> 4.2857143 | U5: =MINA(B5:S5) -> 2 | V5: =MAXA(B5:S5) -> 8 | W5: =V5-U5 -> 6
A6: New England Patriots | B6: 1 | C6: 1 | D6: 5 | E6: 6 | F6: 6 | G6: 5 | H6: 7 | T6: =AVERAGE(B6:S6) -> 4.4285714 | U6: =MINA(B6:S6) -> 1 | V6: =MAXA(B6:S6) -> 7 | W6: =V6-U6 -> 6
A7: Philadelphia Eagles | B7: 3 | C7: 8 | D7: 6 | E7: 12 | F7: 8 | G7: 10 | H7: 13 | T7: =AVERAGE(B7:S7) -> 8.5714286 | U7: =MINA(B7:S7) -> 3 | V7: =MAXA(B7:S7) -> 13 | W7: =V7-U7 -> 10
A8: Green Bay Packers | B8: 2 | C8: 6 | D8: 4 | E8: 8 | F8: 12 | G8: 16 | H8: 12 | T8: =AVERAGE(B8:S8) -> 8.5714286 | U8: =MINA(B8:S8) -> 2 | V8: =MAXA(B8:S8) -> 16 | W8: =V8-U8 -> 14
A9: Chicago Bears | B9: 9 | C9: 7 | D9: 10 | E9: 11 | F9: 14 | G9: 8 | H9: 4 | T9: =AVERAGE(B9:S9) -> 9 | U9: =MINA(B9:S9) -> 4 | V9: =MAXA(B9:S9) -> 14 | W9: =V9-U9 -> 10
A10: New York Giants | B10: 6 | C10: 12 | D10: 11 | E10: 10 | F10: 15 | G10: 14 | H10: 5 | T10: =AVERAGE(B10:S10) -> 10.428571 | U10: =MINA(B10:S10) -> 5 | V10: =MAXA(B10:S10) -> 15 | W10: =V10-U10 -> 10
A11: Pittsburgh Steelers | B11: 7 | C11: 10 | D11: 9 | E11: 14 | F11: 17 | G11: 9 | H11: 11 | T11: =AVERAGE(B11:S11) -> 11 | U11: =MINA(B11:S11) -> 7 | V11: =MAXA(B11:S11) -> 17 | W11: =V11-U11 -> 10
A12: Dallas Cowboys | B12: 13 | C12: 11 | D12: 13 | E12: 9 | F12: 13 | G12: 13 | H12: 14 | T12: =AVERAGE(B12:S12) -> 12.285714 | U12: =MINA(B12:S12) -> 9 | V12: =MAXA(B12:S12) -> 14 | W12: =V12-U12 -> 5
A13: Arizona Cardinals | B13: 26 | C13: 25 | D13: 17 | E13: 5 | F13: 5 | G13: 7 | H13: 9 | T13: =AVERAGE(B13:S13) -> 13.428571 | U13: =MINA(B13:S13) -> 5 | V13: =MAXA(B13:S13) -> 26 | W13: =V13-U13 -> 21
... A33: Cleveland Browns | B33: 31 | C33: 32 | D33: 32 | E33: 32 | F33: 32 | G33: 32 | H33: 29 | T33: =AVERAGE(B33:S33) -> 31.428571 | U33: =MINA(B33:S33) -> 29 | V33: =MAXA(B33:S33) -> 32 | W33: =V33-U33 -> 3

Sheet Graziano
A1: Team | B1: Week 1 | C1: Week 2 | D1: Week 3 | E1: Week 4 | F1: Week 5 | G1: Week 6 | H1: Week 7 | I1: Week 8 | J1: Week 9 | K1: Week 10 | L1: Week 11 | M1: Week 12 | N1: Week 13 | O1: Week 14 | P1: Week 15 | Q1: Week 16 | R1: Week 17 | S1: Week 18 | T1: Average | U1: Highest | V1: Lowest | W1: Gap | X1: x
A2: Houston Texans | B2: 6 | C2: 4 | D2: 3 | E2: 1 | F2: 1 | G2: 1 | H2: 3 | T2: =AVERAGE(B2:S2) -> 2.7142857 | U2: =MINA(B2:S2) -> 1 | V2: =MAXA(B2:S2) -> 6 | W2: =V2-U2 -> 5
A3: San Francisco 49ers | B3: 4 | C3: 1 | D3: 1 | E3: 3 | F3: 3 | G3: 3 | H3: 5 | T3: =AVERAGE(B3:S3) -> 2.8571429 | U3: =MINA(B3:S3) -> 1 | V3: =MAXA(B3:S3) -> 5 | W3: =V3-U3 -> 4
A4: Atlanta Falcons | B4: 8 | C4: 7 | D4: 4 | E4: 2 | F4: 2 | G4: 2 | H4: 1 | T4: =AVERAGE(B4:S4) -> 3.7142857 | U4: =MINA(B4:S4) -> 1 | V4: =MAXA(B4:S4) -> 8 | W4: =V4-U4 -> 7
A5: Green Bay Packers | B5: 1 | C5: 2 | D5: 2 | E5: 4 | F5: 4 | G5: 8 | H5: 6 | T5: =AVERAGE(B5:S5) -> 3.8571429 | U5: =MINA(B5:S5) -> 1 | V5: =MAXA(B5:S5) -> 8 | W5: =V5-U5 -> 7
A6: New York Giants | B6: 2 | C6: 5 | D6: 6 | E6: 5 | F6: 6 | G6: 5 | H6: 2 | T6: =AVERAGE(B6:S6) -> 4.4285714 | U6: =MINA(B6:S6) -> 2 | V6: =MAXA(B6:S6) -> 6 | W6: =V6-U6 -> 4
A7: Baltimore Ravens | B7: 7 | C7: 6 | D7: 8 | E7: 6 | F7: 5 | G7: 4 | H7: 4 | T7: =AVERAGE(B7:S7) -> 5.7142857 | U7: =MINA(B7:S7) -> 4 | V7: =MAXA(B7:S7) -> 8 | W7: =V7-U7 -> 4
A8: New England Patriots | B8: 5 | C8: 3 | D8: 5 | E8: 7 | F8: 7 | G8: 6 | H8: 8 | T8: =AVERAGE(B8:S8) -> 5.8571429 | U8: =MINA(B8:S8) -> 3 | V8: =MAXA(B8:S8) -> 8 | W8: =V8-U8 -> 5
A9: Philadelphia Eagles | B9: 3 | C9: 9 | D9: 7 | E9: 9 | F9: 9 | G9: 9 | H9: 10 | T9: =AVERAGE(B9:S9) -> 8 | U9: =MINA(B9:S9) -> 3 | V9: =MAXA(B9:S9) -> 10 | W9: =V9-U9 -> 7
A10: Chicago Bears | B10: 10 | C10: 8 | D10: 10 | E10: 10 | F10: 10 | G10: 7 | H10: 7 | T10: =AVERAGE(B10:S10) -> 8.8571429 | U10: =MINA(B10:S10) -> 7 | V10: =MAXA(B10:S10) -> 10 | W10: =V10-U10 -> 3
A11: Pittsburgh Steelers | B11: 9 | C11: 11 | D11: 9 | E11: 12 | F11: 12 | G11: 12 | H11: 15 | T11: =AVERAGE(B11:S11) -> 11.428571 | U11: =MINA(B11:S11) -> 9 | V11: =MAXA(B11:S11) -> 15 | W11: =V11-U11 -> 6
A12: Denver Broncos | B12: 18 | C12: 12 | D12: 12 | E12: 13 | F12: 11 | G12: 11 | H12: 9 | T12: =AVERAGE(B12:S12) -> 12.285714 | U12: =MINA(B12:S12) -> 9 | V12: =MAXA(B12:S12) -> 18 | W12: =V12-U12 -> 9
A13: Dallas Cowboys | B13: 15 | C13: 10 | D13: 13 | E13: 11 | F13: 13 | G13: 13 | H13: 13 | T13: =AVERAGE(B13:S13) -> 12.571429 | U13: =MINA(B13:S13) -> 10 | V13: =MAXA(B13:S13) -> 15 | W13: =V13-U13 -> 5
... A33: Cleveland Browns | B33: 31 | C33: 30 | D33: 32 | E33: 32 | F33: 32 | G33: 32 | H33: 31 | T33: =AVERAGE(B33:S33) -> 31.428571 | U33: =MINA(B33:S33) -> 30 | V33: =MAXA(B33:S33) -> 32 | W33: =V33-U33 -> 2

Sheet Hensley
A1: Team | B1: Week 1 | C1: Week 2 | D1: Week 3 | E1: Week 4 | F1: Week 5 | G1: Week 6 | H1: Week 7 | I1: Week 8 | J1: Week 9 | K1: Week 10 | L1: Week 11 | M1: Week 12 | N1: Week 13 | O1: Week 14 | P1: Week 15 | Q1: Week 16 | R1: Week 17 | S1: Week 18 | T1: Average | U1: Highest | V1: Lowest | W1: Gap | X1: x
A2: Houston Texans | B2: 5 | C2: 5 | D2: 3 | E2: 2 | F2: 2 | G2: 2 | H2: 3 | T2: =AVERAGE(B2:S2) -> 3.1428571 | U2: =MINA(B2:S2) -> 2 | V2: =MAXA(B2:S2) -> 5 | W2: =V2-U2 -> 3
A3: San Francisco 49ers | B3: 9 | C3: 2 | D3: 1 | E3: 3 | F3: 3 | G3: 3 | H3: 5 | T3: =AVERAGE(B3:S3) -> 3.7142857 | U3: =MINA(B3:S3) -> 1 | V3: =MAXA(B3:S3) -> 9 | W3: =V3-U3 -> 8
A4: Baltimore Ravens | B4: 6 | C4: 3 | D4: 6 | E4: 4 | F4: 4 | G4: 4 | H4: 2 | T4: =AVERAGE(B4:S4) -> 4.1428571 | U4: =MINA(B4:S4) -> 2 | V4: =MAXA(B4:S4) -> 6 | W4: =V4-U4 -> 4
A5: Atlanta Falcons | B5: 15 | C5: 11 | D5: 4 | E5: 1 | F5: 1 | G5: 1 | H5: 1 | T5: =AVERAGE(B5:S5) -> 4.8571429 | U5: =MINA(B5:S5) -> 1 | V5: =MAXA(B5:S5) -> 15 | W5: =V5-U5 -> 14
A6: Green Bay Packers | B6: 1 | C6: 4 | D6: 2 | E6: 8 | F6: 7 | G6: 12 | H6: 7 | T6: =AVERAGE(B6:S6) -> 5.8571429 | U6: =MINA(B6:S6) -> 1 | V6: =MAXA(B6:S6) -> 12 | W6: =V6-U6 -> 11
A7: New York Giants | B7: 3 | C7: 7 | D7: 7 | E7: 5 | F7: 9 | G7: 7 | H7: 4 | T7: =AVERAGE(B7:S7) -> 6 | U7: =MINA(B7:S7) -> 3 | V7: =MAXA(B7:S7) -> 9 | W7: =V7-U7 -> 6
A8: New England Patriots | B8: 2 | C8: 1 | D8: 8 | E8: 13 | F8: 10 | G8: 5 | H8: 8 | T8: =AVERAGE(B8:S8) -> 6.7142857 | U8: =MINA(B8:S8) -> 1 | V8: =MAXA(B8:S8) -> 13 | W8: =V8-U8 -> 12
A9: Philadelphia Eagles | B9: 8 | C9: 9 | D9: 5 | E9: 7 | F9: 6 | G9: 11 | H9: 16 | T9: =AVERAGE(B9:S9) -> 8.8571429 | U9: =MINA(B9:S9) -> 5 | V9: =MAXA(B9:S9) -> 16 | W9: =V9-U9 -> 11
A10: Chicago Bears | B10: 13 | C10: 12 | D10: 14 | E10: 10 | F10: 8 | G10: 6 | H10: 6 | T10: =AVERAGE(B10:S10) -> 9.8571429 | U10: =MINA(B10:S10) -> 6 | V10: =MAXA(B10:S10) -> 14 | W10: =V10-U10 -> 8
A11: Arizona Cardinals | B11: 19 | C11: 18 | D11: 12 | E11: 6 | F11: 5 | G11: 9 | H11: 10 | T11: =AVERAGE(B11:S11) -> 11.285714 | U11: =MINA(B11:S11) -> 5 | V11: =MAXA(B11:S11) -> 19 | W11: =V11-U11 -> 14
A12: Pittsburgh Steelers | B12: 4 | C12: 10 | D12: 10 | E12: 16 | F12: 16 | G12: 10 | H12: 15 | T12: =AVERAGE(B12:S12) -> 11.571429 | U12: =MINA(B12:S12) -> 4 | V12: =MAXA(B12:S12) -> 16 | W12: =V12-U12 -> 12
A13: Dallas Cowboys | B13: 7 | C13: 6 | D13: 13 | E13: 9 | F13: 15 | G13: 16 | H13: 19 | T13: =AVERAGE(B13:S13) -> 12.142857 | U13: =MINA(B13:S13) -> 6 | V13: =MAXA(B13:S13) -> 19 | W13: =V13-U13 -> 13
... A33: Cleveland Browns | B33: 28 | C33: 28 | D33: 29 | E33: 32 | F33: 32 | G33: 32 | H33: 30 | T33: =AVERAGE(B33:S33) -> 30.142857 | U33: =MINA(B33:S33) -> 28 | V33: =MAXA(B33:S33) -> 32 | W33: =V33-U33 -> 4

Sheet Fox
A1: Team | B1: Week 1 | C1: Week 2 | D1: Week 3 | E1: Week 4 | F1: Week 5 | G1: Week 6 | H1: Week 7 | I1: Week 8 | J1: Week 9 | K1: Week 10 | L1: Week 11 | M1: Week 12 | N1: Week 13 | O1: Week 14 | P1: Week 15 | Q1: Week 16 | R1: Week 17 | S1: Week 18 | T1: Average | U1: Highest | V1: Lowest | W1: Gap | X1: x
A2: Houston Texans | B2: 6 | C2: 4 | D2: 2 | E2: 1 | F2: 1 | G2: 1 | H2: 3 | T2: =AVERAGE(B2:S2) -> 2.5714286 | U2: =MINA(B2:S2) -> 1 | V2: =MAXA(B2:S2) -> 6 | W2: =V2-U2 -> 5
A3: Baltimore Ravens | B3: 4 | C3: 3 | D3: 4 | E3: 3 | F3: 3 | G3: 3 | H3: 4 | T3: =AVERAGE(B3:S3) -> 3.4285714 | U3: =MINA(B3:S3) -> 3 | V3: =MAXA(B3:S3) -> 4 | W3: =V3-U3 -> 1
A4: San Francisco 49ers | B4: 5 | C4: 2 | D4: 1 | E4: 6 | F4: 5 | G4: 4 | H4: 6 | T4: =AVERAGE(B4:S4) -> 4.1428571 | U4: =MINA(B4:S4) -> 1 | V4: =MAXA(B4:S4) -> 6 | W4: =V4-U4 -> 5
A5: Atlanta Falcons | B5: 12 | C5: 9 | D5: 3 | E5: 2 | F5: 2 | G5: 2 | H5: 1 | T5: =AVERAGE(B5:S5) -> 4.4285714 | U5: =MINA(B5:S5) -> 1 | V5: =MAXA(B5:S5) -> 12 | W5: =V5-U5 -> 11
A6: New England Patriots | B6: 2 | C6: 1 | D6: 7 | E6: 7 | F6: 6 | G6: 5 | H6: 8 | T6: =AVERAGE(B6:S6) -> 5.1428571 | U6: =MINA(B6:S6) -> 1 | V6: =MAXA(B6:S6) -> 8 | W6: =V6-U6 -> 7
A7: New York Giants | B7: 1 | C7: 5 | D7: 5 | E7: 4 | F7: 12 | G7: 7 | H7: 2 | T7: =AVERAGE(B7:S7) -> 5.1428571 | U7: =MINA(B7:S7) -> 1 | V7: =MAXA(B7:S7) -> 12 | W7: =V7-U7 -> 11
A8: Green Bay Packers | B8: 3 | C8: 6 | D8: 6 | E8: 9 | F8: 8 | G8: 14 | H8: 9 | T8: =AVERAGE(B8:S8) -> 7.8571429 | U8: =MINA(B8:S8) -> 3 | V8: =MAXA(B8:S8) -> 14 | W8: =V8-U8 -> 11
A9: Chicago Bears | B9: 10 | C9: 8 | D9: 13 | E9: 8 | F9: 9 | G9: 6 | H9: 5 | T9: =AVERAGE(B9:S9) -> 8.4285714 | U9: =MINA(B9:S9) -> 5 | V9: =MAXA(B9:S9) -> 13 | W9: =V9-U9 -> 8
A10: Philadelphia Eagles | B10: 9 | C10: 14 | D10: 10 | E10: 11 | F10: 7 | G10: 11 | H10: 12 | T10: =AVERAGE(B10:S10) -> 10.571429 | U10: =MINA(B10:S10) -> 7 | V10: =MAXA(B10:S10) -> 14 | W10: =V10-U10 -> 7
A11: San Diego Chargers | B11: 13 | C11: 10 | D11: 8 | E11: 10 | F11: 10 | G11: 13 | H11: 15 | T11: =AVERAGE(B11:S11) -> 11.285714 | U11: =MINA(B11:S11) -> 8 | V11: =MAXA(B11:S11) -> 15 | W11: =V11-U11 -> 7
A12: Arizona Cardinals | B12: 19 | C12: 19 | D12: 12 | E12: 5 | F12: 4 | G12: 10 | H12: 11 | T12: =AVERAGE(B12:S12) -> 11.428571 | U12: =MINA(B12:S12) -> 4 | V12: =MAXA(B12:S12) -> 19 | W12: =V12-U12 -> 15
A13: Denver Broncos | B13: 8 | C13: 7 | D13: 9 | E13: 17 | F13: 14 | G13: 16 | H13: 14 | T13: =AVERAGE(B13:S13) -> 12.142857 | U13: =MINA(B13:S13) -> 7 | V13: =MAXA(B13:S13) -> 17 | W13: =V13-U13 -> 10
... A33: Cleveland Browns | B33: 30 | C33: 31 | D33: 32 | E33: 32 | F33: 32 | G33: 32 | H33: 30 | T33: =AVERAGE(B33:S33) -> 31.285714 | U33: =MINA(B33:S33) -> 30 | V33: =MAXA(B33:S33) -> 32 | W33: =V33-U33 -> 2

Sheet powerflaws
Z1: =SUM(Z3:Z34) -> 30
A2: NFL Team | B2: Conf | C2: Div | D2: W | E2: L | F2: T | G2: Pct | H2: PF | I2: PA | J2: Net Pts | K2: TD | L2: Home | M2: Road | N2: Div | O2: Pct | P2: Conf | Q2: Pct | R2: Non-Conf | S2: Streak | T2: Last 5 | U2: PPG | V2: PPG Allowed | W2: PPG Differential | X2: Total Games Played | Y2: Power Ranking | Z2: Higher Ranked Teams Beaten | AA2: Team Code | AB2: Beat | AC2: Beat | AD2: Beat | AE2: Beat | AF2: Beat | AG2: Beat | AH2: Beat | AI2: Beat | AJ2: Beat | AK2: Beat | AL2: Beat | AM2: Beat | AN2: Beat | AO2: Beat | AP2: Beat | AQ2: Beat | AR2: Beat | AS2: Team | AT2: Wins | AU2: Losses
A3: Atlanta Falcons | B3: NFC | C3: NCS | D3: 6 | E3: 0 | F3: 0 | G3: 1 | H3: 171 | I3: 113 | J3: 58 | K3: 19 | L3: 3-0 | M3: 3-0 | N3: 1-0 | O3: 1 | P3: 2-0 | Q3: 1 | R3: 4-0 | S3: 6W | T3: 5-0 | U3: =H3/(D3+E3+F3) -> 28.5 | V3: =I3/(D3+E3+F3) -> 18.833333 | W3: =U3-V3 -> 9.6666667 | X3: =SUM(D3:F3) -> 6 | Y3: 1 | Z3: 0 | AA3: =VLOOKUP(A3,howfared!$A$2:$B$33,2,FALSE) -> ATL | AB3: =VLOOKUP(AA3,howfared!$B$2:$AH$33,2,FALSE) -> KC | AC3: =VLOOKUP(AA3,howfared!$B$2:$AH$33,3,FALSE) -> DEN | AD3: =VLOOKUP(AA3,howfared!$B$2:$AH$33,4,FALSE) -> SD | AE3: =VLOOKUP(AA3,howfared!$B$2:$AH$33,5,FALSE) -> CAR | AF3: =VLOOKUP(AA3,howfared!$B$2:$AH$33,6,FALSE) -> WAS | AG3: =VLOOKUP(AA3,howfared!$B$2:$AH$33,7,FALSE) -> OAK | AH3: =VLOOKUP(AA3,howfared!$B$2:$AH$33,8,FALSE) -> 0 | AI3: =VLOOKUP(AA3,howfared!$B$2:$AH$33,9,FALSE) -> 0 | AJ3: =VLOOKUP(AA3,howfared!$B$2:$AH$33,10,FALSE) -> 0 | AK3: =VLOOKUP(AA3,howfared!$B$2:$AH$33,11,FALSE) -> 0 | AL3: =VLOOKUP(AA3,howfared!$B$2:$AH$33,12,FALSE) -> 0 | AM3: =VLOOKUP(AA3,howfared!$B$2:$AH$33,13,FALSE) -> 0 | AN3: =VLOOKUP(AA3,howfared!$B$2:$AH$33,14,FALSE) -> 0 | AO3: =VLOOKUP(AA3,howfared!$B$2:$AH$33,15,FALSE) -> 0 | AP3: =VLOOKUP(AA3,howfared!$B$2:$AH$33,16,FALSE) -> 0 | AQ3: =VLOOKUP(AA3,howfared!$B$2:$AH$33,17,FALSE) -> 0 | AR3: =VLOOKUP(AA3,howfared!$B$2:$AH$33,18,FALSE) -> 0 | AS3: =AA3 -> ATL | AT3: =D3 -> 6 | AU3: =E3 -> 0
A4: Houston Texans | B4: NFC | C4: ACS | D4: 5 | E4: 1 | F4: 0 | G4: 0.833 | H4: 173 | I4: 115 | J4: 58 | K4: 20 | L4: 2-1 | M4: 3-0 | N4: 2-0 | O4: 1 | P4: 5-0 | Q4: 1 | R4: 0-1 | S4: 1L | T4: 4-1 | U4: =H4/(D4+E4+F4) -> 28.833333 | V4: =I4/(D4+E4+F4) -> 19.166667 | W4: =U4-V4 -> 9.6666667 | X4: =SUM(D4:F4) -> 6 | Y4: 2 | Z4: =COUNTIF(AA$3:AA3,AB4)+COUNTIF(AA$3:AA4,AC4)+COUNTIF(AA$3:AA4,AD4)+COUNTIF(AA$3:AA4,AE4)+COUNTIF(AA$3:AA4,AF4)+COUNTIF(AA$3:AA4,AG4)+COUNTIF(AA$3:AA4,AH4)+COUNTIF(AA$3:AA4,AI4)+COUNTIF(AA$3:AA4,AJ4)+COUNTIF(AA$3:AA4,AK4)+COUNTIF(AA$3:AA4,AL4)+COUNTIF(AA$3:AA4,AM4)+COUNTIF(AA$3:AA4,AN4)+COUNTIF(AA$3:AA4,AO4)+COUNTIF(AA$3:AA4,AP4)+COUNTIF(AA$3:AA4,AQ4)+COUNTIF(AA$3:AA4,AR4) -> 0 | AA4: =VLOOKUP(A4,howfared!$A$2:$B$33,2,FALSE) -> HOU | AB4: =VLOOKUP(AA4,howfared!$B$2:$AH$33,2,FALSE) -> MIA | AC4: =VLOOKUP(AA4,howfared!$B$2:$AH$33,3,FALSE) -> JAC | AD4: =VLOOKUP(AA4,howfared!$B$2:$AH$33,4,FALSE) -> DEN | AE4: =VLOOKUP(AA4,howfared!$B$2:$AH$33,5,FALSE) -> TEN | AF4: =VLOOKUP(AA4,howfared!$B$2:$AH$33,6,FALSE) -> NYJ | AG4: =VLOOKUP(AA4,howfared!$B$2:$AH$33,7,FALSE) -> 0 | AH4: =VLOOKUP(AA4,howfared!$B$2:$AH$33,8,FALSE) -> 0 | AI4: =VLOOKUP(AA4,howfared!$B$2:$AH$33,9,FALSE) -> 0 | AJ4: =VLOOKUP(AA4,howfared!$B$2:$AH$33,10,FALSE) -> 0 | AK4: =VLOOKUP(AA4,howfared!$B$2:$AH$33,11,FALSE) -> 0 | AL4: =VLOOKUP(AA4,howfared!$B$2:$AH$33,12,FALSE) -> 0 | AM4: =VLOOKUP(AA4,howfared!$B$2:$AH$33,13,FALSE) -> 0 | AN4: =VLOOKUP(AA4,howfared!$B$2:$AH$33,14,FALSE) -> 0 | AO4: =VLOOKUP(AA4,howfared!$B$2:$AH$33,15,FALSE) -> 0 | AP4: =VLOOKUP(AA4,howfared!$B$2:$AH$33,16,FALSE) -> 0 | AQ4: =VLOOKUP(AA4,howfared!$B$2:$AH$33,17,FALSE) -> 0 | AR4: =VLOOKUP(AA4,howfared!$B$2:$AH$33,18,FALSE) -> 0 | AS4: =AA4 -> HOU | AT4: =D4 -> 5 | AU4: =E4 -> 1
A5: New York Giants | B5: NFC | C5: NCE | D5: 4 | E5: 2 | F5: 0 | G5: 0.667 | H5: 178 | I5: 114 | J5: 64 | K5: 18 | L5: 2-1 | M5: 2-1 | N5: 0-2 | O5: 0 | P5: 3-2 | Q5: 0.6 | R5: 1-0 | S5: 2W | T5: 4-1 | U5: =H5/(D5+E5+F5) -> 29.666667 | V5: =I5/(D5+E5+F5) -> 19 | W5: =U5-V5 -> 10.666667 | X5: =SUM(D5:F5) -> 6 | Y5: 3 | Z5: =COUNTIF(AA$3:AA4,AB5)+COUNTIF(AA$3:AA5,AC5)+COUNTIF(AA$3:AA5,AD5)+COUNTIF(AA$3:AA5,AE5)+COUNTIF(AA$3:AA5,AF5)+COUNTIF(AA$3:AA5,AG5)+COUNTIF(AA$3:AA5,AH5)+COUNTIF(AA$3:AA5,AI5)+COUNTIF(AA$3:AA5,AJ5)+COUNTIF(AA$3:AA5,AK5)+COUNTIF(AA$3:AA5,AL5)+COUNTIF(AA$3:AA5,AM5)+COUNTIF(AA$3:AA5,AN5)+COUNTIF(AA$3:AA5,AO5)+COUNTIF(AA$3:AA5,AP5)+COUNTIF(AA$3:AA5,AQ5)+COUNTIF(AA$3:AA5,AR5) -> 0 | AA5: =VLOOKUP(A5,howfared!$A$2:$B$33,2,FALSE) -> NYG | AB5: =VLOOKUP(AA5,howfared!$B$2:$AH$33,2,FALSE) -> 0 | AC5: =VLOOKUP(AA5,howfared!$B$2:$AH$33,3,FALSE) -> TB | AD5: =VLOOKUP(AA5,howfared!$B$2:$AH$33,4,FALSE) -> CAR | AE5: =VLOOKUP(AA5,howfared!$B$2:$AH$33,5,FALSE) -> 0 | AF5: =VLOOKUP(AA5,howfared!$B$2:$AH$33,6,FALSE) -> CLE | AG5: =VLOOKUP(AA5,howfared!$B$2:$AH$33,7,FALSE) -> SF | AH5: =VLOOKUP(AA5,howfared!$B$2:$AH$33,8,FALSE) -> 0 | AI5: =VLOOKUP(AA5,howfared!$B$2:$AH$33,9,FALSE) -> 0 | AJ5: =VLOOKUP(AA5,howfared!$B$2:$AH$33,10,FALSE) -> 0 | AK5: =VLOOKUP(AA5,howfared!$B$2:$AH$33,11,FALSE) -> 0 | AL5: =VLOOKUP(AA5,howfared!$B$2:$AH$33,12,FALSE) -> 0 | AM5: =VLOOKUP(AA5,howfared!$B$2:$AH$33,13,FALSE) -> 0 | AN5: =VLOOKUP(AA5,howfared!$B$2:$AH$33,14,FALSE) -> 0 | AO5: =VLOOKUP(AA5,howfared!$B$2:$AH$33,15,FALSE) -> 0 | AP5: =VLOOKUP(AA5,howfared!$B$2:$AH$33,16,FALSE) -> 0 | AQ5: =VLOOKUP(AA5,howfared!$B$2:$AH$33,17,FALSE) -> 0 | AR5: =VLOOKUP(AA5,howfared!$B$2:$AH$33,18,FALSE) -> 0 | AS5: =AA5 -> NYG | AT5: =D5 -> 4 | AU5: =E5 -> 2
A6: Baltimore Ravens | B6: AFC | C6: ACN | D6: 5 | E6: 1 | F6: 0 | G6: 0.833 | H6: 161 | I6: 118 | J6: 43 | K6: 18 | L6: 4-0 | M6: 1-1 | N6: 2-0 | O6: 1 | P6: 4-0 | Q6: 1 | R6: 1-1 | S6: 4W | T6: 4-1 | U6: =H6/(D6+E6+F6) -> 26.833333 | V6: =I6/(D6+E6+F6) -> 19.666667 | W6: =U6-V6 -> 7.1666667 | X6: =SUM(D6:F6) -> 6 | Y6: 4 | Z6: =COUNTIF(AA$3:AA5,AB6)+COUNTIF(AA$3:AA6,AC6)+COUNTIF(AA$3:AA6,AD6)+COUNTIF(AA$3:AA6,AE6)+COUNTIF(AA$3:AA6,AF6)+COUNTIF(AA$3:AA6,AG6)+COUNTIF(AA$3:AA6,AH6)+COUNTIF(AA$3:AA6,AI6)+COUNTIF(AA$3:AA6,AJ6)+COUNTIF(AA$3:AA6,AK6)+COUNTIF(AA$3:AA6,AL6)+COUNTIF(AA$3:AA6,AM6)+COUNTIF(AA$3:AA6,AN6)+COUNTIF(AA$3:AA6,AO6)+COUNTIF(AA$3:AA6,AP6)+COUNTIF(AA$3:AA6,AQ6)+COUNTIF(AA$3:AA6,AR6) -> 0 | AA6: =VLOOKUP(A6,howfared!$A$2:$B$33,2,FALSE) -> BAL | AB6: =VLOOKUP(AA6,howfared!$B$2:$AH$33,2,FALSE) -> CIN | AC6: =VLOOKUP(AA6,howfared!$B$2:$AH$33,3,FALSE) -> 0 | AD6: =VLOOKUP(AA6,howfared!$B$2:$AH$33,4,FALSE) -> NE | AE6: =VLOOKUP(AA6,howfared!$B$2:$AH$33,5,FALSE) -> CLE | AF6: =VLOOKUP(AA6,howfared!$B$2:$AH$33,6,FALSE) -> KC | AG6: =VLOOKUP(AA6,howfared!$B$2:$AH$33,7,FALSE) -> DAL | AH6: =VLOOKUP(AA6,howfared!$B$2:$AH$33,8,FALSE) -> 0 | AI6: =VLOOKUP(AA6,howfared!$B$2:$AH$33,9,FALSE) -> 0 | AJ6: =VLOOKUP(AA6,howfared!$B$2:$AH$33,10,FALSE) -> 0 | AK6: =VLOOKUP(AA6,howfared!$B$2:$AH$33,11,FALSE) -> 0 | AL6: =VLOOKUP(AA6,howfared!$B$2:$AH$33,12,FALSE) -> 0 | AM6: =VLOOKUP(AA6,howfared!$B$2:$AH$33,13,FALSE) -> 0 | AN6: =VLOOKUP(AA6,howfared!$B$2:$AH$33,14,FALSE) -> 0 | AO6: =VLOOKUP(AA6,howfared!$B$2:$AH$33,15,FALSE) -> 0 | AP6: =VLOOKUP(AA6,howfared!$B$2:$AH$33,16,FALSE) -> 0 | AQ6: =VLOOKUP(AA6,howfared!$B$2:$AH$33,17,FALSE) -> 0 | AR6: =VLOOKUP(AA6,howfared!$B$2:$AH$33,18,FALSE) -> 0 | AS6: =AA6 -> BAL | AT6: =D6 -> 5 | AU6: =E6 -> 1
A7: San Francisco 49ers | B7: NFC | C7: NCW | D7: 4 | E7: 2 | F7: 0 | G7: 0.667 | H7: 152 | I7: 94 | J7: 58 | K7: 17 | L7: 2-1 | M7: 2-1 | N7: 0-0 | O7: 0 | P7: 2-2 | Q7: 0.5 | R7: 2-0 | S7: 1L | T7: 3-2 | U7: =H7/(D7+E7+F7) -> 25.333333 | V7: =I7/(D7+E7+F7) -> 15.666667 | W7: =U7-V7 -> 9.6666667 | X7: =SUM(D7:F7) -> 6 | Y7: 5 | Z7: =COUNTIF(AA$3:AA6,AB7)+COUNTIF(AA$3:AA7,AC7)+COUNTIF(AA$3:AA7,AD7)+COUNTIF(AA$3:AA7,AE7)+COUNTIF(AA$3:AA7,AF7)+COUNTIF(AA$3:AA7,AG7)+COUNTIF(AA$3:AA7,AH7)+COUNTIF(AA$3:AA7,AI7)+COUNTIF(AA$3:AA7,AJ7)+COUNTIF(AA$3:AA7,AK7)+COUNTIF(AA$3:AA7,AL7)+COUNTIF(AA$3:AA7,AM7)+COUNTIF(AA$3:AA7,AN7)+COUNTIF(AA$3:AA7,AO7)+COUNTIF(AA$3:AA7,AP7)+COUNTIF(AA$3:AA7,AQ7)+COUNTIF(AA$3:AA7,AR7) -> 0 | AA7: =VLOOKUP(A7,howfared!$A$2:$B$33,2,FALSE) -> SF | AB7: =VLOOKUP(AA7,howfared!$B$2:$AH$33,2,FALSE) -> GB | AC7: =VLOOKUP(AA7,howfared!$B$2:$AH$33,3,FALSE) -> DET | AD7: =VLOOKUP(AA7,howfared!$B$2:$AH$33,4,FALSE) -> 0 | AE7: =VLOOKUP(AA7,howfared!$B$2:$AH$33,5,FALSE) -> NYJ | AF7: =VLOOKUP(AA7,howfared!$B$2:$AH$33,6,FALSE) -> BUF | AG7: =VLOOKUP(AA7,howfared!$B$2:$AH$33,7,FALSE) -> 0 | AH7: =VLOOKUP(AA7,howfared!$B$2:$AH$33,8,FALSE) -> 0 | AI7: =VLOOKUP(AA7,howfared!$B$2:$AH$33,9,FALSE) -> 0 | AJ7: =VLOOKUP(AA7,howfared!$B$2:$AH$33,10,FALSE) -> 0 | AK7: =VLOOKUP(AA7,howfared!$B$2:$AH$33,11,FALSE) -> 0 | AL7: =VLOOKUP(AA7,howfared!$B$2:$AH$33,12,FALSE) -> 0 | AM7: =VLOOKUP(AA7,howfared!$B$2:$AH$33,13,FALSE) -> 0 | AN7: =VLOOKUP(AA7,howfared!$B$2:$AH$33,14,FALSE) -> 0 | AO7: =VLOOKUP(AA7,howfared!$B$2:$AH$33,15,FALSE) -> 0 | AP7: =VLOOKUP(AA7,howfared!$B$2:$AH$33,16,FALSE) -> 0 | AQ7: =VLOOKUP(AA7,howfared!$B$2:$AH$33,17,FALSE) -> 0 | AR7: =VLOOKUP(AA7,howfared!$B$2:$AH$33,18,FALSE) -> 0 | AS7: =AA7 -> SF | AT7: =D7 -> 4 | AU7: =E7 -> 2
A8: Chicago Bears | B8: AFC | C8: NCN | D8: 4 | E8: 1 | F8: 0 | G8: 0.8 | H8: 149 | I8: 71 | J8: 78 | K8: 17 | L8: 2-0 | M8: 2-1 | N8: 0-1 | O8: 0 | P8: 2-1 | Q8: 0.667 | R8: 2-0 | S8: 3W | T8: 4-1 | U8: =H8/(D8+E8+F8) -> 29.8 | V8: =I8/(D8+E8+F8) -> 14.2 | W8: =U8-V8 -> 15.6 | X8: =SUM(D8:F8) -> 5 | Y8: 6 | Z8: =COUNTIF(AA$3:AA7,AB8)+COUNTIF(AA$3:AA8,AC8)+COUNTIF(AA$3:AA8,AD8)+COUNTIF(AA$3:AA8,AE8)+COUNTIF(AA$3:AA8,AF8)+COUNTIF(AA$3:AA8,AG8)+COUNTIF(AA$3:AA8,AH8)+COUNTIF(AA$3:AA8,AI8)+COUNTIF(AA$3:AA8,AJ8)+COUNTIF(AA$3:AA8,AK8)+COUNTIF(AA$3:AA8,AL8)+COUNTIF(AA$3:AA8,AM8)+COUNTIF(AA$3:AA8,AN8)+COUNTIF(AA$3:AA8,AO8)+COUNTIF(AA$3:AA8,AP8)+COUNTIF(AA$3:AA8,AQ8)+COUNTIF(AA$3:AA8,AR8) -> 0 | AA8: =VLOOKUP(A8,howfared!$A$2:$B$33,2,FALSE) -> CHI | AB8: =VLOOKUP(AA8,howfared!$B$2:$AH$33,2,FALSE) -> IND | AC8: =VLOOKUP(AA8,howfared!$B$2:$AH$33,3,FALSE) -> 0 | AD8: =VLOOKUP(AA8,howfared!$B$2:$AH$33,4,FALSE) -> STL | AE8: =VLOOKUP(AA8,howfared!$B$2:$AH$33,5,FALSE) -> DAL | AF8: =VLOOKUP(AA8,howfared!$B$2:$AH$33,6,FALSE) -> JAC | AG8: =VLOOKUP(AA8,howfared!$B$2:$AH$33,7,FALSE) -> 0 | AH8: =VLOOKUP(AA8,howfared!$B$2:$AH$33,8,FALSE) -> 0 | AI8: =VLOOKUP(AA8,howfared!$B$2:$AH$33,9,FALSE) -> 0 | AJ8: =VLOOKUP(AA8,howfared!$B$2:$AH$33,10,FALSE) -> 0 | AK8: =VLOOKUP(AA8,howfared!$B$2:$AH$33,11,FALSE) -> 0 | AL8: =VLOOKUP(AA8,howfared!$B$2:$AH$33,12,FALSE) -> 0 | AM8: =VLOOKUP(AA8,howfared!$B$2:$AH$33,13,FALSE) -> 0 | AN8: =VLOOKUP(AA8,howfared!$B$2:$AH$33,14,FALSE) -> 0 | AO8: =VLOOKUP(AA8,howfared!$B$2:$AH$33,15,FALSE) -> 0 | AP8: =VLOOKUP(AA8,howfared!$B$2:$AH$33,16,FALSE) -> 0 | AQ8: =VLOOKUP(AA8,howfared!$B$2:$AH$33,17,FALSE) -> 0 | AR8: =VLOOKUP(AA8,howfared!$B$2:$AH$33,18,FALSE) -> 0 | AS8: =AA8 -> CHI | AT8: =D8 -> 4 | AU8: =E8 -> 1
A9: New England Patriots | B9: AFC | C9: ACE | D9: 3 | E9: 3 | F9: 0 | G9: 0.5 | H9: 188 | I9: 137 | J9: 51 | K9: 21 | L9: 1-1 | M9: 2-2 | N9: 1-0 | O9: 1 | P9: 3-1 | Q9: 0.75 | R9: 0-2 | S9: 1L | T9: 2-3 | U9: =H9/(D9+E9+F9) -> 31.333333 | V9: =I9/(D9+E9+F9) -> 22.833333 | W9: =U9-V9 -> 8.5 | X9: =SUM(D9:F9) -> 6 | Y9: 7 | Z9: =COUNTIF(AA$3:AA8,AB9)+COUNTIF(AA$3:AA9,AC9)+COUNTIF(AA$3:AA9,AD9)+COUNTIF(AA$3:AA9,AE9)+COUNTIF(AA$3:AA9,AF9)+COUNTIF(AA$3:AA9,AG9)+COUNTIF(AA$3:AA9,AH9)+COUNTIF(AA$3:AA9,AI9)+COUNTIF(AA$3:AA9,AJ9)+COUNTIF(AA$3:AA9,AK9)+COUNTIF(AA$3:AA9,AL9)+COUNTIF(AA$3:AA9,AM9)+COUNTIF(AA$3:AA9,AN9)+COUNTIF(AA$3:AA9,AO9)+COUNTIF(AA$3:AA9,AP9)+COUNTIF(AA$3:AA9,AQ9)+COUNTIF(AA$3:AA9,AR9) -> 0 | AA9: =VLOOKUP(A9,howfared!$A$2:$B$33,2,FALSE) -> NE | AB9: =VLOOKUP(AA9,howfared!$B$2:$AH$33,2,FALSE) -> TEN | AC9: =VLOOKUP(AA9,howfared!$B$2:$AH$33,3,FALSE) -> 0 | AD9: =VLOOKUP(AA9,howfared!$B$2:$AH$33,4,FALSE) -> 0 | AE9: =VLOOKUP(AA9,howfared!$B$2:$AH$33,5,FALSE) -> BUF | AF9: =VLOOKUP(AA9,howfared!$B$2:$AH$33,6,FALSE) -> DEN | AG9: =VLOOKUP(AA9,howfared!$B$2:$AH$33,7,FALSE) -> 0 | AH9: =VLOOKUP(AA9,howfared!$B$2:$AH$33,8,FALSE) -> 0 | AI9: =VLOOKUP(AA9,howfared!$B$2:$AH$33,9,FALSE) -> 0 | AJ9: =VLOOKUP(AA9,howfared!$B$2:$AH$33,10,FALSE) -> 0 | AK9: =VLOOKUP(AA9,howfared!$B$2:$AH$33,11,FALSE) -> 0 | AL9: =VLOOKUP(AA9,howfared!$B$2:$AH$33,12,FALSE) -> 0 | AM9: =VLOOKUP(AA9,howfared!$B$2:$AH$33,13,FALSE) -> 0 | AN9: =VLOOKUP(AA9,howfared!$B$2:$AH$33,14,FALSE) -> 0 | AO9: =VLOOKUP(AA9,howfared!$B$2:$AH$33,15,FALSE) -> 0 | AP9: =VLOOKUP(AA9,howfared!$B$2:$AH$33,16,FALSE) -> 0 | AQ9: =VLOOKUP(AA9,howfared!$B$2:$AH$33,17,FALSE) -> 0 | AR9: =VLOOKUP(AA9,howfared!$B$2:$AH$33,18,FALSE) -> 0 | AS9: =AA9 -> NE | AT9: =D9 -> 3 | AU9: =E9 -> 3
A10: Green Bay Packers | B10: NFC | C10: NCN | D10: 3 | E10: 3 | F10: 0 | G10: 0.5 | H10: 154 | I10: 135 | J10: 19 | K10: 20 | L10: 2-1 | M10: 1-2 | N10: 1-0 | O10: 1 | P10: 2-2 | Q10: 0.5 | R10: 1-1 | S10: 1W | T10: 3-2 | U10: =H10/(D10+E10+F10) -> 25.666667 | V10: =I10/(D10+E10+F10) -> 22.5 | W10: =U10-V10 -> 3.1666667 | X10: =SUM(D10:F10) -> 6 | Y10: 8 | Z10: =COUNTIF(AA$3:AA9,AB10)+COUNTIF(AA$3:AA10,AC10)+COUNTIF(AA$3:AA10,AD10)+COUNTIF(AA$3:AA10,AE10)+COUNTIF(AA$3:AA10,AF10)+COUNTIF(AA$3:AA10,AG10)+COUNTIF(AA$3:AA10,AH10)+COUNTIF(AA$3:AA10,AI10)+COUNTIF(AA$3:AA10,AJ10)+COUNTIF(AA$3:AA10,AK10)+COUNTIF(AA$3:AA10,AL10)+COUNTIF(AA$3:AA10,AM10)+COUNTIF(AA$3:AA10,AN10)+COUNTIF(AA$3:AA10,AO10)+COUNTIF(AA$3:AA10,AP10)+COUNTIF(AA$3:AA10,AQ10)+COUNTIF(AA$3:AA10,AR10) -> 2 | AA10: =VLOOKUP(A10,howfared!$A$2:$B$33,2,FALSE) -> GB | AB10: =VLOOKUP(AA10,howfared!$B$2:$AH$33,2,FALSE) -> 0 | AC10: =VLOOKUP(AA10,howfared!$B$2:$AH$33,3,FALSE) -> CHI | AD10: =VLOOKUP(AA10,howfared!$B$2:$AH$33,4,FALSE) -> 0 | AE10: =VLOOKUP(AA10,howfared!$B$2:$AH$33,5,FALSE) -> NO | AF10: =VLOOKUP(AA10,howfared!$B$2:$AH$33,6,FALSE) -> 0 | AG10: =VLOOKUP(AA10,howfared!$B$2:$AH$33,7,FALSE) -> HOU | AH10: =VLOOKUP(AA10,howfared!$B$2:$AH$33,8,FALSE) -> 0 | AI10: =VLOOKUP(AA10,howfared!$B$2:$AH$33,9,FALSE) -> 0 | AJ10: =VLOOKUP(AA10,howfared!$B$2:$AH$33,10,FALSE) -> 0 | AK10: =VLOOKUP(AA10,howfared!$B$2:$AH$33,11,FALSE) -> 0 | AL10: =VLOOKUP(AA10,howfared!$B$2:$AH$33,12,FALSE) -> 0 | AM10: =VLOOKUP(AA10,howfared!$B$2:$AH$33,13,FALSE) -> 0 | AN10: =VLOOKUP(AA10,howfared!$B$2:$AH$33,14,FALSE) -> 0 | AO10: =VLOOKUP(AA10,howfared!$B$2:$AH$33,15,FALSE) -> 0 | AP10: =VLOOKUP(AA10,howfared!$B$2:$AH$33,16,FALSE) -> 0 | AQ10: =VLOOKUP(AA10,howfared!$B$2:$AH$33,17,FALSE) -> 0 | AR10: =VLOOKUP(AA10,howfared!$B$2:$AH$33,18,FALSE) -> 0 | AS10: =AA10 -> GB | AT10: =D10 -> 3 | AU10: =E10 -> 3
A11: Seattle Seahawks | B11: AFC | C11: NCW | D11: 4 | E11: 2 | F11: 0 | G11: 0.667 | H11: 110 | I11: 93 | J11: 17 | K11: 11 | L11: 3-0 | M11: 1-2 | N11: 0-2 | O11: 0 | P11: 3-2 | Q11: 0.6 | R11: 1-0 | S11: 2W | T11: 4-1 | U11: =H11/(D11+E11+F11) -> 18.333333 | V11: =I11/(D11+E11+F11) -> 15.5 | W11: =U11-V11 -> 2.8333333 | X11: =SUM(D11:F11) -> 6 | Y11: 9 | Z11: =COUNTIF(AA$3:AA10,AB11)+COUNTIF(AA$3:AA11,AC11)+COUNTIF(AA$3:AA11,AD11)+COUNTIF(AA$3:AA11,AE11)+COUNTIF(AA$3:AA11,AF11)+COUNTIF(AA$3:AA11,AG11)+COUNTIF(AA$3:AA11,AH11)+COUNTIF(AA$3:AA11,AI11)+COUNTIF(AA$3:AA11,AJ11)+COUNTIF(AA$3:AA11,AK11)+COUNTIF(AA$3:AA11,AL11)+COUNTIF(AA$3:AA11,AM11)+COUNTIF(AA$3:AA11,AN11)+COUNTIF(AA$3:AA11,AO11)+COUNTIF(AA$3:AA11,AP11)+COUNTIF(AA$3:AA11,AQ11)+COUNTIF(AA$3:AA11,AR11) -> 2 | AA11: =VLOOKUP(A11,howfared!$A$2:$B$33,2,FALSE) -> SEA | AB11: =VLOOKUP(AA11,howfared!$B$2:$AH$33,2,FALSE) -> 0 | AC11: =VLOOKUP(AA11,howfared!$B$2:$AH$33,3,FALSE) -> DAL | AD11: =VLOOKUP(AA11,howfared!$B$2:$AH$33,4,FALSE) -> GB | AE11: =VLOOKUP(AA11,howfared!$B$2:$AH$33,5,FALSE) -> 0 | AF11: =VLOOKUP(AA11,howfared!$B$2:$AH$33,6,FALSE) -> CAR | AG11: =VLOOKUP(AA11,howfared!$B$2:$AH$33,7,FALSE) -> NE | AH11: =VLOOKUP(AA11,howfared!$B$2:$AH$33,8,FALSE) -> 0 | AI11: =VLOOKUP(AA11,howfared!$B$2:$AH$33,9,FALSE) -> 0 | AJ11: =VLOOKUP(AA11,howfared!$B$2:$AH$33,10,FALSE) -> 0 | AK11: =VLOOKUP(AA11,howfared!$B$2:$AH$33,11,FALSE) -> 0 | AL11: =VLOOKUP(AA11,howfared!$B$2:$AH$33,12,FALSE) -> 0 | AM11: =VLOOKUP(AA11,howfared!$B$2:$AH$33,13,FALSE) -> 0 | AN11: =VLOOKUP(AA11,howfared!$B$2:$AH$33,14,FALSE) -> 0 | AO11: =VLOOKUP(AA11,howfared!$B$2:$AH$33,15,FALSE) -> 0 | AP11: =VLOOKUP(AA11,howfared!$B$2:$AH$33,16,FALSE) -> 0 | AQ11: =VLOOKUP(AA11,howfared!$B$2:$AH$33,17,FALSE) -> 0 | AR11: =VLOOKUP(AA11,howfared!$B$2:$AH$33,18,FALSE) -> 0 | AS11: =AA11 -> SEA | AT11: =D11 -> 4 | AU11: =E11 -> 2
A12: Minnesota Vikings | B12: NFC | C12: NCN | D12: 4 | E12: 2 | F12: 0 | G12: 0.667 | H12: 146 | I12: 117 | J12: 29 | K12: 14 | L12: 3-0 | M12: 1-2 | N12: 1-0 | O12: 1 | P12: 2-1 | Q12: 0.667 | R12: 2-1 | S12: 1L | T12: 3-2 | U12: =H12/(D12+E12+F12) -> 24.333333 | V12: =I12/(D12+E12+F12) -> 19.5 | W12: =U12-V12 -> 4.8333333 | X12: =SUM(D12:F12) -> 6 | Y12: 10 | Z12: =COUNTIF(AA$3:AA11,AB12)+COUNTIF(AA$3:AA12,AC12)+COUNTIF(AA$3:AA12,AD12)+COUNTIF(AA$3:AA12,AE12)+COUNTIF(AA$3:AA12,AF12)+COUNTIF(AA$3:AA12,AG12)+COUNTIF(AA$3:AA12,AH12)+COUNTIF(AA$3:AA12,AI12)+COUNTIF(AA$3:AA12,AJ12)+COUNTIF(AA$3:AA12,AK12)+COUNTIF(AA$3:AA12,AL12)+COUNTIF(AA$3:AA12,AM12)+COUNTIF(AA$3:AA12,AN12)+COUNTIF(AA$3:AA12,AO12)+COUNTIF(AA$3:AA12,AP12)+COUNTIF(AA$3:AA12,AQ12)+COUNTIF(AA$3:AA12,AR12) -> 2 | AA12: =VLOOKUP(A12,howfared!$A$2:$B$33,2,FALSE) -> MIN | AB12: =VLOOKUP(AA12,howfared!$B$2:$AH$33,2,FALSE) -> JAC | AC12: =VLOOKUP(AA12,howfared!$B$2:$AH$33,3,FALSE) -> 0 | AD12: =VLOOKUP(AA12,howfared!$B$2:$AH$33,4,FALSE) -> SF | AE12: =VLOOKUP(AA12,howfared!$B$2:$AH$33,5,FALSE) -> DET | AF12: =VLOOKUP(AA12,howfared!$B$2:$AH$33,6,FALSE) -> MIN | AG12: =VLOOKUP(AA12,howfared!$B$2:$AH$33,7,FALSE) -> 0 | AH12: =VLOOKUP(AA12,howfared!$B$2:$AH$33,8,FALSE) -> 0 | AI12: =VLOOKUP(AA12,howfared!$B$2:$AH$33,9,FALSE) -> 0 | AJ12: =VLOOKUP(AA12,howfared!$B$2:$AH$33,10,FALSE) -> 0 | AK12: =VLOOKUP(AA12,howfared!$B$2:$AH$33,11,FALSE) -> 0 | AL12: =VLOOKUP(AA12,howfared!$B$2:$AH$33,12,FALSE) -> 0 | AM12: =VLOOKUP(AA12,howfared!$B$2:$AH$33,13,FALSE) -> 0 | AN12: =VLOOKUP(AA12,howfared!$B$2:$AH$33,14,FALSE) -> 0 | AO12: =VLOOKUP(AA12,howfared!$B$2:$AH$33,15,FALSE) -> 0 | AP12: =VLOOKUP(AA12,howfared!$B$2:$AH$33,16,FALSE) -> 0 | AQ12: =VLOOKUP(AA12,howfared!$B$2:$AH$33,17,FALSE) -> 0 | AR12: =VLOOKUP(AA12,howfared!$B$2:$AH$33,18,FALSE) -> 0 | AS12: =AA12 -> MIN | AT12: =D12 -> 4 | AU12: =E12 -> 2
A13: Arizona Cardinals | B13: NFC | C13: NCW | D13: 4 | E13: 2 | F13: 0 | G13: 0.667 | H13: 110 | I13: 97 | J13: 13 | K13: 11 | L13: 3-1 | M13: 1-1 | N13: 1-1 | O13: 0.5 | P13: 2-1 | Q13: 0.667 | R13: 2-1 | S13: 2L | T13: 3-2 | U13: =H13/(D13+E13+F13) -> 18.333333 | V13: =I13/(D13+E13+F13) -> 16.166667 | W13: =U13-V13 -> 2.1666667 | X13: =SUM(D13:F13) -> 6 | Y13: 11 | Z13: =COUNTIF(AA$3:AA12,AB13)+COUNTIF(AA$3:AA13,AC13)+COUNTIF(AA$3:AA13,AD13)+COUNTIF(AA$3:AA13,AE13)+COUNTIF(AA$3:AA13,AF13)+COUNTIF(AA$3:AA13,AG13)+COUNTIF(AA$3:AA13,AH13)+COUNTIF(AA$3:AA13,AI13)+COUNTIF(AA$3:AA13,AJ13)+COUNTIF(AA$3:AA13,AK13)+COUNTIF(AA$3:AA13,AL13)+COUNTIF(AA$3:AA13,AM13)+COUNTIF(AA$3:AA13,AN13)+COUNTIF(AA$3:AA13,AO13)+COUNTIF(AA$3:AA13,AP13)+COUNTIF(AA$3:AA13,AQ13)+COUNTIF(AA$3:AA13,AR13) -> 2 | AA13: =VLOOKUP(A13,howfared!$A$2:$B$33,2,FALSE) -> ARI | AB13: =VLOOKUP(AA13,howfared!$B$2:$AH$33,2,FALSE) -> SEA | AC13: =VLOOKUP(AA13,howfared!$B$2:$AH$33,3,FALSE) -> NE | AD13: =VLOOKUP(AA13,howfared!$B$2:$AH$33,4,FALSE) -> PHI | AE13: =VLOOKUP(AA13,howfared!$B$2:$AH$33,5,FALSE) -> MIA | AF13: =VLOOKUP(AA13,howfared!$B$2:$AH$33,6,FALSE) -> 0 | AG13: =VLOOKUP(AA13,howfared!$B$2:$AH$33,7,FALSE) -> 0 | AH13: =VLOOKUP(AA13,howfared!$B$2:$AH$33,8,FALSE) -> 0 | AI13: =VLOOKUP(AA13,howfared!$B$2:$AH$33,9,FALSE) -> 0 | AJ13: =VLOOKUP(AA13,howfared!$B$2:$AH$33,10,FALSE) -> 0 | AK13: =VLOOKUP(AA13,howfared!$B$2:$AH$33,11,FALSE) -> 0 | AL13: =VLOOKUP(AA13,howfared!$B$2:$AH$33,12,FALSE) -> 0 | AM13: =VLOOKUP(AA13,howfared!$B$2:$AH$33,13,FALSE) -> 0 | AN13: =VLOOKUP(AA13,howfared!$B$2:$AH$33,14,FALSE) -> 0 | AO13: =VLOOKUP(AA13,howfared!$B$2:$AH$33,15,FALSE) -> 0 | AP13: =VLOOKUP(AA13,howfared!$B$2:$AH$33,16,FALSE) -> 0 | AQ13: =VLOOKUP(AA13,howfared!$B$2:$AH$33,17,FALSE) -> 0 | AR13: =VLOOKUP(AA13,howfared!$B$2:$AH$33,18,FALSE) -> 0 | AS13: =AA13 -> ARI | AT13: =D13 -> 4 | AU13: =E13 -> 2
A14: Denver Broncos | B14: AFC | C14: ACW | D14: 3 | E14: 3 | F14: 0 | G14: 0.5 | H14: 170 | I14: 138 | J14: 32 | K14: 21 | L14: 2-1 | M14: 1-2 | N14: 2-0 | O14: 1 | P14: 3-2 | Q14: 0.6 | R14: 0-1 | S14: 1W | T14: 2-3 | U14: =H14/(D14+E14+F14) -> 28.333333 | V14: =I14/(D14+E14+F14) -> 23 | W14: =U14-V14 -> 5.3333333 | X14: =SUM(D14:F14) -> 6 | Y14: 12 | Z14: =COUNTIF(AA$3:AA13,AB14)+COUNTIF(AA$3:AA14,AC14)+COUNTIF(AA$3:AA14,AD14)+COUNTIF(AA$3:AA14,AE14)+COUNTIF(AA$3:AA14,AF14)+COUNTIF(AA$3:AA14,AG14)+COUNTIF(AA$3:AA14,AH14)+COUNTIF(AA$3:AA14,AI14)+COUNTIF(AA$3:AA14,AJ14)+COUNTIF(AA$3:AA14,AK14)+COUNTIF(AA$3:AA14,AL14)+COUNTIF(AA$3:AA14,AM14)+COUNTIF(AA$3:AA14,AN14)+COUNTIF(AA$3:AA14,AO14)+COUNTIF(AA$3:AA14,AP14)+COUNTIF(AA$3:AA14,AQ14)+COUNTIF(AA$3:AA14,AR14) -> 0 | AA14: =VLOOKUP(A14,howfared!$A$2:$B$33,2,FALSE) -> DEN | AB14: =VLOOKUP(AA14,howfared!$B$2:$AH$33,2,FALSE) -> PIT | AC14: =VLOOKUP(AA14,howfared!$B$2:$AH$33,3,FALSE) -> 0 | AD14: =VLOOKUP(AA14,howfared!$B$2:$AH$33,4,FALSE) -> 0 | AE14: =VLOOKUP(AA14,howfared!$B$2:$AH$33,5,FALSE) -> OAK | AF14: =VLOOKUP(AA14,howfared!$B$2:$AH$33,6,FALSE) -> 0 | AG14: =VLOOKUP(AA14,howfared!$B$2:$AH$33,7,FALSE) -> SD | AH14: =VLOOKUP(AA14,howfared!$B$2:$AH$33,8,FALSE) -> 0 | AI14: =VLOOKUP(AA14,howfared!$B$2:$AH$33,9,FALSE) -> 0 | AJ14: =VLOOKUP(AA14,howfared!$B$2:$AH$33,10,FALSE) -> 0 | AK14: =VLOOKUP(AA14,howfared!$B$2:$AH$33,11,FALSE) -> 0 | AL14: =VLOOKUP(AA14,howfared!$B$2:$AH$33,12,FALSE) -> 0 | AM14: =VLOOKUP(AA14,howfared!$B$2:$AH$33,13,FALSE) -> 0 | AN14: =VLOOKUP(AA14,howfared!$B$2:$AH$33,14,FALSE) -> 0 | AO14: =VLOOKUP(AA14,howfared!$B$2:$AH$33,15,FALSE) -> 0 | AP14: =VLOOKUP(AA14,howfared!$B$2:$AH$33,16,FALSE) -> 0 | AQ14: =VLOOKUP(AA14,howfared!$B$2:$AH$33,17,FALSE) -> 0 | AR14: =VLOOKUP(AA14,howfared!$B$2:$AH$33,18,FALSE) -> 0 | AS14: =AA14 -> DEN | AT14: =D14 -> 3 | AU14: =E14 -> 3
A15: Philadelphia Eagles | B15: AFC | C15: NCE | D15: 3 | E15: 3 | F15: 0 | G15: 0.5 | H15: 103 | I15: 125 | J15: -22 | K15: 10 | L15: 2-1 | M15: 1-2 | N15: 1-0 | O15: 1 | P15: 1-2 | Q15: 0.333 | R15: 2-1 | S15: 2L | T15: 2-3 | U15: =H15/(D15+E15+F15) -> 17.166667 | V15: =I15/(D15+E15+F15) -> 20.833333 | W15: =U15-V15 -> -3.6666667 | X15: =SUM(D15:F15) -> 6 | Y15: 13 | Z15: =COUNTIF(AA$3:AA14,AB15)+COUNTIF(AA$3:AA15,AC15)+COUNTIF(AA$3:AA15,AD15)+COUNTIF(AA$3:AA15,AE15)+COUNTIF(AA$3:AA15,AF15)+COUNTIF(AA$3:AA15,AG15)+COUNTIF(AA$3:AA15,AH15)+COUNTIF(AA$3:AA15,AI15)+COUNTIF(AA$3:AA15,AJ15)+COUNTIF(AA$3:AA15,AK15)+COUNTIF(AA$3:AA15,AL15)+COUNTIF(AA$3:AA15,AM15)+COUNTIF(AA$3:AA15,AN15)+COUNTIF(AA$3:AA15,AO15)+COUNTIF(AA$3:AA15,AP15)+COUNTIF(AA$3:AA15,AQ15)+COUNTIF(AA$3:AA15,AR15) -> 2 | AA15: =VLOOKUP(A15,howfared!$A$2:$B$33,2,FALSE) -> PHI | AB15: =VLOOKUP(AA15,howfared!$B$2:$AH$33,2,FALSE) -> CLE | AC15: =VLOOKUP(AA15,howfared!$B$2:$AH$33,3,FALSE) -> BAL | AD15: =VLOOKUP(AA15,howfared!$B$2:$AH$33,4,FALSE) -> 0 | AE15: =VLOOKUP(AA15,howfared!$B$2:$AH$33,5,FALSE) -> NYG | AF15: =VLOOKUP(AA15,howfared!$B$2:$AH$33,6,FALSE) -> 0 | AG15: =VLOOKUP(AA15,howfared!$B$2:$AH$33,7,FALSE) -> 0 | AH15: =VLOOKUP(AA15,howfared!$B$2:$AH$33,8,FALSE) -> 0 | AI15: =VLOOKUP(AA15,howfared!$B$2:$AH$33,9,FALSE) -> 0 | AJ15: =VLOOKUP(AA15,howfared!$B$2:$AH$33,10,FALSE) -> 0 | AK15: =VLOOKUP(AA15,howfared!$B$2:$AH$33,11,FALSE) -> 0 | AL15: =VLOOKUP(AA15,howfared!$B$2:$AH$33,12,FALSE) -> 0 | AM15: =VLOOKUP(AA15,howfared!$B$2:$AH$33,13,FALSE) -> 0 | AN15: =VLOOKUP(AA15,howfared!$B$2:$AH$33,14,FALSE) -> 0 | AO15: =VLOOKUP(AA15,howfared!$B$2:$AH$33,15,FALSE) -> 0 | AP15: =VLOOKUP(AA15,howfared!$B$2:$AH$33,16,FALSE) -> 0 | AQ15: =VLOOKUP(AA15,howfared!$B$2:$AH$33,17,FALSE) -> 0 | AR15: =VLOOKUP(AA15,howfared!$B$2:$AH$33,18,FALSE) -> 0 | AS15: =AA15 -> PHI | AT15: =D15 -> 3 | AU15: =E15 -> 3
... A34: Kansas City Chiefs | B34: AFC | C34: ACW | D34: 1 | E34: 5 | F34: 0 | G34: 0.167 | H34: 104 | I34: 183 | J34: -79 | K34: 10 | L34: 0-3 | M34: 1-2 | N34: 0-1 | O34: 0 | P34: 0-3 | Q34: 0 | R34: 1-2 | S34: 3L | T34: 1-4 | U34: =H34/(D34+E34+F34) -> 17.333333 | V34: =I34/(D34+E34+F34) -> 30.5 | W34: =U34-V34 -> -13.166667 | X34: =SUM(D34:F34) -> 6 | Y34: 32 | Z34: =COUNTIF(AA$3:AA33,AB34)+COUNTIF(AA$3:AA34,AC34)+COUNTIF(AA$3:AA34,AD34)+COUNTIF(AA$3:AA34,AE34)+COUNTIF(AA$3:AA34,AF34)+COUNTIF(AA$3:AA34,AG34)+COUNTIF(AA$3:AA34,AH34)+COUNTIF(AA$3:AA34,AI34)+COUNTIF(AA$3:AA34,AJ34)+COUNTIF(AA$3:AA34,AK34)+COUNTIF(AA$3:AA34,AL34)+COUNTIF(AA$3:AA34,AM34)+COUNTIF(AA$3:AA34,AN34)+COUNTIF(AA$3:AA34,AO34)+COUNTIF(AA$3:AA34,AP34)+COUNTIF(AA$3:AA34,AQ34)+COUNTIF(AA$3:AA34,AR34) -> 1 | AA34: =VLOOKUP(A34,howfared!$A$2:$B$33,2,FALSE) -> KC | AB34: =VLOOKUP(AA34,howfared!$B$2:$AH$33,2,FALSE) -> 0 | AC34: =VLOOKUP(AA34,howfared!$B$2:$AH$33,3,FALSE) -> 0 | AD34: =VLOOKUP(AA34,howfared!$B$2:$AH$33,4,FALSE) -> NO | AE34: =VLOOKUP(AA34,howfared!$B$2:$AH$33,5,FALSE) -> 0 | AF34: =VLOOKUP(AA34,howfared!$B$2:$AH$33,6,FALSE) -> 0 | AG34: =VLOOKUP(AA34,howfared!$B$2:$AH$33,7,FALSE) -> 0 | AH34: =VLOOKUP(AA34,howfared!$B$2:$AH$33,8,FALSE) -> 0 | AI34: =VLOOKUP(AA34,howfared!$B$2:$AH$33,9,FALSE) -> 0 | AJ34: =VLOOKUP(AA34,howfared!$B$2:$AH$33,10,FALSE) -> 0 | AK34: =VLOOKUP(AA34,howfared!$B$2:$AH$33,11,FALSE) -> 0 | AL34: =VLOOKUP(AA34,howfared!$B$2:$AH$33,12,FALSE) -> 0 | AM34: =VLOOKUP(AA34,howfared!$B$2:$AH$33,13,FALSE) -> 0 | AN34: =VLOOKUP(AA34,howfared!$B$2:$AH$33,14,FALSE) -> 0 | AO34: =VLOOKUP(AA34,howfared!$B$2:$AH$33,15,FALSE) -> 0 | AP34: =VLOOKUP(AA34,howfared!$B$2:$AH$33,16,FALSE) -> 0 | AQ34: =VLOOKUP(AA34,howfared!$B$2:$AH$33,17,FALSE) -> 0 | AR34: =VLOOKUP(AA34,howfared!$B$2:$AH$33,18,FALSE) -> 0 | AS34: =AA34 -> KC | AT34: =D34 -> 1 | AU34: =E34 -> 5

Sheet Power by Week
A1: Team | B1: Week 1 | C1: Week 2 | D1: Week 3 | E1: Week 4 | F1: Week 5 | G1: Week 6 | H1: Week 7 | I1: Week 8 | J1: Week 9 | K1: Week 10 | L1: Week 11 | M1: Week 12 | N1: Week 13 | O1: Week 14 | P1: Week 15 | Q1: Week 16 | R1: Week 17 | S1: Average | T1: Highest | U1: Lowest | V1: Biggest Gap | W1: Team Change Code | X1: Change from Last Week | Y1: Change from Week 1
A2: Houston Texans | B2: 6 | C2: 4 | D2: 2 | E2: 1 | F2: 1 | G2: 1 | H2: 2 | S2: =AVERAGE(B2:R2) -> 2.4285714 | T2: =MINA(B2:R2) -> 1 | U2: =MAXA(B2:R2) -> 6 | V2: =U2-T2 -> 5 | W2: =IF(X2<0,CONCATENATE(A2," (-",ABS(X2),"), "),IF(X2=0,CONCATENATE(A2,", "),CONCATENATE(A2," (+",ABS(X2),"), "))) -> Houston Texans (-1), | X2: =G2-H2 -> -1 | Y2: =G2-B2 -> -5
A3: San Francisco 49ers | B3: 5 | C3: 2 | D3: 1 | E3: 4 | F3: 4 | G3: 3 | H3: 5 | S3: =AVERAGE(B3:R3) -> 3.4285714 | T3: =MINA(B3:R3) -> 1 | U3: =MAXA(B3:R3) -> 5 | V3: =U3-T3 -> 4 | W3: =IF(X3<0,CONCATENATE(A3," (-",ABS(X3),"), "),IF(X3=0,CONCATENATE(A3,", "),CONCATENATE(A3," (+",ABS(X3),"), "))) -> San Francisco 49ers (-2), | X3: =G3-H3 -> -2 | Y3: =G3-B3 -> -2
A4: Baltimore Ravens | B4: 4 | C4: 3 | D4: 6 | E4: 3 | F4: 3 | G4: 4 | H4: 4 | S4: =AVERAGE(B4:R4) -> 3.8571429 | T4: =MINA(B4:R4) -> 3 | U4: =MAXA(B4:R4) -> 6 | V4: =U4-T4 -> 3 | W4: =IF(X4<0,CONCATENATE(A4," (-",ABS(X4),"), "),IF(X4=0,CONCATENATE(A4,", "),CONCATENATE(A4," (+",ABS(X4),"), "))) -> Baltimore Ravens, | X4: =G4-H4 -> 0 | Y4: =G4-B4 -> 0
A5: Atlanta Falcons | B5: 12 | C5: 6 | D5: 3 | E5: 2 | F5: 2 | G5: 2 | H5: 1 | S5: =AVERAGE(B5:R5) -> 4 | T5: =MINA(B5:R5) -> 1 | U5: =MAXA(B5:R5) -> 12 | V5: =U5-T5 -> 11 | W5: =IF(X5<0,CONCATENATE(A5," (-",ABS(X5),"), "),IF(X5=0,CONCATENATE(A5,", "),CONCATENATE(A5," (+",ABS(X5),"), "))) -> Atlanta Falcons (+1), | X5: =G5-H5 -> 1 | Y5: =G5-B5 -> -10
A6: New England Patriots | B6: 2 | C6: 1 | D6: 5 | E6: 8 | F6: 6 | G6: 5 | H6: 7 | S6: =AVERAGE(B6:R6) -> 4.8571429 | T6: =MINA(B6:R6) -> 1 | U6: =MAXA(B6:R6) -> 8 | V6: =U6-T6 -> 7 | W6: =IF(X6<0,CONCATENATE(A6," (-",ABS(X6),"), "),IF(X6=0,CONCATENATE(A6,", "),CONCATENATE(A6," (+",ABS(X6),"), "))) -> New England Patriots (-2), | X6: =G6-H6 -> -2 | Y6: =G6-B6 -> 3
A7: New York Giants | B7: 1 | C7: 7 | D7: 8 | E7: 6 | F7: 10 | G7: 7 | H7: 3 | S7: =AVERAGE(B7:R7) -> 6 | T7: =MINA(B7:R7) -> 1 | U7: =MAXA(B7:R7) -> 10 | V7: =U7-T7 -> 9 | W7: =IF(X7<0,CONCATENATE(A7," (-",ABS(X7),"), "),IF(X7=0,CONCATENATE(A7,", "),CONCATENATE(A7," (+",ABS(X7),"), "))) -> New York Giants (+4), | X7: =G7-H7 -> 4 | Y7: =G7-B7 -> 6
A8: Green Bay Packers | B8: 3 | C8: 5 | D8: 4 | E8: 7 | F8: 8 | G8: 12 | H8: 8 | S8: =AVERAGE(B8:R8) -> 6.7142857 | T8: =MINA(B8:R8) -> 3 | U8: =MAXA(B8:R8) -> 12 | V8: =U8-T8 -> 9 | W8: =IF(X8<0,CONCATENATE(A8," (-",ABS(X8),"), "),IF(X8=0,CONCATENATE(A8,", "),CONCATENATE(A8," (+",ABS(X8),"), "))) -> Green Bay Packers (+4), | X8: =G8-H8 -> 4 | Y8: =G8-B8 -> 9
A9: Chicago Bears | B9: 11 | C9: 8 | D9: 12 | E9: 11 | F9: 9 | G9: 6 | H9: 6 | S9: =AVERAGE(B9:R9) -> 9 | T9: =MINA(B9:R9) -> 6 | U9: =MAXA(B9:R9) -> 12 | V9: =U9-T9 -> 6 | W9: =IF(X9<0,CONCATENATE(A9," (-",ABS(X9),"), "),IF(X9=0,CONCATENATE(A9,", "),CONCATENATE(A9," (+",ABS(X9),"), "))) -> Chicago Bears, | X9: =G9-H9 -> 0 | Y9: =G9-B9 -> -5
A10: Philadelphia Eagles | B10: 7 | C10: 12 | D10: 7 | E10: 9 | F10: 7 | G10: 11 | H10: 13 | S10: =AVERAGE(B10:R10) -> 9.4285714 | T10: =MINA(B10:R10) -> 7 | U10: =MAXA(B10:R10) -> 13 | V10: =U10-T10 -> 6 | W10: =IF(X10<0,CONCATENATE(A10," (-",ABS(X10),"), "),IF(X10=0,CONCATENATE(A10,", "),CONCATENATE(A10," (+",ABS(X10),"), "))) -> Philadelphia Eagles (-2), | X10: =G10-H10 -> -2 | Y10: =G10-B10 -> 4
A11: Arizona Cardinals | B11: 19 | C11: 20 | D11: 14 | E11: 5 | F11: 5 | G11: 9 | H11: 11 | S11: =AVERAGE(B11:R11) -> 11.857143 | T11: =MINA(B11:R11) -> 5 | U11: =MAXA(B11:R11) -> 20 | V11: =U11-T11 -> 15 | W11: =IF(X11<0,CONCATENATE(A11," (-",ABS(X11),"), "),IF(X11=0,CONCATENATE(A11,", "),CONCATENATE(A11," (+",ABS(X11),"), "))) -> Arizona Cardinals (-2), | X11: =G11-H11 -> -2 | Y11: =G11-B11 -> -10
A12: Pittsburgh Steelers | B12: 8 | C12: 11 | D12: 9 | E12: 16 | F12: 16 | G12: 10 | H12: 14 | S12: =AVERAGE(B12:R12) -> 12 | T12: =MINA(B12:R12) -> 8 | U12: =MAXA(B12:R12) -> 16 | V12: =U12-T12 -> 8 | W12: =IF(X12<0,CONCATENATE(A12," (-",ABS(X12),"), "),IF(X12=0,CONCATENATE(A12,", "),CONCATENATE(A12," (+",ABS(X12),"), "))) -> Pittsburgh Steelers (-4), | X12: =G12-H12 -> -4 | Y12: =G12-B12 -> 2
A13: Denver Broncos | B13: 10 | C13: 9 | D13: 10 | E13: 14 | F13: 13 | G13: 17 | H13: 12 | S13: =AVERAGE(B13:R13) -> 12.142857 | T13: =MINA(B13:R13) -> 9 | U13: =MAXA(B13:R13) -> 17 | V13: =U13-T13 -> 8 | W13: =IF(X13<0,CONCATENATE(A13," (-",ABS(X13),"), "),IF(X13=0,CONCATENATE(A13,", "),CONCATENATE(A13," (+",ABS(X13),"), "))) -> Denver Broncos (+5), | X13: =G13-H13 -> 5 | Y13: =G13-B13 -> 7
... A33: Cleveland Browns | B33: 30 | C33: 31 | D33: 32 | E33: 32 | F33: 32 | G33: 32 | H33: 30 | S33: =AVERAGE(B33:R33) -> 31.285714 | T33: =MINA(B33:R33) -> 30 | U33: =MAXA(B33:R33) -> 32 | V33: =U33-T33 -> 2 | W33: =IF(X33<0,CONCATENATE(A33," (-",ABS(X33),"), "),IF(X33=0,CONCATENATE(A33,", "),CONCATENATE(A33," (+",ABS(X33),"), "))) -> Cleveland Browns (+2), | X33: =G33-H33 -> 2 | Y33: =G33-B33 -> 2

Sheet divisions
A1: Voter | B1: AFC East | C1: AFC North | D1: AFC South | E1: AFC West | F1: NFC East | G1: NFC North | H1: NFC South | I1: NFC West | J1: Average (should equal 16.5)
A2: Mike Sando | B2: =AVERAGEIFS(power!$G$2:$G$33,power!$P$2:$P$33,B$1) -> 19 | C2: =AVERAGEIFS(power!$G$2:$G$33,power!$P$2:$P$33,C$1) -> 15.75 | D2: =AVERAGEIFS(power!$G$2:$G$33,power!$P$2:$P$33,D$1) -> 21.25 | E2: =AVERAGEIFS(power!$G$2:$G$33,power!$P$2:$P$33,E$1) -> 22 | F2: =AVERAGEIFS(power!$G$2:$G$33,power!$P$2:$P$33,F$1) -> 14 | G2: =AVERAGEIFS(power!$G$2:$G$33,power!$P$2:$P$33,G$1) -> 10.25 | H2: =AVERAGEIFS(power!$G$2:$G$33,power!$P$2:$P$33,H$1) -> 18.5 | I2: =AVERAGEIFS(power!$G$2:$G$33,power!$P$2:$P$33,I$1) -> 11.25 | J2: =AVERAGE(B2:I2) -> 16.5 | AE2: =AC2-AD2 -> 0
A3: John Clayton | B3: =AVERAGEIFS(power!$H$2:$H$33,power!$P$2:$P$33,B$1) -> 18.25 | C3: =AVERAGEIFS(power!$H$2:$H$33,power!$P$2:$P$33,C$1) -> 15 | D3: =AVERAGEIFS(power!$H$2:$H$33,power!$P$2:$P$33,D$1) -> 21.25 | E3: =AVERAGEIFS(power!$H$2:$H$33,power!$P$2:$P$33,E$1) -> 23.25 | F3: =AVERAGEIFS(power!$H$2:$H$33,power!$P$2:$P$33,F$1) -> 13.5 | G3: =AVERAGEIFS(power!$H$2:$H$33,power!$P$2:$P$33,G$1) -> 10.25 | H3: =AVERAGEIFS(power!$H$2:$H$33,power!$P$2:$P$33,H$1) -> 19 | I3: =AVERAGEIFS(power!$H$2:$H$33,power!$P$2:$P$33,I$1) -> 11.5 | J3: =AVERAGE(B3:I3) -> 16.5 | AE3: =AC3-AD3 -> 0
A4: Dan Graziano | B4: =AVERAGEIFS(power!$I$2:$I$33,power!$P$2:$P$33,B$1) -> 19.5 | C4: =AVERAGEIFS(power!$I$2:$I$33,power!$P$2:$P$33,C$1) -> 18 | D4: =AVERAGEIFS(power!$I$2:$I$33,power!$P$2:$P$33,D$1) -> 22.75 | E4: =AVERAGEIFS(power!$I$2:$I$33,power!$P$2:$P$33,E$1) -> 21.25 | F4: =AVERAGEIFS(power!$I$2:$I$33,power!$P$2:$P$33,F$1) -> 9.25 | G4: =AVERAGEIFS(power!$I$2:$I$33,power!$P$2:$P$33,G$1) -> 11 | H4: =AVERAGEIFS(power!$I$2:$I$33,power!$P$2:$P$33,H$1) -> 16.5 | I4: =AVERAGEIFS(power!$I$2:$I$33,power!$P$2:$P$33,I$1) -> 13.75 | J4: =AVERAGE(B4:I4) -> 16.5 | AE4: =AC4-AD4 -> 0
A5: Jamison Hensley | B5: =AVERAGEIFS(power!$J$2:$J$33,power!$P$2:$P$33,B$1) -> 17.25 | C5: =AVERAGEIFS(power!$J$2:$J$33,power!$P$2:$P$33,C$1) -> 17.5 | D5: =AVERAGEIFS(power!$J$2:$J$33,power!$P$2:$P$33,D$1) -> 20 | E5: =AVERAGEIFS(power!$J$2:$J$33,power!$P$2:$P$33,E$1) -> 22.5 | F5: =AVERAGEIFS(power!$J$2:$J$33,power!$P$2:$P$33,F$1) -> 13 | G5: =AVERAGEIFS(power!$J$2:$J$33,power!$P$2:$P$33,G$1) -> 11.75 | H5: =AVERAGEIFS(power!$J$2:$J$33,power!$P$2:$P$33,H$1) -> 19 | I5: =AVERAGEIFS(power!$J$2:$J$33,power!$P$2:$P$33,I$1) -> 11 | J5: =AVERAGE(B5:I5) -> 16.5 | AE5: =AC5-AD5 -> 0
A6: Ashley Fox | B6: =AVERAGEIFS(power!$K$2:$K$33,power!$P$2:$P$33,B$1) -> 17.75 | C6: =AVERAGEIFS(power!$K$2:$K$33,power!$P$2:$P$33,C$1) -> 17.5 | D6: =AVERAGEIFS(power!$K$2:$K$33,power!$P$2:$P$33,D$1) -> 22.25 | E6: =AVERAGEIFS(power!$K$2:$K$33,power!$P$2:$P$33,E$1) -> 22.5 | F6: =AVERAGEIFS(power!$K$2:$K$33,power!$P$2:$P$33,F$1) -> 11.75 | G6: =AVERAGEIFS(power!$K$2:$K$33,power!$P$2:$P$33,G$1) -> 11.25 | H6: =AVERAGEIFS(power!$K$2:$K$33,power!$P$2:$P$33,H$1) -> 18.5 | I6: =AVERAGEIFS(power!$K$2:$K$33,power!$P$2:$P$33,I$1) -> 10.5 | J6: =AVERAGE(B6:I6) -> 16.5 | AE6: =AC6-AD6 -> 0
AE7: =AC7-AD7 -> 0
A8: Average | B8: =AVERAGE(B2:B6) -> 18.35 | C8: =AVERAGE(C2:C6) -> 16.75 | D8: =AVERAGE(D2:D6) -> 21.5 | E8: =AVERAGE(E2:E6) -> 22.3 | F8: =AVERAGE(F2:F6) -> 12.3 | G8: =AVERAGE(G2:G6) -> 10.9 | H8: =AVERAGE(H2:H6) -> 18.3 | I8: =AVERAGE(I2:I6) -> 11.6 | AE8: =AC8-AD8 -> 0
A9: Rank | B9: =RANK(B8,$B$8:$I$8,1) -> 6 | C9: =RANK(C8,$B$8:$I$8,1) -> 4 | D9: =RANK(D8,$B$8:$I$8,1) -> 7 | E9: =RANK(E8,$B$8:$I$8,1) -> 8 | F9: =RANK(F8,$B$8:$I$8,1) -> 3 | G9: =RANK(G8,$B$8:$I$8,1) -> 1 | H9: =RANK(H8,$B$8:$I$8,1) -> 5 | I9: =RANK(I8,$B$8:$I$8,1) -> 2

Sheet howfared
A1: Team | B1: Code | C1: Beat | D1: Beat | E1: Beat | F1: Beat | G1: Beat | H1: Beat | I1: Beat | J1: Beat | K1: Beat | L1: Beat | M1: Beat | N1: Beat | O1: Beat | P1: Beat | Q1: Beat | R1: Beat | S1: Beat | T1: Total Wins | U1: Playoffs | V1: Wins vs Playoff Teams | W1: Losses vs Playoff Teams
A2: Arizona Cardinals | B2: ARI | C2: SEA | D2: NE | E2: PHI | F2: MIA | T2: =COUNTIF(C2:S2,">0'") -> 4
A3: Atlanta Falcons | B3: ATL | C3: KC | D3: DEN | E3: SD | F3: CAR | G3: WAS | H3: OAK | T3: =COUNTIF(C3:S3,">0'") -> 6
A4: Baltimore Ravens | B4: BAL | C4: CIN | E4: NE | F4: CLE | G4: KC | H4: DAL | T4: =COUNTIF(C4:S4,">0'") -> 5
A5: Buffalo Bills | B5: BUF | D5: KC | E5: CLE | H5: ARI | T5: =COUNTIF(C5:S5,">0'") -> 3
A6: Carolina Panthers | B6: CAR | D6: NO | T6: =COUNTIF(C6:S6,">0'") -> 1
A7: Chicago Bears | B7: CHI | C7: IND | E7: STL | F7: DAL | G7: JAC | T7: =COUNTIF(C7:S7,">0'") -> 4
A8: Cincinnati Bengals | B8: CIN | D8: CLE | E8: WAS | F8: JAC | T8: =COUNTIF(C8:S8,">0'") -> 3
A9: Cleveland Browns | B9: CLE | H9: CIN | T9: =COUNTIF(C9:S9,">0'") -> 1
A10: Dallas Cowboys | B10: DAL | C10: NYG | E10: TB | T10: =COUNTIF(C10:S10,">0'") -> 2
A11: Denver Broncos | B11: DEN | C11: PIT | F11: OAK | H11: SD | T11: =COUNTIF(C11:S11,">0'") -> 3
A12: Detroit Lions | B12: DET | C12: STL | H12: PHI | T12: =COUNTIF(C12:S12,">0'") -> 2
A13: Green Bay Packers | B13: GB | D13: CHI | F13: NO | H13: HOU | T13: =COUNTIF(C13:S13,">0'") -> 3
A14: Houston Texans | B14: HOU | C14: MIA | D14: JAC | E14: DEN | F14: TEN | G14: NYJ | T14: =COUNTIF(C14:S14,">0'") -> 5
A15: Indianapolis Colts | B15: IND | D15: MIN | G15: GB | T15: =COUNTIF(C15:S15,">0'") -> 2
A16: Jacksonville Jaguars | B16: JAC | E16: IND | T16: =COUNTIF(C16:S16,">0'") -> 1
A17: Kansas City Chiefs | B17: KC | E17: NO | T17: =COUNTIF(C17:S17,">0'") -> 1
A18: Miami Dolphins | B18: MIA | D18: OAK | G18: CIN | H18: STL | T18: =COUNTIF(C18:S18,">0'") -> 3
A19: Minnesota Vikings | B19: MIN | C19: JAC | E19: SF | F19: DET | G19: MIN | T19: =COUNTIF(C19:S19,">0'") -> 4
A20: New England Patriots | B20: NE | C20: TEN | F20: BUF | G20: DEN | T20: =COUNTIF(C20:S20,">0'") -> 3
A21: New Orleans Saints | B21: NO | G21: SD | T21: =COUNTIF(C21:S21,">0'") -> 1
A22: New York Giants | B22: NYG | D22: TB | E22: CAR | G22: CLE | H22: SF | T22: =COUNTIF(C22:S22,">0'") -> 4
A23: New York Jets | B23: NYJ | C23: BUF | E23: MIA | H23: IND | T23: =COUNTIF(C23:S23,">0'") -> 3
