Workbook

Sheet Data
C1: Gulf | D1: In port | F1: Loaded | H1: Due | I1: PNW | L1: Vancouver
C2: In Port | D2: 4-year | E2: Loaded | F2: prior | G2: Due | H2: 10-days | I2: In Port | J2: Loaded | K2: Due | L2: In Port | M2: Loaded | N2: Due | P2: In Port | Q2: Loaded
A3: Date | D3: average | E3: 7-Days | F3: 4-year avg | G3: 10-days | H3: prior 4-yr avg | J3: 7-Days | K3: 10-days | M3: 7-Days | N3: 10-days | O3: Week #
A4: 34703 | B4: 01/04/1995 | C4: 39 | E4: 58 | G4: 62 | O4: 1
A5: 34710 | B5: 01/11/1995 | C5: 36 | E5: 64 | G5: 72 | O5: 2
A6: 34717 | B6: 01/18/1995 | C6: 40 | E6: 60 | G6: 73 | O6: 3
A7: 34724 | B7: 01/25/1995 | C7: 41 | E7: 59 | G7: 63 | O7: 4
A8: 34731 | B8: 02/01/1995 | C8: 36 | E8: 62 | G8: 79 | O8: 5
A9: 34738 | B9: 02/08/1995 | C9: 42 | E9: 59 | G9: 78 | O9: 6
A10: 34745 | B10: 02/15/1995 | C10: 42 | E10: na | G10: na | O10: 7
A11: 34752 | B11: 02/22/1995 | C11: 32 | E11: 58 | G11: 73 | O11: 8
A12: 34759 | B12: 03/01/1995 | C12: 38 | E12: 56 | G12: 72 | O12: 9
A13: 34766 | B13: 03/08/1995 | C13: 35 | E13: 58 | G13: 77 | O13: 10
A14: 34773 | B14: 03/15/1995 | C14: 32 | E14: 50 | G14: 77 | O14: 11
A15: 34780 | B15: 03/22/1995 | C15: 31 | E15: 50 | G15: 83 | O15: 12
A16: 34787 | B16: 03/29/1995 | C16: 32 | E16: 44 | G16: 90 | O16: 13
A17: 34794 | B17: 04/05/1995 | C17: 29 | E17: 47 | G17: 77 | O17: 14
A18: 34801 | B18: 04/12/1995 | C18: 29 | E18: na | G18: na | O18: 15
A19: 34808 | B19: 04/19/1995 | C19: 27 | E19: 47 | G19: 69 | O19: 16
A20: 34815 | B20: 04/26/1995 | C20: 19 | E20: 37 | G20: 48 | O20: 17
A21: 34822 | B21: 05/03/1995 | C21: 24 | E21: 48 | G21: 48 | O21: 18
A22: 34829 | B22: 05/10/1995 | C22: 24 | E22: na | G22: na | O22: 19
A23: 34836 | B23: 05/17/1995 | C23: 26 | E23: 43 | G23: 59 | O23: 20
A24: 34843 | B24: 05/24/1995 | C24: 23 | E24: 53 | G24: 49 | O24: 21
A25: 34850 | B25: 05/31/1995 | C25: 30 | E25: 45 | G25: 42 | O25: 22
A26: 34857 | B26: 06/07/1995 | C26: 26 | E26: 37 | G26: 37 | O26: 23
A27: 34864 | B27: 06/14/1995 | C27: 28 | E27: 22 | G27: 31 | O27: 24
A28: 34871 | B28: 06/21/1995 | C28: 27 | E28: 30 | G28: 38 | O28: 25
A29: 34878 | B29: 06/28/1995 | C29: 26 | E29: 41 | G29: 52 | O29: 26
A30: 34885 | B30: 07/05/1995 | C30: 24 | E30: 40 | G30: 50 | O30: 27
A31: 34892 | B31: 07/12/1995 | C31: 17 | E31: 38 | G31: 56 | O31: 28
A32: 34899 | B32: 07/19/1995 | C32: 23 | E32: 44 | G32: 60 | O32: 29
A33: 34906 | B33: 07/26/1995 | C33: 24 | E33: 40 | G33: 67 | O33: 30
A34: 34913 | B34: 08/02/1995 | C34: 25 | E34: 48 | G34: 70 | O34: 31
... A54: 35053 | B54: 12/20/1995 | C54: 39 | E54: 39 | G54: 71 | O54: 51
A55: 35060 | B55: 12/27/1995 | C55: 32 | E55: 49 | G55: 66 | O55: 52 | P55: 31.358491 | Q55: 45.933333
A56: 35067 | B56: 01/03/1996 | C56: 34 | E56: 40 | G56: 83 | O56: 1
A57: 35075 | B57: 01/11/1996 | C57: 37 | E57: 56 | G57: 75 | O57: 2
A58: 35081 | B58: 01/17/1996 | C58: 38 | E58: 52 | G58: 81 | O58: 3
A59: 35088 | B59: 01/24/1996 | C59: 30 | E59: 55 | G59: 88 | O59: 4
...

Sheet New  Table 17
A1: Table 17
A2: Weekly Port Region Grain Ocean Vessel Activity (number of vessels)
E3: Pacific | F3: Vancouver
B4: Gulf | E4: Northwest | F4: B.C.
C5: Loaded | D5: Due next
A6: Date | B6: In port | C6: 7-days | D6: 10-days | E6: In port | F6: In port
A7: =Data!A1022 -> 41830 | B7: =Data!C1022 -> 29 | C7: =Data!E1022 -> 31 | D7: =Data!G1022 -> 41 | E7: =Data!I1022 -> 12 | F7: =Data!L1022 -> n/a
A8: =Data!A1021 -> 41823 | B8: =Data!C1021 -> 32 | C8: =Data!E1021 -> 26 | D8: =Data!G1021 -> 48 | E8: =Data!I1021 -> 11 | F8: =Data!L1021 -> n/a
A9: 2013 range | B9: (16..60) | C9: (20..56) | D9: (31..81) | E9: (0..24) | F9: n/a
A10: 2013 avg. | B10: 32 | C10: 33 | D10: 51 | E10: 12 | F10: n/a
A11: Source: Transportation & Marketing Programs/AMS/USDA
