Workbook

Sheet Instructions
B1: Where | C1: Do
A2: 1 | B2: File | C2: <Save As> to new filename for current year
A3: 2 | B3: Raw Results | C3: Delete obsolete contest year data.
A4: 3 | B4: Raw Results | C4: Add new contest data.
A5: 4 | B5: Racing Results | C5: Delete data in white cells
A6: 5 | B6: Raw Results | C6: <Copy> and <Paste Special - link> data to 'Racing Results'
A7: 6 | B7: Racing Results | C7: Update adjoining coloured cells if necessary
A8: 7 | B8: Scoring | C8: Delete data in white cells
A9: 8 | B9: Racing Results | C9: <Copy> orange data and <Paste Special - Link> to 'Scoring'
A10: 9 | B10: Scoring | C10: Follow sorting/editing instructions on 'Scoring'.
A11: 10 | B11: Scoring | C11: <Copy> orange data and <Paste Special - Link> to 'Seeding List'
A12: 11 | B12: Seeding List | C12: Sort by"Seeding Group" (hidden) then "Seeding Points"
A13: 12 | B13: Seeding List | C13: Clean up layout for publishing.

Sheet Raw Results
A1: Raw Results
A2: 2011 | B2: = Current Year
A3: Year | B3: Competition | C3: Class | D3: Comp Code | E3: Winner Score | F3: Name | G3: Pilot Score
A4: 2009 | B4: Canadian National Soaring Championships (FAI) | C4: A | D4: C | E4: 4556 | F4: Dave Springford | G4: 4556
A5: 2009 | B5: Canadian National Soaring Championships (FAI) | C5: A | D5: C | E5: 4556 | F5: Jerzy Szemplinski | G5: 4526
A6: 2009 | B6: Canadian National Soaring Championships (FAI) | C6: A | D6: C | E6: 4556 | F6: Willem Langelaan | G6: 4417
A7: 2009 | B7: Canadian National Soaring Championships (FAI) | C7: A | D7: C | E7: 4556 | F7: Nick Bonniere | G7: 4271
A8: 2009 | B8: Canadian National Soaring Championships (FAI) | C8: A | D8: C | E8: 4556 | F8: Joerg Stieber | G8: 4251
A9: 2009 | B9: Canadian National Soaring Championships (FAI) | C9: A | D9: C | E9: 4556 | F9: Ed Hollistelle Sr. | G9: 4229
A10: 2009 | B10: Canadian National Soaring Championships (FAI) | C10: A | D10: C | E10: 4556 | F10: Sergei Morozov | G10: 3674
A11: 2009 | B11: Canadian National Soaring Championships (FAI) | C11: A | D11: C | E11: 4556 | F11: Steve Burany | G11: 2058
A12: 2009 | B12: Canadian National Soaring Championships (FAI) | C12: A | D12: C | E12: 4556 | F12: Roger Hildesheim | G12: 1989
A13: 2009 | B13: Canadian National Soaring Championships (CLUB) | C13: B | D13: C | E13: 4336 | F13: Anthony Kawzowicz | G13: 4336
A14: 2009 | B14: Canadian National Soaring Championships (CLUB) | C14: B | D14: C | E14: 4336 | F14: Derek Mackie | G14: 3704
A15: 2009 | B15: Canadian National Soaring Championships (CLUB) | C15: B | D15: C | E15: 4336 | F15: Alf Marcelissen | G15: 3699
... A25: 2009 | B25: US Sports Nationals | C25: P | D25: F | E25: 3099 | F25: Andrzej Kobus | G25: 1541
A26: 2009 | B26: US 18m Nationals | C26: 18 | D26: F | E26: 7845 | F26: Dale Kramer | G26: 7412
A27: 2009 | B27: US 18m Nationals | C27: 18 | D27: F | E27: 7845 | F27: Mike Thompson | G27: 6645
A28: 2009 | B28: US Standard Nationals | C28: S | D28: F | E28: 7346 | F28: Dennis Vreeken | G28: 4350
A29: 2009 | B29: US Open Nationals | C29: O | D29: F | E29: 8266 | F29: Dale Kramer | G29: 6679
A30: 2009 | B30: Junior WGC Club | C30: C | D30: W | E30: 8160 | F30: Chris Gough | G30: 5758
A31: 2010 | B31: Canadian National Soaring Championships (FAI) | C31: A | D31: C | E31: 4887 | F31: Joerg Stieber | G31: 4887
A32: 2010 | B32: Canadian National Soaring Championships (FAI) | C32: A | D32: C | E32: 4887 | F32: Nick Bonniere | G32: 4381
A33: 2010 | B33: Canadian National Soaring Championships (FAI) | C33: A | D33: C | E33: 4887 | F33: Dennis Vreeken | G33: 4281
A34: 2010 | B34: Canadian National Soaring Championships (FAI) | C34: A | D34: C | E34: 4887 | F34: Derek Mackie | G34: 4260
A35: 2010 | B35: Canadian National Soaring Championships (FAI) | C35: A | D35: C | E35: 4887 | F35: Mike Thompson | G35: 4143
A36: 2010 | B36: Canadian National Soaring Championships (FAI) | C36: A | D36: C | E36: 4887 | F36: Luke Szczepaniak | G36: 4139
A37: 2010 | B37: Canadian National Soaring Championships (FAI) | C37: A | D37: C | E37: 4887 | F37: Dave Springford | G37: 4093
A38: 2010 | B38: Canadian National Soaring Championships (FAI) | C38: A | D38: C | E38: 4887 | F38: Ryszard Gatkiewicz | G38: 3894
A39: 2010 | B39: Canadian National Soaring Championships (FAI) | C39: A | D39: C | E39: 4887 | F39: John Mulder | G39: 3722
... A54: 2010 | B54: US Sport Nationals | C54: P | D54: F | E54: 8069 | F54: Wilf Krueger | G54: 6199
A55: 2010 | B55: US 15m Nationals | C55: 15 | D55: F | E55: 7817 | F55: Dale Kramer | G55: 7517
A56: 2010 | B56: US 15m Nationals | C56: 15 | D56: F | E56: 7817 | F56: Nick Bonniere | G56: 7027
A57: 2010 | B57: US 18m Nationals | C57: 18 | D57: F | E57: 3315 | F57: Jerzy Szemplinski | G57: 3078
A58: 2010 | B58: US 18m Nationals | C58: 18 | D58: F | E58: 3315 | F58: Ed Hollistelle Sr. | G58: 2690
A59: 2010 | B59: US 18m Nationals | C59: 18 | D59: F | E59: 3315 | F59: Dale Kramer | G59: 2544
A60: 2010 | B60: US Open Nationals | C60: O | D60: F | E60: 2125 | F60: Brian Milner | G60: 1778
A61: 2010 | B61: Flatland Cup (Hungarian Open Nationals) | C61: O | D61: F | E61: 8392 | F61: Willem Langelaan | G61: 4516
A62: 2010 | B62: WGC 15m | C62: 15 | D62: W | E62: 5959 | F62: Dave Springford | G62: 4088
A63: 2010 | B63: WGC 18m | C63: 18 | D63: W | E63: 6279 | F63: Jerzy Szemplinski | G63: 5898
...

Sheet Racing Results
A1: Racing Results | J1: Can Nats = | K1: C | L1: 1
J2: WGC = | K2: W | L2: 1.12
J3: PWGC = | K3: P | L3: 1.1
J4: EGC = | K4: E | L4: 1.1
A5: ='Raw Results'!$A$2 -> 2011 | J5: US Nats + = | K5: F | L5: 1.05
A6: ='Raw Results'!A3 -> Year | B6: ='Raw Results'!B3 -> Competition | C6: ='Raw Results'!C3 -> Class | D6: ='Raw Results'!D3 -> Comp Code | E6: ='Raw Results'!E3 -> Winner Score | F6: ='Raw Results'!F3 -> Name | G6: ='Raw Results'!G3 -> Pilot Score | H6: Result vs Winner | I6: Comp Factor | J6: =F6 -> Name | K6: Comp Code | L6: Class Code | M6: Term Code | N6: Factored Result
A7: ='Raw Results'!A4 -> 2009 | B7: ='Raw Results'!B4 -> Canadian National Soaring Championships (FAI) | C7: ='Raw Results'!C4 -> A | D7: ='Raw Results'!D4 -> C | E7: ='Raw Results'!E4 -> 4556 | F7: ='Raw Results'!F4 -> Dave Springford | G7: ='Raw Results'!G4 -> 4556 | H7: =G7/E7 -> 1 | I7: =IF(D7="C",$L$1,IF(D7="W",$L$2,IF(D7="P",$L$3,IF(D7="E",$L$4, IF(D7="F",$L$5,"Error"))))) -> 1 | J7: =F7 -> Dave Springford | K7: =D7 -> C | L7: =IF(C7="C","C",IF(OR(C7="A",C7="O",C7=18, C7=15, C7="S"),"A","B")) -> A | M7: =IF(AND(A7=$A$5,OR(D7="C",D7="W",D7="P")),1,2) -> 2 | N7: =H7*I7 -> 1
A8: ='Raw Results'!A5 -> 2009 | B8: ='Raw Results'!B5 -> Canadian National Soaring Championships (FAI) | C8: ='Raw Results'!C5 -> A | D8: ='Raw Results'!D5 -> C | E8: ='Raw Results'!E5 -> 4556 | F8: ='Raw Results'!F5 -> Jerzy Szemplinski | G8: ='Raw Results'!G5 -> 4526 | H8: =G8/E8 -> 0.99341528 | I8: =IF(D8="C",$L$1,IF(D8="W",$L$2,IF(D8="P",$L$3,IF(D8="E",$L$4, IF(D8="F",$L$5,"Error"))))) -> 1 | J8: =F8 -> Jerzy Szemplinski | K8: =D8 -> C | L8: =IF(C8="C","C",IF(OR(C8="A",C8="O",C8=18, C8=15, C8="S"),"A","B")) -> A | M8: =IF(AND(A8=$A$5,OR(D8="C",D8="W",D8="P")),1,2) -> 2 | N8: =H8*I8 -> 0.99341528
A9: ='Raw Results'!A6 -> 2009 | B9: ='Raw Results'!B6 -> Canadian National Soaring Championships (FAI) | C9: ='Raw Results'!C6 -> A | D9: ='Raw Results'!D6 -> C | E9: ='Raw Results'!E6 -> 4556 | F9: ='Raw Results'!F6 -> Willem Langelaan | G9: ='Raw Results'!G6 -> 4417 | H9: =G9/E9 -> 0.96949078 | I9: =IF(D9="C",$L$1,IF(D9="W",$L$2,IF(D9="P",$L$3,IF(D9="E",$L$4, IF(D9="F",$L$5,"Error"))))) -> 1 | J9: =F9 -> Willem Langelaan | K9: =D9 -> C | L9: =IF(C9="C","C",IF(OR(C9="A",C9="O",C9=18, C9=15, C9="S"),"A","B")) -> A | M9: =IF(AND(A9=$A$5,OR(D9="C",D9="W",D9="P")),1,2) -> 2 | N9: =H9*I9 -> 0.96949078
A10: ='Raw Results'!A7 -> 2009 | B10: ='Raw Results'!B7 -> Canadian National Soaring Championships (FAI) | C10: ='Raw Results'!C7 -> A | D10: ='Raw Results'!D7 -> C | E10: ='Raw Results'!E7 -> 4556 | F10: ='Raw Results'!F7 -> Nick Bonniere | G10: ='Raw Results'!G7 -> 4271 | H10: =G10/E10 -> 0.93744513 | I10: =IF(D10="C",$L$1,IF(D10="W",$L$2,IF(D10="P",$L$3,IF(D10="E",$L$4, IF(D10="F",$L$5,"Error"))))) -> 1 | J10: =F10 -> Nick Bonniere | K10: =D10 -> C | L10: =IF(C10="C","C",IF(OR(C10="A",C10="O",C10=18, C10=15, C10="S"),"A","B")) -> A | M10: =IF(AND(A10=$A$5,OR(D10="C",D10="W",D10="P")),1,2) -> 2 | N10: =H10*I10 -> 0.93744513
A11: ='Raw Results'!A8 -> 2009 | B11: ='Raw Results'!B8 -> Canadian National Soaring Championships (FAI) | C11: ='Raw Results'!C8 -> A | D11: ='Raw Results'!D8 -> C | E11: ='Raw Results'!E8 -> 4556 | F11: ='Raw Results'!F8 -> Joerg Stieber | G11: ='Raw Results'!G8 -> 4251 | H11: =G11/E11 -> 0.93305531 | I11: =IF(D11="C",$L$1,IF(D11="W",$L$2,IF(D11="P",$L$3,IF(D11="E",$L$4, IF(D11="F",$L$5,"Error"))))) -> 1 | J11: =F11 -> Joerg Stieber | K11: =D11 -> C | L11: =IF(C11="C","C",IF(OR(C11="A",C11="O",C11=18, C11=15, C11="S"),"A","B")) -> A | M11: =IF(AND(A11=$A$5,OR(D11="C",D11="W",D11="P")),1,2) -> 2 | N11: =H11*I11 -> 0.93305531
A12: ='Raw Results'!A9 -> 2009 | B12: ='Raw Results'!B9 -> Canadian National Soaring Championships (FAI) | C12: ='Raw Results'!C9 -> A | D12: ='Raw Results'!D9 -> C | E12: ='Raw Results'!E9 -> 4556 | F12: ='Raw Results'!F9 -> Ed Hollistelle Sr. | G12: ='Raw Results'!G9 -> 4229 | H12: =G12/E12 -> 0.92822651 | I12: =IF(D12="C",$L$1,IF(D12="W",$L$2,IF(D12="P",$L$3,IF(D12="E",$L$4, IF(D12="F",$L$5,"Error"))))) -> 1 | J12: =F12 -> Ed Hollistelle Sr. | K12: =D12 -> C | L12: =IF(C12="C","C",IF(OR(C12="A",C12="O",C12=18, C12=15, C12="S"),"A","B")) -> A | M12: =IF(AND(A12=$A$5,OR(D12="C",D12="W",D12="P")),1,2) -> 2 | N12: =H12*I12 -> 0.92822651
A13: ='Raw Results'!A10 -> 2009 | B13: ='Raw Results'!B10 -> Canadian National Soaring Championships (FAI) | C13: ='Raw Results'!C10 -> A | D13: ='Raw Results'!D10 -> C | E13: ='Raw Results'!E10 -> 4556 | F13: ='Raw Results'!F10 -> Sergei Morozov | G13: ='Raw Results'!G10 -> 3674 | H13: =G13/E13 -> 0.80640913 | I13: =IF(D13="C",$L$1,IF(D13="W",$L$2,IF(D13="P",$L$3,IF(D13="E",$L$4, IF(D13="F",$L$5,"Error"))))) -> 1 | J13: =F13 -> Sergei Morozov | K13: =D13 -> C | L13: =IF(C13="C","C",IF(OR(C13="A",C13="O",C13=18, C13=15, C13="S"),"A","B")) -> A | M13: =IF(AND(A13=$A$5,OR(D13="C",D13="W",D13="P")),1,2) -> 2 | N13: =H13*I13 -> 0.80640913
A14: ='Raw Results'!A11 -> 2009 | B14: ='Raw Results'!B11 -> Canadian National Soaring Championships (FAI) | C14: ='Raw Results'!C11 -> A | D14: ='Raw Results'!D11 -> C | E14: ='Raw Results'!E11 -> 4556 | F14: ='Raw Results'!F11 -> Steve Burany | G14: ='Raw Results'!G11 -> 2058 | H14: =G14/E14 -> 0.45171203 | I14: =IF(D14="C",$L$1,IF(D14="W",$L$2,IF(D14="P",$L$3,IF(D14="E",$L$4, IF(D14="F",$L$5,"Error"))))) -> 1 | J14: =F14 -> Steve Burany | K14: =D14 -> C | L14: =IF(C14="C","C",IF(OR(C14="A",C14="O",C14=18, C14=15, C14="S"),"A","B")) -> A | M14: =IF(AND(A14=$A$5,OR(D14="C",D14="W",D14="P")),1,2) -> 2 | N14: =H14*I14 -> 0.45171203
A15: ='Raw Results'!A12 -> 2009 | B15: ='Raw Results'!B12 -> Canadian National Soaring Championships (FAI) | C15: ='Raw Results'!C12 -> A | D15: ='Raw Results'!D12 -> C | E15: ='Raw Results'!E12 -> 4556 | F15: ='Raw Results'!F12 -> Roger Hildesheim | G15: ='Raw Results'!G12 -> 1989 | H15: =G15/E15 -> 0.43656716 | I15: =IF(D15="C",$L$1,IF(D15="W",$L$2,IF(D15="P",$L$3,IF(D15="E",$L$4, IF(D15="F",$L$5,"Error"))))) -> 1 | J15: =F15 -> Roger Hildesheim | K15: =D15 -> C | L15: =IF(C15="C","C",IF(OR(C15="A",C15="O",C15=18, C15=15, C15="S"),"A","B")) -> A | M15: =IF(AND(A15=$A$5,OR(D15="C",D15="W",D15="P")),1,2) -> 2 | N15: =H15*I15 -> 0.43656716
A16: ='Raw Results'!A13 -> 2009 | B16: ='Raw Results'!B13 -> Canadian National Soaring Championships (CLUB) | C16: ='Raw Results'!C13 -> B | D16: ='Raw Results'!D13 -> C | E16: ='Raw Results'!E13 -> 4336 | F16: ='Raw Results'!F13 -> Anthony Kawzowicz | G16: ='Raw Results'!G13 -> 4336 | H16: =G16/E16 -> 1 | I16: =IF(D16="C",$L$1,IF(D16="W",$L$2,IF(D16="P",$L$3,IF(D16="E",$L$4, IF(D16="F",$L$5,"Error"))))) -> 1 | J16: =F16 -> Anthony Kawzowicz | K16: =D16 -> C | L16: =IF(C16="C","C",IF(OR(C16="A",C16="O",C16=18, C16=15, C16="S"),"A","B")) -> B | M16: =IF(AND(A16=$A$5,OR(D16="C",D16="W",D16="P")),1,2) -> 2 | N16: =H16*I16 -> 1
A17: ='Raw Results'!A14 -> 2009 | B17: ='Raw Results'!B14 -> Canadian National Soaring Championships (CLUB) | C17: ='Raw Results'!C14 -> B | D17: ='Raw Results'!D14 -> C | E17: ='Raw Results'!E14 -> 4336 | F17: ='Raw Results'!F14 -> Derek Mackie | G17: ='Raw Results'!G14 -> 3704 | H17: =G17/E17 -> 0.85424354 | I17: =IF(D17="C",$L$1,IF(D17="W",$L$2,IF(D17="P",$L$3,IF(D17="E",$L$4, IF(D17="F",$L$5,"Error"))))) -> 1 | J17: =F17 -> Derek Mackie | K17: =D17 -> C | L17: =IF(C17="C","C",IF(OR(C17="A",C17="O",C17=18, C17=15, C17="S"),"A","B")) -> B | M17: =IF(AND(A17=$A$5,OR(D17="C",D17="W",D17="P")),1,2) -> 2 | N17: =H17*I17 -> 0.85424354
A18: ='Raw Results'!A15 -> 2009 | B18: ='Raw Results'!B15 -> Canadian National Soaring Championships (CLUB) | C18: ='Raw Results'!C15 -> B | D18: ='Raw Results'!D15 -> C | E18: ='Raw Results'!E15 -> 4336 | F18: ='Raw Results'!F15 -> Alf Marcelissen | G18: ='Raw Results'!G15 -> 3699 | H18: =G18/E18 -> 0.85309041 | I18: =IF(D18="C",$L$1,IF(D18="W",$L$2,IF(D18="P",$L$3,IF(D18="E",$L$4, IF(D18="F",$L$5,"Error"))))) -> 1 | J18: =F18 -> Alf Marcelissen | K18: =D18 -> C | L18: =IF(C18="C","C",IF(OR(C18="A",C18="O",C18=18, C18=15, C18="S"),"A","B")) -> B | M18: =IF(AND(A18=$A$5,OR(D18="C",D18="W",D18="P")),1,2) -> 2 | N18: =H18*I18 -> 0.85309041
... A114: ='Raw Results'!A111 -> 2011 | B114: ='Raw Results'!B111 -> JWGC | C114: ='Raw Results'!C111 -> C | D114: ='Raw Results'!D111 -> W | E114: ='Raw Results'!E111 -> 4536 | F114: ='Raw Results'!F111 -> Selena Boyle | G114: ='Raw Results'!G111 -> 1654 | H114: =G114/E114 -> 0.36463845 | I114: =IF(D114="C",$L$1,IF(D114="W",$L$2,IF(D114="P",$L$3,IF(D114="E",$L$4, IF(D114="F",$L$5,"Error"))))) -> 1.12 | J114: =F114 -> Selena Boyle | K114: =D114 -> W | L114: =IF(C114="C","C",IF(OR(C114="A",C114="O",C114=18, C114=15, C114="S"),"A","B")) -> C | M114: =IF(AND(A114=$A$5,OR(D114="C",D114="W",D114="P")),1,2) -> 1 | N114: =H114*I114 -> 0.40839506

Sheet Scoring
A1: Scoring
A2: Sort White Cells by: | B2: 1. Name (Lowest - Highest) | K2: Seeding Weights
B3: 2. Term Code (lowest- highest) | K3: Term 1 | L3: 60
B4: 3. Term 1 (highest - lowest) | K4: Term 2 | L4: 40
A5: Delete: | B5: 1. Pilots without Comp Code C contest | K5: Total | L5: =L3+L4 -> 100
B6: 2. Teams
A7: Section 1 Keep: | B7: Best result with Term Code = 1 AND Country Code = C, W or P
A8: Section 2 cut&paste: | B8: Next best result. If Section 1 is not Country Code C, then Section 2 must be Country Code C.
A9: Delete: | B9: Remaining contest results | K9: FAI
A10: Cleanup: | B10: Section 3 by Copy&Paste of the "Seed Formatting" line to the rest of the pink section | K10: Club
K11: ERROR: No Can Nats
A12: Section 1 | F12: Section 2 | J12: Section 3
A13: ='Racing Results'!J6 -> Name | B13: ='Racing Results'!K6 -> Comp Code | C13: ='Racing Results'!L6 -> Class Code | D13: ='Racing Results'!M6 -> Term Code | E13: Term 1 | F13: ='Racing Results'!K6 -> Comp Code | G13: ='Racing Results'!L6 -> Class Code | H13: ='Racing Results'!M6 -> Term Code | I13: Term 2 | J13: =A13 -> Name | K13: SEEDING GROUP | L13: Seeding Points
A14: Seed Formatting | J14: =A14 -> Seed Formatting | K14: =IF($C14="",$G14,$C14) -> 0 | L14: =$L$3*E14+$L$4*I14 -> 0
A15: ='Racing Results'!J48 -> Al Hoar | F15: ='Racing Results'!K48 -> C | G15: ='Racing Results'!L48 -> B | H15: ='Racing Results'!M48 -> 2 | I15: ='Racing Results'!N48 -> 0.8003876 | J15: =A15 -> Al Hoar | K15: =IF($C15="",$G15,$C15) -> B | L15: =$L$3*E15+$L$4*I15 -> 32.015504
A16: ='Racing Results'!J87 -> Alf Marcelissen | B16: ='Racing Results'!K87 -> C | C16: ='Racing Results'!L87 -> B | D16: ='Racing Results'!M87 -> 1 | E16: ='Racing Results'!N87 -> 0.73496659 | F16: ='Racing Results'!K18 -> C | G16: ='Racing Results'!L18 -> B | H16: ='Racing Results'!M18 -> 2 | I16: ='Racing Results'!N18 -> 0.85309041 | J16: =A16 -> Alf Marcelissen | K16: =IF($C16="",$G16,$C16) -> B | L16: =$L$3*E16+$L$4*I16 -> 78.221612
A17: ='Racing Results'!J72 -> Andrzej Kobus | B17: ='Racing Results'!K72 -> C | C17: ='Racing Results'!L72 -> A | D17: ='Racing Results'!M72 -> 1 | E17: ='Racing Results'!N72 -> 0.89565767 | F17: ='Racing Results'!K28 -> F | G17: ='Racing Results'!L28 -> B | H17: ='Racing Results'!M28 -> 2 | I17: ='Racing Results'!N28 -> 0.52212004 | J17: =A17 -> Andrzej Kobus | K17: =IF($C17="",$G17,$C17) -> A | L17: =$L$3*E17+$L$4*I17 -> 74.624262
A18: ='Racing Results'!J80 -> Anthony Kawzowicz | B18: ='Racing Results'!K80 -> C | C18: ='Racing Results'!L80 -> B | D18: ='Racing Results'!M80 -> 1 | E18: ='Racing Results'!N80 -> 0.89615813 | F18: ='Racing Results'!K16 -> C | G18: ='Racing Results'!L16 -> B | H18: ='Racing Results'!M16 -> 2 | I18: ='Racing Results'!N16 -> 1 | J18: =A18 -> Anthony Kawzowicz | K18: =IF($C18="",$G18,$C18) -> B | L18: =$L$3*E18+$L$4*I18 -> 93.769488
A19: ='Racing Results'!J83 -> Bill Cole | B19: ='Racing Results'!K83 -> C | C19: ='Racing Results'!L83 -> B | D19: ='Racing Results'!M83 -> 1 | E19: ='Racing Results'!N83 -> 0.79398664 | F19: ='Racing Results'!K44 -> C | G19: ='Racing Results'!L44 -> B | H19: ='Racing Results'!M44 -> 2 | I19: ='Racing Results'!N44 -> 1 | J19: =A19 -> Bill Cole | K19: =IF($C19="",$G19,$C19) -> B | L19: =$L$3*E19+$L$4*I19 -> 87.639198
A20: ='Racing Results'!J46 -> Bruce Friesen | F20: ='Racing Results'!K46 -> C | G20: ='Racing Results'!L46 -> B | H20: ='Racing Results'!M46 -> 2 | I20: ='Racing Results'!N46 -> 0.83677864 | J20: =A20 -> Bruce Friesen | K20: =IF($C20="",$G20,$C20) -> B | L20: =$L$3*E20+$L$4*I20 -> 33.471146
A21: ='Racing Results'!J52 -> Carol Mulder | F21: ='Racing Results'!K52 -> C | G21: ='Racing Results'!L52 -> B | H21: ='Racing Results'!M52 -> 2 | I21: ='Racing Results'!N52 -> 0.53165375 | J21: =A21 -> Carol Mulder | K21: =IF($C21="",$G21,$C21) -> B | L21: =$L$3*E21+$L$4*I21 -> 21.26615
A22: ='Racing Results'!J79 -> Chris Gough | B22: ='Racing Results'!K79 -> C | C22: ='Racing Results'!L79 -> B | D22: ='Racing Results'!M79 -> 1 | E22: ='Racing Results'!N79 -> 1 | F22: ='Racing Results'!K33 -> W | G22: ='Racing Results'!L33 -> C | H22: ='Racing Results'!M33 -> 2 | I22: ='Racing Results'!N33 -> 0.79031373 | J22: =A22 -> Chris Gough | K22: =IF($C22="",$G22,$C22) -> B | L22: =$L$3*E22+$L$4*I22 -> 91.612549
A23: ='Racing Results'!J90 -> Dan Cook | B23: ='Racing Results'!K90 -> C | C23: ='Racing Results'!L90 -> B | D23: ='Racing Results'!M90 -> 1 | E23: ='Racing Results'!N90 -> 0.65144766 | F23: ='Racing Results'!K43 -> C | G23: ='Racing Results'!L43 -> A | H23: ='Racing Results'!M43 -> 2 | I23: ='Racing Results'!N43 -> 0.41804788 | J23: =A23 -> Dan Cook | K23: =IF($C23="",$G23,$C23) -> B | L23: =$L$3*E23+$L$4*I23 -> 55.808775
A24: ='Racing Results'!J86 -> Dave Cole | B24: ='Racing Results'!K86 -> C | C24: ='Racing Results'!L86 -> B | D24: ='Racing Results'!M86 -> 1 | E24: ='Racing Results'!N86 -> 0.75835189 | F24: ='Racing Results'!K25 -> C | G24: ='Racing Results'!L25 -> B | H24: ='Racing Results'!M25 -> 2 | I24: ='Racing Results'!N25 -> 0.49561808 | J24: =A24 -> Dave Cole | K24: =IF($C24="",$G24,$C24) -> B | L24: =$L$3*E24+$L$4*I24 -> 65.325837
A25: ='Racing Results'!J108 -> Dave Springford | B25: ='Racing Results'!K108 -> P | C25: ='Racing Results'!L108 -> A | D25: ='Racing Results'!M108 -> 1 | E25: ='Racing Results'!N108 -> 1.0534734 | F25: ='Racing Results'!K7 -> C | G25: ='Racing Results'!L7 -> A | H25: ='Racing Results'!M7 -> 2 | I25: ='Racing Results'!N7 -> 1 | J25: =A25 -> Dave Springford | K25: =IF($C25="",$G25,$C25) -> A | L25: =$L$3*E25+$L$4*I25 -> 103.2084
A26: ='Racing Results'!J36 -> Dennis Vreeken | F26: ='Racing Results'!K36 -> C | G26: ='Racing Results'!L36 -> A | H26: ='Racing Results'!M36 -> 2 | I26: ='Racing Results'!N36 -> 0.87599754 | J26: =A26 -> Dennis Vreeken | K26: =IF($C26="",$G26,$C26) -> A | L26: =$L$3*E26+$L$4*I26 -> 35.039902
A27: ='Racing Results'!J70 -> Derek Mackie | B27: ='Racing Results'!K70 -> C | C27: ='Racing Results'!L70 -> A | D27: ='Racing Results'!M70 -> 1 | E27: ='Racing Results'!N70 -> 0.92706577 | F27: ='Racing Results'!K37 -> C | G27: ='Racing Results'!L37 -> A | H27: ='Racing Results'!M37 -> 2 | I27: ='Racing Results'!N37 -> 0.87170043 | J27: =A27 -> Derek Mackie | K27: =IF($C27="",$G27,$C27) -> A | L27: =$L$3*E27+$L$4*I27 -> 90.491963
A28: ='Racing Results'!J75 -> Ed Hollistelle Sr. | B28: ='Racing Results'!K75 -> C | C28: ='Racing Results'!L75 -> A | D28: ='Racing Results'!M75 -> 1 | E28: ='Racing Results'!N75 -> 0.83199831 | F28: ='Racing Results'!K12 -> C | G28: ='Racing Results'!L12 -> A | H28: ='Racing Results'!M12 -> 2 | I28: ='Racing Results'!N12 -> 0.92822651 | J28: =A28 -> Ed Hollistelle Sr. | K28: =IF($C28="",$G28,$C28) -> A | L28: =$L$3*E28+$L$4*I28 -> 87.048959
A29: ='Racing Results'!J94 -> Emmanuael Cadieux | B29: ='Racing Results'!K94 -> C | C29: ='Racing Results'!L94 -> B | D29: ='Racing Results'!M94 -> 1 | E29: ='Racing Results'!N94 -> 0.36525612 | J29: =A29 -> Emmanuael Cadieux | K29: =IF($C29="",$G29,$C29) -> B | L29: =$L$3*E29+$L$4*I29 -> 21.915367
A30: ='Racing Results'!J56 -> Frank Cwikla | F30: ='Racing Results'!K56 -> C | G30: ='Racing Results'!L56 -> B | H30: ='Racing Results'!M56 -> 2 | I30: ='Racing Results'!N56 -> 0.15288544 | J30: =A30 -> Frank Cwikla | K30: =IF($C30="",$G30,$C30) -> B | L30: =$L$3*E30+$L$4*I30 -> 6.1154177
A31: ='Racing Results'!J47 -> Guy Blood | F31: ='Racing Results'!K47 -> C | G31: ='Racing Results'!L47 -> B | H31: ='Racing Results'!M47 -> 2 | I31: ='Racing Results'!N47 -> 0.8249354 | J31: =A31 -> Guy Blood | K31: =IF($C31="",$G31,$C31) -> B | L31: =$L$3*E31+$L$4*I31 -> 32.997416
A32: ='Racing Results'!J55 -> Hank Hees | F32: ='Racing Results'!K55 -> C | G32: ='Racing Results'!L55 -> B | H32: ='Racing Results'!M55 -> 2 | I32: ='Racing Results'!N55 -> 0.37295435 | J32: =A32 -> Hank Hees | K32: =IF($C32="",$G32,$C32) -> B | L32: =$L$3*E32+$L$4*I32 -> 14.918174
A33: ='Racing Results'!J96 -> Hans Juergensen | B33: ='Racing Results'!K96 -> C | C33: ='Racing Results'!L96 -> B | D33: ='Racing Results'!M96 -> 1 | E33: ='Racing Results'!N96 -> 0.22577951 | J33: =A33 -> Hans Juergensen | K33: =IF($C33="",$G33,$C33) -> B | L33: =$L$3*E33+$L$4*I33 -> 13.546771
A34: ='Racing Results'!J99 -> Herrie ten Cate | B34: ='Racing Results'!K99 -> C | C34: ='Racing Results'!L99 -> C | D34: ='Racing Results'!M99 -> 1 | E34: ='Racing Results'!N99 -> 0.74344023 | J34: =A34 -> Herrie ten Cate | K34: =IF($C34="",$G34,$C34) -> C | L34: =$L$3*E34+$L$4*I34 -> 44.606414
A35: ='Racing Results'!J103 -> Jay Allardyce | B35: ='Racing Results'!K103 -> C | C35: ='Racing Results'!L103 -> C | D35: ='Racing Results'!M103 -> 1 | E35: ='Racing Results'!N103 -> 0.31516035 | J35: =A35 -> Jay Allardyce | K35: =IF($C35="",$G35,$C35) -> C | L35: =$L$3*E35+$L$4*I35 -> 18.909621
A36: ='Racing Results'!J69 -> Jerzy Szemplinski | B36: ='Racing Results'!K69 -> C | C36: ='Racing Results'!L69 -> A | D36: ='Racing Results'!M69 -> 1 | E36: ='Racing Results'!N69 -> 1 | F36: ='Racing Results'!K66 -> W | G36: ='Racing Results'!L66 -> A | H36: ='Racing Results'!M66 -> 2 | I36: ='Racing Results'!N66 -> 1.0520401 | J36: =A36 -> Jerzy Szemplinski | K36: =IF($C36="",$G36,$C36) -> A | L36: =$L$3*E36+$L$4*I36 -> 102.08161
A37: ='Racing Results'!J78 -> Jim Carpenter | B37: ='Racing Results'!K78 -> C | C37: ='Racing Results'!L78 -> A | D37: ='Racing Results'!M78 -> 1 | E37: ='Racing Results'!N78 -> 0.09148398 | J37: =A37 -> Jim Carpenter | K37: =IF($C37="",$G37,$C37) -> A | L37: =$L$3*E37+$L$4*I37 -> 5.4890388
A38: ='Racing Results'!J98 -> Jim Freyett | B38: ='Racing Results'!K98 -> C | C38: ='Racing Results'!L98 -> C | D38: ='Racing Results'!M98 -> 1 | E38: ='Racing Results'!N98 -> 0.86851312 | F38: ='Racing Results'!K20 -> C | G38: ='Racing Results'!L20 -> B | H38: ='Racing Results'!M20 -> 2 | I38: ='Racing Results'!N20 -> 0.76337638 | J38: =A38 -> Jim Freyett | K38: =IF($C38="",$G38,$C38) -> C | L38: =$L$3*E38+$L$4*I38 -> 82.645843
A39: ='Racing Results'!J109 -> Joerg Stieber | B39: ='Racing Results'!K109 -> P | C39: ='Racing Results'!L109 -> A | D39: ='Racing Results'!M109 -> 1 | E39: ='Racing Results'!N109 -> 0.93715686 | F39: ='Racing Results'!K34 -> C | G39: ='Racing Results'!L34 -> A | H39: ='Racing Results'!M34 -> 2 | I39: ='Racing Results'!N34 -> 1 | J39: =A39 -> Joerg Stieber | K39: =IF($C39="",$G39,$C39) -> A | L39: =$L$3*E39+$L$4*I39 -> 96.229412
A40: ='Racing Results'!J82 -> John Brennan | B40: ='Racing Results'!K82 -> C | C40: ='Racing Results'!L82 -> B | D40: ='Racing Results'!M82 -> 1 | E40: ='Racing Results'!N82 -> 0.82433185 | F40: ='Racing Results'!K22 -> C | G40: ='Racing Results'!L22 -> B | H40: ='Racing Results'!M22 -> 2 | I40: ='Racing Results'!N22 -> 0.72117159 | J40: =A40 -> John Brennan | K40: =IF($C40="",$G40,$C40) -> B | L40: =$L$3*E40+$L$4*I40 -> 78.306774
...

Sheet Seeding List
B1: Seeding List
B2: Rank | C2: NAME | D2: SEEDING GROUP | E2: SEEDING POINTS
A3: Group A | B3: 1 | C3: =Scoring!J25 -> Dave Springford | D3: =Scoring!K25 -> A | E3: =Scoring!L25 -> 103.2084
B4: 2 | C4: =Scoring!J36 -> Jerzy Szemplinski | D4: =Scoring!K36 -> A | E4: =Scoring!L36 -> 102.08161
B5: 3 | C5: =Scoring!J39 -> Joerg Stieber | D5: =Scoring!K39 -> A | E5: =Scoring!L39 -> 96.229412
B6: 4 | C6: =Scoring!J50 -> Nick Bonniere | D6: =Scoring!K50 -> A | E6: =Scoring!L50 -> 92.582555
B7: 5 | C7: =Scoring!J27 -> Derek Mackie | D7: =Scoring!K27 -> A | E7: =Scoring!L27 -> 90.491963
B8: 6 | C8: =Scoring!J28 -> Ed Hollistelle Sr. | D8: =Scoring!K28 -> A | E8: =Scoring!L28 -> 87.048959
B9: 7 | C9: =Scoring!J64 -> Willem Langelaan | D9: =Scoring!K64 -> A | E9: =Scoring!L64 -> 77.101722
B10: 8 | C10: =Scoring!J17 -> Andrzej Kobus | D10: =Scoring!K17 -> A | E10: =Scoring!L17 -> 74.624262
B11: 9 | C11: =Scoring!J26 -> Dennis Vreeken | D11: =Scoring!K26 -> A | E11: =Scoring!L26 -> 35.039902
B12: 10 | C12: =Scoring!J49 -> Mike Thompson | D12: =Scoring!K49 -> A | E12: =Scoring!L49 -> 33.910374
B13: 11 | C13: =Scoring!J58 -> Ryszard Gatkiewicz | D13: =Scoring!K58 -> A | E13: =Scoring!L58 -> 31.872314
B14: 12 | C14: =Scoring!J61 -> Steve Burany | D14: =Scoring!K61 -> A | E14: =Scoring!L61 -> 18.068481
B15: 13 | C15: =Scoring!J44 -> Leo Deschamps | D15: =Scoring!K44 -> A | E15: =Scoring!L44 -> 12.533727
B16: 14 | C16: =Scoring!J37 -> Jim Carpenter | D16: =Scoring!K37 -> A | E16: =Scoring!L37 -> 5.4890388
A17: Group B | B17: 1 | C17: =Scoring!J18 -> Anthony Kawzowicz | D17: =Scoring!K18 -> B | E17: =Scoring!L18 -> 93.769488
B18: 2 | C18: =Scoring!J22 -> Chris Gough | D18: =Scoring!K22 -> B | E18: =Scoring!L22 -> 91.612549
B19: 3 | C19: =Scoring!J19 -> Bill Cole | D19: =Scoring!K19 -> B | E19: =Scoring!L19 -> 87.639198
B20: 4 | C20: =Scoring!J45 -> Luke Szczepaniak | D20: =Scoring!K45 -> B | E20: =Scoring!L45 -> 80.330864
B21: 5 | C21: =Scoring!J60 -> Sergei Morozov | D21: =Scoring!K60 -> B | E21: =Scoring!L60 -> 79.845452
B22: 6 | C22: =Scoring!J40 -> John Brennan | D22: =Scoring!K40 -> B | E22: =Scoring!L40 -> 78.306774
B23: 7 | C23: =Scoring!J16 -> Alf Marcelissen | D23: =Scoring!K16 -> B | E23: =Scoring!L16 -> 78.221612
B24: 8 | C24: =Scoring!J41 -> John Mulder | D24: =Scoring!K41 -> B | E24: =Scoring!L41 -> 69.501246
B25: 9 | C25: =Scoring!J24 -> Dave Cole | D25: =Scoring!K24 -> B | E25: =Scoring!L24 -> 65.325837
B26: 10 | C26: =Scoring!J55 -> Roger Hildesheim | D26: =Scoring!K55 -> B | E26: =Scoring!L55 -> 59.138633
B27: 11 | C27: =Scoring!J23 -> Dan Cook | D27: =Scoring!K23 -> B | E27: =Scoring!L23 -> 55.808775
B28: 12 | C28: =Scoring!J51 -> Paul Fish | D28: =Scoring!K51 -> B | E28: =Scoring!L51 -> 51.998886
B29: 13 | C29: =Scoring!J46 -> Marian Nowak | D29: =Scoring!K46 -> B | E29: =Scoring!L46 -> 43.329621
B30: 14 | C30: =Scoring!J47 -> Martin Brassard | D30: =Scoring!K47 -> B | E30: =Scoring!L47 -> 38.886414
B31: 15 | C31: =Scoring!J63 -> Tony Burton | D31: =Scoring!K63 -> B | E31: =Scoring!L63 -> 35.116279
B32: 16 | C32: =Scoring!J42 -> Krzysztof Wiercioch | D32: =Scoring!K42 -> B | E32: =Scoring!L42 -> 34.075724
B33: 17 | C33: =Scoring!J20 -> Bruce Friesen | D33: =Scoring!K20 -> B | E33: =Scoring!L20 -> 33.471146
B34: 18 | C34: =Scoring!J31 -> Guy Blood | D34: =Scoring!K31 -> B | E34: =Scoring!L31 -> 32.997416
B35: 19 | C35: =Scoring!J15 -> Al Hoar | D35: =Scoring!K15 -> B | E35: =Scoring!L15 -> 32.015504
B36: 20 | C36: =Scoring!J43 -> Larry Springford | D36: =Scoring!K43 -> B | E36: =Scoring!L43 -> 31.669742
B37: 21 | C37: =Scoring!J56 -> Ron Cattaruzza | D37: =Scoring!K56 -> B | E37: =Scoring!L56 -> 26.709733
B38: 22 | C38: =Scoring!J53 -> Randy Neilsen | D38: =Scoring!K53 -> B | E38: =Scoring!L53 -> 24.538745
B39: 23 | C39: =Scoring!J57 -> Roy Eichendorf | D39: =Scoring!K57 -> B | E39: =Scoring!L57 -> 23.169681
B40: 24 | C40: =Scoring!J29 -> Emmanuael Cadieux | D40: =Scoring!K29 -> B | E40: =Scoring!L29 -> 21.915367
...
