Workbook
Name TARIFF: #REF!

Sheet Data
A1: fsc: | B1: fuel surcharge | C1: Tariff Rail Rates for Unit and Shuttle Train Shipments | L1: Tariff Rail Rates for Unit and Shuttle Train Shipments | U1: quarter
A2: tr: | B2: tariff rate | D2: = month at the end of a quarter | H2: = data that shows in the table | S2: quarterly | U2: over
F3: gtr | O3: tr plus fsc | P3: tr plus fsc | Q3: year over | R3: year over | S3: tr plus fsc | T3: quarter | U3: same quarter
E4: effective | F4: publication | J4: fsc | K4: tr per | L4: tr per | N4: tr plus fsc | O4: per | P4: per | Q4: year change | R4: year change | S4: per | T4: over quarter | U4: last year
A5: commodity | B5: origin | C5: destination | D5: train type | E5: date | F5: date | G5: tr per car | H5: mileage | I5: railroad | J5: per mile | K5: metric ton | L5: bushel | M5: fsc per car | N5: per car | O5: metric ton | P5: bushel | Q5: of tr | R5: of tr plus fsc | S5: metric ton | T5: change | U5: change | V5: Tariff document
A6: Wheat | B6: South Central KS | C6: St. Louis, MO | D6: unit | E6: 40330 | F6: 40339 | G6: 2774 | H6: 506 | I6: UP | J6: =IF(I6="BNSF",0.46,IF(I6="CN",0.1495,IF(I6="CSX",0.27,0.2))) -> 0.2 | K6: =G6/100.7 -> 27.54717 | L6: =IF(A6="corn",G6/(111*2000/56),G6/(111*2000/60)) -> 0.74972973 | M6: =H6*J6 -> 101.2 | N6: =G6+M6 -> 2875.2 | O6: =N6/100.7 -> 28.552135 | P6: =IF(A6="corn",N6/(111*2000/56),N6/(111*2000/60)) -> 0.77708108
A7: Wheat | B7: Grand Forks, ND | C7: Dulth-Superior, MN | D7: unit | E7: 40330 | F7: 40339 | G7: 2400 | H7: 298 | I7: BNSF | J7: =IF(I7="BNSF",0.46,IF(I7="CN",0.1495,IF(I7="CSX",0.27,0.2))) -> 0.46 | K7: =G7/100.7 -> 23.833168 | L7: =IF(A7="corn",G7/(111*2000/56),G7/(111*2000/60)) -> 0.64864865 | M7: =H7*J7 -> 137.08 | N7: =G7+M7 -> 2537.08 | O7: =N7/100.7 -> 25.194439 | P7: =IF(A7="corn",N7/(111*2000/56),N7/(111*2000/60)) -> 0.6856973
A8: Wheat | B8: South Central KS | C8: Los Angeles, CA | D8: unit | E8: 40330 | F8: 40339 | G8: 5047 | H8: 1530 | I8: BNSF | J8: =IF(I8="BNSF",0.46,IF(I8="CN",0.1495,IF(I8="CSX",0.27,0.2))) -> 0.46 | K8: =G8/100.7 -> 50.119166 | L8: =IF(A8="corn",G8/(111*2000/56),G8/(111*2000/60)) -> 1.3640541 | M8: =H8*J8 -> 703.8 | N8: =G8+M8 -> 5750.8 | O8: =N8/100.7 -> 57.108242 | P8: =IF(A8="corn",N8/(111*2000/56),N8/(111*2000/60)) -> 1.5542703
A9: Wheat | B9: South Central KS | C9: New Orleans, LA | D9: unit | E9: 40330 | F9: 40339 | G9: 3275 | H9: 890 | I9: UP | J9: =IF(I9="BNSF",0.46,IF(I9="CN",0.1495,IF(I9="CSX",0.27,0.2))) -> 0.2 | K9: =G9/100.7 -> 32.522344 | L9: =IF(A9="corn",G9/(111*2000/56),G9/(111*2000/60)) -> 0.88513514 | M9: =H9*J9 -> 178 | N9: =G9+M9 -> 3453 | O9: =N9/100.7 -> 34.28997 | P9: =IF(A9="corn",N9/(111*2000/56),N9/(111*2000/60)) -> 0.93324324
A10: Wheat | B10: Sioux Falls, SD | C10: Galveston-Houston, TX | D10: unit | E10: 40330 | F10: 40339 | G10: 4981 | H10: 1256 | I10: BNSF | J10: =IF(I10="BNSF",0.46,IF(I10="CN",0.1495,IF(I10="CSX",0.27,0.2))) -> 0.46 | K10: =G10/100.7 -> 49.463754 | L10: =IF(A10="corn",G10/(111*2000/56),G10/(111*2000/60)) -> 1.3462162 | M10: =H10*J10 -> 577.76 | N10: =G10+M10 -> 5558.76 | O10: =N10/100.7 -> 55.201192 | P10: =IF(A10="corn",N10/(111*2000/56),N10/(111*2000/60)) -> 1.5023676
A11: Wheat | B11: Northwest KS | C11: Galveston-Houston, TX | D11: unit | E11: 40330 | F11: 40339 | G11: 3543 | H11: 975 | I11: UP | J11: =IF(I11="BNSF",0.46,IF(I11="CN",0.1495,IF(I11="CSX",0.27,0.2))) -> 0.2 | K11: =G11/100.7 -> 35.183714 | L11: =IF(A11="corn",G11/(111*2000/56),G11/(111*2000/60)) -> 0.95756757 | M11: =H11*J11 -> 195 | N11: =G11+M11 -> 3738 | O11: =N11/100.7 -> 37.120159 | P11: =IF(A11="corn",N11/(111*2000/56),N11/(111*2000/60)) -> 1.0102703
A12: Wheat | B12: Amarillo, TX | C12: Los Angeles, CA | D12: unit | E12: 40330 | F12: 40339 | G12: 3742 | H12: 1357 | I12: UP | J12: =IF(I12="BNSF",0.46,IF(I12="CN",0.1495,IF(I12="CSX",0.27,0.2))) -> 0.2 | K12: =G12/100.7 -> 37.159881 | L12: =IF(A12="corn",G12/(111*2000/56),G12/(111*2000/60)) -> 1.0113514 | M12: =H12*J12 -> 271.4 | N12: =G12+M12 -> 4013.4 | O12: =N12/100.7 -> 39.855015 | P12: =IF(A12="corn",N12/(111*2000/56),N12/(111*2000/60)) -> 1.0847027
A13: Corn | B13: Champaign-Urbana, IL | C13: New Orleans, LA | D13: unit | E13: 40330 | F13: 40339 | G13: 2785 | H13: 1006 | I13: UP | J13: =IF(I13="BNSF",0.46,IF(I13="CN",0.1495,IF(I13="CSX",0.27,0.2))) -> 0.2 | K13: =G13/100.7 -> 27.656405 | L13: =IF(A13="corn",G13/(111*2000/56),G13/(111*2000/60)) -> 0.70252252 | M13: =H13*J13 -> 201.2 | N13: =G13+M13 -> 2986.2 | O13: =N13/100.7 -> 29.654419 | P13: =IF(A13="corn",N13/(111*2000/56),N13/(111*2000/60)) -> 0.75327568
A14: Corn | B14: Toledo, OH | C14: Raleigh, NC | D14: unit | E14: 40330 | F14: 40339 | G14: 3471 | H14: 866 | I14: CSX | J14: =IF(I14="BNSF",0.46,IF(I14="CN",0.1495,IF(I14="CSX",0.27,0.2))) -> 0.27 | K14: =G14/100.7 -> 34.468719 | L14: =IF(A14="corn",G14/(111*2000/56),G14/(111*2000/60)) -> 0.87556757 | M14: =H14*J14 -> 233.82 | N14: =G14+M14 -> 3704.82 | O14: =N14/100.7 -> 36.790665 | P14: =IF(A14="corn",N14/(111*2000/56),N14/(111*2000/60)) -> 0.93454919
A15: Corn | B15: Des Moines, IA | C15: Davenport, IA | D15: unit | E15: 40330 | F15: 40339 | G15: 1912 | H15: 213 | I15: UP | J15: =IF(I15="BNSF",0.46,IF(I15="CN",0.1495,IF(I15="CSX",0.27,0.2))) -> 0.2 | K15: =G15/100.7 -> 18.98709 | L15: =IF(A15="corn",G15/(111*2000/56),G15/(111*2000/60)) -> 0.48230631 | M15: =H15*J15 -> 42.6 | N15: =G15+M15 -> 1954.6 | O15: =N15/100.7 -> 19.410129 | P15: =IF(A15="corn",N15/(111*2000/56),N15/(111*2000/60)) -> 0.49305225
A16: Corn | B16: Indianapolis, IN | C16: Atlanta, GA | D16: unit | E16: 40330 | F16: 40339 | G16: 2993 | H16: 650 | I16: CSX | J16: =IF(I16="BNSF",0.46,IF(I16="CN",0.1495,IF(I16="CSX",0.27,0.2))) -> 0.27 | K16: =G16/100.7 -> 29.721946 | L16: =IF(A16="corn",G16/(111*2000/56),G16/(111*2000/60)) -> 0.75499099 | M16: =H16*J16 -> 175.5 | N16: =G16+M16 -> 3168.5 | O16: =N16/100.7 -> 31.464747 | P16: =IF(A16="corn",N16/(111*2000/56),N16/(111*2000/60)) -> 0.79926126
A17: Corn | B17: Indianapolis, IN | C17: Knoxville, TN | D17: unit | E17: 40330 | F17: 40339 | G17: 2557 | H17: 417 | I17: CSX | J17: =IF(I17="BNSF",0.46,IF(I17="CN",0.1495,IF(I17="CSX",0.27,0.2))) -> 0.27 | K17: =G17/100.7 -> 25.392254 | L17: =IF(A17="corn",G17/(111*2000/56),G17/(111*2000/60)) -> 0.64500901 | M17: =H17*J17 -> 112.59 | N17: =G17+M17 -> 2669.59 | O17: =N17/100.7 -> 26.510328 | P17: =IF(A17="corn",N17/(111*2000/56),N17/(111*2000/60)) -> 0.67341009
... A81: Soybeans | B81: Grand Island, NE | C81: Portland, OR | D81: shuttle | E81: 40360 | F81: 40365 | G81: 4320 | H81: 1637 | I81: UP | J81: =IF(I81="BNSF",0.46,IF(I81="CN",0.1495,IF(I81="CSX",0.27,0.2))) -> 0.2 | K81: =G81/100.7 -> 42.899702 | L81: =IF(A81="corn",G81/(111*2000/56),G81/(111*2000/60)) -> 1.1675676 | M81: =H81*J81 -> 327.4 | N81: =G81+M81 -> 4647.4 | O81: =N81/100.7 -> 46.150943 | P81: =IF(A81="corn",N81/(111*2000/56),N81/(111*2000/60)) -> 1.2560541
A82: Wheat | B82: South Central KS | C82: St. Louis, MO | D82: unit | E82: 40391 | F82: 40395 | G82: 2774 | H82: 506 | I82: UP | J82: =IF(I82="BNSF",0.43,IF(I82="CN",0.1265,IF(I82="CSX",0.24,0.17))) -> 0.17 | K82: =G82/100.7 -> 27.54717 | L82: =IF(A82="corn",G82/(111*2000/56),G82/(111*2000/60)) -> 0.74972973 | M82: =H82*J82 -> 86.02 | N82: =G82+M82 -> 2860.02 | O82: =N82/100.7 -> 28.40139 | P82: =IF(A82="corn",N82/(111*2000/56),N82/(111*2000/60)) -> 0.77297838
A83: Wheat | B83: Grand Forks, ND | C83: Dulth-Superior, MN | D83: unit | E83: 40391 | F83: 40395 | G83: 2563 | H83: 298 | I83: BNSF | J83: =IF(I83="BNSF",0.43,IF(I83="CN",0.1265,IF(I83="CSX",0.24,0.17))) -> 0.43 | K83: =G83/100.7 -> 25.451837 | L83: =IF(A83="corn",G83/(111*2000/56),G83/(111*2000/60)) -> 0.6927027 | M83: =H83*J83 -> 128.14 | N83: =G83+M83 -> 2691.14 | O83: =N83/100.7 -> 26.72433 | P83: =IF(A83="corn",N83/(111*2000/56),N83/(111*2000/60)) -> 0.72733514
A84: Wheat | B84: South Central KS | C84: Los Angeles, CA | D84: unit | E84: 40391 | F84: 40395 | G84: 5047 | H84: 1530 | I84: BNSF | J84: =IF(I84="BNSF",0.43,IF(I84="CN",0.1265,IF(I84="CSX",0.24,0.17))) -> 0.43 | K84: =G84/100.7 -> 50.119166 | L84: =IF(A84="corn",G84/(111*2000/56),G84/(111*2000/60)) -> 1.3640541 | M84: =H84*J84 -> 657.9 | N84: =G84+M84 -> 5704.9 | O84: =N84/100.7 -> 56.652433 | P84: =IF(A84="corn",N84/(111*2000/56),N84/(111*2000/60)) -> 1.5418649
A85: Wheat | B85: South Central KS | C85: New Orleans, LA | D85: unit | E85: 40391 | F85: 40395 | G85: 3275 | H85: 890 | I85: UP | J85: =IF(I85="BNSF",0.43,IF(I85="CN",0.1265,IF(I85="CSX",0.24,0.17))) -> 0.17 | K85: =G85/100.7 -> 32.522344 | L85: =IF(A85="corn",G85/(111*2000/56),G85/(111*2000/60)) -> 0.88513514 | M85: =H85*J85 -> 151.3 | N85: =G85+M85 -> 3426.3 | O85: =N85/100.7 -> 34.024826 | P85: =IF(A85="corn",N85/(111*2000/56),N85/(111*2000/60)) -> 0.92602703
A86: Wheat | B86: Sioux Falls, SD | C86: Galveston-Houston, TX | D86: unit | E86: 40391 | F86: 40395 | G86: 4981 | H86: 1256 | I86: BNSF | J86: =IF(I86="BNSF",0.43,IF(I86="CN",0.1265,IF(I86="CSX",0.24,0.17))) -> 0.43 | K86: =G86/100.7 -> 49.463754 | L86: =IF(A86="corn",G86/(111*2000/56),G86/(111*2000/60)) -> 1.3462162 | M86: =H86*J86 -> 540.08 | N86: =G86+M86 -> 5521.08 | O86: =N86/100.7 -> 54.827011 | P86: =IF(A86="corn",N86/(111*2000/56),N86/(111*2000/60)) -> 1.4921838
A87: Wheat | B87: Northwest KS | C87: Galveston-Houston, TX | D87: unit | E87: 40391 | F87: 40395 | G87: 3543 | H87: 975 | I87: UP | J87: =IF(I87="BNSF",0.43,IF(I87="CN",0.1265,IF(I87="CSX",0.24,0.17))) -> 0.17 | K87: =G87/100.7 -> 35.183714 | L87: =IF(A87="corn",G87/(111*2000/56),G87/(111*2000/60)) -> 0.95756757 | M87: =H87*J87 -> 165.75 | N87: =G87+M87 -> 3708.75 | O87: =N87/100.7 -> 36.829692 | P87: =IF(A87="corn",N87/(111*2000/56),N87/(111*2000/60)) -> 1.0023649
A88: Wheat | B88: Amarillo, TX | C88: Los Angeles, CA | D88: unit | E88: 40391 | F88: 40395 | G88: 3742 | H88: 1357 | I88: UP | J88: =IF(I88="BNSF",0.43,IF(I88="CN",0.1265,IF(I88="CSX",0.24,0.17))) -> 0.17 | K88: =G88/100.7 -> 37.159881 | L88: =IF(A88="corn",G88/(111*2000/56),G88/(111*2000/60)) -> 1.0113514 | M88: =H88*J88 -> 230.69 | N88: =G88+M88 -> 3972.69 | O88: =N88/100.7 -> 39.450745 | P88: =IF(A88="corn",N88/(111*2000/56),N88/(111*2000/60)) -> 1.0737
A89: Corn | B89: Champaign-Urbana, IL | C89: New Orleans, LA | D89: unit | E89: 40391 | F89: 40395 | G89: 2785 | H89: 1006 | I89: UP | J89: =IF(I89="BNSF",0.43,IF(I89="CN",0.1265,IF(I89="CSX",0.24,0.17))) -> 0.17 | K89: =G89/100.7 -> 27.656405 | L89: =IF(A89="corn",G89/(111*2000/56),G89/(111*2000/60)) -> 0.70252252 | M89: =H89*J89 -> 171.02 | N89: =G89+M89 -> 2956.02 | O89: =N89/100.7 -> 29.354717 | P89: =IF(A89="corn",N89/(111*2000/56),N89/(111*2000/60)) -> 0.7456627
A90: Corn | B90: Toledo, OH | C90: Raleigh, NC | D90: unit | E90: 40391 | F90: 40395 | G90: 3471 | H90: 866 | I90: CSX | J90: =IF(I90="BNSF",0.43,IF(I90="CN",0.1265,IF(I90="CSX",0.24,0.17))) -> 0.24 | K90: =G90/100.7 -> 34.468719 | L90: =IF(A90="corn",G90/(111*2000/56),G90/(111*2000/60)) -> 0.87556757 | M90: =H90*J90 -> 207.84 | N90: =G90+M90 -> 3678.84 | O90: =N90/100.7 -> 36.532671 | P90: =IF(A90="corn",N90/(111*2000/56),N90/(111*2000/60)) -> 0.92799568
A91: Corn | B91: Des Moines, IA | C91: Davenport, IA | D91: unit | E91: 40391 | F91: 40395 | G91: 1912 | H91: 213 | I91: UP | J91: =IF(I91="BNSF",0.43,IF(I91="CN",0.1265,IF(I91="CSX",0.24,0.17))) -> 0.17 | K91: =G91/100.7 -> 18.98709 | L91: =IF(A91="corn",G91/(111*2000/56),G91/(111*2000/60)) -> 0.48230631 | M91: =H91*J91 -> 36.21 | N91: =G91+M91 -> 1948.21 | O91: =N91/100.7 -> 19.346673 | P91: =IF(A91="corn",N91/(111*2000/56),N91/(111*2000/60)) -> 0.49144036
A92: Corn | B92: Indianapolis, IN | C92: Atlanta, GA | D92: unit | E92: 40391 | F92: 40395 | G92: 2993 | H92: 650 | I92: CSX | J92: =IF(I92="BNSF",0.43,IF(I92="CN",0.1265,IF(I92="CSX",0.24,0.17))) -> 0.24 | K92: =G92/100.7 -> 29.721946 | L92: =IF(A92="corn",G92/(111*2000/56),G92/(111*2000/60)) -> 0.75499099 | M92: =H92*J92 -> 156 | N92: =G92+M92 -> 3149 | O92: =N92/100.7 -> 31.271102 | P92: =IF(A92="corn",N92/(111*2000/56),N92/(111*2000/60)) -> 0.79434234
A93: Corn | B93: Indianapolis, IN | C93: Knoxville, TN | D93: unit | E93: 40391 | F93: 40395 | G93: 2557 | H93: 417 | I93: CSX | J93: =IF(I93="BNSF",0.43,IF(I93="CN",0.1265,IF(I93="CSX",0.24,0.17))) -> 0.24 | K93: =G93/100.7 -> 25.392254 | L93: =IF(A93="corn",G93/(111*2000/56),G93/(111*2000/60)) -> 0.64500901 | M93: =H93*J93 -> 100.08 | N93: =G93+M93 -> 2657.08 | O93: =N93/100.7 -> 26.386097 | P93: =IF(A93="corn",N93/(111*2000/56),N93/(111*2000/60)) -> 0.67025441
... A119: Soybeans | B119: Grand Island, NE | C119: Portland, OR | D119: shuttle | E119: 40391 | F119: 40395 | G119: 4320 | H119: 1637 | I119: UP | J119: =IF(I119="BNSF",0.43,IF(I119="CN",0.1265,IF(I119="CSX",0.24,0.17))) -> 0.17 | K119: =G119/100.7 -> 42.899702 | L119: =IF(A119="corn",G119/(111*2000/56),G119/(111*2000/60)) -> 1.1675676 | M119: =H119*J119 -> 278.29 | N119: =G119+M119 -> 4598.29 | O119: =N119/100.7 -> 45.663257 | P119: =IF(A119="corn",N119/(111*2000/56),N119/(111*2000/60)) -> 1.2427811
A120: Wheat | B120: South Central KS | C120: St. Louis, MO | D120: unit | E120: 40422 | F120: 40428 | G120: 2774 | H120: 506 | I120: UP | J120: =IF(I120="BNSF",0.42,IF(I120="CN",0.1208,IF(I120="CSX",0.23,0.17))) -> 0.17 | K120: =G120/100.7 -> 27.54717 | L120: =IF(A120="corn",G120/(111*2000/56),G120/(111*2000/60)) -> 0.74972973 | M120: =H120*J120 -> 86.02 | N120: =G120+M120 -> 2860.02 | O120: =N120/100.7 -> 28.40139 | P120: =IF(A120="corn",N120/(111*2000/56),N120/(111*2000/60)) -> 0.77297838 | S120: =AVERAGE(O44,O82,O120) -> 28.451639
A121: Wheat | B121: Grand Forks, ND | C121: Dulth-Superior, MN | D121: unit | E121: 40422 | F121: 40428 | G121: 2563 | H121: 298 | I121: BNSF | J121: =IF(I121="BNSF",0.42,IF(I121="CN",0.1208,IF(I121="CSX",0.23,0.17))) -> 0.42 | K121: =G121/100.7 -> 25.451837 | L121: =IF(A121="corn",G121/(111*2000/56),G121/(111*2000/60)) -> 0.6927027 | M121: =H121*J121 -> 125.16 | N121: =G121+M121 -> 2688.16 | O121: =N121/100.7 -> 26.694737 | P121: =IF(A121="corn",N121/(111*2000/56),N121/(111*2000/60)) -> 0.72652973 | S121: =AVERAGE(O45,O83,O121) -> 26.204502
A122: Wheat | B122: South Central KS | C122: Los Angeles, CA | D122: unit | E122: 40422 | F122: 40428 | G122: 5047 | H122: 1530 | I122: BNSF | J122: =IF(I122="BNSF",0.42,IF(I122="CN",0.1208,IF(I122="CSX",0.23,0.17))) -> 0.42 | K122: =G122/100.7 -> 50.119166 | L122: =IF(A122="corn",G122/(111*2000/56),G122/(111*2000/60)) -> 1.3640541 | M122: =H122*J122 -> 642.6 | N122: =G122+M122 -> 5689.6 | O122: =N122/100.7 -> 56.500497 | P122: =IF(A122="corn",N122/(111*2000/56),N122/(111*2000/60)) -> 1.5377297 | S122: =AVERAGE(O46,O84,O122) -> 56.753724
A123: Wheat | B123: South Central KS | C123: New Orleans, LA | D123: unit | E123: 40422 | F123: 40428 | G123: 3275 | H123: 890 | I123: UP | J123: =IF(I123="BNSF",0.42,IF(I123="CN",0.1208,IF(I123="CSX",0.23,0.17))) -> 0.17 | K123: =G123/100.7 -> 32.522344 | L123: =IF(A123="corn",G123/(111*2000/56),G123/(111*2000/60)) -> 0.88513514 | M123: =H123*J123 -> 151.3 | N123: =G123+M123 -> 3426.3 | O123: =N123/100.7 -> 34.024826 | P123: =IF(A123="corn",N123/(111*2000/56),N123/(111*2000/60)) -> 0.92602703 | S123: =AVERAGE(O47,O85,O123) -> 34.113208
A124: Wheat | B124: Sioux Falls, SD | C124: Galveston-Houston, TX | D124: unit | E124: 40422 | F124: 40428 | G124: 4981 | H124: 1256 | I124: BNSF | J124: =IF(I124="BNSF",0.42,IF(I124="CN",0.1208,IF(I124="CSX",0.23,0.17))) -> 0.42 | K124: =G124/100.7 -> 49.463754 | L124: =IF(A124="corn",G124/(111*2000/56),G124/(111*2000/60)) -> 1.3462162 | M124: =H124*J124 -> 527.52 | N124: =G124+M124 -> 5508.52 | O124: =N124/100.7 -> 54.702284 | P124: =IF(A124="corn",N124/(111*2000/56),N124/(111*2000/60)) -> 1.4887892 | S124: =AVERAGE(O48,O86,O124) -> 54.910162
A125: Wheat | B125: Northwest KS | C125: Galveston-Houston, TX | D125: unit | E125: 40422 | F125: 40428 | G125: 3543 | H125: 975 | I125: UP | J125: =IF(I125="BNSF",0.42,IF(I125="CN",0.1208,IF(I125="CSX",0.23,0.17))) -> 0.17 | K125: =G125/100.7 -> 35.183714 | L125: =IF(A125="corn",G125/(111*2000/56),G125/(111*2000/60)) -> 0.95756757 | M125: =H125*J125 -> 165.75 | N125: =G125+M125 -> 3708.75 | O125: =N125/100.7 -> 36.829692 | P125: =IF(A125="corn",N125/(111*2000/56),N125/(111*2000/60)) -> 1.0023649 | S125: =AVERAGE(O49,O87,O125) -> 36.926514
A126: Wheat | B126: Amarillo, TX | C126: Los Angeles, CA | D126: unit | E126: 40422 | F126: 40428 | G126: 3742 | H126: 1357 | I126: UP | J126: =IF(I126="BNSF",0.42,IF(I126="CN",0.1208,IF(I126="CSX",0.23,0.17))) -> 0.17 | K126: =G126/100.7 -> 37.159881 | L126: =IF(A126="corn",G126/(111*2000/56),G126/(111*2000/60)) -> 1.0113514 | M126: =H126*J126 -> 230.69 | N126: =G126+M126 -> 3972.69 | O126: =N126/100.7 -> 39.450745 | P126: =IF(A126="corn",N126/(111*2000/56),N126/(111*2000/60)) -> 1.0737 | S126: =AVERAGE(O50,O88,O126) -> 39.585501
A127: Corn | B127: Champaign-Urbana, IL | C127: New Orleans, LA | D127: unit | E127: 40422 | F127: 40428 | G127: 2785 | H127: 1006 | I127: UP | J127: =IF(I127="BNSF",0.42,IF(I127="CN",0.1208,IF(I127="CSX",0.23,0.17))) -> 0.17 | K127: =G127/100.7 -> 27.656405 | L127: =IF(A127="corn",G127/(111*2000/56),G127/(111*2000/60)) -> 0.70252252 | M127: =H127*J127 -> 171.02 | N127: =G127+M127 -> 2956.02 | O127: =N127/100.7 -> 29.354717 | P127: =IF(A127="corn",N127/(111*2000/56),N127/(111*2000/60)) -> 0.7456627 | S127: =AVERAGE(O51,O89,O127) -> 29.454618
A128: Corn | B128: Toledo, OH | C128: Raleigh, NC | D128: unit | E128: 40422 | F128: 40428 | G128: 3471 | H128: 866 | I128: CSX | J128: =IF(I128="BNSF",0.42,IF(I128="CN",0.1208,IF(I128="CSX",0.23,0.17))) -> 0.23 | K128: =G128/100.7 -> 34.468719 | L128: =IF(A128="corn",G128/(111*2000/56),G128/(111*2000/60)) -> 0.87556757 | M128: =H128*J128 -> 199.18 | N128: =G128+M128 -> 3670.18 | O128: =N128/100.7 -> 36.446673 | P128: =IF(A128="corn",N128/(111*2000/56),N128/(111*2000/60)) -> 0.92581117 | S128: =AVERAGE(O52,O90,O128) -> 36.590003
...

Sheet Table 7
A1: Table 7
A2: Tariff Rail Rates for Unit and Shuttle Train Shipments1
A3: Effective date: | E3: Fuel surcharge per car | H3: Percent
D4: Tariff | F4: Tariff plus surcharge per: | H4: change
A5: =INDEX(Data!E:E,COUNTIF(Data!E:E,">0")+2,1) -> 41974 | B5: Origin region* | C5: Destination region* | D5: rate/car | F5: metric ton | G5: bushel2 | H5: Y/Y3
A6: Unit train
A7: Wheat | B7: Wichita, KS | C7: St. Louis, MO | D7: =INDEX(Data!G:G,COUNTIF(Data!$E:$E,">0")-32,1) -> 3387 | E7: =INDEX(Data!M:M,COUNTIF(Data!$E:$E,">0")-32,1) -> 161.92 | F7: =INDEX(Data!O:O,COUNTIF(Data!$E:$E,">0")-32,1) -> 35.242502 | G7: =INDEX(Data!P:P,COUNTIF(Data!$E:$E,">0")-32,1) -> 0.95916757 | H7: =INDEX(Data!R:R,COUNTIF(Data!$E:$E,">0")-32,1) -> 5.2105444
B8: Grand Forks, ND | C8: Duluth-Superior, MN | D8: =INDEX(Data!G:G,COUNTIF(Data!$E:$E,">0")-31,1) -> 3596 | E8: =INDEX(Data!M:M,COUNTIF(Data!$E:$E,">0")-31,1) -> 89.4 | F8: =INDEX(Data!O:O,COUNTIF(Data!$E:$E,">0")-31,1) -> 36.597815 | G8: =INDEX(Data!P:P,COUNTIF(Data!$E:$E,">0")-31,1) -> 0.99605405 | H8: =INDEX(Data!R:R,COUNTIF(Data!$E:$E,">0")-31,1) -> -0.40267005
B9: Wichita, KS | C9: Los Angeles, CA | D9: =INDEX(Data!G:G,COUNTIF(Data!$E:$E,">0")-30,1) -> 6244 | E9: =INDEX(Data!M:M,COUNTIF(Data!$E:$E,">0")-30,1) -> 459 | F9: =INDEX(Data!O:O,COUNTIF(Data!$E:$E,">0")-30,1) -> 66.564052 | G9: =INDEX(Data!P:P,COUNTIF(Data!$E:$E,">0")-30,1) -> 1.8116216 | H9: =INDEX(Data!R:R,COUNTIF(Data!$E:$E,">0")-30,1) -> -1.1284018
B10: Wichita, KS | C10: New Orleans, LA | D10: =INDEX(Data!G:G,COUNTIF(Data!$E:$E,">0")-29,1) -> 4026 | E10: =INDEX(Data!M:M,COUNTIF(Data!$E:$E,">0")-29,1) -> 284.8 | F10: =INDEX(Data!O:O,COUNTIF(Data!$E:$E,">0")-29,1) -> 42.808342 | G10: =INDEX(Data!P:P,COUNTIF(Data!$E:$E,">0")-29,1) -> 1.1650811 | H10: =INDEX(Data!R:R,COUNTIF(Data!$E:$E,">0")-29,1) -> 4.4181765
B11: Sioux Falls, SD | C11: Galveston-Houston, TX | D11: =INDEX(Data!G:G,COUNTIF(Data!$E:$E,">0")-28,1) -> 5824 | E11: =INDEX(Data!M:M,COUNTIF(Data!$E:$E,">0")-28,1) -> 376.8 | F11: =INDEX(Data!O:O,COUNTIF(Data!$E:$E,">0")-28,1) -> 61.576961 | G11: =INDEX(Data!P:P,COUNTIF(Data!$E:$E,">0")-28,1) -> 1.6758919 | H11: =INDEX(Data!R:R,COUNTIF(Data!$E:$E,">0")-28,1) -> -1.0026183
B12: Northwest KS | C12: Galveston-Houston, TX | D12: =INDEX(Data!G:G,COUNTIF(Data!$E:$E,">0")-27,1) -> 4293 | E12: =INDEX(Data!M:M,COUNTIF(Data!$E:$E,">0")-27,1) -> 312 | F12: =INDEX(Data!O:O,COUNTIF(Data!$E:$E,">0")-27,1) -> 45.729891 | G12: =INDEX(Data!P:P,COUNTIF(Data!$E:$E,">0")-27,1) -> 1.2445946 | H12: =INDEX(Data!R:R,COUNTIF(Data!$E:$E,">0")-27,1) -> 4.0207816
B13: Amarillo, TX | C13: Los Angeles, CA | D13: =INDEX(Data!G:G,COUNTIF(Data!$E:$E,">0")-26,1) -> 4492 | E13: =INDEX(Data!M:M,COUNTIF(Data!$E:$E,">0")-26,1) -> 434.24 | F13: =INDEX(Data!O:O,COUNTIF(Data!$E:$E,">0")-26,1) -> 48.91996 | G13: =INDEX(Data!P:P,COUNTIF(Data!$E:$E,">0")-26,1) -> 1.3314162 | H13: =INDEX(Data!R:R,COUNTIF(Data!$E:$E,">0")-26,1) -> 3.4159613
A14: Corn | B14: Champaign-Urbana, IL | C14: New Orleans, LA | D14: =INDEX(Data!G:G,COUNTIF(Data!$E:$E,">0")-25,1) -> 3328 | E14: =INDEX(Data!M:M,COUNTIF(Data!$E:$E,">0")-25,1) -> 321.92 | F14: =INDEX(Data!O:O,COUNTIF(Data!$E:$E,">0")-25,1) -> 36.245482 | G14: =INDEX(Data!P:P,COUNTIF(Data!$E:$E,">0")-25,1) -> 0.92070054 | H14: =INDEX(Data!R:R,COUNTIF(Data!$E:$E,">0")-25,1) -> 2.6943075
B15: Toledo, OH | C15: Raleigh, NC | D15: =INDEX(Data!G:G,COUNTIF(Data!$E:$E,">0")-24,1) -> 4875 | E15: =INDEX(Data!M:M,COUNTIF(Data!$E:$E,">0")-24,1) -> 372.38 | F15: =INDEX(Data!O:O,COUNTIF(Data!$E:$E,">0")-24,1) -> 52.109037 | G15: =INDEX(Data!P:P,COUNTIF(Data!$E:$E,">0")-24,1) -> 1.3236634 | H15: =INDEX(Data!R:R,COUNTIF(Data!$E:$E,">0")-24,1) -> 2.855922
B16: Des Moines, IA | C16: Davenport, IA | D16: =INDEX(Data!G:G,COUNTIF(Data!$E:$E,">0")-23,1) -> 2168 | E16: =INDEX(Data!M:M,COUNTIF(Data!$E:$E,">0")-23,1) -> 68.16 | F16: =INDEX(Data!O:O,COUNTIF(Data!$E:$E,">0")-23,1) -> 22.206157 | G16: =INDEX(Data!P:P,COUNTIF(Data!$E:$E,">0")-23,1) -> 0.5640764 | H16: =INDEX(Data!R:R,COUNTIF(Data!$E:$E,">0")-23,1) -> 3.781536
B17: Indianapolis, IN | C17: Atlanta, GA | D17: =INDEX(Data!G:G,COUNTIF(Data!$E:$E,">0")-22,1) -> 4211 | E17: =INDEX(Data!M:M,COUNTIF(Data!$E:$E,">0")-22,1) -> 279.5 | F17: =INDEX(Data!O:O,COUNTIF(Data!$E:$E,">0")-22,1) -> 44.59285 | G17: =INDEX(Data!P:P,COUNTIF(Data!$E:$E,">0")-22,1) -> 1.1327387 | H17: =INDEX(Data!R:R,COUNTIF(Data!$E:$E,">0")-22,1) -> 2.6869426
B18: Indianapolis, IN | C18: Knoxville, TN | D18: =INDEX(Data!G:G,COUNTIF(Data!$E:$E,">0")-21,1) -> 3593 | E18: =INDEX(Data!M:M,COUNTIF(Data!$E:$E,">0")-21,1) -> 179.31 | F18: =INDEX(Data!O:O,COUNTIF(Data!$E:$E,">0")-21,1) -> 37.460874 | G18: =INDEX(Data!P:P,COUNTIF(Data!$E:$E,">0")-21,1) -> 0.95157369 | H18: =INDEX(Data!R:R,COUNTIF(Data!$E:$E,">0")-21,1) -> 2.8112702
B19: Des Moines, IA | C19: Little Rock, AR | D19: =INDEX(Data!G:G,COUNTIF(Data!$E:$E,">0")-20,1) -> 3308 | E19: =INDEX(Data!M:M,COUNTIF(Data!$E:$E,">0")-20,1) -> 200.32 | F19: =INDEX(Data!O:O,COUNTIF(Data!$E:$E,">0")-20,1) -> 34.839325 | G19: =INDEX(Data!P:P,COUNTIF(Data!$E:$E,">0")-20,1) -> 0.88498162 | H19: =INDEX(Data!R:R,COUNTIF(Data!$E:$E,">0")-20,1) -> 1.8865294
B20: Des Moines, IA | C20: Los Angeles, CA | D20: =INDEX(Data!G:G,COUNTIF(Data!$E:$E,">0")-19,1) -> 5365 | E20: =INDEX(Data!M:M,COUNTIF(Data!$E:$E,">0")-19,1) -> 583.36 | F20: =INDEX(Data!O:O,COUNTIF(Data!$E:$E,">0")-19,1) -> 59.070109 | G20: =INDEX(Data!P:P,COUNTIF(Data!$E:$E,">0")-19,1) -> 1.5004872 | H20: =INDEX(Data!R:R,COUNTIF(Data!$E:$E,">0")-19,1) -> 1.3128313
A21: Soybeans | B21: Minneapolis, MN | C21: New Orleans, LA | D21: =INDEX(Data!G:G,COUNTIF(Data!$E:$E,">0")-18,1) -> 3839 | E21: =INDEX(Data!M:M,COUNTIF(Data!$E:$E,">0")-18,1) -> 350.0385 | F21: =INDEX(Data!O:O,COUNTIF(Data!$E:$E,">0")-18,1) -> 41.599191 | G21: =INDEX(Data!P:P,COUNTIF(Data!$E:$E,">0")-18,1) -> 1.1321726 | H21: =INDEX(Data!R:R,COUNTIF(Data!$E:$E,">0")-18,1) -> 4.8907459
B22: Toledo, OH | C22: Huntsville, AL | D22: =INDEX(Data!G:G,COUNTIF(Data!$E:$E,">0")-17,1) -> 3807 | E22: =INDEX(Data!M:M,COUNTIF(Data!$E:$E,">0")-17,1) -> 264.45 | F22: =INDEX(Data!O:O,COUNTIF(Data!$E:$E,">0")-17,1) -> 40.43148 | G22: =INDEX(Data!P:P,COUNTIF(Data!$E:$E,">0")-17,1) -> 1.1003919 | H22: =INDEX(Data!R:R,COUNTIF(Data!$E:$E,">0")-17,1) -> 2.2412234
B23: Indianapolis, IN | C23: Raleigh, NC | D23: =INDEX(Data!G:G,COUNTIF(Data!$E:$E,">0")-16,1) -> 4946 | E23: =INDEX(Data!M:M,COUNTIF(Data!$E:$E,">0")-16,1) -> 374.96 | F23: =INDEX(Data!O:O,COUNTIF(Data!$E:$E,">0")-16,1) -> 52.839722 | G23: =INDEX(Data!P:P,COUNTIF(Data!$E:$E,">0")-16,1) -> 1.4380973 | H23: =INDEX(Data!R:R,COUNTIF(Data!$E:$E,">0")-16,1) -> 2.8292261
B24: Indianapolis, IN | C24: Huntsville, AL | D24: =INDEX(Data!G:G,COUNTIF(Data!$E:$E,">0")-15,1) -> 3499 | E24: =INDEX(Data!M:M,COUNTIF(Data!$E:$E,">0")-15,1) -> 179.31 | F24: =INDEX(Data!O:O,COUNTIF(Data!$E:$E,">0")-15,1) -> 36.527408 | G24: =INDEX(Data!P:P,COUNTIF(Data!$E:$E,">0")-15,1) -> 0.99413784 | H24: =INDEX(Data!R:R,COUNTIF(Data!$E:$E,">0")-15,1) -> 2.7702031
B25: Champaign-Urbana, IL | C25: New Orleans, LA | D25: =INDEX(Data!G:G,COUNTIF(Data!$E:$E,">0")-14,1) -> 3974 | E25: =INDEX(Data!M:M,COUNTIF(Data!$E:$E,">0")-14,1) -> 321.92 | F25: =INDEX(Data!O:O,COUNTIF(Data!$E:$E,">0")-14,1) -> 42.660576 | G25: =INDEX(Data!P:P,COUNTIF(Data!$E:$E,">0")-14,1) -> 1.1610595 | H25: =INDEX(Data!R:R,COUNTIF(Data!$E:$E,">0")-14,1) -> 4.5195321
A26: Shuttle Train
A27: Wheat | B27: Great Falls, MT | C27: Portland, OR | D27: =INDEX(Data!G:G,COUNTIF(Data!$E:$E,">0")-13,1) -> 3678 | E27: =INDEX(Data!M:M,COUNTIF(Data!$E:$E,">0")-13,1) -> 264 | F27: =INDEX(Data!O:O,COUNTIF(Data!$E:$E,">0")-13,1) -> 39.145978 | G27: =INDEX(Data!P:P,COUNTIF(Data!$E:$E,">0")-13,1) -> 1.0654054 | H27: =INDEX(Data!R:R,COUNTIF(Data!$E:$E,">0")-13,1) -> -1.1038635
B28: Wichita, KS | C28: Galveston-Houston, TX | D28: =INDEX(Data!G:G,COUNTIF(Data!$E:$E,">0")-12,1) -> 3471 | E28: =INDEX(Data!M:M,COUNTIF(Data!$E:$E,">0")-12,1) -> 205.5 | F28: =INDEX(Data!O:O,COUNTIF(Data!$E:$E,">0")-12,1) -> 36.509434 | G28: =INDEX(Data!P:P,COUNTIF(Data!$E:$E,">0")-12,1) -> 0.99364865 | H28: =INDEX(Data!R:R,COUNTIF(Data!$E:$E,">0")-12,1) -> -8.9468144
B29: Chicago, IL | C29: Albany, NY | D29: =INDEX(Data!G:G,COUNTIF(Data!$E:$E,">0")-11,1) -> 4140 | E29: =INDEX(Data!M:M,COUNTIF(Data!$E:$E,">0")-11,1) -> 349.16 | F29: =INDEX(Data!O:O,COUNTIF(Data!$E:$E,">0")-11,1) -> 44.579543 | G29: =INDEX(Data!P:P,COUNTIF(Data!$E:$E,">0")-11,1) -> 1.2132865 | H29: =INDEX(Data!R:R,COUNTIF(Data!$E:$E,">0")-11,1) -> 3.4425867
B30: Grand Forks, ND | C30: Portland, OR | D30: =INDEX(Data!G:G,COUNTIF(Data!$E:$E,">0")-10,1) -> 5159 | E30: =INDEX(Data!M:M,COUNTIF(Data!$E:$E,">0")-10,1) -> 456 | F30: =INDEX(Data!O:O,COUNTIF(Data!$E:$E,">0")-10,1) -> 55.759682 | G30: =INDEX(Data!P:P,COUNTIF(Data!$E:$E,">0")-10,1) -> 1.5175676 | H30: =INDEX(Data!R:R,COUNTIF(Data!$E:$E,">0")-10,1) -> -1.3354419
B31: Grand Forks, ND | C31: Galveston-Houston, TX | D31: =INDEX(Data!G:G,COUNTIF(Data!$E:$E,">0")-9,1) -> 6084 | E31: =INDEX(Data!M:M,COUNTIF(Data!$E:$E,">0")-9,1) -> 474.9 | F31: =INDEX(Data!O:O,COUNTIF(Data!$E:$E,">0")-9,1) -> 65.133069 | G31: =INDEX(Data!P:P,COUNTIF(Data!$E:$E,">0")-9,1) -> 1.7726757 | H31: =INDEX(Data!R:R,COUNTIF(Data!$E:$E,">0")-9,1) -> -1.1923682
B32: Northwest KS | C32: Portland, OR | D32: =INDEX(Data!G:G,COUNTIF(Data!$E:$E,">0")-8,1) -> 5260 | E32: =INDEX(Data!M:M,COUNTIF(Data!$E:$E,">0")-8,1) -> 511.68 | F32: =INDEX(Data!O:O,COUNTIF(Data!$E:$E,">0")-8,1) -> 57.315591 | G32: =INDEX(Data!P:P,COUNTIF(Data!$E:$E,">0")-8,1) -> 1.5599135 | H32: =INDEX(Data!R:R,COUNTIF(Data!$E:$E,">0")-8,1) -> 2.7237908
A33: Corn | B33: Minneapolis, MN | C33: Portland, OR | D33: =INDEX(Data!G:G,COUNTIF(Data!$E:$E,">0")-7,1) -> 5000 | E33: =INDEX(Data!M:M,COUNTIF(Data!$E:$E,">0")-7,1) -> 555.3 | F33: =INDEX(Data!O:O,COUNTIF(Data!$E:$E,">0")-7,1) -> 55.166832 | G33: =INDEX(Data!P:P,COUNTIF(Data!$E:$E,">0")-7,1) -> 1.4013369 | H33: =INDEX(Data!R:R,COUNTIF(Data!$E:$E,">0")-7,1) -> -1.6386767
B34: Sioux Falls, SD | C34: Tacoma, WA | D34: =INDEX(Data!G:G,COUNTIF(Data!$E:$E,">0")-6,1) -> 4960 | E34: =INDEX(Data!M:M,COUNTIF(Data!$E:$E,">0")-6,1) -> 508.5 | F34: =INDEX(Data!O:O,COUNTIF(Data!$E:$E,">0")-6,1) -> 54.304866 | G34: =INDEX(Data!P:P,COUNTIF(Data!$E:$E,">0")-6,1) -> 1.3794414 | H34: =INDEX(Data!R:R,COUNTIF(Data!$E:$E,">0")-6,1) -> -1.5261333
B35: Champaign-Urbana, IL | C35: New Orleans, LA | D35: =INDEX(Data!G:G,COUNTIF(Data!$E:$E,">0")-5,1) -> 3147 | E35: =INDEX(Data!M:M,COUNTIF(Data!$E:$E,">0")-5,1) -> 321.92 | F35: =INDEX(Data!O:O,COUNTIF(Data!$E:$E,">0")-5,1) -> 34.448064 | G35: =INDEX(Data!P:P,COUNTIF(Data!$E:$E,">0")-5,1) -> 0.87504288 | H35: =INDEX(Data!R:R,COUNTIF(Data!$E:$E,">0")-5,1) -> 2.838881
B36: Lincoln, NE | C36: Galveston-Houston, TX | D36: =INDEX(Data!G:G,COUNTIF(Data!$E:$E,">0")-4,1) -> 3510 | E36: =INDEX(Data!M:M,COUNTIF(Data!$E:$E,">0")-4,1) -> 296.4 | F36: =INDEX(Data!O:O,COUNTIF(Data!$E:$E,">0")-4,1) -> 37.799404 | G36: =INDEX(Data!P:P,COUNTIF(Data!$E:$E,">0")-4,1) -> 0.96017297 | H36: =INDEX(Data!R:R,COUNTIF(Data!$E:$E,">0")-4,1) -> -1.2811868
B37: Des Moines, IA | C37: Amarillo, TX | D37: =INDEX(Data!G:G,COUNTIF(Data!$E:$E,">0")-3,1) -> 3690 | E37: =INDEX(Data!M:M,COUNTIF(Data!$E:$E,">0")-3,1) -> 251.84 | F37: =INDEX(Data!O:O,COUNTIF(Data!$E:$E,">0")-3,1) -> 39.144389 | G37: =INDEX(Data!P:P,COUNTIF(Data!$E:$E,">0")-3,1) -> 0.99433802 | H37: =INDEX(Data!R:R,COUNTIF(Data!$E:$E,">0")-3,1) -> 1.769025
B38: Minneapolis, MN | C38: Tacoma, WA | D38: =INDEX(Data!G:G,COUNTIF(Data!$E:$E,">0")-2,1) -> 5000 | E38: =INDEX(Data!M:M,COUNTIF(Data!$E:$E,">0")-2,1) -> 550.8 | F38: =INDEX(Data!O:O,COUNTIF(Data!$E:$E,">0")-2,1) -> 55.122145 | G38: =INDEX(Data!P:P,COUNTIF(Data!$E:$E,">0")-2,1) -> 1.4002018 | H38: =INDEX(Data!R:R,COUNTIF(Data!$E:$E,">0")-2,1) -> -1.6269096
B39: Council Bluffs, IA | C39: Stockton, CA | D39: =INDEX(Data!G:G,COUNTIF(Data!$E:$E,">0")-1,1) -> 4400 | E39: =INDEX(Data!M:M,COUNTIF(Data!$E:$E,">0")-1,1) -> 569.7 | F39: =INDEX(Data!O:O,COUNTIF(Data!$E:$E,">0")-1,1) -> 49.351539 | G39: =INDEX(Data!P:P,COUNTIF(Data!$E:$E,">0")-1,1) -> 1.253618 | H39: =INDEX(Data!R:R,COUNTIF(Data!$E:$E,">0")-1,1) -> -1.8747594
A40: Soybeans | B40: Sioux Falls, SD | C40: Tacoma, WA | D40: =INDEX(Data!G:G,COUNTIF(Data!$E:$E,">0"),1) -> 5520 | E40: =INDEX(Data!M:M,COUNTIF(Data!$E:$E,">0"),1) -> 508.5 | F40: =INDEX(Data!O:O,COUNTIF(Data!$E:$E,">0"),1) -> 59.865938 | G40: =INDEX(Data!P:P,COUNTIF(Data!$E:$E,">0"),1) -> 1.6293243 | H40: =INDEX(Data!R:R,COUNTIF(Data!$E:$E,">0"),1) -> -1.386333
...

Sheet Info
A1: Commodity | B1: STCC | C1: Origin Area | D1: Actual Origin | E1: Destination Area | F1: Actual Destination | G1: Railroad | H1: Train Type | I1: Tariff Document | J1: Rate | K1: Effective Date | L1: Mileage
A2: Wheat | B2: 0113710 | C2: South Central KS | D2: Wichita, KS | E2: St. Louis, MO | F2: St Louis, MO | G2: UP | H2: Unit | I2: UP 4052 Item 9171 | J2: 2774 | K2: 40353 | L2: 506
A3: Wheat | C3: Grand Forks, ND | D3: Grand Forks, ND | E3: Dulth-Superior, MN | F3: Duluth, MN | G3: BNSF | H3: Unit | I3: BNSF 4022-M Item 45316 | J3: 2400 | K3: 40271 | L3: 298
A4: Wheat | C4: South Central KS | D4: Wichita, KS | E4: Los Angeles, CA | F4: Los Angeles, CA | G4: BNSF | H4: Unit | I4: BNSF 4022-M Item 44102 | J4: 5047 | K4: 40330 | L4: 1530
A5: Wheat | C5: South Central KS | D5: Wichita, KS | E5: New Orleans, LA | F5: Ama, LA | G5: UP | H5: Unit | I5: UP 4052 Item 7021 | J5: 3275 | K5: 40330 | L5: 890
A6: Wheat | C6: Sioux Falls, SD | D6: Mitchell, SD | E6: Galveston-Houston, TX | F6: Houston, TX | G6: BNSF | H6: Unit | I6: BNSF 4022-M Item 46103 | J6: 4981 | K6: 40325 | L6: 1256
A7: Wheat | C7: Northwest KS | D7: Colby, KS | E7: Galveston-Houston, TX | F7: Houston, TX | G7: UP | H7: Unit | I7: UP 4052 Item 7101 | J7: 3543 | K7: 40339 | L7: 975
A8: Wheat | C8: Amarillo, TX | D8: Amarillo, TX | E8: Los Angeles, CA | F8: Los Angeles, CA | G8: UP | H8: Unit | I8: UP 4052 Item 9045 | J8: 3742 | K8: 40339 | L8: 1357
A9: Corn | B9: 0113210 | C9: Champaign-Urbana, IL | D9: Pontiac, IL | E9: New Orleans, LA | F9: Ama, LA | G9: UP | H9: Unit | I9: UP 4051 Item 1132.000 | J9: 2785 | K9: 40235 | L9: 1006
A10: Corn | C10: Toledo, OH | D10: Toledo, OH | E10: Raleigh, NC | F10: Raleigh, NC | G10: CSX | H10: Unit | I10: Public CSXT 4315 | J10: 3471 | K10: 40087 | L10: 866
A11: Corn | C11: Des Moines, IA | D11: Des Moines, IA | E11: Davenport, IA | F11: Clinton, IA | G11: UP | H11: Unit | I11: UP 4051 Item 2606.000 | J11: 1912 | K11: 40179 | L11: 213
A12: Corn | C12: Indianapolis, IN | D12: Indianapolis, IN | E12: Atlanta, GA | F12: Athens, GA | G12: CSX | H12: Unit | I12: Public CSXT 4315 | J12: 2993 | K12: 40087 | L12: 650
A13: Corn | C13: Indianapolis, IN | D13: Indianapolis, IN | E13: Knoxville, TN | F13: Knoxville, TN | G13: CSX | H13: Unit | I13: Public CSXT 4315 | J13: 2557 | K13: 40087 | L13: 417
A14: Corn | C14: Des Moines, IA | D14: Des Moines, IA | E14: Little Rock, AR | F14: Russellville, AR | G14: UP | H14: Unit | I14: UP 4051 Item 2205.000 | J14: 2848 | K14: 40179 | L14: 626
A15: Corn | C15: Des Moines, IA | D15: Des Moines, IA | E15: Los Angeles, CA | F15: Brawley, CA | G15: UP | H15: Unit | I15: UP 4051 Item 2320.000 | J15: 4263 | K15: 40179 | L15: 1823
A16: Soybeans | B16: 0114410 | C16: Minneapolis, MN | D16: Glenville, MN | E16: New Orleans, LA | F16: Reserve, LA | G16: CN | H16: Unit | I16: CN T 004051 Item 1110000 | J16: 2851 | K16: 40360 | L16: 1295
A17: Soybeans | C17: Toledo, OH | D17: Toledo, OH | E17: Huntsville, AL | F17: Decatur, AL | G17: CSX | H17: Unit | I17: Public CSXT 4315 | J17: 2748 | K17: 40087 | L17: 615
A18: Soybeans | C18: Indianapolis, IN | D18: Indianapolis, IN | E18: Raleigh, NC | F18: Raleigh, NC | G18: CSX | H18: Unit | I18: Public CSXT 4315 | J18: 3540 | K18: 40087 | L18: 872
A19: Soybeans | C19: Indianapolis, IN | D19: Indianapolis, IN | E19: Huntsville, AL | F19: Decatur, AL | G19: CSX | H19: Unit | I19: Public CSXT 4315 | J19: 2443 | K19: 40087 | L19: 417
A20: Soybeans | C20: Champaign-Urbana, IL | D20: Pontiac, IL | E20: New Orleans, LA | F20: Ama, LA | G20: UP | H20: Unit | I20: UP 4051 Item 1144.000 | J20: 3038 | K20: 40179 | L20: 1006
A21: Wheat | B21: 0113710 | C21: Great Falls, MT | D21: Great Falls, MT | E21: Portland, OR | F21: Portland, OR | G21: BNSF | H21: Shuttle | I21: BNSF 4022-M Item 43802 | J21: 2770 | K21: 40330 | L21: 880
A22: Wheat | C22: South Central KS | D22: Wichita, KS | E22: Galveston-Houston, TX | F22: Galveston, TX | G22: BNSF | H22: Shuttle | I22: BNSF 4022-M Item 46303 | J22: 2867 | K22: 40322 | L22: 685
A23: Wheat | C23: Chicago, IL | D23: Chicago, IL | E23: Albany, NY | F23: Albany, NY | G23: CSX | H23: Shuttle | I23: Public CSXT 4315 | J23: 3811 | K23: 40087 | L23: 812
A24: Wheat | C24: Grand Forks, ND | D24: North Grand Forks, ND | E24: Portland, OR | F24: Portland, OR | G24: BNSF | H24: Shuttle | I24: BNSF 4022-M Item 43802 | J24: 4033 | K24: 40330 | L24: 1520
A25: Wheat | C25: Grand Forks, ND | D25: North Grand Forks, ND | E25: Galveston-Houston, TX | F25: Houston, TX | G25: BNSF | H25: Shuttle | I25: BNSF 4022-M Item 45416 | J25: 4948 | K25: 40322 | L25: 1583
A26: Wheat | C26: Northwest KS | D26: Colby, KS | E26: Portland, OR | F26: Portland, OR | G26: UP | H26: Shuttle | I26: UP 4052 Item 6021 | J26: 4510 | K26: 40339 | L26: 1599
A27: Corn | B27: 0113210 | C27: Minneapolis, MN | D27: New Ulm, MN | E27: Portland, OR | F27: Portland, OR | G27: BNSF | H27: Shuttle | I27: BNSF 4022-M Item 39007 | J27: 3920 | K27: 40346 | L27: 1851
A28: Corn | C28: Sioux Falls, SD | D28: Mitchell, SD | E28: Tacoma, WA | F28: Tacoma, WA | G28: BNSF | H28: Shuttle | I28: BNSF 4022-M Item 39007 | J28: 3920 | K28: 40346 | L28: 1695
A29: Corn | C29: Champaign-Urbana, IL | D29: Pontiac, IL | E29: New Orleans, LA | F29: Ama, LA | G29: UP | H29: Shuttle | I29: UP 4051 Item 1132.000 | J29: 2677 | K29: 40235 | L29: 1006
A30: Corn | C30: Lincoln, NE | D30: Lincoln, NE | E30: Galveston-Houston, TX | F30: Houston, TX | G30: BNSF | H30: Shuttle | I30: BNSF 4022-M Item 39007 | J30: 2800 | K30: 40346 | L30: 988
A31: Corn | C31: Des Moines, IA | D31: Avon, IA | E31: Amarillo, TX | F31: Amarillo, TX | G31: UP | H31: Shuttle | I31: UP 4051 Item 2240.000 | J31: 3230 | K31: 40179 | L31: 787
A32: Corn | C32: Minneapolis, MN | D32: New Ulm, MN | E32: Tacoma, WA | F32: Tacoma, WA | G32: BNSF | H32: Shuttle | I32: BNSF 4022-M Item 39007 | J32: 3920 | K32: 40346 | L32: 1836
A33: Corn | C33: Council Bluffs, IA | D33: Red Oak, IA | E33: Stockton, CA | F33: Stockton, CA | G33: BNSF | H33: Shuttle | I33: BNSF 4022-M Item 39007 | J33: 3400 | K33: 40346 | L33: 1899
A34: Soybeans | B34: 0114410 | C34: Sioux Falls, SD | D34: Mitchell, SD | E34: Tacoma, WA | F34: Tacoma, WA | G34: BNSF | H34: Shuttle | I34: BNSF 4022-M Item 61907 | J34: 4220 | K34: 40299 | L34: 1695
A35: Soybeans | C35: Minneapolis, MN | D35: New Ulm, MN | E35: Portland, OR | F35: Portland, OR | G35: BNSF | H35: Shuttle | I35: BNSF 4022-M Item 61907 | J35: 4170 | K35: 40299 | L35: 1851
A36: Soybeans | C36: Fargo, ND | D36: Casselton, ND | E36: Tacoma, WA | F36: Tacoma, WA | G36: BNSF | H36: Shuttle | I36: BNSF 4022-M Item 61907 | J36: 4170 | K36: 40299 | L36: 1507
A37: Soybeans | C37: Council Bluffs, IA | D37: Council Bluffs, IA | E37: New Orleans, LA | F37: Ama, LA | G37: UP | H37: Shuttle | I37: UP 4051 Item 1144.000 | J37: 3410 | K37: 40179 | L37: 1160
A38: Soybeans | C38: Toledo, OH | D38: Toledo, OH | E38: Huntsville, AL | F38: Decatur, AL | G38: CSX | H38: Shuttle | I38: Public CSXT 4315 | J38: 2366 | K38: 40087 | L38: 615
A39: Soybeans | C39: Grand Island, NE | D39: Grand Island, NE | E39: Portland, OR | F39: Portland, OR | G39: UP | H39: Shuttle | I39: UP 4051 Item 1300.000 | J39: 4320 | K39: 40148 | L39: 1637

Sheet Selected Hist. Rates
A2: BNSF rates for | K2: BNSF rates for | U2: UP rates for
A3: Minneapolis, MN | B3: to | C3: St. Louis, MO | K3: Minneapolis, MN | L3: to | M3: St. Louis, MO | U3: Minneapolis, MN to St. Louis, MO
A5: Corn | K5: Soybeans | U5: Corn, Soybean
A6: Heavy axle railcars -- load to 111 tons | E6: = | F6: =111/1.10231 -> 100.69763 | G6: MT | K6: Heavy axle railcars -- load to 111 tons | O6: = | P6: =111/1.10231 -> 100.69763 | Q6: MT | U6: Heavy axle railcars -- load to 111 tons
A7: Shuttle trains of 110 to 120 railcars | K7: Shuttle trains of 110 to 120 railcars | U7: Shuttle trains of 110 to 120 railcars
A8: Miles | C8: 601 | K8: Miles | M8: 601 | U8: Miles | W8: 681.57895
D9: FSC | E9: FSC | F9: Tariff + | H9: Rate per | N9: FSC | O9: FSC | P9: Tariff + | R9: Rate per | X9: FSC | Y9: FSC | Z9: Tariff + | AB9: Rate per
A10: Month/year | C10: Tariff rate | D10: rate/mile | E10: per carload | F10: FSC | H10: Railcar | I10: Rate/MT | K10: Month/year | M10: Tariff rate | N10: rate/mile | O10: per carload | P10: FSC | R10: Railcar | S10: Rate/MT | U10: Month/year | W10: Tariff rate | X10: rate/mile | Y10: per carload | Z10: FSC | AB10: Railcar | AC10: Rate/MT
A11: Jan. 14 | C11: 4308 | D11: 0.34 | E11: =D11*$C$8 -> 204.34 | F11: =C11+E11 -> 4512.34 | K11: Jan. 14 | M11: 3570 | N11: 0.34 | O11: =N11*$C$8 -> 204.34 | P11: =M11+O11 -> 3774.34 | U11: Jan. 14 | W11: 4452 | X11: 0.35 | Y11: =$W$8*X11 -> 238.55263 | Z11: =W11+Y11 -> 4690.5526
A12: Feb. 14 | C12: 4308 | D12: 0.35 | E12: =D12*$C$8 -> 210.35 | F12: =C12+E12 -> 4518.35 | K12: Feb. 14 | M12: 3570 | N12: 0.35 | O12: =N12*$C$8 -> 210.35 | P12: =M12+O12 -> 3780.35 | U12: Feb. 14 | W12: 4452 | X12: 0.36 | Y12: =$W$8*X12 -> 245.36842 | Z12: =W12+Y12 -> 4697.3684
A13: Mar. 14 | C13: 4308 | D13: 0.35 | E13: =D13*$C$8 -> 210.35 | F13: =C13+E13 -> 4518.35 | G13: 1Q 14 | H13: =AVERAGE(F11:F13) -> 4516.3467 | I13: =H13/$F$6 -> 44.850577 | K13: Mar. 14 | M13: 3570 | N13: 0.35 | O13: =N13*$C$8 -> 210.35 | P13: =M13+O13 -> 3780.35 | Q13: 1Q 14 | R13: =AVERAGE(P11:P13) -> 3778.3467 | S13: =R13/$F$6 -> 37.521706 | U13: Mar. 14 | W13: 4452 | X13: 0.36 | Y13: =$W$8*X13 -> 245.36842 | Z13: =W13+Y13 -> 4697.3684 | AA13: 1Q 14 | AB13: =AVERAGE(Z11:Z13) -> 4695.0965 | AC13: =AB13/$F$6 -> 46.625692
A14: Apr. 14 | C14: 4308 | D14: 0.38 | E14: =D14*$C$8 -> 228.38 | F14: =C14+E14 -> 4536.38 | K14: Apr. 14 | M14: 3570 | N14: 0.38 | O14: =N14*$C$8 -> 228.38 | P14: =M14+O14 -> 3798.38 | U14: Apr. 14 | W14: 4452 | X14: 0.38 | Y14: =$W$8*X14 -> 259 | Z14: =W14+Y14 -> 4711
A15: May. 14 | C15: 4308 | D15: 0.38 | E15: =D15*$C$8 -> 228.38 | F15: =C15+E15 -> 4536.38 | K15: May. 14 | M15: 3570 | N15: 0.38 | O15: =N15*$C$8 -> 228.38 | P15: =M15+O15 -> 3798.38 | U15: May. 14 | W15: 4452 | X15: 0.39 | Y15: =$W$8*X15 -> 265.81579 | Z15: =W15+Y15 -> 4717.8158
A16: Jun. 14 | C16: 4308 | D16: 0.37 | E16: =D16*$C$8 -> 222.37 | F16: =C16+E16 -> 4530.37 | G16: 2Q14 | H16: =AVERAGE(F14:F16) -> 4534.3767 | I16: =H16/$F$6 -> 45.029628 | K16: Jun. 14 | M16: 3570 | N16: 0.37 | O16: =N16*$C$8 -> 222.37 | P16: =M16+O16 -> 3792.37 | Q16: 2Q14 | R16: =AVERAGE(P14:P16) -> 3796.3767 | S16: =R16/$F$6 -> 37.700756 | U16: Jun. 14 | W16: 4452 | X16: 0.38 | Y16: =$W$8*X16 -> 259 | Z16: =W16+Y16 -> 4711 | AA16: 2Q14 | AB16: =AVERAGE(Z14:Z16) -> 4713.2719 | AC16: =AB16/$F$6 -> 46.806187
A17: Jul. 14 | C17: 4308 | D17: 0.37 | E17: =D17*$C$8 -> 222.37 | F17: =C17+E17 -> 4530.37 | K17: Jul. 14 | M17: 3570 | N17: 0.37 | O17: =N17*$C$8 -> 222.37 | P17: =M17+O17 -> 3792.37 | U17: Jul. 14 | W17: 4452 | X17: 0.37 | Y17: =$W$8*X17 -> 252.18421 | Z17: =W17+Y17 -> 4704.1842
A18: Aug. 14 | C18: 4308 | D18: 0.36 | E18: =D18*$C$8 -> 216.36 | F18: =C18+E18 -> 4524.36 | K18: Aug. 14 | M18: 3570 | N18: 0.36 | O18: =N18*$C$8 -> 216.36 | P18: =M18+O18 -> 3786.36 | U18: Aug. 14 | W18: 4452 | X18: 0.37 | Y18: =$W$8*X18 -> 252.18421 | Z18: =W18+Y18 -> 4704.1842
A19: Sep. 14 | C19: 4308 | D19: 0.35 | E19: =D19*$C$8 -> 210.35 | F19: =C19+E19 -> 4518.35 | G19: 3Q14 | H19: =AVERAGE(F17:F19) -> 4524.36 | I19: =H19/$F$30 -> 44.930156 | K19: Sep. 14 | M19: 3570 | N19: 0.35 | O19: =N19*$C$8 -> 210.35 | P19: =M19+O19 -> 3780.35 | Q19: 3Q14 | R19: =AVERAGE(P17:P19) -> 3786.36 | S19: =R19/$F$30 -> 37.601284 | U19: Sep. 14 | W19: 4452 | X19: 0.36 | Y19: =$W$8*X19 -> 245.36842 | Z19: =W19+Y19 -> 4697.3684 | AA19: 3Q14 | AB19: =AVERAGE(Z17:Z19) -> 4701.9123 | AC19: =AB19/$F$6 -> 46.693378
A20: Oct. 14 | C20: 4308 | D20: 0.34 | E20: =D20*$C$8 -> 204.34 | F20: =C20+E20 -> 4512.34 | K20: Oct. 14 | M20: 3570 | N20: 0.34 | O20: =N20*$C$8 -> 204.34 | P20: =M20+O20 -> 3774.34 | U20: Oct. 14 | W20: 4602 | X20: 0.35 | Y20: =$W$8*X20 -> 238.55263 | Z20: =W20+Y20 -> 4840.5526
A26: BNSF rates for | K26: BNSF rates for | U26: UP rates for
A27: Davenport, IA | B27: to | C27: St. Louis, MO | K27: Davenport, IA | L27: to | M27: St. Louis, MO | U27: Davenport, IA to St. Louis, MO
U28: (Clinton, IA)
A29: Corn | K29: Soybeans | U29: Corn, Soybean
A30: Heavy axle railcars -- load to 111 tons | E30: = | F30: =111/1.10231 -> 100.69763 | G30: MT | K30: Heavy axle railcars -- load to 111 tons | O30: = | P30: =111/1.10231 -> 100.69763 | Q30: MT | U30: Heavy axle railcars -- load to 111 tons
A31: Shuttle trains of 110 to 120 railcars | K31: Shuttle trains of 110 to 120 railcars | U31: Shuttle trains of 110 to 120 railcars
A32: Miles | C32: 265 | K32: Miles | M32: 265 | U32: Miles | W32: 276.31579
D33: FSC | E33: FSC | F33: Tariff + | H33: Rate per | N33: FSC | O33: FSC | P33: Tariff + | R33: Rate per | X33: FSC | Y33: FSC | Z33: Tariff + | AB33: Rate per
A34: Month/year | C34: Tariff rate | D34: rate/mile | E34: per carload | F34: FSC | H34: Railcar | I34: Rate/MT | K34: Month/year | M34: Tariff rate | N34: rate/mile | O34: per carload | P34: FSC | R34: Railcar | S34: Rate/MT | U34: Month/year | W34: Tariff rate | X34: rate/mile | Y34: per carload | Z34: FSC | AB34: Railcar | AC34: Rate/MT
A35: Jan. 14 | C35: 3620 | D35: 0.34 | E35: =D35*$C$32 -> 90.1 | F35: =C35+E35 -> 3710.1 | K35: Jan. 14 | M35: 2816 | N35: 0.34 | O35: =N35*$C$32 -> 90.1 | P35: =M35+O35 -> 2906.1 | U35: Jan. 14 | W35: 3189 | X35: 0.35 | Y35: =$W$32*X35 -> 96.710526 | Z35: =W35+Y35 -> 3285.7105
A36: Feb. 14 | C36: 3620 | D36: 0.35 | E36: =D36*$C$32 -> 92.75 | F36: =C36+E36 -> 3712.75 | K36: Feb. 14 | M36: 2816 | N36: 0.35 | O36: =N36*$C$32 -> 92.75 | P36: =M36+O36 -> 2908.75 | U36: Feb. 14 | W36: 3189 | X36: 0.36 | Y36: =$W$32*X36 -> 99.473684 | Z36: =W36+Y36 -> 3288.4737
A37: Mar. 14 | C37: 3620 | D37: 0.35 | E37: =D37*$C$32 -> 92.75 | F37: =C37+E37 -> 3712.75 | G37: 1Q 14 | H37: =AVERAGE(F35:F37) -> 3711.8667 | I37: =H37/$F$30 -> 36.861511 | K37: Mar. 14 | M37: 2816 | N37: 0.35 | O37: =N37*$C$32 -> 92.75 | P37: =M37+O37 -> 2908.75 | Q37: 1Q 14 | R37: =AVERAGE(P35:P37) -> 2907.8667 | S37: =R37/$F$30 -> 28.877212 | U37: Mar. 14 | W37: 3189 | X37: 0.36 | Y37: =$W$32*X37 -> 99.473684 | Z37: =W37+Y37 -> 3288.4737 | AA37: 1Q 14 | AB37: =AVERAGE(Z35:Z37) -> 3287.5526 | AC37: =AB37/$F$6 -> 32.647767
A38: Apr. 14 | C38: 3620 | D38: 0.38 | E38: =D38*$C$32 -> 100.7 | F38: =C38+E38 -> 3720.7 | K38: Apr. 14 | M38: 2816 | N38: 0.38 | O38: =N38*$C$32 -> 100.7 | P38: =M38+O38 -> 2916.7 | U38: Apr. 14 | W38: 3189 | X38: 0.38 | Y38: =$W$32*X38 -> 105 | Z38: =W38+Y38 -> 3294
A39: May. 14 | C39: 3620 | D39: 0.38 | E39: =D39*$C$32 -> 100.7 | F39: =C39+E39 -> 3720.7 | K39: May. 14 | M39: 2816 | N39: 0.38 | O39: =N39*$C$32 -> 100.7 | P39: =M39+O39 -> 2916.7 | U39: May. 14 | W39: 3189 | X39: 0.39 | Y39: =$W$32*X39 -> 107.76316 | Z39: =W39+Y39 -> 3296.7632
A40: Jun. 14 | C40: 3620 | D40: 0.37 | E40: =D40*$C$32 -> 98.05 | F40: =C40+E40 -> 3718.05 | G40: 2Q14 | H40: =AVERAGE(F38:F40) -> 3719.8167 | I40: =H40/$F$30 -> 36.94046 | K40: Jun. 14 | M40: 2816 | N40: 0.37 | O40: =N40*$C$32 -> 98.05 | P40: =M40+O40 -> 2914.05 | Q40: 2Q14 | R40: =AVERAGE(P38:P40) -> 2915.8167 | S40: =R40/$F$30 -> 28.956161 | U40: Jun. 14 | W40: 3189 | X40: 0.38 | Y40: =$W$32*X40 -> 105 | Z40: =W40+Y40 -> 3294 | AA40: 2Q14 | AB40: =AVERAGE(Z38:Z40) -> 3294.9211 | AC40: =AB40/$F$6 -> 32.720941
A41: Jul. 14 | C41: 3620 | D41: 0.37 | E41: =D41*$C$32 -> 98.05 | F41: =C41+E41 -> 3718.05 | K41: Jul. 14 | M41: 2816 | N41: 0.37 | O41: =N41*$C$32 -> 98.05 | P41: =M41+O41 -> 2914.05 | U41: Jul. 14 | W41: 3189 | X41: 0.37 | Y41: =$W$32*X41 -> 102.23684 | Z41: =W41+Y41 -> 3291.2368
A42: Aug. 14 | C42: 3620 | D42: 0.36 | E42: =D42*$C$32 -> 95.4 | F42: =C42+E42 -> 3715.4 | K42: Aug. 14 | M42: 2816 | N42: 0.36 | O42: =N42*$C$32 -> 95.4 | P42: =M42+O42 -> 2911.4 | U42: Aug. 14 | W42: 3189 | X42: 0.37 | Y42: =$W$32*X42 -> 102.23684 | Z42: =W42+Y42 -> 3291.2368
A43: Sep. 14 | C43: 3620 | D43: 0.35 | E43: =D43*$C$32 -> 92.75 | F43: =C43+E43 -> 3712.75 | G43: 3Q14 | H43: =AVERAGE(F41:F43) -> 3715.4 | I43: =H43/$F$30 -> 36.8966 | K43: Sep. 14 | M43: 2816 | N43: 0.35 | O43: =N43*$C$32 -> 92.75 | P43: =M43+O43 -> 2908.75 | Q43: 3Q14 | R43: =AVERAGE(P41:P43) -> 2911.4 | S43: =R43/$F$30 -> 28.9123 | U43: Sep. 14 | W43: 3189 | X43: 0.36 | Y43: =$W$32*X43 -> 99.473684 | Z43: =W43+Y43 -> 3288.4737 | AA43: 3Q14 | AB43: =AVERAGE(Z41:Z43) -> 3290.3158 | AC43: =AB43/$F$6 -> 32.675207
A44: Oct. 14 | C44: 3620 | D44: 0.34 | E44: =D44*$C$32 -> 90.1 | F44: =C44+E44 -> 3710.1 | K44: Oct. 14 | M44: 2816 | N44: 0.34 | O44: =N44*$C$32 -> 90.1 | P44: =M44+O44 -> 2906.1 | U44: Oct. 14 | W44: 3339 | X44: 0.35 | Y44: =$W$32*X44 -> 96.710526 | Z44: =W44+Y44 -> 3435.7105
A62: BNSF rates for | K62: BNSF rates for
A63: Fargo, ND | B63: to | C63: Tacoma, WA | K63: Minneapolis,MN to Portland, OR
A64: (Casselton, ND) | K64: (New Ulm, MN)
...
