Workbook
Name E: 'Memo HIV'!$F$3
Name ES: 'Memo HIV'!$F$4
Name HIVII: 'Memo HIV'!$B$2:$B$8
Name HIVOI: 'Memo HIV'!$D$2:$D$15
Name HIVSDA: 'Memo HIV'!$A$2:$A$30
Name HIVSource: 'Memo HIV'!$E$2:$E$22
Name IndicatorTypesList: [1]SDAs_impact_datasources!$D$2:$D$3
Name LFA_SDA: #REF!
Name LFA_SDA: '[2]LFA_Programmatic Progress_1B'!#REF!
Name LFA_SDA: #REF!
Name LFA_SDA: 'LFA_Programmatic Progress_1B'!#REF!
Name LFASig: #REF!
Name LFASig: '[2]LFA_Signature (image)'!$B$2
Name LFASig: #REF!
Name LFASig: #REF!
Name list: #REF!
Name List_IE: 'Definitions-lists-EFR'!$A$58:$A$65
Name list1: #REF!
Name list2: #REF!
Name listH: #REF!
Name listH: #REF!
Name ListHIV: 'Definitions-lists-EFR'!$A$1:$A$7
Name ListHIV_SDA: 'Definitions-lists-EFR'!$A$11:$A$18
Name listie: #REF!
Name listmac: #REF!
Name ListMal: 'Definitions-lists-EFR'!$A$21:$A$25
Name ListMal_SDA: 'Definitions-lists-EFR'!$A$28:$A$35
Name listnew: #REF!
Name listS: #REF!
Name listsda: #REF!
Name listsdah: #REF!
Name listsdahiv: #REF!
Name listsdahiv1: #REF!
Name listsdam: [3]Definitions!$C$28:$C$50
Name listsdat: #REF!
Name listsdat1: [4]Definitions!$C$39:$C$54
Name listserv: #REF!
Name ListTB: 'Definitions-lists-EFR'!$A$39:$A$44
Name ListTB_SDA: 'Definitions-lists-EFR'!$A$48:$A$55
Name MalariaII: 'Memo Malaria'!$B$2:$B$10
Name MalariaOI: 'Memo Malaria'!$D$2:$D$10
Name MalariaSDA: 'Memo Malaria'!$A$2:$A$23
Name MalariaSource: 'Memo Malaria'!$E$2:$E$25
Name Please_Select: 'Memo Malaria'!$A$3:$A$14
Name PR_SDA: #REF!
Name PR_SDA: '[2]LFA_Programmatic Progress_1A'!#REF!
Name PR_SDA: 'PR_Programmatic Progress_1B'!$C$12:$C$31
Name PR_SDA: #REF!
Name PR_SDA: 'LFA_Programmatic Progress_1A'!#REF!
Name PS: 'Memo HIV'!$F$5
Name SD: #REF!
Name SD: #REF!
Name SDA: #REF!
Name SDA: #REF!
Name SDAList: 'Memo Malaria'!$A$3:$A$20
Name Select: 'Memo HIV'!$J$2:$J$3
Name Sources: #REF!
Name Sources: #REF!
Name TBII: 'Memo TB'!$B$2:$B$5
Name TBOI: 'Memo TB'!$D$2:$D$5

Sheet Cover Sheet
A1: On-going Progress Update and Disbursement Request and LFA On-going Progress Review and Disbursement Recommendation
A3: In completing this report, please refer to the detailed "Guidelines for completing the PR “ongoing progress update and disbursement request”, and LFA “ongoing progress review and disbursement recommendation”
A4: During the lifetime of a grant, the Global Fund periodically disburses funds to the Principal Recipient (PR) based on demonstrated program performance and financial needs for the following period of implementation. The PR’s ongoing progress update and disbursement request (PU/DR) is both a progress report on the latest completed period of program implementation and a request for funds for the following period of implementation. Its purpose is to provide an update of the programmatic and financial progress of a Global Fund-financed grant, as well as an update on fulfillment of conditions precedent, management actions and other requirements. The PU/DR, alongside the Local Fund Agent (LFA) ongoing progress review and disbursement recommendation (short-form: LFA-verified PU/DR), forms the basis for the Global Fund’s disbursement decision by linking historical and expected program performance with the level of financing to be provided to the PR. One Excel file contains both the PR’s PU/DR and the LFA-verified PU/DR. The PR should only complete the worksheets of the file pertaining to the PU/DR (the worksheet tabs color-coded in green), whereas the LFA should complete the worksheets of the file pertaining to the LFA-verified PU/DR (the worksheet tabs color-coded in blue). The Excel file also includes a reference checklist of supporting documents for the PU/DR review (the worksheet tab color-coded in yellow). This checklist is included for information and not for completion. The PU/DR should be completed by the PR of a Global Fund grant for every period in which a progress update is required, usually either on a quarterly, semiannual or annual basis, regardless of whether or not a disbursement is being requested. Once a year, the PR is expected to submit the Enhanced Financial Report (EFR) as part of the PU/DR (there is a dedicated tab for EFR in the Excel file). The PR is required to submit the PU/DR to the LFA within 45 calendar days from the closing date of the relevant progress update period when the report does not contain the EFR (as indicated in the performance framework of Annex A of the grant agreement) and within 60 calendar days when the report contains the EFR (once a year). The LFA should complete and submit a signed copy of the LFA-verified PU/DR to the Global Fund within ten working days after receiving the final signed version of the PU/DR from the PR and within 13 working days when the PU/DR report contains the EFR (once a year), unless agreed otherwise with the FPM (The LFA does not need to submit original/hard copies of each PU/DR reports. However, these documents should be available at the LFA’s offices for any audit/reviews. Also, the LFA should be ready at all times to submit these originals to the Secretariat upon request). In this report the LFA should provide an analysis and comments based on verification of the PR-reported information, document grant risks and recommendations for improving program implementation, and finally, provide a performance rating to the grant and disbursement recommendation for the Global Fund’s consideration. In defining the performance rating and recommending a disbursement amount, the LFA should use the Grant Rating Methodology of the Global Fund (as described in Annex 2 and communicated at various regional meetings and LFA training events) along with the Excel version of the Grant Rating Tool (to be provided to LFAs) to support the calculation of Indicator Rating.
A17: Upon completion, this form should be submitted (with supporting documentation) to the Local Fund Agent and copied to the Global Fund.

Sheet PR_Programmatic Progress_1A
A1: On-going Progress Update and Disbursement Request | U1: Select
U2: AIS (AIDS Indicator Survey)
U3: BSS (Behavioral and Surveillance Survey)
A4: GENERAL GRANT INFORMATION | U4: Census
A5: Country: | C5: Monrovia | U5: Clinical cohort follow-up studies
A6: Disease: | C6: HIV/AIDS | U6: DHS/DHS+ (Demographic and Health Survey)
A7: Grant Number: | C7: MNR-809-G04-H | U7: MICS (Multiple Indicator Cluster Survey)
A8: Principal Recipient: | C8: Ministry of Health | U8: MIS (Malaria Indicator Survey)
A9: Program Start Date: | C9: 40087 | U9: WHO Global report/estimates
A10: Currency: | C10: EUR | U10: Other (type as appropriate)
A11: PROGRESS UPDATE
A12: Progress Update - Reporting Period: | C12: Cycle: | D12: Quarter | E12: Number: | F12: 7
A13: Progress Update - Period Covered: | C13: Beginning Date: | D13: 40452 | E13: End Date: | F13: 40543
A14: Progress Update - Number: | C14: 5
A15: DISBURSEMENT REQUEST
A16: Disbursement Request - Disbursement Period: | C16: Cycle: | D16: Quarter | E16: Number: | F16: 8
A17: Disbursement Request - Period Covered: | C17: Beginning Date: | D17: 40544 | E17: End Date: | F17: 40633
A18: Disbursement Request - Number: | C18: 6
A22: Section 1: Programmatic Progress
A23: Note: The table below should contain those Impact/Outcome indicators that are (1) due for reporting during the current year of a grant and (2) those reporting on which is overdue from the previous periods.
A24: A. Impact / Outcome Indicators
A25: Impact / Outcome | B25: Indicator Description | G25: Baseline (if applicable) | I25: Year of Target | J25: Intended Target | K25: Report Due Date | L25: Actual Result | M25: Data Source of Results | N25: Comments on results on Impact/Outcome indicators and data sources, and any other comments
G26: Value | H26: Year
A27: Outcome | B27: % of young women and men aged 15 - 24 who have had sexual intercourse before the age of 15 | G27: 2.7 (males) 17.1% (females) | H27: 2005 | I27: 2010 | J27: 2.1% (males) 13% (females) | K27: 40543 | L27: 1.5% (males) 7.4% (females) | M27: BSS (Behavioral and Surveillance Survey) | N27: Draft report of the BSS has been validated. Final report expecetd on 21/02/11
A28: Impact | B28: % of young women and men aged 15 - 24 who are HIV infected | G28: 2.4% NSS | H28: 2006 | I28: 2010 | J28: 0.0224 | K28: 40543 | L28: - | M28: Other (NSS) | N28: Preparatory work for 2010 NSS has been completed and sample collection is expected to commence soon
A29: Outcome | B29: % of most-at-risk populatoion(s) (sex workers, clients of sex workers, men who have sex with men, injecting drug users) who are HIV infected | G29: TBA | H29: 2008 | I29: 2011 | J29: TBD | K29: - | L29: - | M29: Other (2 yearly mapping) | N29: Two-yearly mapping updates and surveys
A30: Outcome | B30: % of people aged 15 - 49 years with more than one sexual partners in the past 12 months reporting the use of condoms during their last sexual intercourse | G30: 18.8% (males) 11.1% (females) | H30: 2010 | I30: 2010 | J30: 18.8% (males) 11.1% (females) | K30: 40543 | L30: 18.8% (males) 11.1% (females) | M30: BSS (Behavioral and Surveillance Survey) | N30: Draft report of the BSS has been validated. Final report expecetd on 21/02/11
A31: Outcome | B31: % of young people aged 10 -24 years reached by life skill-based HIV/AIDS education in and out of school | G31: 0.56 | H31: 2010 | I31: 2010 | J31: 0.56 | K31: 40543 | L31: 0.56 | M31: Other (Life skills based HIV/AIDS education survey) | N31: Baseline information information on out-of school youths reached through life skills training updated in the report and new baseline established.
A32: Select | G32: - | H32: - | I32: - | J32: - | K32: - | L32: - | M32: Select
A33: Select | G33: - | H33: - | I33: - | J33: - | K33: - | L33: - | M33: Select
A34: Select | G34: - | H34: - | I34: - | J34: - | K34: - | L34: - | M34: Select
A35: Select | G35: - | H35: - | I35: - | J35: - | K35: - | L35: - | M35: Select
A36: Select | G36: - | H36: - | I36: - | J36: - | K36: - | L36: - | M36: Select

Sheet PR_Programmatic Progress_1B
A1: On-going Progress Update and Disbursement Request
A2: PROGRESS UPDATE PERIOD
A3: Grant number: | D3: =IF('PR_Programmatic Progress_1A'!C7="","",'PR_Programmatic Progress_1A'!C7) -> MNR-809-G04-H
A4: Progress Update - Reporting Period: | D4: Cycle: | E4: =IF('PR_Programmatic Progress_1A'!D12="Select","",'PR_Programmatic Progress_1A'!D12) -> Quarter | F4: Number: | G4: 7
A5: Progress Update - Period Covered: | D5: Beginning Date: | E5: =IF('PR_Programmatic Progress_1A'!D13="","",'PR_Programmatic Progress_1A'!D13) -> 40452 | F5: End Date: | G5: =IF('PR_Programmatic Progress_1A'!F13="","",'PR_Programmatic Progress_1A'!F13) -> 40543
A6: Progress Update - Number: | D6: 5
A8: Note: All programmatic indicators contained in the current Performance Framework should be listed, regardless of whether there are targets/results for the period covered by the Progress Update or whether the targets have been met in previous periods.
A9: B. Programmatic Indicators
A10: Objective No. | B10: * Indicator No. | C10: Indicator Description | G10: Tied To | H10: Targets cumulative? | I10: Top 10 indicator? | J10: Baseline (if applicable) | L10: Intended Target to date | M10: Actual Result to date | N10: % achievement (Please calculate as appropriate) | O10: Reasons for programmatic deviation from intended target and deviations from the related workplan activities
J11: Value | K11: Year
A12: 1 | B12: 1.2 | C12: Number of commercial sex workers reached with prevention interventions | G12: GF | H12: Y-cumulative annually | I12: Yes - Top 10 | J12: 95 | K12: 2008 | L12: 225 | M12: 100 | N12: =M12/L12 -> 0.44444444 | O12: The delays are due to the following reasons: The PR has canceled a contract with one SR due to performance and accountability issues. There is ongoing prevention work with CSWs in the capital city but given the underperformance with regards to the set targets for prevention activities for commercial sex workers, the PR has decided to support service delivery sites in additional cities and towns where the need for the work with this target group has been identified (initial findings of ongoing BSS activities). The PR has signed contracts with new SRs after the end of the reporting period and plans to accelerate the work to achieve the targets. The PR has developed with the new SRs an accelerated implementation plan, to be supported with the unused budgeted resources as of the end of Q5 (EUR 400,000) (see attached docs).
A13: 1 | B13: 1.3 | C13: Number of medical (doctors and nurses) and non-medical staff (psychologists, social assistants, peer consultants) trained in HIV/AIDS | G13: GF | H13: Y-over program term | I13: Yes - Top 10 | J13: n/a | K13: n/a | L13: 400 | M13: 594 | N13: =M13/L13 -> 1.485 | O13: The PR, in coordination with the sub-recipients, managed to deliver trainings to more people than initially planned. The target was exceeded by 194 people. This was possible due to the involvement of a newly opened training center with the Medical Academy in the capital city and the engagement of the Regional Centers of the social services. The PR coordinated with the regional centers to add a module on HIV/AIDS to a training program, which was already organized by the social services. . All sub-recipients and contractors are required to maintain detailed training records. The PR is also conducting spot checks of training activities. The PR is also conducting spot checks of training activities. Finally, the PR is reviewing all SR reports and training log sheets, cross-checking the data and maintaining a central database of participants in trainings. As a result of the PR’s quality checks, 53 people from the SR reports were excluded from the cumulative results reported by the PR (e.g. due to incomplete records, double-counting by SRs).
A14: 1 | B14: 1.4 | C14: Number of IDUs on opioid substitution therapy | G14: GF | H14: Y-over program term | I14: Yes - Top 10 | J14: 30 | K14: 2008 | L14: 100 | M14: 0 | N14: =M14/L14 -> 0 | O14: While no people started methadone therapy during the reporting period, a number of important preparatory activities were completed. The first site in the capital city was fully renovated and it passed successfully the mandatory review procedures by the local authorities, who granted the necessary authorizations for its full-fledge operation. In the meantime, the contractors for the renovation of the service delivery facilities in one additional spot in the capital city and two other regional centers were selected and they started the renovation works in these spots. Importantly, the necessary authorizations for the methadone import were obtained and the partial pre-payment (15% of the invoice amount) was made during the reporting period. The methadone was actually delivered to the country after the end of the reporting period, and at the time of this PU/DR submission the first patients are already receiving therapy in the capital city. The already functioning center has the capacity to service 60 people per day and we expect to accelerate performance in this area. With the ongoing work on the opening of similar centers in other locations, we will be able to achieve the set targets.
A15: 2 | B15: 2.1 | C15: Number of people provided with ARV treatment | G15: Current grant | H15: N-not cumulative | I15: Yes - Top 10 | J15: 200 | K15: 2008 | L15: 300 | M15: 300 | N15: =M15/L15 -> 1 | O15: We are fully on track with the set targets for this indicator thanks to close coordination with the Central and Regional Infectious Disease Hospitals and the close cooperation with the NGOs providing care and support to the patients. It is important to note that the PR has supported the development of a comprehensive treatment monitoring electronic system, including treatment regimens and ARV drugs consumption. The system has been rolled out at the central hospital for now and following the field testing, the necessary revisions will be made and the e-system will be rolled out to the regional centers.
G18: Select | H18: Select | I18: Select | L18: - | M18: -
G19: Select | H19: Select | I19: Select | L19: - | M19: -
G20: Select | H20: Select | I20: Select | L20: - | M20: -
G21: Select | H21: Select | I21: Select | L21: - | M21: -
G22: Select | H22: Select | I22: Select | L22: - | M22: -
G23: Select | H23: Select | I23: Select | L23: - | M23: -
G24: Select | H24: Select | I24: Select | L24: - | M24: -
G26: Select | H26: Select | I26: Select | L26: - | M26: -
G27: Select | H27: Select | I27: Select | L27: - | M27: -
G28: Select | H28: Select | I28: Select | L28: - | M28: -
G29: Select | H29: Select | I29: Select | L29: - | M29: -
G30: Select | H30: Select | I30: Select | L30: - | M30: -
A32: * Indicator No. should correspond to the indicator number listed in the approved Performance Framework of the grant (1.1, 1.2, etc.)
A33: C. Analysis of data quality and reporting issues (!) This section should contain (1) a summary of issues related to data quality and reporting on programmatic indicators, and any relevant issues which are not covered in 'Reasons for programmatic deviation', and (2) remedial actions that are underway or planned to address these issues.
A35: Please see above for details.

Sheet PR_Grant Management_2
A1: On-going Progress Update and Disbursement Request
A2: PROGRESS UPDATE PERIOD
A3: Grant number: | D3: =IF('PR_Programmatic Progress_1A'!C7="","",'PR_Programmatic Progress_1A'!C7) -> MNR-809-G04-H
A4: Progress Update - Reporting Period: | D4: Cycle: | E4: =IF('PR_Programmatic Progress_1A'!D12="Select","",'PR_Programmatic Progress_1A'!D12) -> Quarter | F4: Number: | G4: =IF('PR_Programmatic Progress_1A'!F12="Select","",'PR_Programmatic Progress_1A'!F12) -> 7
A5: Progress Update - Period Covered: | D5: Beginning Date: | E5: =IF('PR_Programmatic Progress_1A'!D13="","",'PR_Programmatic Progress_1A'!D13) -> 40452 | F5: End Date: | G5: =IF('PR_Programmatic Progress_1A'!F13="","",'PR_Programmatic Progress_1A'!F13) -> 40543
A6: Progress Update - Number: | D6: 5
A8: Section 2: Grant Management
A10: A. PR COMMENTS ON THE FULFILLMENT OF CONDITIONS PRECEDENT AND/OR SPECIAL CONDITIONS UNDER THE GRANT AGREEMENT
A12: ! Please include in this table the CP number as per Grant Agreement and full text of CPs and/or other special conditions due for fulfilment during this period or outstanding from previous periods. ! Some Special Conditions may apply to more than one period of grant implementation. Their fulfilment during one period does not automatically imply fulfilment in subsequent periods. The LFA should verify that the status of such conditions is reported by the PR during each period concerned.
A13: Conditions Precedent and/or other special conditions | F13: Status | G13: PR Comments on Progress of Implementation
A14: The first disbursement of Grant funds by the Global Fund to the Principal Recipient is subject to the satisfaction of each of the following conditions: a. the delivery by the Principal Recipient to the Global Fund of a statement confirming the bank account into which the Grant funds will be disbursed as indicated in block 10 of the face sheet of this Agreement; | F14: Met | G14: This condition was initially met at the time of grant signing. During the last reporting period, the GF communicated a management action to the PR requiring the opening of a separate bank account. The PR opened the required separate bank account. Please find attached the PR Bank Details form duly completed and the respective supporting documents for the new bank account.
A15: The second disbursement of Grant funds by the Global Fund to the Principal Recipient is subject to the delivery by the Principal Recipient to the Global Fund of evidence, in form and substance satisfactory to the Global Fund, that the Principal Recipient has upgraded its Accounting System as well as its Accounting Manual, particularly cash basis of accounting, to facilitate compliance with Global Fund reporting requirements. | F15: Met | G15: The condition was fulfilled. The PR has upgraded its accounting system to generate expense reports on cash basis. The Accounting Manual was also updated to reflect the requirement for cash basis reporting to the GF and the necessary changes in the internal accounting procedures.
A17: B. PR REVIEW OF PROGRESS ON IMPLEMENTATION OF OUTSTANDING MANAGEMENT ACTIONS FROM PREVIOUS DISBURSEMENTS
A18: ! Please list all issues raised in the last Management Letter from the Global Fund or outstanding from previous Management Letters, and comment on the progress. Please include the date of the management letter and the item number.
A20: Global Fund Management Actions | E20: PR Comments on Progress of Implementation
A21: Reduce Stigma and Discrimination - Meaningful involvement of PLHIVs (Mission meeting in Nov. 2010) | E21: The two PRS (AAITG/NAS) had a joint meeting with all SRs on the R8 grant including social workers from ART sites which agreed that PLHIVs should be involved in all grant activities where possible in order to help reduce stigma and discrimination
A26: 1. The sub-recipients audit plan is still outstanding. It was due by 30 October 2010. | E26: The PR was indeed late with the submission of the plan for the audit of SRs for Year 1 (1 October 2009 - 30 September 2010) of the program. The SR audit plan, however, was submitted in December following the newly issued GF Guidelines on Annual Audits. The GF has already commented on the plan and required further amendments. They were made and the revised SR Audit Plan was submitted in January. Hence, the management action was completed.
A27: 2. The PR needs to open a separate bank account for this grant and transfer the correct cash balance from the current joint bank account. | E27: The bank account is opened and new bank instructions are provided for this disbursement. The Finance team has calculate the necessary balance on GF funds to be transferred to the account and submitted the necessary calculations and supporting information and documentation to the LFA for their review.
A28: 3. Although the PR has upgraded its accounting system to allow generating expenses reports on cash basis, the expenditures in the PU are still presented using the accrual basis of accounting. This prevents the verification of the cash balance, which is being calculated as a balance based on the cumulative expenditures of the program. Cumulative expenditures need to be updated based on actual cash disbursements from the PR grant account. | E28: The PR has worked on this point and the expenses for the reporting period covered by this PU/DR (both current reporting period expenditures and cumulative expenditures) are presented on a cash basis.
A35: C. PR COMMENTS ON ANNUAL GRANT REPORTING REQUIREMENTS
A36: ! Please indicate a date for the report due for submission. If a report is overdue, indicate the original due date and explain the reason for delay.
A37: Required Documentation | E37: Due date (dd-mmm-yy) | F37: Status | G37: Comments
A38: PR Audit Report | E38: 40724 | F38: Preparation on track
A39: PR Audit Report | E39: 40633 | F39: Preparation on track | G39: The audit company was selected and contracted, the field audit work was completed, the final report is due for submission by the end of March.
A40: Enhanced Financial Reporting (EFR) | E40: 40589 | F40: Submitted to GF | G40: The EFR was submitted in accordance with the set timelines.

Sheet PR_Total PR Cash Outflow_3A
A1: On-going Progress Update and Disbursement Request
A2: PROGRESS UPDATE PERIOD
A3: Grant number: | D3: =IF('PR_Programmatic Progress_1A'!C7="","",'PR_Programmatic Progress_1A'!C7) -> MNR-809-G04-H
A4: Progress Update - Reporting Period: | D4: Cycle: | E4: =IF('PR_Programmatic Progress_1A'!D12="Select","",'PR_Programmatic Progress_1A'!D12) -> Quarter | F4: Number: | G4: =IF('PR_Programmatic Progress_1A'!F12="Select","",'PR_Programmatic Progress_1A'!F12) -> 7
A5: Progress Update - Period Covered: | D5: Beginning Date: | E5: =IF('PR_Programmatic Progress_1A'!D13="","",'PR_Programmatic Progress_1A'!D13) -> 40452 | F5: End Date: | G5: =IF('PR_Programmatic Progress_1A'!F13="","",'PR_Programmatic Progress_1A'!F13) -> 40543
A6: Progress Update - Number: | D6: =IF('PR_Programmatic Progress_1A'!C14="Select","",'PR_Programmatic Progress_1A'!C14) -> 5
A7: Currency: | D7: =IF('PR_Programmatic Progress_1A'!C10="Select","",'PR_Programmatic Progress_1A'!C10) -> EUR
A9: Section 3A: Total PR Cash Outflow
A10: ! For RCC grants the cumulative section of the table below should contain cumulative amount from the start of the RCC and not from the start of Phase 1 of the program.
C11: Budget for Reporting Period | D11: Actual Cash Outflow for Reporting Period | E11: Variance | F11: Reason for Variance | H11: Cumulative Budget through period of Progress Update | I11: Cumulative Actual Cash Outflow through period of Progress Update | J11: Variance | K11: Reason for Variance
A12: 1. Total PR cash outflow vs. budget | C12: =C13+C14 -> 2500000 | D12: =D13+D14 -> 2235000 | E12: =IF(C12="",IF(D12="","",C12-D12),C12-D12) -> 265000 | H12: =H13+H14 -> 5600000 | I12: =I13+I14 -> 4500000 | J12: =IF(H12="",IF(I12="","",H12-I12),H12-I12) -> 1100000
A13: 1a. PR's total expenditures | C13: 1500000 | D13: 1435000 | E13: =IF(C13="",IF(D13="",0,C13-D13),C13-D13) -> 65000 | F13: Not implemented: 50,000 Technical Assistance for lab assessment Staff travel not realized in the amount of 15,000. | H13: 2600000 | I13: 2000000 | J13: =IF(H13="",IF(I13="",0,H13-I13),H13-I13) -> 600000 | K13: Contracts signed for procuring CD4 count equipment but not yet paid - 300,000. Final installment per signed contract to be paid for transportation and storage of drugs in regional warehouses - 35,000. Savings: 100,000 from late recruitment of staff Delayed activities (in progress now): 265,000 (media campaign - 50,000, refurbishment of facilities for delivery of opioid substitution therapy - 150,000, trainings related to substitution therapy - $15,000) Advance payment: (100,000) for procurement of test systems brought forward from Q7 due to bulk order
A14: 1b. Disbursements to sub-recipients | C14: 1000000 | D14: 800000 | E14: =IF(C14="",IF(D14="",0,C14-D14),C14-D14) -> 200000 | F14: The PR has canceled a contract with one SR due to performance and accountability issues. Given the underperformance with regards to the set targets for prevention activities for commercial sex workers, the PR has decided to support service delivery sites in additional cities and towns where the need for the work with this target group has been identified (initial findings of ongoing BSS activities). The PR has signed contracts with new SRs after the end of the reporting period and plans to accelerate the work to achieve the targets. The PR has developed with the new SRs an accelerated implementation plan, to be supported with the unused budgeted resources as of the end of Q5 (200,000) (see attached docs). | H14: 3000000 | I14: 2500000 | J14: =IF(H14="",IF(I14="",0,H14-I14),H14-I14) -> 500000 | K14: The PR has canceled a contract with one SR due to performance and accountability issues. Given the underperformance with regards to the set targets for prevention activities for commercial sex workers, the PR has decided to support service delivery sites in additional cities and towns where the need for the work with this target group has been identified (initial findings of ongoing BSS activities). The PR has signed contracts with new SRs after the end of the reporting period and plans to accelerate the work to achieve the targets. The PR has developed with the new SRs an accelerated implementation plan, to be supported with the unused budgeted resources as of the end of Q5 (200,000) (see attached docs). Payments in the amount of 300,000 were not made to SRs by the end of the reporting period due to delays in submission of the SR reports or inconsistent reports. Payment in the amount of 280,000 was made to SR right after the end of the reporting period (for all SRs where the outstanding issues were successfully resolved).
C16: Budget for Reporting Period* | D16: Actual Cash Outflow for Reporting Period | E16: Variance | F16: Reason for Variance | H16: Cumulative Budget through period of Progress Update | I16: Cumulative Actual Cash Outflow through period of Progress Update | J16: Variance | K16: Reason for Variance
A17: 2. Total pharmaceutical & health product expenditures vs. budget | C17: =C18+C19 -> 1300000 | D17: =D18+D19 -> 1350000 | E17: =IF(C17="",IF(D17="","",C17-D17),C17-D17) -> -50000 | H17: =H18+H19 -> 2500000 | I17: =I18+I19 -> 1950000 | J17: =IF(H17="",IF(I17="","",H17-I17),H17-I17) -> 550000
A18: 2a. Medicines and pharmaceutical products | C18: 600000 | D18: =C18-50000 -> 550000 | E18: =IF(C18="",IF(D18="",0,C18-D18),C18-D18) -> 50000 | F18: OI drugs cost less than initially budgeted (savings in the amount of 50,000). | H18: 1000000 | I18: 850000 | J18: =IF(H18="",IF(I18="",0,H18-I18),H18-I18) -> 150000 | K18: OI drugs cost less than initially budgeted (savings in the amount of 50,000). These savings are used to fund higher prices for some second-line ARVs. There is a last installement for the annual order of ARV drugs in the amount 100,000 to be paid in the next quarter.
A19: 2b. Health products and health equipment | C19: 700000 | D19: =C19+100000 -> 800000 | E19: =IF(C19="",IF(D19="",0,C19-D19),C19-D19) -> -100000 | F19: Advance payment: (100,000) for procurement of test systems brought forward from Q7 due to bulk order | H19: 1500000 | I19: =H19-E19-500000 -> 1100000 | J19: =IF(H19="",IF(I19="",0,H19-I19),H19-I19) -> 400000 | K19: Advance payment: (100,000) for procurement of test systems brought forward from Q7 due to bulk order. The order for lab equipment was placed (total amount: 500,000) - payment will be made in installements in the next two quarters.

Sheet EFR HIV AIDS Financial Data_3B
A1: SECTION 3B: HIV/AIDS FINANCIAL REPORTING FORM
A3: Country | C3: ='PR_Programmatic Progress_1A'!C5:F5 -> Monrovia | F3: PLEASE REFER TO THE "GUIDANCE FOR COMPLETION OF THE ENHANCED FINANCIAL REPORTING TEMPLATE" DOCUMENT TO ASSIST YOU IN COMPLETING THE TEMPLATE
A4: Grant No. | C4: ='PR_Programmatic Progress_1A'!C7:F7 -> MNR-809-G04-H
A5: PR | C5: ='PR_Programmatic Progress_1A'!C8:F8 -> Ministry of Health | F5: TO BE COMPLETED ONLY ONCE A YEAR EXCEPT AT MONTH 18 FOR PURPOSES OF PHASE 2 REVIEW
A6: Currency | C6: Please Select …
G7: dd-mm-yyyy | K7: dd-mm-yyyy
E8: Current Reporting Period | F8: Start Date: | I8: Cumulative Reporting Period | J8: Start Date:
F9: End Date: | J9: End Date:
H10: The end date for the current reporting period and cumulative reporting period must be the same
E12: The "TOTAL" rows in Table A, B and C will have a RED background if the amounts in each table do not agree. If the Totals for each Table agrees, these rows will have a YELLOW background.
A15: A- BREAKDOWN* BY EXPENDITURE CATEGORY | E15: Current Reporting Period | I15: Cumulative Reporting Period | P15: =IF('PR_Programmatic Progress_1A'!R15="Select","Please select currency on Page 'PR_Programmatic Achievement (1)'", "All amounts are in: "&'PR_Programmatic Progress_1A'!R15) -> All amounts are in: | R15: Budget for Reporting Period | S15: Actual Cash Outflow for Reporting Period | T15: Variance | U15: Reason for Variance | W15: Cumulative Budget through period of Progress Update | X15: Cumulative Actual Cash Outflow through period of Progress Update | Y15: Variance | Z15: Reason for Variance
A16: # | B16: Category | E16: Budget | F16: Expenditures | G16: Variance | H16: Reason for Variance | I16: Cumulative Budget | J16: Cumulative Expenditure | K16: Variance | L16: Reason for Variance | P16: 1. Total PR cash outflow vs. budget | R16: =R17+R18 -> 2500000 | S16: =S17+S18 -> 2235000 | T16: =IF(R16="",IF(S16="","",R16-S16),R16-S16) -> 265000 | W16: =W17+W18 -> 5600000 | X16: =X17+X18 -> 4500000 | Y16: =IF(W16="",IF(X16="","",W16-X16),W16-X16) -> 1100000
A17: 1 | B17: Human Resources | G17: =IF((E17=0)*AND(F17=0)," ",E17-F17) | K17: =IF((I17=0)*AND(J17=0)," ",I17-J17) | P17: 1a. PR's total expenditures | R17: ='PR_Total PR Cash Outflow_3A'!C13 -> 1500000 | S17: ='PR_Total PR Cash Outflow_3A'!D13 -> 1435000 | T17: =IF(R17="",IF(S17="",0,R17-S17),R17-S17) -> 65000 | W17: ='PR_Total PR Cash Outflow_3A'!H13 -> 2600000 | X17: ='PR_Total PR Cash Outflow_3A'!I13 -> 2000000 | Y17: =IF(W17="",IF(X17="",0,W17-X17),W17-X17) -> 600000
A18: 2 | B18: Technical Assistance | G18: =IF((E18=0)*AND(F18=0)," ",E18-F18) | K18: =IF((I18=0)*AND(J18=0)," ",I18-J18) | P18: 1b. Disbursements to sub-recipients | R18: ='PR_Total PR Cash Outflow_3A'!C14 -> 1000000 | S18: ='PR_Total PR Cash Outflow_3A'!D14 -> 800000 | T18: =IF(R18="",IF(S18="",0,R18-S18),R18-S18) -> 200000 | W18: ='PR_Total PR Cash Outflow_3A'!H14 -> 3000000 | X18: ='PR_Total PR Cash Outflow_3A'!I14 -> 2500000 | Y18: =IF(W18="",IF(X18="",0,W18-X18),W18-X18) -> 500000
A19: 3 | B19: Training | G19: =IF((E19=0)*AND(F19=0)," ",E19-F19) | K19: =IF((I19=0)*AND(J19=0)," ",I19-J19)
A20: 4 | B20: Health Products and Health Equipment | G20: =IF((E20=0)*AND(F20=0)," ",E20-F20) | K20: =IF((I20=0)*AND(J20=0)," ",I20-J20) | R20: Budget for Reporting Period* | S20: Actual Cash Outflow for Reporting Period | T20: Variance | U20: Reason for Variance | W20: Cumulative Budget through period of Progress Update | X20: Cumulative Actual Cash Outflow through period of Progress Update | Y20: Variance | Z20: Reason for Variance
A21: 5 | B21: Medicines and Pharmaceutical Products | G21: =IF((E21=0)*AND(F21=0)," ",E21-F21) | K21: =IF((I21=0)*AND(J21=0)," ",I21-J21) | P21: 2. Total pharmaceutical & health product expenditures vs. budget | R21: =R22+R23 -> 1300000 | S21: =S22+S23 -> 1350000 | T21: =IF(R21="",IF(S21="","",R21-S21),R21-S21) -> -50000 | W21: =W22+W23 -> 2500000 | X21: =X22+X23 -> 1950000 | Y21: =IF(W21="",IF(X21="","",W21-X21),W21-X21) -> 550000
A22: 6 | B22: Procurement and Supply Management Costs | G22: =IF((E22=0)*AND(F22=0)," ",E22-F22) | K22: =IF((I22=0)*AND(J22=0)," ",I22-J22) | P22: 2a. Medicines and pharmaceutical products | R22: ='PR_Total PR Cash Outflow_3A'!C18 -> 600000 | S22: ='PR_Total PR Cash Outflow_3A'!D18 -> 550000 | T22: =IF(R22="",IF(S22="",0,R22-S22),R22-S22) -> 50000 | W22: ='PR_Total PR Cash Outflow_3A'!H18 -> 1000000 | X22: ='PR_Total PR Cash Outflow_3A'!I18 -> 850000 | Y22: =IF(W22="",IF(X22="",0,W22-X22),W22-X22) -> 150000
A23: 7 | B23: Infrastructure and Other Equipment | G23: =IF((E23=0)*AND(F23=0)," ",E23-F23) | K23: =IF((I23=0)*AND(J23=0)," ",I23-J23) | P23: 2b. Health products and health equipment | R23: ='PR_Total PR Cash Outflow_3A'!C19 -> 700000 | S23: ='PR_Total PR Cash Outflow_3A'!D19 -> 800000 | T23: =IF(R23="",IF(S23="",0,R23-S23),R23-S23) -> -100000 | W23: ='PR_Total PR Cash Outflow_3A'!H19 -> 1500000 | X23: ='PR_Total PR Cash Outflow_3A'!I19 -> 1100000 | Y23: =IF(W23="",IF(X23="",0,W23-X23),W23-X23) -> 400000
A24: 8 | B24: Communication Materials | G24: =IF((E24=0)*AND(F24=0)," ",E24-F24) | K24: =IF((I24=0)*AND(J24=0)," ",I24-J24)
A25: 9 | B25: Monitoring & Evaluation | G25: =IF((E25=0)*AND(F25=0)," ",E25-F25) | K25: =IF((I25=0)*AND(J25=0)," ",I25-J25)
A26: 10 | B26: Living Support to Clients/Target Populations | G26: =IF((E26=0)*AND(F26=0)," ",E26-F26) | K26: =IF((I26=0)*AND(J26=0)," ",I26-J26)
A27: 11 | B27: Planning and Administration | G27: =IF((E27=0)*AND(F27=0)," ",E27-F27) | K27: =IF((I27=0)*AND(J27=0)," ",I27-J27)
A28: 12 | B28: Overheads | G28: =IF((E28=0)*AND(F28=0)," ",E28-F28) | K28: =IF((I28=0)*AND(J28=0)," ",I28-J28)
A29: 13 | B29: Other | G29: =IF((E29=0)*AND(F29=0)," ",E29-F29) | K29: =IF((I29=0)*AND(J29=0)," ",I29-J29)
D30: TOTAL | E30: =SUM(E17:E29) -> 0 | F30: =SUM(F17:F29) -> 0 | G30: =SUM(G17:G29) -> 0 | I30: =SUM(I17:I29) -> 0 | J30: =SUM(J17:J29) -> 0 | K30: =SUM(K17:K29) -> 0
A33: B- BREAKDOWN* BY PROGRAM ACTIVITY | E33: Current Reporting Period | I33: Cumulative Reporting Period
A34: # | B34: Macro-category | C34: Objectives | D34: Service Delivery Area | E34: Budget | F34: Expenditures | G34: Variance | H34: Reason for Variance | I34: Cumulative Budget | J34: Cumulative Expenditure | K34: Variance | L34: Reason for Variance
B35: Please Select… | D35: Please Select… | G35: =IF((E35=0)*AND(F35=0)," ",E35-F35) | K35: =IF((I35=0)*AND(J35=0)," ",I35-J35)
B36: Please Select… | D36: Please Select… | G36: =IF((E36=0)*AND(F36=0)," ",E36-F36) | K36: =IF((I36=0)*AND(J36=0)," ",I36-J36)
B37: Please Select… | D37: Please Select… | G37: =IF((E37=0)*AND(F37=0)," ",E37-F37) | K37: =IF((I37=0)*AND(J37=0)," ",I37-J37)
B38: Please Select… | D38: Please Select… | G38: =IF((E38=0)*AND(F38=0)," ",E38-F38) | K38: =IF((I38=0)*AND(J38=0)," ",I38-J38)
B39: Please Select… | D39: Please Select… | G39: =IF((E39=0)*AND(F39=0)," ",E39-F39) | K39: =IF((I39=0)*AND(J39=0)," ",I39-J39)
A40: TOTAL | E40: =SUM(E35:E39) -> 0 | F40: =SUM(F35:F39) -> 0 | G40: =SUM(G35:G39) -> 0 | I40: =SUM(I35:I39) -> 0 | J40: =SUM(J35:J39) -> 0 | K40: =SUM(K35:K39) -> 0
A41: To add additional rows, right click the row number (Row 39 in a blank template) to the left of the row above the row for TOTAL and select copy, then over the same number, right click again and select Insert Copied Cells. WARNING: Inserting Rows without copying a row as described above will cause the formula in the variance column to become invalid and will mean the overall information will be inaccurate.
A45: C- BREAKDOWN* BY IMPLEMENTING ENTITY | E45: Current Reporting Period | I45: Cumulative Reporting Period
A46: # | B46: PR/SR | C46: Name | D46: Type of Implementing Entity | E46: Budget | F46: Expenditures | G46: Variance | H46: Reason for Variance | I46: Cumulative Budget | J46: Cumulative Expenditure | K46: Variance | L46: Reason for Variance
B47: Please Select … | D47: Please Select… | G47: =IF((E47=0)*AND(F47=0)," ",E47-F47) | K47: =IF((I47=0)*AND(J47=0)," ",I47-J47)
B48: Please Select … | D48: Please Select… | G48: =IF((E48=0)*AND(F48=0)," ",E48-F48) | K48: =IF((I48=0)*AND(J48=0)," ",I48-J48)
B49: Please Select … | D49: Please Select… | G49: =IF((E49=0)*AND(F49=0)," ",E49-F49) | K49: =IF((I49=0)*AND(J49=0)," ",I49-J49)
...

Sheet PR_Procurement Info_4
A1: On-going Progress Update and Disbursement Request
A2: PROGRESS UPDATE PERIOD
A3: Grant number: | D3: =IF('PR_Programmatic Progress_1A'!C7="","",'PR_Programmatic Progress_1A'!C7) -> MNR-809-G04-H
A4: Progress Update - Reporting Period: | D4: Cycle: | E4: =IF('PR_Programmatic Progress_1A'!D12="Select","",'PR_Programmatic Progress_1A'!D12) -> Quarter | F4: Number: | G4: =IF('PR_Programmatic Progress_1A'!F12="Select","",'PR_Programmatic Progress_1A'!F12) -> 7
A5: Progress Update - Period Covered: | D5: Beginning Date: | E5: =IF('PR_Programmatic Progress_1A'!D13="","",'PR_Programmatic Progress_1A'!D13) -> 40452 | F5: End Date: | G5: =IF('PR_Programmatic Progress_1A'!F13="","",'PR_Programmatic Progress_1A'!F13) -> 40543
A6: Progress Update - Number: | D6: =IF('PR_Programmatic Progress_1A'!C14="Select","",'PR_Programmatic Progress_1A'!C14) -> 5
A8: Section 4: Procurement and Supply Management
G9: Comments
A10: 1a. Have you updated the Price Quality Reporting (PQR) with the required information on the pharmaceuticals and health products received during the period covered by this PU/DR’ (if applicable)? If health products procurement information has not been entered into the PQR, please explain why. ! For further guidance on PQR data entry, please refer to the guidelines. | F10: Yes | G10: The required information was updated for ARVs, rapid tests and condoms in the PQR (for cases when we did not have the final invoices, we updated the PQR based on pro-forma invoices).
A11: 2. Based on the most up-to-date stock situation, are there any risks of stockouts of key pharmaceuticals & health products at the central level in the next period of implementation? If yes, please comment. | F11: No | G11: Based on available information, there are sufficient stocks of drugs at central level. There were issues with drugs stocks in two regional centers but the PR worked closely with the central warehouse, the chief medical facility and the distribution company and ensured that the stocks at the regional level were replenished as soon as possible.
A13: 3. Comment on additional issues related to the procurement and supply management of pharmaceuticals and health products

Sheet PR Cash Rec Answer
A1: On-going Progress Update and Disbursement Request
A2: DISBURSEMENT REQUEST PERIOD
A3: Grant number: | D3: =IF('[5]PR_Programmatic Progress_1A'!C7="","",'[5]PR_Programmatic Progress_1A'!C7) -> MNR-809-G04-H | H3: ! A Statement of Sources and Uses of Funds (SSUF) is to be provided by PR along with the PUDR form
A4: Progress Update - Reporting Period: | D4: Cycle: | E4: =IF('[5]PR_Programmatic Progress_1A'!D12="Select","",'[5]PR_Programmatic Progress_1A'!D12) -> Quarter | F4: Number: | G4: =IF('[5]PR_Programmatic Progress_1A'!F12="Select","",'[5]PR_Programmatic Progress_1A'!F12) -> 7
A5: Progress Update - Period Covered: | D5: Beginning Date: | E5: =IF('[5]PR_Programmatic Progress_1A'!D13="","",'[5]PR_Programmatic Progress_1A'!D13) -> 40452 | F5: End Date: | G5: =IF('[5]PR_Programmatic Progress_1A'!F13="","",'[5]PR_Programmatic Progress_1A'!F13) -> 40543
A6: Progress Update - Number: | D6: =IF('[5]PR_Programmatic Progress_1A'!C14="Select","",'[5]PR_Programmatic Progress_1A'!C14) -> 5
A7: Currency: | D7: =IF('[5]PR_Programmatic Progress_1A'!C10="Select","",'[5]PR_Programmatic Progress_1A'!C10) -> EUR
A9: Section 5: Cash Reconciliation and Disbursement Request
A10: A: CASH RECONCILIATION FOR PERIOD COVERED BY PROGRESS UPDATE
A12: 1. Cash Balance: Beginning of period covered by Progress Update (line 10 from Cash Reconciliation section of the period covered by the previous Progress Update):
M13: 1700000 | O13: End balance from previous report
A15: Add: | B15: 2. Cash received by the PR from the Global Fund during the period covered by this progress update: | K15: 1000000
B16: 3. Cash disbursed to third parties by the Global Fund on behalf of the PR during the period covered by this progress update: | K16: 250000 | O16: GF pmt to third party on behalf of PR
B17: 4. Interest received on bank account | K17: 20000 | O17: Interest income in correct line
B18: 5. Revenue from income-generating activities (if applicable) | K18: 0
B19: 6. Other income, if applicable (e.g. income from disposal of fixed assets, tax refunds) | M19: =+K15+K16+K17+K18+K19 -> 1270000
A22: Less: | B22: 7. Total cash outflow during period covered by Progress Update (value entered in Section 3A "Total cash outflow"): | K22: =IF('[5]PR_Total PR Cash Outflow_3A'!D12="","",'[5]PR_Total PR Cash Outflow_3A'!D12) -> 2860000
B23: 8. Net exchange rate gains/losses (gains should be shown with a minus sign; losses should be shown with a plus sign)
B24: 9. Reconciliation adjustments (gains should be shown with a minus sign; losses should be shown with a plus sign) | K24: -100000 | M24: =+K22+K23+K24 -> 2760000 | O24: One-off reconciliation for under-reporting in previous reporting period
A26: 10. Cash Balance: End of period covered by Progress Update: | M26: =M13+M19-M24 -> 210000
A28: Explanation of reconciliation adjustments (line 9)
A29: ! An explanation must be provided if there have been any adjustments.
A30: Note re: Adjustment in Line 6: In Year 1 the PR opened a bank account dedicated to VAT re-funds per the requirement of the Ministry of Finance. At the very end of Year 1 i.e. prior to the reporting period of Q5, the first tranche of tax re-funds in the amount of $100,000 was made by the Ministry of Finance to the dedicated tax refund account. This amount is reflected in line 9 above. This is a one-time reconciliation adjustment and in the future tax refunds will be reflected on a periodic basis as part of reporting on other income under Line 6.

Sheet PR_Cash Reconciliation_Answer
A1: On-going Progress Update and Disbursement Request
A2: DISBURSEMENT REQUEST PERIOD
A3: Grant number: | D3: =IF('[5]PR_Programmatic Progress_1A'!C7="","",'[5]PR_Programmatic Progress_1A'!C7) -> MNR-809-G04-H | H3: ! A Statement of Sources and Uses of Funds (SSUF) is to be provided by PR along with the PUDR form
A4: Progress Update - Reporting Period: | D4: Cycle: | E4: =IF('[5]PR_Programmatic Progress_1A'!D12="Select","",'[5]PR_Programmatic Progress_1A'!D12) -> Quarter | F4: Number: | G4: =IF('[5]PR_Programmatic Progress_1A'!F12="Select","",'[5]PR_Programmatic Progress_1A'!F12) -> 7
A5: Progress Update - Period Covered: | D5: Beginning Date: | E5: =IF('[5]PR_Programmatic Progress_1A'!D13="","",'[5]PR_Programmatic Progress_1A'!D13) -> 40452 | F5: End Date: | G5: =IF('[5]PR_Programmatic Progress_1A'!F13="","",'[5]PR_Programmatic Progress_1A'!F13) -> 40543
A6: Progress Update - Number: | D6: =IF('[5]PR_Programmatic Progress_1A'!C14="Select","",'[5]PR_Programmatic Progress_1A'!C14) -> 5
A7: Currency: | D7: =IF('[5]PR_Programmatic Progress_1A'!C10="Select","",'[5]PR_Programmatic Progress_1A'!C10) -> EUR
A9: Section 5: Cash Reconciliation and Disbursement Request
A10: A: CASH RECONCILIATION FOR PERIOD COVERED BY PROGRESS UPDATE
A12: 1. Cash Balance: Beginning of period covered by Progress Update (line 10 from Cash Reconciliation section of the period covered by the previous Progress Update):
M13: 1700000 | O13: End balance from previous report
A15: Add: | B15: 2. Cash received by the PR from the Global Fund during the period covered by this progress update: | K15: 1000000
B16: 3. Cash disbursed to third parties by the Global Fund on behalf of the PR during the period covered by this progress update: | K16: 250000 | O16: GF pmt to third party on behalf of PR
B17: 4. Interest received on bank account | K17: 20000 | O17: Interest income in correct line
B18: 5. Revenue from income-generating activities (if applicable) | K18: 0
B19: 6. Other income, if applicable (e.g. income from disposal of fixed assets, tax refunds) | M19: =+K15+K16+K17+K18+K19 -> 1270000
A22: Less: | B22: 7. Total cash outflow during period covered by Progress Update (value entered in Section 3A "Total cash outflow"): | K22: ='PR_Total PR Cash Outflow_3A'!D12 -> 2235000
B23: 8. Net exchange rate gains/losses (gains should be shown with a minus sign; losses should be shown with a plus sign)
B24: 9. Reconciliation adjustments (gains should be shown with a minus sign; losses should be shown with a plus sign) | K24: -100000 | M24: =+K22+K23+K24 -> 2135000 | O24: One-off reconciliation for under-reporting in previous reporting period
A26: 10. Cash Balance: End of period covered by Progress Update: | M26: =M13+M19-M24 -> 835000
A28: Explanation of reconciliation adjustments (line 9)
A29: ! An explanation must be provided if there have been any adjustments.
A30: Note re: Adjustment in Line 6: In Year 1 the PR opened a bank account dedicated to VAT re-funds per the requirement of the Ministry of Finance. At the very end of Year 1 i.e. prior to the reporting period of Q5, the first tranche of tax re-funds in the amount of $100,000 was made by the Ministry of Finance to the dedicated tax refund account. This amount is reflected in line 9 above. This is a one-time reconciliation adjustment and in the future tax refunds will be reflected on a periodic basis as part of reporting on other income under Line 6.

Sheet PR_Cash Reconciliation_5A
A1: On-going Progress Update and Disbursement Request
A2: DISBURSEMENT REQUEST PERIOD
A3: Grant number: | D3: =IF('PR_Programmatic Progress_1A'!C7="","",'PR_Programmatic Progress_1A'!C7) -> MNR-809-G04-H | H3: ! A Statement of Sources and Uses of Funds (SSUF) is to be provided by PR along with the PUDR form
A4: Progress Update - Reporting Period: | D4: Cycle: | E4: =IF('PR_Programmatic Progress_1A'!D12="Select","",'PR_Programmatic Progress_1A'!D12) -> Quarter | F4: Number: | G4: =IF('PR_Programmatic Progress_1A'!F12="Select","",'PR_Programmatic Progress_1A'!F12) -> 7
A5: Progress Update - Period Covered: | D5: Beginning Date: | E5: =IF('PR_Programmatic Progress_1A'!D13="","",'PR_Programmatic Progress_1A'!D13) -> 40452 | F5: End Date: | G5: =IF('PR_Programmatic Progress_1A'!F13="","",'PR_Programmatic Progress_1A'!F13) -> 40543
A6: Progress Update - Number: | D6: =IF('PR_Programmatic Progress_1A'!C14="Select","",'PR_Programmatic Progress_1A'!C14) -> 5
A7: Currency: | D7: =IF('PR_Programmatic Progress_1A'!C10="Select","",'PR_Programmatic Progress_1A'!C10) -> EUR
A9: Section 5: Cash Reconciliation and Disbursement Request
A10: A: CASH RECONCILIATION FOR PERIOD COVERED BY PROGRESS UPDATE
A12: 1. Cash Balance: Beginning of period covered by Progress Update (line 10 from Cash Reconciliation section of the period covered by the previous Progress Update):
M13: 1700000
A15: Add: | B15: 2. Cash received by the PR from the Global Fund during the period covered by this progress update: | K15: 1000000
B16: 3. Cash disbursed to third parties by the Global Fund on behalf of the PR during the period covered by this progress update: | K16: 250000
B17: 4. Interest received on bank account | K17: 20000
B18: 5. Revenue from income-generating activities (if applicable)
B19: 6. Other income, if applicable (e.g. income from disposal of fixed assets, tax refunds) | M19: =+K15+K16+K17+K18+K19 -> 1270000
A22: Less: | B22: 7. Total cash outflow during period covered by Progress Update (value entered in Section 3A "Total cash outflow"): | K22: =IF('PR_Total PR Cash Outflow_3A'!D12="","",'PR_Total PR Cash Outflow_3A'!D12) -> 2235000
B23: 8. Net exchange rate gains/losses (gains should be shown with a minus sign; losses should be shown with a plus sign) | K23: -100000
B24: 9. Reconciliation adjustments (gains should be shown with a minus sign; losses should be shown with a plus sign) | M24: =+K22+K23+K24 -> 2135000
A26: 10. Cash Balance: End of period covered by Progress Update: | M26: =M13+M19-M24 -> 835000
A28: Explanation of reconciliation adjustments (line 9)
A29: ! An explanation must be provided if there have been any adjustments.
A30: An adjustment of EUR 100,000 in the beginning cash balance was made - VAT refund account was not considered in the financial reporting to date.

Sheet Cash Forecast Detail Top Down
G1: Disbursement Forecast
A2: Amount as originally budgeted: | B2: 500000 | C2: forecasted amount: | E2: 1600000 | F2: Q6
A4: Amount as originally budgeted: | B4: 600000 | C4: forecasted amount: | E4: 600000 | F4: Q7 | G4: =SUM(E2:E4) -> 2200000 | I4: Forecasted expenditures/cash needs in the PU/DR
A6: FORECAST REVIEW
A8: LESS
A9: as of last reporting period | B9: Savings from late staff recruitment | G9: -100000 | I9: See Section 3A
A10: as of last reporting period | B10: Technical assistance for labs - to be funded by another donor | G10: -50000 | I10: See Section 3A
A11: Q5 | B11: Unused SR cash balance not offset by commitments/due payments | E11: Less | G11: -80000 | I11: See Section 4C from Background information
A12: Q7 | B12: Advance pmt for test systems | E12: Less | G12: -100000 | I12: See Section 4C from Background information
E14: TOTAL | F14: (a) | G14: =SUM(G9:G12) -> -330000 | I14: Subtotal of cash declared as "needed" but unjustified
B16: Adjusted Forecasted Cash Needs | F16: (b) | G16: =G4+G14 -> 1870000 | I16: Adjusted Forecast
B18: Cash Balance: End of period covered by Progress Update: | F18: (c ) | G18: ='PR_Cash Reconciliation_Answer'!M26 -> 835000 | I18: Available Funds
F20: (b-c) | G20: =G16-G18 -> 1035000 | I20: Disbursement Amount

Sheet PR_Disbursement Request_5B
A1: On-going Progress Update and Disbursement Request
A2: DISBURSEMENT REQUEST PERIOD
A3: Grant number: | F3: =IF('PR_Programmatic Progress_1A'!C7="","",'PR_Programmatic Progress_1A'!C7) -> MNR-809-G04-H
A4: Progress Update - Reporting Period: | F4: Cycle: | G4: =IF('PR_Programmatic Progress_1A'!D12="Select","",'PR_Programmatic Progress_1A'!D12) -> Quarter | H4: Number: | I4: =IF('PR_Programmatic Progress_1A'!F12="Select","",'PR_Programmatic Progress_1A'!F12) -> 7
A5: Progress Update - Period Covered: | F5: Beginning Date: | G5: =IF('PR_Programmatic Progress_1A'!D13="","",'PR_Programmatic Progress_1A'!D13) -> 40452 | H5: End Date: | I5: =IF('PR_Programmatic Progress_1A'!F13="","",'PR_Programmatic Progress_1A'!F13) -> 40543
A6: Progress Update - Number: | F6: =IF('PR_Programmatic Progress_1A'!C14="Select","",'PR_Programmatic Progress_1A'!C14) -> 5
A7: Currency: | D7: =IF('PR_Programmatic Progress_1A'!C10="Select","",'PR_Programmatic Progress_1A'!C10) -> EUR
A9: Section 5: Cash Reconciliation and Disbursement Request
A11: B: DISBURSEMENT REQUEST
A14: Total forecasted net cash expenditures by the Principal Recipient for the period immediately following the period covered
A15: by the Progress Update:
A16: 1. Period beginning date: | E16: =IF('PR_Programmatic Progress_1A'!D17="","",'PR_Programmatic Progress_1A'!D17) -> 40544 | G16: end date: | H16: =IF('PR_Programmatic Progress_1A'!F17="","",'PR_Programmatic Progress_1A'!F17) -> 40633 | J16: approved budget amount: | K16: 500000 | L16: forecasted amount: | N16: =K16+'PR_Total PR Cash Outflow_3A'!J12-100000-50000-80000 -> 1370000
A17: 2a. Cash buffer period (by default)
A18: (cash "buffer") beginning date: | E18: =IF(H16="","",H16+1) -> 40634 | G18: end date: | H18: =IF(E18="","",DATE(YEAR(E18),MONTH(E18)+3,DAY(E18)-1)) -> 40724 | J18: approved budget amount: | K18: 600000 | L18: forecasted amount: | N18: =K18-100000 -> 500000
S19: PR Total Forecast
A20: 2b. Additional "buffer" (discretionary, select only if there is a prior agreement with the FPM) (1) | S20: =N16+N18+N22 -> 1870000
A21: cash "buffer" agreed with FPM (2) | C21: Select
A22: (cash "buffer") beginning date | E22: =IF(H18="","",H18+1) -> 40725 | G22: end date: | H22: =IF(C21="","",IF(C21="1M",DATE(YEAR(E22),MONTH(E22)+1,DAY(E22)-1),IF(C21="2M",DATE(YEAR(E22),MONTH(E22)+2,DAY(E22)-1),IF(C21="3M",DATE(YEAR(E22),MONTH(E22)+3,DAY(E22)-1),"")))) | J22: approved budget amount: | L22: forecasted amount: | N22: 0
A24: (1) Additional Cash buffer can be requested if the next PU/DR report will contain a completed EFR report or a completed Annex on SR financials, requested by the Secretariat, or if there are any additional GF-specific requirements that cannot be delivered within 45 days. An agreement in principal from the FPM should be obtained prior to requesting an additional cash buffer.
A25: (2) When the additional (cash "buffer" ) period is 1 or 2 months, the approved budget and forecasted amounts should be calculated as prorated values for the period following the regular buffer period.
A27: Please explain any significant variance (based on your judgment) between the forecasted amounts and the amounts as per approved budgets. Please specify the main factors and related amounts that are the major drivers of the variance. NB. Consider the following items when providing the analysis. - Expected timing of payments for any significant budgetary items, - Impact of existing cash balance at SR levels - Current confirmed commitments to be paid during disbursement request period - Current/expected unit prices compared to those in the budget - Change in quantities compared to budget - Exchange rates and inflation - Linkage between budget absorption and programmatic performance to-date. ! The forecast should include any existing commitments (eligible under this grant) as of the end of the reporting period and which are likely to be paid during the disbursement period | I27: Please see the attached spreadsheet named "Cash Forecast Detail Top Down" . The forecast for the next reporting period is based on the Q6 budget adjusted down for the following: Less $100,000 for savings from late staff recruitment (see Section 3A) Less $50,000 – TA for labs to be funded by another donor (see Section 3A) Less $80,000 – Unused SR cash balance not offset by commitments The budget for the buffer quarter is adjusted down for the following: Less $100,00 – advance payment for test systems
A31: Less: | B31: 3. Cash Balance: End of period covered by Progress Update (number 10 from PR Cash Reconciliation sheet): | N31: =+'PR_Cash Reconciliation_5A'!M26 -> 835000
B33: 4. Cash "in transit" disbursed to the PR: | N33: 0
B34: 5. Cash "in transit" disbursed to third parties by the Global Fund on behalf of the PR | N34: 0 | S34: =+N31+N33+N34 -> 835000
A36: 6. PR's Disbursement Request to the Global Fund for the period immediately following the period covered by the Progress Update, plus additional period (cash buffer): | S36: =IF(S20=0,0,IF(S20-S34<0,0,S20-S34)) -> 1035000
A38: 7. Does the PR's Disbursement Request include funds for health product procurement? | I38: Yes
A40: 8. Exchange Rate (used to translate local currency into grant currency) | I40: Name of local currency, date and source of the exchange rate, and other comments (if appropriate)
B41: - used to convert Opening Cash Balance | G41: 46 | I41: Amizian Kilasi
B43: - used to convert Closing Cash Balance | G43: 46 | I43: Amizian Kilasi
B45: - used to convert Total Cash Outflow for the Progress Update Period

Sheet PR_Overall Performance_6
A1: On-going Progress Update and Disbursement Request
A2: PROGRESS UPDATE PERIOD
A3: Grant number: | C3: =IF('LFA_Programmatic Progress_1A'!C7="","",'LFA_Programmatic Progress_1A'!C7) -> MNR-809-G04-H
A4: Progress Update - Reporting Period: | C4: Cycle: | D4: =IF('LFA_Programmatic Progress_1A'!D12="Select","",'LFA_Programmatic Progress_1A'!D12) -> Quarter | E4: Number: | F4: =IF('LFA_Programmatic Progress_1A'!F12="Select","",'LFA_Programmatic Progress_1A'!F12) -> 7
A5: Progress Update - Period Covered: | C5: Beginning Date: | D5: =IF('LFA_Programmatic Progress_1A'!D13="","",'LFA_Programmatic Progress_1A'!D13) -> 40452 | E5: End Date: | F5: =IF('LFA_Programmatic Progress_1A'!F13="","",'LFA_Programmatic Progress_1A'!F13) -> 40543
A6: Progress Update - Number: | C6: =IF('LFA_Programmatic Progress_1A'!C14="Select","",'LFA_Programmatic Progress_1A'!C14) -> 5
A8: Section 6: Overall Performance
A10: A. PR's Overall Self-Evaluation of Grant Performance (including a summary of how financial performance is linked to programmatic achievements)
A11: ! The self-evaluation should be undertaken by taking into account programmatic achievements, financial performance and program issues in various functional areas (M&E, Finance, Procurement, and Program Management, including management of sub-recipients). See Guidelines for more detailed guidance.
A18: B. Planned Changes in the Program, if any
A25: C. External factors beyond the control of the Principal Recipient that have impacted or may impact the Program

Sheet PR_Cash Request_7A&B
A1: On-going Progress Update and Disbursement Request
A2: GENERAL GRANT INFORMATION
A3: Country: | C3: =IF('PR_Programmatic Progress_1A'!C5:F5="","",'PR_Programmatic Progress_1A'!C5:F5) -> Monrovia
A4: Disease: | C4: =IF('PR_Programmatic Progress_1A'!C6:F6="Select","",'PR_Programmatic Progress_1A'!C6:F6) -> HIV/AIDS
A5: Grant number: | C5: =IF('PR_Programmatic Progress_1A'!C7:F7="","",'PR_Programmatic Progress_1A'!C7:F7) -> MNR-809-G04-H
A6: Principal Recipient: | C6: =IF('PR_Programmatic Progress_1A'!C8:F8="","",'PR_Programmatic Progress_1A'!C8:F8) -> Ministry of Health
A7: Program Start Date: | C7: =IF('PR_Programmatic Progress_1A'!C9:F9="","",'PR_Programmatic Progress_1A'!C9:F9) -> 40087
A8: Currency: | C8: =IF('PR_Programmatic Progress_1A'!C10="Select","",'PR_Programmatic Progress_1A'!C10) -> EUR
A9: PROGRESS UPDATE PERIOD
A10: Progress Update - Reporting Period: | C10: Cycle: | D10: =IF('PR_Programmatic Progress_1A'!D12="Select","",'PR_Programmatic Progress_1A'!D12) -> Quarter | E10: Number: | F10: =IF('PR_Programmatic Progress_1A'!F12="Select","",'PR_Programmatic Progress_1A'!F12) -> 7
A11: Progress Update - Period Covered: | C11: Beginning Date: | D11: =IF('PR_Programmatic Progress_1A'!D13="","",'PR_Programmatic Progress_1A'!D13) -> 40452 | E11: End Date: | F11: =IF('PR_Programmatic Progress_1A'!F13="","",'PR_Programmatic Progress_1A'!F13) -> 40543
