Workbook

Sheet Menu
D8: V 2.1
L11: Company | N11: Example company
L12: Branche
L13: Contactperson
L14: Phone
L15: E-mail
L17: Name of the model | N17: Current Business Model
L18: Date | N18: 40908

Sheet Data Entry
A2: Evaluation Business Model | D2: Company: | E2: =Menu!N11 -> Example company | H2: Name model | J2: =Menu!N17 -> Current Business Model | M2: Date | N2: =Menu!N18 -> 40908
A3: Strenght/Weakness | F3: Opportunities | K3: Threats
A4: Nr. | B4: Subject | C4: Score | D4: Result | G4: Subject | H4: Score | I4: Result | L4: Subject | M4: Score | N4: Threat
A5: 1 | B5: =Categorie!A5 -> Our Value Propositions are well aligned with customer needs | C5: 3 | D5: =IF(C5<0,"Weakness","Strength") -> Strength | F5: 1 | G5: =Categorie!E5 -> Could we generate recurring revenues by converting products into services? | H5: 1 | I5: =IF(H5=5,"Extreme",IF(H5=4,"Very high",IF(H5=3,"High",IF(H5=2,"Present","Low")))) -> Low | K5: 1 | L5: =Categorie!I5 -> Are substitute products and services available? | M5: 5 | N5: =IF(M5=5,"Extreme",IF(M5=4,"Very high",IF(M5=3,"High",IF(M5=2,"Present","Low")))) -> Extreme
A6: 2 | B6: =Categorie!A6 -> Our Value Propositions have strong network effects | C6: -2 | D6: =IF(C6<0,"Weakness","Strength") -> Weakness | F6: 2 | G6: =Categorie!E6 -> Could we better integrate our products or services? | H6: 1 | I6: =IF(H6=5,"Extreme",IF(H6=4,"Very high",IF(H6=3,"High",IF(H6=2,"Present","Low")))) -> Low | K6: 2 | L6: =Categorie!I6 -> Are competitors threatening to offer better price or value? | M6: 1 | N6: =IF(M6=5,"Extreme",IF(M6=4,"Very high",IF(M6=3,"High",IF(M6=2,"Present","Low")))) -> Low
A7: 3 | B7: =Categorie!A7 -> There are strong synergies between our products and services | C7: 4 | D7: =IF(C7<0,"Weakness","Strength") -> Strength | F7: 3 | G7: =Categorie!E7 -> Which additional customer needs could we satisfy? | H7: 5 | I7: =IF(H7=5,"Extreme",IF(H7=4,"Very high",IF(H7=3,"High",IF(H7=2,"Present","Low")))) -> Extreme | K7: 3 | L7: =Categorie!I13 -> Are our margins threatened by competitors? By technology? | M7: 1 | N7: =IF(M7=5,"Extreme",IF(M7=4,"Very high",IF(M7=3,"High",IF(M7=2,"Present","Low")))) -> Low
A8: 4 | B8: =Categorie!A8 -> Our customers are very satisfied | C8: 2 | D8: =IF(C8<0,"Weakness","Strength") -> Strength | F8: 4 | G8: =Categorie!E8 -> What complements to or extensions of our Value Proposition are possible? | H8: 4 | I8: =IF(H8=5,"Extreme",IF(H8=4,"Very high",IF(H8=3,"High",IF(H8=2,"Present","Low")))) -> Very high | K8: 4 | L8: =Categorie!I14 -> Do we depend excessively on one or more Revenue Streams? | M8: 1 | N8: =IF(M8=5,"Extreme",IF(M8=4,"Very high",IF(M8=3,"High",IF(M8=2,"Present","Low")))) -> Low
A9: 5 | B9: =Categorie!A13 -> We benefit from strong margins | C9: 3 | D9: =IF(C9<0,"Weakness","Strength") -> Strength | F9: 5 | G9: =Categorie!E9 -> What other jobs could we do on behalf of customers? | H9: 3 | I9: =IF(H9=5,"Extreme",IF(H9=4,"Very high",IF(H9=3,"High",IF(H9=2,"Present","Low")))) -> High | K9: 5 | L9: =Categorie!I15 -> Which Revenue Streams are likely to disappear in the future? | M9: 1 | N9: =IF(M9=5,"Extreme",IF(M9=4,"Very high",IF(M9=3,"High",IF(M9=2,"Present","Low")))) -> Low
A10: 6 | B10: =Categorie!A14 -> Our revenues are predictable | C10: -5 | D10: =IF(C10<0,"Weakness","Strength") -> Weakness | F10: 6 | G10: =Categorie!E13 -> Can we replace one-time transaction revenues with recurring revenues? | H10: 1 | I10: =IF(H10=5,"Extreme",IF(H10=4,"Very high",IF(H10=3,"High",IF(H10=2,"Present","Low")))) -> Low | K10: 6 | L10: =Categorie!I24 -> Which costs threaten to become unpredictable? | M10: 1 | N10: =IF(M10=5,"Extreme",IF(M10=4,"Very high",IF(M10=3,"High",IF(M10=2,"Present","Low")))) -> Low
A11: 7 | B11: =Categorie!A15 -> We have recurring Revenue Streams and frequent repeat purchases | C11: -5 | D11: =IF(C11<0,"Weakness","Strength") -> Weakness | F11: 7 | G11: =Categorie!E14 -> What other elements would customers be willing to pay for? | H11: 2 | I11: =IF(H11=5,"Extreme",IF(H11=4,"Very high",IF(H11=3,"High",IF(H11=2,"Present","Low")))) -> Present | K11: 7 | L11: =Categorie!I25 -> Which costs threaten to grow more quickly than the revenues they support? | M11: 1 | N11: =IF(M11=5,"Extreme",IF(M11=4,"Very high",IF(M11=3,"High",IF(M11=2,"Present","Low")))) -> Low
A12: 8 | B12: =Categorie!A16 -> Our Revenue Streams are diversified | C12: 5 | D12: =IF(C12<0,"Weakness","Strength") -> Strength | F12: 8 | G12: =Categorie!E15 -> Do we have cross-selling opportunities either internally or with partners? | H12: 1 | I12: =IF(H12=5,"Extreme",IF(H12=4,"Very high",IF(H12=3,"High",IF(H12=2,"Present","Low")))) -> Low | K12: 8 | L12: =Categorie!I31 -> Could we face a disruption in the supply of certain resources? | M12: 1 | N12: =IF(M12=5,"Extreme",IF(M12=4,"Very high",IF(M12=3,"High",IF(M12=2,"Present","Low")))) -> Low
A13: 9 | B13: =Categorie!A17 -> Our Revenue Streams are sustainable | C13: 3 | D13: =IF(C13<0,"Weakness","Strength") -> Strength | F13: 9 | G13: =Categorie!E16 -> What other Revenue Streams could we add or create? | H13: 2 | I13: =IF(H13=5,"Extreme",IF(H13=4,"Very high",IF(H13=3,"High",IF(H13=2,"Present","Low")))) -> Present | K13: 9 | L13: =Categorie!I32 -> Is the quality of our resources threatened in any way? | M13: 1 | N13: =IF(M13=5,"Extreme",IF(M13=4,"Very high",IF(M13=3,"High",IF(M13=2,"Present","Low")))) -> Low
A14: 10 | B14: =Categorie!A18 -> We collect revenues before we incur expenses | C14: -5 | D14: =IF(C14<0,"Weakness","Strength") -> Weakness | F14: 10 | G14: =Categorie!E17 -> Can we increase prices? | H14: 1 | I14: =IF(H14=5,"Extreme",IF(H14=4,"Very high",IF(H14=3,"High",IF(H14=2,"Present","Low")))) -> Low | K14: 10 | L14: =Categorie!I38 -> What Key Activities might be disrupted? | M14: 2 | N14: =IF(M14=5,"Extreme",IF(M14=4,"Very high",IF(M14=3,"High",IF(M14=2,"Present","Low")))) -> Present
A15: 11 | B15: =Categorie!A19 -> We charge for what customers are really willing to pay for | C15: 5 | D15: =IF(C15<0,"Weakness","Strength") -> Strength | F15: 11 | G15: =Categorie!E24 -> Where can we reduce costs? | H15: 1 | I15: =IF(H15=5,"Extreme",IF(H15=4,"Very high",IF(H15=3,"High",IF(H15=2,"Present","Low")))) -> Low | K15: 11 | L15: =Categorie!I39 -> Is the quality of our activities threatened in any way? | M15: 2 | N15: =IF(M15=5,"Extreme",IF(M15=4,"Very high",IF(M15=3,"High",IF(M15=2,"Present","Low")))) -> Present
A16: 12 | B16: =Categorie!A20 -> Our pricing mechanisms capture full willingness to pay | C16: 5 | D16: =IF(C16<0,"Weakness","Strength") -> Strength | F16: 12 | G16: =Categorie!E31 -> Could we use less costly resources to achieve the same result? | H16: 1 | I16: =IF(H16=5,"Extreme",IF(H16=4,"Very high",IF(H16=3,"High",IF(H16=2,"Present","Low")))) -> Low | K16: 12 | L16: =Categorie!I45 -> Are we in danger of losing any partners? | M16: 1 | N16: =IF(M16=5,"Extreme",IF(M16=4,"Very high",IF(M16=3,"High",IF(M16=2,"Present","Low")))) -> Low
A17: 13 | B17: =Categorie!A24 -> Our costs are predictable | C17: 5 | D17: =IF(C17<0,"Weakness","Strength") -> Strength | F17: 13 | G17: =Categorie!E32 -> Which Key Resources could be better sourced from partners? | H17: 1 | I17: =IF(H17=5,"Extreme",IF(H17=4,"Very high",IF(H17=3,"High",IF(H17=2,"Present","Low")))) -> Low | K17: 13 | L17: =Categorie!I46 -> Might our partners collaborate with competitors? | M17: 2 | N17: =IF(M17=5,"Extreme",IF(M17=4,"Very high",IF(M17=3,"High",IF(M17=2,"Present","Low")))) -> Present
A18: 14 | B18: =Categorie!A25 -> Our Cost Structure is correctly matched to our business model | C18: 5 | D18: =IF(C18<0,"Weakness","Strength") -> Strength | F18: 14 | G18: =Categorie!E33 -> Which Key Resources are under-exploited? | H18: 1 | I18: =IF(H18=5,"Extreme",IF(H18=4,"Very high",IF(H18=3,"High",IF(H18=2,"Present","Low")))) -> Low | K18: 14 | L18: =Categorie!I47 -> Are we too dependent on certain partners? | M18: 1 | N18: =IF(M18=5,"Extreme",IF(M18=4,"Very high",IF(M18=3,"High",IF(M18=2,"Present","Low")))) -> Low
A19: 15 | B19: =Categorie!A26 -> Our operations are cost-efficient | C19: 2 | D19: =IF(C19<0,"Weakness","Strength") -> Strength | F19: 15 | G19: =Categorie!E34 -> Do we have unused intellectual property of value to others? | H19: 1 | I19: =IF(H19=5,"Extreme",IF(H19=4,"Very high",IF(H19=3,"High",IF(H19=2,"Present","Low")))) -> Low | K19: 15 | L19: =Categorie!I53 -> Could our market be saturated soon? | M19: 1 | N19: =IF(M19=5,"Extreme",IF(M19=4,"Very high",IF(M19=3,"High",IF(M19=2,"Present","Low")))) -> Low
A20: 16 | B20: =Categorie!A27 -> We benefit from economies of scale | C20: -3 | D20: =IF(C20<0,"Weakness","Strength") -> Weakness | F20: 16 | G20: =Categorie!E38 -> Could we standardize some Key Activities? | H20: 3 | I20: =IF(H20=5,"Extreme",IF(H20=4,"Very high",IF(H20=3,"High",IF(H20=2,"Present","Low")))) -> High | K20: 16 | L20: =Categorie!I54 -> Are competitors threatening our market share? | M20: 1 | N20: =IF(M20=5,"Extreme",IF(M20=4,"Very high",IF(M20=3,"High",IF(M20=2,"Present","Low")))) -> Low
A21: 17 | B21: =Categorie!A31 -> Our Key Resources are difficult for competitors to replicate | C21: 5 | D21: =IF(C21<0,"Weakness","Strength") -> Strength | F21: 17 | G21: =Categorie!E39 -> How could we improve efficiency in general? | H21: 1 | I21: =IF(H21=5,"Extreme",IF(H21=4,"Very high",IF(H21=3,"High",IF(H21=2,"Present","Low")))) -> Low | K21: 17 | L21: =Categorie!I55 -> How likely are customers to defect? | M21: 4 | N21: =IF(M21=5,"Extreme",IF(M21=4,"Very high",IF(M21=3,"High",IF(M21=2,"Present","Low")))) -> Very high
A22: 18 | B22: =Categorie!A32 -> Resource needs are predictable | C22: 5 | D22: =IF(C22<0,"Weakness","Strength") -> Strength | F22: 18 | G22: =Categorie!E40 -> Would IT support boost efficiency? | H22: 2 | I22: =IF(H22=5,"Extreme",IF(H22=4,"Very high",IF(H22=3,"High",IF(H22=2,"Present","Low")))) -> Present | K22: 18 | L22: =Categorie!I56 -> How quickly will competition in our market intensify? | M22: 2 | N22: =IF(M22=5,"Extreme",IF(M22=4,"Very high",IF(M22=3,"High",IF(M22=2,"Present","Low")))) -> Present
A23: 19 | B23: =Categorie!A33 -> We deploy Key Resources in the right amount at the right time | C23: 5 | D23: =IF(C23<0,"Weakness","Strength") -> Strength | F23: 19 | G23: =Categorie!E45 -> Are there outsourcing opportunities? | H23: 1 | I23: =IF(H23=5,"Extreme",IF(H23=4,"Very high",IF(H23=3,"High",IF(H23=2,"Present","Low")))) -> Low | K23: 19 | L23: =Categorie!I60 -> Do competitors threaten our Channels? | M23: 1 | N23: =IF(M23=5,"Extreme",IF(M23=4,"Very high",IF(M23=3,"High",IF(M23=2,"Present","Low")))) -> Low
A24: 20 | B24: =Categorie!A38 -> We efficiently execute Key Activities | C24: 1 | D24: =IF(C24<0,"Weakness","Strength") -> Strength | F24: 20 | G24: =Categorie!E46 -> Could greater collaboration with partners help us focus on our core business? | H24: 1 | I24: =IF(H24=5,"Extreme",IF(H24=4,"Very high",IF(H24=3,"High",IF(H24=2,"Present","Low")))) -> Low | K24: 20 | L24: =Categorie!I61 -> Are our Channels in danger of becoming irrelevant to customers? | M24: 1 | N24: =IF(M24=5,"Extreme",IF(M24=4,"Very high",IF(M24=3,"High",IF(M24=2,"Present","Low")))) -> Low
A25: 21 | B25: =Categorie!A39 -> Our Key Activities are difficult to copy | C25: 3 | D25: =IF(C25<0,"Weakness","Strength") -> Strength | F25: 21 | G25: =Categorie!E47 -> Are there cross-selling opportunities with partners? | H25: 2 | I25: =IF(H25=5,"Extreme",IF(H25=4,"Very high",IF(H25=3,"High",IF(H25=2,"Present","Low")))) -> Present | K25: 21 | L25: =Categorie!I70 -> Are any of our Customer Relationships in danger of deteriorating? | M25: 2 | N25: =IF(M25=5,"Extreme",IF(M25=4,"Very high",IF(M25=3,"High",IF(M25=2,"Present","Low")))) -> Present
A26: 22 | B26: =Categorie!A40 -> Execution quality is high | C26: 4 | D26: =IF(C26<0,"Weakness","Strength") -> Strength | F26: 22 | G26: =Categorie!E48 -> Could partner Channels help us better reach customers? | H26: 3 | I26: =IF(H26=5,"Extreme",IF(H26=4,"Very high",IF(H26=3,"High",IF(H26=2,"Present","Low")))) -> High
A27: 23 | B27: =Categorie!A41 -> Balance of in-house versus outsourced execution is ideal | C27: 0 | D27: =IF(C27<0,"Weakness","Strength") -> Strength | F27: 23 | G27: =Categorie!E49 -> Could partners complement our Value Proposition? | H27: 2 | I27: =IF(H27=5,"Extreme",IF(H27=4,"Very high",IF(H27=3,"High",IF(H27=2,"Present","Low")))) -> Present
A28: 24 | B28: =Categorie!A45 -> We are focused and work with partners when necessary | C28: 1 | D28: =IF(C28<0,"Weakness","Strength") -> Strength | F28: 24 | G28: =Categorie!E53 -> How can we benefit from a growing market? | H28: 4 | I28: =IF(H28=5,"Extreme",IF(H28=4,"Very high",IF(H28=3,"High",IF(H28=2,"Present","Low")))) -> Very high
A29: 25 | B29: =Categorie!A46 -> We enjoy good working relationships with Key Partners | C29: 2 | D29: =IF(C29<0,"Weakness","Strength") -> Strength | F29: 25 | G29: =Categorie!E54 -> Could we serve new Customer Segments? | H29: 4 | I29: =IF(H29=5,"Extreme",IF(H29=4,"Very high",IF(H29=3,"High",IF(H29=2,"Present","Low")))) -> Very high
A30: 26 | B30: =Categorie!A53 -> Customer churn rates are low | C30: 4 | D30: =IF(C30<0,"Weakness","Strength") -> Strength | F30: 26 | G30: =Categorie!E55 -> Could we better serve our customers through finer segmentation? | H30: 2 | I30: =IF(H30=5,"Extreme",IF(H30=4,"Very high",IF(H30=3,"High",IF(H30=2,"Present","Low")))) -> Present
A31: 27 | B31: =Categorie!A54 -> Customer base is well segmented | C31: 4 | D31: =IF(C31<0,"Weakness","Strength") -> Strength | F31: 27 | G31: =Categorie!E60 -> How could we improve channel efficiency or effectiveness? | H31: 1 | I31: =IF(H31=5,"Extreme",IF(H31=4,"Very high",IF(H31=3,"High",IF(H31=2,"Present","Low")))) -> Low
A32: 28 | B32: =Categorie!A55 -> We are continuously acquiring new customers | C32: 1 | D32: =IF(C32<0,"Weakness","Strength") -> Strength | F32: 28 | G32: =Categorie!E61 -> Could we integrate our Channels better? | H32: 1 | I32: =IF(H32=5,"Extreme",IF(H32=4,"Very high",IF(H32=3,"High",IF(H32=2,"Present","Low")))) -> Low
A33: 29 | B33: =Categorie!A60 -> Our Channels are very efficient | C33: 0 | D33: =IF(C33<0,"Weakness","Strength") -> Strength | F33: 29 | G33: =Categorie!E62 -> Could we find new complementary partner Channels? | H33: 4 | I33: =IF(H33=5,"Extreme",IF(H33=4,"Very high",IF(H33=3,"High",IF(H33=2,"Present","Low")))) -> Very high
A34: 30 | B34: =Categorie!A61 -> Our Channels are very effective | C34: 4 | D34: =IF(C34<0,"Weakness","Strength") -> Strength | F34: 30 | G34: =Categorie!E63 -> Could we increase margins by directly serving customers? | H34: 1 | I34: =IF(H34=5,"Extreme",IF(H34=4,"Very high",IF(H34=3,"High",IF(H34=2,"Present","Low")))) -> Low
A35: 31 | B35: =Categorie!A62 -> Channel reach is strong among customers | C35: -5 | D35: =IF(C35<0,"Weakness","Strength") -> Weakness | F35: 31 | G35: =Categorie!E64 -> Could we better align Channels with Customer Segments? | H35: 1 | I35: =IF(H35=5,"Extreme",IF(H35=4,"Very high",IF(H35=3,"High",IF(H35=2,"Present","Low")))) -> Low
A36: 32 | B36: =Categorie!A63 -> Customers can easily see our Channels | C36: -5 | D36: =IF(C36<0,"Weakness","Strength") -> Weakness | F36: 32 | G36: =Categorie!E70 -> Is there potential to improve customer follow-up? | H36: 2 | I36: =IF(H36=5,"Extreme",IF(H36=4,"Very high",IF(H36=3,"High",IF(H36=2,"Present","Low")))) -> Present
A37: 33 | B37: =Categorie!A64 -> Channels are strongly integrated | C37: 0 | D37: =IF(C37<0,"Weakness","Strength") -> Strength | F37: 33 | G37: =Categorie!E71 -> How could we tighten our relationships with customers? | H37: 2 | I37: =IF(H37=5,"Extreme",IF(H37=4,"Very high",IF(H37=3,"High",IF(H37=2,"Present","Low")))) -> Present
A38: 34 | B38: =Categorie!A65 -> Channels provide economies of scope | C38: 0 | D38: =IF(C38<0,"Weakness","Strength") -> Strength | F38: 34 | G38: =Categorie!E72 -> Could we improve personalization? | H38: 2 | I38: =IF(H38=5,"Extreme",IF(H38=4,"Very high",IF(H38=3,"High",IF(H38=2,"Present","Low")))) -> Present
A39: 35 | B39: =Categorie!A66 -> Channels are well matched to Customer Segments | C39: 0 | D39: =IF(C39<0,"Weakness","Strength") -> Strength | F39: 35 | G39: =Categorie!E73 -> How could we increase switching costs? | H39: 1 | I39: =IF(H39=5,"Extreme",IF(H39=4,"Very high",IF(H39=3,"High",IF(H39=2,"Present","Low")))) -> Low
A40: 36 | B40: =Categorie!A70 -> Strong Customer Relationships | C40: 5 | D40: =IF(C40<0,"Weakness","Strength") -> Strength | F40: 36 | G40: =Categorie!E74 -> Have we identified and “fired” unprofitable customers? If not, why not? | H40: 1 | I40: =IF(H40=5,"Extreme",IF(H40=4,"Very high",IF(H40=3,"High",IF(H40=2,"Present","Low")))) -> Low
A41: 37 | B41: =Categorie!A71 -> Relationship quality correctly matches Customer Segments | C41: 4 | D41: =IF(C41<0,"Weakness","Strength") -> Strength | F41: 37 | G41: =Categorie!E75 -> Do we need to automate some relationships? | H41: 1 | I41: =IF(H41=5,"Extreme",IF(H41=4,"Very high",IF(H41=3,"High",IF(H41=2,"Present","Low")))) -> Low
...

Sheet Categorie
A1: Business Model Generation: Evaluating Business Models
A2: strength / weakness | E2: Opportunities | I2: Threats
A3: Subject | B3: Score | C3: Results | E3: Subject | F3: Score | G3: Opportunity | I3: Subject | J3: Score | K3: Threat
A4: Value Proposition | E4: =A4 -> Value Proposition | I4: =A4 -> Value Proposition | L4: =A4 -> Value Proposition
A5: Our Value Propositions are well aligned with customer needs | B5: =IF('Data Entry'!C5="","",'Data Entry'!C5) -> 3 | C5: =IF(B5<0,"Zwakte","Sterkte") -> Sterkte | E5: Could we generate recurring revenues by converting products into services? | F5: =IF('Data Entry'!H5="","",'Data Entry'!H5) -> 1 | G5: =IF(F5=5,"Extreem",IF(F5=4,"Zeer groot",IF(F5=3,"Groot",IF(F5=2,"Aanwezig","Matig")))) -> Matig | I5: Are substitute products and services available? | J5: =IF('Data Entry'!M5="","",'Data Entry'!M5) -> 5 | K5: =IF(J5=-5,"Extreem",IF(J5=-4,"Zeer groot",IF(J5=-3,"Groot",IF(J5=-2,"Aanwezig","Matig")))) -> Matig | L5: =A2 -> strength / weakness | N5: =B9 -> 1.75
A6: Our Value Propositions have strong network effects | B6: =IF('Data Entry'!C6="","",'Data Entry'!C6) -> -2 | C6: =IF(B6<0,"Zwakte","Sterkte") -> Zwakte | E6: Could we better integrate our products or services? | F6: =IF('Data Entry'!H6="","",'Data Entry'!H6) -> 1 | G6: =IF(F6=5,"Extreem",IF(F6=4,"Zeer groot",IF(F6=3,"Groot",IF(F6=2,"Aanwezig","Matig")))) -> Matig | I6: Are competitors threatening to offer better price or value? | J6: =IF('Data Entry'!M6="","",'Data Entry'!M6) -> 1 | K6: =IF(J6=-5,"Extreem",IF(J6=-4,"Zeer groot",IF(J6=-3,"Groot",IF(J6=-2,"Aanwezig","Matig")))) -> Matig | L6: Threat | N6: =J7 -> 3
A7: There are strong synergies between our products and services | B7: =IF('Data Entry'!C7="","",'Data Entry'!C7) -> 4 | C7: =IF(B7<0,"Zwakte","Sterkte") -> Sterkte | E7: Which additional customer needs could we satisfy? | F7: =IF('Data Entry'!H7="","",'Data Entry'!H7) -> 5 | G7: =IF(F7=5,"Extreem",IF(F7=4,"Zeer groot",IF(F7=3,"Groot",IF(F7=2,"Aanwezig","Matig")))) -> Extreem | I7: Total | J7: =IF(COUNTBLANK(J5:J6)=2,"",SUM(J5:J6)/2) -> 3 | K7: =IF(J7=-5,"Extreem",IF(J7=-4,"Zeer groot",IF(J7=-3,"Groot",IF(J7=-2,"Aanwezig","Matig")))) -> Matig | L7: Opportunity | N7: =F10 -> 2.8
A8: Our customers are very satisfied | B8: =IF('Data Entry'!C8="","",'Data Entry'!C8) -> 2 | C8: =IF(B8<0,"Zwakte","Sterkte") -> Sterkte | E8: What complements to or extensions of our Value Proposition are possible? | F8: =IF('Data Entry'!H8="","",'Data Entry'!H8) -> 4 | G8: =IF(F8=5,"Extreem",IF(F8=4,"Zeer groot",IF(F8=3,"Groot",IF(F8=2,"Aanwezig","Matig")))) -> Zeer groot
A9: Total | B9: =IF(COUNTBLANK(B5:B8)=4,"",SUM(B5:B8)/4) -> 1.75 | C9: =IF(B9<0,"Zwakte","Sterkte") -> Sterkte | E9: What other jobs could we do on behalf of customers? | F9: =IF('Data Entry'!H9="","",'Data Entry'!H9) -> 3 | G9: =IF(F9=5,"Extreem",IF(F9=4,"Zeer groot",IF(F9=3,"Groot",IF(F9=2,"Aanwezig","Matig")))) -> Groot
E10: Total | F10: =IF(COUNTBLANK(F5:F9)=5,"",SUM(F5:F9)/5) -> 2.8 | G10: =IF(F10=5,"Extreem",IF(F10=4,"Zeer groot",IF(F10=3,"Groot",IF(F10=2,"Aanwezig","Matig")))) -> Matig
A11: =IF(COUNTBLANK(B5:B8)=4,"",SUM(B5:B8)) -> 7
A12: Revenue streams | E12: =A12 -> Revenue streams | I12: =A12 -> Revenue streams
A13: We benefit from strong margins | B13: =IF('Data Entry'!C9="","",'Data Entry'!C9) -> 3 | C13: =IF(B13<0,"Zwakte","Sterkte") -> Sterkte | E13: Can we replace one-time transaction revenues with recurring revenues? | F13: =IF('Data Entry'!H10="","",'Data Entry'!H10) -> 1 | G13: =IF(F13=5,"Extreem",IF(F13=4,"Zeer groot",IF(F13=3,"Groot",IF(F13=2,"Aanwezig","Matig")))) -> Matig | I13: Are our margins threatened by competitors? By technology? | J13: =IF('Data Entry'!M7="","",'Data Entry'!M7) -> 1 | K13: =IF(J13=-5,"Extreem",IF(J13=-4,"Zeer groot",IF(J13=-3,"Groot",IF(J13=-2,"Aanwezig","Matig")))) -> Matig
A14: Our revenues are predictable | B14: =IF('Data Entry'!C10="","",'Data Entry'!C10) -> -5 | C14: =IF(B14<0,"Zwakte","Sterkte") -> Zwakte | E14: What other elements would customers be willing to pay for? | F14: =IF('Data Entry'!H11="","",'Data Entry'!H11) -> 2 | G14: =IF(F14=5,"Extreem",IF(F14=4,"Zeer groot",IF(F14=3,"Groot",IF(F14=2,"Aanwezig","Matig")))) -> Aanwezig | I14: Do we depend excessively on one or more Revenue Streams? | J14: =IF('Data Entry'!M8="","",'Data Entry'!M8) -> 1 | K14: =IF(J14=-5,"Extreem",IF(J14=-4,"Zeer groot",IF(J14=-3,"Groot",IF(J14=-2,"Aanwezig","Matig")))) -> Matig
A15: We have recurring Revenue Streams and frequent repeat purchases | B15: =IF('Data Entry'!C11="","",'Data Entry'!C11) -> -5 | C15: =IF(B15<0,"Zwakte","Sterkte") -> Zwakte | E15: Do we have cross-selling opportunities either internally or with partners? | F15: =IF('Data Entry'!H12="","",'Data Entry'!H12) -> 1 | G15: =IF(F15=5,"Extreem",IF(F15=4,"Zeer groot",IF(F15=3,"Groot",IF(F15=2,"Aanwezig","Matig")))) -> Matig | I15: Which Revenue Streams are likely to disappear in the future? | J15: =IF('Data Entry'!M9="","",'Data Entry'!M9) -> 1 | K15: =IF(J15=-5,"Extreem",IF(J15=-4,"Zeer groot",IF(J15=-3,"Groot",IF(J15=-2,"Aanwezig","Matig")))) -> Matig
A16: Our Revenue Streams are diversified | B16: =IF('Data Entry'!C12="","",'Data Entry'!C12) -> 5 | C16: =IF(B16<0,"Zwakte","Sterkte") -> Sterkte | E16: What other Revenue Streams could we add or create? | F16: =IF('Data Entry'!H13="","",'Data Entry'!H13) -> 2 | G16: =IF(F16=5,"Extreem",IF(F16=4,"Zeer groot",IF(F16=3,"Groot",IF(F16=2,"Aanwezig","Matig")))) -> Aanwezig | I16: Total | J16: =IF(COUNTBLANK(J13:J15)=3,"",SUM(J13:J15)/3) -> 1 | K16: =IF(J16=-5,"Extreem",IF(J16=-4,"Zeer groot",IF(J16=-3,"Groot",IF(J16=-2,"Aanwezig","Matig")))) -> Matig
A17: Our Revenue Streams are sustainable | B17: =IF('Data Entry'!C13="","",'Data Entry'!C13) -> 3 | C17: =IF(B17<0,"Zwakte","Sterkte") -> Sterkte | E17: Can we increase prices? | F17: =IF('Data Entry'!H14="","",'Data Entry'!H14) -> 1 | G17: =IF(F17=5,"Extreem",IF(F17=4,"Zeer groot",IF(F17=3,"Groot",IF(F17=2,"Aanwezig","Matig")))) -> Matig
A18: We collect revenues before we incur expenses | B18: =IF('Data Entry'!C14="","",'Data Entry'!C14) -> -5 | C18: =IF(B18<0,"Zwakte","Sterkte") -> Zwakte | E18: Total | F18: =IF(COUNTBLANK(F13:F17)=5,"",SUM(F13:F17)/5) -> 1.4 | G18: =IF(F18=5,"Extreem",IF(F18=4,"Zeer groot",IF(F18=3,"Groot",IF(F18=2,"Aanwezig","Matig")))) -> Matig
A19: We charge for what customers are really willing to pay for | B19: =IF('Data Entry'!C15="","",'Data Entry'!C15) -> 5 | C19: =IF(B19<0,"Zwakte","Sterkte") -> Sterkte
A20: Our pricing mechanisms capture full willingness to pay | B20: =IF('Data Entry'!C16="","",'Data Entry'!C16) -> 5 | C20: =IF(B20<0,"Zwakte","Sterkte") -> Sterkte
A21: Total | B21: =IF(COUNTBLANK(B13:B20)=8,"",SUM(B13:B20)/8) -> 0.75 | C21: =IF(B21<0,"Zwakte","Sterkte") -> Sterkte
A23: Costs | E23: =A23 -> Costs | I23: =A23 -> Costs
A24: Our costs are predictable | B24: =IF('Data Entry'!C17="","",'Data Entry'!C17) -> 5 | C24: =IF(B24<0,"Zwakte","Sterkte") -> Sterkte | E24: Where can we reduce costs? | F24: =IF('Data Entry'!H15="","",'Data Entry'!H15) -> 1 | G24: =IF(F24=5,"Extreem",IF(F24=4,"Zeer groot",IF(F24=3,"Groot",IF(F24=2,"Aanwezig","Matig")))) -> Matig | I24: Which costs threaten to become unpredictable? | J24: =IF('Data Entry'!M10="","",'Data Entry'!M10) -> 1 | K24: =IF(J24=-5,"Extreem",IF(J24=-4,"Zeer groot",IF(J24=-3,"Groot",IF(J24=-2,"Aanwezig","Matig")))) -> Matig
A25: Our Cost Structure is correctly matched to our business model | B25: =IF('Data Entry'!C18="","",'Data Entry'!C18) -> 5 | C25: =IF(B25<0,"Zwakte","Sterkte") -> Sterkte | E25: Total | F25: =IF(COUNTBLANK(F24)=1,"",SUM(F24)) -> 1 | G25: =IF(F25=5,"Extreem",IF(F25=4,"Zeer groot",IF(F25=3,"Groot",IF(F25=2,"Aanwezig","Matig")))) -> Matig | I25: Which costs threaten to grow more quickly than the revenues they support? | J25: =IF('Data Entry'!M11="","",'Data Entry'!M11) -> 1 | K25: =IF(J25=-5,"Extreem",IF(J25=-4,"Zeer groot",IF(J25=-3,"Groot",IF(J25=-2,"Aanwezig","Matig")))) -> Matig
A26: Our operations are cost-efficient | B26: =IF('Data Entry'!C19="","",'Data Entry'!C19) -> 2 | C26: =IF(B26<0,"Zwakte","Sterkte") -> Sterkte | I26: Total | J26: =IF(COUNTBLANK(J24:J25)=2,"",SUM(J24:J25)/2) -> 1 | K26: =IF(J26=-5,"Extreem",IF(J26=-4,"Zeer groot",IF(J26=-3,"Groot",IF(J26=-2,"Aanwezig","Matig")))) -> Matig
A27: We benefit from economies of scale | B27: =IF('Data Entry'!C20="","",'Data Entry'!C20) -> -3 | C27: =IF(B27<0,"Zwakte","Sterkte") -> Zwakte
A28: Total | B28: =IF(COUNTBLANK(B24:B27)=4,"",SUM(B24:B27)/4) -> 2.25 | C28: =IF(B28<0,"Zwakte","Sterkte") -> Sterkte
A30: Resources | E30: =A30 -> Resources | I30: =A30 -> Resources
A31: Our Key Resources are difficult for competitors to replicate | B31: =IF('Data Entry'!C21="","",'Data Entry'!C21) -> 5 | C31: =IF(B31<0,"Zwakte","Sterkte") -> Sterkte | E31: Could we use less costly resources to achieve the same result? | F31: =IF('Data Entry'!H16="","",'Data Entry'!H16) -> 1 | G31: =IF(F31=5,"Extreem",IF(F31=4,"Zeer groot",IF(F31=3,"Groot",IF(F31=2,"Aanwezig","Matig")))) -> Matig | I31: Could we face a disruption in the supply of certain resources? | J31: =IF('Data Entry'!M12="","",'Data Entry'!M12) -> 1 | K31: =IF(J31=-5,"Extreem",IF(J31=-4,"Zeer groot",IF(J31=-3,"Groot",IF(J31=-2,"Aanwezig","Matig")))) -> Matig
A32: Resource needs are predictable | B32: =IF('Data Entry'!C22="","",'Data Entry'!C22) -> 5 | C32: =IF(B32<0,"Zwakte","Sterkte") -> Sterkte | E32: Which Key Resources could be better sourced from partners? | F32: =IF('Data Entry'!H17="","",'Data Entry'!H17) -> 1 | G32: =IF(F32=5,"Extreem",IF(F32=4,"Zeer groot",IF(F32=3,"Groot",IF(F32=2,"Aanwezig","Matig")))) -> Matig | I32: Is the quality of our resources threatened in any way? | J32: =IF('Data Entry'!M13="","",'Data Entry'!M13) -> 1 | K32: =IF(J32=-5,"Extreem",IF(J32=-4,"Zeer groot",IF(J32=-3,"Groot",IF(J32=-2,"Aanwezig","Matig")))) -> Matig
A33: We deploy Key Resources in the right amount at the right time | B33: =IF('Data Entry'!C23="","",'Data Entry'!C23) -> 5 | C33: =IF(B33<0,"Zwakte","Sterkte") -> Sterkte | E33: Which Key Resources are under-exploited? | F33: =IF('Data Entry'!H18="","",'Data Entry'!H18) -> 1 | G33: =IF(F33=5,"Extreem",IF(F33=4,"Zeer groot",IF(F33=3,"Groot",IF(F33=2,"Aanwezig","Matig")))) -> Matig | I33: Total | J33: =IF(COUNTBLANK(J31:J32)=2,"",SUM(J31:J32)/2) -> 1 | K33: =IF(J33=-5,"Extreem",IF(J33=-4,"Zeer groot",IF(J33=-3,"Groot",IF(J33=-2,"Aanwezig","Matig")))) -> Matig
A34: Total | B34: =IF(COUNTBLANK(B31:B33)=3,"",SUM(B31:B33)/3) -> 5 | C34: =IF(B34<0,"Zwakte","Sterkte") -> Sterkte | E34: Do we have unused intellectual property of value to others? | F34: =IF('Data Entry'!H19="","",'Data Entry'!H19) -> 1 | G34: =IF(F34=5,"Extreem",IF(F34=4,"Zeer groot",IF(F34=3,"Groot",IF(F34=2,"Aanwezig","Matig")))) -> Matig
E35: Total | F35: =IF(COUNTBLANK(F31:F34)=4,"",SUM(F31:F34)/4) -> 1 | G35: =IF(F35=5,"Extreem",IF(F35=4,"Zeer groot",IF(F35=3,"Groot",IF(F35=2,"Aanwezig","Matig")))) -> Matig
A37: Activities | E37: =A37 -> Activities | I37: =A37 -> Activities
A38: We efficiently execute Key Activities | B38: =IF('Data Entry'!C24="","",'Data Entry'!C24) -> 1 | C38: =IF(B38<0,"Zwakte","Sterkte") -> Sterkte | E38: Could we standardize some Key Activities? | F38: =IF('Data Entry'!H20="","",'Data Entry'!H20) -> 3 | G38: =IF(F38=5,"Extreem",IF(F38=4,"Zeer groot",IF(F38=3,"Groot",IF(F38=2,"Aanwezig","Matig")))) -> Groot | I38: What Key Activities might be disrupted? | J38: =IF('Data Entry'!M14="","",'Data Entry'!M14) -> 2 | K38: =IF(J38=-5,"Extreem",IF(J38=-4,"Zeer groot",IF(J38=-3,"Groot",IF(J38=-2,"Aanwezig","Matig")))) -> Matig
A39: Our Key Activities are difficult to copy | B39: =IF('Data Entry'!C25="","",'Data Entry'!C25) -> 3 | C39: =IF(B39<0,"Zwakte","Sterkte") -> Sterkte | E39: How could we improve efficiency in general? | F39: =IF('Data Entry'!H21="","",'Data Entry'!H21) -> 1 | G39: =IF(F39=5,"Extreem",IF(F39=4,"Zeer groot",IF(F39=3,"Groot",IF(F39=2,"Aanwezig","Matig")))) -> Matig | I39: Is the quality of our activities threatened in any way? | J39: =IF('Data Entry'!M15="","",'Data Entry'!M15) -> 2 | K39: =IF(J39=-5,"Extreem",IF(J39=-4,"Zeer groot",IF(J39=-3,"Groot",IF(J39=-2,"Aanwezig","Matig")))) -> Matig
A40: Execution quality is high | B40: =IF('Data Entry'!C26="","",'Data Entry'!C26) -> 4 | C40: =IF(B40<0,"Zwakte","Sterkte") -> Sterkte | E40: Would IT support boost efficiency? | F40: =IF('Data Entry'!H22="","",'Data Entry'!H22) -> 2 | G40: =IF(F40=5,"Extreem",IF(F40=4,"Zeer groot",IF(F40=3,"Groot",IF(F40=2,"Aanwezig","Matig")))) -> Aanwezig | I40: Total | J40: =IF(COUNTBLANK(J38:J39)=2,"",SUM(J38:J39)/2) -> 2 | K40: =IF(J40=-5,"Extreem",IF(J40=-4,"Zeer groot",IF(J40=-3,"Groot",IF(J40=-2,"Aanwezig","Matig")))) -> Matig
A41: Balance of in-house versus outsourced execution is ideal | B41: =IF('Data Entry'!C27="","",'Data Entry'!C27) -> 0 | C41: =IF(B41<0,"Zwakte","Sterkte") -> Sterkte | E41: Total | F41: =IF(COUNTBLANK(F38:F40)=3,"",SUM(F38:F40)/3) -> 2 | G41: =IF(F41=5,"Extreem",IF(F41=4,"Zeer groot",IF(F41=3,"Groot",IF(F41=2,"Aanwezig","Matig")))) -> Aanwezig
A42: Total | B42: =IF(COUNTBLANK(B38:B41)=4,"",SUM(B38:B41)/4) -> 2 | C42: =IF(B42<0,"Zwakte","Sterkte") -> Sterkte
A44: Partners | E44: =A44 -> Partners | I44: =A44 -> Partners
...

Sheet Teksten
A1: Value proposition strength and weakness
A2: -5 | B2: Your products and services are not aligned with your customer needs, nor on each other and that causes unsatisfied customers.
A3: -4 | B3: A better alignment of your products and services and a better alignment on your customer needs would improve a better relationship with your customers.
A4: -3 | B4: The added value of your products and services are poor. Are they well aligned on each other and do they meet customer expectations?
A5: -2 | B5: Your value proposition is not balanced. Either the products and services are not well aligned or they do not meet customer expectations.
A6: -1 | B6: Customers are not quite satisfied. Make sure the alignment of your products and services meet customer expectations.
A7: 0 | B7: A doubtful score. Check to see what is happening or else you will lose customers.
A8: 1 | B8: Customers are slightly satisfied with your products and services. A better alignment with customer needs or a better alignment of your product portfolio is needed.
A9: 2 | B9: You know what customers want and you do your best to meet these expectations. You are doing pretty nice.
A10: 3 | B10: Customers are satisfied with your value proposition. There still is a possibility for improvement.
A11: 4 | B11: Your portfolio is in balance. You have aligned your products and services with your customer needs.
A12: 5 | B12: Your products and services are well aligned with your customer needs. That makes your customer satisfied.
A14: Value proposition opportunities | C14: Toegevoegde waarde klanten | G14: Producten of diensten aanpassen
A15: 5 | B15: There are opportunities to offer more value for your customers or to better align your products and services with each other.
A16: 4 | B16: A better alignment of you portfolio and more added value for your customers will offer extra revenues.
A17: 3 | B17: Use the opportunity to mutually align your portfolio and to better align with customer needs.
A18: 2 | B18: There are opportunities to better align your portfolio on customer needs or to improve the balance in your portfolio.
A19: 1 | B19: There are not many opportunities to improve your value proposition.
A21: Value proposition threads | C21: Substituut | E21: Betere prijs
A22: 5 | B22: Competitors have a better price or there are many substitutes available.
A23: 4 | B23: Substitutes are available and there is a price pressure. | D23: prijs
A24: 3 | B24: See if there are substitutes or check whether your price is to high?
A25: 2 | B25: Thread of substitutes or price pressure.
A26: 1 | B26: There is a low thread of substitutes or low prices at the competition.
A28: Customer relations strength and weakness | C28: Goede en sterke relaties | F28: Klantenbinding door overstapkosten en sterk merk
A29: -5 | B29: Customer relations are poor. The relation are not good and not strong. Customers can easily switch and the brand is not strong.
A30: -4 | B30: The relations with your customers are bad. They will switch easily to other suppliers.
A31: -3 | B31: Your segmentation or relationship management is inadequate. Besides that customers can easily switch and your brand is not strong.
A32: -2 | B32: Give attention to your customers, a better segmentation or account management is needed. Check the switching cost en the image of your brand.
A33: -1 | B33: Your customer relations are wakening and the loyalty of customers is getting less.
A34: 0 | B34: Mind your segmentation and how is your account management. How high are switching cost and what is the image of your brand.
A35: 1 | B35: Your customer relations are reasonable and there is some loyalty of your customers.
A36: 2 | B36: You have a common segmentation, your relationships are maintained however not exploited. Customers can switch whenever they want.
A37: 3 | B37: Take care that your relationships with your customers don't weaken and the brand gets less strong. Mind the switching cost for your customers.
A38: 4 | B38: You have good relationships with your customers and you have a strong brand. Switching is not easy for your customers.
A39: 5 | B39: You customer relations are very good, they are strong and good. Customers can hardly switch and your brand is strong.
A41: Customer relationships opportunities | C41: Klantrelaties, overstapkosten, niet winstgevende klanten, relaties automatiseren
A42: 5 | B42: Improve your customer relationships, increase the switching cost en "fire" non profitable customers.
A43: 4 | B43: Check the relations with your customers, are the switching cost high enough or do you have non profitable customers?
A44: 3 | B44: Your customer relationship probably can be better. Can you "fire" non profitable customers or can you raise switching cost?
...

Sheet Canvas Top
A2: ='Data Entry'!A2 -> Evaluation Business Model | F2: ='Data Entry'!D2 -> Company: | G2: ='Data Entry'!E2 -> Example company | K2: Name model | L2: ='Data Entry'!J2 -> Current Business Model | N2: Datum: | O2: ='Data Entry'!N2 -> 40908
A4: =IF($Y$6="","",IF($Y$6>3,Teksten!$B$248,IF($Y$6<-3,Teksten!$B$246,IF($Y$6="","Geen Tekst",Teksten!$B$247)))) -> Spent attention to your partners to focus better and maintain relations. | D4: =IF($Y$7="","",(IF($Y$7>3,Teksten!$B$252,IF($Y$7<-3,Teksten!$B$250,Teksten!$B$251)))) -> You can execute your activities more efficient and improve the quality. Perhaps some activities can be outsourced. | G4: =IF($Y$9="","",IF($Y$9>3,Teksten!$B$260,IF($Y$9<-3,Teksten!$B$258,Teksten!$B$259))) -> You do what your customer asks. Search for extra possibilities with customers and prospects. | J4: =IF($Y$10="","",IF($Y$10>3,Teksten!$B$264,IF($Y$10<-3,Teksten!$B$262,Teksten!$B$263))) -> You know how to control your customer relationships. Your challenge is to personalise these and to make the relationships stronger. | M4: =IF($Y$12="","",IF($Y$12>3,Teksten!$B$272,IF($Y$12<-3,Teksten!$B$270,Teksten!$B$271))) -> You know your customers. A better contact lowers customer retention. Mind your competition because they are trying to steal your customers.
V5: Sterkte of Zwakte | W5: Kans | X5: Bedreiging | Y5: Gemiddelde
T6: Partners | V6: =Categorie!B47 -> 1.5 | W6: =Categorie!F50 -> 1.8 | X6: =Categorie!J48 -> 1.3333333 | Y6: =Graph!Y6 -> 1.0333333
T7: Activiteiten | V7: =Categorie!B42 -> 2 | W7: =Categorie!F41 -> 2 | X7: =Categorie!J40 -> 2 | Y7: =Graph!Y7 -> 2
T8: Resources | V8: =Categorie!B34 -> 5 | W8: =Categorie!F35 -> 1 | X8: =Categorie!J33 -> 1 | Y8: =Graph!Y8 -> 5
T9: Waardepropositie | V9: =Categorie!B9 -> 1.75 | W9: =Categorie!F10 -> 2.8 | X9: =Categorie!J7 -> 3 | Y9: =Graph!Y9 -> 1.95
T10: Klantrelaties | V10: =Categorie!B74 -> 3 | W10: =Categorie!F76 -> 1.5 | X10: =Categorie!J71 -> 2 | Y10: =Graph!Y10 -> 3.5
T11: Distributieknanalen | V11: =Categorie!B67 -> -0.85714286 | W11: =Categorie!F65 -> 1.6 | X11: =Categorie!J62 -> 1 | Y11: =Graph!Y11 -> -1.4571429
T12: Afnemersegmenten | V12: =Categorie!B56 -> 3 | W12: =Categorie!F56 -> 3.3333333 | X12: =Categorie!J57 -> 2 | Y12: =Graph!Y12 -> 1.6666667
T13: Kosten | V13: =Categorie!B28 -> 2.25 | W13: =Categorie!F25 -> 1 | X13: =Categorie!J26 -> 1 | Y13: =Graph!Y13 -> 2.25
T14: Omzet | V14: =Categorie!B21 -> 0.75 | W14: =Categorie!F18 -> 1.4 | X14: =Categorie!J16 -> 1 | Y14: =Graph!Y14 -> 0.35
D15: =IF($Y$8="","",IF($Y$8>3,Teksten!$B$256,IF($Y$8<-3,Teksten!$B$254,Teksten!$B$255))) -> Your resources are well utilised. There is still room for optimizing. | J15: =IF($Y$11="","",IF($Y$11>3,Teksten!$B$268,IF($Y$11<-3,Teksten!$B$266,Teksten!$B$267))) -> You know how to reach your customers and prospects. However it can be better. How do you reach the different segments and how are opportunities integrated?
T17: Maximum | V17: 5 | W17: 5 | X17: 1 | Y17: =V17+W17-X17 -> 9 | Z17: 3
T19: Minimum | V19: -5 | W19: 1 | X19: 5 | Y19: =V19+W19-X19 -> -9 | Z19: -3
A26: =IF($Y$13="","",IF($Y$13>3,Teksten!$B$276,IF($Y$13<-3,Teksten!$B$274,Teksten!$B$275))) -> You know your cost structure. Align them better with your business model, lower overall cost and make them predictable. | H26: =IF($Y$14="","",IF($Y$14>3,Teksten!$B$280,IF($Y$14<-3,Teksten!$B$278,Teksten!$B$279))) -> You know your revenue streams. Better arguments with customers will lead to consistent revenue streams and less risk that revenues disappear.

Sheet Canvas Detail
B2: ='Data Entry'!A2 -> Evaluation Business Model | E2: ='Data Entry'!D2 -> Company: | F2: ='Data Entry'!E2 -> Example company | H2: Name model | I2: ='Data Entry'!J2 -> Current Business Model | K2: ='Data Entry'!N2 -> 40908 | P2: x
T4: =Graph!V5 -> Strenght or weakness | U4: =Graph!W5 -> Opportunity | V4: =Graph!X5 -> Threat | W4: =Graph!Y5 -> Gemiddelde
B5: =IF(T5="","",IF(T5>4,Teksten!$B228,IF(T5>3,Teksten!$B227,IF(T5>2,Teksten!$B226,IF(T5>1,Teksten!$B225,IF(T5>0,Teksten!$B224,IF(T5>-1,Teksten!$B223,IF(T5>-2,Teksten!$B222,IF(T5>-3,Teksten!$B221,IF(T5>-4,Teksten!$B220,IF(T5>-5,Teksten!$B219,IF(T5>-6,Teksten!$B218,"tekst ontbreekt")))))))))))) -> How can partners better support you? | D5: =IF(T6="","",IF(T6>4,Teksten!B147,IF(T6>3,Teksten!B146,IF(T6>2,Teksten!B145,IF(T6>1,Teksten!B144,IF(T6>0,Teksten!B143,IF(T6>-1,Teksten!B142,IF(T6>-2,Teksten!B141,IF(T6>-3,Teksten!B140,IF(T6>-4,Teksten!B139,IF(T6>-5,Teksten!B138,IF(T6>-6,Teksten!B137,"tekst ontbreekt")))))))))))) -> Check if activities can be more efficient. Protect against copying or outsource activities. | F5: =IF(T8="","",IF(T8>4,Teksten!B12,IF(T8>3,Teksten!B11,IF(T8>2,Teksten!B10,IF(T8>1,Teksten!B9,IF(T8>0,Teksten!B8,IF(T8>-1,Teksten!B7,IF(T8>-2,Teksten!B6,IF(T8>-3,Teksten!B5,IF(T8>-4,Teksten!B4,IF(T8>-5,Teksten!B3,IF(T8>-6,Teksten!B2,"tekst ontbreekt")))))))))))) -> You know what customers want and you do your best to meet these expectations. You are doing pretty nice. | H5: =IF(T9="","",IF(T9>4,Teksten!B39,IF(T9>3,Teksten!B38,IF(T9>2,Teksten!B37,IF(T9>1,Teksten!B36,IF(T9>0,Teksten!B35,IF(T9>-1,Teksten!B34,IF(T9>-2,Teksten!B33,IF(T9>-3,Teksten!B32,IF(T9>-4,Teksten!B31,IF(T9>-5,Teksten!B30,IF(T9>-6,Teksten!B29,"tekst ontbreekt")))))))))))) -> Take care that your relationships with your customers don't weaken and the brand gets less strong. Mind the switching cost for your customers. | J5: =IF(T11="","",IF(T11>4,Teksten!B66,IF(T11>3,Teksten!B65,IF(T11>2,Teksten!B64,IF(T11>1,Teksten!B63,IF(T11>0,Teksten!B62,IF(T11>-1,Teksten!B61,IF(T11>-2,Teksten!B60,IF(T11>-3,Teksten!B59,IF(T11>-4,Teksten!B58,IF(T11>-5,Teksten!B57,IF(T11>-6,Teksten!B56,"tekst ontbreekt")))))))))))) -> Could you improve customer acquisition by target each segment in a different way? Are you able to keep customer retention low? | R5: =Graph!T6 -> Partners | T5: =Graph!V6 -> 1.5 | U5: =Graph!W6 -> 1.8 | V5: =Graph!X6 -> 1.3333333 | W5: =Graph!Y6 -> 1.0333333
R6: =Graph!T7 -> Activities | T6: =Graph!V7 -> 2 | U6: =Graph!W7 -> 2 | V6: =Graph!X7 -> 2 | W6: =Graph!Y7 -> 2
R7: =Graph!T8 -> Resources | T7: =Graph!V8 -> 5 | U7: =Graph!W8 -> 1 | V7: =Graph!X8 -> 1 | W7: =Graph!Y8 -> 5
R8: =Graph!T9 -> Value proposition | T8: =Graph!V9 -> 1.75 | U8: =Graph!W9 -> 2.8 | V8: =Graph!X9 -> 3 | W8: =Graph!Y9 -> 1.95
D9: =IF(U6="","",IF(U6>4,Teksten!$B150,IF(U6>3,Teksten!$B151,IF(U6>2,Teksten!$B152,IF(U6>1,Teksten!$B153,IF(U6>0,Teksten!$B154,)))))) -> Analyse cost savings by standardisation and improvement of efficiency. | H9: =IF(U9="","",IF(U9>4,Teksten!B42,IF(U9>3,Teksten!B43,IF(U9>2,Teksten!B44,IF(U9>1,Teksten!B45,IF(U9>0,Teksten!B46,)))))) -> Check to see if you can improve your relationship with your customers or if you have any non profitable customers. | R9: =Graph!T10 -> Customer relations | T9: =Graph!V10 -> 3 | U9: =Graph!W10 -> 1.5 | V9: =Graph!X10 -> 2 | W9: =Graph!Y10 -> 3.5
R10: =Graph!T11 -> Channels | T10: =Graph!V11 -> -0.85714286 | U10: =Graph!W11 -> 1.6 | V10: =Graph!X11 -> 1 | W10: =Graph!Y11 -> -1.4571429
R11: =Graph!T12 -> Customer segments | T11: =Graph!V12 -> 3 | U11: =Graph!W12 -> 3.3333333 | V11: =Graph!X12 -> 2 | W11: =Graph!Y12 -> 1.6666667
R12: =Graph!T13 -> Cost structure | T12: =Graph!V13 -> 2.25 | U12: =Graph!W13 -> 1 | V12: =Graph!X13 -> 1 | W12: =Graph!Y13 -> 2.25
D13: =IF(V6="","",IF(V6>4,Teksten!$B157,IF(V6>3,Teksten!$B158,IF(V6>2,Teksten!$B159,IF(V6>1,Teksten!$B160,IF(V6>0,Teksten!$B161,)))))) -> What is a risk for continuity of your activities? | H13: =IF(V9="","",IF(V9>4,Teksten!B49,IF(V9>3,Teksten!B50,IF(V9>2,Teksten!B51,IF(V9>1,Teksten!B52,IF(V9>0,Teksten!B53,)))))) -> Your customer relationships may weaken. | R13: =Graph!T14 -> Revenue streams | T13: =Graph!V14 -> 0.75 | U13: =Graph!W14 -> 1.4 | V13: =Graph!X14 -> 1 | W13: =Graph!Y14 -> 0.35
B15: =IF(U5="","",IF(U5>4,Teksten!$B231,IF(U5>3,Teksten!$B232,IF(U5>2,Teksten!$B233,IF(U5>1,Teksten!$B234,IF(U5>0,Teksten!$B235,)))))) -> Which partners offer more value for your customers. | F15: =IF(U8="","",IF(U8>4,Teksten!B19,IF(U8>3,Teksten!B18,IF(U8>2,Teksten!B17,IF(U8>1,Teksten!B16,IF(U8>0,Teksten!B15,"tekst ontbreekt")))))) -> Use the opportunity to mutually align your portfolio and to better align with customer needs. | J15: =IF(U11="","",IF(U11>4,Teksten!B69,IF(U11>3,Teksten!B70,IF(U11>2,Teksten!B71,IF(U11>1,Teksten!B72,IF(U11>0,Teksten!B73,"Geen tekst")))))) -> Segment your target group in more detail and use the growth of the market.
D18: =IF(T7="","",IF(T7>4,Teksten!B174,IF(T7>3,Teksten!B173,IF(T7>2,Teksten!B172,IF(T7>1,Teksten!B171,IF(T7>0,Teksten!B170,IF(T7>-1,Teksten!B169,IF(T7>-2,Teksten!B168,IF(T7>-3,Teksten!B167,IF(T7>-4,Teksten!B166,IF(T7>-5,Teksten!B165,IF(T7>-6,Teksten!B164,"tekst ontbreekt")))))))))))) -> Keep your resources aligned and keep them unique. | H18: =IF(T10="","",IF(T10>4,Teksten!$B93,IF(T10>3,Teksten!$B92,IF(T10>2,Teksten!$B91,IF(T10>1,Teksten!$B90,IF(T10>0,Teksten!$B89,IF(T10>-1,Teksten!$B88,IF(T10>-2,Teksten!$B87,IF(T10>-3,Teksten!$B86,IF(T10>-4,Teksten!$B85,IF(T10>-5,Teksten!$B84,IF(T10>-6,Teksten!$B83,"tekst ontbreekt")))))))))))) -> Further development of channels offer possibilities.
F21: =IF(V8="","",IF(V8>4,Teksten!B26,IF(V8>3,Teksten!B25,IF(V8>2,Teksten!B24,IF(V8>1,Teksten!B23,IF(V8>0,Teksten!B22,"tekst ontbreekt")))))) -> See if there are substitutes or check whether your price is to high? | J21: =IF(V11="","",IF(V11>4,Teksten!B76,IF(V11>3,Teksten!B77,IF(V11>2,Teksten!B78,IF(V11>1,Teksten!B79,IF(V11>0,Teksten!B80,)))))) -> Compare your competitors or check the saturation of the market.
B22: =IF(V5="","",IF(V5>4,Teksten!$B238,IF(V5>3,Teksten!$B239,IF(V5>2,Teksten!$B240,IF(V5>1,Teksten!$B241,IF(V5>0,Teksten!$B184,)))))) -> Spent attention to your partners or they may cause a threat. | D22: =IF(U7="","",IF(U7>4,Teksten!$B177,IF(U7>3,Teksten!$B178,IF(U7>2,Teksten!$B179,IF(U7>1,Teksten!$B180,IF(U7>0,Teksten!$B181,)))))) -> Analyse your resources for cost savings. Check if intellectual property or other means of value can be transferred into money. | H22: =IF(U10="","",IF(U10>4,Teksten!$B96,IF(U10>3,Teksten!$B97,IF(U10>2,Teksten!$B98,IF(U10>1,Teksten!$B99,IF(U10>0,Teksten!$B100,)))))) -> Improve one of the aspects of quality, customer orientation, integration, new channels of your channels.
D26: =IF(V7="","",IF(V7>4,Teksten!$B184,IF(V7>3,Teksten!$B185,IF(V7>2,Teksten!$B186,IF(V7>1,Teksten!$B187,IF(V7>0,Teksten!$B188,)))))) -> What risks are there with respect to your resources? | H26: =IF(V10="","",IF(V10>4,Teksten!$B103,IF(V10>3,Teksten!$B104,IF(V10>2,Teksten!$B105,IF(V10>1,Teksten!$B106,IF(V10>0,Teksten!$B107,)))))) -> Decide which channels are important for you and protect them.
B32: =IF(T12="","",IF(T12>4,Teksten!$B201,IF(T12>3,Teksten!$B200,IF(T12>2,Teksten!$B199,IF(T12>1,Teksten!$B198,IF(T12>0,Teksten!$B197,IF(T12>-1,Teksten!$B196,IF(T12>-2,Teksten!$B195,IF(T12>-3,Teksten!$B194,IF(T12>-4,Teksten!$B193,IF(T12>-5,Teksten!$B92,IF(T12>-6,Teksten!$B91,"tekst ontbreekt")))))))))))) -> Make your business processes more efficient. | G32: =IF(T13="","",IF(T13>4,Teksten!$B120,IF(T13>3,Teksten!$B119,IF(T13>2,Teksten!$B118,IF(T13>1,Teksten!$B117,IF(T13>0,Teksten!$B116,IF(T13>-1,Teksten!$B115,IF(T13>-2,Teksten!$B114,IF(T13>-3,Teksten!$B113,IF(T13>-4,Teksten!$B112,IF(T13>-5,Teksten!$B111,IF(T13>-6,Teksten!$B110,"tekst ontbreekt")))))))))))) -> Find preservation for your revenue streams.
B35: =IF(U12="","",IF(U12>4,Teksten!$B204,IF(U12>3,Teksten!$B205,IF(U12>2,Teksten!$B206,IF(U12>1,Teksten!$B207,IF(U12>0,Teksten!$B208,)))))) -> Save cost on the clear subjects. However don't spent too much time and effort. Your organisation is already pretty lean and mean. | G35: =IF(U13="","",IF(U13>4,Teksten!$B123,IF(U13>3,Teksten!$B124,IF(U13>2,Teksten!$B125,IF(U13>1,Teksten!$B126,IF(U13>0,Teksten!$B127,)))))) -> There is a possibility for other revenue streams or price increase.
B38: =IF(V12="","",IF(V12>4,Teksten!$B211,IF(V12>3,Teksten!$B212,IF(V12>2,Teksten!$B213,IF(V12>1,Teksten!$B214,IF(V12>0,Teksten!$B215,)))))) -> Check your cost structure, but don't invest too much time and energy. | G38: =IF(V13="","",IF(V13>4,Teksten!$B130,IF('Canvas Detail'!V13>3,Teksten!$B131,IF(V13>2,Teksten!$B132,IF(V13>1,Teksten!$B133,IF(V13>0,Teksten!$B134,)))))) -> Which developments on the market can be of influence on your revenue streams and margins?

Sheet Graph
A2: ='Data Entry'!A2 -> Evaluation Business Model | F2: Company: | G2: ='Data Entry'!E2 -> Example company | K2: Name Model: | L2: ='Data Entry'!J2 -> Current Business Model | N2: Date: | O2: ='Data Entry'!N2 -> 40908
V5: Strenght or weakness | W5: Opportunity | X5: Threat | Y5: Gemiddelde
T6: Partners | V6: =Categorie!B47 -> 1.5 | W6: =Categorie!F50 -> 1.8 | X6: =Categorie!J48 -> 1.3333333 | Y6: =IF(V6="",IF(W6="",IF(X6="","",V6+X6-W6),V6+X6-W6),V6+X6-W6) -> 1.0333333
T7: Activities | V7: =Categorie!B42 -> 2 | W7: =Categorie!F41 -> 2 | X7: =Categorie!J40 -> 2 | Y7: =IF(V7="",IF(W7="",IF(X7="","",V7+X7-W7),V7+X7-W7),V7+X7-W7) -> 2
T8: Resources | V8: =Categorie!B34 -> 5 | W8: =Categorie!F35 -> 1 | X8: =Categorie!J33 -> 1 | Y8: =IF(V8="",IF(W8="",IF(X8="","",V8+X8-W8),V8+X8-W8),V8+X8-W8) -> 5
T9: Value proposition | V9: =Categorie!B9 -> 1.75 | W9: =Categorie!F10 -> 2.8 | X9: =Categorie!J7 -> 3 | Y9: =IF(V9="",IF(W9="",IF(X9="","",V9+X9-W9),V9+X9-W9),V9+X9-W9) -> 1.95
T10: Customer relations | V10: =Categorie!B74 -> 3 | W10: =Categorie!F76 -> 1.5 | X10: =Categorie!J71 -> 2 | Y10: =IF(V10="",IF(W10="",IF(X10="","",V10+X10-W10),V10+X10-W10),V10+X10-W10) -> 3.5
T11: Channels | V11: =Categorie!B67 -> -0.85714286 | W11: =Categorie!F65 -> 1.6 | X11: =Categorie!J62 -> 1 | Y11: =IF(V11="",IF(W11="",IF(X11="","",V11+X11-W11),V11+X11-W11),V11+X11-W11) -> -1.4571429
T12: Customer segments | V12: =Categorie!B56 -> 3 | W12: =Categorie!F56 -> 3.3333333 | X12: =Categorie!J57 -> 2 | Y12: =IF(V12="",IF(W12="",IF(X12="","",V12+X12-W12),V12+X12-W12),V12+X12-W12) -> 1.6666667
T13: Cost structure | V13: =Categorie!B28 -> 2.25 | W13: =Categorie!F25 -> 1 | X13: =Categorie!J26 -> 1 | Y13: =IF(V13="",IF(W13="",IF(X13="","",V13+X13-W13),V13+X13-W13),V13+X13-W13) -> 2.25
T14: Revenue streams | V14: =Categorie!B21 -> 0.75 | W14: =Categorie!F18 -> 1.4 | X14: =Categorie!J16 -> 1 | Y14: =IF(V14="",IF(W14="",IF(X14="","",V14+X14-W14),V14+X14-W14),V14+X14-W14) -> 0.35
T17: Maximum | V17: 5 | W17: 5 | X17: 1 | Y17: =V17+W17-X17 -> 9 | Z17: 3
T19: Minimum | V19: -5 | W19: 1 | X19: 5 | Y19: =V19+W19-X19 -> -9 | Z19: -3
