Workbook
Name County: 'Dropdown Menu'!$B$1:$B$101
Name Flow: 'Dropdown Menu'!#REF!
Name Flow: 'Dropdown Menu'!#REF!
Name Flow: 'Dropdown Menu'!#REF!
Name Flow: 'Dropdown Menu'!#REF!
Name Flow: 'Dropdown Menu'!#REF!
Name Month: 'Dropdown Menu'!$A$1:$A$13
Name Parameters: 'Formulas & Weather Codes'!#REF!
Name Parameters: 'Formulas & Weather Codes'!#REF!
Name Parameters: 'Formulas & Weather Codes'!#REF!
Name Parameters: 'Formulas & Weather Codes'!#REF!
Name Parameters: 'Formulas & Weather Codes'!#REF!
Name PCS: 'Formulas & Weather Codes'!#REF!
Name PCS: 'Formulas & Weather Codes'!#REF!
Name PCS: 'Formulas & Weather Codes'!#REF!
Name PCS: 'Formulas & Weather Codes'!#REF!
Name PCS: 'Formulas & Weather Codes'!#REF!
Name PCSCODE: 'Formulas & Weather Codes'!#REF!
Name PCSCODE: 'Formulas & Weather Codes'!#REF!
Name PCSCODE: 'Formulas & Weather Codes'!#REF!
Name PCSCODE: 'Formulas & Weather Codes'!#REF!
Name PCSCODE: 'Formulas & Weather Codes'!#REF!
Name PPI: 'Dropdown Menu'!#REF!
Name PPI: 'Dropdown Menu'!#REF!
Name PPI: 'Dropdown Menu'!#REF!
Name PPI: 'Dropdown Menu'!#REF!
Name PPI: 'Dropdown Menu'!#REF!
Name SamplingType: 'Dropdown Menu'!#REF!
Name SamplingType: 'Dropdown Menu'!#REF!
Name SamplingType: 'Dropdown Menu'!#REF!
Name SamplingType: 'Dropdown Menu'!#REF!
Name SamplingType: 'Dropdown Menu'!#REF!
Name Weather: 'Dropdown Menu'!$D$1:$D$7
Name Year: 'Dropdown Menu'!$C$1:$C$21

Sheet Enter Data Here
A1: Day | B1: Weather | C1: Temp | D1: Precip | E1: Freeboard | F1: Zone 1 | L1: Zone 2 | R1: Zone 3 | X1: Zone 4 | AD1: Zone 5 | AJ1: Zone 6 | AP1: Zone 7 | AV1: Zone 8 | BB1: Zone 9 | BH1: Zone 10 | BN1: Zone 11 | BT1: Zone 12 | BZ1: Zone 13 | CF1: Zone 14 | CL1: Zone 15 | CR1: Zone 16
F2: Dose 1 | H2: Dose 2 | J2: Dose 3 | L2: Dose 1 | N2: Dose 2 | P2: Dose 3 | R2: Dose 1 | T2: Dose 2 | V2: Dose 3 | X2: Dose 1 | Z2: Dose 2 | AB2: Dose 3 | AD2: Dose 1 | AF2: Dose 2 | AH2: Dose 3 | AJ2: Dose 1 | AL2: Dose 2 | AN2: Dose 3 | AP2: Dose 1 | AR2: Dose 2 | AT2: Dose 3 | AV2: Dose 1 | AX2: Dose 2 | AZ2: Dose 3 | BB2: Dose 1 | BD2: Dose 2 | BF2: Dose 3 | BH2: Dose 1 | BJ2: Dose 2 | BL2: Dose 3 | BN2: Dose 1 | BP2: Dose 2 | BR2: Dose 3 | BT2: Dose 1 | BV2: Dose 2 | BX2: Dose 3 | BZ2: Dose 1 | CB2: Dose 2 | CD2: Dose 3 | CF2: Dose 1 | CH2: Dose 2 | CJ2: Dose 3 | CL2: Dose 1 | CN2: Dose 2 | CP2: Dose 3 | CR2: Dose 1 | CT2: Dose 2 | CV2: Dose 3
F3: Vol | G3: Time | H3: Vol | I3: Time | J3: Vol | K3: Time | L3: Vol | M3: Time | N3: Vol | O3: Time | P3: Vol | Q3: Time | R3: Vol | S3: Time | T3: Vol | U3: Time | V3: Vol | W3: Time | X3: Vol | Y3: Time | Z3: Vol | AA3: Time | AB3: Vol | AC3: Time | AD3: Vol | AE3: Time | AF3: Vol | AG3: Time | AH3: Vol | AI3: Time | AJ3: Vol | AK3: Time | AL3: Vol | AM3: Time | AN3: Vol | AO3: Time | AP3: Vol | AQ3: Time | AR3: Vol | AS3: Time | AT3: Vol | AU3: Time | AV3: Vol | AW3: Time | AX3: Vol | AY3: Time | AZ3: Vol | BA3: Time | BB3: Vol | BC3: Time | BD3: Vol | BE3: Time | BF3: Vol | BG3: Time | BH3: Vol | BI3: Time | BJ3: Vol | BK3: Time | BL3: Vol | BM3: Time | BN3: Vol | BO3: Time | BP3: Vol | BQ3: Time | BR3: Vol | BS3: Time | BT3: Vol | BU3: Time | BV3: Vol | BW3: Time | BX3: Vol | BY3: Time | BZ3: Vol | CA3: Time | CB3: Vol | CC3: Time | CD3: Vol | CE3: Time | CF3: Vol | CG3: Time | CH3: Vol | CI3: Time | CJ3: Vol | CK3: Time | CL3: Vol | CM3: Time | CN3: Vol | CO3: Time | CP3: Vol | CQ3: Time | CR3: Vol | CS3: Time | CT3: Vol | CU3: Time | CV3: Vol | CW3: Time
A4: 1
A5: 2
A6: 3
A7: 4
A8: 5
A9: 6
A10: 7
A11: 8
A12: 9
A13: 10
A14: 11
A15: 12
... A34: 31
A38: 1 | F38: =F4/('Page 1'!$I$3*27152) -> 0 | H38: =H4/('Page 1'!$I$3*27152) -> 0 | J38: =J4/('Page 1'!$I$3*27152) -> 0 | L38: =L4/('Page 1'!$M$3*27152) -> 0 | N38: =N4/('Page 1'!$M$3*27152) -> 0 | P38: =P4/('Page 1'!$M$3*27152) -> 0 | R38: =R4/('Page 1'!$Q$3*27152) -> 0 | T38: =T4/('Page 1'!$Q$3*27152) -> 0 | V38: =V4/('Page 1'!$Q$3*27152) -> 0 | X38: =X4/('Page 1'!$U$3*27152) -> 0 | Z38: =Z4/('Page 1'!$U$3*27152) -> 0 | AB38: =AB4/('Page 1'!$U$3*27152) -> 0 | AD38: =AD4/('Page 2'!$I$3*27152) -> 0 | AF38: =AF4/('Page 2'!$I$3*27152) -> 0 | AH38: =AH4/('Page 2'!$I$3*27152) -> 0 | AJ38: =AJ4/('Page 2'!$M$3*27152) -> 0 | AL38: =AL4/('Page 2'!$M$3*27152) -> 0 | AN38: =AN4/('Page 2'!$M$3*27152) -> 0 | AP38: =AP4/('Page 2'!$Q$3*27152) -> 0 | AR38: =AR4/('Page 2'!$Q$3*27152) -> 0 | AT38: =AT4/('Page 2'!$Q$3*27152) -> 0 | AV38: =AV4/('Page 2'!$U$3*27152) -> 0 | AX38: =AX4/('Page 2'!$U$3*27152) -> 0 | AZ38: =AZ4/('Page 2'!$U$3*27152) -> 0 | BB38: =BB4/('Page 3'!$I$3*27152) -> 0 | BD38: =BD4/('Page 3'!$I$3*27152) -> 0 | BF38: =BF4/('Page 3'!$I$3*27152) -> 0 | BH38: =BH4/('Page 3'!$M$3*27152) -> 0 | BJ38: =BJ4/('Page 3'!$M$3*27152) -> 0 | BL38: =BL4/('Page 3'!$M$3*27152) -> 0 | BN38: =BN4/('Page 3'!$Q$3*27152) -> 0 | BP38: =BP4/('Page 3'!$Q$3*27152) -> 0 | BR38: =BR4/('Page 3'!$Q$3*27152) -> 0 | BT38: =BT4/('Page 3'!$U$3*27152) -> 0 | BV38: =BV4/('Page 3'!$U$3*27152) -> 0 | BX38: =BX4/('Page 3'!$U$3*27152) -> 0 | BZ38: =BZ4/('Page 4'!$I$3*27152) -> 0 | CB38: =CB4/('Page 4'!$I$3*27152) -> 0 | CD38: =CD4/('Page 4'!$I$3*27152) -> 0 | CF38: =CF4/('Page 4'!$M$3*27152) -> 0 | CH38: =CH4/('Page 4'!$M$3*27152) -> 0 | CJ38: =CJ4/('Page 4'!$M$3*27152) -> 0 | CL38: =CL4/('Page 4'!$Q$3*27152) -> 0 | CN38: =CN4/('Page 4'!$Q$3*27152) -> 0 | CP38: =CP4/('Page 4'!$Q$3*27152) -> 0 | CR38: =CR4/('Page 4'!$U$3*27152) -> 0 | CT38: =CT4/('Page 4'!$U$3*27152) -> 0 | CV38: =CV4/('Page 4'!$U$3*27152) -> 0
A39: 2 | F39: =F5/('Page 1'!$I$3*27152) -> 0 | H39: =H5/('Page 1'!$I$3*27152) -> 0 | J39: =J5/('Page 1'!$I$3*27152) -> 0 | L39: =L5/('Page 1'!$M$3*27152) -> 0 | N39: =N5/('Page 1'!$M$3*27152) -> 0 | P39: =P5/('Page 1'!$M$3*27152) -> 0 | R39: =R5/('Page 1'!$Q$3*27152) -> 0 | T39: =T5/('Page 1'!$Q$3*27152) -> 0 | V39: =V5/('Page 1'!$Q$3*27152) -> 0 | X39: =X5/('Page 1'!$U$3*27152) -> 0 | Z39: =Z5/('Page 1'!$U$3*27152) -> 0 | AB39: =AB5/('Page 1'!$U$3*27152) -> 0 | AD39: =AD5/('Page 2'!$I$3*27152) -> 0 | AF39: =AF5/('Page 2'!$I$3*27152) -> 0 | AH39: =AH5/('Page 2'!$I$3*27152) -> 0 | AJ39: =AJ5/('Page 2'!$M$3*27152) -> 0 | AL39: =AL5/('Page 2'!$M$3*27152) -> 0 | AN39: =AN5/('Page 2'!$M$3*27152) -> 0 | AP39: =AP5/('Page 2'!$Q$3*27152) -> 0 | AR39: =AR5/('Page 2'!$Q$3*27152) -> 0 | AT39: =AT5/('Page 2'!$Q$3*27152) -> 0 | AV39: =AV5/('Page 2'!$U$3*27152) -> 0 | AX39: =AX5/('Page 2'!$U$3*27152) -> 0 | AZ39: =AZ5/('Page 2'!$U$3*27152) -> 0 | BB39: =BB5/('Page 3'!$I$3*27152) -> 0 | BD39: =BD5/('Page 3'!$I$3*27152) -> 0 | BF39: =BF5/('Page 3'!$I$3*27152) -> 0 | BH39: =BH5/('Page 3'!$M$3*27152) -> 0 | BJ39: =BJ5/('Page 3'!$M$3*27152) -> 0 | BL39: =BL5/('Page 3'!$M$3*27152) -> 0 | BN39: =BN5/('Page 3'!$Q$3*27152) -> 0 | BP39: =BP5/('Page 3'!$Q$3*27152) -> 0 | BR39: =BR5/('Page 3'!$Q$3*27152) -> 0 | BT39: =BT5/('Page 3'!$U$3*27152) -> 0 | BV39: =BV5/('Page 3'!$U$3*27152) -> 0 | BX39: =BX5/('Page 3'!$U$3*27152) -> 0 | BZ39: =BZ5/('Page 4'!$I$3*27152) -> 0 | CB39: =CB5/('Page 4'!$I$3*27152) -> 0 | CD39: =CD5/('Page 4'!$I$3*27152) -> 0 | CF39: =CF5/('Page 4'!$M$3*27152) -> 0 | CH39: =CH5/('Page 4'!$M$3*27152) -> 0 | CJ39: =CJ5/('Page 4'!$M$3*27152) -> 0 | CL39: =CL5/('Page 4'!$Q$3*27152) -> 0 | CN39: =CN5/('Page 4'!$Q$3*27152) -> 0 | CP39: =CP5/('Page 4'!$Q$3*27152) -> 0 | CR39: =CR5/('Page 4'!$U$3*27152) -> 0 | CT39: =CT5/('Page 4'!$U$3*27152) -> 0 | CV39: =CV5/('Page 4'!$U$3*27152) -> 0
A40: 3 | F40: =F6/('Page 1'!$I$3*27152) -> 0 | H40: =H6/('Page 1'!$I$3*27152) -> 0 | J40: =J6/('Page 1'!$I$3*27152) -> 0 | L40: =L6/('Page 1'!$M$3*27152) -> 0 | N40: =N6/('Page 1'!$M$3*27152) -> 0 | P40: =P6/('Page 1'!$M$3*27152) -> 0 | R40: =R6/('Page 1'!$Q$3*27152) -> 0 | T40: =T6/('Page 1'!$Q$3*27152) -> 0 | V40: =V6/('Page 1'!$Q$3*27152) -> 0 | X40: =X6/('Page 1'!$U$3*27152) -> 0 | Z40: =Z6/('Page 1'!$U$3*27152) -> 0 | AB40: =AB6/('Page 1'!$U$3*27152) -> 0 | AD40: =AD6/('Page 2'!$I$3*27152) -> 0 | AF40: =AF6/('Page 2'!$I$3*27152) -> 0 | AH40: =AH6/('Page 2'!$I$3*27152) -> 0 | AJ40: =AJ6/('Page 2'!$M$3*27152) -> 0 | AL40: =AL6/('Page 2'!$M$3*27152) -> 0 | AN40: =AN6/('Page 2'!$M$3*27152) -> 0 | AP40: =AP6/('Page 2'!$Q$3*27152) -> 0 | AR40: =AR6/('Page 2'!$Q$3*27152) -> 0 | AT40: =AT6/('Page 2'!$Q$3*27152) -> 0 | AV40: =AV6/('Page 2'!$U$3*27152) -> 0 | AX40: =AX6/('Page 2'!$U$3*27152) -> 0 | AZ40: =AZ6/('Page 2'!$U$3*27152) -> 0 | BB40: =BB6/('Page 3'!$I$3*27152) -> 0 | BD40: =BD6/('Page 3'!$I$3*27152) -> 0 | BF40: =BF6/('Page 3'!$I$3*27152) -> 0 | BH40: =BH6/('Page 3'!$M$3*27152) -> 0 | BJ40: =BJ6/('Page 3'!$M$3*27152) -> 0 | BL40: =BL6/('Page 3'!$M$3*27152) -> 0 | BN40: =BN6/('Page 3'!$Q$3*27152) -> 0 | BP40: =BP6/('Page 3'!$Q$3*27152) -> 0 | BR40: =BR6/('Page 3'!$Q$3*27152) -> 0 | BT40: =BT6/('Page 3'!$U$3*27152) -> 0 | BV40: =BV6/('Page 3'!$U$3*27152) -> 0 | BX40: =BX6/('Page 3'!$U$3*27152) -> 0 | BZ40: =BZ6/('Page 4'!$I$3*27152) -> 0 | CB40: =CB6/('Page 4'!$I$3*27152) -> 0 | CD40: =CD6/('Page 4'!$I$3*27152) -> 0 | CF40: =CF6/('Page 4'!$M$3*27152) -> 0 | CH40: =CH6/('Page 4'!$M$3*27152) -> 0 | CJ40: =CJ6/('Page 4'!$M$3*27152) -> 0 | CL40: =CL6/('Page 4'!$Q$3*27152) -> 0 | CN40: =CN6/('Page 4'!$Q$3*27152) -> 0 | CP40: =CP6/('Page 4'!$Q$3*27152) -> 0 | CR40: =CR6/('Page 4'!$U$3*27152) -> 0 | CT40: =CT6/('Page 4'!$U$3*27152) -> 0 | CV40: =CV6/('Page 4'!$U$3*27152) -> 0
A41: 4 | F41: =F7/('Page 1'!$I$3*27152) -> 0 | H41: =H7/('Page 1'!$I$3*27152) -> 0 | J41: =J7/('Page 1'!$I$3*27152) -> 0 | L41: =L7/('Page 1'!$M$3*27152) -> 0 | N41: =N7/('Page 1'!$M$3*27152) -> 0 | P41: =P7/('Page 1'!$M$3*27152) -> 0 | R41: =R7/('Page 1'!$Q$3*27152) -> 0 | T41: =T7/('Page 1'!$Q$3*27152) -> 0 | V41: =V7/('Page 1'!$Q$3*27152) -> 0 | X41: =X7/('Page 1'!$U$3*27152) -> 0 | Z41: =Z7/('Page 1'!$U$3*27152) -> 0 | AB41: =AB7/('Page 1'!$U$3*27152) -> 0 | AD41: =AD7/('Page 2'!$I$3*27152) -> 0 | AF41: =AF7/('Page 2'!$I$3*27152) -> 0 | AH41: =AH7/('Page 2'!$I$3*27152) -> 0 | AJ41: =AJ7/('Page 2'!$M$3*27152) -> 0 | AL41: =AL7/('Page 2'!$M$3*27152) -> 0 | AN41: =AN7/('Page 2'!$M$3*27152) -> 0 | AP41: =AP7/('Page 2'!$Q$3*27152) -> 0 | AR41: =AR7/('Page 2'!$Q$3*27152) -> 0 | AT41: =AT7/('Page 2'!$Q$3*27152) -> 0 | AV41: =AV7/('Page 2'!$U$3*27152) -> 0 | AX41: =AX7/('Page 2'!$U$3*27152) -> 0 | AZ41: =AZ7/('Page 2'!$U$3*27152) -> 0 | BB41: =BB7/('Page 3'!$I$3*27152) -> 0 | BD41: =BD7/('Page 3'!$I$3*27152) -> 0 | BF41: =BF7/('Page 3'!$I$3*27152) -> 0 | BH41: =BH7/('Page 3'!$M$3*27152) -> 0 | BJ41: =BJ7/('Page 3'!$M$3*27152) -> 0 | BL41: =BL7/('Page 3'!$M$3*27152) -> 0 | BN41: =BN7/('Page 3'!$Q$3*27152) -> 0 | BP41: =BP7/('Page 3'!$Q$3*27152) -> 0 | BR41: =BR7/('Page 3'!$Q$3*27152) -> 0 | BT41: =BT7/('Page 3'!$U$3*27152) -> 0 | BV41: =BV7/('Page 3'!$U$3*27152) -> 0 | BX41: =BX7/('Page 3'!$U$3*27152) -> 0 | BZ41: =BZ7/('Page 4'!$I$3*27152) -> 0 | CB41: =CB7/('Page 4'!$I$3*27152) -> 0 | CD41: =CD7/('Page 4'!$I$3*27152) -> 0 | CF41: =CF7/('Page 4'!$M$3*27152) -> 0 | CH41: =CH7/('Page 4'!$M$3*27152) -> 0 | CJ41: =CJ7/('Page 4'!$M$3*27152) -> 0 | CL41: =CL7/('Page 4'!$Q$3*27152) -> 0 | CN41: =CN7/('Page 4'!$Q$3*27152) -> 0 | CP41: =CP7/('Page 4'!$Q$3*27152) -> 0 | CR41: =CR7/('Page 4'!$U$3*27152) -> 0 | CT41: =CT7/('Page 4'!$U$3*27152) -> 0 | CV41: =CV7/('Page 4'!$U$3*27152) -> 0
A42: 5 | F42: =F8/('Page 1'!$I$3*27152) -> 0 | H42: =H8/('Page 1'!$I$3*27152) -> 0 | J42: =J8/('Page 1'!$I$3*27152) -> 0 | L42: =L8/('Page 1'!$M$3*27152) -> 0 | N42: =N8/('Page 1'!$M$3*27152) -> 0 | P42: =P8/('Page 1'!$M$3*27152) -> 0 | R42: =R8/('Page 1'!$Q$3*27152) -> 0 | T42: =T8/('Page 1'!$Q$3*27152) -> 0 | V42: =V8/('Page 1'!$Q$3*27152) -> 0 | X42: =X8/('Page 1'!$U$3*27152) -> 0 | Z42: =Z8/('Page 1'!$U$3*27152) -> 0 | AB42: =AB8/('Page 1'!$U$3*27152) -> 0 | AD42: =AD8/('Page 2'!$I$3*27152) -> 0 | AF42: =AF8/('Page 2'!$I$3*27152) -> 0 | AH42: =AH8/('Page 2'!$I$3*27152) -> 0 | AJ42: =AJ8/('Page 2'!$M$3*27152) -> 0 | AL42: =AL8/('Page 2'!$M$3*27152) -> 0 | AN42: =AN8/('Page 2'!$M$3*27152) -> 0 | AP42: =AP8/('Page 2'!$Q$3*27152) -> 0 | AR42: =AR8/('Page 2'!$Q$3*27152) -> 0 | AT42: =AT8/('Page 2'!$Q$3*27152) -> 0 | AV42: =AV8/('Page 2'!$U$3*27152) -> 0 | AX42: =AX8/('Page 2'!$U$3*27152) -> 0 | AZ42: =AZ8/('Page 2'!$U$3*27152) -> 0 | BB42: =BB8/('Page 3'!$I$3*27152) -> 0 | BD42: =BD8/('Page 3'!$I$3*27152) -> 0 | BF42: =BF8/('Page 3'!$I$3*27152) -> 0 | BH42: =BH8/('Page 3'!$M$3*27152) -> 0 | BJ42: =BJ8/('Page 3'!$M$3*27152) -> 0 | BL42: =BL8/('Page 3'!$M$3*27152) -> 0 | BN42: =BN8/('Page 3'!$Q$3*27152) -> 0 | BP42: =BP8/('Page 3'!$Q$3*27152) -> 0 | BR42: =BR8/('Page 3'!$Q$3*27152) -> 0 | BT42: =BT8/('Page 3'!$U$3*27152) -> 0 | BV42: =BV8/('Page 3'!$U$3*27152) -> 0 | BX42: =BX8/('Page 3'!$U$3*27152) -> 0 | BZ42: =BZ8/('Page 4'!$I$3*27152) -> 0 | CB42: =CB8/('Page 4'!$I$3*27152) -> 0 | CD42: =CD8/('Page 4'!$I$3*27152) -> 0 | CF42: =CF8/('Page 4'!$M$3*27152) -> 0 | CH42: =CH8/('Page 4'!$M$3*27152) -> 0 | CJ42: =CJ8/('Page 4'!$M$3*27152) -> 0 | CL42: =CL8/('Page 4'!$Q$3*27152) -> 0 | CN42: =CN8/('Page 4'!$Q$3*27152) -> 0 | CP42: =CP8/('Page 4'!$Q$3*27152) -> 0 | CR42: =CR8/('Page 4'!$U$3*27152) -> 0 | CT42: =CT8/('Page 4'!$U$3*27152) -> 0 | CV42: =CV8/('Page 4'!$U$3*27152) -> 0
A43: 6 | F43: =F9/('Page 1'!$I$3*27152) -> 0 | H43: =H9/('Page 1'!$I$3*27152) -> 0 | J43: =J9/('Page 1'!$I$3*27152) -> 0 | L43: =L9/('Page 1'!$M$3*27152) -> 0 | N43: =N9/('Page 1'!$M$3*27152) -> 0 | P43: =P9/('Page 1'!$M$3*27152) -> 0 | R43: =R9/('Page 1'!$Q$3*27152) -> 0 | T43: =T9/('Page 1'!$Q$3*27152) -> 0 | V43: =V9/('Page 1'!$Q$3*27152) -> 0 | X43: =X9/('Page 1'!$U$3*27152) -> 0 | Z43: =Z9/('Page 1'!$U$3*27152) -> 0 | AB43: =AB9/('Page 1'!$U$3*27152) -> 0 | AD43: =AD9/('Page 2'!$I$3*27152) -> 0 | AF43: =AF9/('Page 2'!$I$3*27152) -> 0 | AH43: =AH9/('Page 2'!$I$3*27152) -> 0 | AJ43: =AJ9/('Page 2'!$M$3*27152) -> 0 | AL43: =AL9/('Page 2'!$M$3*27152) -> 0 | AN43: =AN9/('Page 2'!$M$3*27152) -> 0 | AP43: =AP9/('Page 2'!$Q$3*27152) -> 0 | AR43: =AR9/('Page 2'!$Q$3*27152) -> 0 | AT43: =AT9/('Page 2'!$Q$3*27152) -> 0 | AV43: =AV9/('Page 2'!$U$3*27152) -> 0 | AX43: =AX9/('Page 2'!$U$3*27152) -> 0 | AZ43: =AZ9/('Page 2'!$U$3*27152) -> 0 | BB43: =BB9/('Page 3'!$I$3*27152) -> 0 | BD43: =BD9/('Page 3'!$I$3*27152) -> 0 | BF43: =BF9/('Page 3'!$I$3*27152) -> 0 | BH43: =BH9/('Page 3'!$M$3*27152) -> 0 | BJ43: =BJ9/('Page 3'!$M$3*27152) -> 0 | BL43: =BL9/('Page 3'!$M$3*27152) -> 0 | BN43: =BN9/('Page 3'!$Q$3*27152) -> 0 | BP43: =BP9/('Page 3'!$Q$3*27152) -> 0 | BR43: =BR9/('Page 3'!$Q$3*27152) -> 0 | BT43: =BT9/('Page 3'!$U$3*27152) -> 0 | BV43: =BV9/('Page 3'!$U$3*27152) -> 0 | BX43: =BX9/('Page 3'!$U$3*27152) -> 0 | BZ43: =BZ9/('Page 4'!$I$3*27152) -> 0 | CB43: =CB9/('Page 4'!$I$3*27152) -> 0 | CD43: =CD9/('Page 4'!$I$3*27152) -> 0 | CF43: =CF9/('Page 4'!$M$3*27152) -> 0 | CH43: =CH9/('Page 4'!$M$3*27152) -> 0 | CJ43: =CJ9/('Page 4'!$M$3*27152) -> 0 | CL43: =CL9/('Page 4'!$Q$3*27152) -> 0 | CN43: =CN9/('Page 4'!$Q$3*27152) -> 0 | CP43: =CP9/('Page 4'!$Q$3*27152) -> 0 | CR43: =CR9/('Page 4'!$U$3*27152) -> 0 | CT43: =CT9/('Page 4'!$U$3*27152) -> 0 | CV43: =CV9/('Page 4'!$U$3*27152) -> 0
A44: 7 | F44: =F10/('Page 1'!$I$3*27152) -> 0 | H44: =H10/('Page 1'!$I$3*27152) -> 0 | J44: =J10/('Page 1'!$I$3*27152) -> 0 | L44: =L10/('Page 1'!$M$3*27152) -> 0 | N44: =N10/('Page 1'!$M$3*27152) -> 0 | P44: =P10/('Page 1'!$M$3*27152) -> 0 | R44: =R10/('Page 1'!$Q$3*27152) -> 0 | T44: =T10/('Page 1'!$Q$3*27152) -> 0 | V44: =V10/('Page 1'!$Q$3*27152) -> 0 | X44: =X10/('Page 1'!$U$3*27152) -> 0 | Z44: =Z10/('Page 1'!$U$3*27152) -> 0 | AB44: =AB10/('Page 1'!$U$3*27152) -> 0 | AD44: =AD10/('Page 2'!$I$3*27152) -> 0 | AF44: =AF10/('Page 2'!$I$3*27152) -> 0 | AH44: =AH10/('Page 2'!$I$3*27152) -> 0 | AJ44: =AJ10/('Page 2'!$M$3*27152) -> 0 | AL44: =AL10/('Page 2'!$M$3*27152) -> 0 | AN44: =AN10/('Page 2'!$M$3*27152) -> 0 | AP44: =AP10/('Page 2'!$Q$3*27152) -> 0 | AR44: =AR10/('Page 2'!$Q$3*27152) -> 0 | AT44: =AT10/('Page 2'!$Q$3*27152) -> 0 | AV44: =AV10/('Page 2'!$U$3*27152) -> 0 | AX44: =AX10/('Page 2'!$U$3*27152) -> 0 | AZ44: =AZ10/('Page 2'!$U$3*27152) -> 0 | BB44: =BB10/('Page 3'!$I$3*27152) -> 0 | BD44: =BD10/('Page 3'!$I$3*27152) -> 0 | BF44: =BF10/('Page 3'!$I$3*27152) -> 0 | BH44: =BH10/('Page 3'!$M$3*27152) -> 0 | BJ44: =BJ10/('Page 3'!$M$3*27152) -> 0 | BL44: =BL10/('Page 3'!$M$3*27152) -> 0 | BN44: =BN10/('Page 3'!$Q$3*27152) -> 0 | BP44: =BP10/('Page 3'!$Q$3*27152) -> 0 | BR44: =BR10/('Page 3'!$Q$3*27152) -> 0 | BT44: =BT10/('Page 3'!$U$3*27152) -> 0 | BV44: =BV10/('Page 3'!$U$3*27152) -> 0 | BX44: =BX10/('Page 3'!$U$3*27152) -> 0 | BZ44: =BZ10/('Page 4'!$I$3*27152) -> 0 | CB44: =CB10/('Page 4'!$I$3*27152) -> 0 | CD44: =CD10/('Page 4'!$I$3*27152) -> 0 | CF44: =CF10/('Page 4'!$M$3*27152) -> 0 | CH44: =CH10/('Page 4'!$M$3*27152) -> 0 | CJ44: =CJ10/('Page 4'!$M$3*27152) -> 0 | CL44: =CL10/('Page 4'!$Q$3*27152) -> 0 | CN44: =CN10/('Page 4'!$Q$3*27152) -> 0 | CP44: =CP10/('Page 4'!$Q$3*27152) -> 0 | CR44: =CR10/('Page 4'!$U$3*27152) -> 0 | CT44: =CT10/('Page 4'!$U$3*27152) -> 0 | CV44: =CV10/('Page 4'!$U$3*27152) -> 0
A45: 8 | F45: =F11/('Page 1'!$I$3*27152) -> 0 | H45: =H11/('Page 1'!$I$3*27152) -> 0 | J45: =J11/('Page 1'!$I$3*27152) -> 0 | L45: =L11/('Page 1'!$M$3*27152) -> 0 | N45: =N11/('Page 1'!$M$3*27152) -> 0 | P45: =P11/('Page 1'!$M$3*27152) -> 0 | R45: =R11/('Page 1'!$Q$3*27152) -> 0 | T45: =T11/('Page 1'!$Q$3*27152) -> 0 | V45: =V11/('Page 1'!$Q$3*27152) -> 0 | X45: =X11/('Page 1'!$U$3*27152) -> 0 | Z45: =Z11/('Page 1'!$U$3*27152) -> 0 | AB45: =AB11/('Page 1'!$U$3*27152) -> 0 | AD45: =AD11/('Page 2'!$I$3*27152) -> 0 | AF45: =AF11/('Page 2'!$I$3*27152) -> 0 | AH45: =AH11/('Page 2'!$I$3*27152) -> 0 | AJ45: =AJ11/('Page 2'!$M$3*27152) -> 0 | AL45: =AL11/('Page 2'!$M$3*27152) -> 0 | AN45: =AN11/('Page 2'!$M$3*27152) -> 0 | AP45: =AP11/('Page 2'!$Q$3*27152) -> 0 | AR45: =AR11/('Page 2'!$Q$3*27152) -> 0 | AT45: =AT11/('Page 2'!$Q$3*27152) -> 0 | AV45: =AV11/('Page 2'!$U$3*27152) -> 0 | AX45: =AX11/('Page 2'!$U$3*27152) -> 0 | AZ45: =AZ11/('Page 2'!$U$3*27152) -> 0 | BB45: =BB11/('Page 3'!$I$3*27152) -> 0 | BD45: =BD11/('Page 3'!$I$3*27152) -> 0 | BF45: =BF11/('Page 3'!$I$3*27152) -> 0 | BH45: =BH11/('Page 3'!$M$3*27152) -> 0 | BJ45: =BJ11/('Page 3'!$M$3*27152) -> 0 | BL45: =BL11/('Page 3'!$M$3*27152) -> 0 | BN45: =BN11/('Page 3'!$Q$3*27152) -> 0 | BP45: =BP11/('Page 3'!$Q$3*27152) -> 0 | BR45: =BR11/('Page 3'!$Q$3*27152) -> 0 | BT45: =BT11/('Page 3'!$U$3*27152) -> 0 | BV45: =BV11/('Page 3'!$U$3*27152) -> 0 | BX45: =BX11/('Page 3'!$U$3*27152) -> 0 | BZ45: =BZ11/('Page 4'!$I$3*27152) -> 0 | CB45: =CB11/('Page 4'!$I$3*27152) -> 0 | CD45: =CD11/('Page 4'!$I$3*27152) -> 0 | CF45: =CF11/('Page 4'!$M$3*27152) -> 0 | CH45: =CH11/('Page 4'!$M$3*27152) -> 0 | CJ45: =CJ11/('Page 4'!$M$3*27152) -> 0 | CL45: =CL11/('Page 4'!$Q$3*27152) -> 0 | CN45: =CN11/('Page 4'!$Q$3*27152) -> 0 | CP45: =CP11/('Page 4'!$Q$3*27152) -> 0 | CR45: =CR11/('Page 4'!$U$3*27152) -> 0 | CT45: =CT11/('Page 4'!$U$3*27152) -> 0 | CV45: =CV11/('Page 4'!$U$3*27152) -> 0
A46: 9 | F46: =F12/('Page 1'!$I$3*27152) -> 0 | H46: =H12/('Page 1'!$I$3*27152) -> 0 | J46: =J12/('Page 1'!$I$3*27152) -> 0 | L46: =L12/('Page 1'!$M$3*27152) -> 0 | N46: =N12/('Page 1'!$M$3*27152) -> 0 | P46: =P12/('Page 1'!$M$3*27152) -> 0 | R46: =R12/('Page 1'!$Q$3*27152) -> 0 | T46: =T12/('Page 1'!$Q$3*27152) -> 0 | V46: =V12/('Page 1'!$Q$3*27152) -> 0 | X46: =X12/('Page 1'!$U$3*27152) -> 0 | Z46: =Z12/('Page 1'!$U$3*27152) -> 0 | AB46: =AB12/('Page 1'!$U$3*27152) -> 0 | AD46: =AD12/('Page 2'!$I$3*27152) -> 0 | AF46: =AF12/('Page 2'!$I$3*27152) -> 0 | AH46: =AH12/('Page 2'!$I$3*27152) -> 0 | AJ46: =AJ12/('Page 2'!$M$3*27152) -> 0 | AL46: =AL12/('Page 2'!$M$3*27152) -> 0 | AN46: =AN12/('Page 2'!$M$3*27152) -> 0 | AP46: =AP12/('Page 2'!$Q$3*27152) -> 0 | AR46: =AR12/('Page 2'!$Q$3*27152) -> 0 | AT46: =AT12/('Page 2'!$Q$3*27152) -> 0 | AV46: =AV12/('Page 2'!$U$3*27152) -> 0 | AX46: =AX12/('Page 2'!$U$3*27152) -> 0 | AZ46: =AZ12/('Page 2'!$U$3*27152) -> 0 | BB46: =BB12/('Page 3'!$I$3*27152) -> 0 | BD46: =BD12/('Page 3'!$I$3*27152) -> 0 | BF46: =BF12/('Page 3'!$I$3*27152) -> 0 | BH46: =BH12/('Page 3'!$M$3*27152) -> 0 | BJ46: =BJ12/('Page 3'!$M$3*27152) -> 0 | BL46: =BL12/('Page 3'!$M$3*27152) -> 0 | BN46: =BN12/('Page 3'!$Q$3*27152) -> 0 | BP46: =BP12/('Page 3'!$Q$3*27152) -> 0 | BR46: =BR12/('Page 3'!$Q$3*27152) -> 0 | BT46: =BT12/('Page 3'!$U$3*27152) -> 0 | BV46: =BV12/('Page 3'!$U$3*27152) -> 0 | BX46: =BX12/('Page 3'!$U$3*27152) -> 0 | BZ46: =BZ12/('Page 4'!$I$3*27152) -> 0 | CB46: =CB12/('Page 4'!$I$3*27152) -> 0 | CD46: =CD12/('Page 4'!$I$3*27152) -> 0 | CF46: =CF12/('Page 4'!$M$3*27152) -> 0 | CH46: =CH12/('Page 4'!$M$3*27152) -> 0 | CJ46: =CJ12/('Page 4'!$M$3*27152) -> 0 | CL46: =CL12/('Page 4'!$Q$3*27152) -> 0 | CN46: =CN12/('Page 4'!$Q$3*27152) -> 0 | CP46: =CP12/('Page 4'!$Q$3*27152) -> 0 | CR46: =CR12/('Page 4'!$U$3*27152) -> 0 | CT46: =CT12/('Page 4'!$U$3*27152) -> 0 | CV46: =CV12/('Page 4'!$U$3*27152) -> 0
A47: 10 | F47: =F13/('Page 1'!$I$3*27152) -> 0 | H47: =H13/('Page 1'!$I$3*27152) -> 0 | J47: =J13/('Page 1'!$I$3*27152) -> 0 | L47: =L13/('Page 1'!$M$3*27152) -> 0 | N47: =N13/('Page 1'!$M$3*27152) -> 0 | P47: =P13/('Page 1'!$M$3*27152) -> 0 | R47: =R13/('Page 1'!$Q$3*27152) -> 0 | T47: =T13/('Page 1'!$Q$3*27152) -> 0 | V47: =V13/('Page 1'!$Q$3*27152) -> 0 | X47: =X13/('Page 1'!$U$3*27152) -> 0 | Z47: =Z13/('Page 1'!$U$3*27152) -> 0 | AB47: =AB13/('Page 1'!$U$3*27152) -> 0 | AD47: =AD13/('Page 2'!$I$3*27152) -> 0 | AF47: =AF13/('Page 2'!$I$3*27152) -> 0 | AH47: =AH13/('Page 2'!$I$3*27152) -> 0 | AJ47: =AJ13/('Page 2'!$M$3*27152) -> 0 | AL47: =AL13/('Page 2'!$M$3*27152) -> 0 | AN47: =AN13/('Page 2'!$M$3*27152) -> 0 | AP47: =AP13/('Page 2'!$Q$3*27152) -> 0 | AR47: =AR13/('Page 2'!$Q$3*27152) -> 0 | AT47: =AT13/('Page 2'!$Q$3*27152) -> 0 | AV47: =AV13/('Page 2'!$U$3*27152) -> 0 | AX47: =AX13/('Page 2'!$U$3*27152) -> 0 | AZ47: =AZ13/('Page 2'!$U$3*27152) -> 0 | BB47: =BB13/('Page 3'!$I$3*27152) -> 0 | BD47: =BD13/('Page 3'!$I$3*27152) -> 0 | BF47: =BF13/('Page 3'!$I$3*27152) -> 0 | BH47: =BH13/('Page 3'!$M$3*27152) -> 0 | BJ47: =BJ13/('Page 3'!$M$3*27152) -> 0 | BL47: =BL13/('Page 3'!$M$3*27152) -> 0 | BN47: =BN13/('Page 3'!$Q$3*27152) -> 0 | BP47: =BP13/('Page 3'!$Q$3*27152) -> 0 | BR47: =BR13/('Page 3'!$Q$3*27152) -> 0 | BT47: =BT13/('Page 3'!$U$3*27152) -> 0 | BV47: =BV13/('Page 3'!$U$3*27152) -> 0 | BX47: =BX13/('Page 3'!$U$3*27152) -> 0 | BZ47: =BZ13/('Page 4'!$I$3*27152) -> 0 | CB47: =CB13/('Page 4'!$I$3*27152) -> 0 | CD47: =CD13/('Page 4'!$I$3*27152) -> 0 | CF47: =CF13/('Page 4'!$M$3*27152) -> 0 | CH47: =CH13/('Page 4'!$M$3*27152) -> 0 | CJ47: =CJ13/('Page 4'!$M$3*27152) -> 0 | CL47: =CL13/('Page 4'!$Q$3*27152) -> 0 | CN47: =CN13/('Page 4'!$Q$3*27152) -> 0 | CP47: =CP13/('Page 4'!$Q$3*27152) -> 0 | CR47: =CR13/('Page 4'!$U$3*27152) -> 0 | CT47: =CT13/('Page 4'!$U$3*27152) -> 0 | CV47: =CV13/('Page 4'!$U$3*27152) -> 0
A48: 11 | F48: =F14/('Page 1'!$I$3*27152) -> 0 | H48: =H14/('Page 1'!$I$3*27152) -> 0 | J48: =J14/('Page 1'!$I$3*27152) -> 0 | L48: =L14/('Page 1'!$M$3*27152) -> 0 | N48: =N14/('Page 1'!$M$3*27152) -> 0 | P48: =P14/('Page 1'!$M$3*27152) -> 0 | R48: =R14/('Page 1'!$Q$3*27152) -> 0 | T48: =T14/('Page 1'!$Q$3*27152) -> 0 | V48: =V14/('Page 1'!$Q$3*27152) -> 0 | X48: =X14/('Page 1'!$U$3*27152) -> 0 | Z48: =Z14/('Page 1'!$U$3*27152) -> 0 | AB48: =AB14/('Page 1'!$U$3*27152) -> 0 | AD48: =AD14/('Page 2'!$I$3*27152) -> 0 | AF48: =AF14/('Page 2'!$I$3*27152) -> 0 | AH48: =AH14/('Page 2'!$I$3*27152) -> 0 | AJ48: =AJ14/('Page 2'!$M$3*27152) -> 0 | AL48: =AL14/('Page 2'!$M$3*27152) -> 0 | AN48: =AN14/('Page 2'!$M$3*27152) -> 0 | AP48: =AP14/('Page 2'!$Q$3*27152) -> 0 | AR48: =AR14/('Page 2'!$Q$3*27152) -> 0 | AT48: =AT14/('Page 2'!$Q$3*27152) -> 0 | AV48: =AV14/('Page 2'!$U$3*27152) -> 0 | AX48: =AX14/('Page 2'!$U$3*27152) -> 0 | AZ48: =AZ14/('Page 2'!$U$3*27152) -> 0 | BB48: =BB14/('Page 3'!$I$3*27152) -> 0 | BD48: =BD14/('Page 3'!$I$3*27152) -> 0 | BF48: =BF14/('Page 3'!$I$3*27152) -> 0 | BH48: =BH14/('Page 3'!$M$3*27152) -> 0 | BJ48: =BJ14/('Page 3'!$M$3*27152) -> 0 | BL48: =BL14/('Page 3'!$M$3*27152) -> 0 | BN48: =BN14/('Page 3'!$Q$3*27152) -> 0 | BP48: =BP14/('Page 3'!$Q$3*27152) -> 0 | BR48: =BR14/('Page 3'!$Q$3*27152) -> 0 | BT48: =BT14/('Page 3'!$U$3*27152) -> 0 | BV48: =BV14/('Page 3'!$U$3*27152) -> 0 | BX48: =BX14/('Page 3'!$U$3*27152) -> 0 | BZ48: =BZ14/('Page 4'!$I$3*27152) -> 0 | CB48: =CB14/('Page 4'!$I$3*27152) -> 0 | CD48: =CD14/('Page 4'!$I$3*27152) -> 0 | CF48: =CF14/('Page 4'!$M$3*27152) -> 0 | CH48: =CH14/('Page 4'!$M$3*27152) -> 0 | CJ48: =CJ14/('Page 4'!$M$3*27152) -> 0 | CL48: =CL14/('Page 4'!$Q$3*27152) -> 0 | CN48: =CN14/('Page 4'!$Q$3*27152) -> 0 | CP48: =CP14/('Page 4'!$Q$3*27152) -> 0 | CR48: =CR14/('Page 4'!$U$3*27152) -> 0 | CT48: =CT14/('Page 4'!$U$3*27152) -> 0 | CV48: =CV14/('Page 4'!$U$3*27152) -> 0
A49: 12 | F49: =F15/('Page 1'!$I$3*27152) -> 0 | H49: =H15/('Page 1'!$I$3*27152) -> 0 | J49: =J15/('Page 1'!$I$3*27152) -> 0 | L49: =L15/('Page 1'!$M$3*27152) -> 0 | N49: =N15/('Page 1'!$M$3*27152) -> 0 | P49: =P15/('Page 1'!$M$3*27152) -> 0 | R49: =R15/('Page 1'!$Q$3*27152) -> 0 | T49: =T15/('Page 1'!$Q$3*27152) -> 0 | V49: =V15/('Page 1'!$Q$3*27152) -> 0 | X49: =X15/('Page 1'!$U$3*27152) -> 0 | Z49: =Z15/('Page 1'!$U$3*27152) -> 0 | AB49: =AB15/('Page 1'!$U$3*27152) -> 0 | AD49: =AD15/('Page 2'!$I$3*27152) -> 0 | AF49: =AF15/('Page 2'!$I$3*27152) -> 0 | AH49: =AH15/('Page 2'!$I$3*27152) -> 0 | AJ49: =AJ15/('Page 2'!$M$3*27152) -> 0 | AL49: =AL15/('Page 2'!$M$3*27152) -> 0 | AN49: =AN15/('Page 2'!$M$3*27152) -> 0 | AP49: =AP15/('Page 2'!$Q$3*27152) -> 0 | AR49: =AR15/('Page 2'!$Q$3*27152) -> 0 | AT49: =AT15/('Page 2'!$Q$3*27152) -> 0 | AV49: =AV15/('Page 2'!$U$3*27152) -> 0 | AX49: =AX15/('Page 2'!$U$3*27152) -> 0 | AZ49: =AZ15/('Page 2'!$U$3*27152) -> 0 | BB49: =BB15/('Page 3'!$I$3*27152) -> 0 | BD49: =BD15/('Page 3'!$I$3*27152) -> 0 | BF49: =BF15/('Page 3'!$I$3*27152) -> 0 | BH49: =BH15/('Page 3'!$M$3*27152) -> 0 | BJ49: =BJ15/('Page 3'!$M$3*27152) -> 0 | BL49: =BL15/('Page 3'!$M$3*27152) -> 0 | BN49: =BN15/('Page 3'!$Q$3*27152) -> 0 | BP49: =BP15/('Page 3'!$Q$3*27152) -> 0 | BR49: =BR15/('Page 3'!$Q$3*27152) -> 0 | BT49: =BT15/('Page 3'!$U$3*27152) -> 0 | BV49: =BV15/('Page 3'!$U$3*27152) -> 0 | BX49: =BX15/('Page 3'!$U$3*27152) -> 0 | BZ49: =BZ15/('Page 4'!$I$3*27152) -> 0 | CB49: =CB15/('Page 4'!$I$3*27152) -> 0 | CD49: =CD15/('Page 4'!$I$3*27152) -> 0 | CF49: =CF15/('Page 4'!$M$3*27152) -> 0 | CH49: =CH15/('Page 4'!$M$3*27152) -> 0 | CJ49: =CJ15/('Page 4'!$M$3*27152) -> 0 | CL49: =CL15/('Page 4'!$Q$3*27152) -> 0 | CN49: =CN15/('Page 4'!$Q$3*27152) -> 0 | CP49: =CP15/('Page 4'!$Q$3*27152) -> 0 | CR49: =CR15/('Page 4'!$U$3*27152) -> 0 | CT49: =CT15/('Page 4'!$U$3*27152) -> 0 | CV49: =CV15/('Page 4'!$U$3*27152) -> 0
... A68: 31 | F68: =F34/('Page 1'!$I$3*27152) -> 0 | H68: =H34/('Page 1'!$I$3*27152) -> 0 | J68: =J34/('Page 1'!$I$3*27152) -> 0 | L68: =L34/('Page 1'!$M$3*27152) -> 0 | N68: =N34/('Page 1'!$M$3*27152) -> 0 | P68: =P34/('Page 1'!$M$3*27152) -> 0 | R68: =R34/('Page 1'!$Q$3*27152) -> 0 | T68: =T34/('Page 1'!$Q$3*27152) -> 0 | V68: =V34/('Page 1'!$Q$3*27152) -> 0 | X68: =X34/('Page 1'!$U$3*27152) -> 0 | Z68: =Z34/('Page 1'!$U$3*27152) -> 0 | AB68: =AB34/('Page 1'!$U$3*27152) -> 0 | AD68: =AD34/('Page 2'!$I$3*27152) -> 0 | AF68: =AF34/('Page 2'!$I$3*27152) -> 0 | AH68: =AH34/('Page 2'!$I$3*27152) -> 0 | AJ68: =AJ34/('Page 2'!$M$3*27152) -> 0 | AL68: =AL34/('Page 2'!$M$3*27152) -> 0 | AN68: =AN34/('Page 2'!$M$3*27152) -> 0 | AP68: =AP34/('Page 2'!$Q$3*27152) -> 0 | AR68: =AR34/('Page 2'!$Q$3*27152) -> 0 | AT68: =AT34/('Page 2'!$Q$3*27152) -> 0 | AV68: =AV34/('Page 2'!$U$3*27152) -> 0 | AX68: =AX34/('Page 2'!$U$3*27152) -> 0 | AZ68: =AZ34/('Page 2'!$U$3*27152) -> 0 | BB68: =BB34/('Page 3'!$I$3*27152) -> 0 | BD68: =BD34/('Page 3'!$I$3*27152) -> 0 | BF68: =BF34/('Page 3'!$I$3*27152) -> 0 | BH68: =BH34/('Page 3'!$M$3*27152) -> 0 | BJ68: =BJ34/('Page 3'!$M$3*27152) -> 0 | BL68: =BL34/('Page 3'!$M$3*27152) -> 0 | BN68: =BN34/('Page 3'!$Q$3*27152) -> 0 | BP68: =BP34/('Page 3'!$Q$3*27152) -> 0 | BR68: =BR34/('Page 3'!$Q$3*27152) -> 0 | BT68: =BT34/('Page 3'!$U$3*27152) -> 0 | BV68: =BV34/('Page 3'!$U$3*27152) -> 0 | BX68: =BX34/('Page 3'!$U$3*27152) -> 0 | BZ68: =BZ34/('Page 4'!$I$3*27152) -> 0 | CB68: =CB34/('Page 4'!$I$3*27152) -> 0 | CD68: =CD34/('Page 4'!$I$3*27152) -> 0 | CF68: =CF34/('Page 4'!$M$3*27152) -> 0 | CH68: =CH34/('Page 4'!$M$3*27152) -> 0 | CJ68: =CJ34/('Page 4'!$M$3*27152) -> 0 | CL68: =CL34/('Page 4'!$Q$3*27152) -> 0 | CN68: =CN34/('Page 4'!$Q$3*27152) -> 0 | CP68: =CP34/('Page 4'!$Q$3*27152) -> 0 | CR68: =CR34/('Page 4'!$U$3*27152) -> 0 | CT68: =CT34/('Page 4'!$U$3*27152) -> 0 | CV68: =CV34/('Page 4'!$U$3*27152) -> 0

Sheet Page 1
A1: Permit No.: | D1: WQ0017824 | G1: Facility Name: | I1: Uwharrie Middle School | O1: County: | P1: Randolph | R1: Month: | S1: January | U1: Year: | V1: 2014
A2: Did irrigation occur at this facility? | G2: Field Name: | I2: 1 | K2: Field Name: | M2: 2 | O2: Field Name: | Q2: 3 | S2: Field Name: | U2: 4
G3: Area (acres): | I3: 0.51 | K3: Area (acres): | M3: 0.529 | O3: Area (acres): | Q3: 0.207 | S3: Area (acres): | U3: 0.187
G4: Cover Crop: | I4: Hardwood Forest | K4: Cover Crop: | M4: Hardwood Forest | O4: Cover Crop: | Q4: Hardwood Forest | S4: Cover Crop: | U4: Hardwood Forest
G5: Hourly Rate (in): | I5: 0.25 | K5: Hourly Rate (in): | M5: 0.25 | O5: Hourly Rate (in): | Q5: 0.25 | S5: Hourly Rate (in): | U5: 0.25
G6: Annual Rate (in): | I6: 39 | K6: Annual Rate (in): | M6: 39 | O6: Annual Rate (in): | Q6: 39 | S6: Annual Rate (in): | U6: 39
A7: Day | B7: Weather | E7: Freeboard | G7: Field Irrigated? | K7: Field Irrigated? | O7: Field Irrigated? | S7: Field Irrigated?
B8: Weather Code | C8: Temperature | D8: Precipitation | E8: Storage | F8: 5-Day Upset (if applicable) | G8: Total Volume Applied | H8: Total Time Irrigated | I8: Daily Loading | J8: Maximum Hourly Loading | K8: Total Volume Applied | L8: Total Time Irrigated | M8: Daily Loading | N8: Maximum Hourly Loading | O8: Total Volume Applied | P8: Total Time Irrigated | Q8: Daily Loading | R8: Maximum Hourly Loading | S8: Total Volume Applied | T8: Total Time Irrigated | U8: Daily Loading | V8: Maximum Hourly Loading
C9: ºF | D9: in | E9: ft | F9: ft | G9: gal | H9: min | I9: in | J9: in | K9: gal | L9: min | M9: in | N9: in | O9: gal | P9: min | Q9: in | R9: in | S9: gal | T9: min | U9: in | V9: in
A10: 1 | B10: =IF(ISBLANK('Enter Data Here'!B4), " ", 'Enter Data Here'!B4) | C10: =IF(ISBLANK('Enter Data Here'!C4), " ", 'Enter Data Here'!C4) | D10: =IF(ISBLANK('Enter Data Here'!D4), " ", 'Enter Data Here'!D4) | E10: =IF(ISBLANK('Enter Data Here'!E4), " ", 'Enter Data Here'!E4) | G10: ='Enter Data Here'!F4+'Enter Data Here'!H4+'Enter Data Here'!J4 -> 0 | H10: ='Enter Data Here'!G4+'Enter Data Here'!I4+'Enter Data Here'!K4 -> 0 | I10: =IF((ISBLANK($G10))," ", ($G10)/($I$3*27152)) -> 0 | J10: =MAX('Enter Data Here'!F38:J38) -> 0 | K10: ='Enter Data Here'!L4+'Enter Data Here'!N4+'Enter Data Here'!P4 -> 0 | L10: ='Enter Data Here'!M4+'Enter Data Here'!O4+'Enter Data Here'!Q4 -> 0 | M10: =IF((ISBLANK($K10))," ",($K10)/($M$3*27152)) -> 0 | N10: =MAX('Enter Data Here'!L38:P38) -> 0 | O10: ='Enter Data Here'!R4+'Enter Data Here'!T4+'Enter Data Here'!V4 -> 0 | P10: ='Enter Data Here'!S4+'Enter Data Here'!U4+'Enter Data Here'!W4 -> 0 | Q10: =IF((ISBLANK($O10))," ",($O10)/($Q$3*27152)) -> 0 | R10: =MAX('Enter Data Here'!R38:V38) -> 0 | S10: ='Enter Data Here'!X4+'Enter Data Here'!Z4+'Enter Data Here'!AB4 -> 0 | T10: ='Enter Data Here'!Y4+'Enter Data Here'!AA4+'Enter Data Here'!AC4 -> 0 | U10: =IF((ISBLANK($S10))," ",($S10)/($U$3*27152)) -> 0 | V10: =MAX('Enter Data Here'!X38:AB38) -> 0
A11: 2 | B11: =IF(ISBLANK('Enter Data Here'!B5), " ", 'Enter Data Here'!B5) | C11: =IF(ISBLANK('Enter Data Here'!C5), " ", 'Enter Data Here'!C5) | D11: =IF(ISBLANK('Enter Data Here'!D5), " ", 'Enter Data Here'!D5) | E11: =IF(ISBLANK('Enter Data Here'!E5), " ", 'Enter Data Here'!E5) | G11: ='Enter Data Here'!F5+'Enter Data Here'!H5+'Enter Data Here'!J5 -> 0 | H11: ='Enter Data Here'!G5+'Enter Data Here'!I5+'Enter Data Here'!K5 -> 0 | I11: =IF((ISBLANK($G11))," ", ($G11)/($I$3*27152)) -> 0 | J11: =MAX('Enter Data Here'!F39:J39) -> 0 | K11: ='Enter Data Here'!L5+'Enter Data Here'!N5+'Enter Data Here'!P5 -> 0 | L11: ='Enter Data Here'!M5+'Enter Data Here'!O5+'Enter Data Here'!Q5 -> 0 | M11: =IF((ISBLANK($K11))," ",($K11)/($M$3*27152)) -> 0 | N11: =MAX('Enter Data Here'!L39:P39) -> 0 | O11: ='Enter Data Here'!R5+'Enter Data Here'!T5+'Enter Data Here'!V5 -> 0 | P11: ='Enter Data Here'!S5+'Enter Data Here'!U5+'Enter Data Here'!W5 -> 0 | Q11: =IF((ISBLANK($O11))," ",($O11)/($Q$3*27152)) -> 0 | R11: =MAX('Enter Data Here'!R39:V39) -> 0 | S11: ='Enter Data Here'!X5+'Enter Data Here'!Z5+'Enter Data Here'!AB5 -> 0 | T11: ='Enter Data Here'!Y5+'Enter Data Here'!AA5+'Enter Data Here'!AC5 -> 0 | U11: =IF((ISBLANK($S11))," ",($S11)/($U$3*27152)) -> 0 | V11: =MAX('Enter Data Here'!X39:AB39) -> 0
A12: 3 | B12: =IF(ISBLANK('Enter Data Here'!B6), " ", 'Enter Data Here'!B6) | C12: =IF(ISBLANK('Enter Data Here'!C6), " ", 'Enter Data Here'!C6) | D12: =IF(ISBLANK('Enter Data Here'!D6), " ", 'Enter Data Here'!D6) | E12: =IF(ISBLANK('Enter Data Here'!E6), " ", 'Enter Data Here'!E6) | G12: ='Enter Data Here'!F6+'Enter Data Here'!H6+'Enter Data Here'!J6 -> 0 | H12: ='Enter Data Here'!G6+'Enter Data Here'!I6+'Enter Data Here'!K6 -> 0 | I12: =IF((ISBLANK($G12))," ", ($G12)/($I$3*27152)) -> 0 | J12: =MAX('Enter Data Here'!F40:J40) -> 0 | K12: ='Enter Data Here'!L6+'Enter Data Here'!N6+'Enter Data Here'!P6 -> 0 | L12: ='Enter Data Here'!M6+'Enter Data Here'!O6+'Enter Data Here'!Q6 -> 0 | M12: =IF((ISBLANK($K12))," ",($K12)/($M$3*27152)) -> 0 | N12: =MAX('Enter Data Here'!L40:P40) -> 0 | O12: ='Enter Data Here'!R6+'Enter Data Here'!T6+'Enter Data Here'!V6 -> 0 | P12: ='Enter Data Here'!S6+'Enter Data Here'!U6+'Enter Data Here'!W6 -> 0 | Q12: =IF((ISBLANK($O12))," ",($O12)/($Q$3*27152)) -> 0 | R12: =MAX('Enter Data Here'!R40:V40) -> 0 | S12: ='Enter Data Here'!X6+'Enter Data Here'!Z6+'Enter Data Here'!AB6 -> 0 | T12: ='Enter Data Here'!Y6+'Enter Data Here'!AA6+'Enter Data Here'!AC6 -> 0 | U12: =IF((ISBLANK($S12))," ",($S12)/($U$3*27152)) -> 0 | V12: =MAX('Enter Data Here'!X40:AB40) -> 0
A13: 4 | B13: =IF(ISBLANK('Enter Data Here'!B7), " ", 'Enter Data Here'!B7) | C13: =IF(ISBLANK('Enter Data Here'!C7), " ", 'Enter Data Here'!C7) | D13: =IF(ISBLANK('Enter Data Here'!D7), " ", 'Enter Data Here'!D7) | E13: =IF(ISBLANK('Enter Data Here'!E7), " ", 'Enter Data Here'!E7) | G13: ='Enter Data Here'!F7+'Enter Data Here'!H7+'Enter Data Here'!J7 -> 0 | H13: ='Enter Data Here'!G7+'Enter Data Here'!I7+'Enter Data Here'!K7 -> 0 | I13: =IF((ISBLANK($G13))," ", ($G13)/($I$3*27152)) -> 0 | J13: =MAX('Enter Data Here'!F41:J41) -> 0 | K13: ='Enter Data Here'!L7+'Enter Data Here'!N7+'Enter Data Here'!P7 -> 0 | L13: ='Enter Data Here'!M7+'Enter Data Here'!O7+'Enter Data Here'!Q7 -> 0 | M13: =IF((ISBLANK($K13))," ",($K13)/($M$3*27152)) -> 0 | N13: =MAX('Enter Data Here'!L41:P41) -> 0 | O13: ='Enter Data Here'!R7+'Enter Data Here'!T7+'Enter Data Here'!V7 -> 0 | P13: ='Enter Data Here'!S7+'Enter Data Here'!U7+'Enter Data Here'!W7 -> 0 | Q13: =IF((ISBLANK($O13))," ",($O13)/($Q$3*27152)) -> 0 | R13: =MAX('Enter Data Here'!R41:V41) -> 0 | S13: ='Enter Data Here'!X7+'Enter Data Here'!Z7+'Enter Data Here'!AB7 -> 0 | T13: ='Enter Data Here'!Y7+'Enter Data Here'!AA7+'Enter Data Here'!AC7 -> 0 | U13: =IF((ISBLANK($S13))," ",($S13)/($U$3*27152)) -> 0 | V13: =MAX('Enter Data Here'!X41:AB41) -> 0
A14: 5 | B14: =IF(ISBLANK('Enter Data Here'!B8), " ", 'Enter Data Here'!B8) | C14: =IF(ISBLANK('Enter Data Here'!C8), " ", 'Enter Data Here'!C8) | D14: =IF(ISBLANK('Enter Data Here'!D8), " ", 'Enter Data Here'!D8) | E14: =IF(ISBLANK('Enter Data Here'!E8), " ", 'Enter Data Here'!E8) | G14: ='Enter Data Here'!F8+'Enter Data Here'!H8+'Enter Data Here'!J8 -> 0 | H14: ='Enter Data Here'!G8+'Enter Data Here'!I8+'Enter Data Here'!K8 -> 0 | I14: =IF((ISBLANK($G14))," ", ($G14)/($I$3*27152)) -> 0 | J14: =MAX('Enter Data Here'!F42:J42) -> 0 | K14: ='Enter Data Here'!L8+'Enter Data Here'!N8+'Enter Data Here'!P8 -> 0 | L14: ='Enter Data Here'!M8+'Enter Data Here'!O8+'Enter Data Here'!Q8 -> 0 | M14: =IF((ISBLANK($K14))," ",($K14)/($M$3*27152)) -> 0 | N14: =MAX('Enter Data Here'!L42:P42) -> 0 | O14: ='Enter Data Here'!R8+'Enter Data Here'!T8+'Enter Data Here'!V8 -> 0 | P14: ='Enter Data Here'!S8+'Enter Data Here'!U8+'Enter Data Here'!W8 -> 0 | Q14: =IF((ISBLANK($O14))," ",($O14)/($Q$3*27152)) -> 0 | R14: =MAX('Enter Data Here'!R42:V42) -> 0 | S14: ='Enter Data Here'!X8+'Enter Data Here'!Z8+'Enter Data Here'!AB8 -> 0 | T14: ='Enter Data Here'!Y8+'Enter Data Here'!AA8+'Enter Data Here'!AC8 -> 0 | U14: =IF((ISBLANK($S14))," ",($S14)/($U$3*27152)) -> 0 | V14: =MAX('Enter Data Here'!X42:AB42) -> 0
A15: 6 | B15: =IF(ISBLANK('Enter Data Here'!B9), " ", 'Enter Data Here'!B9) | C15: =IF(ISBLANK('Enter Data Here'!C9), " ", 'Enter Data Here'!C9) | D15: =IF(ISBLANK('Enter Data Here'!D9), " ", 'Enter Data Here'!D9) | E15: =IF(ISBLANK('Enter Data Here'!E9), " ", 'Enter Data Here'!E9) | G15: ='Enter Data Here'!F9+'Enter Data Here'!H9+'Enter Data Here'!J9 -> 0 | H15: ='Enter Data Here'!G9+'Enter Data Here'!I9+'Enter Data Here'!K9 -> 0 | I15: =IF((ISBLANK($G15))," ", ($G15)/($I$3*27152)) -> 0 | J15: =MAX('Enter Data Here'!F43:J43) -> 0 | K15: ='Enter Data Here'!L9+'Enter Data Here'!N9+'Enter Data Here'!P9 -> 0 | L15: ='Enter Data Here'!M9+'Enter Data Here'!O9+'Enter Data Here'!Q9 -> 0 | M15: =IF((ISBLANK($K15))," ",($K15)/($M$3*27152)) -> 0 | N15: =MAX('Enter Data Here'!L43:P43) -> 0 | O15: ='Enter Data Here'!R9+'Enter Data Here'!T9+'Enter Data Here'!V9 -> 0 | P15: ='Enter Data Here'!S9+'Enter Data Here'!U9+'Enter Data Here'!W9 -> 0 | Q15: =IF((ISBLANK($O15))," ",($O15)/($Q$3*27152)) -> 0 | R15: =MAX('Enter Data Here'!R43:V43) -> 0 | S15: ='Enter Data Here'!X9+'Enter Data Here'!Z9+'Enter Data Here'!AB9 -> 0 | T15: ='Enter Data Here'!Y9+'Enter Data Here'!AA9+'Enter Data Here'!AC9 -> 0 | U15: =IF((ISBLANK($S15))," ",($S15)/($U$3*27152)) -> 0 | V15: =MAX('Enter Data Here'!X43:AB43) -> 0
A16: 7 | B16: =IF(ISBLANK('Enter Data Here'!B10), " ", 'Enter Data Here'!B10) | C16: =IF(ISBLANK('Enter Data Here'!C10), " ", 'Enter Data Here'!C10) | D16: =IF(ISBLANK('Enter Data Here'!D10), " ", 'Enter Data Here'!D10) | E16: =IF(ISBLANK('Enter Data Here'!E10), " ", 'Enter Data Here'!E10) | G16: ='Enter Data Here'!F10+'Enter Data Here'!H10+'Enter Data Here'!J10 -> 0 | H16: ='Enter Data Here'!G10+'Enter Data Here'!I10+'Enter Data Here'!K10 -> 0 | I16: =IF((ISBLANK($G16))," ", ($G16)/($I$3*27152)) -> 0 | J16: =MAX('Enter Data Here'!F44:J44) -> 0 | K16: ='Enter Data Here'!L10+'Enter Data Here'!N10+'Enter Data Here'!P10 -> 0 | L16: ='Enter Data Here'!M10+'Enter Data Here'!O10+'Enter Data Here'!Q10 -> 0 | M16: =IF((ISBLANK($K16))," ",($K16)/($M$3*27152)) -> 0 | N16: =MAX('Enter Data Here'!L44:P44) -> 0 | O16: ='Enter Data Here'!R10+'Enter Data Here'!T10+'Enter Data Here'!V10 -> 0 | P16: ='Enter Data Here'!S10+'Enter Data Here'!U10+'Enter Data Here'!W10 -> 0 | Q16: =IF((ISBLANK($O16))," ",($O16)/($Q$3*27152)) -> 0 | R16: =MAX('Enter Data Here'!R44:V44) -> 0 | S16: ='Enter Data Here'!X10+'Enter Data Here'!Z10+'Enter Data Here'!AB10 -> 0 | T16: ='Enter Data Here'!Y10+'Enter Data Here'!AA10+'Enter Data Here'!AC10 -> 0 | U16: =IF((ISBLANK($S16))," ",($S16)/($U$3*27152)) -> 0 | V16: =MAX('Enter Data Here'!X44:AB44) -> 0
A17: 8 | B17: =IF(ISBLANK('Enter Data Here'!B11), " ", 'Enter Data Here'!B11) | C17: =IF(ISBLANK('Enter Data Here'!C11), " ", 'Enter Data Here'!C11) | D17: =IF(ISBLANK('Enter Data Here'!D11), " ", 'Enter Data Here'!D11) | E17: =IF(ISBLANK('Enter Data Here'!E11), " ", 'Enter Data Here'!E11) | G17: ='Enter Data Here'!F11+'Enter Data Here'!H11+'Enter Data Here'!J11 -> 0 | H17: ='Enter Data Here'!G11+'Enter Data Here'!I11+'Enter Data Here'!K11 -> 0 | I17: =IF((ISBLANK($G17))," ", ($G17)/($I$3*27152)) -> 0 | J17: =MAX('Enter Data Here'!F45:J45) -> 0 | K17: ='Enter Data Here'!L11+'Enter Data Here'!N11+'Enter Data Here'!P11 -> 0 | L17: ='Enter Data Here'!M11+'Enter Data Here'!O11+'Enter Data Here'!Q11 -> 0 | M17: =IF((ISBLANK($K17))," ",($K17)/($M$3*27152)) -> 0 | N17: =MAX('Enter Data Here'!L45:P45) -> 0 | O17: ='Enter Data Here'!R11+'Enter Data Here'!T11+'Enter Data Here'!V11 -> 0 | P17: ='Enter Data Here'!S11+'Enter Data Here'!U11+'Enter Data Here'!W11 -> 0 | Q17: =IF((ISBLANK($O17))," ",($O17)/($Q$3*27152)) -> 0 | R17: =MAX('Enter Data Here'!R45:V45) -> 0 | S17: ='Enter Data Here'!X11+'Enter Data Here'!Z11+'Enter Data Here'!AB11 -> 0 | T17: ='Enter Data Here'!Y11+'Enter Data Here'!AA11+'Enter Data Here'!AC11 -> 0 | U17: =IF((ISBLANK($S17))," ",($S17)/($U$3*27152)) -> 0 | V17: =MAX('Enter Data Here'!X45:AB45) -> 0
A18: 9 | B18: =IF(ISBLANK('Enter Data Here'!B12), " ", 'Enter Data Here'!B12) | C18: =IF(ISBLANK('Enter Data Here'!C12), " ", 'Enter Data Here'!C12) | D18: =IF(ISBLANK('Enter Data Here'!D12), " ", 'Enter Data Here'!D12) | E18: =IF(ISBLANK('Enter Data Here'!E12), " ", 'Enter Data Here'!E12) | G18: ='Enter Data Here'!F12+'Enter Data Here'!H12+'Enter Data Here'!J12 -> 0 | H18: ='Enter Data Here'!G12+'Enter Data Here'!I12+'Enter Data Here'!K12 -> 0 | I18: =IF((ISBLANK($G18))," ", ($G18)/($I$3*27152)) -> 0 | J18: =MAX('Enter Data Here'!F46:J46) -> 0 | K18: ='Enter Data Here'!L12+'Enter Data Here'!N12+'Enter Data Here'!P12 -> 0 | L18: ='Enter Data Here'!M12+'Enter Data Here'!O12+'Enter Data Here'!Q12 -> 0 | M18: =IF((ISBLANK($K18))," ",($K18)/($M$3*27152)) -> 0 | N18: =MAX('Enter Data Here'!L46:P46) -> 0 | O18: ='Enter Data Here'!R12+'Enter Data Here'!T12+'Enter Data Here'!V12 -> 0 | P18: ='Enter Data Here'!S12+'Enter Data Here'!U12+'Enter Data Here'!W12 -> 0 | Q18: =IF((ISBLANK($O18))," ",($O18)/($Q$3*27152)) -> 0 | R18: =MAX('Enter Data Here'!R46:V46) -> 0 | S18: ='Enter Data Here'!X12+'Enter Data Here'!Z12+'Enter Data Here'!AB12 -> 0 | T18: ='Enter Data Here'!Y12+'Enter Data Here'!AA12+'Enter Data Here'!AC12 -> 0 | U18: =IF((ISBLANK($S18))," ",($S18)/($U$3*27152)) -> 0 | V18: =MAX('Enter Data Here'!X46:AB46) -> 0
A19: 10 | B19: =IF(ISBLANK('Enter Data Here'!B13), " ", 'Enter Data Here'!B13) | C19: =IF(ISBLANK('Enter Data Here'!C13), " ", 'Enter Data Here'!C13) | D19: =IF(ISBLANK('Enter Data Here'!D13), " ", 'Enter Data Here'!D13) | E19: =IF(ISBLANK('Enter Data Here'!E13), " ", 'Enter Data Here'!E13) | G19: ='Enter Data Here'!F13+'Enter Data Here'!H13+'Enter Data Here'!J13 -> 0 | H19: ='Enter Data Here'!G13+'Enter Data Here'!I13+'Enter Data Here'!K13 -> 0 | I19: =IF((ISBLANK($G19))," ", ($G19)/($I$3*27152)) -> 0 | J19: =MAX('Enter Data Here'!F47:J47) -> 0 | K19: ='Enter Data Here'!L13+'Enter Data Here'!N13+'Enter Data Here'!P13 -> 0 | L19: ='Enter Data Here'!M13+'Enter Data Here'!O13+'Enter Data Here'!Q13 -> 0 | M19: =IF((ISBLANK($K19))," ",($K19)/($M$3*27152)) -> 0 | N19: =MAX('Enter Data Here'!L47:P47) -> 0 | O19: ='Enter Data Here'!R13+'Enter Data Here'!T13+'Enter Data Here'!V13 -> 0 | P19: ='Enter Data Here'!S13+'Enter Data Here'!U13+'Enter Data Here'!W13 -> 0 | Q19: =IF((ISBLANK($O19))," ",($O19)/($Q$3*27152)) -> 0 | R19: =MAX('Enter Data Here'!R47:V47) -> 0 | S19: ='Enter Data Here'!X13+'Enter Data Here'!Z13+'Enter Data Here'!AB13 -> 0 | T19: ='Enter Data Here'!Y13+'Enter Data Here'!AA13+'Enter Data Here'!AC13 -> 0 | U19: =IF((ISBLANK($S19))," ",($S19)/($U$3*27152)) -> 0 | V19: =MAX('Enter Data Here'!X47:AB47) -> 0
A20: 11 | B20: =IF(ISBLANK('Enter Data Here'!B14), " ", 'Enter Data Here'!B14) | C20: =IF(ISBLANK('Enter Data Here'!C14), " ", 'Enter Data Here'!C14) | D20: =IF(ISBLANK('Enter Data Here'!D14), " ", 'Enter Data Here'!D14) | E20: =IF(ISBLANK('Enter Data Here'!E14), " ", 'Enter Data Here'!E14) | G20: ='Enter Data Here'!F14+'Enter Data Here'!H14+'Enter Data Here'!J14 -> 0 | H20: ='Enter Data Here'!G14+'Enter Data Here'!I14+'Enter Data Here'!K14 -> 0 | I20: =IF((ISBLANK($G20))," ", ($G20)/($I$3*27152)) -> 0 | J20: =MAX('Enter Data Here'!F48:J48) -> 0 | K20: ='Enter Data Here'!L14+'Enter Data Here'!N14+'Enter Data Here'!P14 -> 0 | L20: ='Enter Data Here'!M14+'Enter Data Here'!O14+'Enter Data Here'!Q14 -> 0 | M20: =IF((ISBLANK($K20))," ",($K20)/($M$3*27152)) -> 0 | N20: =MAX('Enter Data Here'!L48:P48) -> 0 | O20: ='Enter Data Here'!R14+'Enter Data Here'!T14+'Enter Data Here'!V14 -> 0 | P20: ='Enter Data Here'!S14+'Enter Data Here'!U14+'Enter Data Here'!W14 -> 0 | Q20: =IF((ISBLANK($O20))," ",($O20)/($Q$3*27152)) -> 0 | R20: =MAX('Enter Data Here'!R48:V48) -> 0 | S20: ='Enter Data Here'!X14+'Enter Data Here'!Z14+'Enter Data Here'!AB14 -> 0 | T20: ='Enter Data Here'!Y14+'Enter Data Here'!AA14+'Enter Data Here'!AC14 -> 0 | U20: =IF((ISBLANK($S20))," ",($S20)/($U$3*27152)) -> 0 | V20: =MAX('Enter Data Here'!X48:AB48) -> 0
A21: 12 | B21: =IF(ISBLANK('Enter Data Here'!B15), " ", 'Enter Data Here'!B15) | C21: =IF(ISBLANK('Enter Data Here'!C15), " ", 'Enter Data Here'!C15) | D21: =IF(ISBLANK('Enter Data Here'!D15), " ", 'Enter Data Here'!D15) | E21: =IF(ISBLANK('Enter Data Here'!E15), " ", 'Enter Data Here'!E15) | G21: ='Enter Data Here'!F15+'Enter Data Here'!H15+'Enter Data Here'!J15 -> 0 | H21: ='Enter Data Here'!G15+'Enter Data Here'!I15+'Enter Data Here'!K15 -> 0 | I21: =IF((ISBLANK($G21))," ", ($G21)/($I$3*27152)) -> 0 | J21: =MAX('Enter Data Here'!F49:J49) -> 0 | K21: ='Enter Data Here'!L15+'Enter Data Here'!N15+'Enter Data Here'!P15 -> 0 | L21: ='Enter Data Here'!M15+'Enter Data Here'!O15+'Enter Data Here'!Q15 -> 0 | M21: =IF((ISBLANK($K21))," ",($K21)/($M$3*27152)) -> 0 | N21: =MAX('Enter Data Here'!L49:P49) -> 0 | O21: ='Enter Data Here'!R15+'Enter Data Here'!T15+'Enter Data Here'!V15 -> 0 | P21: ='Enter Data Here'!S15+'Enter Data Here'!U15+'Enter Data Here'!W15 -> 0 | Q21: =IF((ISBLANK($O21))," ",($O21)/($Q$3*27152)) -> 0 | R21: =MAX('Enter Data Here'!R49:V49) -> 0 | S21: ='Enter Data Here'!X15+'Enter Data Here'!Z15+'Enter Data Here'!AB15 -> 0 | T21: ='Enter Data Here'!Y15+'Enter Data Here'!AA15+'Enter Data Here'!AC15 -> 0 | U21: =IF((ISBLANK($S21))," ",($S21)/($U$3*27152)) -> 0 | V21: =MAX('Enter Data Here'!X49:AB49) -> 0
... A40: 31 | B40: =IF(ISBLANK('Enter Data Here'!B34), " ", 'Enter Data Here'!B34) | C40: =IF(ISBLANK('Enter Data Here'!C34), " ", 'Enter Data Here'!C34) | D40: =IF(ISBLANK('Enter Data Here'!D34), " ", 'Enter Data Here'!D34) | E40: =IF(ISBLANK('Enter Data Here'!E34), " ", 'Enter Data Here'!E34) | G40: ='Enter Data Here'!F34+'Enter Data Here'!H34+'Enter Data Here'!J34 -> 0 | H40: ='Enter Data Here'!G34+'Enter Data Here'!I34+'Enter Data Here'!K34 -> 0 | I40: =IF((ISBLANK($G40))," ", ($G40)/($I$3*27152)) -> 0 | J40: =MAX('Enter Data Here'!F68:J68) -> 0 | K40: ='Enter Data Here'!L34+'Enter Data Here'!N34+'Enter Data Here'!P34 -> 0 | L40: ='Enter Data Here'!M34+'Enter Data Here'!O34+'Enter Data Here'!Q34 -> 0 | M40: =IF((ISBLANK($K40))," ",($K40)/($M$3*27152)) -> 0 | N40: =MAX('Enter Data Here'!L68:P68) -> 0 | O40: ='Enter Data Here'!R34+'Enter Data Here'!T34+'Enter Data Here'!V34 -> 0 | P40: ='Enter Data Here'!S34+'Enter Data Here'!U34+'Enter Data Here'!W34 -> 0 | Q40: =IF((ISBLANK($O40))," ",($O40)/($Q$3*27152)) -> 0 | R40: =MAX('Enter Data Here'!R68:V68) -> 0 | S40: ='Enter Data Here'!X34+'Enter Data Here'!Z34+'Enter Data Here'!AB34 -> 0 | T40: ='Enter Data Here'!Y34+'Enter Data Here'!AA34+'Enter Data Here'!AC34 -> 0 | U40: =IF((ISBLANK($S40))," ",($S40)/($U$3*27152)) -> 0 | V40: =MAX('Enter Data Here'!X68:AB68) -> 0
A41: Monthly Loading: | G41: =IF(ISBLANK($S1)," ",SUM(G10:G40)) -> 0 | I41: =IF(ISBLANK($S1)," ",SUM(I10:I40)) -> 0 | K41: =IF(ISBLANK($S1)," ",SUM(K10:K40)) -> 0 | M41: =IF(ISBLANK($S1)," ",SUM(M10:M40)) -> 0 | O41: =IF(ISBLANK($S1)," ",SUM(O10:O40)) -> 0 | Q41: =IF(ISBLANK($S1)," ",SUM(Q10:Q40)) -> 0 | S41: =IF(ISBLANK($S1)," ",SUM(S10:S40)) -> 0 | U41: =IF(ISBLANK($S1)," ",SUM(U10:U40)) -> 0
A42: 12 Month Floating Total (in):

Sheet Page 2
A1: Permit No.: | D1: WQ0017824 | G1: Facility Name: | I1: Uwharrie Middle School | O1: County: | P1: Randolph | R1: Month: | S1: January | U1: Year: | V1: 2014
A2: Did irrigation occur at this facility? | G2: Field Name: | I2: 5 | K2: Field Name: | M2: 6 | O2: Field Name: | Q2: 7 | S2: Field Name: | U2: 8
G3: Area (acres): | I3: 0.338 | K3: Area (acres): | M3: 0.327 | O3: Area (acres): | Q3: 0.338 | S3: Area (acres): | U3: 0.413
G4: Cover Crop: | I4: Hardwood Forest | K4: Cover Crop: | M4: Hardwood Forest | O4: Cover Crop: | Q4: Hardwood Forest | S4: Cover Crop: | U4: Hardwood Forest
G5: Hourly Rate (in): | I5: 0.25 | K5: Hourly Rate (in): | M5: 0.25 | O5: Hourly Rate (in): | Q5: 0.25 | S5: Hourly Rate (in): | U5: 0.25
G6: Annual Rate (in): | I6: 39 | K6: Annual Rate (in): | M6: 39 | O6: Annual Rate (in): | Q6: 39 | S6: Annual Rate (in): | U6: 39
A7: Day | B7: Weather | E7: Freeboard | G7: Field Irrigated? | K7: Field Irrigated? | O7: Field Irrigated? | S7: Field Irrigated?
B8: Weather Code | C8: Temperature | D8: Precipitation | E8: Storage | F8: 5-Day Upset (if applicable) | G8: Total Volume Applied | H8: Total Time Irrigated | I8: Daily Loading | J8: Maximum Hourly Loading | K8: Total Volume Applied | L8: Total Time Irrigated | M8: Daily Loading | N8: Maximum Hourly Loading | O8: Total Volume Applied | P8: Total Time Irrigated | Q8: Daily Loading | R8: Maximum Hourly Loading | S8: Total Volume Applied | T8: Total Time Irrigated | U8: Daily Loading | V8: Maximum Hourly Loading
C9: ºF | D9: in | E9: ft | F9: ft | G9: gal | H9: min | I9: in | J9: in | K9: gal | L9: min | M9: in | N9: in | O9: gal | P9: min | Q9: in | R9: in | S9: gal | T9: min | U9: in | V9: in
A10: 1 | B10: =IF(ISBLANK('Enter Data Here'!B4), " ", 'Enter Data Here'!B4) | C10: =IF(ISBLANK('Enter Data Here'!C4), " ", 'Enter Data Here'!C4) | D10: =IF(ISBLANK('Enter Data Here'!D4), " ", 'Enter Data Here'!D4) | E10: =IF(ISBLANK('Enter Data Here'!E4), " ", 'Enter Data Here'!E4) | G10: ='Enter Data Here'!AD4+'Enter Data Here'!AF4+'Enter Data Here'!AH4 -> 0 | H10: ='Enter Data Here'!AE4+'Enter Data Here'!AG4+'Enter Data Here'!AI4 -> 0 | I10: =IF((ISBLANK($G10))," ", ($G10)/($I$3*27152)) -> 0 | J10: =MAX('Enter Data Here'!AD38:AH38) -> 0 | K10: ='Enter Data Here'!AJ4+'Enter Data Here'!AL4+'Enter Data Here'!AN4 -> 0 | L10: ='Enter Data Here'!AK4+'Enter Data Here'!AM4+'Enter Data Here'!AO4 -> 0 | M10: =IF((ISBLANK($K10))," ",($K10)/($M$3*27152)) -> 0 | N10: =MAX('Enter Data Here'!AJ38:AN38) -> 0 | O10: ='Enter Data Here'!AP4+'Enter Data Here'!AR4+'Enter Data Here'!AT4 -> 0 | P10: ='Enter Data Here'!AQ4+'Enter Data Here'!AS4+'Enter Data Here'!AU4 -> 0 | Q10: =IF((ISBLANK($O10))," ",($O10)/($Q$3*27152)) -> 0 | R10: =MAX('Enter Data Here'!AP38:AT38) -> 0 | S10: ='Enter Data Here'!AV4+'Enter Data Here'!AX4+'Enter Data Here'!AZ4 -> 0 | T10: ='Enter Data Here'!AW4+'Enter Data Here'!AY4+'Enter Data Here'!BA4 -> 0 | U10: =IF((ISBLANK($S10))," ",($S10)/($U$3*27152)) -> 0 | V10: =MAX('Enter Data Here'!AV38:AZ38) -> 0
A11: 2 | B11: =IF(ISBLANK('Enter Data Here'!B5), " ", 'Enter Data Here'!B5) | C11: =IF(ISBLANK('Enter Data Here'!C5), " ", 'Enter Data Here'!C5) | D11: =IF(ISBLANK('Enter Data Here'!D5), " ", 'Enter Data Here'!D5) | E11: =IF(ISBLANK('Enter Data Here'!E5), " ", 'Enter Data Here'!E5) | G11: ='Enter Data Here'!AD5+'Enter Data Here'!AF5+'Enter Data Here'!AH5 -> 0 | H11: ='Enter Data Here'!AE5+'Enter Data Here'!AG5+'Enter Data Here'!AI5 -> 0 | I11: =IF((ISBLANK($G11))," ", ($G11)/($I$3*27152)) -> 0 | J11: =MAX('Enter Data Here'!AD39:AH39) -> 0 | K11: ='Enter Data Here'!AJ5+'Enter Data Here'!AL5+'Enter Data Here'!AN5 -> 0 | L11: ='Enter Data Here'!AK5+'Enter Data Here'!AM5+'Enter Data Here'!AO5 -> 0 | M11: =IF((ISBLANK($K11))," ",($K11)/($M$3*27152)) -> 0 | N11: =MAX('Enter Data Here'!AJ39:AN39) -> 0 | O11: ='Enter Data Here'!AP5+'Enter Data Here'!AR5+'Enter Data Here'!AT5 -> 0 | P11: ='Enter Data Here'!AQ5+'Enter Data Here'!AS5+'Enter Data Here'!AU5 -> 0 | Q11: =IF((ISBLANK($O11))," ",($O11)/($Q$3*27152)) -> 0 | R11: =MAX('Enter Data Here'!AP39:AT39) -> 0 | S11: ='Enter Data Here'!AV5+'Enter Data Here'!AX5+'Enter Data Here'!AZ5 -> 0 | T11: ='Enter Data Here'!AW5+'Enter Data Here'!AY5+'Enter Data Here'!BA5 -> 0 | U11: =IF((ISBLANK($S11))," ",($S11)/($U$3*27152)) -> 0 | V11: =MAX('Enter Data Here'!AV39:AZ39) -> 0
A12: 3 | B12: =IF(ISBLANK('Enter Data Here'!B6), " ", 'Enter Data Here'!B6) | C12: =IF(ISBLANK('Enter Data Here'!C6), " ", 'Enter Data Here'!C6) | D12: =IF(ISBLANK('Enter Data Here'!D6), " ", 'Enter Data Here'!D6) | E12: =IF(ISBLANK('Enter Data Here'!E6), " ", 'Enter Data Here'!E6) | G12: ='Enter Data Here'!AD6+'Enter Data Here'!AF6+'Enter Data Here'!AH6 -> 0 | H12: ='Enter Data Here'!AE6+'Enter Data Here'!AG6+'Enter Data Here'!AI6 -> 0 | I12: =IF((ISBLANK($G12))," ", ($G12)/($I$3*27152)) -> 0 | J12: =MAX('Enter Data Here'!AD40:AH40) -> 0 | K12: ='Enter Data Here'!AJ6+'Enter Data Here'!AL6+'Enter Data Here'!AN6 -> 0 | L12: ='Enter Data Here'!AK6+'Enter Data Here'!AM6+'Enter Data Here'!AO6 -> 0 | M12: =IF((ISBLANK($K12))," ",($K12)/($M$3*27152)) -> 0 | N12: =MAX('Enter Data Here'!AJ40:AN40) -> 0 | O12: ='Enter Data Here'!AP6+'Enter Data Here'!AR6+'Enter Data Here'!AT6 -> 0 | P12: ='Enter Data Here'!AQ6+'Enter Data Here'!AS6+'Enter Data Here'!AU6 -> 0 | Q12: =IF((ISBLANK($O12))," ",($O12)/($Q$3*27152)) -> 0 | R12: =MAX('Enter Data Here'!AP40:AT40) -> 0 | S12: ='Enter Data Here'!AV6+'Enter Data Here'!AX6+'Enter Data Here'!AZ6 -> 0 | T12: ='Enter Data Here'!AW6+'Enter Data Here'!AY6+'Enter Data Here'!BA6 -> 0 | U12: =IF((ISBLANK($S12))," ",($S12)/($U$3*27152)) -> 0 | V12: =MAX('Enter Data Here'!AV40:AZ40) -> 0
A13: 4 | B13: =IF(ISBLANK('Enter Data Here'!B7), " ", 'Enter Data Here'!B7) | C13: =IF(ISBLANK('Enter Data Here'!C7), " ", 'Enter Data Here'!C7) | D13: =IF(ISBLANK('Enter Data Here'!D7), " ", 'Enter Data Here'!D7) | E13: =IF(ISBLANK('Enter Data Here'!E7), " ", 'Enter Data Here'!E7) | G13: ='Enter Data Here'!AD7+'Enter Data Here'!AF7+'Enter Data Here'!AH7 -> 0 | H13: ='Enter Data Here'!AE7+'Enter Data Here'!AG7+'Enter Data Here'!AI7 -> 0 | I13: =IF((ISBLANK($G13))," ", ($G13)/($I$3*27152)) -> 0 | J13: =MAX('Enter Data Here'!AD41:AH41) -> 0 | K13: ='Enter Data Here'!AJ7+'Enter Data Here'!AL7+'Enter Data Here'!AN7 -> 0 | L13: ='Enter Data Here'!AK7+'Enter Data Here'!AM7+'Enter Data Here'!AO7 -> 0 | M13: =IF((ISBLANK($K13))," ",($K13)/($M$3*27152)) -> 0 | N13: =MAX('Enter Data Here'!AJ41:AN41) -> 0 | O13: ='Enter Data Here'!AP7+'Enter Data Here'!AR7+'Enter Data Here'!AT7 -> 0 | P13: ='Enter Data Here'!AQ7+'Enter Data Here'!AS7+'Enter Data Here'!AU7 -> 0 | Q13: =IF((ISBLANK($O13))," ",($O13)/($Q$3*27152)) -> 0 | R13: =MAX('Enter Data Here'!AP41:AT41) -> 0 | S13: ='Enter Data Here'!AV7+'Enter Data Here'!AX7+'Enter Data Here'!AZ7 -> 0 | T13: ='Enter Data Here'!AW7+'Enter Data Here'!AY7+'Enter Data Here'!BA7 -> 0 | U13: =IF((ISBLANK($S13))," ",($S13)/($U$3*27152)) -> 0 | V13: =MAX('Enter Data Here'!AV41:AZ41) -> 0
A14: 5 | B14: =IF(ISBLANK('Enter Data Here'!B8), " ", 'Enter Data Here'!B8) | C14: =IF(ISBLANK('Enter Data Here'!C8), " ", 'Enter Data Here'!C8) | D14: =IF(ISBLANK('Enter Data Here'!D8), " ", 'Enter Data Here'!D8) | E14: =IF(ISBLANK('Enter Data Here'!E8), " ", 'Enter Data Here'!E8) | G14: ='Enter Data Here'!AD8+'Enter Data Here'!AF8+'Enter Data Here'!AH8 -> 0 | H14: ='Enter Data Here'!AE8+'Enter Data Here'!AG8+'Enter Data Here'!AI8 -> 0 | I14: =IF((ISBLANK($G14))," ", ($G14)/($I$3*27152)) -> 0 | J14: =MAX('Enter Data Here'!AD42:AH42) -> 0 | K14: ='Enter Data Here'!AJ8+'Enter Data Here'!AL8+'Enter Data Here'!AN8 -> 0 | L14: ='Enter Data Here'!AK8+'Enter Data Here'!AM8+'Enter Data Here'!AO8 -> 0 | M14: =IF((ISBLANK($K14))," ",($K14)/($M$3*27152)) -> 0 | N14: =MAX('Enter Data Here'!AJ42:AN42) -> 0 | O14: ='Enter Data Here'!AP8+'Enter Data Here'!AR8+'Enter Data Here'!AT8 -> 0 | P14: ='Enter Data Here'!AQ8+'Enter Data Here'!AS8+'Enter Data Here'!AU8 -> 0 | Q14: =IF((ISBLANK($O14))," ",($O14)/($Q$3*27152)) -> 0 | R14: =MAX('Enter Data Here'!AP42:AT42) -> 0 | S14: ='Enter Data Here'!AV8+'Enter Data Here'!AX8+'Enter Data Here'!AZ8 -> 0 | T14: ='Enter Data Here'!AW8+'Enter Data Here'!AY8+'Enter Data Here'!BA8 -> 0 | U14: =IF((ISBLANK($S14))," ",($S14)/($U$3*27152)) -> 0 | V14: =MAX('Enter Data Here'!AV42:AZ42) -> 0
A15: 6 | B15: =IF(ISBLANK('Enter Data Here'!B9), " ", 'Enter Data Here'!B9) | C15: =IF(ISBLANK('Enter Data Here'!C9), " ", 'Enter Data Here'!C9) | D15: =IF(ISBLANK('Enter Data Here'!D9), " ", 'Enter Data Here'!D9) | E15: =IF(ISBLANK('Enter Data Here'!E9), " ", 'Enter Data Here'!E9) | G15: ='Enter Data Here'!AD9+'Enter Data Here'!AF9+'Enter Data Here'!AH9 -> 0 | H15: ='Enter Data Here'!AE9+'Enter Data Here'!AG9+'Enter Data Here'!AI9 -> 0 | I15: =IF((ISBLANK($G15))," ", ($G15)/($I$3*27152)) -> 0 | J15: =MAX('Enter Data Here'!AD43:AH43) -> 0 | K15: ='Enter Data Here'!AJ9+'Enter Data Here'!AL9+'Enter Data Here'!AN9 -> 0 | L15: ='Enter Data Here'!AK9+'Enter Data Here'!AM9+'Enter Data Here'!AO9 -> 0 | M15: =IF((ISBLANK($K15))," ",($K15)/($M$3*27152)) -> 0 | N15: =MAX('Enter Data Here'!AJ43:AN43) -> 0 | O15: ='Enter Data Here'!AP9+'Enter Data Here'!AR9+'Enter Data Here'!AT9 -> 0 | P15: ='Enter Data Here'!AQ9+'Enter Data Here'!AS9+'Enter Data Here'!AU9 -> 0 | Q15: =IF((ISBLANK($O15))," ",($O15)/($Q$3*27152)) -> 0 | R15: =MAX('Enter Data Here'!AP43:AT43) -> 0 | S15: ='Enter Data Here'!AV9+'Enter Data Here'!AX9+'Enter Data Here'!AZ9 -> 0 | T15: ='Enter Data Here'!AW9+'Enter Data Here'!AY9+'Enter Data Here'!BA9 -> 0 | U15: =IF((ISBLANK($S15))," ",($S15)/($U$3*27152)) -> 0 | V15: =MAX('Enter Data Here'!AV43:AZ43) -> 0
A16: 7 | B16: =IF(ISBLANK('Enter Data Here'!B10), " ", 'Enter Data Here'!B10) | C16: =IF(ISBLANK('Enter Data Here'!C10), " ", 'Enter Data Here'!C10) | D16: =IF(ISBLANK('Enter Data Here'!D10), " ", 'Enter Data Here'!D10) | E16: =IF(ISBLANK('Enter Data Here'!E10), " ", 'Enter Data Here'!E10) | G16: ='Enter Data Here'!AD10+'Enter Data Here'!AF10+'Enter Data Here'!AH10 -> 0 | H16: ='Enter Data Here'!AE10+'Enter Data Here'!AG10+'Enter Data Here'!AI10 -> 0 | I16: =IF((ISBLANK($G16))," ", ($G16)/($I$3*27152)) -> 0 | J16: =MAX('Enter Data Here'!AD44:AH44) -> 0 | K16: ='Enter Data Here'!AJ10+'Enter Data Here'!AL10+'Enter Data Here'!AN10 -> 0 | L16: ='Enter Data Here'!AK10+'Enter Data Here'!AM10+'Enter Data Here'!AO10 -> 0 | M16: =IF((ISBLANK($K16))," ",($K16)/($M$3*27152)) -> 0 | N16: =MAX('Enter Data Here'!AJ44:AN44) -> 0 | O16: ='Enter Data Here'!AP10+'Enter Data Here'!AR10+'Enter Data Here'!AT10 -> 0 | P16: ='Enter Data Here'!AQ10+'Enter Data Here'!AS10+'Enter Data Here'!AU10 -> 0 | Q16: =IF((ISBLANK($O16))," ",($O16)/($Q$3*27152)) -> 0 | R16: =MAX('Enter Data Here'!AP44:AT44) -> 0 | S16: ='Enter Data Here'!AV10+'Enter Data Here'!AX10+'Enter Data Here'!AZ10 -> 0 | T16: ='Enter Data Here'!AW10+'Enter Data Here'!AY10+'Enter Data Here'!BA10 -> 0 | U16: =IF((ISBLANK($S16))," ",($S16)/($U$3*27152)) -> 0 | V16: =MAX('Enter Data Here'!AV44:AZ44) -> 0
