Workbook

Sheet Summary
A1: Community and Technical Colleges, Report of Fundable Operating Expenses, Fiscal Year (FY) 2008
A2: Summary of Expense divided Contact Hours
A3: Contact Hours for fall 2007 and spring and summer 2008
A4: Fund | B4: Total Expense by Discipline | D4: Contact Hours | E4: Expense | F4: Expense per Contact Hour
A5: 1 | B5: Agriculture | D5: =D36 -> 1534719 | E5: =E36+E67+IFERROR($E$105/$D$105*D5,0) -> 13513304 | F5: =F36+F67+$F$105 -> 7.7
A6: 2 | B6: Architecture and Precision Production Trades | D6: =D37 -> 3407979 | E6: =E37+E68+IFERROR($E$105/$D$105*D6,0) -> 34957122 | F6: =F37+F68+$F$105 -> 8.88
A7: 3 | B7: Biology, Physical Sciences, and Science Technology | D7: =D38 -> 29317564 | E7: =E38+E69+IFERROR($E$105/$D$105*D7,0) -> 2.2249238e+08 | F7: =F38+F69+$F$105 -> 6.85
A8: 4 | B8: Business Management, Marketing, and Administrative Services | D8: =D39 -> 17818481 | E8: =E39+E70+IFERROR($E$105/$D$105*D8,0) -> 1.4084724e+08 | F8: =F39+F70+$F$105 -> 7.11
A9: 5 | B9: Career Pilot | D9: =D40 -> 180656 | E9: =E40+E71+IFERROR($E$105/$D$105*D9,0) -> 5463573.8 | F9: =F40+F71+$F$105 -> 33.87
A10: 6 | B10: Communications | D10: =D41 -> 4119103 | E10: =E41+E72+IFERROR($E$105/$D$105*D10,0) -> 33422475 | F10: =F41+F72+$F$105 -> 7.65
A11: 7 | B11: Computer and Information Sciences | D11: =D42 -> 11156743 | E11: =E42+E73+IFERROR($E$105/$D$105*D11,0) -> 1.0896882e+08 | F11: =F42+F73+$F$105 -> 8.52
A12: 8 | B12: Construction Trades | D12: =D43 -> 1641826 | E12: =E43+E74+IFERROR($E$105/$D$105*D12,0) -> 15050396 | F12: =F43+F74+$F$105 -> 8.03
A13: 9 | B13: Consumer and Homemaking Education | D13: =D44 -> 8752792 | E13: =E44+E75+IFERROR($E$105/$D$105*D13,0) -> 66186357 | F13: =F44+F75+$F$105 -> 6.75
A14: 10 | B14: Engineering | D14: =D45 -> 253339 | E14: =E45+E76+IFERROR($E$105/$D$105*D14,0) -> 2621275.6 | F14: =F45+F76+$F$105 -> 7.86
A15: 11 | B15: Engineering Related | D15: =D46 -> 6787477 | E15: =E46+E77+IFERROR($E$105/$D$105*D15,0) -> 60923755 | F15: =F46+F77+$F$105 -> 7.41
A16: 12 | B16: English Language, Lit, Philosophy, Humanities, & Interdisciplinary | D16: =D47 -> 38977120 | E16: =E47+E78+IFERROR($E$105/$D$105*D16,0) -> 3.2234136e+08 | F16: =F47+F78+$F$105 -> 7.31
... A30: 26 | B30: Visual and Performing Arts | D30: =D61 -> 12932275 | E30: =E61+E92+IFERROR($E$105/$D$105*D30,0) -> 1.2311475e+08 | F30: =F61+F92+$F$105 -> 8.36
A31: 28 | B31: Developmental Education - Math | D31: =D62 -> 0 | E31: =E62+E93+IFERROR($E$105/$D$105*D31,0) -> 0
A32: 29 | B32: Developmental Education - Reading/Writing | D32: =D63 -> 0 | E32: =E63+E94+IFERROR($E$105/$D$105*D32,0) -> 0
B33: Total | D33: =SUM(D5:D32) -> 254560011 | E33: =SUM(E5:E32) -> 2.1110026e+09 | F33: =F64+F95+$F$105 -> 7.6
A35: Fund | B35: Departmental Operating Expense by Discipline | D35: Contact Hours | E35: Expense | F35: Expense per Contact Hour
A36: 1 | B36: Agriculture | D36: =SUM('1:57'!D36) -> 1534719 | E36: =SUM('1:57'!E36) -> 2984519 | F36: =ROUND(MEDIAN('1:57'!F36),2) -> 1.16
A37: 2 | B37: Architecture and Precision Production Trades | D37: =SUM('1:57'!D37) -> 3407979 | E37: =SUM('1:57'!E37) -> 8046820 | F37: =ROUND(MEDIAN('1:57'!F37),2) -> 2.22
A38: 3 | B38: Biology, Physical Sciences, and Science Technology | D38: =SUM('1:57'!D38) -> 29317564 | E38: =SUM('1:57'!E38) -> 29374637 | F38: =ROUND(MEDIAN('1:57'!F38),2) -> 0.81
A39: 4 | B39: Business Management, Marketing, and Administrative Services | D39: =SUM('1:57'!D39) -> 17818481 | E39: =SUM('1:57'!E39) -> 19582467 | F39: =ROUND(MEDIAN('1:57'!F39),2) -> 0.81
A40: 5 | B40: Career Pilot | D40: =SUM('1:57'!D40) -> 180656 | E40: =SUM('1:57'!E40) -> 3465653 | F40: =ROUND(MEDIAN('1:57'!F40),2) -> 20.99
A41: 6 | B41: Communications | D41: =SUM('1:57'!D41) -> 4119103 | E41: =SUM('1:57'!E41) -> 9113634 | F41: =ROUND(MEDIAN('1:57'!F41),2) -> 1.5
A42: 7 | B42: Computer and Information Sciences | D42: =SUM('1:57'!D42) -> 11156743 | E42: =SUM('1:57'!E42) -> 22748020 | F42: =ROUND(MEDIAN('1:57'!F42),2) -> 1.39
A43: 8 | B43: Construction Trades | D43: =SUM('1:57'!D43) -> 1641826 | E43: =SUM('1:57'!E43) -> 3590333 | F43: =ROUND(MEDIAN('1:57'!F43),2) -> 1.92
A44: 9 | B44: Consumer and Homemaking Education | D44: =SUM('1:57'!D44) -> 8752792 | E44: =SUM('1:57'!E44) -> 11488314 | F44: =ROUND(MEDIAN('1:57'!F44),2) -> 0.87
A45: 10 | B45: Engineering | D45: =SUM('1:57'!D45) -> 253339 | E45: =SUM('1:57'!E45) -> 456097 | F45: =ROUND(MEDIAN('1:57'!F45),2) -> 1.29
A46: 11 | B46: Engineering Related | D46: =SUM('1:57'!D46) -> 6787477 | E46: =SUM('1:57'!E46) -> 13809588 | F46: =ROUND(MEDIAN('1:57'!F46),2) -> 1.28
A47: 12 | B47: English Language, Lit, Philosophy, Humanities, & Interdisciplinary | D47: =SUM('1:57'!D47) -> 38977120 | E47: =SUM('1:57'!E47) -> 35213340 | F47: =ROUND(MEDIAN('1:57'!F47),2) -> 0.71
... A61: 26 | B61: Visual and Performing Arts | D61: =SUM('1:57'!D61) -> 12932275 | E61: =SUM('1:57'!E61) -> 19609036 | F61: =ROUND(MEDIAN('1:57'!F61),2) -> 1.23
A62: 28 | B62: Developmental Education - Math | D62: =SUM('1:57'!D62) -> 0 | E62: =SUM('1:57'!E62) -> 0
A63: 29 | B63: Developmental Education - Reading/Writing | D63: =SUM('1:57'!D63) -> 0 | E63: =SUM('1:57'!E63) -> 0
C64: Total | D64: =SUM(D36:D63) -> 254560011 | E64: =SUM(E36:E63) -> 298174071 | F64: =ROUND(MEDIAN('1:57'!F64),2) -> 1.05
A66: Fund | B66: Faculty Salaries by Discipline | D66: Contact Hours | E66: Expense | F66: Expense per Contact Hour
A67: 1 | B67: Agriculture | D67: =D36 -> 1534719 | E67: =SUM('1:57'!E67) -> 4815786 | F67: =ROUND(MEDIAN('1:57'!F67),2) -> 3.26
A68: 2 | B68: Architecture and Precision Production Trades | D68: =D37 -> 3407979 | E68: =SUM('1:57'!E68) -> 14224084 | F68: =ROUND(MEDIAN('1:57'!F68),2) -> 3.38
...

Sheet Rate History
A1: =Summary!A1 -> Community and Technical Colleges, Report of Fundable Operating Expenses, Fiscal Year (FY) 2008
A2: Rate History | N2: Year over Year Change
A3: Fund | B3: Expense per Contact Hour by Discipline | C3: 2008 | D3: 2007 | E3: 2006 | F3: 2005 | G3: 2004 | H3: 2003 | I3: 2002 | J3: 2001 | K3: 2000 | L3: 1999 | N3: 2008 | O3: 2007 | P3: 2006 | Q3: 2005 | R3: 2004 | S3: 2003 | T3: 2002 | U3: 2001 | V3: 2000
A4: 1 | B4: Agriculture | C4: =Summary!F5 -> 7.7 | D4: 7.37 | F4: 7.25 | G4: 9.82 | H4: 7.18 | I4: 7.58 | J4: 7 | K4: 6.67 | L4: 6.81 | N4: =IFERROR(C4/D4-1,"") -> 0.044776119 | O4: =IFERROR(D4/E4-1,"") | P4: =IFERROR(E4/F4-1,"") -> -1 | Q4: =IFERROR(F4/G4-1,"") -> -0.26171079 | R4: =IFERROR(G4/H4-1,"") -> 0.36768802 | S4: =IFERROR(H4/I4-1,"") -> -0.052770449 | T4: =IFERROR(I4/J4-1,"") -> 0.082857143 | U4: =IFERROR(J4/K4-1,"") -> 0.049475262 | V4: =IFERROR(K4/L4-1,"") -> -0.020558003
A5: 2 | B5: Architecture and Precision Production Trades | C5: =Summary!F6 -> 8.88 | D5: 10.29 | F5: 8.82 | G5: 11.31 | H5: 7.31 | I5: 7.27 | J5: 7.56 | K5: 6.83 | L5: 6.64 | N5: =IFERROR(C5/D5-1,"") -> -0.13702624 | O5: =IFERROR(D5/E5-1,"") | P5: =IFERROR(E5/F5-1,"") -> -1 | Q5: =IFERROR(F5/G5-1,"") -> -0.22015915 | R5: =IFERROR(G5/H5-1,"") -> 0.54719562 | S5: =IFERROR(H5/I5-1,"") -> 0.0055020633 | T5: =IFERROR(I5/J5-1,"") -> -0.038359788 | U5: =IFERROR(J5/K5-1,"") -> 0.10688141 | V5: =IFERROR(K5/L5-1,"") -> 0.028614458
A6: 3 | B6: Biology, Physical Sciences, and Science Technology | C6: =Summary!F7 -> 6.85 | D6: 6.65 | F6: 6.19 | G6: 7.98 | H6: 5.86 | I6: 6.04 | J6: 5.9 | K6: 5.69 | L6: 5.51 | N6: =IFERROR(C6/D6-1,"") -> 0.030075188 | O6: =IFERROR(D6/E6-1,"") | P6: =IFERROR(E6/F6-1,"") -> -1 | Q6: =IFERROR(F6/G6-1,"") -> -0.22431078 | R6: =IFERROR(G6/H6-1,"") -> 0.36177474 | S6: =IFERROR(H6/I6-1,"") -> -0.029801325 | T6: =IFERROR(I6/J6-1,"") -> 0.023728814 | U6: =IFERROR(J6/K6-1,"") -> 0.036906854 | V6: =IFERROR(K6/L6-1,"") -> 0.032667877
A7: 4 | B7: Business Management, Marketing, and Administrative Services | C7: =Summary!F8 -> 7.11 | D7: 6.97 | F7: 6.58 | G7: 8.86 | H7: 6.69 | I7: 6.46 | J7: 6.07 | K7: 6.13 | L7: 6.22 | N7: =IFERROR(C7/D7-1,"") -> 0.020086083 | O7: =IFERROR(D7/E7-1,"") | P7: =IFERROR(E7/F7-1,"") -> -1 | Q7: =IFERROR(F7/G7-1,"") -> -0.25733634 | R7: =IFERROR(G7/H7-1,"") -> 0.32436472 | S7: =IFERROR(H7/I7-1,"") -> 0.035603715 | T7: =IFERROR(I7/J7-1,"") -> 0.064250412 | U7: =IFERROR(J7/K7-1,"") -> -0.0097879282 | V7: =IFERROR(K7/L7-1,"") -> -0.014469453
A8: 5 | B8: Career Pilot | C8: =Summary!F9 -> 33.87 | D8: 30.76 | F8: 23.45 | G8: 25.28 | H8: 13.77 | I8: 11.03 | J8: 16.04 | K8: 19.42 | L8: 18.69 | N8: =IFERROR(C8/D8-1,"") -> 0.10110533 | O8: =IFERROR(D8/E8-1,"") | P8: =IFERROR(E8/F8-1,"") -> -1 | Q8: =IFERROR(F8/G8-1,"") -> -0.072389241 | R8: =IFERROR(G8/H8-1,"") -> 0.83587509 | S8: =IFERROR(H8/I8-1,"") -> 0.24841342 | T8: =IFERROR(I8/J8-1,"") -> -0.31234414 | U8: =IFERROR(J8/K8-1,"") -> -0.17404737 | V8: =IFERROR(K8/L8-1,"") -> 0.03905832
A9: 6 | B9: Communications | C9: =Summary!F10 -> 7.65 | D9: 7.3 | F9: 7.3 | G9: 10.01 | H9: 7.21 | I9: 7.26 | J9: 6.99 | K9: 9.21 | L9: 8.21 | N9: =IFERROR(C9/D9-1,"") -> 0.047945205 | O9: =IFERROR(D9/E9-1,"") | P9: =IFERROR(E9/F9-1,"") -> -1 | Q9: =IFERROR(F9/G9-1,"") -> -0.27072927 | R9: =IFERROR(G9/H9-1,"") -> 0.38834951 | S9: =IFERROR(H9/I9-1,"") -> -0.0068870523 | T9: =IFERROR(I9/J9-1,"") -> 0.038626609 | U9: =IFERROR(J9/K9-1,"") -> -0.24104235 | V9: =IFERROR(K9/L9-1,"") -> 0.12180268
A10: 7 | B10: Computer and Information Sciences | C10: =Summary!F11 -> 8.52 | D10: 8.44 | F10: 7.57 | G10: 9.93 | H10: 6.94 | I10: 6.92 | J10: 6.69 | K10: 6.32 | L10: 5.44 | N10: =IFERROR(C10/D10-1,"") -> 0.009478673 | O10: =IFERROR(D10/E10-1,"") | P10: =IFERROR(E10/F10-1,"") -> -1 | Q10: =IFERROR(F10/G10-1,"") -> -0.23766365 | R10: =IFERROR(G10/H10-1,"") -> 0.43083573 | S10: =IFERROR(H10/I10-1,"") -> 0.0028901734 | T10: =IFERROR(I10/J10-1,"") -> 0.034379671 | U10: =IFERROR(J10/K10-1,"") -> 0.058544304 | V10: =IFERROR(K10/L10-1,"") -> 0.16176471
A11: 8 | B11: Construction Trades | C11: =Summary!F12 -> 8.03 | D11: 7.77 | F11: 8.2 | G11: 10.92 | H11: 7.36 | I11: 6.75 | J11: 6.12 | K11: 6.42 | L11: 5.99 | N11: =IFERROR(C11/D11-1,"") -> 0.033462033 | O11: =IFERROR(D11/E11-1,"") | P11: =IFERROR(E11/F11-1,"") -> -1 | Q11: =IFERROR(F11/G11-1,"") -> -0.24908425 | R11: =IFERROR(G11/H11-1,"") -> 0.48369565 | S11: =IFERROR(H11/I11-1,"") -> 0.09037037 | T11: =IFERROR(I11/J11-1,"") -> 0.10294118 | U11: =IFERROR(J11/K11-1,"") -> -0.046728972 | V11: =IFERROR(K11/L11-1,"") -> 0.071786311
A12: 9 | B12: Consumer and Homemaking Education | C12: =Summary!F13 -> 6.75 | D12: 6.49 | F12: 6.14 | G12: 8.08 | H12: 5.49 | I12: 5.51 | J12: 5.52 | K12: 5.14 | L12: 5.35 | N12: =IFERROR(C12/D12-1,"") -> 0.040061633 | O12: =IFERROR(D12/E12-1,"") | P12: =IFERROR(E12/F12-1,"") -> -1 | Q12: =IFERROR(F12/G12-1,"") -> -0.24009901 | R12: =IFERROR(G12/H12-1,"") -> 0.47176685 | S12: =IFERROR(H12/I12-1,"") -> -0.0036297641 | T12: =IFERROR(I12/J12-1,"") -> -0.0018115942 | U12: =IFERROR(J12/K12-1,"") -> 0.073929961 | V12: =IFERROR(K12/L12-1,"") -> -0.039252336
A13: 10 | B13: Engineering | C13: =Summary!F14 -> 7.86 | D13: 7.53 | F13: 10.3 | G13: 11.38 | H13: 8.92 | I13: 8.54 | J13: 11.49 | K13: 9.83 | L13: 7.64 | N13: =IFERROR(C13/D13-1,"") -> 0.043824701 | O13: =IFERROR(D13/E13-1,"") | P13: =IFERROR(E13/F13-1,"") -> -1 | Q13: =IFERROR(F13/G13-1,"") -> -0.094903339 | R13: =IFERROR(G13/H13-1,"") -> 0.27578475 | S13: =IFERROR(H13/I13-1,"") -> 0.044496487 | T13: =IFERROR(I13/J13-1,"") -> -0.256745 | U13: =IFERROR(J13/K13-1,"") -> 0.1688708 | V13: =IFERROR(K13/L13-1,"") -> 0.28664921
A14: 11 | B14: Engineering Related | C14: =Summary!F15 -> 7.41 | D14: 7.09 | F14: 6.82 | G14: 9.52 | H14: 7.23 | I14: 6.89 | J14: 6.58 | K14: 6.71 | L14: 6.42 | N14: =IFERROR(C14/D14-1,"") -> 0.045133992 | O14: =IFERROR(D14/E14-1,"") | P14: =IFERROR(E14/F14-1,"") -> -1 | Q14: =IFERROR(F14/G14-1,"") -> -0.28361345 | R14: =IFERROR(G14/H14-1,"") -> 0.31673582 | S14: =IFERROR(H14/I14-1,"") -> 0.04934688 | T14: =IFERROR(I14/J14-1,"") -> 0.047112462 | U14: =IFERROR(J14/K14-1,"") -> -0.019374069 | V14: =IFERROR(K14/L14-1,"") -> 0.04517134
A15: 12 | B15: English Language, Lit, Philosophy, Humanities, & Interdisciplinary | C15: =Summary!F16 -> 7.31 | D15: 7.08 | F15: 6.48 | G15: 8.33 | H15: 5.83 | I15: 5.94 | J15: 5.75 | K15: 5.68 | L15: 5.26 | N15: =IFERROR(C15/D15-1,"") -> 0.032485876 | O15: =IFERROR(D15/E15-1,"") | P15: =IFERROR(E15/F15-1,"") -> -1 | Q15: =IFERROR(F15/G15-1,"") -> -0.22208884 | R15: =IFERROR(G15/H15-1,"") -> 0.42881647 | S15: =IFERROR(H15/I15-1,"") -> -0.018518519 | T15: =IFERROR(I15/J15-1,"") -> 0.033043478 | U15: =IFERROR(J15/K15-1,"") -> 0.012323944 | V15: =IFERROR(K15/L15-1,"") -> 0.079847909
... A31: 29 | B31: Developmental Education - Reading/Writing | C31: =Summary!F32 -> 0 | D31: 0 | F31: 0 | G31: 0 | H31: 0 | I31: 0 | J31: 0 | K31: 0 | L31: 0 | N31: =IFERROR(C31/D31-1,"") | O31: =IFERROR(D31/E31-1,"") | P31: =IFERROR(E31/F31-1,"") | Q31: =IFERROR(F31/G31-1,"") | R31: =IFERROR(G31/H31-1,"") | S31: =IFERROR(H31/I31-1,"") | T31: =IFERROR(I31/J31-1,"") | U31: =IFERROR(J31/K31-1,"") | V31: =IFERROR(K31/L31-1,"")
B32: Average | C32: =AVERAGE(C4:C31) -> 8.67 | D32: =AVERAGE(D4:D31) -> 8.4635714 | F32: =AVERAGE(F4:F31) -> 7.7992857 | G32: =AVERAGE(G4:G31) -> 9.7525 | H32: =AVERAGE(H4:H31) -> 6.9428571 | I32: =AVERAGE(I4:I31) -> 7.0071429 | J32: =AVERAGE(J4:J31) -> 7.0107143 | K32: =AVERAGE(K4:K31) -> 7.0171429 | L32: =AVERAGE(L4:L31) -> 6.5617857 | N32: =IFERROR(C32/D32-1,"") -> 0.024390244 | O32: =IFERROR(D32/E32-1,"") | P32: =IFERROR(E32/F32-1,"") -> -1 | Q32: =IFERROR(F32/G32-1,"") -> -0.20027832 | R32: =IFERROR(G32/H32-1,"") -> 0.40468107 | S32: =IFERROR(H32/I32-1,"") -> -0.0091743119 | T32: =IFERROR(I32/J32-1,"") -> -0.00050942435 | U32: =IFERROR(J32/K32-1,"") -> -0.00091612378 | V32: =IFERROR(K32/L32-1,"") -> 0.069395308
B33: Median | C33: =MEDIAN(C4:C31) -> 7.78 | D33: =MEDIAN(D4:D31) -> 7.525 | F33: =MEDIAN(F4:F31) -> 7.345 | G33: =MEDIAN(G4:G31) -> 9.615 | H33: =MEDIAN(H4:H31) -> 6.995 | I33: =MEDIAN(I4:I31) -> 6.905 | J33: =MEDIAN(J4:J31) -> 6.69 | K33: =MEDIAN(K4:K31) -> 6.69 | L33: =MEDIAN(L4:L31) -> 6.32 | N33: =IFERROR(C33/D33-1,"") -> 0.033887043 | O33: =IFERROR(D33/E33-1,"") | P33: =IFERROR(E33/F33-1,"") -> -1 | Q33: =IFERROR(F33/G33-1,"") -> -0.23608944 | R33: =IFERROR(G33/H33-1,"") -> 0.37455325 | S33: =IFERROR(H33/I33-1,"") -> 0.013034033 | T33: =IFERROR(I33/J33-1,"") -> 0.032137519 | U33: =IFERROR(J33/K33-1,"") -> 0 | V33: =IFERROR(K33/L33-1,"") -> 0.058544304
B34: Standard Deviation | C34: =STDEV(C4:C31) -> 5.7536855 | D34: =STDEV(D4:D31) -> 5.2587227 | F34: =STDEV(F4:F31) -> 4.1137528 | G34: =STDEV(G4:G31) -> 4.4105653 | H34: =STDEV(H4:H31) -> 2.7509808 | I34: =STDEV(I4:I31) -> 2.6772026 | J34: =STDEV(J4:J31) -> 3.0868058 | K34: =STDEV(K4:K31) -> 3.4645516 | L34: =STDEV(L4:L31) -> 3.2525364 | N34: =IFERROR(C34/D34-1,"") -> 0.094122236 | O34: =IFERROR(D34/E34-1,"") | P34: =IFERROR(E34/F34-1,"") -> -1 | Q34: =IFERROR(F34/G34-1,"") -> -0.067295782 | R34: =IFERROR(G34/H34-1,"") -> 0.60327012 | S34: =IFERROR(H34/I34-1,"") -> 0.027557936 | T34: =IFERROR(I34/J34-1,"") -> -0.13269483 | U34: =IFERROR(J34/K34-1,"") -> -0.10903165 | V34: =IFERROR(K34/L34-1,"") -> 0.065184562

Sheet FTSE Summary
A1: =Summary!A1 -> Community and Technical Colleges, Report of Fundable Operating Expenses, Fiscal Year (FY) 2008
A2: Average Total Expenditure per Full-Time Student Equivalent (FTSE)
A3: Institution | B3: Annual State Funded Semester Credit Hours | C3: Total FTSE | D3: Total Expenditure | E3: Average Expenditure per FTSE
A4: Alamo | B4: 998865 | C4: =B4/30 -> 33295.5 | D4: ='1'!$E$33 -> 1.9123947e+08 | E4: =IFERROR(D4/C4,"") -> 5743.7032
A5: Alvin | B5: 92788 | C5: =B5/30 -> 3092.9333 | D5: ='2'!$E$33 -> 20109762 | E5: =IFERROR(D5/C5,"") -> 6501.8414
A6: Amarillo | B6: 178668 | C6: =B6/30 -> 5955.6 | D6: ='3'!$E$33 -> 34512276 | E6: =IFERROR(D6/C6,"") -> 5794.9285
A7: Angelina | B7: 94431 | C7: =B7/30 -> 3147.7 | D7: ='4'!$E$33 -> 13509317 | E7: =IFERROR(D7/C7,"") -> 4291.8058
A8: Austin | B8: 637122 | C8: =B8/30 -> 21237.4 | D8: ='5'!$E$33 -> 136750474 | E8: =IFERROR(D8/C8,"") -> 6439.1345
A9: Blinn | B9: 328749 | C9: =B9/30 -> 10958.3 | D9: ='6'!$E$33 -> 39123738 | E9: =IFERROR(D9/C9,"") -> 3570.2379
A10: Brazosport | B10: 66827 | C10: =B10/30 -> 2227.5667 | D10: ='7'!$E$33 -> 14287859 | E10: =IFERROR(D10/C10,"") -> 6414.1106
A11: Central Texas | B11: 261238 | C11: =B11/30 -> 8707.9333 | D11: ='8'!$E$33 -> 44599543 | E11: =IFERROR(D11/C11,"") -> 5121.7139
A12: Cisco | B12: 71870 | C12: =B12/30 -> 2395.6667 | D12: ='9'!$E$33 -> 9248686 | E12: =IFERROR(D12/C12,"") -> 3860.5897
A13: Clarendon | B13: 25155 | C13: =B13/30 -> 838.5 | D13: ='10'!$E$33 -> 3668635 | E13: =IFERROR(D13/C13,"") -> 4375.2355
A14: Coastal Bend | B14: 63382 | C14: =B14/30 -> 2112.7333 | D14: ='11'!$E$33 -> 0 | E14: =IFERROR(D14/C14,"") -> 0
A15: College Of The Mainland | B15: 71997 | C15: =B15/30 -> 2399.9 | D15: ='12'!$E$33 -> 24391320 | E15: =IFERROR(D15/C15,"") -> 10163.473
A16: Collin | B16: 412203 | C16: =B16/30 -> 13740.1 | D16: ='13'!$E$33 -> 70034922 | E16: =IFERROR(D16/C16,"") -> 5097.1188
A17: Dallas | B17: 1151165 | C17: =B17/30 -> 38372.167 | D17: ='14'!$E$33 -> 214562812 | E17: =IFERROR(D17/C17,"") -> 5591.6262
A18: Del Mar | B18: 204427 | C18: =B18/30 -> 6814.2333 | D18: ='15'!$E$33 -> 57594377 | E18: =IFERROR(D18/C18,"") -> 8452.07
A19: El Paso | B19: 471363 | C19: =B19/30 -> 15712.1 | D19: ='16'!$E$33 -> 81085589 | E19: =IFERROR(D19/C19,"") -> 5160.7098
A20: Frank Phillips | B20: 26276 | C20: =B20/30 -> 875.86667 | D20: ='17'!$E$33 -> 5764019 | E20: =IFERROR(D20/C20,"") -> 6580.932
A21: Galveston | B21: 40208 | C21: =B21/30 -> 1340.2667 | D21: ='18'!$E$33 -> 0 | E21: =IFERROR(D21/C21,"") -> 0
A22: Grayson | B22: 82457 | C22: =B22/30 -> 2748.5667 | D22: ='19'!$E$33 -> 13664320 | E22: =IFERROR(D22/C22,"") -> 4971.4348
A23: Hill | B23: 70448 | C23: =B23/30 -> 2348.2667 | D23: ='20'!$E$33 -> 10335070 | E23: =IFERROR(D23/C23,"") -> 4401.1484
A24: Houston | B24: 846337 | C24: =B24/30 -> 28211.233 | D24: ='21'!$E$33 -> 166950232 | E24: =IFERROR(D24/C24,"") -> 5917.8636
A25: Howard | B25: 61090 | C25: =B25/30 -> 2036.3333 | D25: ='22'!$E$33 -> 15565901 | E25: =IFERROR(D25/C25,"") -> 7644.083
A26: Kilgore | B26: 115663 | C26: =B26/30 -> 3855.4333 | D26: ='23'!$E$33 -> 18384957 | E26: =IFERROR(D26/C26,"") -> 4768.5838
A27: Laredo | B27: 154193 | C27: =B27/30 -> 5139.7667 | D27: ='24'!$E$33 -> 33753934 | E27: =IFERROR(D27/C27,"") -> 6567.2114
A28: Lee | B28: 125718 | C28: =B28/30 -> 4190.6 | D28: ='25'!$E$33 -> 29033951 | E28: =IFERROR(D28/C28,"") -> 6928.3518
A29: Lonestar | B29: 832324 | C29: =B29/30 -> 27744.133 | D29: ='26'!$E$33 -> 1.5254139e+08 | E29: =IFERROR(D29/C29,"") -> 5498.1494
A30: Mclennan | B30: 174178 | C30: =B30/30 -> 5805.9333 | D30: ='27'!$E$33 -> 29680633 | E30: =IFERROR(D30/C30,"") -> 5112.1209
A31: Midland | B31: 111509 | C31: =B31/30 -> 3716.9667 | D31: ='28'!$E$33 -> 26095442 | E31: =IFERROR(D31/C31,"") -> 7020.6285
A32: Navarro | B32: 165450 | C32: =B32/30 -> 5515 | D32: ='29'!$E$33 -> 19666734 | E32: =IFERROR(D32/C32,"") -> 3566.0442
A33: North Central Texas | B33: 145014 | C33: =B33/30 -> 4833.8 | D33: ='30'!$E$33 -> 16235310 | E33: =IFERROR(D33/C33,"") -> 3358.7054
A34: Northeast Texas | B34: 52949 | C34: =B34/30 -> 1764.9667 | D34: ='31'!$E$33 -> 8929016 | E34: =IFERROR(D34/C34,"") -> 5059.0281
A35: Odessa | B35: 85524 | C35: =B35/30 -> 2850.8 | D35: ='32'!$E$33 -> 19384637 | E35: =IFERROR(D35/C35,"") -> 6799.7183
A36: Panola | B36: 40729 | C36: =B36/30 -> 1357.6333 | D36: ='33'!$E$33 -> 8985085 | E36: =IFERROR(D36/C36,"") -> 6618.1971
A37: Paris | B37: 90017 | C37: =B37/30 -> 3000.5667 | D37: ='34'!$E$33 -> 12682934 | E37: =IFERROR(D37/C37,"") -> 4226.8463
A38: Ranger | B38: 18238 | C38: =B38/30 -> 607.93333 | D38: ='35'!$E$33 -> 2678849 | E38: =IFERROR(D38/C38,"") -> 4406.4848
A39: San Jacinto | B39: 476825 | C39: =B39/30 -> 15894.167 | D39: ='36'!$E$33 -> 91234511 | E39: =IFERROR(D39/C39,"") -> 5740.1255
A40: South Plains | B40: 192922 | C40: =B40/30 -> 6430.7333 | D40: ='37'!$E$33 -> 27138670 | E40: =IFERROR(D40/C40,"") -> 4220.1517
...

Sheet Discipline Summary
A1: =Summary!A1 -> Community and Technical Colleges, Report of Fundable Operating Expenses, Fiscal Year (FY) 2008
A2: Discipline Summary of Expense per Contact Hour by Institution
A3: Institution | B3: AG | C3: ARCH | D3: SCI | E3: BA | F3: CP | G3: COMM | H3: CS | I3: CNSTR | J3: HE | K3: ENG | L3: ENGR | M3: LA | N3: FL | O3: HODA | P3: HODH | Q3: HOO | R3: HORT | S3: NUR | T3: MATH | U3: AUTO | V3: MECH | W3: ELECT | X3: PE | Y3: PA | Z3: SS | AA3: FA | AB3: DEM | AC3: DER | AD3: Total
A4: Alamo | B4: ='1'!$F$5 -> 6.93 | C4: ='1'!$F$6 -> 12.48 | D4: ='1'!$F$7 -> 9.03 | E4: ='1'!$F$8 -> 9.83 | F4: ='1'!$F$9 -> 36.07 | G4: ='1'!$F$10 -> 10.5 | H4: ='1'!$F$11 -> 10.79 | I4: ='1'!$F$12 -> 11.76 | J4: ='1'!$F$13 -> 8.76 | K4: ='1'!$F$14 -> 15.24 | L4: ='1'!$F$15 -> 13.35 | M4: ='1'!$F$16 -> 9.3 | N4: ='1'!$F$17 -> 7.7 | O4: ='1'!$F$18 -> 15.39 | P4: ='1'!$F$19 | Q4: ='1'!$F$20 -> 9.88 | R4: ='1'!$F$21 -> 15.1 | S4: ='1'!$F$22 -> 10.47 | T4: ='1'!$F$23 -> 8.65 | U4: ='1'!$F$24 -> 10.37 | V4: ='1'!$F$25 -> 12.62 | W4: ='1'!$F$26 -> 4.95 | X4: ='1'!$F$27 -> 9.82 | Y4: ='1'!$F$28 -> 9 | Z4: ='1'!$F$29 -> 8.28 | AA4: ='1'!$F$30 -> 10.18 | AB4: ='1'!$F$31 | AC4: ='1'!$F$32 | AD4: ='1'!$F$33 -> 9.43
A5: Alvin | B5: ='2'!$F$5 -> 5.33 | C5: ='2'!$F$6 -> 9.53 | D5: ='2'!$F$7 -> 6.06 | E5: ='2'!$F$8 -> 9.56 | F5: ='2'!$F$9 | G5: ='2'!$F$10 -> 8.89 | H5: ='2'!$F$11 -> 10.72 | I5: ='2'!$F$12 -> 14.76 | J5: ='2'!$F$13 -> 7.83 | K5: ='2'!$F$14 | L5: ='2'!$F$15 -> 7.58 | M5: ='2'!$F$16 -> 7.7 | N5: ='2'!$F$17 -> 8.7 | O5: ='2'!$F$18 -> 10.72 | P5: ='2'!$F$19 | Q5: ='2'!$F$20 -> 10.54 | R5: ='2'!$F$21 -> 12.37 | S5: ='2'!$F$22 -> 10.06 | T5: ='2'!$F$23 -> 7.24 | U5: ='2'!$F$24 -> 7.61 | V5: ='2'!$F$25 -> 17.98 | W5: ='2'!$F$26 -> 12.56 | X5: ='2'!$F$27 -> 10.16 | Y5: ='2'!$F$28 -> 7.6 | Z5: ='2'!$F$29 -> 7.48 | AA5: ='2'!$F$30 -> 12.81 | AB5: ='2'!$F$31 | AC5: ='2'!$F$32 | AD5: ='2'!$F$33 -> 8.68
A6: Amarillo | B6: ='3'!$F$5 -> 7.44 | C6: ='3'!$F$6 -> 7.96 | D6: ='3'!$F$7 -> 7.13 | E6: ='3'!$F$8 -> 7.78 | F6: ='3'!$F$9 | G6: ='3'!$F$10 -> 7.74 | H6: ='3'!$F$11 -> 7.74 | I6: ='3'!$F$12 -> 8.27 | J6: ='3'!$F$13 -> 6.74 | K6: ='3'!$F$14 -> 7.12 | L6: ='3'!$F$15 -> 7.74 | M6: ='3'!$F$16 -> 8.34 | N6: ='3'!$F$17 -> 7.5 | O6: ='3'!$F$18 -> 8.32 | P6: ='3'!$F$19 -> 8.06 | Q6: ='3'!$F$20 -> 7.93 | R6: ='3'!$F$21 -> 8.16 | S6: ='3'!$F$22 -> 8.47 | T6: ='3'!$F$23 -> 7.29 | U6: ='3'!$F$24 -> 7.96 | V6: ='3'!$F$25 -> 7.96 | W6: ='3'!$F$26 -> 7.58 | X6: ='3'!$F$27 -> 5.6 | Y6: ='3'!$F$28 -> 7.42 | Z6: ='3'!$F$29 -> 5.79 | AA6: ='3'!$F$30 -> 7.48 | AB6: ='3'!$F$31 | AC6: ='3'!$F$32 | AD6: ='3'!$F$33 -> 7.45
A7: Angelina | B7: ='4'!$F$5 | C7: ='4'!$F$6 -> 8.46 | D7: ='4'!$F$7 -> 5.39 | E7: ='4'!$F$8 -> 5.65 | F7: ='4'!$F$9 | G7: ='4'!$F$10 -> 12.59 | H7: ='4'!$F$11 -> 10.21 | I7: ='4'!$F$12 -> 5.61 | J7: ='4'!$F$13 -> 6.66 | K7: ='4'!$F$14 -> 12.31 | L7: ='4'!$F$15 -> 5.61 | M7: ='4'!$F$16 -> 5.37 | N7: ='4'!$F$17 -> 5.46 | O7: ='4'!$F$18 -> 9.58 | P7: ='4'!$F$19 | Q7: ='4'!$F$20 -> 5.85 | R7: ='4'!$F$21 -> 7.98 | S7: ='4'!$F$22 -> 6.24 | T7: ='4'!$F$23 -> 6.83 | U7: ='4'!$F$24 -> 9.2 | V7: ='4'!$F$25 -> 7.98 | W7: ='4'!$F$26 -> 5.66 | X7: ='4'!$F$27 -> 6.39 | Y7: ='4'!$F$28 -> 5.93 | Z7: ='4'!$F$29 -> 5.28 | AA7: ='4'!$F$30 -> 7.49 | AB7: ='4'!$F$31 | AC7: ='4'!$F$32 | AD7: ='4'!$F$33 -> 6.3
A8: Austin | B8: ='5'!$F$5 -> 6.53 | C8: ='5'!$F$6 -> 15.75 | D8: ='5'!$F$7 -> 10.89 | E8: ='5'!$F$8 -> 9.69 | F8: ='5'!$F$9 | G8: ='5'!$F$10 -> 9.36 | H8: ='5'!$F$11 -> 16.63 | I8: ='5'!$F$12 -> 5.84 | J8: ='5'!$F$13 -> 14.69 | K8: ='5'!$F$14 -> 16.99 | L8: ='5'!$F$15 -> 12.33 | M8: ='5'!$F$16 -> 9.87 | N8: ='5'!$F$17 -> 9.5 | O8: ='5'!$F$18 -> 15.12 | P8: ='5'!$F$19 -> 32.54 | Q8: ='5'!$F$20 -> 15.01 | R8: ='5'!$F$21 | S8: ='5'!$F$22 -> 16.87 | T8: ='5'!$F$23 -> 8.99 | U8: ='5'!$F$24 -> 14.52 | V8: ='5'!$F$25 -> 12.64 | W8: ='5'!$F$26 -> 4.93 | X8: ='5'!$F$27 -> 9.84 | Y8: ='5'!$F$28 -> 9.1 | Z8: ='5'!$F$29 -> 8.47 | AA8: ='5'!$F$30 -> 14.03 | AB8: ='5'!$F$31 | AC8: ='5'!$F$32 | AD8: ='5'!$F$33 -> 10.6
A9: Blinn | B9: ='6'!$F$5 -> 6.53 | C9: ='6'!$F$6 -> 12.83 | D9: ='6'!$F$7 -> 4.78 | E9: ='6'!$F$8 -> 7.02 | F9: ='6'!$F$9 | G9: ='6'!$F$10 -> 4.45 | H9: ='6'!$F$11 -> 16.77 | I9: ='6'!$F$12 -> 12.83 | J9: ='6'!$F$13 -> 3.87 | K9: ='6'!$F$14 | L9: ='6'!$F$15 -> 9.04 | M9: ='6'!$F$16 -> 6.49 | N9: ='6'!$F$17 -> 6.12 | O9: ='6'!$F$18 -> 13.47 | P9: ='6'!$F$19 -> 21.61 | Q9: ='6'!$F$20 -> 6.87 | R9: ='6'!$F$21 | S9: ='6'!$F$22 -> 7.27 | T9: ='6'!$F$23 -> 5.71 | U9: ='6'!$F$24 -> 12.83 | V9: ='6'!$F$25 -> 12.83 | W9: ='6'!$F$26 -> 12.83 | X9: ='6'!$F$27 -> 6.76 | Y9: ='6'!$F$28 -> 5.07 | Z9: ='6'!$F$29 -> 4.8 | AA9: ='6'!$F$30 -> 6.51 | AB9: ='6'!$F$31 | AC9: ='6'!$F$32 | AD9: ='6'!$F$33 -> 6.04
A10: Brazosport | B10: ='7'!$F$5 | C10: ='7'!$F$6 -> 9.46 | D10: ='7'!$F$7 -> 9.57 | E10: ='7'!$F$8 -> 10.16 | F10: ='7'!$F$9 | G10: ='7'!$F$10 -> 5.14 | H10: ='7'!$F$11 -> 15.6 | I10: ='7'!$F$12 -> 8.81 | J10: ='7'!$F$13 -> 8.41 | K10: ='7'!$F$14 | L10: ='7'!$F$15 -> 6.72 | M10: ='7'!$F$16 -> 9.24 | N10: ='7'!$F$17 -> 9.21 | O10: ='7'!$F$18 -> 37.39 | P10: ='7'!$F$19 | Q10: ='7'!$F$20 -> 15.62 | R10: ='7'!$F$21 | S10: ='7'!$F$22 -> 13.83 | T10: ='7'!$F$23 -> 8.66 | U10: ='7'!$F$24 -> 9.22 | V10: ='7'!$F$25 | W10: ='7'!$F$26 -> 13.48 | X10: ='7'!$F$27 -> 10.68 | Y10: ='7'!$F$28 -> 8.3 | Z10: ='7'!$F$29 -> 8.33 | AA10: ='7'!$F$30 -> 14.11 | AB10: ='7'!$F$31 | AC10: ='7'!$F$32 | AD10: ='7'!$F$33 -> 9.54
A11: Central Texas | B11: ='8'!$F$5 -> 5.2 | C11: ='8'!$F$6 -> 12.49 | D11: ='8'!$F$7 -> 7.2 | E11: ='8'!$F$8 -> 6.79 | F11: ='8'!$F$9 -> 56.23 | G11: ='8'!$F$10 -> 7.41 | H11: ='8'!$F$11 -> 14.68 | I11: ='8'!$F$12 -> 8.98 | J11: ='8'!$F$13 -> 5.46 | K11: ='8'!$F$14 -> 2.98 | L11: ='8'!$F$15 -> 3.46 | M11: ='8'!$F$16 -> 6.71 | N11: ='8'!$F$17 -> 7.37 | O11: ='8'!$F$18 -> 11.72 | P11: ='8'!$F$19 | Q11: ='8'!$F$20 -> 9.54 | R11: ='8'!$F$21 | S11: ='8'!$F$22 -> 9.11 | T11: ='8'!$F$23 -> 5.88 | U11: ='8'!$F$24 -> 9.71 | V11: ='8'!$F$25 -> 6.87 | W11: ='8'!$F$26 -> 17.9 | X11: ='8'!$F$27 -> 7.67 | Y11: ='8'!$F$28 -> 8.2 | Z11: ='8'!$F$29 -> 5.79 | AA11: ='8'!$F$30 -> 6.62 | AB11: ='8'!$F$31 | AC11: ='8'!$F$32 | AD11: ='8'!$F$33 -> 7.74
A12: Cisco | B12: ='9'!$F$5 -> 9.89 | C12: ='9'!$F$6 -> 6.05 | D12: ='9'!$F$7 -> 4.79 | E12: ='9'!$F$8 -> 4.83 | F12: ='9'!$F$9 | G12: ='9'!$F$10 | H12: ='9'!$F$11 -> 17.6 | I12: ='9'!$F$12 -> 5.98 | J12: ='9'!$F$13 -> 5.3 | K12: ='9'!$F$14 | L12: ='9'!$F$15 -> 6.21 | M12: ='9'!$F$16 -> 5.81 | N12: ='9'!$F$17 -> 5.2 | O12: ='9'!$F$18 -> 6.53 | P12: ='9'!$F$19 | Q12: ='9'!$F$20 -> 4.41 | R12: ='9'!$F$21 -> 18.94 | S12: ='9'!$F$22 -> 7.26 | T12: ='9'!$F$23 -> 5.95 | U12: ='9'!$F$24 -> 7.77 | V12: ='9'!$F$25 | W12: ='9'!$F$26 | X12: ='9'!$F$27 -> 10.28 | Y12: ='9'!$F$28 -> 8.72 | Z12: ='9'!$F$29 -> 5.56 | AA12: ='9'!$F$30 -> 7.44 | AB12: ='9'!$F$31 | AC12: ='9'!$F$32 | AD12: ='9'!$F$33 -> 6.14
A13: Clarendon | B13: ='10'!$F$5 -> 10.25 | C13: ='10'!$F$6 | D13: ='10'!$F$7 -> 6.04 | E13: ='10'!$F$8 -> 5.84 | F13: ='10'!$F$9 | G13: ='10'!$F$10 | H13: ='10'!$F$11 -> 10.19 | I13: ='10'!$F$12 | J13: ='10'!$F$13 -> 3.96 | K13: ='10'!$F$14 | L13: ='10'!$F$15 -> 5.05 | M13: ='10'!$F$16 -> 6.08 | N13: ='10'!$F$17 -> 7.15 | O13: ='10'!$F$18 | P13: ='10'!$F$19 | Q13: ='10'!$F$20 -> 3.48 | R13: ='10'!$F$21 | S13: ='10'!$F$22 -> 6.96 | T13: ='10'!$F$23 -> 5.79 | U13: ='10'!$F$24 | V13: ='10'!$F$25 | W13: ='10'!$F$26 -> 4.09 | X13: ='10'!$F$27 -> 9.35 | Y13: ='10'!$F$28 -> 3.15 | Z13: ='10'!$F$29 -> 5.73 | AA13: ='10'!$F$30 -> 6.03 | AB13: ='10'!$F$31 | AC13: ='10'!$F$32 | AD13: ='10'!$F$33 -> 6.62
A14: Coastal Bend | B14: ='11'!$F$5 | C14: ='11'!$F$6 | D14: ='11'!$F$7 | E14: ='11'!$F$8 | F14: ='11'!$F$9 | G14: ='11'!$F$10 | H14: ='11'!$F$11 | I14: ='11'!$F$12 | J14: ='11'!$F$13 | K14: ='11'!$F$14 | L14: ='11'!$F$15 | M14: ='11'!$F$16 | N14: ='11'!$F$17 | O14: ='11'!$F$18 | P14: ='11'!$F$19 | Q14: ='11'!$F$20 | R14: ='11'!$F$21 | S14: ='11'!$F$22 | T14: ='11'!$F$23 | U14: ='11'!$F$24 | V14: ='11'!$F$25 | W14: ='11'!$F$26 | X14: ='11'!$F$27 | Y14: ='11'!$F$28 | Z14: ='11'!$F$29 | AA14: ='11'!$F$30 | AB14: ='11'!$F$31 | AC14: ='11'!$F$32 | AD14: ='11'!$F$33
A15: College Of The Mainland | B15: ='12'!$F$5 -> 7.62 | C15: ='12'!$F$6 -> 27.1 | D15: ='12'!$F$7 -> 10.85 | E15: ='12'!$F$8 -> 12.8 | F15: ='12'!$F$9 | G15: ='12'!$F$10 -> 7.62 | H15: ='12'!$F$11 -> 21.16 | I15: ='12'!$F$12 -> 9.61 | J15: ='12'!$F$13 -> 20.2 | K15: ='12'!$F$14 | L15: ='12'!$F$15 -> 8.25 | M15: ='12'!$F$16 -> 11.92 | N15: ='12'!$F$17 -> 11.97 | O15: ='12'!$F$18 -> 20.29 | P15: ='12'!$F$19 | Q15: ='12'!$F$20 -> 12.61 | R15: ='12'!$F$21 | S15: ='12'!$F$22 -> 17.8 | T15: ='12'!$F$23 -> 11.29 | U15: ='12'!$F$24 | V15: ='12'!$F$25 | W15: ='12'!$F$26 -> 9.64 | X15: ='12'!$F$27 -> 12.89 | Y15: ='12'!$F$28 -> 15.59 | Z15: ='12'!$F$29 -> 13.2 | AA15: ='12'!$F$30 -> 17.18 | AB15: ='12'!$F$31 | AC15: ='12'!$F$32 | AD15: ='12'!$F$33 -> 13.81
A16: Collin | B16: ='13'!$F$5 -> 6.59 | C16: ='13'!$F$6 -> 9.96 | D16: ='13'!$F$7 -> 7.46 | E16: ='13'!$F$8 -> 7.92 | F16: ='13'!$F$9 -> 3.54 | G16: ='13'!$F$10 -> 9.47 | H16: ='13'!$F$11 -> 7.26 | I16: ='13'!$F$12 -> 10.01 | J16: ='13'!$F$13 -> 7.41 | K16: ='13'!$F$14 -> 14.08 | L16: ='13'!$F$15 -> 16.19 | M16: ='13'!$F$16 -> 7.45 | N16: ='13'!$F$17 -> 6.66 | O16: ='13'!$F$18 -> 16.05 | P16: ='13'!$F$19 -> 29.51 | Q16: ='13'!$F$20 -> 10.55 | R16: ='13'!$F$21 -> 12.88 | S16: ='13'!$F$22 | T16: ='13'!$F$23 -> 6.92 | U16: ='13'!$F$24 | V16: ='13'!$F$25 | W16: ='13'!$F$26 -> 4.88 | X16: ='13'!$F$27 -> 8.5 | Y16: ='13'!$F$28 -> 11.22 | Z16: ='13'!$F$29 -> 6.57 | AA16: ='13'!$F$30 -> 10.28 | AB16: ='13'!$F$31 | AC16: ='13'!$F$32 | AD16: ='13'!$F$33 -> 7.91
A17: Dallas | B17: ='14'!$F$5 -> 15.27 | C17: ='14'!$F$6 -> 11.16 | D17: ='14'!$F$7 -> 7.91 | E17: ='14'!$F$8 -> 8.28 | F17: ='14'!$F$9 -> 13.04 | G17: ='14'!$F$10 -> 7.96 | H17: ='14'!$F$11 -> 8.24 | I17: ='14'!$F$12 -> 11.99 | J17: ='14'!$F$13 -> 7.29 | K17: ='14'!$F$14 -> 10.11 | L17: ='14'!$F$15 -> 6.03 | M17: ='14'!$F$16 -> 8.34 | N17: ='14'!$F$17 -> 7.18 | O17: ='14'!$F$18 -> 12.27 | P17: ='14'!$F$19 | Q17: ='14'!$F$20 -> 7.89 | R17: ='14'!$F$21 -> 17.52 | S17: ='14'!$F$22 -> 12.73 | T17: ='14'!$F$23 -> 7.33 | U17: ='14'!$F$24 -> 9.5 | V17: ='14'!$F$25 -> 6.08 | W17: ='14'!$F$26 -> 12.78 | X17: ='14'!$F$27 -> 9.12 | Y17: ='14'!$F$28 -> 6.66 | Z17: ='14'!$F$29 -> 6.94 | AA17: ='14'!$F$30 -> 9.09 | AB17: ='14'!$F$31 | AC17: ='14'!$F$32 | AD17: ='14'!$F$33 -> 8
A18: Del Mar | B18: ='15'!$F$5 -> 9.51 | C18: ='15'!$F$6 -> 11.75 | D18: ='15'!$F$7 -> 9.64 | E18: ='15'!$F$8 -> 11.73 | F18: ='15'!$F$9 | G18: ='15'!$F$10 -> 12.93 | H18: ='15'!$F$11 -> 10.65 | I18: ='15'!$F$12 -> 8.82 | J18: ='15'!$F$13 -> 11.11 | K18: ='15'!$F$14 -> 12.43 | L18: ='15'!$F$15 -> 11.48 | M18: ='15'!$F$16 -> 12.02 | N18: ='15'!$F$17 -> 10.84 | O18: ='15'!$F$18 -> 15 | P18: ='15'!$F$19 -> 21.76 | Q18: ='15'!$F$20 -> 11.06 | R18: ='15'!$F$21 -> 24.55 | S18: ='15'!$F$22 -> 13.81 | T18: ='15'!$F$23 -> 11.74 | U18: ='15'!$F$24 -> 11.75 | V18: ='15'!$F$25 -> 11.52 | W18: ='15'!$F$26 -> 14.26 | X18: ='15'!$F$27 -> 10.21 | Y18: ='15'!$F$28 -> 12.18 | Z18: ='15'!$F$29 -> 9.73 | AA18: ='15'!$F$30 -> 14.28 | AB18: ='15'!$F$31 | AC18: ='15'!$F$32 | AD18: ='15'!$F$33 -> 11.64
A19: El Paso | B19: ='16'!$F$5 -> 8.63 | C19: ='16'!$F$6 -> 18.43 | D19: ='16'!$F$7 -> 7.34 | E19: ='16'!$F$8 -> 8.7 | F19: ='16'!$F$9 | G19: ='16'!$F$10 -> 8.01 | H19: ='16'!$F$11 -> 10.75 | I19: ='16'!$F$12 -> 5.55 | J19: ='16'!$F$13 -> 5.92 | K19: ='16'!$F$14 -> 7.67 | L19: ='16'!$F$15 -> 5.48 | M19: ='16'!$F$16 -> 9.77 | N19: ='16'!$F$17 -> 6.63 | O19: ='16'!$F$18 -> 14.41 | P19: ='16'!$F$19 -> 15.19 | Q19: ='16'!$F$20 -> 12.84 | R19: ='16'!$F$21 -> 16.07 | S19: ='16'!$F$22 -> 7 | T19: ='16'!$F$23 -> 7.08 | U19: ='16'!$F$24 -> 9.7 | V19: ='16'!$F$25 -> 15.44 | W19: ='16'!$F$26 -> 4.46 | X19: ='16'!$F$27 -> 23.39 | Y19: ='16'!$F$28 -> 9.06 | Z19: ='16'!$F$29 -> 6.69 | AA19: ='16'!$F$30 -> 7.76 | AB19: ='16'!$F$31 | AC19: ='16'!$F$32 | AD19: ='16'!$F$33 -> 8.42
A20: Frank Phillips | B20: ='17'!$F$5 -> 9.77 | C20: ='17'!$F$6 -> 9.3 | D20: ='17'!$F$7 -> 7.12 | E20: ='17'!$F$8 -> 7.09 | F20: ='17'!$F$9 | G20: ='17'!$F$10 -> 3.6 | H20: ='17'!$F$11 -> 15.08 | I20: ='17'!$F$12 -> 13.47 | J20: ='17'!$F$13 -> 7.63 | K20: ='17'!$F$14 -> 67.81 | L20: ='17'!$F$15 -> 9.76 | M20: ='17'!$F$16 -> 7.12 | N20: ='17'!$F$17 -> 5.3 | O20: ='17'!$F$18 -> 6.96 | P20: ='17'!$F$19 | Q20: ='17'!$F$20 -> 6.96 | R20: ='17'!$F$21 | S20: ='17'!$F$22 -> 7.31 | T20: ='17'!$F$23 -> 7.19 | U20: ='17'!$F$24 | V20: ='17'!$F$25 -> 5.39 | W20: ='17'!$F$26 -> 5.85 | X20: ='17'!$F$27 -> 7.24 | Y20: ='17'!$F$28 -> 5.52 | Z20: ='17'!$F$29 -> 6.92 | AA20: ='17'!$F$30 -> 8.83 | AB20: ='17'!$F$31 | AC20: ='17'!$F$32 | AD20: ='17'!$F$33 -> 8.28
A21: Galveston | B21: ='18'!$F$5 | C21: ='18'!$F$6 | D21: ='18'!$F$7 | E21: ='18'!$F$8 | F21: ='18'!$F$9 | G21: ='18'!$F$10 | H21: ='18'!$F$11 | I21: ='18'!$F$12 | J21: ='18'!$F$13 | K21: ='18'!$F$14 | L21: ='18'!$F$15 | M21: ='18'!$F$16 | N21: ='18'!$F$17 | O21: ='18'!$F$18 | P21: ='18'!$F$19 | Q21: ='18'!$F$20 | R21: ='18'!$F$21 | S21: ='18'!$F$22 | T21: ='18'!$F$23 | U21: ='18'!$F$24 | V21: ='18'!$F$25 | W21: ='18'!$F$26 | X21: ='18'!$F$27 | Y21: ='18'!$F$28 | Z21: ='18'!$F$29 | AA21: ='18'!$F$30 | AB21: ='18'!$F$31 | AC21: ='18'!$F$32 | AD21: ='18'!$F$33
A22: Grayson | B22: ='19'!$F$5 -> 8.93 | C22: ='19'!$F$6 -> 11.85 | D22: ='19'!$F$7 -> 6.31 | E22: ='19'!$F$8 -> 7.54 | F22: ='19'!$F$9 | G22: ='19'!$F$10 -> 3.06 | H22: ='19'!$F$11 -> 8.28 | I22: ='19'!$F$12 -> 3.06 | J22: ='19'!$F$13 -> 5.26 | K22: ='19'!$F$14 -> 3.06 | L22: ='19'!$F$15 -> 6.01 | M22: ='19'!$F$16 -> 6.08 | N22: ='19'!$F$17 -> 6.22 | O22: ='19'!$F$18 -> 9.89 | P22: ='19'!$F$19 | Q22: ='19'!$F$20 -> 6.76 | R22: ='19'!$F$21 | S22: ='19'!$F$22 -> 8.39 | T22: ='19'!$F$23 -> 5.82 | U22: ='19'!$F$24 -> 7.37 | V22: ='19'!$F$25 -> 3.06 | W22: ='19'!$F$26 -> 18.29 | X22: ='19'!$F$27 -> 18.88 | Y22: ='19'!$F$28 -> 6.93 | Z22: ='19'!$F$29 -> 5.8 | AA22: ='19'!$F$30 -> 7.86 | AB22: ='19'!$F$31 | AC22: ='19'!$F$32 | AD22: ='19'!$F$33 -> 7.02
A23: Hill | B23: ='20'!$F$5 -> 12.33 | C23: ='20'!$F$6 -> 6.45 | D23: ='20'!$F$7 -> 5.34 | E23: ='20'!$F$8 -> 4.13 | F23: ='20'!$F$9 | G23: ='20'!$F$10 -> 8.12 | H23: ='20'!$F$11 -> 6.52 | I23: ='20'!$F$12 -> 8.16 | J23: ='20'!$F$13 -> 5.21 | K23: ='20'!$F$14 | L23: ='20'!$F$15 -> 4.63 | M23: ='20'!$F$16 -> 4.87 | N23: ='20'!$F$17 -> 4.65 | O23: ='20'!$F$18 -> 6.49 | P23: ='20'!$F$19 | Q23: ='20'!$F$20 -> 4.23 | R23: ='20'!$F$21 | S23: ='20'!$F$22 -> 9.69 | T23: ='20'!$F$23 -> 5.19 | U23: ='20'!$F$24 -> 4.72 | V23: ='20'!$F$25 -> 8.12 | W23: ='20'!$F$26 -> 8.12 | X23: ='20'!$F$27 -> 9.5 | Y23: ='20'!$F$28 -> 6.84 | Z23: ='20'!$F$29 -> 5.22 | AA23: ='20'!$F$30 -> 6.32 | AB23: ='20'!$F$31 | AC23: ='20'!$F$32 | AD23: ='20'!$F$33 -> 5.78
A24: Houston | B24: ='21'!$F$5 -> 8.36 | C24: ='21'!$F$6 -> 8.58 | D24: ='21'!$F$7 -> 7.74 | E24: ='21'!$F$8 -> 8.08 | F24: ='21'!$F$9 | G24: ='21'!$F$10 -> 7.31 | H24: ='21'!$F$11 -> 19.81 | I24: ='21'!$F$12 -> 9.44 | J24: ='21'!$F$13 -> 7.87 | K24: ='21'!$F$14 -> 9.2 | L24: ='21'!$F$15 -> 9.11 | M24: ='21'!$F$16 -> 8.74 | N24: ='21'!$F$17 -> 8.26 | O24: ='21'!$F$18 -> 10.69 | P24: ='21'!$F$19 | Q24: ='21'!$F$20 -> 11.58 | R24: ='21'!$F$21 -> 14.44 | S24: ='21'!$F$22 -> 13.33 | T24: ='21'!$F$23 -> 7.72 | U24: ='21'!$F$24 -> 10.25 | V24: ='21'!$F$25 -> 15.16 | W24: ='21'!$F$26 -> 8.8 | X24: ='21'!$F$27 -> 11.47 | Y24: ='21'!$F$28 -> 9.81 | Z24: ='21'!$F$29 -> 7.48 | AA24: ='21'!$F$30 -> 9.47 | AB24: ='21'!$F$31 | AC24: ='21'!$F$32 | AD24: ='21'!$F$33 -> 8.64
A25: Howard | B25: ='22'!$F$5 -> 5.98 | C25: ='22'!$F$6 -> 6.79 | D25: ='22'!$F$7 -> 6.26 | E25: ='22'!$F$8 -> 4.45 | F25: ='22'!$F$9 | G25: ='22'!$F$10 -> 4.49 | H25: ='22'!$F$11 -> 6.47 | I25: ='22'!$F$12 -> 7.99 | J25: ='22'!$F$13 -> 4.41 | K25: ='22'!$F$14 | L25: ='22'!$F$15 -> 7.52 | M25: ='22'!$F$16 -> 10.16 | N25: ='22'!$F$17 -> 7.34 | O25: ='22'!$F$18 -> 14.13 | P25: ='22'!$F$19 -> 16.56 | Q25: ='22'!$F$20 -> 7.58 | R25: ='22'!$F$21 -> 12.82 | S25: ='22'!$F$22 -> 8.12 | T25: ='22'!$F$23 -> 5.34 | U25: ='22'!$F$24 -> 48.31 | V25: ='22'!$F$25 -> 7.69 | W25: ='22'!$F$26 -> 7.26 | X25: ='22'!$F$27 -> 19.12 | Y25: ='22'!$F$28 -> 6.29 | Z25: ='22'!$F$29 -> 5.66 | AA25: ='22'!$F$30 -> 7.27 | AB25: ='22'!$F$31 | AC25: ='22'!$F$32 | AD25: ='22'!$F$33 -> 6.8
A26: Kilgore | B26: ='23'!$F$5 -> 10.64 | C26: ='23'!$F$6 -> 7.96 | D26: ='23'!$F$7 -> 6.05 | E26: ='23'!$F$8 -> 5.06 | F26: ='23'!$F$9 | G26: ='23'!$F$10 -> 9.81 | H26: ='23'!$F$11 -> 3.66 | I26: ='23'!$F$12 -> 2.22 | J26: ='23'!$F$13 -> 5.2 | K26: ='23'!$F$14 -> 24.95 | L26: ='23'!$F$15 -> 7.15 | M26: ='23'!$F$16 -> 5.06 | N26: ='23'!$F$17 -> 9.5 | O26: ='23'!$F$18 -> 6.36 | P26: ='23'!$F$19 | Q26: ='23'!$F$20 -> 6.19 | R26: ='23'!$F$21 | S26: ='23'!$F$22 -> 5.94 | T26: ='23'!$F$23 -> 5.11 | U26: ='23'!$F$24 -> 7.09 | V26: ='23'!$F$25 -> 5.84 | W26: ='23'!$F$26 -> 2.3 | X26: ='23'!$F$27 -> 6.95 | Y26: ='23'!$F$28 -> 4.39 | Z26: ='23'!$F$29 -> 4.31 | AA26: ='23'!$F$30 -> 6.51 | AB26: ='23'!$F$31 | AC26: ='23'!$F$32 | AD26: ='23'!$F$33 -> 5.33
A27: Laredo | B27: ='24'!$F$5 | C27: ='24'!$F$6 | D27: ='24'!$F$7 -> 9.27 | E27: ='24'!$F$8 -> 10.74 | F27: ='24'!$F$9 | G27: ='24'!$F$10 -> 8.4 | H27: ='24'!$F$11 -> 11.07 | I27: ='24'!$F$12 -> 10.1 | J27: ='24'!$F$13 | K27: ='24'!$F$14 | L27: ='24'!$F$15 | M27: ='24'!$F$16 -> 12.29 | N27: ='24'!$F$17 -> 10.95 | O27: ='24'!$F$18 -> 15.58 | P27: ='24'!$F$19 | Q27: ='24'!$F$20 -> 11 | R27: ='24'!$F$21 | S27: ='24'!$F$22 -> 17.03 | T27: ='24'!$F$23 -> 8.74 | U27: ='24'!$F$24 -> 22.85 | V27: ='24'!$F$25 | W27: ='24'!$F$26 -> 11.07 | X27: ='24'!$F$27 -> 9.92 | Y27: ='24'!$F$28 -> 11.3 | Z27: ='24'!$F$29 -> 8.01 | AA27: ='24'!$F$30 -> 12.6 | AB27: ='24'!$F$31 | AC27: ='24'!$F$32 | AD27: ='24'!$F$33 -> 10.58
A28: Lee | B28: ='25'!$F$5 -> 7.12 | C28: ='25'!$F$6 -> 13.32 | D28: ='25'!$F$7 -> 8.97 | E28: ='25'!$F$8 -> 8.08 | F28: ='25'!$F$9 -> 4.5 | G28: ='25'!$F$10 -> 10.91 | H28: ='25'!$F$11 -> 10.67 | I28: ='25'!$F$12 -> 13.63 | J28: ='25'!$F$13 -> 7.33 | K28: ='25'!$F$14 | L28: ='25'!$F$15 -> 7.56 | M28: ='25'!$F$16 -> 11.46 | N28: ='25'!$F$17 -> 9.03 | O28: ='25'!$F$18 -> 11.69 | P28: ='25'!$F$19 | Q28: ='25'!$F$20 -> 27.66 | R28: ='25'!$F$21 | S28: ='25'!$F$22 -> 13.22 | T28: ='25'!$F$23 -> 10.6 | U28: ='25'!$F$24 -> 7.65 | V28: ='25'!$F$25 -> 8.02 | W28: ='25'!$F$26 -> 4.5 | X28: ='25'!$F$27 -> 20.06 | Y28: ='25'!$F$28 -> 6.99 | Z28: ='25'!$F$29 -> 9 | AA28: ='25'!$F$30 -> 11.05 | AB28: ='25'!$F$31 | AC28: ='25'!$F$32 | AD28: ='25'!$F$33 -> 10
A29: Lonestar | B29: ='26'!$F$5 -> 9.74 | C29: ='26'!$F$6 -> 8.95 | D29: ='26'!$F$7 -> 8.25 | E29: ='26'!$F$8 -> 8.68 | F29: ='26'!$F$9 -> 4.43 | G29: ='26'!$F$10 -> 6.32 | H29: ='26'!$F$11 -> 8.93 | I29: ='26'!$F$12 -> 9.2 | J29: ='26'!$F$13 -> 7.52 | K29: ='26'!$F$14 -> 17.99 | L29: ='26'!$F$15 -> 10.95 | M29: ='26'!$F$16 -> 8.9 | N29: ='26'!$F$17 -> 7.7 | O29: ='26'!$F$18 -> 12.49 | P29: ='26'!$F$19 -> 22.52 | Q29: ='26'!$F$20 -> 10.62 | R29: ='26'!$F$21 -> 14.16 | S29: ='26'!$F$22 -> 9.78 | T29: ='26'!$F$23 -> 7.84 | U29: ='26'!$F$24 -> 8.77 | V29: ='26'!$F$25 -> 15.47 | W29: ='26'!$F$26 -> 8.87 | X29: ='26'!$F$27 -> 9.49 | Y29: ='26'!$F$28 -> 8.4 | Z29: ='26'!$F$29 -> 7.66 | AA29: ='26'!$F$30 -> 10.64 | AB29: ='26'!$F$31 | AC29: ='26'!$F$32 | AD29: ='26'!$F$33 -> 8.7
A30: Mclennan | B30: ='27'!$F$5 -> 16.59 | C30: ='27'!$F$6 | D30: ='27'!$F$7 -> 5.91 | E30: ='27'!$F$8 -> 7.31 | F30: ='27'!$F$9 | G30: ='27'!$F$10 -> 3.37 | H30: ='27'!$F$11 -> 13.57 | I30: ='27'!$F$12 | J30: ='27'!$F$13 -> 9.95 | K30: ='27'!$F$14 -> 3.01 | L30: ='27'!$F$15 -> 6.41 | M30: ='27'!$F$16 -> 7.72 | N30: ='27'!$F$17 -> 5.83 | O30: ='27'!$F$18 -> 13.28 | P30: ='27'!$F$19 | Q30: ='27'!$F$20 -> 8.45 | R30: ='27'!$F$21 -> 9.43 | S30: ='27'!$F$22 -> 7.56 | T30: ='27'!$F$23 -> 6.56 | U30: ='27'!$F$24 | V30: ='27'!$F$25 -> 3.27 | W30: ='27'!$F$26 -> 3.01 | X30: ='27'!$F$27 -> 10.1 | Y30: ='27'!$F$28 -> 7.35 | Z30: ='27'!$F$29 -> 5.69 | AA30: ='27'!$F$30 -> 10.33 | AB30: ='27'!$F$31 | AC30: ='27'!$F$32 | AD30: ='27'!$F$33 -> 7.83
A31: Midland | B31: ='28'!$F$5 -> 4.72 | C31: ='28'!$F$6 -> 9.34 | D31: ='28'!$F$7 -> 7.95 | E31: ='28'!$F$8 -> 9.76 | F31: ='28'!$F$9 -> 41.03 | G31: ='28'!$F$10 -> 14.47 | H31: ='28'!$F$11 -> 18.73 | I31: ='28'!$F$12 -> 9.67 | J31: ='28'!$F$13 -> 8.03 | K31: ='28'!$F$14 -> 10.58 | L31: ='28'!$F$15 -> 19.08 | M31: ='28'!$F$16 -> 9.32 | N31: ='28'!$F$17 -> 6.01 | O31: ='28'!$F$18 -> 10.11 | P31: ='28'!$F$19 | Q31: ='28'!$F$20 -> 10.9 | R31: ='28'!$F$21 -> 10.45 | S31: ='28'!$F$22 -> 9.67 | T31: ='28'!$F$23 -> 8.57 | U31: ='28'!$F$24 -> 13.29 | V31: ='28'!$F$25 -> 20.9 | W31: ='28'!$F$26 -> 13.75 | X31: ='28'!$F$27 -> 9.76 | Y31: ='28'!$F$28 -> 10.43 | Z31: ='28'!$F$29 -> 7.7 | AA31: ='28'!$F$30 -> 9.54 | AB31: ='28'!$F$31 | AC31: ='28'!$F$32 | AD31: ='28'!$F$33 -> 9.79
A32: Navarro | B32: ='29'!$F$5 -> 6.72 | C32: ='29'!$F$6 -> 2.46 | D32: ='29'!$F$7 -> 5.01 | E32: ='29'!$F$8 -> 5.54 | F32: ='29'!$F$9 | G32: ='29'!$F$10 -> 10.08 | H32: ='29'!$F$11 -> 4 | I32: ='29'!$F$12 -> 4.43 | J32: ='29'!$F$13 -> 3.06 | K32: ='29'!$F$14 -> 19.34 | L32: ='29'!$F$15 -> 6.34 | M32: ='29'!$F$16 -> 5.09 | N32: ='29'!$F$17 -> 3.91 | O32: ='29'!$F$18 -> 8.65 | P32: ='29'!$F$19 | Q32: ='29'!$F$20 -> 4.41 | R32: ='29'!$F$21 | S32: ='29'!$F$22 -> 8.12 | T32: ='29'!$F$23 -> 5.04 | U32: ='29'!$F$24 -> 6.34 | V32: ='29'!$F$25 -> 6.34 | W32: ='29'!$F$26 -> 2.84 | X32: ='29'!$F$27 -> 5.37 | Y32: ='29'!$F$28 -> 3.79 | Z32: ='29'!$F$29 -> 4.78 | AA32: ='29'!$F$30 -> 5.92 | AB32: ='29'!$F$31 | AC32: ='29'!$F$32 | AD32: ='29'!$F$33 -> 4.91
A33: North Central Texas | B33: ='30'!$F$5 -> 9.18 | C33: ='30'!$F$6 -> 25.75 | D33: ='30'!$F$7 -> 5.28 | E33: ='30'!$F$8 -> 5.46 | F33: ='30'!$F$9 | G33: ='30'!$F$10 -> 4.5 | H33: ='30'!$F$11 -> 12.1 | I33: ='30'!$F$12 | J33: ='30'!$F$13 -> 4.75 | K33: ='30'!$F$14 | L33: ='30'!$F$15 -> 3.2 | M33: ='30'!$F$16 -> 5.63 | N33: ='30'!$F$17 -> 4.19 | O33: ='30'!$F$18 -> 7.64 | P33: ='30'!$F$19 | Q33: ='30'!$F$20 -> 7.41 | R33: ='30'!$F$21 | S33: ='30'!$F$22 -> 5.12 | T33: ='30'!$F$23 -> 5.05 | U33: ='30'!$F$24 | V33: ='30'!$F$25 | W33: ='30'!$F$26 -> 15.35 | X33: ='30'!$F$27 -> 8.41 | Y33: ='30'!$F$28 -> 6.59 | Z33: ='30'!$F$29 -> 4.56 | AA33: ='30'!$F$30 -> 6.05 | AB33: ='30'!$F$31 | AC33: ='30'!$F$32 | AD33: ='30'!$F$33 -> 5.73
A34: Northeast Texas | B34: ='31'!$F$5 -> 16.17 | C34: ='31'!$F$6 -> 7.6 | D34: ='31'!$F$7 -> 7.3 | E34: ='31'!$F$8 -> 7.16 | F34: ='31'!$F$9 | G34: ='31'!$F$10 -> 13.67 | H34: ='31'!$F$11 -> 14.83 | I34: ='31'!$F$12 -> 7.01 | J34: ='31'!$F$13 -> 5.46 | K34: ='31'!$F$14 | L34: ='31'!$F$15 -> 3.28 | M34: ='31'!$F$16 -> 6.56 | N34: ='31'!$F$17 -> 12.39 | O34: ='31'!$F$18 -> 10.61 | P34: ='31'!$F$19 -> 16.06 | Q34: ='31'!$F$20 -> 8.43 | R34: ='31'!$F$21 | S34: ='31'!$F$22 -> 9.78 | T34: ='31'!$F$23 -> 6.81 | U34: ='31'!$F$24 -> 7.85 | V34: ='31'!$F$25 -> 18.63 | W34: ='31'!$F$26 -> 3.28 | X34: ='31'!$F$27 -> 6.66 | Y34: ='31'!$F$28 -> 10.95 | Z34: ='31'!$F$29 -> 6.15 | AA34: ='31'!$F$30 -> 10.52 | AB34: ='31'!$F$31 | AC34: ='31'!$F$32 | AD34: ='31'!$F$33 -> 7.84
A35: Odessa | B35: ='32'!$F$5 -> 12.25 | C35: ='32'!$F$6 -> 7.16 | D35: ='32'!$F$7 -> 8.13 | E35: ='32'!$F$8 -> 8.51 | F35: ='32'!$F$9 | G35: ='32'!$F$10 -> 5.04 | H35: ='32'!$F$11 -> 8.78 | I35: ='32'!$F$12 -> 5.61 | J35: ='32'!$F$13 -> 9.62 | K35: ='32'!$F$14 | L35: ='32'!$F$15 -> 8.16 | M35: ='32'!$F$16 -> 9.05 | N35: ='32'!$F$17 -> 8.97 | O35: ='32'!$F$18 -> 12.16 | P35: ='32'!$F$19 | Q35: ='32'!$F$20 -> 11.36 | R35: ='32'!$F$21 -> 24.08 | S35: ='32'!$F$22 -> 10.67 | T35: ='32'!$F$23 -> 8.52 | U35: ='32'!$F$24 -> 10.06 | V35: ='32'!$F$25 -> 13.58 | W35: ='32'!$F$26 -> 7.3 | X35: ='32'!$F$27 -> 9.76 | Y35: ='32'!$F$28 -> 10.57 | Z35: ='32'!$F$29 -> 8.01 | AA35: ='32'!$F$30 -> 10.97 | AB35: ='32'!$F$31 | AC35: ='32'!$F$32 | AD35: ='32'!$F$33 -> 9.18
A36: Panola | B36: ='33'!$F$5 -> 6.47 | C36: ='33'!$F$6 -> 13.66 | D36: ='33'!$F$7 -> 8.56 | E36: ='33'!$F$8 -> 8.49 | F36: ='33'!$F$9 | G36: ='33'!$F$10 -> 17.51 | H36: ='33'!$F$11 -> 15.87 | I36: ='33'!$F$12 -> 8.16 | J36: ='33'!$F$13 -> 7.07 | K36: ='33'!$F$14 | L36: ='33'!$F$15 -> 15.01 | M36: ='33'!$F$16 -> 8.21 | N36: ='33'!$F$17 -> 11.65 | O36: ='33'!$F$18 -> 10.92 | P36: ='33'!$F$19 | Q36: ='33'!$F$20 -> 8.78 | R36: ='33'!$F$21 | S36: ='33'!$F$22 -> 7.94 | T36: ='33'!$F$23 -> 10.58 | U36: ='33'!$F$24 | V36: ='33'!$F$25 | W36: ='33'!$F$26 -> 30.38 | X36: ='33'!$F$27 -> 8.75 | Y36: ='33'!$F$28 -> 6.41 | Z36: ='33'!$F$29 -> 7.35 | AA36: ='33'!$F$30 -> 9.58 | AB36: ='33'!$F$31 | AC36: ='33'!$F$32 | AD36: ='33'!$F$33 -> 9.17
A37: Paris | B37: ='34'!$F$5 -> 14.53 | C37: ='34'!$F$6 -> 6.41 | D37: ='34'!$F$7 -> 4.35 | E37: ='34'!$F$8 -> 5.55 | F37: ='34'!$F$9 | G37: ='34'!$F$10 -> 11.04 | H37: ='34'!$F$11 -> 5.47 | I37: ='34'!$F$12 -> 6.83 | J37: ='34'!$F$13 -> 4.26 | K37: ='34'!$F$14 | L37: ='34'!$F$15 -> 4.72 | M37: ='34'!$F$16 -> 5.19 | N37: ='34'!$F$17 -> 4.98 | O37: ='34'!$F$18 -> 11.63 | P37: ='34'!$F$19 | Q37: ='34'!$F$20 -> 6.16 | R37: ='34'!$F$21 | S37: ='34'!$F$22 -> 7.23 | T37: ='34'!$F$23 -> 4.16 | U37: ='34'!$F$24 | V37: ='34'!$F$25 -> 14.85 | W37: ='34'!$F$26 -> 2.31 | X37: ='34'!$F$27 -> 6.05 | Y37: ='34'!$F$28 -> 4.98 | Z37: ='34'!$F$29 -> 5 | AA37: ='34'!$F$30 -> 6.65 | AB37: ='34'!$F$31 | AC37: ='34'!$F$32 | AD37: ='34'!$F$33 -> 5.44
A38: Ranger | B38: ='35'!$F$5 -> 7.29 | C38: ='35'!$F$6 -> 5.22 | D38: ='35'!$F$7 -> 4.89 | E38: ='35'!$F$8 -> 7.82 | F38: ='35'!$F$9 | G38: ='35'!$F$10 | H38: ='35'!$F$11 -> 5.64 | I38: ='35'!$F$12 | J38: ='35'!$F$13 -> 5.29 | K38: ='35'!$F$14 | L38: ='35'!$F$15 | M38: ='35'!$F$16 -> 5.73 | N38: ='35'!$F$17 -> 4.52 | O38: ='35'!$F$18 | P38: ='35'!$F$19 | Q38: ='35'!$F$20 -> 7.92 | R38: ='35'!$F$21 | S38: ='35'!$F$22 -> 5.41 | T38: ='35'!$F$23 -> 6.1 | U38: ='35'!$F$24 | V38: ='35'!$F$25 | W38: ='35'!$F$26 -> 6.16 | X38: ='35'!$F$27 -> 11.25 | Y38: ='35'!$F$28 | Z38: ='35'!$F$29 -> 4.75 | AA38: ='35'!$F$30 -> 8.72 | AB38: ='35'!$F$31 | AC38: ='35'!$F$32 | AD38: ='35'!$F$33 -> 6.3
A39: San Jacinto | B39: ='36'!$F$5 -> 7.86 | C39: ='36'!$F$6 -> 6.94 | D39: ='36'!$F$7 -> 7.07 | E39: ='36'!$F$8 -> 7.17 | F39: ='36'!$F$9 -> 32.32 | G39: ='36'!$F$10 -> 5.81 | H39: ='36'!$F$11 -> 10.11 | I39: ='36'!$F$12 -> 7.4 | J39: ='36'!$F$13 -> 8.42 | K39: ='36'!$F$14 -> 10 | L39: ='36'!$F$15 -> 18.38 | M39: ='36'!$F$16 -> 7.52 | N39: ='36'!$F$17 -> 9.36 | O39: ='36'!$F$18 -> 10.76 | P39: ='36'!$F$19 | Q39: ='36'!$F$20 -> 10.92 | R39: ='36'!$F$21 -> 10.15 | S39: ='36'!$F$22 -> 10.99 | T39: ='36'!$F$23 -> 7.64 | U39: ='36'!$F$24 -> 10.07 | V39: ='36'!$F$25 -> 18.31 | W39: ='36'!$F$26 -> 7.95 | X39: ='36'!$F$27 -> 8.62 | Y39: ='36'!$F$28 -> 12.33 | Z39: ='36'!$F$29 -> 7.43 | AA39: ='36'!$F$30 -> 9.68 | AB39: ='36'!$F$31 | AC39: ='36'!$F$32 | AD39: ='36'!$F$33 -> 8.52
A40: South Plains | B40: ='37'!$F$5 -> 11.14 | C40: ='37'!$F$6 -> 6.41 | D40: ='37'!$F$7 -> 5.81 | E40: ='37'!$F$8 -> 5.85 | F40: ='37'!$F$9 -> 2.49 | G40: ='37'!$F$10 -> 5.32 | H40: ='37'!$F$11 -> 6.83 | I40: ='37'!$F$12 -> 2.49 | J40: ='37'!$F$13 -> 5.99 | K40: ='37'!$F$14 -> 2.49 | L40: ='37'!$F$15 -> 4.06 | M40: ='37'!$F$16 -> 6.54 | N40: ='37'!$F$17 -> 5.29 | O40: ='37'!$F$18 -> 6.33 | P40: ='37'!$F$19 | Q40: ='37'!$F$20 -> 8.75 | R40: ='37'!$F$21 -> 8.45 | S40: ='37'!$F$22 -> 6.14 | T40: ='37'!$F$23 -> 5.31 | U40: ='37'!$F$24 -> 6.11 | V40: ='37'!$F$25 -> 5.6 | W40: ='37'!$F$26 -> 18.9 | X40: ='37'!$F$27 -> 11.04 | Y40: ='37'!$F$28 -> 4.6 | Z40: ='37'!$F$29 -> 5.42 | AA40: ='37'!$F$30 -> 9.78 | AB40: ='37'!$F$31 | AC40: ='37'!$F$32 | AD40: ='37'!$F$33 -> 6.33
...

Sheet Discipline Analysis
A1: =Summary!A1 -> Community and Technical Colleges, Report of Fundable Operating Expenses, Fiscal Year (FY) 2008
A2: Discipline Analysis by Institution | X2: Discipline
A3: 1 | X3: Agriculture
X4: Architecture and Precision Production Trades
A5: Institution | B5: Contact Hours | C5: Total | E5: Faculty Salaries | G5: Academic Support | I5: Institutional Support | K5: Student Services | M5: Departmental Operating Expense | O5: Research | Q5: Scholarships and Fellowships | S5: Equipment Depreciation | U5: Local Benefits | X5: Biology, Physical Sciences, and Science Technology
C6: Expense | D6: per Hour | E6: Expense | F6: per Hour | G6: Expense | H6: per Hour | I6: Expense | J6: per Hour | K6: Expense | L6: per Hour | M6: Expense | N6: per Hour | O6: Expense | P6: per Hour | Q6: Expense | R6: per Hour | S6: Expense | T6: per Hour | U6: Expense | V6: per Hour | X6: Business Management, Marketing, and Administrative Services
A7: Alamo | B7: =OFFSET('1'!$D$4,$A$3,0) -> 71760 | C7: =OFFSET('1'!$E$4,$A$3,0) -> 496985.98 | D7: =OFFSET('1'!$F$4,$A$3,0) -> 6.93 | E7: =OFFSET('1'!$E$66,$A$3,0) -> 109155 | F7: =OFFSET('1'!$F$66,$A$3,0) -> 1.52 | G7: =IFERROR('1'!$F$100*'Discipline Analysis'!$B7,"") -> 66019.2 | H7: ='1'!$F$100 -> 0.92 | I7: =IFERROR('1'!$F$98*'Discipline Analysis'!$B7,"") -> 133473.6 | J7: ='1'!$F$98 -> 1.86 | K7: =IFERROR('1'!$F$99*'Discipline Analysis'!$B7,"") -> 71760 | L7: ='1'!$F$99 -> 1 | M7: =OFFSET('1'!$E$35,$A$3,0) -> 76984 | N7: =OFFSET('1'!$F$35,$A$3,0) -> 1.07 | O7: =IFERROR('1'!$F$101*'Discipline Analysis'!$B7,"") -> 0 | P7: ='1'!$F$101 -> 0 | Q7: =IFERROR('1'!$F$102*'Discipline Analysis'!$B7,"") -> 2152.8 | R7: ='1'!$F$102 -> 0.03 | S7: =IFERROR('1'!$F$103*'Discipline Analysis'!$B7,"") -> 11481.6 | T7: ='1'!$F$103 -> 0.16 | U7: =IFERROR('1'!$F$104*'Discipline Analysis'!$B7,"") -> 25833.6 | V7: ='1'!$F$104 -> 0.36 | X7: Career Pilot
A8: Alvin | B8: =OFFSET('2'!$D$4,$A$3,0) -> 39312 | C8: =OFFSET('2'!$E$4,$A$3,0) -> 209379.57 | D8: =OFFSET('2'!$F$4,$A$3,0) -> 5.33 | E8: =OFFSET('2'!$E$66,$A$3,0) -> 67356 | F8: =OFFSET('2'!$F$66,$A$3,0) -> 1.71 | G8: =IFERROR('2'!$F$100*'Discipline Analysis'!$B8,"") -> 41670.72 | H8: ='2'!$F$100 -> 1.06 | I8: =IFERROR('2'!$F$98*'Discipline Analysis'!$B8,"") -> 54250.56 | J8: ='2'!$F$98 -> 1.38 | K8: =IFERROR('2'!$F$99*'Discipline Analysis'!$B8,"") -> 28304.64 | L8: ='2'!$F$99 -> 0.72 | M8: =OFFSET('2'!$E$35,$A$3,0) -> 7191 | N8: =OFFSET('2'!$F$35,$A$3,0) -> 0.18 | O8: =IFERROR('2'!$F$101*'Discipline Analysis'!$B8,"") -> 0 | P8: ='2'!$F$101 -> 0 | Q8: =IFERROR('2'!$F$102*'Discipline Analysis'!$B8,"") -> 0 | R8: ='2'!$F$102 -> 0 | S8: =IFERROR('2'!$F$103*'Discipline Analysis'!$B8,"") -> 5110.56 | T8: ='2'!$F$103 -> 0.13 | U8: =IFERROR('2'!$F$104*'Discipline Analysis'!$B8,"") -> 5110.56 | V8: ='2'!$F$104 -> 0.13 | X8: Communications
A9: Amarillo | B9: =OFFSET('3'!$D$4,$A$3,0) -> 10184 | C9: =OFFSET('3'!$E$4,$A$3,0) -> 75770.544 | D9: =OFFSET('3'!$F$4,$A$3,0) -> 7.44 | E9: =OFFSET('3'!$E$66,$A$3,0) -> 29498 | F9: =OFFSET('3'!$F$66,$A$3,0) -> 2.9 | G9: =IFERROR('3'!$F$100*'Discipline Analysis'!$B9,"") -> 5397.52 | H9: ='3'!$F$100 -> 0.53 | I9: =IFERROR('3'!$F$98*'Discipline Analysis'!$B9,"") -> 18942.24 | J9: ='3'!$F$98 -> 1.86 | K9: =IFERROR('3'!$F$99*'Discipline Analysis'!$B9,"") -> 5397.52 | L9: ='3'!$F$99 -> 0.53 | M9: =OFFSET('3'!$E$35,$A$3,0) -> 11524 | N9: =OFFSET('3'!$F$35,$A$3,0) -> 1.13 | O9: =IFERROR('3'!$F$101*'Discipline Analysis'!$B9,"") -> 0 | P9: ='3'!$F$101 -> 0 | Q9: =IFERROR('3'!$F$102*'Discipline Analysis'!$B9,"") -> 0 | R9: ='3'!$F$102 -> 0 | S9: =IFERROR('3'!$F$103*'Discipline Analysis'!$B9,"") -> 1527.6 | T9: ='3'!$F$103 -> 0.15 | U9: =IFERROR('3'!$F$104*'Discipline Analysis'!$B9,"") -> 3564.4 | V9: ='3'!$F$104 -> 0.35 | X9: Computer and Information Sciences
A10: Angelina | B10: =OFFSET('4'!$D$4,$A$3,0) -> 0 | C10: =OFFSET('4'!$E$4,$A$3,0) -> 0 | D10: =OFFSET('4'!$F$4,$A$3,0) | E10: =OFFSET('4'!$E$66,$A$3,0) -> 0 | F10: =OFFSET('4'!$F$66,$A$3,0) | G10: =IFERROR('4'!$F$100*'Discipline Analysis'!$B10,"") -> 0 | H10: ='4'!$F$100 -> 0.86 | I10: =IFERROR('4'!$F$98*'Discipline Analysis'!$B10,"") -> 0 | J10: ='4'!$F$98 -> 0.93 | K10: =IFERROR('4'!$F$99*'Discipline Analysis'!$B10,"") -> 0 | L10: ='4'!$F$99 -> 0.41 | M10: =OFFSET('4'!$E$35,$A$3,0) -> 0 | N10: =OFFSET('4'!$F$35,$A$3,0) | O10: =IFERROR('4'!$F$101*'Discipline Analysis'!$B10,"") -> 0 | P10: ='4'!$F$101 -> 0 | Q10: =IFERROR('4'!$F$102*'Discipline Analysis'!$B10,"") -> 0 | R10: ='4'!$F$102 -> 0 | S10: =IFERROR('4'!$F$103*'Discipline Analysis'!$B10,"") -> 0 | T10: ='4'!$F$103 -> 0.13 | U10: =IFERROR('4'!$F$104*'Discipline Analysis'!$B10,"") -> 0 | V10: ='4'!$F$104 -> 0.08 | X10: Construction Trades
A11: Austin | B11: =OFFSET('5'!$D$4,$A$3,0) -> 85570 | C11: =OFFSET('5'!$E$4,$A$3,0) -> 559145.37 | D11: =OFFSET('5'!$F$4,$A$3,0) -> 6.53 | E11: =OFFSET('5'!$E$66,$A$3,0) -> 113776 | F11: =OFFSET('5'!$F$66,$A$3,0) -> 1.33 | G11: =IFERROR('5'!$F$100*'Discipline Analysis'!$B11,"") -> 116375.2 | H11: ='5'!$F$100 -> 1.36 | I11: =IFERROR('5'!$F$98*'Discipline Analysis'!$B11,"") -> 167717.2 | J11: ='5'!$F$98 -> 1.96 | K11: =IFERROR('5'!$F$99*'Discipline Analysis'!$B11,"") -> 98405.5 | L11: ='5'!$F$99 -> 1.15 | M11: =OFFSET('5'!$E$35,$A$3,0) -> 23208 | N11: =OFFSET('5'!$F$35,$A$3,0) -> 0.27 | O11: =IFERROR('5'!$F$101*'Discipline Analysis'!$B11,"") -> 0 | P11: ='5'!$F$101 -> 0 | Q11: =IFERROR('5'!$F$102*'Discipline Analysis'!$B11,"") -> 0 | R11: ='5'!$F$102 -> 0 | S11: =IFERROR('5'!$F$103*'Discipline Analysis'!$B11,"") -> 11979.8 | T11: ='5'!$F$103 -> 0.14 | U11: =IFERROR('5'!$F$104*'Discipline Analysis'!$B11,"") -> 28238.1 | V11: ='5'!$F$104 -> 0.33 | X11: Consumer and Homemaking Education
A12: Blinn | B12: =OFFSET('6'!$D$4,$A$3,0) -> 59744 | C12: =OFFSET('6'!$E$4,$A$3,0) -> 389838.05 | D12: =OFFSET('6'!$F$4,$A$3,0) -> 6.53 | E12: =OFFSET('6'!$E$66,$A$3,0) -> 221421 | F12: =OFFSET('6'!$F$66,$A$3,0) -> 3.71 | G12: =IFERROR('6'!$F$100*'Discipline Analysis'!$B12,"") -> 26287.36 | H12: ='6'!$F$100 -> 0.44 | I12: =IFERROR('6'!$F$98*'Discipline Analysis'!$B12,"") -> 58549.12 | J12: ='6'!$F$98 -> 0.98 | K12: =IFERROR('6'!$F$99*'Discipline Analysis'!$B12,"") -> 31664.32 | L12: ='6'!$F$99 -> 0.53 | M12: =OFFSET('6'!$E$35,$A$3,0) -> 39519 | N12: =OFFSET('6'!$F$35,$A$3,0) -> 0.66 | O12: =IFERROR('6'!$F$101*'Discipline Analysis'!$B12,"") -> 0 | P12: ='6'!$F$101 -> 0 | Q12: =IFERROR('6'!$F$102*'Discipline Analysis'!$B12,"") -> 3584.64 | R12: ='6'!$F$102 -> 0.06 | S12: =IFERROR('6'!$F$103*'Discipline Analysis'!$B12,"") -> 2987.2 | T12: ='6'!$F$103 -> 0.05 | U12: =IFERROR('6'!$F$104*'Discipline Analysis'!$B12,"") -> 5376.96 | V12: ='6'!$F$104 -> 0.09 | X12: Engineering
A13: Brazosport | B13: =OFFSET('7'!$D$4,$A$3,0) -> 0 | C13: =OFFSET('7'!$E$4,$A$3,0) -> 0 | D13: =OFFSET('7'!$F$4,$A$3,0) | E13: =OFFSET('7'!$E$66,$A$3,0) -> 0 | F13: =OFFSET('7'!$F$66,$A$3,0) | G13: =IFERROR('7'!$F$100*'Discipline Analysis'!$B13,"") -> 0 | H13: ='7'!$F$100 -> 0.92 | I13: =IFERROR('7'!$F$98*'Discipline Analysis'!$B13,"") -> 0 | J13: ='7'!$F$98 -> 2.59 | K13: =IFERROR('7'!$F$99*'Discipline Analysis'!$B13,"") -> 0 | L13: ='7'!$F$99 -> 1.1 | M13: =OFFSET('7'!$E$35,$A$3,0) -> 0 | N13: =OFFSET('7'!$F$35,$A$3,0) | O13: =IFERROR('7'!$F$101*'Discipline Analysis'!$B13,"") -> 0 | P13: ='7'!$F$101 -> 0 | Q13: =IFERROR('7'!$F$102*'Discipline Analysis'!$B13,"") -> 0 | R13: ='7'!$F$102 -> 0.18 | S13: =IFERROR('7'!$F$103*'Discipline Analysis'!$B13,"") -> 0 | T13: ='7'!$F$103 -> 0.23 | U13: =IFERROR('7'!$F$104*'Discipline Analysis'!$B13,"") -> 0 | V13: ='7'!$F$104 -> 0.13 | X13: Engineering Related
A14: Central Texas | B14: =OFFSET('8'!$D$4,$A$3,0) -> 72622 | C14: =OFFSET('8'!$E$4,$A$3,0) -> 377500.37 | D14: =OFFSET('8'!$F$4,$A$3,0) -> 5.2 | E14: =OFFSET('8'!$E$66,$A$3,0) -> 87639 | F14: =OFFSET('8'!$F$66,$A$3,0) -> 1.21 | G14: =IFERROR('8'!$F$100*'Discipline Analysis'!$B14,"") -> 26143.92 | H14: ='8'!$F$100 -> 0.36 | I14: =IFERROR('8'!$F$98*'Discipline Analysis'!$B14,"") -> 111837.88 | J14: ='8'!$F$98 -> 1.54 | K14: =IFERROR('8'!$F$99*'Discipline Analysis'!$B14,"") -> 47204.3 | L14: ='8'!$F$99 -> 0.65 | M14: =OFFSET('8'!$E$35,$A$3,0) -> 73228 | N14: =OFFSET('8'!$F$35,$A$3,0) -> 1.01 | O14: =IFERROR('8'!$F$101*'Discipline Analysis'!$B14,"") -> 0 | P14: ='8'!$F$101 -> 0 | Q14: =IFERROR('8'!$F$102*'Discipline Analysis'!$B14,"") -> 0 | R14: ='8'!$F$102 -> 0 | S14: =IFERROR('8'!$F$103*'Discipline Analysis'!$B14,"") -> 10893.3 | T14: ='8'!$F$103 -> 0.15 | U14: =IFERROR('8'!$F$104*'Discipline Analysis'!$B14,"") -> 19607.94 | V14: ='8'!$F$104 -> 0.27 | X14: English Language, Lit, Philosophy, Humanities, & Interdisciplinary
A15: Cisco | B15: =OFFSET('9'!$D$4,$A$3,0) -> 7360 | C15: =OFFSET('9'!$E$4,$A$3,0) -> 72773.299 | D15: =OFFSET('9'!$F$4,$A$3,0) -> 9.89 | E15: =OFFSET('9'!$E$66,$A$3,0) -> 46166 | F15: =OFFSET('9'!$F$66,$A$3,0) -> 6.27 | G15: =IFERROR('9'!$F$100*'Discipline Analysis'!$B15,"") -> 3900.8 | H15: ='9'!$F$100 -> 0.53 | I15: =IFERROR('9'!$F$98*'Discipline Analysis'!$B15,"") -> 8979.2 | J15: ='9'!$F$98 -> 1.22 | K15: =IFERROR('9'!$F$99*'Discipline Analysis'!$B15,"") -> 4195.2 | L15: ='9'!$F$99 -> 0.57 | M15: =OFFSET('9'!$E$35,$A$3,0) -> 7552 | N15: =OFFSET('9'!$F$35,$A$3,0) -> 1.03 | O15: =IFERROR('9'!$F$101*'Discipline Analysis'!$B15,"") -> 0 | P15: ='9'!$F$101 -> 0 | Q15: =IFERROR('9'!$F$102*'Discipline Analysis'!$B15,"") -> 0 | R15: ='9'!$F$102 -> 0 | S15: =IFERROR('9'!$F$103*'Discipline Analysis'!$B15,"") -> 1472 | T15: ='9'!$F$103 -> 0.2 | U15: =IFERROR('9'!$F$104*'Discipline Analysis'!$B15,"") -> 588.8 | V15: ='9'!$F$104 -> 0.08 | X15: Foreign Languages
A16: Clarendon | B16: =OFFSET('10'!$D$4,$A$3,0) -> 34368 | C16: =OFFSET('10'!$E$4,$A$3,0) -> 352163.33 | D16: =OFFSET('10'!$F$4,$A$3,0) -> 10.25 | E16: =OFFSET('10'!$E$66,$A$3,0) -> 173229 | F16: =OFFSET('10'!$F$66,$A$3,0) -> 5.04 | G16: =IFERROR('10'!$F$100*'Discipline Analysis'!$B16,"") -> 22339.2 | H16: ='10'!$F$100 -> 0.65 | I16: =IFERROR('10'!$F$98*'Discipline Analysis'!$B16,"") -> 45709.44 | J16: ='10'!$F$98 -> 1.33 | K16: =IFERROR('10'!$F$99*'Discipline Analysis'!$B16,"") -> 20620.8 | L16: ='10'!$F$99 -> 0.6 | M16: =OFFSET('10'!$E$35,$A$3,0) -> 70511 | N16: =OFFSET('10'!$F$35,$A$3,0) -> 2.05 | O16: =IFERROR('10'!$F$101*'Discipline Analysis'!$B16,"") -> 0 | P16: ='10'!$F$101 -> 0 | Q16: =IFERROR('10'!$F$102*'Discipline Analysis'!$B16,"") -> 0 | R16: ='10'!$F$102 -> 0 | S16: =IFERROR('10'!$F$103*'Discipline Analysis'!$B16,"") -> 17184 | T16: ='10'!$F$103 -> 0.5 | U16: =IFERROR('10'!$F$104*'Discipline Analysis'!$B16,"") -> 2749.44 | V16: ='10'!$F$104 -> 0.08 | X16: Health Occupations - Dental Assistants, Medical Lab, and Assoc. Degree Nursing
A17: Coastal Bend | B17: =OFFSET('11'!$D$4,$A$3,0) -> 0 | C17: =OFFSET('11'!$E$4,$A$3,0) -> 0 | D17: =OFFSET('11'!$F$4,$A$3,0) | E17: =OFFSET('11'!$E$66,$A$3,0) -> 0 | F17: =OFFSET('11'!$F$66,$A$3,0) | G17: =IFERROR('11'!$F$100*'Discipline Analysis'!$B17,"") | H17: ='11'!$F$100 | I17: =IFERROR('11'!$F$98*'Discipline Analysis'!$B17,"") | J17: ='11'!$F$98 | K17: =IFERROR('11'!$F$99*'Discipline Analysis'!$B17,"") | L17: ='11'!$F$99 | M17: =OFFSET('11'!$E$35,$A$3,0) -> 0 | N17: =OFFSET('11'!$F$35,$A$3,0) | O17: =IFERROR('11'!$F$101*'Discipline Analysis'!$B17,"") | P17: ='11'!$F$101 | Q17: =IFERROR('11'!$F$102*'Discipline Analysis'!$B17,"") | R17: ='11'!$F$102 | S17: =IFERROR('11'!$F$103*'Discipline Analysis'!$B17,"") | T17: ='11'!$F$103 | U17: =IFERROR('11'!$F$104*'Discipline Analysis'!$B17,"") | V17: ='11'!$F$104 | X17: Health Occupations - Dental Hygiene
