Workbook

Sheet Form
A1: Kansas State University
A2: Recruiting/Commitment Form
A3: College of Agriculture/KSRE
A4: Position Number | J4: Proposed Final
A6: Department/Org | F6: Job Title
A7: Name | F7: Specialization
A8: Proposed Salary | F8: Effective Date
A11: Type of Position | F11: Space | H11: VPR INTERNAL USE ONLY
A12: New Position Vacancy | C12: Non-Tenured/Tenure Track/Tenured | F12: Office _______________________ | H12: Year 1 FY | J12: Amount: | K12: =K34 -> 0
F13: Lab _________________________ | H13: Transfer Document #:
A14: Budgeted Non Budget | C14: 12 MO 9 MO Other | H14: Date:
H15: Year 2 FY | J15: Amount: | K15: =K43 -> 0
A16: POSITION FUNDING | C16: FTE | D16: SALARY | F16: EFFORT DISTRIBUTION: | H16: Transfer Document #:
A17: University (VP of Research, Provost, etc) | D17: =SUM(C17*B8) -> 0 | F17: Teaching: | H17: Date:
A18: College (Teaching) | D18: =SUM(C18*B8) -> 0 | F18: Research: | H18: Year 3 FY | J18: Amount: | K18: =K52 -> 0
A19: AES | D19: =SUM(C19*B8) -> 0 | F19: Service: | H19: Transfer Document #:
A20: CES | D20: =SUM(C20*B8) -> 0 | F20: Administrative: | H20: Date:
A21: Other | D21: =SUM(C21*B9) -> 0 | J21: Total: | K21: =K12+K15+K18 -> 0
A22: Total | C22: =SUM(C17:C21) -> 0 | D22: =SUM(D17:D21) -> 0
A23: RECRUITING PACKAGE COMMITMENTS | H23: ACTUAL EXPENDITURES
C24: CoA/KSRE | F24: OTHER | H24: Total FY Expenses | K24: VPR Share
A25: Year 1 FY _____ | B25: DEPT | C25: TEACHING | D25: RESEARCH | E25: EXTENSION | F25: ___________ | G25: TOTAL ALL | H25: Reimburse Project & Org ________________________
A26: Faculty Summer Salary | G26: =SUM(B26:F26) -> 0
A27: Technical Support | G27: =SUM(B27:F27) -> 0
A28: Startup/Equipment | G28: =SUM(B28:F28) -> 0
A29: Office/Lab Renovations | G29: =SUM(B29:F29) -> 0
A30: Research Expense | G30: =SUM(B30:F30) -> 0
A31: GRA/Post-Docs, etc. | G31: =SUM(B31:F31) -> 0
A32: Spousal Hire | G32: =SUM(B32:F32) -> 0
A33: Other _______ | G33: =SUM(B33:F33) -> 0
A34: Total | B34: =SUM(B26:B33) -> 0 | C34: =SUM(C26:C33) -> 0 | D34: =SUM(D26:D33) -> 0 | E34: =SUM(E26:E33) -> 0 | F34: =SUM(F26:F33) -> 0 | G34: =SUM(G26:G32) -> 0 | H34: =SUM(H26:H33) -> 0 | K34: =+H34*F54 -> 0
A35: Year 2 FY _____ | B35: DEPT | C35: TEACHING | D35: RESEARCH | E35: EXTENSION | F35: ___________ | H35: Reimburse Project & Org ________________________
A36: Faculty Summer Salary | G36: =SUM(B36:F36) -> 0
A37: Technical Support | G37: =SUM(B37:F37) -> 0
A38: Startup/Equipment | G38: =SUM(B38:F38) -> 0
A39: Research Expense | G39: =SUM(B39:F39) -> 0
A40: GRA/Post-Docs, etc. | G40: =SUM(B40:F40) -> 0
A41: Spousal Hire | G41: =SUM(B41:F41) -> 0
A42: Other _______ | G42: =SUM(B42:F42) -> 0
A43: Total | B43: =SUM(B36:B42) -> 0 | C43: =SUM(C36:C42) -> 0 | D43: =SUM(D36:D42) -> 0 | E43: =SUM(E36:E42) -> 0 | F43: =SUM(F36:F42) -> 0 | G43: =SUM(G36:G42) -> 0 | H43: =SUM(H36:J42) -> 0 | K43: =+H43*F54 -> 0
...

Sheet Contribution
A1: Kansas State University
A2: Recruiting/Commitment Form
A4: Position Number | B4: =Form!B4 -> 0
A6: Department/Org | B6: =Form!B6 -> 0 | E6: Job Title | F6: =Form!G6 -> 0
A7: Name | B7: =Form!B7 -> 0 | E7: Specialization | F7: =Form!G7 -> 0
A8: Proposed Salary | B8: =Form!B8 -> 0 | E8: Effective Date | F8: =Form!G8 -> 0
A11: Description of Expected Contribution to Research, Scholarly and Creative Activities, and Discovery (RSCAD)
A14: RSCAD Contribution | C14: Yr 1 FY
A15: (for example, proposals submitted, grants awarded, etc)
A17: RSCAD Contribution | C17: Yr 2 FY
A20: RSCAD Contribution | C20: Yr 3 FY

Sheet Instructions
A1: Position Responsibilities: | B1: Reflect the time the employee will be working in each category and the salary associated with each category.
A3: Recruiting Package Commitments: | B3: Technical Support should show any type of IT commitment.
B5: Rows may be inserted if other categories are needed, please copy the forumla down.
