Workbook
Name matchresults_1: 'Online Results'!$L$1:$U$153
Name rankings: 'Online Results'!$A$1:$J$103

Sheet Notes
A1: To set up the database you need to:
B2: Copy in the team list to "Teams".
B3: Make sure that "Online Results" is linked correctly.
B4: Copy in the team and OPR list from 1114's database.
B5: Make sure that the database has formulas in enough rows to account for all of the teams.
A7: The OPR data is from 1114's database.
A9: The database is linked to FIRST's online database so in theory all that you need to do is click "Refresh All" (under "Data") to view the realtime results.

Sheet Teams
A1: Team | B1: OPR | C1: QS | D1: QS+CP | E1: RS | F1: Extra Match (0 or Match Number) | G1: Sort by me! | H1: OPR | I1: OPR High | J1: OPR Norm
A2: 987 | B2: =VLOOKUP($A2, 'Enter Team Data Here'!$F:$W, 2, FALSE) -> 33.0073 | C2: =VLOOKUP($A2, 'Enter Team Data Here'!$F:$W, 17, FALSE) -> 18 | D2: =VLOOKUP($A2, 'Enter Team Data Here'!$F:$W, 18, FALSE) -> 24 | E2: =VLOOKUP($A2, 'Enter Team Data Here'!$F:$W, 16, FALSE) -> 281.78052 | F2: 0 | G2: =SUM(1000*D2, E2) -> 24281.781 | H2: =B2 -> 33.0073 | L2: You should paste in the team numbers so that funky things don't happen when you sort.
A3: 341 | B3: =VLOOKUP($A3, 'Enter Team Data Here'!$F:$W, 2, FALSE) -> 34.869675 | C3: =VLOOKUP($A3, 'Enter Team Data Here'!$F:$W, 17, FALSE) -> 18 | D3: =VLOOKUP($A3, 'Enter Team Data Here'!$F:$W, 18, FALSE) -> 24 | E3: =VLOOKUP($A3, 'Enter Team Data Here'!$F:$W, 16, FALSE) -> 280.00213 | F3: 0 | G3: =SUM(1000*D3, E3) -> 24280.002 | H3: =B3 -> 34.869675 | L3: I don't remember where I got the OPR High and OPR Norm from…
A4: 1507 | B4: =VLOOKUP($A4, 'Enter Team Data Here'!$F:$W, 2, FALSE) -> 30.17285 | C4: =VLOOKUP($A4, 'Enter Team Data Here'!$F:$W, 17, FALSE) -> 18 | D4: =VLOOKUP($A4, 'Enter Team Data Here'!$F:$W, 18, FALSE) -> 22 | E4: =VLOOKUP($A4, 'Enter Team Data Here'!$F:$W, 16, FALSE) -> 307.80803 | F4: 0 | G4: =SUM(1000*D4, E4) -> 22307.808 | H4: =B4 -> 30.17285
A5: 624 | B5: =VLOOKUP($A5, 'Enter Team Data Here'!$F:$W, 2, FALSE) -> 28.8894 | C5: =VLOOKUP($A5, 'Enter Team Data Here'!$F:$W, 17, FALSE) -> 12 | D5: =VLOOKUP($A5, 'Enter Team Data Here'!$F:$W, 18, FALSE) -> 18 | E5: =VLOOKUP($A5, 'Enter Team Data Here'!$F:$W, 16, FALSE) -> 291.59986 | F5: 0 | G5: =SUM(1000*D5, E5) -> 18291.6 | H5: =B5 -> 28.8894 | L5: Search for a team by entering in their number here:
A6: 58 | B6: =VLOOKUP($A6, 'Enter Team Data Here'!$F:$W, 2, FALSE) -> 18.6124 | C6: =VLOOKUP($A6, 'Enter Team Data Here'!$F:$W, 17, FALSE) -> 16 | D6: =VLOOKUP($A6, 'Enter Team Data Here'!$F:$W, 18, FALSE) -> 18 | E6: =VLOOKUP($A6, 'Enter Team Data Here'!$F:$W, 16, FALSE) -> 273.68036 | F6: 0 | G6: =SUM(1000*D6, E6) -> 18273.68 | H6: =B6 -> 18.6124 | L6: 254
A7: 3205 | B7: =VLOOKUP($A7, 'Enter Team Data Here'!$F:$W, 2, FALSE) -> 23.9137 | C7: =VLOOKUP($A7, 'Enter Team Data Here'!$F:$W, 17, FALSE) -> 18 | D7: =VLOOKUP($A7, 'Enter Team Data Here'!$F:$W, 18, FALSE) -> 18 | E7: =VLOOKUP($A7, 'Enter Team Data Here'!$F:$W, 16, FALSE) -> 260.93339 | F7: 0 | G7: =SUM(1000*D7, E7) -> 18260.933 | H7: =B7 -> 23.9137
A8: 1986 | B8: =VLOOKUP($A8, 'Enter Team Data Here'!$F:$W, 2, FALSE) -> 28.11245 | C8: =VLOOKUP($A8, 'Enter Team Data Here'!$F:$W, 17, FALSE) -> 14 | D8: =VLOOKUP($A8, 'Enter Team Data Here'!$F:$W, 18, FALSE) -> 16 | E8: =VLOOKUP($A8, 'Enter Team Data Here'!$F:$W, 16, FALSE) -> 311.51819 | F8: 0 | G8: =SUM(1000*D8, E8) -> 16311.518 | H8: =B8 -> 28.11245
A9: 254 | B9: =VLOOKUP($A9, 'Enter Team Data Here'!$F:$W, 2, FALSE) -> 29.39955 | C9: =VLOOKUP($A9, 'Enter Team Data Here'!$F:$W, 17, FALSE) -> 14 | D9: =VLOOKUP($A9, 'Enter Team Data Here'!$F:$W, 18, FALSE) -> 16 | E9: =VLOOKUP($A9, 'Enter Team Data Here'!$F:$W, 16, FALSE) -> 298.77022 | F9: 3 | G9: =SUM(1000*D9, E9) -> 16298.77 | H9: =B9 -> 29.39955
A10: 3098 | B10: =VLOOKUP($A10, 'Enter Team Data Here'!$F:$W, 2, FALSE) -> 19.627433 | C10: =VLOOKUP($A10, 'Enter Team Data Here'!$F:$W, 17, FALSE) -> 14 | D10: =VLOOKUP($A10, 'Enter Team Data Here'!$F:$W, 18, FALSE) -> 16 | E10: =VLOOKUP($A10, 'Enter Team Data Here'!$F:$W, 16, FALSE) -> 288.52211 | F10: 0 | G10: =SUM(1000*D10, E10) -> 16288.522 | H10: =B10 -> 19.627433
A11: 3970 | B11: =VLOOKUP($A11, 'Enter Team Data Here'!$F:$W, 2, FALSE) -> 13.44124 | C11: =VLOOKUP($A11, 'Enter Team Data Here'!$F:$W, 17, FALSE) -> 12 | D11: =VLOOKUP($A11, 'Enter Team Data Here'!$F:$W, 18, FALSE) -> 16 | E11: =VLOOKUP($A11, 'Enter Team Data Here'!$F:$W, 16, FALSE) -> 274.68293 | F11: 0 | G11: =SUM(1000*D11, E11) -> 16274.683 | H11: =B11 -> 13.44124
A12: 78 | B12: =VLOOKUP($A12, 'Enter Team Data Here'!$F:$W, 2, FALSE) -> 13.8272 | C12: =VLOOKUP($A12, 'Enter Team Data Here'!$F:$W, 17, FALSE) -> 14 | D12: =VLOOKUP($A12, 'Enter Team Data Here'!$F:$W, 18, FALSE) -> 16 | E12: =VLOOKUP($A12, 'Enter Team Data Here'!$F:$W, 16, FALSE) -> 257.80266 | F12: 0 | G12: =SUM(1000*D12, E12) -> 16257.803 | H12: =B12 -> 13.8272
A13: 2474 | B13: =VLOOKUP($A13, 'Enter Team Data Here'!$F:$W, 2, FALSE) -> 25.520925 | C13: =VLOOKUP($A13, 'Enter Team Data Here'!$F:$W, 17, FALSE) -> 12 | D13: =VLOOKUP($A13, 'Enter Team Data Here'!$F:$W, 18, FALSE) -> 16 | E13: =VLOOKUP($A13, 'Enter Team Data Here'!$F:$W, 16, FALSE) -> 243.12418 | F13: 0 | G13: =SUM(1000*D13, E13) -> 16243.124 | H13: =B13 -> 25.520925
A14: 51 | B14: =VLOOKUP($A14, 'Enter Team Data Here'!$F:$W, 2, FALSE) -> 21.605133 | C14: =VLOOKUP($A14, 'Enter Team Data Here'!$F:$W, 17, FALSE) -> 16 | D14: =VLOOKUP($A14, 'Enter Team Data Here'!$F:$W, 18, FALSE) -> 16 | E14: =VLOOKUP($A14, 'Enter Team Data Here'!$F:$W, 16, FALSE) -> 240.38133 | F14: 0 | G14: =SUM(1000*D14, E14) -> 16240.381 | H14: =B14 -> 21.605133
A15: 4265 | B15: =VLOOKUP($A15, 'Enter Team Data Here'!$F:$W, 2, FALSE) -> 7.44503 | C15: =VLOOKUP($A15, 'Enter Team Data Here'!$F:$W, 17, FALSE) -> 12 | D15: =VLOOKUP($A15, 'Enter Team Data Here'!$F:$W, 18, FALSE) -> 16 | E15: =VLOOKUP($A15, 'Enter Team Data Here'!$F:$W, 16, FALSE) -> 237.77075 | F15: 0 | G15: =SUM(1000*D15, E15) -> 16237.771 | H15: =B15 -> 7.44503
A16: 3528 | B16: =VLOOKUP($A16, 'Enter Team Data Here'!$F:$W, 2, FALSE) -> 21.5243 | C16: =VLOOKUP($A16, 'Enter Team Data Here'!$F:$W, 17, FALSE) -> 14 | D16: =VLOOKUP($A16, 'Enter Team Data Here'!$F:$W, 18, FALSE) -> 16 | E16: =VLOOKUP($A16, 'Enter Team Data Here'!$F:$W, 16, FALSE) -> 227.8682 | F16: 0 | G16: =SUM(1000*D16, E16) -> 16227.868 | H16: =B16 -> 21.5243
A17: 3711 | B17: =VLOOKUP($A17, 'Enter Team Data Here'!$F:$W, 2, FALSE) -> 6.840615 | C17: =VLOOKUP($A17, 'Enter Team Data Here'!$F:$W, 17, FALSE) -> 12 | D17: =VLOOKUP($A17, 'Enter Team Data Here'!$F:$W, 18, FALSE) -> 16 | E17: =VLOOKUP($A17, 'Enter Team Data Here'!$F:$W, 16, FALSE) -> 225.19955 | F17: 0 | G17: =SUM(1000*D17, E17) -> 16225.2 | H17: =B17 -> 6.840615
A18: 3950 | B18: =VLOOKUP($A18, 'Enter Team Data Here'!$F:$W, 2, FALSE) -> 5.80187 | C18: =VLOOKUP($A18, 'Enter Team Data Here'!$F:$W, 17, FALSE) -> 14 | D18: =VLOOKUP($A18, 'Enter Team Data Here'!$F:$W, 18, FALSE) -> 16 | E18: =VLOOKUP($A18, 'Enter Team Data Here'!$F:$W, 16, FALSE) -> 223.29955 | F18: 0 | G18: =SUM(1000*D18, E18) -> 16223.3 | H18: =B18 -> 5.80187
... A101: 1033 | B101: =VLOOKUP($A101, 'Enter Team Data Here'!$F:$W, 2, FALSE) -> 2.32 | C101: =VLOOKUP($A101, 'Enter Team Data Here'!$F:$W, 17, FALSE) -> 2 | D101: =VLOOKUP($A101, 'Enter Team Data Here'!$F:$W, 18, FALSE) -> 4 | E101: =VLOOKUP($A101, 'Enter Team Data Here'!$F:$W, 16, FALSE) -> 163.31424 | F101: 0 | G101: =SUM(1000*D101, E101) -> 4163.3142 | H101: =B101 -> 2.32

Sheet Matches
A1: Time | B1: Match | C1: R1 | D1: R2 | E1: R3 | F1: B1 | G1: B2 | H1: B3 | I1: R Score (Expected) | J1: B Score (Expected) | K1: R QS | L1: B QS | M1: RS | N1: R Score (Actual) | O1: B Score (Actual) | P1: R Score | Q1: B Score | R1: Error | S1: R OPR | T1: B OPR | U1: Err Norm | V1: Err Cum | W1: Err Norm Cum | X1: Err Match | Y1: Err Match Cum
A2: ='Online Results'!L4 -> 0.54166667 | B2: ='Online Results'!M4 -> 1 | C2: ='Online Results'!N4 -> 3929 | D2: ='Online Results'!O4 -> 4253 | E2: ='Online Results'!P4 -> 1986 | F2: ='Online Results'!Q4 -> 4265 | G2: ='Online Results'!R4 -> 702 | H2: ='Online Results'!S4 -> 3941 | I2: =SUM(VLOOKUP(C2, Teams!A:B, 2, FALSE), VLOOKUP(D2, Teams!A:B, 2, FALSE), VLOOKUP(E2, Teams!A:B, 2, FALSE)) -> 44.82452 | J2: =SUM(VLOOKUP(F2, Teams!A:B, 2, FALSE), VLOOKUP(G2, Teams!A:B, 2, FALSE), VLOOKUP(H2, Teams!A:B, 2, FALSE)) -> 22.74814 | K2: =IF(P2>Q2,2,IF(P2=Q2,1,0)) -> 2 | L2: =SUM(-1*K2+2) -> 0 | M2: =MIN(P2:Q2) -> 14 | N2: =IF('Online Results'!T4="", "", 'Online Results'!T4) -> 26 | O2: =IF('Online Results'!U4="", "", 'Online Results'!U4) -> 14 | P2: =IF(N2="", I2, N2) -> 26 | Q2: =IF(O2="", J2, O2) -> 14 | R2: =ABS(I2+J2-N2-O2)/(N2+O2) -> 0.6893165 | S2: =SUM(VLOOKUP(C2, Teams!A:B, 2, FALSE), VLOOKUP(D2, Teams!A:B, 2, FALSE), VLOOKUP(E2, Teams!A:B, 2, FALSE)) -> 44.82452 | T2: =SUM(VLOOKUP(F2, Teams!A:B, 2, FALSE), VLOOKUP(G2, Teams!A:B, 2, FALSE), VLOOKUP(H2, Teams!A:B, 2, FALSE)) -> 22.74814 | U2: =R2*SUM(S2, T2)/SUM(AVERAGE($S$2:$S2), AVERAGE($T$2:$T2)) -> 0.6893165 | V2: =AVERAGE($R$2:$R2) -> 0.6893165 | W2: =AVERAGE($U$2:$U2) -> 0.6893165 | X2: =IF(S2>T2,IF(N2>O2,0,IF(N2=O2, 1, 2)),IF(S2=T2,IF(N2=O2,0,1), IF(N2<O2, 0, 2))) -> 0 | Y2: =AVERAGE($X$2:$X2)*0.5 -> 0 | AA2: Search for a team by entering in their number here:
A3: ='Online Results'!L5 -> 0.58541667 | B3: ='Online Results'!M5 -> 2 | C3: ='Online Results'!N5 -> 836 | D3: ='Online Results'!O5 -> 2881 | E3: ='Online Results'!P5 -> 178 | F3: ='Online Results'!Q5 -> 3098 | G3: ='Online Results'!R5 -> 1885 | H3: ='Online Results'!S5 -> 2757 | I3: =SUM(VLOOKUP(C3, Teams!A:B, 2, FALSE), VLOOKUP(D3, Teams!A:B, 2, FALSE), VLOOKUP(E3, Teams!A:B, 2, FALSE)) -> 31.766776 | J3: =SUM(VLOOKUP(F3, Teams!A:B, 2, FALSE), VLOOKUP(G3, Teams!A:B, 2, FALSE), VLOOKUP(H3, Teams!A:B, 2, FALSE)) -> 33.982133 | K3: =IF(P3>Q3,2,IF(P3=Q3,1,0)) -> 0 | L3: =SUM(-1*K3+2) -> 2 | M3: =MIN(P3:Q3) -> 14 | N3: =IF('Online Results'!T5="", "", 'Online Results'!T5) -> 14 | O3: =IF('Online Results'!U5="", "", 'Online Results'!U5) -> 36 | P3: =IF(N3="", I3, N3) -> 14 | Q3: =IF(O3="", J3, O3) -> 36 | R3: =ABS(I3+J3-N3-O3)/(N3+O3) -> 0.31497819 | S3: =SUM(VLOOKUP(C3, Teams!A:B, 2, FALSE), VLOOKUP(D3, Teams!A:B, 2, FALSE), VLOOKUP(E3, Teams!A:B, 2, FALSE)) -> 31.766776 | T3: =SUM(VLOOKUP(F3, Teams!A:B, 2, FALSE), VLOOKUP(G3, Teams!A:B, 2, FALSE), VLOOKUP(H3, Teams!A:B, 2, FALSE)) -> 33.982133 | U3: =R3*SUM(S3, T3)/SUM(AVERAGE($S$2:$S3), AVERAGE($T$2:$T3)) -> 0.31066949 | V3: =AVERAGE($R$2:$R3) -> 0.50214734 | W3: =AVERAGE($U$2:$U3) -> 0.499993 | X3: =IF(S3>T3,IF(N3>O3,0,IF(N3=O3, 1, 2)),IF(S3=T3,IF(N3=O3,0,1), IF(N3<O3, 0, 2))) -> 0 | Y3: =AVERAGE($X$2:$X3)*0.5 -> 0 | AA3: 987
A4: ='Online Results'!L6 -> 0.54791667 | B4: ='Online Results'!M6 -> 3 | C4: ='Online Results'!N6 -> 51 | D4: ='Online Results'!O6 -> 3115 | E4: ='Online Results'!P6 -> 58 | F4: ='Online Results'!Q6 -> 78 | G4: ='Online Results'!R6 -> 2960 | H4: ='Online Results'!S6 -> 3711 | I4: =SUM(VLOOKUP(C4, Teams!A:B, 2, FALSE), VLOOKUP(D4, Teams!A:B, 2, FALSE), VLOOKUP(E4, Teams!A:B, 2, FALSE)) -> 41.528394 | J4: =SUM(VLOOKUP(F4, Teams!A:B, 2, FALSE), VLOOKUP(G4, Teams!A:B, 2, FALSE), VLOOKUP(H4, Teams!A:B, 2, FALSE)) -> 35.202555 | K4: =IF(P4>Q4,2,IF(P4=Q4,1,0)) -> 2 | L4: =SUM(-1*K4+2) -> 0 | M4: =MIN(P4:Q4) -> 30 | N4: =IF('Online Results'!T6="", "", 'Online Results'!T6) -> 45 | O4: =IF('Online Results'!U6="", "", 'Online Results'!U6) -> 30 | P4: =IF(N4="", I4, N4) -> 45 | Q4: =IF(O4="", J4, O4) -> 30 | R4: =ABS(I4+J4-N4-O4)/(N4+O4) -> 0.023079324 | S4: =SUM(VLOOKUP(C4, Teams!A:B, 2, FALSE), VLOOKUP(D4, Teams!A:B, 2, FALSE), VLOOKUP(E4, Teams!A:B, 2, FALSE)) -> 41.528394 | T4: =SUM(VLOOKUP(F4, Teams!A:B, 2, FALSE), VLOOKUP(G4, Teams!A:B, 2, FALSE), VLOOKUP(H4, Teams!A:B, 2, FALSE)) -> 35.202555 | U4: =R4*SUM(S4, T4)/SUM(AVERAGE($S$2:$S4), AVERAGE($T$2:$T4)) -> 0.025292224 | V4: =AVERAGE($R$2:$R4) -> 0.342458 | W4: =AVERAGE($U$2:$U4) -> 0.34175941 | X4: =IF(S4>T4,IF(N4>O4,0,IF(N4=O4, 1, 2)),IF(S4=T4,IF(N4=O4,0,1), IF(N4<O4, 0, 2))) -> 0 | Y4: =AVERAGE($X$2:$X4)*0.5 -> 0
A5: ='Online Results'!L7 -> 0.55208333 | B5: ='Online Results'!M7 -> 4 | C5: ='Online Results'!N7 -> 244 | D5: ='Online Results'!O7 -> 4069 | E5: ='Online Results'!P7 -> 433 | F5: ='Online Results'!Q7 -> 3419 | G5: ='Online Results'!R7 -> 3860 | H5: ='Online Results'!S7 -> 537 | I5: =SUM(VLOOKUP(C5, Teams!A:B, 2, FALSE), VLOOKUP(D5, Teams!A:B, 2, FALSE), VLOOKUP(E5, Teams!A:B, 2, FALSE)) -> 25.51077 | J5: =SUM(VLOOKUP(F5, Teams!A:B, 2, FALSE), VLOOKUP(G5, Teams!A:B, 2, FALSE), VLOOKUP(H5, Teams!A:B, 2, FALSE)) -> 25.7524 | K5: =IF(P5>Q5,2,IF(P5=Q5,1,0)) -> 2 | L5: =SUM(-1*K5+2) -> 0 | M5: =MIN(P5:Q5) -> 19 | N5: =IF('Online Results'!T7="", "", 'Online Results'!T7) -> 32 | O5: =IF('Online Results'!U7="", "", 'Online Results'!U7) -> 19 | P5: =IF(N5="", I5, N5) -> 32 | Q5: =IF(O5="", J5, O5) -> 19 | R5: =ABS(I5+J5-N5-O5)/(N5+O5) -> 0.0051601961 | S5: =SUM(VLOOKUP(C5, Teams!A:B, 2, FALSE), VLOOKUP(D5, Teams!A:B, 2, FALSE), VLOOKUP(E5, Teams!A:B, 2, FALSE)) -> 25.51077 | T5: =SUM(VLOOKUP(F5, Teams!A:B, 2, FALSE), VLOOKUP(G5, Teams!A:B, 2, FALSE), VLOOKUP(H5, Teams!A:B, 2, FALSE)) -> 25.7524 | U5: =R5*SUM(S5, T5)/SUM(AVERAGE($S$2:$S5), AVERAGE($T$2:$T5)) -> 0.0040491715 | V5: =AVERAGE($R$2:$R5) -> 0.25813355 | W5: =AVERAGE($U$2:$U5) -> 0.25733185 | X5: =IF(S5>T5,IF(N5>O5,0,IF(N5=O5, 1, 2)),IF(S5=T5,IF(N5=O5,0,1), IF(N5<O5, 0, 2))) -> 2 | Y5: =AVERAGE($X$2:$X5)*0.5 -> 0.25
A6: ='Online Results'!L8 -> 0.55625 | B6: ='Online Results'!M8 -> 5 | C6: ='Online Results'!N8 -> 3965 | D6: ='Online Results'!O8 -> 4269 | E6: ='Online Results'!P8 -> 2914 | F6: ='Online Results'!Q8 -> 1778 | G6: ='Online Results'!R8 -> 3205 | H6: ='Online Results'!S8 -> 3132 | I6: =SUM(VLOOKUP(C6, Teams!A:B, 2, FALSE), VLOOKUP(D6, Teams!A:B, 2, FALSE), VLOOKUP(E6, Teams!A:B, 2, FALSE)) -> 22.546505 | J6: =SUM(VLOOKUP(F6, Teams!A:B, 2, FALSE), VLOOKUP(G6, Teams!A:B, 2, FALSE), VLOOKUP(H6, Teams!A:B, 2, FALSE)) -> 30.1375 | K6: =IF(P6>Q6,2,IF(P6=Q6,1,0)) -> 0 | L6: =SUM(-1*K6+2) -> 2 | M6: =MIN(P6:Q6) -> 26 | N6: =IF('Online Results'!T8="", "", 'Online Results'!T8) -> 26 | O6: =IF('Online Results'!U8="", "", 'Online Results'!U8) -> 27 | P6: =IF(N6="", I6, N6) -> 26 | Q6: =IF(O6="", J6, O6) -> 27 | R6: =ABS(I6+J6-N6-O6)/(N6+O6) -> 0.0059621698 | S6: =SUM(VLOOKUP(C6, Teams!A:B, 2, FALSE), VLOOKUP(D6, Teams!A:B, 2, FALSE), VLOOKUP(E6, Teams!A:B, 2, FALSE)) -> 22.546505 | T6: =SUM(VLOOKUP(F6, Teams!A:B, 2, FALSE), VLOOKUP(G6, Teams!A:B, 2, FALSE), VLOOKUP(H6, Teams!A:B, 2, FALSE)) -> 30.1375 | U6: =R6*SUM(S6, T6)/SUM(AVERAGE($S$2:$S6), AVERAGE($T$2:$T6)) -> 0.0050017721 | V6: =AVERAGE($R$2:$R6) -> 0.20769928 | W6: =AVERAGE($U$2:$U6) -> 0.20686583 | X6: =IF(S6>T6,IF(N6>O6,0,IF(N6=O6, 1, 2)),IF(S6=T6,IF(N6=O6,0,1), IF(N6<O6, 0, 2))) -> 0 | Y6: =AVERAGE($X$2:$X6)*0.5 -> 0.2
A7: ='Online Results'!L9 -> 0.5625 | B7: ='Online Results'!M9 -> 6 | C7: ='Online Results'!N9 -> 624 | D7: ='Online Results'!O9 -> 3528 | E7: ='Online Results'!P9 -> 3970 | F7: ='Online Results'!Q9 -> 1143 | G7: ='Online Results'!R9 -> 2500 | H7: ='Online Results'!S9 -> 2474 | I7: =SUM(VLOOKUP(C7, Teams!A:B, 2, FALSE), VLOOKUP(D7, Teams!A:B, 2, FALSE), VLOOKUP(E7, Teams!A:B, 2, FALSE)) -> 63.85494 | J7: =SUM(VLOOKUP(F7, Teams!A:B, 2, FALSE), VLOOKUP(G7, Teams!A:B, 2, FALSE), VLOOKUP(H7, Teams!A:B, 2, FALSE)) -> 35.38189 | K7: =IF(P7>Q7,2,IF(P7=Q7,1,0)) -> 2 | L7: =SUM(-1*K7+2) -> 0 | M7: =MIN(P7:Q7) -> 29 | N7: =IF('Online Results'!T9="", "", 'Online Results'!T9) -> 47 | O7: =IF('Online Results'!U9="", "", 'Online Results'!U9) -> 29 | P7: =IF(N7="", I7, N7) -> 47 | Q7: =IF(O7="", J7, O7) -> 29 | R7: =ABS(I7+J7-N7-O7)/(N7+O7) -> 0.30574776 | S7: =SUM(VLOOKUP(C7, Teams!A:B, 2, FALSE), VLOOKUP(D7, Teams!A:B, 2, FALSE), VLOOKUP(E7, Teams!A:B, 2, FALSE)) -> 63.85494 | T7: =SUM(VLOOKUP(F7, Teams!A:B, 2, FALSE), VLOOKUP(G7, Teams!A:B, 2, FALSE), VLOOKUP(H7, Teams!A:B, 2, FALSE)) -> 35.38189 | U7: =R7*SUM(S7, T7)/SUM(AVERAGE($S$2:$S7), AVERAGE($T$2:$T7)) -> 0.44054342 | V7: =AVERAGE($R$2:$R7) -> 0.22404069 | W7: =AVERAGE($U$2:$U7) -> 0.2458121 | X7: =IF(S7>T7,IF(N7>O7,0,IF(N7=O7, 1, 2)),IF(S7=T7,IF(N7=O7,0,1), IF(N7<O7, 0, 2))) -> 0 | Y7: =AVERAGE($X$2:$X7)*0.5 -> 0.16666667
A8: ='Online Results'!L10 -> 0.56805556 | B8: ='Online Results'!M10 -> 7 | C8: ='Online Results'!N10 -> 1507 | D8: ='Online Results'!O10 -> 2844 | E8: ='Online Results'!P10 -> 85 | F8: ='Online Results'!Q10 -> 932 | G8: ='Online Results'!R10 -> 207 | H8: ='Online Results'!S10 -> 1683 | I8: =SUM(VLOOKUP(C8, Teams!A:B, 2, FALSE), VLOOKUP(D8, Teams!A:B, 2, FALSE), VLOOKUP(E8, Teams!A:B, 2, FALSE)) -> 46.628815 | J8: =SUM(VLOOKUP(F8, Teams!A:B, 2, FALSE), VLOOKUP(G8, Teams!A:B, 2, FALSE), VLOOKUP(H8, Teams!A:B, 2, FALSE)) -> 23.491245 | K8: =IF(P8>Q8,2,IF(P8=Q8,1,0)) -> 2 | L8: =SUM(-1*K8+2) -> 0 | M8: =MIN(P8:Q8) -> 1 | N8: =IF('Online Results'!T10="", "", 'Online Results'!T10) -> 22 | O8: =IF('Online Results'!U10="", "", 'Online Results'!U10) -> 1 | P8: =IF(N8="", I8, N8) -> 22 | Q8: =IF(O8="", J8, O8) -> 1 | R8: =ABS(I8+J8-N8-O8)/(N8+O8) -> 2.0486983 | S8: =SUM(VLOOKUP(C8, Teams!A:B, 2, FALSE), VLOOKUP(D8, Teams!A:B, 2, FALSE), VLOOKUP(E8, Teams!A:B, 2, FALSE)) -> 46.628815 | T8: =SUM(VLOOKUP(F8, Teams!A:B, 2, FALSE), VLOOKUP(G8, Teams!A:B, 2, FALSE), VLOOKUP(H8, Teams!A:B, 2, FALSE)) -> 23.491245 | U8: =R8*SUM(S8, T8)/SUM(AVERAGE($S$2:$S8), AVERAGE($T$2:$T8)) -> 2.0804184 | V8: =AVERAGE($R$2:$R8) -> 0.48470606 | W8: =AVERAGE($U$2:$U8) -> 0.50789871 | X8: =IF(S8>T8,IF(N8>O8,0,IF(N8=O8, 1, 2)),IF(S8=T8,IF(N8=O8,0,1), IF(N8<O8, 0, 2))) -> 0 | Y8: =AVERAGE($X$2:$X8)*0.5 -> 0.14285714
A9: ='Online Results'!L11 -> 0.57291667 | B9: ='Online Results'!M11 -> 8 | C9: ='Online Results'!N11 -> 564 | D9: ='Online Results'!O11 -> 1828 | E9: ='Online Results'!P11 -> 1501 | F9: ='Online Results'!Q11 -> 293 | G9: ='Online Results'!R11 -> 1764 | H9: ='Online Results'!S11 -> 604 | I9: =SUM(VLOOKUP(C9, Teams!A:B, 2, FALSE), VLOOKUP(D9, Teams!A:B, 2, FALSE), VLOOKUP(E9, Teams!A:B, 2, FALSE)) -> 25.66116 | J9: =SUM(VLOOKUP(F9, Teams!A:B, 2, FALSE), VLOOKUP(G9, Teams!A:B, 2, FALSE), VLOOKUP(H9, Teams!A:B, 2, FALSE)) -> 21.90598 | K9: =IF(P9>Q9,2,IF(P9=Q9,1,0)) -> 2 | L9: =SUM(-1*K9+2) -> 0 | M9: =MIN(P9:Q9) -> 9 | N9: =IF('Online Results'!T11="", "", 'Online Results'!T11) -> 42 | O9: =IF('Online Results'!U11="", "", 'Online Results'!U11) -> 9 | P9: =IF(N9="", I9, N9) -> 42 | Q9: =IF(O9="", J9, O9) -> 9 | R9: =ABS(I9+J9-N9-O9)/(N9+O9) -> 0.06731098 | S9: =SUM(VLOOKUP(C9, Teams!A:B, 2, FALSE), VLOOKUP(D9, Teams!A:B, 2, FALSE), VLOOKUP(E9, Teams!A:B, 2, FALSE)) -> 25.66116 | T9: =SUM(VLOOKUP(F9, Teams!A:B, 2, FALSE), VLOOKUP(G9, Teams!A:B, 2, FALSE), VLOOKUP(H9, Teams!A:B, 2, FALSE)) -> 21.90598 | U9: =R9*SUM(S9, T9)/SUM(AVERAGE($S$2:$S9), AVERAGE($T$2:$T9)) -> 0.048244833 | V9: =AVERAGE($R$2:$R9) -> 0.43253167 | W9: =AVERAGE($U$2:$U9) -> 0.45044197 | X9: =IF(S9>T9,IF(N9>O9,0,IF(N9=O9, 1, 2)),IF(S9=T9,IF(N9=O9,0,1), IF(N9<O9, 0, 2))) -> 0 | Y9: =AVERAGE($X$2:$X9)*0.5 -> 0.125
A10: ='Online Results'!L12 -> 0.57708333 | B10: ='Online Results'!M12 -> 9 | C10: ='Online Results'!N12 -> 1319 | D10: ='Online Results'!O12 -> 971 | E10: ='Online Results'!P12 -> 27 | F10: ='Online Results'!Q12 -> 4130 | G10: ='Online Results'!R12 -> 2164 | H10: ='Online Results'!S12 -> 341 | I10: =SUM(VLOOKUP(C10, Teams!A:B, 2, FALSE), VLOOKUP(D10, Teams!A:B, 2, FALSE), VLOOKUP(E10, Teams!A:B, 2, FALSE)) -> 52.008898 | J10: =SUM(VLOOKUP(F10, Teams!A:B, 2, FALSE), VLOOKUP(G10, Teams!A:B, 2, FALSE), VLOOKUP(H10, Teams!A:B, 2, FALSE)) -> 45.10215 | K10: =IF(P10>Q10,2,IF(P10=Q10,1,0)) -> 0 | L10: =SUM(-1*K10+2) -> 2 | M10: =MIN(P10:Q10) -> 22 | N10: =IF('Online Results'!T12="", "", 'Online Results'!T12) -> 22 | O10: =IF('Online Results'!U12="", "", 'Online Results'!U12) -> 49 | P10: =IF(N10="", I10, N10) -> 22 | Q10: =IF(O10="", J10, O10) -> 49 | R10: =ABS(I10+J10-N10-O10)/(N10+O10) -> 0.36776124 | S10: =SUM(VLOOKUP(C10, Teams!A:B, 2, FALSE), VLOOKUP(D10, Teams!A:B, 2, FALSE), VLOOKUP(E10, Teams!A:B, 2, FALSE)) -> 52.008898 | T10: =SUM(VLOOKUP(F10, Teams!A:B, 2, FALSE), VLOOKUP(G10, Teams!A:B, 2, FALSE), VLOOKUP(H10, Teams!A:B, 2, FALSE)) -> 45.10215 | U10: =R10*SUM(S10, T10)/SUM(AVERAGE($S$2:$S10), AVERAGE($T$2:$T10)) -> 0.51179192 | V10: =AVERAGE($R$2:$R10) -> 0.42533496 | W10: =AVERAGE($U$2:$U10) -> 0.45725863 | X10: =IF(S10>T10,IF(N10>O10,0,IF(N10=O10, 1, 2)),IF(S10=T10,IF(N10=O10,0,1), IF(N10<O10, 0, 2))) -> 2 | Y10: =AVERAGE($X$2:$X10)*0.5 -> 0.22222222
A11: ='Online Results'!L13 -> 0.58055556 | B11: ='Online Results'!M13 -> 10 | C11: ='Online Results'!N13 -> 2102 | D11: ='Online Results'!O13 -> 694 | E11: ='Online Results'!P13 -> 1477 | F11: ='Online Results'!Q13 -> 116 | G11: ='Online Results'!R13 -> 1678 | H11: ='Online Results'!S13 -> 1511 | I11: =SUM(VLOOKUP(C11, Teams!A:B, 2, FALSE), VLOOKUP(D11, Teams!A:B, 2, FALSE), VLOOKUP(E11, Teams!A:B, 2, FALSE)) -> 47.587133 | J11: =SUM(VLOOKUP(F11, Teams!A:B, 2, FALSE), VLOOKUP(G11, Teams!A:B, 2, FALSE), VLOOKUP(H11, Teams!A:B, 2, FALSE)) -> 49.29435 | K11: =IF(P11>Q11,2,IF(P11=Q11,1,0)) -> 0 | L11: =SUM(-1*K11+2) -> 2 | M11: =MIN(P11:Q11) -> 33 | N11: =IF('Online Results'!T13="", "", 'Online Results'!T13) -> 33 | O11: =IF('Online Results'!U13="", "", 'Online Results'!U13) -> 36 | P11: =IF(N11="", I11, N11) -> 33 | Q11: =IF(O11="", J11, O11) -> 36 | R11: =ABS(I11+J11-N11-O11)/(N11+O11) -> 0.40407947 | S11: =SUM(VLOOKUP(C11, Teams!A:B, 2, FALSE), VLOOKUP(D11, Teams!A:B, 2, FALSE), VLOOKUP(E11, Teams!A:B, 2, FALSE)) -> 47.587133 | T11: =SUM(VLOOKUP(F11, Teams!A:B, 2, FALSE), VLOOKUP(G11, Teams!A:B, 2, FALSE), VLOOKUP(H11, Teams!A:B, 2, FALSE)) -> 49.29435 | U11: =R11*SUM(S11, T11)/SUM(AVERAGE($S$2:$S11), AVERAGE($T$2:$T11)) -> 0.54003229 | V11: =AVERAGE($R$2:$R11) -> 0.42320941 | W11: =AVERAGE($U$2:$U11) -> 0.465536 | X11: =IF(S11>T11,IF(N11>O11,0,IF(N11=O11, 1, 2)),IF(S11=T11,IF(N11=O11,0,1), IF(N11<O11, 0, 2))) -> 0 | Y11: =AVERAGE($X$2:$X11)*0.5 -> 0.2
A12: ='Online Results'!L14 -> 0.58541667 | B12: ='Online Results'!M14 -> 11 | C12: ='Online Results'!N14 -> 254 | D12: ='Online Results'!O14 -> 2591 | E12: ='Online Results'!P14 -> 3936 | F12: ='Online Results'!Q14 -> 3940 | G12: ='Online Results'!R14 -> 1741 | H12: ='Online Results'!S14 -> 2180 | I12: =SUM(VLOOKUP(C12, Teams!A:B, 2, FALSE), VLOOKUP(D12, Teams!A:B, 2, FALSE), VLOOKUP(E12, Teams!A:B, 2, FALSE)) -> 46.21309 | J12: =SUM(VLOOKUP(F12, Teams!A:B, 2, FALSE), VLOOKUP(G12, Teams!A:B, 2, FALSE), VLOOKUP(H12, Teams!A:B, 2, FALSE)) -> 40.83829 | K12: =IF(P12>Q12,2,IF(P12=Q12,1,0)) -> 0 | L12: =SUM(-1*K12+2) -> 2 | M12: =MIN(P12:Q12) -> 26 | N12: =IF('Online Results'!T14="", "", 'Online Results'!T14) -> 26 | O12: =IF('Online Results'!U14="", "", 'Online Results'!U14) -> 27 | P12: =IF(N12="", I12, N12) -> 26 | Q12: =IF(O12="", J12, O12) -> 27 | R12: =ABS(I12+J12-N12-O12)/(N12+O12) -> 0.64247887 | S12: =SUM(VLOOKUP(C12, Teams!A:B, 2, FALSE), VLOOKUP(D12, Teams!A:B, 2, FALSE), VLOOKUP(E12, Teams!A:B, 2, FALSE)) -> 46.21309 | T12: =SUM(VLOOKUP(F12, Teams!A:B, 2, FALSE), VLOOKUP(G12, Teams!A:B, 2, FALSE), VLOOKUP(H12, Teams!A:B, 2, FALSE)) -> 40.83829 | U12: =R12*SUM(S12, T12)/SUM(AVERAGE($S$2:$S12), AVERAGE($T$2:$T12)) -> 0.75768462 | V12: =AVERAGE($R$2:$R12) -> 0.443143 | W12: =AVERAGE($U$2:$U12) -> 0.49209496 | X12: =IF(S12>T12,IF(N12>O12,0,IF(N12=O12, 1, 2)),IF(S12=T12,IF(N12=O12,0,1), IF(N12<O12, 0, 2))) -> 2 | Y12: =AVERAGE($X$2:$X12)*0.5 -> 0.27272727
A13: ='Online Results'!L15 -> 0.59027778 | B13: ='Online Results'!M15 -> 12 | C13: ='Online Results'!N15 -> 597 | D13: ='Online Results'!O15 -> 987 | E13: ='Online Results'!P15 -> 4203 | F13: ='Online Results'!Q15 -> 1266 | G13: ='Online Results'!R15 -> 1817 | H13: ='Online Results'!S15 -> 830 | I13: =SUM(VLOOKUP(C13, Teams!A:B, 2, FALSE), VLOOKUP(D13, Teams!A:B, 2, FALSE), VLOOKUP(E13, Teams!A:B, 2, FALSE)) -> 41.93411 | J13: =SUM(VLOOKUP(F13, Teams!A:B, 2, FALSE), VLOOKUP(G13, Teams!A:B, 2, FALSE), VLOOKUP(H13, Teams!A:B, 2, FALSE)) -> 28.083077 | K13: =IF(P13>Q13,2,IF(P13=Q13,1,0)) -> 2 | L13: =SUM(-1*K13+2) -> 0 | M13: =MIN(P13:Q13) -> 16 | N13: =IF('Online Results'!T15="", "", 'Online Results'!T15) -> 71 | O13: =IF('Online Results'!U15="", "", 'Online Results'!U15) -> 16 | P13: =IF(N13="", I13, N13) -> 71 | Q13: =IF(O13="", J13, O13) -> 16 | R13: =ABS(I13+J13-N13-O13)/(N13+O13) -> 0.19520475 | S13: =SUM(VLOOKUP(C13, Teams!A:B, 2, FALSE), VLOOKUP(D13, Teams!A:B, 2, FALSE), VLOOKUP(E13, Teams!A:B, 2, FALSE)) -> 41.93411 | T13: =SUM(VLOOKUP(F13, Teams!A:B, 2, FALSE), VLOOKUP(G13, Teams!A:B, 2, FALSE), VLOOKUP(H13, Teams!A:B, 2, FALSE)) -> 28.083077 | U13: =R13*SUM(S13, T13)/SUM(AVERAGE($S$2:$S13), AVERAGE($T$2:$T13)) -> 0.18595813 | V13: =AVERAGE($R$2:$R13) -> 0.42248148 | W13: =AVERAGE($U$2:$U13) -> 0.46658356 | X13: =IF(S13>T13,IF(N13>O13,0,IF(N13=O13, 1, 2)),IF(S13=T13,IF(N13=O13,0,1), IF(N13<O13, 0, 2))) -> 0 | Y13: =AVERAGE($X$2:$X13)*0.5 -> 0.25
A14: ='Online Results'!L16 -> 0.59513889 | B14: ='Online Results'!M16 -> 13 | C14: ='Online Results'!N16 -> 3288 | D14: ='Online Results'!O16 -> 233 | E14: ='Online Results'!P16 -> 279 | F14: ='Online Results'!Q16 -> 4226 | G14: ='Online Results'!R16 -> 2130 | H14: ='Online Results'!S16 -> 288 | I14: =SUM(VLOOKUP(C14, Teams!A:B, 2, FALSE), VLOOKUP(D14, Teams!A:B, 2, FALSE), VLOOKUP(E14, Teams!A:B, 2, FALSE)) -> 37.594268 | J14: =SUM(VLOOKUP(F14, Teams!A:B, 2, FALSE), VLOOKUP(G14, Teams!A:B, 2, FALSE), VLOOKUP(H14, Teams!A:B, 2, FALSE)) -> 20.99599 | K14: =IF(P14>Q14,2,IF(P14=Q14,1,0)) -> 2 | L14: =SUM(-1*K14+2) -> 0 | M14: =MIN(P14:Q14) -> 7 | N14: =IF('Online Results'!T16="", "", 'Online Results'!T16) -> 55 | O14: =IF('Online Results'!U16="", "", 'Online Results'!U16) -> 7 | P14: =IF(N14="", I14, N14) -> 55 | Q14: =IF(O14="", J14, O14) -> 7 | R14: =ABS(I14+J14-N14-O14)/(N14+O14) -> 0.054995839 | S14: =SUM(VLOOKUP(C14, Teams!A:B, 2, FALSE), VLOOKUP(D14, Teams!A:B, 2, FALSE), VLOOKUP(E14, Teams!A:B, 2, FALSE)) -> 37.594268 | T14: =SUM(VLOOKUP(F14, Teams!A:B, 2, FALSE), VLOOKUP(G14, Teams!A:B, 2, FALSE), VLOOKUP(H14, Teams!A:B, 2, FALSE)) -> 20.99599 | U14: =R14*SUM(S14, T14)/SUM(AVERAGE($S$2:$S14), AVERAGE($T$2:$T14)) -> 0.044535376 | V14: =AVERAGE($R$2:$R14) -> 0.39421335 | W14: =AVERAGE($U$2:$U14) -> 0.43411832 | X14: =IF(S14>T14,IF(N14>O14,0,IF(N14=O14, 1, 2)),IF(S14=T14,IF(N14=O14,0,1), IF(N14<O14, 0, 2))) -> 0 | Y14: =AVERAGE($X$2:$X14)*0.5 -> 0.23076923
A15: ='Online Results'!L17 -> 0.59861111 | B15: ='Online Results'!M17 -> 14 | C15: ='Online Results'!N17 -> 2522 | D15: ='Online Results'!O17 -> 706 | E15: ='Online Results'!P17 -> 192 | F15: ='Online Results'!Q17 -> 503 | G15: ='Online Results'!R17 -> 525 | H15: ='Online Results'!S17 -> 4161 | I15: =SUM(VLOOKUP(C15, Teams!A:B, 2, FALSE), VLOOKUP(D15, Teams!A:B, 2, FALSE), VLOOKUP(E15, Teams!A:B, 2, FALSE)) -> 33.50611 | J15: =SUM(VLOOKUP(F15, Teams!A:B, 2, FALSE), VLOOKUP(G15, Teams!A:B, 2, FALSE), VLOOKUP(H15, Teams!A:B, 2, FALSE)) -> 39.02373 | K15: =IF(P15>Q15,2,IF(P15=Q15,1,0)) -> 0 | L15: =SUM(-1*K15+2) -> 2 | M15: =MIN(P15:Q15) -> 6 | N15: =IF('Online Results'!T17="", "", 'Online Results'!T17) -> 6 | O15: =IF('Online Results'!U17="", "", 'Online Results'!U17) -> 49 | P15: =IF(N15="", I15, N15) -> 6 | Q15: =IF(O15="", J15, O15) -> 49 | R15: =ABS(I15+J15-N15-O15)/(N15+O15) -> 0.31872436 | S15: =SUM(VLOOKUP(C15, Teams!A:B, 2, FALSE), VLOOKUP(D15, Teams!A:B, 2, FALSE), VLOOKUP(E15, Teams!A:B, 2, FALSE)) -> 33.50611 | T15: =SUM(VLOOKUP(F15, Teams!A:B, 2, FALSE), VLOOKUP(G15, Teams!A:B, 2, FALSE), VLOOKUP(H15, Teams!A:B, 2, FALSE)) -> 39.02373 | U15: =R15*SUM(S15, T15)/SUM(AVERAGE($S$2:$S15), AVERAGE($T$2:$T15)) -> 0.31945199 | V15: =AVERAGE($R$2:$R15) -> 0.38882128 | W15: =AVERAGE($U$2:$U15) -> 0.42592786 | X15: =IF(S15>T15,IF(N15>O15,0,IF(N15=O15, 1, 2)),IF(S15=T15,IF(N15=O15,0,1), IF(N15<O15, 0, 2))) -> 0 | Y15: =AVERAGE($X$2:$X15)*0.5 -> 0.21428571
... A151: ='Online Results'!L153 -> 0.42708333 | B151: ='Online Results'!M153 -> 150 | C151: ='Online Results'!N153 -> 1507 | D151: ='Online Results'!O153 -> 3205 | E151: ='Online Results'!P153 -> 1828 | F151: ='Online Results'!Q153 -> 2164 | G151: ='Online Results'!R153 -> 597 | H151: ='Online Results'!S153 -> 2180 | I151: =SUM(VLOOKUP(C151, Teams!A:B, 2, FALSE), VLOOKUP(D151, Teams!A:B, 2, FALSE), VLOOKUP(E151, Teams!A:B, 2, FALSE)) -> 63.84443 | J151: =SUM(VLOOKUP(F151, Teams!A:B, 2, FALSE), VLOOKUP(G151, Teams!A:B, 2, FALSE), VLOOKUP(H151, Teams!A:B, 2, FALSE)) -> 28.965805 | K151: =IF(P151>Q151,2,IF(P151=Q151,1,0)) -> 2 | L151: =SUM(-1*K151+2) -> 0 | M151: =MIN(P151:Q151) -> 28.965805 | N151: =IF('Online Results'!T153="", "", 'Online Results'!T153) | O151: =IF('Online Results'!U153="", "", 'Online Results'!U153) | P151: =IF(N151="", I151, N151) -> 63.84443 | Q151: =IF(O151="", J151, O151) -> 28.965805 | R151: =ABS(I151+J151-N151-O151)/(N151+O151) -> #VALUE! | S151: =SUM(VLOOKUP(C151, Teams!A:B, 2, FALSE), VLOOKUP(D151, Teams!A:B, 2, FALSE), VLOOKUP(E151, Teams!A:B, 2, FALSE)) -> 63.84443 | T151: =SUM(VLOOKUP(F151, Teams!A:B, 2, FALSE), VLOOKUP(G151, Teams!A:B, 2, FALSE), VLOOKUP(H151, Teams!A:B, 2, FALSE)) -> 28.965805 | U151: =R151*SUM(S151, T151)/SUM(AVERAGE($S$2:$S151), AVERAGE($T$2:$T151)) -> #VALUE! | V151: =AVERAGE($R$2:$R151) -> #VALUE! | W151: =AVERAGE($U$2:$U151) -> #VALUE! | X151: =IF(S151>T151,IF(N151>O151,0,IF(N151=O151, 1, 2)),IF(S151=T151,IF(N151=O151,0,1), IF(N151<O151, 0, 2))) -> 1 | Y151: =AVERAGE($X$2:$X151)*0.5 -> 0.61333333
N152: =IF('Online Results'!T154="", "", 'Online Results'!T154) | O152: =IF('Online Results'!U154="", "", 'Online Results'!U154)

Sheet Online Results
L1: Data as of Match Number 38
A2: Data as of Match Number 38 | L2: Qualification Matches
A3: Rank | B3: Team | C3: QS | D3: HP | E3: BP | F3: TP | G3: CP | H3: Record (W-L-T) | I3: DQ | J3: Played | L3: Time | M3: Match | N3: Red 1 | O3: Red 2 | P3: Red 3 | Q3: Blue 1 | R3: Blue 2 | S3: Blue 3 | T3: Red Score | U3: Blue Score
A4: 1 | B4: 341 | C4: 12 | D4: 83 | E4: 20 | F4: 76 | G4: 6 | H4: 3-0-0 | I4: 0 | J4: 3 | L4: 0.54166667 | M4: 1 | N4: 3929 | O4: 4253 | P4: 1986 | Q4: 4265 | R4: 702 | S4: 3941 | T4: 26 | U4: 14
A5: 2 | B5: 987 | C5: 12 | D5: 77 | E5: 50 | F5: 114 | G5: 6 | H5: 3-0-0 | I5: 0 | J5: 3 | L5: 0.58541667 | M5: 2 | N5: 836 | O5: 2881 | P5: 178 | Q5: 3098 | R5: 1885 | S5: 2757 | T5: 14 | U5: 36
A6: 3 | B6: 1507 | C6: 10 | D6: 66 | E6: 40 | F6: 65 | G6: 4 | H6: 3-0-0 | I6: 0 | J6: 3 | L6: 0.54791667 | M6: 3 | N6: 51 | O6: 3115 | P6: 58 | Q6: 78 | R6: 2960 | S6: 3711 | T6: 45 | U6: 30
A7: 4 | B7: 624 | C7: 10 | D7: 52 | E7: 30 | F7: 85 | G7: 6 | H7: 36557 | I7: 0 | J7: 3 | L7: 0.55208333 | M7: 4 | N7: 244 | O7: 4069 | P7: 433 | Q7: 3419 | R7: 3860 | S7: 537 | T7: 32 | U7: 19
A8: 5 | B8: 836 | C8: 8 | D8: 72 | E8: 30 | F8: 48 | G8: 4 | H8: 36557 | I8: 0 | J8: 3 | L8: 0.55625 | M8: 5 | N8: 3965 | O8: 4269 | P8: 2914 | Q8: 1778 | R8: 3205 | S8: 3132 | T8: 26 | U8: 27
A9: 6 | B9: 3970 | C9: 8 | D9: 64 | E9: 40 | F9: 52 | G9: 4 | H9: 36557 | I9: 0 | J9: 3 | L9: 0.5625 | M9: 6 | N9: 624 | O9: 3528 | P9: 3970 | Q9: 1143 | R9: 2500 | S9: 2474 | T9: 47 | U9: 29
A10: 7 | B10: 3950 | C10: 8 | D10: 49 | E10: 60 | F10: 63 | G10: 2 | H10: 3-0-0 | I10: 0 | J10: 3 | L10: 0.56805556 | M10: 7 | N10: 1507 | O10: 2844 | P10: 85 | Q10: 932 | R10: 207 | S10: 1683 | T10: 22 | U10: 1
A11: 8 | B11: 2164 | C11: 8 | D11: 49 | E11: 0 | F11: 26 | G11: 4 | H11: 2-0-0 | I11: 0 | J11: 2 | L11: 0.57291667 | M11: 8 | N11: 564 | O11: 1828 | P11: 1501 | Q11: 293 | R11: 1764 | S11: 604 | T11: 42 | U11: 9
A12: 9 | B12: 4130 | C12: 8 | D12: 41 | E12: 10 | F12: 46 | G12: 4 | H12: 2-0-0 | I12: 0 | J12: 2 | L12: 0.57708333 | M12: 9 | N12: 1319 | O12: 971 | P12: 27 | Q12: 4130 | R12: 2164 | S12: 341 | T12: 22 | U12: 49
A13: 10 | B13: 597 | C13: 8 | D13: 40 | E13: 20 | F13: 68 | G13: 4 | H13: 2-0-0 | I13: 0 | J13: 2 | L13: 0.58055556 | M13: 10 | N13: 2102 | O13: 694 | P13: 1477 | Q13: 116 | R13: 1678 | S13: 1511 | T13: 33 | U13: 36
A14: 11 | B14: 233 | C14: 8 | D14: 36 | E14: 20 | F14: 35 | G14: 4 | H14: 2-0-0 | I14: 0 | J14: 2 | L14: 0.58541667 | M14: 11 | N14: 254 | O14: 2591 | P14: 3936 | Q14: 3940 | R14: 1741 | S14: 2180 | T14: 26 | U14: 27
A15: 12 | B15: 1683 | C15: 8 | D15: 24 | E15: 20 | F15: 54 | G15: 4 | H15: 36557 | I15: 0 | J15: 3 | L15: 0.59027778 | M15: 12 | N15: 597 | O15: 987 | P15: 4203 | Q15: 1266 | R15: 1817 | S15: 830 | T15: 71 | U15: 16
A16: 13 | B16: 433 | C16: 6 | D16: 54 | E16: 40 | F16: 35 | G16: 2 | H16: 36557 | I16: 0 | J16: 3 | L16: 0.59513889 | M16: 13 | N16: 3288 | O16: 233 | P16: 279 | Q16: 4226 | R16: 2130 | S16: 288 | T16: 55 | U16: 7
A17: 14 | B17: 279 | C17: 6 | D17: 51 | E17: 40 | F17: 23 | G17: 4 | H17: 36527 | I17: 0 | J17: 3 | L17: 0.59861111 | M17: 14 | N17: 2522 | O17: 706 | P17: 192 | Q17: 503 | R17: 525 | S17: 4161 | T17: 6 | U17: 49
A18: 15 | B18: 3098 | C18: 6 | D18: 43 | E18: 20 | F18: 50 | G18: 2 | H18: 36557 | I18: 0 | J18: 3 | L18: 0.60208333 | M18: 15 | N18: 1690 | O18: 1391 | P18: 461 | Q18: 1985 | R18: 3950 | S18: 3880 | T18: 15 | U18: 50
A19: 16 | B19: 3711 | C19: 6 | D19: 41 | E19: 30 | F19: 45 | G19: 4 | H19: 36527 | I19: 0 | J19: 3 | L19: 0.60763889 | M19: 16 | N19: 415 | O19: 1033 | P19: 120 | Q19: 571 | R19: 3847 | S19: 1649 | T19: 10 | U19: 20
A20: 17 | B20: 3528 | C20: 6 | D20: 38 | E20: 20 | F20: 38 | G20: 2 | H20: 2-0-0 | I20: 0 | J20: 2 | L20: 0.62986111 | M20: 17 | N20: 3951 | O20: 1912 | P20: 244 | Q20: 2626 | R20: 3807 | S20: 51 | T20: 25 | U20: 32
A21: 18 | B21: 293 | C21: 6 | D21: 36 | E21: 40 | F21: 34 | G21: 2 | H21: 36557 | I21: 0 | J21: 3 | L21: 0.62083333 | M21: 18 | N21: 836 | O21: 1507 | P21: 293 | Q21: 3970 | R21: 1477 | S21: 1986 | T21: 63 | U21: 59
A22: 19 | B22: 3860 | C22: 6 | D22: 36 | E22: 20 | F22: 39 | G22: 4 | H22: 36527 | I22: 0 | J22: 3 | L22: 0.63194444 | M22: 19 | N22: 3860 | O22: 116 | P22: 3132 | Q22: 2844 | R22: 254 | S22: 2881 | T22: 12 | U22: 33
A23: 20 | B23: 4161 | C23: 6 | D23: 34 | E23: 30 | F23: 25 | G23: 2 | H23: 2-0-0 | I23: 0 | J23: 2 | L23: 0.63541667 | M23: 20 | N23: 2960 | O23: 694 | P23: 3528 | Q23: 1817 | R23: 433 | S23: 1741 | T23: 49 | U23: 24
A24: 21 | B24: 1828 | C24: 6 | D24: 34 | E24: 10 | F24: 34 | G24: 2 | H24: 2-0-0 | I24: 0 | J24: 2 | L24: 0.63958333 | M24: 21 | N24: 597 | O24: 341 | P24: 1885 | Q24: 624 | R24: 932 | S24: 1511 | T24: 57 | U24: 56
A25: 22 | B25: 3288 | C25: 6 | D25: 30 | E25: 30 | F25: 35 | G25: 2 | H25: 2-0-0 | I25: 0 | J25: 2 | L25: 0.64375 | M25: 22 | N25: 3941 | O25: 207 | P25: 3115 | Q25: 1828 | R25: 2757 | S25: 233 | T25: 22 | U25: 36
A26: 23 | B26: 1885 | C26: 6 | D26: 30 | E26: 20 | F26: 43 | G26: 2 | H26: 2-0-0 | I26: 0 | J26: 2 | L26: 0.64722222 | M26: 23 | N26: 4226 | O26: 2591 | P26: 525 | Q26: 1764 | R26: 3098 | S26: 58 | T26: 30 | U26: 46
A27: 24 | B27: 830 | C27: 6 | D27: 28 | E27: 20 | F27: 8 | G27: 4 | H27: 36526 | I27: 0 | J27: 2 | L27: 0.65138889 | M27: 24 | N27: 564 | O27: 85 | P27: 3929 | Q27: 987 | R27: 3950 | S27: 3965 | T27: 29 | U27: 84
A28: 25 | B28: 4203 | C28: 6 | D28: 27 | E28: 30 | F28: 42 | G28: 4 | H28: 36526 | I28: 0 | J28: 2 | L28: 0.65625 | M28: 25 | N28: 1683 | O28: 1690 | P28: 2626 | Q28: 2500 | R28: 2914 | S28: 288 | T28: 33 | U28: 20
A29: 26 | B29: 2500 | C29: 6 | D29: 27 | E29: 20 | F29: 37 | G29: 6 | H29: 0-3-0 | I29: 0 | J29: 3 | L29: 0.66041667 | M29: 26 | N29: 1143 | O29: 503 | P29: 3940 | Q29: 27 | R29: 4069 | S29: 4265 | T29: 35 | U29: 47
A30: 27 | B30: 58 | C30: 6 | D30: 25 | E30: 20 | F30: 46 | G30: 2 | H30: 2-0-0 | I30: 0 | J30: 2 | L30: 0.66388889 | M30: 27 | N30: 3419 | O30: 461 | P30: 3951 | Q30: 1501 | R30: 571 | S30: 1778 | T30: 29 | U30: 16
A31: 28 | B31: 1678 | C31: 6 | D31: 24 | E31: 10 | F31: 50 | G31: 2 | H31: 2-0-0 | I31: 0 | J31: 2 | L31: 0.66875 | M31: 28 | N31: 830 | O31: 4161 | P31: 415 | Q31: 4253 | R31: 3880 | S31: 3711 | T31: 40 | U31: 0
A32: 29 | B32: 4069 | C32: 6 | D32: 23 | E32: 40 | F32: 16 | G32: 2 | H32: 2-0-0 | I32: 0 | J32: 2 | L32: 0.67708333 | M32: 29 | N32: 4203 | O32: 192 | P32: 279 | Q32: 604 | R32: 78 | S32: 1391 | T32: 28 | U32: 34
A33: 30 | B33: 27 | C33: 6 | D33: 23 | E33: 20 | F33: 26 | G33: 4 | H33: 36526 | I33: 0 | J33: 2 | L33: 0.68125 | M33: 30 | N33: 1649 | O33: 2102 | P33: 2180 | Q33: 3807 | R33: 3288 | S33: 971 | T33: 30 | U33: 40
A34: 31 | B34: 2844 | C34: 6 | D34: 22 | E34: 0 | F34: 33 | G34: 2 | H34: 2-0-0 | I34: 0 | J34: 2 | L34: 0.68541667 | M34: 31 | N34: 3205 | O34: 537 | P34: 2130 | Q34: 3847 | R34: 706 | S34: 1319 | T34: 45 | U34: 31
A35: 32 | B35: 1764 | C35: 6 | D35: 20 | E35: 10 | F35: 42 | G35: 4 | H35: 36527 | I35: 0 | J35: 3 | L35: 0.68819444 | M35: 32 | N35: 2164 | O35: 178 | P35: 702 | Q35: 1266 | R35: 1985 | S35: 1033 | T35: 26 | U35: 11
A36: 33 | B36: 4265 | C36: 6 | D36: 17 | E36: 40 | F36: 39 | G36: 4 | H36: 36527 | I36: 0 | J36: 3 | L36: 0.69236111 | M36: 33 | N36: 1678 | O36: 4130 | P36: 4269 | Q36: 2474 | R36: 120 | S36: 1912 | T36: 48 | U36: 24
A37: 34 | B37: 4226 | C37: 6 | D37: 16 | E37: 20 | F37: 26 | G37: 6 | H37: 0-3-0 | I37: 0 | J37: 3 | L37: 0.69791667 | M37: 34 | N37: 3936 | O37: 3950 | P37: 293 | Q37: 2522 | R37: 2757 | S37: 694 | T37: 38 | U37: 27
A38: 35 | B38: 2626 | C38: 6 | D38: 10 | E38: 30 | F38: 25 | G38: 2 | H38: 2-0-0 | I38: 0 | J38: 2 | L38: 0.70625 | M38: 35 | N38: 1817 | O38: 3941 | P38: 1764 | Q38: 3860 | R38: 624 | S38: 1683 | T38: 17 | U38: 64
A39: 36 | B39: 415 | C39: 4 | D39: 48 | E39: 20 | F39: 13 | G39: 2 | H39: 36527 | I39: 0 | J39: 3 | L39: 0.70972222 | M39: 36 | N39: 2500 | O39: 4265 | P39: 571 | Q39: 3711 | R39: 1507 | S39: 987 | T39: 35 | U39: 86
A40: 37 | B40: 1986 | C40: 4 | D40: 42 | E40: 20 | F40: 23 | G40: 2 | H40: 36526 | I40: 0 | J40: 2 | L40: 0.71666667 | M40: 37 | N40: 836 | O40: 341 | P40: 433 | Q40: 192 | R40: 207 | S40: 4226 | T40: 73 | U40: 25
...

Sheet Enter Team Data Here
A1: Team | B1: OPR | D1: Avg OPR | F1: Team List | G1: OPR | H1: CP | I1: RS as R1 | J1: RS as R2 | K1: RS as R3 | L1: RS as B1 | M1: RS as B2 | N1: RS as B3 | O1: QS as R1 | P1: QS as R2 | Q1: QS as R3 | R1: QS as B1 | S1: QS as B2 | T1: QS as B3 | U1: RS | V1: QS | W1: QS+CP | Y1: Do not sort!
A2: 27 | B2: 28.4371 | C2: =IF(A2=A3, IF(A3=A4, IF(A4=A5, AVERAGE(B2:B5), AVERAGE(B2:B4)), AVERAGE(B2:B3)), B2) -> 19.507575 | D2: =IF(A2=A1, D1, C2) -> 19.507575 | F2: ='Online Results'!B4 -> 341 | G2: =VLOOKUP(F2,A:D,3, FALSE ) -> 34.869675 | H2: =VLOOKUP(F2, 'Online Results'!$B$3:$G$103, 6, FALSE) -> 6 | I2: =SUMIF(Matches!C:C, $F2, Matches!$M:$M) -> 41.49926 | J2: =SUMIF(Matches!D:D, $F2, Matches!$M:$M) -> 114.33412 | K2: =SUMIF(Matches!E:E, $F2, Matches!$M:$M) -> 0 | L2: =SUMIF(Matches!F:F, $F2, Matches!$M:$M) -> 0 | M2: =SUMIF(Matches!G:G, $F2, Matches!$M:$M) -> 49.595876 | N2: =SUMIF(Matches!H:H, $F2, Matches!$M:$M) -> 74.572875 | O2: =SUMIF(Matches!C:C,$F2,Matches!$K:$K) -> 2 | P2: =SUMIF(Matches!D:D,$F2,Matches!$K:$K) -> 6 | Q2: =SUMIF(Matches!E:E,$F2,Matches!$K:$K) -> 0 | R2: =SUMIF(Matches!F:F,$F2,Matches!$L:$L) -> 0 | S2: =SUMIF(Matches!G:G,$F2,Matches!$L:$L) -> 4 | T2: =SUMIF(Matches!H:H,$F2,Matches!$L:$L) -> 6 | U2: =SUM(I2:N2) -> 280.00213 | V2: =SUM(O2:T2) -> 18 | W2: =H2+V2 -> 24
A3: 27 | B3: 20.4626 | C3: =IF(A3=A4, IF(A4=A5, IF(A5=A6, AVERAGE(B3:B6), AVERAGE(B3:B5)), AVERAGE(B3:B4)), B3) -> 16.531067 | D3: =IF(A3=A2, D2, C3) -> 19.507575 | F3: ='Online Results'!B5 -> 987 | G3: =VLOOKUP(F3,A:D,3, FALSE ) -> 33.0073 | H3: =VLOOKUP(F3, 'Online Results'!$B$3:$G$103, 6, FALSE) -> 6 | I3: =SUMIF(Matches!C:C, $F3, Matches!$M:$M) -> 49.21345 | J3: =SUMIF(Matches!D:D, $F3, Matches!$M:$M) -> 43.90534 | K3: =SUMIF(Matches!E:E, $F3, Matches!$M:$M) -> 76.244653 | L3: =SUMIF(Matches!F:F, $F3, Matches!$M:$M) -> 29 | M3: =SUMIF(Matches!G:G, $F3, Matches!$M:$M) -> 25.833093 | N3: =SUMIF(Matches!H:H, $F3, Matches!$M:$M) -> 57.58398 | O3: =SUMIF(Matches!C:C,$F3,Matches!$K:$K) -> 2 | P3: =SUMIF(Matches!D:D,$F3,Matches!$K:$K) -> 4 | Q3: =SUMIF(Matches!E:E,$F3,Matches!$K:$K) -> 4 | R3: =SUMIF(Matches!F:F,$F3,Matches!$L:$L) -> 2 | S3: =SUMIF(Matches!G:G,$F3,Matches!$L:$L) -> 2 | T3: =SUMIF(Matches!H:H,$F3,Matches!$L:$L) -> 4 | U3: =SUM(I3:N3) -> 281.78052 | V3: =SUM(O3:T3) -> 18 | W3: =H3+V3 -> 24
A4: 27 | B4: 16.1615 | C4: =IF(A4=A5, IF(A5=A6, IF(A6=A7, AVERAGE(B4:B7), AVERAGE(B4:B6)), AVERAGE(B4:B5)), B4) -> 14.5653 | D4: =IF(A4=A3, D3, C4) -> 19.507575 | F4: ='Online Results'!B6 -> 1507 | G4: =VLOOKUP(F4,A:D,3, FALSE ) -> 30.17285 | H4: =VLOOKUP(F4, 'Online Results'!$B$3:$G$103, 6, FALSE) -> 4 | I4: =SUMIF(Matches!C:C, $F4, Matches!$M:$M) -> 29.965805 | J4: =SUMIF(Matches!D:D, $F4, Matches!$M:$M) -> 59 | K4: =SUMIF(Matches!E:E, $F4, Matches!$M:$M) -> 45.848665 | L4: =SUMIF(Matches!F:F, $F4, Matches!$M:$M) -> 137.99356 | M4: =SUMIF(Matches!G:G, $F4, Matches!$M:$M) -> 35 | N4: =SUMIF(Matches!H:H, $F4, Matches!$M:$M) -> 0 | O4: =SUMIF(Matches!C:C,$F4,Matches!$K:$K) -> 4 | P4: =SUMIF(Matches!D:D,$F4,Matches!$K:$K) -> 2 | Q4: =SUMIF(Matches!E:E,$F4,Matches!$K:$K) -> 2 | R4: =SUMIF(Matches!F:F,$F4,Matches!$L:$L) -> 8 | S4: =SUMIF(Matches!G:G,$F4,Matches!$L:$L) -> 2 | T4: =SUMIF(Matches!H:H,$F4,Matches!$L:$L) -> 0 | U4: =SUM(I4:N4) -> 307.80803 | V4: =SUM(O4:T4) -> 18 | W4: =H4+V4 -> 22
A5: 27 | B5: 12.9691 | C5: =IF(A5=A6, IF(A6=A7, IF(A7=A8, AVERAGE(B5:B8), AVERAGE(B5:B7)), AVERAGE(B5:B6)), B5) -> 12.9691 | D5: =IF(A5=A4, D4, C5) -> 19.507575 | F5: ='Online Results'!B7 -> 624 | G5: =VLOOKUP(F5,A:D,3, FALSE ) -> 28.8894 | H5: =VLOOKUP(F5, 'Online Results'!$B$3:$G$103, 6, FALSE) -> 6 | I5: =SUMIF(Matches!C:C, $F5, Matches!$M:$M) -> 29 | J5: =SUMIF(Matches!D:D, $F5, Matches!$M:$M) -> 51.326986 | K5: =SUMIF(Matches!E:E, $F5, Matches!$M:$M) -> 33.73621 | L5: =SUMIF(Matches!F:F, $F5, Matches!$M:$M) -> 160.53666 | M5: =SUMIF(Matches!G:G, $F5, Matches!$M:$M) -> 17 | N5: =SUMIF(Matches!H:H, $F5, Matches!$M:$M) -> 0 | O5: =SUMIF(Matches!C:C,$F5,Matches!$K:$K) -> 2 | P5: =SUMIF(Matches!D:D,$F5,Matches!$K:$K) -> 2 | Q5: =SUMIF(Matches!E:E,$F5,Matches!$K:$K) -> 2 | R5: =SUMIF(Matches!F:F,$F5,Matches!$L:$L) -> 4 | S5: =SUMIF(Matches!G:G,$F5,Matches!$L:$L) -> 2 | T5: =SUMIF(Matches!H:H,$F5,Matches!$L:$L) -> 0 | U5: =SUM(I5:N5) -> 291.59986 | V5: =SUM(O5:T5) -> 12 | W5: =H5+V5 -> 18
A6: 51 | B6: 24.8475 | C6: =IF(A6=A7, IF(A7=A8, IF(A8=A9, AVERAGE(B6:B9), AVERAGE(B6:B8)), AVERAGE(B6:B7)), B6) -> 21.605133 | D6: =IF(A6=A5, D5, C6) -> 21.605133 | F6: ='Online Results'!B8 -> 836 | G6: =VLOOKUP(F6,A:D,3, FALSE ) -> 19.3026 | H6: =VLOOKUP(F6, 'Online Results'!$B$3:$G$103, 6, FALSE) -> 4 | I6: =SUMIF(Matches!C:C, $F6, Matches!$M:$M) -> 98 | J6: =SUMIF(Matches!D:D, $F6, Matches!$M:$M) -> 26.585975 | K6: =SUMIF(Matches!E:E, $F6, Matches!$M:$M) -> 66.04377 | L6: =SUMIF(Matches!F:F, $F6, Matches!$M:$M) -> 0 | M6: =SUMIF(Matches!G:G, $F6, Matches!$M:$M) -> 65.876895 | N6: =SUMIF(Matches!H:H, $F6, Matches!$M:$M) -> 39.597075 | O6: =SUMIF(Matches!C:C,$F6,Matches!$K:$K) -> 4 | P6: =SUMIF(Matches!D:D,$F6,Matches!$K:$K) -> 0 | Q6: =SUMIF(Matches!E:E,$F6,Matches!$K:$K) -> 2 | R6: =SUMIF(Matches!F:F,$F6,Matches!$L:$L) -> 0 | S6: =SUMIF(Matches!G:G,$F6,Matches!$L:$L) -> 4 | T6: =SUMIF(Matches!H:H,$F6,Matches!$L:$L) -> 0 | U6: =SUM(I6:N6) -> 296.10372 | V6: =SUM(O6:T6) -> 10 | W6: =H6+V6 -> 14
A7: 51 | B7: 23.5172 | C7: =IF(A7=A8, IF(A8=A9, IF(A9=A10, AVERAGE(B7:B10), AVERAGE(B7:B9)), AVERAGE(B7:B8)), B7) -> 19.98395 | D7: =IF(A7=A6, D6, C7) -> 21.605133 | F7: ='Online Results'!B9 -> 3970 | G7: =VLOOKUP(F7,A:D,3, FALSE ) -> 13.44124 | H7: =VLOOKUP(F7, 'Online Results'!$B$3:$G$103, 6, FALSE) -> 4 | I7: =SUMIF(Matches!C:C, $F7, Matches!$M:$M) -> 38.802315 | J7: =SUMIF(Matches!D:D, $F7, Matches!$M:$M) -> 37.997351 | K7: =SUMIF(Matches!E:E, $F7, Matches!$M:$M) -> 55.712157 | L7: =SUMIF(Matches!F:F, $F7, Matches!$M:$M) -> 90 | M7: =SUMIF(Matches!G:G, $F7, Matches!$M:$M) -> 28.35577 | N7: =SUMIF(Matches!H:H, $F7, Matches!$M:$M) -> 23.81534 | O7: =SUMIF(Matches!C:C,$F7,Matches!$K:$K) -> 4 | P7: =SUMIF(Matches!D:D,$F7,Matches!$K:$K) -> 0 | Q7: =SUMIF(Matches!E:E,$F7,Matches!$K:$K) -> 4 | R7: =SUMIF(Matches!F:F,$F7,Matches!$L:$L) -> 2 | S7: =SUMIF(Matches!G:G,$F7,Matches!$L:$L) -> 2 | T7: =SUMIF(Matches!H:H,$F7,Matches!$L:$L) -> 0 | U7: =SUM(I7:N7) -> 274.68293 | V7: =SUM(O7:T7) -> 12 | W7: =H7+V7 -> 16
A8: 51 | B8: 16.4507 | C8: =IF(A8=A9, IF(A9=A10, IF(A10=A11, AVERAGE(B8:B11), AVERAGE(B8:B10)), AVERAGE(B8:B9)), B8) -> 16.4507 | D8: =IF(A8=A7, D7, C8) -> 21.605133 | F8: ='Online Results'!B10 -> 3950 | G8: =VLOOKUP(F8,A:D,3, FALSE ) -> 5.80187 | H8: =VLOOKUP(F8, 'Online Results'!$B$3:$G$103, 6, FALSE) -> 2 | I8: =SUMIF(Matches!C:C, $F8, Matches!$M:$M) -> 19.106655 | J8: =SUMIF(Matches!D:D, $F8, Matches!$M:$M) -> 27 | K8: =SUMIF(Matches!E:E, $F8, Matches!$M:$M) -> 53.65273 | L8: =SUMIF(Matches!F:F, $F8, Matches!$M:$M) -> 14.862915 | M8: =SUMIF(Matches!G:G, $F8, Matches!$M:$M) -> 82.880976 | N8: =SUMIF(Matches!H:H, $F8, Matches!$M:$M) -> 25.79627 | O8: =SUMIF(Matches!C:C,$F8,Matches!$K:$K) -> 0 | P8: =SUMIF(Matches!D:D,$F8,Matches!$K:$K) -> 2 | Q8: =SUMIF(Matches!E:E,$F8,Matches!$K:$K) -> 4 | R8: =SUMIF(Matches!F:F,$F8,Matches!$L:$L) -> 2 | S8: =SUMIF(Matches!G:G,$F8,Matches!$L:$L) -> 6 | T8: =SUMIF(Matches!H:H,$F8,Matches!$L:$L) -> 0 | U8: =SUM(I8:N8) -> 223.29955 | V8: =SUM(O8:T8) -> 14 | W8: =H8+V8 -> 16
A9: 58 | B9: 18.6124 | C9: =IF(A9=A10, IF(A10=A11, IF(A11=A12, AVERAGE(B9:B12), AVERAGE(B9:B11)), AVERAGE(B9:B10)), B9) -> 18.6124 | D9: =IF(A9=A8, D8, C9) -> 18.6124 | F9: ='Online Results'!B11 -> 2164 | G9: =VLOOKUP(F9,A:D,3, FALSE ) -> 5.661875 | H9: =VLOOKUP(F9, 'Online Results'!$B$3:$G$103, 6, FALSE) -> 4 | I9: =SUMIF(Matches!C:C, $F9, Matches!$M:$M) -> 52.542373 | J9: =SUMIF(Matches!D:D, $F9, Matches!$M:$M) -> 0 | K9: =SUMIF(Matches!E:E, $F9, Matches!$M:$M) -> 12.44601 | L9: =SUMIF(Matches!F:F, $F9, Matches!$M:$M) -> 55.708975 | M9: =SUMIF(Matches!G:G, $F9, Matches!$M:$M) -> 62.739668 | N9: =SUMIF(Matches!H:H, $F9, Matches!$M:$M) -> 22.388487 | O9: =SUMIF(Matches!C:C,$F9,Matches!$K:$K) -> 2 | P9: =SUMIF(Matches!D:D,$F9,Matches!$K:$K) -> 0 | Q9: =SUMIF(Matches!E:E,$F9,Matches!$K:$K) -> 2 | R9: =SUMIF(Matches!F:F,$F9,Matches!$L:$L) -> 2 | S9: =SUMIF(Matches!G:G,$F9,Matches!$L:$L) -> 2 | T9: =SUMIF(Matches!H:H,$F9,Matches!$L:$L) -> 2 | U9: =SUM(I9:N9) -> 205.82551 | V9: =SUM(O9:T9) -> 10 | W9: =H9+V9 -> 14
A10: 78 | B10: 20.2057 | C10: =IF(A10=A11, IF(A11=A12, IF(A12=A13, AVERAGE(B10:B13), AVERAGE(B10:B12)), AVERAGE(B10:B11)), B10) -> 13.8272 | D10: =IF(A10=A9, D9, C10) -> 13.8272 | F10: ='Online Results'!B12 -> 4130 | G10: =VLOOKUP(F10,A:D,3, FALSE ) -> 4.5706 | H10: =VLOOKUP(F10, 'Online Results'!$B$3:$G$103, 6, FALSE) -> 4 | I10: =SUMIF(Matches!C:C, $F10, Matches!$M:$M) -> 52.1439 | J10: =SUMIF(Matches!D:D, $F10, Matches!$M:$M) -> 64.2475 | K10: =SUMIF(Matches!E:E, $F10, Matches!$M:$M) -> 0 | L10: =SUMIF(Matches!F:F, $F10, Matches!$M:$M) -> 22 | M10: =SUMIF(Matches!G:G, $F10, Matches!$M:$M) -> 20.31075 | N10: =SUMIF(Matches!H:H, $F10, Matches!$M:$M) -> 84.11531 | O10: =SUMIF(Matches!C:C,$F10,Matches!$K:$K) -> 0 | P10: =SUMIF(Matches!D:D,$F10,Matches!$K:$K) -> 2 | Q10: =SUMIF(Matches!E:E,$F10,Matches!$K:$K) -> 0 | R10: =SUMIF(Matches!F:F,$F10,Matches!$L:$L) -> 2 | S10: =SUMIF(Matches!G:G,$F10,Matches!$L:$L) -> 2 | T10: =SUMIF(Matches!H:H,$F10,Matches!$L:$L) -> 2 | U10: =SUM(I10:N10) -> 242.81746 | V10: =SUM(O10:T10) -> 8 | W10: =H10+V10 -> 12
A11: 78 | B11: 7.4487 | C11: =IF(A11=A12, IF(A12=A13, IF(A13=A14, AVERAGE(B11:B14), AVERAGE(B11:B13)), AVERAGE(B11:B12)), B11) -> 7.4487 | D11: =IF(A11=A10, D10, C11) -> 13.8272 | F11: ='Online Results'!B13 -> 597 | G11: =VLOOKUP(F11,A:D,3, FALSE ) -> 6.92963 | H11: =VLOOKUP(F11, 'Online Results'!$B$3:$G$103, 6, FALSE) -> 4 | I11: =SUMIF(Matches!C:C, $F11, Matches!$M:$M) -> 97.79627 | J11: =SUMIF(Matches!D:D, $F11, Matches!$M:$M) -> 0 | K11: =SUMIF(Matches!E:E, $F11, Matches!$M:$M) -> 15.03003 | L11: =SUMIF(Matches!F:F, $F11, Matches!$M:$M) -> 29.12903 | M11: =SUMIF(Matches!G:G, $F11, Matches!$M:$M) -> 67.325191 | N11: =SUMIF(Matches!H:H, $F11, Matches!$M:$M) -> 19.395135 | O11: =SUMIF(Matches!C:C,$F11,Matches!$K:$K) -> 6 | P11: =SUMIF(Matches!D:D,$F11,Matches!$K:$K) -> 0 | Q11: =SUMIF(Matches!E:E,$F11,Matches!$K:$K) -> 0 | R11: =SUMIF(Matches!F:F,$F11,Matches!$L:$L) -> 0 | S11: =SUMIF(Matches!G:G,$F11,Matches!$L:$L) -> 0 | T11: =SUMIF(Matches!H:H,$F11,Matches!$L:$L) -> 0 | U11: =SUM(I11:N11) -> 228.67566 | V11: =SUM(O11:T11) -> 6 | W11: =H11+V11 -> 10
A12: 85 | B12: 15.8779 | C12: =IF(A12=A13, IF(A13=A14, IF(A14=A15, AVERAGE(B12:B15), AVERAGE(B12:B14)), AVERAGE(B12:B13)), B12) -> 13.47266 | D12: =IF(A12=A11, D11, C12) -> 13.47266 | F12: ='Online Results'!B14 -> 233 | G12: =VLOOKUP(F12,A:D,3, FALSE ) -> 18.10485 | H12: =VLOOKUP(F12, 'Online Results'!$B$3:$G$103, 6, FALSE) -> 4 | I12: =SUMIF(Matches!C:C, $F12, Matches!$M:$M) -> 20.40248 | J12: =SUMIF(Matches!D:D, $F12, Matches!$M:$M) -> 42.35333 | K12: =SUMIF(Matches!E:E, $F12, Matches!$M:$M) -> 67.504398 | L12: =SUMIF(Matches!F:F, $F12, Matches!$M:$M) -> 0 | M12: =SUMIF(Matches!G:G, $F12, Matches!$M:$M) -> 60.040765 | N12: =SUMIF(Matches!H:H, $F12, Matches!$M:$M) -> 53.38385 | O12: =SUMIF(Matches!C:C,$F12,Matches!$K:$K) -> 2 | P12: =SUMIF(Matches!D:D,$F12,Matches!$K:$K) -> 2 | Q12: =SUMIF(Matches!E:E,$F12,Matches!$K:$K) -> 2 | R12: =SUMIF(Matches!F:F,$F12,Matches!$L:$L) -> 0 | S12: =SUMIF(Matches!G:G,$F12,Matches!$L:$L) -> 2 | T12: =SUMIF(Matches!H:H,$F12,Matches!$L:$L) -> 2 | U12: =SUM(I12:N12) -> 243.68482 | V12: =SUM(O12:T12) -> 10 | W12: =H12+V12 -> 14
A13: 85 | B13: 15.067 | C13: =IF(A13=A14, IF(A14=A15, IF(A15=A16, AVERAGE(B13:B16), AVERAGE(B13:B15)), AVERAGE(B13:B14)), B13) -> 12.27004 | D13: =IF(A13=A12, D12, C13) -> 13.47266 | F13: ='Online Results'!B15 -> 1683 | G13: =VLOOKUP(F13,A:D,3, FALSE ) -> 10.164 | H13: =VLOOKUP(F13, 'Online Results'!$B$3:$G$103, 6, FALSE) -> 4 | I13: =SUMIF(Matches!C:C, $F13, Matches!$M:$M) -> 20 | J13: =SUMIF(Matches!D:D, $F13, Matches!$M:$M) -> 62.502193 | K13: =SUMIF(Matches!E:E, $F13, Matches!$M:$M) -> 31.739 | L13: =SUMIF(Matches!F:F, $F13, Matches!$M:$M) -> 49.706293 | M13: =SUMIF(Matches!G:G, $F13, Matches!$M:$M) -> 0 | N13: =SUMIF(Matches!H:H, $F13, Matches!$M:$M) -> 44.712157 | O13: =SUMIF(Matches!C:C,$F13,Matches!$K:$K) -> 2 | P13: =SUMIF(Matches!D:D,$F13,Matches!$K:$K) -> 0 | Q13: =SUMIF(Matches!E:E,$F13,Matches!$K:$K) -> 0 | R13: =SUMIF(Matches!F:F,$F13,Matches!$L:$L) -> 0 | S13: =SUMIF(Matches!G:G,$F13,Matches!$L:$L) -> 0 | T13: =SUMIF(Matches!H:H,$F13,Matches!$L:$L) -> 2 | U13: =SUM(I13:N13) -> 208.65964 | V13: =SUM(O13:T13) -> 4 | W13: =H13+V13 -> 8
... A101: 1678 | B101: 20.4106 | C101: =IF(A101=A102, IF(A102=A103, IF(A103=A104, AVERAGE(B101:B104), AVERAGE(B101:B103)), AVERAGE(B101:B102)), B101) -> 20.4106 | D101: =IF(A101=A100, D100, C101) -> 23.24525 | F101: ='Online Results'!B103 -> 706 | G101: =VLOOKUP(F101,A:D,3, FALSE ) -> 9.42203 | H101: =VLOOKUP(F101, 'Online Results'!$B$3:$G$103, 6, FALSE) -> 0 | I101: =SUMIF(Matches!C:C, $F101, Matches!$M:$M) -> 39.724581 | J101: =SUMIF(Matches!D:D, $F101, Matches!$M:$M) -> 54.557038 | K101: =SUMIF(Matches!E:E, $F101, Matches!$M:$M) -> 26.92022 | L101: =SUMIF(Matches!F:F, $F101, Matches!$M:$M) -> 0 | M101: =SUMIF(Matches!G:G, $F101, Matches!$M:$M) -> 88.0162 | N101: =SUMIF(Matches!H:H, $F101, Matches!$M:$M) -> 26.76473 | O101: =SUMIF(Matches!C:C,$F101,Matches!$K:$K) -> 4 | P101: =SUMIF(Matches!D:D,$F101,Matches!$K:$K) -> 0 | Q101: =SUMIF(Matches!E:E,$F101,Matches!$K:$K) -> 0 | R101: =SUMIF(Matches!F:F,$F101,Matches!$L:$L) -> 0 | S101: =SUMIF(Matches!G:G,$F101,Matches!$L:$L) -> 2 | T101: =SUMIF(Matches!H:H,$F101,Matches!$L:$L) -> 2 | U101: =SUM(I101:N101) -> 235.98277 | V101: =SUM(O101:T101) -> 8 | W101: =H101+V101 -> 8
A102: 1683 | B102: 10.164 | C102: =IF(A102=A103, IF(A103=A104, IF(A104=A105, AVERAGE(B102:B105), AVERAGE(B102:B104)), AVERAGE(B102:B103)), B102) -> 10.164 | D102: =IF(A102=A101, D101, C102) -> 10.164
A103: 1690 | B103: 13.4712 | C103: =IF(A103=A104, IF(A104=A105, IF(A105=A106, AVERAGE(B103:B106), AVERAGE(B103:B105)), AVERAGE(B103:B104)), B103) -> 13.4712 | D103: =IF(A103=A102, D102, C103) -> 13.4712
A104: 1741 | B104: 20.393 | C104: =IF(A104=A105, IF(A105=A106, IF(A106=A107, AVERAGE(B104:B107), AVERAGE(B104:B106)), AVERAGE(B104:B105)), B104) -> 12.09299 | D104: =IF(A104=A103, D103, C104) -> 12.09299
A105: 1741 | B105: 3.79298 | C105: =IF(A105=A106, IF(A106=A107, IF(A107=A108, AVERAGE(B105:B108), AVERAGE(B105:B107)), AVERAGE(B105:B106)), B105) -> 3.79298 | D105: =IF(A105=A104, D104, C105) -> 12.09299
A106: 1764 | B106: 12.8275 | C106: =IF(A106=A107, IF(A107=A108, IF(A108=A109, AVERAGE(B106:B109), AVERAGE(B106:B108)), AVERAGE(B106:B107)), B106) -> 7.430255 | D106: =IF(A106=A105, D105, C106) -> 7.430255
A107: 1764 | B107: 2.03301 | C107: =IF(A107=A108, IF(A108=A109, IF(A109=A110, AVERAGE(B107:B110), AVERAGE(B107:B109)), AVERAGE(B107:B108)), B107) -> 2.03301 | D107: =IF(A107=A106, D106, C107) -> 7.430255
A108: 1778 | B108: 2.85233 | C108: =IF(A108=A109, IF(A109=A110, IF(A110=A111, AVERAGE(B108:B111), AVERAGE(B108:B110)), AVERAGE(B108:B109)), B108) -> 2.85233 | D108: =IF(A108=A107, D107, C108) -> 2.85233
A109: 1817 | B109: 6.73501 | C109: =IF(A109=A110, IF(A110=A111, IF(A111=A112, AVERAGE(B109:B112), AVERAGE(B109:B111)), AVERAGE(B109:B110)), B109) -> 5.187 | D109: =IF(A109=A108, D108, C109) -> 5.187
A110: 1817 | B110: 3.63899 | C110: =IF(A110=A111, IF(A111=A112, IF(A112=A113, AVERAGE(B110:B113), AVERAGE(B110:B112)), AVERAGE(B110:B111)), B110) -> 3.63899 | D110: =IF(A110=A109, D109, C110) -> 5.187
A111: 1828 | B111: 17.1834 | C111: =IF(A111=A112, IF(A112=A113, IF(A113=A114, AVERAGE(B111:B114), AVERAGE(B111:B113)), AVERAGE(B111:B112)), B111) -> 9.75788 | D111: =IF(A111=A110, D110, C111) -> 9.75788
A112: 1828 | B112: 2.33236 | C112: =IF(A112=A113, IF(A113=A114, IF(A114=A115, AVERAGE(B112:B115), AVERAGE(B112:B114)), AVERAGE(B112:B113)), B112) -> 2.33236 | D112: =IF(A112=A111, D111, C112) -> 9.75788
A113: 1885 | B113: 12.1818 | C113: =IF(A113=A114, IF(A114=A115, IF(A115=A116, AVERAGE(B113:B116), AVERAGE(B113:B115)), AVERAGE(B113:B114)), B113) -> 11.1947 | D113: =IF(A113=A112, D112, C113) -> 11.1947
... A190: 4269 | B190: 5.97547 | C190: =IF(A190=A191, IF(A191=A192, IF(A192=A193, AVERAGE(B190:B193), AVERAGE(B190:B192)), AVERAGE(B190:B191)), B190) -> 5.97547 | D190: =IF(A190=A189, D189, C190) -> 5.97547
