Workbook

Sheet April 2013 - Data
A1: Department / Read date 3/31/2013 | B1: General Ledger | C1: GL Description | D1: Building | E1: Room | F1: Model | G1: Device Type | H1: Ricoh Tag | I1: Total BW Click Count | J1: Total Color Click Count | K1: BW Click Charge | L1: Color Click Charge | M1: Device Total Click Charge | N1: Serial Number | O1: IP Address | P1: CPC BW | Q1: CPC Color | R1: Prev BW Click Count | S1: Current BW Click Count | T1: Prev Color Click Count | U1: Current Color Click Count
A2: Academic Advising | B2: 10_07_205_90300_5521 | C2: =VLOOKUP(B2,Tables!$G$2:$H$90,2,FALSE) -> Academic Advising | D2: Shell Hall | E2: 301 | F2: AF SPC242DN | G2: =VLOOKUP(F2,Tables!$D$2:$E$20,2,FALSE) -> PTR | H2: 17099684 | I2: =SUM(S2-R2) -> 234 | J2: =SUM(U2-T2) -> 165 | K2: =SUM(I2*$P2) -> 6.1308 | L2: =SUM(J2*$Q2) -> 19.47 | M2: =K2+L2 -> 25.6008 | N2: T202P700442 | O2: 144.75.180.103 | P2: =IF(G2="MFP",Tables!$B$2,Tables!$B$5) -> 0.0262 | Q2: =IF(G2="MFP",Tables!$B$3,Tables!$B$6) -> 0.118 | R2: =VLOOKUP($N2,'Meter Comparison'!$C$2:$G$314,2,FALSE) -> 2529 | S2: =VLOOKUP($N2,'Meter Comparison'!$C$2:$G$314,3,FALSE) -> 2763 | T2: =VLOOKUP($N2,'Meter Comparison'!$C$2:$G$314,4,FALSE) -> 834 | U2: =VLOOKUP($N2,'Meter Comparison'!$C$2:$G$314,5,FALSE) -> 999
B3: 10_07_205_90300_5521 Total | M3: =SUBTOTAL(9,M2:M2) -> 25.6008
A4: Addmissions | B4: 10_03_054_01100_5521 | C4: =VLOOKUP(B4,Tables!$G$2:$H$90,2,FALSE) -> Admissions Office | D4: Moody Hall | E4: 104 | F4: AF SP4310N | G4: =VLOOKUP(F4,Tables!$D$2:$E$20,2,FALSE) -> PTR | H4: 17099824 | I4: =SUM(S4-R4) -> 43 | J4: =SUM(U4-T4) -> 0 | K4: =SUM(I4*$P4) -> 1.1266 | L4: =SUM(J4*$Q4) -> 0 | M4: =K4+L4 -> 1.1266 | N4: T1129010634 | O4: 144.75.184.23 | P4: =IF(G4="MFP",Tables!$B$2,Tables!$B$5) -> 0.0262 | Q4: =IF(G4="MFP",Tables!$B$3,Tables!$B$6) -> 0.118 | R4: =VLOOKUP($N4,'Meter Comparison'!$C$2:$G$314,2,FALSE) -> 505 | S4: =VLOOKUP($N4,'Meter Comparison'!$C$2:$G$314,3,FALSE) -> 548 | T4: =VLOOKUP($N4,'Meter Comparison'!$C$2:$G$314,4,FALSE) -> 0 | U4: =VLOOKUP($N4,'Meter Comparison'!$C$2:$G$314,5,FALSE) -> 0
A5: Admissions | B5: 10_03_054_01100_5521 | C5: =VLOOKUP(B5,Tables!$G$2:$H$90,2,FALSE) -> Admissions Office | D5: 307 Letcher | E5: 204 | F5: AF MPC3502 | G5: =VLOOKUP(F5,Tables!$D$2:$E$20,2,FALSE) -> MFP | H5: 17099493 | I5: =SUM(S5-R5) -> 2045 | J5: =SUM(U5-T5) -> 2677 | K5: =SUM(I5*$P5) -> 42.3315 | L5: =SUM(J5*$Q5) -> 232.899 | M5: =K5+L5 -> 275.2305 | N5: W502L600872 | O5: 144.75.215.48 | P5: =IF(G5="MFP",Tables!$B$2,Tables!$B$5) -> 0.0207 | Q5: =IF(G5="MFP",Tables!$B$3,Tables!$B$6) -> 0.087 | R5: =VLOOKUP($N5,'Meter Comparison'!$C$2:$G$314,2,FALSE) -> 41492 | S5: =VLOOKUP($N5,'Meter Comparison'!$C$2:$G$314,3,FALSE) -> 43537 | T5: =VLOOKUP($N5,'Meter Comparison'!$C$2:$G$314,4,FALSE) -> 22039 | U5: =VLOOKUP($N5,'Meter Comparison'!$C$2:$G$314,5,FALSE) -> 24716
A6: Admissions | B6: 10_03_054_01100_5521 | C6: =VLOOKUP(B6,Tables!$G$2:$H$90,2,FALSE) -> Admissions Office | D6: 309 Letcher | E6: 200 | F6: AF SPC430DN | G6: =VLOOKUP(F6,Tables!$D$2:$E$20,2,FALSE) -> PTR | H6: 17099785 | I6: =SUM(S6-R6) -> 262 | J6: =SUM(U6-T6) -> 682 | K6: =SUM(I6*$P6) -> 6.8644 | L6: =SUM(J6*$Q6) -> 80.476 | M6: =K6+L6 -> 87.3404 | N6: S9329101091 | O6: 144.75.186.31 | P6: =IF(G6="MFP",Tables!$B$2,Tables!$B$5) -> 0.0262 | Q6: =IF(G6="MFP",Tables!$B$3,Tables!$B$6) -> 0.118 | R6: =VLOOKUP($N6,'Meter Comparison'!$C$2:$G$314,2,FALSE) -> 1512 | S6: =VLOOKUP($N6,'Meter Comparison'!$C$2:$G$314,3,FALSE) -> 1774 | T6: =VLOOKUP($N6,'Meter Comparison'!$C$2:$G$314,4,FALSE) -> 3151 | U6: =VLOOKUP($N6,'Meter Comparison'!$C$2:$G$314,5,FALSE) -> 3833
A7: Admissions | B7: 10_03_054_01100_5521 | C7: =VLOOKUP(B7,Tables!$G$2:$H$90,2,FALSE) -> Admissions Office | D7: 309 Letcher | E7: 201 | F7: AF SP4310N | G7: =VLOOKUP(F7,Tables!$D$2:$E$20,2,FALSE) -> PTR | H7: 17099780 | I7: =SUM(S7-R7) -> 468 | J7: =SUM(U7-T7) -> 0 | K7: =SUM(I7*$P7) -> 12.2616 | L7: =SUM(J7*$Q7) -> 0 | M7: =K7+L7 -> 12.2616 | N7: T1128911219 | O7: 144.75.215.43 | P7: =IF(G7="MFP",Tables!$B$2,Tables!$B$5) -> 0.0262 | Q7: =IF(G7="MFP",Tables!$B$3,Tables!$B$6) -> 0.118 | R7: =VLOOKUP($N7,'Meter Comparison'!$C$2:$G$314,2,FALSE) -> 948 | S7: =VLOOKUP($N7,'Meter Comparison'!$C$2:$G$314,3,FALSE) -> 1416 | T7: =VLOOKUP($N7,'Meter Comparison'!$C$2:$G$314,4,FALSE) -> 0 | U7: =VLOOKUP($N7,'Meter Comparison'!$C$2:$G$314,5,FALSE) -> 0
A8: Admissions | B8: 10_03_054_01100_5521 | C8: =VLOOKUP(B8,Tables!$G$2:$H$90,2,FALSE) -> Admissions Office | D8: 309 Letcher | E8: 201 | F8: AF SP4310N | G8: =VLOOKUP(F8,Tables!$D$2:$E$20,2,FALSE) -> PTR | H8: 17099512 | I8: =SUM(S8-R8) -> 2 | J8: =SUM(U8-T8) -> 0 | K8: =SUM(I8*$P8) -> 0.0524 | L8: =SUM(J8*$Q8) -> 0 | M8: =K8+L8 -> 0.0524 | N8: T1129010877 | O8: 144.75.186.30 | P8: =IF(G8="MFP",Tables!$B$2,Tables!$B$5) -> 0.0262 | Q8: =IF(G8="MFP",Tables!$B$3,Tables!$B$6) -> 0.118 | R8: =VLOOKUP($N8,'Meter Comparison'!$C$2:$G$314,2,FALSE) -> 50 | S8: =VLOOKUP($N8,'Meter Comparison'!$C$2:$G$314,3,FALSE) -> 52 | T8: =VLOOKUP($N8,'Meter Comparison'!$C$2:$G$314,4,FALSE) -> 0 | U8: =VLOOKUP($N8,'Meter Comparison'!$C$2:$G$314,5,FALSE) -> 0
A9: Admissions | B9: 10_03_054_01100_5521 | C9: =VLOOKUP(B9,Tables!$G$2:$H$90,2,FALSE) -> Admissions Office | D9: 309 Letcher | E9: 302 | F9: AF SPC242DN | G9: =VLOOKUP(F9,Tables!$D$2:$E$20,2,FALSE) -> PTR | H9: 17099423 | I9: =SUM(S9-R9) -> 53 | J9: =SUM(U9-T9) -> 130 | K9: =SUM(I9*$P9) -> 1.3886 | L9: =SUM(J9*$Q9) -> 15.34 | M9: =K9+L9 -> 16.7286 | N9: T202P700463 | O9: 144.75.186.29 | P9: =IF(G9="MFP",Tables!$B$2,Tables!$B$5) -> 0.0262 | Q9: =IF(G9="MFP",Tables!$B$3,Tables!$B$6) -> 0.118 | R9: =VLOOKUP($N9,'Meter Comparison'!$C$2:$G$314,2,FALSE) -> 255 | S9: =VLOOKUP($N9,'Meter Comparison'!$C$2:$G$314,3,FALSE) -> 308 | T9: =VLOOKUP($N9,'Meter Comparison'!$C$2:$G$314,4,FALSE) -> 766 | U9: =VLOOKUP($N9,'Meter Comparison'!$C$2:$G$314,5,FALSE) -> 896
A10: Admissions | B10: 10_03_054_01100_5521 | C10: =VLOOKUP(B10,Tables!$G$2:$H$90,2,FALSE) -> Admissions Office | D10: 309 Letcher | E10: 306 | F10: AF SPC242DN | G10: =VLOOKUP(F10,Tables!$D$2:$E$20,2,FALSE) -> PTR | H10: 17099731 | I10: =SUM(S10-R10) -> 279 | J10: =SUM(U10-T10) -> 111 | K10: =SUM(I10*$P10) -> 7.3098 | L10: =SUM(J10*$Q10) -> 13.098 | M10: =K10+L10 -> 20.4078 | N10: T202P600637 | O10: 144.75.186.28 | P10: =IF(G10="MFP",Tables!$B$2,Tables!$B$5) -> 0.0262 | Q10: =IF(G10="MFP",Tables!$B$3,Tables!$B$6) -> 0.118 | R10: =VLOOKUP($N10,'Meter Comparison'!$C$2:$G$314,2,FALSE) -> 1730 | S10: =VLOOKUP($N10,'Meter Comparison'!$C$2:$G$314,3,FALSE) -> 2009 | T10: =VLOOKUP($N10,'Meter Comparison'!$C$2:$G$314,4,FALSE) -> 672 | U10: =VLOOKUP($N10,'Meter Comparison'!$C$2:$G$314,5,FALSE) -> 783
A11: Admissions | B11: 10_03_054_01100_5521 | C11: =VLOOKUP(B11,Tables!$G$2:$H$90,2,FALSE) -> Admissions Office | D11: 309 Letcher | E11: 306 | F11: AF SPC242DN | G11: =VLOOKUP(F11,Tables!$D$2:$E$20,2,FALSE) -> PTR | H11: 17099511 | I11: =SUM(S11-R11) -> 31 | J11: =SUM(U11-T11) -> 58 | K11: =SUM(I11*$P11) -> 0.8122 | L11: =SUM(J11*$Q11) -> 6.844 | M11: =K11+L11 -> 7.6562 | N11: T202P700465 | O11: 144.75.186.25 | P11: =IF(G11="MFP",Tables!$B$2,Tables!$B$5) -> 0.0262 | Q11: =IF(G11="MFP",Tables!$B$3,Tables!$B$6) -> 0.118 | R11: =VLOOKUP($N11,'Meter Comparison'!$C$2:$G$314,2,FALSE) -> 445 | S11: =VLOOKUP($N11,'Meter Comparison'!$C$2:$G$314,3,FALSE) -> 476 | T11: =VLOOKUP($N11,'Meter Comparison'!$C$2:$G$314,4,FALSE) -> 557 | U11: =VLOOKUP($N11,'Meter Comparison'!$C$2:$G$314,5,FALSE) -> 615
B12: 10_03_054_01100_5521 Total | M12: =SUBTOTAL(9,M4:M11) -> 420.8041
A13: ADV | B13: 10_03_064_50550_5521 | C13: =VLOOKUP(B13,Tables!$G$2:$H$90,2,FALSE) -> Printer Services | D13: Carroll Hall | E13: 210C | F13: AF SP4310N | G13: =VLOOKUP(F13,Tables!$D$2:$E$20,2,FALSE) -> PTR | H13: 17099562 | I13: =SUM(S13-R13) -> 148 | J13: =SUM(U13-T13) -> 0 | K13: =SUM(I13*$P13) -> 3.8776 | L13: =SUM(J13*$Q13) -> 0 | M13: =K13+L13 -> 3.8776 | N13: T1128911292 | O13: 144.75.195.20 | P13: =IF(G13="MFP",Tables!$B$2,Tables!$B$5) -> 0.0262 | Q13: =IF(G13="MFP",Tables!$B$3,Tables!$B$6) -> 0.118 | R13: =VLOOKUP($N13,'Meter Comparison'!$C$2:$G$314,2,FALSE) -> 3771 | S13: =VLOOKUP($N13,'Meter Comparison'!$C$2:$G$314,3,FALSE) -> 3919 | T13: =VLOOKUP($N13,'Meter Comparison'!$C$2:$G$314,4,FALSE) -> 0 | U13: =VLOOKUP($N13,'Meter Comparison'!$C$2:$G$314,5,FALSE) -> 0
A14: ADV | B14: 10_03_064_50550_5521 | C14: =VLOOKUP(B14,Tables!$G$2:$H$90,2,FALSE) -> Printer Services | D14: Carroll Hall | E14: 210C | F14: AF SPC242DN | G14: =VLOOKUP(F14,Tables!$D$2:$E$20,2,FALSE) -> PTR | H14: 17099741 | I14: =SUM(S14-R14) -> 89 | J14: =SUM(U14-T14) -> 119 | K14: =SUM(I14*$P14) -> 2.3318 | L14: =SUM(J14*$Q14) -> 14.042 | M14: =K14+L14 -> 16.3738 | N14: T202P801019 | O14: 144.75.195.97 | P14: =IF(G14="MFP",Tables!$B$2,Tables!$B$5) -> 0.0262 | Q14: =IF(G14="MFP",Tables!$B$3,Tables!$B$6) -> 0.118 | R14: =VLOOKUP($N14,'Meter Comparison'!$C$2:$G$314,2,FALSE) -> 47 | S14: =VLOOKUP($N14,'Meter Comparison'!$C$2:$G$314,3,FALSE) -> 136 | T14: =VLOOKUP($N14,'Meter Comparison'!$C$2:$G$314,4,FALSE) -> 71 | U14: =VLOOKUP($N14,'Meter Comparison'!$C$2:$G$314,5,FALSE) -> 190
B15: 10_03_064_50550_5521 Total | M15: =SUBTOTAL(9,M13:M14) -> 20.2514
A16: Air Force Rotc | B16: 10_03_011_02100_5521 | C16: =VLOOKUP(B16,Tables!$G$2:$H$90,2,FALSE) -> ROTC-Air Force | D16: Kilbourne Hall | E16: 2012 | F16: AF SP4310N | G16: =VLOOKUP(F16,Tables!$D$2:$E$20,2,FALSE) -> PTR | H16: 17099443 | I16: =SUM(S16-R16) -> 0 | J16: =SUM(U16-T16) -> 0 | K16: =SUM(I16*$P16) -> 0 | L16: =SUM(J16*$Q16) -> 0 | M16: =K16+L16 -> 0 | N16: T1129010871 | O16: 144.75.187.135 | P16: =IF(G16="MFP",Tables!$B$2,Tables!$B$5) -> 0.0262 | Q16: =IF(G16="MFP",Tables!$B$3,Tables!$B$6) -> 0.118 | R16: =VLOOKUP($N16,'Meter Comparison'!$C$2:$G$314,2,FALSE) -> 321 | S16: =VLOOKUP($N16,'Meter Comparison'!$C$2:$G$314,3,FALSE) -> 321 | T16: =VLOOKUP($N16,'Meter Comparison'!$C$2:$G$314,4,FALSE) -> 0 | U16: =VLOOKUP($N16,'Meter Comparison'!$C$2:$G$314,5,FALSE) -> 0
A17: Air Force Rotc | B17: 10_03_011_02100_5521 | C17: =VLOOKUP(B17,Tables!$G$2:$H$90,2,FALSE) -> ROTC-Air Force | D17: Kilbourne Hall | E17: 2018 | F17: AF SP4310N | G17: =VLOOKUP(F17,Tables!$D$2:$E$20,2,FALSE) -> PTR | H17: 17099438 | I17: =SUM(S17-R17) -> 6 | J17: =SUM(U17-T17) -> 0 | K17: =SUM(I17*$P17) -> 0.1572 | L17: =SUM(J17*$Q17) -> 0 | M17: =K17+L17 -> 0.1572 | N17: T1129010832 | O17: 144.75.187.138 | P17: =IF(G17="MFP",Tables!$B$2,Tables!$B$5) -> 0.0262 | Q17: =IF(G17="MFP",Tables!$B$3,Tables!$B$6) -> 0.118 | R17: =VLOOKUP($N17,'Meter Comparison'!$C$2:$G$314,2,FALSE) -> 844 | S17: =VLOOKUP($N17,'Meter Comparison'!$C$2:$G$314,3,FALSE) -> 850 | T17: =VLOOKUP($N17,'Meter Comparison'!$C$2:$G$314,4,FALSE) -> 0 | U17: =VLOOKUP($N17,'Meter Comparison'!$C$2:$G$314,5,FALSE) -> 0
B18: 10_03_011_02100_5521 Total | M18: =SUBTOTAL(9,M16:M17) -> 0.1572
A19: Army Rotc | B19: 10_03_011_04100_5521 | C19: =VLOOKUP(B19,Tables!$G$2:$H$90,2,FALSE) -> ROTC-Army | D19: Kilbourne Hall | E19: 1024 | F19: AF SP4310N | G19: =VLOOKUP(F19,Tables!$D$2:$E$20,2,FALSE) -> PTR | H19: 17099705 | I19: =SUM(S19-R19) -> 0 | J19: =SUM(U19-T19) -> 0 | K19: =SUM(I19*$P19) -> 0 | L19: =SUM(J19*$Q19) -> 0 | M19: =K19+L19 -> 0 | N19: T1128911220 | O19: 144.75.187.127 | P19: =IF(G19="MFP",Tables!$B$2,Tables!$B$5) -> 0.0262 | Q19: =IF(G19="MFP",Tables!$B$3,Tables!$B$6) -> 0.118 | R19: =VLOOKUP($N19,'Meter Comparison'!$C$2:$G$314,2,FALSE) -> 119 | S19: =VLOOKUP($N19,'Meter Comparison'!$C$2:$G$314,3,FALSE) -> 119 | T19: =VLOOKUP($N19,'Meter Comparison'!$C$2:$G$314,4,FALSE) -> 0 | U19: =VLOOKUP($N19,'Meter Comparison'!$C$2:$G$314,5,FALSE) -> 0
A20: Army Rotc | B20: 10_03_011_04100_5521 | C20: =VLOOKUP(B20,Tables!$G$2:$H$90,2,FALSE) -> ROTC-Army | D20: Kilbourne Hall | E20: 1027 | F20: AF SP4310N | G20: =VLOOKUP(F20,Tables!$D$2:$E$20,2,FALSE) -> PTR | H20: 17099737 | I20: =SUM(S20-R20) -> 165 | J20: =SUM(U20-T20) -> 0 | K20: =SUM(I20*$P20) -> 4.323 | L20: =SUM(J20*$Q20) -> 0 | M20: =K20+L20 -> 4.323 | N20: T1129011362 | O20: 144.75.187.151 | P20: =IF(G20="MFP",Tables!$B$2,Tables!$B$5) -> 0.0262 | Q20: =IF(G20="MFP",Tables!$B$3,Tables!$B$6) -> 0.118 | R20: =VLOOKUP($N20,'Meter Comparison'!$C$2:$G$314,2,FALSE) -> 132 | S20: =VLOOKUP($N20,'Meter Comparison'!$C$2:$G$314,3,FALSE) -> 297 | T20: =VLOOKUP($N20,'Meter Comparison'!$C$2:$G$314,4,FALSE) -> 0 | U20: =VLOOKUP($N20,'Meter Comparison'!$C$2:$G$314,5,FALSE) -> 0
A21: Army Rotc | B21: 10_03_011_04100_5521 | C21: =VLOOKUP(B21,Tables!$G$2:$H$90,2,FALSE) -> ROTC-Army | D21: Kilbourne Hall | E21: 1027 | F21: AF SP4310N | G21: =VLOOKUP(F21,Tables!$D$2:$E$20,2,FALSE) -> PTR | H21: 17099738 | I21: =SUM(S21-R21) -> 49 | J21: =SUM(U21-T21) -> 0 | K21: =SUM(I21*$P21) -> 1.2838 | L21: =SUM(J21*$Q21) -> 0 | M21: =K21+L21 -> 1.2838 | N21: T1129012368 | O21: 144.75.187.148 | P21: =IF(G21="MFP",Tables!$B$2,Tables!$B$5) -> 0.0262 | Q21: =IF(G21="MFP",Tables!$B$3,Tables!$B$6) -> 0.118 | R21: =VLOOKUP($N21,'Meter Comparison'!$C$2:$G$314,2,FALSE) -> 297 | S21: =VLOOKUP($N21,'Meter Comparison'!$C$2:$G$314,3,FALSE) -> 346 | T21: =VLOOKUP($N21,'Meter Comparison'!$C$2:$G$314,4,FALSE) -> 0 | U21: =VLOOKUP($N21,'Meter Comparison'!$C$2:$G$314,5,FALSE) -> 0
A22: Army Rotc | B22: 10_03_011_04100_5521 | C22: =VLOOKUP(B22,Tables!$G$2:$H$90,2,FALSE) -> ROTC-Army | D22: Kilbourne Hall | E22: 1030 | F22: Af SP4310N | G22: =VLOOKUP(F22,Tables!$D$2:$E$20,2,FALSE) -> PTR | H22: 17099719 | I22: =SUM(S22-R22) -> 189 | J22: =SUM(U22-T22) -> 0 | K22: =SUM(I22*$P22) -> 4.9518 | L22: =SUM(J22*$Q22) -> 0 | M22: =K22+L22 -> 4.9518 | N22: T1129010918 | O22: 144.75.187.124 | P22: =IF(G22="MFP",Tables!$B$2,Tables!$B$5) -> 0.0262 | Q22: =IF(G22="MFP",Tables!$B$3,Tables!$B$6) -> 0.118 | R22: =VLOOKUP($N22,'Meter Comparison'!$C$2:$G$314,2,FALSE) -> 2399 | S22: =VLOOKUP($N22,'Meter Comparison'!$C$2:$G$314,3,FALSE) -> 2588 | T22: =VLOOKUP($N22,'Meter Comparison'!$C$2:$G$314,4,FALSE) -> 0 | U22: =VLOOKUP($N22,'Meter Comparison'!$C$2:$G$314,5,FALSE) -> 0
A23: Army Rotc | B23: 10_03_011_04100_5521 | C23: =VLOOKUP(B23,Tables!$G$2:$H$90,2,FALSE) -> ROTC-Army | D23: Kilbourne Hall | E23: 2020 | F23: AF SP4310N | G23: =VLOOKUP(F23,Tables!$D$2:$E$20,2,FALSE) -> PTR | H23: 17099714 | I23: =SUM(S23-R23) -> 113 | J23: =SUM(U23-T23) -> 0 | K23: =SUM(I23*$P23) -> 2.9606 | L23: =SUM(J23*$Q23) -> 0 | M23: =K23+L23 -> 2.9606 | N23: T1129010890 | O23: 144.75.187.101 | P23: =IF(G23="MFP",Tables!$B$2,Tables!$B$5) -> 0.0262 | Q23: =IF(G23="MFP",Tables!$B$3,Tables!$B$6) -> 0.118 | R23: =VLOOKUP($N23,'Meter Comparison'!$C$2:$G$314,2,FALSE) -> 794 | S23: =VLOOKUP($N23,'Meter Comparison'!$C$2:$G$314,3,FALSE) -> 907 | T23: =VLOOKUP($N23,'Meter Comparison'!$C$2:$G$314,4,FALSE) -> 0 | U23: =VLOOKUP($N23,'Meter Comparison'!$C$2:$G$314,5,FALSE) -> 0
A24: Army Rotc | B24: 10_03_011_04100_5521 | C24: =VLOOKUP(B24,Tables!$G$2:$H$90,2,FALSE) -> ROTC-Army | D24: Kilbourne Hall | E24: 2022 | F24: AF MPC3502 | G24: =VLOOKUP(F24,Tables!$D$2:$E$20,2,FALSE) -> MFP | H24: 17099434 | I24: =SUM(S24-R24) -> 10563 | J24: =SUM(U24-T24) -> 1101 | K24: =SUM(I24*$P24) -> 218.6541 | L24: =SUM(J24*$Q24) -> 95.787 | M24: =K24+L24 -> 314.4411 | N24: W502L600854 | O24: 144.75.187.122 | P24: =IF(G24="MFP",Tables!$B$2,Tables!$B$5) -> 0.0207 | Q24: =IF(G24="MFP",Tables!$B$3,Tables!$B$6) -> 0.087 | R24: =VLOOKUP($N24,'Meter Comparison'!$C$2:$G$314,2,FALSE) -> 85021 | S24: =VLOOKUP($N24,'Meter Comparison'!$C$2:$G$314,3,FALSE) -> 95584 | T24: =VLOOKUP($N24,'Meter Comparison'!$C$2:$G$314,4,FALSE) -> 8124 | U24: =VLOOKUP($N24,'Meter Comparison'!$C$2:$G$314,5,FALSE) -> 9225
A25: Army Rotc | B25: 10_03_011_04100_5521 | C25: =VLOOKUP(B25,Tables!$G$2:$H$90,2,FALSE) -> ROTC-Army | D25: Kilbourne Hall | E25: 2023 | F25: AF SP4310N | G25: =VLOOKUP(F25,Tables!$D$2:$E$20,2,FALSE) -> PTR | H25: 17099435 | I25: =SUM(S25-R25) -> 86 | J25: =SUM(U25-T25) -> 0 | K25: =SUM(I25*$P25) -> 2.2532 | L25: =SUM(J25*$Q25) -> 0 | M25: =K25+L25 -> 2.2532 | N25: T1129010902 | O25: 144.75.187.16 | P25: =IF(G25="MFP",Tables!$B$2,Tables!$B$5) -> 0.0262 | Q25: =IF(G25="MFP",Tables!$B$3,Tables!$B$6) -> 0.118 | R25: =VLOOKUP($N25,'Meter Comparison'!$C$2:$G$314,2,FALSE) -> 616 | S25: =VLOOKUP($N25,'Meter Comparison'!$C$2:$G$314,3,FALSE) -> 702 | T25: =VLOOKUP($N25,'Meter Comparison'!$C$2:$G$314,4,FALSE) -> 0 | U25: =VLOOKUP($N25,'Meter Comparison'!$C$2:$G$314,5,FALSE) -> 0
A26: Army Rotc | B26: 10_03_011_04100_5521 | C26: =VLOOKUP(B26,Tables!$G$2:$H$90,2,FALSE) -> ROTC-Army | D26: Kilbourne Hall | E26: 2029 | F26: AF SP4310N | G26: =VLOOKUP(F26,Tables!$D$2:$E$20,2,FALSE) -> PTR | H26: 17099446 | I26: =SUM(S26-R26) -> 29 | J26: =SUM(U26-T26) -> 0 | K26: =SUM(I26*$P26) -> 0.7598 | L26: =SUM(J26*$Q26) -> 0 | M26: =K26+L26 -> 0.7598 | N26: T1129010869 | O26: 144.75.187.137 | P26: =IF(G26="MFP",Tables!$B$2,Tables!$B$5) -> 0.0262 | Q26: =IF(G26="MFP",Tables!$B$3,Tables!$B$6) -> 0.118 | R26: =VLOOKUP($N26,'Meter Comparison'!$C$2:$G$314,2,FALSE) -> 308 | S26: =VLOOKUP($N26,'Meter Comparison'!$C$2:$G$314,3,FALSE) -> 337 | T26: =VLOOKUP($N26,'Meter Comparison'!$C$2:$G$314,4,FALSE) -> 0 | U26: =VLOOKUP($N26,'Meter Comparison'!$C$2:$G$314,5,FALSE) -> 0
A27: Army Rotc | B27: 10_03_011_04100_5521 | C27: =VLOOKUP(B27,Tables!$G$2:$H$90,2,FALSE) -> ROTC-Army | D27: Kilbourne Hall | E27: 2051 | F27: AF SP4310N | G27: =VLOOKUP(F27,Tables!$D$2:$E$20,2,FALSE) -> PTR | H27: 17099715 | I27: =SUM(S27-R27) -> 7 | J27: =SUM(U27-T27) -> 0 | K27: =SUM(I27*$P27) -> 0.1834 | L27: =SUM(J27*$Q27) -> 0 | M27: =K27+L27 -> 0.1834 | N27: T1129010910 | O27: 144.75.187.111 | P27: =IF(G27="MFP",Tables!$B$2,Tables!$B$5) -> 0.0262 | Q27: =IF(G27="MFP",Tables!$B$3,Tables!$B$6) -> 0.118 | R27: =VLOOKUP($N27,'Meter Comparison'!$C$2:$G$314,2,FALSE) -> 504 | S27: =VLOOKUP($N27,'Meter Comparison'!$C$2:$G$314,3,FALSE) -> 511 | T27: =VLOOKUP($N27,'Meter Comparison'!$C$2:$G$314,4,FALSE) -> 0 | U27: =VLOOKUP($N27,'Meter Comparison'!$C$2:$G$314,5,FALSE) -> 0
A28: Army Rotc | B28: 10_03_011_04100_5521 | C28: =VLOOKUP(B28,Tables!$G$2:$H$90,2,FALSE) -> ROTC-Army | D28: Kilbourne Hall | E28: 2052 | F28: AF SP4310N | G28: =VLOOKUP(F28,Tables!$D$2:$E$20,2,FALSE) -> PTR | H28: 17099852 | I28: =SUM(S28-R28) -> 2 | J28: =SUM(U28-T28) -> 0 | K28: =SUM(I28*$P28) -> 0.0524 | L28: =SUM(J28*$Q28) -> 0 | M28: =K28+L28 -> 0.0524 | N28: T1129010839 | O28: 144.75.187.102 | P28: =IF(G28="MFP",Tables!$B$2,Tables!$B$5) -> 0.0262 | Q28: =IF(G28="MFP",Tables!$B$3,Tables!$B$6) -> 0.118 | R28: =VLOOKUP($N28,'Meter Comparison'!$C$2:$G$314,2,FALSE) -> 5 | S28: =VLOOKUP($N28,'Meter Comparison'!$C$2:$G$314,3,FALSE) -> 7 | T28: =VLOOKUP($N28,'Meter Comparison'!$C$2:$G$314,4,FALSE) -> 0 | U28: =VLOOKUP($N28,'Meter Comparison'!$C$2:$G$314,5,FALSE) -> 0
A29: Army Rotc | B29: 10_03_011_04100_5521 | C29: =VLOOKUP(B29,Tables!$G$2:$H$90,2,FALSE) -> ROTC-Army | D29: Kilbourne Hall | E29: 2053 | F29: AF SP4310N | G29: =VLOOKUP(F29,Tables!$D$2:$E$20,2,FALSE) -> PTR | H29: 17099437 | I29: =SUM(S29-R29) -> 154 | J29: =SUM(U29-T29) -> 0 | K29: =SUM(I29*$P29) -> 4.0348 | L29: =SUM(J29*$Q29) -> 0 | M29: =K29+L29 -> 4.0348 | N29: T1129010748 | O29: 144.75.187.112 | P29: =IF(G29="MFP",Tables!$B$2,Tables!$B$5) -> 0.0262 | Q29: =IF(G29="MFP",Tables!$B$3,Tables!$B$6) -> 0.118 | R29: =VLOOKUP($N29,'Meter Comparison'!$C$2:$G$314,2,FALSE) -> 1512 | S29: =VLOOKUP($N29,'Meter Comparison'!$C$2:$G$314,3,FALSE) -> 1666 | T29: =VLOOKUP($N29,'Meter Comparison'!$C$2:$G$314,4,FALSE) -> 0 | U29: =VLOOKUP($N29,'Meter Comparison'!$C$2:$G$314,5,FALSE) -> 0
A30: Army Rotc | B30: 10_03_011_04100_5521 | C30: =VLOOKUP(B30,Tables!$G$2:$H$90,2,FALSE) -> ROTC-Army | D30: Kilbourne Hall | E30: 2056 | F30: AF SP4310N | G30: =VLOOKUP(F30,Tables!$D$2:$E$20,2,FALSE) -> PTR | H30: 17099436 | I30: =SUM(S30-R30) -> 385 | J30: =SUM(U30-T30) -> 0 | K30: =SUM(I30*$P30) -> 10.087 | L30: =SUM(J30*$Q30) -> 0 | M30: =K30+L30 -> 10.087 | N30: T1129010837 | O30: 144.75.187.131 | P30: =IF(G30="MFP",Tables!$B$2,Tables!$B$5) -> 0.0262 | Q30: =IF(G30="MFP",Tables!$B$3,Tables!$B$6) -> 0.118 | R30: =VLOOKUP($N30,'Meter Comparison'!$C$2:$G$314,2,FALSE) -> 2029 | S30: =VLOOKUP($N30,'Meter Comparison'!$C$2:$G$314,3,FALSE) -> 2414 | T30: =VLOOKUP($N30,'Meter Comparison'!$C$2:$G$314,4,FALSE) -> 0 | U30: =VLOOKUP($N30,'Meter Comparison'!$C$2:$G$314,5,FALSE) -> 0
... A40: Army Rotc | B40: 10_03_011_04100_5521 | C40: =VLOOKUP(B40,Tables!$G$2:$H$90,2,FALSE) -> ROTC-Army | D40: Kilbourne Hall | E40: 2070 | F40: AF SP4310N | G40: =VLOOKUP(F40,Tables!$D$2:$E$20,2,FALSE) -> PTR | H40: 17099428 | I40: =SUM(S40-R40) -> 94 | J40: =SUM(U40-T40) -> 0 | K40: =SUM(I40*$P40) -> 2.4628 | L40: =SUM(J40*$Q40) -> 0 | M40: =K40+L40 -> 2.4628 | N40: T1129010900 | O40: 144.75.187.132 | P40: =IF(G40="MFP",Tables!$B$2,Tables!$B$5) -> 0.0262 | Q40: =IF(G40="MFP",Tables!$B$3,Tables!$B$6) -> 0.118 | R40: =VLOOKUP($N40,'Meter Comparison'!$C$2:$G$314,2,FALSE) -> 1306 | S40: =VLOOKUP($N40,'Meter Comparison'!$C$2:$G$314,3,FALSE) -> 1400 | T40: =VLOOKUP($N40,'Meter Comparison'!$C$2:$G$314,4,FALSE) -> 0 | U40: =VLOOKUP($N40,'Meter Comparison'!$C$2:$G$314,5,FALSE) -> 0
B41: 10_03_011_04100_5521 Total | M41: =SUBTOTAL(9,M19:M40) -> 404.0189
A42: Athletic Advising | B42: 40_00_052_06550_5521 | C42: =VLOOKUP(B42,Tables!$G$2:$H$90,2,FALSE) -> AOF - Academic Advising | D42: Carroll Hall | E42: 210 | F42: AF MPC2051 | G42: =VLOOKUP(F42,Tables!$D$2:$E$20,2,FALSE) -> MFP | H42: 17099459 | I42: =SUM(S42-R42) -> 8227 | J42: =SUM(U42-T42) -> 433 | K42: =SUM(I42*$P42) -> 170.2989 | L42: =SUM(J42*$Q42) -> 37.671 | M42: =K42+L42 -> 207.9699 | N42: V9725401429 | O42: 144.75.195.41 | P42: =IF(G42="MFP",Tables!$B$2,Tables!$B$5) -> 0.0207 | Q42: =IF(G42="MFP",Tables!$B$3,Tables!$B$6) -> 0.087 | R42: =VLOOKUP($N42,'Meter Comparison'!$C$2:$G$314,2,FALSE) -> 41732 | S42: =VLOOKUP($N42,'Meter Comparison'!$C$2:$G$314,3,FALSE) -> 49959 | T42: =VLOOKUP($N42,'Meter Comparison'!$C$2:$G$314,4,FALSE) -> 3496 | U42: =VLOOKUP($N42,'Meter Comparison'!$C$2:$G$314,5,FALSE) -> 3929
B43: 40_00_052_06550_5521 Total | M43: =SUBTOTAL(9,M42:M42) -> 207.9699
A44: Athletic Communications | B44: 30_00_310_06104_5521 | C44: =VLOOKUP(B44,Tables!$G$2:$H$90,2,FALSE) -> Sports Information | D44: Smith Hall | E44: 116 | F44: AF MP301SP | G44: =VLOOKUP(F44,Tables!$D$2:$E$20,2,FALSE) -> MFP | H44: 17099531 | I44: =SUM(S44-R44) -> 1251 | J44: =SUM(U44-T44) -> 0 | K44: =SUM(I44*$P44) -> 25.8957 | L44: =SUM(J44*$Q44) -> 0 | M44: =K44+L44 -> 25.8957 | N44: W912P602286 | O44: 144.75.179.49 | P44: =IF(G44="MFP",Tables!$B$2,Tables!$B$5) -> 0.0207 | Q44: =IF(G44="MFP",Tables!$B$3,Tables!$B$6) -> 0.087 | R44: =VLOOKUP($N44,'Meter Comparison'!$C$2:$G$314,2,FALSE) -> 6785 | S44: =VLOOKUP($N44,'Meter Comparison'!$C$2:$G$314,3,FALSE) -> 8036 | T44: =VLOOKUP($N44,'Meter Comparison'!$C$2:$G$314,4,FALSE) -> 0 | U44: =VLOOKUP($N44,'Meter Comparison'!$C$2:$G$314,5,FALSE) -> 0
B45: 30_00_310_06104_5521 Total | M45: =SUBTOTAL(9,M44:M44) -> 25.8957
A46: Athletics | B46: 30_00_310_06020_5521 | C46: =VLOOKUP(B46,Tables!$G$2:$H$90,2,FALSE) -> Track & Cross Country | D46: Cameron Hall | E46: 231 | F46: AF SP4310N | G46: =VLOOKUP(F46,Tables!$D$2:$E$20,2,FALSE) -> PTR | H46: 17099560 | I46: =SUM(S46-R46) -> 520 | J46: =SUM(U46-T46) -> 0 | K46: =SUM(I46*$P46) -> 13.624 | L46: =SUM(J46*$Q46) -> 0 | M46: =K46+L46 -> 13.624 | N46: T1129010426 | O46: 144.75.183.68 | P46: =IF(G46="MFP",Tables!$B$2,Tables!$B$5) -> 0.0262 | Q46: =IF(G46="MFP",Tables!$B$3,Tables!$B$6) -> 0.118 | R46: =VLOOKUP($N46,'Meter Comparison'!$C$2:$G$314,2,FALSE) -> 3600 | S46: =VLOOKUP($N46,'Meter Comparison'!$C$2:$G$314,3,FALSE) -> 4120 | T46: =VLOOKUP($N46,'Meter Comparison'!$C$2:$G$314,4,FALSE) -> 0 | U46: =VLOOKUP($N46,'Meter Comparison'!$C$2:$G$314,5,FALSE) -> 0
B47: 30_00_310_06020_5521 Total | M47: =SUBTOTAL(9,M46:M46) -> 13.624
A48: Athletics | B48: 30_00_310_06090_5521 | C48: =VLOOKUP(B48,Tables!$G$2:$H$90,2,FALSE) -> Soccer | D48: Cameron Hall | E48: 245 | F48: AF SP4310N | G48: =VLOOKUP(F48,Tables!$D$2:$E$20,2,FALSE) -> PTR | H48: 17099557 | I48: =SUM(S48-R48) -> 93 | J48: =SUM(U48-T48) -> 0 | K48: =SUM(I48*$P48) -> 2.4366 | L48: =SUM(J48*$Q48) -> 0 | M48: =K48+L48 -> 2.4366 | N48: T1129010429 | O48: 144.75.183.65 | P48: =IF(G48="MFP",Tables!$B$2,Tables!$B$5) -> 0.0262 | Q48: =IF(G48="MFP",Tables!$B$3,Tables!$B$6) -> 0.118 | R48: =VLOOKUP($N48,'Meter Comparison'!$C$2:$G$314,2,FALSE) -> 948 | S48: =VLOOKUP($N48,'Meter Comparison'!$C$2:$G$314,3,FALSE) -> 1041 | T48: =VLOOKUP($N48,'Meter Comparison'!$C$2:$G$314,4,FALSE) -> 0 | U48: =VLOOKUP($N48,'Meter Comparison'!$C$2:$G$314,5,FALSE) -> 0
B49: 30_00_310_06090_5521 Total | M49: =SUBTOTAL(9,M48:M48) -> 2.4366
...

Sheet Sheet2
A1: Department / Read date 3/31/2013 | B1: General Ledger | C1: GL Description | D1: Building | E1: Room | F1: Model | G1: Device Type | H1: Ricoh Tag | I1: Total BW Click Count | J1: Total Color Click Count | K1: BW Click Charge | L1: Color Click Charge | M1: Device Total Click Charge | N1: Serial Number | O1: IP Address | P1: CPC BW | Q1: CPC Color | R1: Prev BW Click Count | S1: Current BW Click Count | T1: Prev Color Click Count | U1: Current Color Click Count
A2: Academic Advising | B2: 10_07_205_90300_5521 | C2: Academic Advising | D2: Shell Hall | E2: 301 | F2: AF SPC242DN | G2: PTR | H2: 17099684 | I2: 341 | J2: 165 | K2: 8.9342 | L2: 19.47 | M2: 28.4042 | N2: T202P700442 | O2: 144.75.180.103 | P2: 0.0262 | Q2: 0.118 | R2: 2188 | S2: 2529 | T2: 669 | U2: 834
A3: Athletics | B3: 30_00_310_06110_5521 | C3: Administrative | D3: Cameron Hall | E3: 204 | F3: AF MP301SP | G3: MFP | H3: 17099507 | I3: 1486 | J3: 0 | K3: 30.7602 | L3: 0 | M3: 30.7602 | N3: W912P602280 | O3: 144.75.183.73 | P3: 0.0207 | Q3: 0.087 | R3: 12247 | S3: 13733 | T3: 0 | U3: 0
A4: Athletics | B4: 30_00_310_06110_5521 | C4: Administrative | D4: Cameron Hall | E4: 235 | F4: AF MPC6501 | G4: MFP | H4: 17099490 | I4: 9308 | J4: 3008 | K4: 192.6756 | L4: 261.696 | M4: 454.3716 | N4: V7620400078 | O4: 144.75.183.56 | P4: 0.0207 | Q4: 0.087 | R4: 35267 | S4: 44575 | T4: 13165 | U4: 16173
A5: Athletics | B5: 30_00_310_06110_5521 | C5: Administrative | D5: Cameron Hall | E5: 241 | F5: AF SP4310N | G5: PTR | H5: 17099552 | I5: 644 | J5: 0 | K5: 16.8728 | L5: 0 | M5: 16.8728 | N5: T1129010427 | O5: 144.75.183.9 | P5: 0.0262 | Q5: 0.118 | R5: 3916 | S5: 4560 | T5: 0 | U5: 0
A6: Athletics | B6: 30_00_310_06110_5521 | C6: Administrative | D6: Cameron Hall | E6: 242 | F6: AF SP4310N | G6: PTR | H6: 17099553 | I6: 222 | J6: 0 | K6: 5.8164 | L6: 0 | M6: 5.8164 | N6: T1129010420 | O6: 144.75.183.64 | P6: 0.0262 | Q6: 0.118 | R6: 1110 | S6: 1332 | T6: 0 | U6: 0
A7: Athletics | B7: 30_00_310_06110_5521 | C7: Administrative | D7: Cameron Hall | E7: 302 | F7: AF MPC2051 | G7: MFP | H7: 17099722 | I7: 810 | J7: 1418 | K7: 16.767 | L7: 123.366 | M7: 140.133 | N7: V9725401418 | O7: 144.75.183.52 | P7: 0.0207 | Q7: 0.087 | R7: 6179 | S7: 6989 | T7: 13950 | U7: 15368
A8: Athletics | B8: 30_00_310_06110_5521 | C8: Administrative | D8: Cameron Hall | E8: 312 | F8: AF SP4310N | G8: PTR | H8: 17099555 | I8: 287 | J8: 0 | K8: 7.5194 | L8: 0 | M8: 7.5194 | N8: T1129010428 | O8: 144.75.183.67 | P8: 0.0262 | Q8: 0.118 | R8: 1574 | S8: 1861 | T8: 0 | U8: 0
A9: Athletics | B9: 30_00_310_06110_5521 | C9: Administrative | D9: Cameron Hall | E9: 314 | F9: AF SP4310N | G9: PTR | H9: 17099558 | I9: 175 | J9: 0 | K9: 4.585 | L9: 0 | M9: 4.585 | N9: T1129010421 | O9: 144.75.183.62 | P9: 0.0262 | Q9: 0.118 | R9: 1925 | S9: 2100 | T9: 0 | U9: 0
A10: Athletics | B10: 30_00_310_06110_5521 | C10: Administrative | D10: Cameron Hall | E10: 317 | F10: AF SP4310N | G10: PTR | H10: 17099554 | I10: 62 | J10: 0 | K10: 1.6244 | L10: 0 | M10: 1.6244 | N10: T1129010385 | O10: 144.75.183.63 | P10: 0.0262 | Q10: 0.118 | R10: 632 | S10: 694 | T10: 0 | U10: 0
A11: Commandant's Office | B11: 30_00_310_06110_5521 | C11: Administrative | D11: Kilbourne Hall | E11: Rifle Range | F11: AF SP4310N | G11: PTR | H11: 17099797 | I11: 0 | J11: 0 | K11: 0 | L11: 0 | M11: 0 | N11: T1129010627 | O11: 144.75.187.120 | P11: 0.0262 | Q11: 0.118 | R11: 204 | S11: 204 | T11: 0 | U11: 0
A12: Commandant's Office | B12: 30_00_310_06110_5521 | C12: Administrative | D12: Old Barracks | E12: 3C-14 | F12: AF SP4310N | G12: PTR | H12: 17099762 | I12: 189 | J12: 0 | K12: 4.9518 | L12: 0 | M12: 4.9518 | N12: T1129010629 | O12: 144.75.155.56 | P12: 0.0262 | Q12: 0.118 | R12: 545 | S12: 734 | T12: 0 | U12: 0
A13: Sport Medicine | B13: 30_00_310_06110_5521 | C13: Administrative | D13: Cameron Hall | E13: 215 | F13: AF SP4310N | G13: PTR | H13: 17099566 | I13: 180 | J13: 0 | K13: 4.716 | L13: 0 | M13: 4.716 | N13: T1129010423 | O13: 144.75.183.71 | P13: 0.0262 | Q13: 0.118 | R13: 1047 | S13: 1227 | T13: 0 | U13: 0
A14: Addmissions | B14: 10_03_054_01100_5521 | C14: Admissions Office | D14: Moody Hall | E14: 104 | F14: AF SP4310N | G14: PTR | H14: 17099824 | I14: 101 | J14: 0 | K14: 2.6462 | L14: 0 | M14: 2.6462 | N14: T1129010634 | O14: 144.75.184.23 | P14: 0.0262 | Q14: 0.118 | R14: 404 | S14: 505 | T14: 0 | U14: 0
A15: Admissions | B15: 10_03_054_01100_5521 | C15: Admissions Office | D15: 307 Letcher | E15: 204 | F15: AF MPC3502 | G15: MFP | H15: 17099493 | I15: 6744 | J15: 5255 | K15: 139.6008 | L15: 457.185 | M15: 596.7858 | N15: W502L600872 | O15: 144.75.215.48 | P15: 0.0207 | Q15: 0.087 | R15: 34748 | S15: 41492 | T15: 16784 | U15: 22039
A16: Admissions | B16: 10_03_054_01100_5521 | C16: Admissions Office | D16: 309 Letcher | E16: 200 | F16: AF SPC430DN | G16: PTR | H16: 17099785 | I16: 519 | J16: 1151 | K16: 13.5978 | L16: 135.818 | M16: 149.4158 | N16: S9329101091 | O16: 144.75.186.31 | P16: 0.0262 | Q16: 0.118 | R16: 993 | S16: 1512 | T16: 2000 | U16: 3151
A17: Admissions | B17: 10_03_054_01100_5521 | C17: Admissions Office | D17: 309 Letcher | E17: 201 | F17: AF SP4310N | G17: PTR | H17: 17099780 | I17: 269 | J17: 0 | K17: 7.0478 | L17: 0 | M17: 7.0478 | N17: T1128911219 | O17: 144.75.215.43 | P17: 0.0262 | Q17: 0.118 | R17: 679 | S17: 948 | T17: 0 | U17: 0
A18: Admissions | B18: 10_03_054_01100_5521 | C18: Admissions Office | D18: 309 Letcher | E18: 201 | F18: AF SP4310N | G18: PTR | H18: 17099512 | I18: 0 | J18: 0 | K18: 0 | L18: 0 | M18: 0 | N18: T1129010877 | O18: 144.75.186.30 | P18: 0.0262 | Q18: 0.118 | R18: 50 | S18: 50 | T18: 0 | U18: 0
A19: Admissions | B19: 10_03_054_01100_5521 | C19: Admissions Office | D19: 309 Letcher | E19: 302 | F19: AF SPC242DN | G19: PTR | H19: 17099423 | I19: 59 | J19: 216 | K19: 1.5458 | L19: 25.488 | M19: 27.0338 | N19: T202P700463 | O19: 144.75.186.29 | P19: 0.0262 | Q19: 0.118 | R19: 196 | S19: 255 | T19: 550 | U19: 766
A20: Admissions | B20: 10_03_054_01100_5521 | C20: Admissions Office | D20: 309 Letcher | E20: 306 | F20: AF SPC242DN | G20: PTR | H20: 17099731 | I20: 230 | J20: 54 | K20: 6.026 | L20: 6.372 | M20: 12.398 | N20: T202P600637 | O20: 144.75.186.28 | P20: 0.0262 | Q20: 0.118 | R20: 1500 | S20: 1730 | T20: 618 | U20: 672
A21: Admissions | B21: 10_03_054_01100_5521 | C21: Admissions Office | D21: 309 Letcher | E21: 306 | F21: AF SPC242DN | G21: PTR | H21: 17099511 | I21: 36 | J21: 85 | K21: 0.9432 | L21: 10.03 | M21: 10.9732 | N21: T202P700465 | O21: 144.75.186.25 | P21: 0.0262 | Q21: 0.118 | R21: 409 | S21: 445 | T21: 472 | U21: 557
A22: Athletic Advising | B22: 40_00_052_06550_5521 | C22: AOF - Academic Advising | D22: Carroll Hall | E22: 210 | F22: AF MPC2051 | G22: MFP | H22: 17099459 | I22: 8103 | J22: 326 | K22: 167.7321 | L22: 28.362 | M22: 196.0941 | N22: V9725401429 | O22: 144.75.195.41 | P22: 0.0207 | Q22: 0.087 | R22: 33629 | S22: 41732 | T22: 3170 | U22: 3496
A23: Auxiliary Services | B23: 10_08_309_82115_5521 | C23: Auxiliary Administration | D23: Cocke Hall | E23: 502 | F23: AF MPC2051 | G23: MFP | H23: 17099424 | I23: 968 | J23: 196 | K23: 20.0376 | L23: 17.052 | M23: 37.0896 | N23: V9725500651 | O23: 144.75.177.32 | P23: 0.0207 | Q23: 0.087 | R23: 5760 | S23: 6728 | T23: 625 | U23: 821
A24: Laundry | B24: 10_08_303_82240_5521 | C24: AUX-Laundry & Pressing | D24: Richardson Hall | E24: 201 | F24: AF SPC242DN | G24: PTR | H24: 17099622 | I24: 39 | J24: 37 | K24: 1.0218 | L24: 4.366 | M24: 5.3878 | N24: T202P700340 | O24: 144.75.195.95 | P24: 0.0262 | Q24: 0.118 | R24: 51 | S24: 90 | T24: 38 | U24: 75
A25: Laundry | B25: 10_08_303_82240_5521 | C25: AUX-Laundry & Pressing | D25: Richardson Hall | E25: 201 | F25: AF MP301SP | G25: MFP | H25: 17099401 | I25: 1046 | J25: 0 | K25: 21.6522 | L25: 0 | M25: 21.6522 | N25: W912P602288 | O25: 144.75.195.6 | P25: 0.0207 | Q25: 0.087 | R25: 6131 | S25: 7177 | T25: 0 | U25: 0
A26: Military Store | B26: 10_08_302_82190_5521 | C26: AUX-Military Store | D26: Kilbourne Hall | E26: QMD | F26: AF MPC2051 | G26: MFP | H26: 17099416 | I26: 1277 | J26: 6 | K26: 26.4339 | L26: 0.522 | M26: 26.9559 | N26: V9734900029 | O26: 144.75.187.37 | P26: 0.0207 | Q26: 0.087 | R26: 463 | S26: 1740 | T26: 27 | U26: 33
A27: Military Store | B27: 10_08_302_82190_5521 | C27: AUX-Military Store | D27: Richardson Hall | E27: 401 | F27: AF SP4310N | G27: PTR | H27: 17099589 | I27: 149 | J27: 0 | K27: 3.9038 | L27: 0 | M27: 3.9038 | N27: T1129012233 | O27: 144.75.180.101 | P27: 0.0262 | Q27: 0.118 | R27: 314 | S27: 463 | T27: 0 | U27: 0
A28: Military Store | B28: 10_08_302_82190_5521 | C28: AUX-Military Store | D28: Richardson Hall | E28: 401 | F28: AF SPC242DN | G28: PTR | H28: 17099724 | I28: 284 | J28: 87 | K28: 7.4408 | L28: 10.266 | M28: 17.7068 | N28: T202P801021 | O28: 144.75.180.11 | P28: 0.0262 | Q28: 0.118 | R28: 905 | S28: 1189 | T28: 229 | U28: 316
A29: Military Store | B29: 10_08_302_82190_5521 | C29: AUX-Military Store | D29: Richardson Hall | E29: 401 | F29: AF MPC2051 | G29: MFP | H29: 17099491 | I29: 1198 | J29: 1172 | K29: 24.7986 | L29: 101.964 | M29: 126.7626 | N29: V9725700303 | O29: 144.75.180.200 | P29: 0.0207 | Q29: 0.087 | R29: 5718 | S29: 6916 | T29: 2571 | U29: 3743
A30: Infirmary | B30: 10_08_305_80150_5521 | C30: AUX-Student Health | D30: Infirmary | E30: 113 | F30: AF SP4310N | G30: PTR | H30: 17099605 | I30: 2113 | J30: 0 | K30: 55.3606 | L30: 0 | M30: 55.3606 | N30: T1129010432 | O30: 144.75.176.29 | P30: 0.0262 | Q30: 0.118 | R30: 9160 | S30: 11273 | T30: 0 | U30: 0
A31: Infirmary | B31: 10_08_305_80150_5521 | C31: AUX-Student Health | D31: Infirmary | E31: 121 | F31: AF MPC2051 | G31: MFP | H31: 17099496 | I31: 1988 | J31: 715 | K31: 41.1516 | L31: 62.205 | M31: 103.3566 | N31: V9725401162 | O31: 144.75.176.21 | P31: 0.0207 | Q31: 0.087 | R31: 13826 | S31: 15814 | T31: 1144 | U31: 1859
A32: Infirmary | B32: 10_08_305_80150_5521 | C32: AUX-Student Health | D32: Infirmary | E32: 219 | F32: AF SP4310N | G32: PTR | H32: 17099635 | I32: 1130 | J32: 0 | K32: 29.606 | L32: 0 | M32: 29.606 | N32: T1128710823 | O32: 144.75.176.20 | P32: 0.0262 | Q32: 0.118 | R32: 4720 | S32: 5850 | T32: 0 | U32: 0
A33: Infirmary | B33: 10_08_305_80150_5521 | C33: AUX-Student Health | D33: Infirmary | E33: 219 | F33: AF MPC2051 | G33: MFP | H33: 17099495 | I33: 644 | J33: 138 | K33: 13.3308 | L33: 12.006 | M33: 25.3368 | N33: V9725401375 | O33: 144.75.176.46 | P33: 0.0207 | Q33: 0.087 | R33: 3815 | S33: 4459 | T33: 130 | U33: 268
A34: Tailor Shop | B34: 10_08_302_82230_5521 | C34: AUX-Tailor Shop | D34: Kilbourne Hall | E34: Tailor Shop | F34: AF SP4310N | G34: PTR | H34: 17099415 | I34: 0 | J34: 0 | K34: 0 | L34: 0 | M34: 0 | N34: T1129010838 | O34: 144.75.187.152 | P34: 0.0262 | Q34: 0.118 | R34: 7 | S34: 7 | T34: 0 | U34: 0
A35: Tailor Shop | B35: 10_08_302_82230_5521 | C35: AUX-Tailor Shop | D35: Richardson Hall | E35: Tailor Shop | F35: AF SP4310N | G35: PTR | H35: 17099610 | I35: 857 | J35: 0 | K35: 22.4534 | L35: 0 | M35: 22.4534 | N35: T1129012234 | O35: 144.75.180.89 | P35: 0.0262 | Q35: 0.118 | R35: 2746 | S35: 3603 | T35: 0 | U35: 0
A36: Business Office | B36: 10_03_062_16100_5521 | C36: Business Executive | D36: Smith Hall | E36: 301 | F36: AF SP4310N | G36: PTR | H36: 17099696 | I36: 581 | J36: 0 | K36: 15.2222 | L36: 0 | M36: 15.2222 | N36: T1129012215 | O36: 144.75.179.113 | P36: 0.0262 | Q36: 0.118 | R36: 2108 | S36: 2689 | T36: 0 | U36: 0
A37: Business Office | B37: 10_03_062_16100_5521 | C37: Business Executive | D37: Smith Hall | E37: 303 | F37: AF SPC242DN | G37: PTR | H37: 17099739 | I37: 78 | J37: 130 | K37: 2.0436 | L37: 15.34 | M37: 17.3836 | N37: T202P901338 | O37: 144.75.179.122 | P37: 0.0262 | Q37: 0.118 | R37: 17 | S37: 95 | T37: 107 | U37: 237
A38: Physics & Astronomy | B38: 40_00_011_78500_5521 | C38: Cameron Physics & Astronomy | D38: Mallory Hall | E38: 123 | F38: AF SP4310N | G38: PTR | H38: 17099689 | I38: 25 | J38: 0 | K38: 0.655 | L38: 0 | M38: 0.655 | N38: T1129011274 | O38: 144.75.182.85 | P38: 0.0262 | Q38: 0.118 | R38: 443 | S38: 468 | T38: 0 | U38: 0
A39: Physics & Astronomy | B39: 40_00_011_78500_5521 | C39: Cameron Physics & Astronomy | D39: Mallory Hall | E39: 324 | F39: AF MPC3502 | G39: MFP | H39: 17099463 | I39: 5358 | J39: 1725 | K39: 110.9106 | L39: 150.075 | M39: 260.9856 | N39: W502L601236 | O39: 144.75.182.208 | P39: 0.0207 | Q39: 0.087 | R39: 38106 | S39: 43464 | T39: 4714 | U39: 6439
A40: Physics & Astronomy | B40: 40_00_011_78500_5521 | C40: Cameron Physics & Astronomy | D40: Mallory Hall | E40: 328 | F40: AF SP4310N | G40: PTR | H40: 17099588 | I40: 156 | J40: 0 | K40: 4.0872 | L40: 0 | M40: 4.0872 | N40: T1129011359 | O40: 144.75.182.15 | P40: 0.0262 | Q40: 0.118 | R40: 762 | S40: 918 | T40: 0 | U40: 0
...

Sheet GL Summary
A3: Row Labels | B3: Sum of Device Total Click Charge
A4: Academic Advising | B4: 25.6008
A5: Administrative | B5: 657.5527
A6: Admissions Office | B6: 420.8041
A7: AOF - Academic Advising | B7: 207.9699
A8: Auxiliary Administration | B8: 24.1839
A9: AUX-Laundry & Pressing | B9: 28.5029
A10: AUX-Military Store | B10: 150.7084
A11: AUX-Student Health | B11: 208.4622
A12: AUX-Tailor Shop | B12: 18.1042
A13: Business Executive | B13: 230.7838
A14: Cameron Physics & Astronomy | B14: 417.5798
A15: Career Services and Placement | B15: 63.5088
... A65: Undergraduate Research | B65: 30.1076
A66: (blank)
A67: Biology | B67: 9.7988
A68: Drug & Alcohol Abuse | B68: 66.4495
A69: Financial Aid Administration | B69: 146.5366
A70: Post Security | B70: 195.9836
A71: Stone Wall Jackson House | B71: 26.3756
A72: Math Education Resource Center | B72: 28.9077
A73: Grand Total | B73: 22154.258

Sheet April 2013 - HP Toner
A1: Department | B1: General Ledger | C1: GL Description | D1: Building | E1: Room | F1: Model | G1: Device Type | H1: Ricoh Tag | I1: Toner Type | J1: Quantity | K1: Toner Cost Ea. | L1: Total Toner Cost | M1: Serial Number | N1: IP Address
A2: Superintendents House | B2: 10_03_061_94100_5521 | C2: =VLOOKUP(B2,Tables!G$2:H$79,2,FALSE) -> Superintendents Office | D2: Superintendents House | E2: Basement | F2: M2727 | G2: HP-MFP | H2: 17099735 | I2: Black | K2: 47.92 | L2: =SUM(J2*K2) -> 0 | M2: CNG8961SWT | N2: 144.75.156.35
A3: Protocol | B3: 10_03_065_84100_5521 | C3: =VLOOKUP(B3,Tables!G$2:H$79,2,FALSE) -> Protocol Office | D3: 303 Letcher | E3: 300 | F3: 4650 | G3: HP-PTR | H3: 17099-732 | I3: Black | K3: 58.48 | L3: =SUM(J3*K3) -> 0 | M3: JPKAC48117 | N3: 144.75.178.14
A4: Protocol | B4: 10_03_065_84100_5521 | C4: =VLOOKUP(B4,Tables!G$2:H$79,2,FALSE) -> Protocol Office | D4: 303 Letcher | E4: 300 | F4: 4650 | G4: HP-PTR | H4: 17099-732 | I4: Cyan | K4: 58.48 | L4: =SUM(J4*K4) -> 0 | M4: JPKAC48117 | N4: 144.75.178.14
A5: Protocol | B5: 10_03_065_84100_5521 | C5: =VLOOKUP(B5,Tables!G$2:H$90,2,FALSE) -> Protocol Office | D5: 303 Letcher | E5: 300 | F5: 4650 | G5: HP-PTR | H5: 17099-732 | I5: Magenta | K5: 58.48 | L5: =SUM(J5*K5) -> 0 | M5: JPKAC48117 | N5: 144.75.178.14
A6: Protocol | B6: 10_03_065_84100_5521 | C6: =VLOOKUP(B6,Tables!G$2:H$90,2,FALSE) -> Protocol Office | D6: 303 Letcher | E6: 300 | F6: 4650 | G6: HP-PTR | H6: 17099-732 | I6: Yellow | K6: 58.48 | L6: =SUM(J6*K6) -> 0 | M6: JPKAC48117 | N6: 144.75.178.14
A7: Admissions | B7: 10_03_054_01100_5521 | C7: =VLOOKUP(B7,Tables!G$2:H$90,2,FALSE) -> Admissions Office | D7: 307 Letcher | E7: 204 | F7: CP4025 | G7: HP-PTR | H7: 17099781 | I7: Black | K7: 89.75 | L7: =SUM(J7*K7) -> 0 | M7: JPBCBBMOSG | N7: 144.75.215.29
A8: Admissions | B8: 10_03_054_01100_5521 | C8: =VLOOKUP(B8,Tables!G$2:H$90,2,FALSE) -> Admissions Office | D8: 307 Letcher | E8: 204 | F8: CP4025 | G8: HP-PTR | H8: 17099781 | I8: Cyan | K8: 91.49 | L8: =SUM(J8*K8) -> 0 | M8: JPBCBBMOSG | N8: 144.75.215.29
A9: Admissions | B9: 10_03_054_01100_5521 | C9: =VLOOKUP(B9,Tables!G$2:H$90,2,FALSE) -> Admissions Office | D9: 307 Letcher | E9: 204 | F9: CP4025 | G9: HP-PTR | H9: 17099781 | I9: Magenta | K9: 91.49 | L9: =SUM(J9*K9) -> 0 | M9: JPBCBBMOSG | N9: 144.75.215.29
A10: Admissions | B10: 10_03_054_01100_5521 | C10: =VLOOKUP(B10,Tables!G$2:H$90,2,FALSE) -> Admissions Office | D10: 307 Letcher | E10: 204 | F10: CP4025 | G10: HP-PTR | H10: 17099781 | I10: Yellow | K10: 91.49 | L10: =SUM(J10*K10) -> 0 | M10: JPBCBBMOSG | N10: 144.75.215.29
A11: Media Services | B11: 10_03_041_62100_5521 | C11: =VLOOKUP(B11,Tables!G$2:H$90,2,FALSE) -> Libraries | D11: Preston Library | E11: 406 | F11: LJ3600 | G11: HP-PTR | H11: 17099815 | I11: Black | K11: 53.82 | L11: =SUM(J11*K11) -> 0 | M11: CNWDF12176 | N11: 144.75.196.251
A12: Media Services | B12: 10_03_041_62100_5521 | C12: =VLOOKUP(B12,Tables!G$2:H$90,2,FALSE) -> Libraries | D12: Preston Library | E12: 406 | F12: LJ3600 | G12: HP-PTR | H12: 17099815 | I12: Cyan | K12: 61.89 | L12: =SUM(J12*K12) -> 0 | M12: CNWDF12177 | N12: 144.75.196.251
A13: Media Services | B13: 10_03_041_62100_5521 | C13: =VLOOKUP(B13,Tables!G$2:H$90,2,FALSE) -> Libraries | D13: Preston Library | E13: 406 | F13: LJ3600 | G13: HP-PTR | H13: 17099815 | I13: Magenta | K13: 61.89 | L13: =SUM(J13*K13) -> 0 | M13: CNWDF12178 | N13: 144.75.196.251
A14: Media Services | B14: 10_03_041_62100_5521 | C14: =VLOOKUP(B14,Tables!G$2:H$90,2,FALSE) -> Libraries | D14: Preston Library | E14: 406 | F14: LJ3600 | G14: HP-PTR | H14: 17099815 | I14: Yellow | K14: 61.89 | L14: =SUM(J14*K14) -> 0 | M14: CNWDF12179 | N14: 144.75.196.251
A15: Psychology & Philosophy | B15: 10_03_011_86100_5521 | C15: =VLOOKUP(B15,Tables!G$2:H$90,2,FALSE) -> Philosophy & Psychology | D15: Carroll Hall | E15: 403 | F15: LJ4005 | G15: HP-PTR | H15: 17099728 | I15: Black | K15: 74.18 | L15: =SUM(J15*K15) -> 0 | M15: JPRLB46624 | N15: 144.75.195.232
A16: Psychology & Philosophy | B16: 10_03_011_86100_5521 | C16: =VLOOKUP(B16,Tables!G$2:H$90,2,FALSE) -> Philosophy & Psychology | D16: Carroll Hall | E16: 403 | F16: LJ4005 | G16: HP-PTR | H16: 17099728 | I16: Cyan | K16: 76.19 | L16: =SUM(J16*K16) -> 0 | M16: JPRLB46625 | N16: 144.75.195.232
A17: Psychology & Philosophy | B17: 10_03_011_86100_5521 | C17: =VLOOKUP(B17,Tables!G$2:H$90,2,FALSE) -> Philosophy & Psychology | D17: Carroll Hall | E17: 403 | F17: LJ4005 | G17: HP-PTR | H17: 17099728 | I17: Magenta | K17: 76.19 | L17: =SUM(J17*K17) -> 0 | M17: JPRLB46626 | N17: 144.75.195.232
A18: Psychology & Philosophy | B18: 10_03_011_86100_5521 | C18: =VLOOKUP(B18,Tables!G$2:H$90,2,FALSE) -> Philosophy & Psychology | D18: Carroll Hall | E18: 403 | F18: LJ4005 | G18: HP-PTR | H18: 17099728 | I18: Yellow | K18: 76.19 | L18: =SUM(J18*K18) -> 0 | M18: JPRLB46627 | N18: 144.75.195.232
A19: Athletics | B19: 30_00_310_06110_5521 | C19: =VLOOKUP(B19,Tables!G$2:H$90,2,FALSE) -> Administrative | D19: Cameron Hall | E19: 345 | F19: LJ4005 | G19: HP-PTR | H19: 17099-828 | I19: Black | K19: 74.18 | L19: =SUM(J19*K19) -> 0 | M19: JP4LC17284 | N19: Not on network
A20: Athletics | B20: 30_00_310_06110_5521 | C20: =VLOOKUP(B20,Tables!G$2:H$90,2,FALSE) -> Administrative | D20: Cameron Hall | E20: 345 | F20: LJ4005 | G20: HP-PTR | H20: 17099-828 | I20: Cyan | K20: 76.19 | L20: =SUM(J20*K20) -> 0 | M20: JP4LC17284 | N20: Not on network
A21: Athletics | B21: 30_00_310_06110_5521 | C21: =VLOOKUP(B21,Tables!G$2:H$90,2,FALSE) -> Administrative | D21: Cameron Hall | E21: 345 | F21: LJ4005 | G21: HP-PTR | H21: 17099-828 | I21: Magenta | K21: 76.19 | L21: =SUM(J21*K21) -> 0 | M21: JP4LC17284 | N21: Not on network
A22: Athletics | B22: 30_00_310_06110_5521 | C22: =VLOOKUP(B22,Tables!G$2:H$90,2,FALSE) -> Administrative | D22: Cameron Hall | E22: 345 | F22: LJ4005 | G22: HP-PTR | H22: 17099-828 | I22: Yellow | K22: 76.19 | L22: =SUM(J22*K22) -> 0 | M22: JP4LC17284 | N22: Not on network
A23: Comptrollers | B23: 10_03_062_32100_5521 | C23: =VLOOKUP(B23,Tables!G$2:H$90,2,FALSE) -> Comptroller's Office | D23: Smith Hall | E23: 311 | F23: P3010 | G23: HP-PTR | H23: 17099745 | I23: Black | K23: 32.03 | L23: =SUM(J23*K23) -> 0 | M23: VNBCC4L0MD | N23: 144.75.179.5
A24: Comptrollers | B24: 10_03_062_32100_5521 | C24: =VLOOKUP(B24,Tables!G$2:H$90,2,FALSE) -> Comptroller's Office | D24: Smith Hall | E24: 320 | F24: P3010 | G24: HP-PTR | H24: 17099744 | I24: Black | K24: 32.03 | L24: =SUM(J24*K24) -> 0 | M24: VNBCC4L0M6 | N24: 144.75.179.31
A25: Laundry | B25: 10_08_303_82240_5521 | C25: =VLOOKUP(B25,Tables!G$2:H$90,2,FALSE) -> AUX-Laundry & Pressing | D25: Ricohardson Hall | E25: Kiosk | F25: 2430 | G25: HP-PTR | H25: 17099843 | I25: Black | K25: 117.39 | L25: =SUM(J25*K25) -> 0
A26: Financial Aid | B26: 10_03_055_42100_5521 | C26: =VLOOKUP(B26,Tables!G$2:H$90,2,FALSE) -> Financial Aid Administration | D26: Carroll Hall | E26: 302 | F26: m1536dnf | G26: HP-MFP | H26: 17099742 | I26: Black | K26: 25.24 | L26: =SUM(J26*K26) -> 0 | M26: CNC9CC2DKZ | N26: 144.75.195.116
A27: Physical Education | B27: 10_03_011_76100_5521 | C27: =VLOOKUP(B27,Tables!G$2:H$90,2,FALSE) -> Physical Education | D27: Cocke Hall | E27: 322A | F27: CP4025 | G27: HP-PTR | H27: 17099746 | I27: Black | L27: =SUM(J27*K27) -> 0 | M27: CNDX147930 | N27: 144.75.177.50
A28: Math & Computer Science | B28: 10_03_011_64100_5521 | C28: =VLOOKUP(B28,Tables!G$2:H$90,2,FALSE) -> Mathematics | D28: Mallory Hall | E28: 310 | F28: P3005DN | G28: HP-PTR | H28: 17099747 | I28: Black | J28: 1 | K28: 49.38 | L28: =SUM(J28*K28) -> 49.38 | M28: CDN1S33307 | N28: 144.75.182.73
A29: Math & Computer Science | B29: 10_03_011_64100_5521 | C29: =VLOOKUP(B29,Tables!G$2:H$90,2,FALSE) -> Mathematics | D29: Mallory Hall | E29: 314 | F29: P3005DN | G29: HP-PTR | H29: 17099748 | I29: Black | K29: 49.38 | L29: =SUM(J29*K29) -> 0 | M29: CND1S29060 | N29: 144.75.182.65
A30: Math & Computer Science | B30: 10_03_011_64100_5521 | C30: =VLOOKUP(B30,Tables!G$2:H$90,2,FALSE) -> Mathematics | D30: Mallory Hall | E30: 316 | F30: P3005DN | G30: HP-PTR | H30: 17099748 | I30: Black | K30: 49.38 | L30: =SUM(J30*K30) -> 0 | M30: CND1R25001 | N30: 144.75.182.88
A31: Chemistry | B31: 10_03_011_26100_5521 | C31: =VLOOKUP(B31,Tables!G$2:H$90,2,FALSE) -> Chemistry | D31: Maury Brooke | E31: 303 | F31: LJ4005 | G31: HP-PTR | H31: 17099751 | I31: Black | K31: 102.01 | L31: =SUM(J31*K31) -> 0 | M31: JP4LC04882 | N31: 144.75.202.79
A32: Chemistry | B32: 10_03_011_26100_5521 | C32: =VLOOKUP(B32,Tables!G$2:H$90,2,FALSE) -> Chemistry | D32: Maury Brooke | E32: 303 | F32: LJ4005 | G32: HP-PTR | H32: 17099751 | I32: Cyan | K32: 102.01 | L32: =SUM(J32*K32) -> 0 | M32: JP4LC04883 | N32: 144.75.202.80
A33: Chemistry | B33: 10_03_011_26100_5521 | C33: =VLOOKUP(B33,Tables!G$2:H$90,2,FALSE) -> Chemistry | D33: Maury Brooke | E33: 303 | F33: LJ4005 | G33: HP-PTR | H33: 17099751 | I33: Magenta | K33: 102.01 | L33: =SUM(J33*K33) -> 0 | M33: JP4LC04884 | N33: 144.75.202.81
A34: Chemistry | B34: 10_03_011_26100_5521 | C34: =VLOOKUP(B34,Tables!G$2:H$90,2,FALSE) -> Chemistry | D34: Maury Brooke | E34: 303 | F34: LJ4005 | G34: HP-PTR | H34: 17099751 | I34: Yellow | K34: 102.01 | L34: =SUM(J34*K34) -> 0 | M34: JP4LC04885 | N34: 144.75.202.82
A35: Custodial Services | B35: 10_03_071_14100_5521 | C35: =VLOOKUP(B35,Tables!G$2:H$90,2,FALSE) -> Physical Plant Administration | D35: 320 Institute Hill | E35: Basement | F35: LJ2420 | G35: HP-PTR | H35: 17099855 | I35: Black | J35: 1 | K35: 49.37 | L35: =SUM(J35*K35) -> 49.37 | M35: CNGKK65998 | N35: 144.75.201.27
A36: Business Office | B36: 10_03_062_16100_5521 | C36: =VLOOKUP(B36,Tables!G$2:H$90,2,FALSE) -> Business Executive | D36: Smith Hall | E36: 303 | F36: LJ4005 | G36: HP-PTR | H36: 17099854 | I36: Black | K36: 102.01 | L36: =SUM(J36*K36) -> 0 | M36: JP4LC04906 | N36: 144.75.179.112
A37: Business Office | B37: 10_03_062_16100_5521 | C37: =VLOOKUP(B37,Tables!G$2:H$90,2,FALSE) -> Business Executive | D37: Smith Hall | E37: 303 | F37: LJ4005 | G37: HP-PTR | H37: 17099854 | I37: Cyan | K37: 102.01 | L37: =SUM(J37*K37) -> 0 | M37: JP4LC04906 | N37: 144.75.179.112
A38: Business Office | B38: 10_03_062_16100_5521 | C38: =VLOOKUP(B38,Tables!G$2:H$90,2,FALSE) -> Business Executive | D38: Smith Hall | E38: 303 | F38: LJ4005 | G38: HP-PTR | H38: 17099854 | I38: Magenta | K38: 102.01 | L38: =SUM(J38*K38) -> 0 | M38: JP4LC04906 | N38: 144.75.179.112
A39: Business Office | B39: 10_03_062_16100_5521 | C39: =VLOOKUP(B39,Tables!G$2:H$90,2,FALSE) -> Business Executive | D39: Smith Hall | E39: 303 | F39: LJ4005 | G39: HP-PTR | H39: 17099854 | I39: Yellow | K39: 102.01 | L39: =SUM(J39*K39) -> 0 | M39: JP4LC04906 | N39: 144.75.179.112
A40: Institutional Research | B40: 10_03_045_54100_5521 | C40: =VLOOKUP(B40,Tables!G$2:H$90,2,FALSE) -> Institutional Analysis | D40: Smith Hall | E40: 101 | F40: LJ5550HDN | G40: HP-PTR | H40: 17099854 | I40: Black | K40: 127.24 | L40: =SUM(J40*K40) -> 0 | M40: JPDC4CK00H | N40: 144.75.179.229
...

Sheet Totals
D2: B&W MFP | E2: Color MFP | F2: B/W MFD | G2: Color MFD | J2: B&W MFP | K2: Color MFP
C3: MFP: | D3: =SUMIF('April 2013 - Data'!G$2:$G$384,"MFP",'April 2013 - Data'!I$2:I$384) -> 443547 | E3: =SUMIF('April 2013 - Data'!G$2:$G$384,"MFP",'April 2013 - Data'!J$2:J$384) -> 75530 | F3: =SUM(D3)*D14 -> 9181.4229 | G3: =SUM(E3)*E14 -> 6571.11 | J3: =SUMIF('April 2013 - Data'!$G$2:G$384,"MFP",'April 2013 - Data'!K$2:K$384) -> 9181.4229 | K3: =SUMIF('April 2013 - Data'!$G$2:$G$384,"MFP",'April 2013 - Data'!L$2:L$384) -> 6571.11
D5: B&W Printer | E5: Color Printer | F5: B/W Printer | G5: Color Printer | J5: B&W Printer | K5: Color Printer
C6: Printer: | D6: =SUMIF('April 2013 - Data'!$G$2:$G$384,"PTR",'April 2013 - Data'!I2:I384) -> 223033 | E6: =SUMIF('April 2013 - Data'!$G2:$G$384,"PTR",'April 2013 - Data'!J$2:J$384) -> 4731 | F6: =SUM(D6)*D15 -> 5843.4646 | G6: =SUM(E6)*E15 -> 558.258 | J6: =SUMIF('April 2013 - Data'!$G$2:$G$384,"PTR",'April 2013 - Data'!K$2:K$384) -> 5843.4646 | K6: =SUMIF('April 2013 - Data'!$G$2:$G$384,"PTR",'April 2013 - Data'!L$2:L$384) -> 558.258
D8: Total B&W | E8: Total Color | F8: Total B&W | G8: Total Color | J8: Total B&W | K8: Total Color
C9: Total: | D9: =SUM(D3,D6) -> 666580 | E9: =SUM(E3,E6) -> 80261 | F9: =ROUNDUP(F3+F6,2) -> 15024.89 | G9: =ROUNDUP(G3+G6,2) -> 7129.37 | J9: =ROUNDUP(J3+J6,2) -> 15024.89 | K9: =ROUNDUP(K3+K6,2) -> 7129.37
F11: Total This Invoice: | G11: =(F9+G9) -> 22154.26 | J11: Total This Invoice: | K11: =SUM(J9+K9) -> 22154.26
F12: HP Toner: | G12: ='April 2013 - HP Toner'!L51 -> 157.28 | J12: Total Invoice w/ HP Toner: | K12: =G13 -> 22311.54
F13: Invoice Total | G13: =SUM(G11:G12) -> 22311.54
C14: MFP | D14: =Tables!B2 -> 0.0207 | E14: =Tables!B3 -> 0.087
C15: Printer | D15: =Tables!B5 -> 0.0262 | E15: =Tables!B6 -> 0.118
F18: MFP Total: | G18: =COUNTIF('April 2013 - Data'!G2:G384,"PTR") -> 231
F19: Printer Total: | G19: =COUNTIF('April 2013 - Data'!G2:G384,"MFP") -> 68
F20: Device Total: | G20: =SUM(G18:G19) -> 299

Sheet Tables
A1: Rates | D1: Devices | E1: Type | G1: GL # | H1: Description
A2: MFP B&W | B2: 0.0207 | D2: AF MP301SP | E2: MFP | G2: 10_03_054_60100_5521 | H2: Learning Programs
A3: MFP Color | B3: 0.087 | D3: AF MP4002 | E3: MFP | G3: 10_03_054_01100_5521 | H3: Admissions Office
D4: AF MP6001 | E4: MFP | G4: 10_03_011_02100_5521 | H4: ROTC-Air Force
A5: Printer B&W | B5: 0.0262 | D5: AF MPC2051 | E5: MFP | G5: 10_03_011_04100_5521 | H5: ROTC-Army
A6: Printer Color | B6: 0.118 | D6: AF MPC3502 | E6: MFP | G6: 30_00_310_06104_5521 | H6: Sports Information
D7: AF MPC4502 | E7: MFP | G7: 30_00_310_06095_5521 | H7: Soccer - Women
D8: AF MPC6501 | E8: MFP | G8: 30_00_310_06000_5521 | H8: Football
D9: AF SP4310N | E9: PTR | G9: 30_00_310_06090_5521 | H9: Soccer
D10: AF SPC242DN | E10: PTR | G10: 30_00_310_06010_5521 | H10: Basketball
D11: AF SPC430DN | E11: PTR | G11: 30_00_310_06020_5521 | H11: Track & Cross Country
D12: AF MPC5502 | E12: MFP | G12: 30_00_310_06110_5521 | H12: Administrative
G13: 40_00_052_06550_5521 | H13: AOF - Academic Advising
G14: 10_08_309_82115_5521 | H14: Auxiliary Administration
G15: 10_08_303_82240_5521 | H15: AUX-Laundry & Pressing
G16: 10_08_302_82230_5521 | H16: AUX-Tailor Shop
G17: 10_03_064_82140_5521 | H17: Post Mail
G18: 10_08_302_82190_5521 | H18: AUX-Military Store
G19: 40_00_011_10250_5521 | H19: Carroll Biology Fund
G20: 10_03_011_10100_5521 | H20: Biology
G21: 10_03_062_16100_5521 | H21: Business Executive
G22: 10_03_062_16150_5521 | H22: Institute Planning
G23: 10_08_307_18380_5521 | H23: Student Union
G24: 10_03_053_20300_5521 | H24: Career Services and Placement
... G82: 30_00_031_70150_5521 | H82: New Market Battle Field

Sheet Meter Comparison
A1: Manufacturer | B1: Model | C1: Serial Number | D1: Mono Pages First Meter | E1: Mono Pages Last Meter | F1: Color Pages First Meter | G1: Color Pages Last Meter | H1: First Meter Date | I1: Last Meter Date | J1: Serial Number
A2: RICOH | B2: Aficio SP C430DN | C2: S9329101012 | D2: 871 | E2: 873 | F2: 87 | G2: 87 | J2: S9329101012
A3: RICOH | B3: Aficio SP C430DN | C3: S9329101091 | D3: 1512 | E3: 1774 | F3: 3151 | G3: 3833 | J3: S9329101091
A4: RICOH | B4: Aficio SP 4310N | C4: T1128710718 | D4: 14950 | E4: 17598 | F4: 0 | G4: 0 | J4: T1128710718
A5: RICOH | B5: Aficio SP 4310N | C5: T1128710823 | D5: 5850 | E5: 6833 | F5: 0 | G5: 0 | J5: T1128710823
A6: RICOH | B6: Aficio SP 4310N | C6: T1128710825 | D6: 2296 | E6: 2859 | F6: 0 | G6: 0 | J6: T1128710825
A7: RICOH | B7: Aficio SP 4310N | C7: T1128710860 | D7: 3599 | E7: 4324 | F7: 0 | G7: 0 | J7: T1128710860
A8: RICOH | B8: Aficio SP 4310N | C8: T1128710864 | D8: 2758 | E8: 4419 | F8: 0 | G8: 0 | J8: T1128710864
A9: RICOH | B9: Aficio SP 4310N | C9: T1128712304 | D9: 55883 | E9: 64629 | F9: 0 | G9: 0 | J9: T1128712304
A10: RICOH | B10: Aficio SP 4310N | C10: T1128712307 | D10: 55960 | E10: 66853 | F10: 0 | G10: 0 | J10: T1128712307
A11: RICOH | B11: Aficio SP 4310N | C11: T1128810903 | D11: 2373 | E11: 2608 | F11: 0 | G11: 0 | J11: T1128810903
A12: RICOH | B12: Aficio SP 4310N | C12: T1128811582 | D12: 4781 | E12: 5958 | F12: 0 | G12: 0 | J12: T1128811582
A13: RICOH | B13: Aficio SP 4310N | C13: T1128811618 | D13: 1527 | E13: 1918 | F13: 0 | G13: 0 | J13: T1128811618
... A101: RICOH | B101: Aficio SP 4310N | C101: T1129010432 | D101: 11273 | E101: 14673 | F101: 0 | G101: 0 | J101: T1129010432
A102: RICOH | B102: Aficio SP 4310N | C102: T1129010621 | D102: 548 | E102: 656 | J102: T1129010621
A103: RICOH | B103: Aficio SP 4310N | C103: T1129010623 | D103: 1195 | E103: 1852 | F103: 0 | G103: 0 | J103: T1129010623
A104: RICOH | B104: Aficio SP 4310N | C104: T1129010625 | D104: 148 | E104: 297 | F104: 0 | G104: 0 | J104: T1129010625
A105: RICOH | B105: Aficio SP 4310N | C105: T1129010627 | D105: 204 | E105: 204 | F105: 0 | G105: 0 | J105: T1129010627
A106: RICOH | B106: Aficio SP 4310N | C106: T1129010629 | D106: 734 | E106: 1293 | F106: 0 | G106: 0 | J106: T1129010629
A107: RICOH | B107: Aficio SP 4310N | C107: T1129010631 | D107: 122 | E107: 240 | F107: 0 | G107: 0 | J107: T1129010631
A108: RICOH | B108: Aficio SP 4310N | C108: T1129010633 | D108: 8 | E108: 92 | J108: T1129010633
A109: RICOH | B109: Aficio SP 4310N | C109: T1129010634 | D109: 505 | E109: 548 | F109: 0 | G109: 0 | J109: T1129010634
A110: RICOH | B110: Aficio SP 4310N | C110: T1129010677 | D110: 3865 | E110: 4735 | F110: 0 | G110: 0 | J110: T1129010677
A111: RICOH | B111: Aficio SP 4310N | C111: T1129010681 | D111: 1133 | E111: 1332 | F111: 0 | G111: 0 | J111: T1129010681
A112: RICOH | B112: Aficio SP 4310N | C112: T1129010744 | D112: 1394 | E112: 1678 | F112: 0 | G112: 0 | J112: T1129010744
A113: RICOH | B113: Aficio SP 4310N | C113: T1129010748 | D113: 1512 | E113: 1666 | F113: 0 | G113: 0 | J113: T1129010748
A114: RICOH | B114: Aficio SP 4310N | C114: T1129010760 | D114: 561 | E114: 719 | F114: 0 | G114: 0 | J114: T1129010760
A115: RICOH | B115: Aficio SP 4310N | C115: T1129010803 | D115: 3808 | E115: 4686 | F115: 0 | G115: 0 | J115: T1129010803
A116: RICOH | B116: Aficio SP 4310N | C116: T1129010820 | D116: 458 | E116: 589 | F116: 0 | G116: 0 | J116: T1129010820
A117: RICOH | B117: Aficio SP 4310N | C117: T1129010823 | D117: 979 | E117: 1176 | F117: 0 | G117: 0 | J117: T1129010823
A118: RICOH | B118: Aficio SP 4310N | C118: T1129010832 | D118: 844 | E118: 850 | F118: 0 | G118: 0 | J118: T1129010832
A119: RICOH | B119: Aficio SP 4310N | C119: T1129010833 | D119: 2654 | E119: 3155 | F119: 0 | G119: 0 | J119: T1129010833
A120: RICOH | B120: Aficio SP 4310N | C120: T1129010836 | D120: 1912 | E120: 1932 | F120: 0 | G120: 0 | J120: T1129010836
... A141: RICOH | B141: Aficio SP 4310N | C141: T1129010904 | D141: 182 | E141: 411 | F141: 0 | G141: 0 | J141: T1129010904
A142: RICOH | B142: Aficio SP 4310N | C142: T1129010906 | D142: 115 | E142: 119 | J142: T1129010906
A143: RICOH | B143: Aficio SP 4310N | C143: T1129010908 | D143: 5 | E143: 7 | J143: T1129010908
A144: RICOH | B144: Aficio SP 4310N | C144: T1129010910 | D144: 504 | E144: 511 | F144: 0 | G144: 0 | J144: T1129010910
A145: RICOH | B145: Aficio SP 4310N | C145: T1129010912 | D145: 148 | E145: 176 | F145: 0 | G145: 0 | J145: T1129010912
A146: RICOH | B146: Aficio SP 4310N | C146: T1129010915 | D146: 778 | E146: 1090 | F146: 0 | G146: 0 | J146: T1129010915
A147: RICOH | B147: Aficio SP 4310N | C147: T1129010918 | D147: 2399 | E147: 2588 | F147: 0 | G147: 0 | J147: T1129010918
...
