Workbook

Sheet 01
A1: 1 | B1: ANDROSCOGGIN
A2: Age | C2: 0-4 | D2: 5-9 | E2: 10-14 | F2: 15-19 | G2: 20-24 | H2: 25-29 | I2: 30-34 | J2: 35-39 | K2: 40-44 | L2: 45-49 | M2: 50-54 | N2: 55-59 | O2: 60-64 | P2: 65-69 | Q2: 70-74 | R2: 75-79 | S2: 80-84 | T2: 85+ | U2: Total
A3: Female
A4: 2001 | C4: 3022 | D4: 3252 | E4: 3596 | F4: 3772 | G4: 3351 | H4: 3024 | I4: 3762 | J4: 4235 | K4: 4258 | L4: 3882 | M4: 3685 | N4: 2680 | O4: 2171 | P4: 2121 | Q4: 1920 | R4: 1848 | S4: 1519 | T4: 1609 | U4: =SUM(C4:T4) -> 53707
A5: 2002 | C5: 3049 | D5: 3165 | E5: 3650 | F5: 3739 | G5: 3529 | H5: 3004 | I5: 3628 | J5: 4217 | K5: 4302 | L5: 3987 | M5: 3692 | N5: 2962 | O5: 2209 | P5: 2054 | Q5: 1943 | R5: 1812 | S5: 1510 | T5: 1567 | U5: =SUM(C5:T5) -> 54019
A6: 2003 | C6: 3119 | D6: 3115 | E6: 3630 | F6: 3821 | G6: 3512 | H6: 3083 | I6: 3557 | J6: 4204 | K6: 4298 | L6: 4049 | M6: 3764 | N6: 3070 | O6: 2325 | P6: 2082 | Q6: 1935 | R6: 1806 | S6: 1462 | T6: 1577 | U6: =SUM(C6:T6) -> 54409
A7: 2004 | C7: 3176 | D7: 3126 | E7: 3606 | F7: 3729 | G7: 3483 | H7: 3210 | I7: 3483 | J7: 4029 | K7: 4390 | L7: 4117 | M7: 3827 | N7: 3238 | O7: 2411 | P7: 2069 | Q7: 1949 | R7: 1779 | S7: 1451 | T7: 1534 | U7: =SUM(C7:T7) -> 54607
A8: 2005 | C8: 3241 | D8: 3183 | E8: 3435 | F8: 3742 | G8: 3574 | H8: 3324 | I8: 3397 | J8: 3889 | K8: 4444 | L8: 4150 | M8: 3916 | N8: 3398 | O8: 2521 | P8: 2021 | Q8: 1910 | R8: 1722 | S8: 1435 | T8: 1530 | U8: =SUM(C8:T8) -> 54832
A9: 2006 | C9: 3390 | D9: 3164 | E9: 3374 | F9: 3672 | G9: 3625 | H9: 3434 | I9: 3333 | J9: 3817 | K9: 4321 | L9: 4232 | M9: 3954 | N9: 3571 | O9: 2637 | P9: 2003 | Q9: 1901 | R9: 1741 | S9: 1424 | T9: 1511 | U9: =SUM(C9:T9) -> 55104
A10: 2007 | C10: 3445 | D10: 3147 | E10: 3292 | F10: 3639 | G10: 3522 | H10: 3496 | I10: 3252 | J10: 3684 | K10: 4295 | L10: 4218 | M10: 4021 | N10: 3578 | O10: 2884 | P10: 2027 | Q10: 1813 | R10: 1732 | S10: 1427 | T10: 1526 | U10: =SUM(C10:T10) -> 54998
A11: 2008 | C11: 3498 | D11: 3176 | E11: 3141 | F11: 3561 | G11: 3647 | H11: 3460 | I11: 3283 | J11: 3625 | K11: 4155 | L11: 4227 | M11: 4146 | N11: 3624 | O11: 2997 | P11: 2203 | Q11: 1825 | R11: 1700 | S11: 1433 | T11: 1530 | U11: =SUM(C11:T11) -> 55231
A12: 2009 | C12: 3425 | D12: 3204 | E12: 3150 | F12: 3534 | G12: 3541 | H12: 3373 | I12: 3307 | J12: 3517 | K12: 3954 | L12: 4339 | M12: 4175 | N12: 3660 | O12: 3147 | P12: 2288 | Q12: 1789 | R12: 1719 | S12: 1408 | T12: 1488 | U12: =SUM(C12:T12) -> 55018
A13: 2010 | C13: 3392 | D13: 3220 | E13: 3185 | F13: 3428 | G13: 3579 | H13: 3355 | I13: 3355 | J13: 3365 | K13: 3846 | L13: 4347 | M13: 4179 | N13: 3700 | O13: 3303 | P13: 2352 | Q13: 1776 | R13: 1698 | S13: 1362 | T13: 1525 | U13: =SUM(C13:T13) -> 54967
A14: 2015 | C14: 3339.793 | D14: 3545.9511 | E14: 3315.8719 | F14: 3277.7304 | G14: 3528.8988 | H14: 3448.5893 | I14: 3421.6556 | J14: 3381.3614 | K14: 3370.8165 | L14: 3847.7013 | M14: 4333.3464 | N14: 4102.0418 | O14: 3577.782 | P14: 3056.5616 | Q14: 2126.1241 | R14: 1542.9808 | S14: 1367.064 | T14: 1548.7438 | U14: =SUM(C14:T14) -> 56133.014
A15: 2020 | C15: 3337.3551 | D15: 3506.2159 | E15: 3642.0251 | F15: 3406.5306 | G15: 3393.2105 | H15: 3386.368 | I15: 3521.1868 | J15: 3455.5635 | K15: 3399.694 | L15: 3393.7693 | M15: 3851.9053 | N15: 4238.6476 | O15: 3956.8331 | P15: 3311.4381 | Q15: 2757.1623 | R15: 1848.9513 | S15: 1261.1692 | T15: 1568.1413 | U15: =SUM(C15:T15) -> 57236.167
... A17: 2030 | C17: 3399.0169 | D17: 3515.597 | E17: 3613.9063 | F17: 3707.2663 | G17: 3822.0949 | H17: 3377.7906 | I17: 3355.2069 | J17: 3486.258 | K17: 3586.9838 | L17: 3520.2049 | M17: 3475.1024 | N17: 3368.5626 | O17: 3640.0016 | P17: 3765.666 | Q17: 3295.9155 | R17: 2594.0974 | S17: 1949.8681 | T17: 1686.4259 | U17: =SUM(C17:T17) -> 59159.965
A19: Male
A20: 2001 | C20: 3123 | D20: 3384 | E20: 3859 | F20: 3785 | G20: 3266 | H20: 2965 | I20: 3511 | J20: 4341 | K20: 4323 | L20: 3850 | M20: 3622 | N20: 2580 | O20: 2082 | P20: 1803 | Q20: 1491 | R20: 1231 | S20: 776 | T20: 561 | U20: =SUM(C20:T20) -> 50553
A21: 2002 | C21: 3228 | D21: 3307 | E21: 3871 | F21: 3775 | G21: 3382 | H21: 2922 | I21: 3455 | J21: 4235 | K21: 4399 | L21: 3981 | M21: 3604 | N21: 2855 | O21: 2149 | P21: 1823 | Q21: 1491 | R21: 1222 | S21: 795 | T21: 550 | U21: =SUM(C21:T21) -> 51044
A22: 2003 | C22: 3301 | D22: 3292 | E22: 3839 | F22: 3913 | G22: 3437 | H22: 2936 | I22: 3512 | J22: 4090 | K22: 4458 | L22: 4088 | M22: 3629 | N22: 3048 | O22: 2245 | P22: 1829 | Q22: 1499 | R22: 1226 | S22: 823 | T22: 566 | U22: =SUM(C22:T22) -> 51731
A23: 2004 | C23: 3365 | D23: 3254 | E23: 3855 | F23: 3979 | G23: 3440 | H23: 3015 | I23: 3436 | J23: 3978 | K23: 4412 | L23: 4262 | M23: 3736 | N23: 3210 | O23: 2287 | P23: 1876 | Q23: 1512 | R23: 1225 | S23: 830 | T23: 588 | U23: =SUM(C23:T23) -> 52260
A24: 2005 | C24: 3372 | D24: 3257 | E24: 3768 | F24: 4003 | G24: 3509 | H24: 3033 | I24: 3364 | J24: 3829 | K24: 4444 | L24: 4322 | M24: 3781 | N24: 3402 | O24: 2399 | P24: 1883 | Q24: 1551 | R24: 1162 | S24: 868 | T24: 573 | U24: =SUM(C24:T24) -> 52520
A25: 2006 | C25: 3450 | D25: 3332 | E25: 3671 | F25: 3979 | G25: 3495 | H25: 3167 | I25: 3198 | J25: 3781 | K25: 4409 | L25: 4350 | M25: 3868 | N25: 3548 | O25: 2438 | P25: 1906 | Q25: 1587 | R25: 1208 | S25: 840 | T25: 601 | U25: =SUM(C25:T25) -> 52828
A26: 2007 | C26: 3506 | D26: 3306 | E26: 3558 | F26: 3968 | G26: 3399 | H26: 3214 | I26: 3089 | J26: 3772 | K26: 4266 | L26: 4348 | M26: 3964 | N26: 3492 | O26: 2667 | P26: 1937 | Q26: 1601 | R26: 1213 | S26: 846 | T26: 595 | U26: =SUM(C26:T26) -> 52741
A27: 2008 | C27: 3541 | D27: 3381 | E27: 3457 | F27: 3964 | G27: 3457 | H27: 3187 | I27: 3134 | J27: 3703 | K27: 4097 | L27: 4385 | M27: 4046 | N27: 3518 | O27: 2882 | P27: 1978 | Q27: 1595 | R27: 1246 | S27: 856 | T27: 626 | U27: =SUM(C27:T27) -> 53053
A28: 2009 | C28: 3519 | D28: 3370 | E28: 3412 | F28: 3864 | G28: 3408 | H28: 3138 | I28: 3211 | J28: 3516 | K28: 3926 | L28: 4313 | M28: 4120 | N28: 3599 | O28: 3011 | P28: 2046 | Q28: 1609 | R28: 1245 | S28: 867 | T28: 638 | U28: =SUM(C28:T28) -> 52812
A29: 2010 | C29: 3476 | D29: 3346 | E29: 3421 | F29: 3820 | G29: 3388 | H29: 3115 | I29: 3181 | J29: 3371 | K29: 3789 | L29: 4304 | M29: 4147 | N29: 3660 | O29: 3188 | P29: 2128 | Q29: 1628 | R29: 1245 | S29: 846 | T29: 655 | U29: =SUM(C29:T29) -> 52708
A30: 2015 | C30: 3461.1578 | D30: 3641.3084 | E30: 3447.6609 | F30: 3514.7041 | G30: 3932.7022 | H30: 3287.7344 | I30: 3199.1234 | J30: 3218.2618 | K30: 3382.1815 | L30: 3779.4289 | M30: 4256.9104 | N30: 4015.8861 | O30: 3459.6303 | P30: 2840.7131 | Q30: 1832.7279 | R30: 1330.418 | S30: 916.55413 | T30: 759.93145 | U30: =SUM(C30:T30) -> 54277.035
A31: 2020 | C31: 3458.6312 | D31: 3637.567 | E31: 3744.735 | F31: 3541.8063 | G31: 3654.1822 | H31: 3702.9379 | I31: 3375.3853 | J31: 3252.5278 | K31: 3253.176 | L31: 3394.1551 | M31: 3755.5185 | N31: 4109.5543 | O31: 3787.5353 | P31: 3083.6274 | Q31: 2439.103 | R31: 1501.4068 | S31: 990.55121 | T31: 846.13178 | U31: =SUM(C31:T31) -> 55528.532
... A33: 2030 | C33: 3522.5338 | D33: 3647.1726 | E33: 3752.0798 | F33: 3849.6265 | G33: 3975.2495 | H33: 3509.6506 | I33: 3531.1742 | J33: 3754.1037 | K33: 3483.473 | L33: 3344.4831 | M33: 3311.9746 | N33: 3300.5896 | O33: 3427.4037 | P33: 3439.1491 | Q33: 2892.748 | R33: 2164.6345 | S33: 1481.865 | T33: 1074.0614 | U33: =SUM(C33:T33) -> 57461.973
A35: Total
A36: 2001 | C36: =C20+C4 -> 6145 | D36: =D20+D4 -> 6636 | E36: =E20+E4 -> 7455 | F36: =F20+F4 -> 7557 | G36: =G20+G4 -> 6617 | H36: =H20+H4 -> 5989 | I36: =I20+I4 -> 7273 | J36: =J20+J4 -> 8576 | ... T36: =T20+T4 -> 2170 | U36: =SUM(C36:T36) -> 104260
A37: 2002 | C37: =C21+C5 -> 6277 | D37: =D21+D5 -> 6472 | E37: =E21+E5 -> 7521 | F37: =F21+F5 -> 7514 | G37: =G21+G5 -> 6911 | H37: =H21+H5 -> 5926 | I37: =I21+I5 -> 7083 | J37: =J21+J5 -> 8452 | ... T37: =T21+T5 -> 2117 | U37: =SUM(C37:T37) -> 105063
A38: 2003 | C38: =C22+C6 -> 6420 | D38: =D22+D6 -> 6407 | E38: =E22+E6 -> 7469 | F38: =F22+F6 -> 7734 | G38: =G22+G6 -> 6949 | H38: =H22+H6 -> 6019 | I38: =I22+I6 -> 7069 | J38: =J22+J6 -> 8294 | ... T38: =T22+T6 -> 2143 | U38: =SUM(C38:T38) -> 106140
A39: 2004 | C39: =C23+C7 -> 6541 | D39: =D23+D7 -> 6380 | E39: =E23+E7 -> 7461 | F39: =F23+F7 -> 7708 | G39: =G23+G7 -> 6923 | H39: =H23+H7 -> 6225 | I39: =I23+I7 -> 6919 | J39: =J23+J7 -> 8007 | ... T39: =T23+T7 -> 2122 | U39: =SUM(C39:T39) -> 106867
A40: 2005 | C40: =C24+C8 -> 6613 | D40: =D24+D8 -> 6440 | E40: =E24+E8 -> 7203 | F40: =F24+F8 -> 7745 | G40: =G24+G8 -> 7083 | H40: =H24+H8 -> 6357 | I40: =I24+I8 -> 6761 | J40: =J24+J8 -> 7718 | ... T40: =T24+T8 -> 2103 | U40: =SUM(C40:T40) -> 107352
A41: 2006 | C41: =C25+C9 -> 6840 | D41: =D25+D9 -> 6496 | E41: =E25+E9 -> 7045 | F41: =F25+F9 -> 7651 | G41: =G25+G9 -> 7120 | H41: =H25+H9 -> 6601 | I41: =I25+I9 -> 6531 | J41: =J25+J9 -> 7598 | ... T41: =T25+T9 -> 2112 | U41: =SUM(C41:T41) -> 107932
A42: 2007 | C42: =C26+C10 -> 6951 | D42: =D26+D10 -> 6453 | E42: =E26+E10 -> 6850 | F42: =F26+F10 -> 7607 | G42: =G26+G10 -> 6921 | H42: =H26+H10 -> 6710 | I42: =I26+I10 -> 6341 | J42: =J26+J10 -> 7456 | ... T42: =T26+T10 -> 2121 | U42: =SUM(C42:T42) -> 107739
A43: 2008 | C43: =C27+C11 -> 7039 | D43: =D27+D11 -> 6557 | E43: =E27+E11 -> 6598 | F43: =F27+F11 -> 7525 | G43: =G27+G11 -> 7104 | H43: =H27+H11 -> 6647 | I43: =I27+I11 -> 6417 | J43: =J27+J11 -> 7328 | ... T43: =T27+T11 -> 2156 | U43: =SUM(C43:T43) -> 108284
A44: 2009 | C44: =C28+C12 -> 6944 | D44: =D28+D12 -> 6574 | E44: =E28+E12 -> 6562 | F44: =F28+F12 -> 7398 | G44: =G28+G12 -> 6949 | H44: =H28+H12 -> 6511 | I44: =I28+I12 -> 6518 | J44: =J28+J12 -> 7033 | ... T44: =T28+T12 -> 2126 | U44: =SUM(C44:T44) -> 107830
...

Sheet 03
A1: 3 | B1: AROOSTOOK
A2: Age | C2: 0-4 | D2: 5-9 | E2: 10-14 | F2: 15-19 | G2: 20-24 | H2: 25-29 | I2: 30-34 | J2: 35-39 | K2: 40-44 | L2: 45-49 | M2: 50-54 | N2: 55-59 | O2: 60-64 | P2: 65-69 | Q2: 70-74 | R2: 75-79 | S2: 80-84 | T2: 85+ | U2: Total
A3: Female
A4: 2001 | C4: 1795 | D4: 2146 | E4: 2412 | F4: 2487 | G4: 1859 | H4: 1801 | I4: 2120 | J4: 2683 | K4: 2867 | L4: 3060 | M4: 2708 | N4: 2220 | O4: 1984 | P4: 1751 | Q4: 1876 | R4: 1428 | S4: 1114 | T4: 1084 | U4: =SUM(C4:T4) -> 37395
A5: 2002 | C5: 1751 | D5: 2071 | E5: 2419 | F5: 2472 | G5: 1928 | H5: 1694 | I5: 2102 | J5: 2553 | K5: 2826 | L5: 3091 | M5: 2750 | N5: 2334 | O5: 2033 | P5: 1744 | Q5: 1865 | R5: 1465 | S5: 1114 | T5: 1105 | U5: =SUM(C5:T5) -> 37317
A6: 2003 | C6: 1754 | D6: 2024 | E6: 2350 | F6: 2490 | G6: 1952 | H6: 1686 | I6: 2024 | J6: 2473 | K6: 2806 | L6: 3038 | M6: 2858 | N6: 2418 | O6: 2072 | P6: 1807 | Q6: 1732 | R6: 1490 | S6: 1098 | T6: 1117 | U6: =SUM(C6:T6) -> 37189
A7: 2004 | C7: 1733 | D7: 2012 | E7: 2355 | F7: 2456 | G7: 1931 | H7: 1676 | I7: 2030 | J7: 2328 | K7: 2856 | L7: 2944 | M7: 2973 | N7: 2542 | O7: 2037 | P7: 1892 | Q7: 1640 | R7: 1574 | S7: 1096 | T7: 1074 | U7: =SUM(C7:T7) -> 37149
A8: 2005 | C8: 1773 | D8: 1994 | E8: 2345 | F8: 2429 | G8: 1957 | H8: 1690 | I8: 1948 | J8: 2233 | K8: 2839 | L8: 2897 | M8: 2997 | N8: 2616 | O8: 2129 | P8: 1910 | Q8: 1589 | R8: 1642 | S8: 1063 | T8: 1078 | U8: =SUM(C8:T8) -> 37129
A9: 2006 | C9: 1702 | D9: 1956 | E9: 2271 | F9: 2423 | G9: 1924 | H9: 1651 | I9: 1893 | J9: 2211 | K9: 2761 | L9: 2871 | M9: 3026 | N9: 2738 | O9: 2216 | P9: 1904 | Q9: 1594 | R9: 1712 | S9: 1080 | T9: 1089 | U9: =SUM(C9:T9) -> 37022
A10: 2007 | C10: 1674 | D10: 1912 | E10: 2236 | F10: 2426 | G10: 1869 | H10: 1690 | I10: 1805 | J10: 2173 | K10: 2680 | L10: 2872 | M10: 3043 | N10: 2780 | O10: 2352 | P10: 1954 | Q10: 1563 | R10: 1700 | S10: 1106 | T10: 1115 | U10: =SUM(C10:T10) -> 36950
A11: 2008 | C11: 1662 | D11: 1868 | E11: 2183 | F11: 2396 | G11: 1858 | H11: 1666 | I11: 1777 | J11: 2138 | K11: 2582 | L11: 2851 | M11: 2998 | N11: 2880 | O11: 2408 | P11: 2014 | Q11: 1639 | R11: 1572 | S11: 1161 | T11: 1164 | U11: =SUM(C11:T11) -> 36817
A12: 2009 | C12: 1716 | D12: 1864 | E12: 2131 | F12: 2373 | G12: 1850 | H12: 1673 | I12: 1772 | J12: 2085 | K12: 2394 | L12: 2880 | M12: 2896 | N12: 2956 | O12: 2524 | P12: 2000 | Q12: 1690 | R12: 1504 | S12: 1215 | T12: 1177 | U12: =SUM(C12:T12) -> 36700
A13: 2010 | C13: 1676 | D13: 1820 | E13: 2081 | F13: 2298 | G13: 1825 | H13: 1687 | I13: 1765 | J13: 2012 | K13: 2312 | L13: 2797 | M13: 2907 | N13: 2986 | O13: 2563 | P13: 2070 | Q13: 1701 | R13: 1448 | S13: 1243 | T13: 1209 | U13: =SUM(C13:T13) -> 36400
A14: 2015 | C14: 1691.3932 | D14: 1625.2151 | E14: 1794.3173 | F14: 2049.5108 | G14: 2226.0788 | H14: 1808.4019 | I14: 1650.8297 | J14: 1700.3883 | K14: 1994.6837 | L14: 2254.1548 | M14: 2803.3517 | N14: 2867.2611 | O14: 2893.4555 | P14: 2446.9836 | Q14: 1927.8563 | R14: 1512.8311 | S14: 1174.3308 | T14: 1330.0203 | U14: =SUM(C14:T14) -> 35751.064
A15: 2020 | C15: 1759.234 | D15: 1641.3177 | E15: 1610.047 | F15: 1777.0832 | G15: 2031.722 | H15: 2165.7061 | I15: 1764.3123 | J15: 1593.4015 | K15: 1698.1715 | L15: 1956.3624 | M15: 2271.1792 | N15: 2762.4754 | O15: 2781.1769 | P15: 2761.2636 | Q15: 2276.5377 | R15: 1718.1832 | S15: 1229.1876 | T15: 1347.3009 | U15: =SUM(C15:T15) -> 35144.662
... A17: 2030 | C17: 1683.7085 | D17: 1706.6167 | E17: 1691.5045 | F17: 1622.1921 | G17: 1679.0344 | H17: 1811.4184 | I17: 1945.0029 | J17: 2007.7977 | K17: 1703.8864 | L17: 1591.1733 | M17: 1720.2187 | N17: 1971.9787 | O17: 2187.8323 | P17: 2557.0002 | Q17: 2475.4833 | R17: 2286.9231 | S17: 1649.635 | T17: 1518.8536 | U17: =SUM(C17:T17) -> 33810.26
A19: Male
A20: 2001 | C20: 1814 | D20: 2095 | E20: 2561 | F20: 2884 | G20: 1931 | H20: 1575 | I20: 2062 | J20: 2632 | K20: 2899 | L20: 2923 | M20: 2843 | N20: 2229 | O20: 1765 | P20: 1662 | Q20: 1537 | R20: 1031 | S20: 655 | T20: 469 | U20: =SUM(C20:T20) -> 35567
A21: 2002 | C21: 1849 | D21: 2051 | E21: 2481 | F21: 2919 | G21: 1991 | H21: 1530 | I21: 1997 | J21: 2539 | K21: 2870 | L21: 2926 | M21: 2816 | N21: 2402 | O21: 1853 | P21: 1634 | Q21: 1582 | R21: 1059 | S21: 649 | T21: 477 | U21: =SUM(C21:T21) -> 35625
A22: 2003 | C22: 1839 | D22: 2002 | E22: 2464 | F22: 2926 | G22: 2090 | H22: 1557 | I22: 1949 | J22: 2439 | K22: 2836 | L22: 2980 | M22: 2852 | N22: 2522 | O22: 1845 | P22: 1697 | Q22: 1513 | R22: 1099 | S22: 679 | T22: 466 | U22: =SUM(C22:T22) -> 35755
A23: 2004 | C23: 1867 | D23: 1967 | E23: 2453 | F23: 2854 | G23: 2120 | H23: 1550 | I23: 1897 | J23: 2346 | K23: 2791 | L23: 3016 | M23: 2932 | N23: 2591 | O23: 1960 | P23: 1737 | Q23: 1451 | R23: 1136 | S23: 685 | T23: 457 | U23: =SUM(C23:T23) -> 35810
A24: 2005 | C24: 1867 | D24: 1999 | E24: 2367 | F24: 2745 | G24: 2127 | H24: 1615 | I24: 1818 | J24: 2292 | K24: 2755 | L24: 2965 | M24: 2900 | N24: 2741 | O24: 2053 | P24: 1696 | Q24: 1486 | R24: 1163 | S24: 694 | T24: 469 | U24: =SUM(C24:T24) -> 35752
A25: 2006 | C25: 1920 | D25: 1966 | E25: 2292 | F25: 2685 | G25: 2129 | H25: 1608 | I25: 1739 | J25: 2225 | K25: 2732 | L25: 2966 | M25: 2947 | N25: 2803 | O25: 2193 | P25: 1722 | Q25: 1484 | R25: 1227 | S25: 691 | T25: 476 | U25: =SUM(C25:T25) -> 35805
A26: 2007 | C26: 1901 | D26: 1989 | E26: 2244 | F26: 2638 | G26: 2073 | H26: 1635 | I26: 1715 | J26: 2121 | K26: 2658 | L26: 2993 | M26: 2976 | N26: 2787 | O26: 2366 | P26: 1753 | Q26: 1458 | R26: 1282 | S26: 722 | T26: 450 | U26: =SUM(C26:T26) -> 35761
A27: 2008 | C27: 1903 | D27: 1973 | E27: 2178 | F27: 2594 | G27: 2054 | H27: 1632 | I27: 1718 | J27: 2085 | K27: 2546 | L27: 2933 | M27: 3003 | N27: 2822 | O27: 2482 | P27: 1786 | Q27: 1536 | R27: 1213 | S27: 786 | T27: 481 | U27: =SUM(C27:T27) -> 35725
A28: 2009 | C28: 1853 | D28: 1980 | E28: 2112 | F28: 2570 | G28: 2042 | H28: 1666 | I28: 1729 | J28: 1976 | K28: 2410 | L28: 2854 | M28: 3024 | N28: 2873 | O28: 2542 | P28: 1910 | Q28: 1540 | R28: 1157 | S28: 826 | T28: 494 | U28: =SUM(C28:T28) -> 35558
A29: 2010 | C29: 1797 | D29: 1936 | E29: 2103 | F29: 2470 | G29: 1989 | H29: 1699 | I29: 1760 | J29: 1864 | K29: 2364 | L29: 2796 | M29: 2996 | N29: 2854 | O29: 2664 | P29: 1979 | Q29: 1506 | R29: 1183 | S29: 847 | T29: 516 | U29: =SUM(C29:T29) -> 35323
A30: 2015 | C30: 1810.7501 | D30: 1768.6871 | E30: 1931.2999 | F30: 2095.9036 | G30: 2487.1924 | H30: 2020.0879 | I30: 1698.1048 | J30: 1704.6676 | K30: 1858.9223 | L30: 2319.2171 | M30: 2786.5928 | N30: 2932.9127 | O30: 2738.6713 | P30: 2493.705 | Q30: 1783.3333 | R30: 1242.1402 | S30: 853.82143 | T30: 605.86621 | U30: =SUM(C30:T30) -> 35131.876
A31: 2020 | C31: 1883.3782 | D31: 1783.703 | E31: 1772.396 | F31: 1932.8692 | G31: 2177.9776 | H31: 2471.2551 | I31: 1996.476 | J31: 1647.2931 | K31: 1710.9424 | L31: 1844.6065 | M31: 2323.9974 | N31: 2728.5883 | O31: 2813.6937 | P31: 2570.7153 | Q31: 2239.9492 | R31: 1474.182 | S31: 899.46312 | T31: 642.47298 | U31: =SUM(C31:T31) -> 34913.959
... A33: 2030 | C33: 1802.5231 | D33: 1854.7419 | E33: 1859.5204 | F33: 1801.6143 | G33: 1934.8848 | H33: 2090.8472 | I33: 2166.1161 | J33: 2321.2987 | K33: 1934.4901 | L33: 1667.3558 | M33: 1747.796 | N33: 1855.2967 | O33: 2203.1103 | P33: 2458.6477 | Q33: 2377.4045 | R33: 1912.8535 | S33: 1338.052 | T33: 785.94956 | U33: =SUM(C33:T33) -> 34112.503
A35: Total
A36: 2001 | C36: =C20+C4 -> 3609 | D36: =D20+D4 -> 4241 | E36: =E20+E4 -> 4973 | F36: =F20+F4 -> 5371 | G36: =G20+G4 -> 3790 | H36: =H20+H4 -> 3376 | I36: =I20+I4 -> 4182 | J36: =J20+J4 -> 5315 | ... T36: =T20+T4 -> 1553 | U36: =SUM(C36:T36) -> 72962
A37: 2002 | C37: =C21+C5 -> 3600 | D37: =D21+D5 -> 4122 | E37: =E21+E5 -> 4900 | F37: =F21+F5 -> 5391 | G37: =G21+G5 -> 3919 | H37: =H21+H5 -> 3224 | I37: =I21+I5 -> 4099 | J37: =J21+J5 -> 5092 | ... T37: =T21+T5 -> 1582 | U37: =SUM(C37:T37) -> 72942
A38: 2003 | C38: =C22+C6 -> 3593 | D38: =D22+D6 -> 4026 | E38: =E22+E6 -> 4814 | F38: =F22+F6 -> 5416 | G38: =G22+G6 -> 4042 | H38: =H22+H6 -> 3243 | I38: =I22+I6 -> 3973 | J38: =J22+J6 -> 4912 | ... T38: =T22+T6 -> 1583 | U38: =SUM(C38:T38) -> 72944
A39: 2004 | C39: =C23+C7 -> 3600 | D39: =D23+D7 -> 3979 | E39: =E23+E7 -> 4808 | F39: =F23+F7 -> 5310 | G39: =G23+G7 -> 4051 | H39: =H23+H7 -> 3226 | I39: =I23+I7 -> 3927 | J39: =J23+J7 -> 4674 | ... T39: =T23+T7 -> 1531 | U39: =SUM(C39:T39) -> 72959
A40: 2005 | C40: =C24+C8 -> 3640 | D40: =D24+D8 -> 3993 | E40: =E24+E8 -> 4712 | F40: =F24+F8 -> 5174 | G40: =G24+G8 -> 4084 | H40: =H24+H8 -> 3305 | I40: =I24+I8 -> 3766 | J40: =J24+J8 -> 4525 | ... T40: =T24+T8 -> 1547 | U40: =SUM(C40:T40) -> 72881
A41: 2006 | C41: =C25+C9 -> 3622 | D41: =D25+D9 -> 3922 | E41: =E25+E9 -> 4563 | F41: =F25+F9 -> 5108 | G41: =G25+G9 -> 4053 | H41: =H25+H9 -> 3259 | I41: =I25+I9 -> 3632 | J41: =J25+J9 -> 4436 | ... T41: =T25+T9 -> 1565 | U41: =SUM(C41:T41) -> 72827
A42: 2007 | C42: =C26+C10 -> 3575 | D42: =D26+D10 -> 3901 | E42: =E26+E10 -> 4480 | F42: =F26+F10 -> 5064 | G42: =G26+G10 -> 3942 | H42: =H26+H10 -> 3325 | I42: =I26+I10 -> 3520 | J42: =J26+J10 -> 4294 | ... T42: =T26+T10 -> 1565 | U42: =SUM(C42:T42) -> 72711
A43: 2008 | C43: =C27+C11 -> 3565 | D43: =D27+D11 -> 3841 | E43: =E27+E11 -> 4361 | F43: =F27+F11 -> 4990 | G43: =G27+G11 -> 3912 | H43: =H27+H11 -> 3298 | I43: =I27+I11 -> 3495 | J43: =J27+J11 -> 4223 | ... T43: =T27+T11 -> 1645 | U43: =SUM(C43:T43) -> 72542
A44: 2009 | C44: =C28+C12 -> 3569 | D44: =D28+D12 -> 3844 | E44: =E28+E12 -> 4243 | F44: =F28+F12 -> 4943 | G44: =G28+G12 -> 3892 | H44: =H28+H12 -> 3339 | I44: =I28+I12 -> 3501 | J44: =J28+J12 -> 4061 | ... T44: =T28+T12 -> 1671 | U44: =SUM(C44:T44) -> 72258
...

Sheet 05
A1: 5 | B1: CUMBERLAND
A2: Age | C2: 0-4 | D2: 5-9 | E2: 10-14 | F2: 15-19 | G2: 20-24 | H2: 25-29 | I2: 30-34 | J2: 35-39 | K2: 40-44 | L2: 45-49 | M2: 50-54 | N2: 55-59 | O2: 60-64 | P2: 65-69 | Q2: 70-74 | R2: 75-79 | S2: 80-84 | T2: 85+ | U2: Total
A3: Female
A4: 2001 | C4: 7452 | D4: 8152 | E4: 9111 | F4: 8791 | G4: 7830 | H4: 8015 | I4: 10067 | J4: 11482 | K4: 12309 | L4: 11143 | M4: 9964 | N4: 7127 | O4: 5379 | P4: 4774 | Q4: 4852 | R4: 4535 | S4: 3564 | T4: 3673 | U4: =SUM(C4:T4) -> 138220
A5: 2002 | C5: 7351 | D5: 8093 | E5: 9159 | F5: 8961 | G5: 8032 | H5: 7994 | I5: 9985 | J5: 11174 | K5: 12278 | L5: 11404 | M5: 10078 | N5: 7809 | O5: 5592 | P5: 4759 | Q5: 4745 | R5: 4568 | S5: 3700 | T5: 3674 | U5: =SUM(C5:T5) -> 139356
A6: 2003 | C6: 7468 | D6: 8073 | E6: 9060 | F6: 9152 | G6: 8283 | H6: 8068 | I6: 9659 | J6: 10976 | K6: 12270 | L6: 11692 | M6: 10381 | N6: 8126 | O6: 5966 | P6: 4864 | Q6: 4627 | R6: 4543 | S6: 3757 | T6: 3700 | U6: =SUM(C6:T6) -> 140665
A7: 2004 | C7: 7507 | D7: 8073 | E7: 8934 | F7: 9333 | G7: 8483 | H7: 8163 | I7: 9322 | J7: 10628 | K7: 12053 | L7: 11876 | M7: 10564 | N7: 8644 | O7: 6357 | P7: 4938 | Q7: 4552 | R7: 4502 | S7: 3865 | T7: 3826 | U7: =SUM(C7:T7) -> 141620
A8: 2005 | C8: 7480 | D8: 7967 | E8: 8862 | F8: 9408 | G8: 8698 | H8: 8231 | I8: 8782 | J8: 10545 | K8: 11775 | L8: 12038 | M8: 10770 | N8: 9126 | O8: 6635 | P8: 5037 | Q8: 4567 | R8: 4391 | S8: 3893 | T8: 3928 | U8: =SUM(C8:T8) -> 142133
A9: 2006 | C9: 7335 | D9: 7977 | E9: 8588 | F9: 9470 | G9: 8763 | H9: 8276 | I9: 8368 | J9: 10434 | K9: 11468 | L9: 12201 | M9: 11028 | N9: 9642 | O9: 6924 | P9: 5120 | Q9: 4485 | R9: 4381 | S9: 3776 | T9: 4086 | U9: =SUM(C9:T9) -> 142322
A10: 2007 | C10: 7297 | D10: 7915 | E10: 8553 | F10: 9402 | G10: 8727 | H10: 8587 | I10: 8154 | J10: 10311 | K10: 11114 | L10: 12175 | M10: 11267 | N10: 9853 | O10: 7543 | P10: 5338 | Q10: 4537 | R10: 4335 | S10: 3831 | T10: 4253 | U10: =SUM(C10:T10) -> 143192
A11: 2008 | C11: 7341 | D11: 7988 | E11: 8415 | F11: 9364 | G11: 8753 | H11: 8619 | I11: 8292 | J11: 9934 | K11: 10918 | L11: 12187 | M11: 11479 | N11: 10213 | O11: 7937 | P11: 5753 | Q11: 4638 | R11: 4209 | S11: 3853 | T11: 4396 | U11: =SUM(C11:T11) -> 144289
A12: 2009 | C12: 7236 | D12: 7952 | E12: 8470 | F12: 9206 | G12: 8846 | H12: 8767 | I12: 8294 | J12: 9683 | K12: 10619 | L12: 12027 | M12: 11676 | N12: 10581 | O12: 8454 | P12: 6165 | Q12: 4632 | R12: 4146 | S12: 3780 | T12: 4475 | U12: =SUM(C12:T12) -> 145009
A13: 2010 | C13: 7147 | D13: 7791 | E13: 8397 | F13: 9009 | G13: 8819 | H13: 8703 | I13: 8365 | J13: 9207 | K13: 10517 | L13: 11735 | M13: 11820 | N13: 10844 | O13: 8937 | P13: 6420 | Q13: 4714 | R13: 4140 | S13: 3722 | T13: 4551 | U13: =SUM(C13:T13) -> 144838
A14: 2015 | C14: 6986.552 | D14: 7162.5676 | E14: 7765.1936 | F14: 8360.6093 | G14: 8917.7971 | H14: 8755.423 | I14: 8904.0852 | J14: 8299.1805 | K14: 9200.2001 | L14: 10394.923 | M14: 11559.287 | N14: 11578.741 | O14: 10712.146 | P14: 8561.6349 | Q14: 6007.2319 | R14: 4166.8454 | S14: 3354.8379 | T14: 4716.9802 | U14: =SUM(C14:T14) -> 145404.24
A15: 2020 | C15: 6980.2274 | D15: 7041.8863 | E15: 7179.3633 | F15: 7770.29 | G15: 8444.7417 | H15: 8796.8707 | I15: 8988.6369 | J15: 8821.3814 | K15: 8391.9595 | L15: 9157.2857 | M15: 10278.749 | N15: 11304.774 | O15: 11413.281 | P15: 10242.98 | Q15: 7958.5612 | R15: 5311.9222 | S15: 3397.5855 | T15: 4585.5962 | U15: =SUM(C15:T15) -> 146066.09
... A17: 2030 | C17: 6823.2208 | D17: 7029.7497 | E17: 7099.8762 | F17: 7141.6525 | G17: 7604.4558 | H17: 8255.054 | I17: 8869.5626 | J17: 8905.2059 | K17: 9019.9103 | L17: 8942.1124 | M17: 8462.7882 | N17: 8990.888 | O17: 9955.8333 | P17: 10612.926 | Q17: 10092.668 | R17: 8342.9384 | S17: 5685.9518 | T17: 5187.5264 | U17: =SUM(C17:T17) -> 147022.32
A19: Male
A20: 2001 | C20: 7896 | D20: 8902 | E20: 9728 | F20: 9406 | G20: 7958 | H20: 7847 | I20: 9808 | J20: 10996 | K20: 11443 | L20: 10561 | M20: 9779 | N20: 6667 | O20: 4935 | P20: 4195 | Q20: 3656 | R20: 3005 | S20: 2019 | T20: 1370 | U20: =SUM(C20:T20) -> 130171
A21: 2002 | C21: 7741 | D21: 8738 | E21: 9823 | F21: 9505 | G21: 8182 | H21: 7822 | I21: 9677 | J21: 10755 | K21: 11494 | L21: 10807 | M21: 9730 | N21: 7437 | O21: 5142 | P21: 4168 | Q21: 3649 | R21: 3048 | S21: 2043 | T21: 1416 | U21: =SUM(C21:T21) -> 131177
A22: 2003 | C22: 7832 | D22: 8551 | E22: 9837 | F22: 9680 | G22: 8484 | H22: 7856 | I22: 9541 | J22: 10411 | K22: 11390 | L22: 11044 | M22: 9845 | N22: 7907 | O22: 5503 | P22: 4221 | Q22: 3625 | R22: 3079 | S22: 2104 | T22: 1466 | U22: =SUM(C22:T22) -> 132376
A23: 2004 | C23: 7909 | D23: 8440 | E23: 9535 | F23: 9955 | G23: 8726 | H23: 7851 | I23: 9196 | J23: 10132 | K23: 11424 | L23: 11064 | M23: 10125 | N23: 8355 | O23: 5783 | P23: 4362 | Q23: 3593 | R23: 3168 | S23: 2138 | T23: 1544 | U23: =SUM(C23:T23) -> 133300
A24: 2005 | C24: 7947 | D24: 8267 | E24: 9415 | F24: 9970 | G24: 9018 | H24: 8005 | I24: 8802 | J24: 10011 | K24: 11399 | L24: 11104 | M24: 10322 | N24: 8817 | O24: 6156 | P24: 4406 | Q24: 3583 | R24: 3147 | S24: 2162 | T24: 1611 | U24: =SUM(C24:T24) -> 134142
A25: 2006 | C25: 7882 | D25: 8283 | E25: 9246 | F25: 10060 | G25: 9001 | H25: 8283 | I25: 8272 | J25: 9934 | K25: 11205 | L25: 11262 | M25: 10433 | N25: 9359 | O25: 6401 | P25: 4502 | Q25: 3633 | R25: 3163 | S25: 2157 | T25: 1686 | U25: =SUM(C25:T25) -> 134762
A26: 2007 | C26: 7924 | D26: 8355 | E26: 9094 | F26: 9971 | G26: 8890 | H26: 8573 | I26: 8271 | J26: 9757 | K26: 10815 | L26: 11272 | M26: 10768 | N26: 9270 | O26: 7089 | P26: 4742 | Q26: 3695 | R26: 3107 | S26: 2261 | T26: 1735 | U26: =SUM(C26:T26) -> 135589
A27: 2008 | C27: 7805 | D27: 8437 | E27: 8957 | F27: 9874 | G27: 8893 | H27: 8794 | I27: 8279 | J27: 9561 | K27: 10470 | L27: 11322 | M27: 10980 | N27: 9431 | O27: 7574 | P27: 5059 | Q27: 3773 | R27: 3095 | S27: 2254 | T27: 1834 | U27: =SUM(C27:T27) -> 136392
A28: 2009 | C28: 7710 | D28: 8448 | E28: 8911 | F28: 9668 | G28: 8935 | H28: 8831 | I28: 8308 | J28: 9369 | K28: 10236 | L28: 11361 | M28: 11028 | N28: 9719 | O28: 8025 | P28: 5372 | Q28: 3868 | R28: 2993 | S28: 2309 | T28: 1869 | U28: =SUM(C28:T28) -> 136960
A29: 2010 | C29: 7542 | D29: 8362 | E29: 8722 | F29: 9486 | G29: 8733 | H29: 8825 | I29: 8342 | J29: 8857 | K29: 10071 | L29: 11316 | M29: 11016 | N29: 9918 | O29: 8531 | P29: 5700 | Q29: 3906 | R29: 3016 | S29: 2259 | T29: 1946 | U29: =SUM(C29:T29) -> 136548
A30: 2015 | C30: 7414.2525 | D30: 7610.5768 | E30: 8359.0815 | F30: 8699.6336 | G30: 9454.3954 | H30: 8761.4661 | I30: 9143.4533 | J30: 8336.96 | K30: 8888.3438 | L30: 9938.4618 | M30: 11082.36 | N30: 10672.161 | O30: 9679.2613 | P30: 8010.7105 | Q30: 5198.0127 | R30: 3273.2284 | S30: 2230.6137 | T30: 2115.933 | U30: =SUM(C30:T30) -> 138868.91
A31: 2020 | C31: 7407.5407 | D31: 7521.1714 | E31: 7655.1579 | F31: 8367.5914 | G31: 8863.2369 | H31: 9278.8227 | I31: 9133.168 | J31: 9094.1122 | K31: 8454.3548 | L31: 8840.6233 | M31: 9781.6491 | N31: 10709.942 | O31: 10386.476 | P31: 9084.7696 | Q31: 7227.425 | R31: 4351.88 | S31: 2437.2375 | T31: 2188.4283 | U31: =SUM(C31:T31) -> 140783.59
... A33: 2030 | C33: 7240.9225 | D33: 7509.0512 | E33: 7608.4243 | F33: 7657.5583 | G33: 8153.0279 | H33: 8835.8951 | I33: 9329.7092 | J33: 9430.0745 | K33: 9221.4872 | L33: 9190.7554 | M33: 8468.5846 | N33: 8557.9012 | O33: 9252.3777 | P33: 9725.6659 | Q33: 8761.6161 | R33: 6801.4597 | S33: 4423.3872 | T33: 2911.1184 | U33: =SUM(C33:T33) -> 143079.02
A35: Total
A36: 2001 | C36: =C20+C4 -> 15348 | D36: =D20+D4 -> 17054 | E36: =E20+E4 -> 18839 | F36: =F20+F4 -> 18197 | G36: =G20+G4 -> 15788 | H36: =H20+H4 -> 15862 | I36: =I20+I4 -> 19875 | J36: =J20+J4 -> 22478 | ... T36: =T20+T4 -> 5043 | U36: =SUM(C36:T36) -> 268391
A37: 2002 | C37: =C21+C5 -> 15092 | D37: =D21+D5 -> 16831 | E37: =E21+E5 -> 18982 | F37: =F21+F5 -> 18466 | G37: =G21+G5 -> 16214 | H37: =H21+H5 -> 15816 | I37: =I21+I5 -> 19662 | J37: =J21+J5 -> 21929 | ... T37: =T21+T5 -> 5090 | U37: =SUM(C37:T37) -> 270533
A38: 2003 | C38: =C22+C6 -> 15300 | D38: =D22+D6 -> 16624 | E38: =E22+E6 -> 18897 | F38: =F22+F6 -> 18832 | G38: =G22+G6 -> 16767 | H38: =H22+H6 -> 15924 | I38: =I22+I6 -> 19200 | J38: =J22+J6 -> 21387 | ... T38: =T22+T6 -> 5166 | U38: =SUM(C38:T38) -> 273041
A39: 2004 | C39: =C23+C7 -> 15416 | D39: =D23+D7 -> 16513 | E39: =E23+E7 -> 18469 | F39: =F23+F7 -> 19288 | G39: =G23+G7 -> 17209 | H39: =H23+H7 -> 16014 | I39: =I23+I7 -> 18518 | J39: =J23+J7 -> 20760 | ... T39: =T23+T7 -> 5370 | U39: =SUM(C39:T39) -> 274920
A40: 2005 | C40: =C24+C8 -> 15427 | D40: =D24+D8 -> 16234 | E40: =E24+E8 -> 18277 | F40: =F24+F8 -> 19378 | G40: =G24+G8 -> 17716 | H40: =H24+H8 -> 16236 | I40: =I24+I8 -> 17584 | J40: =J24+J8 -> 20556 | ... T40: =T24+T8 -> 5539 | U40: =SUM(C40:T40) -> 276275
A41: 2006 | C41: =C25+C9 -> 15217 | D41: =D25+D9 -> 16260 | E41: =E25+E9 -> 17834 | F41: =F25+F9 -> 19530 | G41: =G25+G9 -> 17764 | H41: =H25+H9 -> 16559 | I41: =I25+I9 -> 16640 | J41: =J25+J9 -> 20368 | ... T41: =T25+T9 -> 5772 | U41: =SUM(C41:T41) -> 277084
A42: 2007 | C42: =C26+C10 -> 15221 | D42: =D26+D10 -> 16270 | E42: =E26+E10 -> 17647 | F42: =F26+F10 -> 19373 | G42: =G26+G10 -> 17617 | H42: =H26+H10 -> 17160 | I42: =I26+I10 -> 16425 | J42: =J26+J10 -> 20068 | ... T42: =T26+T10 -> 5988 | U42: =SUM(C42:T42) -> 278781
A43: 2008 | C43: =C27+C11 -> 15146 | D43: =D27+D11 -> 16425 | E43: =E27+E11 -> 17372 | F43: =F27+F11 -> 19238 | G43: =G27+G11 -> 17646 | H43: =H27+H11 -> 17413 | I43: =I27+I11 -> 16571 | J43: =J27+J11 -> 19495 | ... T43: =T27+T11 -> 6230 | U43: =SUM(C43:T43) -> 280681
A44: 2009 | C44: =C28+C12 -> 14946 | D44: =D28+D12 -> 16400 | E44: =E28+E12 -> 17381 | F44: =F28+F12 -> 18874 | G44: =G28+G12 -> 17781 | H44: =H28+H12 -> 17598 | I44: =I28+I12 -> 16602 | J44: =J28+J12 -> 19052 | ... T44: =T28+T12 -> 6344 | U44: =SUM(C44:T44) -> 281969
...

Sheet 07
A1: 7 | B1: FRANKLIN
A2: Age | C2: 0-4 | D2: 5-9 | E2: 10-14 | F2: 15-19 | G2: 20-24 | H2: 25-29 | I2: 30-34 | J2: 35-39 | K2: 40-44 | L2: 45-49 | M2: 50-54 | N2: 55-59 | O2: 60-64 | P2: 65-69 | Q2: 70-74 | R2: 75-79 | S2: 80-84 | T2: 85+ | U2: Total
A3: Female
A4: 2001 | C4: 719 | D4: 888 | E4: 1037 | F4: 1309 | G4: 1198 | H4: 712 | I4: 850 | J4: 1077 | K4: 1191 | L4: 1208 | M4: 1096 | N4: 849 | O4: 669 | P4: 645 | Q4: 577 | R4: 518 | S4: 354 | T4: 414 | U4: =SUM(C4:T4) -> 15311
A5: 2002 | C5: 715 | D5: 856 | E5: 1020 | F5: 1372 | G5: 1237 | H5: 687 | I5: 855 | J5: 1055 | K5: 1218 | L5: 1189 | M5: 1128 | N5: 947 | O5: 687 | P5: 630 | Q5: 598 | R5: 521 | S5: 394 | T5: 400 | U5: =SUM(C5:T5) -> 15509
A6: 2003 | C6: 663 | D6: 815 | E6: 1020 | F6: 1376 | G6: 1182 | H6: 732 | I6: 784 | J6: 1066 | K6: 1169 | L6: 1215 | M6: 1178 | N6: 1007 | O6: 739 | P6: 592 | Q6: 601 | R6: 497 | S6: 375 | T6: 410 | U6: =SUM(C6:T6) -> 15421
A7: 2004 | C7: 652 | D7: 817 | E7: 978 | F7: 1378 | G7: 1195 | H7: 793 | I7: 763 | J7: 976 | K7: 1181 | L7: 1267 | M7: 1189 | N7: 1022 | O7: 833 | P7: 551 | Q7: 588 | R7: 471 | S7: 373 | T7: 421 | U7: =SUM(C7:T7) -> 15448
A8: 2005 | C8: 674 | D8: 785 | E8: 931 | F8: 1363 | G8: 1204 | H8: 819 | I8: 727 | J8: 936 | K8: 1171 | L8: 1281 | M8: 1223 | N8: 1055 | O8: 852 | P8: 594 | Q8: 608 | R8: 482 | S8: 369 | T8: 398 | U8: =SUM(C8:T8) -> 15472
A9: 2006 | C9: 701 | D9: 794 | E9: 934 | F9: 1351 | G9: 1206 | H9: 836 | I9: 696 | J9: 929 | K9: 1136 | L9: 1295 | M9: 1259 | N9: 1138 | O9: 837 | P9: 667 | Q9: 618 | R9: 441 | S9: 392 | T9: 396 | U9: =SUM(C9:T9) -> 15626
A10: 2007 | C10: 718 | D10: 782 | E10: 933 | F10: 1279 | G10: 1229 | H10: 809 | I10: 671 | J10: 911 | K10: 1093 | L10: 1294 | M10: 1273 | N10: 1152 | O10: 912 | P10: 694 | Q10: 611 | R10: 461 | S10: 394 | T10: 382 | U10: =SUM(C10:T10) -> 15598
A11: 2008 | C11: 722 | D11: 780 | E11: 877 | F11: 1329 | G11: 1212 | H11: 764 | I11: 734 | J11: 835 | K11: 1109 | L11: 1250 | M11: 1283 | N11: 1182 | O11: 966 | P11: 737 | Q11: 592 | R11: 476 | S11: 404 | T11: 395 | U11: =SUM(C11:T11) -> 15647
A12: 2009 | C12: 735 | D12: 758 | E12: 876 | F12: 1298 | G12: 1244 | H12: 760 | I12: 746 | J12: 824 | K12: 1017 | L12: 1235 | M12: 1336 | N12: 1199 | O12: 1000 | P12: 831 | Q12: 591 | R12: 481 | S12: 378 | T12: 409 | U12: =SUM(C12:T12) -> 15718
A13: 2010 | C13: 710 | D13: 762 | E13: 831 | F13: 1245 | G13: 1254 | H13: 761 | I13: 750 | J13: 790 | K13: 985 | L13: 1227 | M13: 1337 | N13: 1235 | O13: 1041 | P13: 851 | Q13: 625 | R13: 498 | S13: 375 | T13: 408 | U13: =SUM(C13:T13) -> 15685
A14: 2015 | C14: 723.38533 | D14: 715.99101 | E14: 765.1818 | F14: 1161.641 | G14: 1266.694 | H14: 785.77148 | I14: 743.98792 | J14: 767.51476 | K14: 799.55776 | L14: 998.09931 | M14: 1175.7241 | N14: 1317.3884 | O14: 1216.3861 | P14: 979.94054 | Q14: 774.8281 | R14: 530.28171 | S14: 428.65847 | T14: 441.0227 | U14: =SUM(C14:T14) -> 15592.054
A15: 2020 | C15: 718.42015 | D15: 730.7653 | E15: 721.82598 | F15: 1099.1213 | G15: 1206.837 | H15: 791.23092 | I15: 767.65508 | J15: 763.72356 | K15: 780.47665 | L15: 818.62937 | M15: 958.85705 | N15: 1160.1943 | O15: 1294.9434 | P15: 1144.8379 | Q15: 891.81469 | R15: 657.65585 | S15: 463.33031 | T15: 488.38306 | U15: =SUM(C15:T15) -> 15458.702
... A17: 2030 | C17: 695.54101 | D17: 721.61617 | E17: 735.90051 | F17: 1074.6963 | G17: 1137.162 | H17: 729.91085 | I17: 745.02904 | J17: 790.15373 | K17: 802.9161 | L17: 803.6549 | M17: 776.39578 | N17: 790.52757 | O17: 944.52149 | P17: 1075.5833 | Q17: 1106.6519 | R17: 882.83274 | S17: 664.09837 | T17: 640.21953 | U17: =SUM(C17:T17) -> 15117.411
A19: Male
A20: 2001 | C20: 790 | D20: 907 | E20: 1142 | F20: 1205 | G20: 950 | H20: 711 | I20: 757 | J20: 1055 | K20: 1228 | L20: 1103 | M20: 1073 | N20: 876 | O20: 705 | P20: 577 | Q20: 500 | R20: 381 | S20: 228 | T20: 132 | U20: =SUM(C20:T20) -> 14320
A21: 2002 | C21: 819 | D21: 832 | E21: 1172 | F21: 1243 | G21: 988 | H21: 694 | I21: 777 | J21: 1011 | K21: 1188 | L21: 1144 | M21: 1075 | N21: 944 | O21: 742 | P21: 605 | Q21: 504 | R21: 396 | S21: 250 | T21: 126 | U21: =SUM(C21:T21) -> 14510
A22: 2003 | C22: 811 | D22: 823 | E22: 1146 | F22: 1271 | G22: 1011 | H22: 719 | I22: 736 | J22: 967 | K22: 1168 | L22: 1160 | M22: 1111 | N22: 983 | O22: 815 | P22: 583 | Q22: 515 | R22: 387 | S22: 267 | T22: 132 | U22: =SUM(C22:T22) -> 14605
A23: 2004 | C23: 770 | D23: 845 | E23: 1073 | F23: 1279 | G23: 1046 | H23: 767 | I23: 704 | J23: 923 | K23: 1130 | L23: 1195 | M23: 1181 | N23: 1004 | O23: 856 | P23: 589 | Q23: 504 | R23: 386 | S23: 255 | T23: 141 | U23: =SUM(C23:T23) -> 14648
A24: 2005 | C24: 774 | D24: 837 | E24: 1029 | F24: 1264 | G24: 1080 | H24: 752 | I24: 688 | J24: 897 | K24: 1089 | L24: 1264 | M24: 1177 | N24: 1048 | O24: 885 | P24: 634 | Q24: 537 | R24: 398 | S24: 246 | T24: 155 | U24: =SUM(C24:T24) -> 14754
A25: 2006 | C25: 809 | D25: 858 | E25: 984 | F25: 1259 | G25: 1078 | H25: 788 | I25: 692 | J25: 851 | K25: 1067 | L25: 1270 | M25: 1180 | N25: 1145 | O25: 898 | P25: 678 | Q25: 515 | R25: 404 | S25: 268 | T25: 158 | U25: =SUM(C25:T25) -> 14902
A26: 2007 | C26: 809 | D26: 885 | E26: 940 | F26: 1240 | G26: 1080 | H26: 774 | I26: 672 | J26: 874 | K26: 1000 | L26: 1260 | M26: 1234 | N26: 1126 | O26: 958 | P26: 740 | Q26: 555 | R26: 396 | S26: 288 | T26: 167 | U26: =SUM(C26:T26) -> 14998
A27: 2008 | C27: 813 | D27: 859 | E27: 938 | F27: 1208 | G27: 1081 | H27: 758 | I27: 678 | J27: 856 | K27: 957 | L27: 1265 | M27: 1233 | N27: 1171 | O27: 975 | P27: 786 | Q27: 546 | R27: 429 | S27: 280 | T27: 172 | U27: =SUM(C27:T27) -> 15005
A28: 2009 | C28: 818 | D28: 812 | E28: 960 | F28: 1151 | G28: 1114 | H28: 764 | I28: 679 | J28: 809 | K28: 905 | L28: 1238 | M28: 1257 | N28: 1221 | O28: 1020 | P28: 819 | Q28: 580 | R28: 435 | S28: 288 | T28: 191 | U28: =SUM(C28:T28) -> 15061
A29: 2010 | C29: 790 | D29: 803 | E29: 949 | F29: 1110 | G29: 1119 | H29: 748 | I29: 688 | J29: 782 | K29: 881 | L29: 1178 | M29: 1305 | N29: 1191 | O29: 1056 | P29: 846 | Q29: 616 | R29: 470 | S29: 299 | T29: 195 | U29: =SUM(C29:T29) -> 15026
A30: 2015 | C30: 820.19623 | D30: 781.1633 | E30: 801.1735 | F30: 1114.2029 | G30: 1096.2442 | H30: 844.46401 | I30: 711.78044 | J30: 696.34662 | K30: 782.53954 | L30: 882.92316 | M30: 1109.8374 | N30: 1258.6931 | O30: 1148.9757 | P30: 974.23531 | Q30: 751.03955 | R30: 504.2371 | S30: 373.56587 | T30: 256.96501 | U30: =SUM(C30:T30) -> 14908.583
A31: 2020 | C31: 814.56656 | D31: 810.78442 | E31: 781.12106 | F31: 972.10977 | G31: 1109.9958 | H31: 820.77021 | I31: 796.66209 | J31: 720.77634 | K31: 702.68398 | L31: 789.3031 | M31: 834.95455 | N31: 1073.3129 | O31: 1212.5909 | P31: 1060.1012 | Q31: 864.50698 | R31: 615.16165 | S31: 407.34527 | T31: 317.19711 | U31: =SUM(C31:T31) -> 14703.944
... A33: 2030 | C33: 788.62549 | D33: 799.14809 | E33: 808.47484 | F33: 983.70879 | G33: 992.51736 | H33: 764.97159 | I33: 798.54513 | J33: 780.74419 | K33: 807.62264 | L33: 741.38556 | M33: 680.8537 | N33: 734.04778 | O33: 796.47104 | P33: 957.75386 | Q33: 992.69159 | R33: 771.19003 | S33: 577.14537 | T33: 443.50322 | U33: =SUM(C33:T33) -> 14219.4
A35: Total
A36: 2001 | C36: =C20+C4 -> 1509 | D36: =D20+D4 -> 1795 | E36: =E20+E4 -> 2179 | F36: =F20+F4 -> 2514 | G36: =G20+G4 -> 2148 | H36: =H20+H4 -> 1423 | I36: =I20+I4 -> 1607 | J36: =J20+J4 -> 2132 | ... T36: =T20+T4 -> 546 | U36: =SUM(C36:T36) -> 29631
A37: 2002 | C37: =C21+C5 -> 1534 | D37: =D21+D5 -> 1688 | E37: =E21+E5 -> 2192 | F37: =F21+F5 -> 2615 | G37: =G21+G5 -> 2225 | H37: =H21+H5 -> 1381 | I37: =I21+I5 -> 1632 | J37: =J21+J5 -> 2066 | ... T37: =T21+T5 -> 526 | U37: =SUM(C37:T37) -> 30019
A38: 2003 | C38: =C22+C6 -> 1474 | D38: =D22+D6 -> 1638 | E38: =E22+E6 -> 2166 | F38: =F22+F6 -> 2647 | G38: =G22+G6 -> 2193 | H38: =H22+H6 -> 1451 | I38: =I22+I6 -> 1520 | J38: =J22+J6 -> 2033 | ... T38: =T22+T6 -> 542 | U38: =SUM(C38:T38) -> 30026
A39: 2004 | C39: =C23+C7 -> 1422 | D39: =D23+D7 -> 1662 | E39: =E23+E7 -> 2051 | F39: =F23+F7 -> 2657 | G39: =G23+G7 -> 2241 | H39: =H23+H7 -> 1560 | I39: =I23+I7 -> 1467 | J39: =J23+J7 -> 1899 | ... T39: =T23+T7 -> 562 | U39: =SUM(C39:T39) -> 30096
A40: 2005 | C40: =C24+C8 -> 1448 | D40: =D24+D8 -> 1622 | E40: =E24+E8 -> 1960 | F40: =F24+F8 -> 2627 | G40: =G24+G8 -> 2284 | H40: =H24+H8 -> 1571 | I40: =I24+I8 -> 1415 | J40: =J24+J8 -> 1833 | ... T40: =T24+T8 -> 553 | U40: =SUM(C40:T40) -> 30226
A41: 2006 | C41: =C25+C9 -> 1510 | D41: =D25+D9 -> 1652 | E41: =E25+E9 -> 1918 | F41: =F25+F9 -> 2610 | G41: =G25+G9 -> 2284 | H41: =H25+H9 -> 1624 | I41: =I25+I9 -> 1388 | J41: =J25+J9 -> 1780 | ... T41: =T25+T9 -> 554 | U41: =SUM(C41:T41) -> 30528
A42: 2007 | C42: =C26+C10 -> 1527 | D42: =D26+D10 -> 1667 | E42: =E26+E10 -> 1873 | F42: =F26+F10 -> 2519 | G42: =G26+G10 -> 2309 | H42: =H26+H10 -> 1583 | I42: =I26+I10 -> 1343 | J42: =J26+J10 -> 1785 | ... T42: =T26+T10 -> 549 | U42: =SUM(C42:T42) -> 30596
A43: 2008 | C43: =C27+C11 -> 1535 | D43: =D27+D11 -> 1639 | E43: =E27+E11 -> 1815 | F43: =F27+F11 -> 2537 | G43: =G27+G11 -> 2293 | H43: =H27+H11 -> 1522 | I43: =I27+I11 -> 1412 | J43: =J27+J11 -> 1691 | ... T43: =T27+T11 -> 567 | U43: =SUM(C43:T43) -> 30652
A44: 2009 | C44: =C28+C12 -> 1553 | D44: =D28+D12 -> 1570 | E44: =E28+E12 -> 1836 | F44: =F28+F12 -> 2449 | G44: =G28+G12 -> 2358 | H44: =H28+H12 -> 1524 | I44: =I28+I12 -> 1425 | J44: =J28+J12 -> 1633 | ... T44: =T28+T12 -> 600 | U44: =SUM(C44:T44) -> 30779
...

Sheet 09
A1: 9 | B1: HANCOCK
A2: Age | C2: 0-4 | D2: 5-9 | E2: 10-14 | F2: 15-19 | G2: 20-24 | H2: 25-29 | I2: 30-34 | J2: 35-39 | K2: 40-44 | L2: 45-49 | M2: 50-54 | N2: 55-59 | O2: 60-64 | P2: 65-69 | Q2: 70-74 | R2: 75-79 | S2: 80-84 | T2: 85+ | U2: Total
A3: Female
A4: 2001 | C4: 1168 | D4: 1441 | E4: 1688 | F4: 1726 | G4: 1214 | H4: 1193 | I4: 1655 | J4: 2011 | K4: 2282 | L4: 2251 | M4: 2228 | N4: 1697 | O4: 1296 | P4: 1163 | Q4: 1163 | R4: 948 | S4: 705 | T4: 785 | U4: =SUM(C4:T4) -> 26614
A5: 2002 | C5: 1138 | D5: 1376 | E5: 1632 | F5: 1725 | G5: 1251 | H5: 1174 | I5: 1609 | J5: 1900 | K5: 2286 | L5: 2291 | M5: 2272 | N5: 1839 | O5: 1399 | P5: 1170 | Q5: 1168 | R5: 942 | S5: 716 | T5: 768 | U5: =SUM(C5:T5) -> 26656
A6: 2003 | C6: 1171 | D6: 1346 | E6: 1630 | F6: 1703 | G6: 1339 | H6: 1204 | I6: 1537 | J6: 1885 | K6: 2303 | L6: 2316 | M6: 2286 | N6: 1990 | O6: 1496 | P6: 1183 | Q6: 1146 | R6: 969 | S6: 737 | T6: 784 | U6: =SUM(C6:T6) -> 27025
A7: 2004 | C7: 1201 | D7: 1318 | E7: 1580 | F7: 1697 | G7: 1345 | H7: 1279 | I7: 1509 | J7: 1867 | K7: 2249 | L7: 2299 | M7: 2376 | N7: 2075 | O7: 1616 | P7: 1225 | Q7: 1135 | R7: 981 | S7: 723 | T7: 795 | U7: =SUM(C7:T7) -> 27270
A8: 2005 | C8: 1211 | D8: 1302 | E8: 1540 | F8: 1674 | G8: 1384 | H8: 1290 | I8: 1432 | J8: 1806 | K8: 2170 | L8: 2340 | M8: 2382 | N8: 2217 | O8: 1696 | P8: 1235 | Q8: 1134 | R8: 991 | S8: 713 | T8: 825 | U8: =SUM(C8:T8) -> 27342
A9: 2006 | C9: 1256 | D9: 1266 | E9: 1508 | F9: 1640 | G9: 1388 | H9: 1256 | I9: 1381 | J9: 1802 | K9: 2139 | L9: 2334 | M9: 2392 | N9: 2345 | O9: 1768 | P9: 1280 | Q9: 1163 | R9: 1002 | S9: 739 | T9: 836 | U9: =SUM(C9:T9) -> 27495
A10: 2007 | C10: 1294 | D10: 1250 | E10: 1484 | F10: 1596 | G10: 1404 | H10: 1280 | I10: 1327 | J10: 1765 | K10: 2019 | L10: 2352 | M10: 2448 | N10: 2384 | O10: 1924 | P10: 1360 | Q10: 1151 | R10: 1006 | S10: 760 | T10: 859 | U10: =SUM(C10:T10) -> 27663
A11: 2008 | C11: 1285 | D11: 1282 | E11: 1468 | F11: 1570 | G11: 1407 | H11: 1288 | I11: 1330 | J11: 1663 | K11: 1946 | L11: 2331 | M11: 2458 | N11: 2382 | O11: 2069 | P11: 1479 | Q11: 1149 | R11: 1008 | S11: 792 | T11: 864 | U11: =SUM(C11:T11) -> 27771
A12: 2009 | C12: 1253 | D12: 1304 | E12: 1395 | F12: 1551 | G12: 1434 | H12: 1278 | I12: 1353 | J12: 1607 | K12: 1899 | L12: 2285 | M12: 2437 | N12: 2445 | O12: 2177 | P12: 1597 | Q12: 1168 | R12: 979 | S12: 817 | T12: 836 | U12: =SUM(C12:T12) -> 27815
A13: 2010 | C13: 1304 | D13: 1291 | E13: 1357 | F13: 1478 | G13: 1381 | H13: 1307 | I13: 1358 | J13: 1547 | K13: 1796 | L13: 2225 | M13: 2433 | N13: 2459 | O13: 2291 | P13: 1672 | Q13: 1182 | R13: 971 | S13: 823 | T13: 872 | U13: =SUM(C13:T13) -> 27747
A14: 2015 | C14: 1161.7542 | D14: 1247.6635 | E14: 1317.1656 | F14: 1382.6692 | G14: 1449.1003 | H14: 1304.482 | I14: 1291.5144 | J14: 1299.3882 | K14: 1510.3618 | L14: 1831.3037 | M14: 2168.178 | N14: 2395.093 | O14: 2453.497 | P14: 2141.998 | Q14: 1557.529 | R14: 1042.7798 | S14: 796.64178 | T14: 945.9081 | U14: =SUM(C14:T14) -> 27297.027
A15: 2020 | C15: 1142.3603 | D15: 1121.4467 | E15: 1277.3927 | F15: 1346.143 | G15: 1379.1191 | H15: 1356.6625 | I15: 1292.8294 | J15: 1241.5156 | K15: 1285.182 | L15: 1556.9216 | M15: 1789.9505 | N15: 2136.5326 | O15: 2393.1177 | P15: 2295.6964 | Q15: 1992.7677 | R15: 1373.5817 | S15: 859.07973 | T15: 966.99258 | U15: =SUM(C15:T15) -> 26807.292
... A17: 2030 | C17: 1122.5183 | D17: 1100.0631 | E17: 1142.6004 | F17: 1193.9828 | G17: 1335.6434 | H17: 1299.3068 | I17: 1303.8143 | J17: 1282.5188 | K17: 1239.6264 | L17: 1302.5159 | M17: 1329.09 | N17: 1522.7588 | O17: 1786.309 | P17: 2004.3529 | Q17: 2086.705 | R17: 1881.9439 | S17: 1438.9398 | T17: 1221.4536 | U17: =SUM(C17:T17) -> 25594.143
A19: Male
A20: 2001 | C20: 1319 | D20: 1478 | E20: 1972 | F20: 1926 | G20: 1381 | H20: 1254 | I20: 1517 | J20: 1880 | K20: 2122 | L20: 2122 | M20: 2174 | N20: 1600 | O20: 1172 | P20: 1093 | Q20: 981 | R20: 722 | S20: 483 | T20: 299 | U20: =SUM(C20:T20) -> 25495
A21: 2002 | C21: 1283 | D21: 1418 | E21: 1957 | F21: 1954 | G21: 1482 | H21: 1180 | I21: 1500 | J21: 1772 | K21: 2092 | L21: 2187 | M21: 2140 | N21: 1834 | O21: 1238 | P21: 1111 | Q21: 995 | R21: 730 | S21: 489 | T21: 309 | U21: =SUM(C21:T21) -> 25671
A22: 2003 | C22: 1316 | D22: 1381 | E22: 1876 | F22: 2011 | G22: 1533 | H22: 1160 | I22: 1495 | J22: 1732 | K22: 2095 | L22: 2200 | M22: 2143 | N22: 1977 | O22: 1373 | P22: 1107 | Q22: 1008 | R22: 760 | S22: 521 | T22: 317 | U22: =SUM(C22:T22) -> 26005
A23: 2004 | C23: 1270 | D23: 1396 | E23: 1813 | F23: 2020 | G23: 1661 | H23: 1172 | I23: 1471 | J23: 1674 | K23: 2083 | L23: 2249 | M23: 2214 | N23: 2034 | O23: 1501 | P23: 1145 | Q23: 1010 | R23: 793 | S23: 480 | T23: 357 | U23: =SUM(C23:T23) -> 26343
A24: 2005 | C24: 1278 | D24: 1351 | E24: 1681 | F24: 2060 | G24: 1682 | H24: 1211 | I24: 1402 | J24: 1621 | K24: 2032 | L24: 2231 | M24: 2228 | N24: 2191 | O24: 1593 | P24: 1166 | Q24: 1000 | R24: 822 | S24: 461 | T24: 393 | U24: =SUM(C24:T24) -> 26403
A25: 2006 | C25: 1294 | D25: 1389 | E25: 1564 | F25: 2055 | G25: 1684 | H25: 1196 | I25: 1360 | J25: 1616 | K25: 1990 | L25: 2241 | M25: 2259 | N25: 2304 | O25: 1676 | P25: 1193 | Q25: 998 | R25: 831 | S25: 479 | T25: 385 | U25: =SUM(C25:T25) -> 26514
A26: 2007 | C26: 1328 | D26: 1386 | E26: 1487 | F26: 2025 | G26: 1670 | H26: 1236 | I26: 1301 | J26: 1593 | K26: 1875 | L26: 2222 | M26: 2302 | N26: 2274 | O26: 1903 | P26: 1270 | Q26: 1026 | R26: 824 | S26: 514 | T26: 401 | U26: =SUM(C26:T26) -> 26637
A27: 2008 | C27: 1301 | D27: 1382 | E27: 1450 | F27: 1938 | G27: 1635 | H27: 1264 | I27: 1282 | J27: 1567 | K27: 1793 | L27: 2179 | M27: 2320 | N27: 2261 | O27: 2038 | P27: 1401 | Q27: 1022 | R27: 818 | S27: 536 | T27: 413 | U27: =SUM(C27:T27) -> 26600
A28: 2009 | C28: 1308 | D28: 1374 | E28: 1426 | F28: 1881 | G28: 1650 | H28: 1290 | I28: 1294 | J28: 1507 | K28: 1711 | L28: 2175 | M28: 2342 | N28: 2337 | O28: 2058 | P28: 1518 | Q28: 1039 | R28: 826 | S28: 565 | T28: 383 | U28: =SUM(C28:T28) -> 26684
A29: 2010 | C29: 1283 | D29: 1354 | E29: 1423 | F29: 1790 | G29: 1602 | H29: 1344 | I29: 1291 | J29: 1452 | K29: 1654 | L29: 2093 | M29: 2313 | N29: 2345 | O29: 2184 | P29: 1601 | Q29: 1053 | R29: 828 | S29: 586 | T29: 417 | U29: =SUM(C29:T29) -> 26613
A30: 2015 | C30: 1232.7454 | D30: 1192.2862 | E30: 1370.8403 | F30: 1438.8905 | G30: 1700.3406 | H30: 1451.9149 | I30: 1279.908 | J30: 1196.81 | K30: 1389.6205 | L30: 1674.592 | M30: 1997.0302 | N30: 2233.4511 | O30: 2300.3915 | P30: 1958.0143 | Q30: 1406.5995 | R30: 881.96858 | S30: 611.05902 | T30: 492.30429 | U30: =SUM(C30:T30) -> 25808.767
A31: 2020 | C31: 1212.1664 | D31: 1150.8187 | E31: 1216.5239 | F31: 1390.7253 | G31: 1414.5558 | H31: 1525.4929 | I31: 1374.4089 | J31: 1189.8111 | K31: 1164.2258 | L31: 1425.0648 | M31: 1604.3995 | N31: 1933.0647 | O31: 2196.8737 | P31: 2065.2492 | Q31: 1718.6155 | R31: 1177.5689 | S31: 655.28452 | T31: 537.93014 | U31: =SUM(C31:T31) -> 24952.78
... A33: 2030 | C33: 1191.1119 | D33: 1128.8753 | E33: 1164.6721 | F33: 1209.3139 | G33: 1268.3027 | H33: 1290.758 | I33: 1258.2759 | J33: 1323.9745 | K33: 1240.3374 | L33: 1220.2061 | M33: 1181.3775 | N33: 1347.3744 | O33: 1558.8165 | P33: 1720.3053 | Q33: 1736.8423 | R33: 1518.4806 | S33: 1063.4981 | T33: 728.12264 | U33: =SUM(C33:T33) -> 23150.645
A35: Total
A36: 2001 | C36: =C20+C4 -> 2487 | D36: =D20+D4 -> 2919 | E36: =E20+E4 -> 3660 | F36: =F20+F4 -> 3652 | G36: =G20+G4 -> 2595 | H36: =H20+H4 -> 2447 | I36: =I20+I4 -> 3172 | J36: =J20+J4 -> 3891 | ... T36: =T20+T4 -> 1084 | U36: =SUM(C36:T36) -> 52109
A37: 2002 | C37: =C21+C5 -> 2421 | D37: =D21+D5 -> 2794 | E37: =E21+E5 -> 3589 | F37: =F21+F5 -> 3679 | G37: =G21+G5 -> 2733 | H37: =H21+H5 -> 2354 | I37: =I21+I5 -> 3109 | J37: =J21+J5 -> 3672 | ... T37: =T21+T5 -> 1077 | U37: =SUM(C37:T37) -> 52327
A38: 2003 | C38: =C22+C6 -> 2487 | D38: =D22+D6 -> 2727 | E38: =E22+E6 -> 3506 | F38: =F22+F6 -> 3714 | G38: =G22+G6 -> 2872 | H38: =H22+H6 -> 2364 | I38: =I22+I6 -> 3032 | J38: =J22+J6 -> 3617 | ... T38: =T22+T6 -> 1101 | U38: =SUM(C38:T38) -> 53030
A39: 2004 | C39: =C23+C7 -> 2471 | D39: =D23+D7 -> 2714 | E39: =E23+E7 -> 3393 | F39: =F23+F7 -> 3717 | G39: =G23+G7 -> 3006 | H39: =H23+H7 -> 2451 | I39: =I23+I7 -> 2980 | J39: =J23+J7 -> 3541 | ... T39: =T23+T7 -> 1152 | U39: =SUM(C39:T39) -> 53613
A40: 2005 | C40: =C24+C8 -> 2489 | D40: =D24+D8 -> 2653 | E40: =E24+E8 -> 3221 | F40: =F24+F8 -> 3734 | G40: =G24+G8 -> 3066 | H40: =H24+H8 -> 2501 | I40: =I24+I8 -> 2834 | J40: =J24+J8 -> 3427 | ... T40: =T24+T8 -> 1218 | U40: =SUM(C40:T40) -> 53745
A41: 2006 | C41: =C25+C9 -> 2550 | D41: =D25+D9 -> 2655 | E41: =E25+E9 -> 3072 | F41: =F25+F9 -> 3695 | G41: =G25+G9 -> 3072 | H41: =H25+H9 -> 2452 | I41: =I25+I9 -> 2741 | J41: =J25+J9 -> 3418 | ... T41: =T25+T9 -> 1221 | U41: =SUM(C41:T41) -> 54009
A42: 2007 | C42: =C26+C10 -> 2622 | D42: =D26+D10 -> 2636 | E42: =E26+E10 -> 2971 | F42: =F26+F10 -> 3621 | G42: =G26+G10 -> 3074 | H42: =H26+H10 -> 2516 | I42: =I26+I10 -> 2628 | J42: =J26+J10 -> 3358 | ... T42: =T26+T10 -> 1260 | U42: =SUM(C42:T42) -> 54300
A43: 2008 | C43: =C27+C11 -> 2586 | D43: =D27+D11 -> 2664 | E43: =E27+E11 -> 2918 | F43: =F27+F11 -> 3508 | G43: =G27+G11 -> 3042 | H43: =H27+H11 -> 2552 | I43: =I27+I11 -> 2612 | J43: =J27+J11 -> 3230 | ... T43: =T27+T11 -> 1277 | U43: =SUM(C43:T43) -> 54371
A44: 2009 | C44: =C28+C12 -> 2561 | D44: =D28+D12 -> 2678 | E44: =E28+E12 -> 2821 | F44: =F28+F12 -> 3432 | G44: =G28+G12 -> 3084 | H44: =H28+H12 -> 2568 | I44: =I28+I12 -> 2647 | J44: =J28+J12 -> 3114 | ... T44: =T28+T12 -> 1219 | U44: =SUM(C44:T44) -> 54499
...

Sheet 11
A1: 11 | B1: KENNEBEC
A2: Age | C2: 0-4 | D2: 5-9 | E2: 10-14 | F2: 15-19 | G2: 20-24 | H2: 25-29 | I2: 30-34 | J2: 35-39 | K2: 40-44 | L2: 45-49 | M2: 50-54 | N2: 55-59 | O2: 60-64 | P2: 65-69 | Q2: 70-74 | R2: 75-79 | S2: 80-84 | T2: 85+ | U2: Total
A3: Female
A4: 2001 | C4: 3247 | D4: 3565 | E4: 4184 | F4: 4379 | G4: 3339 | H4: 3096 | I4: 3906 | J4: 4734 | K4: 5288 | L4: 4953 | M4: 4460 | N4: 3290 | O4: 2610 | P4: 2379 | Q4: 2325 | R4: 2060 | S4: 1496 | T4: 1509 | U4: =SUM(C4:T4) -> 60820
A5: 2002 | C5: 3243 | D5: 3472 | E5: 4187 | F5: 4327 | G5: 3484 | H5: 3050 | I5: 3784 | J5: 4556 | K5: 5299 | L5: 5068 | M5: 4498 | N5: 3546 | O5: 2694 | P5: 2390 | Q5: 2277 | R5: 2117 | S5: 1507 | T5: 1533 | U5: =SUM(C5:T5) -> 61032
A6: 2003 | C6: 3253 | D6: 3485 | E6: 4096 | F6: 4363 | G6: 3607 | H6: 3052 | I6: 3695 | J6: 4459 | K6: 5271 | L6: 5225 | M6: 4578 | N6: 3760 | O6: 2816 | P6: 2449 | Q6: 2180 | R6: 2170 | S6: 1508 | T6: 1520 | U6: =SUM(C6:T6) -> 61487
A7: 2004 | C7: 3269 | D7: 3540 | E7: 4040 | F7: 4291 | G7: 3680 | H7: 3135 | I7: 3556 | J7: 4400 | K7: 5244 | L7: 5252 | M7: 4722 | N7: 3946 | O7: 3008 | P7: 2464 | Q7: 2149 | R7: 2147 | S7: 1532 | T7: 1496 | U7: =SUM(C7:T7) -> 61871
A8: 2005 | C8: 3223 | D8: 3524 | E8: 3950 | F8: 4366 | G8: 3710 | H8: 3167 | I8: 3488 | J8: 4278 | K8: 5112 | L8: 5341 | M8: 4892 | N8: 4165 | O8: 3177 | P8: 2484 | Q8: 2136 | R8: 2076 | S8: 1611 | T8: 1520 | U8: =SUM(C8:T8) -> 62220
A9: 2006 | C9: 3172 | D9: 3590 | E9: 3776 | F9: 4309 | G9: 3764 | H9: 3178 | I9: 3489 | J9: 4204 | K9: 4912 | L9: 5392 | M9: 5033 | N9: 4451 | O9: 3253 | P9: 2571 | Q9: 2129 | R9: 2052 | S9: 1628 | T9: 1586 | U9: =SUM(C9:T9) -> 62489
A10: 2007 | C10: 3178 | D10: 3545 | E10: 3711 | F10: 4213 | G10: 3684 | H10: 3289 | I10: 3393 | J10: 4095 | K10: 4757 | L10: 5388 | M10: 5130 | N10: 4557 | O10: 3483 | P10: 2647 | Q10: 2164 | R10: 2013 | S10: 1664 | T10: 1612 | U10: =SUM(C10:T10) -> 62523
A11: 2008 | C11: 3151 | D11: 3512 | E11: 3641 | F11: 4148 | G11: 3693 | H11: 3376 | I11: 3345 | J11: 3957 | K11: 4593 | L11: 5336 | M11: 5293 | N11: 4644 | O11: 3700 | P11: 2746 | Q11: 2252 | R11: 1910 | S11: 1700 | T11: 1686 | U11: =SUM(C11:T11) -> 62683
A12: 2009 | C12: 3076 | D12: 3445 | E12: 3651 | F12: 4053 | G12: 3596 | H12: 3352 | I12: 3373 | J12: 3808 | K12: 4475 | L12: 5233 | M12: 5338 | N12: 4749 | O12: 3940 | P12: 2898 | Q12: 2237 | R12: 1900 | S12: 1714 | T12: 1729 | U12: =SUM(C12:T12) -> 62567
A13: 2010 | C13: 3062 | D13: 3381 | E13: 3564 | F13: 3928 | G13: 3611 | H13: 3419 | I13: 3361 | J13: 3732 | K13: 4357 | L13: 5118 | M13: 5380 | N13: 4869 | O13: 4156 | P13: 3021 | Q13: 2267 | R13: 1914 | S13: 1678 | T13: 1788 | U13: =SUM(C13:T13) -> 62606
A14: 2015 | C14: 3031.7591 | D14: 3101.2343 | E14: 3424.7986 | F14: 3602.4625 | G14: 3723.5822 | H14: 3452.6853 | I14: 3452.2327 | J14: 3494.2343 | K14: 3711.1184 | L14: 4391.383 | M14: 5063.1345 | N14: 5263.7871 | O14: 4700.2992 | P14: 3974.5828 | Q14: 2724.9744 | R14: 1976.1086 | S14: 1482.6116 | T14: 1812.4471 | U14: =SUM(C14:T14) -> 62383.436
A15: 2020 | C15: 3021.0096 | D15: 3080.0528 | E15: 3162.2661 | F15: 3475.4456 | G15: 3453.0832 | H15: 3541.0259 | I15: 3491.9931 | J15: 3596.5492 | K15: 3501.5636 | L15: 3773.0589 | M15: 4365.7821 | N15: 4951.8633 | O15: 5072.6888 | P15: 4493.1878 | Q15: 3575.3083 | R15: 2379.2131 | S15: 1535.5488 | T15: 1714.169 | U15: =SUM(C15:T15) -> 62183.809
... A17: 2030 | C17: 2894.608 | D17: 3035.1915 | E17: 3149.0521 | F17: 3224.2066 | G17: 3151.9636 | H17: 3264.5364 | I17: 3400.6014 | J17: 3703.5076 | K17: 3658.1542 | L17: 3699.5232 | M17: 3618.8969 | N17: 3729.3173 | O17: 4140.444 | P17: 4553.1954 | Q17: 4350.833 | R17: 3515.6113 | S17: 2414.5723 | T17: 1895.0565 | U17: =SUM(C17:T17) -> 61399.271
A19: Male
A20: 2001 | C20: 3218 | D20: 3839 | E20: 4444 | F20: 4545 | G20: 3304 | H20: 2893 | I20: 3713 | J20: 4416 | K20: 4957 | L20: 4687 | M20: 4443 | N20: 3352 | O20: 2414 | P20: 2170 | Q20: 1812 | R20: 1500 | S20: 895 | T20: 602 | U20: =SUM(C20:T20) -> 57204
A21: 2002 | C21: 3211 | D21: 3726 | E21: 4401 | F21: 4598 | G21: 3452 | H21: 2808 | I21: 3662 | J21: 4295 | K21: 4869 | L21: 4863 | M21: 4456 | N21: 3633 | O21: 2559 | P21: 2165 | Q21: 1850 | R21: 1461 | S21: 932 | T21: 638 | U21: =SUM(C21:T21) -> 57579
A22: 2003 | C22: 3209 | D22: 3636 | E22: 4368 | F22: 4611 | G22: 3614 | H22: 2833 | I22: 3580 | J22: 4265 | K22: 4747 | L22: 5045 | M22: 4466 | N22: 3797 | O22: 2764 | P22: 2177 | Q22: 1832 | R22: 1462 | S22: 991 | T22: 654 | U22: =SUM(C22:T22) -> 58051
A23: 2004 | C23: 3284 | D23: 3629 | E23: 4386 | F23: 4547 | G23: 3648 | H23: 2919 | I23: 3470 | J23: 4155 | K23: 4706 | L23: 5062 | M23: 4546 | N23: 3973 | O23: 2958 | P23: 2207 | Q23: 1809 | R23: 1473 | S23: 1014 | T23: 646 | U23: =SUM(C23:T23) -> 58432
A24: 2005 | C24: 3281 | D24: 3595 | E24: 4242 | F24: 4568 | G24: 3697 | H24: 2913 | I24: 3379 | J24: 4190 | K24: 4602 | L24: 5073 | M24: 4654 | N24: 4241 | O24: 3087 | P24: 2235 | Q24: 1825 | R24: 1461 | S24: 1025 | T24: 669 | U24: =SUM(C24:T24) -> 58737
A25: 2006 | C25: 3270 | D25: 3540 | E25: 4152 | F25: 4517 | G25: 3708 | H25: 3003 | I25: 3233 | J25: 4105 | K25: 4556 | L25: 5118 | M25: 4768 | N25: 4451 | O25: 3233 | P25: 2219 | Q25: 1851 | R25: 1493 | S25: 1067 | T25: 735 | U25: =SUM(C25:T25) -> 59019
A26: 2007 | C26: 3264 | D26: 3591 | E26: 3935 | F26: 4487 | G26: 3723 | H26: 3090 | I26: 3137 | J26: 3981 | K26: 4470 | L26: 5027 | M26: 4923 | N26: 4495 | O26: 3524 | P26: 2332 | Q26: 1862 | R26: 1543 | S26: 1042 | T26: 792 | U26: =SUM(C26:T26) -> 59218
A27: 2008 | C27: 3334 | D27: 3529 | E27: 3834 | F27: 4385 | G27: 3701 | H27: 3178 | I27: 3159 | J27: 3813 | K27: 4400 | L27: 4983 | M27: 5084 | N27: 4509 | O27: 3699 | P27: 2547 | Q27: 1874 | R27: 1549 | S27: 1037 | T27: 849 | U27: =SUM(C27:T27) -> 59464
A28: 2009 | C28: 3272 | D28: 3506 | E28: 3789 | F28: 4319 | G28: 3647 | H28: 3144 | I28: 3261 | J28: 3720 | K28: 4195 | L28: 4941 | M28: 5085 | N28: 4591 | O28: 3914 | P28: 2715 | Q28: 1915 | R28: 1561 | S28: 1082 | T28: 860 | U28: =SUM(C28:T28) -> 59517
A29: 2010 | C29: 3249 | D29: 3443 | E29: 3725 | F29: 4136 | G29: 3597 | H29: 3248 | I29: 3307 | J29: 3532 | K29: 4155 | L29: 4822 | M29: 5141 | N29: 4686 | O29: 4133 | P29: 2809 | Q29: 1968 | R29: 1597 | S29: 1078 | T29: 899 | U29: =SUM(C29:T29) -> 59525
A30: 2015 | C30: 3099.1617 | D30: 3273.3382 | E30: 3473.9057 | F30: 3749.3618 | G30: 3884.9113 | H30: 3384.7064 | I30: 3247.4691 | J30: 3422.1448 | K30: 3503.3384 | L30: 4172.0153 | M30: 4728.5393 | N30: 4947.9772 | O30: 4435.2731 | P30: 3842.612 | Q30: 2421.1837 | R30: 1633.9799 | S30: 1121.7235 | T30: 949.74751 | U30: =SUM(C30:T30) -> 59291.389
A31: 2020 | C31: 3088.1731 | D31: 3139.1537 | E31: 3317.8846 | F31: 3514.6355 | G31: 3560.6702 | H31: 3617.2391 | I31: 3377.3285 | J31: 3383.0847 | K31: 3415.9059 | L31: 3552.6741 | M31: 4111.6286 | N31: 4553.365 | O31: 4678.3486 | P31: 4127.7737 | Q31: 3299.7118 | R31: 2013.4893 | S31: 1153.2213 | T31: 996.56806 | U31: =SUM(C31:T31) -> 58900.856
... A33: 2030 | C33: 2958.9614 | D33: 3092.7393 | E33: 3195.2095 | F33: 3260.8389 | G33: 3255.2734 | H33: 3218.463 | I33: 3373.1887 | J33: 3684.4258 | K33: 3515.3782 | L33: 3468.0958 | M33: 3486.0398 | N33: 3434.6161 | O33: 3771.3513 | P33: 4008.6526 | Q33: 3736.7142 | R33: 2939.3893 | S33: 1922.0502 | T33: 1209.3103 | U33: =SUM(C33:T33) -> 57530.698
A35: Total
A36: 2001 | C36: =C20+C4 -> 6465 | D36: =D20+D4 -> 7404 | E36: =E20+E4 -> 8628 | F36: =F20+F4 -> 8924 | G36: =G20+G4 -> 6643 | H36: =H20+H4 -> 5989 | I36: =I20+I4 -> 7619 | J36: =J20+J4 -> 9150 | ... T36: =T20+T4 -> 2111 | U36: =SUM(C36:T36) -> 118024
A37: 2002 | C37: =C21+C5 -> 6454 | D37: =D21+D5 -> 7198 | E37: =E21+E5 -> 8588 | F37: =F21+F5 -> 8925 | G37: =G21+G5 -> 6936 | H37: =H21+H5 -> 5858 | I37: =I21+I5 -> 7446 | J37: =J21+J5 -> 8851 | ... T37: =T21+T5 -> 2171 | U37: =SUM(C37:T37) -> 118611
A38: 2003 | C38: =C22+C6 -> 6462 | D38: =D22+D6 -> 7121 | E38: =E22+E6 -> 8464 | F38: =F22+F6 -> 8974 | G38: =G22+G6 -> 7221 | H38: =H22+H6 -> 5885 | I38: =I22+I6 -> 7275 | J38: =J22+J6 -> 8724 | ... T38: =T22+T6 -> 2174 | U38: =SUM(C38:T38) -> 119538
A39: 2004 | C39: =C23+C7 -> 6553 | D39: =D23+D7 -> 7169 | E39: =E23+E7 -> 8426 | F39: =F23+F7 -> 8838 | G39: =G23+G7 -> 7328 | H39: =H23+H7 -> 6054 | I39: =I23+I7 -> 7026 | J39: =J23+J7 -> 8555 | ... T39: =T23+T7 -> 2142 | U39: =SUM(C39:T39) -> 120303
A40: 2005 | C40: =C24+C8 -> 6504 | D40: =D24+D8 -> 7119 | E40: =E24+E8 -> 8192 | F40: =F24+F8 -> 8934 | G40: =G24+G8 -> 7407 | H40: =H24+H8 -> 6080 | I40: =I24+I8 -> 6867 | J40: =J24+J8 -> 8468 | ... T40: =T24+T8 -> 2189 | U40: =SUM(C40:T40) -> 120957
A41: 2006 | C41: =C25+C9 -> 6442 | D41: =D25+D9 -> 7130 | E41: =E25+E9 -> 7928 | F41: =F25+F9 -> 8826 | G41: =G25+G9 -> 7472 | H41: =H25+H9 -> 6181 | I41: =I25+I9 -> 6722 | J41: =J25+J9 -> 8309 | ... T41: =T25+T9 -> 2321 | U41: =SUM(C41:T41) -> 121508
A42: 2007 | C42: =C26+C10 -> 6442 | D42: =D26+D10 -> 7136 | E42: =E26+E10 -> 7646 | F42: =F26+F10 -> 8700 | G42: =G26+G10 -> 7407 | H42: =H26+H10 -> 6379 | I42: =I26+I10 -> 6530 | J42: =J26+J10 -> 8076 | ... T42: =T26+T10 -> 2404 | U42: =SUM(C42:T42) -> 121741
A43: 2008 | C43: =C27+C11 -> 6485 | D43: =D27+D11 -> 7041 | E43: =E27+E11 -> 7475 | F43: =F27+F11 -> 8533 | G43: =G27+G11 -> 7394 | H43: =H27+H11 -> 6554 | I43: =I27+I11 -> 6504 | J43: =J27+J11 -> 7770 | ... T43: =T27+T11 -> 2535 | U43: =SUM(C43:T43) -> 122147
A44: 2009 | C44: =C28+C12 -> 6348 | D44: =D28+D12 -> 6951 | E44: =E28+E12 -> 7440 | F44: =F28+F12 -> 8372 | G44: =G28+G12 -> 7243 | H44: =H28+H12 -> 6496 | I44: =I28+I12 -> 6634 | J44: =J28+J12 -> 7528 | ... T44: =T28+T12 -> 2589 | U44: =SUM(C44:T44) -> 122084
...

Sheet 13
A1: 13 | B1: KNOX
A2: Age | C2: 0-4 | D2: 5-9 | E2: 10-14 | F2: 15-19 | G2: 20-24 | H2: 25-29 | I2: 30-34 | J2: 35-39 | K2: 40-44 | L2: 45-49 | M2: 50-54 | N2: 55-59 | O2: 60-64 | P2: 65-69 | Q2: 70-74 | R2: 75-79 | S2: 80-84 | T2: 85+ | U2: Total
A3: Female
A4: 2001 | C4: 1043 | D4: 1069 | E4: 1434 | F4: 1180 | G4: 801 | H4: 1044 | I4: 1206 | J4: 1364 | K4: 1704 | L4: 1672 | M4: 1655 | N4: 1218 | O4: 1028 | P4: 920 | Q4: 864 | R4: 891 | S4: 653 | T4: 618 | U4: =SUM(C4:T4) -> 20364
A5: 2002 | C5: 1019 | D5: 1066 | E5: 1357 | F5: 1253 | G5: 835 | H5: 1022 | I5: 1221 | J5: 1330 | K5: 1644 | L5: 1773 | M5: 1612 | N5: 1350 | O5: 1052 | P5: 919 | Q5: 830 | R5: 914 | S5: 650 | T5: 637 | U5: =SUM(C5:T5) -> 20484
A6: 2003 | C6: 967 | D6: 1123 | E6: 1271 | F6: 1275 | G6: 842 | H6: 1012 | I6: 1177 | J6: 1284 | K6: 1595 | L6: 1777 | M6: 1656 | N6: 1409 | O6: 1128 | P6: 952 | Q6: 802 | R6: 888 | S6: 692 | T6: 650 | U6: =SUM(C6:T6) -> 20500
A7: 2004 | C7: 919 | D7: 1131 | E7: 1259 | F7: 1265 | G7: 883 | H7: 955 | I7: 1166 | J7: 1239 | K7: 1540 | L7: 1773 | M7: 1686 | N7: 1538 | O7: 1153 | P7: 991 | Q7: 808 | R7: 841 | S7: 727 | T7: 669 | U7: =SUM(C7:T7) -> 20543
A8: 2005 | C8: 953 | D8: 1106 | E8: 1222 | F8: 1280 | G8: 895 | H8: 953 | I8: 1091 | J8: 1261 | K8: 1474 | L8: 1764 | M8: 1738 | N8: 1609 | O8: 1194 | P8: 1010 | Q8: 812 | R8: 798 | S8: 772 | T8: 666 | U8: =SUM(C8:T8) -> 20598
A9: 2006 | C9: 935 | D9: 1113 | E9: 1147 | F9: 1244 | G9: 882 | H9: 936 | I9: 1048 | J9: 1236 | K9: 1420 | L9: 1774 | M9: 1731 | N9: 1732 | O9: 1252 | P9: 1004 | Q9: 863 | R9: 735 | S9: 791 | T9: 672 | U9: =SUM(C9:T9) -> 20515
A10: 2007 | C10: 962 | D10: 1065 | E10: 1132 | F10: 1159 | G10: 902 | H10: 936 | I10: 1029 | J10: 1204 | K10: 1387 | L10: 1672 | M10: 1806 | N10: 1681 | O10: 1382 | P10: 1036 | Q10: 847 | R10: 734 | S10: 802 | T10: 710 | U10: =SUM(C10:T10) -> 20446
A11: 2008 | C11: 979 | D11: 1011 | E11: 1181 | F11: 1087 | G11: 875 | H11: 915 | I11: 989 | J11: 1212 | K11: 1319 | L11: 1630 | M11: 1814 | N11: 1705 | O11: 1404 | P11: 1133 | Q11: 897 | R11: 711 | S11: 761 | T11: 731 | U11: =SUM(C11:T11) -> 20354
