Workbook

Sheet Summary
A1: Community and Technical Colleges, Report of Fundable Operating Expenses, Fiscal Year (FY) 1999
A2: Summary of Expense divided Contact Hours
A3: Contact Hours for fall 1998 and spring and summer 1999
A4: Fund | B4: Total Expense by Discipline | D4: Contact Hours | E4: Expense | F4: Expense per Contact Hour
A5: 1 | B5: Agriculture | D5: =D36 -> 1156306 | E5: =E36+E67+IFERROR($E$105/$D$105*D5,0) -> 8858021.5 | F5: =F36+F67+$F$105 -> 6.81
A6: 2 | B6: Architecture and Precision Production Trades | D6: =D37 -> 5213661 | E6: =E37+E68+IFERROR($E$105/$D$105*D6,0) -> 34812484 | F6: =F37+F68+$F$105 -> 6.64
A7: 3 | B7: Biology, Physical Sciences, and Science Technology | D7: =D38 -> 18409138 | E7: =E38+E69+IFERROR($E$105/$D$105*D7,0) -> 1.0786112e+08 | F7: =F38+F69+$F$105 -> 5.51
A8: 4 | B8: Business Management, Marketing, and Administrative Services | D8: =D39 -> 15167456 | E8: =E39+E70+IFERROR($E$105/$D$105*D8,0) -> 1.0390477e+08 | F8: =F39+F70+$F$105 -> 6.22
A9: 5 | B9: Career Pilot | D9: =D40 -> 204871 | E9: =E40+E71+IFERROR($E$105/$D$105*D9,0) -> 3446564.2 | F9: =F40+F71+$F$105 -> 18.69
A10: 6 | B10: Communications | D10: =D41 -> 914335 | E10: =E41+E72+IFERROR($E$105/$D$105*D10,0) -> 8275048.8 | F10: =F41+F72+$F$105 -> 8.21
A11: 7 | B11: Computer and Information Sciences | D11: =D42 -> 13874819 | E11: =E42+E73+IFERROR($E$105/$D$105*D11,0) -> 84977754 | F11: =F42+F73+$F$105 -> 5.44
A12: 8 | B12: Construction Trades | D12: =D43 -> 1587260 | E12: =E43+E74+IFERROR($E$105/$D$105*D12,0) -> 9343167 | F12: =F43+F74+$F$105 -> 5.99
A13: 9 | B13: Consumer and Homemaking Education | D13: =D44 -> 4970395 | E13: =E44+E75+IFERROR($E$105/$D$105*D13,0) -> 30743351 | F13: =F44+F75+$F$105 -> 5.35
A14: 10 | B14: Engineering | D14: =D45 -> 109700 | E14: =E45+E76+IFERROR($E$105/$D$105*D14,0) -> 2076928.4 | F14: =F45+F76+$F$105 -> 7.64
A15: 11 | B15: Engineering Related | D15: =D46 -> 4655432 | E15: =E46+E77+IFERROR($E$105/$D$105*D15,0) -> 31866786 | F15: =F46+F77+$F$105 -> 6.42
A16: 12 | B16: English Language, Lit, Philosophy, Humanities, & Interdisciplinary | D16: =D47 -> 31461433 | E16: =E47+E78+IFERROR($E$105/$D$105*D16,0) -> 1.7977561e+08 | F16: =F47+F78+$F$105 -> 5.26
... A30: 26 | B30: Visual and Performing Arts | D30: =D61 -> 7572223 | E30: =E61+E92+IFERROR($E$105/$D$105*D30,0) -> 59044663 | F30: =F61+F92+$F$105 -> 7.33
A31: 28 | B31: Developmental Education - Math | D31: =D62 -> 0 | E31: =E62+E93+IFERROR($E$105/$D$105*D31,0) -> 0
A32: 29 | B32: Developmental Education - Reading/Writing | D32: =D63 -> 0 | E32: =E63+E94+IFERROR($E$105/$D$105*D32,0) -> 0
B33: Total | D33: =SUM(D5:D32) -> 192706184 | E33: =SUM(E5:E32) -> 1.2071055e+09 | F33: =F64+F95+$F$105 -> 5.77
A35: Fund | B35: Departmental Operating Expense by Discipline | D35: Contact Hours | E35: Expense | F35: Expense per Contact Hour
A36: 1 | B36: Agriculture | D36: =SUM('1:57'!D36) -> 1156306 | E36: =SUM('1:57'!E36) -> 1784347 | F36: =ROUND(MEDIAN('1:57'!F36),2) -> 0.92
A37: 2 | B37: Architecture and Precision Production Trades | D37: =SUM('1:57'!D37) -> 5213661 | E37: =SUM('1:57'!E37) -> 6224692 | F37: =ROUND(MEDIAN('1:57'!F37),2) -> 1.29
A38: 3 | B38: Biology, Physical Sciences, and Science Technology | D38: =SUM('1:57'!D38) -> 18409138 | E38: =SUM('1:57'!E38) -> 12557365 | F38: =ROUND(MEDIAN('1:57'!F38),2) -> 0.5
A39: 4 | B39: Business Management, Marketing, and Administrative Services | D39: =SUM('1:57'!D39) -> 15167456 | E39: =SUM('1:57'!E39) -> 14533847 | F39: =ROUND(MEDIAN('1:57'!F39),2) -> 0.56
A40: 5 | B40: Career Pilot | D40: =SUM('1:57'!D40) -> 204871 | E40: =SUM('1:57'!E40) -> 1699963 | F40: =ROUND(MEDIAN('1:57'!F40),2) -> 8.73
A41: 6 | B41: Communications | D41: =SUM('1:57'!D41) -> 914335 | E41: =SUM('1:57'!E41) -> 2355814 | F41: =ROUND(MEDIAN('1:57'!F41),2) -> 1.48
A42: 7 | B42: Computer and Information Sciences | D42: =SUM('1:57'!D42) -> 13874819 | E42: =SUM('1:57'!E42) -> 16343241 | F42: =ROUND(MEDIAN('1:57'!F42),2) -> 0.69
A43: 8 | B43: Construction Trades | D43: =SUM('1:57'!D43) -> 1587260 | E43: =SUM('1:57'!E43) -> 1163947 | F43: =ROUND(MEDIAN('1:57'!F43),2) -> 0.86
A44: 9 | B44: Consumer and Homemaking Education | D44: =SUM('1:57'!D44) -> 4970395 | E44: =SUM('1:57'!E44) -> 4180066 | F44: =ROUND(MEDIAN('1:57'!F44),2) -> 0.48
A45: 10 | B45: Engineering | D45: =SUM('1:57'!D45) -> 109700 | E45: =SUM('1:57'!E45) -> 744438 | F45: =ROUND(MEDIAN('1:57'!F45),2) -> 0.46
A46: 11 | B46: Engineering Related | D46: =SUM('1:57'!D46) -> 4655432 | E46: =SUM('1:57'!E46) -> 5378490 | F46: =ROUND(MEDIAN('1:57'!F46),2) -> 0.92
A47: 12 | B47: English Language, Lit, Philosophy, Humanities, & Interdisciplinary | D47: =SUM('1:57'!D47) -> 31461433 | E47: =SUM('1:57'!E47) -> 13161115 | F47: =ROUND(MEDIAN('1:57'!F47),2) -> 0.26
... A61: 26 | B61: Visual and Performing Arts | D61: =SUM('1:57'!D61) -> 7572223 | E61: =SUM('1:57'!E61) -> 8194517 | F61: =ROUND(MEDIAN('1:57'!F61),2) -> 0.94
A62: 28 | B62: Developmental Education - Math | D62: =SUM('1:57'!D62) -> 0 | E62: =SUM('1:57'!E62) -> 0
A63: 29 | B63: Developmental Education - Reading/Writing | D63: =SUM('1:57'!D63) -> 0 | E63: =SUM('1:57'!E63) -> 0
C64: Total | D64: =SUM(D36:D63) -> 192706184 | E64: =SUM(E36:E63) -> 136043544 | F64: =ROUND(MEDIAN('1:57'!F64),2) -> 0.62
A66: Fund | B66: Faculty Salaries by Discipline | D66: Contact Hours | E66: Expense | F66: Expense per Contact Hour
A67: 1 | B67: Agriculture | D67: =D36 -> 1156306 | E67: =SUM('1:57'!E67) -> 3793956 | F67: =ROUND(MEDIAN('1:57'!F67),2) -> 3.32
A68: 2 | B68: Architecture and Precision Production Trades | D68: =D37 -> 5213661 | E68: =SUM('1:57'!E68) -> 13799890 | F68: =ROUND(MEDIAN('1:57'!F68),2) -> 2.78
...

Sheet Rate History
A1: =Summary!A1 -> Community and Technical Colleges, Report of Fundable Operating Expenses, Fiscal Year (FY) 1999
A2: Rate History
A3: Fund | B3: Expense per Contact Hour by Discipline | C3: 1999
A4: 1 | B4: Agriculture | C4: =Summary!F5 -> 6.81
A5: 2 | B5: Architecture and Precision Production Trades | C5: =Summary!F6 -> 6.64
A6: 3 | B6: Biology, Physical Sciences, and Science Technology | C6: =Summary!F7 -> 5.51
A7: 4 | B7: Business Management, Marketing, and Administrative Services | C7: =Summary!F8 -> 6.22
A8: 5 | B8: Career Pilot | C8: =Summary!F9 -> 18.69
A9: 6 | B9: Communications | C9: =Summary!F10 -> 8.21
A10: 7 | B10: Computer and Information Sciences | C10: =Summary!F11 -> 5.44
A11: 8 | B11: Construction Trades | C11: =Summary!F12 -> 5.99
A12: 9 | B12: Consumer and Homemaking Education | C12: =Summary!F13 -> 5.35
A13: 10 | B13: Engineering | C13: =Summary!F14 -> 7.64
A14: 11 | B14: Engineering Related | C14: =Summary!F15 -> 6.42
A15: 12 | B15: English Language, Lit, Philosophy, Humanities, & Interdisciplinary | C15: =Summary!F16 -> 5.26
... A31: 29 | B31: Developmental Education - Reading/Writing | C31: =Summary!F32 -> 0
B32: Average | C32: =AVERAGE(C4:C31) -> 6.5617857
B33: Median | C33: =MEDIAN(C4:C31) -> 6.32
B34: Standard Deviation | C34: =STDEV(C4:C31) -> 3.2525364

Sheet FTSE Summary
A1: =Summary!A1 -> Community and Technical Colleges, Report of Fundable Operating Expenses, Fiscal Year (FY) 1999
A2: Average Total Expenditure per Full-Time Student Equivalent (FTSE)
A3: Institution | B3: Annual State Funded Semester Credit Hours | C3: Total FTSE | D3: Total Expenditure | E3: Average Expenditure per FTSE
A4: Alamo | B4: =(161+3898+11775+4803)*30 -> 619110 | C4: =B4/30 -> 20637 | D4: ='1'!$E$33 -> 1.1017196e+08 | E4: =IFERROR(D4/C4,"") -> 5338.5647
A5: Alvin | B5: =2047*30 -> 61410 | C5: =B5/30 -> 2047 | D5: ='2'!$E$33 -> 12071182 | E5: =IFERROR(D5/C5,"") -> 5897.0112
A6: Amarillo | B6: =4129*30 -> 123870 | C6: =B6/30 -> 4129 | D6: ='3'!$E$33 -> 25602472 | E6: =IFERROR(D6/C6,"") -> 6200.6471
A7: Angelina | B7: =2579*30 -> 77370 | C7: =B7/30 -> 2579 | D7: ='4'!$E$33 -> 9238820 | E7: =IFERROR(D7/C7,"") -> 3582.3265
A8: Austin | B8: =13182*30 -> 395460 | C8: =B8/30 -> 13182 | D8: ='5'!$E$33 -> 67025182 | E8: =IFERROR(D8/C8,"") -> 5084.5988
A9: Blinn | B9: =7374*30 -> 221220 | C9: =B9/30 -> 7374 | D9: ='6'!$E$33 -> 21396825 | E9: =IFERROR(D9/C9,"") -> 2901.6579
A10: Brazosport | B10: =1772*30 -> 53160 | C10: =B10/30 -> 1772 | D10: ='7'!$E$33 -> 9361650 | E10: =IFERROR(D10/C10,"") -> 5283.0982
A11: Central Texas | B11: =4163*30 -> 124890 | C11: =B11/30 -> 4163 | D11: ='8'!$E$33 -> 20575441 | E11: =IFERROR(D11/C11,"") -> 4942.4552
A12: Cisco | B12: =1780*30 -> 53400 | C12: =B12/30 -> 1780 | D12: ='9'!$E$33 -> 5009954 | E12: =IFERROR(D12/C12,"") -> 2814.5809
A13: Clarendon | B13: =527*30 -> 15810 | C13: =B13/30 -> 527 | D13: ='10'!$E$33 -> 2796292 | E13: =IFERROR(D13/C13,"") -> 5306.0569
A14: Coastal Bend | B14: =1874*30 -> 56220 | C14: =B14/30 -> 1874 | D14: ='11'!$E$33 -> 9107206 | E14: =IFERROR(D14/C14,"") -> 4859.7684
A15: College Of The Mainland | B15: =1962*30 -> 58860 | C15: =B15/30 -> 1962 | D15: ='12'!$E$33 -> 13101401 | E15: =IFERROR(D15/C15,"") -> 6677.5744
A16: Collin | B16: =6003*30 -> 180090 | C16: =B16/30 -> 6003 | D16: ='13'!$E$33 -> 33833767 | E16: =IFERROR(D16/C16,"") -> 5636.1431
A17: Dallas | B17: =+(4194+1465+4658+2342+2713+3055+6601)*30 -> 750840 | C17: =B17/30 -> 25028 | D17: ='14'!$E$33 -> 134413752 | E17: =IFERROR(D17/C17,"") -> 5370.5351
A18: Del Mar | B18: =5744*30 -> 172320 | C18: =B18/30 -> 5744 | D18: ='15'!$E$33 -> 0 | E18: =IFERROR(D18/C18,"") -> 0
A19: El Paso | B19: =12805*30 -> 384150 | C19: =B19/30 -> 12805 | D19: ='16'!$E$33 -> 55011518 | E19: =IFERROR(D19/C19,"") -> 4296.0967
A20: Frank Phillips | B20: =701*30 -> 21030 | C20: =B20/30 -> 701 | D20: ='17'!$E$33 -> 3485837 | E20: =IFERROR(D20/C20,"") -> 4972.6633
A21: Galveston | B21: =1124*30 -> 33720 | C21: =B21/30 -> 1124 | D21: ='18'!$E$33 -> 8461037 | E21: =IFERROR(D21/C21,"") -> 7527.613
A22: Grayson | B22: =2087*30 -> 62610 | C22: =B22/30 -> 2087 | D22: ='19'!$E$33 -> 9022087 | E22: =IFERROR(D22/C22,"") -> 4322.9933
A23: Hill | B23: =1470*30 -> 44100 | C23: =B23/30 -> 1470 | D23: ='20'!$E$33 -> 6266760 | E23: =IFERROR(D23/C23,"") -> 4263.102
A24: Houston | B24: =17117*30 -> 513510 | C24: =B24/30 -> 17117 | D24: ='21'!$E$33 -> 109213361 | E24: =IFERROR(D24/C24,"") -> 6380.4032
A25: Howard | B25: =(1274+79)*30 -> 40590 | C25: =B25/30 -> 1353 | D25: ='22'!$E$33 -> 8125967 | E25: =IFERROR(D25/C25,"") -> 6005.8884
A26: Kilgore | B26: =2826*30 -> 84780 | C26: =B26/30 -> 2826 | D26: ='23'!$E$33 -> 0 | E26: =IFERROR(D26/C26,"") -> 0
A27: Laredo | B27: =4700*30 -> 141000 | C27: =B27/30 -> 4700 | D27: ='24'!$E$33 -> 21519871 | E27: =IFERROR(D27/C27,"") -> 4578.696
A28: Lee | B28: =3063*30 -> 91890 | C28: =B28/30 -> 3063 | D28: ='25'!$E$33 -> 22425942 | E28: =IFERROR(D28/C28,"") -> 7321.5612
A29: Lonestar | B29: =(2033+2554+4755+2525)*30 -> 356010 | C29: =B29/30 -> 11867 | D29: ='26'!$E$33 -> 62042788 | E29: =IFERROR(D29/C29,"") -> 5228.178
A30: Mclennan | B30: =3623*30 -> 108690 | C30: =B30/30 -> 3623 | D30: ='27'!$E$33 -> 17848119 | E30: =IFERROR(D30/C30,"") -> 4926.337
A31: Midland | B31: =2601*30 -> 78030 | C31: =B31/30 -> 2601 | D31: ='28'!$E$33 -> 14172389 | E31: =IFERROR(D31/C31,"") -> 5448.8231
A32: Navarro | B32: =2512*30 -> 75360 | C32: =B32/30 -> 2512 | D32: ='29'!$E$33 -> 10082860 | E32: =IFERROR(D32/C32,"") -> 4013.8774
A33: North Central Texas | B33: =2404*30 -> 72120 | C33: =B33/30 -> 2404 | D33: ='30'!$E$33 -> 8053602 | E33: =IFERROR(D33/C33,"") -> 3350.084
A34: Northeast Texas | B34: =1346*30 -> 40380 | C34: =B34/30 -> 1346 | D34: ='31'!$E$33 -> 6397564 | E34: =IFERROR(D34/C34,"") -> 4753.0193
A35: Odessa | B35: =2738*30 -> 82140 | C35: =B35/30 -> 2738 | D35: ='32'!$E$33 -> 15350416 | E35: =IFERROR(D35/C35,"") -> 5606.4339
A36: Panola | B36: =1129*30 -> 33870 | C36: =B36/30 -> 1129 | D36: ='33'!$E$33 -> 6580557 | E36: =IFERROR(D36/C36,"") -> 5828.6599
A37: Paris | B37: =1923*30 -> 57690 | C37: =B37/30 -> 1923 | D37: ='34'!$E$33 -> 8390679 | E37: =IFERROR(D37/C37,"") -> 4363.3276
A38: Ranger | B38: =628*30 -> 18840 | C38: =B38/30 -> 628 | D38: ='35'!$E$33 -> 2269241 | E38: =IFERROR(D38/C38,"") -> 3613.4411
A39: San Jacinto | B39: =(5723+2339+2873)*30 -> 328050 | C39: =B39/30 -> 10935 | D39: ='36'!$E$33 -> 55578066 | E39: =IFERROR(D39/C39,"") -> 5082.5849
A40: South Plains | B40: =4483*30 -> 134490 | C40: =B40/30 -> 4483 | D40: ='37'!$E$33 -> 17958309 | E40: =IFERROR(D40/C40,"") -> 4005.8686
...

Sheet Discipline Summary
A1: =Summary!A1 -> Community and Technical Colleges, Report of Fundable Operating Expenses, Fiscal Year (FY) 1999
A2: Discipline Summary of Expense per Contact Hour by Institution
A3: Institution | B3: AG | C3: ARCH | D3: SCI | E3: BA | F3: CP | G3: COMM | H3: CS | I3: CNSTR | J3: HE | K3: ENG | L3: ENGR | M3: LA | N3: FL | O3: HODA | P3: HODH | Q3: HOO | R3: HORT | S3: NUR | T3: MATH | U3: AUTO | V3: MECH | W3: ELECT | X3: PE | Y3: PA | Z3: SS | AA3: FA | AB3: DEM | AC3: DER | AD3: Total
A4: Alamo | B4: ='1'!$F$5 -> 6.35 | C4: ='1'!$F$6 -> 8.93 | D4: ='1'!$F$7 -> 7.15 | E4: ='1'!$F$8 -> 8.81 | F4: ='1'!$F$9 -> 24.55 | G4: ='1'!$F$10 -> 13.15 | H4: ='1'!$F$11 -> 6.27 | I4: ='1'!$F$12 | J4: ='1'!$F$13 -> 9.45 | K4: ='1'!$F$14 -> 18.17 | L4: ='1'!$F$15 -> 8.79 | M4: ='1'!$F$16 -> 6.38 | N4: ='1'!$F$17 -> 6.82 | O4: ='1'!$F$18 -> 11.63 | P4: ='1'!$F$19 | Q4: ='1'!$F$20 -> 6.79 | R4: ='1'!$F$21 -> 10.18 | S4: ='1'!$F$22 -> 7.91 | T4: ='1'!$F$23 -> 6.48 | U4: ='1'!$F$24 -> 9.01 | V4: ='1'!$F$25 -> 8.85 | W4: ='1'!$F$26 -> 7.23 | X4: ='1'!$F$27 -> 7.64 | Y4: ='1'!$F$28 -> 6.04 | Z4: ='1'!$F$29 -> 7.44 | AA4: ='1'!$F$30 -> 9.24 | AB4: ='1'!$F$31 | AC4: ='1'!$F$32 | AD4: ='1'!$F$33 -> 7.45
A5: Alvin | B5: ='2'!$F$5 -> 4.92 | C5: ='2'!$F$6 -> 5.34 | D5: ='2'!$F$7 -> 6.02 | E5: ='2'!$F$8 -> 6.13 | F5: ='2'!$F$9 | G5: ='2'!$F$10 -> 5.14 | H5: ='2'!$F$11 -> 5.46 | I5: ='2'!$F$12 | J5: ='2'!$F$13 -> 7.05 | K5: ='2'!$F$14 | L5: ='2'!$F$15 -> 4.36 | M5: ='2'!$F$16 -> 4.9 | N5: ='2'!$F$17 -> 5.66 | O5: ='2'!$F$18 -> 7.9 | P5: ='2'!$F$19 | Q5: ='2'!$F$20 -> 7.59 | R5: ='2'!$F$21 -> 12.68 | S5: ='2'!$F$22 -> 12.34 | T5: ='2'!$F$23 -> 9.25 | U5: ='2'!$F$24 -> 5.11 | V5: ='2'!$F$25 | W5: ='2'!$F$26 | X5: ='2'!$F$27 -> 7.48 | Y5: ='2'!$F$28 -> 5.18 | Z5: ='2'!$F$29 -> 4.84 | AA5: ='2'!$F$30 -> 7.77 | AB5: ='2'!$F$31 | AC5: ='2'!$F$32 | AD5: ='2'!$F$33 -> 5.92
A6: Amarillo | B6: ='3'!$F$5 -> 11.1 | C6: ='3'!$F$6 -> 7.69 | D6: ='3'!$F$7 -> 5.49 | E6: ='3'!$F$8 -> 6.46 | F6: ='3'!$F$9 | G6: ='3'!$F$10 -> 9.4 | H6: ='3'!$F$11 -> 5.51 | I6: ='3'!$F$12 -> 4.31 | J6: ='3'!$F$13 -> 5.48 | K6: ='3'!$F$14 -> 7.28 | L6: ='3'!$F$15 -> 7.97 | M6: ='3'!$F$16 -> 5.82 | N6: ='3'!$F$17 -> 7.58 | O6: ='3'!$F$18 -> 7.91 | P6: ='3'!$F$19 -> 9.84 | Q6: ='3'!$F$20 -> 5.96 | R6: ='3'!$F$21 -> 8.46 | S6: ='3'!$F$22 -> 6.03 | T6: ='3'!$F$23 -> 5.18 | U6: ='3'!$F$24 -> 8.22 | V6: ='3'!$F$25 -> 6.78 | W6: ='3'!$F$26 -> 7.89 | X6: ='3'!$F$27 -> 5.63 | Y6: ='3'!$F$28 -> 5.57 | Z6: ='3'!$F$29 -> 5.47 | AA6: ='3'!$F$30 -> 9.25 | AB6: ='3'!$F$31 | AC6: ='3'!$F$32 | AD6: ='3'!$F$33 -> 6.26
A7: Angelina | B7: ='4'!$F$5 -> 5.94 | C7: ='4'!$F$6 -> 4.18 | D7: ='4'!$F$7 -> 3.99 | E7: ='4'!$F$8 -> 5.84 | F7: ='4'!$F$9 | G7: ='4'!$F$10 -> 6.22 | H7: ='4'!$F$11 -> 6.21 | I7: ='4'!$F$12 -> 5.89 | J7: ='4'!$F$13 -> 4.78 | K7: ='4'!$F$14 -> 10.82 | L7: ='4'!$F$15 -> 3.53 | M7: ='4'!$F$16 -> 3.89 | N7: ='4'!$F$17 -> 5.11 | O7: ='4'!$F$18 -> 6.73 | P7: ='4'!$F$19 | Q7: ='4'!$F$20 -> 6.54 | R7: ='4'!$F$21 -> 6.39 | S7: ='4'!$F$22 -> 6.17 | T7: ='4'!$F$23 -> 3.89 | U7: ='4'!$F$24 -> 5.59 | V7: ='4'!$F$25 -> 6.15 | W7: ='4'!$F$26 -> 5.53 | X7: ='4'!$F$27 -> 4.6 | Y7: ='4'!$F$28 -> 4.66 | Z7: ='4'!$F$29 -> 3.68 | AA7: ='4'!$F$30 -> 5.87 | AB7: ='4'!$F$31 | AC7: ='4'!$F$32 | AD7: ='4'!$F$33 -> 4.75
A8: Austin | B8: ='5'!$F$5 | C8: ='5'!$F$6 -> 9.55 | D8: ='5'!$F$7 -> 7 | E8: ='5'!$F$8 -> 7.78 | F8: ='5'!$F$9 | G8: ='5'!$F$10 -> 7.3 | H8: ='5'!$F$11 -> 6.99 | I8: ='5'!$F$12 -> 10.73 | J8: ='5'!$F$13 -> 7.59 | K8: ='5'!$F$14 -> 12.19 | L8: ='5'!$F$15 -> 9.8 | M8: ='5'!$F$16 -> 6.61 | N8: ='5'!$F$17 -> 5.99 | O8: ='5'!$F$18 -> 13.68 | P8: ='5'!$F$19 | Q8: ='5'!$F$20 -> 9.03 | R8: ='5'!$F$21 | S8: ='5'!$F$22 -> 11.43 | T8: ='5'!$F$23 -> 6.08 | U8: ='5'!$F$24 -> 13.12 | V8: ='5'!$F$25 | W8: ='5'!$F$26 -> 9.47 | X8: ='5'!$F$27 -> 8.58 | Y8: ='5'!$F$28 -> 7.8 | Z8: ='5'!$F$29 -> 5.51 | AA8: ='5'!$F$30 -> 7.76 | AB8: ='5'!$F$31 | AC8: ='5'!$F$32 | AD8: ='5'!$F$33 -> 6.97
A9: Blinn | B9: ='6'!$F$5 -> 7.82 | C9: ='6'!$F$6 -> 5.12 | D9: ='6'!$F$7 -> 3.38 | E9: ='6'!$F$8 -> 4.41 | F9: ='6'!$F$9 | G9: ='6'!$F$10 -> 4.96 | H9: ='6'!$F$11 -> 7.84 | I9: ='6'!$F$12 | J9: ='6'!$F$13 -> 4.65 | K9: ='6'!$F$14 | L9: ='6'!$F$15 -> 2.35 | M9: ='6'!$F$16 -> 4.4 | N9: ='6'!$F$17 -> 3.96 | O9: ='6'!$F$18 -> 9.28 | P9: ='6'!$F$19 -> 10.14 | Q9: ='6'!$F$20 -> 5.62 | R9: ='6'!$F$21 | S9: ='6'!$F$22 -> 5 | T9: ='6'!$F$23 -> 3.83 | U9: ='6'!$F$24 | V9: ='6'!$F$25 | W9: ='6'!$F$26 | X9: ='6'!$F$27 -> 3.8 | Y9: ='6'!$F$28 -> 3.83 | Z9: ='6'!$F$29 -> 3.63 | AA9: ='6'!$F$30 -> 6.62 | AB9: ='6'!$F$31 | AC9: ='6'!$F$32 | AD9: ='6'!$F$33 -> 4.21
A10: Brazosport | B10: ='7'!$F$5 | C10: ='7'!$F$6 -> 5.98 | D10: ='7'!$F$7 -> 7.14 | E10: ='7'!$F$8 -> 6.35 | F10: ='7'!$F$9 | G10: ='7'!$F$10 -> 6.92 | H10: ='7'!$F$11 -> 6.41 | I10: ='7'!$F$12 -> 5.27 | J10: ='7'!$F$13 -> 5.05 | K10: ='7'!$F$14 | L10: ='7'!$F$15 -> 5.81 | M10: ='7'!$F$16 -> 6.51 | N10: ='7'!$F$17 -> 7.86 | O10: ='7'!$F$18 -> 14.95 | P10: ='7'!$F$19 | Q10: ='7'!$F$20 -> 4.8 | R10: ='7'!$F$21 | S10: ='7'!$F$22 | T10: ='7'!$F$23 -> 5.69 | U10: ='7'!$F$24 -> 16.37 | V10: ='7'!$F$25 -> 4.47 | W10: ='7'!$F$26 -> 6.16 | X10: ='7'!$F$27 -> 7.59 | Y10: ='7'!$F$28 -> 4.82 | Z10: ='7'!$F$29 -> 5.82 | AA10: ='7'!$F$30 -> 9.19 | AB10: ='7'!$F$31 | AC10: ='7'!$F$32 | AD10: ='7'!$F$33 -> 6.21
A11: Central Texas | B11: ='8'!$F$5 -> 9.43 | C11: ='8'!$F$6 -> 5.09 | D11: ='8'!$F$7 -> 6.1 | E11: ='8'!$F$8 -> 4.59 | F11: ='8'!$F$9 -> 28.12 | G11: ='8'!$F$10 | H11: ='8'!$F$11 -> 3.85 | I11: ='8'!$F$12 -> 5.29 | J11: ='8'!$F$13 -> 4.23 | K11: ='8'!$F$14 -> 5.68 | L11: ='8'!$F$15 -> 3.28 | M11: ='8'!$F$16 -> 4.31 | N11: ='8'!$F$17 -> 4.41 | O11: ='8'!$F$18 -> 8.69 | P11: ='8'!$F$19 | Q11: ='8'!$F$20 -> 5.93 | R11: ='8'!$F$21 | S11: ='8'!$F$22 -> 4.79 | T11: ='8'!$F$23 -> 3.63 | U11: ='8'!$F$24 -> 5.47 | V11: ='8'!$F$25 -> 11.21 | W11: ='8'!$F$26 -> 4.99 | X11: ='8'!$F$27 -> 4.84 | Y11: ='8'!$F$28 -> 3.8 | Z11: ='8'!$F$29 -> 3.73 | AA11: ='8'!$F$30 -> 6.02 | AB11: ='8'!$F$31 | AC11: ='8'!$F$32 | AD11: ='8'!$F$33 -> 4.66
A12: Cisco | B12: ='9'!$F$5 -> 6.71 | C12: ='9'!$F$6 -> 3.36 | D12: ='9'!$F$7 -> 3.46 | E12: ='9'!$F$8 -> 4.7 | F12: ='9'!$F$9 | G12: ='9'!$F$10 | H12: ='9'!$F$11 -> 4.36 | I12: ='9'!$F$12 | J12: ='9'!$F$13 -> 3.48 | K12: ='9'!$F$14 | L12: ='9'!$F$15 -> 3.35 | M12: ='9'!$F$16 -> 3.68 | N12: ='9'!$F$17 -> 6.03 | O12: ='9'!$F$18 -> 5.4 | P12: ='9'!$F$19 | Q12: ='9'!$F$20 -> 4.43 | R12: ='9'!$F$21 | S12: ='9'!$F$22 -> 4.06 | T12: ='9'!$F$23 -> 3.7 | U12: ='9'!$F$24 -> 5.23 | V12: ='9'!$F$25 | W12: ='9'!$F$26 -> 6.09 | X12: ='9'!$F$27 -> 7 | Y12: ='9'!$F$28 -> 4.81 | Z12: ='9'!$F$29 -> 3.32 | AA12: ='9'!$F$30 -> 6.12 | AB12: ='9'!$F$31 | AC12: ='9'!$F$32 | AD12: ='9'!$F$33 -> 4.14
A13: Clarendon | B13: ='10'!$F$5 -> 9.45 | C13: ='10'!$F$6 | D13: ='10'!$F$7 -> 6.43 | E13: ='10'!$F$8 -> 8.9 | F13: ='10'!$F$9 | G13: ='10'!$F$10 | H13: ='10'!$F$11 -> 7.1 | I13: ='10'!$F$12 | J13: ='10'!$F$13 -> 4.2 | K13: ='10'!$F$14 | L13: ='10'!$F$15 -> 8.49 | M13: ='10'!$F$16 -> 6.2 | N13: ='10'!$F$17 -> 4.78 | O13: ='10'!$F$18 | P13: ='10'!$F$19 | Q13: ='10'!$F$20 -> 4.07 | R13: ='10'!$F$21 | S13: ='10'!$F$22 -> 8.15 | T13: ='10'!$F$23 -> 4.67 | U13: ='10'!$F$24 | V13: ='10'!$F$25 | W13: ='10'!$F$26 | X13: ='10'!$F$27 -> 9.7 | Y13: ='10'!$F$28 | Z13: ='10'!$F$29 -> 6.13 | AA13: ='10'!$F$30 -> 14.93 | AB13: ='10'!$F$31 | AC13: ='10'!$F$32 | AD13: ='10'!$F$33 -> 7.01
A14: Coastal Bend | B14: ='11'!$F$5 -> 3.59 | C14: ='11'!$F$6 -> 7.69 | D14: ='11'!$F$7 -> 3.94 | E14: ='11'!$F$8 -> 5.2 | F14: ='11'!$F$9 | G14: ='11'!$F$10 | H14: ='11'!$F$11 -> 3.82 | I14: ='11'!$F$12 -> 3.77 | J14: ='11'!$F$13 -> 5.12 | K14: ='11'!$F$14 -> 4.27 | L14: ='11'!$F$15 | M14: ='11'!$F$16 -> 4.4 | N14: ='11'!$F$17 -> 11.59 | O14: ='11'!$F$18 | P14: ='11'!$F$19 -> 7.32 | Q14: ='11'!$F$20 -> 4.71 | R14: ='11'!$F$21 | S14: ='11'!$F$22 -> 3.78 | T14: ='11'!$F$23 -> 4.44 | U14: ='11'!$F$24 -> 5.77 | V14: ='11'!$F$25 | W14: ='11'!$F$26 -> 10.1 | X14: ='11'!$F$27 -> 5.56 | Y14: ='11'!$F$28 -> 4.86 | Z14: ='11'!$F$29 -> 4.39 | AA14: ='11'!$F$30 -> 8.76 | AB14: ='11'!$F$31 | AC14: ='11'!$F$32 | AD14: ='11'!$F$33 -> 4.88
A15: College Of The Mainland | B15: ='12'!$F$5 | C15: ='12'!$F$6 | D15: ='12'!$F$7 -> 7.7 | E15: ='12'!$F$8 -> 10.4 | F15: ='12'!$F$9 | G15: ='12'!$F$10 -> 30.94 | H15: ='12'!$F$11 | I15: ='12'!$F$12 | J15: ='12'!$F$13 -> 10.39 | K15: ='12'!$F$14 | L15: ='12'!$F$15 | M15: ='12'!$F$16 -> 9.53 | N15: ='12'!$F$17 | O15: ='12'!$F$18 -> 10.03 | P15: ='12'!$F$19 | Q15: ='12'!$F$20 | R15: ='12'!$F$21 | S15: ='12'!$F$22 | T15: ='12'!$F$23 -> 7.09 | U15: ='12'!$F$24 | V15: ='12'!$F$25 -> 12.87 | W15: ='12'!$F$26 -> 8.77 | X15: ='12'!$F$27 -> 9.11 | Y15: ='12'!$F$28 -> 7.48 | Z15: ='12'!$F$29 -> 7.17 | AA15: ='12'!$F$30 -> 11.05 | AB15: ='12'!$F$31 | AC15: ='12'!$F$32 | AD15: ='12'!$F$33 -> 8.8
A16: Collin | B16: ='13'!$F$5 -> 11.07 | C16: ='13'!$F$6 -> 7.91 | D16: ='13'!$F$7 -> 6.41 | E16: ='13'!$F$8 -> 8.19 | F16: ='13'!$F$9 -> 7.37 | G16: ='13'!$F$10 -> 4.35 | H16: ='13'!$F$11 -> 6.31 | I16: ='13'!$F$12 | J16: ='13'!$F$13 -> 8.71 | K16: ='13'!$F$14 -> 5.36 | L16: ='13'!$F$15 -> 7.42 | M16: ='13'!$F$16 -> 6.38 | N16: ='13'!$F$17 -> 7.24 | O16: ='13'!$F$18 -> 13.82 | P16: ='13'!$F$19 -> 16.09 | Q16: ='13'!$F$20 -> 7.36 | R16: ='13'!$F$21 -> 8.88 | S16: ='13'!$F$22 -> 9.39 | T16: ='13'!$F$23 -> 5.5 | U16: ='13'!$F$24 | V16: ='13'!$F$25 | W16: ='13'!$F$26 -> 10.43 | X16: ='13'!$F$27 -> 10.05 | Y16: ='13'!$F$28 -> 8.03 | Z16: ='13'!$F$29 -> 6.21 | AA16: ='13'!$F$30 -> 9.41 | AB16: ='13'!$F$31 | AC16: ='13'!$F$32 | AD16: ='13'!$F$33 -> 6.97
A17: Dallas | B17: ='14'!$F$5 -> 12.63 | C17: ='14'!$F$6 -> 4.82 | D17: ='14'!$F$7 -> 6.52 | E17: ='14'!$F$8 -> 6.66 | F17: ='14'!$F$9 -> 22.92 | G17: ='14'!$F$10 -> 9.6 | H17: ='14'!$F$11 -> 6.86 | I17: ='14'!$F$12 -> 12.21 | J17: ='14'!$F$13 -> 4.31 | K17: ='14'!$F$14 -> 6.91 | L17: ='14'!$F$15 -> 3.83 | M17: ='14'!$F$16 -> 6.08 | N17: ='14'!$F$17 -> 6.06 | O17: ='14'!$F$18 -> 11.34 | P17: ='14'!$F$19 | Q17: ='14'!$F$20 -> 6.43 | R17: ='14'!$F$21 -> 12.99 | S17: ='14'!$F$22 -> 8.13 | T17: ='14'!$F$23 -> 5.68 | U17: ='14'!$F$24 -> 7.01 | V17: ='14'!$F$25 -> 3.47 | W17: ='14'!$F$26 -> 16.38 | X17: ='14'!$F$27 -> 7.99 | Y17: ='14'!$F$28 -> 4.53 | Z17: ='14'!$F$29 -> 5.89 | AA17: ='14'!$F$30 -> 8.85 | AB17: ='14'!$F$31 | AC17: ='14'!$F$32 | AD17: ='14'!$F$33 -> 6.42
A18: Del Mar | B18: ='15'!$F$5 | C18: ='15'!$F$6 | D18: ='15'!$F$7 | E18: ='15'!$F$8 | F18: ='15'!$F$9 | G18: ='15'!$F$10 | H18: ='15'!$F$11 | I18: ='15'!$F$12 | J18: ='15'!$F$13 | K18: ='15'!$F$14 | L18: ='15'!$F$15 | M18: ='15'!$F$16 | N18: ='15'!$F$17 | O18: ='15'!$F$18 | P18: ='15'!$F$19 | Q18: ='15'!$F$20 | R18: ='15'!$F$21 | S18: ='15'!$F$22 | T18: ='15'!$F$23 | U18: ='15'!$F$24 | V18: ='15'!$F$25 | W18: ='15'!$F$26 | X18: ='15'!$F$27 | Y18: ='15'!$F$28 | Z18: ='15'!$F$29 | AA18: ='15'!$F$30 | AB18: ='15'!$F$31 | AC18: ='15'!$F$32 | AD18: ='15'!$F$33
A19: El Paso | B19: ='16'!$F$5 | C19: ='16'!$F$6 -> 8.85 | D19: ='16'!$F$7 -> 5.74 | E19: ='16'!$F$8 -> 17.52 | F19: ='16'!$F$9 | G19: ='16'!$F$10 -> 12.78 | H19: ='16'!$F$11 -> 6.47 | I19: ='16'!$F$12 | J19: ='16'!$F$13 -> 7.13 | K19: ='16'!$F$14 -> 9.36 | L19: ='16'!$F$15 -> 6.03 | M19: ='16'!$F$16 -> 6.31 | N19: ='16'!$F$17 -> 6.72 | O19: ='16'!$F$18 -> 10.16 | P19: ='16'!$F$19 -> 17.76 | Q19: ='16'!$F$20 -> 10.56 | R19: ='16'!$F$21 -> 11.9 | S19: ='16'!$F$22 | T19: ='16'!$F$23 -> 5.83 | U19: ='16'!$F$24 -> 6.92 | V19: ='16'!$F$25 | W19: ='16'!$F$26 -> 9.57 | X19: ='16'!$F$27 -> 7.29 | Y19: ='16'!$F$28 -> 6.85 | Z19: ='16'!$F$29 -> 6.03 | AA19: ='16'!$F$30 -> 7.03 | AB19: ='16'!$F$31 | AC19: ='16'!$F$32 | AD19: ='16'!$F$33 -> 7.09
A20: Frank Phillips | B20: ='17'!$F$5 -> 8.22 | C20: ='17'!$F$6 -> 4.85 | D20: ='17'!$F$7 -> 6.34 | E20: ='17'!$F$8 -> 6.87 | F20: ='17'!$F$9 | G20: ='17'!$F$10 -> 10.35 | H20: ='17'!$F$11 -> 4.22 | I20: ='17'!$F$12 -> 5.66 | J20: ='17'!$F$13 -> 4.64 | K20: ='17'!$F$14 | L20: ='17'!$F$15 -> 4.45 | M20: ='17'!$F$16 -> 4.52 | N20: ='17'!$F$17 -> 5.01 | O20: ='17'!$F$18 -> 6.55 | P20: ='17'!$F$19 | Q20: ='17'!$F$20 -> 5.53 | R20: ='17'!$F$21 | S20: ='17'!$F$22 -> 5.19 | T20: ='17'!$F$23 -> 4.75 | U20: ='17'!$F$24 | V20: ='17'!$F$25 | W20: ='17'!$F$26 -> 4.04 | X20: ='17'!$F$27 -> 7.68 | Y20: ='17'!$F$28 -> 5.64 | Z20: ='17'!$F$29 -> 5.25 | AA20: ='17'!$F$30 -> 8.35 | AB20: ='17'!$F$31 | AC20: ='17'!$F$32 | AD20: ='17'!$F$33 -> 5.44
A21: Galveston | B21: ='18'!$F$5 | C21: ='18'!$F$6 -> 5.46 | D21: ='18'!$F$7 -> 7.89 | E21: ='18'!$F$8 -> 6.64 | F21: ='18'!$F$9 | G21: ='18'!$F$10 | H21: ='18'!$F$11 -> 7.35 | I21: ='18'!$F$12 -> 7.16 | J21: ='18'!$F$13 -> 6.43 | K21: ='18'!$F$14 | L21: ='18'!$F$15 -> 6.36 | M21: ='18'!$F$16 -> 6.63 | N21: ='18'!$F$17 -> 5.57 | O21: ='18'!$F$18 -> 10.47 | P21: ='18'!$F$19 | Q21: ='18'!$F$20 -> 8.23 | R21: ='18'!$F$21 | S21: ='18'!$F$22 -> 6.93 | T21: ='18'!$F$23 -> 6.16 | U21: ='18'!$F$24 | V21: ='18'!$F$25 | W21: ='18'!$F$26 | X21: ='18'!$F$27 -> 8.24 | Y21: ='18'!$F$28 -> 6.17 | Z21: ='18'!$F$29 -> 7.54 | AA21: ='18'!$F$30 -> 8.99 | AB21: ='18'!$F$31 | AC21: ='18'!$F$32 | AD21: ='18'!$F$33 -> 7.33
A22: Grayson | B22: ='19'!$F$5 -> 6.31 | C22: ='19'!$F$6 -> 8.04 | D22: ='19'!$F$7 -> 5.23 | E22: ='19'!$F$8 -> 5.69 | F22: ='19'!$F$9 | G22: ='19'!$F$10 | H22: ='19'!$F$11 -> 6.53 | I22: ='19'!$F$12 -> 2.91 | J22: ='19'!$F$13 -> 5.32 | K22: ='19'!$F$14 -> 6.88 | L22: ='19'!$F$15 -> 5.32 | M22: ='19'!$F$16 -> 5.15 | N22: ='19'!$F$17 -> 5.16 | O22: ='19'!$F$18 -> 8.23 | P22: ='19'!$F$19 | Q22: ='19'!$F$20 -> 6.72 | R22: ='19'!$F$21 | S22: ='19'!$F$22 -> 4.52 | T22: ='19'!$F$23 -> 4.37 | U22: ='19'!$F$24 -> 7.43 | V22: ='19'!$F$25 -> 2.43 | W22: ='19'!$F$26 -> 7.63 | X22: ='19'!$F$27 -> 6.39 | Y22: ='19'!$F$28 -> 5.66 | Z22: ='19'!$F$29 -> 4.65 | AA22: ='19'!$F$30 -> 6.75 | AB22: ='19'!$F$31 | AC22: ='19'!$F$32 | AD22: ='19'!$F$33 -> 5.7
A23: Hill | B23: ='20'!$F$5 -> 7.28 | C23: ='20'!$F$6 -> 7.53 | D23: ='20'!$F$7 -> 5.37 | E23: ='20'!$F$8 -> 2.98 | F23: ='20'!$F$9 | G23: ='20'!$F$10 | H23: ='20'!$F$11 -> 5.66 | I23: ='20'!$F$12 | J23: ='20'!$F$13 -> 4.26 | K23: ='20'!$F$14 | L23: ='20'!$F$15 -> 6.96 | M23: ='20'!$F$16 -> 4.28 | N23: ='20'!$F$17 -> 4.84 | O23: ='20'!$F$18 | P23: ='20'!$F$19 | Q23: ='20'!$F$20 -> 4.28 | R23: ='20'!$F$21 | S23: ='20'!$F$22 -> 6.11 | T23: ='20'!$F$23 -> 4.03 | U23: ='20'!$F$24 -> 6.09 | V23: ='20'!$F$25 | W23: ='20'!$F$26 -> 7.4 | X23: ='20'!$F$27 -> 5.95 | Y23: ='20'!$F$28 -> 5.47 | Z23: ='20'!$F$29 -> 5.48 | AA23: ='20'!$F$30 -> 5.38 | AB23: ='20'!$F$31 | AC23: ='20'!$F$32 | AD23: ='20'!$F$33 -> 5.12
A24: Houston | B24: ='21'!$F$5 -> 5.78 | C24: ='21'!$F$6 -> 5.4 | D24: ='21'!$F$7 -> 5.95 | E24: ='21'!$F$8 -> 7.04 | F24: ='21'!$F$9 | G24: ='21'!$F$10 -> 8.27 | H24: ='21'!$F$11 -> 7.55 | I24: ='21'!$F$12 -> 6.67 | J24: ='21'!$F$13 -> 6.62 | K24: ='21'!$F$14 -> 7.4 | L24: ='21'!$F$15 -> 7.46 | M24: ='21'!$F$16 -> 6.14 | N24: ='21'!$F$17 -> 6.84 | O24: ='21'!$F$18 -> 11.6 | P24: ='21'!$F$19 | Q24: ='21'!$F$20 -> 8.77 | R24: ='21'!$F$21 -> 11.42 | S24: ='21'!$F$22 -> 8.28 | T24: ='21'!$F$23 -> 5.82 | U24: ='21'!$F$24 -> 11.11 | V24: ='21'!$F$25 -> 10.23 | W24: ='21'!$F$26 -> 4.54 | X24: ='21'!$F$27 -> 5.76 | Y24: ='21'!$F$28 -> 6.59 | Z24: ='21'!$F$29 -> 5.9 | AA24: ='21'!$F$30 -> 7.95 | AB24: ='21'!$F$31 | AC24: ='21'!$F$32 | AD24: ='21'!$F$33 -> 6.71
A25: Howard | B25: ='22'!$F$5 -> 4.76 | C25: ='22'!$F$6 -> 4.96 | D25: ='22'!$F$7 -> 4.98 | E25: ='22'!$F$8 -> 4.01 | F25: ='22'!$F$9 -> 3.26 | G25: ='22'!$F$10 -> 3.88 | H25: ='22'!$F$11 -> 7.44 | I25: ='22'!$F$12 -> 3.28 | J25: ='22'!$F$13 -> 3.52 | K25: ='22'!$F$14 | L25: ='22'!$F$15 -> 6.67 | M25: ='22'!$F$16 -> 3.85 | N25: ='22'!$F$17 -> 2.43 | O25: ='22'!$F$18 -> 5.39 | P25: ='22'!$F$19 -> 12.05 | Q25: ='22'!$F$20 -> 4.79 | R25: ='22'!$F$21 -> 6.88 | S25: ='22'!$F$22 -> 11.84 | T25: ='22'!$F$23 -> 4.31 | U25: ='22'!$F$24 -> 2.25 | V25: ='22'!$F$25 -> 2.77 | W25: ='22'!$F$26 -> 3.95 | X25: ='22'!$F$27 -> 9.74 | Y25: ='22'!$F$28 -> 2.79 | Z25: ='22'!$F$29 -> 4.83 | AA25: ='22'!$F$30 -> 7.9 | AB25: ='22'!$F$31 | AC25: ='22'!$F$32 | AD25: ='22'!$F$33 -> 4.65
A26: Kilgore | B26: ='23'!$F$5 | C26: ='23'!$F$6 | D26: ='23'!$F$7 | E26: ='23'!$F$8 | F26: ='23'!$F$9 | G26: ='23'!$F$10 | H26: ='23'!$F$11 | I26: ='23'!$F$12 | J26: ='23'!$F$13 | K26: ='23'!$F$14 | L26: ='23'!$F$15 | M26: ='23'!$F$16 | N26: ='23'!$F$17 | O26: ='23'!$F$18 | P26: ='23'!$F$19 | Q26: ='23'!$F$20 | R26: ='23'!$F$21 | S26: ='23'!$F$22 | T26: ='23'!$F$23 | U26: ='23'!$F$24 | V26: ='23'!$F$25 | W26: ='23'!$F$26 | X26: ='23'!$F$27 | Y26: ='23'!$F$28 | Z26: ='23'!$F$29 | AA26: ='23'!$F$30 | AB26: ='23'!$F$31 | AC26: ='23'!$F$32 | AD26: ='23'!$F$33
A27: Laredo | B27: ='24'!$F$5 | C27: ='24'!$F$6 -> 6.76 | D27: ='24'!$F$7 -> 7.01 | E27: ='24'!$F$8 -> 6.79 | F27: ='24'!$F$9 | G27: ='24'!$F$10 | H27: ='24'!$F$11 -> 6.05 | I27: ='24'!$F$12 -> 11.22 | J27: ='24'!$F$13 -> 6.3 | K27: ='24'!$F$14 | L27: ='24'!$F$15 -> 5.27 | M27: ='24'!$F$16 -> 6.08 | N27: ='24'!$F$17 -> 21.97 | O27: ='24'!$F$18 -> 12.94 | P27: ='24'!$F$19 | Q27: ='24'!$F$20 -> 6.16 | R27: ='24'!$F$21 | S27: ='24'!$F$22 -> 10.07 | T27: ='24'!$F$23 -> 5.5 | U27: ='24'!$F$24 -> 11.94 | V27: ='24'!$F$25 | W27: ='24'!$F$26 -> 7.85 | X27: ='24'!$F$27 -> 5.69 | Y27: ='24'!$F$28 -> 4.8 | Z27: ='24'!$F$29 -> 5.34 | AA27: ='24'!$F$30 -> 8.58 | AB27: ='24'!$F$31 | AC27: ='24'!$F$32 | AD27: ='24'!$F$33 -> 6.46
A28: Lee | B28: ='25'!$F$5 -> 6.03 | C28: ='25'!$F$6 -> 6.23 | D28: ='25'!$F$7 -> 9.47 | E28: ='25'!$F$8 -> 8.18 | F28: ='25'!$F$9 -> 11.08 | G28: ='25'!$F$10 -> 19.8 | H28: ='25'!$F$11 -> 7.07 | I28: ='25'!$F$12 -> 6.53 | J28: ='25'!$F$13 -> 6.98 | K28: ='25'!$F$14 | L28: ='25'!$F$15 -> 6.76 | M28: ='25'!$F$16 -> 8.91 | N28: ='25'!$F$17 -> 8.43 | O28: ='25'!$F$18 -> 12.68 | P28: ='25'!$F$19 | Q28: ='25'!$F$20 -> 7.28 | R28: ='25'!$F$21 | S28: ='25'!$F$22 -> 8.02 | T28: ='25'!$F$23 -> 7.33 | U28: ='25'!$F$24 -> 6.06 | V28: ='25'!$F$25 -> 11 | W28: ='25'!$F$26 -> 8.68 | X28: ='25'!$F$27 -> 8.28 | Y28: ='25'!$F$28 -> 7.48 | Z28: ='25'!$F$29 -> 8.28 | AA28: ='25'!$F$30 -> 19.85 | AB28: ='25'!$F$31 | AC28: ='25'!$F$32 | AD28: ='25'!$F$33 -> 8.02
A29: Lonestar | B29: ='26'!$F$5 -> 11.2 | C29: ='26'!$F$6 -> 7.34 | D29: ='26'!$F$7 -> 6.75 | E29: ='26'!$F$8 -> 6.92 | F29: ='26'!$F$9 -> 17.3 | G29: ='26'!$F$10 -> 10.1 | H29: ='26'!$F$11 -> 7.06 | I29: ='26'!$F$12 -> 7.89 | J29: ='26'!$F$13 -> 6.88 | K29: ='26'!$F$14 -> 8.8 | L29: ='26'!$F$15 -> 7.83 | M29: ='26'!$F$16 -> 6.63 | N29: ='26'!$F$17 -> 6.3 | O29: ='26'!$F$18 -> 9.64 | P29: ='26'!$F$19 | Q29: ='26'!$F$20 -> 7.38 | R29: ='26'!$F$21 -> 8.81 | S29: ='26'!$F$22 -> 6.97 | T29: ='26'!$F$23 -> 6.07 | U29: ='26'!$F$24 -> 8.27 | V29: ='26'!$F$25 | W29: ='26'!$F$26 -> 8.73 | X29: ='26'!$F$27 -> 7.22 | Y29: ='26'!$F$28 -> 5.7 | Z29: ='26'!$F$29 -> 6.36 | AA29: ='26'!$F$30 -> 8.47 | AB29: ='26'!$F$31 | AC29: ='26'!$F$32 | AD29: ='26'!$F$33 -> 6.82
A30: Mclennan | B30: ='27'!$F$5 | C30: ='27'!$F$6 -> 10.61 | D30: ='27'!$F$7 -> 4.92 | E30: ='27'!$F$8 -> 5.34 | F30: ='27'!$F$9 | G30: ='27'!$F$10 -> 7.36 | H30: ='27'!$F$11 -> 7.29 | I30: ='27'!$F$12 -> 10.33 | J30: ='27'!$F$13 -> 9.33 | K30: ='27'!$F$14 -> 11.69 | L30: ='27'!$F$15 -> 3.82 | M30: ='27'!$F$16 -> 5.53 | N30: ='27'!$F$17 -> 4.58 | O30: ='27'!$F$18 -> 9.54 | P30: ='27'!$F$19 | Q30: ='27'!$F$20 -> 7.42 | R30: ='27'!$F$21 -> 8.68 | S30: ='27'!$F$22 -> 4.36 | T30: ='27'!$F$23 -> 5.17 | U30: ='27'!$F$24 | V30: ='27'!$F$25 | W30: ='27'!$F$26 | X30: ='27'!$F$27 -> 7.11 | Y30: ='27'!$F$28 -> 5.5 | Z30: ='27'!$F$29 -> 3.83 | AA30: ='27'!$F$30 -> 8.66 | AB30: ='27'!$F$31 | AC30: ='27'!$F$32 | AD30: ='27'!$F$33 -> 6.12
A31: Midland | B31: ='28'!$F$5 -> 15.88 | C31: ='28'!$F$6 -> 6.81 | D31: ='28'!$F$7 -> 5.61 | E31: ='28'!$F$8 -> 5.42 | F31: ='28'!$F$9 | G31: ='28'!$F$10 -> 9.67 | H31: ='28'!$F$11 -> 5.23 | I31: ='28'!$F$12 -> 6.38 | J31: ='28'!$F$13 -> 6.22 | K31: ='28'!$F$14 | L31: ='28'!$F$15 -> 10.94 | M31: ='28'!$F$16 -> 6.98 | N31: ='28'!$F$17 -> 5.28 | O31: ='28'!$F$18 -> 9.55 | P31: ='28'!$F$19 | Q31: ='28'!$F$20 -> 7.76 | R31: ='28'!$F$21 -> 10.16 | S31: ='28'!$F$22 -> 13.67 | T31: ='28'!$F$23 -> 5.42 | U31: ='28'!$F$24 -> 7.57 | V31: ='28'!$F$25 -> 10.56 | W31: ='28'!$F$26 | X31: ='28'!$F$27 -> 8.64 | Y31: ='28'!$F$28 -> 7.04 | Z31: ='28'!$F$29 -> 5.84 | AA31: ='28'!$F$30 -> 8.46 | AB31: ='28'!$F$31 | AC31: ='28'!$F$32 | AD31: ='28'!$F$33 -> 6.77
A32: Navarro | B32: ='29'!$F$5 -> 3.26 | C32: ='29'!$F$6 | D32: ='29'!$F$7 -> 4.63 | E32: ='29'!$F$8 -> 6.39 | F32: ='29'!$F$9 -> 30.55 | G32: ='29'!$F$10 -> 31.35 | H32: ='29'!$F$11 -> 4.38 | I32: ='29'!$F$12 | J32: ='29'!$F$13 -> 3.81 | K32: ='29'!$F$14 -> 4.25 | L32: ='29'!$F$15 -> 6.15 | M32: ='29'!$F$16 -> 4.5 | N32: ='29'!$F$17 -> 3.71 | O32: ='29'!$F$18 -> 13.21 | P32: ='29'!$F$19 | Q32: ='29'!$F$20 -> 5.02 | R32: ='29'!$F$21 | S32: ='29'!$F$22 -> 4.71 | T32: ='29'!$F$23 -> 4.54 | U32: ='29'!$F$24 | V32: ='29'!$F$25 -> 16.58 | W32: ='29'!$F$26 -> 2.84 | X32: ='29'!$F$27 -> 5.64 | Y32: ='29'!$F$28 -> 4.11 | Z32: ='29'!$F$29 -> 3.94 | AA32: ='29'!$F$30 -> 6.09 | AB32: ='29'!$F$31 | AC32: ='29'!$F$32 | AD32: ='29'!$F$33 -> 5.17
A33: North Central Texas | B33: ='30'!$F$5 -> 8.06 | C33: ='30'!$F$6 -> 6.6 | D33: ='30'!$F$7 -> 4.44 | E33: ='30'!$F$8 -> 5.12 | F33: ='30'!$F$9 | G33: ='30'!$F$10 -> 5.38 | H33: ='30'!$F$11 -> 6.4 | I33: ='30'!$F$12 | J33: ='30'!$F$13 -> 3.72 | K33: ='30'!$F$14 | L33: ='30'!$F$15 -> 20.73 | M33: ='30'!$F$16 -> 4.41 | N33: ='30'!$F$17 -> 4.73 | O33: ='30'!$F$18 -> 6.65 | P33: ='30'!$F$19 | Q33: ='30'!$F$20 -> 8.63 | R33: ='30'!$F$21 | S33: ='30'!$F$22 -> 5.66 | T33: ='30'!$F$23 -> 3.52 | U33: ='30'!$F$24 | V33: ='30'!$F$25 | W33: ='30'!$F$26 -> 6.34 | X33: ='30'!$F$27 -> 5.4 | Y33: ='30'!$F$28 -> 4.71 | Z33: ='30'!$F$29 -> 3.76 | AA33: ='30'!$F$30 -> 5.84 | AB33: ='30'!$F$31 | AC33: ='30'!$F$32 | AD33: ='30'!$F$33 -> 5.05
A34: Northeast Texas | B34: ='31'!$F$5 -> 6.62 | C34: ='31'!$F$6 -> 6.07 | D34: ='31'!$F$7 -> 6.45 | E34: ='31'!$F$8 -> 7.07 | F34: ='31'!$F$9 | G34: ='31'!$F$10 -> 9.85 | H34: ='31'!$F$11 -> 6.18 | I34: ='31'!$F$12 | J34: ='31'!$F$13 -> 4.97 | K34: ='31'!$F$14 | L34: ='31'!$F$15 | M34: ='31'!$F$16 -> 5.08 | N34: ='31'!$F$17 -> 8.23 | O34: ='31'!$F$18 -> 10.71 | P34: ='31'!$F$19 -> 12.1 | Q34: ='31'!$F$20 -> 10.44 | R34: ='31'!$F$21 | S34: ='31'!$F$22 -> 5.11 | T34: ='31'!$F$23 -> 6.24 | U34: ='31'!$F$24 -> 10.98 | V34: ='31'!$F$25 -> 6.21 | W34: ='31'!$F$26 | X34: ='31'!$F$27 -> 5.85 | Y34: ='31'!$F$28 -> 6.31 | Z34: ='31'!$F$29 -> 5.43 | AA34: ='31'!$F$30 -> 9.27 | AB34: ='31'!$F$31 | AC34: ='31'!$F$32 | AD34: ='31'!$F$33 -> 6.26
A35: Odessa | B35: ='32'!$F$5 -> 5.32 | C35: ='32'!$F$6 -> 8.27 | D35: ='32'!$F$7 -> 6.13 | E35: ='32'!$F$8 -> 7.36 | F35: ='32'!$F$9 | G35: ='32'!$F$10 -> 8.8 | H35: ='32'!$F$11 -> 7.32 | I35: ='32'!$F$12 -> 5.35 | J35: ='32'!$F$13 -> 6.38 | K35: ='32'!$F$14 | L35: ='32'!$F$15 -> 9.11 | M35: ='32'!$F$16 -> 6.05 | N35: ='32'!$F$17 -> 6.26 | O35: ='32'!$F$18 -> 11.12 | P35: ='32'!$F$19 | Q35: ='32'!$F$20 -> 7.25 | R35: ='32'!$F$21 -> 8.03 | S35: ='32'!$F$22 -> 6.06 | T35: ='32'!$F$23 -> 5.54 | U35: ='32'!$F$24 -> 5.75 | V35: ='32'!$F$25 -> 13.95 | W35: ='32'!$F$26 -> 6.42 | X35: ='32'!$F$27 -> 6.19 | Y35: ='32'!$F$28 -> 6.88 | Z35: ='32'!$F$29 -> 5.88 | AA35: ='32'!$F$30 -> 10.02 | AB35: ='32'!$F$31 | AC35: ='32'!$F$32 | AD35: ='32'!$F$33 -> 6.88
A36: Panola | B36: ='33'!$F$5 -> 8.46 | C36: ='33'!$F$6 -> 7.12 | D36: ='33'!$F$7 -> 6.76 | E36: ='33'!$F$8 -> 8.9 | F36: ='33'!$F$9 | G36: ='33'!$F$10 -> 19.85 | H36: ='33'!$F$11 -> 6.65 | I36: ='33'!$F$12 | J36: ='33'!$F$13 -> 5.36 | K36: ='33'!$F$14 -> 7.56 | L36: ='33'!$F$15 -> 6 | M36: ='33'!$F$16 -> 5.88 | N36: ='33'!$F$17 -> 12.84 | O36: ='33'!$F$18 -> 14.64 | P36: ='33'!$F$19 | Q36: ='33'!$F$20 -> 7.98 | R36: ='33'!$F$21 | S36: ='33'!$F$22 -> 6.06 | T36: ='33'!$F$23 -> 5.86 | U36: ='33'!$F$24 | V36: ='33'!$F$25 | W36: ='33'!$F$26 | X36: ='33'!$F$27 -> 6.22 | Y36: ='33'!$F$28 | Z36: ='33'!$F$29 -> 5.89 | AA36: ='33'!$F$30 -> 9.48 | AB36: ='33'!$F$31 | AC36: ='33'!$F$32 | AD36: ='33'!$F$33 -> 7.05
A37: Paris | B37: ='34'!$F$5 -> 9.35 | C37: ='34'!$F$6 -> 7.43 | D37: ='34'!$F$7 -> 4.4 | E37: ='34'!$F$8 -> 5.52 | F37: ='34'!$F$9 | G37: ='34'!$F$10 -> 12.67 | H37: ='34'!$F$11 -> 4.54 | I37: ='34'!$F$12 | J37: ='34'!$F$13 -> 3.33 | K37: ='34'!$F$14 -> 29.94 | L37: ='34'!$F$15 -> 5.59 | M37: ='34'!$F$16 -> 4.34 | N37: ='34'!$F$17 -> 5.2 | O37: ='34'!$F$18 -> 14.51 | P37: ='34'!$F$19 | Q37: ='34'!$F$20 -> 2.16 | R37: ='34'!$F$21 | S37: ='34'!$F$22 -> 7.13 | T37: ='34'!$F$23 -> 3.44 | U37: ='34'!$F$24 | V37: ='34'!$F$25 | W37: ='34'!$F$26 -> 4.85 | X37: ='34'!$F$27 -> 4.9 | Y37: ='34'!$F$28 -> 2.16 | Z37: ='34'!$F$29 -> 4.02 | AA37: ='34'!$F$30 -> 9.56 | AB37: ='34'!$F$31 | AC37: ='34'!$F$32 | AD37: ='34'!$F$33 -> 4.99
A38: Ranger | B38: ='35'!$F$5 -> 3.54 | C38: ='35'!$F$6 -> 6.57 | D38: ='35'!$F$7 -> 4.37 | E38: ='35'!$F$8 -> 4.65 | F38: ='35'!$F$9 | G38: ='35'!$F$10 -> 3.78 | H38: ='35'!$F$11 -> 4.82 | I38: ='35'!$F$12 | J38: ='35'!$F$13 -> 4.57 | K38: ='35'!$F$14 | L38: ='35'!$F$15 | M38: ='35'!$F$16 -> 4.42 | N38: ='35'!$F$17 -> 3.26 | O38: ='35'!$F$18 | P38: ='35'!$F$19 | Q38: ='35'!$F$20 | R38: ='35'!$F$21 | S38: ='35'!$F$22 -> 4.14 | T38: ='35'!$F$23 -> 4.35 | U38: ='35'!$F$24 -> 7.86 | V38: ='35'!$F$25 | W38: ='35'!$F$26 | X38: ='35'!$F$27 -> 10.18 | Y38: ='35'!$F$28 -> 2.4 | Z38: ='35'!$F$29 -> 4.02 | AA38: ='35'!$F$30 -> 5.45 | AB38: ='35'!$F$31 | AC38: ='35'!$F$32 | AD38: ='35'!$F$33 -> 4.97
A39: San Jacinto | B39: ='36'!$F$5 -> 3.87 | C39: ='36'!$F$6 -> 5.89 | D39: ='36'!$F$7 -> 4.66 | E39: ='36'!$F$8 -> 6.83 | F39: ='36'!$F$9 -> 10.77 | G39: ='36'!$F$10 -> 10.01 | H39: ='36'!$F$11 -> 6.43 | I39: ='36'!$F$12 -> 4.57 | J39: ='36'!$F$13 -> 7.15 | K39: ='36'!$F$14 -> 381.63 | L39: ='36'!$F$15 -> 8.27 | M39: ='36'!$F$16 -> 4.63 | N39: ='36'!$F$17 -> 6.56 | O39: ='36'!$F$18 -> 6.85 | P39: ='36'!$F$19 | Q39: ='36'!$F$20 -> 8.69 | R39: ='36'!$F$21 -> 9.28 | S39: ='36'!$F$22 -> 8.78 | T39: ='36'!$F$23 -> 6.54 | U39: ='36'!$F$24 -> 9.41 | V39: ='36'!$F$25 -> 12.41 | W39: ='36'!$F$26 -> 8.91 | X39: ='36'!$F$27 -> 80.07 | Y39: ='36'!$F$28 -> 6.01 | Z39: ='36'!$F$29 -> 5.33 | AA39: ='36'!$F$30 -> 7.39 | AB39: ='36'!$F$31 | AC39: ='36'!$F$32 | AD39: ='36'!$F$33 -> 6.64
A40: South Plains | B40: ='37'!$F$5 -> 8.12 | C40: ='37'!$F$6 -> 8.7 | D40: ='37'!$F$7 -> 5.03 | E40: ='37'!$F$8 -> 6.97 | F40: ='37'!$F$9 | G40: ='37'!$F$10 -> 8.15 | H40: ='37'!$F$11 -> 5.57 | I40: ='37'!$F$12 -> 15.4 | J40: ='37'!$F$13 -> 4.71 | K40: ='37'!$F$14 -> 18.95 | L40: ='37'!$F$15 -> 7.04 | M40: ='37'!$F$16 -> 5.39 | N40: ='37'!$F$17 -> 5.44 | O40: ='37'!$F$18 -> 6.77 | P40: ='37'!$F$19 | Q40: ='37'!$F$20 -> 4.2 | R40: ='37'!$F$21 -> 7.77 | S40: ='37'!$F$22 -> 3.55 | T40: ='37'!$F$23 -> 4.57 | U40: ='37'!$F$24 -> 6.07 | V40: ='37'!$F$25 -> 7.03 | W40: ='37'!$F$26 -> 5.75 | X40: ='37'!$F$27 -> 10.04 | Y40: ='37'!$F$28 -> 6.59 | Z40: ='37'!$F$29 -> 5.15 | AA40: ='37'!$F$30 -> 9.37 | AB40: ='37'!$F$31 | AC40: ='37'!$F$32 | AD40: ='37'!$F$33 -> 5.67
...

Sheet Discipline Analysis
A1: =Summary!A1 -> Community and Technical Colleges, Report of Fundable Operating Expenses, Fiscal Year (FY) 1999
A2: Discipline Analysis by Institution | X2: Discipline
A3: 1 | X3: Agriculture
X4: Architecture and Precision Production Trades
A5: Institution | B5: Contact Hours | C5: Total | E5: Faculty Salaries | G5: Library | I5: Institutional Support | K5: Student Services | M5: Departmental Operating Expense | O5: Instructional Administration | Q5: Organized Activities | S5: Equipment Depreciation | U5: Local Benefits | X5: Biology, Physical Sciences, and Science Technology
C6: Expense | D6: per Hour | E6: Expense | F6: per Hour | G6: Expense | H6: per Hour | I6: Expense | J6: per Hour | K6: Expense | L6: per Hour | M6: Expense | N6: per Hour | O6: Expense | P6: per Hour | Q6: Expense | R6: per Hour | S6: Expense | T6: per Hour | U6: Expense | V6: per Hour | X6: Business Management, Marketing, and Administrative Services
A7: Alamo | B7: =OFFSET('1'!$D$4,$A$3,0) -> 22080 | C7: =OFFSET('1'!$E$4,$A$3,0) -> 140133.37 | D7: =OFFSET('1'!$F$4,$A$3,0) -> 6.35 | E7: =OFFSET('1'!$E$66,$A$3,0) -> 57648 | F7: =OFFSET('1'!$F$66,$A$3,0) -> 2.61 | G7: =IFERROR('1'!$F$100*'Discipline Analysis'!$B7,"") -> 6844.8 | H7: ='1'!$F$100 -> 0.31 | I7: =IFERROR('1'!$F$98*'Discipline Analysis'!$B7,"") -> 28262.4 | J7: ='1'!$F$98 -> 1.28 | K7: =IFERROR('1'!$F$99*'Discipline Analysis'!$B7,"") -> 16780.8 | L7: ='1'!$F$99 -> 0.76 | M7: =OFFSET('1'!$E$35,$A$3,0) -> 2068 | N7: =OFFSET('1'!$F$35,$A$3,0) -> 0.09 | O7: =IFERROR('1'!$F$101*'Discipline Analysis'!$B7,"") -> 11481.6 | P7: ='1'!$F$101 -> 0.52 | Q7: =IFERROR('1'!$F$102*'Discipline Analysis'!$B7,"") -> 220.8 | R7: ='1'!$F$102 -> 0.01 | S7: =IFERROR('1'!$F$103*'Discipline Analysis'!$B7,"") -> 0 | T7: ='1'!$F$103 -> 0 | U7: =IFERROR('1'!$F$104*'Discipline Analysis'!$B7,"") -> 16780.8 | V7: ='1'!$F$104 -> 0.76 | X7: Career Pilot
A8: Alvin | B8: =OFFSET('2'!$D$4,$A$3,0) -> 28654 | C8: =OFFSET('2'!$E$4,$A$3,0) -> 141037.41 | D8: =OFFSET('2'!$F$4,$A$3,0) -> 4.92 | E8: =OFFSET('2'!$E$66,$A$3,0) -> 58178 | F8: =OFFSET('2'!$F$66,$A$3,0) -> 2.03 | G8: =IFERROR('2'!$F$100*'Discipline Analysis'!$B8,"") -> 7450.04 | H8: ='2'!$F$100 -> 0.26 | I8: =IFERROR('2'!$F$98*'Discipline Analysis'!$B8,"") -> 27507.84 | J8: ='2'!$F$98 -> 0.96 | K8: =IFERROR('2'!$F$99*'Discipline Analysis'!$B8,"") -> 17192.4 | L8: ='2'!$F$99 -> 0.6 | M8: =OFFSET('2'!$E$35,$A$3,0) -> 13379 | N8: =OFFSET('2'!$F$35,$A$3,0) -> 0.47 | O8: =IFERROR('2'!$F$101*'Discipline Analysis'!$B8,"") -> 10028.9 | P8: ='2'!$F$101 -> 0.35 | Q8: =IFERROR('2'!$F$102*'Discipline Analysis'!$B8,"") | R8: ='2'!$F$102 | S8: =IFERROR('2'!$F$103*'Discipline Analysis'!$B8,"") | T8: ='2'!$F$103 | U8: =IFERROR('2'!$F$104*'Discipline Analysis'!$B8,"") -> 7450.04 | V8: ='2'!$F$104 -> 0.26 | X8: Communications
A9: Amarillo | B9: =OFFSET('3'!$D$4,$A$3,0) -> 2552 | C9: =OFFSET('3'!$E$4,$A$3,0) -> 28324.803 | D9: =OFFSET('3'!$F$4,$A$3,0) -> 11.1 | E9: =OFFSET('3'!$E$66,$A$3,0) -> 16833 | F9: =OFFSET('3'!$F$66,$A$3,0) -> 6.6 | G9: =IFERROR('3'!$F$100*'Discipline Analysis'!$B9,"") -> 535.92 | H9: ='3'!$F$100 -> 0.21 | I9: =IFERROR('3'!$F$98*'Discipline Analysis'!$B9,"") -> 3496.24 | J9: ='3'!$F$98 -> 1.37 | K9: =IFERROR('3'!$F$99*'Discipline Analysis'!$B9,"") -> 1352.56 | L9: ='3'!$F$99 -> 0.53 | M9: =OFFSET('3'!$E$35,$A$3,0) -> 3905 | N9: =OFFSET('3'!$F$35,$A$3,0) -> 1.53 | O9: =IFERROR('3'!$F$101*'Discipline Analysis'!$B9,"") -> 791.12 | P9: ='3'!$F$101 -> 0.31 | Q9: =IFERROR('3'!$F$102*'Discipline Analysis'!$B9,"") -> 178.64 | R9: ='3'!$F$102 -> 0.07 | S9: =IFERROR('3'!$F$103*'Discipline Analysis'!$B9,"") | T9: ='3'!$F$103 | U9: =IFERROR('3'!$F$104*'Discipline Analysis'!$B9,"") -> 1250.48 | V9: ='3'!$F$104 -> 0.49 | X9: Computer and Information Sciences
A10: Angelina | B10: =OFFSET('4'!$D$4,$A$3,0) -> 120 | C10: =OFFSET('4'!$E$4,$A$3,0) -> 713.38161 | D10: =OFFSET('4'!$F$4,$A$3,0) -> 5.94 | E10: =OFFSET('4'!$E$66,$A$3,0) -> 105 | F10: =OFFSET('4'!$F$66,$A$3,0) -> 0.88 | G10: =IFERROR('4'!$F$100*'Discipline Analysis'!$B10,"") -> 16.8 | H10: ='4'!$F$100 -> 0.14 | I10: =IFERROR('4'!$F$98*'Discipline Analysis'!$B10,"") -> 63.6 | J10: ='4'!$F$98 -> 0.53 | K10: =IFERROR('4'!$F$99*'Discipline Analysis'!$B10,"") -> 42 | L10: ='4'!$F$99 -> 0.35 | M10: =OFFSET('4'!$E$35,$A$3,0) -> 431 | N10: =OFFSET('4'!$F$35,$A$3,0) -> 3.59 | O10: =IFERROR('4'!$F$101*'Discipline Analysis'!$B10,"") -> 38.4 | P10: ='4'!$F$101 -> 0.32 | Q10: =IFERROR('4'!$F$102*'Discipline Analysis'!$B10,"") | R10: ='4'!$F$102 | S10: =IFERROR('4'!$F$103*'Discipline Analysis'!$B10,"") | T10: ='4'!$F$103 | U10: =IFERROR('4'!$F$104*'Discipline Analysis'!$B10,"") -> 15.6 | V10: ='4'!$F$104 -> 0.13 | X10: Construction Trades
A11: Austin | B11: =OFFSET('5'!$D$4,$A$3,0) -> 0 | C11: =OFFSET('5'!$E$4,$A$3,0) -> 0 | D11: =OFFSET('5'!$F$4,$A$3,0) | E11: =OFFSET('5'!$E$66,$A$3,0) -> 0 | F11: =OFFSET('5'!$F$66,$A$3,0) | G11: =IFERROR('5'!$F$100*'Discipline Analysis'!$B11,"") -> 0 | H11: ='5'!$F$100 -> 0.35 | I11: =IFERROR('5'!$F$98*'Discipline Analysis'!$B11,"") -> 0 | J11: ='5'!$F$98 -> 1.38 | K11: =IFERROR('5'!$F$99*'Discipline Analysis'!$B11,"") -> 0 | L11: ='5'!$F$99 -> 0.64 | M11: =OFFSET('5'!$E$35,$A$3,0) -> 0 | N11: =OFFSET('5'!$F$35,$A$3,0) | O11: =IFERROR('5'!$F$101*'Discipline Analysis'!$B11,"") -> 0 | P11: ='5'!$F$101 -> 0.74 | Q11: =IFERROR('5'!$F$102*'Discipline Analysis'!$B11,"") | R11: ='5'!$F$102 | S11: =IFERROR('5'!$F$103*'Discipline Analysis'!$B11,"") | T11: ='5'!$F$103 | U11: =IFERROR('5'!$F$104*'Discipline Analysis'!$B11,"") -> 0 | V11: ='5'!$F$104 -> 0.24 | X11: Consumer and Homemaking Education
A12: Blinn | B12: =OFFSET('6'!$D$4,$A$3,0) -> 17856 | C12: =OFFSET('6'!$E$4,$A$3,0) -> 139615.11 | D12: =OFFSET('6'!$F$4,$A$3,0) -> 7.82 | E12: =OFFSET('6'!$E$66,$A$3,0) -> 95600 | F12: =OFFSET('6'!$F$66,$A$3,0) -> 5.35 | G12: =IFERROR('6'!$F$100*'Discipline Analysis'!$B12,"") -> 3035.52 | H12: ='6'!$F$100 -> 0.17 | I12: =IFERROR('6'!$F$98*'Discipline Analysis'!$B12,"") -> 8392.32 | J12: ='6'!$F$98 -> 0.47 | K12: =IFERROR('6'!$F$99*'Discipline Analysis'!$B12,"") -> 6963.84 | L12: ='6'!$F$99 -> 0.39 | M12: =OFFSET('6'!$E$35,$A$3,0) -> 16173 | N12: =OFFSET('6'!$F$35,$A$3,0) -> 0.91 | O12: =IFERROR('6'!$F$101*'Discipline Analysis'!$B12,"") -> 3392.64 | P12: ='6'!$F$101 -> 0.19 | Q12: =IFERROR('6'!$F$102*'Discipline Analysis'!$B12,"") | R12: ='6'!$F$102 | S12: =IFERROR('6'!$F$103*'Discipline Analysis'!$B12,"") | T12: ='6'!$F$103 | U12: =IFERROR('6'!$F$104*'Discipline Analysis'!$B12,"") -> 6249.6 | V12: ='6'!$F$104 -> 0.35 | X12: Engineering
A13: Brazosport | B13: =OFFSET('7'!$D$4,$A$3,0) -> 0 | C13: =OFFSET('7'!$E$4,$A$3,0) -> 0 | D13: =OFFSET('7'!$F$4,$A$3,0) | E13: =OFFSET('7'!$E$66,$A$3,0) -> 0 | F13: =OFFSET('7'!$F$66,$A$3,0) | G13: =IFERROR('7'!$F$100*'Discipline Analysis'!$B13,"") -> 0 | H13: ='7'!$F$100 -> 0.23 | I13: =IFERROR('7'!$F$98*'Discipline Analysis'!$B13,"") -> 0 | J13: ='7'!$F$98 -> 1.51 | K13: =IFERROR('7'!$F$99*'Discipline Analysis'!$B13,"") -> 0 | L13: ='7'!$F$99 -> 0.51 | M13: =OFFSET('7'!$E$35,$A$3,0) -> 0 | N13: =OFFSET('7'!$F$35,$A$3,0) | O13: =IFERROR('7'!$F$101*'Discipline Analysis'!$B13,"") -> 0 | P13: ='7'!$F$101 -> 0.23 | Q13: =IFERROR('7'!$F$102*'Discipline Analysis'!$B13,"") -> 0 | R13: ='7'!$F$102 -> 0.2 | S13: =IFERROR('7'!$F$103*'Discipline Analysis'!$B13,"") | T13: ='7'!$F$103 | U13: =IFERROR('7'!$F$104*'Discipline Analysis'!$B13,"") -> 0 | V13: ='7'!$F$104 -> 0.79 | X13: Engineering Related
A14: Central Texas | B14: =OFFSET('8'!$D$4,$A$3,0) -> 11440 | C14: =OFFSET('8'!$E$4,$A$3,0) -> 107910.12 | D14: =OFFSET('8'!$F$4,$A$3,0) -> 9.43 | E14: =OFFSET('8'!$E$66,$A$3,0) -> 50760 | F14: =OFFSET('8'!$F$66,$A$3,0) -> 4.44 | G14: =IFERROR('8'!$F$100*'Discipline Analysis'!$B14,"") -> 2059.2 | H14: ='8'!$F$100 -> 0.18 | I14: =IFERROR('8'!$F$98*'Discipline Analysis'!$B14,"") -> 9609.6 | J14: ='8'!$F$98 -> 0.84 | K14: =IFERROR('8'!$F$99*'Discipline Analysis'!$B14,"") -> 5605.6 | L14: ='8'!$F$99 -> 0.49 | M14: =OFFSET('8'!$E$35,$A$3,0) -> 37342 | N14: =OFFSET('8'!$F$35,$A$3,0) -> 3.26 | O14: =IFERROR('8'!$F$101*'Discipline Analysis'!$B14,"") -> 1944.8 | P14: ='8'!$F$101 -> 0.17 | Q14: =IFERROR('8'!$F$102*'Discipline Analysis'!$B14,"") -> 457.6 | R14: ='8'!$F$102 -> 0.04 | S14: =IFERROR('8'!$F$103*'Discipline Analysis'!$B14,"") | T14: ='8'!$F$103 | U14: =IFERROR('8'!$F$104*'Discipline Analysis'!$B14,"") | V14: ='8'!$F$104 | X14: English Language, Lit, Philosophy, Humanities, & Interdisciplinary
A15: Cisco | B15: =OFFSET('9'!$D$4,$A$3,0) -> 10032 | C15: =OFFSET('9'!$E$4,$A$3,0) -> 67298.013 | D15: =OFFSET('9'!$F$4,$A$3,0) -> 6.71 | E15: =OFFSET('9'!$E$66,$A$3,0) -> 44101 | F15: =OFFSET('9'!$F$66,$A$3,0) -> 4.4 | G15: =IFERROR('9'!$F$100*'Discipline Analysis'!$B15,"") -> 1003.2 | H15: ='9'!$F$100 -> 0.1 | I15: =IFERROR('9'!$F$98*'Discipline Analysis'!$B15,"") -> 6821.76 | J15: ='9'!$F$98 -> 0.68 | K15: =IFERROR('9'!$F$99*'Discipline Analysis'!$B15,"") -> 6621.12 | L15: ='9'!$F$99 -> 0.66 | M15: =OFFSET('9'!$E$35,$A$3,0) -> 5707 | N15: =OFFSET('9'!$F$35,$A$3,0) -> 0.57 | O15: =IFERROR('9'!$F$101*'Discipline Analysis'!$B15,"") -> 1605.12 | P15: ='9'!$F$101 -> 0.16 | Q15: =IFERROR('9'!$F$102*'Discipline Analysis'!$B15,"") | R15: ='9'!$F$102 | S15: =IFERROR('9'!$F$103*'Discipline Analysis'!$B15,"") | T15: ='9'!$F$103 | U15: =IFERROR('9'!$F$104*'Discipline Analysis'!$B15,"") -> 1404.48 | V15: ='9'!$F$104 -> 0.14 | X15: Foreign Languages
A16: Clarendon | B16: =OFFSET('10'!$D$4,$A$3,0) -> 35120 | C16: =OFFSET('10'!$E$4,$A$3,0) -> 331938.42 | D16: =OFFSET('10'!$F$4,$A$3,0) -> 9.45 | E16: =OFFSET('10'!$E$66,$A$3,0) -> 151895 | F16: =OFFSET('10'!$F$66,$A$3,0) -> 4.33 | G16: =IFERROR('10'!$F$100*'Discipline Analysis'!$B16,"") -> 5619.2 | H16: ='10'!$F$100 -> 0.16 | I16: =IFERROR('10'!$F$98*'Discipline Analysis'!$B16,"") -> 57596.8 | J16: ='10'!$F$98 -> 1.64 | K16: =IFERROR('10'!$F$99*'Discipline Analysis'!$B16,"") -> 24935.2 | L16: ='10'!$F$99 -> 0.71 | M16: =OFFSET('10'!$E$35,$A$3,0) -> 71504 | N16: =OFFSET('10'!$F$35,$A$3,0) -> 2.04 | O16: =IFERROR('10'!$F$101*'Discipline Analysis'!$B16,"") -> 14048 | P16: ='10'!$F$101 -> 0.4 | Q16: =IFERROR('10'!$F$102*'Discipline Analysis'!$B16,"") | R16: ='10'!$F$102 | S16: =IFERROR('10'!$F$103*'Discipline Analysis'!$B16,"") | T16: ='10'!$F$103 | U16: =IFERROR('10'!$F$104*'Discipline Analysis'!$B16,"") -> 6321.6 | V16: ='10'!$F$104 -> 0.18 | X16: Health Occupations - Dental Assistants, Medical Lab, and Assoc. Degree Nursing
A17: Coastal Bend | B17: =OFFSET('11'!$D$4,$A$3,0) -> 32264 | C17: =OFFSET('11'!$E$4,$A$3,0) -> 115846.44 | D17: =OFFSET('11'!$F$4,$A$3,0) -> 3.59 | E17: =OFFSET('11'!$E$66,$A$3,0) -> 42518 | F17: =OFFSET('11'!$F$66,$A$3,0) -> 1.32 | G17: =IFERROR('11'!$F$100*'Discipline Analysis'!$B17,"") -> 8711.28 | H17: ='11'!$F$100 -> 0.27 | I17: =IFERROR('11'!$F$98*'Discipline Analysis'!$B17,"") -> 31941.36 | J17: ='11'!$F$98 -> 0.99 | K17: =IFERROR('11'!$F$99*'Discipline Analysis'!$B17,"") -> 10001.84 | L17: ='11'!$F$99 -> 0.31 | M17: =OFFSET('11'!$E$35,$A$3,0) -> 2545 | N17: =OFFSET('11'!$F$35,$A$3,0) -> 0.08 | O17: =IFERROR('11'!$F$101*'Discipline Analysis'!$B17,"") -> 14518.8 | P17: ='11'!$F$101 -> 0.45 | Q17: =IFERROR('11'!$F$102*'Discipline Analysis'!$B17,"") | R17: ='11'!$F$102 | S17: =IFERROR('11'!$F$103*'Discipline Analysis'!$B17,"") | T17: ='11'!$F$103 | U17: =IFERROR('11'!$F$104*'Discipline Analysis'!$B17,"") -> 5807.52 | V17: ='11'!$F$104 -> 0.18 | X17: Health Occupations - Dental Hygiene
A18: College Of The Mainland | B18: =OFFSET('12'!$D$4,$A$3,0) -> 0 | C18: =OFFSET('12'!$E$4,$A$3,0) -> 0 | D18: =OFFSET('12'!$F$4,$A$3,0) | E18: =OFFSET('12'!$E$66,$A$3,0) -> 0 | F18: =OFFSET('12'!$F$66,$A$3,0) | G18: =IFERROR('12'!$F$100*'Discipline Analysis'!$B18,"") -> 0 | H18: ='12'!$F$100 -> 0.47 | I18: =IFERROR('12'!$F$98*'Discipline Analysis'!$B18,"") -> 0 | J18: ='12'!$F$98 -> 1.89 | K18: =IFERROR('12'!$F$99*'Discipline Analysis'!$B18,"") -> 0 | L18: ='12'!$F$99 -> 0.69 | M18: =OFFSET('12'!$E$35,$A$3,0) -> 0 | N18: =OFFSET('12'!$F$35,$A$3,0) | O18: =IFERROR('12'!$F$101*'Discipline Analysis'!$B18,"") | P18: ='12'!$F$101 | Q18: =IFERROR('12'!$F$102*'Discipline Analysis'!$B18,"") | R18: ='12'!$F$102 | S18: =IFERROR('12'!$F$103*'Discipline Analysis'!$B18,"") | T18: ='12'!$F$103 | U18: =IFERROR('12'!$F$104*'Discipline Analysis'!$B18,"") -> 0 | V18: ='12'!$F$104 -> 1.16 | X18: Health Occupations - Other
A19: Collin | B19: =OFFSET('13'!$D$4,$A$3,0) -> 9036 | C19: =OFFSET('13'!$E$4,$A$3,0) -> 100017.98 | D19: =OFFSET('13'!$F$4,$A$3,0) -> 11.07 | E19: =OFFSET('13'!$E$66,$A$3,0) -> 57491 | F19: =OFFSET('13'!$F$66,$A$3,0) -> 6.36 | G19: =IFERROR('13'!$F$100*'Discipline Analysis'!$B19,"") -> 4156.56 | H19: ='13'!$F$100 -> 0.46 | I19: =IFERROR('13'!$F$98*'Discipline Analysis'!$B19,"") -> 10752.84 | J19: ='13'!$F$98 -> 1.19 | K19: =IFERROR('13'!$F$99*'Discipline Analysis'!$B19,"") -> 7499.88 | L19: ='13'!$F$99 -> 0.83 | M19: =OFFSET('13'!$E$35,$A$3,0) -> 12724 | N19: =OFFSET('13'!$F$35,$A$3,0) -> 1.41 | O19: =IFERROR('13'!$F$101*'Discipline Analysis'!$B19,"") -> 4337.28 | P19: ='13'!$F$101 -> 0.48 | Q19: =IFERROR('13'!$F$102*'Discipline Analysis'!$B19,"") | R19: ='13'!$F$102 | S19: =IFERROR('13'!$F$103*'Discipline Analysis'!$B19,"") | T19: ='13'!$F$103 | U19: =IFERROR('13'!$F$104*'Discipline Analysis'!$B19,"") -> 3072.24 | V19: ='13'!$F$104 -> 0.34 | X19: Health Occupations - Respiratory Therapy
A20: Dallas | B20: =OFFSET('14'!$D$4,$A$3,0) -> 78084 | C20: =OFFSET('14'!$E$4,$A$3,0) -> 986188.42 | D20: =OFFSET('14'!$F$4,$A$3,0) -> 12.63 | E20: =OFFSET('14'!$E$66,$A$3,0) -> 380468 | F20: =OFFSET('14'!$F$66,$A$3,0) -> 4.87 | G20: =IFERROR('14'!$F$100*'Discipline Analysis'!$B20,"") -> 24986.88 | H20: ='14'!$F$100 -> 0.32 | I20: =IFERROR('14'!$F$98*'Discipline Analysis'!$B20,"") -> 97605 | J20: ='14'!$F$98 -> 1.25 | K20: =IFERROR('14'!$F$99*'Discipline Analysis'!$B20,"") -> 49973.76 | L20: ='14'!$F$99 -> 0.64 | M20: =OFFSET('14'!$E$35,$A$3,0) -> 396609 | N20: =OFFSET('14'!$F$35,$A$3,0) -> 5.08 | O20: =IFERROR('14'!$F$101*'Discipline Analysis'!$B20,"") -> 17959.32 | P20: ='14'!$F$101 -> 0.23 | Q20: =IFERROR('14'!$F$102*'Discipline Analysis'!$B20,"") -> 2342.52 | R20: ='14'!$F$102 -> 0.03 | S20: =IFERROR('14'!$F$103*'Discipline Analysis'!$B20,"") | T20: ='14'!$F$103 | U20: =IFERROR('14'!$F$104*'Discipline Analysis'!$B20,"") -> 17178.48 | V20: ='14'!$F$104 -> 0.22 | X20: Health Occupations - Vocational Nursing
A21: Del Mar | B21: =OFFSET('15'!$D$4,$A$3,0) -> 0 | C21: =OFFSET('15'!$E$4,$A$3,0) -> 0 | D21: =OFFSET('15'!$F$4,$A$3,0) | E21: =OFFSET('15'!$E$66,$A$3,0) -> 0 | F21: =OFFSET('15'!$F$66,$A$3,0) | G21: =IFERROR('15'!$F$100*'Discipline Analysis'!$B21,"") | H21: ='15'!$F$100 | I21: =IFERROR('15'!$F$98*'Discipline Analysis'!$B21,"") | J21: ='15'!$F$98 | K21: =IFERROR('15'!$F$99*'Discipline Analysis'!$B21,"") | L21: ='15'!$F$99 | M21: =OFFSET('15'!$E$35,$A$3,0) -> 0 | N21: =OFFSET('15'!$F$35,$A$3,0) | O21: =IFERROR('15'!$F$101*'Discipline Analysis'!$B21,"") | P21: ='15'!$F$101 | Q21: =IFERROR('15'!$F$102*'Discipline Analysis'!$B21,"") | R21: ='15'!$F$102 | S21: =IFERROR('15'!$F$103*'Discipline Analysis'!$B21,"") | T21: ='15'!$F$103 | U21: =IFERROR('15'!$F$104*'Discipline Analysis'!$B21,"") | V21: ='15'!$F$104 | X21: Mathematics
A22: El Paso | B22: =OFFSET('16'!$D$4,$A$3,0) -> 0 | C22: =OFFSET('16'!$E$4,$A$3,0) -> 0 | D22: =OFFSET('16'!$F$4,$A$3,0) | E22: =OFFSET('16'!$E$66,$A$3,0) -> 0 | F22: =OFFSET('16'!$F$66,$A$3,0) | G22: =IFERROR('16'!$F$100*'Discipline Analysis'!$B22,"") -> 0 | H22: ='16'!$F$100 -> 0.37 | I22: =IFERROR('16'!$F$98*'Discipline Analysis'!$B22,"") -> 0 | J22: ='16'!$F$98 -> 1.52 | K22: =IFERROR('16'!$F$99*'Discipline Analysis'!$B22,"") -> 0 | L22: ='16'!$F$99 -> 0.71 | M22: =OFFSET('16'!$E$35,$A$3,0) -> 0 | N22: =OFFSET('16'!$F$35,$A$3,0) | O22: =IFERROR('16'!$F$101*'Discipline Analysis'!$B22,"") -> 0 | P22: ='16'!$F$101 -> 0.66 | Q22: =IFERROR('16'!$F$102*'Discipline Analysis'!$B22,"") -> 0 | R22: ='16'!$F$102 -> 0.01 | S22: =IFERROR('16'!$F$103*'Discipline Analysis'!$B22,"") | T22: ='16'!$F$103 | U22: =IFERROR('16'!$F$104*'Discipline Analysis'!$B22,"") -> 0 | V22: ='16'!$F$104 -> 0.37 | X22: Mechanics and Repairers - Automotive
A23: Frank Phillips | B23: =OFFSET('17'!$D$4,$A$3,0) -> 22176 | C23: =OFFSET('17'!$E$4,$A$3,0) -> 182221.03 | D23: =OFFSET('17'!$F$4,$A$3,0) -> 8.22 | E23: =OFFSET('17'!$E$66,$A$3,0) -> 105321 | F23: =OFFSET('17'!$F$66,$A$3,0) -> 4.75 | G23: =IFERROR('17'!$F$100*'Discipline Analysis'!$B23,"") -> 4435.2 | H23: ='17'!$F$100 -> 0.2 | I23: =IFERROR('17'!$F$98*'Discipline Analysis'!$B23,"") -> 25058.88 | J23: ='17'!$F$98 -> 1.13 | K23: =IFERROR('17'!$F$99*'Discipline Analysis'!$B23,"") -> 11088 | L23: ='17'!$F$99 -> 0.5 | M23: =OFFSET('17'!$E$35,$A$3,0) -> 12982 | N23: =OFFSET('17'!$F$35,$A$3,0) -> 0.59 | O23: =IFERROR('17'!$F$101*'Discipline Analysis'!$B23,"") -> 16410.24 | P23: ='17'!$F$101 -> 0.74 | Q23: =IFERROR('17'!$F$102*'Discipline Analysis'!$B23,"") -> 1330.56 | R23: ='17'!$F$102 -> 0.06 | S23: =IFERROR('17'!$F$103*'Discipline Analysis'!$B23,"") | T23: ='17'!$F$103 | U23: =IFERROR('17'!$F$104*'Discipline Analysis'!$B23,"") -> 5322.24 | V23: ='17'!$F$104 -> 0.24 | X23: Mechanics and Repairers - Diesel, Aviation Mechanics, and Transportation Workers
A24: Galveston | B24: =OFFSET('18'!$D$4,$A$3,0) -> 0 | C24: =OFFSET('18'!$E$4,$A$3,0) -> 0 | D24: =OFFSET('18'!$F$4,$A$3,0) | E24: =OFFSET('18'!$E$66,$A$3,0) -> 0 | F24: =OFFSET('18'!$F$66,$A$3,0) | G24: =IFERROR('18'!$F$100*'Discipline Analysis'!$B24,"") -> 0 | H24: ='18'!$F$100 -> 0.27 | I24: =IFERROR('18'!$F$98*'Discipline Analysis'!$B24,"") -> 0 | J24: ='18'!$F$98 -> 1.62 | K24: =IFERROR('18'!$F$99*'Discipline Analysis'!$B24,"") -> 0 | L24: ='18'!$F$99 -> 0.42 | M24: =OFFSET('18'!$E$35,$A$3,0) -> 0 | N24: =OFFSET('18'!$F$35,$A$3,0) | O24: =IFERROR('18'!$F$101*'Discipline Analysis'!$B24,"") -> 0 | P24: ='18'!$F$101 -> 0.84 | Q24: =IFERROR('18'!$F$102*'Discipline Analysis'!$B24,"") -> 0 | R24: ='18'!$F$102 -> 0.14 | S24: =IFERROR('18'!$F$103*'Discipline Analysis'!$B24,"") | T24: ='18'!$F$103 | U24: =IFERROR('18'!$F$104*'Discipline Analysis'!$B24,"") -> 0 | V24: ='18'!$F$104 -> 0.71 | X24: Mechanics and Repairers - Electronics
A25: Grayson | B25: =OFFSET('19'!$D$4,$A$3,0) -> 15912 | C25: =OFFSET('19'!$E$4,$A$3,0) -> 100368.89 | D25: =OFFSET('19'!$F$4,$A$3,0) -> 6.31 | E25: =OFFSET('19'!$E$66,$A$3,0) -> 48212 | F25: =OFFSET('19'!$F$66,$A$3,0) -> 3.03 | G25: =IFERROR('19'!$F$100*'Discipline Analysis'!$B25,"") -> 2545.92 | H25: ='19'!$F$100 -> 0.16 | I25: =IFERROR('19'!$F$98*'Discipline Analysis'!$B25,"") -> 15593.76 | J25: ='19'!$F$98 -> 0.98 | K25: =IFERROR('19'!$F$99*'Discipline Analysis'!$B25,"") -> 8433.36 | L25: ='19'!$F$99 -> 0.53 | M25: =OFFSET('19'!$E$35,$A$3,0) -> 14671 | N25: =OFFSET('19'!$F$35,$A$3,0) -> 0.92 | O25: =IFERROR('19'!$F$101*'Discipline Analysis'!$B25,"") -> 3341.52 | P25: ='19'!$F$101 -> 0.21 | Q25: =IFERROR('19'!$F$102*'Discipline Analysis'!$B25,"") -> 477.36 | R25: ='19'!$F$102 -> 0.03 | S25: =IFERROR('19'!$F$103*'Discipline Analysis'!$B25,"") | T25: ='19'!$F$103 | U25: =IFERROR('19'!$F$104*'Discipline Analysis'!$B25,"") -> 7160.4 | V25: ='19'!$F$104 -> 0.45 | X25: Physical Education and Fitness
A26: Hill | B26: =OFFSET('20'!$D$4,$A$3,0) -> 10200 | C26: =OFFSET('20'!$E$4,$A$3,0) -> 74205.989 | D26: =OFFSET('20'!$F$4,$A$3,0) -> 7.28 | E26: =OFFSET('20'!$E$66,$A$3,0) -> 40034 | F26: =OFFSET('20'!$F$66,$A$3,0) -> 3.92 | G26: =IFERROR('20'!$F$100*'Discipline Analysis'!$B26,"") -> 5916 | H26: ='20'!$F$100 -> 0.58 | I26: =IFERROR('20'!$F$98*'Discipline Analysis'!$B26,"") -> 9384 | J26: ='20'!$F$98 -> 0.92 | K26: =IFERROR('20'!$F$99*'Discipline Analysis'!$B26,"") -> 4998 | L26: ='20'!$F$99 -> 0.49 | M26: =OFFSET('20'!$E$35,$A$3,0) -> 9525 | N26: =OFFSET('20'!$F$35,$A$3,0) -> 0.93 | O26: =IFERROR('20'!$F$101*'Discipline Analysis'!$B26,"") -> 2958 | P26: ='20'!$F$101 -> 0.29 | Q26: =IFERROR('20'!$F$102*'Discipline Analysis'!$B26,"") | R26: ='20'!$F$102 | S26: =IFERROR('20'!$F$103*'Discipline Analysis'!$B26,"") | T26: ='20'!$F$103 | U26: =IFERROR('20'!$F$104*'Discipline Analysis'!$B26,"") -> 1326 | V26: ='20'!$F$104 -> 0.13 | X26: Protective Services and Public Administration
